1618677609.211448: {"m":"depth","symbol":"CHZ/USDT", "data":{"ts":1618677609116,"seqnum":21034366119,"asks":[["0.629959","5799"],["0.63","0"]],"bids":[]}}
1618677609.211514: {"m":"depth","symbol":"ALTBULL/USDT", "data":{"ts":1618677609095,"seqnum":21031929382,"asks":[["1446.5","0"]],"bids":[]}}
1618677609.211539: {"m":"depth","symbol":"NEO/USDT", "data":{"ts":1618677609086,"seqnum":32164169231,"asks":[["95.134","0"],["95.169","0"],["95.179","10.97"]],"bids":[]}}
1618677609.5508108: {"m":"depth","symbol":"SRM/BTC", "data":{"ts":1618677609250,"seqnum":14844468743,"asks":[["0.000112545","0"],["0.000112582","0"]],"bids":[]}}
1618677609.550872: {"m":"depth","symbol":"ALTBULL/USDT", "data":{"ts":1618677609116,"seqnum":21031929383,"asks":[["1443.2","1.304"]],"bids":[]}}
1618677609.550897: {"m":"depth","symbol":"CHZ/USDT", "data":{"ts":1618677609407,"seqnum":21034366120,"asks":[["0.629959","0"],["0.63018","5798"]],"bids":[]}}
1618677609.5509162: {"m":"depth","symbol":"NEO/USDT", "data":{"ts":1618677609212,"seqnum":32164169232,"asks":[["95.172","11.06"],["95.229","21.95"],["95.335","0"],["95.345","0"],["95.365","1.27"],["95.375","31.63"],["95.385","12.94"],["95.405","12.67"],["95.415","87.86"],["95.445","16.71"],["95.456","81.19"],["95.486","40.64"],["95.496","21.5"],["95.516","32.45"],["95.536","91.42"],["95.556","44.88"],["95.596","22.83"]],"bids":[["94.702","0"],["94.672","223.19"],["94.662","10.61"],["94.652","0"],["94.632","9.57"],["94.622","32.52"],["94.612","26.02"],["94.593","70.2"],["94.573","48.48"],["94.553","48.47"],["94.543","8.97"],["94.513","31.32"],["93.825","17.84"],["93.765","0"],["93.716","0"],["92.868","0.27"]]}}
1618677609.797868: {"m":"depth","symbol":"CHR/USDT", "data":{"ts":1618677609663,"seqnum":45632691678,"asks":[["0.39261","0"]],"bids":[["0.37128","0"],["0.36934","0"]]}}
1618677609.8044128: {"m":"depth","symbol":"CHZ/USDT", "data":{"ts":1618677609578,"seqnum":21034366121,"asks":[["0.63018","0"]],"bids":[["0.62285","0"]]}}
1618677609.804478: {"m":"depth","symbol":"SRM/BTC", "data":{"ts":1618677609636,"seqnum":14844468744,"asks":[["0.000112543","154"],["0.000112576","307"]],"bids":[]}}
1618677609.8044941: {"m":"depth","symbol":"NEO/USDT", "data":{"ts":1618677609698,"seqnum":32164169233,"asks":[["95.134","11.06"],["95.172","0"]],"bids":[["94.823","0"],["94.808","11.7"],["93.597","1.15"]]}}
1618677610.115861: {"m":"depth","symbol":"CHZ/USDT", "data":{"ts":1618677609990,"seqnum":21034366122,"asks":[["0.630378","5798"],["0.636926","0"]],"bids":[["0.623367","1658"]]}}
1618677610.115999: {"m":"depth","symbol":"NEO/USDT", "data":{"ts":1618677609861,"seqnum":32164169234,"asks":[["95.134","0"],["95.177","11.06"],["95.191","0"]],"bids":[["94.852","11.7"],["94.808","0"]]}}
1618677610.4736772: {"m":"depth","symbol":"EGLD/USDT", "data":{"ts":1618677610073,"seqnum":14843382633,"asks":[],"bids":[["209.1814","0"]]}}
1618677610.4738219: {"m":"depth","symbol":"CHZ/USDT", "data":{"ts":1618677610193,"seqnum":21034366123,"asks":[],"bids":[["0.622509","0"]]}}
1618677610.473891: {"m":"depth","symbol":"NEO/USDT", "data":{"ts":1618677610332,"seqnum":32164169235,"asks":[["95.134","11.06"],["95.177","0"],["95.186","25.48"],["95.365","1.57"],["95.385","0.89"],["95.415","40.04"],["95.435","0"],["95.466","42.97"],["95.476","13.18"],["95.536","79.31"],["95.556","0"],["95.857","5.85"],["95.937","233.26"],["96.077","4.08"]],"bids":[["94.852","0"],["94.702","50.33"],["94.692","161.28"],["94.682","10.92"],["94.672","92.57"],["94.602","49.68"],["94.583","0"],["94.573","36.36"],["94.563","86.14"],["94.523","57.3"],["94.513","31.32"],["94.343","12"],["92.868","0"]]}}
1618677610.73061: {"m":"depth","symbol":"EGLD/USDT", "data":{"ts":1618677610559,"seqnum":14843382634,"asks":[],"bids":[["209.1816","10.76"]]}}
1618677610.7551: {"m":"depth","symbol":"CHZ/USDT", "data":{"ts":1618677610609,"seqnum":21034366124,"asks":[["0.630378","0"]],"bids":[["0.623134","3316"]]}}
1618677611.08724: {"m":"depth","symbol":"CHZ/USDT", "data":{"ts":1618677610851,"seqnum":21034366125,"asks":[["0.630349","0"],["0.630519","1653"],["0.630563","5795"]],"bids":[]}}
1618677611.087421: {"m":"depth","symbol":"NEO/USDT", "data":{"ts":1618677610961,"seqnum":32164169236,"asks":[["95.134","0"],["95.173","11.06"]],"bids":[["94.861","11.7"],["94.836","0"]]}}
1618677611.397098: {"m":"depth","symbol":"CHZ/USDT", "data":{"ts":1618677611146,"seqnum":21034366126,"asks":[["0.630348","0"],["0.636914","677"]],"bids":[]}}
1618677611.397247: {"m":"depth","symbol":"NEO/USDT", "data":{"ts":1618677611238,"seqnum":32164169237,"asks":[["95.135","24.98"],["95.173","0"],["95.623","0"]],"bids":[["94.861","0"]]}}
1618677611.7024581: {"m":"depth","symbol":"CHR/USDT", "data":{"ts":1618677611541,"seqnum":45632691679,"asks":[],"bids":[["0.36934","8122"]]}}
1618677611.702615: {"m":"depth","symbol":"EGLD/USDT", "data":{"ts":1618677611506,"seqnum":14843382635,"asks":[],"bids":[["209.1093","0"]]}}
1618677611.702703: {"m":"depth","symbol":"NEO/USDT", "data":{"ts":1618677611567,"seqnum":32164169238,"asks":[["95.531","375.67"]],"bids":[["94.849","0"],["94.839","38.4"],["94.82","10.98"],["94.79","11.7"]]}}
1618677611.9932292: {"m":"depth","symbol":"CHR/USDT", "data":{"ts":1618677611684,"seqnum":45632691680,"asks":[["0.39266","2639"]],"bids":[["0.37128","2639"]]}}
1618677611.995065: {"m":"depth","symbol":"EGLD/USDT", "data":{"ts":1618677611625,"seqnum":14843382636,"asks":[],"bids":[["209.1382","9.7"]]}}
1618677612.007099: {"m":"depth","symbol":"SRM/BTC", "data":{"ts":1618677611830,"seqnum":14844468745,"asks":[["0.000112576","0"]],"bids":[]}}
1618677612.217559: {"m":"depth","symbol":"NEO/USDT", "data":{"ts":1618677611861,"seqnum":32164169239,"asks":[],"bids":[["94.793","11.7"],["94.79","0"]]}}
1618677612.273439: {"m":"depth","symbol":"ZIG/USDT", "data":{"ts":1618677612009,"seqnum":15360487477,"asks":[["0.098331","415"]],"bids":[]}}
1618677612.282979: {"m":"depth","symbol":"SRM/BTC", "data":{"ts":1618677612174,"seqnum":14844468746,"asks":[["0.000112586","307"]],"bids":[]}}
1618677612.283123: {"m":"depth","symbol":"CHZ/USDT", "data":{"ts":1618677612136,"seqnum":21034366127,"asks":[["0.636915","0"]],"bids":[["0.623293","0"]]}}
1618677612.2835531: {"m":"depth","symbol":"NEO/USDT", "data":{"ts":1618677612172,"seqnum":32164169240,"asks":[["95.265","10.29"],["95.285","3.92"],["95.295","1.16"],["95.305","50.33"],["95.315","12.8"],["95.325","33.61"],["95.335","1.36"],["95.345","21.23"],["95.355","0.24"],["95.365","44.2"],["95.375","72.98"],["95.385","28.54"],["95.395","51.12"],["95.405","0"],["95.415","0"],["95.435","11.41"],["95.445","5.88"],["95.456","81.2"],["95.466","20.7"],["95.476","13.18"],["95.486","27.11"],["95.496","21.5"],["95.506","29.31"],["95.516","39.5"],["95.536","82.21"],["95.566","25.26"],["95.576","8.35"],["95.586","65.68"],["95.596","12.15"],["95.616","0"],["95.626","4.67"],["95.706","0"],["95.957","0"],["95.967","0"],["95.977","0"],["95.997","0"],["96.037","0"],["96.077","0"]],"bids":[["94.839","0"],["94.82","0"],["94.793","0"],["94.702","0"],["94.692","0"],["94.682","0"],["94.672","0"],["94.662","0"],["94.632","0"],["94.622","78.3"],["94.612","0"],["94.602","36.5"],["94.593","11.7"],["94.573","54.63"],["94.563","81.67"],["94.553","42.81"],["94.543","11.05"],["94.533","74.5"],["94.523","48.62"],["94.513","0"],["94.503","26.38"],["94.493","11.26"],["94.483","3.75"],["94.473","32.17"],["94.443","5.85"],["94.413","1.96"],["92.868","0.27"],["92.848","4.52"],["92.818","35.64"]]}}
1618677612.585922: {"m":"depth","symbol":"EGLD/USDT", "data":{"ts":1618677612307,"seqnum":14843382637,"asks":[],"bids":[["209.1817","4.49"],["209.1815","0"]]}}
1618677612.5931652: {"m":"depth","symbol":"CHZ/USDT", "data":{"ts":1618677612214,"seqnum":21034366128,"asks":[["0.636913","600"]],"bids":[["0.623896","1658"]]}}
1618677612.593277: {"m":"depth","symbol":"SRM/BTC", "data":{"ts":1618677612248,"seqnum":14844468747,"asks":[],"bids":[["0.000112231","0"]]}}
1618677612.5933282: {"m":"depth","symbol":"NEO/USDT", "data":{"ts":1618677612483,"seqnum":32164169241,"asks":[["95.061","13.49"],["95.134","11.06"],["95.135","13.92"],["95.245","0"]],"bids":[["94.86","0"],["94.833","10.98"],["94.786","38.42"],["94.772","0"],["94.77","11.7"],["94.761","10.98"]]}}
1618677612.903043: {"m":"depth","symbol":"SRM/BTC", "data":{"ts":1618677612719,"seqnum":14844468748,"asks":[],"bids":[["0.00011224","188"]]}}
1618677612.903171: {"m":"depth","symbol":"NEO/USDT", "data":{"ts":1618677612794,"seqnum":32164169242,"asks":[["95.134","0"],["95.186","10.98"]],"bids":[["94.77","0"]]}}
1618677613.21287: {"m":"depth","symbol":"CHZ/USDT", "data":{"ts":1618677613109,"seqnum":21034366129,"asks":[["0.630519","0"],["0.630563","0"],["0.631231","1649"],["0.631376","5771"]],"bids":[["0.624801","0"]]}}
1618677613.212972: {"m":"depth","symbol":"ALTBULL/USDT", "data":{"ts":1618677612948,"seqnum":21031929384,"asks":[],"bids":[["1406.1","0"],["1403.8","1.576"]]}}
1618677613.213008: {"m":"depth","symbol":"NEO/USDT", "data":{"ts":1618677613143,"seqnum":32164169243,"asks":[["94.996","12.94"]],"bids":[["94.833","0"],["94.786","0"],["94.761","0"],["94.745","7.7"],["94.713","0"],["94.678","21.98"],["94.48","10.06"]]}}
1618677613.548146: {"m":"depth","symbol":"NEO/USDT", "data":{"ts":1618677613406,"seqnum":32164169244,"asks":[["95.018","13.01"],["95.165","1.03"],["95.175","191.49"],["95.185","3.81"],["95.195","56.87"],["95.215","51.55"],["95.225","0.29"],["95.235","9.76"],["95.255","28.28"],["95.265","0.22"],["95.285","0"],["95.295","0"],["95.305","0"],["95.315","8.61"],["95.325","63.05"],["95.335","11.05"],["95.345","0"],["95.355","7.28"],["95.365","33.15"],["95.375","27.7"],["95.385","9.92"],["95.395","1.96"],["95.405","10.75"],["95.425","178.27"],["95.435","44.62"],["95.445","10.43"],["95.456","61.06"],["95.476","21.06"],["95.496","8.05"],["95.516","21.86"],["95.536","42.39"],["95.546","1.88"],["95.566","0"],["95.576","0"],["95.586","68.79"],["95.596","8.25"],["95.606","0"],["95.626","1.1"],["95.636","0"],["95.646","4.9"],["95.666","17.97"],["95.766","28.71"],["95.787","257.4"],["95.837","7.41"],["95.867","0"],["95.887","58.41"],["95.907","3.01"],["95.917","6.06"],["95.937","0"],["95.947","0"]],"bids":[["94.745","0"],["94.678","0"],["94.664","9.74"],["94.661","11"],["94.622","0"],["94.602","0"],["94.593","0"],["94.573","0"],["94.563","0"],["94.553","0"],["94.543","0"],["94.533","19.5"],["94.523","0"],["94.503","0"],["94.493","0"],["94.483","11.05"],["94.473","43.7"],["94.463","21.98"],["94.453","11.17"],["94.443","38.33"],["94.433","25.35"],["94.423","13.55"],["94.413","42.67"],["94.403","24.63"],["94.383","7.4"],["94.373","7.06"],["94.363","30.68"],["94.343","0"],["94.313","0"],["94.303","61.95"],["94.293","4.35"],["94.283","10.99"],["94.264","12.3"],["94.224","0"],["94.204","4.63"],["94.194","5.67"],["94.174","5.64"],["94.154","73.91"],["94.094","6.81"],["94.024","5.73"],["94.004","2.33"],["93.984","0"],["93.915","0"],["93.855","66.69"],["93.825","0"],["93.805","16.49"],["93.775","19.41"],["93.516","0"],["93.416","25.93"],["92.818","0"],["92.778","0.15"],["92.744","1610.02"]]}}
1618677613.853258: {"m":"depth","symbol":"CHR/USDT", "data":{"ts":1618677613545,"seqnum":45632691681,"asks":[["0.39266","0"]],"bids":[["0.37128","0"],["0.36934","0"]]}}
1618677613.853436: {"m":"depth","symbol":"NEO/USDT", "data":{"ts":1618677613698,"seqnum":32164169245,"asks":[["95.018","0"],["95.054","13.01"]],"bids":[["94.661","0"],["94.529","22"]]}}
1618677614.1340292: {"m":"depth","symbol":"ZIG/USDT", "data":{"ts":1618677613943,"seqnum":15360487478,"asks":[],"bids":[["0.096192","415"]]}}
1618677614.153197: {"m":"depth","symbol":"NEO/USDT", "data":{"ts":1618677614027,"seqnum":32164169246,"asks":[["94.933","12.95"],["95.054","0"],["95.135","0"]],"bids":[["94.664","9.74"],["94.595","11"]]}}
1618677614.4692879: {"m":"depth","symbol":"EGLD/USDT", "data":{"ts":1618677614210,"seqnum":14843382638,"asks":[],"bids":[["209.1816","0"]]}}
1618677614.469429: {"m":"depth","symbol":"CHZ/USDT", "data":{"ts":1618677614198,"seqnum":21034366130,"asks":[["0.630518","677"],["0.631375","600"],["0.636913","0"],["0.636914","0"]],"bids":[["0.624801","10"]]}}
1618677614.469562: {"m":"depth","symbol":"NEO/USDT", "data":{"ts":1618677614369,"seqnum":32164169247,"asks":[["95.072","11.47"],["95.229","0"]],"bids":[["94.663","0"],["94.543","3"]]}}
1618677614.768626: {"m":"depth","symbol":"NEO/USDT", "data":{"ts":1618677614435,"seqnum":32164169248,"asks":[["95.072","0"]],"bids":[]}}
1618677615.187432: {"m":"depth","symbol":"EGLD/USDT", "data":{"ts":1618677614723,"seqnum":14843382639,"asks":[],"bids":[["209.1818","10.76"]]}}
1618677615.187509: {"m":"depth","symbol":"SRM/BTC", "data":{"ts":1618677614925,"seqnum":14844468749,"asks":[["0.000112558","0"],["0.000112605","154"]],"bids":[]}}
1618677615.187556: {"m":"depth","symbol":"CHZ/USDT", "data":{"ts":1618677614853,"seqnum":21034366131,"asks":[["0.631231","0"],["0.631376","0"],["0.631606","5791"]],"bids":[]}}
1618677615.187598: {"m":"depth","symbol":"ALTBULL/USDT", "data":{"ts":1618677614789,"seqnum":21031929385,"asks":[],"bids":[["1406.3","1.253"]]}}
1618677615.1876218: {"m":"depth","symbol":"NEO/USDT", "data":{"ts":1618677614886,"seqnum":32164169249,"asks":[["94.972","21.99"]],"bids":[["93.597","0"]]}}
1618677615.3843699: {"m":"depth","symbol":"ALTBULL/USDT", "data":{"ts":1618677615247,"seqnum":21031929386,"asks":[["1443.2","0"]],"bids":[["1404.3","0"]]}}
1618677615.3845272: {"m":"depth","symbol":"CHZ/USDT", "data":{"ts":1618677615247,"seqnum":21034366132,"asks":[["0.630518","0"],["0.631321","1655"],["0.631375","0"],["0.636914","677"],["0.636915","600"]],"bids":[["0.623367","0"]]}}
1618677615.388: {"m":"depth","symbol":"NEO/USDT", "data":{"ts":1618677615285,"seqnum":32164169250,"asks":[["95.104","0.4"],["95.114","12.05"],["95.125","78.98"],["95.145","10.67"],["95.155","156.16"],["95.165","0"],["95.175","75.19"],["95.185","0.25"],["95.195","37.52"],["95.215","78.95"],["95.225","44.27"],["95.235","21.44"],["95.265","82.45"],["95.275","19.64"],["95.285","7.73"],["95.295","3.97"],["95.305","4.2"],["95.315","8.61"],["95.325","0"],["95.335","21.24"],["95.355","9.05"],["95.365","33.15"],["95.375","42.01"],["95.395","15.31"],["95.415","6.38"],["95.425","22.11"],["95.435","33.3"],["95.445","4.54"],["95.456","36.1"],["95.476","13.18"],["95.486","0"],["95.506","2.01"],["95.516","0"],["95.536","0"],["95.586","58.05"],["95.596","0"],["95.626","222.1"],["95.666","88.36"],["95.716","23.08"],["95.766","7.96"],["95.787","21.72"],["95.887","0"],["95.897","0"],["95.907","0"],["95.917","0"]],"bids":[["94.533","0"],["94.483","0.64"],["94.463","27.99"],["94.453","6.95"],["94.443","0"],["94.433","0"],["94.423","0.28"],["94.413","0"],["94.403","12.98"],["94.393","53.51"],["94.383","11.89"],["94.373","0"],["94.363","17.2"],["94.353","9.75"],["94.343","25.35"],["94.333","43.5"],["94.323","20.44"],["94.313","59.75"],["94.303","96.19"],["94.293","4.35"],["94.283","22.86"],["94.273","38.72"],["94.264","6.04"],["94.263","0"],["94.244","5.05"],["94.224","25.35"],["94.204","0"],["94.194","0"],["94.174","1.95"],["94.154","67.19"],["94.104","4.52"],["94.094","0"],["94.074","0"],["94.024","0"],["93.964","0"],["93.925","5.4"],["93.881","80.7"],["93.825","48.06"],["93.805","0"],["93.795","247.89"],["93.755","303.46"],["93.487","1.15"],["93.416","0"],["93.286","22.86"],["92.848","0"],["92.778","0"]]}}
1618677615.695065: {"m":"depth","symbol":"CHR/USDT", "data":{"ts":1618677615497,"seqnum":45632691682,"asks":[["0.39255","2638"]],"bids":[["0.37128","2638"],["0.36934","8122"]]}}
1618677615.695233: {"m":"depth","symbol":"CHZ/USDT", "data":{"ts":1618677615469,"seqnum":21034366133,"asks":[["0.63123","677"],["0.636914","0"]],"bids":[["0.624106","1657"]]}}
1618677615.695337: {"m":"depth","symbol":"SRM/BTC", "data":{"ts":1618677615358,"seqnum":14844468750,"asks":[["0.000112529","168"],["0.000112556","0"]],"bids":[]}}
1618677615.6954129: {"m":"depth","symbol":"ALTBULL/USDT", "data":{"ts":1618677615620,"seqnum":21031929387,"asks":[["1444.3","1.362"]],"bids":[]}}
1618677615.6954648: {"m":"depth","symbol":"NEO/USDT", "data":{"ts":1618677615554,"seqnum":32164169251,"asks":[["95.005","11.63"],["95.186","0"]],"bids":[]}}
1618677616.005673: {"m":"depth","symbol":"CHZ/USDT", "data":{"ts":1618677615800,"seqnum":21034366134,"asks":[],"bids":[["0.623134","0"]]}}
1618677616.005816: {"m":"depth","symbol":"NEO/USDT", "data":{"ts":1618677615902,"seqnum":32164169252,"asks":[["94.939","11"],["94.996","12.94"],["95.001","11.63"],["95.005","0"]],"bids":[["94.595","0"]]}}
1618677616.316194: {"m":"depth","symbol":"NEO/USDT", "data":{"ts":1618677616243,"seqnum":32164169253,"asks":[],"bids":[["94.036","0"]]}}
1618677616.316333: {"m":"depth","symbol":"CHZ/USDT", "data":{"ts":1618677616193,"seqnum":21034366135,"asks":[["0.636916","0"],["0.651399","2273"]],"bids":[["0.623898","3313"]]}}
1618677616.316441: {"m":"depth","symbol":"SRM/BTC", "data":{"ts":1618677616243,"seqnum":14844468751,"asks":[["0.000112529","0"],["0.000112665","171"]],"bids":[]}}
1618677616.7225778: {"m":"depth","symbol":"SRM/BTC", "data":{"ts":1618677616269,"seqnum":14844468752,"asks":[["0.000112556","28"]],"bids":[]}}
1618677616.722677: {"m":"depth","symbol":"NEO/USDT", "data":{"ts":1618677616545,"seqnum":32164169254,"asks":[["95.001","0"],["95.375","45.01"],["95.455","0"]],"bids":[["94.591","11"]]}}
1618677617.02973: {"m":"depth","symbol":"CHZ/USDT", "data":{"ts":1618677616769,"seqnum":21034366136,"asks":[],"bids":[["0.624801","0"],["0.6248","5384"]]}}
1618677617.029835: {"m":"depth","symbol":"NEO/USDT", "data":{"ts":1618677616765,"seqnum":32164169255,"asks":[["95.017","11.63"]],"bids":[["94.591","0"],["93.869","277.4"]]}}
1618677617.233854: {"m":"depth","symbol":"ZIG/USDT", "data":{"ts":1618677616947,"seqnum":15360487479,"asks":[["0.098331","0"]],"bids":[]}}
1618677617.246685: {"m":"depth","symbol":"CHZ/USDT", "data":{"ts":1618677617118,"seqnum":21034366137,"asks":[["0.636915","0"]],"bids":[]}}
1618677617.2468312: {"m":"depth","symbol":"NEO/USDT", "data":{"ts":1618677617136,"seqnum":32164169256,"asks":[["95.017","0"],["95.054","33.02"],["95.061","0"],["95.064","32.64"],["95.074","41.74"],["95.084","161.2"],["95.094","10.93"],["95.104","3.92"],["95.125","28.65"],["95.135","12.82"],["95.145","9.36"],["95.155","146.77"],["95.175","35.38"],["95.185","0"],["95.195","0"],["95.205","13.22"],["95.215","0"],["95.255","28.28"],["95.265","82.45"],["95.275","19.64"],["95.285","7.73"],["95.305","6.2"],["95.335","25.51"],["95.355","1.76"],["95.375","48.07"],["95.395","20.25"],["95.415","0"],["95.435","21.89"],["95.456","4.82"],["95.476","21.08"],["95.546","0"],["95.586","52.86"],["95.666","80.27"],["95.776","234"],["95.787","26.89"],["95.837","0"],["95.847","0"],["95.857","0"]],"bids":[["94.664","0"],["94.581","11"],["94.544","11.13"],["94.483","0"],["94.473","0"],["94.463","0"],["94.453","0.07"],["94.423","0"],["94.403","0.13"],["94.393","0.7"],["94.383","29.1"],["94.363","9.97"],["94.343","0"],["94.333","39.3"],["94.323","0"],["94.313","36.7"],["94.303","26.49"],["94.293","77.22"],["94.283","5.71"],["94.273","38.72"],["94.264","6.85"],["94.254","12.48"],["94.244","0"],["94.234","27.16"],["94.184","56.64"],["94.174","1.96"],["94.164","1.63"],["94.154","58.62"],["94.144","0"],["94.104","4.63"],["94.094","4.27"],["94.054","0"],["94.014","2.87"],["93.994","6.54"],["93.954","7.82"],["93.855","0"],["93.775","0"],["93.745","4.04"],["93.725","59.28"],["93.685","20.3"],["93.556","18.14"],["93.306","0.37"],["93.286","0"],["93.277","23.17"],["93.197","0"],["93.087","0.27"],["92.997","21.35"],["92.878","1.12"],["92.744","0"]]}}
1618677617.642674: {"m":"depth","symbol":"CHR/USDT", "data":{"ts":1618677617316,"seqnum":45632691683,"asks":[["0.39255","0"]],"bids":[["0.37128","0"],["0.36934","0"]]}}
1618677617.6428502: {"m":"depth","symbol":"EGLD/USDT", "data":{"ts":1618677617460,"seqnum":14843382640,"asks":[],"bids":[["209.1819","4.49"],["209.1817","0"]]}}
1618677617.642936: {"m":"depth","symbol":"XDAI/USDT", "data":{"ts":1618677617329,"seqnum":14842030534,"asks":[],"bids":[["1.0004","0"]]}}
1618677617.642991: {"m":"depth","symbol":"CHZ/USDT", "data":{"ts":1618677617482,"seqnum":21034366138,"asks":[["0.636914","2273"],["0.651397","600"],["0.651399","0"]],"bids":[["0.624258","1657"],["0.623896","0"]]}}
1618677617.643104: {"m":"depth","symbol":"SRM/BTC", "data":{"ts":1618677617304,"seqnum":14844468753,"asks":[["0.000112601","307"],["0.000112639","0"]],"bids":[]}}
1618677617.64317: {"m":"depth","symbol":"NEO/USDT", "data":{"ts":1618677617435,"seqnum":32164169257,"asks":[["94.875","11.63"],["94.876","12.99"]],"bids":[["94.581","0"],["94.544","0"],["94.529","0"],["94.506","2.01"],["93.487","0"]]}}
1618677617.951073: {"m":"depth","symbol":"XDAI/USDT", "data":{"ts":1618677617645,"seqnum":14842030535,"asks":[],"bids":[["1.0004","15.2"]]}}
1618677617.951175: {"m":"depth","symbol":"NEO/USDT", "data":{"ts":1618677617478,"seqnum":32164169258,"asks":[],"bids":[["94.506","0"]]}}
1618677617.951232: {"m":"depth","symbol":"SRM/BTC", "data":{"ts":1618677617716,"seqnum":14844468754,"asks":[["0.000112354","139"],["0.000112556","0"],["0.000112586","0"],["0.000112665","0"]],"bids":[]}}
1618677618.2553542: {"m":"depth","symbol":"CHZ/USDT", "data":{"ts":1618677617939,"seqnum":21034366139,"asks":[],"bids":[["0.622903","3314"],["0.621639","0"]]}}
1618677618.255517: {"m":"depth","symbol":"SRM/BTC", "data":{"ts":1618677617883,"seqnum":14844468755,"asks":[["0.000112354","0"],["0.000112555","307"],["0.000112574","66"]],"bids":[]}}
1618677618.2556171: {"m":"depth","symbol":"ALTBULL/USDT", "data":{"ts":1618677618004,"seqnum":21031929388,"asks":[["1445.2","8.103"]],"bids":[["1406.3","0"],["1402","1.298"]]}}
1618677618.255697: {"m":"depth","symbol":"NEO/USDT", "data":{"ts":1618677617945,"seqnum":32164169259,"asks":[],"bids":[["94.551","11.01"],["94.478","22.02"],["94.461","11.2"],["93.307","1.15"]]}}
1618677618.565851: {"m":"depth","symbol":"CHZ/USDT", "data":{"ts":1618677618384,"seqnum":21034366140,"asks":[["0.636913","600"],["0.651397","0"]],"bids":[["0.607385","8797"],["0.601382","0"]]}}
1618677618.565989: {"m":"depth","symbol":"SRM/BTC", "data":{"ts":1618677618360,"seqnum":14844468756,"asks":[["0.000112543","0"],["0.000112574","66"]],"bids":[]}}
1618677618.566039: {"m":"depth","symbol":"ALTBULL/USDT", "data":{"ts":1618677618223,"seqnum":21031929389,"asks":[["1443.2","1.279"],["1444.3","0"]],"bids":[]}}
1618677618.566082: {"m":"depth","symbol":"NEO/USDT", "data":{"ts":1618677618329,"seqnum":32164169260,"asks":[["95.024","218.65"],["95.044","50.33"],["95.054","34.28"],["95.064","42.58"],["95.074","10.07"],["95.084","0"],["95.094","44.19"],["95.104","0.13"],["95.114","12.18"],["95.135","0"],["95.145","10.31"],["95.155","0"],["95.175","23.59"],["95.195","7.74"],["95.215","27.17"],["95.235","21.44"],["95.265","94.26"],["95.275","62.21"],["95.295","5.96"],["95.305","9.3"],["95.315","8.49"],["95.335","25.52"],["95.355","0"],["95.375","40.36"],["95.385","17.36"],["95.395","30.6"],["95.415","6.63"],["95.425","0"],["95.476","13.18"],["95.656","49.72"],["95.702","75.54"],["95.706","17.68"],["95.716","4.42"],["95.787","0"]],"bids":[["94.551","0"],["94.511","11.2"],["94.48","0"],["94.461","0"],["94.453","0"],["94.403","0"],["94.393","0"],["94.383","0.11"],["94.364","10.06"],["94.363","41.05"],["94.353","9.84"],["94.333","15.95"],["94.323","13.35"],["94.313","25.06"],["94.303","31.25"],["94.293","32.17"],["94.283","15.8"],["94.273","0"],["94.264","38.81"],["94.254","37.51"],["94.244","5.05"],["94.234","37.05"],["94.224","33.54"],["94.204","3.87"],["94.194","30.03"],["94.174","0.31"],["94.164","28.9"],["94.154","56.61"],["94.124","24.69"],["94.114","3.8"],["94.104","0"],["94.094","0"],["94.054","5.06"],["94.034","4.97"],["93.994","0"],["93.954","0.14"],["93.944","36.85"],["93.895","6.63"],["93.795","0"],["93.715","23.99"],["93.685","0"],["93.625","16.53"],["93.606","219.37"],["93.556","0"],["93.496","20.09"],["93.277","0"],["93.217","25.31"],["92.878","0"],["92.868","0"]]}}
1618677618.8739352: {"m":"depth","symbol":"SRM/BTC", "data":{"ts":1618677618697,"seqnum":14844468757,"asks":[["0.000112495","154"],["0.000112574","0"],["0.000112594","0"],["0.000112601","0"],["0.000112605","307"],["0.000112623","307"]],"bids":[]}}
1618677618.874157: {"m":"depth","symbol":"NEO/USDT", "data":{"ts":1618677618699,"seqnum":32164169261,"asks":[["95.855","0"]],"bids":[["94.511","0"],["94.478","0"]]}}
1618677619.094375: {"m":"depth","symbol":"ZIG/USDT", "data":{"ts":1618677618926,"seqnum":15360487480,"asks":[],"bids":[["0.096192","0"]]}}
1618677619.1036742: {"m":"depth","symbol":"ALTBULL/USDT", "data":{"ts":1618677618832,"seqnum":21031929390,"asks":[["1443.4","0"]],"bids":[]}}
1618677619.103824: {"m":"depth","symbol":"NEO/USDT", "data":{"ts":1618677618950,"seqnum":32164169262,"asks":[["94.803","11.56"],["94.804","12.12"],["94.875","0"],["94.996","0"]],"bids":[["94.543","3"],["94.471","11.01"],["94.424","22.03"]]}}
1618677619.103967: {"m":"depth","symbol":"CHZ/USDT", "data":{"ts":1618677618990,"seqnum":21034366141,"asks":[["0.63123","0"],["0.636914","2950"]],"bids":[]}}
1618677619.423242: {"m":"depth","symbol":"CHZ/USDT", "data":{"ts":1618677619260,"seqnum":21034366142,"asks":[["0.636914","2950"]],"bids":[["0.625236","1655"],["0.623781","0"]]}}
1618677619.423413: {"m":"depth","symbol":"ALTBULL/USDT", "data":{"ts":1618677619274,"seqnum":21031929391,"asks":[],"bids":[["1404.1","1.347"]]}}
1618677619.423477: {"m":"depth","symbol":"NEO/USDT", "data":{"ts":1618677619312,"seqnum":32164169263,"asks":[],"bids":[["94.543","0"],["94.464","3"],["94.424","22.03"],["94.421","11.2"]]}}
1618677619.423566: {"m":"depth","symbol":"SRM/BTC", "data":{"ts":1618677619062,"seqnum":14844468758,"asks":[["0.000112495","0"]],"bids":[]}}
1618677619.713161: {"m":"depth","symbol":"CHR/USDT", "data":{"ts":1618677619513,"seqnum":45632691684,"asks":[],"bids":[["0.37128","2639"],["0.36934","8122"]]}}
1618677619.745654: {"m":"depth","symbol":"ALTBULL/USDT", "data":{"ts":1618677619573,"seqnum":21031929392,"asks":[],"bids":[["1402","0"]]}}
1618677619.745805: {"m":"depth","symbol":"SRM/BTC", "data":{"ts":1618677619609,"seqnum":14844468759,"asks":[["0.000112525","154"],["0.000112555","0"],["0.000112623","0"]],"bids":[]}}
1618677619.745877: {"m":"depth","symbol":"NEO/USDT", "data":{"ts":1618677619511,"seqnum":32164169264,"asks":[],"bids":[["94.432","11.2"],["94.421","0"]]}}
1618677620.101602: {"m":"depth","symbol":"CHR/USDT", "data":{"ts":1618677619654,"seqnum":45632691685,"asks":[["0.39252","2598"]],"bids":[]}}
1618677620.1017432: {"m":"depth","symbol":"EGLD/USDT", "data":{"ts":1618677619770,"seqnum":14843382641,"asks":[],"bids":[["209.1818","0"]]}}
1618677620.1018188: {"m":"depth","symbol":"CHZ/USDT", "data":{"ts":1618677619889,"seqnum":21034366143,"asks":[["0.631605","677"],["0.636914","2273"]],"bids":[]}}
1618677620.10189: {"m":"depth","symbol":"SRM/BTC", "data":{"ts":1618677619842,"seqnum":14844468760,"asks":[["0.000112587","156"],["0.000112605","154"],["0.000112645","307"]],"bids":[]}}
1618677620.101986: {"m":"depth","symbol":"NEO/USDT", "data":{"ts":1618677619891,"seqnum":32164169265,"asks":[["94.972","0"]],"bids":[["94.472","11.2"],["94.432","0"]]}}
1618677620.372038: {"m":"depth","symbol":"EGLD/USDT", "data":{"ts":1618677620262,"seqnum":14843382642,"asks":[],"bids":[["209.182","10.76"]]}}
1618677620.37218: {"m":"depth","symbol":"CHZ/USDT", "data":{"ts":1618677620175,"seqnum":21034366144,"asks":[["0.631605","0"],["0.636912","677"]],"bids":[]}}
1618677620.372278: {"m":"depth","symbol":"SRM/BTC", "data":{"ts":1618677619997,"seqnum":14844468761,"asks":[["0.000112581","307"],["0.000112619","153"]],"bids":[]}}
1618677620.377527: {"m":"depth","symbol":"NEO/USDT", "data":{"ts":1618677620234,"seqnum":32164169266,"asks":[["94.832","22.02"],["94.964","35.32"],["94.974","121.3"],["94.994","41.05"],["95.024","205.93"],["95.044","118.37"],["95.054","32.72"],["95.064","10.9"],["95.074","55.92"],["95.084","31.75"],["95.094","10.93"],["95.104","25.04"],["95.114","12.86"],["95.145","24.78"],["95.155","10.29"],["95.175","0"],["95.185","3.76"],["95.195","7.74"],["95.205","21.41"],["95.215","0"],["95.225","5.15"],["95.235","12.43"],["95.255","38.82"],["95.265","53.05"],["95.275","49.9"],["95.285","9.46"],["95.295","0"],["95.305","0"],["95.315","0"],["95.335","21.24"],["95.365","7.19"],["95.375","54.83"],["95.385","24.8"],["95.395","15.28"],["95.405","0"],["95.415","0"],["95.445","0"],["95.456","0"],["95.556","66.69"],["95.566","19.89"],["95.656","35.97"],["95.666","9.88"],["95.787","4.57"]],"bids":[["94.464","0"],["94.384","3"],["94.383","0"],["94.363","2.82"],["94.353","0"],["94.343","170.97"],["94.333","62.92"],["94.323","0"],["94.313","0"],["94.303","113.94"],["94.293","12.28"],["94.283","11.43"],["94.273","11.09"],["94.264","41.3"],["94.254","0.11"],["94.244","13.07"],["94.234","0"],["94.224","25.35"],["94.214","19.29"],["94.204","43.83"],["94.194","0"],["94.184","56.64"],["94.174","69.31"],["94.164","50.36"],["94.154","64.21"],["94.114","0"],["94.054","2.08"],["94.034","0"],["94.004","1.2"],["93.994","1.65"],["93.974","5.2"],["93.964","4.89"],["93.944","29.24"],["93.895","0"],["93.875","8.23"],["93.845","7.68"],["93.835","0"],["93.815","1.09"],["93.725","0"],["93.715","11.55"],["93.625","57.42"],["93.566","18.65"],["93.496","0"],["93.476","18.97"],["93.436","223.68"],["93.366","13.28"],["93.217","0"],["93.147","19.98"],["92.997","0"],["92.928","24.81"],["92.904","1905.08"]]}}
1618677620.715765: {"m":"depth","symbol":"SRM/BTC", "data":{"ts":1618677620420,"seqnum":14844468762,"asks":[["0.000112567","3"]],"bids":[]}}
1618677620.715919: {"m":"depth","symbol":"CHZ/USDT", "data":{"ts":1618677620571,"seqnum":21034366145,"asks":[],"bids":[["0.624106","0"]]}}
1618677620.715998: {"m":"depth","symbol":"NEO/USDT", "data":{"ts":1618677620500,"seqnum":32164169267,"asks":[["94.803","0"],["94.816","11.56"]],"bids":[]}}
1618677621.023199: {"m":"depth","symbol":"CHZ/USDT", "data":{"ts":1618677620888,"seqnum":21034366146,"asks":[["0.631321","0"],["0.631548","1655"]],"bids":[["0.605796","0"]]}}
1618677621.0233889: {"m":"depth","symbol":"NEO/USDT", "data":{"ts":1618677620744,"seqnum":32164169268,"asks":[["94.803","11.56"],["94.816","0"]],"bids":[["94.472","11.2"],["94.424","22.03"]]}}
1618677621.327604: {"m":"depth","symbol":"CHR/USDT", "data":{"ts":1618677621191,"seqnum":45632691686,"asks":[["0.39252","0"]],"bids":[["0.37128","0"],["0.36934","0"]]}}
1618677621.32778: {"m":"depth","symbol":"CHZ/USDT", "data":{"ts":1618677621141,"seqnum":21034366147,"asks":[["0.636913","0"]],"bids":[["0.624526","1655"]]}}
1618677621.327871: {"m":"depth","symbol":"NEO/USDT", "data":{"ts":1618677621037,"seqnum":32164169269,"asks":[["94.939","0"]],"bids":[["94.471","0"]]}}
1618677621.6372411: {"m":"depth","symbol":"CHZ/USDT", "data":{"ts":1618677621376,"seqnum":21034366148,"asks":[["0.636911","600"],["0.655083","0"]],"bids":[["0.623898","0"]]}}
1618677621.637432: {"m":"depth","symbol":"NEO/USDT", "data":{"ts":1618677621400,"seqnum":32164169270,"asks":[["94.804","23.14"]],"bids":[["94.472","0"],["94.461","11.02"],["94.425","11.2"],["93.307","0"]]}}
1618677621.952088: {"m":"depth","symbol":"CHZ/USDT", "data":{"ts":1618677621702,"seqnum":21034366149,"asks":[],"bids":[["0.624475","3309"]]}}
1618677621.952229: {"m":"depth","symbol":"NEO/USDT", "data":{"ts":1618677621702,"seqnum":32164169271,"asks":[],"bids":[["94.462","11.2"],["94.425","0"]]}}
1618677622.249183: {"m":"depth","symbol":"EGLD/USDT", "data":{"ts":1618677621960,"seqnum":14843382643,"asks":[],"bids":[["209.1821","4.49"],["209.1819","0"]]}}
1618677622.249346: {"m":"depth","symbol":"CHZ/USDT", "data":{"ts":1618677622072,"seqnum":21034366150,"asks":[["0.631606","0"],["0.631993","5787"],["0.656859","5332"]],"bids":[["0.6248","0"]]}}
1618677622.249463: {"m":"depth","symbol":"NEO/USDT", "data":{"ts":1618677622087,"seqnum":32164169272,"asks":[["94.803","0"],["94.858","11.56"]],"bids":[["93.869","0"],["93.437","1.15"]]}}
1618677622.5591922: {"m":"depth","symbol":"CHZ/USDT", "data":{"ts":1618677622407,"seqnum":21034366151,"asks":[],"bids":[["0.626218","5789"],["0.607386","1876"]]}}
1618677622.55935: {"m":"depth","symbol":"ALTBULL/USDT", "data":{"ts":1618677622396,"seqnum":21031929393,"asks":[["1444.9","1.357"]],"bids":[]}}
1618677622.559415: {"m":"depth","symbol":"SRM/BTC", "data":{"ts":1618677622279,"seqnum":14844468763,"asks":[["0.000112525","0"]],"bids":[]}}
1618677622.559482: {"m":"depth","symbol":"NEO/USDT", "data":{"ts":1618677622193,"seqnum":32164169273,"asks":[["94.964","0"],["94.974","172.82"],["94.984","3.36"],["94.994","0"],["95.004","22.32"],["95.014","56.87"],["95.024","306.44"],["95.034","48.28"],["95.044","0.14"],["95.054","47.35"],["95.064","42.58"],["95.074","5.54"],["95.104","0"],["95.125","55.85"],["95.155","10.29"],["95.205","13.23"],["95.215","20.99"],["95.225","0"],["95.245","6.77"],["95.275","42.56"],["95.305","15.72"],["95.385","14.88"],["95.466","254.7"],["95.546","19.11"],["95.566","0"],["95.626","1.1"],["95.686","4.27"],["95.756","0"],["95.766","0"],["95.776","0"],["95.787","0"]],"bids":[["94.363","0"],["94.343","0"],["94.333","55.73"],["94.323","0.77"],["94.313","157.82"],["94.303","51.38"],["94.283","0"],["94.273","20.96"],["94.264","0"],["94.254","48.26"],["94.244","13.54"],["94.234","13.58"],["94.224","0"],["94.214","11.7"],["94.184","28.63"],["94.174","39.09"],["94.164","99.11"],["94.154","64.21"],["94.144","16.82"],["94.134","23.92"],["94.124","28.67"],["94.064","69.04"],["94.014","32.07"],["94.004","3"],["93.994","0"],["93.964","0"],["93.944","38.11"],["93.875","0"],["93.845","0.16"],["93.835","7.42"],["93.815","7.86"],["93.566","0"],["93.536","17.47"],["93.147","0"],["93.117","25.25"],["92.878","1.12"]]}}
1618677622.866567: {"m":"depth","symbol":"SRM/BTC", "data":{"ts":1618677622623,"seqnum":14844468764,"asks":[["0.000112516","154"]],"bids":[]}}
1618677622.866709: {"m":"depth","symbol":"CHZ/USDT", "data":{"ts":1618677622741,"seqnum":21034366152,"asks":[["0.631993","0"],["0.632239","5786"]],"bids":[["0.625042","1655"],["0.624258","0"]]}}
1618677622.866845: {"m":"depth","symbol":"ALTBULL/USDT", "data":{"ts":1618677622531,"seqnum":21031929394,"asks":[["1443.2","0"]],"bids":[]}}
1618677622.866884: {"m":"depth","symbol":"NEO/USDT", "data":{"ts":1618677622698,"seqnum":32164169274,"asks":[["94.858","0"],["94.882","11.56"],["95.461","10.06"],["95.578","0"]],"bids":[]}}
1618677623.173415: {"m":"depth","symbol":"EGLD/USDT", "data":{"ts":1618677622835,"seqnum":14843382644,"asks":[["216.8297","0"]],"bids":[]}}
1618677623.1735559: {"m":"depth","symbol":"SRM/BTC", "data":{"ts":1618677623024,"seqnum":14844468765,"asks":[["0.000112516","0"]],"bids":[]}}
1618677623.1736262: {"m":"depth","symbol":"NEO/USDT", "data":{"ts":1618677622985,"seqnum":32164169275,"asks":[["94.882","0"]],"bids":[]}}
1618677623.785056: {"m":"depth","symbol":"SRM/BTC", "data":{"ts":1618677623445,"seqnum":14844468766,"asks":[["0.000112529","154"]],"bids":[]}}
1618677623.785203: {"m":"depth","symbol":"NEO/USDT", "data":{"ts":1618677623683,"seqnum":32164169276,"asks":[["94.804","11.02"],["94.962","12.19"]],"bids":[["93.721","278.02"]]}}
1618677624.07615: {"m":"depth","symbol":"EGLD/USDT", "data":{"ts":1618677623785,"seqnum":14843382645,"asks":[],"bids":[["209.182","0"]]}}
1618677624.087936: {"m":"depth","symbol":"ALTBULL/USDT", "data":{"ts":1618677623971,"seqnum":21031929395,"asks":[["1443","10.739"]],"bids":[]}}
1618677624.0880718: {"m":"depth","symbol":"NEO/USDT", "data":{"ts":1618677623941,"seqnum":32164169277,"asks":[["94.804","0"],["94.832","0"],["94.859","9.05"],["94.877","38.49"],["95.226","0"],["95.702","0"]],"bids":[["93.437","0"]]}}
1618677624.382132: {"m":"depth","symbol":"CHR/USDT", "data":{"ts":1618677624292,"seqnum":45632691687,"asks":[["0.39274","2638"]],"bids":[["0.37128","2638"],["0.36934","8122"]]}}
1618677624.382308: {"m":"depth","symbol":"EGLD/USDT", "data":{"ts":1618677624302,"seqnum":14843382646,"asks":[],"bids":[["209.1822","10.76"]]}}
1618677624.393777: {"m":"depth","symbol":"CHZ/USDT", "data":{"ts":1618677624305,"seqnum":21034366153,"asks":[["0.636912","0"]],"bids":[]}}
1618677624.396808: {"m":"depth","symbol":"NEO/USDT", "data":{"ts":1618677624300,"seqnum":32164169278,"asks":[["94.885","11.01"],["94.922","22.02"],["94.974","0"],["94.984","0"],["95.004","0"],["95.014","0"],["95.024","0"],["95.034","0"],["95.044","0"],["95.054","51.65"],["95.064","63.35"],["95.074","0"],["95.084","31.2"],["95.094","11.06"],["95.104","12.65"],["95.114","35.1"],["95.125","146.92"],["95.135","6.97"],["95.145","9.36"],["95.155","6.86"],["95.179","0"],["95.185","3.76"],["95.195","7.74"],["95.205","34.64"],["95.215","6.3"],["95.235","0"],["95.245","0"],["95.255","32.6"],["95.265","45.8"],["95.275","0"],["95.285","4.83"],["95.295","14.63"],["95.305","13.58"],["95.315","5.38"],["95.325","8.28"],["95.335","25.43"],["95.365","7.02"],["95.375","98.64"],["95.385","22.32"],["95.415","6.5"],["95.466","20.7"],["95.546","0"],["95.596","16.19"],["95.601","60.08"],["95.656","30"],["95.726","4.98"],["95.756","7.41"],["95.766","14.17"],["95.776","234"],["95.787","4.57"]],"bids":[["94.424","0"],["94.413","45.47"],["94.403","181.35"],["94.384","0"],["94.383","209.94"],["94.373","5.3"],["94.343","12.29"],["94.333","0"],["94.323","0.13"],["94.313","11.83"],["94.303","16.28"],["94.293","34.1"],["94.273","41.11"],["94.244","3.22"],["94.214","41.53"],["94.184","0"],["94.174","61.27"],["94.164","0"],["94.154","64.21"],["94.124","24.69"],["94.114","1.87"],["94.054","2.05"],["94.034","4.83"],["94.004","1.2"],["93.994","4"],["93.974","0"],["93.944","33.33"],["93.925","11.27"],["93.905","208"],["93.885","8.35"],["93.865","8.08"],["93.835","0"],["93.815","1.09"],["93.536","0"],["93.187","0"],["93.117","0"],["93.087","0"],["92.928","0"],["92.904","0"],["92.878","0"]]}}
1618677624.707076: {"m":"depth","symbol":"CHZ/USDT", "data":{"ts":1618677624332,"seqnum":21034366154,"asks":[["0.632238","677"]],"bids":[]}}
1618677624.707222: {"m":"depth","symbol":"ALTBULL/USDT", "data":{"ts":1618677624635,"seqnum":21031929396,"asks":[["1442.7","1.331"]],"bids":[]}}
1618677624.707299: {"m":"depth","symbol":"NEO/USDT", "data":{"ts":1618677624516,"seqnum":32164169279,"asks":[["94.86","11"],["94.877","0"],["94.897","38.5"]],"bids":[["94.481","22.02"],["94.464","13.64"],["94.463","3"],["94.462","0"],["93.307","1.15"]]}}
1618677625.118798: {"m":"depth","symbol":"ALTBULL/USDT", "data":{"ts":1618677624827,"seqnum":21031929397,"asks":[["1445.2","0"]],"bids":[]}}
1618677625.424747: {"m":"depth","symbol":"CHZ/USDT", "data":{"ts":1618677625223,"seqnum":21034366155,"asks":[["0.636911","0"],["0.636913","600"]],"bids":[]}}
1618677625.424912: {"m":"depth","symbol":"ALTBULL/USDT", "data":{"ts":1618677625038,"seqnum":21031929398,"asks":[["1444.9","0"]],"bids":[]}}
1618677625.4249809: {"m":"depth","symbol":"SRM/BTC", "data":{"ts":1618677625142,"seqnum":14844468767,"asks":[["0.000112591","153"],["0.000112619","0"]],"bids":[]}}
1618677625.425056: {"m":"depth","symbol":"NEO/USDT", "data":{"ts":1618677625247,"seqnum":32164169280,"asks":[["94.897","0"],["94.907","38.5"],["95.054","51.38"],["95.064","9.55"],["95.074","3.47"],["95.084","39.87"],["95.094","43.23"],["95.114","0"],["95.125","28.65"],["95.145","20.07"],["95.155","17.94"],["95.165","22.89"],["95.195","11.61"],["95.205","39.45"],["95.255","32.6"],["95.305","59.88"],["95.405","8.05"],["95.476","0"],["95.787","0"]],"bids":[["94.464","0"],["94.433","6.59"],["94.413","0"],["94.383","166.23"],["94.373","47.68"],["94.313","48.54"],["94.303","11.26"],["94.254","51.76"],["94.244","5.6"],["94.224","19.82"],["94.204","43.83"],["94.144","0"],["94.134","0"],["94.014","26.21"],["93.925","5.4"],["93.197","23.45"]]}}
1618677625.624279: {"m":"depth","symbol":"EGLD/USDT", "data":{"ts":1618677625543,"seqnum":14843382647,"asks":[["216.8302","0"]],"bids":[]}}
1618677625.641477: {"m":"depth","symbol":"SRM/BTC", "data":{"ts":1618677625293,"seqnum":14844468768,"asks":[["0.000112581","0"]],"bids":[]}}
1618677625.6416261: {"m":"depth","symbol":"CHZ/USDT", "data":{"ts":1618677625555,"seqnum":21034366156,"asks":[["0.632238","0"],["0.63691","677"]],"bids":[]}}
1618677625.6417222: {"m":"depth","symbol":"NEO/USDT", "data":{"ts":1618677625557,"seqnum":32164169281,"asks":[["94.922","0"]],"bids":[["94.482","13.59"]]}}
1618677625.94324: {"m":"depth","symbol":"SRM/BTC", "data":{"ts":1618677625660,"seqnum":14844468769,"asks":[["0.000112561","307"]],"bids":[]}}
1618677626.256097: {"m":"depth","symbol":"CHR/USDT", "data":{"ts":1618677626103,"seqnum":45632691688,"asks":[["0.39274","0"]],"bids":[["0.37128","0"],["0.36934","0"]]}}
1618677626.256217: {"m":"depth","symbol":"CHZ/USDT", "data":{"ts":1618677626176,"seqnum":21034366157,"asks":[["0.63691","0"],["0.636913","0"]],"bids":[]}}
1618677626.2562711: {"m":"depth","symbol":"SRM/BTC", "data":{"ts":1618677626078,"seqnum":14844468770,"asks":[["0.000112567","0"]],"bids":[]}}
1618677626.25631: {"m":"depth","symbol":"NEO/USDT", "data":{"ts":1618677625909,"seqnum":32164169282,"asks":[["94.922","22.02"]],"bids":[]}}
1618677626.5528488: {"m":"depth","symbol":"EGLD/USDT", "data":{"ts":1618677626287,"seqnum":14843382648,"asks":[["216.8295","0.03"]],"bids":[]}}
1618677626.566311: {"m":"depth","symbol":"CHZ/USDT", "data":{"ts":1618677626463,"seqnum":21034366158,"asks":[["0.631548","0"],["0.632238","677"],["0.632239","0"],["0.636909","600"]],"bids":[["0.626218","0"],["0.625236","0"],["0.624526","0"]]}}
1618677626.566551: {"m":"depth","symbol":"NEO/USDT", "data":{"ts":1618677626460,"seqnum":32164169283,"asks":[["94.86","0"],["94.907","0"]],"bids":[["94.482","0"],["94.445","11.97"],["93.307","0"]]}}
1618677626.9640372: {"m":"depth","symbol":"EGLD/USDT", "data":{"ts":1618677626750,"seqnum":14843382649,"asks":[],"bids":[["209.1382","0"]]}}
1618677626.964194: {"m":"depth","symbol":"CHZ/USDT", "data":{"ts":1618677626595,"seqnum":21034366159,"asks":[],"bids":[["0.625055","1652"]]}}
1618677626.9642692: {"m":"depth","symbol":"SRM/BTC", "data":{"ts":1618677626537,"seqnum":14844468771,"asks":[["0.000112609","538"]],"bids":[]}}
1618677626.964332: {"m":"depth","symbol":"NEO/USDT", "data":{"ts":1618677626738,"seqnum":32164169284,"asks":[],"bids":[["94.461","0"],["94.445","0"],["94.444","11.97"]]}}
1618677627.268064: {"m":"depth","symbol":"EGLD/USDT", "data":{"ts":1618677626883,"seqnum":14843382650,"asks":[["216.8294","4.49"],["216.8296","0"]],"bids":[["209.1823","4.49"],["209.1821","0"],["209.1558","9.7"]]}}
1618677627.2682061: {"m":"depth","symbol":"CHZ/USDT", "data":{"ts":1618677626988,"seqnum":21034366160,"asks":[],"bids":[["0.624475","0"]]}}
1618677627.268251: {"m":"depth","symbol":"NEO/USDT", "data":{"ts":1618677627099,"seqnum":32164169285,"asks":[["94.812","12.48"],["94.962","0"]],"bids":[["94.482","11.97"],["94.478","11.01"],["94.444","0"],["93.626","1.15"]]}}
1618677627.4882822: {"m":"depth","symbol":"CHR/USDT", "data":{"ts":1618677627271,"seqnum":45632691689,"asks":[],"bids":[["0.34533","0"]]}}
1618677627.497015: {"m":"depth","symbol":"CHZ/USDT", "data":{"ts":1618677627306,"seqnum":21034366161,"asks":[["0.636909","0"],["0.636913","600"]],"bids":[["0.625158","3303"]]}}
1618677627.497194: {"m":"depth","symbol":"NEO/USDT", "data":{"ts":1618677627222,"seqnum":32164169286,"asks":[["94.994","41.05"],["95.034","13.4"],["95.044","45.47"],["95.054","67.57"],["95.064","38.8"],["95.074","0.11"],["95.084","0"],["95.094","10.93"],["95.104","0"],["95.145","0"],["95.155","6.86"],["95.165","0"],["95.185","8.63"],["95.195","60.14"],["95.205","43.54"],["95.235","37.51"],["95.255","34.33"],["95.295","17.47"],["95.305","24.07"],["95.335","21.24"],["95.375","78.46"],["95.405","16.11"],["95.415","0"],["95.496","0"],["95.586","4.24"],["95.787","4.57"],["95.817","19.61"]],"bids":[["94.433","0"],["94.403","0"],["94.383","0"],["94.373","0"],["94.363","0.1"],["94.343","0.94"],["94.333","50.33"],["94.323","0"],["94.313","5.17"],["94.293","0.12"],["94.273","31.15"],["94.264","31.86"],["94.254","3.5"],["94.244","25.35"],["94.214","6.43"],["94.204","43.83"],["94.184","7.08"],["94.154","102.24"],["94.114","0"],["94.074","6.78"],["94.034","0"],["93.984","5.24"],["93.745","67.03"],["93.625","0"],["93.187","0.13"],["93.087","0.27"],["93.033","1799.4"]]}}
1618677627.807853: {"m":"depth","symbol":"ALTBULL/USDT", "data":{"ts":1618677627608,"seqnum":21031929399,"asks":[],"bids":[["1404.1","0"]]}}
1618677628.189613: {"m":"depth","symbol":"ROOM/USDT", "data":{"ts":1618677627766,"seqnum":15303408702,"asks":[],"bids":[["1.7947","0"]]}}
1618677628.189759: {"m":"depth","symbol":"EGLD/USDT", "data":{"ts":1618677627803,"seqnum":14843382651,"asks":[],"bids":[["209.1822","0"]]}}
1618677628.189829: {"m":"depth","symbol":"CHZ/USDT", "data":{"ts":1618677627955,"seqnum":21034366162,"asks":[],"bids":[["0.625088","1652"],["0.625042","0"]]}}
1618677628.1899168: {"m":"depth","symbol":"NEO/USDT", "data":{"ts":1618677627876,"seqnum":32164169287,"asks":[["94.811","10.79"],["94.859","0"]],"bids":[]}}
1618677628.4985652: {"m":"depth","symbol":"EGLD/USDT", "data":{"ts":1618677628298,"seqnum":14843382652,"asks":[],"bids":[["209.1824","10.76"]]}}
1618677628.4987059: {"m":"depth","symbol":"NEO/USDT", "data":{"ts":1618677628350,"seqnum":32164169288,"asks":[["94.811","0"],["94.875","10.79"]],"bids":[]}}
1618677628.78468: {"m":"depth","symbol":"SRM/BTC", "data":{"ts":1618677628581,"seqnum":14844468772,"asks":[["0.00011255","3"],["0.000112609","0"]],"bids":[]}}
1618677628.7848582: {"m":"depth","symbol":"NEO/USDT", "data":{"ts":1618677628607,"seqnum":32164169289,"asks":[["94.812","0"],["94.875","0"]],"bids":[["94.482","0"]]}}
1618677629.092523: {"m":"depth","symbol":"CHR/USDT", "data":{"ts":1618677628916,"seqnum":45632691690,"asks":[],"bids":[["0.36934","8122"]]}}
1618677629.120022: {"m":"depth","symbol":"CHZ/USDT", "data":{"ts":1618677628951,"seqnum":21034366163,"asks":[],"bids":[["0.607386","0"]]}}
1618677629.120169: {"m":"depth","symbol":"NEO/USDT", "data":{"ts":1618677628874,"seqnum":32164169290,"asks":[["94.875","9.53"],["94.885","0"],["94.922","0"],["94.965","12.51"]],"bids":[["94.482","13.22"],["93.626","0"]]}}
1618677629.1203148: {"m":"depth","symbol":"SRM/BTC", "data":{"ts":1618677629013,"seqnum":14844468773,"asks":[["0.000112529","0"],["0.00011255","0"],["0.000112561","0"],["0.000112591","0"],["0.000112616","153"],["0.000112632","538"],["0.000112645","0"],["0.000112673","307"]],"bids":[]}}
1618677629.519503: {"m":"depth","symbol":"CHZ/USDT", "data":{"ts":1618677629251,"seqnum":21034366164,"asks":[["0.632238","0"]],"bids":[]}}
1618677629.519644: {"m":"depth","symbol":"SRM/BTC", "data":{"ts":1618677629322,"seqnum":14844468774,"asks":[["0.000112568","153"],["0.0001126","307"],["0.000112605","0"],["0.000112624","154"],["0.000112632","0"],["0.000112717","538"]],"bids":[]}}
1618677629.5197818: {"m":"depth","symbol":"NEO/USDT", "data":{"ts":1618677629206,"seqnum":32164169291,"asks":[["94.875","0"],["94.899","11.01"],["94.932","22.01"],["94.994","0"],["95.034","0"],["95.054","0"],["95.064","0"],["95.074","41.05"],["95.094","0"],["95.125","0.14"],["95.135","0.25"],["95.145","20.47"],["95.155","59.84"],["95.185","0"],["95.195","4.55"],["95.205","37.88"],["95.215","0"],["95.225","13.92"],["95.235","0"],["95.255","28.28"],["95.265","42.98"],["95.285","0"],["95.295","0"],["95.305","5.17"],["95.315","0"],["95.325","1.61"],["95.335","21.24"],["95.345","7.03"],["95.355","11.79"],["95.365","37.05"],["95.375","12.65"],["95.385","45"],["95.395","0"],["95.405","0"],["95.415","37.54"],["95.445","7.12"],["95.466","7.87"],["95.556","0"],["95.596","0"],["95.656","118.88"],["95.817","0"],["95.837","7.41"],["95.847","3.8"],["95.857","5.85"],["95.897","33.03"],["95.907","3.01"],["95.937","8.22"],["95.947","6.32"],["95.957","6.52"],["95.967","19.76"],["95.977","51.99"]],"bids":[["94.463","154.73"],["94.433","65.95"],["94.423","52.03"],["94.403","189.47"],["94.383","10.61"],["94.363","0.11"],["94.353","9.66"],["94.343","0"],["94.333","49.2"],["94.323","17.33"],["94.313","24.21"],["94.303","0"],["94.293","0"],["94.283","20.8"],["94.273","11.09"],["94.264","0"],["94.254","39.39"],["94.244","0"],["94.234","39.64"],["94.214","6.43"],["94.204","43.83"],["94.184","29.97"],["94.174","39.09"],["94.154","64.21"],["94.134","1.98"],["94.104","1.85"],["94.074","0"],["94.054","5.09"],["94.034","4.9"],["94.014","2.87"],["93.994","5.17"],["93.984","0"],["93.925","18.67"],["93.915","6.99"],["93.885","0"],["93.865","0"],["93.625","16.66"],["93.267","0"],["93.197","0"],["93.187","0"],["93.087","0"]]}}
1618677629.729407: {"m":"depth","symbol":"SRM/BTC", "data":{"ts":1618677629589,"seqnum":14844468775,"asks":[["0.000112673","0"],["0.000112692","307"]],"bids":[]}}
1618677629.7295759: {"m":"depth","symbol":"CHZ/USDT", "data":{"ts":1618677629434,"seqnum":21034366165,"asks":[["0.636908","677"],["0.656859","0"]],"bids":[]}}
1618677629.729666: {"m":"depth","symbol":"NEO/USDT", "data":{"ts":1618677629614,"seqnum":32164169292,"asks":[["94.932","0"]],"bids":[["94.481","0"],["93.607","1.15"]]}}
1618677630.099922: {"m":"depth","symbol":"SRM/BTC", "data":{"ts":1618677629828,"seqnum":14844468776,"asks":[["0.000112616","0"],["0.000112692","0"]],"bids":[]}}
1618677630.444005: {"m":"depth","symbol":"CHZ/USDT", "data":{"ts":1618677630178,"seqnum":21034366166,"asks":[["0.636907","600"],["0.636913","0"],["0.686962","5332"]],"bids":[]}}
1618677630.444184: {"m":"depth","symbol":"SRM/BTC", "data":{"ts":1618677630213,"seqnum":14844468777,"asks":[["0.000112568","0"],["0.000112688","153"],["0.000112753","307"]],"bids":[]}}
1618677630.444281: {"m":"depth","symbol":"NEO/USDT", "data":{"ts":1618677630227,"seqnum":32164169293,"asks":[["94.899","0"],["94.951","22.01"],["94.967","11.11"]],"bids":[["94.525","11.65"],["94.524","22.01"],["94.482","0"]]}}
1618677630.751263: {"m":"depth","symbol":"ZIG/USDT", "data":{"ts":1618677630535,"seqnum":15360487481,"asks":[["0.097998","415"]],"bids":[]}}
1618677630.751403: {"m":"depth","symbol":"EGLD/USDT", "data":{"ts":1618677630353,"seqnum":14843382653,"asks":[],"bids":[["209.1825","4.49"],["209.1823","0"]]}}
1618677630.751492: {"m":"depth","symbol":"SRM/BTC", "data":{"ts":1618677630439,"seqnum":14844468778,"asks":[["0.000112594","153"]],"bids":[]}}
1618677630.75155: {"m":"depth","symbol":"CHZ/USDT", "data":{"ts":1618677630425,"seqnum":21034366167,"asks":[["0.636912","2273"],["0.636914","0"]],"bids":[["0.622904","1829"],["0.610777","18122"],["0.605795","0"]]}}
1618677630.751657: {"m":"depth","symbol":"NEO/USDT", "data":{"ts":1618677630564,"seqnum":32164169294,"asks":[["94.875","11.11"],["94.945","11.01"],["94.967","0"]],"bids":[["94.525","0"]]}}
1618677630.966471: {"m":"depth","symbol":"NEO/USDT", "data":{"ts":1618677630580,"seqnum":32164169295,"asks":[],"bids":[["94.453","10.27"]]}}
1618677631.362676: {"m":"depth","symbol":"ZIG/USDT", "data":{"ts":1618677631174,"seqnum":15360487482,"asks":[],"bids":[["0.090862","0"]]}}
1618677631.3628201: {"m":"depth","symbol":"ROOM/USDT", "data":{"ts":1618677631002,"seqnum":15303408703,"asks":[],"bids":[["1.7947","167.2"]]}}
1618677631.6699488: {"m":"depth","symbol":"CHZ/USDT", "data":{"ts":1618677631455,"seqnum":21034366168,"asks":[["0.636906","2273"],["0.636912","0"]],"bids":[]}}
1618677631.670114: {"m":"depth","symbol":"NEO/USDT", "data":{"ts":1618677631419,"seqnum":32164169296,"asks":[["95.044","0"],["95.084","11.81"],["95.114","129"],["95.125","12.24"],["95.135","38.17"],["95.145","3.36"],["95.155","39.69"],["95.185","45.08"],["95.195","9.56"],["95.215","13.57"],["95.225","0"],["95.255","31.82"],["95.265","50.3"],["95.285","7.73"],["95.305","18.74"],["95.325","1.61"],["95.335","21.24"],["95.345","11.45"],["95.355","9.1"],["95.365","4.58"],["95.385","54.93"],["95.395","13.22"],["95.415","0"],["95.445","20.75"],["95.456","58.24"],["95.476","15.28"],["95.766","7.96"],["95.787","9.79"],["95.857","21.72"],["95.937","0"],["95.947","0"],["95.957","0"],["95.967","0"],["95.977","0"]],"bids":[["94.483","10.11"],["94.463","3"],["94.433","0"],["94.423","0"],["94.403","181.35"],["94.393","0.23"],["94.363","11.07"],["94.343","61.6"],["94.333","37.09"],["94.323","0"],["94.244","5.6"],["94.194","58.41"],["94.184","22.89"],["94.064","0"],["93.994","0"],["93.925","12.81"],["93.721","0"],["93.607","0"],["93.536","17.24"],["93.476","0"],["93.267","4.92"],["93.245","1993.53"],["93.033","0"]]}}
1618677631.897763: {"m":"depth","symbol":"XDAI/USDT", "data":{"ts":1618677631756,"seqnum":14842030536,"asks":[],"bids":[["1.0004","0"]]}}
1618677631.897907: {"m":"depth","symbol":"CHZ/USDT", "data":{"ts":1618677631759,"seqnum":21034366169,"asks":[],"bids":[["0.625055","0"]]}}
1618677631.897978: {"m":"depth","symbol":"SRM/BTC", "data":{"ts":1618677631641,"seqnum":14844468779,"asks":[],"bids":[["0.00011224","122"]]}}
1618677631.909137: {"m":"depth","symbol":"CHR/USDT", "data":{"ts":1618677631544,"seqnum":45632691691,"asks":[],"bids":[["0.34532","869"]]}}
1618677632.203159: {"m":"depth","symbol":"EGLD/USDT", "data":{"ts":1618677631856,"seqnum":14843382654,"asks":[],"bids":[["209.1824","0"]]}}
1618677632.2033012: {"m":"depth","symbol":"XDAI/USDT", "data":{"ts":1618677632079,"seqnum":14842030537,"asks":[],"bids":[["1.0004","15.4"]]}}
1618677632.203373: {"m":"depth","symbol":"CHZ/USDT", "data":{"ts":1618677632128,"seqnum":21034366170,"asks":[["0.636907","0"]],"bids":[]}}
1618677632.203439: {"m":"depth","symbol":"NEO/USDT", "data":{"ts":1618677632030,"seqnum":32164169297,"asks":[],"bids":[["94.453","0"],["94.441","10.27"],["93.626","1.15"]]}}
1618677632.51474: {"m":"depth","symbol":"EGLD/USDT", "data":{"ts":1618677632332,"seqnum":14843382655,"asks":[],"bids":[["209.1826","10.76"]]}}
1618677632.5148768: {"m":"depth","symbol":"CHZ/USDT", "data":{"ts":1618677632218,"seqnum":21034366171,"asks":[["0.636904","600"]],"bids":[["0.625859","1647"]]}}
1618677632.5149598: {"m":"depth","symbol":"NEO/USDT", "data":{"ts":1618677632226,"seqnum":32164169298,"asks":[],"bids":[["94.478","0"]]}}
1618677632.901824: {"m":"depth","symbol":"CHZ/USDT", "data":{"ts":1618677632533,"seqnum":21034366172,"asks":[],"bids":[["0.625158","0"]]}}
1618677632.901972: {"m":"depth","symbol":"ALTBULL/USDT", "data":{"ts":1618677632446,"seqnum":21031929400,"asks":[],"bids":[["1403","1.349"]]}}
1618677632.9020438: {"m":"depth","symbol":"NEO/USDT", "data":{"ts":1618677632556,"seqnum":32164169299,"asks":[],"bids":[["94.507","11.01"]]}}
1618677633.205884: {"m":"depth","symbol":"SRM/BTC", "data":{"ts":1618677632988,"seqnum":14844468780,"asks":[],"bids":[["0.000112241","66"]]}}
1618677633.206023: {"m":"depth","symbol":"CHZ/USDT", "data":{"ts":1618677632860,"seqnum":21034366173,"asks":[],"bids":[["0.625814","3295"]]}}
1618677633.2060921: {"m":"depth","symbol":"NEO/USDT", "data":{"ts":1618677632930,"seqnum":32164169300,"asks":[["95.531","0"]],"bids":[]}}
1618677633.5141492: {"m":"depth","symbol":"CHZ/USDT", "data":{"ts":1618677633193,"seqnum":21034366174,"asks":[["0.636903","13"]],"bids":[["0.625396","1644"],["0.625088","0"],["0.624085","3289"],["0.622903","0"]]}}
1618677634.0669298: {"m":"depth","symbol":"EGLD/USDT", "data":{"ts":1618677633817,"seqnum":14843382656,"asks":[],"bids":[["209.1827","4.49"],["209.1825","0"]]}}
1618677634.0670888: {"m":"depth","symbol":"CHZ/USDT", "data":{"ts":1618677633851,"seqnum":21034366175,"asks":[["0.636902","2273"],["0.636906","0"]],"bids":[]}}
1618677634.088031: {"m":"depth","symbol":"NEO/USDT", "data":{"ts":1618677633967,"seqnum":32164169301,"asks":[],"bids":[["93.734","374.2"]]}}
1618677634.3642828: {"m":"depth","symbol":"ZIG/USDT", "data":{"ts":1618677634250,"seqnum":15360487483,"asks":[],"bids":[["0.090708","3307"]]}}
1618677634.374966: {"m":"depth","symbol":"CHZ/USDT", "data":{"ts":1618677634228,"seqnum":21034366176,"asks":[["0.6369","600"],["0.636904","0"]],"bids":[["0.622904","0"]]}}
1618677634.375149: {"m":"depth","symbol":"NEO/USDT", "data":{"ts":1618677634274,"seqnum":32164169302,"asks":[["95.074","0"],["95.084","0"],["95.104","59.27"],["95.114","164.1"],["95.125","61.64"],["95.135","0.14"],["95.145","96.67"],["95.155","20.56"],["95.165","22.89"],["95.195","4.55"],["95.205","36.56"],["95.596","195"],["95.636","18.75"],["95.706","0"],["95.907","0"]],"bids":[["94.525","10.27"],["94.483","1.28"],["94.441","0"],["94.433","12.67"],["94.413","12.14"],["94.403","341"],["94.393","2.1"],["94.373","0.12"],["94.363","11.19"],["94.353","9.55"],["94.343","48.78"],["94.333","49.44"],["94.303","12.51"],["94.283","52"],["94.273","0"],["94.254","10.14"],["94.244","54.42"],["94.234","93.94"],["94.224","19.82"],["94.214","25.74"],["94.204","0"],["94.184","0"],["94.174","0.31"],["93.267","0"]]}}
1618677634.683181: {"m":"depth","symbol":"SRM/BTC", "data":{"ts":1618677634591,"seqnum":14844468781,"asks":[["0.0001126","0"]],"bids":[]}}
1618677634.683329: {"m":"depth","symbol":"NEO/USDT", "data":{"ts":1618677634522,"seqnum":32164169303,"asks":[["94.875","0"],["94.923","12.49"]],"bids":[]}}
1618677635.052014: {"m":"depth","symbol":"CHZ/USDT", "data":{"ts":1618677634711,"seqnum":21034366177,"asks":[],"bids":[["0.624086","1826"]]}}
1618677635.0521119: {"m":"depth","symbol":"NEO/USDT", "data":{"ts":1618677634912,"seqnum":32164169304,"asks":[["94.875","12.49"],["94.923","0"]],"bids":[["94.525","10.27"]]}}
1618677635.360694: {"m":"depth","symbol":"SRM/BTC", "data":{"ts":1618677634966,"seqnum":14844468782,"asks":[["0.000112588","307"]],"bids":[]}}
1618677635.360836: {"m":"depth","symbol":"NEO/USDT", "data":{"ts":1618677634929,"seqnum":32164169305,"asks":[],"bids":[["94.525","0"]]}}
1618677635.663674: {"m":"depth","symbol":"ZIG/USDT", "data":{"ts":1618677635458,"seqnum":15360487484,"asks":[["0.097998","0"]],"bids":[]}}
1618677635.663817: {"m":"depth","symbol":"NEO/USDT", "data":{"ts":1618677635239,"seqnum":32164169306,"asks":[],"bids":[["94.524","0"]]}}
1618677635.939753: {"m":"depth","symbol":"EGLD/USDT", "data":{"ts":1618677635831,"seqnum":14843382657,"asks":[],"bids":[["209.1826","0"]]}}
1618677635.939896: {"m":"depth","symbol":"NEO/USDT", "data":{"ts":1618677635629,"seqnum":32164169307,"asks":[["94.945","0"],["94.951","0"]],"bids":[["94.533","22.02"],["93.734","0"]]}}
1618677636.238105: {"m":"depth","symbol":"NEO/USDT", "data":{"ts":1618677636088,"seqnum":32164169308,"asks":[["94.914","11.01"],["94.918","22.02"]],"bids":[["94.523","10.27"]]}}
1618677636.588494: {"m":"depth","symbol":"EGLD/USDT", "data":{"ts":1618677636376,"seqnum":14843382658,"asks":[],"bids":[["209.1828","10.76"]]}}
1618677636.588634: {"m":"depth","symbol":"CHZ/USDT", "data":{"ts":1618677636388,"seqnum":21034366178,"asks":[["0.636899","2273"],["0.636902","0"]],"bids":[]}}
1618677636.58873: {"m":"depth","symbol":"SRM/BTC", "data":{"ts":1618677636470,"seqnum":14844468783,"asks":[["0.000112665","153"],["0.000112688","0"]],"bids":[["0.000112241","0"]]}}
1618677636.588829: {"m":"depth","symbol":"NEO/USDT", "data":{"ts":1618677636343,"seqnum":32164169309,"asks":[["94.875","0"],["94.914","23.5"],["95.064","74.81"],["95.104","11.14"],["95.114","11.7"],["95.125","74.49"],["95.135","121.48"],["95.145","34.36"],["95.165","5.72"],["95.185","33.81"],["95.195","29.59"],["95.205","31.26"],["95.215","19.02"],["95.305","18.74"],["95.385","64.86"],["95.415","6.19"],["95.857","0"],["95.897","0"]],"bids":[["94.534","10.27"],["94.523","0"],["94.483","0.51"],["94.433","0"],["94.413","0"],["94.403","229.03"],["94.393","22.54"],["94.383","11.04"],["94.373","99.55"],["94.363","11.07"],["94.353","9.66"],["94.343","48.93"],["94.303","46.52"],["94.283","31.2"],["94.273","11.07"],["94.254","31.6"],["94.244","49.4"],["94.234","80.35"],["93.267","4.92"]]}}
1618677636.8956878: {"m":"depth","symbol":"SRM/BTC", "data":{"ts":1618677636681,"seqnum":14844468784,"asks":[["0.000112665","0"]],"bids":[["0.000112241","66"]]}}
1618677636.895863: {"m":"depth","symbol":"ALTBULL/USDT", "data":{"ts":1618677636580,"seqnum":21031929401,"asks":[["1442.7","0"]],"bids":[]}}
1618677636.89593: {"m":"depth","symbol":"NEO/USDT", "data":{"ts":1618677636539,"seqnum":32164169310,"asks":[["94.914","11.01"]],"bids":[]}}
1618677636.8959758: {"m":"depth","symbol":"CHR/USDT", "data":{"ts":1618677636637,"seqnum":45632691692,"asks":[["0.39673","0"],["0.39717","1164"]],"bids":[]}}
1618677637.2030568: {"m":"depth","symbol":"SRM/BTC", "data":{"ts":1618677637027,"seqnum":14844468785,"asks":[["0.000112594","0"],["0.000112685","153"]],"bids":[["0.000112241","0"]]}}
1618677637.203242: {"m":"depth","symbol":"NEO/USDT", "data":{"ts":1618677636859,"seqnum":32164169311,"asks":[["94.938","12.49"]],"bids":[["93.626","0"]]}}
1618677637.506755: {"m":"depth","symbol":"CHZ/USDT", "data":{"ts":1618677637226,"seqnum":21034366179,"asks":[["0.636898","600"],["0.6369","0"]],"bids":[]}}
1618677637.506929: {"m":"depth","symbol":"SRM/BTC", "data":{"ts":1618677637360,"seqnum":14844468786,"asks":[["0.000112529","69"],["0.000112576","153"],["0.000112583","0"]],"bids":[["0.000112231","66"],["0.000112101","0"],["0.000112047","55"]]}}
1618677637.507062: {"m":"depth","symbol":"NEO/USDT", "data":{"ts":1618677637315,"seqnum":32164169312,"asks":[["94.938","0"],["95.335","761.27"]],"bids":[]}}
1618677637.821121: {"m":"depth","symbol":"CHZ/USDT", "data":{"ts":1618677637509,"seqnum":21034366180,"asks":[],"bids":[["0.625859","0"]]}}
1618677637.821265: {"m":"depth","symbol":"SRM/BTC", "data":{"ts":1618677637669,"seqnum":14844468787,"asks":[],"bids":[["0.000112231","0"]]}}
1618677637.8213382: {"m":"depth","symbol":"NEO/USDT", "data":{"ts":1618677637675,"seqnum":32164169313,"asks":[["94.904","12.49"],["94.918","0"]],"bids":[["93.607","1.15"]]}}
1618677638.125062: {"m":"depth","symbol":"CHZ/USDT", "data":{"ts":1618677637895,"seqnum":21034366181,"asks":[],"bids":[["0.626573","1646"]]}}
1618677638.1251998: {"m":"depth","symbol":"SRM/BTC", "data":{"ts":1618677637895,"seqnum":14844468788,"asks":[],"bids":[["0.000112229","66"]]}}
1618677638.125272: {"m":"depth","symbol":"NEO/USDT", "data":{"ts":1618677637980,"seqnum":32164169314,"asks":[["94.875","12.49"],["94.904","0"],["94.918","22.01"]],"bids":[["94.534","0"],["94.507","0"]]}}
1618677638.428768: {"m":"depth","symbol":"CHZ/USDT", "data":{"ts":1618677638256,"seqnum":21034366182,"asks":[],"bids":[["0.625396","0"]]}}
1618677638.4289122: {"m":"depth","symbol":"NEO/USDT", "data":{"ts":1618677638200,"seqnum":32164169315,"asks":[],"bids":[["93.849","445.49"]]}}
1618677638.428991: {"m":"depth","symbol":"ALTBULL/USDT", "data":{"ts":1618677638174,"seqnum":21031929402,"asks":[["1442.7","1.345"]],"bids":[]}}
1618677638.7137961: {"m":"depth","symbol":"CHZ/USDT", "data":{"ts":1618677638412,"seqnum":21034366183,"asks":[],"bids":[["0.625867","1644"],["0.625814","0"]]}}
1618677638.7139578: {"m":"depth","symbol":"SRM/BTC", "data":{"ts":1618677638565,"seqnum":14844468789,"asks":[["0.000112528","66"]],"bids":[]}}
1618677638.7140281: {"m":"depth","symbol":"NEO/USDT", "data":{"ts":1618677638318,"seqnum":32164169316,"asks":[],"bids":[["94.528","11.01"]]}}
1618677639.022563: {"m":"depth","symbol":"CHZ/USDT", "data":{"ts":1618677638649,"seqnum":21034366184,"asks":[],"bids":[["0.626579","3292"]]}}
1618677639.0332952: {"m":"depth","symbol":"CHR/USDT", "data":{"ts":1618677638678,"seqnum":45632691693,"asks":[],"bids":[["0.37128","2635"]]}}
1618677639.332654: {"m":"depth","symbol":"EGLD/USDT", "data":{"ts":1618677639184,"seqnum":14843382659,"asks":[],"bids":[["209.1829","4.49"],["209.1827","0"]]}}
