1650929749.603894: {"m":"depth","symbol":"BTC-PERP", "data":{"ts":1650929749505,"seqnum":7795625656,"asks":[["40493","0.1298"],["40495","0.0026"],["40496","0"],["40497","0.1298"],["40500","0"]],"bids":[["40477","0"],["40475","0"],["40474","0"],["40473","0.2622"]]}}
1650929749.765266: {"m":"depth","symbol":"LINK-PERP", "data":{"ts":1650929749583,"seqnum":13069695688,"asks":[["13.487","0"],["13.49","28.5"],["13.491","226.2"],["13.495","40.7"],["13.499","22"],["13.502","49.9"],["13.506","148.1"],["13.51","434.2"]],"bids":[["13.47","4"],["13.467","785.3"],["13.465","676.1"],["13.462","1.9"],["13.458","601.9"],["13.455","84.5"],["13.451","203.5"],["13.447","352"]]}}
1650929749.8946528: {"m":"depth","symbol":"UNI-PERP", "data":{"ts":1650929749849,"seqnum":7795023594,"asks":[["8.77","948.4"]],"bids":[]}}
1650929749.894711: {"m":"depth","symbol":"APE-PERP", "data":{"ts":1650929749799,"seqnum":608730329,"asks":[["19.045","0"],["19.047","12"],["19.064","0"],["19.065","54"],["19.068","0"],["19.069","116"],["19.071","0"],["19.073","11"],["19.075","0"],["19.077","12"],["19.08","0"],["19.081","1178"]],"bids":[["19.044","2"],["19.024","94"],["19.023","0"],["19.02","93"],["19.018","0"],["19.017","295"],["19.014","0"],["19.013","11"],["19.01","0"],["19.009","91"],["19.006","0"]]}}
1650929749.895209: {"m":"depth","symbol":"DOT-PERP", "data":{"ts":1650929749615,"seqnum":13069591793,"asks":[["18.15","90.7"],["18.153","98.2"],["18.16","52.4"],["18.165","44.3"],["18.169","162.3"],["18.174","66.1"],["18.179","956.3"]],"bids":[["18.122","67.4"],["18.119","85.8"],["18.111","31.8"],["18.106","30"],["18.102","467"],["18.097","69.2"],["18.092","84.2"]]}}
1650929749.929652: {"m":"depth","symbol":"BTC-PERP", "data":{"ts":1650929749727,"seqnum":7795625657,"asks":[["40492","0.4108"],["40493","0"],["40497","0"],["40499","0"],["40500","2.9019"]],"bids":[["40483","2.4809"],["40482","0"],["40473","0.0026"]]}}
1650929750.223642: {"m":"depth","symbol":"BTC-PERP", "data":{"ts":1650929750032,"seqnum":7795625658,"asks":[["40493","0.1298"],["40497","0.1298"]],"bids":[["40477","0.1298"],["40475","0.1298"]]}}
1650929750.394479: {"m":"depth","symbol":"LINK-PERP", "data":{"ts":1650929750328,"seqnum":13069695689,"asks":[["13.487","395.9"]],"bids":[["13.47","399.9"]]}}
1650929750.536491: {"m":"depth","symbol":"BTC-PERP", "data":{"ts":1650929750508,"seqnum":7795625659,"asks":[["40492","0"],["40493","0"],["40497","0"],["40499","2.4313"],["40500","0"]],"bids":[["40483","0.3241"],["40482","2.7843"],["40477","0"],["40475","0"]]}}
1650929750.824022: {"m":"depth","symbol":"UNI-PERP", "data":{"ts":1650929750754,"seqnum":7795023595,"asks":[["8.77","3487.8"]],"bids":[]}}
1650929750.8245618: {"m":"depth","symbol":"DOT-PERP", "data":{"ts":1650929750812,"seqnum":13069591794,"asks":[["18.15","30"],["18.153","8.9"],["18.16","50.4"],["18.165","44.3"],["18.169","162.3"],["18.174","69"],["18.179","982.9"]],"bids":[["18.122","17.1"],["18.119","61.4"],["18.111","31.9"],["18.106","25.4"],["18.102","467.6"],["18.097","69.2"],["18.092","84.2"]]}}
1650929750.845381: {"m":"depth","symbol":"BTC-PERP", "data":{"ts":1650929750723,"seqnum":7795625660,"asks":[["40493","0.1298"],["40497","0.1298"],["40498","3.8927"],["40499","0"]],"bids":[["40482","0"],["40481","3.108"],["40474","0.1298"],["40473","0.1324"]]}}
1650929751.0247612: {"m":"depth","symbol":"LINK-PERP", "data":{"ts":1650929750782,"seqnum":13069695690,"asks":[["13.487","0"],["13.49","222.1"],["13.491","19"],["13.495","3.9"],["13.499","18.9"],["13.502","32.5"],["13.506","114.3"],["13.51","417.2"]],"bids":[["13.47","4"],["13.467","707.2"],["13.465","487.5"],["13.462","35.3"],["13.458","609.2"],["13.455","60.7"],["13.451","105.6"],["13.447","288.9"]]}}
1650929751.139863: {"m":"depth","symbol":"DOT-PERP", "data":{"ts":1650929750814,"seqnum":13069591795,"asks":[["18.179","956.3"]],"bids":[]}}
1650929751.139967: {"m":"depth","symbol":"UNI-PERP", "data":{"ts":1650929750852,"seqnum":7795023596,"asks":[["8.77","948.4"]],"bids":[]}}
1650929751.156595: {"m":"depth","symbol":"BTC-PERP", "data":{"ts":1650929751001,"seqnum":7795625661,"asks":[["40497","0.1298"],["40498","0.3241"],["40499","3.2941"]],"bids":[["40484","0"],["40482","3.3725"],["40481","0.1669"],["40480","0.0114"]]}}
1650929751.344683: {"m":"depth","symbol":"LINK-PERP", "data":{"ts":1650929751234,"seqnum":13069695691,"asks":[["13.485","38.8"],["13.487","395.9"]],"bids":[["13.47","399.9"],["13.464","57.5"]]}}
1650929751.465868: {"m":"depth","symbol":"BTC-PERP", "data":{"ts":1650929751456,"seqnum":7795625662,"asks":[["40498","0.3241"],["40499","2.4313"]],"bids":[["40482","3.4117"],["40481","0.1669"]]}}
1650929751.76425: {"m":"depth","symbol":"DOT-PERP", "data":{"ts":1650929751737,"seqnum":13069591796,"asks":[["18.14","0"]],"bids":[["18.124","0"]]}}
1650929751.764328: {"m":"depth","symbol":"APE-PERP", "data":{"ts":1650929751613,"seqnum":608730330,"asks":[["19.045","165"],["19.047","0"],["19.064","82"],["19.065","0"],["19.068","72"],["19.069","0"],["19.073","11"],["19.077","14"],["19.081","85"]],"bids":[["19.044","0"],["19.042","79"],["19.024","0"],["19.021","37"],["19.02","0"],["19.017","115"],["19.013","0"],["19.012","47"],["19.009","0"],["19.008","175"],["19.004","37"]]}}
1650929752.066101: {"m":"depth","symbol":"DOT-PERP", "data":{"ts":1650929751741,"seqnum":13069591797,"asks":[["18.141","33"]],"bids":[["18.125","42.7"]]}}
1650929752.0662138: {"m":"depth","symbol":"UNI-PERP", "data":{"ts":1650929751799,"seqnum":7795023597,"asks":[["8.77","948.4"]],"bids":[]}}
1650929752.089222: {"m":"depth","symbol":"BTC-PERP", "data":{"ts":1650929751977,"seqnum":7795625663,"asks":[["40498","0.3241"],["40499","2.9019"]],"bids":[["40482","3.3725"],["40481","0.1669"]]}}
1650929752.624737: {"m":"depth","symbol":"LINK-PERP", "data":{"ts":1650929752586,"seqnum":13069695692,"asks":[["13.487","395.9"],["13.49","261.7"],["13.491","28.9"],["13.495","9.6"],["13.496","584"],["13.499","12.6"],["13.502","37.6"],["13.506","111.9"],["13.51","451"]],"bids":[["13.47","399.9"],["13.467","651.7"],["13.465","537.2"],["13.462","36.6"],["13.458","647.9"],["13.455","72.9"],["13.451","67.8"],["13.447","288.9"]]}}
1650929752.6859891: {"m":"depth","symbol":"DOT-PERP", "data":{"ts":1650929752638,"seqnum":13069591798,"asks":[["18.141","0"],["18.142","49.8"],["18.15","96.8"],["18.153","32.5"],["18.16","1"],["18.165","3.1"],["18.169","23.8"],["18.174","24.3"],["18.179","969.3"]],"bids":[["18.126","150.2"],["18.125","0"],["18.122","32.8"],["18.119","1.5"],["18.111","91.4"],["18.106","47.4"],["18.102","478.3"],["18.097","130.3"],["18.092","85.6"]]}}
1650929752.705109: {"m":"depth","symbol":"BTC-PERP", "data":{"ts":1650929752494,"seqnum":7795625664,"asks":[["40498","3.3045"],["40499","0"]],"bids":[["40482","0"],["40481","4.01"]]}}
1650929753.107339: {"m":"depth","symbol":"UNI-PERP", "data":{"ts":1650929752825,"seqnum":7795023598,"asks":[["8.77","948.4"]],"bids":[]}}
1650929753.107445: {"m":"depth","symbol":"APE-PERP", "data":{"ts":1650929752808,"seqnum":608730331,"asks":[["19.045","0"],["19.064","0"],["19.068","0"],["19.07","189"],["19.073","0"],["19.077","0"],["19.081","0"],["19.088","11"],["19.092","11"],["19.095","92"],["19.099","27"],["19.103","11"]],"bids":[["19.047","97"],["19.043","176"],["19.042","0"],["19.04","11"],["19.036","107"],["19.032","20"],["19.021","0"],["19.017","0"],["19.012","0"],["19.008","0"],["19.004","0"]]}}
1650929753.107636: {"m":"depth","symbol":"BTC-PERP", "data":{"ts":1650929753002,"seqnum":7795625665,"asks":[["40498","0.3241"],["40500","2.549"]],"bids":[["40483","3.6182"],["40481","0.1669"]]}}
1650929753.308553: {"m":"depth","symbol":"DOT-PERP", "data":{"ts":1650929753161,"seqnum":13069591799,"asks":[],"bids":[["18.126","101.1"],["18.125","64.7"]]}}
1650929753.324918: {"m":"depth","symbol":"BTC-PERP", "data":{"ts":1650929753277,"seqnum":7795625666,"asks":[["40499","3.8431"],["40500","0"]],"bids":[["40483","0.3241"],["40482","2.5882"]]}}
1650929753.722232: {"m":"depth","symbol":"DOT-PERP", "data":{"ts":1650929753603,"seqnum":13069591800,"asks":[],"bids":[["18.126","101.1"],["18.125","54.3"]]}}
1650929753.722352: {"m":"depth","symbol":"BTC-PERP", "data":{"ts":1650929753589,"seqnum":7795625667,"asks":[["40499","0"],["40500","2.196"]],"bids":[["40483","2.8731"],["40482","0"]]}}
1650929753.8955038: {"m":"depth","symbol":"LINK-PERP", "data":{"ts":1650929753774,"seqnum":13069695693,"asks":[["13.487","395.9"],["13.49","260.6"],["13.491","69.3"],["13.495","9.9"],["13.499","12.6"],["13.502","44"],["13.506","128.7"],["13.51","418.4"]],"bids":[["13.47","399.9"],["13.467","842.7"],["13.465","407.8"],["13.462","57.1"],["13.458","648.9"],["13.455","79.2"],["13.451","71.9"],["13.447","288.9"]]}}
1650929753.92851: {"m":"depth","symbol":"UNI-PERP", "data":{"ts":1650929753857,"seqnum":7795023599,"asks":[["8.77","948.4"]],"bids":[]}}
1650929753.928616: {"m":"depth","symbol":"DOT-PERP", "data":{"ts":1650929753826,"seqnum":13069591801,"asks":[["18.141","49.1"],["18.142","0"],["18.15","34.4"],["18.153","20.2"],["18.16","1.1"],["18.165","1"],["18.169","21.5"],["18.174","19.2"],["18.179","959.1"]],"bids":[["18.122","8.2"],["18.119","98.8"],["18.111","92.1"],["18.106","47.4"],["18.102","496"],["18.097","209.8"],["18.092","100"]]}}
1650929753.9481611: {"m":"depth","symbol":"BTC-PERP", "data":{"ts":1650929753765,"seqnum":7795625668,"asks":[["40499","2.9019"],["40500","0"]],"bids":[["40483","0.3241"],["40482","2.7843"]]}}
1650929754.235831: {"m":"depth","symbol":"DOT-PERP", "data":{"ts":1650929754231,"seqnum":13069591802,"asks":[["18.141","0"],["18.142","45.2"]],"bids":[["18.126","147"],["18.125","0"]]}}
1650929754.5462441: {"m":"depth","symbol":"DOT-PERP", "data":{"ts":1650929754399,"seqnum":13069591803,"asks":[],"bids":[["18.126","136"]]}}
1650929754.860132: {"m":"depth","symbol":"LINK-PERP", "data":{"ts":1650929754819,"seqnum":13069695694,"asks":[["13.487","0"]],"bids":[["13.47","4"]]}}
1650929754.860252: {"m":"depth","symbol":"APE-PERP", "data":{"ts":1650929754619,"seqnum":608730332,"asks":[["19.07","0"],["19.088","0"],["19.091","87"],["19.092","0"],["19.095","0"],["19.099","0"],["19.103","0"],["19.11","85"],["19.114","11"],["19.117","27"],["19.121","24"],["19.125","85"]],"bids":[["19.068","18"],["19.064","228"],["19.061","11"],["19.057","64"],["19.053","31"],["19.047","0"],["19.043","0"],["19.04","0"],["19.036","0"],["19.032","0"]]}}
1650929754.860432: {"m":"depth","symbol":"UNI-PERP", "data":{"ts":1650929754805,"seqnum":7795023600,"asks":[["8.77","3480.1"]],"bids":[]}}
1650929755.169837: {"m":"depth","symbol":"LINK-PERP", "data":{"ts":1650929755037,"seqnum":13069695695,"asks":[["13.487","395.9"]],"bids":[["13.47","399.9"]]}}
1650929755.1699488: {"m":"depth","symbol":"UNI-PERP", "data":{"ts":1650929754907,"seqnum":7795023601,"asks":[["8.77","948.4"]],"bids":[]}}
1650929755.1897159: {"m":"depth","symbol":"BTC-PERP", "data":{"ts":1650929755015,"seqnum":7795625669,"asks":[["40490","0.1298"],["40493","0"],["40496","0.1298"],["40497","0"]],"bids":[["40474","0.2596"],["40473","0.0026"]]}}
1650929755.4784791: {"m":"depth","symbol":"DOT-PERP", "data":{"ts":1650929755229,"seqnum":13069591804,"asks":[["18.141","40.7"],["18.142","0"]],"bids":[["18.126","101.1"],["18.125","58.8"]]}}
1650929755.494417: {"m":"depth","symbol":"BTC-PERP", "data":{"ts":1650929755347,"seqnum":7795625670,"asks":[["40499","3.2549"]],"bids":[["40483","0.3241"],["40482","2.3529"]]}}
1650929755.785068: {"m":"depth","symbol":"LINK-PERP", "data":{"ts":1650929755603,"seqnum":13069695696,"asks":[["13.487","0"],["13.49","101.1"],["13.491","297.8"],["13.495","10.5"],["13.499","12.6"],["13.502","45.7"],["13.506","145.4"],["13.51","689"]],"bids":[["13.47","4"],["13.467","798"],["13.465","431.7"],["13.462","54.8"],["13.458","648.9"],["13.455","66.8"],["13.451","68"],["13.447","288.9"]]}}
1650929755.785259: {"m":"depth","symbol":"DOT-PERP", "data":{"ts":1650929755653,"seqnum":13069591805,"asks":[["18.15","52.1"],["18.153","85.7"],["18.16","0"],["18.161","1.3"],["18.165","0"],["18.166","1.4"],["18.169","0"],["18.17","55.5"],["18.174","0"],["18.175","44.3"],["18.179","929.7"],["18.18","63.9"]],"bids":[["18.122","81.5"],["18.119","26.6"],["18.112","85.6"],["18.111","0"],["18.107","59.4"],["18.106","0"],["18.103","124"],["18.102","433.9"],["18.098","29.9"],["18.097","0"],["18.093","164.1"],["18.092","0"]]}}
1650929756.094055: {"m":"depth","symbol":"LINK-PERP", "data":{"ts":1650929755875,"seqnum":13069695697,"asks":[],"bids":[["13.459","633.9"],["13.458","51.4"]]}}
1650929756.094173: {"m":"depth","symbol":"UNI-PERP", "data":{"ts":1650929755950,"seqnum":7795023602,"asks":[["8.77","948.4"]],"bids":[]}}
1650929756.094622: {"m":"depth","symbol":"APE-PERP", "data":{"ts":1650929755815,"seqnum":608730333,"asks":[["19.091","0"],["19.11","0"],["19.111","93"],["19.114","0"],["19.117","0"],["19.121","0"],["19.125","0"],["19.13","90"],["19.134","11"],["19.137","11"],["19.141","18"],["19.146","121"]],"bids":[["19.088","15"],["19.083","44"],["19.08","123"],["19.076","91"],["19.071","11"],["19.068","0"],["19.064","0"],["19.061","0"],["19.057","0"],["19.053","0"]]}}
1650929756.116889: {"m":"depth","symbol":"BTC-PERP", "data":{"ts":1650929756022,"seqnum":7795625671,"asks":[["40489","0.2499"],["40490","0"],["40494","0.1298"],["40495","0.1617"],["40498","0.3241"],["40499","3.8823"]],"bids":[["40482","2.7843"],["40481","0.1669"],["40474","0.1298"],["40473","0.1324"]]}}
1650929756.4058828: {"m":"depth","symbol":"LINK-PERP", "data":{"ts":1650929756185,"seqnum":13069695698,"asks":[["13.487","395.9"]],"bids":[["13.468","395.9"]]}}
1650929756.4060001: {"m":"depth","symbol":"DOT-PERP", "data":{"ts":1650929756390,"seqnum":13069591806,"asks":[["18.141","0"],["18.142","62.1"]],"bids":[["18.126","137.3"],["18.125","0"]]}}
1650929756.4060748: {"m":"depth","symbol":"AKT-PERP", "data":{"ts":1650929756396,"seqnum":7794290672,"asks":[["1.079","242"]],"bids":[]}}
1650929756.4259431: {"m":"depth","symbol":"BTC-PERP", "data":{"ts":1650929756266,"seqnum":7795625672,"asks":[["40499","0"],["40500","3.6078"]],"bids":[["40483","2.6378"],["40482","0"]]}}
1650929756.7190442: {"m":"depth","symbol":"DOT-PERP", "data":{"ts":1650929756449,"seqnum":13069591807,"asks":[["18.141","64.7"],["18.142","0"]],"bids":[["18.126","101.1"],["18.125","49.8"]]}}
1650929756.73737: {"m":"depth","symbol":"BTC-PERP", "data":{"ts":1650929756550,"seqnum":7795625673,"asks":[["40489","0"],["40495","0.0026"],["40499","2.3921"],["40500","0"]],"bids":[["40483","0.3241"],["40482","3.0196"],["40481","0"],["40475","0.2447"]]}}
1650929757.025235: {"m":"depth","symbol":"LINK-PERP", "data":{"ts":1650929756792,"seqnum":13069695699,"asks":[["13.49","179.6"],["13.491","125.2"],["13.495","10.5"],["13.499","12.6"],["13.502","36.4"],["13.506","111.9"],["13.51","418.4"]],"bids":[["13.467","822.2"],["13.465","494"],["13.462","57.2"],["13.458","51.4"],["13.455","66.8"],["13.451","85.2"],["13.447","303"]]}}
1650929757.025358: {"m":"depth","symbol":"UNI-PERP", "data":{"ts":1650929756916,"seqnum":7795023603,"asks":[["8.77","948.4"]],"bids":[]}}
1650929757.025388: {"m":"depth","symbol":"DOT-PERP", "data":{"ts":1650929756962,"seqnum":13069591808,"asks":[["18.141","0"],["18.143","43.9"],["18.15","6.1"],["18.153","15.2"],["18.161","1.5"],["18.166","9.1"],["18.17","55.8"],["18.175","34.5"],["18.18","42.5"]],"bids":[["18.127","36.2"],["18.126","101.1"],["18.125","0"],["18.122","41.5"],["18.119","45.1"],["18.112","107.5"],["18.107","19.6"],["18.103","65.6"],["18.098","83.8"],["18.093","120.3"]]}}
1650929757.046128: {"m":"depth","symbol":"BTC-PERP", "data":{"ts":1650929757014,"seqnum":7795625674,"asks":[["40499","0"],["40500","3.8039"]],"bids":[["40483","3.226"],["40482","0"],["40475","0"]]}}
1650929757.3362648: {"m":"depth","symbol":"DOT-PERP", "data":{"ts":1650929757294,"seqnum":13069591809,"asks":[],"bids":[["18.127","0"],["18.126","161.2"]]}}
1650929757.353599: {"m":"depth","symbol":"BTC-PERP", "data":{"ts":1650929757211,"seqnum":7795625675,"asks":[["40499","3.4509"],["40500","0"]],"bids":[["40483","0.3241"],["40482","2.3137"]]}}
1650929757.710592: {"m":"depth","symbol":"DOT-PERP", "data":{"ts":1650929757430,"seqnum":13069591810,"asks":[["18.142","64.7"],["18.143","0"]],"bids":[]}}
1650929757.710706: {"m":"depth","symbol":"APE-PERP", "data":{"ts":1650929757624,"seqnum":608730334,"asks":[["19.111","0"],["19.12","172"],["19.13","0"],["19.134","0"],["19.137","0"],["19.141","103"],["19.146","98"],["19.158","26"],["19.162","15"],["19.166","82"]],"bids":[["19.095","11"],["19.091","11"],["19.088","0"],["19.083","0"],["19.081","26"],["19.08","0"],["19.077","11"],["19.076","0"],["19.073","53"],["19.071","0"]]}}
1650929757.955188: {"m":"depth","symbol":"LINK-PERP", "data":{"ts":1650929757854,"seqnum":13069695700,"asks":[["13.487","0"],["13.488","785.2"]],"bids":[["13.468","395.9"]]}}
1650929757.955312: {"m":"depth","symbol":"UNI-PERP", "data":{"ts":1650929757947,"seqnum":7795023604,"asks":[["8.77","948.4"]],"bids":[]}}
1650929757.974771: {"m":"depth","symbol":"BTC-PERP", "data":{"ts":1650929757935,"seqnum":7795625676,"asks":[["40498","0.3241"],["40499","2"]],"bids":[["40482","2.9411"]]}}
1650929758.2885811: {"m":"depth","symbol":"BTC-PERP", "data":{"ts":1650929758052,"seqnum":7795625677,"asks":[["40499","0"],["40500","3.0588"]],"bids":[["40483","3.6966"],["40482","0"]]}}
1650929758.8901582: {"m":"depth","symbol":"LINK-PERP", "data":{"ts":1650929758589,"seqnum":13069695701,"asks":[["13.49","110.6"],["13.491","67.5"],["13.495","10.4"],["13.499","12.6"],["13.502","36.4"],["13.506","131"],["13.51","510.1"]],"bids":[["13.467","823.6"],["13.465","555.1"],["13.462","43.6"],["13.458","51.4"],["13.455","128.6"],["13.451","193.5"],["13.447","299.8"]]}}
1650929758.890336: {"m":"depth","symbol":"UNI-PERP", "data":{"ts":1650929758861,"seqnum":7795023605,"asks":[["8.77","3469.7"]],"bids":[]}}
1650929758.890382: {"m":"depth","symbol":"AKT-PERP", "data":{"ts":1650929758856,"seqnum":7794290673,"asks":[["1.0982","0"]],"bids":[["1.0488","0"]]}}
1650929758.890431: {"m":"depth","symbol":"DOT-PERP", "data":{"ts":1650929758876,"seqnum":13069591811,"asks":[["18.142","0"],["18.15","0"],["18.153","50.6"],["18.156","93.4"],["18.161","0"],["18.163","17.6"],["18.166","0"],["18.168","21.3"],["18.17","0"],["18.172","23"],["18.175","0"],["18.177","134"],["18.18","0"],["18.182","116.5"]],"bids":[["18.127","43.3"],["18.126","101.1"],["18.125","81.7"],["18.122","37.5"],["18.119","0"],["18.114","31.5"],["18.112","0"],["18.109","3.9"],["18.107","0"],["18.105","44.2"],["18.103","0"],["18.1","24.3"],["18.098","0"],["18.095","75.4"],["18.093","0"]]}}
1650929758.890626: {"m":"depth","symbol":"APE-PERP", "data":{"ts":1650929758823,"seqnum":608730335,"asks":[["19.104","54"],["19.12","0"],["19.124","11"],["19.128","11"],["19.131","80"],["19.135","19"],["19.139","85"],["19.141","0"],["19.146","0"],["19.158","0"],["19.162","0"],["19.166","0"]],"bids":[["19.101","177"],["19.095","0"],["19.091","0"],["19.081","0"],["19.08","16"],["19.077","0"],["19.076","34"],["19.073","11"],["19.069","23"],["19.065","30"]]}}
1650929758.906473: {"m":"depth","symbol":"BTC-PERP", "data":{"ts":1650929758780,"seqnum":7795625678,"asks":[["40496","0"],["40499","0.1298"],["40500","2.9019"]],"bids":[["40483","3.3045"],["40476","0.1298"],["40474","0"]]}}
1650929759.199712: {"m":"depth","symbol":"UNI-PERP", "data":{"ts":1650929758976,"seqnum":7795023606,"asks":[["8.77","948.4"]],"bids":[]}}
1650929759.199761: {"m":"depth","symbol":"DOT-PERP", "data":{"ts":1650929759165,"seqnum":13069591812,"asks":[["18.143","56.2"]],"bids":[["18.127","0"],["18.126","134.7"]]}}
1650929759.213953: {"m":"depth","symbol":"BTC-PERP", "data":{"ts":1650929758968,"seqnum":7795625679,"asks":[["40500","0"],["40501","3.098"]],"bids":[["40484","3.9215"],["40483","0.3241"]]}}
1650929759.505912: {"m":"depth","symbol":"DOT-PERP", "data":{"ts":1650929759402,"seqnum":13069591813,"asks":[["18.142","45.2"],["18.143","0"]],"bids":[["18.126","139.2"]]}}
1650929759.5239308: {"m":"depth","symbol":"BTC-PERP", "data":{"ts":1650929759339,"seqnum":7795625680,"asks":[["40494","0"],["40499","0"],["40500","2.6666"],["40501","0"]],"bids":[["40484","0"],["40483","3.9319"],["40476","0"],["40473","0.0026"]]}}
1650929759.816309: {"m":"depth","symbol":"LINK-PERP", "data":{"ts":1650929759789,"seqnum":13069695702,"asks":[["13.487","395.9"],["13.488","389.3"],["13.49","46.4"],["13.491","205.3"],["13.495","10.5"],["13.499","12.6"],["13.5","8.1"],["13.501","16.2"],["13.502","623.1"],["13.506","131"],["13.51","459.5"]],"bids":[["13.47","399.9"],["13.468","0"],["13.467","606.3"],["13.465","610.6"],["13.462","43.5"],["13.458","51.4"],["13.455","128.6"],["13.451","193.5"],["13.447","299.8"]]}}
1650929759.8343942: {"m":"depth","symbol":"BTC-PERP", "data":{"ts":1650929759721,"seqnum":7795625681,"asks":[["40495","0.1298"],["40496","0.0026"],["40499","0.1298"],["40500","0"],["40501","3.1764"],["40502","0.3241"]],"bids":[["40484","3.6862"],["40483","0.3241"],["40476","0.1298"],["40475","0.1298"],["40474","0.0026"],["40473","0"]]}}
1650929760.130933: {"m":"depth","symbol":"UNI-PERP", "data":{"ts":1650929759904,"seqnum":7795023607,"asks":[["8.77","948.4"]],"bids":[]}}
1650929760.1310441: {"m":"depth","symbol":"AKT-PERP", "data":{"ts":1650929759870,"seqnum":7794290674,"asks":[["1.0982","3000"]],"bids":[["1.0488","3000"]]}}
1650929760.1311119: {"m":"depth","symbol":"DOT-PERP", "data":{"ts":1650929759842,"seqnum":13069591814,"asks":[["18.153","57.7"],["18.156","57.2"],["18.163","15.3"],["18.168","77.1"],["18.172","35.7"],["18.177","94.5"],["18.182","45.1"]],"bids":[["18.125","14.9"],["18.122","6.2"],["18.114","32.1"],["18.109","6.5"],["18.105","58.9"],["18.1","47.3"],["18.095","137.1"]]}}
1650929760.144528: {"m":"depth","symbol":"BTC-PERP", "data":{"ts":1650929759947,"seqnum":7795625682,"asks":[["40499","2.2082"],["40501","0"]],"bids":[["40484","0"],["40483","0.3241"],["40482","2.8627"]]}}
1650929760.4561121: {"m":"depth","symbol":"BTC-PERP", "data":{"ts":1650929760177,"seqnum":7795625683,"asks":[["40499","0.1298"],["40500","3.8431"]],"bids":[["40483","3.3045"],["40482","0"]]}}
1650929760.745018: {"m":"depth","symbol":"APE-PERP", "data":{"ts":1650929760662,"seqnum":608730336,"asks":[["19.104","0"],["19.124","0"],["19.128","0"],["19.131","0"],["19.135","0"],["19.139","0"],["19.141","124"],["19.159","66"],["19.163","713"],["19.166","11"],["19.17","53"],["19.174","157"]],"bids":[["19.118","499"],["19.112","11"],["19.109","112"],["19.105","77"],["19.101","0"],["19.1","120"],["19.08","0"],["19.076","0"],["19.073","0"],["19.069","0"],["19.065","0"]]}}
1650929760.767829: {"m":"depth","symbol":"BTC-PERP", "data":{"ts":1650929760594,"seqnum":7795625684,"asks":[["40499","3.9729"],["40500","0"]],"bids":[["40483","0.3241"],["40482","2.549"]]}}
1650929761.095444: {"m":"depth","symbol":"LINK-PERP", "data":{"ts":1650929760824,"seqnum":13069695703,"asks":[["13.487","0"]],"bids":[["13.47","4"]]}}
1650929761.095567: {"m":"depth","symbol":"UNI-PERP", "data":{"ts":1650929760887,"seqnum":7795023608,"asks":[["8.77","3473"]],"bids":[]}}
1650929761.095614: {"m":"depth","symbol":"BTC-PERP", "data":{"ts":1650929761054,"seqnum":7795625685,"asks":[["40499","0.1298"],["40500","3.4902"]],"bids":[["40483","2.7554"],["40482","0"]]}}
1650929761.3658721: {"m":"depth","symbol":"LINK-PERP", "data":{"ts":1650929761284,"seqnum":13069695704,"asks":[["13.489","395.9"]],"bids":[["13.47","399.9"]]}}
1650929761.384127: {"m":"depth","symbol":"BTC-PERP", "data":{"ts":1650929761293,"seqnum":7795625686,"asks":[["40499","0.1298"],["40500","3.8431"]],"bids":[["40483","2.7946"]]}}
1650929761.677953: {"m":"depth","symbol":"LINK-PERP", "data":{"ts":1650929761598,"seqnum":13069695705,"asks":[["13.49","0"],["13.491","50.2"],["13.492","109.3"],["13.495","0"],["13.496","606.6"],["13.499","4"],["13.5","44.5"],["13.502","586.7"],["13.503","19.4"],["13.506","104.2"],["13.507","292.2"],["13.51","382.4"],["13.511","274"]],"bids":[["13.468","227.3"],["13.467","588.3"],["13.466","265.8"],["13.465","389.3"],["13.463","42.3"],["13.462","0"],["13.459","670"],["13.458","0"],["13.456","37.6"],["13.455","0"],["13.452","89.7"],["13.451","0"],["13.448","129.6"],["13.447","104.2"]]}}
1650929761.694243: {"m":"depth","symbol":"BTC-PERP", "data":{"ts":1650929761679,"seqnum":7795625687,"asks":[["40499","0.1298"],["40500","3.6862"]],"bids":[["40483","3.1084"]]}}
1650929761.986306: {"m":"depth","symbol":"APE-PERP", "data":{"ts":1650929761854,"seqnum":608730337,"asks":[["19.129","190"],["19.141","0"],["19.148","16"],["19.155","13"],["19.158","65"],["19.159","0"],["19.162","115"],["19.163","0"],["19.166","62"],["19.17","0"],["19.174","0"]],"bids":[["19.126","138"],["19.118","0"],["19.112","0"],["19.109","0"],["19.105","181"],["19.101","11"],["19.1","0"],["19.098","312"],["19.094","14"],["19.09","87"]]}}
1650929761.986408: {"m":"depth","symbol":"DOT-PERP", "data":{"ts":1650929761676,"seqnum":13069591815,"asks":[["18.153","25.7"],["18.156","1.1"],["18.163","34.1"],["18.168","63.5"],["18.172","50.6"],["18.177","102.9"],["18.182","139.1"]],"bids":[["18.125","93.5"],["18.122","7.8"],["18.114","68.1"],["18.109","6.5"],["18.105","29.1"],["18.1","29.7"],["18.095","83.8"]]}}
1650929762.0134778: {"m":"depth","symbol":"BTC-PERP", "data":{"ts":1650929761932,"seqnum":7795625688,"asks":[["40500","0"],["40501","3.9215"]],"bids":[["40484","2.549"],["40483","0.3241"]]}}
1650929762.3253949: {"m":"depth","symbol":"BTC-PERP", "data":{"ts":1650929762314,"seqnum":7795625689,"asks":[["40499","0.1298"],["40500","3.2156"],["40501","0"]],"bids":[["40484","0"],["40483","3.6966"]]}}
1650929762.643565: {"m":"depth","symbol":"BTC-PERP", "data":{"ts":1650929762544,"seqnum":7795625690,"asks":[["40495","0.3918"],["40497","0.17"],["40499","3.3454"],["40500","0"]],"bids":[["40483","0.3241"],["40482","3.4509"],["40481","0.2534"],["40480","0.1754"],["40475","0.1298"],["40474","0.0026"]]}}
1650929762.919042: {"m":"depth","symbol":"LINK-PERP", "data":{"ts":1650929762798,"seqnum":13069695706,"asks":[["13.489","0"],["13.491","4.7"],["13.492","13.3"],["13.496","620.2"],["13.5","44.5"],["13.503","7.7"],["13.507","260.5"],["13.511","3.6"]],"bids":[["13.47","4"],["13.468","175.5"],["13.466","100.8"],["13.463","42.3"],["13.459","667.8"],["13.456","21.6"],["13.452","151.5"],["13.448","145.3"]]}}
1650929762.919161: {"m":"depth","symbol":"DOT-PERP", "data":{"ts":1650929762889,"seqnum":13069591816,"asks":[["18.141","52.4"],["18.142","0"],["18.153","20.5"],["18.156","57.5"],["18.163","46.9"],["18.168","74.5"],["18.172","50.6"],["18.177","139.5"],["18.182","150.8"]],"bids":[["18.126","101.1"],["18.125","69.4"],["18.122","73"],["18.114","61.6"],["18.109","3.9"],["18.105","31.7"],["18.1","29.5"],["18.095","115.7"]]}}
1650929762.9569511: {"m":"depth","symbol":"BTC-PERP", "data":{"ts":1650929762927,"seqnum":7795625691,"asks":[["40495","0"],["40497","0.1298"],["40498","2.677"],["40499","0.1298"],["40509","0"],["40518","0.5163"]],"bids":[["40482","0"],["40481","2.2353"],["40475","0.1298"]]}}
1650929763.264993: {"m":"depth","symbol":"BTC-PERP", "data":{"ts":1650929763184,"seqnum":7795625692,"asks":[["40492","0.1298"],["40497","0"]],"bids":[["40475","0.1298"]]}}
1650929763.550405: {"m":"depth","symbol":"LINK-PERP", "data":{"ts":1650929763278,"seqnum":13069695707,"asks":[["13.489","395.9"]],"bids":[["13.47","399.9"]]}}
1650929763.584296: {"m":"depth","symbol":"BTC-PERP", "data":{"ts":1650929763563,"seqnum":7795625693,"asks":[["40492","0.1298"],["40498","0.3241"],["40499","2.9533"],["40510","0.9399"],["40518","0"]],"bids":[["40482","3.3725"],["40481","0"],["40475","0.1298"]]}}
1650929763.855975: {"m":"depth","symbol":"APE-PERP", "data":{"ts":1650929763661,"seqnum":608730338,"asks":[["19.129","0"],["19.141","54"],["19.146","69"],["19.148","0"],["19.149","91"],["19.153","249"],["19.155","0"],["19.157","168"],["19.158","0"],["19.162","0"],["19.166","0"]],"bids":[["19.126","0"],["19.119","57"],["19.105","0"],["19.101","0"],["19.1","11"],["19.098","0"],["19.096","13"],["19.094","0"],["19.093","11"],["19.09","0"],["19.089","13"],["19.085","13"]]}}
1650929763.904408: {"m":"depth","symbol":"BTC-PERP", "data":{"ts":1650929763867,"seqnum":7795625694,"asks":[["40498","0.3241"],["40499","2.2082"]],"bids":[["40482","3.2156"]]}}
1650929764.215362: {"m":"depth","symbol":"BTC-PERP", "data":{"ts":1650929764198,"seqnum":7795625695,"asks":[["40498","4.0888"],["40499","0.1298"]],"bids":[["40482","0"],["40481","2.7451"]]}}
1650929764.465044: {"m":"depth","symbol":"LINK-PERP", "data":{"ts":1650929764366,"seqnum":13069695708,"asks":[["13.489","0"]],"bids":[["13.47","4"]]}}
1650929764.777494: {"m":"depth","symbol":"LINK-PERP", "data":{"ts":1650929764735,"seqnum":13069695709,"asks":[["13.489","395.9"],["13.491","229.1"],["13.492","8.1"],["13.496","645.5"],["13.5","39.4"],["13.503","42.2"],["13.507","209.9"],["13.511","6"]],"bids":[["13.47","399.9"],["13.468","15.9"],["13.466","75.4"],["13.463","37.9"],["13.459","636.6"],["13.456","51.8"],["13.452","89.7"],["13.448","126.2"]]}}
1650929764.777685: {"m":"depth","symbol":"DOT-PERP", "data":{"ts":1650929764660,"seqnum":13069591817,"asks":[["18.153","70.5"],["18.156","66.6"],["18.163","79.3"],["18.168","82.8"],["18.172","161"],["18.177","106"],["18.182","45.1"]],"bids":[["18.125","96.1"],["18.122","66.4"],["18.114","9.1"],["18.109","1"],["18.105","4.6"],["18.1","30.2"],["18.095","77.2"]]}}
1650929765.189132: {"m":"depth","symbol":"APE-PERP", "data":{"ts":1650929764860,"seqnum":608730339,"asks":[["19.141","0"],["19.146","0"],["19.149","0"],["19.153","0"],["19.157","0"],["19.161","41"],["19.18","11"],["19.184","20"],["19.187","11"],["19.191","122"],["19.195","11"]],"bids":[["19.139","11"],["19.133","11"],["19.13","11"],["19.126","57"],["19.122","109"],["19.119","0"],["19.1","0"],["19.096","0"],["19.093","0"],["19.089","0"],["19.085","0"]]}}
1650929765.487513: {"m":"depth","symbol":"BTC-PERP", "data":{"ts":1650929765466,"seqnum":7795625696,"asks":[["40492","0"],["40495","0.1324"],["40496","0"],["40497","3.5686"],["40498","3.6966"],["40499","0"],["40500","0.1298"]],"bids":[["40481","2.4313"],["40480","0.1754"],["40476","0"],["40475","0.2596"],["40474","0"],["40473","0.0026"]]}}
1650929765.70506: {"m":"depth","symbol":"UNI-PERP", "data":{"ts":1650929765631,"seqnum":7795023609,"asks":[["8.75","1825.4"],["8.77","948.4"]],"bids":[["8.73","4661.9"]]}}
1650929765.8054469: {"m":"depth","symbol":"MATIC-PERP", "data":{"ts":1650929765555,"seqnum":7794660108,"asks":[["1.3554","0"]],"bids":[]}}
1650929765.805569: {"m":"depth","symbol":"BTC-PERP", "data":{"ts":1650929765788,"seqnum":7795625697,"asks":[["40495","0.0026"],["40496","0.1298"],["40497","0"],["40498","0.3241"],["40500","0"],["40501","0.1298"]],"bids":[["40484","0.1298"],["40483","0.3241"],["40481","0.1298"],["40480","0.0114"],["40475","0"]]}}
1650929766.0145721: {"m":"depth","symbol":"LINK-PERP", "data":{"ts":1650929765835,"seqnum":13069695710,"asks":[["13.489","395.9"],["13.491","227.4"],["13.492","269.4"],["13.496","640.7"],["13.5","48.1"],["13.503","41.5"],["13.507","209.9"],["13.511","3.6"]],"bids":[["13.47","399.9"],["13.468","93.8"],["13.466","190.9"],["13.463","41.6"],["13.459","634.9"],["13.456","51.8"],["13.452","151.5"],["13.448","142.8"]]}}
1650929766.015263: {"m":"depth","symbol":"UNI-PERP", "data":{"ts":1650929765954,"seqnum":7795023610,"asks":[["8.76","3325.3"],["8.77","948.4"]],"bids":[]}}
1650929766.015724: {"m":"depth","symbol":"DOT-PERP", "data":{"ts":1650929765857,"seqnum":13069591818,"asks":[["18.141","0"],["18.142","42.7"],["18.15","5"],["18.153","2"],["18.156","0"],["18.161","5.1"],["18.163","0"],["18.166","1"],["18.168","0"],["18.17","36.4"],["18.172","0"],["18.175","90.1"],["18.177","0"],["18.18","143.1"],["18.182","0"]],"bids":[["18.126","157.3"],["18.125","0"],["18.122","71.1"],["18.119","80.2"],["18.114","0"],["18.112","26.8"],["18.109","0"],["18.107","10.5"],["18.105","0"],["18.103","80.2"],["18.1","0"],["18.098","73.7"],["18.095","0"],["18.093","84.8"]]}}
1650929766.11499: {"m":"depth","symbol":"MATIC-PERP", "data":{"ts":1650929766106,"seqnum":7794660109,"asks":[["1.355","5604"],["1.3551","10302"]],"bids":[]}}
1650929766.115124: {"m":"depth","symbol":"BTC-PERP", "data":{"ts":1650929766047,"seqnum":7795625698,"asks":[["40495","0.1324"],["40496","0"],["40500","0.1298"],["40501","3.5686"],["40502","0.3241"]],"bids":[["40484","3.6078"],["40483","0.3241"],["40481","0"],["40475","0.1298"],["40474","0.1298"]]}}
1650929766.405876: {"m":"depth","symbol":"DOT-PERP", "data":{"ts":1650929766249,"seqnum":13069591819,"asks":[],"bids":[["18.126","101.1"],["18.125","33"]]}}
1650929766.737084: {"m":"depth","symbol":"BTC-PERP", "data":{"ts":1650929766631,"seqnum":7795625699,"asks":[["40500","0.1298"],["40501","2.3529"]],"bids":[["40484","3.647"],["40483","0.3241"]]}}
1650929767.031293: {"m":"depth","symbol":"UNI-PERP", "data":{"ts":1650929766919,"seqnum":7795023611,"asks":[["8.77","2654"]],"bids":[]}}
1650929767.0313659: {"m":"depth","symbol":"DOT-PERP", "data":{"ts":1650929766677,"seqnum":13069591820,"asks":[["18.142","58.2"]],"bids":[["18.126","161.2"],["18.125","0"]]}}
1650929767.0314088: {"m":"depth","symbol":"APE-PERP", "data":{"ts":1650929766670,"seqnum":608730340,"asks":[["19.161","0"],["19.173","110"],["19.18","0"],["19.184","0"],["19.187","0"],["19.191","90"],["19.195","0"],["19.196","118"],["19.199","77"],["19.203","93"],["19.207","129"]],"bids":[["19.15","85"],["19.143","82"],["19.14","259"],["19.139","0"],["19.136","273"],["19.133","0"],["19.132","149"],["19.13","0"],["19.126","0"],["19.122","0"]]}}
1650929767.047254: {"m":"depth","symbol":"BTC-PERP", "data":{"ts":1650929767030,"seqnum":7795625700,"asks":[["40500","3.8945"],["40501","0"]],"bids":[["40484","0"],["40483","3.1084"]]}}
1650929767.3253472: {"m":"depth","symbol":"DOT-PERP", "data":{"ts":1650929767067,"seqnum":13069591821,"asks":[["18.141","55"],["18.142","0"]],"bids":[["18.126","101.1"],["18.125","47.8"]]}}
1650929767.325481: {"m":"depth","symbol":"UNI-PERP", "data":{"ts":1650929767136,"seqnum":7795023612,"asks":[["8.75","2460.6"],["8.77","948.4"]],"bids":[["8.73","4895.9"]]}}
1650929767.354837: {"m":"depth","symbol":"BTC-PERP", "data":{"ts":1650929767127,"seqnum":7795625701,"asks":[["40500","2.2866"]],"bids":[["40483","3.6182"]]}}
1650929767.5706618: {"m":"depth","symbol":"LINK-PERP", "data":{"ts":1650929767342,"seqnum":13069695711,"asks":[["13.489","395.9"]],"bids":[["13.472","395.9"],["13.47","4"]]}}
1650929767.666038: {"m":"depth","symbol":"BTC-PERP", "data":{"ts":1650929767536,"seqnum":7795625702,"asks":[["40498","2.9907"],["40500","0.1298"]],"bids":[["40483","0.3241"],["40481","3.0196"]]}}
1650929767.874968: {"m":"depth","symbol":"LINK-PERP", "data":{"ts":1650929767614,"seqnum":13069695712,"asks":[["13.491","174"],["13.492","185.1"],["13.496","601.2"],["13.5","39.4"],["13.503","7.7"],["13.507","200.5"],["13.511","20.4"]],"bids":[["13.468","88.5"],["13.466","259.1"],["13.463","50.2"],["13.459","758.6"],["13.456","39.9"],["13.452","103.2"],["13.448","126.2"]]}}
1650929767.875058: {"m":"depth","symbol":"APE-PERP", "data":{"ts":1650929767848,"seqnum":608730341,"asks":[["19.173","0"],["19.191","0"],["19.196","0"],["19.199","0"],["19.201","151"],["19.203","0"],["19.207","0"],["19.219","85"],["19.223","240"],["19.226","13"],["19.23","11"],["19.234","212"]],"bids":[["19.178","159"],["19.174","82"],["19.17","11"],["19.166","11"],["19.162","11"],["19.15","0"],["19.143","0"],["19.14","0"],["19.136","0"],["19.132","0"]]}}
1650929767.875558: {"m":"depth","symbol":"DOT-PERP", "data":{"ts":1650929767670,"seqnum":13069591822,"asks":[["18.15","0"],["18.153","7.2"],["18.156","95.5"],["18.161","0"],["18.164","92.8"],["18.166","0"],["18.169","50.1"],["18.17","0"],["18.173","136.4"],["18.175","0"],["18.178","73.3"],["18.18","0"],["18.183","120.1"]],"bids":[["18.125","124.6"],["18.122","32.1"],["18.119","0"],["18.115","1"],["18.112","0"],["18.11","35"],["18.107","0"],["18.106","1"],["18.103","0"],["18.101","23.7"],["18.098","0"],["18.096","42.2"],["18.093","0"]]}}
1650929767.98252: {"m":"depth","symbol":"BTC-PERP", "data":{"ts":1650929767965,"seqnum":7795625703,"asks":[["40498","0.3241"]],"bids":[["40481","3.2156"]]}}
1650929768.1886919: {"m":"depth","symbol":"UNI-PERP", "data":{"ts":1650929767972,"seqnum":7795023613,"asks":[["8.77","948.4"]],"bids":[]}}
1650929768.287122: {"m":"depth","symbol":"BTC-PERP", "data":{"ts":1650929768275,"seqnum":7795625704,"asks":[["40494","0.4201"],["40498","0.3241"],["40499","2.9019"]],"bids":[["40482","3.3725"],["40481","0"]]}}
1650929768.6711822: {"m":"depth","symbol":"BTC-PERP", "data":{"ts":1650929768579,"seqnum":7795625705,"asks":[["40495","0.0026"],["40498","0.3241"],["40499","2.196"],["40500","0"]],"bids":[["40482","3.1372"],["40475","0"],["40474","0"]]}}
1650929768.805475: {"m":"depth","symbol":"LINK-PERP", "data":{"ts":1650929768801,"seqnum":13069695713,"asks":[["13.489","395.9"]],"bids":[["13.472","0"],["13.47","399.9"],["13.468","187.5"],["13.466","494.3"]]}}
1650929768.903782: {"m":"depth","symbol":"BTC-PERP", "data":{"ts":1650929768897,"seqnum":7795625706,"asks":[["40494","0"],["40498","0.3241"],["40499","0"]],"bids":[["40483","0.3241"],["40482","0"],["40473","0.0026"]]}}
1650929769.115648: {"m":"depth","symbol":"LINK-PERP", "data":{"ts":1650929768827,"seqnum":13069695714,"asks":[["13.489","0"],["13.491","91.4"],["13.492","194.4"],["13.496","625.8"],["13.5","39.4"],["13.503","8.4"],["13.507","217.3"],["13.511","37.4"]],"bids":[["13.47","4"],["13.468","99"],["13.466","235.2"],["13.463","41"],["13.459","670.2"],["13.456","37.8"],["13.452","204.4"],["13.448","111.7"]]}}
1650929769.115842: {"m":"depth","symbol":"UNI-PERP", "data":{"ts":1650929768996,"seqnum":7795023614,"asks":[["8.77","948.4"]],"bids":[]}}
1650929769.1162932: {"m":"depth","symbol":"DOT-PERP", "data":{"ts":1650929768868,"seqnum":13069591823,"asks":[["18.153","34.3"],["18.156","99.1"],["18.164","122.3"],["18.169","125.1"],["18.173","57.2"],["18.178","118.2"],["18.183","140.9"]],"bids":[["18.125","115.3"],["18.122","37.6"],["18.115","1"],["18.11","1"],["18.106","17.2"],["18.101","8.3"],["18.096","43"]]}}
1650929769.214585: {"m":"depth","symbol":"BTC-PERP", "data":{"ts":1650929769060,"seqnum":7795625707,"asks":[["40499","2.1568"]],"bids":[["40483","0.3241"],["40482","2.1176"]]}}
1650929769.423965: {"m":"depth","symbol":"LINK-PERP", "data":{"ts":1650929769340,"seqnum":13069695715,"asks":[["13.489","395.9"]],"bids":[["13.47","399.9"]]}}
1650929769.534463: {"m":"depth","symbol":"BTC-PERP", "data":{"ts":1650929769438,"seqnum":7795625708,"asks":[["40494","0.1298"],["40498","0.3241"],["40499","3.8039"],["40500","0.1298"]],"bids":[["40482","3.4117"],["40474","0.1298"],["40473","0.1324"]]}}
1650929769.7354188: {"m":"depth","symbol":"APE-PERP", "data":{"ts":1650929769678,"seqnum":608730342,"asks":[["19.201","0"],["19.208","181"],["19.219","0"],["19.223","0"],["19.226","0"],["19.228","14"],["19.23","0"],["19.232","95"],["19.234","0"],["19.235","91"],["19.239","47"],["19.243","36"]],"bids":[["19.185","11"],["19.181","11"],["19.178","100"],["19.174","80"],["19.17","11"],["19.166","0"],["19.162","0"]]}}
1650929769.85577: {"m":"depth","symbol":"MATIC-PERP", "data":{"ts":1650929769620,"seqnum":7794660110,"asks":[["1.3551","2786"]],"bids":[["1.3505","0"]]}}
1650929770.0468512: {"m":"depth","symbol":"AKT-PERP", "data":{"ts":1650929769864,"seqnum":7794290675,"asks":[["1.0982","0"]],"bids":[["1.0488","0"]]}}
1650929770.0469701: {"m":"depth","symbol":"UNI-PERP", "data":{"ts":1650929770039,"seqnum":7795023615,"asks":[["8.75","1856.2"],["8.77","948.4"]],"bids":[["8.73","4634.8"]]}}
1650929770.173148: {"m":"depth","symbol":"BTC-PERP", "data":{"ts":1650929770001,"seqnum":7795625709,"asks":[["40494","0"],["40498","0.3241"],["40499","2.6666"],["40500","0"]],"bids":[["40482","2.0784"],["40474","0"],["40473","0.0026"]]}}
1650929770.353879: {"m":"depth","symbol":"AKT-PERP", "data":{"ts":1650929770226,"seqnum":7794290676,"asks":[["1.071","248"],["1.079","0"]],"bids":[["1.07","0"],["1.062","236"]]}}
1650929770.484472: {"m":"depth","symbol":"BTC-PERP", "data":{"ts":1650929770278,"seqnum":7795625710,"asks":[["40494","0.1298"],["40500","0.1298"]],"bids":[["40474","0.1298"],["40473","0.1324"]]}}
1650929770.664983: {"m":"depth","symbol":"DOT-PERP", "data":{"ts":1650929770609,"seqnum":13069591824,"asks":[],"bids":[["18.125","101.1"]]}}
1650929770.665091: {"m":"depth","symbol":"LINK-PERP", "data":{"ts":1650929770626,"seqnum":13069695716,"asks":[["13.489","395.9"],["13.491","65.1"],["13.492","14.9"],["13.496","625.5"],["13.5","39.4"],["13.503","1"],["13.507","201.4"],["13.511","62.6"]],"bids":[["13.47","399.9"],["13.468","39.4"],["13.466","164.3"],["13.463","40.8"],["13.459","672.3"],["13.456","91.2"],["13.452","192.1"],["13.448","122.6"]]}}
1650929770.804941: {"m":"depth","symbol":"MATIC-PERP", "data":{"ts":1650929770628,"seqnum":7794660111,"asks":[["1.355","13120"]],"bids":[["1.3505","7340"]]}}
1650929770.9808278: {"m":"depth","symbol":"UNI-PERP", "data":{"ts":1650929770766,"seqnum":7795023616,"asks":[["8.75","2461.5"]],"bids":[["8.73","4896.6"]]}}
1650929770.980886: {"m":"depth","symbol":"AKT-PERP", "data":{"ts":1650929770940,"seqnum":7794290677,"asks":[["1.0926","3000"]],"bids":[["1.0434","3000"]]}}
1650929770.98091: {"m":"depth","symbol":"APE-PERP", "data":{"ts":1650929770876,"seqnum":608730343,"asks":[["19.195","127"],["19.199","88"],["19.202","11"],["19.206","20"],["19.208","0"],["19.21","11"],["19.228","0"],["19.232","0"],["19.235","0"],["19.239","0"],["19.243","0"]],"bids":[["19.185","0"],["19.181","0"],["19.178","0"],["19.174","170"],["19.17","0"],["19.154","13"],["19.15","56"],["19.147","11"],["19.143","11"],["19.139","11"]]}}
1650929770.9809809: {"m":"depth","symbol":"DOT-PERP", "data":{"ts":1650929770683,"seqnum":13069591825,"asks":[["18.153","76"],["18.156","66.3"],["18.164","93.2"],["18.169","135.1"],["18.173","57.2"],["18.178","118.2"],["18.183","120.1"]],"bids":[["18.125","108.1"],["18.122","29.7"],["18.115","1"],["18.11","1"],["18.106","1"],["18.101","15.2"],["18.096","11.3"]]}}
1650929771.3313768: {"m":"depth","symbol":"DOT-PERP", "data":{"ts":1650929771087,"seqnum":13069591826,"asks":[],"bids":[["18.125","115.2"]]}}
1650929771.33149: {"m":"depth","symbol":"UNI-PERP", "data":{"ts":1650929771019,"seqnum":7795023617,"asks":[["8.77","948.4"]],"bids":[]}}
1650929771.4350872: {"m":"depth","symbol":"BTC-PERP", "data":{"ts":1650929771412,"seqnum":7795625711,"asks":[["40494","0"],["40495","0.1324"],["40500","0.1298"]],"bids":[["40476","0.1298"],["40474","0.1298"],["40473","0.0026"]]}}
1650929771.755059: {"m":"depth","symbol":"BTC-PERP", "data":{"ts":1650929771436,"seqnum":7795625712,"asks":[],"bids":[["40484","0.2536"],["40474","0.2943"]]}}
1650929771.90475: {"m":"depth","symbol":"DOT-PERP", "data":{"ts":1650929771894,"seqnum":13069591827,"asks":[["18.153","138.7"],["18.156","87.9"]],"bids":[["18.125","126.9"],["18.122","124.6"]]}}
1650929771.904876: {"m":"depth","symbol":"UNI-PERP", "data":{"ts":1650929771787,"seqnum":7795023618,"asks":[["8.75","1856.2"]],"bids":[["8.73","4634.8"]]}}
1650929771.904929: {"m":"depth","symbol":"LINK-PERP", "data":{"ts":1650929771829,"seqnum":13069695717,"asks":[["13.489","0"],["13.491","226.9"],["13.492","143.4"],["13.496","629.3"],["13.5","39.4"],["13.503","46.5"],["13.507","432.8"],["13.511","28.8"]],"bids":[["13.47","4"],["13.468","108.6"],["13.466","219"],["13.463","40.2"],["13.459","672.3"],["13.456","91.2"],["13.452","192.1"],["13.448","111.7"]]}}
1650929772.090485: {"m":"depth","symbol":"BTC-PERP", "data":{"ts":1650929771972,"seqnum":7795625713,"asks":[["40498","0.3241"],["40499","2.3137"]],"bids":[["40482","2.7451"]]}}
1650929772.218461: {"m":"depth","symbol":"UNI-PERP", "data":{"ts":1650929772009,"seqnum":7795023619,"asks":[["8.77","948.4"]],"bids":[]}}
1650929772.218566: {"m":"depth","symbol":"DOT-PERP", "data":{"ts":1650929771907,"seqnum":13069591828,"asks":[["18.153","62.7"],["18.156","21.6"],["18.164","92.1"],["18.169","149.6"],["18.173","57.2"],["18.178","118.2"],["18.183","128.1"]],"bids":[["18.125","52.4"],["18.122","94.9"],["18.115","1"],["18.11","1"],["18.106","1"],["18.101","36.5"],["18.096","29.6"]]}}
1650929772.394925: {"m":"depth","symbol":"MATIC-PERP", "data":{"ts":1650929772135,"seqnum":7794660112,"asks":[["1.355","10334"],["1.3551","0"],["1.3553","0"]],"bids":[["1.351","1690"],["1.3508","0"]]}}
1650929772.5255349: {"m":"depth","symbol":"LINK-PERP", "data":{"ts":1650929772236,"seqnum":13069695718,"asks":[["13.489","395.9"]],"bids":[["13.47","399.9"]]}}
1650929772.5278342: {"m":"depth","symbol":"DOT-PERP", "data":{"ts":1650929772458,"seqnum":13069591829,"asks":[],"bids":[["18.125","11.7"],["18.124","56.9"]]}}
1650929772.837334: {"m":"depth","symbol":"DOT-PERP", "data":{"ts":1650929772747,"seqnum":13069591830,"asks":[],"bids":[["18.125","46.6"],["18.124","0"]]}}
1650929772.837449: {"m":"depth","symbol":"APE-PERP", "data":{"ts":1650929772685,"seqnum":608730344,"asks":[["19.158","28"],["19.163","13"],["19.166","86"],["19.17","11"],["19.174","21"],["19.195","0"],["19.199","0"],["19.202","0"],["19.206","0"],["19.21","0"]],"bids":[["19.174","0"],["19.154","0"],["19.15","0"],["19.147","0"],["19.143","0"],["19.139","0"],["19.137","144"],["19.117","15"],["19.113","88"],["19.11","342"],["19.106","706"],["19.102","11"]]}}
1650929773.147923: {"m":"depth","symbol":"UNI-PERP", "data":{"ts":1650929773055,"seqnum":7795023620,"asks":[["8.77","948.4"]],"bids":[]}}
1650929773.147973: {"m":"depth","symbol":"DOT-PERP", "data":{"ts":1650929773142,"seqnum":13069591831,"asks":[["18.141","57.5"]],"bids":[["18.125","75.7"]]}}
1650929773.337903: {"m":"depth","symbol":"BTC-PERP", "data":{"ts":1650929773278,"seqnum":7795625714,"asks":[["40494","0.1298"],["40495","0"],["40496","0.0026"],["40499","3.098"],["40500","0.1298"]],"bids":[["40483","0.3241"],["40482","2.9019"],["40476","0"],["40474","0.1645"],["40473","0.1324"],["40472","0.2594"]]}}
1650929773.454798: {"m":"depth","symbol":"LINK-PERP", "data":{"ts":1650929773372,"seqnum":13069695719,"asks":[["13.489","0"]],"bids":[["13.47","4"]]}}
1650929773.454925: {"m":"depth","symbol":"DOT-PERP", "data":{"ts":1650929773163,"seqnum":13069591832,"asks":[],"bids":[["18.125","11.7"],["18.124","33"]]}}
1650929773.454994: {"m":"depth","symbol":"UNI-PERP", "data":{"ts":1650929773284,"seqnum":7795023621,"asks":[["8.75","2466.9"]],"bids":[["8.73","4894.6"]]}}
1650929773.646789: {"m":"depth","symbol":"MATIC-PERP", "data":{"ts":1650929773636,"seqnum":7794660113,"asks":[["1.3549","2786"],["1.3551","2786"]],"bids":[["1.3504","2196"],["1.3503","2196"]]}}
1650929773.646858: {"m":"depth","symbol":"BTC-PERP", "data":{"ts":1650929773531,"seqnum":7795625715,"asks":[["40499","2.4313"],["40500","0.1298"]],"bids":[["40483","0.3241"],["40482","3.2549"]]}}
1650929773.771193: {"m":"depth","symbol":"LINK-PERP", "data":{"ts":1650929773631,"seqnum":13069695720,"asks":[["13.489","395.9"],["13.491","30.2"],["13.492","128.7"],["13.496","632.2"],["13.5","39.4"],["13.503","1"],["13.507","175.2"],["13.511","45.6"]],"bids":[["13.47","399.9"],["13.468","202.4"],["13.466","239.6"],["13.463","40"],["13.459","672.3"],["13.456","88"],["13.452","130.3"],["13.448","173.5"]]}}
1650929773.771382: {"m":"depth","symbol":"DOT-PERP", "data":{"ts":1650929773709,"seqnum":13069591833,"asks":[["18.14","53"],["18.141","0"],["18.153","3.5"],["18.156","50.4"],["18.163","110.6"],["18.164","0"],["18.168","128.5"],["18.169","0"],["18.172","235.6"],["18.173","0"],["18.177","45.2"],["18.178","0"],["18.182","118.2"],["18.183","0"]],"bids":[["18.125","7.1"],["18.122","81.9"],["18.115","0"],["18.114","1.4"],["18.11","0"],["18.109","18.1"],["18.106","0"],["18.105","5.9"],["18.101","0"],["18.1","11.4"],["18.096","0"],["18.095","68.9"]]}}
1650929773.954081: {"m":"depth","symbol":"MATIC-PERP", "data":{"ts":1650929773648,"seqnum":7794660114,"asks":[["1.3547","2786"]],"bids":[["1.3505","9536"]]}}
1650929774.0824268: {"m":"depth","symbol":"UNI-PERP", "data":{"ts":1650929774058,"seqnum":7795023622,"asks":[["8.77","948.4"]],"bids":[]}}
1650929774.0825322: {"m":"depth","symbol":"APE-PERP", "data":{"ts":1650929773885,"seqnum":608730345,"asks":[["19.152","79"],["19.156","15"],["19.158","0"],["19.159","95"],["19.163","391"],["19.166","0"],["19.167","235"],["19.17","0"],["19.174","0"]],"bids":[["19.137","0"],["19.129","188"],["19.117","0"],["19.113","0"],["19.11","0"],["19.108","37"],["19.106","0"],["19.104","11"],["19.102","0"],["19.1","29"],["19.096","17"],["19.092","11"]]}}
1650929774.2648199: {"m":"depth","symbol":"BTC-PERP", "data":{"ts":1650929774238,"seqnum":7795625716,"asks":[["40493","0.4239"],["40499","3.1372"],["40500","0.1298"]],"bids":[["40483","0.3241"],["40482","3.4509"]]}}
1650929774.384255: {"m":"depth","symbol":"LINK-PERP", "data":{"ts":1650929774380,"seqnum":13069695721,"asks":[["13.489","0"]],"bids":[["13.47","4"],["13.464","0"],["13.463","73"]]}}
1650929774.585574: {"m":"depth","symbol":"BTC-PERP", "data":{"ts":1650929774351,"seqnum":7795625717,"asks":[["40499","3.8431"],["40500","0.1298"]],"bids":[["40483","0.3241"],["40482","2.7058"]]}}
1650929774.6953511: {"m":"depth","symbol":"LINK-PERP", "data":{"ts":1650929774535,"seqnum":13069695722,"asks":[["13.485","47.8"]],"bids":[["13.464","42.7"],["13.463","40"]]}}
1650929774.6954749: {"m":"depth","symbol":"APE-PERP", "data":{"ts":1650929774388,"seqnum":608730346,"asks":[["19.152","0"],["19.156","0"],["19.159","56"]],"bids":[]}}
1650929774.9121: {"m":"depth","symbol":"BTC-PERP", "data":{"ts":1650929774898,"seqnum":7795625718,"asks":[["40498","3.775"],["40499","0"]],"bids":[["40482","2.3137"]]}}
1650929775.0040572: {"m":"depth","symbol":"LINK-PERP", "data":{"ts":1650929774936,"seqnum":13069695723,"asks":[["13.489","395.9"],["13.491","95.4"],["13.492","29.1"],["13.496","653"],["13.5","39.4"],["13.503","39.3"],["13.507","429.9"],["13.511","31.2"]],"bids":[["13.47","399.9"],["13.468","71.1"],["13.466","239.6"],["13.463","40"],["13.459","634.9"],["13.456","43.2"],["13.452","130.3"],["13.448","197.6"]]}}
1650929775.004641: {"m":"depth","symbol":"DOT-PERP", "data":{"ts":1650929774907,"seqnum":13069591834,"asks":[["18.153","94.6"],["18.156","55"],["18.163","131.4"],["18.168","114.9"],["18.172","231.8"],["18.177","45.2"],["18.182","126.3"]],"bids":[["18.125","57.1"],["18.122","43.1"],["18.114","1.4"],["18.109","1"],["18.105","5.9"],["18.1","11.5"],["18.095","67.3"]]}}
1650929775.229366: {"m":"depth","symbol":"BTC-PERP", "data":{"ts":1650929775184,"seqnum":7795625719,"asks":[["40493","0"],["40494","0.2596"],["40498","0.3241"],["40499","3.2549"],["40500","0"]],"bids":[["40476","0.1298"],["40473","0.0026"]]}}
1650929775.2294981: {"m":"depth","symbol":"MATIC-PERP", "data":{"ts":1650929775218,"seqnum":7794660115,"asks":[["1.3544","2184"]],"bids":[["1.3518","0"]]}}
1650929775.317436: {"m":"depth","symbol":"LINK-PERP", "data":{"ts":1650929775205,"seqnum":13069695724,"asks":[["13.484","33.6"],["13.485","0"]],"bids":[["13.464","0"],["13.463","91.1"]]}}
1650929775.31757: {"m":"depth","symbol":"UNI-PERP", "data":{"ts":1650929775059,"seqnum":7795023623,"asks":[["8.77","948.4"]],"bids":[]}}
1650929775.317617: {"m":"depth","symbol":"DOT-PERP", "data":{"ts":1650929775289,"seqnum":13069591835,"asks":[["18.14","33.6"]],"bids":[["18.126","0"],["18.124","0"],["18.123","38.8"]]}}
1650929775.538517: {"m":"depth","symbol":"BTC-PERP", "data":{"ts":1650929775446,"seqnum":7795625720,"asks":[["40497","2.8235"],["40498","0.3241"],["40499","0"]],"bids":[["40482","0"],["40480","2.7172"]]}}
1650929775.5483038: {"m":"depth","symbol":"MATIC-PERP", "data":{"ts":1650929775537,"seqnum":7794660116,"asks":[["1.3538","314"],["1.3539","1767"],["1.3544","0"],["1.3546","3880"],["1.3551","0"],["1.3556","0"],["1.3566","5820"],["1.3576","0"],["1.3618","1012"],["1.3619","3035"],["1.362","5058"],["1.3621","7081"],["1.3622","9105"],["1.3623","11128"],["1.3624","13152"],["1.3625","15175"],["1.3628","0"],["1.3629","0"],["1.363","0"],["1.3631","0"],["1.3632","0"],["1.3633","0"],["1.3634","0"],["1.3635","0"],["1.3636","0"],["1.3637","0"]],"bids":[["1.3521","0"],["1.3516","0"],["1.3506","6557"],["1.3496","0"],["1.3486","5820"],["1.3444","0"],["1.3443","0"],["1.3442","0"],["1.3441","0"],["1.344","0"],["1.3439","0"],["1.3438","0"],["1.3437","0"],["1.3436","0"],["1.3435","0"],["1.3434","1012"],["1.3433","3035"],["1.3432","5058"],["1.3431","7081"],["1.343","9105"],["1.3429","11128"],["1.3428","13152"],["1.3427","15175"],["1.3426","17198"],["1.3425","19221"]]}}
1650929775.63052: {"m":"depth","symbol":"DOT-PERP", "data":{"ts":1650929775452,"seqnum":13069591836,"asks":[["18.137","33"],["18.14","0"]],"bids":[["18.123","0"],["18.122","43.1"],["18.121","53.7"]]}}
1650929775.855139: {"m":"depth","symbol":"BTC-PERP", "data":{"ts":1650929775728,"seqnum":7795625721,"asks":[["40488","0.1298"],["40494","0.1298"],["40496","0.0026"],["40497","0"],["40499","2.8235"]],"bids":[["40482","2.5098"],["40480","0.0114"],["40479","0.3241"],["40472","0.1296"],["40471","0.1298"]]}}
1650929775.864955: {"m":"depth","symbol":"MATIC-PERP", "data":{"ts":1650929775669,"seqnum":7794660117,"asks":[["1.3547","0"],["1.3549","0"],["1.355","2818"],["1.3626","17198"],["1.3627","19221"]],"bids":[["1.3505","0"],["1.3504","0"],["1.3503","0"]]}}
1650929775.9414022: {"m":"depth","symbol":"APE-PERP", "data":{"ts":1650929775699,"seqnum":608730347,"asks":[["19.147","85"],["19.156","77"],["19.159","0"],["19.16","157"],["19.163","0"],["19.164","11"],["19.167","0"],["19.168","173"]],"bids":[["19.129","0"],["19.126","172"],["19.108","0"],["19.106","257"],["19.104","0"],["19.101","11"],["19.1","0"],["19.098","11"],["19.096","0"],["19.094","23"],["19.092","0"],["19.09","43"]]}}
1650929776.175812: {"m":"depth","symbol":"BTC-PERP", "data":{"ts":1650929776153,"seqnum":7795625722,"asks":[["40498","3.4221"],["40499","0"]],"bids":[["40482","0"],["40481","2.1176"],["40480","0.0114"]]}}
1650929776.1830962: {"m":"depth","symbol":"MATIC-PERP", "data":{"ts":1650929775927,"seqnum":7794660118,"asks":[["1.353","2254"],["1.358","0"]],"bids":[]}}
1650929776.246965: {"m":"depth","symbol":"AKT-PERP", "data":{"ts":1650929776240,"seqnum":7794290678,"asks":[],"bids":[["1.07","162"],["1.062","0"]]}}
1650929776.247095: {"m":"depth","symbol":"UNI-PERP", "data":{"ts":1650929776184,"seqnum":7795023624,"asks":[["8.75","1831.7"],["8.76","1608"]],"bids":[["8.73","1128.9"]]}}
1650929776.557537: {"m":"depth","symbol":"BTC-PERP", "data":{"ts":1650929776451,"seqnum":7795625723,"asks":[["40488","0"],["40494","0"],["40497","3.8431"],["40498","0.3241"]],"bids":[["40481","0"],["40480","2.5212"],["40476","0"],["40474","0"],["40471","0"]]}}
1650929776.557612: {"m":"depth","symbol":"MATIC-PERP", "data":{"ts":1650929776218,"seqnum":7794660119,"asks":[["1.353","0"],["1.358","1831"]],"bids":[]}}
1650929776.557638: {"m":"depth","symbol":"LINK-PERP", "data":{"ts":1650929776486,"seqnum":13069695725,"asks":[["13.489","395.9"]],"bids":[["13.47","4"],["13.469","404"]]}}
1650929776.557662: {"m":"depth","symbol":"UNI-PERP", "data":{"ts":1650929776290,"seqnum":7795023625,"asks":[["8.75","1221"]],"bids":[["8.73","869.1"]]}}
1650929776.814062: {"m":"depth","symbol":"BTC-PERP", "data":{"ts":1650929776798,"seqnum":7795625724,"asks":[["40496","3.8065"],["40497","0"],["40498","0.3241"]],"bids":[["40484","0"],["40480","0.0114"],["40479","3.9711"]]}}
1650929776.872447: {"m":"depth","symbol":"LINK-PERP", "data":{"ts":1650929776639,"seqnum":13069695726,"asks":[["13.49","13.3"],["13.491","84.7"],["13.492","0"],["13.495","96.9"],["13.496","584"],["13.499","301.3"],["13.5","8.1"],["13.502","619.2"],["13.503","0"],["13.506","113.9"],["13.507","173.9"],["13.51","526.8"],["13.511","0"]],"bids":[["13.468","0"],["13.467","809.1"],["13.466","0"],["13.465","402.5"],["13.463","51.1"],["13.462","23.8"],["13.459","633.9"],["13.458","1"],["13.456","0"],["13.455","8.5"],["13.452","0"],["13.451","55.6"],["13.448","34.8"],["13.447","162.7"]]}}
1650929776.872722: {"m":"depth","symbol":"DOT-PERP", "data":{"ts":1650929776802,"seqnum":13069591837,"asks":[["18.137","0"],["18.138","41.4"],["18.147","27.3"],["18.15","55.8"],["18.153","0"],["18.156","0"],["18.157","10.8"],["18.162","18"],["18.163","0"],["18.166","53.1"],["18.168","0"],["18.171","150.1"],["18.172","0"],["18.176","81.2"],["18.177","0"],["18.182","0"]],"bids":[["18.125","0"],["18.122","45.9"],["18.121","0"],["18.119","10.6"],["18.116","60.9"],["18.114","0"],["18.109","0"],["18.108","94.4"],["18.105","0"],["18.103","59.9"],["18.1","0"],["18.099","112.2"],["18.095","0"],["18.094","36"],["18.089","43.7"]]}}
1650929777.167888: {"m":"depth","symbol":"BTC-PERP", "data":{"ts":1650929777098,"seqnum":7795625725,"asks":[["40491","0.0113"],["40496","0.0026"],["40498","2.9123"]],"bids":[["40481","2.3529"],["40480","0.0114"],["40479","0.3241"]]}}
1650929777.168017: {"m":"depth","symbol":"MATIC-PERP", "data":{"ts":1650929777083,"seqnum":7794660120,"asks":[["1.3536","2184"],["1.3538","313"]],"bids":[["1.3508","5281"]]}}
1650929777.1762: {"m":"depth","symbol":"LINK-PERP", "data":{"ts":1650929777006,"seqnum":13069695727,"asks":[["13.484","33.5"],["13.489","0"]],"bids":[["13.469","8.1"]]}}
1650929777.176255: {"m":"depth","symbol":"ATOM-PERP", "data":{"ts":1650929776950,"seqnum":7794440731,"asks":[["22.14","101.8"]],"bids":[]}}
1650929777.1763232: {"m":"depth","symbol":"PORT-PERP", "data":{"ts":1650929776978,"seqnum":273532941,"asks":[],"bids":[["0.51","396"]]}}
1650929777.1763961: {"m":"depth","symbol":"AKT-PERP", "data":{"ts":1650929776947,"seqnum":7794290679,"asks":[["1.071","246"]],"bids":[]}}
1650929777.1764202: {"m":"depth","symbol":"DOT-PERP", "data":{"ts":1650929777153,"seqnum":13069591838,"asks":[["18.138","0"],["18.139","38.8"]],"bids":[["18.122","48.5"]]}}
1650929777.176459: {"m":"depth","symbol":"XPRT-PERP", "data":{"ts":1650929776999,"seqnum":608427309,"asks":[],"bids":[["2.715","129"]]}}
1650929777.1764858: {"m":"depth","symbol":"UNI-PERP", "data":{"ts":1650929777170,"seqnum":7795023626,"asks":[["8.75","1858.2"],["8.76","2449.5"],["8.77","948.4"]],"bids":[["8.73","3782.3"]]}}
1650929777.185039: {"m":"depth","symbol":"APE-PERP", "data":{"ts":1650929776899,"seqnum":608730348,"asks":[["19.147","0"],["19.154","127"],["19.156","0"],["19.16","0"],["19.164","0"],["19.168","0"],["19.173","153"],["19.177","127"],["19.18","11"],["19.184","11"],["19.189","69"]],"bids":[["19.132","42"],["19.128","11"],["19.126","0"],["19.125","11"],["19.121","72"],["19.117","49"],["19.106","0"],["19.101","0"],["19.098","0"],["19.094","0"],["19.09","0"]]}}
1650929777.444951: {"m":"depth","symbol":"BTC-PERP", "data":{"ts":1650929777152,"seqnum":7795625726,"asks":[["40490","0.1298"],["40494","0.1298"]],"bids":[["40473","0.1324"],["40471","0.1298"]]}}
1650929777.456077: {"m":"depth","symbol":"MATIC-PERP", "data":{"ts":1650929777147,"seqnum":7794660121,"asks":[["1.3539","369"]],"bids":[]}}
1650929777.488354: {"m":"depth","symbol":"LINK-PERP", "data":{"ts":1650929777435,"seqnum":13069695728,"asks":[["13.489","395.9"]],"bids":[["13.469","404"]]}}
1650929777.4884312: {"m":"depth","symbol":"DOT-PERP", "data":{"ts":1650929777242,"seqnum":13069591839,"asks":[["18.138","61.4"],["18.139","0"]],"bids":[]}}
1650929777.488469: {"m":"depth","symbol":"UNI-PERP", "data":{"ts":1650929777297,"seqnum":7795023627,"asks":[["8.75","2463.1"],["8.76","3322.3"]],"bids":[["8.73","4621.6"],["8.72","547.7"]]}}
1650929777.76303: {"m":"depth","symbol":"BTC-PERP", "data":{"ts":1650929777686,"seqnum":7795625727,"asks":[["40490","0"],["40494","0"],["40495","0.1298"],["40500","0.1298"]],"bids":[["40473","0.0026"],["40472","0.2594"],["40471","0.1298"]]}}
1650929777.774542: {"m":"depth","symbol":"MATIC-PERP", "data":{"ts":1650929777706,"seqnum":7794660122,"asks":[["1.354","4899"],["1.3542","2786"],["1.3543","2786"],["1.3544","7516"]],"bids":[["1.35","10158"],["1.3499","4392"],["1.3498","2196"]]}}
1650929778.093196: {"m":"depth","symbol":"BTC-PERP", "data":{"ts":1650929778037,"seqnum":7795625728,"asks":[["40498","0.3241"],["40499","2.8627"]],"bids":[["40482","2.1176"],["40481","0"]]}}
1650929778.10908: {"m":"depth","symbol":"UNI-PERP", "data":{"ts":1650929778060,"seqnum":7795023628,"asks":[["8.77","2641.6"]],"bids":[]}}
1650929778.1091259: {"m":"depth","symbol":"DOT-PERP", "data":{"ts":1650929777919,"seqnum":13069591840,"asks":[["18.147","0"],["18.149","69"],["18.15","0"],["18.152","291.5"],["18.157","0"],["18.159","6.1"],["18.162","0"],["18.164","15.2"],["18.166","0"],["18.168","42.2"],["18.171","0"],["18.173","167.2"],["18.176","0"],["18.178","106.5"]],"bids":[["18.121","28.3"],["18.119","0"],["18.118","88.2"],["18.116","0"],["18.11","29.2"],["18.108","0"],["18.105","35.2"],["18.103","0"],["18.101","76.9"],["18.099","0"],["18.096","90.5"],["18.094","0"],["18.091","107.7"],["18.089","0"]]}}
1650929778.109215: {"m":"depth","symbol":"LINK-PERP", "data":{"ts":1650929777835,"seqnum":13069695729,"asks":[["13.49","162.6"],["13.491","156.6"],["13.495","105.5"],["13.499","296.3"],["13.502","619.2"],["13.506","113.9"],["13.51","407.8"]],"bids":[["13.467","628.5"],["13.465","491.3"],["13.462","24.5"],["13.458","1"],["13.455","9.6"],["13.451","83"],["13.447","281.7"]]}}
1650929778.500679: {"m":"depth","symbol":"BTC-PERP", "data":{"ts":1650929778386,"seqnum":7795625729,"asks":[["40497","3.1372"],["40498","0.3241"],["40499","0"]],"bids":[["40482","0"],["40480","2.2074"]]}}
1650929778.50082: {"m":"depth","symbol":"UNI-PERP", "data":{"ts":1650929778321,"seqnum":7795023629,"asks":[["8.77","948.4"]],"bids":[["8.72","547.7"]]}}
1650929778.704392: {"m":"depth","symbol":"BTC-PERP", "data":{"ts":1650929778696,"seqnum":7795625730,"asks":[["40495","0"],["40496","0.0026"],["40497","3.0196"],["40498","0.3241"],["40500","0"]],"bids":[["40480","3.5408"],["40479","0.3241"],["40472","0.1296"],["40471","0"]]}}
1650929778.723665: {"m":"depth","symbol":"MATIC-PERP", "data":{"ts":1650929778504,"seqnum":7794660123,"asks":[["1.353","1690"],["1.358","0"]],"bids":[]}}
1650929778.7237198: {"m":"depth","symbol":"APE-PERP", "data":{"ts":1650929778693,"seqnum":608730349,"asks":[["19.139","142"],["19.154","0"],["19.159","85"],["19.163","182"],["19.166","47"],["19.172","89"],["19.173","0"],["19.176","11"],["19.177","0"],["19.18","0"],["19.184","0"],["19.189","0"]],"bids":[["19.136","82"],["19.132","0"],["19.128","0"],["19.125","0"],["19.121","0"],["19.117","0"],["19.115","11"],["19.111","11"],["19.108","88"],["19.103","11"],["19.099","37"]]}}
1650929779.033185: {"m":"depth","symbol":"BTC-PERP", "data":{"ts":1650929778921,"seqnum":7795625731,"asks":[["40495","0.1298"],["40497","0"],["40498","3.4613"],["40500","0.1298"]],"bids":[["40481","2.549"],["40480","0.0114"],["40473","0.1324"],["40471","0.1298"]]}}
1650929779.0351539: {"m":"depth","symbol":"MATIC-PERP", "data":{"ts":1650929778932,"seqnum":7794660124,"asks":[["1.353","0"],["1.358","1690"]],"bids":[]}}
1650929779.039689: {"m":"depth","symbol":"LINK-PERP", "data":{"ts":1650929778858,"seqnum":13069695730,"asks":[["13.489","0"]],"bids":[["13.469","8.1"]]}}
1650929779.0397298: {"m":"depth","symbol":"DOT-PERP", "data":{"ts":1650929778795,"seqnum":13069591841,"asks":[],"bids":[["18.085","0"]]}}
1650929779.3429718: {"m":"depth","symbol":"MATIC-PERP", "data":{"ts":1650929779205,"seqnum":7794660125,"asks":[["1.353","2818"],["1.358","0"]],"bids":[]}}
1650929779.3545668: {"m":"depth","symbol":"DOT-PERP", "data":{"ts":1650929779250,"seqnum":13069591842,"asks":[["18.137","62.7"],["18.138","0"]],"bids":[["18.122","0"],["18.121","61.3"]]}}
1650929779.354697: {"m":"depth","symbol":"UNI-PERP", "data":{"ts":1650929779268,"seqnum":7795023630,"asks":[["8.76","2449.5"],["8.77","948.4"]],"bids":[["8.73","4043.7"],["8.72","547.7"]]}}
1650929779.653758: {"m":"depth","symbol":"MATIC-PERP", "data":{"ts":1650929779458,"seqnum":7794660126,"asks":[["1.353","0"],["1.358","2536"]],"bids":[]}}
