1625273778.618699: {"jsonrpc":"2.0","method":"updateOrderbook","params":{"ask":[{"price":"0.00011580","size":"2139.17"},{"price":"0.00011581","size":"99.00"},{"price":"0.00011583","size":"0"},{"price":"0.00011584","size":"255.99"},{"price":"0.00011598","size":"0"},{"price":"0.00011608","size":"88.49"},{"price":"0.00023468","size":"0"},{"price":"0.00023511","size":"30396.48"},{"price":"0.00075415","size":"0"},{"price":"0.00076004","size":"42091.73"}],"bid":[{"price":"0.00011566","size":"298.10"},{"price":"0.00011565","size":"87.20"}],"sequence":12351633,"timestamp":"2021-07-03T00:56:18.350Z","symbol":"EOSBTC"}}
1625273778.6187909: {"jsonrpc":"2.0","method":"updateOrderbook","params":{"ask":[{"price":"0.07649","size":"0"}],"bid":[],"sequence":7339897,"timestamp":"2021-07-03T00:56:18.317Z","symbol":"MKRBTC"}}
1625273778.6188009: {"jsonrpc":"2.0","method":"updateOrderbook","params":{"ask":[],"bid":[{"price":"30546.24","size":"1.39725"},{"price":"30167.71","size":"0"}],"sequence":7476857,"timestamp":"2021-07-03T00:56:18.261Z","symbol":"BTCTUSD"}}
1625273778.618809: {"jsonrpc":"2.0","method":"updateOrderbook","params":{"ask":[{"price":"33674.81","size":"1.07700"},{"price":"33692.01","size":"0"}],"bid":[{"price":"33546.82","size":"0.02940"},{"price":"33545.23","size":"0"}],"sequence":12626594,"timestamp":"2021-07-03T00:56:18.440Z","symbol":"BTCUSDB"}}
1625273778.618818: {"jsonrpc":"2.0","method":"updateOrderbook","params":{"ask":[],"bid":[{"price":"0.00011566","size":"286.59"},{"price":"0.00011565","size":"98.71"}],"sequence":12351634,"timestamp":"2021-07-03T00:56:18.354Z","symbol":"EOSBTC"}}
1625273778.633612: {"jsonrpc":"2.0","method":"updateOrderbook","params":{"ask":[],"bid":[{"price":"33541.31","size":"0.05460"},{"price":"33539.73","size":"0"},{"price":"33501.95","size":"1.81560"},{"price":"33498.83","size":"0"}],"sequence":12626595,"timestamp":"2021-07-03T00:56:18.526Z","symbol":"BTCUSDB"}}
1625273778.633674: {"jsonrpc":"2.0","method":"updateOrderbook","params":{"ask":[{"price":"0.00011583","size":"244.48"},{"price":"0.00011584","size":"11.51"},{"price":"0.00011610","size":"4960.33"},{"price":"0.00011619","size":"4550.12"},{"price":"0.00011645","size":"10828.91"},{"price":"0.00011663","size":"5557.50"},{"price":"0.00013962","size":"53526.30"},{"price":"0.00013993","size":"0"}],"bid":[{"price":"0.00011475","size":"10860.97"},{"price":"0.00011454","size":"4559.60"},{"price":"0.00011002","size":"0"},{"price":"0.00010973","size":"7497.84"}],"sequence":12351635,"timestamp":"2021-07-03T00:56:18.549Z","symbol":"EOSBTC"}}
1625273778.734561: {"jsonrpc":"2.0","method":"updateOrderbook","params":{"ask":[{"price":"0.00011579","size":"0"},{"price":"0.00011583","size":"124.04"},{"price":"0.00011584","size":"131.95"}],"bid":[{"price":"0.00011570","size":"491.99"}],"sequence":12351636,"timestamp":"2021-07-03T00:56:18.566Z","symbol":"EOSBTC"}}
1625273778.734689: {"jsonrpc":"2.0","method":"updateOrderbook","params":{"ask":[{"price":"33632.87","size":"0"},{"price":"33633.61","size":"0.00533"}],"bid":[],"sequence":7211195,"timestamp":"2021-07-03T00:56:18.615Z","symbol":"BTCPAX"}}
1625273778.7429461: {"jsonrpc":"2.0","method":"updateOrderbook","params":{"ask":[{"price":"33518.97","size":"0"},{"price":"33519.84","size":"0.01231"}],"bid":[],"sequence":7476858,"timestamp":"2021-07-03T00:56:18.615Z","symbol":"BTCTUSD"}}
1625273778.825612: {"jsonrpc":"2.0","method":"updateOrderbook","params":{"ask":[{"price":"33564.81","size":"2.47430"},{"price":"33567.10","size":"0"},{"price":"33570.32","size":"0"},{"price":"33571.77","size":"0.75370"},{"price":"33575.61","size":"1.43490"},{"price":"33578.83","size":"0"},{"price":"33581.63","size":"0"}],"bid":[],"sequence":12626596,"timestamp":"2021-07-03T00:56:18.701Z","symbol":"BTCUSDB"}}
1625273778.83099: {"jsonrpc":"2.0","method":"updateOrderbook","params":{"ask":[{"price":"33519.84","size":"0"},{"price":"33520.09","size":"0.01231"}],"bid":[],"sequence":7476859,"timestamp":"2021-07-03T00:56:18.654Z","symbol":"BTCTUSD"}}
1625273778.9290419: {"jsonrpc":"2.0","method":"updateOrderbook","params":{"ask":[{"price":"0.00011579","size":"99.00"},{"price":"0.00011581","size":"124.04"},{"price":"0.00011583","size":"0"},{"price":"0.00011645","size":"12985.20"},{"price":"0.00011674","size":"0"}],"bid":[],"sequence":12351637,"timestamp":"2021-07-03T00:56:18.770Z","symbol":"EOSBTC"}}
1625273778.929131: {"jsonrpc":"2.0","method":"updateOrderbook","params":{"ask":[{"price":"0.07990","size":"17.0727"},{"price":"0.08009","size":"0"}],"bid":[],"sequence":7339898,"timestamp":"2021-07-03T00:56:18.821Z","symbol":"MKRBTC"}}
1625273779.024684: {"jsonrpc":"2.0","method":"updateOrderbook","params":{"ask":[{"price":"33574.90","size":"0.01174"},{"price":"33578.55","size":"0"},{"price":"33587.33","size":"1.13490"},{"price":"33591.58","size":"0"}],"bid":[],"sequence":12626597,"timestamp":"2021-07-03T00:56:18.856Z","symbol":"BTCUSDB"}}
1625273779.0247428: {"jsonrpc":"2.0","method":"updateOrderbook","params":{"ask":[{"price":"0.00011598","size":"88.49"},{"price":"0.00011608","size":"0"}],"bid":[],"sequence":12351638,"timestamp":"2021-07-03T00:56:18.874Z","symbol":"EOSBTC"}}
1625273779.128681: {"jsonrpc":"2.0","method":"updateOrderbook","params":{"ask":[{"price":"167675.75","size":"0"},{"price":"167676.08","size":"0.00012"}],"bid":[{"price":"32625.67","size":"1.69554"},{"price":"32614.14","size":"1.55380"},{"price":"32571.17","size":"0"},{"price":"32552.86","size":"0"},{"price":"32521.06","size":"1.13252"},{"price":"32461.96","size":"0"},{"price":"32452.46","size":"1.65075"},{"price":"32387.47","size":"0"},{"price":"32104.01","size":"1.33884"},{"price":"32046.02","size":"0"},{"price":"30841.69","size":"1.70291"},{"price":"30797.74","size":"0"}],"sequence":12626598,"timestamp":"2021-07-03T00:56:18.961Z","symbol":"BTCUSDB"}}
1625273779.1287491: {"jsonrpc":"2.0","method":"updateOrderbook","params":{"ask":[{"price":"0.07634","size":"1.4283"},{"price":"0.07637","size":"1.9169"},{"price":"0.07643","size":"0.5753"},{"price":"0.07646","size":"2.0319"}],"bid":[],"sequence":7339899,"timestamp":"2021-07-03T00:56:19.026Z","symbol":"MKRBTC"}}
1625273779.228235: {"jsonrpc":"2.0","method":"updateOrderbook","params":{"ask":[],"bid":[{"price":"33500.59","size":"1.43690"},{"price":"33491.69","size":"0"}],"sequence":12626599,"timestamp":"2021-07-03T00:56:19.066Z","symbol":"BTCUSDB"}}
1625273779.228263: {"jsonrpc":"2.0","method":"updateOrderbook","params":{"ask":[],"bid":[{"price":"0.00011475","size":"15420.57"},{"price":"0.00011454","size":"0"}],"sequence":12351639,"timestamp":"2021-07-03T00:56:19.094Z","symbol":"EOSBTC"}}
1625273779.338302: {"jsonrpc":"2.0","method":"updateOrderbook","params":{"ask":[{"price":"33587.18","size":"0.95910"},{"price":"33592.31","size":"0"},{"price":"33607.30","size":"1.06920"},{"price":"33617.52","size":"0"}],"bid":[{"price":"33547.12","size":"0.02940"},{"price":"33546.82","size":"0"}],"sequence":12626600,"timestamp":"2021-07-03T00:56:19.232Z","symbol":"BTCUSDB"}}
1625273779.338343: {"jsonrpc":"2.0","method":"updateOrderbook","params":{"ask":[{"price":"0.00011579","size":"230.00"},{"price":"0.00011580","size":"1727.51"},{"price":"0.00011581","size":"510.66"},{"price":"0.00011583","size":"124.04"}],"bid":[{"price":"0.00011571","size":"230.00"}],"sequence":12351640,"timestamp":"2021-07-03T00:56:19.236Z","symbol":"EOSBTC"}}
1625273779.424438: {"jsonrpc":"2.0","method":"updateOrderbook","params":{"ask":[],"bid":[{"price":"2109.753","size":"22.1000"},{"price":"2103.542","size":"0"},{"price":"2092.591","size":"36.1000"},{"price":"2090.349","size":"0"}],"sequence":1513054,"timestamp":"2021-07-03T00:56:19.301Z","symbol":"ETHDAI"}}
1625273779.424969: {"jsonrpc":"2.0","method":"updateOrderbook","params":{"ask":[{"price":"33563.95","size":"0.18597"},{"price":"33568.36","size":"0"},{"price":"33574.46","size":"0.32123"},{"price":"33576.70","size":"0"}],"bid":[{"price":"33514.68","size":"0"},{"price":"33511.96","size":"0.31747"},{"price":"33504.60","size":"0.37383"},{"price":"33502.49","size":"0"}],"sequence":5708294,"timestamp":"2021-07-03T00:56:19.334Z","symbol":"BTCDAI"}}
1625273779.4298: {"jsonrpc":"2.0","method":"updateOrderbook","params":{"ask":[{"price":"33550.88","size":"0.02460"},{"price":"33551.18","size":"0"},{"price":"33564.81","size":"0.41740"},{"price":"33567.08","size":"1.09780"},{"price":"33570.24","size":"0.95910"},{"price":"33571.77","size":"0"},{"price":"33575.61","size":"0"},{"price":"33577.35","size":"0.75370"},{"price":"33579.73","size":"1.43490"},{"price":"33594.84","size":"1.43490"},{"price":"33598.09","size":"0"}],"bid":[{"price":"33547.54","size":"0.02940"},{"price":"33547.12","size":"0"},{"price":"33539.56","size":"0.77340"},{"price":"33538.80","size":"0"}],"sequence":12626601,"timestamp":"2021-07-03T00:56:19.318Z","symbol":"BTCUSDB"}}
1625273779.429944: {"jsonrpc":"2.0","method":"updateOrderbook","params":{"ask":[{"price":"0.00011580","size":"2139.25"},{"price":"0.00011581","size":"99.00"},{"price":"0.00011582","size":"0"},{"price":"0.00011583","size":"1118.24"},{"price":"0.00011591","size":"1717.25"},{"price":"0.00011592","size":"460.00"},{"price":"0.00011595","size":"2018.53"},{"price":"0.00011597","size":"941.38"}],"bid":[{"price":"0.00011570","size":"492.07"},{"price":"0.00011568","size":"1710.82"},{"price":"0.00011567","size":"0"},{"price":"0.00011559","size":"2612.06"},{"price":"0.00011555","size":"4729.60"}],"sequence":12351641,"timestamp":"2021-07-03T00:56:19.337Z","symbol":"EOSBTC"}}
1625273779.439476: {"jsonrpc":"2.0","method":"updateOrderbook","params":{"ask":[{"price":"33523.18","size":"0"},{"price":"33523.98","size":"0.02974"},{"price":"33532.04","size":"0"},{"price":"33533.43","size":"0.05137"},{"price":"33539.10","size":"0.06039"},{"price":"33542.38","size":"0"}],"bid":[{"price":"33494.29","size":"0"},{"price":"33491.83","size":"0.01472"},{"price":"33490.32","size":"0"},{"price":"33488.04","size":"0.02734"},{"price":"33480.23","size":"0"},{"price":"33478.56","size":"0.05077"},{"price":"33474.19","size":"0"},{"price":"33472.83","size":"0.05979"}],"sequence":7476860,"timestamp":"2021-07-03T00:56:19.337Z","symbol":"BTCTUSD"}}
1625273779.535798: {"jsonrpc":"2.0","method":"updateOrderbook","params":{"ask":[{"price":"33550.53","size":"0.02460"},{"price":"33550.88","size":"0"},{"price":"33575.23","size":"0.27520"},{"price":"33579.21","size":"0.39780"}],"bid":[{"price":"33547.54","size":"0"},{"price":"33547.07","size":"0.02940"}],"sequence":12626602,"timestamp":"2021-07-03T00:56:19.437Z","symbol":"BTCUSDB"}}
1625273779.535928: {"jsonrpc":"2.0","method":"updateOrderbook","params":{"ask":[{"price":"33633.61","size":"0"},{"price":"33644.13","size":"0"},{"price":"33655.66","size":"0.00533"},{"price":"33665.37","size":"0.00533"},{"price":"33678.47","size":"0"},{"price":"33699.80","size":"0.00533"}],"bid":[{"price":"32893.47","size":"1.26650"},{"price":"32440.26","size":"0"},{"price":"31338.18","size":"1.68120"},{"price":"29359.45","size":"0"}],"sequence":7211196,"timestamp":"2021-07-03T00:56:19.441Z","symbol":"BTCPAX"}}
1625273779.53596: {"jsonrpc":"2.0","method":"updateOrderbook","params":{"ask":[{"price":"0.09639","size":"3.7522"},{"price":"0.10402","size":"0"}],"bid":[{"price":"0.07607","size":"0"},{"price":"0.07603","size":"0.1380"},{"price":"0.07602","size":"0.6400"},{"price":"0.07599","size":"0.5550"}],"sequence":7339900,"timestamp":"2021-07-03T00:56:19.437Z","symbol":"MKRBTC"}}
1625273779.535983: {"jsonrpc":"2.0","method":"updateOrderbook","params":{"ask":[{"price":"33519.21","size":"0.01231"},{"price":"33520.09","size":"0"},{"price":"34033.54","size":"1.76840"},{"price":"34108.08","size":"0"}],"bid":[],"sequence":7476861,"timestamp":"2021-07-03T00:56:19.416Z","symbol":"BTCTUSD"}}
1625273779.6237462: {"jsonrpc":"2.0","method":"updateOrderbook","params":{"ask":[],"bid":[{"price":"33003.44","size":"1.90000"},{"price":"32929.24","size":"0"},{"price":"32799.31","size":"2.20000"},{"price":"32764.91","size":"0"}],"sequence":5708295,"timestamp":"2021-07-03T00:56:19.502Z","symbol":"BTCDAI"}}
1625273779.6267378: {"jsonrpc":"2.0","method":"updateOrderbook","params":{"ask":[{"price":"33550.27","size":"0.02460"},{"price":"33550.53","size":"0"},{"price":"33554.16","size":"0"},{"price":"33554.87","size":"0.74140"},{"price":"33555.25","size":"0.05940"},{"price":"33558.33","size":"1.03952"}],"bid":[{"price":"33496.80","size":"0.94240"},{"price":"33490.03","size":"1.31900"},{"price":"33488.62","size":"0"},{"price":"33486.59","size":"0"}],"sequence":12626603,"timestamp":"2021-07-03T00:56:19.552Z","symbol":"BTCUSDB"}}
1625273779.626784: {"jsonrpc":"2.0","method":"updateOrderbook","params":{"ask":[{"price":"0.00011578","size":"99.00"},{"price":"0.00011579","size":"354.04"},{"price":"0.00011581","size":"0"},{"price":"0.00011582","size":"120.44"},{"price":"0.00011583","size":"994.20"},{"price":"0.00011584","size":"11.51"}],"bid":[],"sequence":12351642,"timestamp":"2021-07-03T00:56:19.545Z","symbol":"EOSBTC"}}
1625273779.633884: {"jsonrpc":"2.0","method":"updateOrderbook","params":{"ask":[{"price":"0.07634","size":"0"},{"price":"0.07637","size":"0"},{"price":"0.07644","size":"1.4283"},{"price":"0.07655","size":"1.9169"},{"price":"0.07657","size":"0"},{"price":"0.07674","size":"5.0008"},{"price":"0.07703","size":"0"},{"price":"0.07721","size":"6.2765"},{"price":"0.07768","size":"0"},{"price":"0.07806","size":"9.6365"}],"bid":[],"sequence":7339901,"timestamp":"2021-07-03T00:56:19.494Z","symbol":"MKRBTC"}}
1625273779.7281091: {"jsonrpc":"2.0","method":"updateOrderbook","params":{"ask":[{"price":"33550.27","size":"0"},{"price":"33551.39","size":"0.02460"},{"price":"33555.25","size":"0"},{"price":"33556.57","size":"0.05940"},{"price":"33567.08","size":"0"},{"price":"33568.60","size":"1.09780"}],"bid":[{"price":"33547.66","size":"0.02940"},{"price":"33547.07","size":"0"},{"price":"33536.12","size":"0"},{"price":"33535.99","size":"1.81560"},{"price":"33513.60","size":"0.64790"},{"price":"33512.41","size":"0"},{"price":"33497.65","size":"0.94140"},{"price":"33496.20","size":"0"},{"price":"33494.79","size":"1.43580"},{"price":"33491.51","size":"0"},{"price":"33488.62","size":"2.64430"},{"price":"33484.64","size":"0"},{"price":"33222.28","size":"1.54703"},{"price":"33205.12","size":"0"}],"sequence":12626604,"timestamp":"2021-07-03T00:56:19.647Z","symbol":"BTCUSDB"}}
1625273779.728262: {"jsonrpc":"2.0","method":"updateOrderbook","params":{"ask":[{"price":"0.00011788","size":"0"},{"price":"0.00011820","size":"21895.64"},{"price":"0.00012082","size":"0"},{"price":"0.00012157","size":"27581.23"},{"price":"0.00012771","size":"0"},{"price":"0.00012834","size":"98730.11"},{"price":"0.00013962","size":"0"},{"price":"0.00014065","size":"53526.30"}],"bid":[],"sequence":12351643,"timestamp":"2021-07-03T00:56:19.651Z","symbol":"EOSBTC"}}
1625273779.728281: {"jsonrpc":"2.0","method":"updateOrderbook","params":{"ask":[{"price":"33634.45","size":"0.00533"},{"price":"33643.89","size":"0.00533"},{"price":"33655.66","size":"0"},{"price":"33665.37","size":"0"}],"bid":[{"price":"31114.50","size":"0"}],"sequence":7211197,"timestamp":"2021-07-03T00:56:19.632Z","symbol":"BTCPAX"}}
1625273779.7282948: {"jsonrpc":"2.0","method":"updateOrderbook","params":{"ask":[],"bid":[{"price":"0.07592","size":"3.9135"},{"price":"0.07588","size":"1.4156"}],"sequence":7339902,"timestamp":"2021-07-03T00:56:19.591Z","symbol":"MKRBTC"}}
1625273779.7331579: {"jsonrpc":"2.0","method":"updateOrderbook","params":{"ask":[{"price":"33519.21","size":"0"},{"price":"33519.87","size":"0.01231"}],"bid":[],"sequence":7476862,"timestamp":"2021-07-03T00:56:19.625Z","symbol":"BTCTUSD"}}
1625273779.83808: {"jsonrpc":"2.0","method":"updateOrderbook","params":{"ask":[{"price":"33551.05","size":"0.02460"},{"price":"33551.39","size":"0"},{"price":"33587.18","size":"0"},{"price":"33590.29","size":"0.95910"},{"price":"33612.60","size":"0.09820"},{"price":"33621.42","size":"0"}],"bid":[{"price":"33547.66","size":"0"},{"price":"33545.91","size":"0.02940"},{"price":"33540.49","size":"0.77340"},{"price":"33539.56","size":"0"}],"sequence":12626605,"timestamp":"2021-07-03T00:56:19.745Z","symbol":"BTCUSDB"}}
1625273779.838228: {"jsonrpc":"2.0","method":"updateOrderbook","params":{"ask":[],"bid":[{"price":"0.00010517","size":"23147.93"},{"price":"0.00010356","size":"0"},{"price":"0.00009213","size":"12370.85"},{"price":"0.00008925","size":"0"}],"sequence":12351644,"timestamp":"2021-07-03T00:56:19.716Z","symbol":"EOSBTC"}}
1625273779.838254: {"jsonrpc":"2.0","method":"updateOrderbook","params":{"ask":[{"price":"33634.45","size":"0"},{"price":"33643.89","size":"0"},{"price":"33662.43","size":"0.00533"},{"price":"33672.10","size":"0.00533"},{"price":"33696.33","size":"0"},{"price":"33725.74","size":"0.00533"}],"bid":[{"price":"31338.19","size":"0.00259"}],"sequence":7211198,"timestamp":"2021-07-03T00:56:19.662Z","symbol":"BTCPAX"}}
1625273779.8382761: {"jsonrpc":"2.0","method":"updateOrderbook","params":{"ask":[],"bid":[{"price":"0.07592","size":"1.9731"},{"price":"0.07587","size":"3.9791"},{"price":"0.07586","size":"0"},{"price":"0.07570","size":"2.6761"},{"price":"0.07552","size":"0"},{"price":"0.07548","size":"0"},{"price":"0.07540","size":"1.4000"},{"price":"0.07538","size":"5.8334"}],"sequence":7339903,"timestamp":"2021-07-03T00:56:19.705Z","symbol":"MKRBTC"}}
1625273779.935039: {"jsonrpc":"2.0","method":"updateOrderbook","params":{"ask":[{"price":"33552.90","size":"0.05940"},{"price":"33556.57","size":"0"}],"bid":[{"price":"33545.91","size":"0"},{"price":"33543.50","size":"0.02940"},{"price":"33541.31","size":"0"},{"price":"33540.49","size":"0"},{"price":"33539.85","size":"0.77340"},{"price":"33538.13","size":"0.05460"},{"price":"33535.99","size":"0"},{"price":"33535.27","size":"1.81560"},{"price":"33533.61","size":"0"},{"price":"33528.30","size":"0.10140"}],"sequence":12626606,"timestamp":"2021-07-03T00:56:19.849Z","symbol":"BTCUSDB"}}
1625273779.9351091: {"jsonrpc":"2.0","method":"updateOrderbook","params":{"ask":[{"price":"33661.08","size":"0.00533"},{"price":"33662.43","size":"0"}],"bid":[],"sequence":7211199,"timestamp":"2021-07-03T00:56:19.765Z","symbol":"BTCPAX"}}
1625273779.935136: {"jsonrpc":"2.0","method":"updateOrderbook","params":{"ask":[{"price":"0.09639","size":"0"},{"price":"0.09691","size":"3.7522"}],"bid":[{"price":"0.07552","size":"0.6900"},{"price":"0.07540","size":"0.7100"}],"sequence":7339904,"timestamp":"2021-07-03T00:56:19.813Z","symbol":"MKRBTC"}}
1625273779.935157: {"jsonrpc":"2.0","method":"updateOrderbook","params":{"ask":[{"price":"33518.65","size":"0.01231"},{"price":"33519.87","size":"0"}],"bid":[],"sequence":7476863,"timestamp":"2021-07-03T00:56:19.802Z","symbol":"BTCTUSD"}}
1625273780.034483: {"jsonrpc":"2.0","method":"updateOrderbook","params":{"ask":[{"price":"33561.87","size":"0.10260"},{"price":"33567.72","size":"0"},{"price":"33587.11","size":"0.95910"},{"price":"33590.29","size":"0"},{"price":"33705.77","size":"0.45190"},{"price":"33728.58","size":"0"}],"bid":[{"price":"33543.50","size":"0"},{"price":"33542.81","size":"0.02940"},{"price":"33527.56","size":"0"},{"price":"33525.56","size":"1.10595"}],"sequence":12626607,"timestamp":"2021-07-03T00:56:19.933Z","symbol":"BTCUSDB"}}
1625273780.0345511: {"jsonrpc":"2.0","method":"updateOrderbook","params":{"ask":[{"price":"0.00089177","size":"86093.30"},{"price":"0.00092366","size":"0"}],"bid":[],"sequence":12351645,"timestamp":"2021-07-03T00:56:19.901Z","symbol":"EOSBTC"}}
1625273780.0345778: {"jsonrpc":"2.0","method":"updateOrderbook","params":{"ask":[{"price":"33517.51","size":"0.01231"},{"price":"33518.65","size":"0"},{"price":"33522.43","size":"0.02974"},{"price":"33523.98","size":"0"}],"bid":[],"sequence":7476864,"timestamp":"2021-07-03T00:56:19.939Z","symbol":"BTCTUSD"}}
1625273780.034661: {"jsonrpc":"2.0","method":"updateOrderbook","params":{"ask":[],"bid":[{"price":"0.07598","size":"0"},{"price":"0.07594","size":"1.3731"}],"sequence":7339905,"timestamp":"2021-07-03T00:56:19.892Z","symbol":"MKRBTC"}}
1625273780.1367328: {"jsonrpc":"2.0","method":"updateOrderbook","params":{"ask":[{"price":"33551.11","size":"0.05940"},{"price":"33552.90","size":"0"},{"price":"167665.43","size":"0.00018"},{"price":"167676.08","size":"0"}],"bid":[{"price":"33542.81","size":"0"},{"price":"33542.50","size":"0.02940"},{"price":"33517.34","size":"0"},{"price":"33514.25","size":"1.04220"},{"price":"10060.54","size":"0"},{"price":"10059.92","size":"0.00019"}],"sequence":12626608,"timestamp":"2021-07-03T00:56:20.014Z","symbol":"BTCUSDB"}}
1625273780.13681: {"jsonrpc":"2.0","method":"updateOrderbook","params":{"ask":[{"price":"0.24068","size":"4.2976"},{"price":"0.34942","size":"0"}],"bid":[],"sequence":7339906,"timestamp":"2021-07-03T00:56:19.995Z","symbol":"MKRBTC"}}
1625273780.240748: {"jsonrpc":"2.0","method":"updateOrderbook","params":{"ask":[],"bid":[{"price":"33544.66","size":"0"},{"price":"33542.50","size":"0"},{"price":"33541.74","size":"0.02940"},{"price":"33541.68","size":"0.38210"},{"price":"33539.85","size":"0"},{"price":"33538.13","size":"0"},{"price":"33536.51","size":"0.05460"},{"price":"33535.37","size":"0.77340"},{"price":"33535.27","size":"0"},{"price":"33534.72","size":"1.81560"},{"price":"33527.96","size":"0"},{"price":"33526.60","size":"0.94240"},{"price":"33525.56","size":"0"},{"price":"33521.24","size":"1.10595"},{"price":"33520.04","size":"0"},{"price":"33515.64","size":"0.77390"},{"price":"33504.25","size":"0"},{"price":"33502.73","size":"0.96010"},{"price":"33500.59","size":"0"},{"price":"33497.65","size":"0"},{"price":"33497.47","size":"1.43690"},{"price":"33496.80","size":"0"},{"price":"33496.23","size":"0.94140"},{"price":"33491.33","size":"0.94240"},{"price":"33490.03","size":"0"},{"price":"33486.59","size":"1.31900"}],"sequence":12626609,"timestamp":"2021-07-03T00:56:20.133Z","symbol":"BTCUSDB"}}
1625273780.240802: {"jsonrpc":"2.0","method":"updateOrderbook","params":{"ask":[{"price":"0.00011578","size":"0"},{"price":"0.00011579","size":"329.00"},{"price":"0.00011580","size":"411.74"},{"price":"0.00011581","size":"124.04"},{"price":"0.00011584","size":"1738.89"}],"bid":[],"sequence":12351646,"timestamp":"2021-07-03T00:56:20.143Z","symbol":"EOSBTC"}}
1625273780.240865: {"jsonrpc":"2.0","method":"updateOrderbook","params":{"ask":[{"price":"33661.08","size":"0"},{"price":"33672.10","size":"0"},{"price":"33678.55","size":"0.00533"},{"price":"33688.17","size":"0.00533"},{"price":"33699.80","size":"0"},{"price":"33722.46","size":"0.00533"}],"bid":[],"sequence":7211200,"timestamp":"2021-07-03T00:56:20.059Z","symbol":"BTCPAX"}}
1625273780.240881: {"jsonrpc":"2.0","method":"updateOrderbook","params":{"ask":[{"price":"33516.08","size":"0.01231"},{"price":"33517.51","size":"0"},{"price":"33521.06","size":"0.02974"},{"price":"33522.43","size":"0"}],"bid":[],"sequence":7476865,"timestamp":"2021-07-03T00:56:20.149Z","symbol":"BTCTUSD"}}
1625273780.3331041: {"jsonrpc":"2.0","method":"updateOrderbook","params":{"ask":[{"price":"39905.44","size":"4.51490"},{"price":"39982.35","size":"0"}],"bid":[{"price":"33527.52","size":"0.09205"},{"price":"33526.26","size":"0"}],"sequence":5708296,"timestamp":"2021-07-03T00:56:20.185Z","symbol":"BTCDAI"}}
1625273780.333226: {"jsonrpc":"2.0","method":"updateOrderbook","params":{"ask":[{"price":"33551.11","size":"0"},{"price":"33553.51","size":"0.05940"},{"price":"33563.33","size":"0.75200"},{"price":"33564.84","size":"0"},{"price":"33610.07","size":"0.51010"},{"price":"33620.72","size":"0"}],"bid":[{"price":"33541.74","size":"0"},{"price":"33541.68","size":"0"},{"price":"33538.45","size":"0.02940"},{"price":"33536.57","size":"0.38210"},{"price":"33536.51","size":"0"},{"price":"33535.37","size":"0"},{"price":"33534.79","size":"0"},{"price":"33534.69","size":"0.77340"},{"price":"33533.53","size":"1.43690"},{"price":"33532.10","size":"0.05460"},{"price":"33528.30","size":"0"},{"price":"33526.82","size":"0"},{"price":"33526.60","size":"0"},{"price":"33524.61","size":"0.94240"},{"price":"33521.65","size":"0.10140"},{"price":"33521.24","size":"0"},{"price":"33518.51","size":"1.10595"},{"price":"33515.54","size":"0.11940"},{"price":"33513.60","size":"0"},{"price":"33510.25","size":"0.64790"},{"price":"33502.73","size":"0"},{"price":"33501.95","size":"0"},{"price":"33500.28","size":"0.96010"},{"price":"33498.93","size":"1.81560"},{"price":"33497.47","size":"0"},{"price":"33491.33","size":"0"},{"price":"33491.15","size":"1.43690"},{"price":"33488.62","size":"0"},{"price":"33486.59","size":"2.26140"},{"price":"33483.97","size":"2.64430"},{"price":"33450.62","size":"0"},{"price":"33441.60","size":"1.13040"}],"sequence":12626610,"timestamp":"2021-07-03T00:56:20.242Z","symbol":"BTCUSDB"}}
1625273780.3332832: {"jsonrpc":"2.0","method":"updateOrderbook","params":{"ask":[{"price":"0.00011583","size":"1005.71"},{"price":"0.00011584","size":"1727.38"}],"bid":[{"price":"0.00011566","size":"298.10"},{"price":"0.00011565","size":"87.20"}],"sequence":12351647,"timestamp":"2021-07-03T00:56:20.196Z","symbol":"EOSBTC"}}
1625273780.333306: {"jsonrpc":"2.0","method":"updateOrderbook","params":{"ask":[{"price":"33516.08","size":"0"},{"price":"33519.66","size":"0.01231"},{"price":"33521.06","size":"0"},{"price":"33522.36","size":"0.02974"}],"bid":[{"price":"33491.83","size":"0"},{"price":"33486.50","size":"0.01472"}],"sequence":7476866,"timestamp":"2021-07-03T00:56:20.217Z","symbol":"BTCTUSD"}}
1625273780.4300458: {"jsonrpc":"2.0","method":"updateOrderbook","params":{"ask":[{"price":"33561.95","size":"1.09780"},{"price":"33562.83","size":"0.95910"},{"price":"33568.60","size":"0"},{"price":"33570.24","size":"0"},{"price":"33570.81","size":"0.75370"},{"price":"33571.48","size":"1.43490"},{"price":"33575.23","size":"0"},{"price":"33577.35","size":"0"},{"price":"33578.41","size":"0.27520"},{"price":"33579.73","size":"0"},{"price":"33621.04","size":"0.17177"},{"price":"33626.65","size":"0.71880"},{"price":"33632.52","size":"0"},{"price":"33639.00","size":"0"}],"bid":[{"price":"33536.57","size":"0"},{"price":"33535.89","size":"0.38210"},{"price":"33533.53","size":"0"},{"price":"33532.27","size":"1.43690"},{"price":"33524.61","size":"0"},{"price":"33518.51","size":"0"},{"price":"33518.11","size":"0.94240"},{"price":"33517.23","size":"1.10595"},{"price":"33516.24","size":"0"},{"price":"33515.23","size":"0"},{"price":"33510.25","size":"0"},{"price":"33510.23","size":"0.32903"},{"price":"33508.35","size":"0.64790"},{"price":"33506.08","size":"0.81859"},{"price":"33105.39","size":"2.20353"},{"price":"33089.30","size":"0"}],"sequence":12626611,"timestamp":"2021-07-03T00:56:20.345Z","symbol":"BTCUSDB"}}
1625273780.430128: {"jsonrpc":"2.0","method":"updateOrderbook","params":{"ask":[{"price":"0.00011580","size":"0"},{"price":"0.00011581","size":"535.78"},{"price":"0.00012207","size":"16338.72"},{"price":"0.00012236","size":"0"},{"price":"0.00012939","size":"22588.08"},{"price":"0.00013333","size":"0"},{"price":"0.00015348","size":"26975.46"},{"price":"0.00015672","size":"2.00"}],"bid":[],"sequence":12351648,"timestamp":"2021-07-03T00:56:20.336Z","symbol":"EOSBTC"}}
1625273780.430161: {"jsonrpc":"2.0","method":"updateOrderbook","params":{"ask":[{"price":"33683.82","size":"0.00533"},{"price":"33688.17","size":"0"}],"bid":[{"price":"31338.18","size":"0"},{"price":"31218.11","size":"1.68120"}],"sequence":7211201,"timestamp":"2021-07-03T00:56:20.349Z","symbol":"BTCPAX"}}
1625273780.43629: {"jsonrpc":"2.0","method":"updateOrderbook","params":{"ask":[{"price":"0.09691","size":"0"},{"price":"0.10365","size":"3.7522"},{"price":"0.24068","size":"0"},{"price":"0.34362","size":"4.2976"}],"bid":[],"sequence":7339907,"timestamp":"2021-07-03T00:56:20.305Z","symbol":"MKRBTC"}}
1625273780.436322: {"jsonrpc":"2.0","method":"updateOrderbook","params":{"ask":[],"bid":[{"price":"32152.11","size":"0"},{"price":"32030.37","size":"1.67560"}],"sequence":7476867,"timestamp":"2021-07-03T00:56:20.264Z","symbol":"BTCTUSD"}}
1625273780.529417: {"jsonrpc":"2.0","method":"updateOrderbook","params":{"ask":[{"price":"33574.90","size":"0"},{"price":"33578.57","size":"0.01174"}],"bid":[{"price":"33534.72","size":"0"},{"price":"33534.14","size":"1.81560"},{"price":"33532.27","size":"0"},{"price":"33531.22","size":"1.43690"},{"price":"33518.11","size":"0"},{"price":"33517.23","size":"0"},{"price":"33517.20","size":"0.94240"},{"price":"33516.17","size":"1.10595"},{"price":"33506.41","size":"0"},{"price":"33502.13","size":"0"},{"price":"33501.78","size":"0.38210"},{"price":"33498.84","size":"0.77340"},{"price":"33491.15","size":"0"},{"price":"33487.80","size":"1.43690"}],"sequence":12626612,"timestamp":"2021-07-03T00:56:20.451Z","symbol":"BTCUSDB"}}
1625273780.52956: {"jsonrpc":"2.0","method":"updateOrderbook","params":{"ask":[{"price":"0.00011578","size":"223.04"},{"price":"0.00011579","size":"350.44"},{"price":"0.00011580","size":"411.74"},{"price":"0.00011581","size":"0"},{"price":"0.00011582","size":"0"},{"price":"0.00011599","size":"1896.82"},{"price":"0.00011602","size":"2195.59"}],"bid":[],"sequence":12351649,"timestamp":"2021-07-03T00:56:20.408Z","symbol":"EOSBTC"}}
1625273780.546356: {"jsonrpc":"2.0","method":"updateOrderbook","params":{"ask":[{"price":"0.07647","size":"0.0003"},{"price":"0.07650","size":"0"},{"price":"0.07655","size":"3.3582"},{"price":"0.07658","size":"3.2039"},{"price":"0.07671","size":"2.1638"},{"price":"0.07674","size":"2.3685"},{"price":"0.08650","size":"2.6323"},{"price":"0.10365","size":"0"},{"price":"0.11501","size":"3.7522"},{"price":"0.34362","size":"0"}],"bid":[],"sequence":7339908,"timestamp":"2021-07-03T00:56:20.443Z","symbol":"MKRBTC"}}
1625273780.546422: {"jsonrpc":"2.0","method":"updateOrderbook","params":{"ask":[],"bid":[{"price":"33491.92","size":"0.01472"},{"price":"33486.50","size":"0"}],"sequence":7476868,"timestamp":"2021-07-03T00:56:20.380Z","symbol":"BTCTUSD"}}
1625273780.629677: {"jsonrpc":"2.0","method":"updateOrderbook","params":{"ask":[{"price":"0.00011580","size":"0"},{"price":"0.00011581","size":"411.74"},{"price":"0.00011598","size":"0"},{"price":"0.00011608","size":"88.49"},{"price":"0.00012207","size":"0"},{"price":"0.00012249","size":"16338.72"},{"price":"0.00012939","size":"0"},{"price":"0.00012965","size":"22588.08"},{"price":"0.00015348","size":"0"},{"price":"0.00015370","size":"26975.46"}],"bid":[{"price":"0.00011475","size":"10860.97"},{"price":"0.00011459","size":"22590.80"}],"sequence":12351650,"timestamp":"2021-07-03T00:56:20.527Z","symbol":"EOSBTC"}}
1625273780.6297479: {"jsonrpc":"2.0","method":"updateOrderbook","params":{"ask":[{"price":"33581.47","size":"0.03960"},{"price":"33590.17","size":"0"}],"bid":[],"sequence":7211202,"timestamp":"2021-07-03T00:56:20.454Z","symbol":"BTCPAX"}}
1625273780.629774: {"jsonrpc":"2.0","method":"updateOrderbook","params":{"ask":[{"price":"33587.11","size":"0"},{"price":"33591.95","size":"0.95910"}],"bid":[{"price":"33538.45","size":"0"},{"price":"33536.08","size":"0.02940"},{"price":"33532.10","size":"0"},{"price":"33531.22","size":"0"},{"price":"33529.84","size":"1.43690"},{"price":"33529.58","size":"0.05460"},{"price":"33517.54","size":"1.10595"},{"price":"33516.17","size":"0"},{"price":"33514.25","size":"0"},{"price":"33511.18","size":"1.04220"},{"price":"33498.93","size":"0"},{"price":"33494.84","size":"1.81560"},{"price":"33494.79","size":"0"},{"price":"33491.55","size":"1.43580"},{"price":"33455.08","size":"0"},{"price":"33446.23","size":"1.46790"},{"price":"33444.44","size":"0"},{"price":"33438.04","size":"2.61890"}],"sequence":12626613,"timestamp":"2021-07-03T00:56:20.530Z","symbol":"BTCUSDB"}}
1625273780.6328058: {"jsonrpc":"2.0","method":"updateOrderbook","params":{"ask":[{"price":"0.08376","size":"0"},{"price":"0.08414","size":"15.5136"},{"price":"0.46588","size":"4.2976"}],"bid":[],"sequence":7339909,"timestamp":"2021-07-03T00:56:20.539Z","symbol":"MKRBTC"}}
1625273780.636111: {"jsonrpc":"2.0","method":"updateOrderbook","params":{"ask":[],"bid":[{"price":"33153.73","size":"0"},{"price":"33142.11","size":"1.35000"}],"sequence":7476869,"timestamp":"2021-07-03T00:56:20.477Z","symbol":"BTCTUSD"}}
1625273780.728823: {"jsonrpc":"2.0","method":"updateOrderbook","params":{"ask":[{"price":"35896.77","size":"0.57000"},{"price":"35908.28","size":"0"}],"bid":[{"price":"34056.05","size":"0"},{"price":"34045.42","size":"0.06500"}],"sequence":1470725,"timestamp":"2021-07-03T00:56:20.646Z","symbol":"BTCGUSD"}}
1625273780.728881: {"jsonrpc":"2.0","method":"updateOrderbook","params":{"ask":[{"price":"33613.89","size":"0.41570"},{"price":"33621.93","size":"0"}],"bid":[{"price":"33536.50","size":"0"},{"price":"33536.08","size":"0"},{"price":"33535.59","size":"0.02940"},{"price":"33526.37","size":"0.12346"},{"price":"33520.23","size":"0"},{"price":"33515.85","size":"0.07390"}],"sequence":12626614,"timestamp":"2021-07-03T00:56:20.627Z","symbol":"BTCUSDB"}}
1625273780.728897: {"jsonrpc":"2.0","method":"updateOrderbook","params":{"ask":[{"price":"33677.11","size":"0.00533"},{"price":"33678.55","size":"0"}],"bid":[],"sequence":7211203,"timestamp":"2021-07-03T00:56:20.616Z","symbol":"BTCPAX"}}
1625273780.732116: {"jsonrpc":"2.0","method":"updateOrderbook","params":{"ask":[{"price":"0.07678","size":"3.4246"},{"price":"0.07680","size":"0.1192"}],"bid":[],"sequence":7339910,"timestamp":"2021-07-03T00:56:20.590Z","symbol":"MKRBTC"}}
1625273780.745247: {"jsonrpc":"2.0","method":"updateOrderbook","params":{"ask":[{"price":"33518.73","size":"0.01231"},{"price":"33519.66","size":"0"}],"bid":[],"sequence":7476870,"timestamp":"2021-07-03T00:56:20.650Z","symbol":"BTCTUSD"}}
1625273780.8303092: {"jsonrpc":"2.0","method":"updateOrderbook","params":{"ask":[{"price":"33550.90","size":"0.05940"},{"price":"33553.51","size":"0"}],"bid":[{"price":"33539.82","size":"0.02940"},{"price":"33535.59","size":"0"},{"price":"33517.74","size":"0.94240"},{"price":"33517.54","size":"0"},{"price":"33517.20","size":"0"},{"price":"33517.00","size":"1.10595"}],"sequence":12626615,"timestamp":"2021-07-03T00:56:20.751Z","symbol":"BTCUSDB"}}
1625273780.832681: {"jsonrpc":"2.0","method":"updateOrderbook","params":{"ask":[{"price":"0.00023740","size":"39545.26"},{"price":"0.00024241","size":"0"},{"price":"0.00033436","size":"56176.40"},{"price":"0.00034476","size":"0"}],"bid":[{"price":"0.00011491","size":"8378.72"},{"price":"0.00011477","size":"0"}],"sequence":12351651,"timestamp":"2021-07-03T00:56:20.681Z","symbol":"EOSBTC"}}
1625273780.8326988: {"jsonrpc":"2.0","method":"updateOrderbook","params":{"ask":[{"price":"33602.89","size":"0.16080"},{"price":"33618.25","size":"0"},{"price":"33629.62","size":"0.00533"},{"price":"33677.11","size":"0"}],"bid":[{"price":"31338.19","size":"0"}],"sequence":7211204,"timestamp":"2021-07-03T00:56:20.745Z","symbol":"BTCPAX"}}
1625273780.832713: {"jsonrpc":"2.0","method":"updateOrderbook","params":{"ask":[],"bid":[{"price":"0.07584","size":"0"},{"price":"0.07573","size":"0.5527"}],"sequence":7339911,"timestamp":"2021-07-03T00:56:20.656Z","symbol":"MKRBTC"}}
1625273780.930451: {"jsonrpc":"2.0","method":"updateOrderbook","params":{"ask":[{"price":"33553.88","size":"1.03952"},{"price":"33556.56","size":"0.45140"},{"price":"33558.33","size":"0"},{"price":"33558.94","size":"0"},{"price":"33561.95","size":"1.51520"},{"price":"33564.69","size":"0.91740"},{"price":"33564.81","size":"0"},{"price":"33567.20","size":"0"},{"price":"33594.84","size":"0"},{"price":"33599.47","size":"1.43490"},{"price":"33607.30","size":"0"},{"price":"33617.52","size":"1.06920"}],"bid":[{"price":"33540.90","size":"0.02940"},{"price":"33539.82","size":"0"},{"price":"33535.86","size":"0.05460"},{"price":"33534.14","size":"0"},{"price":"33533.29","size":"1.81560"},{"price":"33529.84","size":"0"},{"price":"33529.58","size":"0"},{"price":"33527.62","size":"1.43690"},{"price":"33517.74","size":"0"},{"price":"33517.63","size":"0.94240"},{"price":"33517.00","size":"0"},{"price":"33516.00","size":"1.10595"},{"price":"33504.98","size":"0.38210"},{"price":"33501.78","size":"0"},{"price":"33492.16","size":"1.43690"},{"price":"33490.62","size":"0.94240"},{"price":"33487.80","size":"0"},{"price":"33486.59","size":"1.31900"}],"sequence":12626616,"timestamp":"2021-07-03T00:56:20.827Z","symbol":"BTCUSDB"}}
1625273780.9305081: {"jsonrpc":"2.0","method":"updateOrderbook","params":{"ask":[{"price":"0.00011580","size":"411.74"},{"price":"0.00011581","size":"0"},{"price":"0.00012965","size":"0"},{"price":"0.00012994","size":"22588.08"},{"price":"0.00023740","size":"0"},{"price":"0.00023775","size":"39545.26"},{"price":"0.00033436","size":"0"},{"price":"0.00033510","size":"56176.40"}],"bid":[],"sequence":12351652,"timestamp":"2021-07-03T00:56:20.806Z","symbol":"EOSBTC"}}
1625273780.940268: {"jsonrpc":"2.0","method":"updateOrderbook","params":{"ask":[{"price":"34033.54","size":"0"},{"price":"34084.71","size":"1.76840"},{"price":"35644.64","size":"0"},{"price":"35780.80","size":"1.29584"}],"bid":[],"sequence":7476871,"timestamp":"2021-07-03T00:56:20.788Z","symbol":"BTCTUSD"}}
1625273781.034265: {"jsonrpc":"2.0","method":"updateOrderbook","params":{"ask":[{"price":"33574.08","size":"0.01174"},{"price":"33578.57","size":"0"},{"price":"33736.69","size":"0"},{"price":"33758.32","size":"0.12750"}],"bid":[{"price":"33540.90","size":"0"},{"price":"33539.68","size":"0.02940"},{"price":"33535.86","size":"0"},{"price":"33534.24","size":"0.05460"},{"price":"33534.06","size":"1.81560"},{"price":"33533.29","size":"0"},{"price":"33516.70","size":"1.10595"},{"price":"33516.00","size":"0"},{"price":"33490.62","size":"0"},{"price":"33487.17","size":"0.94240"}],"sequence":12626617,"timestamp":"2021-07-03T00:56:20.940Z","symbol":"BTCUSDB"}}
1625273781.034291: {"jsonrpc":"2.0","method":"updateOrderbook","params":{"ask":[],"bid":[{"price":"0.00011566","size":"286.59"},{"price":"0.00011565","size":"98.71"},{"price":"0.00010973","size":"0"},{"price":"0.00010906","size":"7497.84"}],"sequence":12351653,"timestamp":"2021-07-03T00:56:20.903Z","symbol":"EOSBTC"}}
1625273781.034303: {"jsonrpc":"2.0","method":"updateOrderbook","params":{"ask":[{"price":"33636.68","size":"0.00533"},{"price":"33675.45","size":"0.00533"},{"price":"33683.82","size":"0"},{"price":"33722.46","size":"0"}],"bid":[],"sequence":7211205,"timestamp":"2021-07-03T00:56:20.929Z","symbol":"BTCPAX"}}
1625273781.0351841: {"jsonrpc":"2.0","method":"updateOrderbook","params":{"ask":[{"price":"33518.73","size":"0"},{"price":"33520.02","size":"0.01231"},{"price":"33522.36","size":"0"},{"price":"33523.76","size":"0.02974"}],"bid":[],"sequence":7476872,"timestamp":"2021-07-03T00:56:20.874Z","symbol":"BTCTUSD"}}
1625273781.125001: {"jsonrpc":"2.0","method":"updateOrderbook","params":{"ask":[{"price":"167643.75","size":"0.00019"},{"price":"167665.43","size":"0"}],"bid":[{"price":"33540.63","size":"0.02940"},{"price":"33539.68","size":"0"},{"price":"33492.16","size":"0"},{"price":"33486.86","size":"1.43690"}],"sequence":12626618,"timestamp":"2021-07-03T00:56:21.026Z","symbol":"BTCUSDB"}}
1625273781.125066: {"jsonrpc":"2.0","method":"updateOrderbook","params":{"ask":[],"bid":[{"price":"0.00011566","size":"298.10"},{"price":"0.00011565","size":"87.20"}],"sequence":12351654,"timestamp":"2021-07-03T00:56:20.999Z","symbol":"EOSBTC"}}
1625273781.125089: {"jsonrpc":"2.0","method":"updateOrderbook","params":{"ask":[{"price":"33612.61","size":"0.20400"},{"price":"33632.88","size":"0"},{"price":"33633.47","size":"0.25340"},{"price":"33658.89","size":"0"}],"bid":[],"sequence":7211206,"timestamp":"2021-07-03T00:56:21.035Z","symbol":"BTCPAX"}}
1625273781.136563: {"jsonrpc":"2.0","method":"updateOrderbook","params":{"ask":[{"price":"33520.02","size":"0"},{"price":"33520.38","size":"0.01231"}],"bid":[],"sequence":7476873,"timestamp":"2021-07-03T00:56:21.050Z","symbol":"BTCTUSD"}}
1625273781.235104: {"jsonrpc":"2.0","method":"updateOrderbook","params":{"ask":[],"bid":[{"price":"33540.63","size":"0"},{"price":"33540.24","size":"0.02940"}],"sequence":12626619,"timestamp":"2021-07-03T00:56:21.127Z","symbol":"BTCUSDB"}}
1625273781.235161: {"jsonrpc":"2.0","method":"updateOrderbook","params":{"ask":[{"price":"0.00011598","size":"88.49"},{"price":"0.00011608","size":"0"}],"bid":[],"sequence":12351655,"timestamp":"2021-07-03T00:56:21.106Z","symbol":"EOSBTC"}}
1625273781.243668: {"jsonrpc":"2.0","method":"updateOrderbook","params":{"ask":[{"price":"33520.38","size":"0"},{"price":"33520.79","size":"0.01231"}],"bid":[],"sequence":7476874,"timestamp":"2021-07-03T00:56:21.059Z","symbol":"BTCTUSD"}}
1625273781.334937: {"jsonrpc":"2.0","method":"updateOrderbook","params":{"ask":[],"bid":[{"price":"33528.87","size":"0.09205"},{"price":"33527.52","size":"0"}],"sequence":5708297,"timestamp":"2021-07-03T00:56:21.236Z","symbol":"BTCDAI"}}
1625273781.33506: {"jsonrpc":"2.0","method":"updateOrderbook","params":{"ask":[{"price":"33694.41","size":"0.00533"},{"price":"33725.74","size":"0"}],"bid":[],"sequence":7211207,"timestamp":"2021-07-03T00:56:21.215Z","symbol":"BTCPAX"}}
1625273781.335083: {"jsonrpc":"2.0","method":"updateOrderbook","params":{"ask":[{"price":"33520.79","size":"0"},{"price":"33521.86","size":"0.01231"},{"price":"33523.76","size":"0"},{"price":"33525.22","size":"0.02974"}],"bid":[],"sequence":7476875,"timestamp":"2021-07-03T00:56:21.214Z","symbol":"BTCTUSD"}}
1625273781.4295092: {"jsonrpc":"2.0","method":"updateOrderbook","params":{"ask":[{"price":"33583.95","size":"0.35370"},{"price":"33587.76","size":"0"},{"price":"33594.31","size":"0.94720"},{"price":"33599.23","size":"0"}],"bid":[{"price":"33534.06","size":"0"},{"price":"33531.37","size":"1.81560"},{"price":"33527.62","size":"0"},{"price":"33526.10","size":"1.43690"},{"price":"33517.63","size":"0"},{"price":"33516.77","size":"0.94240"},{"price":"33516.70","size":"0"},{"price":"33515.69","size":"1.10595"}],"sequence":12626620,"timestamp":"2021-07-03T00:56:21.314Z","symbol":"BTCUSDB"}}
1625273781.429555: {"jsonrpc":"2.0","method":"updateOrderbook","params":{"ask":[{"price":"0.00011600","size":"357.51"},{"price":"0.00011604","size":"1196.19"}],"bid":[],"sequence":12351656,"timestamp":"2021-07-03T00:56:21.279Z","symbol":"EOSBTC"}}
1625273781.436455: {"jsonrpc":"2.0","method":"updateOrderbook","params":{"ask":[{"price":"33706.66","size":"0.35600"},{"price":"33763.49","size":"0"}],"bid":[],"sequence":7211208,"timestamp":"2021-07-03T00:56:21.319Z","symbol":"BTCPAX"}}
1625273781.525782: {"jsonrpc":"2.0","method":"updateOrderbook","params":{"ask":[],"bid":[{"price":"33525.40","size":"0.17095"},{"price":"33522.44","size":"0"}],"sequence":5708298,"timestamp":"2021-07-03T00:56:21.362Z","symbol":"BTCDAI"}}
1625273781.528534: {"jsonrpc":"2.0","method":"updateOrderbook","params":{"ask":[],"bid":[{"price":"33541.76","size":"0.38210"},{"price":"33540.34","size":"0.02940"},{"price":"33540.24","size":"0"},{"price":"33535.89","size":"0"}],"sequence":12626621,"timestamp":"2021-07-03T00:56:21.421Z","symbol":"BTCUSDB"}}
1625273781.528575: {"jsonrpc":"2.0","method":"updateOrderbook","params":{"ask":[{"price":"33629.62","size":"0"},{"price":"33636.68","size":"0"},{"price":"33675.45","size":"0"},{"price":"33676.09","size":"0.00533"},{"price":"33682.23","size":"0.00533"},{"price":"33694.41","size":"0"},{"price":"33721.01","size":"0.00533"},{"price":"33740.62","size":"0.00533"}],"bid":[{"price":"31218.12","size":"0.00260"}],"sequence":7211209,"timestamp":"2021-07-03T00:56:21.415Z","symbol":"BTCPAX"}}
1625273781.528615: {"jsonrpc":"2.0","method":"updateOrderbook","params":{"ask":[{"price":"33521.19","size":"0.01231"},{"price":"33521.86","size":"0"}],"bid":[],"sequence":7476876,"timestamp":"2021-07-03T00:56:21.370Z","symbol":"BTCTUSD"}}
1625273781.6273541: {"jsonrpc":"2.0","method":"updateOrderbook","params":{"ask":[{"price":"33595.98","size":"1.43490"},{"price":"33599.47","size":"0"}],"bid":[],"sequence":12626622,"timestamp":"2021-07-03T00:56:21.464Z","symbol":"BTCUSDB"}}
1625273781.740709: {"jsonrpc":"2.0","method":"updateOrderbook","params":{"ask":[{"price":"33574.24","size":"0.27520"},{"price":"33578.41","size":"0"}],"bid":[],"sequence":12626623,"timestamp":"2021-07-03T00:56:21.598Z","symbol":"BTCUSDB"}}
1625273781.740839: {"jsonrpc":"2.0","method":"updateOrderbook","params":{"ask":[],"bid":[],"sequence":12351657,"timestamp":"2021-07-03T00:56:21.632Z","symbol":"EOSBTC"}}
1625273781.823908: {"jsonrpc":"2.0","method":"updateOrderbook","params":{"ask":[],"bid":[{"price":"33540.81","size":"0.02940"},{"price":"33540.34","size":"0"},{"price":"33535.50","size":"0.05460"},{"price":"33534.24","size":"0"}],"sequence":12626624,"timestamp":"2021-07-03T00:56:21.724Z","symbol":"BTCUSDB"}}
1625273781.823968: {"jsonrpc":"2.0","method":"updateOrderbook","params":{"ask":[{"price":"0.00011622","size":"910.00"},{"price":"0.00011640","size":"1836.00"},{"price":"0.00011645","size":"10828.91"},{"price":"0.00011676","size":"2156.29"},{"price":"0.00011981","size":"0"},{"price":"0.00012470","size":"4513.55"},{"price":"0.00015226","size":"0"},{"price":"0.00015598","size":"5718.01"},{"price":"0.00017187","size":"0"},{"price":"0.00017497","size":"7220.48"},{"price":"0.00018932","size":"0"},{"price":"0.00019094","size":"10554.74"},{"price":"0.00022583","size":"0"},{"price":"0.00022940","size":"15617.57"},{"price":"0.00026901","size":"0"},{"price":"0.00027077","size":"21530.31"}],"bid":[{"price":"0.00010517","size":"0"},{"price":"0.00010370","size":"23147.93"},{"price":"0.00009213","size":"0"},{"price":"0.00008939","size":"12370.85"}],"sequence":12351658,"timestamp":"2021-07-03T00:56:21.689Z","symbol":"EOSBTC"}}
1625273781.827242: {"jsonrpc":"2.0","method":"updateOrderbook","params":{"ask":[],"bid":[{"price":"0.07591","size":"1.9404"},{"price":"0.07587","size":"2.0387"}],"sequence":7339912,"timestamp":"2021-07-03T00:56:21.688Z","symbol":"MKRBTC"}}
1625273781.926495: {"jsonrpc":"2.0","method":"updateOrderbook","params":{"ask":[{"price":"33574.24","size":"0.67300"},{"price":"33579.21","size":"0"},{"price":"33613.89","size":"0"},{"price":"33620.93","size":"0.41570"}],"bid":[{"price":"33541.76","size":"0"},{"price":"33535.70","size":"0.38210"},{"price":"33516.60","size":"1.10595"},{"price":"33515.69","size":"0"}],"sequence":12626625,"timestamp":"2021-07-03T00:56:21.831Z","symbol":"BTCUSDB"}}
1625273781.9265559: {"jsonrpc":"2.0","method":"updateOrderbook","params":{"ask":[{"price":"0.00011790","size":"21895.64"},{"price":"0.00011820","size":"0"},{"price":"0.00012077","size":"27581.23"},{"price":"0.00012157","size":"0"}],"bid":[],"sequence":12351659,"timestamp":"2021-07-03T00:56:21.794Z","symbol":"EOSBTC"}}
1625273782.032586: {"jsonrpc":"2.0","method":"updateOrderbook","params":{"ask":[{"price":"33719.69","size":"0.77520"},{"price":"33740.49","size":"0.52080"}],"bid":[{"price":"33532.87","size":"1.81560"},{"price":"33531.37","size":"0"},{"price":"33529.25","size":"1.43690"},{"price":"33526.10","size":"0"},{"price":"33518.93","size":"0.94240"},{"price":"33516.77","size":"0"}],"sequence":12626626,"timestamp":"2021-07-03T00:56:21.935Z","symbol":"BTCUSDB"}}
1625273782.032632: {"jsonrpc":"2.0","method":"updateOrderbook","params":{"ask":[{"price":"34951.15","size":"1.84720"},{"price":"35228.37","size":"0"}],"bid":[],"sequence":7211210,"timestamp":"2021-07-03T00:56:21.921Z","symbol":"BTCPAX"}}
1625273782.132428: {"jsonrpc":"2.0","method":"updateOrderbook","params":{"ask":[{"price":"167643.75","size":"0"},{"price":"167650.75","size":"0.00018"}],"bid":[{"price":"33541.31","size":"0.02940"},{"price":"33540.81","size":"0"},{"price":"33514.23","size":"1.37123"},{"price":"33511.18","size":"0"},{"price":"33510.23","size":"0"},{"price":"10059.92","size":"0"},{"price":"10059.04","size":"0.00016"}],"sequence":12626627,"timestamp":"2021-07-03T00:56:22.035Z","symbol":"BTCUSDB"}}
1625273782.1324868: {"jsonrpc":"2.0","method":"updateOrderbook","params":{"ask":[{"price":"0.07660","size":"2.1638"},{"price":"0.07671","size":"0"},{"price":"0.07691","size":"0"}],"bid":[],"sequence":7339913,"timestamp":"2021-07-03T00:56:21.985Z","symbol":"MKRBTC"}}
1625273782.1348422: {"jsonrpc":"2.0","method":"updateOrderbook","params":{"ask":[{"price":"33520.81","size":"0.01231"},{"price":"33521.19","size":"0"}],"bid":[],"sequence":7476877,"timestamp":"2021-07-03T00:56:21.995Z","symbol":"BTCTUSD"}}
1625273782.224709: {"jsonrpc":"2.0","method":"updateOrderbook","params":{"ask":[{"price":"33575.09","size":"1.75290"},{"price":"33576.81","size":"0"}],"bid":[{"price":"33541.31","size":"0"},{"price":"33541.07","size":"0.02940"},{"price":"33518.93","size":"0"},{"price":"33517.13","size":"0.94240"},{"price":"33497.96","size":"1.81560"},{"price":"33496.09","size":"1.43690"},{"price":"33494.84","size":"0"},{"price":"33486.86","size":"0"},{"price":"33449.99","size":"1.13040"},{"price":"33441.60","size":"0"}],"sequence":12626628,"timestamp":"2021-07-03T00:56:22.124Z","symbol":"BTCUSDB"}}
1625273782.224776: {"jsonrpc":"2.0","method":"updateOrderbook","params":{"ask":[{"price":"0.00011607","size":"2672.37"},{"price":"0.00011612","size":"345.13"},{"price":"0.00012745","size":"40454.70"},{"price":"0.00012834","size":"58275.41"},{"price":"0.00013954","size":"53526.30"},{"price":"0.00014065","size":"0"}],"bid":[{"price":"0.00011473","size":"4559.60"},{"price":"0.00011459","size":"18031.20"}],"sequence":12351660,"timestamp":"2021-07-03T00:56:22.123Z","symbol":"EOSBTC"}}
1625273782.24107: {"jsonrpc":"2.0","method":"updateOrderbook","params":{"ask":[{"price":"33520.52","size":"0.01231"},{"price":"33520.81","size":"0"}],"bid":[],"sequence":7476878,"timestamp":"2021-07-03T00:56:22.094Z","symbol":"BTCTUSD"}}
1625273782.3251991: {"jsonrpc":"2.0","method":"updateOrderbook","params":{"ask":[{"price":"33577.28","size":"0.55720"},{"price":"33581.12","size":"0"},{"price":"33718.91","size":"0.52080"},{"price":"33740.49","size":"0"}],"bid":[],"sequence":12626629,"timestamp":"2021-07-03T00:56:22.231Z","symbol":"BTCUSDB"}}
1625273782.325228: {"jsonrpc":"2.0","method":"updateOrderbook","params":{"ask":[],"bid":[{"price":"0.07582","size":"2.6761"},{"price":"0.07570","size":"0"}],"sequence":7339914,"timestamp":"2021-07-03T00:56:22.188Z","symbol":"MKRBTC"}}
1625273782.333657: {"jsonrpc":"2.0","method":"updateOrderbook","params":{"ask":[{"price":"33519.28","size":"0.01231"},{"price":"33520.52","size":"0"},{"price":"33523.66","size":"0.02974"},{"price":"33525.22","size":"0"}],"bid":[],"sequence":7476879,"timestamp":"2021-07-03T00:56:22.250Z","symbol":"BTCTUSD"}}
1625273782.42679: {"jsonrpc":"2.0","method":"updateOrderbook","params":{"ask":[{"price":"33577.32","size":"0.54615"},{"price":"33579.76","size":"0.75200"},{"price":"33581.65","size":"0"},{"price":"33584.53","size":"1.49780"}],"bid":[{"price":"33541.43","size":"0.02940"},{"price":"33541.07","size":"0"},{"price":"33491.66","size":"0.94240"},{"price":"33487.17","size":"0"},{"price":"33452.47","size":"1.46790"},{"price":"33446.23","size":"0"}],"sequence":12626630,"timestamp":"2021-07-03T00:56:22.332Z","symbol":"BTCUSDB"}}
1625273782.426867: {"jsonrpc":"2.0","method":"updateOrderbook","params":{"ask":[],"bid":[{"price":"0.00011566","size":"286.59"},{"price":"0.00011565","size":"98.71"}],"sequence":12351661,"timestamp":"2021-07-03T00:56:22.280Z","symbol":"EOSBTC"}}
1625273782.426893: {"jsonrpc":"2.0","method":"updateOrderbook","params":{"ask":[],"bid":[{"price":"0.07585","size":"0.5563"},{"price":"0.07573","size":"0"}],"sequence":7339915,"timestamp":"2021-07-03T00:56:22.291Z","symbol":"MKRBTC"}}
1625273782.5307982: {"jsonrpc":"2.0","method":"updateOrderbook","params":{"ask":[],"bid":[{"price":"33538.63","size":"0.38210"},{"price":"33535.70","size":"0"}],"sequence":12626631,"timestamp":"2021-07-03T00:56:22.445Z","symbol":"BTCUSDB"}}
1625273782.530855: {"jsonrpc":"2.0","method":"updateOrderbook","params":{"ask":[{"price":"33519.28","size":"0"},{"price":"33519.73","size":"0.01231"}],"bid":[],"sequence":7476880,"timestamp":"2021-07-03T00:56:22.363Z","symbol":"BTCTUSD"}}
1625273782.530942: {"jsonrpc":"2.0","method":"updateOrderbook","params":{"ask":[],"bid":[{"price":"0.00011566","size":"298.10"},{"price":"0.00011565","size":"87.20"}],"sequence":12351662,"timestamp":"2021-07-03T00:56:22.422Z","symbol":"EOSBTC"}}
1625273782.624471: {"jsonrpc":"2.0","method":"updateOrderbook","params":{"ask":[],"bid":[{"price":"0.00011473","size":"0"},{"price":"0.00011456","size":"4559.60"}],"sequence":12351663,"timestamp":"2021-07-03T00:56:22.497Z","symbol":"EOSBTC"}}
1625273782.728703: {"jsonrpc":"2.0","method":"updateOrderbook","params":{"ask":[],"bid":[{"price":"33541.45","size":"0.02940"},{"price":"33541.43","size":"0"},{"price":"33491.66","size":"0"},{"price":"33486.93","size":"0.94240"}],"sequence":12626632,"timestamp":"2021-07-03T00:56:22.641Z","symbol":"BTCUSDB"}}
1625273782.728724: {"jsonrpc":"2.0","method":"updateOrderbook","params":{"ask":[{"price":"0.07673","size":"3.3223"},{"price":"0.08650","size":"0"},{"price":"0.09409","size":"3.7522"},{"price":"0.11501","size":"0"}],"bid":[],"sequence":7339916,"timestamp":"2021-07-03T00:56:22.584Z","symbol":"MKRBTC"}}
1625273782.7311811: {"jsonrpc":"2.0","method":"updateOrderbook","params":{"ask":[{"price":"33563.95","size":"0.00910"},{"price":"33569.87","size":"0"}],"bid":[],"sequence":7476881,"timestamp":"2021-07-03T00:56:22.568Z","symbol":"BTCTUSD"}}
1625273782.824439: {"jsonrpc":"2.0","method":"updateOrderbook","params":{"ask":[],"bid":[{"price":"33541.45","size":"0"},{"price":"33540.61","size":"0.02940"}],"sequence":12626633,"timestamp":"2021-07-03T00:56:22.739Z","symbol":"BTCUSDB"}}
1625273782.827635: {"jsonrpc":"2.0","method":"updateOrderbook","params":{"ask":[{"price":"0.00012214","size":"16338.72"},{"price":"0.00012249","size":"0"},{"price":"0.00086970","size":"86093.30"},{"price":"0.00089177","size":"0"}],"bid":[],"sequence":12351664,"timestamp":"2021-07-03T00:56:22.730Z","symbol":"EOSBTC"}}
1625273782.941517: {"jsonrpc":"2.0","method":"updateOrderbook","params":{"ask":[{"price":"33570.24","size":"0.01174"},{"price":"33574.08","size":"0"},{"price":"33581.58","size":"0.79591"},{"price":"33585.55","size":"0"},{"price":"33600.72","size":"1.43410"},{"price":"33608.99","size":"0"}],"bid":[],"sequence":12626634,"timestamp":"2021-07-03T00:56:22.851Z","symbol":"BTCUSDB"}}
1625273782.9415832: {"jsonrpc":"2.0","method":"updateOrderbook","params":{"ask":[{"price":"0.00011598","size":"0"},{"price":"0.00011608","size":"88.49"},{"price":"0.00012214","size":"0"},{"price":"0.00012257","size":"16338.72"},{"price":"0.00015964","size":"0"},{"price":"0.00015999","size":"19505.60"},{"price":"0.00076004","size":"0"},{"price":"0.00076108","size":"42091.73"}],"bid":[],"sequence":12351665,"timestamp":"2021-07-03T00:56:22.820Z","symbol":"EOSBTC"}}
1625273782.941615: {"jsonrpc":"2.0","method":"updateOrderbook","params":{"ask":[],"bid":[{"price":"31218.11","size":"0"},{"price":"31112.54","size":"1.68120"}],"sequence":7211211,"timestamp":"2021-07-03T00:56:22.788Z","symbol":"BTCPAX"}}
1625273782.9416351: {"jsonrpc":"2.0","method":"updateOrderbook","params":{"ask":[{"price":"33519.44","size":"0.01231"},{"price":"33519.73","size":"0"},{"price":"33579.57","size":"0.09760"},{"price":"33590.47","size":"0.15630"},{"price":"33591.11","size":"0"},{"price":"33603.74","size":"0"}],"bid":[],"sequence":7476882,"timestamp":"2021-07-03T00:56:22.849Z","symbol":"BTCTUSD"}}
1625273783.02669: {"jsonrpc":"2.0","method":"updateOrderbook","params":{"ask":[{"price":"33660.68","size":"1.07700"},{"price":"33671.95","size":"1.25250"},{"price":"33674.81","size":"0"},{"price":"33707.37","size":"0"}],"bid":[{"price":"33541.02","size":"0.02940"},{"price":"33540.61","size":"0"}],"sequence":12626635,"timestamp":"2021-07-03T00:56:22.939Z","symbol":"BTCUSDB"}}
1625273783.036232: {"jsonrpc":"2.0","method":"updateOrderbook","params":{"ask":[{"price":"33518.47","size":"0.01231"},{"price":"33519.44","size":"0"}],"bid":[],"sequence":7476883,"timestamp":"2021-07-03T00:56:22.920Z","symbol":"BTCTUSD"}}
1625273783.129465: {"jsonrpc":"2.0","method":"updateOrderbook","params":{"ask":[{"price":"33600.62","size":"1.07210"},{"price":"33606.10","size":"0"},{"price":"167645.58","size":"0.00016"},{"price":"167650.75","size":"0"}],"bid":[{"price":"10059.04","size":"0"},{"price":"10058.73","size":"0.00015"}],"sequence":12626636,"timestamp":"2021-07-03T00:56:23.044Z","symbol":"BTCUSDB"}}
1625273783.129526: {"jsonrpc":"2.0","method":"updateOrderbook","params":{"ask":[{"price":"0.00086970","size":"0"},{"price":"0.00087596","size":"86093.30"}],"bid":[],"sequence":12351666,"timestamp":"2021-07-03T00:56:22.995Z","symbol":"EOSBTC"}}
1625273783.12955: {"jsonrpc":"2.0","method":"updateOrderbook","params":{"ask":[{"price":"0.09409","size":"0"},{"price":"0.09664","size":"3.7522"}],"bid":[{"price":"0.07598","size":"1.3731"},{"price":"0.07594","size":"0"}],"sequence":7339917,"timestamp":"2021-07-03T00:56:22.985Z","symbol":"MKRBTC"}}
1625273783.1295822: {"jsonrpc":"2.0","method":"updateOrderbook","params":{"ask":[{"price":"33518.10","size":"0.01231"},{"price":"33518.47","size":"0"},{"price":"33521.71","size":"0.02974"},{"price":"33523.66","size":"0"}],"bid":[],"sequence":7476884,"timestamp":"2021-07-03T00:56:23.013Z","symbol":"BTCTUSD"}}
1625273783.227386: {"jsonrpc":"2.0","method":"updateOrderbook","params":{"ask":[],"bid":[{"price":"33541.02","size":"0"},{"price":"33540.51","size":"0.02940"}],"sequence":12626637,"timestamp":"2021-07-03T00:56:23.071Z","symbol":"BTCUSDB"}}
1625273783.227423: {"jsonrpc":"2.0","method":"updateOrderbook","params":{"ask":[{"price":"0.00012935","size":"22588.08"},{"price":"0.00012994","size":"0"},{"price":"0.00015346","size":"26975.46"},{"price":"0.00015370","size":"0"},{"price":"0.00087596","size":"0"},{"price":"0.00087765","size":"86093.30"}],"bid":[{"price":"0.00011473","size":"4559.60"},{"price":"0.00011456","size":"0"}],"sequence":12351667,"timestamp":"2021-07-03T00:56:23.098Z","symbol":"EOSBTC"}}
1625273783.227444: {"jsonrpc":"2.0","method":"updateOrderbook","params":{"ask":[{"price":"0.07990","size":"0"},{"price":"0.08035","size":"17.0727"}],"bid":[],"sequence":7339918,"timestamp":"2021-07-03T00:56:23.082Z","symbol":"MKRBTC"}}
1625273783.227457: {"jsonrpc":"2.0","method":"updateOrderbook","params":{"ask":[{"price":"33605.45","size":"0.18170"},{"price":"33630.34","size":"0"}],"bid":[],"sequence":7476885,"timestamp":"2021-07-03T00:56:23.119Z","symbol":"BTCTUSD"}}
1625273783.326612: {"jsonrpc":"2.0","method":"updateOrderbook","params":{"ask":[{"price":"33558.50","size":"0.91740"},{"price":"33564.69","size":"0"},{"price":"33571.17","size":"1.75290"},{"price":"33575.09","size":"0"},{"price":"33612.51","size":"0.41570"},{"price":"33620.93","size":"0"},{"price":"33691.80","size":"0.82970"},{"price":"33707.85","size":"1.34610"},{"price":"33714.75","size":"0"},{"price":"33729.17","size":"0"},{"price":"33736.73","size":"0.12750"},{"price":"33758.32","size":"0"}],"bid":[],"sequence":12626638,"timestamp":"2021-07-03T00:56:23.245Z","symbol":"BTCUSDB"}}
1625273783.32668: {"jsonrpc":"2.0","method":"updateOrderbook","params":{"ask":[{"price":"0.00012935","size":"0"},{"price":"0.00012965","size":"22588.08"},{"price":"0.00015346","size":"0"},{"price":"0.00015369","size":"26975.46"},{"price":"0.00087765","size":"0"},{"price":"0.00088101","size":"86093.30"}],"bid":[],"sequence":12351668,"timestamp":"2021-07-03T00:56:23.233Z","symbol":"EOSBTC"}}
1625273783.3289979: {"jsonrpc":"2.0","method":"updateOrderbook","params":{"ask":[{"price":"0.23657","size":"4.2976"},{"price":"0.46588","size":"0"}],"bid":[],"sequence":7339919,"timestamp":"2021-07-03T00:56:23.187Z","symbol":"MKRBTC"}}
1625273783.431118: {"jsonrpc":"2.0","method":"updateOrderbook","params":{"ask":[{"price":"0.00023738","size":"39545.26"},{"price":"0.00023775","size":"0"},{"price":"0.00033432","size":"56176.40"},{"price":"0.00033510","size":"0"}],"bid":[],"sequence":12351669,"timestamp":"2021-07-03T00:56:23.337Z","symbol":"EOSBTC"}}
1625273783.4311612: {"jsonrpc":"2.0","method":"updateOrderbook","params":{"ask":[{"price":"33629.46","size":"0.00533"},{"price":"33676.09","size":"0"},{"price":"33695.75","size":"0.00533"},{"price":"33740.62","size":"0"}],"bid":[{"price":"31218.12","size":"0"}],"sequence":7211212,"timestamp":"2021-07-03T00:56:23.318Z","symbol":"BTCPAX"}}
1625273783.5332491: {"jsonrpc":"2.0","method":"updateOrderbook","params":{"ask":[{"price":"33570.25","size":"0.27520"},{"price":"33574.24","size":"0.39780"},{"price":"33580.38","size":"1.49780"},{"price":"33584.53","size":"0"},{"price":"33584.93","size":"0.95910"},{"price":"33591.95","size":"0"},{"price":"33603.81","size":"1.06920"},{"price":"33617.52","size":"0"}],"bid":[{"price":"33540.51","size":"0"},{"price":"33538.41","size":"0.02940"},{"price":"33535.50","size":"0"},{"price":"33533.57","size":"0.05460"}],"sequence":12626639,"timestamp":"2021-07-03T00:56:23.449Z","symbol":"BTCUSDB"}}
1625273783.533294: {"jsonrpc":"2.0","method":"updateOrderbook","params":{"ask":[{"price":"0.00011598","size":"88.49"},{"price":"0.00011608","size":"0"},{"price":"0.00088101","size":"0"},{"price":"0.00088145","size":"86093.30"}],"bid":[],"sequence":12351670,"timestamp":"2021-07-03T00:56:23.440Z","symbol":"EOSBTC"}}
1625273783.533392: {"jsonrpc":"2.0","method":"updateOrderbook","params":{"ask":[{"price":"33629.46","size":"0"},{"price":"33675.56","size":"0.00533"},{"price":"33695.75","size":"0"},{"price":"33741.89","size":"0.00533"}],"bid":[{"price":"31114.50","size":"0.00261"}],"sequence":7211213,"timestamp":"2021-07-03T00:56:23.362Z","symbol":"BTCPAX"}}
1625273783.629672: {"jsonrpc":"2.0","method":"updateOrderbook","params":{"ask":[{"price":"33671.95","size":"0"},{"price":"33694.21","size":"1.25250"}],"bid":[{"price":"33538.89","size":"0.02940"},{"price":"33538.41","size":"0"}],"sequence":12626640,"timestamp":"2021-07-03T00:56:23.520Z","symbol":"BTCUSDB"}}
1625273783.6296902: {"jsonrpc":"2.0","method":"updateOrderbook","params":{"ask":[],"bid":[{"price":"0.00011473","size":"0"},{"price":"0.00011459","size":"22590.80"}],"sequence":12351671,"timestamp":"2021-07-03T00:56:23.497Z","symbol":"EOSBTC"}}
1625273783.631745: {"jsonrpc":"2.0","method":"updateOrderbook","params":{"ask":[{"price":"33669.58","size":"0.00533"},{"price":"33675.56","size":"0"}],"bid":[],"sequence":7211214,"timestamp":"2021-07-03T00:56:23.479Z","symbol":"BTCPAX"}}
1625273783.63421: {"jsonrpc":"2.0","method":"updateOrderbook","params":{"ask":[{"price":"0.07640","size":"1.4283"},{"price":"0.07644","size":"0"},{"price":"0.07651","size":"1.9169"},{"price":"0.07655","size":"1.4413"},{"price":"0.07688","size":"4.9241"}],"bid":[],"sequence":7339920,"timestamp":"2021-07-03T00:56:23.529Z","symbol":"MKRBTC"}}
1625273783.634238: {"jsonrpc":"2.0","method":"updateOrderbook","params":{"ask":[{"price":"33518.10","size":"0"},{"price":"33518.54","size":"0.01231"}],"bid":[],"sequence":7476886,"timestamp":"2021-07-03T00:56:23.466Z","symbol":"BTCTUSD"}}
1625273783.732009: {"jsonrpc":"2.0","method":"updateOrderbook","params":{"ask":[{"price":"33622.90","size":"1.29870"},{"price":"33633.02","size":"0"}],"bid":[{"price":"33540.51","size":"0.02940"},{"price":"33538.89","size":"0"},{"price":"33535.30","size":"0.05460"},{"price":"33533.57","size":"0"},{"price":"33519.33","size":"0.94240"},{"price":"33517.13","size":"0"}],"sequence":12626641,"timestamp":"2021-07-03T00:56:23.637Z","symbol":"BTCUSDB"}}
1625273783.732034: {"jsonrpc":"2.0","method":"updateOrderbook","params":{"ask":[{"price":"33676.29","size":"0.00533"},{"price":"33682.23","size":"0"}],"bid":[],"sequence":7211215,"timestamp":"2021-07-03T00:56:23.637Z","symbol":"BTCPAX"}}
1625273783.8296478: {"jsonrpc":"2.0","method":"updateOrderbook","params":{"ask":[],"bid":[{"price":"33540.51","size":"0"},{"price":"33539.05","size":"0.02940"},{"price":"33535.30","size":"0"},{"price":"33533.23","size":"0.05460"},{"price":"33490.32","size":"0.94240"},{"price":"33486.93","size":"0"}],"sequence":12626642,"timestamp":"2021-07-03T00:56:23.686Z","symbol":"BTCUSDB"}}
1625273783.829675: {"jsonrpc":"2.0","method":"updateOrderbook","params":{"ask":[{"price":"0.00011578","size":"99.00"},{"price":"0.00011579","size":"641.74"},{"price":"0.00011580","size":"0"},{"price":"0.00011582","size":"244.48"}],"bid":[{"price":"0.00011566","size":"286.59"},{"price":"0.00011565","size":"98.71"}],"sequence":12351672,"timestamp":"2021-07-03T00:56:23.706Z","symbol":"EOSBTC"}}
1625273783.833786: {"jsonrpc":"2.0","method":"updateOrderbook","params":{"ask":[{"price":"33518.54","size":"0"},{"price":"33520.20","size":"0.01231"},{"price":"33521.71","size":"0"},{"price":"33522.99","size":"0.02974"}],"bid":[],"sequence":7476887,"timestamp":"2021-07-03T00:56:23.680Z","symbol":"BTCTUSD"}}
1625273783.925236: {"jsonrpc":"2.0","method":"updateOrderbook","params":{"ask":[],"bid":[{"price":"33530.14","size":"0.09205"},{"price":"33528.87","size":"0"}],"sequence":5708299,"timestamp":"2021-07-03T00:56:23.825Z","symbol":"BTCDAI"}}
1625273783.9256709: {"jsonrpc":"2.0","method":"updateOrderbook","params":{"ask":[],"bid":[{"price":"33541.06","size":"0.02940"},{"price":"33539.05","size":"0"}],"sequence":12626643,"timestamp":"2021-07-03T00:56:23.814Z","symbol":"BTCUSDB"}}
1625273783.9257028: {"jsonrpc":"2.0","method":"updateOrderbook","params":{"ask":[{"price":"0.00011617","size":"4400.68"},{"price":"0.00011640","size":"0"},{"price":"0.00011645","size":"12985.20"},{"price":"0.00011676","size":"0"}],"bid":[],"sequence":12351673,"timestamp":"2021-07-03T00:56:23.811Z","symbol":"EOSBTC"}}
1625273783.925725: {"jsonrpc":"2.0","method":"updateOrderbook","params":{"ask":[{"price":"33669.58","size":"0"},{"price":"33671.06","size":"0.00533"},{"price":"33676.29","size":"0"},{"price":"33677.76","size":"0.00533"}],"bid":[],"sequence":7211216,"timestamp":"2021-07-03T00:56:23.794Z","symbol":"BTCPAX"}}
1625273783.934486: {"jsonrpc":"2.0","method":"updateOrderbook","params":{"ask":[{"price":"33520.20","size":"0"},{"price":"33520.96","size":"0.01231"},{"price":"33522.99","size":"0"},{"price":"33524.29","size":"0.02974"}],"bid":[],"sequence":7476888,"timestamp":"2021-07-03T00:56:23.836Z","symbol":"BTCTUSD"}}
1625273784.0297868: {"jsonrpc":"2.0","method":"updateOrderbook","params":{"ask":[{"price":"33558.50","size":"0"},{"price":"33560.24","size":"0.91740"},{"price":"33561.95","size":"0.41740"},{"price":"33562.83","size":"0"},{"price":"33564.62","size":"1.09780"},{"price":"33564.82","size":"0.95910"},{"price":"33570.24","size":"0"},{"price":"33570.25","size":"0"},{"price":"33570.81","size":"0"},{"price":"33571.48","size":"0"},{"price":"33573.13","size":"0.01174"},{"price":"33574.25","size":"0.27520"},{"price":"33576.00","size":"0.75370"},{"price":"33576.62","size":"1.43490"}],"bid":[{"price":"33541.69","size":"0.02940"},{"price":"33541.06","size":"0"},{"price":"33536.65","size":"0.05460"},{"price":"33533.23","size":"0"},{"price":"33517.10","size":"1.10595"},{"price":"33516.60","size":"0"}],"sequence":12626644,"timestamp":"2021-07-03T00:56:23.950Z","symbol":"BTCUSDB"}}
1625273784.029838: {"jsonrpc":"2.0","method":"updateOrderbook","params":{"ask":[{"price":"0.00011578","size":"223.04"},{"price":"0.00011582","size":"120.44"}],"bid":[],"sequence":12351674,"timestamp":"2021-07-03T00:56:23.917Z","symbol":"EOSBTC"}}
1625273784.029855: {"jsonrpc":"2.0","method":"updateOrderbook","params":{"ask":[{"price":"0.07637","size":"1.2689"},{"price":"0.07642","size":"1.4548"}],"bid":[],"sequence":7339921,"timestamp":"2021-07-03T00:56:23.934Z","symbol":"MKRBTC"}}
1625273784.030781: {"jsonrpc":"2.0","method":"updateOrderbook","params":{"ask":[{"price":"33520.96","size":"0"},{"price":"33521.32","size":"0.01231"}],"bid":[],"sequence":7476889,"timestamp":"2021-07-03T00:56:23.860Z","symbol":"BTCTUSD"}}
1625273784.128117: {"jsonrpc":"2.0","method":"updateOrderbook","params":{"ask":[{"price":"33550.90","size":"0"},{"price":"33553.48","size":"0.05940"},{"price":"33564.62","size":"0"},{"price":"33564.82","size":"0"},{"price":"33569.41","size":"1.09780"},{"price":"33570.55","size":"0.95910"},{"price":"33576.62","size":"0"},{"price":"33579.30","size":"1.43490"},{"price":"167645.58","size":"0"},{"price":"167658.70","size":"0.00011"}],"bid":[{"price":"33541.69","size":"0"},{"price":"33541.52","size":"0.02940"},{"price":"33496.09","size":"0"},{"price":"33490.67","size":"1.43690"},{"price":"33490.32","size":"0"},{"price":"33486.82","size":"0.94240"},{"price":"10059.52","size":"0.00019"},{"price":"10058.73","size":"0"}],"sequence":12626645,"timestamp":"2021-07-03T00:56:24.040Z","symbol":"BTCUSDB"}}
1625273784.1282618: {"jsonrpc":"2.0","method":"updateOrderbook","params":{"ask":[{"price":"0.00011617","size":"2564.68"},{"price":"0.00011640","size":"1836.00"},{"price":"0.00011645","size":"10828.91"},{"price":"0.00011676","size":"2156.29"}],"bid":[{"price":"0.00010985","size":"7497.84"},{"price":"0.00010906","size":"0"},{"price":"0.00010540","size":"216635.43"},{"price":"0.00010370","size":"0"},{"price":"0.00009253","size":"12370.85"},{"price":"0.00008939","size":"0"}],"sequence":12351675,"timestamp":"2021-07-03T00:56:23.993Z","symbol":"EOSBTC"}}
1625273784.13439: {"jsonrpc":"2.0","method":"updateOrderbook","params":{"ask":[{"price":"0.07639","size":"2.3685"},{"price":"0.07674","size":"0"}],"bid":[{"price":"0.07604","size":"0.1370"},{"price":"0.07601","size":"1.4327"}],"sequence":7339922,"timestamp":"2021-07-03T00:56:24.043Z","symbol":"MKRBTC"}}
1625273784.232069: {"jsonrpc":"2.0","method":"updateOrderbook","params":{"ask":[{"price":"33563.33","size":"0"},{"price":"33566.17","size":"0.75200"},{"price":"33584.93","size":"0"},{"price":"33590.35","size":"0.95910"},{"price":"33603.81","size":"0"},{"price":"33612.68","size":"1.06920"}],"bid":[{"price":"33543.65","size":"0.02940"},{"price":"33541.52","size":"0"}],"sequence":12626646,"timestamp":"2021-07-03T00:56:24.104Z","symbol":"BTCUSDB"}}
1625273784.243658: {"jsonrpc":"2.0","method":"updateOrderbook","params":{"ask":[{"price":"0.00011581","size":"994.20"},{"price":"0.00011583","size":"11.51"},{"price":"0.00011903","size":"0"},{"price":"0.00011938","size":"6250.68"}],"bid":[{"price":"0.00011473","size":"4559.60"},{"price":"0.00011459","size":"18031.20"},{"price":"0.00010540","size":"193487.50"},{"price":"0.00010514","size":"23147.93"},{"price":"0.00009253","size":"0"},{"price":"0.00009204","size":"12370.85"}],"sequence":12351676,"timestamp":"2021-07-03T00:56:24.145Z","symbol":"EOSBTC"}}
1625273784.243677: {"jsonrpc":"2.0","method":"updateOrderbook","params":{"ask":[{"price":"0.07664","size":"0"},{"price":"0.07682","size":"4.3568"},{"price":"0.07689","size":"0"},{"price":"0.07709","size":"8.2348"},{"price":"0.07761","size":"0"},{"price":"0.07812","size":"11.9903"},{"price":"0.08035","size":"0"},{"price":"0.08413","size":"17.0727"}],"bid":[],"sequence":7339923,"timestamp":"2021-07-03T00:56:24.139Z","symbol":"MKRBTC"}}
1625273784.243691: {"jsonrpc":"2.0","method":"updateOrderbook","params":{"ask":[{"price":"33521.32","size":"0"},{"price":"33523.04","size":"0.01231"},{"price":"33524.29","size":"0"},{"price":"33526.15","size":"0.02974"},{"price":"34010.82","size":"1.76840"},{"price":"34084.71","size":"0"}],"bid":[{"price":"32116.72","size":"1.67560"},{"price":"32030.37","size":"0"}],"sequence":7476890,"timestamp":"2021-07-03T00:56:24.144Z","symbol":"BTCTUSD"}}
1625273784.329331: {"jsonrpc":"2.0","method":"updateOrderbook","params":{"ask":[{"price":"33566.17","size":"0"},{"price":"33567.98","size":"0.75200"},{"price":"33576.00","size":"0"},{"price":"33578.26","size":"0.75370"}],"bid":[{"price":"33544.17","size":"0.02940"},{"price":"33543.65","size":"0"},{"price":"33519.23","size":"0.07390"},{"price":"33515.85","size":"0"}],"sequence":12626647,"timestamp":"2021-07-03T00:56:24.189Z","symbol":"BTCUSDB"}}
1625273784.329373: {"jsonrpc":"2.0","method":"updateOrderbook","params":{"ask":[{"price":"0.00011985","size":"4513.55"},{"price":"0.00012470","size":"0"}],"bid":[],"sequence":12351677,"timestamp":"2021-07-03T00:56:24.248Z","symbol":"EOSBTC"}}
1625273784.32939: {"jsonrpc":"2.0","method":"updateOrderbook","params":{"ask":[{"price":"34951.15","size":"0"},{"price":"35043.10","size":"1.84720"}],"bid":[],"sequence":7211217,"timestamp":"2021-07-03T00:56:24.187Z","symbol":"BTCPAX"}}
1625273784.329401: {"jsonrpc":"2.0","method":"updateOrderbook","params":{"ask":[{"price":"0.07637","size":"0"},{"price":"0.07640","size":"2.6972"},{"price":"0.07659","size":"0"},{"price":"0.07665","size":"3.7617"},{"price":"0.07709","size":"0"},{"price":"0.07717","size":"8.2348"},{"price":"0.08413","size":"0"},{"price":"0.08485","size":"17.0727"}],"bid":[],"sequence":7339924,"timestamp":"2021-07-03T00:56:24.221Z","symbol":"MKRBTC"}}
1625273784.329414: {"jsonrpc":"2.0","method":"updateOrderbook","params":{"ask":[{"price":"33605.45","size":"0"},{"price":"33626.19","size":"0.18170"},{"price":"34010.82","size":"0"},{"price":"34100.30","size":"1.76840"}],"bid":[],"sequence":7476891,"timestamp":"2021-07-03T00:56:24.194Z","symbol":"BTCTUSD"}}
1625273784.422081: {"jsonrpc":"2.0","method":"updateOrderbook","params":{"ask":[],"bid":[{"price":"33530.98","size":"0.09204"},{"price":"33530.14","size":"0"},{"price":"33527.02","size":"0.17094"},{"price":"33525.40","size":"0"}],"sequence":5708300,"timestamp":"2021-07-03T00:56:24.336Z","symbol":"BTCDAI"}}
1625273784.425642: {"jsonrpc":"2.0","method":"updateOrderbook","params":{"ask":[{"price":"33553.48","size":"0"},{"price":"33555.83","size":"0.05940"},{"price":"33604.18","size":"1.06920"},{"price":"33612.68","size":"0"},{"price":"33626.65","size":"0"},{"price":"33642.21","size":"0.71880"},{"price":"33705.77","size":"0"},{"price":"33707.85","size":"0"},{"price":"33731.53","size":"0.45190"},{"price":"33734.68","size":"1.34610"}],"bid":[],"sequence":12626648,"timestamp":"2021-07-03T00:56:24.342Z","symbol":"BTCUSDB"}}
1625273784.4257169: {"jsonrpc":"2.0","method":"updateOrderbook","params":{"ask":[{"price":"0.00011578","size":"99.00"},{"price":"0.00011579","size":"641.82"},{"price":"0.00011580","size":"244.48"},{"price":"0.00011581","size":"994.40"},{"price":"0.00011582","size":"0"},{"price":"0.00011590","size":"1806.70"},{"price":"0.00011591","size":"0"},{"price":"0.00011593","size":"2392.62"},{"price":"0.00011595","size":"0"}],"bid":[{"price":"0.00011570","size":"492.17"},{"price":"0.00011568","size":"1711.00"},{"price":"0.00011560","size":"1697.51"},{"price":"0.00011559","size":"914.89"},{"price":"0.00011556","size":"1998.84"},{"price":"0.00011555","size":"2731.16"}],"sequence":12351678,"timestamp":"2021-07-03T00:56:24.349Z","symbol":"EOSBTC"}}
1625273784.4258602: {"jsonrpc":"2.0","method":"updateOrderbook","params":{"ask":[{"price":"33671.06","size":"0"},{"price":"33672.66","size":"0.00533"},{"price":"33677.76","size":"0"},{"price":"33679.32","size":"0.00533"}],"bid":[{"price":"33545.64","size":"0.01072"},{"price":"33541.36","size":"0"}],"sequence":7211218,"timestamp":"2021-07-03T00:56:24.343Z","symbol":"BTCPAX"}}
1625273784.430182: {"jsonrpc":"2.0","method":"updateOrderbook","params":{"ask":[{"price":"33523.04","size":"0"},{"price":"33523.65","size":"0.01232"},{"price":"33526.15","size":"0"},{"price":"33526.82","size":"0.02976"},{"price":"33533.43","size":"0"},{"price":"33535.60","size":"0.05140"},{"price":"33539.10","size":"0"},{"price":"33540.97","size":"0.06042"}],"bid":[{"price":"33492.74","size":"0.01473"},{"price":"33491.92","size":"0"},{"price":"33489.18","size":"0.02735"},{"price":"33488.04","size":"0"},{"price":"33480.43","size":"0.05080"},{"price":"33478.56","size":"0"},{"price":"33475.05","size":"0.05982"},{"price":"33472.83","size":"0"}],"sequence":7476892,"timestamp":"2021-07-03T00:56:24.346Z","symbol":"BTCTUSD"}}
1625273784.524752: {"jsonrpc":"2.0","method":"updateOrderbook","params":{"ask":[{"price":"33553.88","size":"0"},{"price":"33555.74","size":"1.03952"},{"price":"33560.24","size":"0"},{"price":"33562.87","size":"0.91740"},{"price":"33571.17","size":"0"},{"price":"33573.65","size":"1.75290"},{"price":"33580.38","size":"0"},{"price":"33584.43","size":"1.49780"},{"price":"33594.31","size":"0"},{"price":"33599.90","size":"0.94720"},{"price":"33604.18","size":"0"},{"price":"33615.17","size":"1.06920"},{"price":"33622.90","size":"0"},{"price":"33634.88","size":"1.29870"},{"price":"33691.80","size":"0"},{"price":"33716.49","size":"0.82970"}],"bid":[{"price":"33544.91","size":"0.02940"},{"price":"33544.17","size":"0"},{"price":"33541.81","size":"0.38210"},{"price":"33541.13","size":"0.77340"},{"price":"33538.63","size":"0"},{"price":"33535.43","size":"1.81560"},{"price":"33534.69","size":"0"},{"price":"33533.17","size":"1.43690"},{"price":"33532.87","size":"0"},{"price":"33529.25","size":"0"},{"price":"33524.25","size":"0.94240"},{"price":"33524.05","size":"1.10595"},{"price":"33519.33","size":"0"},{"price":"33518.32","size":"0.77390"},{"price":"33517.10","size":"0"},{"price":"33515.64","size":"0"}],"sequence":12626649,"timestamp":"2021-07-03T00:56:24.451Z","symbol":"BTCUSDB"}}
1625273784.627003: {"jsonrpc":"2.0","method":"updateOrderbook","params":{"ask":[{"price":"33555.74","size":"0"},{"price":"33557.89","size":"1.03952"},{"price":"33574.24","size":"0"},{"price":"33577.71","size":"0.39780"},{"price":"33581.58","size":"0"},{"price":"33584.43","size":"0"},{"price":"33585.96","size":"0.79591"},{"price":"33589.54","size":"1.49780"},{"price":"33590.35","size":"0"},{"price":"33593.05","size":"0"},{"price":"33594.61","size":"0.95910"},{"price":"33595.98","size":"0"},{"price":"33596.94","size":"0.75370"},{"price":"33605.96","size":"1.43490"}],"bid":[],"sequence":12626650,"timestamp":"2021-07-03T00:56:24.465Z","symbol":"BTCUSDB"}}
1625273784.627073: {"jsonrpc":"2.0","method":"updateOrderbook","params":{"ask":[{"price":"0.00088145","size":"0"},{"price":"0.00088174","size":"86093.30"}],"bid":[{"price":"0.00011473","size":"0"},{"price":"0.00011457","size":"22978.18"}],"sequence":12351679,"timestamp":"2021-07-03T00:56:24.498Z","symbol":"EOSBTC"}}
1625273784.630313: {"jsonrpc":"2.0","method":"updateOrderbook","params":{"ask":[{"price":"0.07685","size":"6.2765"},{"price":"0.07721","size":"0"}],"bid":[],"sequence":7339925,"timestamp":"2021-07-03T00:56:24.528Z","symbol":"MKRBTC"}}
1625273784.630344: {"jsonrpc":"2.0","method":"updateOrderbook","params":{"ask":[{"price":"33523.35","size":"0.01232"},{"price":"33523.65","size":"0"}],"bid":[],"sequence":7476893,"timestamp":"2021-07-03T00:56:24.500Z","symbol":"BTCTUSD"}}
1625273784.723617: {"jsonrpc":"2.0","method":"updateOrderbook","params":{"ask":[],"bid":[{"price":"33530.98","size":"0"},{"price":"33529.30","size":"0.09204"}],"sequence":5708301,"timestamp":"2021-07-03T00:56:24.647Z","symbol":"BTCDAI"}}
1625273784.728698: {"jsonrpc":"2.0","method":"updateOrderbook","params":{"ask":[{"price":"33551.05","size":"0"},{"price":"33555.58","size":"0.02460"},{"price":"33555.83","size":"0"},{"price":"33556.56","size":"0"},{"price":"33557.89","size":"0"},{"price":"33560.05","size":"0.05940"},{"price":"33561.31","size":"0.45140"},{"price":"33561.87","size":"0"},{"price":"33561.95","size":"1.45692"},{"price":"33562.87","size":"0"},{"price":"33565.42","size":"0.91740"},{"price":"33567.82","size":"0.10260"},{"price":"33573.65","size":"0"},{"price":"33576.03","size":"1.75290"},{"price":"33577.32","size":"0.12875"},{"price":"33580.47","size":"0.41740"},{"price":"33600.62","size":"0"},{"price":"33607.48","size":"1.07210"},{"price":"33612.51","size":"0"},{"price":"33612.60","size":"0"},{"price":"33621.43","size":"0.09820"},{"price":"33622.31","size":"0.41570"},{"price":"33660.68","size":"0"},{"price":"33682.45","size":"1.07700"},{"price":"33718.91","size":"0"},{"price":"33734.63","size":"0"},{"price":"33740.42","size":"0.52080"},{"price":"33754.18","size":"0.65060"}],"bid":[{"price":"33544.91","size":"0"},{"price":"33542.45","size":"0.02940"},{"price":"33524.91","size":"1.10595"},{"price":"33524.05","size":"0"}],"sequence":12626651,"timestamp":"2021-07-03T00:56:24.651Z","symbol":"BTCUSDB"}}
1625273784.728788: {"jsonrpc":"2.0","method":"updateOrderbook","params":{"ask":[{"price":"0.00012965","size":"0"},{"price":"0.00013059","size":"22588.08"},{"price":"0.00015369","size":"0"},{"price":"0.00015441","size":"26975.46"},{"price":"0.00023738","size":"0"},{"price":"0.00023868","size":"39545.26"},{"price":"0.00033432","size":"0"},{"price":"0.00033705","size":"56176.40"},{"price":"0.00088174","size":"0"},{"price":"0.00089141","size":"86093.30"}],"bid":[],"sequence":12351680,"timestamp":"2021-07-03T00:56:24.621Z","symbol":"EOSBTC"}}
1625273784.7288132: {"jsonrpc":"2.0","method":"updateOrderbook","params":{"ask":[{"price":"33706.66","size":"0"},{"price":"33744.73","size":"0.35600"},{"price":"35043.10","size":"0"},{"price":"35115.24","size":"1.84720"}],"bid":[],"sequence":7211219,"timestamp":"2021-07-03T00:56:24.586Z","symbol":"BTCPAX"}}
1625273784.83393: {"jsonrpc":"2.0","method":"updateOrderbook","params":{"ask":[{"price":"33554.30","size":"0.02460"},{"price":"33554.87","size":"0.07070"},{"price":"33555.58","size":"0"},{"price":"33557.13","size":"0.67070"},{"price":"33561.31","size":"0"},{"price":"33563.10","size":"0.45140"},{"price":"33565.42","size":"0"},{"price":"33567.30","size":"0.91740"},{"price":"33577.28","size":"0"},{"price":"33581.23","size":"0.55720"},{"price":"33592.26","size":"0"},{"price":"33598.29","size":"1.17130"},{"price":"33610.07","size":"0"},{"price":"33618.94","size":"0.51010"},{"price":"33640.37","size":"0"},{"price":"33652.18","size":"0"},{"price":"33654.40","size":"1.10440"},{"price":"33667.10","size":"0.11760"},{"price":"33694.21","size":"0"},{"price":"33719.69","size":"0"},{"price":"33720.18","size":"1.25250"},{"price":"33745.81","size":"0.77520"}],"bid":[{"price":"33548.04","size":"0.02940"},{"price":"33542.45","size":"0"},{"price":"33532.34","size":"0.10140"},{"price":"33521.65","size":"0"},{"price":"33467.95","size":"1.04000"},{"price":"33462.67","size":"0"}],"sequence":12626652,"timestamp":"2021-07-03T00:56:24.736Z","symbol":"BTCUSDB"}}
1625273784.834079: {"jsonrpc":"2.0","method":"updateOrderbook","params":{"ask":[{"price":"0.00013936","size":"5718.01"},{"price":"0.00015598","size":"0"},{"price":"0.00016561","size":"7220.48"},{"price":"0.00017497","size":"0"},{"price":"0.00089141","size":"0"},{"price":"0.00089215","size":"86093.30"}],"bid":[],"sequence":12351681,"timestamp":"2021-07-03T00:56:24.751Z","symbol":"EOSBTC"}}
1625273784.834105: {"jsonrpc":"2.0","method":"updateOrderbook","params":{"ask":[{"price":"33633.47","size":"0"},{"price":"33655.58","size":"0.00533"},{"price":"33668.66","size":"0.25340"},{"price":"33672.66","size":"0"},{"price":"35115.24","size":"0"},{"price":"35230.87","size":"1.84720"}],"bid":[],"sequence":7211220,"timestamp":"2021-07-03T00:56:24.696Z","symbol":"BTCPAX"}}
1625273784.834126: {"jsonrpc":"2.0","method":"updateOrderbook","params":{"ask":[],"bid":[{"price":"0.07552","size":"0"},{"price":"0.07540","size":"1.4000"}],"sequence":7339926,"timestamp":"2021-07-03T00:56:24.671Z","symbol":"MKRBTC"}}
1625273784.834143: {"jsonrpc":"2.0","method":"updateOrderbook","params":{"ask":[{"price":"33521.33","size":"0.01232"},{"price":"33523.35","size":"0"},{"price":"33524.87","size":"0.02976"},{"price":"33526.82","size":"0"}],"bid":[{"price":"32116.72","size":"0"},{"price":"32034.29","size":"1.67560"}],"sequence":7476894,"timestamp":"2021-07-03T00:56:24.725Z","symbol":"BTCTUSD"}}
1625273784.9265978: {"jsonrpc":"2.0","method":"updateOrderbook","params":{"ask":[{"price":"33553.03","size":"0.02460"},{"price":"33554.30","size":"0"},{"price":"33556.61","size":"0.05940"},{"price":"33560.05","size":"0"},{"price":"33561.95","size":"1.03952"},{"price":"33563.60","size":"0.41740"},{"price":"33567.30","size":"0"},{"price":"33569.37","size":"0.91740"},{"price":"33624.49","size":"0"},{"price":"33632.28","size":"1.15780"},{"price":"33661.30","size":"0"},{"price":"33678.30","size":"1.37330"}],"bid":[{"price":"33549.37","size":"0.02940"},{"price":"33548.04","size":"0"},{"price":"33544.20","size":"0.05460"},{"price":"33536.65","size":"0"},{"price":"33528.21","size":"0.11940"},{"price":"33515.54","size":"0"},{"price":"33487.83","size":"2.64430"},{"price":"33483.97","size":"0"},{"price":"33476.43","size":"0.49410"},{"price":"33474.58","size":"0.43060"},{"price":"33470.61","size":"0"},{"price":"33468.78","size":"0"}],"sequence":12626653,"timestamp":"2021-07-03T00:56:24.842Z","symbol":"BTCUSDB"}}
1625273784.926773: {"jsonrpc":"2.0","method":"updateOrderbook","params":{"ask":[{"price":"0.00011578","size":"0"},{"price":"0.00011579","size":"230.00"},{"price":"0.00011580","size":"411.82"},{"price":"0.00011583","size":"0"},{"price":"0.00011584","size":"354.99"}],"bid":[{"price":"0.00011514","size":"8147.56"},{"price":"0.00011512","size":"1100.00"}],"sequence":12351682,"timestamp":"2021-07-03T00:56:24.832Z","symbol":"EOSBTC"}}
1625273784.9268181: {"jsonrpc":"2.0","method":"updateOrderbook","params":{"ask":[{"price":"33653.56","size":"0.00533"},{"price":"33655.58","size":"0"},{"price":"33661.97","size":"0.00533"},{"price":"33679.32","size":"0"},{"price":"33699.63","size":"0.00533"},{"price":"33721.01","size":"0"}],"bid":[],"sequence":7211221,"timestamp":"2021-07-03T00:56:24.836Z","symbol":"BTCPAX"}}
1625273784.93104: {"jsonrpc":"2.0","method":"updateOrderbook","params":{"ask":[{"price":"33521.33","size":"0"},{"price":"33523.68","size":"0.01232"},{"price":"33524.87","size":"0"},{"price":"33526.69","size":"0.02976"}],"bid":[],"sequence":7476895,"timestamp":"2021-07-03T00:56:24.845Z","symbol":"BTCTUSD"}}
1625273785.023802: {"jsonrpc":"2.0","method":"updateOrderbook","params":{"ask":[{"price":"33552.38","size":"0.02460"},{"price":"33553.03","size":"0"},{"price":"33599.90","size":"0"},{"price":"33606.19","size":"0.94720"}],"bid":[{"price":"33516.56","size":"0.64790"},{"price":"33511.48","size":"0.96010"},{"price":"33508.35","size":"0"},{"price":"33500.28","size":"0"},{"price":"33499.95","size":"0.94140"},{"price":"33496.23","size":"0"},{"price":"33451.87","size":"0.08510"},{"price":"33438.04","size":"2.53380"}],"sequence":12626654,"timestamp":"2021-07-03T00:56:24.925Z","symbol":"BTCUSDB"}}
1625273785.023884: {"jsonrpc":"2.0","method":"updateOrderbook","params":{"ask":[{"price":"0.00011583","size":"1727.58"},{"price":"0.00012209","size":"16338.72"},{"price":"0.00012257","size":"0"},{"price":"0.00013059","size":"0"},{"price":"0.00013163","size":"22588.08"},{"price":"0.00015441","size":"0"},{"price":"0.00015519","size":"26975.46"},{"price":"0.00023868","size":"0"},{"price":"0.00024023","size":"39545.26"},{"price":"0.00033705","size":"0"},{"price":"0.00034000","size":"56179.82"},{"price":"0.00089215","size":"0"},{"price":"0.00090341","size":"86093.30"}],"bid":[],"sequence":12351683,"timestamp":"2021-07-03T00:56:24.934Z","symbol":"EOSBTC"}}
1625273785.0284889: {"jsonrpc":"2.0","method":"updateOrderbook","params":{"ask":[{"price":"33523.13","size":"0.01232"},{"price":"33523.68","size":"0"},{"price":"33563.95","size":"0"},{"price":"33570.90","size":"0.00910"},{"price":"33590.47","size":"0"},{"price":"33604.65","size":"0.15630"},{"price":"35780.80","size":"0"},{"price":"35888.16","size":"1.29584"}],"bid":[],"sequence":7476896,"timestamp":"2021-07-03T00:56:24.895Z","symbol":"BTCTUSD"}}
1625273785.1276312: {"jsonrpc":"2.0","method":"updateOrderbook","params":{"ask":[{"price":"0.00011577","size":"230.00"},{"price":"0.00011578","size":"99.00"},{"price":"0.00011579","size":"765.86"},{"price":"0.00011580","size":"120.44"},{"price":"0.00011584","size":"11.51"}],"bid":[],"sequence":12351684,"timestamp":"2021-07-03T00:56:25.051Z","symbol":"EOSBTC"}}
1625273785.127763: {"jsonrpc":"2.0","method":"updateOrderbook","params":{"ask":[{"price":"33551.70","size":"0.02460"},{"price":"33552.38","size":"0"},{"price":"33570.55","size":"0"},{"price":"33572.43","size":"0.95910"},{"price":"167658.70","size":"0"},{"price":"167685.18","size":"0.00012"}],"bid":[{"price":"33549.37","size":"0"},{"price":"33548.82","size":"0.02940"},{"price":"33541.81","size":"1.15550"},{"price":"33541.13","size":"0"},{"price":"33540.61","size":"1.81560"},{"price":"33535.99","size":"1.43690"},{"price":"33535.43","size":"0"},{"price":"33533.17","size":"0"},{"price":"33527.88","size":"0.94240"},{"price":"33524.25","size":"0"}],"sequence":12626655,"timestamp":"2021-07-03T00:56:25.021Z","symbol":"BTCUSDB"}}
1625273785.1308732: {"jsonrpc":"2.0","method":"updateOrderbook","params":{"ask":[{"price":"0.07728","size":"9.6365"},{"price":"0.07806","size":"0"}],"bid":[],"sequence":7339927,"timestamp":"2021-07-03T00:56:24.994Z","symbol":"MKRBTC"}}
1625273785.2322948: {"jsonrpc":"2.0","method":"updateOrderbook","params":{"ask":[{"price":"33551.49","size":"0.02460"},{"price":"33551.70","size":"0"}],"bid":[],"sequence":12626656,"timestamp":"2021-07-03T00:56:25.063Z","symbol":"BTCUSDB"}}
1625273785.232414: {"jsonrpc":"2.0","method":"updateOrderbook","params":{"ask":[{"price":"0.00011579","size":"641.82"},{"price":"0.00011580","size":"244.48"},{"price":"0.00011598","size":"0"},{"price":"0.00011608","size":"88.49"},{"price":"0.00012209","size":"0"},{"price":"0.00012257","size":"16338.72"}],"bid":[{"price":"0.00011570","size":"0"},{"price":"0.00011569","size":"492.17"},{"price":"0.00011471","size":"4559.60"},{"price":"0.00011457","size":"18418.58"},{"price":"0.00011007","size":"7497.84"},{"price":"0.00010985","size":"0"}],"sequence":12351685,"timestamp":"2021-07-03T00:56:25.124Z","symbol":"EOSBTC"}}
1625273785.341589: {"jsonrpc":"2.0","method":"updateOrderbook","params":{"ask":[{"price":"33551.30","size":"0.02460"},{"price":"33551.49","size":"0"}],"bid":[{"price":"33548.82","size":"0"},{"price":"33547.85","size":"0.02940"},{"price":"33540.61","size":"0"},{"price":"33538.92","size":"1.81560"},{"price":"33535.99","size":"0"},{"price":"33535.20","size":"1.43690"},{"price":"33527.88","size":"0"},{"price":"33526.59","size":"0.94240"},{"price":"33525.20","size":"1.10595"},{"price":"33524.91","size":"0"},{"price":"33511.48","size":"0"},{"price":"33506.35","size":"0.96010"},{"price":"33504.97","size":"0.77340"},{"price":"33499.95","size":"0"},{"price":"33498.84","size":"1.43690"},{"price":"33498.79","size":"0.94240"},{"price":"33498.38","size":"0.94140"},{"price":"33490.67","size":"0"},{"price":"33486.82","size":"0"}],"sequence":12626657,"timestamp":"2021-07-03T00:56:25.248Z","symbol":"BTCUSDB"}}
1625273785.341734: {"jsonrpc":"2.0","method":"updateOrderbook","params":{"ask":[{"price":"0.00011608","size":"433.62"},{"price":"0.00011612","size":"0"},{"price":"0.00013163","size":"0"},{"price":"0.00013194","size":"22588.08"},{"price":"0.00015519","size":"0"},{"price":"0.00015545","size":"26975.46"},{"price":"0.00018658","size":"10554.74"},{"price":"0.00019094","size":"0"},{"price":"0.00021790","size":"15617.57"},{"price":"0.00022940","size":"0"},{"price":"0.00024023","size":"0"},{"price":"0.00024068","size":"39545.26"},{"price":"0.00034000","size":"3.42"},{"price":"0.00034084","size":"56176.40"},{"price":"0.00090341","size":"0"},{"price":"0.00090699","size":"86093.30"}],"bid":[{"price":"0.00011570","size":"492.17"},{"price":"0.00011569","size":"0"}],"sequence":12351686,"timestamp":"2021-07-03T00:56:25.224Z","symbol":"EOSBTC"}}
1625273785.3417711: {"jsonrpc":"2.0","method":"updateOrderbook","params":{"ask":[{"price":"0.07656","size":"6.6272"},{"price":"0.07665","size":"0"}],"bid":[],"sequence":7339928,"timestamp":"2021-07-03T00:56:25.197Z","symbol":"MKRBTC"}}
1625273785.341791: {"jsonrpc":"2.0","method":"updateOrderbook","params":{"ask":[{"price":"33522.68","size":"0.01232"},{"price":"33523.13","size":"0"}],"bid":[],"sequence":7476897,"timestamp":"2021-07-03T00:56:25.226Z","symbol":"BTCTUSD"}}
1625273785.42457: {"jsonrpc":"2.0","method":"updateOrderbook","params":{"ask":[{"price":"39905.44","size":"0"},{"price":"39982.22","size":"4.51490"}],"bid":[],"sequence":5708302,"timestamp":"2021-07-03T00:56:25.292Z","symbol":"BTCDAI"}}
1625273785.4246242: {"jsonrpc":"2.0","method":"updateOrderbook","params":{"ask":[{"price":"33550.98","size":"0.02460"},{"price":"33551.30","size":"0"},{"price":"33574.25","size":"0"},{"price":"33579.18","size":"0.27520"},{"price":"33593.91","size":"0.75370"},{"price":"33596.94","size":"0"}],"bid":[{"price":"33547.85","size":"0"},{"price":"33547.48","size":"0.02940"},{"price":"33544.20","size":"0"},{"price":"33542.39","size":"0.05460"},{"price":"33538.92","size":"0"},{"price":"33538.04","size":"1.81560"},{"price":"33525.20","size":"0"},{"price":"33524.20","size":"1.10595"}],"sequence":12626658,"timestamp":"2021-07-03T00:56:25.326Z","symbol":"BTCUSDB"}}
1625273785.4247339: {"jsonrpc":"2.0","method":"updateOrderbook","params":{"ask":[{"price":"0.00090699","size":"0"},{"price":"0.00090778","size":"86093.30"}],"bid":[{"price":"0.00011514","size":"9247.56"},{"price":"0.00011512","size":"0"}],"sequence":12351687,"timestamp":"2021-07-03T00:56:25.310Z","symbol":"EOSBTC"}}
1625273785.527364: {"jsonrpc":"2.0","method":"updateOrderbook","params":{"ask":[{"price":"33550.74","size":"0.02460"},{"price":"33550.98","size":"0"}],"bid":[{"price":"33519.23","size":"1.44513"},{"price":"33514.23","size":"0"}],"sequence":12626659,"timestamp":"2021-07-03T00:56:25.397Z","symbol":"BTCUSDB"}}
1625273785.527498: {"jsonrpc":"2.0","method":"updateOrderbook","params":{"ask":[{"price":"33652.57","size":"0.00533"},{"price":"33653.56","size":"0"}],"bid":[],"sequence":7211222,"timestamp":"2021-07-03T00:56:25.421Z","symbol":"BTCPAX"}}
1625273785.5275211: {"jsonrpc":"2.0","method":"updateOrderbook","params":{"ask":[{"price":"33522.18","size":"0.01232"},{"price":"33522.68","size":"0"}],"bid":[],"sequence":7476898,"timestamp":"2021-07-03T00:56:25.416Z","symbol":"BTCTUSD"}}
1625273785.631783: {"jsonrpc":"2.0","method":"updateOrderbook","params":{"ask":[],"bid":[{"price":"33529.30","size":"0"},{"price":"33527.83","size":"0.09204"},{"price":"33527.02","size":"0"},{"price":"33523.93","size":"0.17094"}],"sequence":5708303,"timestamp":"2021-07-03T00:56:25.462Z","symbol":"BTCDAI"}}
1625273785.631935: {"jsonrpc":"2.0","method":"updateOrderbook","params":{"ask":[{"price":"33550.62","size":"0.02460"},{"price":"33550.74","size":"0"}],"bid":[{"price":"33504.01","size":"1.81560"},{"price":"33497.96","size":"0"},{"price":"33492.92","size":"1.31900"},{"price":"33486.59","size":"0"}],"sequence":12626660,"timestamp":"2021-07-03T00:56:25.529Z","symbol":"BTCUSDB"}}
1625273785.632: {"jsonrpc":"2.0","method":"updateOrderbook","params":{"ask":[],"bid":[{"price":"0.00011471","size":"0"},{"price":"0.00011456","size":"4559.60"},{"price":"0.00011007","size":"0"},{"price":"0.00010976","size":"7497.84"}],"sequence":12351688,"timestamp":"2021-07-03T00:56:25.501Z","symbol":"EOSBTC"}}
1625273785.6352: {"jsonrpc":"2.0","method":"updateOrderbook","params":{"ask":[{"price":"0.07634","size":"1.4283"},{"price":"0.07637","size":"1.9169"},{"price":"0.07640","size":"1.2689"},{"price":"0.07651","size":"0"},{"price":"0.07661","size":"4.3568"},{"price":"0.07682","size":"0"}],"bid":[],"sequence":7339929,"timestamp":"2021-07-03T00:56:25.462Z","symbol":"MKRBTC"}}
1625273785.635242: {"jsonrpc":"2.0","method":"updateOrderbook","params":{"ask":[{"price":"33521.42","size":"0.01232"},{"price":"33522.18","size":"0"}],"bid":[],"sequence":7476899,"timestamp":"2021-07-03T00:56:25.479Z","symbol":"BTCTUSD"}}
1625273785.723348: {"jsonrpc":"2.0","method":"updateOrderbook","params":{"ask":[],"bid":[{"price":"33230.64","size":"1.84640"},{"price":"33117.30","size":"0"}],"sequence":5708304,"timestamp":"2021-07-03T00:56:25.567Z","symbol":"BTCDAI"}}
1625273785.732445: {"jsonrpc":"2.0","method":"updateOrderbook","params":{"ask":[{"price":"33550.41","size":"0.02460"},{"price":"33550.62","size":"0"},{"price":"33582.89","size":"1.49780"},{"price":"33589.54","size":"0"},{"price":"33596.01","size":"1.43490"},{"price":"33605.96","size":"0"}],"bid":[],"sequence":12626661,"timestamp":"2021-07-03T00:56:25.647Z","symbol":"BTCUSDB"}}
1625273785.732513: {"jsonrpc":"2.0","method":"updateOrderbook","params":{"ask":[{"price":"0.00013936","size":"0"},{"price":"0.00015225","size":"5718.01"},{"price":"0.00016561","size":"0"},{"price":"0.00017187","size":"7220.48"},{"price":"0.00018658","size":"0"},{"price":"0.00018932","size":"10554.74"},{"price":"0.00021790","size":"0"},{"price":"0.00022582","size":"15617.57"}],"bid":[],"sequence":12351689,"timestamp":"2021-07-03T00:56:25.638Z","symbol":"EOSBTC"}}
1625273785.7364511: {"jsonrpc":"2.0","method":"updateOrderbook","params":{"ask":[{"price":"33524.90","size":"0.02976"},{"price":"33526.69","size":"0"}],"bid":[],"sequence":7476900,"timestamp":"2021-07-03T00:56:25.600Z","symbol":"BTCTUSD"}}
1625273785.8255959: {"jsonrpc":"2.0","method":"updateOrderbook","params":{"ask":[],"bid":[{"price":"33548.46","size":"0.02940"},{"price":"33547.48","size":"0"},{"price":"33509.96","size":"0.38210"},{"price":"33504.98","size":"0"},{"price":"33498.79","size":"0"},{"price":"33493.59","size":"0.94240"},{"price":"33492.92","size":"0"},{"price":"33489.38","size":"1.31900"}],"sequence":12626662,"timestamp":"2021-07-03T00:56:25.671Z","symbol":"BTCUSDB"}}
1625273785.82566: {"jsonrpc":"2.0","method":"updateOrderbook","params":{"ask":[{"price":"0.00026766","size":"21530.31"},{"price":"0.00027077","size":"0"}],"bid":[{"price":"0.00010514","size":"0"},{"price":"0.00010491","size":"23147.93"},{"price":"0.00009204","size":"0"},{"price":"0.00009161","size":"12370.85"}],"sequence":12351690,"timestamp":"2021-07-03T00:56:25.740Z","symbol":"EOSBTC"}}
1625273785.8279302: {"jsonrpc":"2.0","method":"updateOrderbook","params":{"ask":[{"price":"0.07673","size":"0"},{"price":"0.07677","size":"0.6900"},{"price":"0.07679","size":"6.8712"},{"price":"0.09664","size":"0"},{"price":"0.10441","size":"3.7522"},{"price":"0.23657","size":"0"},{"price":"0.35535","size":"4.2976"}],"bid":[{"price":"0.07548","size":"0.6900"},{"price":"0.07547","size":"5.8334"},{"price":"0.07540","size":"0.7100"},{"price":"0.07538","size":"0"}],"sequence":7339930,"timestamp":"2021-07-03T00:56:25.704Z","symbol":"MKRBTC"}}
1625273785.923104: {"jsonrpc":"2.0","method":"updateOrderbook","params":{"ask":[],"bid":[{"price":"32116.16","size":"2.30540"},{"price":"31495.66","size":"0"},{"price":"30108.66","size":"3.10680"},{"price":"29908.41","size":"0"}],"sequence":5708305,"timestamp":"2021-07-03T00:56:25.840Z","symbol":"BTCDAI"}}
1625273785.923126: {"jsonrpc":"2.0","method":"updateOrderbook","params":{"ask":[{"price":"33550.41","size":"0"},{"price":"33550.78","size":"0.02460"}],"bid":[{"price":"33540.61","size":"1.81560"},{"price":"33538.04","size":"0"},{"price":"33537.92","size":"1.43690"},{"price":"33535.20","size":"0"},{"price":"33528.71","size":"0.94240"},{"price":"33526.66","size":"1.10595"},{"price":"33526.59","size":"0"},{"price":"33524.20","size":"0"},{"price":"33509.96","size":"0"},{"price":"33506.65","size":"0.38210"}],"sequence":12626663,"timestamp":"2021-07-03T00:56:25.812Z","symbol":"BTCUSDB"}}
1625273785.92319: {"jsonrpc":"2.0","method":"updateOrderbook","params":{"ask":[{"price":"0.00011598","size":"88.49"},{"price":"0.00011608","size":"345.13"}],"bid":[],"sequence":12351691,"timestamp":"2021-07-03T00:56:25.766Z","symbol":"EOSBTC"}}
1625273785.928273: {"jsonrpc":"2.0","method":"updateOrderbook","params":{"ask":[{"price":"0.07634","size":"0"},{"price":"0.07637","size":"0"},{"price":"0.07639","size":"1.4283"},{"price":"0.07651","size":"1.9169"},{"price":"0.07666","size":"2.3685"},{"price":"0.07685","size":"0"},{"price":"0.07689","size":"8.2348"},{"price":"0.07712","size":"6.2765"},{"price":"0.07717","size":"0"},{"price":"0.07728","size":"0"},{"price":"0.07768","size":"11.9903"},{"price":"0.07792","size":"9.6365"},{"price":"0.07812","size":"0"}],"bid":[{"price":"0.07462","size":"0"}],"sequence":7339931,"timestamp":"2021-07-03T00:56:25.803Z","symbol":"MKRBTC"}}
1625273786.0257: {"jsonrpc":"2.0","method":"updateOrderbook","params":{"ask":[{"price":"33559.24","size":"0.45140"},{"price":"33563.10","size":"0"},{"price":"33566.97","size":"0.91740"},{"price":"33569.37","size":"0"}],"bid":[],"sequence":12626664,"timestamp":"2021-07-03T00:56:25.857Z","symbol":"BTCUSDB"}}
1625273786.025759: {"jsonrpc":"2.0","method":"updateOrderbook","params":{"ask":[],"bid":[{"price":"0.00010491","size":"0"},{"price":"0.00010393","size":"23147.93"},{"price":"0.00009161","size":"0"},{"price":"0.00008979","size":"12370.85"}],"sequence":12351692,"timestamp":"2021-07-03T00:56:25.903Z","symbol":"EOSBTC"}}
1625273786.025785: {"jsonrpc":"2.0","method":"updateOrderbook","params":{"ask":[{"price":"33652.57","size":"0"},{"price":"33654.41","size":"0.00533"}],"bid":[],"sequence":7211223,"timestamp":"2021-07-03T00:56:25.887Z","symbol":"BTCPAX"}}
1625273786.027166: {"jsonrpc":"2.0","method":"updateOrderbook","params":{"ask":[{"price":"0.07651","size":"3.3582"},{"price":"0.07655","size":"0"}],"bid":[{"price":"0.07357","size":"0.6513"}],"sequence":7339932,"timestamp":"2021-07-03T00:56:25.869Z","symbol":"MKRBTC"}}
1625273786.0272279: {"jsonrpc":"2.0","method":"updateOrderbook","params":{"ask":[{"price":"33521.42","size":"0"},{"price":"33521.92","size":"0.01232"}],"bid":[],"sequence":7476901,"timestamp":"2021-07-03T00:56:25.901Z","symbol":"BTCTUSD"}}
1625273786.1267998: {"jsonrpc":"2.0","method":"updateOrderbook","params":{"ask":[{"price":"0.00011632","size":"502.37"},{"price":"0.00011638","size":"0"}],"bid":[],"sequence":12351693,"timestamp":"2021-07-03T00:56:25.987Z","symbol":"EOSBTC"}}
1625273786.130193: {"jsonrpc":"2.0","method":"updateOrderbook","params":{"ask":[{"price":"167681.00","size":"0.00015"},{"price":"167685.18","size":"0"}],"bid":[{"price":"10060.86","size":"0.00015"},{"price":"10059.52","size":"0"}],"sequence":12626665,"timestamp":"2021-07-03T00:56:25.973Z","symbol":"BTCUSDB"}}
1625273786.2221172: {"jsonrpc":"2.0","method":"updateOrderbook","params":{"ask":[{"price":"2407.217","size":"8.9672"},{"price":"2419.659","size":"0"}],"bid":[],"sequence":1513055,"timestamp":"2021-07-03T00:56:26.138Z","symbol":"ETHDAI"}}
1625273786.222174: {"jsonrpc":"2.0","method":"updateOrderbook","params":{"ask":[],"bid":[{"price":"33527.83","size":"0"},{"price":"33526.76","size":"0.09204"},{"price":"29079.94","size":"4.54640"},{"price":"28852.92","size":"0"},{"price":"27967.12","size":"1.87330"},{"price":"27681.89","size":"0"}],"sequence":5708306,"timestamp":"2021-07-03T00:56:26.137Z","symbol":"BTCDAI"}}
1625273786.2282162: {"jsonrpc":"2.0","method":"updateOrderbook","params":{"ask":[],"bid":[{"price":"0.00011471","size":"4559.60"},{"price":"0.00011456","size":"0"},{"price":"0.00011007","size":"7497.84"},{"price":"0.00010976","size":"0"}],"sequence":12351694,"timestamp":"2021-07-03T00:56:26.101Z","symbol":"EOSBTC"}}
1625273786.2282329: {"jsonrpc":"2.0","method":"updateOrderbook","params":{"ask":[{"price":"33550.59","size":"0.02460"},{"price":"33550.78","size":"0"}],"bid":[{"price":"33548.46","size":"0"},{"price":"33547.39","size":"0.02940"},{"price":"33540.61","size":"0"},{"price":"33538.73","size":"1.81560"},{"price":"33537.92","size":"0"},{"price":"33536.15","size":"1.43690"},{"price":"33528.71","size":"0"},{"price":"33526.81","size":"0.94240"},{"price":"33526.66","size":"0"},{"price":"33523.97","size":"1.10595"},{"price":"33516.56","size":"0"},{"price":"33513.73","size":"0.64790"},{"price":"33506.35","size":"0"},{"price":"33503.35","size":"0.96010"},{"price":"33451.87","size":"0"},{"price":"33438.03","size":"0.08510"}],"sequence":12626666,"timestamp":"2021-07-03T00:56:26.137Z","symbol":"BTCUSDB"}}
1625273786.233593: {"jsonrpc":"2.0","method":"updateOrderbook","params":{"ask":[{"price":"0.08035","size":"17.0727"},{"price":"0.08485","size":"0"}],"bid":[],"sequence":7339933,"timestamp":"2021-07-03T00:56:26.108Z","symbol":"MKRBTC"}}
1625273786.23365: {"jsonrpc":"2.0","method":"updateOrderbook","params":{"ask":[{"price":"33520.78","size":"0.01232"},{"price":"33521.92","size":"0"}],"bid":[],"sequence":7476902,"timestamp":"2021-07-03T00:56:26.137Z","symbol":"BTCTUSD"}}
1625273786.333368: {"jsonrpc":"2.0","method":"updateOrderbook","params":{"ask":[],"bid":[],"sequence":12351695,"timestamp":"2021-07-03T00:56:26.206Z","symbol":"EOSBTC"}}
1625273786.333379: {"jsonrpc":"2.0","method":"updateOrderbook","params":{"ask":[{"price":"33550.53","size":"0.02460"},{"price":"33550.59","size":"0"},{"price":"33554.37","size":"0.05940"},{"price":"33556.61","size":"0"}],"bid":[{"price":"33547.39","size":"0"},{"price":"33546.76","size":"0.02940"},{"price":"33541.81","size":"0.38210"},{"price":"33541.12","size":"0.77340"},{"price":"33536.15","size":"0"},{"price":"33535.26","size":"1.43690"},{"price":"33526.81","size":"0"},{"price":"33526.16","size":"0.94240"},{"price":"33523.97","size":"0"},{"price":"33522.59","size":"1.10595"},{"price":"33504.97","size":"0"},{"price":"33504.01","size":"0"},{"price":"33501.76","size":"0.77340"},{"price":"33499.56","size":"1.81560"},{"price":"33498.84","size":"0"},{"price":"33494.59","size":"1.43690"},{"price":"33493.59","size":"0"},{"price":"33489.65","size":"0.94240"}],"sequence":12626667,"timestamp":"2021-07-03T00:56:26.250Z","symbol":"BTCUSDB"}}
1625273786.33351: {"jsonrpc":"2.0","method":"updateOrderbook","params":{"ask":[],"bid":[{"price":"0.07552","size":"0.6900"},{"price":"0.07548","size":"0"},{"price":"0.07357","size":"0"}],"sequence":7339934,"timestamp":"2021-07-03T00:56:26.226Z","symbol":"MKRBTC"}}
1625273786.4332569: {"jsonrpc":"2.0","method":"updateOrderbook","params":{"ask":[],"bid":[{"price":"0.07462","size":"0.6421"}],"sequence":7339935,"timestamp":"2021-07-03T00:56:26.297Z","symbol":"MKRBTC"}}
1625273786.550247: {"jsonrpc":"2.0","method":"updateOrderbook","params":{"ask":[],"bid":[{"price":"2109.753","size":"0"},{"price":"2103.414","size":"22.1000"},{"price":"2092.591","size":"0"},{"price":"2090.213","size":"36.1000"}],"sequence":1513056,"timestamp":"2021-07-03T00:56:26.395Z","symbol":"ETHDAI"}}
1625273786.550307: {"jsonrpc":"2.0","method":"updateOrderbook","params":{"ask":[],"bid":[{"price":"33003.44","size":"0"},{"price":"32929.83","size":"1.90000"}],"sequence":5708307,"timestamp":"2021-07-03T00:56:26.395Z","symbol":"BTCDAI"}}
1625273786.5503302: {"jsonrpc":"2.0","method":"updateOrderbook","params":{"ask":[{"price":"33588.64","size":"0.95910"},{"price":"33594.61","size":"0"}],"bid":[{"price":"33506.65","size":"0"},{"price":"33500.88","size":"0.38210"}],"sequence":12626668,"timestamp":"2021-07-03T00:56:26.364Z","symbol":"BTCUSDB"}}
1625273786.6301398: {"jsonrpc":"2.0","method":"updateOrderbook","params":{"ask":[],"bid":[{"price":"33493.07","size":"0.94240"},{"price":"33489.65","size":"0"}],"sequence":12626669,"timestamp":"2021-07-03T00:56:26.465Z","symbol":"BTCUSDB"}}
1625273786.630201: {"jsonrpc":"2.0","method":"updateOrderbook","params":{"ask":[],"bid":[{"price":"0.00011471","size":"0"},{"price":"0.00011456","size":"4559.60"}],"sequence":12351696,"timestamp":"2021-07-03T00:56:26.508Z","symbol":"EOSBTC"}}
1625273786.630223: {"jsonrpc":"2.0","method":"updateOrderbook","params":{"ask":[],"bid":[{"price":"0.07540","size":"0"},{"price":"0.07539","size":"0"},{"price":"0.07463","size":"0.7100"}],"sequence":7339936,"timestamp":"2021-07-03T00:56:26.491Z","symbol":"MKRBTC"}}
1625273786.726474: {"jsonrpc":"2.0","method":"updateOrderbook","params":{"ask":[{"price":"35022.38","size":"1.84720"},{"price":"35230.87","size":"0"}],"bid":[{"price":"31195.61","size":"1.68120"},{"price":"31112.54","size":"0"}],"sequence":7211224,"timestamp":"2021-07-03T00:56:26.599Z","symbol":"BTCPAX"}}
1625273786.726532: {"jsonrpc":"2.0","method":"updateOrderbook","params":{"ask":[{"price":"33579.30","size":"0"},{"price":"33581.47","size":"1.43490"}],"bid":[{"price":"33535.89","size":"1.43690"},{"price":"33535.26","size":"0"},{"price":"33526.74","size":"0.94240"},{"price":"33526.16","size":"0"},{"price":"33523.35","size":"1.10595"},{"price":"33522.59","size":"0"}],"sequence":12626670,"timestamp":"2021-07-03T00:56:26.617Z","symbol":"BTCUSDB"}}
1625273786.831573: {"jsonrpc":"2.0","method":"updateOrderbook","params":{"ask":[{"price":"33604.76","size":"1.06920"},{"price":"33615.17","size":"0"}],"bid":[{"price":"33538.73","size":"0"},{"price":"33538.09","size":"1.81560"},{"price":"33535.89","size":"0"},{"price":"33535.21","size":"1.43690"},{"price":"33526.74","size":"0"},{"price":"33526.16","size":"0.94240"},{"price":"33523.35","size":"0"},{"price":"33522.60","size":"1.10595"}],"sequence":12626671,"timestamp":"2021-07-03T00:56:26.668Z","symbol":"BTCUSDB"}}
1625273786.831615: {"jsonrpc":"2.0","method":"updateOrderbook","params":{"ask":[],"bid":[{"price":"0.07463","size":"0"},{"price":"0.07462","size":"0"},{"price":"0.07357","size":"0.7100"}],"sequence":7339937,"timestamp":"2021-07-03T00:56:26.662Z","symbol":"MKRBTC"}}
1625273786.831648: {"jsonrpc":"2.0","method":"updateOrderbook","params":{"ask":[{"price":"33520.78","size":"0"},{"price":"33521.61","size":"0.01232"}],"bid":[],"sequence":7476903,"timestamp":"2021-07-03T00:56:26.750Z","symbol":"BTCTUSD"}}
1625273786.925598: {"jsonrpc":"2.0","method":"updateOrderbook","params":{"ask":[{"price":"33550.39","size":"0.02460"},{"price":"33550.53","size":"0"},{"price":"33554.37","size":"0"},{"price":"33555.85","size":"0.05940"}],"bid":[{"price":"33547.54","size":"0.02940"},{"price":"33546.76","size":"0"}],"sequence":12626672,"timestamp":"2021-07-03T00:56:26.833Z","symbol":"BTCUSDB"}}
1625273786.925672: {"jsonrpc":"2.0","method":"updateOrderbook","params":{"ask":[],"bid":[{"price":"0.07357","size":"1.3613"}],"sequence":7339938,"timestamp":"2021-07-03T00:56:26.781Z","symbol":"MKRBTC"}}
1625273786.926625: {"jsonrpc":"2.0","method":"updateOrderbook","params":{"ask":[{"price":"33521.20","size":"0.01232"},{"price":"33521.61","size":"0"}],"bid":[{"price":"32108.15","size":"1.67560"},{"price":"32034.29","size":"0"}],"sequence":7476904,"timestamp":"2021-07-03T00:56:26.795Z","symbol":"BTCTUSD"}}
1625273787.0308359: {"jsonrpc":"2.0","method":"updateOrderbook","params":{"ask":[{"price":"33550.39","size":"0"},{"price":"33551.39","size":"0.02460"},{"price":"33555.85","size":"0"},{"price":"33557.18","size":"0.05940"}],"bid":[{"price":"33547.54","size":"0"},{"price":"33546.91","size":"0.02940"},{"price":"33504.17","size":"0.38210"},{"price":"33500.88","size":"0"},{"price":"32552.81","size":"2.84092"},{"price":"32502.97","size":"0"},{"price":"31078.15","size":"3.00570"},{"price":"31017.34","size":"0"},{"price":"30723.38","size":"2.82432"},{"price":"30662.16","size":"0"}],"sequence":12626673,"timestamp":"2021-07-03T00:56:26.948Z","symbol":"BTCUSDB"}}
1625273787.0308878: {"jsonrpc":"2.0","method":"updateOrderbook","params":{"ask":[],"bid":[{"price":"0.07552","size":"0"},{"price":"0.07548","size":"0.6900"}],"sequence":7339939,"timestamp":"2021-07-03T00:56:26.894Z","symbol":"MKRBTC"}}
1625273787.030901: {"jsonrpc":"2.0","method":"updateOrderbook","params":{"ask":[{"price":"33521.20","size":"0"},{"price":"33521.26","size":"0.01232"},{"price":"33523.73","size":"0.02976"},{"price":"33524.90","size":"0"}],"bid":[],"sequence":7476905,"timestamp":"2021-07-03T00:56:26.945Z","symbol":"BTCTUSD"}}
1625273787.126892: {"jsonrpc":"2.0","method":"updateOrderbook","params":{"ask":[{"price":"33551.39","size":"0"},{"price":"33551.95","size":"0.02460"},{"price":"167678.48","size":"0.00012"},{"price":"167681.00","size":"0"}],"bid":[{"price":"33547.69","size":"0.02940"},{"price":"33546.91","size":"0"},{"price":"10060.86","size":"0"},{"price":"10060.70","size":"0.00016"}],"sequence":12626674,"timestamp":"2021-07-03T00:56:27.041Z","symbol":"BTCUSDB"}}
1625273787.135799: {"jsonrpc":"2.0","method":"updateOrderbook","params":{"ask":[{"price":"33519.84","size":"0.01232"},{"price":"33521.26","size":"0"}],"bid":[],"sequence":7476906,"timestamp":"2021-07-03T00:56:26.993Z","symbol":"BTCTUSD"}}
1625273787.234314: {"jsonrpc":"2.0","method":"updateOrderbook","params":{"ask":[{"price":"33551.71","size":"0.02460"},{"price":"33551.95","size":"0"}],"bid":[{"price":"33541.81","size":"1.15550"},{"price":"33541.12","size":"0"}],"sequence":12626675,"timestamp":"2021-07-03T00:56:27.150Z","symbol":"BTCUSDB"}}
1625273787.234445: {"jsonrpc":"2.0","method":"updateOrderbook","params":{"ask":[{"price":"33654.41","size":"0"},{"price":"33655.44","size":"0.00533"},{"price":"33661.97","size":"0"},{"price":"33663.90","size":"0.00533"},{"price":"35022.38","size":"0"},{"price":"35115.26","size":"1.84720"}],"bid":[],"sequence":7211225,"timestamp":"2021-07-03T00:56:27.114Z","symbol":"BTCPAX"}}
1625273787.234473: {"jsonrpc":"2.0","method":"updateOrderbook","params":{"ask":[{"price":"0.00011917","size":"6250.68"},{"price":"0.00011938","size":"0"}],"bid":[{"price":"0.00011571","size":"428.72"},{"price":"0.00011566","size":"87.73"}],"sequence":12351697,"timestamp":"2021-07-03T00:56:27.097Z","symbol":"EOSBTC"}}
1625273787.2345011: {"jsonrpc":"2.0","method":"updateOrderbook","params":{"ask":[{"price":"0.07910","size":"1.6378"},{"price":"0.07916","size":"0"}],"bid":[{"price":"0.07357","size":"0.7100"}],"sequence":7339940,"timestamp":"2021-07-03T00:56:27.134Z","symbol":"MKRBTC"}}
1625273787.234532: {"jsonrpc":"2.0","method":"updateOrderbook","params":{"ask":[{"price":"33519.84","size":"0"},{"price":"33520.76","size":"0.01232"},{"price":"35713.68","size":"1.29584"},{"price":"35888.16","size":"0"}],"bid":[{"price":"33495.12","size":"0.01473"},{"price":"33492.74","size":"0"}],"sequence":7476907,"timestamp":"2021-07-03T00:56:27.117Z","symbol":"BTCTUSD"}}
1625273787.335816: {"jsonrpc":"2.0","method":"updateOrderbook","params":{"ask":[],"bid":[{"price":"0.07462","size":"0.6421"}],"sequence":7339941,"timestamp":"2021-07-03T00:56:27.206Z","symbol":"MKRBTC"}}
1625273787.424962: {"jsonrpc":"2.0","method":"updateOrderbook","params":{"ask":[],"bid":[{"price":"33528.13","size":"0.94240"},{"price":"33527.22","size":"1.10595"},{"price":"33526.16","size":"0"},{"price":"33522.60","size":"0"}],"sequence":12626676,"timestamp":"2021-07-03T00:56:27.339Z","symbol":"BTCUSDB"}}
1625273787.42502: {"jsonrpc":"2.0","method":"updateOrderbook","params":{"ask":[{"price":"0.00012211","size":"16338.72"},{"price":"0.00012257","size":"0"}],"bid":[],"sequence":12351698,"timestamp":"2021-07-03T00:56:27.277Z","symbol":"EOSBTC"}}
1625273787.4322932: {"jsonrpc":"2.0","method":"updateOrderbook","params":{"ask":[],"bid":[{"price":"0.07592","size":"3.3887"},{"price":"0.07588","size":"0"}],"sequence":7339942,"timestamp":"2021-07-03T00:56:27.291Z","symbol":"MKRBTC"}}
1625273787.5258508: {"jsonrpc":"2.0","method":"updateOrderbook","params":{"ask":[],"bid":[{"price":"2117.684","size":"20.7428"},{"price":"2114.815","size":"0"},{"price":"2109.824","size":"22.1000"},{"price":"2103.414","size":"0"},{"price":"2092.647","size":"36.1000"},{"price":"2090.213","size":"0"}],"sequence":1513057,"timestamp":"2021-07-03T00:56:27.401Z","symbol":"ETHDAI"}}
1625273787.525874: {"jsonrpc":"2.0","method":"updateOrderbook","params":{"ask":[],"bid":[{"price":"33003.91","size":"1.90000"},{"price":"32929.83","size":"0"}],"sequence":5708308,"timestamp":"2021-07-03T00:56:27.401Z","symbol":"BTCDAI"}}
1625273787.5296152: {"jsonrpc":"2.0","method":"updateOrderbook","params":{"ask":[{"price":"0.00011579","size":"230.00"},{"price":"0.00011580","size":"656.30"},{"price":"0.00011598","size":"0"},{"price":"0.00011608","size":"433.62"},{"price":"0.00012211","size":"0"},{"price":"0.00012254","size":"259811.63"}],"bid":[{"price":"0.00011570","size":"0"},{"price":"0.00011569","size":"492.17"}],"sequence":12351699,"timestamp":"2021-07-03T00:56:27.427Z","symbol":"EOSBTC"}}
1625273787.529666: {"jsonrpc":"2.0","method":"updateOrderbook","params":{"ask":[{"price":"33551.64","size":"0.02460"},{"price":"33551.71","size":"0"}],"bid":[{"price":"33547.69","size":"0"},{"price":"33547.24","size":"0.02940"}],"sequence":12626677,"timestamp":"2021-07-03T00:56:27.452Z","symbol":"BTCUSDB"}}
1625273787.529753: {"jsonrpc":"2.0","method":"updateOrderbook","params":{"ask":[],"bid":[{"price":"0.07463","size":"0.7100"},{"price":"0.07357","size":"0"}],"sequence":7339943,"timestamp":"2021-07-03T00:56:27.355Z","symbol":"MKRBTC"}}
1625273787.626199: {"jsonrpc":"2.0","method":"updateOrderbook","params":{"ask":[{"price":"33551.64","size":"0"},{"price":"33552.28","size":"0.02460"}],"bid":[{"price":"33547.46","size":"0.02940"},{"price":"33547.24","size":"0"},{"price":"33528.13","size":"0"},{"price":"33527.34","size":"0.94240"},{"price":"33527.22","size":"0"},{"price":"33525.50","size":"1.10595"},{"price":"33498.81","size":"1.43690"},{"price":"33494.59","size":"0"}],"sequence":12626678,"timestamp":"2021-07-03T00:56:27.540Z","symbol":"BTCUSDB"}}
1625273787.626336: {"jsonrpc":"2.0","method":"updateOrderbook","params":{"ask":[],"bid":[{"price":"0.00011570","size":"492.17"},{"price":"0.00011569","size":"0"}],"sequence":12351700,"timestamp":"2021-07-03T00:56:27.458Z","symbol":"EOSBTC"}}
1625273787.724718: {"jsonrpc":"2.0","method":"updateOrderbook","params":{"ask":[{"price":"33552.28","size":"0"},{"price":"33554.50","size":"0.02460"},{"price":"33557.18","size":"0"},{"price":"33559.05","size":"0.05940"},{"price":"33612.82","size":"0.09820"},{"price":"33621.43","size":"0"}],"bid":[{"price":"33548.42","size":"0.02940"},{"price":"33547.46","size":"0"},{"price":"33474.58","size":"0"},{"price":"33466.63","size":"0.43060"}],"sequence":12626679,"timestamp":"2021-07-03T00:56:27.647Z","symbol":"BTCUSDB"}}
1625273787.724855: {"jsonrpc":"2.0","method":"updateOrderbook","params":{"ask":[{"price":"0.00011579","size":"354.04"},{"price":"0.00011580","size":"532.26"},{"price":"0.00011917","size":"0"},{"price":"0.00011980","size":"6250.68"},{"price":"0.00012871","size":"22588.08"},{"price":"0.00013194","size":"0"},{"price":"0.00015282","size":"26975.46"},{"price":"0.00015545","size":"0"},{"price":"0.00075990","size":"42091.73"},{"price":"0.00076108","size":"0"}],"bid":[],"sequence":12351701,"timestamp":"2021-07-03T00:56:27.638Z","symbol":"EOSBTC"}}
1625273787.741738: {"jsonrpc":"2.0","method":"updateOrderbook","params":{"ask":[],"bid":[{"price":"0.07463","size":"0"},{"price":"0.07462","size":"0"},{"price":"0.07357","size":"1.3613"}],"sequence":7339944,"timestamp":"2021-07-03T00:56:27.643Z","symbol":"MKRBTC"}}
1625273787.826015: {"jsonrpc":"2.0","method":"updateOrderbook","params":{"ask":[{"price":"33554.04","size":"0.02460"},{"price":"33554.50","size":"0"}],"bid":[{"price":"33505.75","size":"0.96010"},{"price":"33503.35","size":"0"}],"sequence":12626680,"timestamp":"2021-07-03T00:56:27.667Z","symbol":"BTCUSDB"}}
1625273787.8261409: {"jsonrpc":"2.0","method":"updateOrderbook","params":{"ask":[],"bid":[{"price":"31114.50","size":"0"}],"sequence":7211226,"timestamp":"2021-07-03T00:56:27.741Z","symbol":"BTCPAX"}}
1625273787.92435: {"jsonrpc":"2.0","method":"updateOrderbook","params":{"ask":[{"price":"33554.04","size":"0"},{"price":"33555.04","size":"0.02460"}],"bid":[{"price":"33548.42","size":"0"},{"price":"33547.53","size":"0.02940"},{"price":"33541.81","size":"0.38210"},{"price":"33540.74","size":"0.77340"},{"price":"33525.50","size":"0"},{"price":"33523.10","size":"1.10595"},{"price":"33496.96","size":"0.94240"},{"price":"33495.12","size":"1.43580"},{"price":"33493.07","size":"0"},{"price":"33491.55","size":"0"},{"price":"33121.16","size":"2.20309"},{"price":"33105.39","size":"0"}],"sequence":12626681,"timestamp":"2021-07-03T00:56:27.822Z","symbol":"BTCUSDB"}}
1625273787.924427: {"jsonrpc":"2.0","method":"updateOrderbook","params":{"ask":[{"price":"0.00023610","size":"39545.26"},{"price":"0.00024068","size":"0"},{"price":"0.00033161","size":"56176.40"},{"price":"0.00034084","size":"0"}],"bid":[],"sequence":12351702,"timestamp":"2021-07-03T00:56:27.839Z","symbol":"EOSBTC"}}
1625273787.926663: {"jsonrpc":"2.0","method":"updateOrderbook","params":{"ask":[{"price":"33654.89","size":"0.00533"},{"price":"33655.44","size":"0"},{"price":"33699.21","size":"0.00533"},{"price":"33699.63","size":"0"}],"bid":[{"price":"31195.62","size":"0.00260"}],"sequence":7211227,"timestamp":"2021-07-03T00:56:27.830Z","symbol":"BTCPAX"}}
1625273787.926683: {"jsonrpc":"2.0","method":"updateOrderbook","params":{"ask":[],"bid":[{"price":"0.07552","size":"0.6900"},{"price":"0.07548","size":"0"}],"sequence":7339945,"timestamp":"2021-07-03T00:56:27.811Z","symbol":"MKRBTC"}}
1625273788.030591: {"jsonrpc":"2.0","method":"updateOrderbook","params":{"ask":[{"price":"0.00026766","size":"0"},{"price":"0.00026901","size":"21530.31"}],"bid":[],"sequence":12351703,"timestamp":"2021-07-03T00:56:27.877Z","symbol":"EOSBTC"}}
1625273788.030648: {"jsonrpc":"2.0","method":"updateOrderbook","params":{"ask":[{"price":"0.09664","size":"3.7522"},{"price":"0.10441","size":"0"}],"bid":[],"sequence":7339946,"timestamp":"2021-07-03T00:56:27.915Z","symbol":"MKRBTC"}}
1625273788.130045: {"jsonrpc":"2.0","method":"updateOrderbook","params":{"ask":[],"bid":[{"price":"33503.53","size":"1.81560"},{"price":"33499.56","size":"0"},{"price":"33242.83","size":"1.54706"},{"price":"33222.28","size":"0"},{"price":"10060.92","size":"0.00013"},{"price":"10060.70","size":"0"}],"sequence":12626682,"timestamp":"2021-07-03T00:56:27.973Z","symbol":"BTCUSDB"}}
1625273788.130074: {"jsonrpc":"2.0","method":"updateOrderbook","params":{"ask":[],"bid":[{"price":"0.00010393","size":"0"},{"price":"0.00010369","size":"23147.93"},{"price":"0.00008979","size":"0"},{"price":"0.00008935","size":"12370.85"}],"sequence":12351704,"timestamp":"2021-07-03T00:56:28.020Z","symbol":"EOSBTC"}}
1625273788.135011: {"jsonrpc":"2.0","method":"updateOrderbook","params":{"ask":[],"bid":[{"price":"0.07605","size":"1.4327"},{"price":"0.07601","size":"0"},{"price":"0.07542","size":"0.7100"},{"price":"0.07541","size":"0.0629"},{"price":"0.07357","size":"0"}],"sequence":7339947,"timestamp":"2021-07-03T00:56:28.041Z","symbol":"MKRBTC"}}
1625273788.1350322: {"jsonrpc":"2.0","method":"updateOrderbook","params":{"ask":[{"price":"33520.76","size":"0"},{"price":"33521.34","size":"0.01232"},{"price":"35713.68","size":"0"},{"price":"35832.02","size":"1.29584"}],"bid":[],"sequence":7476908,"timestamp":"2021-07-03T00:56:28.020Z","symbol":"BTCTUSD"}}
1625273788.2310982: {"jsonrpc":"2.0","method":"updateOrderbook","params":{"ask":[{"price":"0.00087068","size":"86093.30"},{"price":"0.00090778","size":"0"}],"bid":[{"price":"0.00011475","size":"15420.57"},{"price":"0.00011456","size":"0"}],"sequence":12351705,"timestamp":"2021-07-03T00:56:28.129Z","symbol":"EOSBTC"}}
1625273788.231118: {"jsonrpc":"2.0","method":"updateOrderbook","params":{"ask":[],"bid":[{"price":"0.07462","size":"0.6421"}],"sequence":7339948,"timestamp":"2021-07-03T00:56:28.073Z","symbol":"MKRBTC"}}
1625273788.2311249: {"jsonrpc":"2.0","method":"updateOrderbook","params":{"ask":[{"price":"33521.26","size":"0.01232"},{"price":"33521.34","size":"0"},{"price":"35832.02","size":"0"},{"price":"35888.15","size":"1.29584"}],"bid":[],"sequence":7476909,"timestamp":"2021-07-03T00:56:28.142Z","symbol":"BTCTUSD"}}
1625273788.3291378: {"jsonrpc":"2.0","method":"updateOrderbook","params":{"ask":[{"price":"33555.04","size":"0"},{"price":"33555.54","size":"0.02460"},{"price":"33559.05","size":"0"},{"price":"33560.88","size":"0.05940"}],"bid":[{"price":"33548.11","size":"0.02940"},{"price":"33547.53","size":"0"},{"price":"33507.52","size":"0.38210"},{"price":"33504.17","size":"0"}],"sequence":12626683,"timestamp":"2021-07-03T00:56:28.235Z","symbol":"BTCUSDB"}}
1625273788.329153: {"jsonrpc":"2.0","method":"updateOrderbook","params":{"ask":[{"price":"33654.89","size":"0"},{"price":"33660.66","size":"0.00533"},{"price":"33663.90","size":"0"},{"price":"33669.09","size":"0.00533"}],"bid":[],"sequence":7211228,"timestamp":"2021-07-03T00:56:28.226Z","symbol":"BTCPAX"}}
1625273788.32916: {"jsonrpc":"2.0","method":"updateOrderbook","params":{"ask":[{"price":"0.00011579","size":"230.00"},{"price":"0.00011580","size":"656.30"},{"price":"0.00011640","size":"0"},{"price":"0.00011657","size":"1836.00"},{"price":"0.00012050","size":"27582.23"},{"price":"0.00012077","size":"0"},{"price":"0.00013913","size":"53526.30"},{"price":"0.00013954","size":"0"}],"bid":[{"price":"0.00011571","size":"230.00"},{"price":"0.00011567","size":"198.80"}],"sequence":12351706,"timestamp":"2021-07-03T00:56:28.246Z","symbol":"EOSBTC"}}
1625273788.331111: {"jsonrpc":"2.0","method":"updateOrderbook","params":{"ask":[{"price":"33521.01","size":"0.01232"},{"price":"33521.26","size":"0"}],"bid":[],"sequence":7476910,"timestamp":"2021-07-03T00:56:28.214Z","symbol":"BTCTUSD"}}
1625273788.4274611: {"jsonrpc":"2.0","method":"updateOrderbook","params":{"ask":[{"price":"33736.73","size":"0"},{"price":"33759.13","size":"0.12750"}],"bid":[{"price":"33548.11","size":"0"},{"price":"33546.96","size":"0.02940"},{"price":"33541.81","size":"1.15550"},{"price":"33540.74","size":"0"},{"price":"33537.64","size":"1.43690"},{"price":"33535.21","size":"0"},{"price":"33527.90","size":"1.10595"},{"price":"33523.10","size":"0"}],"sequence":12626684,"timestamp":"2021-07-03T00:56:28.328Z","symbol":"BTCUSDB"}}
1625273788.431644: {"jsonrpc":"2.0","method":"updateOrderbook","params":{"ask":[{"price":"33520.47","size":"0.01232"},{"price":"33521.01","size":"0"}],"bid":[{"price":"33495.12","size":"0"},{"price":"33491.84","size":"0.01473"}],"sequence":7476911,"timestamp":"2021-07-03T00:56:28.328Z","symbol":"BTCTUSD"}}
1625273788.6776478: {"jsonrpc":"2.0","method":"updateOrderbook","params":{"ask":[],"bid":[{"price":"2109.824","size":"0"},{"price":"2103.474","size":"22.1000"},{"price":"2092.647","size":"0"},{"price":"2090.248","size":"36.1000"}],"sequence":1513058,"timestamp":"2021-07-03T00:56:28.393Z","symbol":"ETHDAI"}}
1625273788.677713: {"jsonrpc":"2.0","method":"updateOrderbook","params":{"ask":[],"bid":[{"price":"33003.91","size":"0"},{"price":"32930.19","size":"1.90000"}],"sequence":5708309,"timestamp":"2021-07-03T00:56:28.393Z","symbol":"BTCDAI"}}
1625273788.677736: {"jsonrpc":"2.0","method":"updateOrderbook","params":{"ask":[],"bid":[{"price":"33242.83","size":"0"},{"price":"33229.15","size":"1.54704"},{"price":"33121.16","size":"0"},{"price":"33110.72","size":"2.20306"}],"sequence":12626685,"timestamp":"2021-07-03T00:56:28.398Z","symbol":"BTCUSDB"}}
1625273788.6777558: {"jsonrpc":"2.0","method":"updateOrderbook","params":{"ask":[{"price":"0.00011579","size":"350.44"},{"price":"0.00011580","size":"535.86"}],"bid":[{"price":"0.00011356","size":"0"}],"sequence":12351707,"timestamp":"2021-07-03T00:56:28.446Z","symbol":"EOSBTC"}}
1625273788.6777742: {"jsonrpc":"2.0","method":"updateOrderbook","params":{"ask":[{"price":"0.07628","size":"0.1227"},{"price":"0.07630","size":"0"},{"price":"0.23657","size":"4.2976"},{"price":"0.35535","size":"0"}],"bid":[],"sequence":7339949,"timestamp":"2021-07-03T00:56:28.381Z","symbol":"MKRBTC"}}
1625273788.677792: {"jsonrpc":"2.0","method":"updateOrderbook","params":{"ask":[{"price":"33519.71","size":"0.01232"},{"price":"33520.47","size":"0"}],"bid":[],"sequence":7476912,"timestamp":"2021-07-03T00:56:28.356Z","symbol":"BTCTUSD"}}
1625273788.677871: {"jsonrpc":"2.0","method":"updateOrderbook","params":{"ask":[{"price":"0.00011579","size":"230.00"},{"price":"0.00011582","size":"120.44"},{"price":"0.00012228","size":"16338.72"},{"price":"0.00012254","size":"243472.91"}],"bid":[{"price":"0.00011571","size":"722.17"},{"price":"0.00011570","size":"914.04"},{"price":"0.00011568","size":"796.96"},{"price":"0.00011536","size":"4032.48"},{"price":"0.00011526","size":"6999.63"},{"price":"0.00011491","size":"0"},{"price":"0.00011473","size":"8378.72"},{"price":"0.00011444","size":"0"},{"price":"0.00011402","size":"16444.03"},{"price":"0.00011375","size":"14.29"},{"price":"0.00010369","size":"0"},{"price":"0.00010236","size":"23147.93"},{"price":"0.00008935","size":"0"},{"price":"0.00008664","size":"12370.85"}],"sequence":12351708,"timestamp":"2021-07-03T00:56:28.525Z","symbol":"EOSBTC"}}
1625273788.731092: {"jsonrpc":"2.0","method":"updateOrderbook","params":{"ask":[{"price":"33609.22","size":"0.51010"},{"price":"33618.94","size":"0"},{"price":"33621.30","size":"1.15780"},{"price":"33632.28","size":"0"}],"bid":[{"price":"33528.25","size":"0.94240"},{"price":"33527.34","size":"0"}],"sequence":12626686,"timestamp":"2021-07-03T00:56:28.568Z","symbol":"BTCUSDB"}}
1625273788.731116: {"jsonrpc":"2.0","method":"updateOrderbook","params":{"ask":[{"price":"0.00011579","size":"641.82"},{"price":"0.00011580","size":"124.04"}],"bid":[],"sequence":12351709,"timestamp":"2021-07-03T00:56:28.648Z","symbol":"EOSBTC"}}
1625273788.7311292: {"jsonrpc":"2.0","method":"updateOrderbook","params":{"ask":[{"price":"33518.94","size":"0.01232"},{"price":"33519.71","size":"0"},{"price":"33530.93","size":"0.05140"},{"price":"33535.60","size":"0"}],"bid":[],"sequence":7476913,"timestamp":"2021-07-03T00:56:28.607Z","symbol":"BTCTUSD"}}
1625273788.83005: {"jsonrpc":"2.0","method":"updateOrderbook","params":{"ask":[],"bid":[{"price":"33537.64","size":"0"},{"price":"33535.57","size":"1.43690"},{"price":"33527.90","size":"0"},{"price":"33526.65","size":"1.10595"}],"sequence":12626687,"timestamp":"2021-07-03T00:56:28.745Z","symbol":"BTCUSDB"}}
1625273788.8300989: {"jsonrpc":"2.0","method":"updateOrderbook","params":{"ask":[{"price":"0.00015282","size":"0"},{"price":"0.00015304","size":"26975.46"},{"price":"0.00087068","size":"0"},{"price":"0.00087142","size":"86093.30"}],"bid":[{"price":"0.00011570","size":"0"},{"price":"0.00011569","size":"914.04"},{"price":"0.00011547","size":"1435.91"},{"price":"0.00011537","size":"866.81"}],"sequence":12351710,"timestamp":"2021-07-03T00:56:28.711Z","symbol":"EOSBTC"}}
1625273788.8301408: {"jsonrpc":"2.0","method":"updateOrderbook","params":{"ask":[{"price":"33518.94","size":"0"},{"price":"33519.26","size":"0.01232"}],"bid":[],"sequence":7476914,"timestamp":"2021-07-03T00:56:28.736Z","symbol":"BTCTUSD"}}
1625273788.928351: {"jsonrpc":"2.0","method":"updateOrderbook","params":{"ask":[{"price":"33555.54","size":"0"},{"price":"33555.63","size":"0.02460"},{"price":"33565.37","size":"0.91740"},{"price":"33566.97","size":"0"}],"bid":[{"price":"33546.96","size":"0"},{"price":"33546.34","size":"0.02940"},{"price":"33528.25","size":"0"},{"price":"33527.38","size":"0.94240"},{"price":"33526.65","size":"0"},{"price":"33525.58","size":"1.10595"}],"sequence":12626688,"timestamp":"2021-07-03T00:56:28.798Z","symbol":"BTCUSDB"}}
1625273788.928375: {"jsonrpc":"2.0","method":"updateOrderbook","params":{"ask":[{"price":"0.00011578","size":"0"},{"price":"0.00011579","size":"230.00"},{"price":"0.00011580","size":"411.82"},{"price":"0.00011582","size":"223.04"},{"price":"0.00011583","size":"0"},{"price":"0.00011584","size":"131.95"}],"bid":[{"price":"0.00011571","size":"230.00"},{"price":"0.00011569","size":"492.17"},{"price":"0.00011567","size":"1112.84"}],"sequence":12351711,"timestamp":"2021-07-03T00:56:28.849Z","symbol":"EOSBTC"}}
1625273788.935442: {"jsonrpc":"2.0","method":"updateOrderbook","params":{"ask":[{"price":"0.07759","size":"11.9903"},{"price":"0.07768","size":"0"}],"bid":[],"sequence":7339950,"timestamp":"2021-07-03T00:56:28.803Z","symbol":"MKRBTC"}}
1625273788.935468: {"jsonrpc":"2.0","method":"updateOrderbook","params":{"ask":[{"price":"33518.94","size":"0.01232"},{"price":"33519.26","size":"0"},{"price":"33522.27","size":"0.02976"},{"price":"33523.73","size":"0"}],"bid":[],"sequence":7476915,"timestamp":"2021-07-03T00:56:28.768Z","symbol":"BTCTUSD"}}
1625273789.0273302: {"jsonrpc":"2.0","method":"updateOrderbook","params":{"ask":[{"price":"33659.07","size":"1.37330"},{"price":"33678.30","size":"0"}],"bid":[{"price":"33541.81","size":"0.38210"},{"price":"33541.22","size":"0.77340"},{"price":"33525.58","size":"0"},{"price":"33524.95","size":"1.10595"},{"price":"33474.49","size":"0.43060"},{"price":"33466.63","size":"0"}],"sequence":12626689,"timestamp":"2021-07-03T00:56:28.916Z","symbol":"BTCUSDB"}}
1625273789.027374: {"jsonrpc":"2.0","method":"updateOrderbook","params":{"ask":[{"price":"0.00011579","size":"1727.60"},{"price":"0.00012871","size":"0"},{"price":"0.00012934","size":"22588.08"},{"price":"0.00015304","size":"0"},{"price":"0.00015346","size":"26975.46"},{"price":"0.00023610","size":"0"},{"price":"0.00023696","size":"39545.26"},{"price":"0.00033161","size":"0"},{"price":"0.00033343","size":"56176.40"},{"price":"0.00087142","size":"0"},{"price":"0.00087761","size":"86093.30"}],"bid":[{"price":"0.00011475","size":"10860.97"},{"price":"0.00011460","size":"4559.60"}],"sequence":12351712,"timestamp":"2021-07-03T00:56:28.925Z","symbol":"EOSBTC"}}
1625273789.128402: {"jsonrpc":"2.0","method":"updateOrderbook","params":{"ask":[{"price":"33555.30","size":"0.02460"},{"price":"33555.63","size":"0"},{"price":"167677.50","size":"0.00019"},{"price":"167678.48","size":"0"}],"bid":[{"price":"33541.22","size":"0"},{"price":"33540.62","size":"0.77340"},{"price":"33535.57","size":"0"},{"price":"33534.96","size":"1.43690"},{"price":"33527.38","size":"0"},{"price":"33526.74","size":"0.94240"},{"price":"33524.95","size":"0"},{"price":"33524.10","size":"1.10595"},{"price":"10060.92","size":"0"},{"price":"10060.65","size":"0.00014"}],"sequence":12626690,"timestamp":"2021-07-03T00:56:28.989Z","symbol":"BTCUSDB"}}
1625273789.128463: {"jsonrpc":"2.0","method":"updateOrderbook","params":{"ask":[{"price":"0.00011579","size":"2139.42"},{"price":"0.00011580","size":"0"}],"bid":[{"price":"0.00011571","size":"722.17"},{"price":"0.00011570","size":"914.04"},{"price":"0.00011569","size":"0"},{"price":"0.00011567","size":"198.80"},{"price":"0.00011375","size":"0"},{"price":"0.00010266","size":"23147.93"},{"price":"0.00010236","size":"0"}],"sequence":12351713,"timestamp":"2021-07-03T00:56:29.014Z","symbol":"EOSBTC"}}
1625273789.243267: {"jsonrpc":"2.0","method":"updateOrderbook","params":{"ask":[{"price":"33576.26","size":"0.27520"},{"price":"33579.18","size":"0"}],"bid":[],"sequence":12626691,"timestamp":"2021-07-03T00:56:29.132Z","symbol":"BTCUSDB"}}
1625273789.2432861: {"jsonrpc":"2.0","method":"updateOrderbook","params":{"ask":[{"price":"0.00011599","size":"1986.07"},{"price":"0.00011602","size":"2106.34"}],"bid":[{"price":"0.00011356","size":"14.32"}],"sequence":12351714,"timestamp":"2021-07-03T00:56:29.086Z","symbol":"EOSBTC"}}
1625273789.243299: {"jsonrpc":"2.0","method":"updateOrderbook","params":{"ask":[{"price":"33640.94","size":"0.25340"},{"price":"33668.66","size":"0"}],"bid":[],"sequence":7211229,"timestamp":"2021-07-03T00:56:29.139Z","symbol":"BTCPAX"}}
1625273789.24331: {"jsonrpc":"2.0","method":"updateOrderbook","params":{"ask":[{"price":"0.07988","size":"17.0727"},{"price":"0.08035","size":"0"}],"bid":[],"sequence":7339951,"timestamp":"2021-07-03T00:56:29.072Z","symbol":"MKRBTC"}}
1625273789.24332: {"jsonrpc":"2.0","method":"updateOrderbook","params":{"ask":[{"price":"33518.94","size":"0"},{"price":"33519.67","size":"0.01232"}],"bid":[],"sequence":7476916,"timestamp":"2021-07-03T00:56:29.052Z","symbol":"BTCTUSD"}}
1625273789.328893: {"jsonrpc":"2.0","method":"updateOrderbook","params":{"ask":[{"price":"33519.26","size":"0.01232"},{"price":"33519.67","size":"0"}],"bid":[{"price":"33495.85","size":"0.01473"},{"price":"33491.84","size":"0"}],"sequence":7476917,"timestamp":"2021-07-03T00:56:29.213Z","symbol":"BTCTUSD"}}
1625273789.428407: {"jsonrpc":"2.0","method":"updateOrderbook","params":{"ask":[{"price":"33554.34","size":"0.02460"},{"price":"33555.30","size":"0"}],"bid":[{"price":"33548.54","size":"0.02940"},{"price":"33546.34","size":"0"}],"sequence":12626692,"timestamp":"2021-07-03T00:56:29.347Z","symbol":"BTCUSDB"}}
1625273789.428534: {"jsonrpc":"2.0","method":"updateOrderbook","params":{"ask":[{"price":"0.00011579","size":"2139.50"},{"price":"0.00011581","size":"994.61"},{"price":"0.00011584","size":"120.44"},{"price":"0.00011586","size":"98.98"},{"price":"0.00011589","size":"1717.96"},{"price":"0.00011590","size":"89.10"},{"price":"0.00011593","size":"2393.05"}],"bid":[{"price":"0.00011571","size":"722.28"},{"price":"0.00011570","size":"914.23"},{"price":"0.00011562","size":"2583.84"},{"price":"0.00011560","size":"363.60"},{"price":"0.00011558","size":"2824.92"},{"price":"0.00011556","size":"0"},{"price":"0.00011552","size":"874.68"},{"price":"0.00011549","size":"921.44"}],"sequence":12351715,"timestamp":"2021-07-03T00:56:29.338Z","symbol":"EOSBTC"}}
1625273789.434112: {"jsonrpc":"2.0","method":"updateOrderbook","params":{"ask":[{"price":"33519.26","size":"0"},{"price":"33519.67","size":"0.01233"},{"price":"33522.27","size":"0"},{"price":"33523.01","size":"0.02977"},{"price":"33530.93","size":"0"},{"price":"33531.64","size":"0.05142"},{"price":"33536.76","size":"0.06045"},{"price":"33540.97","size":"0"}],"bid":[{"price":"33490.45","size":"0.02736"},{"price":"33489.18","size":"0"},{"price":"33480.69","size":"0.19502"},{"price":"33480.43","size":"0"},{"price":"33476.67","size":"0.05985"},{"price":"33475.05","size":"0"}],"sequence":7476918,"timestamp":"2021-07-03T00:56:29.337Z","symbol":"BTCTUSD"}}
1625273789.542115: {"jsonrpc":"2.0","method":"updateOrderbook","params":{"ask":[{"price":"33553.86","size":"0.02460"},{"price":"33554.34","size":"0"},{"price":"33557.41","size":"0.05940"},{"price":"33560.88","size":"0"},{"price":"33561.98","size":"0.41740"},{"price":"33563.60","size":"0"},{"price":"33566.46","size":"0.75200"},{"price":"33567.98","size":"0"},{"price":"33570.13","size":"0.95910"},{"price":"33572.43","size":"0"},{"price":"33573.13","size":"0"},{"price":"33576.26","size":"0.28694"},{"price":"33694.50","size":"1.25250"},{"price":"33720.18","size":"0"}],"bid":[{"price":"33548.54","size":"0"},{"price":"33544.01","size":"0.02940"},{"price":"33542.39","size":"0"},{"price":"33541.81","size":"0"},{"price":"33540.62","size":"0"},{"price":"33539.18","size":"0.05460"},{"price":"33538.09","size":"0"},{"price":"33537.85","size":"0.38210"},{"price":"33535.05","size":"0.77340"},{"price":"33534.96","size":"0"},{"price":"33533.97","size":"1.81560"},{"price":"33528.24","size":"1.43690"},{"price":"33526.74","size":"0"},{"price":"33524.10","size":"0"},{"price":"33519.23","size":"0.07390"},{"price":"33518.32","size":"0"},{"price":"33517.60","size":"0.94240"},{"price":"33516.57","size":"1.10595"},{"price":"33515.72","size":"0.77390"},{"price":"33514.26","size":"1.04220"},{"price":"33514.23","size":"0.32903"},{"price":"33503.53","size":"0"},{"price":"33500.28","size":"1.81560"},{"price":"33496.96","size":"0"},{"price":"33491.30","size":"0.94240"},{"price":"33487.83","size":"0"},{"price":"33483.68","size":"2.64430"},{"price":"33474.49","size":"0"},{"price":"33466.61","size":"0.43060"}],"sequence":12626693,"timestamp":"2021-07-03T00:56:29.450Z","symbol":"BTCUSDB"}}
1625273789.5422049: {"jsonrpc":"2.0","method":"updateOrderbook","params":{"ask":[{"price":"0.00011577","size":"0"},{"price":"0.00011579","size":"0"},{"price":"0.00011580","size":"411.90"},{"price":"0.00011583","size":"1727.47"},{"price":"0.00011584","size":"0"},{"price":"0.00011585","size":"120.44"},{"price":"0.00011588","size":"3454.93"},{"price":"0.00087761","size":"0"},{"price":"0.00087803","size":"86093.30"}],"bid":[{"price":"0.00011566","size":"99.24"},{"price":"0.00011565","size":"87.20"}],"sequence":12351716,"timestamp":"2021-07-03T00:56:29.448Z","symbol":"EOSBTC"}}
1625273789.545402: {"jsonrpc":"2.0","method":"updateOrderbook","params":{"ask":[{"price":"33517.45","size":"0.01233"},{"price":"33519.67","size":"0"}],"bid":[{"price":"33495.85","size":"0"},{"price":"33493.12","size":"0.01473"}],"sequence":7476919,"timestamp":"2021-07-03T00:56:29.451Z","symbol":"BTCTUSD"}}
1625273789.624476: {"jsonrpc":"2.0","method":"updateOrderbook","params":{"ask":[{"price":"35612.03","size":"0.67400"},{"price":"35622.31","size":"0"}],"bid":[],"sequence":1470726,"timestamp":"2021-07-03T00:56:29.453Z","symbol":"BTCGUSD"}}
1625273789.630444: {"jsonrpc":"2.0","method":"updateOrderbook","params":{"ask":[{"price":"33584.67","size":"0.95910"},{"price":"33588.64","size":"0"}],"bid":[{"price":"33544.01","size":"0"},{"price":"33542.76","size":"0.02940"},{"price":"33539.18","size":"0"},{"price":"33538.56","size":"0.38210"},{"price":"33537.85","size":"0"},{"price":"33537.59","size":"0.05460"},{"price":"33532.34","size":"0"},{"price":"33529.00","size":"1.43690"},{"price":"33528.24","size":"0"},{"price":"33526.78","size":"0.10140"},{"price":"33517.35","size":"1.10595"},{"price":"33516.57","size":"0"},{"price":"33513.73","size":"0"},{"price":"33510.36","size":"0.64790"},{"price":"33507.52","size":"0"},{"price":"33505.75","size":"0"},{"price":"33504.42","size":"0.96010"},{"price":"33501.75","size":"0.38210"},{"price":"33500.28","size":"0"},{"price":"33498.81","size":"0"},{"price":"33498.38","size":"0"},{"price":"33496.65","size":"0.94140"},{"price":"33496.11","size":"1.81560"},{"price":"33495.12","size":"0"},{"price":"33492.15","size":"1.43580"},{"price":"33491.30","size":"0"},{"price":"33488.73","size":"1.43690"},{"price":"33486.59","size":"0.94240"}],"sequence":12626694,"timestamp":"2021-07-03T00:56:29.539Z","symbol":"BTCUSDB"}}
1625273789.630474: {"jsonrpc":"2.0","method":"updateOrderbook","params":{"ask":[{"price":"0.00011579","size":"99.00"},{"price":"0.00011582","size":"124.04"},{"price":"0.00011585","size":"131.95"},{"price":"0.00011586","size":"87.47"}],"bid":[{"price":"0.00011571","size":"1636.51"},{"price":"0.00011570","size":"0"},{"price":"0.00011554","size":"866.81"},{"price":"0.00011537","size":"0"}],"sequence":12351717,"timestamp":"2021-07-03T00:56:29.548Z","symbol":"EOSBTC"}}
1625273789.630516: {"jsonrpc":"2.0","method":"updateOrderbook","params":{"ask":[],"bid":[{"price":"31195.61","size":"0"},{"price":"31079.68","size":"1.68120"}],"sequence":7211230,"timestamp":"2021-07-03T00:56:29.489Z","symbol":"BTCPAX"}}
1625273789.6462588: {"jsonrpc":"2.0","method":"updateOrderbook","params":{"ask":[{"price":"0.07651","size":"1.4413"},{"price":"0.07655","size":"1.9169"},{"price":"0.07666","size":"0"},{"price":"0.07675","size":"3.0785"},{"price":"0.07712","size":"0"},{"price":"0.07723","size":"6.2765"},{"price":"0.07792","size":"0"},{"price":"0.07809","size":"9.6365"}],"bid":[],"sequence":7339952,"timestamp":"2021-07-03T00:56:29.501Z","symbol":"MKRBTC"}}
1625273789.64628: {"jsonrpc":"2.0","method":"updateOrderbook","params":{"ask":[{"price":"33516.31","size":"0.01233"},{"price":"33517.45","size":"0"},{"price":"33518.94","size":"0.02977"},{"price":"33523.01","size":"0"}],"bid":[{"price":"33493.12","size":"0"},{"price":"33488.99","size":"0.01473"},{"price":"32108.15","size":"0"},{"price":"32031.25","size":"1.67560"}],"sequence":7476920,"timestamp":"2021-07-03T00:56:29.537Z","symbol":"BTCTUSD"}}
1625273789.729408: {"jsonrpc":"2.0","method":"updateOrderbook","params":{"ask":[{"price":"33553.43","size":"0.05940"},{"price":"33557.41","size":"0"},{"price":"33560.44","size":"0.10260"},{"price":"33567.82","size":"0"},{"price":"33582.55","size":"0.79591"},{"price":"33585.96","size":"0"},{"price":"33608.33","size":"1.06050"},{"price":"33609.22","size":"0"},{"price":"33616.27","size":"0"},{"price":"33617.51","size":"0.51010"},{"price":"33694.50","size":"0"},{"price":"33719.09","size":"1.25250"}],"bid":[{"price":"33542.76","size":"0"},{"price":"33542.28","size":"0.02940"},{"price":"33476.43","size":"0"},{"price":"33470.48","size":"0.49410"}],"sequence":12626695,"timestamp":"2021-07-03T00:56:29.640Z","symbol":"BTCUSDB"}}
1625273789.7294898: {"jsonrpc":"2.0","method":"updateOrderbook","params":{"ask":[{"price":"33659.64","size":"0.00533"},{"price":"33660.66","size":"0"}],"bid":[],"sequence":7211231,"timestamp":"2021-07-03T00:56:29.561Z","symbol":"BTCPAX"}}
1625273789.736491: {"jsonrpc":"2.0","method":"updateOrderbook","params":{"ask":[{"price":"33515.64","size":"0.01233"},{"price":"33516.31","size":"0"}],"bid":[{"price":"33490.45","size":"0"},{"price":"33488.99","size":"0"},{"price":"33484.78","size":"0.01473"},{"price":"33481.48","size":"0.02736"},{"price":"33467.38","size":"0"},{"price":"33444.99","size":"0.20870"},{"price":"33428.59","size":"0"},{"price":"33404.24","size":"0.26550"},{"price":"32031.25","size":"0"},{"price":"31948.83","size":"1.67560"},{"price":"30546.24","size":"0"},{"price":"30460.12","size":"1.39725"}],"sequence":7476921,"timestamp":"2021-07-03T00:56:29.625Z","symbol":"BTCTUSD"}}
1625273789.834125: {"jsonrpc":"2.0","method":"updateOrderbook","params":{"ask":[{"price":"33574.27","size":"0.39780"},{"price":"33577.71","size":"0"},{"price":"33586.88","size":"1.06050"},{"price":"33595.92","size":"0"},{"price":"33682.45","size":"0"},{"price":"33703.31","size":"1.07700"}],"bid":[{"price":"33519.23","size":"0"},{"price":"33515.96","size":"0.07390"},{"price":"33513.82","size":"0.01821"},{"price":"33510.83","size":"0"}],"sequence":12626696,"timestamp":"2021-07-03T00:56:29.739Z","symbol":"BTCUSDB"}}
1625273789.834167: {"jsonrpc":"2.0","method":"updateOrderbook","params":{"ask":[{"price":"0.00011582","size":"244.48"},{"price":"0.00011585","size":"11.51"}],"bid":[{"price":"0.00011569","size":"87.20"},{"price":"0.00011565","size":"0"}],"sequence":12351718,"timestamp":"2021-07-03T00:56:29.709Z","symbol":"EOSBTC"}}
1625273789.834188: {"jsonrpc":"2.0","method":"updateOrderbook","params":{"ask":[{"price":"33515.29","size":"0.01233"},{"price":"33515.64","size":"0"}],"bid":[],"sequence":7476922,"timestamp":"2021-07-03T00:56:29.659Z","symbol":"BTCTUSD"}}
1625273789.933332: {"jsonrpc":"2.0","method":"updateOrderbook","params":{"ask":[{"price":"33584.67","size":"0"},{"price":"33587.81","size":"0.95910"},{"price":"33608.33","size":"0"},{"price":"33617.10","size":"1.06050"}],"bid":[],"sequence":12626697,"timestamp":"2021-07-03T00:56:29.765Z","symbol":"BTCUSDB"}}
1625273789.933352: {"jsonrpc":"2.0","method":"updateOrderbook","params":{"ask":[{"price":"0.00011580","size":"535.94"},{"price":"0.00011582","size":"120.44"}],"bid":[],"sequence":12351719,"timestamp":"2021-07-03T00:56:29.764Z","symbol":"EOSBTC"}}
1625273789.933362: {"jsonrpc":"2.0","method":"updateOrderbook","params":{"ask":[{"price":"33514.91","size":"0.01233"},{"price":"33515.29","size":"0"},{"price":"33565.16","size":"0.00910"},{"price":"33570.90","size":"0"}],"bid":[],"sequence":7476923,"timestamp":"2021-07-03T00:56:29.811Z","symbol":"BTCTUSD"}}
1625273790.030842: {"jsonrpc":"2.0","method":"updateOrderbook","params":{"ask":[{"price":"33561.98","size":"2.26720"},{"price":"33566.46","size":"0"},{"price":"33569.41","size":"0"}],"bid":[{"price":"33542.28","size":"0"},{"price":"33541.81","size":"0.02940"},{"price":"33538.56","size":"0"},{"price":"33537.82","size":"0.38210"},{"price":"33521.59","size":"0.94240"},{"price":"33517.60","size":"0"}],"sequence":12626698,"timestamp":"2021-07-03T00:56:29.949Z","symbol":"BTCUSDB"}}
1625273790.030905: {"jsonrpc":"2.0","method":"updateOrderbook","params":{"ask":[],"bid":[{"price":"0.00011027","size":"7497.84"},{"price":"0.00011007","size":"0"},{"price":"0.00010616","size":"95671.85"},{"price":"0.00010609","size":"0"}],"sequence":12351720,"timestamp":"2021-07-03T00:56:29.864Z","symbol":"EOSBTC"}}
1625273790.133437: {"jsonrpc":"2.0","method":"updateOrderbook","params":{"ask":[{"price":"33565.52","size":"0.95910"},{"price":"33570.13","size":"0"},{"price":"33573.27","size":"0.28694"},{"price":"33576.26","size":"0"},{"price":"33577.17","size":"1.43490"},{"price":"33581.47","size":"0"},{"price":"167648.30","size":"0.00017"},{"price":"167677.50","size":"0"}],"bid":[{"price":"33541.81","size":"0"},{"price":"33537.93","size":"0.02940"},{"price":"33537.59","size":"0"},{"price":"33535.05","size":"0"},{"price":"33533.97","size":"0"},{"price":"33533.13","size":"0.77340"},{"price":"33532.91","size":"0.05460"},{"price":"33530.50","size":"1.81560"},{"price":"33529.00","size":"0"},{"price":"33528.21","size":"0"},{"price":"33526.05","size":"1.43690"},{"price":"33521.59","size":"0"},{"price":"33517.35","size":"0"},{"price":"33516.82","size":"0.11940"},{"price":"33514.87","size":"0.94240"},{"price":"33510.96","size":"1.10595"},{"price":"33504.42","size":"0"},{"price":"33503.24","size":"0.96010"},{"price":"10060.65","size":"0"},{"price":"10058.89","size":"0.00017"}],"sequence":12626699,"timestamp":"2021-07-03T00:56:30.051Z","symbol":"BTCUSDB"}}
1625273790.133525: {"jsonrpc":"2.0","method":"updateOrderbook","params":{"ask":[{"price":"33659.57","size":"0.00533"},{"price":"33659.64","size":"0"},{"price":"33667.83","size":"0.00533"},{"price":"33669.09","size":"0"},{"price":"35023.24","size":"1.84720"},{"price":"35115.26","size":"0"}],"bid":[{"price":"31195.62","size":"0"},{"price":"31114.50","size":"0.00261"}],"sequence":7211232,"timestamp":"2021-07-03T00:56:30.021Z","symbol":"BTCPAX"}}
1625273790.135967: {"jsonrpc":"2.0","method":"updateOrderbook","params":{"ask":[{"price":"33514.91","size":"0"},{"price":"33515.95","size":"0.01233"}],"bid":[],"sequence":7476924,"timestamp":"2021-07-03T00:56:30.030Z","symbol":"BTCTUSD"}}
1625273790.239528: {"jsonrpc":"2.0","method":"updateOrderbook","params":{"ask":[{"price":"39894.14","size":"4.51490"},{"price":"39982.22","size":"0"}],"bid":[],"sequence":5708310,"timestamp":"2021-07-03T00:56:30.052Z","symbol":"BTCDAI"}}
1625273790.239593: {"jsonrpc":"2.0","method":"updateOrderbook","params":{"ask":[{"price":"33553.90","size":"1.03952"},{"price":"33561.95","size":"0"}],"bid":[{"price":"33526.05","size":"0"},{"price":"33523.66","size":"1.43690"},{"price":"33515.72","size":"0"},{"price":"33514.87","size":"0"},{"price":"33514.26","size":"0"},{"price":"33514.23","size":"0"},{"price":"33512.48","size":"0.94240"},{"price":"33511.29","size":"0.77390"},{"price":"33510.96","size":"0"},{"price":"33510.23","size":"1.37123"},{"price":"33510.15","size":"1.10595"}],"sequence":12626700,"timestamp":"2021-07-03T00:56:30.146Z","symbol":"BTCUSDB"}}
1625273790.239629: {"jsonrpc":"2.0","method":"updateOrderbook","params":{"ask":[],"bid":[{"price":"0.00011514","size":"3484.91"},{"price":"0.00011498","size":"12144.04"},{"price":"0.00011402","size":"0"},{"price":"0.00011373","size":"16444.03"},{"price":"0.00010266","size":"0"},{"price":"0.00010138","size":"23148.30"},{"price":"0.00008664","size":"0"},{"price":"0.00008451","size":"12370.85"}],"sequence":12351721,"timestamp":"2021-07-03T00:56:30.130Z","symbol":"EOSBTC"}}
1625273790.239656: {"jsonrpc":"2.0","method":"updateOrderbook","params":{"ask":[{"price":"33515.95","size":"0"},{"price":"33516.29","size":"0.01233"}],"bid":[],"sequence":7476925,"timestamp":"2021-07-03T00:56:30.145Z","symbol":"BTCTUSD"}}
1625273790.383511: {"jsonrpc":"2.0","method":"updateOrderbook","params":{"ask":[{"price":"33553.90","size":"1.71022"},{"price":"33557.13","size":"0"}],"bid":[{"price":"33539.17","size":"0.02940"},{"price":"33537.93","size":"0"},{"price":"33523.66","size":"0"},{"price":"33523.01","size":"1.43690"},{"price":"33503.24","size":"0"},{"price":"33501.99","size":"0.96010"},{"price":"33501.76","size":"0"},{"price":"33498.84","size":"0.77340"},{"price":"33496.65","size":"0"},{"price":"33496.11","size":"0"},{"price":"33494.24","size":"0.94140"},{"price":"33492.85","size":"1.81560"},{"price":"33492.15","size":"0"},{"price":"33489.25","size":"1.43580"},{"price":"33449.99","size":"0"},{"price":"33440.05","size":"1.13040"}],"sequence":12626701,"timestamp":"2021-07-03T00:56:30.234Z","symbol":"BTCUSDB"}}
1625273790.383542: {"jsonrpc":"2.0","method":"updateOrderbook","params":{"ask":[{"price":"0.00011619","size":"4260.12"},{"price":"0.00011621","size":"290.00"},{"price":"0.00012934","size":"0"},{"price":"0.00012966","size":"22588.08"},{"price":"0.00015346","size":"0"},{"price":"0.00015370","size":"26975.46"},{"price":"0.00023696","size":"0"},{"price":"0.00023740","size":"39545.26"},{"price":"0.00033343","size":"0"},{"price":"0.00033435","size":"56176.40"},{"price":"0.00087803","size":"0"},{"price":"0.00088111","size":"86093.30"}],"bid":[],"sequence":12351722,"timestamp":"2021-07-03T00:56:30.185Z","symbol":"EOSBTC"}}
1625273790.383561: {"jsonrpc":"2.0","method":"updateOrderbook","params":{"ask":[],"bid":[{"price":"33484.78","size":"0"},{"price":"33481.61","size":"0.01473"},{"price":"33379.80","size":"0"},{"price":"33347.96","size":"0.34070"},{"price":"32861.21","size":"0"},{"price":"32806.42","size":"1.37100"},{"price":"31948.83","size":"0"},{"price":"31866.40","size":"1.67560"}],"sequence":7476926,"timestamp":"2021-07-03T00:56:30.250Z","symbol":"BTCTUSD"}}
1625273790.426178: {"jsonrpc":"2.0","method":"updateOrderbook","params":{"ask":[],"bid":[{"price":"2109.737","size":"22.1000"},{"price":"2103.474","size":"0"},{"price":"2092.633","size":"36.1000"},{"price":"2090.248","size":"0"}],"sequence":1513059,"timestamp":"2021-07-03T00:56:30.301Z","symbol":"ETHDAI"}}
1625273790.4262059: {"jsonrpc":"2.0","method":"updateOrderbook","params":{"ask":[],"bid":[{"price":"32997.95","size":"1.90000"},{"price":"32930.19","size":"0"}],"sequence":5708311,"timestamp":"2021-07-03T00:56:30.301Z","symbol":"BTCDAI"}}
1625273790.42968: {"jsonrpc":"2.0","method":"updateOrderbook","params":{"ask":[],"bid":[{"price":"33523.62","size":"1.43690"},{"price":"33523.01","size":"0"}],"sequence":12626702,"timestamp":"2021-07-03T00:56:30.273Z","symbol":"BTCUSDB"}}
1625273790.432362: {"jsonrpc":"2.0","method":"updateOrderbook","params":{"ask":[{"price":"33516.29","size":"0"},{"price":"33517.39","size":"0.01233"},{"price":"33518.94","size":"0"},{"price":"33520.38","size":"0.02977"}],"bid":[{"price":"33489.14","size":"0.01473"},{"price":"33481.61","size":"0"},{"price":"33480.69","size":"0.14420"},{"price":"33468.26","size":"0.05082"}],"sequence":7476927,"timestamp":"2021-07-03T00:56:30.305Z","symbol":"BTCTUSD"}}
1625273790.530346: {"jsonrpc":"2.0","method":"updateOrderbook","params":{"ask":[{"price":"33604.76","size":"0"},{"price":"33613.65","size":"1.06920"}],"bid":[{"price":"33530.63","size":"1.81560"},{"price":"33530.50","size":"0"},{"price":"33467.95","size":"0"},{"price":"33457.98","size":"1.04000"}],"sequence":12626703,"timestamp":"2021-07-03T00:56:30.422Z","symbol":"BTCUSDB"}}
1625273790.5303822: {"jsonrpc":"2.0","method":"updateOrderbook","params":{"ask":[],"bid":[{"price":"33444.99","size":"0"},{"price":"33423.06","size":"0.20870"}],"sequence":7476928,"timestamp":"2021-07-03T00:56:30.397Z","symbol":"BTCTUSD"}}
1625273790.631839: {"jsonrpc":"2.0","method":"updateOrderbook","params":{"ask":[{"price":"33582.55","size":"0"},{"price":"33585.73","size":"0.79591"}],"bid":[],"sequence":12626704,"timestamp":"2021-07-03T00:56:30.486Z","symbol":"BTCUSDB"}}
1625273790.631897: {"jsonrpc":"2.0","method":"updateOrderbook","params":{"ask":[{"price":"33659.57","size":"0"},{"price":"33660.70","size":"0.00533"}],"bid":[],"sequence":7211233,"timestamp":"2021-07-03T00:56:30.471Z","symbol":"BTCPAX"}}
1625273790.63192: {"jsonrpc":"2.0","method":"updateOrderbook","params":{"ask":[{"price":"0.08176","size":"15.9281"},{"price":"0.08204","size":"0"},{"price":"0.08205","size":"14.0829"},{"price":"0.08223","size":"14.6010"},{"price":"0.08224","size":"0"},{"price":"0.08245","size":"14.8797"},{"price":"0.08253","size":"0"},{"price":"0.08279","size":"14.3738"},{"price":"0.08284","size":"0"},{"price":"0.08311","size":"0"},{"price":"0.08312","size":"15.6194"},{"price":"0.08343","size":"0"},{"price":"0.08351","size":"15.5136"},{"price":"0.08414","size":"0"}],"bid":[],"sequence":7339953,"timestamp":"2021-07-03T00:56:30.544Z","symbol":"MKRBTC"}}
1625273790.631951: {"jsonrpc":"2.0","method":"updateOrderbook","params":{"ask":[{"price":"33517.39","size":"0"},{"price":"33518.19","size":"0.01233"},{"price":"33520.38","size":"0"},{"price":"33521.83","size":"0.02977"}],"bid":[],"sequence":7476929,"timestamp":"2021-07-03T00:56:30.477Z","symbol":"BTCTUSD"}}
1625273790.731489: {"jsonrpc":"2.0","method":"updateOrderbook","params":{"ask":[{"price":"33587.81","size":"0"},{"price":"33591.42","size":"0.95910"}],"bid":[{"price":"33510.23","size":"1.04220"},{"price":"33507.32","size":"0.32903"}],"sequence":12626705,"timestamp":"2021-07-03T00:56:30.591Z","symbol":"BTCUSDB"}}
1625273790.7315478: {"jsonrpc":"2.0","method":"updateOrderbook","params":{"ask":[{"price":"0.00011915","size":"6250.68"},{"price":"0.00011980","size":"0"},{"price":"0.00015959","size":"19505.60"},{"price":"0.00015999","size":"0"},{"price":"0.00023458","size":"30396.48"},{"price":"0.00023511","size":"0"}],"bid":[],"sequence":12351723,"timestamp":"2021-07-03T00:56:30.635Z","symbol":"EOSBTC"}}
1625273790.731578: {"jsonrpc":"2.0","method":"updateOrderbook","params":{"ask":[{"price":"33667.83","size":"0"},{"price":"33669.49","size":"0.00533"}],"bid":[],"sequence":7211234,"timestamp":"2021-07-03T00:56:30.571Z","symbol":"BTCPAX"}}
1625273790.7416708: {"jsonrpc":"2.0","method":"updateOrderbook","params":{"ask":[{"price":"33518.19","size":"0"},{"price":"33519.53","size":"0.01233"}],"bid":[],"sequence":7476930,"timestamp":"2021-07-03T00:56:30.576Z","symbol":"BTCTUSD"}}
1625273790.827085: {"jsonrpc":"2.0","method":"updateOrderbook","params":{"ask":[{"price":"0.00011770","size":"4513.55"},{"price":"0.00011985","size":"0"}],"bid":[],"sequence":12351724,"timestamp":"2021-07-03T00:56:30.738Z","symbol":"EOSBTC"}}
1625273790.827142: {"jsonrpc":"2.0","method":"updateOrderbook","params":{"ask":[{"price":"33552.57","size":"0.02460"},{"price":"33552.90","size":"0.07070"},{"price":"33553.86","size":"0"},{"price":"33554.87","size":"0"}],"bid":[],"sequence":12626706,"timestamp":"2021-07-03T00:56:30.727Z","symbol":"BTCUSDB"}}
1625273790.9228768: {"jsonrpc":"2.0","method":"updateOrderbook","params":{"ask":[],"bid":[{"price":"2099.104","size":"22.3435"},{"price":"2094.397","size":"0"}],"sequence":1513060,"timestamp":"2021-07-03T00:56:30.772Z","symbol":"ETHDAI"}}
1625273790.930906: {"jsonrpc":"2.0","method":"updateOrderbook","params":{"ask":[{"price":"33570.26","size":"0.28694"},{"price":"33573.27","size":"0"}],"bid":[{"price":"33539.63","size":"0.02940"},{"price":"33539.17","size":"0"}],"sequence":12626707,"timestamp":"2021-07-03T00:56:30.837Z","symbol":"BTCUSDB"}}
1625273791.0284429: {"jsonrpc":"2.0","method":"updateOrderbook","params":{"ask":[{"price":"0.00075744","size":"42091.73"},{"price":"0.00075990","size":"0"}],"bid":[],"sequence":12351725,"timestamp":"2021-07-03T00:56:30.942Z","symbol":"EOSBTC"}}
1625273791.0313249: {"jsonrpc":"2.0","method":"updateOrderbook","params":{"ask":[],"bid":[{"price":"33542.51","size":"0.02940"},{"price":"33539.63","size":"0"},{"price":"33525.33","size":"1.43690"},{"price":"33523.62","size":"0"},{"price":"33516.99","size":"0.94240"},{"price":"33513.21","size":"1.10595"},{"price":"33512.48","size":"0"},{"price":"33510.15","size":"0"}],"sequence":12626708,"timestamp":"2021-07-03T00:56:30.935Z","symbol":"BTCUSDB"}}
1625273791.125579: {"jsonrpc":"2.0","method":"updateOrderbook","params":{"ask":[{"price":"167648.30","size":"0"},{"price":"167651.50","size":"0.00019"}],"bid":[{"price":"33542.73","size":"0.02940"},{"price":"33542.51","size":"0"},{"price":"33531.17","size":"1.81560"},{"price":"33530.63","size":"0"},{"price":"33492.29","size":"1.43580"},{"price":"33489.25","size":"0"},{"price":"10059.09","size":"0.00010"},{"price":"10058.89","size":"0"}],"sequence":12626709,"timestamp":"2021-07-03T00:56:31.039Z","symbol":"BTCUSDB"}}
1625273791.1323168: {"jsonrpc":"2.0","method":"updateOrderbook","params":{"ask":[{"price":"0.07639","size":"0"},{"price":"0.07643","size":"2.0036"}],"bid":[],"sequence":7339954,"timestamp":"2021-07-03T00:56:31.039Z","symbol":"MKRBTC"}}
1625273791.235337: {"jsonrpc":"2.0","method":"updateOrderbook","params":{"ask":[{"price":"33561.98","size":"1.16940"},{"price":"33565.52","size":"0"},{"price":"33569.50","size":"1.09780"},{"price":"33570.55","size":"0.95910"}],"bid":[{"price":"33542.98","size":"0.02940"},{"price":"33542.73","size":"0"},{"price":"33537.60","size":"0.05460"},{"price":"33532.91","size":"0"},{"price":"33531.77","size":"1.81560"},{"price":"33531.17","size":"0"},{"price":"33517.65","size":"0.94240"},{"price":"33516.99","size":"0"}],"sequence":12626710,"timestamp":"2021-07-03T00:56:31.118Z","symbol":"BTCUSDB"}}
1625273791.327209: {"jsonrpc":"2.0","method":"updateOrderbook","params":{"ask":[{"price":"33561.98","size":"0.41740"},{"price":"33563.47","size":"0.75200"}],"bid":[{"price":"33542.98","size":"0"},{"price":"33542.86","size":"0.02940"},{"price":"33532.42","size":"1.81560"},{"price":"33531.77","size":"0"}],"sequence":12626711,"timestamp":"2021-07-03T00:56:31.251Z","symbol":"BTCUSDB"}}
1625273791.327273: {"jsonrpc":"2.0","method":"updateOrderbook","params":{"ask":[{"price":"0.00011599","size":"1896.82"},{"price":"0.00011602","size":"2195.59"},{"price":"0.00014667","size":"5718.01"},{"price":"0.00015225","size":"0"},{"price":"0.00016864","size":"7220.48"},{"price":"0.00017187","size":"0"}],"bid":[],"sequence":12351726,"timestamp":"2021-07-03T00:56:31.231Z","symbol":"EOSBTC"}}
1625273791.3273: {"jsonrpc":"2.0","method":"updateOrderbook","params":{"ask":[{"price":"0.09664","size":"0"},{"price":"0.10027","size":"3.7522"},{"price":"0.23657","size":"0"},{"price":"0.29199","size":"4.2976"}],"bid":[],"sequence":7339955,"timestamp":"2021-07-03T00:56:31.167Z","symbol":"MKRBTC"}}
1625273791.327321: {"jsonrpc":"2.0","method":"updateOrderbook","params":{"ask":[{"price":"33519.53","size":"0"},{"price":"33521.83","size":"0"},{"price":"33522.34","size":"0.01233"},{"price":"33525.68","size":"0.02977"},{"price":"33565.16","size":"0"},{"price":"33570.90","size":"0.00910"},{"price":"34100.30","size":"0"},{"price":"34149.40","size":"1.76840"}],"bid":[{"price":"33489.14","size":"0"},{"price":"33486.17","size":"0.01473"}],"sequence":7476931,"timestamp":"2021-07-03T00:56:31.206Z","symbol":"BTCTUSD"}}
1625273791.421752: {"jsonrpc":"2.0","method":"updateOrderbook","params":{"ask":[{"price":"33558.05","size":"0.07707"},{"price":"33559.16","size":"0"},{"price":"33561.67","size":"0.18610"},{"price":"33563.95","size":"0"},{"price":"33570.64","size":"0.32146"},{"price":"33574.46","size":"0"},{"price":"33577.32","size":"0.37785"},{"price":"33583.27","size":"0"}],"bid":[{"price":"33526.95","size":"0.09211"},{"price":"33526.76","size":"0"},{"price":"33523.93","size":"0"},{"price":"33523.34","size":"0.17107"},{"price":"33514.35","size":"0.31770"},{"price":"33511.96","size":"0"},{"price":"33507.62","size":"0.37409"},{"price":"33504.60","size":"0"}],"sequence":5708312,"timestamp":"2021-07-03T00:56:31.333Z","symbol":"BTCDAI"}}
1625273791.428295: {"jsonrpc":"2.0","method":"updateOrderbook","params":{"ask":[{"price":"33570.26","size":"0.01174"},{"price":"33574.26","size":"0.27520"},{"price":"33582.72","size":"0.79591"},{"price":"33585.73","size":"0"}],"bid":[{"price":"33241.67","size":"1.54724"},{"price":"33229.15","size":"0"}],"sequence":12626712,"timestamp":"2021-07-03T00:56:31.339Z","symbol":"BTCUSDB"}}
1625273791.4283211: {"jsonrpc":"2.0","method":"updateOrderbook","params":{"ask":[{"price":"0.00011579","size":"0"},{"price":"0.00011580","size":"230.00"},{"price":"0.00011581","size":"511.32"},{"price":"0.00011582","size":"1240.09"},{"price":"0.00011589","size":"0"},{"price":"0.00011590","size":"1808.80"},{"price":"0.00011593","size":"2395.09"}],"bid":[{"price":"0.00011571","size":"1637.94"},{"price":"0.00011563","size":"1880.18"},{"price":"0.00011562","size":"885.97"},{"price":"0.00011559","size":"2916.18"},{"price":"0.00011558","size":"825.66"}],"sequence":12351727,"timestamp":"2021-07-03T00:56:31.351Z","symbol":"EOSBTC"}}
1625273791.42836: {"jsonrpc":"2.0","method":"updateOrderbook","params":{"ask":[{"price":"33660.70","size":"0"},{"price":"33661.81","size":"0.00533"}],"bid":[{"price":"33549.06","size":"0.01069"},{"price":"33545.64","size":"0"},{"price":"33541.84","size":"0"},{"price":"33538.81","size":"0.01986"},{"price":"33504.63","size":"0.03689"},{"price":"33504.27","size":"0"},{"price":"33486.10","size":"0.04344"},{"price":"33484.83","size":"0"}],"sequence":7211235,"timestamp":"2021-07-03T00:56:31.340Z","symbol":"BTCPAX"}}
1625273791.4353259: {"jsonrpc":"2.0","method":"updateOrderbook","params":{"ask":[{"price":"0.07643","size":"1.4283"},{"price":"0.07648","size":"3.1588"},{"price":"0.07651","size":"0"},{"price":"0.07656","size":"8.0685"},{"price":"0.07660","size":"0"},{"price":"0.07665","size":"2.1638"},{"price":"0.10027","size":"0"},{"price":"0.10751","size":"3.7522"},{"price":"0.29199","size":"0"},{"price":"0.41473","size":"4.2976"}],"bid":[],"sequence":7339956,"timestamp":"2021-07-03T00:56:31.342Z","symbol":"MKRBTC"}}
1625273791.435348: {"jsonrpc":"2.0","method":"updateOrderbook","params":{"ask":[{"price":"33520.27","size":"0.01233"},{"price":"33521.43","size":"0.02977"},{"price":"33522.34","size":"0"},{"price":"33525.68","size":"0"}],"bid":[],"sequence":7476932,"timestamp":"2021-07-03T00:56:31.349Z","symbol":"BTCTUSD"}}
1625273791.535521: {"jsonrpc":"2.0","method":"updateOrderbook","params":{"ask":[{"price":"33553.90","size":"0.67070"},{"price":"33557.57","size":"1.03952"},{"price":"33596.01","size":"0"},{"price":"33599.31","size":"1.43490"},{"price":"33687.23","size":"1.07700"},{"price":"33703.31","size":"0"}],"bid":[{"price":"33543.07","size":"0.02940"},{"price":"33542.86","size":"0"}],"sequence":12626713,"timestamp":"2021-07-03T00:56:31.395Z","symbol":"BTCUSDB"}}
1625273791.535564: {"jsonrpc":"2.0","method":"updateOrderbook","params":{"ask":[{"price":"33518.02","size":"0.01233"},{"price":"33520.27","size":"0"}],"bid":[{"price":"33491.79","size":"0.01473"},{"price":"33486.17","size":"0"}],"sequence":7476933,"timestamp":"2021-07-03T00:56:31.439Z","symbol":"BTCTUSD"}}
1625273791.653554: {"jsonrpc":"2.0","method":"updateOrderbook","params":{"ask":[{"price":"33563.47","size":"0"},{"price":"33567.20","size":"0.75200"}],"bid":[{"price":"33543.29","size":"0.02940"},{"price":"33543.07","size":"0"},{"price":"33518.07","size":"1.10595"},{"price":"33513.21","size":"0"}],"sequence":12626714,"timestamp":"2021-07-03T00:56:31.522Z","symbol":"BTCUSDB"}}
1625273791.653619: {"jsonrpc":"2.0","method":"updateOrderbook","params":{"ask":[{"price":"0.00011580","size":"642.32"},{"price":"0.00011581","size":"343.48"},{"price":"0.00011582","size":"995.61"},{"price":"0.00011770","size":"0"},{"price":"0.00012474","size":"4513.55"},{"price":"0.00014667","size":"0"},{"price":"0.00015600","size":"5733.01"},{"price":"0.00016864","size":"0"},{"price":"0.00017499","size":"7220.48"},{"price":"0.00018932","size":"0"},{"price":"0.00019095","size":"10554.74"},{"price":"0.00022582","size":"0"},{"price":"0.00022942","size":"15617.57"},{"price":"0.00026901","size":"0"},{"price":"0.00027078","size":"21530.31"}],"bid":[{"price":"0.00011536","size":"7852.58"},{"price":"0.00011526","size":"3179.53"},{"price":"0.00011027","size":"0"},{"price":"0.00011001","size":"7497.84"}],"sequence":12351728,"timestamp":"2021-07-03T00:56:31.547Z","symbol":"EOSBTC"}}
1625273791.653662: {"jsonrpc":"2.0","method":"updateOrderbook","params":{"ask":[{"price":"33517.74","size":"0.01233"},{"price":"33518.02","size":"0"}],"bid":[{"price":"33488.47","size":"0.02736"},{"price":"33481.48","size":"0"}],"sequence":7476934,"timestamp":"2021-07-03T00:56:31.474Z","symbol":"BTCTUSD"}}
1625273791.775856: {"jsonrpc":"2.0","method":"updateOrderbook","params":{"ask":[{"price":"33553.90","size":"0"},{"price":"33557.99","size":"0.67070"},{"price":"33570.26","size":"0"},{"price":"33574.26","size":"0.28694"},{"price":"33608.35","size":"0.51010"},{"price":"33617.51","size":"0"}],"bid":[{"price":"33543.97","size":"0.02940"},{"price":"33543.29","size":"0"},{"price":"33541.81","size":"1.15550"},{"price":"33537.82","size":"0"},{"price":"33533.13","size":"0"},{"price":"33532.32","size":"1.43690"},{"price":"33525.33","size":"0"},{"price":"33503.83","size":"0.77340"},{"price":"33502.47","size":"1.81560"},{"price":"33498.84","size":"0"},{"price":"33492.85","size":"0"},{"price":"33449.94","size":"1.13040"},{"price":"33440.05","size":"0"}],"sequence":12626715,"timestamp":"2021-07-03T00:56:31.625Z","symbol":"BTCUSDB"}}
1625273791.7759302: {"jsonrpc":"2.0","method":"updateOrderbook","params":{"ask":[{"price":"33564.09","size":"0.00910"},{"price":"33570.90","size":"0"}],"bid":[{"price":"33479.19","size":"0.05082"},{"price":"33468.26","size":"0"},{"price":"33380.70","size":"0.34070"},{"price":"33347.96","size":"0"}],"sequence":7476935,"timestamp":"2021-07-03T00:56:31.638Z","symbol":"BTCTUSD"}}
1625273791.832726: {"jsonrpc":"2.0","method":"updateOrderbook","params":{"ask":[],"bid":[{"price":"33538.87","size":"0.05460"},{"price":"33537.60","size":"0"}],"sequence":12626716,"timestamp":"2021-07-03T00:56:31.685Z","symbol":"BTCUSDB"}}
1625273791.832754: {"jsonrpc":"2.0","method":"updateOrderbook","params":{"ask":[{"price":"0.07759","size":"0"},{"price":"0.07768","size":"11.9903"},{"price":"0.07988","size":"0"},{"price":"0.08063","size":"17.0727"}],"bid":[],"sequence":7339957,"timestamp":"2021-07-03T00:56:31.660Z","symbol":"MKRBTC"}}
1625273791.964224: {"jsonrpc":"2.0","method":"updateOrderbook","params":{"ask":[],"bid":[{"price":"33544.62","size":"0.02940"},{"price":"33543.97","size":"0"},{"price":"33537.72","size":"1.81560"},{"price":"33532.42","size":"0"},{"price":"33522.19","size":"0.94240"},{"price":"33517.65","size":"0"},{"price":"33515.23","size":"0.32903"},{"price":"33507.32","size":"0"}],"sequence":12626717,"timestamp":"2021-07-03T00:56:31.832Z","symbol":"BTCUSDB"}}
1625273791.9642391: {"jsonrpc":"2.0","method":"updateOrderbook","params":{"ask":[{"price":"0.00011579","size":"99.00"},{"price":"0.00011581","size":"244.48"}],"bid":[{"price":"0.00011525","size":"5762.65"},{"price":"0.00011498","size":"6381.39"},{"price":"0.00011493","size":"8378.72"},{"price":"0.00011473","size":"0"}],"sequence":12351729,"timestamp":"2021-07-03T00:56:31.852Z","symbol":"EOSBTC"}}
1625273791.964273: {"jsonrpc":"2.0","method":"updateOrderbook","params":{"ask":[],"bid":[{"price":"33467.49","size":"0.20870"},{"price":"33423.06","size":"0"}],"sequence":7476936,"timestamp":"2021-07-03T00:56:31.771Z","symbol":"BTCTUSD"}}
1625273792.036408: {"jsonrpc":"2.0","method":"updateOrderbook","params":{"ask":[{"price":"0.00011579","size":"412.32"},{"price":"0.00011580","size":"329.00"}],"bid":[{"price":"0.00011460","size":"0"},{"price":"0.00011446","size":"4559.60"},{"price":"0.00011001","size":"0"},{"price":"0.00010898","size":"7497.84"}],"sequence":12351730,"timestamp":"2021-07-03T00:56:31.940Z","symbol":"EOSBTC"}}
1625273792.036438: {"jsonrpc":"2.0","method":"updateOrderbook","params":{"ask":[{"price":"33553.43","size":"0"},{"price":"33555.55","size":"0.05940"},{"price":"33560.44","size":"0"},{"price":"33565.52","size":"0.10260"}],"bid":[{"price":"33544.62","size":"0"},{"price":"33542.60","size":"0.02940"},{"price":"33538.87","size":"0"},{"price":"33535.06","size":"0.05460"},{"price":"33522.19","size":"0"},{"price":"33519.73","size":"0.94240"},{"price":"33518.07","size":"0"},{"price":"33517.14","size":"1.10595"}],"sequence":12626718,"timestamp":"2021-07-03T00:56:31.932Z","symbol":"BTCUSDB"}}
1625273792.036458: {"jsonrpc":"2.0","method":"updateOrderbook","params":{"ask":[{"price":"33590.47","size":"0.15630"},{"price":"33604.65","size":"0"}],"bid":[],"sequence":7476937,"timestamp":"2021-07-03T00:56:31.875Z","symbol":"BTCTUSD"}}
1625273792.1295528: {"jsonrpc":"2.0","method":"updateOrderbook","params":{"ask":[{"price":"33567.20","size":"0"},{"price":"33568.95","size":"0.75200"},{"price":"167651.50","size":"0"},{"price":"167668.93","size":"0.00013"}],"bid":[{"price":"33543.74","size":"0.02940"},{"price":"33542.60","size":"0"},{"price":"33541.81","size":"0.38210"},{"price":"33539.22","size":"0.77340"},{"price":"33537.72","size":"0"},{"price":"33534.52","size":"1.81560"},{"price":"33532.32","size":"0"},{"price":"33529.34","size":"1.43690"},{"price":"33519.73","size":"0"},{"price":"33517.14","size":"0"},{"price":"33516.75","size":"0.94240"},{"price":"33512.82","size":"1.10595"},{"price":"33467.71","size":"1.04000"},{"price":"33457.98","size":"0"},{"price":"10060.13","size":"0.00017"},{"price":"10059.09","size":"0"}],"sequence":12626719,"timestamp":"2021-07-03T00:56:32.035Z","symbol":"BTCUSDB"}}
1625273792.129631: {"jsonrpc":"2.0","method":"updateOrderbook","params":{"ask":[{"price":"0.00011579","size":"0"},{"price":"0.00011580","size":"741.32"}],"bid":[],"sequence":12351731,"timestamp":"2021-07-03T00:56:31.974Z","symbol":"EOSBTC"}}
1625273792.234659: {"jsonrpc":"2.0","method":"updateOrderbook","params":{"ask":[],"bid":[{"price":"0.00011461","size":"4559.60"},{"price":"0.00011449","size":"16444.03"},{"price":"0.00011446","size":"0"},{"price":"0.00011373","size":"0"}],"sequence":12351732,"timestamp":"2021-07-03T00:56:32.124Z","symbol":"EOSBTC"}}
1625273792.234721: {"jsonrpc":"2.0","method":"updateOrderbook","params":{"ask":[{"price":"33553.63","size":"0.05940"},{"price":"33555.55","size":"0"}],"bid":[{"price":"33545.09","size":"0.02940"},{"price":"33543.74","size":"0"},{"price":"33538.05","size":"0.05460"},{"price":"33535.06","size":"0"},{"price":"33518.23","size":"0.77390"},{"price":"33511.29","size":"0"},{"price":"33505.12","size":"0.38210"},{"price":"33501.75","size":"0"}],"sequence":12626720,"timestamp":"2021-07-03T00:56:32.127Z","symbol":"BTCUSDB"}}
1625273792.3388002: {"jsonrpc":"2.0","method":"updateOrderbook","params":{"ask":[{"price":"0.00011579","size":"99.00"},{"price":"0.00011580","size":"642.32"},{"price":"0.00012474","size":"0"},{"price":"0.00012604","size":"4513.55"},{"price":"0.00015600","size":"15.00"},{"price":"0.00015673","size":"5719.01"},{"price":"0.00017499","size":"0"},{"price":"0.00017562","size":"7220.48"},{"price":"0.00019095","size":"0"},{"price":"0.00019132","size":"10554.74"},{"price":"0.00022942","size":"0"},{"price":"0.00023030","size":"15619.57"},{"price":"0.00027078","size":"0"},{"price":"0.00027115","size":"21530.31"}],"bid":[],"sequence":12351733,"timestamp":"2021-07-03T00:56:32.205Z","symbol":"EOSBTC"}}
1625273792.338909: {"jsonrpc":"2.0","method":"updateOrderbook","params":{"ask":[{"price":"33574.27","size":"0"},{"price":"33577.72","size":"0.39780"},{"price":"33582.72","size":"0"},{"price":"33585.97","size":"0.79591"},{"price":"33598.16","size":"0.94720"},{"price":"33606.19","size":"0"}],"bid":[{"price":"33518.23","size":"1.81610"},{"price":"33510.23","size":"0"}],"sequence":12626721,"timestamp":"2021-07-03T00:56:32.182Z","symbol":"BTCUSDB"}}
1625273792.338929: {"jsonrpc":"2.0","method":"updateOrderbook","params":{"ask":[],"bid":[{"price":"32854.37","size":"1.37100"},{"price":"32806.42","size":"0"},{"price":"32116.39","size":"1.67560"},{"price":"31866.40","size":"0"}],"sequence":7476938,"timestamp":"2021-07-03T00:56:32.193Z","symbol":"BTCTUSD"}}
1625273792.449918: {"jsonrpc":"2.0","method":"updateOrderbook","params":{"ask":[{"price":"33552.00","size":"0.02460"},{"price":"33552.27","size":"0.05940"},{"price":"33552.57","size":"0"},{"price":"33553.63","size":"0"}],"bid":[{"price":"33540.07","size":"0.05460"},{"price":"33539.22","size":"0"},{"price":"33538.35","size":"0.77340"},{"price":"33538.05","size":"0"},{"price":"33534.52","size":"0"},{"price":"33534.35","size":"1.81560"},{"price":"33498.85","size":"1.43690"},{"price":"33497.38","size":"0.94240"},{"price":"33488.73","size":"0"},{"price":"33486.59","size":"0"}],"sequence":12626722,"timestamp":"2021-07-03T00:56:32.307Z","symbol":"BTCUSDB"}}
1625273792.450062: {"jsonrpc":"2.0","method":"updateOrderbook","params":{"ask":[{"price":"0.00015348","size":"26975.46"},{"price":"0.00015370","size":"0"}],"bid":[],"sequence":12351734,"timestamp":"2021-07-03T00:56:32.306Z","symbol":"EOSBTC"}}
1625273792.4500852: {"jsonrpc":"2.0","method":"updateOrderbook","params":{"ask":[{"price":"33517.47","size":"0.01233"},{"price":"33517.74","size":"0"}],"bid":[],"sequence":7476939,"timestamp":"2021-07-03T00:56:32.262Z","symbol":"BTCTUSD"}}
1625273792.532532: {"jsonrpc":"2.0","method":"updateOrderbook","params":{"ask":[],"bid":[{"price":"0.00011569","size":"0"},{"price":"0.00011566","size":"186.44"},{"price":"0.00010637","size":"23147.93"},{"price":"0.00010138","size":"0.37"},{"price":"0.00009438","size":"12370.85"},{"price":"0.00008451","size":"0"}],"sequence":12351735,"timestamp":"2021-07-03T00:56:32.394Z","symbol":"EOSBTC"}}
1625273792.632425: {"jsonrpc":"2.0","method":"updateOrderbook","params":{"ask":[{"price":"0.00012936","size":"22588.08"},{"price":"0.00012966","size":"0"}],"bid":[{"price":"0.00011535","size":"0"},{"price":"0.00011526","size":"5004.40"},{"price":"0.00011499","size":"2812.89"},{"price":"0.00011485","size":"3392.48"},{"price":"0.00011461","size":"0"},{"price":"0.00011439","size":"4559.60"},{"price":"0.00010898","size":"0"},{"price":"0.00010828","size":"7497.84"}],"sequence":12351736,"timestamp":"2021-07-03T00:56:32.533Z","symbol":"EOSBTC"}}
1625273792.632492: {"jsonrpc":"2.0","method":"updateOrderbook","params":{"ask":[{"price":"33595.18","size":"1.43490"},{"price":"33599.31","size":"0"},{"price":"33609.99","size":"0"},{"price":"33618.85","size":"0.43410"}],"bid":[{"price":"33521.85","size":"0.94240"},{"price":"33519.16","size":"1.10595"},{"price":"33516.75","size":"0"},{"price":"33512.82","size":"0"},{"price":"33489.97","size":"0"},{"price":"33479.88","size":"1.11830"},{"price":"33470.12","size":"1.34190"},{"price":"33467.98","size":"0.69420"}],"sequence":12626723,"timestamp":"2021-07-03T00:56:32.546Z","symbol":"BTCUSDB"}}
1625273792.6325262: {"jsonrpc":"2.0","method":"updateOrderbook","params":{"ask":[],"bid":[{"price":"30531.12","size":"1.39725"},{"price":"30460.12","size":"0"}],"sequence":7476940,"timestamp":"2021-07-03T00:56:32.472Z","symbol":"BTCTUSD"}}
1625273792.7394922: {"jsonrpc":"2.0","method":"updateOrderbook","params":{"ask":[{"price":"33562.05","size":"0.75200"},{"price":"33568.95","size":"0"}],"bid":[{"price":"33521.85","size":"0"},{"price":"33520.29","size":"0.94240"},{"price":"33519.16","size":"0"},{"price":"33517.11","size":"1.10595"}],"sequence":12626724,"timestamp":"2021-07-03T00:56:32.635Z","symbol":"BTCUSDB"}}
1625273792.73953: {"jsonrpc":"2.0","method":"updateOrderbook","params":{"ask":[],"bid":[{"price":"0.00011535","size":"1824.87"},{"price":"0.00011526","size":"3179.53"},{"price":"0.00011356","size":"0"}],"sequence":12351737,"timestamp":"2021-07-03T00:56:32.600Z","symbol":"EOSBTC"}}
1625273792.746277: {"jsonrpc":"2.0","method":"updateOrderbook","params":{"ask":[{"price":"33517.47","size":"0"},{"price":"33518.48","size":"0.01233"}],"bid":[],"sequence":7476941,"timestamp":"2021-07-03T00:56:32.645Z","symbol":"BTCTUSD"}}
1625273792.8298829: {"jsonrpc":"2.0","method":"updateOrderbook","params":{"ask":[{"price":"0.00013913","size":"0"},{"price":"0.00013944","size":"53526.30"}],"bid":[{"price":"0.00011375","size":"14.29"}],"sequence":12351738,"timestamp":"2021-07-03T00:56:32.748Z","symbol":"EOSBTC"}}
1625273792.8352242: {"jsonrpc":"2.0","method":"updateOrderbook","params":{"ask":[{"price":"33518.08","size":"0.01233"},{"price":"33518.48","size":"0"}],"bid":[],"sequence":7476942,"timestamp":"2021-07-03T00:56:32.686Z","symbol":"BTCTUSD"}}
1625273792.933195: {"jsonrpc":"2.0","method":"updateOrderbook","params":{"ask":[{"price":"33563.78","size":"0.91740"},{"price":"33565.37","size":"0"}],"bid":[{"price":"33538.91","size":"0.77340"},{"price":"33538.35","size":"0"},{"price":"33534.95","size":"1.81560"},{"price":"33534.35","size":"0"},{"price":"33531.42","size":"1.43690"},{"price":"33529.34","size":"0"},{"price":"33521.04","size":"0.94240"},{"price":"33520.29","size":"0"}],"sequence":12626725,"timestamp":"2021-07-03T00:56:32.803Z","symbol":"BTCUSDB"}}
1625273792.9364312: {"jsonrpc":"2.0","method":"updateOrderbook","params":{"ask":[{"price":"0.00012050","size":"1.00"},{"price":"0.00012076","size":"27581.23"},{"price":"0.00023695","size":"39545.26"},{"price":"0.00023740","size":"0"},{"price":"0.00033340","size":"56176.40"},{"price":"0.00033435","size":"0"}],"bid":[],"sequence":12351739,"timestamp":"2021-07-03T00:56:32.847Z","symbol":"EOSBTC"}}
1625273792.963339: {"jsonrpc":"2.0","method":"updateOrderbook","params":{"ask":[{"price":"0.07645","size":"0.5753"},{"price":"0.07648","size":"2.5835"}],"bid":[],"sequence":7339958,"timestamp":"2021-07-03T00:56:32.756Z","symbol":"MKRBTC"}}
1625273793.045265: {"jsonrpc":"2.0","method":"updateOrderbook","params":{"ask":[],"bid":[{"price":"33538.91","size":"0"},{"price":"33537.74","size":"0.77340"},{"price":"33531.42","size":"0"},{"price":"33529.89","size":"1.43690"},{"price":"33521.04","size":"0"},{"price":"33519.68","size":"0.94240"},{"price":"33518.23","size":"2.14513"},{"price":"33517.11","size":"0"},{"price":"33516.39","size":"1.10595"},{"price":"33515.23","size":"0"}],"sequence":12626726,"timestamp":"2021-07-03T00:56:32.910Z","symbol":"BTCUSDB"}}
1625273793.0453298: {"jsonrpc":"2.0","method":"updateOrderbook","params":{"ask":[{"price":"33518.08","size":"0"},{"price":"33518.50","size":"0.01233"}],"bid":[],"sequence":7476943,"timestamp":"2021-07-03T00:56:32.907Z","symbol":"BTCTUSD"}}
1625273793.1448479: {"jsonrpc":"2.0","method":"updateOrderbook","params":{"ask":[{"price":"33567.90","size":"1.09780"},{"price":"33569.50","size":"0"},{"price":"167665.55","size":"0.00010"},{"price":"167668.93","size":"0"}],"bid":[{"price":"10060.13","size":"0"},{"price":"10059.93","size":"0.00013"}],"sequence":12626727,"timestamp":"2021-07-03T00:56:33.007Z","symbol":"BTCUSDB"}}
1625273793.2443252: {"jsonrpc":"2.0","method":"updateOrderbook","params":{"ask":[{"price":"33604.30","size":"1.06920"},{"price":"33613.65","size":"0"}],"bid":[],"sequence":12626728,"timestamp":"2021-07-03T00:56:33.066Z","symbol":"BTCUSDB"}}
1625273793.244382: {"jsonrpc":"2.0","method":"updateOrderbook","params":{"ask":[{"price":"0.00087682","size":"86093.30"},{"price":"0.00088111","size":"0"}],"bid":[{"price":"0.00011499","size":"6205.37"},{"price":"0.00011485","size":"0"}],"sequence":12351740,"timestamp":"2021-07-03T00:56:33.133Z","symbol":"EOSBTC"}}
1625273793.2444081: {"jsonrpc":"2.0","method":"updateOrderbook","params":{"ask":[{"price":"34031.87","size":"1.76840"},{"price":"34149.40","size":"0"}],"bid":[],"sequence":7476944,"timestamp":"2021-07-03T00:56:33.112Z","symbol":"BTCTUSD"}}
1625273793.329818: {"jsonrpc":"2.0","method":"updateOrderbook","params":{"ask":[{"price":"0.07651","size":"1.4413"},{"price":"0.07656","size":"6.6272"},{"price":"0.07748","size":"11.9903"},{"price":"0.07768","size":"0"}],"bid":[],"sequence":7339959,"timestamp":"2021-07-03T00:56:33.201Z","symbol":"MKRBTC"}}
1625273793.434695: {"jsonrpc":"2.0","method":"updateOrderbook","params":{"ask":[{"price":"33585.03","size":"0.95910"},{"price":"33591.42","size":"0"}],"bid":[],"sequence":12626729,"timestamp":"2021-07-03T00:56:33.269Z","symbol":"BTCUSDB"}}
1625273793.434783: {"jsonrpc":"2.0","method":"updateOrderbook","params":{"ask":[],"bid":[{"price":"0.00011403","size":"0"},{"price":"0.00010909","size":"5810.54"},{"price":"0.00010828","size":"0"},{"price":"0.00010813","size":"7497.84"}],"sequence":12351741,"timestamp":"2021-07-03T00:56:33.341Z","symbol":"EOSBTC"}}
1625273793.4348009: {"jsonrpc":"2.0","method":"updateOrderbook","params":{"ask":[{"price":"35638.69","size":"1.29584"},{"price":"35888.15","size":"0"}],"bid":[],"sequence":7476945,"timestamp":"2021-07-03T00:56:33.316Z","symbol":"BTCTUSD"}}
1625273793.528366: {"jsonrpc":"2.0","method":"updateOrderbook","params":{"ask":[{"price":"33552.27","size":"0"},{"price":"33554.50","size":"0.05940"},{"price":"33589.25","size":"0.75370"},{"price":"33593.91","size":"0"}],"bid":[{"price":"33545.15","size":"0.02940"},{"price":"33545.09","size":"0"},{"price":"33538.53","size":"0.77340"},{"price":"33537.74","size":"0"},{"price":"33533.36","size":"1.43690"},{"price":"33529.89","size":"0"},{"price":"33522.46","size":"0.94240"},{"price":"33519.95","size":"1.10595"},{"price":"33519.68","size":"0"},{"price":"33516.39","size":"0"},{"price":"33493.01","size":"1.31900"},{"price":"33489.38","size":"0"}],"sequence":12626730,"timestamp":"2021-07-03T00:56:33.432Z","symbol":"BTCUSDB"}}
1625273793.528409: {"jsonrpc":"2.0","method":"updateOrderbook","params":{"ask":[{"price":"0.00087682","size":"0"},{"price":"0.00087755","size":"86093.30"}],"bid":[],"sequence":12351742,"timestamp":"2021-07-03T00:56:33.444Z","symbol":"EOSBTC"}}
1625273793.6234088: {"jsonrpc":"2.0","method":"updateOrderbook","params":{"ask":[],"bid":[{"price":"33539.07","size":"0.77340"},{"price":"33538.53","size":"0"}],"sequence":12626731,"timestamp":"2021-07-03T00:56:33.491Z","symbol":"BTCUSDB"}}
1625273793.626762: {"jsonrpc":"2.0","method":"updateOrderbook","params":{"ask":[{"price":"33518.50","size":"0"},{"price":"33518.60","size":"0.01233"},{"price":"33521.43","size":"0"},{"price":"33522.65","size":"0.02977"}],"bid":[{"price":"33498.36","size":"0.01473"},{"price":"33491.79","size":"0"}],"sequence":7476946,"timestamp":"2021-07-03T00:56:33.529Z","symbol":"BTCTUSD"}}
1625273793.728899: {"jsonrpc":"2.0","method":"updateOrderbook","params":{"ask":[{"price":"33551.34","size":"0.02460"},{"price":"33552.00","size":"0"}],"bid":[{"price":"33545.96","size":"0.02940"},{"price":"33545.15","size":"0"}],"sequence":12626732,"timestamp":"2021-07-03T00:56:33.643Z","symbol":"BTCUSDB"}}
1625273793.7289422: {"jsonrpc":"2.0","method":"updateOrderbook","params":{"ask":[{"price":"0.00012936","size":"0"},{"price":"0.00013177","size":"22588.08"},{"price":"0.00015348","size":"0"},{"price":"0.00015519","size":"26975.46"},{"price":"0.00023695","size":"0"},{"price":"0.00024022","size":"39545.26"},{"price":"0.00033340","size":"0"},{"price":"0.00033999","size":"56176.40"},{"price":"0.00087755","size":"0"},{"price":"0.00090337","size":"86093.30"}],"bid":[{"price":"0.00011375","size":"0"},{"price":"0.00010637","size":"0"},{"price":"0.00010591","size":"23147.93"},{"price":"0.00009438","size":"0"},{"price":"0.00009349","size":"12372.57"}],"sequence":12351743,"timestamp":"2021-07-03T00:56:33.615Z","symbol":"EOSBTC"}}
1625273793.728967: {"jsonrpc":"2.0","method":"updateOrderbook","params":{"ask":[{"price":"0.07945","size":"17.0727"},{"price":"0.08063","size":"0"}],"bid":[],"sequence":7339960,"timestamp":"2021-07-03T00:56:33.559Z","symbol":"MKRBTC"}}
1625273793.734609: {"jsonrpc":"2.0","method":"updateOrderbook","params":{"ask":[{"price":"33518.60","size":"0"},{"price":"33519.39","size":"0.01233"},{"price":"33607.40","size":"0.18170"},{"price":"33626.19","size":"0"}],"bid":[{"price":"33494.72","size":"0.02736"},{"price":"33488.47","size":"0"}],"sequence":7476947,"timestamp":"2021-07-03T00:56:33.645Z","symbol":"BTCTUSD"}}
1625273793.825087: {"jsonrpc":"2.0","method":"updateOrderbook","params":{"ask":[{"price":"33551.00","size":"0.02460"},{"price":"33551.34","size":"0"}],"bid":[],"sequence":12626733,"timestamp":"2021-07-03T00:56:33.725Z","symbol":"BTCUSDB"}}
1625273793.8252108: {"jsonrpc":"2.0","method":"updateOrderbook","params":{"ask":[],"bid":[{"price":"0.00011356","size":"14.32"}],"sequence":12351744,"timestamp":"2021-07-03T00:56:33.674Z","symbol":"EOSBTC"}}
1625273793.829403: {"jsonrpc":"2.0","method":"updateOrderbook","params":{"ask":[{"price":"0.09716","size":"3.7522"},{"price":"0.10751","size":"0"}],"bid":[],"sequence":7339961,"timestamp":"2021-07-03T00:56:33.705Z","symbol":"MKRBTC"}}
1625273793.829447: {"jsonrpc":"2.0","method":"updateOrderbook","params":{"ask":[{"price":"33519.04","size":"0.01233"},{"price":"33519.39","size":"0"}],"bid":[],"sequence":7476948,"timestamp":"2021-07-03T00:56:33.749Z","symbol":"BTCTUSD"}}
1625273793.930187: {"jsonrpc":"2.0","method":"updateOrderbook","params":{"ask":[{"price":"33551.00","size":"0"},{"price":"33552.34","size":"0.02460"},{"price":"33554.50","size":"0"},{"price":"33557.10","size":"0.05940"}],"bid":[{"price":"33545.96","size":"0"},{"price":"33543.41","size":"0.02940"}],"sequence":12626734,"timestamp":"2021-07-03T00:56:33.843Z","symbol":"BTCUSDB"}}
1625273793.930239: {"jsonrpc":"2.0","method":"updateOrderbook","params":{"ask":[{"price":"0.00090337","size":"0"},{"price":"0.00090416","size":"86093.30"}],"bid":[],"sequence":12351745,"timestamp":"2021-07-03T00:56:33.752Z","symbol":"EOSBTC"}}
1625273793.930249: {"jsonrpc":"2.0","method":"updateOrderbook","params":{"ask":[{"price":"33655.85","size":"0.00533"},{"price":"33661.81","size":"0"}],"bid":[],"sequence":7211236,"timestamp":"2021-07-03T00:56:33.842Z","symbol":"BTCPAX"}}
1625273793.9335492: {"jsonrpc":"2.0","method":"updateOrderbook","params":{"ask":[{"price":"33519.04","size":"0"},{"price":"33519.55","size":"0.01233"}],"bid":[],"sequence":7476949,"timestamp":"2021-07-03T00:56:33.794Z","symbol":"BTCTUSD"}}
1625273794.029919: {"jsonrpc":"2.0","method":"updateOrderbook","params":{"ask":[{"price":"33551.81","size":"0.02460"},{"price":"33552.34","size":"0"},{"price":"33574.47","size":"0.39780"},{"price":"33577.72","size":"0"}],"bid":[{"price":"33545.76","size":"0.02940"},{"price":"33543.41","size":"0"},{"price":"33467.71","size":"0"},{"price":"33459.84","size":"1.04000"}],"sequence":12626735,"timestamp":"2021-07-03T00:56:33.920Z","symbol":"BTCUSDB"}}
1625273794.0299442: {"jsonrpc":"2.0","method":"updateOrderbook","params":{"ask":[],"bid":[{"price":"0.00010591","size":"0"},{"price":"0.00010569","size":"23147.93"},{"price":"0.00009349","size":"1.72"},{"price":"0.00009307","size":"12370.85"}],"sequence":12351746,"timestamp":"2021-07-03T00:56:33.906Z","symbol":"EOSBTC"}}
1625273794.029952: {"jsonrpc":"2.0","method":"updateOrderbook","params":{"ask":[{"price":"33664.24","size":"0.00533"},{"price":"33669.49","size":"0"}],"bid":[],"sequence":7211237,"timestamp":"2021-07-03T00:56:33.934Z","symbol":"BTCPAX"}}
1625273794.1245089: {"jsonrpc":"2.0","method":"updateOrderbook","params":{"ask":[{"price":"39894.14","size":"0"},{"price":"39982.21","size":"4.51490"}],"bid":[],"sequence":5708313,"timestamp":"2021-07-03T00:56:33.997Z","symbol":"BTCDAI"}}
1625273794.1281002: {"jsonrpc":"2.0","method":"updateOrderbook","params":{"ask":[{"price":"33551.39","size":"0.02460"},{"price":"33551.81","size":"0"},{"price":"33556.00","size":"0.05940"},{"price":"33557.10","size":"0"},{"price":"167665.55","size":"0"},{"price":"167670.65","size":"0.00015"}],"bid":[{"price":"33505.12","size":"1.34220"},{"price":"33501.99","size":"0"},{"price":"33501.08","size":"0.94140"},{"price":"33494.24","size":"0"},{"price":"33481.48","size":"2.03610"},{"price":"33470.12","size":"0"},{"price":"33467.98","size":"0"},{"price":"10060.23","size":"0.00014"},{"price":"10059.93","size":"0"}],"sequence":12626736,"timestamp":"2021-07-03T00:56:34.036Z","symbol":"BTCUSDB"}}
1625273794.128175: {"jsonrpc":"2.0","method":"updateOrderbook","params":{"ask":[{"price":"33714.40","size":"0.00533"},{"price":"33741.89","size":"0"},{"price":"35023.24","size":"0"},{"price":"35115.28","size":"1.84720"}],"bid":[],"sequence":7211238,"timestamp":"2021-07-03T00:56:33.990Z","symbol":"BTCPAX"}}
1625273794.1286552: {"jsonrpc":"2.0","method":"updateOrderbook","params":{"ask":[{"price":"35638.69","size":"0"},{"price":"35713.67","size":"1.29584"}],"bid":[],"sequence":7476950,"timestamp":"2021-07-03T00:56:33.999Z","symbol":"BTCTUSD"}}
1625273794.230361: {"jsonrpc":"2.0","method":"updateOrderbook","params":{"ask":[{"price":"33551.39","size":"0"},{"price":"33553.33","size":"0.02460"},{"price":"33556.00","size":"0"},{"price":"33558.08","size":"0.05940"}],"bid":[{"price":"33545.76","size":"0"},{"price":"33544.93","size":"0.02940"},{"price":"33541.81","size":"1.15550"},{"price":"33539.07","size":"0"},{"price":"33538.44","size":"1.81560"},{"price":"33535.01","size":"1.43690"},{"price":"33534.95","size":"0"},{"price":"33533.36","size":"0"},{"price":"33527.97","size":"0.94240"},{"price":"33525.10","size":"1.10595"},{"price":"33522.46","size":"0"},{"price":"33519.95","size":"0"},{"price":"33495.10","size":"1.43580"},{"price":"33492.29","size":"0"}],"sequence":12626737,"timestamp":"2021-07-03T00:56:34.141Z","symbol":"BTCUSDB"}}
1625273794.230457: {"jsonrpc":"2.0","method":"updateOrderbook","params":{"ask":[],"bid":[{"price":"0.00010569","size":"0"},{"price":"0.00010549","size":"23147.93"},{"price":"0.00009307","size":"0"},{"price":"0.00009271","size":"12370.85"}],"sequence":12351747,"timestamp":"2021-07-03T00:56:34.140Z","symbol":"EOSBTC"}}
1625273794.3212569: {"jsonrpc":"2.0","method":"updateOrderbook","params":{"ask":[],"bid":[{"price":"2090.413","size":"23.9000"},{"price":"2088.230","size":"0"},{"price":"2085.986","size":"31.9000"},{"price":"2083.754","size":"0"}],"sequence":1513061,"timestamp":"2021-07-03T00:56:34.188Z","symbol":"ETHDAI"}}
1625273794.331687: {"jsonrpc":"2.0","method":"updateOrderbook","params":{"ask":[{"price":"33552.90","size":"0"},{"price":"33553.33","size":"0"},{"price":"33553.76","size":"0.02460"},{"price":"33558.39","size":"0.07070"},{"price":"33559.24","size":"0"},{"price":"33562.64","size":"0.45140"},{"price":"33563.78","size":"0"},{"price":"33566.57","size":"0.91740"},{"price":"33612.82","size":"0"},{"price":"33620.39","size":"0.09820"},{"price":"33623.77","size":"1.29870"},{"price":"33630.19","size":"0.71880"},{"price":"33634.88","size":"0"},{"price":"33642.21","size":"0"}],"bid":[{"price":"33546.05","size":"0.02940"},{"price":"33544.93","size":"0"},{"price":"33525.10","size":"0"},{"price":"33524.46","size":"1.10595"}],"sequence":12626738,"timestamp":"2021-07-03T00:56:34.251Z","symbol":"BTCUSDB"}}
1625273794.3322449: {"jsonrpc":"2.0","method":"updateOrderbook","params":{"ask":[{"price":"33519.55","size":"0"},{"price":"33520.10","size":"0.01233"}],"bid":[],"sequence":7476951,"timestamp":"2021-07-03T00:56:34.170Z","symbol":"BTCTUSD"}}
1625273794.430932: {"jsonrpc":"2.0","method":"updateOrderbook","params":{"ask":[{"price":"35612.03","size":"0"},{"price":"35622.28","size":"0.67400"}],"bid":[],"sequence":1470727,"timestamp":"2021-07-03T00:56:34.345Z","symbol":"BTCGUSD"}}
1625273794.430942: {"jsonrpc":"2.0","method":"updateOrderbook","params":{"ask":[{"price":"33570.19","size":"0.32145"},{"price":"33570.64","size":"0"}],"bid":[{"price":"33524.30","size":"0.17106"},{"price":"33523.34","size":"0"},{"price":"33515.27","size":"0.31769"},{"price":"33514.35","size":"0"}],"sequence":5708314,"timestamp":"2021-07-03T00:56:34.338Z","symbol":"BTCDAI"}}
1625273794.4309509: {"jsonrpc":"2.0","method":"updateOrderbook","params":{"ask":[{"price":"33553.03","size":"0.02460"},{"price":"33553.76","size":"0"},{"price":"33589.25","size":"0"},{"price":"33593.59","size":"0.75370"},{"price":"33608.35","size":"0"},{"price":"33616.89","size":"0.51010"}],"bid":[{"price":"33546.55","size":"0.02940"},{"price":"33546.05","size":"0"},{"price":"33542.04","size":"0.05460"},{"price":"33540.07","size":"0"},{"price":"33539.24","size":"1.81560"},{"price":"33538.44","size":"0"},{"price":"33535.01","size":"0"},{"price":"33535.00","size":"1.43690"},{"price":"33527.97","size":"0"},{"price":"33527.02","size":"0.11940"},{"price":"33526.30","size":"0.94240"},{"price":"33524.46","size":"0"},{"price":"33520.48","size":"1.10595"},{"price":"33516.82","size":"0"}],"sequence":12626739,"timestamp":"2021-07-03T00:56:34.352Z","symbol":"BTCUSDB"}}
1625273794.430986: {"jsonrpc":"2.0","method":"updateOrderbook","params":{"ask":[{"price":"0.00011580","size":"642.42"},{"price":"0.00011581","size":"995.85"},{"price":"0.00011582","size":"244.48"},{"price":"0.00011589","size":"1720.11"},{"price":"0.00011590","size":"89.10"},{"price":"0.00011593","size":"2395.58"},{"price":"0.00011645","size":"2908.55"},{"price":"0.00011659","size":"13408.34"},{"price":"0.00013177","size":"0"},{"price":"0.00014537","size":"22588.08"},{"price":"0.00015519","size":"0"},{"price":"0.00023878","size":"26975.46"},{"price":"0.00024022","size":"0"},{"price":"0.00028015","size":"39545.26"},{"price":"0.00033999","size":"0"},{"price":"0.00046654","size":"56176.40"},{"price":"0.00090416","size":"0"}],"bid":[{"price":"0.00011571","size":"1638.27"},{"price":"0.00011563","size":"1880.60"},{"price":"0.00011559","size":"2916.66"},{"price":"0.00011355","size":"0"}],"sequence":12351748,"timestamp":"2021-07-03T00:56:34.345Z","symbol":"EOSBTC"}}
1625273794.4432168: {"jsonrpc":"2.0","method":"updateOrderbook","params":{"ask":[{"price":"0.24215","size":"4.2976"},{"price":"0.41473","size":"0"}],"bid":[],"sequence":7339962,"timestamp":"2021-07-03T00:56:34.289Z","symbol":"MKRBTC"}}
1625273794.443257: {"jsonrpc":"2.0","method":"updateOrderbook","params":{"ask":[{"price":"33520.10","size":"0"},{"price":"33520.85","size":"0.01233"},{"price":"33522.65","size":"0"},{"price":"33523.32","size":"0.02979"},{"price":"33531.64","size":"0"},{"price":"33532.37","size":"0.05145"},{"price":"33536.76","size":"0"},{"price":"33537.36","size":"0.06048"},{"price":"33607.40","size":"0"},{"price":"33627.22","size":"0.18170"},{"price":"34031.87","size":"0"},{"price":"34106.27","size":"1.76840"},{"price":"35713.67","size":"0"},{"price":"35832.02","size":"1.29584"}],"bid":[{"price":"33498.95","size":"0.01474"},{"price":"33498.36","size":"0"},{"price":"33495.52","size":"0.02738"},{"price":"33494.72","size":"0"},{"price":"33486.43","size":"0.05085"},{"price":"33481.73","size":"0.05988"},{"price":"33479.19","size":"0"},{"price":"33476.67","size":"0"},{"price":"33433.97","size":"0.26550"},{"price":"33404.24","size":"0"},{"price":"33190.77","size":"0.87470"},{"price":"33101.02","size":"0"}],"sequence":7476952,"timestamp":"2021-07-03T00:56:34.347Z","symbol":"BTCTUSD"}}
1625273794.5260868: {"jsonrpc":"2.0","method":"updateOrderbook","params":{"ask":[{"price":"33552.38","size":"0.02460"},{"price":"33553.03","size":"0"},{"price":"33555.78","size":"0.05940"},{"price":"33558.08","size":"0"}],"bid":[{"price":"33541.81","size":"0.38210"},{"price":"33539.39","size":"0.77340"},{"price":"33539.24","size":"0"},{"price":"33536.64","size":"1.81560"},{"price":"33526.30","size":"0"},{"price":"33523.76","size":"0.94240"},{"price":"33520.48","size":"0"},{"price":"33520.26","size":"1.10595"},{"price":"33270.83","size":"0.94487"},{"price":"33254.46","size":"0"}],"sequence":12626740,"timestamp":"2021-07-03T00:56:34.441Z","symbol":"BTCUSDB"}}
1625273794.526211: {"jsonrpc":"2.0","method":"updateOrderbook","params":{"ask":[{"price":"0.00011619","size":"4550.12"},{"price":"0.00011621","size":"0"},{"price":"0.00090479","size":"86093.30"}],"bid":[{"price":"0.00010549","size":"0"},{"price":"0.00010401","size":"23147.93"},{"price":"0.00009271","size":"0"},{"price":"0.00008994","size":"12370.85"}],"sequence":12351749,"timestamp":"2021-07-03T00:56:34.377Z","symbol":"EOSBTC"}}
1625273794.538978: {"jsonrpc":"2.0","method":"updateOrderbook","params":{"ask":[{"price":"33520.85","size":"0"},{"price":"33521.39","size":"0.01233"},{"price":"33523.32","size":"0"},{"price":"33525.45","size":"0.02979"},{"price":"35832.02","size":"0"},{"price":"35888.15","size":"1.29584"}],"bid":[],"sequence":7476953,"timestamp":"2021-07-03T00:56:34.423Z","symbol":"BTCTUSD"}}
1625273794.625807: {"jsonrpc":"2.0","method":"updateOrderbook","params":{"ask":[{"price":"33551.62","size":"0.02460"},{"price":"33552.38","size":"0"}],"bid":[],"sequence":12626741,"timestamp":"2021-07-03T00:56:34.532Z","symbol":"BTCUSDB"}}
1625273794.6258821: {"jsonrpc":"2.0","method":"updateOrderbook","params":{"ask":[],"bid":[{"price":"31215.03","size":"1.68120"},{"price":"31079.68","size":"0"}],"sequence":7211239,"timestamp":"2021-07-03T00:56:34.539Z","symbol":"BTCPAX"}}
1625273794.633101: {"jsonrpc":"2.0","method":"updateOrderbook","params":{"ask":[{"price":"33520.96","size":"0.01233"},{"price":"33521.39","size":"0"},{"price":"33524.14","size":"0.02979"},{"price":"33525.45","size":"0"}],"bid":[],"sequence":7476954,"timestamp":"2021-07-03T00:56:34.551Z","symbol":"BTCTUSD"}}
1625273794.731553: {"jsonrpc":"2.0","method":"updateOrderbook","params":{"ask":[{"price":"33551.42","size":"0.02460"},{"price":"33551.62","size":"0"}],"bid":[],"sequence":12626742,"timestamp":"2021-07-03T00:56:34.643Z","symbol":"BTCUSDB"}}
1625273794.7316322: {"jsonrpc":"2.0","method":"updateOrderbook","params":{"ask":[{"price":"0.00011599","size":"1986.07"},{"price":"0.00011602","size":"2106.34"}],"bid":[{"price":"0.00011032","size":"0"}],"sequence":12351750,"timestamp":"2021-07-03T00:56:34.577Z","symbol":"EOSBTC"}}
1625273794.836819: {"jsonrpc":"2.0","method":"updateOrderbook","params":{"ask":[{"price":"33550.92","size":"0.02460"},{"price":"33551.42","size":"0"}],"bid":[{"price":"33546.55","size":"0"},{"price":"33545.42","size":"0.02940"}],"sequence":12626743,"timestamp":"2021-07-03T00:56:34.748Z","symbol":"BTCUSDB"}}
