1625273794.836939: {"jsonrpc":"2.0","method":"updateOrderbook","params":{"ask":[],"bid":[{"price":"0.00011571","size":"230.00"},{"price":"0.00011570","size":"492.89"},{"price":"0.00011568","size":"1712.34"},{"price":"0.00011562","size":"802.24"},{"price":"0.00011560","size":"0"},{"price":"0.00011554","size":"0"},{"price":"0.00011552","size":"958.41"},{"price":"0.00011547","size":"1799.51"},{"price":"0.00011537","size":"866.81"},{"price":"0.00011458","size":"4559.60"},{"price":"0.00011439","size":"0"}],"sequence":12351751,"timestamp":"2021-07-03T00:56:34.732Z","symbol":"EOSBTC"}}
1625273794.837075: {"jsonrpc":"2.0","method":"updateOrderbook","params":{"ask":[],"bid":[{"price":"33370.71","size":"0.44090"},{"price":"33304.12","size":"0"}],"sequence":7476955,"timestamp":"2021-07-03T00:56:34.671Z","symbol":"BTCTUSD"}}
1625273794.9267259: {"jsonrpc":"2.0","method":"updateOrderbook","params":{"ask":[{"price":"33550.67","size":"0.02460"},{"price":"33550.92","size":"0"},{"price":"33554.77","size":"0.05940"},{"price":"33555.78","size":"0"}],"bid":[{"price":"33536.64","size":"0"},{"price":"33535.51","size":"1.81560"},{"price":"33535.00","size":"0"},{"price":"33534.37","size":"1.43690"}],"sequence":12626744,"timestamp":"2021-07-03T00:56:34.830Z","symbol":"BTCUSDB"}}
1625273794.926858: {"jsonrpc":"2.0","method":"updateOrderbook","params":{"ask":[{"price":"0.00011719","size":"4513.55"},{"price":"0.00012604","size":"0"}],"bid":[{"price":"0.00010884","size":"6431.45"}],"sequence":12351752,"timestamp":"2021-07-03T00:56:34.843Z","symbol":"EOSBTC"}}
1625273794.9338748: {"jsonrpc":"2.0","method":"updateOrderbook","params":{"ask":[{"price":"33674.14","size":"0.00533"},{"price":"33699.21","size":"0"}],"bid":[{"price":"31114.50","size":"0"}],"sequence":7211240,"timestamp":"2021-07-03T00:56:34.845Z","symbol":"BTCPAX"}}
1625273794.935856: {"jsonrpc":"2.0","method":"updateOrderbook","params":{"ask":[{"price":"0.07652","size":"0"}],"bid":[],"sequence":7339963,"timestamp":"2021-07-03T00:56:34.847Z","symbol":"MKRBTC"}}
1625273794.9573078: {"jsonrpc":"2.0","method":"updateOrderbook","params":{"ask":[{"price":"33520.65","size":"0.01233"},{"price":"33520.96","size":"0"}],"bid":[],"sequence":7476956,"timestamp":"2021-07-03T00:56:34.826Z","symbol":"BTCTUSD"}}
1625273795.030302: {"jsonrpc":"2.0","method":"updateOrderbook","params":{"ask":[{"price":"33550.37","size":"0.02460"},{"price":"33550.67","size":"0"}],"bid":[{"price":"33539.39","size":"0"},{"price":"33538.27","size":"0.77340"},{"price":"33534.96","size":"1.43690"},{"price":"33534.37","size":"0"},{"price":"33527.85","size":"0.94240"},{"price":"33523.76","size":"0"}],"sequence":12626745,"timestamp":"2021-07-03T00:56:34.942Z","symbol":"BTCUSDB"}}
1625273795.030451: {"jsonrpc":"2.0","method":"updateOrderbook","params":{"ask":[{"price":"0.00011580","size":"766.46"},{"price":"0.00011582","size":"120.44"},{"price":"0.00090479","size":"0"},{"price":"0.00090757","size":"86093.30"}],"bid":[],"sequence":12351753,"timestamp":"2021-07-03T00:56:34.936Z","symbol":"EOSBTC"}}
1625273795.030484: {"jsonrpc":"2.0","method":"updateOrderbook","params":{"ask":[{"price":"33655.85","size":"0"},{"price":"33661.80","size":"0.00533"},{"price":"33664.24","size":"0"},{"price":"33670.22","size":"0.00533"},{"price":"33674.14","size":"0"},{"price":"33702.36","size":"0.00533"}],"bid":[{"price":"31215.04","size":"0.00260"}],"sequence":7211241,"timestamp":"2021-07-03T00:56:34.895Z","symbol":"BTCPAX"}}
1625273795.0334039: {"jsonrpc":"2.0","method":"updateOrderbook","params":{"ask":[{"price":"33520.65","size":"0"},{"price":"33520.86","size":"0.01233"}],"bid":[],"sequence":7476957,"timestamp":"2021-07-03T00:56:34.923Z","symbol":"BTCTUSD"}}
1625273795.136021: {"jsonrpc":"2.0","method":"updateOrderbook","params":{"ask":[{"price":"0.00011719","size":"0"},{"price":"0.00011981","size":"4513.55"}],"bid":[],"sequence":12351754,"timestamp":"2021-07-03T00:56:34.981Z","symbol":"EOSBTC"}}
1625273795.1360672: {"jsonrpc":"2.0","method":"updateOrderbook","params":{"ask":[{"price":"33550.22","size":"0.02460"},{"price":"33550.37","size":"0"},{"price":"33564.95","size":"0.91740"},{"price":"33566.57","size":"0"},{"price":"167670.03","size":"0.00014"},{"price":"167670.65","size":"0"}],"bid":[{"price":"33527.85","size":"0"},{"price":"33527.23","size":"0.94240"},{"price":"33502.47","size":"0"},{"price":"33498.85","size":"1.81560"},{"price":"33497.38","size":"0"},{"price":"33495.57","size":"1.43690"},{"price":"33493.01","size":"0"},{"price":"33490.80","size":"1.03296"},{"price":"33488.19","size":"1.31900"},{"price":"10060.23","size":"0"},{"price":"10060.20","size":"0.00013"}],"sequence":12626746,"timestamp":"2021-07-03T00:56:35.016Z","symbol":"BTCUSDB"}}
1625273795.13616: {"jsonrpc":"2.0","method":"updateOrderbook","params":{"ask":[{"price":"33520.44","size":"0.01233"},{"price":"33520.86","size":"0"}],"bid":[],"sequence":7476958,"timestamp":"2021-07-03T00:56:34.954Z","symbol":"BTCTUSD"}}
1625273795.224705: {"jsonrpc":"2.0","method":"updateOrderbook","params":{"ask":[{"price":"33550.16","size":"0.02460"},{"price":"33550.22","size":"0"}],"bid":[{"price":"33542.04","size":"0"},{"price":"33540.35","size":"0.05460"},{"price":"33527.89","size":"0.94240"},{"price":"33527.23","size":"0"},{"price":"33503.83","size":"0"},{"price":"33499.22","size":"0.77340"},{"price":"33487.99","size":"2.64430"},{"price":"33483.68","size":"0"},{"price":"33467.71","size":"1.04000"},{"price":"33459.84","size":"0"}],"sequence":12626747,"timestamp":"2021-07-03T00:56:35.077Z","symbol":"BTCUSDB"}}
1625273795.224798: {"jsonrpc":"2.0","method":"updateOrderbook","params":{"ask":[{"price":"0.00011598","size":"88.49"},{"price":"0.00011608","size":"345.13"},{"price":"0.00011893","size":"6250.68"},{"price":"0.00011915","size":"0"}],"bid":[{"price":"0.00011473","size":"4559.60"},{"price":"0.00011458","size":"0"},{"price":"0.00010884","size":"0"}],"sequence":12351755,"timestamp":"2021-07-03T00:56:35.125Z","symbol":"EOSBTC"}}
1625273795.334935: {"jsonrpc":"2.0","method":"updateOrderbook","params":{"ask":[{"price":"33553.15","size":"0.05940"},{"price":"33554.77","size":"0"},{"price":"33558.47","size":"0.45140"},{"price":"33562.64","size":"0"}],"bid":[],"sequence":12626748,"timestamp":"2021-07-03T00:56:35.246Z","symbol":"BTCUSDB"}}
1625273795.3408058: {"jsonrpc":"2.0","method":"updateOrderbook","params":{"ask":[{"price":"0.00090757","size":"0"},{"price":"0.00091166","size":"86093.30"}],"bid":[],"sequence":12351756,"timestamp":"2021-07-03T00:56:35.244Z","symbol":"EOSBTC"}}
1625273795.340863: {"jsonrpc":"2.0","method":"updateOrderbook","params":{"ask":[{"price":"0.07660","size":"2.1638"},{"price":"0.07665","size":"0"}],"bid":[],"sequence":7339964,"timestamp":"2021-07-03T00:56:35.187Z","symbol":"MKRBTC"}}
1625273795.340886: {"jsonrpc":"2.0","method":"updateOrderbook","params":{"ask":[],"bid":[{"price":"32934.06","size":"1.37100"},{"price":"32854.37","size":"0"},{"price":"32466.45","size":"1.67560"},{"price":"32116.39","size":"0"}],"sequence":7476959,"timestamp":"2021-07-03T00:56:35.202Z","symbol":"BTCTUSD"}}
1625273795.430028: {"jsonrpc":"2.0","method":"updateOrderbook","params":{"ask":[],"bid":[{"price":"33526.17","size":"1.10595"},{"price":"33520.26","size":"0"}],"sequence":12626749,"timestamp":"2021-07-03T00:56:35.335Z","symbol":"BTCUSDB"}}
1625273795.4300869: {"jsonrpc":"2.0","method":"updateOrderbook","params":{"ask":[{"price":"0.00014656","size":"5718.01"},{"price":"0.00015673","size":"1.00"},{"price":"0.00015869","size":"19505.60"},{"price":"0.00015959","size":"0"},{"price":"0.00016859","size":"7220.48"},{"price":"0.00017562","size":"0"},{"price":"0.00023292","size":"30396.48"},{"price":"0.00023458","size":"0"}],"bid":[],"sequence":12351757,"timestamp":"2021-07-03T00:56:35.330Z","symbol":"EOSBTC"}}
1625273795.432665: {"jsonrpc":"2.0","method":"updateOrderbook","params":{"ask":[],"bid":[{"price":"0.07582","size":"0"},{"price":"0.07575","size":"3.7316"}],"sequence":7339965,"timestamp":"2021-07-03T00:56:35.302Z","symbol":"MKRBTC"}}
1625273795.536733: {"jsonrpc":"2.0","method":"updateOrderbook","params":{"ask":[{"price":"33589.71","size":"0.75370"},{"price":"33593.59","size":"0"}],"bid":[{"price":"33518.23","size":"0.77390"},{"price":"33515.23","size":"1.37123"}],"sequence":12626750,"timestamp":"2021-07-03T00:56:35.441Z","symbol":"BTCUSDB"}}
1625273795.5367942: {"jsonrpc":"2.0","method":"updateOrderbook","params":{"ask":[{"price":"33660.83","size":"0.00533"},{"price":"33661.80","size":"0"}],"bid":[],"sequence":7211242,"timestamp":"2021-07-03T00:56:35.389Z","symbol":"BTCPAX"}}
1625273795.536818: {"jsonrpc":"2.0","method":"updateOrderbook","params":{"ask":[],"bid":[{"price":"0.07583","size":"0.0013"}],"sequence":7339966,"timestamp":"2021-07-03T00:56:35.407Z","symbol":"MKRBTC"}}
1625273795.5368361: {"jsonrpc":"2.0","method":"updateOrderbook","params":{"ask":[{"price":"33519.66","size":"0.01233"},{"price":"33520.44","size":"0"}],"bid":[],"sequence":7476960,"timestamp":"2021-07-03T00:56:35.355Z","symbol":"BTCTUSD"}}
1625273795.62603: {"jsonrpc":"2.0","method":"updateOrderbook","params":{"ask":[{"price":"0.00074926","size":"42091.73"},{"price":"0.00075744","size":"0"}],"bid":[],"sequence":12351758,"timestamp":"2021-07-03T00:56:35.534Z","symbol":"EOSBTC"}}
1625273795.628225: {"jsonrpc":"2.0","method":"updateOrderbook","params":{"ask":[{"price":"0.07652","size":"0.0055"}],"bid":[],"sequence":7339967,"timestamp":"2021-07-03T00:56:35.540Z","symbol":"MKRBTC"}}
1625273795.628263: {"jsonrpc":"2.0","method":"updateOrderbook","params":{"ask":[{"price":"33522.80","size":"0.02979"},{"price":"33524.14","size":"0"}],"bid":[{"price":"30708.78","size":"1.39725"},{"price":"30531.12","size":"0"}],"sequence":7476961,"timestamp":"2021-07-03T00:56:35.506Z","symbol":"BTCTUSD"}}
1625273795.7285042: {"jsonrpc":"2.0","method":"updateOrderbook","params":{"ask":[],"bid":[{"price":"33539.27","size":"0.77340"},{"price":"33538.27","size":"0"}],"sequence":12626751,"timestamp":"2021-07-03T00:56:35.569Z","symbol":"BTCUSDB"}}
1625273795.7285619: {"jsonrpc":"2.0","method":"updateOrderbook","params":{"ask":[{"price":"0.00091166","size":"0"},{"price":"0.00092098","size":"86093.30"}],"bid":[{"price":"0.00011547","size":"2666.32"},{"price":"0.00011537","size":"0"},{"price":"0.00011024","size":"7497.84"},{"price":"0.00010813","size":"0"}],"sequence":12351759,"timestamp":"2021-07-03T00:56:35.600Z","symbol":"EOSBTC"}}
1625273795.7345312: {"jsonrpc":"2.0","method":"updateOrderbook","params":{"ask":[{"price":"33519.35","size":"0.01233"},{"price":"33519.66","size":"0"}],"bid":[],"sequence":7476962,"timestamp":"2021-07-03T00:56:35.554Z","symbol":"BTCTUSD"}}
1625273795.851808: {"jsonrpc":"2.0","method":"updateOrderbook","params":{"ask":[],"bid":[{"price":"33527.89","size":"0"},{"price":"33527.02","size":"1.06180"},{"price":"33526.17","size":"0"},{"price":"33524.55","size":"1.10595"},{"price":"33391.49","size":"0.54822"},{"price":"33377.46","size":"0"},{"price":"33370.35","size":"0.68851"},{"price":"33360.20","size":"0"},{"price":"33180.73","size":"1.46061"},{"price":"33166.83","size":"0"}],"sequence":12626752,"timestamp":"2021-07-03T00:56:35.710Z","symbol":"BTCUSDB"}}
1625273795.8518772: {"jsonrpc":"2.0","method":"updateOrderbook","params":{"ask":[{"price":"33518.21","size":"0.01233"},{"price":"33519.35","size":"0"},{"price":"33521.11","size":"0.02979"},{"price":"33522.80","size":"0"}],"bid":[],"sequence":7476963,"timestamp":"2021-07-03T00:56:35.721Z","symbol":"BTCTUSD"}}
1625273795.9279208: {"jsonrpc":"2.0","method":"updateOrderbook","params":{"ask":[{"price":"0.00011579","size":"223.04"},{"price":"0.00011580","size":"642.42"},{"price":"0.00018801","size":"10554.74"},{"price":"0.00019132","size":"0"},{"price":"0.00022196","size":"15617.57"},{"price":"0.00023030","size":"2.00"}],"bid":[],"sequence":12351760,"timestamp":"2021-07-03T00:56:35.813Z","symbol":"EOSBTC"}}
1625273795.927937: {"jsonrpc":"2.0","method":"updateOrderbook","params":{"ask":[{"price":"33660.83","size":"0"},{"price":"33661.60","size":"0.00533"}],"bid":[],"sequence":7211243,"timestamp":"2021-07-03T00:56:35.851Z","symbol":"BTCPAX"}}
1625273795.940138: {"jsonrpc":"2.0","method":"updateOrderbook","params":{"ask":[{"price":"33518.21","size":"0"},{"price":"33518.74","size":"0.01233"}],"bid":[],"sequence":7476964,"timestamp":"2021-07-03T00:56:35.851Z","symbol":"BTCTUSD"}}
1625273796.031499: {"jsonrpc":"2.0","method":"updateOrderbook","params":{"ask":[],"bid":[{"price":"33539.27","size":"0"},{"price":"33538.44","size":"0.77340"}],"sequence":12626753,"timestamp":"2021-07-03T00:56:35.922Z","symbol":"BTCUSDB"}}
1625273796.031539: {"jsonrpc":"2.0","method":"updateOrderbook","params":{"ask":[{"price":"33518.74","size":"0"},{"price":"33519.00","size":"0.01233"}],"bid":[],"sequence":7476965,"timestamp":"2021-07-03T00:56:35.856Z","symbol":"BTCTUSD"}}
1625273796.031598: {"jsonrpc":"2.0","method":"updateOrderbook","params":{"ask":[{"price":"0.09593","size":"3.7522"},{"price":"0.09716","size":"0"}],"bid":[],"sequence":7339968,"timestamp":"2021-07-03T00:56:35.884Z","symbol":"MKRBTC"}}
1625273796.1276958: {"jsonrpc":"2.0","method":"updateOrderbook","params":{"ask":[{"price":"33552.91","size":"0.74140"},{"price":"33557.99","size":"0"},{"price":"33558.39","size":"0"},{"price":"167667.30","size":"0.00019"},{"price":"167670.03","size":"0"}],"bid":[{"price":"10060.20","size":"0"},{"price":"10060.03","size":"0.00015"}],"sequence":12626754,"timestamp":"2021-07-03T00:56:36.005Z","symbol":"BTCUSDB"}}
1625273796.3285801: {"jsonrpc":"2.0","method":"updateOrderbook","params":{"ask":[],"bid":[{"price":"33527.88","size":"0.94240"},{"price":"33527.02","size":"0.11940"},{"price":"33526.15","size":"1.10595"},{"price":"33524.55","size":"0"}],"sequence":12626755,"timestamp":"2021-07-03T00:56:36.229Z","symbol":"BTCUSDB"}}
1625273796.328639: {"jsonrpc":"2.0","method":"updateOrderbook","params":{"ask":[{"price":"0.09593","size":"0"},{"price":"0.09700","size":"3.7522"}],"bid":[],"sequence":7339969,"timestamp":"2021-07-03T00:56:36.248Z","symbol":"MKRBTC"}}
1625273796.429326: {"jsonrpc":"2.0","method":"updateOrderbook","params":{"ask":[{"price":"34010.34","size":"1.76840"},{"price":"34106.27","size":"0"}],"bid":[],"sequence":7476966,"timestamp":"2021-07-03T00:56:36.262Z","symbol":"BTCTUSD"}}
1625273796.527191: {"jsonrpc":"2.0","method":"updateOrderbook","params":{"ask":[{"price":"0.00026765","size":"21530.31"},{"price":"0.00027115","size":"0"}],"bid":[{"price":"0.00011419","size":"5810.54"},{"price":"0.00010909","size":"0"}],"sequence":12351761,"timestamp":"2021-07-03T00:56:36.434Z","symbol":"EOSBTC"}}
1625273796.53302: {"jsonrpc":"2.0","method":"updateOrderbook","params":{"ask":[{"price":"0.09700","size":"0"},{"price":"0.10064","size":"3.7522"},{"price":"0.24215","size":"0"},{"price":"0.29757","size":"4.2976"}],"bid":[],"sequence":7339970,"timestamp":"2021-07-03T00:56:36.399Z","symbol":"MKRBTC"}}
1625273796.629612: {"jsonrpc":"2.0","method":"updateOrderbook","params":{"ask":[],"bid":[{"price":"33538.44","size":"0"},{"price":"33537.53","size":"0.77340"},{"price":"33527.88","size":"0"},{"price":"33527.29","size":"0.94240"},{"price":"33526.15","size":"0"},{"price":"33525.45","size":"1.10595"}],"sequence":12626756,"timestamp":"2021-07-03T00:56:36.548Z","symbol":"BTCUSDB"}}
1625273796.6296802: {"jsonrpc":"2.0","method":"updateOrderbook","params":{"ask":[{"price":"0.00013224","size":"22588.08"},{"price":"0.00014537","size":"0"},{"price":"0.00015573","size":"26975.46"},{"price":"0.00023878","size":"0"}],"bid":[{"price":"0.00011493","size":"0"},{"price":"0.00011476","size":"8378.72"},{"price":"0.00011449","size":"0"},{"price":"0.00011422","size":"16444.03"},{"price":"0.00010401","size":"0"},{"price":"0.00010324","size":"23147.93"},{"price":"0.00008994","size":"0"},{"price":"0.00008843","size":"22326.00"}],"sequence":12351762,"timestamp":"2021-07-03T00:56:36.495Z","symbol":"EOSBTC"}}
1625273796.7255611: {"jsonrpc":"2.0","method":"updateOrderbook","params":{"ask":[{"price":"33552.91","size":"1.78092"},{"price":"33557.57","size":"0"}],"bid":[],"sequence":12626757,"timestamp":"2021-07-03T00:56:36.651Z","symbol":"BTCUSDB"}}
1625273796.736543: {"jsonrpc":"2.0","method":"updateOrderbook","params":{"ask":[{"price":"0.00012173","size":"16338.72"},{"price":"0.00012228","size":"0"},{"price":"0.00014656","size":"0"},{"price":"0.00015103","size":"12447.66"},{"price":"0.00016859","size":"0"},{"price":"0.00017108","size":"7220.48"},{"price":"0.00018801","size":"0"},{"price":"0.00018893","size":"10554.74"},{"price":"0.00022196","size":"0"},{"price":"0.00022493","size":"15617.57"},{"price":"0.00026765","size":"0"},{"price":"0.00026863","size":"21530.31"}],"bid":[],"sequence":12351763,"timestamp":"2021-07-03T00:56:36.645Z","symbol":"EOSBTC"}}
1625273796.737885: {"jsonrpc":"2.0","method":"updateOrderbook","params":{"ask":[{"price":"35529.35","size":"1.29584"},{"price":"35888.15","size":"0"}],"bid":[],"sequence":7476967,"timestamp":"2021-07-03T00:56:36.566Z","symbol":"BTCTUSD"}}
1625273796.8361511: {"jsonrpc":"2.0","method":"updateOrderbook","params":{"ask":[],"bid":[{"price":"33527.86","size":"0.94240"},{"price":"33527.29","size":"0"},{"price":"33526.04","size":"1.10595"},{"price":"33525.45","size":"0"}],"sequence":12626758,"timestamp":"2021-07-03T00:56:36.660Z","symbol":"BTCUSDB"}}
1625273796.8362129: {"jsonrpc":"2.0","method":"updateOrderbook","params":{"ask":[{"price":"0.00011626","size":"1100.00"},{"price":"0.00011628","size":"6284.09"},{"price":"0.00011679","size":"0"},{"price":"0.00011693","size":"3273.50"},{"price":"0.00011981","size":"0"},{"price":"0.00012737","size":"4513.55"},{"price":"0.00015103","size":"6729.65"},{"price":"0.00015741","size":"5718.01"},{"price":"0.00017108","size":"0"},{"price":"0.00017621","size":"7220.48"},{"price":"0.00018893","size":"0"},{"price":"0.00019167","size":"10554.74"},{"price":"0.00022493","size":"0"},{"price":"0.00023114","size":"15617.57"},{"price":"0.00026863","size":"0"},{"price":"0.00027148","size":"21530.31"},{"price":"0.00074926","size":"0"},{"price":"0.00074971","size":"42091.73"}],"bid":[],"sequence":12351764,"timestamp":"2021-07-03T00:56:36.749Z","symbol":"EOSBTC"}}
1625273796.836257: {"jsonrpc":"2.0","method":"updateOrderbook","params":{"ask":[{"price":"33608.42","size":"0.18170"},{"price":"33627.22","size":"0"}],"bid":[],"sequence":7476968,"timestamp":"2021-07-03T00:56:36.671Z","symbol":"BTCTUSD"}}
1625273796.92826: {"jsonrpc":"2.0","method":"updateOrderbook","params":{"ask":[{"price":"33598.16","size":"0"},{"price":"33606.52","size":"0.94720"},{"price":"33607.48","size":"0"},{"price":"33613.36","size":"1.07210"},{"price":"33623.77","size":"0"},{"price":"33630.19","size":"0"},{"price":"33633.93","size":"1.29870"},{"price":"33643.30","size":"0.71880"},{"price":"33726.33","size":"0.77520"},{"price":"33745.81","size":"0"}],"bid":[],"sequence":12626759,"timestamp":"2021-07-03T00:56:36.821Z","symbol":"BTCUSDB"}}
1625273796.9282932: {"jsonrpc":"2.0","method":"updateOrderbook","params":{"ask":[{"price":"0.00011579","size":"99.00"},{"price":"0.00011580","size":"354.04"},{"price":"0.00011581","size":"1408.27"},{"price":"0.00011598","size":"0"},{"price":"0.00011608","size":"433.62"},{"price":"0.00012076","size":"0"},{"price":"0.00012101","size":"27581.23"},{"price":"0.00012173","size":"0"},{"price":"0.00012212","size":"16338.72"},{"price":"0.00013944","size":"0"},{"price":"0.00013989","size":"53527.30"},{"price":"0.00015869","size":"0"},{"price":"0.00015931","size":"19505.60"},{"price":"0.00023292","size":"0"},{"price":"0.00023405","size":"30396.48"},{"price":"0.00024106","size":"39545.26"},{"price":"0.00028015","size":"0"},{"price":"0.00034161","size":"56176.40"},{"price":"0.00046654","size":"0"},{"price":"0.00074971","size":"0"},{"price":"0.00075484","size":"42091.73"}],"bid":[],"sequence":12351765,"timestamp":"2021-07-03T00:56:36.849Z","symbol":"EOSBTC"}}
1625273797.031899: {"jsonrpc":"2.0","method":"updateOrderbook","params":{"ask":[{"price":"0.00012212","size":"0"},{"price":"0.00012270","size":"16338.72"},{"price":"0.00015931","size":"0"},{"price":"0.00016019","size":"19505.60"},{"price":"0.00023405","size":"0"},{"price":"0.00023569","size":"30396.48"},{"price":"0.00075484","size":"0"},{"price":"0.00076289","size":"42091.73"}],"bid":[],"sequence":12351766,"timestamp":"2021-07-03T00:56:36.872Z","symbol":"EOSBTC"}}
1625273797.0319638: {"jsonrpc":"2.0","method":"updateOrderbook","params":{"ask":[{"price":"35021.47","size":"1.84720"},{"price":"35115.28","size":"0"}],"bid":[],"sequence":7211244,"timestamp":"2021-07-03T00:56:36.893Z","symbol":"BTCPAX"}}
1625273797.125961: {"jsonrpc":"2.0","method":"updateOrderbook","params":{"ask":[{"price":"167667.30","size":"0.00014"}],"bid":[{"price":"10060.03","size":"0.00018"}],"sequence":12626760,"timestamp":"2021-07-03T00:56:37.029Z","symbol":"BTCUSDB"}}
1625273797.228467: {"jsonrpc":"2.0","method":"updateOrderbook","params":{"ask":[{"price":"33589.71","size":"0"},{"price":"33593.59","size":"0.75370"}],"bid":[{"price":"33526.04","size":"0"},{"price":"33525.39","size":"1.10595"}],"sequence":12626761,"timestamp":"2021-07-03T00:56:37.114Z","symbol":"BTCUSDB"}}
1625273797.228524: {"jsonrpc":"2.0","method":"updateOrderbook","params":{"ask":[{"price":"0.00011579","size":"0"},{"price":"0.00011580","size":"329.00"},{"price":"0.00011581","size":"0"},{"price":"0.00011582","size":"656.90"},{"price":"0.00011583","size":"2723.32"}],"bid":[],"sequence":12351767,"timestamp":"2021-07-03T00:56:37.106Z","symbol":"EOSBTC"}}
1625273797.323982: {"jsonrpc":"2.0","method":"updateOrderbook","params":{"ask":[],"bid":[{"price":"33545.42","size":"0"},{"price":"33544.42","size":"0.02940"},{"price":"33539.57","size":"0.77340"},{"price":"33537.53","size":"0"}],"sequence":12626762,"timestamp":"2021-07-03T00:56:37.225Z","symbol":"BTCUSDB"}}
1625273797.324042: {"jsonrpc":"2.0","method":"updateOrderbook","params":{"ask":[{"price":"0.00011580","size":"230.00"},{"price":"0.00011581","size":"99.00"}],"bid":[],"sequence":12351768,"timestamp":"2021-07-03T00:56:37.238Z","symbol":"EOSBTC"}}
1625273797.425589: {"jsonrpc":"2.0","method":"updateOrderbook","params":{"ask":[],"bid":[{"price":"33526.34","size":"1.10595"},{"price":"33525.39","size":"0"}],"sequence":12626763,"timestamp":"2021-07-03T00:56:37.297Z","symbol":"BTCUSDB"}}
1625273797.527594: {"jsonrpc":"2.0","method":"updateOrderbook","params":{"ask":[],"bid":[{"price":"33545.21","size":"0.02940"},{"price":"33544.42","size":"0"}],"sequence":12626764,"timestamp":"2021-07-03T00:56:37.360Z","symbol":"BTCUSDB"}}
1625273797.527651: {"jsonrpc":"2.0","method":"updateOrderbook","params":{"ask":[{"price":"0.00011581","size":"223.04"},{"price":"0.00011582","size":"532.86"}],"bid":[],"sequence":12351769,"timestamp":"2021-07-03T00:56:37.373Z","symbol":"EOSBTC"}}
1625273797.641099: {"jsonrpc":"2.0","method":"updateOrderbook","params":{"ask":[{"price":"33585.03","size":"0"},{"price":"33590.81","size":"0.95910"},{"price":"33604.30","size":"0"},{"price":"33616.52","size":"1.06920"}],"bid":[{"price":"33539.57","size":"0"},{"price":"33538.78","size":"0.77340"},{"price":"33527.86","size":"0"},{"price":"33527.27","size":"0.94240"},{"price":"33526.34","size":"0"},{"price":"33525.59","size":"1.10595"}],"sequence":12626765,"timestamp":"2021-07-03T00:56:37.470Z","symbol":"BTCUSDB"}}
1625273797.641166: {"jsonrpc":"2.0","method":"updateOrderbook","params":{"ask":[],"bid":[{"price":"0.07581","size":"2.6761"},{"price":"0.07575","size":"1.0555"}],"sequence":7339971,"timestamp":"2021-07-03T00:56:37.495Z","symbol":"MKRBTC"}}
1625273797.641192: {"jsonrpc":"2.0","method":"updateOrderbook","params":{"ask":[],"bid":[{"price":"33498.95","size":"0"},{"price":"33496.43","size":"0.01474"},{"price":"32466.45","size":"0"},{"price":"32358.87","size":"1.67560"},{"price":"30708.78","size":"0"},{"price":"30631.58","size":"1.39725"}],"sequence":7476969,"timestamp":"2021-07-03T00:56:37.545Z","symbol":"BTCTUSD"}}
1625273797.7316082: {"jsonrpc":"2.0","method":"updateOrderbook","params":{"ask":[{"price":"33613.59","size":"0.09820"},{"price":"33620.39","size":"0"}],"bid":[],"sequence":12626766,"timestamp":"2021-07-03T00:56:37.554Z","symbol":"BTCUSDB"}}
1625273797.731665: {"jsonrpc":"2.0","method":"updateOrderbook","params":{"ask":[{"price":"0.00011580","size":"329.00"},{"price":"0.00011581","size":"124.04"}],"bid":[],"sequence":12351770,"timestamp":"2021-07-03T00:56:37.604Z","symbol":"EOSBTC"}}
1625273797.927736: {"jsonrpc":"2.0","method":"updateOrderbook","params":{"ask":[{"price":"33698.98","size":"1.25250"},{"price":"33719.09","size":"0"}],"bid":[],"sequence":12626767,"timestamp":"2021-07-03T00:56:37.824Z","symbol":"BTCUSDB"}}
1625273797.927776: {"jsonrpc":"2.0","method":"updateOrderbook","params":{"ask":[{"price":"0.00011581","size":"412.42"},{"price":"0.00011582","size":"244.48"}],"bid":[],"sequence":12351771,"timestamp":"2021-07-03T00:56:37.809Z","symbol":"EOSBTC"}}
1625273797.927791: {"jsonrpc":"2.0","method":"updateOrderbook","params":{"ask":[{"price":"35021.47","size":"0"},{"price":"35115.28","size":"1.84720"}],"bid":[],"sequence":7211245,"timestamp":"2021-07-03T00:56:37.793Z","symbol":"BTCPAX"}}
1625273797.9278028: {"jsonrpc":"2.0","method":"updateOrderbook","params":{"ask":[{"price":"35529.35","size":"0"},{"price":"35636.47","size":"1.29584"}],"bid":[],"sequence":7476970,"timestamp":"2021-07-03T00:56:37.799Z","symbol":"BTCTUSD"}}
1625273798.025153: {"jsonrpc":"2.0","method":"updateOrderbook","params":{"ask":[],"bid":[{"price":"33527.09","size":"0.09211"},{"price":"33526.95","size":"0"}],"sequence":5708315,"timestamp":"2021-07-03T00:56:37.941Z","symbol":"BTCDAI"}}
1625273798.029279: {"jsonrpc":"2.0","method":"updateOrderbook","params":{"ask":[],"bid":[{"price":"33545.21","size":"0"},{"price":"33544.10","size":"0.02940"}],"sequence":12626768,"timestamp":"2021-07-03T00:56:37.933Z","symbol":"BTCUSDB"}}
1625273798.0292952: {"jsonrpc":"2.0","method":"updateOrderbook","params":{"ask":[{"price":"0.00011580","size":"230.00"},{"price":"0.00011581","size":"99.00"},{"price":"0.00011582","size":"656.90"},{"price":"0.00034161","size":"0"},{"price":"0.00034205","size":"56176.40"}],"bid":[],"sequence":12351772,"timestamp":"2021-07-03T00:56:37.934Z","symbol":"EOSBTC"}}
1625273798.029307: {"jsonrpc":"2.0","method":"updateOrderbook","params":{"ask":[{"price":"33661.60","size":"0"},{"price":"33670.22","size":"0"},{"price":"33678.51","size":"0.00533"},{"price":"33686.68","size":"0.00533"},{"price":"33702.36","size":"0"},{"price":"33717.29","size":"0.00533"}],"bid":[],"sequence":7211246,"timestamp":"2021-07-03T00:56:37.932Z","symbol":"BTCPAX"}}
1625273798.0293188: {"jsonrpc":"2.0","method":"updateOrderbook","params":{"ask":[{"price":"33519.00","size":"0"},{"price":"33520.88","size":"0.01233"},{"price":"33521.11","size":"0"},{"price":"33523.91","size":"0.02979"}],"bid":[],"sequence":7476971,"timestamp":"2021-07-03T00:56:37.932Z","symbol":"BTCTUSD"}}
1625273798.128479: {"jsonrpc":"2.0","method":"updateOrderbook","params":{"ask":[],"bid":[{"price":"33528.82","size":"0.09211"},{"price":"33527.09","size":"0"}],"sequence":5708316,"timestamp":"2021-07-03T00:56:37.981Z","symbol":"BTCDAI"}}
1625273798.129149: {"jsonrpc":"2.0","method":"updateOrderbook","params":{"ask":[{"price":"33553.15","size":"0"},{"price":"33554.06","size":"0.05940"}],"bid":[{"price":"33544.10","size":"0"},{"price":"33543.91","size":"0.02940"},{"price":"33540.35","size":"0"},{"price":"33538.78","size":"0"},{"price":"33538.75","size":"0.05460"},{"price":"33537.88","size":"0.77340"},{"price":"33535.51","size":"0"},{"price":"33534.97","size":"1.81560"},{"price":"33534.96","size":"0"},{"price":"33533.39","size":"1.43690"},{"price":"33527.27","size":"0"},{"price":"33525.59","size":"0"},{"price":"33524.41","size":"0.94240"},{"price":"33522.86","size":"1.10595"},{"price":"33518.23","size":"0"},{"price":"33515.30","size":"0.77390"}],"sequence":12626769,"timestamp":"2021-07-03T00:56:38.048Z","symbol":"BTCUSDB"}}
1625273798.129208: {"jsonrpc":"2.0","method":"updateOrderbook","params":{"ask":[],"bid":[{"price":"0.00011567","size":"210.31"},{"price":"0.00011566","size":"174.93"}],"sequence":12351773,"timestamp":"2021-07-03T00:56:38.014Z","symbol":"EOSBTC"}}
1625273798.129233: {"jsonrpc":"2.0","method":"updateOrderbook","params":{"ask":[{"price":"33520.48","size":"0.01233"},{"price":"33520.88","size":"0"}],"bid":[],"sequence":7476972,"timestamp":"2021-07-03T00:56:38.014Z","symbol":"BTCTUSD"}}
1625273798.2394052: {"jsonrpc":"2.0","method":"updateOrderbook","params":{"ask":[{"price":"33550.94","size":"0.05940"},{"price":"33554.06","size":"0"},{"price":"33563.36","size":"0.91740"},{"price":"33564.95","size":"0"}],"bid":[{"price":"33543.91","size":"0"},{"price":"33542.97","size":"0.02940"},{"price":"33537.88","size":"0"},{"price":"33536.12","size":"0.77340"},{"price":"33525.04","size":"0.94240"},{"price":"33524.41","size":"0"},{"price":"33522.86","size":"0"},{"price":"33522.67","size":"1.10595"},{"price":"33505.12","size":"0.38210"},{"price":"33502.52","size":"0.96010"},{"price":"33501.08","size":"0"},{"price":"33500.56","size":"0.77340"},{"price":"33499.22","size":"0"},{"price":"33495.77","size":"0.94140"}],"sequence":12626770,"timestamp":"2021-07-03T00:56:38.141Z","symbol":"BTCUSDB"}}
1625273798.239476: {"jsonrpc":"2.0","method":"updateOrderbook","params":{"ask":[{"price":"0.00011581","size":"343.48"},{"price":"0.00011582","size":"412.42"},{"price":"0.00076289","size":"0"},{"price":"0.00076327","size":"42091.73"}],"bid":[],"sequence":12351774,"timestamp":"2021-07-03T00:56:38.151Z","symbol":"EOSBTC"}}
1625273798.2395039: {"jsonrpc":"2.0","method":"updateOrderbook","params":{"ask":[{"price":"33520.48","size":"0"},{"price":"33521.30","size":"0.01233"}],"bid":[],"sequence":7476973,"timestamp":"2021-07-03T00:56:38.144Z","symbol":"BTCTUSD"}}
1625273798.3449678: {"jsonrpc":"2.0","method":"updateOrderbook","params":{"ask":[{"price":"33550.94","size":"0"},{"price":"33553.06","size":"0.05940"},{"price":"33574.90","size":"1.43490"},{"price":"33577.17","size":"0"},{"price":"33613.59","size":"0"},{"price":"33621.87","size":"0.09820"},{"price":"33687.23","size":"0"},{"price":"33698.98","size":"0"},{"price":"33703.36","size":"1.07700"},{"price":"33722.20","size":"1.25250"}],"bid":[{"price":"33542.97","size":"0"},{"price":"33541.81","size":"0"},{"price":"33541.34","size":"0.02940"},{"price":"33538.75","size":"0"},{"price":"33538.32","size":"0.38210"},{"price":"33536.12","size":"0"},{"price":"33535.25","size":"0.05460"},{"price":"33535.01","size":"0.77340"},{"price":"33533.39","size":"0"},{"price":"33532.07","size":"1.43690"},{"price":"33525.04","size":"0"},{"price":"33522.67","size":"0"},{"price":"33522.23","size":"0.94240"},{"price":"33519.65","size":"1.10595"}],"sequence":12626771,"timestamp":"2021-07-03T00:56:38.235Z","symbol":"BTCUSDB"}}
1625273798.345044: {"jsonrpc":"2.0","method":"updateOrderbook","params":{"ask":[{"price":"0.00011581","size":"223.04"},{"price":"0.00011582","size":"532.86"}],"bid":[],"sequence":12351775,"timestamp":"2021-07-03T00:56:38.154Z","symbol":"EOSBTC"}}
1625273798.3450701: {"jsonrpc":"2.0","method":"updateOrderbook","params":{"ask":[{"price":"33677.48","size":"0.00533"},{"price":"33678.51","size":"0"}],"bid":[],"sequence":7211247,"timestamp":"2021-07-03T00:56:38.183Z","symbol":"BTCPAX"}}
1625273798.345088: {"jsonrpc":"2.0","method":"updateOrderbook","params":{"ask":[{"price":"33520.25","size":"0.01233"},{"price":"33521.30","size":"0"}],"bid":[{"price":"33496.43","size":"0"},{"price":"33493.95","size":"0.01474"},{"price":"33370.71","size":"0"},{"price":"33337.60","size":"0.44090"},{"price":"33190.77","size":"0"},{"price":"33147.70","size":"0.87470"},{"price":"32934.06","size":"0"},{"price":"32888.38","size":"1.37100"},{"price":"32358.87","size":"0"},{"price":"32279.11","size":"1.67560"}],"sequence":7476974,"timestamp":"2021-07-03T00:56:38.223Z","symbol":"BTCTUSD"}}
1625273798.428044: {"jsonrpc":"2.0","method":"updateOrderbook","params":{"ask":[],"bid":[{"price":"33528.82","size":"0"},{"price":"33527.95","size":"0.09211"}],"sequence":5708317,"timestamp":"2021-07-03T00:56:38.340Z","symbol":"BTCDAI"}}
1625273798.443695: {"jsonrpc":"2.0","method":"updateOrderbook","params":{"ask":[{"price":"33550.10","size":"0.05940"},{"price":"33553.06","size":"0"},{"price":"33559.23","size":"0.10260"},{"price":"33565.52","size":"0"},{"price":"33592.14","size":"1.17130"},{"price":"33598.29","size":"0"},{"price":"33599.67","size":"0.94720"},{"price":"33606.52","size":"0"}],"bid":[{"price":"33534.97","size":"0"},{"price":"33534.00","size":"1.81560"},{"price":"33532.07","size":"0"},{"price":"33531.33","size":"1.43690"},{"price":"33515.23","size":"0"},{"price":"33512.23","size":"1.37123"},{"price":"33510.36","size":"0"},{"price":"33509.22","size":"0.64790"}],"sequence":12626772,"timestamp":"2021-07-03T00:56:38.346Z","symbol":"BTCUSDB"}}
1625273798.443746: {"jsonrpc":"2.0","method":"updateOrderbook","params":{"ask":[{"price":"33519.82","size":"0.01233"},{"price":"33520.25","size":"0"},{"price":"34010.34","size":"0"},{"price":"34075.20","size":"1.76840"},{"price":"35636.47","size":"0"},{"price":"35758.21","size":"1.29584"}],"bid":[{"price":"33496.18","size":"0.01474"},{"price":"33495.52","size":"0"},{"price":"33493.95","size":"0"},{"price":"33490.92","size":"0.02738"}],"sequence":7476975,"timestamp":"2021-07-03T00:56:38.300Z","symbol":"BTCTUSD"}}
1625273798.523642: {"jsonrpc":"2.0","method":"updateOrderbook","params":{"ask":[{"price":"33550.19","size":"0.07707"},{"price":"33558.05","size":"0"},{"price":"33560.26","size":"0.01062"},{"price":"33570.52","size":"0"}],"bid":[],"sequence":5708318,"timestamp":"2021-07-03T00:56:38.394Z","symbol":"BTCDAI"}}
1625273798.52938: {"jsonrpc":"2.0","method":"updateOrderbook","params":{"ask":[{"price":"33582.88","size":"0.79591"},{"price":"33585.97","size":"0"}],"bid":[{"price":"33505.12","size":"0"},{"price":"33502.52","size":"0"},{"price":"33501.66","size":"0.38210"},{"price":"33501.27","size":"0.96010"},{"price":"33495.57","size":"0"},{"price":"33490.63","size":"1.43690"}],"sequence":12626773,"timestamp":"2021-07-03T00:56:38.372Z","symbol":"BTCUSDB"}}
1625273798.529394: {"jsonrpc":"2.0","method":"updateOrderbook","params":{"ask":[{"price":"0.00011580","size":"329.00"},{"price":"0.00011581","size":"124.04"},{"price":"0.00024106","size":"0"},{"price":"0.00024131","size":"39545.26"}],"bid":[],"sequence":12351776,"timestamp":"2021-07-03T00:56:38.402Z","symbol":"EOSBTC"}}
1625273798.529401: {"jsonrpc":"2.0","method":"updateOrderbook","params":{"ask":[{"price":"33677.48","size":"0"},{"price":"33679.25","size":"0.00533"}],"bid":[],"sequence":7211248,"timestamp":"2021-07-03T00:56:38.361Z","symbol":"BTCPAX"}}
1625273798.529407: {"jsonrpc":"2.0","method":"updateOrderbook","params":{"ask":[{"price":"33519.31","size":"0.01233"},{"price":"33519.82","size":"0"}],"bid":[],"sequence":7476976,"timestamp":"2021-07-03T00:56:38.378Z","symbol":"BTCTUSD"}}
1625273798.630235: {"jsonrpc":"2.0","method":"updateOrderbook","params":{"ask":[{"price":"33550.19","size":"0"},{"price":"33551.53","size":"0.07707"},{"price":"33555.28","size":"0.18610"},{"price":"33561.67","size":"0"}],"bid":[{"price":"33531.73","size":"0.09211"},{"price":"33528.52","size":"0.17106"},{"price":"33527.95","size":"0"},{"price":"33524.30","size":"0"}],"sequence":5708319,"timestamp":"2021-07-03T00:56:38.550Z","symbol":"BTCDAI"}}
1625273798.630367: {"jsonrpc":"2.0","method":"updateOrderbook","params":{"ask":[{"price":"33561.98","size":"2.47430"},{"price":"33567.90","size":"0"},{"price":"33568.69","size":"0.75370"},{"price":"33570.55","size":"0"},{"price":"33578.26","size":"0"}],"bid":[{"price":"33541.34","size":"0"},{"price":"33540.76","size":"0.02940"},{"price":"33531.33","size":"0"},{"price":"33529.05","size":"1.43690"},{"price":"33522.23","size":"0"},{"price":"33520.43","size":"0.94240"},{"price":"33520.24","size":"1.10595"},{"price":"33519.65","size":"0"}],"sequence":12626774,"timestamp":"2021-07-03T00:56:38.540Z","symbol":"BTCUSDB"}}
1625273798.630403: {"jsonrpc":"2.0","method":"updateOrderbook","params":{"ask":[{"price":"0.00013224","size":"0"},{"price":"0.00013274","size":"22588.08"},{"price":"0.00015573","size":"0"},{"price":"0.00015625","size":"26975.46"},{"price":"0.00024131","size":"0"},{"price":"0.00024177","size":"39545.26"},{"price":"0.00034205","size":"0"},{"price":"0.00034306","size":"56176.40"},{"price":"0.00091644","size":"86093.30"},{"price":"0.00092098","size":"0"}],"bid":[],"sequence":12351777,"timestamp":"2021-07-03T00:56:38.529Z","symbol":"EOSBTC"}}
1625273798.637192: {"jsonrpc":"2.0","method":"updateOrderbook","params":{"ask":[{"price":"33522.05","size":"0.02979"},{"price":"33523.91","size":"0"}],"bid":[],"sequence":7476977,"timestamp":"2021-07-03T00:56:38.536Z","symbol":"BTCTUSD"}}
1625273798.729961: {"jsonrpc":"2.0","method":"updateOrderbook","params":{"ask":[{"price":"33571.40","size":"0.01174"},{"price":"33574.26","size":"0.27520"},{"price":"33585.10","size":"0.95910"},{"price":"33590.81","size":"0"},{"price":"33603.25","size":"1.06920"},{"price":"33616.52","size":"0"}],"bid":[{"price":"33542.15","size":"0.02940"},{"price":"33540.76","size":"0"}],"sequence":12626775,"timestamp":"2021-07-03T00:56:38.635Z","symbol":"BTCUSDB"}}
1625273798.729981: {"jsonrpc":"2.0","method":"updateOrderbook","params":{"ask":[],"bid":[{"price":"0.00010324","size":"0"},{"price":"0.00010304","size":"23147.93"},{"price":"0.00008843","size":"9955.15"},{"price":"0.00008804","size":"12370.85"}],"sequence":12351778,"timestamp":"2021-07-03T00:56:38.594Z","symbol":"EOSBTC"}}
1625273798.7299929: {"jsonrpc":"2.0","method":"updateOrderbook","params":{"ask":[{"price":"33677.00","size":"0.00533"},{"price":"33679.25","size":"0"}],"bid":[],"sequence":7211249,"timestamp":"2021-07-03T00:56:38.601Z","symbol":"BTCPAX"}}
1625273798.730004: {"jsonrpc":"2.0","method":"updateOrderbook","params":{"ask":[{"price":"33519.31","size":"0"},{"price":"33520.62","size":"0.01233"},{"price":"33522.05","size":"0"},{"price":"33523.64","size":"0.02979"}],"bid":[],"sequence":7476978,"timestamp":"2021-07-03T00:56:38.649Z","symbol":"BTCTUSD"}}
1625273798.823885: {"jsonrpc":"2.0","method":"updateOrderbook","params":{"ask":[],"bid":[{"price":"2109.737","size":"0"},{"price":"2103.571","size":"22.1000"},{"price":"2092.633","size":"0"},{"price":"2090.413","size":"0"},{"price":"2090.318","size":"36.1000"},{"price":"2088.156","size":"23.9000"}],"sequence":1513062,"timestamp":"2021-07-03T00:56:38.702Z","symbol":"ETHDAI"}}
1625273798.823949: {"jsonrpc":"2.0","method":"updateOrderbook","params":{"ask":[{"price":"33541.99","size":"0.01030"},{"price":"33548.69","size":"0.03810"},{"price":"33551.27","size":"0"},{"price":"33557.97","size":"0"}],"bid":[{"price":"33531.73","size":"0"},{"price":"33528.52","size":"0"},{"price":"33527.20","size":"0.09211"},{"price":"33523.99","size":"0.17106"},{"price":"32997.95","size":"0"},{"price":"32932.16","size":"1.90000"}],"sequence":5708320,"timestamp":"2021-07-03T00:56:38.714Z","symbol":"BTCDAI"}}
1625273798.831406: {"jsonrpc":"2.0","method":"updateOrderbook","params":{"ask":[],"bid":[{"price":"33537.62","size":"0.05460"},{"price":"33535.25","size":"0"},{"price":"33495.10","size":"0"},{"price":"33492.12","size":"1.43580"},{"price":"33487.99","size":"0"},{"price":"33482.94","size":"2.64430"},{"price":"33467.71","size":"0"},{"price":"33461.87","size":"1.04000"},{"price":"33241.67","size":"0"},{"price":"33229.78","size":"1.54744"}],"sequence":12626776,"timestamp":"2021-07-03T00:56:38.739Z","symbol":"BTCUSDB"}}
1625273798.831429: {"jsonrpc":"2.0","method":"updateOrderbook","params":{"ask":[{"price":"33520.62","size":"0"},{"price":"33521.08","size":"0.01233"}],"bid":[],"sequence":7476979,"timestamp":"2021-07-03T00:56:38.671Z","symbol":"BTCTUSD"}}
1625273798.934113: {"jsonrpc":"2.0","method":"updateOrderbook","params":{"ask":[{"price":"0.09700","size":"3.7522"},{"price":"0.10064","size":"0"}],"bid":[],"sequence":7339972,"timestamp":"2021-07-03T00:56:38.767Z","symbol":"MKRBTC"}}
1625273799.028363: {"jsonrpc":"2.0","method":"updateOrderbook","params":{"ask":[{"price":"33615.72","size":"0.38410"},{"price":"33627.62","size":"0"}],"bid":[],"sequence":12626777,"timestamp":"2021-07-03T00:56:38.870Z","symbol":"BTCUSDB"}}
1625273799.028382: {"jsonrpc":"2.0","method":"updateOrderbook","params":{"ask":[{"price":"0.00011599","size":"1896.82"},{"price":"0.00011602","size":"2195.59"}],"bid":[],"sequence":12351779,"timestamp":"2021-07-03T00:56:38.859Z","symbol":"EOSBTC"}}
1625273799.0283918: {"jsonrpc":"2.0","method":"updateOrderbook","params":{"ask":[{"price":"33677.00","size":"0"},{"price":"33677.98","size":"0.00533"}],"bid":[],"sequence":7211250,"timestamp":"2021-07-03T00:56:38.950Z","symbol":"BTCPAX"}}
1625273799.033737: {"jsonrpc":"2.0","method":"updateOrderbook","params":{"ask":[{"price":"33521.08","size":"0"},{"price":"33521.84","size":"0.01233"}],"bid":[],"sequence":7476980,"timestamp":"2021-07-03T00:56:38.950Z","symbol":"BTCTUSD"}}
1625273799.128501: {"jsonrpc":"2.0","method":"updateOrderbook","params":{"ask":[],"bid":[{"price":"33528.76","size":"0.09211"},{"price":"33527.20","size":"0"}],"sequence":5708321,"timestamp":"2021-07-03T00:56:39.020Z","symbol":"BTCDAI"}}
1625273799.128623: {"jsonrpc":"2.0","method":"updateOrderbook","params":{"ask":[{"price":"167647.25","size":"0.00019"},{"price":"167667.30","size":"0"}],"bid":[{"price":"10060.03","size":"0"},{"price":"10058.83","size":"0.00013"}],"sequence":12626778,"timestamp":"2021-07-03T00:56:39.050Z","symbol":"BTCUSDB"}}
1625273799.132757: {"jsonrpc":"2.0","method":"updateOrderbook","params":{"ask":[{"price":"33677.98","size":"0"},{"price":"33678.76","size":"0.00533"}],"bid":[],"sequence":7211251,"timestamp":"2021-07-03T00:56:39.014Z","symbol":"BTCPAX"}}
1625273799.1328142: {"jsonrpc":"2.0","method":"updateOrderbook","params":{"ask":[{"price":"33521.84","size":"0"},{"price":"33522.58","size":"0.01233"},{"price":"33523.64","size":"0"},{"price":"33525.56","size":"0.02979"}],"bid":[],"sequence":7476981,"timestamp":"2021-07-03T00:56:38.959Z","symbol":"BTCTUSD"}}
1625273799.225618: {"jsonrpc":"2.0","method":"updateOrderbook","params":{"ask":[],"bid":[{"price":"33534.00","size":"0"},{"price":"33533.44","size":"1.81560"},{"price":"33520.24","size":"0"},{"price":"33519.45","size":"1.10595"}],"sequence":12626779,"timestamp":"2021-07-03T00:56:39.115Z","symbol":"BTCUSDB"}}
1625273799.334823: {"jsonrpc":"2.0","method":"updateOrderbook","params":{"ask":[{"price":"33574.46","size":"1.75290"},{"price":"33576.03","size":"0"},{"price":"33607.60","size":"1.07210"},{"price":"33613.36","size":"0"}],"bid":[],"sequence":12626780,"timestamp":"2021-07-03T00:56:39.241Z","symbol":"BTCUSDB"}}
1625273799.334841: {"jsonrpc":"2.0","method":"updateOrderbook","params":{"ask":[{"price":"0.00011581","size":"412.42"},{"price":"0.00011582","size":"244.48"}],"bid":[],"sequence":12351780,"timestamp":"2021-07-03T00:56:39.155Z","symbol":"EOSBTC"}}
1625273799.334852: {"jsonrpc":"2.0","method":"updateOrderbook","params":{"ask":[{"price":"33678.76","size":"0"},{"price":"33679.55","size":"0.00533"}],"bid":[],"sequence":7211252,"timestamp":"2021-07-03T00:56:39.232Z","symbol":"BTCPAX"}}
1625273799.334861: {"jsonrpc":"2.0","method":"updateOrderbook","params":{"ask":[{"price":"33522.58","size":"0"},{"price":"33524.07","size":"0.01233"},{"price":"33525.56","size":"0"},{"price":"33527.03","size":"0.02979"}],"bid":[],"sequence":7476982,"timestamp":"2021-07-03T00:56:39.235Z","symbol":"BTCTUSD"}}
1625273799.4277802: {"jsonrpc":"2.0","method":"updateOrderbook","params":{"ask":[{"price":"33555.34","size":"0.45140"},{"price":"33558.47","size":"0"}],"bid":[],"sequence":12626781,"timestamp":"2021-07-03T00:56:39.340Z","symbol":"BTCUSDB"}}
1625273799.4278002: {"jsonrpc":"2.0","method":"updateOrderbook","params":{"ask":[{"price":"0.00011581","size":"412.52"},{"price":"0.00011583","size":"2723.56"},{"price":"0.00011589","size":"0"},{"price":"0.00011590","size":"1809.62"},{"price":"0.00011593","size":"373.69"},{"price":"0.00011594","size":"2110.39"},{"price":"0.00011768","size":"4513.55"},{"price":"0.00012737","size":"0"},{"price":"0.00013274","size":"0"},{"price":"0.00013372","size":"22588.08"},{"price":"0.00015625","size":"0"},{"price":"0.00015724","size":"26975.46"},{"price":"0.00024177","size":"0"},{"price":"0.00024312","size":"39545.26"},{"price":"0.00034306","size":"0"},{"price":"0.00034579","size":"56176.40"},{"price":"0.00091644","size":"0"},{"price":"0.00092805","size":"86093.30"}],"bid":[{"price":"0.00011570","size":"493.01"},{"price":"0.00011568","size":"1712.56"},{"price":"0.00011567","size":"198.80"},{"price":"0.00011566","size":"186.44"},{"price":"0.00011563","size":"180.60"},{"price":"0.00011561","size":"2617.93"},{"price":"0.00011559","size":"914.89"},{"price":"0.00011558","size":"2827.90"}],"sequence":12351781,"timestamp":"2021-07-03T00:56:39.349Z","symbol":"EOSBTC"}}
1625273799.4395452: {"jsonrpc":"2.0","method":"updateOrderbook","params":{"ask":[{"price":"0.22571","size":"4.2976"},{"price":"0.29757","size":"0"}],"bid":[],"sequence":7339973,"timestamp":"2021-07-03T00:56:39.340Z","symbol":"MKRBTC"}}
1625273799.439585: {"jsonrpc":"2.0","method":"updateOrderbook","params":{"ask":[{"price":"33524.03","size":"0.01234"},{"price":"33524.07","size":"0"},{"price":"33527.03","size":"0.02980"},{"price":"33532.37","size":"0"},{"price":"33533.46","size":"0.05147"},{"price":"33537.36","size":"0"},{"price":"33538.15","size":"0.06050"}],"bid":[{"price":"33496.18","size":"0"},{"price":"33494.43","size":"0.01475"},{"price":"33491.29","size":"0.02739"},{"price":"33490.92","size":"0"},{"price":"33486.43","size":"0"},{"price":"33484.86","size":"0.05087"},{"price":"33481.73","size":"0"},{"price":"33480.13","size":"0.05990"}],"sequence":7476983,"timestamp":"2021-07-03T00:56:39.335Z","symbol":"BTCTUSD"}}
1625273799.5218382: {"jsonrpc":"2.0","method":"updateOrderbook","params":{"ask":[],"bid":[{"price":"2127.753","size":"23.5393"},{"price":"2125.867","size":"0"}],"sequence":1513063,"timestamp":"2021-07-03T00:56:39.364Z","symbol":"ETHDAI"}}
1625273799.5218549: {"jsonrpc":"2.0","method":"updateOrderbook","params":{"ask":[],"bid":[{"price":"33526.10","size":"0.17106"},{"price":"33523.99","size":"0"}],"sequence":5708322,"timestamp":"2021-07-03T00:56:39.421Z","symbol":"BTCDAI"}}
1625273799.625895: {"jsonrpc":"2.0","method":"updateOrderbook","params":{"ask":[],"bid":[{"price":"33528.76","size":"0"},{"price":"33527.76","size":"0.09211"},{"price":"33526.10","size":"0"},{"price":"33524.05","size":"0.17106"}],"sequence":5708323,"timestamp":"2021-07-03T00:56:39.533Z","symbol":"BTCDAI"}}
1625273799.6260219: {"jsonrpc":"2.0","method":"updateOrderbook","params":{"ask":[{"price":"33550.10","size":"0"},{"price":"33550.16","size":"0"},{"price":"33550.39","size":"0.02460"},{"price":"33554.95","size":"0.05940"},{"price":"33555.34","size":"0"},{"price":"33559.23","size":"0"},{"price":"33559.78","size":"0.45140"},{"price":"33563.36","size":"0"},{"price":"33564.52","size":"0.10260"},{"price":"33567.07","size":"0.91740"},{"price":"33574.46","size":"0"},{"price":"33576.77","size":"1.75290"},{"price":"33592.14","size":"0"},{"price":"33597.21","size":"1.17130"},{"price":"33659.07","size":"0"},{"price":"33674.63","size":"1.37330"},{"price":"33726.33","size":"0"},{"price":"33745.85","size":"0.77520"}],"bid":[{"price":"33545.72","size":"0.02940"},{"price":"33542.15","size":"0"},{"price":"33537.62","size":"0"},{"price":"33536.25","size":"0.05460"},{"price":"33534.22","size":"1.81560"},{"price":"33533.44","size":"0"},{"price":"33515.30","size":"0"},{"price":"33512.85","size":"0.77390"}],"sequence":12626782,"timestamp":"2021-07-03T00:56:39.551Z","symbol":"BTCUSDB"}}
1625273799.633009: {"jsonrpc":"2.0","method":"updateOrderbook","params":{"ask":[{"price":"0.00011581","size":"536.56"},{"price":"0.00011582","size":"120.44"}],"bid":[],"sequence":12351782,"timestamp":"2021-07-03T00:56:39.549Z","symbol":"EOSBTC"}}
1625273799.633047: {"jsonrpc":"2.0","method":"updateOrderbook","params":{"ask":[{"price":"33686.68","size":"0"},{"price":"33688.64","size":"0.00533"}],"bid":[],"sequence":7211253,"timestamp":"2021-07-03T00:56:39.530Z","symbol":"BTCPAX"}}
1625273799.640522: {"jsonrpc":"2.0","method":"updateOrderbook","params":{"ask":[{"price":"33524.03","size":"0"},{"price":"33524.69","size":"0.01234"}],"bid":[],"sequence":7476984,"timestamp":"2021-07-03T00:56:39.530Z","symbol":"BTCTUSD"}}
1625273799.7283862: {"jsonrpc":"2.0","method":"updateOrderbook","params":{"ask":[{"price":"33550.31","size":"0.02460"},{"price":"33550.39","size":"0"},{"price":"33552.91","size":"0.74140"},{"price":"33554.83","size":"1.03952"},{"price":"33559.78","size":"0"},{"price":"33561.98","size":"0.41740"},{"price":"33563.20","size":"0.45140"},{"price":"33568.02","size":"1.09780"},{"price":"33568.69","size":"0"},{"price":"33569.22","size":"0.95910"},{"price":"33574.90","size":"0"},{"price":"33577.23","size":"0.75370"},{"price":"33577.51","size":"1.43490"}],"bid":[{"price":"33546.23","size":"0.02940"},{"price":"33545.72","size":"0"},{"price":"33534.85","size":"1.43690"},{"price":"33534.77","size":"1.81560"},{"price":"33534.22","size":"0"},{"price":"33529.05","size":"0"},{"price":"33524.32","size":"1.10595"},{"price":"33519.45","size":"0"},{"price":"33516.56","size":"0.77390"},{"price":"33512.85","size":"0"},{"price":"33458.73","size":"1.46790"},{"price":"33452.47","size":"0"}],"sequence":12626783,"timestamp":"2021-07-03T00:56:39.648Z","symbol":"BTCUSDB"}}
1625273799.728545: {"jsonrpc":"2.0","method":"updateOrderbook","params":{"ask":[],"bid":[{"price":"0.00011570","size":"0"},{"price":"0.00011569","size":"493.01"},{"price":"0.00011473","size":"0"},{"price":"0.00011454","size":"4559.60"},{"price":"0.00011024","size":"0"},{"price":"0.00010940","size":"7497.84"}],"sequence":12351783,"timestamp":"2021-07-03T00:56:39.589Z","symbol":"EOSBTC"}}
1625273799.7285728: {"jsonrpc":"2.0","method":"updateOrderbook","params":{"ask":[{"price":"33656.55","size":"0.00533"},{"price":"33679.55","size":"0"}],"bid":[],"sequence":7211254,"timestamp":"2021-07-03T00:56:39.560Z","symbol":"BTCPAX"}}
1625273799.7341938: {"jsonrpc":"2.0","method":"updateOrderbook","params":{"ask":[{"price":"0.07655","size":"0"},{"price":"0.07659","size":"1.9169"},{"price":"0.07809","size":"0"},{"price":"0.07822","size":"9.6365"}],"bid":[],"sequence":7339974,"timestamp":"2021-07-03T00:56:39.606Z","symbol":"MKRBTC"}}
1625273799.73422: {"jsonrpc":"2.0","method":"updateOrderbook","params":{"ask":[{"price":"33522.37","size":"0.01234"},{"price":"33524.69","size":"0"}],"bid":[],"sequence":7476985,"timestamp":"2021-07-03T00:56:39.597Z","symbol":"BTCTUSD"}}
1625273799.82372: {"jsonrpc":"2.0","method":"updateOrderbook","params":{"ask":[],"bid":[{"price":"2109.992","size":"22.1000"},{"price":"2103.571","size":"0"},{"price":"2092.760","size":"36.1000"},{"price":"2090.318","size":"0"}],"sequence":1513064,"timestamp":"2021-07-03T00:56:39.703Z","symbol":"ETHDAI"}}
1625273799.826875: {"jsonrpc":"2.0","method":"updateOrderbook","params":{"ask":[],"bid":[{"price":"33006.68","size":"1.90000"},{"price":"32932.16","size":"0"}],"sequence":5708324,"timestamp":"2021-07-03T00:56:39.703Z","symbol":"BTCDAI"}}
1625273799.829777: {"jsonrpc":"2.0","method":"updateOrderbook","params":{"ask":[{"price":"33550.28","size":"0.02460"},{"price":"33550.31","size":"0"},{"price":"33551.53","size":"0.05940"},{"price":"33554.95","size":"0"}],"bid":[{"price":"33546.23","size":"0"},{"price":"33546.02","size":"0.02940"},{"price":"33541.48","size":"0.05460"},{"price":"33536.25","size":"0"},{"price":"33535.40","size":"1.81560"},{"price":"33534.85","size":"0"},{"price":"33534.77","size":"0"},{"price":"33533.53","size":"1.43690"},{"price":"33524.32","size":"0"},{"price":"33522.27","size":"1.10595"},{"price":"33473.59","size":"0.43060"},{"price":"33466.61","size":"0"}],"sequence":12626784,"timestamp":"2021-07-03T00:56:39.737Z","symbol":"BTCUSDB"}}
1625273799.8298712: {"jsonrpc":"2.0","method":"updateOrderbook","params":{"ask":[{"price":"0.00011580","size":"642.52"},{"price":"0.00011581","size":"223.04"},{"price":"0.00012270","size":"0"},{"price":"0.00012295","size":"16338.72"},{"price":"0.00016019","size":"0"},{"price":"0.00016058","size":"19505.60"},{"price":"0.00023569","size":"0"},{"price":"0.00023642","size":"30396.48"},{"price":"0.00076327","size":"0"},{"price":"0.00076647","size":"42091.73"}],"bid":[{"price":"0.00011570","size":"493.01"},{"price":"0.00011569","size":"0"}],"sequence":12351784,"timestamp":"2021-07-03T00:56:39.740Z","symbol":"EOSBTC"}}
1625273799.829893: {"jsonrpc":"2.0","method":"updateOrderbook","params":{"ask":[{"price":"33664.59","size":"0.00533"},{"price":"33688.64","size":"0"}],"bid":[],"sequence":7211255,"timestamp":"2021-07-03T00:56:39.718Z","symbol":"BTCPAX"}}
1625273799.8299048: {"jsonrpc":"2.0","method":"updateOrderbook","params":{"ask":[{"price":"0.22571","size":"0"},{"price":"0.24215","size":"4.2976"}],"bid":[],"sequence":7339975,"timestamp":"2021-07-03T00:56:39.677Z","symbol":"MKRBTC"}}
1625273799.829916: {"jsonrpc":"2.0","method":"updateOrderbook","params":{"ask":[{"price":"33525.03","size":"0.02980"},{"price":"33527.03","size":"0"}],"bid":[],"sequence":7476986,"timestamp":"2021-07-03T00:56:39.718Z","symbol":"BTCTUSD"}}
1625273799.932395: {"jsonrpc":"2.0","method":"updateOrderbook","params":{"ask":[{"price":"33550.09","size":"0.02460"},{"price":"33550.28","size":"0"},{"price":"33551.53","size":"0"},{"price":"33554.43","size":"0.05940"},{"price":"33585.10","size":"0"},{"price":"33588.37","size":"0.95910"}],"bid":[{"price":"33532.24","size":"0.10140"},{"price":"33526.78","size":"0"}],"sequence":12626785,"timestamp":"2021-07-03T00:56:39.846Z","symbol":"BTCUSDB"}}
1625273799.9325252: {"jsonrpc":"2.0","method":"updateOrderbook","params":{"ask":[{"price":"0.00014660","size":"5718.01"},{"price":"0.00015741","size":"0"},{"price":"0.00016861","size":"7220.48"},{"price":"0.00017621","size":"0"}],"bid":[],"sequence":12351785,"timestamp":"2021-07-03T00:56:39.844Z","symbol":"EOSBTC"}}
1625273800.022291: {"jsonrpc":"2.0","method":"updateOrderbook","params":{"ask":[{"price":"33550.09","size":"0"},{"price":"33552.54","size":"0.02460"},{"price":"33554.43","size":"0"},{"price":"33556.71","size":"0.05940"},{"price":"33568.02","size":"0"},{"price":"33569.22","size":"0"},{"price":"33569.64","size":"1.09780"},{"price":"33570.81","size":"0.95910"}],"bid":[{"price":"33548.19","size":"0.02940"},{"price":"33546.02","size":"0"},{"price":"33486.00","size":"2.64430"},{"price":"33482.94","size":"0"}],"sequence":12626786,"timestamp":"2021-07-03T00:56:39.946Z","symbol":"BTCUSDB"}}
1625273800.025941: {"jsonrpc":"2.0","method":"updateOrderbook","params":{"ask":[{"price":"0.00092805","size":"0"},{"price":"0.00092911","size":"86093.30"}],"bid":[],"sequence":12351786,"timestamp":"2021-07-03T00:56:39.895Z","symbol":"EOSBTC"}}
1625273800.025953: {"jsonrpc":"2.0","method":"updateOrderbook","params":{"ask":[{"price":"33695.38","size":"0.00533"},{"price":"33717.29","size":"0"}],"bid":[],"sequence":7211256,"timestamp":"2021-07-03T00:56:39.874Z","symbol":"BTCPAX"}}
1625273800.128405: {"jsonrpc":"2.0","method":"updateOrderbook","params":{"ask":[{"price":"33552.53","size":"0.02460"},{"price":"33552.54","size":"0"},{"price":"33577.51","size":"0"},{"price":"33579.85","size":"1.43490"},{"price":"33660.40","size":"1.37330"},{"price":"33674.63","size":"0"}],"bid":[{"price":"33243.59","size":"1.54712"},{"price":"33229.78","size":"0"},{"price":"33121.74","size":"2.20317"},{"price":"33110.72","size":"0"}],"sequence":12626787,"timestamp":"2021-07-03T00:56:39.992Z","symbol":"BTCUSDB"}}
1625273800.1285172: {"jsonrpc":"2.0","method":"updateOrderbook","params":{"ask":[{"price":"0.00013372","size":"0"},{"price":"0.00013422","size":"22588.08"},{"price":"0.00015724","size":"0"},{"price":"0.00015774","size":"26975.46"},{"price":"0.00024312","size":"0"},{"price":"0.00024381","size":"39545.26"},{"price":"0.00034579","size":"0"},{"price":"0.00034717","size":"56176.40"},{"price":"0.00092911","size":"0"},{"price":"0.00093394","size":"86093.30"}],"bid":[],"sequence":12351787,"timestamp":"2021-07-03T00:56:40.006Z","symbol":"EOSBTC"}}
1625273800.128549: {"jsonrpc":"2.0","method":"updateOrderbook","params":{"ask":[{"price":"33522.00","size":"0.01234"},{"price":"33522.37","size":"0"}],"bid":[{"price":"32328.62","size":"1.67560"},{"price":"32279.11","size":"0"}],"sequence":7476987,"timestamp":"2021-07-03T00:56:40.040Z","symbol":"BTCTUSD"}}
1625273800.2405472: {"jsonrpc":"2.0","method":"updateOrderbook","params":{"ask":[{"price":"33552.01","size":"0.02460"},{"price":"33552.53","size":"0"},{"price":"167647.25","size":"0"},{"price":"167675.83","size":"0.00014"}],"bid":[{"price":"33548.19","size":"0"},{"price":"33546.60","size":"0.02940"},{"price":"33541.81","size":"1.15550"},{"price":"33538.32","size":"0"},{"price":"33535.01","size":"0"},{"price":"33528.30","size":"0.94240"},{"price":"33520.43","size":"0"},{"price":"33497.57","size":"1.43690"},{"price":"33490.63","size":"0"},{"price":"33486.00","size":"0"},{"price":"33482.94","size":"2.64430"},{"price":"33473.59","size":"0"},{"price":"33466.15","size":"0.43060"},{"price":"33458.73","size":"0"},{"price":"33452.53","size":"1.46790"},{"price":"10060.54","size":"0.00012"},{"price":"10058.83","size":"0"}],"sequence":12626788,"timestamp":"2021-07-03T00:56:40.143Z","symbol":"BTCUSDB"}}
1625273800.2406778: {"jsonrpc":"2.0","method":"updateOrderbook","params":{"ask":[{"price":"0.00011580","size":"230.00"},{"price":"0.00011581","size":"635.56"},{"price":"0.00011612","size":"880.11"},{"price":"0.00011619","size":"3670.01"},{"price":"0.00013422","size":"0"},{"price":"0.00013454","size":"22588.08"},{"price":"0.00015774","size":"0"},{"price":"0.00015805","size":"26975.46"},{"price":"0.00024381","size":"0"},{"price":"0.00024422","size":"39545.26"},{"price":"0.00034717","size":"0"},{"price":"0.00034802","size":"56176.40"},{"price":"0.00093394","size":"0"},{"price":"0.00093752","size":"86093.30"}],"bid":[{"price":"0.00011474","size":"4559.60"},{"price":"0.00011454","size":"0"}],"sequence":12351788,"timestamp":"2021-07-03T00:56:40.145Z","symbol":"EOSBTC"}}
1625273800.328253: {"jsonrpc":"2.0","method":"updateOrderbook","params":{"ask":[{"price":"33551.55","size":"0.02460"},{"price":"33552.01","size":"0"},{"price":"33552.91","size":"0.07070"},{"price":"33554.68","size":"0.67070"},{"price":"33554.83","size":"0"},{"price":"33558.91","size":"1.03952"}],"bid":[{"price":"33546.60","size":"0"},{"price":"33546.21","size":"0.02940"},{"price":"33541.81","size":"0.38210"},{"price":"33539.21","size":"0.77340"},{"price":"33528.30","size":"0"},{"price":"33527.10","size":"0.94240"},{"price":"33502.83","size":"0.96010"},{"price":"33501.27","size":"0"}],"sequence":12626789,"timestamp":"2021-07-03T00:56:40.218Z","symbol":"BTCUSDB"}}
1625273800.328346: {"jsonrpc":"2.0","method":"updateOrderbook","params":{"ask":[{"price":"0.00011679","size":"3273.50"},{"price":"0.00011693","size":"0"}],"bid":[],"sequence":12351789,"timestamp":"2021-07-03T00:56:40.248Z","symbol":"EOSBTC"}}
1625273800.328361: {"jsonrpc":"2.0","method":"updateOrderbook","params":{"ask":[{"price":"33655.73","size":"0.00533"},{"price":"33656.55","size":"0"}],"bid":[],"sequence":7211257,"timestamp":"2021-07-03T00:56:40.221Z","symbol":"BTCPAX"}}
1625273800.339712: {"jsonrpc":"2.0","method":"updateOrderbook","params":{"ask":[{"price":"33521.18","size":"0.01234"},{"price":"33522.00","size":"0"}],"bid":[],"sequence":7476988,"timestamp":"2021-07-03T00:56:40.194Z","symbol":"BTCTUSD"}}
1625273800.4250932: {"jsonrpc":"2.0","method":"updateOrderbook","params":{"ask":[],"bid":[{"price":"33527.76","size":"0"},{"price":"33525.68","size":"0.09211"},{"price":"33524.05","size":"0"},{"price":"33521.94","size":"0.17106"}],"sequence":5708325,"timestamp":"2021-07-03T00:56:40.295Z","symbol":"BTCDAI"}}
1625273800.425202: {"jsonrpc":"2.0","method":"updateOrderbook","params":{"ask":[{"price":"33551.01","size":"0.02460"},{"price":"33551.55","size":"0"},{"price":"33554.11","size":"0.05940"},{"price":"33556.71","size":"0"}],"bid":[{"price":"33539.21","size":"0"},{"price":"33536.83","size":"0.77340"},{"price":"33534.96","size":"1.43690"},{"price":"33533.53","size":"0"},{"price":"33527.70","size":"0.94240"},{"price":"33527.10","size":"0"},{"price":"33525.32","size":"1.10595"},{"price":"33522.27","size":"0"}],"sequence":12626790,"timestamp":"2021-07-03T00:56:40.332Z","symbol":"BTCUSDB"}}
1625273800.4252748: {"jsonrpc":"2.0","method":"updateOrderbook","params":{"ask":[{"price":"0.00011580","size":"642.52"},{"price":"0.00011581","size":"223.04"},{"price":"0.00018802","size":"10554.74"},{"price":"0.00019167","size":"0"},{"price":"0.00022198","size":"15617.57"},{"price":"0.00023114","size":"0"}],"bid":[],"sequence":12351790,"timestamp":"2021-07-03T00:56:40.312Z","symbol":"EOSBTC"}}
1625273800.425298: {"jsonrpc":"2.0","method":"updateOrderbook","params":{"ask":[{"price":"33654.99","size":"0.00533"},{"price":"33655.73","size":"0"}],"bid":[],"sequence":7211258,"timestamp":"2021-07-03T00:56:40.323Z","symbol":"BTCPAX"}}
1625273800.428067: {"jsonrpc":"2.0","method":"updateOrderbook","params":{"ask":[{"price":"0.07647","size":"0"},{"price":"0.07650","size":"0.0003"},{"price":"0.09700","size":"0"},{"price":"0.09752","size":"3.7522"},{"price":"0.24215","size":"0"},{"price":"0.25006","size":"4.2976"}],"bid":[],"sequence":7339976,"timestamp":"2021-07-03T00:56:40.313Z","symbol":"MKRBTC"}}
1625273800.428128: {"jsonrpc":"2.0","method":"updateOrderbook","params":{"ask":[{"price":"33519.95","size":"0.01234"},{"price":"33521.18","size":"0"}],"bid":[],"sequence":7476989,"timestamp":"2021-07-03T00:56:40.349Z","symbol":"BTCTUSD"}}
1625273800.536653: {"jsonrpc":"2.0","method":"updateOrderbook","params":{"ask":[{"price":"33550.74","size":"0.02460"},{"price":"33551.01","size":"0"},{"price":"33571.40","size":"0"},{"price":"33574.47","size":"0"},{"price":"33574.96","size":"0.01174"},{"price":"33577.38","size":"0.39780"},{"price":"33582.88","size":"0"},{"price":"33585.96","size":"0.79591"}],"bid":[{"price":"33525.92","size":"1.10595"},{"price":"33525.32","size":"0"}],"sequence":12626791,"timestamp":"2021-07-03T00:56:40.416Z","symbol":"BTCUSDB"}}
1625273800.536788: {"jsonrpc":"2.0","method":"updateOrderbook","params":{"ask":[{"price":"0.00011580","size":"230.00"},{"price":"0.00011581","size":"635.56"}],"bid":[],"sequence":12351791,"timestamp":"2021-07-03T00:56:40.376Z","symbol":"EOSBTC"}}
1625273800.627765: {"jsonrpc":"2.0","method":"updateOrderbook","params":{"ask":[],"bid":[{"price":"33525.68","size":"0"},{"price":"33524.90","size":"0.09211"}],"sequence":5708326,"timestamp":"2021-07-03T00:56:40.489Z","symbol":"BTCDAI"}}
1625273800.6278908: {"jsonrpc":"2.0","method":"updateOrderbook","params":{"ask":[],"bid":[{"price":"33511.89","size":"0.64790"},{"price":"33509.22","size":"0"}],"sequence":12626792,"timestamp":"2021-07-03T00:56:40.504Z","symbol":"BTCUSDB"}}
1625273800.627914: {"jsonrpc":"2.0","method":"updateOrderbook","params":{"ask":[{"price":"0.00011606","size":"1826.42"},{"price":"0.00011614","size":"1190.78"}],"bid":[],"sequence":12351792,"timestamp":"2021-07-03T00:56:40.499Z","symbol":"EOSBTC"}}
1625273800.639175: {"jsonrpc":"2.0","method":"updateOrderbook","params":{"ask":[{"price":"33522.64","size":"0.02980"},{"price":"33525.03","size":"0"}],"bid":[],"sequence":7476990,"timestamp":"2021-07-03T00:56:40.473Z","symbol":"BTCTUSD"}}
1625273800.7272599: {"jsonrpc":"2.0","method":"updateOrderbook","params":{"ask":[],"bid":[{"price":"33494.71","size":"0.94240"},{"price":"33490.80","size":"0.09056"}],"sequence":12626793,"timestamp":"2021-07-03T00:56:40.607Z","symbol":"BTCUSDB"}}
1625273800.727316: {"jsonrpc":"2.0","method":"updateOrderbook","params":{"ask":[{"price":"0.00011580","size":"329.00"},{"price":"0.00011581","size":"536.56"}],"bid":[],"sequence":12351793,"timestamp":"2021-07-03T00:56:40.580Z","symbol":"EOSBTC"}}
1625273800.731919: {"jsonrpc":"2.0","method":"updateOrderbook","params":{"ask":[{"price":"33519.36","size":"0.01234"},{"price":"33519.95","size":"0"},{"price":"33529.01","size":"0.05147"},{"price":"33533.46","size":"0"}],"bid":[],"sequence":7476991,"timestamp":"2021-07-03T00:56:40.600Z","symbol":"BTCTUSD"}}
1625273800.830326: {"jsonrpc":"2.0","method":"updateOrderbook","params":{"ask":[{"price":"33559.11","size":"0.45140"},{"price":"33563.20","size":"0"},{"price":"33565.37","size":"0.91740"},{"price":"33567.07","size":"0"},{"price":"33575.08","size":"1.75290"},{"price":"33576.77","size":"0"}],"bid":[{"price":"33525.92","size":"0"},{"price":"33525.35","size":"1.10595"},{"price":"33516.23","size":"1.37123"},{"price":"33512.23","size":"0"},{"price":"33511.89","size":"0"},{"price":"33509.73","size":"0.64790"}],"sequence":12626794,"timestamp":"2021-07-03T00:56:40.736Z","symbol":"BTCUSDB"}}
1625273800.8303711: {"jsonrpc":"2.0","method":"updateOrderbook","params":{"ask":[{"price":"0.00012295","size":"0"},{"price":"0.00012331","size":"16338.72"},{"price":"0.00016058","size":"0"},{"price":"0.00016111","size":"19505.60"},{"price":"0.00023642","size":"0"},{"price":"0.00023741","size":"30396.48"},{"price":"0.00076647","size":"0"},{"price":"0.00077138","size":"42091.73"}],"bid":[],"sequence":12351794,"timestamp":"2021-07-03T00:56:40.727Z","symbol":"EOSBTC"}}
1625273800.8303921: {"jsonrpc":"2.0","method":"updateOrderbook","params":{"ask":[{"price":"35023.99","size":"1.84720"},{"price":"35115.28","size":"0"}],"bid":[],"sequence":7211259,"timestamp":"2021-07-03T00:56:40.739Z","symbol":"BTCPAX"}}
1625273800.830404: {"jsonrpc":"2.0","method":"updateOrderbook","params":{"ask":[],"bid":[{"price":"0.07607","size":"0.1281"},{"price":"0.07602","size":"0.5119"}],"sequence":7339977,"timestamp":"2021-07-03T00:56:40.699Z","symbol":"MKRBTC"}}
1625273800.830415: {"jsonrpc":"2.0","method":"updateOrderbook","params":{"ask":[],"bid":[{"price":"33494.43","size":"0"},{"price":"33491.68","size":"0.01475"},{"price":"32328.62","size":"0"},{"price":"32199.15","size":"1.67560"},{"price":"30631.58","size":"0"},{"price":"30566.25","size":"1.39725"}],"sequence":7476992,"timestamp":"2021-07-03T00:56:40.739Z","symbol":"BTCTUSD"}}
1625273800.922894: {"jsonrpc":"2.0","method":"updateOrderbook","params":{"ask":[{"price":"39880.09","size":"4.51490"},{"price":"39982.21","size":"0"}],"bid":[],"sequence":5708327,"timestamp":"2021-07-03T00:56:40.794Z","symbol":"BTCDAI"}}
1625273800.9279392: {"jsonrpc":"2.0","method":"updateOrderbook","params":{"ask":[{"price":"33608.38","size":"0.51010"},{"price":"33612.83","size":"0.09820"},{"price":"33616.89","size":"0"},{"price":"33621.87","size":"0"}],"bid":[{"price":"33546.21","size":"0"},{"price":"33545.18","size":"0.02940"},{"price":"33534.96","size":"0"},{"price":"33534.13","size":"1.43690"},{"price":"33527.70","size":"0"},{"price":"33525.35","size":"0"},{"price":"33524.82","size":"0.94240"},{"price":"33522.50","size":"1.10595"}],"sequence":12626795,"timestamp":"2021-07-03T00:56:40.811Z","symbol":"BTCUSDB"}}
1625273800.9279602: {"jsonrpc":"2.0","method":"updateOrderbook","params":{"ask":[{"price":"0.00026766","size":"21530.31"},{"price":"0.00027148","size":"0"}],"bid":[],"sequence":12351795,"timestamp":"2021-07-03T00:56:40.831Z","symbol":"EOSBTC"}}
1625273801.025536: {"jsonrpc":"2.0","method":"updateOrderbook","params":{"ask":[{"price":"33553.37","size":"0.05940"},{"price":"33554.11","size":"0"},{"price":"33574.04","size":"0.39780"},{"price":"33577.38","size":"0"}],"bid":[{"price":"33537.78","size":"0.77340"},{"price":"33536.83","size":"0"},{"price":"33486.32","size":"2.64430"},{"price":"33482.94","size":"0"}],"sequence":12626796,"timestamp":"2021-07-03T00:56:40.925Z","symbol":"BTCUSDB"}}
1625273801.026809: {"jsonrpc":"2.0","method":"updateOrderbook","params":{"ask":[{"price":"0.00011645","size":"4744.55"},{"price":"0.00011657","size":"0"},{"price":"0.00011768","size":"0"},{"price":"0.00011820","size":"4513.55"},{"price":"0.00014660","size":"0"},{"price":"0.00014845","size":"5718.01"},{"price":"0.00016861","size":"0"},{"price":"0.00016960","size":"7220.48"},{"price":"0.00018802","size":"0"},{"price":"0.00018838","size":"10554.74"},{"price":"0.00022198","size":"0"},{"price":"0.00022318","size":"15617.57"},{"price":"0.00026766","size":"0"},{"price":"0.00026804","size":"21530.31"}],"bid":[],"sequence":12351796,"timestamp":"2021-07-03T00:56:40.855Z","symbol":"EOSBTC"}}
1625273801.129354: {"jsonrpc":"2.0","method":"updateOrderbook","params":{"ask":[{"price":"33585.09","size":"0.95910"},{"price":"33588.37","size":"0"},{"price":"33589.36","size":"0.75370"},{"price":"33593.59","size":"0"}],"bid":[{"price":"33545.18","size":"0"},{"price":"33543.07","size":"0.02940"},{"price":"33541.48","size":"0"},{"price":"33539.03","size":"0.05460"}],"sequence":12626797,"timestamp":"2021-07-03T00:56:41.049Z","symbol":"BTCUSDB"}}
1625273801.1294148: {"jsonrpc":"2.0","method":"updateOrderbook","params":{"ask":[{"price":"33654.99","size":"0"},{"price":"33664.59","size":"0"},{"price":"33678.00","size":"0.00533"},{"price":"33686.32","size":"0.00533"},{"price":"33695.38","size":"0"},{"price":"33716.63","size":"0.00533"}],"bid":[],"sequence":7211260,"timestamp":"2021-07-03T00:56:41.043Z","symbol":"BTCPAX"}}
1625273801.131501: {"jsonrpc":"2.0","method":"updateOrderbook","params":{"ask":[{"price":"33519.36","size":"0"},{"price":"33520.87","size":"0.01234"},{"price":"35660.61","size":"1.29584"},{"price":"35758.21","size":"0"}],"bid":[],"sequence":7476993,"timestamp":"2021-07-03T00:56:41.048Z","symbol":"BTCTUSD"}}
1625273801.232265: {"jsonrpc":"2.0","method":"updateOrderbook","params":{"ask":[{"price":"35611.65","size":"0.67400"},{"price":"35622.28","size":"0"}],"bid":[],"sequence":1470728,"timestamp":"2021-07-03T00:56:41.092Z","symbol":"BTCGUSD"}}
1625273801.23232: {"jsonrpc":"2.0","method":"updateOrderbook","params":{"ask":[],"bid":[{"price":"33526.21","size":"0.09211"},{"price":"33524.90","size":"0"}],"sequence":5708328,"timestamp":"2021-07-03T00:56:41.074Z","symbol":"BTCDAI"}}
1625273801.235596: {"jsonrpc":"2.0","method":"updateOrderbook","params":{"ask":[{"price":"0.00011598","size":"89.25"},{"price":"0.00011602","size":"2106.34"},{"price":"0.00011603","size":"345.13"},{"price":"0.00011608","size":"88.49"}],"bid":[{"price":"0.00011570","size":"0"},{"price":"0.00011569","size":"493.01"},{"price":"0.00011491","size":"8378.72"},{"price":"0.00011476","size":"0"}],"sequence":12351797,"timestamp":"2021-07-03T00:56:41.138Z","symbol":"EOSBTC"}}
1625273801.2367082: {"jsonrpc":"2.0","method":"updateOrderbook","params":{"ask":[{"price":"33563.51","size":"0.91740"},{"price":"33565.37","size":"0"},{"price":"167663.25","size":"0.00012"},{"price":"167675.83","size":"0"}],"bid":[{"price":"33543.45","size":"0.02940"},{"price":"33543.07","size":"0"},{"price":"33537.78","size":"0"},{"price":"33536.38","size":"0.77340"},{"price":"33534.13","size":"0"},{"price":"33533.52","size":"1.43690"},{"price":"33524.82","size":"0"},{"price":"33523.70","size":"0.94240"},{"price":"33522.50","size":"0"},{"price":"33520.87","size":"1.10595"},{"price":"33495.77","size":"0"},{"price":"33495.75","size":"0.94140"},{"price":"33466.55","size":"1.04490"},{"price":"33460.10","size":"0"},{"price":"10060.54","size":"0"},{"price":"10059.79","size":"0.00014"}],"sequence":12626798,"timestamp":"2021-07-03T00:56:41.147Z","symbol":"BTCUSDB"}}
1625273801.240075: {"jsonrpc":"2.0","method":"updateOrderbook","params":{"ask":[{"price":"33519.93","size":"0.01234"},{"price":"33520.87","size":"0"},{"price":"33522.64","size":"0"},{"price":"33523.77","size":"0.02980"}],"bid":[],"sequence":7476994,"timestamp":"2021-07-03T00:56:41.146Z","symbol":"BTCTUSD"}}
1625273801.3315: {"jsonrpc":"2.0","method":"updateOrderbook","params":{"ask":[{"price":"33550.62","size":"0.05940"},{"price":"33553.37","size":"0"},{"price":"33561.98","size":"2.47430"},{"price":"33568.69","size":"0.75370"},{"price":"33569.64","size":"0"},{"price":"33570.81","size":"0"},{"price":"33573.34","size":"1.43490"},{"price":"33577.23","size":"0"},{"price":"33579.85","size":"0"},{"price":"33590.56","size":"1.17130"},{"price":"33597.21","size":"0"}],"bid":[{"price":"33543.45","size":"0"},{"price":"33541.24","size":"0.02940"},{"price":"33539.03","size":"0"},{"price":"33537.04","size":"0.05460"},{"price":"33535.40","size":"0"},{"price":"33534.84","size":"1.81560"},{"price":"33533.52","size":"0"},{"price":"33532.62","size":"1.43690"},{"price":"33516.56","size":"0"},{"price":"33516.23","size":"0"},{"price":"33513.70","size":"0.77390"},{"price":"33513.23","size":"1.37123"},{"price":"33494.71","size":"0"},{"price":"33491.23","size":"0.94240"}],"sequence":12626799,"timestamp":"2021-07-03T00:56:41.243Z","symbol":"BTCUSDB"}}
1625273801.331687: {"jsonrpc":"2.0","method":"updateOrderbook","params":{"ask":[],"bid":[{"price":"0.00011570","size":"493.01"},{"price":"0.00011569","size":"0"}],"sequence":12351798,"timestamp":"2021-07-03T00:56:41.237Z","symbol":"EOSBTC"}}
1625273801.331703: {"jsonrpc":"2.0","method":"updateOrderbook","params":{"ask":[{"price":"0.07644","size":"1.9169"},{"price":"0.07659","size":"0"}],"bid":[],"sequence":7339978,"timestamp":"2021-07-03T00:56:41.207Z","symbol":"MKRBTC"}}
1625273801.331715: {"jsonrpc":"2.0","method":"updateOrderbook","params":{"ask":[{"price":"33522.36","size":"0.02980"},{"price":"33523.77","size":"0"}],"bid":[{"price":"33496.44","size":"0.01475"},{"price":"33491.68","size":"0"}],"sequence":7476995,"timestamp":"2021-07-03T00:56:41.238Z","symbol":"BTCTUSD"}}
1625273801.430513: {"jsonrpc":"2.0","method":"updateOrderbook","params":{"ask":[{"price":"33589.36","size":"0"},{"price":"33592.46","size":"0.75370"},{"price":"33600.24","size":"1.07210"},{"price":"33607.60","size":"0"},{"price":"33611.82","size":"0.41570"},{"price":"33622.31","size":"0"}],"bid":[{"price":"33542.20","size":"0.02940"},{"price":"33541.81","size":"0"},{"price":"33541.24","size":"0"},{"price":"33538.26","size":"0.38210"},{"price":"33536.38","size":"0"},{"price":"33535.11","size":"0.77340"},{"price":"33532.62","size":"0"},{"price":"33531.99","size":"1.43690"},{"price":"33523.70","size":"0"},{"price":"33522.37","size":"0.94240"},{"price":"33520.87","size":"0"},{"price":"33520.37","size":"1.10595"}],"sequence":12626800,"timestamp":"2021-07-03T00:56:41.336Z","symbol":"BTCUSDB"}}
1625273801.430539: {"jsonrpc":"2.0","method":"updateOrderbook","params":{"ask":[{"price":"0.00011579","size":"99.00"},{"price":"0.00011580","size":"230.00"},{"price":"0.00011820","size":"0"},{"price":"0.00011981","size":"4513.55"},{"price":"0.00014845","size":"0"},{"price":"0.00015225","size":"5718.01"},{"price":"0.00016960","size":"0"},{"price":"0.00017187","size":"7220.48"},{"price":"0.00018838","size":"0"},{"price":"0.00018932","size":"10554.74"},{"price":"0.00022318","size":"0"},{"price":"0.00022582","size":"15617.57"},{"price":"0.00026804","size":"0"},{"price":"0.00026901","size":"21530.31"}],"bid":[],"sequence":12351799,"timestamp":"2021-07-03T00:56:41.311Z","symbol":"EOSBTC"}}
1625273801.4305851: {"jsonrpc":"2.0","method":"updateOrderbook","params":{"ask":[{"price":"33677.24","size":"0.00533"},{"price":"33678.00","size":"0"}],"bid":[],"sequence":7211261,"timestamp":"2021-07-03T00:56:41.268Z","symbol":"BTCPAX"}}
1625273801.43387: {"jsonrpc":"2.0","method":"updateOrderbook","params":{"ask":[{"price":"33519.46","size":"0.01234"},{"price":"33519.93","size":"0"}],"bid":[],"sequence":7476996,"timestamp":"2021-07-03T00:56:41.268Z","symbol":"BTCTUSD"}}
1625273801.5257611: {"jsonrpc":"2.0","method":"updateOrderbook","params":{"ask":[],"bid":[{"price":"33526.21","size":"0"},{"price":"33525.32","size":"0.09211"}],"sequence":5708329,"timestamp":"2021-07-03T00:56:41.404Z","symbol":"BTCDAI"}}
1625273801.527549: {"jsonrpc":"2.0","method":"updateOrderbook","params":{"ask":[{"price":"33558.83","size":"0.10260"},{"price":"33564.52","size":"0"}],"bid":[{"price":"33502.83","size":"0"},{"price":"33501.54","size":"0.96010"}],"sequence":12626801,"timestamp":"2021-07-03T00:56:41.412Z","symbol":"BTCUSDB"}}
1625273801.52761: {"jsonrpc":"2.0","method":"updateOrderbook","params":{"ask":[],"bid":[],"sequence":12351800,"timestamp":"2021-07-03T00:56:41.416Z","symbol":"EOSBTC"}}
1625273801.53353: {"jsonrpc":"2.0","method":"updateOrderbook","params":{"ask":[{"price":"33677.24","size":"0"},{"price":"33679.25","size":"0.00533"}],"bid":[],"sequence":7211262,"timestamp":"2021-07-03T00:56:41.404Z","symbol":"BTCPAX"}}
1625273801.533547: {"jsonrpc":"2.0","method":"updateOrderbook","params":{"ask":[{"price":"33518.47","size":"0.01234"},{"price":"33519.46","size":"0"},{"price":"33521.10","size":"0.02980"},{"price":"33522.36","size":"0"}],"bid":[],"sequence":7476997,"timestamp":"2021-07-03T00:56:41.427Z","symbol":"BTCTUSD"}}
1625273801.624396: {"jsonrpc":"2.0","method":"updateOrderbook","params":{"ask":[{"price":"33550.92","size":"0.07070"},{"price":"33552.91","size":"0"},{"price":"33735.22","size":"0.65060"},{"price":"33754.18","size":"0"}],"bid":[],"sequence":12626802,"timestamp":"2021-07-03T00:56:41.535Z","symbol":"BTCUSDB"}}
1625273801.624456: {"jsonrpc":"2.0","method":"updateOrderbook","params":{"ask":[{"price":"0.00011580","size":"354.04"},{"price":"0.00011581","size":"412.52"}],"bid":[],"sequence":12351801,"timestamp":"2021-07-03T00:56:41.521Z","symbol":"EOSBTC"}}
1625273801.7427552: {"jsonrpc":"2.0","method":"updateOrderbook","params":{"ask":[],"bid":[{"price":"33521.05","size":"1.10595"},{"price":"33520.37","size":"0"}],"sequence":12626803,"timestamp":"2021-07-03T00:56:41.555Z","symbol":"BTCUSDB"}}
1625273801.742812: {"jsonrpc":"2.0","method":"updateOrderbook","params":{"ask":[],"bid":[{"price":"0.00011474","size":"0"},{"price":"0.00011460","size":"4559.60"}],"sequence":12351802,"timestamp":"2021-07-03T00:56:41.575Z","symbol":"EOSBTC"}}
1625273801.834681: {"jsonrpc":"2.0","method":"updateOrderbook","params":{"ask":[{"price":"33677.00","size":"0.00533"},{"price":"33679.25","size":"0"}],"bid":[],"sequence":7211263,"timestamp":"2021-07-03T00:56:41.738Z","symbol":"BTCPAX"}}
1625273801.834713: {"jsonrpc":"2.0","method":"updateOrderbook","params":{"ask":[{"price":"0.07658","size":"5.5724"},{"price":"0.07675","size":"0.7100"}],"bid":[],"sequence":7339979,"timestamp":"2021-07-03T00:56:41.735Z","symbol":"MKRBTC"}}
1625273801.934165: {"jsonrpc":"2.0","method":"updateOrderbook","params":{"ask":[{"price":"33550.92","size":"0.74140"},{"price":"33551.90","size":"1.03952"},{"price":"33554.68","size":"0"},{"price":"33558.91","size":"0"},{"price":"33589.26","size":"0.75370"},{"price":"33592.46","size":"0"},{"price":"33725.56","size":"0.77520"},{"price":"33745.85","size":"0"}],"bid":[],"sequence":12626804,"timestamp":"2021-07-03T00:56:41.849Z","symbol":"BTCUSDB"}}
1625273801.934247: {"jsonrpc":"2.0","method":"updateOrderbook","params":{"ask":[{"price":"0.07644","size":"0"},{"price":"0.07658","size":"5.1208"},{"price":"0.07678","size":"5.7931"},{"price":"0.07679","size":"2.6323"},{"price":"0.07687","size":"4.2389"}],"bid":[],"sequence":7339980,"timestamp":"2021-07-03T00:56:41.802Z","symbol":"MKRBTC"}}
1625273801.934273: {"jsonrpc":"2.0","method":"updateOrderbook","params":{"ask":[{"price":"33518.47","size":"0"},{"price":"33518.81","size":"0.01234"}],"bid":[],"sequence":7476998,"timestamp":"2021-07-03T00:56:41.796Z","symbol":"BTCTUSD"}}
1625273802.032044: {"jsonrpc":"2.0","method":"updateOrderbook","params":{"ask":[],"bid":[{"price":"0.00011444","size":"16444.03"},{"price":"0.00011422","size":"0"}],"sequence":12351803,"timestamp":"2021-07-03T00:56:41.887Z","symbol":"EOSBTC"}}
1625273802.03206: {"jsonrpc":"2.0","method":"updateOrderbook","params":{"ask":[{"price":"33518.81","size":"0"},{"price":"33519.22","size":"0.01234"}],"bid":[],"sequence":7476999,"timestamp":"2021-07-03T00:56:41.862Z","symbol":"BTCTUSD"}}
1625273802.135576: {"jsonrpc":"2.0","method":"updateOrderbook","params":{"ask":[{"price":"33660.30","size":"1.07700"},{"price":"33703.36","size":"0"}],"bid":[],"sequence":12626805,"timestamp":"2021-07-03T00:56:41.957Z","symbol":"BTCUSDB"}}
1625273802.2222002: {"jsonrpc":"2.0","method":"updateOrderbook","params":{"ask":[],"bid":[{"price":"33526.13","size":"0.09211"},{"price":"33525.32","size":"0"}],"sequence":5708330,"timestamp":"2021-07-03T00:56:42.083Z","symbol":"BTCDAI"}}
1625273802.23019: {"jsonrpc":"2.0","method":"updateOrderbook","params":{"ask":[{"price":"167637.85","size":"0.00016"},{"price":"167663.25","size":"0"}],"bid":[{"price":"33522.29","size":"1.10595"},{"price":"33521.05","size":"0"},{"price":"10059.79","size":"0"},{"price":"10058.27","size":"0.00015"}],"sequence":12626806,"timestamp":"2021-07-03T00:56:42.110Z","symbol":"BTCUSDB"}}
1625273802.230245: {"jsonrpc":"2.0","method":"updateOrderbook","params":{"ask":[{"price":"33677.00","size":"0"},{"price":"33678.63","size":"0.00533"}],"bid":[],"sequence":7211264,"timestamp":"2021-07-03T00:56:42.121Z","symbol":"BTCPAX"}}
1625273802.230261: {"jsonrpc":"2.0","method":"updateOrderbook","params":{"ask":[{"price":"33519.22","size":"0"},{"price":"33521.10","size":"0"},{"price":"33521.83","size":"0.01234"},{"price":"33524.73","size":"0.02980"}],"bid":[],"sequence":7477000,"timestamp":"2021-07-03T00:56:42.148Z","symbol":"BTCTUSD"}}
1625273802.33335: {"jsonrpc":"2.0","method":"updateOrderbook","params":{"ask":[{"price":"33593.57","size":"0.94720"},{"price":"33599.67","size":"0"}],"bid":[{"price":"33542.20","size":"0"},{"price":"33540.20","size":"0.02940"}],"sequence":12626807,"timestamp":"2021-07-03T00:56:42.247Z","symbol":"BTCUSDB"}}
1625273802.333427: {"jsonrpc":"2.0","method":"updateOrderbook","params":{"ask":[{"price":"0.00011580","size":"230.00"},{"price":"0.00011581","size":"536.56"}],"bid":[{"price":"0.00011571","size":"723.01"},{"price":"0.00011570","size":"0"},{"price":"0.00010537","size":"23147.93"},{"price":"0.00010304","size":"0"},{"price":"0.00009247","size":"12370.85"},{"price":"0.00008804","size":"0"}],"sequence":12351804,"timestamp":"2021-07-03T00:56:42.206Z","symbol":"EOSBTC"}}
1625273802.333459: {"jsonrpc":"2.0","method":"updateOrderbook","params":{"ask":[{"price":"33678.63","size":"0"},{"price":"33679.32","size":"0.00533"}],"bid":[],"sequence":7211265,"timestamp":"2021-07-03T00:56:42.251Z","symbol":"BTCPAX"}}
1625273802.333478: {"jsonrpc":"2.0","method":"updateOrderbook","params":{"ask":[{"price":"0.07701","size":"6.2765"},{"price":"0.07723","size":"0"}],"bid":[{"price":"0.07605","size":"1.9877"},{"price":"0.07599","size":"0"}],"sequence":7339981,"timestamp":"2021-07-03T00:56:42.210Z","symbol":"MKRBTC"}}
1625273802.333496: {"jsonrpc":"2.0","method":"updateOrderbook","params":{"ask":[{"price":"33521.83","size":"0"},{"price":"33522.81","size":"0.01234"}],"bid":[],"sequence":7477001,"timestamp":"2021-07-03T00:56:42.251Z","symbol":"BTCTUSD"}}
1625273802.4240818: {"jsonrpc":"2.0","method":"updateOrderbook","params":{"ask":[],"bid":[{"price":"33527.35","size":"0.09211"},{"price":"33526.13","size":"0"}],"sequence":5708331,"timestamp":"2021-07-03T00:56:42.274Z","symbol":"BTCDAI"}}
1625273802.426065: {"jsonrpc":"2.0","method":"updateOrderbook","params":{"ask":[{"price":"33554.03","size":"0.45140"},{"price":"33559.11","size":"0"},{"price":"33560.37","size":"0.91740"},{"price":"33563.51","size":"0"},{"price":"33572.10","size":"1.75290"},{"price":"33575.08","size":"0"}],"bid":[{"price":"33534.84","size":"0"},{"price":"33533.91","size":"1.81560"},{"price":"33531.99","size":"0"},{"price":"33529.86","size":"1.43690"},{"price":"33522.29","size":"0"},{"price":"33521.57","size":"1.10595"}],"sequence":12626808,"timestamp":"2021-07-03T00:56:42.295Z","symbol":"BTCUSDB"}}
1625273802.426131: {"jsonrpc":"2.0","method":"updateOrderbook","params":{"ask":[{"price":"0.00011579","size":"0"},{"price":"0.00011581","size":"99.00"},{"price":"0.00011582","size":"657.00"},{"price":"0.00013280","size":"22588.08"},{"price":"0.00013454","size":"0"},{"price":"0.00015632","size":"26975.46"},{"price":"0.00015805","size":"0"}],"bid":[{"price":"0.00011570","size":"915.60"},{"price":"0.00011568","size":"796.96"}],"sequence":12351805,"timestamp":"2021-07-03T00:56:42.316Z","symbol":"EOSBTC"}}
1625273802.435285: {"jsonrpc":"2.0","method":"updateOrderbook","params":{"ask":[{"price":"0.07647","size":"0.0003"},{"price":"0.07650","size":"0"}],"bid":[],"sequence":7339982,"timestamp":"2021-07-03T00:56:42.311Z","symbol":"MKRBTC"}}
1625273802.435315: {"jsonrpc":"2.0","method":"updateOrderbook","params":{"ask":[{"price":"33522.81","size":"0"},{"price":"33523.24","size":"0.01234"},{"price":"33524.73","size":"0"},{"price":"33526.09","size":"0.02980"}],"bid":[],"sequence":7477002,"timestamp":"2021-07-03T00:56:42.257Z","symbol":"BTCTUSD"}}
1625273802.526061: {"jsonrpc":"2.0","method":"updateOrderbook","params":{"ask":[{"price":"34245.33","size":"0.00590"},{"price":"34257.46","size":"0"}],"bid":[],"sequence":1470729,"timestamp":"2021-07-03T00:56:42.384Z","symbol":"BTCGUSD"}}
1625273802.526119: {"jsonrpc":"2.0","method":"updateOrderbook","params":{"ask":[],"bid":[{"price":"33524.61","size":"0.17106"},{"price":"33521.94","size":"0"}],"sequence":5708332,"timestamp":"2021-07-03T00:56:42.431Z","symbol":"BTCDAI"}}
1625273802.54622: {"jsonrpc":"2.0","method":"updateOrderbook","params":{"ask":[{"price":"0.00011603","size":"0"},{"price":"0.00011607","size":"3017.50"}],"bid":[],"sequence":12351806,"timestamp":"2021-07-03T00:56:42.445Z","symbol":"EOSBTC"}}
1625273802.546278: {"jsonrpc":"2.0","method":"updateOrderbook","params":{"ask":[{"price":"27841.39","size":"0.06255"},{"price":"27850.45","size":"0"}],"bid":[],"sequence":1054666,"timestamp":"2021-07-03T00:56:42.367Z","symbol":"BTCEURS"}}
1625273802.546367: {"jsonrpc":"2.0","method":"updateOrderbook","params":{"ask":[{"price":"33678.71","size":"0.00533"},{"price":"33679.32","size":"0"}],"bid":[],"sequence":7211266,"timestamp":"2021-07-03T00:56:42.375Z","symbol":"BTCPAX"}}
1625273802.546388: {"jsonrpc":"2.0","method":"updateOrderbook","params":{"ask":[{"price":"33522.81","size":"0.01234"},{"price":"33523.24","size":"0"}],"bid":[{"price":"33496.44","size":"0"},{"price":"33494.01","size":"0.01475"}],"sequence":7477003,"timestamp":"2021-07-03T00:56:42.452Z","symbol":"BTCTUSD"}}
1625273802.627437: {"jsonrpc":"2.0","method":"updateOrderbook","params":{"ask":[],"bid":[{"price":"33540.59","size":"0.02940"},{"price":"33540.20","size":"0"},{"price":"33533.91","size":"0"},{"price":"33532.38","size":"1.81560"},{"price":"33532.24","size":"0"},{"price":"33527.07","size":"0.10140"}],"sequence":12626809,"timestamp":"2021-07-03T00:56:42.517Z","symbol":"BTCUSDB"}}
1625273802.627498: {"jsonrpc":"2.0","method":"updateOrderbook","params":{"ask":[{"price":"0.00011581","size":"223.04"},{"price":"0.00011582","size":"532.96"},{"price":"0.00011598","size":"0"},{"price":"0.00011602","size":"2195.59"}],"bid":[],"sequence":12351807,"timestamp":"2021-07-03T00:56:42.521Z","symbol":"EOSBTC"}}
1625273802.628913: {"jsonrpc":"2.0","method":"updateOrderbook","params":{"ask":[{"price":"33678.03","size":"0.00533"},{"price":"33678.71","size":"0"}],"bid":[],"sequence":7211267,"timestamp":"2021-07-03T00:56:42.484Z","symbol":"BTCPAX"}}
1625273802.637171: {"jsonrpc":"2.0","method":"updateOrderbook","params":{"ask":[{"price":"33521.88","size":"0.01234"},{"price":"33522.81","size":"0"}],"bid":[],"sequence":7477004,"timestamp":"2021-07-03T00:56:42.454Z","symbol":"BTCTUSD"}}
1625273802.7253408: {"jsonrpc":"2.0","method":"updateOrderbook","params":{"ask":[{"price":"33632.04","size":"0.71880"},{"price":"33643.30","size":"0"}],"bid":[{"price":"33538.26","size":"0"},{"price":"33537.12","size":"0.38210"},{"price":"33497.57","size":"0"},{"price":"33495.75","size":"0"},{"price":"33494.66","size":"1.43690"},{"price":"33494.28","size":"0.94140"}],"sequence":12626810,"timestamp":"2021-07-03T00:56:42.613Z","symbol":"BTCUSDB"}}
1625273802.725388: {"jsonrpc":"2.0","method":"updateOrderbook","params":{"ask":[{"price":"0.00011893","size":"0"},{"price":"0.00011952","size":"6250.68"},{"price":"0.00012294","size":"16338.72"},{"price":"0.00012331","size":"0"},{"price":"0.00024186","size":"39545.26"},{"price":"0.00024422","size":"0"},{"price":"0.00034323","size":"56176.40"},{"price":"0.00034802","size":"0"}],"bid":[],"sequence":12351808,"timestamp":"2021-07-03T00:56:42.635Z","symbol":"EOSBTC"}}
1625273802.735927: {"jsonrpc":"2.0","method":"updateOrderbook","params":{"ask":[{"price":"33521.51","size":"0.01234"},{"price":"33521.88","size":"0"},{"price":"33524.36","size":"0.02980"},{"price":"33526.09","size":"0"}],"bid":[],"sequence":7477005,"timestamp":"2021-07-03T00:56:42.634Z","symbol":"BTCTUSD"}}
1625273802.8282728: {"jsonrpc":"2.0","method":"updateOrderbook","params":{"ask":[{"price":"33570.83","size":"0.01174"},{"price":"33574.96","size":"0"},{"price":"33579.06","size":"1.49780"},{"price":"33581.15","size":"0.79591"},{"price":"33582.89","size":"0"},{"price":"33585.96","size":"0"}],"bid":[],"sequence":12626811,"timestamp":"2021-07-03T00:56:42.748Z","symbol":"BTCUSDB"}}
1625273802.828335: {"jsonrpc":"2.0","method":"updateOrderbook","params":{"ask":[],"bid":[{"price":"33506.38","size":"0"},{"price":"33499.21","size":"0.01070"},{"price":"33418.20","size":"0"},{"price":"33377.39","size":"0.37050"},{"price":"32893.47","size":"0"},{"price":"32840.36","size":"1.26650"},{"price":"31215.03","size":"0"},{"price":"30922.33","size":"1.68120"}],"sequence":7211268,"timestamp":"2021-07-03T00:56:42.697Z","symbol":"BTCPAX"}}
1625273802.828365: {"jsonrpc":"2.0","method":"updateOrderbook","params":{"ask":[{"price":"0.07672","size":"0.6900"},{"price":"0.07673","size":"2.6323"},{"price":"0.07677","size":"0"},{"price":"0.07679","size":"0"},{"price":"0.07773","size":"9.6365"},{"price":"0.07822","size":"0"}],"bid":[{"price":"0.07554","size":"0.1230"},{"price":"0.07552","size":"0"},{"price":"0.07551","size":"0"},{"price":"0.07548","size":"0.6900"}],"sequence":7339983,"timestamp":"2021-07-03T00:56:42.727Z","symbol":"MKRBTC"}}
1625273802.829699: {"jsonrpc":"2.0","method":"updateOrderbook","params":{"ask":[],"bid":[{"price":"0.00011570","size":"1002.80"},{"price":"0.00011566","size":"99.24"}],"sequence":12351809,"timestamp":"2021-07-03T00:56:42.672Z","symbol":"EOSBTC"}}
1625273802.829756: {"jsonrpc":"2.0","method":"updateOrderbook","params":{"ask":[{"price":"35660.61","size":"0"},{"price":"35777.38","size":"1.29584"}],"bid":[],"sequence":7477006,"timestamp":"2021-07-03T00:56:42.704Z","symbol":"BTCTUSD"}}
1625273802.926311: {"jsonrpc":"2.0","method":"updateOrderbook","params":{"ask":[],"bid":[{"price":"33541.04","size":"0.02940"},{"price":"33540.59","size":"0"},{"price":"33537.04","size":"0"},{"price":"33535.45","size":"0.05460"},{"price":"33486.32","size":"0"},{"price":"33480.73","size":"2.64430"},{"price":"33466.55","size":"0"},{"price":"33457.69","size":"1.04490"},{"price":"33449.94","size":"0"},{"price":"33438.21","size":"1.13040"}],"sequence":12626812,"timestamp":"2021-07-03T00:56:42.849Z","symbol":"BTCUSDB"}}
1625273802.933832: {"jsonrpc":"2.0","method":"updateOrderbook","params":{"ask":[],"bid":[{"price":"0.07592","size":"1.9731"},{"price":"0.07588","size":"1.4156"}],"sequence":7339984,"timestamp":"2021-07-03T00:56:42.800Z","symbol":"MKRBTC"}}
1625273802.933859: {"jsonrpc":"2.0","method":"updateOrderbook","params":{"ask":[],"bid":[{"price":"32334.08","size":"1.67560"},{"price":"32199.15","size":"0"}],"sequence":7477007,"timestamp":"2021-07-03T00:56:42.808Z","symbol":"BTCTUSD"}}
1625273803.0248692: {"jsonrpc":"2.0","method":"updateOrderbook","params":{"ask":[],"bid":[{"price":"33541.04","size":"0"},{"price":"33538.16","size":"0.02940"}],"sequence":12626813,"timestamp":"2021-07-03T00:56:42.951Z","symbol":"BTCUSDB"}}
1625273803.02491: {"jsonrpc":"2.0","method":"updateOrderbook","params":{"ask":[{"price":"0.00011580","size":"329.00"},{"price":"0.00011581","size":"124.04"},{"price":"0.00016056","size":"19505.60"},{"price":"0.00016111","size":"0"},{"price":"0.00023639","size":"30396.48"},{"price":"0.00023741","size":"0"},{"price":"0.00091746","size":"86093.30"},{"price":"0.00093752","size":"0"}],"bid":[],"sequence":12351810,"timestamp":"2021-07-03T00:56:42.916Z","symbol":"EOSBTC"}}
1625273803.0285718: {"jsonrpc":"2.0","method":"updateOrderbook","params":{"ask":[{"price":"0.09487","size":"3.7522"},{"price":"0.09752","size":"0"}],"bid":[{"price":"0.07605","size":"1.4327"},{"price":"0.07601","size":"0.5550"},{"price":"0.07581","size":"0"},{"price":"0.07573","size":"2.6761"}],"sequence":7339985,"timestamp":"2021-07-03T00:56:42.905Z","symbol":"MKRBTC"}}
1625273803.12764: {"jsonrpc":"2.0","method":"updateOrderbook","params":{"ask":[{"price":"33579.06","size":"0"},{"price":"33582.60","size":"1.49780"},{"price":"33589.26","size":"0"},{"price":"33593.59","size":"0.75370"}],"bid":[{"price":"33538.16","size":"0"},{"price":"33537.84","size":"0.02940"},{"price":"33535.45","size":"0"},{"price":"33533.70","size":"0.05460"},{"price":"33471.67","size":"0.43060"},{"price":"33467.72","size":"1.04000"},{"price":"33466.15","size":"0"},{"price":"33461.87","size":"0"}],"sequence":12626814,"timestamp":"2021-07-03T00:56:43.033Z","symbol":"BTCUSDB"}}
1625273803.128006: {"jsonrpc":"2.0","method":"updateOrderbook","params":{"ask":[],"bid":[{"price":"31215.04","size":"0"}],"sequence":7211269,"timestamp":"2021-07-03T00:56:43.050Z","symbol":"BTCPAX"}}
1625273803.131556: {"jsonrpc":"2.0","method":"updateOrderbook","params":{"ask":[],"bid":[{"price":"0.07542","size":"0"},{"price":"0.07541","size":"0"},{"price":"0.07463","size":"0.7100"}],"sequence":7339986,"timestamp":"2021-07-03T00:56:43.046Z","symbol":"MKRBTC"}}
1625273803.2382772: {"jsonrpc":"2.0","method":"updateOrderbook","params":{"ask":[],"bid":[{"price":"2137.545","size":"0"},{"price":"2137.049","size":"0.1619"},{"price":"2136.403","size":"0"},{"price":"2135.485","size":"1.9493"},{"price":"2117.684","size":"0"},{"price":"2114.338","size":"20.7429"}],"sequence":1513065,"timestamp":"2021-07-03T00:56:43.126Z","symbol":"ETHDAI"}}
1625273803.238417: {"jsonrpc":"2.0","method":"updateOrderbook","params":{"ask":[{"price":"33546.90","size":"0.07707"},{"price":"33551.53","size":"0"},{"price":"33555.28","size":"0"},{"price":"33561.23","size":"0.18610"}],"bid":[{"price":"33527.35","size":"0"},{"price":"33524.61","size":"0"},{"price":"33515.27","size":"0"},{"price":"33512.84","size":"0.09211"},{"price":"33507.62","size":"0"},{"price":"33507.39","size":"0.17106"},{"price":"33499.27","size":"0.31769"},{"price":"33491.99","size":"0.37409"},{"price":"33462.68","size":"0"},{"price":"33455.98","size":"0"},{"price":"33454.48","size":"0.00920"},{"price":"33453.76","size":"0"},{"price":"33444.48","size":"0.03610"},{"price":"33441.96","size":"0"},{"price":"33435.26","size":"0"},{"price":"33429.11","size":"0.09140"},{"price":"33428.56","size":"0"},{"price":"33421.26","size":"0.14150"},{"price":"33416.31","size":"0"},{"price":"33403.31","size":"0.19360"},{"price":"33401.21","size":"0"},{"price":"33383.55","size":"0.23620"},{"price":"33376.85","size":"0.38830"},{"price":"33353.38","size":"0.46920"},{"price":"33230.64","size":"0"},{"price":"32969.47","size":"1.84640"},{"price":"32116.16","size":"0"},{"price":"31071.11","size":"2.30540"},{"price":"30108.66","size":"0"},{"price":"29819.66","size":"3.10680"},{"price":"29079.94","size":"0"},{"price":"28730.30","size":"4.54640"},{"price":"27967.12","size":"0"},{"price":"27461.42","size":"1.87330"}],"sequence":5708333,"timestamp":"2021-07-03T00:56:43.147Z","symbol":"BTCDAI"}}
1625273803.2384791: {"jsonrpc":"2.0","method":"updateOrderbook","params":{"ask":[{"price":"33547.78","size":"0.02460"},{"price":"33548.64","size":"0.05940"},{"price":"33550.62","size":"0"},{"price":"33550.74","size":"0"},{"price":"33569.29","size":"0.12875"},{"price":"33577.32","size":"0"},{"price":"167633.78","size":"0.00013"},{"price":"167637.85","size":"0"}],"bid":[{"price":"33549.54","size":"0"},{"price":"33539.98","size":"0.02940"},{"price":"33537.84","size":"0"},{"price":"33536.69","size":"0.17179"},{"price":"33532.38","size":"0"},{"price":"33529.86","size":"0"},{"price":"33529.40","size":"1.81560"},{"price":"33527.41","size":"1.43690"},{"price":"33522.37","size":"0"},{"price":"33521.57","size":"0"},{"price":"33515.96","size":"1.01630"},{"price":"33512.90","size":"1.10595"},{"price":"33510.82","size":"0"},{"price":"33509.59","size":"0"},{"price":"33506.47","size":"0.37734"},{"price":"33504.83","size":"0.32211"},{"price":"33494.66","size":"0"},{"price":"33491.23","size":"0"},{"price":"33490.42","size":"1.43690"},{"price":"33488.55","size":"0"},{"price":"33488.19","size":"2.26140"},{"price":"33478.84","size":"0"},{"price":"33471.67","size":"0"},{"price":"33467.72","size":"0"},{"price":"33466.16","size":"0.43060"},{"price":"33462.60","size":"0.40014"},{"price":"33461.57","size":"1.04000"},{"price":"33454.47","size":"0.63855"},{"price":"33452.53","size":"0"},{"price":"33446.07","size":"1.46790"},{"price":"33427.16","size":"0"},{"price":"33417.05","size":"0.61286"},{"price":"33243.59","size":"0"},{"price":"33189.25","size":"1.54758"},{"price":"33121.74","size":"0"},{"price":"33080.26","size":"2.20382"},{"price":"32552.81","size":"0"},{"price":"32461.71","size":"2.84176"},{"price":"31078.15","size":"0"},{"price":"30993.51","size":"3.00659"},{"price":"30723.38","size":"0"},{"price":"30639.27","size":"2.82516"},{"price":"10058.27","size":"0"},{"price":"10058.02","size":"0.00010"}],"sequence":12626815,"timestamp":"2021-07-03T00:56:43.151Z","symbol":"BTCUSDB"}}
1625273803.238539: {"jsonrpc":"2.0","method":"updateOrderbook","params":{"ask":[{"price":"0.00076674","size":"42091.73"},{"price":"0.00077138","size":"0"}],"bid":[{"price":"0.00011571","size":"921.53"},{"price":"0.00011567","size":"0"}],"sequence":12351811,"timestamp":"2021-07-03T00:56:43.146Z","symbol":"EOSBTC"}}
1625273803.238553: {"jsonrpc":"2.0","method":"updateOrderbook","params":{"ask":[],"bid":[{"price":"27468.45","size":"0"},{"price":"27463.51","size":"0.06040"}],"sequence":1054667,"timestamp":"2021-07-03T00:56:43.118Z","symbol":"BTCEURS"}}
1625273803.238563: {"jsonrpc":"2.0","method":"updateOrderbook","params":{"ask":[{"price":"33677.82","size":"0.00533"},{"price":"33678.03","size":"0"}],"bid":[{"price":"31114.50","size":"0.00261"}],"sequence":7211270,"timestamp":"2021-07-03T00:56:43.123Z","symbol":"BTCPAX"}}
1625273803.238574: {"jsonrpc":"2.0","method":"updateOrderbook","params":{"ask":[],"bid":[{"price":"0.07555","size":"0.6900"},{"price":"0.07548","size":"0"}],"sequence":7339987,"timestamp":"2021-07-03T00:56:43.132Z","symbol":"MKRBTC"}}
1625273803.2406201: {"jsonrpc":"2.0","method":"updateOrderbook","params":{"ask":[{"price":"33520.83","size":"0.01234"},{"price":"33521.51","size":"0"}],"bid":[{"price":"30621.95","size":"1.39725"},{"price":"30566.25","size":"0"}],"sequence":7477008,"timestamp":"2021-07-03T00:56:43.125Z","symbol":"BTCTUSD"}}
1625273803.3265128: {"jsonrpc":"2.0","method":"updateOrderbook","params":{"ask":[{"price":"33546.90","size":"0"},{"price":"33551.53","size":"0.07707"}],"bid":[],"sequence":5708334,"timestamp":"2021-07-03T00:56:43.245Z","symbol":"BTCDAI"}}
1625273803.3307672: {"jsonrpc":"2.0","method":"updateOrderbook","params":{"ask":[{"price":"33546.30","size":"0.02460"},{"price":"33547.78","size":"0"},{"price":"33558.42","size":"0.95910"},{"price":"33561.98","size":"1.51520"},{"price":"33566.51","size":"0.75370"},{"price":"33568.69","size":"0"},{"price":"33579.48","size":"1.49780"},{"price":"33582.60","size":"0"},{"price":"33591.43","size":"1.43490"},{"price":"33595.18","size":"0"}],"bid":[{"price":"33539.98","size":"0"},{"price":"33539.49","size":"0.02940"},{"price":"33537.12","size":"0"},{"price":"33535.57","size":"0.05460"},{"price":"33535.11","size":"0"},{"price":"33534.76","size":"0.38210"},{"price":"33534.21","size":"0.77340"},{"price":"33533.70","size":"0"},{"price":"33529.40","size":"0"},{"price":"33527.41","size":"0"},{"price":"33526.65","size":"1.81560"},{"price":"33520.43","size":"1.43690"},{"price":"33515.96","size":"0.07390"},{"price":"33513.70","size":"0"},{"price":"33513.23","size":"0"},{"price":"33512.90","size":"0"},{"price":"33510.78","size":"0.77390"},{"price":"33509.84","size":"0.94240"},{"price":"33509.73","size":"0"},{"price":"33509.23","size":"1.37123"},{"price":"33507.87","size":"0.64790"},{"price":"33502.50","size":"1.10595"},{"price":"33501.54","size":"0"},{"price":"33500.56","size":"0"},{"price":"33499.63","size":"0.96010"},{"price":"33498.85","size":"0"},{"price":"33493.41","size":"0.77340"},{"price":"33492.12","size":"0"},{"price":"33491.57","size":"1.81560"},{"price":"33488.48","size":"1.43580"},{"price":"33470.48","size":"0"},{"price":"33466.16","size":"0"},{"price":"33464.24","size":"0.49410"},{"price":"33461.26","size":"0.43060"},{"price":"33423.16","size":"0"},{"price":"33412.89","size":"0.87852"}],"sequence":12626816,"timestamp":"2021-07-03T00:56:43.235Z","symbol":"BTCUSDB"}}
1625273803.330862: {"jsonrpc":"2.0","method":"updateOrderbook","params":{"ask":[{"price":"0.00011581","size":"412.52"},{"price":"0.00011582","size":"244.48"},{"price":"0.00011619","size":"3380.01"},{"price":"0.00011621","size":"290.00"},{"price":"0.00011626","size":"0"},{"price":"0.00011630","size":"9697.41"},{"price":"0.00013280","size":"0"},{"price":"0.00013535","size":"22588.08"},{"price":"0.00015632","size":"0"},{"price":"0.00015902","size":"26975.46"},{"price":"0.00024186","size":"0"},{"price":"0.00024529","size":"39545.26"},{"price":"0.00034323","size":"0"},{"price":"0.00035035","size":"56176.40"},{"price":"0.00091746","size":"0"},{"price":"0.00094746","size":"86093.30"}],"bid":[{"price":"0.00011516","size":"1102.37"},{"price":"0.00011514","size":"2384.91"}],"sequence":12351812,"timestamp":"2021-07-03T00:56:43.196Z","symbol":"EOSBTC"}}
1625273803.335572: {"jsonrpc":"2.0","method":"updateOrderbook","params":{"ask":[],"bid":[{"price":"33377.39","size":"0"},{"price":"33346.81","size":"0.37050"},{"price":"30922.33","size":"0"},{"price":"30691.99","size":"1.68120"}],"sequence":7211271,"timestamp":"2021-07-03T00:56:43.198Z","symbol":"BTCPAX"}}
1625273803.335613: {"jsonrpc":"2.0","method":"updateOrderbook","params":{"ask":[{"price":"0.09487","size":"0"},{"price":"0.09592","size":"3.7522"}],"bid":[{"price":"0.07605","size":"0"},{"price":"0.07602","size":"1.9446"},{"price":"0.07462","size":"0"}],"sequence":7339988,"timestamp":"2021-07-03T00:56:43.245Z","symbol":"MKRBTC"}}
1625273803.3356302: {"jsonrpc":"2.0","method":"updateOrderbook","params":{"ask":[{"price":"33517.99","size":"0.01234"},{"price":"33520.83","size":"0"},{"price":"33521.99","size":"0.02980"},{"price":"33524.36","size":"0"}],"bid":[{"price":"33511.44","size":"0"},{"price":"33505.13","size":"0.00970"},{"price":"33467.49","size":"0"},{"price":"33445.02","size":"0.20870"},{"price":"33433.97","size":"0"},{"price":"33411.31","size":"0.26550"},{"price":"32334.08","size":"0"},{"price":"32254.34","size":"1.67560"}],"sequence":7477009,"timestamp":"2021-07-03T00:56:43.224Z","symbol":"BTCTUSD"}}
1625273803.424258: {"jsonrpc":"2.0","method":"updateOrderbook","params":{"ask":[{"price":"34233.07","size":"0.00400"},{"price":"34243.70","size":"0"},{"price":"34928.05","size":"0.75000"},{"price":"34938.81","size":"0"}],"bid":[],"sequence":1470730,"timestamp":"2021-07-03T00:56:43.292Z","symbol":"BTCGUSD"}}
1625273803.4243782: {"jsonrpc":"2.0","method":"updateOrderbook","params":{"ask":[{"price":"33554.91","size":"0.18610"},{"price":"33561.23","size":"0"}],"bid":[{"price":"33510.63","size":"0.17106"},{"price":"33507.39","size":"0"}],"sequence":5708335,"timestamp":"2021-07-03T00:56:43.334Z","symbol":"BTCDAI"}}
1625273803.429457: {"jsonrpc":"2.0","method":"updateOrderbook","params":{"ask":[],"bid":[{"price":"0.00011474","size":"4559.60"},{"price":"0.00011460","size":"0"}],"sequence":12351813,"timestamp":"2021-07-03T00:56:43.296Z","symbol":"EOSBTC"}}
1625273803.429522: {"jsonrpc":"2.0","method":"updateOrderbook","params":{"ask":[{"price":"33544.48","size":"0.02460"},{"price":"33544.99","size":"0.05940"},{"price":"33546.30","size":"0"},{"price":"33548.64","size":"0"},{"price":"33548.92","size":"0.07070"},{"price":"33549.16","size":"0.67070"},{"price":"33550.92","size":"0"},{"price":"33554.13","size":"0.10260"},{"price":"33558.42","size":"0"},{"price":"33558.83","size":"0"},{"price":"33560.04","size":"1.09780"},{"price":"33561.89","size":"0.95910"},{"price":"33561.98","size":"0.41740"},{"price":"33571.25","size":"0.27520"},{"price":"33574.26","size":"0"}],"bid":[{"price":"33539.49","size":"0"},{"price":"33539.07","size":"0.02940"},{"price":"33515.96","size":"0"},{"price":"33510.66","size":"0.07390"},{"price":"33507.87","size":"0"},{"price":"33505.73","size":"0.64790"},{"price":"33501.66","size":"0"},{"price":"33499.63","size":"0"},{"price":"33496.32","size":"0.96010"},{"price":"33495.21","size":"0.38210"},{"price":"33494.28","size":"0"},{"price":"33492.98","size":"0.94140"},{"price":"33457.69","size":"0"},{"price":"33448.44","size":"1.04490"}],"sequence":12626817,"timestamp":"2021-07-03T00:56:43.342Z","symbol":"BTCUSDB"}}
1625273803.429643: {"jsonrpc":"2.0","method":"updateOrderbook","params":{"ask":[{"price":"33686.32","size":"0"},{"price":"33687.96","size":"0.00533"}],"bid":[{"price":"33160.88","size":"0"},{"price":"33118.23","size":"0.92410"}],"sequence":7211272,"timestamp":"2021-07-03T00:56:43.328Z","symbol":"BTCPAX"}}
1625273803.432862: {"jsonrpc":"2.0","method":"updateOrderbook","params":{"ask":[{"price":"0.07945","size":"0"},{"price":"0.07969","size":"17.0727"},{"price":"0.09592","size":"0"},{"price":"0.09699","size":"3.7522"}],"bid":[{"price":"0.07465","size":"0.7100"},{"price":"0.07464","size":"0.6420"},{"price":"0.07463","size":"0"}],"sequence":7339989,"timestamp":"2021-07-03T00:56:43.317Z","symbol":"MKRBTC"}}
1625273803.438336: {"jsonrpc":"2.0","method":"updateOrderbook","params":{"ask":[{"price":"33515.87","size":"0.01234"},{"price":"33517.99","size":"0"},{"price":"33531.32","size":"0.06050"},{"price":"33538.15","size":"0"},{"price":"33590.47","size":"0"},{"price":"33603.81","size":"0.15630"},{"price":"33608.42","size":"0"},{"price":"33630.28","size":"0.18170"},{"price":"33661.09","size":"1.27000"},{"price":"33676.41","size":"0"},{"price":"33710.69","size":"1.35000"},{"price":"33722.84","size":"0"},{"price":"33750.01","size":"1.47000"},{"price":"33767.31","size":"0"},{"price":"34075.20","size":"0"},{"price":"34131.20","size":"1.76840"},{"price":"35777.38","size":"0"},{"price":"35891.27","size":"1.29584"}],"bid":[{"price":"33496.25","size":"0.01475"},{"price":"33494.01","size":"0"},{"price":"33491.29","size":"0"},{"price":"33486.74","size":"0.02739"}],"sequence":7477010,"timestamp":"2021-07-03T00:56:43.350Z","symbol":"BTCTUSD"}}
1625273803.5252979: {"jsonrpc":"2.0","method":"updateOrderbook","params":{"ask":[],"bid":[{"price":"2109.992","size":"0"},{"price":"2103.621","size":"22.1000"},{"price":"2092.760","size":"0"},{"price":"2090.321","size":"36.1000"}],"sequence":1513066,"timestamp":"2021-07-03T00:56:43.415Z","symbol":"ETHDAI"}}
1625273803.5282629: {"jsonrpc":"2.0","method":"updateOrderbook","params":{"ask":[],"bid":[{"price":"33006.68","size":"0"},{"price":"32921.98","size":"1.90000"},{"price":"32799.31","size":"0"},{"price":"32759.37","size":"2.20000"}],"sequence":5708336,"timestamp":"2021-07-03T00:56:43.415Z","symbol":"BTCDAI"}}
1625273803.5339122: {"jsonrpc":"2.0","method":"updateOrderbook","params":{"ask":[{"price":"33542.89","size":"0.02460"},{"price":"33544.48","size":"0"},{"price":"33558.78","size":"0.91740"},{"price":"33560.37","size":"0"},{"price":"33566.51","size":"0"},{"price":"33568.67","size":"0.75370"},{"price":"33570.77","size":"0.39780"},{"price":"33571.11","size":"1.43490"},{"price":"33573.34","size":"0"},{"price":"33574.04","size":"0"},{"price":"33579.18","size":"0.09055"},{"price":"33583.80","size":"1.13490"},{"price":"33587.33","size":"0"},{"price":"33589.50","size":"0"},{"price":"33605.56","size":"1.06050"},{"price":"33617.10","size":"0"}],"bid":[{"price":"33539.07","size":"0"},{"price":"33538.70","size":"0.02940"},{"price":"33535.57","size":"0"},{"price":"33534.18","size":"0.05460"},{"price":"33264.68","size":"0"},{"price":"33235.22","size":"0"},{"price":"33221.68","size":"0.40340"},{"price":"33190.06","size":"0.52486"},{"price":"33189.25","size":"0"},{"price":"33169.45","size":"1.54758"},{"price":"33080.26","size":"0"},{"price":"33061.58","size":"2.20382"},{"price":"32987.44","size":"0"},{"price":"32956.67","size":"1.23617"},{"price":"31635.22","size":"0"},{"price":"31563.49","size":"1.89095"}],"sequence":12626818,"timestamp":"2021-07-03T00:56:43.451Z","symbol":"BTCUSDB"}}
1625273803.534082: {"jsonrpc":"2.0","method":"updateOrderbook","params":{"ask":[{"price":"0.00011622","size":"0"},{"price":"0.00011624","size":"6589.49"},{"price":"0.00012745","size":"0"},{"price":"0.00012770","size":"40454.70"}],"bid":[{"price":"0.00011561","size":"2527.54"},{"price":"0.00011558","size":"2918.29"}],"sequence":12351814,"timestamp":"2021-07-03T00:56:43.389Z","symbol":"EOSBTC"}}
1625273803.534558: {"jsonrpc":"2.0","method":"updateOrderbook","params":{"ask":[{"price":"33683.40","size":"0.00533"},{"price":"33687.96","size":"0"}],"bid":[],"sequence":7211273,"timestamp":"2021-07-03T00:56:43.431Z","symbol":"BTCPAX"}}
1625273803.5345988: {"jsonrpc":"2.0","method":"updateOrderbook","params":{"ask":[{"price":"0.24197","size":"4.2976"},{"price":"0.25006","size":"0"}],"bid":[],"sequence":7339990,"timestamp":"2021-07-03T00:56:43.380Z","symbol":"MKRBTC"}}
1625273803.5390568: {"jsonrpc":"2.0","method":"updateOrderbook","params":{"ask":[{"price":"33515.47","size":"0.01234"},{"price":"33515.87","size":"0"},{"price":"33518.29","size":"0.02980"},{"price":"33521.99","size":"0"}],"bid":[{"price":"33498.82","size":"0.01475"},{"price":"33496.25","size":"0"},{"price":"33495.99","size":"0.02739"},{"price":"33486.74","size":"0"}],"sequence":7477011,"timestamp":"2021-07-03T00:56:43.448Z","symbol":"BTCTUSD"}}
1625273803.6345432: {"jsonrpc":"2.0","method":"updateOrderbook","params":{"ask":[{"price":"33542.08","size":"0.02460"},{"price":"33542.89","size":"0"},{"price":"33558.87","size":"0.12060"},{"price":"33569.23","size":"0"}],"bid":[{"price":"33538.70","size":"0"},{"price":"33538.16","size":"0.02940"},{"price":"33461.57","size":"0"},{"price":"33455.78","size":"1.04000"}],"sequence":12626819,"timestamp":"2021-07-03T00:56:43.539Z","symbol":"BTCUSDB"}}
1625273803.6346712: {"jsonrpc":"2.0","method":"updateOrderbook","params":{"ask":[{"price":"0.00011598","size":"88.49"},{"price":"0.00011608","size":"0"}],"bid":[],"sequence":12351815,"timestamp":"2021-07-03T00:56:43.495Z","symbol":"EOSBTC"}}
1625273803.6346948: {"jsonrpc":"2.0","method":"updateOrderbook","params":{"ask":[{"price":"35023.99","size":"0"},{"price":"35078.62","size":"1.84720"}],"bid":[{"price":"33442.87","size":"0"},{"price":"33413.80","size":"0.24960"},{"price":"32840.36","size":"0"},{"price":"32787.46","size":"1.26650"},{"price":"30691.99","size":"0"},{"price":"30500.07","size":"1.68120"}],"sequence":7211274,"timestamp":"2021-07-03T00:56:43.511Z","symbol":"BTCPAX"}}
1625273803.634718: {"jsonrpc":"2.0","method":"updateOrderbook","params":{"ask":[{"price":"0.07650","size":"1.9169"},{"price":"0.07658","size":"3.2039"}],"bid":[],"sequence":7339991,"timestamp":"2021-07-03T00:56:43.507Z","symbol":"MKRBTC"}}
1625273803.634736: {"jsonrpc":"2.0","method":"updateOrderbook","params":{"ask":[{"price":"33558.76","size":"0.00910"},{"price":"33564.09","size":"0"},{"price":"33566.65","size":"0.04260"},{"price":"33574.72","size":"0"}],"bid":[],"sequence":7477012,"timestamp":"2021-07-03T00:56:43.504Z","symbol":"BTCTUSD"}}
1625273803.729111: {"jsonrpc":"2.0","method":"updateOrderbook","params":{"ask":[{"price":"33541.03","size":"0.02460"},{"price":"33542.08","size":"0"},{"price":"33578.54","size":"1.30100"},{"price":"33582.12","size":"0"}],"bid":[{"price":"33538.40","size":"0.02940"},{"price":"33538.16","size":"0"},{"price":"33510.78","size":"0"},{"price":"33509.23","size":"0"},{"price":"33507.87","size":"0.77390"},{"price":"33506.57","size":"1.04220"},{"price":"33506.23","size":"0.32903"},{"price":"33446.07","size":"0"},{"price":"33439.86","size":"1.46790"}],"sequence":12626820,"timestamp":"2021-07-03T00:56:43.648Z","symbol":"BTCUSDB"}}
1625273803.729256: {"jsonrpc":"2.0","method":"updateOrderbook","params":{"ask":[{"price":"33566.76","size":"0.00940"},{"price":"33579.92","size":"0"},{"price":"33673.25","size":"0.00533"},{"price":"33677.82","size":"0"},{"price":"33679.78","size":"0.00533"},{"price":"33683.40","size":"0"}],"bid":[],"sequence":7211275,"timestamp":"2021-07-03T00:56:43.651Z","symbol":"BTCPAX"}}
1625273803.729315: {"jsonrpc":"2.0","method":"updateOrderbook","params":{"ask":[],"bid":[{"price":"0.00011474","size":"0"},{"price":"0.00011456","size":"4559.60"}],"sequence":12351816,"timestamp":"2021-07-03T00:56:43.586Z","symbol":"EOSBTC"}}
1625273803.732218: {"jsonrpc":"2.0","method":"updateOrderbook","params":{"ask":[],"bid":[{"price":"0.07356","size":"0"},{"price":"0.07330","size":"1.8459"},{"price":"0.07174","size":"0"},{"price":"0.07162","size":"2.6896"}],"sequence":7339992,"timestamp":"2021-07-03T00:56:43.604Z","symbol":"MKRBTC"}}
1625273803.823478: {"jsonrpc":"2.0","method":"updateOrderbook","params":{"ask":[],"bid":[{"price":"33514.34","size":"0.09211"},{"price":"33512.84","size":"0"}],"sequence":5708337,"timestamp":"2021-07-03T00:56:43.750Z","symbol":"BTCDAI"}}
1625273803.828994: {"jsonrpc":"2.0","method":"updateOrderbook","params":{"ask":[],"bid":[{"price":"33413.80","size":"0"},{"price":"33373.63","size":"0.24960"},{"price":"33346.81","size":"0"},{"price":"33313.65","size":"0.37050"}],"sequence":7211276,"timestamp":"2021-07-03T00:56:43.697Z","symbol":"BTCPAX"}}
1625273803.833726: {"jsonrpc":"2.0","method":"updateOrderbook","params":{"ask":[],"bid":[{"price":"0.07465","size":"0"},{"price":"0.07464","size":"0"},{"price":"0.07335","size":"0.7100"}],"sequence":7339993,"timestamp":"2021-07-03T00:56:43.724Z","symbol":"MKRBTC"}}
1625273803.8337831: {"jsonrpc":"2.0","method":"updateOrderbook","params":{"ask":[{"price":"33540.77","size":"0.02460"},{"price":"33541.03","size":"0"},{"price":"33547.91","size":"1.03952"},{"price":"33551.90","size":"0"},{"price":"33555.34","size":"0.41740"},{"price":"33558.12","size":"0.75200"},{"price":"33561.98","size":"0"},{"price":"33562.05","size":"0"}],"bid":[{"price":"33538.40","size":"0"},{"price":"33538.10","size":"0.02940"},{"price":"33530.41","size":"1.81560"},{"price":"33526.74","size":"1.43690"},{"price":"33526.65","size":"0"},{"price":"33520.43","size":"0"},{"price":"33516.00","size":"0.94240"},{"price":"33513.79","size":"1.10595"},{"price":"33509.84","size":"0"},{"price":"33502.50","size":"0"}],"sequence":12626821,"timestamp":"2021-07-03T00:56:43.731Z","symbol":"BTCUSDB"}}
1625273803.9251258: {"jsonrpc":"2.0","method":"updateOrderbook","params":{"ask":[],"bid":[{"price":"33515.62","size":"0.09211"},{"price":"33514.34","size":"0"}],"sequence":5708338,"timestamp":"2021-07-03T00:56:43.846Z","symbol":"BTCDAI"}}
1625273803.925171: {"jsonrpc":"2.0","method":"updateOrderbook","params":{"ask":[{"price":"33568.17","size":"1.75290"},{"price":"33572.10","size":"0"},{"price":"33577.64","size":"0.79591"},{"price":"33578.95","size":"0.35370"},{"price":"33581.15","size":"0"},{"price":"33583.95","size":"0"},{"price":"33599.52","size":"1.23720"},{"price":"33607.79","size":"0"}],"bid":[{"price":"33538.81","size":"0.02940"},{"price":"33538.10","size":"0"}],"sequence":12626822,"timestamp":"2021-07-03T00:56:43.849Z","symbol":"BTCUSDB"}}
1625273803.9252338: {"jsonrpc":"2.0","method":"updateOrderbook","params":{"ask":[{"price":"0.00011621","size":"0"},{"price":"0.00011623","size":"2111.95"},{"price":"0.00011624","size":"5679.49"},{"price":"0.00011626","size":"910.00"},{"price":"0.00011630","size":"8597.41"},{"price":"0.00011632","size":"1602.37"}],"bid":[],"sequence":12351817,"timestamp":"2021-07-03T00:56:43.789Z","symbol":"EOSBTC"}}
1625273803.935526: {"jsonrpc":"2.0","method":"updateOrderbook","params":{"ask":[{"price":"0.09699","size":"0"},{"price":"0.10425","size":"3.7522"},{"price":"0.24197","size":"0"},{"price":"0.35282","size":"4.2976"}],"bid":[{"price":"0.07467","size":"0.7100"},{"price":"0.07466","size":"0.6418"},{"price":"0.07335","size":"0"}],"sequence":7339994,"timestamp":"2021-07-03T00:56:43.842Z","symbol":"MKRBTC"}}
1625273804.038409: {"jsonrpc":"2.0","method":"updateOrderbook","params":{"ask":[],"bid":[{"price":"33538.81","size":"0"},{"price":"33538.60","size":"0.02940"},{"price":"33526.74","size":"0"},{"price":"33525.44","size":"1.43690"},{"price":"33516.00","size":"0"},{"price":"33514.74","size":"0.94240"}],"sequence":12626823,"timestamp":"2021-07-03T00:56:43.949Z","symbol":"BTCUSDB"}}
1625273804.03845: {"jsonrpc":"2.0","method":"updateOrderbook","params":{"ask":[{"price":"0.00011612","size":"0"},{"price":"0.00011619","size":"4260.12"}],"bid":[],"sequence":12351818,"timestamp":"2021-07-03T00:56:43.951Z","symbol":"EOSBTC"}}
1625273804.038462: {"jsonrpc":"2.0","method":"updateOrderbook","params":{"ask":[{"price":"33584.06","size":"0.09080"},{"price":"33601.13","size":"0"}],"bid":[],"sequence":7211277,"timestamp":"2021-07-03T00:56:43.898Z","symbol":"BTCPAX"}}
1625273804.038472: {"jsonrpc":"2.0","method":"updateOrderbook","params":{"ask":[{"price":"33515.47","size":"0"},{"price":"33516.46","size":"0.01234"},{"price":"33518.29","size":"0"},{"price":"33519.30","size":"0.02980"}],"bid":[],"sequence":7477013,"timestamp":"2021-07-03T00:56:43.859Z","symbol":"BTCTUSD"}}
1625273804.131073: {"jsonrpc":"2.0","method":"updateOrderbook","params":{"ask":[],"bid":[{"price":"33538.60","size":"0"},{"price":"33538.12","size":"0.02940"},{"price":"33534.76","size":"1.15550"},{"price":"33534.21","size":"0"},{"price":"33530.41","size":"0"},{"price":"33529.24","size":"1.81560"},{"price":"33514.58","size":"1.10595"},{"price":"33513.82","size":"0"},{"price":"33513.79","size":"0"},{"price":"33510.31","size":"0.01821"}],"sequence":12626824,"timestamp":"2021-07-03T00:56:44.036Z","symbol":"BTCUSDB"}}
1625273804.1312141: {"jsonrpc":"2.0","method":"updateOrderbook","params":{"ask":[{"price":"0.07645","size":"0"},{"price":"0.07648","size":"3.1588"},{"price":"0.07651","size":"0"},{"price":"0.07656","size":"8.0685"},{"price":"0.07660","size":"0"},{"price":"0.07665","size":"2.1638"},{"price":"0.07672","size":"0"},{"price":"0.07673","size":"0"},{"price":"0.07677","size":"0.6900"},{"price":"0.07681","size":"2.6323"},{"price":"0.10425","size":"0"},{"price":"0.10908","size":"3.7522"},{"price":"0.35282","size":"0"},{"price":"0.45138","size":"4.2976"}],"bid":[],"sequence":7339995,"timestamp":"2021-07-03T00:56:43.960Z","symbol":"MKRBTC"}}
1625273804.131254: {"jsonrpc":"2.0","method":"updateOrderbook","params":{"ask":[{"price":"33587.56","size":"0.15630"},{"price":"33603.81","size":"0"},{"price":"33767.30","size":"0"}],"bid":[],"sequence":7477014,"timestamp":"2021-07-03T00:56:44.024Z","symbol":"BTCTUSD"}}
1625273804.2307708: {"jsonrpc":"2.0","method":"updateOrderbook","params":{"ask":[{"price":"33555.34","size":"0"},{"price":"33557.38","size":"0.41740"},{"price":"167629.45","size":"0.00016"},{"price":"167633.78","size":"0"}],"bid":[{"price":"33538.37","size":"0.02940"},{"price":"33538.12","size":"0"},{"price":"33535.43","size":"0.38210"},{"price":"33534.76","size":"0.77340"},{"price":"33514.62","size":"1.10595"},{"price":"33514.58","size":"0"},{"price":"10058.02","size":"0"},{"price":"10057.76","size":"0.00016"}],"sequence":12626825,"timestamp":"2021-07-03T00:56:44.145Z","symbol":"BTCUSDB"}}
1625273804.230904: {"jsonrpc":"2.0","method":"updateOrderbook","params":{"ask":[{"price":"0.00011599","size":"1986.07"},{"price":"0.00011602","size":"2106.34"}],"bid":[{"price":"0.00011571","size":"428.52"},{"price":"0.00011570","size":"1495.81"},{"price":"0.00011562","size":"892.63"},{"price":"0.00011558","size":"2827.90"}],"sequence":12351819,"timestamp":"2021-07-03T00:56:44.091Z","symbol":"EOSBTC"}}
1625273804.235229: {"jsonrpc":"2.0","method":"updateOrderbook","params":{"ask":[{"price":"0.07668","size":"2.3685"},{"price":"0.07678","size":"3.4246"}],"bid":[{"price":"0.07605","size":"0.5550"},{"price":"0.07601","size":"0"},{"price":"0.07555","size":"0"},{"price":"0.07548","size":"0.6900"},{"price":"0.07467","size":"0"},{"price":"0.07466","size":"0"},{"price":"0.07335","size":"0.7100"}],"sequence":7339996,"timestamp":"2021-07-03T00:56:44.132Z","symbol":"MKRBTC"}}
1625273804.235261: {"jsonrpc":"2.0","method":"updateOrderbook","params":{"ask":[{"price":"33779.70","size":"0.00214"}],"bid":[],"sequence":7477015,"timestamp":"2021-07-03T00:56:44.083Z","symbol":"BTCTUSD"}}
1625273804.3306391: {"jsonrpc":"2.0","method":"updateOrderbook","params":{"ask":[],"bid":[{"price":"33427.42","size":"0.19360"},{"price":"33420.71","size":"0.23620"},{"price":"33403.31","size":"0"},{"price":"33383.55","size":"0"}],"sequence":5708339,"timestamp":"2021-07-03T00:56:44.153Z","symbol":"BTCDAI"}}
1625273804.3429399: {"jsonrpc":"2.0","method":"updateOrderbook","params":{"ask":[{"price":"33540.77","size":"0"},{"price":"33541.02","size":"0.02460"},{"price":"33544.99","size":"0"},{"price":"33546.13","size":"0.05940"},{"price":"33586.09","size":"0.75370"},{"price":"33593.59","size":"0"},{"price":"33699.88","size":"1.25250"},{"price":"33722.20","size":"0"},{"price":"33733.38","size":"0.53479"},{"price":"33746.97","size":"1.46091"},{"price":"33760.10","size":"0"},{"price":"33761.49","size":"0"}],"bid":[{"price":"33538.37","size":"0"},{"price":"33537.59","size":"0.02940"},{"price":"33534.18","size":"0"},{"price":"33532.90","size":"0.05460"},{"price":"33527.02","size":"0"},{"price":"33526.86","size":"1.43690"},{"price":"33525.44","size":"0"},{"price":"33519.28","size":"0.11940"},{"price":"33516.17","size":"0.94240"},{"price":"33514.74","size":"0"},{"price":"33514.62","size":"0"},{"price":"33514.60","size":"1.10595"},{"price":"33511.22","size":"0.77390"},{"price":"33507.87","size":"0"}],"sequence":12626826,"timestamp":"2021-07-03T00:56:44.251Z","symbol":"BTCUSDB"}}
1625273804.343107: {"jsonrpc":"2.0","method":"updateOrderbook","params":{"ask":[],"bid":[{"price":"0.07469","size":"0.7100"},{"price":"0.07468","size":"0.6416"},{"price":"0.07335","size":"0"}],"sequence":7339997,"timestamp":"2021-07-03T00:56:44.197Z","symbol":"MKRBTC"}}
1625273804.4371169: {"jsonrpc":"2.0","method":"updateOrderbook","params":{"ask":[{"price":"0.00011580","size":"230.00"},{"price":"0.00011581","size":"412.61"},{"price":"0.00011582","size":"223.04"},{"price":"0.00011583","size":"2723.79"},{"price":"0.00011585","size":"131.95"},{"price":"0.00011590","size":"1810.02"},{"price":"0.00011593","size":"2396.53"},{"price":"0.00011594","size":"88.02"},{"price":"0.00011621","size":"290.00"},{"price":"0.00011623","size":"1821.95"},{"price":"0.00011624","size":"6589.49"},{"price":"0.00011626","size":"0"}],"bid":[{"price":"0.00011570","size":"580.33"},{"price":"0.00011569","size":"915.81"},{"price":"0.00011561","size":"2527.93"},{"price":"0.00011558","size":"2828.37"}],"sequence":12351820,"timestamp":"2021-07-03T00:56:44.350Z","symbol":"EOSBTC"}}
1625273804.437187: {"jsonrpc":"2.0","method":"updateOrderbook","params":{"ask":[{"price":"33540.43","size":"0.02460"},{"price":"33541.02","size":"0"},{"price":"33560.04","size":"0"},{"price":"33561.72","size":"1.09780"},{"price":"33568.67","size":"0"},{"price":"33571.11","size":"0"},{"price":"33572.73","size":"0.75370"},{"price":"33573.50","size":"1.43490"},{"price":"33581.00","size":"0.95910"},{"price":"33585.09","size":"0"},{"price":"33609.02","size":"0.43410"},{"price":"33618.85","size":"0"}],"bid":[{"price":"33537.88","size":"0.02940"},{"price":"33537.59","size":"0"}],"sequence":12626827,"timestamp":"2021-07-03T00:56:44.318Z","symbol":"BTCUSDB"}}
1625273804.441159: {"jsonrpc":"2.0","method":"updateOrderbook","params":{"ask":[{"price":"0.07647","size":"0"},{"price":"0.07649","size":"0.0003"}],"bid":[],"sequence":7339998,"timestamp":"2021-07-03T00:56:44.312Z","symbol":"MKRBTC"}}
1625273804.447177: {"jsonrpc":"2.0","method":"updateOrderbook","params":{"ask":[{"price":"33515.53","size":"0.01234"},{"price":"33516.46","size":"0"},{"price":"33519.21","size":"0.02981"},{"price":"33519.30","size":"0"},{"price":"33526.99","size":"0.05149"},{"price":"33529.01","size":"0"},{"price":"33531.32","size":"0"},{"price":"33531.65","size":"0.06053"},{"price":"33613.32","size":"0.18170"},{"price":"33630.28","size":"0"}],"bid":[{"price":"33495.99","size":"0"},{"price":"33495.64","size":"0.02740"},{"price":"33487.87","size":"0.05089"},{"price":"33484.86","size":"0"},{"price":"33483.33","size":"0.05993"},{"price":"33480.13","size":"0"},{"price":"33464.71","size":"0.20870"},{"price":"33445.02","size":"0"}],"sequence":7477016,"timestamp":"2021-07-03T00:56:44.338Z","symbol":"BTCTUSD"}}
1625273804.534941: {"jsonrpc":"2.0","method":"updateOrderbook","params":{"ask":[],"bid":[{"price":"2109.993","size":"22.1000"},{"price":"2103.621","size":"0"},{"price":"2092.764","size":"36.1000"},{"price":"2090.321","size":"0"}],"sequence":1513067,"timestamp":"2021-07-03T00:56:44.423Z","symbol":"ETHDAI"}}
1625273804.5406091: {"jsonrpc":"2.0","method":"updateOrderbook","params":{"ask":[],"bid":[{"price":"33409.00","size":"0.38830"},{"price":"33376.85","size":"0"},{"price":"32996.06","size":"1.90000"},{"price":"32921.98","size":"0"},{"price":"32793.51","size":"2.20000"},{"price":"32759.37","size":"0"}],"sequence":5708340,"timestamp":"2021-07-03T00:56:44.425Z","symbol":"BTCDAI"}}
1625273804.54067: {"jsonrpc":"2.0","method":"updateOrderbook","params":{"ask":[{"price":"33540.02","size":"0.02460"},{"price":"33540.43","size":"0"},{"price":"33544.58","size":"0.05940"},{"price":"33546.13","size":"0"},{"price":"33582.32","size":"0.75370"},{"price":"33586.09","size":"0"},{"price":"33586.13","size":"1.43490"},{"price":"33591.43","size":"0"}],"bid":[{"price":"33537.88","size":"0"},{"price":"33537.64","size":"0.02940"}],"sequence":12626828,"timestamp":"2021-07-03T00:56:44.430Z","symbol":"BTCUSDB"}}
1625273804.540765: {"jsonrpc":"2.0","method":"updateOrderbook","params":{"ask":[{"price":"0.00011630","size":"9697.41"},{"price":"0.00011632","size":"502.37"}],"bid":[{"price":"0.00011571","size":"921.65"},{"price":"0.00011570","size":"87.20"},{"price":"0.00011400","size":"7510.42"},{"price":"0.00011374","size":"0"}],"sequence":12351821,"timestamp":"2021-07-03T00:56:44.392Z","symbol":"EOSBTC"}}
1625273804.6289148: {"jsonrpc":"2.0","method":"updateOrderbook","params":{"ask":[],"bid":[{"price":"33537.64","size":"0"},{"price":"33537.51","size":"0.02940"},{"price":"33531.23","size":"1.81560"},{"price":"33529.24","size":"0"},{"price":"33492.98","size":"0"},{"price":"33491.77","size":"0.94140"}],"sequence":12626829,"timestamp":"2021-07-03T00:56:44.546Z","symbol":"BTCUSDB"}}
1625273804.6290429: {"jsonrpc":"2.0","method":"updateOrderbook","params":{"ask":[],"bid":[{"price":"0.00011570","size":"1003.01"},{"price":"0.00011569","size":"0"},{"price":"0.00011525","size":"6672.65"},{"price":"0.00011523","size":"0"}],"sequence":12351822,"timestamp":"2021-07-03T00:56:44.481Z","symbol":"EOSBTC"}}
1625273804.629075: {"jsonrpc":"2.0","method":"updateOrderbook","params":{"ask":[{"price":"33672.59","size":"0.00533"},{"price":"33673.25","size":"0"}],"bid":[],"sequence":7211278,"timestamp":"2021-07-03T00:56:44.545Z","symbol":"BTCPAX"}}
1625273804.6290948: {"jsonrpc":"2.0","method":"updateOrderbook","params":{"ask":[],"bid":[{"price":"0.07548","size":"0.7528"},{"price":"0.07469","size":"0"},{"price":"0.07468","size":"0"},{"price":"0.07335","size":"0.7100"}],"sequence":7339999,"timestamp":"2021-07-03T00:56:44.541Z","symbol":"MKRBTC"}}
1625273804.7284532: {"jsonrpc":"2.0","method":"updateOrderbook","params":{"ask":[{"price":"33539.77","size":"0.02460"},{"price":"33540.02","size":"0"},{"price":"33549.77","size":"0.45140"},{"price":"33554.03","size":"0"},{"price":"33554.73","size":"0.91740"},{"price":"33558.78","size":"0"},{"price":"33574.59","size":"0.55720"},{"price":"33581.23","size":"0"}],"bid":[{"price":"33537.51","size":"0"},{"price":"33537.20","size":"0.02940"},{"price":"33531.23","size":"0"},{"price":"33530.63","size":"1.81560"}],"sequence":12626830,"timestamp":"2021-07-03T00:56:44.622Z","symbol":"BTCUSDB"}}
1625273804.728588: {"jsonrpc":"2.0","method":"updateOrderbook","params":{"ask":[{"price":"0.00011580","size":"329.00"},{"price":"0.00011582","size":"124.04"}],"bid":[],"sequence":12351823,"timestamp":"2021-07-03T00:56:44.566Z","symbol":"EOSBTC"}}
1625273804.735441: {"jsonrpc":"2.0","method":"updateOrderbook","params":{"ask":[{"price":"0.07650","size":"0"},{"price":"0.07658","size":"5.1208"},{"price":"0.07668","size":"0"},{"price":"0.07678","size":"5.7931"},{"price":"0.07701","size":"0"},{"price":"0.07715","size":"6.2765"},{"price":"0.07773","size":"0"},{"price":"0.07795","size":"9.6365"}],"bid":[{"price":"0.07463","size":"0.7100"},{"price":"0.07462","size":"0.6421"},{"price":"0.07335","size":"0"}],"sequence":7340000,"timestamp":"2021-07-03T00:56:44.640Z","symbol":"MKRBTC"}}
1625273804.830538: {"jsonrpc":"2.0","method":"updateOrderbook","params":{"ask":[{"price":"33576.36","size":"0.75200"},{"price":"33579.76","size":"0"}],"bid":[{"price":"33537.20","size":"0"},{"price":"33537.15","size":"0.02940"},{"price":"33530.63","size":"0"},{"price":"33530.55","size":"1.81560"},{"price":"33527.80","size":"1.43690"},{"price":"33526.86","size":"0"},{"price":"33520.74","size":"0.94240"},{"price":"33517.03","size":"1.10595"},{"price":"33516.17","size":"0"},{"price":"33514.60","size":"0"}],"sequence":12626831,"timestamp":"2021-07-03T00:56:44.753Z","symbol":"BTCUSDB"}}
1625273804.830592: {"jsonrpc":"2.0","method":"updateOrderbook","params":{"ask":[{"price":"0.00011580","size":"230.00"},{"price":"0.00011581","size":"0"},{"price":"0.00011582","size":"635.65"},{"price":"0.00011585","size":"120.44"},{"price":"0.00011586","size":"98.98"}],"bid":[{"price":"0.00011573","size":"230.00"},{"price":"0.00011572","size":"1290.00"},{"price":"0.00011571","size":"230.00"},{"price":"0.00011568","size":"0"},{"price":"0.00011567","size":"198.56"},{"price":"0.00011509","size":"7357.60"},{"price":"0.00011496","size":"18593.65"}],"sequence":12351824,"timestamp":"2021-07-03T00:56:44.721Z","symbol":"EOSBTC"}}
1625273804.8376021: {"jsonrpc":"2.0","method":"updateOrderbook","params":{"ask":[{"price":"0.07660","size":"2.1638"},{"price":"0.07665","size":"0"},{"price":"0.07672","size":"0.6900"},{"price":"0.07673","size":"2.6323"},{"price":"0.07677","size":"0"},{"price":"0.07681","size":"0"}],"bid":[],"sequence":7340001,"timestamp":"2021-07-03T00:56:44.684Z","symbol":"MKRBTC"}}
1625273804.930596: {"jsonrpc":"2.0","method":"updateOrderbook","params":{"ask":[],"bid":[{"price":"33189.10","size":"1.54755"},{"price":"33169.45","size":"0"},{"price":"33079.61","size":"2.20379"},{"price":"33061.58","size":"0"}],"sequence":12626832,"timestamp":"2021-07-03T00:56:44.852Z","symbol":"BTCUSDB"}}
1625273805.036932: {"jsonrpc":"2.0","method":"updateOrderbook","params":{"ask":[],"bid":[{"price":"33537.15","size":"0"},{"price":"33537.14","size":"0.02940"},{"price":"33531.30","size":"1.81560"},{"price":"33530.55","size":"0"},{"price":"33517.72","size":"1.10595"},{"price":"33517.03","size":"0"},{"price":"33461.04","size":"1.04000"},{"price":"33455.78","size":"0"},{"price":"33448.09","size":"1.46790"},{"price":"33439.86","size":"0"}],"sequence":12626833,"timestamp":"2021-07-03T00:56:44.947Z","symbol":"BTCUSDB"}}
1625273805.037065: {"jsonrpc":"2.0","method":"updateOrderbook","params":{"ask":[{"price":"0.00011581","size":"99.00"},{"price":"0.00011582","size":"536.65"},{"price":"0.00013535","size":"0"},{"price":"0.00015137","size":"22588.08"},{"price":"0.00015902","size":"0"},{"price":"0.00024234","size":"26975.46"},{"price":"0.00024529","size":"0"},{"price":"0.00028179","size":"39545.26"},{"price":"0.00035035","size":"0"},{"price":"0.00047796","size":"56176.40"},{"price":"0.00094746","size":"0"}],"bid":[{"price":"0.00011540","size":"3999.28"},{"price":"0.00011530","size":"290.00"}],"sequence":12351825,"timestamp":"2021-07-03T00:56:44.901Z","symbol":"EOSBTC"}}
1625273805.125458: {"jsonrpc":"2.0","method":"updateOrderbook","params":{"ask":[],"bid":[{"price":"33220.31","size":"1.84640"},{"price":"32969.47","size":"0"}],"sequence":5708341,"timestamp":"2021-07-03T00:56:45.052Z","symbol":"BTCDAI"}}
1625273805.12895: {"jsonrpc":"2.0","method":"updateOrderbook","params":{"ask":[{"price":"33539.77","size":"0"},{"price":"33539.95","size":"0.02460"},{"price":"33685.03","size":"0.68866"},{"price":"33695.71","size":"0"}],"bid":[],"sequence":12626834,"timestamp":"2021-07-03T00:56:45.050Z","symbol":"BTCUSDB"}}
1625273805.129007: {"jsonrpc":"2.0","method":"updateOrderbook","params":{"ask":[{"price":"0.00012252","size":"16338.72"},{"price":"0.00012294","size":"0"}],"bid":[],"sequence":12351826,"timestamp":"2021-07-03T00:56:45.006Z","symbol":"EOSBTC"}}
1625273805.141025: {"jsonrpc":"2.0","method":"updateOrderbook","params":{"ask":[],"bid":[{"price":"0.07465","size":"0.7100"},{"price":"0.07464","size":"0.6420"},{"price":"0.07463","size":"0"},{"price":"0.07462","size":"0"}],"sequence":7340002,"timestamp":"2021-07-03T00:56:45.048Z","symbol":"MKRBTC"}}
1625273805.141066: {"jsonrpc":"2.0","method":"updateOrderbook","params":{"ask":[{"price":"33518.30","size":"0.02981"},{"price":"33519.21","size":"0"}],"bid":[],"sequence":7477017,"timestamp":"2021-07-03T00:56:45.003Z","symbol":"BTCTUSD"}}
1625273805.243408: {"jsonrpc":"2.0","method":"updateOrderbook","params":{"ask":[{"price":"33567.23","size":"0.28694"},{"price":"33570.83","size":"0"},{"price":"33571.25","size":"0"},{"price":"33580.22","size":"1.13490"},{"price":"33583.80","size":"0"},{"price":"33613.90","size":"1.15780"},{"price":"33619.27","size":"1.29870"},{"price":"33621.30","size":"0"},{"price":"33632.66","size":"0.34300"},{"price":"33633.93","size":"0"},{"price":"33644.35","size":"0"},{"price":"167628.70","size":"0.00013"},{"price":"167629.45","size":"0"}],"bid":[{"price":"33537.65","size":"0.02940"},{"price":"33537.14","size":"0"},{"price":"33517.72","size":"0"},{"price":"33517.13","size":"1.10595"},{"price":"33513.23","size":"0.07390"},{"price":"33510.66","size":"0"},{"price":"33445.98","size":"1.13040"},{"price":"33438.21","size":"0"},{"price":"10057.76","size":"0"},{"price":"10057.72","size":"0.00013"}],"sequence":12626835,"timestamp":"2021-07-03T00:56:45.151Z","symbol":"BTCUSDB"}}
1625273805.243465: {"jsonrpc":"2.0","method":"updateOrderbook","params":{"ask":[{"price":"0.07646","size":"0"},{"price":"0.07648","size":"0.5753"},{"price":"0.07651","size":"2.0319"},{"price":"0.07656","size":"6.8903"},{"price":"0.07661","size":"3.7617"},{"price":"0.07681","size":"4.3568"},{"price":"0.07689","size":"0"},{"price":"0.07698","size":"8.2348"},{"price":"0.07748","size":"0"},{"price":"0.07805","size":"11.9903"},{"price":"0.07969","size":"0"},{"price":"0.08337","size":"17.0727"}],"bid":[{"price":"0.07592","size":"0"},{"price":"0.07590","size":"0"},{"price":"0.07586","size":"2.6083"},{"price":"0.07581","size":"1.9731"}],"sequence":7340003,"timestamp":"2021-07-03T00:56:45.147Z","symbol":"MKRBTC"}}
1625273805.243485: {"jsonrpc":"2.0","method":"updateOrderbook","params":{"ask":[{"price":"33515.53","size":"0"},{"price":"33515.81","size":"0.01234"}],"bid":[],"sequence":7477018,"timestamp":"2021-07-03T00:56:45.075Z","symbol":"BTCTUSD"}}
1625273805.32918: {"jsonrpc":"2.0","method":"updateOrderbook","params":{"ask":[{"price":"0.00011581","size":"0"},{"price":"0.00011582","size":"99.00"},{"price":"0.00011583","size":"3136.40"},{"price":"0.00011584","size":"124.04"},{"price":"0.00011598","size":"0"},{"price":"0.00011608","size":"88.49"},{"price":"0.00011622","size":"910.00"},{"price":"0.00011624","size":"5679.49"},{"price":"0.00012252","size":"0"},{"price":"0.00012295","size":"16338.72"},{"price":"0.00094746","size":"86093.30"}],"bid":[{"price":"0.00011573","size":"723.13"},{"price":"0.00011572","size":"796.87"}],"sequence":12351827,"timestamp":"2021-07-03T00:56:45.236Z","symbol":"EOSBTC"}}
1625273805.3292422: {"jsonrpc":"2.0","method":"updateOrderbook","params":{"ask":[{"price":"33539.95","size":"0"},{"price":"33540.13","size":"0.02460"}],"bid":[{"price":"33537.89","size":"0.02940"},{"price":"33537.65","size":"0"},{"price":"33531.30","size":"0"},{"price":"33530.65","size":"1.81560"},{"price":"33510.23","size":"1.37123"},{"price":"33506.57","size":"0"},{"price":"33506.23","size":"0"}],"sequence":12626836,"timestamp":"2021-07-03T00:56:45.243Z","symbol":"BTCUSDB"}}
1625273805.3293262: {"jsonrpc":"2.0","method":"updateOrderbook","params":{"ask":[],"bid":[{"price":"0.07605","size":"1.9877"},{"price":"0.07602","size":"0.5119"},{"price":"0.07591","size":"0"},{"price":"0.07586","size":"4.5487"},{"price":"0.07547","size":"0"},{"price":"0.07537","size":"0.7100"},{"price":"0.07536","size":"5.8334"},{"price":"0.07465","size":"0"}],"sequence":7340004,"timestamp":"2021-07-03T00:56:45.249Z","symbol":"MKRBTC"}}
1625273805.329352: {"jsonrpc":"2.0","method":"updateOrderbook","params":{"ask":[{"price":"33515.81","size":"0"},{"price":"33516.11","size":"0.01234"}],"bid":[{"price":"32409.09","size":"1.67560"},{"price":"32254.34","size":"0"}],"sequence":7477019,"timestamp":"2021-07-03T00:56:45.192Z","symbol":"BTCTUSD"}}
1625273805.4402502: {"jsonrpc":"2.0","method":"updateOrderbook","params":{"ask":[{"price":"33573.10","size":"0.41740"},{"price":"33580.47","size":"0"},{"price":"33609.65","size":"1.23720"},{"price":"33619.35","size":"0"}],"bid":[{"price":"33538.01","size":"0.02940"},{"price":"33537.89","size":"0"}],"sequence":12626837,"timestamp":"2021-07-03T00:56:45.294Z","symbol":"BTCUSDB"}}
1625273805.4403992: {"jsonrpc":"2.0","method":"updateOrderbook","params":{"ask":[{"price":"0.00011628","size":"7384.09"},{"price":"0.00011630","size":"8597.41"}],"bid":[{"price":"0.00011565","size":"1700.79"},{"price":"0.00011561","size":"827.14"},{"price":"0.00010621","size":"23147.93"},{"price":"0.00010537","size":"0"},{"price":"0.00009406","size":"12370.85"},{"price":"0.00009247","size":"0"}],"sequence":12351828,"timestamp":"2021-07-03T00:56:45.345Z","symbol":"EOSBTC"}}
1625273805.440432: {"jsonrpc":"2.0","method":"updateOrderbook","params":{"ask":[{"price":"33679.78","size":"0"},{"price":"33681.46","size":"0.00533"}],"bid":[],"sequence":7211279,"timestamp":"2021-07-03T00:56:45.318Z","symbol":"BTCPAX"}}
1625273805.440449: {"jsonrpc":"2.0","method":"updateOrderbook","params":{"ask":[{"price":"34036.98","size":"1.76840"},{"price":"34131.20","size":"0"}],"bid":[],"sequence":7477020,"timestamp":"2021-07-03T00:56:45.294Z","symbol":"BTCTUSD"}}
1625273805.5276842: {"jsonrpc":"2.0","method":"updateOrderbook","params":{"ask":[],"bid":[{"price":"32034.58","size":"2.30540"},{"price":"31071.11","size":"0"},{"price":"30068.80","size":"3.10680"},{"price":"29819.66","size":"0"}],"sequence":5708342,"timestamp":"2021-07-03T00:56:45.357Z","symbol":"BTCDAI"}}
1625273805.5309289: {"jsonrpc":"2.0","method":"updateOrderbook","params":{"ask":[{"price":"33540.13","size":"0"},{"price":"33540.26","size":"0.02460"}],"bid":[{"price":"33538.01","size":"0"},{"price":"33537.75","size":"0.02940"},{"price":"33535.43","size":"0"},{"price":"33534.74","size":"0.38210"},{"price":"33531.35","size":"1.81560"},{"price":"33530.65","size":"0"},{"price":"33520.74","size":"0"},{"price":"33520.05","size":"0.94240"},{"price":"33472.88","size":"0.40013"},{"price":"33462.60","size":"0"}],"sequence":12626838,"timestamp":"2021-07-03T00:56:45.452Z","symbol":"BTCUSDB"}}
1625273805.531046: {"jsonrpc":"2.0","method":"updateOrderbook","params":{"ask":[],"bid":[{"price":"0.00011571","size":"1145.81"},{"price":"0.00011570","size":"87.20"},{"price":"0.00011567","size":"210.07"},{"price":"0.00011566","size":"87.73"}],"sequence":12351829,"timestamp":"2021-07-03T00:56:45.399Z","symbol":"EOSBTC"}}
1625273805.53161: {"jsonrpc":"2.0","method":"updateOrderbook","params":{"ask":[],"bid":[{"price":"0.07464","size":"0"},{"price":"0.07462","size":"0.6421"}],"sequence":7340005,"timestamp":"2021-07-03T00:56:45.441Z","symbol":"MKRBTC"}}
1625273805.630086: {"jsonrpc":"2.0","method":"updateOrderbook","params":{"ask":[],"bid":[{"price":"33537.75","size":"0"},{"price":"33537.64","size":"0.02940"},{"price":"33531.35","size":"0"},{"price":"33530.40","size":"1.81560"}],"sequence":12626839,"timestamp":"2021-07-03T00:56:45.519Z","symbol":"BTCUSDB"}}
1625273805.7325592: {"jsonrpc":"2.0","method":"updateOrderbook","params":{"ask":[],"bid":[{"price":"33537.64","size":"0"},{"price":"33537.62","size":"0.02940"},{"price":"33517.95","size":"1.10595"},{"price":"33517.13","size":"0"}],"sequence":12626840,"timestamp":"2021-07-03T00:56:45.641Z","symbol":"BTCUSDB"}}
1625273805.732683: {"jsonrpc":"2.0","method":"updateOrderbook","params":{"ask":[{"price":"0.00076600","size":"42091.73"},{"price":"0.00076674","size":"0"}],"bid":[{"price":"0.00011554","size":"1849.17"},{"price":"0.00011551","size":"3673.40"},{"price":"0.00011545","size":"0"},{"price":"0.00011540","size":"1692.93"}],"sequence":12351830,"timestamp":"2021-07-03T00:56:45.606Z","symbol":"EOSBTC"}}
1625273805.736198: {"jsonrpc":"2.0","method":"updateOrderbook","params":{"ask":[{"price":"35656.37","size":"1.29584"},{"price":"35891.27","size":"0"}],"bid":[],"sequence":7477021,"timestamp":"2021-07-03T00:56:45.599Z","symbol":"BTCTUSD"}}
1625273805.827759: {"jsonrpc":"2.0","method":"updateOrderbook","params":{"ask":[],"bid":[{"price":"29047.23","size":"4.54640"},{"price":"28730.30","size":"0"},{"price":"27940.71","size":"1.87330"},{"price":"27461.42","size":"0"}],"sequence":5708343,"timestamp":"2021-07-03T00:56:45.663Z","symbol":"BTCDAI"}}
1625273805.827816: {"jsonrpc":"2.0","method":"updateOrderbook","params":{"ask":[{"price":"33540.26","size":"0"},{"price":"33540.40","size":"0.02460"},{"price":"33554.73","size":"0"},{"price":"33556.38","size":"0.91740"},{"price":"33568.17","size":"0"},{"price":"33570.39","size":"1.75290"},{"price":"33613.90","size":"0"},{"price":"33620.54","size":"1.15780"},{"price":"33632.66","size":"0"},{"price":"33644.95","size":"0.34300"}],"bid":[{"price":"33538.32","size":"0.02940"},{"price":"33537.62","size":"0"},{"price":"33534.76","size":"0"},{"price":"33534.74","size":"1.15550"},{"price":"33531.44","size":"1.81560"},{"price":"33530.40","size":"0"},{"price":"33517.95","size":"0"},{"price":"33517.08","size":"1.10595"}],"sequence":12626841,"timestamp":"2021-07-03T00:56:45.749Z","symbol":"BTCUSDB"}}
1625273805.827918: {"jsonrpc":"2.0","method":"updateOrderbook","params":{"ask":[],"bid":[{"price":"33411.33","size":"0.24960"},{"price":"33373.63","size":"0"}],"sequence":7211280,"timestamp":"2021-07-03T00:56:45.739Z","symbol":"BTCPAX"}}
1625273805.82794: {"jsonrpc":"2.0","method":"updateOrderbook","params":{"ask":[{"price":"0.00011622","size":"0"},{"price":"0.00011624","size":"6589.49"},{"price":"0.00011628","size":"6284.09"},{"price":"0.00011630","size":"9697.41"},{"price":"0.00011659","size":"5487.98"},{"price":"0.00011676","size":"10076.65"},{"price":"0.00011901","size":"6250.68"},{"price":"0.00011952","size":"0"},{"price":"0.00015137","size":"0"},{"price":"0.00015673","size":"22589.08"},{"price":"0.00024234","size":"0"},{"price":"0.00024476","size":"26975.46"},{"price":"0.00028179","size":"0"},{"price":"0.00028310","size":"39545.26"},{"price":"0.00047796","size":"0"},{"price":"0.00048724","size":"56176.40"},{"price":"0.00094746","size":"0"}],"bid":[{"price":"0.00011568","size":"11.51"},{"price":"0.00011567","size":"198.56"}],"sequence":12351831,"timestamp":"2021-07-03T00:56:45.735Z","symbol":"EOSBTC"}}
1625273805.938453: {"jsonrpc":"2.0","method":"updateOrderbook","params":{"ask":[{"price":"33540.40","size":"0"},{"price":"33541.69","size":"0.02460"},{"price":"33544.58","size":"0"},{"price":"33547.17","size":"0.05940"},{"price":"33561.89","size":"0"},{"price":"33565.37","size":"0.95910"}],"bid":[{"price":"33538.65","size":"0.02940"},{"price":"33538.32","size":"0"},{"price":"33531.44","size":"0"},{"price":"33530.84","size":"1.81560"}],"sequence":12626842,"timestamp":"2021-07-03T00:56:45.838Z","symbol":"BTCUSDB"}}
1625273805.938586: {"jsonrpc":"2.0","method":"updateOrderbook","params":{"ask":[{"price":"0.00011582","size":"511.61"},{"price":"0.00011583","size":"2723.79"},{"price":"0.00011628","size":"1785.90"},{"price":"0.00011649","size":"4498.19"},{"price":"0.00011682","size":"0"},{"price":"0.00011700","size":"8759.33"},{"price":"0.00011727","size":"27902.32"},{"price":"0.00011779","size":"11170.70"},{"price":"0.00012295","size":"0"},{"price":"0.00013126","size":"16338.72"},{"price":"0.00016056","size":"0"},{"price":"0.00016880","size":"19505.60"},{"price":"0.00023639","size":"0"},{"price":"0.00025264","size":"30396.48"},{"price":"0.00076600","size":"0"},{"price":"0.00088689","size":"42091.73"},{"price":"0.00095644","size":"86093.30"}],"bid":[{"price":"0.00011573","size":"230.00"},{"price":"0.00011572","size":"1290.00"},{"price":"0.00011556","size":"1367.05"},{"price":"0.00011551","size":"2306.35"}],"sequence":12351832,"timestamp":"2021-07-03T00:56:45.820Z","symbol":"EOSBTC"}}
1625273805.940602: {"jsonrpc":"2.0","method":"updateOrderbook","params":{"ask":[{"price":"0.07646","size":"2.0319"},{"price":"0.07651","size":"0"}],"bid":[],"sequence":7340006,"timestamp":"2021-07-03T00:56:45.852Z","symbol":"MKRBTC"}}
1625273806.029387: {"jsonrpc":"2.0","method":"updateOrderbook","params":{"ask":[{"price":"33549.77","size":"0"},{"price":"33554.16","size":"0.45140"},{"price":"33556.38","size":"0"},{"price":"33560.30","size":"0.91740"},{"price":"33570.39","size":"0"},{"price":"33573.32","size":"1.75290"},{"price":"33611.82","size":"0"},{"price":"33619.69","size":"0.41570"},{"price":"33660.30","size":"0"},{"price":"33683.14","size":"1.07700"}],"bid":[{"price":"33534.74","size":"0.38210"},{"price":"33534.69","size":"0.77340"},{"price":"33530.84","size":"0"},{"price":"33530.79","size":"1.81560"},{"price":"33499.05","size":"0.38210"},{"price":"33495.21","size":"0"},{"price":"33494.68","size":"1.81560"},{"price":"33491.57","size":"0"},{"price":"33470.89","size":"0.49410"},{"price":"33464.24","size":"0"},{"price":"33457.56","size":"1.04490"},{"price":"33448.44","size":"0"}],"sequence":12626843,"timestamp":"2021-07-03T00:56:45.950Z","symbol":"BTCUSDB"}}
1625273806.029454: {"jsonrpc":"2.0","method":"updateOrderbook","params":{"ask":[{"price":"0.00011600","size":"0"},{"price":"0.00011604","size":"1553.70"}],"bid":[],"sequence":12351833,"timestamp":"2021-07-03T00:56:45.904Z","symbol":"EOSBTC"}}
1625273806.02948: {"jsonrpc":"2.0","method":"updateOrderbook","params":{"ask":[],"bid":[{"price":"0.07605","size":"1.4327"},{"price":"0.07599","size":"0.5550"}],"sequence":7340007,"timestamp":"2021-07-03T00:56:45.905Z","symbol":"MKRBTC"}}
1625273806.129494: {"jsonrpc":"2.0","method":"updateOrderbook","params":{"ask":[{"price":"0.00011581","size":"99.00"},{"price":"0.00011582","size":"412.61"},{"price":"0.00011619","size":"6096.12"},{"price":"0.00011645","size":"5064.84"},{"price":"0.00011676","size":"7920.36"}],"bid":[],"sequence":12351834,"timestamp":"2021-07-03T00:56:46.043Z","symbol":"EOSBTC"}}
1625273806.129558: {"jsonrpc":"2.0","method":"updateOrderbook","params":{"ask":[{"price":"33541.69","size":"0"},{"price":"33546.04","size":"0.02460"},{"price":"33547.17","size":"0"},{"price":"33549.16","size":"0.73010"},{"price":"33582.32","size":"0"},{"price":"33585.88","size":"0.75370"},{"price":"33586.13","size":"0"},{"price":"33591.41","size":"1.43490"}],"bid":[{"price":"33538.65","size":"0"},{"price":"33536.99","size":"0.38210"},{"price":"33534.74","size":"0"},{"price":"33534.72","size":"0.02940"},{"price":"33532.90","size":"0"},{"price":"33531.13","size":"0.05460"},{"price":"33527.07","size":"0"},{"price":"33521.77","size":"0.10140"},{"price":"33520.72","size":"0.94240"},{"price":"33520.05","size":"0"},{"price":"33497.52","size":"0.96010"},{"price":"33496.32","size":"0"},{"price":"33493.80","size":"1.43690"},{"price":"33490.42","size":"0"}],"sequence":12626844,"timestamp":"2021-07-03T00:56:46.041Z","symbol":"BTCUSDB"}}
1625273806.1296651: {"jsonrpc":"2.0","method":"updateOrderbook","params":{"ask":[{"price":"33672.59","size":"0"},{"price":"33673.41","size":"0.00533"}],"bid":[],"sequence":7211281,"timestamp":"2021-07-03T00:56:46.040Z","symbol":"BTCPAX"}}
1625273806.227262: {"jsonrpc":"2.0","method":"updateOrderbook","params":{"ask":[],"bid":[{"price":"33517.11","size":"0.09211"},{"price":"33515.62","size":"0"},{"price":"33514.06","size":"0.17106"},{"price":"33510.63","size":"0"}],"sequence":5708344,"timestamp":"2021-07-03T00:56:46.148Z","symbol":"BTCDAI"}}
1625273806.2273102: {"jsonrpc":"2.0","method":"updateOrderbook","params":{"ask":[{"price":"33545.49","size":"0.02460"},{"price":"33546.04","size":"0"},{"price":"33554.16","size":"0"},{"price":"33556.23","size":"0.45140"},{"price":"33558.12","size":"0"},{"price":"33559.75","size":"0.75200"},{"price":"33561.72","size":"0"},{"price":"33563.38","size":"1.09780"},{"price":"167628.70","size":"0"},{"price":"167635.20","size":"0.00011"}],"bid":[{"price":"33536.43","size":"0.02940"},{"price":"33534.72","size":"0"},{"price":"33497.52","size":"0"},{"price":"33495.34","size":"0.96010"},{"price":"33289.66","size":"0.40338"},{"price":"33256.95","size":"0.52484"},{"price":"33234.34","size":"1.54749"},{"price":"33221.68","size":"0"},{"price":"33190.06","size":"0"},{"price":"33189.10","size":"0"},{"price":"33114.15","size":"2.20370"},{"price":"33079.61","size":"0"},{"price":"32998.48","size":"1.23611"},{"price":"32956.67","size":"0"},{"price":"32547.78","size":"2.84162"},{"price":"32461.71","size":"0"},{"price":"31634.79","size":"1.89085"},{"price":"31563.49","size":"0"},{"price":"31071.04","size":"3.00643"},{"price":"30993.51","size":"0"},{"price":"30716.09","size":"2.82502"},{"price":"30639.27","size":"0"}],"sequence":12626845,"timestamp":"2021-07-03T00:56:46.135Z","symbol":"BTCUSDB"}}
1625273806.228914: {"jsonrpc":"2.0","method":"updateOrderbook","params":{"ask":[{"price":"0.00011719","size":"4513.55"},{"price":"0.00011981","size":"0"},{"price":"0.00095644","size":"0"},{"price":"0.00096243","size":"86093.30"}],"bid":[{"price":"0.00011568","size":"0"},{"price":"0.00011567","size":"210.07"}],"sequence":12351835,"timestamp":"2021-07-03T00:56:46.153Z","symbol":"EOSBTC"}}
1625273806.228956: {"jsonrpc":"2.0","method":"updateOrderbook","params":{"ask":[{"price":"33668.14","size":"0.00533"},{"price":"33673.41","size":"0"}],"bid":[{"price":"30657.57","size":"1.68120"},{"price":"30500.07","size":"0"}],"sequence":7211282,"timestamp":"2021-07-03T00:56:46.106Z","symbol":"BTCPAX"}}
1625273806.237303: {"jsonrpc":"2.0","method":"updateOrderbook","params":{"ask":[{"price":"0.07649","size":"2.5838"},{"price":"0.07655","size":"3.7617"},{"price":"0.07656","size":"4.3068"},{"price":"0.07661","size":"0"},{"price":"0.09652","size":"3.7522"},{"price":"0.10908","size":"0"}],"bid":[{"price":"0.07595","size":"2.6083"},{"price":"0.07592","size":"1.9731"},{"price":"0.07586","size":"1.9404"},{"price":"0.07581","size":"0"}],"sequence":7340008,"timestamp":"2021-07-03T00:56:46.109Z","symbol":"MKRBTC"}}
1625273806.237374: {"jsonrpc":"2.0","method":"updateOrderbook","params":{"ask":[{"price":"33516.11","size":"0"},{"price":"33518.30","size":"0"},{"price":"33519.48","size":"0.01234"},{"price":"33522.29","size":"0.02981"},{"price":"35656.37","size":"0"},{"price":"35715.13","size":"1.29584"}],"bid":[],"sequence":7477022,"timestamp":"2021-07-03T00:56:46.106Z","symbol":"BTCTUSD"}}
1625273806.331069: {"jsonrpc":"2.0","method":"updateOrderbook","params":{"ask":[{"price":"33547.91","size":"0"},{"price":"33549.16","size":"0.05940"},{"price":"33551.29","size":"0.67070"},{"price":"33551.90","size":"1.03952"},{"price":"33593.57","size":"0"},{"price":"33600.24","size":"0"},{"price":"33600.58","size":"0.94720"},{"price":"33606.47","size":"1.07210"},{"price":"33619.27","size":"0"},{"price":"33630.18","size":"1.29870"},{"price":"33632.04","size":"0"},{"price":"33643.19","size":"0.71880"}],"bid":[],"sequence":12626846,"timestamp":"2021-07-03T00:56:46.211Z","symbol":"BTCUSDB"}}
1625273806.331142: {"jsonrpc":"2.0","method":"updateOrderbook","params":{"ask":[],"bid":[{"price":"0.00011572","size":"796.87"},{"price":"0.00011571","size":"230.00"},{"price":"0.00011570","size":"580.33"},{"price":"0.00011569","size":"915.81"},{"price":"0.00011551","size":"0"},{"price":"0.00011541","size":"3997.84"}],"sequence":12351836,"timestamp":"2021-07-03T00:56:46.253Z","symbol":"EOSBTC"}}
1625273806.331171: {"jsonrpc":"2.0","method":"updateOrderbook","params":{"ask":[{"price":"33677.20","size":"0.00533"},{"price":"33681.46","size":"0"}],"bid":[],"sequence":7211283,"timestamp":"2021-07-03T00:56:46.249Z","symbol":"BTCPAX"}}
1625273806.331191: {"jsonrpc":"2.0","method":"updateOrderbook","params":{"ask":[{"price":"33518.14","size":"0.01234"},{"price":"33519.48","size":"0"}],"bid":[],"sequence":7477023,"timestamp":"2021-07-03T00:56:46.206Z","symbol":"BTCTUSD"}}
1625273806.428254: {"jsonrpc":"2.0","method":"updateOrderbook","params":{"ask":[{"price":"33546.62","size":"0.07707"},{"price":"33551.53","size":"0"}],"bid":[{"price":"33519.59","size":"0.09211"},{"price":"33517.11","size":"0"},{"price":"33420.71","size":"0"},{"price":"33409.00","size":"0"},{"price":"33387.36","size":"0.23620"},{"price":"33376.85","size":"0.38830"},{"price":"33220.31","size":"0"},{"price":"33014.99","size":"1.84640"},{"price":"32034.58","size":"0"},{"price":"31179.35","size":"2.30540"},{"price":"30068.80","size":"0"},{"price":"29843.55","size":"3.10680"},{"price":"29047.23","size":"0"},{"price":"28762.94","size":"4.54640"},{"price":"27940.71","size":"0"},{"price":"27522.30","size":"1.87330"}],"sequence":5708345,"timestamp":"2021-07-03T00:56:46.302Z","symbol":"BTCDAI"}}
1625273806.42835: {"jsonrpc":"2.0","method":"updateOrderbook","params":{"ask":[{"price":"33581.00","size":"0"},{"price":"33585.79","size":"0.95910"},{"price":"33585.88","size":"0"},{"price":"33590.36","size":"0.75370"},{"price":"33591.41","size":"0"},{"price":"33596.04","size":"1.43490"},{"price":"33605.56","size":"0"},{"price":"33615.71","size":"1.06050"}],"bid":[{"price":"33289.66","size":"0"},{"price":"33244.63","size":"0.40336"},{"price":"33234.34","size":"0"},{"price":"33195.45","size":"1.54742"},{"price":"33114.15","size":"0"},{"price":"33084.48","size":"2.20359"},{"price":"32547.78","size":"0"},{"price":"32467.61","size":"2.84147"},{"price":"31071.04","size":"0"},{"price":"31002.03","size":"3.00628"},{"price":"30716.09","size":"0"},{"price":"30647.20","size":"2.82487"}],"sequence":12626847,"timestamp":"2021-07-03T00:56:46.306Z","symbol":"BTCUSDB"}}
1625273806.428385: {"jsonrpc":"2.0","method":"updateOrderbook","params":{"ask":[{"price":"0.00011581","size":"0"},{"price":"0.00011584","size":"99.00"},{"price":"0.00011585","size":"244.48"}],"bid":[],"sequence":12351837,"timestamp":"2021-07-03T00:56:46.254Z","symbol":"EOSBTC"}}
1625273806.437291: {"jsonrpc":"2.0","method":"updateOrderbook","params":{"ask":[{"price":"0.07647","size":"0.0003"},{"price":"0.07649","size":"2.5835"}],"bid":[],"sequence":7340009,"timestamp":"2021-07-03T00:56:46.311Z","symbol":"MKRBTC"}}
1625273806.448073: {"jsonrpc":"2.0","method":"updateOrderbook","params":{"ask":[{"price":"33518.14","size":"0"},{"price":"33519.12","size":"0.01234"},{"price":"33521.95","size":"0.02981"},{"price":"33522.29","size":"0"}],"bid":[],"sequence":7477024,"timestamp":"2021-07-03T00:56:46.341Z","symbol":"BTCTUSD"}}
1625273806.52779: {"jsonrpc":"2.0","method":"updateOrderbook","params":{"ask":[{"price":"33546.62","size":"0"},{"price":"33550.06","size":"0.07707"}],"bid":[{"price":"33519.59","size":"0"},{"price":"33518.57","size":"0.09211"}],"sequence":5708346,"timestamp":"2021-07-03T00:56:46.447Z","symbol":"BTCDAI"}}
1625273806.530815: {"jsonrpc":"2.0","method":"updateOrderbook","params":{"ask":[{"price":"33739.28","size":"0.12750"},{"price":"33759.13","size":"0"}],"bid":[],"sequence":12626848,"timestamp":"2021-07-03T00:56:46.390Z","symbol":"BTCUSDB"}}
1625273806.5308769: {"jsonrpc":"2.0","method":"updateOrderbook","params":{"ask":[{"price":"0.00096243","size":"0"},{"price":"0.00096290","size":"86093.30"}],"bid":[],"sequence":12351838,"timestamp":"2021-07-03T00:56:46.387Z","symbol":"EOSBTC"}}
1625273806.530902: {"jsonrpc":"2.0","method":"updateOrderbook","params":{"ask":[{"price":"0.07649","size":"4.5004"},{"price":"0.07658","size":"3.2039"},{"price":"0.07659","size":"4.3568"},{"price":"0.07681","size":"0"}],"bid":[],"sequence":7340010,"timestamp":"2021-07-03T00:56:46.420Z","symbol":"MKRBTC"}}
1625273806.635413: {"jsonrpc":"2.0","method":"updateOrderbook","params":{"ask":[],"bid":[{"price":"33524.00","size":"0.09211"},{"price":"33518.57","size":"0"},{"price":"33518.03","size":"0.17106"},{"price":"33514.06","size":"0"}],"sequence":5708347,"timestamp":"2021-07-03T00:56:46.545Z","symbol":"BTCDAI"}}
1625273806.635478: {"jsonrpc":"2.0","method":"updateOrderbook","params":{"ask":[{"price":"33606.57","size":"1.06050"},{"price":"33615.71","size":"0"}],"bid":[],"sequence":12626849,"timestamp":"2021-07-03T00:56:46.466Z","symbol":"BTCUSDB"}}
1625273806.635492: {"jsonrpc":"2.0","method":"updateOrderbook","params":{"ask":[{"price":"0.00011622","size":"910.00"},{"price":"0.00011624","size":"5679.49"},{"price":"0.00011628","size":"2885.90"},{"price":"0.00011630","size":"8597.41"},{"price":"0.00096290","size":"0"},{"price":"0.00098824","size":"86093.30"}],"bid":[{"price":"0.00011568","size":"11.51"},{"price":"0.00011567","size":"198.56"}],"sequence":12351839,"timestamp":"2021-07-03T00:56:46.550Z","symbol":"EOSBTC"}}
1625273806.635506: {"jsonrpc":"2.0","method":"updateOrderbook","params":{"ask":[{"price":"35078.62","size":"0"},{"price":"35194.28","size":"1.84720"}],"bid":[],"sequence":7211284,"timestamp":"2021-07-03T00:56:46.465Z","symbol":"BTCPAX"}}
1625273806.635516: {"jsonrpc":"2.0","method":"updateOrderbook","params":{"ask":[{"price":"0.23472","size":"4.2976"},{"price":"0.45138","size":"0"}],"bid":[],"sequence":7340011,"timestamp":"2021-07-03T00:56:46.524Z","symbol":"MKRBTC"}}
1625273806.723223: {"jsonrpc":"2.0","method":"updateOrderbook","params":{"ask":[],"bid":[{"price":"33520.73","size":"0.17106"},{"price":"33518.03","size":"0"},{"price":"33510.66","size":"0.31769"},{"price":"33499.27","size":"0"},{"price":"33454.37","size":"0.03610"},{"price":"33444.48","size":"0"}],"sequence":5708348,"timestamp":"2021-07-03T00:56:46.648Z","symbol":"BTCDAI"}}
1625273806.7288451: {"jsonrpc":"2.0","method":"updateOrderbook","params":{"ask":[],"bid":[{"price":"33532.82","size":"1.81560"},{"price":"33530.79","size":"0"},{"price":"33519.41","size":"1.10595"},{"price":"33517.08","size":"0"}],"sequence":12626850,"timestamp":"2021-07-03T00:56:46.630Z","symbol":"BTCUSDB"}}
1625273806.7289028: {"jsonrpc":"2.0","method":"updateOrderbook","params":{"ask":[{"price":"0.00011607","size":"2672.37"},{"price":"0.00011610","size":"2135.53"},{"price":"0.00011613","size":"8121.37"},{"price":"0.00011619","size":"8920.92"},{"price":"0.00011630","size":"2298.31"},{"price":"0.00011643","size":"6299.10"},{"price":"0.00011712","size":"0"},{"price":"0.00011730","size":"13895.96"},{"price":"0.00013937","size":"5718.01"},{"price":"0.00015225","size":"0"},{"price":"0.00016561","size":"7220.48"},{"price":"0.00017187","size":"0"},{"price":"0.00098824","size":"0"},{"price":"0.00099879","size":"86093.30"}],"bid":[],"sequence":12351840,"timestamp":"2021-07-03T00:56:46.652Z","symbol":"EOSBTC"}}
1625273806.831092: {"jsonrpc":"2.0","method":"updateOrderbook","params":{"ask":[{"price":"33545.49","size":"0"},{"price":"33545.55","size":"0.02460"}],"bid":[{"price":"33536.82","size":"0.02940"},{"price":"33536.43","size":"0"},{"price":"33535.24","size":"0.77340"},{"price":"33534.69","size":"0"},{"price":"33532.82","size":"0"},{"price":"33532.12","size":"1.81560"},{"price":"33519.41","size":"0"},{"price":"33518.49","size":"1.10595"}],"sequence":12626851,"timestamp":"2021-07-03T00:56:46.752Z","symbol":"BTCUSDB"}}
1625273806.839374: {"jsonrpc":"2.0","method":"updateOrderbook","params":{"ask":[{"price":"0.07689","size":"8.2348"},{"price":"0.07698","size":"0"},{"price":"0.07749","size":"11.9903"},{"price":"0.07805","size":"0"}],"bid":[],"sequence":7340012,"timestamp":"2021-07-03T00:56:46.726Z","symbol":"MKRBTC"}}
1625273806.925209: {"jsonrpc":"2.0","method":"updateOrderbook","params":{"ask":[],"bid":[{"price":"33503.98","size":"0.37409"},{"price":"33491.99","size":"0"}],"sequence":5708349,"timestamp":"2021-07-03T00:56:46.770Z","symbol":"BTCDAI"}}
1625273806.929787: {"jsonrpc":"2.0","method":"updateOrderbook","params":{"ask":[{"price":"33545.11","size":"0.02460"},{"price":"33545.55","size":"0"},{"price":"33606.57","size":"0"},{"price":"33615.71","size":"1.06050"},{"price":"33664.46","size":"1.07700"},{"price":"33683.14","size":"0"}],"bid":[{"price":"33535.24","size":"0"},{"price":"33534.69","size":"0.77340"},{"price":"33532.12","size":"0"},{"price":"33529.77","size":"1.81560"},{"price":"33527.80","size":"0"},{"price":"33527.09","size":"1.43690"},{"price":"33520.72","size":"0"},{"price":"33518.49","size":"0"},{"price":"33517.45","size":"0.94240"},{"price":"33516.33","size":"1.10595"}],"sequence":12626852,"timestamp":"2021-07-03T00:56:46.820Z","symbol":"BTCUSDB"}}
1625273807.027263: {"jsonrpc":"2.0","method":"updateOrderbook","params":{"ask":[],"bid":[{"price":"33447.66","size":"0.09140"},{"price":"33429.11","size":"0"}],"sequence":5708350,"timestamp":"2021-07-03T00:56:46.952Z","symbol":"BTCDAI"}}
1625273807.027319: {"jsonrpc":"2.0","method":"updateOrderbook","params":{"ask":[{"price":"33544.63","size":"0.02460"},{"price":"33545.11","size":"0"}],"bid":[{"price":"33530.32","size":"1.81560"},{"price":"33529.77","size":"0"}],"sequence":12626853,"timestamp":"2021-07-03T00:56:46.927Z","symbol":"BTCUSDB"}}
1625273807.027416: {"jsonrpc":"2.0","method":"updateOrderbook","params":{"ask":[{"price":"0.00011682","size":"8759.33"},{"price":"0.00011700","size":"0"}],"bid":[{"price":"0.00011568","size":"0"},{"price":"0.00011567","size":"210.07"}],"sequence":12351841,"timestamp":"2021-07-03T00:56:46.936Z","symbol":"EOSBTC"}}
1625273807.030268: {"jsonrpc":"2.0","method":"updateOrderbook","params":{"ask":[{"price":"0.07666","size":"2.3685"},{"price":"0.07678","size":"3.4246"}],"bid":[],"sequence":7340013,"timestamp":"2021-07-03T00:56:46.908Z","symbol":"MKRBTC"}}
1625273807.1301491: {"jsonrpc":"2.0","method":"updateOrderbook","params":{"ask":[{"price":"33544.63","size":"0"},{"price":"33545.17","size":"0.02460"},{"price":"33554.13","size":"0"},{"price":"33558.98","size":"0.10260"},{"price":"33560.30","size":"0"},{"price":"33562.16","size":"0.91740"},{"price":"33689.11","size":"0.82970"},{"price":"33716.49","size":"0"}],"bid":[{"price":"33536.82","size":"0"},{"price":"33535.81","size":"0.02940"},{"price":"33528.41","size":"1.43690"},{"price":"33527.09","size":"0"},{"price":"33518.00","size":"0.94240"},{"price":"33517.45","size":"0"},{"price":"33516.71","size":"1.10595"},{"price":"33516.33","size":"0"},{"price":"33493.80","size":"0"},{"price":"33490.91","size":"1.43690"},{"price":"33469.14","size":"0.43060"},{"price":"33461.26","size":"0"}],"sequence":12626854,"timestamp":"2021-07-03T00:56:47.051Z","symbol":"BTCUSDB"}}
1625273807.130292: {"jsonrpc":"2.0","method":"updateOrderbook","params":{"ask":[{"price":"33668.14","size":"0"},{"price":"33674.25","size":"0.00533"},{"price":"33677.20","size":"0"},{"price":"33685.28","size":"0.00533"}],"bid":[],"sequence":7211285,"timestamp":"2021-07-03T00:56:47.034Z","symbol":"BTCPAX"}}
1625273807.135021: {"jsonrpc":"2.0","method":"updateOrderbook","params":{"ask":[{"price":"0.07950","size":"17.0727"},{"price":"0.08337","size":"0"}],"bid":[{"price":"0.07605","size":"0"},{"price":"0.07602","size":"1.9446"}],"sequence":7340014,"timestamp":"2021-07-03T00:56:47.041Z","symbol":"MKRBTC"}}
1625273807.135042: {"jsonrpc":"2.0","method":"updateOrderbook","params":{"ask":[{"price":"33518.83","size":"0.01234"},{"price":"33519.12","size":"0"}],"bid":[],"sequence":7477025,"timestamp":"2021-07-03T00:56:47.033Z","symbol":"BTCTUSD"}}
1625273807.227859: {"jsonrpc":"2.0","method":"updateOrderbook","params":{"ask":[],"bid":[{"price":"33440.96","size":"0.14150"},{"price":"33421.26","size":"0"}],"sequence":5708351,"timestamp":"2021-07-03T00:56:47.055Z","symbol":"BTCDAI"}}
1625273807.2317362: {"jsonrpc":"2.0","method":"updateOrderbook","params":{"ask":[{"price":"0.00011634","size":"12896.83"},{"price":"0.00011649","size":"0"},{"price":"0.00018658","size":"10554.74"},{"price":"0.00018932","size":"0"},{"price":"0.00021790","size":"15617.57"},{"price":"0.00022582","size":"0"}],"bid":[{"price":"0.00011571","size":"723.13"},{"price":"0.00011570","size":"87.20"}],"sequence":12351842,"timestamp":"2021-07-03T00:56:47.148Z","symbol":"EOSBTC"}}
1625273807.231782: {"jsonrpc":"2.0","method":"updateOrderbook","params":{"ask":[{"price":"33544.96","size":"0.02460"},{"price":"33545.17","size":"0"},{"price":"33671.93","size":"1.25250"},{"price":"33699.88","size":"0"},{"price":"33701.20","size":"0.45190"},{"price":"33731.53","size":"0"},{"price":"167635.20","size":"0"},{"price":"167642.08","size":"0.00016"}],"bid":[{"price":"33537.86","size":"0.02940"},{"price":"33535.81","size":"0"},{"price":"33528.98","size":"1.43690"},{"price":"33528.41","size":"0"},{"price":"33517.42","size":"1.10595"},{"price":"33516.71","size":"0"},{"price":"10058.52","size":"0.00012"},{"price":"10057.72","size":"0"}],"sequence":12626855,"timestamp":"2021-07-03T00:56:47.131Z","symbol":"BTCUSDB"}}
1625273807.23185: {"jsonrpc":"2.0","method":"updateOrderbook","params":{"ask":[{"price":"33673.93","size":"0.00533"},{"price":"33674.25","size":"0"}],"bid":[],"sequence":7211286,"timestamp":"2021-07-03T00:56:47.071Z","symbol":"BTCPAX"}}
1625273807.231864: {"jsonrpc":"2.0","method":"updateOrderbook","params":{"ask":[{"price":"33518.07","size":"0.01234"},{"price":"33518.83","size":"0"}],"bid":[],"sequence":7477026,"timestamp":"2021-07-03T00:56:47.126Z","symbol":"BTCTUSD"}}
1625273807.328744: {"jsonrpc":"2.0","method":"updateOrderbook","params":{"ask":[{"price":"33543.40","size":"0.02460"},{"price":"33544.96","size":"0"},{"price":"33549.16","size":"0"},{"price":"33550.21","size":"0.05940"}],"bid":[{"price":"33538.86","size":"0.02940"},{"price":"33537.86","size":"0"}],"sequence":12626856,"timestamp":"2021-07-03T00:56:47.252Z","symbol":"BTCUSDB"}}
1625273807.328872: {"jsonrpc":"2.0","method":"updateOrderbook","params":{"ask":[{"price":"33668.09","size":"0.00533"},{"price":"33673.93","size":"0"},{"price":"33679.22","size":"0.00533"},{"price":"33685.28","size":"0"}],"bid":[{"price":"33435.60","size":"0.24960"},{"price":"33411.33","size":"0"}],"sequence":7211287,"timestamp":"2021-07-03T00:56:47.231Z","symbol":"BTCPAX"}}
1625273807.329376: {"jsonrpc":"2.0","method":"updateOrderbook","params":{"ask":[{"price":"33518.07","size":"0"},{"price":"33518.32","size":"0.01234"}],"bid":[{"price":"33498.82","size":"0"},{"price":"33496.98","size":"0.01475"}],"sequence":7477027,"timestamp":"2021-07-03T00:56:47.205Z","symbol":"BTCTUSD"}}
1625273807.430006: {"jsonrpc":"2.0","method":"updateOrderbook","params":{"ask":[{"price":"33542.30","size":"0.02460"},{"price":"33543.40","size":"0"},{"price":"33547.97","size":"0.05940"},{"price":"33550.21","size":"0"}],"bid":[{"price":"33539.63","size":"0.02940"},{"price":"33538.86","size":"0"},{"price":"33534.37","size":"0.05460"},{"price":"33531.13","size":"0"}],"sequence":12626857,"timestamp":"2021-07-03T00:56:47.353Z","symbol":"BTCUSDB"}}
1625273807.430156: {"jsonrpc":"2.0","method":"updateOrderbook","params":{"ask":[{"price":"0.00011584","size":"223.04"},{"price":"0.00011585","size":"120.44"}],"bid":[],"sequence":12351843,"timestamp":"2021-07-03T00:56:47.325Z","symbol":"EOSBTC"}}
1625273807.433184: {"jsonrpc":"2.0","method":"updateOrderbook","params":{"ask":[{"price":"33518.32","size":"0"},{"price":"33518.70","size":"0.01234"}],"bid":[],"sequence":7477028,"timestamp":"2021-07-03T00:56:47.262Z","symbol":"BTCTUSD"}}
1625273807.5313091: {"jsonrpc":"2.0","method":"updateOrderbook","params":{"ask":[],"bid":[{"price":"33427.55","size":"0.23620"},{"price":"33387.36","size":"0"}],"sequence":5708352,"timestamp":"2021-07-03T00:56:47.360Z","symbol":"BTCDAI"}}
1625273807.5313668: {"jsonrpc":"2.0","method":"updateOrderbook","params":{"ask":[{"price":"33541.87","size":"0.02460"},{"price":"33542.30","size":"0"}],"bid":[{"price":"33540.11","size":"0.02940"},{"price":"33539.63","size":"0"}],"sequence":12626858,"timestamp":"2021-07-03T00:56:47.426Z","symbol":"BTCUSDB"}}
1625273807.531473: {"jsonrpc":"2.0","method":"updateOrderbook","params":{"ask":[{"price":"0.00099879","size":"0"}],"bid":[{"price":"0.00011019","size":"7497.84"},{"price":"0.00010940","size":"0"}],"sequence":12351844,"timestamp":"2021-07-03T00:56:47.452Z","symbol":"EOSBTC"}}
1625273807.5382001: {"jsonrpc":"2.0","method":"updateOrderbook","params":{"ask":[{"price":"0.07706","size":"6.2765"},{"price":"0.07715","size":"0"}],"bid":[{"price":"0.07592","size":"3.9135"},{"price":"0.07586","size":"0"}],"sequence":7340015,"timestamp":"2021-07-03T00:56:47.432Z","symbol":"MKRBTC"}}
1625273807.629497: {"jsonrpc":"2.0","method":"updateOrderbook","params":{"ask":[{"price":"33541.57","size":"0.02460"},{"price":"33541.87","size":"0"}],"bid":[{"price":"33465.30","size":"0.63848"},{"price":"33454.47","size":"0"}],"sequence":12626859,"timestamp":"2021-07-03T00:56:47.509Z","symbol":"BTCUSDB"}}
1625273807.629623: {"jsonrpc":"2.0","method":"updateOrderbook","params":{"ask":[{"price":"33668.09","size":"0"},{"price":"33668.33","size":"0.00533"}],"bid":[],"sequence":7211288,"timestamp":"2021-07-03T00:56:47.469Z","symbol":"BTCPAX"}}
1625273807.63117: {"jsonrpc":"2.0","method":"updateOrderbook","params":{"ask":[{"price":"0.07666","size":"0"},{"price":"0.07672","size":"3.0585"}],"bid":[{"price":"0.07592","size":"5.3291"},{"price":"0.07588","size":"0"}],"sequence":7340016,"timestamp":"2021-07-03T00:56:47.509Z","symbol":"MKRBTC"}}
1625273807.7319129: {"jsonrpc":"2.0","method":"updateOrderbook","params":{"ask":[],"bid":[{"price":"33533.02","size":"1.81560"},{"price":"33530.32","size":"0"},{"price":"33520.83","size":"0.94240"},{"price":"33518.00","size":"0"}],"sequence":12626860,"timestamp":"2021-07-03T00:56:47.604Z","symbol":"BTCUSDB"}}
1625273807.731947: {"jsonrpc":"2.0","method":"updateOrderbook","params":{"ask":[],"bid":[{"price":"33359.39","size":"0.37050"},{"price":"33313.65","size":"0"}],"sequence":7211289,"timestamp":"2021-07-03T00:56:47.572Z","symbol":"BTCPAX"}}
1625273807.731967: {"jsonrpc":"2.0","method":"updateOrderbook","params":{"ask":[{"price":"0.07649","size":"2.5835"},{"price":"0.07659","size":"6.2737"},{"price":"0.07672","size":"0.6900"},{"price":"0.07678","size":"5.7931"},{"price":"0.07706","size":"0"},{"price":"0.07716","size":"6.2765"}],"bid":[],"sequence":7340017,"timestamp":"2021-07-03T00:56:47.606Z","symbol":"MKRBTC"}}
1625273807.83344: {"jsonrpc":"2.0","method":"updateOrderbook","params":{"ask":[],"bid":[{"price":"33417.14","size":"0.38830"},{"price":"33386.67","size":"0.46920"},{"price":"33376.85","size":"0"},{"price":"33353.38","size":"0"}],"sequence":5708353,"timestamp":"2021-07-03T00:56:47.665Z","symbol":"BTCDAI"}}
