1618677396.685211: {"stream":"aaveupusdt@depth@100ms","data":{"e":"depthUpdate","E":1618677396631,"s":"AAVEUPUSDT","U":82464077,"u":82464079,"b":[["84.40100000","0.00000000"],["84.40000000","1.25000000"],["83.76900000","0.00000000"],["83.69200000","314.76000000"]],"a":[]}}
1618677396.771754: {"stream":"aaveupusdt@bookTicker","data":{"u":82464080,"s":"AAVEUPUSDT","b":"84.40000000","B":"1.25000000","a":"84.92800000","A":"0.25000000"}}
1618677396.787137: {"stream":"aaveupusdt@depth@100ms","data":{"e":"depthUpdate","E":1618677396731,"s":"AAVEUPUSDT","U":82464080,"u":82464080,"b":[],"a":[["84.92800000","0.25000000"]]}}
1618677396.887111: {"stream":"aaveupusdt@depth@100ms","data":{"e":"depthUpdate","E":1618677396831,"s":"AAVEUPUSDT","U":82464081,"u":82464081,"b":[],"a":[["84.93000000","105.93000000"]]}}
1618677396.930793: {"stream":"aaveupusdt@bookTicker","data":{"u":82464083,"s":"AAVEUPUSDT","b":"84.40000000","B":"1.25000000","a":"84.92800000","A":"0.42000000"}}
1618677396.986439: {"stream":"aaveupusdt@depth@100ms","data":{"e":"depthUpdate","E":1618677396931,"s":"AAVEUPUSDT","U":82464082,"u":82464084,"b":[],"a":[["84.92800000","0.42000000"],["84.92900000","0.00000000"],["84.93000000","0.00000000"]]}}
1618677397.132771: {"stream":"gtobtc@bookTicker","data":{"u":137196759,"s":"GTOBTC","b":"0.00000162","B":"54715.00000000","a":"0.00000163","A":"345860.00000000"}}
1618677397.1338072: {"stream":"gtobtc@bookTicker","data":{"u":137196760,"s":"GTOBTC","b":"0.00000162","B":"64715.00000000","a":"0.00000163","A":"345860.00000000"}}
1618677397.1475708: {"stream":"veteth@bookTicker","data":{"u":327913338,"s":"VETETH","b":"0.00009379","B":"200.00000000","a":"0.00009400","A":"12565.00000000"}}
1618677397.151134: {"stream":"swrvbusd@bookTicker","data":{"u":64830362,"s":"SWRVBUSD","b":"2.27100000","B":"22.01100000","a":"2.27700000","A":"1.19200000"}}
1618677397.165474: {"stream":"veteth@bookTicker","data":{"u":327913340,"s":"VETETH","b":"0.00009379","B":"200.00000000","a":"0.00009399","A":"83459.00000000"}}
1618677397.185257: {"stream":"veteth@depth@100ms","data":{"e":"depthUpdate","E":1618677397130,"s":"VETETH","U":327913338,"u":327913341,"b":[],"a":[["0.00009399","83459.00000000"],["0.00009400","0.00000000"],["0.00009401","0.00000000"]]}}
1618677397.1854222: {"stream":"swrvbusd@depth@100ms","data":{"e":"depthUpdate","E":1618677397130,"s":"SWRVBUSD","U":64830361,"u":64830362,"b":[["2.26700000","9.28800000"],["2.26600000","98.59100000"]],"a":[["2.27600000","0.00000000"]]}}
1618677397.1855192: {"stream":"gtobtc@depth@100ms","data":{"e":"depthUpdate","E":1618677397131,"s":"GTOBTC","U":137196759,"u":137196760,"b":[["0.00000162","64715.00000000"]],"a":[]}}
1618677397.193506: {"stream":"aaveupusdt@bookTicker","data":{"u":82464085,"s":"AAVEUPUSDT","b":"84.40000000","B":"1.25000000","a":"84.92700000","A":"94.16000000"}}
1618677397.2020962: {"stream":"gtobtc@bookTicker","data":{"u":137196761,"s":"GTOBTC","b":"0.00000162","B":"73974.00000000","a":"0.00000163","A":"345860.00000000"}}
1618677397.208436: {"stream":"aaveupusdt@bookTicker","data":{"u":82464086,"s":"AAVEUPUSDT","b":"84.40000000","B":"1.25000000","a":"84.92700000","A":"200.09000000"}}
1618677397.215961: {"stream":"swrvbusd@bookTicker","data":{"u":64830365,"s":"SWRVBUSD","b":"2.27100000","B":"22.01100000","a":"2.27600000","A":"20.45400000"}}
1618677397.284519: {"stream":"aaveupusdt@bookTicker","data":{"u":82464087,"s":"AAVEUPUSDT","b":"84.27300000","B":"35.61000000","a":"84.92700000","A":"200.09000000"}}
1618677397.2846022: {"stream":"swrvbusd@depth@100ms","data":{"e":"depthUpdate","E":1618677397230,"s":"SWRVBUSD","U":64830363,"u":64830366,"b":[["2.26700000","42.27600000"],["2.26500000","171.22500000"]],"a":[["2.27600000","20.45400000"]]}}
1618677397.284731: {"stream":"gtobtc@depth@100ms","data":{"e":"depthUpdate","E":1618677397231,"s":"GTOBTC","U":137196761,"u":137196761,"b":[["0.00000162","73974.00000000"]],"a":[]}}
1618677397.2850869: {"stream":"aaveupusdt@depth@100ms","data":{"e":"depthUpdate","E":1618677397231,"s":"AAVEUPUSDT","U":82464085,"u":82464087,"b":[["84.40000000","0.00000000"]],"a":[["84.92700000","200.09000000"]]}}
1618677397.297205: {"stream":"veteth@bookTicker","data":{"u":327913342,"s":"VETETH","b":"0.00009379","B":"200.00000000","a":"0.00009402","A":"20116.00000000"}}
1618677397.298932: {"stream":"aaveupusdt@bookTicker","data":{"u":82464088,"s":"AAVEUPUSDT","b":"84.27300000","B":"35.61000000","a":"84.92700000","A":"221.49000000"}}
1618677397.298996: {"stream":"gtobtc@bookTicker","data":{"u":137196762,"s":"GTOBTC","b":"0.00000162","B":"63974.00000000","a":"0.00000163","A":"345860.00000000"}}
1618677397.308011: {"stream":"veteth@bookTicker","data":{"u":327913343,"s":"VETETH","b":"0.00009379","B":"200.00000000","a":"0.00009401","A":"83459.00000000"}}
1618677397.339825: {"stream":"veteth@bookTicker","data":{"u":327913344,"s":"VETETH","b":"0.00009380","B":"200.00000000","a":"0.00009401","A":"83459.00000000"}}
1618677397.38535: {"stream":"veteth@depth@100ms","data":{"e":"depthUpdate","E":1618677397330,"s":"VETETH","U":327913342,"u":327913345,"b":[["0.00009380","200.00000000"],["0.00009377","0.00000000"]],"a":[["0.00009399","0.00000000"],["0.00009401","83459.00000000"]]}}
1618677397.385535: {"stream":"gtobtc@depth@100ms","data":{"e":"depthUpdate","E":1618677397331,"s":"GTOBTC","U":137196762,"u":137196762,"b":[["0.00000162","63974.00000000"]],"a":[]}}
1618677397.3856: {"stream":"aaveupusdt@depth@100ms","data":{"e":"depthUpdate","E":1618677397331,"s":"AAVEUPUSDT","U":82464088,"u":82464088,"b":[],"a":[["84.92700000","221.49000000"]]}}
1618677397.483895: {"stream":"veteth@depth@100ms","data":{"e":"depthUpdate","E":1618677397430,"s":"VETETH","U":327913346,"u":327913348,"b":[["0.00009379","0.00000000"]],"a":[["0.00009456","200000.00000000"],["0.00009469","0.00000000"]]}}
1618677397.487493: {"stream":"aaveupusdt@depth@100ms","data":{"e":"depthUpdate","E":1618677397431,"s":"AAVEUPUSDT","U":82464089,"u":82464089,"b":[],"a":[["84.92800000","0.17000000"]]}}
1618677397.5132532: {"stream":"aaveupusdt@bookTicker","data":{"u":82464090,"s":"AAVEUPUSDT","b":"84.27300000","B":"35.61000000","a":"84.92600000","A":"0.25000000"}}
1618677397.586528: {"stream":"aaveupusdt@bookTicker","data":{"u":82464091,"s":"AAVEUPUSDT","b":"84.27300000","B":"23.74000000","a":"84.92600000","A":"0.25000000"}}
1618677397.594044: {"stream":"veteth@depth@100ms","data":{"e":"depthUpdate","E":1618677397530,"s":"VETETH","U":327913349,"u":327913350,"b":[["0.00009378","0.00000000"],["0.00009376","96556.00000000"]],"a":[]}}
1618677397.594193: {"stream":"aaveupusdt@depth@100ms","data":{"e":"depthUpdate","E":1618677397531,"s":"AAVEUPUSDT","U":82464090,"u":82464091,"b":[["84.27300000","23.74000000"]],"a":[["84.92600000","0.25000000"]]}}
1618677397.59428: {"stream":"aaveupusdt@bookTicker","data":{"u":82464092,"s":"AAVEUPUSDT","b":"84.27300000","B":"11.87000000","a":"84.92600000","A":"0.25000000"}}
1618677397.594316: {"stream":"aaveupusdt@bookTicker","data":{"u":82464093,"s":"AAVEUPUSDT","b":"84.19000000","B":"23.76000000","a":"84.92600000","A":"0.25000000"}}
1618677397.61428: {"stream":"qspbtc@aggTrade","data":{"e":"aggTrade","E":1618677397559,"s":"QSPBTC","a":5549025,"p":"0.00000169","q":"8896.00000000","f":7684049,"l":7684049,"T":1618677397557,"m":false,"M":true}}
1618677397.614361: {"stream":"qspbtc@bookTicker","data":{"u":105811223,"s":"QSPBTC","b":"0.00000168","B":"197838.00000000","a":"0.00000169","A":"87543.00000000"}}
1618677397.627268: {"stream":"qspbtc@kline_1m","data":{"e":"kline","E":1618677397561,"s":"QSPBTC","k":{"t":1618677360000,"T":1618677419999,"s":"QSPBTC","i":"1m","f":7684049,"L":7684049,"o":"0.00000169","c":"0.00000169","h":"0.00000169","l":"0.00000169","v":"8896.00000000","n":1,"x":false,"q":"0.01503424","V":"8896.00000000","Q":"0.01503424","B":"0"}}}
1618677397.691381: {"stream":"qspbtc@depth@100ms","data":{"e":"depthUpdate","E":1618677397630,"s":"QSPBTC","U":105811223,"u":105811223,"b":[],"a":[["0.00000169","87543.00000000"]]}}
1618677397.691485: {"stream":"aaveupusdt@depth@100ms","data":{"e":"depthUpdate","E":1618677397631,"s":"AAVEUPUSDT","U":82464092,"u":82464100,"b":[["84.27300000","0.00000000"],["84.18200000","0.00000000"],["83.99600000","4.36000000"],["82.63400000","0.00000000"]],"a":[["84.92700000","360.03000000"],["84.99600000","0.00000000"]]}}
1618677397.795102: {"stream":"aaveupusdt@depth@100ms","data":{"e":"depthUpdate","E":1618677397731,"s":"AAVEUPUSDT","U":82464101,"u":82464101,"b":[],"a":[["84.92800000","0.00000000"]]}}
1618677397.795261: {"stream":"swrvbusd@bookTicker","data":{"u":64830367,"s":"SWRVBUSD","b":"2.27100000","B":"22.01100000","a":"2.27700000","A":"1.19200000"}}
1618677397.8163252: {"stream":"gtobtc@bookTicker","data":{"u":137196763,"s":"GTOBTC","b":"0.00000162","B":"58886.00000000","a":"0.00000163","A":"345860.00000000"}}
1618677397.8203871: {"stream":"gtobtc@bookTicker","data":{"u":137196764,"s":"GTOBTC","b":"0.00000162","B":"62918.00000000","a":"0.00000163","A":"345860.00000000"}}
1618677397.844042: {"stream":"gtobtc@bookTicker","data":{"u":137196765,"s":"GTOBTC","b":"0.00000162","B":"58886.00000000","a":"0.00000163","A":"345860.00000000"}}
1618677397.8631308: {"stream":"swrvbusd@bookTicker","data":{"u":64830368,"s":"SWRVBUSD","b":"2.27100000","B":"22.01100000","a":"2.27600000","A":"20.45400000"}}
1618677397.885202: {"stream":"veteth@depth@100ms","data":{"e":"depthUpdate","E":1618677397830,"s":"VETETH","U":327913351,"u":327913352,"b":[],"a":[["0.00009457","3580.00000000"],["0.00009476","111.00000000"]]}}
1618677397.885319: {"stream":"swrvbusd@depth@100ms","data":{"e":"depthUpdate","E":1618677397831,"s":"SWRVBUSD","U":64830367,"u":64830368,"b":[],"a":[["2.27600000","20.45400000"]]}}
1618677397.885382: {"stream":"gtobtc@depth@100ms","data":{"e":"depthUpdate","E":1618677397831,"s":"GTOBTC","U":137196763,"u":137196765,"b":[["0.00000162","58886.00000000"]],"a":[]}}
1618677397.957498: {"stream":"onttry@bookTicker","data":{"u":282126,"s":"ONTTRY","b":"18.94000000","B":"204.81000000","a":"18.99000000","A":"153.06000000"}}
1618677397.9575622: {"stream":"onttry@aggTrade","data":{"e":"aggTrade","E":1618677397900,"s":"ONTTRY","a":8614,"p":"18.99000000","q":"57.21000000","f":9336,"l":9336,"T":1618677397899,"m":false,"M":true}}
1618677397.99005: {"stream":"onttry@depth@100ms","data":{"e":"depthUpdate","E":1618677397931,"s":"ONTTRY","U":282126,"u":282126,"b":[],"a":[["18.99000000","153.06000000"]]}}
1618677397.9901628: {"stream":"swrvbusd@depth@100ms","data":{"e":"depthUpdate","E":1618677397931,"s":"SWRVBUSD","U":64830369,"u":64830369,"b":[],"a":[["4.10000000","61509.25200000"]]}}
1618677398.087153: {"stream":"veteth@depth@100ms","data":{"e":"depthUpdate","E":1618677398031,"s":"VETETH","U":327913353,"u":327913353,"b":[],"a":[["0.00009420","0.00000000"]]}}
1618677398.2259269: {"stream":"aaveupusdt@bookTicker","data":{"u":82464103,"s":"AAVEUPUSDT","b":"84.19000000","B":"23.76000000","a":"84.92600000","A":"66.87000000"}}
1618677398.28414: {"stream":"veteth@depth@100ms","data":{"e":"depthUpdate","E":1618677398231,"s":"VETETH","U":327913354,"u":327913357,"b":[["0.00009347","0.00000000"],["0.00009339","132310.00000000"]],"a":[["0.00009402","166489.00000000"],["0.00009410","540.00000000"]]}}
1618677398.2861052: {"stream":"aaveupusdt@depth@100ms","data":{"e":"depthUpdate","E":1618677398231,"s":"AAVEUPUSDT","U":82464102,"u":82464103,"b":[],"a":[["84.92600000","66.87000000"],["84.93300000","0.00000000"]]}}
1618677398.32614: {"stream":"gtobtc@bookTicker","data":{"u":137196766,"s":"GTOBTC","b":"0.00000162","B":"49627.00000000","a":"0.00000163","A":"345860.00000000"}}
1618677398.326924: {"stream":"swrvbusd@bookTicker","data":{"u":64830371,"s":"SWRVBUSD","b":"2.27100000","B":"22.01100000","a":"2.27700000","A":"1.19200000"}}
1618677398.358274: {"stream":"aaveupusdt@bookTicker","data":{"u":82464104,"s":"AAVEUPUSDT","b":"84.19000000","B":"23.76000000","a":"84.92600000","A":"66.62000000"}}
1618677398.3839612: {"stream":"veteth@depth@100ms","data":{"e":"depthUpdate","E":1618677398331,"s":"VETETH","U":327913358,"u":327913358,"b":[],"a":[["0.00009402","146373.00000000"]]}}
1618677398.386776: {"stream":"swrvbusd@depth@100ms","data":{"e":"depthUpdate","E":1618677398331,"s":"SWRVBUSD","U":64830370,"u":64830374,"b":[["2.26700000","9.28800000"],["2.26600000","222.47900000"],["2.26500000","171.22500000"]],"a":[["2.27600000","0.00000000"]]}}
1618677398.386931: {"stream":"gtobtc@depth@100ms","data":{"e":"depthUpdate","E":1618677398331,"s":"GTOBTC","U":137196766,"u":137196766,"b":[["0.00000162","49627.00000000"]],"a":[]}}
1618677398.386997: {"stream":"aaveupusdt@depth@100ms","data":{"e":"depthUpdate","E":1618677398331,"s":"AAVEUPUSDT","U":82464104,"u":82464104,"b":[],"a":[["84.92600000","66.62000000"]]}}
1618677398.391459: {"stream":"onttry@bookTicker","data":{"u":282127,"s":"ONTTRY","b":"18.92000000","B":"155.57000000","a":"18.99000000","A":"153.06000000"}}
1618677398.392311: {"stream":"swrvbusd@bookTicker","data":{"u":64830375,"s":"SWRVBUSD","b":"2.27100000","B":"22.01100000","a":"2.27600000","A":"20.45400000"}}
1618677398.486749: {"stream":"onttry@depth@100ms","data":{"e":"depthUpdate","E":1618677398431,"s":"ONTTRY","U":282127,"u":282128,"b":[["18.94000000","0.00000000"],["18.59000000","1842.69000000"]],"a":[]}}
1618677398.486891: {"stream":"swrvbusd@depth@100ms","data":{"e":"depthUpdate","E":1618677398431,"s":"SWRVBUSD","U":64830375,"u":64830376,"b":[["2.26500000","165.06800000"]],"a":[["2.27600000","20.45400000"]]}}
1618677398.486978: {"stream":"aaveupusdt@depth@100ms","data":{"e":"depthUpdate","E":1618677398431,"s":"AAVEUPUSDT","U":82464105,"u":82464105,"b":[["81.65900000","0.00000000"]],"a":[]}}
1618677398.541771: {"stream":"aaveupusdt@bookTicker","data":{"u":82464106,"s":"AAVEUPUSDT","b":"84.19000000","B":"23.76000000","a":"84.92500000","A":"0.25000000"}}
1618677398.586755: {"stream":"busdtry@depth@100ms","data":{"e":"depthUpdate","E":1618677398531,"s":"BUSDTRY","U":10166147,"u":10166147,"b":[["8.10000000","83259.77000000"]],"a":[]}}
1618677398.586859: {"stream":"aaveupusdt@depth@100ms","data":{"e":"depthUpdate","E":1618677398531,"s":"AAVEUPUSDT","U":82464106,"u":82464106,"b":[],"a":[["84.92500000","0.25000000"]]}}
1618677398.651157: {"stream":"veteth@bookTicker","data":{"u":327913359,"s":"VETETH","b":"0.00009380","B":"200.00000000","a":"0.00009400","A":"20116.00000000"}}
1618677398.666511: {"stream":"veteth@bookTicker","data":{"u":327913361,"s":"VETETH","b":"0.00009380","B":"200.00000000","a":"0.00009399","A":"83459.00000000"}}
1618677398.684244: {"stream":"veteth@depth@100ms","data":{"e":"depthUpdate","E":1618677398631,"s":"VETETH","U":327913359,"u":327913361,"b":[],"a":[["0.00009399","83459.00000000"],["0.00009400","20116.00000000"],["0.00009401","0.00000000"]]}}
1618677398.787651: {"stream":"aaveupusdt@depth@100ms","data":{"e":"depthUpdate","E":1618677398731,"s":"AAVEUPUSDT","U":82464107,"u":82464107,"b":[["81.82600000","2.47000000"]],"a":[]}}
1618677398.838704: {"stream":"onttry@bookTicker","data":{"u":282129,"s":"ONTTRY","b":"18.92000000","B":"199.56000000","a":"18.99000000","A":"153.06000000"}}
1618677398.881384: {"stream":"swrvbusd@bookTicker","data":{"u":64830378,"s":"SWRVBUSD","b":"2.27100000","B":"22.01100000","a":"2.27700000","A":"1.19200000"}}
1618677398.884685: {"stream":"onttry@depth@100ms","data":{"e":"depthUpdate","E":1618677398831,"s":"ONTTRY","U":282129,"u":282129,"b":[["18.92000000","199.56000000"]],"a":[]}}
1618677398.884798: {"stream":"swrvbusd@depth@100ms","data":{"e":"depthUpdate","E":1618677398831,"s":"SWRVBUSD","U":64830377,"u":64830378,"b":[["2.26600000","131.57900000"]],"a":[["2.27600000","0.00000000"]]}}
1618677398.902566: {"stream":"veteth@bookTicker","data":{"u":327913362,"s":"VETETH","b":"0.00009380","B":"11200.00000000","a":"0.00009399","A":"83459.00000000"}}
1618677398.948836: {"stream":"swrvbusd@bookTicker","data":{"u":64830379,"s":"SWRVBUSD","b":"2.27100000","B":"22.01100000","a":"2.27600000","A":"20.45400000"}}
1618677398.9865742: {"stream":"veteth@depth@100ms","data":{"e":"depthUpdate","E":1618677398931,"s":"VETETH","U":327913362,"u":327913362,"b":[["0.00009380","11200.00000000"]],"a":[]}}
1618677398.9866922: {"stream":"swrvbusd@depth@100ms","data":{"e":"depthUpdate","E":1618677398931,"s":"SWRVBUSD","U":64830379,"u":64830379,"b":[],"a":[["2.27600000","20.45400000"]]}}
1618677399.024843: {"stream":"aaveupusdt@kline_1m","data":{"e":"kline","E":1618677398956,"s":"AAVEUPUSDT","k":{"t":1618677360000,"T":1618677419999,"s":"AAVEUPUSDT","i":"1m","f":1857323,"L":1857329,"o":"84.58500000","c":"84.40000000","h":"84.69900000","l":"84.40000000","v":"8.65000000","n":7,"x":false,"q":"731.92373000","V":"1.65000000","Q":"139.62848000","B":"0"}}}
1618677399.085799: {"stream":"veteth@depth@100ms","data":{"e":"depthUpdate","E":1618677399031,"s":"VETETH","U":327913363,"u":327913363,"b":[],"a":[["0.00009413","2619.00000000"]]}}
1618677399.0859368: {"stream":"qspbtc@depth@100ms","data":{"e":"depthUpdate","E":1618677399031,"s":"QSPBTC","U":105811224,"u":105811224,"b":[],"a":[["0.00000225","119868.00000000"]]}}
1618677399.286603: {"stream":"aaveupusdt@depth@100ms","data":{"e":"depthUpdate","E":1618677399232,"s":"AAVEUPUSDT","U":82464108,"u":82464109,"b":[],"a":[["84.92700000","159.94000000"]]}}
1618677399.3277671: {"stream":"aaveupusdt@bookTicker","data":{"u":82464111,"s":"AAVEUPUSDT","b":"84.19000000","B":"23.76000000","a":"84.92400000","A":"0.17000000"}}
1618677399.386687: {"stream":"aaveupusdt@depth@100ms","data":{"e":"depthUpdate","E":1618677399332,"s":"AAVEUPUSDT","U":82464110,"u":82464111,"b":[],"a":[["84.92400000","0.17000000"],["84.92700000","138.54000000"]]}}
1618677399.485965: {"stream":"swrvbusd@depth@100ms","data":{"e":"depthUpdate","E":1618677399431,"s":"SWRVBUSD","U":64830380,"u":64830381,"b":[["2.26600000","98.59100000"],["2.26500000","139.51700000"]],"a":[]}}
1618677399.486488: {"stream":"aaveupusdt@depth@100ms","data":{"e":"depthUpdate","E":1618677399432,"s":"AAVEUPUSDT","U":82464112,"u":82464113,"b":[["84.11600000","23.78000000"]],"a":[]}}
1618677399.501747: {"stream":"swrvbusd@bookTicker","data":{"u":64830383,"s":"SWRVBUSD","b":"2.27100000","B":"22.01100000","a":"2.27700000","A":"1.19200000"}}
1618677399.512526: {"stream":"onttry@aggTrade","data":{"e":"aggTrade","E":1618677399456,"s":"ONTTRY","a":8615,"p":"18.92000000","q":"16.67000000","f":9337,"l":9337,"T":1618677399450,"m":true,"M":true}}
1618677399.512627: {"stream":"onttry@bookTicker","data":{"u":282130,"s":"ONTTRY","b":"18.92000000","B":"182.89000000","a":"18.99000000","A":"153.06000000"}}
1618677399.512667: {"stream":"onttry@bookTicker","data":{"u":282131,"s":"ONTTRY","b":"18.92000000","B":"182.89000000","a":"18.98000000","A":"1677.58000000"}}
1618677399.51747: {"stream":"onttry@kline_1m","data":{"e":"kline","E":1618677399463,"s":"ONTTRY","k":{"t":1618677360000,"T":1618677419999,"s":"ONTTRY","i":"1m","f":9332,"L":9337,"o":"19.00000000","c":"18.92000000","h":"19.00000000","l":"18.92000000","v":"530.76000000","n":6,"x":false,"q":"10078.23170000","V":"62.21000000","Q":"1181.41790000","B":"0"}}}
1618677399.521342: {"stream":"onttry@bookTicker","data":{"u":282132,"s":"ONTTRY","b":"18.92000000","B":"182.89000000","a":"18.99000000","A":"153.06000000"}}
1618677399.530079: {"stream":"onttry@bookTicker","data":{"u":282133,"s":"ONTTRY","b":"18.92000000","B":"172.76000000","a":"18.99000000","A":"153.06000000"}}
1618677399.530138: {"stream":"onttry@aggTrade","data":{"e":"aggTrade","E":1618677399476,"s":"ONTTRY","a":8616,"p":"18.92000000","q":"10.13000000","f":9338,"l":9338,"T":1618677399465,"m":true,"M":true}}
1618677399.5583591: {"stream":"veteth@bookTicker","data":{"u":327913365,"s":"VETETH","b":"0.00009381","B":"96556.00000000","a":"0.00009399","A":"83459.00000000"}}
1618677399.566148: {"stream":"swrvbusd@bookTicker","data":{"u":64830386,"s":"SWRVBUSD","b":"2.27100000","B":"22.01100000","a":"2.27600000","A":"20.45400000"}}
1618677399.5733702: {"stream":"onttry@bookTicker","data":{"u":282136,"s":"ONTTRY","b":"18.90000000","B":"185.50000000","a":"18.99000000","A":"153.06000000"}}
1618677399.5734541: {"stream":"onttry@aggTrade","data":{"e":"aggTrade","E":1618677399519,"s":"ONTTRY","a":8617,"p":"18.92000000","q":"172.76000000","f":9339,"l":9340,"T":1618677399513,"m":true,"M":true}}
1618677399.586949: {"stream":"veteth@depth@100ms","data":{"e":"depthUpdate","E":1618677399531,"s":"VETETH","U":327913364,"u":327913366,"b":[["0.00009381","96556.00000000"],["0.00009380","200.00000000"],["0.00009376","0.00000000"]],"a":[]}}
1618677399.587138: {"stream":"onttry@depth@100ms","data":{"e":"depthUpdate","E":1618677399531,"s":"ONTTRY","U":282130,"u":282136,"b":[["18.92000000","0.00000000"],["18.82000000","277.03000000"]],"a":[["18.98000000","0.00000000"],["19.11000000","1798.74000000"]]}}
1618677399.5877278: {"stream":"swrvbusd@depth@100ms","data":{"e":"depthUpdate","E":1618677399531,"s":"SWRVBUSD","U":64830382,"u":64830387,"b":[["2.26600000","131.57900000"],["2.26500000","171.22500000"]],"a":[["2.27600000","20.45400000"]]}}
1618677399.5878332: {"stream":"aaveupusdt@depth@100ms","data":{"e":"depthUpdate","E":1618677399532,"s":"AAVEUPUSDT","U":82464114,"u":82464114,"b":[],"a":[["84.92500000","0.00000000"]]}}
1618677399.6279318: {"stream":"aaveupusdt@bookTicker","data":{"u":82464116,"s":"AAVEUPUSDT","b":"84.19000000","B":"23.76000000","a":"84.92300000","A":"0.25000000"}}
1618677399.6577432: {"stream":"onttry@bookTicker","data":{"u":282139,"s":"ONTTRY","b":"18.90000000","B":"185.50000000","a":"18.98000000","A":"223.80000000"}}
1618677399.681206: {"stream":"onttry@bookTicker","data":{"u":282142,"s":"ONTTRY","b":"18.90000000","B":"185.50000000","a":"18.99000000","A":"153.06000000"}}
1618677399.6868439: {"stream":"veteth@depth@100ms","data":{"e":"depthUpdate","E":1618677399631,"s":"VETETH","U":327913367,"u":327913367,"b":[["0.00009380","0.00000000"]],"a":[]}}
1618677399.687001: {"stream":"onttry@depth@100ms","data":{"e":"depthUpdate","E":1618677399631,"s":"ONTTRY","U":282137,"u":282142,"b":[["18.76000000","199.74000000"]],"a":[["18.98000000","0.00000000"],["19.06000000","199.47000000"],["19.07000000","0.00000000"]]}}
1618677399.687108: {"stream":"swrvbusd@depth@100ms","data":{"e":"depthUpdate","E":1618677399631,"s":"SWRVBUSD","U":64830388,"u":64830388,"b":[["2.26500000","165.06800000"]],"a":[]}}
1618677399.688388: {"stream":"aaveupusdt@depth@100ms","data":{"e":"depthUpdate","E":1618677399632,"s":"AAVEUPUSDT","U":82464115,"u":82464116,"b":[["82.55200000","2.06000000"]],"a":[["84.92300000","0.25000000"]]}}
1618677399.702925: {"stream":"veteth@bookTicker","data":{"u":327913368,"s":"VETETH","b":"0.00009375","B":"9033.00000000","a":"0.00009399","A":"83459.00000000"}}
1618677399.7245162: {"stream":"veteth@bookTicker","data":{"u":327913369,"s":"VETETH","b":"0.00009376","B":"96556.00000000","a":"0.00009399","A":"83459.00000000"}}
1618677399.734633: {"stream":"veteth@bookTicker","data":{"u":327913370,"s":"VETETH","b":"0.00009376","B":"116672.00000000","a":"0.00009399","A":"83459.00000000"}}
1618677399.7862332: {"stream":"adarub@depth@100ms","data":{"e":"depthUpdate","E":1618677399731,"s":"ADARUB","U":1720416,"u":1720417,"b":[["106.00000000","0.00000000"],["104.55000000","8787.85000000"]],"a":[]}}
1618677399.7863948: {"stream":"veteth@depth@100ms","data":{"e":"depthUpdate","E":1618677399731,"s":"VETETH","U":327913368,"u":327913370,"b":[["0.00009381","0.00000000"],["0.00009376","116672.00000000"]],"a":[]}}
1618677399.850353: {"stream":"adarub@bookTicker","data":{"u":1720418,"s":"ADARUB","b":"105.91000000","B":"3244.17000000","a":"106.09000000","A":"7.54000000"}}
1618677399.862844: {"stream":"adarub@bookTicker","data":{"u":1720419,"s":"ADARUB","b":"105.92000000","B":"301.56000000","a":"106.09000000","A":"7.54000000"}}
1618677399.886872: {"stream":"adarub@depth@100ms","data":{"e":"depthUpdate","E":1618677399831,"s":"ADARUB","U":1720418,"u":1720419,"b":[["106.01000000","0.00000000"],["105.92000000","301.56000000"]],"a":[]}}
1618677399.8870459: {"stream":"veteth@depth@100ms","data":{"e":"depthUpdate","E":1618677399831,"s":"VETETH","U":327913371,"u":327913371,"b":[["0.00009132","983.00000000"]],"a":[]}}
1618677399.887122: {"stream":"steemeth@depth@100ms","data":{"e":"depthUpdate","E":1618677399832,"s":"STEEMETH","U":126265014,"u":126265015,"b":[["0.00050400","2864.15000000"],["0.00050200","52.14000000"]],"a":[]}}
1618677400.07433: {"stream":"aaveupusdt@bookTicker","data":{"u":82464117,"s":"AAVEUPUSDT","b":"84.19000000","B":"23.76000000","a":"84.92200000","A":"94.16000000"}}
1618677400.087564: {"stream":"veteth@depth@100ms","data":{"e":"depthUpdate","E":1618677400031,"s":"VETETH","U":327913372,"u":327913372,"b":[["0.00009356","542.00000000"]],"a":[]}}
1618677400.090755: {"stream":"aaveupusdt@depth@100ms","data":{"e":"depthUpdate","E":1618677400032,"s":"AAVEUPUSDT","U":82464117,"u":82464117,"b":[],"a":[["84.92200000","94.16000000"]]}}
1618677400.09091: {"stream":"aaveupusdt@bookTicker","data":{"u":82464118,"s":"AAVEUPUSDT","b":"84.19000000","B":"23.76000000","a":"84.92200000","A":"115.56000000"}}
1618677400.111379: {"stream":"aaveupusdt@bookTicker","data":{"u":82464119,"s":"AAVEUPUSDT","b":"84.19000000","B":"23.76000000","a":"84.92200000","A":"125.19000000"}}
1618677400.1464279: {"stream":"swrvbusd@bookTicker","data":{"u":64830389,"s":"SWRVBUSD","b":"2.27100000","B":"22.01100000","a":"2.27700000","A":"1.19200000"}}
1618677400.187001: {"stream":"swrvbusd@depth@100ms","data":{"e":"depthUpdate","E":1618677400132,"s":"SWRVBUSD","U":64830389,"u":64830389,"b":[],"a":[["2.27600000","0.00000000"]]}}
1618677400.187098: {"stream":"aaveupusdt@depth@100ms","data":{"e":"depthUpdate","E":1618677400132,"s":"AAVEUPUSDT","U":82464118,"u":82464119,"b":[],"a":[["84.92200000","125.19000000"]]}}
1618677400.212909: {"stream":"aaveupusdt@bookTicker","data":{"u":82464121,"s":"AAVEUPUSDT","b":"84.19000000","B":"23.76000000","a":"84.92200000","A":"231.12000000"}}
1618677400.288683: {"stream":"aaveupusdt@depth@100ms","data":{"e":"depthUpdate","E":1618677400232,"s":"AAVEUPUSDT","U":82464120,"u":82464122,"b":[],"a":[["84.92200000","231.12000000"],["84.92300000","0.00000000"],["84.92400000","0.00000000"]]}}
1618677400.308867: {"stream":"swrvbusd@bookTicker","data":{"u":64830390,"s":"SWRVBUSD","b":"2.27100000","B":"22.01100000","a":"2.27600000","A":"20.45400000"}}
1618677400.386867: {"stream":"swrvbusd@depth@100ms","data":{"e":"depthUpdate","E":1618677400332,"s":"SWRVBUSD","U":64830390,"u":64830390,"b":[],"a":[["2.27600000","20.45400000"]]}}
1618677400.3874428: {"stream":"aaveupusdt@depth@100ms","data":{"e":"depthUpdate","E":1618677400332,"s":"AAVEUPUSDT","U":82464123,"u":82464123,"b":[["81.60800000","0.00000000"]],"a":[]}}
1618677400.491101: {"stream":"aaveupusdt@bookTicker","data":{"u":82464124,"s":"AAVEUPUSDT","b":"84.19000000","B":"23.76000000","a":"84.92100000","A":"0.25000000"}}
1618677400.512465: {"stream":"onttry@aggTrade","data":{"e":"aggTrade","E":1618677400457,"s":"ONTTRY","a":8618,"p":"18.90000000","q":"185.50000000","f":9341,"l":9341,"T":1618677400348,"m":true,"M":true}}
1618677400.5125709: {"stream":"onttry@bookTicker","data":{"u":282143,"s":"ONTTRY","b":"18.88000000","B":"153.40000000","a":"18.99000000","A":"153.06000000"}}
1618677400.5345469: {"stream":"onttry@bookTicker","data":{"u":282144,"s":"ONTTRY","b":"18.86000000","B":"146.32000000","a":"18.99000000","A":"153.06000000"}}
1618677400.5868428: {"stream":"onttry@depth@100ms","data":{"e":"depthUpdate","E":1618677400532,"s":"ONTTRY","U":282143,"u":282148,"b":[["18.90000000","0.00000000"],["18.88000000","0.00000000"],["18.80000000","694.83000000"],["18.56000000","1648.62000000"],["18.53000000","1860.75000000"]],"a":[["20.24000000","0.00000000"]]}}
1618677400.58747: {"stream":"aaveupusdt@depth@100ms","data":{"e":"depthUpdate","E":1618677400532,"s":"AAVEUPUSDT","U":82464124,"u":82464128,"b":[["83.69200000","0.00000000"],["83.62700000","306.79000000"]],"a":[["84.92100000","0.25000000"],["85.12500000","2.57000000"],["85.25000000","0.00000000"]]}}
1618677400.68678: {"stream":"perlbnb@depth@100ms","data":{"e":"depthUpdate","E":1618677400632,"s":"PERLBNB","U":97581386,"u":97581386,"b":[["0.00038900","142116.00000000"]],"a":[]}}
1618677400.786619: {"stream":"veteth@depth@100ms","data":{"e":"depthUpdate","E":1618677400732,"s":"VETETH","U":327913373,"u":327913373,"b":[],"a":[["0.00009400","0.00000000"]]}}
1618677400.78673: {"stream":"perlbnb@depth@100ms","data":{"e":"depthUpdate","E":1618677400732,"s":"PERLBNB","U":97581387,"u":97581387,"b":[["0.00039000","4703.00000000"]],"a":[]}}
1618677400.786775: {"stream":"swrvbusd@depth@100ms","data":{"e":"depthUpdate","E":1618677400732,"s":"SWRVBUSD","U":64830391,"u":64830391,"b":[["2.26600000","98.59100000"],["2.26500000","133.36000000"]],"a":[]}}
1618677400.7987452: {"stream":"swrvbusd@bookTicker","data":{"u":64830392,"s":"SWRVBUSD","b":"2.27100000","B":"22.01100000","a":"2.27700000","A":"1.19200000"}}
1618677400.8609622: {"stream":"aaveupusdt@bookTicker","data":{"u":82464129,"s":"AAVEUPUSDT","b":"84.19000000","B":"23.76000000","a":"84.85900000","A":"354.24000000"}}
1618677400.888649: {"stream":"swrvbusd@depth@100ms","data":{"e":"depthUpdate","E":1618677400832,"s":"SWRVBUSD","U":64830392,"u":64830392,"b":[],"a":[["2.27600000","0.00000000"]]}}
1618677400.8888059: {"stream":"aaveupusdt@depth@100ms","data":{"e":"depthUpdate","E":1618677400832,"s":"AAVEUPUSDT","U":82464129,"u":82464130,"b":[],"a":[["84.85900000","354.24000000"],["84.92700000","0.00000000"]]}}
1618677400.944088: {"stream":"swrvbusd@bookTicker","data":{"u":64830395,"s":"SWRVBUSD","b":"2.27100000","B":"22.01100000","a":"2.27600000","A":"20.45400000"}}
1618677400.9684281: {"stream":"veteth@bookTicker","data":{"u":327913374,"s":"VETETH","b":"0.00009376","B":"116672.00000000","a":"0.00009402","A":"146373.00000000"}}
1618677400.986683: {"stream":"veteth@depth@100ms","data":{"e":"depthUpdate","E":1618677400932,"s":"VETETH","U":327913374,"u":327913374,"b":[],"a":[["0.00009399","0.00000000"]]}}
1618677400.986838: {"stream":"swrvbusd@depth@100ms","data":{"e":"depthUpdate","E":1618677400932,"s":"SWRVBUSD","U":64830393,"u":64830396,"b":[["2.26600000","131.57900000"],["2.26500000","171.22500000"]],"a":[["2.27600000","20.45400000"]]}}
1618677400.988725: {"stream":"aaveupusdt@depth@100ms","data":{"e":"depthUpdate","E":1618677400932,"s":"AAVEUPUSDT","U":82464131,"u":82464131,"b":[],"a":[["84.92100000","0.00000000"]]}}
1618677401.06255: {"stream":"veteth@bookTicker","data":{"u":327913375,"s":"VETETH","b":"0.00009376","B":"116672.00000000","a":"0.00009401","A":"83459.00000000"}}
1618677401.087183: {"stream":"veteth@depth@100ms","data":{"e":"depthUpdate","E":1618677401032,"s":"VETETH","U":327913375,"u":327913375,"b":[],"a":[["0.00009401","83459.00000000"]]}}
1618677401.191013: {"stream":"veteth@bookTicker","data":{"u":327913377,"s":"VETETH","b":"0.00009376","B":"116672.00000000","a":"0.00009400","A":"20116.00000000"}}
1618677401.201314: {"stream":"veteth@depth@100ms","data":{"e":"depthUpdate","E":1618677401132,"s":"VETETH","U":327913376,"u":327913377,"b":[["0.00009343","2275.00000000"]],"a":[["0.00009400","20116.00000000"]]}}
1618677401.2114758: {"stream":"veteth@bookTicker","data":{"u":327913378,"s":"VETETH","b":"0.00009377","B":"200.00000000","a":"0.00009400","A":"20116.00000000"}}
1618677401.28617: {"stream":"veteth@depth@100ms","data":{"e":"depthUpdate","E":1618677401232,"s":"VETETH","U":327913378,"u":327913379,"b":[["0.00009377","200.00000000"]],"a":[["0.00009401","0.00000000"]]}}
1618677401.35116: {"stream":"veteth@bookTicker","data":{"u":327913380,"s":"VETETH","b":"0.00009377","B":"200.00000000","a":"0.00009399","A":"83459.00000000"}}
1618677401.3834748: {"stream":"swrvbusd@bookTicker","data":{"u":64830397,"s":"SWRVBUSD","b":"2.27100000","B":"22.01100000","a":"2.27700000","A":"1.19200000"}}
1618677401.386569: {"stream":"veteth@depth@100ms","data":{"e":"depthUpdate","E":1618677401332,"s":"VETETH","U":327913380,"u":327913380,"b":[],"a":[["0.00009399","83459.00000000"]]}}
1618677401.386647: {"stream":"swrvbusd@depth@100ms","data":{"e":"depthUpdate","E":1618677401332,"s":"SWRVBUSD","U":64830397,"u":64830397,"b":[],"a":[["2.27600000","0.00000000"]]}}
1618677401.4873211: {"stream":"onttry@depth@100ms","data":{"e":"depthUpdate","E":1618677401432,"s":"ONTTRY","U":282149,"u":282149,"b":[["18.39000000","0.00000000"]],"a":[]}}
1618677401.871777: {"stream":"busdtry@depth@100ms","data":{"e":"depthUpdate","E":1618677401432,"s":"BUSDTRY","U":10166148,"u":10166148,"b":[["8.10000000","83321.19000000"]],"a":[]}}
1618677401.871913: {"stream":"swrvbusd@bookTicker","data":{"u":64830398,"s":"SWRVBUSD","b":"2.27100000","B":"22.01100000","a":"2.27600000","A":"20.45400000"}}
1618677401.871957: {"stream":"swrvbusd@depth@100ms","data":{"e":"depthUpdate","E":1618677401532,"s":"SWRVBUSD","U":64830398,"u":64830398,"b":[],"a":[["2.27600000","20.45400000"]]}}
1618677401.8720472: {"stream":"onttry@depth@100ms","data":{"e":"depthUpdate","E":1618677401632,"s":"ONTTRY","U":282150,"u":282150,"b":[["18.57000000","81.64000000"]],"a":[]}}
1618677401.872086: {"stream":"steemeth@depth@100ms","data":{"e":"depthUpdate","E":1618677401632,"s":"STEEMETH","U":126265016,"u":126265017,"b":[],"a":[["0.00051000","5463.57000000"],["0.00051100","13275.53000000"]]}}
1618677401.872121: {"stream":"veteth@depth@100ms","data":{"e":"depthUpdate","E":1618677401732,"s":"VETETH","U":327913381,"u":327913381,"b":[["0.00009376","96556.00000000"]],"a":[]}}
1618677401.872152: {"stream":"aaveupusdt@bookTicker","data":{"u":82464132,"s":"AAVEUPUSDT","b":"84.19000000","B":"23.76000000","a":"84.85800000","A":"0.17000000"}}
1618677401.872171: {"stream":"aaveupusdt@bookTicker","data":{"u":82464134,"s":"AAVEUPUSDT","b":"84.19000000","B":"23.76000000","a":"84.85700000","A":"0.25000000"}}
1618677401.889096: {"stream":"aaveupusdt@depth@100ms","data":{"e":"depthUpdate","E":1618677401832,"s":"AAVEUPUSDT","U":82464132,"u":82464134,"b":[["81.82600000","0.00000000"]],"a":[["84.85700000","0.25000000"],["84.85800000","0.17000000"]]}}
1618677401.9723048: {"stream":"swrvbusd@bookTicker","data":{"u":64830399,"s":"SWRVBUSD","b":"2.27100000","B":"22.01100000","a":"2.27700000","A":"1.19200000"}}
1618677402.0022972: {"stream":"swrvbusd@depth@100ms","data":{"e":"depthUpdate","E":1618677401932,"s":"SWRVBUSD","U":64830399,"u":64830399,"b":[],"a":[["2.27600000","0.00000000"]]}}
1618677402.002453: {"stream":"aaveupusdt@depth@100ms","data":{"e":"depthUpdate","E":1618677401932,"s":"AAVEUPUSDT","U":82464135,"u":82464136,"b":[["83.79600000","0.00000000"],["83.66500000","2.57000000"]],"a":[]}}
1618677402.053489: {"stream":"swrvbusd@bookTicker","data":{"u":64830400,"s":"SWRVBUSD","b":"2.27100000","B":"22.01100000","a":"2.27600000","A":"20.45400000"}}
1618677402.0535738: {"stream":"onttry@kline_1m","data":{"e":"kline","E":1618677401959,"s":"ONTTRY","k":{"t":1618677360000,"T":1618677419999,"s":"ONTTRY","i":"1m","f":9332,"L":9341,"o":"19.00000000","c":"18.90000000","h":"19.00000000","l":"18.90000000","v":"899.15000000","n":10,"x":false,"q":"17044.46050000","V":"62.21000000","Q":"1181.41790000","B":"0"}}}
1618677402.089032: {"stream":"swrvbusd@depth@100ms","data":{"e":"depthUpdate","E":1618677402032,"s":"SWRVBUSD","U":64830400,"u":64830403,"b":[["2.26600000","131.57900000"],["2.26500000","171.22500000"]],"a":[["2.27600000","20.45400000"]]}}
1618677402.089205: {"stream":"aaveupusdt@depth@100ms","data":{"e":"depthUpdate","E":1618677402032,"s":"AAVEUPUSDT","U":82464137,"u":82464137,"b":[["81.24400000","0.13000000"]],"a":[]}}
1618677402.1881092: {"stream":"aaveupusdt@depth@100ms","data":{"e":"depthUpdate","E":1618677402133,"s":"AAVEUPUSDT","U":82464138,"u":82464141,"b":[["81.46100000","2.48000000"]],"a":[["84.92200000","105.93000000"]]}}
1618677402.28811: {"stream":"aaveupusdt@depth@100ms","data":{"e":"depthUpdate","E":1618677402232,"s":"AAVEUPUSDT","U":82464142,"u":82464143,"b":[],"a":[["84.85800000","0.00000000"],["84.92200000","0.00000000"]]}}
1618677402.401246: {"stream":"aaveupusdt@bookTicker","data":{"u":82464144,"s":"AAVEUPUSDT","b":"84.19000000","B":"23.76000000","a":"84.85900000","A":"354.24000000"}}


