1618677490.331713: {"stream":"btcusd_perp@depth@100ms","data":{"e":"depthUpdate","E":1618677490277,"T":1618677490204,"s":"BTCUSD_PERP","ps":"BTCUSD","U":86143441502,"u":86143443371,"pu":86143441500,"b":[["57566.3","120"],["60497.9","0"],["60511.3","500"],["60517.5","3000"],["60539.1","0"],["60557.6","363"],["60574.7","0"],["60574.8","485"],["60574.9","8"],["60575.4","969"],["60577.2","80"],["60578.8","123"],["60578.9","243"],["60579.1","0"],["60579.4","0"],["60579.6","0"],["60580.3","0"],["60580.5","0"],["60585.3","0"],["60585.6","0"],["60586.2","17"],["60587.5","0"],["60587.9","0"],["60589.0","0"],["60589.1","25"],["60589.5","490"],["60591.1","50"],["60591.7","243"],["60592.2","0"],["60593.1","15"],["60593.2","360"],["60593.6","1363"],["60593.8","3147"],["60594.3","0"],["60594.4","0"],["60594.5","1"],["60595.2","0"],["60595.6","30"],["60596.2","15830"],["60596.3","0"],["60596.4","0"],["60596.5","0"],["60596.7","0"],["60596.8","0"],["60596.9","0"],["60597.0","0"],["60597.1","0"],["60597.3","0"],["60597.5","0"],["60597.7","0"],["60597.9","0"],["60598.1","0"],["60598.2","0"],["60598.3","0"],["60598.4","0"],["60598.5","0"],["60598.7","0"],["60598.8","0"],["60598.9","0"],["60599.0","0"],["60599.1","0"],["60599.3","0"],["60599.5","0"],["60599.7","0"],["60599.9","0"],["60600.1","0"],["60600.2","0"],["60600.3","0"],["60600.4","0"],["60600.5","0"],["60600.6","0"],["60600.7","0"],["60600.8","0"],["60600.9","0"],["60601.0","0"],["60601.1","0"],["60601.3","0"],["60601.4","0"],["60601.5","0"],["60601.6","0"],["60601.7","0"],["60601.9","0"],["60602.1","0"],["60602.2","0"],["60602.3","0"],["60602.4","0"],["60602.5","0"],["60602.6","0"],["60602.7","0"],["60602.8","0"],["60602.9","0"],["60603.0","0"],["60603.1","0"],["60603.3","0"],["60603.5","0"],["60603.7","0"],["60603.9","0"],["60604.1","0"],["60604.2","0"],["60604.4","0"],["60604.6","0"],["60604.8","0"],["60605.0","0"],["60605.1","0"],["60605.3","0"]],"a":[["60596.3","1022"],["60597.8","483"],["60600.0","50"],["60600.3","0"],["60601.0","30"],["60602.5","0"],["60603.1","151"],["60603.7","40"],["60604.4","402"],["60605.0","25"],["60608.2","50"],["60610.9","0"],["60613.1","0"],["60620.0","50"],["60620.2","16"],["60620.3","122"],["60622.9","1511"],["60628.5","438"],["60632.8","243"],["60636.9","1095"],["60645.6","243"],["60647.8","243"],["60662.5","519"],["60675.1","3008"],["60715.8","0"],["60758.0","1101"],["60800.0","1250"],["60800.6","1815"]]}}
1618677490.33518: {"stream":"linkusd_210625@depth@100ms","data":{"e":"depthUpdate","E":1618677490284,"T":1618677490266,"s":"LINKUSD_210625","ps":"LINKUSD","U":86143443030,"u":86143444250,"pu":86143442385,"b":[["43.562","300"]],"a":[["43.790","0"],["43.797","93"],["43.814","24"]]}}
1618677490.340061: {"stream":"xrpusd_210625@depth@100ms","data":{"e":"depthUpdate","E":1618677490287,"T":1618677490246,"s":"XRPUSD_210625","ps":"XRPUSD","U":86143443057,"u":86143443903,"pu":86143442664,"b":[["1.6906","0"],["1.6907","0"],["1.6908","0"],["1.6910","128"]],"a":[["1.7036","80"]]}}
1618677490.362547: {"stream":"dotusd_210625@depth@100ms","data":{"e":"depthUpdate","E":1618677490309,"T":1618677490300,"s":"DOTUSD_210625","ps":"DOTUSD","U":86143443418,"u":86143444671,"pu":86143443041,"b":[["46.501","0"],["46.555","1331"],["46.733","0"],["46.734","50"],["46.738","124"]],"a":[["46.767","0"],["46.788","84"],["46.789","0"],["46.790","0"]]}}
1618677490.378792: {"stream":"egldusd_perp@depth@100ms","data":{"e":"depthUpdate","E":1618677490326,"T":1618677490317,"s":"EGLDUSD_PERP","ps":"EGLDUSD","U":86143443603,"u":86143444856,"pu":86143442814,"b":[["215.859","0"],["215.948","0"],["215.962","22"],["216.068","170"]],"a":[["216.070","41"],["216.071","0"],["216.145","0"],["216.171","0"],["216.173","97"],["216.342","482"],["216.343","81"],["216.345","0"]]}}
1618677490.3811882: {"stream":"linkusd_210924@depth@100ms","data":{"e":"depthUpdate","E":1618677490329,"T":1618677490273,"s":"LINKUSD_210924","ps":"LINKUSD","U":86143443642,"u":86143444362,"pu":86143441489,"b":[],"a":[["45.397","0"],["45.405","0"],["45.406","0"],["45.418","867"]]}}
1618677490.38753: {"stream":"ethusd_210625@depth@100ms","data":{"e":"depthUpdate","E":1618677490332,"T":1618677490263,"s":"ETHUSD_210625","ps":"ETHUSD","U":86143442429,"u":86143444203,"pu":86143442350,"b":[["2503.18","0"],["2503.93","4602"],["2510.13","0"],["2510.62","299"],["2510.71","0"],["2510.86","2325"]],"a":[["2510.87","2262"],["2510.94","0"],["2511.04","121"],["2511.15","532"],["2511.23","0"],["2524.56","3024"]]}}
1618677490.388176: {"stream":"bchusd_210625@depth@100ms","data":{"e":"depthUpdate","E":1618677490336,"T":1618677490300,"s":"BCHUSD_210625","ps":"BCHUSD","U":86143443732,"u":86143444670,"pu":86143443608,"b":[["1121.21","0"],["1121.67","431"],["1123.18","0"],["1123.31","1111"],["1124.34","0"],["1128.23","0"],["1128.24","0"],["1128.29","15"],["1128.30","0"],["1128.31","0"],["1128.32","0"],["1128.33","64"],["1128.34","44"]],"a":[]}}
1618677490.394869: {"stream":"ethusd_210924@depth@100ms","data":{"e":"depthUpdate","E":1618677490343,"T":1618677490321,"s":"ETHUSD_210924","ps":"ETHUSD","U":86143443840,"u":86143444885,"pu":86143443131,"b":[["2646.93","10576"],["2687.96","0"],["2688.71","500"]],"a":[["2689.80","48"],["2690.07","0"]]}}
1618677490.403635: {"stream":"btcusd_210924@depth@100ms","data":{"e":"depthUpdate","E":1618677490351,"T":1618677490343,"s":"BTCUSD_210924","ps":"BTCUSD","U":86143443917,"u":86143445147,"pu":86143443060,"b":[["68555.7","0"],["68572.1","20"],["68574.6","0"],["68590.9","20"],["68632.2","0"],["68645.0","0"],["68646.0","0"],["68647.0","0"],["68647.1","0"],["68650.0","10"],["68651.0","10"],["68652.0","635"]],"a":[["68652.1","60"],["68658.5","0"],["68671.9","26"],["68675.0","20"],["68677.5","0"],["68693.8","20"],["68703.0","834"],["68703.3","0"]]}}
1618677490.437004: {"stream":"linkusd_210625@depth@100ms","data":{"e":"depthUpdate","E":1618677490384,"T":1618677490373,"s":"LINKUSD_210625","ps":"LINKUSD","U":86143444439,"u":86143445441,"pu":86143444250,"b":[["43.724","0"],["43.740","92"],["43.745","0"],["43.756","150"],["43.765","142"],["43.766","22"],["43.768","45"]],"a":[["43.777","0"],["43.785","0"],["43.787","32"],["43.789","0"],["43.793","13"],["43.815","539"],["43.902","0"]]}}
1618677490.4467251: {"stream":"btcusd_perp@depth@100ms","data":{"e":"depthUpdate","E":1618677490391,"T":1618677490366,"s":"BTCUSD_PERP","ps":"BTCUSD","U":86143443372,"u":86143445392,"pu":86143443371,"b":[["57566.3","0"],["60230.1","0"],["60500.5","10"],["60539.5","1405"],["60550.2","0"],["60559.3","20"],["60560.1","0"],["60561.1","0"],["60561.2","371"],["60564.7","0"],["60569.3","20"],["60570.4","8"],["60571.0","734"],["60574.6","120"],["60575.3","397"],["60575.5","993"],["60578.8","1"],["60578.9","5"],["60579.0","0"],["60579.8","122"],["60580.0","1"],["60580.1","0"],["60580.3","0"],["60583.5","0"],["60586.2","0"],["60589.3","10"],["60589.5","40"],["60589.6","7"],["60590.0","121"],["60590.1","401"],["60590.7","0"],["60591.0","0"],["60591.7","0"],["60592.9","0"],["60593.2","0"],["60593.3","0"],["60593.6","1120"],["60593.8","1602"],["60593.9","30"],["60594.6","243"],["60595.1","0"],["60595.3","100"],["60595.8","500"],["60596.2","17993"],["60596.3","0"],["60596.4","0"],["60596.5","0"],["60596.7","0"],["60596.8","0"],["60596.9","0"],["60597.0","0"],["60597.1","0"],["60597.3","0"],["60597.5","0"],["60597.7","0"],["60597.9","0"],["60598.1","0"],["60598.2","0"],["60598.3","0"],["60598.4","0"],["60598.5","0"],["60598.7","0"],["60598.8","0"],["60598.9","0"],["60599.0","0"],["60599.1","0"],["60599.3","0"],["60599.5","0"],["60599.7","0"],["60599.9","0"],["60600.1","0"],["60600.2","0"],["60600.3","0"],["60600.4","0"],["60600.5","0"],["60600.6","0"],["60600.7","0"],["60600.8","0"],["60600.9","0"],["60601.0","0"],["60601.1","0"],["60601.3","0"],["60601.4","0"],["60601.5","0"],["60601.6","0"],["60601.7","0"],["60601.9","0"],["60602.1","0"],["60602.2","0"],["60602.3","0"],["60602.4","0"],["60602.5","0"],["60602.6","0"],["60602.7","0"],["60602.8","0"],["60602.9","0"],["60603.0","0"],["60603.1","0"],["60603.3","0"],["60603.5","0"],["60603.7","0"],["60603.9","0"],["60604.1","0"],["60604.2","0"],["60604.4","0"],["60604.6","0"],["60604.8","0"],["60605.0","0"],["60605.1","0"],["60605.3","0"]],"a":[["60596.3","622"],["60597.5","257"],["60600.5","0"],["60601.0","0"],["60601.2","5"],["60601.5","37"],["60602.4","0"],["60602.7","0"],["60603.1","1"],["60603.9","398"],["60604.3","0"],["60605.7","0"],["60607.0","196"],["60609.1","105"],["60610.0","10"],["60610.2","0"],["60610.7","0"],["60613.2","0"],["60616.1","0"],["60616.7","0"],["60618.9","0"],["60619.8","20"],["60619.9","596"],["60620.3","0"],["60620.5","0"],["60620.6","0"],["60620.7","122"],["60620.8","0"],["60626.2","40"],["60629.8","654"],["60632.8","0"],["60633.2","243"],["60639.9","10"],["60645.6","0"],["60646.0","1651"],["60647.8","0"],["60648.5","243"],["60656.5","509"],["60657.5","0"],["60671.9","606"],["60678.4","1000"],["60693.8","0"],["60699.7","1136"],["60706.0","0"],["60717.3","1100"],["60758.0","1"],["60814.7","1805"]]}}
1618677490.4636512: {"stream":"dotusd_210625@depth@100ms","data":{"e":"depthUpdate","E":1618677490412,"T":1618677490408,"s":"DOTUSD_210625","ps":"DOTUSD","U":86143444762,"u":86143446153,"pu":86143444671,"b":[["46.200","0"],["46.716","250"]],"a":[["46.760","0"],["46.788","0"],["46.790","63"]]}}
1618677490.486958: {"stream":"egldusd_perp@depth@100ms","data":{"e":"depthUpdate","E":1618677490433,"T":1618677490408,"s":"EGLDUSD_PERP","ps":"EGLDUSD","U":86143444956,"u":86143446161,"pu":86143444856,"b":[["215.859","394"],["215.860","0"],["216.068","224"]],"a":[["216.265","40"],["216.341","101"],["216.343","0"],["216.344","0"],["216.346","0"],["216.397","592"]]}}
1618677490.499367: {"stream":"ethusd_210924@depth@100ms","data":{"e":"depthUpdate","E":1618677490446,"T":1618677490389,"s":"ETHUSD_210924","ps":"ETHUSD","U":86143445123,"u":86143445644,"pu":86143444885,"b":[["2685.19","150"],["2686.73","0"],["2687.40","3269"]],"a":[["2689.80","168"],["2690.58","150"]]}}
1618677490.504708: {"stream":"ethusd_210625@depth@100ms","data":{"e":"depthUpdate","E":1618677490452,"T":1618677490426,"s":"ETHUSD_210625","ps":"ETHUSD","U":86143444520,"u":86143446334,"pu":86143444203,"b":[["2499.61","433"],["2505.26","0"],["2505.60","0"],["2509.86","262"],["2510.13","0"],["2510.62","0"],["2510.63","299"],["2510.88","0"]],"a":[["2510.85","0"],["2510.87","2137"],["2512.18","0"]]}}
1618677490.5127301: {"stream":"bchusd_210625@depth@100ms","data":{"e":"depthUpdate","E":1618677490461,"T":1618677490451,"s":"BCHUSD_210625","ps":"BCHUSD","U":86143445301,"u":86143446626,"pu":86143444670,"b":[["1121.67","774"],["1122.19","0"],["1124.82","0"],["1125.06","612"],["1127.68","0"],["1128.13","619"],["1128.29","15"],["1128.30","0"],["1128.35","35"]],"a":[["1129.45","0"],["1129.47","0"],["1129.74","746"],["1129.80","0"],["1130.45","0"],["1132.10","95"]]}}
1618677490.5194938: {"stream":"linkusd_210924@depth@100ms","data":{"e":"depthUpdate","E":1618677490466,"T":1618677490443,"s":"LINKUSD_210924","ps":"LINKUSD","U":86143445339,"u":86143446551,"pu":86143444362,"b":[],"a":[["45.322","0"],["45.332","0"],["45.333","0"],["45.417","183"],["45.426","0"],["45.435","1751"],["45.554","0"],["45.623","0"]]}}
1618677490.519736: {"stream":"btcusd_210924@depth@100ms","data":{"e":"depthUpdate","E":1618677490466,"T":1618677490449,"s":"BTCUSD_210924","ps":"BTCUSD","U":86143445336,"u":86143446613,"pu":86143445147,"b":[],"a":[["68652.1","125"],["68663.9","20"],["68664.0","0"],["68664.1","0"],["68672.0","0"],["68673.1","60"],["68677.0","0"],["68695.6","0"]]}}
1618677490.539291: {"stream":"linkusd_210625@depth@100ms","data":{"e":"depthUpdate","E":1618677490487,"T":1618677490395,"s":"LINKUSD_210625","ps":"LINKUSD","U":86143445566,"u":86143445930,"pu":86143445441,"b":[["43.623","174"]],"a":[["43.796","50"],["43.897","0"],["44.002","0"]]}}
1618677490.545075: {"stream":"btcusd_perp@depth@100ms","data":{"e":"depthUpdate","E":1618677490492,"T":1618677490488,"s":"BTCUSD_PERP","ps":"BTCUSD","U":86143445401,"u":86143447050,"pu":86143445392,"b":[["60505.5","1578"],["60506.0","167"],["60506.5","77"],["60507.0","77"],["60523.7","0"],["60545.1","1050"],["60552.8","0"],["60560.2","0"],["60567.6","0"],["60572.2","100"],["60577.3","1492"],["60578.0","100"],["60579.8","0"],["60580.8","79"],["60582.6","0"],["60583.1","0"],["60585.2","200"],["60585.4","0"],["60585.5","122"],["60585.7","243"],["60585.9","0"],["60588.9","50"],["60589.4","15"],["60590.8","30"],["60591.1","75"],["60592.9","0"],["60593.0","0"],["60593.9","0"],["60594.6","0"],["60594.9","0"],["60595.9","0"],["60596.2","18477"],["60596.3","0"],["60596.4","0"],["60596.5","0"],["60596.6","0"],["60596.7","0"],["60596.8","0"],["60596.9","0"],["60597.0","0"],["60597.1","0"],["60597.2","0"],["60597.3","0"],["60597.4","0"],["60597.5","0"],["60597.6","0"],["60597.7","0"],["60597.8","0"],["60597.9","0"],["60598.0","0"],["60598.1","0"],["60598.2","0"],["60598.3","0"],["60598.4","0"],["60598.5","0"],["60598.6","0"],["60598.7","0"],["60598.8","0"],["60598.9","0"],["60599.0","0"],["60599.1","0"],["60599.2","0"],["60599.3","0"],["60599.4","0"],["60599.5","0"],["60599.6","0"],["60599.7","0"],["60599.8","0"],["60599.9","0"],["60600.0","0"],["60600.1","0"],["60600.2","0"],["60600.3","0"],["60600.4","0"],["60600.5","0"],["60600.6","0"],["60600.7","0"],["60600.8","0"],["60600.9","0"],["60601.0","0"],["60601.1","0"],["60601.2","0"],["60601.3","0"],["60601.5","0"],["60601.7","0"],["60601.9","0"],["60602.1","0"],["60602.3","0"],["60602.5","0"],["60602.7","0"],["60602.9","0"],["60603.1","0"],["60603.3","0"],["60603.5","0"],["60603.7","0"],["60603.9","0"],["60604.1","0"],["60604.3","0"],["60604.5","0"],["60604.7","0"],["60604.9","0"],["60605.1","0"],["60605.3","0"],["60605.5","0"],["60605.7","0"],["60605.9","0"],["60606.1","0"]],"a":[["60596.8","0"],["60597.6","0"],["60598.1","0"],["60598.2","0"],["60598.4","0"],["60599.1","0"],["60599.4","0"],["60601.5","7"],["60601.9","30"],["60602.5","0"],["60603.3","215"],["60603.7","0"],["60604.4","402"],["60604.7","197"],["60604.8","0"],["60604.9","200"],["60605.6","218"],["60605.8","218"],["60606.0","0"],["60606.5","0"],["60608.8","40"],["60611.3","291"],["60613.8","1502"],["60616.6","0"],["60619.0","0"],["60620.0","170"],["60620.2","36"],["60620.7","0"],["60621.1","0"],["60622.2","0"],["60625.2","0"],["60625.9","0"],["60630.0","257"],["60633.2","0"],["60633.8","0"],["60635.0","0"],["60642.8","243"],["60644.9","243"],["60646.0","1408"],["60646.7","0"],["60647.8","0"],["60648.5","0"],["60650.0","335"],["60715.7","0"],["60717.3","0"],["60741.8","100"]]}}
1618677490.5536451: {"stream":"xrpusd_210625@depth@100ms","data":{"e":"depthUpdate","E":1618677490499,"T":1618677490485,"s":"XRPUSD_210625","ps":"XRPUSD","U":86143445928,"u":86143447038,"pu":86143443903,"b":[["1.6911","45"]],"a":[["1.6924","0"],["1.6928","45"],["1.6932","153"]]}}
1618677490.575074: {"stream":"dotusd_210625@depth@100ms","data":{"e":"depthUpdate","E":1618677490522,"T":1618677490479,"s":"DOTUSD_210625","ps":"DOTUSD","U":86143446272,"u":86143446954,"pu":86143446153,"b":[["46.201","40"],["46.715","0"],["46.717","63"]],"a":[["46.755","200"]]}}
1618677490.6010082: {"stream":"egldusd_perp@depth@100ms","data":{"e":"depthUpdate","E":1618677490547,"T":1618677490468,"s":"EGLDUSD_PERP","ps":"EGLDUSD","U":86143446553,"u":86143446819,"pu":86143446161,"b":[],"a":[["216.163","16"],["216.265","0"],["216.310","20"]]}}
1618677490.614048: {"stream":"ethusd_210625@depth@100ms","data":{"e":"depthUpdate","E":1618677490560,"T":1618677490542,"s":"ETHUSD_210625","ps":"ETHUSD","U":86143446501,"u":86143447706,"pu":86143446334,"b":[["2498.63","0"],["2499.60","2000"],["2501.35","2099"],["2505.25","1000"],["2505.75","500"],["2508.33","0"],["2508.38","23069"],["2508.78","1618"],["2509.24","60"],["2509.59","0"],["2510.88","0"]],"a":[["2511.04","0"],["2511.05","1373"],["2511.15","62"],["2511.23","218"],["2511.29","1074"],["2511.44","121"],["2511.61","751"],["2511.91","0"],["2529.15","0"]]}}
1618677490.6143832: {"stream":"bchusd_210625@depth@100ms","data":{"e":"depthUpdate","E":1618677490562,"T":1618677490540,"s":"BCHUSD_210625","ps":"BCHUSD","U":86143446681,"u":86143447683,"pu":86143446626,"b":[["1115.19","0"],["1115.90","1000"],["1116.65","0"],["1117.35","300"],["1123.25","0"],["1123.96","1000"],["1125.06","471"],["1125.53","141"],["1127.56","96"],["1128.14","129"],["1128.28","0"],["1128.29","0"],["1128.34","13"],["1128.35","0"],["1128.36","0"],["1128.37","64"],["1128.38","7"]],"a":[]}}
1618677490.631894: {"stream":"btcusd_210924@depth@100ms","data":{"e":"depthUpdate","E":1618677490579,"T":1618677490575,"s":"BTCUSD_210924","ps":"BTCUSD","U":86143446915,"u":86143448031,"pu":86143446613,"b":[["68569.6","150"],["68581.4","0"],["68581.5","0"],["68591.0","1625"],["68591.1","392"],["68620.5","217"],["68623.4","276"],["68650.1","0"],["68652.0","635"]],"a":[["68663.9","0"],["68665.0","20"],["68673.2","304"],["68674.3","0"],["68723.4","0"],["68723.5","30"],["68823.7","150"]]}}
1618677490.638239: {"stream":"linkusd_210924@depth@100ms","data":{"e":"depthUpdate","E":1618677490584,"T":1618677490566,"s":"LINKUSD_210924","ps":"LINKUSD","U":86143446965,"u":86143447918,"pu":86143446551,"b":[],"a":[["45.322","8"],["45.364","118"],["45.365","555"],["45.380","250"]]}}
1618677490.644685: {"stream":"btcusd_perp@depth@100ms","data":{"e":"depthUpdate","E":1618677490592,"T":1618677490587,"s":"BTCUSD_PERP","ps":"BTCUSD","U":86143447058,"u":86143448188,"pu":86143447050,"b":[["60443.9","0"],["60445.3","8"],["60480.8","0"],["60500.7","0"],["60505.5","1501"],["60506.0","0"],["60506.5","0"],["60507.5","77"],["60508.0","79"],["60535.5","200"],["60539.0","0"],["60550.9","3690"],["60553.0","0"],["60564.6","0"],["60571.0","0"],["60573.2","560"],["60581.1","826"],["60583.0","0"],["60585.5","0"],["60585.7","243"],["60585.8","122"],["60589.6","0"],["60590.0","1"],["60590.2","32"],["60590.8","0"],["60592.3","30"],["60593.0","30"],["60595.6","0"],["60596.2","18382"],["60596.3","0"],["60596.4","0"],["60596.5","0"],["60596.7","0"],["60596.8","0"],["60596.9","0"],["60597.0","0"],["60597.1","0"],["60597.3","0"],["60597.5","0"],["60597.7","0"],["60597.9","0"],["60598.1","0"],["60598.2","0"],["60598.3","0"],["60598.4","0"],["60598.5","0"],["60598.7","0"],["60598.8","0"],["60598.9","0"],["60599.0","0"],["60599.1","0"],["60599.3","0"],["60599.5","0"],["60599.7","0"],["60599.9","0"],["60600.1","0"],["60600.2","0"],["60600.3","0"],["60600.4","0"],["60600.5","0"],["60600.6","0"],["60600.7","0"],["60600.8","0"],["60600.9","0"],["60601.0","0"],["60601.1","0"],["60601.3","0"],["60601.4","0"],["60601.5","0"],["60601.6","0"],["60601.7","0"],["60601.9","0"],["60602.1","0"],["60602.2","0"],["60602.3","0"],["60602.4","0"],["60602.5","0"],["60602.6","0"],["60602.7","0"],["60602.8","0"],["60602.9","0"],["60603.0","0"],["60603.1","0"],["60603.3","0"],["60603.5","0"],["60603.7","0"],["60603.9","0"],["60604.1","0"],["60604.2","0"],["60604.4","0"],["60604.6","0"],["60604.8","0"],["60605.0","0"],["60605.1","0"],["60605.3","0"]],"a":[["60596.3","3365"],["60599.7","30"],["60601.9","0"],["60603.7","40"],["60605.0","0"],["60605.8","218"],["60608.5","25"],["60608.8","0"],["60617.2","0"],["60620.4","122"],["60620.8","0"],["60622.3","0"],["60624.3","26"],["60626.5","0"],["60628.4","1034"],["60630.0","14"],["60633.1","243"],["60633.5","2"],["60635.1","0"],["60642.8","0"],["60644.9","0"],["60645.9","243"],["60646.3","0"],["60647.9","0"],["60648.1","243"],["60648.5","0"],["60650.1","2501"],["60652.0","0"],["60654.4","11"],["60665.6","1000"],["60667.6","0"],["60678.4","0"],["60697.7","0"],["60710.9","1100"],["60712.1","0"],["60717.8","0"],["60788.4","0"],["60792.3","1846"],["60801.7","1200"]]}}
1618677490.6643462: {"stream":"ethusd_210924@depth@100ms","data":{"e":"depthUpdate","E":1618677490608,"T":1618677490599,"s":"ETHUSD_210924","ps":"ETHUSD","U":86143447246,"u":86143448279,"pu":86143445644,"b":[["2667.70","250"],["2680.35","0"],["2680.52","0"],["2680.83","250"],["2681.24","1000"],["2687.98","250"]],"a":[["2689.80","48"],["2702.77","0"],["2703.50","250"]]}}
1618677490.664481: {"stream":"linkusd_210625@depth@100ms","data":{"e":"depthUpdate","E":1618677490613,"T":1618677490509,"s":"LINKUSD_210625","ps":"LINKUSD","U":86143447273,"u":86143447273,"pu":86143445930,"b":[],"a":[["44.029","196"]]}}
1618677490.682455: {"stream":"xrpusd_210625@depth@100ms","data":{"e":"depthUpdate","E":1618677490629,"T":1618677490525,"s":"XRPUSD_210625","ps":"XRPUSD","U":86143447504,"u":86143447504,"pu":86143447038,"b":[],"a":[["1.6959","321"]]}}
1618677490.715841: {"stream":"ethusd_210625@depth@100ms","data":{"e":"depthUpdate","E":1618677490662,"T":1618677490648,"s":"ETHUSD_210625","ps":"ETHUSD","U":86143447826,"u":86143448605,"pu":86143447706,"b":[["2510.51","0"],["2510.63","0"],["2510.71","299"],["2510.88","0"]],"a":[["2511.04","121"],["2511.05","1354"],["2511.22","0"],["2511.24","0"],["2511.26","1073"],["2511.29","0"],["2511.33","1071"],["2511.44","0"],["2512.00","0"],["2512.03","16746"],["2512.07","0"],["2523.06","0"]]}}
1618677490.718251: {"stream":"bchusd_210625@depth@100ms","data":{"e":"depthUpdate","E":1618677490665,"T":1618677490653,"s":"BCHUSD_210625","ps":"BCHUSD","U":86143447870,"u":86143448648,"pu":86143447683,"b":[["1120.85","190"],["1125.10","250"],["1125.34","250"],["1125.74","250"],["1125.81","250"],["1126.44","370"],["1127.68","0"],["1128.33","0"],["1128.34","0"],["1128.35","0"],["1128.38","28"],["1128.39","35"],["1128.41","64"]],"a":[["1132.49","0"]]}}
1618677490.722513: {"stream":"dotusd_210625@depth@100ms","data":{"e":"depthUpdate","E":1618677490669,"T":1618677490591,"s":"DOTUSD_210625","ps":"DOTUSD","U":86143447913,"u":86143448209,"pu":86143446954,"b":[],"a":[["46.841","250"],["46.916","2383"]]}}
1618677490.744328: {"stream":"egldusd_perp@depth@100ms","data":{"e":"depthUpdate","E":1618677490690,"T":1618677490657,"s":"EGLDUSD_PERP","ps":"EGLDUSD","U":86143448170,"u":86143448676,"pu":86143446819,"b":[["210.794","1388"],["212.750","1138"],["213.728","1138"],["214.706","1138"],["214.902","310"]],"a":[["216.070","211"],["216.309","482"],["216.341","0"],["216.342","0"],["216.485","310"],["216.684","1138"],["216.819","843"],["217.750","1138"],["218.815","1138"],["220.945","1138"]]}}
1618677490.7446442: {"stream":"btcusd_perp@depth@100ms","data":{"e":"depthUpdate","E":1618677490693,"T":1618677490688,"s":"BTCUSD_PERP","ps":"BTCUSD","U":86143448196,"u":86143448903,"pu":86143448188,"b":[["60453.0","2"],["60489.4","0"],["60499.9","0"],["60508.5","77"],["60509.0","79"],["60517.5","3719"],["60541.7","0"],["60542.1","1225"],["60553.1","532"],["60560.3","363"],["60561.6","0"],["60578.8","0"],["60580.7","548"],["60580.8","0"],["60580.9","0"],["60581.2","79"],["60581.6","0"],["60581.8","0"],["60585.2","200"],["60585.3","0"],["60585.7","0"],["60585.8","0"],["60586.6","25"],["60586.7","1"],["60588.3","30"],["60589.5","56"],["60590.2","0"],["60590.5","0"],["60593.0","0"],["60594.4","0"],["60595.7","4541"],["60596.2","17898"],["60596.4","0"]],"a":[["60596.3","4782"],["60598.6","197"],["60599.7","0"],["60601.5","37"],["60602.3","15"],["60603.1","0"],["60603.4","291"],["60604.7","0"],["60604.9","200"],["60611.0","1"],["60611.3","1"],["60617.7","122"],["60620.4","0"],["60630.5","251"],["60633.1","0"],["60638.5","0"],["60643.3","243"],["60645.4","3304"],["60645.9","0"],["60647.4","1225"],["60648.1","0"],["60656.4","369"],["60674.2","531"],["60687.0","0"],["60699.8","2495"],["60722.1","802"],["60723.0","0"],["60772.3","100"]]}}
1618677490.7468832: {"stream":"btcusd_210924@depth@100ms","data":{"e":"depthUpdate","E":1618677490694,"T":1618677490600,"s":"BTCUSD_210924","ps":"BTCUSD","U":86143448198,"u":86143448287,"pu":86143448031,"b":[["68560.9","0"]],"a":[["68671.9","97"],["68674.2","0"]]}}
1618677490.756154: {"stream":"linkusd_210924@depth@100ms","data":{"e":"depthUpdate","E":1618677490704,"T":1618677490688,"s":"LINKUSD_210924","ps":"LINKUSD","U":86143448289,"u":86143448904,"pu":86143447918,"b":[],"a":[["45.380","0"],["45.407","184"],["45.408","875"],["45.417","0"],["45.418","0"],["45.646","40"]]}}
1618677491.005609: {"stream":"xrpusd_210625@depth@100ms","data":{"e":"depthUpdate","E":1618677490730,"T":1618677490722,"s":"XRPUSD_210625","ps":"XRPUSD","U":86143448451,"u":86143449203,"pu":86143447504,"b":[["1.6905","0"],["1.6906","45"],["1.6911","0"]],"a":[["1.6924","45"],["1.6928","0"]]}}
1618677491.005722: {"stream":"ethusd_210924@depth@100ms","data":{"e":"depthUpdate","E":1618677490731,"T":1618677490720,"s":"ETHUSD_210924","ps":"ETHUSD","U":86143448471,"u":86143449179,"pu":86143448279,"b":[["2686.13","0"],["2686.15","0"],["2686.72","6720"]],"a":[["2689.80","48"],["2695.26","500"],["2703.36","250"],["2703.50","0"]]}}
1618677491.005915: {"stream":"linkusd_210625@depth@100ms","data":{"e":"depthUpdate","E":1618677490749,"T":1618677490728,"s":"LINKUSD_210625","ps":"LINKUSD","U":86143448570,"u":86143449246,"pu":86143447273,"b":[["42.754","0"],["42.790","1551"],["43.118","0"],["43.157","1551"],["43.300","0"],["43.340","1551"],["43.483","0"],["43.518","0"],["43.523","1650"],["43.555","59"],["43.558","423"],["43.562","400"],["43.751","0"],["43.758","132"]],"a":[["43.796","0"],["43.805","50"],["43.812","50"],["43.815","439"],["43.817","2819"],["43.840","401"],["43.849","385"],["43.853","0"],["43.855","0"],["43.867","423"],["43.889","0"],["43.903","1551"],["43.910","652"],["43.911","40"],["44.072","0"],["44.123","1551"],["44.288","35"],["44.344","1551"],["44.721","0"],["44.787","1551"]]}}
1618677491.006208: {"stream":"ethusd_210625@depth@100ms","data":{"e":"depthUpdate","E":1618677490764,"T":1618677490744,"s":"ETHUSD_210625","ps":"ETHUSD","U":86143448686,"u":86143449349,"pu":86143448605,"b":[["2510.71","0"],["2510.72","299"],["2510.86","2325"],["2510.88","0"]],"a":[["2510.85","0"],["2511.04","0"],["2511.05","1375"],["2511.09","121"],["2511.23","0"],["2511.25","73"],["2511.55","1074"],["2512.03","16746"],["2513.33","1952"],["2513.77","7548"]]}}
1618677491.0063412: {"stream":"bchusd_210625@depth@100ms","data":{"e":"depthUpdate","E":1618677490773,"T":1618677490766,"s":"BCHUSD_210625","ps":"BCHUSD","U":86143448757,"u":86143449514,"pu":86143448648,"b":[["1120.85","0"],["1120.86","190"],["1128.13","0"],["1128.15","0"],["1128.38","0"],["1128.39","0"],["1128.42","35"]],"a":[]}}
1618677491.0065222: {"stream":"btcusd_perp@depth@100ms","data":{"e":"depthUpdate","E":1618677490795,"T":1618677490783,"s":"BTCUSD_PERP","ps":"BTCUSD","U":86143448922,"u":86143449645,"pu":86143448903,"b":[["60493.7","2450"],["60574.9","1521"],["60579.8","243"],["60580.0","123"],["60580.6","0"],["60580.7","305"],["60586.2","0"],["60586.9","50"],["60588.3","0"],["60590.1","0"],["60591.0","30"],["60591.1","25"],["60592.6","243"],["60593.3","0"],["60594.8","243"],["60595.7","4298"],["60596.2","17998"],["60596.4","0"]],"a":[["60596.3","3565"],["60597.0","40"],["60597.3","30"],["60601.2","155"],["60601.5","7"],["60603.7","0"],["60604.1","50"],["60608.2","0"],["60631.7","293"],["60637.3","140"],["60640.7","0"],["60717.8","0"]]}}
1618677491.0067468: {"stream":"egldusd_perp@depth@100ms","data":{"e":"depthUpdate","E":1618677490807,"T":1618677490801,"s":"EGLDUSD_PERP","ps":"EGLDUSD","U":86143448994,"u":86143449746,"pu":86143448676,"b":[["215.720","23"],["215.859","389"],["216.068","170"]],"a":[["216.069","41"],["216.070","170"],["216.308","27"],["216.310","0"]]}}
1618677491.0068212: {"stream":"linkusd_210924@depth@100ms","data":{"e":"depthUpdate","E":1618677490812,"T":1618677490733,"s":"LINKUSD_210924","ps":"LINKUSD","U":86143449053,"u":86143449277,"pu":86143448904,"b":[["45.241","360"],["45.246","0"],["45.247","0"]],"a":[]}}
1618677491.0068731: {"stream":"btcusd_210924@depth@100ms","data":{"e":"depthUpdate","E":1618677490814,"T":1618677490799,"s":"BTCUSD_210924","ps":"BTCUSD","U":86143449069,"u":86143449739,"pu":86143448287,"b":[["68623.4","0"]],"a":[["68652.1","1140"],["68665.1","0"],["68677.1","277"],["68677.2","20"],["68688.1","0"],["68688.2","0"],["68693.7","145"],["68695.0","636"],["68736.3","0"],["68775.1","200"],["68813.3","0"]]}}
1618677491.0069818: {"stream":"dotusd_210625@depth@100ms","data":{"e":"depthUpdate","E":1618677490818,"T":1618677490808,"s":"DOTUSD_210625","ps":"DOTUSD","U":86143449109,"u":86143449794,"pu":86143448209,"b":[],"a":[["46.753","540"],["46.755","0"],["46.760","200"],["46.886","1020"],["46.918","110"]]}}
