wss://stream.binance.us:9443/stream?streams=batusd@kline_1m/hntusd@kline_1m/zrxusd@kline_1m/manausd@kline_1m/batusd@aggTrade/hntusd@aggTrade/zrxusd@aggTrade/manausd@aggTrade/batusd@bookTicker/hntusd@bookTicker/zrxusd@bookTicker/manausd@bookTicker/batusd@depth@100ms/hntusd@depth@100ms/zrxusd@depth@100ms/manausd@depth@100ms <-> 1628952313.672555
1628952313.904641: {"stream":"zrxusd@bookTicker","data":{"u":124790176,"s":"ZRXUSD","b":"1.0550","B":"562.66000000","a":"1.0566","A":"10950.08000000"}}
1628952313.908036: {"stream":"manausd@depth@100ms","data":{"e":"depthUpdate","E":1628952313956,"s":"MANAUSD","U":108545652,"u":108545652,"b":[["0.8269","1417.65000000"]],"a":[]}}
1628952314.018563: {"stream":"zrxusd@depth@100ms","data":{"e":"depthUpdate","E":1628952313956,"s":"ZRXUSD","U":124790176,"u":124790176,"b":[],"a":[["1.0566","10950.08000000"]]}}
1628952314.052504: {"stream":"manausd@depth@100ms","data":{"e":"depthUpdate","E":1628952314056,"s":"MANAUSD","U":108545653,"u":108545653,"b":[["0.8273","1200.00000000"]],"a":[]}}
1628952314.052536: {"stream":"batusd@depth@100ms","data":{"e":"depthUpdate","E":1628952314056,"s":"BATUSD","U":126705846,"u":126705847,"b":[["0.7695","0.00000000"],["0.7691","370.00000000"]],"a":[]}}
1628952314.0877671: {"stream":"manausd@bookTicker","data":{"u":108545654,"s":"MANAUSD","b":"0.8291","B":"680.00000000","a":"0.8296","A":"4771.01000000"}}
1628952314.109119: {"stream":"batusd@depth@100ms","data":{"e":"depthUpdate","E":1628952314156,"s":"BATUSD","U":126705848,"u":126705851,"b":[["0.7676","609.00000000"],["0.7669","4216.00000000"]],"a":[["0.7719","609.00000000"],["0.7727","20.00000000"]]}}
1628952314.1092238: {"stream":"manausd@depth@100ms","data":{"e":"depthUpdate","E":1628952314156,"s":"MANAUSD","U":108545654,"u":108545656,"b":[["0.8292","0.00000000"],["0.8290","2800.00000000"],["0.8288","0.00000000"]],"a":[]}}
1628952314.2146392: {"stream":"manausd@bookTicker","data":{"u":108545657,"s":"MANAUSD","b":"0.8291","B":"680.00000000","a":"0.8296","A":"2980.00000000"}}
1628952314.264182: {"stream":"batusd@bookTicker","data":{"u":126705852,"s":"BATUSD","b":"0.7691","B":"370.00000000","a":"0.7703","A":"1194.10000000"}}
1628952314.2864268: {"stream":"batusd@bookTicker","data":{"u":126705853,"s":"BATUSD","b":"0.7692","B":"726.85000000","a":"0.7703","A":"1194.10000000"}}
1628952314.2926772: {"stream":"batusd@bookTicker","data":{"u":126705855,"s":"BATUSD","b":"0.7693","B":"370.00000000","a":"0.7703","A":"1194.10000000"}}
1628952314.308746: {"stream":"batusd@depth@100ms","data":{"e":"depthUpdate","E":1628952314357,"s":"BATUSD","U":126705852,"u":126705855,"b":[["0.7696","0.00000000"],["0.7693","370.00000000"],["0.7692","726.85000000"],["0.7691","0.00000000"]],"a":[]}}
1628952314.3088589: {"stream":"manausd@depth@100ms","data":{"e":"depthUpdate","E":1628952314357,"s":"MANAUSD","U":108545657,"u":108545659,"b":[["0.8289","0.00000000"]],"a":[["0.8296","2980.00000000"],["0.8298","1790.88000000"]]}}
1628952314.4089322: {"stream":"zrxusd@depth@100ms","data":{"e":"depthUpdate","E":1628952314457,"s":"ZRXUSD","U":124790177,"u":124790177,"b":[],"a":[["1.0574","2708.90000000"]]}}
1628952314.409014: {"stream":"batusd@depth@100ms","data":{"e":"depthUpdate","E":1628952314457,"s":"BATUSD","U":126705856,"u":126705856,"b":[],"a":[["0.7711","4728.60000000"]]}}
1628952314.4090571: {"stream":"manausd@depth@100ms","data":{"e":"depthUpdate","E":1628952314457,"s":"MANAUSD","U":108545660,"u":108545660,"b":[["0.8242","2997.21000000"]],"a":[]}}
1628952314.608973: {"stream":"hntusd@depth@100ms","data":{"e":"depthUpdate","E":1628952314657,"s":"HNTUSD","U":98434193,"u":98434193,"b":[["16.5119","0.00000000"]],"a":[]}}
1628952314.7083268: {"stream":"hntusd@depth@100ms","data":{"e":"depthUpdate","E":1628952314757,"s":"HNTUSD","U":98434194,"u":98434194,"b":[["16.5099","14.55000000"]],"a":[]}}
1628952314.801497: {"stream":"hntusd@bookTicker","data":{"u":98434196,"s":"HNTUSD","b":"16.5315","B":"24.00000000","a":"16.5711","A":"49.93000000"}}
1628952314.808974: {"stream":"hntusd@depth@100ms","data":{"e":"depthUpdate","E":1628952314857,"s":"HNTUSD","U":98434195,"u":98434196,"b":[],"a":[["16.5711","49.93000000"],["16.5713","0.00000000"]]}}
1628952314.809141: {"stream":"batusd@depth@100ms","data":{"e":"depthUpdate","E":1628952314857,"s":"BATUSD","U":126705857,"u":126705857,"b":[["0.7692","0.00000000"]],"a":[]}}
1628952314.8175292: {"stream":"batusd@bookTicker","data":{"u":126705859,"s":"BATUSD","b":"0.7691","B":"370.00000000","a":"0.7703","A":"1194.10000000"}}
1628952314.821105: {"stream":"batusd@bookTicker","data":{"u":126705860,"s":"BATUSD","b":"0.7694","B":"726.83000000","a":"0.7703","A":"1194.10000000"}}
1628952314.8277388: {"stream":"batusd@bookTicker","data":{"u":126705861,"s":"BATUSD","b":"0.7695","B":"370.00000000","a":"0.7703","A":"1194.10000000"}}
1628952314.880584: {"stream":"hntusd@bookTicker","data":{"u":98434198,"s":"HNTUSD","b":"16.5315","B":"24.00000000","a":"16.5710","A":"11.19000000"}}
1628952314.909812: {"stream":"batusd@depth@100ms","data":{"e":"depthUpdate","E":1628952314957,"s":"BATUSD","U":126705858,"u":126705862,"b":[["0.7695","370.00000000"],["0.7694","726.83000000"],["0.7693","0.00000000"],["0.7691","0.00000000"]],"a":[]}}
1628952314.9099991: {"stream":"hntusd@depth@100ms","data":{"e":"depthUpdate","E":1628952314957,"s":"HNTUSD","U":98434197,"u":98434198,"b":[],"a":[["16.5710","11.19000000"],["16.5712","0.00000000"]]}}
1628952314.9573271: {"stream":"batusd@bookTicker","data":{"u":126705863,"s":"BATUSD","b":"0.7695","B":"370.00000000","a":"0.7706","A":"726.89000000"}}
1628952314.957852: {"stream":"batusd@bookTicker","data":{"u":126705865,"s":"BATUSD","b":"0.7695","B":"370.00000000","a":"0.7704","A":"865.92000000"}}
1628952315.00895: {"stream":"batusd@depth@100ms","data":{"e":"depthUpdate","E":1628952315057,"s":"BATUSD","U":126705863,"u":126705866,"b":[],"a":[["0.7703","0.00000000"],["0.7704","865.92000000"],["0.7705","370.00000000"],["0.8159","0.00000000"]]}}
1628952315.052042: {"stream":"batusd@bookTicker","data":{"u":126705868,"s":"BATUSD","b":"0.7695","B":"370.00000000","a":"0.7704","A":"1592.74000000"}}
1628952315.108421: {"stream":"batusd@depth@100ms","data":{"e":"depthUpdate","E":1628952315157,"s":"BATUSD","U":126705867,"u":126705869,"b":[],"a":[["0.7704","1592.74000000"],["0.7706","0.00000000"],["0.8164","15168.26000000"]]}}
1628952315.108598: {"stream":"manausd@depth@100ms","data":{"e":"depthUpdate","E":1628952315157,"s":"MANAUSD","U":108545661,"u":108545661,"b":[],"a":[["0.8314","4571.00000000"]]}}
1628952315.208991: {"stream":"batusd@depth@100ms","data":{"e":"depthUpdate","E":1628952315257,"s":"BATUSD","U":126705870,"u":126705870,"b":[],"a":[["0.7705","0.00000000"]]}}
1628952315.3094132: {"stream":"manausd@depth@100ms","data":{"e":"depthUpdate","E":1628952315357,"s":"MANAUSD","U":108545662,"u":108545663,"b":[],"a":[["0.8320","4271.41000000"],["0.8414","1928.57000000"]]}}
1628952315.9832761: {"stream":"manausd@bookTicker","data":{"u":108545664,"s":"MANAUSD","b":"0.8291","B":"1180.00000000","a":"0.8296","A":"2980.00000000"}}
1628952316.010257: {"stream":"manausd@depth@100ms","data":{"e":"depthUpdate","E":1628952316058,"s":"MANAUSD","U":108545664,"u":108545665,"b":[["0.8291","1180.00000000"],["0.8290","2300.00000000"]],"a":[]}}
1628952316.309708: {"stream":"manausd@depth@100ms","data":{"e":"depthUpdate","E":1628952316358,"s":"MANAUSD","U":108545666,"u":108545667,"b":[["0.8183","123.43000000"]],"a":[["0.8410","67.75000000"]]}}
1628952316.3830268: {"stream":"manausd@bookTicker","data":{"u":108545668,"s":"MANAUSD","b":"0.8291","B":"680.00000000","a":"0.8296","A":"2980.00000000"}}
1628952316.410552: {"stream":"manausd@depth@100ms","data":{"e":"depthUpdate","E":1628952316458,"s":"MANAUSD","U":108545668,"u":108545669,"b":[["0.8291","680.00000000"],["0.8290","2800.00000000"]],"a":[]}}
1628952316.610058: {"stream":"manausd@depth@100ms","data":{"e":"depthUpdate","E":1628952316658,"s":"MANAUSD","U":108545670,"u":108545670,"b":[["0.8290","2300.00000000"]],"a":[]}}
1628952316.711781: {"stream":"batusd@depth@100ms","data":{"e":"depthUpdate","E":1628952316758,"s":"BATUSD","U":126705871,"u":126705871,"b":[],"a":[["0.7712","106094.10000000"]]}}
1628952316.835774: {"stream":"hntusd@bookTicker","data":{"u":98434200,"s":"HNTUSD","b":"16.5315","B":"24.00000000","a":"16.5709","A":"49.93000000"}}
1628952316.9106119: {"stream":"hntusd@depth@100ms","data":{"e":"depthUpdate","E":1628952316958,"s":"HNTUSD","U":98434199,"u":98434202,"b":[],"a":[["16.5709","49.93000000"],["16.5710","0.00000000"],["16.5711","0.00000000"],["16.5723","11.82000000"]]}}
1628952316.9692428: {"stream":"hntusd@bookTicker","data":{"u":98434204,"s":"HNTUSD","b":"16.5315","B":"24.00000000","a":"16.5708","A":"15.63000000"}}
1628952316.9926798: {"stream":"batusd@bookTicker","data":{"u":126705872,"s":"BATUSD","b":"0.7695","B":"370.00000000","a":"0.7704","A":"865.92000000"}}
1628952317.010546: {"stream":"hntusd@depth@100ms","data":{"e":"depthUpdate","E":1628952317058,"s":"HNTUSD","U":98434203,"u":98434206,"b":[],"a":[["16.5708","15.63000000"],["16.5722","24.00000000"],["16.5723","0.00000000"],["16.5724","0.00000000"]]}}
1628952317.010667: {"stream":"batusd@depth@100ms","data":{"e":"depthUpdate","E":1628952317058,"s":"BATUSD","U":126705872,"u":126705872,"b":[],"a":[["0.7704","865.92000000"]]}}
1628952317.040854: {"stream":"manausd@bookTicker","data":{"u":108545671,"s":"MANAUSD","b":"0.8292","B":"2300.00000000","a":"0.8296","A":"2980.00000000"}}
1628952317.110351: {"stream":"batusd@depth@100ms","data":{"e":"depthUpdate","E":1628952317158,"s":"BATUSD","U":126705873,"u":126705873,"b":[],"a":[["0.7707","726.78000000"]]}}
1628952317.1104891: {"stream":"manausd@depth@100ms","data":{"e":"depthUpdate","E":1628952317158,"s":"MANAUSD","U":108545671,"u":108545671,"b":[["0.8292","2300.00000000"]],"a":[]}}
1628952317.311456: {"stream":"manausd@depth@100ms","data":{"e":"depthUpdate","E":1628952317359,"s":"MANAUSD","U":108545672,"u":108545672,"b":[["0.8178","116.74000000"]],"a":[]}}
1628952317.411683: {"stream":"manausd@depth@100ms","data":{"e":"depthUpdate","E":1628952317459,"s":"MANAUSD","U":108545673,"u":108545673,"b":[["0.8263","93.37000000"]],"a":[]}}
1628952317.510933: {"stream":"zrxusd@depth@100ms","data":{"e":"depthUpdate","E":1628952317559,"s":"ZRXUSD","U":124790178,"u":124790178,"b":[["1.0482","0.00000000"]],"a":[]}}
1628952317.6112058: {"stream":"zrxusd@depth@100ms","data":{"e":"depthUpdate","E":1628952317659,"s":"ZRXUSD","U":124790179,"u":124790179,"b":[["1.0482","5029.00000000"]],"a":[]}}
1628952317.772289: {"stream":"batusd@bookTicker","data":{"u":126705875,"s":"BATUSD","b":"0.7696","B":"726.76000000","a":"0.7704","A":"865.92000000"}}
1628952317.7935941: {"stream":"batusd@bookTicker","data":{"u":126705876,"s":"BATUSD","b":"0.7696","B":"726.76000000","a":"0.7703","A":"110.11000000"}}
1628952317.8092659: {"stream":"batusd@depth@100ms","data":{"e":"depthUpdate","E":1628952317859,"s":"BATUSD","U":126705874,"u":126705876,"b":[["0.7696","726.76000000"],["0.7694","0.00000000"]],"a":[["0.7703","110.11000000"]]}}
1628952317.9115899: {"stream":"batusd@depth@100ms","data":{"e":"depthUpdate","E":1628952317959,"s":"BATUSD","U":126705877,"u":126705878,"b":[["0.7695","0.00000000"],["0.7691","370.00000000"]],"a":[]}}
1628952318.651347: {"stream":"manausd@bookTicker","data":{"u":108545674,"s":"MANAUSD","b":"0.8291","B":"680.00000000","a":"0.8296","A":"2980.00000000"}}
1628952318.7113311: {"stream":"manausd@depth@100ms","data":{"e":"depthUpdate","E":1628952318760,"s":"MANAUSD","U":108545674,"u":108545674,"b":[["0.8292","0.00000000"]],"a":[]}}
1628952319.048963: {"stream":"hntusd@bookTicker","data":{"u":98434208,"s":"HNTUSD","b":"16.5315","B":"24.00000000","a":"16.5722","A":"24.00000000"}}
1628952319.0509388: {"stream":"hntusd@bookTicker","data":{"u":98434209,"s":"HNTUSD","b":"16.5315","B":"24.00000000","a":"16.5706","A":"49.93000000"}}
1628952319.111707: {"stream":"hntusd@depth@100ms","data":{"e":"depthUpdate","E":1628952319160,"s":"HNTUSD","U":98434207,"u":98434210,"b":[],"a":[["16.5706","49.93000000"],["16.5708","0.00000000"],["16.5709","0.00000000"],["16.5721","14.39000000"]]}}
1628952319.199521: {"stream":"hntusd@bookTicker","data":{"u":98434212,"s":"HNTUSD","b":"16.5315","B":"24.00000000","a":"16.5705","A":"12.13000000"}}
1628952319.2124438: {"stream":"hntusd@depth@100ms","data":{"e":"depthUpdate","E":1628952319260,"s":"HNTUSD","U":98434211,"u":98434213,"b":[],"a":[["16.5705","12.13000000"],["16.5719","24.00000000"],["16.5721","0.00000000"]]}}
1628952319.3114161: {"stream":"hntusd@depth@100ms","data":{"e":"depthUpdate","E":1628952319360,"s":"HNTUSD","U":98434214,"u":98434214,"b":[],"a":[["16.5722","0.00000000"]]}}
1628952319.499531: {"stream":"manausd@bookTicker","data":{"u":108545676,"s":"MANAUSD","b":"0.8290","B":"2980.00000000","a":"0.8296","A":"2980.00000000"}}
1628952319.507586: {"stream":"hntusd@bookTicker","data":{"u":98434216,"s":"HNTUSD","b":"16.5315","B":"24.00000000","a":"16.5719","A":"24.00000000"}}
1628952319.512107: {"stream":"manausd@depth@100ms","data":{"e":"depthUpdate","E":1628952319560,"s":"MANAUSD","U":108545675,"u":108545676,"b":[["0.8291","0.00000000"],["0.8290","2980.00000000"]],"a":[]}}
1628952319.512213: {"stream":"hntusd@depth@100ms","data":{"e":"depthUpdate","E":1628952319560,"s":"HNTUSD","U":98434215,"u":98434216,"b":[],"a":[["16.5705","0.00000000"],["16.5706","0.00000000"]]}}
1628952319.549564: {"stream":"hntusd@bookTicker","data":{"u":98434217,"s":"HNTUSD","b":"16.5315","B":"24.00000000","a":"16.5718","A":"15.59000000"}}
1628952319.611625: {"stream":"batusd@depth@100ms","data":{"e":"depthUpdate","E":1628952319660,"s":"BATUSD","U":126705879,"u":126705880,"b":[["0.7690","5564.74000000"],["0.7688","1000.00000000"]],"a":[]}}
1628952319.6117601: {"stream":"hntusd@depth@100ms","data":{"e":"depthUpdate","E":1628952319660,"s":"HNTUSD","U":98434217,"u":98434217,"b":[],"a":[["16.5718","15.59000000"]]}}
1628952319.667253: {"stream":"batusd@bookTicker","data":{"u":126705881,"s":"BATUSD","b":"0.7697","B":"370.00000000","a":"0.7703","A":"110.11000000"}}
1628952319.712744: {"stream":"batusd@depth@100ms","data":{"e":"depthUpdate","E":1628952319760,"s":"BATUSD","U":126705881,"u":126705882,"b":[["0.7697","370.00000000"],["0.7691","0.00000000"]],"a":[]}}
1628952320.2129269: {"stream":"zrxusd@depth@100ms","data":{"e":"depthUpdate","E":1628952320261,"s":"ZRXUSD","U":124790180,"u":124790180,"b":[["1.0545","2367.75000000"]],"a":[]}}
1628952320.429116: {"stream":"hntusd@bookTicker","data":{"u":98434218,"s":"HNTUSD","b":"16.5315","B":"24.00000000","a":"16.5717","A":"49.93000000"}}
1628952320.506241: {"stream":"hntusd@bookTicker","data":{"u":98434220,"s":"HNTUSD","b":"16.5315","B":"24.00000000","a":"16.5716","A":"15.24000000"}}
1628952320.5140622: {"stream":"hntusd@depth@100ms","data":{"e":"depthUpdate","E":1628952320561,"s":"HNTUSD","U":98434218,"u":98434220,"b":[],"a":[["16.5716","15.24000000"],["16.5717","49.93000000"],["16.5718","0.00000000"]]}}
1628952320.5142431: {"stream":"manausd@depth@100ms","data":{"e":"depthUpdate","E":1628952320561,"s":"MANAUSD","U":108545677,"u":108545677,"b":[],"a":[["0.8298","0.00000000"]]}}
1628952320.530302: {"stream":"manausd@bookTicker","data":{"u":108545678,"s":"MANAUSD","b":"0.8290","B":"2980.00000000","a":"0.8296","A":"4770.99000000"}}
1628952320.552589: {"stream":"batusd@bookTicker","data":{"u":126705885,"s":"BATUSD","b":"0.7697","B":"370.00000000","a":"0.7704","A":"865.92000000"}}
1628952320.61345: {"stream":"batusd@depth@100ms","data":{"e":"depthUpdate","E":1628952320661,"s":"BATUSD","U":126705883,"u":126705886,"b":[["0.7693","5942.61000000"]],"a":[["0.7703","0.00000000"],["0.7706","127.08000000"],["0.7711","0.00000000"]]}}
1628952320.6136441: {"stream":"manausd@depth@100ms","data":{"e":"depthUpdate","E":1628952320661,"s":"MANAUSD","U":108545678,"u":108545678,"b":[],"a":[["0.8296","4770.99000000"]]}}
1628952320.714236: {"stream":"batusd@depth@100ms","data":{"e":"depthUpdate","E":1628952320761,"s":"BATUSD","U":126705887,"u":126705887,"b":[["0.7690","1948.57000000"]],"a":[]}}
1628952320.786965: {"stream":"batusd@bookTicker","data":{"u":126705888,"s":"BATUSD","b":"0.7697","B":"370.00000000","a":"0.7706","A":"127.08000000"}}
1628952320.794375: {"stream":"batusd@bookTicker","data":{"u":126705890,"s":"BATUSD","b":"0.7697","B":"370.00000000","a":"0.7706","A":"497.08000000"}}
1628952320.814827: {"stream":"batusd@depth@100ms","data":{"e":"depthUpdate","E":1628952320861,"s":"BATUSD","U":126705888,"u":126705890,"b":[],"a":[["0.7704","0.00000000"],["0.7706","497.08000000"],["0.8184","12337.48000000"]]}}
1628952320.913794: {"stream":"manausd@depth@100ms","data":{"e":"depthUpdate","E":1628952320961,"s":"MANAUSD","U":108545679,"u":108545680,"b":[["0.8271","26.79000000"],["0.8220","531.56000000"]],"a":[]}}
1628952321.042618: {"stream":"manausd@bookTicker","data":{"u":108545681,"s":"MANAUSD","b":"0.8290","B":"2980.00000000","a":"0.8296","A":"2980.00000000"}}
1628952321.1131961: {"stream":"manausd@depth@100ms","data":{"e":"depthUpdate","E":1628952321161,"s":"MANAUSD","U":108545681,"u":108545682,"b":[],"a":[["0.8296","2980.00000000"],["0.8298","1790.92000000"]]}}
1628952321.214392: {"stream":"batusd@depth@100ms","data":{"e":"depthUpdate","E":1628952321261,"s":"BATUSD","U":126705891,"u":126705891,"b":[],"a":[["0.7708","380.12000000"]]}}
1628952321.318957: {"stream":"manausd@bookTicker","data":{"u":108545683,"s":"MANAUSD","b":"0.8290","B":"3480.00000000","a":"0.8296","A":"2980.00000000"}}
1628952321.414091: {"stream":"manausd@depth@100ms","data":{"e":"depthUpdate","E":1628952321461,"s":"MANAUSD","U":108545683,"u":108545683,"b":[["0.8290","3480.00000000"]],"a":[]}}
1628952321.427861: {"stream":"manausd@bookTicker","data":{"u":108545684,"s":"MANAUSD","b":"0.8290","B":"2980.00000000","a":"0.8296","A":"2980.00000000"}}
1628952321.5152519: {"stream":"batusd@depth@100ms","data":{"e":"depthUpdate","E":1628952321562,"s":"BATUSD","U":126705892,"u":126705892,"b":[],"a":[["0.7711","1000.00000000"]]}}
1628952321.515394: {"stream":"manausd@depth@100ms","data":{"e":"depthUpdate","E":1628952321562,"s":"MANAUSD","U":108545684,"u":108545685,"b":[["0.8290","2980.00000000"]],"a":[["0.8310","0.00000000"]]}}
1628952321.614264: {"stream":"manausd@depth@100ms","data":{"e":"depthUpdate","E":1628952321662,"s":"MANAUSD","U":108545686,"u":108545687,"b":[["0.8238","79.09000000"]],"a":[["0.8312","1200.00000000"]]}}
1628952321.750941: {"stream":"manausd@bookTicker","data":{"u":108545689,"s":"MANAUSD","b":"0.8290","B":"2980.00000000","a":"0.8295","A":"628.09000000"}}
1628952321.7624772: {"stream":"manausd@bookTicker","data":{"u":108545691,"s":"MANAUSD","b":"0.8290","B":"2980.00000000","a":"0.8294","A":"2300.00000000"}}
1628952321.773452: {"stream":"manausd@bookTicker","data":{"u":108545693,"s":"MANAUSD","b":"0.8290","B":"680.00000000","a":"0.8294","A":"2300.00000000"}}
1628952321.778704: {"stream":"batusd@bookTicker","data":{"u":126705894,"s":"BATUSD","b":"0.7698","B":"726.65000000","a":"0.7706","A":"497.08000000"}}
1628952321.779882: {"stream":"manausd@bookTicker","data":{"u":108545696,"s":"MANAUSD","b":"0.8290","B":"680.00000000","a":"0.8294","A":"2980.00000000"}}
1628952321.779967: {"stream":"manausd@bookTicker","data":{"u":108545697,"s":"MANAUSD","b":"0.8287","B":"3617.99000000","a":"0.8294","A":"2980.00000000"}}
1628952321.781991: {"stream":"manausd@bookTicker","data":{"u":108545698,"s":"MANAUSD","b":"0.8288","B":"680.00000000","a":"0.8294","A":"2980.00000000"}}
1628952321.786203: {"stream":"manausd@bookTicker","data":{"u":108545699,"s":"MANAUSD","b":"0.8288","B":"1308.09000000","a":"0.8294","A":"2980.00000000"}}
1628952321.8128378: {"stream":"manausd@depth@100ms","data":{"e":"depthUpdate","E":1628952321862,"s":"MANAUSD","U":108545688,"u":108545701,"b":[["0.8290","0.00000000"],["0.8288","1308.09000000"],["0.8285","1791.10000000"]],"a":[["0.8294","2980.00000000"],["0.8295","628.09000000"],["0.8296","4091.20000000"],["0.8297","0.00000000"],["0.8298","0.00000000"],["0.8611","62.91000000"]]}}
1628952321.813084: {"stream":"batusd@depth@100ms","data":{"e":"depthUpdate","E":1628952321862,"s":"BATUSD","U":126705893,"u":126705894,"b":[["0.7698","726.65000000"],["0.7696","0.00000000"]],"a":[]}}
1628952321.883865: {"stream":"manausd@bookTicker","data":{"u":108545703,"s":"MANAUSD","b":"0.8288","B":"1308.09000000","a":"0.8294","A":"2300.00000000"}}
1628952321.88532: {"stream":"manausd@bookTicker","data":{"u":108545704,"s":"MANAUSD","b":"0.8288","B":"1308.09000000","a":"0.8293","A":"680.00000000"}}
1628952321.885403: {"stream":"manausd@bookTicker","data":{"u":108545705,"s":"MANAUSD","b":"0.8288","B":"680.00000000","a":"0.8293","A":"680.00000000"}}
1628952321.897621: {"stream":"manausd@bookTicker","data":{"u":108545707,"s":"MANAUSD","b":"0.8288","B":"680.00000000","a":"0.8292","A":"2300.00000000"}}
1628952321.913574: {"stream":"batusd@depth@100ms","data":{"e":"depthUpdate","E":1628952321962,"s":"BATUSD","U":126705895,"u":126705896,"b":[["0.7697","0.00000000"],["0.7694","370.00000000"]],"a":[]}}
1628952321.913645: {"stream":"manausd@depth@100ms","data":{"e":"depthUpdate","E":1628952321962,"s":"MANAUSD","U":108545702,"u":108545707,"b":[["0.8288","680.00000000"],["0.8285","0.00000000"]],"a":[["0.8292","2300.00000000"],["0.8293","680.00000000"],["0.8294","2300.00000000"],["0.8296","1791.20000000"]]}}
1628952321.9370549: {"stream":"manausd@bookTicker","data":{"u":108545711,"s":"MANAUSD","b":"0.8287","B":"680.00000000","a":"0.8292","A":"2300.00000000"}}
1628952321.944343: {"stream":"manausd@bookTicker","data":{"u":108545712,"s":"MANAUSD","b":"0.8287","B":"680.00000000","a":"0.8291","A":"680.00000000"}}
1628952321.9550421: {"stream":"manausd@bookTicker","data":{"u":108545716,"s":"MANAUSD","b":"0.8284","B":"3619.12000000","a":"0.8291","A":"680.00000000"}}
1628952321.955065: {"stream":"manausd@bookTicker","data":{"u":108545717,"s":"MANAUSD","b":"0.8285","B":"680.00000000","a":"0.8291","A":"680.00000000"}}
1628952321.95823: {"stream":"manausd@bookTicker","data":{"u":108545718,"s":"MANAUSD","b":"0.8285","B":"680.00000000","a":"0.8290","A":"2300.00000000"}}
1628952322.014506: {"stream":"manausd@depth@100ms","data":{"e":"depthUpdate","E":1628952322062,"s":"MANAUSD","U":108545708,"u":108545720,"b":[["0.8288","0.00000000"],["0.8287","0.00000000"],["0.8285","680.00000000"],["0.8280","5084.15000000"]],"a":[["0.8290","2300.00000000"],["0.8291","680.00000000"],["0.8293","0.00000000"],["0.8294","0.00000000"],["0.8297","3619.28000000"],["0.8299","0.00000000"],["0.8302","0.00000000"]]}}
1628952322.114205: {"stream":"manausd@depth@100ms","data":{"e":"depthUpdate","E":1628952322162,"s":"MANAUSD","U":108545721,"u":108545724,"b":[["0.8284","0.00000000"],["0.8281","500.00000000"],["0.8273","0.00000000"],["0.8256","32.96000000"]],"a":[]}}
1628952322.120859: {"stream":"manausd@bookTicker","data":{"u":108545725,"s":"MANAUSD","b":"0.8281","B":"500.00000000","a":"0.8290","A":"2300.00000000"}}
1628952322.1224298: {"stream":"manausd@bookTicker","data":{"u":108545726,"s":"MANAUSD","b":"0.8282","B":"680.00000000","a":"0.8290","A":"2300.00000000"}}
1628952322.150252: {"stream":"manausd@bookTicker","data":{"u":108545728,"s":"MANAUSD","b":"0.8283","B":"2300.00000000","a":"0.8290","A":"2300.00000000"}}
1628952322.157655: {"stream":"manausd@bookTicker","data":{"u":108545729,"s":"MANAUSD","b":"0.8284","B":"680.00000000","a":"0.8290","A":"2300.00000000"}}
1628952322.170323: {"stream":"manausd@bookTicker","data":{"u":108545732,"s":"MANAUSD","b":"0.8285","B":"628.09000000","a":"0.8290","A":"2300.00000000"}}
1628952322.216405: {"stream":"manausd@depth@100ms","data":{"e":"depthUpdate","E":1628952322262,"s":"MANAUSD","U":108545725,"u":108545732,"b":[["0.8285","628.09000000"],["0.8284","680.00000000"],["0.8283","2300.00000000"],["0.8282","0.00000000"],["0.8272","1792.07000000"],["0.8269","2617.65000000"]],"a":[]}}
1628952322.258101: {"stream":"manausd@bookTicker","data":{"u":108545733,"s":"MANAUSD","b":"0.8286","B":"2300.00000000","a":"0.8290","A":"2300.00000000"}}
1628952322.285595: {"stream":"batusd@bookTicker","data":{"u":126705898,"s":"BATUSD","b":"0.7698","B":"726.65000000","a":"0.7706","A":"1223.75000000"}}
1628952322.315564: {"stream":"batusd@depth@100ms","data":{"e":"depthUpdate","E":1628952322362,"s":"BATUSD","U":126705897,"u":126705898,"b":[],"a":[["0.7706","1223.75000000"],["0.7707","0.00000000"]]}}
1628952322.315722: {"stream":"manausd@depth@100ms","data":{"e":"depthUpdate","E":1628952322362,"s":"MANAUSD","U":108545733,"u":108545734,"b":[["0.8286","2300.00000000"]],"a":[["0.8611","211.14000000"]]}}
1628952322.315829: {"stream":"batusd@bookTicker","data":{"u":126705899,"s":"BATUSD","b":"0.7698","B":"726.65000000","a":"0.7706","A":"1096.67000000"}}
1628952322.366729: {"stream":"batusd@bookTicker","data":{"u":126705900,"s":"BATUSD","b":"0.7698","B":"726.65000000","a":"0.7706","A":"1256.51000000"}}
1628952322.413729: {"stream":"batusd@depth@100ms","data":{"e":"depthUpdate","E":1628952322462,"s":"BATUSD","U":126705899,"u":126705900,"b":[],"a":[["0.7706","1256.51000000"]]}}
1628952322.414272: {"stream":"manausd@depth@100ms","data":{"e":"depthUpdate","E":1628952322462,"s":"MANAUSD","U":108545735,"u":108545738,"b":[["0.8283","2800.00000000"],["0.8281","0.00000000"],["0.8280","3619.28000000"],["0.8045","6619.63000000"]],"a":[]}}
1628952322.460475: {"stream":"hntusd@bookTicker","data":{"u":98434222,"s":"HNTUSD","b":"16.5315","B":"24.00000000","a":"16.5715","A":"49.93000000"}}
1628952322.467893: {"stream":"hntusd@bookTicker","data":{"u":98434225,"s":"HNTUSD","b":"16.5315","B":"24.00000000","a":"16.5713","A":"24.00000000"}}
1628952322.5139258: {"stream":"hntusd@depth@100ms","data":{"e":"depthUpdate","E":1628952322562,"s":"HNTUSD","U":98434221,"u":98434225,"b":[],"a":[["16.5713","24.00000000"],["16.5715","49.93000000"],["16.5716","0.00000000"],["16.5717","0.00000000"],["16.5719","0.00000000"]]}}
1628952322.6150331: {"stream":"manausd@depth@100ms","data":{"e":"depthUpdate","E":1628952322662,"s":"MANAUSD","U":108545739,"u":108545740,"b":[["0.8283","2300.00000000"]],"a":[["0.8312","0.00000000"]]}}
1628952322.61519: {"stream":"hntusd@depth@100ms","data":{"e":"depthUpdate","E":1628952322662,"s":"HNTUSD","U":98434226,"u":98434227,"b":[],"a":[["16.5718","0.00000000"]]}}
1628952322.615252: {"stream":"zrxusd@depth@100ms","data":{"e":"depthUpdate","E":1628952322662,"s":"ZRXUSD","U":124790181,"u":124790181,"b":[],"a":[["1.0579","0.00000000"]]}}
1628952322.716259: {"stream":"hntusd@depth@100ms","data":{"e":"depthUpdate","E":1628952322762,"s":"HNTUSD","U":98434228,"u":98434228,"b":[],"a":[["16.5714","15.42000000"]]}}
1628952322.814411: {"stream":"manausd@depth@100ms","data":{"e":"depthUpdate","E":1628952322862,"s":"MANAUSD","U":108545741,"u":108545743,"b":[["0.8266","0.00000000"],["0.8257","4571.00000000"]],"a":[["0.8303","1200.00000000"]]}}
1628952322.915712: {"stream":"manausd@depth@100ms","data":{"e":"depthUpdate","E":1628952322962,"s":"MANAUSD","U":108545744,"u":108545747,"b":[["0.8282","3620.43000000"],["0.8280","0.00000000"],["0.8277","3620.69000000"]],"a":[["0.8293","3620.89000000"]]}}
1628952323.015213: {"stream":"manausd@depth@100ms","data":{"e":"depthUpdate","E":1628952323062,"s":"MANAUSD","U":108545748,"u":108545749,"b":[["0.8278","1792.04000000"],["0.8272","0.00000000"]],"a":[]}}
1628952323.015383: {"stream":"batusd@depth@100ms","data":{"e":"depthUpdate","E":1628952323062,"s":"BATUSD","U":126705901,"u":126705901,"b":[["0.7690","0.00000000"]],"a":[]}}
1628952323.2661288: {"stream":"batusd@bookTicker","data":{"u":126705902,"s":"BATUSD","b":"0.7698","B":"726.65000000","a":"0.7706","A":"529.84000000"}}
1628952323.270535: {"stream":"hntusd@bookTicker","data":{"u":98434231,"s":"HNTUSD","b":"16.5315","B":"24.00000000","a":"16.5711","A":"43.84000000"}}
1628952323.314622: {"stream":"batusd@depth@100ms","data":{"e":"depthUpdate","E":1628952323363,"s":"BATUSD","U":126705902,"u":126705903,"b":[],"a":[["0.7706","529.84000000"],["0.7707","726.69000000"]]}}
1628952323.3147771: {"stream":"hntusd@depth@100ms","data":{"e":"depthUpdate","E":1628952323363,"s":"HNTUSD","U":98434229,"u":98434231,"b":[],"a":[["16.5711","43.84000000"],["16.5714","0.00000000"],["16.5715","0.00000000"]]}}
1628952323.3188522: {"stream":"batusd@bookTicker","data":{"u":126705904,"s":"BATUSD","b":"0.7698","B":"726.65000000","a":"0.7706","A":"370.00000000"}}
1628952323.364615: {"stream":"batusd@bookTicker","data":{"u":126705905,"s":"BATUSD","b":"0.7698","B":"726.65000000","a":"0.7706","A":"544.36000000"}}
1628952323.414826: {"stream":"hntusd@depth@100ms","data":{"e":"depthUpdate","E":1628952323463,"s":"HNTUSD","U":98434232,"u":98434233,"b":[],"a":[["16.5713","24.00000000"]]}}
1628952323.414953: {"stream":"batusd@depth@100ms","data":{"e":"depthUpdate","E":1628952323463,"s":"BATUSD","U":126705904,"u":126705905,"b":[],"a":[["0.7706","544.36000000"]]}}
1628952323.421249: {"stream":"hntusd@bookTicker","data":{"u":98434234,"s":"HNTUSD","b":"16.5315","B":"24.00000000","a":"16.5710","A":"14.13000000"}}
1628952323.515263: {"stream":"hntusd@depth@100ms","data":{"e":"depthUpdate","E":1628952323563,"s":"HNTUSD","U":98434234,"u":98434234,"b":[],"a":[["16.5710","14.13000000"]]}}
1628952323.5154078: {"stream":"manausd@depth@100ms","data":{"e":"depthUpdate","E":1628952323563,"s":"MANAUSD","U":108545750,"u":108545750,"b":[["0.8238","171.94000000"]],"a":[]}}
1628952323.5438259: {"stream":"manausd@bookTicker","data":{"u":108545751,"s":"MANAUSD","b":"0.8286","B":"2300.00000000","a":"0.8291","A":"680.00000000"}}
1628952323.614368: {"stream":"manausd@depth@100ms","data":{"e":"depthUpdate","E":1628952323663,"s":"MANAUSD","U":108545751,"u":108545751,"b":[],"a":[["0.8290","0.00000000"]]}}
1628952323.814611: {"stream":"manausd@depth@100ms","data":{"e":"depthUpdate","E":1628952323863,"s":"MANAUSD","U":108545752,"u":108545752,"b":[],"a":[["0.8295","0.00000000"]]}}
1628952324.1429088: {"stream":"manausd@bookTicker","data":{"u":108545753,"s":"MANAUSD","b":"0.8286","B":"2800.00000000","a":"0.8291","A":"680.00000000"}}
1628952324.165633: {"stream":"manausd@bookTicker","data":{"u":108545754,"s":"MANAUSD","b":"0.8286","B":"2300.00000000","a":"0.8291","A":"680.00000000"}}
1628952324.170642: {"stream":"manausd@bookTicker","data":{"u":108545755,"s":"MANAUSD","b":"0.8287","B":"500.00000000","a":"0.8291","A":"680.00000000"}}
1628952324.197442: {"stream":"manausd@bookTicker","data":{"u":108545757,"s":"MANAUSD","b":"0.8287","B":"500.00000000","a":"0.8292","A":"2300.00000000"}}
1628952324.197524: {"stream":"manausd@bookTicker","data":{"u":108545758,"s":"MANAUSD","b":"0.8287","B":"500.00000000","a":"0.8292","A":"2980.00000000"}}
1628952324.2050638: {"stream":"manausd@bookTicker","data":{"u":108545759,"s":"MANAUSD","b":"0.8287","B":"500.00000000","a":"0.8292","A":"680.00000000"}}
1628952324.211214: {"stream":"manausd@bookTicker","data":{"u":108545761,"s":"MANAUSD","b":"0.8287","B":"1180.00000000","a":"0.8292","A":"680.00000000"}}
1628952324.2144508: {"stream":"manausd@depth@100ms","data":{"e":"depthUpdate","E":1628952324263,"s":"MANAUSD","U":108545753,"u":108545761,"b":[["0.8287","1180.00000000"],["0.8286","2300.00000000"],["0.8285","0.00000000"],["0.8284","0.00000000"]],"a":[["0.8291","0.00000000"],["0.8292","680.00000000"]]}}
1628952324.2229629: {"stream":"manausd@bookTicker","data":{"u":108545765,"s":"MANAUSD","b":"0.8288","B":"2300.00000000","a":"0.8292","A":"680.00000000"}}
1628952324.229681: {"stream":"manausd@bookTicker","data":{"u":108545767,"s":"MANAUSD","b":"0.8288","B":"2300.00000000","a":"0.8296","A":"1791.20000000"}}
1628952324.2302148: {"stream":"manausd@bookTicker","data":{"u":108545768,"s":"MANAUSD","b":"0.8288","B":"2300.00000000","a":"0.8293","A":"680.00000000"}}
1628952324.238608: {"stream":"manausd@bookTicker","data":{"u":108545772,"s":"MANAUSD","b":"0.8288","B":"2980.00000000","a":"0.8293","A":"680.00000000"}}
1628952324.242698: {"stream":"manausd@bookTicker","data":{"u":108545775,"s":"MANAUSD","b":"0.8288","B":"2980.00000000","a":"0.8295","A":"1308.09000000"}}
1628952324.247076: {"stream":"manausd@bookTicker","data":{"u":108545776,"s":"MANAUSD","b":"0.8288","B":"2980.00000000","a":"0.8292","A":"2300.00000000"}}
1628952324.315638: {"stream":"manausd@depth@100ms","data":{"e":"depthUpdate","E":1628952324363,"s":"MANAUSD","U":108545762,"u":108545778,"b":[["0.8288","2980.00000000"],["0.8287","500.00000000"],["0.8284","1791.23000000"],["0.8283","0.00000000"],["0.8282","0.00000000"],["0.8278","0.00000000"]],"a":[["0.8292","2300.00000000"],["0.8293","0.00000000"],["0.8294","680.00000000"],["0.8295","628.09000000"],["0.8300","3619.81000000"]]}}
1628952324.686015: {"stream":"manausd@bookTicker","data":{"u":108545779,"s":"MANAUSD","b":"0.8288","B":"2980.00000000","a":"0.8294","A":"680.00000000"}}
1628952324.6991549: {"stream":"manausd@bookTicker","data":{"u":108545780,"s":"MANAUSD","b":"0.8288","B":"2300.00000000","a":"0.8294","A":"680.00000000"}}
1628952324.6992378: {"stream":"manausd@bookTicker","data":{"u":108545781,"s":"MANAUSD","b":"0.8289","B":"680.00000000","a":"0.8294","A":"680.00000000"}}
1628952324.711807: {"stream":"manausd@bookTicker","data":{"u":108545782,"s":"MANAUSD","b":"0.8290","B":"2300.00000000","a":"0.8294","A":"680.00000000"}}
1628952324.716154: {"stream":"manausd@depth@100ms","data":{"e":"depthUpdate","E":1628952324764,"s":"MANAUSD","U":108545779,"u":108545783,"b":[["0.8290","2300.00000000"],["0.8289","680.00000000"],["0.8288","2300.00000000"],["0.8286","0.00000000"]],"a":[["0.8292","0.00000000"]]}}
1628952324.719498: {"stream":"manausd@bookTicker","data":{"u":108545784,"s":"MANAUSD","b":"0.8290","B":"2300.00000000","a":"0.8295","A":"628.09000000"}}
1628952324.7195818: {"stream":"manausd@bookTicker","data":{"u":108545785,"s":"MANAUSD","b":"0.8290","B":"2300.00000000","a":"0.8295","A":"1308.09000000"}}
1628952324.8154602: {"stream":"manausd@depth@100ms","data":{"e":"depthUpdate","E":1628952324864,"s":"MANAUSD","U":108545784,"u":108545788,"b":[["0.8286","3618.70000000"],["0.8281","3618.85000000"],["0.8277","0.00000000"]],"a":[["0.8294","0.00000000"],["0.8295","1308.09000000"]]}}
1628952324.9157782: {"stream":"manausd@depth@100ms","data":{"e":"depthUpdate","E":1628952324964,"s":"MANAUSD","U":108545789,"u":108545789,"b":[],"a":[["0.8303","0.00000000"]]}}
1628952324.941375: {"stream":"manausd@bookTicker","data":{"u":108545791,"s":"MANAUSD","b":"0.8291","B":"628.09000000","a":"0.8295","A":"1308.09000000"}}
1628952324.9487429: {"stream":"manausd@bookTicker","data":{"u":108545793,"s":"MANAUSD","b":"0.8291","B":"628.09000000","a":"0.8295","A":"628.09000000"}}
1628952324.953553: {"stream":"manausd@bookTicker","data":{"u":108545794,"s":"MANAUSD","b":"0.8292","B":"2300.00000000","a":"0.8295","A":"628.09000000"}}
1628952324.972794: {"stream":"manausd@bookTicker","data":{"u":108545799,"s":"MANAUSD","b":"0.8292","B":"2300.00000000","a":"0.8296","A":"680.00000000"}}
1628952325.016781: {"stream":"manausd@depth@100ms","data":{"e":"depthUpdate","E":1628952325064,"s":"MANAUSD","U":108545790,"u":108545799,"b":[["0.8292","2300.00000000"],["0.8291","628.09000000"],["0.8288","0.00000000"],["0.8286","0.00000000"]],"a":[["0.8295","0.00000000"],["0.8296","680.00000000"],["0.8297","0.00000000"],["0.8312","1200.00000000"]]}}
1628952325.027921: {"stream":"manausd@bookTicker","data":{"u":108545800,"s":"MANAUSD","b":"0.8292","B":"2300.00000000","a":"0.8296","A":"2980.00000000"}}
1628952325.0342882: {"stream":"manausd@bookTicker","data":{"u":108545803,"s":"MANAUSD","b":"0.8292","B":"2300.00000000","a":"0.8296","A":"2300.00000000"}}
1628952325.1163478: {"stream":"manausd@depth@100ms","data":{"e":"depthUpdate","E":1628952325164,"s":"MANAUSD","U":108545800,"u":108545805,"b":[["0.8269","1417.65000000"],["0.8268","4571.00000000"],["0.8257","0.00000000"],["0.8228","27.87000000"]],"a":[["0.8296","2300.00000000"]]}}
1628952325.216157: {"stream":"batusd@depth@100ms","data":{"e":"depthUpdate","E":1628952325264,"s":"BATUSD","U":126705906,"u":126705906,"b":[["0.7695","117.90000000"]],"a":[]}}
1628952325.2162938: {"stream":"manausd@depth@100ms","data":{"e":"depthUpdate","E":1628952325264,"s":"MANAUSD","U":108545806,"u":108545806,"b":[["0.8273","1200.00000000"]],"a":[]}}
1628952325.216369: {"stream":"zrxusd@depth@100ms","data":{"e":"depthUpdate","E":1628952325264,"s":"ZRXUSD","U":124790182,"u":124790183,"b":[["1.0490","1133.01000000"],["1.0478","0.00000000"]],"a":[]}}
1628952325.3165052: {"stream":"hntusd@bookTicker","data":{"u":98434236,"s":"HNTUSD","b":"16.5315","B":"24.00000000","a":"16.5708","A":"49.93000000"}}
1628952325.31659: {"stream":"batusd@depth@100ms","data":{"e":"depthUpdate","E":1628952325364,"s":"BATUSD","U":126705907,"u":126705911,"b":[["0.7696","370.00000000"],["0.7695","0.00000000"],["0.7694","0.00000000"]],"a":[["0.7707","726.54000000"]]}}
1628952325.316737: {"stream":"hntusd@depth@100ms","data":{"e":"depthUpdate","E":1628952325364,"s":"HNTUSD","U":98434235,"u":98434236,"b":[],"a":[["16.5708","49.93000000"],["16.5711","0.00000000"]]}}
1628952325.366011: {"stream":"batusd@bookTicker","data":{"u":126705915,"s":"BATUSD","b":"0.7698","B":"726.65000000","a":"0.7706","A":"174.36000000"}}
1628952325.369674: {"stream":"batusd@bookTicker","data":{"u":126705917,"s":"BATUSD","b":"0.7699","B":"370.00000000","a":"0.7706","A":"174.36000000"}}
1628952325.390956: {"stream":"batusd@bookTicker","data":{"u":126705918,"s":"BATUSD","b":"0.7699","B":"370.00000000","a":"0.7707","A":"726.54000000"}}
1628952325.41571: {"stream":"batusd@depth@100ms","data":{"e":"depthUpdate","E":1628952325464,"s":"BATUSD","U":126705912,"u":126705921,"b":[["0.7699","370.00000000"],["0.7696","0.00000000"],["0.7695","119.84000000"],["0.7694","0.00000000"],["0.7685","0.00000000"]],"a":[["0.7706","0.00000000"],["0.7709","0.00000000"],["0.7712","102845.73000000"]]}}
1628952325.4159381: {"stream":"hntusd@depth@100ms","data":{"e":"depthUpdate","E":1628952325464,"s":"HNTUSD","U":98434237,"u":98434238,"b":[],"a":[["16.5710","0.00000000"],["16.5712","13.81000000"]]}}
1628952325.4741771: {"stream":"batusd@bookTicker","data":{"u":126705927,"s":"BATUSD","b":"0.7699","B":"370.00000000","a":"0.7708","A":"380.12000000"}}
1628952325.478397: {"stream":"hntusd@bookTicker","data":{"u":98434240,"s":"HNTUSD","b":"16.5315","B":"24.00000000","a":"16.5707","A":"13.58000000"}}
1628952325.514957: {"stream":"batusd@depth@100ms","data":{"e":"depthUpdate","E":1628952325564,"s":"BATUSD","U":126705922,"u":126705930,"b":[["0.7695","0.00000000"]],"a":[["0.7707","0.00000000"],["0.7709","0.00000000"],["0.7710","512.39000000"],["0.7711","0.00000000"],["0.7713","1947.99000000"],["0.7716","3246.37000000"]]}}
1628952325.515188: {"stream":"manausd@depth@100ms","data":{"e":"depthUpdate","E":1628952325564,"s":"MANAUSD","U":108545807,"u":108545807,"b":[],"a":[["0.8299","1790.75000000"]]}}
1628952325.515263: {"stream":"hntusd@depth@100ms","data":{"e":"depthUpdate","E":1628952325564,"s":"HNTUSD","U":98434239,"u":98434240,"b":[],"a":[["16.5707","13.58000000"],["16.5712","0.00000000"]]}}
1628952325.616309: {"stream":"batusd@depth@100ms","data":{"e":"depthUpdate","E":1628952325664,"s":"BATUSD","U":126705931,"u":126705934,"b":[["0.7696","0.00000000"]],"a":[["0.7710","370.00000000"],["0.7715","3863.31000000"]]}}
1628952325.616467: {"stream":"manausd@depth@100ms","data":{"e":"depthUpdate","E":1628952325664,"s":"MANAUSD","U":108545808,"u":108545808,"b":[["0.8287","0.00000000"]],"a":[]}}
1628952325.716442: {"stream":"batusd@depth@100ms","data":{"e":"depthUpdate","E":1628952325764,"s":"BATUSD","U":126705935,"u":126705939,"b":[["0.7696","143.82000000"]],"a":[["0.7709","148.68000000"],["0.7711","1000.00000000"]]}}
1628952325.8180401: {"stream":"batusd@depth@100ms","data":{"e":"depthUpdate","E":1628952325864,"s":"BATUSD","U":126705940,"u":126705942,"b":[["0.7696","0.00000000"],["0.7693","0.00000000"],["0.7689","172.30000000"]],"a":[]}}
1628952325.8182158: {"stream":"manausd@depth@100ms","data":{"e":"depthUpdate","E":1628952325864,"s":"MANAUSD","U":108545809,"u":108545810,"b":[["0.8281","5077.81000000"],["0.8045","0.00000000"]],"a":[]}}
1628952326.161104: {"stream":"manausd@bookTicker","data":{"u":108545811,"s":"MANAUSD","b":"0.8291","B":"628.09000000","a":"0.8296","A":"2300.00000000"}}
1628952326.17089: {"stream":"manausd@bookTicker","data":{"u":108545813,"s":"MANAUSD","b":"0.8291","B":"628.09000000","a":"0.8296","A":"2980.00000000"}}
1628952326.2172: {"stream":"manausd@depth@100ms","data":{"e":"depthUpdate","E":1628952326265,"s":"MANAUSD","U":108545811,"u":108545813,"b":[["0.8292","0.00000000"],["0.8289","0.00000000"]],"a":[["0.8296","2980.00000000"]]}}
1628952326.317159: {"stream":"batusd@depth@100ms","data":{"e":"depthUpdate","E":1628952326365,"s":"BATUSD","U":126705943,"u":126705944,"b":[["0.7693","931.80000000"],["0.7386","0.00000000"]],"a":[]}}
1628952326.4188569: {"stream":"manausd@depth@100ms","data":{"e":"depthUpdate","E":1628952326465,"s":"MANAUSD","U":108545814,"u":108545814,"b":[["0.8290","2980.00000000"]],"a":[]}}
1628952326.4189959: {"stream":"batusd@bookTicker","data":{"u":126705945,"s":"BATUSD","b":"0.7699","B":"370.00000000","a":"0.7708","A":"750.12000000"}}
1628952326.419041: {"stream":"manausd@bookTicker","data":{"u":108545815,"s":"MANAUSD","b":"0.8290","B":"2980.00000000","a":"0.8296","A":"2980.00000000"}}
1628952326.518112: {"stream":"manausd@depth@100ms","data":{"e":"depthUpdate","E":1628952326565,"s":"MANAUSD","U":108545815,"u":108545815,"b":[["0.8291","0.00000000"]],"a":[]}}
1628952326.518265: {"stream":"batusd@depth@100ms","data":{"e":"depthUpdate","E":1628952326565,"s":"BATUSD","U":126705945,"u":126705948,"b":[["0.7694","150.03000000"],["0.7689","0.00000000"]],"a":[["0.7708","750.12000000"],["0.7710","0.00000000"]]}}
1628952326.559603: {"stream":"manausd@bookTicker","data":{"u":108545816,"s":"MANAUSD","b":"0.8290","B":"2980.00000000","a":"0.8296","A":"2300.00000000"}}
1628952326.559662: {"stream":"manausd@bookTicker","data":{"u":108545817,"s":"MANAUSD","b":"0.8290","B":"2980.00000000","a":"0.8295","A":"680.00000000"}}
1628952326.571213: {"stream":"manausd@bookTicker","data":{"u":108545818,"s":"MANAUSD","b":"0.8290","B":"2980.00000000","a":"0.8294","A":"2300.00000000"}}
1628952326.578478: {"stream":"manausd@bookTicker","data":{"u":108545819,"s":"MANAUSD","b":"0.8290","B":"680.00000000","a":"0.8294","A":"2300.00000000"}}
1628952326.584198: {"stream":"batusd@bookTicker","data":{"u":126705950,"s":"BATUSD","b":"0.7699","B":"370.00000000","a":"0.7707","A":"144.78000000"}}
1628952326.5842829: {"stream":"manausd@bookTicker","data":{"u":108545820,"s":"MANAUSD","b":"0.8284","B":"1791.23000000","a":"0.8294","A":"2300.00000000"}}
1628952326.5861702: {"stream":"manausd@bookTicker","data":{"u":108545821,"s":"MANAUSD","b":"0.8285","B":"680.00000000","a":"0.8294","A":"2300.00000000"}}
1628952326.5969: {"stream":"manausd@bookTicker","data":{"u":108545823,"s":"MANAUSD","b":"0.8285","B":"2980.00000000","a":"0.8294","A":"2300.00000000"}}
1628952326.605673: {"stream":"manausd@bookTicker","data":{"u":108545826,"s":"MANAUSD","b":"0.8287","B":"3617.95000000","a":"0.8294","A":"2300.00000000"}}
1628952326.613211: {"stream":"manausd@bookTicker","data":{"u":108545828,"s":"MANAUSD","b":"0.8288","B":"680.00000000","a":"0.8294","A":"2300.00000000"}}
1628952326.617235: {"stream":"hntusd@depth@100ms","data":{"e":"depthUpdate","E":1628952326665,"s":"HNTUSD","U":98434241,"u":98434241,"b":[["16.5099","0.00000000"]],"a":[]}}
1628952326.617383: {"stream":"batusd@depth@100ms","data":{"e":"depthUpdate","E":1628952326665,"s":"BATUSD","U":126705949,"u":126705950,"b":[],"a":[["0.7707","144.78000000"],["0.7709","0.00000000"]]}}
1628952326.617485: {"stream":"manausd@depth@100ms","data":{"e":"depthUpdate","E":1628952326665,"s":"MANAUSD","U":108545816,"u":108545828,"b":[["0.8290","0.00000000"],["0.8288","680.00000000"],["0.8287","3617.95000000"],["0.8285","2300.00000000"]],"a":[["0.8294","2300.00000000"],["0.8295","680.00000000"],["0.8296","2300.00000000"],["0.8298","3618.46000000"],["0.8300","0.00000000"],["0.8304","3617.95000000"]]}}
1628952326.6176481: {"stream":"manausd@bookTicker","data":{"u":108545829,"s":"MANAUSD","b":"0.8288","B":"2980.00000000","a":"0.8294","A":"2300.00000000"}}
1628952326.717578: {"stream":"manausd@depth@100ms","data":{"e":"depthUpdate","E":1628952326765,"s":"MANAUSD","U":108545829,"u":108545829,"b":[["0.8288","2980.00000000"]],"a":[]}}
1628952326.7177038: {"stream":"hntusd@depth@100ms","data":{"e":"depthUpdate","E":1628952326765,"s":"HNTUSD","U":98434242,"u":98434242,"b":[["16.5029","11.32000000"]],"a":[]}}
1628952326.731675: {"stream":"zrxusd@bookTicker","data":{"u":124790184,"s":"ZRXUSD","b":"1.0549","B":"1420.60000000","a":"1.0566","A":"10950.08000000"}}
1628952326.7455108: {"stream":"manausd@bookTicker","data":{"u":108545830,"s":"MANAUSD","b":"0.8288","B":"680.00000000","a":"0.8294","A":"2300.00000000"}}
1628952326.746753: {"stream":"batusd@bookTicker","data":{"u":126705952,"s":"BATUSD","b":"0.7699","B":"370.00000000","a":"0.7707","A":"514.78000000"}}
1628952326.7537339: {"stream":"zrxusd@bookTicker","data":{"u":124790185,"s":"ZRXUSD","b":"1.0550","B":"562.80000000","a":"1.0566","A":"10950.08000000"}}
1628952326.757419: {"stream":"batusd@bookTicker","data":{"u":126705953,"s":"BATUSD","b":"0.7698","B":"726.65000000","a":"0.7707","A":"514.78000000"}}
1628952326.774215: {"stream":"batusd@bookTicker","data":{"u":126705956,"s":"BATUSD","b":"0.7698","B":"726.65000000","a":"0.7706","A":"370.00000000"}}
1628952326.81175: {"stream":"zrxusd@bookTicker","data":{"u":124790186,"s":"ZRXUSD","b":"1.0549","B":"1420.60000000","a":"1.0566","A":"10950.08000000"}}
1628952326.8172338: {"stream":"manausd@depth@100ms","data":{"e":"depthUpdate","E":1628952326865,"s":"MANAUSD","U":108545830,"u":108545830,"b":[["0.8288","680.00000000"]],"a":[]}}
1628952326.817358: {"stream":"batusd@depth@100ms","data":{"e":"depthUpdate","E":1628952326865,"s":"BATUSD","U":126705951,"u":126705959,"b":[["0.7699","0.00000000"],["0.7695","370.00000000"]],"a":[["0.7706","370.00000000"],["0.7707","0.00000000"],["0.7708","380.12000000"],["0.7710","726.45000000"],["0.7713","0.00000000"]]}}
1628952326.817556: {"stream":"zrxusd@depth@100ms","data":{"e":"depthUpdate","E":1628952326865,"s":"ZRXUSD","U":124790184,"u":124790186,"b":[["1.0550","0.00000000"]],"a":[]}}
1628952326.917572: {"stream":"batusd@depth@100ms","data":{"e":"depthUpdate","E":1628952326965,"s":"BATUSD","U":126705960,"u":126705961,"b":[["0.7694","0.00000000"]],"a":[["0.7707","137.59000000"]]}}
1628952326.917739: {"stream":"zrxusd@depth@100ms","data":{"e":"depthUpdate","E":1628952326965,"s":"ZRXUSD","U":124790187,"u":124790190,"b":[["1.0525","642.00000000"]],"a":[["1.0577","614.55000000"],["1.0578","59.46000000"],["1.0594","3164.61000000"]]}}
1628952326.917855: {"stream":"hntusd@depth@100ms","data":{"e":"depthUpdate","E":1628952326965,"s":"HNTUSD","U":98434243,"u":98434244,"b":[["16.5029","0.00000000"],["16.4995","15.86000000"]],"a":[]}}
1628952326.967634: {"stream":"hntusd@bookTicker","data":{"u":98434245,"s":"HNTUSD","b":"16.5315","B":"24.00000000","a":"16.5707","A":"37.58000000"}}
1628952326.967716: {"stream":"manausd@bookTicker","data":{"u":108545832,"s":"MANAUSD","b":"0.8288","B":"680.00000000","a":"0.8293","A":"680.00000000"}}
1628952326.980577: {"stream":"manausd@bookTicker","data":{"u":108545833,"s":"MANAUSD","b":"0.8288","B":"680.00000000","a":"0.8292","A":"2300.00000000"}}
1628952327.018844: {"stream":"manausd@depth@100ms","data":{"e":"depthUpdate","E":1628952327065,"s":"MANAUSD","U":108545831,"u":108545834,"b":[],"a":[["0.8292","2300.00000000"],["0.8293","680.00000000"],["0.8295","0.00000000"],["0.8296","0.00000000"]]}}
1628952327.018982: {"stream":"batusd@depth@100ms","data":{"e":"depthUpdate","E":1628952327065,"s":"BATUSD","U":126705962,"u":126705965,"b":[["0.7695","0.00000000"],["0.7694","370.00000000"],["0.7689","137.43000000"]],"a":[["0.7715","0.00000000"]]}}
1628952327.01906: {"stream":"zrxusd@depth@100ms","data":{"e":"depthUpdate","E":1628952327065,"s":"ZRXUSD","U":124790191,"u":124790197,"b":[["1.0517","2000.00000000"],["1.0508","0.00000000"]],"a":[["1.0571","0.00000000"],["1.0576","649.36000000"],["1.0577","0.00000000"],["1.0586","2000.00000000"],["1.0594","164.61000000"]]}}
1628952327.019148: {"stream":"hntusd@depth@100ms","data":{"e":"depthUpdate","E":1628952327065,"s":"HNTUSD","U":98434245,"u":98434246,"b":[],"a":[["16.5707","37.58000000"],["16.5713","0.00000000"]]}}
1628952327.028053: {"stream":"manausd@bookTicker","data":{"u":108545835,"s":"MANAUSD","b":"0.8289","B":"2300.00000000","a":"0.8292","A":"2300.00000000"}}
1628952327.046966: {"stream":"hntusd@bookTicker","data":{"u":98434247,"s":"HNTUSD","b":"16.5315","B":"24.00000000","a":"16.5707","A":"13.58000000"}}
1628952327.049101: {"stream":"hntusd@bookTicker","data":{"u":98434249,"s":"HNTUSD","b":"16.5315","B":"24.00000000","a":"16.5706","A":"24.00000000"}}
1628952327.118446: {"stream":"manausd@depth@100ms","data":{"e":"depthUpdate","E":1628952327165,"s":"MANAUSD","U":108545835,"u":108545839,"b":[["0.8289","2300.00000000"],["0.8281","3618.85000000"],["0.8268","0.00000000"],["0.8257","4571.00000000"],["0.8049","5854.64000000"]],"a":[]}}
1628952327.118567: {"stream":"zrxusd@depth@100ms","data":{"e":"depthUpdate","E":1628952327165,"s":"ZRXUSD","U":124790198,"u":124790199,"b":[],"a":[["1.0575","646.75000000"],["1.0576","0.00000000"]]}}
1628952327.118614: {"stream":"hntusd@depth@100ms","data":{"e":"depthUpdate","E":1628952327165,"s":"HNTUSD","U":98434247,"u":98434250,"b":[["16.4995","0.00000000"],["16.4970","13.44000000"]],"a":[["16.5706","24.00000000"],["16.5707","13.58000000"]]}}
1628952327.21793: {"stream":"zrxusd@depth@100ms","data":{"e":"depthUpdate","E":1628952327265,"s":"ZRXUSD","U":124790200,"u":124790205,"b":[["1.0546","562.94000000"],["1.0529","4366.99000000"],["1.0499","3000.00000000"]],"a":[["1.0575","623.14000000"],["1.0604","3000.00000000"]]}}
1628952327.218125: {"stream":"batusd@depth@100ms","data":{"e":"depthUpdate","E":1628952327265,"s":"BATUSD","U":126705966,"u":126705969,"b":[["0.7677","0.00000000"]],"a":[["0.7712","106093.95000000"],["0.7716","0.00000000"],["0.7725","7396.96000000"]]}}
1628952327.317062: {"stream":"batusd@depth@100ms","data":{"e":"depthUpdate","E":1628952327365,"s":"BATUSD","U":126705970,"u":126705971,"b":[["0.7689","0.00000000"],["0.7688","0.00000000"]],"a":[]}}
1628952327.3172202: {"stream":"zrxusd@depth@100ms","data":{"e":"depthUpdate","E":1628952327365,"s":"ZRXUSD","U":124790206,"u":124790208,"b":[["1.0534","0.00000000"]],"a":[["1.0573","627.13000000"],["1.0575","0.00000000"]]}}
1628952327.3744829: {"stream":"batusd@bookTicker","data":{"u":126705973,"s":"BATUSD","b":"0.7694","B":"370.00000000","a":"0.7706","A":"370.00000000"}}
1628952327.418931: {"stream":"batusd@depth@100ms","data":{"e":"depthUpdate","E":1628952327465,"s":"BATUSD","U":126705972,"u":126705974,"b":[["0.7698","0.00000000"],["0.7689","0.00000000"]],"a":[]}}
1628952327.461314: {"stream":"manausd@bookTicker","data":{"u":108545840,"s":"MANAUSD","b":"0.8289","B":"2300.00000000","a":"0.8293","A":"680.00000000"}}
1628952327.475285: {"stream":"manausd@bookTicker","data":{"u":108545842,"s":"MANAUSD","b":"0.8289","B":"2300.00000000","a":"0.8293","A":"2980.00000000"}}
1628952327.517632: {"stream":"batusd@depth@100ms","data":{"e":"depthUpdate","E":1628952327565,"s":"BATUSD","U":126705975,"u":126705978,"b":[["0.7687","1155.41000000"],["0.7672","2500.00000000"]],"a":[["0.7722","2500.00000000"]]}}
1628952327.517802: {"stream":"manausd@depth@100ms","data":{"e":"depthUpdate","E":1628952327565,"s":"MANAUSD","U":108545840,"u":108545842,"b":[],"a":[["0.8292","0.00000000"],["0.8293","2980.00000000"],["0.8294","0.00000000"]]}}
1628952327.5179121: {"stream":"zrxusd@depth@100ms","data":{"e":"depthUpdate","E":1628952327565,"s":"ZRXUSD","U":124790209,"u":124790210,"b":[["1.0546","0.00000000"],["1.0545","0.00000000"]],"a":[]}}
1628952327.529352: {"stream":"manausd@bookTicker","data":{"u":108545843,"s":"MANAUSD","b":"0.8289","B":"2300.00000000","a":"0.8293","A":"2967.82000000"}}
1628952327.529441: {"stream":"manausd@kline_1m","data":{"e":"kline","E":1628952327579,"s":"MANAUSD","k":{"t":1628952300000,"T":1628952359999,"s":"MANAUSD","i":"1m","f":1985493,"L":1985520,"o":"0.8297","c":"0.8293","h":"0.8304","l":"0.8291","v":"3531.87000000","n":28,"x":false,"q":"2931.0642","V":"2065.82000000","Q":"1714.5153","B":"0"}}}
1628952327.5295172: {"stream":"manausd@aggTrade","data":{"e":"aggTrade","E":1628952327578,"s":"MANAUSD","a":1698905,"p":"0.8293","q":"12.18000000","f":1985520,"l":1985520,"T":1628952327578,"m":false,"M":true}}
1628952327.53544: {"stream":"zrxusd@bookTicker","data":{"u":124790211,"s":"ZRXUSD","b":"1.0537","B":"308.74000000","a":"1.0566","A":"10950.08000000"}}
1628952327.57391: {"stream":"zrxusd@bookTicker","data":{"u":124790212,"s":"ZRXUSD","b":"1.0538","B":"563.04000000","a":"1.0566","A":"10950.08000000"}}
1628952327.6179168: {"stream":"manausd@depth@100ms","data":{"e":"depthUpdate","E":1628952327666,"s":"MANAUSD","U":108545843,"u":108545844,"b":[],"a":[["0.8293","2967.82000000"],["0.8312","0.00000000"]]}}
1628952327.6180742: {"stream":"batusd@depth@100ms","data":{"e":"depthUpdate","E":1628952327666,"s":"BATUSD","U":126705979,"u":126705979,"b":[["0.7662","0.00000000"]],"a":[]}}
1628952327.618159: {"stream":"zrxusd@depth@100ms","data":{"e":"depthUpdate","E":1628952327666,"s":"ZRXUSD","U":124790211,"u":124790212,"b":[["1.0549","0.00000000"],["1.0538","563.04000000"]],"a":[]}}
1628952327.7183528: {"stream":"batusd@depth@100ms","data":{"e":"depthUpdate","E":1628952327766,"s":"BATUSD","U":126705980,"u":126705980,"b":[["0.7657","3888.43000000"]],"a":[]}}
1628952327.718476: {"stream":"zrxusd@depth@100ms","data":{"e":"depthUpdate","E":1628952327766,"s":"ZRXUSD","U":124790213,"u":124790213,"b":[],"a":[["1.0574","87.83000000"]]}}
1628952327.71854: {"stream":"manausd@depth@100ms","data":{"e":"depthUpdate","E":1628952327766,"s":"MANAUSD","U":108545845,"u":108545845,"b":[],"a":[["0.8305","2820.90000000"]]}}
1628952327.788961: {"stream":"zrxusd@bookTicker","data":{"u":124790214,"s":"ZRXUSD","b":"1.0538","B":"563.04000000","a":"1.0566","A":"10855.43000000"}}
1628952327.789073: {"stream":"zrxusd@kline_1m","data":{"e":"kline","E":1628952327839,"s":"ZRXUSD","k":{"t":1628952300000,"T":1628952359999,"s":"ZRXUSD","i":"1m","f":967090,"L":967092,"o":"1.0562","c":"1.0566","h":"1.0566","l":"1.0555","v":"246.84000000","n":3,"x":false,"q":"260.7099","V":"94.65000000","Q":"100.0071","B":"0"}}}
1628952327.78912: {"stream":"zrxusd@aggTrade","data":{"e":"aggTrade","E":1628952327838,"s":"ZRXUSD","a":886501,"p":"1.0566","q":"94.65000000","f":967092,"l":967092,"T":1628952327838,"m":false,"M":true}}
1628952327.806658: {"stream":"batusd@bookTicker","data":{"u":126705981,"s":"BATUSD","b":"0.7693","B":"931.80000000","a":"0.7706","A":"370.00000000"}}
1628952327.818774: {"stream":"zrxusd@depth@100ms","data":{"e":"depthUpdate","E":1628952327866,"s":"ZRXUSD","U":124790214,"u":124790215,"b":[["1.0537","0.00000000"]],"a":[["1.0566","10855.43000000"]]}}
1628952327.818932: {"stream":"manausd@depth@100ms","data":{"e":"depthUpdate","E":1628952327866,"s":"MANAUSD","U":108545846,"u":108545849,"b":[["0.8284","0.00000000"],["0.8282","1791.23000000"],["0.8231","149.63000000"],["0.8225","41.20000000"]],"a":[]}}
1628952327.8190389: {"stream":"batusd@depth@100ms","data":{"e":"depthUpdate","E":1628952327866,"s":"BATUSD","U":126705981,"u":126705981,"b":[["0.7694","0.00000000"]],"a":[]}}
1628952327.819082: {"stream":"hntusd@depth@100ms","data":{"e":"depthUpdate","E":1628952327866,"s":"HNTUSD","U":98434251,"u":98434251,"b":[],"a":[["16.5708","0.00000000"]]}}
1628952327.831199: {"stream":"batusd@bookTicker","data":{"u":126705982,"s":"BATUSD","b":"0.7693","B":"931.80000000","a":"0.7700","A":"1086.14000000"}}
1628952327.8941052: {"stream":"hntusd@bookTicker","data":{"u":98434253,"s":"HNTUSD","b":"16.5315","B":"24.00000000","a":"16.5706","A":"38.13000000"}}
1628952327.9181728: {"stream":"batusd@depth@100ms","data":{"e":"depthUpdate","E":1628952327966,"s":"BATUSD","U":126705982,"u":126705982,"b":[],"a":[["0.7700","1086.14000000"]]}}
1628952327.918318: {"stream":"hntusd@depth@100ms","data":{"e":"depthUpdate","E":1628952327966,"s":"HNTUSD","U":98434252,"u":98434253,"b":[],"a":[["16.5706","38.13000000"],["16.5707","0.00000000"]]}}
1628952327.91841: {"stream":"zrxusd@depth@100ms","data":{"e":"depthUpdate","E":1628952327966,"s":"ZRXUSD","U":124790216,"u":124790216,"b":[["1.0536","1027.80000000"]],"a":[]}}
1628952327.941219: {"stream":"hntusd@bookTicker","data":{"u":98434254,"s":"HNTUSD","b":"16.5315","B":"24.00000000","a":"16.5706","A":"24.00000000"}}
1628952327.9874618: {"stream":"batusd@bookTicker","data":{"u":126705985,"s":"BATUSD","b":"0.7687","B":"1155.41000000","a":"0.7700","A":"1086.14000000"}}
1628952327.9875178: {"stream":"batusd@bookTicker","data":{"u":126705987,"s":"BATUSD","b":"0.7688","B":"370.00000000","a":"0.7700","A":"1086.14000000"}}
1628952327.989922: {"stream":"batusd@bookTicker","data":{"u":126705988,"s":"BATUSD","b":"0.7688","B":"370.00000000","a":"0.7699","A":"162.33000000"}}
1628952328.0169961: {"stream":"batusd@depth@100ms","data":{"e":"depthUpdate","E":1628952328066,"s":"BATUSD","U":126705983,"u":126705988,"b":[["0.7693","0.00000000"],["0.7688","370.00000000"],["0.7386","9910.56000000"]],"a":[["0.7699","162.33000000"],["0.7707","0.00000000"],["0.8184","0.00000000"]]}}
1628952328.017148: {"stream":"hntusd@depth@100ms","data":{"e":"depthUpdate","E":1628952328066,"s":"HNTUSD","U":98434254,"u":98434255,"b":[],"a":[["16.5706","24.00000000"],["16.5725","11.98000000"]]}}
1628952328.017204: {"stream":"manausd@depth@100ms","data":{"e":"depthUpdate","E":1628952328066,"s":"MANAUSD","U":108545850,"u":108545851,"b":[["0.8244","255.50000000"]],"a":[["0.8350","12.18000000"]]}}
1628952328.1167822: {"stream":"batusd@depth@100ms","data":{"e":"depthUpdate","E":1628952328166,"s":"BATUSD","U":126705989,"u":126705990,"b":[["0.7687","1000.00000000"],["0.7686","44317.40000000"]],"a":[]}}
1628952328.2182322: {"stream":"manausd@depth@100ms","data":{"e":"depthUpdate","E":1628952328266,"s":"MANAUSD","U":108545852,"u":108545852,"b":[["0.8257","4595.23000000"]],"a":[]}}
1628952328.218358: {"stream":"batusd@depth@100ms","data":{"e":"depthUpdate","E":1628952328266,"s":"BATUSD","U":126705991,"u":126705991,"b":[],"a":[["0.7711","0.00000000"]]}}
1628952328.4177868: {"stream":"zrxusd@depth@100ms","data":{"e":"depthUpdate","E":1628952328466,"s":"ZRXUSD","U":124790217,"u":124790217,"b":[],"a":[["1.0593","427.99000000"]]}}
1628952328.422761: {"stream":"manausd@bookTicker","data":{"u":108545853,"s":"MANAUSD","b":"0.8288","B":"680.00000000","a":"0.8293","A":"2967.82000000"}}
1628952328.518343: {"stream":"manausd@depth@100ms","data":{"e":"depthUpdate","E":1628952328566,"s":"MANAUSD","U":108545853,"u":108545857,"b":[["0.8289","0.00000000"],["0.8287","0.00000000"],["0.8284","3619.29000000"]],"a":[["0.8296","3619.29000000"],["0.8298","0.00000000"]]}}
1628952328.518559: {"stream":"batusd@depth@100ms","data":{"e":"depthUpdate","E":1628952328566,"s":"BATUSD","U":126705992,"u":126705992,"b":[],"a":[["0.7707","1000.00000000"]]}}
1628952328.5257: {"stream":"manausd@bookTicker","data":{"u":108545858,"s":"MANAUSD","b":"0.8285","B":"2300.00000000","a":"0.8293","A":"2967.82000000"}}
1628952328.525782: {"stream":"manausd@bookTicker","data":{"u":108545859,"s":"MANAUSD","b":"0.8286","B":"680.00000000","a":"0.8293","A":"2967.82000000"}}
1628952328.535176: {"stream":"manausd@bookTicker","data":{"u":108545861,"s":"MANAUSD","b":"0.8286","B":"1308.09000000","a":"0.8293","A":"2967.82000000"}}
1628952328.538284: {"stream":"manausd@bookTicker","data":{"u":108545862,"s":"MANAUSD","b":"0.8287","B":"2300.00000000","a":"0.8293","A":"2967.82000000"}}
1628952328.6189928: {"stream":"manausd@depth@100ms","data":{"e":"depthUpdate","E":1628952328666,"s":"MANAUSD","U":108545858,"u":108545862,"b":[["0.8288","0.00000000"],["0.8287","2300.00000000"],["0.8286","1308.09000000"]],"a":[["0.8304","0.00000000"]]}}
1628952328.718462: {"stream":"manausd@depth@100ms","data":{"e":"depthUpdate","E":1628952328766,"s":"MANAUSD","U":108545863,"u":108545863,"b":[["0.8244","316.73000000"]],"a":[]}}
1628952328.818775: {"stream":"zrxusd@depth@100ms","data":{"e":"depthUpdate","E":1628952328866,"s":"ZRXUSD","U":124790218,"u":124790219,"b":[["1.0536","315.42000000"],["1.0208","7067.86000000"]],"a":[]}}
1628952328.917824: {"stream":"zrxusd@depth@100ms","data":{"e":"depthUpdate","E":1628952328966,"s":"ZRXUSD","U":124790220,"u":124790221,"b":[["1.0536","0.00000000"],["1.0530","322.31000000"]],"a":[]}}
1628952329.5196311: {"stream":"manausd@depth@100ms","data":{"e":"depthUpdate","E":1628952329567,"s":"MANAUSD","U":108545864,"u":108545865,"b":[],"a":[["0.8295","1791.42000000"],["0.8299","0.00000000"]]}}
1628952329.519802: {"stream":"hntusd@depth@100ms","data":{"e":"depthUpdate","E":1628952329567,"s":"HNTUSD","U":98434256,"u":98434257,"b":[["16.4970","0.00000000"],["16.4939","11.15000000"]],"a":[]}}
1628952329.522561: {"stream":"batusd@bookTicker","data":{"u":126705993,"s":"BATUSD","b":"0.7688","B":"370.00000000","a":"0.7700","A":"1086.14000000"}}
1628952329.549676: {"stream":"batusd@bookTicker","data":{"u":126705994,"s":"BATUSD","b":"0.7688","B":"370.00000000","a":"0.7700","A":"1223.30000000"}}
1628952329.619298: {"stream":"batusd@depth@100ms","data":{"e":"depthUpdate","E":1628952329667,"s":"BATUSD","U":126705993,"u":126705994,"b":[],"a":[["0.7699","0.00000000"],["0.7700","1223.30000000"]]}}
1628952329.7359328: {"stream":"batusd@bookTicker","data":{"u":126705995,"s":"BATUSD","b":"0.7688","B":"370.00000000","a":"0.7700","A":"1086.14000000"}}
1628952329.8188689: {"stream":"batusd@depth@100ms","data":{"e":"depthUpdate","E":1628952329867,"s":"BATUSD","U":126705995,"u":126705998,"b":[["0.7687","1130.74000000"],["0.7686","44179.43000000"]],"a":[["0.7700","1086.14000000"],["0.7705","135.84000000"]]}}
1628952329.8189812: {"stream":"manausd@depth@100ms","data":{"e":"depthUpdate","E":1628952329867,"s":"MANAUSD","U":108545866,"u":108545866,"b":[],"a":[["0.8301","3619.42000000"]]}}
1628952329.915916: {"stream":"manausd@bookTicker","data":{"u":108545867,"s":"MANAUSD","b":"0.8288","B":"680.00000000","a":"0.8293","A":"2967.82000000"}}
1628952329.920813: {"stream":"manausd@depth@100ms","data":{"e":"depthUpdate","E":1628952329967,"s":"MANAUSD","U":108545867,"u":108545868,"b":[["0.8288","680.00000000"],["0.8286","628.09000000"]],"a":[]}}
1628952329.920958: {"stream":"batusd@depth@100ms","data":{"e":"depthUpdate","E":1628952329967,"s":"BATUSD","U":126705999,"u":126706000,"b":[["0.7687","1137.31000000"]],"a":[]}}
1628952329.926236: {"stream":"manausd@bookTicker","data":{"u":108545869,"s":"MANAUSD","b":"0.8288","B":"680.00000000","a":"0.8293","A":"667.82000000"}}
1628952329.928607: {"stream":"manausd@bookTicker","data":{"u":108545871,"s":"MANAUSD","b":"0.8289","B":"2300.00000000","a":"0.8293","A":"667.82000000"}}
1628952329.932085: {"stream":"manausd@bookTicker","data":{"u":108545873,"s":"MANAUSD","b":"0.8289","B":"2300.00000000","a":"0.8294","A":"680.00000000"}}
1628952330.019584: {"stream":"manausd@depth@100ms","data":{"e":"depthUpdate","E":1628952330067,"s":"MANAUSD","U":108545869,"u":108545873,"b":[["0.8289","2300.00000000"],["0.8285","0.00000000"]],"a":[["0.8293","0.00000000"],["0.8294","680.00000000"]]}}
1628952330.20957: {"stream":"zrxusd@bookTicker","data":{"u":124790223,"s":"ZRXUSD","b":"1.0541","B":"2368.92000000","a":"1.0566","A":"10855.43000000"}}
1628952330.219442: {"stream":"batusd@depth@100ms","data":{"e":"depthUpdate","E":1628952330267,"s":"BATUSD","U":126706001,"u":126706002,"b":[["0.7687","1159.82000000"]],"a":[]}}
1628952330.2195709: {"stream":"zrxusd@depth@100ms","data":{"e":"depthUpdate","E":1628952330267,"s":"ZRXUSD","U":124790222,"u":124790223,"b":[["1.0541","2368.92000000"]],"a":[["1.0573","2995.19000000"]]}}
1628952330.233401: {"stream":"manausd@bookTicker","data":{"u":108545874,"s":"MANAUSD","b":"0.8289","B":"2300.00000000","a":"0.8293","A":"2300.00000000"}}
1628952330.246264: {"stream":"zrxusd@bookTicker","data":{"u":124790225,"s":"ZRXUSD","b":"1.0542","B":"562.90000000","a":"1.0566","A":"10855.43000000"}}
1628952330.320437: {"stream":"manausd@depth@100ms","data":{"e":"depthUpdate","E":1628952330367,"s":"MANAUSD","U":108545874,"u":108545874,"b":[],"a":[["0.8293","2300.00000000"]]}}
1628952330.3205912: {"stream":"zrxusd@depth@100ms","data":{"e":"depthUpdate","E":1628952330367,"s":"ZRXUSD","U":124790224,"u":124790225,"b":[["1.0542","562.90000000"],["1.0538","0.00000000"]],"a":[]}}
1628952330.320673: {"stream":"batusd@depth@100ms","data":{"e":"depthUpdate","E":1628952330367,"s":"BATUSD","U":126706003,"u":126706004,"b":[["0.7687","1169.95000000"]],"a":[]}}
1628952330.420293: {"stream":"batusd@depth@100ms","data":{"e":"depthUpdate","E":1628952330468,"s":"BATUSD","U":126706005,"u":126706005,"b":[["0.7687","1000.00000000"]],"a":[]}}
1628952330.519885: {"stream":"batusd@depth@100ms","data":{"e":"depthUpdate","E":1628952330568,"s":"BATUSD","U":126706006,"u":126706008,"b":[["0.7687","1152.60000000"]],"a":[]}}
1628952330.531399: {"stream":"batusd@bookTicker","data":{"u":126706009,"s":"BATUSD","b":"0.7688","B":"3739.83000000","a":"0.7700","A":"1086.14000000"}}
1628952330.620212: {"stream":"batusd@depth@100ms","data":{"e":"depthUpdate","E":1628952330668,"s":"BATUSD","U":126706009,"u":126706011,"b":[["0.7688","3739.83000000"],["0.7687","1156.15000000"]],"a":[]}}
1628952330.620364: {"stream":"manausd@depth@100ms","data":{"e":"depthUpdate","E":1628952330668,"s":"MANAUSD","U":108545875,"u":108545875,"b":[["0.8286","0.00000000"]],"a":[]}}
1628952330.721803: {"stream":"batusd@depth@100ms","data":{"e":"depthUpdate","E":1628952330768,"s":"BATUSD","U":126706012,"u":126706012,"b":[["0.7687","1000.00000000"]],"a":[]}}
1628952330.821769: {"stream":"batusd@depth@100ms","data":{"e":"depthUpdate","E":1628952330868,"s":"BATUSD","U":126706013,"u":126706015,"b":[["0.7687","1136.50000000"]],"a":[]}}
1628952330.9200058: {"stream":"hntusd@depth@100ms","data":{"e":"depthUpdate","E":1628952330968,"s":"HNTUSD","U":98434258,"u":98434259,"b":[["16.4971","12.58000000"],["16.4939","0.00000000"]],"a":[]}}
1628952330.920192: {"stream":"batusd@depth@100ms","data":{"e":"depthUpdate","E":1628952330968,"s":"BATUSD","U":126706016,"u":126706016,"b":[["0.7687","1000.00000000"]],"a":[]}}
1628952331.020233: {"stream":"batusd@depth@100ms","data":{"e":"depthUpdate","E":1628952331068,"s":"BATUSD","U":126706017,"u":126706017,"b":[["0.7687","1132.54000000"]],"a":[]}}
1628952331.020324: {"stream":"manausd@depth@100ms","data":{"e":"depthUpdate","E":1628952331068,"s":"MANAUSD","U":108545876,"u":108545876,"b":[["0.8237","73.48000000"]],"a":[]}}
1628952331.2206411: {"stream":"manausd@depth@100ms","data":{"e":"depthUpdate","E":1628952331268,"s":"MANAUSD","U":108545877,"u":108545878,"b":[],"a":[["0.8295","0.00000000"],["0.8300","1791.09000000"]]}}
1628952331.333825: {"stream":"batusd@depth@100ms","data":{"e":"depthUpdate","E":1628952331368,"s":"BATUSD","U":126706018,"u":126706018,"b":[["0.7687","1000.00000000"]],"a":[]}}
1628952331.33392: {"stream":"manausd@depth@100ms","data":{"e":"depthUpdate","E":1628952331368,"s":"MANAUSD","U":108545879,"u":108545881,"b":[["0.8285","1791.05000000"],["0.8282","0.00000000"]],"a":[["0.8294","0.00000000"]]}}
1628952331.351647: {"stream":"manausd@bookTicker","data":{"u":108545882,"s":"MANAUSD","b":"0.8289","B":"2300.00000000","a":"0.8296","A":"3619.29000000"}}
1628952331.359276: {"stream":"manausd@bookTicker","data":{"u":108545883,"s":"MANAUSD","b":"0.8289","B":"2300.00000000","a":"0.8295","A":"680.00000000"}}
1628952331.3638458: {"stream":"batusd@bookTicker","data":{"u":126706019,"s":"BATUSD","b":"0.7688","B":"3857.12000000","a":"0.7700","A":"1086.14000000"}}
1628952331.364394: {"stream":"manausd@bookTicker","data":{"u":108545884,"s":"MANAUSD","b":"0.8289","B":"2300.00000000","a":"0.8295","A":"2980.00000000"}}
1628952331.409342: {"stream":"batusd@bookTicker","data":{"u":126706020,"s":"BATUSD","b":"0.7688","B":"3739.83000000","a":"0.7700","A":"1086.14000000"}}
1628952331.420898: {"stream":"manausd@depth@100ms","data":{"e":"depthUpdate","E":1628952331468,"s":"MANAUSD","U":108545882,"u":108545884,"b":[],"a":[["0.8293","0.00000000"],["0.8295","2980.00000000"]]}}
1628952331.421071: {"stream":"batusd@depth@100ms","data":{"e":"depthUpdate","E":1628952331468,"s":"BATUSD","U":126706019,"u":126706020,"b":[["0.7688","3739.83000000"]],"a":[]}}
1628952331.425984: {"stream":"batusd@bookTicker","data":{"u":126706021,"s":"BATUSD","b":"0.7688","B":"3864.81000000","a":"0.7700","A":"1086.14000000"}}
1628952331.458693: {"stream":"batusd@bookTicker","data":{"u":126706022,"s":"BATUSD","b":"0.7688","B":"3739.83000000","a":"0.7700","A":"1086.14000000"}}
1628952331.508783: {"stream":"batusd@bookTicker","data":{"u":126706023,"s":"BATUSD","b":"0.7688","B":"3859.11000000","a":"0.7700","A":"1086.14000000"}}
1628952331.520638: {"stream":"zrxusd@depth@100ms","data":{"e":"depthUpdate","E":1628952331568,"s":"ZRXUSD","U":124790226,"u":124790227,"b":[["1.0536","758.38000000"],["1.0208","0.00000000"]],"a":[]}}
1628952331.5227368: {"stream":"batusd@depth@100ms","data":{"e":"depthUpdate","E":1628952331568,"s":"BATUSD","U":126706021,"u":126706023,"b":[["0.7688","3859.11000000"]],"a":[]}}
1628952331.556957: {"stream":"batusd@bookTicker","data":{"u":126706024,"s":"BATUSD","b":"0.7688","B":"3739.83000000","a":"0.7700","A":"1086.14000000"}}
1628952331.6215522: {"stream":"batusd@depth@100ms","data":{"e":"depthUpdate","E":1628952331668,"s":"BATUSD","U":126706024,"u":126706025,"b":[["0.7688","3739.83000000"],["0.7687","1151.63000000"]],"a":[]}}
1628952331.621687: {"stream":"zrxusd@depth@100ms","data":{"e":"depthUpdate","E":1628952331668,"s":"ZRXUSD","U":124790228,"u":124790229,"b":[["1.0536","1065.68000000"],["1.0530","0.00000000"]],"a":[]}}
1628952331.726725: {"stream":"hntusd@depth@100ms","data":{"e":"depthUpdate","E":1628952331768,"s":"HNTUSD","U":98434260,"u":98434260,"b":[["16.4971","0.00000000"]],"a":[]}}
1628952331.7978728: {"stream":"batusd@bookTicker","data":{"u":126706027,"s":"BATUSD","b":"0.7689","B":"726.97000000","a":"0.7700","A":"1086.14000000"}}
1628952331.806441: {"stream":"batusd@bookTicker","data":{"u":126706029,"s":"BATUSD","b":"0.7690","B":"370.00000000","a":"0.7700","A":"1086.14000000"}}
1628952331.8216152: {"stream":"hntusd@depth@100ms","data":{"e":"depthUpdate","E":1628952331869,"s":"HNTUSD","U":98434261,"u":98434261,"b":[["16.4984","14.60000000"]],"a":[]}}
1628952331.821774: {"stream":"batusd@depth@100ms","data":{"e":"depthUpdate","E":1628952331869,"s":"BATUSD","U":126706026,"u":126706029,"b":[["0.7690","370.00000000"],["0.7689","726.97000000"],["0.7688","3369.83000000"]],"a":[["0.7707","0.00000000"]]}}
1628952331.921201: {"stream":"batusd@depth@100ms","data":{"e":"depthUpdate","E":1628952331969,"s":"BATUSD","U":126706030,"u":126706031,"b":[["0.7688","3490.09000000"],["0.7687","1000.00000000"]],"a":[]}}
1628952332.020946: {"stream":"hntusd@depth@100ms","data":{"e":"depthUpdate","E":1628952332069,"s":"HNTUSD","U":98434262,"u":98434263,"b":[["16.5002","13.27000000"],["16.4984","0.00000000"]],"a":[]}}
1628952332.021112: {"stream":"batusd@depth@100ms","data":{"e":"depthUpdate","E":1628952332069,"s":"BATUSD","U":126706032,"u":126706034,"b":[["0.7688","3369.83000000"],["0.7687","1141.13000000"]],"a":[["0.7710","1726.45000000"]]}}
1628952332.121089: {"stream":"batusd@depth@100ms","data":{"e":"depthUpdate","E":1628952332169,"s":"BATUSD","U":126706035,"u":126706036,"b":[["0.7687","1134.82000000"]],"a":[]}}
1628952332.221071: {"stream":"zrxusd@depth@100ms","data":{"e":"depthUpdate","E":1628952332269,"s":"ZRXUSD","U":124790230,"u":124790230,"b":[],"a":[["1.0568","3013.73000000"]]}}
1628952332.320908: {"stream":"batusd@depth@100ms","data":{"e":"depthUpdate","E":1628952332369,"s":"BATUSD","U":126706037,"u":126706040,"b":[["0.7687","1168.37000000"]],"a":[["0.7704","726.87000000"],["0.7710","1000.00000000"]]}}
1628952332.421333: {"stream":"batusd@depth@100ms","data":{"e":"depthUpdate","E":1628952332469,"s":"BATUSD","U":126706041,"u":126706043,"b":[["0.7688","3483.48000000"],["0.7687","1000.00000000"]],"a":[["0.7705","0.00000000"]]}}
1628952332.521517: {"stream":"batusd@depth@100ms","data":{"e":"depthUpdate","E":1628952332569,"s":"BATUSD","U":126706044,"u":126706046,"b":[["0.7688","3369.83000000"],["0.7687","1165.33000000"]],"a":[["0.7703","163.26000000"]]}}
1628952332.521682: {"stream":"manausd@depth@100ms","data":{"e":"depthUpdate","E":1628952332569,"s":"MANAUSD","U":108545885,"u":108545886,"b":[["0.8278","1457.79000000"],["0.8049","0.00000000"]],"a":[]}}
1628952332.561072: {"stream":"batusd@bookTicker","data":{"u":126706048,"s":"BATUSD","b":"0.7691","B":"726.86000000","a":"0.7700","A":"1086.14000000"}}
1628952332.56982: {"stream":"batusd@bookTicker","data":{"u":126706050,"s":"BATUSD","b":"0.7692","B":"370.00000000","a":"0.7700","A":"1086.14000000"}}
1628952332.62212: {"stream":"batusd@depth@100ms","data":{"e":"depthUpdate","E":1628952332669,"s":"BATUSD","U":126706047,"u":126706052,"b":[["0.7692","370.00000000"],["0.7691","726.86000000"],["0.7690","0.00000000"],["0.7689","0.00000000"],["0.7687","1148.02000000"]],"a":[]}}
1628952332.721905: {"stream":"batusd@depth@100ms","data":{"e":"depthUpdate","E":1628952332769,"s":"BATUSD","U":126706053,"u":126706055,"b":[["0.7688","5319.09000000"],["0.7687","1158.80000000"]],"a":[]}}
1628952332.822098: {"stream":"batusd@depth@100ms","data":{"e":"depthUpdate","E":1628952332869,"s":"BATUSD","U":126706056,"u":126706057,"b":[["0.7688","5431.95000000"],["0.7687","1000.00000000"]],"a":[]}}
1628952332.921351: {"stream":"batusd@depth@100ms","data":{"e":"depthUpdate","E":1628952332969,"s":"BATUSD","U":126706058,"u":126706059,"b":[["0.7688","5432.07000000"]],"a":[]}}
1628952333.021515: {"stream":"batusd@depth@100ms","data":{"e":"depthUpdate","E":1628952333069,"s":"BATUSD","U":126706060,"u":126706061,"b":[["0.7689","151.01000000"],["0.7688","5319.09000000"]],"a":[]}}
1628952333.223928: {"stream":"batusd@bookTicker","data":{"u":126706062,"s":"BATUSD","b":"0.7692","B":"370.00000000","a":"0.7703","A":"163.26000000"}}
1628952333.230657: {"stream":"batusd@bookTicker","data":{"u":126706066,"s":"BATUSD","b":"0.7692","B":"370.00000000","a":"0.7703","A":"1220.60000000"}}
1628952333.230745: {"stream":"batusd@bookTicker","data":{"u":126706067,"s":"BATUSD","b":"0.7692","B":"370.00000000","a":"0.7703","A":"1590.60000000"}}
1628952333.321395: {"stream":"batusd@depth@100ms","data":{"e":"depthUpdate","E":1628952333370,"s":"BATUSD","U":126706062,"u":126706067,"b":[],"a":[["0.7700","0.00000000"],["0.7703","1590.60000000"],["0.7706","0.00000000"],["0.8163","16934.65000000"],["0.8164","0.00000000"]]}}
1628952333.367462: {"stream":"batusd@bookTicker","data":{"u":126706068,"s":"BATUSD","b":"0.7692","B":"370.00000000","a":"0.7703","A":"1427.34000000"}}
1628952333.397526: {"stream":"batusd@bookTicker","data":{"u":126706069,"s":"BATUSD","b":"0.7692","B":"370.00000000","a":"0.7702","A":"138.68000000"}}
1628952333.4221509: {"stream":"batusd@depth@100ms","data":{"e":"depthUpdate","E":1628952333470,"s":"BATUSD","U":126706068,"u":126706069,"b":[],"a":[["0.7702","138.68000000"],["0.7703","1427.34000000"]]}}
1628952333.510981: {"stream":"batusd@bookTicker","data":{"u":126706071,"s":"BATUSD","b":"0.7692","B":"370.00000000","a":"0.7702","A":"508.68000000"}}
1628952333.524006: {"stream":"batusd@depth@100ms","data":{"e":"depthUpdate","E":1628952333570,"s":"BATUSD","U":126706070,"u":126706071,"b":[],"a":[["0.7702","508.68000000"],["0.7703","1057.34000000"]]}}
1628952333.6210291: {"stream":"batusd@depth@100ms","data":{"e":"depthUpdate","E":1628952333670,"s":"BATUSD","U":126706072,"u":126706072,"b":[["0.7689","0.00000000"]],"a":[]}}
1628952333.722395: {"stream":"batusd@depth@100ms","data":{"e":"depthUpdate","E":1628952333770,"s":"BATUSD","U":126706073,"u":126706075,"b":[["0.7688","5484.74000000"],["0.7687","0.00000000"]],"a":[["0.7726","8965.83000000"]]}}
1628952333.822252: {"stream":"batusd@depth@100ms","data":{"e":"depthUpdate","E":1628952333870,"s":"BATUSD","U":126706076,"u":126706078,"b":[["0.7682","1000.00000000"]],"a":[["0.7704","0.00000000"],["0.7707","726.86000000"]]}}
1628952334.023298: {"stream":"batusd@depth@100ms","data":{"e":"depthUpdate","E":1628952334070,"s":"BATUSD","U":126706079,"u":126706079,"b":[],"a":[["0.7734","2005.00000000"]]}}
1628952334.023366: {"stream":"manausd@depth@100ms","data":{"e":"depthUpdate","E":1628952334070,"s":"MANAUSD","U":108545887,"u":108545888,"b":[["0.8286","3618.76000000"],["0.8284","0.00000000"]],"a":[]}}
1628952334.061861: {"stream":"batusd@bookTicker","data":{"u":126706081,"s":"BATUSD","b":"0.7693","B":"726.85000000","a":"0.7702","A":"508.68000000"}}
1628952334.123072: {"stream":"manausd@depth@100ms","data":{"e":"depthUpdate","E":1628952334170,"s":"MANAUSD","U":108545889,"u":108545890,"b":[["0.8287","4090.75000000"],["0.8285","0.00000000"]],"a":[]}}
1628952334.12323: {"stream":"batusd@depth@100ms","data":{"e":"depthUpdate","E":1628952334170,"s":"BATUSD","U":126706080,"u":126706081,"b":[["0.7693","726.85000000"],["0.7691","0.00000000"]],"a":[]}}
1628952334.222616: {"stream":"batusd@depth@100ms","data":{"e":"depthUpdate","E":1628952334270,"s":"BATUSD","U":126706082,"u":126706083,"b":[["0.7692","0.00000000"],["0.7689","370.00000000"]],"a":[]}}
1628952334.423373: {"stream":"batusd@depth@100ms","data":{"e":"depthUpdate","E":1628952334470,"s":"BATUSD","U":126706084,"u":126706087,"b":[["0.7672","0.00000000"]],"a":[["0.7706","726.89000000"],["0.7707","0.00000000"],["0.7722","0.00000000"]]}}
1628952334.4235678: {"stream":"zrxusd@depth@100ms","data":{"e":"depthUpdate","E":1628952334470,"s":"ZRXUSD","U":124790231,"u":124790232,"b":[["1.0536","758.38000000"]],"a":[["1.0573","2368.06000000"]]}}
1628952334.450465: {"stream":"manausd@bookTicker","data":{"u":108545891,"s":"MANAUSD","b":"0.8288","B":"680.00000000","a":"0.8295","A":"2980.00000000"}}
1628952334.521944: {"stream":"manausd@depth@100ms","data":{"e":"depthUpdate","E":1628952334570,"s":"MANAUSD","U":108545891,"u":108545892,"b":[["0.8289","0.00000000"],["0.8287","2300.00000000"]],"a":[]}}
1628952334.522625: {"stream":"hntusd@depth@100ms","data":{"e":"depthUpdate","E":1628952334570,"s":"HNTUSD","U":98434264,"u":98434265,"b":[["16.5002","0.00000000"],["16.4977","14.34000000"]],"a":[]}}
1628952334.522709: {"stream":"zrxusd@depth@100ms","data":{"e":"depthUpdate","E":1628952334570,"s":"ZRXUSD","U":124790233,"u":124790234,"b":[["1.0530","308.67000000"]],"a":[["1.0572","614.02000000"]]}}
1628952334.522763: {"stream":"batusd@depth@100ms","data":{"e":"depthUpdate","E":1628952334570,"s":"BATUSD","U":126706088,"u":126706089,"b":[["0.7671","2500.00000000"]],"a":[["0.7718","5047.20000000"]]}}
1628952334.544888: {"stream":"zrxusd@bookTicker","data":{"u":124790236,"s":"ZRXUSD","b":"1.0541","B":"2368.92000000","a":"1.0566","A":"10855.43000000"}}
1628952334.564173: {"stream":"zrxusd@bookTicker","data":{"u":124790237,"s":"ZRXUSD","b":"1.0542","B":"563.17000000","a":"1.0566","A":"10855.43000000"}}
1628952334.5769222: {"stream":"zrxusd@bookTicker","data":{"u":124790238,"s":"ZRXUSD","b":"1.0541","B":"2368.92000000","a":"1.0566","A":"10855.43000000"}}
1628952334.6230972: {"stream":"zrxusd@depth@100ms","data":{"e":"depthUpdate","E":1628952334670,"s":"ZRXUSD","U":124790235,"u":124790238,"b":[["1.0542","0.00000000"]],"a":[["1.0573","0.00000000"]]}}
1628952334.6236548: {"stream":"batusd@depth@100ms","data":{"e":"depthUpdate","E":1628952334670,"s":"BATUSD","U":126706090,"u":126706090,"b":[["0.7688","5319.09000000"]],"a":[]}}
1628952334.623745: {"stream":"manausd@depth@100ms","data":{"e":"depthUpdate","E":1628952334670,"s":"MANAUSD","U":108545893,"u":108545893,"b":[["0.8282","1791.18000000"]],"a":[]}}
1628952334.6289861: {"stream":"manausd@bookTicker","data":{"u":108545894,"s":"MANAUSD","b":"0.8288","B":"680.00000000","a":"0.8294","A":"724.39000000"}}
1628952334.638926: {"stream":"manausd@bookTicker","data":{"u":108545896,"s":"MANAUSD","b":"0.8288","B":"680.00000000","a":"0.8293","A":"680.00000000"}}
1628952334.641005: {"stream":"manausd@bookTicker","data":{"u":108545897,"s":"MANAUSD","b":"0.8288","B":"680.00000000","a":"0.8293","A":"2980.00000000"}}
1628952334.724352: {"stream":"zrxusd@depth@100ms","data":{"e":"depthUpdate","E":1628952334770,"s":"ZRXUSD","U":124790239,"u":124790240,"b":[],"a":[["1.0571","639.40000000"],["1.0572","0.00000000"]]}}
1628952334.7245162: {"stream":"manausd@depth@100ms","data":{"e":"depthUpdate","E":1628952334770,"s":"MANAUSD","U":108545894,"u":108545897,"b":[],"a":[["0.8293","2980.00000000"],["0.8294","724.39000000"],["0.8295","2300.00000000"]]}}
1628952334.724624: {"stream":"batusd@depth@100ms","data":{"e":"depthUpdate","E":1628952334771,"s":"BATUSD","U":126706091,"u":126706093,"b":[["0.7690","155.15000000"],["0.7685","3248.76000000"]],"a":[["0.7707","1949.56000000"]]}}
1628952334.7370691: {"stream":"batusd@bookTicker","data":{"u":126706095,"s":"BATUSD","b":"0.7693","B":"1096.85000000","a":"0.7702","A":"508.68000000"}}
1628952334.7423968: {"stream":"manausd@bookTicker","data":{"u":108545898,"s":"MANAUSD","b":"0.8289","B":"2300.00000000","a":"0.8293","A":"2980.00000000"}}
1628952334.7968829: {"stream":"zrxusd@bookTicker","data":{"u":124790242,"s":"ZRXUSD","b":"1.0536","B":"758.38000000","a":"1.0566","A":"10855.43000000"}}
1628952334.822755: {"stream":"batusd@depth@100ms","data":{"e":"depthUpdate","E":1628952334871,"s":"BATUSD","U":126706094,"u":126706097,"b":[["0.7693","1096.85000000"],["0.7690","0.00000000"],["0.7689","0.00000000"]],"a":[["0.7710","0.00000000"]]}}
1628952334.823384: {"stream":"manausd@depth@100ms","data":{"e":"depthUpdate","E":1628952334871,"s":"MANAUSD","U":108545898,"u":108545898,"b":[["0.8289","2300.00000000"]],"a":[]}}
1628952334.8235: {"stream":"zrxusd@depth@100ms","data":{"e":"depthUpdate","E":1628952334871,"s":"ZRXUSD","U":124790241,"u":124790243,"b":[["1.0541","0.00000000"]],"a":[["1.0570","611.79000000"],["1.0571","0.00000000"]]}}
1628952334.923031: {"stream":"zrxusd@depth@100ms","data":{"e":"depthUpdate","E":1628952334971,"s":"ZRXUSD","U":124790244,"u":124790248,"b":[["1.0529","0.00000000"],["1.0517","0.00000000"]],"a":[["1.0570","0.00000000"],["1.0573","625.12000000"],["1.0586","0.00000000"]]}}
1628952334.923231: {"stream":"batusd@depth@100ms","data":{"e":"depthUpdate","E":1628952334971,"s":"BATUSD","U":126706098,"u":126706099,"b":[["0.7690","0.00000000"]],"a":[]}}
1628952334.978836: {"stream":"zrxusd@bookTicker","data":{"u":124790250,"s":"ZRXUSD","b":"1.0537","B":"563.13000000","a":"1.0566","A":"10855.43000000"}}
1628952335.0191941: {"stream":"batusd@bookTicker","data":{"u":126706103,"s":"BATUSD","b":"0.7693","B":"726.85000000","a":"0.7702","A":"508.68000000"}}
1628952335.020318: {"stream":"batusd@bookTicker","data":{"u":126706104,"s":"BATUSD","b":"0.7694","B":"370.00000000","a":"0.7702","A":"508.68000000"}}
1628952335.023531: {"stream":"batusd@depth@100ms","data":{"e":"depthUpdate","E":1628952335071,"s":"BATUSD","U":126706100,"u":126706104,"b":[["0.7694","370.00000000"],["0.7693","726.85000000"],["0.7690","0.00000000"]],"a":[["0.7706","1726.89000000"]]}}
1628952335.023645: {"stream":"zrxusd@depth@100ms","data":{"e":"depthUpdate","E":1628952335071,"s":"ZRXUSD","U":124790249,"u":124790251,"b":[["1.0537","563.13000000"],["1.0531","315.86000000"],["1.0530","0.00000000"]],"a":[]}}
1628952335.050334: {"stream":"batusd@bookTicker","data":{"u":126706107,"s":"BATUSD","b":"0.7695","B":"726.91000000","a":"0.7702","A":"508.68000000"}}
1628952335.1241212: {"stream":"zrxusd@depth@100ms","data":{"e":"depthUpdate","E":1628952335171,"s":"ZRXUSD","U":124790252,"u":124790257,"b":[["1.0536","0.00000000"],["1.0532","320.07000000"],["1.0531","0.00000000"],["1.0511","2000.00000000"],["1.0201","7503.09000000"]],"a":[["1.0580","2189.07000000"]]}}
1628952335.124327: {"stream":"batusd@depth@100ms","data":{"e":"depthUpdate","E":1628952335171,"s":"BATUSD","U":126706105,"u":126706108,"b":[["0.7695","726.91000000"],["0.7693","0.00000000"],["0.7690","0.00000000"]],"a":[]}}
1628952335.2235808: {"stream":"zrxusd@depth@100ms","data":{"e":"depthUpdate","E":1628952335271,"s":"ZRXUSD","U":124790258,"u":124790259,"b":[["1.0533","307.06000000"],["1.0532","0.00000000"]],"a":[]}}
1628952335.223757: {"stream":"batusd@depth@100ms","data":{"e":"depthUpdate","E":1628952335271,"s":"BATUSD","U":126706109,"u":126706111,"b":[["0.7694","0.00000000"],["0.7689","506.08000000"]],"a":[]}}
1628952335.323103: {"stream":"zrxusd@depth@100ms","data":{"e":"depthUpdate","E":1628952335371,"s":"ZRXUSD","U":124790260,"u":124790261,"b":[["1.0533","326.27000000"]],"a":[]}}
1628952335.401352: {"stream":"zrxusd@bookTicker","data":{"u":124790263,"s":"ZRXUSD","b":"1.0542","B":"1421.75000000","a":"1.0566","A":"10855.43000000"}}
1628952335.423711: {"stream":"zrxusd@depth@100ms","data":{"e":"depthUpdate","E":1628952335471,"s":"ZRXUSD","U":124790262,"u":124790264,"b":[["1.0542","1421.75000000"],["1.0533","309.62000000"]],"a":[]}}
1628952335.423855: {"stream":"batusd@depth@100ms","data":{"e":"depthUpdate","E":1628952335471,"s":"BATUSD","U":126706112,"u":126706112,"b":[["0.7689","370.00000000"]],"a":[]}}
1628952335.5227818: {"stream":"batusd@depth@100ms","data":{"e":"depthUpdate","E":1628952335571,"s":"BATUSD","U":126706113,"u":126706113,"b":[["0.7687","123.38000000"]],"a":[]}}
1628952335.522923: {"stream":"zrxusd@depth@100ms","data":{"e":"depthUpdate","E":1628952335571,"s":"ZRXUSD","U":124790265,"u":124790266,"b":[["1.0533","322.53000000"]],"a":[]}}
1628952335.6233752: {"stream":"zrxusd@depth@100ms","data":{"e":"depthUpdate","E":1628952335671,"s":"ZRXUSD","U":124790267,"u":124790270,"b":[["1.0533","305.14000000"],["1.0526","0.00000000"],["1.0515","443.00000000"]],"a":[]}}
1628952335.6235409: {"stream":"batusd@depth@100ms","data":{"e":"depthUpdate","E":1628952335671,"s":"BATUSD","U":126706114,"u":126706114,"b":[],"a":[["0.7709","6250.88000000"]]}}
1628952335.660498: {"stream":"zrxusd@bookTicker","data":{"u":124790273,"s":"ZRXUSD","b":"1.0543","B":"563.19000000","a":"1.0566","A":"10855.43000000"}}
1628952335.7234979: {"stream":"zrxusd@depth@100ms","data":{"e":"depthUpdate","E":1628952335771,"s":"ZRXUSD","U":124790271,"u":124790274,"b":[["1.0543","563.19000000"],["1.0537","0.00000000"],["1.0533","321.60000000"]],"a":[]}}
1628952335.824042: {"stream":"zrxusd@depth@100ms","data":{"e":"depthUpdate","E":1628952335871,"s":"ZRXUSD","U":124790275,"u":124790276,"b":[["1.0533","310.97000000"]],"a":[]}}
1628952335.8241658: {"stream":"batusd@depth@100ms","data":{"e":"depthUpdate","E":1628952335871,"s":"BATUSD","U":126706115,"u":126706115,"b":[["0.7682","0.00000000"]],"a":[]}}
1628952335.854845: {"stream":"batusd@bookTicker","data":{"u":126706117,"s":"BATUSD","b":"0.7695","B":"726.91000000","a":"0.7702","A":"1235.71000000"}}
1628952335.9244852: {"stream":"batusd@depth@100ms","data":{"e":"depthUpdate","E":1628952335971,"s":"BATUSD","U":126706116,"u":126706117,"b":[],"a":[["0.7702","1235.71000000"],["0.7706","1000.00000000"]]}}
1628952335.924623: {"stream":"zrxusd@depth@100ms","data":{"e":"depthUpdate","E":1628952335971,"s":"ZRXUSD","U":124790277,"u":124790278,"b":[["1.0533","323.96000000"]],"a":[]}}
1628952335.929893: {"stream":"batusd@bookTicker","data":{"u":126706118,"s":"BATUSD","b":"0.7695","B":"726.91000000","a":"0.7702","A":"1097.03000000"}}
1628952335.978817: {"stream":"batusd@bookTicker","data":{"u":126706120,"s":"BATUSD","b":"0.7695","B":"726.91000000","a":"0.7701","A":"140.89000000"}}
1628952336.021481: {"stream":"zrxusd@depth@100ms","data":{"e":"depthUpdate","E":1628952336071,"s":"ZRXUSD","U":124790279,"u":124790280,"b":[["1.0533","317.59000000"]],"a":[]}}
1628952336.0247612: {"stream":"batusd@depth@100ms","data":{"e":"depthUpdate","E":1628952336071,"s":"BATUSD","U":126706118,"u":126706120,"b":[["0.7686","45179.43000000"]],"a":[["0.7701","140.89000000"],["0.7702","1097.03000000"]]}}
1628952336.0249228: {"stream":"hntusd@depth@100ms","data":{"e":"depthUpdate","E":1628952336071,"s":"HNTUSD","U":98434266,"u":98434266,"b":[["16.4977","0.00000000"]],"a":[]}}
1628952336.123756: {"stream":"zrxusd@depth@100ms","data":{"e":"depthUpdate","E":1628952336171,"s":"ZRXUSD","U":124790281,"u":124790282,"b":[["1.0534","305.91000000"],["1.0533","0.00000000"]],"a":[]}}
1628952336.1238668: {"stream":"hntusd@depth@100ms","data":{"e":"depthUpdate","E":1628952336171,"s":"HNTUSD","U":98434267,"u":98434267,"b":[["16.4955","15.69000000"]],"a":[]}}
1628952336.2232902: {"stream":"manausd@depth@100ms","data":{"e":"depthUpdate","E":1628952336271,"s":"MANAUSD","U":108545899,"u":108545901,"b":[["0.8288","0.00000000"],["0.8264","4571.00000000"],["0.8257","24.23000000"]],"a":[]}}
1628952336.2234619: {"stream":"zrxusd@depth@100ms","data":{"e":"depthUpdate","E":1628952336271,"s":"ZRXUSD","U":124790283,"u":124790284,"b":[["1.0534","323.95000000"]],"a":[]}}
1628952336.3235111: {"stream":"manausd@depth@100ms","data":{"e":"depthUpdate","E":1628952336372,"s":"MANAUSD","U":108545902,"u":108545902,"b":[["0.8287","0.00000000"]],"a":[]}}
1628952336.3236558: {"stream":"zrxusd@depth@100ms","data":{"e":"depthUpdate","E":1628952336372,"s":"ZRXUSD","U":124790285,"u":124790286,"b":[["1.0534","0.00000000"],["1.0528","301.67000000"]],"a":[]}}
1628952336.685772: {"stream":"manausd@bookTicker","data":{"u":108545903,"s":"MANAUSD","b":"0.8289","B":"2300.00000000","a":"0.8293","A":"680.00000000"}}
1628952336.6858292: {"stream":"batusd@depth@100ms","data":{"e":"depthUpdate","E":1628952336672,"s":"BATUSD","U":126706121,"u":126706122,"b":[],"a":[["0.7702","370.00000000"],["0.7705","726.95000000"]]}}
1628952336.6859038: {"stream":"manausd@depth@100ms","data":{"e":"depthUpdate","E":1628952336672,"s":"MANAUSD","U":108545903,"u":108545903,"b":[],"a":[["0.8293","680.00000000"]]}}
1628952336.685942: {"stream":"batusd@bookTicker","data":{"u":126706123,"s":"BATUSD","b":"0.7695","B":"726.91000000","a":"0.7702","A":"370.00000000"}}
1628952336.685963: {"stream":"batusd@bookTicker","data":{"u":126706124,"s":"BATUSD","b":"0.7695","B":"726.91000000","a":"0.7701","A":"149.43000000"}}
1628952336.685979: {"stream":"batusd@bookTicker","data":{"u":126706125,"s":"BATUSD","b":"0.7695","B":"726.91000000","a":"0.7702","A":"370.00000000"}}
1628952336.724736: {"stream":"batusd@depth@100ms","data":{"e":"depthUpdate","E":1628952336772,"s":"BATUSD","U":126706123,"u":126706125,"b":[],"a":[["0.7701","0.00000000"]]}}
1628952336.724879: {"stream":"manausd@depth@100ms","data":{"e":"depthUpdate","E":1628952336772,"s":"MANAUSD","U":108545904,"u":108545904,"b":[],"a":[["0.8294","0.00000000"]]}}
1628952336.732964: {"stream":"manausd@bookTicker","data":{"u":108545906,"s":"MANAUSD","b":"0.8289","B":"2300.00000000","a":"0.8294","A":"680.00000000"}}
1628952336.7337852: {"stream":"batusd@bookTicker","data":{"u":126706126,"s":"BATUSD","b":"0.7695","B":"726.91000000","a":"0.7702","A":"536.85000000"}}
1628952336.823822: {"stream":"manausd@depth@100ms","data":{"e":"depthUpdate","E":1628952336872,"s":"MANAUSD","U":108545905,"u":108545906,"b":[],"a":[["0.8293","0.00000000"],["0.8294","680.00000000"]]}}
1628952336.82399: {"stream":"batusd@depth@100ms","data":{"e":"depthUpdate","E":1628952336872,"s":"BATUSD","U":126706126,"u":126706128,"b":[["0.7688","5485.80000000"],["0.7687","0.00000000"]],"a":[["0.7702","536.85000000"]]}}
1628952336.83265: {"stream":"manausd@bookTicker","data":{"u":108545907,"s":"MANAUSD","b":"0.8289","B":"2300.00000000","a":"0.8293","A":"2300.00000000"}}
1628952336.840408: {"stream":"manausd@bookTicker","data":{"u":108545909,"s":"MANAUSD","b":"0.8289","B":"2300.00000000","a":"0.8292","A":"680.00000000"}}
1628952336.9233558: {"stream":"manausd@depth@100ms","data":{"e":"depthUpdate","E":1628952336972,"s":"MANAUSD","U":108545907,"u":108545909,"b":[],"a":[["0.8292","680.00000000"],["0.8293","2300.00000000"],["0.8294","0.00000000"]]}}
1628952337.023332: {"stream":"manausd@depth@100ms","data":{"e":"depthUpdate","E":1628952337072,"s":"MANAUSD","U":108545910,"u":108545910,"b":[],"a":[["0.8295","0.00000000"]]}}
1628952337.1412852: {"stream":"zrxusd@bookTicker","data":{"u":124790287,"s":"ZRXUSD","b":"1.0542","B":"1421.75000000","a":"1.0566","A":"10855.43000000"}}
1628952337.224669: {"stream":"zrxusd@depth@100ms","data":{"e":"depthUpdate","E":1628952337272,"s":"ZRXUSD","U":124790287,"u":124790289,"b":[["1.0543","0.00000000"],["1.0529","563.23000000"],["1.0527","4141.71000000"]],"a":[]}}
1628952337.22484: {"stream":"batusd@depth@100ms","data":{"e":"depthUpdate","E":1628952337272,"s":"BATUSD","U":126706129,"u":126706129,"b":[["0.7688","5319.09000000"]],"a":[]}}
1628952337.317451: {"stream":"batusd@bookTicker","data":{"u":126706132,"s":"BATUSD","b":"0.7695","B":"726.91000000","a":"0.7702","A":"1263.83000000"}}
1628952337.3242428: {"stream":"zrxusd@depth@100ms","data":{"e":"depthUpdate","E":1628952337372,"s":"ZRXUSD","U":124790290,"u":124790291,"b":[["1.0530","320.94000000"],["1.0528","0.00000000"]],"a":[]}}
1628952337.3244102: {"stream":"manausd@depth@100ms","data":{"e":"depthUpdate","E":1628952337372,"s":"MANAUSD","U":108545911,"u":108545911,"b":[["0.8178","0.00000000"]],"a":[]}}
1628952337.324488: {"stream":"batusd@depth@100ms","data":{"e":"depthUpdate","E":1628952337372,"s":"BATUSD","U":126706130,"u":126706132,"b":[["0.7687","119.15000000"]],"a":[["0.7702","1263.83000000"],["0.7705","0.00000000"]]}}
1628952337.435008: {"stream":"batusd@bookTicker","data":{"u":126706133,"s":"BATUSD","b":"0.7695","B":"726.91000000","a":"0.7702","A":"1096.98000000"}}
1628952337.487293: {"stream":"batusd@bookTicker","data":{"u":126706134,"s":"BATUSD","b":"0.7695","B":"726.91000000","a":"0.7701","A":"154.03000000"}}
1628952337.524792: {"stream":"manausd@depth@100ms","data":{"e":"depthUpdate","E":1628952337572,"s":"MANAUSD","U":108545912,"u":108545912,"b":[],"a":[["0.8305","1620.90000000"]]}}
1628952337.524918: {"stream":"batusd@depth@100ms","data":{"e":"depthUpdate","E":1628952337572,"s":"BATUSD","U":126706133,"u":126706134,"b":[],"a":[["0.7701","154.03000000"],["0.7702","1096.98000000"]]}}
1628952337.575559: {"stream":"manausd@bookTicker","data":{"u":108545915,"s":"MANAUSD","b":"0.8289","B":"2300.00000000","a":"0.8292","A":"2980.00000000"}}
1628952337.6243389: {"stream":"batusd@depth@100ms","data":{"e":"depthUpdate","E":1628952337672,"s":"BATUSD","U":126706135,"u":126706136,"b":[["0.7687","0.00000000"]],"a":[["0.7709","0.00000000"]]}}
1628952337.62445: {"stream":"manausd@depth@100ms","data":{"e":"depthUpdate","E":1628952337672,"s":"MANAUSD","U":108545913,"u":108545915,"b":[],"a":[["0.8292","2980.00000000"],["0.8293","0.00000000"],["0.8309","1698.97000000"]]}}
1628952337.700299: {"stream":"zrxusd@bookTicker","data":{"u":124790293,"s":"ZRXUSD","b":"1.0543","B":"563.20000000","a":"1.0566","A":"10855.43000000"}}
1628952337.7249658: {"stream":"batusd@depth@100ms","data":{"e":"depthUpdate","E":1628952337772,"s":"BATUSD","U":126706137,"u":126706137,"b":[["0.7686","45325.46000000"]],"a":[]}}
1628952337.725097: {"stream":"zrxusd@depth@100ms","data":{"e":"depthUpdate","E":1628952337773,"s":"ZRXUSD","U":124790292,"u":124790294,"b":[["1.0543","563.20000000"],["1.0530","0.00000000"],["1.0529","0.00000000"]],"a":[]}}
1628952337.8241081: {"stream":"zrxusd@depth@100ms","data":{"e":"depthUpdate","E":1628952337873,"s":"ZRXUSD","U":124790295,"u":124790296,"b":[["1.0531","0.00000000"]],"a":[]}}
1628952337.925044: {"stream":"zrxusd@depth@100ms","data":{"e":"depthUpdate","E":1628952337973,"s":"ZRXUSD","U":124790297,"u":124790297,"b":[["1.0528","313.90000000"]],"a":[]}}
1628952338.319532: {"stream":"zrxusd@bookTicker","data":{"u":124790298,"s":"ZRXUSD","b":"1.0542","B":"1421.75000000","a":"1.0566","A":"10855.43000000"}}
1628952338.325144: {"stream":"zrxusd@depth@100ms","data":{"e":"depthUpdate","E":1628952338373,"s":"ZRXUSD","U":124790298,"u":124790298,"b":[["1.0543","0.00000000"]],"a":[]}}
1628952338.4266298: {"stream":"manausd@depth@100ms","data":{"e":"depthUpdate","E":1628952338473,"s":"MANAUSD","U":108545916,"u":108545916,"b":[["0.8174","116.74000000"]],"a":[]}}
1628952338.4267678: {"stream":"zrxusd@depth@100ms","data":{"e":"depthUpdate","E":1628952338473,"s":"ZRXUSD","U":124790299,"u":124790299,"b":[["1.0529","563.23000000"]],"a":[]}}
1628952338.525492: {"stream":"zrxusd@depth@100ms","data":{"e":"depthUpdate","E":1628952338573,"s":"ZRXUSD","U":124790300,"u":124790300,"b":[["1.0528","0.00000000"]],"a":[]}}
1628952338.6272829: {"stream":"batusd@depth@100ms","data":{"e":"depthUpdate","E":1628952338673,"s":"BATUSD","U":126706138,"u":126706138,"b":[["0.7686","45179.43000000"]],"a":[]}}
1628952338.62741: {"stream":"zrxusd@depth@100ms","data":{"e":"depthUpdate","E":1628952338673,"s":"ZRXUSD","U":124790301,"u":124790301,"b":[["1.0530","325.20000000"]],"a":[]}}
1628952338.726193: {"stream":"batusd@depth@100ms","data":{"e":"depthUpdate","E":1628952338773,"s":"BATUSD","U":126706139,"u":126706139,"b":[["0.7687","124.92000000"]],"a":[]}}
1628952338.733929: {"stream":"manausd@bookTicker","data":{"u":108545917,"s":"MANAUSD","b":"0.8286","B":"3618.76000000","a":"0.8292","A":"2980.00000000"}}
1628952338.7414021: {"stream":"manausd@bookTicker","data":{"u":108545918,"s":"MANAUSD","b":"0.8287","B":"724.39000000","a":"0.8292","A":"2980.00000000"}}
1628952338.750241: {"stream":"manausd@bookTicker","data":{"u":108545921,"s":"MANAUSD","b":"0.8287","B":"1404.39000000","a":"0.8292","A":"2980.00000000"}}
1628952338.825492: {"stream":"manausd@depth@100ms","data":{"e":"depthUpdate","E":1628952338873,"s":"MANAUSD","U":108545917,"u":108545921,"b":[["0.8289","0.00000000"],["0.8287","1404.39000000"],["0.8286","3618.76000000"]],"a":[]}}
1628952338.861632: {"stream":"manausd@bookTicker","data":{"u":108545922,"s":"MANAUSD","b":"0.8287","B":"724.39000000","a":"0.8292","A":"2980.00000000"}}
1628952338.925605: {"stream":"zrxusd@depth@100ms","data":{"e":"depthUpdate","E":1628952338973,"s":"ZRXUSD","U":124790302,"u":124790304,"b":[["1.0531","563.23000000"],["1.0530","0.00000000"],["1.0529","0.00000000"]],"a":[]}}
1628952338.9257789: {"stream":"manausd@depth@100ms","data":{"e":"depthUpdate","E":1628952338973,"s":"MANAUSD","U":108545922,"u":108545928,"b":[["0.8287","724.39000000"],["0.8286","0.00000000"],["0.8283","3619.97000000"],["0.8281","0.00000000"],["0.8279","3619.86000000"]],"a":[["0.8295","3619.86000000"],["0.8296","0.00000000"]]}}
1628952339.025852: {"stream":"manausd@depth@100ms","data":{"e":"depthUpdate","E":1628952339073,"s":"MANAUSD","U":108545929,"u":108545932,"b":[["0.8284","680.00000000"],["0.8273","0.00000000"]],"a":[["0.8295","0.00000000"],["0.8301","0.00000000"]]}}
1628952339.025989: {"stream":"zrxusd@depth@100ms","data":{"e":"depthUpdate","E":1628952339073,"s":"ZRXUSD","U":124790305,"u":124790306,"b":[["1.0531","563.23000000"]],"a":[]}}
1628952339.124577: {"stream":"zrxusd@depth@100ms","data":{"e":"depthUpdate","E":1628952339173,"s":"ZRXUSD","U":124790307,"u":124790307,"b":[["1.0532","322.03000000"]],"a":[]}}
1628952339.12466: {"stream":"manausd@depth@100ms","data":{"e":"depthUpdate","E":1628952339173,"s":"MANAUSD","U":108545933,"u":108545933,"b":[["0.8269","2617.65000000"]],"a":[]}}
1628952339.227366: {"stream":"zrxusd@depth@100ms","data":{"e":"depthUpdate","E":1628952339274,"s":"ZRXUSD","U":124790308,"u":124790309,"b":[["1.0535","2370.35000000"]],"a":[["1.0567","3067.27000000"]]}}
1628952339.325505: {"stream":"manausd@depth@100ms","data":{"e":"depthUpdate","E":1628952339374,"s":"MANAUSD","U":108545934,"u":108545934,"b":[],"a":[["0.8410","35.61000000"]]}}
1628952339.386397: {"stream":"manausd@bookTicker","data":{"u":108545935,"s":"MANAUSD","b":"0.8284","B":"680.00000000","a":"0.8292","A":"2980.00000000"}}
1628952339.4173372: {"stream":"zrxusd@bookTicker","data":{"u":124790311,"s":"ZRXUSD","b":"1.0543","B":"563.14000000","a":"1.0566","A":"10855.43000000"}}
1628952339.426063: {"stream":"manausd@depth@100ms","data":{"e":"depthUpdate","E":1628952339474,"s":"MANAUSD","U":108545935,"u":108545935,"b":[["0.8287","0.00000000"]],"a":[]}}
1628952339.426207: {"stream":"zrxusd@depth@100ms","data":{"e":"depthUpdate","E":1628952339474,"s":"ZRXUSD","U":124790310,"u":124790311,"b":[["1.0543","563.14000000"],["1.0531","0.00000000"]],"a":[]}}
1628952339.5262039: {"stream":"manausd@depth@100ms","data":{"e":"depthUpdate","E":1628952339574,"s":"MANAUSD","U":108545936,"u":108545939,"b":[["0.8278","0.00000000"],["0.8047","5080.04000000"]],"a":[["0.8295","1218.60000000"],["0.8851","0.00000000"]]}}
1628952339.5264041: {"stream":"zrxusd@depth@100ms","data":{"e":"depthUpdate","E":1628952339574,"s":"ZRXUSD","U":124790312,"u":124790313,"b":[["1.0533","324.43000000"],["1.0532","0.00000000"]],"a":[]}}
1628952339.6253939: {"stream":"manausd@depth@100ms","data":{"e":"depthUpdate","E":1628952339674,"s":"MANAUSD","U":108545940,"u":108545941,"b":[],"a":[["0.8294","1791.51000000"],["0.8300","0.00000000"]]}}
1628952339.625559: {"stream":"zrxusd@depth@100ms","data":{"e":"depthUpdate","E":1628952339674,"s":"ZRXUSD","U":124790314,"u":124790315,"b":[["1.0534","306.83000000"],["1.0533","0.00000000"]],"a":[]}}
1628952339.725555: {"stream":"zrxusd@depth@100ms","data":{"e":"depthUpdate","E":1628952339774,"s":"ZRXUSD","U":124790316,"u":124790318,"b":[["1.0534","0.00000000"]],"a":[]}}
1628952339.7323148: {"stream":"manausd@bookTicker","data":{"u":108545942,"s":"MANAUSD","b":"0.8285","B":"724.39000000","a":"0.8292","A":"2980.00000000"}}
1628952339.826454: {"stream":"manausd@depth@100ms","data":{"e":"depthUpdate","E":1628952339874,"s":"MANAUSD","U":108545942,"u":108545942,"b":[["0.8285","724.39000000"]],"a":[]}}
1628952339.826591: {"stream":"zrxusd@depth@100ms","data":{"e":"depthUpdate","E":1628952339874,"s":"ZRXUSD","U":124790319,"u":124790319,"b":[["1.0528","318.19000000"]],"a":[]}}
1628952340.026467: {"stream":"manausd@depth@100ms","data":{"e":"depthUpdate","E":1628952340074,"s":"MANAUSD","U":108545943,"u":108545943,"b":[["0.8284","1180.00000000"]],"a":[]}}
1628952340.226655: {"stream":"manausd@depth@100ms","data":{"e":"depthUpdate","E":1628952340274,"s":"MANAUSD","U":108545944,"u":108545944,"b":[],"a":[["0.8309","498.97000000"]]}}
1628952340.308735: {"stream":"manausd@bookTicker","data":{"u":108545945,"s":"MANAUSD","b":"0.8286","B":"2300.00000000","a":"0.8292","A":"2980.00000000"}}
1628952340.326536: {"stream":"manausd@depth@100ms","data":{"e":"depthUpdate","E":1628952340374,"s":"MANAUSD","U":108545945,"u":108545948,"b":[["0.8286","2300.00000000"],["0.8284","680.00000000"],["0.8283","4119.97000000"]],"a":[["0.8405","256.04000000"]]}}
1628952340.3815749: {"stream":"manausd@bookTicker","data":{"u":108545951,"s":"MANAUSD","b":"0.8286","B":"2800.00000000","a":"0.8292","A":"2980.00000000"}}
1628952340.391084: {"stream":"manausd@bookTicker","data":{"u":108545952,"s":"MANAUSD","b":"0.8286","B":"2300.00000000","a":"0.8292","A":"2980.00000000"}}
1628952340.428252: {"stream":"manausd@depth@100ms","data":{"e":"depthUpdate","E":1628952340474,"s":"MANAUSD","U":108545949,"u":108545954,"b":[["0.8286","2300.00000000"],["0.8283","3619.97000000"]],"a":[["0.8294","0.00000000"],["0.8304","2991.35000000"]]}}
1628952340.428434: {"stream":"batusd@depth@100ms","data":{"e":"depthUpdate","E":1628952340474,"s":"BATUSD","U":126706140,"u":126706140,"b":[["0.7687","0.00000000"]],"a":[]}}
1628952340.526463: {"stream":"batusd@depth@100ms","data":{"e":"depthUpdate","E":1628952340574,"s":"BATUSD","U":126706141,"u":126706141,"b":[["0.7686","45290.90000000"]],"a":[]}}
1628952340.624641: {"stream":"manausd@bookTicker","data":{"u":108545958,"s":"MANAUSD","b":"0.8286","B":"2980.00000000","a":"0.8292","A":"2980.00000000"}}
1628952340.626836: {"stream":"manausd@depth@100ms","data":{"e":"depthUpdate","E":1628952340674,"s":"MANAUSD","U":108545955,"u":108545958,"b":[["0.8286","2980.00000000"],["0.8284","0.00000000"]],"a":[["0.8295","0.00000000"],["0.8845","5653.45000000"]]}}
1628952340.626959: {"stream":"batusd@depth@100ms","data":{"e":"depthUpdate","E":1628952340674,"s":"BATUSD","U":126706142,"u":126706144,"b":[],"a":[["0.7705","1949.87000000"],["0.7707","5549.74000000"]]}}
1628952340.826448: {"stream":"manausd@depth@100ms","data":{"e":"depthUpdate","E":1628952340875,"s":"MANAUSD","U":108545959,"u":108545960,"b":[],"a":[["0.8293","3620.36000000"],["0.8298","3620.36000000"]]}}
1628952340.826605: {"stream":"batusd@depth@100ms","data":{"e":"depthUpdate","E":1628952340875,"s":"BATUSD","U":126706145,"u":126706145,"b":[],"a":[["0.7706","0.00000000"]]}}
1628952341.127116: {"stream":"batusd@depth@100ms","data":{"e":"depthUpdate","E":1628952341175,"s":"BATUSD","U":126706146,"u":126706146,"b":[],"a":[["0.7705","2949.87000000"]]}}
1628952341.167993: {"stream":"zrxusd@bookTicker","data":{"u":124790320,"s":"ZRXUSD","b":"1.0543","B":"563.14000000","a":"1.0563","A":"1421.62000000"}}
1628952341.2127948: {"stream":"zrxusd@bookTicker","data":{"u":124790323,"s":"ZRXUSD","b":"1.0543","B":"563.14000000","a":"1.0562","A":"563.13000000"}}
1628952341.226977: {"stream":"batusd@depth@100ms","data":{"e":"depthUpdate","E":1628952341275,"s":"BATUSD","U":126706147,"u":126706151,"b":[["0.7688","3369.83000000"],["0.7685","0.00000000"],["0.7684","1949.99000000"]],"a":[["0.7707","8799.73000000"],["0.7712","102845.73000000"]]}}
1628952341.2271621: {"stream":"zrxusd@depth@100ms","data":{"e":"depthUpdate","E":1628952341275,"s":"ZRXUSD","U":124790320,"u":124790323,"b":[],"a":[["1.0562","563.13000000"],["1.0563","1421.62000000"],["1.0566","10387.45000000"],["1.0573","0.00000000"]]}}
1628952341.260287: {"stream":"batusd@bookTicker","data":{"u":126706154,"s":"BATUSD","b":"0.7695","B":"726.91000000","a":"0.7700","A":"370.00000000"}}
1628952341.327125: {"stream":"zrxusd@depth@100ms","data":{"e":"depthUpdate","E":1628952341375,"s":"ZRXUSD","U":124790324,"u":124790325,"b":[],"a":[["1.0572","0.00000000"]]}}
1628952341.327196: {"stream":"batusd@depth@100ms","data":{"e":"depthUpdate","E":1628952341375,"s":"BATUSD","U":126706152,"u":126706155,"b":[["0.7688","0.00000000"],["0.7686","44290.90000000"]],"a":[["0.7700","370.00000000"],["0.7702","726.98000000"]]}}
1628952341.425844: {"stream":"zrxusd@depth@100ms","data":{"e":"depthUpdate","E":1628952341475,"s":"ZRXUSD","U":124790326,"u":124790326,"b":[],"a":[["1.0569","608.47000000"]]}}
1628952341.425982: {"stream":"batusd@depth@100ms","data":{"e":"depthUpdate","E":1628952341475,"s":"BATUSD","U":126706156,"u":126706158,"b":[["0.7689","0.00000000"],["0.7687","370.00000000"],["0.7686","111.47000000"]],"a":[]}}
1628952341.51761: {"stream":"manausd@bookTicker","data":{"u":108545961,"s":"MANAUSD","b":"0.8286","B":"2999.91000000","a":"0.8292","A":"2980.00000000"}}
1628952341.52686: {"stream":"batusd@depth@100ms","data":{"e":"depthUpdate","E":1628952341575,"s":"BATUSD","U":126706159,"u":126706160,"b":[["0.7686","0.00000000"],["0.7684","2949.99000000"]],"a":[]}}
1628952341.527012: {"stream":"hntusd@depth@100ms","data":{"e":"depthUpdate","E":1628952341575,"s":"HNTUSD","U":98434268,"u":98434269,"b":[["16.4955","0.00000000"],["16.4929","12.44000000"]],"a":[]}}
1628952341.527107: {"stream":"manausd@depth@100ms","data":{"e":"depthUpdate","E":1628952341575,"s":"MANAUSD","U":108545961,"u":108545963,"b":[["0.8286","2999.91000000"],["0.8284","19.91000000"],["0.8282","1811.10000000"]],"a":[]}}
1628952341.6271071: {"stream":"batusd@depth@100ms","data":{"e":"depthUpdate","E":1628952341675,"s":"BATUSD","U":126706161,"u":126706167,"b":[["0.7687","0.00000000"],["0.7686","0.00000000"],["0.7685","370.00000000"],["0.7671","0.00000000"]],"a":[["0.7718","2547.20000000"],["0.7725","3646.96000000"]]}}
1628952341.727714: {"stream":"batusd@depth@100ms","data":{"e":"depthUpdate","E":1628952341775,"s":"BATUSD","U":126706168,"u":126706168,"b":[["0.7686","175.31000000"]],"a":[]}}
1628952341.8133278: {"stream":"batusd@bookTicker","data":{"u":126706175,"s":"BATUSD","b":"0.7687","B":"370.00000000","a":"0.7700","A":"370.00000000"}}
1628952341.827936: {"stream":"batusd@depth@100ms","data":{"e":"depthUpdate","E":1628952341875,"s":"BATUSD","U":126706169,"u":126706177,"b":[["0.7695","0.00000000"],["0.7687","370.00000000"],["0.7686","123.94000000"],["0.7685","0.00000000"],["0.7668","3621.59000000"]],"a":[["0.7705","1000.00000000"],["0.7711","2500.00000000"],["0.7718","6297.20000000"]]}}
1628952341.828174: {"stream":"manausd@depth@100ms","data":{"e":"depthUpdate","E":1628952341875,"s":"MANAUSD","U":108545964,"u":108545964,"b":[["0.8285","0.00000000"]],"a":[]}}
1628952341.834466: {"stream":"batusd@bookTicker","data":{"u":126706179,"s":"BATUSD","b":"0.7688","B":"727.10000000","a":"0.7700","A":"370.00000000"}}
1628952341.842528: {"stream":"batusd@bookTicker","data":{"u":126706181,"s":"BATUSD","b":"0.7689","B":"370.00000000","a":"0.7700","A":"370.00000000"}}
1628952341.927336: {"stream":"batusd@depth@100ms","data":{"e":"depthUpdate","E":1628952341975,"s":"BATUSD","U":126706178,"u":126706182,"b":[["0.7689","370.00000000"],["0.7688","727.10000000"],["0.7687","0.00000000"],["0.7686","0.00000000"]],"a":[["0.7703","3007.70000000"]]}}
1628952342.027311: {"stream":"batusd@depth@100ms","data":{"e":"depthUpdate","E":1628952342075,"s":"BATUSD","U":126706183,"u":126706185,"b":[["0.7686","0.00000000"],["0.7685","144.44000000"]],"a":[]}}
1628952342.363521: {"stream":"batusd@bookTicker","data":{"u":126706187,"s":"BATUSD","b":"0.7690","B":"727.11000000","a":"0.7700","A":"370.00000000"}}
1628952342.427566: {"stream":"batusd@depth@100ms","data":{"e":"depthUpdate","E":1628952342476,"s":"BATUSD","U":126706186,"u":126706188,"b":[["0.7690","727.11000000"],["0.7688","0.00000000"],["0.7679","44179.43000000"]],"a":[]}}
1628952342.527494: {"stream":"batusd@depth@100ms","data":{"e":"depthUpdate","E":1628952342576,"s":"BATUSD","U":126706189,"u":126706190,"b":[["0.7689","0.00000000"],["0.7686","370.00000000"]],"a":[]}}
1628952342.628591: {"stream":"manausd@depth@100ms","data":{"e":"depthUpdate","E":1628952342676,"s":"MANAUSD","U":108545965,"u":108545966,"b":[],"a":[["0.8297","1791.34000000"],["0.8304","1200.00000000"]]}}
1628952342.628741: {"stream":"batusd@depth@100ms","data":{"e":"depthUpdate","E":1628952342676,"s":"BATUSD","U":126706191,"u":126706192,"b":[["0.7686","501.28000000"],["0.7685","0.00000000"]],"a":[]}}
1628952343.328214: {"stream":"manausd@depth@100ms","data":{"e":"depthUpdate","E":1628952343376,"s":"MANAUSD","U":108545967,"u":108545967,"b":[["0.8282","1791.18000000"]],"a":[]}}
1628952343.41754: {"stream":"manausd@kline_1m","data":{"e":"kline","E":1628952343466,"s":"MANAUSD","k":{"t":1628952300000,"T":1628952359999,"s":"MANAUSD","i":"1m","f":1985493,"L":1985521,"o":"0.8297","c":"0.8292","h":"0.8304","l":"0.8291","v":"3551.79000000","n":29,"x":false,"q":"2947.5818","V":"2085.74000000","Q":"1731.0329","B":"0"}}}
1628952343.41765: {"stream":"manausd@aggTrade","data":{"e":"aggTrade","E":1628952343466,"s":"MANAUSD","a":1698906,"p":"0.8292","q":"19.92000000","f":1985521,"l":1985521,"T":1628952343465,"m":false,"M":true}}
1628952343.417699: {"stream":"manausd@bookTicker","data":{"u":108545968,"s":"MANAUSD","b":"0.8286","B":"2999.91000000","a":"0.8292","A":"2960.08000000"}}
1628952343.425904: {"stream":"manausd@bookTicker","data":{"u":108545969,"s":"MANAUSD","b":"0.8287","B":"500.00000000","a":"0.8292","A":"2960.08000000"}}
1628952343.428022: {"stream":"manausd@depth@100ms","data":{"e":"depthUpdate","E":1628952343476,"s":"MANAUSD","U":108545968,"u":108545969,"b":[["0.8287","500.00000000"]],"a":[["0.8292","2960.08000000"]]}}
1628952343.557632: {"stream":"manausd@bookTicker","data":{"u":108545970,"s":"MANAUSD","b":"0.8286","B":"2999.91000000","a":"0.8292","A":"2960.08000000"}}
1628952343.557717: {"stream":"manausd@bookTicker","data":{"u":108545971,"s":"MANAUSD","b":"0.8286","B":"3499.91000000","a":"0.8292","A":"2960.08000000"}}
1628952343.628109: {"stream":"batusd@depth@100ms","data":{"e":"depthUpdate","E":1628952343676,"s":"BATUSD","U":126706193,"u":126706194,"b":[["0.7684","1949.99000000"]],"a":[["0.7705","0.00000000"]]}}
1628952343.6282701: {"stream":"manausd@depth@100ms","data":{"e":"depthUpdate","E":1628952343676,"s":"MANAUSD","U":108545970,"u":108545971,"b":[["0.8287","0.00000000"],["0.8286","3499.91000000"]],"a":[]}}
1628952343.828604: {"stream":"manausd@depth@100ms","data":{"e":"depthUpdate","E":1628952343877,"s":"MANAUSD","U":108545972,"u":108545973,"b":[["0.8284","1811.26000000"],["0.8282","0.00000000"]],"a":[]}}
1628952343.913141: {"stream":"manausd@bookTicker","data":{"u":108545974,"s":"MANAUSD","b":"0.8286","B":"2999.91000000","a":"0.8292","A":"2960.08000000"}}
1628952343.9280372: {"stream":"batusd@depth@100ms","data":{"e":"depthUpdate","E":1628952343977,"s":"BATUSD","U":126706195,"u":126706196,"b":[["0.7680","1970.01000000"]],"a":[["0.7702","1726.98000000"]]}}
1628952343.928133: {"stream":"manausd@depth@100ms","data":{"e":"depthUpdate","E":1628952343977,"s":"MANAUSD","U":108545974,"u":108545974,"b":[["0.8286","2999.91000000"]],"a":[]}}
1628952344.12894: {"stream":"batusd@depth@100ms","data":{"e":"depthUpdate","E":1628952344177,"s":"BATUSD","U":126706197,"u":126706197,"b":[["0.7687","5197.52000000"]],"a":[]}}
1628952344.150883: {"stream":"batusd@bookTicker","data":{"u":126706199,"s":"BATUSD","b":"0.7690","B":"1097.11000000","a":"0.7700","A":"370.00000000"}}
1628952344.229974: {"stream":"batusd@depth@100ms","data":{"e":"depthUpdate","E":1628952344277,"s":"BATUSD","U":126706198,"u":126706201,"b":[["0.7690","1097.11000000"],["0.7686","167.92000000"]],"a":[]}}
1628952344.328844: {"stream":"batusd@depth@100ms","data":{"e":"depthUpdate","E":1628952344377,"s":"BATUSD","U":126706202,"u":126706203,"b":[["0.7686","160.70000000"]],"a":[]}}
1628952344.430166: {"stream":"batusd@depth@100ms","data":{"e":"depthUpdate","E":1628952344477,"s":"BATUSD","U":126706204,"u":126706205,"b":[["0.7686","156.92000000"]],"a":[]}}
1628952344.529498: {"stream":"batusd@depth@100ms","data":{"e":"depthUpdate","E":1628952344577,"s":"BATUSD","U":126706206,"u":126706207,"b":[["0.7686","112.76000000"]],"a":[]}}
1628952344.62972: {"stream":"batusd@depth@100ms","data":{"e":"depthUpdate","E":1628952344677,"s":"BATUSD","U":126706208,"u":126706209,"b":[["0.7686","152.05000000"]],"a":[]}}

