1626916419.332675: {"stream":"xrpusd_perp@depth@100ms","data":{"e":"depthUpdate","E":1626916419358,"T":1626916419328,"s":"XRPUSD_PERP","ps":"XRPUSD","U":167006185560,"u":167006186113,"pu":167006185452,"b":[["0.5626","1763"],["0.5645","4191"],["0.5658","3141"]],"a":[["0.5664","5337"],["0.5665","5530"],["0.5667","1192"],["0.5672","1642"],["0.5673","6182"],["0.5674","15406"],["0.5682","36596"],["0.5687","25"],["0.5703","0"]]}}
1626916419.3384268: {"stream":"linkusd_211231@depth@100ms","data":{"e":"depthUpdate","E":1626916419366,"T":1626916419323,"s":"LINKUSD_211231","ps":"LINKUSD","U":167006185630,"u":167006186081,"pu":167006185342,"b":[["15.211","169"],["15.260","0"],["15.261","0"],["15.307","0"]],"a":[["15.366","202"],["15.368","29"],["15.377","0"],["15.419","0"]]}}
1626916419.3418298: {"stream":"ethusd_210924@depth@100ms","data":{"e":"depthUpdate","E":1626916419368,"T":1626916419351,"s":"ETHUSD_210924","ps":"ETHUSD","U":167006185679,"u":167006186211,"pu":167006185552,"b":[["1967.21","4203"],["1988.89","12308"],["1989.04","343"],["1990.46","0"],["1990.75","270"],["1990.76","263"]],"a":[["1992.15","2316"],["1993.40","121"],["2019.13","0"],["2145.08","0"]]}}
1626916419.3451252: {"stream":"etcusd_perp@depth@100ms","data":{"e":"depthUpdate","E":1626916419373,"T":1626916419360,"s":"ETCUSD_PERP","ps":"ETCUSD","U":167006185748,"u":167006186238,"pu":167006185516,"b":[["42.194","0"],["42.224","664"],["42.225","1603"],["42.237","887"]],"a":[["42.267","90"],["42.277","72"],["42.298","0"],["42.306","100"],["42.309","0"],["42.314","200"],["42.324","0"]]}}
1626916419.3474061: {"stream":"linkusd_perp@depth@100ms","data":{"e":"depthUpdate","E":1626916419375,"T":1626916419349,"s":"LINKUSD_PERP","ps":"LINKUSD","U":167006185777,"u":167006186204,"pu":167006185656,"b":[["15.058","20"],["15.059","0"],["15.060","254"]],"a":[["15.072","1093"],["15.073","1105"],["15.076","424"]]}}
1626916419.356559: {"stream":"trxusd_perp@depth@100ms","data":{"e":"depthUpdate","E":1626916419383,"T":1626916419277,"s":"TRXUSD_PERP","ps":"TRXUSD","U":167006185830,"u":167006185834,"pu":167006184655,"b":[["0.05306","943"],["0.05324","956"]],"a":[["0.05346","2229"],["0.05361","169"],["0.05379","521"]]}}
1626916419.420774: {"stream":"bchusd_perp@depth@100ms","data":{"e":"depthUpdate","E":1626916419449,"T":1626916419425,"s":"BCHUSD_PERP","ps":"BCHUSD","U":167006186187,"u":167006186447,"pu":167006185924,"b":[["427.77","175"]],"a":[["427.81","100"],["427.88","0"]]}}
1626916419.4243891: {"stream":"btcusd_211231@depth@100ms","data":{"e":"depthUpdate","E":1626916419452,"T":1626916419419,"s":"BTCUSD_211231","ps":"BTCUSD","U":167006186196,"u":167006186425,"pu":167006185986,"b":[["27403.6","546"]],"a":[["32625.1","12"],["32631.9","46"],["32632.8","153"],["32632.9","0"],["32633.8","0"]]}}
1626916419.453523: {"stream":"ethusd_210924@depth@100ms","data":{"e":"depthUpdate","E":1626916419480,"T":1626916419473,"s":"ETHUSD_210924","ps":"ETHUSD","U":167006186295,"u":167006186666,"pu":167006186211,"b":[["1990.75","0"],["1990.77","270"],["1990.98","1015"]],"a":[["1991.14","500"],["1992.50","50"],["2143.53","5304"],["2145.09","0"]]}}
1626916419.453942: {"stream":"etcusd_perp@depth@100ms","data":{"e":"depthUpdate","E":1626916419483,"T":1626916419471,"s":"ETCUSD_PERP","ps":"ETCUSD","U":167006186298,"u":167006186661,"pu":167006186238,"b":[["42.152","0"],["42.202","256"]],"a":[["42.289","1033"],["42.294","0"],["42.297","0"],["42.306","56"],["42.314","400"],["42.349","0"],["42.368","900"]]}}
1626916419.475899: {"stream":"eosusd_perp@depth@100ms","data":{"e":"depthUpdate","E":1626916419503,"T":1626916419487,"s":"EOSUSD_PERP","ps":"EOSUSD","U":167006186377,"u":167006186753,"pu":167006185521,"b":[["3.462","5477"],["3.468","0"]],"a":[["3.489","4177"]]}}
1626916419.488958: {"stream":"xrpusd_perp@depth@100ms","data":{"e":"depthUpdate","E":1626916419514,"T":1626916419489,"s":"XRPUSD_PERP","ps":"XRPUSD","U":167006186403,"u":167006186760,"pu":167006186113,"b":[["0.5658","3099"],["0.5659","1576"],["0.5661","6656"]],"a":[["0.5682","35960"],["0.5683","2358"]]}}
1626916419.5313869: {"stream":"btcusd_211231@depth@100ms","data":{"e":"depthUpdate","E":1626916419560,"T":1626916419488,"s":"BTCUSD_211231","ps":"BTCUSD","U":167006186585,"u":167006186758,"pu":167006186425,"b":[],"a":[["32625.1","13"],["32631.3","46"],["32631.8","153"],["32631.9","0"],["32632.8","0"]]}}
1626916419.5527449: {"stream":"linkusd_perp@depth@100ms","data":{"e":"depthUpdate","E":1626916419579,"T":1626916419568,"s":"LINKUSD_PERP","ps":"LINKUSD","U":167006186671,"u":167006187309,"pu":167006186204,"b":[["15.050","460"],["15.052","651"],["15.054","100"],["15.055","1195"],["15.056","1562"],["15.057","939"],["15.058","766"],["15.059","375"],["15.060","101"],["15.061","410"],["15.062","62"],["15.063","250"],["15.064","100"],["15.065","74"],["15.066","0"]],"a":[["15.064","0"],["15.066","0"],["15.067","190"],["15.068","100"],["15.069","359"],["15.071","428"],["15.073","1405"],["15.075","564"],["15.077","849"]]}}
1626916419.5614982: {"stream":"etcusd_perp@depth@100ms","data":{"e":"depthUpdate","E":1626916419588,"T":1626916419567,"s":"ETCUSD_PERP","ps":"ETCUSD","U":167006186719,"u":167006187306,"pu":167006186661,"b":[["42.000","165"],["42.161","145"],["42.202","56"],["42.204","323"],["42.210","1637"]],"a":[["42.295","0"],["42.305","56"],["42.310","679"],["42.315","437"]]}}
1626916419.565202: {"stream":"bchusd_210924@depth@100ms","data":{"e":"depthUpdate","E":1626916419590,"T":1626916419515,"s":"BCHUSD_210924","ps":"BCHUSD","U":167006186733,"u":167006186962,"pu":167006184842,"b":[],"a":[["1335.71","9415"],["1335.81","0"]]}}
1626916419.567467: {"stream":"ethusd_210924@depth@100ms","data":{"e":"depthUpdate","E":1626916419592,"T":1626916419584,"s":"ETHUSD_210924","ps":"ETHUSD","U":167006186745,"u":167006187405,"pu":167006186666,"b":[["1982.05","0"],["1988.47","0"],["1988.49","565"],["1988.85","405"],["1989.77","0"],["1990.07","0"],["1990.11","1556"],["1990.74","0"]],"a":[["1991.53","0"],["1992.50","0"],["1994.84","565"],["1995.14","0"],["1995.60","0"],["1997.70","190"],["1999.92","0"],["2023.38","0"],["2033.30","0"],["2043.22","0"],["2053.13","0"],["2063.05","0"]]}}
1626916419.5750668: {"stream":"linkusd_211231@depth@100ms","data":{"e":"depthUpdate","E":1626916419602,"T":1626916419574,"s":"LINKUSD_211231","ps":"LINKUSD","U":167006186821,"u":167006187342,"pu":167006186081,"b":[["14.761","100"],["14.837","100"],["14.912","100"],["14.987","100"],["15.063","100"],["15.289","0"],["15.292","43"],["15.294","1258"],["15.295","0"],["15.296","123"]],"a":[["15.340","0"],["15.343","70"]]}}
1626916419.590283: {"stream":"eosusd_perp@depth@100ms","data":{"e":"depthUpdate","E":1626916419617,"T":1626916419603,"s":"EOSUSD_PERP","ps":"EOSUSD","U":167006186956,"u":167006187488,"pu":167006186753,"b":[["3.468","0"]],"a":[["3.489","4378"]]}}
1626916419.590842: {"stream":"bchusd_perp@depth@100ms","data":{"e":"depthUpdate","E":1626916419618,"T":1626916419597,"s":"BCHUSD_PERP","ps":"BCHUSD","U":167006186960,"u":167006187454,"pu":167006186447,"b":[["426.39","0"]],"a":[["427.81","0"],["427.88","100"],["429.16","0"],["439.04","0"]]}}
1626916419.594748: {"stream":"trxusd_perp@depth@100ms","data":{"e":"depthUpdate","E":1626916419622,"T":1626916419537,"s":"TRXUSD_PERP","ps":"TRXUSD","U":167006186989,"u":167006187143,"pu":167006185834,"b":[["0.05338","183"],["0.05341","2122"],["0.05343","1470"]],"a":[]}}
1626916419.642365: {"stream":"xrpusd_perp@depth@100ms","data":{"e":"depthUpdate","E":1626916419670,"T":1626916419665,"s":"XRPUSD_PERP","ps":"XRPUSD","U":167006187292,"u":167006187859,"pu":167006186760,"b":[["0.5653","5053"],["0.5659","1716"],["0.5661","6816"]],"a":[["0.5667","1192"],["0.5674","15420"]]}}
1626916419.653418: {"stream":"linkusd_perp@depth@100ms","data":{"e":"depthUpdate","E":1626916419679,"T":1626916419674,"s":"LINKUSD_PERP","ps":"LINKUSD","U":167006187345,"u":167006187960,"pu":167006187309,"b":[["15.033","15615"],["15.037","2970"],["15.041","575"],["15.044","892"],["15.047","3447"],["15.049","0"],["15.050","260"],["15.052","280"],["15.053","3279"],["15.054","0"],["15.055","1195"],["15.056","1662"],["15.057","959"],["15.058","1146"],["15.061","300"],["15.062","62"],["15.063","402"],["15.064","100"],["15.066","110"]],"a":[["15.069","150"],["15.071","279"],["15.072","193"],["15.073","1295"],["15.074","1246"],["15.075","464"],["15.077","1375"],["15.079","1597"],["15.085","515"],["15.088","946"],["15.090","17"],["15.091","472"],["15.094","413"],["15.129","1500"],["15.167","237"]]}}
1626916419.662456: {"stream":"etcusd_perp@depth@100ms","data":{"e":"depthUpdate","E":1626916419689,"T":1626916419675,"s":"ETCUSD_PERP","ps":"ETCUSD","U":167006187387,"u":167006187986,"pu":167006187306,"b":[["42.140","266"],["42.225","1513"],["42.234","0"],["42.237","977"]],"a":[["42.255","0"],["42.263","0"],["42.264","500"],["42.290","0"]]}}
1626916419.6626828: {"stream":"btcusd_211231@depth@100ms","data":{"e":"depthUpdate","E":1626916419689,"T":1626916419673,"s":"BTCUSD_211231","ps":"BTCUSD","U":167006187388,"u":167006187944,"pu":167006186758,"b":[],"a":[["32631.8","0"],["32634.8","153"],["32694.5","0"],["33031.9","45"],["33192.0","45"],["33352.0","45"],["33512.1","46"],["33672.1","46"]]}}
1626916419.6776772: {"stream":"ethusd_210924@depth@100ms","data":{"e":"depthUpdate","E":1626916419704,"T":1626916419685,"s":"ETHUSD_210924","ps":"ETHUSD","U":167006187459,"u":167006188067,"pu":167006187405,"b":[["1986.98","500"],["1989.33","1870"],["1990.69","480"],["1990.76","0"]],"a":[["1991.21","0"],["1991.26","480"],["1991.47","270"],["1991.52","0"],["1991.96","1301"],["1991.97","3712"],["1999.92","2000"],["2023.71","408"],["2033.63","410"],["2043.55","412"],["2053.47","414"],["2063.39","416"]]}}
1626916419.69519: {"stream":"linkusd_211231@depth@100ms","data":{"e":"depthUpdate","E":1626916419722,"T":1626916419683,"s":"LINKUSD_211231","ps":"LINKUSD","U":167006187549,"u":167006188036,"pu":167006187342,"b":[["15.300","47"]],"a":[["15.322","0"],["15.324","952"],["15.325","0"],["15.338","0"],["15.340","1906"],["15.525","0"],["15.600","38"],["15.675","0"],["15.751","0"],["15.826","0"]]}}
1626916419.703552: {"stream":"eosusd_perp@depth@100ms","data":{"e":"depthUpdate","E":1626916419730,"T":1626916419718,"s":"EOSUSD_PERP","ps":"EOSUSD","U":167006187605,"u":167006188250,"pu":167006187488,"b":[["3.468","0"]],"a":[["3.471","5169"]]}}
1626916419.719071: {"stream":"trxusd_perp@depth@100ms","data":{"e":"depthUpdate","E":1626916419745,"T":1626916419726,"s":"TRXUSD_PERP","ps":"TRXUSD","U":167006187675,"u":167006188313,"pu":167006187143,"b":[["0.05339","775"],["0.05340","2438"],["0.05343","1470"],["0.05345","551"]],"a":[["0.05347","19897"],["0.05350","3297"]]}}
1626916419.745794: {"stream":"xrpusd_perp@depth@100ms","data":{"e":"depthUpdate","E":1626916419774,"T":1626916419758,"s":"XRPUSD_PERP","ps":"XRPUSD","U":167006187915,"u":167006188444,"pu":167006187859,"b":[["0.5646","23367"],["0.5653","4778"],["0.5657","5598"],["0.5658","3205"],["0.5661","6916"]],"a":[["0.5662","809"]]}}
1626916419.753324: {"stream":"linkusd_perp@depth@100ms","data":{"e":"depthUpdate","E":1626916419780,"T":1626916419774,"s":"LINKUSD_PERP","ps":"LINKUSD","U":167006187969,"u":167006188538,"pu":167006187960,"b":[["15.029","2147"],["15.036","1032"],["15.037","3470"],["15.048","571"],["15.052","380"],["15.053","3079"],["15.054","148"],["15.055","1295"],["15.061","500"]],"a":[["15.069","0"],["15.070","5843"],["15.071","250"],["15.072","164"],["15.073","1624"],["15.074","1275"],["15.075","615"],["15.076","350"],["15.077","1775"],["15.078","751"],["15.079","1487"],["15.080","853"],["15.082","2704"],["15.084","110"],["15.086","0"],["15.168","3681"]]}}
1626916419.767103: {"stream":"etcusd_perp@depth@100ms","data":{"e":"depthUpdate","E":1626916419793,"T":1626916419782,"s":"ETCUSD_PERP","ps":"ETCUSD","U":167006188074,"u":167006188580,"pu":167006187986,"b":[["41.894","0"],["41.909","595"],["42.059","0"],["42.133","0"],["42.144","97"],["42.155","300"],["42.210","1537"],["42.216","578"]],"a":[["42.263","150"],["42.264","500"],["42.267","0"],["42.277","162"],["42.286","0"],["42.289","322"],["42.316","396"],["42.342","501"],["42.343","23282"],["42.350","72"],["42.440","300"],["42.453","488"],["42.462","0"]]}}
1626916419.771542: {"stream":"btcusd_211231@depth@100ms","data":{"e":"depthUpdate","E":1626916419798,"T":1626916419792,"s":"BTCUSD_211231","ps":"BTCUSD","U":167006188117,"u":167006188606,"pu":167006187944,"b":[["32494.1","0"],["32517.0","1845"]],"a":[["32631.1","0"],["32631.2","0"],["32631.3","0"],["32633.9","46"],["32634.8","153"],["32644.4","0"],["32709.7","374"]]}}
1626916419.774102: {"stream":"bchusd_perp@depth@100ms","data":{"e":"depthUpdate","E":1626916419800,"T":1626916419696,"s":"BCHUSD_PERP","ps":"BCHUSD","U":167006188136,"u":167006188136,"pu":167006187454,"b":[],"a":[["438.24","3115"]]}}
1626916419.789075: {"stream":"ethusd_210924@depth@100ms","data":{"e":"depthUpdate","E":1626916419815,"T":1626916419791,"s":"ETHUSD_210924","ps":"ETHUSD","U":167006188198,"u":167006188602,"pu":167006188067,"b":[["1990.35","1770"],["1990.38","798"]],"a":[["1991.25","270"],["1991.47","0"],["1991.48","0"],["1991.73","0"],["1991.74","0"]]}}
1626916419.796764: {"stream":"linkusd_211231@depth@100ms","data":{"e":"depthUpdate","E":1626916419824,"T":1626916419801,"s":"LINKUSD_211231","ps":"LINKUSD","U":167006188263,"u":167006188648,"pu":167006188036,"b":[["15.281","53"],["15.282","0"],["15.294","0"],["15.296","1381"]],"a":[["15.526","164"],["15.601","165"],["15.676","204"],["15.752","167"],["15.827","168"]]}}
1626916419.807533: {"stream":"eosusd_perp@depth@100ms","data":{"e":"depthUpdate","E":1626916419834,"T":1626916419751,"s":"EOSUSD_PERP","ps":"EOSUSD","U":167006188321,"u":167006188423,"pu":167006188250,"b":[["3.468","0"]],"a":[]}}
1626916419.853536: {"stream":"trxusd_perp@depth@100ms","data":{"e":"depthUpdate","E":1626916419881,"T":1626916419807,"s":"TRXUSD_PERP","ps":"TRXUSD","U":167006188547,"u":167006188680,"pu":167006188313,"b":[["0.05338","183"],["0.05343","1470"]],"a":[]}}
1626916419.853684: {"stream":"linkusd_perp@depth@100ms","data":{"e":"depthUpdate","E":1626916419881,"T":1626916419874,"s":"LINKUSD_PERP","ps":"LINKUSD","U":167006188548,"u":167006188954,"pu":167006188538,"b":[["15.005","0"],["15.008","895"],["15.051","1738"],["15.052","180"],["15.053","3108"],["15.054","348"],["15.056","1813"],["15.063","400"],["15.066","112"]],"a":[["15.068","0"],["15.069","100"],["15.070","2057"],["15.072","568"],["15.073","1524"],["15.075","715"],["15.077","1885"],["15.078","825"],["15.084","0"],["15.089","51"],["15.171","740"]]}}
1626916419.868203: {"stream":"etcusd_perp@depth@100ms","data":{"e":"depthUpdate","E":1626916419895,"T":1626916419820,"s":"ETCUSD_PERP","ps":"ETCUSD","U":167006188603,"u":167006188727,"pu":167006188580,"b":[["42.070","536"],["42.156","145"],["42.227","1131"]],"a":[["42.320","200"],["42.329","1320"],["42.353","214"],["42.361","185"],["42.476","336"]]}}
1626916419.8723998: {"stream":"xrpusd_perp@depth@100ms","data":{"e":"depthUpdate","E":1626916419899,"T":1626916419888,"s":"XRPUSD_PERP","ps":"XRPUSD","U":167006188635,"u":167006189023,"pu":167006188444,"b":[["0.5653","4290"],["0.5654","14779"]],"a":[["0.5662","500"],["0.5667","2273"],["0.5674","13130"]]}}
1626916419.874669: {"stream":"btcusd_211231@depth@100ms","data":{"e":"depthUpdate","E":1626916419900,"T":1626916419888,"s":"BTCUSD_211231","ps":"BTCUSD","U":167006188626,"u":167006189024,"pu":167006188606,"b":[["32593.8","20"]],"a":[["32632.9","0"],["32633.8","46"],["32633.9","0"],["32634.0","0"],["32634.7","0"],["32634.8","153"],["32637.5","139"],["32637.6","0"],["32637.7","0"]]}}
1626916419.8940318: {"stream":"bchusd_perp@depth@100ms","data":{"e":"depthUpdate","E":1626916419920,"T":1626916419834,"s":"BCHUSD_PERP","ps":"BCHUSD","U":167006188708,"u":167006188775,"pu":167006188136,"b":[["427.30","4064"],["427.35","3467"],["427.69","288"]],"a":[]}}
1626916419.9631581: {"stream":"ethusd_210924@depth@100ms","data":{"e":"depthUpdate","E":1626916419986,"T":1626916419927,"s":"ETHUSD_210924","ps":"ETHUSD","U":167006189000,"u":167006189185,"pu":167006188602,"b":[],"a":[["1991.26","0"],["1995.60","190"],["1997.70","0"]]}}
1626916419.9633448: {"stream":"trxusd_perp@depth@100ms","data":{"e":"depthUpdate","E":1626916419988,"T":1626916419929,"s":"TRXUSD_PERP","ps":"TRXUSD","U":167006189006,"u":167006189190,"pu":167006188680,"b":[["0.05330","252"]],"a":[["0.05348","100"],["0.05363","23820"]]}}
1626916419.9678211: {"stream":"eosusd_perp@depth@100ms","data":{"e":"depthUpdate","E":1626916419991,"T":1626916419973,"s":"EOSUSD_PERP","ps":"EOSUSD","U":167006189010,"u":167006189387,"pu":167006188423,"b":[["3.462","5381"],["3.468","0"]],"a":[]}}
1626916419.981261: {"stream":"linkusd_perp@depth@100ms","data":{"e":"depthUpdate","E":1626916420008,"T":1626916420000,"s":"LINKUSD_PERP","ps":"LINKUSD","U":167006189074,"u":167006189553,"pu":167006188954,"b":[["14.946","0"],["14.951","780"],["15.000","2409"],["15.046","1000"],["15.048","645"],["15.063","399"],["15.066","113"]],"a":[["15.072","4493"],["15.073","1224"],["15.075","1015"],["15.104","15405"]]}}
1626916419.98675: {"stream":"btcusd_211231@depth@100ms","data":{"e":"depthUpdate","E":1626916420014,"T":1626916419934,"s":"BTCUSD_211231","ps":"BTCUSD","U":167006189105,"u":167006189223,"pu":167006189024,"b":[],"a":[["32632.8","46"],["32633.7","153"],["32633.8","0"],["32634.8","0"]]}}
1626916420.0134022: {"stream":"bchusd_perp@depth@100ms","data":{"e":"depthUpdate","E":1626916420040,"T":1626916420034,"s":"BCHUSD_PERP","ps":"BCHUSD","U":167006189204,"u":167006189716,"pu":167006188775,"b":[["426.39","310"],["427.41","2439"],["427.77","151"]],"a":[["429.16","310"]]}}
1626916420.027513: {"stream":"etcusd_perp@depth@100ms","data":{"e":"depthUpdate","E":1626916420055,"T":1626916419999,"s":"ETCUSD_PERP","ps":"ETCUSD","U":167006189298,"u":167006189547,"pu":167006188727,"b":[],"a":[["42.300","33"],["42.304","586"],["42.320","0"]]}}
1626916420.049896: {"stream":"linkusd_211231@depth@100ms","data":{"e":"depthUpdate","E":1626916420077,"T":1626916419972,"s":"LINKUSD_211231","ps":"LINKUSD","U":167006189385,"u":167006189385,"pu":167006188648,"b":[],"a":[["15.349","0"]]}}
1626916420.072066: {"stream":"eosusd_perp@depth@100ms","data":{"e":"depthUpdate","E":1626916420098,"T":1626916420080,"s":"EOSUSD_PERP","ps":"EOSUSD","U":167006189509,"u":167006189904,"pu":167006189387,"b":[["3.468","0"]],"a":[]}}
1626916420.084718: {"stream":"xrpusd_perp@depth@100ms","data":{"e":"depthUpdate","E":1626916420109,"T":1626916420042,"s":"XRPUSD_PERP","ps":"XRPUSD","U":167006189576,"u":167006189737,"pu":167006189023,"b":[["0.5644","3793"],["0.5657","4913"],["0.5658","3890"],["0.5661","6568"]],"a":[["0.5667","1192"],["0.5674","15361"]]}}
1626916420.096616: {"stream":"btcusd_211231@depth@100ms","data":{"e":"depthUpdate","E":1626916420123,"T":1626916420086,"s":"BTCUSD_211231","ps":"BTCUSD","U":167006189638,"u":167006189936,"pu":167006189223,"b":[["32476.0","0"]],"a":[["32631.8","46"],["32632.7","153"],["32632.8","0"],["32633.7","0"],["32867.8","0"]]}}
1626916420.1048331: {"stream":"linkusd_perp@depth@100ms","data":{"e":"depthUpdate","E":1626916420132,"T":1626916420109,"s":"LINKUSD_PERP","ps":"LINKUSD","U":167006189670,"u":167006190015,"pu":167006189553,"b":[["15.004","706"]],"a":[["15.077","1505"],["15.078","1205"]]}}
1626916420.1128068: {"stream":"bchusd_perp@depth@100ms","data":{"e":"depthUpdate","E":1626916420140,"T":1626916420110,"s":"BCHUSD_PERP","ps":"BCHUSD","U":167006189720,"u":167006190017,"pu":167006189716,"b":[["424.65","618"],["426.24","300"],["427.40","398"]],"a":[["428.94","344"],["429.31","300"],["430.90","606"],["8585.21","0"]]}}
1626916420.129388: {"stream":"etcusd_perp@depth@100ms","data":{"e":"depthUpdate","E":1626916420156,"T":1626916420079,"s":"ETCUSD_PERP","ps":"ETCUSD","U":167006189771,"u":167006189902,"pu":167006189547,"b":[],"a":[["42.267","90"],["42.277","72"],["42.300","0"]]}}
1626916420.138013: {"stream":"ethusd_210924@depth@100ms","data":{"e":"depthUpdate","E":1626916420161,"T":1626916420058,"s":"ETHUSD_210924","ps":"ETHUSD","U":167006189824,"u":167006189824,"pu":167006189185,"b":[],"a":[["2301.19","0"]]}}
1626916420.176975: {"stream":"eosusd_perp@depth@100ms","data":{"e":"depthUpdate","E":1626916420206,"T":1626916420191,"s":"EOSUSD_PERP","ps":"EOSUSD","U":167006189989,"u":167006190387,"pu":167006189904,"b":[["3.468","0"]],"a":[]}}
1626916420.1805172: {"stream":"xrpusd_perp@depth@100ms","data":{"e":"depthUpdate","E":1626916420209,"T":1626916420187,"s":"XRPUSD_PERP","ps":"XRPUSD","U":167006189992,"u":167006190381,"pu":167006189737,"b":[["0.1133","2931"],["0.3965","7310"],["0.5098","5117"],["0.5495","2924"]],"a":[["0.5664","4597"],["0.5667","1932"],["0.5668","5536"],["0.5669","5704"],["0.5674","14861"],["0.5676","53765"],["0.5836","2924"],["0.6233","5117"],["0.6300","1877"],["0.7366","7310"],["2.3456","36551"]]}}
1626916420.2051468: {"stream":"btcusd_211231@depth@100ms","data":{"e":"depthUpdate","E":1626916420233,"T":1626916420214,"s":"BTCUSD_211231","ps":"BTCUSD","U":167006190104,"u":167006190493,"pu":167006189936,"b":[["31363.4","55"],["31523.4","55"],["31683.4","55"],["31843.5","55"],["32003.5","55"],["32254.3","515"],["32410.7","0"]],"a":[["32631.1","46"],["32631.7","153"],["32631.8","0"],["32632.7","0"],["32976.2","1"]]}}
1626916420.2334201: {"stream":"bchusd_perp@depth@100ms","data":{"e":"depthUpdate","E":1626916420260,"T":1626916420238,"s":"BCHUSD_PERP","ps":"BCHUSD","U":167006190201,"u":167006190628,"pu":167006190017,"b":[["427.52","0"],["427.57","100"],["427.64","3214"]],"a":[["8585.11","60514"]]}}
1626916420.2390132: {"stream":"etcusd_perp@depth@100ms","data":{"e":"depthUpdate","E":1626916420265,"T":1626916420222,"s":"ETCUSD_PERP","ps":"ETCUSD","U":167006190247,"u":167006190561,"pu":167006189902,"b":[["42.199","400"],["42.210","1437"],["42.216","478"],["42.225","33"],["42.226","90"],["42.230","1501"],["42.237","887"]],"a":[["42.263","250"],["42.264","400"],["42.300","200"]]}}
1626916420.239595: {"stream":"linkusd_perp@depth@100ms","data":{"e":"depthUpdate","E":1626916420267,"T":1626916420254,"s":"LINKUSD_PERP","ps":"LINKUSD","U":167006190258,"u":167006190677,"pu":167006190015,"b":[["14.994","995"],["15.055","1195"],["15.057","1059"],["15.058","766"],["15.059","755"],["15.061","200"],["15.063","809"],["15.064","0"],["15.065","0"],["15.066","103"]],"a":[["15.075","915"],["15.077","1885"],["15.078","825"],["15.124","180"]]}}
1626916420.244992: {"stream":"bchusd_210924@depth@100ms","data":{"e":"depthUpdate","E":1626916420271,"T":1626916420185,"s":"BCHUSD_210924","ps":"BCHUSD","U":167006190285,"u":167006190377,"pu":167006186962,"b":[["429.12","40"],["429.13","584"],["429.23","0"]],"a":[]}}
1626916420.251868: {"stream":"linkusd_211231@depth@100ms","data":{"e":"depthUpdate","E":1626916420277,"T":1626916420196,"s":"LINKUSD_211231","ps":"LINKUSD","U":167006190317,"u":167006190417,"pu":167006189385,"b":[["15.296","123"],["15.297","1741"]],"a":[]}}
1626916420.268595: {"stream":"ethusd_210924@depth@100ms","data":{"e":"depthUpdate","E":1626916420296,"T":1626916420288,"s":"ETHUSD_210924","ps":"ETHUSD","U":167006190389,"u":167006190833,"pu":167006189824,"b":[["1974.52","0"],["1987.20","0"],["1988.50","0"],["1988.75","425"],["1988.99","7480"]],"a":[["1991.53","37"],["1993.29","0"],["1993.72","0"],["1994.48","0"],["2299.59","5742"]]}}
1626916420.289921: {"stream":"eosusd_perp@depth@100ms","data":{"e":"depthUpdate","E":1626916420315,"T":1626916420308,"s":"EOSUSD_PERP","ps":"EOSUSD","U":167006190484,"u":167006190948,"pu":167006190387,"b":[["3.452","5558"],["3.468","0"]],"a":[["3.470","4908"],["3.471","4710"]]}}
1626916420.293128: {"stream":"xrpusd_perp@depth@100ms","data":{"e":"depthUpdate","E":1626916420321,"T":1626916420290,"s":"XRPUSD_PERP","ps":"XRPUSD","U":167006190510,"u":167006190842,"pu":167006190381,"b":[["0.5658","3010"],["0.5659","2596"],["0.5661","6568"]],"a":[["0.5665","5495"],["0.5666","1759"],["0.5668","4656"],["0.5669","6584"],["0.5674","12661"],["0.5677","3383"]]}}
1626916420.297663: {"stream":"trxusd_perp@depth@100ms","data":{"e":"depthUpdate","E":1626916420325,"T":1626916420222,"s":"TRXUSD_PERP","ps":"TRXUSD","U":167006190559,"u":167006190559,"pu":167006189190,"b":[],"a":[["0.05364","2080"]]}}
1626916420.337717: {"stream":"btcusd_211231@depth@100ms","data":{"e":"depthUpdate","E":1626916420365,"T":1626916420340,"s":"BTCUSD_211231","ps":"BTCUSD","U":167006190700,"u":167006191145,"pu":167006190493,"b":[["32494.0","2650"],["32517.0","0"]],"a":[["32631.7","0"],["32634.8","153"],["32639.8","0"]]}}
1626916420.347279: {"stream":"etcusd_perp@depth@100ms","data":{"e":"depthUpdate","E":1626916420373,"T":1626916420309,"s":"ETCUSD_PERP","ps":"ETCUSD","U":167006190737,"u":167006190955,"pu":167006190561,"b":[["42.140","66"],["42.226","0"],["42.230","33"],["42.237","977"]],"a":[["42.299","245"],["42.315","100"]]}}
1626916420.351566: {"stream":"linkusd_perp@depth@100ms","data":{"e":"depthUpdate","E":1626916420377,"T":1626916420372,"s":"LINKUSD_PERP","ps":"LINKUSD","U":167006190760,"u":167006191337,"pu":167006190677,"b":[["15.030","706"],["15.055","1295"],["15.057","959"],["15.061","500"],["15.063","509"]],"a":[["15.072","568"],["15.128","1435"]]}}
1626916420.369762: {"stream":"bchusd_210924@depth@100ms","data":{"e":"depthUpdate","E":1626916420396,"T":1626916420364,"s":"BCHUSD_210924","ps":"BCHUSD","U":167006190855,"u":167006191286,"pu":167006190377,"b":[["429.00","0"],["429.11","916"],["429.12","0"],["429.13","0"],["429.14","0"],["429.23","40"]],"a":[["429.86","0"],["429.92","289"]]}}
1626916420.378804: {"stream":"ethusd_210924@depth@100ms","data":{"e":"depthUpdate","E":1626916420405,"T":1626916420379,"s":"ETHUSD_210924","ps":"ETHUSD","U":167006190874,"u":167006191377,"pu":167006190833,"b":[["1937.46","0"],["1987.32","532"],["1988.71","237"],["1988.97","169"],["1990.46","0"],["1990.70","270"],["1990.71","263"],["1990.77","0"]],"a":[["1993.38","6217"],["1994.49","237"]]}}
1626916420.393995: {"stream":"eosusd_perp@depth@100ms","data":{"e":"depthUpdate","E":1626916420420,"T":1626916420412,"s":"EOSUSD_PERP","ps":"EOSUSD","U":167006190982,"u":167006191562,"pu":167006190948,"b":[["3.468","0"]],"a":[["3.470","4658"],["3.471","4458"]]}}
1626916420.410387: {"stream":"bchusd_perp@depth@100ms","data":{"e":"depthUpdate","E":1626916420436,"T":1626916420398,"s":"BCHUSD_PERP","ps":"BCHUSD","U":167006191094,"u":167006191498,"pu":167006190628,"b":[["427.57","0"],["427.62","100"]],"a":[["427.78","152"]]}}
1626916420.410836: {"stream":"linkusd_211231@depth@100ms","data":{"e":"depthUpdate","E":1626916420438,"T":1626916420336,"s":"LINKUSD_211231","ps":"LINKUSD","U":167006191116,"u":167006191121,"pu":167006190417,"b":[["15.296","0"],["15.298","123"]],"a":[]}}
1626916420.426605: {"stream":"xrpusd_perp@depth@100ms","data":{"e":"depthUpdate","E":1626916420454,"T":1626916420438,"s":"XRPUSD_PERP","ps":"XRPUSD","U":167006191192,"u":167006191713,"pu":167006190842,"b":[["0.5579","6"],["0.5581","1182"],["0.5621","5968"],["0.5623","1086"],["0.5635","2529"],["0.5636","610"],["0.5655","4672"],["0.5656","9264"],["0.5658","3596"],["0.5659","2756"],["0.5661","6408"]],"a":[["0.5668","4282"],["0.5669","5998"],["0.5670","7215"],["0.5671","904"],["0.5672","3595"],["0.5689","300"],["0.5692","9272"],["0.5704","17108"],["0.5706","1106"],["0.5746","2"],["0.5748","5636"]]}}
1626916420.4375622: {"stream":"btcusd_211231@depth@100ms","data":{"e":"depthUpdate","E":1626916420465,"T":1626916420362,"s":"BTCUSD_211231","ps":"BTCUSD","U":167006191254,"u":167006191255,"pu":167006191145,"b":[],"a":[["32631.1","0"],["32633.9","46"]]}}
1626916420.451366: {"stream":"linkusd_perp@depth@100ms","data":{"e":"depthUpdate","E":1626916420478,"T":1626916420406,"s":"LINKUSD_PERP","ps":"LINKUSD","U":167006191343,"u":167006191528,"pu":167006191337,"b":[["15.055","1195"],["15.057","1059"]],"a":[["15.072","404"]]}}
1626916420.460999: {"stream":"etcusd_perp@depth@100ms","data":{"e":"depthUpdate","E":1626916420489,"T":1626916420474,"s":"ETCUSD_PERP","ps":"ETCUSD","U":167006191424,"u":167006191842,"pu":167006190955,"b":[["42.000","365"],["42.141","1052"],["42.162","0"],["42.215","22"],["42.219","70"],["42.228","1468"]],"a":[["42.263","150"],["42.264","500"]]}}
1626916420.501976: {"stream":"bchusd_210924@depth@100ms","data":{"e":"depthUpdate","E":1626916420528,"T":1626916420433,"s":"BCHUSD_210924","ps":"BCHUSD","U":167006191635,"u":167006191697,"pu":167006191286,"b":[["429.00","287"],["429.11","674"]],"a":[]}}
1626916420.506281: {"stream":"eosusd_perp@depth@100ms","data":{"e":"depthUpdate","E":1626916420532,"T":1626916420516,"s":"EOSUSD_PERP","ps":"EOSUSD","U":167006191648,"u":167006192071,"pu":167006191562,"b":[["3.446","13583"],["3.468","0"]],"a":[["3.468","216"],["3.489","2706"]]}}
1626916420.511748: {"stream":"ethusd_210924@depth@100ms","data":{"e":"depthUpdate","E":1626916420538,"T":1626916420432,"s":"ETHUSD_210924","ps":"ETHUSD","U":167006191693,"u":167006191693,"pu":167006191377,"b":[],"a":[["1991.53","0"]]}}
1626916420.514432: {"stream":"linkusd_211231@depth@100ms","data":{"e":"depthUpdate","E":1626916420541,"T":1626916420521,"s":"LINKUSD_211231","ps":"LINKUSD","U":167006191712,"u":167006192082,"pu":167006191121,"b":[["14.761","0"],["14.837","0"],["14.912","0"],["14.987","0"],["15.063","0"]],"a":[["15.339","4014"],["15.340","0"]]}}
1626916420.51925: {"stream":"trxusd_perp@depth@100ms","data":{"e":"depthUpdate","E":1626916420548,"T":1626916420515,"s":"TRXUSD_PERP","ps":"TRXUSD","U":167006191729,"u":167006192062,"pu":167006190559,"b":[["0.05340","2324"],["0.05341","2236"]],"a":[["0.05350","3175"],["0.05351","2832"],["0.05363","23839"],["0.05364","2212"],["0.05379","521"]]}}
1626916420.5388281: {"stream":"xrpusd_perp@depth@100ms","data":{"e":"depthUpdate","E":1626916420566,"T":1626916420489,"s":"XRPUSD_PERP","ps":"XRPUSD","U":167006191788,"u":167006191930,"pu":167006191713,"b":[],"a":[["0.5667","1890"],["0.5668","4324"],["0.5669","6373"]]}}
1626916420.5393898: {"stream":"btcusd_211231@depth@100ms","data":{"e":"depthUpdate","E":1626916420567,"T":1626916420535,"s":"BTCUSD_211231","ps":"BTCUSD","U":167006191791,"u":167006192149,"pu":167006191255,"b":[["32265.0","457"]],"a":[["32625.1","13"],["32631.0","0"],["32632.9","46"],["32633.8","153"],["32633.9","0"],["32634.8","0"]]}}
1626916420.5484722: {"stream":"bchusd_perp@depth@100ms","data":{"e":"depthUpdate","E":1626916420576,"T":1626916420539,"s":"BCHUSD_PERP","ps":"BCHUSD","U":167006191837,"u":167006192155,"pu":167006191498,"b":[["427.77","151"]],"a":[]}}
1626916420.608533: {"stream":"eosusd_perp@depth@100ms","data":{"e":"depthUpdate","E":1626916420634,"T":1626916420625,"s":"EOSUSD_PERP","ps":"EOSUSD","U":167006192121,"u":167006192488,"pu":167006192071,"b":[["3.464","4557"],["3.465","7437"],["3.468","0"]],"a":[["3.470","4558"],["3.471","4658"]]}}
1626916420.632385: {"stream":"ethusd_210924@depth@100ms","data":{"e":"depthUpdate","E":1626916420658,"T":1626916420565,"s":"ETHUSD_210924","ps":"ETHUSD","U":167006192214,"u":167006192263,"pu":167006191693,"b":[["1939.18","2421"]],"a":[["1993.83","169"]]}}
1626916420.632554: {"stream":"trxusd_perp@depth@100ms","data":{"e":"depthUpdate","E":1626916420662,"T":1626916420655,"s":"TRXUSD_PERP","ps":"TRXUSD","U":167006192237,"u":167006192591,"pu":167006192062,"b":[["0.05341","2236"],["0.05343","1470"]],"a":[["0.05350","3075"],["0.05352","1144"]]}}
1626916420.640366: {"stream":"xrpusd_perp@depth@100ms","data":{"e":"depthUpdate","E":1626916420669,"T":1626916420589,"s":"XRPUSD_PERP","ps":"XRPUSD","U":167006192259,"u":167006192366,"pu":167006191930,"b":[["0.5653","4590"],["0.5657","5481"],["0.5659","2456"],["0.5661","6417"]],"a":[]}}
1626916420.648306: {"stream":"btcusd_211231@depth@100ms","data":{"e":"depthUpdate","E":1626916420677,"T":1626916420592,"s":"BTCUSD_211231","ps":"BTCUSD","U":167006192289,"u":167006192373,"pu":167006192149,"b":[],"a":[["32631.9","46"],["32632.8","153"],["32632.9","0"],["32633.8","0"]]}}
1626916420.653564: {"stream":"etcusd_perp@depth@100ms","data":{"e":"depthUpdate","E":1626916420681,"T":1626916420674,"s":"ETCUSD_PERP","ps":"ETCUSD","U":167006192311,"u":167006192654,"pu":167006191842,"b":[["42.199","0"],["42.204","323"],["42.210","1337"],["42.211","655"],["42.216","578"],["42.237","977"],["42.238","0"]],"a":[["42.238","7"],["42.264","0"],["42.266","100"],["42.272","0"],["42.290","33"],["42.298","482"],["42.304","0"],["42.313","614"],["42.314","0"],["42.324","400"]]}}
1626916420.707637: {"stream":"eosusd_perp@depth@100ms","data":{"e":"depthUpdate","E":1626916420734,"T":1626916420629,"s":"EOSUSD_PERP","ps":"EOSUSD","U":167006192507,"u":167006192508,"pu":167006192488,"b":[["3.468","0"]],"a":[]}}
1626916420.733688: {"stream":"trxusd_perp@depth@100ms","data":{"e":"depthUpdate","E":1626916420762,"T":1626916420713,"s":"TRXUSD_PERP","ps":"TRXUSD","U":167006192592,"u":167006192833,"pu":167006192591,"b":[],"a":[["0.05348","200"],["0.05349","620"],["0.05350","3275"],["0.05351","2732"],["0.05352","1144"]]}}
1626916420.747218: {"stream":"linkusd_perp@depth@100ms","data":{"e":"depthUpdate","E":1626916420774,"T":1626916420728,"s":"LINKUSD_PERP","ps":"LINKUSD","U":167006192645,"u":167006192898,"pu":167006191528,"b":[],"a":[["15.073","1524"],["15.075","615"],["15.106","272"]]}}
1626916420.758925: {"stream":"btcusd_211231@depth@100ms","data":{"e":"depthUpdate","E":1626916420785,"T":1626916420727,"s":"BTCUSD_211231","ps":"BTCUSD","U":167006192677,"u":167006192895,"pu":167006192373,"b":[],"a":[["32631.5","46"],["32631.8","153"],["32631.9","0"],["32632.8","0"],["32633.9","0"],["32634.8","0"],["32696.9","392"],["32709.7","0"]]}}
1626916420.760352: {"stream":"ethusd_210924@depth@100ms","data":{"e":"depthUpdate","E":1626916420789,"T":1626916420685,"s":"ETHUSD_210924","ps":"ETHUSD","U":167006192697,"u":167006192701,"pu":167006192263,"b":[],"a":[["2023.71","0"],["2033.63","0"],["2043.55","0"],["2053.47","0"],["2063.39","0"]]}}
1626916420.7605498: {"stream":"bchusd_perp@depth@100ms","data":{"e":"depthUpdate","E":1626916420789,"T":1626916420724,"s":"BCHUSD_PERP","ps":"BCHUSD","U":167006192696,"u":167006192882,"pu":167006192155,"b":[["427.09","5417"],["427.10","116"],["427.59","51"],["427.61","0"],["427.63","1122"]],"a":[]}}
1626916420.769648: {"stream":"xrpusd_perp@depth@100ms","data":{"e":"depthUpdate","E":1626916420797,"T":1626916420779,"s":"XRPUSD_PERP","ps":"XRPUSD","U":167006192727,"u":167006193090,"pu":167006192366,"b":[["0.5617","2689"],["0.5653","4290"],["0.5656","7587"],["0.5659","2798"],["0.5660","6232"],["0.5661","6417"]],"a":[]}}
1626916420.791085: {"stream":"linkusd_211231@depth@100ms","data":{"e":"depthUpdate","E":1626916420817,"T":1626916420712,"s":"LINKUSD_211231","ps":"LINKUSD","U":167006192822,"u":167006192822,"pu":167006192082,"b":[["15.288","0"]],"a":[]}}
1626916420.8060632: {"stream":"etcusd_perp@depth@100ms","data":{"e":"depthUpdate","E":1626916420835,"T":1626916420823,"s":"ETCUSD_PERP","ps":"ETCUSD","U":167006192907,"u":167006193239,"pu":167006192654,"b":[["42.237","980"]],"a":[["42.308","600"],["42.313","514"]]}}
1626916420.8084018: {"stream":"eosusd_perp@depth@100ms","data":{"e":"depthUpdate","E":1626916420835,"T":1626916420822,"s":"EOSUSD_PERP","ps":"EOSUSD","U":167006192904,"u":167006193237,"pu":167006192508,"b":[["3.462","5449"],["3.464","4657"],["3.465","7337"],["3.468","0"]],"a":[]}}
1626916420.8633358: {"stream":"linkusd_perp@depth@100ms","data":{"e":"depthUpdate","E":1626916420890,"T":1626916420882,"s":"LINKUSD_PERP","ps":"LINKUSD","U":167006193106,"u":167006193480,"pu":167006192898,"b":[["15.056","1813"],["15.062","176"],["15.063","399"],["15.064","110"],["15.065","40"]],"a":[["15.072","3412"]]}}
1626916420.863521: {"stream":"ethusd_210924@depth@100ms","data":{"e":"depthUpdate","E":1626916420890,"T":1626916420846,"s":"ETHUSD_210924","ps":"ETHUSD","U":167006193105,"u":167006193318,"pu":167006192701,"b":[["1989.33","0"],["1989.77","1746"]],"a":[["1991.14","0"]]}}
1626916420.901248: {"stream":"linkusd_211231@depth@100ms","data":{"e":"depthUpdate","E":1626916420929,"T":1626916420843,"s":"LINKUSD_211231","ps":"LINKUSD","U":167006193243,"u":167006193308,"pu":167006192822,"b":[["15.294","1339"],["15.297","0"]],"a":[]}}
1626916420.916905: {"stream":"eosusd_perp@depth@100ms","data":{"e":"depthUpdate","E":1626916420943,"T":1626916420926,"s":"EOSUSD_PERP","ps":"EOSUSD","U":167006193297,"u":167006193605,"pu":167006193237,"b":[["3.457","3036"],["3.468","0"]],"a":[["3.478","6552"]]}}
1626916420.9245281: {"stream":"btcusd_211231@depth@100ms","data":{"e":"depthUpdate","E":1626916420951,"T":1626916420881,"s":"BTCUSD_211231","ps":"BTCUSD","U":167006193313,"u":167006193479,"pu":167006192895,"b":[["32516.9","0"],["32526.7","862"]],"a":[["32656.0","0"]]}}
1626916420.934818: {"stream":"trxusd_perp@depth@100ms","data":{"e":"depthUpdate","E":1626916420962,"T":1626916420924,"s":"TRXUSD_PERP","ps":"TRXUSD","U":167006193371,"u":167006193600,"pu":167006192833,"b":[["0.05341","2236"],["0.05343","1470"]],"a":[["0.05348","100"],["0.05349","520"],["0.05350","3175"],["0.05351","2832"],["0.05352","1344"],["0.05366","1230"]]}}
1626916420.9495292: {"stream":"bchusd_perp@depth@100ms","data":{"e":"depthUpdate","E":1626916420976,"T":1626916420962,"s":"BCHUSD_PERP","ps":"BCHUSD","U":167006193431,"u":167006193702,"pu":167006192882,"b":[],"a":[["427.78","232"],["429.11","0"],["4697.19","22176"],["4697.24","0"]]}}
1626916420.955604: {"stream":"xrpusd_perp@depth@100ms","data":{"e":"depthUpdate","E":1626916420983,"T":1626916420957,"s":"XRPUSD_PERP","ps":"XRPUSD","U":167006193467,"u":167006193691,"pu":167006193090,"b":[["0.5644","3157"],["0.5645","4827"],["0.5646","347"],["0.5647","24531"]],"a":[["0.5682","12940"],["0.5683","25378"]]}}
1626916420.978204: {"stream":"linkusd_perp@depth@100ms","data":{"e":"depthUpdate","E":1626916421004,"T":1626916420997,"s":"LINKUSD_PERP","ps":"LINKUSD","U":167006193524,"u":167006193833,"pu":167006193480,"b":[["15.024","391"],["15.033","15423"],["15.036","1224"],["15.047","3373"],["15.049","74"]],"a":[["15.067","270"],["15.120","1156"],["15.123","444"]]}}
1626916421.0225751: {"stream":"eosusd_perp@depth@100ms","data":{"e":"depthUpdate","E":1626916421049,"T":1626916421028,"s":"EOSUSD_PERP","ps":"EOSUSD","U":167006193676,"u":167006193975,"pu":167006193605,"b":[["3.468","0"]],"a":[["3.468","296"]]}}
1626916421.022673: {"stream":"linkusd_211231@depth@100ms","data":{"e":"depthUpdate","E":1626916421049,"T":1626916421019,"s":"LINKUSD_211231","ps":"LINKUSD","U":167006193675,"u":167006193922,"pu":167006193308,"b":[["14.764","100"],["14.840","100"],["14.915","100"],["14.990","100"],["15.066","100"],["15.283","223"],["15.309","120"]],"a":[["15.526","0"],["15.601","0"],["15.676","38"],["15.752","0"],["15.827","0"]]}}
1626916421.02468: {"stream":"etcusd_perp@depth@100ms","data":{"e":"depthUpdate","E":1626916421052,"T":1626916421042,"s":"ETCUSD_PERP","ps":"ETCUSD","U":167006193678,"u":167006194014,"pu":167006193239,"b":[["41.827","0"],["42.000","165"],["42.038","0"],["42.204","523"],["42.211","455"],["42.237","983"]],"a":[["42.262","80"],["42.320","200"],["42.453","336"],["42.664","0"]]}}
1626916421.0442922: {"stream":"btcusd_211231@depth@100ms","data":{"e":"depthUpdate","E":1626916421071,"T":1626916421023,"s":"BTCUSD_211231","ps":"BTCUSD","U":167006193725,"u":167006193942,"pu":167006193479,"b":[["32619.5","33"]],"a":[["33028.5","0"]]}}
1626916421.065791: {"stream":"ethusd_210924@depth@100ms","data":{"e":"depthUpdate","E":1626916421094,"T":1626916421085,"s":"ETHUSD_210924","ps":"ETHUSD","U":167006193809,"u":167006194165,"pu":167006193318,"b":[["1990.11","1242"],["1990.12","1876"]],"a":[["1991.25","0"],["1991.34","270"],["1991.53","167"],["1991.55","0"],["1993.24","0"],["1993.35","314"],["2019.61","8186"]]}}
1626916421.070068: {"stream":"xrpusd_perp@depth@100ms","data":{"e":"depthUpdate","E":1626916421098,"T":1626916421075,"s":"XRPUSD_PERP","ps":"XRPUSD","U":167006193826,"u":167006194116,"pu":167006193691,"b":[["0.5661","6771"]],"a":[["0.5662","636"],["0.5666","1987"],["0.5667","1662"]]}}
1626916421.090337: {"stream":"trxusd_perp@depth@100ms","data":{"e":"depthUpdate","E":1626916421119,"T":1626916421050,"s":"TRXUSD_PERP","ps":"TRXUSD","U":167006193895,"u":167006194026,"pu":167006193600,"b":[["0.05338","183"],["0.05341","2236"],["0.05343","1470"]],"a":[["0.05350","3375"],["0.05351","2832"],["0.05352","1144"]]}}
1626916421.097127: {"stream":"bchusd_perp@depth@100ms","data":{"e":"depthUpdate","E":1626916421125,"T":1626916421019,"s":"BCHUSD_PERP","ps":"BCHUSD","U":167006193926,"u":167006193926,"pu":167006193702,"b":[["427.77","175"]],"a":[]}}
1626916421.099164: {"stream":"linkusd_perp@depth@100ms","data":{"e":"depthUpdate","E":1626916421127,"T":1626916421024,"s":"LINKUSD_PERP","ps":"LINKUSD","U":167006193944,"u":167006193945,"pu":167006193833,"b":[],"a":[["15.074","1385"],["15.077","1775"]]}}
1626916421.122831: {"stream":"eosusd_perp@depth@100ms","data":{"e":"depthUpdate","E":1626916421151,"T":1626916421134,"s":"EOSUSD_PERP","ps":"EOSUSD","U":167006194023,"u":167006194325,"pu":167006193975,"b":[["3.457","3136"],["3.468","0"]],"a":[["3.478","6652"]]}}
1626916421.173362: {"stream":"ethusd_210924@depth@100ms","data":{"e":"depthUpdate","E":1626916421199,"T":1626916421191,"s":"ETHUSD_210924","ps":"ETHUSD","U":167006194186,"u":167006194561,"pu":167006194165,"b":[["1989.77","0"],["1990.12","2135"],["1990.58","312"]],"a":[["1991.14","500"],["2023.69","408"],["2033.61","409"],["2043.53","412"],["2053.45","413"],["2063.37","416"]]}}
1626916421.182065: {"stream":"etcusd_perp@depth@100ms","data":{"e":"depthUpdate","E":1626916421209,"T":1626916421180,"s":"ETCUSD_PERP","ps":"ETCUSD","U":167006194233,"u":167006194514,"pu":167006194014,"b":[["41.819","309"],["42.031","153"],["42.237","989"]],"a":[["42.308","500"],["42.313","614"],["42.444","250"],["42.656","312"]]}}
1626916421.1899068: {"stream":"btcusd_211231@depth@100ms","data":{"e":"depthUpdate","E":1626916421217,"T":1626916421183,"s":"BTCUSD_211231","ps":"BTCUSD","U":167006194270,"u":167006194522,"pu":167006193942,"b":[["31363.4","0"],["31523.4","0"],["31683.4","0"],["31843.5","0"],["32003.5","0"]],"a":[["32656.0","15"]]}}
1626916421.192482: {"stream":"bchusd_210924@depth@100ms","data":{"e":"depthUpdate","E":1626916421217,"T":1626916421124,"s":"BCHUSD_210924","ps":"BCHUSD","U":167006194272,"u":167006194297,"pu":167006191697,"b":[],"a":[["429.81","246"],["429.92","0"]]}}
1626916421.212517: {"stream":"trxusd_perp@depth@100ms","data":{"e":"depthUpdate","E":1626916421242,"T":1626916421214,"s":"TRXUSD_PERP","ps":"TRXUSD","U":167006194350,"u":167006194667,"pu":167006194026,"b":[["0.05341","2236"],["0.05343","1390"],["0.05344","1013"]],"a":[["0.05350","3375"],["0.05351","2832"],["0.05352","1144"]]}}
1626916421.2310789: {"stream":"eosusd_perp@depth@100ms","data":{"e":"depthUpdate","E":1626916421258,"T":1626916421238,"s":"EOSUSD_PERP","ps":"EOSUSD","U":167006194397,"u":167006194737,"pu":167006194325,"b":[["3.468","0"]],"a":[]}}
1626916421.2373161: {"stream":"xrpusd_perp@depth@100ms","data":{"e":"depthUpdate","E":1626916421265,"T":1626916421258,"s":"XRPUSD_PERP","ps":"XRPUSD","U":167006194413,"u":167006194839,"pu":167006194116,"b":[["0.5661","6417"]],"a":[["0.5662","945"]]}}
1626916421.237438: {"stream":"bchusd_perp@depth@100ms","data":{"e":"depthUpdate","E":1626916421266,"T":1626916421241,"s":"BCHUSD_PERP","ps":"BCHUSD","U":167006194412,"u":167006194753,"pu":167006193926,"b":[],"a":[["427.88","0"],["427.96","100"],["432.98","0"]]}}
1626916421.247571: {"stream":"linkusd_perp@depth@100ms","data":{"e":"depthUpdate","E":1626916421274,"T":1626916421264,"s":"LINKUSD_PERP","ps":"LINKUSD","U":167006194453,"u":167006194865,"pu":167006193945,"b":[["14.994","1395"],["15.030","306"],["15.048","525"],["15.050","260"],["15.053","3308"],["15.054","558"],["15.055","995"],["15.056","1713"],["15.057","1439"],["15.059","675"],["15.061","200"],["15.063","209"],["15.064","0"],["15.065","0"]],"a":[["15.069","332"],["15.074","1621"],["15.076","730"],["15.077","1395"],["15.109","291"]]}}
1626916421.2588558: {"stream":"linkusd_211231@depth@100ms","data":{"e":"depthUpdate","E":1626916421285,"T":1626916421241,"s":"LINKUSD_211231","ps":"LINKUSD","U":167006194515,"u":167006194766,"pu":167006193922,"b":[["15.287","1339"],["15.294","0"],["15.298","0"],["15.309","80"]],"a":[]}}
1626916421.2722812: {"stream":"ethusd_210924@depth@100ms","data":{"e":"depthUpdate","E":1626916421299,"T":1626916421271,"s":"ETHUSD_210924","ps":"ETHUSD","U":167006194582,"u":167006194890,"pu":167006194561,"b":[["1990.58","262"],["1990.69","0"]],"a":[["1991.28","480"],["1991.34","0"],["1991.41","270"],["1991.64","0"]]}}
1626916421.320141: {"stream":"trxusd_perp@depth@100ms","data":{"e":"depthUpdate","E":1626916421348,"T":1626916421251,"s":"TRXUSD_PERP","ps":"TRXUSD","U":167006194768,"u":167006194788,"pu":167006194667,"b":[["0.05341","2236"],["0.05343","1470"],["0.05344","933"]],"a":[]}}
1626916421.3388858: {"stream":"eosusd_perp@depth@100ms","data":{"e":"depthUpdate","E":1626916421366,"T":1626916421354,"s":"EOSUSD_PERP","ps":"EOSUSD","U":167006194842,"u":167006195239,"pu":167006194737,"b":[["3.468","0"]],"a":[["3.485","5678"],["3.486","686"]]}}
1626916421.348574: {"stream":"bchusd_perp@depth@100ms","data":{"e":"depthUpdate","E":1626916421376,"T":1626916421288,"s":"BCHUSD_PERP","ps":"BCHUSD","U":167006194891,"u":167006194964,"pu":167006194753,"b":[["426.66","0"]],"a":[["427.88","100"],["427.96","0"]]}}
1626916421.353188: {"stream":"xrpusd_perp@depth@100ms","data":{"e":"depthUpdate","E":1626916421381,"T":1626916421295,"s":"XRPUSD_PERP","ps":"XRPUSD","U":167006194912,"u":167006195003,"pu":167006194839,"b":[["0.5660","6262"],["0.5661","6387"]],"a":[["0.5663","2814"]]}}
1626916421.356431: {"stream":"linkusd_perp@depth@100ms","data":{"e":"depthUpdate","E":1626916421383,"T":1626916421374,"s":"LINKUSD_PERP","ps":"LINKUSD","U":167006194916,"u":167006195340,"pu":167006194865,"b":[["15.054","1944"],["15.055","0"],["15.057","1439"],["15.059","675"],["15.061","0"],["15.062","172"],["15.063","57"],["15.064","100"],["15.065","36"],["15.066","3"]],"a":[["15.068","264"],["15.069","646"],["15.071","550"],["15.073","1324"],["15.075","815"],["15.077","995"]]}}
1626916421.36704: {"stream":"btcusd_211231@depth@100ms","data":{"e":"depthUpdate","E":1626916421395,"T":1626916421309,"s":"BTCUSD_211231","ps":"BTCUSD","U":167006194950,"u":167006195057,"pu":167006194522,"b":[["31367.9","55"],["31527.9","55"],["31688.0","55"],["31848.0","55"],["32008.1","55"]],"a":[["32980.1","0"]]}}
1626916421.396972: {"stream":"ethusd_210924@depth@100ms","data":{"e":"depthUpdate","E":1626916421424,"T":1626916421333,"s":"ETHUSD_210924","ps":"ETHUSD","U":167006195109,"u":167006195146,"pu":167006194890,"b":[["1989.33","1708"]],"a":[["1991.14","0"]]}}
1626916421.400152: {"stream":"etcusd_perp@depth@100ms","data":{"e":"depthUpdate","E":1626916421428,"T":1626916421413,"s":"ETCUSD_PERP","ps":"ETCUSD","U":167006195122,"u":167006195483,"pu":167006194514,"b":[["42.205","100"],["42.216","478"],["42.220","1573"],["42.224","664"],["42.226","90"],["42.228","0"],["42.236","266"],["42.237","845"]],"a":[["42.260","400"],["42.266","0"],["42.267","0"],["42.286","90"]]}}
1626916421.443247: {"stream":"eosusd_perp@depth@100ms","data":{"e":"depthUpdate","E":1626916421469,"T":1626916421457,"s":"EOSUSD_PERP","ps":"EOSUSD","U":167006195286,"u":167006195637,"pu":167006195239,"b":[["3.462","5381"],["3.468","0"]],"a":[["3.473","2499"],["3.474","4775"]]}}
1626916421.446576: {"stream":"trxusd_perp@depth@100ms","data":{"e":"depthUpdate","E":1626916421473,"T":1626916421466,"s":"TRXUSD_PERP","ps":"TRXUSD","U":167006195295,"u":167006195692,"pu":167006194788,"b":[["0.05338","263"],["0.05341","2236"],["0.05343","1390"]],"a":[["0.05348","200"],["0.05349","620"],["0.05350","3275"],["0.05351","2732"]]}}
1626916421.467865: {"stream":"xrpusd_perp@depth@100ms","data":{"e":"depthUpdate","E":1626916421495,"T":1626916421457,"s":"XRPUSD_PERP","ps":"XRPUSD","U":167006195399,"u":167006195639,"pu":167006195003,"b":[["0.5661","6052"]],"a":[["0.5662","1280"],["0.5664","5337"]]}}
1626916421.476496: {"stream":"linkusd_perp@depth@100ms","data":{"e":"depthUpdate","E":1626916421503,"T":1626916421481,"s":"LINKUSD_PERP","ps":"LINKUSD","U":167006195429,"u":167006195745,"pu":167006195340,"b":[["15.055","0"],["15.058","966"],["15.061","110"],["15.062","62"]],"a":[]}}
1626916421.510517: {"stream":"etcusd_perp@depth@100ms","data":{"e":"depthUpdate","E":1626916421536,"T":1626916421470,"s":"ETCUSD_PERP","ps":"ETCUSD","U":167006195556,"u":167006195700,"pu":167006195483,"b":[["42.220","200"],["42.222","1373"],["42.226","0"],["42.236","25"],["42.237","1053"]],"a":[["42.286","0"],["42.288","112"],["42.297","0"],["42.308","600"],["42.313","514"]]}}
1626916421.511015: {"stream":"bchusd_perp@depth@100ms","data":{"e":"depthUpdate","E":1626916421541,"T":1626916421488,"s":"BCHUSD_PERP","ps":"BCHUSD","U":167006195582,"u":167006195782,"pu":167006194964,"b":[["427.56","1332"],["427.63","425"],["427.77","151"]],"a":[]}}
1626916421.518871: {"stream":"linkusd_211231@depth@100ms","data":{"e":"depthUpdate","E":1626916421544,"T":1626916421440,"s":"LINKUSD_211231","ps":"LINKUSD","U":167006195586,"u":167006195590,"pu":167006194766,"b":[],"a":[["15.525","164"],["15.600","203"],["15.675","166"],["15.751","167"],["15.826","168"]]}}
1626916421.564064: {"stream":"btcusd_211231@depth@100ms","data":{"e":"depthUpdate","E":1626916421590,"T":1626916421583,"s":"BTCUSD_211231","ps":"BTCUSD","U":167006195771,"u":167006196145,"pu":167006195057,"b":[["32526.6","0"],["32526.8","1724"],["32598.7","20"]],"a":[["32625.1","12"],["32631.4","153"],["32631.5","0"],["32631.8","0"],["32633.9","46"],["32634.8","0"],["32648.2","75"],["33031.9","0"],["33192.0","0"],["33352.0","0"],["33512.1","0"],["33672.1","0"]]}}
1626916421.5647411: {"stream":"trxusd_perp@depth@100ms","data":{"e":"depthUpdate","E":1626916421593,"T":1626916421547,"s":"TRXUSD_PERP","ps":"TRXUSD","U":167006195781,"u":167006195989,"pu":167006195692,"b":[["0.05338","183"],["0.05343","1470"]],"a":[["0.05348","100"],["0.05349","520"],["0.05350","3475"],["0.05351","2932"]]}}
1626916421.5873501: {"stream":"linkusd_perp@depth@100ms","data":{"e":"depthUpdate","E":1626916421613,"T":1626916421574,"s":"LINKUSD_PERP","ps":"LINKUSD","U":167006195844,"u":167006196092,"pu":167006195745,"b":[["15.055","100"],["15.057","1339"],["15.061","261"]],"a":[]}}
1626916421.6086242: {"stream":"ethusd_210924@depth@100ms","data":{"e":"depthUpdate","E":1626916421635,"T":1626916421630,"s":"ETHUSD_210924","ps":"ETHUSD","U":167006195936,"u":167006196489,"pu":167006195146,"b":[["1986.84","0"],["1987.11","0"],["1987.32","0"],["1987.42","6141"],["1987.65","0"],["1987.76","0"],["1987.77","414"],["1987.93","0"],["1988.00","365"],["1988.01","0"],["1988.02","0"],["1988.12","0"],["1988.13","0"],["1988.14","0"],["1988.25","0"],["1988.30","500"],["1988.31","5965"],["1988.42","120"],["1988.46","0"],["1988.58","0"],["1988.65","0"],["1988.71","0"],["1988.97","0"],["1988.98","0"],["1990.71","0"],["1990.72","480"],["1990.73","264"]],"a":[["1991.28","0"],["1992.79","0"],["1992.89","289"],["1993.04","0"],["1993.06","0"],["1993.15","414"],["1993.21","0"],["1993.38","5685"],["1993.44","0"],["1993.73","0"],["1993.83","0"],["1994.06","0"],["1994.16","0"],["1994.29","0"],["1994.34","0"],["1994.36","0"],["1994.49","0"],["1994.57","0"],["1994.59","0"],["1994.62","0"],["1994.81","0"],["1994.86","0"],["1994.92","2702"],["1995.32","0"],["1995.47","0"],["1995.72","0"],["1995.89","12"]]}}
1626916421.616791: {"stream":"etcusd_perp@depth@100ms","data":{"e":"depthUpdate","E":1626916421644,"T":1626916421614,"s":"ETCUSD_PERP","ps":"ETCUSD","U":167006195965,"u":167006196313,"pu":167006195700,"b":[["42.140","266"],["42.205","0"],["42.216","578"]],"a":[["42.287","112"],["42.288","22"],["42.297","0"],["42.298","0"],["42.308","500"],["42.310","679"],["42.315","0"],["42.316","819"],["42.319","70"],["42.320","0"],["42.324","400"],["42.325","400"],["42.342","0"],["42.416","0"],["42.438","0"]]}}
1626916421.641068: {"stream":"bchusd_perp@depth@100ms","data":{"e":"depthUpdate","E":1626916421668,"T":1626916421632,"s":"BCHUSD_PERP","ps":"BCHUSD","U":167006196057,"u":167006196511,"pu":167006195782,"b":[["424.79","610"],["427.77","175"]],"a":[["427.87","100"],["428.02","50"]]}}
1626916421.659591: {"stream":"xrpusd_perp@depth@100ms","data":{"e":"depthUpdate","E":1626916421686,"T":1626916421638,"s":"XRPUSD_PERP","ps":"XRPUSD","U":167006196130,"u":167006196565,"pu":167006195639,"b":[["0.5656","9344"],["0.5660","5178"],["0.5661","6389"]],"a":[]}}
1626916421.671925: {"stream":"btcusd_211231@depth@100ms","data":{"e":"depthUpdate","E":1626916421700,"T":1626916421690,"s":"BTCUSD_211231","ps":"BTCUSD","U":167006196209,"u":167006196929,"pu":167006196145,"b":[],"a":[["32625.1","13"],["32631.2","0"],["32631.3","153"],["32631.4","0"],["32632.9","0"],["32633.8","0"],["32633.9","0"],["33034.1","45"],["33194.1","45"],["33354.2","45"],["33514.2","46"],["33674.3","46"]]}}
1626916421.676399: {"stream":"trxusd_perp@depth@100ms","data":{"e":"depthUpdate","E":1626916421705,"T":1626916421701,"s":"TRXUSD_PERP","ps":"TRXUSD","U":167006196235,"u":167006196991,"pu":167006195989,"b":[],"a":[["0.05348","100"],["0.05349","520"],["0.05350","3175"],["0.05351","2632"],["0.05352","1344"],["0.05358","1138"],["0.05359","306"]]}}
1626916421.692996: {"stream":"bchusd_210924@depth@100ms","data":{"e":"depthUpdate","E":1626916421720,"T":1626916421616,"s":"BCHUSD_210924","ps":"BCHUSD","U":167006196307,"u":167006196328,"pu":167006194297,"b":[],"a":[["429.54","27"],["429.76","0"]]}}
1626916421.70477: {"stream":"linkusd_211231@depth@100ms","data":{"e":"depthUpdate","E":1626916421732,"T":1626916421705,"s":"LINKUSD_211231","ps":"LINKUSD","U":167006196439,"u":167006197016,"pu":167006195590,"b":[["14.764","0"],["14.840","0"],["14.915","0"],["14.990","0"],["15.066","0"],["15.297","1596"]],"a":[]}}
1626916421.70804: {"stream":"ethusd_210924@depth@100ms","data":{"e":"depthUpdate","E":1626916421735,"T":1626916421719,"s":"ETHUSD_210924","ps":"ETHUSD","U":167006196497,"u":167006197108,"pu":167006196489,"b":[["1986.91","783"],["1987.16","501"],["1987.21","15019"],["1987.43","481"],["1987.66","321"]],"a":[["1991.15","500"],["1992.98","365"],["1993.13","321"],["1993.30","401"],["1993.38","6217"],["1993.54","501"],["1994.27","783"],["1995.67","474"]]}}
1626916421.7218869: {"stream":"etcusd_perp@depth@100ms","data":{"e":"depthUpdate","E":1626916421747,"T":1626916421737,"s":"ETCUSD_PERP","ps":"ETCUSD","U":167006196623,"u":167006197244,"pu":167006196313,"b":[["42.208","1858"],["42.211","55"],["42.215","0"],["42.216","478"],["42.217","0"],["42.223","22"],["42.225","55"],["42.233","100"],["42.237","643"],["42.238","280"],["42.243","334"],["42.244","0"],["42.246","397"],["42.247","735"],["42.259","202"]],"a":[["42.238","0"],["42.260","0"],["42.263","0"],["42.268","0"],["42.272","0"],["42.275","0"],["42.276","0"],["42.277","0"],["42.280","300"],["42.286","38"],["42.290","0"],["42.308","500"],["42.316","719"],["42.322","100"],["42.325","100"],["42.334","200"]]}}
1626916421.7657092: {"stream":"linkusd_perp@depth@100ms","data":{"e":"depthUpdate","E":1626916421793,"T":1626916421762,"s":"LINKUSD_PERP","ps":"LINKUSD","U":167006196916,"u":167006197456,"pu":167006196092,"b":[["15.052","580"],["15.054","1744"],["15.061","110"],["15.062","214"]],"a":[["15.070","4654"],["15.072","0"]]}}
1626916421.7736268: {"stream":"eosusd_perp@depth@100ms","data":{"e":"depthUpdate","E":1626916421801,"T":1626916421700,"s":"EOSUSD_PERP","ps":"EOSUSD","U":167006196977,"u":167006196982,"pu":167006195637,"b":[["3.457","2936"]],"a":[["3.478","6452"]]}}
1626916421.7792058: {"stream":"trxusd_perp@depth@100ms","data":{"e":"depthUpdate","E":1626916421806,"T":1626916421797,"s":"TRXUSD_PERP","ps":"TRXUSD","U":167006196992,"u":167006197649,"pu":167006196991,"b":[["0.05306","631"],["0.05326","401"],["0.05340","2324"],["0.05341","2236"],["0.05343","1470"]],"a":[["0.05348","200"],["0.05349","620"],["0.05350","3275"],["0.05351","2732"],["0.05352","1144"],["0.05358","1438"],["0.05359","606"],["0.05365","3572"],["0.05385","1812"]]}}
1626916421.7837021: {"stream":"btcusd_211231@depth@100ms","data":{"e":"depthUpdate","E":1626916421811,"T":1626916421805,"s":"BTCUSD_211231","ps":"BTCUSD","U":167006197018,"u":167006197719,"pu":167006196929,"b":[],"a":[["32631.3","0"],["32633.9","46"],["32634.8","153"],["32853.5","49"]]}}
1626916421.802874: {"stream":"xrpusd_perp@depth@100ms","data":{"e":"depthUpdate","E":1626916421831,"T":1626916421816,"s":"XRPUSD_PERP","ps":"XRPUSD","U":167006197168,"u":167006197756,"pu":167006196565,"b":[["0.5660","5178"]],"a":[]}}
1626916421.809889: {"stream":"ethusd_210924@depth@100ms","data":{"e":"depthUpdate","E":1626916421835,"T":1626916421828,"s":"ETHUSD_210924","ps":"ETHUSD","U":167006197181,"u":167006197830,"pu":167006197108,"b":[["1988.22","541"],["1988.34","1185"],["1988.35","304"],["1988.40","1286"],["1988.42","526"],["1988.45","440"],["1988.46","474"],["1988.61","338"],["1988.65","338"],["1988.68","1335"],["1988.72","237"],["1988.81","203"],["1988.90","169"],["1989.21","203"],["1989.27","169"]],"a":[["1991.53","0"],["1993.81","169"],["1993.82","169"],["1994.03","203"],["1994.20","338"],["1994.31","237"],["1994.33","338"],["1994.35","384"],["1994.45","237"],["1994.54","203"],["1994.76","541"],["1994.78","304"],["1994.83","406"],["1994.88","406"],["1995.24","440"],["1995.42","2948"],["1995.83","474"]]}}
1626916421.819424: {"stream":"etcusd_perp@depth@100ms","data":{"e":"depthUpdate","E":1626916421847,"T":1626916421834,"s":"ETCUSD_PERP","ps":"ETCUSD","U":167006197279,"u":167006197860,"pu":167006197244,"b":[["41.847","210"],["42.039","41"],["42.161","0"],["42.173","145"],["42.197","0"],["42.202","0"],["42.204","323"],["42.206","56"],["42.208","1758"],["42.210","1337"],["42.213","56"],["42.222","1373"],["42.224","964"],["42.225","297"],["42.230","0"],["42.247","490"],["42.251","400"],["42.252","0"],["42.256","255"]],"a":[["42.274","0"],["42.277","250"],["42.278","1364"],["42.280","0"],["42.282","0"],["42.283","270"],["42.286","378"],["42.287","0"],["42.288","0"],["42.289","0"],["42.295","22"],["42.298","90"],["42.299","0"],["42.300","22"],["42.305","0"],["42.306","0"],["42.312","2038"],["42.317","826"],["42.319","0"],["42.320","200"],["42.324","200"],["42.342","498"],["42.348","0"],["42.651","0"]]}}
1626916421.819946: {"stream":"linkusd_211231@depth@100ms","data":{"e":"depthUpdate","E":1626916421846,"T":1626916421740,"s":"LINKUSD_211231","ps":"LINKUSD","U":167006197261,"u":167006197265,"pu":167006197016,"b":[["14.761","100"],["14.837","100"],["14.912","100"],["14.987","100"],["15.063","100"]],"a":[]}}
1626916421.833653: {"stream":"bchusd_perp@depth@100ms","data":{"e":"depthUpdate","E":1626916421862,"T":1626916421758,"s":"BCHUSD_PERP","ps":"BCHUSD","U":167006197419,"u":167006197424,"pu":167006196511,"b":[],"a":[["427.87","0"],["428.05","100"]]}}
1626916421.897173: {"stream":"btcusd_211231@depth@100ms","data":{"e":"depthUpdate","E":1626916421924,"T":1626916421913,"s":"BTCUSD_211231","ps":"BTCUSD","U":167006197772,"u":167006198387,"pu":167006197719,"b":[["32396.6","160"],["32461.9","161"],["32598.7","0"]],"a":[["32632.9","46"],["32633.8","153"],["32633.9","0"],["32634.8","0"]]}}
1626916421.922965: {"stream":"etcusd_perp@depth@100ms","data":{"e":"depthUpdate","E":1626916421949,"T":1626916421933,"s":"ETCUSD_PERP","ps":"ETCUSD","U":167006197898,"u":167006198524,"pu":167006197860,"b":[["41.425","0"],["41.435","528"],["41.848","0"],["41.858","528"],["41.870","560"],["42.053","336"],["42.070","200"],["42.073","0"],["42.081","336"],["42.082","2154"],["42.156","0"],["42.172","0"],["42.204","1"],["42.210","339"],["42.214","0"],["42.220","1320"],["42.223","0"],["42.224","268"],["42.225","275"],["42.227","1453"],["42.229","300"],["42.232","22"],["42.234","396"],["42.235","22"],["42.237","741"],["42.239","0"],["42.247","400"],["42.248","90"],["42.252","0"],["42.253","968"],["42.471","0"]],"a":[["42.262","0"],["42.277","150"],["42.278","0"],["42.279","0"],["42.281","0"],["42.283","0"],["42.285","100"],["42.286","625"],["42.288","400"],["42.293","0"],["42.295","0"],["42.297","90"],["42.298","0"],["42.299","98"],["42.307","1139"],["42.309","0"],["42.316","323"],["42.318","56"],["42.324","0"],["42.325","0"],["42.328","396"],["42.329","497"],["42.331","310"],["42.334","0"],["42.336","25"],["42.339","1320"],["42.341","15"],["42.342","0"],["42.349","300"],["42.353","69"],["42.358","539"],["42.361","40"],["42.364","145"],["42.365","132"],["42.372","145"],["42.393","369"],["42.453","0"],["42.454","300"],["42.464","1656"],["42.615","0"],["42.629","560"],["42.674","560"],["42.691","0"],["42.702","528"],["43.114","0"],["43.125","528"]]}}
1626916421.964878: {"stream":"bchusd_210924@depth@100ms","data":{"e":"depthUpdate","E":1626916421993,"T":1626916421949,"s":"BCHUSD_210924","ps":"BCHUSD","U":167006198170,"u":167006198594,"pu":167006196328,"b":[],"a":[["1056.95","4990"],["1057.28","0"]]}}
1626916421.967257: {"stream":"linkusd_perp@depth@100ms","data":{"e":"depthUpdate","E":1626916421994,"T":1626916421978,"s":"LINKUSD_PERP","ps":"LINKUSD","U":167006198185,"u":167006198750,"pu":167006197456,"b":[["15.053","3688"],["15.057","959"],["15.059","827"],["15.062","62"]],"a":[["15.067","190"],["15.073","1224"],["15.074","1621"],["15.075","1115"],["15.078","825"],["15.085","566"]]}}
1626916421.967446: {"stream":"xrpusd_perp@depth@100ms","data":{"e":"depthUpdate","E":1626916421994,"T":1626916421945,"s":"XRPUSD_PERP","ps":"XRPUSD","U":167006198204,"u":167006198587,"pu":167006197756,"b":[["0.5661","6054"]],"a":[["0.5662","1200"]]}}
1626916421.978373: {"stream":"bchusd_perp@depth@100ms","data":{"e":"depthUpdate","E":1626916422003,"T":1626916421990,"s":"BCHUSD_PERP","ps":"BCHUSD","U":167006198271,"u":167006198791,"pu":167006197424,"b":[["427.77","175"]],"a":[["427.78","152"],["427.87","100"],["428.05","0"]]}}
1626916421.980492: {"stream":"trxusd_perp@depth@100ms","data":{"e":"depthUpdate","E":1626916422005,"T":1626916421997,"s":"TRXUSD_PERP","ps":"TRXUSD","U":167006198275,"u":167006198822,"pu":167006197649,"b":[["0.05338","263"],["0.05340","2324"],["0.05342","852"],["0.05343","1390"]],"a":[["0.05348","100"],["0.05349","520"],["0.05350","3475"],["0.05351","2932"],["0.05355","1249"],["0.05356","899"],["0.05358","1138"],["0.05359","306"]]}}
1626916421.98699: {"stream":"ethusd_210924@depth@100ms","data":{"e":"depthUpdate","E":1626916422014,"T":1626916422009,"s":"ETHUSD_210924","ps":"ETHUSD","U":167006198329,"u":167006198889,"pu":167006197830,"b":[["1974.76","2897"],["1978.52","0"],["1982.51","0"],["1988.99","0"],["1989.14","6739"]],"a":[["1992.49","50"]]}}
1626916422.0072918: {"stream":"btcusd_211231@depth@100ms","data":{"e":"depthUpdate","E":1626916422035,"T":1626916421950,"s":"BTCUSD_211231","ps":"BTCUSD","U":167006198505,"u":167006198610,"pu":167006198387,"b":[],"a":[["32631.9","46"],["32632.8","153"],["32632.9","0"],["32633.8","0"]]}}
1626916422.029786: {"stream":"etcusd_perp@depth@100ms","data":{"e":"depthUpdate","E":1626916422056,"T":1626916422050,"s":"ETCUSD_PERP","ps":"ETCUSD","U":167006198611,"u":167006199051,"pu":167006198524,"b":[["41.909","35"],["41.924","560"],["42.168","145"],["42.173","0"],["42.182","445"],["42.206","0"],["42.209","1105"],["42.213","0"],["42.218","323"],["42.224","524"],["42.229","0"],["42.234","496"],["42.237","738"],["42.240","200"],["42.256","0"],["42.258","0"],["42.259","259"],["42.260","0"]],"a":[["42.285","0"],["42.286","0"],["42.287","100"],["42.289","253"],["42.292","0"],["42.296","349"],["42.300","0"],["42.304","22"],["42.306","2447"],["42.309","22"],["42.317","770"],["42.318","0"],["42.322","0"],["42.326","56"],["42.327","56"],["42.329","0"],["42.331","410"],["42.365","0"],["42.366","0"],["42.389","250"],["42.431","0"],["42.463","923"],["42.476","0"],["42.492","336"]]}}
1626916422.048886: {"stream":"eosusd_perp@depth@100ms","data":{"e":"depthUpdate","E":1626916422076,"T":1626916422014,"s":"EOSUSD_PERP","ps":"EOSUSD","U":167006198711,"u":167006198901,"pu":167006196982,"b":[["3.468","0"]],"a":[["3.468","216"]]}}
1626916422.07823: {"stream":"bchusd_perp@depth@100ms","data":{"e":"depthUpdate","E":1626916422105,"T":1626916422091,"s":"BCHUSD_PERP","ps":"BCHUSD","U":167006198841,"u":167006199255,"pu":167006198791,"b":[["425.60","907"],["427.00","226"],["427.49","0"],["427.56","598"],["427.57","100"],["427.62","0"],["427.77","151"]],"a":[["427.81","100"],["427.86","0"],["427.88","0"]]}}
1626916422.078465: {"stream":"bchusd_210924@depth@100ms","data":{"e":"depthUpdate","E":1626916422105,"T":1626916422002,"s":"BCHUSD_210924","ps":"BCHUSD","U":167006198846,"u":167006198852,"pu":167006198594,"b":[["429.12","40"],["429.23","0"]],"a":[]}}
1626916422.083782: {"stream":"linkusd_perp@depth@100ms","data":{"e":"depthUpdate","E":1626916422111,"T":1626916422039,"s":"LINKUSD_PERP","ps":"LINKUSD","U":167006198877,"u":167006199008,"pu":167006198750,"b":[["15.053","3308"],["15.054","2124"],["15.056","1562"],["15.059","675"]],"a":[]}}
1626916422.0874: {"stream":"trxusd_perp@depth@100ms","data":{"e":"depthUpdate","E":1626916422115,"T":1626916422027,"s":"TRXUSD_PERP","ps":"TRXUSD","U":167006198890,"u":167006198964,"pu":167006198822,"b":[["0.05338","183"],["0.05340","2324"],["0.05343","1470"]],"a":[]}}
1626916422.096021: {"stream":"ethusd_210924@depth@100ms","data":{"e":"depthUpdate","E":1626916422123,"T":1626916422050,"s":"ETHUSD_210924","ps":"ETHUSD","U":167006198918,"u":167006199055,"pu":167006198889,"b":[["1990.46","0"],["1990.70","0"],["1990.74","270"]],"a":[["1991.53","131"]]}}
1626916422.119366: {"stream":"xrpusd_perp@depth@100ms","data":{"e":"depthUpdate","E":1626916422147,"T":1626916422139,"s":"XRPUSD_PERP","ps":"XRPUSD","U":167006199026,"u":167006199438,"pu":167006198587,"b":[["0.5621","11917"],["0.5641","3352"],["0.5660","5172"]],"a":[["0.5667","2743"],["0.5674","10430"]]}}
1626916422.1199381: {"stream":"btcusd_211231@depth@100ms","data":{"e":"depthUpdate","E":1626916422147,"T":1626916422113,"s":"BTCUSD_211231","ps":"BTCUSD","U":167006199020,"u":167006199347,"pu":167006198610,"b":[["32526.7","0"],["32526.9","747"]],"a":[["32631.2","46"],["32631.8","153"],["32631.9","0"],["32632.8","0"]]}}
1626916422.133098: {"stream":"etcusd_perp@depth@100ms","data":{"e":"depthUpdate","E":1626916422161,"T":1626916422158,"s":"ETCUSD_PERP","ps":"ETCUSD","U":167006199079,"u":167006199492,"pu":167006199051,"b":[["42.212","1240"],["42.223","90"],["42.227","1553"],["42.232","0"],["42.234","396"],["42.235","0"],["42.237","381"],["42.241","22"],["42.243","22"],["42.246","0"],["42.248","0"],["42.256","0"],["42.259","202"]],"a":[]}}
1626916422.186638: {"stream":"bchusd_perp@depth@100ms","data":{"e":"depthUpdate","E":1626916422214,"T":1626916422206,"s":"BCHUSD_PERP","ps":"BCHUSD","U":167006199336,"u":167006199694,"pu":167006199255,"b":[["427.26","162"],["427.27","162"],["427.28","162"],["427.29","162"],["427.35","3305"],["427.70","130"],["427.71","336"],["427.72","0"],["427.77","1"]],"a":[["427.80","0"],["427.81","0"],["427.86","100"],["428.02","99"]]}}
1626916422.1939998: {"stream":"bchusd_210924@depth@100ms","data":{"e":"depthUpdate","E":1626916422221,"T":1626916422115,"s":"BCHUSD_210924","ps":"BCHUSD","U":167006199354,"u":167006199355,"pu":167006198852,"b":[["429.12","0"],["429.23","40"]],"a":[]}}
1626916422.24492: {"stream":"etcusd_perp@depth@100ms","data":{"e":"depthUpdate","E":1626916422272,"T":1626916422266,"s":"ETCUSD_PERP","ps":"ETCUSD","U":167006199509,"u":167006199942,"pu":167006199492,"b":[["42.223","0"],["42.227","1553"],["42.233","100"],["42.235","0"],["42.236","25"],["42.240","0"],["42.241","22"],["42.242","90"],["42.243","122"],["42.247","0"],["42.252","0"],["42.253","0"],["42.254","280"],["42.257","0"],["42.259","0"]],"a":[["42.276","535"],["42.277","0"],["42.281","295"],["42.287","0"],["42.288","490"],["42.289","0"],["42.295","34"],["42.297","0"],["42.310","779"],["42.320","0"],["42.331","310"],["42.332","100"],["42.335","497"],["42.341","215"],["42.344","0"],["42.349","0"],["42.368","600"],["42.386","325"],["42.410","70"]]}}
1626916422.245682: {"stream":"linkusd_perp@depth@100ms","data":{"e":"depthUpdate","E":1626916422274,"T":1626916422259,"s":"LINKUSD_PERP","ps":"LINKUSD","U":167006199534,"u":167006199917,"pu":167006199008,"b":[],"a":[["15.069","1267"],["15.106","121"],["15.114","1526"]]}}
1626916422.2503219: {"stream":"xrpusd_perp@depth@100ms","data":{"e":"depthUpdate","E":1626916422278,"T":1626916422192,"s":"XRPUSD_PERP","ps":"XRPUSD","U":167006199555,"u":167006199614,"pu":167006199438,"b":[["0.5659","2638"],["0.5660","5178"],["0.5661","6214"]],"a":[]}}
1626916422.260942: {"stream":"ethusd_210924@depth@100ms","data":{"e":"depthUpdate","E":1626916422288,"T":1626916422263,"s":"ETHUSD_210924","ps":"ETHUSD","U":167006199567,"u":167006199930,"pu":167006199055,"b":[["1977.04","493"],["1990.72","0"],["1990.73","0"]],"a":[["1991.27","480"],["2023.69","0"],["2033.61","0"],["2043.53","0"],["2053.45","0"],["2063.37","0"]]}}
1626916422.281717: {"stream":"eosusd_perp@depth@100ms","data":{"e":"depthUpdate","E":1626916422307,"T":1626916422232,"s":"EOSUSD_PERP","ps":"EOSUSD","U":167006199664,"u":167006199796,"pu":167006198901,"b":[["3.437","2451"],["3.457","3136"]],"a":[["3.478","6652"]]}}
1626916422.295995: {"stream":"trxusd_perp@depth@100ms","data":{"e":"depthUpdate","E":1626916422323,"T":1626916422249,"s":"TRXUSD_PERP","ps":"TRXUSD","U":167006199734,"u":167006199879,"pu":167006198964,"b":[],"a":[["0.05356","992"],["0.05366","982"]]}}
1626916422.298204: {"stream":"bchusd_perp@depth@100ms","data":{"e":"depthUpdate","E":1626916422325,"T":1626916422300,"s":"BCHUSD_PERP","ps":"BCHUSD","U":167006199746,"u":167006200117,"pu":167006199694,"b":[["427.20","200"],["427.41","1809"],["427.47","1239"],["427.50","4530"],["427.59","351"],["427.64","2914"],["427.71","335"]],"a":[["427.81","100"],["427.86","0"],["427.87","0"],["427.99","1889"],["428.06","562"],["428.09","400"],["428.20","1033"],["429.39","264"],["429.50","0"]]}}
1626916422.305901: {"stream":"bchusd_210924@depth@100ms","data":{"e":"depthUpdate","E":1626916422333,"T":1626916422264,"s":"BCHUSD_210924","ps":"BCHUSD","U":167006199779,"u":167006199938,"pu":167006199355,"b":[["428.76","90"],["428.77","4508"],["429.12","0"],["429.23","40"]],"a":[]}}
1626916422.347902: {"stream":"etcusd_perp@depth@100ms","data":{"e":"depthUpdate","E":1626916422375,"T":1626916422364,"s":"ETCUSD_PERP","ps":"ETCUSD","U":167006199963,"u":167006200335,"pu":167006199942,"b":[["39.544","0"],["41.959","0"],["42.210","739"],["42.224","268"],["42.228","563"],["42.229","98"],["42.233","122"],["42.235","22"],["42.236","425"],["42.237","283"],["42.238","0"],["42.241","0"],["42.242","256"],["42.243","0"],["42.251","0"],["42.254","0"]],"a":[["42.272","767"],["42.273","0"],["42.274","351"],["42.275","322"],["42.276","435"],["42.281","0"],["42.288","400"],["42.295","513"],["42.298","100"],["42.309","90"],["42.310","879"],["42.312","1716"],["42.326","0"],["42.331","110"],["42.334","200"],["42.341","15"],["42.358","839"],["42.386","25"]]}}
1626916422.3508549: {"stream":"linkusd_perp@depth@100ms","data":{"e":"depthUpdate","E":1626916422378,"T":1626916422316,"s":"LINKUSD_PERP","ps":"LINKUSD","U":167006199976,"u":167006200159,"pu":167006199917,"b":[["15.057","1259"],["15.059","375"]],"a":[["15.075","1015"],["15.274","0"]]}}
1626916422.369169: {"stream":"xrpusd_perp@depth@100ms","data":{"e":"depthUpdate","E":1626916422393,"T":1626916422370,"s":"XRPUSD_PERP","ps":"XRPUSD","U":167006200025,"u":167006200348,"pu":167006199614,"b":[["0.5644","2857"],["0.5646","694"],["0.5659","2798"],["0.5660","5178"],["0.5661","6054"]],"a":[["0.5679","3477"]]}}
1626916422.369385: {"stream":"btcusd_211231@depth@100ms","data":{"e":"depthUpdate","E":1626916422395,"T":1626916422288,"s":"BTCUSD_211231","ps":"BTCUSD","U":167006200034,"u":167006200038,"pu":167006199347,"b":[["31367.9","0"],["31527.9","0"],["31688.0","0"],["31848.0","0"],["32008.1","0"]],"a":[]}}
1626916422.371684: {"stream":"ethusd_210924@depth@100ms","data":{"e":"depthUpdate","E":1626916422397,"T":1626916422325,"s":"ETHUSD_210924","ps":"ETHUSD","U":167006200062,"u":167006200203,"pu":167006199930,"b":[["1981.03","494"]],"a":[["2023.71","408"],["2033.63","410"],["2043.55","412"],["2053.47","414"],["2063.39","416"]]}}
1626916422.399246: {"stream":"bchusd_perp@depth@100ms","data":{"e":"depthUpdate","E":1626916422425,"T":1626916422407,"s":"BCHUSD_PERP","ps":"BCHUSD","U":167006200184,"u":167006200480,"pu":167006200117,"b":[["427.20","0"],["427.57","0"],["427.64","3014"],["427.77","25"]],"a":[["427.81","0"],["427.88","100"],["427.98","36"],["428.47","236"],["428.54","0"]]}}
1626916422.450878: {"stream":"etcusd_perp@depth@100ms","data":{"e":"depthUpdate","E":1626916422476,"T":1626916422471,"s":"ETCUSD_PERP","ps":"ETCUSD","U":167006200351,"u":167006200760,"pu":167006200335,"b":[["41.947","0"],["41.948","0"],["42.170","215"],["42.182","300"],["42.207","1366"],["42.213","0"],["42.215","56"],["42.218","267"],["42.223","90"],["42.228","473"],["42.246","400"]],"a":[["42.268","0"],["42.269","357"],["42.270","0"],["42.271","150"],["42.272","421"],["42.275","412"],["42.287","0"],["42.298","0"],["42.300","200"],["42.301","22"],["42.304","0"],["42.306","1243"],["42.309","0"],["42.310","779"],["42.316","579"],["42.317","826"],["42.327","0"]]}}
1626916422.461979: {"stream":"eosusd_perp@depth@100ms","data":{"e":"depthUpdate","E":1626916422488,"T":1626916422424,"s":"EOSUSD_PERP","ps":"EOSUSD","U":167006200397,"u":167006200573,"pu":167006199796,"b":[["3.463","2097"],["3.465","9677"],["3.466","5334"],["3.467","2472"],["3.468","0"]],"a":[]}}
1626916422.487944: {"stream":"linkusd_perp@depth@100ms","data":{"e":"depthUpdate","E":1626916422515,"T":1626916422504,"s":"LINKUSD_PERP","ps":"LINKUSD","U":167006200509,"u":167006200873,"pu":167006200159,"b":[["15.018","250"],["15.054","628"],["15.055","1704"],["15.057","959"],["15.058","1266"]],"a":[["15.073","1334"],["15.074","1511"],["15.077","995"],["15.271","7500"]]}}
1626916422.488068: {"stream":"linkusd_211231@depth@100ms","data":{"e":"depthUpdate","E":1626916422515,"T":1626916422442,"s":"LINKUSD_211231","ps":"LINKUSD","U":167006200512,"u":167006200657,"pu":167006197265,"b":[["15.287","0"],["15.294","1359"]],"a":[["15.323","1350"],["15.324","0"],["15.525","0"],["15.600","38"],["15.675","0"],["15.751","0"],["15.826","0"]]}}
1626916422.506916: {"stream":"xrpusd_perp@depth@100ms","data":{"e":"depthUpdate","E":1626916422534,"T":1626916422519,"s":"XRPUSD_PERP","ps":"XRPUSD","U":167006200581,"u":167006200939,"pu":167006200348,"b":[["0.2850","0"],["0.5604","335"]],"a":[]}}
1626916422.529939: {"stream":"bchusd_perp@depth@100ms","data":{"e":"depthUpdate","E":1626916422558,"T":1626916422494,"s":"BCHUSD_PERP","ps":"BCHUSD","U":167006200690,"u":167006200841,"pu":167006200480,"b":[["425.41","210"],["427.50","4730"],["427.77","1"]],"a":[]}}
1626916422.539237: {"stream":"trxusd_perp@depth@100ms","data":{"e":"depthUpdate","E":1626916422567,"T":1626916422463,"s":"TRXUSD_PERP","ps":"TRXUSD","U":167006200713,"u":167006200713,"pu":167006199879,"b":[],"a":[["0.05357","2334"]]}}
1626916422.551889: {"stream":"etcusd_perp@depth@100ms","data":{"e":"depthUpdate","E":1626916422579,"T":1626916422571,"s":"ETCUSD_PERP","ps":"ETCUSD","U":167006200768,"u":167006201131,"pu":167006200760,"b":[["41.912","560"],["41.924","0"],["41.959","2000"],["42.186","487"],["42.210","417"],["42.223","0"],["42.224","290"],["42.227","1575"],["42.233","100"],["42.235","0"],["42.236","515"]],"a":[["42.273","0"],["42.274","351"],["42.275","322"],["42.287","90"],["42.296","371"],["42.350","386"],["42.356","145"],["42.364","0"],["42.478","336"],["42.492","0"]]}}
1626916422.560728: {"stream":"ethusd_210924@depth@100ms","data":{"e":"depthUpdate","E":1626916422589,"T":1626916422568,"s":"ETHUSD_210924","ps":"ETHUSD","U":167006200813,"u":167006201125,"pu":167006200203,"b":[["1987.21","14487"],["1989.33","0"],["1989.77","1684"]],"a":[["1993.38","5685"],["2001.67","1585"]]}}
1626916422.5983229: {"stream":"linkusd_perp@depth@100ms","data":{"e":"depthUpdate","E":1626916422625,"T":1626916422617,"s":"LINKUSD_PERP","ps":"LINKUSD","U":167006200948,"u":167006201382,"pu":167006200873,"b":[["15.061","151"],["15.064","210"]],"a":[["15.073","1334"],["15.076","730"]]}}
1626916422.598476: {"stream":"eosusd_perp@depth@100ms","data":{"e":"depthUpdate","E":1626916422625,"T":1626916422616,"s":"EOSUSD_PERP","ps":"EOSUSD","U":167006200946,"u":167006201374,"pu":167006200573,"b":[["3.462","5433"],["3.463","2017"],["3.465","9757"]],"a":[["3.470","4558"],["3.471","4658"]]}}
1626916422.626302: {"stream":"linkusd_211231@depth@100ms","data":{"e":"depthUpdate","E":1626916422654,"T":1626916422572,"s":"LINKUSD_211231","ps":"LINKUSD","U":167006201063,"u":167006201143,"pu":167006200657,"b":[["15.294","0"],["15.295","123"],["15.296","1335"],["15.298","560"]],"a":[]}}
1626916422.6621141: {"stream":"etcusd_perp@depth@100ms","data":{"e":"depthUpdate","E":1626916422687,"T":1626916422665,"s":"ETCUSD_PERP","ps":"ETCUSD","U":167006201176,"u":167006201562,"pu":167006201131,"b":[["42.216","0"],["42.220","1520"]],"a":[["42.268","100"],["42.269","257"],["42.274","441"],["42.287","0"],["42.299","340"],["42.313","0"],["42.316","256"],["42.329","200"],["42.334","0"]]}}
1626916422.666794: {"stream":"xrpusd_perp@depth@100ms","data":{"e":"depthUpdate","E":1626916422693,"T":1626916422668,"s":"XRPUSD_PERP","ps":"XRPUSD","U":167006201207,"u":167006201586,"pu":167006200939,"b":[["0.5644","3157"],["0.5661","6389"]],"a":[["0.5662","556"],["0.5667","1662"],["0.5674","12711"],["0.5679","3777"]]}}
1626916422.6669571: {"stream":"ethusd_210924@depth@100ms","data":{"e":"depthUpdate","E":1626916422693,"T":1626916422666,"s":"ETHUSD_210924","ps":"ETHUSD","U":167006201208,"u":167006201567,"pu":167006201125,"b":[["1986.95","1159"],["1988.22","0"],["1988.34","779"],["1988.35","0"],["1988.40","0"],["1988.42","120"],["1988.45","0"],["1988.46","0"],["1988.61","0"],["1988.65","0"],["1988.68","1098"],["1988.72","0"],["1988.81","0"],["1988.90","0"],["1989.21","0"],["1989.27","0"],["1989.58","259"],["1989.77","0"],["1989.82","50"],["1990.06","0"],["1990.12","1876"],["1990.39","270"],["1990.74","0"]],"a":[["1992.66","1016"],["1993.38","6217"],["1993.81","0"],["1993.82","0"],["1994.03","0"],["1994.20","0"],["1994.31","0"],["1994.33","0"],["1994.45","0"],["1994.54","0"],["1994.76","0"],["1994.78","0"],["1994.83","0"],["1994.88","0"],["1995.24","0"],["1995.42","2508"],["1995.83","0"]]}}
1626916422.6692438: {"stream":"btcusd_211231@depth@100ms","data":{"e":"depthUpdate","E":1626916422697,"T":1626916422658,"s":"BTCUSD_211231","ps":"BTCUSD","U":167006201219,"u":167006201536,"pu":167006200038,"b":[],"a":[["32625.1","12"],["33273.0","0"]]}}
1626916422.676637: {"stream":"bchusd_210924@depth@100ms","data":{"e":"depthUpdate","E":1626916422705,"T":1626916422618,"s":"BCHUSD_210924","ps":"BCHUSD","U":167006201290,"u":167006201386,"pu":167006199938,"b":[["429.10","289"],["429.11","0"]],"a":[["436.92","0"]]}}
1626916422.685837: {"stream":"trxusd_perp@depth@100ms","data":{"e":"depthUpdate","E":1626916422713,"T":1626916422689,"s":"TRXUSD_PERP","ps":"TRXUSD","U":167006201321,"u":167006201691,"pu":167006200713,"b":[["0.05310","574"],["0.05329","1704"],["0.05343","1470"],["0.05344","933"],["0.05345","291"]],"a":[["0.05362","773"],["0.05383","273"]]}}
1626916422.708158: {"stream":"linkusd_perp@depth@100ms","data":{"e":"depthUpdate","E":1626916422733,"T":1626916422680,"s":"LINKUSD_PERP","ps":"LINKUSD","U":167006201431,"u":167006201627,"pu":167006201382,"b":[["15.057","1071"],["15.058","966"],["15.065","74"]],"a":[]}}
1626916422.721308: {"stream":"bchusd_perp@depth@100ms","data":{"e":"depthUpdate","E":1626916422749,"T":1626916422728,"s":"BCHUSD_PERP","ps":"BCHUSD","U":167006201492,"u":167006201965,"pu":167006200841,"b":[["427.47","492"],["427.50","4530"],["427.56","98"]],"a":[["427.81","100"],["427.82","3039"],["427.88","0"],["427.96","0"],["427.99","2062"],["428.31","3009"],["428.33","0"]]}}
1626916422.773304: {"stream":"btcusd_211231@depth@100ms","data":{"e":"depthUpdate","E":1626916422800,"T":1626916422783,"s":"BTCUSD_211231","ps":"BTCUSD","U":167006201731,"u":167006202362,"pu":167006201536,"b":[["32612.0","0"]],"a":[["32625.1","13"],["32627.3","85"],["32627.4","13"],["32637.5","0"],["32637.9","0"],["32639.1","75"],["33029.0","824"]]}}
1626916422.778692: {"stream":"etcusd_perp@depth@100ms","data":{"e":"depthUpdate","E":1626916422807,"T":1626916422747,"s":"ETCUSD_PERP","ps":"ETCUSD","U":167006201762,"u":167006202145,"pu":167006201562,"b":[["41.959","2000"],["42.208","1096"],["42.225","937"]],"a":[["42.273","90"],["42.274","351"],["42.287","0"],["42.294","310"],["42.316","256"],["42.320","522"],["42.325","0"],["42.335","0"]]}}
1626916422.7853591: {"stream":"ethusd_210924@depth@100ms","data":{"e":"depthUpdate","E":1626916422810,"T":1626916422802,"s":"ETHUSD_210924","ps":"ETHUSD","U":167006201784,"u":167006202475,"pu":167006201567,"b":[["1986.98","0"],["1987.91","474"],["1987.94","406"],["1987.97","372"],["1988.00","906"],["1988.02","304"],["1988.03","440"],["1988.05","846"],["1988.06","486"],["1988.22","338"],["1988.25","237"],["1988.39","237"],["1988.47","203"],["1988.55","169"],["1988.65","169"],["1988.87","203"],["1990.13","270"],["1990.39","0"],["1990.61","0"],["1990.62","125"],["1990.65","360"],["1990.98","235"]],"a":[["1991.14","270"],["1991.41","0"],["1993.82","169"],["1994.03","203"],["1994.18","338"],["1994.31","575"],["1994.35","12"],["1994.45","237"],["1994.54","203"],["1994.76","541"],["1994.78","304"],["1994.81","406"],["1994.85","406"],["1995.20","440"],["1995.39","440"],["1995.67","0"],["1995.83","474"]]}}
1626916422.791179: {"stream":"trxusd_perp@depth@100ms","data":{"e":"depthUpdate","E":1626916422819,"T":1626916422784,"s":"TRXUSD_PERP","ps":"TRXUSD","U":167006201831,"u":167006202368,"pu":167006201691,"b":[["0.05343","1570"],["0.05344","833"]],"a":[["0.05351","2810"]]}}
1626916422.807321: {"stream":"xrpusd_perp@depth@100ms","data":{"e":"depthUpdate","E":1626916422833,"T":1626916422821,"s":"XRPUSD_PERP","ps":"XRPUSD","U":167006201973,"u":167006202547,"pu":167006201586,"b":[["0.5621","5968"],["0.5641","7832"],["0.5646","347"]],"a":[["1.1400","1"]]}}
1626916422.8321621: {"stream":"linkusd_perp@depth@100ms","data":{"e":"depthUpdate","E":1626916422857,"T":1626916422790,"s":"LINKUSD_PERP","ps":"LINKUSD","U":167006202174,"u":167006202390,"pu":167006201627,"b":[["15.066","4"]],"a":[["15.069","3514"],["15.070","2057"]]}}
1626916422.839939: {"stream":"bchusd_perp@depth@100ms","data":{"e":"depthUpdate","E":1626916422867,"T":1626916422862,"s":"BCHUSD_PERP","ps":"BCHUSD","U":167006202240,"u":167006202741,"pu":167006201965,"b":[["424.78","42"],["427.47","590"],["427.56","0"],["427.57","0"],["427.59","51"],["427.64","3014"],["427.69","418"],["427.70","0"],["427.71","0"],["427.77","25"]],"a":[["427.81","130"],["427.82","2909"],["427.88","100"],["427.95","300"],["427.99","1889"]]}}
1626916422.8431628: {"stream":"bchusd_210924@depth@100ms","data":{"e":"depthUpdate","E":1626916422867,"T":1626916422837,"s":"BCHUSD_210924","ps":"BCHUSD","U":167006202234,"u":167006202640,"pu":167006201386,"b":[["429.11","0"],["429.23","40"]],"a":[["435.93","41"]]}}
1626916422.84698: {"stream":"linkusd_211231@depth@100ms","data":{"e":"depthUpdate","E":1626916422873,"T":1626916422767,"s":"LINKUSD_211231","ps":"LINKUSD","U":167006202277,"u":167006202277,"pu":167006201143,"b":[["15.300","0"]],"a":[]}}
1626916422.876508: {"stream":"btcusd_211231@depth@100ms","data":{"e":"depthUpdate","E":1626916422905,"T":1626916422832,"s":"BTCUSD_211231","ps":"BTCUSD","U":167006202447,"u":167006202613,"pu":167006202362,"b":[["32494.0","0"],["32516.8","1955"],["32589.0","0"]],"a":[["32626.6","5"],["32627.2","0"],["32631.1","153"],["32631.8","0"],["32637.7","25"]]}}
1626916422.8793972: {"stream":"etcusd_perp@depth@100ms","data":{"e":"depthUpdate","E":1626916422907,"T":1626916422878,"s":"ETCUSD_PERP","ps":"ETCUSD","U":167006202452,"u":167006202843,"pu":167006202145,"b":[["42.158","145"],["42.168","0"],["42.230","33"]],"a":[["42.299","98"],["42.305","262"]]}}
1626916422.887027: {"stream":"ethusd_210924@depth@100ms","data":{"e":"depthUpdate","E":1626916422913,"T":1626916422908,"s":"ETHUSD_210924","ps":"ETHUSD","U":167006202496,"u":167006202962,"pu":167006202475,"b":[["1986.53","0"],["1990.13","0"],["1990.37","460"],["1990.46","270"],["1990.61","360"],["1990.62","125"],["1990.65","0"],["1990.66","0"],["1990.69","0"],["1990.70","0"]],"a":[["1992.38","0"],["1993.73","169"],["1995.44","0"],["1995.59","474"]]}}
1626916422.90509: {"stream":"trxusd_perp@depth@100ms","data":{"e":"depthUpdate","E":1626916422929,"T":1626916422868,"s":"TRXUSD_PERP","ps":"TRXUSD","U":167006202561,"u":167006202772,"pu":167006202368,"b":[],"a":[["0.05350","3597"],["0.05354","1293"],["0.05363","23971"],["0.05364","2080"],["0.05379","521"]]}}
1626916422.909416: {"stream":"xrpusd_perp@depth@100ms","data":{"e":"depthUpdate","E":1626916422938,"T":1626916422845,"s":"XRPUSD_PERP","ps":"XRPUSD","U":167006202619,"u":167006202673,"pu":167006202547,"b":[["0.5660","5148"],["0.5661","6419"]],"a":[]}}
1626916422.918245: {"stream":"eosusd_perp@depth@100ms","data":{"e":"depthUpdate","E":1626916422944,"T":1626916422839,"s":"EOSUSD_PERP","ps":"EOSUSD","U":167006202646,"u":167006202646,"pu":167006201374,"b":[["3.452","5312"]],"a":[]}}
1626916422.9455569: {"stream":"bchusd_perp@depth@100ms","data":{"e":"depthUpdate","E":1626916422972,"T":1626916422954,"s":"BCHUSD_PERP","ps":"BCHUSD","U":167006202767,"u":167006203243,"pu":167006202741,"b":[["427.63","725"],["427.77","25"]],"a":[["432.23","1"]]}}
1626916422.9542851: {"stream":"linkusd_perp@depth@100ms","data":{"e":"depthUpdate","E":1626916422981,"T":1626916422933,"s":"LINKUSD_PERP","ps":"LINKUSD","U":167006202814,"u":167006203072,"pu":167006202390,"b":[["15.016","797"],["15.053","3308"],["15.055","1704"],["15.066","103"]],"a":[["15.067","290"],["15.069","3414"]]}}
1626916422.975189: {"stream":"linkusd_211231@depth@100ms","data":{"e":"depthUpdate","E":1626916423002,"T":1626916422910,"s":"LINKUSD_211231","ps":"LINKUSD","U":167006202922,"u":167006202968,"pu":167006202277,"b":[],"a":[["15.323","0"],["15.325","987"]]}}
1626916422.9957938: {"stream":"btcusd_211231@depth@100ms","data":{"e":"depthUpdate","E":1626916423023,"T":1626916423012,"s":"BTCUSD_211231","ps":"BTCUSD","U":167006202994,"u":167006203621,"pu":167006202613,"b":[["32585.2","15"],["32622.2","0"]],"a":[["32625.1","75"],["32627.2","153"],["32631.1","0"],["32988.5","876"]]}}
1626916422.9960058: {"stream":"etcusd_perp@depth@100ms","data":{"e":"depthUpdate","E":1626916423023,"T":1626916423008,"s":"ETCUSD_PERP","ps":"ETCUSD","U":167006202993,"u":167006203594,"pu":167006202843,"b":[["42.222","0"],["42.227","2805"],["42.239","400"],["42.240","322"],["42.246","0"]],"a":[["42.272","0"],["42.274","0"],["42.276","0"],["42.287","1173"],["42.316","256"],["42.325","0"]]}}
1626916422.9979699: {"stream":"ethusd_210924@depth@100ms","data":{"e":"depthUpdate","E":1626916423025,"T":1626916423017,"s":"ETHUSD_210924","ps":"ETHUSD","U":167006203016,"u":167006203660,"pu":167006202962,"b":[["1982.05","2000"],["1986.53","1000"],["1987.43","401"],["1988.24","1338"],["1989.14","0"],["1989.82","0"],["1990.37","0"],["1990.45","0"],["1990.61","360"],["1990.62","125"],["1990.65","0"],["1990.66","0"],["1990.69","0"],["1990.70","0"],["1990.98","115"]],"a":[["1990.99","4317"],["1992.08","60"],["1994.06","372"],["1995.44","1000"],["1999.93","1000"]]}}
1626916423.019299: {"stream":"xrpusd_perp@depth@100ms","data":{"e":"depthUpdate","E":1626916423046,"T":1626916423039,"s":"XRPUSD_PERP","ps":"XRPUSD","U":167006203117,"u":167006203843,"pu":167006202673,"b":[["0.5622","316"],["0.5661","5584"]],"a":[["0.5701","1544"]]}}
1626916423.046818: {"stream":"bchusd_perp@depth@100ms","data":{"e":"depthUpdate","E":1626916423074,"T":1626916423047,"s":"BCHUSD_PERP","ps":"BCHUSD","U":167006203350,"u":167006203932,"pu":167006203243,"b":[["426.27","0"],["427.47","1314"],["427.77","1"]],"a":[]}}
1626916423.049483: {"stream":"bchusd_210924@depth@100ms","data":{"e":"depthUpdate","E":1626916423076,"T":1626916422971,"s":"BCHUSD_210924","ps":"BCHUSD","U":167006203357,"u":167006203357,"pu":167006202640,"b":[["429.10","2141"]],"a":[]}}
1626916423.053508: {"stream":"linkusd_perp@depth@100ms","data":{"e":"depthUpdate","E":1626916423081,"T":1626916423058,"s":"LINKUSD_PERP","ps":"LINKUSD","U":167006203399,"u":167006203988,"pu":167006203072,"b":[["15.021","528"],["15.024","391"],["15.026","0"],["15.051","2118"],["15.054","248"],["15.057","959"],["15.060","211"],["15.064","100"],["15.065","0"]],"a":[["15.073","1224"],["15.074","1621"],["15.078","825"]]}}
1626916423.0948071: {"stream":"eosusd_perp@depth@100ms","data":{"e":"depthUpdate","E":1626916423121,"T":1626916423106,"s":"EOSUSD_PERP","ps":"EOSUSD","U":167006203654,"u":167006204422,"pu":167006202646,"b":[["3.468","0"]],"a":[["3.470","4658"],["3.471","4458"],["3.485","5427"],["3.486","437"]]}}
1626916423.094922: {"stream":"linkusd_211231@depth@100ms","data":{"e":"depthUpdate","E":1626916423121,"T":1626916423107,"s":"LINKUSD_211231","ps":"LINKUSD","U":167006203665,"u":167006204437,"pu":167006202968,"b":[["14.761","0"],["14.762","100"],["14.837","0"],["14.838","100"],["14.912","0"],["14.913","100"],["14.987","0"],["14.988","100"],["15.063","0"],["15.064","100"]],"a":[["15.526","164"],["15.601","165"],["15.676","204"],["15.752","167"],["15.827","168"]]}}
1626916423.1177092: {"stream":"ethusd_210924@depth@100ms","data":{"e":"depthUpdate","E":1626916423142,"T":1626916423134,"s":"ETHUSD_210924","ps":"ETHUSD","U":167006203811,"u":167006204735,"pu":167006203660,"b":[["1985.02","1000"],["1987.05","0"],["1987.24","1224"],["1989.29","0"],["1989.32","1030"],["1989.58","0"],["1989.61","0"],["1989.82","50"],["1989.86","259"],["1990.35","0"],["1990.38","0"],["1990.61","0"],["1990.62","0"],["1990.65","360"],["1990.66","126"]],"a":[["1990.60","0"],["1990.99","4587"],["1991.06","400"],["1991.14","0"],["1991.42","0"],["1991.82","581"],["1992.12","0"],["1992.28","0"],["1992.29","0"],["1992.46","400"],["1992.49","0"],["1992.74","0"],["1993.19","549"],["1993.50","0"],["1994.75","500"],["1994.96","1000"],["1998.03","1200"],["2000.28","0"]]}}
1626916423.121987: {"stream":"etcusd_perp@depth@100ms","data":{"e":"depthUpdate","E":1626916423149,"T":1626916423112,"s":"ETCUSD_PERP","ps":"ETCUSD","U":167006203867,"u":167006204467,"pu":167006203594,"b":[],"a":[["42.266","119"],["42.267","0"],["42.268","90"],["42.269","0"],["42.270","0"],["42.273","0"],["42.286","0"],["42.300","233"],["42.316","256"],["42.325","0"],["42.350","1339"]]}}
1626916423.1221912: {"stream":"btcusd_211231@depth@100ms","data":{"e":"depthUpdate","E":1626916423150,"T":1626916423091,"s":"BTCUSD_211231","ps":"BTCUSD","U":167006203877,"u":167006204309,"pu":167006203621,"b":[["31363.5","55"],["31523.5","55"],["31683.5","55"],["31843.5","55"],["32003.5","55"],["32607.3","381"]],"a":[["33034.1","0"],["33194.1","0"],["33354.2","0"],["33514.2","0"],["33674.3","0"]]}}
1626916423.130722: {"stream":"xrpusd_perp@depth@100ms","data":{"e":"depthUpdate","E":1626916423158,"T":1626916423112,"s":"XRPUSD_PERP","ps":"XRPUSD","U":167006203965,"u":167006204469,"pu":167006203843,"b":[["0.5622","916"],["0.5660","5142"],["0.5661","5184"]],"a":[["0.5662","1121"],["0.5701","2144"]]}}
1626916423.165529: {"stream":"bchusd_perp@depth@100ms","data":{"e":"depthUpdate","E":1626916423193,"T":1626916423162,"s":"BCHUSD_PERP","ps":"BCHUSD","U":167006204262,"u":167006205146,"pu":167006203932,"b":[["424.89","1478"],["424.97","0"],["426.08","2363"],["426.16","0"],["426.27","500"],["426.67","1478"],["426.73","0"],["426.76","0"],["426.91","547"],["427.16","0"],["427.27","1640"],["427.35","1827"],["427.36","443"],["427.47","871"],["427.68","0"],["427.69","130"],["427.77","1"]],"a":[["427.80","543"],["428.19","1163"],["428.28","630"],["428.30","1493"],["428.39","0"],["428.87","1478"],["428.95","429"],["429.44","1548"],["429.52","0"],["430.58","1478"],["430.65","0"]]}}
1626916423.1682901: {"stream":"linkusd_perp@depth@100ms","data":{"e":"depthUpdate","E":1626916423195,"T":1626916423185,"s":"LINKUSD_PERP","ps":"LINKUSD","U":167006204277,"u":167006205436,"pu":167006203988,"b":[["14.884","0"],["15.051","1738"],["15.052","560"],["15.053","3508"],["15.060","101"],["15.063","167"]],"a":[["15.104","15253"]]}}
1626916423.200203: {"stream":"eosusd_perp@depth@100ms","data":{"e":"depthUpdate","E":1626916423227,"T":1626916423218,"s":"EOSUSD_PERP","ps":"EOSUSD","U":167006204569,"u":167006205994,"pu":167006204422,"b":[["3.465","9549"],["3.466","3172"],["3.468","0"]],"a":[["3.470","4184"],["3.471","4658"]]}}
1626916423.222316: {"stream":"ethusd_210924@depth@100ms","data":{"e":"depthUpdate","E":1626916423248,"T":1626916423244,"s":"ETHUSD_210924","ps":"ETHUSD","U":167006204874,"u":167006206626,"pu":167006204735,"b":[["1980.04","1000"],["1987.42","0"],["1988.31","5965"],["1989.26","100"],["1989.28","0"],["1989.29","1310"],["1989.31","0"],["1989.32","0"],["1989.82","0"],["1989.94","0"],["1989.95","0"],["1990.11","0"],["1990.13","0"],["1990.29","0"],["1990.34","270"],["1990.46","0"],["1990.57","0"],["1990.58","0"],["1990.59","0"],["1990.65","0"],["1990.66","0"],["1990.67","0"],["1990.98","0"]],"a":[["1990.59","3946"],["1990.60","2777"],["1990.67","737"],["1990.80","20"],["1990.89","0"],["1990.97","4205"],["1990.98","780"],["1990.99","2619"],["1991.15","0"],["1991.27","0"],["1991.37","0"],["1991.53","419"],["1991.85","2363"],["1991.97","0"],["1992.13","952"],["1992.14","404"],["1992.19","0"],["1992.93","0"],["1993.38","532"],["1995.60","0"]]}}
1626916423.2226582: {"stream":"etcusd_perp@depth@100ms","data":{"e":"depthUpdate","E":1626916423250,"T":1626916423243,"s":"ETCUSD_PERP","ps":"ETCUSD","U":167006204884,"u":167006206615,"pu":167006204467,"b":[["42.229","188"],["42.236","425"],["42.239","0"],["42.240","0"],["42.242","0"],["42.243","0"],["42.244","148"]],"a":[["42.266","0"],["42.267","0"],["42.268","100"],["42.269","200"],["42.270","0"],["42.271","150"],["42.272","0"],["42.274","90"],["42.286","0"],["42.310","1301"],["42.320","0"]]}}
1626916423.2322218: {"stream":"trxusd_perp@depth@100ms","data":{"e":"depthUpdate","E":1626916423260,"T":1626916423252,"s":"TRXUSD_PERP","ps":"TRXUSD","U":167006204996,"u":167006206886,"pu":167006202772,"b":[["0.05306","943"],["0.05324","703"],["0.05326","557"],["0.05344","754"],["0.05345","6"]],"a":[["0.05365","3724"],["0.05385","2112"]]}}
1626916423.234098: {"stream":"linkusd_211231@depth@100ms","data":{"e":"depthUpdate","E":1626916423260,"T":1626916423158,"s":"LINKUSD_211231","ps":"LINKUSD","U":167006205035,"u":167006205091,"pu":167006204437,"b":[["14.762","0"],["14.838","0"],["14.913","0"],["14.988","0"],["15.064","0"]],"a":[["15.349","122"],["15.526","0"],["15.601","0"],["15.676","38"],["15.752","0"],["15.827","0"]]}}
1626916423.234591: {"stream":"btcusd_211231@depth@100ms","data":{"e":"depthUpdate","E":1626916423261,"T":1626916423232,"s":"BTCUSD_211231","ps":"BTCUSD","U":167006205039,"u":167006206349,"pu":167006204309,"b":[["32593.8","0"],["32621.2","77"],["32623.3","0"],["32625.0","0"]],"a":[["32621.3","16"],["32621.6","0"],["32622.1","0"],["32623.3","0"],["32623.4","0"],["32625.0","153"],["32625.1","1"],["32625.5","0"],["32626.6","0"],["32627.2","0"],["32644.9","218"],["33027.7","45"],["33187.7","45"],["33347.7","45"],["33507.7","46"],["33667.7","382"]]}}
1626916423.236883: {"stream":"xrpusd_perp@depth@100ms","data":{"e":"depthUpdate","E":1626916423266,"T":1626916423255,"s":"XRPUSD_PERP","ps":"XRPUSD","U":167006205123,"u":167006206996,"pu":167006204469,"b":[["0.5659","2470"],["0.5661","3833"]],"a":[["0.5662","1121"],["0.5664","5637"],["0.5665","5195"]]}}
1626916423.268613: {"stream":"bchusd_perp@depth@100ms","data":{"e":"depthUpdate","E":1626916423296,"T":1626916423285,"s":"BCHUSD_PERP","ps":"BCHUSD","U":167006205528,"u":167006207774,"pu":167006205146,"b":[["427.56","100"],["427.63","425"],["427.64","2914"],["427.65","290"],["427.66","130"],["427.67","1355"],["427.69","0"],["427.77","1"]],"a":[["427.78","638"],["427.81","230"],["427.82","2910"],["427.87","0"],["427.88","0"],["427.99","1888"],["428.01","3821"],["428.23","40"]]}}
1626916423.288467: {"stream":"linkusd_perp@depth@100ms","data":{"e":"depthUpdate","E":1626916423316,"T":1626916423305,"s":"LINKUSD_PERP","ps":"LINKUSD","U":167006205858,"u":167006208311,"pu":167006205436,"b":[["14.874","3751"],["15.054","1547"],["15.055","100"],["15.058","220"],["15.059","0"]],"a":[["15.071","701"],["15.089","0"]]}}
1626916423.307414: {"stream":"eosusd_perp@depth@100ms","data":{"e":"depthUpdate","E":1626916423332,"T":1626916423324,"s":"EOSUSD_PERP","ps":"EOSUSD","U":167006206271,"u":167006208748,"pu":167006205994,"b":[["3.464","5035"],["3.466","4972"],["3.467","2072"]],"a":[["3.471","5120"]]}}
1626916423.323924: {"stream":"ethusd_210924@depth@100ms","data":{"e":"depthUpdate","E":1626916423349,"T":1626916423334,"s":"ETHUSD_210924","ps":"ETHUSD","U":167006206664,"u":167006208873,"pu":167006206626,"b":[["1971.75","1440"],["1972.18","0"],["1981.71","1440"],["1982.14","0"],["1984.55","3600"],["1984.99","0"],["1985.60","2702"],["1986.45","0"],["1986.88","2000"],["1986.91","0"],["1986.94","3741"],["1986.95","532"],["1987.02","0"],["1987.24","1144"],["1987.80","190"],["1987.81","1002"],["1988.38","0"],["1988.75","0"],["1988.89","11306"],["1988.90","4378"],["1989.02","2000"],["1989.05","3600"],["1989.06","1386"],["1989.29","0"],["1989.30","1598"],["1989.38","314"],["1989.50","0"],["1989.51","1080"],["1989.52","0"],["1989.57","1403"],["1989.58","0"],["1989.60","50"],["1989.74","0"],["1989.83","466"],["1989.87","0"],["1989.93","750"],["1989.94","270"],["1990.09","65"],["1990.12","0"],["1990.13","0"],["1990.16","360"],["1990.28","0"],["1990.33","0"],["1990.34","0"],["1990.35","0"],["1990.37","435"],["1990.39","0"],["1990.57","0"],["1990.58","0"],["1990.66","0"],["1990.98","0"]],"a":[["1990.35","0"],["1990.38","1776"],["1990.40","20"],["1990.47","480"],["1990.48","120"],["1990.56","0"],["1990.57","0"],["1990.58","81"],["1990.59","500"],["1990.60","0"],["1990.65","794"],["1990.66","2269"],["1990.67","0"],["1990.73","650"],["1990.89","1238"],["1990.98","0"],["1991.06","0"],["1991.35","0"],["1991.53","678"],["1991.54","280"],["1991.82","322"],["1991.84","60"],["1991.93","0"],["1991.96","0"],["1992.08","0"],["1992.16","1395"],["1992.18","0"],["1992.46","0"],["1992.55","0"],["1992.62","0"],["1992.82","0"],["1992.88","0"],["1992.89","369"],["1993.08","0"],["1993.19","469"],["1993.46","1000"],["1993.55","1080"],["1993.98","0"],["1994.25","3612"],["1994.45","737"],["1994.68","0"],["1994.71","270"],["1994.86","1000"],["1995.29","0"],["1995.30","190"],["1995.75","500"],["1996.10","0"],["1996.40","0"],["2001.33","3600"],["2001.61","1440"],["2001.75","0"],["2002.04","0"],["2011.57","1440"],["2012.00","0"],["2023.71","0"],["2033.63","0"],["2043.55","0"],["2053.47","0"],["2063.39","0"]]}}
1626916423.325027: {"stream":"etcusd_perp@depth@100ms","data":{"e":"depthUpdate","E":1626916423351,"T":1626916423336,"s":"ETCUSD_PERP","ps":"ETCUSD","U":167006206748,"u":167006208900,"pu":167006206615,"b":[["42.227","1674"],["42.229","98"],["42.238","90"],["42.242","300"],["42.244","0"]],"a":[["42.268","100"],["42.270","0"],["42.310","1501"],["42.316","56"]]}}
1626916423.3539588: {"stream":"btcusd_211231@depth@100ms","data":{"e":"depthUpdate","E":1626916423381,"T":1626916423367,"s":"BTCUSD_211231","ps":"BTCUSD","U":167006207553,"u":167006209428,"pu":167006206349,"b":[["32584.4","15"],["32585.2","0"],["32618.1","175"]],"a":[["32642.0","0"]]}}
1626916423.3691368: {"stream":"bchusd_perp@depth@100ms","data":{"e":"depthUpdate","E":1626916423397,"T":1626916423384,"s":"BCHUSD_PERP","ps":"BCHUSD","U":167006207972,"u":167006209643,"pu":167006207774,"b":[["425.63","42"],["427.07","114"],["427.14","405"],["427.50","3947"],["427.56","184"],["427.77","1"]],"a":[["427.89","101"],["427.92","0"],["427.95","718"],["428.01","4021"],["428.03","0"],["428.06","445"],["428.07","0"],["428.09","200"],["428.12","822"],["428.19","1119"],["428.52","467"],["428.60","0"],["429.13","590"],["429.21","264"],["429.29","0"],["429.64","0"]]}}
1626916423.3776178: {"stream":"trxusd_perp@depth@100ms","data":{"e":"depthUpdate","E":1626916423404,"T":1626916423386,"s":"TRXUSD_PERP","ps":"TRXUSD","U":167006208116,"u":167006209663,"pu":167006206886,"b":[["0.05309","2410"],["0.05311","2277"],["0.05312","1997"],["0.05341","2122"],["0.05343","1448"]],"a":[["0.05348","349"],["0.05382","300"]]}}
1626916423.392373: {"stream":"linkusd_perp@depth@100ms","data":{"e":"depthUpdate","E":1626916423417,"T":1626916423401,"s":"LINKUSD_PERP","ps":"LINKUSD","U":167006208419,"u":167006209862,"pu":167006208311,"b":[["15.036","1032"],["15.059","110"],["15.063","157"],["15.064","0"]],"a":[["15.075","1395"],["15.076","350"],["15.120","1600"],["15.123","0"]]}}
1626916423.3926039: {"stream":"bchusd_210924@depth@100ms","data":{"e":"depthUpdate","E":1626916423418,"T":1626916423314,"s":"BCHUSD_210924","ps":"BCHUSD","U":167006208495,"u":167006208501,"pu":167006203357,"b":[["429.10","2009"]],"a":[["429.60","126"]]}}
1626916423.399091: {"stream":"linkusd_211231@depth@100ms","data":{"e":"depthUpdate","E":1626916423424,"T":1626916423343,"s":"LINKUSD_211231","ps":"LINKUSD","U":167006208642,"u":167006208978,"pu":167006205091,"b":[["15.292","0"],["15.294","1256"],["15.296","0"]],"a":[]}}
1626916423.4167209: {"stream":"eosusd_perp@depth@100ms","data":{"e":"depthUpdate","E":1626916423443,"T":1626916423426,"s":"EOSUSD_PERP","ps":"EOSUSD","U":167006208918,"u":167006210113,"pu":167006208748,"b":[["3.466","4872"],["3.467","962"],["3.468","0"]],"a":[["3.468","216"],["3.469","2103"],["3.470","4643"],["3.471","5387"]]}}
1626916423.425001: {"stream":"xrpusd_perp@depth@100ms","data":{"e":"depthUpdate","E":1626916423450,"T":1626916423445,"s":"XRPUSD_PERP","ps":"XRPUSD","U":167006209053,"u":167006210283,"pu":167006206996,"b":[["0.5660","5172"],["0.5661","3803"],["0.5662","0"]],"a":[["0.5662","672"],["0.5664","5337"],["0.5665","5195"],["0.5668","4324"]]}}
1626916423.4251242: {"stream":"ethusd_210924@depth@100ms","data":{"e":"depthUpdate","E":1626916423449,"T":1626916423438,"s":"ETHUSD_210924","ps":"ETHUSD","U":167006208964,"u":167006210213,"pu":167006208873,"b":[["1840.53","4554"],["1975.12","10739"],["1983.01","0"],["1986.01","2000"],["1986.28","783"],["1986.38","626"],["1986.95","0"],["1987.16","0"],["1987.37","0"],["1987.74","425"],["1987.80","0"],["1988.11","404"],["1988.32","1033"],["1988.62","259"],["1988.68","0"],["1988.85","0"],["1989.00","322"],["1989.13","62"],["1989.39","0"],["1989.55","0"],["1989.57","0"],["1989.60","0"],["1989.61","0"],["1989.71","0"],["1989.76","0"],["1989.77","1581"],["1989.86","0"],["1989.87","270"],["1989.94","0"],["1989.96","360"],["1989.99","0"],["1990.02","0"],["1990.09","0"],["1990.16","0"]],"a":[["1990.65","1064"],["1990.74","350"],["1990.99","2349"],["1991.26","1149"],["1991.27","3285"],["1991.65","955"],["1991.83","1207"],["1991.84","60"],["1992.08","425"],["1992.09","100"],["1992.14","1579"],["1992.16","50"],["1992.17","0"],["1992.33","1281"],["1992.66","0"],["1994.64","4000"],["1995.30","0"],["2022.94","408"],["2032.86","410"],["2042.77","412"],["2052.69","414"],["2062.61","416"]]}}
1626916423.43286: {"stream":"etcusd_perp@depth@100ms","data":{"e":"depthUpdate","E":1626916423460,"T":1626916423447,"s":"ETCUSD_PERP","ps":"ETCUSD","U":167006209287,"u":167006210311,"pu":167006208900,"b":[["42.210","217"],["42.235","450"],["42.237","363"],["42.238","0"],["42.242","0"],["42.243","109"],["42.244","0"]],"a":[["42.274","90"],["42.275","0"],["42.286","0"],["42.293","38"],["42.298","322"],["42.310","1815"],["42.317","1026"],["42.325","0"],["42.331","1035"]]}}
1626916423.4577239: {"stream":"btcusd_211231@depth@100ms","data":{"e":"depthUpdate","E":1626916423484,"T":1626916423460,"s":"BTCUSD_211231","ps":"BTCUSD","U":167006209595,"u":167006210411,"pu":167006209428,"b":[["32526.8","0"],["32527.0","977"],["32610.1","0"],["32610.2","0"],["32612.4","0"],["32614.1","0"]],"a":[["32625.0","0"],["32627.2","153"]]}}
1626916423.471942: {"stream":"bchusd_perp@depth@100ms","data":{"e":"depthUpdate","E":1626916423498,"T":1626916423489,"s":"BCHUSD_PERP","ps":"BCHUSD","U":167006209700,"u":167006210594,"pu":167006209643,"b":[["426.40","0"],["427.44","0"],["427.56","0"],["427.64","3014"],["427.77","25"]],"a":[["427.81","130"],["427.88","100"],["427.98","136"],["428.00","1397"],["428.06","345"],["428.94","0"],["430.54","0"]]}}
1626916423.4804301: {"stream":"trxusd_perp@depth@100ms","data":{"e":"depthUpdate","E":1626916423509,"T":1626916423499,"s":"TRXUSD_PERP","ps":"TRXUSD","U":167006209881,"u":167006210654,"pu":167006209663,"b":[["0.05340","2438"],["0.05342","974"]],"a":[["0.05347","20245"]]}}
1626916423.501981: {"stream":"linkusd_perp@depth@100ms","data":{"e":"depthUpdate","E":1626916423530,"T":1626916423516,"s":"LINKUSD_PERP","ps":"LINKUSD","U":167006210125,"u":167006210774,"pu":167006209862,"b":[["15.033","15615"],["15.037","3519"],["15.041","526"],["15.046","1074"],["15.049","0"],["15.050","460"],["15.051","2118"],["15.052","180"],["15.053","3308"],["15.054","248"],["15.055","100"],["15.057","1037"],["15.061","0"]],"a":[["15.077","1115"]]}}
1626916423.515983: {"stream":"bchusd_210924@depth@100ms","data":{"e":"depthUpdate","E":1626916423541,"T":1626916423440,"s":"BCHUSD_210924","ps":"BCHUSD","U":167006210197,"u":167006210240,"pu":167006208501,"b":[],"a":[["429.72","120"],["429.75","0"]]}}
1626916423.523444: {"stream":"linkusd_211231@depth@100ms","data":{"e":"depthUpdate","E":1626916423549,"T":1626916423534,"s":"LINKUSD_211231","ps":"LINKUSD","U":167006210267,"u":167006210890,"pu":167006208978,"b":[["3.141","770"],["15.287","1231"],["15.294","0"],["15.296","0"]],"a":[["15.325","1087"],["15.326","40"],["15.329","0"],["15.342","162"]]}}
1626916423.524418: {"stream":"ethusd_210924@depth@100ms","data":{"e":"depthUpdate","E":1626916423551,"T":1626916423538,"s":"ETHUSD_210924","ps":"ETHUSD","U":167006210288,"u":167006210923,"pu":167006210213,"b":[["1839.26","4552"],["1840.53","2277"],["1986.12","0"],["1986.18","532"],["1986.23","501"],["1986.53","6720"],["1987.87","1217"],["1988.32","3509"],["1988.49","0"],["1988.62","0"],["1989.13","12"],["1989.29","280"],["1989.39","50"],["1989.43","259"],["1989.61","0"],["1989.78","554"],["1989.87","270"],["1989.94","262"],["1989.97","127"]],"a":[["1990.66","3507"],["1990.89","0"],["1991.58","363"],["1992.15","1953"],["1992.78","5747"],["1994.84","0"],["1997.40","190"],["2032.85","0"]]}}
1626916423.529037: {"stream":"xrpusd_perp@depth@100ms","data":{"e":"depthUpdate","E":1626916423555,"T":1626916423453,"s":"XRPUSD_PERP","ps":"XRPUSD","U":167006210327,"u":167006210344,"pu":167006210283,"b":[["0.5654","15079"],["0.5659","2170"]],"a":[["0.5664","5637"]]}}
1626916423.535321: {"stream":"etcusd_perp@depth@100ms","data":{"e":"depthUpdate","E":1626916423562,"T":1626916423537,"s":"ETCUSD_PERP","ps":"ETCUSD","U":167006210399,"u":167006210917,"pu":167006210311,"b":[["42.234","486"],["42.237","363"],["42.243","19"]],"a":[["42.266","0"],["42.267","0"],["42.268","100"],["42.273","90"],["42.274","0"],["42.286","0"],["42.299","713"],["42.310","1293"]]}}
1626916423.555874: {"stream":"eosusd_perp@depth@100ms","data":{"e":"depthUpdate","E":1626916423582,"T":1626916423527,"s":"EOSUSD_PERP","ps":"EOSUSD","U":167006210513,"u":167006210849,"pu":167006210113,"b":[["3.455","13500"],["3.456","812"]],"a":[["3.474","4915"],["3.475","2102"]]}}
1626916423.556024: {"stream":"btcusd_211231@depth@100ms","data":{"e":"depthUpdate","E":1626916423584,"T":1626916423570,"s":"BTCUSD_211231","ps":"BTCUSD","U":167006210520,"u":167006211109,"pu":167006210411,"b":[["31363.5","0"],["31523.5","0"],["31683.5","0"],["31843.5","0"],["32003.5","0"]],"a":[["32626.3","46"],["32631.2","0"],["33027.7","0"],["33187.7","0"],["33347.7","0"],["33507.7","0"],["33667.7","336"]]}}
1626916423.569637: {"stream":"bchusd_perp@depth@100ms","data":{"e":"depthUpdate","E":1626916423598,"T":1626916423585,"s":"BCHUSD_PERP","ps":"BCHUSD","U":167006210611,"u":167006211177,"pu":167006210594,"b":[["426.32","264"],["427.38","44"],["427.57","0"]],"a":[["427.81","230"],["427.88","0"],["428.03","200"],["428.09","0"],["430.45","440"]]}}
1626916423.6125708: {"stream":"trxusd_perp@depth@100ms","data":{"e":"depthUpdate","E":1626916423639,"T":1626916423553,"s":"TRXUSD_PERP","ps":"TRXUSD","U":167006210893,"u":167006211008,"pu":167006210654,"b":[["0.05341","2222"],["0.05344","654"],["0.05345","194"]],"a":[]}}
1626916423.612716: {"stream":"linkusd_perp@depth@100ms","data":{"e":"depthUpdate","E":1626916423639,"T":1626916423568,"s":"LINKUSD_PERP","ps":"LINKUSD","U":167006210896,"u":167006211092,"pu":167006210774,"b":[["15.055","100"],["15.057","959"],["15.059","0"],["15.060","252"],["15.061","198"]],"a":[["15.071","801"],["15.073","1424"],["15.074","1741"],["15.075","995"]]}}
1626916423.629262: {"stream":"ethusd_210924@depth@100ms","data":{"e":"depthUpdate","E":1626916423656,"T":1626916423649,"s":"ETHUSD_210924","ps":"ETHUSD","U":167006210986,"u":167006211456,"pu":167006210923,"b":[["1987.53","100"],["1987.54","1936"],["1987.78","565"],["1988.07","1002"],["1988.24","338"],["1988.43","1272"],["1988.72","1000"],["1989.62","1750"],["1989.96","0"],["1989.97","0"],["1990.00","0"],["1990.01","0"],["1990.04","0"],["1990.05","0"],["1990.08","360"],["1990.09","126"]],"a":[["1990.78","1000"],["1994.73","565"],["1995.19","999"],["2022.94","0"],["2032.86","0"],["2042.77","0"],["2052.69","0"],["2062.61","0"]]}}
1626916423.6462028: {"stream":"etcusd_perp@depth@100ms","data":{"e":"depthUpdate","E":1626916423673,"T":1626916423661,"s":"ETCUSD_PERP","ps":"ETCUSD","U":167006211087,"u":167006211505,"pu":167006210917,"b":[["42.237","283"],["42.238","400"],["42.243","14"]],"a":[["42.268","106"],["42.269","0"],["42.272","90"],["42.273","0"],["42.286","0"]]}}
1626916423.646823: {"stream":"xrpusd_perp@depth@100ms","data":{"e":"depthUpdate","E":1626916423675,"T":1626916423589,"s":"XRPUSD_PERP","ps":"XRPUSD","U":167006211111,"u":167006211194,"pu":167006210344,"b":[["0.5654","14779"],["0.5660","5472"]],"a":[["0.5662","724"]]}}
1626916423.6664581: {"stream":"btcusd_211231@depth@100ms","data":{"e":"depthUpdate","E":1626916423694,"T":1626916423640,"s":"BTCUSD_211231","ps":"BTCUSD","U":167006211197,"u":167006211414,"pu":167006211109,"b":[],"a":[["32625.8","46"],["32626.2","153"],["32626.3","0"],["32627.2","0"],["32877.0","976"],["32914.2","0"]]}}
1626916423.6878378: {"stream":"linkusd_211231@depth@100ms","data":{"e":"depthUpdate","E":1626916423714,"T":1626916423701,"s":"LINKUSD_211231","ps":"LINKUSD","U":167006211292,"u":167006211799,"pu":167006210890,"b":[],"a":[["15.324","50"],["15.524","164"],["15.599","165"],["15.674","166"],["15.750","167"],["15.825","168"]]}}
1626916423.742901: {"stream":"ethusd_210924@depth@100ms","data":{"e":"depthUpdate","E":1626916423769,"T":1626916423724,"s":"ETHUSD_210924","ps":"ETHUSD","U":167006211513,"u":167006211931,"pu":167006211456,"b":[["1986.30","190"],["1987.46","4000"],["1989.87","0"],["1990.08","0"],["1990.09","0"],["1990.10","270"],["1990.12","0"],["1990.13","127"],["1990.14","360"],["1990.37","426"]],"a":[["2029.35","2534"]]}}
1626916423.747165: {"stream":"etcusd_perp@depth@100ms","data":{"e":"depthUpdate","E":1626916423776,"T":1626916423771,"s":"ETCUSD_PERP","ps":"ETCUSD","U":167006211582,"u":167006212200,"pu":167006211505,"b":[["42.227","444"],["42.231","1230"],["42.234","396"],["42.241","300"],["42.244","90"]],"a":[["42.272","0"],["42.285","582"],["42.286","90"],["42.317","826"],["42.325","200"],["42.345","70"]]}}
1626916423.7503822: {"stream":"linkusd_perp@depth@100ms","data":{"e":"depthUpdate","E":1626916423778,"T":1626916423732,"s":"LINKUSD_PERP","ps":"LINKUSD","U":167006211597,"u":167006211970,"pu":167006211092,"b":[["14.699","0"],["15.050","1692"]],"a":[["15.831","0"]]}}
1626916423.752576: {"stream":"bchusd_perp@depth@100ms","data":{"e":"depthUpdate","E":1626916423781,"T":1626916423757,"s":"BCHUSD_PERP","ps":"BCHUSD","U":167006211616,"u":167006212134,"pu":167006211177,"b":[["427.29","792"],["427.51","270"]],"a":[["427.81","130"],["427.88","100"],["429.25","1048"]]}}
1626916423.753118: {"stream":"bchusd_210924@depth@100ms","data":{"e":"depthUpdate","E":1626916423781,"T":1626916423718,"s":"BCHUSD_210924","ps":"BCHUSD","U":167006211617,"u":167006211887,"pu":167006210240,"b":[["428.74","3663"],["429.35","0"]],"a":[]}}
1626916423.7665222: {"stream":"xrpusd_perp@depth@100ms","data":{"e":"depthUpdate","E":1626916423793,"T":1626916423789,"s":"XRPUSD_PERP","ps":"XRPUSD","U":167006211681,"u":167006212290,"pu":167006211194,"b":[["0.5621","11917"],["0.5641","3352"],["0.5661","4303"]],"a":[["0.5667","1662"],["0.5674","12731"]]}}
1626916423.777057: {"stream":"btcusd_211231@depth@100ms","data":{"e":"depthUpdate","E":1626916423803,"T":1626916423791,"s":"BTCUSD_211231","ps":"BTCUSD","U":167006211788,"u":167006212306,"pu":167006211414,"b":[["31362.6","55"],["31522.6","55"],["31682.6","55"],["31842.6","55"],["32002.7","55"]],"a":[["32621.3","17"],["32625.1","0"],["32626.2","0"],["32627.2","0"],["32634.8","153"]]}}
1626916423.795298: {"stream":"linkusd_211231@depth@100ms","data":{"e":"depthUpdate","E":1626916423820,"T":1626916423715,"s":"LINKUSD_211231","ps":"LINKUSD","U":167006211881,"u":167006211881,"pu":167006211799,"b":[],"a":[["15.324","89"]]}}
1626916423.835083: {"stream":"eosusd_perp@depth@100ms","data":{"e":"depthUpdate","E":1626916423862,"T":1626916423764,"s":"EOSUSD_PERP","ps":"EOSUSD","U":167006212130,"u":167006212171,"pu":167006210849,"b":[["3.444","9977"],["3.451","3936"]],"a":[]}}
1626916423.847873: {"stream":"ethusd_210924@depth@100ms","data":{"e":"depthUpdate","E":1626916423874,"T":1626916423868,"s":"ETHUSD_210924","ps":"ETHUSD","U":167006212195,"u":167006212595,"pu":167006211931,"b":[["1699.97","0"],["1839.26","6828"],["1840.37","2277"],["1983.82","0"],["1986.30","0"]],"a":[["1990.38","1525"],["1990.65","794"],["1990.96","270"],["1997.40","0"]]}}
1626916423.851012: {"stream":"etcusd_perp@depth@100ms","data":{"e":"depthUpdate","E":1626916423878,"T":1626916423779,"s":"ETCUSD_PERP","ps":"ETCUSD","U":167006212207,"u":167006212249,"pu":167006212200,"b":[["42.210","17"],["42.215","256"],["42.241","0"],["42.244","103"]],"a":[["42.316","256"],["42.325","0"]]}}
1626916423.855746: {"stream":"linkusd_perp@depth@100ms","data":{"e":"depthUpdate","E":1626916423882,"T":1626916423803,"s":"LINKUSD_PERP","ps":"LINKUSD","U":167006212242,"u":167006212337,"pu":167006211970,"b":[],"a":[["15.078","899"],["15.080","779"]]}}
1626916423.8780868: {"stream":"btcusd_211231@depth@100ms","data":{"e":"depthUpdate","E":1626916423907,"T":1626916423825,"s":"BTCUSD_211231","ps":"BTCUSD","U":167006212339,"u":167006212423,"pu":167006212306,"b":[],"a":[["32634.7","152"],["32634.8","153"],["32637.6","0"]]}}
1626916423.885095: {"stream":"xrpusd_perp@depth@100ms","data":{"e":"depthUpdate","E":1626916423913,"T":1626916423897,"s":"XRPUSD_PERP","ps":"XRPUSD","U":167006212370,"u":167006212696,"pu":167006212290,"b":[["0.2830","13443"],["0.5621","5968"],["0.5641","7830"],["0.5646","697"],["0.5660","5442"],["0.5661","4333"]],"a":[["0.5662","564"]]}}
1626916423.8898041: {"stream":"bchusd_perp@depth@100ms","data":{"e":"depthUpdate","E":1626916423918,"T":1626916423896,"s":"BCHUSD_PERP","ps":"BCHUSD","U":167006212379,"u":167006212677,"pu":167006212134,"b":[["427.58","300"],["427.77","1"]],"a":[["427.81","230"],["427.88","0"]]}}
1626916423.911298: {"stream":"bchusd_210924@depth@100ms","data":{"e":"depthUpdate","E":1626916423937,"T":1626916423831,"s":"BCHUSD_210924","ps":"BCHUSD","U":167006212446,"u":167006212446,"pu":167006211887,"b":[["428.93","403"]],"a":[]}}
1626916423.948305: {"stream":"ethusd_210924@depth@100ms","data":{"e":"depthUpdate","E":1626916423975,"T":1626916423966,"s":"ETHUSD_210924","ps":"ETHUSD","U":167006212601,"u":167006213015,"pu":167006212595,"b":[["1982.41","4906"],["1982.47","1864"],["1983.91","0"],["1988.91","2167"],["1989.83","516"],["1989.84","270"],["1990.10","0"]],"a":[["1990.65","1064"],["1990.95","1564"],["1990.96","0"],["1992.54","0"],["1992.57","0"],["1997.10","190"]]}}
1626916423.962878: {"stream":"eosusd_perp@depth@100ms","data":{"e":"depthUpdate","E":1626916423990,"T":1626916423949,"s":"EOSUSD_PERP","ps":"EOSUSD","U":167006212650,"u":167006212881,"pu":167006212171,"b":[["3.431","207"],["3.452","5559"]],"a":[]}}
1626916423.9651499: {"stream":"linkusd_perp@depth@100ms","data":{"e":"depthUpdate","E":1626916423990,"T":1626916423941,"s":"LINKUSD_PERP","ps":"LINKUSD","U":167006212652,"u":167006212858,"pu":167006212337,"b":[["14.646","3628"],["15.014","1660"]],"a":[]}}
1626916423.981505: {"stream":"linkusd_211231@depth@100ms","data":{"e":"depthUpdate","E":1626916424006,"T":1626916423901,"s":"LINKUSD_211231","ps":"LINKUSD","U":167006212721,"u":167006212721,"pu":167006211881,"b":[],"a":[["15.325","987"]]}}
1626916423.986156: {"stream":"xrpusd_perp@depth@100ms","data":{"e":"depthUpdate","E":1626916424013,"T":1626916424007,"s":"XRPUSD_PERP","ps":"XRPUSD","U":167006212744,"u":167006213232,"pu":167006212696,"b":[["0.5655","4972"],["0.5660","5142"],["0.5661","4333"],["0.5662","0"]],"a":[["0.5662","873"],["0.5664","5337"],["0.5665","5495"]]}}
1626916424.065239: {"stream":"ethusd_210924@depth@100ms","data":{"e":"depthUpdate","E":1626916424091,"T":1626916424074,"s":"ETHUSD_210924","ps":"ETHUSD","U":167006213167,"u":167006213532,"pu":167006213015,"b":[["1702.29","2125"],["1986.75","80"],["1987.53","0"],["1988.91","2481"],["1989.31","301"],["1989.38","0"],["1989.84","0"],["1989.97","360"],["1990.13","0"],["1990.14","270"],["1990.15","0"],["1990.18","0"],["1990.19","127"]],"a":[["1990.40","0"],["1990.80","0"],["1991.62","301"],["1992.78","5827"],["1992.84","314"],["1992.89","289"],["1993.35","0"],["2005.94","11300"],["2008.08","0"]]}}
1626916424.068535: {"stream":"etcusd_perp@depth@100ms","data":{"e":"depthUpdate","E":1626916424096,"T":1626916424077,"s":"ETCUSD_PERP","ps":"ETCUSD","U":167006213179,"u":167006213538,"pu":167006212249,"b":[["42.210","217"],["42.215","56"],["42.238","0"]],"a":[]}}
1626916424.081067: {"stream":"linkusd_perp@depth@100ms","data":{"e":"depthUpdate","E":1626916424108,"T":1626916424091,"s":"LINKUSD_PERP","ps":"LINKUSD","U":167006213220,"u":167006213593,"pu":167006212858,"b":[["15.021","678"],["15.024","539"],["15.026","148"],["15.057","1021"]],"a":[["15.820","347"]]}}
1626916424.0993211: {"stream":"xrpusd_perp@depth@100ms","data":{"e":"depthUpdate","E":1626916424128,"T":1626916424050,"s":"XRPUSD_PERP","ps":"XRPUSD","U":167006213317,"u":167006213418,"pu":167006213232,"b":[],"a":[["0.5664","5637"],["0.5665","5195"],["1.1300","54101"]]}}
1626916424.118338: {"stream":"btcusd_211231@depth@100ms","data":{"e":"depthUpdate","E":1626916424139,"T":1626916424033,"s":"BTCUSD_211231","ps":"BTCUSD","U":167006213346,"u":167006213349,"pu":167006212423,"b":[["32526.9","0"],["32527.1","508"]],"a":[]}}
1626916424.131967: {"stream":"trxusd_perp@depth@100ms","data":{"e":"depthUpdate","E":1626916424159,"T":1626916424085,"s":"TRXUSD_PERP","ps":"TRXUSD","U":167006213447,"u":167006213583,"pu":167006211008,"b":[["0.05337","3192"],["0.05338","83"]],"a":[]}}
1626916424.1699562: {"stream":"ethusd_210924@depth@100ms","data":{"e":"depthUpdate","E":1626916424196,"T":1626916424187,"s":"ETHUSD_210924","ps":"ETHUSD","U":167006213589,"u":167006213992,"pu":167006213532,"b":[["1839.26","11380"],["1839.27","2276"],["1840.29","0"],["1840.36","0"],["1840.81","2278"],["1986.60","190"],["1986.82","0"],["1987.73","100"],["1989.16","1500"],["1989.70","0"],["1989.97","0"],["1990.15","94"],["1990.19","360"],["1990.20","126"],["1990.37","486"]],"a":[["1991.58","423"],["1991.84","0"],["1992.90","1500"],["1993.28","12"],["1993.38","544"],["1993.49","0"],["1996.33","3000"],["1997.63","0"],["1997.73","0"],["1997.76","0"]]}}
1626916424.20221: {"stream":"etcusd_perp@depth@100ms","data":{"e":"depthUpdate","E":1626916424231,"T":1626916424198,"s":"ETCUSD_PERP","ps":"ETCUSD","U":167006213727,"u":167006214075,"pu":167006213538,"b":[["42.038","63"],["42.232","400"],["42.242","300"],["42.244","90"]],"a":[["42.298","969"],["42.299","98"],["42.316","256"],["42.325","0"],["42.416","59"]]}}
1626916424.202421: {"stream":"linkusd_perp@depth@100ms","data":{"e":"depthUpdate","E":1626916424230,"T":1626916424220,"s":"LINKUSD_PERP","ps":"LINKUSD","U":167006213715,"u":167006214194,"pu":167006213593,"b":[["14.978","86"],["15.019","301"],["15.050","460"],["15.051","3303"]],"a":[["15.069","3414"],["15.071","501"],["15.075","615"],["15.077","1495"],["15.104","15403"]]}}
1626916424.2163699: {"stream":"bchusd_perp@depth@100ms","data":{"e":"depthUpdate","E":1626916424243,"T":1626916424228,"s":"BCHUSD_PERP","ps":"BCHUSD","U":167006213767,"u":167006214234,"pu":167006212677,"b":[["427.46","3009"],["427.48","0"],["427.77","1"]],"a":[["427.78","768"],["427.80","1101"],["427.81","0"],["427.87","27"],["427.88","100"],["427.98","336"],["428.03","0"],["428.10","298"],["428.23","3049"],["428.31","0"]]}}
1626916424.237659: {"stream":"eosusd_perp@depth@100ms","data":{"e":"depthUpdate","E":1626916424264,"T":1626916424160,"s":"EOSUSD_PERP","ps":"EOSUSD","U":167006213867,"u":167006213869,"pu":167006212881,"b":[],"a":[["3.485","5678"],["3.486","690"]]}}
1626916424.246769: {"stream":"btcusd_211231@depth@100ms","data":{"e":"depthUpdate","E":1626916424274,"T":1626916424263,"s":"BTCUSD_211231","ps":"BTCUSD","U":167006213899,"u":167006214430,"pu":167006213349,"b":[["32614.1","181"]],"a":[["32625.8","0"],["32626.8","46"],["32627.3","238"],["32634.8","0"],["32887.2","0"]]}}
1626916424.264459: {"stream":"linkusd_211231@depth@100ms","data":{"e":"depthUpdate","E":1626916424291,"T":1626916424184,"s":"LINKUSD_211231","ps":"LINKUSD","U":167006213978,"u":167006213978,"pu":167006212721,"b":[],"a":[["15.324","39"]]}}
1626916424.266864: {"stream":"xrpusd_perp@depth@100ms","data":{"e":"depthUpdate","E":1626916424293,"T":1626916424273,"s":"XRPUSD_PERP","ps":"XRPUSD","U":167006213986,"u":167006214470,"pu":167006213418,"b":[["0.5655","4672"],["0.5657","5740"],["0.5660","5442"],["0.5661","4060"]],"a":[["0.5662","564"]]}}
1626916424.279242: {"stream":"bchusd_210924@depth@100ms","data":{"e":"depthUpdate","E":1626916424304,"T":1626916424198,"s":"BCHUSD_210924","ps":"BCHUSD","U":167006214076,"u":167006214076,"pu":167006212446,"b":[["429.11","807"]],"a":[]}}
1626916424.280431: {"stream":"trxusd_perp@depth@100ms","data":{"e":"depthUpdate","E":1626916424308,"T":1626916424203,"s":"TRXUSD_PERP","ps":"TRXUSD","U":167006214095,"u":167006214095,"pu":167006213583,"b":[["0.05324","951"]],"a":[]}}
1626916424.2846131: {"stream":"ethusd_210924@depth@100ms","data":{"e":"depthUpdate","E":1626916424312,"T":1626916424298,"s":"ETHUSD_210924","ps":"ETHUSD","U":167006214123,"u":167006214606,"pu":167006213992,"b":[["1839.26","13656"],["1839.27","4552"],["1840.47","0"],["1840.53","0"],["1986.41","500"],["1987.67","4185"],["1989.52","0"],["1989.84","0"],["1989.95","270"],["1989.97","360"],["1990.14","0"],["1990.15","0"],["1990.19","0"]],"a":[["1997.10","0"],["2000.68","1498"]]}}
1626916424.304385: {"stream":"linkusd_perp@depth@100ms","data":{"e":"depthUpdate","E":1626916424332,"T":1626916424326,"s":"LINKUSD_PERP","ps":"LINKUSD","U":167006214217,"u":167006214708,"pu":167006214194,"b":[["15.034","279"],["15.036","840"]],"a":[["15.069","3714"],["15.071","501"],["15.076","730"],["15.077","1115"]]}}
1626916424.311588: {"stream":"etcusd_perp@depth@100ms","data":{"e":"depthUpdate","E":1626916424339,"T":1626916424286,"s":"ETCUSD_PERP","ps":"ETCUSD","U":167006214254,"u":167006214540,"pu":167006214075,"b":[["42.231","0"],["42.233","1325"],["42.237","909"]],"a":[["42.268","100"],["42.269","295"],["42.270","0"]]}}
1626916424.3182762: {"stream":"bchusd_perp@depth@100ms","data":{"e":"depthUpdate","E":1626916424345,"T":1626916424278,"s":"BCHUSD_PERP","ps":"BCHUSD","U":167006214302,"u":167006214506,"pu":167006214234,"b":[["427.20","200"]],"a":[["427.80","0"]]}}
1626916424.38898: {"stream":"ethusd_210924@depth@100ms","data":{"e":"depthUpdate","E":1626916424415,"T":1626916424397,"s":"ETHUSD_210924","ps":"ETHUSD","U":167006214648,"u":167006215022,"pu":167006214606,"b":[["1976.91","0"],["1986.60","0"],["1989.97","0"],["1989.98","222"],["1990.01","0"],["1990.02","125"],["1990.05","360"],["1990.20","0"]],"a":[["1990.65","794"],["1990.98","270"],["1991.25","0"],["1991.52","0"],["1996.80","190"],["2023.13","408"],["2033.05","410"],["2042.97","412"],["2052.89","414"],["2062.80","416"]]}}
1626916424.3937678: {"stream":"linkusd_211231@depth@100ms","data":{"e":"depthUpdate","E":1626916424421,"T":1626916424332,"s":"LINKUSD_211231","ps":"LINKUSD","U":167006214674,"u":167006214742,"pu":167006213978,"b":[],"a":[["15.323","911"],["15.324","119"],["15.325","0"]]}}
1626916424.400384: {"stream":"btcusd_211231@depth@100ms","data":{"e":"depthUpdate","E":1626916424428,"T":1626916424326,"s":"BTCUSD_211231","ps":"BTCUSD","U":167006214693,"u":167006214726,"pu":167006214430,"b":[],"a":[["32802.5","0"],["33196.8","331"]]}}
1626916424.425351: {"stream":"linkusd_perp@depth@100ms","data":{"e":"depthUpdate","E":1626916424449,"T":1626916424430,"s":"LINKUSD_PERP","ps":"LINKUSD","U":167006214798,"u":167006215132,"pu":167006214708,"b":[["14.976","601"]],"a":[["15.069","3414"],["15.071","801"]]}}
1626916424.42551: {"stream":"bchusd_perp@depth@100ms","data":{"e":"depthUpdate","E":1626916424451,"T":1626916424424,"s":"BCHUSD_PERP","ps":"BCHUSD","U":167006214809,"u":167006215122,"pu":167006214506,"b":[["427.47","147"],["427.55","700"],["427.72","300"]],"a":[["429.61","53"],["430.76","0"]]}}
1626916424.455978: {"stream":"xrpusd_perp@depth@100ms","data":{"e":"depthUpdate","E":1626916424483,"T":1626916424447,"s":"XRPUSD_PERP","ps":"XRPUSD","U":167006214951,"u":167006215192,"pu":167006214470,"b":[["0.5657","5900"],["0.5659","2010"],["0.5661","3660"]],"a":[["0.5664","5337"],["0.5665","5495"]]}}
1626916424.4878452: {"stream":"ethusd_210924@depth@100ms","data":{"e":"depthUpdate","E":1626916424515,"T":1626916424491,"s":"ETHUSD_210924","ps":"ETHUSD","U":167006215057,"u":167006215416,"pu":167006215022,"b":[["1969.84","4777"],["1972.38","0"],["1974.81","391"],["1977.81","4797"],["1979.39","0"],["1985.91","500"],["1990.02","0"],["1990.05","0"],["1990.06","0"],["1990.09","0"],["1990.10","0"],["1990.13","360"],["1990.14","125"]],"a":[["1990.73","920"],["1990.98","0"],["1991.81","2045"]]}}
1626916424.528321: {"stream":"btcusd_211231@depth@100ms","data":{"e":"depthUpdate","E":1626916424554,"T":1626916424447,"s":"BTCUSD_211231","ps":"BTCUSD","U":167006215195,"u":167006215195,"pu":167006214726,"b":[["32609.7","85"]],"a":[]}}
1626916424.530781: {"stream":"bchusd_perp@depth@100ms","data":{"e":"depthUpdate","E":1626916424557,"T":1626916424497,"s":"BCHUSD_PERP","ps":"BCHUSD","U":167006215214,"u":167006215427,"pu":167006215122,"b":[["427.77","25"]],"a":[["427.78","638"],["427.81","100"],["427.88","0"],["427.98","681"],["430.76","610"]]}}
1626916424.530983: {"stream":"linkusd_perp@depth@100ms","data":{"e":"depthUpdate","E":1626916424557,"T":1626916424496,"s":"LINKUSD_PERP","ps":"LINKUSD","U":167006215221,"u":167006215424,"pu":167006215132,"b":[["15.021","528"]],"a":[["15.076","730"]]}}
1626916424.5310578: {"stream":"linkusd_211231@depth@100ms","data":{"e":"depthUpdate","E":1626916424557,"T":1626916424472,"s":"LINKUSD_211231","ps":"LINKUSD","U":167006215222,"u":167006215324,"pu":167006214742,"b":[["15.287","0"],["15.293","1371"]],"a":[["15.324","219"]]}}
1626916424.536928: {"stream":"bchusd_210924@depth@100ms","data":{"e":"depthUpdate","E":1626916424563,"T":1626916424459,"s":"BCHUSD_210924","ps":"BCHUSD","U":167006215259,"u":167006215259,"pu":167006214076,"b":[["428.77","390"]],"a":[]}}
1626916424.543233: {"stream":"etcusd_perp@depth@100ms","data":{"e":"depthUpdate","E":1626916424570,"T":1626916424562,"s":"ETCUSD_PERP","ps":"ETCUSD","U":167006215298,"u":167006215753,"pu":167006214540,"b":[["42.141","552"],["42.167","500"]],"a":[["42.268","106"],["42.269","0"],["42.316","256"],["42.325","0"]]}}
1626916424.5935261: {"stream":"xrpusd_perp@depth@100ms","data":{"e":"depthUpdate","E":1626916424622,"T":1626916424582,"s":"XRPUSD_PERP","ps":"XRPUSD","U":167006215530,"u":167006215859,"pu":167006215192,"b":[["0.5657","5740"],["0.5659","2170"],["0.5660","5448"],["0.5662","0"]],"a":[["0.5662","477"],["0.5664","5637"],["0.5665","5195"]]}}
1626916424.6020072: {"stream":"ethusd_210924@depth@100ms","data":{"e":"depthUpdate","E":1626916424630,"T":1626916424621,"s":"ETHUSD_210924","ps":"ETHUSD","U":167006215568,"u":167006216002,"pu":167006215416,"b":[["1989.63","0"],["1989.95","0"],["1989.99","270"],["1990.01","360"],["1990.13","0"],["1990.14","0"],["1990.17","0"],["1990.18","0"],["1990.20","0"],["1990.21","127"]],"a":[]}}
1626916424.632064: {"stream":"btcusd_211231@depth@100ms","data":{"e":"depthUpdate","E":1626916424659,"T":1626916424591,"s":"BTCUSD_211231","ps":"BTCUSD","U":167006215693,"u":167006215887,"pu":167006215195,"b":[["31987.0","0"]],"a":[["33117.0","0"]]}}
1626916424.896447: {"stream":"eosusd_perp@depth@100ms","data":{"e":"depthUpdate","E":1626916424714,"T":1626916424621,"s":"EOSUSD_PERP","ps":"EOSUSD","U":167006215946,"u":167006216003,"pu":167006213869,"b":[["3.444","9773"],["3.451","3732"]],"a":[]}}
1626916424.8965068: {"stream":"bchusd_210924@depth@100ms","data":{"e":"depthUpdate","E":1626916424720,"T":1626916424614,"s":"BCHUSD_210924","ps":"BCHUSD","U":167006215988,"u":167006215988,"pu":167006215259,"b":[["428.10","0"]],"a":[]}}
1626916424.896608: {"stream":"ethusd_210924@depth@100ms","data":{"e":"depthUpdate","E":1626916424738,"T":1626916424706,"s":"ETHUSD_210924","ps":"ETHUSD","U":167006216048,"u":167006216350,"pu":167006216002,"b":[["1989.98","0"],["1990.01","0"],["1990.02","220"],["1990.19","840"],["1990.20","169"],["1990.21","0"]],"a":[["1990.47","0"],["1990.56","373"],["1990.57","480"],["1999.92","0"]]}}
1626916424.8967638: {"stream":"linkusd_perp@depth@100ms","data":{"e":"depthUpdate","E":1626916424744,"T":1626916424706,"s":"LINKUSD_PERP","ps":"LINKUSD","U":167006216093,"u":167006216351,"pu":167006215424,"b":[["15.051","2923"],["15.052","560"],["15.060","101"],["15.061","350"],["15.062","0"]],"a":[["15.074","1741"],["15.075","995"],["15.076","350"],["15.077","1115"]]}}
1626916424.896838: {"stream":"etcusd_perp@depth@100ms","data":{"e":"depthUpdate","E":1626916424750,"T":1626916424727,"s":"ETCUSD_PERP","ps":"ETCUSD","U":167006216115,"u":167006216423,"pu":167006215753,"b":[["42.230","0"],["42.233","100"],["42.234","1621"],["42.240","33"],["42.242","0"],["42.244","267"]],"a":[["42.268","0"],["42.269","100"],["42.270","296"]]}}
1626916424.896928: {"stream":"bchusd_perp@depth@100ms","data":{"e":"depthUpdate","E":1626916424778,"T":1626916424702,"s":"BCHUSD_PERP","ps":"BCHUSD","U":167006216205,"u":167006216334,"pu":167006215427,"b":[["427.08","8919"],["427.09","0"]],"a":[["427.81","0"],["427.86","100"],["428.63","5417"],["428.71","418"]]}}
1626916424.8969972: {"stream":"xrpusd_perp@depth@100ms","data":{"e":"depthUpdate","E":1626916424782,"T":1626916424706,"s":"XRPUSD_PERP","ps":"XRPUSD","U":167006216226,"u":167006216348,"pu":167006215859,"b":[["0.5653","4590"],["0.5660","5148"]],"a":[["0.5662","786"],["0.5672","3617"],["0.5677","3361"]]}}
1626916424.8971038: {"stream":"ethusd_210924@depth@100ms","data":{"e":"depthUpdate","E":1626916424839,"T":1626916424824,"s":"ETHUSD_210924","ps":"ETHUSD","U":167006216447,"u":167006216724,"pu":167006216350,"b":[["1839.26","15932"],["1840.81","0"],["1987.74","0"],["1989.79","0"],["1989.99","0"],["1990.02","0"],["1990.03","270"],["1990.21","0"]],"a":[["1992.04","50"]]}}
1626916424.897186: {"stream":"linkusd_211231@depth@100ms","data":{"e":"depthUpdate","E":1626916424866,"T":1626916424780,"s":"LINKUSD_211231","ps":"LINKUSD","U":167006216528,"u":167006216581,"pu":167006215324,"b":[],"a":[["15.322","318"],["15.342","40"]]}}
1626916424.897228: {"stream":"linkusd_perp@depth@100ms","data":{"e":"depthUpdate","E":1626916424864,"T":1626916424832,"s":"LINKUSD_PERP","ps":"LINKUSD","U":167006216509,"u":167006216739,"pu":167006216351,"b":[["15.051","1738"],["15.052","1729"]],"a":[["15.074","1621"]]}}
1626916424.8972642: {"stream":"btcusd_211231@depth@100ms","data":{"e":"depthUpdate","E":1626916424873,"T":1626916424832,"s":"BTCUSD_211231","ps":"BTCUSD","U":167006216550,"u":167006216740,"pu":167006215887,"b":[["32516.9","547"],["32527.1","0"]],"a":[["32621.3","16"]]}}
1626916424.897331: {"stream":"eosusd_perp@depth@100ms","data":{"e":"depthUpdate","E":1626916424898,"T":1626916424880,"s":"EOSUSD_PERP","ps":"EOSUSD","U":167006216629,"u":167006216887,"pu":167006216003,"b":[["3.468","0"]],"a":[["3.470","4743"],["3.471","5187"]]}}
1626916424.906382: {"stream":"xrpusd_perp@depth@100ms","data":{"e":"depthUpdate","E":1626916424929,"T":1626916424916,"s":"XRPUSD_PERP","ps":"XRPUSD","U":167006216718,"u":167006217038,"pu":167006216348,"b":[["0.5646","23717"],["0.5647","1511"],["0.5653","4290"],["0.5660","5472"],["0.5661","3630"]],"a":[["0.5662","477"],["0.5682","35960"],["0.5683","2358"]]}}
1626916424.945846: {"stream":"ethusd_210924@depth@100ms","data":{"e":"depthUpdate","E":1626916424954,"T":1626916424940,"s":"ETHUSD_210924","ps":"ETHUSD","U":167006216790,"u":167006217131,"pu":167006216724,"b":[["1988.25","7883"],["1988.51","425"],["1990.19","0"],["1990.20","529"]],"a":[]}}
1626916424.950062: {"stream":"btcusd_211231@depth@100ms","data":{"e":"depthUpdate","E":1626916424974,"T":1626916424873,"s":"BTCUSD_211231","ps":"BTCUSD","U":167006216845,"u":167006216862,"pu":167006216740,"b":[["32607.3","0"]],"a":[["32621.3","17"]]}}
1626916424.950219: {"stream":"linkusd_211231@depth@100ms","data":{"e":"depthUpdate","E":1626916424976,"T":1626916424870,"s":"LINKUSD_211231","ps":"LINKUSD","U":167006216846,"u":167006216846,"pu":167006216581,"b":[["15.295","0"]],"a":[]}}
1626916424.955908: {"stream":"linkusd_perp@depth@100ms","data":{"e":"depthUpdate","E":1626916424981,"T":1626916424913,"s":"LINKUSD_PERP","ps":"LINKUSD","U":167006216875,"u":167006217019,"pu":167006216739,"b":[["15.052","1349"],["15.053","3688"]],"a":[["15.077","995"]]}}
1626916424.993595: {"stream":"bchusd_perp@depth@100ms","data":{"e":"depthUpdate","E":1626916425004,"T":1626916424999,"s":"BCHUSD_PERP","ps":"BCHUSD","U":167006216960,"u":167006217388,"pu":167006216334,"b":[["427.72","500"],["427.77","25"]],"a":[["427.81","100"],["427.86","0"]]}}
1626916424.993734: {"stream":"eosusd_perp@depth@100ms","data":{"e":"depthUpdate","E":1626916425007,"T":1626916424987,"s":"EOSUSD_PERP","ps":"EOSUSD","U":167006216969,"u":167006217346,"pu":167006216887,"b":[["3.468","0"]],"a":[]}}
1626916424.993828: {"stream":"bchusd_210924@depth@100ms","data":{"e":"depthUpdate","E":1626916425011,"T":1626916424907,"s":"BCHUSD_210924","ps":"BCHUSD","U":167006216994,"u":167006216994,"pu":167006215988,"b":[["427.90","49"]],"a":[]}}
1626916425.03356: {"stream":"etcusd_perp@depth@100ms","data":{"e":"depthUpdate","E":1626916425041,"T":1626916424937,"s":"ETCUSD_PERP","ps":"ETCUSD","U":167006217116,"u":167006217120,"pu":167006216423,"b":[["42.234","396"],["42.235","1630"]],"a":[]}}
1626916425.054973: {"stream":"ethusd_210924@depth@100ms","data":{"e":"depthUpdate","E":1626916425081,"T":1626916425074,"s":"ETHUSD_210924","ps":"ETHUSD","U":167006217269,"u":167006217795,"pu":167006217131,"b":[["1986.23","0"],["1986.30","190"],["1986.41","0"],["1987.43","0"],["1987.50","0"],["1987.66","0"],["1987.77","0"],["1988.00","541"],["1988.25","237"],["1988.89","10943"],["1988.94","0"],["1989.00","0"],["1989.04","0"],["1989.17","0"],["1989.29","0"],["1989.31","0"],["1989.43","0"],["1989.52","270"],["1989.63","612"],["1989.77","0"],["1989.78","0"],["1990.03","0"],["1990.37","235"]],"a":[["1990.50","20"],["1990.78","0"],["1991.53","419"],["1992.04","0"]]}}
1626916425.0673862: {"stream":"xrpusd_perp@depth@100ms","data":{"e":"depthUpdate","E":1626916425094,"T":1626916425089,"s":"XRPUSD_PERP","ps":"XRPUSD","U":167006217350,"u":167006217855,"pu":167006217038,"b":[["0.5658","3481"],["0.5660","5478"]],"a":[["0.5662","142"],["0.5664","5637"],["0.5665","5195"]]}}
1626916425.087661: {"stream":"linkusd_perp@depth@100ms","data":{"e":"depthUpdate","E":1626916425104,"T":1626916425078,"s":"LINKUSD_PERP","ps":"LINKUSD","U":167006217389,"u":167006217805,"pu":167006217019,"b":[["15.053","3308"],["15.057","959"],["15.058","600"],["15.059","212"],["15.061","240"],["15.062","110"],["15.063","457"],["15.064","0"],["15.065","0"]],"a":[["15.073","1534"],["15.074","1611"],["15.077","795"]]}}
1626916425.087807: {"stream":"linkusd_211231@depth@100ms","data":{"e":"depthUpdate","E":1626916425105,"T":1626916425021,"s":"LINKUSD_211231","ps":"LINKUSD","U":167006217405,"u":167006217492,"pu":167006216846,"b":[],"a":[["15.322","872"],["15.323","0"],["15.524","0"],["15.599","0"],["15.674","0"],["15.750","0"],["15.825","0"]]}}
1626916425.0878952: {"stream":"eosusd_perp@depth@100ms","data":{"e":"depthUpdate","E":1626916425114,"T":1626916425099,"s":"EOSUSD_PERP","ps":"EOSUSD","U":167006217431,"u":167006217899,"pu":167006217346,"b":[["3.443","7166"],["3.450","18509"],["3.468","0"]],"a":[]}}
1626916425.097149: {"stream":"btcusd_211231@depth@100ms","data":{"e":"depthUpdate","E":1626916425125,"T":1626916425091,"s":"BTCUSD_211231","ps":"BTCUSD","U":167006217486,"u":167006217861,"pu":167006216862,"b":[["31362.6","0"],["31522.6","0"],["31682.6","0"],["31842.6","0"],["32002.7","0"],["32328.4","0"],["32340.1","0"],["32356.1","700"],["32618.1","0"]],"a":[]}}
1626916425.1034582: {"stream":"bchusd_perp@depth@100ms","data":{"e":"depthUpdate","E":1626916425131,"T":1626916425113,"s":"BCHUSD_PERP","ps":"BCHUSD","U":167006217516,"u":167006217943,"pu":167006217388,"b":[["426.39","0"],["427.77","25"]],"a":[["427.99","4083"],["428.00","34"],["429.16","0"]]}}
1626916425.157832: {"stream":"ethusd_210924@depth@100ms","data":{"e":"depthUpdate","E":1626916425184,"T":1626916425175,"s":"ETHUSD_210924","ps":"ETHUSD","U":167006217822,"u":167006218214,"pu":167006217795,"b":[["1986.05","501"],["1986.28","0"],["1986.30","0"],["1986.39","401"],["1986.47","469"],["1986.66","320"],["1986.78","414"],["1987.01","404"],["1987.24","0"],["1987.82","363"],["1987.97","714"],["1988.17","280"],["1988.18","301"],["1988.46","259"],["1989.52","0"],["1989.79","270"]],"a":[["1990.86","418"],["1991.22","259"],["1991.23","280"],["1991.53","0"],["1991.54","0"],["1991.82","0"],["1999.31","2000"]]}}
1626916425.171697: {"stream":"xrpusd_perp@depth@100ms","data":{"e":"depthUpdate","E":1626916425200,"T":1626916425170,"s":"XRPUSD_PERP","ps":"XRPUSD","U":167006217877,"u":167006218192,"pu":167006217855,"b":[["0.5618","5977"],["0.5641","3352"],["0.5661","3965"]],"a":[["0.5664","3610"],["0.5667","4338"],["0.5674","10430"]]}}
1626916425.198136: {"stream":"linkusd_211231@depth@100ms","data":{"e":"depthUpdate","E":1626916425225,"T":1626916425187,"s":"LINKUSD_211231","ps":"LINKUSD","U":167006217972,"u":167006218285,"pu":167006217492,"b":[["14.759","100"],["14.761","100"],["14.835","100"],["14.837","100"],["14.910","100"],["14.912","100"],["14.985","676"],["14.987","100"],["15.061","100"],["15.063","100"],["15.289","46"],["15.294","123"]],"a":[["15.322","0"],["15.324","119"]]}}
1626916425.200471: {"stream":"eosusd_perp@depth@100ms","data":{"e":"depthUpdate","E":1626916425227,"T":1626916425210,"s":"EOSUSD_PERP","ps":"EOSUSD","U":167006217986,"u":167006218423,"pu":167006217899,"b":[["3.468","0"]],"a":[]}}
1626916425.211993: {"stream":"bchusd_perp@depth@100ms","data":{"e":"depthUpdate","E":1626916425240,"T":1626916425204,"s":"BCHUSD_PERP","ps":"BCHUSD","U":167006218054,"u":167006218385,"pu":167006217943,"b":[],"a":[["427.81","760"],["427.86","100"],["427.89","1"],["428.02","199"]]}}
1626916425.233553: {"stream":"linkusd_perp@depth@100ms","data":{"e":"depthUpdate","E":1626916425258,"T":1626916425240,"s":"LINKUSD_PERP","ps":"LINKUSD","U":167006218118,"u":167006218551,"pu":167006217805,"b":[["15.037","3470"],["15.042","1415"],["15.050","260"],["15.053","3708"],["15.054","148"],["15.055","300"],["15.056","1662"],["15.058","220"],["15.059","592"],["15.062","0"],["15.063","357"],["15.064","100"],["15.065","35"],["15.066","213"]],"a":[["15.067","190"],["15.068","100"],["15.069","2479"],["15.071","550"],["15.073","1524"],["15.074","1511"],["15.075","615"],["15.076","450"],["15.077","1175"],["15.078","1009"],["15.079","2182"],["15.082","2074"],["15.084","0"]]}}
1626916425.233879: {"stream":"btcusd_211231@depth@100ms","data":{"e":"depthUpdate","E":1626916425263,"T":1626916425210,"s":"BTCUSD_211231","ps":"BTCUSD","U":167006218136,"u":167006218425,"pu":167006217861,"b":[["31362.9","55"],["31522.9","55"],["31682.9","55"],["31842.9","55"],["32003.0","55"]],"a":[["32627.2","153"],["32627.3","0"],["32627.4","0"],["32634.6","0"],["33027.6","45"],["33029.4","45"],["33187.6","45"],["33189.4","45"],["33347.6","45"],["33349.5","45"],["33507.7","46"],["33509.5","46"],["33667.7","382"],["33669.5","46"]]}}
1626916425.242005: {"stream":"trxusd_perp@depth@100ms","data":{"e":"depthUpdate","E":1626916425269,"T":1626916425194,"s":"TRXUSD_PERP","ps":"TRXUSD","U":167006218155,"u":167006218332,"pu":167006214095,"b":[["0.05344","754"]],"a":[["0.05369","484"],["0.05372","1672"]]}}
1626916425.2521589: {"stream":"etcusd_perp@depth@100ms","data":{"e":"depthUpdate","E":1626916425279,"T":1626916425254,"s":"ETCUSD_PERP","ps":"ETCUSD","U":167006218213,"u":167006218613,"pu":167006217120,"b":[["42.210","17"],["42.215","256"],["42.220","1320"],["42.235","450"],["42.237","2089"],["42.240","233"]],"a":[]}}
1626916425.2538712: {"stream":"bchusd_210924@depth@100ms","data":{"e":"depthUpdate","E":1626916425281,"T":1626916425176,"s":"BCHUSD_210924","ps":"BCHUSD","U":167006218221,"u":167006218221,"pu":167006216994,"b":[["428.99","5977"]],"a":[]}}
1626916425.266716: {"stream":"ethusd_210924@depth@100ms","data":{"e":"depthUpdate","E":1626916425292,"T":1626916425279,"s":"ETHUSD_210924","ps":"ETHUSD","U":167006218288,"u":167006218703,"pu":167006218214,"b":[["1982.08","0"],["1984.62","783"],["1985.99","1459"],["1986.60","190"],["1987.82","0"],["1987.97","372"],["1988.17","0"],["1988.18","0"],["1988.46","0"],["1988.73","363"],["1989.10","342"],["1989.29","280"],["1989.31","301"],["1989.43","259"]],"a":[["1990.50","0"]]}}
1626916425.307544: {"stream":"linkusd_211231@depth@100ms","data":{"e":"depthUpdate","E":1626916425334,"T":1626916425231,"s":"LINKUSD_211231","ps":"LINKUSD","U":167006218491,"u":167006218499,"pu":167006218285,"b":[],"a":[["15.526","164"],["15.601","165"],["15.676","204"],["15.752","167"],["15.827","168"]]}}
1626916425.309837: {"stream":"eosusd_perp@depth@100ms","data":{"e":"depthUpdate","E":1626916425336,"T":1626916425326,"s":"EOSUSD_PERP","ps":"EOSUSD","U":167006218504,"u":167006218906,"pu":167006218423,"b":[["3.468","0"]],"a":[]}}
1626916425.3142211: {"stream":"bchusd_perp@depth@100ms","data":{"e":"depthUpdate","E":1626916425341,"T":1626916425325,"s":"BCHUSD_PERP","ps":"BCHUSD","U":167006218541,"u":167006218901,"pu":167006218385,"b":[["424.65","0"],["426.24","0"],["426.39","310"],["427.20","0"],["427.26","0"],["427.50","4147"],["427.58","0"],["427.63","725"],["427.77","1"]],"a":[["427.90","100"],["427.98","581"],["429.16","310"],["429.31","0"],["430.90","0"]]}}
1626916425.343113: {"stream":"btcusd_211231@depth@100ms","data":{"e":"depthUpdate","E":1626916425370,"T":1626916425357,"s":"BTCUSD_211231","ps":"BTCUSD","U":167006218653,"u":167006219009,"pu":167006218425,"b":[],"a":[["32626.7","0"],["32626.8","0"],["32627.2","0"],["32633.7","46"],["32634.6","153"]]}}
1626916425.347201: {"stream":"linkusd_perp@depth@100ms","data":{"e":"depthUpdate","E":1626916425372,"T":1626916425365,"s":"LINKUSD_PERP","ps":"LINKUSD","U":167006218664,"u":167006219063,"pu":167006218551,"b":[["15.015","328"],["15.018","550"],["15.055","200"],["15.057","1059"],["15.062","110"],["15.066","103"]],"a":[["15.073","1324"],["15.077","1375"],["15.084","630"],["15.112","1551"],["15.115","362"]]}}
1626916425.3639839: {"stream":"etcusd_perp@depth@100ms","data":{"e":"depthUpdate","E":1626916425392,"T":1626916425387,"s":"ETCUSD_PERP","ps":"ETCUSD","U":167006218731,"u":167006219182,"pu":167006218613,"b":[["42.230","1132"],["42.237","909"],["42.238","0"],["42.240","33"]],"a":[]}}
1626916425.367937: {"stream":"ethusd_210924@depth@100ms","data":{"e":"depthUpdate","E":1626916425394,"T":1626916425383,"s":"ETHUSD_210924","ps":"ETHUSD","U":167006218743,"u":167006219166,"pu":167006218703,"b":[["1839.27","6828"],["1840.37","0"],["1984.62","0"],["1986.60","0"],["1987.82","363"],["1987.97","714"],["1988.73","0"],["1989.10","0"],["1989.31","0"],["1989.40","0"],["1989.64","0"],["1989.79","0"],["1989.95","270"]],"a":[["1991.26","2774"],["1992.15","0"],["2023.13","0"],["2033.05","0"],["2042.97","0"],["2052.89","0"],["2062.80","0"]]}}
1626916425.4109929: {"stream":"trxusd_perp@depth@100ms","data":{"e":"depthUpdate","E":1626916425437,"T":1626916425423,"s":"TRXUSD_PERP","ps":"TRXUSD","U":167006218931,"u":167006219341,"pu":167006218332,"b":[["0.05272","1428"],["0.05328","2715"]],"a":[["0.05348","710"],["0.05350","3193"],["0.05379","220"]]}}
1626916425.4270551: {"stream":"eosusd_perp@depth@100ms","data":{"e":"depthUpdate","E":1626916425453,"T":1626916425434,"s":"EOSUSD_PERP","ps":"EOSUSD","U":167006218985,"u":167006219408,"pu":167006218906,"b":[["3.468","0"]],"a":[]}}
1626916425.445088: {"stream":"bchusd_perp@depth@100ms","data":{"e":"depthUpdate","E":1626916425473,"T":1626916425459,"s":"BCHUSD_PERP","ps":"BCHUSD","U":167006219068,"u":167006219575,"pu":167006218901,"b":[["424.65","618"],["426.24","312"],["427.50","3947"],["427.55","17"],["427.77","25"]],"a":[["427.90","0"],["427.98","681"],["428.01","3821"],["428.07","200"],["429.31","300"],["430.90","606"]]}}
1626916425.452194: {"stream":"linkusd_perp@depth@100ms","data":{"e":"depthUpdate","E":1626916425479,"T":1626916425431,"s":"LINKUSD_PERP","ps":"LINKUSD","U":167006219107,"u":167006219383,"pu":167006219063,"b":[["14.959","2285"]],"a":[["15.073","1224"],["15.075","725"],["15.076","550"],["15.078","899"],["15.085","515"],["15.168","3081"]]}}
1626916425.452791: {"stream":"btcusd_211231@depth@100ms","data":{"e":"depthUpdate","E":1626916425482,"T":1626916425408,"s":"BTCUSD_211231","ps":"BTCUSD","U":167006219111,"u":167006219282,"pu":167006219009,"b":[],"a":[["32626.7","0"],["32632.7","46"],["32633.6","153"],["32633.7","0"],["32634.6","0"]]}}
1626916425.4631932: {"stream":"xrpusd_perp@depth@100ms","data":{"e":"depthUpdate","E":1626916425491,"T":1626916425435,"s":"XRPUSD_PERP","ps":"XRPUSD","U":167006219187,"u":167006219412,"pu":167006218192,"b":[["0.5660","5442"],["0.5661","3660"]],"a":[["0.5662","477"]]}}
1626916425.488037: {"stream":"ethusd_210924@depth@100ms","data":{"e":"depthUpdate","E":1626916425516,"T":1626916425506,"s":"ETHUSD_210924","ps":"ETHUSD","U":167006219289,"u":167006219837,"pu":167006219166,"b":[["1982.84","1200"],["1984.35","0"],["1984.39","0"],["1986.05","0"],["1986.18","0"],["1986.38","0"],["1986.39","0"],["1986.47","0"],["1986.66","0"],["1986.78","0"],["1987.01","39"],["1987.46","4425"],["1988.05","846"],["1988.18","301"],["1988.31","5676"],["1988.51","0"],["1989.17","0"],["1989.18","50"],["1989.29","0"],["1989.39","0"],["1989.43","0"],["1989.64","270"],["1989.95","0"],["1989.98","0"],["1989.99","0"],["1990.02","0"],["1990.03","0"],["1990.06","360"],["1990.20","0"]],"a":[["1990.50","20"],["1990.99","3349"],["1994.70","190"],["1995.97","18467"],["1996.80","0"],["2022.91","408"],["2032.83","409"],["2042.74","412"],["2052.66","413"],["2062.58","416"]]}}
1626916425.5188942: {"stream":"etcusd_perp@depth@100ms","data":{"e":"depthUpdate","E":1626916425546,"T":1626916425493,"s":"ETCUSD_PERP","ps":"ETCUSD","U":167006219449,"u":167006219766,"pu":167006219182,"b":[["42.220","1520"]],"a":[["42.298","322"]]}}
1626916425.52866: {"stream":"trxusd_perp@depth@100ms","data":{"e":"depthUpdate","E":1626916425555,"T":1626916425519,"s":"TRXUSD_PERP","ps":"TRXUSD","U":167006219513,"u":167006219905,"pu":167006219341,"b":[["0.05328","2866"],["0.05343","1748"]],"a":[["0.05348","349"],["0.05349","916"],["0.05378","301"]]}}
1626916425.528857: {"stream":"linkusd_211231@depth@100ms","data":{"e":"depthUpdate","E":1626916425556,"T":1626916425551,"s":"LINKUSD_211231","ps":"LINKUSD","U":167006219524,"u":167006220079,"pu":167006218499,"b":[],"a":[["15.329","848"],["15.330","100"]]}}
1626916425.533021: {"stream":"eosusd_perp@depth@100ms","data":{"e":"depthUpdate","E":1626916425560,"T":1626916425542,"s":"EOSUSD_PERP","ps":"EOSUSD","U":167006219565,"u":167006220037,"pu":167006219408,"b":[["3.468","0"]],"a":[]}}
1626916425.554541: {"stream":"linkusd_perp@depth@100ms","data":{"e":"depthUpdate","E":1626916425581,"T":1626916425560,"s":"LINKUSD_PERP","ps":"LINKUSD","U":167006219676,"u":167006220136,"pu":167006219383,"b":[["15.046","1000"],["15.056","1810"]],"a":[["15.075","574"],["15.076","350"],["15.078","1099"],["15.089","49"]]}}
1626916425.5646431: {"stream":"btcusd_211231@depth@100ms","data":{"e":"depthUpdate","E":1626916425592,"T":1626916425561,"s":"BTCUSD_211231","ps":"BTCUSD","U":167006219729,"u":167006220141,"pu":167006219282,"b":[["32516.9","0"],["32527.1","582"],["32618.5","208"]],"a":[["32631.7","46"],["32632.6","153"],["32632.7","0"],["32633.6","0"],["32639.1","0"],["32648.2","0"]]}}
1626916425.581033: {"stream":"xrpusd_perp@depth@100ms","data":{"e":"depthUpdate","E":1626916425608,"T":1626916425598,"s":"XRPUSD_PERP","ps":"XRPUSD","U":167006219832,"u":167006220378,"pu":167006219412,"b":[],"a":[["0.5664","3610"],["0.5665","7062"],["0.5666","1987"],["0.5667","4380"],["0.5668","4282"]]}}
1626916425.591742: {"stream":"ethusd_210924@depth@100ms","data":{"e":"depthUpdate","E":1626916425617,"T":1626916425603,"s":"ETHUSD_210924","ps":"ETHUSD","U":167006219877,"u":167006220401,"pu":167006219837,"b":[["1984.20","0"],["1985.01","626"],["1985.89","532"],["1985.94","501"],["1986.38","469"],["1986.39","401"],["1986.62","320"],["1986.69","414"],["1986.97","365"],["1987.27","289"],["1987.97","714"],["1988.05","846"],["1988.18","301"],["1988.91","2167"],["1989.05","3914"],["1989.18","0"],["1989.39","259"],["1989.40","50"],["1989.64","0"],["1989.65","1567"],["1989.66","642"],["1989.95","270"],["1989.97","0"],["1989.98","0"],["1990.01","0"],["1990.02","0"],["1990.05","360"],["1990.06","0"],["1990.07","0"],["1990.10","0"],["1990.11","0"],["1990.14","0"],["1990.15","127"]],"a":[["1990.49","270"],["1990.73","650"],["1991.26","1149"],["1991.64","1943"],["2142.15","2650"],["2144.26","5306"]]}}
1626916425.642878: {"stream":"eosusd_perp@depth@100ms","data":{"e":"depthUpdate","E":1626916425671,"T":1626916425653,"s":"EOSUSD_PERP","ps":"EOSUSD","U":167006220159,"u":167006220626,"pu":167006220037,"b":[["3.443","7303"],["3.450","18646"],["3.468","0"]],"a":[]}}
1626916425.663223: {"stream":"linkusd_perp@depth@100ms","data":{"e":"depthUpdate","E":1626916425690,"T":1626916425666,"s":"LINKUSD_PERP","ps":"LINKUSD","U":167006220305,"u":167006220662,"pu":167006220136,"b":[["15.048","719"],["15.063","57"],["15.065","335"]],"a":[]}}
1626916425.673016: {"stream":"btcusd_211231@depth@100ms","data":{"e":"depthUpdate","E":1626916425701,"T":1626916425617,"s":"BTCUSD_211231","ps":"BTCUSD","U":167006220371,"u":167006220456,"pu":167006220141,"b":[],"a":[["32630.7","46"],["32631.6","153"],["32631.7","0"],["32632.6","0"]]}}
1626916425.684841: {"stream":"etcusd_perp@depth@100ms","data":{"e":"depthUpdate","E":1626916425714,"T":1626916425705,"s":"ETCUSD_PERP","ps":"ETCUSD","U":167006220431,"u":167006220802,"pu":167006219766,"b":[["42.215","56"],["42.227","644"]],"a":[["42.301","22"]]}}
1626916425.6920378: {"stream":"ethusd_210924@depth@100ms","data":{"e":"depthUpdate","E":1626916425717,"T":1626916425712,"s":"ETHUSD_210924","ps":"ETHUSD","U":167006220446,"u":167006220819,"pu":167006220401,"b":[["1985.73","933"],["1985.91","0"],["1987.82","0"],["1987.97","372"],["1988.07","8648"],["1988.18","0"],["1988.87","545"],["1989.13","313"],["1989.98","0"],["1989.99","0"],["1990.05","0"],["1990.06","0"],["1990.09","0"],["1990.10","0"],["1990.13","360"],["1990.14","125"],["1990.15","0"]],"a":[]}}
1626916425.7148979: {"stream":"trxusd_perp@depth@100ms","data":{"e":"depthUpdate","E":1626916425742,"T":1626916425637,"s":"TRXUSD_PERP","ps":"TRXUSD","U":167006220560,"u":167006220560,"pu":167006219905,"b":[["0.05265","3953"]],"a":[]}}
1626916425.753912: {"stream":"eosusd_perp@depth@100ms","data":{"e":"depthUpdate","E":1626916425781,"T":1626916425763,"s":"EOSUSD_PERP","ps":"EOSUSD","U":167006220695,"u":167006221050,"pu":167006220626,"b":[["3.468","0"]],"a":[]}}
1626916425.7556832: {"stream":"bchusd_perp@depth@100ms","data":{"e":"depthUpdate","E":1626916425783,"T":1626916425689,"s":"BCHUSD_PERP","ps":"BCHUSD","U":167006220723,"u":167006220745,"pu":167006219575,"b":[],"a":[["428.23","40"],["428.33","3009"]]}}
1626916425.782367: {"stream":"linkusd_perp@depth@100ms","data":{"e":"depthUpdate","E":1626916425809,"T":1626916425781,"s":"LINKUSD_PERP","ps":"LINKUSD","U":167006220788,"u":167006221134,"pu":167006220662,"b":[["15.031","386"],["15.034","87"],["15.036","1032"],["15.040","1726"]],"a":[["15.076","501"],["15.078","1025"],["15.080","853"]]}}
1626916425.784292: {"stream":"btcusd_211231@depth@100ms","data":{"e":"depthUpdate","E":1626916425811,"T":1626916425739,"s":"BTCUSD_211231","ps":"BTCUSD","U":167006220804,"u":167006220953,"pu":167006220456,"b":[],"a":[["32629.7","46"],["32630.6","153"],["32630.7","0"],["32631.6","0"]]}}
1626916425.791728: {"stream":"ethusd_210924@depth@100ms","data":{"e":"depthUpdate","E":1626916425818,"T":1626916425797,"s":"ETHUSD_210924","ps":"ETHUSD","U":167006220828,"u":167006221197,"pu":167006220819,"b":[["1985.01","0"],["1986.66","626"],["1987.46","4000"],["1988.11","0"],["1988.60","425"],["1988.87","949"],["1988.91","2530"],["1988.96","384"],["1989.98","0"],["1989.99","127"],["1990.02","360"],["1990.13","0"],["1990.14","0"],["1990.17","0"],["1990.18","0"]],"a":[["1990.49","0"],["1990.50","0"],["1990.72","270"],["1991.90","384"]]}}
1626916425.84092: {"stream":"xrpusd_perp@depth@100ms","data":{"e":"depthUpdate","E":1626916425869,"T":1626916425825,"s":"XRPUSD_PERP","ps":"XRPUSD","U":167006221054,"u":167006221322,"pu":167006220378,"b":[["0.5653","4590"],["0.5660","5142"],["0.5661","2770"]],"a":[["0.5661","0"],["0.5662","3533"],["0.5663","3584"],["0.5668","4388"],["0.5669","6267"]]}}
1626916425.841099: {"stream":"etcusd_perp@depth@100ms","data":{"e":"depthUpdate","E":1626916425869,"T":1626916425852,"s":"ETCUSD_PERP","ps":"ETCUSD","U":167006221067,"u":167006221421,"pu":167006220802,"b":[["42.220","1320"]],"a":[["42.316","56"],["42.317","826"],["42.325","200"]]}}
1626916425.863706: {"stream":"eosusd_perp@depth@100ms","data":{"e":"depthUpdate","E":1626916425890,"T":1626916425876,"s":"EOSUSD_PERP","ps":"EOSUSD","U":167006221145,"u":167006221538,"pu":167006221050,"b":[["3.465","8939"],["3.468","0"]],"a":[]}}
1626916425.891375: {"stream":"ethusd_210924@depth@100ms","data":{"e":"depthUpdate","E":1626916425919,"T":1626916425902,"s":"ETHUSD_210924","ps":"ETHUSD","U":167006221257,"u":167006221652,"pu":167006221197,"b":[["1989.98","50"],["1989.99","0"],["1990.02","0"],["1990.03","0"],["1990.06","0"],["1990.07","126"],["1990.10","360"]],"a":[["1990.72","270"],["1990.94","0"],["2016.86","0"]]}}
1626916425.895707: {"stream":"btcusd_211231@depth@100ms","data":{"e":"depthUpdate","E":1626916425923,"T":1626916425914,"s":"BTCUSD_211231","ps":"BTCUSD","U":167006221297,"u":167006221702,"pu":167006220953,"b":[],"a":[["32621.3","16"],["32628.7","46"],["32629.6","153"],["32629.7","0"],["32630.6","0"],["32888.9","288"]]}}
1626916425.967823: {"stream":"linkusd_perp@depth@100ms","data":{"e":"depthUpdate","E":1626916425994,"T":1626916425975,"s":"LINKUSD_PERP","ps":"LINKUSD","U":167006221587,"u":167006222051,"pu":167006221134,"b":[],"a":[["15.069","232"],["15.070","4637"],["15.071","250"],["15.073","1524"]]}}
1626916425.968003: {"stream":"bchusd_perp@depth@100ms","data":{"e":"depthUpdate","E":1626916425996,"T":1626916425908,"s":"BCHUSD_PERP","ps":"BCHUSD","U":167006221603,"u":167006221668,"pu":167006220745,"b":[["427.54","1182"]],"a":[["427.81","860"],["427.86","0"]]}}
1626916425.979548: {"stream":"eosusd_perp@depth@100ms","data":{"e":"depthUpdate","E":1626916426005,"T":1626916425993,"s":"EOSUSD_PERP","ps":"EOSUSD","U":167006221628,"u":167006222135,"pu":167006221538,"b":[["3.456","711"],["3.468","0"]],"a":[["3.485","5540"],["3.492","9650"]]}}
1626916425.9905229: {"stream":"etcusd_perp@depth@100ms","data":{"e":"depthUpdate","E":1626916426018,"T":1626916425956,"s":"ETCUSD_PERP","ps":"ETCUSD","U":167006221698,"u":167006221965,"pu":167006221421,"b":[["42.217","200"],["42.227","444"]],"a":[["42.310","1977"]]}}
1626916426.002035: {"stream":"ethusd_210924@depth@100ms","data":{"e":"depthUpdate","E":1626916426028,"T":1626916425995,"s":"ETHUSD_210924","ps":"ETHUSD","U":167006221750,"u":167006222150,"pu":167006221652,"b":[["1978.47","0"],["1990.07","0"],["1990.10","0"],["1990.11","0"],["1990.14","0"],["1990.18","480"],["1990.19","528"]],"a":[["1990.57","480"],["2022.91","0"],["2032.83","0"],["2042.74","0"],["2052.66","0"],["2062.58","0"],["2144.25","0"]]}}
1626916426.002626: {"stream":"btcusd_211231@depth@100ms","data":{"e":"depthUpdate","E":1626916426032,"T":1626916426011,"s":"BTCUSD_211231","ps":"BTCUSD","U":167006221807,"u":167006222243,"pu":167006221702,"b":[["32621.2","97"]],"a":[["32621.3","17"],["32628.6","199"],["32628.7","0"],["32629.5","0"],["32629.6","0"],["32633.7","0"],["32634.6","0"],["32696.9","0"]]}}
1626916426.002749: {"stream":"xrpusd_perp@depth@100ms","data":{"e":"depthUpdate","E":1626916426032,"T":1626916426021,"s":"XRPUSD_PERP","ps":"XRPUSD","U":167006221794,"u":167006222283,"pu":167006221322,"b":[["0.5656","9344"],["0.5658","3641"],["0.5659","2010"],["0.5661","2781"]],"a":[["0.5662","1723"]]}}
1626916426.0212858: {"stream":"trxusd_perp@depth@100ms","data":{"e":"depthUpdate","E":1626916426047,"T":1626916426015,"s":"TRXUSD_PERP","ps":"TRXUSD","U":167006221862,"u":167006222252,"pu":167006220560,"b":[["0.05343","1648"],["0.05344","854"],["0.05345","265"]],"a":[["0.05350","2893"],["0.05351","2710"],["0.05352","1344"],["0.05355","949"],["0.05356","692"],["0.05358","1438"],["0.05359","606"],["0.21119","1601"],["0.21123","0"]]}}
1626916426.058215: {"stream":"bchusd_210924@depth@100ms","data":{"e":"depthUpdate","E":1626916426083,"T":1626916426072,"s":"BCHUSD_210924","ps":"BCHUSD","U":167006222059,"u":167006222526,"pu":167006218221,"b":[["428.94","3845"],["428.99","2612"]],"a":[["429.73","0"]]}}
1626916426.076472: {"stream":"bchusd_perp@depth@100ms","data":{"e":"depthUpdate","E":1626916426102,"T":1626916426069,"s":"BCHUSD_PERP","ps":"BCHUSD","U":167006222162,"u":167006222524,"pu":167006221668,"b":[],"a":[["427.81","860"],["427.86","0"]]}}
1626916426.084447: {"stream":"linkusd_perp@depth@100ms","data":{"e":"depthUpdate","E":1626916426110,"T":1626916426007,"s":"LINKUSD_PERP","ps":"LINKUSD","U":167006222213,"u":167006222215,"pu":167006222051,"b":[],"a":[["15.068","0"],["15.069","332"]]}}
1626916426.089273: {"stream":"eosusd_perp@depth@100ms","data":{"e":"depthUpdate","E":1626916426117,"T":1626916426093,"s":"EOSUSD_PERP","ps":"EOSUSD","U":167006222248,"u":167006222623,"pu":167006222135,"b":[["3.444","9572"],["3.468","0"]],"a":[["3.470","4743"],["3.471","5187"]]}}
1626916426.1053922: {"stream":"etcusd_perp@depth@100ms","data":{"e":"depthUpdate","E":1626916426132,"T":1626916426067,"s":"ETCUSD_PERP","ps":"ETCUSD","U":167006222308,"u":167006222515,"pu":167006221965,"b":[["41.819","0"],["42.031","0"],["42.230","0"]],"a":[["42.269","0"],["42.270","0"],["42.271","250"],["42.273","252"],["42.444","97"],["42.656","0"]]}}
1626916426.111288: {"stream":"ethusd_210924@depth@100ms","data":{"e":"depthUpdate","E":1626916426132,"T":1626916426082,"s":"ETHUSD_210924","ps":"ETHUSD","U":167006222311,"u":167006222580,"pu":167006222150,"b":[["1681.04","0"],["1986.30","190"],["1986.63","500"]],"a":[["2014.26","462"],["2142.14","2650"]]}}
1626916426.124207: {"stream":"btcusd_211231@depth@100ms","data":{"e":"depthUpdate","E":1626916426152,"T":1626916426054,"s":"BTCUSD_211231","ps":"BTCUSD","U":167006222394,"u":167006222439,"pu":167006222243,"b":[],"a":[["32710.1","367"],["32784.4","49"]]}}
1626916426.131949: {"stream":"xrpusd_perp@depth@100ms","data":{"e":"depthUpdate","E":1626916426160,"T":1626916426109,"s":"XRPUSD_PERP","ps":"XRPUSD","U":167006222457,"u":167006222683,"pu":167006222283,"b":[["0.5647","1011"],["0.5652","1041"],["0.5658","4521"],["0.5659","1130"]],"a":[["0.5665","7097"],["0.5666","1952"],["0.5668","5268"],["0.5669","5387"],["0.5670","7335"],["0.5673","6062"]]}}
1626916426.1938822: {"stream":"eosusd_perp@depth@100ms","data":{"e":"depthUpdate","E":1626916426220,"T":1626916426205,"s":"EOSUSD_PERP","ps":"EOSUSD","U":167006222694,"u":167006223094,"pu":167006222623,"b":[["3.446","13784"],["3.456","812"],["3.468","0"]],"a":[["3.470","4743"],["3.471","5187"]]}}
1626916426.200344: {"stream":"linkusd_211231@depth@100ms","data":{"e":"depthUpdate","E":1626916426228,"T":1626916426222,"s":"LINKUSD_211231","ps":"LINKUSD","U":167006222737,"u":167006223161,"pu":167006220079,"b":[["14.759","0"],["14.761","0"],["14.835","0"],["14.837","0"],["14.910","0"],["14.912","0"],["14.985","576"],["14.987","0"],["15.061","0"],["15.063","0"],["15.293","123"],["15.296","58"]],"a":[["15.349","0"]]}}
1626916426.209378: {"stream":"ethusd_210924@depth@100ms","data":{"e":"depthUpdate","E":1626916426235,"T":1626916426213,"s":"ETHUSD_210924","ps":"ETHUSD","U":167006222754,"u":167006223116,"pu":167006222580,"b":[["1989.67","0"],["1989.95","0"],["1989.99","270"],["1990.19","168"],["1990.20","360"]],"a":[["1992.78","5747"],["1992.86","80"],["2144.26","2653"]]}}
1626916426.209599: {"stream":"bchusd_perp@depth@100ms","data":{"e":"depthUpdate","E":1626916426235,"T":1626916426206,"s":"BCHUSD_PERP","ps":"BCHUSD","U":167006222748,"u":167006223106,"pu":167006222524,"b":[],"a":[["427.81","760"],["427.86","100"],["4583.40","32307"],["4585.86","0"]]}}
1626916426.215678: {"stream":"trxusd_perp@depth@100ms","data":{"e":"depthUpdate","E":1626916426243,"T":1626916426231,"s":"TRXUSD_PERP","ps":"TRXUSD","U":167006222804,"u":167006223204,"pu":167006222252,"b":[["0.05337","3092"],["0.05338","183"],["0.05342","852"],["0.05343","1770"]],"a":[["0.05349","1216"],["0.05350","3093"],["0.05351","2410"],["0.05352","1144"]]}}
1626916426.230111: {"stream":"etcusd_perp@depth@100ms","data":{"e":"depthUpdate","E":1626916426257,"T":1626916426242,"s":"ETCUSD_PERP","ps":"ETCUSD","U":167006222860,"u":167006223254,"pu":167006222515,"b":[["41.839","557"],["42.049","152"],["42.186","0"],["42.209","1105"],["42.227","1553"]],"a":[["42.465","194"],["42.676","306"]]}}
1626916426.231201: {"stream":"linkusd_perp@depth@100ms","data":{"e":"depthUpdate","E":1626916426259,"T":1626916426216,"s":"LINKUSD_PERP","ps":"LINKUSD","U":167006222872,"u":167006223129,"pu":167006222215,"b":[],"a":[["15.074","1621"],["15.075","464"],["15.076","881"],["15.077","995"],["15.078","1025"]]}}
1626916426.247287: {"stream":"bchusd_210924@depth@100ms","data":{"e":"depthUpdate","E":1626916426274,"T":1626916426180,"s":"BCHUSD_210924","ps":"BCHUSD","U":167006222938,"u":167006222989,"pu":167006222526,"b":[["426.08","0"],["426.93","0"]],"a":[]}}
1626916426.2722611: {"stream":"btcusd_211231@depth@100ms","data":{"e":"depthUpdate","E":1626916426300,"T":1626916426253,"s":"BTCUSD_211231","ps":"BTCUSD","U":167006223047,"u":167006223284,"pu":167006222439,"b":[["31362.9","0"],["31522.9","0"],["31682.9","0"],["31842.9","0"],["32003.0","0"],["32494.0","2725"],["32516.8","0"]],"a":[["33027.6","0"],["33029.4","0"],["33110.5","1571"],["33187.6","0"],["33189.4","0"],["33347.6","0"],["33349.5","0"],["33507.7","0"],["33509.5","0"],["33667.7","336"],["33669.5","0"]]}}
1626916426.301374: {"stream":"linkusd_211231@depth@100ms","data":{"e":"depthUpdate","E":1626916426328,"T":1626916426230,"s":"LINKUSD_211231","ps":"LINKUSD","U":167006223166,"u":167006223203,"pu":167006223161,"b":[["15.290","1199"]],"a":[["15.526","0"],["15.601","0"],["15.676","38"],["15.752","0"],["15.827","0"]]}}
1626916426.3015838: {"stream":"eosusd_perp@depth@100ms","data":{"e":"depthUpdate","E":1626916426329,"T":1626916426314,"s":"EOSUSD_PERP","ps":"EOSUSD","U":167006223169,"u":167006223476,"pu":167006223094,"b":[["3.468","0"]],"a":[]}}
1626916426.312947: {"stream":"ethusd_210924@depth@100ms","data":{"e":"depthUpdate","E":1626916426338,"T":1626916426328,"s":"ETHUSD_210924","ps":"ETHUSD","U":167006223208,"u":167006223498,"pu":167006223116,"b":[["1681.87","2100"],["1986.30","0"],["1986.60","190"],["1986.63","0"],["1987.54","0"],["1988.48","1478"],["1988.87","545"],["1990.02","0"],["1990.03","127"],["1990.06","360"],["1990.18","0"],["1990.19","0"],["1990.20","0"],["1990.21","0"]],"a":[["1992.14","1175"],["2142.15","5300"]]}}
1626916426.314498: {"stream":"trxusd_perp@depth@100ms","data":{"e":"depthUpdate","E":1626916426343,"T":1626916426239,"s":"TRXUSD_PERP","ps":"TRXUSD","U":167006223234,"u":167006223237,"pu":167006223204,"b":[],"a":[["0.05348","449"],["0.05349","1116"]]}}
1626916426.325977: {"stream":"xrpusd_perp@depth@100ms","data":{"e":"depthUpdate","E":1626916426350,"T":1626916426317,"s":"XRPUSD_PERP","ps":"XRPUSD","U":167006223259,"u":167006223489,"pu":167006222683,"b":[["0.5650","6185"]],"a":[["0.5662","1753"],["0.5663","3554"]]}}
1626916426.330409: {"stream":"etcusd_perp@depth@100ms","data":{"e":"depthUpdate","E":1626916426357,"T":1626916426253,"s":"ETCUSD_PERP","ps":"ETCUSD","U":167006223282,"u":167006223282,"pu":167006223254,"b":[["42.186","490"]],"a":[]}}
1626916426.351892: {"stream":"linkusd_perp@depth@100ms","data":{"e":"depthUpdate","E":1626916426377,"T":1626916426305,"s":"LINKUSD_PERP","ps":"LINKUSD","U":167006223326,"u":167006223448,"pu":167006223129,"b":[["15.055","300"],["15.057","959"]],"a":[["15.106","121"]]}}
1626916426.377826: {"stream":"btcusd_211231@depth@100ms","data":{"e":"depthUpdate","E":1626916426401,"T":1626916426360,"s":"BTCUSD_211231","ps":"BTCUSD","U":167006223404,"u":167006223607,"pu":167006223284,"b":[["28223.7","0"],["31364.2","55"],["31524.2","55"],["31684.2","55"],["31844.3","55"],["32004.3","55"],["32049.6","320"]],"a":[]}}
1626916426.382815: {"stream":"bchusd_perp@depth@100ms","data":{"e":"depthUpdate","E":1626916426408,"T":1626916426383,"s":"BCHUSD_PERP","ps":"BCHUSD","U":167006223445,"u":167006223680,"pu":167006223106,"b":[],"a":[["427.81","860"],["427.86","0"]]}}
1626916426.41434: {"stream":"eosusd_perp@depth@100ms","data":{"e":"depthUpdate","E":1626916426441,"T":1626916426420,"s":"EOSUSD_PERP","ps":"EOSUSD","U":167006223535,"u":167006223839,"pu":167006223476,"b":[["3.468","0"]],"a":[]}}
1626916426.42658: {"stream":"ethusd_210924@depth@100ms","data":{"e":"depthUpdate","E":1626916426448,"T":1626916426428,"s":"ETHUSD_210924","ps":"ETHUSD","U":167006223559,"u":167006223875,"pu":167006223498,"b":[["1990.03","0"],["1990.06","0"],["1990.07","0"],["1990.10","0"],["1990.11","126"],["1990.14","360"]],"a":[]}}
1626916426.450876: {"stream":"xrpusd_perp@depth@100ms","data":{"e":"depthUpdate","E":1626916426478,"T":1626916426454,"s":"XRPUSD_PERP","ps":"XRPUSD","U":167006223660,"u":167006223957,"pu":167006223489,"b":[["0.5658","4361"],["0.5660","5302"],["0.5661","2780"]],"a":[]}}
1626916426.4681401: {"stream":"bchusd_210924@depth@100ms","data":{"e":"depthUpdate","E":1626916426494,"T":1626916426483,"s":"BCHUSD_210924","ps":"BCHUSD","U":167006223719,"u":167006224073,"pu":167006222989,"b":[["426.33","42"],["427.19","42"],["429.35","30"]],"a":[]}}
1626916426.475509: {"stream":"linkusd_perp@depth@100ms","data":{"e":"depthUpdate","E":1626916426500,"T":1626916426398,"s":"LINKUSD_PERP","ps":"LINKUSD","U":167006223751,"u":167006223751,"pu":167006223448,"b":[],"a":[["15.067","191"]]}}
1626916426.4910028: {"stream":"etcusd_perp@depth@100ms","data":{"e":"depthUpdate","E":1626916426518,"T":1626916426509,"s":"ETCUSD_PERP","ps":"ETCUSD","U":167006223819,"u":167006224182,"pu":167006223282,"b":[["42.212","1440"],["42.217","0"],["42.245","386"]],"a":[["42.271","150"],["42.273","352"],["42.308","500"],["42.310","1193"],["42.315","0"],["42.325","200"],["42.330","72"]]}}
1626916426.4966989: {"stream":"bchusd_perp@depth@100ms","data":{"e":"depthUpdate","E":1626916426525,"T":1626916426519,"s":"BCHUSD_PERP","ps":"BCHUSD","U":167006223841,"u":167006224231,"pu":167006223680,"b":[["427.64","2914"],["427.65","1309"],["427.66","130"],["427.67","0"],["427.68","0"],["427.72","0"],["427.77","1"]],"a":[["427.81","760"],["427.86","100"]]}}
1626916426.5210419: {"stream":"eosusd_perp@depth@100ms","data":{"e":"depthUpdate","E":1626916426547,"T":1626916426529,"s":"EOSUSD_PERP","ps":"EOSUSD","U":167006223901,"u":167006224286,"pu":167006223839,"b":[["3.468","0"]],"a":[]}}
1626916426.53387: {"stream":"ethusd_210924@depth@100ms","data":{"e":"depthUpdate","E":1626916426549,"T":1626916426543,"s":"ETHUSD_210924","ps":"ETHUSD","U":167006223912,"u":167006224345,"pu":167006223875,"b":[["1989.83","466"],["1989.99","0"],["1990.11","0"],["1990.14","0"],["1990.15","0"],["1990.18","480"],["1990.19","295"],["1990.21","360"],["1990.22","127"]],"a":[["1990.57","0"],["2023.17","408"],["2033.08","410"],["2043.00","412"],["2052.92","413"],["2062.84","416"]]}}
1626916426.582635: {"stream":"trxusd_perp@depth@100ms","data":{"e":"depthUpdate","E":1626916426611,"T":1626916426550,"s":"TRXUSD_PERP","ps":"TRXUSD","U":167006224173,"u":167006224382,"pu":167006223237,"b":[],"a":[["0.05348","649"],["0.05349","1316"],["0.05350","2793"],["0.05351","2410"],["0.05355","1249"],["0.05358","1138"]]}}
1626916426.5969532: {"stream":"etcusd_perp@depth@100ms","data":{"e":"depthUpdate","E":1626916426623,"T":1626916426618,"s":"ETCUSD_PERP","ps":"ETCUSD","U":167006224226,"u":167006224697,"pu":167006224182,"b":[["42.207","2050"],["42.212","1240"],["42.225","1701"],["42.227","1453"],["42.236","25"],["42.237","283"],["42.244","400"],["42.246","0"],["42.247","687"],["42.248","0"],["42.249","0"],["42.250","323"],["42.251","90"],["42.252","241"]],"a":[["42.271","0"],["42.272","0"],["42.273","0"],["42.275","0"],["42.276","0"],["42.278","100"],["42.279","300"],["42.300","200"],["42.310","1226"],["42.329","0"],["42.333","419"],["42.340","280"]]}}
1626916426.5971498: {"stream":"bchusd_perp@depth@100ms","data":{"e":"depthUpdate","E":1626916426625,"T":1626916426607,"s":"BCHUSD_PERP","ps":"BCHUSD","U":167006224232,"u":167006224640,"pu":167006224231,"b":[["427.51","270"],["427.60","100"],["427.67","0"]],"a":[["427.80","572"],["427.81","860"],["427.86","0"],["427.87","127"],["427.98","581"]]}}
1626916426.5996218: {"stream":"bchusd_210924@depth@100ms","data":{"e":"depthUpdate","E":1626916426625,"T":1626916426566,"s":"BCHUSD_210924","ps":"BCHUSD","U":167006224234,"u":167006224477,"pu":167006224073,"b":[["429.12","0"],["429.23","0"],["429.29","40"]],"a":[]}}
1626916426.607548: {"stream":"linkusd_perp@depth@100ms","data":{"e":"depthUpdate","E":1626916426634,"T":1626916426625,"s":"LINKUSD_PERP","ps":"LINKUSD","U":167006224287,"u":167006224719,"pu":167006223751,"b":[["15.042","785"],["15.052","180"],["15.054","148"],["15.057","1449"],["15.058","220"],["15.059","512"],["15.062","0"],["15.063","0"],["15.064","100"],["15.065","36"]],"a":[["15.067","439"],["15.068","100"],["15.069","833"],["15.071","550"],["15.073","1524"],["15.075","844"],["15.076","401"],["15.077","795"]]}}
1626916426.61175: {"stream":"linkusd_211231@depth@100ms","data":{"e":"depthUpdate","E":1626916426639,"T":1626916426608,"s":"LINKUSD_211231","ps":"LINKUSD","U":167006224313,"u":167006224645,"pu":167006223203,"b":[["15.290","0"],["15.296","58"]],"a":[["15.329","848"],["15.330","0"],["15.334","55"]]}}
1626916426.621145: {"stream":"ethusd_210924@depth@100ms","data":{"e":"depthUpdate","E":1626916426649,"T":1626916426632,"s":"ETHUSD_210924","ps":"ETHUSD","U":167006224346,"u":167006224754,"pu":167006224345,"b":[["1989.67","0"],["1989.99","270"]],"a":[["1990.66","2269"]]}}
1626916426.630924: {"stream":"eosusd_perp@depth@100ms","data":{"e":"depthUpdate","E":1626916426656,"T":1626916426638,"s":"EOSUSD_PERP","ps":"EOSUSD","U":167006224383,"u":167006224779,"pu":167006224286,"b":[["3.468","0"]],"a":[["3.470","4643"],["3.471","5287"]]}}
1626916426.6330292: {"stream":"btcusd_211231@depth@100ms","data":{"e":"depthUpdate","E":1626916426660,"T":1626916426596,"s":"BTCUSD_211231","ps":"BTCUSD","U":167006224416,"u":167006224613,"pu":167006223607,"b":[["28217.4","281"]],"a":[["32628.5","153"],["32628.6","0"],["32633.7","46"],["32634.6","0"]]}}
1626916426.7005188: {"stream":"etcusd_perp@depth@100ms","data":{"e":"depthUpdate","E":1626916426727,"T":1626916426720,"s":"ETCUSD_PERP","ps":"ETCUSD","U":167006224704,"u":167006225223,"pu":167006224697,"b":[["41.912","0"],["41.925","560"],["42.158","0"],["42.170","70"],["42.171","459"],["42.181","145"],["42.186","0"],["42.207","1994"],["42.212","0"],["42.213","330"],["42.215","0"],["42.219","0"],["42.224","268"],["42.227","1431"],["42.233","122"],["42.238","70"],["42.239","22"],["42.240","0"],["42.245","0"],["42.247","0"],["42.250","0"],["42.251","0"],["42.253","90"]],"a":[["42.278","100"],["42.279","150"],["42.284","0"],["42.285","0"],["42.286","551"],["42.287","1473"],["42.295","603"],["42.296","349"],["42.300","0"],["42.305","0"],["42.311","55"],["42.316","258"],["42.325","0"],["42.330","272"],["42.356","0"],["42.358","539"],["42.368","745"],["42.386","325"]]}}
1626916426.71714: {"stream":"linkusd_211231@depth@100ms","data":{"e":"depthUpdate","E":1626916426743,"T":1626916426638,"s":"LINKUSD_211231","ps":"LINKUSD","U":167006224776,"u":167006224776,"pu":167006224645,"b":[["15.283","123"]],"a":[]}}
1626916426.721144: {"stream":"linkusd_perp@depth@100ms","data":{"e":"depthUpdate","E":1626916426747,"T":1626916426740,"s":"LINKUSD_PERP","ps":"LINKUSD","U":167006224801,"u":167006225324,"pu":167006224719,"b":[["15.042","737"],["15.048","2290"],["15.053","3308"],["15.057","1339"],["15.060","211"],["15.062","100"],["15.063","0"],["15.064","0"],["15.065","35"]],"a":[["15.067","440"],["15.074","1891"],["15.075","464"],["15.076","601"],["15.078","825"],["15.081","135"],["15.085","564"],["15.174","0"]]}}
1626916426.726676: {"stream":"bchusd_perp@depth@100ms","data":{"e":"depthUpdate","E":1626916426751,"T":1626916426736,"s":"BCHUSD_PERP","ps":"BCHUSD","U":167006224819,"u":167006225303,"pu":167006224640,"b":[["427.20","200"],["427.77","1"]],"a":[["427.81","100"],["427.99","1888"],["428.01","6051"],["430.57","0"]]}}
1626916426.726893: {"stream":"ethusd_210924@depth@100ms","data":{"e":"depthUpdate","E":1626916426754,"T":1626916426748,"s":"ETHUSD_210924","ps":"ETHUSD","U":167006224821,"u":167006225351,"pu":167006224754,"b":[["1985.83","500"]],"a":[["1990.84","142"],["1990.99","1000"],["1995.80","1277"],["1996.61","0"]]}}
1626916426.7396789: {"stream":"eosusd_perp@depth@100ms","data":{"e":"depthUpdate","E":1626916426766,"T":1626916426758,"s":"EOSUSD_PERP","ps":"EOSUSD","U":167006224870,"u":167006225444,"pu":167006224779,"b":[["3.468","0"]],"a":[["3.470","4743"],["3.471","5187"],["3.483","647"],["3.490","1548"]]}}
1626916426.744053: {"stream":"btcusd_211231@depth@100ms","data":{"e":"depthUpdate","E":1626916426771,"T":1626916426727,"s":"BTCUSD_211231","ps":"BTCUSD","U":167006224906,"u":167006225260,"pu":167006224613,"b":[["32344.0","604"]],"a":[["32628.5","0"],["32632.7","46"],["32633.6","153"],["32633.7","0"]]}}
1626916426.7472541: {"stream":"trxusd_perp@depth@100ms","data":{"e":"depthUpdate","E":1626916426774,"T":1626916426762,"s":"TRXUSD_PERP","ps":"TRXUSD","U":167006224935,"u":167006225474,"pu":167006224382,"b":[],"a":[["0.05348","449"],["0.05349","1016"],["0.05350","2993"],["0.05351","2610"],["0.05356","992"],["0.05359","306"]]}}
1626916426.783551: {"stream":"bchusd_210924@depth@100ms","data":{"e":"depthUpdate","E":1626916426809,"T":1626916426706,"s":"BCHUSD_210924","ps":"BCHUSD","U":167006225152,"u":167006225152,"pu":167006224477,"b":[],"a":[["429.73","1081"]]}}
1626916426.793251: {"stream":"xrpusd_perp@depth@100ms","data":{"e":"depthUpdate","E":1626916426820,"T":1626916426743,"s":"XRPUSD_PERP","ps":"XRPUSD","U":167006225213,"u":167006225339,"pu":167006223957,"b":[["0.5646","23367"]],"a":[["0.5677","3060"]]}}
1626916426.806318: {"stream":"etcusd_perp@depth@100ms","data":{"e":"depthUpdate","E":1626916426832,"T":1626916426818,"s":"ETCUSD_PERP","ps":"ETCUSD","U":167006225263,"u":167006225825,"pu":167006225223,"b":[["42.219","56"],["42.223","56"],["42.225","1459"],["42.238","310"]],"a":[["42.285","90"],["42.295","513"],["42.307","1161"],["42.317","770"],["42.320","200"],["42.325","724"],["42.326","56"],["42.345","0"],["42.566","0"]]}}
1626916426.8205929: {"stream":"linkusd_perp@depth@100ms","data":{"e":"depthUpdate","E":1626916426847,"T":1626916426833,"s":"LINKUSD_PERP","ps":"LINKUSD","U":167006225333,"u":167006225916,"pu":167006225324,"b":[["14.962","600"],["15.038","739"],["15.041","26"],["15.048","519"],["15.051","2118"],["15.053","3508"],["15.054","248"],["15.055","210"],["15.056","1710"],["15.057","959"],["15.059","212"],["15.060","101"],["15.062","100"],["15.063","0"],["15.064","0"],["15.065","0"]],"a":[["15.069","1924"],["15.071","350"],["15.073","1914"],["15.074","1511"],["15.081","25"],["15.089","0"],["15.171","1340"]]}}
1626916426.8319418: {"stream":"ethusd_210924@depth@100ms","data":{"e":"depthUpdate","E":1626916426858,"T":1626916426850,"s":"ETHUSD_210924","ps":"ETHUSD","U":167006225411,"u":167006225993,"pu":167006225351,"b":[["1990.21","0"],["1990.22","0"],["1990.23","360"],["1990.24","125"],["1990.37","1015"]],"a":[["1990.38","1201"],["1990.65","0"],["1990.66","0"],["1990.72","0"],["1990.94","270"],["1990.97","360"]]}}
1626916426.835652: {"stream":"bchusd_perp@depth@100ms","data":{"e":"depthUpdate","E":1626916426863,"T":1626916426801,"s":"BCHUSD_PERP","ps":"BCHUSD","U":167006225446,"u":167006225737,"pu":167006225303,"b":[["424.79","0"],["427.60","0"],["427.65","1409"]],"a":[["427.82","2909"],["429.72","0"]]}}
1626916426.844238: {"stream":"eosusd_perp@depth@100ms","data":{"e":"depthUpdate","E":1626916426870,"T":1626916426863,"s":"EOSUSD_PERP","ps":"EOSUSD","U":167006225485,"u":167006226072,"pu":167006225444,"b":[["3.468","0"]],"a":[["3.479","3227"]]}}
1626916426.852604: {"stream":"linkusd_211231@depth@100ms","data":{"e":"depthUpdate","E":1626916426878,"T":1626916426832,"s":"LINKUSD_211231","ps":"LINKUSD","U":167006225532,"u":167006225907,"pu":167006224776,"b":[["15.271","1231"]],"a":[["15.358","1609"]]}}
1626916426.852758: {"stream":"btcusd_211231@depth@100ms","data":{"e":"depthUpdate","E":1626916426881,"T":1626916426824,"s":"BTCUSD_211231","ps":"BTCUSD","U":167006225577,"u":167006225863,"pu":167006225260,"b":[],"a":[["32631.7","46"],["32632.6","153"],["32632.7","0"],["32633.6","0"]]}}
1626916426.8963819: {"stream":"xrpusd_perp@depth@100ms","data":{"e":"depthUpdate","E":1626916426923,"T":1626916426838,"s":"XRPUSD_PERP","ps":"XRPUSD","U":167006225807,"u":167006225944,"pu":167006225339,"b":[],"a":[["0.5662","1753"]]}}
1626916426.922709: {"stream":"linkusd_perp@depth@100ms","data":{"e":"depthUpdate","E":1626916426948,"T":1626916426937,"s":"LINKUSD_PERP","ps":"LINKUSD","U":167006225968,"u":167006226493,"pu":167006225916,"b":[["15.008","451"],["15.033","16115"],["15.036","840"],["15.039","454"],["15.048","371"],["15.055","100"],["15.056","1562"],["15.058","330"]],"a":[["15.069","1624"],["15.073","1885"],["15.074","1482"],["15.078","825"],["15.080","779"],["15.128","991"]]}}
1626916426.928342: {"stream":"etcusd_perp@depth@100ms","data":{"e":"depthUpdate","E":1626916426954,"T":1626916426938,"s":"ETCUSD_PERP","ps":"ETCUSD","U":167006225996,"u":167006226500,"pu":167006225825,"b":[["42.239","112"],["42.253","0"]],"a":[["42.301","0"],["42.309","22"],["42.478","0"],["42.491","336"],["42.567","212"]]}}
1626916426.93451: {"stream":"ethusd_210924@depth@100ms","data":{"e":"depthUpdate","E":1626916426962,"T":1626916426944,"s":"ETHUSD_210924","ps":"ETHUSD","U":167006226033,"u":167006226537,"pu":167006225993,"b":[["1989.09","322"],["1989.98","0"],["1989.99","0"],["1990.23","0"],["1990.24","0"],["1990.25","270"],["1990.26","360"],["1990.27","222"]],"a":[["1990.38","120"],["1990.56","0"],["1990.58","0"],["1990.59","0"],["1990.72","350"],["1990.84","0"],["1990.86","0"],["1990.93","642"],["1991.72","322"]]}}
1626916426.957797: {"stream":"eosusd_perp@depth@100ms","data":{"e":"depthUpdate","E":1626916426985,"T":1626916426974,"s":"EOSUSD_PERP","ps":"EOSUSD","U":167006226145,"u":167006226712,"pu":167006226072,"b":[["3.468","0"]],"a":[["3.479","3328"]]}}
1626916426.9611552: {"stream":"linkusd_211231@depth@100ms","data":{"e":"depthUpdate","E":1626916426987,"T":1626916426883,"s":"LINKUSD_211231","ps":"LINKUSD","U":167006226164,"u":167006226164,"pu":167006225907,"b":[],"a":[["15.351","40"]]}}
1626916426.964371: {"stream":"btcusd_211231@depth@100ms","data":{"e":"depthUpdate","E":1626916426992,"T":1626916426966,"s":"BTCUSD_211231","ps":"BTCUSD","U":167006226187,"u":167006226664,"pu":167006225863,"b":[],"a":[["32630.7","0"],["32631.6","0"],["32631.7","0"],["32632.6","0"],["32633.7","46"],["32634.6","153"],["32639.1","0"],["32648.6","0"]]}}
1626916427.022768: {"stream":"linkusd_perp@depth@100ms","data":{"e":"depthUpdate","E":1626916427048,"T":1626916427043,"s":"LINKUSD_PERP","ps":"LINKUSD","U":167006226526,"u":167006227018,"pu":167006226493,"b":[["15.000","2853"],["15.004","262"],["15.005","444"],["15.033","16307"],["15.045","253"],["15.048","251"],["15.051","2347"],["15.053","3279"],["15.057","1259"]],"a":[["15.071","879"],["15.072","29"],["15.073","1685"],["15.076","675"],["15.089","192"],["15.091","472"],["15.094","221"],["15.124","624"]]}}
1626916427.0293188: {"stream":"etcusd_perp@depth@100ms","data":{"e":"depthUpdate","E":1626916427057,"T":1626916427029,"s":"ETCUSD_PERP","ps":"ETCUSD","U":167006226594,"u":167006226964,"pu":167006226500,"b":[["42.233","322"],["42.244","100"]],"a":[["42.278","90"],["42.284","0"],["42.285","0"],["42.300","200"],["42.320","0"],["42.331","110"]]}}
1626916427.0423691: {"stream":"ethusd_210924@depth@100ms","data":{"e":"depthUpdate","E":1626916427069,"T":1626916427051,"s":"ETHUSD_210924","ps":"ETHUSD","U":167006226658,"u":167006227055,"pu":167006226537,"b":[["1966.30","0"],["1987.67","0"],["1988.66","3094"],["1989.05","3600"],["1989.20","314"],["1990.25","0"],["1990.37","1285"]],"a":[["1990.99","0"],["1994.96","0"],["1999.93","0"]]}}
1626916427.0592508: {"stream":"bchusd_perp@depth@100ms","data":{"e":"depthUpdate","E":1626916427087,"T":1626916427015,"s":"BCHUSD_PERP","ps":"BCHUSD","U":167006226738,"u":167006226897,"pu":167006225737,"b":[],"a":[["429.92","42"],["430.77","43"]]}}
1626916427.065886: {"stream":"btcusd_211231@depth@100ms","data":{"e":"depthUpdate","E":1626916427093,"T":1626916427070,"s":"BTCUSD_211231","ps":"BTCUSD","U":167006226752,"u":167006227133,"pu":167006226664,"b":[["30444.6","0"],["31258.6","0"],["31828.4","0"],["32527.0","0"],["32527.2","1514"]],"a":[["32621.3","17"],["32631.6","0"],["32632.7","46"],["32633.6","153"],["32633.7","0"],["32634.6","0"],["32710.1","0"],["33428.6","0"],["34000.7","0"],["34818.0","0"]]}}
1626916427.075586: {"stream":"eosusd_perp@depth@100ms","data":{"e":"depthUpdate","E":1626916427102,"T":1626916427096,"s":"EOSUSD_PERP","ps":"EOSUSD","U":167006226840,"u":167006227249,"pu":167006226712,"b":[["3.467","995"],["3.468","0"]],"a":[["3.468","210"],["3.478","6552"],["3.485","5748"],["3.492","9859"]]}}
1626916427.112345: {"stream":"linkusd_211231@depth@100ms","data":{"e":"depthUpdate","E":1626916427137,"T":1626916427077,"s":"LINKUSD_211231","ps":"LINKUSD","U":167006226987,"u":167006227164,"pu":167006226164,"b":[],"a":[["62.982","15276"],["62.990","0"]]}}
1626916427.139285: {"stream":"linkusd_perp@depth@100ms","data":{"e":"depthUpdate","E":1626916427166,"T":1626916427157,"s":"LINKUSD_PERP","ps":"LINKUSD","U":167006227082,"u":167006227491,"pu":167006227018,"b":[["15.050","460"],["15.053","3079"],["15.058","220"],["15.061","350"]],"a":[["15.069","1724"],["15.071","779"],["15.172","119"]]}}
1626916427.1424809: {"stream":"bchusd_210924@depth@100ms","data":{"e":"depthUpdate","E":1626916427169,"T":1626916427063,"s":"BCHUSD_210924","ps":"BCHUSD","U":167006227095,"u":167006227095,"pu":167006225152,"b":[["429.35","0"]],"a":[]}}
1626916427.1492338: {"stream":"etcusd_perp@depth@100ms","data":{"e":"depthUpdate","E":1626916427176,"T":1626916427139,"s":"ETCUSD_PERP","ps":"ETCUSD","U":167006227137,"u":167006227432,"pu":167006226964,"b":[["42.171","145"],["42.207","1310"],["42.210","332"],["42.233","122"],["42.241","200"],["42.243","14"]],"a":[["42.284","241"],["42.287","1173"],["42.300","0"]]}}
1626916427.1514518: {"stream":"ethusd_210924@depth@100ms","data":{"e":"depthUpdate","E":1626916427178,"T":1626916427164,"s":"ETHUSD_210924","ps":"ETHUSD","U":167006227142,"u":167006227520,"pu":167006227055,"b":[["1980.04","0"],["1985.02","0"]],"a":[["1990.92","270"],["1990.94","0"],["1991.21","0"],["1991.90","0"],["1992.89","673"],["2060.96","0"]]}}
1626916427.164086: {"stream":"xrpusd_perp@depth@100ms","data":{"e":"depthUpdate","E":1626916427192,"T":1626916427143,"s":"XRPUSD_PERP","ps":"XRPUSD","U":167006227212,"u":167006227450,"pu":167006225944,"b":[["0.5653","4290"],["0.5659","1430"]],"a":[["0.5668","5268"]]}}
1626916427.171577: {"stream":"btcusd_211231@depth@100ms","data":{"e":"depthUpdate","E":1626916427199,"T":1626916427119,"s":"BTCUSD_211231","ps":"BTCUSD","U":167006227225,"u":167006227354,"pu":167006227133,"b":[],"a":[["32631.7","46"],["32632.6","153"],["32632.7","0"],["32633.6","0"],["33031.1","45"],["33191.2","45"],["33351.2","45"],["33511.2","46"],["33671.3","46"]]}}
1626916427.1801972: {"stream":"eosusd_perp@depth@100ms","data":{"e":"depthUpdate","E":1626916427208,"T":1626916427191,"s":"EOSUSD_PERP","ps":"EOSUSD","U":167006227273,"u":167006227642,"pu":167006227249,"b":[["3.457","3036"],["3.468","0"]],"a":[]}}
1626916427.191218: {"stream":"trxusd_perp@depth@100ms","data":{"e":"depthUpdate","E":1626916427217,"T":1626916427115,"s":"TRXUSD_PERP","ps":"TRXUSD","U":167006227317,"u":167006227324,"pu":167006225474,"b":[],"a":[["0.05348","349"],["0.05349","916"],["0.05350","3193"],["0.05351","2810"]]}}
1626916427.251473: {"stream":"linkusd_perp@depth@100ms","data":{"e":"depthUpdate","E":1626916427277,"T":1626916427243,"s":"LINKUSD_PERP","ps":"LINKUSD","U":167006227556,"u":167006227858,"pu":167006227491,"b":[["15.053","3179"],["15.055","0"]],"a":[["15.069","1624"],["15.070","4737"],["15.071","579"],["15.072","29"],["15.073","1885"]]}}
1626916427.2517738: {"stream":"etcusd_perp@depth@100ms","data":{"e":"depthUpdate","E":1626916427279,"T":1626916427267,"s":"ETCUSD_PERP","ps":"ETCUSD","U":167006227561,"u":167006227951,"pu":167006227432,"b":[["42.228","1663"],["42.240","33"],["42.244","0"],["42.245","100"],["42.252","5"]],"a":[["42.277","100"],["42.279","150"],["42.280","300"],["42.284","0"],["42.310","712"],["42.345","70"]]}}
1626916427.25455: {"stream":"ethusd_210924@depth@100ms","data":{"e":"depthUpdate","E":1626916427281,"T":1626916427254,"s":"ETHUSD_210924","ps":"ETHUSD","U":167006227574,"u":167006227896,"pu":167006227520,"b":[["1986.44","500"],["1987.73","0"],["1988.18","100"],["1990.60","0"]],"a":[["1990.38","504"],["1990.55","0"],["1990.56","0"],["1991.25","1000"]]}}
1626916427.281454: {"stream":"btcusd_211231@depth@100ms","data":{"e":"depthUpdate","E":1626916427308,"T":1626916427297,"s":"BTCUSD_211231","ps":"BTCUSD","U":167006227692,"u":167006228095,"pu":167006227354,"b":[["31364.2","0"],["31524.2","0"],["31684.2","0"],["31844.3","0"],["32004.3","0"]],"a":[["32630.7","46"],["32631.6","153"],["32631.7","0"],["32632.6","0"],["32696.2","354"]]}}
1626916427.2817202: {"stream":"eosusd_perp@depth@100ms","data":{"e":"depthUpdate","E":1626916427308,"T":1626916427295,"s":"EOSUSD_PERP","ps":"EOSUSD","U":167006227685,"u":167006228086,"pu":167006227642,"b":[["3.466","4372"],["3.468","0"]],"a":[]}}
1626916427.2974348: {"stream":"bchusd_perp@depth@100ms","data":{"e":"depthUpdate","E":1626916427325,"T":1626916427220,"s":"BCHUSD_PERP","ps":"BCHUSD","U":167006227758,"u":167006227758,"pu":167006226897,"b":[["427.77","25"]],"a":[]}}
1626916427.314076: {"stream":"linkusd_211231@depth@100ms","data":{"e":"depthUpdate","E":1626916427341,"T":1626916427288,"s":"LINKUSD_211231","ps":"LINKUSD","U":167006227822,"u":167006228048,"pu":167006227164,"b":[["14.763","0"],["14.839","0"],["14.914","0"],["14.989","0"],["15.065","0"]],"a":[["15.328","297"]]}}
1626916427.353045: {"stream":"linkusd_perp@depth@100ms","data":{"e":"depthUpdate","E":1626916427378,"T":1626916427342,"s":"LINKUSD_PERP","ps":"LINKUSD","U":167006227971,"u":167006228265,"pu":167006227858,"b":[["15.044","2463"],["15.051","2447"],["15.053","3079"],["15.063","37"]],"a":[["15.071","727"]]}}
1626916427.353222: {"stream":"etcusd_perp@depth@100ms","data":{"e":"depthUpdate","E":1626916427380,"T":1626916427366,"s":"ETCUSD_PERP","ps":"ETCUSD","U":167006227982,"u":167006228352,"pu":167006227951,"b":[["42.227","322"],["42.233","369"],["42.238","1159"],["42.242","150"],["42.245","180"]],"a":[["42.276","0"],["42.277","0"],["42.278","100"],["42.285","90"]]}}
1626916427.369535: {"stream":"ethusd_210924@depth@100ms","data":{"e":"depthUpdate","E":1626916427395,"T":1626916427382,"s":"ETHUSD_210924","ps":"ETHUSD","U":167006228050,"u":167006228441,"pu":167006227896,"b":[["1986.53","1000"],["1988.32","0"],["1988.66","0"],["1989.84","270"],["1989.95","0"],["1990.28","0"],["1990.37","1015"]],"a":[["1990.91","270"],["1990.92","0"],["1990.93","802"],["1990.94","0"],["1991.21","0"],["1991.27","0"],["1992.78","0"],["1994.70","0"],["1995.00","190"],["2060.67","2573"],["2142.15","7950"],["2144.26","0"]]}}
1626916427.3883321: {"stream":"eosusd_perp@depth@100ms","data":{"e":"depthUpdate","E":1626916427415,"T":1626916427399,"s":"EOSUSD_PERP","ps":"EOSUSD","U":167006228151,"u":167006228550,"pu":167006228086,"b":[["3.464","3350"],["3.465","8939"],["3.466","4372"],["3.468","0"]],"a":[]}}
1626916427.391618: {"stream":"btcusd_211231@depth@100ms","data":{"e":"depthUpdate","E":1626916427419,"T":1626916427399,"s":"BTCUSD_211231","ps":"BTCUSD","U":167006228166,"u":167006228547,"pu":167006228095,"b":[["30194.9","0"],["31364.2","55"],["31524.2","55"],["31684.3","55"],["31844.3","55"],["32004.3","55"]],"a":[["32629.7","46"],["32630.6","153"],["32630.7","0"],["32631.6","0"]]}}
1626916427.4158442: {"stream":"xrpusd_perp@depth@100ms","data":{"e":"depthUpdate","E":1626916427442,"T":1626916427431,"s":"XRPUSD_PERP","ps":"XRPUSD","U":167006228249,"u":167006228704,"pu":167006227450,"b":[],"a":[["0.5662","1725"],["0.5663","2844"]]}}
1626916427.443744: {"stream":"bchusd_perp@depth@100ms","data":{"e":"depthUpdate","E":1626916427471,"T":1626916427424,"s":"BCHUSD_PERP","ps":"BCHUSD","U":167006228358,"u":167006228677,"pu":167006227758,"b":[["424.79","610"],["427.77","225"]],"a":[["427.78","636"],["427.80","0"]]}}
1626916427.449707: {"stream":"trxusd_perp@depth@100ms","data":{"e":"depthUpdate","E":1626916427477,"T":1626916427372,"s":"TRXUSD_PERP","ps":"TRXUSD","U":167006228394,"u":167006228394,"pu":167006227324,"b":[],"a":[["0.05346","960"]]}}
1626916427.4574468: {"stream":"etcusd_perp@depth@100ms","data":{"e":"depthUpdate","E":1626916427485,"T":1626916427465,"s":"ETCUSD_PERP","ps":"ETCUSD","U":167006228443,"u":167006228843,"pu":167006228352,"b":[["42.230","70"],["42.233","569"],["42.238","1089"],["42.239","22"],["42.240","233"],["42.241","0"],["42.246","90"]],"a":[]}}
1626916427.457654: {"stream":"linkusd_perp@depth@100ms","data":{"e":"depthUpdate","E":1626916427485,"T":1626916427473,"s":"LINKUSD_PERP","ps":"LINKUSD","U":167006228445,"u":167006228867,"pu":167006228265,"b":[],"a":[["15.067","540"],["15.068","0"],["15.069","0"],["15.070","4737"],["15.072","229"],["15.073","1685"],["15.271","0"]]}}
