wss://stream-cloud.trbinance.com/stream?streams=belbtc@kline_1m/xemusdt@kline_1m/elfbusd@kline_1m/ltcbrl@kline_1m/belbtc@aggTrade/xemusdt@aggTrade/elfbusd@aggTrade/ltcbrl@aggTrade/belbtc@depth@100ms/xemusdt@depth@100ms/elfbusd@depth@100ms/ltcbrl@depth@100ms/belbtc@bookTicker/xemusdt@bookTicker/elfbusd@bookTicker/ltcbrl@bookTicker <-> 1681154038.65506
1681154040.0430064: {"stream":"xemusdt@bookTicker","data":{"u":542937457,"s":"XEMUSDT","b":"0.04100000","B":"485240.00000000","a":"0.04110000","A":"44994.00000000"}}
1681154040.0465894: {"stream":"xemusdt@depth@100ms","data":{"e":"depthUpdate","E":1681154039900,"s":"XEMUSDT","U":542937454,"u":542937457,"b":[["0.04100000","485240.00000000"]],"a":[["0.04210000","661133.00000000"],["0.04360000","607624.00000000"]]}}
1681154040.3172204: {"stream":"xemusdt@kline_1m","data":{"e":"kline","E":1681154040004,"s":"XEMUSDT","k":{"t":1681153980000,"T":1681154039999,"s":"XEMUSDT","i":"1m","f":35012468,"L":35012468,"o":"0.04110000","c":"0.04110000","h":"0.04110000","l":"0.04110000","v":"243.00000000","n":1,"x":true,"q":"9.98730000","V":"243.00000000","Q":"9.98730000","B":"0"}}}
1681154040.3172522: {"stream":"ltcbrl@kline_1m","data":{"e":"kline","E":1681154040004,"s":"LTCBRL","k":{"t":1681153980000,"T":1681154039999,"s":"LTCBRL","i":"1m","f":1758813,"L":1758814,"o":"473.30000000","c":"473.10000000","h":"473.30000000","l":"473.10000000","v":"0.53400000","n":2,"x":true,"q":"252.73120000","V":"0.00000000","Q":"0.00000000","B":"0"}}}
1681154040.317271: {"stream":"belbtc@kline_1m","data":{"e":"kline","E":1681154040004,"s":"BELBTC","k":{"t":1681153980000,"T":1681154039999,"s":"BELBTC","i":"1m","f":-1,"L":-1,"o":"0.00002369","c":"0.00002369","h":"0.00002369","l":"0.00002369","v":"0.00000000","n":0,"x":true,"q":"0.00000000","V":"0.00000000","Q":"0.00000000","B":"0"}}}
1681154040.3172872: {"stream":"elfbusd@kline_1m","data":{"e":"kline","E":1681154040005,"s":"ELFBUSD","k":{"t":1681153980000,"T":1681154039999,"s":"ELFBUSD","i":"1m","f":-1,"L":-1,"o":"0.31170000","c":"0.31170000","h":"0.31170000","l":"0.31170000","v":"0.00000000","n":0,"x":true,"q":"0.00000000","V":"0.00000000","Q":"0.00000000","B":"0"}}}
1681154040.3173022: {"stream":"xemusdt@depth@100ms","data":{"e":"depthUpdate","E":1681154040100,"s":"XEMUSDT","U":542937458,"u":542937458,"b":[["0.04080000","231406.00000000"]],"a":[]}}
1681154041.0802677: {"stream":"ltcbrl@bookTicker","data":{"u":126821977,"s":"LTCBRL","b":"473.10000000","B":"2.65300000","a":"473.40000000","A":"7.53200000"}}
1681154041.1463873: {"stream":"ltcbrl@depth@100ms","data":{"e":"depthUpdate","E":1681154041000,"s":"LTCBRL","U":126821977,"u":126821977,"b":[],"a":[["473.40000000","7.53200000"]]}}
1681154041.8973205: {"stream":"ltcbrl@bookTicker","data":{"u":126821978,"s":"LTCBRL","b":"473.10000000","B":"2.65300000","a":"473.60000000","A":"7.52800000"}}
1681154041.897344: {"stream":"ltcbrl@depth@100ms","data":{"e":"depthUpdate","E":1681154041100,"s":"LTCBRL","U":126821978,"u":126821978,"b":[],"a":[["473.40000000","0.00000000"]]}}
1681154042.346602: {"stream":"ltcbrl@depth@100ms","data":{"e":"depthUpdate","E":1681154042201,"s":"LTCBRL","U":126821979,"u":126821979,"b":[["470.10000000","9.75900000"],["469.70000000","0.00000000"]],"a":[]}}
1681154042.399767: {"stream":"belbtc@bookTicker","data":{"u":396548036,"s":"BELBTC","b":"0.00002361","B":"888.20000000","a":"0.00002368","A":"871.10000000"}}
1681154042.4451308: {"stream":"belbtc@depth@100ms","data":{"e":"depthUpdate","E":1681154042301,"s":"BELBTC","U":396548036,"u":396548037,"b":[["0.00002361","888.20000000"],["0.00002345","6585.50000000"]],"a":[]}}
1681154043.192257: {"stream":"ltcbrl@kline_1m","data":{"e":"kline","E":1681154042674,"s":"LTCBRL","k":{"t":1681154040000,"T":1681154099999,"s":"LTCBRL","i":"1m","f":-1,"L":-1,"o":"473.10000000","c":"473.10000000","h":"473.10000000","l":"473.10000000","v":"0.00000000","n":0,"x":false,"q":"0.00000000","V":"0.00000000","Q":"0.00000000","B":"0"}}}
1681154043.192279: {"stream":"belbtc@kline_1m","data":{"e":"kline","E":1681154042675,"s":"BELBTC","k":{"t":1681154040000,"T":1681154099999,"s":"BELBTC","i":"1m","f":-1,"L":-1,"o":"0.00002369","c":"0.00002369","h":"0.00002369","l":"0.00002369","v":"0.00000000","n":0,"x":false,"q":"0.00000000","V":"0.00000000","Q":"0.00000000","B":"0"}}}
1681154043.1922903: {"stream":"xemusdt@kline_1m","data":{"e":"kline","E":1681154042676,"s":"XEMUSDT","k":{"t":1681154040000,"T":1681154099999,"s":"XEMUSDT","i":"1m","f":-1,"L":-1,"o":"0.04110000","c":"0.04110000","h":"0.04110000","l":"0.04110000","v":"0.00000000","n":0,"x":false,"q":"0.00000000","V":"0.00000000","Q":"0.00000000","B":"0"}}}
1681154043.1923: {"stream":"elfbusd@kline_1m","data":{"e":"kline","E":1681154042676,"s":"ELFBUSD","k":{"t":1681154040000,"T":1681154099999,"s":"ELFBUSD","i":"1m","f":-1,"L":-1,"o":"0.31170000","c":"0.31170000","h":"0.31170000","l":"0.31170000","v":"0.00000000","n":0,"x":false,"q":"0.00000000","V":"0.00000000","Q":"0.00000000","B":"0"}}}
1681154043.1923091: {"stream":"belbtc@depth@100ms","data":{"e":"depthUpdate","E":1681154042801,"s":"BELBTC","U":396548038,"u":396548039,"b":[["0.00002334","3631.00000000"],["0.00002330","18.20000000"]],"a":[]}}
1681154043.2542748: {"stream":"ltcbrl@bookTicker","data":{"u":126821980,"s":"LTCBRL","b":"473.10000000","B":"2.65300000","a":"473.50000000","A":"2.14900000"}}
1681154043.2575123: {"stream":"ltcbrl@bookTicker","data":{"u":126821981,"s":"LTCBRL","b":"473.10000000","B":"2.65300000","a":"473.40000000","A":"7.53300000"}}
1681154043.3481474: {"stream":"ltcbrl@depth@100ms","data":{"e":"depthUpdate","E":1681154043202,"s":"LTCBRL","U":126821980,"u":126821981,"b":[],"a":[["473.40000000","7.53300000"],["473.50000000","2.14900000"]]}}
1681154043.3483896: {"stream":"xemusdt@depth@100ms","data":{"e":"depthUpdate","E":1681154043202,"s":"XEMUSDT","U":542937459,"u":542937459,"b":[["0.04090000","287225.00000000"]],"a":[]}}
1681154043.6482017: {"stream":"ltcbrl@depth@100ms","data":{"e":"depthUpdate","E":1681154043502,"s":"LTCBRL","U":126821982,"u":126821982,"b":[],"a":[["473.50000000","0.00000000"]]}}
1681154043.751356: {"stream":"ltcbrl@bookTicker","data":{"u":126821983,"s":"LTCBRL","b":"473.10000000","B":"2.65300000","a":"473.60000000","A":"7.52800000"}}
1681154043.8478286: {"stream":"ltcbrl@depth@100ms","data":{"e":"depthUpdate","E":1681154043702,"s":"LTCBRL","U":126821983,"u":126821985,"b":[["473.00000000","2.15200000"],["468.40000000","23.82800000"]],"a":[["473.40000000","0.00000000"]]}}
1681154044.0492547: {"stream":"xemusdt@depth@100ms","data":{"e":"depthUpdate","E":1681154043902,"s":"XEMUSDT","U":542937460,"u":542937460,"b":[["0.04080000","226536.00000000"]],"a":[]}}
1681154044.257686: {"stream":"ltcbrl@bookTicker","data":{"u":126821986,"s":"LTCBRL","b":"473.10000000","B":"2.65300000","a":"473.50000000","A":"2.14900000"}}
1681154044.2608845: {"stream":"ltcbrl@bookTicker","data":{"u":126821987,"s":"LTCBRL","b":"473.10000000","B":"2.65300000","a":"473.40000000","A":"7.53300000"}}
1681154044.3485954: {"stream":"ltcbrl@depth@100ms","data":{"e":"depthUpdate","E":1681154044202,"s":"LTCBRL","U":126821986,"u":126821987,"b":[],"a":[["473.40000000","7.53300000"],["473.50000000","2.14900000"]]}}
1681154045.1483834: {"stream":"xemusdt@depth@100ms","data":{"e":"depthUpdate","E":1681154045002,"s":"XEMUSDT","U":542937461,"u":542937461,"b":[["0.04090000","309404.00000000"]],"a":[]}}
1681154045.7859728: {"stream":"belbtc@bookTicker","data":{"u":396548040,"s":"BELBTC","b":"0.00002361","B":"598.50000000","a":"0.00002368","A":"871.10000000"}}
1681154045.8179886: {"stream":"belbtc@bookTicker","data":{"u":396548042,"s":"BELBTC","b":"0.00002362","B":"289.70000000","a":"0.00002368","A":"871.10000000"}}
1681154045.8335907: {"stream":"belbtc@bookTicker","data":{"u":396548045,"s":"BELBTC","b":"0.00002359","B":"145.40000000","a":"0.00002368","A":"871.10000000"}}
1681154045.8539236: {"stream":"belbtc@depth@100ms","data":{"e":"depthUpdate","E":1681154045703,"s":"BELBTC","U":396548040,"u":396548045,"b":[["0.00002362","0.00000000"],["0.00002361","0.00000000"],["0.00002359","145.40000000"],["0.00002352","154.10000000"]],"a":[]}}
1681154045.865203: {"stream":"belbtc@bookTicker","data":{"u":396548047,"s":"BELBTC","b":"0.00002362","B":"289.70000000","a":"0.00002368","A":"871.10000000"}}
1681154045.873763: {"stream":"belbtc@bookTicker","data":{"u":396548049,"s":"BELBTC","b":"0.00002359","B":"145.40000000","a":"0.00002368","A":"871.10000000"}}
1681154045.9095364: {"stream":"belbtc@bookTicker","data":{"u":396548050,"s":"BELBTC","b":"0.00002363","B":"289.70000000","a":"0.00002368","A":"871.10000000"}}
1681154045.9497972: {"stream":"belbtc@depth@100ms","data":{"e":"depthUpdate","E":1681154045803,"s":"BELBTC","U":396548046,"u":396548053,"b":[["0.00002363","289.70000000"],["0.00002362","0.00000000"],["0.00002355","189.10000000"],["0.00002354","1491.80000000"],["0.00002353","153.50000000"]],"a":[]}}
1681154045.997427: {"stream":"belbtc@bookTicker","data":{"u":396548055,"s":"BELBTC","b":"0.00002359","B":"775.40000000","a":"0.00002368","A":"871.10000000"}}
1681154046.0033085: {"stream":"belbtc@bookTicker","data":{"u":396548056,"s":"BELBTC","b":"0.00002360","B":"289.70000000","a":"0.00002368","A":"871.10000000"}}
1681154046.3914971: {"stream":"belbtc@depth@100ms","data":{"e":"depthUpdate","E":1681154045903,"s":"BELBTC","U":396548054,"u":396548056,"b":[["0.00002363","0.00000000"],["0.00002360","289.70000000"],["0.00002359","775.40000000"]],"a":[]}}
1681154046.3915486: {"stream":"xemusdt@depth@100ms","data":{"e":"depthUpdate","E":1681154045904,"s":"XEMUSDT","U":542937462,"u":542937462,"b":[["0.04090000","304534.00000000"]],"a":[]}}
1681154047.0517528: {"stream":"ltcbrl@depth@100ms","data":{"e":"depthUpdate","E":1681154046904,"s":"LTCBRL","U":126821988,"u":126821988,"b":[["473.00000000","0.00000000"]],"a":[]}}
1681154047.0646427: {"stream":"ltcbrl@bookTicker","data":{"u":126821990,"s":"LTCBRL","b":"472.90000000","B":"2.66100000","a":"473.40000000","A":"7.53300000"}}
1681154047.1511447: {"stream":"ltcbrl@depth@100ms","data":{"e":"depthUpdate","E":1681154047004,"s":"LTCBRL","U":126821989,"u":126821990,"b":[["473.10000000","0.00000000"],["472.90000000","2.66100000"]],"a":[]}}
1681154047.949658: {"stream":"belbtc@depth@100ms","data":{"e":"depthUpdate","E":1681154047804,"s":"BELBTC","U":396548057,"u":396548057,"b":[],"a":[["0.00002541","963.00000000"]]}}
1681154048.2570221: {"stream":"belbtc@depth@100ms","data":{"e":"depthUpdate","E":1681154048104,"s":"BELBTC","U":396548058,"u":396548058,"b":[],"a":[["0.00002539","623.20000000"]]}}
1681154048.751142: {"stream":"belbtc@depth@100ms","data":{"e":"depthUpdate","E":1681154048604,"s":"BELBTC","U":396548059,"u":396548059,"b":[["0.00002345","725.00000000"]],"a":[]}}
1681154049.3523006: {"stream":"ltcbrl@depth@100ms","data":{"e":"depthUpdate","E":1681154049204,"s":"LTCBRL","U":126821991,"u":126821991,"b":[["470.10000000","0.05300000"],["469.70000000","9.71400000"]],"a":[]}}
1681154050.4388506: {"stream":"xemusdt@bookTicker","data":{"u":542937463,"s":"XEMUSDT","b":"0.04100000","B":"485240.00000000","a":"0.04110000","A":"47491.00000000"}}
1681154050.4520152: {"stream":"xemusdt@depth@100ms","data":{"e":"depthUpdate","E":1681154050305,"s":"XEMUSDT","U":542937463,"u":542937463,"b":[],"a":[["0.04110000","47491.00000000"]]}}
1681154051.4213278: {"stream":"xemusdt@bookTicker","data":{"u":542937464,"s":"XEMUSDT","b":"0.04100000","B":"484971.00000000","a":"0.04110000","A":"47491.00000000"}}
1681154051.4516618: {"stream":"xemusdt@depth@100ms","data":{"e":"depthUpdate","E":1681154051306,"s":"XEMUSDT","U":542937464,"u":542937464,"b":[["0.04100000","484971.00000000"]],"a":[]}}
1681154051.5320466: {"stream":"xemusdt@bookTicker","data":{"u":542937465,"s":"XEMUSDT","b":"0.04100000","B":"485240.00000000","a":"0.04110000","A":"47491.00000000"}}
1681154051.5514927: {"stream":"xemusdt@depth@100ms","data":{"e":"depthUpdate","E":1681154051406,"s":"XEMUSDT","U":542937465,"u":542937465,"b":[["0.04100000","485240.00000000"]],"a":[]}}
1681154052.452068: {"stream":"belbtc@depth@100ms","data":{"e":"depthUpdate","E":1681154052306,"s":"BELBTC","U":396548060,"u":396548060,"b":[["0.00002339","1493.70000000"]],"a":[]}}
1681154053.1531794: {"stream":"xemusdt@depth@100ms","data":{"e":"depthUpdate","E":1681154053007,"s":"XEMUSDT","U":542937466,"u":542937466,"b":[],"a":[["0.04130000","500996.00000000"]]}}
1681154053.252737: {"stream":"xemusdt@depth@100ms","data":{"e":"depthUpdate","E":1681154053107,"s":"XEMUSDT","U":542937467,"u":542937467,"b":[["0.04080000","175777.00000000"]],"a":[]}}
1681154054.3537674: {"stream":"belbtc@depth@100ms","data":{"e":"depthUpdate","E":1681154054207,"s":"BELBTC","U":396548061,"u":396548061,"b":[["0.00002342","37.60000000"]],"a":[]}}
1681154054.4523535: {"stream":"belbtc@depth@100ms","data":{"e":"depthUpdate","E":1681154054307,"s":"BELBTC","U":396548062,"u":396548062,"b":[],"a":[["0.00002544","744.70000000"]]}}
1681154054.6540208: {"stream":"belbtc@depth@100ms","data":{"e":"depthUpdate","E":1681154054507,"s":"BELBTC","U":396548063,"u":396548063,"b":[],"a":[["0.00002539","1883.70000000"]]}}
1681154054.8536046: {"stream":"ltcbrl@depth@100ms","data":{"e":"depthUpdate","E":1681154054707,"s":"LTCBRL","U":126821992,"u":126821992,"b":[],"a":[["478.50000000","0.00000000"]]}}
1681154054.8536482: {"stream":"ltcbrl@bookTicker","data":{"u":126821993,"s":"LTCBRL","b":"472.90000000","B":"2.66100000","a":"473.40000000","A":"12.52900000"}}
1681154054.9533556: {"stream":"ltcbrl@depth@100ms","data":{"e":"depthUpdate","E":1681154054807,"s":"LTCBRL","U":126821993,"u":126821993,"b":[],"a":[["473.40000000","12.52900000"]]}}
1681154054.9533892: {"stream":"belbtc@depth@100ms","data":{"e":"depthUpdate","E":1681154054807,"s":"BELBTC","U":396548064,"u":396548064,"b":[],"a":[["0.00002543","381.60000000"]]}}
1681154055.254944: {"stream":"belbtc@depth@100ms","data":{"e":"depthUpdate","E":1681154055108,"s":"BELBTC","U":396548065,"u":396548065,"b":[],"a":[["0.00002538","1130.10000000"]]}}
1681154055.9540825: {"stream":"belbtc@depth@100ms","data":{"e":"depthUpdate","E":1681154055808,"s":"BELBTC","U":396548066,"u":396548066,"b":[],"a":[["0.00002540","919.80000000"]]}}
1681154055.954116: {"stream":"ltcbrl@depth@100ms","data":{"e":"depthUpdate","E":1681154055808,"s":"LTCBRL","U":126821994,"u":126821995,"b":[],"a":[["475.80000000","0.00000000"],["476.00000000","42.60000000"]]}}
1681154055.9718528: {"stream":"xemusdt@bookTicker","data":{"u":542937468,"s":"XEMUSDT","b":"0.04100000","B":"532450.00000000","a":"0.04110000","A":"47491.00000000"}}
1681154056.0556812: {"stream":"xemusdt@depth@100ms","data":{"e":"depthUpdate","E":1681154055908,"s":"XEMUSDT","U":542937468,"u":542937468,"b":[["0.04100000","532450.00000000"]],"a":[]}}
1681154056.0986538: {"stream":"xemusdt@bookTicker","data":{"u":542937469,"s":"XEMUSDT","b":"0.04100000","B":"485240.00000000","a":"0.04110000","A":"47491.00000000"}}
1681154056.1549144: {"stream":"xemusdt@depth@100ms","data":{"e":"depthUpdate","E":1681154056008,"s":"XEMUSDT","U":542937469,"u":542937469,"b":[["0.04100000","485240.00000000"]],"a":[]}}
1681154056.5177474: {"stream":"belbtc@bookTicker","data":{"u":396548067,"s":"BELBTC","b":"0.00002360","B":"1378.90000000","a":"0.00002368","A":"871.10000000"}}
1681154056.5541644: {"stream":"belbtc@depth@100ms","data":{"e":"depthUpdate","E":1681154056408,"s":"BELBTC","U":396548067,"u":396548067,"b":[["0.00002360","1378.90000000"],["0.00002359","630.00000000"]],"a":[]}}
1681154056.5542111: {"stream":"xemusdt@depth@100ms","data":{"e":"depthUpdate","E":1681154056408,"s":"XEMUSDT","U":542937470,"u":542937470,"b":[],"a":[["0.04120000","263332.00000000"]]}}
1681154056.653998: {"stream":"belbtc@depth@100ms","data":{"e":"depthUpdate","E":1681154056508,"s":"BELBTC","U":396548068,"u":396548068,"b":[],"a":[["0.00002538","1471.80000000"]]}}
1681154056.6540408: {"stream":"xemusdt@depth@100ms","data":{"e":"depthUpdate","E":1681154056508,"s":"XEMUSDT","U":542937471,"u":542937471,"b":[["0.04080000","178227.00000000"]],"a":[]}}
1681154057.0534039: {"stream":"belbtc@depth@100ms","data":{"e":"depthUpdate","E":1681154056908,"s":"BELBTC","U":396548069,"u":396548069,"b":[],"a":[["0.00002541","628.40000000"]]}}
1681154057.2545435: {"stream":"belbtc@depth@100ms","data":{"e":"depthUpdate","E":1681154057109,"s":"BELBTC","U":396548070,"u":396548070,"b":[],"a":[["0.00002537","334.60000000"]]}}
1681154057.873829: {"stream":"xemusdt@bookTicker","data":{"u":542937472,"s":"XEMUSDT","b":"0.04100000","B":"485240.00000000","a":"0.04110000","A":"75898.00000000"}}
1681154057.9100363: {"stream":"xemusdt@bookTicker","data":{"u":542937473,"s":"XEMUSDT","b":"0.04100000","B":"471797.00000000","a":"0.04110000","A":"75898.00000000"}}
1681154057.9556994: {"stream":"xemusdt@depth@100ms","data":{"e":"depthUpdate","E":1681154057809,"s":"XEMUSDT","U":542937472,"u":542937473,"b":[["0.04100000","471797.00000000"]],"a":[["0.04110000","75898.00000000"]]}}
1681154057.9557366: {"stream":"ltcbrl@depth@100ms","data":{"e":"depthUpdate","E":1681154057809,"s":"LTCBRL","U":126821996,"u":126821996,"b":[["472.80000000","0.00000000"]],"a":[]}}
1681154057.9632232: {"stream":"ltcbrl@bookTicker","data":{"u":126821997,"s":"LTCBRL","b":"472.70000000","B":"4.53500000","a":"473.40000000","A":"12.52900000"}}
1681154057.9647474: {"stream":"ltcbrl@bookTicker","data":{"u":126821998,"s":"LTCBRL","b":"472.80000000","B":"2.66900000","a":"473.40000000","A":"12.52900000"}}
1681154057.9876704: {"stream":"ltcbrl@bookTicker","data":{"u":126822000,"s":"LTCBRL","b":"472.90000000","B":"2.15200000","a":"473.40000000","A":"12.52900000"}}
1681154058.0558348: {"stream":"ltcbrl@depth@100ms","data":{"e":"depthUpdate","E":1681154057909,"s":"LTCBRL","U":126821997,"u":126822002,"b":[["472.90000000","2.15200000"],["472.80000000","0.00000000"],["472.60000000","13.34900000"],["472.50000000","2.66900000"]],"a":[]}}
1681154058.1536052: {"stream":"ltcbrl@depth@100ms","data":{"e":"depthUpdate","E":1681154058009,"s":"LTCBRL","U":126822003,"u":126822003,"b":[["472.50000000","0.00000000"]],"a":[]}}
1681154058.5549748: {"stream":"belbtc@depth@100ms","data":{"e":"depthUpdate","E":1681154058409,"s":"BELBTC","U":396548071,"u":396548071,"b":[],"a":[["0.00002541","293.00000000"]]}}
1681154058.7536778: {"stream":"belbtc@depth@100ms","data":{"e":"depthUpdate","E":1681154058609,"s":"BELBTC","U":396548072,"u":396548072,"b":[],"a":[["0.00002537","670.00000000"]]}}
1681154058.8559127: {"stream":"belbtc@depth@100ms","data":{"e":"depthUpdate","E":1681154058709,"s":"BELBTC","U":396548073,"u":396548073,"b":[],"a":[["0.00002541","0.00000000"]]}}
1681154058.9455416: {"stream":"xemusdt@bookTicker","data":{"u":542937474,"s":"XEMUSDT","b":"0.04100000","B":"485428.00000000","a":"0.04110000","A":"75898.00000000"}}
1681154058.9556673: {"stream":"xemusdt@depth@100ms","data":{"e":"depthUpdate","E":1681154058810,"s":"XEMUSDT","U":542937474,"u":542937474,"b":[["0.04100000","485428.00000000"]],"a":[]}}
1681154058.965469: {"stream":"xemusdt@bookTicker","data":{"u":542937475,"s":"XEMUSDT","b":"0.04100000","B":"471797.00000000","a":"0.04110000","A":"75898.00000000"}}
1681154059.027589: {"stream":"ltcbrl@bookTicker","data":{"u":126822004,"s":"LTCBRL","b":"472.70000000","B":"4.53500000","a":"473.40000000","A":"12.52900000"}}
1681154059.0416737: {"stream":"ltcbrl@bookTicker","data":{"u":126822005,"s":"LTCBRL","b":"472.80000000","B":"2.66900000","a":"473.40000000","A":"12.52900000"}}
1681154059.0559282: {"stream":"xemusdt@depth@100ms","data":{"e":"depthUpdate","E":1681154058910,"s":"XEMUSDT","U":542937475,"u":542937475,"b":[["0.04100000","471797.00000000"]],"a":[]}}
1681154059.0559769: {"stream":"ltcbrl@depth@100ms","data":{"e":"depthUpdate","E":1681154058909,"s":"LTCBRL","U":126822004,"u":126822005,"b":[["472.90000000","0.00000000"],["472.80000000","2.66900000"]],"a":[]}}
1681154059.1558733: {"stream":"belbtc@depth@100ms","data":{"e":"depthUpdate","E":1681154059010,"s":"BELBTC","U":396548074,"u":396548074,"b":[],"a":[["0.00002537","963.00000000"]]}}
1681154059.356216: {"stream":"belbtc@depth@100ms","data":{"e":"depthUpdate","E":1681154059210,"s":"BELBTC","U":396548075,"u":396548075,"b":[],"a":[["0.00002540","0.00000000"]]}}
1681154059.5557268: {"stream":"belbtc@depth@100ms","data":{"e":"depthUpdate","E":1681154059410,"s":"BELBTC","U":396548076,"u":396548076,"b":[],"a":[["0.00002537","1882.80000000"]]}}
1681154059.990544: {"stream":"xemusdt@bookTicker","data":{"u":542937476,"s":"XEMUSDT","b":"0.04100000","B":"485428.00000000","a":"0.04110000","A":"75898.00000000"}}
1681154060.013576: {"stream":"xemusdt@bookTicker","data":{"u":542937477,"s":"XEMUSDT","b":"0.04100000","B":"471797.00000000","a":"0.04110000","A":"75898.00000000"}}
1681154060.0555744: {"stream":"xemusdt@depth@100ms","data":{"e":"depthUpdate","E":1681154059910,"s":"XEMUSDT","U":542937476,"u":542937477,"b":[["0.04100000","471797.00000000"]],"a":[]}}
1681154060.156296: {"stream":"xemusdt@depth@100ms","data":{"e":"depthUpdate","E":1681154060010,"s":"XEMUSDT","U":542937478,"u":542937478,"b":[],"a":[["0.04120000","288307.00000000"]]}}
1681154061.0363371: {"stream":"xemusdt@bookTicker","data":{"u":542937479,"s":"XEMUSDT","b":"0.04100000","B":"519007.00000000","a":"0.04110000","A":"75898.00000000"}}
1681154061.0561044: {"stream":"xemusdt@depth@100ms","data":{"e":"depthUpdate","E":1681154060911,"s":"XEMUSDT","U":542937479,"u":542937479,"b":[["0.04100000","519007.00000000"]],"a":[]}}
1681154061.1569786: {"stream":"belbtc@depth@100ms","data":{"e":"depthUpdate","E":1681154061010,"s":"BELBTC","U":396548077,"u":396548077,"b":[],"a":[["0.00002497","333.50000000"],["0.00002539","1550.20000000"]]}}
1681154061.3558822: {"stream":"xemusdt@bookTicker","data":{"u":542937480,"s":"XEMUSDT","b":"0.04100000","B":"471797.00000000","a":"0.04110000","A":"75898.00000000"}}
1681154061.3584018: {"stream":"xemusdt@depth@100ms","data":{"e":"depthUpdate","E":1681154061211,"s":"XEMUSDT","U":542937480,"u":542937480,"b":[["0.04100000","471797.00000000"]],"a":[]}}
1681154061.556829: {"stream":"belbtc@depth@100ms","data":{"e":"depthUpdate","E":1681154061411,"s":"BELBTC","U":396548078,"u":396548078,"b":[["0.00002321","2154.20000000"]],"a":[]}}
1681154063.157541: {"stream":"xemusdt@depth@100ms","data":{"e":"depthUpdate","E":1681154063012,"s":"XEMUSDT","U":542937481,"u":542937481,"b":[["0.04080000","228998.00000000"]],"a":[]}}
1681154064.8587022: {"stream":"xemusdt@depth@100ms","data":{"e":"depthUpdate","E":1681154064712,"s":"XEMUSDT","U":542937482,"u":542937482,"b":[["0.04090000","282355.00000000"]],"a":[]}}
1681154065.6574: {"stream":"belbtc@depth@100ms","data":{"e":"depthUpdate","E":1681154065513,"s":"BELBTC","U":396548079,"u":396548079,"b":[],"a":[["0.00002423","22.10000000"]]}}
1681154065.959341: {"stream":"belbtc@depth@100ms","data":{"e":"depthUpdate","E":1681154065813,"s":"BELBTC","U":396548080,"u":396548080,"b":[],"a":[["0.00002536","329.80000000"]]}}
1681154066.0610538: {"stream":"xemusdt@bookTicker","data":{"u":542937483,"s":"XEMUSDT","b":"0.04100000","B":"519007.00000000","a":"0.04110000","A":"75898.00000000"}}
1681154066.1590822: {"stream":"xemusdt@depth@100ms","data":{"e":"depthUpdate","E":1681154066013,"s":"XEMUSDT","U":542937483,"u":542937483,"b":[["0.04100000","519007.00000000"]],"a":[]}}
1681154066.1698055: {"stream":"xemusdt@bookTicker","data":{"u":542937484,"s":"XEMUSDT","b":"0.04100000","B":"471797.00000000","a":"0.04110000","A":"75898.00000000"}}
1681154066.2602763: {"stream":"xemusdt@depth@100ms","data":{"e":"depthUpdate","E":1681154066113,"s":"XEMUSDT","U":542937484,"u":542937484,"b":[["0.04100000","471797.00000000"]],"a":[]}}
1681154066.3589864: {"stream":"belbtc@depth@100ms","data":{"e":"depthUpdate","E":1681154066213,"s":"BELBTC","U":396548081,"u":396548081,"b":[],"a":[["0.00002544","0.00000000"]]}}
1681154066.5987852: {"stream":"ltcbrl@bookTicker","data":{"u":126822006,"s":"LTCBRL","b":"472.90000000","B":"2.15200000","a":"473.40000000","A":"12.52900000"}}
1681154066.658206: {"stream":"ltcbrl@depth@100ms","data":{"e":"depthUpdate","E":1681154066513,"s":"LTCBRL","U":126822006,"u":126822007,"b":[["472.90000000","2.15200000"],["472.80000000","0.00000000"]],"a":[]}}
1681154066.6588843: {"stream":"xemusdt@depth@100ms","data":{"e":"depthUpdate","E":1681154066513,"s":"XEMUSDT","U":542937485,"u":542937485,"b":[["0.04080000","226548.00000000"]],"a":[]}}
1681154066.760377: {"stream":"belbtc@depth@100ms","data":{"e":"depthUpdate","E":1681154066613,"s":"BELBTC","U":396548082,"u":396548082,"b":[],"a":[["0.00002536","1074.50000000"]]}}
1681154067.6602511: {"stream":"belbtc@depth@100ms","data":{"e":"depthUpdate","E":1681154067514,"s":"BELBTC","U":396548083,"u":396548083,"b":[],"a":[["0.00002428","0.00000000"]]}}
1681154068.1833565: {"stream":"belbtc@depth@100ms","data":{"e":"depthUpdate","E":1681154067614,"s":"BELBTC","U":396548084,"u":396548084,"b":[],"a":[["0.00002436","55.20000000"]]}}
1681154068.1833894: {"stream":"xemusdt@bookTicker","data":{"u":542937486,"s":"XEMUSDT","b":"0.04100000","B":"485428.00000000","a":"0.04110000","A":"75898.00000000"}}
1681154068.1834028: {"stream":"xemusdt@bookTicker","data":{"u":542937487,"s":"XEMUSDT","b":"0.04100000","B":"471797.00000000","a":"0.04110000","A":"75898.00000000"}}
1681154068.1834111: {"stream":"xemusdt@depth@100ms","data":{"e":"depthUpdate","E":1681154067814,"s":"XEMUSDT","U":542937486,"u":542937487,"b":[["0.04100000","471797.00000000"]],"a":[]}}
1681154068.6611009: {"stream":"xemusdt@depth@100ms","data":{"e":"depthUpdate","E":1681154068515,"s":"XEMUSDT","U":542937488,"u":542937488,"b":[["0.04050000","112952.00000000"]],"a":[]}}
1681154068.672338: {"stream":"ltcbrl@bookTicker","data":{"u":126822008,"s":"LTCBRL","b":"472.70000000","B":"4.53500000","a":"473.40000000","A":"12.52900000"}}
1681154068.6873026: {"stream":"ltcbrl@bookTicker","data":{"u":126822009,"s":"LTCBRL","b":"472.80000000","B":"2.68500000","a":"473.40000000","A":"12.52900000"}}
1681154068.76407: {"stream":"ltcbrl@depth@100ms","data":{"e":"depthUpdate","E":1681154068615,"s":"LTCBRL","U":126822008,"u":126822009,"b":[["472.90000000","0.00000000"],["472.80000000","2.68500000"]],"a":[]}}
1681154068.9604378: {"stream":"xemusdt@depth@100ms","data":{"e":"depthUpdate","E":1681154068815,"s":"XEMUSDT","U":542937489,"u":542937489,"b":[["0.04050000","113827.00000000"]],"a":[]}}
1681154068.9851248: {"stream":"xemusdt@bookTicker","data":{"u":542937490,"s":"XEMUSDT","b":"0.04100000","B":"485428.00000000","a":"0.04110000","A":"75898.00000000"}}
1681154069.0057304: {"stream":"xemusdt@bookTicker","data":{"u":542937491,"s":"XEMUSDT","b":"0.04100000","B":"471797.00000000","a":"0.04110000","A":"75898.00000000"}}
1681154069.0605903: {"stream":"xemusdt@depth@100ms","data":{"e":"depthUpdate","E":1681154068915,"s":"XEMUSDT","U":542937490,"u":542937491,"b":[["0.04100000","471797.00000000"]],"a":[]}}
1681154069.2608037: {"stream":"xemusdt@depth@100ms","data":{"e":"depthUpdate","E":1681154069115,"s":"XEMUSDT","U":542937492,"u":542937492,"b":[],"a":[["0.04120000","339080.00000000"]]}}

