1618677485.286623: {"stream":"linkusd_210924@depth@100ms","data":{"e":"depthUpdate","E":1618677484776,"T":1618677484753,"s":"LINKUSD_210924","ps":"LINKUSD","U":86143399403,"u":86143400482,"pu":86143399159,"b":[["45.145","0"],["45.186","44"],["45.241","296"]],"a":[["45.392","0"],["45.435","2449"],["45.448","0"]]}}
1618677485.286689: {"stream":"xrpusd_210625@depth@100ms","data":{"e":"depthUpdate","E":1618677484785,"T":1618677484770,"s":"XRPUSD_210625","ps":"XRPUSD","U":86143399466,"u":86143400631,"pu":86143399350,"b":[["1.6837","4386"],["1.6894","801"],["1.6902","45"],["1.6907","0"]],"a":[["1.6928","0"],["1.6931","62"],["1.6932","33"],["1.6935","0"],["1.6936","0"],["1.6951","478"]]}}
1618677485.286753: {"stream":"btcusd_perp@depth@100ms","data":{"e":"depthUpdate","E":1618677484793,"T":1618677484783,"s":"BTCUSD_PERP","ps":"BTCUSD","U":86143399547,"u":86143400811,"pu":86143399525,"b":[["60480.8","96"],["60579.2","0"],["60584.4","0"],["60589.5","10882"],["60589.7","0"]],"a":[["60589.6","4411"],["60591.4","0"],["60596.7","160"],["60612.8","122"],["60613.0","0"],["60745.5","45"]]}}
1618677485.286798: {"stream":"ethusd_210924@depth@100ms","data":{"e":"depthUpdate","E":1618677484795,"T":1618677484782,"s":"ETHUSD_210924","ps":"ETHUSD","U":86143399563,"u":86143400792,"pu":86143399513,"b":[["2667.05","0"],["2667.38","400"],["2684.87","0"],["2687.33","0"],["2687.37","0"],["2687.66","302"],["2689.49","0"],["2689.53","1000"],["2689.58","672"]],"a":[["2690.26","0"],["2691.10","0"]]}}
1618677485.286863: {"stream":"ethusd_210625@depth@100ms","data":{"e":"depthUpdate","E":1618677484797,"T":1618677484790,"s":"ETHUSD_210625","ps":"ETHUSD","U":86143399577,"u":86143400859,"pu":86143399555,"b":[["2503.74","0"],["2503.94","2999"],["2506.19","201"],["2507.36","0"],["2509.32","1840"],["2510.00","0"],["2510.06","1203"],["2510.09","97"],["2510.10","0"],["2510.11","0"],["2510.12","0"],["2510.20","0"],["2510.29","0"],["2510.42","2000"],["2510.43","420"],["2510.50","100"],["2510.56","1"],["2510.57","1378"],["2510.58","367"],["2510.59","744"],["2510.60","100"],["2510.61","0"],["2510.63","0"],["2510.64","0"],["2510.70","100"],["2510.87","2666"],["2510.88","0"],["2510.89","0"],["2510.94","0"]],"a":[["2510.57","0"],["2510.87","0"],["2510.88","349"],["2510.89","0"],["2510.95","53"],["2510.97","0"],["2510.99","0"],["2511.36","0"],["2511.38","0"],["2511.41","1250"],["2511.49","0"],["2511.50","0"],["2511.57","0"],["2511.59","675"],["2511.60","0"],["2511.61","0"],["2511.66","0"],["2511.67","0"],["2511.77","2342"],["2511.82","0"],["2511.88","686"],["2511.89","0"],["2511.90","3145"],["2511.94","1351"],["2511.95","0"],["2511.97","2030"],["2512.01","0"],["2512.08","0"],["2512.13","121"],["2512.19","0"],["2512.30","1461"],["2512.33","2998"],["2515.63","1004"],["2636.01","0"],["2636.41","900"]]}}
1618677485.287124: {"stream":"dotusd_210625@depth@100ms","data":{"e":"depthUpdate","E":1618677484813,"T":1618677484801,"s":"DOTUSD_210625","ps":"DOTUSD","U":86143399800,"u":86143400945,"pu":86143399523,"b":[],"a":[["46.774","540"],["46.776","0"],["46.777","0"],["46.779","0"],["46.780","0"],["46.785","0"],["47.000","1"],["47.026","1049"]]}}
1618677485.287182: {"stream":"bchusd_210625@depth@100ms","data":{"e":"depthUpdate","E":1618677484816,"T":1618677484803,"s":"BCHUSD_210625","ps":"BCHUSD","U":86143399820,"u":86143400975,"pu":86143399765,"b":[["1121.26","0"],["1125.49","0"],["1125.87","50"],["1126.45","0"],["1126.64","1630"],["1127.86","0"],["1127.87","0"],["1127.90","0"],["1127.94","0"],["1127.95","0"],["1127.96","35"],["1127.97","64"],["1127.98","0"],["1127.99","43"]],"a":[["1129.67","20"],["1130.35","250"],["1133.04","286"],["1134.71","1"],["1135.21","3622"],["1135.59","400"],["1139.31","112"]]}}
1618677485.287327: {"stream":"egldusd_perp@depth@100ms","data":{"e":"depthUpdate","E":1618677484843,"T":1618677484786,"s":"EGLDUSD_PERP","ps":"EGLDUSD","U":86143400267,"u":86143400824,"pu":86143399235,"b":[["216.054","0"]],"a":[["216.256","0"],["216.399","0"],["216.468","26"]]}}
1618677485.287489: {"stream":"btcusd_210924@depth@100ms","data":{"e":"depthUpdate","E":1618677484867,"T":1618677484813,"s":"BTCUSD_210924","ps":"BTCUSD","U":86143400562,"u":86143401063,"pu":86143398989,"b":[["68580.7","1616"],["68584.5","0"],["68584.6","0"]],"a":[["69243.5","0"]]}}
1618677485.2875059: {"stream":"linkusd_210625@depth@100ms","data":{"e":"depthUpdate","E":1618677484881,"T":1618677484864,"s":"LINKUSD_210625","ps":"LINKUSD","U":86143400724,"u":86143401676,"pu":86143400469,"b":[["43.654","0"],["43.684","2561"],["43.763","21"],["43.765","43"],["43.767","0"]],"a":[["43.833","20"],["43.840","652"]]}}
1618677485.287552: {"stream":"linkusd_210924@depth@100ms","data":{"e":"depthUpdate","E":1618677484882,"T":1618677484861,"s":"LINKUSD_210924","ps":"LINKUSD","U":86143400723,"u":86143401652,"pu":86143400482,"b":[["45.241","470"]],"a":[]}}
1618677485.2875772: {"stream":"xrpusd_210625@depth@100ms","data":{"e":"depthUpdate","E":1618677484892,"T":1618677484885,"s":"XRPUSD_210625","ps":"XRPUSD","U":86143400843,"u":86143401944,"pu":86143400631,"b":[["1.6801","10800"],["1.6879","706"],["1.6900","308"],["1.6902","0"],["1.6903","0"],["1.6905","100"],["1.6907","0"]],"a":[["1.6922","0"],["1.6928","45"],["1.6929","60"],["1.6945","251"],["1.6946","1370"],["1.6975","2588"],["1.7028","10800"]]}}
1618677485.287627: {"stream":"btcusd_perp@depth@100ms","data":{"e":"depthUpdate","E":1618677484896,"T":1618677484889,"s":"BTCUSD_PERP","ps":"BTCUSD","U":86143400869,"u":86143401972,"pu":86143400811,"b":[["59680.7","100"],["60460.1","0"],["60472.4","30"],["60573.3","243"],["60573.4","122"],["60573.5","0"],["60573.8","0"],["60573.9","0"],["60575.1","45"],["60581.0","3572"],["60583.0","30"],["60584.9","40"],["60585.4","0"],["60586.1","343"],["60586.6","0"],["60588.1","243"],["60588.6","110"],["60589.5","10682"],["60589.7","0"]],"a":[["60589.6","4617"],["60596.0","96"],["60601.0","0"],["60610.3","0"],["60612.8","0"],["60623.1","0"],["60625.7","0"],["60635.9","99"],["60637.9","0"],["60638.4","0"],["60640.4","0"]]}}
1618677485.2877262: {"stream":"ethusd_210924@depth@100ms","data":{"e":"depthUpdate","E":1618677484896,"T":1618677484871,"s":"ETHUSD_210924","ps":"ETHUSD","U":86143400872,"u":86143401752,"pu":86143400792,"b":[["2668.08","0"],["2670.82","210"],["2689.53","0"],["2689.61","1000"],["2689.63","276"],["2689.79","1076"]],"a":[["2689.80","98"],["2691.65","2587"],["2698.99","0"],["2699.48","16907"]]}}
1618677485.287772: {"stream":"ethusd_210625@depth@100ms","data":{"e":"depthUpdate","E":1618677484897,"T":1618677484891,"s":"ETHUSD_210625","ps":"ETHUSD","U":86143400888,"u":86143401993,"pu":86143400859,"b":[["2504.05","0"],["2505.36","1002"],["2505.38","0"],["2507.48","0"],["2508.98","1073"],["2509.03","0"],["2510.23","0"],["2510.26","0"],["2510.27","0"],["2510.57","0"],["2510.59","0"],["2510.61","477"],["2510.89","0"]],"a":[["2510.88","357"],["2510.96","0"],["2511.09","61"],["2511.13","182"],["2511.14","0"],["2511.15","62"],["2511.18","0"],["2511.34","2803"],["2511.36","1700"],["2511.37","2794"],["2511.38","2306"],["2511.42","2027"],["2511.45","2151"],["2511.71","1072"],["2511.74","1073"],["2511.75","0"],["2511.76","0"],["2511.77","0"],["2511.78","1070"],["2511.87","0"],["2511.88","0"],["2511.90","839"],["2511.94","0"],["2511.96","0"],["2511.97","0"],["2511.99","0"],["2512.01","1874"],["2512.04","0"],["2512.13","0"],["2512.30","391"],["2512.33","1926"],["2512.36","0"],["2512.89","2787"],["2512.92","1652"],["2513.08","1530"],["2513.15","0"],["2513.23","881"],["2513.61","3704"],["2513.69","0"],["2514.41","4594"],["2514.50","6073"],["2514.56","2820"],["2514.63","0"],["2515.82","0"],["2537.85","0"]]}}
1618677485.28806: {"stream":"dotusd_210625@depth@100ms","data":{"e":"depthUpdate","E":1618677484914,"T":1618677484909,"s":"DOTUSD_210625","ps":"DOTUSD","U":86143401058,"u":86143402159,"pu":86143400945,"b":[["46.714","63"],["46.722","0"],["46.744","244"],["46.764","0"]],"a":[["46.771","796"],["46.773","200"],["46.785","0"],["46.828","100"],["46.833","0"],["46.849","635"],["46.874","0"],["47.109","100"],["47.115","0"],["47.130","0"]]}}
1618677485.2881448: {"stream":"bchusd_210625@depth@100ms","data":{"e":"depthUpdate","E":1618677484920,"T":1618677484913,"s":"BCHUSD_210625","ps":"BCHUSD","U":86143401084,"u":86143402206,"pu":86143400975,"b":[["1125.87","0"],["1125.97","50"],["1126.64","0"],["1126.66","1511"],["1127.92","0"],["1127.93","0"],["1127.96","0"],["1127.97","0"],["1127.98","0"],["1127.99","0"],["1128.00","0"],["1128.01","64"],["1128.02","0"],["1128.03","34"],["1128.04","35"],["1128.05","64"],["1128.06","24"]],"a":[["1130.86","250"],["1131.11","548"]]}}
1618677485.28839: {"stream":"egldusd_perp@depth@100ms","data":{"e":"depthUpdate","E":1618677484952,"T":1618677484860,"s":"EGLDUSD_PERP","ps":"EGLDUSD","U":86143401503,"u":86143401642,"pu":86143400824,"b":[["216.054","54"]],"a":[["216.180","20"],["216.310","502"],["216.350","0"]]}}
1618677485.2885: {"stream":"btcusd_perp@depth@100ms","data":{"e":"depthUpdate","E":1618677484997,"T":1618677484991,"s":"BTCUSD_PERP","ps":"BTCUSD","U":86143402021,"u":86143402800,"pu":86143401972,"b":[["60573.3","243"],["60573.4","122"],["60577.8","0"],["60578.8","25"],["60580.5","30"],["60581.0","3547"],["60583.0","0"],["60583.3","100"],["60586.6","394"],["60587.2","0"],["60589.5","10762"],["60589.7","0"]],"a":[["60589.6","7648"],["60595.8","151"],["60596.7","10"],["60600.8","25"],["60602.9","0"],["60607.6","172"],["60608.8","0"],["60609.8","0"],["60610.0","120"],["60621.6","0"],["60622.7","0"],["60633.2","243"],["60634.4","0"],["60635.2","396"],["60635.5","0"],["60636.4","2"],["60637.5","8"],["60674.7","110"]]}}
1618677485.288589: {"stream":"ethusd_210625@depth@100ms","data":{"e":"depthUpdate","E":1618677484998,"T":1618677484989,"s":"ETHUSD_210625","ps":"ETHUSD","U":86143402030,"u":86143402781,"pu":86143401993,"b":[["2494.62","0"],["2501.89","0"],["2503.37","0"],["2503.51","6219"],["2503.75","200"],["2503.94","0"],["2504.49","2999"],["2504.82","0"],["2504.94","0"],["2505.20","0"],["2505.28","0"],["2505.69","0"],["2505.70","0"],["2505.85","7107"],["2507.74","0"],["2507.93","3375"],["2507.96","105"],["2508.89","0"],["2508.91","1073"],["2508.98","0"],["2509.37","100"],["2509.59","60"],["2510.10","0"],["2510.44","110"],["2510.61","2564"],["2510.62","637"],["2510.71","299"],["2510.86","800"],["2510.87","2367"],["2510.89","0"]],"a":[["2510.86","0"],["2511.07","112"],["2511.08","425"],["2511.09","0"],["2511.13","0"],["2511.33","121"],["2511.34","0"],["2511.36","367"],["2511.37","0"],["2511.38","0"],["2511.40","2349"],["2511.41","4054"],["2511.44","2794"],["2511.45","2306"],["2511.53","2030"],["2511.58","0"],["2511.63","0"],["2511.71","0"],["2511.74","0"],["2511.78","1073"],["2511.81","1074"],["2511.85","1071"],["2511.87","0"],["2511.88","0"],["2511.89","0"],["2511.90","839"],["2511.97","0"],["2512.00","0"],["2512.01","60"],["2512.17","0"],["2512.22","0"],["2512.26","0"],["2512.27","391"],["2512.28","391"],["2512.30","391"],["2512.49","2240"],["2512.54","391"],["2512.82","0"],["2512.83","0"],["2513.61","5204"],["2514.07","2386"],["2514.09","0"],["2514.22","0"],["2514.41","2603"],["2514.52","2603"],["2516.50","0"],["2518.09","3000"]]}}
1618677485.2888489: {"stream":"xrpusd_210625@depth@100ms","data":{"e":"depthUpdate","E":1618677485005,"T":1618677484961,"s":"XRPUSD_210625","ps":"XRPUSD","U":86143402085,"u":86143402616,"pu":86143401944,"b":[["1.6889","12"],["1.6891","110"],["1.6903","0"],["1.6907","45"]],"a":[["1.6921","152"],["1.6923","0"],["1.6947","630"],["1.6967","2121"],["1.6972","2607"],["1.6975","223"],["1.6993","20187"]]}}
1618677485.288915: {"stream":"ethusd_210924@depth@100ms","data":{"e":"depthUpdate","E":1618677485009,"T":1618677484988,"s":"ETHUSD_210924","ps":"ETHUSD","U":86143402132,"u":86143402773,"pu":86143401752,"b":[["2679.69","2400"],["2686.68","3639"],["2687.39","48"],["2689.20","0"],["2689.50","1000"],["2689.61","0"],["2689.63","67"],["2689.79","1076"]],"a":[["2689.80","48"],["2706.43","0"],["2710.49","210"]]}}
1618677485.288961: {"stream":"linkusd_210924@depth@100ms","data":{"e":"depthUpdate","E":1618677485009,"T":1618677484986,"s":"LINKUSD_210924","ps":"LINKUSD","U":86143402135,"u":86143402754,"pu":86143401652,"b":[["45.104","250"],["45.211","577"],["45.212","121"],["45.234","0"],["45.238","1156"],["45.241","493"]],"a":[["45.753","0"]]}}
1618677485.288996: {"stream":"linkusd_210625@depth@100ms","data":{"e":"depthUpdate","E":1618677485013,"T":1618677484949,"s":"LINKUSD_210625","ps":"LINKUSD","U":86143402157,"u":86143402518,"pu":86143401676,"b":[["43.725","250"],["43.763","23"],["43.765","42"],["43.766","0"]],"a":[]}}
1618677485.2890298: {"stream":"dotusd_210625@depth@100ms","data":{"e":"depthUpdate","E":1618677485016,"T":1618677485007,"s":"DOTUSD_210625","ps":"DOTUSD","U":86143402193,"u":86143402906,"pu":86143402159,"b":[["46.299","0"],["46.714","0"],["46.722","63"],["46.744","357"]],"a":[["46.768","540"],["46.770","0"],["46.772","0"],["46.773","0"],["46.774","0"],["46.785","0"],["46.786","0"],["46.893","1000"],["46.923","0"],["46.964","1200"],["47.027","0"],["47.175","1000"],["47.204","11"]]}}
1618677485.289129: {"stream":"bchusd_210625@depth@100ms","data":{"e":"depthUpdate","E":1618677485024,"T":1618677485015,"s":"BCHUSD_210625","ps":"BCHUSD","U":86143402259,"u":86143402977,"pu":86143402206,"b":[["1115.24","1000"],["1115.86","0"],["1117.31","200"],["1123.30","1173"],["1123.92","0"],["1124.60","0"],["1125.49","141"],["1125.66","0"],["1125.97","0"],["1128.01","0"],["1128.02","0"],["1128.03","0"],["1128.04","0"],["1128.06","35"],["1128.07","0"],["1128.08","0"],["1128.09","0"],["1128.10","440"],["1128.11","35"],["1128.12","116"]],"a":[["1132.06","254"],["1133.81","0"],["1134.16","0"],["1139.01","2970"]]}}
1618677485.2893262: {"stream":"btcusd_210924@depth@100ms","data":{"e":"depthUpdate","E":1618677485063,"T":1618677484985,"s":"BTCUSD_210924","ps":"BTCUSD","U":86143402586,"u":86143402747,"pu":86143401063,"b":[["68589.9","1154"],["68590.0","287"],["68592.1","0"],["68592.2","0"]],"a":[]}}
1618677485.289439: {"stream":"btcusd_perp@depth@100ms","data":{"e":"depthUpdate","E":1618677485099,"T":1618677485089,"s":"BTCUSD_PERP","ps":"BTCUSD","U":86143402816,"u":86143403777,"pu":86143402800,"b":[["60492.7","0"],["60498.0","0"],["60565.0","0"],["60580.5","0"],["60583.5","1"],["60585.8","190"],["60589.7","0"],["60590.0","0"]],"a":[["60589.6","8097"],["60597.4","0"],["60607.6","50"],["60608.0","122"],["60608.1","0"],["60620.4","0"],["60620.9","243"],["60633.2","0"],["60633.7","243"],["60635.2","153"],["60635.7","243"]]}}
1618677485.2895072: {"stream":"ethusd_210625@depth@100ms","data":{"e":"depthUpdate","E":1618677485101,"T":1618677485096,"s":"ETHUSD_210625","ps":"ETHUSD","U":86143402840,"u":86143403855,"pu":86143402781,"b":[["2495.97","1400"],["2505.17","3037"],["2505.30","3037"],["2505.43","2820"],["2505.44","2820"],["2505.75","2603"],["2505.76","2820"],["2508.85","12"],["2508.95","12"],["2509.04","2656"],["2510.07","642"],["2510.44","0"],["2510.71","0"],["2510.87","2666"],["2510.89","0"]],"a":[["2510.86","0"],["2511.07","0"],["2511.08","0"],["2511.14","48"],["2511.15","73"],["2511.32","102"],["2511.33","0"],["2511.40","1335"],["2511.41","4054"],["2511.42","0"],["2511.44","2794"],["2511.45","2306"],["2511.49","2027"],["2511.52","0"],["2511.53","2030"],["2511.58","121"],["2511.77","580"],["2511.78","1073"],["2511.81","1074"],["2511.85","1071"],["2511.96","0"],["2511.99","0"],["2512.00","4502"],["2512.01","60"],["2512.04","0"],["2512.08","0"],["2512.33","1926"],["2512.36","0"],["2512.41","0"],["2512.89","3871"],["2512.95","1518"],["2513.00","48"],["2513.30","1518"],["2513.34","1518"],["2513.50","1735"],["2513.94","0"],["2514.00","1982"],["2514.65","0"],["2514.87","3254"],["2514.93","105"],["2515.90","1992"],["2516.94","189"]]}}
1618677485.2897139: {"stream":"ethusd_210924@depth@100ms","data":{"e":"depthUpdate","E":1618677485111,"T":1618677485104,"s":"ETHUSD_210924","ps":"ETHUSD","U":86143402896,"u":86143403936,"pu":86143402773,"b":[["2680.11","0"],["2686.13","0"],["2687.30","0"],["2687.31","7614"],["2688.98","0"],["2689.50","0"],["2689.52","1000"]],"a":[["2689.80","48"],["2690.24","150"]]}}
1618677485.28979: {"stream":"linkusd_210924@depth@100ms","data":{"e":"depthUpdate","E":1618677485113,"T":1618677485084,"s":"LINKUSD_210924","ps":"LINKUSD","U":86143402923,"u":86143403725,"pu":86143402754,"b":[["44.505","0"],["44.532","40"]],"a":[["45.551","0"],["45.774","100"]]}}
1618677485.28982: {"stream":"dotusd_210625@depth@100ms","data":{"e":"depthUpdate","E":1618677485120,"T":1618677485114,"s":"DOTUSD_210625","ps":"DOTUSD","U":86143402963,"u":86143404026,"pu":86143402906,"b":[["46.713","12"],["46.714","63"],["46.722","0"],["46.744","51"],["46.745","0"],["46.746","540"],["46.747","0"],["46.749","540"],["46.750","227"],["46.753","0"],["46.754","0"],["46.763","0"]],"a":[["46.763","256"],["46.764","200"],["46.765","540"],["46.767","0"],["46.768","0"],["46.771","256"],["46.803","276"],["46.807","0"],["46.822","50"],["46.828","0"],["46.953","40"],["47.103","235"],["47.109","0"]]}}
1618677485.2899048: {"stream":"bchusd_210625@depth@100ms","data":{"e":"depthUpdate","E":1618677485125,"T":1618677485109,"s":"BCHUSD_210625","ps":"BCHUSD","U":86143403051,"u":86143403987,"pu":86143402977,"b":[["1115.24","0"],["1121.08","190"],["1122.78","130"],["1123.30","173"],["1128.05","0"],["1128.06","0"],["1128.07","35"],["1128.11","0"],["1128.13","0"],["1128.14","0"],["1128.15","0"],["1128.16","64"],["1128.17","116"]],"a":[["1134.48","100"],["1134.84","40"]]}}
1618677485.289985: {"stream":"linkusd_210625@depth@100ms","data":{"e":"depthUpdate","E":1618677485146,"T":1618677485135,"s":"LINKUSD_210625","ps":"LINKUSD","U":86143403257,"u":86143404243,"pu":86143402518,"b":[["43.739","442"],["43.765","0"],["43.766","0"]],"a":[]}}
1618677485.290414: {"stream":"egldusd_perp@depth@100ms","data":{"e":"depthUpdate","E":1618677485179,"T":1618677485154,"s":"EGLDUSD_PERP","ps":"EGLDUSD","U":86143403623,"u":86143404370,"pu":86143401642,"b":[],"a":[["216.135","16"],["216.180","4"],["216.307","125"],["216.308","531"],["216.309","0"],["216.310","0"],["216.395","121"],["216.396","571"]]}}
1618677485.2905548: {"stream":"btcusd_perp@depth@100ms","data":{"e":"depthUpdate","E":1618677485205,"T":1618677485200,"s":"BTCUSD_PERP","ps":"BTCUSD","U":86143403909,"u":86143404661,"pu":86143403777,"b":[["60573.2","122"],["60573.3","243"],["60573.4","0"],["60574.8","0"],["60575.4","0"],["60589.7","0"]],"a":[["60589.6","8098"],["60634.5","45"]]}}
1618677485.290594: {"stream":"ethusd_210625@depth@100ms","data":{"e":"depthUpdate","E":1618677485210,"T":1618677485204,"s":"ETHUSD_210625","ps":"ETHUSD","U":86143403946,"u":86143404680,"pu":86143403855,"b":[["2504.49","0"],["2504.56","2999"],["2504.65","0"],["2506.47","2603"],["2510.89","0"]],"a":[["2511.15","62"],["2511.39","121"],["2511.40","689"],["2511.41","1250"],["2511.44","0"],["2511.45","0"],["2511.49","0"],["2511.53","0"],["2511.58","0"],["2511.77","0"],["2511.78","0"],["2511.79","716"],["2511.81","2794"],["2511.83","2306"],["2511.85","1029"],["2511.86","2027"],["2511.90","2869"],["2511.96","0"],["2511.98","4394"],["2511.99","0"],["2512.00","0"],["2512.01","60"],["2512.08","0"],["2512.18","1074"],["2512.33","2999"],["2512.36","0"],["2512.41","1071"],["2513.06","3471"],["2515.01","3049"]]}}
1618677485.290713: {"stream":"ethusd_210924@depth@100ms","data":{"e":"depthUpdate","E":1618677485211,"T":1618677485156,"s":"ETHUSD_210924","ps":"ETHUSD","U":86143403975,"u":86143404380,"pu":86143403936,"b":[["2687.32","1891"],["2689.52","1000"],["2689.63","0"],["2689.64","500"],["2689.65","171"]],"a":[["2689.80","168"]]}}
1618677485.2907798: {"stream":"xrpusd_210625@depth@100ms","data":{"e":"depthUpdate","E":1618677485218,"T":1618677485213,"s":"XRPUSD_210625","ps":"XRPUSD","U":86143404029,"u":86143404730,"pu":86143402616,"b":[["1.6895","169"],["1.6905","100"],["1.6907","0"]],"a":[["1.6932","0"],["1.6933","0"],["1.6944","129"]]}}
1618677485.290866: {"stream":"bchusd_210625@depth@100ms","data":{"e":"depthUpdate","E":1618677485233,"T":1618677485226,"s":"BCHUSD_210625","ps":"BCHUSD","U":86143404173,"u":86143404812,"pu":86143403987,"b":[["1115.86","1000"],["1117.31","0"],["1117.82","50"],["1123.92","1000"],["1125.49","0"],["1126.00","50"],["1126.66","12"],["1126.69","1499"],["1128.07","0"],["1128.10","376"],["1128.17","13"],["1128.18","0"],["1128.19","166"],["1128.21","64"]],"a":[]}}
1618677485.290923: {"stream":"dotusd_210625@depth@100ms","data":{"e":"depthUpdate","E":1618677485234,"T":1618677485222,"s":"DOTUSD_210625","ps":"DOTUSD","U":86143404176,"u":86143404795,"pu":86143404026,"b":[["46.089","0"],["46.486","0"],["46.542","1639"],["46.694","14"],["46.698","63"],["46.714","0"],["46.742","0"],["46.744","1"],["46.746","0"],["46.749","0"],["46.750","0"],["46.752","0"],["46.753","0"],["46.755","540"]],"a":[["46.760","540"],["46.762","200"],["46.764","0"],["46.822","0"],["46.834","0"],["46.896","502"],["46.967","0"],["47.103","185"]]}}
1618677485.303709: {"stream":"linkusd_210924@depth@100ms","data":{"e":"depthUpdate","E":1618677485250,"T":1618677485234,"s":"LINKUSD_210924","ps":"LINKUSD","U":86143404285,"u":86143404869,"pu":86143403725,"b":[["44.947","180"],["44.956","232"]],"a":[["45.407","208"],["45.408","988"],["45.417","0"],["45.418","0"],["45.554","182"]]}}
1618677485.3499038: {"stream":"egldusd_perp@depth@100ms","data":{"e":"depthUpdate","E":1618677485298,"T":1618677485254,"s":"EGLDUSD_PERP","ps":"EGLDUSD","U":86143404628,"u":86143405113,"pu":86143404370,"b":[],"a":[["216.135","16"],["216.394","55"],["216.468","0"]]}}
1618677485.3573859: {"stream":"btcusd_perp@depth@100ms","data":{"e":"depthUpdate","E":1618677485305,"T":1618677485295,"s":"BTCUSD_PERP","ps":"BTCUSD","U":86143404665,"u":86143405516,"pu":86143404661,"b":[["60443.9","0"],["60481.1","0"],["60506.9","6184"],["60532.2","0"],["60540.2","1405"],["60573.1","1"],["60573.2","122"],["60581.3","0"],["60587.2","100"]],"a":[["60608.0","0"],["60608.1","122"],["60632.4","730"],["60639.9","1405"],["60662.2","0"],["60679.2","6184"]]}}
1618677485.36533: {"stream":"btcusd_210924@depth@100ms","data":{"e":"depthUpdate","E":1618677485309,"T":1618677485230,"s":"BTCUSD_210924","ps":"BTCUSD","U":86143404688,"u":86143404838,"pu":86143402747,"b":[["68580.8","1154"],["68580.9","589"],["68589.9","0"],["68590.0","0"]],"a":[]}}
1618677485.365526: {"stream":"ethusd_210625@depth@100ms","data":{"e":"depthUpdate","E":1618677485310,"T":1618677485299,"s":"ETHUSD_210625","ps":"ETHUSD","U":86143404691,"u":86143405563,"pu":86143404680,"b":[["2385.39","0"],["2504.56","0"],["2505.65","3471"],["2505.92","0"],["2506.20","112"],["2506.38","0"],["2506.76","0"],["2508.41","849"],["2510.10","299"],["2510.42","2000"],["2510.44","0"],["2510.61","0"],["2510.62","0"],["2510.71","0"],["2510.87","2242"],["2510.89","0"]],"a":[["2510.86","0"],["2510.88","999"],["2511.13","0"],["2511.31","121"],["2511.39","0"],["2511.58","2804"],["2511.59","1506"],["2511.61","2794"],["2511.63","2306"],["2511.66","2027"],["2511.67","0"],["2511.70","2126"],["2511.78","0"],["2511.79","0"],["2511.81","0"],["2511.83","0"],["2511.85","0"],["2511.86","0"],["2511.90","839"],["2511.95","1073"],["2511.98","5468"],["2512.03","17817"],["2512.18","0"],["2512.33","1926"],["2512.41","0"],["2513.22","1857"],["2515.38","0"],["2516.85","996"],["2517.16","436"],["2518.87","3000"]]}}
1618677485.382953: {"stream":"linkusd_210625@depth@100ms","data":{"e":"depthUpdate","E":1618677485323,"T":1618677485310,"s":"LINKUSD_210625","ps":"LINKUSD","U":86143404771,"u":86143405637,"pu":86143404243,"b":[["43.287","128"],["43.351","813"],["43.406","1342"],["43.763","0"],["43.765","0"],["43.766","0"]],"a":[["43.898","0"]]}}
1618677485.3937678: {"stream":"xrpusd_210625@depth@100ms","data":{"e":"depthUpdate","E":1618677485331,"T":1618677485255,"s":"XRPUSD_210625","ps":"XRPUSD","U":86143404818,"u":86143405114,"pu":86143404730,"b":[["1.6907","45"]],"a":[["1.6925","150"],["1.6931","12"]]}}
1618677485.393884: {"stream":"dotusd_210625@depth@100ms","data":{"e":"depthUpdate","E":1618677485337,"T":1618677485328,"s":"DOTUSD_210625","ps":"DOTUSD","U":86143404850,"u":86143405830,"pu":86143404795,"b":[["46.150","452"],["46.694","244"],["46.744","310"],["46.753","50"],["46.755","540"]],"a":[["46.762","0"],["46.771","0"],["46.802","200"],["46.818","50"],["46.939","140"],["46.989","140"],["47.100","100"]]}}
1618677485.394003: {"stream":"ethusd_210924@depth@100ms","data":{"e":"depthUpdate","E":1618677485337,"T":1618677485330,"s":"ETHUSD_210924","ps":"ETHUSD","U":86143404851,"u":86143405853,"pu":86143404380,"b":[["2686.73","7614"],["2687.31","0"],["2687.32","0"],["2688.39","0"],["2688.71","500"],["2689.34","1000"],["2689.47","0"],["2689.52","0"],["2689.53","0"],["2689.58","0"],["2689.64","0"],["2689.65","0"],["2689.66","660"],["2689.79","185"]],"a":[["2689.80","3355"]]}}
1618677485.39413: {"stream":"bchusd_210625@depth@100ms","data":{"e":"depthUpdate","E":1618677485337,"T":1618677485329,"s":"BCHUSD_210625","ps":"BCHUSD","U":86143404847,"u":86143405841,"pu":86143404812,"b":[["1117.31","200"],["1117.82","0"],["1120.90","0"],["1125.49","141"],["1126.00","0"],["1128.16","0"],["1128.17","0"],["1128.18","0"],["1128.19","0"],["1128.20","0"],["1128.22","15"],["1128.23","0"],["1128.24","0"],["1128.25","0"],["1128.26","64"],["1128.27","35"],["1128.28","40"]],"a":[]}}
1618677485.4662201: {"stream":"ethusd_210625@depth@100ms","data":{"e":"depthUpdate","E":1618677485411,"T":1618677485403,"s":"ETHUSD_210625","ps":"ETHUSD","U":86143405607,"u":86143406423,"pu":86143405563,"b":[["2385.39","2000"],["2499.61","2433"],["2503.18","3098"],["2505.26","1000"],["2505.75","3103"],["2506.97","1652"],["2507.26","1354"],["2507.88","1073"],["2507.94","1083"],["2508.91","0"],["2509.04","1585"],["2509.19","0"],["2509.87","0"],["2510.07","0"],["2510.10","0"],["2510.11","299"],["2510.42","0"],["2510.43","0"],["2510.44","73"],["2510.87","1342"]],"a":[["2510.86","0"],["2510.88","4404"],["2510.94","0"],["2511.09","0"],["2511.30","121"],["2511.31","0"],["2511.55","1074"],["2511.59","2577"],["2511.95","0"],["2511.98","0"],["2512.03","16746"],["2512.08","2230"],["2512.09","0"],["2513.61","3669"]]}}
1618677485.477162: {"stream":"btcusd_perp@depth@100ms","data":{"e":"depthUpdate","E":1618677485417,"T":1618677485412,"s":"BTCUSD_PERP","ps":"BTCUSD","U":86143405673,"u":86143406479,"pu":86143405516,"b":[["60104.8","100"],["60359.5","3616"],["60361.7","0"],["60500.7","93"],["60506.0","90"],["60573.1","1"],["60573.2","0"],["60573.4","122"],["60581.0","3497"],["60582.2","0"],["60584.9","90"],["60587.6","0"],["60589.3","80"],["60589.7","0"]],"a":[["60589.6","8068"],["60590.6","30"],["60592.6","30"],["60594.2","0"],["60597.6","291"],["60599.8","40"],["60601.5","57"],["60608.1","0"],["60608.8","0"],["60609.4","0"],["60610.0","120"],["60620.9","0"],["60621.5","0"],["60622.1","0"],["60622.7","243"],["60633.7","0"],["60634.4","0"],["60635.0","0"],["60635.5","243"],["60635.7","0"],["60636.4","2"],["60637.0","32"],["60637.6","243"],["60754.6","45"],["60800.4","0"],["60833.5","3644"]]}}
1618677485.487293: {"stream":"linkusd_210625@depth@100ms","data":{"e":"depthUpdate","E":1618677485434,"T":1618677485423,"s":"LINKUSD_210625","ps":"LINKUSD","U":86143405856,"u":86143406552,"pu":86143405637,"b":[["43.200","0"],["43.344","128"],["43.623","0"],["43.766","0"]],"a":[["43.776","0"]]}}
1618677485.4892402: {"stream":"linkusd_210924@depth@100ms","data":{"e":"depthUpdate","E":1618677485436,"T":1618677485364,"s":"LINKUSD_210924","ps":"LINKUSD","U":86143405859,"u":86143406133,"pu":86143404869,"b":[["45.216","0"],["45.223","20"]],"a":[["45.448","3955"],["45.450","0"]]}}
1618677485.4893818: {"stream":"bchusd_210625@depth@100ms","data":{"e":"depthUpdate","E":1618677485437,"T":1618677485431,"s":"BCHUSD_210625","ps":"BCHUSD","U":86143405872,"u":86143406594,"pu":86143405841,"b":[["1122.18","333"],["1128.21","0"],["1128.22","0"],["1128.26","0"],["1128.27","0"],["1128.28","0"],["1128.29","0"],["1128.30","64"],["1128.31","15"],["1128.32","0"],["1128.33","0"],["1128.34","76"],["1128.35","64"]],"a":[["1138.56","3052"]]}}
1618677485.4977121: {"stream":"ethusd_210924@depth@100ms","data":{"e":"depthUpdate","E":1618677485442,"T":1618677485435,"s":"ETHUSD_210924","ps":"ETHUSD","U":86143405937,"u":86143406629,"pu":86143405853,"b":[["2667.38","0"],["2667.51","250"],["2674.82","0"],["2686.74","1621"],["2687.66","0"],["2687.96","0"],["2688.72","0"],["2689.30","1000"],["2689.34","0"],["2689.35","0"],["2689.66","0"]],"a":[["2689.80","3725"],["2690.24","0"],["2694.75","500"]]}}
1618677485.523283: {"stream":"dotusd_210625@depth@100ms","data":{"e":"depthUpdate","E":1618677485446,"T":1618677485441,"s":"DOTUSD_210625","ps":"DOTUSD","U":86143405956,"u":86143406678,"pu":86143405830,"b":[["46.548","1030"],["46.625","0"]],"a":[["46.762","200"],["46.801","84"],["46.802","0"],["46.803","192"],["46.857","0"],["47.100","0"]]}}
1618677485.523605: {"stream":"xrpusd_210625@depth@100ms","data":{"e":"depthUpdate","E":1618677485454,"T":1618677485350,"s":"XRPUSD_210625","ps":"XRPUSD","U":86143406035,"u":86143406037,"pu":86143405114,"b":[],"a":[["1.6924","45"],["1.6928","0"]]}}
1618677485.551754: {"stream":"btcusd_210924@depth@100ms","data":{"e":"depthUpdate","E":1618677485499,"T":1618677485434,"s":"BTCUSD_210924","ps":"BTCUSD","U":86143406363,"u":86143406621,"pu":86143404838,"b":[["68580.8","0"],["68605.3","1204"],["68606.6","290"]],"a":[]}}
1618677485.553139: {"stream":"egldusd_perp@depth@100ms","data":{"e":"depthUpdate","E":1618677485499,"T":1618677485491,"s":"EGLDUSD_PERP","ps":"EGLDUSD","U":86143406370,"u":86143407015,"pu":86143405113,"b":[["215.959","97"],["216.031","0"],["216.044","0"]],"a":[["216.307","0"],["216.308","0"],["216.350","531"]]}}
1618677485.573956: {"stream":"ethusd_210625@depth@100ms","data":{"e":"depthUpdate","E":1618677485514,"T":1618677485510,"s":"ETHUSD_210625","ps":"ETHUSD","U":86143406470,"u":86143407103,"pu":86143406423,"b":[["2503.39","500"],["2503.75","0"],["2505.65","3971"],["2505.75","2603"],["2508.41","1760"],["2509.05","0"],["2509.12","0"],["2509.38","299"],["2509.87","0"],["2510.11","0"],["2510.12","1378"],["2510.13","374"],["2510.44","0"],["2510.87","1342"]],"a":[["2510.86","0"],["2510.88","4404"],["2511.09","0"],["2511.14","0"],["2511.30","0"],["2511.35","618"],["2511.52","0"],["2511.54","1040"],["2511.55","0"],["2511.59","1506"],["2512.18","1074"],["2512.53","1535"]]}}
1618677485.578038: {"stream":"btcusd_perp@depth@100ms","data":{"e":"depthUpdate","E":1618677485519,"T":1618677485496,"s":"BTCUSD_PERP","ps":"BTCUSD","U":86143406499,"u":86143407041,"pu":86143406479,"b":[["60334.1","1807"],["60378.7","0"],["60574.8","485"],["60575.4","545"],["60577.3","0"],["60579.8","1"]],"a":[["60601.4","50"],["60601.7","0"],["60604.1","1"],["60609.9","135"],["60610.0","120"],["60610.3","0"],["60720.0","594"],["60819.6","1838"]]}}
1618677485.593664: {"stream":"linkusd_210625@depth@100ms","data":{"e":"depthUpdate","E":1618677485536,"T":1618677485469,"s":"LINKUSD_210625","ps":"LINKUSD","U":86143406612,"u":86143406886,"pu":86143406552,"b":[["43.251","128"],["43.584","0"],["43.609","24"],["43.644","103"],["43.766","0"]],"a":[["43.777","13"],["43.814","118"],["43.832","0"]]}}
1618677485.598429: {"stream":"bchusd_210625@depth@100ms","data":{"e":"depthUpdate","E":1618677485538,"T":1618677485530,"s":"BCHUSD_210625","ps":"BCHUSD","U":86143406624,"u":86143407217,"pu":86143406594,"b":[["1125.49","0"],["1125.97","50"],["1128.30","0"],["1128.31","0"],["1128.34","0"],["1128.35","64"],["1128.36","35"],["1128.37","0"]],"a":[["1129.67","0"],["1129.68","0"],["1129.76","0"],["1129.77","0"],["1129.79","716"],["1129.80","0"],["1138.56","1359"]]}}
1618677485.603282: {"stream":"ethusd_210924@depth@100ms","data":{"e":"depthUpdate","E":1618677485543,"T":1618677485524,"s":"ETHUSD_210924","ps":"ETHUSD","U":86143406664,"u":86143407188,"pu":86143406629,"b":[["2555.39","1000"],["2666.93","150"],["2667.51","0"],["2680.04","250"],["2687.20","150"],["2687.79","0"],["2687.96","0"],["2688.72","660"],["2689.20","0"],["2689.30","0"]],"a":[["2689.80","3605"],["2698.51","19211"],["2699.48","0"]]}}
1618677485.603637: {"stream":"linkusd_210924@depth@100ms","data":{"e":"depthUpdate","E":1618677485546,"T":1618677485542,"s":"LINKUSD_210924","ps":"LINKUSD","U":86143406692,"u":86143407285,"pu":86143406133,"b":[["45.206","0"],["45.241","0"],["45.242","100"],["45.243","265"]],"a":[["45.364","250"],["45.384","250"]]}}
1618677485.6037571: {"stream":"dotusd_210625@depth@100ms","data":{"e":"depthUpdate","E":1618677485546,"T":1618677485486,"s":"DOTUSD_210625","ps":"DOTUSD","U":86143406689,"u":86143406981,"pu":86143406678,"b":[],"a":[["46.762","0"],["46.764","200"],["46.801","0"],["46.802","84"],["46.803","0"],["46.980","40"],["47.095","100"]]}}
1618677485.6193469: {"stream":"xrpusd_210625@depth@100ms","data":{"e":"depthUpdate","E":1618677485558,"T":1618677485535,"s":"XRPUSD_210625","ps":"XRPUSD","U":86143406771,"u":86143407232,"pu":86143406037,"b":[["1.6871","90"],["1.6906","7"]],"a":[["1.6924","0"],["1.6928","45"],["1.6951","124"],["1.6952","97"],["1.6958","346"],["1.7012","0"],["1.7031","2191"]]}}
1618677485.669527: {"stream":"egldusd_perp@depth@100ms","data":{"e":"depthUpdate","E":1618677485609,"T":1618677485544,"s":"EGLDUSD_PERP","ps":"EGLDUSD","U":86143407088,"u":86143407290,"pu":86143407015,"b":[["215.858","0"],["215.945","0"],["215.959","0"],["215.960","413"],["215.969","54"],["215.974","97"],["216.054","0"]],"a":[["216.310","58"],["216.394","0"],["216.460","15"]]}}
1618677485.6697972: {"stream":"ethusd_210625@depth@100ms","data":{"e":"depthUpdate","E":1618677485617,"T":1618677485610,"s":"ETHUSD_210625","ps":"ETHUSD","U":86143407112,"u":86143407633,"pu":86143407103,"b":[["2503.51","3000"],["2503.90","330"],["2505.55","1194"],["2505.65","3471"],["2507.96","0"],["2508.85","117"],["2509.38","0"],["2510.12","0"],["2510.13","0"],["2510.14","1378"],["2510.15","352"],["2510.71","299"],["2510.87","1342"]],"a":[["2510.86","0"],["2511.14","0"],["2511.31","121"],["2511.35","497"],["2511.52","0"],["2511.55","0"],["2511.59","1506"],["2512.15","587"],["2512.18","0"],["2512.21","1073"],["2512.22","0"],["2512.24","1074"],["2512.28","1462"],["2513.15","6098"],["2513.22","2444"],["2513.93","0"],["2514.73","105"],["2514.93","0"],["2514.95","500"],["2523.69","0"],["2525.12","12499"]]}}
1618677485.694728: {"stream":"bchusd_210625@depth@100ms","data":{"e":"depthUpdate","E":1618677485640,"T":1618677485633,"s":"BCHUSD_210625","ps":"BCHUSD","U":86143407243,"u":86143407779,"pu":86143407217,"b":[["1122.78","0"],["1124.11","132"],["1125.49","141"],["1125.97","0"],["1128.35","0"],["1128.36","0"],["1128.37","20"],["1128.38","64"],["1128.39","17"],["1128.40","35"]],"a":[["1130.06","96"],["1132.06","0"],["1137.20","1263"],["1138.56","0"]]}}
1618677485.695035: {"stream":"btcusd_perp@depth@100ms","data":{"e":"depthUpdate","E":1618677485641,"T":1618677485619,"s":"BTCUSD_PERP","ps":"BTCUSD","U":86143407242,"u":86143407694,"pu":86143407041,"b":[["54522.9","0"],["57854.9","1"],["60377.5","1808"]],"a":[["60801.6","1821"]]}}
1618677485.698084: {"stream":"ethusd_210924@depth@100ms","data":{"e":"depthUpdate","E":1618677485643,"T":1618677485636,"s":"ETHUSD_210924","ps":"ETHUSD","U":86143407257,"u":86143407792,"pu":86143407188,"b":[["2688.72","0"],["2689.20","660"],["2689.58","461"]],"a":[["2689.80","3355"],["2690.23","50"],["2694.75","0"],["2702.75","0"]]}}
1618677485.698325: {"stream":"linkusd_210625@depth@100ms","data":{"e":"depthUpdate","E":1618677485643,"T":1618677485615,"s":"LINKUSD_210625","ps":"LINKUSD","U":86143407263,"u":86143407673,"pu":86143406886,"b":[["43.580","0"],["43.766","0"]],"a":[["43.776","0"],["43.784","50"],["43.789","0"],["43.963","1319"]]}}
1618677485.7016242: {"stream":"linkusd_210924@depth@100ms","data":{"e":"depthUpdate","E":1618677485647,"T":1618677485582,"s":"LINKUSD_210924","ps":"LINKUSD","U":86143407293,"u":86143407503,"pu":86143407285,"b":[],"a":[["45.364","0"],["45.384","0"],["45.434","3482"],["45.448","0"]]}}
1618677485.7169652: {"stream":"dotusd_210625@depth@100ms","data":{"e":"depthUpdate","E":1618677485661,"T":1618677485637,"s":"DOTUSD_210625","ps":"DOTUSD","U":86143407360,"u":86143407796,"pu":86143406981,"b":[],"a":[["46.764","0"],["46.801","200"],["46.802","0"],["46.803","84"],["46.868","1816"],["46.915","0"],["46.993","731"],["47.065","0"]]}}
1618677485.718831: {"stream":"xrpusd_210625@depth@100ms","data":{"e":"depthUpdate","E":1618677485664,"T":1618677485654,"s":"XRPUSD_210625","ps":"XRPUSD","U":86143407379,"u":86143407883,"pu":86143407232,"b":[["1.6733","0"],["1.6887","135"],["1.6894","898"],["1.6906","52"],["1.6907","0"]],"a":[["1.6924","45"],["1.6928","0"],["1.6931","112"],["1.6932","533"],["1.6946","1467"],["1.6949","1000"],["1.6952","0"],["1.6958","0"],["1.6959","651"],["1.6967","4304"],["1.6972","3339"]]}}
1618677485.731315: {"stream":"btcusd_210924@depth@100ms","data":{"e":"depthUpdate","E":1618677485676,"T":1618677485598,"s":"BTCUSD_210924","ps":"BTCUSD","U":86143407444,"u":86143407567,"pu":86143406621,"b":[["68524.5","534"],["68589.9","1204"],["68590.0","297"],["68605.3","0"],["68606.6","54"]],"a":[]}}
1618677485.77018: {"stream":"egldusd_perp@depth@100ms","data":{"e":"depthUpdate","E":1618677485717,"T":1618677485705,"s":"EGLDUSD_PERP","ps":"EGLDUSD","U":86143407662,"u":86143408142,"pu":86143407290,"b":[["215.960","0"],["215.969","0"],["215.974","391"],["215.975","7"],["215.989","97"],["216.064","54"]],"a":[]}}
1618677485.7794719: {"stream":"ethusd_210625@depth@100ms","data":{"e":"depthUpdate","E":1618677485725,"T":1618677485694,"s":"ETHUSD_210625","ps":"ETHUSD","U":86143407715,"u":86143408070,"pu":86143407633,"b":[["2510.14","0"],["2510.15","0"],["2510.16","1378"]],"a":[["2510.86","0"],["2510.94","121"],["2511.09","0"],["2511.31","0"],["2511.52","1073"],["2511.55","1074"],["2511.59","2577"],["2512.21","0"],["2512.24","0"],["2512.28","391"]]}}
1618677485.807253: {"stream":"bchusd_210625@depth@100ms","data":{"e":"depthUpdate","E":1618677485748,"T":1618677485743,"s":"BCHUSD_210625","ps":"BCHUSD","U":86143407837,"u":86143408330,"pu":86143407779,"b":[["1121.08","0"],["1125.26","0"],["1127.01","12"],["1128.37","0"],["1128.38","64"],["1128.40","35"]],"a":[["1130.16","12"],["1131.84","0"],["1140.54","0"]]}}
1618677485.8074539: {"stream":"linkusd_210625@depth@100ms","data":{"e":"depthUpdate","E":1618677485748,"T":1618677485737,"s":"LINKUSD_210625","ps":"LINKUSD","U":86143407834,"u":86143408301,"pu":86143407673,"b":[["43.351","0"],["43.406","2156"],["43.589","481"],["43.766","0"]],"a":[["43.780","100"],["43.782","100"],["43.784","100"],["43.788","0"],["43.790","0"],["43.792","0"],["43.833","579"],["43.840","0"],["43.954","180"]]}}
1618677485.807632: {"stream":"ethusd_210924@depth@100ms","data":{"e":"depthUpdate","E":1618677485748,"T":1618677485738,"s":"ETHUSD_210924","ps":"ETHUSD","U":86143407832,"u":86143408306,"pu":86143407792,"b":[["2666.93","150"],["2667.64","0"],["2686.13","8116"],["2686.73","0"],["2686.74","0"],["2687.20","150"],["2687.92","0"],["2689.20","0"],["2689.58","660"],["2689.63","0"]],"a":[["2689.80","3405"],["2690.23","0"]]}}
1618677485.841235: {"stream":"btcusd_perp@depth@100ms","data":{"e":"depthUpdate","E":1618677485772,"T":1618677485760,"s":"BTCUSD_PERP","ps":"BTCUSD","U":86143407958,"u":86143408428,"pu":86143407694,"b":[["60370.2","1808"],["60574.8","0"],["60575.4","0"],["60586.6","0"]],"a":[["60609.6","122"],["60609.9","13"],["60610.0","120"],["60622.3","243"],["60622.7","0"],["60635.2","396"],["60635.5","0"],["60637.2","243"],["60637.6","0"],["60808.9","1821"]]}}
1618677485.841492: {"stream":"dotusd_210625@depth@100ms","data":{"e":"depthUpdate","E":1618677485776,"T":1618677485740,"s":"DOTUSD_210625","ps":"DOTUSD","U":86143407968,"u":86143408317,"pu":86143407796,"b":[],"a":[["46.800","1260"],["46.803","0"],["46.980","0"],["47.095","50"]]}}
1618677485.8451462: {"stream":"xrpusd_210625@depth@100ms","data":{"e":"depthUpdate","E":1618677485785,"T":1618677485764,"s":"XRPUSD_210625","ps":"XRPUSD","U":86143408004,"u":86143408437,"pu":86143407883,"b":[["1.6648","0"],["1.6746","1607"]],"a":[["1.6924","0"]]}}
1618677485.877066: {"stream":"egldusd_perp@depth@100ms","data":{"e":"depthUpdate","E":1618677485823,"T":1618677485810,"s":"EGLDUSD_PERP","ps":"EGLDUSD","U":86143408236,"u":86143408702,"pu":86143408142,"b":[["215.942","595"],["215.945","15"],["215.974","0"],["215.975","0"],["216.064","0"],["216.117","0"]],"a":[["216.170","97"],["216.281","558"],["216.309","523"],["216.350","0"]]}}
1618677485.891807: {"stream":"ethusd_210625@depth@100ms","data":{"e":"depthUpdate","E":1618677485836,"T":1618677485831,"s":"ETHUSD_210625","ps":"ETHUSD","U":86143408282,"u":86143408884,"pu":86143408070,"b":[["2507.88","0"],["2507.94","12"],["2508.40","0"],["2508.77","1881"],["2510.10","1378"],["2510.11","563"],["2510.16","0"],["2510.51","299"],["2510.71","0"],["2510.87","127"]],"a":[["2510.86","0"],["2510.88","4904"],["2510.94","121"],["2511.14","0"],["2511.30","0"],["2511.52","0"],["2511.55","0"],["2511.59","1506"],["2512.24","1074"]]}}
1618677485.9064472: {"stream":"linkusd_210924@depth@100ms","data":{"e":"depthUpdate","E":1618677485848,"T":1618677485767,"s":"LINKUSD_210924","ps":"LINKUSD","U":86143408333,"u":86143408448,"pu":86143407503,"b":[],"a":[["45.397","250"],["45.427","2189"],["45.435","0"],["45.801","137"]]}}
1618677485.9158468: {"stream":"ethusd_210924@depth@100ms","data":{"e":"depthUpdate","E":1618677485848,"T":1618677485838,"s":"ETHUSD_210924","ps":"ETHUSD","U":86143408335,"u":86143408936,"pu":86143408306,"b":[["2680.04","0"],["2685.20","18721"],["2689.20","660"],["2689.58","0"]],"a":[["2689.80","3525"],["2690.60","150"]]}}
1618677485.916023: {"stream":"linkusd_210625@depth@100ms","data":{"e":"depthUpdate","E":1618677485848,"T":1618677485838,"s":"LINKUSD_210625","ps":"LINKUSD","U":86143408331,"u":86143408937,"pu":86143408301,"b":[["43.395","0"],["43.419","290"],["43.755","0"],["43.766","0"]],"a":[["43.776","50"],["43.829","431"]]}}
1618677485.92432: {"stream":"bchusd_210625@depth@100ms","data":{"e":"depthUpdate","E":1618677485863,"T":1618677485854,"s":"BCHUSD_210625","ps":"BCHUSD","U":86143408421,"u":86143409065,"pu":86143408330,"b":[["1117.31","0"],["1117.79","100"],["1125.16","286"],["1125.49","0"],["1125.97","100"],["1128.10","0"],["1128.38","0"],["1128.39","0"],["1128.40","0"],["1128.41","0"],["1128.42","64"],["1128.43","14"],["1128.44","0"],["1128.45","0"],["1128.46","0"],["1128.47","64"]],"a":[["1132.87","200"],["1132.89","0"]]}}
1618677485.942977: {"stream":"btcusd_perp@depth@100ms","data":{"e":"depthUpdate","E":1618677485886,"T":1618677485877,"s":"BTCUSD_PERP","ps":"BTCUSD","U":86143408521,"u":86143409278,"pu":86143408428,"b":[["59017.4","50"],["60217.2","50"],["60253.1","0"],["60449.7","0"],["60571.3","243"],["60571.4","122"],["60572.3","0"],["60572.5","0"],["60573.3","0"],["60573.4","0"],["60574.8","485"],["60575.4","545"],["60579.3","0"],["60581.2","50"],["60583.3","130"],["60584.1","243"],["60585.2","0"],["60585.8","160"],["60586.1","343"],["60587.2","100"],["60588.1","0"],["60589.7","0"]],"a":[["60589.6","8098"],["60590.6","0"],["60592.6","0"],["60593.9","151"],["60595.8","1"],["60596.8","215"],["60606.0","20"],["60607.4","122"],["60608.8","0"],["60609.6","0"],["60618.0","10"],["60620.2","299"],["60621.6","0"],["60622.3","0"],["60632.0","30"],["60633.0","243"],["60634.4","0"],["60635.0","243"],["60635.2","153"],["60636.4","2"],["60637.2","0"]]}}
1618677485.946759: {"stream":"btcusd_210924@depth@100ms","data":{"e":"depthUpdate","E":1618677485889,"T":1618677485845,"s":"BTCUSD_210924","ps":"BTCUSD","U":86143408536,"u":86143408975,"pu":86143407567,"b":[["68581.0","1204"],["68589.9","0"],["68590.0","0"],["68597.0","50"]],"a":[["68632.1","120"]]}}
1618677485.946901: {"stream":"dotusd_210625@depth@100ms","data":{"e":"depthUpdate","E":1618677485889,"T":1618677485882,"s":"DOTUSD_210625","ps":"DOTUSD","U":86143408553,"u":86143409337,"pu":86143408317,"b":[["46.744","1"]],"a":[["46.758","256"],["46.764","0"],["46.790","611"],["46.798","242"],["46.799","84"],["46.800","1176"],["46.801","0"],["46.818","0"],["46.838","250"],["46.868","2066"],["46.972","40"],["47.079","50"],["47.095","0"],["47.322","0"],["47.347","464"]]}}
1618677485.9566321: {"stream":"xrpusd_210625@depth@100ms","data":{"e":"depthUpdate","E":1618677485898,"T":1618677485804,"s":"XRPUSD_210625","ps":"XRPUSD","U":86143408606,"u":86143408674,"pu":86143408437,"b":[["1.6661","5558"],["1.6861","61"]],"a":[["1.6928","45"]]}}
1618677485.98611: {"stream":"egldusd_perp@depth@100ms","data":{"e":"depthUpdate","E":1618677485928,"T":1618677485891,"s":"EGLDUSD_PERP","ps":"EGLDUSD","U":86143408805,"u":86143409403,"pu":86143408702,"b":[["215.587","875"],["215.623","0"],["215.720","23"],["215.857","389"],["215.942","2"],["215.944","0"],["215.945","0"],["215.946","1"],["215.959","0"],["215.969","54"],["215.989","0"],["215.999","170"],["216.008","97"]],"a":[["216.280","75"],["216.310","0"]]}}
1618677485.98928: {"stream":"ethusd_210625@depth@100ms","data":{"e":"depthUpdate","E":1618677485936,"T":1618677485923,"s":"ETHUSD_210625","ps":"ETHUSD","U":86143408885,"u":86143409587,"pu":86143408884,"b":[["2503.18","0"],["2503.39","200"],["2503.74","3098"],["2510.10","100"],["2510.12","1378"],["2510.20","100"],["2510.30","100"],["2510.50","0"],["2510.51","0"],["2510.57","299"],["2510.60","0"],["2510.61","100"],["2510.70","0"],["2510.87","0"]],"a":[["2510.85","0"],["2510.86","0"],["2510.87","2343"],["2510.88","3922"],["2510.94","0"],["2511.55","1074"],["2512.24","0"],["2512.67","0"],["2515.84","500"]]}}
1618677486.052893: {"stream":"dotusd_210625@depth@100ms","data":{"e":"depthUpdate","E":1618677485994,"T":1618677485982,"s":"DOTUSD_210625","ps":"DOTUSD","U":86143409392,"u":86143410007,"pu":86143409337,"b":[["46.542","0"],["46.549","1518"],["46.673","3"],["46.743","1200"],["46.744","0"],["46.755","0"]],"a":[["46.754","796"],["46.755","0"],["46.756","0"],["46.760","0"],["46.763","0"],["46.764","0"],["46.765","0"],["46.789","84"],["46.799","0"],["46.939","0"],["46.972","0"],["47.226","0"]]}}
1618677486.0589912: {"stream":"btcusd_perp@depth@100ms","data":{"e":"depthUpdate","E":1618677485998,"T":1618677485984,"s":"BTCUSD_PERP","ps":"BTCUSD","U":86143409418,"u":86143410027,"pu":86143409278,"b":[["59975.2","132"],["60560.8","0"],["60569.3","0"],["60570.4","2291"],["60570.6","122"],["60571.2","0"],["60571.3","0"],["60571.4","0"],["60574.8","0"],["60575.3","397"],["60575.4","0"],["60581.2","0"],["60581.6","30"],["60582.6","50"],["60583.3","343"],["60583.7","0"],["60584.1","0"],["60584.2","32"],["60584.9","40"],["60585.2","0"],["60585.3","273"],["60586.1","100"]],"a":[["60599.1","268"],["60601.5","7"],["60607.0","122"],["60607.4","0"],["60619.8","243"],["60620.2","56"],["60632.6","643"],["60633.0","0"],["60634.6","243"],["60635.0","0"],["60674.7","109"],["61186.9","0"]]}}
1618677486.070593: {"stream":"ethusd_210924@depth@100ms","data":{"e":"depthUpdate","E":1618677485954,"T":1618677485947,"s":"ETHUSD_210924","ps":"ETHUSD","U":86143409002,"u":86143409750,"pu":86143408936,"b":[["2680.02","250"],["2685.20","18571"],["2686.68","0"],["2687.16","4086"]],"a":[["2689.80","3525"],["2690.60","0"]]}}
1618677486.0707572: {"stream":"bchusd_210625@depth@100ms","data":{"e":"depthUpdate","E":1618677485963,"T":1618677485958,"s":"BCHUSD_210625","ps":"BCHUSD","U":86143409109,"u":86143409830,"pu":86143409065,"b":[["1121.29","190"],["1127.66","0"],["1128.12","0"],["1128.13","35"],["1128.42","0"],["1128.43","0"],["1128.48","14"],["1128.49","0"],["1128.50","0"],["1128.51","0"],["1128.52","0"],["1128.53","64"]],"a":[["1132.86","0"],["1132.87","0"]]}}
1618677486.070868: {"stream":"linkusd_210625@depth@100ms","data":{"e":"depthUpdate","E":1618677485966,"T":1618677485938,"s":"LINKUSD_210625","ps":"LINKUSD","U":86143409139,"u":86143409686,"pu":86143408937,"b":[["43.754","598"],["43.756","100"],["43.762","0"],["43.764","0"]],"a":[["43.776","0"],["43.779","50"],["43.828","559"],["43.833","20"]]}}
1618677486.0963268: {"stream":"xrpusd_210625@depth@100ms","data":{"e":"depthUpdate","E":1618677486033,"T":1618677486013,"s":"XRPUSD_210625","ps":"XRPUSD","U":86143409631,"u":86143410291,"pu":86143408674,"b":[["1.6808","100"],["1.6812","0"],["1.6840","0"],["1.6852","531"],["1.6863","0"],["1.6870","714"],["1.6880","150"],["1.6899","0"],["1.6900","176"],["1.6901","126"],["1.6902","66"],["1.6905","24"],["1.6906","0"]],"a":[["1.6924","821"],["1.6928","0"],["1.6996","0"],["1.7022","2527"]]}}
1618677486.096651: {"stream":"egldusd_perp@depth@100ms","data":{"e":"depthUpdate","E":1618677486034,"T":1618677486020,"s":"EGLDUSD_PERP","ps":"EGLDUSD","U":86143409636,"u":86143410341,"pu":86143409403,"b":[["215.956","0"],["215.969","0"]],"a":[]}}
1618677486.103132: {"stream":"ethusd_210625@depth@100ms","data":{"e":"depthUpdate","E":1618677486043,"T":1618677486026,"s":"ETHUSD_210625","ps":"ETHUSD","U":86143409687,"u":86143410422,"pu":86143409587,"b":[["2510.12","1378"],["2510.31","0"],["2510.57","299"],["2510.86","1300"]],"a":[["2510.85","0"],["2510.87","2222"],["2510.94","121"],["2511.09","0"],["2511.40","1923"],["2511.41","4054"],["2511.44","2794"],["2511.45","2306"],["2511.49","2027"],["2511.53","2030"],["2511.54","0"],["2511.58","0"],["2511.59","675"],["2511.61","0"],["2511.63","0"],["2511.66","0"],["2511.70","96"],["2512.00","0"],["2512.30","1444"]]}}
1618677486.1342962: {"stream":"linkusd_210625@depth@100ms","data":{"e":"depthUpdate","E":1618677486067,"T":1618677486019,"s":"LINKUSD_210625","ps":"LINKUSD","U":86143409869,"u":86143410334,"pu":86143409686,"b":[["43.740","92"],["43.746","97"],["43.757","0"]],"a":[["43.764","32"],["43.772","100"],["43.774","100"],["43.776","100"],["43.780","0"],["43.782","0"],["43.784","0"],["43.796","103"],["43.954","0"],["44.000","0"]]}}
1618677486.139473: {"stream":"btcusd_210924@depth@100ms","data":{"e":"depthUpdate","E":1618677486075,"T":1618677486064,"s":"BTCUSD_210924","ps":"BTCUSD","U":86143409914,"u":86143410706,"pu":86143408975,"b":[["68524.5","0"],["68599.0","15"]],"a":[["68677.3","161"],["68677.4","745"],["68689.8","0"],["68689.9","0"],["68736.4","15"]]}}
1618677486.139709: {"stream":"bchusd_210625@depth@100ms","data":{"e":"depthUpdate","E":1618677486075,"T":1618677486068,"s":"BCHUSD_210625","ps":"BCHUSD","U":86143409935,"u":86143410744,"pu":86143409830,"b":[["1126.69","1162"],["1127.66","0"],["1128.13","0"],["1128.14","35"],["1128.48","0"]],"a":[["1132.86","100"],["1137.01","1263"],["1137.20","0"]]}}
1618677486.139904: {"stream":"ethusd_210924@depth@100ms","data":{"e":"depthUpdate","E":1618677486081,"T":1618677486064,"s":"ETHUSD_210924","ps":"ETHUSD","U":86143409985,"u":86143410710,"pu":86143409750,"b":[["2689.20","0"],["2689.58","660"]],"a":[["2689.80","3405"],["2702.63","250"]]}}
1618677486.152189: {"stream":"dotusd_210625@depth@100ms","data":{"e":"depthUpdate","E":1618677486099,"T":1618677486072,"s":"DOTUSD_210625","ps":"DOTUSD","U":86143410077,"u":86143410779,"pu":86143410007,"b":[["46.426","1020"],["46.722","262"]],"a":[["46.757","200"],["46.764","0"],["46.788","0"],["46.917","140"],["46.964","1240"],["47.126","1035"],["47.175","1150"]]}}
1618677486.159965: {"stream":"btcusd_perp@depth@100ms","data":{"e":"depthUpdate","E":1618677486102,"T":1618677486078,"s":"BTCUSD_PERP","ps":"BTCUSD","U":86143410097,"u":86143410813,"pu":86143410027,"b":[["60534.4","100"],["60560.9","363"],["60570.4","260"],["60570.5","2111"],["60581.6","0"],["60583.7","32"],["60584.2","0"],["60584.3","30"],["60589.7","0"]],"a":[["60589.6","8128"],["60594.2","40"],["60599.8","0"],["60606.9","122"],["60607.0","0"]]}}
1618677486.160254: {"stream":"linkusd_210924@depth@100ms","data":{"e":"depthUpdate","E":1618677486102,"T":1618677486096,"s":"LINKUSD_210924","ps":"LINKUSD","U":86143410120,"u":86143410928,"pu":86143408448,"b":[["45.179","44"],["45.186","0"],["45.237","0"]],"a":[["45.405","191"],["45.406","902"],["45.407","0"],["45.408","0"],["45.449","0"]]}}
1618677486.1896122: {"stream":"xrpusd_210625@depth@100ms","data":{"e":"depthUpdate","E":1618677486136,"T":1618677486133,"s":"XRPUSD_210625","ps":"XRPUSD","U":86143410474,"u":86143411166,"pu":86143410291,"b":[["1.6808","0"],["1.6810","207"],["1.6888","0"],["1.6895","217"],["1.6897","0"],["1.6900","128"],["1.6901","26"],["1.6902","21"],["1.6903","50"]],"a":[["1.6920","0"],["1.6922","100"],["1.6924","776"],["1.6925","48"],["1.6928","0"],["1.6929","12"],["1.6970","3498"],["1.6972","242"]]}}
1618677486.201945: {"stream":"egldusd_perp@depth@100ms","data":{"e":"depthUpdate","E":1618677486150,"T":1618677486050,"s":"EGLDUSD_PERP","ps":"EGLDUSD","U":86143410573,"u":86143410592,"pu":86143410341,"b":[["215.858","301"],["215.956","54"]],"a":[["216.279","134"]]}}
1618677486.214324: {"stream":"ethusd_210625@depth@100ms","data":{"e":"depthUpdate","E":1618677486157,"T":1618677486100,"s":"ETHUSD_210625","ps":"ETHUSD","U":86143410617,"u":86143410948,"pu":86143410422,"b":[],"a":[["2510.85","0"],["2510.87","2343"],["2510.94","0"],["2512.89","3036"]]}}
1618677486.238761: {"stream":"bchusd_210625@depth@100ms","data":{"e":"depthUpdate","E":1618677486186,"T":1618677486181,"s":"BCHUSD_210625","ps":"BCHUSD","U":86143410842,"u":86143411480,"pu":86143410744,"b":[["1112.27","0"],["1127.66","0"],["1128.14","0"],["1128.15","0"],["1128.48","35"],["1128.49","20"],["1128.54","6"]],"a":[]}}
1618677486.247054: {"stream":"linkusd_210625@depth@100ms","data":{"e":"depthUpdate","E":1618677486195,"T":1618677486181,"s":"LINKUSD_210625","ps":"LINKUSD","U":86143410887,"u":86143411483,"pu":86143410334,"b":[],"a":[["43.786","0"],["43.828","0"],["43.840","559"],["43.905","32"],["43.952","180"]]}}
1618677486.25998: {"stream":"ethusd_210924@depth@100ms","data":{"e":"depthUpdate","E":1618677486204,"T":1618677486169,"s":"ETHUSD_210924","ps":"ETHUSD","U":86143410953,"u":86143411406,"pu":86143410710,"b":[["2688.72","660"],["2689.58","0"]],"a":[["2689.80","3355"],["2690.23","400"],["2697.71","10492"],["2698.14","0"],["2702.63","0"]]}}
1618677486.261813: {"stream":"btcusd_perp@depth@100ms","data":{"e":"depthUpdate","E":1618677486207,"T":1618677486200,"s":"BTCUSD_PERP","ps":"BTCUSD","U":86143410967,"u":86143411628,"pu":86143410813,"b":[],"a":[["60606.9","0"],["60607.5","122"],["60632.6","400"],["60633.0","243"],["60634.6","0"],["60635.1","243"],["60639.9","0"]]}}
1618677486.2936509: {"stream":"xrpusd_210625@depth@100ms","data":{"e":"depthUpdate","E":1618677486241,"T":1618677486231,"s":"XRPUSD_210625","ps":"XRPUSD","U":86143411205,"u":86143411870,"pu":86143411166,"b":[["1.6808","100"],["1.6810","157"],["1.6897","45"],["1.6901","126"],["1.6902","0"],["1.6903","0"],["1.6906","0"]],"a":[["1.6924","821"]]}}
1618677486.312865: {"stream":"egldusd_perp@depth@100ms","data":{"e":"depthUpdate","E":1618677486259,"T":1618677486176,"s":"EGLDUSD_PERP","ps":"EGLDUSD","U":86143411315,"u":86143411450,"pu":86143410592,"b":[["215.857","0"],["215.859","390"],["215.956","0"],["216.018","54"]],"a":[["216.278","74"],["216.280","0"]]}}
1618677486.315139: {"stream":"ethusd_210625@depth@100ms","data":{"e":"depthUpdate","E":1618677486262,"T":1618677486251,"s":"ETHUSD_210625","ps":"ETHUSD","U":86143411330,"u":86143411976,"pu":86143410948,"b":[["2510.21","0"],["2510.31","299"],["2510.57","0"],["2510.58","367"],["2510.86","1425"]],"a":[["2510.85","0"],["2510.87","2222"],["2511.39","121"],["2511.78","835"],["2511.79","0"],["2511.80","2145"],["2513.08","0"],["2513.15","0"],["2513.26","6541"],["2513.96","0"],["2517.84","3199"]]}}
1618677486.3247092: {"stream":"dotusd_210625@depth@100ms","data":{"e":"depthUpdate","E":1618677486273,"T":1618677486228,"s":"DOTUSD_210625","ps":"DOTUSD","U":86143411412,"u":86143411838,"pu":86143410779,"b":[["46.723","56"],["46.741","52"],["46.743","0"]],"a":[["46.752","0"],["46.754","540"],["46.757","0"],["46.788","200"]]}}
1618677486.343793: {"stream":"bchusd_210625@depth@100ms","data":{"e":"depthUpdate","E":1618677486290,"T":1618677486276,"s":"BCHUSD_210625","ps":"BCHUSD","U":86143411513,"u":86143412141,"pu":86143411480,"b":[["1123.44","5476"],["1127.66","0"],["1128.10","436"],["1128.15","0"],["1128.48","0"],["1128.50","35"]],"a":[]}}
1618677486.351344: {"stream":"btcusd_210924@depth@100ms","data":{"e":"depthUpdate","E":1618677486297,"T":1618677486259,"s":"BTCUSD_210924","ps":"BTCUSD","U":86143411566,"u":86143412037,"pu":86143410706,"b":[],"a":[["68632.1","185"],["68693.9","334"],["68694.0","1491"],["68703.4","0"],["68703.5","0"]]}}
1618677486.351546: {"stream":"linkusd_210625@depth@100ms","data":{"e":"depthUpdate","E":1618677486298,"T":1618677486289,"s":"LINKUSD_210625","ps":"LINKUSD","U":86143411583,"u":86143412212,"pu":86143411483,"b":[],"a":[["43.764","0"],["43.778","51"],["43.779","0"],["43.784","0"],["43.795","0"],["43.952","0"]]}}
1618677486.365823: {"stream":"ethusd_210924@depth@100ms","data":{"e":"depthUpdate","E":1618677486313,"T":1618677486308,"s":"ETHUSD_210924","ps":"ETHUSD","U":86143411667,"u":86143412343,"pu":86143411406,"b":[["2688.72","0"],["2689.20","660"],["2689.58","0"]],"a":[["2689.80","3475"]]}}
1618677486.3691058: {"stream":"btcusd_perp@depth@100ms","data":{"e":"depthUpdate","E":1618677486316,"T":1618677486311,"s":"BTCUSD_PERP","ps":"BTCUSD","U":86143411707,"u":86143412359,"pu":86143411628,"b":[["59983.6","102"],["60443.9","45"],["60570.1","0"],["60570.2","122"],["60570.5","80"],["60570.6","0"],["60575.3","1997"],["60582.8","244"],["60583.3","100"],["60584.3","0"],["60584.8","243"],["60585.3","30"],["60586.2","30"],["60589.7","0"]],"a":[["60606.5","1487"],["60606.8","122"],["60607.5","0"],["60619.3","243"],["60619.8","0"],["60632.1","243"],["60633.0","0"],["60634.1","243"],["60635.1","0"],["60636.1","1414"],["60673.2","1"],["61195.5","2"]]}}
1618677486.39473: {"stream":"xrpusd_210625@depth@100ms","data":{"e":"depthUpdate","E":1618677486342,"T":1618677486329,"s":"XRPUSD_210625","ps":"XRPUSD","U":86143411918,"u":86143412479,"pu":86143411870,"b":[["1.6808","0"],["1.6838","80"],["1.6886","145"],["1.6897","0"],["1.6901","26"],["1.6902","606"],["1.6905","31"],["1.6906","45"]],"a":[["1.6920","0"],["1.6924","0"],["1.6928","45"],["1.6970","401"],["1.6976","0"],["1.6985","4055"]]}}
1618677486.420778: {"stream":"ethusd_210625@depth@100ms","data":{"e":"depthUpdate","E":1618677486368,"T":1618677486359,"s":"ETHUSD_210625","ps":"ETHUSD","U":86143412072,"u":86143412643,"pu":86143411976,"b":[["2505.06","1635"],["2506.08","0"],["2508.04","772"],["2508.41","911"],["2510.31","0"],["2510.62","299"],["2510.86","2325"]],"a":[["2510.85","0"],["2510.87","2262"],["2511.09","0"],["2511.14","0"],["2511.31","121"],["2511.39","0"]]}}
1618677486.437166: {"stream":"dotusd_210625@depth@100ms","data":{"e":"depthUpdate","E":1618677486385,"T":1618677486359,"s":"DOTUSD_210625","ps":"DOTUSD","U":86143412166,"u":86143412637,"pu":86143411838,"b":[["46.521","1428"],["46.549","0"]],"a":[["46.752","0"],["46.757","200"],["46.787","84"],["46.788","0"],["46.789","0"],["46.798","50"],["46.838","0"],["46.868","1816"],["46.889","0"],["46.908","0"]]}}
1618677486.450859: {"stream":"linkusd_210625@depth@100ms","data":{"e":"depthUpdate","E":1618677486398,"T":1618677486378,"s":"LINKUSD_210625","ps":"LINKUSD","U":86143412253,"u":86143412749,"pu":86143412212,"b":[["43.645","0"],["43.684","2311"],["43.697","0"],["43.712","99"],["43.725","0"],["43.755","125"],["43.757","23"],["43.759","28"]],"a":[["43.778","1"],["43.784","50"],["43.954","180"]]}}
1618677486.4574442: {"stream":"bchusd_210625@depth@100ms","data":{"e":"depthUpdate","E":1618677486404,"T":1618677486389,"s":"BCHUSD_210625","ps":"BCHUSD","U":86143412274,"u":86143412824,"pu":86143412141,"b":[["1121.29","0"],["1121.67","0"],["1123.17","481"],["1128.11","92"],["1128.49","0"],["1128.50","0"],["1128.54","0"]],"a":[["1132.79","100"],["1132.86","0"],["1140.49","190"]]}}
1618677486.472808: {"stream":"btcusd_210924@depth@100ms","data":{"e":"depthUpdate","E":1618677486420,"T":1618677486359,"s":"BTCUSD_210924","ps":"BTCUSD","U":86143412382,"u":86143412640,"pu":86143412037,"b":[["61768.8","1"]],"a":[["68632.1","120"]]}}
1618677486.476195: {"stream":"ethusd_210924@depth@100ms","data":{"e":"depthUpdate","E":1618677486424,"T":1618677486420,"s":"ETHUSD_210924","ps":"ETHUSD","U":86143412407,"u":86143412990,"pu":86143412343,"b":[["2687.16","0"],["2687.46","4086"],["2687.47","924"],["2687.96","500"],["2688.71","0"],["2689.20","0"],["2689.21","0"],["2689.58","0"],["2689.63","0"],["2689.79","999"]],"a":[["2689.80","202"],["2702.91","250"]]}}
1618677486.48751: {"stream":"btcusd_perp@depth@100ms","data":{"e":"depthUpdate","E":1618677486435,"T":1618677486415,"s":"BTCUSD_PERP","ps":"BTCUSD","U":86143412498,"u":86143412978,"pu":86143412359,"b":[["59351.1","0"],["60372.7","5427"],["60569.1","365"],["60569.3","0"],["60570.2","0"],["60570.4","17"],["60581.9","243"],["60582.8","1"],["60583.9","243"],["60584.8","0"],["60589.7","0"]],"a":[["60593.9","151"],["60606.6","1618"],["60606.7","0"],["60606.8","0"],["60607.6","50"],["60619.3","243"],["60620.4","0"],["60632.1","0"],["60632.2","243"],["60633.2","0"],["60634.1","0"],["60634.2","1332"],["60635.2","153"],["60814.3","1822"]]}}
1618677486.499684: {"stream":"xrpusd_210625@depth@100ms","data":{"e":"depthUpdate","E":1618677486444,"T":1618677486437,"s":"XRPUSD_210625","ps":"XRPUSD","U":86143412567,"u":86143413059,"pu":86143412479,"b":[["1.6804","145"],["1.6808","0"],["1.6809","100"],["1.6838","0"],["1.6854","172"],["1.6856","0"],["1.6859","56"],["1.6872","0"],["1.6876","470"],["1.6897","0"],["1.6901","26"],["1.6902","100"],["1.6903","21"],["1.6906","45"]],"a":[["1.6924","540"],["1.6928","0"],["1.7040","0"]]}}
1618677486.530047: {"stream":"ethusd_210625@depth@100ms","data":{"e":"depthUpdate","E":1618677486476,"T":1618677486473,"s":"ETHUSD_210625","ps":"ETHUSD","U":86143412713,"u":86143413309,"pu":86143412643,"b":[["2385.39","0"],["2510.31","299"],["2510.41","2000"],["2510.62","0"],["2510.86","2325"]],"a":[["2510.85","0"],["2510.88","3882"],["2511.09","121"],["2511.14","0"],["2511.30","0"],["2511.31","0"],["2513.26","0"],["2513.96","6541"],["2520.37","0"]]}}
1618677486.536784: {"stream":"linkusd_210924@depth@100ms","data":{"e":"depthUpdate","E":1618677486482,"T":1618677486465,"s":"LINKUSD_210924","ps":"LINKUSD","U":86143412746,"u":86143413268,"pu":86143410928,"b":[["45.223","0"],["45.243","276"]],"a":[]}}
1618677486.5422342: {"stream":"dotusd_210625@depth@100ms","data":{"e":"depthUpdate","E":1618677486490,"T":1618677486483,"s":"DOTUSD_210625","ps":"DOTUSD","U":86143412802,"u":86143413366,"pu":86143412637,"b":[["46.741","54"]],"a":[["46.757","200"],["46.786","0"],["46.787","0"],["46.789","84"]]}}
1618677486.560361: {"stream":"linkusd_210625@depth@100ms","data":{"e":"depthUpdate","E":1618677486508,"T":1618677486498,"s":"LINKUSD_210625","ps":"LINKUSD","U":86143412924,"u":86143413484,"pu":86143412749,"b":[["43.600","308"],["43.755","127"],["43.757","22"],["43.759","0"]],"a":[["43.783","0"],["43.784","0"],["43.795","0"],["43.954","0"]]}}
1618677486.569504: {"stream":"bchusd_210625@depth@100ms","data":{"e":"depthUpdate","E":1618677486516,"T":1618677486491,"s":"BCHUSD_210625","ps":"BCHUSD","U":86143412968,"u":86143413430,"pu":86143412824,"b":[["1121.30","190"],["1128.12","0"],["1128.48","0"],["1128.54","35"]],"a":[["1132.29","286"]]}}
1618677486.576587: {"stream":"ethusd_210924@depth@100ms","data":{"e":"depthUpdate","E":1618677486524,"T":1618677486518,"s":"ETHUSD_210924","ps":"ETHUSD","U":86143412992,"u":86143413600,"pu":86143412990,"b":[["2555.39","0"],["2689.33","0"],["2689.58","463"],["2689.63","0"],["2689.64","191"],["2689.79","999"]],"a":[["2689.80","48"],["2695.02","1001"]]}}
1618677486.586642: {"stream":"btcusd_210924@depth@100ms","data":{"e":"depthUpdate","E":1618677486535,"T":1618677486525,"s":"BTCUSD_210924","ps":"BTCUSD","U":86143413047,"u":86143413637,"pu":86143412640,"b":[["68580.7","0"],["68580.9","0"],["68581.1","1339"],["68581.2","540"]],"a":[["68632.1","185"]]}}
1618677486.600965: {"stream":"xrpusd_210625@depth@100ms","data":{"e":"depthUpdate","E":1618677486548,"T":1618677486536,"s":"XRPUSD_210625","ps":"XRPUSD","U":86143413095,"u":86143413699,"pu":86143413059,"b":[["1.6899","697"],["1.6906","0"],["1.6907","0"]],"a":[["1.6922","0"],["1.6924","0"],["1.6930","0"],["1.6931","112"],["1.6932","0"],["1.6940","718"],["1.6949","0"],["1.6967","4304"]]}}
1618677486.606349: {"stream":"btcusd_perp@depth@100ms","data":{"e":"depthUpdate","E":1618677486552,"T":1618677486528,"s":"BTCUSD_PERP","ps":"BTCUSD","U":86143413136,"u":86143413659,"pu":86143412978,"b":[["60568.8","0"],["60569.1","365"],["60569.3","1600"],["60569.5","219"],["60574.2","0"],["60574.7","485"],["60575.2","745"],["60575.3","397"],["60582.2","30"],["60583.7","0"],["60584.0","32"],["60584.3","0"],["60586.2","0"],["60589.7","0"]],"a":[["60606.4","122"],["60606.6","1496"],["60606.7","0"],["60606.8","0"]]}}
1618677486.6326232: {"stream":"ethusd_210625@depth@100ms","data":{"e":"depthUpdate","E":1618677486578,"T":1618677486538,"s":"ETHUSD_210625","ps":"ETHUSD","U":86143413316,"u":86143413711,"pu":86143413309,"b":[["2503.39","200"],["2505.55","694"],["2508.39","0"],["2508.75","20"],["2510.12","0"],["2510.31","0"],["2510.42","1195"],["2510.43","670"],["2510.63","299"]],"a":[["2510.85","0"],["2511.66","250"],["2514.72","0"],["2520.36","0"],["2522.13","2000"]]}}
1618677486.642126: {"stream":"linkusd_210924@depth@100ms","data":{"e":"depthUpdate","E":1618677486589,"T":1618677486512,"s":"LINKUSD_210924","ps":"LINKUSD","U":86143413370,"u":86143413568,"pu":86143413268,"b":[["45.241","225"],["45.243","23"],["45.244","20"],["45.245","26"]],"a":[]}}
1618677486.648139: {"stream":"egldusd_perp@depth@100ms","data":{"e":"depthUpdate","E":1618677486596,"T":1618677486590,"s":"EGLDUSD_PERP","ps":"EGLDUSD","U":86143413422,"u":86143414066,"pu":86143411450,"b":[["215.944","384"],["216.018","0"]],"a":[["216.067","170"],["216.077","33"],["216.135","0"],["216.190","0"],["216.279","0"],["216.281","0"]]}}
1618677486.674397: {"stream":"dotusd_210625@depth@100ms","data":{"e":"depthUpdate","E":1618677486617,"T":1618677486544,"s":"DOTUSD_210625","ps":"DOTUSD","U":86143413585,"u":86143413750,"pu":86143413366,"b":[["46.741","0"]],"a":[["46.754","740"],["46.757","0"],["46.790","0"]]}}
1618677486.6784809: {"stream":"bchusd_210625@depth@100ms","data":{"e":"depthUpdate","E":1618677486626,"T":1618677486620,"s":"BCHUSD_210625","ps":"BCHUSD","U":86143413623,"u":86143414277,"pu":86143413430,"b":[["1120.24","0"],["1121.25","190"],["1121.30","0"],["1121.40","1665"],["1124.52","0"],["1126.69","0"],["1127.05","1162"],["1127.06","244"],["1128.12","35"],["1128.54","0"]],"a":[["1137.01","0"],["1137.43","1427"],["1140.49","0"]]}}
1618677486.691029: {"stream":"linkusd_210625@depth@100ms","data":{"e":"depthUpdate","E":1618677486638,"T":1618677486629,"s":"LINKUSD_210625","ps":"LINKUSD","U":86143413676,"u":86143414363,"pu":86143413484,"b":[["43.589","301"],["43.757","21"],["43.759","28"]],"a":[["43.772","0"],["43.774","0"],["43.776","0"],["43.780","100"],["43.782","100"],["43.784","100"],["43.795","50"],["43.805","0"],["43.829","0"],["43.832","707"],["43.840","0"],["43.955","180"]]}}
1618677486.6945732: {"stream":"ethusd_210924@depth@100ms","data":{"e":"depthUpdate","E":1618677486641,"T":1618677486611,"s":"ETHUSD_210924","ps":"ETHUSD","U":86143413697,"u":86143414191,"pu":86143413600,"b":[["2686.13","0"],["2686.73","8012"],["2689.50","0"],["2689.54","0"],["2689.58","674"],["2689.64","0"]],"a":[["2689.80","48"],["2702.91","0"],["2702.92","250"]]}}
1618677486.694816: {"stream":"btcusd_210924@depth@100ms","data":{"e":"depthUpdate","E":1618677486640,"T":1618677486627,"s":"BTCUSD_210924","ps":"BTCUSD","U":86143413686,"u":86143414346,"pu":86143413637,"b":[["68616.1","0"],["68632.0","841"]],"a":[["68632.1","120"],["68677.4","0"],["68688.2","716"],["68694.0","0"]]}}
1618677486.704154: {"stream":"xrpusd_210625@depth@100ms","data":{"e":"depthUpdate","E":1618677486650,"T":1618677486623,"s":"XRPUSD_210625","ps":"XRPUSD","U":86143413766,"u":86143414305,"pu":86143413699,"b":[["1.6837","4466"],["1.6906","0"],["1.6907","702"]],"a":[["1.6928","35"],["1.6929","162"],["1.6931","57"],["1.6935","80"],["1.6939","152"],["1.6956","1000"]]}}
1618677486.708749: {"stream":"btcusd_perp@depth@100ms","data":{"e":"depthUpdate","E":1618677486655,"T":1618677486642,"s":"BTCUSD_PERP","ps":"BTCUSD","U":86143413788,"u":86143414565,"pu":86143413659,"b":[["60471.0","0"],["60500.9","1100"],["60519.3","36"],["60539.3","0"],["60550.0","0"],["60550.2","20"],["60560.1","20"],["60569.0","0"],["60569.1","0"],["60573.1","1"],["60573.3","243"],["60573.5","122"],["60573.6","378"],["60581.9","0"],["60582.2","0"],["60583.9","0"],["60585.1","0"],["60585.8","0"],["60586.1","343"],["60587.0","126"],["60588.2","243"],["60589.3","0"],["60589.5","11687"],["60589.7","0"],["60590.3","0"],["60590.4","0"],["60590.6","0"],["60591.2","0"],["60591.4","0"],["60591.7","0"],["60592.1","0"],["60592.3","0"],["60592.4","0"],["60592.6","0"],["60592.8","0"],["60593.0","0"],["60593.2","0"],["60593.4","0"],["60593.5","0"],["60593.7","0"],["60593.9","0"],["60594.0","0"],["60594.1","0"],["60594.2","0"],["60594.3","0"],["60594.4","0"],["60594.6","0"],["60594.7","0"],["60594.8","0"],["60594.9","0"],["60595.0","0"],["60595.2","0"],["60595.4","0"],["60595.5","0"],["60595.7","0"],["60595.9","0"],["60596.1","0"],["60596.3","0"],["60596.4","0"],["60596.6","0"],["60596.8","0"],["60597.0","0"],["60597.2","0"],["60597.4","0"],["60597.5","0"],["60597.7","0"],["60597.9","0"],["60598.1","0"],["60598.3","0"],["60598.4","0"],["60598.6","0"]],"a":[["60589.6","1494"],["60590.1","0"],["60592.5","35"],["60593.9","1"],["60594.2","0"],["60596.2","0"],["60597.5","407"],["60599.7","0"],["60600.6","40"],["60601.4","0"],["60606.4","0"],["60607.8","172"],["60609.1","100"],["60610.5","0"],["60610.7","20"],["60611.8","40"],["60619.3","0"],["60620.6","263"],["60624.5","0"],["60632.2","0"],["60633.4","243"],["60634.2","1089"],["60635.4","251"],["60637.4","0"],["60639.4","0"],["60673.2","0"]]}}
1618677486.74015: {"stream":"ethusd_210625@depth@100ms","data":{"e":"depthUpdate","E":1618677486686,"T":1618677486652,"s":"ETHUSD_210625","ps":"ETHUSD","U":86143413992,"u":86143414650,"pu":86143413711,"b":[["2505.54","500"],["2510.10","0"],["2510.20","0"],["2510.30","0"],["2510.42","0"],["2510.44","503"],["2510.50","100"],["2510.60","100"],["2510.63","0"],["2510.64","299"],["2510.70","100"],["2510.86","2802"]],"a":[["2510.85","0"],["2511.08","121"],["2511.09","0"],["2511.31","0"],["2511.40","689"],["2511.41","1250"],["2511.44","0"],["2511.45","587"],["2511.53","0"],["2511.87","2804"],["2511.90","3633"],["2511.91","2306"],["2511.98","2030"],["2516.48","1000"]]}}
1618677486.7490292: {"stream":"egldusd_perp@depth@100ms","data":{"e":"depthUpdate","E":1618677486696,"T":1618677486684,"s":"EGLDUSD_PERP","ps":"EGLDUSD","U":86143414076,"u":86143414905,"pu":86143414066,"b":[["215.956","0"],["215.960","97"],["215.999","0"],["216.008","0"],["216.028","170"]],"a":[["216.278","0"],["216.307","483"],["216.308","24"],["216.309","0"]]}}
1618677486.770562: {"stream":"linkusd_210924@depth@100ms","data":{"e":"depthUpdate","E":1618677486717,"T":1618677486689,"s":"LINKUSD_210924","ps":"LINKUSD","U":86143414206,"u":86143415008,"pu":86143413568,"b":[["45.085","0"],["45.142","500"],["45.238","0"],["45.240","4326"],["45.241","284"]],"a":[["45.405","0"],["45.406","0"],["45.407","240"],["45.408","1138"],["45.427","2724"]]}}
1618677486.7794392: {"stream":"dotusd_210625@depth@100ms","data":{"e":"depthUpdate","E":1618677486727,"T":1618677486714,"s":"DOTUSD_210625","ps":"DOTUSD","U":86143414301,"u":86143415174,"pu":86143413750,"b":[["46.339","150"],["46.698","0"],["46.724","57"],["46.741","52"]],"a":[["46.789","0"],["46.797","84"],["46.799","192"],["46.868","0"],["46.931","1823"]]}}
1618677486.7969651: {"stream":"ethusd_210924@depth@100ms","data":{"e":"depthUpdate","E":1618677486743,"T":1618677486734,"s":"ETHUSD_210924","ps":"ETHUSD","U":86143414492,"u":86143415322,"pu":86143414191,"b":[["2687.96","0"],["2688.71","500"],["2689.37","1000"],["2689.54","0"],["2689.63","725"],["2689.79","339"]],"a":[["2689.80","2597"]]}}
1618677486.797548: {"stream":"linkusd_210625@depth@100ms","data":{"e":"depthUpdate","E":1618677486746,"T":1618677486712,"s":"LINKUSD_210625","ps":"LINKUSD","U":86143414577,"u":86143415164,"pu":86143414363,"b":[["43.580","180"]],"a":[["43.781","50"],["43.795","0"]]}}
1618677486.802222: {"stream":"bchusd_210625@depth@100ms","data":{"e":"depthUpdate","E":1618677486749,"T":1618677486734,"s":"BCHUSD_210625","ps":"BCHUSD","U":86143414599,"u":86143415323,"pu":86143414277,"b":[["1121.25","0"],["1123.17","211"],["1125.69","1671"],["1128.12","0"],["1128.54","35"]],"a":[["1140.45","190"]]}}
1618677486.8080509: {"stream":"xrpusd_210625@depth@100ms","data":{"e":"depthUpdate","E":1618677486754,"T":1618677486749,"s":"XRPUSD_210625","ps":"XRPUSD","U":86143414643,"u":86143415395,"pu":86143414305,"b":[["1.6867","12"],["1.6880","0"],["1.6881","187"],["1.6908","0"],["1.6910","128"],["1.6911","45"]],"a":[["1.6927","45"],["1.6928","0"],["1.6929","12"],["1.6930","50"],["1.6931","12"],["1.6961","175"],["1.6967","4129"],["1.7039","80"]]}}
1618677486.8083332: {"stream":"btcusd_210924@depth@100ms","data":{"e":"depthUpdate","E":1618677486753,"T":1618677486715,"s":"BTCUSD_210924","ps":"BTCUSD","U":86143414632,"u":86143415183,"pu":86143414346,"b":[["68624.2","0"],["68631.1","0"],["68632.0","841"]],"a":[["68677.3","0"],["68688.1","223"],["68693.9","0"]]}}
1618677486.8085032: {"stream":"btcusd_perp@depth@100ms","data":{"e":"depthUpdate","E":1618677486755,"T":1618677486745,"s":"BTCUSD_PERP","ps":"BTCUSD","U":86143414566,"u":86143415375,"pu":86143414565,"b":[["54530.6","1"],["60400.0","59"],["60470.2","0"],["60489.4","2450"],["60569.3","0"],["60570.6","1600"],["60571.7","243"],["60571.8","122"],["60573.3","0"],["60573.5","0"],["60573.8","0"],["60574.7","0"],["60577.0","0"],["60578.8","0"],["60580.0","136"],["60580.7","0"],["60583.3","0"],["60583.7","32"],["60584.0","0"],["60584.5","243"],["60586.1","100"],["60586.3","30"],["60586.5","243"],["60586.6","100"],["60587.0","96"],["60588.2","0"],["60589.7","0"],["60590.1","0"],["60590.3","0"],["60590.4","0"],["60590.6","0"],["60590.8","0"],["60591.0","0"],["60591.2","0"],["60591.4","0"],["60591.5","0"],["60591.7","0"],["60591.9","0"],["60592.1","0"],["60592.3","0"],["60592.4","0"],["60592.6","0"],["60592.8","0"],["60593.0","0"],["60593.2","0"],["60593.4","0"],["60593.5","0"],["60593.7","0"],["60593.9","0"],["60594.0","0"],["60594.1","0"],["60594.2","0"],["60594.3","0"],["60594.4","0"],["60594.6","0"],["60594.7","0"],["60594.8","0"],["60594.9","0"],["60595.0","0"],["60595.2","0"],["60595.4","0"],["60595.5","0"],["60595.7","0"],["60595.9","0"],["60596.1","0"],["60596.3","0"],["60596.4","0"],["60596.6","0"],["60596.8","0"],["60597.0","0"],["60597.2","0"],["60597.4","0"],["60597.5","0"],["60597.7","0"],["60597.9","0"],["60598.1","0"],["60598.3","0"],["60598.4","0"],["60598.6","0"]],"a":[["60589.6","1394"],["60589.8","30"],["60590.3","0"],["60592.5","5"],["60593.1","0"],["60595.0","0"],["60597.5","407"],["60598.4","200"],["60599.9","11"],["60600.2","0"],["60600.7","0"],["60600.8","0"],["60607.8","50"],["60608.1","122"],["60610.9","0"],["60611.7","15"],["60620.6","20"],["60620.9","243"],["60623.6","0"],["60624.4","0"],["60633.4","0"],["60633.7","243"],["60635.4","8"],["60635.7","243"],["60636.5","0"],["60637.2","0"],["60638.5","1225"],["60639.2","0"],["60640.0","586"],["60680.5","100"],["60687.0","2450"]]}}
1618677486.8385012: {"stream":"ethusd_210625@depth@100ms","data":{"e":"depthUpdate","E":1618677486787,"T":1618677486779,"s":"ETHUSD_210625","ps":"ETHUSD","U":86143414902,"u":86143415571,"pu":86143414650,"b":[["2507.82","391"],["2508.27","1073"],["2508.33","1071"]],"a":[["2510.85","0"],["2511.38","2804"],["2511.43","2306"],["2511.52","1073"],["2511.59","1746"],["2511.87","0"],["2511.90","839"],["2511.91","0"],["2511.98","0"],["2513.49","6541"],["2513.96","0"]]}}
1618677486.870242: {"stream":"egldusd_perp@depth@100ms","data":{"e":"depthUpdate","E":1618677486817,"T":1618677486790,"s":"EGLDUSD_PERP","ps":"EGLDUSD","U":86143415166,"u":86143415614,"pu":86143414905,"b":[["215.960","0"],["215.970","0"],["215.984","97"],["216.038","54"]],"a":[["216.057","0"],["216.135","16"],["216.305","483"],["216.306","10"],["216.307","0"],["216.308","0"]]}}
1618677486.906931: {"stream":"ethusd_210924@depth@100ms","data":{"e":"depthUpdate","E":1618677486855,"T":1618677486815,"s":"ETHUSD_210924","ps":"ETHUSD","U":86143415404,"u":86143415732,"pu":86143415322,"b":[["2689.33","1000"],["2689.37","0"],["2689.63","660"],["2689.64","204"]],"a":[["2697.49","5603"],["2697.72","0"]]}}
1618677486.907532: {"stream":"xrpusd_210625@depth@100ms","data":{"e":"depthUpdate","E":1618677486855,"T":1618677486847,"s":"XRPUSD_210625","ps":"XRPUSD","U":86143415400,"u":86143415958,"pu":86143415395,"b":[],"a":[["1.6927","45"],["1.6929","162"],["1.6930","0"],["1.6939","12"],["1.6940","0"],["1.6955","212"]]}}
1618677486.907656: {"stream":"bchusd_210625@depth@100ms","data":{"e":"depthUpdate","E":1618677486855,"T":1618677486834,"s":"BCHUSD_210625","ps":"BCHUSD","U":86143415399,"u":86143415818,"pu":86143415323,"b":[["1116.99","400"],["1117.23","0"],["1117.79","0"],["1121.18","0"],["1122.19","360"],["1125.11","173"],["1125.16","427"],["1125.40","0"],["1125.97","0"],["1127.05","0"],["1127.06","0"],["1127.07","1060"],["1127.08","223"],["1128.12","35"],["1128.48","13"],["1128.54","27"]],"a":[]}}
1618677486.9154649: {"stream":"btcusd_perp@depth@100ms","data":{"e":"depthUpdate","E":1618677486862,"T":1618677486847,"s":"BTCUSD_PERP","ps":"BTCUSD","U":86143415419,"u":86143415974,"pu":86143415375,"b":[["60500.0","1167"],["60571.7","243"],["60571.8","122"],["60574.8","485"],["60575.2","200"],["60575.4","545"],["60580.8","75"],["60581.6","25"],["60582.3","124"],["60589.7","0"],["60590.1","0"],["60590.3","0"],["60590.4","0"],["60590.6","0"],["60590.8","0"],["60591.0","0"],["60591.2","0"],["60591.4","0"],["60591.5","0"],["60591.7","0"],["60591.9","0"],["60592.1","0"],["60592.3","0"],["60592.4","0"],["60592.6","0"],["60592.8","0"],["60593.0","0"],["60593.2","0"],["60593.4","0"],["60593.5","0"],["60593.7","0"],["60593.9","0"],["60594.0","0"],["60594.1","0"],["60594.2","0"],["60594.3","0"],["60594.4","0"],["60594.6","0"],["60594.7","0"],["60594.8","0"],["60594.9","0"],["60595.0","0"],["60595.2","0"],["60595.4","0"],["60595.5","0"],["60595.7","0"],["60595.9","0"],["60596.1","0"],["60596.3","0"],["60596.4","0"],["60596.6","0"],["60596.8","0"],["60597.0","0"],["60597.2","0"],["60597.4","0"],["60597.5","0"],["60597.7","0"],["60597.9","0"],["60598.1","0"],["60598.3","0"],["60598.4","0"],["60598.6","0"]],"a":[["60589.6","1448"],["60603.0","10"],["60603.5","25"],["60603.9","428"],["60673.2","1"]]}}
1618677486.9159381: {"stream":"dotusd_210625@depth@100ms","data":{"e":"depthUpdate","E":1618677486862,"T":1618677486838,"s":"DOTUSD_210625","ps":"DOTUSD","U":86143415473,"u":86143415828,"pu":86143415174,"b":[["46.741","0"]],"a":[["46.993","315"],["47.025","560"]]}}
1618677486.9462342: {"stream":"linkusd_210625@depth@100ms","data":{"e":"depthUpdate","E":1618677486894,"T":1618677486867,"s":"LINKUSD_210625","ps":"LINKUSD","U":86143415617,"u":86143416057,"pu":86143415164,"b":[],"a":[["43.781","0"],["43.805","0"],["43.813","50"]]}}
1618677486.949599: {"stream":"ethusd_210625@depth@100ms","data":{"e":"depthUpdate","E":1618677486897,"T":1618677486876,"s":"ETHUSD_210625","ps":"ETHUSD","U":86143415637,"u":86143416114,"pu":86143415571,"b":[["2503.74","0"],["2504.09","3437"],["2510.86","1777"]],"a":[["2510.85","0"],["2510.94","121"],["2511.08","0"],["2511.40","1335"],["2511.41","4044"],["2511.50","2030"]]}}
1618677486.971918: {"stream":"linkusd_210924@depth@100ms","data":{"e":"depthUpdate","E":1618677486919,"T":1618677486895,"s":"LINKUSD_210924","ps":"LINKUSD","U":86143415723,"u":86143416218,"pu":86143415008,"b":[["45.241","420"]],"a":[["45.434","0"],["45.451","4552"]]}}
1618677486.98558: {"stream":"egldusd_perp@depth@100ms","data":{"e":"depthUpdate","E":1618677486933,"T":1618677486904,"s":"EGLDUSD_PERP","ps":"EGLDUSD","U":86143415785,"u":86143416260,"pu":86143415614,"b":[["215.960","97"],["215.984","0"]],"a":[["216.303","462"],["216.304","5"],["216.305","0"],["216.306","0"],["216.726","1113"],["216.820","0"]]}}
1618677487.020247: {"stream":"btcusd_perp@depth@100ms","data":{"e":"depthUpdate","E":1618677486967,"T":1618677486961,"s":"BTCUSD_PERP","ps":"BTCUSD","U":86143416036,"u":86143416532,"pu":86143415974,"b":[["54530.6","0"],["59954.5","0"],["60571.5","0"],["60571.7","365"],["60571.8","0"],["60580.3","336"],["60582.4","30"],["60586.3","0"],["60589.7","0"]],"a":[["60589.6","2577"],["60589.8","0"],["60594.7","40"],["60595.8","151"],["60597.5","257"],["60600.6","0"],["60607.0","122"],["60608.1","0"],["60619.7","243"],["60620.9","0"],["60632.6","643"],["60633.7","0"],["60634.6","243"],["60635.7","0"]]}}
1618677487.0328279: {"stream":"btcusd_210924@depth@100ms","data":{"e":"depthUpdate","E":1618677486980,"T":1618677486941,"s":"BTCUSD_210924","ps":"BTCUSD","U":86143416116,"u":86143416438,"pu":86143415183,"b":[],"a":[["68632.1","120"],["68694.0","0"]]}}
1618677487.0521119: {"stream":"bchusd_210625@depth@100ms","data":{"e":"depthUpdate","E":1618677486957,"T":1618677486950,"s":"BCHUSD_210625","ps":"BCHUSD","U":86143416005,"u":86143416484,"pu":86143415818,"b":[["1128.12","0"],["1128.48","13"],["1128.54","0"],["1128.55","35"]],"a":[]}}
1618677487.052236: {"stream":"ethusd_210924@depth@100ms","data":{"e":"depthUpdate","E":1618677486963,"T":1618677486955,"s":"ETHUSD_210924","ps":"ETHUSD","U":86143416017,"u":86143416505,"pu":86143415732,"b":[["2686.74","1703"],["2687.46","0"],["2687.47","0"],["2689.33","0"],["2689.58","0"],["2689.63","0"],["2689.64","0"],["2689.65","0"],["2689.79","339"]],"a":[["2689.80","2477"]]}}
1618677487.0524049: {"stream":"xrpusd_210625@depth@100ms","data":{"e":"depthUpdate","E":1618677486976,"T":1618677486953,"s":"XRPUSD_210625","ps":"XRPUSD","U":86143416085,"u":86143416499,"pu":86143415958,"b":[],"a":[["1.6928","34"],["1.6972","2742"],["1.6973","570"],["1.6985","1200"]]}}
1618677487.052526: {"stream":"linkusd_210625@depth@100ms","data":{"e":"depthUpdate","E":1618677486994,"T":1618677486975,"s":"LINKUSD_210625","ps":"LINKUSD","U":86143416197,"u":86143416601,"pu":86143416057,"b":[["43.740","140"]],"a":[["43.776","13"],["43.777","0"],["43.795","50"],["43.805","0"],["43.813","0"],["43.816","88"],["43.857","0"],["43.955","0"]]}}
1618677487.052833: {"stream":"ethusd_210625@depth@100ms","data":{"e":"depthUpdate","E":1618677486999,"T":1618677486906,"s":"ETHUSD_210625","ps":"ETHUSD","U":86143416213,"u":86143416268,"pu":86143416114,"b":[["2504.09","0"],["2505.54","0"]],"a":[["2510.85","0"]]}}
1618677487.0952: {"stream":"linkusd_210924@depth@100ms","data":{"e":"depthUpdate","E":1618677487041,"T":1618677486936,"s":"LINKUSD_210924","ps":"LINKUSD","U":86143416414,"u":86143416420,"pu":86143416218,"b":[["45.241","521"]],"a":[["45.309","0"]]}}
1618677487.1007318: {"stream":"egldusd_perp@depth@100ms","data":{"e":"depthUpdate","E":1618677487047,"T":1618677487024,"s":"EGLDUSD_PERP","ps":"EGLDUSD","U":86143416456,"u":86143416872,"pu":86143416260,"b":[["215.947","80"]],"a":[["216.135","0"],["216.293","0"],["216.300","99"],["216.301","462"],["216.302","7"],["216.303","0"],["216.304","0"]]}}
1618677487.108382: {"stream":"dotusd_210625@depth@100ms","data":{"e":"depthUpdate","E":1618677487056,"T":1618677487048,"s":"DOTUSD_210625","ps":"DOTUSD","U":86143416493,"u":86143417038,"pu":86143415828,"b":[["46.741","0"]],"a":[["47.321","463"],["47.347","0"]]}}
1618677487.113735: {"stream":"bchusd_210625@depth@100ms","data":{"e":"depthUpdate","E":1618677487061,"T":1618677487044,"s":"BCHUSD_210625","ps":"BCHUSD","U":86143416513,"u":86143417016,"pu":86143416484,"b":[["1120.94","0"],["1125.16","286"],["1125.40","50"],["1125.97","0"],["1128.13","35"],["1128.14","9"],["1128.47","0"],["1128.48","0"],["1128.55","0"]],"a":[["1132.79","100"],["1137.43","0"],["1138.57","1560"]]}}
1618677487.1213639: {"stream":"ethusd_210924@depth@100ms","data":{"e":"depthUpdate","E":1618677487067,"T":1618677487057,"s":"ETHUSD_210924","ps":"ETHUSD","U":86143416536,"u":86143417097,"pu":86143416505,"b":[["2687.96","500"],["2688.71","0"],["2689.33","1000"],["2689.37","0"],["2689.59","660"]],"a":[["2689.80","2477"],["2690.23","0"]]}}
1618677487.124429: {"stream":"btcusd_perp@depth@100ms","data":{"e":"depthUpdate","E":1618677487071,"T":1618677487064,"s":"BTCUSD_PERP","ps":"BTCUSD","U":86143416552,"u":86143417168,"pu":86143416532,"b":[["60393.0","0"],["60491.2","1100"],["60500.9","0"],["60507.1","0"],["60571.2","0"],["60571.3","0"],["60571.7","0"],["60571.9","0"],["60572.1","32"],["60582.4","0"],["60584.0","0"],["60584.5","0"],["60584.7","0"],["60584.8","30"],["60586.0","0"],["60586.5","0"],["60586.7","0"],["60589.5","10967"],["60589.7","0"],["60592.4","0"]],"a":[["60595.8","1"],["60596.6","367"],["60597.5","257"],["60599.9","0"],["60607.0","0"],["60607.1","122"],["60610.2","90"],["60611.7","0"],["60616.1","60"],["60620.2","16"],["61117.5","100"]]}}
1618677487.135123: {"stream":"xrpusd_210625@depth@100ms","data":{"e":"depthUpdate","E":1618677487081,"T":1618677487076,"s":"XRPUSD_210625","ps":"XRPUSD","U":86143416608,"u":86143417244,"pu":86143416499,"b":[["1.6783","10214"]],"a":[["1.6925","198"],["1.6928","0"],["1.6929","12"],["1.6935","0"],["1.7039","0"],["1.7042","556"]]}}
1618677487.135335: {"stream":"btcusd_210924@depth@100ms","data":{"e":"depthUpdate","E":1618677487082,"T":1618677487066,"s":"BTCUSD_210924","ps":"BTCUSD","U":86143416613,"u":86143417183,"pu":86143416438,"b":[["68599.0","0"]],"a":[["68632.1","60"],["68680.9","0"],["68736.4","0"]]}}
1618677487.173692: {"stream":"ethusd_210625@depth@100ms","data":{"e":"depthUpdate","E":1618677487120,"T":1618677487116,"s":"ETHUSD_210625","ps":"ETHUSD","U":86143416832,"u":86143417497,"pu":86143416268,"b":[["2505.11","0"],["2505.60","500"],["2510.86","2677"]],"a":[["2510.85","0"],["2510.94","0"],["2511.09","121"],["2516.74","189"],["2516.94","0"]]}}
1618677487.208574: {"stream":"linkusd_210625@depth@100ms","data":{"e":"depthUpdate","E":1618677487155,"T":1618677487141,"s":"LINKUSD_210625","ps":"LINKUSD","U":86143417052,"u":86143417641,"pu":86143416601,"b":[],"a":[["43.766","0"],["43.780","0"],["43.782","0"],["43.784","50"],["43.790","100"],["43.792","100"],["43.794","100"],["43.795","0"],["43.797","92"],["43.959","180"]]}}
1618677487.213922: {"stream":"egldusd_perp@depth@100ms","data":{"e":"depthUpdate","E":1618677487160,"T":1618677487109,"s":"EGLDUSD_PERP","ps":"EGLDUSD","U":86143417084,"u":86143417444,"pu":86143416872,"b":[],"a":[["216.053","33"],["216.077","0"],["216.145","0"],["216.299","17"],["216.302","0"],["216.725","116"]]}}
1618677487.216042: {"stream":"dotusd_210625@depth@100ms","data":{"e":"depthUpdate","E":1618677487164,"T":1618677487151,"s":"DOTUSD_210625","ps":"DOTUSD","U":86143417149,"u":86143417713,"pu":86143417038,"b":[["46.521","0"],["46.555","1420"],["46.741","54"]],"a":[["46.754","540"],["46.796","200"],["46.799","0"]]}}
1618677487.2212548: {"stream":"linkusd_210924@depth@100ms","data":{"e":"depthUpdate","E":1618677487169,"T":1618677487164,"s":"LINKUSD_210924","ps":"LINKUSD","U":86143417173,"u":86143417794,"pu":86143416420,"b":[["44.736","0"],["45.146","94"]],"a":[["45.397","0"],["45.410","0"],["45.427","448"],["45.450","2601"],["46.789","0"]]}}
1618677487.221896: {"stream":"ethusd_210924@depth@100ms","data":{"e":"depthUpdate","E":1618677487170,"T":1618677487164,"s":"ETHUSD_210924","ps":"ETHUSD","U":86143417178,"u":86143417800,"pu":86143417097,"b":[["2666.93","0"],["2667.21","250"],["2686.13","3717"],["2687.20","0"],["2687.49","250"],["2689.33","0"],["2689.59","0"],["2689.63","0"],["2689.65","0"],["2689.79","339"]],"a":[["2689.80","48"]]}}
1618677487.225523: {"stream":"btcusd_perp@depth@100ms","data":{"e":"depthUpdate","E":1618677487173,"T":1618677487150,"s":"BTCUSD_PERP","ps":"BTCUSD","U":86143417193,"u":86143417701,"pu":86143417168,"b":[["60490.6","1100"],["60491.2","0"],["60557.3","0"],["60571.2","243"],["60571.3","0"],["60571.4","122"],["60578.8","0"],["60581.2","0"],["60581.4","30"],["60584.0","243"],["60584.3","0"],["60584.8","0"],["60586.0","243"],["60589.5","10612"],["60589.7","0"],["60592.4","0"]],"a":[["60589.6","2573"],["60596.6","517"],["60610.7","70"],["60611.1","10"],["60616.9","0"]]}}
1618677487.232672: {"stream":"bchusd_210625@depth@100ms","data":{"e":"depthUpdate","E":1618677487181,"T":1618677487138,"s":"BCHUSD_210625","ps":"BCHUSD","U":86143417247,"u":86143417624,"pu":86143417016,"b":[["1119.45","0"],["1119.96","0"],["1120.30","0"],["1120.91","0"],["1121.03","173"],["1127.05","124"],["1128.13","0"],["1128.14","0"],["1128.54","13"]],"a":[["1131.74","0"]]}}
1618677487.235001: {"stream":"xrpusd_210625@depth@100ms","data":{"e":"depthUpdate","E":1618677487183,"T":1618677487160,"s":"XRPUSD_210625","ps":"XRPUSD","U":86143417253,"u":86143417772,"pu":86143417244,"b":[["1.6897","0"],["1.6902","100"],["1.6911","0"]],"a":[["1.6927","0"],["1.6928","0"],["1.6934","0"],["1.6936","45"],["1.6945","348"],["1.6946","1370"],["1.7039","80"]]}}
1618677487.283204: {"stream":"btcusd_210924@depth@100ms","data":{"e":"depthUpdate","E":1618677487231,"T":1618677487189,"s":"BTCUSD_210924","ps":"BTCUSD","U":86143417544,"u":86143417969,"pu":86143417183,"b":[["68624.2","0"],["68631.1","0"],["68632.0","841"]],"a":[["68632.1","60"]]}}
1618677487.285716: {"stream":"ethusd_210625@depth@100ms","data":{"e":"depthUpdate","E":1618677487233,"T":1618677487129,"s":"ETHUSD_210625","ps":"ETHUSD","U":86143417558,"u":86143417567,"pu":86143417497,"b":[["2503.18","3186"],["2506.82","1069"]],"a":[]}}
1618677487.327034: {"stream":"btcusd_perp@depth@100ms","data":{"e":"depthUpdate","E":1618677487274,"T":1618677487235,"s":"BTCUSD_PERP","ps":"BTCUSD","U":86143417850,"u":86143418247,"pu":86143417701,"b":[["60490.6","1100"],["60539.0","1933"],["60540.2","0"],["60557.4","363"],["60561.4","0"],["60571.4","0"],["60571.5","122"],["60581.4","0"],["60583.3","30"],["60583.7","0"],["60584.1","6"],["60589.7","0"]],"a":[["60596.3","404"],["60596.6","367"],["60607.1","0"],["60608.0","122"],["60619.7","0"],["60620.8","243"],["60632.6","400"],["60633.6","243"],["60634.6","0"],["60635.6","243"],["60636.1","9"],["60636.4","1407"]]}}
1618677487.331411: {"stream":"dotusd_210625@depth@100ms","data":{"e":"depthUpdate","E":1618677487276,"T":1618677487259,"s":"DOTUSD_210625","ps":"DOTUSD","U":86143417864,"u":86143418448,"pu":86143417713,"b":[["46.753","590"]],"a":[["46.795","284"],["46.796","0"],["46.797","0"],["46.798","0"],["46.807","0"],["47.079","0"],["47.256","0"]]}}
1618677487.3316321: {"stream":"ethusd_210924@depth@100ms","data":{"e":"depthUpdate","E":1618677487276,"T":1618677487267,"s":"ETHUSD_210924","ps":"ETHUSD","U":86143417854,"u":86143418508,"pu":86143417800,"b":[["2686.13","0"],["2687.40","3717"],["2689.65","1000"],["2689.79","999"]],"a":[["2689.80","2688"]]}}
1618677487.3345861: {"stream":"egldusd_perp@depth@100ms","data":{"e":"depthUpdate","E":1618677487282,"T":1618677487240,"s":"EGLDUSD_PERP","ps":"EGLDUSD","U":86143417891,"u":86143418286,"pu":86143417444,"b":[],"a":[["216.146","97"],["216.160","16"],["216.170","0"],["216.265","25"],["216.297","101"],["216.298","462"],["216.299","0"],["216.300","0"],["216.301","0"],["216.725","233"]]}}
1618677487.346751: {"stream":"linkusd_210924@depth@100ms","data":{"e":"depthUpdate","E":1618677487294,"T":1618677487254,"s":"LINKUSD_210924","ps":"LINKUSD","U":86143417984,"u":86143418407,"pu":86143417794,"b":[],"a":[["45.435","2601"],["45.450","0"],["46.841","400"]]}}
1618677487.347358: {"stream":"bchusd_210625@depth@100ms","data":{"e":"depthUpdate","E":1618677487294,"T":1618677487283,"s":"BCHUSD_210625","ps":"BCHUSD","U":86143417978,"u":86143418611,"pu":86143417624,"b":[["1127.07","0"],["1127.08","0"],["1127.19","1173"],["1127.21","285"],["1128.12","35"],["1128.55","0"],["1128.57","64"]],"a":[]}}
1618677487.364842: {"stream":"linkusd_210625@depth@100ms","data":{"e":"depthUpdate","E":1618677487312,"T":1618677487292,"s":"LINKUSD_210625","ps":"LINKUSD","U":86143418089,"u":86143418671,"pu":86143417641,"b":[],"a":[["43.778","0"],["43.784","0"],["43.790","101"],["43.793","50"]]}}
1618677487.367848: {"stream":"xrpusd_210625@depth@100ms","data":{"e":"depthUpdate","E":1618677487316,"T":1618677487278,"s":"XRPUSD_210625","ps":"XRPUSD","U":86143418119,"u":86143418587,"pu":86143417772,"b":[["1.6908","45"]],"a":[["1.6928","45"],["1.6936","0"]]}}
1618677487.4287932: {"stream":"btcusd_210924@depth@100ms","data":{"e":"depthUpdate","E":1618677487377,"T":1618677487371,"s":"BTCUSD_210924","ps":"BTCUSD","U":86143418545,"u":86143419186,"pu":86143417969,"b":[],"a":[["68632.1","60"],["68679.4","1360"],["68873.9","0"],["68874.1","11"],["68929.0","0"]]}}
1618677487.428989: {"stream":"dotusd_210625@depth@100ms","data":{"e":"depthUpdate","E":1618677487377,"T":1618677487367,"s":"DOTUSD_210625","ps":"DOTUSD","U":86143418548,"u":86143419160,"pu":86143418448,"b":[["46.711","626"],["46.754","124"],["46.757","0"]],"a":[["46.754","0"],["46.758","0"],["46.792","256"],["46.794","284"],["46.795","0"],["46.799","200"],["46.807","0"],["46.808","12"],["46.931","0"],["46.964","1200"],["47.089","0"],["47.222","2790"]]}}
1618677487.429493: {"stream":"btcusd_perp@depth@100ms","data":{"e":"depthUpdate","E":1618677487379,"T":1618677487373,"s":"BTCUSD_PERP","ps":"BTCUSD","U":86143418569,"u":86143419207,"pu":86143418247,"b":[["57854.9","0"],["59851.8","0"],["60573.6","0"],["60582.5","30"],["60583.3","0"],["60585.5","0"],["60589.5","11317"],["60589.7","0"],["60592.4","0"],["60592.6","0"]],"a":[["60589.6","1412"],["60594.7","0"],["60596.3","254"],["60596.7","160"],["60599.7","40"]]}}
1618677487.43838: {"stream":"ethusd_210924@depth@100ms","data":{"e":"depthUpdate","E":1618677487384,"T":1618677487379,"s":"ETHUSD_210924","ps":"ETHUSD","U":86143418591,"u":86143419262,"pu":86143418508,"b":[["2667.40","0"],["2680.02","0"],["2687.41","791"],["2687.96","0"],["2688.71","500"],["2689.37","1000"],["2689.65","0"]],"a":[["2689.80","2688"]]}}
1618677487.450182: {"stream":"egldusd_perp@depth@100ms","data":{"e":"depthUpdate","E":1618677487397,"T":1618677487322,"s":"EGLDUSD_PERP","ps":"EGLDUSD","U":86143418679,"u":86143418838,"pu":86143418286,"b":[],"a":[["216.146","0"],["216.160","0"],["216.165","97"]]}}
1618677487.450324: {"stream":"linkusd_210924@depth@100ms","data":{"e":"depthUpdate","E":1618677487396,"T":1618677487314,"s":"LINKUSD_210924","ps":"LINKUSD","U":86143418663,"u":86143418785,"pu":86143418407,"b":[],"a":[["45.369","0"],["45.384","0"]]}}
1618677487.456425: {"stream":"bchusd_210625@depth@100ms","data":{"e":"depthUpdate","E":1618677487402,"T":1618677487380,"s":"BCHUSD_210625","ps":"BCHUSD","U":86143418705,"u":86143419269,"pu":86143418611,"b":[["1128.12","0"],["1128.13","35"],["1128.54","13"]],"a":[["1133.44","0"]]}}
1618677487.473511: {"stream":"xrpusd_210625@depth@100ms","data":{"e":"depthUpdate","E":1618677487420,"T":1618677487410,"s":"XRPUSD_210625","ps":"XRPUSD","U":86143418787,"u":86143419430,"pu":86143418587,"b":[["1.6785","250"],["1.6789","250"],["1.6792","750"],["1.6798","250"],["1.6837","4466"],["1.6907","693"],["1.6908","45"]],"a":[]}}
1618677487.4736671: {"stream":"ethusd_210625@depth@100ms","data":{"e":"depthUpdate","E":1618677487420,"T":1618677487414,"s":"ETHUSD_210625","ps":"ETHUSD","U":86143418793,"u":86143419452,"pu":86143417567,"b":[["2503.18","0"],["2503.40","3186"],["2505.85","5602"],["2506.55","587"],["2507.16","0"],["2507.26","391"],["2507.56","0"],["2508.07","0"],["2508.12","0"],["2510.86","1777"]],"a":[["2510.85","0"],["2511.09","0"],["2511.31","121"],["2511.38","0"],["2511.40","689"],["2511.41","1250"],["2511.43","0"],["2511.50","0"],["2511.68","0"],["2511.80","1529"],["2511.87","2804"],["2511.90","3633"],["2511.91","2306"],["2511.98","2030"],["2512.14","587"],["2512.46","0"],["2512.55","0"],["2512.68","0"],["2512.75","0"],["2523.06","2434"]]}}
1618677487.495904: {"stream":"linkusd_210625@depth@100ms","data":{"e":"depthUpdate","E":1618677487443,"T":1618677487338,"s":"LINKUSD_210625","ps":"LINKUSD","U":86143418937,"u":86143418937,"pu":86143418671,"b":[],"a":[["43.793","0"]]}}
1618677487.531316: {"stream":"btcusd_210924@depth@100ms","data":{"e":"depthUpdate","E":1618677487479,"T":1618677487473,"s":"BTCUSD_210924","ps":"BTCUSD","U":86143419218,"u":86143419749,"pu":86143419186,"b":[],"a":[["68632.1","125"],["68929.4","26"]]}}
1618677487.53179: {"stream":"dotusd_210625@depth@100ms","data":{"e":"depthUpdate","E":1618677487480,"T":1618677487469,"s":"DOTUSD_210625","ps":"DOTUSD","U":86143419231,"u":86143419732,"pu":86143419160,"b":[["46.293","0"],["46.340","38"],["46.693","185"],["46.694","14"],["46.724","0"],["46.742","63"]],"a":[["46.784","256"],["46.786","540"],["46.788","256"],["46.789","200"],["46.790","540"],["46.791","84"],["46.792","0"],["46.794","0"],["46.797","192"],["46.798","50"],["46.799","0"],["46.807","0"],["46.826","200"],["46.896","0"],["46.960","612"],["46.969","40"],["47.079","50"]]}}
1618677487.5372548: {"stream":"btcusd_perp@depth@100ms","data":{"e":"depthUpdate","E":1618677487485,"T":1618677487476,"s":"BTCUSD_PERP","ps":"BTCUSD","U":86143419274,"u":86143419776,"pu":86143419207,"b":[["60560.0","502"],["60560.9","0"],["60561.0","363"],["60561.5","545"],["60568.4","243"],["60568.5","122"],["60570.0","0"],["60570.2","0"],["60571.2","0"],["60571.5","0"],["60575.4","0"],["60581.2","243"],["60582.5","0"],["60582.8","1"],["60583.2","243"],["60584.0","0"],["60584.7","30"],["60584.8","0"],["60586.0","0"],["60589.5","10812"],["60589.7","0"]],"a":[["60589.6","2382"],["60591.8","30"],["60593.9","151"],["60596.7","10"],["60601.4","50"],["60606.6","1618"],["60606.9","0"],["60608.0","0"],["60619.7","243"],["60620.8","0"],["60632.5","1152"],["60633.6","0"],["60634.5","288"],["60635.6","0"]]}}
1618677487.543995: {"stream":"ethusd_210924@depth@100ms","data":{"e":"depthUpdate","E":1618677487491,"T":1618677487468,"s":"ETHUSD_210924","ps":"ETHUSD","U":86143419331,"u":86143419721,"pu":86143419262,"b":[["2680.52","250"],["2689.33","1000"],["2689.37","0"],["2689.63","660"],["2689.79","339"]],"a":[["2702.92","0"]]}}
1618677487.5601852: {"stream":"bchusd_210625@depth@100ms","data":{"e":"depthUpdate","E":1618677487507,"T":1618677487476,"s":"BCHUSD_210625","ps":"BCHUSD","U":86143419408,"u":86143419778,"pu":86143419269,"b":[["1127.19","89"],["1127.21","0"],["1127.22","1084"],["1127.23","229"],["1128.13","0"],["1128.54","0"],["1128.58","0"]],"a":[]}}
1618677487.575424: {"stream":"xrpusd_210625@depth@100ms","data":{"e":"depthUpdate","E":1618677487523,"T":1618677487510,"s":"XRPUSD_210625","ps":"XRPUSD","U":86143419496,"u":86143420034,"pu":86143419430,"b":[["1.6804","295"],["1.6809","0"],["1.6897","148"],["1.6902","0"],["1.6903","0"],["1.6907","0"],["1.6908","0"],["1.6911","45"]],"a":[["1.6923","150"],["1.6924","45"],["1.6925","48"],["1.6928","0"]]}}
1618677487.57571: {"stream":"ethusd_210625@depth@100ms","data":{"e":"depthUpdate","E":1618677487523,"T":1618677487517,"s":"ETHUSD_210625","ps":"ETHUSD","U":86143419488,"u":86143420084,"pu":86143419452,"b":[["2506.15","1506"],["2507.25","963"],["2507.32","1133"],["2507.49","1354"],["2507.85","616"],["2507.87","1194"],["2510.10","100"],["2510.20","100"],["2510.30","100"],["2510.50","0"],["2510.60","0"],["2510.70","0"]],"a":[["2510.85","0"],["2510.94","121"],["2511.05","1354"],["2511.08","0"],["2511.09","0"],["2511.31","0"],["2511.37","616"],["2511.50","1133"],["2511.81","963"],["2511.92","1194"],["2511.96","1506"]]}}
1618677487.58449: {"stream":"egldusd_perp@depth@100ms","data":{"e":"depthUpdate","E":1618677487530,"T":1618677487510,"s":"EGLDUSD_PERP","ps":"EGLDUSD","U":86143419508,"u":86143420029,"pu":86143418838,"b":[["216.028","0"],["216.038","0"],["216.048","170"]],"a":[["216.155","16"],["216.296","462"],["216.298","0"]]}}
1618677487.610207: {"stream":"linkusd_210924@depth@100ms","data":{"e":"depthUpdate","E":1618677487556,"T":1618677487524,"s":"LINKUSD_210924","ps":"LINKUSD","U":86143419647,"u":86143420124,"pu":86143418785,"b":[["45.242","0"],["45.243","0"],["45.245","0"],["45.251","100"],["45.252","405"],["45.253","103"]],"a":[["45.309","12"],["45.402","76"],["45.403","361"],["45.407","0"],["45.408","0"],["45.418","1258"]]}}
1618677487.634368: {"stream":"btcusd_210924@depth@100ms","data":{"e":"depthUpdate","E":1618677487581,"T":1618677487572,"s":"BTCUSD_210924","ps":"BTCUSD","U":86143419801,"u":86143420572,"pu":86143419749,"b":[],"a":[["68632.1","125"],["68677.3","145"],["68677.4","665"],["68679.4","0"],["68688.1","0"],["68688.2","0"]]}}
1618677487.643841: {"stream":"dotusd_210625@depth@100ms","data":{"e":"depthUpdate","E":1618677487589,"T":1618677487580,"s":"DOTUSD_210625","ps":"DOTUSD","U":86143419852,"u":86143420628,"pu":86143419732,"b":[["46.724","1186"],["46.725","249"],["46.740","0"],["46.741","0"],["46.742","0"]],"a":[["46.782","540"],["46.783","84"],["46.788","0"],["46.789","0"],["46.790","0"],["46.791","0"],["46.797","392"],["46.825","0"],["46.826","0"],["46.835","0"],["46.963","1732"],["46.969","0"]]}}
1618677487.645644: {"stream":"btcusd_perp@depth@100ms","data":{"e":"depthUpdate","E":1618677487592,"T":1618677487583,"s":"BTCUSD_PERP","ps":"BTCUSD","U":86143419859,"u":86143420658,"pu":86143419776,"b":[["60519.3","0"],["60568.3","0"],["60568.4","0"],["60568.5","0"],["60568.7","0"],["60569.7","122"],["60575.4","545"],["60579.6","25"],["60579.8","0"],["60581.2","0"],["60581.6","0"],["60582.0","816"],["60583.2","0"],["60583.7","32"],["60584.1","0"],["60584.4","243"],["60589.7","0"],["60590.1","0"],["60590.3","0"],["60590.4","0"],["60590.6","0"],["60590.8","0"],["60591.0","0"],["60591.2","0"],["60591.4","0"],["60591.5","0"],["60591.7","0"],["60591.9","0"],["60592.1","0"],["60592.3","0"],["60592.4","0"],["60592.6","0"],["60592.8","0"],["60593.0","0"],["60593.2","0"],["60593.4","0"],["60593.5","0"],["60593.7","0"],["60593.9","0"],["60594.0","0"],["60594.1","0"],["60594.2","0"],["60594.3","0"],["60594.4","0"],["60594.6","0"],["60594.7","0"],["60594.8","0"],["60594.9","0"],["60595.0","0"],["60595.2","0"],["60595.4","0"],["60595.5","0"],["60595.7","0"],["60595.9","0"],["60596.1","0"],["60596.3","0"],["60596.4","0"],["60596.6","0"],["60596.8","0"],["60597.0","0"],["60597.2","0"],["60597.4","0"],["60597.5","0"],["60597.7","0"],["60597.9","0"],["60598.1","0"],["60598.3","0"],["60598.4","0"],["60598.6","0"]],"a":[["60591.8","0"],["60593.9","1"],["60594.5","30"],["60595.8","151"],["60596.3","254"],["60601.4","0"],["60601.5","32"],["60603.5","0"],["60604.1","0"],["60606.3","1"],["60606.6","1496"],["60609.5","0"],["60610.8","0"],["60619.7","0"],["60622.3","0"],["60623.6","243"],["60632.5","909"],["60634.5","45"],["60635.1","0"],["60636.4","1650"],["60637.1","0"],["60638.4","243"]]}}
1618677487.647491: {"stream":"ethusd_210924@depth@100ms","data":{"e":"depthUpdate","E":1618677487594,"T":1618677487502,"s":"ETHUSD_210924","ps":"ETHUSD","U":86143419889,"u":86143419980,"pu":86143419721,"b":[["2667.95","480"]],"a":[["2697.43","5714"],["2697.49","0"]]}}
1618677487.667766: {"stream":"bchusd_210625@depth@100ms","data":{"e":"depthUpdate","E":1618677487616,"T":1618677487592,"s":"BCHUSD_210625","ps":"BCHUSD","U":86143420038,"u":86143420703,"pu":86143419778,"b":[["1120.96","332"],["1125.40","0"],["1126.01","50"],["1128.12","35"]],"a":[["1129.75","739"],["1129.76","103"],["1129.79","0"],["1129.80","0"],["1132.03","0"],["1140.44","0"],["1140.45","0"]]}}
1618677487.6864572: {"stream":"xrpusd_210625@depth@100ms","data":{"e":"depthUpdate","E":1618677487634,"T":1618677487620,"s":"XRPUSD_210625","ps":"XRPUSD","U":86143420185,"u":86143420859,"pu":86143420034,"b":[["1.6866","0"],["1.6900","128"]],"a":[["1.6924","0"],["1.6928","0"],["1.6947","1630"],["1.6955","0"],["1.6956","0"],["1.6970","2723"],["1.6972","242"]]}}
1618677487.686646: {"stream":"egldusd_perp@depth@100ms","data":{"e":"depthUpdate","E":1618677487634,"T":1618677487623,"s":"EGLDUSD_PERP","ps":"EGLDUSD","U":86143420174,"u":86143420890,"pu":86143420029,"b":[["215.859","0"],["215.961","391"]],"a":[["216.053","0"],["216.067","0"],["216.102","33"],["216.297","0"]]}}
1618677487.7065542: {"stream":"ethusd_210625@depth@100ms","data":{"e":"depthUpdate","E":1618677487655,"T":1618677487554,"s":"ETHUSD_210625","ps":"ETHUSD","U":86143420394,"u":86143420469,"pu":86143420084,"b":[["2503.40","0"],["2503.74","3066"],["2506.67","4121"]],"a":[["2510.85","0"],["2513.28","1735"]]}}
1618677487.730238: {"stream":"linkusd_210924@depth@100ms","data":{"e":"depthUpdate","E":1618677487677,"T":1618677487663,"s":"LINKUSD_210924","ps":"LINKUSD","U":86143420571,"u":86143421127,"pu":86143420124,"b":[["45.211","0"],["45.212","0"]],"a":[["45.309","0"],["45.402","0"],["45.403","0"],["45.416","1258"],["45.417","264"],["45.418","0"]]}}
1618677487.74635: {"stream":"btcusd_perp@depth@100ms","data":{"e":"depthUpdate","E":1618677487693,"T":1618677487687,"s":"BTCUSD_PERP","ps":"BTCUSD","U":86143420676,"u":86143421251,"pu":86143420658,"b":[["60490.6","0"],["60492.1","1100"],["60551.6","219"],["60560.1","383"],["60569.3","920"],["60569.5","0"],["60569.6","0"],["60569.7","0"],["60570.4","260"],["60570.5","202"],["60570.6","0"],["60574.8","0"],["60575.4","0"],["60581.0","3496"],["60582.4","0"],["60583.2","243"],["60584.4","0"],["60585.2","243"],["60589.5","10812"],["60589.7","0"],["60592.4","0"]],"a":[["60589.6","2381"],["60592.2","30"],["60594.5","0"],["60595.8","1"],["60610.5","0"],["60611.2","0"],["60709.5","0"],["60711.4","1100"]]}}
1618677487.746763: {"stream":"btcusd_210924@depth@100ms","data":{"e":"depthUpdate","E":1618677487694,"T":1618677487615,"s":"BTCUSD_210924","ps":"BTCUSD","U":86143420694,"u":86143420834,"pu":86143420572,"b":[],"a":[["68632.1","60"],["68677.3","0"],["68677.4","0"]]}}
1618677487.746848: {"stream":"dotusd_210625@depth@100ms","data":{"e":"depthUpdate","E":1618677487694,"T":1618677487687,"s":"DOTUSD_210625","ps":"DOTUSD","U":86143420690,"u":86143421249,"pu":86143420628,"b":[["46.724","1123"],["46.735","63"]],"a":[["46.777","540"],["46.779","0"],["46.781","84"],["46.783","0"],["46.786","0"],["46.789","0"],["46.797","192"],["46.803","0"],["46.826","0"],["46.964","1240"]]}}
1618677487.777531: {"stream":"ethusd_210924@depth@100ms","data":{"e":"depthUpdate","E":1618677487724,"T":1618677487706,"s":"ETHUSD_210924","ps":"ETHUSD","U":86143420861,"u":86143421377,"pu":86143419980,"b":[["2689.33","0"],["2689.37","1000"],["2689.63","0"],["2689.64","660"],["2689.79","339"]],"a":[["2689.80","2688"]]}}
1618677487.784571: {"stream":"bchusd_210625@depth@100ms","data":{"e":"depthUpdate","E":1618677487732,"T":1618677487718,"s":"BCHUSD_210625","ps":"BCHUSD","U":86143420913,"u":86143421453,"pu":86143420703,"b":[["1115.19","1000"],["1115.86","0"],["1116.99","50"],["1120.73","190"],["1121.33","0"],["1123.25","1000"],["1123.92","0"],["1125.16","336"],["1125.41","0"],["1126.01","0"],["1127.51","0"],["1127.66","0"],["1128.10","0"],["1128.12","0"],["1128.13","35"]],"a":[["1132.79","0"],["1140.32","190"]]}}
1618677487.789857: {"stream":"egldusd_perp@depth@100ms","data":{"e":"depthUpdate","E":1618677487736,"T":1618677487663,"s":"EGLDUSD_PERP","ps":"EGLDUSD","U":86143420944,"u":86143421120,"pu":86143420890,"b":[["215.720","0"],["215.859","23"],["215.961","0"],["216.058","54"]],"a":[["216.145","170"]]}}
1618677487.805589: {"stream":"xrpusd_210625@depth@100ms","data":{"e":"depthUpdate","E":1618677487751,"T":1618677487692,"s":"XRPUSD_210625","ps":"XRPUSD","U":86143421006,"u":86143421277,"pu":86143420859,"b":[["1.6863","172"]],"a":[["1.6922","100"],["1.6923","0"],["1.6930","45"],["1.6947","630"],["1.6955","211"],["1.6956","1000"]]}}
1618677487.8161752: {"stream":"linkusd_210625@depth@100ms","data":{"e":"depthUpdate","E":1618677487762,"T":1618677487725,"s":"LINKUSD_210625","ps":"LINKUSD","U":86143421102,"u":86143421496,"pu":86143418937,"b":[],"a":[["43.784","50"],["43.816","0"]]}}
1618677487.844688: {"stream":"linkusd_210924@depth@100ms","data":{"e":"depthUpdate","E":1618677487793,"T":1618677487689,"s":"LINKUSD_210924","ps":"LINKUSD","U":86143421259,"u":86143421262,"pu":86143421127,"b":[],"a":[["45.415","265"],["45.417","0"]]}}
1618677487.847889: {"stream":"btcusd_perp@depth@100ms","data":{"e":"depthUpdate","E":1618677487795,"T":1618677487783,"s":"BTCUSD_PERP","ps":"BTCUSD","U":86143421272,"u":86143421899,"pu":86143421251,"b":[["60492.1","0"],["60589.7","0"]],"a":[["60590.3","30"],["60592.2","0"],["60594.4","40"],["60595.8","151"],["60599.7","0"],["60611.0","122"],["60611.2","0"],["60613.2","70"],["60711.4","0"]]}}
1618677487.8543842: {"stream":"dotusd_210625@depth@100ms","data":{"e":"depthUpdate","E":1618677487801,"T":1618677487793,"s":"DOTUSD_210625","ps":"DOTUSD","U":86143421305,"u":86143421976,"pu":86143421249,"b":[["46.220","0"],["46.673","1"],["46.726","63"],["46.735","0"],["46.754","1"],["46.755","151"]],"a":[["46.769","796"],["46.771","200"],["46.772","540"],["46.773","0"],["46.774","256"],["46.776","63"],["46.777","0"],["46.781","0"],["46.782","0"],["46.784","0"],["46.796","0"]]}}
1618677487.877795: {"stream":"ethusd_210924@depth@100ms","data":{"e":"depthUpdate","E":1618677487825,"T":1618677487748,"s":"ETHUSD_210924","ps":"ETHUSD","U":86143421469,"u":86143421636,"pu":86143421377,"b":[["2687.40","0"],["2687.41","0"],["2687.50","3371"],["2687.51","762"],["2689.37","1000"],["2689.64","0"],["2689.79","999"]],"a":[["2689.80","2568"]]}}
1618677487.882259: {"stream":"btcusd_210924@depth@100ms","data":{"e":"depthUpdate","E":1618677487829,"T":1618677487751,"s":"BTCUSD_210924","ps":"BTCUSD","U":86143421502,"u":86143421656,"pu":86143420834,"b":[],"a":[["68688.1","212"],["68688.2","665"]]}}
1618677487.88784: {"stream":"bchusd_210625@depth@100ms","data":{"e":"depthUpdate","E":1618677487836,"T":1618677487827,"s":"BCHUSD_210625","ps":"BCHUSD","U":86143421539,"u":86143422255,"pu":86143421453,"b":[["1116.99","0"],["1117.23","50"],["1121.52","73"],["1123.17","408"],["1124.11","0"],["1124.87","37"],["1125.16","286"],["1125.41","50"],["1127.47","97"],["1128.11","0"]],"a":[["1132.49","174"],["1132.50","0"],["1132.79","100"]]}}
1618677487.890017: {"stream":"ethusd_210625@depth@100ms","data":{"e":"depthUpdate","E":1618677487835,"T":1618677487796,"s":"ETHUSD_210625","ps":"ETHUSD","U":86143421530,"u":86143421994,"pu":86143420469,"b":[["2503.74","0"],["2504.05","3066"],["2507.00","0"],["2507.59","1500"],["2508.33","1071"]],"a":[["2511.80","0"],["2512.16","0"]]}}
1618677487.8988328: {"stream":"egldusd_perp@depth@100ms","data":{"e":"depthUpdate","E":1618677487846,"T":1618677487759,"s":"EGLDUSD_PERP","ps":"EGLDUSD","U":86143421599,"u":86143421707,"pu":86143421120,"b":[["215.720","23"],["215.859","0"],["215.948","389"]],"a":[]}}
1618677487.906346: {"stream":"xrpusd_210625@depth@100ms","data":{"e":"depthUpdate","E":1618677487854,"T":1618677487750,"s":"XRPUSD_210625","ps":"XRPUSD","U":86143421655,"u":86143421655,"pu":86143421277,"b":[],"a":[["1.6935","80"]]}}
1618677487.952822: {"stream":"btcusd_perp@depth@100ms","data":{"e":"depthUpdate","E":1618677487901,"T":1618677487896,"s":"BTCUSD_PERP","ps":"BTCUSD","U":86143421991,"u":86143422873,"pu":86143421899,"b":[["59670.0","0"],["60490.6","1100"],["60570.4","382"],["60570.5","80"],["60576.2","0"],["60581.3","50"],["60589.7","0"],["60596.6","0"],["60596.8","0"],["60597.0","0"],["60597.2","0"],["60597.4","0"],["60597.5","0"],["60597.7","0"],["60597.9","0"],["60598.1","0"],["60598.3","0"],["60598.4","0"],["60598.6","0"]],"a":[["60610.3","122"],["60610.7","70"],["60610.9","0"],["60611.0","0"],["60623.1","243"],["60623.6","0"],["60635.9","342"],["60636.4","1407"],["60637.9","243"],["60638.4","0"],["60703.7","1100"]]}}
1618677487.953492: {"stream":"dotusd_210625@depth@100ms","data":{"e":"depthUpdate","E":1618677487902,"T":1618677487894,"s":"DOTUSD_210625","ps":"DOTUSD","U":86143422003,"u":86143422850,"pu":86143421976,"b":[["46.221","40"],["46.693","187"],["46.754","0"],["46.755","0"]],"a":[["46.762","200"],["46.763","796"],["46.765","0"],["46.766","540"],["46.768","0"],["46.769","256"],["46.771","0"],["46.772","0"],["46.774","0"],["46.776","0"],["46.796","1060"],["46.940","1732"],["46.963","0"],["47.138","0"],["47.206","39"]]}}
1618677488.0039098: {"stream":"ethusd_210625@depth@100ms","data":{"e":"depthUpdate","E":1618677487951,"T":1618677487945,"s":"ETHUSD_210625","ps":"ETHUSD","U":86143422417,"u":86143423340,"pu":86143421994,"b":[["2507.11","1529"],["2507.51","771"]],"a":[["2511.52","0"],["2511.55","0"],["2511.58","771"],["2511.59","675"],["2511.68","2306"],["2511.80","1529"],["2511.87","0"],["2511.90","839"],["2511.91","0"],["2511.98","0"],["2512.92","0"]]}}
1618677488.030339: {"stream":"btcusd_210924@depth@100ms","data":{"e":"depthUpdate","E":1618677487977,"T":1618677487941,"s":"BTCUSD_210924","ps":"BTCUSD","U":86143422584,"u":86143423300,"pu":86143421656,"b":[["68620.1","0"],["68620.3","0"]],"a":[["68632.1","60"],["68703.1","390"],["68703.2","1324"],["69243.5","0"]]}}
1618677488.052094: {"stream":"linkusd_210924@depth@100ms","data":{"e":"depthUpdate","E":1618677487999,"T":1618677487922,"s":"LINKUSD_210924","ps":"LINKUSD","U":86143422835,"u":86143423128,"pu":86143421262,"b":[],"a":[["45.413","266"],["45.414","1258"],["45.415","0"],["45.416","0"]]}}
1618677488.055889: {"stream":"btcusd_perp@depth@100ms","data":{"e":"depthUpdate","E":1618677488004,"T":1618677487996,"s":"BTCUSD_PERP","ps":"BTCUSD","U":86143422898,"u":86143423764,"pu":86143422873,"b":[["60345.6","3614"],["60497.9","42"],["60569.5","0"],["60569.6","0"],["60570.4","17"],["60571.8","243"],["60572.0","122"],["60581.3","0"],["60582.3","124"],["60583.2","0"],["60584.3","0"],["60584.6","243"],["60584.7","0"],["60585.2","0"],["60586.7","243"],["60587.3","30"],["60589.7","0"],["60598.3","0"]],"a":[["60589.6","2631"],["60594.4","0"],["60599.6","40"],["60610.3","0"],["60610.4","0"],["60610.7","192"],["60637.9","0"],["60638.4","243"],["60845.0","1824"]]}}
1618677488.056101: {"stream":"dotusd_210625@depth@100ms","data":{"e":"depthUpdate","E":1618677488004,"T":1618677487980,"s":"DOTUSD_210625","ps":"DOTUSD","U":86143422901,"u":86143423655,"pu":86143422850,"b":[["46.711","0"],["46.712","63"],["46.726","0"]],"a":[["46.757","540"],["46.759","200"],["46.760","540"],["46.762","0"],["46.763","0"],["46.766","0"],["46.797","0"]]}}
1618677488.065058: {"stream":"ethusd_210924@depth@100ms","data":{"e":"depthUpdate","E":1618677487943,"T":1618677487929,"s":"ETHUSD_210924","ps":"ETHUSD","U":86143422360,"u":86143423184,"pu":86143421636,"b":[["2682.62","0"],["2686.73","0"],["2686.74","0"],["2686.75","6624"],["2689.37","1000"],["2689.63","660"],["2689.79","339"]],"a":[["2689.80","2568"]]}}
1618677488.065322: {"stream":"bchusd_210625@depth@100ms","data":{"e":"depthUpdate","E":1618677487948,"T":1618677487939,"s":"BCHUSD_210625","ps":"BCHUSD","U":86143422373,"u":86143423291,"pu":86143422255,"b":[["1121.38","0"],["1122.19","0"],["1123.17","211"],["1127.01","1064"],["1127.22","0"],["1127.66","0"],["1128.13","0"],["1128.14","35"]],"a":[["1131.22","0"]]}}
1618677488.065462: {"stream":"egldusd_perp@depth@100ms","data":{"e":"depthUpdate","E":1618677487958,"T":1618677487883,"s":"EGLDUSD_PERP","ps":"EGLDUSD","U":86143422468,"u":86143422698,"pu":86143421707,"b":[],"a":[["216.265","0"],["216.294","457"],["216.295","37"],["216.296","0"]]}}
1618677488.065523: {"stream":"xrpusd_210625@depth@100ms","data":{"e":"depthUpdate","E":1618677487983,"T":1618677487963,"s":"XRPUSD_210625","ps":"XRPUSD","U":86143422645,"u":86143423527,"pu":86143421655,"b":[["1.6837","4386"]],"a":[["1.6930","0"],["1.7039","0"]]}}
1618677488.065595: {"stream":"linkusd_210625@depth@100ms","data":{"e":"depthUpdate","E":1618677487998,"T":1618677487988,"s":"LINKUSD_210625","ps":"LINKUSD","U":86143422821,"u":86143423708,"pu":86143421496,"b":[["43.580","0"],["43.608","4147"],["43.621","20"]],"a":[["43.784","0"]]}}
1618677488.096302: {"stream":"ethusd_210924@depth@100ms","data":{"e":"depthUpdate","E":1618677488043,"T":1618677488038,"s":"ETHUSD_210924","ps":"ETHUSD","U":86143423263,"u":86143424136,"pu":86143423184,"b":[["2689.33","0"],["2689.37","0"]],"a":[["2689.80","2688"],["2702.62","250"]]}}
1618677488.10411: {"stream":"ethusd_210625@depth@100ms","data":{"e":"depthUpdate","E":1618677488052,"T":1618677488048,"s":"ETHUSD_210625","ps":"ETHUSD","U":86143423370,"u":86143424230,"pu":86143423340,"b":[["2385.39","2000"],["2510.44","0"],["2510.65","5"],["2510.86","1300"]],"a":[["2510.85","0"],["2510.94","0"],["2511.05","1442"],["2511.14","121"],["2511.26","1073"],["2511.29","1074"],["2511.31","0"],["2511.33","1071"],["2511.63","2804"],["2511.66","3044"],["2511.75","2030"],["2511.88","1652"],["2513.27","8047"],["2513.49","0"],["2537.85","0"]]}}
1618677488.1060932: {"stream":"bchusd_210625@depth@100ms","data":{"e":"depthUpdate","E":1618677488054,"T":1618677488047,"s":"BCHUSD_210625","ps":"BCHUSD","U":86143423399,"u":86143424229,"pu":86143423291,"b":[["1116.69","150"],["1117.23","0"],["1120.73","0"],["1121.67","706"],["1124.86","141"],["1125.41","0"],["1126.68","1134"],["1127.01","12"],["1127.23","0"],["1127.66","35"],["1127.67","7"],["1128.14","0"],["1128.57","0"]],"a":[["1130.45","425"]]}}
1618677488.14398: {"stream":"btcusd_210924@depth@100ms","data":{"e":"depthUpdate","E":1618677488092,"T":1618677488004,"s":"BTCUSD_210924","ps":"BTCUSD","U":86143423705,"u":86143423808,"pu":86143423300,"b":[["68613.2","202"],["68620.4","0"]],"a":[["68632.1","120"]]}}
1618677488.154773: {"stream":"xrpusd_210625@depth@100ms","data":{"e":"depthUpdate","E":1618677488103,"T":1618677488094,"s":"XRPUSD_210625","ps":"XRPUSD","U":86143423783,"u":86143424584,"pu":86143423527,"b":[["1.6836","80"],["1.6911","0"]],"a":[["1.6930","0"],["1.6932","153"],["1.6933","723"]]}}
1618677488.1572852: {"stream":"dotusd_210625@depth@100ms","data":{"e":"depthUpdate","E":1618677488105,"T":1618677488065,"s":"DOTUSD_210625","ps":"DOTUSD","U":86143423798,"u":86143424380,"pu":86143423655,"b":[["46.698","63"],["46.712","0"],["46.754","0"]],"a":[["46.756","200"],["46.759","0"],["46.760","0"]]}}
1618677488.175207: {"stream":"linkusd_210625@depth@100ms","data":{"e":"depthUpdate","E":1618677488121,"T":1618677488081,"s":"LINKUSD_210625","ps":"LINKUSD","U":86143423912,"u":86143424499,"pu":86143423708,"b":[["43.582","180"]],"a":[["43.784","50"]]}}
1618677488.18475: {"stream":"btcusd_perp@depth@100ms","data":{"e":"depthUpdate","E":1618677488128,"T":1618677488114,"s":"BTCUSD_PERP","ps":"BTCUSD","U":86143424009,"u":86143424742,"pu":86143423764,"b":[["60443.9","0"],["60569.3","0"],["60571.8","0"],["60572.0","0"],["60572.2","243"],["60572.4","122"],["60575.3","1317"],["60582.3","114"],["60583.8","0"],["60584.6","0"],["60585.0","243"],["60586.7","0"],["60587.1","243"],["60589.5","11517"],["60589.7","0"],["60592.4","0"]],"a":[["60589.6","2600"],["60590.3","0"],["60591.6","30"],["60594.4","0"],["60595.6","180"],["60595.8","1"],["60603.0","0"],["60610.7","70"],["60613.3","0"],["60613.7","122"],["60613.8","0"],["60623.1","0"],["60626.1","243"],["60626.5","140"],["60635.9","99"],["60638.4","0"],["60638.9","243"],["60639.3","8"],["60640.9","0"],["60641.3","243"],["60641.4","1002"],["60703.7","0"],["60715.8","1100"],["60782.0","3"]]}}
1618677488.195231: {"stream":"egldusd_perp@depth@100ms","data":{"e":"depthUpdate","E":1618677488136,"T":1618677488124,"s":"EGLDUSD_PERP","ps":"EGLDUSD","U":86143424078,"u":86143424807,"pu":86143422698,"b":[["215.947","0"],["215.948","0"],["215.949","0"],["215.960","390"],["215.961","104"],["215.975","97"],["216.048","0"],["216.058","0"],["216.068","170"],["216.078","54"]],"a":[["216.291","103"],["216.292","457"],["216.293","37"],["216.294","0"],["216.295","0"]]}}
1618677488.210025: {"stream":"ethusd_210924@depth@100ms","data":{"e":"depthUpdate","E":1618677488147,"T":1618677488142,"s":"ETHUSD_210924","ps":"ETHUSD","U":86143424183,"u":86143424912,"pu":86143424136,"b":[["2555.39","1000"],["2684.57","1001"],["2685.19","150"],["2686.13","6624"],["2686.75","0"],["2689.63","660"],["2689.79","339"]],"a":[["2690.58","150"]]}}
1618677488.219831: {"stream":"ethusd_210625@depth@100ms","data":{"e":"depthUpdate","E":1618677488153,"T":1618677488142,"s":"ETHUSD_210625","ps":"ETHUSD","U":86143424242,"u":86143424914,"pu":86143424230,"b":[["2510.41","0"],["2510.43","0"],["2510.44","757"],["2510.65","0"]],"a":[["2510.85","0"],["2510.87","2262"],["2510.99","121"],["2511.04","0"],["2511.14","0"],["2511.25","296"],["2511.31","0"],["2511.35","0"],["2512.18","1357"]]}}
1618677488.239954: {"stream":"bchusd_210625@depth@100ms","data":{"e":"depthUpdate","E":1618677488173,"T":1618677488166,"s":"BCHUSD_210625","ps":"BCHUSD","U":86143424406,"u":86143425077,"pu":86143424229,"b":[["1116.69","0"],["1117.17","150"],["1120.67","190"],["1124.86","0"],["1125.34","141"],["1126.45","1033"],["1126.68","100"],["1127.21","58"],["1127.47","0"],["1127.64","0"],["1127.65","0"],["1127.66","0"],["1127.67","0"],["1127.68","0"],["1127.69","0"],["1127.70","64"],["1127.71","21"],["1128.53","0"]],"a":[["1129.89","407"],["1132.51","359"],["1132.79","0"],["1134.08","1000"],["1134.72","0"]]}}
1618677488.252068: {"stream":"linkusd_210924@depth@100ms","data":{"e":"depthUpdate","E":1618677488189,"T":1618677488137,"s":"LINKUSD_210924","ps":"LINKUSD","U":86143424485,"u":86143424897,"pu":86143423128,"b":[],"a":[["45.309","10"],["45.397","0"],["45.401","81"],["45.402","377"],["45.411","256"],["45.412","1215"],["45.413","0"],["45.414","0"]]}}
1618677488.261162: {"stream":"xrpusd_210625@depth@100ms","data":{"e":"depthUpdate","E":1618677488204,"T":1618677488190,"s":"XRPUSD_210625","ps":"XRPUSD","U":86143424620,"u":86143425225,"pu":86143424584,"b":[["1.6852","445"],["1.6863","304"],["1.6902","0"],["1.6911","45"]],"a":[["1.6924","45"]]}}
1618677488.2824461: {"stream":"btcusd_perp@depth@100ms","data":{"e":"depthUpdate","E":1618677488231,"T":1618677488226,"s":"BTCUSD_PERP","ps":"BTCUSD","U":86143424818,"u":86143425426,"pu":86143424742,"b":[["60538.7","1405"],["60539.0","528"],["60579.6","35"],["60585.0","343"],["60587.2","0"],["60589.5","10812"],["60589.7","0"]],"a":[["60600.3","10"],["60613.2","70"],["60613.5","122"],["60613.7","0"],["60636.2","1405"],["60636.4","2"],["60640.9","243"],["60641.3","0"],["60679.2","0"]]}}
1618677488.298618: {"stream":"btcusd_210924@depth@100ms","data":{"e":"depthUpdate","E":1618677488247,"T":1618677488169,"s":"BTCUSD_210924","ps":"BTCUSD","U":86143424917,"u":86143425090,"pu":86143423808,"b":[["68581.0","0"],["68589.9","1235"],["68590.0","306"]],"a":[]}}
1618677488.30416: {"stream":"egldusd_perp@depth@100ms","data":{"e":"depthUpdate","E":1618677488250,"T":1618677488228,"s":"EGLDUSD_PERP","ps":"EGLDUSD","U":86143424958,"u":86143425439,"pu":86143424807,"b":[["215.947","80"],["215.960","0"],["215.961","0"],["215.962","0"],["215.963","0"],["215.975","0"],["215.976","0"],["215.985","54"],["215.990","97"],["215.991","21"],["216.078","0"]],"a":[["216.102","0"],["216.112","33"],["216.155","0"],["216.290","12"],["216.293","0"],["216.535","42"]]}}
1618677488.31871: {"stream":"dotusd_210625@depth@100ms","data":{"e":"depthUpdate","E":1618677488267,"T":1618677488260,"s":"DOTUSD_210625","ps":"DOTUSD","U":86143425053,"u":86143425617,"pu":86143424380,"b":[["46.754","0"],["46.755","0"],["46.756","540"],["46.757","206"]],"a":[["46.756","0"],["46.757","0"],["46.768","200"],["46.797","192"],["46.892","1674"],["46.940","0"]]}}
1618677488.324596: {"stream":"ethusd_210625@depth@100ms","data":{"e":"depthUpdate","E":1618677488269,"T":1618677488216,"s":"ETHUSD_210625","ps":"ETHUSD","U":86143425056,"u":86143425387,"pu":86143424914,"b":[["2504.05","0"],["2504.09","3066"],["2510.12","1378"],["2510.44","0"]],"a":[["2510.85","0"],["2510.87","2383"],["2510.98","0"],["2510.99","0"],["2511.14","0"]]}}
1618677488.343521: {"stream":"bchusd_210625@depth@100ms","data":{"e":"depthUpdate","E":1618677488290,"T":1618677488276,"s":"BCHUSD_210625","ps":"BCHUSD","U":86143425198,"u":86143425720,"pu":86143425077,"b":[["1117.17","0"],["1121.03","346"],["1122.42","0"],["1123.95","0"],["1125.11","0"],["1125.34","0"],["1127.72","0"],["1127.73","0"],["1127.75","64"],["1127.76","35"]],"a":[["1131.59","50"],["1132.51","0"],["1134.08","0"],["1139.01","0"]]}}
1618677488.350106: {"stream":"linkusd_210625@depth@100ms","data":{"e":"depthUpdate","E":1618677488296,"T":1618677488192,"s":"LINKUSD_210625","ps":"LINKUSD","U":86143425238,"u":86143425238,"pu":86143424499,"b":[["43.582","0"]],"a":[]}}
1618677488.3589451: {"stream":"linkusd_210924@depth@100ms","data":{"e":"depthUpdate","E":1618677488306,"T":1618677488201,"s":"LINKUSD_210924","ps":"LINKUSD","U":86143425301,"u":86143425301,"pu":86143424897,"b":[["45.234","554"]],"a":[]}}
1618677488.394805: {"stream":"btcusd_perp@depth@100ms","data":{"e":"depthUpdate","E":1618677488341,"T":1618677488327,"s":"BTCUSD_PERP","ps":"BTCUSD","U":86143425453,"u":86143426131,"pu":86143425426,"b":[["54530.5","1"],["60496.2","6184"],["60506.9","0"],["60537.6","0"],["60553.3","0"],["60569.3","934"],["60575.3","397"],["60589.7","0"],["60590.1","0"],["60590.3","0"],["60590.4","0"],["60590.6","0"],["60590.8","0"],["60591.0","0"],["60591.2","0"],["60591.4","0"],["60591.5","0"],["60591.7","0"],["60591.9","0"],["60592.1","0"],["60592.3","0"],["60592.4","0"],["60592.6","0"],["60593.0","0"],["60593.2","0"],["60593.4","0"],["60593.5","0"],["60593.7","0"],["60593.9","0"],["60594.0","0"],["60594.1","0"],["60594.2","0"],["60594.3","0"],["60594.4","0"],["60594.6","0"],["60594.7","0"],["60594.8","0"],["60594.9","0"],["60595.0","0"],["60595.2","0"],["60595.4","0"],["60595.5","0"],["60595.7","0"],["60595.9","0"],["60596.1","0"],["60596.3","0"],["60596.4","0"],["60596.6","0"],["60596.8","0"],["60597.0","0"],["60597.2","0"],["60597.4","0"],["60597.5","0"],["60597.7","0"],["60597.9","0"],["60598.1","0"],["60598.3","0"],["60598.4","0"],["60598.6","0"]],"a":[["60589.6","1830"],["60591.6","0"],["60613.5","0"],["60613.6","122"],["60650.6","1000"],["60675.8","6184"],["60692.9","0"],["60694.9","1361"]]}}
1618677488.410732: {"stream":"egldusd_perp@depth@100ms","data":{"e":"depthUpdate","E":1618677488358,"T":1618677488336,"s":"EGLDUSD_PERP","ps":"EGLDUSD","U":86143425570,"u":86143426187,"pu":86143425439,"b":[["215.961","97"],["215.962","22"],["215.985","0"],["215.990","0"],["215.991","0"],["216.000","0"]],"a":[["216.092","170"],["216.102","0"]]}}
1618677488.419335: {"stream":"dotusd_210625@depth@100ms","data":{"e":"depthUpdate","E":1618677488368,"T":1618677488359,"s":"DOTUSD_210625","ps":"DOTUSD","U":86143425638,"u":86143426263,"pu":86143425617,"b":[["46.693","2"],["46.698","0"],["46.713","825"],["46.714","175"],["46.722","0"],["46.723","0"],["46.726","326"],["46.753","50"],["46.756","0"],["46.757","0"],["46.759","540"],["46.760","113"]],"a":[["46.768","0"],["46.769","0"],["46.793","796"],["46.794","0"],["46.795","0"],["46.796","84"],["46.816","0"],["46.826","200"]]}}
1618677488.442712: {"stream":"ethusd_210625@depth@100ms","data":{"e":"depthUpdate","E":1618677488390,"T":1618677488339,"s":"ETHUSD_210625","ps":"ETHUSD","U":86143425771,"u":86143426205,"pu":86143425387,"b":[],"a":[["2510.85","0"],["2511.04","54"],["2511.25","0"]]}}
1618677488.4482281: {"stream":"bchusd_210625@depth@100ms","data":{"e":"depthUpdate","E":1618677488395,"T":1618677488386,"s":"BCHUSD_210625","ps":"BCHUSD","U":86143425805,"u":86143426377,"pu":86143425720,"b":[["1116.69","0"],["1116.87","50"],["1117.17","0"],["1123.31","250"],["1123.70","0"],["1124.10","173"],["1124.82","0"],["1124.86","0"],["1124.98","0"],["1125.05","50"],["1125.34","0"],["1127.70","0"],["1127.71","0"],["1127.76","0"],["1127.77","18"],["1127.79","64"],["1127.80","35"]],"a":[["1134.72","0"],["1137.43","1625"],["1138.57","0"]]}}
1618677488.44857: {"stream":"ethusd_210924@depth@100ms","data":{"e":"depthUpdate","E":1618677488395,"T":1618677488292,"s":"ETHUSD_210924","ps":"ETHUSD","U":86143425813,"u":86143425813,"pu":86143424912,"b":[],"a":[["2689.80","2568"]]}}
1618677488.474302: {"stream":"linkusd_210924@depth@100ms","data":{"e":"depthUpdate","E":1618677488423,"T":1618677488347,"s":"LINKUSD_210924","ps":"LINKUSD","U":86143425966,"u":86143426234,"pu":86143425301,"b":[["45.240","3169"],["45.241","420"],["45.245","1158"],["45.246","156"]],"a":[["45.365","0"],["45.384","0"]]}}
1618677488.480318: {"stream":"linkusd_210625@depth@100ms","data":{"e":"depthUpdate","E":1618677488427,"T":1618677488422,"s":"LINKUSD_210625","ps":"LINKUSD","U":86143426074,"u":86143426561,"pu":86143425238,"b":[["43.549","0"],["43.555","159"],["43.745","0"],["43.751","100"]],"a":[["43.776","0"]]}}
1618677488.49146: {"stream":"btcusd_210924@depth@100ms","data":{"e":"depthUpdate","E":1618677488437,"T":1618677488358,"s":"BTCUSD_210924","ps":"BTCUSD","U":86143426171,"u":86143426261,"pu":86143425090,"b":[],"a":[["68679.4","662"],["68688.1","0"],["68688.2","0"]]}}
1618677488.4934368: {"stream":"btcusd_perp@depth@100ms","data":{"e":"depthUpdate","E":1618677488441,"T":1618677488432,"s":"BTCUSD_PERP","ps":"BTCUSD","U":86143426144,"u":86143426604,"pu":86143426131,"b":[["60094.1","0"],["60522.2","2274"],["60561.9","1432"],["60569.3","0"],["60575.3","1331"],["60589.5","11517"],["60589.7","0"],["60592.4","0"],["60592.8","0"],["60593.2","0"],["60597.0","0"]],"a":[["60589.6","1579"],["60613.4","122"],["60613.5","0"],["60613.6","0"],["60614.1","0"],["60626.1","0"],["60626.2","243"],["60626.9","0"],["60638.9","0"],["60639.0","251"],["60639.7","0"],["60640.9","0"],["60641.1","243"],["60641.8","0"]]}}
1618677488.528527: {"stream":"dotusd_210625@depth@100ms","data":{"e":"depthUpdate","E":1618677488476,"T":1618677488470,"s":"DOTUSD_210625","ps":"DOTUSD","U":86143426307,"u":86143426848,"pu":86143426263,"b":[["46.605","0"],["46.726","263"],["46.735","63"]],"a":[["46.786","540"],["46.787","0"],["46.788","256"],["46.790","540"],["46.792","84"],["46.793","256"],["46.795","0"],["46.796","0"],["46.803","0"],["46.826","0"]]}}
1618677488.55142: {"stream":"ethusd_210924@depth@100ms","data":{"e":"depthUpdate","E":1618677488498,"T":1618677488428,"s":"ETHUSD_210924","ps":"ETHUSD","U":86143426423,"u":86143426582,"pu":86143425813,"b":[["2668.97","0"],["2686.13","0"],["2686.73","6624"]],"a":[["2689.80","2688"]]}}
1618677488.551619: {"stream":"bchusd_210625@depth@100ms","data":{"e":"depthUpdate","E":1618677488498,"T":1618677488447,"s":"BCHUSD_210625","ps":"BCHUSD","U":86143426429,"u":86143426686,"pu":86143426377,"b":[["1116.87","0"],["1117.24","50"],["1120.67","0"],["1125.05","0"],["1125.42","50"],["1127.77","0"]],"a":[["1134.46","1000"]]}}
1618677488.5517702: {"stream":"egldusd_perp@depth@100ms","data":{"e":"depthUpdate","E":1618677488500,"T":1618677488461,"s":"EGLDUSD_PERP","ps":"EGLDUSD","U":86143426437,"u":86143426799,"pu":86143426187,"b":[["215.961","0"],["215.962","0"],["215.972","54"],["215.986","97"]],"a":[["216.135","16"]]}}
1618677488.560603: {"stream":"xrpusd_210625@depth@100ms","data":{"e":"depthUpdate","E":1618677488508,"T":1618677488494,"s":"XRPUSD_210625","ps":"XRPUSD","U":86143426458,"u":86143426962,"pu":86143425225,"b":[["1.6804","145"],["1.6808","100"],["1.6897","0"],["1.6901","126"],["1.6906","45"],["1.6910","0"],["1.6911","0"]],"a":[]}}
1618677488.580678: {"stream":"linkusd_210625@depth@100ms","data":{"e":"depthUpdate","E":1618677488527,"T":1618677488520,"s":"LINKUSD_210625","ps":"LINKUSD","U":86143426570,"u":86143427128,"pu":86143426561,"b":[["43.585","180"],["43.684","1000"]],"a":[["43.777","13"],["43.784","0"],["43.789","50"],["43.795","0"],["43.805","0"],["43.832","531"],["43.959","0"],["43.963","0"]]}}
1618677488.596287: {"stream":"btcusd_perp@depth@100ms","data":{"e":"depthUpdate","E":1618677488544,"T":1618677488533,"s":"BTCUSD_PERP","ps":"BTCUSD","U":86143426645,"u":86143427211,"pu":86143426604,"b":[["60572.3","122"],["60572.4","0"],["60574.8","485"],["60575.4","545"],["60583.5","0"],["60589.5","10812"],["60589.7","0"],["60593.0","0"]],"a":[["60613.4","0"],["60613.5","122"],["60613.7","0"],["60693.8","1361"],["60694.9","0"]]}}
1618677488.636798: {"stream":"dotusd_210625@depth@100ms","data":{"e":"depthUpdate","E":1618677488583,"T":1618677488564,"s":"DOTUSD_210625","ps":"DOTUSD","U":86143426880,"u":86143427387,"pu":86143426848,"b":[["46.626","1015"],["46.737","250"]],"a":[["46.779","200"],["46.780","540"],["46.782","0"],["46.783","796"],["46.785","84"],["46.786","0"],["46.788","0"],["46.790","0"],["46.792","0"],["46.793","0"]]}}
1618677488.63708: {"stream":"ethusd_210625@depth@100ms","data":{"e":"depthUpdate","E":1618677488584,"T":1618677488561,"s":"ETHUSD_210625","ps":"ETHUSD","U":86143426889,"u":86143427365,"pu":86143426205,"b":[["2503.61","3066"],["2504.09","0"]],"a":[["2510.85","0"],["2510.87","2383"],["2511.03","0"],["2511.25","0"]]}}
1618677488.665487: {"stream":"egldusd_perp@depth@100ms","data":{"e":"depthUpdate","E":1618677488612,"T":1618677488539,"s":"EGLDUSD_PERP","ps":"EGLDUSD","U":86143427047,"u":86143427252,"pu":86143426799,"b":[["215.961","97"],["215.972","0"],["215.986","0"],["215.996","54"]],"a":[]}}
1618677488.668502: {"stream":"xrpusd_210625@depth@100ms","data":{"e":"depthUpdate","E":1618677488615,"T":1618677488595,"s":"XRPUSD_210625","ps":"XRPUSD","U":86143427082,"u":86143427605,"pu":86143426962,"b":[["1.6836","0"],["1.6902","21"]],"a":[]}}
1618677488.668628: {"stream":"ethusd_210924@depth@100ms","data":{"e":"depthUpdate","E":1618677488615,"T":1618677488609,"s":"ETHUSD_210924","ps":"ETHUSD","U":86143427083,"u":86143427686,"pu":86143426582,"b":[["2644.00","0"],["2686.74","3278"],["2686.75","2100"],["2687.50","0"],["2687.51","0"],["2689.20","0"],["2689.63","0"],["2689.79","185"]],"a":[]}}
1618677488.678071: {"stream":"linkusd_210924@depth@100ms","data":{"e":"depthUpdate","E":1618677488624,"T":1618677488521,"s":"LINKUSD_210924","ps":"LINKUSD","U":86143427126,"u":86143427135,"pu":86143426234,"b":[],"a":[["45.436","4443"],["45.451","0"]]}}
1618677488.685791: {"stream":"bchusd_210625@depth@100ms","data":{"e":"depthUpdate","E":1618677488633,"T":1618677488619,"s":"BCHUSD_210625","ps":"BCHUSD","U":86143427189,"u":86143427767,"pu":86143426686,"b":[["1117.24","0"],["1120.77","190"],["1124.70","0"],["1125.42","0"],["1127.18","0"],["1127.19","0"]],"a":[["1137.43","0"],["1138.57","1708"],["1140.32","0"]]}}
1618677488.69233: {"stream":"linkusd_210625@depth@100ms","data":{"e":"depthUpdate","E":1618677488638,"T":1618677488588,"s":"LINKUSD_210625","ps":"LINKUSD","U":86143427228,"u":86143427549,"pu":86143427128,"b":[["43.709","1312"]],"a":[["43.963","180"],["43.990","1320"]]}}
1618677488.702282: {"stream":"btcusd_perp@depth@100ms","data":{"e":"depthUpdate","E":1618677488649,"T":1618677488643,"s":"BTCUSD_PERP","ps":"BTCUSD","U":86143427293,"u":86143427894,"pu":86143427211,"b":[["60557.4","0"],["60574.8","0"],["60575.4","0"],["60584.8","1"],["60589.5","14662"],["60589.7","0"],["60593.5","0"],["60593.7","0"],["60594.2","0"],["60594.7","0"],["60595.4","0"]],"a":[["60612.0","122"],["60613.4","0"],["60613.5","0"],["60624.8","345"],["60626.2","0"],["60637.6","243"],["60639.0","8"],["60639.6","243"],["60641.1","0"]]}}
1618677488.736047: {"stream":"dotusd_210625@depth@100ms","data":{"e":"depthUpdate","E":1618677488684,"T":1618677488675,"s":"DOTUSD_210625","ps":"DOTUSD","U":86143427480,"u":86143428157,"pu":86143427387,"b":[["46.735","0"],["46.738","63"],["46.760","0"]],"a":[["46.776","200"],["46.777","796"],["46.778","15"],["46.779","0"],["46.780","0"],["46.783","256"],["46.784","0"],["46.785","0"],["46.796","0"],["46.892","0"],["46.916","1924"]]}}
1618677488.738745: {"stream":"btcusd_210924@depth@100ms","data":{"e":"depthUpdate","E":1618677488685,"T":1618677488666,"s":"BTCUSD_210924","ps":"BTCUSD","U":86143427490,"u":86143428082,"pu":86143426261,"b":[["68581.3","1195"],["68589.9","0"],["68590.0","0"]],"a":[["68673.4","217"]]}}
1618677488.768852: {"stream":"ethusd_210625@depth@100ms","data":{"e":"depthUpdate","E":1618677488716,"T":1618677488639,"s":"ETHUSD_210625","ps":"ETHUSD","U":86143427721,"u":86143427866,"pu":86143427365,"b":[["2510.31","0"],["2510.57","299"],["2510.64","0"]],"a":[["2510.85","0"]]}}
1618677488.7733371: {"stream":"ethusd_210924@depth@100ms","data":{"e":"depthUpdate","E":1618677488722,"T":1618677488672,"s":"ETHUSD_210924","ps":"ETHUSD","U":86143427752,"u":86143428131,"pu":86143427686,"b":[["2667.37","799"],["2689.20","0"],["2689.58","660"]],"a":[]}}
1618677488.773462: {"stream":"egldusd_perp@depth@100ms","data":{"e":"depthUpdate","E":1618677488722,"T":1618677488688,"s":"EGLDUSD_PERP","ps":"EGLDUSD","U":86143427766,"u":86143428244,"pu":86143427252,"b":[["215.587","0"],["215.604","764"],["215.971","0"],["215.996","0"],["216.006","54"]],"a":[["216.080","41"],["216.102","16"],["216.112","0"],["216.135","0"]]}}
1618677488.7916641: {"stream":"bchusd_210625@depth@100ms","data":{"e":"depthUpdate","E":1618677488741,"T":1618677488707,"s":"BCHUSD_210625","ps":"BCHUSD","U":86143427850,"u":86143428361,"pu":86143427767,"b":[["1116.65","400"],["1120.40","190"],["1120.77","0"],["1124.82","141"],["1127.76","15"]],"a":[["1129.74","900"],["1129.75","30"],["1133.75","1000"],["1134.46","0"]]}}
1618677488.7969458: {"stream":"xrpusd_210625@depth@100ms","data":{"e":"depthUpdate","E":1618677488745,"T":1618677488650,"s":"XRPUSD_210625","ps":"XRPUSD","U":86143427883,"u":86143427936,"pu":86143427605,"b":[],"a":[["1.6945","251"],["1.6946","1467"]]}}
1618677488.802537: {"stream":"btcusd_perp@depth@100ms","data":{"e":"depthUpdate","E":1618677488749,"T":1618677488741,"s":"BTCUSD_PERP","ps":"BTCUSD","U":86143427903,"u":86143428522,"pu":86143427894,"b":[["59898.6","100"],["60541.7","1225"],["60542.1","0"],["60557.5","363"],["60561.5","0"]],"a":[["60612.0","0"],["60612.9","0"],["60624.8","102"],["60625.7","0"],["60628.2","261"],["60637.6","0"],["60638.5","1225"],["60639.6","0"],["60640.5","90"]]}}
1618677488.850504: {"stream":"dotusd_210625@depth@100ms","data":{"e":"depthUpdate","E":1618677488799,"T":1618677488792,"s":"DOTUSD_210625","ps":"DOTUSD","U":86143428299,"u":86143428799,"pu":86143428157,"b":[],"a":[["46.768","540"],["46.770","200"],["46.771","796"],["46.773","0"],["46.774","0"],["46.776","0"],["46.777","256"],["46.778","0"],["46.783","0"],["46.794","931"],["46.796","84"]]}}
1618677488.884093: {"stream":"egldusd_perp@depth@100ms","data":{"e":"depthUpdate","E":1618677488833,"T":1618677488759,"s":"EGLDUSD_PERP","ps":"EGLDUSD","U":86143428469,"u":86143428631,"pu":86143428244,"b":[["216.006","0"]],"a":[["216.102","0"],["216.145","0"]]}}
1618677488.900128: {"stream":"btcusd_perp@depth@100ms","data":{"e":"depthUpdate","E":1618677488849,"T":1618677488836,"s":"BTCUSD_PERP","ps":"BTCUSD","U":86143428550,"u":86143429055,"pu":86143428522,"b":[["60578.6","0"],["60581.3","30"],["60587.3","0"],["60589.5","14661"],["60589.7","0"]],"a":[["60589.6","1585"],["60611.8","40"],["60611.9","0"],["60612.8","122"],["60624.7","0"],["60625.6","243"],["60637.5","8"],["60638.4","243"],["60639.6","0"],["60640.5","333"]]}}
1618677488.9085639: {"stream":"xrpusd_210625@depth@100ms","data":{"e":"depthUpdate","E":1618677488857,"T":1618677488778,"s":"XRPUSD_210625","ps":"XRPUSD","U":86143428591,"u":86143428719,"pu":86143427936,"b":[["1.6899","0"]],"a":[["1.6921","197"],["1.6924","0"]]}}
1618677488.9086971: {"stream":"bchusd_210625@depth@100ms","data":{"e":"depthUpdate","E":1618677488857,"T":1618677488851,"s":"BCHUSD_210625","ps":"BCHUSD","U":86143428588,"u":86143429119,"pu":86143428361,"b":[["1121.03","519"],["1121.21","166"],["1122.55","1067"],["1126.45","0"],["1127.75","0"],["1127.76","0"],["1127.80","14"],["1127.81","0"],["1127.82","0"],["1127.83","64"],["1127.84","35"],["1127.85","18"]],"a":[["1129.22","20"],["1129.23","96"],["1129.51","52"],["1129.52","250"],["1129.74","28"],["1129.80","613"],["1132.08","174"],["1136.42","218"],["1137.40","2970"],["1139.19","190"]]}}
1618677488.915211: {"stream":"btcusd_210924@depth@100ms","data":{"e":"depthUpdate","E":1618677488862,"T":1618677488811,"s":"BTCUSD_210924","ps":"BTCUSD","U":86143428630,"u":86143428916,"pu":86143428082,"b":[["68599.0","15"]],"a":[["68632.1","70"],["68688.1","359"],["68688.2","1369"],["68703.1","0"],["68703.2","0"],["68736.4","15"]]}}
1618677488.925678: {"stream":"linkusd_210924@depth@100ms","data":{"e":"depthUpdate","E":1618677488873,"T":1618677488770,"s":"LINKUSD_210924","ps":"LINKUSD","U":86143428681,"u":86143428686,"pu":86143427135,"b":[],"a":[["45.436","250"],["45.451","4193"]]}}
1618677488.962344: {"stream":"dotusd_210625@depth@100ms","data":{"e":"depthUpdate","E":1618677488908,"T":1618677488901,"s":"DOTUSD_210625","ps":"DOTUSD","U":86143428873,"u":86143429351,"pu":86143428799,"b":[["46.727","63"],["46.738","53"],["46.754","12"],["46.759","0"]],"a":[["46.762","540"],["46.764","0"],["46.765","796"],["46.767","0"],["46.768","0"],["46.770","0"],["46.771","0"],["46.777","0"],["46.793","84"],["46.796","0"]]}}
1618677488.9889789: {"stream":"egldusd_perp@depth@100ms","data":{"e":"depthUpdate","E":1618677488934,"T":1618677488911,"s":"EGLDUSD_PERP","ps":"EGLDUSD","U":86143429020,"u":86143429394,"pu":86143428631,"b":[["215.859","389"]],"a":[["216.092","170"],["216.155","16"]]}}
1618677488.9891598: {"stream":"ethusd_210924@depth@100ms","data":{"e":"depthUpdate","E":1618677488934,"T":1618677488856,"s":"ETHUSD_210924","ps":"ETHUSD","U":86143429018,"u":86143429149,"pu":86143428131,"b":[["2686.13","6557"],["2686.73","0"],["2686.75","0"]],"a":[]}}
1618677489.001469: {"stream":"btcusd_perp@depth@100ms","data":{"e":"depthUpdate","E":1618677488949,"T":1618677488943,"s":"BTCUSD_PERP","ps":"BTCUSD","U":86143429091,"u":86143429716,"pu":86143429055,"b":[["60561.0","0"],["60580.5","0"],["60581.3","0"],["60582.5","30"],["60584.2","0"],["60585.6","0"],["60589.7","0"]],"a":[["60589.6","1585"],["60593.9","1"],["60594.7","40"],["60595.6","30"],["60599.6","0"],["60611.6","0"],["60612.8","0"],["60612.9","122"],["60624.3","295"],["60625.6","243"],["60637.2","0"],["60638.4","0"],["60638.5","1468"],["60639.2","0"],["60640.5","333"]]}}
1618677489.0306828: {"stream":"ethusd_210625@depth@100ms","data":{"e":"depthUpdate","E":1618677488976,"T":1618677488968,"s":"ETHUSD_210625","ps":"ETHUSD","U":86143429198,"u":86143429890,"pu":86143427866,"b":[["2503.61","0"],["2503.74","3116"],["2505.01","1000"],["2505.05","0"],["2505.08","0"],["2505.17","0"],["2505.30","0"],["2505.32","0"],["2505.35","0"],["2505.43","0"],["2505.44","0"],["2505.65","0"],["2505.75","0"],["2505.76","0"],["2505.85","3000"],["2505.87","0"],["2505.89","0"],["2506.06","0"],["2506.09","0"],["2506.15","0"],["2506.16","0"],["2506.17","0"],["2506.31","0"],["2506.34","0"],["2506.35","0"],["2506.37","0"],["2506.47","0"],["2506.49","0"],["2506.50","0"],["2506.55","0"],["2506.61","0"],["2506.62","0"],["2506.64","0"],["2506.66","0"],["2506.67","0"],["2506.68","0"],["2506.69","0"],["2506.70","1652"],["2506.72","0"],["2506.74","0"],["2506.75","0"],["2506.79","0"],["2506.80","0"],["2506.82","189"],["2506.86","0"],["2506.88","0"],["2506.95","0"],["2506.97","0"],["2507.04","0"],["2507.05","0"],["2507.18","0"],["2507.19","0"],["2507.25","0"],["2507.26","0"],["2507.32","0"],["2507.33","0"],["2507.34","1535"],["2507.35","0"],["2507.46","0"],["2507.49","0"],["2507.51","771"],["2507.54","0"],["2507.66","0"],["2507.67","0"],["2507.79","0"],["2507.82","0"],["2507.83","1053"],["2507.85","0"],["2507.87","0"],["2508.06","0"],["2508.21","0"]],"a":[["2510.85","0"],["2511.05","88"],["2511.37","0"],["2511.50","0"],["2511.58","771"],["2511.78","0"],["2511.81","0"],["2511.88","1652"],["2511.90","0"],["2511.92","0"],["2511.96","0"],["2511.97","1535"],["2512.14","0"],["2512.15","0"],["2512.27","0"],["2512.28","0"],["2512.30","0"],["2512.38","0"],["2512.39","0"],["2512.42","0"],["2512.45","0"],["2512.49","0"],["2512.53","0"],["2512.54","0"],["2512.63","0"],["2512.66","0"],["2512.70","0"],["2512.77","0"],["2512.88","0"],["2512.89","0"],["2512.90","0"],["2512.95","0"],["2513.04","0"],["2513.06","0"],["2513.16","0"],["2513.17","0"],["2513.20","0"],["2513.21","21899"],["2513.22","1857"],["2513.23","0"],["2513.27","6065"],["2513.28","0"],["2513.30","0"],["2513.31","0"],["2513.34","0"],["2513.50","0"],["2513.53","0"],["2513.61","1500"],["2513.66","0"],["2513.68","1798"],["2513.97","0"],["2514.00","0"],["2514.02","0"],["2514.07","0"],["2514.08","0"],["2514.21","0"],["2514.28","0"],["2514.33","0"],["2514.36","0"],["2514.41","0"],["2514.44","0"],["2514.50","0"],["2514.51","0"],["2514.52","0"],["2514.56","0"],["2514.67","0"],["2514.87","0"],["2515.01","12"],["2515.23","0"]]}}
1618677489.046301: {"stream":"bchusd_210625@depth@100ms","data":{"e":"depthUpdate","E":1618677488962,"T":1618677488903,"s":"BCHUSD_210625","ps":"BCHUSD","U":86143429159,"u":86143429359,"pu":86143429119,"b":[["1127.37","35"],["1127.38","11"],["1127.79","0"],["1127.80","0"],["1127.84","0"],["1127.85","18"],["1127.86","64"],["1127.87","30"]],"a":[]}}
1618677489.048129: {"stream":"xrpusd_210625@depth@100ms","data":{"e":"depthUpdate","E":1618677488979,"T":1618677488966,"s":"XRPUSD_210625","ps":"XRPUSD","U":86143429207,"u":86143429881,"pu":86143428719,"b":[["1.6838","80"],["1.6902","21"],["1.6903","45"],["1.6905","0"],["1.6906","45"],["1.6907","0"],["1.6908","0"]],"a":[["1.7037","80"]]}}
1618677489.065779: {"stream":"dotusd_210625@depth@100ms","data":{"e":"depthUpdate","E":1618677489013,"T":1618677489005,"s":"DOTUSD_210625","ps":"DOTUSD","U":86143429391,"u":86143430082,"pu":86143429351,"b":[["46.555","0"],["46.563","1409"],["46.713","12"],["46.754","0"]],"a":[["46.756","540"],["46.758","200"],["46.759","540"],["46.761","0"],["46.762","0"],["46.765","256"],["46.793","276"],["46.797","0"]]}}
1618677489.084233: {"stream":"linkusd_210924@depth@100ms","data":{"e":"depthUpdate","E":1618677489032,"T":1618677489002,"s":"LINKUSD_210924","ps":"LINKUSD","U":86143429539,"u":86143430045,"pu":86143428686,"b":[["44.847","0"],["44.894","266"]],"a":[["45.407","196"],["45.408","930"],["45.411","0"],["45.412","0"]]}}
1618677489.0889118: {"stream":"btcusd_210924@depth@100ms","data":{"e":"depthUpdate","E":1618677489038,"T":1618677489029,"s":"BTCUSD_210924","ps":"BTCUSD","U":86143429658,"u":86143430252,"pu":86143428916,"b":[],"a":[["68688.1","0"],["68688.2","0"],["68703.1","392"],["68703.2","1334"]]}}
1618677489.093056: {"stream":"linkusd_210625@depth@100ms","data":{"e":"depthUpdate","E":1618677489041,"T":1618677488937,"s":"LINKUSD_210625","ps":"LINKUSD","U":86143429686,"u":86143429686,"pu":86143427549,"b":[],"a":[["43.899","0"]]}}
1618677489.09953: {"stream":"egldusd_perp@depth@100ms","data":{"e":"depthUpdate","E":1618677489046,"T":1618677489031,"s":"EGLDUSD_PERP","ps":"EGLDUSD","U":86143429703,"u":86143430270,"pu":86143429394,"b":[["215.961","0"],["215.971","54"],["215.985","97"]],"a":[["216.155","113"],["216.165","0"]]}}
1618677489.102698: {"stream":"btcusd_perp@depth@100ms","data":{"e":"depthUpdate","E":1618677489051,"T":1618677489041,"s":"BTCUSD_PERP","ps":"BTCUSD","U":86143429737,"u":86143430327,"pu":86143429716,"b":[["60560.1","20"],["60561.1","363"],["60561.6","545"],["60575.4","424"],["60577.5","25"],["60579.6","50"],["60580.3","0"],["60582.4","44"],["60582.5","0"],["60584.4","30"],["60584.9","0"],["60585.0","243"],["60587.2","100"],["60589.5","13466"],["60589.7","0"],["60590.1","0"],["60590.3","0"],["60590.4","0"],["60590.6","0"],["60590.8","0"],["60591.0","0"],["60591.2","0"],["60591.4","0"],["60591.5","0"],["60591.7","0"],["60591.9","0"],["60592.1","0"],["60592.3","0"],["60592.4","0"],["60592.6","0"],["60592.8","0"],["60593.0","0"],["60593.2","0"],["60593.4","0"],["60593.5","0"],["60593.7","0"],["60593.9","0"],["60594.1","0"],["60594.3","0"]],"a":[["60589.6","1625"],["60594.7","0"],["60595.6","180"],["60599.5","25"],["60601.5","7"],["60612.8","0"],["60612.9","0"],["60625.6","0"],["60638.5","1225"],["60640.5","90"]]}}
1618677489.1317382: {"stream":"ethusd_210625@depth@100ms","data":{"e":"depthUpdate","E":1618677489078,"T":1618677489074,"s":"ETHUSD_210625","ps":"ETHUSD","U":86143429920,"u":86143430614,"pu":86143429890,"b":[["2503.74","0"],["2503.87","2989"],["2505.35","3037"],["2505.36","4473"],["2505.42","3037"],["2505.46","3037"],["2505.71","4255"],["2505.72","2820"],["2505.73","2820"],["2505.87","3254"],["2506.03","3471"],["2506.04","2603"],["2506.06","2820"],["2506.12","2603"],["2506.15","1506"],["2506.20","2715"],["2506.21","2820"],["2506.38","2603"],["2506.39","3242"],["2506.41","1982"],["2506.46","2386"],["2506.49","1982"],["2506.51","1204"],["2506.53","4121"],["2506.54","3056"],["2506.57","1321"],["2506.59","1952"],["2506.60","1982"],["2506.68","1952"],["2506.72","881"],["2506.76","2169"],["2506.77","2386"],["2506.79","3303"],["2506.80","1735"],["2506.84","1321"],["2506.85","587"],["2506.87","1735"],["2506.88","1518"],["2506.93","1530"],["2506.95","881"],["2507.00","1518"],["2507.05","2496"],["2507.06","978"],["2507.08","22548"],["2507.17","963"],["2507.26","1084"],["2507.32","1133"],["2507.34","4195"],["2507.42","1301"],["2507.45","1084"],["2507.49","1354"],["2507.55","839"],["2507.57","1301"],["2507.80","616"],["2507.87","1194"],["2508.14","835"],["2508.41","0"],["2509.04","0"],["2510.12","0"],["2510.62","423"]],"a":[["2510.85","0"],["2511.04","0"],["2511.05","1442"],["2511.24","561"],["2511.25","527"],["2511.31","839"],["2511.37","616"],["2511.50","1133"],["2511.78","2194"],["2511.81","963"],["2511.82","1204"],["2511.83","1053"],["2511.92","1194"],["2511.96","1506"],["2512.41","391"],["2512.44","782"],["2512.80","1084"],["2512.83","587"],["2512.86","587"],["2512.87","1084"],["2512.92","1518"],["2513.07","6481"],["2513.09","3471"],["2513.15","1735"],["2513.16","3623"],["2513.23","1518"],["2513.27","7800"],["2513.31","881"],["2513.36","1301"],["2513.37","881"],["2513.38","3253"],["2513.46","1321"],["2513.47","2616"],["2513.58","2169"],["2513.79","1952"],["2513.82","1952"],["2513.88","1321"],["2513.98","2169"],["2514.07","2169"],["2514.14","2386"],["2514.17","2603"],["2514.34","2386"],["2514.36","1321"],["2514.40","2820"],["2514.48","3037"],["2514.50","2603"],["2514.51","2603"],["2514.61","2386"],["2514.63","5857"],["2514.65","5857"],["2514.71","1982"],["2514.73","2708"],["2514.78","1982"],["2514.86","2820"],["2514.90","6242"],["2514.95","3971"],["2515.04","3037"],["2515.30","3254"]]}}
1618677489.158574: {"stream":"xrpusd_210625@depth@100ms","data":{"e":"depthUpdate","E":1618677489105,"T":1618677489028,"s":"XRPUSD_210625","ps":"XRPUSD","U":86143430032,"u":86143430247,"pu":86143429881,"b":[["1.6903","0"],["1.6905","20"],["1.6906","45"]],"a":[["1.6920","45"],["1.6921","152"]]}}
1618677489.1587782: {"stream":"bchusd_210625@depth@100ms","data":{"e":"depthUpdate","E":1618677489105,"T":1618677489097,"s":"BCHUSD_210625","ps":"BCHUSD","U":86143430034,"u":86143430771,"pu":86143429359,"b":[["1127.37","0"],["1127.38","0"],["1127.83","0"],["1127.85","0"],["1127.88","0"],["1127.89","0"],["1127.90","0"],["1127.91","64"],["1127.92","35"],["1127.93","34"]],"a":[]}}
1618677489.1721961: {"stream":"dotusd_210625@depth@100ms","data":{"e":"depthUpdate","E":1618677489118,"T":1618677489104,"s":"DOTUSD_210625","ps":"DOTUSD","U":86143430155,"u":86143430804,"pu":86143430082,"b":[["46.563","0"],["46.673","212"],["46.693","183"],["46.698","63"],["46.714","0"],["46.724","0"],["46.725","0"],["46.727","56"],["46.738","0"]],"a":[["46.754","740"],["46.755","0"],["46.758","0"],["46.759","0"]]}}
1618677489.1744251: {"stream":"ethusd_210924@depth@100ms","data":{"e":"depthUpdate","E":1618677489120,"T":1618677489090,"s":"ETHUSD_210924","ps":"ETHUSD","U":86143430165,"u":86143430725,"pu":86143429149,"b":[["2685.19","0"],["2686.74","0"],["2687.30","3276"],["2687.31","981"]],"a":[["2690.58","0"],["2691.12","1238"]]}}
1618677489.20244: {"stream":"btcusd_perp@depth@100ms","data":{"e":"depthUpdate","E":1618677489151,"T":1618677489139,"s":"BTCUSD_PERP","ps":"BTCUSD","U":86143430364,"u":86143431039,"pu":86143430327,"b":[["59898.6","0"],["60443.9","45"],["60577.9","15"],["60580.0","121"]],"a":[["60611.9","0"],["60612.1","122"],["60612.4","0"],["60624.3","319"],["60624.7","0"],["60625.2","288"],["60637.5","8"],["60638.0","243"],["60639.6","0"],["60640.1","243"],["61117.5","0"]]}}
1618677489.213824: {"stream":"egldusd_perp@depth@100ms","data":{"e":"depthUpdate","E":1618677489161,"T":1618677489157,"s":"EGLDUSD_PERP","ps":"EGLDUSD","U":86143430410,"u":86143431140,"pu":86143430270,"b":[["215.971","0"],["215.985","0"],["215.986","0"],["215.995","54"],["215.999","0"]],"a":[["216.154","97"],["216.155","16"]]}}
1618677489.232647: {"stream":"ethusd_210625@depth@100ms","data":{"e":"depthUpdate","E":1618677489180,"T":1618677489166,"s":"ETHUSD_210625","ps":"ETHUSD","U":86143430633,"u":86143431205,"pu":86143430614,"b":[["2503.87","0"],["2503.94","2989"],["2506.23","3037"],["2506.24","2386"],["2506.38","4772"],["2506.40","2169"],["2506.58","881"],["2506.63","1952"],["2506.70","2533"],["2506.94","587"],["2508.04","1601"],["2510.12","1378"],["2510.62","0"]],"a":[["2510.85","0"],["2511.15","421"],["2511.25","0"],["2512.42","391"],["2512.80","1671"],["2513.38","4134"],["2513.58","4151"],["2513.66","1952"],["2513.97","1982"],["2514.24","2386"],["2514.30","2169"]]}}
1618677489.242229: {"stream":"linkusd_210924@depth@100ms","data":{"e":"depthUpdate","E":1618677489190,"T":1618677489183,"s":"LINKUSD_210924","ps":"LINKUSD","U":86143430698,"u":86143431333,"pu":86143430045,"b":[["44.889","0"],["44.936","667"]],"a":[["45.397","0"],["45.436","3971"],["45.451","0"]]}}
1618677489.2593799: {"stream":"xrpusd_210625@depth@100ms","data":{"e":"depthUpdate","E":1618677489207,"T":1618677489203,"s":"XRPUSD_210625","ps":"XRPUSD","U":86143430802,"u":86143431441,"pu":86143430247,"b":[["1.6807","182"],["1.6808","0"],["1.6838","0"],["1.6899","711"],["1.6900","178"],["1.6901","26"],["1.6902","0"]],"a":[["1.6920","0"],["1.6922","0"]]}}
1618677489.259551: {"stream":"bchusd_210625@depth@100ms","data":{"e":"depthUpdate","E":1618677489207,"T":1618677489201,"s":"BCHUSD_210625","ps":"BCHUSD","U":86143430806,"u":86143431436,"pu":86143430771,"b":[["1122.55","0"],["1122.85","1067"],["1125.16","0"],["1125.69","0"],["1127.11","570"],["1127.12","119"],["1127.86","0"],["1127.87","0"],["1127.91","0"],["1127.92","0"],["1127.93","0"],["1127.95","64"],["1127.96","0"],["1127.97","36"],["1127.98","35"],["1127.99","64"]],"a":[["1129.22","0"],["1129.23","0"],["1129.46","75"],["1129.47","99"],["1131.11","298"],["1132.01","112"],["1139.19","0"]]}}
1618677489.264395: {"stream":"btcusd_210924@depth@100ms","data":{"e":"depthUpdate","E":1618677489212,"T":1618677489183,"s":"BTCUSD_210924","ps":"BTCUSD","U":86143430825,"u":86143431338,"pu":86143430252,"b":[],"a":[["68632.1","70"],["68677.4","667"],["68679.4","0"]]}}
1618677489.313251: {"stream":"btcusd_perp@depth@100ms","data":{"e":"depthUpdate","E":1618677489261,"T":1618677489230,"s":"BTCUSD_PERP","ps":"BTCUSD","U":86143431147,"u":86143431599,"pu":86143431039,"b":[["60538.7","0"],["60539.1","1405"],["60560.2","363"],["60576.7","100"],["60577.2","50"],["60580.8","25"],["60586.6","0"],["60589.7","0"]],"a":[["60600.3","40"],["60603.9","398"],["60611.6","122"],["60611.7","0"],["60612.1","0"],["60624.5","243"],["60625.2","45"],["60636.2","0"],["60636.9","2500"],["60637.3","243"],["60638.0","0"],["60639.4","243"],["60640.1","0"]]}}
1618677489.313612: {"stream":"dotusd_210625@depth@100ms","data":{"e":"depthUpdate","E":1618677489261,"T":1618677489251,"s":"DOTUSD_210625","ps":"DOTUSD","U":86143431144,"u":86143431736,"pu":86143430804,"b":[["46.732","50"],["46.734","0"],["46.753","0"]],"a":[["46.747","796"],["46.749","0"],["46.750","540"],["46.751","0"],["46.752","256"],["46.753","0"],["46.754","0"],["46.756","0"],["46.765","0"],["46.884","514"],["46.960","110"]]}}
1618677489.3165922: {"stream":"egldusd_perp@depth@100ms","data":{"e":"depthUpdate","E":1618677489265,"T":1618677489219,"s":"EGLDUSD_PERP","ps":"EGLDUSD","U":86143431181,"u":86143431536,"pu":86143431140,"b":[["215.961","97"],["215.995","0"],["215.999","0"],["216.005","54"]],"a":[["216.074","41"],["216.080","0"]]}}
1618677489.336524: {"stream":"ethusd_210625@depth@100ms","data":{"e":"depthUpdate","E":1618677489283,"T":1618677489179,"s":"ETHUSD_210625","ps":"ETHUSD","U":86143431282,"u":86143431282,"pu":86143431205,"b":[],"a":[["2513.96","1321"]]}}
1618677489.364716: {"stream":"btcusd_210924@depth@100ms","data":{"e":"depthUpdate","E":1618677489313,"T":1618677489208,"s":"BTCUSD_210924","ps":"BTCUSD","U":86143431471,"u":86143431471,"pu":86143431338,"b":[],"a":[["68677.3","146"]]}}
1618677489.3688698: {"stream":"bchusd_210625@depth@100ms","data":{"e":"depthUpdate","E":1618677489316,"T":1618677489311,"s":"BCHUSD_210625","ps":"BCHUSD","U":86143431492,"u":86143432131,"pu":86143431436,"b":[["1115.19","0"],["1123.25","0"],["1124.25","250"],["1124.82","0"],["1125.07","1670"],["1127.96","13"],["1127.97","0"],["1127.98","0"],["1128.00","26"]],"a":[["1129.14","0"],["1129.45","84"],["1129.46","0"],["1132.08","0"]]}}
1618677489.3695931: {"stream":"xrpusd_210625@depth@100ms","data":{"e":"depthUpdate","E":1618677489317,"T":1618677489290,"s":"XRPUSD_210625","ps":"XRPUSD","U":86143431500,"u":86143431981,"pu":86143431441,"b":[],"a":[["1.6924","0"],["1.6926","50"],["1.6930","0"]]}}
1618677489.397121: {"stream":"ethusd_210924@depth@100ms","data":{"e":"depthUpdate","E":1618677489344,"T":1618677489331,"s":"ETHUSD_210924","ps":"ETHUSD","U":86143431658,"u":86143432239,"pu":86143430725,"b":[["2686.13","0"],["2686.73","6553"],["2689.79","186"]],"a":[]}}
1618677489.415884: {"stream":"dotusd_210625@depth@100ms","data":{"e":"depthUpdate","E":1618677489362,"T":1618677489348,"s":"DOTUSD_210625","ps":"DOTUSD","U":86143431779,"u":86143432342,"pu":86143431736,"b":[["46.221","0"],["46.692","0"],["46.699","1154"],["46.700","243"],["46.714","262"],["46.715","56"],["46.719","200"],["46.720","42"],["46.721","0"],["46.722","96"],["46.726","0"],["46.727","0"],["46.732","0"],["46.737","0"]],"a":[["46.741","540"],["46.743","0"],["46.744","540"],["46.746","0"],["46.747","0"],["46.750","0"],["46.774","792"],["46.792","84"],["46.793","192"]]}}
1618677489.432679: {"stream":"btcusd_perp@depth@100ms","data":{"e":"depthUpdate","E":1618677489379,"T":1618677489372,"s":"BTCUSD_PERP","ps":"BTCUSD","U":86143431902,"u":86143432502,"pu":86143431599,"b":[["60572.3","0"],["60572.4","122"],["60580.6","50"],["60582.6","0"],["60584.4","0"],["60586.3","30"],["60589.5","13465"],["60589.7","0"]],"a":[["60589.6","5061"],["60595.6","30"],["60611.2","122"],["60611.6","0"],["60613.2","40"],["60624.0","273"],["60624.5","0"],["60636.8","243"],["60637.3","0"],["60638.9","243"],["60639.4","0"],["60715.7","100"]]}}
1618677489.4459589: {"stream":"egldusd_perp@depth@100ms","data":{"e":"depthUpdate","E":1618677489392,"T":1618677489387,"s":"EGLDUSD_PERP","ps":"EGLDUSD","U":86143431984,"u":86143432616,"pu":86143431536,"b":[["215.961","0"],["215.962","0"],["215.976","97"],["215.977","22"],["216.005","0"],["216.015","54"]],"a":[]}}
1618677489.45042: {"stream":"ethusd_210625@depth@100ms","data":{"e":"depthUpdate","E":1618677489398,"T":1618677489348,"s":"ETHUSD_210625","ps":"ETHUSD","U":86143432007,"u":86143432345,"pu":86143431282,"b":[["2503.94","0"],["2504.09","2989"]],"a":[["2510.85","0"],["2511.04","7"],["2511.15","62"]]}}
1618677489.4708748: {"stream":"bchusd_210625@depth@100ms","data":{"e":"depthUpdate","E":1618677489418,"T":1618677489412,"s":"BCHUSD_210625","ps":"BCHUSD","U":86143432149,"u":86143432743,"pu":86143432131,"b":[["1115.83","1000"],["1120.40","0"],["1120.82","190"],["1123.70","250"],["1123.90","1000"],["1123.95","500"],["1124.04","286"],["1124.46","250"],["1124.64","0"],["1124.97","250"],["1125.47","141"],["1127.37","0"],["1127.95","0"],["1127.96","0"],["1128.00","0"],["1128.01","35"],["1128.03","64"]],"a":[["1137.39","1708"],["1138.57","0"]]}}
1618677489.490171: {"stream":"linkusd_210924@depth@100ms","data":{"e":"depthUpdate","E":1618677489437,"T":1618677489395,"s":"LINKUSD_210924","ps":"LINKUSD","U":86143432253,"u":86143432659,"pu":86143431333,"b":[["44.782","0"],["44.830","377"]],"a":[["45.364","0"],["45.384","0"],["45.436","250"],["45.451","3721"]]}}
1618677489.492678: {"stream":"xrpusd_210625@depth@100ms","data":{"e":"depthUpdate","E":1618677489439,"T":1618677489421,"s":"XRPUSD_210625","ps":"XRPUSD","U":86143432256,"u":86143432798,"pu":86143431981,"b":[["1.6835","291"],["1.6878","1920"],["1.6882","349"]],"a":[["1.6923","0"],["1.6924","45"],["1.6926","0"]]}}
1618677489.51551: {"stream":"dotusd_210625@depth@100ms","data":{"e":"depthUpdate","E":1618677489463,"T":1618677489456,"s":"DOTUSD_210625","ps":"DOTUSD","U":86143432407,"u":86143432981,"pu":86143432342,"b":[["46.501","1409"],["46.649","0"],["46.673","1"],["46.693","2"],["46.698","0"],["46.707","63"],["46.715","0"],["46.720","0"],["46.722","0"],["46.724","0"],["46.725","0"],["46.727","540"],["46.728","0"],["46.730","540"]],"a":[["46.736","0"],["46.737","0"],["46.738","0"],["46.740","200"],["46.744","0"],["46.773","84"],["46.792","0"],["46.793","0"],["46.838","250"],["46.859","250"],["46.876","250"],["46.892","250"],["46.908","250"]]}}
1618677489.534314: {"stream":"btcusd_perp@depth@100ms","data":{"e":"depthUpdate","E":1618677489482,"T":1618677489477,"s":"BTCUSD_PERP","ps":"BTCUSD","U":86143432566,"u":86143433105,"pu":86143432502,"b":[["60579.1","0"],["60579.2","30"],["60581.6","0"],["60583.7","32"],["60586.3","0"],["60589.5","13705"],["60589.7","0"]],"a":[["60593.9","151"],["60601.4","50"],["61084.8","0"]]}}
1618677489.560944: {"stream":"ethusd_210924@depth@100ms","data":{"e":"depthUpdate","E":1618677489508,"T":1618677489490,"s":"ETHUSD_210924","ps":"ETHUSD","U":86143432708,"u":86143433159,"pu":86143432239,"b":[["2686.13","6544"],["2686.73","0"]],"a":[["2689.80","2568"],["2694.52","500"],["2694.68","500"]]}}
1618677489.568653: {"stream":"btcusd_210924@depth@100ms","data":{"e":"depthUpdate","E":1618677489516,"T":1618677489440,"s":"BTCUSD_210924","ps":"BTCUSD","U":86143432740,"u":86143432894,"pu":86143431471,"b":[["68581.1","0"],["68581.2","0"],["68581.4","1549"],["68581.5","582"]],"a":[]}}
1618677489.57725: {"stream":"bchusd_210625@depth@100ms","data":{"e":"depthUpdate","E":1618677489526,"T":1618677489490,"s":"BCHUSD_210625","ps":"BCHUSD","U":86143432806,"u":86143433160,"pu":86143432743,"b":[["1121.67","353"],["1122.19","283"],["1128.01","0"],["1128.04","35"]],"a":[["1131.59","0"],["1132.02","100"],["1139.25","190"]]}}
1618677489.5826461: {"stream":"egldusd_perp@depth@100ms","data":{"e":"depthUpdate","E":1618677489529,"T":1618677489523,"s":"EGLDUSD_PERP","ps":"EGLDUSD","U":86143432815,"u":86143433327,"pu":86143432616,"b":[["215.976","0"],["215.991","97"],["216.015","0"]],"a":[["216.468","314"],["216.553","0"]]}}
1618677489.588393: {"stream":"ethusd_210625@depth@100ms","data":{"e":"depthUpdate","E":1618677489536,"T":1618677489525,"s":"ETHUSD_210625","ps":"ETHUSD","U":86143432858,"u":86143433333,"pu":86143432345,"b":[["2499.96","500"],["2503.18","2861"],["2504.09","0"]],"a":[["2511.65","721"],["2512.62","0"],["2514.64","1591"],["2517.14","0"]]}}
1618677489.601441: {"stream":"xrpusd_210625@depth@100ms","data":{"e":"depthUpdate","E":1618677489549,"T":1618677489445,"s":"XRPUSD_210625","ps":"XRPUSD","U":86143432919,"u":86143432919,"pu":86143432798,"b":[],"a":[["1.6925","198"]]}}
1618677489.617985: {"stream":"linkusd_210625@depth@100ms","data":{"e":"depthUpdate","E":1618677489564,"T":1618677489460,"s":"LINKUSD_210625","ps":"LINKUSD","U":86143432997,"u":86143433006,"pu":86143429686,"b":[["43.684","1250"],["43.697","250"],["43.709","1562"],["43.722","250"],["43.745","250"]],"a":[]}}
1618677489.6239219: {"stream":"dotusd_210625@depth@100ms","data":{"e":"depthUpdate","E":1618677489569,"T":1618677489565,"s":"DOTUSD_210625","ps":"DOTUSD","U":86143433026,"u":86143433590,"pu":86143432981,"b":[["46.418","0"],["46.701","63"],["46.707","0"],["46.719","0"],["46.727","0"],["46.730","0"],["46.731","0"],["46.732","540"],["46.733","0"],["46.735","540"],["46.736","203"]],"a":[["46.737","0"],["46.738","0"],["46.740","0"],["46.741","0"],["46.772","0"]]}}
1618677489.640169: {"stream":"btcusd_perp@depth@100ms","data":{"e":"depthUpdate","E":1618677489587,"T":1618677489583,"s":"BTCUSD_PERP","ps":"BTCUSD","U":86143433130,"u":86143433731,"pu":86143433105,"b":[["60230.1","100"],["60572.2","0"],["60572.4","0"],["60573.5","243"],["60579.2","0"],["60581.7","0"],["60582.0","815"],["60585.0","0"],["60586.2","30"],["60586.3","243"],["60587.1","0"],["60588.5","243"],["60589.6","0"],["60589.7","0"],["60590.2","0"],["60590.6","0"],["60592.4","0"]],"a":[["60589.6","569"],["60593.9","1"],["60596.0","0"],["60597.5","407"],["60601.4","0"],["60602.0","96"],["60606.3","0"],["60611.2","0"],["60802.7","0"]]}}
1618677489.640456: {"stream":"linkusd_210924@depth@100ms","data":{"e":"depthUpdate","E":1618677489589,"T":1618677489582,"s":"LINKUSD_210924","ps":"LINKUSD","U":86143433142,"u":86143433715,"pu":86143432659,"b":[["45.241","335"],["45.251","0"],["45.259","100"],["45.260","21"]],"a":[["45.426","1741"],["45.435","0"]]}}
1618677489.681134: {"stream":"bchusd_210625@depth@100ms","data":{"e":"depthUpdate","E":1618677489627,"T":1618677489619,"s":"BCHUSD_210625","ps":"BCHUSD","U":86143433330,"u":86143434154,"pu":86143433160,"b":[["1128.00","13"]],"a":[["1129.45","22"],["1129.51","0"],["1129.52","0"],["1132.02","0"],["1132.21","359"],["1137.39","0"],["1138.57","1747"],["1139.25","0"],["1139.70","0"]]}}
1618677489.691763: {"stream":"egldusd_perp@depth@100ms","data":{"e":"depthUpdate","E":1618677489640,"T":1618677489577,"s":"EGLDUSD_PERP","ps":"EGLDUSD","U":86143433406,"u":86143433693,"pu":86143433327,"b":[["215.961","97"],["215.977","0"],["215.991","0"],["216.001","54"]],"a":[]}}
1618677489.721843: {"stream":"dotusd_210625@depth@100ms","data":{"e":"depthUpdate","E":1618677489670,"T":1618677489660,"s":"DOTUSD_210625","ps":"DOTUSD","U":86143433614,"u":86143434811,"pu":86143433590,"b":[["46.233","0"],["46.520","0"],["46.619","0"],["46.691","897"],["46.692","189"],["46.701","0"],["46.715","63"],["46.732","0"],["46.733","100"],["46.735","0"],["46.736","0"],["46.737","540"],["46.738","0"]],"a":[["46.752","0"],["46.770","200"],["46.771","796"],["46.773","84"],["46.774","0"],["46.793","0"],["46.797","200"],["46.803","0"],["46.838","0"],["47.033","0"]]}}
1618677489.734623: {"stream":"ethusd_210924@depth@100ms","data":{"e":"depthUpdate","E":1618677489681,"T":1618677489668,"s":"ETHUSD_210924","ps":"ETHUSD","U":86143433702,"u":86143434954,"pu":86143433159,"b":[],"a":[["2689.80","2688"],["2691.82","1771"],["2694.52","0"],["2694.68","0"],["2702.62","0"]]}}
1618677489.7434082: {"stream":"btcusd_perp@depth@100ms","data":{"e":"depthUpdate","E":1618677489691,"T":1618677489681,"s":"BTCUSD_PERP","ps":"BTCUSD","U":86143433732,"u":86143435070,"pu":86143433731,"b":[["60571.9","0"],["60572.1","32"],["60573.2","243"],["60573.4","122"],["60573.5","0"],["60573.7","0"],["60578.8","1"],["60579.6","10"],["60583.5","100"],["60584.7","40"],["60586.0","243"],["60586.2","0"],["60586.3","0"],["60586.9","0"],["60587.2","0"],["60588.1","273"],["60588.5","0"],["60589.6","0"],["60589.7","0"],["60589.8","0"],["60589.9","0"],["60590.0","0"],["60590.1","0"],["60590.2","0"],["60590.3","0"],["60590.4","0"],["60590.6","0"],["60590.8","0"],["60591.0","0"],["60591.2","0"],["60591.4","0"],["60591.5","0"],["60591.6","0"],["60591.7","0"],["60591.8","0"],["60591.9","0"],["60592.0","0"],["60592.1","0"],["60592.2","0"],["60592.3","0"],["60592.4","0"],["60592.6","0"],["60592.8","0"],["60593.0","0"],["60593.2","0"],["60593.4","0"],["60593.5","0"],["60593.6","0"],["60593.7","0"],["60593.8","0"],["60593.9","0"],["60594.0","0"],["60594.1","0"],["60594.2","0"],["60594.3","0"],["60594.4","0"],["60594.6","0"],["60594.7","0"],["60594.8","0"],["60594.9","0"],["60595.0","0"],["60595.2","0"],["60595.4","0"],["60595.5","0"],["60595.6","0"],["60595.7","0"],["60595.8","0"],["60595.9","0"],["60596.0","0"],["60596.1","0"],["60596.2","0"],["60596.3","0"],["60596.4","0"],["60596.6","0"],["60596.8","0"],["60597.0","0"],["60597.2","0"],["60597.4","0"],["60597.5","0"],["60597.7","0"],["60597.9","0"],["60598.1","0"],["60598.3","0"],["60598.4","0"],["60598.6","0"]],"a":[["60589.6","213"],["60590.0","0"],["60594.5","40"],["60594.8","0"],["60595.6","0"],["60596.1","0"],["60596.6","397"],["60596.7","0"],["60597.5","287"],["60598.2","197"],["60598.8","400"],["60600.4","201"],["60601.2","10"],["60601.4","0"],["60603.1","1"],["60606.0","20"],["60606.6","0"],["60606.9","0"],["60611.5","0"],["60613.1","1492"],["60613.9","2049"],["60615.2","0"],["60619.7","0"],["60624.0","30"],["60626.7","243"],["60627.9","2"],["60632.5","909"],["60634.6","0"],["60636.8","0"],["60638.9","0"],["60639.5","243"],["60640.7","368"],["60641.6","243"],["60642.9","350"]]}}
1618677489.744171: {"stream":"xrpusd_210625@depth@100ms","data":{"e":"depthUpdate","E":1618677489692,"T":1618677489595,"s":"XRPUSD_210625","ps":"XRPUSD","U":86143433803,"u":86143433843,"pu":86143432919,"b":[],"a":[["1.6920","45"],["1.6924","0"],["1.7037","0"]]}}
1618677489.779605: {"stream":"linkusd_210625@depth@100ms","data":{"e":"depthUpdate","E":1618677489725,"T":1618677489645,"s":"LINKUSD_210625","ps":"LINKUSD","U":86143434219,"u":86143434598,"pu":86143433006,"b":[["43.585","0"]],"a":[["43.832","0"],["43.840","408"]]}}
1618677489.785973: {"stream":"bchusd_210625@depth@100ms","data":{"e":"depthUpdate","E":1618677489733,"T":1618677489729,"s":"BCHUSD_210625","ps":"BCHUSD","U":86143434303,"u":86143435683,"pu":86143434154,"b":[["1115.19","1000"],["1115.83","0"],["1116.65","350"],["1120.43","190"],["1120.82","0"],["1123.25","1000"],["1123.31","0"],["1123.70","0"],["1123.90","0"],["1123.95","0"],["1124.45","173"],["1124.82","141"],["1125.47","0"],["1127.37","0"],["1127.38","0"],["1127.99","0"],["1128.00","0"],["1128.04","0"],["1128.05","17"],["1128.06","0"],["1128.07","0"],["1128.08","64"],["1128.09","35"]],"a":[["1139.84","190"]]}}
1618677489.802219: {"stream":"btcusd_210924@depth@100ms","data":{"e":"depthUpdate","E":1618677489748,"T":1618677489735,"s":"BTCUSD_210924","ps":"BTCUSD","U":86143434531,"u":86143435819,"pu":86143432894,"b":[["68581.3","0"],["68589.9","1081"],["68590.0","272"]],"a":[["68677.4","0"]]}}
1618677489.806056: {"stream":"egldusd_perp@depth@100ms","data":{"e":"depthUpdate","E":1618677489751,"T":1618677489735,"s":"EGLDUSD_PERP","ps":"EGLDUSD","U":86143434615,"u":86143435802,"pu":86143433693,"b":[["215.971","0"],["216.001","0"],["216.011","54"]],"a":[["216.071","41"],["216.074","0"]]}}
1618677489.831933: {"stream":"ethusd_210924@depth@100ms","data":{"e":"depthUpdate","E":1618677489781,"T":1618677489777,"s":"ETHUSD_210924","ps":"ETHUSD","U":86143435030,"u":86143436405,"pu":86143434954,"b":[["2686.14","3272"],["2686.15","2329"],["2687.30","0"],["2687.31","0"],["2689.20","660"],["2689.58","0"]],"a":[["2702.77","250"]]}}
1618677489.835049: {"stream":"dotusd_210625@depth@100ms","data":{"e":"depthUpdate","E":1618677489782,"T":1618677489773,"s":"DOTUSD_210625","ps":"DOTUSD","U":86143435035,"u":86143436353,"pu":86143434811,"b":[["46.200","40"],["46.376","1055"],["46.620","665"],["46.626","0"],["46.738","113"]],"a":[["46.764","540"],["46.765","200"],["46.766","256"],["46.767","0"],["46.768","540"],["46.769","84"],["46.770","0"],["46.771","0"],["46.773","0"],["46.791","50"],["46.793","0"],["46.797","0"],["46.798","0"],["46.964","1200"],["46.965","140"],["47.072","50"],["47.079","0"],["47.222","1338"]]}}
1618677489.8615959: {"stream":"btcusd_perp@depth@100ms","data":{"e":"depthUpdate","E":1618677489803,"T":1618677489782,"s":"BTCUSD_PERP","ps":"BTCUSD","U":86143435095,"u":86143436490,"pu":86143435070,"b":[["60472.4","0"],["60475.9","30"],["60487.2","0"],["60498.6","1090"],["60499.3","0"],["60510.7","1000"],["60523.5","0"],["60529.5","45"],["60540.9","400"],["60567.9","0"],["60570.5","0"],["60570.8","120"],["60573.2","0"],["60573.4","80"],["60573.7","243"],["60573.9","0"],["60574.5","0"],["60574.6","79"],["60574.7","79"],["60577.4","79"],["60577.5","0"],["60577.9","0"],["60579.7","0"],["60580.6","0"],["60582.6","15"],["60582.8","0"],["60583.1","50"],["60583.6","1507"],["60584.7","0"],["60585.6","50"],["60586.0","0"],["60586.5","243"],["60588.1","30"],["60588.4","243"],["60589.5","1529"],["60589.6","180"],["60589.7","180"],["60589.8","0"],["60589.9","0"],["60590.0","180"],["60590.1","180"],["60590.2","0"],["60590.3","0"],["60590.4","180"],["60590.5","0"],["60590.6","0"],["60590.7","0"],["60590.8","360"],["60590.9","0"],["60591.0","180"],["60591.1","0"],["60591.2","0"],["60591.3","0"],["60591.4","0"],["60591.5","0"],["60591.6","180"],["60591.7","0"],["60591.8","180"],["60591.9","0"],["60592.0","180"],["60592.1","180"],["60592.2","180"],["60592.3","0"],["60592.4","14748"],["60592.5","0"],["60592.6","0"],["60592.7","0"],["60592.8","0"],["60592.9","0"],["60593.0","0"],["60593.1","0"],["60593.2","0"],["60593.3","0"],["60593.4","0"],["60593.5","0"],["60593.6","0"],["60593.7","0"],["60593.8","0"],["60593.9","0"],["60594.0","0"],["60594.1","0"],["60594.2","0"],["60594.3","0"],["60594.4","0"],["60594.5","0"],["60594.6","0"],["60594.7","0"],["60594.8","0"],["60594.9","0"],["60595.0","0"],["60595.1","0"],["60595.2","0"],["60595.4","0"],["60595.5","0"],["60595.6","0"],["60595.7","0"],["60595.8","0"],["60595.9","0"],["60596.0","0"],["60596.1","0"],["60596.2","0"],["60596.3","0"],["60596.4","0"],["60596.5","0"],["60596.6","0"],["60596.7","0"],["60596.8","0"],["60596.9","0"],["60597.0","0"],["60597.1","0"],["60597.2","0"],["60597.3","0"],["60597.4","0"],["60597.5","0"],["60597.6","0"],["60597.7","0"],["60597.8","0"],["60597.9","0"],["60598.0","0"],["60598.1","0"],["60598.3","0"],["60598.4","0"],["60598.5","0"],["60598.6","0"],["60598.7","0"],["60598.8","0"],["60598.9","0"],["60599.0","0"],["60599.1","0"],["60599.2","0"],["60599.3","0"],["60599.5","0"],["60599.7","0"],["60599.9","0"],["60600.1","0"],["60600.3","0"]],"a":[["60589.6","0"],["60592.5","405"],["60594.5","0"],["60597.5","257"],["60597.6","291"],["60599.1","218"],["60599.2","30"],["60599.5","0"],["60600.6","40"],["60601.1","0"],["60601.2","10"],["60602.5","50"],["60602.6","0"],["60603.1","1"],["60604.6","0"],["60611.1","0"],["60613.9","1927"],["60615.0","0"],["60615.2","122"],["60616.0","1658"],["60626.7","0"],["60627.8","0"],["60628.0","243"],["60628.8","16"],["60632.6","0"],["60638.7","0"],["60639.5","0"],["60640.6","0"],["60640.8","243"],["60641.6","0"],["60642.7","8"],["60642.9","593"],["60643.7","283"],["60644.0","402"],["60662.9","0"],["60675.0","3"],["60685.1","1000"],["60686.4","1000"],["60822.4","0"],["60906.7","99"]]}}
1618677489.862514: {"stream":"xrpusd_210625@depth@100ms","data":{"e":"depthUpdate","E":1618677489805,"T":1618677489701,"s":"XRPUSD_210625","ps":"XRPUSD","U":86143435332,"u":86143435358,"pu":86143433843,"b":[],"a":[["1.6920","0"],["1.6924","45"]]}}
1618677489.8877: {"stream":"linkusd_210625@depth@100ms","data":{"e":"depthUpdate","E":1618677489832,"T":1618677489729,"s":"LINKUSD_210625","ps":"LINKUSD","U":86143435677,"u":86143435677,"pu":86143434598,"b":[["43.587","180"]],"a":[]}}
1618677489.911176: {"stream":"ethusd_210625@depth@100ms","data":{"e":"depthUpdate","E":1618677489857,"T":1618677489849,"s":"ETHUSD_210625","ps":"ETHUSD","U":86143435892,"u":86143437314,"pu":86143433333,"b":[["2505.35","0"],["2505.36","1002"],["2505.42","0"],["2505.46","0"],["2505.71","1001"],["2505.72","0"],["2505.73","0"],["2505.87","0"],["2506.03","0"],["2506.04","0"],["2506.06","0"],["2506.12","0"],["2506.15","1506"],["2506.20","112"],["2506.21","0"],["2506.23","0"],["2506.24","0"],["2506.38","0"],["2506.39","856"],["2506.40","0"],["2506.41","0"],["2506.46","0"],["2506.49","0"],["2506.51","1204"],["2506.53","0"],["2506.54","0"],["2506.57","0"],["2506.58","0"],["2506.59","0"],["2506.60","0"],["2506.63","0"],["2506.68","0"],["2506.70","1652"],["2506.72","0"],["2506.76","0"],["2506.77","0"],["2506.79","0"],["2506.80","0"],["2506.84","0"],["2506.85","0"],["2506.87","0"],["2506.88","0"],["2506.93","12"],["2506.95","0"],["2507.00","0"],["2507.05","0"],["2507.06","0"],["2507.08","21766"],["2507.11","1529"],["2507.15","963"],["2507.17","0"],["2507.26","0"],["2507.32","1133"],["2507.34","2894"],["2507.42","0"],["2507.45","0"],["2507.49","1354"],["2507.51","771"],["2507.55","839"],["2507.57","0"],["2507.80","616"],["2507.83","1053"],["2507.87","1194"],["2508.14","835"]],"a":[["2510.85","0"],["2511.05","1442"],["2511.31","839"],["2511.37","616"],["2511.50","1133"],["2511.58","771"],["2511.78","2194"],["2511.80","1529"],["2511.81","963"],["2511.82","1204"],["2511.83","1053"],["2511.88","1652"],["2511.92","1194"],["2511.96","1506"],["2511.97","0"],["2512.41","0"],["2512.42","0"],["2512.44","0"],["2512.80","0"],["2512.83","0"],["2512.86","0"],["2512.87","0"],["2512.92","0"],["2513.07","5180"],["2513.09","0"],["2513.15","0"],["2513.16","0"],["2513.23","0"],["2513.27","6065"],["2513.31","0"],["2513.36","0"],["2513.37","0"],["2513.38","0"],["2513.46","0"],["2513.47","0"],["2513.58","0"],["2513.66","0"],["2513.79","0"],["2513.82","0"],["2513.88","0"],["2513.96","0"],["2513.97","0"],["2513.98","0"],["2514.07","0"],["2514.14","0"],["2514.17","0"],["2514.24","0"],["2514.30","0"],["2514.34","0"],["2514.36","0"],["2514.40","0"],["2514.48","0"],["2514.50","0"],["2514.51","0"],["2514.61","0"],["2514.63","0"],["2514.65","0"],["2514.71","0"],["2514.73","105"],["2514.78","0"],["2514.86","0"],["2514.90","2988"],["2514.95","500"],["2515.04","0"],["2515.30","0"]]}}
1618677489.9165041: {"stream":"egldusd_perp@depth@100ms","data":{"e":"depthUpdate","E":1618677489862,"T":1618677489757,"s":"EGLDUSD_PERP","ps":"EGLDUSD","U":86143436129,"u":86143436133,"pu":86143435802,"b":[["215.971","54"],["216.011","0"]],"a":[]}}
1618677489.918709: {"stream":"btcusd_210924@depth@100ms","data":{"e":"depthUpdate","E":1618677489866,"T":1618677489847,"s":"BTCUSD_210924","ps":"BTCUSD","U":86143436194,"u":86143437278,"pu":86143435819,"b":[["68599.0","0"]],"a":[["68677.3","0"],["68688.1","204"],["68688.2","621"],["68736.4","0"]]}}
1618677489.923894: {"stream":"bchusd_210625@depth@100ms","data":{"e":"depthUpdate","E":1618677489871,"T":1618677489850,"s":"BCHUSD_210625","ps":"BCHUSD","U":86143436241,"u":86143437318,"pu":86143435683,"b":[["1120.43","0"],["1120.83","190"],["1122.85","0"],["1122.90","1095"],["1128.03","0"],["1128.05","0"],["1128.09","0"],["1128.10","0"],["1128.11","0"],["1128.12","64"],["1128.13","35"]],"a":[]}}
1618677489.925596: {"stream":"linkusd_210924@depth@100ms","data":{"e":"depthUpdate","E":1618677489871,"T":1618677489792,"s":"LINKUSD_210924","ps":"LINKUSD","U":86143436236,"u":86143436645,"pu":86143433715,"b":[],"a":[["45.405","183"],["45.406","870"],["45.407","0"],["45.408","0"]]}}
1618677489.938616: {"stream":"dotusd_210625@depth@100ms","data":{"e":"depthUpdate","E":1618677489883,"T":1618677489874,"s":"DOTUSD_210625","ps":"DOTUSD","U":86143436425,"u":86143437712,"pu":86143436353,"b":[["46.607","1014"],["46.645","2"],["46.693","0"]],"a":[["46.756","540"],["46.758","200"],["46.759","540"],["46.761","256"],["46.762","0"],["46.763","84"],["46.765","0"],["46.766","0"],["46.768","192"],["46.769","0"],["47.087","1126"]]}}
1618677489.943916: {"stream":"ethusd_210924@depth@100ms","data":{"e":"depthUpdate","E":1618677489892,"T":1618677489870,"s":"ETHUSD_210924","ps":"ETHUSD","U":86143436572,"u":86143437601,"pu":86143436405,"b":[["2687.96","500"],["2688.71","0"],["2689.20","0"],["2689.63","0"],["2689.79","1000"]],"a":[["2689.80","48"]]}}
1618677489.9738612: {"stream":"btcusd_perp@depth@100ms","data":{"e":"depthUpdate","E":1618677489916,"T":1618677489895,"s":"BTCUSD_PERP","ps":"BTCUSD","U":86143436492,"u":86143438084,"pu":86143436490,"b":[["57562.7","120"],["60496.0","85"],["60498.6","2090"],["60512.0","23"],["60512.5","0"],["60513.0","200"],["60513.5","250"],["60514.0","0"],["60534.9","1000"],["60536.8","0"],["60570.8","0"],["60573.6","0"],["60573.7","0"],["60574.6","0"],["60574.7","485"],["60574.9","553"],["60575.2","0"],["60578.1","1743"],["60578.3","122"],["60580.0","1"],["60581.5","400"],["60583.0","25"],["60583.6","1492"],["60583.7","0"],["60584.3","0"],["60585.0","50"],["60586.5","0"],["60588.1","0"],["60588.4","0"],["60588.5","1"],["60588.7","32"],["60589.5","1514"],["60589.6","0"],["60589.7","0"],["60589.8","0"],["60590.0","0"],["60590.1","30"],["60590.2","0"],["60590.4","0"],["60590.6","0"],["60590.8","0"],["60591.0","243"],["60591.4","0"],["60591.6","0"],["60591.8","0"],["60591.9","40"],["60592.0","0"],["60592.1","0"],["60592.2","0"],["60592.4","15460"],["60592.5","151"],["60592.6","0"],["60592.7","220"],["60592.8","0"],["60592.9","0"],["60593.0","0"],["60593.1","0"],["60593.2","0"],["60593.3","0"],["60593.4","0"],["60593.5","0"],["60593.6","0"],["60593.7","0"],["60593.8","120"],["60593.9","0"],["60594.0","0"],["60594.1","0"],["60594.2","0"],["60594.3","0"],["60594.4","0"],["60594.5","0"],["60594.6","0"],["60594.7","0"],["60594.8","0"],["60594.9","0"],["60595.0","0"],["60595.1","0"],["60595.2","0"],["60595.3","0"],["60595.4","0"],["60595.5","0"],["60595.6","0"],["60595.7","0"],["60595.8","0"],["60595.9","0"],["60596.0","0"],["60596.1","0"],["60596.2","0"],["60596.3","0"],["60596.4","0"],["60596.5","0"],["60596.6","0"],["60596.7","0"],["60596.8","0"],["60596.9","0"],["60597.0","0"],["60597.1","0"],["60597.2","0"],["60597.3","0"],["60597.4","0"],["60597.5","0"],["60597.7","0"],["60597.9","0"],["60598.1","0"],["60598.2","0"],["60598.3","0"],["60598.5","0"],["60598.7","0"],["60598.9","0"],["60599.1","0"],["60599.3","0"],["60599.4","0"],["60599.5","0"],["60599.7","0"],["60599.9","0"],["60600.1","0"],["60600.3","0"],["60600.5","0"],["60600.7","0"],["60600.9","0"],["60601.1","0"],["60601.3","0"],["60601.5","0"],["60601.7","0"],["60601.9","0"],["60602.1","0"],["60602.3","0"]],"a":[["60592.5","0"],["60597.3","0"],["60597.6","291"],["60599.2","0"],["60599.8","0"],["60600.1","30"],["60600.6","0"],["60602.0","0"],["60602.5","200"],["60605.0","25"],["60607.0","96"],["60608.2","0"],["60615.2","0"],["60615.3","0"],["60615.4","0"],["60616.7","162"],["60628.0","0"],["60629.5","259"],["60640.8","0"],["60642.3","243"],["60642.9","350"],["60644.4","243"],["60650.1","2501"],["60674.3","1002"],["60708.8","0"],["60728.8","100"],["60811.3","1789"],["60887.1","0"]]}}
1618677490.018568: {"stream":"ethusd_210625@depth@100ms","data":{"e":"depthUpdate","E":1618677489960,"T":1618677489942,"s":"ETHUSD_210625","ps":"ETHUSD","U":86143437342,"u":86143438890,"pu":86143437314,"b":[["2503.39","0"],["2505.31","3037"],["2505.39","3037"],["2505.45","3037"],["2505.66","3254"],["2505.71","3821"],["2505.82","3254"],["2505.98","3471"],["2506.05","2820"],["2506.11","2603"],["2506.15","3892"],["2506.17","2820"],["2506.19","2804"],["2506.20","3149"],["2506.36","2169"],["2506.38","2386"],["2506.39","5007"],["2506.45","2386"],["2506.48","1982"],["2506.51","3156"],["2506.52","2169"],["2506.53","1735"],["2506.54","1321"],["2506.57","1321"],["2506.58","881"],["2506.59","1982"],["2506.60","1952"],["2506.67","1952"],["2506.72","2863"],["2506.73","1735"],["2506.75","2169"],["2506.79","1321"],["2506.84","1321"],["2506.86","1735"],["2506.87","1518"],["2506.92","1518"],["2506.93","1530"],["2506.94","0"],["2506.95","881"],["2507.03","1518"],["2507.09","391"],["2507.10","978"],["2507.12","782"],["2507.26","1084"],["2507.33","1301"],["2507.42","1301"],["2507.45","1084"],["2507.57","1301"],["2510.10","0"],["2510.20","0"],["2510.30","0"],["2510.50","100"],["2510.60","100"],["2510.70","100"],["2510.86","1425"]],"a":[["2510.85","0"],["2510.87","2262"],["2510.99","121"],["2511.04","0"],["2511.15","491"],["2511.97","1535"],["2512.41","391"],["2512.42","391"],["2512.44","782"],["2512.72","1084"],["2512.79","1084"],["2512.80","587"],["2512.83","587"],["2512.86","587"],["2512.88","1518"],["2513.05","2299"],["2513.10","3471"],["2513.11","1735"],["2513.12","881"],["2513.14","1518"],["2513.15","1518"],["2513.16","587"],["2513.21","23417"],["2513.22","4473"],["2513.27","0"],["2513.28","1301"],["2513.30","881"],["2513.33","1952"],["2513.37","1301"],["2513.38","1321"],["2513.43","1735"],["2513.54","1982"],["2513.55","2169"],["2513.61","3452"],["2513.75","1952"],["2513.80","1321"],["2513.88","1321"],["2513.93","1982"],["2513.95","2169"],["2514.05","4555"],["2514.25","2169"],["2514.31","2386"],["2514.37","5761"],["2514.40","2820"],["2514.42","2603"],["2514.50","2603"],["2514.57","2820"],["2514.60","2386"],["2514.63","5857"],["2514.66","3037"],["2514.67","1982"],["2514.76","2820"],["2514.77","1982"],["2514.90","6242"],["2515.30","3254"]]}}
1618677490.039895: {"stream":"dotusd_210625@depth@100ms","data":{"e":"depthUpdate","E":1618677489988,"T":1618677489965,"s":"DOTUSD_210625","ps":"DOTUSD","U":86143437940,"u":86143439389,"pu":86143437712,"b":[],"a":[["46.755","0"],["46.757","200"],["46.758","0"],["46.759","0"],["46.763","0"],["46.764","0"],["46.790","84"],["46.940","311"],["46.957","40"],["47.087","0"]]}}
1618677490.057409: {"stream":"linkusd_210625@depth@100ms","data":{"e":"depthUpdate","E":1618677489946,"T":1618677489922,"s":"LINKUSD_210625","ps":"LINKUSD","U":86143437225,"u":86143438437,"pu":86143435677,"b":[["43.587","0"]],"a":[["43.833","0"]]}}
1618677490.063266: {"stream":"bchusd_210625@depth@100ms","data":{"e":"depthUpdate","E":1618677489983,"T":1618677489970,"s":"BCHUSD_210625","ps":"BCHUSD","U":86143437824,"u":86143439446,"pu":86143437318,"b":[["1120.43","190"],["1120.83","0"],["1124.84","230"]],"a":[]}}
1618677490.0633779: {"stream":"egldusd_perp@depth@100ms","data":{"e":"depthUpdate","E":1618677489992,"T":1618677489978,"s":"EGLDUSD_PERP","ps":"EGLDUSD","U":86143437989,"u":86143439536,"pu":86143436133,"b":[["215.537","774"],["215.604","0"],["215.971","0"],["215.981","54"],["216.068","170"]],"a":[["216.092","0"],["216.154","0"],["216.171","97"],["216.396","0"],["216.491","484"]]}}
1618677490.0668108: {"stream":"ethusd_210924@depth@100ms","data":{"e":"depthUpdate","E":1618677490006,"T":1618677489996,"s":"ETHUSD_210924","ps":"ETHUSD","U":86143438150,"u":86143440002,"pu":86143437601,"b":[["2686.14","0"],["2686.73","3272"]],"a":[["2689.80","2424"]]}}
1618677490.0726871: {"stream":"btcusd_210924@depth@100ms","data":{"e":"depthUpdate","E":1618677490014,"T":1618677490009,"s":"BTCUSD_210924","ps":"BTCUSD","U":86143438289,"u":86143440157,"pu":86143437278,"b":[["68142.6","0"],["68157.4","160"],["68521.7","0"],["68562.4","251"],["68597.0","0"],["68599.3","0"],["68606.8","50"],["68611.5","0"],["68613.1","0"],["68614.2","100"],["68630.0","0"],["68631.0","0"],["68631.9","0"],["68632.0","196"],["68632.1","0"],["68632.2","90"],["68632.3","90"],["68635.5","0"],["68635.6","0"],["68650.0","10"],["68651.0","10"],["68652.0","458"]],"a":[["68632.1","0"],["68652.1","145"],["68652.2","0"],["68652.3","0"],["68655.8","0"],["68655.9","0"],["68664.0","16"],["68667.2","0"],["68672.1","100"],["68673.4","0"],["68674.2","59"],["68674.3","277"],["68677.0","50"],["68688.4","0"]]}}
1618677490.104502: {"stream":"linkusd_210924@depth@100ms","data":{"e":"depthUpdate","E":1618677490052,"T":1618677490047,"s":"LINKUSD_210924","ps":"LINKUSD","U":86143439110,"u":86143441042,"pu":86143436645,"b":[["45.245","0"],["45.246","1385"]],"a":[["45.309","0"]]}}
1618677490.109133: {"stream":"btcusd_perp@depth@100ms","data":{"e":"depthUpdate","E":1618677490054,"T":1618677489993,"s":"BTCUSD_PERP","ps":"BTCUSD","U":86143438087,"u":86143439950,"pu":86143438084,"b":[["57562.7","0"],["57564.1","120"],["59017.4","0"],["59027.2","50"],["60217.2","0"],["60227.0","52"],["60450.5","0"],["60454.8","500"],["60481.7","0"],["60485.6","0"],["60496.0","8"],["60498.8","44"],["60503.1","500"],["60515.5","30"],["60519.9","501"],["60533.8","0"],["60552.4","300"],["60558.3","300"],["60558.7","0"],["60562.1","0"],["60565.5","0"],["60566.8","0"],["60573.4","0"],["60574.8","80"],["60576.7","0"],["60577.2","0"],["60577.4","0"],["60577.5","0"],["60578.1","1500"],["60578.3","0"],["60578.8","323"],["60579.0","122"],["60580.5","0"],["60580.7","305"],["60583.6","895"],["60587.4","0"],["60587.9","15"],["60588.7","0"],["60589.5","614"],["60589.6","32"],["60591.0","0"],["60591.7","243"],["60592.4","700"],["60592.5","0"],["60592.6","0"],["60592.7","0"],["60592.8","200"],["60592.9","0"],["60593.1","0"],["60593.3","0"],["60593.4","0"],["60593.5","0"],["60593.6","1120"],["60593.7","0"],["60593.8","12778"],["60593.9","580"],["60594.0","580"],["60594.1","580"],["60594.2","180"],["60594.3","580"],["60594.4","405"],["60594.5","580"],["60594.6","180"],["60594.7","580"],["60594.8","180"],["60594.9","805"],["60595.0","180"],["60595.1","805"],["60595.2","180"],["60595.3","805"],["60595.4","180"],["60595.5","805"],["60595.6","180"],["60595.7","6888"],["60595.8","550"],["60595.9","580"],["60596.0","405"],["60596.1","580"],["60596.2","1705"],["60596.3","0"],["60596.4","0"],["60596.5","0"],["60596.6","0"],["60596.7","0"],["60596.8","0"],["60596.9","0"],["60597.0","0"],["60597.1","0"],["60597.2","0"],["60597.3","0"],["60597.4","0"],["60597.5","0"],["60597.6","0"],["60597.7","0"],["60597.8","0"],["60597.9","0"],["60598.0","0"],["60598.1","0"],["60598.2","0"],["60598.3","0"],["60598.4","0"],["60598.5","0"],["60598.6","0"],["60598.7","0"],["60598.8","0"],["60598.9","0"],["60599.0","0"],["60599.1","0"],["60599.2","0"],["60599.3","0"],["60599.5","0"],["60599.7","0"],["60599.8","0"],["60599.9","0"],["60600.0","0"],["60600.1","0"],["60600.2","0"],["60600.3","0"],["60600.4","0"],["60600.5","0"],["60600.6","0"],["60600.7","0"],["60600.9","0"],["60601.1","0"],["60601.3","0"],["60601.5","0"],["60601.7","0"],["60601.8","0"],["60601.9","0"],["60602.0","0"],["60602.1","0"],["60602.2","0"],["60602.3","0"],["60602.4","0"],["60602.5","0"],["60602.6","0"],["60602.7","0"],["60602.9","0"],["60603.1","0"],["60603.3","0"],["60603.5","0"],["60603.7","0"],["60653.1","0"]],"a":[["60592.5","0"],["60593.9","0"],["60595.8","0"],["60596.6","367"],["60597.7","341"],["60598.0","0"],["60600.1","0"],["60600.3","10"],["60601.9","30"],["60602.5","50"],["60602.8","30"],["60603.9","548"],["60605.4","0"],["60605.6","40"],["60608.7","0"],["60615.8","438"],["60616.7","40"],["60618.0","0"],["60619.0","555"],["60620.2","16"],["60620.5","122"],["60628.2","0"],["60629.5","16"],["60631.8","0"],["60633.0","243"],["60642.3","0"],["60644.4","0"],["60644.6","0"],["60645.8","243"],["60646.7","0"],["60647.9","243"],["60680.4","0"],["60684.7","500"],["60700.0","475"],["60723.9","0"],["60728.9","0"],["60729.5","1050"],["60733.2","919"],["60786.4","0"]]}}
1618677490.113698: {"stream":"linkusd_210625@depth@100ms","data":{"e":"depthUpdate","E":1618677490056,"T":1618677490045,"s":"LINKUSD_210625","ps":"LINKUSD","U":86143439231,"u":86143441012,"pu":86143438437,"b":[["43.589","481"],["43.754","498"],["43.756","102"],["43.757","42"],["43.759","51"],["43.762","100"],["43.764","100"]],"a":[["43.790","1"],["43.792","0"],["43.794","0"],["43.798","100"],["43.800","100"],["43.802","100"],["43.840","0"],["43.853","408"]]}}
1618677490.1139798: {"stream":"xrpusd_210625@depth@100ms","data":{"e":"depthUpdate","E":1618677490058,"T":1618677490045,"s":"XRPUSD_210625","ps":"XRPUSD","U":86143439248,"u":86143441011,"pu":86143435358,"b":[["1.6835","211"]],"a":[["1.6920","0"],["1.6925","48"],["1.6935","0"],["1.7036","80"]]}}
1618677490.1557682: {"stream":"egldusd_perp@depth@100ms","data":{"e":"depthUpdate","E":1618677490101,"T":1618677490090,"s":"EGLDUSD_PERP","ps":"EGLDUSD","U":86143440009,"u":86143441948,"pu":86143439536,"b":[["215.537","0"],["215.587","0"],["215.604","783"],["215.720","0"],["215.860","5"],["215.961","0"],["215.985","97"],["215.986","21"]],"a":[["216.145","16"],["216.155","0"],["216.190","0"],["216.265","2"],["216.290","0"],["216.291","0"],["216.292","0"],["216.346","467"],["216.347","106"],["216.348","0"],["216.349","0"],["216.350","0"],["216.395","0"]]}}
1618677490.164414: {"stream":"dotusd_210625@depth@100ms","data":{"e":"depthUpdate","E":1618677490108,"T":1618677490094,"s":"DOTUSD_210625","ps":"DOTUSD","U":86143440067,"u":86143441977,"pu":86143439389,"b":[["46.596","528"],["46.613","140"],["46.633","0"],["46.650","78"]],"a":[["46.757","0"],["46.799","0"],["46.814","200"],["46.835","0"],["46.884","12"],["46.940","0"],["46.962","502"],["47.224","1417"]]}}
1618677490.164771: {"stream":"ethusd_210924@depth@100ms","data":{"e":"depthUpdate","E":1618677490111,"T":1618677490103,"s":"ETHUSD_210924","ps":"ETHUSD","U":86143440129,"u":86143442148,"pu":86143440002,"b":[["2689.58","461"],["2689.63","726"],["2689.79","340"]],"a":[["2689.80","2088"],["2691.12","0"],["2692.25","1495"],["2698.51","0"]]}}
1618677490.166944: {"stream":"ethusd_210625@depth@100ms","data":{"e":"depthUpdate","E":1618677490111,"T":1618677490026,"s":"ETHUSD_210625","ps":"ETHUSD","U":86143438893,"u":86143440677,"pu":86143438890,"b":[["2503.35","2961"],["2503.75","400"],["2505.31","6508"],["2505.72","2820"],["2506.03","2603"],["2506.37","2603"],["2506.70","2533"],["2506.76","2386"],["2507.09","978"],["2510.57","0"],["2510.71","299"]],"a":[["2510.87","2383"],["2510.99","0"],["2511.65","0"],["2513.33","7551"],["2513.47","881"],["2513.77","1952"],["2514.09","2603"],["2514.21","2386"],["2514.37","0"],["2514.48","3037"],["2514.72","2603"],["2514.95","3971"],["2515.04","3037"]]}}
1618677490.171979: {"stream":"bchusd_210625@depth@100ms","data":{"e":"depthUpdate","E":1618677490120,"T":1618677490114,"s":"BCHUSD_210625","ps":"BCHUSD","U":86143440364,"u":86143442294,"pu":86143439446,"b":[["1120.43","0"],["1124.87","210"],["1127.66","378"],["1127.67","81"],["1128.08","0"],["1128.09","0"],["1128.12","0"],["1128.13","0"],["1128.14","36"],["1128.15","0"],["1128.16","0"],["1128.17","0"],["1128.18","64"],["1128.19","14"],["1128.20","35"],["1128.21","41"]],"a":[["1129.89","0"]]}}
1618677490.1808362: {"stream":"btcusd_210924@depth@100ms","data":{"e":"depthUpdate","E":1618677490128,"T":1618677490119,"s":"BTCUSD_210924","ps":"BTCUSD","U":86143440644,"u":86143442367,"pu":86143440157,"b":[["68064.1","12"],["68444.5","0"],["68480.4","150"],["68538.9","0"],["68589.9","0"],["68590.0","0"],["68598.8","1006"],["68598.9","213"],["68606.8","0"],["68613.2","0"],["68632.4","202"]],"a":[["68652.1","1132"],["68658.4","20"],["68703.6","0"],["68712.9","0"],["68723.4","30"],["68734.5","150"],["68787.6","0"],["68821.9","0"],["69260.1","0"],["69270.7","138"]]}}
1618677490.209256: {"stream":"linkusd_210625@depth@100ms","data":{"e":"depthUpdate","E":1618677490157,"T":1618677490121,"s":"LINKUSD_210625","ps":"LINKUSD","U":86143441186,"u":86143442385,"pu":86143441012,"b":[["43.552","0"],["43.712","0"],["43.757","21"],["43.759","6"],["43.763","23"],["43.765","43"],["43.767","12"],["43.768","23"]],"a":[["43.796","0"],["43.885","105"]]}}
1618677490.2229838: {"stream":"btcusd_perp@depth@100ms","data":{"e":"depthUpdate","E":1618677490170,"T":1618677490066,"s":"BTCUSD_PERP","ps":"BTCUSD","U":86143439959,"u":86143441500,"pu":86143439950,"b":[["57564.1","0"],["59027.2","0"],["60227.0","2"],["60511.3","1500"],["60557.5","0"],["60574.8","0"],["60578.8","366"],["60578.9","0"],["60579.0","0"],["60580.8","104"],["60582.7","0"],["60587.0","50"],["60587.5","1"],["60588.0","0"],["60589.0","1"],["60589.5","534"],["60589.6","0"],["60590.0","120"],["60590.1","0"],["60590.7","30"],["60592.4","0"],["60592.7","0"],["60592.8","0"],["60593.8","4468"],["60593.9","0"],["60594.0","96"],["60594.1","0"],["60594.2","198"],["60594.3","0"],["60594.4","0"],["60594.5","0"],["60594.6","0"],["60594.7","0"],["60594.8","0"],["60594.9","0"],["60595.0","96"],["60595.1","0"],["60595.2","0"],["60595.3","0"],["60595.4","0"],["60595.5","0"],["60595.6","0"],["60595.7","4298"],["60595.8","0"],["60595.9","0"],["60596.0","96"],["60596.1","0"],["60596.2","13379"],["60596.3","0"],["60596.4","0"],["60596.5","0"],["60596.6","0"],["60596.7","0"],["60596.8","0"],["60596.9","0"],["60597.0","0"],["60597.1","0"],["60597.2","0"],["60597.3","0"],["60597.4","0"],["60597.5","0"],["60597.6","0"],["60597.7","0"],["60597.8","0"],["60597.9","0"],["60598.0","0"],["60598.1","0"],["60598.2","0"],["60598.3","0"],["60598.4","0"],["60598.5","0"],["60598.7","0"],["60598.8","0"],["60598.9","0"],["60599.0","0"],["60599.1","0"],["60599.2","0"],["60599.3","0"],["60599.4","0"],["60599.5","0"],["60599.7","0"],["60599.8","0"],["60599.9","0"],["60600.0","0"],["60600.1","0"],["60600.2","0"],["60600.3","0"],["60600.4","0"],["60600.5","0"],["60600.6","0"],["60600.7","0"],["60600.8","0"],["60600.9","0"],["60601.0","0"],["60601.1","0"],["60601.2","0"],["60601.3","0"],["60601.4","0"],["60601.5","0"],["60601.6","0"],["60601.7","0"],["60601.9","0"],["60602.1","0"],["60602.2","0"],["60602.3","0"],["60602.4","0"],["60602.5","0"],["60602.6","0"],["60602.7","0"],["60602.8","0"],["60602.9","0"],["60603.0","0"],["60603.1","0"],["60603.3","0"],["60603.5","0"],["60603.7","0"],["60603.9","0"],["60604.1","0"],["60604.2","0"],["60604.4","0"],["60604.5","0"],["60604.6","0"],["60604.7","0"],["60604.8","0"],["60605.0","0"],["60605.1","0"],["60605.3","0"],["60605.5","0"],["60605.9","0"],["60606.1","0"]],"a":[["60593.9","0"],["60595.9","0"],["60596.2","0"],["60596.3","640"],["60596.6","0"],["60597.4","0"],["60600.0","80"],["60601.9","0"],["60602.3","15"],["60602.8","284"],["60603.9","398"],["60604.4","552"],["60605.6","0"],["60610.1","30"],["60615.8","0"],["60620.5","0"],["60620.8","0"],["60633.0","0"],["60633.6","0"],["60645.8","0"],["60646.4","0"],["60647.9","0"],["60648.6","0"],["60800.1","0"],["60835.0","1862"]]}}
1618677490.223897: {"stream":"xrpusd_210625@depth@100ms","data":{"e":"depthUpdate","E":1618677490169,"T":1618677490146,"s":"XRPUSD_210625","ps":"XRPUSD","U":86143441480,"u":86143442664,"pu":86143441011,"b":[["1.6837","4466"]],"a":[["1.6920","0"],["1.6923","0"],["1.6924","45"],["1.6925","198"],["1.6928","0"],["1.6955","1000"],["1.6956","0"],["1.6968","330"],["1.7036","0"]]}}
1618677490.224345: {"stream":"linkusd_210924@depth@100ms","data":{"e":"depthUpdate","E":1618677490169,"T":1618677490066,"s":"LINKUSD_210924","ps":"LINKUSD","U":86143441481,"u":86143441489,"pu":86143441042,"b":[["45.241","0"],["45.247","243"]],"a":[]}}
1618677490.2603772: {"stream":"dotusd_210625@depth@100ms","data":{"e":"depthUpdate","E":1618677490208,"T":1618677490182,"s":"DOTUSD_210625","ps":"DOTUSD","U":86143442180,"u":86143443041,"pu":86143441977,"b":[],"a":[["46.789","200"],["46.814","0"],["46.965","0"]]}}
1618677490.265265: {"stream":"egldusd_perp@depth@100ms","data":{"e":"depthUpdate","E":1618677490212,"T":1618677490159,"s":"EGLDUSD_PERP","ps":"EGLDUSD","U":86143442229,"u":86143442814,"pu":86143441948,"b":[["215.961","97"],["215.981","0"],["215.985","0"],["215.986","0"],["216.068","224"]],"a":[["216.265","0"],["216.344","115"],["216.345","80"],["216.347","0"]]}}
1618677490.2680042: {"stream":"ethusd_210924@depth@100ms","data":{"e":"depthUpdate","E":1618677490213,"T":1618677490190,"s":"ETHUSD_210924","ps":"ETHUSD","U":86143442248,"u":86143443131,"pu":86143442148,"b":[["2667.21","0"],["2667.70","350"],["2687.49","0"],["2687.95","0"],["2687.98","302"],["2689.20","0"],["2689.63","0"],["2689.79","1000"]],"a":[["2689.80","48"],["2699.48","19981"]]}}
1618677490.279855: {"stream":"ethusd_210625@depth@100ms","data":{"e":"depthUpdate","E":1618677490224,"T":1618677490118,"s":"ETHUSD_210625","ps":"ETHUSD","U":86143440705,"u":86143442350,"pu":86143440677,"b":[["2506.58","2833"],["2506.89","587"],["2506.94","587"],["2508.85","12"],["2508.94","105"]],"a":[["2510.85","0"],["2514.28","1321"],["2529.15","4800"]]}}
1618677490.28294: {"stream":"bchusd_210625@depth@100ms","data":{"e":"depthUpdate","E":1618677490230,"T":1618677490223,"s":"BCHUSD_210625","ps":"BCHUSD","U":86143442427,"u":86143443608,"pu":86143442294,"b":[["1122.90","0"],["1123.18","1111"],["1127.05","0"],["1127.31","97"],["1128.14","0"],["1128.18","0"],["1128.19","0"],["1128.20","0"],["1128.21","0"],["1128.22","0"],["1128.23","64"],["1128.24","13"],["1128.25","0"],["1128.26","0"],["1128.27","0"],["1128.28","64"],["1128.29","0"],["1128.30","40"]],"a":[]}}
1618677490.289172: {"stream":"btcusd_210924@depth@100ms","data":{"e":"depthUpdate","E":1618677490237,"T":1618677490183,"s":"BTCUSD_210924","ps":"BTCUSD","U":86143442526,"u":86143443060,"pu":86143442367,"b":[["68046.8","0"],["68645.0","10"],["68646.0","10"],["68647.0","10"],["68650.0","0"],["68651.0","0"],["68652.0","448"]],"a":[["68658.4","0"],["68672.0","20"],["68695.6","364"],["68856.3","0"],["68858.1","477"],["68892.4","477"]]}}
