wss://fstream.binance.com/stream?streams=dentusdt@aggTrade/ksmusdt@aggTrade/xmrusdt@aggTrade/yfiusdt@aggTrade/dentusdt@kline_1m/ksmusdt@kline_1m/xmrusdt@kline_1m/yfiusdt@kline_1m/dentusdt@depth@100ms/ksmusdt@depth@100ms/xmrusdt@depth@100ms/yfiusdt@depth@100ms/dentusdt@bookTicker/ksmusdt@bookTicker/xmrusdt@bookTicker/yfiusdt@bookTicker <-> 1618677447.2908978
1618677448.110592: {"stream":"yfiusdt@bookTicker","data":{"e":"bookTicker","u":335340584945,"s":"YFIUSDT","b":"49951.9","B":"0.005","a":"49966.7","A":"0.001","T":1618677448047,"E":1618677448051}}
1618677448.110691: {"stream":"ksmusdt@depth@100ms","data":{"e":"depthUpdate","E":1618677448053,"T":1618677448043,"s":"KSMUSDT","U":335340582178,"u":335340584861,"pu":335340581994,"b":[["451.725","66.4"],["453.937","0.0"],["456.342","0.0"],["457.625","0.0"],["457.822","0.0"],["457.826","0.5"],["458.627","0.2"],["458.967","0.3"],["458.968","1.8"]],"a":[["459.229","0.0"],["459.271","0.0"],["459.385","0.0"],["459.460","1.0"],["459.484","0.1"],["459.497","1.6"],["459.498","1.4"],["459.589","0.0"],["459.590","0.0"],["459.641","0.1"],["459.722","0.4"],["459.794","2.4"],["460.023","2.4"],["460.079","2.8"],["460.227","0.0"],["460.391","0.0"],["460.882","0.0"],["462.663","1.9"],["465.633","43.0"]]}}
1618677448.40599: {"stream":"yfiusdt@bookTicker","data":{"e":"bookTicker","u":335340585035,"s":"YFIUSDT","b":"49953.1","B":"0.006","a":"49966.7","A":"0.001","T":1618677448049,"E":1618677448053}}
1618677448.406025: {"stream":"yfiusdt@bookTicker","data":{"e":"bookTicker","u":335340585096,"s":"YFIUSDT","b":"49953.1","B":"0.006","a":"49965.8","A":"0.008","T":1618677448050,"E":1618677448054}}
1618677448.406044: {"stream":"yfiusdt@bookTicker","data":{"e":"bookTicker","u":335340585163,"s":"YFIUSDT","b":"49951.9","B":"0.002","a":"49965.8","A":"0.008","T":1618677448052,"E":1618677448057}}
1618677448.406058: {"stream":"yfiusdt@bookTicker","data":{"e":"bookTicker","u":335340585239,"s":"YFIUSDT","b":"49951.9","B":"0.006","a":"49965.8","A":"0.008","T":1618677448054,"E":1618677448057}}
1618677448.406071: {"stream":"yfiusdt@depth@100ms","data":{"e":"depthUpdate","E":1618677448058,"T":1618677448054,"s":"YFIUSDT","U":335340582341,"u":335340585239,"pu":335340580836,"b":[["49488.8","0.000"],["49771.3","0.000"],["49783.3","0.052"],["49881.0","0.004"],["49896.0","0.000"],["49900.2","0.000"],["49902.2","0.060"],["49904.4","0.000"],["49908.6","0.110"],["49912.8","0.110"],["49915.6","0.000"],["49915.7","0.059"],["49917.0","0.110"],["49923.8","0.000"],["49930.1","0.000"],["49930.2","0.046"],["49930.3","0.200"],["49943.5","0.000"],["49950.3","0.013"],["49951.6","0.000"],["49951.7","0.000"],["49951.8","0.000"],["49951.9","0.006"],["49953.1","0.000"],["49954.3","0.000"],["49954.4","0.000"],["49955.7","0.000"],["49964.4","0.000"],["49965.7","0.000"]],"a":[["49965.8","0.008"],["49983.6","0.012"],["50031.5","0.004"],["50032.1","0.000"],["50045.3","0.000"],["50054.4","0.060"],["50064.9","0.000"],["50068.1","0.000"],["50084.9","0.009"],["50111.9","0.000"],["50139.0","0.000"],["54497.0","0.000"]]}}
1618677448.623756: {"stream":"yfiusdt@bookTicker","data":{"e":"bookTicker","u":335340585321,"s":"YFIUSDT","b":"49951.9","B":"0.006","a":"49966.7","A":"0.001","T":1618677448056,"E":1618677448060}}
1618677448.623795: {"stream":"yfiusdt@bookTicker","data":{"e":"bookTicker","u":335340585335,"s":"YFIUSDT","b":"49953.2","B":"0.006","a":"49966.7","A":"0.001","T":1618677448056,"E":1618677448060}}
1618677448.6238132: {"stream":"yfiusdt@bookTicker","data":{"e":"bookTicker","u":335340585468,"s":"YFIUSDT","b":"49953.2","B":"0.012","a":"49966.7","A":"0.001","T":1618677448060,"E":1618677448064}}
1618677448.623827: {"stream":"yfiusdt@bookTicker","data":{"e":"bookTicker","u":335340585644,"s":"YFIUSDT","b":"49953.2","B":"0.006","a":"49966.7","A":"0.001","T":1618677448064,"E":1618677448068}}
1618677448.623839: {"stream":"yfiusdt@bookTicker","data":{"e":"bookTicker","u":335340585793,"s":"YFIUSDT","b":"49950.4","B":"0.006","a":"49966.7","A":"0.001","T":1618677448069,"E":1618677448072}}
1618677448.623851: {"stream":"yfiusdt@bookTicker","data":{"e":"bookTicker","u":335340585816,"s":"YFIUSDT","b":"49954.5","B":"0.006","a":"49966.7","A":"0.001","T":1618677448069,"E":1618677448073}}
1618677448.623863: {"stream":"dentusdt@depth@100ms","data":{"e":"depthUpdate","E":1618677448073,"T":1618677448056,"s":"DENTUSDT","U":335340582674,"u":335340585311,"pu":335340582066,"b":[["0.012341","45277"]],"a":[["0.012355","53992"],["0.012404","38341"]]}}
1618677448.8332832: {"stream":"yfiusdt@bookTicker","data":{"e":"bookTicker","u":335340585864,"s":"YFIUSDT","b":"49963.2","B":"0.016","a":"49966.7","A":"0.001","T":1618677448070,"E":1618677448074}}
1618677448.833317: {"stream":"yfiusdt@bookTicker","data":{"e":"bookTicker","u":335340586130,"s":"YFIUSDT","b":"49963.2","B":"0.016","a":"49986.7","A":"0.001","T":1618677448084,"E":1618677448087}}
1618677448.833335: {"stream":"yfiusdt@kline_1m","data":{"e":"kline","E":1618677448088,"s":"YFIUSDT","k":{"t":1618677420000,"T":1618677479999,"s":"YFIUSDT","i":"1m","f":64902095,"L":64902163,"o":"50010.8","c":"49966.7","h":"50044.2","l":"49950.6","v":"0.842","n":69,"x":false,"q":"42099.6830","V":"0.538","Q":"26900.2291","B":"0"}}}
1618677448.8333619: {"stream":"yfiusdt@bookTicker","data":{"e":"bookTicker","u":335340586465,"s":"YFIUSDT","b":"49964.5","B":"0.006","a":"49986.7","A":"0.001","T":1618677448108,"E":1618677448111}}
1618677448.833376: {"stream":"ksmusdt@depth@100ms","data":{"e":"depthUpdate","E":1618677448153,"T":1618677448137,"s":"KSMUSDT","U":335340585036,"u":335340586930,"pu":335340584861,"b":[["451.668","0.0"],["456.322","0.0"],["458.254","2.2"],["458.627","0.0"],["458.943","0.0"],["458.967","0.0"],["458.969","0.5"]],"a":[["459.460","0.0"],["459.496","1.0"],["459.517","0.0"],["459.711","0.1"],["465.633","0.0"]]}}
1618677448.833389: {"stream":"yfiusdt@depth@100ms","data":{"e":"depthUpdate","E":1618677448160,"T":1618677448137,"s":"YFIUSDT","U":335340585321,"u":335340586939,"pu":335340585239,"b":[["49511.1","0.000"],["49695.1","0.031"],["49736.0","0.000"],["49839.1","0.006"],["49896.0","0.000"],["49900.2","0.000"],["49904.4","0.110"],["49908.6","0.110"],["49912.8","0.110"],["49915.5","0.000"],["49917.0","0.000"],["49930.2","0.000"],["49930.3","0.000"],["49930.4","0.045"],["49950.3","0.000"],["49950.4","0.006"],["49951.9","0.000"],["49952.0","0.000"],["49953.2","0.014"],["49953.3","0.003"],["49954.5","0.000"],["49954.6","0.007"],["49963.2","0.016"],["49964.5","0.006"]],"a":[["49965.8","0.000"],["49966.7","0.000"],["49967.3","0.000"],["49983.6","0.000"],["49998.0","0.014"],["50064.9","0.005"],["50185.5","0.000"],["50202.5","0.083"],["50410.3","0.000"],["50427.4","0.083"]]}}
1618677448.8334038: {"stream":"dentusdt@depth@100ms","data":{"e":"depthUpdate","E":1618677448187,"T":1618677448163,"s":"DENTUSDT","U":335340586119,"u":335340587327,"pu":335340585311,"b":[["0.012177","29524"],["0.012335","82259"]],"a":[["0.012686","165345"]]}}
1618677448.8334138: {"stream":"yfiusdt@bookTicker","data":{"e":"bookTicker","u":335340588227,"s":"YFIUSDT","b":"49964.5","B":"0.006","a":"49983.6","A":"0.012","T":1618677448199,"E":1618677448204}}
1618677448.833427: {"stream":"yfiusdt@bookTicker","data":{"e":"bookTicker","u":335340589269,"s":"YFIUSDT","b":"49964.6","B":"0.010","a":"49983.6","A":"0.012","T":1618677448225,"E":1618677448231}}
1618677448.8334389: {"stream":"yfiusdt@aggTrade","data":{"e":"aggTrade","E":1618677448238,"a":52599685,"s":"YFIUSDT","p":"49966.7","q":"0.001","f":64902163,"l":64902163,"T":1618677448084,"m":false}}
1618677448.8334541: {"stream":"yfiusdt@bookTicker","data":{"e":"bookTicker","u":335340589868,"s":"YFIUSDT","b":"49964.5","B":"0.006","a":"49983.6","A":"0.012","T":1618677448239,"E":1618677448243}}
1618677448.833466: {"stream":"ksmusdt@depth@100ms","data":{"e":"depthUpdate","E":1618677448264,"T":1618677448254,"s":"KSMUSDT","U":335340587037,"u":335340590665,"pu":335340586930,"b":[["456.860","15.0"],["458.920","0.0"],["458.969","1.4"],["458.970","0.3"]],"a":[["459.459","1.4"],["459.496","0.0"],["459.498","0.0"],["459.501","0.0"],["459.517","1.0"],["459.658","5.0"],["459.716","0.0"],["459.901","0.0"],["459.937","0.0"],["460.009","1.0"],["460.491","8.3"],["461.404","15.0"],["471.606","0.7"]]}}
1618677448.833478: {"stream":"yfiusdt@depth@100ms","data":{"e":"depthUpdate","E":1618677448264,"T":1618677448255,"s":"YFIUSDT","U":335340587082,"u":335340590721,"pu":335340586939,"b":[["49527.9","0.083"],["49752.8","0.083"],["49860.9","0.141"],["49915.7","0.000"],["49930.4","0.000"],["49934.4","0.087"],["49934.5","0.018"],["49950.1","0.012"],["49950.4","0.000"],["49954.6","0.000"],["49963.2","0.000"],["49964.6","0.000"]],"a":[["49983.6","0.012"],["49984.3","0.055"],["49988.4","0.012"],["49997.2","0.000"],["49997.9","0.004"],["49998.0","0.000"],["50004.2","0.040"],["50004.3","0.049"],["50013.8","0.000"],["50025.0","0.009"],["50030.7","0.000"],["50047.8","0.004"],["50051.9","0.000"],["50068.0","0.009"],["50084.9","0.000"],["50090.4","0.141"],["50150.0","0.008"],["50160.9","0.157"]]}}
1618677448.833492: {"stream":"ksmusdt@bookTicker","data":{"e":"bookTicker","u":335340591066,"s":"KSMUSDT","b":"459.166","B":"1.7","a":"459.226","A":"1.5","T":1618677448263,"E":1618677448268}}
1618677448.833504: {"stream":"dentusdt@depth@100ms","data":{"e":"depthUpdate","E":1618677448291,"T":1618677448244,"s":"DENTUSDT","U":335340587887,"u":335340590163,"pu":335340587327,"b":[["0.012335","82259"]],"a":[["0.012391","130265"],["0.012409","157659"],["0.012410","157911"]]}}
1618677448.833514: {"stream":"ksmusdt@bookTicker","data":{"e":"bookTicker","u":335340592949,"s":"KSMUSDT","b":"459.196","B":"0.1","a":"459.226","A":"1.5","T":1618677448305,"E":1618677448309}}
1618677448.8335261: {"stream":"xmrusdt@bookTicker","data":{"e":"bookTicker","u":335340594445,"s":"XMRUSDT","b":"352.52","B":"4.011","a":"352.53","A":"0.015","T":1618677448347,"E":1618677448351}}
1618677448.833537: {"stream":"xmrusdt@depth@100ms","data":{"e":"depthUpdate","E":1618677448356,"T":1618677448348,"s":"XMRUSDT","U":335340590587,"u":335340594482,"pu":335340582039,"b":[["351.87","2.966"],["352.06","0.000"],["352.10","35.934"],["352.16","23.208"],["352.40","0.567"],["352.41","1.400"],["352.52","4.011"]],"a":[["352.61","0.000"],["352.62","2.464"]]}}
1618677449.040826: {"stream":"ksmusdt@depth@100ms","data":{"e":"depthUpdate","E":1618677448364,"T":1618677448348,"s":"KSMUSDT","U":335340590972,"u":335340594459,"pu":335340590665,"b":[["452.220","22.1"],["456.978","0.0"],["457.914","0.0"],["457.928","0.0"],["458.604","0.5"],["458.719","7.4"],["458.966","0.0"],["458.969","0.2"],["458.977","0.0"],["459.085","0.0"],["459.166","1.7"],["459.196","0.1"]],"a":[["459.328","0.0"],["459.330","0.0"],["459.458","0.3"],["459.496","1.3"],["459.509","0.0"],["459.517","0.0"],["459.796","0.0"],["460.010","0.0"],["460.024","0.0"],["460.088","0.0"],["460.429","0.0"]]}}
1618677449.040978: {"stream":"yfiusdt@depth@100ms","data":{"e":"depthUpdate","E":1618677448372,"T":1618677448363,"s":"YFIUSDT","U":335340591297,"u":335340595057,"pu":335340590721,"b":[["49246.9","0.000"],["49695.1","0.000"],["49702.9","0.002"],["49912.5","0.000"],["49930.1","0.235"],["49950.2","0.005"],["49953.4","0.010"]],"a":[["49997.9","0.000"],["50004.3","0.019"],["50072.1","0.000"],["50087.5","0.000"],["50088.2","0.000"],["50147.3","0.013"],["50198.6","0.001"],["50725.5","0.000"],["50976.0","0.000"]]}}
1618677449.040998: {"stream":"dentusdt@depth@100ms","data":{"e":"depthUpdate","E":1618677448429,"T":1618677448391,"s":"DENTUSDT","U":335340593742,"u":335340595971,"pu":335340590163,"b":[["0.012335","82259"]],"a":[["0.012375","521781"],["0.012379","67587"],["0.012400","736853"]]}}
1618677449.0410109: {"stream":"yfiusdt@kline_1m","data":{"e":"kline","E":1618677448453,"s":"YFIUSDT","k":{"t":1618677420000,"T":1618677479999,"s":"YFIUSDT","i":"1m","f":64902095,"L":64902164,"o":"50010.8","c":"49964.5","h":"50044.2","l":"49950.6","v":"0.843","n":70,"x":false,"q":"42149.6475","V":"0.538","Q":"26900.2291","B":"0"}}}
1618677449.041041: {"stream":"yfiusdt@bookTicker","data":{"e":"bookTicker","u":335340597797,"s":"YFIUSDT","b":"49964.5","B":"0.005","a":"49983.6","A":"0.012","T":1618677448450,"E":1618677448454}}
1618677449.041058: {"stream":"ksmusdt@depth@100ms","data":{"e":"depthUpdate","E":1618677448464,"T":1618677448450,"s":"KSMUSDT","U":335340594852,"u":335340597800,"pu":335340594459,"b":[["451.364","0.0"],["451.725","0.0"],["452.220","66.3"],["457.896","8.5"],["457.998","3.1"],["458.157","10.9"],["458.970","0.0"],["459.108","0.3"],["459.156","0.7"]],"a":[["460.009","0.0"],["460.023","0.0"],["460.078","1.0"],["460.192","2.3"],["460.268","10.9"],["460.633","3.7"],["466.114","64.4"]]}}
1618677449.0411541: {"stream":"yfiusdt@bookTicker","data":{"e":"bookTicker","u":335340598157,"s":"YFIUSDT","b":"49964.5","B":"0.005","a":"49984.3","A":"0.055","T":1618677448461,"E":1618677448465}}
1618677449.041172: {"stream":"xmrusdt@depth@100ms","data":{"e":"depthUpdate","E":1618677448467,"T":1618677448389,"s":"XMRUSDT","U":335340595027,"u":335340595877,"pu":335340594482,"b":[["351.95","19.290"],["352.03","15.786"],["352.51","3.301"]],"a":[["352.63","0.000"]]}}
1618677449.041184: {"stream":"yfiusdt@depth@100ms","data":{"e":"depthUpdate","E":1618677448483,"T":1618677448474,"s":"YFIUSDT","U":335340595636,"u":335340598565,"pu":335340595057,"b":[["49900.1","0.100"],["49905.0","0.042"],["49922.2","0.075"],["49964.5","0.005"]],"a":[["49940.0","0.000"],["49983.6","0.000"],["50033.5","0.000"],["50054.9","0.011"],["50056.3","0.061"],["50070.0","0.057"],["50092.6","0.000"],["50121.5","0.100"]]}}
1618677449.041194: {"stream":"xmrusdt@kline_1m","data":{"e":"kline","E":1618677448528,"s":"XMRUSDT","k":{"t":1618677420000,"T":1618677479999,"s":"XMRUSDT","i":"1m","f":34692938,"L":34692958,"o":"352.86","c":"352.53","h":"352.93","l":"352.53","v":"19.249","n":21,"x":false,"q":"6789.51000","V":"1.638","Q":"577.96953","B":"0"}}}
1618677449.041215: {"stream":"xmrusdt@bookTicker","data":{"e":"bookTicker","u":335340600194,"s":"XMRUSDT","b":"352.52","B":"4.011","a":"352.62","A":"2.464","T":1618677448523,"E":1618677448528}}
1618677449.041229: {"stream":"xmrusdt@bookTicker","data":{"e":"bookTicker","u":335340600545,"s":"XMRUSDT","b":"352.53","B":"2.917","a":"352.62","A":"2.464","T":1618677448535,"E":1618677448538}}
1618677449.0412412: {"stream":"xmrusdt@bookTicker","data":{"e":"bookTicker","u":335340600594,"s":"XMRUSDT","b":"352.53","B":"2.917","a":"352.62","A":"1.064","T":1618677448536,"E":1618677448540}}
1618677449.041253: {"stream":"xmrusdt@bookTicker","data":{"e":"bookTicker","u":335340601542,"s":"XMRUSDT","b":"352.55","B":"5.997","a":"352.62","A":"1.064","T":1618677448564,"E":1618677448568}}
1618677449.041264: {"stream":"xmrusdt@bookTicker","data":{"e":"bookTicker","u":335340601678,"s":"XMRUSDT","b":"352.53","B":"3.318","a":"352.62","A":"1.064","T":1618677448569,"E":1618677448573}}
1618677449.0412748: {"stream":"xmrusdt@bookTicker","data":{"e":"bookTicker","u":335340601755,"s":"XMRUSDT","b":"352.54","B":"3.700","a":"352.62","A":"1.064","T":1618677448571,"E":1618677448575}}
1618677449.041287: {"stream":"ksmusdt@depth@100ms","data":{"e":"depthUpdate","E":1618677448579,"T":1618677448549,"s":"KSMUSDT","U":335340598598,"u":335340600991,"pu":335340597800,"b":[["457.807","0.9"]],"a":[["459.793","13.5"],["461.531","0.4"],["465.652","0.0"],["467.036","0.0"]]}}
1618677449.041332: {"stream":"xmrusdt@bookTicker","data":{"e":"bookTicker","u":335340601842,"s":"XMRUSDT","b":"352.55","B":"2.845","a":"352.62","A":"1.064","T":1618677448574,"E":1618677448579}}
1618677449.041346: {"stream":"dentusdt@depth@100ms","data":{"e":"depthUpdate","E":1618677448581,"T":1618677448541,"s":"DENTUSDT","U":335340598663,"u":335340600733,"pu":335340595971,"b":[["0.012177","111548"],["0.012335","82259"]],"a":[["0.012389","150186"],["0.012391","127436"],["0.012401","105580"]]}}
1618677449.04136: {"stream":"xmrusdt@bookTicker","data":{"e":"bookTicker","u":335340602012,"s":"XMRUSDT","b":"352.54","B":"3.700","a":"352.62","A":"1.064","T":1618677448579,"E":1618677448585}}
1618677449.041373: {"stream":"xmrusdt@bookTicker","data":{"e":"bookTicker","u":335340602062,"s":"XMRUSDT","b":"352.55","B":"3.012","a":"352.62","A":"1.064","T":1618677448581,"E":1618677448586}}
1618677449.041384: {"stream":"yfiusdt@depth@100ms","data":{"e":"depthUpdate","E":1618677448596,"T":1618677448537,"s":"YFIUSDT","U":335340599133,"u":335340600601,"pu":335340598565,"b":[],"a":[["49988.4","0.000"],["49993.0","0.012"],["50004.1","0.020"],["50004.2","0.000"],["50033.3","0.000"]]}}
1618677449.0414238: {"stream":"yfiusdt@aggTrade","data":{"e":"aggTrade","E":1618677448605,"a":52599686,"s":"YFIUSDT","p":"49964.5","q":"0.001","f":64902164,"l":64902164,"T":1618677448450,"m":true}}
1618677449.041441: {"stream":"xmrusdt@bookTicker","data":{"e":"bookTicker","u":335340602957,"s":"XMRUSDT","b":"352.55","B":"3.413","a":"352.62","A":"1.064","T":1618677448609,"E":1618677448614}}
1618677449.0414531: {"stream":"xmrusdt@bookTicker","data":{"e":"bookTicker","u":335340602983,"s":"XMRUSDT","b":"352.56","B":"3.700","a":"352.62","A":"1.064","T":1618677448610,"E":1618677448614}}
1618677449.041464: {"stream":"xmrusdt@bookTicker","data":{"e":"bookTicker","u":335340603269,"s":"XMRUSDT","b":"352.57","B":"2.980","a":"352.62","A":"1.064","T":1618677448621,"E":1618677448625}}
1618677449.041476: {"stream":"xmrusdt@depth@100ms","data":{"e":"depthUpdate","E":1618677448628,"T":1618677448621,"s":"XMRUSDT","U":335340600194,"u":335340603269,"pu":335340595877,"b":[["351.33","1.026"],["352.26","14.000"],["352.35","0.000"],["352.40","7.767"],["352.41","0.000"],["352.51","0.000"],["352.52","0.311"],["352.53","0.000"],["352.54","3.700"],["352.55","0.401"],["352.56","3.700"],["352.57","2.980"]],"a":[["352.53","0.000"],["352.62","1.064"],["352.64","0.240"],["352.66","1.400"],["352.70","0.000"],["352.71","0.000"],["353.10","0.468"]]}}
1618677449.041489: {"stream":"xmrusdt@bookTicker","data":{"e":"bookTicker","u":335340604151,"s":"XMRUSDT","b":"352.58","B":"3.700","a":"352.62","A":"1.064","T":1618677448652,"E":1618677448656}}
1618677449.041501: {"stream":"ksmusdt@depth@100ms","data":{"e":"depthUpdate","E":1618677448679,"T":1618677448654,"s":"KSMUSDT","U":335340601874,"u":335340604227,"pu":335340600991,"b":[["458.066","3.2"],["458.149","0.0"],["458.451","2.2"],["459.108","0.0"],["459.156","0.0"]],"a":[["459.458","0.0"],["459.459","0.0"],["459.494","1.0"],["459.495","1.4"],["459.768","0.0"],["459.792","13.6"],["459.794","0.0"],["460.078","0.0"],["463.942","4.4"]]}}
1618677449.041586: {"stream":"xmrusdt@aggTrade","data":{"e":"aggTrade","E":1618677448679,"a":23619018,"s":"XMRUSDT","p":"352.53","q":"0.015","f":34692958,"l":34692958,"T":1618677448523,"m":false}}
1618677449.0416021: {"stream":"xmrusdt@bookTicker","data":{"e":"bookTicker","u":335340605361,"s":"XMRUSDT","b":"352.60","B":"0.021","a":"352.62","A":"1.064","T":1618677448691,"E":1618677448695}}
1618677449.041614: {"stream":"yfiusdt@depth@100ms","data":{"e":"depthUpdate","E":1618677448696,"T":1618677448655,"s":"YFIUSDT","U":335340602410,"u":335340604267,"pu":335340600601,"b":[["49417.1","0.021"],["49875.5","0.023"],["49930.1","0.000"],["49934.5","0.000"],["49934.6","0.235"]],"a":[]}}
1618677449.0416589: {"stream":"xmrusdt@depth@100ms","data":{"e":"depthUpdate","E":1618677448736,"T":1618677448731,"s":"XMRUSDT","U":335340603592,"u":335340606587,"pu":335340603269,"b":[["352.16","0.000"],["352.23","4.057"],["352.24","0.000"],["352.27","2.500"],["352.33","0.000"],["352.52","0.290"],["352.54","0.000"],["352.55","0.000"],["352.56","4.101"],["352.58","3.700"],["352.60","0.021"]],"a":[["352.86","0.000"],["353.07","0.000"],["353.14","16.443"],["353.45","14.778"],["353.46","19.290"],["353.60","0.000"],["353.88","0.000"],["354.29","2.536"],["354.62","10.742"],["354.79","3.378"],["357.18","97.964"],["357.19","0.000"]]}}
1618677449.041673: {"stream":"dentusdt@kline_1m","data":{"e":"kline","E":1618677448776,"s":"DENTUSDT","k":{"t":1618677420000,"T":1618677479999,"s":"DENTUSDT","i":"1m","f":15787262,"L":15787356,"o":"0.012366","c":"0.012341","h":"0.012366","l":"0.012339","v":"1312185","n":95,"x":false,"q":"16208.176574","V":"794635","Q":"9817.286741","B":"0"}}}
1618677449.041696: {"stream":"dentusdt@bookTicker","data":{"e":"bookTicker","u":335340607660,"s":"DENTUSDT","b":"0.012341","B":"37179","a":"0.012354","A":"36333","T":1618677448771,"E":1618677448777}}
1618677449.041709: {"stream":"dentusdt@depth@100ms","data":{"e":"depthUpdate","E":1618677448778,"T":1618677448771,"s":"DENTUSDT","U":335340604870,"u":335340607660,"pu":335340600733,"b":[["0.012335","82259"],["0.012341","37179"]],"a":[["0.012373","54594"],["0.012415","47407"]]}}
1618677449.041739: {"stream":"ksmusdt@bookTicker","data":{"e":"bookTicker","u":335340608114,"s":"KSMUSDT","b":"459.211","B":"1.7","a":"459.226","A":"1.5","T":1618677448786,"E":1618677448792}}
1618677449.041752: {"stream":"ksmusdt@depth@100ms","data":{"e":"depthUpdate","E":1618677448799,"T":1618677448789,"s":"KSMUSDT","U":335340605491,"u":335340608237,"pu":335340604227,"b":[["451.946","4.4"],["452.308","63.7"],["458.158","1.1"],["459.166","0.0"],["459.211","1.7"]],"a":[["466.114","126.2"]]}}
1618677449.0417972: {"stream":"ksmusdt@aggTrade","data":{"e":"aggTrade","E":1618677448812,"a":21396959,"s":"KSMUSDT","p":"459.211","q":"1.7","f":25426551,"l":25426551,"T":1618677448808,"m":true}}
1618677449.041813: {"stream":"ksmusdt@bookTicker","data":{"e":"bookTicker","u":335340608905,"s":"KSMUSDT","b":"459.204","B":"3.3","a":"459.226","A":"1.5","T":1618677448808,"E":1618677448812}}
1618677449.041826: {"stream":"ksmusdt@kline_1m","data":{"e":"kline","E":1618677448813,"s":"KSMUSDT","k":{"t":1618677420000,"T":1618677479999,"s":"KSMUSDT","i":"1m","f":25426460,"L":25426551,"o":"459.607","c":"459.211","h":"459.671","l":"458.391","v":"96.1","n":92,"x":false,"q":"44113.5212","V":"49.7","Q":"22824.2739","B":"0"}}}
1618677449.041845: {"stream":"ksmusdt@bookTicker","data":{"e":"bookTicker","u":335340609018,"s":"KSMUSDT","b":"459.196","B":"0.1","a":"459.226","A":"1.5","T":1618677448811,"E":1618677448814}}
1618677449.041857: {"stream":"ksmusdt@aggTrade","data":{"e":"aggTrade","E":1618677448825,"a":21396960,"s":"KSMUSDT","p":"459.204","q":"1.1","f":25426552,"l":25426552,"T":1618677448808,"m":true}}
1618677449.04187: {"stream":"ksmusdt@bookTicker","data":{"e":"bookTicker","u":335340609340,"s":"KSMUSDT","b":"459.107","B":"6.4","a":"459.226","A":"1.5","T":1618677448821,"E":1618677448825}}
1618677449.041883: {"stream":"yfiusdt@depth@100ms","data":{"e":"depthUpdate","E":1618677448827,"T":1618677448810,"s":"YFIUSDT","U":335340606249,"u":335340608959,"pu":335340604267,"b":[["49922.8","0.000"],["49934.7","0.168"],["49940.7","0.009"]],"a":[["50020.0","0.017"],["50025.0","0.026"],["50734.1","0.099"]]}}
1618677449.0419269: {"stream":"xmrusdt@depth@100ms","data":{"e":"depthUpdate","E":1618677448836,"T":1618677448816,"s":"XMRUSDT","U":335340606629,"u":335340609161,"pu":335340606587,"b":[["352.02","6.185"],["352.27","0.000"],["352.30","2.500"],["352.41","0.000"],["352.55","2.888"],["352.56","0.000"],["352.57","0.000"]],"a":[["352.66","0.000"],["352.67","1.400"],["353.47","4.000"],["353.64","0.000"],["353.93","0.000"],["354.29","0.036"]]}}
1618677449.041939: {"stream":"ksmusdt@bookTicker","data":{"e":"bookTicker","u":335340609878,"s":"KSMUSDT","b":"459.107","B":"6.4","a":"459.167","A":"1.1","T":1618677448836,"E":1618677448839}}
1618677449.041951: {"stream":"xmrusdt@bookTicker","data":{"e":"bookTicker","u":335340610100,"s":"XMRUSDT","b":"352.60","B":"0.021","a":"352.61","A":"16.951","T":1618677448843,"E":1618677448847}}
1618677449.041963: {"stream":"xmrusdt@bookTicker","data":{"e":"bookTicker","u":335340610515,"s":"XMRUSDT","b":"352.60","B":"0.074","a":"352.61","A":"16.951","T":1618677448856,"E":1618677448860}}
1618677449.041975: {"stream":"ksmusdt@depth@100ms","data":{"e":"depthUpdate","E":1618677448903,"T":1618677448893,"s":"KSMUSDT","U":335340608694,"u":335340611829,"pu":335340608237,"b":[["440.137","0.0"],["441.116","0.0"],["445.341","10.2"],["445.509","0.0"],["446.652","12.0"],["448.029","14.8"],["456.410","0.0"],["458.158","0.0"],["458.582","0.0"],["459.000","1.2"],["459.196","0.0"],["459.204","0.0"],["459.211","0.0"]],"a":[["459.167","1.1"],["460.164","0.0"],["460.466","6.2"],["460.757","6.0"],["461.775","0.3"],["467.501","4.3"]]}}
1618677449.042083: {"stream":"dentusdt@bookTicker","data":{"e":"bookTicker","u":335340612051,"s":"DENTUSDT","b":"0.012341","B":"91179","a":"0.012354","A":"36333","T":1618677448900,"E":1618677448904}}
1618677449.0420978: {"stream":"dentusdt@bookTicker","data":{"e":"bookTicker","u":335340612066,"s":"DENTUSDT","b":"0.012341","B":"94418","a":"0.012354","A":"36333","T":1618677448901,"E":1618677448904}}
1618677449.042111: {"stream":"dentusdt@bookTicker","data":{"e":"bookTicker","u":335340612408,"s":"DENTUSDT","b":"0.012341","B":"91179","a":"0.012354","A":"36333","T":1618677448910,"E":1618677448916}}
1618677449.042123: {"stream":"dentusdt@depth@100ms","data":{"e":"depthUpdate","E":1618677448918,"T":1618677448910,"s":"DENTUSDT","U":335340609110,"u":335340612422,"pu":335340607660,"b":[["0.012326","287362"],["0.012328","30588"],["0.012330","543906"],["0.012335","1259"],["0.012341","91179"]],"a":[["0.012355","53992"],["0.012356","0"],["0.012357","48600"],["0.012358","48594"],["0.012361","29853"],["0.012367","217028"],["0.012373","40494"],["0.012379","17239"],["0.012383","29649"],["0.012389","109819"],["0.012390","0"]]}}
1618677449.0421948: {"stream":"dentusdt@aggTrade","data":{"e":"aggTrade","E":1618677448919,"a":8476382,"s":"DENTUSDT","p":"0.012341","q":"8098","f":15787356,"l":15787357,"T":1618677448771,"m":true}}
1618677449.042211: {"stream":"dentusdt@aggTrade","data":{"e":"aggTrade","E":1618677448919,"a":8476383,"s":"DENTUSDT","p":"0.012354","q":"36333","f":15787358,"l":15787359,"T":1618677448915,"m":false}}
1618677449.0422242: {"stream":"dentusdt@aggTrade","data":{"e":"aggTrade","E":1618677448919,"a":8476384,"s":"DENTUSDT","p":"0.012355","q":"53992","f":15787360,"l":15787360,"T":1618677448915,"m":false}}
1618677449.0422359: {"stream":"dentusdt@bookTicker","data":{"e":"bookTicker","u":335340612520,"s":"DENTUSDT","b":"0.012341","B":"91179","a":"0.012357","A":"1069","T":1618677448915,"E":1618677448919}}
1618677449.042249: {"stream":"yfiusdt@depth@100ms","data":{"e":"depthUpdate","E":1618677448927,"T":1618677448843,"s":"YFIUSDT","U":335340609401,"u":335340610086,"pu":335340608959,"b":[["49695.0","0.048"],["49934.6","0.000"],["49934.8","0.235"]],"a":[["50139.6","0.018"],["50193.0","0.009"],["50231.5","0.020"]]}}
1618677449.042294: {"stream":"dentusdt@bookTicker","data":{"e":"bookTicker","u":335340612908,"s":"DENTUSDT","b":"0.012341","B":"91179","a":"0.012357","A":"9841","T":1618677448927,"E":1618677448930}}
1618677449.042308: {"stream":"dentusdt@bookTicker","data":{"e":"bookTicker","u":335340612956,"s":"DENTUSDT","b":"0.012341","B":"100299","a":"0.012357","A":"9841","T":1618677448928,"E":1618677448931}}
1618677449.0423198: {"stream":"dentusdt@bookTicker","data":{"e":"bookTicker","u":335340613108,"s":"DENTUSDT","b":"0.012341","B":"100299","a":"0.012357","A":"8772","T":1618677448934,"E":1618677448939}}
1618677449.042332: {"stream":"dentusdt@bookTicker","data":{"e":"bookTicker","u":335340613137,"s":"DENTUSDT","b":"0.012341","B":"76160","a":"0.012357","A":"8772","T":1618677448936,"E":1618677448939}}
1618677449.042343: {"stream":"dentusdt@bookTicker","data":{"e":"bookTicker","u":335340613139,"s":"DENTUSDT","b":"0.012341","B":"63120","a":"0.012357","A":"8772","T":1618677448936,"E":1618677448939}}
1618677449.0423539: {"stream":"xmrusdt@depth@100ms","data":{"e":"depthUpdate","E":1618677448943,"T":1618677448925,"s":"XMRUSDT","U":335340609964,"u":335340612854,"pu":335340609161,"b":[["352.19","2.941"],["352.30","0.000"],["352.31","2.500"],["352.52","3.565"],["352.55","0.000"],["352.60","0.074"]],"a":[["352.61","16.951"],["352.67","0.401"],["352.97","0.000"],["353.07","2.500"],["353.17","0.000"],["353.31","0.000"],["353.32","0.000"],["353.42","0.000"],["353.47","1.500"],["353.49","13.328"],["353.61","14.428"]]}}
1618677449.042366: {"stream":"xmrusdt@bookTicker","data":{"e":"bookTicker","u":335340613725,"s":"XMRUSDT","b":"352.60","B":"0.311","a":"352.61","A":"16.951","T":1618677448956,"E":1618677448960}}
1618677449.042378: {"stream":"dentusdt@bookTicker","data":{"e":"bookTicker","u":335340614146,"s":"DENTUSDT","b":"0.012341","B":"63120","a":"0.012361","A":"29853","T":1618677448966,"E":1618677448969}}
1618677449.04239: {"stream":"dentusdt@bookTicker","data":{"e":"bookTicker","u":335340614154,"s":"DENTUSDT","b":"0.012341","B":"117105","a":"0.012361","A":"29853","T":1618677448966,"E":1618677448969}}
1618677449.042401: {"stream":"dentusdt@bookTicker","data":{"e":"bookTicker","u":335340614165,"s":"DENTUSDT","b":"0.012341","B":"117105","a":"0.012364","A":"520","T":1618677448966,"E":1618677448969}}
1618677449.042667: {"stream":"ksmusdt@aggTrade","data":{"e":"aggTrade","E":1618677448976,"a":21396961,"s":"KSMUSDT","p":"459.196","q":"0.1","f":25426553,"l":25426553,"T":1618677448821,"m":true}}
1618677449.0426948: {"stream":"dentusdt@bookTicker","data":{"e":"bookTicker","u":335340614547,"s":"DENTUSDT","b":"0.012341","B":"117105","a":"0.012363","A":"217028","T":1618677448977,"E":1618677448981}}
1618677449.062748: {"stream":"ksmusdt@depth@100ms","data":{"e":"depthUpdate","E":1618677449005,"T":1618677448996,"s":"KSMUSDT","U":335340612073,"u":335340615304,"pu":335340611829,"b":[["457.359","0.2"],["458.128","2.3"],["458.158","1.1"],["458.221","2.2"],["458.720","0.2"],["458.969","0.0"]],"a":[["460.171","5.5"],["463.770","0.4"]]}}
1618677449.0776262: {"stream":"dentusdt@depth@100ms","data":{"e":"depthUpdate","E":1618677449019,"T":1618677449013,"s":"DENTUSDT","U":335340612504,"u":335340616048,"pu":335340612422,"b":[["0.011837","253088"],["0.012300","974638"],["0.012314","22720"],["0.012315","150084"],["0.012322","412265"],["0.012326","4374"],["0.012330","176504"],["0.012331","313570"],["0.012333","138190"],["0.012335","1259"],["0.012336","25382"],["0.012337","255918"],["0.012338","88488"],["0.012339","317646"],["0.012340","102577"],["0.012341","117105"],["0.012478","0"]],"a":[["0.012354","0"],["0.012355","0"],["0.012357","0"],["0.012358","0"],["0.012361","0"],["0.012362","0"],["0.012363","217028"],["0.012365","94485"],["0.012366","256536"],["0.012368","11205"],["0.012369","0"],["0.012373","0"],["0.012374","0"],["0.012375","116759"],["0.012376","557381"],["0.012377","51731"],["0.012383","26410"],["0.012404","68174"],["0.012500","76063"]]}}
1618677449.099732: {"stream":"dentusdt@bookTicker","data":{"e":"bookTicker","u":335340617242,"s":"DENTUSDT","b":"0.012341","B":"117105","a":"0.012362","A":"6729","T":1618677449037,"E":1618677449041}}
1618677449.099839: {"stream":"dentusdt@bookTicker","data":{"e":"bookTicker","u":335340617248,"s":"DENTUSDT","b":"0.012342","B":"4077","a":"0.012362","A":"6729","T":1618677449038,"E":1618677449041}}
1618677449.1002638: {"stream":"dentusdt@bookTicker","data":{"e":"bookTicker","u":335340617275,"s":"DENTUSDT","b":"0.012342","B":"4077","a":"0.012362","A":"11152","T":1618677449038,"E":1618677449043}}
1618677449.103604: {"stream":"yfiusdt@depth@100ms","data":{"e":"depthUpdate","E":1618677449044,"T":1618677449019,"s":"YFIUSDT","U":335340613314,"u":335340616455,"pu":335340610086,"b":[["49934.7","0.000"],["49934.8","0.000"],["49934.9","0.168"],["49935.0","0.104"],["49936.3","0.250"]],"a":[["49989.9","0.012"],["50095.5","0.000"],["50111.1","0.025"],["50111.9","0.050"],["50144.6","0.018"],["50193.9","0.041"],["50734.1","0.000"]]}}
1618677449.105521: {"stream":"xmrusdt@depth@100ms","data":{"e":"depthUpdate","E":1618677449046,"T":1618677449037,"s":"XMRUSDT","U":335340613402,"u":335340617232,"pu":335340612854,"b":[["351.75","0.000"],["351.87","58.721"],["352.12","2.968"],["352.31","0.000"],["352.52","3.328"],["352.60","0.311"]],"a":[["352.86","2.500"],["353.07","0.000"],["353.37","0.000"],["353.47","167.069"],["353.49","70.048"],["353.94","9.238"],["354.55","0.000"]]}}
1618677449.11214: {"stream":"dentusdt@bookTicker","data":{"e":"bookTicker","u":335340617737,"s":"DENTUSDT","b":"0.012343","B":"8654","a":"0.012362","A":"11152","T":1618677449049,"E":1618677449054}}
1618677449.239599: {"stream":"dentusdt@aggTrade","data":{"e":"aggTrade","E":1618677449070,"a":8476385,"s":"DENTUSDT","p":"0.012357","q":"47531","f":15787361,"l":15787361,"T":1618677448915,"m":false}}
1618677449.244859: {"stream":"dentusdt@bookTicker","data":{"e":"bookTicker","u":335340619086,"s":"DENTUSDT","b":"0.012343","B":"8654","a":"0.012362","A":"65122","T":1618677449083,"E":1618677449087}}
1618677449.250344: {"stream":"ksmusdt@depth@100ms","data":{"e":"depthUpdate","E":1618677449121,"T":1618677449077,"s":"KSMUSDT","U":335340616300,"u":335340618867,"pu":335340615304,"b":[["454.684","22.4"],["458.159","2.7"],["458.721","1.6"],["459.087","0.7"]],"a":[["459.484","0.0"],["459.608","0.1"],["459.641","0.0"],["459.699","0.1"],["459.711","0.0"],["459.765","0.1"],["459.791","7.0"]]}}
1618677449.2506292: {"stream":"dentusdt@depth@100ms","data":{"e":"depthUpdate","E":1618677449122,"T":1618677449117,"s":"DENTUSDT","U":335340616440,"u":335340619573,"pu":335340616048,"b":[["0.012277","4032"],["0.012312","71875"],["0.012317","399640"],["0.012322","817058"],["0.012336","1243"],["0.012340","48592"],["0.012341","102575"],["0.012342","58047"],["0.012343","8654"]],"a":[["0.012362","65122"],["0.012365","40500"],["0.012374","242876"],["0.012382","969790"],["0.012404","38341"],["0.012414","218028"],["0.012438","175915"]]}}
1618677449.2508218: {"stream":"dentusdt@bookTicker","data":{"e":"bookTicker","u":335340619593,"s":"DENTUSDT","b":"0.012343","B":"62624","a":"0.012362","A":"65122","T":1618677449118,"E":1618677449123}}
1618677449.25441: {"stream":"yfiusdt@depth@100ms","data":{"e":"depthUpdate","E":1618677449154,"T":1618677449146,"s":"YFIUSDT","U":335340617754,"u":335340619885,"pu":335340616455,"b":[["49845.6","0.010"],["49934.9","0.000"],["49935.1","0.168"],["49936.4","0.052"]],"a":[["50193.9","0.002"],["50734.1","0.099"]]}}
1618677449.2569358: {"stream":"xmrusdt@depth@100ms","data":{"e":"depthUpdate","E":1618677449175,"T":1618677449153,"s":"XMRUSDT","U":335340618676,"u":335340620059,"pu":335340617232,"b":[["344.69","28.948"],["352.11","6.652"],["352.12","0.468"],["352.20","2.500"],["352.27","2.940"],["352.41","1.633"],["352.52","2.927"],["352.53","0.401"]],"a":[["352.97","6.379"],["353.13","3.247"],["353.46","0.000"]]}}
1618677449.280162: {"stream":"dentusdt@depth@100ms","data":{"e":"depthUpdate","E":1618677449223,"T":1618677449216,"s":"DENTUSDT","U":335340619593,"u":335340621391,"pu":335340619573,"b":[["0.012300","905249"],["0.012335","0"],["0.012337","257177"],["0.012340","72731"],["0.012343","62624"]],"a":[["0.012375","146590"],["0.012383","38962"],["0.012450","96879"]]}}
1618677449.299417: {"stream":"yfiusdt@bookTicker","data":{"e":"bookTicker","u":335340622373,"s":"YFIUSDT","b":"49966.1","B":"0.055","a":"49984.3","A":"0.055","T":1618677449238,"E":1618677449241}}
1618677449.314219: {"stream":"ksmusdt@depth@100ms","data":{"e":"depthUpdate","E":1618677449256,"T":1618677449240,"s":"KSMUSDT","U":335340620032,"u":335340622495,"pu":335340618867,"b":[["457.411","0.2"],["457.758","1.9"],["459.087","0.0"]],"a":[["460.369","1.9"]]}}
1618677449.314425: {"stream":"yfiusdt@depth@100ms","data":{"e":"depthUpdate","E":1618677449256,"T":1618677449250,"s":"YFIUSDT","U":335340620071,"u":335340623071,"pu":335340619885,"b":[["49911.6","0.000"],["49925.7","0.026"],["49935.0","0.000"],["49935.2","0.054"],["49936.3","0.000"],["49936.4","0.000"],["49936.5","0.250"],["49936.6","0.054"],["49966.1","0.055"]],"a":[["50004.4","0.000"],["50036.5","0.000"],["50043.0","0.026"],["50047.9","0.005"],["50064.9","0.000"]]}}
1618677449.314941: {"stream":"yfiusdt@bookTicker","data":{"e":"bookTicker","u":335340623228,"s":"YFIUSDT","b":"49966.2","B":"0.012","a":"49984.3","A":"0.055","T":1618677449254,"E":1618677449257}}
1618677449.334595: {"stream":"yfiusdt@bookTicker","data":{"e":"bookTicker","u":335340623936,"s":"YFIUSDT","b":"49966.1","B":"0.055","a":"49984.3","A":"0.055","T":1618677449269,"E":1618677449274}}
1618677449.33983: {"stream":"xmrusdt@depth@100ms","data":{"e":"depthUpdate","E":1618677449282,"T":1618677449266,"s":"XMRUSDT","U":335340620514,"u":335340623833,"pu":335340620059,"b":[["341.82","0.123"],["350.24","7.006"],["351.88","6.462"],["352.20","0.000"],["352.32","2.500"]],"a":[["352.57","0.000"],["353.22","4.052"],["353.23","19.290"],["354.41","7.673"],["356.38","0.393"],["357.62","0.216"],["359.40","0.000"],["361.13","0.222"],["365.15","0.000"],["373.02","0.072"],["391.52","0.030"]]}}
1618677449.3653061: {"stream":"dentusdt@bookTicker","data":{"e":"bookTicker","u":335340625187,"s":"DENTUSDT","b":"0.012344","B":"4076","a":"0.012362","A":"65122","T":1618677449303,"E":1618677449307}}
1618677449.3782341: {"stream":"dentusdt@bookTicker","data":{"e":"bookTicker","u":335340625549,"s":"DENTUSDT","b":"0.012345","B":"9335","a":"0.012362","A":"65122","T":1618677449315,"E":1618677449319}}
1618677449.39417: {"stream":"dentusdt@depth@100ms","data":{"e":"depthUpdate","E":1618677449336,"T":1618677449315,"s":"DENTUSDT","U":335340621993,"u":335340625549,"pu":335340621391,"b":[["0.012318","108762"],["0.012324","474298"],["0.012337","257177"],["0.012342","53970"],["0.012343","53970"],["0.012344","4076"],["0.012345","9335"]],"a":[["0.012375","68703"],["0.012385","25394"]]}}
1618677449.402878: {"stream":"ksmusdt@bookTicker","data":{"e":"bookTicker","u":335340626469,"s":"KSMUSDT","b":"459.107","B":"6.4","a":"459.226","A":"1.5","T":1618677449341,"E":1618677449344}}
1618677449.414021: {"stream":"ksmusdt@depth@100ms","data":{"e":"depthUpdate","E":1618677449356,"T":1618677449352,"s":"KSMUSDT","U":335340623119,"u":335340626797,"pu":335340622495,"b":[["457.896","2.3"],["457.975","1.1"],["458.068","0.0"],["458.070","0.0"],["458.158","0.0"],["458.290","2.1"],["458.567","15.8"],["458.720","0.0"],["458.722","0.2"],["459.014","7.6"]],"a":[["459.167","0.0"],["459.493","1.4"],["459.495","0.0"],["459.590","0.0"],["459.961","5.4"]]}}
1618677449.4143412: {"stream":"yfiusdt@depth@100ms","data":{"e":"depthUpdate","E":1618677449356,"T":1618677449340,"s":"YFIUSDT","U":335340623123,"u":335340626451,"pu":335340623071,"b":[["49911.9","0.000"],["49930.1","0.250"],["49935.1","0.000"],["49935.2","0.000"],["49935.3","0.168"],["49936.5","0.000"],["49942.7","0.065"],["49953.2","0.000"],["49953.3","0.000"],["49961.5","0.013"],["49966.2","0.000"]],"a":[["49989.9","0.000"],["49992.9","0.014"],["49993.0","0.000"],["49998.9","0.013"],["50004.3","0.000"],["50111.9","0.000"]]}}
1618677449.422157: {"stream":"ksmusdt@bookTicker","data":{"e":"bookTicker","u":335340627062,"s":"KSMUSDT","b":"459.107","B":"6.4","a":"459.167","A":"1.1","T":1618677449358,"E":1618677449363}}
1618677449.440531: {"stream":"xmrusdt@depth@100ms","data":{"e":"depthUpdate","E":1618677449382,"T":1618677449318,"s":"XMRUSDT","U":335340624071,"u":335340625624,"pu":335340623833,"b":[["341.81","73.327"]],"a":[["355.99","0.000"],["357.62","0.808"],["359.40","0.828"],["361.14","0.518"],["364.77","1.035"],["365.16","1.153"],["368.19","2.287"],["372.45","0.000"],["372.48","2.026"]]}}
1618677449.453321: {"stream":"yfiusdt@bookTicker","data":{"e":"bookTicker","u":335340628246,"s":"YFIUSDT","b":"49966.1","B":"0.055","a":"49986.7","A":"0.001","T":1618677449392,"E":1618677449395}}
1618677449.490782: {"stream":"ksmusdt@kline_1m","data":{"e":"kline","E":1618677449433,"s":"KSMUSDT","k":{"t":1618677420000,"T":1618677479999,"s":"KSMUSDT","i":"1m","f":25426460,"L":25426554,"o":"459.607","c":"459.167","h":"459.671","l":"458.391","v":"98.4","n":95,"x":false,"q":"45169.6489","V":"50.8","Q":"23329.3576","B":"0"}}}
1618677449.490906: {"stream":"ksmusdt@bookTicker","data":{"e":"bookTicker","u":335340629599,"s":"KSMUSDT","b":"459.107","B":"6.4","a":"459.226","A":"1.5","T":1618677449429,"E":1618677449433}}
1618677449.499861: {"stream":"dentusdt@depth@100ms","data":{"e":"depthUpdate","E":1618677449441,"T":1618677449436,"s":"DENTUSDT","U":335340626382,"u":335340629879,"pu":335340625549,"b":[["0.000011","20805663"],["0.012337","255918"],["0.012338","0"],["0.012340","48592"],["0.012341","126714"],["0.012342","107932"],["0.012343","0"]],"a":[["0.012363","225531"]]}}
1618677449.503019: {"stream":"ksmusdt@bookTicker","data":{"e":"bookTicker","u":335340629958,"s":"KSMUSDT","b":"459.107","B":"6.4","a":"459.227","A":"0.1","T":1618677449439,"E":1618677449442}}
1618677449.51488: {"stream":"ksmusdt@bookTicker","data":{"e":"bookTicker","u":335340630437,"s":"KSMUSDT","b":"459.108","B":"1.0","a":"459.227","A":"0.1","T":1618677449451,"E":1618677449456}}
1618677449.515481: {"stream":"ksmusdt@bookTicker","data":{"e":"bookTicker","u":335340630504,"s":"KSMUSDT","b":"459.108","B":"2.2","a":"459.227","A":"0.1","T":1618677449453,"E":1618677449457}}
1618677449.518029: {"stream":"yfiusdt@depth@100ms","data":{"e":"depthUpdate","E":1618677449459,"T":1618677449455,"s":"YFIUSDT","U":335340626900,"u":335340630584,"pu":335340626451,"b":[["49900.1","0.000"],["49904.4","0.000"],["49908.6","0.000"],["49917.0","0.110"],["49921.2","0.110"],["49935.3","0.000"],["49936.6","0.000"],["49936.7","0.168"],["49958.1","0.016"],["49961.5","0.000"],["49962.2","0.013"]],"a":[["49984.3","0.000"],["49992.9","0.000"],["50011.1","0.042"],["50054.4","0.000"],["50055.5","0.000"],["50080.5","0.060"],["50080.7","0.102"],["50084.4","0.000"],["50084.9","0.006"],["50102.7","0.401"],["50128.4","0.000"]]}}
1618677449.520502: {"stream":"ksmusdt@depth@100ms","data":{"e":"depthUpdate","E":1618677449463,"T":1618677449453,"s":"KSMUSDT","U":335340627062,"u":335340630505,"pu":335340626797,"b":[["457.145","0.0"],["457.975","0.0"],["458.540","6.0"],["459.000","0.0"],["459.015","0.2"],["459.108","2.2"]],"a":[["459.167","0.0"],["459.226","0.0"],["459.487","1.2"],["459.493","0.0"],["459.494","0.0"],["459.643","0.0"],["459.790","13.6"],["459.792","0.0"]]}}
1618677449.5586402: {"stream":"ksmusdt@bookTicker","data":{"e":"bookTicker","u":335340632062,"s":"KSMUSDT","b":"459.130","B":"6.4","a":"459.227","A":"0.1","T":1618677449498,"E":1618677449502}}
1618677449.562995: {"stream":"dentusdt@bookTicker","data":{"e":"bookTicker","u":335340632219,"s":"DENTUSDT","b":"0.012345","B":"63301","a":"0.012362","A":"65122","T":1618677449502,"E":1618677449506}}
1618677449.5679018: {"stream":"xmrusdt@depth@100ms","data":{"e":"depthUpdate","E":1618677449511,"T":1618677449478,"s":"XMRUSDT","U":335340628825,"u":335340631444,"pu":335340625624,"b":[],"a":[["352.64","0.000"],["352.66","1.400"],["352.67","0.401"],["355.99","1.531"]]}}
1618677449.60922: {"stream":"dentusdt@depth@100ms","data":{"e":"depthUpdate","E":1618677449551,"T":1618677449502,"s":"DENTUSDT","U":335340630305,"u":335340632219,"pu":335340629879,"b":[["0.012303","7362"],["0.012304","593224"],["0.012339","318905"],["0.012342","53966"],["0.012345","63301"]],"a":[["0.012392","1847"],["0.012399","550843"]]}}
1618677449.625706: {"stream":"ksmusdt@depth@100ms","data":{"e":"depthUpdate","E":1618677449567,"T":1618677449535,"s":"KSMUSDT","U":335340630933,"u":335340633253,"pu":335340630505,"b":[["455.728","0.0"],["457.238","0.0"],["457.811","2.0"],["458.160","1.1"],["458.439","1.9"],["458.722","0.0"],["458.965","0.0"],["458.968","0.0"],["459.130","6.4"]],"a":[["459.498","1.3"],["459.590","1.4"],["459.789","0.0"],["460.369","0.0"],["462.169","0.0"]]}}
1618677449.630922: {"stream":"yfiusdt@depth@100ms","data":{"e":"depthUpdate","E":1618677449574,"T":1618677449568,"s":"YFIUSDT","U":335340631241,"u":335340634424,"pu":335340630584,"b":[["49905.0","0.017"],["49930.1","0.000"],["49934.5","0.272"],["49950.1","0.000"]],"a":[["49998.8","0.030"],["50002.1","0.000"],["50004.1","0.000"],["50011.1","0.030"],["50047.9","0.000"],["50062.7","0.005"],["50144.6","0.008"],["50160.9","0.000"],["50168.4","0.157"]]}}
1618677449.6407812: {"stream":"ksmusdt@aggTrade","data":{"e":"aggTrade","E":1618677449584,"a":21396962,"s":"KSMUSDT","p":"459.167","q":"1.1","f":25426554,"l":25426554,"T":1618677449429,"m":false}}
1618677449.641384: {"stream":"ksmusdt@bookTicker","data":{"e":"bookTicker","u":335340634772,"s":"KSMUSDT","b":"459.131","B":"0.7","a":"459.227","A":"0.1","T":1618677449580,"E":1618677449584}}
1618677449.6484349: {"stream":"ksmusdt@bookTicker","data":{"e":"bookTicker","u":335340634972,"s":"KSMUSDT","b":"459.131","B":"2.2","a":"459.227","A":"0.1","T":1618677449587,"E":1618677449591}}
1618677449.665355: {"stream":"yfiusdt@bookTicker","data":{"e":"bookTicker","u":335340635350,"s":"YFIUSDT","b":"49966.2","B":"0.003","a":"49986.7","A":"0.001","T":1618677449602,"E":1618677449607}}
1618677449.6695411: {"stream":"ksmusdt@bookTicker","data":{"e":"bookTicker","u":335340635430,"s":"KSMUSDT","b":"459.153","B":"6.4","a":"459.227","A":"0.1","T":1618677449607,"E":1618677449611}}
1618677449.684617: {"stream":"dentusdt@bookTicker","data":{"e":"bookTicker","u":335340635804,"s":"DENTUSDT","b":"0.012345","B":"9335","a":"0.012362","A":"65122","T":1618677449621,"E":1618677449626}}
1618677449.726151: {"stream":"ksmusdt@depth@100ms","data":{"e":"depthUpdate","E":1618677449668,"T":1618677449662,"s":"KSMUSDT","U":335340634274,"u":335340637023,"pu":335340633253,"b":[["449.007","0.0"],["452.838","0.0"],["454.754","0.0"],["456.669","0.0"],["457.052","0.0"],["457.619","2.4"],["458.160","1.1"],["458.722","0.2"],["459.015","0.0"],["459.107","0.0"],["459.108","1.0"],["459.131","2.2"],["459.153","6.4"]],"a":[["459.789","0.0"],["459.791","0.0"],["459.793","0.0"],["459.923","0.0"],["460.174","5.7"],["460.230","2.1"],["460.282","0.0"],["460.466","0.0"],["460.621","0.0"],["461.137","0.0"],["462.171","0.0"],["463.713","0.0"],["466.290","0.0"],["471.443","5.3"]]}}
1618677449.726943: {"stream":"dentusdt@bookTicker","data":{"e":"bookTicker","u":335340637058,"s":"DENTUSDT","b":"0.012345","B":"63301","a":"0.012362","A":"65122","T":1618677449664,"E":1618677449669}}
1618677449.732969: {"stream":"yfiusdt@depth@100ms","data":{"e":"depthUpdate","E":1618677449674,"T":1618677449667,"s":"YFIUSDT","U":335340634466,"u":335340637179,"pu":335340634424,"b":[["49792.4","0.135"],["49899.7","0.025"],["49934.5","0.000"],["49946.0","0.272"],["49950.2","0.000"],["49966.2","0.003"]],"a":[["49998.7","0.003"],["49998.8","0.000"],["50011.0","0.012"],["50025.0","0.017"],["50027.6","0.000"],["50037.0","0.009"],["50079.9","0.020"],["50112.0","0.000"]]}}
1618677449.740041: {"stream":"dentusdt@depth@100ms","data":{"e":"depthUpdate","E":1618677449683,"T":1618677449674,"s":"DENTUSDT","U":335340634687,"u":335340637371,"pu":335340632219,"b":[["0.012253","288187"],["0.012339","318905"],["0.012341","136592"],["0.012345","63301"]],"a":[["0.012363","274100"],["0.012365","133473"],["0.012366","0"],["0.012383","335944"]]}}
1618677449.7684858: {"stream":"dentusdt@kline_1m","data":{"e":"kline","E":1618677449711,"s":"DENTUSDT","k":{"t":1618677420000,"T":1618677479999,"s":"DENTUSDT","i":"1m","f":15787262,"L":15787362,"o":"0.012366","c":"0.012345","h":"0.012366","l":"0.012339","v":"1460748","n":101,"x":false,"q":"18043.618610","V":"932491","Q":"11520.556350","B":"0"}}}
1618677449.768611: {"stream":"dentusdt@bookTicker","data":{"e":"bookTicker","u":335340638403,"s":"DENTUSDT","b":"0.012345","B":"2502","a":"0.012362","A":"65122","T":1618677449707,"E":1618677449710}}
1618677449.777052: {"stream":"dentusdt@bookTicker","data":{"e":"bookTicker","u":335340638687,"s":"DENTUSDT","b":"0.012346","B":"9489","a":"0.012362","A":"65122","T":1618677449716,"E":1618677449719}}
1618677449.7771578: {"stream":"dentusdt@bookTicker","data":{"e":"bookTicker","u":335340638727,"s":"DENTUSDT","b":"0.012346","B":"9489","a":"0.012361","A":"8958","T":1618677449718,"E":1618677449721}}
1618677449.777569: {"stream":"dentusdt@bookTicker","data":{"e":"bookTicker","u":335340638740,"s":"DENTUSDT","b":"0.012345","B":"2502","a":"0.012361","A":"8958","T":1618677449719,"E":1618677449722}}
1618677449.8038988: {"stream":"dentusdt@bookTicker","data":{"e":"bookTicker","u":335340639323,"s":"DENTUSDT","b":"0.012345","B":"2502","a":"0.012361","A":"38787","T":1618677449742,"E":1618677449746}}
1618677449.804001: {"stream":"dentusdt@bookTicker","data":{"e":"bookTicker","u":335340639325,"s":"DENTUSDT","b":"0.012344","B":"4076","a":"0.012361","A":"38787","T":1618677449742,"E":1618677449746}}
1618677449.8059928: {"stream":"xmrusdt@depth@100ms","data":{"e":"depthUpdate","E":1618677449748,"T":1618677449705,"s":"XMRUSDT","U":335340636482,"u":335340638306,"pu":335340631444,"b":[["352.10","19.856"],["352.11","3.069"],["352.20","15.657"]],"a":[["354.18","0.772"]]}}
1618677449.825166: {"stream":"ksmusdt@bookTicker","data":{"e":"bookTicker","u":335340639865,"s":"KSMUSDT","b":"459.153","B":"6.4","a":"459.351","A":"0.1","T":1618677449765,"E":1618677449768}}
1618677449.825268: {"stream":"ksmusdt@kline_1m","data":{"e":"kline","E":1618677449769,"s":"KSMUSDT","k":{"t":1618677420000,"T":1618677479999,"s":"KSMUSDT","i":"1m","f":25426460,"L":25426555,"o":"459.607","c":"459.227","h":"459.671","l":"458.391","v":"98.5","n":96,"x":false,"q":"45215.5716","V":"50.9","Q":"23375.2803","B":"0"}}}
1618677449.834771: {"stream":"ksmusdt@depth@100ms","data":{"e":"depthUpdate","E":1618677449777,"T":1618677449765,"s":"KSMUSDT","U":335340637328,"u":335340639865,"pu":335340637023,"b":[["457.803","2.0"],["457.811","0.0"],["457.893","0.0"],["458.123","0.8"],["459.131","3.4"]],"a":[["459.227","0.0"],["459.487","0.0"],["460.106","0.0"],["460.247","2.3"],["460.437","1.0"],["460.491","0.0"],["460.606","8.3"]]}}
1618677449.8350651: {"stream":"yfiusdt@depth@100ms","data":{"e":"depthUpdate","E":1618677449777,"T":1618677449766,"s":"YFIUSDT","U":335340637313,"u":335340639897,"pu":335340637179,"b":[["49521.5","0.002"],["49771.0","0.006"],["49896.1","0.000"],["49912.9","0.010"],["49945.9","0.000"]],"a":[["50077.1","0.073"],["50079.8","0.000"],["50102.6","0.011"],["50103.6","0.007"],["50120.6","0.000"],["50124.3","0.025"],["50124.9","0.000"],["50135.9","0.007"],["50147.8","0.021"],["50151.2","0.007"]]}}
1618677449.839: {"stream":"ksmusdt@bookTicker","data":{"e":"bookTicker","u":335340640161,"s":"KSMUSDT","b":"459.164","B":"1.2","a":"459.351","A":"0.1","T":1618677449776,"E":1618677449779}}
1618677449.839606: {"stream":"dentusdt@bookTicker","data":{"e":"bookTicker","u":335340640242,"s":"DENTUSDT","b":"0.012344","B":"4076","a":"0.012361","A":"130729","T":1618677449779,"E":1618677449783}}
1618677449.849695: {"stream":"dentusdt@depth@100ms","data":{"e":"depthUpdate","E":1618677449792,"T":1618677449780,"s":"DENTUSDT","U":335340637847,"u":335340640276,"pu":335340637371,"b":[["0.012250","269498"],["0.012257","87442"],["0.012319","148118"],["0.012322","493145"],["0.012326","28659"],["0.012337","0"],["0.012338","99619"],["0.012339","318905"],["0.012345","0"],["0.012346","0"]],"a":[["0.012361","130729"],["0.012362","11152"],["0.012363","322671"],["0.012366","24172"],["0.012369","57938"],["0.012373","11311"],["0.012375","38872"],["0.012377","27541"],["0.012381","409797"],["0.012397","198157"]]}}
1618677449.872155: {"stream":"yfiusdt@bookTicker","data":{"e":"bookTicker","u":335340641078,"s":"YFIUSDT","b":"49967.5","B":"0.006","a":"49986.7","A":"0.001","T":1618677449809,"E":1618677449813}}
1618677449.881967: {"stream":"dentusdt@bookTicker","data":{"e":"bookTicker","u":335340641356,"s":"DENTUSDT","b":"0.012342","B":"53966","a":"0.012361","A":"130729","T":1618677449819,"E":1618677449824}}
1618677449.88207: {"stream":"dentusdt@bookTicker","data":{"e":"bookTicker","u":335340641392,"s":"DENTUSDT","b":"0.012346","B":"4076","a":"0.012361","A":"130729","T":1618677449820,"E":1618677449824}}
1618677449.904999: {"stream":"dentusdt@bookTicker","data":{"e":"bookTicker","u":335340642145,"s":"DENTUSDT","b":"0.012346","B":"4076","a":"0.012360","A":"6729","T":1618677449843,"E":1618677449846}}
1618677449.9051049: {"stream":"dentusdt@bookTicker","data":{"e":"bookTicker","u":335340642178,"s":"DENTUSDT","b":"0.012346","B":"4076","a":"0.012360","A":"11152","T":1618677449843,"E":1618677449846}}
1618677449.914144: {"stream":"yfiusdt@bookTicker","data":{"e":"bookTicker","u":335340642426,"s":"YFIUSDT","b":"49967.6","B":"0.003","a":"49986.7","A":"0.001","T":1618677449852,"E":1618677449855}}
1618677449.9183738: {"stream":"dentusdt@bookTicker","data":{"e":"bookTicker","u":335340642500,"s":"DENTUSDT","b":"0.012346","B":"4076","a":"0.012359","A":"8983","T":1618677449855,"E":1618677449859}}
1618677449.9184792: {"stream":"dentusdt@aggTrade","data":{"e":"aggTrade","E":1618677449861,"a":8476386,"s":"DENTUSDT","p":"0.012345","q":"60799","f":15787362,"l":15787363,"T":1618677449707,"m":true}}
1618677449.938844: {"stream":"ksmusdt@depth@100ms","data":{"e":"depthUpdate","E":1618677449879,"T":1618677449856,"s":"KSMUSDT","U":335340640126,"u":335340642521,"pu":335340639865,"b":[["451.334","1.1"],["457.442","2.3"],["457.972","0.0"],["458.148","0.0"],["458.160","1.1"],["458.203","10.9"],["458.637","5.8"],["458.722","0.0"],["459.015","0.2"],["459.076","0.5"],["459.131","2.2"],["459.164","1.2"]],"a":[["459.497","0.0"],["459.498","0.0"],["459.591","0.0"],["459.810","1.7"],["460.079","0.0"],["460.082","0.0"],["460.219","2.2"],["460.314","10.9"],["460.437","0.0"],["460.647","0.0"]]}}
1618677449.951487: {"stream":"dentusdt@depth@100ms","data":{"e":"depthUpdate","E":1618677449893,"T":1618677449884,"s":"DENTUSDT","U":335340640535,"u":335340643331,"pu":335340640276,"b":[["0.012288","525690"],["0.012304","119634"],["0.012338","0"],["0.012339","317646"],["0.012342","111288"],["0.012344","0"],["0.012346","4076"]],"a":[["0.012359","8983"],["0.012360","11152"],["0.012361","121771"],["0.012362","0"],["0.012363","225531"],["0.012369","0"],["0.012395","180771"],["0.012399","77253"],["0.012411","1718"],["0.012414","691618"],["0.012435","952457"]]}}
1618677449.9601421: {"stream":"xmrusdt@depth@100ms","data":{"e":"depthUpdate","E":1618677449903,"T":1618677449845,"s":"XMRUSDT","U":335340640760,"u":335340642237,"pu":335340638306,"b":[["351.81","0.000"],["352.36","6.019"]],"a":[["354.36","0.852"]]}}
1618677449.96115: {"stream":"dentusdt@aggTrade","data":{"e":"aggTrade","E":1618677449903,"a":8476387,"s":"DENTUSDT","p":"0.012359","q":"8983","f":15787364,"l":15787364,"T":1618677449898,"m":false}}
1618677449.961202: {"stream":"dentusdt@bookTicker","data":{"e":"bookTicker","u":335340643695,"s":"DENTUSDT","b":"0.012346","B":"4076","a":"0.012360","A":"10248","T":1618677449898,"E":1618677449903}}
1618677449.970486: {"stream":"yfiusdt@depth@100ms","data":{"e":"depthUpdate","E":1618677449913,"T":1618677449860,"s":"YFIUSDT","U":335340641064,"u":335340642641,"pu":335340639897,"b":[["49964.5","0.000"],["49966.2","0.000"],["49967.5","0.006"],["49967.6","0.003"]],"a":[["50143.6","0.013"],["50244.9","0.010"]]}}
1618677449.970716: {"stream":"dentusdt@bookTicker","data":{"e":"bookTicker","u":335340643933,"s":"DENTUSDT","b":"0.012347","B":"50000","a":"0.012360","A":"10248","T":1618677449909,"E":1618677449913}}
1618677449.97277: {"stream":"dentusdt@bookTicker","data":{"e":"bookTicker","u":335340643939,"s":"DENTUSDT","b":"0.012347","B":"100000","a":"0.012360","A":"10248","T":1618677449910,"E":1618677449915}}
1618677449.9769611: {"stream":"ksmusdt@aggTrade","data":{"e":"aggTrade","E":1618677449919,"a":21396963,"s":"KSMUSDT","p":"459.227","q":"0.1","f":25426555,"l":25426555,"T":1618677449765,"m":false}}
1618677449.9775639: {"stream":"dentusdt@bookTicker","data":{"e":"bookTicker","u":335340644053,"s":"DENTUSDT","b":"0.012347","B":"100000","a":"0.012359","A":"9540","T":1618677449915,"E":1618677449919}}
1618677450.022602: {"stream":"dentusdt@bookTicker","data":{"e":"bookTicker","u":335340645180,"s":"DENTUSDT","b":"0.012348","B":"16037","a":"0.012359","A":"9540","T":1618677449959,"E":1618677449962}}
1618677450.037868: {"stream":"ksmusdt@depth@100ms","data":{"e":"depthUpdate","E":1618677449981,"T":1618677449977,"s":"KSMUSDT","U":335340643050,"u":335340645625,"pu":335340642521,"b":[["457.595","0.0"],["457.826","0.0"],["458.007","0.5"],["458.159","0.0"],["458.160","0.0"],["458.204","1.1"],["458.254","0.0"],["458.566","0.0"]],"a":[["459.590","0.0"],["459.607","1.4"],["459.722","0.0"],["459.761","13.6"],["459.790","0.0"],["459.903","0.4"],["459.960","11.9"],["459.961","0.0"],["460.144","1.0"],["460.244","8.0"],["460.280","0.0"],["460.689","0.4"],["461.347","0.0"]]}}
1618677450.05493: {"stream":"dentusdt@bookTicker","data":{"e":"bookTicker","u":335340646008,"s":"DENTUSDT","b":"0.012354","B":"206360","a":"0.012359","A":"9540","T":1618677449992,"E":1618677449996}}
1618677450.058437: {"stream":"dentusdt@depth@100ms","data":{"e":"depthUpdate","E":1618677449999,"T":1618677449992,"s":"DENTUSDT","U":335340643612,"u":335340646008,"pu":335340643331,"b":[["0.012301","147076"],["0.012333","26933"],["0.012337","111093"],["0.012339","220474"],["0.012340","49851"],["0.012341","115691"],["0.012342","40968"],["0.012343","97138"],["0.012347","100000"],["0.012348","16037"],["0.012354","206360"]],"a":[["0.012359","9540"],["0.012360","10248"],["0.012361","0"],["0.012362","121769"],["0.012367","217028"],["0.012376","422401"],["0.012379","20477"],["0.012381","544722"]]}}
1618677450.083549: {"stream":"yfiusdt@bookTicker","data":{"e":"bookTicker","u":335340646905,"s":"YFIUSDT","b":"49967.7","B":"0.014","a":"49986.7","A":"0.001","T":1618677450021,"E":1618677450025}}
1618677450.101839: {"stream":"yfiusdt@depth@100ms","data":{"e":"depthUpdate","E":1618677450043,"T":1618677450034,"s":"YFIUSDT","U":335340644611,"u":335340647282,"pu":335340642641,"b":[["48977.6","0.001"],["49844.7","0.000"],["49902.2","0.000"],["49946.1","0.062"],["49958.1","0.000"],["49966.2","0.013"],["49967.7","0.014"]],"a":[["49998.5","0.008"],["49998.6","0.012"],["49998.7","0.000"],["50010.9","0.012"],["50056.3","0.000"],["50080.5","0.000"],["50959.0","0.049"]]}}
1618677450.111535: {"stream":"dentusdt@aggTrade","data":{"e":"aggTrade","E":1618677450054,"a":8476388,"s":"DENTUSDT","p":"0.012360","q":"904","f":15787365,"l":15787365,"T":1618677449898,"m":false}}
1618677450.115985: {"stream":"xmrusdt@depth@100ms","data":{"e":"depthUpdate","E":1618677450057,"T":1618677450036,"s":"XMRUSDT","U":335340644944,"u":335340647305,"pu":335340642237,"b":[["351.66","0.000"],["351.74","200.381"],["352.21","3.287"]],"a":[["353.38","0.468"],["353.46","200.000"],["353.95","6.691"],["354.73","0.000"],["361.76","5.595"]]}}
1618677450.237806: {"stream":"ksmusdt@bookTicker","data":{"e":"bookTicker","u":335340648112,"s":"KSMUSDT","b":"459.186","B":"6.4","a":"459.351","A":"0.1","T":1618677450057,"E":1618677450062}}
1618677450.237911: {"stream":"dentusdt@bookTicker","data":{"e":"bookTicker","u":335340648235,"s":"DENTUSDT","b":"0.012355","B":"11189","a":"0.012359","A":"9540","T":1618677450060,"E":1618677450064}}
1618677450.237956: {"stream":"dentusdt@bookTicker","data":{"e":"bookTicker","u":335340648253,"s":"DENTUSDT","b":"0.012355","B":"27217","a":"0.012359","A":"9540","T":1618677450060,"E":1618677450066}}
1618677450.239208: {"stream":"yfiusdt@bookTicker","data":{"e":"bookTicker","u":335340648406,"s":"YFIUSDT","b":"49967.8","B":"0.003","a":"49986.7","A":"0.001","T":1618677450064,"E":1618677450069}}
1618677450.244118: {"stream":"yfiusdt@bookTicker","data":{"e":"bookTicker","u":335340648732,"s":"YFIUSDT","b":"49969.1","B":"0.006","a":"49986.7","A":"0.001","T":1618677450074,"E":1618677450078}}
1618677450.244221: {"stream":"yfiusdt@bookTicker","data":{"e":"bookTicker","u":335340648767,"s":"YFIUSDT","b":"49970.1","B":"0.055","a":"49986.7","A":"0.001","T":1618677450075,"E":1618677450080}}
1618677450.244263: {"stream":"dentusdt@bookTicker","data":{"e":"bookTicker","u":335340648838,"s":"DENTUSDT","b":"0.012355","B":"32093","a":"0.012359","A":"9540","T":1618677450076,"E":1618677450080}}
1618677450.244299: {"stream":"ksmusdt@depth@100ms","data":{"e":"depthUpdate","E":1618677450083,"T":1618677450077,"s":"KSMUSDT","U":335340645697,"u":335340648868,"pu":335340645625,"b":[["449.734","0.0"],["453.749","0.0"],["454.739","0.0"],["454.756","15.0"],["455.147","3.9"],["456.804","0.0"],["457.006","15.0"],["457.135","0.0"],["457.214","3.9"],["457.320","1.1"],["458.568","3.4"],["458.605","1.9"],["459.130","0.0"],["459.154","1.3"],["459.186","6.4"]],"a":[["459.499","0.0"],["459.500","0.0"],["459.606","0.3"],["459.657","5.9"],["459.690","0.6"],["459.699","0.0"],["459.760","2.8"],["459.765","0.0"],["459.875","0.1"],["459.959","2.5"],["460.144","0.0"],["460.170","2.5"],["460.244","0.0"],["460.373","2.3"],["460.593","1.1"],["460.932","0.0"],["461.090","0.0"],["461.347","3.9"],["461.467","9.2"],["461.509","15.0"],["461.781","0.0"],["462.997","0.0"],["463.414","3.9"],["463.759","15.0"]]}}
1618677450.246146: {"stream":"yfiusdt@bookTicker","data":{"e":"bookTicker","u":335340649114,"s":"YFIUSDT","b":"49971.4","B":"0.006","a":"49986.7","A":"0.001","T":1618677450084,"E":1618677450090}}
1618677450.2462158: {"stream":"dentusdt@bookTicker","data":{"e":"bookTicker","u":335340649180,"s":"DENTUSDT","b":"0.012355","B":"55603","a":"0.012359","A":"9540","T":1618677450088,"E":1618677450093}}
1618677450.247893: {"stream":"dentusdt@depth@100ms","data":{"e":"depthUpdate","E":1618677450100,"T":1618677450088,"s":"DENTUSDT","U":335340646058,"u":335340649184,"pu":335340646008,"b":[["0.012170","32771"],["0.012307","129207"],["0.012315","124833"],["0.012327","389118"],["0.012340","53953"],["0.012341","13116"],["0.012342","242787"],["0.012344","24139"],["0.012348","1259"],["0.012355","55603"]],"a":[["0.012361","51464"],["0.012362","0"],["0.012376","17444"],["0.012380","137186"],["0.012382","917513"],["0.012385","430039"],["0.012388","716439"],["0.012397","223190"]]}}
1618677450.254734: {"stream":"yfiusdt@bookTicker","data":{"e":"bookTicker","u":335340649683,"s":"YFIUSDT","b":"49971.5","B":"0.003","a":"49986.7","A":"0.001","T":1618677450107,"E":1618677450111}}
1618677450.2814348: {"stream":"yfiusdt@depth@100ms","data":{"e":"depthUpdate","E":1618677450144,"T":1618677450130,"s":"YFIUSDT","U":335340647471,"u":335340649935,"pu":335340647282,"b":[["49905.3","0.060"],["49918.4","0.130"],["49945.8","0.000"],["49946.0","0.000"],["49946.1","0.000"],["49946.2","0.272"],["49946.3","0.064"],["49959.8","0.016"],["49967.5","0.000"],["49967.6","0.000"],["49967.7","0.000"],["49967.8","0.000"],["49967.9","0.000"],["49969.1","0.000"],["49969.2","0.000"],["49970.1","0.055"],["49970.2","0.000"],["49971.4","0.006"],["49971.5","0.003"]],"a":[["49998.2","0.003"],["49998.3","0.006"],["49998.4","0.000"],["49998.5","0.000"],["49998.6","0.000"],["50068.6","0.060"],["50094.9","0.050"]]}}
1618677450.282191: {"stream":"xmrusdt@depth@100ms","data":{"e":"depthUpdate","E":1618677450162,"T":1618677450140,"s":"XMRUSDT","U":335340648115,"u":335340650100,"pu":335340647305,"b":[["352.18","37.208"],["352.19","7.814"]],"a":[["354.56","22.425"]]}}
1618677450.282261: {"stream":"yfiusdt@bookTicker","data":{"e":"bookTicker","u":335340650284,"s":"YFIUSDT","b":"49971.6","B":"0.025","a":"49986.7","A":"0.001","T":1618677450160,"E":1618677450164}}
1618677450.290195: {"stream":"ksmusdt@depth@100ms","data":{"e":"depthUpdate","E":1618677450193,"T":1618677450188,"s":"KSMUSDT","U":335340649178,"u":335340650809,"pu":335340648868,"b":[["453.741","19.9"],["454.343","0.0"],["456.591","0.0"],["457.969","0.0"],["458.204","1.1"],["458.842","5.0"],["459.154","0.0"]],"a":[["459.495","0.3"],["459.605","1.0"],["459.608","0.0"],["459.657","7.5"],["459.718","0.1"],["459.759","13.6"],["459.761","0.0"],["461.440","0.8"],["461.778","19.6"],["463.338","0.0"]]}}
1618677450.290545: {"stream":"dentusdt@kline_1m","data":{"e":"kline","E":1618677450194,"s":"DENTUSDT","k":{"t":1618677420000,"T":1618677479999,"s":"DENTUSDT","i":"1m","f":15787262,"L":15787366,"o":"0.012366","c":"0.012359","h":"0.012366","l":"0.012339","v":"1523072","n":105,"x":false,"q":"18813.161334","V":"943351","Q":"11654.775994","B":"0"}}}
1618677450.2906291: {"stream":"dentusdt@bookTicker","data":{"e":"bookTicker","u":335340650910,"s":"DENTUSDT","b":"0.012355","B":"55603","a":"0.012359","A":"8567","T":1618677450190,"E":1618677450195}}
1618677450.290658: {"stream":"yfiusdt@bookTicker","data":{"e":"bookTicker","u":335340651098,"s":"YFIUSDT","b":"49971.7","B":"0.003","a":"49986.7","A":"0.001","T":1618677450195,"E":1618677450200}}
1618677450.295407: {"stream":"yfiusdt@bookTicker","data":{"e":"bookTicker","u":335340651695,"s":"YFIUSDT","b":"49973.0","B":"0.006","a":"49986.7","A":"0.001","T":1618677450222,"E":1618677450228}}
1618677450.295511: {"stream":"dentusdt@depth@100ms","data":{"e":"depthUpdate","E":1618677450229,"T":1618677450210,"s":"DENTUSDT","U":335340649879,"u":335340651325,"pu":335340649184,"b":[["0.012322","88352"],["0.012327","441971"],["0.012340","0"],["0.012343","151089"],["0.012344","24139"],["0.012348","0"],["0.012349","1259"],["0.012353","8750"]],"a":[["0.012359","8567"],["0.012365","92973"]]}}
1618677450.295707: {"stream":"ksmusdt@bookTicker","data":{"e":"bookTicker","u":335340651917,"s":"KSMUSDT","b":"459.201","B":"1.2","a":"459.351","A":"0.1","T":1618677450229,"E":1618677450235}}
1618677450.301017: {"stream":"ksmusdt@kline_1m","data":{"e":"kline","E":1618677450244,"s":"KSMUSDT","k":{"t":1618677420000,"T":1618677479999,"s":"KSMUSDT","i":"1m","f":25426460,"L":25426556,"o":"459.607","c":"459.351","h":"459.671","l":"458.391","v":"98.6","n":97,"x":false,"q":"45261.5067","V":"51.0","Q":"23421.2154","B":"0"}}}
1618677450.3034098: {"stream":"ksmusdt@aggTrade","data":{"e":"aggTrade","E":1618677450245,"a":21396964,"s":"KSMUSDT","p":"459.351","q":"0.1","f":25426556,"l":25426556,"T":1618677450240,"m":false}}
1618677450.303514: {"stream":"ksmusdt@bookTicker","data":{"e":"bookTicker","u":335340652445,"s":"KSMUSDT","b":"459.201","B":"1.2","a":"459.496","A":"1.3","T":1618677450240,"E":1618677450245}}
1618677450.315574: {"stream":"yfiusdt@depth@100ms","data":{"e":"depthUpdate","E":1618677450256,"T":1618677450249,"s":"YFIUSDT","U":335340650162,"u":335340652726,"pu":335340649935,"b":[["49866.0","0.001"],["49875.5","0.000"],["49940.7","0.000"],["49946.2","0.000"],["49946.3","0.000"],["49950.1","0.285"],["49950.2","0.063"],["49952.4","0.009"],["49970.2","0.000"],["49971.4","0.000"],["49971.5","0.000"],["49971.6","0.025"],["49971.7","0.003"],["49973.0","0.006"]],"a":[["49998.3","0.003"],["50037.0","0.000"],["50043.0","0.009"],["50138.5","0.009"]]}}
1618677450.326593: {"stream":"yfiusdt@bookTicker","data":{"e":"bookTicker","u":335340653307,"s":"YFIUSDT","b":"49973.1","B":"0.003","a":"49986.7","A":"0.001","T":1618677450264,"E":1618677450268}}
1618677450.336946: {"stream":"yfiusdt@bookTicker","data":{"e":"bookTicker","u":335340653750,"s":"YFIUSDT","b":"49974.0","B":"0.055","a":"49986.7","A":"0.001","T":1618677450275,"E":1618677450279}}
1618677450.3465412: {"stream":"yfiusdt@bookTicker","data":{"e":"bookTicker","u":335340654083,"s":"YFIUSDT","b":"49975.3","B":"0.006","a":"49986.7","A":"0.001","T":1618677450284,"E":1618677450288}}
1618677450.356352: {"stream":"ksmusdt@depth@100ms","data":{"e":"depthUpdate","E":1618677450298,"T":1618677450292,"s":"KSMUSDT","U":335340651092,"u":335340654334,"pu":335340650809,"b":[["457.340","0.0"],["457.350","0.0"],["457.405","4.2"],["457.441","0.0"],["457.690","0.0"],["458.065","24.4"],["458.204","0.0"],["458.741","6.2"],["459.015","0.0"],["459.153","0.0"],["459.164","0.0"],["459.187","0.2"],["459.201","1.2"],["460.056","0.0"]],"a":[["459.351","0.0"],["459.495","0.0"],["459.534","2.3"],["459.605","2.4"],["459.606","0.0"],["459.607","0.0"],["459.625","1.0"],["459.758","2.8"],["459.760","0.0"],["459.794","2.0"],["459.810","0.0"],["459.884","0.0"],["460.250","0.0"],["461.480","0.1"],["462.455","0.0"],["463.170","0.2"]]}}
1618677450.368839: {"stream":"yfiusdt@bookTicker","data":{"e":"bookTicker","u":335340654750,"s":"YFIUSDT","b":"49975.4","B":"0.003","a":"49986.7","A":"0.001","T":1618677450306,"E":1618677450310}}
1618677450.399369: {"stream":"xmrusdt@depth@100ms","data":{"e":"depthUpdate","E":1618677450341,"T":1618677450327,"s":"XMRUSDT","U":335340652205,"u":335340655481,"pu":335340650100,"b":[["343.71","5.812"]],"a":[["352.66","0.000"],["352.67","1.801"]]}}
1618677450.400907: {"stream":"yfiusdt@bookTicker","data":{"e":"bookTicker","u":335340655899,"s":"YFIUSDT","b":"49976.7","B":"0.006","a":"49986.7","A":"0.001","T":1618677450340,"E":1618677450342}}
1618677450.403004: {"stream":"dentusdt@depth@100ms","data":{"e":"depthUpdate","E":1618677450345,"T":1618677450332,"s":"DENTUSDT","U":335340652392,"u":335340655644,"pu":335340651325,"b":[["0.012327","846600"],["0.012346","0"]],"a":[["0.012360","0"],["0.012373","41123"],["0.012380","107374"],["0.012391","17444"]]}}
1618677450.403213: {"stream":"dentusdt@aggTrade","data":{"e":"aggTrade","E":1618677450346,"a":8476389,"s":"DENTUSDT","p":"0.012359","q":"973","f":15787366,"l":15787366,"T":1618677450190,"m":false}}
1618677450.422716: {"stream":"yfiusdt@depth@100ms","data":{"e":"depthUpdate","E":1618677450365,"T":1618677450361,"s":"YFIUSDT","U":335340653181,"u":335340656604,"pu":335340652726,"b":[["49898.3","0.054"],["49911.0","0.000"],["49912.8","0.000"],["49917.0","0.000"],["49921.2","0.000"],["49924.1","0.000"],["49925.4","0.110"],["49929.6","0.110"],["49933.8","0.110"],["49936.4","0.080"],["49949.1","0.080"],["49966.1","0.000"],["49966.2","0.000"],["49971.7","0.000"],["49973.0","0.000"],["49973.1","0.000"],["49974.0","0.055"],["49975.3","0.000"],["49975.4","0.003"],["49976.7","0.006"]],"a":[["49998.2","0.000"],["49998.9","0.000"],["50004.2","0.015"],["50004.3","0.013"],["50007.0","0.014"],["50043.0","0.000"],["50065.8","0.009"],["50068.9","0.026"],["50151.5","0.001"]]}}
1618677450.436169: {"stream":"ksmusdt@bookTicker","data":{"e":"bookTicker","u":335340656931,"s":"KSMUSDT","b":"459.202","B":"0.2","a":"459.496","A":"1.3","T":1618677450373,"E":1618677450377}}
1618677450.440321: {"stream":"yfiusdt@bookTicker","data":{"e":"bookTicker","u":335340657144,"s":"YFIUSDT","b":"49976.8","B":"0.003","a":"49986.7","A":"0.001","T":1618677450379,"E":1618677450382}}
1618677450.445639: {"stream":"ksmusdt@bookTicker","data":{"e":"bookTicker","u":335340657293,"s":"KSMUSDT","b":"459.203","B":"1.2","a":"459.496","A":"1.3","T":1618677450384,"E":1618677450388}}
1618677450.453314: {"stream":"ksmusdt@aggTrade","data":{"e":"aggTrade","E":1618677450396,"a":21396965,"s":"KSMUSDT","p":"459.495","q":"0.3","f":25426557,"l":25426558,"T":1618677450240,"m":false}}
1618677450.460638: {"stream":"ksmusdt@depth@100ms","data":{"e":"depthUpdate","E":1618677450403,"T":1618677450389,"s":"KSMUSDT","U":335340654527,"u":335340657417,"pu":335340654334,"b":[["449.499","35.6"],["453.339","35.6"],["453.885","0.0"],["454.756","30.0"],["455.259","35.6"],["457.006","30.0"],["457.178","35.6"],["457.488","1.5"],["457.562","9.7"],["457.580","0.4"],["458.000","3.2"],["458.204","1.1"],["458.227","2.2"],["458.263","0.0"],["458.289","0.4"],["458.655","2.2"],["458.997","0.1"],["459.187","0.0"],["459.201","0.0"],["459.202","0.2"],["459.203","1.2"]],"a":[["459.574","0.0"],["459.604","1.0"],["459.605","1.4"],["459.625","0.0"],["459.757","13.6"],["459.758","0.0"],["459.759","0.0"],["459.955","1.7"],["460.106","0.3"],["460.574","3.2"],["460.639","0.2"],["460.669","0.0"],["460.841","1.2"],["461.140","9.7"],["461.509","30.0"],["461.641","0.4"],["461.656","35.6"],["461.996","0.0"],["462.711","0.1"],["462.961","0.0"],["463.759","30.0"],["464.239","35.6"],["466.821","35.6"],["471.986","35.6"]]}}
1618677450.50511: {"stream":"dentusdt@depth@100ms","data":{"e":"depthUpdate","E":1618677450445,"T":1618677450432,"s":"DENTUSDT","U":335340655987,"u":335340658454,"pu":335340655644,"b":[["0.000011","21805663"],["0.012304","66511"],["0.012321","27020"],["0.012326","73749"],["0.012332","798"],["0.012342","459815"],["0.012349","1259"],["0.012352","8947"],["0.012353","0"]],"a":[["0.012377","0"],["0.012384","37800"]]}}
1618677450.5053701: {"stream":"xmrusdt@depth@100ms","data":{"e":"depthUpdate","E":1618677450446,"T":1618677450380,"s":"XMRUSDT","U":335340656039,"u":335340657169,"pu":335340655481,"b":[["352.03","13.903"],["352.11","4.951"],["352.20","0.000"],["352.21","0.000"],["352.23","19.667"]],"a":[]}}
1618677450.539528: {"stream":"yfiusdt@depth@100ms","data":{"e":"depthUpdate","E":1618677450482,"T":1618677450467,"s":"YFIUSDT","U":335340657129,"u":335340659314,"pu":335340656604,"b":[["49875.7","0.100"],["49930.1","0.025"],["49936.7","0.000"],["49938.5","0.009"],["49942.7","0.233"],["49950.1","0.000"],["49950.2","0.000"],["49952.4","0.000"],["49975.4","0.000"],["49976.8","0.003"]],"a":[["49998.3","0.000"],["50004.1","0.003"],["50004.2","0.000"],["50010.8","0.030"],["50042.3","0.000"],["50059.2","0.010"],["50089.9","0.100"],["50121.5","0.000"]]}}
1618677450.563704: {"stream":"ksmusdt@depth@100ms","data":{"e":"depthUpdate","E":1618677450506,"T":1618677450496,"s":"KSMUSDT","U":335340657727,"u":335340660092,"pu":335340657417,"b":[["457.877","0.0"],["458.067","0.0"],["458.098","0.8"],["458.204","0.0"],["458.228","2.3"],["458.229","1.1"],["458.289","0.0"],["458.843","0.2"],["459.202","0.0"]],"a":[["459.534","0.0"],["459.565","2.3"],["459.604","0.0"],["459.757","0.0"],["460.014","2.2"],["460.244","8.0"],["460.528","1.0"],["460.590","0.0"],["460.653","2.3"],["460.933","1.6"],["460.980","6.0"],["461.199","0.0"],["461.335","2.5"],["462.871","1.9"]]}}
1618677450.608342: {"stream":"dentusdt@depth@100ms","data":{"e":"depthUpdate","E":1618677450549,"T":1618677450536,"s":"DENTUSDT","U":335340658730,"u":335340661009,"pu":335340658454,"b":[["0.012327","793747"],["0.012338","4702"],["0.012349","1259"]],"a":[["0.012361","0"],["0.012362","51464"],["0.012373","41123"],["0.012380","107372"],["0.012396","215561"]]}}
1618677450.63008: {"stream":"ksmusdt@bookTicker","data":{"e":"bookTicker","u":335340661869,"s":"KSMUSDT","b":"459.204","B":"0.2","a":"459.496","A":"1.3","T":1618677450568,"E":1618677450572}}
1618677450.641352: {"stream":"ksmusdt@bookTicker","data":{"e":"bookTicker","u":335340662274,"s":"KSMUSDT","b":"459.212","B":"1.2","a":"459.496","A":"1.3","T":1618677450580,"E":1618677450584}}
1618677450.653126: {"stream":"yfiusdt@depth@100ms","data":{"e":"depthUpdate","E":1618677450595,"T":1618677450572,"s":"YFIUSDT","U":335340659979,"u":335340662025,"pu":335340659314,"b":[["49527.9","0.000"],["49752.8","0.000"],["49843.3","0.000"],["49881.8","0.021"],["49899.7","0.000"],["49930.1","0.000"],["49933.9","0.308"]],"a":[["50003.8","0.003"],["50003.9","0.030"],["50004.0","0.111"],["50004.1","0.000"],["50010.8","0.000"],["50010.9","0.000"],["50011.0","0.000"],["50011.1","0.000"],["50077.1","0.000"],["50089.9","0.000"],["50202.5","0.000"],["50427.4","0.000"]]}}
1618677450.65839: {"stream":"yfiusdt@bookTicker","data":{"e":"bookTicker","u":335340662680,"s":"YFIUSDT","b":"49976.8","B":"0.003","a":"49981.8","A":"0.001","T":1618677450596,"E":1618677450601}}
1618677450.6726558: {"stream":"ksmusdt@depth@100ms","data":{"e":"depthUpdate","E":1618677450615,"T":1618677450605,"s":"KSMUSDT","U":335340660506,"u":335340662963,"pu":335340660092,"b":[["452.942","0.0"],["454.629","0.0"],["454.804","15.0"],["456.609","0.0"],["457.451","2.1"],["457.865","0.0"],["458.229","0.0"],["458.298","0.8"],["458.785","0.5"],["458.843","0.0"],["459.203","0.0"],["459.204","0.2"],["459.212","1.2"]],"a":[["459.603","1.4"],["459.605","0.0"],["459.690","0.1"],["459.919","2.2"],["460.080","0.0"],["460.244","0.0"],["460.415","0.8"],["460.437","31.5"],["460.655","1.9"],["461.327","0.1"],["463.898","15.0"]]}}
1618677450.684164: {"stream":"yfiusdt@bookTicker","data":{"e":"bookTicker","u":335340663515,"s":"YFIUSDT","b":"49978.1","B":"0.006","a":"49981.8","A":"0.001","T":1618677450622,"E":1618677450626}}
1618677450.738685: {"stream":"xmrusdt@depth@100ms","data":{"e":"depthUpdate","E":1618677450681,"T":1618677450668,"s":"XMRUSDT","U":335340662148,"u":335340664952,"pu":335340657169,"b":[["352.32","0.000"],["352.36","0.000"],["352.38","6.019"],["352.39","2.500"]],"a":[["352.68","0.000"],["352.86","0.000"],["352.95","2.500"],["353.36","10.993"]]}}
1618677450.743862: {"stream":"yfiusdt@bookTicker","data":{"e":"bookTicker","u":335340665481,"s":"YFIUSDT","b":"49976.8","B":"0.003","a":"49981.8","A":"0.001","T":1618677450681,"E":1618677450687}}
1618677450.7523909: {"stream":"yfiusdt@depth@100ms","data":{"e":"depthUpdate","E":1618677450696,"T":1618677450681,"s":"YFIUSDT","U":335340662537,"u":335340665481,"pu":335340662025,"b":[["49533.4","0.083"],["49758.3","0.083"],["49936.5","0.168"],["49942.7","0.065"],["49976.7","0.000"],["49978.1","0.000"]],"a":[["49981.8","0.001"],["50004.0","0.000"],["50049.6","0.064"],["50180.7","0.000"],["50208.0","0.083"],["50433.0","0.083"]]}}
1618677450.770692: {"stream":"dentusdt@depth@100ms","data":{"e":"depthUpdate","E":1618677450713,"T":1618677450650,"s":"DENTUSDT","U":335340663133,"u":335340664310,"pu":335340661009,"b":[["0.012310","36047"],["0.012331","288607"],["0.012349","1259"]],"a":[]}}
1618677450.777567: {"stream":"ksmusdt@depth@100ms","data":{"e":"depthUpdate","E":1618677450719,"T":1618677450706,"s":"KSMUSDT","U":335340663256,"u":335340666295,"pu":335340662963,"b":[["445.764","0.0"],["456.501","0.0"],["456.618","0.0"],["456.655","0.1"],["458.062","6.2"],["458.229","0.0"]],"a":[["459.634","0.3"],["459.803","0.0"],["459.919","0.0"],["460.436","1.0"],["460.517","1.6"],["460.528","0.0"],["460.862","1.6"],["461.101","0.0"],["461.468","2.3"]]}}
1618677450.77888: {"stream":"ksmusdt@bookTicker","data":{"e":"bookTicker","u":335340666698,"s":"KSMUSDT","b":"459.213","B":"0.2","a":"459.496","A":"1.3","T":1618677450715,"E":1618677450720}}
1618677450.789688: {"stream":"yfiusdt@bookTicker","data":{"e":"bookTicker","u":335340666998,"s":"YFIUSDT","b":"49974.0","B":"0.055","a":"49981.8","A":"0.001","T":1618677450726,"E":1618677450732}}
1618677450.790217: {"stream":"ksmusdt@bookTicker","data":{"e":"bookTicker","u":335340667114,"s":"KSMUSDT","b":"459.225","B":"1.2","a":"459.496","A":"1.3","T":1618677450730,"E":1618677450734}}
1618677450.802989: {"stream":"yfiusdt@bookTicker","data":{"e":"bookTicker","u":335340667390,"s":"YFIUSDT","b":"49975.3","B":"0.006","a":"49981.8","A":"0.001","T":1618677450738,"E":1618677450743}}
1618677450.855696: {"stream":"xmrusdt@depth@100ms","data":{"e":"depthUpdate","E":1618677450798,"T":1618677450784,"s":"XMRUSDT","U":335340665855,"u":335340669016,"pu":335340664952,"b":[["351.61","68.426"],["351.63","0.000"]],"a":[["352.86","2.500"],["352.95","0.000"],["353.44","23.178"],["353.45","0.000"],["354.49","0.000"]]}}
1618677450.876825: {"stream":"ksmusdt@depth@100ms","data":{"e":"depthUpdate","E":1618677450820,"T":1618677450810,"s":"KSMUSDT","U":335340666698,"u":335340669855,"pu":335340666295,"b":[["457.896","0.0"],["458.229","1.1"],["459.204","0.0"],["459.212","0.0"],["459.213","0.2"],["459.225","1.2"]],"a":[["459.564","1.4"],["459.603","0.0"],["459.657","5.9"],["460.087","2.7"],["460.174","0.0"],["460.192","0.0"],["460.436","1.0"],["461.255","0.1"],["461.467","4.7"]]}}
1618677450.877146: {"stream":"dentusdt@depth@100ms","data":{"e":"depthUpdate","E":1618677450820,"T":1618677450810,"s":"DENTUSDT","U":335340666687,"u":335340669849,"pu":335340664310,"b":[["0.012320","86715"],["0.012349","1259"]],"a":[["0.012372","6580"],["0.012386","17444"],["0.012390","2887"],["0.012424","83159"]]}}
1618677450.8812659: {"stream":"ksmusdt@bookTicker","data":{"e":"bookTicker","u":335340670102,"s":"KSMUSDT","b":"459.272","B":"3.9","a":"459.496","A":"1.3","T":1618677450819,"E":1618677450823}}
1618677450.8813708: {"stream":"ksmusdt@bookTicker","data":{"e":"bookTicker","u":335340670108,"s":"KSMUSDT","b":"459.272","B":"2.3","a":"459.496","A":"1.3","T":1618677450819,"E":1618677450823}}
1618677450.881414: {"stream":"ksmusdt@kline_1m","data":{"e":"kline","E":1618677450824,"s":"KSMUSDT","k":{"t":1618677420000,"T":1618677479999,"s":"KSMUSDT","i":"1m","f":25426460,"L":25426559,"o":"459.607","c":"459.272","h":"459.671","l":"458.391","v":"100.5","n":100,"x":false,"q":"46134.1904","V":"51.3","Q":"23559.0639","B":"0"}}}
1618677450.885298: {"stream":"ksmusdt@bookTicker","data":{"e":"bookTicker","u":335340670171,"s":"KSMUSDT","b":"459.225","B":"1.2","a":"459.496","A":"1.3","T":1618677450822,"E":1618677450827}}
1618677450.88957: {"stream":"yfiusdt@depth@100ms","data":{"e":"depthUpdate","E":1618677450832,"T":1618677450823,"s":"YFIUSDT","U":335340666998,"u":335340670209,"pu":335340665481,"b":[["49798.7","0.027"],["49825.2","0.000"],["49905.4","0.010"],["49912.9","0.000"],["49971.7","0.003"],["49975.3","0.006"],["49976.8","0.000"]],"a":[["50036.8","0.000"],["50044.7","0.021"],["50090.0","0.028"],["50102.6","0.000"],["50121.6","0.000"],["50146.5","0.007"]]}}
1618677450.8939352: {"stream":"ksmusdt@bookTicker","data":{"e":"bookTicker","u":335340670497,"s":"KSMUSDT","b":"459.213","B":"0.2","a":"459.496","A":"1.3","T":1618677450831,"E":1618677450836}}
1618677450.894041: {"stream":"ksmusdt@bookTicker","data":{"e":"bookTicker","u":335340670513,"s":"KSMUSDT","b":"459.283","B":"1.2","a":"459.496","A":"1.3","T":1618677450832,"E":1618677450836}}
1618677450.897723: {"stream":"ksmusdt@bookTicker","data":{"e":"bookTicker","u":335340670613,"s":"KSMUSDT","b":"459.213","B":"0.2","a":"459.496","A":"1.3","T":1618677450835,"E":1618677450840}}
1618677450.8978271: {"stream":"ksmusdt@bookTicker","data":{"e":"bookTicker","u":335340670632,"s":"KSMUSDT","b":"459.214","B":"1.2","a":"459.496","A":"1.3","T":1618677450836,"E":1618677450840}}
1618677450.9274418: {"stream":"yfiusdt@kline_1m","data":{"e":"kline","E":1618677450870,"s":"YFIUSDT","k":{"t":1618677420000,"T":1618677479999,"s":"YFIUSDT","i":"1m","f":64902095,"L":64902165,"o":"50010.8","c":"49981.8","h":"50044.2","l":"49950.6","v":"0.844","n":71,"x":false,"q":"42199.6293","V":"0.539","Q":"26950.2109","B":"0"}}}
1618677450.9308429: {"stream":"yfiusdt@aggTrade","data":{"e":"aggTrade","E":1618677450871,"a":52599687,"s":"YFIUSDT","p":"49981.8","q":"0.001","f":64902165,"l":64902165,"T":1618677450865,"m":false}}
1618677450.930945: {"stream":"yfiusdt@bookTicker","data":{"e":"bookTicker","u":335340671654,"s":"YFIUSDT","b":"49975.3","B":"0.006","a":"50003.8","A":"0.003","T":1618677450865,"E":1618677450871}}
1618677450.942044: {"stream":"yfiusdt@bookTicker","data":{"e":"bookTicker","u":335340672176,"s":"YFIUSDT","b":"49975.3","B":"0.006","a":"50003.8","A":"0.016","T":1618677450882,"E":1618677450884}}
1618677450.944758: {"stream":"yfiusdt@bookTicker","data":{"e":"bookTicker","u":335340672225,"s":"YFIUSDT","b":"49975.3","B":"0.006","a":"50001.4","A":"0.055","T":1618677450882,"E":1618677450886}}
1618677450.9448588: {"stream":"yfiusdt@aggTrade","data":{"e":"aggTrade","E":1618677450886,"a":52599688,"s":"YFIUSDT","p":"49986.7","q":"0.001","f":64902166,"l":64902166,"T":1618677450865,"m":false}}
1618677450.944911: {"stream":"yfiusdt@bookTicker","data":{"e":"bookTicker","u":335340672242,"s":"YFIUSDT","b":"49975.3","B":"0.006","a":"50001.4","A":"0.042","T":1618677450883,"E":1618677450886}}
1618677450.958722: {"stream":"yfiusdt@bookTicker","data":{"e":"bookTicker","u":335340672608,"s":"YFIUSDT","b":"49975.3","B":"0.006","a":"50003.8","A":"0.016","T":1618677450895,"E":1618677450900}}
1618677450.96136: {"stream":"yfiusdt@bookTicker","data":{"e":"bookTicker","u":335340672675,"s":"YFIUSDT","b":"49975.4","B":"0.005","a":"50003.8","A":"0.016","T":1618677450897,"E":1618677450902}}
1618677450.96458: {"stream":"yfiusdt@bookTicker","data":{"e":"bookTicker","u":335340672925,"s":"YFIUSDT","b":"49975.4","B":"0.005","a":"50003.8","A":"0.003","T":1618677450905,"E":1618677450908}}
1618677450.9667861: {"stream":"yfiusdt@bookTicker","data":{"e":"bookTicker","u":335340672937,"s":"YFIUSDT","b":"49975.4","B":"0.005","a":"50003.9","A":"0.030","T":1618677450905,"E":1618677450910}}
1618677450.966887: {"stream":"yfiusdt@bookTicker","data":{"e":"bookTicker","u":335340672948,"s":"YFIUSDT","b":"49975.4","B":"0.005","a":"50002.6","A":"0.014","T":1618677450906,"E":1618677450910}}
1618677450.96693: {"stream":"yfiusdt@bookTicker","data":{"e":"bookTicker","u":335340672949,"s":"YFIUSDT","b":"49975.4","B":"0.005","a":"50001.3","A":"0.003","T":1618677450906,"E":1618677450910}}
1618677450.966963: {"stream":"yfiusdt@bookTicker","data":{"e":"bookTicker","u":335340672950,"s":"YFIUSDT","b":"49975.4","B":"0.008","a":"50001.3","A":"0.003","T":1618677450906,"E":1618677450910}}
1618677450.967486: {"stream":"yfiusdt@bookTicker","data":{"e":"bookTicker","u":335340673014,"s":"YFIUSDT","b":"49975.4","B":"0.008","a":"50000.9","A":"0.055","T":1618677450909,"E":1618677450912}}
1618677450.971139: {"stream":"yfiusdt@bookTicker","data":{"e":"bookTicker","u":335340673050,"s":"YFIUSDT","b":"49975.4","B":"0.013","a":"50000.9","A":"0.055","T":1618677450910,"E":1618677450914}}
1618677450.975512: {"stream":"yfiusdt@bookTicker","data":{"e":"bookTicker","u":335340673153,"s":"YFIUSDT","b":"49975.4","B":"0.008","a":"50000.9","A":"0.055","T":1618677450913,"E":1618677450917}}
1618677450.977911: {"stream":"yfiusdt@bookTicker","data":{"e":"bookTicker","u":335340673189,"s":"YFIUSDT","b":"49975.5","B":"0.005","a":"50000.9","A":"0.055","T":1618677450915,"E":1618677450919}}
1618677450.980109: {"stream":"ksmusdt@depth@100ms","data":{"e":"depthUpdate","E":1618677450923,"T":1618677450909,"s":"KSMUSDT","U":335340670102,"u":335340673004,"pu":335340669855,"b":[["459.108","0.0"],["459.214","1.2"],["459.225","0.0"],["459.272","0.0"],["459.283","0.0"]],"a":[["460.247","0.0"],["460.462","2.3"],["460.514","5.7"],["460.659","5.9"]]}}
1618677450.986083: {"stream":"ksmusdt@bookTicker","data":{"e":"bookTicker","u":335340673470,"s":"KSMUSDT","b":"459.226","B":"0.2","a":"459.496","A":"1.3","T":1618677450924,"E":1618677450927}}
1618677450.986805: {"stream":"yfiusdt@bookTicker","data":{"e":"bookTicker","u":335340673559,"s":"YFIUSDT","b":"49975.5","B":"0.008","a":"50000.9","A":"0.055","T":1618677450927,"E":1618677450931}}
1618677450.990433: {"stream":"yfiusdt@bookTicker","data":{"e":"bookTicker","u":335340673604,"s":"YFIUSDT","b":"49975.5","B":"0.003","a":"50000.9","A":"0.055","T":1618677450929,"E":1618677450932}}
1618677450.9905338: {"stream":"yfiusdt@bookTicker","data":{"e":"bookTicker","u":335340673611,"s":"YFIUSDT","b":"49975.6","B":"0.004","a":"50000.9","A":"0.055","T":1618677450929,"E":1618677450932}}
1618677450.995696: {"stream":"yfiusdt@depth@100ms","data":{"e":"depthUpdate","E":1618677450936,"T":1618677450929,"s":"YFIUSDT","U":335340670478,"u":335340673619,"pu":335340670209,"b":[["49769.0","0.014"],["49875.7","0.000"],["49918.4","0.155"],["49925.4","0.000"],["49929.6","0.000"],["49933.9","0.000"],["49934.4","0.000"],["49936.5","0.000"],["49938.0","0.110"],["49942.2","0.110"],["49942.8","0.308"],["49949.2","0.000"],["49953.4","0.000"],["49971.7","0.000"],["49975.4","0.003"],["49975.5","0.003"],["49975.6","0.004"],["50481.6","0.000"]],"a":[["49981.8","0.000"],["49986.7","0.000"],["50000.9","0.055"],["50001.3","0.003"],["50001.4","0.000"],["50002.2","0.013"],["50002.6","0.000"],["50003.8","0.000"],["50004.3","0.000"],["50020.0","0.000"],["50025.0","0.000"],["50044.9","0.000"],["50054.9","0.000"],["50073.9","0.011"],["50102.7","0.000"],["50117.2","0.400"],["50138.7","0.000"],["50163.9","0.000"],["50174.9","0.014"]]}}
1618677450.996215: {"stream":"dentusdt@depth@100ms","data":{"e":"depthUpdate","E":1618677450938,"T":1618677450916,"s":"DENTUSDT","U":335340670569,"u":335340673240,"pu":335340669849,"b":[],"a":[["0.012364","157109"],["0.012365","0"],["0.012368","0"],["0.012373","52316"]]}}
1618677451.002303: {"stream":"yfiusdt@bookTicker","data":{"e":"bookTicker","u":335340673931,"s":"YFIUSDT","b":"49975.6","B":"0.007","a":"50000.9","A":"0.055","T":1618677450939,"E":1618677450941}}
1618677451.002406: {"stream":"yfiusdt@bookTicker","data":{"e":"bookTicker","u":335340673934,"s":"YFIUSDT","b":"49975.6","B":"0.007","a":"50000.8","A":"0.003","T":1618677450939,"E":1618677450943}}
1618677451.002819: {"stream":"yfiusdt@bookTicker","data":{"e":"bookTicker","u":335340674027,"s":"YFIUSDT","b":"49975.6","B":"0.009","a":"50000.8","A":"0.003","T":1618677450941,"E":1618677450945}}
1618677451.016691: {"stream":"yfiusdt@bookTicker","data":{"e":"bookTicker","u":335340674337,"s":"YFIUSDT","b":"49975.6","B":"0.007","a":"50000.8","A":"0.003","T":1618677450952,"E":1618677450956}}
1618677451.016792: {"stream":"yfiusdt@bookTicker","data":{"e":"bookTicker","u":335340674338,"s":"YFIUSDT","b":"49975.6","B":"0.003","a":"50000.8","A":"0.003","T":1618677450952,"E":1618677450956}}
1618677451.016835: {"stream":"yfiusdt@bookTicker","data":{"e":"bookTicker","u":335340674365,"s":"YFIUSDT","b":"49975.7","B":"0.006","a":"50000.8","A":"0.003","T":1618677450953,"E":1618677450957}}
1618677451.016868: {"stream":"xmrusdt@depth@100ms","data":{"e":"depthUpdate","E":1618677450959,"T":1618677450929,"s":"XMRUSDT","U":335340671303,"u":335340673599,"pu":335340669016,"b":[["352.30","2.500"],["352.39","0.000"]],"a":[["353.36","0.612"],["354.54","1.621"],["355.97","20.529"]]}}
1618677451.027904: {"stream":"yfiusdt@bookTicker","data":{"e":"bookTicker","u":335340674722,"s":"YFIUSDT","b":"49975.6","B":"0.003","a":"50000.8","A":"0.003","T":1618677450966,"E":1618677450971}}
1618677451.031014: {"stream":"ksmusdt@aggTrade","data":{"e":"aggTrade","E":1618677450974,"a":21396966,"s":"KSMUSDT","p":"459.272","q":"1.6","f":25426559,"l":25426559,"T":1618677450819,"m":true}}
1618677451.121813: {"stream":"yfiusdt@bookTicker","data":{"e":"bookTicker","u":335340674899,"s":"YFIUSDT","b":"49975.3","B":"0.006","a":"50000.8","A":"0.003","T":1618677450970,"E":1618677450975}}
1618677451.121912: {"stream":"yfiusdt@bookTicker","data":{"e":"bookTicker","u":335340674918,"s":"YFIUSDT","b":"49975.8","B":"0.003","a":"50000.8","A":"0.003","T":1618677450970,"E":1618677450975}}
1618677451.12196: {"stream":"ksmusdt@bookTicker","data":{"e":"bookTicker","u":335340675189,"s":"KSMUSDT","b":"459.215","B":"0.2","a":"459.496","A":"1.3","T":1618677450978,"E":1618677450982}}
1618677451.121996: {"stream":"yfiusdt@bookTicker","data":{"e":"bookTicker","u":335340675360,"s":"YFIUSDT","b":"49975.9","B":"0.003","a":"50000.8","A":"0.003","T":1618677450985,"E":1618677450989}}
1618677451.1220338: {"stream":"ksmusdt@bookTicker","data":{"e":"bookTicker","u":335340675540,"s":"KSMUSDT","b":"459.216","B":"1.2","a":"459.496","A":"1.3","T":1618677450992,"E":1618677450996}}
1618677451.1220748: {"stream":"yfiusdt@bookTicker","data":{"e":"bookTicker","u":335340675730,"s":"YFIUSDT","b":"49975.9","B":"0.005","a":"50000.8","A":"0.003","T":1618677451000,"E":1618677451004}}
1618677451.122092: {"stream":"yfiusdt@bookTicker","data":{"e":"bookTicker","u":335340676069,"s":"YFIUSDT","b":"49975.9","B":"0.003","a":"50000.8","A":"0.003","T":1618677451010,"E":1618677451014}}
1618677451.122109: {"stream":"yfiusdt@bookTicker","data":{"e":"bookTicker","u":335340676094,"s":"YFIUSDT","b":"49975.8","B":"0.003","a":"50000.8","A":"0.003","T":1618677451010,"E":1618677451014}}
1618677451.1221251: {"stream":"ksmusdt@depth@100ms","data":{"e":"depthUpdate","E":1618677451027,"T":1618677451018,"s":"KSMUSDT","U":335340673470,"u":335340676349,"pu":335340673004,"b":[["458.229","1.1"],["459.213","0.0"],["459.214","0.0"],["459.215","0.2"],["459.216","1.2"],["459.226","0.0"]],"a":[["459.690","0.0"],["459.882","13.6"],["460.405","2.3"],["460.788","2.6"],["461.528","4.5"],["462.940","0.0"],["464.210","4.4"]]}}
1618677451.122287: {"stream":"yfiusdt@bookTicker","data":{"e":"bookTicker","u":335340676548,"s":"YFIUSDT","b":"49975.8","B":"0.003","a":"50000.7","A":"0.014","T":1618677451023,"E":1618677451027}}
1618677451.1223109: {"stream":"yfiusdt@bookTicker","data":{"e":"bookTicker","u":335340676742,"s":"YFIUSDT","b":"49976.0","B":"0.021","a":"50000.7","A":"0.014","T":1618677451028,"E":1618677451032}}
1618677451.1223302: {"stream":"yfiusdt@aggTrade","data":{"e":"aggTrade","E":1618677451037,"a":52599689,"s":"YFIUSDT","p":"50001.4","q":"0.013","f":64902167,"l":64902167,"T":1618677450883,"m":false}}
1618677451.122354: {"stream":"yfiusdt@depth@100ms","data":{"e":"depthUpdate","E":1618677451039,"T":1618677451028,"s":"YFIUSDT","U":335340673810,"u":335340676768,"pu":335340673619,"b":[["49903.8","0.025"],["49918.4","0.130"],["49925.4","0.110"],["49929.6","0.110"],["49938.0","0.000"],["49942.2","0.000"],["49942.9","0.080"],["49945.5","0.087"],["49970.2","0.012"],["49975.4","0.000"],["49975.5","0.000"],["49975.6","0.000"],["49975.7","0.000"],["49975.8","0.003"],["49975.9","0.000"],["49976.0","0.021"]],"a":[["50000.7","0.014"],["50000.8","0.003"],["50001.3","0.012"],["50001.5","0.000"],["50001.7","0.000"],["50002.2","0.000"],["50003.8","0.000"],["50003.9","0.000"],["50025.5","0.000"],["50047.4","0.000"],["50053.1","0.094"],["50060.9","0.022"],["50068.0","0.000"],["50077.1","0.073"],["50092.8","0.009"],["50111.9","0.001"],["50124.3","0.000"],["50132.1","0.001"],["50137.5","0.001"],["50168.4","0.000"],["50174.2","0.157"],["50191.8","0.004"],["50218.2","0.000"]]}}
1618677451.122625: {"stream":"dentusdt@depth@100ms","data":{"e":"depthUpdate","E":1618677451043,"T":1618677451035,"s":"DENTUSDT","U":335340673954,"u":335340677113,"pu":335340673240,"b":[["0.012322","58454"],["0.012323","1556"],["0.012349","1259"]],"a":[["0.012364","520"],["0.012375","5538"],["0.012383","38962"],["0.012397","160517"]]}}
1618677451.122689: {"stream":"yfiusdt@bookTicker","data":{"e":"bookTicker","u":335340677300,"s":"YFIUSDT","b":"49976.0","B":"0.021","a":"50000.6","A":"0.012","T":1618677451040,"E":1618677451046}}
1618677451.122713: {"stream":"yfiusdt@bookTicker","data":{"e":"bookTicker","u":335340677390,"s":"YFIUSDT","b":"49976.0","B":"0.021","a":"50000.6","A":"0.015","T":1618677451041,"E":1618677451046}}
1618677451.122731: {"stream":"yfiusdt@bookTicker","data":{"e":"bookTicker","u":335340677395,"s":"YFIUSDT","b":"49976.1","B":"0.003","a":"50000.6","A":"0.015","T":1618677451041,"E":1618677451046}}
1618677451.1227489: {"stream":"yfiusdt@bookTicker","data":{"e":"bookTicker","u":335340677482,"s":"YFIUSDT","b":"49976.1","B":"0.003","a":"49998.4","A":"0.055","T":1618677451044,"E":1618677451048}}
1618677451.217997: {"stream":"yfiusdt@bookTicker","data":{"e":"bookTicker","u":335340677901,"s":"YFIUSDT","b":"49976.2","B":"0.019","a":"49998.4","A":"0.055","T":1618677451054,"E":1618677451059}}
1618677451.2180989: {"stream":"yfiusdt@bookTicker","data":{"e":"bookTicker","u":335340678004,"s":"YFIUSDT","b":"49976.2","B":"0.019","a":"49998.3","A":"0.027","T":1618677451057,"E":1618677451062}}
1618677451.218142: {"stream":"xmrusdt@depth@100ms","data":{"e":"depthUpdate","E":1618677451065,"T":1618677451050,"s":"XMRUSDT","U":335340674561,"u":335340677736,"pu":335340673599,"b":[["344.41","48.282"],["352.13","2.500"],["352.18","14.000"],["352.19","2.941"],["352.20","15.695"],["352.21","3.295"],["352.23","4.057"],["352.24","0.000"],["352.30","0.000"],["352.31","0.000"],["352.39","0.000"]],"a":[]}}
1618677451.221318: {"stream":"yfiusdt@bookTicker","data":{"e":"bookTicker","u":335340678459,"s":"YFIUSDT","b":"49976.1","B":"0.003","a":"49998.3","A":"0.027","T":1618677451068,"E":1618677451073}}
1618677451.22139: {"stream":"yfiusdt@bookTicker","data":{"e":"bookTicker","u":335340678466,"s":"YFIUSDT","b":"49976.4","B":"0.020","a":"49998.3","A":"0.027","T":1618677451068,"E":1618677451073}}
1618677451.221417: {"stream":"yfiusdt@bookTicker","data":{"e":"bookTicker","u":335340678537,"s":"YFIUSDT","b":"49976.4","B":"0.020","a":"49998.4","A":"0.055","T":1618677451070,"E":1618677451075}}
1618677451.224579: {"stream":"yfiusdt@bookTicker","data":{"e":"bookTicker","u":335340678767,"s":"YFIUSDT","b":"49976.5","B":"0.003","a":"49998.4","A":"0.055","T":1618677451082,"E":1618677451086}}
1618677451.225764: {"stream":"yfiusdt@bookTicker","data":{"e":"bookTicker","u":335340678958,"s":"YFIUSDT","b":"49976.6","B":"0.016","a":"49998.4","A":"0.055","T":1618677451093,"E":1618677451097}}
1618677451.226121: {"stream":"yfiusdt@bookTicker","data":{"e":"bookTicker","u":335340679087,"s":"YFIUSDT","b":"49976.6","B":"0.016","a":"49998.3","A":"0.026","T":1618677451106,"E":1618677451108}}
1618677451.230259: {"stream":"ksmusdt@depth@100ms","data":{"e":"depthUpdate","E":1618677451127,"T":1618677451109,"s":"KSMUSDT","U":335340676460,"u":335340679270,"pu":335340676349,"b":[["458.229","1.1"]],"a":[["459.536","2.5"],["459.563","0.5"],["459.565","0.0"],["459.702","0.1"],["459.718","0.0"],["459.785","0.1"],["459.874","2.8"],["459.875","0.0"],["459.882","0.0"],["459.941","0.1"],["460.267","2.4"],["460.436","0.0"],["460.655","0.0"]]}}
1618677451.230531: {"stream":"ksmusdt@bookTicker","data":{"e":"bookTicker","u":335340679528,"s":"KSMUSDT","b":"459.217","B":"0.2","a":"459.496","A":"1.3","T":1618677451130,"E":1618677451134}}
1618677451.230858: {"stream":"yfiusdt@bookTicker","data":{"e":"bookTicker","u":335340679694,"s":"YFIUSDT","b":"49976.7","B":"0.003","a":"49998.3","A":"0.026","T":1618677451132,"E":1618677451136}}
1618677451.230902: {"stream":"yfiusdt@bookTicker","data":{"e":"bookTicker","u":335340679844,"s":"YFIUSDT","b":"49976.7","B":"0.003","a":"49998.2","A":"0.003","T":1618677451134,"E":1618677451139}}
1618677451.231988: {"stream":"yfiusdt@depth@100ms","data":{"e":"depthUpdate","E":1618677451143,"T":1618677451134,"s":"YFIUSDT","U":335340677232,"u":335340679844,"pu":335340676768,"b":[["49744.9","0.000"],["49812.7","0.000"],["49823.4","0.000"],["49867.0","0.000"],["49881.8","0.000"],["49905.7","0.000"],["49974.1","0.012"],["49975.8","0.000"],["49976.0","0.000"],["49976.1","0.000"],["49976.2","0.000"],["49976.4","0.000"],["49976.5","0.000"],["49976.6","0.000"],["49976.7","0.003"]],"a":[["49998.2","0.003"],["49998.3","0.026"],["49998.4","0.055"],["50000.1","0.012"],["50000.3","0.000"],["50000.4","0.000"],["50000.5","0.000"],["50000.6","0.000"],["50000.7","0.000"],["50000.8","0.000"],["50001.3","0.000"],["50003.1","0.000"],["50004.6","0.000"],["50035.5","0.000"],["50244.9","0.000"],["50987.0","0.000"]]}}
1618677451.23228: {"stream":"dentusdt@depth@100ms","data":{"e":"depthUpdate","E":1618677451147,"T":1618677451131,"s":"DENTUSDT","U":335340677415,"u":335340679588,"pu":335340677113,"b":[["0.012173","813"],["0.012322","36372"],["0.012349","1259"],["0.012352","0"]],"a":[["0.012362","0"],["0.012373","22504"],["0.012378","0"],["0.012380","38712"]]}}
1618677451.239445: {"stream":"yfiusdt@bookTicker","data":{"e":"bookTicker","u":335340680650,"s":"YFIUSDT","b":"49976.7","B":"0.003","a":"49998.1","A":"0.026","T":1618677451160,"E":1618677451164}}
1618677451.239545: {"stream":"yfiusdt@bookTicker","data":{"e":"bookTicker","u":335340680860,"s":"YFIUSDT","b":"49976.8","B":"0.013","a":"49998.1","A":"0.026","T":1618677451163,"E":1618677451168}}
1618677451.23959: {"stream":"yfiusdt@bookTicker","data":{"e":"bookTicker","u":335340681268,"s":"YFIUSDT","b":"49976.8","B":"0.013","a":"49998.2","A":"0.003","T":1618677451171,"E":1618677451174}}
1618677451.2396228: {"stream":"yfiusdt@bookTicker","data":{"e":"bookTicker","u":335340681277,"s":"YFIUSDT","b":"49976.8","B":"0.013","a":"49997.9","A":"0.024","T":1618677451171,"E":1618677451174}}
1618677451.2396622: {"stream":"yfiusdt@bookTicker","data":{"e":"bookTicker","u":335340681431,"s":"YFIUSDT","b":"49976.7","B":"0.003","a":"49997.9","A":"0.024","T":1618677451175,"E":1618677451178}}
1618677451.239698: {"stream":"yfiusdt@bookTicker","data":{"e":"bookTicker","u":335340681459,"s":"YFIUSDT","b":"49977.0","B":"0.015","a":"49997.9","A":"0.024","T":1618677451175,"E":1618677451180}}
1618677451.242618: {"stream":"yfiusdt@bookTicker","data":{"e":"bookTicker","u":335340681596,"s":"YFIUSDT","b":"49977.0","B":"0.015","a":"49998.0","A":"0.144","T":1618677451180,"E":1618677451184}}
1618677451.243629: {"stream":"yfiusdt@bookTicker","data":{"e":"bookTicker","u":335340681629,"s":"YFIUSDT","b":"49977.0","B":"0.015","a":"49997.7","A":"0.023","T":1618677451181,"E":1618677451186}}
1618677451.248497: {"stream":"xmrusdt@depth@100ms","data":{"e":"depthUpdate","E":1618677451190,"T":1618677451152,"s":"XMRUSDT","U":335340678822,"u":335340680336,"pu":335340677736,"b":[["351.75","0.000"],["352.13","0.000"],["352.32","2.500"]],"a":[]}}
1618677451.248678: {"stream":"yfiusdt@bookTicker","data":{"e":"bookTicker","u":335340681717,"s":"YFIUSDT","b":"49976.7","B":"0.003","a":"49997.7","A":"0.023","T":1618677451185,"E":1618677451190}}
1618677451.248731: {"stream":"yfiusdt@bookTicker","data":{"e":"bookTicker","u":335340681828,"s":"YFIUSDT","b":"49976.7","B":"0.003","a":"49997.7","A":"0.027","T":1618677451187,"E":1618677451192}}
1618677451.253684: {"stream":"yfiusdt@bookTicker","data":{"e":"bookTicker","u":335340681893,"s":"YFIUSDT","b":"49976.6","B":"0.014","a":"49997.7","A":"0.027","T":1618677451189,"E":1618677451193}}
1618677451.2537842: {"stream":"yfiusdt@bookTicker","data":{"e":"bookTicker","u":335340681900,"s":"YFIUSDT","b":"49977.1","B":"0.003","a":"49997.7","A":"0.027","T":1618677451189,"E":1618677451193}}
1618677451.253834: {"stream":"yfiusdt@bookTicker","data":{"e":"bookTicker","u":335340681912,"s":"YFIUSDT","b":"49977.1","B":"0.003","a":"49997.7","A":"0.053","T":1618677451189,"E":1618677451194}}
1618677451.253867: {"stream":"yfiusdt@bookTicker","data":{"e":"bookTicker","u":335340681986,"s":"YFIUSDT","b":"49977.1","B":"0.003","a":"49997.7","A":"0.030","T":1618677451191,"E":1618677451195}}
1618677451.253896: {"stream":"yfiusdt@bookTicker","data":{"e":"bookTicker","u":335340681989,"s":"YFIUSDT","b":"49977.1","B":"0.003","a":"49997.7","A":"0.004","T":1618677451191,"E":1618677451195}}
1618677451.253922: {"stream":"yfiusdt@bookTicker","data":{"e":"bookTicker","u":335340681990,"s":"YFIUSDT","b":"49977.1","B":"0.003","a":"49997.8","A":"0.133","T":1618677451191,"E":1618677451195}}
1618677451.253949: {"stream":"yfiusdt@bookTicker","data":{"e":"bookTicker","u":335340681992,"s":"YFIUSDT","b":"49977.1","B":"0.003","a":"49997.5","A":"0.031","T":1618677451191,"E":1618677451195}}
1618677451.263666: {"stream":"yfiusdt@bookTicker","data":{"e":"bookTicker","u":335340682393,"s":"YFIUSDT","b":"49977.1","B":"0.003","a":"49997.5","A":"0.056","T":1618677451201,"E":1618677451205}}
1618677451.2642088: {"stream":"yfiusdt@bookTicker","data":{"e":"bookTicker","u":335340682465,"s":"YFIUSDT","b":"49977.1","B":"0.003","a":"49997.5","A":"0.025","T":1618677451203,"E":1618677451207}}
1618677451.264278: {"stream":"yfiusdt@bookTicker","data":{"e":"bookTicker","u":335340682473,"s":"YFIUSDT","b":"49977.1","B":"0.003","a":"49997.8","A":"0.133","T":1618677451204,"E":1618677451207}}
1618677451.264317: {"stream":"yfiusdt@bookTicker","data":{"e":"bookTicker","u":335340682479,"s":"YFIUSDT","b":"49977.1","B":"0.003","a":"49997.3","A":"0.031","T":1618677451204,"E":1618677451207}}
1618677451.2687721: {"stream":"yfiusdt@bookTicker","data":{"e":"bookTicker","u":335340682666,"s":"YFIUSDT","b":"49977.2","B":"0.019","a":"49997.3","A":"0.031","T":1618677451208,"E":1618677451211}}
1618677451.2720609: {"stream":"yfiusdt@bookTicker","data":{"e":"bookTicker","u":335340682743,"s":"YFIUSDT","b":"49977.2","B":"0.019","a":"49996.3","A":"0.055","T":1618677451210,"E":1618677451213}}
1618677451.2784672: {"stream":"yfiusdt@bookTicker","data":{"e":"bookTicker","u":335340683060,"s":"YFIUSDT","b":"49977.1","B":"0.003","a":"49996.3","A":"0.055","T":1618677451219,"E":1618677451221}}
1618677451.281752: {"stream":"yfiusdt@bookTicker","data":{"e":"bookTicker","u":335340683156,"s":"YFIUSDT","b":"49977.1","B":"0.003","a":"49996.2","A":"0.040","T":1618677451221,"E":1618677451224}}
1618677451.281853: {"stream":"yfiusdt@bookTicker","data":{"e":"bookTicker","u":335340683157,"s":"YFIUSDT","b":"49976.6","B":"0.014","a":"49996.2","A":"0.040","T":1618677451221,"E":1618677451224}}
1618677451.421372: {"stream":"yfiusdt@bookTicker","data":{"e":"bookTicker","u":335340683171,"s":"YFIUSDT","b":"49977.3","B":"0.003","a":"49996.2","A":"0.040","T":1618677451222,"E":1618677451226}}
1618677451.423176: {"stream":"yfiusdt@bookTicker","data":{"e":"bookTicker","u":335340683197,"s":"YFIUSDT","b":"49977.3","B":"0.003","a":"49996.2","A":"0.049","T":1618677451222,"E":1618677451226}}
1618677451.423249: {"stream":"ksmusdt@bookTicker","data":{"e":"bookTicker","u":335340683407,"s":"KSMUSDT","b":"459.239","B":"6.4","a":"459.496","A":"1.3","T":1618677451229,"E":1618677451230}}
1618677451.4232771: {"stream":"ksmusdt@depth@100ms","data":{"e":"depthUpdate","E":1618677451234,"T":1618677451229,"s":"KSMUSDT","U":335340679528,"u":335340683407,"pu":335340679270,"b":[["457.135","0.2"],["458.229","0.0"],["458.282","2.2"],["459.078","1.6"],["459.215","0.0"],["459.217","0.2"],["459.239","6.4"]],"a":[["459.535","0.0"],["459.538","1.4"],["459.563","0.0"],["459.564","0.0"],["459.874","0.0"],["459.876","0.9"],["460.436","1.0"]]}}
1618677451.423449: {"stream":"yfiusdt@bookTicker","data":{"e":"bookTicker","u":335340683656,"s":"YFIUSDT","b":"49977.3","B":"0.003","a":"49996.1","A":"0.047","T":1618677451234,"E":1618677451238}}
1618677451.423476: {"stream":"ksmusdt@bookTicker","data":{"e":"bookTicker","u":335340683900,"s":"KSMUSDT","b":"459.270","B":"1.2","a":"459.496","A":"1.3","T":1618677451241,"E":1618677451246}}
1618677451.423496: {"stream":"yfiusdt@bookTicker","data":{"e":"bookTicker","u":335340683921,"s":"YFIUSDT","b":"49977.4","B":"0.019","a":"49996.1","A":"0.047","T":1618677451241,"E":1618677451246}}
1618677451.4235141: {"stream":"yfiusdt@depth@100ms","data":{"e":"depthUpdate","E":1618677451250,"T":1618677451245,"s":"YFIUSDT","U":335340679945,"u":335340684032,"pu":335340679844,"b":[["48987.7","0.001"],["49743.5","0.200"],["49749.4","0.200"],["49754.4","0.200"],["49839.1","0.000"],["49863.8","0.000"],["49928.1","0.043"],["49934.0","0.043"],["49938.6","0.323"],["49939.0","0.036"],["49942.8","0.000"],["49942.9","0.000"],["49948.5","0.215"],["49949.2","0.062"],["49974.1","0.000"],["49976.6","0.014"],["49976.7","0.000"],["49976.8","0.000"],["49977.0","0.000"],["49977.1","0.000"],["49977.2","0.000"],["49977.3","0.003"],["49977.4","0.019"]],"a":[["49996.1","0.047"],["49996.2","0.000"],["49996.3","0.055"],["49997.2","0.145"],["49997.3","0.000"],["49997.5","0.000"],["49997.7","0.000"],["49997.8","0.000"],["49997.9","0.000"],["49998.0","0.000"],["49998.1","0.000"],["49998.2","0.000"],["49998.3","0.000"],["50000.1","0.000"],["50000.8","0.013"],["50000.9","0.000"],["50001.0","0.000"],["50001.6","0.000"],["50002.6","0.000"],["50002.9","0.000"],["50007.0","0.000"],["50043.5","0.000"],["50049.4","0.000"],["50052.2","0.292"],["50053.1","0.000"],["50064.2","0.000"],["50070.0","0.000"],["50081.0","0.006"],["50085.5","0.064"],["50121.5","0.025"],["50129.4","0.000"],["50139.3","0.000"],["50158.1","0.060"],["50168.1","0.015"],["50178.6","0.038"],["50209.2","0.000"],["50268.7","0.010"]]}}
1618677451.4238641: {"stream":"dentusdt@depth@100ms","data":{"e":"depthUpdate","E":1618677451250,"T":1618677451237,"s":"DENTUSDT","U":335340679977,"u":335340683792,"pu":335340679588,"b":[["0.012311","1434"],["0.012316","66125"],["0.012349","0"],["0.012354","215403"]],"a":[["0.012362","29812"],["0.012371","51464"],["0.012380","79175"],["0.012384","65954"],["0.012425","40758"]]}}
1618677451.4239528: {"stream":"yfiusdt@bookTicker","data":{"e":"bookTicker","u":335340684359,"s":"YFIUSDT","b":"49977.3","B":"0.003","a":"49996.1","A":"0.047","T":1618677451253,"E":1618677451257}}
1618677451.423976: {"stream":"yfiusdt@bookTicker","data":{"e":"bookTicker","u":335340684394,"s":"YFIUSDT","b":"49977.6","B":"0.019","a":"49996.1","A":"0.047","T":1618677451254,"E":1618677451257}}
1618677451.423994: {"stream":"yfiusdt@bookTicker","data":{"e":"bookTicker","u":335340684602,"s":"YFIUSDT","b":"49977.6","B":"0.019","a":"49994.2","A":"0.055","T":1618677451259,"E":1618677451263}}
1618677451.424012: {"stream":"yfiusdt@bookTicker","data":{"e":"bookTicker","u":335340685037,"s":"YFIUSDT","b":"49977.5","B":"0.003","a":"49994.2","A":"0.055","T":1618677451269,"E":1618677451272}}
1618677451.4240289: {"stream":"yfiusdt@bookTicker","data":{"e":"bookTicker","u":335340685045,"s":"YFIUSDT","b":"49977.8","B":"0.017","a":"49994.2","A":"0.055","T":1618677451270,"E":1618677451273}}
1618677451.424046: {"stream":"xmrusdt@depth@100ms","data":{"e":"depthUpdate","E":1618677451324,"T":1618677451293,"s":"XMRUSDT","U":335340683149,"u":335340685917,"pu":335340680336,"b":[["349.72","200.044"],["350.35","204.265"],["351.52","17.260"],["351.72","1.335"],["352.05","0.000"],["352.09","24.243"],["352.14","4.883"],["352.15","5.719"],["352.22","2.500"],["352.32","0.000"],["352.35","1.000"]],"a":[["352.85","3.400"],["354.60","200.028"]]}}
1618677451.4241438: {"stream":"ksmusdt@depth@100ms","data":{"e":"depthUpdate","E":1618677451342,"T":1618677451337,"s":"KSMUSDT","U":335340683728,"u":335340687520,"pu":335340683407,"b":[["413.282","0.2"],["449.979","5.5"],["458.229","0.0"],["458.567","0.0"],["458.568","0.0"],["458.786","22.4"],["459.074","0.7"],["459.078","0.0"],["459.216","0.0"],["459.240","0.2"],["459.270","1.2"]],"a":[["459.536","0.0"],["459.538","0.0"],["459.562","1.4"],["459.566","2.3"],["460.436","1.0"]]}}
1618677451.424278: {"stream":"yfiusdt@depth@100ms","data":{"e":"depthUpdate","E":1618677451350,"T":1618677451341,"s":"YFIUSDT","U":335340684107,"u":335340687711,"pu":335340684032,"b":[["49735.8","0.202"],["49739.2","0.200"],["49739.9","0.319"],["49834.6","0.000"],["49844.2","0.007"],["49885.1","0.000"],["49911.3","0.020"],["49927.9","0.008"],["49931.3","0.008"],["49932.0","0.008"],["49959.8","0.000"],["49974.0","0.000"],["49974.1","0.006"],["49977.3","0.000"],["49977.4","0.000"],["49977.5","0.003"],["49977.6","0.000"],["49977.8","0.017"]],"a":[["49994.2","0.055"],["49996.0","0.003"],["49996.1","0.013"],["49997.1","0.000"],["49997.2","0.142"],["49997.7","0.000"],["49998.4","0.000"],["49998.7","0.000"],["50000.8","0.000"],["50003.5","0.013"],["50031.1","0.001"],["50040.4","0.022"],["50042.0","0.003"],["50042.3","0.000"],["50042.9","0.003"],["50046.3","0.013"],["50048.2","0.000"],["50054.2","0.011"],["50055.9","0.006"],["50060.1","0.000"],["50062.7","0.000"],["50069.9","0.000"],["50074.8","0.005"],["50077.1","0.000"],["50083.2","0.094"],["50094.9","0.000"],["50121.5","0.000"],["50131.2","0.000"]]}}
1618677451.424545: {"stream":"dentusdt@depth@100ms","data":{"e":"depthUpdate","E":1618677451351,"T":1618677451344,"s":"DENTUSDT","U":335340684175,"u":335340687803,"pu":335340683792,"b":[["0.012057","12315"],["0.012327","768631"],["0.012333","0"],["0.012349","1259"],["0.012353","8941"],["0.012354","206360"]],"a":[["0.012382","957523"],["0.012383","26410"]]}}
1618677451.424618: {"stream":"yfiusdt@bookTicker","data":{"e":"bookTicker","u":335340688164,"s":"YFIUSDT","b":"49977.5","B":"0.003","a":"49994.2","A":"0.055","T":1618677451354,"E":1618677451358}}
1618677451.44266: {"stream":"ksmusdt@bookTicker","data":{"e":"bookTicker","u":335340689341,"s":"KSMUSDT","b":"459.240","B":"0.2","a":"459.496","A":"1.3","T":1618677451380,"E":1618677451383}}
1618677451.44276: {"stream":"ksmusdt@bookTicker","data":{"e":"bookTicker","u":335340689371,"s":"KSMUSDT","b":"459.242","B":"1.2","a":"459.496","A":"1.3","T":1618677451381,"E":1618677451385}}
1618677451.458282: {"stream":"yfiusdt@bookTicker","data":{"e":"bookTicker","u":335340690069,"s":"YFIUSDT","b":"49976.6","B":"0.014","a":"49994.2","A":"0.055","T":1618677451396,"E":1618677451400}}
1618677451.458383: {"stream":"yfiusdt@bookTicker","data":{"e":"bookTicker","u":335340690090,"s":"YFIUSDT","b":"49976.6","B":"0.014","a":"49994.1","A":"0.003","T":1618677451397,"E":1618677451400}}
1618677451.489697: {"stream":"xmrusdt@depth@100ms","data":{"e":"depthUpdate","E":1618677451432,"T":1618677451405,"s":"XMRUSDT","U":335340687185,"u":335340690387,"pu":335340685917,"b":[["352.20","0.000"],["352.21","0.000"],["352.22","0.000"],["352.24","2.500"],["352.36","0.000"]],"a":[["352.66","1.400"],["352.67","0.401"],["352.71","2.000"]]}}
1618677451.507051: {"stream":"ksmusdt@depth@100ms","data":{"e":"depthUpdate","E":1618677451449,"T":1618677451430,"s":"KSMUSDT","U":335340687826,"u":335340691358,"pu":335340687520,"b":[["453.435","0.0"],["455.067","0.0"],["458.084","1.6"],["458.229","0.0"],["459.014","0.0"],["459.186","0.0"],["459.217","0.0"],["459.242","1.2"],["459.270","0.0"]],"a":[["459.562","0.0"],["459.656","1.4"],["460.436","1.0"],["461.528","0.0"],["462.464","0.0"]]}}
1618677451.5134149: {"stream":"dentusdt@kline_1m","data":{"e":"kline","E":1618677451455,"s":"DENTUSDT","k":{"t":1618677420000,"T":1618677479999,"s":"DENTUSDT","i":"1m","f":15787262,"L":15787367,"o":"0.012366","c":"0.012355","h":"0.012366","l":"0.012339","v":"1534261","n":106,"x":false,"q":"18951.401429","V":"943351","Q":"11654.775994","B":"0"}}}
1618677451.5140312: {"stream":"dentusdt@aggTrade","data":{"e":"aggTrade","E":1618677451456,"a":8476390,"s":"DENTUSDT","p":"0.012355","q":"55603","f":15787367,"l":15787370,"T":1618677451451,"m":true}}
1618677451.514079: {"stream":"dentusdt@aggTrade","data":{"e":"aggTrade","E":1618677451456,"a":8476391,"s":"DENTUSDT","p":"0.012354","q":"206360","f":15787371,"l":15787371,"T":1618677451451,"m":true}}
1618677451.51455: {"stream":"dentusdt@aggTrade","data":{"e":"aggTrade","E":1618677451456,"a":8476392,"s":"DENTUSDT","p":"0.012353","q":"8941","f":15787372,"l":15787372,"T":1618677451451,"m":true}}
1618677451.5146: {"stream":"dentusdt@aggTrade","data":{"e":"aggTrade","E":1618677451456,"a":8476393,"s":"DENTUSDT","p":"0.012349","q":"1259","f":15787373,"l":15787373,"T":1618677451451,"m":true}}
1618677451.5146282: {"stream":"dentusdt@aggTrade","data":{"e":"aggTrade","E":1618677451456,"a":8476394,"s":"DENTUSDT","p":"0.012347","q":"100000","f":15787374,"l":15787375,"T":1618677451451,"m":true}}
1618677451.5146508: {"stream":"dentusdt@bookTicker","data":{"e":"bookTicker","u":335340692132,"s":"DENTUSDT","b":"0.012344","B":"4172","a":"0.012359","A":"8567","T":1618677451451,"E":1618677451456}}
1618677451.5168169: {"stream":"yfiusdt@depth@100ms","data":{"e":"depthUpdate","E":1618677451458,"T":1618677451452,"s":"YFIUSDT","U":335340688161,"u":335340692203,"pu":335340687711,"b":[["49898.8","0.021"],["49905.5","0.100"],["49917.0","0.110"],["49921.2","0.110"],["49929.6","0.000"],["49933.8","0.000"],["49950.1","0.054"],["49962.3","0.003"],["49970.1","0.000"],["49970.2","0.000"],["49971.6","0.000"],["49971.7","0.000"],["49974.1","0.000"],["49977.5","0.000"],["49977.8","0.000"]],"a":[["49994.1","0.003"],["49996.0","0.000"],["49998.8","0.014"],["50003.5","0.000"],["50006.7","0.001"],["50031.1","0.000"],["50038.7","0.013"],["50042.0","0.000"],["50042.9","0.000"],["50043.6","0.000"],["50049.5","0.016"],["50050.4","0.016"],["50065.9","0.006"],["50070.0","0.073"],["50122.3","0.100"],["50147.3","0.000"],["50147.6","0.022"],["50261.9","0.010"],["50268.7","0.000"],["50276.5","0.000"]]}}
1618677451.519868: {"stream":"xmrusdt@kline_1m","data":{"e":"kline","E":1618677451461,"s":"XMRUSDT","k":{"t":1618677420000,"T":1618677479999,"s":"XMRUSDT","i":"1m","f":34692938,"L":34692959,"o":"352.86","c":"352.60","h":"352.93","l":"352.53","v":"19.270","n":22,"x":false,"q":"6796.91460","V":"1.638","Q":"577.96953","B":"0"}}}
1618677451.519957: {"stream":"xmrusdt@aggTrade","data":{"e":"aggTrade","E":1618677451462,"a":23619019,"s":"XMRUSDT","p":"352.60","q":"0.311","f":34692959,"l":34692961,"T":1618677451458,"m":true}}
1618677451.519992: {"stream":"xmrusdt@bookTicker","data":{"e":"bookTicker","u":335340692502,"s":"XMRUSDT","b":"352.58","B":"2.011","a":"352.61","A":"16.951","T":1618677451458,"E":1618677451462}}
1618677451.525219: {"stream":"dentusdt@depth@100ms","data":{"e":"depthUpdate","E":1618677451466,"T":1618677451460,"s":"DENTUSDT","U":335340688523,"u":335340692650,"pu":335340687803,"b":[["0.012288","52100"],["0.012335","24963"],["0.012344","4172"],["0.012347","0"],["0.012349","0"],["0.012353","0"],["0.012354","0"],["0.012355","0"]],"a":[["0.012379","17239"],["0.012383","29647"],["0.012414","218028"],["0.012420","615331"],["0.012425","167543"]]}}
1618677451.5254111: {"stream":"dentusdt@bookTicker","data":{"e":"bookTicker","u":335340692700,"s":"DENTUSDT","b":"0.012353","B":"9535","a":"0.012359","A":"8567","T":1618677451461,"E":1618677451466}}
1618677451.528449: {"stream":"dentusdt@bookTicker","data":{"e":"bookTicker","u":335340692835,"s":"DENTUSDT","b":"0.012344","B":"4172","a":"0.012359","A":"8567","T":1618677451465,"E":1618677451469}}
1618677451.528525: {"stream":"dentusdt@bookTicker","data":{"e":"bookTicker","u":335340692896,"s":"DENTUSDT","b":"0.012346","B":"81000","a":"0.012359","A":"8567","T":1618677451467,"E":1618677451470}}
1618677451.536736: {"stream":"xmrusdt@bookTicker","data":{"e":"bookTicker","u":335340692959,"s":"XMRUSDT","b":"352.58","B":"2.011","a":"352.60","A":"0.290","T":1618677451468,"E":1618677451476}}
1618677451.5368378: {"stream":"xmrusdt@bookTicker","data":{"e":"bookTicker","u":335340692978,"s":"XMRUSDT","b":"352.53","B":"0.401","a":"352.60","A":"0.290","T":1618677451469,"E":1618677451476}}
1618677451.536882: {"stream":"dentusdt@bookTicker","data":{"e":"bookTicker","u":335340693171,"s":"DENTUSDT","b":"0.012354","B":"2463","a":"0.012359","A":"8567","T":1618677451473,"E":1618677451476}}
1618677451.536917: {"stream":"dentusdt@bookTicker","data":{"e":"bookTicker","u":335340693177,"s":"DENTUSDT","b":"0.012354","B":"1109","a":"0.012359","A":"8567","T":1618677451473,"E":1618677451476}}
1618677451.5369449: {"stream":"dentusdt@aggTrade","data":{"e":"aggTrade","E":1618677451476,"a":8476395,"s":"DENTUSDT","p":"0.012344","q":"19967","f":15787376,"l":15787376,"T":1618677451451,"m":true}}
1618677451.5383139: {"stream":"xmrusdt@bookTicker","data":{"e":"bookTicker","u":335340693256,"s":"XMRUSDT","b":"352.53","B":"0.401","a":"352.60","A":"3.990","T":1618677451476,"E":1618677451480}}
1618677451.5384178: {"stream":"dentusdt@bookTicker","data":{"e":"bookTicker","u":335340693291,"s":"DENTUSDT","b":"0.012346","B":"81000","a":"0.012359","A":"8567","T":1618677451477,"E":1618677451480}}
1618677451.546805: {"stream":"xmrusdt@bookTicker","data":{"e":"bookTicker","u":335340693678,"s":"XMRUSDT","b":"352.42","B":"2.945","a":"352.60","A":"3.990","T":1618677451486,"E":1618677451489}}
1618677451.565991: {"stream":"yfiusdt@bookTicker","data":{"e":"bookTicker","u":335340694343,"s":"YFIUSDT","b":"49976.6","B":"0.014","a":"49992.8","A":"0.009","T":1618677451503,"E":1618677451506}}
1618677451.579499: {"stream":"xmrusdt@aggTrade","data":{"e":"aggTrade","E":1618677451516,"a":23619020,"s":"XMRUSDT","p":"352.58","q":"3.700","f":34692962,"l":34692963,"T":1618677451458,"m":true}}
1618677451.5796008: {"stream":"xmrusdt@bookTicker","data":{"e":"bookTicker","u":335340694656,"s":"XMRUSDT","b":"352.42","B":"2.252","a":"352.60","A":"3.990","T":1618677451512,"E":1618677451516}}
1618677451.579649: {"stream":"yfiusdt@bookTicker","data":{"e":"bookTicker","u":335340694747,"s":"YFIUSDT","b":"49976.6","B":"0.014","a":"49992.7","A":"0.003","T":1618677451515,"E":1618677451518}}
1618677451.580179: {"stream":"xmrusdt@bookTicker","data":{"e":"bookTicker","u":335340694919,"s":"XMRUSDT","b":"352.40","B":"0.567","a":"352.60","A":"3.990","T":1618677451519,"E":1618677451523}}
1618677451.580231: {"stream":"xmrusdt@bookTicker","data":{"e":"bookTicker","u":335340694942,"s":"XMRUSDT","b":"352.40","B":"0.567","a":"352.59","A":"0.529","T":1618677451520,"E":1618677451523}}
1618677451.584069: {"stream":"xmrusdt@bookTicker","data":{"e":"bookTicker","u":335340695010,"s":"XMRUSDT","b":"352.40","B":"0.567","a":"352.59","A":"5.230","T":1618677451521,"E":1618677451526}}
1618677451.584169: {"stream":"xmrusdt@bookTicker","data":{"e":"bookTicker","u":335340695031,"s":"XMRUSDT","b":"352.43","B":"2.922","a":"352.59","A":"5.230","T":1618677451522,"E":1618677451526}}
1618677451.59166: {"stream":"xmrusdt@bookTicker","data":{"e":"bookTicker","u":335340695321,"s":"XMRUSDT","b":"352.40","B":"0.567","a":"352.59","A":"5.230","T":1618677451529,"E":1618677451534}}
1618677451.702657: {"stream":"xmrusdt@depth@100ms","data":{"e":"depthUpdate","E":1618677451547,"T":1618677451535,"s":"XMRUSDT","U":335340691760,"u":335340695492,"pu":335340690387,"b":[["348.10","202.847"],["348.73","202.794"],["349.72","0.044"],["350.35","4.265"],["351.08","100.000"],["351.34","104.777"],["351.54","3.607"],["351.59","0.027"],["351.72","0.335"],["351.74","0.381"],["351.75","56.510"],["351.81","8.527"],["351.87","2.966"],["352.09","1.035"],["352.17","4.031"],["352.19","26.149"],["352.23","1.788"],["352.24","2.500"],["352.26","0.000"],["352.27","0.000"],["352.30","0.000"],["352.35","6.019"],["352.36","1.194"],["352.37","4.254"],["352.38","2.814"],["352.39","1.460"],["352.40","0.567"],["352.41","0.000"],["352.42","0.000"],["352.43","0.000"],["352.52","0.000"],["352.53","0.000"],["352.58","0.000"],["352.60","0.000"]],"a":[["350.82","0.000"],["352.59","5.230"],["352.60","5.390"],["352.61","16.951"],["352.63","0.240"],["352.66","0.000"],["352.67","0.000"],["352.73","0.947"],["352.91","16.833"],["353.09","7.400"],["353.12","15.462"],["353.13","0.000"],["353.14","0.981"],["353.35","200.000"],["353.37","56.724"],["353.46","0.000"],["353.49","13.328"],["353.50","0.612"],["354.60","0.028"],["362.14","201.494"]]}}
1618677451.703167: {"stream":"ksmusdt@depth@100ms","data":{"e":"depthUpdate","E":1618677451551,"T":1618677451538,"s":"KSMUSDT","U":335340691918,"u":335340695562,"pu":335340691358,"b":[["458.229","0.0"],["458.741","0.0"],["458.843","0.2"],["458.955","1.6"],["459.240","0.0"]],"a":[["459.529","2.4"],["459.534","0.0"],["459.565","1.4"],["459.566","0.0"],["459.656","0.0"],["460.224","0.0"],["460.436","1.0"],["460.523","1.9"]]}}
1618677451.7032971: {"stream":"xmrusdt@bookTicker","data":{"e":"bookTicker","u":335340695971,"s":"XMRUSDT","b":"352.40","B":"0.567","a":"352.57","A":"0.300","T":1618677451551,"E":1618677451556}}
1618677451.703327: {"stream":"xmrusdt@bookTicker","data":{"e":"bookTicker","u":335340696097,"s":"XMRUSDT","b":"352.40","B":"3.461","a":"352.57","A":"0.300","T":1618677451555,"E":1618677451558}}
1618677451.70335: {"stream":"yfiusdt@depth@100ms","data":{"e":"depthUpdate","E":1618677451560,"T":1618677451550,"s":"YFIUSDT","U":335340692447,"u":335340695913,"pu":335340692203,"b":[["49928.1","0.000"],["49932.0","0.046"],["49934.0","0.000"],["49937.9","0.038"],["49938.6","0.000"],["49939.1","0.323"],["49974.6","0.000"],["49975.3","0.000"]],"a":[["49992.7","0.003"],["49992.8","0.009"],["49994.1","0.000"],["50032.9","0.013"]]}}
1618677451.703459: {"stream":"dentusdt@depth@100ms","data":{"e":"depthUpdate","E":1618677451566,"T":1618677451547,"s":"DENTUSDT","U":335340692700,"u":335340695821,"pu":335340692650,"b":[["0.012272","1111176"],["0.012282","13761"],["0.012292","480332"],["0.012320","111938"],["0.012326","49464"],["0.012327","873757"],["0.012328","84558"],["0.012329","29449"],["0.012331","11427"],["0.012334","251416"],["0.012337","0"],["0.012340","4172"],["0.012342","297508"],["0.012343","97138"],["0.012344","0"],["0.012346","81000"],["0.012353","0"],["0.012354","0"]],"a":[["0.012361","141740"],["0.012362","55603"],["0.012364","174170"],["0.012365","133881"],["0.012366","0"],["0.012367","274966"],["0.012369","24158"],["0.012371","134887"],["0.012373","11193"],["0.012376","28755"],["0.012380","38712"],["0.012381","86002"],["0.012383","350139"],["0.012435","5278"],["0.012447","987293"]]}}
1618677451.703657: {"stream":"xmrusdt@aggTrade","data":{"e":"aggTrade","E":1618677451573,"a":23619021,"s":"XMRUSDT","p":"352.42","q":"0.693","f":34692964,"l":34692964,"T":1618677451512,"m":true}}
1618677451.703688: {"stream":"xmrusdt@bookTicker","data":{"e":"bookTicker","u":335340696650,"s":"XMRUSDT","b":"352.40","B":"3.407","a":"352.57","A":"0.300","T":1618677451568,"E":1618677451573}}
1618677451.7037098: {"stream":"xmrusdt@bookTicker","data":{"e":"bookTicker","u":335340696762,"s":"XMRUSDT","b":"352.48","B":"0.021","a":"352.57","A":"0.300","T":1618677451572,"E":1618677451578}}
1618677451.7037282: {"stream":"xmrusdt@bookTicker","data":{"e":"bookTicker","u":335340697320,"s":"XMRUSDT","b":"352.48","B":"0.021","a":"352.57","A":"0.829","T":1618677451590,"E":1618677451595}}
1618677451.7037451: {"stream":"xmrusdt@aggTrade","data":{"e":"aggTrade","E":1618677451623,"a":23619022,"s":"XMRUSDT","p":"352.40","q":"0.054","f":34692965,"l":34692965,"T":1618677451568,"m":true}}
1618677451.703765: {"stream":"xmrusdt@bookTicker","data":{"e":"bookTicker","u":335340698199,"s":"XMRUSDT","b":"352.40","B":"3.407","a":"352.57","A":"0.829","T":1618677451618,"E":1618677451623}}
1618677451.7037818: {"stream":"dentusdt@bookTicker","data":{"e":"bookTicker","u":335340698324,"s":"DENTUSDT","b":"0.012346","B":"81000","a":"0.012359","A":"60031","T":1618677451623,"E":1618677451625}}
1618677451.7038: {"stream":"dentusdt@aggTrade","data":{"e":"aggTrade","E":1618677451627,"a":8476396,"s":"DENTUSDT","p":"0.012354","q":"1354","f":15787377,"l":15787377,"T":1618677451473,"m":true}}
1618677451.703818: {"stream":"xmrusdt@bookTicker","data":{"e":"bookTicker","u":335340698443,"s":"XMRUSDT","b":"352.40","B":"3.407","a":"352.49","A":"1.000","T":1618677451625,"E":1618677451628}}
1618677451.709976: {"stream":"xmrusdt@depth@100ms","data":{"e":"depthUpdate","E":1618677451650,"T":1618677451646,"s":"XMRUSDT","U":335340695732,"u":335340699001,"pu":335340695492,"b":[["348.10","2.847"],["348.64","28.483"],["348.73","2.794"],["348.90","148.915"],["348.92","0.000"],["349.58","1.630"],["349.69","207.088"],["350.11","0.233"],["350.32","248.784"],["350.92","3.928"],["351.25","1.448"],["351.36","8.423"],["351.40","15.626"],["351.41","0.000"],["351.51","1.813"],["351.53","3.476"],["351.54","0.607"],["351.55","0.000"],["351.57","0.000"],["351.61","54.250"],["351.63","200.000"],["351.68","16.376"],["351.80","0.864"],["351.81","11.027"],["351.88","0.000"],["352.04","8.285"],["352.05","2.553"],["352.14","0.000"],["352.17","1.031"],["352.18","14.000"],["352.19","2.941"],["352.20","0.000"],["352.24","0.000"],["352.25","1.205"],["352.28","0.000"],["352.35","0.000"],["352.36","1.400"],["352.37","0.000"],["352.38","0.000"],["352.39","0.060"],["352.40","3.407"],["352.48","0.000"]],"a":[["350.66","0.000"],["352.49","1.000"],["352.57","0.829"],["352.58","5.100"],["352.59","4.701"],["352.60","3.990"],["352.63","0.000"],["352.68","30.368"],["352.69","12.164"],["352.71","0.000"],["352.73","0.000"],["352.87","0.000"],["352.89","3.965"],["352.90","0.000"],["352.97","0.000"],["352.98","0.000"],["353.20","0.000"],["353.21","0.000"],["353.26","0.000"],["353.27","0.056"],["353.36","14.796"],["354.60","200.028"],["355.15","22.452"],["355.26","129.242"],["362.14","1.494"]]}}
1618677451.724789: {"stream":"dentusdt@depth@100ms","data":{"e":"depthUpdate","E":1618677451667,"T":1618677451635,"s":"DENTUSDT","U":335340696466,"u":335340698688,"pu":335340695821,"b":[["0.012310","89144"]],"a":[["0.012359","60031"],["0.012360","61382"],["0.012361","0"],["0.012362","34699"],["0.012398","213963"],["0.012454","80298"]]}}
1618677451.7250109: {"stream":"dentusdt@bookTicker","data":{"e":"bookTicker","u":335340699554,"s":"DENTUSDT","b":"0.012346","B":"81000","a":"0.012359","A":"109829","T":1618677451663,"E":1618677451667}}
1618677451.7348769: {"stream":"xmrusdt@bookTicker","data":{"e":"bookTicker","u":335340699739,"s":"XMRUSDT","b":"352.41","B":"3.700","a":"352.49","A":"1.000","T":1618677451669,"E":1618677451675}}
1618677451.734951: {"stream":"ksmusdt@depth@100ms","data":{"e":"depthUpdate","E":1618677451676,"T":1618677451661,"s":"KSMUSDT","U":335340696711,"u":335340699456,"pu":335340695562,"b":[["458.229","1.1"],["458.290","0.0"],["458.609","2.1"],["458.843","0.0"],["458.998","0.2"]],"a":[["459.565","0.0"],["459.656","1.4"],["460.230","0.0"],["460.490","2.1"],["461.850","4.5"],["463.377","1.1"]]}}
1618677451.74068: {"stream":"yfiusdt@depth@100ms","data":{"e":"depthUpdate","E":1618677451679,"T":1618677451659,"s":"YFIUSDT","U":335340696841,"u":335340699410,"pu":335340695913,"b":[["49802.0","0.020"],["49854.0","0.019"],["49890.4","0.018"],["49906.7","0.017"],["49945.5","0.255"]],"a":[["50124.4","0.022"],["50165.3","0.013"],["50205.7","0.000"]]}}
1618677451.7453032: {"stream":"xmrusdt@bookTicker","data":{"e":"bookTicker","u":335340700154,"s":"XMRUSDT","b":"352.42","B":"2.886","a":"352.49","A":"1.000","T":1618677451683,"E":1618677451685}}
1618677451.74536: {"stream":"dentusdt@bookTicker","data":{"e":"bookTicker","u":335340700174,"s":"DENTUSDT","b":"0.012346","B":"72910","a":"0.012359","A":"109829","T":1618677451683,"E":1618677451687}}
1618677451.761877: {"stream":"xmrusdt@bookTicker","data":{"e":"bookTicker","u":335340700687,"s":"XMRUSDT","b":"352.43","B":"3.700","a":"352.49","A":"1.000","T":1618677451699,"E":1618677451702}}
1618677451.761982: {"stream":"yfiusdt@bookTicker","data":{"e":"bookTicker","u":335340700662,"s":"YFIUSDT","b":"49983.2","B":"0.015","a":"49992.7","A":"0.003","T":1618677451698,"E":1618677451702}}
1618677451.772535: {"stream":"xmrusdt@bookTicker","data":{"e":"bookTicker","u":335340700930,"s":"XMRUSDT","b":"352.44","B":"3.059","a":"352.49","A":"1.000","T":1618677451709,"E":1618677451713}}
1618677451.792898: {"stream":"xmrusdt@bookTicker","data":{"e":"bookTicker","u":335340701520,"s":"XMRUSDT","b":"352.44","B":"6.759","a":"352.49","A":"1.000","T":1618677451731,"E":1618677451734}}
1618677451.8051388: {"stream":"yfiusdt@bookTicker","data":{"e":"bookTicker","u":335340701831,"s":"YFIUSDT","b":"49976.6","B":"0.014","a":"49992.7","A":"0.003","T":1618677451742,"E":1618677451747}}
1618677451.80864: {"stream":"xmrusdt@depth@100ms","data":{"e":"depthUpdate","E":1618677451750,"T":1618677451741,"s":"XMRUSDT","U":335340699022,"u":335340701798,"pu":335340699001,"b":[["349.64","61.258"],["350.58","5.658"],["351.51","1.813"],["351.55","1.000"],["351.76","0.000"],["351.81","8.527"],["351.84","18.529"],["351.88","0.000"],["351.92","0.446"],["351.93","15.849"],["352.02","3.916"],["352.03","16.403"],["352.14","0.000"],["352.18","1.000"],["352.19","0.000"],["352.25","0.000"],["352.26","4.255"],["352.31","0.000"],["352.36","0.000"],["352.37","0.000"],["352.39","0.000"],["352.40","0.513"],["352.41","0.000"],["352.42","0.000"],["352.43","0.000"],["352.44","6.759"]],"a":[["352.57","0.300"],["352.58","3.700"],["352.61","0.000"],["352.84","2.500"],["352.86","0.000"],["352.90","7.918"],["352.95","0.000"],["354.60","0.028"],["356.08","0.000"],["356.33","201.461"]]}}
1618677451.8160992: {"stream":"yfiusdt@bookTicker","data":{"e":"bookTicker","u":335340702078,"s":"YFIUSDT","b":"49976.6","B":"0.014","a":"49991.4","A":"0.009","T":1618677451752,"E":1618677451756}}
1618677451.826448: {"stream":"dentusdt@depth@100ms","data":{"e":"depthUpdate","E":1618677451767,"T":1618677451755,"s":"DENTUSDT","U":335340699554,"u":335340702221,"pu":335340698688,"b":[["0.011816","0"],["0.012315","127736"],["0.012326","79541"],["0.012328","30588"],["0.012340","4172"],["0.012343","151108"],["0.012344","919"],["0.012346","72910"]],"a":[["0.012359","109829"],["0.012420","784502"]]}}
1618677451.832195: {"stream":"xmrusdt@aggTrade","data":{"e":"aggTrade","E":1618677451774,"a":23619023,"s":"XMRUSDT","p":"352.48","q":"0.021","f":34692966,"l":34692966,"T":1618677451618,"m":true}}
1618677451.839046: {"stream":"yfiusdt@bookTicker","data":{"e":"bookTicker","u":335340702895,"s":"YFIUSDT","b":"49976.6","B":"0.014","a":"49991.3","A":"0.003","T":1618677451777,"E":1618677451779}}
1618677451.846933: {"stream":"dentusdt@bookTicker","data":{"e":"bookTicker","u":335340703111,"s":"DENTUSDT","b":"0.012346","B":"72910","a":"0.012358","A":"16028","T":1618677451784,"E":1618677451787}}
1618677451.854549: {"stream":"dentusdt@bookTicker","data":{"e":"bookTicker","u":335340703496,"s":"DENTUSDT","b":"0.012346","B":"72910","a":"0.012357","A":"9228","T":1618677451793,"E":1618677451796}}
1618677451.8627589: {"stream":"ksmusdt@depth@100ms","data":{"e":"depthUpdate","E":1618677451802,"T":1618677451782,"s":"KSMUSDT","U":335340700683,"u":335340703066,"pu":335340699456,"b":[["458.229","1.1"],["458.497","2.2"]],"a":[["459.529","0.0"],["459.562","2.4"],["459.959","0.0"],["459.960","0.0"],["460.144","1.0"],["460.436","0.0"],["460.437","0.0"],["462.376","0.0"],["464.377","0.0"]]}}
1618677451.863046: {"stream":"yfiusdt@depth@100ms","data":{"e":"depthUpdate","E":1618677451802,"T":1618677451792,"s":"YFIUSDT","U":335340700662,"u":335340703464,"pu":335340699410,"b":[["49839.6","0.000"],["49850.0","0.174"],["49932.0","0.008"],["49937.9","0.000"],["49938.6","0.003"],["49939.0","0.000"],["49944.5","0.003"],["49945.5","0.087"],["49948.5","0.000"],["49948.6","0.000"],["49949.5","0.003"],["49950.2","0.024"],["49958.7","0.000"],["49960.1","0.015"],["49983.2","0.000"]],"a":[["49991.3","0.003"],["49991.4","0.009"],["49992.7","0.000"],["49992.8","0.000"],["50042.3","0.009"],["50052.2","0.008"],["50065.8","0.000"],["50087.1","0.073"],["50224.9","0.006"]]}}
1618677451.887732: {"stream":"dentusdt@bookTicker","data":{"e":"bookTicker","u":335340704474,"s":"DENTUSDT","b":"0.012346","B":"72910","a":"0.012357","A":"59031","T":1618677451826,"E":1618677451831}}
1618677451.895772: {"stream":"dentusdt@aggTrade","data":{"e":"aggTrade","E":1618677451838,"a":8476397,"s":"DENTUSDT","p":"0.012346","q":"8090","f":15787378,"l":15787378,"T":1618677451683,"m":true}}
1618677451.910757: {"stream":"xmrusdt@depth@100ms","data":{"e":"depthUpdate","E":1618677451854,"T":1618677451849,"s":"XMRUSDT","U":335340701984,"u":335340705085,"pu":335340701798,"b":[["351.51","0.000"],["351.55","0.000"],["351.64","8.159"],["352.03","13.903"],["352.10","19.244"],["352.18","0.000"],["352.24","0.000"],["352.29","0.023"],["352.30","2.500"],["352.31","1.400"]],"a":[["352.85","0.000"],["353.08","14.952"],["353.38","2.281"],["354.55","200.000"],["355.15","21.889"],["356.33","1.461"]]}}
1618677451.932333: {"stream":"dentusdt@depth@100ms","data":{"e":"depthUpdate","E":1618677451874,"T":1618677451867,"s":"DENTUSDT","U":335340702682,"u":335340705647,"pu":335340702221,"b":[["0.012227","111853"],["0.012326","101256"],["0.012327","469128"],["0.012331","36708"]],"a":[["0.012357","59031"],["0.012358","16028"],["0.012359","11189"],["0.012360","4876"],["0.012361","91945"],["0.012362","23510"],["0.012383","647055"]]}}
1618677451.9747279: {"stream":"yfiusdt@depth@100ms","data":{"e":"depthUpdate","E":1618677451917,"T":1618677451909,"s":"YFIUSDT","U":335340704105,"u":335340706800,"pu":335340703464,"b":[["49844.1","0.000"],["49866.6","0.020"],["49891.1","0.006"],["49906.7","0.000"],["49939.1","0.000"],["49944.6","0.000"],["49949.2","0.000"]],"a":[["50086.5","0.006"],["50090.0","0.017"],["50108.1","0.012"],["50139.6","0.000"],["50148.5","0.015"],["50214.9","0.000"]]}}
1618677451.975019: {"stream":"ksmusdt@depth@100ms","data":{"e":"depthUpdate","E":1618677451918,"T":1618677451911,"s":"KSMUSDT","U":335340704120,"u":335340706820,"pu":335340703066,"b":[["458.428","1.6"]],"a":[["459.561","1.4"],["459.656","0.0"],["459.742","0.9"],["460.144","0.0"],["460.384","1.6"],["460.494","8.0"],["460.513","1.0"],["460.523","0.0"],["460.550","8.0"]]}}
1618677451.985644: {"stream":"xmrusdt@bookTicker","data":{"e":"bookTicker","u":335340707086,"s":"XMRUSDT","b":"352.45","B":"0.853","a":"352.49","A":"1.000","T":1618677451922,"E":1618677451926}}
1618677451.985745: {"stream":"yfiusdt@bookTicker","data":{"e":"bookTicker","u":335340707113,"s":"YFIUSDT","b":"49976.6","B":"0.014","a":"49991.2","A":"0.124","T":1618677451922,"E":1618677451926}}
1618677451.993901: {"stream":"yfiusdt@bookTicker","data":{"e":"bookTicker","u":335340707379,"s":"YFIUSDT","b":"49976.6","B":"0.014","a":"49989.9","A":"0.009","T":1618677451932,"E":1618677451937}}
1618677451.996178: {"stream":"xmrusdt@bookTicker","data":{"e":"bookTicker","u":335340707400,"s":"XMRUSDT","b":"352.46","B":"2.932","a":"352.49","A":"1.000","T":1618677451934,"E":1618677451939}}
1618677452.002694: {"stream":"dentusdt@bookTicker","data":{"e":"bookTicker","u":335340707610,"s":"DENTUSDT","b":"0.012346","B":"72910","a":"0.012357","A":"9228","T":1618677451942,"E":1618677451946}}
1618677452.011559: {"stream":"xmrusdt@depth@100ms","data":{"e":"depthUpdate","E":1618677451955,"T":1618677451950,"s":"XMRUSDT","U":335340705123,"u":335340707797,"pu":335340705085,"b":[["344.65","0.000"],["349.64","4.056"],["351.48","2.000"],["352.04","10.785"],["352.11","6.951"],["352.19","0.000"],["352.26","0.000"],["352.28","6.019"],["352.30","0.000"],["352.31","0.000"],["352.44","3.700"],["352.45","0.853"],["352.46","2.932"]],"a":[["356.07","1.683"]]}}
1618677452.011838: {"stream":"dentusdt@bookTicker","data":{"e":"bookTicker","u":335340707827,"s":"DENTUSDT","b":"0.012346","B":"72910","a":"0.012359","A":"11189","T":1618677451951,"E":1618677451955}}
1618677452.020767: {"stream":"xmrusdt@bookTicker","data":{"e":"bookTicker","u":335340707943,"s":"XMRUSDT","b":"352.46","B":"6.632","a":"352.49","A":"1.000","T":1618677451957,"E":1618677451961}}
1618677452.022321: {"stream":"dentusdt@bookTicker","data":{"e":"bookTicker","u":335340708033,"s":"DENTUSDT","b":"0.012346","B":"72910","a":"0.012359","A":"20396","T":1618677451960,"E":1618677451964}}
1618677452.0278559: {"stream":"yfiusdt@bookTicker","data":{"e":"bookTicker","u":335340708132,"s":"YFIUSDT","b":"49976.6","B":"0.014","a":"49989.8","A":"0.003","T":1618677451964,"E":1618677451968}}
1618677452.0307891: {"stream":"yfiusdt@bookTicker","data":{"e":"bookTicker","u":335340708231,"s":"YFIUSDT","b":"49976.6","B":"0.014","a":"49987.5","A":"0.055","T":1618677451967,"E":1618677451972}}
1618677452.032531: {"stream":"dentusdt@depth@100ms","data":{"e":"depthUpdate","E":1618677451974,"T":1618677451968,"s":"DENTUSDT","U":335340705752,"u":335340708238,"pu":335340705647,"b":[["0.012312","149762"],["0.012321","431829"]],"a":[["0.012357","0"],["0.012358","0"],["0.012359","20396"],["0.012360","44414"],["0.012361","0"],["0.012362","5840"],["0.012365","57938"],["0.012367","217028"]]}}
1618677452.041306: {"stream":"yfiusdt@bookTicker","data":{"e":"bookTicker","u":335340708516,"s":"YFIUSDT","b":"49976.6","B":"0.014","a":"49986.2","A":"0.009","T":1618677451979,"E":1618677451983}}
1618677452.047046: {"stream":"dentusdt@bookTicker","data":{"e":"bookTicker","u":335340708669,"s":"DENTUSDT","b":"0.012346","B":"72910","a":"0.012359","A":"71860","T":1618677451984,"E":1618677451989}}
1618677452.076658: {"stream":"dentusdt@bookTicker","data":{"e":"bookTicker","u":335340709414,"s":"DENTUSDT","b":"0.012346","B":"72910","a":"0.012359","A":"60671","T":1618677452012,"E":1618677452017}}
1618677452.0841758: {"stream":"yfiusdt@depth@100ms","data":{"e":"depthUpdate","E":1618677452026,"T":1618677452019,"s":"YFIUSDT","U":335340707113,"u":335340709742,"pu":335340706800,"b":[["49576.8","0.001"],["49949.2","0.016"],["49950.3","0.020"],["49960.2","0.004"],["49962.4","0.003"],["49962.6","0.000"]],"a":[["49986.2","0.009"],["49987.4","0.003"],["49987.5","0.055"],["49989.8","0.000"],["49989.9","0.000"],["49991.1","0.009"],["49991.2","0.124"],["49991.3","0.000"],["49991.4","0.000"],["49996.1","0.000"],["49996.3","0.000"],["50033.6","0.013"],["50038.7","0.000"],["50044.4","0.030"],["50045.3","0.030"],["50049.5","0.000"],["50050.4","0.000"],["50059.1","0.006"],["50073.0","0.052"]]}}
1618677452.0975559: {"stream":"ksmusdt@depth@100ms","data":{"e":"depthUpdate","E":1618677452039,"T":1618677452035,"s":"KSMUSDT","U":335340707426,"u":335340710304,"pu":335340706820,"b":[["458.007","0.0"],["458.314","0.5"],["458.787","5.0"]],"a":[["459.702","0.0"],["459.785","0.0"],["459.816","0.1"],["459.903","0.0"],["459.941","0.0"],["459.972","0.1"],["460.148","0.4"],["460.169","11.7"],["460.313","2.7"],["460.405","0.0"],["460.489","1.0"],["460.513","0.0"],["461.334","0.2"],["463.821","0.0"]]}}
1618677452.243689: {"stream":"xmrusdt@depth@100ms","data":{"e":"depthUpdate","E":1618677452061,"T":1618677452034,"s":"XMRUSDT","U":335340707943,"u":335340710263,"pu":335340707797,"b":[["349.27","38.109"],["351.85","3.891"],["352.04","8.285"],["352.15","14.119"],["352.16","2.966"],["352.24","2.500"],["352.29","1.264"],["352.46","6.632"]],"a":[["352.57","0.778"],["352.67","6.379"],["352.84","0.000"],["353.11","3.247"],["353.21","2.500"],["353.56","5.287"],["355.66","28.270"]]}}
1618677452.250219: {"stream":"dentusdt@depth@100ms","data":{"e":"depthUpdate","E":1618677452076,"T":1618677452034,"s":"DENTUSDT","U":335340708360,"u":335340710273,"pu":335340708238,"b":[["0.012146","693907"],["0.012324","499375"],["0.012337","27003"]],"a":[["0.012359","60671"],["0.012361","11189"],["0.012362","96116"],["0.012363","225531"],["0.012365","133881"],["0.012394","40379"],["0.012396","175195"]]}}
1618677452.259469: {"stream":"yfiusdt@depth@100ms","data":{"e":"depthUpdate","E":1618677452137,"T":1618677452104,"s":"YFIUSDT","U":335340710249,"u":335340712584,"pu":335340709742,"b":[["49860.9","0.000"],["49866.6","0.000"],["49876.3","0.141"],["49905.3","0.000"],["49919.1","0.060"]],"a":[["50068.6","0.000"],["50075.2","0.060"],["50090.4","0.000"],["50092.7","0.016"],["50105.2","0.141"],["50108.8","0.047"],["50109.7","0.025"],["50180.6","0.006"],["50231.5","0.000"]]}}
1618677452.259778: {"stream":"ksmusdt@depth@100ms","data":{"e":"depthUpdate","E":1618677452153,"T":1618677452091,"s":"KSMUSDT","U":335340710822,"u":335340712370,"pu":335340710304,"b":[["457.595","3.0"]],"a":[["460.168","3.7"],["460.170","0.0"],["460.269","0.1"],["460.489","0.0"]]}}
1618677452.262655: {"stream":"xmrusdt@depth@100ms","data":{"e":"depthUpdate","E":1618677452162,"T":1618677452153,"s":"XMRUSDT","U":335340711263,"u":335340713240,"pu":335340710263,"b":[["351.48","0.000"],["351.97","2.500"],["352.11","4.951"],["352.16","4.966"],["352.24","0.000"],["352.30","0.000"]],"a":[["352.57","0.300"],["352.88","2.500"],["352.98","2.500"],["353.07","0.000"],["353.21","0.000"]]}}
1618677452.264241: {"stream":"yfiusdt@bookTicker","data":{"e":"bookTicker","u":335340713560,"s":"YFIUSDT","b":"49962.4","B":"0.003","a":"49986.2","A":"0.009","T":1618677452179,"E":1618677452183}}
1618677452.269863: {"stream":"yfiusdt@bookTicker","data":{"e":"bookTicker","u":335340714199,"s":"YFIUSDT","b":"49962.4","B":"0.003","a":"49986.1","A":"0.003","T":1618677452206,"E":1618677452211}}
1618677452.270606: {"stream":"dentusdt@kline_1m","data":{"e":"kline","E":1618677452214,"s":"DENTUSDT","k":{"t":1618677420000,"T":1618677479999,"s":"DENTUSDT","i":"1m","f":15787262,"L":15787379,"o":"0.012366","c":"0.012359","h":"0.012366","l":"0.012339","v":"1925619","n":118,"x":false,"q":"23785.307814","V":"944324","Q":"11666.801301","B":"0"}}}
1618677452.273346: {"stream":"dentusdt@bookTicker","data":{"e":"bookTicker","u":335340714288,"s":"DENTUSDT","b":"0.012346","B":"72910","a":"0.012359","A":"59698","T":1618677452210,"E":1618677452215}}
1618677452.286191: {"stream":"yfiusdt@bookTicker","data":{"e":"bookTicker","u":335340714641,"s":"YFIUSDT","b":"49962.4","B":"0.008","a":"49986.1","A":"0.003","T":1618677452222,"E":1618677452228}}
1618677452.286289: {"stream":"yfiusdt@bookTicker","data":{"e":"bookTicker","u":335340714663,"s":"YFIUSDT","b":"49962.4","B":"0.003","a":"49986.1","A":"0.003","T":1618677452222,"E":1618677452228}}
1618677452.297107: {"stream":"yfiusdt@bookTicker","data":{"e":"bookTicker","u":335340715012,"s":"YFIUSDT","b":"49974.1","B":"0.015","a":"49986.1","A":"0.003","T":1618677452230,"E":1618677452237}}
1618677452.312064: {"stream":"ksmusdt@depth@100ms","data":{"e":"depthUpdate","E":1618677452255,"T":1618677452211,"s":"KSMUSDT","U":335340713077,"u":335340714347,"pu":335340712370,"b":[],"a":[["460.144","1.0"],["460.507","2.3"],["462.216","1.1"]]}}
1618677452.312629: {"stream":"yfiusdt@depth@100ms","data":{"e":"depthUpdate","E":1618677452255,"T":1618677452248,"s":"YFIUSDT","U":335340713150,"u":335340715752,"pu":335340712584,"b":[["49772.3","0.013"],["49844.1","0.020"],["49845.6","0.000"],["49851.1","0.006"],["49855.6","0.006"],["49898.3","0.134"],["49904.4","0.110"],["49908.6","0.110"],["49911.0","0.080"],["49912.8","0.110"],["49917.0","0.000"],["49921.2","0.000"],["49925.4","0.000"],["49936.4","0.000"],["49938.7","0.326"],["49942.7","0.000"],["49945.5","0.000"],["49949.1","0.000"],["49960.1","0.000"],["49960.2","0.000"],["49960.3","0.000"],["49962.2","0.000"],["49962.4","0.003"],["49974.1","0.015"],["49976.6","0.000"]],"a":[["49986.1","0.003"],["49987.4","0.000"],["49991.1","0.020"],["50060.6","0.005"],["50074.8","0.000"],["50080.6","0.009"],["50087.1","0.000"],["50092.8","0.000"],["50115.3","0.010"]]}}
1618677452.328963: {"stream":"yfiusdt@bookTicker","data":{"e":"bookTicker","u":335340716432,"s":"YFIUSDT","b":"49974.1","B":"0.015","a":"49984.8","A":"0.009","T":1618677452264,"E":1618677452270}}
1618677452.3290691: {"stream":"yfiusdt@bookTicker","data":{"e":"bookTicker","u":335340716469,"s":"YFIUSDT","b":"49974.2","B":"0.003","a":"49984.8","A":"0.009","T":1618677452265,"E":1618677452270}}
1618677452.332994: {"stream":"xmrusdt@depth@100ms","data":{"e":"depthUpdate","E":1618677452275,"T":1618677452220,"s":"XMRUSDT","U":335340713301,"u":335340714568,"pu":335340713240,"b":[["351.53","5.476"],["351.97","0.000"],["352.05","2.553"],["352.25","2.500"]],"a":[["352.57","0.778"],["352.60","3.700"],["352.98","0.000"],["353.16","2.964"]]}}
1618677452.341163: {"stream":"dentusdt@depth@100ms","data":{"e":"depthUpdate","E":1618677452282,"T":1618677452253,"s":"DENTUSDT","U":335340713472,"u":335340715979,"pu":335340710273,"b":[["0.012224","31944"],["0.012340","7410"],["0.012341","9878"]],"a":[["0.012359","59698"],["0.012362","46318"],["0.012373","60991"],["0.012379","50901"],["0.012421","206362"]]}}
1618677452.369173: {"stream":"yfiusdt@bookTicker","data":{"e":"bookTicker","u":335340718026,"s":"YFIUSDT","b":"49956.8","B":"0.006","a":"49984.8","A":"0.009","T":1618677452307,"E":1618677452312}}
1618677452.371676: {"stream":"yfiusdt@bookTicker","data":{"e":"bookTicker","u":335340718088,"s":"YFIUSDT","b":"49956.8","B":"0.006","a":"49984.7","A":"0.003","T":1618677452310,"E":1618677452314}}
1618677452.376874: {"stream":"yfiusdt@bookTicker","data":{"e":"bookTicker","u":335340718126,"s":"YFIUSDT","b":"49967.6","B":"0.015","a":"49984.7","A":"0.003","T":1618677452311,"E":1618677452316}}
1618677452.409566: {"stream":"dentusdt@aggTrade","data":{"e":"aggTrade","E":1618677452351,"a":8476398,"s":"DENTUSDT","p":"0.012359","q":"973","f":15787379,"l":15787379,"T":1618677452210,"m":false}}
1618677452.4096751: {"stream":"dentusdt@bookTicker","data":{"e":"bookTicker","u":335340719187,"s":"DENTUSDT","b":"0.012346","B":"72910","a":"0.012359","A":"51390","T":1618677452347,"E":1618677452351}}
1618677452.414695: {"stream":"yfiusdt@depth@100ms","data":{"e":"depthUpdate","E":1618677452355,"T":1618677452350,"s":"YFIUSDT","U":335340715813,"u":335340719297,"pu":335340715752,"b":[["49758.4","0.043"],["49879.8","0.008"],["49904.4","0.000"],["49905.4","0.000"],["49905.5","0.000"],["49908.6","0.110"],["49912.8","0.110"],["49917.0","0.110"],["49917.7","0.009"],["49921.0","0.009"],["49921.2","0.000"],["49921.8","0.009"],["49925.4","0.000"],["49927.9","0.000"],["49931.3","0.000"],["49932.0","0.000"],["49938.8","0.072"],["49940.5","0.000"],["49940.6","0.000"],["49949.2","0.000"],["49956.7","0.000"],["49956.8","0.000"],["49956.9","0.038"],["49957.0","0.003"],["49960.4","0.000"],["49962.3","0.000"],["49962.4","0.000"],["49967.6","0.015"],["49974.1","0.000"],["49974.2","0.000"]],"a":[["49984.7","0.003"],["49984.8","0.009"],["49986.1","0.000"],["49986.2","0.000"],["50083.1","0.054"]]}}
1618677452.421846: {"stream":"dentusdt@bookTicker","data":{"e":"bookTicker","u":335340719543,"s":"DENTUSDT","b":"0.012346","B":"72910","a":"0.012359","A":"60579","T":1618677452358,"E":1618677452363}}
1618677452.421951: {"stream":"dentusdt@bookTicker","data":{"e":"bookTicker","u":335340719582,"s":"DENTUSDT","b":"0.012346","B":"81731","a":"0.012359","A":"60579","T":1618677452359,"E":1618677452363}}
1618677452.447424: {"stream":"yfiusdt@bookTicker","data":{"e":"bookTicker","u":335340720328,"s":"YFIUSDT","b":"49967.6","B":"0.015","a":"49983.4","A":"0.009","T":1618677452383,"E":1618677452389}}
1618677452.452582: {"stream":"dentusdt@bookTicker","data":{"e":"bookTicker","u":335340720584,"s":"DENTUSDT","b":"0.012346","B":"81731","a":"0.012359","A":"9189","T":1618677452389,"E":1618677452394}}
1618677452.454953: {"stream":"xmrusdt@bookTicker","data":{"e":"bookTicker","u":335340720677,"s":"XMRUSDT","b":"352.47","B":"0.853","a":"352.49","A":"1.000","T":1618677452392,"E":1618677452396}}
1618677452.467718: {"stream":"xmrusdt@bookTicker","data":{"e":"bookTicker","u":335340721023,"s":"XMRUSDT","b":"352.48","B":"2.936","a":"352.49","A":"1.000","T":1618677452402,"E":1618677452407}}
1618677452.468328: {"stream":"xmrusdt@depth@100ms","data":{"e":"depthUpdate","E":1618677452409,"T":1618677452402,"s":"XMRUSDT","U":335340717996,"u":335340721055,"pu":335340714568,"b":[["349.29","57.617"],["351.42","6.574"],["352.17","24.239"],["352.18","0.000"],["352.24","2.500"],["352.25","0.000"],["352.28","0.000"],["352.29","0.023"],["352.32","6.019"],["352.45","0.000"],["352.46","3.700"],["352.47","0.853"],["352.48","2.936"]],"a":[["352.48","0.000"],["355.66","84.503"]]}}
1618677452.470062: {"stream":"dentusdt@depth@100ms","data":{"e":"depthUpdate","E":1618677452409,"T":1618677452390,"s":"DENTUSDT","U":335340717983,"u":335340720597,"pu":335340715979,"b":[["0.012327","496623"],["0.012344","3499"],["0.012346","81731"]],"a":[["0.012359","9189"],["0.012360","20904"],["0.012362","29350"]]}}
1618677452.4880772: {"stream":"yfiusdt@bookTicker","data":{"e":"bookTicker","u":335340722051,"s":"YFIUSDT","b":"49967.6","B":"0.015","a":"49983.3","A":"0.003","T":1618677452425,"E":1618677452429}}
1618677452.496741: {"stream":"dentusdt@bookTicker","data":{"e":"bookTicker","u":335340722379,"s":"DENTUSDT","b":"0.012346","B":"81731","a":"0.012359","A":"60579","T":1618677452433,"E":1618677452437}}
1618677452.499805: {"stream":"xmrusdt@bookTicker","data":{"e":"bookTicker","u":335340722510,"s":"XMRUSDT","b":"352.48","B":"3.789","a":"352.49","A":"1.000","T":1618677452436,"E":1618677452440}}
1618677452.5125482: {"stream":"xmrusdt@bookTicker","data":{"e":"bookTicker","u":335340723007,"s":"XMRUSDT","b":"352.48","B":"7.489","a":"352.49","A":"1.000","T":1618677452449,"E":1618677452453}}
1618677452.514781: {"stream":"yfiusdt@depth@100ms","data":{"e":"depthUpdate","E":1618677452456,"T":1618677452440,"s":"YFIUSDT","U":335340719329,"u":335340722674,"pu":335340719297,"b":[["49829.5","0.010"],["49903.8","0.000"],["49904.4","0.002"],["49918.4","0.000"],["49925.8","0.130"],["49938.7","0.000"],["49938.8","0.000"]],"a":[["49983.3","0.003"],["49983.4","0.009"],["49984.7","0.000"],["49984.8","0.000"],["49986.7","0.001"],["50031.8","0.000"],["50051.9","0.006"],["50138.8","0.000"]]}}
1618677452.523194: {"stream":"yfiusdt@bookTicker","data":{"e":"bookTicker","u":335340723396,"s":"YFIUSDT","b":"49957.0","B":"0.003","a":"49983.3","A":"0.003","T":1618677452461,"E":1618677452464}}
1618677452.5309088: {"stream":"ksmusdt@depth@100ms","data":{"e":"depthUpdate","E":1618677452472,"T":1618677452443,"s":"KSMUSDT","U":335340719889,"u":335340722745,"pu":335340714347,"b":[["444.411","5.2"],["455.251","0.9"],["457.756","1.6"],["458.100","1.6"],["458.500","0.0"],["458.746","0.7"]],"a":[]}}
1618677452.531061: {"stream":"dentusdt@kline_1m","data":{"e":"kline","E":1618677452473,"s":"DENTUSDT","k":{"t":1618677420000,"T":1618677479999,"s":"DENTUSDT","i":"1m","f":15787262,"L":15787382,"o":"0.012366","c":"0.012359","h":"0.012366","l":"0.012339","v":"1943116","n":121,"x":false,"q":"24001.553237","V":"961821","Q":"11883.046724","B":"0"}}}
1618677452.531111: {"stream":"dentusdt@aggTrade","data":{"e":"aggTrade","E":1618677452473,"a":8476399,"s":"DENTUSDT","p":"0.012359","q":"8308","f":15787380,"l":15787381,"T":1618677452347,"m":false}}
1618677452.5311391: {"stream":"dentusdt@aggTrade","data":{"e":"aggTrade","E":1618677452473,"a":8476400,"s":"DENTUSDT","p":"0.012359","q":"60579","f":15787382,"l":15787383,"T":1618677452469,"m":false}}
1618677452.531161: {"stream":"dentusdt@bookTicker","data":{"e":"bookTicker","u":335340723727,"s":"DENTUSDT","b":"0.012346","B":"81731","a":"0.012361","A":"34569","T":1618677452469,"E":1618677452473}}
1618677452.537817: {"stream":"dentusdt@bookTicker","data":{"e":"bookTicker","u":335340723909,"s":"DENTUSDT","b":"0.012347","B":"923","a":"0.012361","A":"34569","T":1618677452477,"E":1618677452480}}
1618677452.543542: {"stream":"dentusdt@bookTicker","data":{"e":"bookTicker","u":335340724039,"s":"DENTUSDT","b":"0.012347","B":"50923","a":"0.012361","A":"34569","T":1618677452480,"E":1618677452484}}
1618677452.5532002: {"stream":"dentusdt@bookTicker","data":{"e":"bookTicker","u":335340724367,"s":"DENTUSDT","b":"0.012348","B":"10368","a":"0.012361","A":"34569","T":1618677452491,"E":1618677452495}}
1618677452.5637639: {"stream":"dentusdt@bookTicker","data":{"e":"bookTicker","u":335340724808,"s":"DENTUSDT","b":"0.012348","B":"10368","a":"0.012362","A":"44414","T":1618677452502,"E":1618677452506}}
1618677452.573185: {"stream":"xmrusdt@bookTicker","data":{"e":"bookTicker","u":335340725030,"s":"XMRUSDT","b":"352.48","B":"7.489","a":"352.49","A":"2.358","T":1618677452508,"E":1618677452514}}
1618677452.5801358: {"stream":"xmrusdt@depth@100ms","data":{"e":"depthUpdate","E":1618677452519,"T":1618677452512,"s":"XMRUSDT","U":335340721521,"u":335340725199,"pu":335340721055,"b":[["351.51","1.000"],["351.53","3.476"],["352.14","1.000"],["352.16","2.966"],["352.18","13.860"],["352.44","0.000"],["352.45","0.000"],["352.46","3.700"],["352.47","0.000"],["352.48","7.489"]],"a":[["352.48","0.000"],["352.49","2.358"],["352.59","0.000"],["352.60","0.000"]]}}
1618677452.583898: {"stream":"dentusdt@depth@100ms","data":{"e":"depthUpdate","E":1618677452527,"T":1618677452511,"s":"DENTUSDT","U":335340721964,"u":335340725161,"pu":335340720597,"b":[["0.000011","20805663"],["0.012325","624630"],["0.012327","385644"],["0.012329","5171"],["0.012337","138096"],["0.012340","27525"],["0.012341","241433"],["0.012343","97138"],["0.012344","0"],["0.012346","72910"],["0.012347","50923"],["0.012348","10368"]],"a":[["0.012359","0"],["0.012360","0"],["0.012361","0"],["0.012362","44414"],["0.012365","0"],["0.012369","0"],["0.012371","0"],["0.012373","60991"],["0.012376","17444"],["0.012380","62888"],["0.012381","220927"],["0.012383","349601"]]}}
1618677452.59728: {"stream":"yfiusdt@bookTicker","data":{"e":"bookTicker","u":335340726042,"s":"YFIUSDT","b":"49957.1","B":"0.013","a":"49983.3","A":"0.003","T":1618677452535,"E":1618677452539}}
1618677452.597383: {"stream":"dentusdt@bookTicker","data":{"e":"bookTicker","u":335340726046,"s":"DENTUSDT","b":"0.012348","B":"83728","a":"0.012362","A":"44414","T":1618677452535,"E":1618677452539}}
1618677452.597429: {"stream":"dentusdt@bookTicker","data":{"e":"bookTicker","u":335340726049,"s":"DENTUSDT","b":"0.012348","B":"137687","a":"0.012362","A":"44414","T":1618677452535,"E":1618677452539}}
1618677452.618531: {"stream":"yfiusdt@depth@100ms","data":{"e":"depthUpdate","E":1618677452559,"T":1618677452551,"s":"YFIUSDT","U":335340723217,"u":335340726678,"pu":335340722674,"b":[["49740.9","0.008"],["49877.9","0.100"],["49900.2","0.110"],["49904.4","0.112"],["49912.8","0.000"],["49917.0","0.000"],["49917.7","0.007"],["49921.0","0.007"],["49921.8","0.007"],["49925.8","0.000"],["49931.2","0.130"],["49931.6","0.087"],["49932.1","0.009"],["49938.0","0.012"],["49938.6","0.000"],["49943.0","0.009"],["49944.5","0.000"],["49944.7","0.000"],["49949.0","0.016"],["49949.5","0.000"],["49950.2","0.012"],["49956.9","0.025"],["49957.1","0.013"],["49967.6","0.000"]],"a":[["49991.1","0.000"],["49991.2","0.000"],["49994.2","0.000"],["49997.2","0.000"],["50025.5","0.000"],["50032.9","0.011"],["50040.3","0.011"],["50040.4","0.009"],["50046.2","0.011"],["50046.3","0.000"],["50068.7","0.021"],["50122.3","0.000"]]}}
1618677452.628118: {"stream":"ksmusdt@depth@100ms","data":{"e":"depthUpdate","E":1618677452572,"T":1618677452525,"s":"KSMUSDT","U":335340723602,"u":335340725636,"pu":335340722745,"b":[["455.147","0.0"],["455.220","3.9"],["457.214","0.0"],["457.287","3.9"]],"a":[["460.501","1.9"],["461.347","0.0"],["461.420","3.9"],["463.414","0.0"],["463.487","3.9"]]}}
1618677452.640349: {"stream":"yfiusdt@bookTicker","data":{"e":"bookTicker","u":335340727648,"s":"YFIUSDT","b":"49957.2","B":"0.003","a":"49983.3","A":"0.003","T":1618677452577,"E":1618677452581}}
1618677452.640878: {"stream":"yfiusdt@bookTicker","data":{"e":"bookTicker","u":335340727751,"s":"YFIUSDT","b":"49959.5","B":"0.055","a":"49983.3","A":"0.003","T":1618677452581,"E":1618677452584}}
1618677452.6657379: {"stream":"ksmusdt@bookTicker","data":{"e":"bookTicker","u":335340728578,"s":"KSMUSDT","b":"459.242","B":"1.2","a":"459.369","A":"0.1","T":1618677452603,"E":1618677452607}}
1618677452.6789272: {"stream":"dentusdt@bookTicker","data":{"e":"bookTicker","u":335340729048,"s":"DENTUSDT","b":"0.012348","B":"137687","a":"0.012362","A":"94201","T":1618677452619,"E":1618677452621}}
1618677452.6796758: {"stream":"yfiusdt@bookTicker","data":{"e":"bookTicker","u":335340729064,"s":"YFIUSDT","b":"49959.9","B":"0.014","a":"49983.3","A":"0.003","T":1618677452620,"E":1618677452621}}
1618677452.679755: {"stream":"xmrusdt@depth@100ms","data":{"e":"depthUpdate","E":1618677452622,"T":1618677452585,"s":"XMRUSDT","U":335340725367,"u":335340727947,"pu":335340725199,"b":[["351.84","2.102"],["351.85","0.888"],["352.06","17.027"],["352.24","2.500"],["352.30","0.000"]],"a":[["352.57","0.300"],["353.00","15.462"],["353.11","0.000"],["353.12","0.000"]]}}
1618677452.680542: {"stream":"dentusdt@aggTrade","data":{"e":"aggTrade","E":1618677452624,"a":8476401,"s":"DENTUSDT","p":"0.012361","q":"30590","f":15787384,"l":15787385,"T":1618677452469,"m":false}}
1618677452.695688: {"stream":"dentusdt@depth@100ms","data":{"e":"depthUpdate","E":1618677452639,"T":1618677452619,"s":"DENTUSDT","U":335340726041,"u":335340729048,"pu":335340725161,"b":[["0.012152","3160"],["0.012342","301680"],["0.012348","137687"]],"a":[["0.012362","94201"],["0.012373","11193"],["0.012380","97446"],["0.012383","346364"],["0.012402","107443"]]}}
1618677452.7040808: {"stream":"ksmusdt@bookTicker","data":{"e":"bookTicker","u":335340729727,"s":"KSMUSDT","b":"459.239","B":"6.4","a":"459.369","A":"0.1","T":1618677452641,"E":1618677452646}}
1618677452.719367: {"stream":"yfiusdt@depth@100ms","data":{"e":"depthUpdate","E":1618677452660,"T":1618677452625,"s":"YFIUSDT","U":335340726783,"u":335340729231,"pu":335340726678,"b":[["49900.2","0.000"],["49912.8","0.110"],["49934.1","0.015"],["49936.3","0.304"],["49950.1","0.000"],["49950.2","0.000"],["49950.3","0.000"],["49957.0","0.000"],["49957.1","0.000"],["49957.2","0.000"],["49957.5","0.000"],["49959.5","0.055"],["49959.6","0.003"],["49959.9","0.014"]],"a":[["50025.5","0.004"],["50372.4","0.000"]]}}
1618677452.71968: {"stream":"yfiusdt@bookTicker","data":{"e":"bookTicker","u":335340730204,"s":"YFIUSDT","b":"49960.0","B":"0.003","a":"49983.3","A":"0.003","T":1618677452656,"E":1618677452660}}
1618677452.7197351: {"stream":"dentusdt@bookTicker","data":{"e":"bookTicker","u":335340730301,"s":"DENTUSDT","b":"0.012348","B":"83728","a":"0.012362","A":"94201","T":1618677452659,"E":1618677452663}}
1618677452.7223191: {"stream":"yfiusdt@bookTicker","data":{"e":"bookTicker","u":335340730383,"s":"YFIUSDT","b":"49962.3","B":"0.055","a":"49983.3","A":"0.003","T":1618677452661,"E":1618677452665}}
1618677452.734543: {"stream":"yfiusdt@bookTicker","data":{"e":"bookTicker","u":335340730731,"s":"YFIUSDT","b":"49963.6","B":"0.006","a":"49983.3","A":"0.003","T":1618677452672,"E":1618677452675}}
1618677452.74771: {"stream":"ksmusdt@depth@100ms","data":{"e":"depthUpdate","E":1618677452684,"T":1618677452657,"s":"KSMUSDT","U":335340727750,"u":335340730256,"pu":335340725636,"b":[["458.229","0.0"],["459.162","1.2"],["459.242","0.0"]],"a":[["459.369","0.1"],["459.961","6.0"],["460.144","1.0"],["461.388","1.0"]]}}
1618677452.7616599: {"stream":"yfiusdt@bookTicker","data":{"e":"bookTicker","u":335340731568,"s":"YFIUSDT","b":"49963.7","B":"0.012","a":"49983.3","A":"0.003","T":1618677452698,"E":1618677452702}}
1618677452.761759: {"stream":"yfiusdt@bookTicker","data":{"e":"bookTicker","u":335340731571,"s":"YFIUSDT","b":"49963.7","B":"0.012","a":"49986.7","A":"0.001","T":1618677452698,"E":1618677452702}}
1618677452.761802: {"stream":"yfiusdt@bookTicker","data":{"e":"bookTicker","u":335340731579,"s":"YFIUSDT","b":"49963.7","B":"0.015","a":"49986.7","A":"0.001","T":1618677452698,"E":1618677452702}}
1618677452.7621582: {"stream":"yfiusdt@bookTicker","data":{"e":"bookTicker","u":335340731673,"s":"YFIUSDT","b":"49966.0","B":"0.055","a":"49986.7","A":"0.001","T":1618677452701,"E":1618677452705}}
1618677452.777366: {"stream":"yfiusdt@bookTicker","data":{"e":"bookTicker","u":335340731960,"s":"YFIUSDT","b":"49967.3","B":"0.006","a":"49986.7","A":"0.001","T":1618677452711,"E":1618677452714}}
1618677452.7827132: {"stream":"yfiusdt@bookTicker","data":{"e":"bookTicker","u":335340732221,"s":"YFIUSDT","b":"49967.4","B":"0.013","a":"49986.7","A":"0.001","T":1618677452720,"E":1618677452724}}
1618677452.79036: {"stream":"dentusdt@bookTicker","data":{"e":"bookTicker","u":335340732435,"s":"DENTUSDT","b":"0.012348","B":"83728","a":"0.012362","A":"44414","T":1618677452728,"E":1618677452731}}
1618677452.7907908: {"stream":"yfiusdt@bookTicker","data":{"e":"bookTicker","u":335340732486,"s":"YFIUSDT","b":"49968.7","B":"0.006","a":"49986.7","A":"0.001","T":1618677452729,"E":1618677452733}}
1618677452.7936409: {"stream":"dentusdt@bookTicker","data":{"e":"bookTicker","u":335340732546,"s":"DENTUSDT","b":"0.012349","B":"927","a":"0.012362","A":"44414","T":1618677452731,"E":1618677452735}}
1618677452.7937138: {"stream":"dentusdt@bookTicker","data":{"e":"bookTicker","u":335340732547,"s":"DENTUSDT","b":"0.012349","B":"927","a":"0.012361","A":"5843","T":1618677452731,"E":1618677452735}}
1618677452.800184: {"stream":"yfiusdt@bookTicker","data":{"e":"bookTicker","u":335340732717,"s":"YFIUSDT","b":"49969.8","B":"0.055","a":"49986.7","A":"0.001","T":1618677452737,"E":1618677452742}}
1618677452.8085709: {"stream":"yfiusdt@bookTicker","data":{"e":"bookTicker","u":335340733046,"s":"YFIUSDT","b":"49971.1","B":"0.006","a":"49986.7","A":"0.001","T":1618677452747,"E":1618677452751}}
1618677452.813084: {"stream":"dentusdt@depth@100ms","data":{"e":"depthUpdate","E":1618677452756,"T":1618677452731,"s":"DENTUSDT","U":335340730104,"u":335340732547,"pu":335340729048,"b":[["0.012318","107772"],["0.012342","301680"],["0.012347","103959"],["0.012348","83728"],["0.012349","927"]],"a":[["0.012361","5843"],["0.012362","44414"],["0.012420","615331"],["0.012468","980"],["0.012489","4731"],["0.012510","59336"],["0.012530","262"],["0.012684","219140"]]}}
1618677452.823148: {"stream":"yfiusdt@depth@100ms","data":{"e":"depthUpdate","E":1618677452760,"T":1618677452752,"s":"YFIUSDT","U":335340730182,"u":335340733154,"pu":335340729231,"b":[["49903.7","0.026"],["49904.4","0.002"],["49908.6","0.000"],["49911.8","0.000"],["49917.0","0.110"],["49918.7","0.009"],["49921.2","0.110"],["49925.7","0.000"],["49931.7","0.000"],["49934.1","0.000"],["49936.3","0.000"],["49936.4","0.168"],["49938.5","0.000"],["49939.9","0.070"],["49943.8","0.081"],["49959.5","0.000"],["49959.6","0.000"],["49959.9","0.000"],["49960.0","0.000"],["49962.3","0.000"],["49962.4","0.000"],["49963.6","0.000"],["49963.7","0.000"],["49963.8","0.000"],["49965.0","0.000"],["49965.6","0.013"],["49966.0","0.055"],["49967.3","0.000"],["49967.4","0.000"],["49967.5","0.003"],["49968.7","0.000"],["49968.8","0.004"],["49969.8","0.055"],["49969.9","0.004"],["49971.1","0.006"]],"a":[["49983.3","0.000"],["49983.4","0.000"],["49987.5","0.000"],["49998.7","0.000"],["49998.8","0.000"],["50004.6","0.013"],["50006.8","0.014"],["50032.8","0.030"],["50068.7","0.000"],["50079.8","0.130"],["50176.4","0.015"],["50226.5","0.185"]]}}
1618677452.84016: {"stream":"dentusdt@bookTicker","data":{"e":"bookTicker","u":335340733676,"s":"DENTUSDT","b":"0.012349","B":"927","a":"0.012361","A":"55630","T":1618677452769,"E":1618677452774}}
1618677452.840265: {"stream":"yfiusdt@bookTicker","data":{"e":"bookTicker","u":335340733719,"s":"YFIUSDT","b":"49971.2","B":"0.003","a":"49986.7","A":"0.001","T":1618677452771,"E":1618677452776}}
1618677452.844757: {"stream":"yfiusdt@bookTicker","data":{"e":"bookTicker","u":335340733871,"s":"YFIUSDT","b":"49971.2","B":"0.009","a":"49986.7","A":"0.001","T":1618677452775,"E":1618677452779}}
1618677452.851135: {"stream":"yfiusdt@bookTicker","data":{"e":"bookTicker","u":335340734165,"s":"YFIUSDT","b":"49971.2","B":"0.003","a":"49986.7","A":"0.001","T":1618677452785,"E":1618677452790}}
1618677452.851237: {"stream":"yfiusdt@bookTicker","data":{"e":"bookTicker","u":335340734207,"s":"YFIUSDT","b":"49972.5","B":"0.006","a":"49986.7","A":"0.001","T":1618677452787,"E":1618677452792}}
1618677452.854964: {"stream":"xmrusdt@depth@100ms","data":{"e":"depthUpdate","E":1618677452793,"T":1618677452758,"s":"XMRUSDT","U":335340731266,"u":335340733329,"pu":335340727947,"b":[["352.24","0.000"],["352.30","2.500"],["352.32","0.000"]],"a":[["352.66","0.095"],["353.40","17.664"],["353.44","8.400"],["354.56","16.492"]]}}
1618677452.85873: {"stream":"ksmusdt@depth@100ms","data":{"e":"depthUpdate","E":1618677452798,"T":1618677452766,"s":"KSMUSDT","U":335340731408,"u":335340733586,"pu":335340730256,"b":[["458.229","1.1"],["458.956","0.2"],["458.998","0.0"]],"a":[["460.437","31.5"]]}}
1618677452.8676: {"stream":"yfiusdt@bookTicker","data":{"e":"bookTicker","u":335340734721,"s":"YFIUSDT","b":"49972.6","B":"0.003","a":"49986.7","A":"0.001","T":1618677452806,"E":1618677452809}}
1618677452.87651: {"stream":"xmrusdt@bookTicker","data":{"e":"bookTicker","u":335340734917,"s":"XMRUSDT","b":"352.48","B":"7.416","a":"352.49","A":"2.358","T":1618677452812,"E":1618677452816}}
1618677452.8766122: {"stream":"xmrusdt@kline_1m","data":{"e":"kline","E":1618677452817,"s":"XMRUSDT","k":{"t":1618677420000,"T":1618677479999,"s":"XMRUSDT","i":"1m","f":34692938,"L":34692967,"o":"352.86","c":"352.48","h":"352.93","l":"352.40","v":"24.101","n":30,"x":false,"q":"8500.10438","V":"1.638","Q":"577.96953","B":"0"}}}
1618677452.883908: {"stream":"ksmusdt@bookTicker","data":{"e":"bookTicker","u":335340735171,"s":"KSMUSDT","b":"459.239","B":"6.4","a":"459.340","A":"2.5","T":1618677452820,"E":1618677452825}}
1618677452.884008: {"stream":"yfiusdt@bookTicker","data":{"e":"bookTicker","u":335340735173,"s":"YFIUSDT","b":"49972.6","B":"0.003","a":"49986.6","A":"0.055","T":1618677452820,"E":1618677452825}}
1618677452.889226: {"stream":"ksmusdt@bookTicker","data":{"e":"bookTicker","u":335340735314,"s":"KSMUSDT","b":"459.239","B":"6.4","a":"459.369","A":"0.1","T":1618677452824,"E":1618677452829}}
1618677452.8893352: {"stream":"yfiusdt@bookTicker","data":{"e":"bookTicker","u":335340735327,"s":"YFIUSDT","b":"49973.9","B":"0.006","a":"49986.6","A":"0.055","T":1618677452824,"E":1618677452829}}
1618677452.910681: {"stream":"dentusdt@bookTicker","data":{"e":"bookTicker","u":335340736022,"s":"DENTUSDT","b":"0.012349","B":"54886","a":"0.012361","A":"55630","T":1618677452847,"E":1618677452853}}
1618677452.920562: {"stream":"yfiusdt@depth@100ms","data":{"e":"depthUpdate","E":1618677452862,"T":1618677452852,"s":"YFIUSDT","U":335340733318,"u":335340736257,"pu":335340733154,"b":[["49758.4","0.000"],["49898.4","0.010"],["49912.8","0.000"],["49917.0","0.000"],["49917.7","0.000"],["49921.0","0.000"],["49921.8","0.000"],["49924.1","0.013"],["49925.4","0.110"],["49927.5","0.013"],["49928.2","0.013"],["49929.6","0.110"],["49931.6","0.000"],["49936.4","0.000"],["49940.0","0.168"],["49965.6","0.000"],["49966.3","0.000"],["49967.3","0.000"],["49967.5","0.000"],["49967.9","0.013"],["49968.8","0.000"],["49969.8","0.000"],["49969.9","0.000"],["49971.1","0.000"],["49971.2","0.000"],["49972.5","0.000"],["49972.6","0.003"],["49973.9","0.006"]],"a":[["49986.6","0.055"],["50004.5","0.003"],["50025.3","0.013"],["50025.5","0.000"],["50025.7","0.003"],["50032.7","0.013"],["50032.8","0.000"],["50032.9","0.000"],["50033.6","0.000"],["50036.5","0.003"],["50037.4","0.003"],["50038.6","0.013"],["50040.3","0.000"],["50043.9","0.000"],["50044.4","0.000"],["50045.3","0.000"],["50046.2","0.000"],["50078.7","0.021"],["50092.7","0.000"],["50108.8","0.029"],["50245.7","0.031"]]}}
1618677452.9216309: {"stream":"dentusdt@bookTicker","data":{"e":"bookTicker","u":335340736513,"s":"DENTUSDT","b":"0.012350","B":"9913","a":"0.012361","A":"55630","T":1618677452859,"E":1618677452864}}
1618677452.930103: {"stream":"dentusdt@depth@100ms","data":{"e":"depthUpdate","E":1618677452871,"T":1618677452859,"s":"DENTUSDT","U":335340733599,"u":335340736513,"pu":335340732547,"b":[["0.012342","221200"],["0.012347","50000"],["0.012348","73360"],["0.012349","54886"],["0.012350","9913"]],"a":[["0.012361","55630"],["0.012420","784500"]]}}
1618677452.967517: {"stream":"xmrusdt@depth@100ms","data":{"e":"depthUpdate","E":1618677452909,"T":1618677452854,"s":"XMRUSDT","U":335340734662,"u":335340736304,"pu":335340733329,"b":[["352.23","0.000"],["352.24","2.500"],["352.30","0.000"],["352.33","1.788"],["352.48","7.416"]],"a":[["352.68","30.368"],["352.88","2.500"],["357.18","96.201"],["357.28","2.314"]]}}
1618677452.978048: {"stream":"yfiusdt@bookTicker","data":{"e":"bookTicker","u":335340738234,"s":"YFIUSDT","b":"49979.7","B":"0.015","a":"49986.6","A":"0.055","T":1618677452917,"E":1618677452921}}
1618677452.9812229: {"stream":"ksmusdt@depth@100ms","data":{"e":"depthUpdate","E":1618677452925,"T":1618677452899,"s":"KSMUSDT","U":335340735171,"u":335340737684,"pu":335340733586,"b":[["458.229","1.1"],["458.957","5.5"]],"a":[["459.340","0.0"],["460.550","14.1"],["461.289","0.9"]]}}
1618677452.994186: {"stream":"dentusdt@bookTicker","data":{"e":"bookTicker","u":335340738668,"s":"DENTUSDT","b":"0.012350","B":"29314","a":"0.012361","A":"55630","T":1618677452930,"E":1618677452935}}
1618677452.9972491: {"stream":"yfiusdt@bookTicker","data":{"e":"bookTicker","u":335340738798,"s":"YFIUSDT","b":"49979.7","B":"0.015","a":"49985.3","A":"0.009","T":1618677452935,"E":1618677452939}}
1618677453.0039601: {"stream":"yfiusdt@bookTicker","data":{"e":"bookTicker","u":335340738957,"s":"YFIUSDT","b":"49974.0","B":"0.003","a":"49985.3","A":"0.009","T":1618677452940,"E":1618677452945}}
1618677453.004066: {"stream":"yfiusdt@bookTicker","data":{"e":"bookTicker","u":335340738976,"s":"YFIUSDT","b":"49974.0","B":"0.003","a":"49986.6","A":"0.055","T":1618677452940,"E":1618677452945}}
1618677453.00443: {"stream":"yfiusdt@bookTicker","data":{"e":"bookTicker","u":335340738985,"s":"YFIUSDT","b":"49981.0","B":"0.006","a":"49986.6","A":"0.055","T":1618677452941,"E":1618677452946}}
1618677453.0244732: {"stream":"yfiusdt@depth@100ms","data":{"e":"depthUpdate","E":1618677452966,"T":1618677452956,"s":"YFIUSDT","U":335340736594,"u":335340739455,"pu":335340736257,"b":[["49922.2","0.145"],["49937.4","0.087"],["49938.1","0.276"],["49939.9","0.000"],["49940.0","0.000"],["49943.9","0.000"],["49944.0","0.001"],["49950.1","0.024"],["49956.9","0.000"],["49957.0","0.000"],["49964.2","0.013"],["49966.0","0.000"],["49967.9","0.000"],["49968.0","0.000"],["49972.6","0.000"],["49973.9","0.000"],["49974.0","0.003"],["49979.7","0.000"],["49981.0","0.006"]],"a":[["49985.3","0.000"],["50006.8","0.000"],["50025.3","0.006"],["50025.5","0.004"],["50032.7","0.006"],["50038.6","0.006"],["50060.6","0.000"],["50073.0","0.000"],["50079.7","0.010"],["50080.6","0.000"],["50083.1","0.004"],["50087.4","0.005"],["50107.4","0.009"],["50108.1","0.000"],["50109.7","0.000"],["50976.4","0.049"]]}}
1618677453.0249548: {"stream":"xmrusdt@aggTrade","data":{"e":"aggTrade","E":1618677452967,"a":23619024,"s":"XMRUSDT","p":"352.48","q":"0.073","f":34692967,"l":34692967,"T":1618677452812,"m":true}}
1618677453.049997: {"stream":"dentusdt@depth@100ms","data":{"e":"depthUpdate","E":1618677452993,"T":1618677452933,"s":"DENTUSDT","U":335340737316,"u":335340738736,"pu":335340736513,"b":[["0.012321","27020"],["0.012325","1029308"],["0.012348","53957"],["0.012350","29314"]],"a":[["0.012408","90468"]]}}
1618677453.0826828: {"stream":"xmrusdt@depth@100ms","data":{"e":"depthUpdate","E":1618677453019,"T":1618677453009,"s":"XMRUSDT","U":335340738154,"u":335340740972,"pu":335340736304,"b":[["352.24","0.000"],["352.34","2.500"]],"a":[["354.10","6.532"],["354.49","5.933"],["355.15","22.452"]]}}
1618677453.086287: {"stream":"yfiusdt@bookTicker","data":{"e":"bookTicker","u":335340741678,"s":"YFIUSDT","b":"49981.0","B":"0.006","a":"49986.7","A":"0.001","T":1618677453023,"E":1618677453029}}
1618677453.0969: {"stream":"ksmusdt@depth@100ms","data":{"e":"depthUpdate","E":1618677453039,"T":1618677453026,"s":"KSMUSDT","U":335340738822,"u":335340741808,"pu":335340737684,"b":[["458.956","0.0"],["459.163","0.2"]],"a":[["460.269","0.0"],["463.759","15.0"],["463.806","15.0"]]}}
1618677453.2384052: {"stream":"yfiusdt@depth@100ms","data":{"e":"depthUpdate","E":1618677453067,"T":1618677453054,"s":"YFIUSDT","U":335340739621,"u":335340743034,"pu":335340739455,"b":[["48977.6","0.000"],["48984.1","0.001"],["49533.4","0.000"],["49758.3","0.000"],["49866.5","0.000"],["49898.3","0.054"],["49911.0","0.000"],["49919.8","0.025"],["49921.2","0.000"],["49933.8","0.110"],["49936.4","0.080"],["49937.4","0.000"],["49938.1","0.000"],["49938.2","0.079"],["49944.1","0.017"],["49949.1","0.080"],["49950.2","0.008"],["49960.0","0.000"],["49964.3","0.000"],["49964.4","0.004"],["49964.5","0.003"],["49964.6","0.012"],["49974.0","0.000"],["49974.7","0.000"],["49974.8","0.000"]],"a":[["49986.6","0.000"],["50001.3","0.009"],["50001.4","0.000"],["50003.7","0.012"],["50004.4","0.005"],["50004.5","0.000"],["50025.3","0.000"],["50025.5","0.000"],["50025.7","0.000"],["50032.3","0.001"],["50032.7","0.000"],["50032.9","0.011"],["50036.5","0.000"],["50037.4","0.000"],["50038.6","0.000"],["50040.3","0.011"],["50043.2","0.001"],["50044.1","0.001"],["50046.2","0.011"],["50046.6","0.085"],["50066.1","0.052"],["50106.9","0.025"],["50115.3","0.000"],["50198.6","0.000"]]}}
1618677453.247783: {"stream":"dentusdt@kline_1m","data":{"e":"kline","E":1618677453096,"s":"DENTUSDT","k":{"t":1618677420000,"T":1618677479999,"s":"DENTUSDT","i":"1m","f":15787262,"L":15787386,"o":"0.012366","c":"0.012350","h":"0.012366","l":"0.012339","v":"2029896","n":125,"x":false,"q":"25074.085237","V":"1043801","Q":"12896.298724","B":"0"}}}
1618677453.2478771: {"stream":"dentusdt@bookTicker","data":{"e":"bookTicker","u":335340744627,"s":"DENTUSDT","b":"0.012350","B":"24514","a":"0.012361","A":"55630","T":1618677453092,"E":1618677453095}}
1618677453.249078: {"stream":"dentusdt@depth@100ms","data":{"e":"depthUpdate","E":1618677453107,"T":1618677453092,"s":"DENTUSDT","U":335340740654,"u":335340744627,"pu":335340738736,"b":[["0.012350","24514"]],"a":[["0.012380","109992"],["0.012382","944973"],["0.012403","446012"]]}}
1618677453.250898: {"stream":"ksmusdt@bookTicker","data":{"e":"bookTicker","u":335340745198,"s":"KSMUSDT","b":"459.239","B":"6.4","a":"459.496","A":"1.3","T":1618677453109,"E":1618677453114}}
1618677453.250968: {"stream":"ksmusdt@bookTicker","data":{"e":"bookTicker","u":335340745398,"s":"KSMUSDT","b":"459.239","B":"6.4","a":"459.304","A":"0.1","T":1618677453115,"E":1618677453119}}
1618677453.282445: {"stream":"ksmusdt@depth@100ms","data":{"e":"depthUpdate","E":1618677453142,"T":1618677453131,"s":"KSMUSDT","U":335340742252,"u":335340745767,"pu":335340741808,"b":[["454.844","1.4"],["457.006","15.0"],["457.253","0.0"],["458.061","0.0"],["458.958","1.6"],["458.966","0.5"],["459.229","1.0"]],"a":[["459.304","0.1"],["459.369","0.0"],["459.764","0.0"],["459.780","0.1"],["459.816","0.0"],["459.871","0.0"],["459.876","0.9"],["459.937","0.1"],["459.972","0.0"],["460.236","0.1"],["461.509","0.0"],["461.555","15.0"],["463.759","0.0"]]}}
1618677453.2850208: {"stream":"xmrusdt@depth@100ms","data":{"e":"depthUpdate","E":1618677453158,"T":1618677453119,"s":"XMRUSDT","U":335340743055,"u":335340745534,"pu":335340740972,"b":[["352.17","1.031"],["352.19","26.120"]],"a":[]}}
1618677453.287338: {"stream":"yfiusdt@depth@100ms","data":{"e":"depthUpdate","E":1618677453174,"T":1618677453149,"s":"YFIUSDT","U":335340743793,"u":335340746065,"pu":335340743034,"b":[["49535.2","0.083"],["49760.1","0.083"],["49877.9","0.000"],["49903.7","0.000"],["49932.1","0.000"],["49935.4","0.026"],["49938.0","0.000"],["49938.2","0.000"],["49941.1","0.000"],["49941.5","0.009"],["49943.0","0.000"],["49947.3","0.035"],["49949.2","0.022"],["49950.3","0.012"],["49952.4","0.009"],["49964.5","0.000"],["49964.7","0.003"]],"a":[["50001.0","0.003"],["50001.1","0.013"],["50001.2","0.000"],["50001.3","0.000"],["50004.4","0.011"],["50004.5","0.030"],["50025.7","0.001"],["50032.3","0.000"],["50036.5","0.001"],["50037.4","0.001"],["50043.2","0.000"],["50044.1","0.000"],["50249.4","0.000"]]}}
1618677453.3033118: {"stream":"dentusdt@aggTrade","data":{"e":"aggTrade","E":1618677453246,"a":8476402,"s":"DENTUSDT","p":"0.012350","q":"4800","f":15787386,"l":15787386,"T":1618677453092,"m":true}}
1618677453.306684: {"stream":"dentusdt@depth@100ms","data":{"e":"depthUpdate","E":1618677453249,"T":1618677453243,"s":"DENTUSDT","U":335340745942,"u":335340749557,"pu":335340744627,"b":[["0.012030","83722"],["0.012324","458499"]],"a":[["0.012381","157328"],["0.012386","49675"],["0.012389","82420"]]}}
1618677453.309964: {"stream":"ksmusdt@depth@100ms","data":{"e":"depthUpdate","E":1618677453253,"T":1618677453223,"s":"KSMUSDT","U":335340746039,"u":335340748430,"pu":335340745767,"b":[["454.756","0.0"],["454.802","15.0"],["457.006","0.0"],["457.053","15.0"],["457.288","0.0"],["459.215","1.0"]],"a":[]}}
1618677453.313055: {"stream":"ksmusdt@bookTicker","data":{"e":"bookTicker","u":335340749964,"s":"KSMUSDT","b":"459.239","B":"7.6","a":"459.304","A":"0.1","T":1618677453251,"E":1618677453255}}
1618677453.315649: {"stream":"ksmusdt@bookTicker","data":{"e":"bookTicker","u":335340750023,"s":"KSMUSDT","b":"459.239","B":"6.4","a":"459.304","A":"0.1","T":1618677453252,"E":1618677453257}}
1618677453.31575: {"stream":"xmrusdt@depth@100ms","data":{"e":"depthUpdate","E":1618677453258,"T":1618677453253,"s":"XMRUSDT","U":335340746136,"u":335340750066,"pu":335340745534,"b":[["348.21","200.000"],["348.84","7.653"],["349.69","7.088"],["350.32","48.784"],["350.43","200.570"],["351.60","0.073"],["351.77","1.423"],["352.19","28.620"],["352.20","4.873"],["352.34","0.000"]],"a":[["353.00","52.419"],["353.01","0.000"],["353.02","4.064"],["353.84","3.103"]]}}
1618677453.333369: {"stream":"yfiusdt@depth@100ms","data":{"e":"depthUpdate","E":1618677453274,"T":1618677453268,"s":"YFIUSDT","U":335340746496,"u":335340750746,"pu":335340746065,"b":[["49714.6","0.000"],["49735.3","0.001"],["49918.7","0.000"],["49950.4","0.009"],["49964.4","0.000"],["49964.7","0.000"],["49964.8","0.013"],["49964.9","0.003"]],"a":[["50000.9","0.003"],["50001.0","0.000"],["50001.1","0.000"],["50003.7","0.000"],["50004.1","0.012"],["50037.7","0.009"],["50042.3","0.000"],["50057.9","0.026"],["50066.1","0.000"],["50068.9","0.000"],["50074.0","0.001"],["50083.0","0.052"],["50106.9","0.000"],["50107.4","0.000"],["50113.7","0.000"],["50128.5","0.000"],["50134.6","0.003"],["50165.0","0.046"],["50219.7","0.000"],["50240.4","0.023"]]}}
1618677453.4112499: {"stream":"ksmusdt@depth@100ms","data":{"e":"depthUpdate","E":1618677453353,"T":1618677453338,"s":"KSMUSDT","U":335340749920,"u":335340754013,"pu":335340748430,"b":[["454.802","30.0"],["457.053","30.0"],["457.341","0.0"],["458.967","0.2"],["459.132","0.0"],["459.162","0.0"],["459.163","0.0"],["459.194","0.0"],["459.239","6.4"]],"a":[["461.555","30.0"],["463.806","30.0"]]}}
1618677453.427281: {"stream":"xmrusdt@depth@100ms","data":{"e":"depthUpdate","E":1618677453367,"T":1618677453357,"s":"XMRUSDT","U":335340750485,"u":335340754999,"pu":335340750066,"b":[["348.21","0.000"],["349.80","7.516"],["350.43","0.570"],["351.89","0.000"],["352.05","3.488"],["352.19","26.120"],["352.21","2.500"],["352.30","0.000"]],"a":[["353.72","1.900"],["353.88","0.619"],["354.55","0.000"],["355.49","1.336"]]}}
1618677453.439281: {"stream":"yfiusdt@depth@100ms","data":{"e":"depthUpdate","E":1618677453377,"T":1618677453373,"s":"YFIUSDT","U":335340750949,"u":335340755702,"pu":335340750746,"b":[["49716.7","0.013"],["49862.6","0.050"],["49924.1","0.000"],["49924.2","0.000"],["49927.5","0.000"],["49927.6","0.000"],["49928.2","0.000"],["49928.3","0.000"],["49936.5","0.276"],["49949.0","0.000"],["49952.5","0.012"],["49964.6","0.000"],["49964.8","0.000"],["49964.9","0.000"],["49965.0","0.000"],["49965.1","0.011"]],"a":[["50004.1","0.000"],["50079.8","0.000"],["50082.9","0.009"],["50099.9","0.050"]]}}
1618677453.530713: {"stream":"ksmusdt@depth@100ms","data":{"e":"depthUpdate","E":1618677453473,"T":1618677453456,"s":"KSMUSDT","U":335340755512,"u":335340758849,"pu":335340754013,"b":[["458.862","0.7"],["458.967","0.0"],["459.074","0.0"],["459.132","0.2"],["459.163","1.2"],["459.215","0.0"],["459.229","0.0"]],"a":[]}}
1618677453.530872: {"stream":"xmrusdt@depth@100ms","data":{"e":"depthUpdate","E":1618677453473,"T":1618677453455,"s":"XMRUSDT","U":335340755514,"u":335340758837,"pu":335340754999,"b":[["348.78","0.000"],["349.41","0.291"],["349.80","207.516"],["350.43","200.570"],["351.29","0.998"],["352.09","0.000"],["352.21","0.000"],["352.26","1.033"],["352.30","2.500"]],"a":[["352.58","0.000"],["352.60","1.400"],["352.66","4.350"],["352.94","0.306"],["353.65","3.300"],["354.60","200.028"],["355.41","0.415"]]}}
1618677453.536884: {"stream":"yfiusdt@depth@100ms","data":{"e":"depthUpdate","E":1618677453478,"T":1618677453448,"s":"YFIUSDT","U":335340755760,"u":335340758521,"pu":335340755702,"b":[["49935.4","0.033"],["49938.7","0.007"],["49939.4","0.007"],["49965.1","0.000"],["49965.2","0.000"],["49965.3","0.010"]],"a":[["50031.5","0.000"]]}}
1618677453.539196: {"stream":"ksmusdt@bookTicker","data":{"e":"bookTicker","u":335340759794,"s":"KSMUSDT","b":"459.249","B":"0.7","a":"459.304","A":"0.1","T":1618677453477,"E":1618677453481}}
1618677453.544517: {"stream":"dentusdt@depth@100ms","data":{"e":"depthUpdate","E":1618677453488,"T":1618677453478,"s":"DENTUSDT","U":335340756063,"u":335340759820,"pu":335340749557,"b":[["0.011843","253783"],["0.012292","6742"],["0.012295","659982"],["0.012336","11778"],["0.012338","0"],["0.012347","98561"]],"a":[["0.012380","58734"],["0.012388","631601"],["0.012687","591669"]]}}
1618677453.548734: {"stream":"ksmusdt@bookTicker","data":{"e":"bookTicker","u":335340760275,"s":"KSMUSDT","b":"459.249","B":"0.7","a":"459.496","A":"1.3","T":1618677453489,"E":1618677453492}}
1618677453.5508978: {"stream":"ksmusdt@kline_1m","data":{"e":"kline","E":1618677453493,"s":"KSMUSDT","k":{"t":1618677420000,"T":1618677479999,"s":"KSMUSDT","i":"1m","f":25426460,"L":25426560,"o":"459.607","c":"459.304","h":"459.671","l":"458.391","v":"100.6","n":101,"x":false,"q":"46180.1208","V":"51.4","Q":"23604.9943","B":"0"}}}
1618677453.5693061: {"stream":"ksmusdt@bookTicker","data":{"e":"bookTicker","u":335340760910,"s":"KSMUSDT","b":"459.239","B":"6.4","a":"459.496","A":"1.3","T":1618677453507,"E":1618677453512}}
1618677453.569407: {"stream":"ksmusdt@bookTicker","data":{"e":"bookTicker","u":335340760915,"s":"KSMUSDT","b":"459.239","B":"6.4","a":"459.539","A":"0.1","T":1618677453507,"E":1618677453512}}
1618677453.572692: {"stream":"yfiusdt@aggTrade","data":{"e":"aggTrade","E":1618677453514,"a":52599690,"s":"YFIUSDT","p":"49986.7","q":"0.001","f":64902168,"l":64902168,"T":1618677453509,"m":false}}
1618677453.5727959: {"stream":"yfiusdt@kline_1m","data":{"e":"kline","E":1618677453514,"s":"YFIUSDT","k":{"t":1618677420000,"T":1618677479999,"s":"YFIUSDT","i":"1m","f":64902095,"L":64902168,"o":"50010.8","c":"49986.7","h":"50044.2","l":"49950.6","v":"0.859","n":74,"x":false,"q":"42949.6209","V":"0.554","Q":"27700.2025","B":"0"}}}
1618677453.596145: {"stream":"yfiusdt@bookTicker","data":{"e":"bookTicker","u":335340760975,"s":"YFIUSDT","b":"49981.0","B":"0.006","a":"50000.9","A":"0.002","T":1618677453509,"E":1618677453514}}
1618677453.5962508: {"stream":"ksmusdt@bookTicker","data":{"e":"bookTicker","u":335340761327,"s":"KSMUSDT","b":"459.253","B":"1.2","a":"459.539","A":"0.1","T":1618677453520,"E":1618677453525}}
1618677453.5962958: {"stream":"yfiusdt@bookTicker","data":{"e":"bookTicker","u":335340761549,"s":"YFIUSDT","b":"49981.0","B":"0.006","a":"49998.5","A":"0.055","T":1618677453527,"E":1618677453530}}
1618677453.596352: {"stream":"ksmusdt@bookTicker","data":{"e":"bookTicker","u":335340761573,"s":"KSMUSDT","b":"459.253","B":"1.2","a":"459.487","A":"6.4","T":1618677453528,"E":1618677453530}}
1618677453.596383: {"stream":"yfiusdt@bookTicker","data":{"e":"bookTicker","u":335340761652,"s":"YFIUSDT","b":"49981.0","B":"0.006","a":"50000.9","A":"0.002","T":1618677453531,"E":1618677453534}}
1618677453.5985038: {"stream":"yfiusdt@bookTicker","data":{"e":"bookTicker","u":335340761771,"s":"YFIUSDT","b":"49982.8","B":"0.055","a":"50000.9","A":"0.002","T":1618677453535,"E":1618677453538}}
1618677453.60264: {"stream":"ksmusdt@bookTicker","data":{"e":"bookTicker","u":335340761879,"s":"KSMUSDT","b":"459.239","B":"6.4","a":"459.487","A":"6.4","T":1618677453538,"E":1618677453542}}
1618677453.618152: {"stream":"yfiusdt@bookTicker","data":{"e":"bookTicker","u":335340762341,"s":"YFIUSDT","b":"49982.9","B":"0.003","a":"50000.9","A":"0.002","T":1618677453553,"E":1618677453557}}
1618677453.63294: {"stream":"yfiusdt@bookTicker","data":{"e":"bookTicker","u":335340762681,"s":"YFIUSDT","b":"49983.0","B":"0.025","a":"50000.9","A":"0.002","T":1618677453564,"E":1618677453568}}
1618677453.6380942: {"stream":"ksmusdt@depth@100ms","data":{"e":"depthUpdate","E":1618677453573,"T":1618677453568,"s":"KSMUSDT","U":335340759489,"u":335340762767,"pu":335340758849,"b":[["457.756","0.0"],["457.761","1.6"],["458.100","0.0"],["458.105","1.6"],["458.229","1.1"],["458.259","0.0"],["458.289","0.4"],["458.603","0.0"],["458.746","0.0"],["458.751","0.0"],["458.855","0.0"],["458.910","0.1"],["458.955","0.0"],["458.976","1.5"],["458.998","0.2"],["459.132","0.0"],["459.162","1.2"],["459.163","0.0"],["459.173","0.7"],["459.249","0.0"],["459.253","0.0"]],"a":[["459.304","0.0"],["459.487","6.4"],["459.496","0.0"],["459.560","1.2"],["459.562","0.0"],["459.580","2.3"],["459.657","0.0"],["459.748","0.1"],["459.793","12.1"],["459.794","0.0"],["459.848","0.0"],["460.144","0.0"],["460.168","0.0"],["460.169","0.0"],["460.436","1.0"],["461.070","0.8"]]}}
1618677453.642584: {"stream":"yfiusdt@depth@100ms","data":{"e":"depthUpdate","E":1618677453581,"T":1618677453566,"s":"YFIUSDT","U":335340759768,"u":335340762719,"pu":335340758521,"b":[["49895.1","0.100"],["49925.4","0.000"],["49929.6","0.000"],["49938.0","0.110"],["49942.2","0.110"],["49950.1","0.000"],["49951.6","0.087"],["49965.3","0.000"],["49965.4","0.000"],["49965.5","0.007"],["49982.8","0.055"],["49982.9","0.003"],["49983.0","0.025"],["50486.6","0.000"]],"a":[["49986.7","0.000"],["49998.5","0.000"],["50000.9","0.002"],["50004.5","0.000"],["50004.6","0.000"],["50007.2","0.013"],["50025.7","0.000"],["50032.3","0.001"],["50032.9","0.010"],["50036.5","0.000"],["50037.4","0.000"],["50040.3","0.010"],["50043.2","0.001"],["50044.1","0.001"],["50046.2","0.010"],["50086.4","0.002"],["50133.0","0.100"]]}}
1618677453.657418: {"stream":"dentusdt@depth@100ms","data":{"e":"depthUpdate","E":1618677453594,"T":1618677453565,"s":"DENTUSDT","U":335340760307,"u":335340762689,"pu":335340759820,"b":[],"a":[["0.012364","41020"],["0.012380","36722"],["0.012382","1029803"],["0.012424","40902"]]}}
1618677453.663701: {"stream":"yfiusdt@bookTicker","data":{"e":"bookTicker","u":335340763679,"s":"YFIUSDT","b":"49983.0","B":"0.025","a":"50006.7","A":"0.001","T":1618677453595,"E":1618677453599}}
1618677453.6638021: {"stream":"yfiusdt@bookTicker","data":{"e":"bookTicker","u":335340763702,"s":"YFIUSDT","b":"49983.1","B":"0.003","a":"50006.7","A":"0.001","T":1618677453595,"E":1618677453599}}
1618677453.676241: {"stream":"yfiusdt@bookTicker","data":{"e":"bookTicker","u":335340764140,"s":"YFIUSDT","b":"49983.1","B":"0.010","a":"50006.7","A":"0.001","T":1618677453610,"E":1618677453614}}
1618677453.676342: {"stream":"yfiusdt@bookTicker","data":{"e":"bookTicker","u":335340764166,"s":"YFIUSDT","b":"49983.2","B":"0.003","a":"50006.7","A":"0.001","T":1618677453610,"E":1618677453614}}
1618677453.696258: {"stream":"yfiusdt@bookTicker","data":{"e":"bookTicker","u":335340764713,"s":"YFIUSDT","b":"49983.2","B":"0.006","a":"50006.7","A":"0.001","T":1618677453632,"E":1618677453636}}
1618677453.6965709: {"stream":"yfiusdt@bookTicker","data":{"e":"bookTicker","u":335340764769,"s":"YFIUSDT","b":"49983.2","B":"0.010","a":"50006.7","A":"0.001","T":1618677453634,"E":1618677453638}}
1618677453.700999: {"stream":"yfiusdt@bookTicker","data":{"e":"bookTicker","u":335340764809,"s":"YFIUSDT","b":"49983.2","B":"0.010","a":"50004.3","A":"0.055","T":1618677453635,"E":1618677453640}}
1618677453.7089128: {"stream":"ksmusdt@aggTrade","data":{"e":"aggTrade","E":1618677453643,"a":21396967,"s":"KSMUSDT","p":"459.304","q":"0.1","f":25426560,"l":25426560,"T":1618677453489,"m":false}}
1618677453.715196: {"stream":"yfiusdt@bookTicker","data":{"e":"bookTicker","u":335340765142,"s":"YFIUSDT","b":"49983.2","B":"0.007","a":"50004.3","A":"0.055","T":1618677453645,"E":1618677453649}}
1618677453.715295: {"stream":"yfiusdt@bookTicker","data":{"e":"bookTicker","u":335340765145,"s":"YFIUSDT","b":"49983.2","B":"0.003","a":"50004.3","A":"0.055","T":1618677453645,"E":1618677453649}}
1618677453.722104: {"stream":"xmrusdt@depth@100ms","data":{"e":"depthUpdate","E":1618677453661,"T":1618677453622,"s":"XMRUSDT","U":335340762502,"u":335340764488,"pu":335340758837,"b":[["348.93","0.299"],["349.56","0.000"],["349.79","204.559"],["349.80","7.516"],["350.42","200.000"],["350.43","0.570"]],"a":[["353.25","9.366"]]}}
1618677453.7264059: {"stream":"yfiusdt@aggTrade","data":{"e":"aggTrade","E":1618677453665,"a":52599691,"s":"YFIUSDT","p":"50000.9","q":"0.001","f":64902169,"l":64902169,"T":1618677453509,"m":false}}
1618677453.731966: {"stream":"ksmusdt@depth@100ms","data":{"e":"depthUpdate","E":1618677453673,"T":1618677453664,"s":"KSMUSDT","U":335340762807,"u":335340765778,"pu":335340762767,"b":[["453.708","1.3"],["458.289","0.0"],["458.378","2.1"],["458.609","0.0"],["458.855","0.7"],["458.976","0.0"],["458.977","0.2"],["458.998","0.0"],["459.173","0.0"]],"a":[["459.557","1.2"],["459.559","1.4"],["459.560","0.0"],["459.561","0.0"],["459.794","17.9"],["459.882","13.6"],["460.270","2.1"],["460.313","0.0"],["460.354","0.0"],["460.436","0.0"],["460.490","0.0"],["460.550","8.0"],["460.747","0.0"]]}}
1618677453.750245: {"stream":"yfiusdt@depth@100ms","data":{"e":"depthUpdate","E":1618677453692,"T":1618677453680,"s":"YFIUSDT","U":335340763482,"u":335340766341,"pu":335340762719,"b":[["49818.9","0.000"],["49844.2","0.107"],["49895.1","0.000"],["49922.2","0.075"],["49936.5","0.000"],["49950.2","0.000"],["49950.7","0.070"],["49952.5","0.000"],["49965.5","0.000"],["49975.0","0.016"],["49982.9","0.000"],["49983.1","0.000"],["49983.2","0.003"]],"a":[["50000.9","0.000"],["50004.3","0.055"],["50004.4","0.000"],["50007.2","0.000"],["50008.6","0.014"],["50011.1","0.000"],["50023.7","0.060"],["50031.8","0.000"],["50032.9","0.000"],["50040.3","0.000"],["50045.9","0.002"],["50046.2","0.000"],["50046.8","0.004"],["50049.6","0.000"],["50053.4","0.002"],["50059.2","0.012"],["50060.4","0.072"],["50080.7","0.000"],["50082.9","0.000"],["50099.9","0.000"],["50107.9","0.009"],["50108.6","0.078"],["50118.4","0.000"],["50143.8","0.100"],["50213.8","0.013"]]}}
1618677453.756129: {"stream":"dentusdt@depth@100ms","data":{"e":"depthUpdate","E":1618677453699,"T":1618677453627,"s":"DENTUSDT","U":335340763699,"u":335340764605,"pu":335340762689,"b":[],"a":[["0.012380","71278"],["0.012383","49448"],["0.012417","121173"]]}}
1618677453.83467: {"stream":"xmrusdt@depth@100ms","data":{"e":"depthUpdate","E":1618677453776,"T":1618677453771,"s":"XMRUSDT","U":335340765968,"u":335340769356,"pu":335340764488,"b":[["344.29","43.797"],["348.44","200.000"],["349.79","4.559"],["350.42","0.000"],["351.68","14.795"],["351.82","2.191"]],"a":[["353.00","36.957"],["353.04","15.462"],["354.60","0.028"],["356.57","201.682"],["359.72","55.574"]]}}
1618677453.838031: {"stream":"ksmusdt@depth@100ms","data":{"e":"depthUpdate","E":1618677453778,"T":1618677453739,"s":"KSMUSDT","U":335340766062,"u":335340768250,"pu":335340765778,"b":[["457.536","0.9"],["457.803","0.0"],["458.021","2.0"],["458.204","1.1"],["458.229","0.0"],["458.967","0.2"],["458.977","0.0"]],"a":[["459.556","1.4"],["459.557","0.0"],["459.559","0.0"],["459.792","17.9"],["459.794","0.0"],["460.267","0.0"],["460.436","1.0"],["460.557","6.1"],["460.606","0.0"],["460.702","8.3"]]}}
1618677453.8568199: {"stream":"yfiusdt@depth@100ms","data":{"e":"depthUpdate","E":1618677453796,"T":1618677453785,"s":"YFIUSDT","U":335340766873,"u":335340769836,"pu":335340766341,"b":[["49862.6","0.000"],["49951.7","0.168"]],"a":[["50006.5","0.013"],["50008.6","0.000"],["50025.7","0.001"],["50032.3","0.000"],["50036.5","0.001"],["50037.4","0.001"],["50043.2","0.000"],["50044.1","0.000"],["50044.7","0.000"],["50078.7","0.000"],["50079.7","0.000"],["50083.0","0.000"],["50143.7","0.020"],["50261.9","0.000"],["50274.9","0.200"]]}}
1618677453.863082: {"stream":"ksmusdt@bookTicker","data":{"e":"bookTicker","u":335340770070,"s":"KSMUSDT","b":"459.239","B":"6.4","a":"459.363","A":"0.1","T":1618677453794,"E":1618677453798}}
1618677453.866483: {"stream":"dentusdt@depth@100ms","data":{"e":"depthUpdate","E":1618677453803,"T":1618677453699,"s":"DENTUSDT","U":335340767045,"u":335340767045,"pu":335340764605,"b":[],"a":[["0.012420","615331"]]}}
1618677453.8950431: {"stream":"ksmusdt@bookTicker","data":{"e":"bookTicker","u":335340771175,"s":"KSMUSDT","b":"459.162","B":"1.2","a":"459.363","A":"0.1","T":1618677453830,"E":1618677453834}}
1618677453.9074938: {"stream":"ksmusdt@bookTicker","data":{"e":"bookTicker","u":335340771515,"s":"KSMUSDT","b":"459.131","B":"1.5","a":"459.363","A":"0.1","T":1618677453842,"E":1618677453846}}
1618677453.918795: {"stream":"ksmusdt@bookTicker","data":{"e":"bookTicker","u":335340771707,"s":"KSMUSDT","b":"459.107","B":"1.2","a":"459.363","A":"0.1","T":1618677453851,"E":1618677453856}}
1618677453.930384: {"stream":"ksmusdt@bookTicker","data":{"e":"bookTicker","u":335340772032,"s":"KSMUSDT","b":"459.076","B":"0.5","a":"459.363","A":"0.1","T":1618677453863,"E":1618677453867}}
1618677453.930484: {"stream":"ksmusdt@bookTicker","data":{"e":"bookTicker","u":335340772037,"s":"KSMUSDT","b":"459.079","B":"1.2","a":"459.363","A":"0.1","T":1618677453864,"E":1618677453867}}
1618677453.938625: {"stream":"xmrusdt@depth@100ms","data":{"e":"depthUpdate","E":1618677453876,"T":1618677453820,"s":"XMRUSDT","U":335340769408,"u":335340770892,"pu":335340769356,"b":[["347.81","0.000"],["348.44","0.000"],["349.78","200.000"],["350.41","200.408"]],"a":[["354.53","200.000"],["356.57","1.682"]]}}
1618677453.955276: {"stream":"ksmusdt@depth@100ms","data":{"e":"depthUpdate","E":1618677453891,"T":1618677453882,"s":"KSMUSDT","U":335340769854,"u":335340772550,"pu":335340768250,"b":[["458.204","0.0"],["458.540","0.0"],["458.637","0.0"],["458.843","6.7"],["458.863","1.1"],["458.900","0.5"],["458.957","0.0"],["458.958","0.0"],["459.076","0.0"],["459.079","1.2"],["459.107","0.0"],["459.131","0.0"],["459.162","0.0"],["459.239","0.0"]],"a":[["459.363","0.1"],["459.486","1.0"],["459.508","1.2"],["459.556","0.0"],["459.579","1.4"],["459.743","7.3"],["460.378","5.8"],["460.436","0.0"],["460.980","0.0"]]}}
1618677453.9709: {"stream":"yfiusdt@depth@100ms","data":{"e":"depthUpdate","E":1618677453909,"T":1618677453879,"s":"YFIUSDT","U":335340770501,"u":335340772450,"pu":335340769836,"b":[["49925.4","0.110"],["49929.6","0.110"],["49938.0","0.000"],["49942.2","0.000"]],"a":[["50025.7","0.000"],["50036.5","0.000"],["50037.4","0.000"],["50037.7","0.000"],["50040.0","0.017"],["50041.1","0.018"],["50045.0","0.017"],["50046.8","0.000"],["50052.0","0.027"],["50052.9","0.027"],["50057.4","0.046"],["50059.6","0.021"],["50098.8","0.021"],["50128.5","0.025"],["50165.0","0.025"]]}}
1618677453.976736: {"stream":"ksmusdt@bookTicker","data":{"e":"bookTicker","u":335340773204,"s":"KSMUSDT","b":"458.997","B":"0.1","a":"459.363","A":"0.1","T":1618677453907,"E":1618677453912}}
1618677453.976867: {"stream":"ksmusdt@bookTicker","data":{"e":"bookTicker","u":335340773225,"s":"KSMUSDT","b":"459.028","B":"1.2","a":"459.363","A":"0.1","T":1618677453908,"E":1618677453912}}
1618677454.012526: {"stream":"ksmusdt@bookTicker","data":{"e":"bookTicker","u":335340774382,"s":"KSMUSDT","b":"459.028","B":"1.2","a":"459.341","A":"6.4","T":1618677453946,"E":1618677453950}}
1618677454.021523: {"stream":"ksmusdt@bookTicker","data":{"e":"bookTicker","u":335340774742,"s":"KSMUSDT","b":"458.997","B":"0.1","a":"459.341","A":"6.4","T":1618677453958,"E":1618677453963}}
1618677454.02613: {"stream":"ksmusdt@bookTicker","data":{"e":"bookTicker","u":335340774765,"s":"KSMUSDT","b":"458.997","B":"0.1","a":"459.328","A":"1.2","T":1618677453959,"E":1618677453965}}
1618677454.0440671: {"stream":"dentusdt@depth@100ms","data":{"e":"depthUpdate","E":1618677453985,"T":1618677453918,"s":"DENTUSDT","U":335340772498,"u":335340773506,"pu":335340767045,"b":[],"a":[["0.012446","0"],["0.012600","140694"]]}}
1618677454.067554: {"stream":"ksmusdt@depth@100ms","data":{"e":"depthUpdate","E":1618677454005,"T":1618677453995,"s":"KSMUSDT","U":335340773042,"u":335340775915,"pu":335340772550,"b":[["457.320","0.0"],["457.438","1.1"],["457.669","10.2"],["458.126","0.5"],["458.215","6.2"],["458.314","0.0"],["458.439","0.0"],["458.605","0.0"],["458.733","1.5"],["458.786","0.0"],["458.821","0.0"],["458.863","0.0"],["459.028","0.0"],["459.079","0.0"]],"a":[["459.328","1.2"],["459.341","6.4"],["459.455","0.0"],["459.485","1.4"],["459.486","0.0"],["459.508","0.0"],["459.579","0.0"],["459.764","0.9"],["459.876","0.0"],["459.931","2.2"],["460.245","2.4"],["460.372","1.0"],["460.593","0.0"],["460.838","1.1"]]}}
1618677454.0738401: {"stream":"yfiusdt@depth@100ms","data":{"e":"depthUpdate","E":1618677454010,"T":1618677453985,"s":"YFIUSDT","U":335340773186,"u":335340775669,"pu":335340772450,"b":[["49771.3","0.029"],["49833.7","0.094"],["49898.4","0.000"],["49919.9","0.010"]],"a":[["50098.7","0.010"],["50107.3","0.073"],["50110.7","0.000"],["50128.5","0.000"],["50147.8","0.000"],["50180.1","0.023"],["50266.8","0.200"],["50280.1","0.202"]]}}
1618677454.093098: {"stream":"yfiusdt@bookTicker","data":{"e":"bookTicker","u":335340777204,"s":"YFIUSDT","b":"49983.3","B":"0.020","a":"50004.3","A":"0.055","T":1618677454026,"E":1618677454030}}
1618677454.093198: {"stream":"yfiusdt@bookTicker","data":{"e":"bookTicker","u":335340777211,"s":"YFIUSDT","b":"49983.3","B":"0.020","a":"50004.2","A":"0.018","T":1618677454026,"E":1618677454030}}
1618677454.098327: {"stream":"yfiusdt@kline_1m","data":{"e":"kline","E":1618677454036,"s":"YFIUSDT","k":{"t":1618677420000,"T":1618677479999,"s":"YFIUSDT","i":"1m","f":64902095,"L":64902170,"o":"50010.8","c":"50000.4","h":"50044.2","l":"49950.6","v":"0.940","n":76,"x":false,"q":"46999.6538","V":"0.635","Q":"31750.2354","B":"0"}}}
1618677454.098451: {"stream":"yfiusdt@bookTicker","data":{"e":"bookTicker","u":335340777438,"s":"YFIUSDT","b":"49983.3","B":"0.020","a":"50000.4","A":"0.117","T":1618677454032,"E":1618677454036}}
1618677454.0985: {"stream":"yfiusdt@bookTicker","data":{"e":"bookTicker","u":335340777443,"s":"YFIUSDT","b":"49983.3","B":"0.020","a":"50000.4","A":"0.037","T":1618677454032,"E":1618677454036}}
1618677454.101701: {"stream":"yfiusdt@bookTicker","data":{"e":"bookTicker","u":335340777530,"s":"YFIUSDT","b":"49983.3","B":"0.020","a":"50004.2","A":"0.018","T":1618677454035,"E":1618677454040}}
1618677454.11317: {"stream":"yfiusdt@bookTicker","data":{"e":"bookTicker","u":335340777861,"s":"YFIUSDT","b":"49983.3","B":"0.020","a":"50000.3","A":"0.005","T":1618677454044,"E":1618677454049}}
1618677454.113269: {"stream":"yfiusdt@bookTicker","data":{"e":"bookTicker","u":335340777942,"s":"YFIUSDT","b":"49983.3","B":"0.020","a":"50004.2","A":"0.018","T":1618677454046,"E":1618677454051}}
1618677454.29053: {"stream":"yfiusdt@bookTicker","data":{"e":"bookTicker","u":335340778183,"s":"YFIUSDT","b":"49983.3","B":"0.020","a":"50004.3","A":"0.055","T":1618677454052,"E":1618677454057}}
1618677454.2987578: {"stream":"yfiusdt@bookTicker","data":{"e":"bookTicker","u":335340778318,"s":"YFIUSDT","b":"49985.6","B":"0.055","a":"50004.3","A":"0.055","T":1618677454055,"E":1618677454060}}
1618677454.298861: {"stream":"yfiusdt@bookTicker","data":{"e":"bookTicker","u":335340778382,"s":"YFIUSDT","b":"49985.6","B":"0.055","a":"50004.2","A":"0.013","T":1618677454056,"E":1618677454060}}
1618677454.2989042: {"stream":"yfiusdt@bookTicker","data":{"e":"bookTicker","u":335340778463,"s":"YFIUSDT","b":"49985.6","B":"0.055","a":"50004.3","A":"0.055","T":1618677454058,"E":1618677454062}}
