1626992757.279488: {"stream":"sushiusdt@bookTicker","data":{"e":"bookTicker","u":600859972631,"s":"SUSHIUSDT","b":"7.6150","B":"25","a":"7.6180","A":"26","T":1626992757230,"E":1626992757232}}
1626992757.2795389: {"stream":"sushiusdt@kline_1m","data":{"e":"kline","E":1626992757232,"s":"SUSHIUSDT","k":{"t":1626992700000,"T":1626992759999,"s":"SUSHIUSDT","i":"1m","f":126902874,"L":126902982,"o":"7.6080","c":"7.6150","h":"7.6160","l":"7.6070","v":"2976","n":109,"x":false,"q":"22654.9420","V":"1876","Q":"14281.8640","B":"0"}}}
1626992757.2876642: {"stream":"ctkusdt@depth@100ms","data":{"e":"depthUpdate","E":1626992757240,"T":1626992757233,"s":"CTKUSDT","U":600859965141,"u":600859972880,"pu":600859964432,"b":[["1.00200","16220"],["1.00400","5024"],["1.00500","33907"],["1.00800","15269"],["1.00900","13330"],["1.01000","83239"],["1.01100","10341"],["1.01500","0"]],"a":[["1.01000","0"],["1.01200","113"],["1.01400","11397"],["1.01500","16635"],["1.02200","4939"],["1.02300","3369"]]}}
1626992757.2920341: {"stream":"keepusdt@depth@100ms","data":{"e":"depthUpdate","E":1626992757246,"T":1626992757243,"s":"KEEPUSDT","U":600859965217,"u":600859973812,"pu":600859964514,"b":[["0.2433","31696"],["0.2436","5495"],["0.2449","15366"],["0.2450","94072"],["0.2452","7407"],["0.2453","11178"],["0.2457","9918"],["0.2459","5077"]],"a":[["0.2471","14846"]]}}
1626992757.292244: {"stream":"sushiusdt@depth@100ms","data":{"e":"depthUpdate","E":1626992757246,"T":1626992757239,"s":"SUSHIUSDT","U":600859965219,"u":600859973417,"pu":600859965112,"b":[["7.5340","9335"],["7.5470","2482"],["7.5510","864"],["7.5550","177"],["7.5600","3810"],["7.5800","2942"],["7.5820","1893"],["7.5830","2817"],["7.5870","2833"],["7.5910","2354"],["7.5940","333"],["7.5950","1862"],["7.5970","2308"],["7.6030","608"],["7.6040","2103"],["7.6060","1248"],["7.6110","1765"],["7.6140","73"],["7.6150","25"]],"a":[["7.6180","26"],["7.6190","405"],["7.6210","2046"],["7.6220","2535"],["7.6230","825"],["7.6240","863"],["7.6260","1576"],["7.6270","2130"],["7.6280","2526"],["7.6290","2371"],["7.6300","1173"],["7.6310","2414"],["7.6320","2659"],["7.6340","2345"],["7.6350","2592"],["7.6370","2073"],["7.6390","1151"],["7.6400","1183"],["7.6420","912"],["7.6430","3223"],["7.6440","6262"],["7.6450","2628"],["7.6460","405"],["7.6530","897"],["7.6560","395"],["7.6570","389"],["7.6600","8756"],["7.6620","477"],["7.6800","3747"]]}}
1626992757.295924: {"stream":"akrousdt@bookTicker","data":{"e":"bookTicker","u":600859974067,"s":"AKROUSDT","b":"0.01732","B":"92000","a":"0.01733","A":"22785","T":1626992757246,"E":1626992757248}}
1626992757.2964852: {"stream":"ctkusdt@bookTicker","data":{"e":"bookTicker","u":600859974331,"s":"CTKUSDT","b":"1.01100","B":"10408","a":"1.01200","A":"113","T":1626992757249,"E":1626992757252}}
1626992757.305619: {"stream":"akrousdt@bookTicker","data":{"e":"bookTicker","u":600859974581,"s":"AKROUSDT","b":"0.01732","B":"92000","a":"0.01733","A":"48234","T":1626992757252,"E":1626992757255}}
1626992757.3096461: {"stream":"sushiusdt@bookTicker","data":{"e":"bookTicker","u":600859975058,"s":"SUSHIUSDT","b":"7.6150","B":"25","a":"7.6180","A":"4","T":1626992757257,"E":1626992757260}}
1626992757.323593: {"stream":"akrousdt@bookTicker","data":{"e":"bookTicker","u":600859976706,"s":"AKROUSDT","b":"0.01732","B":"101762","a":"0.01733","A":"48234","T":1626992757275,"E":1626992757277}}
1626992757.3583941: {"stream":"akrousdt@depth@100ms","data":{"e":"depthUpdate","E":1626992757309,"T":1626992757306,"s":"AKROUSDT","U":600859970625,"u":600859979805,"pu":600859970114,"b":[["0.01709","387826"],["0.01712","1340303"],["0.01714","1443939"],["0.01716","307545"],["0.01717","2923728"],["0.01720","472286"],["0.01721","500493"],["0.01722","437102"],["0.01723","397436"],["0.01724","355364"],["0.01725","829661"],["0.01727","795160"],["0.01728","763595"],["0.01729","446295"],["0.01730","158562"],["0.01731","202697"],["0.01732","101762"]],"a":[["0.01733","48234"],["0.01734","107195"],["0.01735","341203"],["0.01737","345943"],["0.01738","504430"],["0.01739","805699"],["0.01740","251846"],["0.01741","324416"],["0.01744","148710"]]}}
1626992757.387946: {"stream":"ctkusdt@depth@100ms","data":{"e":"depthUpdate","E":1626992757342,"T":1626992757340,"s":"CTKUSDT","U":600859973430,"u":600859983227,"pu":600859972880,"b":[["1.00400","5143"],["1.00600","9140"],["1.00700","8302"],["1.01100","10408"]],"a":[["1.01300","14687"],["1.01500","17251"],["1.01600","19049"],["1.01700","9400"],["1.01800","8049"],["1.03300","4772"],["1.04100","6983"],["1.31400","1236"]]}}
1626992757.3959968: {"stream":"keepusdt@depth@100ms","data":{"e":"depthUpdate","E":1626992757348,"T":1626992757333,"s":"KEEPUSDT","U":600859973992,"u":600859982575,"pu":600859973812,"b":[["0.2431","24072"],["0.2434","20094"],["0.2451","15363"],["0.2460","339"]],"a":[["0.2470","8046"],["0.2473","22777"]]}}
1626992757.396179: {"stream":"sushiusdt@depth@100ms","data":{"e":"depthUpdate","E":1626992757348,"T":1626992757338,"s":"SUSHIUSDT","U":600859973941,"u":600859983097,"pu":600859973417,"b":[["7.4550","2371"],["7.5340","9269"],["7.5380","1287"],["7.5470","2157"],["7.5510","1268"],["7.5610","1257"],["7.5620","2081"],["7.5700","268"],["7.5730","3638"],["7.5750","3456"],["7.5780","394"],["7.5800","2767"],["7.5830","3307"],["7.5840","2995"],["7.5880","1564"],["7.5950","1047"],["7.5960","1634"],["7.5970","2464"],["7.5980","1304"],["7.6000","393"],["7.6010","1194"],["7.6020","742"],["7.6040","2077"],["7.6060","2235"],["7.6070","750"],["7.6080","1165"],["7.6090","569"],["7.6100","469"],["7.6110","1687"],["7.6120","684"],["7.6130","205"],["7.6140","74"]],"a":[["7.6180","4"],["7.6190","273"],["7.6200","943"],["7.6210","1341"],["7.6220","2663"],["7.6230","825"],["7.6240","889"],["7.6250","1366"],["7.6270","1994"],["7.6280","2656"],["7.6290","2534"],["7.6300","418"],["7.6310","2442"],["7.6320","2726"],["7.6340","2276"],["7.6370","2434"],["7.6390","987"],["7.6400","1073"],["7.6410","1103"],["7.6430","3379"],["7.6470","2623"],["7.6530","786"],["7.6550","1288"],["7.6590","517"],["7.6710","1137"],["7.6790","69"],["7.7050","980"],["7.7160","4"],["7.7320","1"]]}}
1626992757.4008179: {"stream":"sushiusdt@bookTicker","data":{"e":"bookTicker","u":600859984343,"s":"SUSHIUSDT","b":"7.6160","B":"8","a":"7.6180","A":"4","T":1626992757352,"E":1626992757354}}
1626992757.4280891: {"stream":"sushiusdt@aggTrade","data":{"e":"aggTrade","E":1626992757383,"a":87353254,"s":"SUSHIUSDT","p":"7.6150","q":"6","f":126902982,"l":126902982,"T":1626992757230,"m":true}}
1626992757.428191: {"stream":"ctkusdt@aggTrade","data":{"e":"aggTrade","E":1626992757383,"a":16599312,"s":"CTKUSDT","p":"1.01100","q":"46","f":23961357,"l":23961358,"T":1626992757230,"m":true}}
1626992757.460035: {"stream":"akrousdt@depth@100ms","data":{"e":"depthUpdate","E":1626992757413,"T":1626992757397,"s":"AKROUSDT","U":600859980268,"u":600859988438,"pu":600859979805,"b":[["0.01677","136958"],["0.01711","734782"],["0.01712","1316966"],["0.01718","114530"],["0.01722","467163"],["0.01723","411944"],["0.01724","229157"],["0.01726","502243"],["0.01727","641731"],["0.01728","890464"]],"a":[["0.01737","359759"],["0.01738","471616"],["0.01739","686496"],["0.01740","281596"],["0.01746","98382"],["0.01748","2769996"]]}}
1626992757.468179: {"stream":"akrousdt@bookTicker","data":{"e":"bookTicker","u":600859990237,"s":"AKROUSDT","b":"0.01732","B":"101762","a":"0.01733","A":"22785","T":1626992757419,"E":1626992757421}}
1626992757.4682791: {"stream":"akrousdt@bookTicker","data":{"e":"bookTicker","u":600859990238,"s":"AKROUSDT","b":"0.01732","B":"101762","a":"0.01733","A":"11392","T":1626992757419,"E":1626992757421}}
1626992757.4697201: {"stream":"akrousdt@bookTicker","data":{"e":"bookTicker","u":600859990361,"s":"AKROUSDT","b":"0.01732","B":"101762","a":"0.01734","A":"107195","T":1626992757420,"E":1626992757422}}
1626992757.4960809: {"stream":"sushiusdt@depth@100ms","data":{"e":"depthUpdate","E":1626992757449,"T":1626992757444,"s":"SUSHIUSDT","U":600859983811,"u":600859992508,"pu":600859983097,"b":[["7.4240","9"],["7.4300","1577"],["7.4990","3405"],["7.5050","2020"],["7.5080","539"],["7.5360","73"],["7.5400","681"],["7.5430","5659"],["7.5490","152"],["7.5500","3264"],["7.5630","1606"],["7.5690","2117"],["7.5730","2535"],["7.5800","3749"],["7.5810","304"],["7.5820","1881"],["7.5830","3467"],["7.5870","3254"],["7.5940","775"],["7.6000","519"],["7.6010","1218"],["7.6020","754"],["7.6060","1514"],["7.6070","768"],["7.6080","219"],["7.6090","1687"],["7.6100","145"],["7.6110","1430"],["7.6120","677"],["7.6130","212"],["7.6140","73"],["7.6160","8"]],"a":[["7.6210","2026"],["7.6220","1203"],["7.6230","1605"],["7.6240","739"],["7.6250","826"],["7.6290","2682"],["7.6300","430"],["7.6370","2013"],["7.6380","789"],["7.6410","446"],["7.6430","3333"],["7.6440","4858"],["7.6450","3049"],["7.6470","2524"],["7.6510","1947"],["7.6530","664"],["7.6580","287"],["7.6650","294"],["7.6740","1672"],["7.6760","633"],["7.6840","1707"],["7.7090","209"],["7.7170","1890"],["7.7370","1066"],["7.7740","29"],["7.7820","1403"]]}}
1626992757.496586: {"stream":"keepusdt@depth@100ms","data":{"e":"depthUpdate","E":1626992757450,"T":1626992757446,"s":"KEEPUSDT","U":600859983978,"u":600859992631,"pu":600859982575,"b":[["0.2431","22429"],["0.2432","105310"],["0.2433","2965"],["0.2434","18453"],["0.2450","92376"],["0.2451","17059"],["0.2458","15117"]],"a":[["0.2467","1222"],["0.2468","1704"],["0.2469","2075"],["0.2472","7242"],["0.2475","7148"],["0.2476","6736"]]}}
1626992757.512285: {"stream":"ctkusdt@depth@100ms","data":{"e":"depthUpdate","E":1626992757468,"T":1626992757443,"s":"CTKUSDT","U":600859985538,"u":600859992355,"pu":600859983227,"b":[["1.00800","15423"]],"a":[["1.01300","14558"],["1.01400","11519"],["1.01600","19171"]]}}
1626992757.5199502: {"stream":"akrousdt@bookTicker","data":{"e":"bookTicker","u":600859994630,"s":"AKROUSDT","b":"0.01732","B":"115600","a":"0.01734","A":"107195","T":1626992757473,"E":1626992757475}}
1626992757.528946: {"stream":"keepusdt@bookTicker","data":{"e":"bookTicker","u":600859995158,"s":"KEEPUSDT","b":"0.2463","B":"384","a":"0.2466","A":"839","T":1626992757480,"E":1626992757483}}
1626992757.529043: {"stream":"keepusdt@bookTicker","data":{"e":"bookTicker","u":600859995193,"s":"KEEPUSDT","b":"0.2463","B":"384","a":"0.2466","A":"27","T":1626992757481,"E":1626992757483}}
1626992757.534539: {"stream":"ctkusdt@bookTicker","data":{"e":"bookTicker","u":600859995472,"s":"CTKUSDT","b":"1.01100","B":"11591","a":"1.01200","A":"113","T":1626992757485,"E":1626992757488}}
1626992757.535466: {"stream":"keepusdt@bookTicker","data":{"e":"bookTicker","u":600859995548,"s":"KEEPUSDT","b":"0.2465","B":"3218","a":"0.2466","A":"27","T":1626992757487,"E":1626992757490}}
1626992757.541583: {"stream":"keepusdt@kline_1m","data":{"e":"kline","E":1626992757499,"s":"KEEPUSDT","k":{"t":1626992700000,"T":1626992759999,"s":"KEEPUSDT","i":"1m","f":2398346,"L":2398359,"o":"0.2463","c":"0.2466","h":"0.2466","l":"0.2458","v":"8464","n":14,"x":false,"q":"2082.4799","V":"344","Q":"84.7670","B":"0"}}}
1626992757.5416682: {"stream":"keepusdt@bookTicker","data":{"e":"bookTicker","u":600859996232,"s":"KEEPUSDT","b":"0.2465","B":"3218","a":"0.2467","A":"383","T":1626992757496,"E":1626992757499}}
1626992757.555725: {"stream":"akrousdt@bookTicker","data":{"e":"bookTicker","u":600859996835,"s":"AKROUSDT","b":"0.01733","B":"31038","a":"0.01734","A":"107195","T":1626992757507,"E":1626992757510}}
1626992757.5587258: {"stream":"keepusdt@bookTicker","data":{"e":"bookTicker","u":600859996953,"s":"KEEPUSDT","b":"0.2465","B":"3767","a":"0.2467","A":"383","T":1626992757509,"E":1626992757513}}
1626992757.560745: {"stream":"keepusdt@bookTicker","data":{"e":"bookTicker","u":600859997113,"s":"KEEPUSDT","b":"0.2465","B":"3767","a":"0.2467","A":"1195","T":1626992757512,"E":1626992757516}}
1626992757.56527: {"stream":"akrousdt@depth@100ms","data":{"e":"depthUpdate","E":1626992757521,"T":1626992757511,"s":"AKROUSDT","U":600859990237,"u":600859997057,"pu":600859988438,"b":[["0.01683","569518"],["0.01714","1453273"],["0.01719","157969"],["0.01720","479509"],["0.01723","401944"],["0.01725","948995"],["0.01726","512243"],["0.01727","529662"],["0.01728","923504"],["0.01731","310121"],["0.01732","115600"],["0.01733","31038"]],"a":[["0.01733","0"],["0.01735","231422"],["0.01736","100605"],["0.01739","511769"],["0.01740","420351"],["0.01741","329585"],["0.01742","383235"]]}}
1626992757.5706072: {"stream":"akrousdt@bookTicker","data":{"e":"bookTicker","u":600859997705,"s":"AKROUSDT","b":"0.01733","B":"31038","a":"0.01734","A":"20640","T":1626992757520,"E":1626992757524}}
1626992757.583361: {"stream":"akrousdt@bookTicker","data":{"e":"bookTicker","u":600859998517,"s":"AKROUSDT","b":"0.01733","B":"31038","a":"0.01734","A":"44440","T":1626992757532,"E":1626992757537}}
1626992757.586729: {"stream":"akrousdt@bookTicker","data":{"e":"bookTicker","u":600859998695,"s":"AKROUSDT","b":"0.01733","B":"77038","a":"0.01734","A":"44440","T":1626992757535,"E":1626992757539}}
1626992757.586849: {"stream":"akrousdt@bookTicker","data":{"e":"bookTicker","u":600859998750,"s":"AKROUSDT","b":"0.01733","B":"77038","a":"0.01734","A":"30440","T":1626992757536,"E":1626992757540}}
1626992757.587254: {"stream":"akrousdt@bookTicker","data":{"e":"bookTicker","u":600859998806,"s":"AKROUSDT","b":"0.01733","B":"91038","a":"0.01734","A":"30440","T":1626992757537,"E":1626992757541}}
1626992757.601778: {"stream":"sushiusdt@depth@100ms","data":{"e":"depthUpdate","E":1626992757557,"T":1626992757552,"s":"SUSHIUSDT","U":600859993358,"u":600859999860,"pu":600859992508,"b":[["7.5440","704"],["7.5450","1380"],["7.5720","4469"],["7.5910","2536"],["7.5950","942"],["7.5970","2308"],["7.5980","1409"],["7.5990","4140"],["7.6020","780"],["7.6050","1284"],["7.6070","718"],["7.6080","701"],["7.6090","1481"]],"a":[["7.6210","1236"],["7.6220","1153"],["7.6230","1445"],["7.6240","959"],["7.6260","2366"],["7.6300","429"],["7.6310","2582"],["7.6330","1723"],["7.6380","769"],["7.6430","3177"],["7.6450","3206"],["7.6520","1247"],["7.6810","2641"],["7.6820","1050"],["7.6840","1723"]]}}
1626992757.617578: {"stream":"keepusdt@depth@100ms","data":{"e":"depthUpdate","E":1626992757571,"T":1626992757523,"s":"KEEPUSDT","U":600859994418,"u":600859997927,"pu":600859992631,"b":[["0.2434","20094"],["0.2445","71965"],["0.2447","2249"],["0.2459","5104"],["0.2464","0"],["0.2465","3767"],["0.2466","0"]],"a":[["0.2466","0"],["0.2467","1195"],["0.2469","2902"],["0.2470","6327"],["0.2471","16565"],["0.2477","10461"],["0.2482","241"]]}}
1626992757.630288: {"stream":"ctkusdt@depth@100ms","data":{"e":"depthUpdate","E":1626992757583,"T":1626992757577,"s":"CTKUSDT","U":600859995198,"u":600860001503,"pu":600859992355,"b":[["1.00000","84858"],["1.00500","33479"],["1.00700","8581"],["1.01000","82040"],["1.01100","11591"]],"a":[["1.01400","12031"],["1.01500","17133"],["1.01600","19428"],["1.01700","9283"],["1.01800","8325"],["1.02100","37119"],["1.02400","6663"]]}}
1626992757.668038: {"stream":"akrousdt@bookTicker","data":{"e":"bookTicker","u":600860004053,"s":"AKROUSDT","b":"0.01733","B":"91038","a":"0.01734","A":"6640","T":1626992757619,"E":1626992757622}}
1626992757.668137: {"stream":"akrousdt@depth@100ms","data":{"e":"depthUpdate","E":1626992757624,"T":1626992757619,"s":"AKROUSDT","U":600859997705,"u":600860004074,"pu":600859997057,"b":[["0.01688","286909"],["0.01715","471976"],["0.01719","149243"],["0.01725","901489"],["0.01726","431243"],["0.01727","539662"],["0.01728","903939"],["0.01729","402981"],["0.01731","337169"],["0.01732","144581"],["0.01733","91038"]],"a":[["0.01734","6640"],["0.01735","221200"],["0.01736","115026"],["0.01737","327649"],["0.01738","457616"],["0.01739","466569"],["0.01740","409175"],["0.01741","305226"]]}}
1626992757.695082: {"stream":"keepusdt@aggTrade","data":{"e":"aggTrade","E":1626992757650,"a":1211538,"s":"KEEPUSDT","p":"0.2466","q":"27","f":2398359,"l":2398359,"T":1626992757496,"m":false}}
1626992757.708176: {"stream":"sushiusdt@depth@100ms","data":{"e":"depthUpdate","E":1626992757662,"T":1626992757656,"s":"SUSHIUSDT","U":600860000340,"u":600860006003,"pu":600859999860,"b":[["7.5250","981"],["7.5490","621"],["7.5650","284"],["7.5760","1599"],["7.5800","3656"],["7.5880","1446"],["7.5900","1882"],["7.5980","1254"],["7.6020","935"],["7.6050","1144"],["7.6060","1482"],["7.6070","923"],["7.6080","681"],["7.6090","1551"],["7.6100","273"],["7.6130","205"]],"a":[["7.6210","1218"],["7.6230","1457"],["7.6240","686"],["7.6260","2346"],["7.6270","2112"],["7.6280","2794"],["7.6340","2158"],["7.6360","2458"],["7.6420","804"],["7.6550","1196"],["7.6580","409"],["7.6810","2680"],["7.6850","2538"]]}}
1626992757.7134988: {"stream":"keepusdt@bookTicker","data":{"e":"bookTicker","u":600860006278,"s":"KEEPUSDT","b":"0.2465","B":"3767","a":"0.2467","A":"1151","T":1626992757662,"E":1626992757667}}
1626992757.731219: {"stream":"keepusdt@bookTicker","data":{"e":"bookTicker","u":600860007224,"s":"KEEPUSDT","b":"0.2465","B":"3767","a":"0.2467","A":"339","T":1626992757680,"E":1626992757684}}
1626992757.734903: {"stream":"ctkusdt@depth@100ms","data":{"e":"depthUpdate","E":1626992757688,"T":1626992757679,"s":"CTKUSDT","U":600860002054,"u":600860007151,"pu":600860001503,"b":[["0.98200","8209"],["1.00500","33330"],["1.00900","12444"],["1.01000","82926"]],"a":[["1.01300","14076"],["1.01400","11689"],["1.01500","16370"],["1.01600","21099"],["1.01700","9400"],["1.01800","8442"],["1.01900","1429"],["1.05100","87"]]}}
1626992757.7455611: {"stream":"keepusdt@depth@100ms","data":{"e":"depthUpdate","E":1626992757701,"T":1626992757691,"s":"KEEPUSDT","U":600860002907,"u":600860007776,"pu":600859997927,"b":[["0.2446","8364"]],"a":[["0.2467","339"],["0.2469","379"],["0.2470","14023"],["0.2480","3279"],["0.2482","4712"],["0.2492","12681"],["0.2507","30038"]]}}
1626992757.748729: {"stream":"ctkusdt@bookTicker","data":{"e":"bookTicker","u":600860008175,"s":"CTKUSDT","b":"1.01100","B":"11591","a":"1.01200","A":"4926","T":1626992757699,"E":1626992757703}}
1626992757.761855: {"stream":"akrousdt@bookTicker","data":{"e":"bookTicker","u":600860008777,"s":"AKROUSDT","b":"0.01733","B":"91038","a":"0.01734","A":"4706","T":1626992757713,"E":1626992757716}}
1626992757.770135: {"stream":"akrousdt@depth@100ms","data":{"e":"depthUpdate","E":1626992757724,"T":1626992757713,"s":"AKROUSDT","U":600860004117,"u":600860008777,"pu":600860004074,"b":[["0.01727","472308"],["0.01729","399511"]],"a":[["0.01734","4706"],["0.01736","132459"],["0.01738","330154"],["0.01739","670898"],["0.01740","402279"],["0.01741","307903"],["0.01742","382409"],["0.01744","141292"],["0.01748","2685042"]]}}
1626992757.775483: {"stream":"keepusdt@bookTicker","data":{"e":"bookTicker","u":600860009603,"s":"KEEPUSDT","b":"0.2465","B":"3767","a":"0.2467","A":"1151","T":1626992757724,"E":1626992757729}}
1626992757.800077: {"stream":"ctkusdt@bookTicker","data":{"e":"bookTicker","u":600860011369,"s":"CTKUSDT","b":"1.01100","B":"11591","a":"1.01200","A":"4931","T":1626992757751,"E":1626992757755}}
1626992757.806934: {"stream":"sushiusdt@depth@100ms","data":{"e":"depthUpdate","E":1626992757762,"T":1626992757753,"s":"SUSHIUSDT","U":600860006050,"u":600860011560,"pu":600860006003,"b":[["7.5720","4369"],["7.5800","3572"],["7.6070","1579"],["7.6100","168"],["7.6130","212"]],"a":[["7.6210","1203"],["7.6220","1490"],["7.6240","1427"],["7.6260","1556"],["7.6280","2618"],["7.6290","2593"],["7.6310","2602"],["7.6360","2428"],["7.6420","834"],["7.6500","755"],["7.6510","1848"],["7.6520","1267"]]}}
1626992757.834738: {"stream":"ctkusdt@depth@100ms","data":{"e":"depthUpdate","E":1626992757790,"T":1626992757778,"s":"CTKUSDT","U":600860007642,"u":600860012911,"pu":600860007151,"b":[["0.99900","9377"],["1.00300","5896"],["1.00400","5024"],["1.00500","33181"],["1.00600","9388"],["1.00700","8491"],["1.00800","15659"],["1.00900","16400"]],"a":[["1.01200","4931"],["1.01300","12496"],["1.01500","16431"],["1.01700","9516"]]}}
1626992757.850744: {"stream":"akrousdt@bookTicker","data":{"e":"bookTicker","u":600860014033,"s":"AKROUSDT","b":"0.01733","B":"91583","a":"0.01734","A":"4706","T":1626992757802,"E":1626992757806}}
1626992757.852874: {"stream":"sushiusdt@bookTicker","data":{"e":"bookTicker","u":600860014061,"s":"SUSHIUSDT","b":"7.6160","B":"8","a":"7.6180","A":"96","T":1626992757803,"E":1626992757807}}
1626992757.8700411: {"stream":"akrousdt@depth@100ms","data":{"e":"depthUpdate","E":1626992757825,"T":1626992757819,"s":"AKROUSDT","U":600860009270,"u":600860014865,"pu":600860008777,"b":[["0.01700","326912"],["0.01716","394083"],["0.01721","509208"],["0.01733","91583"]],"a":[["0.01743","333900"],["0.01750","1601698"]]}}
1626992757.873594: {"stream":"keepusdt@depth@100ms","data":{"e":"depthUpdate","E":1626992757829,"T":1626992757806,"s":"KEEPUSDT","U":600860009603,"u":600860014211,"pu":600860007776,"b":[["0.2421","6946"],["0.2436","1024"],["0.2438","9576"]],"a":[["0.2467","1151"],["0.2492","2503"],["0.2494","13015"],["0.2509","16904"]]}}
1626992757.914023: {"stream":"akrousdt@bookTicker","data":{"e":"bookTicker","u":600860015747,"s":"AKROUSDT","b":"0.01733","B":"101345","a":"0.01734","A":"4706","T":1626992757837,"E":1626992757840}}
1626992757.9167309: {"stream":"sushiusdt@bookTicker","data":{"e":"bookTicker","u":600860016164,"s":"SUSHIUSDT","b":"7.6160","B":"8","a":"7.6180","A":"138","T":1626992757844,"E":1626992757847}}
1626992757.9168372: {"stream":"keepusdt@bookTicker","data":{"e":"bookTicker","u":600860016474,"s":"KEEPUSDT","b":"0.2465","B":"3767","a":"0.2467","A":"339","T":1626992757849,"E":1626992757853}}
1626992757.916884: {"stream":"sushiusdt@depth@100ms","data":{"e":"depthUpdate","E":1626992757865,"T":1626992757856,"s":"SUSHIUSDT","U":600860011981,"u":600860016774,"pu":600860011560,"b":[["7.5670","33"],["7.5690","2057"],["7.5730","2595"],["7.5830","3152"],["7.5850","1303"],["7.5970","1290"],["7.5990","4171"],["7.6040","2473"],["7.6050","250"],["7.6140","151"]],"a":[["7.6180","138"],["7.6190","390"],["7.6260","1706"],["7.6290","2229"],["7.6310","2915"],["7.6340","1541"],["7.6350","3248"],["7.6430","3146"],["7.6450","3237"],["7.6580","441"]]}}
1626992757.941741: {"stream":"keepusdt@bookTicker","data":{"e":"bookTicker","u":600860018693,"s":"KEEPUSDT","b":"0.2465","B":"3767","a":"0.2467","A":"1151","T":1626992757894,"E":1626992757898}}
1626992757.9587479: {"stream":"sushiusdt@bookTicker","data":{"e":"bookTicker","u":600860019481,"s":"SUSHIUSDT","b":"7.6150","B":"25","a":"7.6180","A":"138","T":1626992757909,"E":1626992757914}}
1626992757.965757: {"stream":"ctkusdt@depth@100ms","data":{"e":"depthUpdate","E":1626992757920,"T":1626992757887,"s":"CTKUSDT","U":600860014721,"u":600860018359,"pu":600860012911,"b":[["1.00500","33715"],["1.00600","9507"],["1.00700","8639"],["1.00900","16327"]],"a":[["1.01400","11935"],["1.01500","14981"],["1.01900","1550"],["1.05200","14363"]]}}
1626992757.970648: {"stream":"sushiusdt@bookTicker","data":{"e":"bookTicker","u":600860020080,"s":"SUSHIUSDT","b":"7.6170","B":"8","a":"7.6180","A":"138","T":1626992757921,"E":1626992757925}}
1626992757.970747: {"stream":"akrousdt@depth@100ms","data":{"e":"depthUpdate","E":1626992757926,"T":1626992757918,"s":"AKROUSDT","U":600860014991,"u":600860019919,"pu":600860014865,"b":[["0.01704","143725"],["0.01723","378931"],["0.01731","340635"],["0.01732","134819"],["0.01733","101345"]],"a":[["0.01738","382054"],["0.01739","730562"],["0.01740","436746"],["0.01742","359647"],["0.01747","119119"],["0.01780","258418"]]}}
1626992757.9963331: {"stream":"keepusdt@depth@100ms","data":{"e":"depthUpdate","E":1626992757953,"T":1626992757931,"s":"KEEPUSDT","U":600860016455,"u":600860020510,"pu":600860014211,"b":[["0.2423","10657"],["0.2458","14096"]],"a":[["0.2467","1151"],["0.2472","8490"]]}}
1626992758.012375: {"stream":"sushiusdt@depth@100ms","data":{"e":"depthUpdate","E":1626992757967,"T":1626992757960,"s":"SUSHIUSDT","U":600860017208,"u":600860021939,"pu":600860016774,"b":[["7.5470","2103"],["7.5500","3248"],["7.5580","848"],["7.5650","198"],["7.5850","1130"],["7.5860","1136"],["7.5910","2454"],["7.5940","885"],["7.6060","1510"],["7.6070","1454"],["7.6080","407"],["7.6090","1805"],["7.6130","205"],["7.6140","158"],["7.6160","0"],["7.6170","8"]],"a":[["7.6220","2252"],["7.6240","637"],["7.6290","2579"],["7.6300","372"],["7.6310","2392"],["7.6320","2923"],["7.6340","1705"],["7.6350","3150"],["7.6400","992"],["7.6410","671"],["7.6590","609"],["7.6690","192"]]}}
1626992758.066644: {"stream":"keepusdt@bookTicker","data":{"e":"bookTicker","u":600860024395,"s":"KEEPUSDT","b":"0.2465","B":"3767","a":"0.2467","A":"339","T":1626992758014,"E":1626992758019}}
1626992758.0700219: {"stream":"ctkusdt@depth@100ms","data":{"e":"depthUpdate","E":1626992758025,"T":1626992757920,"s":"CTKUSDT","U":600860020005,"u":600860020025,"pu":600860018359,"b":[["1.00700","8787"]],"a":[["1.01300","12249"]]}}
1626992758.073339: {"stream":"akrousdt@depth@100ms","data":{"e":"depthUpdate","E":1626992758027,"T":1626992758019,"s":"AKROUSDT","U":600860020168,"u":600860024640,"pu":600860019919,"b":[["0.01659","304459"],["0.01722","452586"],["0.01728","953079"],["0.01729","398465"],["0.01730","128562"]],"a":[["0.01738","416554"],["0.01739","635270"],["0.01740","597546"],["0.01745","253293"]]}}
1626992758.10121: {"stream":"keepusdt@bookTicker","data":{"e":"bookTicker","u":600860026250,"s":"KEEPUSDT","b":"0.2465","B":"3767","a":"0.2467","A":"1151","T":1626992758052,"E":1626992758056}}
1626992758.1013062: {"stream":"keepusdt@depth@100ms","data":{"e":"depthUpdate","E":1626992758057,"T":1626992758053,"s":"KEEPUSDT","U":600860021679,"u":600860026279,"pu":600860020510,"b":[["0.2449","14679"],["0.2452","7203"],["0.2453","10500"],["0.2457","5820"],["0.2458","18194"],["0.2459","4157"],["0.2460","1286"]],"a":[["0.2467","1151"],["0.2472","10377"],["0.2473","22138"],["0.2475","11500"]]}}
1626992758.1183932: {"stream":"sushiusdt@depth@100ms","data":{"e":"depthUpdate","E":1626992758073,"T":1626992758063,"s":"SUSHIUSDT","U":600860022251,"u":600860026836,"pu":600860021939,"b":[["7.5600","3826"],["7.5750","3614"],["7.5790","698"],["7.5810","417"],["7.5840","3028"],["7.5860","1060"],["7.5980","1254"],["7.6000","499"],["7.6060","1530"],["7.6070","1909"],["7.6080","429"],["7.6130","310"]],"a":[["7.6190","392"],["7.6210","1020"],["7.6220","1447"],["7.6240","1505"],["7.6250","1631"],["7.6290","2504"],["7.6300","352"],["7.6320","3245"],["7.6360","2428"],["7.6410","847"],["7.6440","4858"],["7.6470","2570"],["7.6610","703"],["7.6800","3747"],["7.6860","171"],["7.6920","196"]]}}
1626992758.174253: {"stream":"akrousdt@depth@100ms","data":{"e":"depthUpdate","E":1626992758128,"T":1626992758118,"s":"AKROUSDT","U":600860024860,"u":600860027609,"pu":600860024640,"b":[["0.01723","367315"],["0.01725","883945"],["0.01731","341681"]],"a":[["0.01736","115026"],["0.01737","316127"],["0.01738","468454"]]}}
1626992758.213684: {"stream":"keepusdt@depth@100ms","data":{"e":"depthUpdate","E":1626992758169,"T":1626992758163,"s":"KEEPUSDT","U":600860026949,"u":600860028104,"pu":600860026279,"b":[["0.2433","1323"],["0.2444","1805"],["0.2445","71147"],["0.2450","93063"],["0.2454","2179"]],"a":[["0.2468","1017"],["0.2475","14400"]]}}
1626992758.245924: {"stream":"sushiusdt@depth@100ms","data":{"e":"depthUpdate","E":1626992758199,"T":1626992758193,"s":"SUSHIUSDT","U":600860027265,"u":600860030086,"pu":600860026836,"b":[["7.5210","875"],["7.5600","3495"],["7.5690","2031"],["7.5750","3640"],["7.5760","1512"],["7.5900","1863"],["7.6010","733"],["7.6040","2077"],["7.6070","1784"],["7.6080","479"],["7.6090","1481"]],"a":[["7.6210","736"],["7.6240","2163"],["7.6260","1680"],["7.6280","2748"],["7.6290","2374"],["7.6320","3219"],["7.6360","2435"],["7.6450","3151"],["7.6460","379"]]}}
1626992758.24618: {"stream":"ctkusdt@depth@100ms","data":{"e":"depthUpdate","E":1626992758199,"T":1626992758184,"s":"CTKUSDT","U":600860027317,"u":600860029235,"pu":600860020025,"b":[["1.00500","33055"],["1.00600","9309"],["1.00700","8589"]],"a":[["1.01400","11331"],["1.01500","14784"]]}}
1626992758.26072: {"stream":"akrousdt@bookTicker","data":{"e":"bookTicker","u":600860031332,"s":"AKROUSDT","b":"0.01733","B":"101345","a":"0.01734","A":"14612","T":1626992758211,"E":1626992758214}}
1626992758.269044: {"stream":"keepusdt@bookTicker","data":{"e":"bookTicker","u":600860031812,"s":"KEEPUSDT","b":"0.2465","B":"3767","a":"0.2467","A":"339","T":1626992758218,"E":1626992758222}}
1626992758.2896588: {"stream":"akrousdt@bookTicker","data":{"e":"bookTicker","u":600860033336,"s":"AKROUSDT","b":"0.01733","B":"101345","a":"0.01734","A":"9906","T":1626992758235,"E":1626992758238}}
1626992758.291064: {"stream":"keepusdt@bookTicker","data":{"e":"bookTicker","u":600860033760,"s":"KEEPUSDT","b":"0.2465","B":"3767","a":"0.2467","A":"1151","T":1626992758239,"E":1626992758243}}
1626992758.2934148: {"stream":"akrousdt@depth@100ms","data":{"e":"depthUpdate","E":1626992758248,"T":1626992758239,"s":"AKROUSDT","U":600860027741,"u":600860033710,"pu":600860027609,"b":[["0.01665","683784"],["0.01717","276613"],["0.01722","3099701"],["0.01723","381874"],["0.01725","690986"],["0.01726","410948"],["0.01727","352570"],["0.01728","1338425"],["0.01729","471261"],["0.01731","365211"]],"a":[["0.01734","9906"],["0.01735","197670"],["0.01736","71522"],["0.01737","246422"],["0.01740","610459"],["0.01741","372483"],["0.01743","382618"]]}}
1626992758.342879: {"stream":"keepusdt@depth@100ms","data":{"e":"depthUpdate","E":1626992758295,"T":1626992758267,"s":"KEEPUSDT","U":600860029873,"u":600860035289,"pu":600860028104,"b":[["0.2452","4498"],["0.2454","4879"],["0.2456","12701"],["0.2460","2305"]],"a":[["0.2467","1151"],["0.2469","1066"],["0.2475","15850"],["0.2485","17991"]]}}
1626992758.3482938: {"stream":"ctkusdt@depth@100ms","data":{"e":"depthUpdate","E":1626992758300,"T":1626992758287,"s":"CTKUSDT","U":600860030398,"u":600860036215,"pu":600860029235,"b":[["1.00600","9967"],["1.00800","15857"],["1.01000","82999"]],"a":[["1.01300","11837"],["1.01400","10244"],["1.01500","15436"],["1.01600","22377"],["1.29300","1261"]]}}
1626992758.348475: {"stream":"sushiusdt@depth@100ms","data":{"e":"depthUpdate","E":1626992758301,"T":1626992758287,"s":"SUSHIUSDT","U":600860030489,"u":600860036231,"pu":600860030086,"b":[["7.5700","239"],["7.5720","4278"],["7.5770","2028"],["7.5800","3552"],["7.5810","504"],["7.5820","1990"],["7.5880","1391"],["7.5890","1120"],["7.5950","632"],["7.5990","4500"],["7.6000","830"],["7.6020","803"],["7.6030","675"],["7.6060","1787"],["7.6080","429"],["7.6100","492"],["7.6140","158"]],"a":[["7.6220","1398"],["7.6230","3773"],["7.6240","961"],["7.6250","1125"],["7.6280","2774"],["7.6300","771"],["7.6330","2386"],["7.6340","2032"],["7.6370","1827"],["7.6400","1178"],["7.6410","866"],["7.6420","715"],["7.6460","487"],["7.6490","14227"],["7.6530","610"]]}}
1626992758.399847: {"stream":"akrousdt@depth@100ms","data":{"e":"depthUpdate","E":1626992758355,"T":1626992758345,"s":"AKROUSDT","U":600860034467,"u":600860038735,"pu":600860033710,"b":[["0.01721","470665"],["0.01722","3138186"],["0.01723","357628"],["0.01724","240764"],["0.01726","436129"],["0.01727","361261"],["0.01728","1215996"],["0.01729","593690"],["0.01731","395193"]],"a":[["0.01737","208248"],["0.01738","526735"],["0.01741","419497"],["0.01742","350551"],["0.01743","388355"]]}}
1626992758.4313548: {"stream":"ctkusdt@kline_1m","data":{"e":"kline","E":1626992758386,"s":"CTKUSDT","k":{"t":1626992700000,"T":1626992759999,"s":"CTKUSDT","i":"1m","f":23961275,"L":23961359,"o":"1.01000","c":"1.01200","h":"1.01200","l":"1.01000","v":"11064","n":85,"x":false,"q":"11183.37000","V":"8664","Q":"8759.32400","B":"0"}}}
1626992758.433409: {"stream":"ctkusdt@bookTicker","data":{"e":"bookTicker","u":600860040520,"s":"CTKUSDT","b":"1.01100","B":"11591","a":"1.01200","A":"4921","T":1626992758382,"E":1626992758386}}
1626992758.452667: {"stream":"sushiusdt@depth@100ms","data":{"e":"depthUpdate","E":1626992758405,"T":1626992758397,"s":"SUSHIUSDT","U":600860036714,"u":600860041177,"pu":600860036231,"b":[["7.5750","3607"],["7.5760","1456"],["7.5770","1989"],["7.5830","3235"],["7.5880","1411"],["7.5920","1414"],["7.5930","4927"],["7.6030","1656"],["7.6060","806"],["7.6080","1150"]],"a":[["7.6220","2188"],["7.6230","2983"],["7.6240","976"],["7.6250","1110"],["7.6270","2045"],["7.6280","1793"],["7.6290","2441"],["7.6300","791"],["7.6320","2518"],["7.6340","2079"],["7.6350","2876"],["7.6390","2752"],["7.6440","4746"],["7.6510","1874"],["7.6680","2560"]]}}
1626992758.4649432: {"stream":"sushiusdt@bookTicker","data":{"e":"bookTicker","u":600860041899,"s":"SUSHIUSDT","b":"7.6170","B":"8","a":"7.6180","A":"114","T":1626992758415,"E":1626992758419}}
1626992758.4650261: {"stream":"sushiusdt@kline_1m","data":{"e":"kline","E":1626992758420,"s":"SUSHIUSDT","k":{"t":1626992700000,"T":1626992759999,"s":"SUSHIUSDT","i":"1m","f":126902874,"L":126902983,"o":"7.6080","c":"7.6180","h":"7.6180","l":"7.6070","v":"2980","n":110,"x":false,"q":"22685.4140","V":"1880","Q":"14312.3360","B":"0"}}}
1626992758.4808881: {"stream":"ctkusdt@depth@100ms","data":{"e":"depthUpdate","E":1626992758436,"T":1626992758422,"s":"CTKUSDT","U":600860038150,"u":600860042152,"pu":600860036215,"b":[["1.00700","12890"],["1.00800","16697"],["1.00900","16268"],["1.01500","0"]],"a":[["1.01200","4921"],["1.01400","11792"],["1.01500","15633"]]}}
1626992758.503444: {"stream":"akrousdt@depth@100ms","data":{"e":"depthUpdate","E":1626992758457,"T":1626992758446,"s":"AKROUSDT","U":600860039142,"u":600860042950,"pu":600860038735,"b":[["0.01724","231757"],["0.01725","654904"],["0.01728","1182992"],["0.01730","126034"]],"a":[["0.01736","35668"],["0.01737","187217"],["0.01739","629520"],["0.01743","408354"]]}}
1626992758.545471: {"stream":"akrousdt@kline_1m","data":{"e":"kline","E":1626992758499,"s":"AKROUSDT","k":{"t":1626992700000,"T":1626992759999,"s":"AKROUSDT","i":"1m","f":27931328,"L":27931355,"o":"0.01731","c":"0.01733","h":"0.01733","l":"0.01731","v":"223151","n":28,"x":false,"q":"3864.53950","V":"101629","Q":"1760.37292","B":"0"}}}
1626992758.5456152: {"stream":"akrousdt@bookTicker","data":{"e":"bookTicker","u":600860044515,"s":"AKROUSDT","b":"0.01733","B":"57722","a":"0.01734","A":"9906","T":1626992758495,"E":1626992758499}}
1626992758.561963: {"stream":"sushiusdt@depth@100ms","data":{"e":"depthUpdate","E":1626992758515,"T":1626992758500,"s":"SUSHIUSDT","U":600860041658,"u":600860044667,"pu":600860041177,"b":[["7.5310","5949"],["7.5770","2089"],["7.5830","3267"],["7.5870","3293"],["7.5900","1889"],["7.6010","1856"],["7.6060","661"],["7.6070","1804"],["7.6080","1200"],["7.6110","1546"],["7.6140","151"]],"a":[["7.6180","114"],["7.6230","2733"],["7.6250","1360"],["7.6270","2045"],["7.6350","3493"],["7.6360","3091"],["7.6370","2101"],["7.6490","10309"],["7.6550","1295"],["7.6780","585"],["7.7730","9"],["8.9200","6507"]]}}
1626992758.582716: {"stream":"ctkusdt@aggTrade","data":{"e":"aggTrade","E":1626992758537,"a":16599313,"s":"CTKUSDT","p":"1.01200","q":"10","f":23961359,"l":23961359,"T":1626992758382,"m":false}}
1626992758.615985: {"stream":"sushiusdt@aggTrade","data":{"e":"aggTrade","E":1626992758570,"a":87353255,"s":"SUSHIUSDT","p":"7.6180","q":"24","f":126902983,"l":126902984,"T":1626992758415,"m":false}}
1626992758.616086: {"stream":"keepusdt@bookTicker","data":{"e":"bookTicker","u":600860046608,"s":"KEEPUSDT","b":"0.2465","B":"3767","a":"0.2467","A":"339","T":1626992758564,"E":1626992758570}}
1626992758.6214058: {"stream":"ctkusdt@depth@100ms","data":{"e":"depthUpdate","E":1626992758575,"T":1626992758471,"s":"CTKUSDT","U":600860043764,"u":600860043764,"pu":600860042152,"b":[["1.00700","7947"]],"a":[]}}
1626992758.621557: {"stream":"akrousdt@depth@100ms","data":{"e":"depthUpdate","E":1626992758577,"T":1626992758571,"s":"AKROUSDT","U":600860043809,"u":600860046848,"pu":600860042950,"b":[["0.01713","12489"],["0.01720","459171"],["0.01724","254756"],["0.01726","445126"],["0.01728","1130571"],["0.01731","397720"],["0.01733","57722"]],"a":[["0.01737","167078"],["0.01738","562083"],["0.01744","150196"]]}}
1626992758.6617029: {"stream":"keepusdt@bookTicker","data":{"e":"bookTicker","u":600860048375,"s":"KEEPUSDT","b":"0.2465","B":"3767","a":"0.2467","A":"1151","T":1626992758611,"E":1626992758618}}
1626992758.665805: {"stream":"sushiusdt@depth@100ms","data":{"e":"depthUpdate","E":1626992758621,"T":1626992758614,"s":"SUSHIUSDT","U":600860045205,"u":600860048502,"pu":600860044667,"b":[["7.5760","1547"],["7.5820","1496"],["7.5920","1908"],["7.6050","250"],["7.6070","1849"],["7.6080","1150"],["7.6120","809"],["7.6140","158"]],"a":[["7.6310","2886"],["7.6360","3052"],["7.6390","2781"],["7.6400","684"],["7.6420","691"],["7.6460","422"],["7.6470","2460"],["7.6520","1306"],["7.6540","319"],["7.6570","4268"],["7.6580","161"],["7.6620","471"],["7.6630","388"],["7.6710","1156"],["7.6750","980"],["7.6840","1697"],["7.6970","381"],["7.7010","566"],["7.7170","3152"]]}}
1626992758.667856: {"stream":"keepusdt@depth@100ms","data":{"e":"depthUpdate","E":1626992758623,"T":1626992758611,"s":"KEEPUSDT","U":600860045228,"u":600860048375,"pu":600860035289,"b":[["0.2433","30054"]],"a":[["0.2467","1151"],["0.2507","29632"]]}}
1626992758.683608: {"stream":"ctkusdt@bookTicker","data":{"e":"bookTicker","u":600860049315,"s":"CTKUSDT","b":"1.01100","B":"11650","a":"1.01200","A":"4921","T":1626992758634,"E":1626992758639}}
1626992758.6942809: {"stream":"akrousdt@aggTrade","data":{"e":"aggTrade","E":1626992758650,"a":14888306,"s":"AKROUSDT","p":"0.01733","q":"43623","f":27931355,"l":27931356,"T":1626992758495,"m":true}}
1626992758.721034: {"stream":"akrousdt@depth@100ms","data":{"e":"depthUpdate","E":1626992758677,"T":1626992758672,"s":"AKROUSDT","U":600860046902,"u":600860050528,"pu":600860046848,"b":[["0.01709","370266"],["0.01721","470259"],["0.01722","3051165"],["0.01726","385711"],["0.01729","629791"],["0.01731","395193"]],"a":[["0.01738","576467"],["0.01739","596725"],["0.01740","646332"],["0.01741","356411"],["0.01743","431103"]]}}
1626992758.7678678: {"stream":"sushiusdt@depth@100ms","data":{"e":"depthUpdate","E":1626992758722,"T":1626992758714,"s":"SUSHIUSDT","U":600860048607,"u":600860051841,"pu":600860048502,"b":[["7.5510","1092"],["7.5830","3242"],["7.6020","693"],["7.6060","771"],["7.6070","1804"],["7.6080","1180"],["7.6160","13"]],"a":[["7.6190","275"],["7.6200","964"],["7.6260","1755"],["7.6360","3315"],["7.6470","2550"],["7.6480","710"],["7.6490","10421"],["7.6650","268"],["7.6780","611"],["7.7170","3385"],["7.8150","520"]]}}
1626992758.782763: {"stream":"ctkusdt@depth@100ms","data":{"e":"depthUpdate","E":1626992758739,"T":1626992758699,"s":"CTKUSDT","U":600860049315,"u":600860051466,"pu":600860043764,"b":[["1.01100","11650"]],"a":[["1.01500","15959"]]}}
1626992758.823209: {"stream":"akrousdt@depth@100ms","data":{"e":"depthUpdate","E":1626992758779,"T":1626992758767,"s":"AKROUSDT","U":600860050573,"u":600860053432,"pu":600860050528,"b":[["0.01712","1334501"],["0.01721","468866"],["0.01724","256555"],["0.01726","691675"],["0.01727","422041"],["0.01728","1119557"]],"a":[["0.01741","345479"]]}}
1626992758.862942: {"stream":"keepusdt@bookTicker","data":{"e":"bookTicker","u":600860054722,"s":"KEEPUSDT","b":"0.2465","B":"3767","a":"0.2467","A":"339","T":1626992758812,"E":1626992758817}}
1626992758.869031: {"stream":"sushiusdt@depth@100ms","data":{"e":"depthUpdate","E":1626992758822,"T":1626992758816,"s":"SUSHIUSDT","U":600860051902,"u":600860054845,"pu":600860051841,"b":[["7.5690","2117"],["7.5820","1027"],["7.5830","3711"],["7.6060","739"],["7.6070","1785"],["7.6080","1150"],["7.6120","841"],["7.6130","374"],["7.6140","236"]],"a":[["7.6200","1113"],["7.6260","1830"],["7.6340","2161"],["7.6360","3400"],["7.6490","8452"],["7.6510","2343"],["7.6630","499"],["7.6900","137"],["8.7480","1620"]]}}
1626992758.9059782: {"stream":"keepusdt@bookTicker","data":{"e":"bookTicker","u":600860055897,"s":"KEEPUSDT","b":"0.2465","B":"3767","a":"0.2467","A":"1151","T":1626992758855,"E":1626992758859}}
1626992758.9158149: {"stream":"keepusdt@depth@100ms","data":{"e":"depthUpdate","E":1626992758871,"T":1626992758855,"s":"KEEPUSDT","U":600860053460,"u":600860055897,"pu":600860048375,"b":[],"a":[["0.2467","1151"],["0.2476","15196"],["0.2486","11780"]]}}
1626992758.9340339: {"stream":"akrousdt@depth@100ms","data":{"e":"depthUpdate","E":1626992758889,"T":1626992758784,"s":"AKROUSDT","U":600860053952,"u":600860053952,"pu":600860053432,"b":[],"a":[["0.01740","666432"]]}}
1626992758.96726: {"stream":"sushiusdt@depth@100ms","data":{"e":"depthUpdate","E":1626992758922,"T":1626992758909,"s":"SUSHIUSDT","U":600860054879,"u":600860057452,"pu":600860054845,"b":[["7.5240","3569"],["7.5410","2723"],["7.5770","589"],["7.5940","1149"],["7.6050","888"],["7.6070","2181"],["7.6160","0"]],"a":[["7.6200","1145"],["7.6210","768"],["7.6230","2748"],["7.6240","1123"],["7.6290","2966"]]}}
1626992758.987405: {"stream":"sushiusdt@bookTicker","data":{"e":"bookTicker","u":600860058251,"s":"SUSHIUSDT","b":"7.6170","B":"21","a":"7.6180","A":"114","T":1626992758937,"E":1626992758942}}
1626992759.0409548: {"stream":"akrousdt@depth@100ms","data":{"e":"depthUpdate","E":1626992758996,"T":1626992758990,"s":"AKROUSDT","U":600860056907,"u":600860060165,"pu":600860053952,"b":[["0.01716","307545"],["0.01725","741970"],["0.01726","671479"],["0.01727","413350"]],"a":[["0.01738","593767"],["0.01740","793077"]]}}
1626992759.0625741: {"stream":"keepusdt@bookTicker","data":{"e":"bookTicker","u":600860060943,"s":"KEEPUSDT","b":"0.2465","B":"3767","a":"0.2467","A":"339","T":1626992759013,"E":1626992759017}}
1626992759.0669582: {"stream":"keepusdt@depth@100ms","data":{"e":"depthUpdate","E":1626992759022,"T":1626992759013,"s":"KEEPUSDT","U":600860057687,"u":600860060943,"pu":600860055897,"b":[],"a":[["0.2467","339"],["0.2471","10477"],["0.2475","18750"],["0.2488","10141"]]}}
1626992759.089629: {"stream":"sushiusdt@depth@100ms","data":{"e":"depthUpdate","E":1626992759042,"T":1626992759033,"s":"SUSHIUSDT","U":600860058251,"u":600860061592,"pu":600860057452,"b":[["7.5550","353"],["7.5830","3766"],["7.6000","1072"],["7.6040","2297"],["7.6080","1080"],["7.6090","1551"],["7.6170","21"]],"a":[["7.6280","1663"],["7.6290","3096"],["7.6350","3051"],["7.6470","3206"],["7.7090","211"],["7.7580","97"]]}}
1626992759.107497: {"stream":"ctkusdt@depth@100ms","data":{"e":"depthUpdate","E":1626992759060,"T":1626992758982,"s":"CTKUSDT","U":600860058852,"u":600860059925,"pu":600860051466,"b":[["0.89700","0"],["0.89800","1699"],["1.00300","5646"]],"a":[["1.12300","73"],["1.12400","1472"]]}}
1626992759.146778: {"stream":"sushiusdt@kline_1m","data":{"e":"kline","E":1626992759101,"s":"SUSHIUSDT","k":{"t":1626992700000,"T":1626992759999,"s":"SUSHIUSDT","i":"1m","f":126902874,"L":126902985,"o":"7.6080","c":"7.6170","h":"7.6180","l":"7.6070","v":"3001","n":112,"x":false,"q":"22845.3910","V":"1900","Q":"14464.6960","B":"0"}}}
1626992759.146925: {"stream":"sushiusdt@bookTicker","data":{"e":"bookTicker","u":600860062720,"s":"SUSHIUSDT","b":"7.6170","B":"20","a":"7.6180","A":"114","T":1626992759095,"E":1626992759101}}
1626992759.154334: {"stream":"keepusdt@bookTicker","data":{"e":"bookTicker","u":600860062791,"s":"KEEPUSDT","b":"0.2465","B":"3767","a":"0.2467","A":"1151","T":1626992759104,"E":1626992759109}}
1626992759.166333: {"stream":"akrousdt@depth@100ms","data":{"e":"depthUpdate","E":1626992759119,"T":1626992759054,"s":"AKROUSDT","U":600860060997,"u":600860062163,"pu":600860060165,"b":[["0.01717","363101"],["0.01723","354726"]],"a":[]}}
1626992759.180852: {"stream":"keepusdt@depth@100ms","data":{"e":"depthUpdate","E":1626992759136,"T":1626992759104,"s":"KEEPUSDT","U":600860061529,"u":600860062791,"pu":600860060943,"b":[],"a":[["0.2467","1151"],["0.2475","21650"]]}}
1626992759.188415: {"stream":"sushiusdt@depth@100ms","data":{"e":"depthUpdate","E":1626992759144,"T":1626992759139,"s":"SUSHIUSDT","U":600860061792,"u":600860064168,"pu":600860061592,"b":[["7.6140","236"],["7.6170","20"]],"a":[["7.6230","2998"],["7.6250","1110"],["7.6280","2405"],["7.6340","2243"],["7.6350","3102"],["7.6410","1308"]]}}
1626992759.229772: {"stream":"keepusdt@bookTicker","data":{"e":"bookTicker","u":600860065540,"s":"KEEPUSDT","b":"0.2465","B":"3767","a":"0.2467","A":"339","T":1626992759178,"E":1626992759185}}
1626992759.277823: {"stream":"keepusdt@bookTicker","data":{"e":"bookTicker","u":600860066811,"s":"KEEPUSDT","b":"0.2465","B":"3767","a":"0.2467","A":"1151","T":1626992759226,"E":1626992759231}}
1626992759.281271: {"stream":"akrousdt@depth@100ms","data":{"e":"depthUpdate","E":1626992759235,"T":1626992759225,"s":"AKROUSDT","U":600860063519,"u":600860066772,"pu":600860062163,"b":[["0.01722","3012680"],["0.01723","393184"],["0.01724","259455"],["0.01731","686154"],["0.01732","178336"]],"a":[["0.01739","670902"],["0.01741","633913"]]}}
1626992759.283556: {"stream":"keepusdt@depth@100ms","data":{"e":"depthUpdate","E":1626992759238,"T":1626992759226,"s":"KEEPUSDT","U":600860063722,"u":600860066811,"pu":600860062791,"b":[],"a":[["0.2467","1151"],["0.2475","24634"],["0.2477","13136"]]}}
1626992759.291164: {"stream":"sushiusdt@depth@100ms","data":{"e":"depthUpdate","E":1626992759246,"T":1626992759231,"s":"SUSHIUSDT","U":600860064429,"u":600860066965,"pu":600860064168,"b":[["7.5620","2180"],["7.5950","896"]],"a":[["7.6220","1915"],["7.6230","2895"],["7.6250","1360"],["7.6260","1880"],["7.6340","2289"],["7.6390","2879"],["7.6560","293"]]}}
1626992759.297523: {"stream":"sushiusdt@aggTrade","data":{"e":"aggTrade","E":1626992759252,"a":87353256,"s":"SUSHIUSDT","p":"7.6170","q":"1","f":126902985,"l":126902985,"T":1626992759095,"m":true}}
1626992759.299546: {"stream":"ctkusdt@depth@100ms","data":{"e":"depthUpdate","E":1626992759256,"T":1626992759152,"s":"CTKUSDT","U":600860064706,"u":600860064742,"pu":600860059925,"b":[["1.01000","83281"]],"a":[]}}
1626992759.3947442: {"stream":"akrousdt@depth@100ms","data":{"e":"depthUpdate","E":1626992759350,"T":1626992759341,"s":"AKROUSDT","U":600860067321,"u":600860069798,"pu":600860066772,"b":[["0.01727","433534"],["0.01731","683627"]],"a":[]}}
1626992759.412909: {"stream":"sushiusdt@depth@100ms","data":{"e":"depthUpdate","E":1626992759367,"T":1626992759322,"s":"SUSHIUSDT","U":600860067671,"u":600860069340,"pu":600860066965,"b":[["7.4580","8"],["7.5630","1253"],["7.5760","1900"],["7.6070","2161"],["7.6080","1100"]],"a":[["7.6230","2945"],["7.6240","1396"],["7.6260","1830"],["7.6280","3061"],["7.6290","2822"],["7.6860","351"],["7.6920","16"]]}}
1626992759.429075: {"stream":"ctkusdt@depth@100ms","data":{"e":"depthUpdate","E":1626992759380,"T":1626992759286,"s":"CTKUSDT","U":600860068167,"u":600860068480,"pu":600860064742,"b":[],"a":[["1.01400","12408"],["1.01500","15818"],["1.01600","22377"],["1.01700","9041"]]}}
1626992759.429183: {"stream":"ctkusdt@bookTicker","data":{"e":"bookTicker","u":600860070883,"s":"CTKUSDT","b":"1.01100","B":"11571","a":"1.01200","A":"4921","T":1626992759378,"E":1626992759382}}
1626992759.429227: {"stream":"ctkusdt@bookTicker","data":{"e":"bookTicker","u":600860070884,"s":"CTKUSDT","b":"1.01100","B":"11571","a":"1.01200","A":"108","T":1626992759378,"E":1626992759382}}
1626992759.4292521: {"stream":"sushiusdt@bookTicker","data":{"e":"bookTicker","u":600860070891,"s":"SUSHIUSDT","b":"7.6170","B":"20","a":"7.6180","A":"42","T":1626992759378,"E":1626992759382}}
1626992759.429274: {"stream":"akrousdt@bookTicker","data":{"e":"bookTicker","u":600860070899,"s":"AKROUSDT","b":"0.01733","B":"57722","a":"0.01735","A":"197670","T":1626992759378,"E":1626992759382}}
1626992759.4303439: {"stream":"sushiusdt@bookTicker","data":{"e":"bookTicker","u":600860070952,"s":"SUSHIUSDT","b":"7.6170","B":"20","a":"7.6190","A":"275","T":1626992759379,"E":1626992759384}}
1626992759.4386728: {"stream":"ctkusdt@bookTicker","data":{"e":"bookTicker","u":600860071221,"s":"CTKUSDT","b":"1.01100","B":"11661","a":"1.01200","A":"108","T":1626992759388,"E":1626992759393}}
1626992759.438772: {"stream":"keepusdt@depth@100ms","data":{"e":"depthUpdate","E":1626992759394,"T":1626992759289,"s":"KEEPUSDT","U":600860068547,"u":600860068547,"pu":600860066811,"b":[],"a":[["0.2500","6485"]]}}
1626992759.4450119: {"stream":"akrousdt@bookTicker","data":{"e":"bookTicker","u":600860071484,"s":"AKROUSDT","b":"0.01733","B":"57722","a":"0.01735","A":"183249","T":1626992759395,"E":1626992759399}}
1626992759.450322: {"stream":"akrousdt@bookTicker","data":{"e":"bookTicker","u":600860071541,"s":"AKROUSDT","b":"0.01733","B":"57722","a":"0.01735","A":"168828","T":1626992759396,"E":1626992759402}}
1626992759.456747: {"stream":"sushiusdt@bookTicker","data":{"e":"bookTicker","u":600860071865,"s":"SUSHIUSDT","b":"7.6170","B":"20","a":"7.6190","A":"158","T":1626992759405,"E":1626992759411}}
1626992759.475966: {"stream":"ctkusdt@bookTicker","data":{"e":"bookTicker","u":600860072443,"s":"CTKUSDT","b":"1.01100","B":"11661","a":"1.01200","A":"103","T":1626992759425,"E":1626992759431}}
1626992759.521748: {"stream":"keepusdt@bookTicker","data":{"e":"bookTicker","u":600860073874,"s":"KEEPUSDT","b":"0.2465","B":"3767","a":"0.2467","A":"339","T":1626992759473,"E":1626992759478}}
1626992759.524128: {"stream":"sushiusdt@depth@100ms","data":{"e":"depthUpdate","E":1626992759480,"T":1626992759472,"s":"SUSHIUSDT","U":600860070820,"u":600860073853,"pu":600860069340,"b":[["6.1010","6480"],["6.4920","1621"],["7.1810","643"],["7.5070","1271"],["7.5520","1005"],["7.5790","727"],["7.5820","1015"],["7.5830","3742"],["7.5840","2682"],["7.5910","2788"],["7.6020","1183"],["7.6030","1680"],["7.6040","2309"],["7.6050","938"],["7.6070","2068"],["7.6080","1050"],["7.6090","683"],["7.6100","1360"],["7.6110","1076"],["7.6140","236"]],"a":[["7.6180","0"],["7.6190","158"],["7.6200","1081"],["7.6220","1903"],["7.6230","1395"],["7.6240","1384"],["7.6270","1391"],["7.6300","803"],["7.6310","2898"],["7.6330","2052"],["7.6400","1018"],["7.6450","3135"],["7.6480","739"],["7.6590","663"],["7.6610","805"]]}}
1626992759.5246358: {"stream":"ctkusdt@depth@100ms","data":{"e":"depthUpdate","E":1626992759482,"T":1626992759437,"s":"CTKUSDT","U":600860070883,"u":600860072845,"pu":600860068480,"b":[["1.00700","12890"],["1.01100","11661"]],"a":[["1.01200","103"],["1.01300","17269"],["1.01400","12819"],["1.04700","12856"]]}}
1626992759.5260642: {"stream":"akrousdt@depth@100ms","data":{"e":"depthUpdate","E":1626992759482,"T":1626992759468,"s":"AKROUSDT","U":600860070899,"u":600860073763,"pu":600860069798,"b":[["0.01726","419106"],["0.01731","184286"],["0.01732","237247"]],"a":[["0.01734","0"],["0.01735","168828"],["0.01737","251674"],["0.01740","822904"],["0.01741","648320"],["0.01742","364393"],["0.01743","445446"]]}}
1626992759.568937: {"stream":"keepusdt@bookTicker","data":{"e":"bookTicker","u":600860075258,"s":"KEEPUSDT","b":"0.2465","B":"3767","a":"0.2467","A":"1151","T":1626992759519,"E":1626992759524}}
1626992759.5741708: {"stream":"akrousdt@bookTicker","data":{"e":"bookTicker","u":600860075364,"s":"AKROUSDT","b":"0.01733","B":"57722","a":"0.01735","A":"170761","T":1626992759526,"E":1626992759529}}
1626992759.579572: {"stream":"keepusdt@depth@100ms","data":{"e":"depthUpdate","E":1626992759534,"T":1626992759530,"s":"KEEPUSDT","U":600860072555,"u":600860075580,"pu":600860068547,"b":[],"a":[["0.2467","1151"],["0.2472","9738"],["0.2473","22777"],["0.2475","15933"]]}}
1626992759.610352: {"stream":"sushiusdt@bookTicker","data":{"e":"bookTicker","u":600860076328,"s":"SUSHIUSDT","b":"7.6170","B":"16","a":"7.6190","A":"158","T":1626992759560,"E":1626992759564}}
1626992759.610452: {"stream":"sushiusdt@kline_1m","data":{"e":"kline","E":1626992759565,"s":"SUSHIUSDT","k":{"t":1626992700000,"T":1626992759999,"s":"SUSHIUSDT","i":"1m","f":126902874,"L":126902986,"o":"7.6080","c":"7.6170","h":"7.6180","l":"7.6070","v":"3005","n":113,"x":false,"q":"22875.8590","V":"1900","Q":"14464.6960","B":"0"}}}
1626992759.6267369: {"stream":"sushiusdt@depth@100ms","data":{"e":"depthUpdate","E":1626992759582,"T":1626992759576,"s":"SUSHIUSDT","U":600860073921,"u":600860076740,"pu":600860073853,"b":[["7.4340","902"],["7.4530","22"],["7.4870","195"],["7.5070","1273"],["7.5570","1062"],["7.5840","1181"],["7.5880","1386"],["7.5920","1733"],["7.5940","1203"],["7.5960","1108"],["7.6050","888"],["7.6070","2023"],["7.6080","1040"],["7.6090","738"],["7.6100","1252"],["7.6110","1139"],["7.6120","969"],["7.6150","103"],["7.6160","36"],["7.6170","16"]],"a":[["7.6220","994"],["7.6240","1454"],["7.6250","2886"],["7.6270","1714"],["7.6290","3975"],["7.6300","667"],["7.6340","2242"],["7.6460","398"],["7.6550","1311"],["7.7090","601"]]}}
1626992759.631158: {"stream":"ctkusdt@depth@100ms","data":{"e":"depthUpdate","E":1626992759586,"T":1626992759481,"s":"CTKUSDT","U":600860074096,"u":600860074096,"pu":600860072845,"b":[["1.00700","7947"]],"a":[]}}
1626992759.6312928: {"stream":"akrousdt@depth@100ms","data":{"e":"depthUpdate","E":1626992759587,"T":1626992759581,"s":"AKROUSDT","U":600860074182,"u":600860076829,"pu":600860073763,"b":[["0.01724","283669"],["0.01726","414400"],["0.01732","457154"]],"a":[["0.01735","170761"],["0.01736","88087"],["0.01737","266074"],["0.01738","644767"],["0.01739","542845"]]}}
1626992759.641877: {"stream":"ctkusdt@kline_1m","data":{"e":"kline","E":1626992759597,"s":"CTKUSDT","k":{"t":1626992700000,"T":1626992759999,"s":"CTKUSDT","i":"1m","f":23961275,"L":23961360,"o":"1.01000","c":"1.01200","h":"1.01200","l":"1.01000","v":"11074","n":86,"x":false,"q":"11193.49000","V":"8674","Q":"8769.44400","B":"0"}}}
1626992759.641998: {"stream":"ctkusdt@bookTicker","data":{"e":"bookTicker","u":600860077043,"s":"CTKUSDT","b":"1.01100","B":"11661","a":"1.01200","A":"93","T":1626992759592,"E":1626992759596}}
1626992759.682498: {"stream":"keepusdt@depth@100ms","data":{"e":"depthUpdate","E":1626992759637,"T":1626992759588,"s":"KEEPUSDT","U":600860075648,"u":600860076974,"pu":600860075580,"b":[["0.2458","19892"]],"a":[["0.2475","13033"],["0.2479","100572"]]}}
1626992759.726741: {"stream":"sushiusdt@depth@100ms","data":{"e":"depthUpdate","E":1626992759682,"T":1626992759622,"s":"SUSHIUSDT","U":600860076755,"u":600860077812,"pu":600860076740,"b":[["7.5770","486"],["7.5940","1348"],["7.5950","829"],["7.5960","2609"],["7.5970","1387"]],"a":[["7.6230","2185"],["7.6260","1856"],["7.6270","924"]]}}
1626992759.7417269: {"stream":"ctkusdt@depth@100ms","data":{"e":"depthUpdate","E":1626992759696,"T":1626992759592,"s":"CTKUSDT","U":600860077039,"u":600860077043,"pu":600860074096,"b":[["1.01500","0"]],"a":[["1.01200","93"]]}}
1626992759.74224: {"stream":"keepusdt@bookTicker","data":{"e":"bookTicker","u":600860079667,"s":"KEEPUSDT","b":"0.2465","B":"3767","a":"0.2467","A":"339","T":1626992759692,"E":1626992759697}}
1626992759.753619: {"stream":"akrousdt@bookTicker","data":{"e":"bookTicker","u":600860079877,"s":"AKROUSDT","b":"0.01733","B":"47960","a":"0.01735","A":"170761","T":1626992759704,"E":1626992759709}}
1626992759.756945: {"stream":"akrousdt@depth@100ms","data":{"e":"depthUpdate","E":1626992759712,"T":1626992759704,"s":"AKROUSDT","U":600860077413,"u":600860079877,"pu":600860076829,"b":[["0.01727","455762"],["0.01731","184286"],["0.01733","47960"]],"a":[["0.01737","280474"],["0.01739","483181"],["0.01740","822729"]]}}
1626992759.7620428: {"stream":"sushiusdt@aggTrade","data":{"e":"aggTrade","E":1626992759715,"a":87353257,"s":"SUSHIUSDT","p":"7.6170","q":"4","f":126902986,"l":126902986,"T":1626992759560,"m":true}}
1626992759.762141: {"stream":"akrousdt@bookTicker","data":{"e":"bookTicker","u":600860080097,"s":"AKROUSDT","b":"0.01733","B":"47960","a":"0.01734","A":"14610","T":1626992759712,"E":1626992759716}}
1626992759.7695968: {"stream":"sushiusdt@bookTicker","data":{"e":"bookTicker","u":600860080269,"s":"SUSHIUSDT","b":"7.6170","B":"13","a":"7.6190","A":"158","T":1626992759719,"E":1626992759724}}
1626992759.78271: {"stream":"keepusdt@bookTicker","data":{"e":"bookTicker","u":600860080545,"s":"KEEPUSDT","b":"0.2465","B":"3767","a":"0.2467","A":"1151","T":1626992759731,"E":1626992759734}}
1626992759.783325: {"stream":"sushiusdt@bookTicker","data":{"e":"bookTicker","u":600860080619,"s":"SUSHIUSDT","b":"7.6180","B":"3","a":"7.6190","A":"158","T":1626992759733,"E":1626992759737}}
1626992759.790472: {"stream":"ctkusdt@aggTrade","data":{"e":"aggTrade","E":1626992759747,"a":16599314,"s":"CTKUSDT","p":"1.01200","q":"10","f":23961360,"l":23961360,"T":1626992759592,"m":false}}
1626992759.7972: {"stream":"keepusdt@depth@100ms","data":{"e":"depthUpdate","E":1626992759753,"T":1626992759731,"s":"KEEPUSDT","U":600860078649,"u":600860080545,"pu":600860076974,"b":[["0.2451","15363"],["0.2452","6194"]],"a":[["0.2467","1151"],["0.2475","8820"],["0.2476","10786"],["0.2477","17546"]]}}
1626992759.822711: {"stream":"sushiusdt@bookTicker","data":{"e":"bookTicker","u":600860081561,"s":"SUSHIUSDT","b":"7.6180","B":"3","a":"7.6190","A":"132","T":1626992759774,"E":1626992759779}}
1626992759.861307: {"stream":"akrousdt@depth@100ms","data":{"e":"depthUpdate","E":1626992759816,"T":1626992759807,"s":"AKROUSDT","U":600860080097,"u":600860082285,"pu":600860079877,"b":[["0.01726","378827"],["0.01728","1128242"],["0.01732","370649"],["0.01734","0"]],"a":[["0.01734","14610"],["0.01735","168828"],["0.01736","102504"],["0.01737","294891"],["0.01738","664895"],["0.01740","842829"]]}}
1626992759.867759: {"stream":"sushiusdt@depth@100ms","data":{"e":"depthUpdate","E":1626992759824,"T":1626992759805,"s":"SUSHIUSDT","U":600860080269,"u":600860082229,"pu":600860077812,"b":[["7.5370","930"],["7.5550","407"],["7.5970","730"],["7.6000","1597"],["7.6010","2512"],["7.6050","638"],["7.6070","2273"],["7.6080","1011"],["7.6110","435"],["7.6120","489"],["7.6140","229"],["7.6150","139"],["7.6170","13"],["7.6180","3"]],"a":[["7.6190","132"],["7.6200","943"],["7.6210","595"],["7.6230","2170"],["7.6240","1469"],["7.6250","2987"],["7.6260","1948"],["7.6280","3173"],["7.6310","3172"]]}}
1626992759.948365: {"stream":"ctkusdt@bookTicker","data":{"e":"bookTicker","u":600860084345,"s":"CTKUSDT","b":"1.01100","B":"11661","a":"1.01200","A":"6045","T":1626992759901,"E":1626992759905}}
1626992759.982024: {"stream":"sushiusdt@depth@100ms","data":{"e":"depthUpdate","E":1626992759936,"T":1626992759928,"s":"SUSHIUSDT","U":600860082799,"u":600860084999,"pu":600860082229,"b":[["7.5430","3171"],["7.5440","524"],["7.5820","2515"],["7.6080","961"],["7.6110","613"],["7.6120","329"],["7.6130","342"],["7.6140","293"]],"a":[["7.6210","627"],["7.6220","1026"],["7.6230","1380"],["7.6270","1714"],["7.6350","2485"],["7.6370","2718"],["7.6540","1819"],["7.6810","236"]]}}
1626992759.992515: {"stream":"akrousdt@depth@100ms","data":{"e":"depthUpdate","E":1626992759947,"T":1626992759880,"s":"AKROUSDT","U":600860083101,"u":600860083878,"pu":600860082285,"b":[["0.01682","33926"],["0.01725","730942"]],"a":[["0.01738","653951"],["0.01743","431103"]]}}
1626992759.9978611: {"stream":"ctkusdt@bookTicker","data":{"e":"bookTicker","u":600860085412,"s":"CTKUSDT","b":"1.01100","B":"11661","a":"1.01200","A":"6050","T":1626992759947,"E":1626992759951}}
1626992760.007506: {"stream":"ctkusdt@depth@100ms","data":{"e":"depthUpdate","E":1626992759963,"T":1626992759957,"s":"CTKUSDT","U":600860083418,"u":600860085657,"pu":600860077043,"b":[["0.98200","8229"],["0.98700","6494"]],"a":[["1.01200","6050"],["1.01300","10257"]]}}
1626992760.037577: {"stream":"keepusdt@bookTicker","data":{"e":"bookTicker","u":600860086593,"s":"KEEPUSDT","b":"0.2465","B":"3767","a":"0.2467","A":"339","T":1626992759989,"E":1626992759994}}
1626992760.0732648: {"stream":"sushiusdt@bookTicker","data":{"e":"bookTicker","u":600860087516,"s":"SUSHIUSDT","b":"7.6180","B":"3","a":"7.6190","A":"130","T":1626992760027,"E":1626992760029}}
1626992760.080729: {"stream":"sushiusdt@depth@100ms","data":{"e":"depthUpdate","E":1626992760036,"T":1626992760032,"s":"SUSHIUSDT","U":600860085087,"u":600860087733,"pu":600860084999,"b":[["7.5400","861"],["7.5490","152"],["7.6150","132"],["7.6170","0"]],"a":[["7.6190","130"],["7.6210","744"],["7.6230","1563"],["7.6240","2259"],["7.6270","924"],["7.6440","4926"],["7.6850","2069"]]}}
1626992760.0871968: {"stream":"keepusdt@bookTicker","data":{"e":"bookTicker","u":600860087910,"s":"KEEPUSDT","b":"0.2465","B":"3767","a":"0.2467","A":"1151","T":1626992760036,"E":1626992760041}}
1626992760.093714: {"stream":"keepusdt@depth@100ms","data":{"e":"depthUpdate","E":1626992760049,"T":1626992760036,"s":"KEEPUSDT","U":600860085295,"u":600860087910,"pu":600860080545,"b":[["0.2382","10061"],["0.2435","37012"]],"a":[["0.2467","1151"]]}}
1626992760.0992541: {"stream":"akrousdt@depth@100ms","data":{"e":"depthUpdate","E":1626992760055,"T":1626992760020,"s":"AKROUSDT","U":600860085482,"u":600860087344,"pu":600860083878,"b":[["0.01731","185767"]],"a":[]}}
1626992760.1795871: {"stream":"ctkusdt@depth@100ms","data":{"e":"depthUpdate","E":1626992760133,"T":1626992760030,"s":"CTKUSDT","U":600860087596,"u":600860087664,"pu":600860085657,"b":[["0.99700","7625"]],"a":[["1.01500","15810"]]}}
1626992760.179729: {"stream":"sushiusdt@depth@100ms","data":{"e":"depthUpdate","E":1626992760137,"T":1626992760081,"s":"SUSHIUSDT","U":600860087756,"u":600860089067,"pu":600860087733,"b":[["7.5500","3717"],["7.5710","1982"],["7.6070","2366"],["7.6150","61"]],"a":[["7.6860","820"],["7.6890","3043"]]}}
1626992760.244919: {"stream":"akrousdt@depth@100ms","data":{"e":"depthUpdate","E":1626992760199,"T":1626992760177,"s":"AKROUSDT","U":600860089179,"u":600860090415,"pu":600860087344,"b":[["0.01689","614194"],["0.01729","630837"]],"a":[["0.01740","862929"]]}}
1626992760.247864: {"stream":"sushiusdt@kline_1m","data":{"e":"kline","E":1626992760203,"s":"SUSHIUSDT","k":{"t":1626992700000,"T":1626992759999,"s":"SUSHIUSDT","i":"1m","f":126902874,"L":126902986,"o":"7.6080","c":"7.6170","h":"7.6180","l":"7.6070","v":"3005","n":113,"x":true,"q":"22875.8590","V":"1900","Q":"14464.6960","B":"0"}}}
1626992760.249877: {"stream":"sushiusdt@bookTicker","data":{"e":"bookTicker","u":600860091436,"s":"SUSHIUSDT","b":"7.6160","B":"36","a":"7.6190","A":"130","T":1626992760198,"E":1626992760203}}
1626992760.284288: {"stream":"keepusdt@bookTicker","data":{"e":"bookTicker","u":600860092481,"s":"KEEPUSDT","b":"0.2465","B":"3767","a":"0.2467","A":"339","T":1626992760235,"E":1626992760240}}
1626992760.28439: {"stream":"akrousdt@bookTicker","data":{"e":"bookTicker","u":600860092498,"s":"AKROUSDT","b":"0.01733","B":"57722","a":"0.01734","A":"14610","T":1626992760235,"E":1626992760240}}
1626992760.295972: {"stream":"ctkusdt@depth@100ms","data":{"e":"depthUpdate","E":1626992760253,"T":1626992760146,"s":"CTKUSDT","U":600860089807,"u":600860089807,"pu":600860087664,"b":[],"a":[["1.01400","12827"]]}}
1626992760.30125: {"stream":"sushiusdt@bookTicker","data":{"e":"bookTicker","u":600860092964,"s":"SUSHIUSDT","b":"7.6150","B":"25","a":"7.6190","A":"130","T":1626992760250,"E":1626992760256}}
1626992760.3184159: {"stream":"sushiusdt@depth@100ms","data":{"e":"depthUpdate","E":1626992760273,"T":1626992760267,"s":"SUSHIUSDT","U":600860090154,"u":600860093371,"pu":600860089067,"b":[["7.5580","815"],["7.5700","229"],["7.5710","1943"],["7.5790","737"],["7.5830","3732"],["7.5920","1743"],["7.5950","819"],["7.6000","1860"],["7.6020","1265"],["7.6040","2319"],["7.6080","1031"],["7.6090","668"],["7.6100","384"],["7.6110","1317"],["7.6130","310"],["7.6140","229"],["7.6150","25"],["7.6160","0"],["7.6180","0"]],"a":[["7.6200","1080"],["7.6210","731"],["7.6220","1041"],["7.6230","3089"],["7.6240","2244"],["7.6250","1461"],["7.6280","3303"],["7.6290","3845"],["7.6310","3308"],["7.6370","2241"],["7.6380","799"],["7.6420","661"]]}}
1626992760.33003: {"stream":"keepusdt@bookTicker","data":{"e":"bookTicker","u":600860093665,"s":"KEEPUSDT","b":"0.2465","B":"3767","a":"0.2467","A":"1151","T":1626992760279,"E":1626992760284}}
1626992760.332161: {"stream":"sushiusdt@bookTicker","data":{"e":"bookTicker","u":600860093737,"s":"SUSHIUSDT","b":"7.6150","B":"230","a":"7.6190","A":"130","T":1626992760283,"E":1626992760286}}
1626992760.335403: {"stream":"sushiusdt@bookTicker","data":{"e":"bookTicker","u":600860093786,"s":"SUSHIUSDT","b":"7.6150","B":"230","a":"7.6190","A":"150","T":1626992760285,"E":1626992760290}}
1626992760.340853: {"stream":"keepusdt@depth@100ms","data":{"e":"depthUpdate","E":1626992760294,"T":1626992760279,"s":"KEEPUSDT","U":600860090892,"u":600860093665,"pu":600860087910,"b":[["0.2446","8446"]],"a":[["0.2467","1151"]]}}
1626992760.341017: {"stream":"sushiusdt@bookTicker","data":{"e":"bookTicker","u":600860093953,"s":"SUSHIUSDT","b":"7.6160","B":"81","a":"7.6190","A":"150","T":1626992760292,"E":1626992760295}}
1626992760.363005: {"stream":"akrousdt@depth@100ms","data":{"e":"depthUpdate","E":1626992760317,"T":1626992760295,"s":"AKROUSDT","U":600860091876,"u":600860094005,"pu":600860090415,"b":[["0.01688","144899"],["0.01727","491315"],["0.01733","57722"]],"a":[["0.01740","922683"],["0.01741","656935"],["0.01743","382385"]]}}
1626992760.402207: {"stream":"sushiusdt@aggTrade","data":{"e":"aggTrade","E":1626992760353,"a":87353258,"s":"SUSHIUSDT","p":"7.6180","q":"3","f":126902987,"l":126902987,"T":1626992760198,"m":true}}
1626992760.418185: {"stream":"sushiusdt@bookTicker","data":{"e":"bookTicker","u":600860095550,"s":"SUSHIUSDT","b":"7.6160","B":"78","a":"7.6190","A":"150","T":1626992760368,"E":1626992760372}}
1626992760.4213068: {"stream":"sushiusdt@depth@100ms","data":{"e":"depthUpdate","E":1626992760374,"T":1626992760368,"s":"SUSHIUSDT","U":600860093467,"u":600860095550,"pu":600860093371,"b":[["7.5190","132"],["7.5430","2999"],["7.5490","2384"],["7.5540","76"],["7.5590","7150"],["7.5660","219"],["7.5710","2009"],["7.5860","1099"],["7.6080","893"],["7.6090","1664"],["7.6110","1189"],["7.6120","344"],["7.6140","179"],["7.6150","230"],["7.6160","78"],["7.6950","0"]],"a":[["7.6190","150"],["7.6200","1138"],["7.6220","1831"],["7.6230","2997"],["7.6240","1234"],["7.6250","1981"],["7.6340","5392"],["7.6540","1818"],["7.6630","500"],["7.6880","2430"],["7.6990","270"],["7.7080","1964"],["7.7450","3138"],["7.7540","13"]]}}
1626992760.442091: {"stream":"sushiusdt@bookTicker","data":{"e":"bookTicker","u":600860096154,"s":"SUSHIUSDT","b":"7.6160","B":"78","a":"7.6180","A":"54","T":1626992760392,"E":1626992760397}}
1626992760.492697: {"stream":"keepusdt@depth@100ms","data":{"e":"depthUpdate","E":1626992760446,"T":1626992760434,"s":"KEEPUSDT","U":600860095034,"u":600860097067,"pu":600860093665,"b":[],"a":[["0.2475","17383"]]}}
1626992760.492827: {"stream":"akrousdt@depth@100ms","data":{"e":"depthUpdate","E":1626992760446,"T":1626992760367,"s":"AKROUSDT","U":600860095054,"u":600860095538,"pu":600860094005,"b":[["0.01728","1079102"]],"a":[["0.01747","101919"]]}}
1626992760.500382: {"stream":"ctkusdt@depth@100ms","data":{"e":"depthUpdate","E":1626992760458,"T":1626992760354,"s":"CTKUSDT","U":600860095305,"u":600860095305,"pu":600860089807,"b":[["1.00200","16075"]],"a":[]}}
1626992760.5185761: {"stream":"sushiusdt@depth@100ms","data":{"e":"depthUpdate","E":1626992760474,"T":1626992760461,"s":"SUSHIUSDT","U":600860095577,"u":600860097625,"pu":600860095550,"b":[["7.5180","785"],["7.5340","9291"],["7.5480","565"],["7.5640","801"],["7.5940","1378"],["7.5970","700"],["7.6020","1183"],["7.6040","738"],["7.6070","2366"],["7.6080","2197"],["7.6090","1501"],["7.6100","512"],["7.6110","1139"],["7.6140","150"]],"a":[["7.6180","54"],["7.6220","1891"],["7.6230","3247"],["7.6250","1731"],["7.6280","3959"]]}}
1626992760.52061: {"stream":"sushiusdt@bookTicker","data":{"e":"bookTicker","u":600860097822,"s":"SUSHIUSDT","b":"7.6160","B":"91","a":"7.6180","A":"54","T":1626992760470,"E":1626992760475}}
1626992760.520679: {"stream":"keepusdt@bookTicker","data":{"e":"bookTicker","u":600860097851,"s":"KEEPUSDT","b":"0.2465","B":"3767","a":"0.2467","A":"339","T":1626992760471,"E":1626992760475}}
1626992760.5509272: {"stream":"keepusdt@bookTicker","data":{"e":"bookTicker","u":600860098584,"s":"KEEPUSDT","b":"0.2465","B":"3767","a":"0.2468","A":"1017","T":1626992760503,"E":1626992760505}}
1626992760.567261: {"stream":"keepusdt@bookTicker","data":{"e":"bookTicker","u":600860098925,"s":"KEEPUSDT","b":"0.2465","B":"3767","a":"0.2468","A":"1828","T":1626992760515,"E":1626992760521}}
1626992760.567362: {"stream":"sushiusdt@aggTrade","data":{"e":"aggTrade","E":1626992760523,"a":87353259,"s":"SUSHIUSDT","p":"7.6160","q":"3","f":126902988,"l":126902988,"T":1626992760368,"m":true}}
1626992760.612545: {"stream":"ctkusdt@depth@100ms","data":{"e":"depthUpdate","E":1626992760567,"T":1626992760465,"s":"CTKUSDT","U":600860097707,"u":600860097707,"pu":600860095305,"b":[["1.00100","75793"]],"a":[]}}
1626992760.620218: {"stream":"keepusdt@depth@100ms","data":{"e":"depthUpdate","E":1626992760575,"T":1626992760568,"s":"KEEPUSDT","U":600860097851,"u":600860100118,"pu":600860097067,"b":[["0.2445","69676"],["0.2456","16799"],["0.2458","15794"],["0.2459","5104"],["0.2460","1358"]],"a":[["0.2467","0"],["0.2468","1828"],["0.2475","20283"],["0.2476","13686"]]}}
1626992760.620424: {"stream":"sushiusdt@depth@100ms","data":{"e":"depthUpdate","E":1626992760575,"T":1626992760560,"s":"SUSHIUSDT","U":600860097822,"u":600860099978,"pu":600860097625,"b":[["7.6070","3087"],["7.6080","2197"],["7.6090","1501"],["7.6160","91"]],"a":[["7.6200","1145"],["7.6210","724"]]}}
1626992760.709406: {"stream":"akrousdt@bookTicker","data":{"e":"bookTicker","u":600860102500,"s":"AKROUSDT","b":"0.01733","B":"24307","a":"0.01734","A":"14610","T":1626992760658,"E":1626992760663}}
1626992760.714168: {"stream":"ctkusdt@depth@100ms","data":{"e":"depthUpdate","E":1626992760670,"T":1626992760618,"s":"CTKUSDT","U":600860100061,"u":600860101371,"pu":600860097707,"b":[["1.00300","5769"]],"a":[["1.01600","27320"]]}}
1626992760.734637: {"stream":"sushiusdt@depth@100ms","data":{"e":"depthUpdate","E":1626992760686,"T":1626992760662,"s":"SUSHIUSDT","U":600860100486,"u":600860102615,"pu":600860099978,"b":[["7.5580","799"],["7.6070","2246"],["7.6080","2918"]],"a":[["7.6280","4401"],["7.6340","5474"]]}}
1626992760.766294: {"stream":"keepusdt@bookTicker","data":{"e":"bookTicker","u":600860104842,"s":"KEEPUSDT","b":"0.2465","B":"3767","a":"0.2468","A":"1017","T":1626992760711,"E":1626992760718}}
1626992760.782763: {"stream":"akrousdt@depth@100ms","data":{"e":"depthUpdate","E":1626992760737,"T":1626992760711,"s":"AKROUSDT","U":600860101731,"u":600860104886,"pu":600860095538,"b":[["0.01726","667261"],["0.01731","129767"],["0.01732","311649"],["0.01733","24307"]],"a":[["0.01823","547779"]]}}
1626992760.809346: {"stream":"keepusdt@bookTicker","data":{"e":"bookTicker","u":600860107400,"s":"KEEPUSDT","b":"0.2465","B":"3767","a":"0.2468","A":"1828","T":1626992760759,"E":1626992760765}}
1626992760.816781: {"stream":"keepusdt@depth@100ms","data":{"e":"depthUpdate","E":1626992760771,"T":1626992760759,"s":"KEEPUSDT","U":600860102757,"u":600860107400,"pu":600860100118,"b":[],"a":[["0.2468","1828"],["0.2475","16070"]]}}
1626992760.8200488: {"stream":"ctkusdt@depth@100ms","data":{"e":"depthUpdate","E":1626992760775,"T":1626992760670,"s":"CTKUSDT","U":600860102873,"u":600860102873,"pu":600860101371,"b":[],"a":[["1.01600","22377"]]}}
1626992760.8375711: {"stream":"ctkusdt@kline_1m","data":{"e":"kline","E":1626992760791,"s":"CTKUSDT","k":{"t":1626992700000,"T":1626992759999,"s":"CTKUSDT","i":"1m","f":23961275,"L":23961360,"o":"1.01000","c":"1.01200","h":"1.01200","l":"1.01000","v":"11074","n":86,"x":true,"q":"11193.49000","V":"8674","Q":"8769.44400","B":"0"}}}
1626992760.837693: {"stream":"ctkusdt@bookTicker","data":{"e":"bookTicker","u":600860108471,"s":"CTKUSDT","b":"1.01100","B":"11661","a":"1.01200","A":"6040","T":1626992760784,"E":1626992760791}}
1626992760.868276: {"stream":"sushiusdt@depth@100ms","data":{"e":"depthUpdate","E":1626992760821,"T":1626992760814,"s":"SUSHIUSDT","U":600860104954,"u":600860109596,"pu":600860102615,"b":[["7.5670","49"],["7.6080","2918"],["7.6090","1501"]],"a":[["7.6190","176"],["7.6200","1197"],["7.6220","1831"],["7.6280","3745"],["7.6320","1870"]]}}
1626992760.874605: {"stream":"sushiusdt@bookTicker","data":{"e":"bookTicker","u":600860109910,"s":"SUSHIUSDT","b":"7.6170","B":"4","a":"7.6180","A":"54","T":1626992760822,"E":1626992760828}}
1626992760.874706: {"stream":"sushiusdt@bookTicker","data":{"e":"bookTicker","u":600860109944,"s":"SUSHIUSDT","b":"7.6170","B":"5","a":"7.6180","A":"54","T":1626992760823,"E":1626992760828}}
1626992760.929197: {"stream":"keepusdt@bookTicker","data":{"e":"bookTicker","u":600860111883,"s":"KEEPUSDT","b":"0.2465","B":"3767","a":"0.2468","A":"1017","T":1626992760878,"E":1626992760883}}
1626992760.929294: {"stream":"akrousdt@depth@100ms","data":{"e":"depthUpdate","E":1626992760884,"T":1626992760863,"s":"AKROUSDT","U":600860108251,"u":600860111387,"pu":600860104886,"b":[["0.01732","268397"]],"a":[["0.01735","197670"],["0.01736","88083"],["0.01737","280474"],["0.01738","671251"],["0.01791","404693"]]}}
1626992760.933258: {"stream":"sushiusdt@aggTrade","data":{"e":"aggTrade","E":1626992760885,"a":87353260,"s":"SUSHIUSDT","p":"7.6180","q":"54","f":126902989,"l":126902989,"T":1626992760880,"m":false}}
1626992760.933376: {"stream":"sushiusdt@aggTrade","data":{"e":"aggTrade","E":1626992760885,"a":87353261,"s":"SUSHIUSDT","p":"7.6190","q":"156","f":126902990,"l":126902992,"T":1626992760881,"m":false}}
1626992760.9334242: {"stream":"sushiusdt@bookTicker","data":{"e":"bookTicker","u":600860111966,"s":"SUSHIUSDT","b":"7.6170","B":"5","a":"7.6200","A":"1029","T":1626992760881,"E":1626992760885}}
1626992760.933465: {"stream":"sushiusdt@kline_1m","data":{"e":"kline","E":1626992760886,"s":"SUSHIUSDT","k":{"t":1626992760000,"T":1626992819999,"s":"SUSHIUSDT","i":"1m","f":126902987,"L":126902989,"o":"7.6180","c":"7.6180","h":"7.6180","l":"7.6160","v":"60","n":3,"x":false,"q":"457.0740","V":"54","Q":"411.3720","B":"0"}}}
1626992760.935669: {"stream":"ctkusdt@depth@100ms","data":{"e":"depthUpdate","E":1626992760891,"T":1626992760858,"s":"CTKUSDT","U":600860108467,"u":600860111244,"pu":600860102873,"b":[["1.00100","76192"],["1.01500","0"]],"a":[["1.01200","6040"]]}}
1626992760.940444: {"stream":"sushiusdt@bookTicker","data":{"e":"bookTicker","u":600860112363,"s":"SUSHIUSDT","b":"7.6170","B":"5","a":"7.6200","A":"721","T":1626992760892,"E":1626992760897}}
1626992760.94812: {"stream":"keepusdt@depth@100ms","data":{"e":"depthUpdate","E":1626992760906,"T":1626992760898,"s":"KEEPUSDT","U":600860109113,"u":600860112577,"pu":600860107400,"b":[["0.2379","266790"],["0.2456","13889"],["0.2457","6834"],["0.2459","6999"]],"a":[["0.2468","1017"]]}}
1626992760.950253: {"stream":"sushiusdt@bookTicker","data":{"e":"bookTicker","u":600860112733,"s":"SUSHIUSDT","b":"7.6170","B":"5","a":"7.6200","A":"714","T":1626992760903,"E":1626992760907}}
1626992760.950367: {"stream":"sushiusdt@bookTicker","data":{"e":"bookTicker","u":600860112749,"s":"SUSHIUSDT","b":"7.6170","B":"5","a":"7.6200","A":"694","T":1626992760904,"E":1626992760907}}
1626992760.953305: {"stream":"keepusdt@bookTicker","data":{"e":"bookTicker","u":600860112789,"s":"KEEPUSDT","b":"0.2465","B":"3767","a":"0.2468","A":"339","T":1626992760905,"E":1626992760909}}
1626992760.957686: {"stream":"sushiusdt@bookTicker","data":{"e":"bookTicker","u":600860112873,"s":"SUSHIUSDT","b":"7.6170","B":"5","a":"7.6190","A":"30","T":1626992760908,"E":1626992760914}}
1626992760.971832: {"stream":"sushiusdt@depth@100ms","data":{"e":"depthUpdate","E":1626992760928,"T":1626992760920,"s":"SUSHIUSDT","U":600860109910,"u":600860113180,"pu":600860109596,"b":[["7.5980","1265"],["7.6070","2316"],["7.6080","2848"],["7.6090","613"],["7.6100","1380"],["7.6120","376"],["7.6130","374"],["7.6150","259"],["7.6170","5"]],"a":[["7.6180","0"],["7.6190","30"],["7.6200","694"],["7.6210","660"],["7.6220","1868"],["7.6230","1518"],["7.6250","3257"],["7.6270","1069"],["7.6280","2431"],["7.6290","5159"]]}}
1626992760.9724731: {"stream":"keepusdt@bookTicker","data":{"e":"bookTicker","u":600860113252,"s":"KEEPUSDT","b":"0.2465","B":"3767","a":"0.2468","A":"1150","T":1626992760922,"E":1626992760928}}
1626992760.986839: {"stream":"ctkusdt@aggTrade","data":{"e":"aggTrade","E":1626992760942,"a":16599315,"s":"CTKUSDT","p":"1.01200","q":"10","f":23961361,"l":23961361,"T":1626992760784,"m":false}}
1626992761.045567: {"stream":"keepusdt@bookTicker","data":{"e":"bookTicker","u":600860115030,"s":"KEEPUSDT","b":"0.2465","B":"549","a":"0.2468","A":"1150","T":1626992760996,"E":1626992761000}}
1626992761.051949: {"stream":"akrousdt@depth@100ms","data":{"e":"depthUpdate","E":1626992761006,"T":1626992760966,"s":"AKROUSDT","U":600860112635,"u":600860114332,"pu":600860111387,"b":[["0.01726","619839"],["0.01727","538710"],["0.01730","158974"]],"a":[["0.01738","723151"]]}}
1626992761.052126: {"stream":"keepusdt@bookTicker","data":{"e":"bookTicker","u":600860115170,"s":"KEEPUSDT","b":"0.2466","B":"3218","a":"0.2468","A":"1150","T":1626992761001,"E":1626992761006}}
1626992761.0552099: {"stream":"keepusdt@depth@100ms","data":{"e":"depthUpdate","E":1626992761009,"T":1626992761001,"s":"KEEPUSDT","U":600860112789,"u":600860115170,"pu":600860112577,"b":[["0.2431","12251"],["0.2433","40232"],["0.2445","65266"],["0.2447","6659"],["0.2465","549"],["0.2466","3218"]],"a":[["0.2468","1150"],["0.2469","1744"],["0.2471","8758"],["0.2472","11457"]]}}
1626992761.073996: {"stream":"sushiusdt@depth@100ms","data":{"e":"depthUpdate","E":1626992761030,"T":1626992761024,"s":"SUSHIUSDT","U":600860113340,"u":600860115854,"pu":600860113180,"b":[["7.6000","1529"],["7.6060","799"],["7.6090","996"],["7.6100","1252"],["7.6120","504"],["7.6140","157"],["7.6160","78"]],"a":[["7.6200","615"],["7.6210","563"],["7.6220","1058"],["7.6230","2421"],["7.6240","961"],["7.6260","1634"],["7.6290","4228"],["7.6300","785"],["7.6310","3925"],["7.6380","769"],["7.6420","691"]]}}
1626992761.0804422: {"stream":"sushiusdt@aggTrade","data":{"e":"aggTrade","E":1626992761036,"a":87353262,"s":"SUSHIUSDT","p":"7.6200","q":"58","f":126902993,"l":126902993,"T":1626992760881,"m":false}}
1626992761.164138: {"stream":"keepusdt@depth@100ms","data":{"e":"depthUpdate","E":1626992761117,"T":1626992761069,"s":"KEEPUSDT","U":600860115479,"u":600860117024,"pu":600860115170,"b":[],"a":[["0.2470","12327"],["0.2472","7891"],["0.2473","22138"],["0.2474","6432"],["0.2475","4469"],["0.2476","10786"],["0.2497","6799"]]}}
1626992761.1864262: {"stream":"akrousdt@depth@100ms","data":{"e":"depthUpdate","E":1626992761143,"T":1626992761038,"s":"AKROUSDT","U":600860116301,"u":600860116301,"pu":600860114332,"b":[["0.01730","126034"]],"a":[]}}
1626992761.1915572: {"stream":"sushiusdt@depth@100ms","data":{"e":"depthUpdate","E":1626992761147,"T":1626992761117,"s":"SUSHIUSDT","U":600860116437,"u":600860117629,"pu":600860115854,"b":[["3.8070","0"],["7.5960","1108"]],"a":[["7.6210","680"],["7.6230","1631"],["7.6300","1099"],["7.6330","1889"],["7.6430","2821"],["7.6440","2336"],["7.6990","37"]]}}
1626992761.202601: {"stream":"ctkusdt@depth@100ms","data":{"e":"depthUpdate","E":1626992761156,"T":1626992761052,"s":"CTKUSDT","U":600860116648,"u":600860116648,"pu":600860111244,"b":[["0.98700","7506"]],"a":[]}}
1626992761.241243: {"stream":"sushiusdt@bookTicker","data":{"e":"bookTicker","u":600860118966,"s":"SUSHIUSDT","b":"7.6180","B":"3","a":"7.6190","A":"30","T":1626992761189,"E":1626992761195}}
1626992761.29214: {"stream":"sushiusdt@depth@100ms","data":{"e":"depthUpdate","E":1626992761247,"T":1626992761233,"s":"SUSHIUSDT","U":600860117784,"u":600860120922,"pu":600860117629,"b":[["7.5830","3263"],["7.5840","2682"],["7.5950","992"],["7.6070","2972"],["7.6110","420"],["7.6140","150"],["7.6180","3"]],"a":[["7.6200","655"],["7.6210","660"],["7.6230","1616"],["7.6240","1766"],["7.6260","1766"],["7.6290","4365"],["7.6310","4198"],["7.6350","2143"],["7.6370","2066"],["7.6380","816"],["7.6390","3054"],["7.6400","1744"],["7.6510","1874"],["7.6520","3894"],["7.6610","1130"],["7.6850","2043"],["7.7050","1006"],["7.7190","234"]]}}
1626992761.319026: {"stream":"keepusdt@depth@100ms","data":{"e":"depthUpdate","E":1626992761274,"T":1626992761220,"s":"KEEPUSDT","U":600860118190,"u":600860120403,"pu":600860117024,"b":[],"a":[["0.2471","10454"],["0.2476","15000"],["0.2486","10340"]]}}
1626992761.322303: {"stream":"akrousdt@depth@100ms","data":{"e":"depthUpdate","E":1626992761276,"T":1626992761258,"s":"AKROUSDT","U":600860118284,"u":600860121732,"pu":600860116301,"b":[["0.01731","129767"]],"a":[["0.01740","942783"],["0.01741","716630"],["0.01771","60501"]]}}
1626992761.385311: {"stream":"sushiusdt@bookTicker","data":{"e":"bookTicker","u":600860123596,"s":"SUSHIUSDT","b":"7.6180","B":"7","a":"7.6190","A":"30","T":1626992761333,"E":1626992761340}}
1626992761.3946712: {"stream":"sushiusdt@depth@100ms","data":{"e":"depthUpdate","E":1626992761351,"T":1626992761333,"s":"SUSHIUSDT","U":600860121256,"u":600860123596,"pu":600860120922,"b":[["3.8090","26"],["7.5480","519"],["7.5540","70"],["7.5620","2186"],["7.5650","137"],["7.5810","565"],["7.5840","3151"],["7.6070","2902"],["7.6080","2918"],["7.6110","563"],["7.6120","361"],["7.6150","266"],["7.6170","0"],["7.6180","7"]],"a":[["7.6280","2561"],["7.6290","4235"],["7.6350","2621"],["7.6360","3742"],["7.6470","3230"],["7.6520","4363"]]}}
1626992761.403452: {"stream":"sushiusdt@bookTicker","data":{"e":"bookTicker","u":600860124098,"s":"SUSHIUSDT","b":"7.6180","B":"8","a":"7.6190","A":"30","T":1626992761353,"E":1626992761358}}
1626992761.450047: {"stream":"ctkusdt@depth@100ms","data":{"e":"depthUpdate","E":1626992761406,"T":1626992761353,"s":"CTKUSDT","U":600860122864,"u":600860124109,"pu":600860116648,"b":[["1.00300","5520"],["1.01000","82417"]],"a":[]}}
1626992761.450187: {"stream":"keepusdt@depth@100ms","data":{"e":"depthUpdate","E":1626992761406,"T":1626992761389,"s":"KEEPUSDT","U":600860122844,"u":600860124915,"pu":600860120403,"b":[["0.2442","11854"]],"a":[["0.2469","1057"],["0.2470","13014"],["0.2476","6540"]]}}
1626992761.501812: {"stream":"sushiusdt@depth@100ms","data":{"e":"depthUpdate","E":1626992761456,"T":1626992761449,"s":"SUSHIUSDT","U":600860123959,"u":600860126322,"pu":600860123596,"b":[["7.5640","847"],["7.5830","3180"],["7.5890","1145"],["7.6040","712"],["7.6110","1063"],["7.6120","1080"],["7.6180","8"]],"a":[["7.6230","1397"],["7.6240","3051"],["7.6250","1512"],["7.6270","1144"],["7.6280","3826"],["7.6290","3051"]]}}
1626992761.503259: {"stream":"akrousdt@depth@100ms","data":{"e":"depthUpdate","E":1626992761458,"T":1626992761384,"s":"AKROUSDT","U":600860124112,"u":600860124808,"pu":600860121732,"b":[["0.01726","630871"],["0.01730","158974"]],"a":[["0.01737","326474"]]}}
1626992761.546284: {"stream":"sushiusdt@bookTicker","data":{"e":"bookTicker","u":600860127202,"s":"SUSHIUSDT","b":"7.6180","B":"21","a":"7.6190","A":"30","T":1626992761493,"E":1626992761500}}
1626992761.561106: {"stream":"keepusdt@bookTicker","data":{"e":"bookTicker","u":600860127568,"s":"KEEPUSDT","b":"0.2465","B":"549","a":"0.2468","A":"1150","T":1626992761508,"E":1626992761516}}
1626992761.5644329: {"stream":"keepusdt@bookTicker","data":{"e":"bookTicker","u":600860127623,"s":"KEEPUSDT","b":"0.2465","B":"549","a":"0.2468","A":"811","T":1626992761511,"E":1626992761519}}
1626992761.564536: {"stream":"keepusdt@depth@100ms","data":{"e":"depthUpdate","E":1626992761521,"T":1626992761512,"s":"KEEPUSDT","U":600860125549,"u":600860127640,"pu":600860124915,"b":[["0.2455","16898"],["0.2461","339"],["0.2462","339"],["0.2466","0"]],"a":[["0.2468","811"],["0.2469","718"],["0.2471","6068"],["0.2479","109030"]]}}
1626992761.5647109: {"stream":"keepusdt@bookTicker","data":{"e":"bookTicker","u":600860127745,"s":"KEEPUSDT","b":"0.2467","B":"3218","a":"0.2468","A":"811","T":1626992761516,"E":1626992761521}}
1626992761.60715: {"stream":"keepusdt@bookTicker","data":{"e":"bookTicker","u":600860128530,"s":"KEEPUSDT","b":"0.2467","B":"3675","a":"0.2468","A":"811","T":1626992761554,"E":1626992761561}}
1626992761.613568: {"stream":"akrousdt@depth@100ms","data":{"e":"depthUpdate","E":1626992761569,"T":1626992761527,"s":"AKROUSDT","U":600860126665,"u":600860127981,"pu":600860124808,"b":[["0.01557","80333"],["0.01726","622181"],["0.01730","169979"]],"a":[["0.01739","494130"],["0.01743","393308"]]}}
1626992761.61373: {"stream":"sushiusdt@depth@100ms","data":{"e":"depthUpdate","E":1626992761570,"T":1626992761553,"s":"SUSHIUSDT","U":600860126698,"u":600860128490,"pu":600860126322,"b":[["7.5500","3757"],["7.5750","3211"],["7.5850","1525"],["7.6110","935"],["7.6130","502"],["7.6150","266"],["7.6180","21"]],"a":[["7.6230","2187"],["7.6240","2261"],["7.6250","1500"],["7.6270","1458"],["7.6300","1099"],["7.6330","1587"],["7.6680","954"],["7.6750","2586"]]}}
1626992761.6614861: {"stream":"ctkusdt@depth@100ms","data":{"e":"depthUpdate","E":1626992761617,"T":1626992761606,"s":"CTKUSDT","U":600860127592,"u":600860129634,"pu":600860124109,"b":[["0.98600","109"],["1.00400","5273"],["1.00700","12890"]],"a":[["1.01400","14211"],["1.01600","27320"]]}}
1626992761.667509: {"stream":"keepusdt@depth@100ms","data":{"e":"depthUpdate","E":1626992761621,"T":1626992761555,"s":"KEEPUSDT","U":600860127745,"u":600860128543,"pu":600860127640,"b":[["0.2465","0"],["0.2467","3675"]],"a":[]}}
1626992761.7332978: {"stream":"akrousdt@depth@100ms","data":{"e":"depthUpdate","E":1626992761690,"T":1626992761635,"s":"AKROUSDT","U":600860129154,"u":600860130196,"pu":600860127981,"b":[["0.01708","726245"],["0.01727","547395"]],"a":[]}}
1626992761.7375062: {"stream":"sushiusdt@depth@100ms","data":{"e":"depthUpdate","E":1626992761692,"T":1626992761681,"s":"SUSHIUSDT","U":600860129226,"u":600860131171,"pu":600860128490,"b":[["7.5960","1133"],["7.6100","1278"],["7.6110","920"],["7.6130","517"],["7.6160","156"]],"a":[]}}
1626992761.768513: {"stream":"ctkusdt@depth@100ms","data":{"e":"depthUpdate","E":1626992761724,"T":1626992761716,"s":"CTKUSDT","U":600860129861,"u":600860131967,"pu":600860129634,"b":[["0.98500","17007"],["0.99100","12441"],["1.00400","5024"],["1.00700","7947"]],"a":[["1.01600","22377"]]}}
1626992761.795056: {"stream":"keepusdt@depth@100ms","data":{"e":"depthUpdate","E":1626992761751,"T":1626992761744,"s":"KEEPUSDT","U":600860130397,"u":600860132615,"pu":600860128543,"b":[["0.2384","10541"],["0.2424","0"],["0.2440","3950"],["0.2442","11830"],["0.2450","92376"],["0.2452","6881"],["0.2454","4201"],["0.2455","17576"]],"a":[["0.2474","7071"],["0.2506","27"]]}}
1626992761.902493: {"stream":"ctkusdt@depth@100ms","data":{"e":"depthUpdate","E":1626992761852,"T":1626992761811,"s":"CTKUSDT","U":600860132688,"u":600860134509,"pu":600860131967,"b":[["0.98300","11139"],["0.98700","9935"],["0.98900","2203"],["1.00000","84732"]],"a":[]}}
1626992761.915784: {"stream":"ctkusdt@bookTicker","data":{"e":"bookTicker","u":600860135807,"s":"CTKUSDT","b":"1.01100","B":"11661","a":"1.01200","A":"6766","T":1626992761865,"E":1626992761870}}
1626992761.919897: {"stream":"keepusdt@depth@100ms","data":{"e":"depthUpdate","E":1626992761875,"T":1626992761794,"s":"KEEPUSDT","U":600860133144,"u":600860133986,"pu":600860132615,"b":[["0.2442","13466"]],"a":[["0.2508","10536"]]}}
1626992761.942074: {"stream":"sushiusdt@depth@100ms","data":{"e":"depthUpdate","E":1626992761897,"T":1626992761880,"s":"SUSHIUSDT","U":600860133909,"u":600860136156,"pu":600860131171,"b":[["7.5170","400"],["7.5820","1015"],["7.6150","266"]],"a":[["7.6240","2313"],["7.6540","318"]]}}
1626992761.987805: {"stream":"akrousdt@depth@100ms","data":{"e":"depthUpdate","E":1626992761942,"T":1626992761874,"s":"AKROUSDT","U":600860135143,"u":600860136023,"pu":600860130196,"b":[["0.01730","137039"],["0.01731","127240"]],"a":[["0.01738","770151"]]}}
1626992762.015189: {"stream":"ctkusdt@kline_1m","data":{"e":"kline","E":1626992761970,"s":"CTKUSDT","k":{"t":1626992760000,"T":1626992819999,"s":"CTKUSDT","i":"1m","f":23961361,"L":23961362,"o":"1.01200","c":"1.01200","h":"1.01200","l":"1.01200","v":"20","n":2,"x":false,"q":"20.24000","V":"20","Q":"20.24000","B":"0"}}}
1626992762.015272: {"stream":"ctkusdt@depth@100ms","data":{"e":"depthUpdate","E":1626992761970,"T":1626992761917,"s":"CTKUSDT","U":600860135807,"u":600860136927,"pu":600860134509,"b":[["1.00200","16196"]],"a":[["1.01200","6766"],["1.01300","15200"],["1.01500","16830"],["1.01600","27320"]]}}
1626992762.015352: {"stream":"ctkusdt@bookTicker","data":{"e":"bookTicker","u":600860138196,"s":"CTKUSDT","b":"1.01100","B":"11661","a":"1.01200","A":"6756","T":1626992761966,"E":1626992761970}}
1626992762.049493: {"stream":"akrousdt@kline_1m","data":{"e":"kline","E":1626992762003,"s":"AKROUSDT","k":{"t":1626992700000,"T":1626992759999,"s":"AKROUSDT","i":"1m","f":27931328,"L":27931356,"o":"0.01731","c":"0.01733","h":"0.01733","l":"0.01731","v":"235736","n":29,"x":true,"q":"4082.63755","V":"101629","Q":"1760.37292","B":"0"}}}
1626992762.049634: {"stream":"keepusdt@kline_1m","data":{"e":"kline","E":1626992762004,"s":"KEEPUSDT","k":{"t":1626992700000,"T":1626992759999,"s":"KEEPUSDT","i":"1m","f":2398346,"L":2398359,"o":"0.2463","c":"0.2466","h":"0.2466","l":"0.2458","v":"8464","n":14,"x":true,"q":"2082.4799","V":"344","Q":"84.7670","B":"0"}}}
1626992762.086543: {"stream":"keepusdt@depth@100ms","data":{"e":"depthUpdate","E":1626992762040,"T":1626992762004,"s":"KEEPUSDT","U":600860137366,"u":600860139060,"pu":600860133986,"b":[["0.2432","104448"]],"a":[["0.2476","12340"]]}}
1626992762.1017568: {"stream":"sushiusdt@depth@100ms","data":{"e":"depthUpdate","E":1626992762056,"T":1626992762042,"s":"SUSHIUSDT","U":600860137757,"u":600860139964,"pu":600860136156,"b":[["7.5330","416"],["7.5340","9304"],["7.6090","1323"]],"a":[["7.6270","1144"],["7.6280","3696"],["7.6290","3181"],["7.6300","1099"],["7.6330","1901"]]}}
1626992762.114472: {"stream":"ctkusdt@depth@100ms","data":{"e":"depthUpdate","E":1626992762070,"T":1626992762048,"s":"CTKUSDT","U":600860138192,"u":600860140112,"pu":600860136927,"b":[["0.98200","11280"],["0.98600","4870"],["0.99000","25252"],["1.00700","7947"],["1.01500","0"]],"a":[["1.01200","6756"],["1.01400","19154"],["1.01600","22377"]]}}
1626992762.1306329: {"stream":"akrousdt@depth@100ms","data":{"e":"depthUpdate","E":1626992762085,"T":1626992762018,"s":"AKROUSDT","U":600860138505,"u":600860139408,"pu":600860136023,"b":[["0.01693","349992"],["0.01729","629791"],["0.01730","169979"],["0.01731","129767"]],"a":[]}}
1626992762.166807: {"stream":"ctkusdt@aggTrade","data":{"e":"aggTrade","E":1626992762121,"a":16599316,"s":"CTKUSDT","p":"1.01200","q":"10","f":23961362,"l":23961362,"T":1626992761966,"m":false}}
1626992762.192662: {"stream":"keepusdt@depth@100ms","data":{"e":"depthUpdate","E":1626992762147,"T":1626992762136,"s":"KEEPUSDT","U":600860139948,"u":600860141452,"pu":600860139060,"b":[],"a":[["0.2476","19590"]]}}
1626992762.238833: {"stream":"sushiusdt@depth@100ms","data":{"e":"depthUpdate","E":1626992762194,"T":1626992762176,"s":"SUSHIUSDT","U":600860140639,"u":600860143105,"pu":600860139964,"b":[["6.8560","6"],["7.6060","689"],["7.6150","259"]],"a":[["7.6250","1216"],["7.6310","4417"],["7.7140","1167"]]}}
1626992762.2641149: {"stream":"akrousdt@depth@100ms","data":{"e":"depthUpdate","E":1626992762219,"T":1626992762118,"s":"AKROUSDT","U":600860141082,"u":600860141168,"pu":600860139408,"b":[["0.01705","27801"],["0.01731","130813"]],"a":[]}}
1626992762.295899: {"stream":"ctkusdt@depth@100ms","data":{"e":"depthUpdate","E":1626992762251,"T":1626992762153,"s":"CTKUSDT","U":600860141879,"u":600860142337,"pu":600860140112,"b":[["1.00200","16341"],["1.00300","5769"]],"a":[]}}
1626992762.30061: {"stream":"keepusdt@depth@100ms","data":{"e":"depthUpdate","E":1626992762257,"T":1626992762207,"s":"KEEPUSDT","U":600860142321,"u":600860143851,"pu":600860141452,"b":[["0.2403","16626"]],"a":[["0.2476","21040"]]}}
1626992762.3442402: {"stream":"sushiusdt@depth@100ms","data":{"e":"depthUpdate","E":1626992762294,"T":1626992762283,"s":"SUSHIUSDT","U":600860143380,"u":600860145729,"pu":600860143105,"b":[["7.6070","3044"],["7.6080","2868"],["7.6110","970"],["7.6150","266"]],"a":[["7.6240","2298"],["7.6250","711"],["7.6260","2018"],["7.6320","1787"],["7.6540","342"],["7.6800","3777"]]}}
1626992762.4049659: {"stream":"keepusdt@depth@100ms","data":{"e":"depthUpdate","E":1626992762361,"T":1626992762323,"s":"KEEPUSDT","U":600860144999,"u":600860146890,"pu":600860143851,"b":[["0.2413","10127"],["0.2423","1668"],["0.2425","42290"],["0.2446","9916"]],"a":[["0.2476","22490"]]}}
1626992762.409237: {"stream":"sushiusdt@bookTicker","data":{"e":"bookTicker","u":600860147785,"s":"SUSHIUSDT","b":"7.6180","B":"20","a":"7.6190","A":"30","T":1626992762360,"E":1626992762364}}
1626992762.4167979: {"stream":"sushiusdt@bookTicker","data":{"e":"bookTicker","u":600860147919,"s":"SUSHIUSDT","b":"7.6180","B":"22","a":"7.6190","A":"30","T":1626992762367,"E":1626992762371}}
1626992762.419594: {"stream":"akrousdt@depth@100ms","data":{"e":"depthUpdate","E":1626992762374,"T":1626992762330,"s":"AKROUSDT","U":600860145335,"u":600860147078,"pu":600860141168,"b":[["0.01707","1128804"],["0.01730","176979"]],"a":[["0.01740","906910"]]}}
1626992762.456238: {"stream":"sushiusdt@depth@100ms","data":{"e":"depthUpdate","E":1626992762411,"T":1626992762367,"s":"SUSHIUSDT","U":600860146374,"u":600860147919,"pu":600860145729,"b":[["7.5930","3162"],["7.5980","3030"],["7.6030","699"],["7.6070","4025"],["7.6180","22"]],"a":[["7.6280","4677"],["7.6320","806"],["7.6330","1855"],["7.6360","5507"],["7.6370","2112"],["7.6390","1289"],["7.7050","991"],["7.7090","616"]]}}
1626992762.513901: {"stream":"ctkusdt@kline_1m","data":{"e":"kline","E":1626992762468,"s":"CTKUSDT","k":{"t":1626992760000,"T":1626992819999,"s":"CTKUSDT","i":"1m","f":23961361,"L":23961363,"o":"1.01200","c":"1.01100","h":"1.01200","l":"1.01100","v":"1417","n":3,"x":false,"q":"1432.60700","V":"20","Q":"20.24000","B":"0"}}}
1626992762.5139961: {"stream":"ctkusdt@bookTicker","data":{"e":"bookTicker","u":600860150048,"s":"CTKUSDT","b":"1.01100","B":"8281","a":"1.01200","A":"6756","T":1626992762462,"E":1626992762468}}
1626992762.52352: {"stream":"akrousdt@depth@100ms","data":{"e":"depthUpdate","E":1626992762478,"T":1626992762457,"s":"AKROUSDT","U":600860148127,"u":600860149921,"pu":600860147078,"b":[],"a":[["0.01737","318875"],["0.01813","238271"]]}}
1626992762.5278149: {"stream":"ctkusdt@bookTicker","data":{"e":"bookTicker","u":600860150370,"s":"CTKUSDT","b":"1.01100","B":"9351","a":"1.01200","A":"6756","T":1626992762478,"E":1626992762483}}
1626992762.527916: {"stream":"ctkusdt@bookTicker","data":{"e":"bookTicker","u":600860150393,"s":"CTKUSDT","b":"1.01100","B":"9346","a":"1.01200","A":"6756","T":1626992762479,"E":1626992762483}}
1626992762.52796: {"stream":"ctkusdt@bookTicker","data":{"e":"bookTicker","u":600860150410,"s":"CTKUSDT","b":"1.01100","B":"10146","a":"1.01200","A":"6756","T":1626992762480,"E":1626992762483}}
1626992762.5406022: {"stream":"ctkusdt@bookTicker","data":{"e":"bookTicker","u":600860150589,"s":"CTKUSDT","b":"1.01100","B":"10151","a":"1.01200","A":"6756","T":1626992762490,"E":1626992762495}}
1626992762.569514: {"stream":"sushiusdt@depth@100ms","data":{"e":"depthUpdate","E":1626992762522,"T":1626992762515,"s":"SUSHIUSDT","U":600860148956,"u":600860151070,"pu":600860147919,"b":[["7.6150","266"]],"a":[["7.6230","2137"],["7.6260","2068"],["7.6280","3412"],["7.6290","4365"],["7.6330","1238"],["7.6340","6091"],["7.6410","1171"],["7.6430","2957"]]}}
1626992762.572344: {"stream":"keepusdt@depth@100ms","data":{"e":"depthUpdate","E":1626992762525,"T":1626992762507,"s":"KEEPUSDT","U":600860149005,"u":600860150923,"pu":600860146890,"b":[["0.2456","11686"],["0.2459","9202"]],"a":[["0.2472","3100"],["0.2474","11851"]]}}
1626992762.5897431: {"stream":"sushiusdt@bookTicker","data":{"e":"bookTicker","u":600860151594,"s":"SUSHIUSDT","b":"7.6180","B":"35","a":"7.6190","A":"30","T":1626992762538,"E":1626992762544}}
1626992762.613089: {"stream":"ctkusdt@depth@100ms","data":{"e":"depthUpdate","E":1626992762568,"T":1626992762490,"s":"CTKUSDT","U":600860150024,"u":600860150589,"pu":600860142337,"b":[["1.00700","9145"],["1.00800","15499"],["1.01100","10151"]],"a":[]}}
1626992762.628203: {"stream":"akrousdt@depth@100ms","data":{"e":"depthUpdate","E":1626992762583,"T":1626992762572,"s":"AKROUSDT","U":600860150411,"u":600860152222,"pu":600860149921,"b":[["0.01729","593690"]],"a":[["0.01741","700277"],["0.01756","409347"]]}}
1626992762.663112: {"stream":"ctkusdt@aggTrade","data":{"e":"aggTrade","E":1626992762618,"a":16599317,"s":"CTKUSDT","p":"1.01100","q":"3380","f":23961363,"l":23961369,"T":1626992762462,"m":true}}
1626992762.671524: {"stream":"sushiusdt@depth@100ms","data":{"e":"depthUpdate","E":1626992762626,"T":1626992762614,"s":"SUSHIUSDT","U":600860151263,"u":600860153152,"pu":600860151070,"b":[["7.5790","721"],["7.5800","3532"],["7.6030","373"],["7.6070","3932"],["7.6080","2798"],["7.6090","1393"],["7.6180","35"]],"a":[["7.6230","2187"],["7.6260","2018"],["7.6350","2570"]]}}
1626992762.707625: {"stream":"keepusdt@depth@100ms","data":{"e":"depthUpdate","E":1626992762663,"T":1626992762557,"s":"KEEPUSDT","U":600860151920,"u":600860151920,"pu":600860150923,"b":[],"a":[["0.2512","7942"]]}}
1626992762.734634: {"stream":"akrousdt@depth@100ms","data":{"e":"depthUpdate","E":1626992762690,"T":1626992762655,"s":"AKROUSDT","U":600860152432,"u":600860154282,"pu":600860152222,"b":[["0.01572","55173"],["0.01730","213060"]],"a":[["0.01740","914050"],["0.01742","573125"]]}}
1626992762.7514932: {"stream":"sushiusdt@bookTicker","data":{"e":"bookTicker","u":600860155486,"s":"SUSHIUSDT","b":"7.6180","B":"35","a":"7.6190","A":"69","T":1626992762701,"E":1626992762705}}
1626992762.772732: {"stream":"sushiusdt@bookTicker","data":{"e":"bookTicker","u":600860156001,"s":"SUSHIUSDT","b":"7.6180","B":"35","a":"7.6190","A":"87","T":1626992762724,"E":1626992762728}}
1626992762.8058162: {"stream":"sushiusdt@depth@100ms","data":{"e":"depthUpdate","E":1626992762763,"T":1626992762745,"s":"SUSHIUSDT","U":600860154367,"u":600860156547,"pu":600860153152,"b":[["7.5850","1545"],["7.6060","719"],["7.6080","3122"],["7.6100","954"],["7.6150","259"]],"a":[["7.6190","87"],["7.6240","1974"],["7.6260","2342"]]}}
1626992762.8490272: {"stream":"ctkusdt@depth@100ms","data":{"e":"depthUpdate","E":1626992762805,"T":1626992762784,"s":"CTKUSDT","U":600860155493,"u":600860157483,"pu":600860150589,"b":[["1.00500","32936"]],"a":[["1.01800","8164"],["1.01900","1223"]]}}
1626992762.870368: {"stream":"akrousdt@depth@100ms","data":{"e":"depthUpdate","E":1626992762826,"T":1626992762816,"s":"AKROUSDT","U":600860155907,"u":600860158086,"pu":600860154282,"b":[["0.01682","4241"],["0.01726","604651"]],"a":[["0.01743","373309"],["0.01744","170183"]]}}
1626992762.923527: {"stream":"sushiusdt@depth@100ms","data":{"e":"depthUpdate","E":1626992762877,"T":1626992762852,"s":"SUSHIUSDT","U":600860157147,"u":600860159035,"pu":600860156547,"b":[["7.5750","3165"],["7.5810","452"],["7.6150","266"]],"a":[["7.6230","1397"],["7.6270","2248"],["7.6280","4622"],["7.6290","3181"],["7.6300","1099"],["7.6330","924"]]}}
1626992762.938029: {"stream":"keepusdt@depth@100ms","data":{"e":"depthUpdate","E":1626992762891,"T":1626992762785,"s":"KEEPUSDT","U":600860157494,"u":600860157494,"pu":600860151920,"b":[],"a":[["0.2515","27794"]]}}
1626992762.969428: {"stream":"sushiusdt@kline_1m","data":{"e":"kline","E":1626992762926,"s":"SUSHIUSDT","k":{"t":1626992760000,"T":1626992819999,"s":"SUSHIUSDT","i":"1m","f":126902987,"L":126902994,"o":"7.6180","c":"7.6180","h":"7.6200","l":"7.6160","v":"277","n":8,"x":false,"q":"2110.4520","V":"268","Q":"2041.8960","B":"0"}}}
1626992762.972708: {"stream":"sushiusdt@bookTicker","data":{"e":"bookTicker","u":600860160543,"s":"SUSHIUSDT","b":"7.6160","B":"156","a":"7.6190","A":"87","T":1626992762920,"E":1626992762926}}
1626992762.9896698: {"stream":"ctkusdt@depth@100ms","data":{"e":"depthUpdate","E":1626992762946,"T":1626992762941,"s":"CTKUSDT","U":600860158752,"u":600860160990,"pu":600860157483,"b":[["0.98700","12161"],["1.00700","14207"]],"a":[["1.01600","22377"]]}}
1626992763.011733: {"stream":"sushiusdt@bookTicker","data":{"e":"bookTicker","u":600860161464,"s":"SUSHIUSDT","b":"7.6160","B":"156","a":"7.6190","A":"106","T":1626992762962,"E":1626992762967}}
1626992763.0345678: {"stream":"sushiusdt@depth@100ms","data":{"e":"depthUpdate","E":1626992762990,"T":1626992762979,"s":"SUSHIUSDT","U":600860159732,"u":600860161748,"pu":600860159035,"b":[["7.5500","3288"],["7.5790","767"],["7.5820","2515"],["7.6060","719"],["7.6070","4002"],["7.6080","3955"],["7.6090","1358"],["7.6100","86"],["7.6130","453"],["7.6150","230"],["7.6180","0"]],"a":[["7.6190","106"],["7.6200","707"],["7.6220","1261"],["7.6230","1397"],["7.6250","1736"],["7.6270","1338"],["7.6290","3051"],["7.6450","3052"],["7.6470","3184"],["7.6490","8535"],["7.6510","1920"],["7.6540","1842"],["7.6860","351"]]}}
1626992763.060369: {"stream":"akrousdt@depth@100ms","data":{"e":"depthUpdate","E":1626992763015,"T":1626992762974,"s":"AKROUSDT","U":600860160304,"u":600860161675,"pu":600860158086,"b":[["0.01731","100831"],["0.01732","298362"]],"a":[["0.01737","311967"]]}}
1626992763.072096: {"stream":"ctkusdt@bookTicker","data":{"e":"bookTicker","u":600860162507,"s":"CTKUSDT","b":"1.01100","B":"10151","a":"1.01200","A":"6942","T":1626992763021,"E":1626992763027}}
1626992763.072195: {"stream":"ctkusdt@bookTicker","data":{"e":"bookTicker","u":600860162512,"s":"CTKUSDT","b":"1.01100","B":"10151","a":"1.01200","A":"7931","T":1626992763021,"E":1626992763027}}
1626992763.095443: {"stream":"ctkusdt@depth@100ms","data":{"e":"depthUpdate","E":1626992763050,"T":1626992763038,"s":"CTKUSDT","U":600860161129,"u":600860162972,"pu":600860160990,"b":[["0.98700","14185"],["1.00700","9264"]],"a":[["1.01200","7931"],["1.04500","9479"]]}}
1626992763.1205308: {"stream":"sushiusdt@aggTrade","data":{"e":"aggTrade","E":1626992763077,"a":87353263,"s":"SUSHIUSDT","p":"7.6180","q":"35","f":126902994,"l":126902998,"T":1626992762920,"m":true}}
1626992763.1392379: {"stream":"sushiusdt@depth@100ms","data":{"e":"depthUpdate","E":1626992763092,"T":1626992763084,"s":"SUSHIUSDT","U":600860161881,"u":600860163692,"pu":600860161748,"b":[["7.5490","2853"],["7.6100","214"],["7.6110","1002"],["7.6120","1112"],["7.6130","325"],["7.6140","179"]],"a":[["7.6210","699"],["7.6230","1365"],["7.6260","2018"],["7.6850","2512"]]}}
1626992763.166081: {"stream":"akrousdt@depth@100ms","data":{"e":"depthUpdate","E":1626992763120,"T":1626992763042,"s":"AKROUSDT","U":600860162361,"u":600860163043,"pu":600860161675,"b":[["0.01731","130813"],["0.01732","268397"]],"a":[["0.01740","920946"]]}}
1626992763.197757: {"stream":"ctkusdt@depth@100ms","data":{"e":"depthUpdate","E":1626992763152,"T":1626992763141,"s":"CTKUSDT","U":600860163137,"u":600860164645,"pu":600860162972,"b":[["1.00700","8906"],["1.00800","15857"]],"a":[["1.01600","22377"]]}}
1626992763.198295: {"stream":"ctkusdt@bookTicker","data":{"e":"bookTicker","u":600860165016,"s":"CTKUSDT","b":"1.01100","B":"10151","a":"1.01200","A":"7921","T":1626992763148,"E":1626992763153}}
1626992763.199075: {"stream":"ctkusdt@kline_1m","data":{"e":"kline","E":1626992763154,"s":"CTKUSDT","k":{"t":1626992760000,"T":1626992819999,"s":"CTKUSDT","i":"1m","f":23961361,"L":23961370,"o":"1.01200","c":"1.01200","h":"1.01200","l":"1.01100","v":"3410","n":10,"x":false,"q":"3447.54000","V":"30","Q":"30.36000","B":"0"}}}
1626992763.2387352: {"stream":"sushiusdt@depth@100ms","data":{"e":"depthUpdate","E":1626992763193,"T":1626992763154,"s":"SUSHIUSDT","U":600860163756,"u":600860165266,"pu":600860163692,"b":[["7.5860","1147"],["7.6080","3724"]],"a":[["7.6230","2155"],["7.6250","946"],["7.6310","4605"],["7.6550","1038"]]}}
1626992763.238903: {"stream":"keepusdt@depth@100ms","data":{"e":"depthUpdate","E":1626992763195,"T":1626992763135,"s":"KEEPUSDT","U":600860163820,"u":600860164572,"pu":600860157494,"b":[["0.2373","74"],["0.2457","5820"],["0.2458","16808"],["0.2459","5954"],["0.2461","3580"]],"a":[]}}
1626992763.297279: {"stream":"ctkusdt@depth@100ms","data":{"e":"depthUpdate","E":1626992763253,"T":1626992763247,"s":"CTKUSDT","U":600860165012,"u":600860167610,"pu":600860164645,"b":[["1.00000","85532"],["1.00100","76990"],["1.01500","0"]],"a":[["1.01200","7921"]]}}
1626992763.306319: {"stream":"sushiusdt@kline_1m","data":{"e":"kline","E":1626992763261,"s":"SUSHIUSDT","k":{"t":1626992760000,"T":1626992819999,"s":"SUSHIUSDT","i":"1m","f":126902987,"L":126902999,"o":"7.6180","c":"7.6160","h":"7.6200","l":"7.6160","v":"322","n":13,"x":false,"q":"2453.2360","V":"268","Q":"2041.8960","B":"0"}}}
1626992763.306441: {"stream":"sushiusdt@bookTicker","data":{"e":"bookTicker","u":600860167826,"s":"SUSHIUSDT","b":"7.6160","B":"143","a":"7.6190","A":"106","T":1626992763257,"E":1626992763261}}
1626992763.319065: {"stream":"akrousdt@depth@100ms","data":{"e":"depthUpdate","E":1626992763274,"T":1626992763217,"s":"AKROUSDT","U":600860165703,"u":600860166923,"pu":600860163043,"b":[["0.01653","601379"],["0.01705","26640"],["0.01731","100831"],["0.01732","298362"]],"a":[]}}
1626992763.322177: {"stream":"akrousdt@bookTicker","data":{"e":"bookTicker","u":600860168159,"s":"AKROUSDT","b":"0.01733","B":"24307","a":"0.01734","A":"14913","T":1626992763272,"E":1626992763278}}
1626992763.3491: {"stream":"ctkusdt@aggTrade","data":{"e":"aggTrade","E":1626992763303,"a":16599318,"s":"CTKUSDT","p":"1.01200","q":"10","f":23961370,"l":23961370,"T":1626992763148,"m":false}}
1626992763.381221: {"stream":"keepusdt@depth@100ms","data":{"e":"depthUpdate","E":1626992763336,"T":1626992763317,"s":"KEEPUSDT","U":600860167247,"u":600860169019,"pu":600860164572,"b":[["0.2408","1237"],["0.2411","55378"],["0.2458","11146"],["0.2460","7456"]],"a":[["0.2477","13136"],["0.2478","9790"],["0.2521","183"],["0.2524","16963"]]}}
1626992763.387579: {"stream":"sushiusdt@depth@100ms","data":{"e":"depthUpdate","E":1626992763343,"T":1626992763332,"s":"SUSHIUSDT","U":600860167425,"u":600860169322,"pu":600860165266,"b":[["7.5590","602"],["7.5990","4363"],["7.6160","143"]],"a":[["7.6230","2405"],["7.6250","696"],["7.6580","312"]]}}
1626992763.392831: {"stream":"akrousdt@bookTicker","data":{"e":"bookTicker","u":600860169511,"s":"AKROUSDT","b":"0.01733","B":"24336","a":"0.01734","A":"14913","T":1626992763343,"E":1626992763348}}
1626992763.410403: {"stream":"keepusdt@bookTicker","data":{"e":"bookTicker","u":600860169678,"s":"KEEPUSDT","b":"0.2467","B":"3675","a":"0.2469","A":"718","T":1626992763354,"E":1626992763360}}
1626992763.424285: {"stream":"akrousdt@depth@100ms","data":{"e":"depthUpdate","E":1626992763378,"T":1626992763343,"s":"AKROUSDT","U":600860168159,"u":600860169511,"pu":600860166923,"b":[["0.01712","1335668"],["0.01729","506293"],["0.01730","352046"],["0.01733","24336"]],"a":[["0.01734","14913"]]}}
1626992763.45212: {"stream":"keepusdt@bookTicker","data":{"e":"bookTicker","u":600860170483,"s":"KEEPUSDT","b":"0.2467","B":"3675","a":"0.2469","A":"1529","T":1626992763401,"E":1626992763405}}
1626992763.456245: {"stream":"sushiusdt@aggTrade","data":{"e":"aggTrade","E":1626992763412,"a":87353264,"s":"SUSHIUSDT","p":"7.6160","q":"13","f":126902999,"l":126902999,"T":1626992763257,"m":true}}
1626992763.463304: {"stream":"ctkusdt@depth@100ms","data":{"e":"depthUpdate","E":1626992763416,"T":1626992763392,"s":"CTKUSDT","U":600860168930,"u":600860170342,"pu":600860167610,"b":[["1.00000","85932"],["1.00300","5520"]],"a":[["1.04300","4730"]]}}
1626992763.491015: {"stream":"sushiusdt@depth@100ms","data":{"e":"depthUpdate","E":1626992763446,"T":1626992763415,"s":"SUSHIUSDT","U":600860169423,"u":600860170742,"pu":600860169322,"b":[["7.5530","1955"],["7.5560","331"],["7.5690","2190"],["7.5720","4344"],["7.5750","551"],["7.6020","1320"]],"a":[["7.6200","785"],["7.6310","4465"],["7.6360","5326"],["7.6430","2757"],["7.6630","622"]]}}
1626992763.491209: {"stream":"ctkusdt@kline_1m","data":{"e":"kline","E":1626992763447,"s":"CTKUSDT","k":{"t":1626992760000,"T":1626992819999,"s":"CTKUSDT","i":"1m","f":23961361,"L":23961371,"o":"1.01200","c":"1.01100","h":"1.01200","l":"1.01100","v":"3662","n":11,"x":false,"q":"3702.31200","V":"30","Q":"30.36000","B":"0"}}}
1626992763.494246: {"stream":"ctkusdt@bookTicker","data":{"e":"bookTicker","u":600860171220,"s":"CTKUSDT","b":"1.01100","B":"9899","a":"1.01200","A":"7921","T":1626992763442,"E":1626992763449}}
1626992763.499455: {"stream":"keepusdt@bookTicker","data":{"e":"bookTicker","u":600860171308,"s":"KEEPUSDT","b":"0.2467","B":"3675","a":"0.2469","A":"851","T":1626992763448,"E":1626992763452}}
1626992763.5056121: {"stream":"keepusdt@depth@100ms","data":{"e":"depthUpdate","E":1626992763460,"T":1626992763448,"s":"KEEPUSDT","U":600860169678,"u":600860171308,"pu":600860169019,"b":[["0.2451","10473"],["0.2452","5185"],["0.2459","5007"],["0.2461","4527"]],"a":[["0.2468","0"],["0.2469","851"]]}}
1626992763.522779: {"stream":"akrousdt@depth@100ms","data":{"e":"depthUpdate","E":1626992763479,"T":1626992763393,"s":"AKROUSDT","U":600860169987,"u":600860170358,"pu":600860169511,"b":[["0.01726","568590"]],"a":[["0.01738","762113"],["0.01739","458130"]]}}
1626992763.5688891: {"stream":"ctkusdt@depth@100ms","data":{"e":"depthUpdate","E":1626992763525,"T":1626992763502,"s":"CTKUSDT","U":600860170800,"u":600860172206,"pu":600860170342,"b":[["0.99700","9629"],["1.00000","85932"],["1.00200","16740"],["1.01100","9899"]],"a":[["1.05000","4398"]]}}
1626992763.591917: {"stream":"keepusdt@bookTicker","data":{"e":"bookTicker","u":600860172736,"s":"KEEPUSDT","b":"0.2467","B":"457","a":"0.2469","A":"851","T":1626992763541,"E":1626992763546}}
1626992763.593894: {"stream":"sushiusdt@depth@100ms","data":{"e":"depthUpdate","E":1626992763549,"T":1626992763463,"s":"SUSHIUSDT","U":600860171195,"u":600860171556,"pu":600860170742,"b":[["7.5680","14991"],["7.5830","5791"]],"a":[]}}
1626992763.600302: {"stream":"keepusdt@bookTicker","data":{"e":"bookTicker","u":600860172852,"s":"KEEPUSDT","b":"0.2468","B":"3218","a":"0.2469","A":"851","T":1626992763549,"E":1626992763554}}
1626992763.634468: {"stream":"keepusdt@depth@100ms","data":{"e":"depthUpdate","E":1626992763591,"T":1626992763576,"s":"KEEPUSDT","U":600860171962,"u":600860173349,"pu":600860171308,"b":[["0.2382","60766"],["0.2416","5414"],["0.2419","10917"],["0.2447","6577"],["0.2453","12278"],["0.2467","457"],["0.2468","3218"]],"a":[["0.2470","13692"]]}}
1626992763.6446452: {"stream":"ctkusdt@aggTrade","data":{"e":"aggTrade","E":1626992763600,"a":16599319,"s":"CTKUSDT","p":"1.01100","q":"252","f":23961371,"l":23961371,"T":1626992763442,"m":true}}
1626992763.667642: {"stream":"sushiusdt@bookTicker","data":{"e":"bookTicker","u":600860173961,"s":"SUSHIUSDT","b":"7.6160","B":"78","a":"7.6190","A":"106","T":1626992763614,"E":1626992763623}}
1626992763.671804: {"stream":"ctkusdt@depth@100ms","data":{"e":"depthUpdate","E":1626992763628,"T":1626992763579,"s":"CTKUSDT","U":600860172463,"u":600860173412,"pu":600860172206,"b":[["1.00000","85532"],["1.00400","5273"]],"a":[]}}
1626992763.697529: {"stream":"sushiusdt@depth@100ms","data":{"e":"depthUpdate","E":1626992763652,"T":1626992763637,"s":"SUSHIUSDT","U":600860172845,"u":600860174339,"pu":600860171556,"b":[["7.1760","12"],["7.6070","4277"],["7.6090","1323"],["7.6100","545"],["7.6140","150"],["7.6160","78"]],"a":[["7.6200","825"],["7.6230","2365"],["7.6370","2187"],["7.7920","303"]]}}
1626992763.710339: {"stream":"sushiusdt@kline_1m","data":{"e":"kline","E":1626992763665,"s":"SUSHIUSDT","k":{"t":1626992760000,"T":1626992819999,"s":"SUSHIUSDT","i":"1m","f":126902987,"L":126903000,"o":"7.6180","c":"7.6160","h":"7.6200","l":"7.6160","v":"355","n":14,"x":false,"q":"2704.5640","V":"268","Q":"2041.8960","B":"0"}}}
1626992763.710455: {"stream":"sushiusdt@bookTicker","data":{"e":"bookTicker","u":600860174722,"s":"SUSHIUSDT","b":"7.6160","B":"45","a":"7.6190","A":"106","T":1626992763659,"E":1626992763665}}
1626992763.729512: {"stream":"sushiusdt@bookTicker","data":{"e":"bookTicker","u":600860175064,"s":"SUSHIUSDT","b":"7.6150","B":"230","a":"7.6190","A":"106","T":1626992763677,"E":1626992763683}}
1626992763.74: {"stream":"akrousdt@depth@100ms","data":{"e":"depthUpdate","E":1626992763695,"T":1626992763687,"s":"AKROUSDT","U":600860173521,"u":600860175232,"pu":600860170358,"b":[["0.01716","191098"],["0.01723","389701"],["0.01729","760075"]],"a":[["0.01737","367692"],["0.01738","1050547"]]}}
1626992763.77114: {"stream":"keepusdt@depth@100ms","data":{"e":"depthUpdate","E":1626992763727,"T":1626992763694,"s":"KEEPUSDT","U":600860174088,"u":600860175354,"pu":600860173349,"b":[["0.2440","4810"]],"a":[["0.2472","1381"],["0.2473","23857"],["0.2474","13098"]]}}
1626992763.792395: {"stream":"ctkusdt@depth@100ms","data":{"e":"depthUpdate","E":1626992763746,"T":1626992763641,"s":"CTKUSDT","U":600860174407,"u":600860174407,"pu":600860173412,"b":[["1.00200","16341"]],"a":[]}}
1626992763.801478: {"stream":"sushiusdt@depth@100ms","data":{"e":"depthUpdate","E":1626992763755,"T":1626992763716,"s":"SUSHIUSDT","U":600860174576,"u":600860175726,"pu":600860174339,"b":[["7.5830","6260"],["7.5840","2682"],["7.6070","4207"],["7.6080","3794"],["7.6090","1373"],["7.6120","1048"],["7.6160","0"]],"a":[["7.6210","714"],["7.6220","1246"],["7.6270","1208"],["7.6280","4752"],["7.6310","4202"],["7.6400","1460"],["7.6500","1224"],["7.6520","3894"]]}}
1626992763.824363: {"stream":"sushiusdt@bookTicker","data":{"e":"bookTicker","u":600860176924,"s":"SUSHIUSDT","b":"7.6150","B":"231","a":"7.6190","A":"106","T":1626992763772,"E":1626992763778}}
1626992763.8497941: {"stream":"akrousdt@depth@100ms","data":{"e":"depthUpdate","E":1626992763805,"T":1626992763711,"s":"AKROUSDT","U":600860175424,"u":600860175662,"pu":600860175232,"b":[["0.01720","575551"],["0.01726","572070"]],"a":[]}}
1626992763.860793: {"stream":"sushiusdt@aggTrade","data":{"e":"aggTrade","E":1626992763816,"a":87353265,"s":"SUSHIUSDT","p":"7.6160","q":"33","f":126903000,"l":126903000,"T":1626992763659,"m":true}}
1626992763.919429: {"stream":"keepusdt@depth@100ms","data":{"e":"depthUpdate","E":1626992763873,"T":1626992763855,"s":"KEEPUSDT","U":600860176798,"u":600860179119,"pu":600860175354,"b":[["0.2432","100342"]],"a":[["0.2474","15592"]]}}
1626992763.9214919: {"stream":"sushiusdt@depth@100ms","data":{"e":"depthUpdate","E":1626992763875,"T":1626992763859,"s":"SUSHIUSDT","U":600860176857,"u":600860179253,"pu":600860175726,"b":[["7.5850","1533"],["7.6050","650"],["7.6080","3397"],["7.6130","249"],["7.6150","231"]],"a":[["7.6230","2252"],["7.6250","684"],["7.6260","2342"],["7.6520","3777"],["8.0990","542"]]}}
1626992763.950409: {"stream":"ctkusdt@bookTicker","data":{"e":"bookTicker","u":600860180444,"s":"CTKUSDT","b":"1.01100","B":"9899","a":"1.01200","A":"8244","T":1626992763900,"E":1626992763904}}
1626992763.962646: {"stream":"ctkusdt@depth@100ms","data":{"e":"depthUpdate","E":1626992763917,"T":1626992763906,"s":"CTKUSDT","U":600860177833,"u":600860180558,"pu":600860174407,"b":[["1.00000","85132"],["1.00100","76192"],["1.00700","13849"]],"a":[["1.01200","8244"],["1.01500","17156"],["1.01600","27320"]]}}
1626992763.9781609: {"stream":"akrousdt@depth@100ms","data":{"e":"depthUpdate","E":1626992763934,"T":1626992763867,"s":"AKROUSDT","U":600860178192,"u":600860179542,"pu":600860175662,"b":[["0.01716","190226"],["0.01720","576424"],["0.01732","275471"]],"a":[]}}
1626992764.042194: {"stream":"keepusdt@depth@100ms","data":{"e":"depthUpdate","E":1626992763997,"T":1626992763941,"s":"KEEPUSDT","U":600860180243,"u":600860181694,"pu":600860179119,"b":[["0.2423","1627"],["0.2431","12292"]],"a":[["0.2470","7692"]]}}
1626992764.050613: {"stream":"sushiusdt@depth@100ms","data":{"e":"depthUpdate","E":1626992764006,"T":1626992763964,"s":"SUSHIUSDT","U":600860180462,"u":600860182270,"pu":600860179253,"b":[["7.6080","3397"]],"a":[["7.6400","1522"],["7.6570","4432"]]}}
1626992764.0709639: {"stream":"ctkusdt@depth@100ms","data":{"e":"depthUpdate","E":1626992764026,"T":1626992764010,"s":"CTKUSDT","U":600860181042,"u":600860183472,"pu":600860180558,"b":[["1.00000","84732"],["1.00700","13849"]],"a":[["1.01600","27320"]]}}
1626992764.1656919: {"stream":"sushiusdt@depth@100ms","data":{"e":"depthUpdate","E":1626992764121,"T":1626992764040,"s":"SUSHIUSDT","U":600860183621,"u":600860184330,"pu":600860182270,"b":[["7.6100","577"],["7.6110","1034"]],"a":[["7.6260","2434"],["7.6310","4342"],["7.6340","6078"],["7.6360","5486"],["7.6570","4549"]]}}
1626992764.171502: {"stream":"akrousdt@depth@100ms","data":{"e":"depthUpdate","E":1626992764126,"T":1626992764051,"s":"AKROUSDT","U":600860183736,"u":600860184613,"pu":600860179542,"b":[["0.01730","353092"],["0.01731","99785"]],"a":[["0.01739","459176"],["0.01740","919900"]]}}
1626992764.194418: {"stream":"keepusdt@depth@100ms","data":{"e":"depthUpdate","E":1626992764149,"T":1626992764130,"s":"KEEPUSDT","U":600860184418,"u":600860185813,"pu":600860181694,"b":[["0.2430","7328"],["0.2447","4858"],["0.2449","16398"]],"a":[["0.2482","241"],["0.2484","5736"]]}}
1626992764.204: {"stream":"ctkusdt@depth@100ms","data":{"e":"depthUpdate","E":1626992764160,"T":1626992764152,"s":"CTKUSDT","U":600860184692,"u":600860186692,"pu":600860183472,"b":[["1.00000","85132"],["1.00700","13849"]],"a":[["1.01600","27320"]]}}
1626992764.277686: {"stream":"sushiusdt@depth@100ms","data":{"e":"depthUpdate","E":1626992764235,"T":1626992764218,"s":"SUSHIUSDT","U":600860185810,"u":600860188256,"pu":600860184330,"b":[["7.1760","44"],["7.5990","4445"]],"a":[["7.6410","1184"],["7.7250","17"],["7.7920","304"]]}}
1626992764.303946: {"stream":"keepusdt@depth@100ms","data":{"e":"depthUpdate","E":1626992764259,"T":1626992764191,"s":"KEEPUSDT","U":600860186666,"u":600860187690,"pu":600860185813,"b":[["0.2438","21352"],["0.2459","3112"],["0.2460","9351"]],"a":[["0.2471","12068"]]}}
1626992764.308151: {"stream":"akrousdt@depth@100ms","data":{"e":"depthUpdate","E":1626992764263,"T":1626992764224,"s":"AKROUSDT","U":600860186849,"u":600860188425,"pu":600860184613,"b":[["0.01731","129767"],["0.01732","245506"]],"a":[["0.01744","150196"]]}}
1626992764.3523378: {"stream":"ctkusdt@depth@100ms","data":{"e":"depthUpdate","E":1626992764309,"T":1626992764264,"s":"CTKUSDT","U":600860188023,"u":600860189181,"pu":600860186692,"b":[["1.00000","85532"],["1.00700","13849"]],"a":[["1.01600","27320"]]}}
1626992764.383533: {"stream":"ctkusdt@kline_1m","data":{"e":"kline","E":1626992764337,"s":"CTKUSDT","k":{"t":1626992760000,"T":1626992819999,"s":"CTKUSDT","i":"1m","f":23961361,"L":23961372,"o":"1.01200","c":"1.01200","h":"1.01200","l":"1.01100","v":"3672","n":12,"x":false,"q":"3712.43200","V":"40","Q":"40.48000","B":"0"}}}
1626992764.3836548: {"stream":"ctkusdt@bookTicker","data":{"e":"bookTicker","u":600860190527,"s":"CTKUSDT","b":"1.01100","B":"9899","a":"1.01200","A":"8234","T":1626992764333,"E":1626992764337}}
1626992764.434519: {"stream":"sushiusdt@depth@100ms","data":{"e":"depthUpdate","E":1626992764391,"T":1626992764381,"s":"SUSHIUSDT","U":600860189536,"u":600860191407,"pu":600860188256,"b":[["7.5460","1179"],["7.5600","494"],["7.5620","2634"],["7.5650","110"],["7.5770","513"],["7.5840","1181"],["7.6100","557"]],"a":[["7.6280","4165"],["7.6290","4032"],["7.6300","1079"],["7.6440","867"],["7.6800","808"],["7.7060","523"],["7.7090","601"]]}}
1626992764.458: {"stream":"ctkusdt@depth@100ms","data":{"e":"depthUpdate","E":1626992764412,"T":1626992764372,"s":"CTKUSDT","U":600860189863,"u":600860191216,"pu":600860189181,"b":[["1.00700","13849"],["1.01500","0"]],"a":[["1.01200","8234"],["1.01500","16681"],["1.01600","27320"],["1.01700","9516"]]}}
1626992764.5317729: {"stream":"ctkusdt@aggTrade","data":{"e":"aggTrade","E":1626992764488,"a":16599320,"s":"CTKUSDT","p":"1.01200","q":"10","f":23961372,"l":23961372,"T":1626992764333,"m":false}}
1626992764.54287: {"stream":"sushiusdt@depth@100ms","data":{"e":"depthUpdate","E":1626992764497,"T":1626992764446,"s":"SUSHIUSDT","U":600860191598,"u":600860192575,"pu":600860191407,"b":[["7.5300","5354"],["7.5600","1995"],["7.5990","4465"]],"a":[["7.6400","1542"],["7.6790","9"],["7.6860","231"],["7.6920","1665"],["7.7100","4439"]]}}
1626992764.557704: {"stream":"ctkusdt@depth@100ms","data":{"e":"depthUpdate","E":1626992764512,"T":1626992764470,"s":"CTKUSDT","U":600860191875,"u":600860193174,"pu":600860191216,"b":[["0.98700","16209"],["1.00700","13849"]],"a":[["1.01500","17156"],["1.01600","27320"],["1.01700","9041"]]}}
1626992764.563029: {"stream":"keepusdt@depth@100ms","data":{"e":"depthUpdate","E":1626992764519,"T":1626992764506,"s":"KEEPUSDT","U":600860191998,"u":600860193976,"pu":600860187690,"b":[],"a":[["0.2509","8223"],["0.2511","13980"],["0.2599","5087"]]}}
1626992764.571487: {"stream":"akrousdt@depth@100ms","data":{"e":"depthUpdate","E":1626992764526,"T":1626992764420,"s":"AKROUSDT","U":600860192112,"u":600860192112,"pu":600860188425,"b":[["0.01564","407315"]],"a":[]}}
1626992764.62174: {"stream":"sushiusdt@bookTicker","data":{"e":"bookTicker","u":600860195116,"s":"SUSHIUSDT","b":"7.6160","B":"105","a":"7.6190","A":"106","T":1626992764570,"E":1626992764575}}
1626992764.6639411: {"stream":"sushiusdt@bookTicker","data":{"e":"bookTicker","u":600860195779,"s":"SUSHIUSDT","b":"7.6160","B":"105","a":"7.6190","A":"87","T":1626992764614,"E":1626992764620}}
1626992764.670196: {"stream":"ctkusdt@depth@100ms","data":{"e":"depthUpdate","E":1626992764625,"T":1626992764525,"s":"CTKUSDT","U":600860194301,"u":600860194400,"pu":600860193174,"b":[["1.00700","8906"]],"a":[["1.01600","22377"]]}}
1626992764.6970592: {"stream":"akrousdt@depth@100ms","data":{"e":"depthUpdate","E":1626992764654,"T":1626992764548,"s":"AKROUSDT","U":600860194778,"u":600860194778,"pu":600860192112,"b":[["0.01680","232091"]],"a":[]}}
1626992764.719402: {"stream":"sushiusdt@depth@100ms","data":{"e":"depthUpdate","E":1626992764675,"T":1626992764633,"s":"SUSHIUSDT","U":600860195116,"u":600860196101,"pu":600860192575,"b":[["7.6080","3447"],["7.6110","984"],["7.6160","105"]],"a":[["7.6190","87"],["7.6200","747"],["7.6210","718"],["7.6220","1261"]]}}
1626992764.831986: {"stream":"sushiusdt@depth@100ms","data":{"e":"depthUpdate","E":1626992764788,"T":1626992764758,"s":"SUSHIUSDT","U":600860197017,"u":600860198203,"pu":600860196101,"b":[["7.6150","230"]],"a":[["7.6200","766"],["7.6210","699"],["7.6520","3640"]]}}
1626992764.865002: {"stream":"akrousdt@bookTicker","data":{"e":"bookTicker","u":600860199289,"s":"AKROUSDT","b":"0.01733","B":"14574","a":"0.01734","A":"14913","T":1626992764814,"E":1626992764818}}
1626992764.872587: {"stream":"akrousdt@bookTicker","data":{"e":"bookTicker","u":600860199490,"s":"AKROUSDT","b":"0.01733","B":"27226","a":"0.01734","A":"14913","T":1626992764822,"E":1626992764827}}
1626992764.8980129: {"stream":"keepusdt@depth@100ms","data":{"e":"depthUpdate","E":1626992764840,"T":1626992764804,"s":"KEEPUSDT","U":600860197914,"u":600860199041,"pu":600860193976,"b":[["0.2411","27867"]],"a":[["0.2519","3249"],["0.2527","26276"],["0.2598","38437"]]}}
1626992764.902677: {"stream":"sushiusdt@bookTicker","data":{"e":"bookTicker","u":600860200180,"s":"SUSHIUSDT","b":"7.6170","B":"13","a":"7.6190","A":"87","T":1626992764852,"E":1626992764857}}
1626992764.9388769: {"stream":"sushiusdt@depth@100ms","data":{"e":"depthUpdate","E":1626992764893,"T":1626992764883,"s":"SUSHIUSDT","U":600860198774,"u":600860200747,"pu":600860198203,"b":[["7.5300","2353"],["7.5500","3284"],["7.5600","3495"],["7.5840","2682"],["7.5990","4445"],["7.6080","2529"],["7.6090","2241"],["7.6100","577"],["7.6110","1034"],["7.6170","13"]],"a":[["7.6200","747"],["7.6210","711"],["7.6230","2002"],["7.6240","448"],["7.6250","934"],["7.6280","4035"],["7.6290","4162"],["7.6300","1099"],["7.6400","1522"],["7.6440","2336"],["7.6540","1979"],["7.6800","3777"],["7.6920","196"],["7.7100","1470"]]}}
1626992764.963325: {"stream":"akrousdt@depth@100ms","data":{"e":"depthUpdate","E":1626992764918,"T":1626992764897,"s":"AKROUSDT","U":600860199289,"u":600860201084,"pu":600860194778,"b":[["0.01707","1129974"],["0.01733","27226"]],"a":[]}}
1626992764.9718668: {"stream":"ctkusdt@depth@100ms","data":{"e":"depthUpdate","E":1626992764927,"T":1626992764847,"s":"CTKUSDT","U":600860199553,"u":600860200088,"pu":600860194400,"b":[],"a":[["1.01800","11759"],["1.04500","11773"]]}}
1626992764.998699: {"stream":"keepusdt@depth@100ms","data":{"e":"depthUpdate","E":1626992764952,"T":1626992764846,"s":"KEEPUSDT","U":600860200058,"u":600860200058,"pu":600860199041,"b":[["0.2419","38337"]],"a":[]}}
1626992765.0539699: {"stream":"sushiusdt@depth@100ms","data":{"e":"depthUpdate","E":1626992765007,"T":1626992764977,"s":"SUSHIUSDT","U":600860201165,"u":600860202939,"pu":600860200747,"b":[["7.5820","1015"],["7.6140","157"]],"a":[["7.6220","1246"],["7.6230","1227"],["7.6240","1238"],["7.6540","479"]]}}
1626992765.1348102: {"stream":"ctkusdt@depth@100ms","data":{"e":"depthUpdate","E":1626992765086,"T":1626992765071,"s":"CTKUSDT","U":600860203004,"u":600860205220,"pu":600860200088,"b":[["1.00000","84732"],["1.00900","16263"]],"a":[]}}
1626992765.165131: {"stream":"sushiusdt@depth@100ms","data":{"e":"depthUpdate","E":1626992765120,"T":1626992765035,"s":"SUSHIUSDT","U":600860203705,"u":600860204359,"pu":600860202939,"b":[["7.1840","4"],["7.6080","3250"]],"a":[["7.6260","3302"]]}}
1626992765.170296: {"stream":"keepusdt@depth@100ms","data":{"e":"depthUpdate","E":1626992765126,"T":1626992765020,"s":"KEEPUSDT","U":600860203890,"u":600860203898,"pu":600860200058,"b":[["0.2459","909"],["0.2460","11554"]],"a":[]}}
1626992765.252362: {"stream":"ctkusdt@depth@100ms","data":{"e":"depthUpdate","E":1626992765207,"T":1626992765142,"s":"CTKUSDT","U":600860205580,"u":600860206167,"pu":600860205220,"b":[["0.98700","16234"]],"a":[["1.04400","5811"]]}}
1626992765.264566: {"stream":"sushiusdt@depth@100ms","data":{"e":"depthUpdate","E":1626992765220,"T":1626992765210,"s":"SUSHIUSDT","U":600860205742,"u":600860208009,"pu":600860204359,"b":[["7.5990","1295"],["7.6040","3859"],["7.6100","545"],["7.6110","970"],["7.6120","1080"],["7.6130","313"],["7.6140","157"]],"a":[["7.6260","3960"],["7.6270","2031"],["7.6280","2825"]]}}
1626992765.2942479: {"stream":"keepusdt@depth@100ms","data":{"e":"depthUpdate","E":1626992765249,"T":1626992765237,"s":"KEEPUSDT","U":600860206319,"u":600860208519,"pu":600860203898,"b":[["0.2430","6506"]],"a":[["0.2474","16839"]]}}
1626992765.411131: {"stream":"akrousdt@depth@100ms","data":{"e":"depthUpdate","E":1626992765366,"T":1626992765353,"s":"AKROUSDT","U":600860208986,"u":600860210520,"pu":600860201084,"b":[["0.01551","3160"],["0.01553","91449"],["0.01730","317011"]],"a":[["0.01911","1647"],["0.01913","71920"]]}}
1626992765.4331362: {"stream":"sushiusdt@bookTicker","data":{"e":"bookTicker","u":600860210945,"s":"SUSHIUSDT","b":"7.6160","B":"105","a":"7.6190","A":"87","T":1626992765383,"E":1626992765388}}
1626992765.4352262: {"stream":"sushiusdt@depth@100ms","data":{"e":"depthUpdate","E":1626992765389,"T":1626992765383,"s":"SUSHIUSDT","U":600860209335,"u":600860210945,"pu":600860208009,"b":[["7.6100","560"],["7.6110","1689"],["7.6120","361"],["7.6130","298"],["7.6170","0"]],"a":[["7.6270","1208"],["7.6280","3648"],["7.6340","5751"],["9.4010","0"]]}}
1626992765.435431: {"stream":"keepusdt@depth@100ms","data":{"e":"depthUpdate","E":1626992765391,"T":1626992765286,"s":"KEEPUSDT","U":600860209360,"u":600860209360,"pu":600860208519,"b":[["0.2438","22164"]],"a":[]}}
1626992765.455384: {"stream":"sushiusdt@bookTicker","data":{"e":"bookTicker","u":600860211244,"s":"SUSHIUSDT","b":"7.6170","B":"13","a":"7.6190","A":"87","T":1626992765406,"E":1626992765410}}
1626992765.5336928: {"stream":"akrousdt@depth@100ms","data":{"e":"depthUpdate","E":1626992765488,"T":1626992765442,"s":"AKROUSDT","U":600860210935,"u":600860211825,"pu":600860210520,"b":[["0.01729","809187"],["0.01730","353092"]],"a":[]}}
1626992765.5444329: {"stream":"sushiusdt@depth@100ms","data":{"e":"depthUpdate","E":1626992765499,"T":1626992765475,"s":"SUSHIUSDT","U":600860211073,"u":600860212355,"pu":600860210945,"b":[["7.5490","2384"],["7.5500","3753"],["7.6090","1373"],["7.6120","592"],["7.6130","234"],["7.6140","150"],["7.6170","13"]],"a":[["7.6200","707"],["7.6230","1367"],["7.6250","1294"],["7.6280","3778"],["7.6290","4032"],["7.6790","69"],["7.6850","2043"],["7.6860","640"]]}}
1626992765.566669: {"stream":"ctkusdt@kline_1m","data":{"e":"kline","E":1626992765521,"s":"CTKUSDT","k":{"t":1626992760000,"T":1626992819999,"s":"CTKUSDT","i":"1m","f":23961361,"L":23961373,"o":"1.01200","c":"1.01200","h":"1.01200","l":"1.01100","v":"3682","n":13,"x":false,"q":"3722.55200","V":"50","Q":"50.60000","B":"0"}}}
1626992765.569807: {"stream":"ctkusdt@bookTicker","data":{"e":"bookTicker","u":600860212950,"s":"CTKUSDT","b":"1.01100","B":"9899","a":"1.01200","A":"8224","T":1626992765516,"E":1626992765521}}
1626992765.6522691: {"stream":"sushiusdt@depth@100ms","data":{"e":"depthUpdate","E":1626992765607,"T":1626992765581,"s":"SUSHIUSDT","U":600860212732,"u":600860213909,"pu":600860212355,"b":[["7.6090","2241"],["7.6100","432"],["7.6120","720"],["7.6140","157"]],"a":[["7.6440","867"],["7.6800","808"]]}}
1626992765.661622: {"stream":"ctkusdt@aggTrade","data":{"e":"aggTrade","E":1626992765615,"a":16599321,"s":"CTKUSDT","p":"1.01200","q":"10","f":23961373,"l":23961373,"T":1626992765516,"m":false}}
1626992765.6616929: {"stream":"ctkusdt@bookTicker","data":{"e":"bookTicker","u":600860214313,"s":"CTKUSDT","b":"1.01100","B":"9524","a":"1.01200","A":"8224","T":1626992765610,"E":1626992765615}}
1626992765.664887: {"stream":"ctkusdt@depth@100ms","data":{"e":"depthUpdate","E":1626992765621,"T":1626992765610,"s":"CTKUSDT","U":600860212946,"u":600860214313,"pu":600860206167,"b":[["1.00700","13849"],["1.01100","9524"],["1.01500","0"]],"a":[["1.01200","8224"],["1.01600","27320"]]}}
1626992765.715241: {"stream":"akrousdt@depth@100ms","data":{"e":"depthUpdate","E":1626992765672,"T":1626992765567,"s":"AKROUSDT","U":600860213714,"u":600860213714,"pu":600860211825,"b":[["0.01730","317011"]],"a":[]}}
1626992765.771743: {"stream":"sushiusdt@bookTicker","data":{"e":"bookTicker","u":600860216060,"s":"SUSHIUSDT","b":"7.6170","B":"38","a":"7.6190","A":"87","T":1626992765722,"E":1626992765728}}
1626992765.774533: {"stream":"ctkusdt@depth@100ms","data":{"e":"depthUpdate","E":1626992765729,"T":1626992765713,"s":"CTKUSDT","U":600860214516,"u":600860215917,"pu":600860214313,"b":[["1.00700","8906"]],"a":[["1.01600","22377"]]}}
1626992765.81113: {"stream":"ctkusdt@aggTrade","data":{"e":"aggTrade","E":1626992765766,"a":16599322,"s":"CTKUSDT","p":"1.01100","q":"375","f":23961374,"l":23961374,"T":1626992765610,"m":true}}
1626992765.815941: {"stream":"sushiusdt@depth@100ms","data":{"e":"depthUpdate","E":1626992765769,"T":1626992765757,"s":"SUSHIUSDT","U":600860215169,"u":600860216702,"pu":600860213909,"b":[["7.6100","417"],["7.6120","735"],["7.6140","150"],["7.6170","38"]],"a":[["7.6220","1297"],["7.6240","1186"],["7.6360","6127"]]}}
1626992765.918553: {"stream":"ctkusdt@depth@100ms","data":{"e":"depthUpdate","E":1626992765873,"T":1626992765828,"s":"CTKUSDT","U":600860216876,"u":600860217944,"pu":600860215917,"b":[["0.97000","20952"],["1.00700","8906"],["1.00900","21206"]],"a":[["1.01600","22377"]]}}
1626992765.955371: {"stream":"sushiusdt@depth@100ms","data":{"e":"depthUpdate","E":1626992765909,"T":1626992765895,"s":"SUSHIUSDT","U":600860217476,"u":600860219358,"pu":600860216702,"b":[["7.6140","157"]],"a":[["7.6440","2337"],["7.6800","3778"],["7.6920","16"],["7.7420","1091"]]}}
1626992765.969853: {"stream":"sushiusdt@bookTicker","data":{"e":"bookTicker","u":600860219979,"s":"SUSHIUSDT","b":"7.6170","B":"25","a":"7.6190","A":"87","T":1626992765921,"E":1626992765925}}
1626992765.984027: {"stream":"sushiusdt@bookTicker","data":{"e":"bookTicker","u":600860220451,"s":"SUSHIUSDT","b":"7.6180","B":"13","a":"7.6190","A":"87","T":1626992765933,"E":1626992765938}}
1626992765.991161: {"stream":"akrousdt@depth@100ms","data":{"e":"depthUpdate","E":1626992765945,"T":1626992765885,"s":"AKROUSDT","U":600860218146,"u":600860219047,"pu":600860213714,"b":[["0.01730","353092"],["0.01731","186767"]],"a":[]}}
1626992766.014585: {"stream":"keepusdt@depth@100ms","data":{"e":"depthUpdate","E":1626992765969,"T":1626992765864,"s":"KEEPUSDT","U":600860218582,"u":600860218585,"pu":600860209360,"b":[["0.2461","3580"],["0.2462","1286"]],"a":[]}}
1626992766.023506: {"stream":"ctkusdt@depth@100ms","data":{"e":"depthUpdate","E":1626992765978,"T":1626992765927,"s":"CTKUSDT","U":600860218797,"u":600860220205,"pu":600860217944,"b":[["1.00700","8906"]],"a":[["1.01600","22377"]]}}
1626992766.0624058: {"stream":"sushiusdt@depth@100ms","data":{"e":"depthUpdate","E":1626992766016,"T":1626992765990,"s":"SUSHIUSDT","U":600860219699,"u":600860221981,"pu":600860219358,"b":[["7.5810","1952"],["7.6080","1310"],["7.6090","4188"],["7.6110","970"],["7.6170","25"],["7.6180","13"]],"a":[["7.6230","1352"],["7.6240","1201"],["7.6280","3648"],["7.6290","4162"],["7.6540","1979"],["7.6860","820"]]}}
1626992766.169336: {"stream":"ctkusdt@depth@100ms","data":{"e":"depthUpdate","E":1626992766122,"T":1626992766061,"s":"CTKUSDT","U":600860222556,"u":600860223594,"pu":600860220205,"b":[["1.00000","84816"]],"a":[["1.01300","15208"],["1.01400","19146"]]}}
1626992766.171198: {"stream":"sushiusdt@depth@100ms","data":{"e":"depthUpdate","E":1626992766124,"T":1626992766075,"s":"SUSHIUSDT","U":600860222619,"u":600860223755,"pu":600860221981,"b":[["7.1840","5"],["7.5930","3790"],["7.6080","3203"],["7.6090","2281"],["7.6140","150"],["7.6150","308"]],"a":[]}}
1626992766.234974: {"stream":"keepusdt@depth@100ms","data":{"e":"depthUpdate","E":1626992766190,"T":1626992766085,"s":"KEEPUSDT","U":600860223800,"u":600860223800,"pu":600860218585,"b":[],"a":[["0.2587","3237"]]}}
1626992766.271063: {"stream":"akrousdt@depth@100ms","data":{"e":"depthUpdate","E":1626992766226,"T":1626992766121,"s":"AKROUSDT","U":600860224306,"u":600860224306,"pu":600860219047,"b":[["0.01718","115111"]],"a":[]}}
1626992766.2711968: {"stream":"sushiusdt@depth@100ms","data":{"e":"depthUpdate","E":1626992766226,"T":1626992766173,"s":"SUSHIUSDT","U":600860224344,"u":600860225662,"pu":600860223755,"b":[["7.5830","5791"],["7.5850","2002"],["7.6080","3243"],["7.6090","2241"],["7.6100","432"],["7.6120","720"],["7.6150","315"]],"a":[["7.6350","2653"],["7.6500","755"],["7.6520","4109"]]}}
1626992766.296212: {"stream":"ctkusdt@depth@100ms","data":{"e":"depthUpdate","E":1626992766248,"T":1626992766181,"s":"CTKUSDT","U":600860224593,"u":600860225775,"pu":600860223594,"b":[["1.00900","21211"]],"a":[["1.01400","19422"]]}}
1626992766.3980968: {"stream":"sushiusdt@depth@100ms","data":{"e":"depthUpdate","E":1626992766353,"T":1626992766335,"s":"SUSHIUSDT","U":600860227303,"u":600860229058,"pu":600860225662,"b":[["3.8090","0"],["7.6060","1888"],["7.6070","3226"],["7.6080","3243"],["7.6090","2241"],["7.6120","688"],["7.6130","266"],["7.6140","214"],["7.6150","308"]],"a":[["7.6280","4629"],["7.6290","3181"]]}}
1626992766.496195: {"stream":"ctkusdt@depth@100ms","data":{"e":"depthUpdate","E":1626992766452,"T":1626992766434,"s":"CTKUSDT","U":600860229227,"u":600860231048,"pu":600860225775,"b":[["1.00000","85216"]],"a":[["1.01400","20452"],["1.17900","237"]]}}
1626992766.4963431: {"stream":"keepusdt@depth@100ms","data":{"e":"depthUpdate","E":1626992766452,"T":1626992766345,"s":"KEEPUSDT","U":600860229210,"u":600860229210,"pu":600860223800,"b":[],"a":[["0.2586","38616"]]}}
1626992766.498004: {"stream":"sushiusdt@depth@100ms","data":{"e":"depthUpdate","E":1626992766454,"T":1626992766372,"s":"SUSHIUSDT","U":600860229290,"u":600860229890,"pu":600860229058,"b":[["7.6100","560"],["7.6120","560"],["7.6150","315"]],"a":[["7.6340","6078"]]}}
1626992766.621127: {"stream":"sushiusdt@depth@100ms","data":{"e":"depthUpdate","E":1626992766577,"T":1626992766571,"s":"SUSHIUSDT","U":600860231759,"u":600860233289,"pu":600860229890,"b":[["7.5300","5354"],["7.5410","2458"],["7.5550","411"],["7.5600","1995"],["7.5840","1181"],["7.6000","1549"],["7.6080","1350"],["7.6090","4134"],["7.6100","540"]],"a":[["7.6300","1079"],["7.6400","1542"],["7.6440","867"],["7.6650","7"],["7.6790","9"],["7.6800","808"],["7.6860","880"],["7.6920","1486"],["7.7100","4440"]]}}
1626992766.6242392: {"stream":"keepusdt@depth@100ms","data":{"e":"depthUpdate","E":1626992766579,"T":1626992766475,"s":"KEEPUSDT","U":600860231804,"u":600860231804,"pu":600860229210,"b":[],"a":[["0.2471","8068"]]}}
1626992766.73106: {"stream":"akrousdt@depth@100ms","data":{"e":"depthUpdate","E":1626992766686,"T":1626992766584,"s":"AKROUSDT","U":600860233461,"u":600860233461,"pu":600860224306,"b":[["0.01731","475201"]],"a":[]}}
1626992766.743316: {"stream":"keepusdt@depth@100ms","data":{"e":"depthUpdate","E":1626992766698,"T":1626992766684,"s":"KEEPUSDT","U":600860233571,"u":600860234979,"pu":600860231804,"b":[["0.2460","7456"],["0.2462","339"],["0.2463","1331"]],"a":[["0.2471","6372"],["0.2472","3077"],["0.2477","17136"],["0.2494","2837"],["0.2496","12570"]]}}
1626992766.756243: {"stream":"sushiusdt@depth@100ms","data":{"e":"depthUpdate","E":1626992766712,"T":1626992766651,"s":"SUSHIUSDT","U":600860233741,"u":600860234479,"pu":600860233289,"b":[["7.6080","1310"],["7.6090","4174"],["7.6150","315"]],"a":[["7.6270","1283"],["7.6490","8699"]]}}
1626992766.759561: {"stream":"ctkusdt@kline_1m","data":{"e":"kline","E":1626992766715,"s":"CTKUSDT","k":{"t":1626992760000,"T":1626992819999,"s":"CTKUSDT","i":"1m","f":23961361,"L":23961375,"o":"1.01200","c":"1.01200","h":"1.01200","l":"1.01100","v":"4067","n":15,"x":false,"q":"4111.79700","V":"60","Q":"60.72000","B":"0"}}}
1626992766.759678: {"stream":"ctkusdt@bookTicker","data":{"e":"bookTicker","u":600860235631,"s":"CTKUSDT","b":"1.01100","B":"9524","a":"1.01200","A":"8214","T":1626992766709,"E":1626992766715}}
1626992766.772576: {"stream":"akrousdt@aggTrade","data":{"e":"aggTrade","E":1626992766726,"a":14888307,"s":"AKROUSDT","p":"0.01734","q":"14913","f":27931357,"l":27931358,"T":1626992766722,"m":false}}
1626992766.772676: {"stream":"akrousdt@bookTicker","data":{"e":"bookTicker","u":600860235944,"s":"AKROUSDT","b":"0.01733","B":"27226","a":"0.01735","A":"152330","T":1626992766722,"E":1626992766726}}
1626992766.772724: {"stream":"akrousdt@kline_1m","data":{"e":"kline","E":1626992766726,"s":"AKROUSDT","k":{"t":1626992760000,"T":1626992819999,"s":"AKROUSDT","i":"1m","f":27931357,"L":27931357,"o":"0.01734","c":"0.01734","h":"0.01734","l":"0.01734","v":"14610","n":1,"x":false,"q":"253.33740","V":"14610","Q":"253.33740","B":"0"}}}
1626992766.784821: {"stream":"akrousdt@bookTicker","data":{"e":"bookTicker","u":600860236195,"s":"AKROUSDT","b":"0.01733","B":"27226","a":"0.01735","A":"115372","T":1626992766733,"E":1626992766738}}
1626992766.786342: {"stream":"akrousdt@bookTicker","data":{"e":"bookTicker","u":600860236243,"s":"AKROUSDT","b":"0.01733","B":"27226","a":"0.01735","A":"129372","T":1626992766735,"E":1626992766740}}
1626992766.79308: {"stream":"akrousdt@bookTicker","data":{"e":"bookTicker","u":600860236427,"s":"AKROUSDT","b":"0.01733","B":"27226","a":"0.01735","A":"114951","T":1626992766741,"E":1626992766747}}
1626992766.795388: {"stream":"ctkusdt@bookTicker","data":{"e":"bookTicker","u":600860236526,"s":"CTKUSDT","b":"1.01100","B":"9524","a":"1.01200","A":"8181","T":1626992766745,"E":1626992766748}}
1626992766.795501: {"stream":"akrousdt@bookTicker","data":{"e":"bookTicker","u":600860236620,"s":"AKROUSDT","b":"0.01733","B":"27226","a":"0.01735","A":"100530","T":1626992766746,"E":1626992766750}}
1626992766.835326: {"stream":"akrousdt@bookTicker","data":{"e":"bookTicker","u":600860237873,"s":"AKROUSDT","b":"0.01733","B":"27226","a":"0.01735","A":"14000","T":1626992766786,"E":1626992766790}}
1626992766.8591418: {"stream":"ctkusdt@depth@100ms","data":{"e":"depthUpdate","E":1626992766815,"T":1626992766795,"s":"CTKUSDT","U":600860235627,"u":600860238155,"pu":600860231048,"b":[["1.00000","85616"],["1.00700","8906"],["1.01500","0"]],"a":[["1.01200","8181"],["1.01600","22377"]]}}
1626992766.867786: {"stream":"sushiusdt@depth@100ms","data":{"e":"depthUpdate","E":1626992766822,"T":1626992766777,"s":"SUSHIUSDT","U":600860235820,"u":600860237644,"pu":600860234479,"b":[["7.5480","784"],["7.6080","1350"],["7.6090","4134"]],"a":[["7.6400","816"]]}}
1626992766.872093: {"stream":"akrousdt@depth@100ms","data":{"e":"depthUpdate","E":1626992766826,"T":1626992766818,"s":"AKROUSDT","U":600860235928,"u":600860238765,"pu":600860233461,"b":[["0.01726","283636"],["0.01727","835746"],["0.01729","660023"],["0.01730","502457"],["0.01731","224507"],["0.01732","451656"],["0.01768","0"]],"a":[["0.01734","0"],["0.01735","14000"],["0.01736","292978"],["0.01737","310092"],["0.01738","816409"],["0.01739","515527"],["0.01740","574540"],["0.01741","710277"],["0.01742","570830"],["0.01743","344669"],["0.01744","146177"],["0.01746","76654"],["0.01747","142032"],["0.01748","2683903"],["0.01749","37647"],["0.01750","1591494"],["0.01751","746889"],["0.01753","77613"],["0.01757","142852"],["0.01760","195226"],["0.01762","173601"],["0.01764","49574"],["0.01765","538135"],["0.01767","301392"]]}}
1626992766.897571: {"stream":"akrousdt@bookTicker","data":{"e":"bookTicker","u":600860239086,"s":"AKROUSDT","b":"0.01733","B":"14574","a":"0.01735","A":"14000","T":1626992766832,"E":1626992766836}}
1626992766.901391: {"stream":"akrousdt@bookTicker","data":{"e":"bookTicker","u":600860239198,"s":"AKROUSDT","b":"0.01733","B":"14029","a":"0.01735","A":"14000","T":1626992766838,"E":1626992766843}}
1626992766.90149: {"stream":"akrousdt@bookTicker","data":{"e":"bookTicker","u":600860239209,"s":"AKROUSDT","b":"0.01734","B":"12652","a":"0.01735","A":"14000","T":1626992766838,"E":1626992766844}}
1626992766.901533: {"stream":"akrousdt@bookTicker","data":{"e":"bookTicker","u":600860239368,"s":"AKROUSDT","b":"0.01734","B":"13197","a":"0.01735","A":"14000","T":1626992766844,"E":1626992766850}}
1626992766.91189: {"stream":"ctkusdt@aggTrade","data":{"e":"aggTrade","E":1626992766866,"a":16599323,"s":"CTKUSDT","p":"1.01200","q":"10","f":23961375,"l":23961375,"T":1626992766709,"m":false}}
1626992766.916933: {"stream":"akrousdt@bookTicker","data":{"e":"bookTicker","u":600860239940,"s":"AKROUSDT","b":"0.01734","B":"13197","a":"0.01735","A":"15932","T":1626992766868,"E":1626992766871}}
1626992766.92134: {"stream":"akrousdt@aggTrade","data":{"e":"aggTrade","E":1626992766877,"a":14888308,"s":"AKROUSDT","p":"0.01735","q":"45340","f":27931359,"l":27931360,"T":1626992766722,"m":false}}
1626992766.967326: {"stream":"sushiusdt@depth@100ms","data":{"e":"depthUpdate","E":1626992766923,"T":1626992766904,"s":"SUSHIUSDT","U":600860238764,"u":600860240975,"pu":600860237644,"b":[["7.5030","178"],["7.6080","1280"],["7.6090","4204"]],"a":[["7.6720","361"]]}}
1626992766.977899: {"stream":"akrousdt@bookTicker","data":{"e":"bookTicker","u":600860241716,"s":"AKROUSDT","b":"0.01734","B":"17523","a":"0.01735","A":"15932","T":1626992766929,"E":1626992766933}}
1626992766.980039: {"stream":"akrousdt@depth@100ms","data":{"e":"depthUpdate","E":1626992766936,"T":1626992766932,"s":"AKROUSDT","U":600860239019,"u":600860241806,"pu":600860238765,"b":[["0.01712","964657"],["0.01716","561237"],["0.01728","1064635"],["0.01729","654451"],["0.01731","254489"],["0.01732","709698"],["0.01733","34999"],["0.01734","17523"]],"a":[["0.01735","15932"],["0.01736","249726"],["0.01739","461080"],["0.01740","478825"],["0.01741","868035"],["0.01742","349229"],["0.01743","400956"],["0.01744","156177"],["0.01745","238967"],["0.01746","79524"],["0.01748","2655323"],["0.01751","739484"],["0.01752","247318"],["0.01771","54728"]]}}
1626992766.995934: {"stream":"akrousdt@bookTicker","data":{"e":"bookTicker","u":600860242124,"s":"AKROUSDT","b":"0.01734","B":"31523","a":"0.01735","A":"15932","T":1626992766946,"E":1626992766950}}
1626992767.012128: {"stream":"ctkusdt@depth@100ms","data":{"e":"depthUpdate","E":1626992766967,"T":1626992766952,"s":"CTKUSDT","U":600860239768,"u":600860242266,"pu":600860238155,"b":[["1.00400","5024"],["1.00700","8906"]],"a":[["1.01600","22377"]]}}
1626992767.0388281: {"stream":"keepusdt@depth@100ms","data":{"e":"depthUpdate","E":1626992766986,"T":1626992766970,"s":"KEEPUSDT","U":600860240338,"u":600860243177,"pu":600860234979,"b":[["0.2438","17693"],["0.2440","9281"],["0.2451","4386"],["0.2457","11900"]],"a":[["0.2470","1564"],["0.2471","7059"],["0.2473","29298"]]}}
1626992767.041514: {"stream":"sushiusdt@bookTicker","data":{"e":"bookTicker","u":600860243800,"s":"SUSHIUSDT","b":"7.6170","B":"25","a":"7.6190","A":"87","T":1626992766987,"E":1626992766991}}
1626992767.041632: {"stream":"sushiusdt@kline_1m","data":{"e":"kline","E":1626992766992,"s":"SUSHIUSDT","k":{"t":1626992760000,"T":1626992819999,"s":"SUSHIUSDT","i":"1m","f":126902987,"L":126903001,"o":"7.6180","c":"7.6180","h":"7.6200","l":"7.6160","v":"368","n":15,"x":false,"q":"2803.5980","V":"268","Q":"2041.8960","B":"0"}}}
1626992767.0491898: {"stream":"ctkusdt@bookTicker","data":{"e":"bookTicker","u":600860244873,"s":"CTKUSDT","b":"1.01100","B":"7437","a":"1.01200","A":"8181","T":1626992766997,"E":1626992767001}}
1626992767.056847: {"stream":"sushiusdt@aggTrade","data":{"e":"aggTrade","E":1626992767010,"a":87353266,"s":"SUSHIUSDT","p":"7.6180","q":"13","f":126903001,"l":126903001,"T":1626992766987,"m":true}}
1626992767.056951: {"stream":"sushiusdt@bookTicker","data":{"e":"bookTicker","u":600860245608,"s":"SUSHIUSDT","b":"7.6160","B":"105","a":"7.6190","A":"87","T":1626992767006,"E":1626992767010}}
1626992767.077025: {"stream":"sushiusdt@depth@100ms","data":{"e":"depthUpdate","E":1626992767030,"T":1626992767025,"s":"SUSHIUSDT","U":600860241621,"u":600860247207,"pu":600860240975,"b":[["7.5990","1315"],["7.6000","1529"],["7.6070","2876"],["7.6080","3205"],["7.6090","1373"],["7.6110","1189"],["7.6140","150"],["7.6150","315"],["7.6170","0"],["7.6180","0"]],"a":[["7.6180","0"],["7.6200","764"],["7.6210","1181"],["7.6280","4759"],["7.6290","3051"],["7.6400","796"],["7.6420","711"]]}}
1626992767.083426: {"stream":"akrousdt@depth@100ms","data":{"e":"depthUpdate","E":1626992767037,"T":1626992767026,"s":"AKROUSDT","U":600860241858,"u":600860247301,"pu":600860241806,"b":[["0.01729","640451"],["0.01730","452457"],["0.01732","755820"],["0.01733","24241"],["0.01734","31523"]],"a":[["0.01736","168988"],["0.01738","781809"],["0.01739","386903"],["0.01740","458725"],["0.01741","787297"],["0.01743","410956"],["0.01755","240939"],["0.01772","192699"]]}}
1626992767.087082: {"stream":"sushiusdt@bookTicker","data":{"e":"bookTicker","u":600860248369,"s":"SUSHIUSDT","b":"7.6160","B":"105","a":"7.6190","A":"105","T":1626992767034,"E":1626992767038}}
1626992767.0871968: {"stream":"sushiusdt@aggTrade","data":{"e":"aggTrade","E":1626992767038,"a":87353267,"s":"SUSHIUSDT","p":"7.6170","q":"25","f":126903002,"l":126903002,"T":1626992767006,"m":true}}
1626992767.0872478: {"stream":"sushiusdt@bookTicker","data":{"e":"bookTicker","u":600860248393,"s":"SUSHIUSDT","b":"7.6150","B":"315","a":"7.6190","A":"105","T":1626992767035,"E":1626992767038}}
1626992767.087559: {"stream":"sushiusdt@bookTicker","data":{"e":"bookTicker","u":600860248554,"s":"SUSHIUSDT","b":"7.6150","B":"308","a":"7.6190","A":"105","T":1626992767036,"E":1626992767040}}
1626992767.0987241: {"stream":"sushiusdt@bookTicker","data":{"e":"bookTicker","u":600860249588,"s":"SUSHIUSDT","b":"7.6150","B":"308","a":"7.6190","A":"268","T":1626992767046,"E":1626992767048}}
1626992767.098819: {"stream":"sushiusdt@bookTicker","data":{"e":"bookTicker","u":600860249721,"s":"SUSHIUSDT","b":"7.6150","B":"308","a":"7.6180","A":"36","T":1626992767047,"E":1626992767050}}
1626992767.100588: {"stream":"sushiusdt@bookTicker","data":{"e":"bookTicker","u":600860249788,"s":"SUSHIUSDT","b":"7.6150","B":"230","a":"7.6180","A":"36","T":1626992767048,"E":1626992767052}}
1626992767.106007: {"stream":"sushiusdt@bookTicker","data":{"e":"bookTicker","u":600860250432,"s":"SUSHIUSDT","b":"7.6150","B":"25","a":"7.6180","A":"36","T":1626992767056,"E":1626992767058}}
1626992767.1147661: {"stream":"ctkusdt@bookTicker","data":{"e":"bookTicker","u":600860251286,"s":"CTKUSDT","b":"1.01100","B":"6367","a":"1.01200","A":"8181","T":1626992767064,"E":1626992767068}}
1626992767.119875: {"stream":"ctkusdt@depth@100ms","data":{"e":"depthUpdate","E":1626992767074,"T":1626992767064,"s":"CTKUSDT","U":600860243158,"u":600860251286,"pu":600860242266,"b":[["1.00700","8906"],["1.01100","6367"]],"a":[["1.01300","15200"],["1.01400","20460"],["1.01600","22377"]]}}
1626992767.176369: {"stream":"sushiusdt@bookTicker","data":{"e":"bookTicker","u":600860252518,"s":"SUSHIUSDT","b":"7.6150","B":"25","a":"7.6180","A":"88","T":1626992767128,"E":1626992767130}}
1626992767.179038: {"stream":"keepusdt@depth@100ms","data":{"e":"depthUpdate","E":1626992767135,"T":1626992767130,"s":"KEEPUSDT","U":600860247965,"u":600860252569,"pu":600860243177,"b":[["0.2455","16898"]],"a":[["0.2476","18276"],["0.2478","5380"]]}}
1626992767.17912: {"stream":"sushiusdt@depth@100ms","data":{"e":"depthUpdate","E":1626992767136,"T":1626992767128,"s":"SUSHIUSDT","U":600860248030,"u":600860252518,"pu":600860247207,"b":[["7.5990","1295"],["7.6010","2532"],["7.6080","3205"],["7.6100","525"],["7.6120","575"],["7.6130","205"],["7.6150","25"],["7.6160","0"]],"a":[["7.6180","88"],["7.6190","250"],["7.6210","1162"],["7.6220","1261"],["7.6230","3128"],["7.6240","1186"],["7.6250","1044"],["7.6260","2434"],["7.6410","1204"],["7.6420","691"]]}}
1626992767.208342: {"stream":"akrousdt@depth@100ms","data":{"e":"depthUpdate","E":1626992767163,"T":1626992767134,"s":"AKROUSDT","U":600860250870,"u":600860252782,"pu":600860247301,"b":[["0.01724","280769"]],"a":[["0.01740","438625"],["0.01741","727602"],["0.01742","421220"],["0.01743","491670"]]}}
1626992767.214359: {"stream":"sushiusdt@bookTicker","data":{"e":"bookTicker","u":600860254090,"s":"SUSHIUSDT","b":"7.6150","B":"25","a":"7.6180","A":"106","T":1626992767163,"E":1626992767168}}
1626992767.2165692: {"stream":"akrousdt@bookTicker","data":{"e":"bookTicker","u":600860254262,"s":"AKROUSDT","b":"0.01734","B":"31523","a":"0.01735","A":"14000","T":1626992767164,"E":1626992767170}}
1626992767.216618: {"stream":"sushiusdt@bookTicker","data":{"e":"bookTicker","u":600860254573,"s":"SUSHIUSDT","b":"7.6140","B":"150","a":"7.6180","A":"106","T":1626992767166,"E":1626992767171}}
1626992767.234654: {"stream":"sushiusdt@aggTrade","data":{"e":"aggTrade","E":1626992767189,"a":87353268,"s":"SUSHIUSDT","p":"7.6160","q":"105","f":126903003,"l":126903003,"T":1626992767035,"m":true}}
1626992767.24455: {"stream":"sushiusdt@bookTicker","data":{"e":"bookTicker","u":600860257159,"s":"SUSHIUSDT","b":"7.6140","B":"181","a":"7.6180","A":"106","T":1626992767189,"E":1626992767191}}
1626992767.249911: {"stream":"sushiusdt@bookTicker","data":{"e":"bookTicker","u":600860257910,"s":"SUSHIUSDT","b":"7.6140","B":"109","a":"7.6180","A":"106","T":1626992767197,"E":1626992767199}}
1626992767.255286: {"stream":"akrousdt@bookTicker","data":{"e":"bookTicker","u":600860258249,"s":"AKROUSDT","b":"0.01734","B":"17523","a":"0.01735","A":"14000","T":1626992767201,"E":1626992767204}}
1626992767.259559: {"stream":"ctkusdt@depth@100ms","data":{"e":"depthUpdate","E":1626992767213,"T":1626992767198,"s":"CTKUSDT","U":600860252158,"u":600860257970,"pu":600860251286,"b":[["1.00300","5769"],["1.01000","81234"]],"a":[["1.01300","16170"],["1.01400","20214"],["1.01500","17996"],["1.01800","10919"]]}}
1626992767.267144: {"stream":"ctkusdt@bookTicker","data":{"e":"bookTicker","u":600860259518,"s":"CTKUSDT","b":"1.01100","B":"6367","a":"1.01200","A":"8981","T":1626992767217,"E":1626992767222}}
1626992767.282511: {"stream":"sushiusdt@depth@100ms","data":{"e":"depthUpdate","E":1626992767237,"T":1626992767232,"s":"SUSHIUSDT","U":600860252666,"u":600860260579,"pu":600860252518,"b":[["7.6010","5682"],["7.6040","712"],["7.6060","3829"],["7.6070","2684"],["7.6080","978"],["7.6090","1281"],["7.6100","199"],["7.6110","205"],["7.6120","212"],["7.6130","282"],["7.6140","109"],["7.6150","0"]],"a":[["7.6180","106"],["7.6190","220"],["7.6200","694"],["7.6210","1559"],["7.6220","1986"],["7.6240","396"],["7.6250","943"],["7.6260","2426"],["7.6270","2230"],["7.6280","3936"],["7.6420","661"]]}}
1626992767.292334: {"stream":"sushiusdt@bookTicker","data":{"e":"bookTicker","u":600860261422,"s":"SUSHIUSDT","b":"7.6140","B":"109","a":"7.6180","A":"223","T":1626992767240,"E":1626992767245}}
1626992767.292384: {"stream":"sushiusdt@bookTicker","data":{"e":"bookTicker","u":600860261590,"s":"SUSHIUSDT","b":"7.6140","B":"109","a":"7.6180","A":"205","T":1626992767242,"E":1626992767247}}
1626992767.296545: {"stream":"sushiusdt@bookTicker","data":{"e":"bookTicker","u":600860261922,"s":"SUSHIUSDT","b":"7.6140","B":"110","a":"7.6180","A":"205","T":1626992767245,"E":1626992767250}}
1626992767.299701: {"stream":"sushiusdt@bookTicker","data":{"e":"bookTicker","u":600860262340,"s":"SUSHIUSDT","b":"7.6140","B":"32","a":"7.6180","A":"205","T":1626992767250,"E":1626992767253}}
1626992767.305064: {"stream":"keepusdt@depth@100ms","data":{"e":"depthUpdate","E":1626992767258,"T":1626992767248,"s":"KEEPUSDT","U":600860253427,"u":600860262179,"pu":600860252569,"b":[["0.2381","0"],["0.2385","33907"],["0.2456","12364"],["0.2458","10132"]],"a":[["0.2479","113440"],["0.2485","3251"],["0.2548","27"],["0.2552","17196"],["0.2597","46807"]]}}
1626992767.312928: {"stream":"sushiusdt@bookTicker","data":{"e":"bookTicker","u":600860263779,"s":"SUSHIUSDT","b":"7.6140","B":"1","a":"7.6180","A":"205","T":1626992767264,"E":1626992767266}}
1626992767.315906: {"stream":"akrousdt@depth@100ms","data":{"e":"depthUpdate","E":1626992767270,"T":1626992767265,"s":"AKROUSDT","U":600860254262,"u":600860263863,"pu":600860252782,"b":[["0.01725","733841"],["0.01727","788351"],["0.01729","591339"],["0.01730","332436"],["0.01731","194962"],["0.01733","26325"],["0.01734","17523"]],"a":[["0.01735","14000"],["0.01740","378963"]]}}
1626992767.316579: {"stream":"sushiusdt@bookTicker","data":{"e":"bookTicker","u":600860264259,"s":"SUSHIUSDT","b":"7.6140","B":"1","a":"7.6170","A":"18","T":1626992767268,"E":1626992767270}}
1626992767.3533802: {"stream":"sushiusdt@bookTicker","data":{"e":"bookTicker","u":600860267830,"s":"SUSHIUSDT","b":"7.6140","B":"1","a":"7.6170","A":"428","T":1626992767304,"E":1626992767307}}
1626992767.3682969: {"stream":"ctkusdt@depth@100ms","data":{"e":"depthUpdate","E":1626992767322,"T":1626992767300,"s":"CTKUSDT","U":600860259518,"u":600860267416,"pu":600860257970,"b":[["1.00000","85216"],["1.00700","9145"],["1.00800","15621"],["1.00900","22096"],["1.01000","80348"]],"a":[["1.01200","8981"]]}}
1626992767.383219: {"stream":"sushiusdt@depth@100ms","data":{"e":"depthUpdate","E":1626992767338,"T":1626992767324,"s":"SUSHIUSDT","U":600860260848,"u":600860269945,"pu":600860260579,"b":[["7.5300","2353"],["7.5600","494"],["7.5730","2535"],["7.6010","5662"],["7.6020","910"],["7.6030","623"],["7.6040","782"],["7.6050","2393"],["7.6060","1700"],["7.6070","2984"],["7.6080","686"],["7.6090","563"],["7.6100","258"],["7.6130","313"],["7.6140","1"]],"a":[["7.6170","428"],["7.6180","205"],["7.6190","351"],["7.6200","944"],["7.6210","1291"],["7.6220","3260"],["7.6230","1962"],["7.6240","422"],["7.6250","693"],["7.6260","3097"],["7.6270","1283"],["7.6290","3312"],["7.6300","1099"],["7.6340","5751"],["7.6350","2326"],["7.6360","6157"],["7.6370","2238"],["7.6390","1114"],["7.6410","1184"],["7.6920","16"],["7.7100","1470"]]}}
1626992767.404586: {"stream":"keepusdt@depth@100ms","data":{"e":"depthUpdate","E":1626992767359,"T":1626992767330,"s":"KEEPUSDT","U":600860262874,"u":600860270160,"pu":600860262179,"b":[["0.2439","6703"]],"a":[["0.2477","18585"],["0.2478","9590"],["0.2485","17985"],["0.2490","58223"]]}}
1626992767.408843: {"stream":"sushiusdt@bookTicker","data":{"e":"bookTicker","u":600860272112,"s":"SUSHIUSDT","b":"7.6140","B":"1","a":"7.6160","A":"150","T":1626992767360,"E":1626992767363}}
1626992767.4216661: {"stream":"akrousdt@bookTicker","data":{"e":"bookTicker","u":600860273335,"s":"AKROUSDT","b":"0.01734","B":"16978","a":"0.01735","A":"14000","T":1626992767372,"E":1626992767375}}
1626992767.430104: {"stream":"sushiusdt@bookTicker","data":{"e":"bookTicker","u":600860274242,"s":"SUSHIUSDT","b":"7.6130","B":"236","a":"7.6160","A":"150","T":1626992767382,"E":1626992767385}}
1626992767.433899: {"stream":"akrousdt@depth@100ms","data":{"e":"depthUpdate","E":1626992767388,"T":1626992767374,"s":"AKROUSDT","U":600860265995,"u":600860273507,"pu":600860263863,"b":[["0.01692","14676"],["0.01728","1116600"],["0.01729","539016"],["0.01734","16978"]],"a":[["0.01736","215110"],["0.01739","404103"],["0.01740","225841"],["0.01743","518538"]]}}
1626992767.4664268: {"stream":"sushiusdt@bookTicker","data":{"e":"bookTicker","u":600860277093,"s":"SUSHIUSDT","b":"7.6130","B":"205","a":"7.6160","A":"150","T":1626992767415,"E":1626992767419}}
1626992767.468666: {"stream":"ctkusdt@depth@100ms","data":{"e":"depthUpdate","E":1626992767423,"T":1626992767366,"s":"CTKUSDT","U":600860269554,"u":600860272702,"pu":600860267416,"b":[],"a":[["1.01300","16416"],["1.01500","17935"]]}}
1626992767.486826: {"stream":"sushiusdt@bookTicker","data":{"e":"bookTicker","u":600860279095,"s":"SUSHIUSDT","b":"7.6120","B":"197","a":"7.6160","A":"150","T":1626992767438,"E":1626992767441}}
1626992767.486855: {"stream":"sushiusdt@depth@100ms","data":{"e":"depthUpdate","E":1626992767442,"T":1626992767438,"s":"SUSHIUSDT","U":600860270366,"u":600860279110,"pu":600860269945,"b":[["7.5600","3495"],["7.5690","2250"],["7.5840","2682"],["7.5920","1918"],["7.5940","1203"],["7.5950","819"],["7.5970","445"],["7.5990","966"],["7.6000","926"],["7.6010","5073"],["7.6020","930"],["7.6030","692"],["7.6060","1674"],["7.6070","1562"],["7.6080","1385"],["7.6090","215"],["7.6100","66"],["7.6120","197"],["7.6130","0"],["7.6140","0"]],"a":[["7.6160","150"],["7.6170","410"],["7.6190","546"],["7.6200","1157"],["7.6210","3607"],["7.6220","944"],["7.6230","1912"],["7.6260","3123"],["7.6270","1350"],["7.6280","3124"],["7.6290","3627"],["7.6310","4029"],["7.6360","5238"],["7.6370","2599"],["7.6400","610"],["7.6440","2337"],["7.6800","3778"]]}}
1626992767.492039: {"stream":"akrousdt@bookTicker","data":{"e":"bookTicker","u":600860279644,"s":"AKROUSDT","b":"0.01734","B":"17480","a":"0.01735","A":"14000","T":1626992767443,"E":1626992767447}}
1626992767.492065: {"stream":"sushiusdt@bookTicker","data":{"e":"bookTicker","u":600860279780,"s":"SUSHIUSDT","b":"7.6120","B":"197","a":"7.6160","A":"209","T":1626992767444,"E":1626992767447}}
1626992767.4983869: {"stream":"sushiusdt@bookTicker","data":{"e":"bookTicker","u":600860280078,"s":"SUSHIUSDT","b":"7.6120","B":"197","a":"7.6160","A":"227","T":1626992767448,"E":1626992767452}}
1626992767.501902: {"stream":"sushiusdt@bookTicker","data":{"e":"bookTicker","u":600860280287,"s":"SUSHIUSDT","b":"7.6120","B":"197","a":"7.6160","A":"344","T":1626992767450,"E":1626992767454}}
1626992767.502584: {"stream":"sushiusdt@bookTicker","data":{"e":"bookTicker","u":600860280408,"s":"SUSHIUSDT","b":"7.6110","B":"205","a":"7.6160","A":"344","T":1626992767451,"E":1626992767456}}
1626992767.5026062: {"stream":"sushiusdt@bookTicker","data":{"e":"bookTicker","u":600860280438,"s":"SUSHIUSDT","b":"7.6120","B":"31","a":"7.6160","A":"344","T":1626992767451,"E":1626992767456}}
1626992767.5222132: {"stream":"ctkusdt@bookTicker","data":{"e":"bookTicker","u":600860282263,"s":"CTKUSDT","b":"1.01100","B":"6367","a":"1.01200","A":"9701","T":1626992767471,"E":1626992767474}}
1626992767.526786: {"stream":"sushiusdt@bookTicker","data":{"e":"bookTicker","u":600860282373,"s":"SUSHIUSDT","b":"7.6120","B":"31","a":"7.6150","A":"3","T":1626992767473,"E":1626992767475}}
1626992767.533747: {"stream":"akrousdt@depth@100ms","data":{"e":"depthUpdate","E":1626992767490,"T":1626992767470,"s":"AKROUSDT","U":600860274555,"u":600860282216,"pu":600860273507,"b":[["0.01685","337569"],["0.01729","488016"],["0.01731","208900"],["0.01732","741982"],["0.01734","17480"]],"a":[["0.01736","249702"],["0.01739","543035"],["0.01741","787020"],["0.01742","439830"]]}}
1626992767.5440042: {"stream":"keepusdt@kline_1m","data":{"e":"kline","E":1626992767499,"s":"KEEPUSDT","k":{"t":1626992760000,"T":1626992819999,"s":"KEEPUSDT","i":"1m","f":2398360,"L":2398360,"o":"0.2468","c":"0.2468","h":"0.2468","l":"0.2468","v":"500","n":1,"x":false,"q":"123.4000","V":"0","Q":"0.0000","B":"0"}}}
1626992767.5445151: {"stream":"sushiusdt@bookTicker","data":{"e":"bookTicker","u":600860284335,"s":"SUSHIUSDT","b":"7.6120","B":"31","a":"7.6160","A":"326","T":1626992767494,"E":1626992767499}}
1626992767.546138: {"stream":"keepusdt@bookTicker","data":{"e":"bookTicker","u":600860284484,"s":"KEEPUSDT","b":"0.2468","B":"2718","a":"0.2469","A":"851","T":1626992767496,"E":1626992767499}}
1626992767.549058: {"stream":"sushiusdt@bookTicker","data":{"e":"bookTicker","u":600860284881,"s":"SUSHIUSDT","b":"7.6120","B":"31","a":"7.6150","A":"18","T":1626992767501,"E":1626992767504}}
1626992767.549133: {"stream":"sushiusdt@bookTicker","data":{"e":"bookTicker","u":600860284886,"s":"SUSHIUSDT","b":"7.6110","B":"441","a":"7.6150","A":"18","T":1626992767501,"E":1626992767504}}
1626992767.555813: {"stream":"ctkusdt@bookTicker","data":{"e":"bookTicker","u":600860285066,"s":"CTKUSDT","b":"1.01100","B":"5212","a":"1.01200","A":"9701","T":1626992767503,"E":1626992767507}}
1626992767.55586: {"stream":"ctkusdt@kline_1m","data":{"e":"kline","E":1626992767508,"s":"CTKUSDT","k":{"t":1626992760000,"T":1626992819999,"s":"CTKUSDT","i":"1m","f":23961361,"L":23961376,"o":"1.01200","c":"1.01100","h":"1.01200","l":"1.01100","v":"4196","n":16,"x":false,"q":"4242.21600","V":"60","Q":"60.72000","B":"0"}}}
1626992767.561197: {"stream":"keepusdt@bookTicker","data":{"e":"bookTicker","u":600860285963,"s":"KEEPUSDT","b":"0.2468","B":"2218","a":"0.2469","A":"851","T":1626992767512,"E":1626992767516}}
1626992767.5662541: {"stream":"keepusdt@depth@100ms","data":{"e":"depthUpdate","E":1626992767519,"T":1626992767512,"s":"KEEPUSDT","U":600860277183,"u":600860285963,"pu":600860270160,"b":[["0.2461","5475"],["0.2468","2218"]],"a":[["0.2468","0"],["0.2597","8686"],["0.2598","76874"]]}}
1626992767.566423: {"stream":"ctkusdt@bookTicker","data":{"e":"bookTicker","u":600860286371,"s":"CTKUSDT","b":"1.01100","B":"4412","a":"1.01200","A":"9701","T":1626992767516,"E":1626992767519}}
1626992767.572949: {"stream":"ctkusdt@bookTicker","data":{"e":"bookTicker","u":600860287299,"s":"CTKUSDT","b":"1.01100","B":"4412","a":"1.01200","A":"11162","T":1626992767525,"E":1626992767527}}
1626992767.57554: {"stream":"ctkusdt@bookTicker","data":{"e":"bookTicker","u":600860287562,"s":"CTKUSDT","b":"1.01100","B":"2312","a":"1.01200","A":"11162","T":1626992767527,"E":1626992767530}}
1626992767.577751: {"stream":"ctkusdt@depth@100ms","data":{"e":"depthUpdate","E":1626992767532,"T":1626992767527,"s":"CTKUSDT","U":600860278396,"u":600860287562,"pu":600860272702,"b":[["1.00000","84816"],["1.00600","9719"],["1.00700","9503"],["1.00800","15263"],["1.01100","2312"]],"a":[["1.01100","0"],["1.01200","11162"],["1.01300","16694"],["1.01400","20039"]]}}
1626992767.58799: {"stream":"ctkusdt@bookTicker","data":{"e":"bookTicker","u":600860288395,"s":"CTKUSDT","b":"1.01100","B":"1512","a":"1.01200","A":"11162","T":1626992767538,"E":1626992767542}}
1626992767.590962: {"stream":"ctkusdt@bookTicker","data":{"e":"bookTicker","u":600860288519,"s":"CTKUSDT","b":"1.01100","B":"1300","a":"1.01200","A":"11162","T":1626992767539,"E":1626992767543}}
1626992767.591058: {"stream":"sushiusdt@depth@100ms","data":{"e":"depthUpdate","E":1626992767544,"T":1626992767539,"s":"SUSHIUSDT","U":600860279453,"u":600860288500,"pu":600860279110,"b":[["6.8500","65"],["7.5700","633"],["7.5730","2131"],["7.5840","4288"],["7.5870","1687"],["7.5920","1948"],["7.5940","1173"],["7.5950","886"],["7.5970","1102"],["7.5980","6180"],["7.6000","1140"],["7.6010","1923"],["7.6020","904"],["7.6030","2596"],["7.6040","1346"],["7.6050","964"],["7.6060","1349"],["7.6070","1505"],["7.6090","298"],["7.6100","55"],["7.6110","441"],["7.6120","0"]],"a":[["7.6150","18"],["7.6160","326"],["7.6180","873"],["7.6190","1386"],["7.6200","1157"],["7.6210","1291"],["7.6230","1366"],["7.6250","823"],["7.6260","2558"],["7.6310","3745"],["7.6350","1670"],["7.6430","2788"],["7.6450","3021"],["7.6470","2528"],["7.6480","433"],["7.6590","336"]]}}
1626992767.597177: {"stream":"ctkusdt@bookTicker","data":{"e":"bookTicker","u":600860288906,"s":"CTKUSDT","b":"1.01100","B":"766","a":"1.01200","A":"11162","T":1626992767544,"E":1626992767550}}
1626992767.5972748: {"stream":"ctkusdt@bookTicker","data":{"e":"bookTicker","u":600860289082,"s":"CTKUSDT","b":"1.01100","B":"570","a":"1.01200","A":"11162","T":1626992767546,"E":1626992767551}}
1626992767.5973198: {"stream":"ctkusdt@bookTicker","data":{"e":"bookTicker","u":600860289155,"s":"CTKUSDT","b":"1.01100","B":"83","a":"1.01200","A":"11162","T":1626992767546,"E":1626992767551}}
1626992767.597355: {"stream":"keepusdt@bookTicker","data":{"e":"bookTicker","u":600860289243,"s":"KEEPUSDT","b":"0.2468","B":"1172","a":"0.2469","A":"851","T":1626992767547,"E":1626992767552}}
1626992767.6001558: {"stream":"ctkusdt@aggTrade","data":{"e":"aggTrade","E":1626992767553,"a":16599324,"s":"CTKUSDT","p":"1.01100","q":"5567","f":23961376,"l":23961392,"T":1626992767503,"m":true}}
1626992767.600234: {"stream":"ctkusdt@bookTicker","data":{"e":"bookTicker","u":600860289616,"s":"CTKUSDT","b":"1.01000","B":"80276","a":"1.01200","A":"11162","T":1626992767550,"E":1626992767553}}
1626992767.610208: {"stream":"ctkusdt@bookTicker","data":{"e":"bookTicker","u":600860290673,"s":"CTKUSDT","b":"1.01000","B":"80276","a":"1.01100","A":"429","T":1626992767561,"E":1626992767563}}
1626992767.6105752: {"stream":"ctkusdt@bookTicker","data":{"e":"bookTicker","u":600860290848,"s":"CTKUSDT","b":"1.01000","B":"80276","a":"1.01100","A":"2254","T":1626992767563,"E":1626992767566}}
1626992767.6179142: {"stream":"keepusdt@bookTicker","data":{"e":"bookTicker","u":600860291219,"s":"KEEPUSDT","b":"0.2467","B":"457","a":"0.2469","A":"851","T":1626992767567,"E":1626992767569}}
1626992767.620697: {"stream":"ctkusdt@bookTicker","data":{"e":"bookTicker","u":600860291381,"s":"CTKUSDT","b":"1.01000","B":"80276","a":"1.01100","A":"2756","T":1626992767570,"E":1626992767571}}
1626992767.6207948: {"stream":"ctkusdt@bookTicker","data":{"e":"bookTicker","u":600860291577,"s":"CTKUSDT","b":"1.01000","B":"80276","a":"1.01100","A":"2856","T":1626992767571,"E":1626992767574}}
1626992767.6364229: {"stream":"akrousdt@depth@100ms","data":{"e":"depthUpdate","E":1626992767591,"T":1626992767588,"s":"AKROUSDT","U":600860283591,"u":600860293008,"pu":600860282216,"b":[],"a":[["0.01737","563496"],["0.01739","590181"]]}}
1626992767.6391969: {"stream":"ctkusdt@bookTicker","data":{"e":"bookTicker","u":600860293061,"s":"CTKUSDT","b":"1.01000","B":"80281","a":"1.01100","A":"2856","T":1626992767589,"E":1626992767591}}
1626992767.639296: {"stream":"ctkusdt@bookTicker","data":{"e":"bookTicker","u":600860293187,"s":"CTKUSDT","b":"1.01000","B":"75338","a":"1.01100","A":"2856","T":1626992767590,"E":1626992767593}}
1626992767.6393569: {"stream":"ctkusdt@bookTicker","data":{"e":"bookTicker","u":600860293271,"s":"CTKUSDT","b":"1.01000","B":"76822","a":"1.01100","A":"2856","T":1626992767591,"E":1626992767594}}
1626992767.672792: {"stream":"ctkusdt@bookTicker","data":{"e":"bookTicker","u":600860295996,"s":"CTKUSDT","b":"1.01000","B":"77998","a":"1.01100","A":"2856","T":1626992767624,"E":1626992767627}}
1626992767.687937: {"stream":"ctkusdt@depth@100ms","data":{"e":"depthUpdate","E":1626992767642,"T":1626992767628,"s":"CTKUSDT","U":600860288395,"u":600860296330,"pu":600860287562,"b":[["1.00700","13503"],["1.00800","11109"],["1.00900","16123"],["1.01000","77998"],["1.01100","0"]],"a":[["1.01100","2856"],["1.01200","17557"],["1.01300","9588"],["1.01400","12057"],["1.01600","23548"],["1.01700","11863"],["1.01800","6919"]]}}
1626992767.695717: {"stream":"sushiusdt@depth@100ms","data":{"e":"depthUpdate","E":1626992767648,"T":1626992767642,"s":"SUSHIUSDT","U":600860288625,"u":600860297381,"pu":600860288500,"b":[["7.5800","3707"],["7.5830","5932"],["7.5850","1689"],["7.5880","1504"],["7.5900","1770"],["7.5930","2890"],["7.5970","1260"],["7.5990","808"],["7.6040","1006"],["7.6050","1014"],["7.6060","1722"],["7.6070","1300"],["7.6080","931"],["7.6100","155"]],"a":[["7.6170","417"],["7.6180","938"],["7.6190","1519"],["7.6200","1850"],["7.6210","1441"],["7.6220","920"],["7.6240","396"],["7.6250","890"],["7.6270","1283"],["7.6300","1166"],["7.6320","739"],["7.6350","1762"],["7.6370","2378"],["7.6430","2943"],["7.6450","3039"],["7.6470","2353"],["7.6560","353"],["7.6580","434"],["7.6630","500"],["7.6860","820"]]}}
1626992767.696047: {"stream":"keepusdt@depth@100ms","data":{"e":"depthUpdate","E":1626992767650,"T":1626992767568,"s":"KEEPUSDT","U":600860288928,"u":600860291262,"pu":600860285963,"b":[["0.2461","3580"],["0.2463","384"],["0.2468","0"]],"a":[["0.2468","0"],["0.2470","10055"],["0.2495","2234"]]}}
1626992767.696194: {"stream":"keepusdt@aggTrade","data":{"e":"aggTrade","E":1626992767650,"a":1211539,"s":"KEEPUSDT","p":"0.2468","q":"3218","f":2398360,"l":2398363,"T":1626992767496,"m":true}}
1626992767.7224479: {"stream":"sushiusdt@bookTicker","data":{"e":"bookTicker","u":600860300391,"s":"SUSHIUSDT","b":"7.6110","B":"415","a":"7.6150","A":"18","T":1626992767674,"E":1626992767677}}
1626992767.748596: {"stream":"akrousdt@depth@100ms","data":{"e":"depthUpdate","E":1626992767703,"T":1626992767696,"s":"AKROUSDT","U":600860293947,"u":600860302110,"pu":600860293008,"b":[["0.01682","123484"],["0.01724","257770"],["0.01727","835022"],["0.01728","1047364"]],"a":[["0.01736","269676"],["0.01737","566950"],["0.01738","682309"],["0.01739","301450"],["0.01740","357166"],["0.01741","1008384"],["0.01743","512801"]]}}
1626992767.748693: {"stream":"ctkusdt@aggTrade","data":{"e":"aggTrade","E":1626992767704,"a":16599325,"s":"CTKUSDT","p":"1.01000","q":"72","f":23961393,"l":23961393,"T":1626992767550,"m":true}}
1626992767.793385: {"stream":"sushiusdt@depth@100ms","data":{"e":"depthUpdate","E":1626992767748,"T":1626992767740,"s":"SUSHIUSDT","U":600860297717,"u":600860305557,"pu":600860297381,"b":[["7.5790","721"],["7.5850","1669"],["7.5940","1502"],["7.5950","991"],["7.5980","6263"],["7.5990","726"],["7.6000","952"],["7.6010","2904"],["7.6020","1083"],["7.6030","2666"],["7.6050","1094"],["7.6060","118"],["7.6070","1433"],["7.6100","100"],["7.6110","415"],["7.6910","0"]],"a":[["7.6190","1499"],["7.6200","2508"],["7.6210","1441"],["7.6220","409"],["7.6320","417"],["7.6340","5869"],["7.6360","5122"],["7.6370","2303"],["7.6400","584"],["7.6510","1874"],["7.6570","4836"],["7.6600","8352"],["7.6780","556"]]}}
1626992767.7969449: {"stream":"ctkusdt@depth@100ms","data":{"e":"depthUpdate","E":1626992767751,"T":1626992767737,"s":"CTKUSDT","U":600860297946,"u":600860305307,"pu":600860296330,"b":[["1.00600","9967"],["1.00700","12437"]],"a":[["1.01200","16457"],["1.01600","23695"]]}}
1626992767.813687: {"stream":"keepusdt@depth@100ms","data":{"e":"depthUpdate","E":1626992767769,"T":1626992767764,"s":"KEEPUSDT","U":600860299771,"u":600860307544,"pu":600860291262,"b":[["0.2394","11265"],["0.2401","34961"],["0.2411","17925"],["0.2412","23341"],["0.2419","48246"],["0.2420","6853"],["0.2421","9009"],["0.2422","13297"],["0.2427","7704"],["0.2428","8354"],["0.2429","30305"],["0.2430","3301"],["0.2434","19889"],["0.2436","614"],["0.2437","16299"],["0.2438","18143"],["0.2439","8341"],["0.2440","7645"],["0.2441","2987"],["0.2443","6425"],["0.2444","1777"],["0.2448","8713"],["0.2449","17621"],["0.2450","92783"],["0.2453","6217"],["0.2459","4156"],["0.2461","339"]],"a":[["0.2472","6851"],["0.2474","5966"],["0.2520","9736"],["0.2528","26238"],["0.2598","115319"]]}}
1626992767.83911: {"stream":"ctkusdt@bookTicker","data":{"e":"bookTicker","u":600860309598,"s":"CTKUSDT","b":"1.01000","B":"77998","a":"1.01100","A":"2427","T":1626992767788,"E":1626992767792}}
1626992767.8392088: {"stream":"ctkusdt@bookTicker","data":{"e":"bookTicker","u":600860309645,"s":"CTKUSDT","b":"1.01000","B":"77998","a":"1.01100","A":"1925","T":1626992767789,"E":1626992767794}}
1626992767.859651: {"stream":"akrousdt@depth@100ms","data":{"e":"depthUpdate","E":1626992767814,"T":1626992767801,"s":"AKROUSDT","U":600860303151,"u":600860310690,"pu":600860302110,"b":[["0.01722","2998162"],["0.01726","274639"],["0.01727","814838"],["0.01728","1186802"],["0.01729","348746"]],"a":[["0.01736","287105"],["0.01737","575585"],["0.01738","646961"],["0.01739","353350"],["0.01741","1154827"],["0.01744","147273"]]}}
1626992767.914811: {"stream":"ctkusdt@bookTicker","data":{"e":"bookTicker","u":600860313085,"s":"CTKUSDT","b":"1.01000","B":"77909","a":"1.01100","A":"1925","T":1626992767833,"E":1626992767836}}
1626992767.9188101: {"stream":"ctkusdt@bookTicker","data":{"e":"bookTicker","u":600860313735,"s":"CTKUSDT","b":"1.01000","B":"77909","a":"1.01100","A":"2985","T":1626992767844,"E":1626992767848}}
1626992767.9189079: {"stream":"sushiusdt@depth@100ms","data":{"e":"depthUpdate","E":1626992767851,"T":1626992767845,"s":"SUSHIUSDT","U":600860306018,"u":600860313774,"pu":600860305557,"b":[["7.5730","2440"],["7.5790","741"],["7.5800","4023"],["7.5860","1329"],["7.5960","1164"],["7.5980","6418"],["7.5990","762"],["7.6000","1429"],["7.6010","2837"],["7.6020","928"],["7.6060","246"],["7.6070","1305"],["7.6080","946"],["7.6090","283"]],"a":[["7.6260","2873"],["7.6290","3312"],["7.6300","2149"],["7.6310","3725"],["7.6340","5074"],["7.6350","1788"],["7.6370","2117"],["7.6550","939"]]}}
1626992767.919105: {"stream":"ctkusdt@depth@100ms","data":{"e":"depthUpdate","E":1626992767860,"T":1626992767853,"s":"CTKUSDT","U":600860306743,"u":600860314255,"pu":600860305307,"b":[["1.00800","10189"],["1.00900","16196"],["1.01000","77909"]],"a":[["1.01100","2985"],["1.01200","18039"],["1.01600","23607"]]}}
1626992767.924499: {"stream":"sushiusdt@bookTicker","data":{"e":"bookTicker","u":600860315280,"s":"SUSHIUSDT","b":"7.6110","B":"415","a":"7.6160","A":"326","T":1626992767871,"E":1626992767876}}
1626992767.9245949: {"stream":"sushiusdt@bookTicker","data":{"e":"bookTicker","u":600860315285,"s":"SUSHIUSDT","b":"7.6110","B":"415","a":"7.6160","A":"344","T":1626992767871,"E":1626992767876}}
1626992767.92465: {"stream":"ctkusdt@bookTicker","data":{"e":"bookTicker","u":600860315488,"s":"CTKUSDT","b":"1.01000","B":"77909","a":"1.01100","A":"1160","T":1626992767874,"E":1626992767880}}
1626992767.943867: {"stream":"keepusdt@kline_1m","data":{"e":"kline","E":1626992767899,"s":"KEEPUSDT","k":{"t":1626992760000,"T":1626992819999,"s":"KEEPUSDT","i":"1m","f":2398360,"L":2398364,"o":"0.2468","c":"0.2467","h":"0.2468","l":"0.2467","v":"3675","n":5,"x":false,"q":"906.9443","V":"0","Q":"0.0000","B":"0"}}}
1626992767.943993: {"stream":"keepusdt@bookTicker","data":{"e":"bookTicker","u":600860316600,"s":"KEEPUSDT","b":"0.2463","B":"384","a":"0.2469","A":"851","T":1626992767894,"E":1626992767899}}
1626992767.948061: {"stream":"ctkusdt@bookTicker","data":{"e":"bookTicker","u":600860316822,"s":"CTKUSDT","b":"1.01000","B":"77909","a":"1.01100","A":"1150","T":1626992767897,"E":1626992767903}}
1626992767.948159: {"stream":"ctkusdt@kline_1m","data":{"e":"kline","E":1626992767904,"s":"CTKUSDT","k":{"t":1626992760000,"T":1626992819999,"s":"CTKUSDT","i":"1m","f":23961361,"L":23961394,"o":"1.01200","c":"1.01100","h":"1.01200","l":"1.01000","v":"9716","n":34,"x":false,"q":"9822.86400","V":"70","Q":"70.83000","B":"0"}}}
1626992767.9565928: {"stream":"keepusdt@bookTicker","data":{"e":"bookTicker","u":600860317211,"s":"KEEPUSDT","b":"0.2462","B":"339","a":"0.2469","A":"851","T":1626992767904,"E":1626992767909}}
1626992767.956689: {"stream":"keepusdt@bookTicker","data":{"e":"bookTicker","u":600860317274,"s":"KEEPUSDT","b":"0.2462","B":"339","a":"0.2469","A":"1327","T":1626992767905,"E":1626992767909}}
1626992767.964294: {"stream":"akrousdt@depth@100ms","data":{"e":"depthUpdate","E":1626992767920,"T":1626992767897,"s":"AKROUSDT","U":600860311862,"u":600860316773,"pu":600860310690,"b":[["0.01731","165637"],["0.01732","785221"]],"a":[["0.01736","301518"],["0.01737","589998"],["0.01739","376400"],["0.01741","1255327"],["0.01743","498458"]]}}
1626992767.975638: {"stream":"keepusdt@depth@100ms","data":{"e":"depthUpdate","E":1626992767928,"T":1626992767921,"s":"KEEPUSDT","U":600860312439,"u":600860318236,"pu":600860307544,"b":[["0.2448","8795"],["0.2449","18429"],["0.2453","6135"],["0.2455","16582"],["0.2463","0"],["0.2467","0"]],"a":[["0.2469","1327"],["0.2476","18654"],["0.2477","20034"],["0.2485","3251"]]}}
1626992767.9871428: {"stream":"keepusdt@aggTrade","data":{"e":"aggTrade","E":1626992767940,"a":1211540,"s":"KEEPUSDT","p":"0.2467","q":"457","f":2398364,"l":2398364,"T":1626992767894,"m":true}}
1626992767.9872441: {"stream":"keepusdt@bookTicker","data":{"e":"bookTicker","u":600860319272,"s":"KEEPUSDT","b":"0.2462","B":"339","a":"0.2467","A":"232","T":1626992767936,"E":1626992767940}}
1626992767.9872918: {"stream":"keepusdt@bookTicker","data":{"e":"bookTicker","u":600860319303,"s":"KEEPUSDT","b":"0.2462","B":"339","a":"0.2467","A":"86","T":1626992767937,"E":1626992767940}}
1626992767.991633: {"stream":"keepusdt@bookTicker","data":{"e":"bookTicker","u":600860319421,"s":"KEEPUSDT","b":"0.2463","B":"249","a":"0.2467","A":"86","T":1626992767939,"E":1626992767943}}
1626992767.99173: {"stream":"ctkusdt@bookTicker","data":{"e":"bookTicker","u":600860319463,"s":"CTKUSDT","b":"1.01000","B":"76733","a":"1.01100","A":"1150","T":1626992767939,"E":1626992767943}}
1626992767.9917738: {"stream":"keepusdt@bookTicker","data":{"e":"bookTicker","u":600860319513,"s":"KEEPUSDT","b":"0.2463","B":"249","a":"0.2468","A":"258","T":1626992767940,"E":1626992767945}}
1626992767.9966211: {"stream":"sushiusdt@depth@100ms","data":{"e":"depthUpdate","E":1626992767951,"T":1626992767936,"s":"SUSHIUSDT","U":600860313860,"u":600860319283,"pu":600860313774,"b":[["7.5460","1647"],["7.5500","3284"],["7.5690","2164"],["7.5750","439"],["7.5830","5616"],["7.5870","1860"],["7.5970","1102"],["7.6030","2824"],["7.6050","1200"],["7.6070","1300"]],"a":[["7.6150","0"],["7.6160","344"],["7.6230","1496"],["7.6250","760"],["7.6260","2893"],["7.6290","3286"],["7.6310","3403"],["7.6320","1074"],["7.6340","5028"],["7.6360","5037"],["7.6430","2788"],["7.6500","872"],["7.6630","389"],["7.6820","1518"],["7.6860","351"]]}}
1626992768.0038059: {"stream":"keepusdt@bookTicker","data":{"e":"bookTicker","u":600860320070,"s":"KEEPUSDT","b":"0.2463","B":"249","a":"0.2468","A":"569","T":1626992767955,"E":1626992767959}}
1626992768.0135: {"stream":"sushiusdt@bookTicker","data":{"e":"bookTicker","u":600860320483,"s":"SUSHIUSDT","b":"7.6110","B":"303","a":"7.6160","A":"344","T":1626992767962,"E":1626992767967}}
1626992768.024319: {"stream":"ctkusdt@depth@100ms","data":{"e":"depthUpdate","E":1626992767980,"T":1626992767965,"s":"CTKUSDT","U":600860315488,"u":600860320740,"pu":600860314255,"b":[["0.89700","1533"],["0.89800","167"],["1.00300","9254"],["1.00700","13637"],["1.00800","12583"],["1.00900","13824"],["1.01000","76733"],["1.01400","0"]],"a":[["1.01100","1150"],["1.01200","18830"],["1.01300","10780"],["1.01400","11904"],["1.01600","22436"],["1.01800","3324"],["1.01900","4816"],["1.12300","1298"],["1.12400","248"]]}}
1626992768.039399: {"stream":"sushiusdt@kline_1m","data":{"e":"kline","E":1626992767995,"s":"SUSHIUSDT","k":{"t":1626992760000,"T":1626992819999,"s":"SUSHIUSDT","i":"1m","f":126902987,"L":126903004,"o":"7.6180","c":"7.6110","h":"7.6200","l":"7.6110","v":"499","n":18,"x":false,"q":"3801.3140","V":"268","Q":"2041.8960","B":"0"}}}
1626992768.0395432: {"stream":"sushiusdt@bookTicker","data":{"e":"bookTicker","u":600860321986,"s":"SUSHIUSDT","b":"7.6110","B":"302","a":"7.6160","A":"344","T":1626992767991,"E":1626992767995}}
1626992768.057482: {"stream":"sushiusdt@bookTicker","data":{"e":"bookTicker","u":600860322689,"s":"SUSHIUSDT","b":"7.6110","B":"302","a":"7.6150","A":"3","T":1626992768005,"E":1626992768011}}
1626992768.073163: {"stream":"sushiusdt@bookTicker","data":{"e":"bookTicker","u":600860323582,"s":"SUSHIUSDT","b":"7.6110","B":"302","a":"7.6140","A":"60","T":1626992768021,"E":1626992768024}}
1626992768.083371: {"stream":"akrousdt@depth@100ms","data":{"e":"depthUpdate","E":1626992768038,"T":1626992768032,"s":"AKROUSDT","U":600860319163,"u":600860324295,"pu":600860316773,"b":[["0.01721","483392"],["0.01723","351243"],["0.01724","266777"],["0.01730","320385"]],"a":[["0.01737","700919"],["0.01738","608830"],["0.01741","1261020"],["0.01742","448744"],["0.01743","487535"]]}}
1626992768.086256: {"stream":"keepusdt@depth@100ms","data":{"e":"depthUpdate","E":1626992768040,"T":1626992768002,"s":"KEEPUSDT","U":600860319272,"u":600860322510,"pu":600860318236,"b":[["0.2434","18248"],["0.2444","3397"],["0.2463","249"]],"a":[["0.2467","0"],["0.2468","569"],["0.2469","1011"]]}}
1626992768.09048: {"stream":"keepusdt@bookTicker","data":{"e":"bookTicker","u":600860324761,"s":"KEEPUSDT","b":"0.2463","B":"249","a":"0.2468","A":"1381","T":1626992768042,"E":1626992768046}}
1626992768.10129: {"stream":"ctkusdt@aggTrade","data":{"e":"aggTrade","E":1626992768054,"a":16599326,"s":"CTKUSDT","p":"1.01100","q":"10","f":23961394,"l":23961394,"T":1626992767897,"m":false}}
1626992768.1062431: {"stream":"sushiusdt@depth@100ms","data":{"e":"depthUpdate","E":1626992768059,"T":1626992768050,"s":"SUSHIUSDT","U":600860320047,"u":600860325337,"pu":600860319283,"b":[["7.5470","2457"],["7.5810","452"],["7.5860","1447"],["7.5880","1386"],["7.5920","2030"],["7.5940","2402"],["7.5950","1149"],["7.5980","6392"],["7.6000","1172"],["7.6010","2701"],["7.6060","216"],["7.6090","165"],["7.6110","302"]],"a":[["7.6140","60"],["7.6150","19"],["7.6160","267"],["7.6170","425"],["7.6180","2699"],["7.6190","1499"],["7.6200","982"],["7.6210","1324"],["7.6230","1246"],["7.6250","1746"],["7.6260","2384"],["7.6300","2195"],["7.6310","3521"],["7.6320","1157"],["7.6330","954"],["7.6340","4910"],["7.6360","5007"],["7.6400","615"],["7.6410","1340"],["7.6430","2757"],["7.6440","867"],["7.6540","479"],["7.6560","1823"],["7.6610","1028"]]}}
1626992768.137651: {"stream":"keepusdt@aggTrade","data":{"e":"aggTrade","E":1626992768091,"a":1211541,"s":"KEEPUSDT","p":"0.2467","q":"146","f":2398365,"l":2398365,"T":1626992767937,"m":false}}
1626992768.166711: {"stream":"ctkusdt@depth@100ms","data":{"e":"depthUpdate","E":1626992768120,"T":1626992768104,"s":"CTKUSDT","U":600860323336,"u":600860326254,"pu":600860320740,"b":[["1.00900","13913"]],"a":[["1.01300","10933"],["1.01400","11896"],["1.01500","18909"],["1.01600","21546"]]}}
1626992768.1917021: {"stream":"keepusdt@depth@100ms","data":{"e":"depthUpdate","E":1626992768146,"T":1626992768125,"s":"KEEPUSDT","U":600860324761,"u":600860326631,"pu":600860322510,"b":[["0.2454","3997"],["0.2455","16786"]],"a":[["0.2468","1381"]]}}
1626992768.19185: {"stream":"sushiusdt@aggTrade","data":{"e":"aggTrade","E":1626992768146,"a":87353269,"s":"SUSHIUSDT","p":"7.6110","q":"1","f":126903004,"l":126903004,"T":1626992767990,"m":true}}
1626992768.213144: {"stream":"sushiusdt@depth@100ms","data":{"e":"depthUpdate","E":1626992768167,"T":1626992768163,"s":"SUSHIUSDT","U":600860325728,"u":600860328482,"pu":600860325337,"b":[["7.5790","712"],["7.5920","1855"],["7.5940","2433"],["7.5950","1302"],["7.5960","1133"],["7.5990","106"],["7.6000","1392"],["7.6030","2754"]],"a":[["7.6160","352"],["7.6170","1215"],["7.6190","709"],["7.6210","1521"],["7.6230","1903"],["7.6250","1772"],["7.6260","2358"],["7.6390","1376"],["7.6420","1318"],["7.6480","404"],["7.6490","8587"]]}}
1626992768.253144: {"stream":"sushiusdt@bookTicker","data":{"e":"bookTicker","u":600860331891,"s":"SUSHIUSDT","b":"7.6110","B":"97","a":"7.6140","A":"60","T":1626992768204,"E":1626992768206}}
1626992768.255733: {"stream":"akrousdt@depth@100ms","data":{"e":"depthUpdate","E":1626992768209,"T":1626992768194,"s":"AKROUSDT","U":600860326222,"u":600860331204,"pu":600860324295,"b":[["0.01721","474677"],["0.01724","255170"],["0.01726","286234"],["0.01727","803251"],["0.01729","410746"],["0.01731","163217"]],"a":[["0.01738","597316"],["0.01739","352395"],["0.01740","368668"],["0.01741","1298391"],["0.01743","473192"],["0.01745","230372"]]}}
1626992768.2975612: {"stream":"keepusdt@depth@100ms","data":{"e":"depthUpdate","E":1626992768253,"T":1626992768235,"s":"KEEPUSDT","U":600860327392,"u":600860333783,"pu":600860326631,"b":[["0.2442","10194"],["0.2446","9957"]],"a":[["0.2471","12500"],["0.2473","23857"],["0.2475","7147"],["0.2477","17359"],["0.2479","109030"],["0.2486","8898"]]}}
1626992768.3007329: {"stream":"ctkusdt@depth@100ms","data":{"e":"depthUpdate","E":1626992768255,"T":1626992768241,"s":"CTKUSDT","U":600860327529,"u":600860334110,"pu":600860326254,"b":[["1.00700","13279"],["1.00800","12941"]],"a":[["1.01300","11504"],["1.01400","13879"],["1.01500","16550"]]}}
1626992768.319385: {"stream":"sushiusdt@depth@100ms","data":{"e":"depthUpdate","E":1626992768273,"T":1626992768264,"s":"SUSHIUSDT","U":600860328871,"u":600860335097,"pu":600860328482,"b":[["7.5620","2535"],["7.5760","1809"],["7.5770","413"],["7.5860","1354"],["7.5900","1945"],["7.5940","2459"],["7.5980","6532"],["7.6010","2839"],["7.6020","1323"],["7.6040","1966"],["7.6090","194"],["7.6110","97"]],"a":[["7.6150","136"],["7.6160","274"],["7.6230","1773"],["7.6240","422"],["7.6280","2927"],["7.6300","2241"],["7.6310","3606"],["7.6330","1029"],["7.6390","1278"],["7.6410","2946"],["7.6450","1433"],["7.6470","2263"],["7.6590","244"],["7.7170","2996"],["7.7790","89"]]}}
1626992768.370532: {"stream":"akrousdt@bookTicker","data":{"e":"bookTicker","u":600860337876,"s":"AKROUSDT","b":"0.01734","B":"17480","a":"0.01735","A":"33258","T":1626992768320,"E":1626992768325}}
1626992768.387721: {"stream":"akrousdt@depth@100ms","data":{"e":"depthUpdate","E":1626992768342,"T":1626992768335,"s":"AKROUSDT","U":600860333987,"u":600860338661,"pu":600860331204,"b":[["0.01718","115692"],["0.01723","336684"],["0.01726","274639"],["0.01728","1178117"],["0.01731","133235"]],"a":[["0.01735","33258"],["0.01737","665086"],["0.01738","519299"],["0.01740","327339"],["0.01741","1298344"],["0.01743","481797"]]}}
1626992768.41965: {"stream":"sushiusdt@depth@100ms","data":{"e":"depthUpdate","E":1626992768375,"T":1626992768360,"s":"SUSHIUSDT","U":600860335263,"u":600860339987,"pu":600860335097,"b":[["7.5340","9978"],["7.5380","613"],["7.5870","1258"],["7.6000","1716"],["7.6020","1349"]],"a":[["7.6160","425"],["7.6180","2704"],["7.6200","812"],["7.6220","539"],["7.6240","1403"],["7.6250","2101"],["7.6280","1946"],["7.6300","1912"],["7.7040","1101"],["7.7060","508"]]}}
1626992768.42139: {"stream":"keepusdt@depth@100ms","data":{"e":"depthUpdate","E":1626992768376,"T":1626992768361,"s":"KEEPUSDT","U":600860335316,"u":600860340046,"pu":600860333783,"b":[["0.2448","10514"],["0.2449","16710"],["0.2455","17464"],["0.2456","11686"],["0.2457","5820"],["0.2459","5103"]],"a":[["0.2470","1564"],["0.2471","14196"],["0.2472","5155"],["0.2476","20105"],["0.2478","14000"],["0.2482","4712"],["0.2484","1265"]]}}
1626992768.428115: {"stream":"keepusdt@bookTicker","data":{"e":"bookTicker","u":600860340929,"s":"KEEPUSDT","b":"0.2463","B":"249","a":"0.2467","A":"6793","T":1626992768377,"E":1626992768381}}
1626992768.428567: {"stream":"keepusdt@bookTicker","data":{"e":"bookTicker","u":600860341008,"s":"KEEPUSDT","b":"0.2463","B":"249","a":"0.2467","A":"8491","T":1626992768378,"E":1626992768383}}
1626992768.434175: {"stream":"ctkusdt@depth@100ms","data":{"e":"depthUpdate","E":1626992768390,"T":1626992768363,"s":"CTKUSDT","U":600860336030,"u":600860340213,"pu":600860334110,"b":[["0.98600","4971"],["1.00200","21325"]],"a":[]}}
1626992768.4590452: {"stream":"sushiusdt@bookTicker","data":{"e":"bookTicker","u":600860342648,"s":"SUSHIUSDT","b":"7.6110","B":"66","a":"7.6140","A":"60","T":1626992768408,"E":1626992768413}}
1626992768.459141: {"stream":"keepusdt@bookTicker","data":{"e":"bookTicker","u":600860342675,"s":"KEEPUSDT","b":"0.2463","B":"249","a":"0.2467","A":"9047","T":1626992768410,"E":1626992768413}}
1626992768.4871628: {"stream":"akrousdt@depth@100ms","data":{"e":"depthUpdate","E":1626992768443,"T":1626992768400,"s":"AKROUSDT","U":600860338865,"u":600860342184,"pu":600860338661,"b":[["0.01717","276613"],["0.01719","157969"],["0.01727","855530"],["0.01728","1126152"]],"a":[["0.01737","734491"],["0.01738","658229"],["0.01739","213463"],["0.01741","1312074"],["0.01742","434902"]]}}
1626992768.5251231: {"stream":"sushiusdt@depth@100ms","data":{"e":"depthUpdate","E":1626992768478,"T":1626992768463,"s":"SUSHIUSDT","U":600860340705,"u":600860345760,"pu":600860339987,"b":[["7.5890","1120"],["7.5930","3378"],["7.5950","1144"],["7.6050","1300"],["7.6060","248"],["7.6070","1364"],["7.6100","131"],["7.6110","66"]],"a":[["7.6160","457"],["7.6170","1279"],["7.6200","780"],["7.6210","1781"],["7.6230","1449"],["7.6240","2060"],["7.6380","790"],["7.6390","1436"],["7.6410","2790"],["7.6460","290"],["7.6800","3847"],["8.4180","164"],["8.9200","6507"]]}}
1626992768.525849: {"stream":"keepusdt@depth@100ms","data":{"e":"depthUpdate","E":1626992768481,"T":1626992768455,"s":"KEEPUSDT","U":600860340929,"u":600860345363,"pu":600860340046,"b":[],"a":[["0.2467","9047"],["0.2468","664"],["0.2469","1417"]]}}
1626992768.545244: {"stream":"ctkusdt@depth@100ms","data":{"e":"depthUpdate","E":1626992768500,"T":1626992768458,"s":"CTKUSDT","U":600860342036,"u":600860345554,"pu":600860340213,"b":[["0.98800","19716"]],"a":[["1.01200","19550"],["1.01800","3046"],["1.29300","25"]]}}
1626992768.59307: {"stream":"akrousdt@depth@100ms","data":{"e":"depthUpdate","E":1626992768548,"T":1626992768519,"s":"AKROUSDT","U":600860344612,"u":600860348239,"pu":600860342184,"b":[["0.01718","202130"],["0.01724","230956"]],"a":[]}}
1626992768.620726: {"stream":"sushiusdt@bookTicker","data":{"e":"bookTicker","u":600860350311,"s":"SUSHIUSDT","b":"7.6120","B":"24","a":"7.6140","A":"60","T":1626992768566,"E":1626992768576}}
1626992768.6408288: {"stream":"sushiusdt@depth@100ms","data":{"e":"depthUpdate","E":1626992768595,"T":1626992768589,"s":"SUSHIUSDT","U":600860346954,"u":600860351174,"pu":600860345760,"b":[["7.5820","906"],["7.5850","1200"],["7.5970","1430"],["7.5980","6668"],["7.5990","431"],["7.6020","1679"],["7.6030","3475"],["7.6040","1098"],["7.6050","2168"],["7.6120","24"]],"a":[["7.6180","1178"],["7.6240","2375"],["7.6260","2043"],["7.6280","2134"],["7.6330","954"],["7.6370","2066"],["7.6380","743"],["7.6520","3640"],["7.6590","190"]]}}
1626992768.653742: {"stream":"akrousdt@bookTicker","data":{"e":"bookTicker","u":600860351613,"s":"AKROUSDT","b":"0.01734","B":"17480","a":"0.01735","A":"50697","T":1626992768601,"E":1626992768607}}
1626992768.654196: {"stream":"ctkusdt@depth@100ms","data":{"e":"depthUpdate","E":1626992768610,"T":1626992768578,"s":"CTKUSDT","U":600860347473,"u":600860350695,"pu":600860345554,"b":[["1.00200","21335"],["1.00900","13870"]],"a":[["1.01400","13468"]]}}
1626992768.670895: {"stream":"sushiusdt@bookTicker","data":{"e":"bookTicker","u":600860352277,"s":"SUSHIUSDT","b":"7.6120","B":"25","a":"7.6140","A":"60","T":1626992768619,"E":1626992768625}}
1626992768.6709929: {"stream":"sushiusdt@bookTicker","data":{"e":"bookTicker","u":600860352283,"s":"SUSHIUSDT","b":"7.6120","B":"30","a":"7.6140","A":"60","T":1626992768619,"E":1626992768625}}
1626992768.694369: {"stream":"akrousdt@depth@100ms","data":{"e":"depthUpdate","E":1626992768649,"T":1626992768643,"s":"AKROUSDT","U":600860349343,"u":600860353148,"pu":600860348239,"b":[["0.01726","355530"],["0.01727","776631"],["0.01729","288317"],["0.01730","486620"],["0.01731","119297"]],"a":[["0.01735","50697"],["0.01736","284089"],["0.01737","748523"],["0.01738","644402"],["0.01739","243307"],["0.01740","374794"]]}}
1626992768.725599: {"stream":"sushiusdt@bookTicker","data":{"e":"bookTicker","u":600860354468,"s":"SUSHIUSDT","b":"7.6120","B":"6","a":"7.6140","A":"60","T":1626992768673,"E":1626992768679}}
1626992768.731426: {"stream":"keepusdt@depth@100ms","data":{"e":"depthUpdate","E":1626992768686,"T":1626992768659,"s":"KEEPUSDT","U":600860350783,"u":600860353851,"pu":600860345363,"b":[["0.2438","22614"],["0.2439","18476"],["0.2440","3174"],["0.2450","101579"],["0.2452","4498"],["0.2456","12700"]],"a":[["0.2468","406"],["0.2469","922"],["0.2474","6980"],["0.2475","4469"],["0.2477","20034"],["0.2481","8310"]]}}
1626992768.7477372: {"stream":"sushiusdt@depth@100ms","data":{"e":"depthUpdate","E":1626992768701,"T":1626992768695,"s":"SUSHIUSDT","U":600860351372,"u":600860355506,"pu":600860351174,"b":[["3.8070","26"],["7.5580","832"],["7.5660","186"],["7.5740","771"],["7.5790","1180"],["7.5840","4406"],["7.5860","1236"],["7.5920","1960"],["7.5950","1039"],["7.5970","1188"],["7.6030","1571"],["7.6040","2806"],["7.6070","1554"],["7.6080","936"],["7.6090","201"],["7.6110","47"],["7.6120","6"]],"a":[["7.6150","117"],["7.6160","469"],["7.6170","499"],["7.6180","1048"],["7.6190","1547"],["7.6200","1615"],["7.6210","1472"],["7.6230","1765"],["7.6240","2279"],["7.6280","2331"],["7.6320","903"],["7.6440","896"],["7.6470","2707"],["7.6560","1763"],["7.6590","250"]]}}
1626992768.79439: {"stream":"akrousdt@depth@100ms","data":{"e":"depthUpdate","E":1626992768750,"T":1626992768742,"s":"AKROUSDT","U":600860353216,"u":600860357955,"pu":600860353148,"b":[["0.01718","242822"],["0.01726","343935"],["0.01727","788218"],["0.01728","1136152"]],"a":[["0.01736","319943"],["0.01737","786685"],["0.01738","606276"],["0.01739","210537"],["0.01740","363292"],["0.01741","1287607"],["0.01742","422498"]]}}
1626992768.842206: {"stream":"keepusdt@depth@100ms","data":{"e":"depthUpdate","E":1626992768798,"T":1626992768723,"s":"KEEPUSDT","U":600860355267,"u":600860356875,"pu":600860353851,"b":[["0.2435","34142"],["0.2444","6260"]],"a":[]}}
1626992768.8487208: {"stream":"sushiusdt@depth@100ms","data":{"e":"depthUpdate","E":1626992768803,"T":1626992768792,"s":"SUSHIUSDT","U":600860355688,"u":600860360001,"pu":600860355506,"b":[["7.5830","5561"],["7.6030","3098"],["7.6040","1098"],["7.6080","1081"]],"a":[["7.6190","1744"],["7.6200","2273"],["7.6210","1622"],["7.6220","877"],["7.6230","2140"],["7.6250","2298"],["7.6260","1426"],["7.6270","1143"],["7.6330","975"],["7.6350","1818"],["7.6520","3632"],["7.6530","732"],["7.6580","312"],["8.7480","0"]]}}
1626992768.865817: {"stream":"ctkusdt@depth@100ms","data":{"e":"depthUpdate","E":1626992768822,"T":1626992768748,"s":"CTKUSDT","U":600860356573,"u":600860358152,"pu":600860350695,"b":[["0.98600","5052"],["0.99600","2844"]],"a":[]}}
1626992768.904444: {"stream":"akrousdt@depth@100ms","data":{"e":"depthUpdate","E":1626992768850,"T":1626992768837,"s":"AKROUSDT","U":600860358045,"u":600860361679,"pu":600860357955,"b":[["0.01727","741078"]],"a":[["0.01737","713175"],["0.01738","644402"],["0.01739","230761"],["0.01741","1276113"]]}}
1626992768.952119: {"stream":"sushiusdt@depth@100ms","data":{"e":"depthUpdate","E":1626992768906,"T":1626992768896,"s":"SUSHIUSDT","U":600860360312,"u":600860363418,"pu":600860360001,"b":[["7.5930","2750"],["7.6030","2377"],["7.6050","2889"],["7.6080","1244"],["7.6090","194"]],"a":[["7.6180","1838"],["7.6190","2402"],["7.6200","825"],["7.6220","1199"],["7.6300","1987"],["7.6470","2715"],["7.6560","1817"],["8.7480","1620"]]}}
1626992768.952704: {"stream":"keepusdt@depth@100ms","data":{"e":"depthUpdate","E":1626992768907,"T":1626992768902,"s":"KEEPUSDT","U":600860360365,"u":600860363540,"pu":600860356875,"b":[["0.2421","18005"],["0.2425","33309"]],"a":[["0.2470","2251"],["0.2471","13509"],["0.2509","16904"],["0.2511","5306"]]}}
1626992768.9737349: {"stream":"ctkusdt@depth@100ms","data":{"e":"depthUpdate","E":1626992768928,"T":1626992768906,"s":"CTKUSDT","U":600860361199,"u":600860363641,"pu":600860358152,"b":[["1.00800","12743"]],"a":[["1.01300","11916"]]}}
1626992769.015143: {"stream":"akrousdt@depth@100ms","data":{"e":"depthUpdate","E":1626992768969,"T":1626992768959,"s":"AKROUSDT","U":600860362536,"u":600860365262,"pu":600860361679,"b":[],"a":[["0.01736","284089"],["0.01737","771502"],["0.01738","630304"],["0.01739","301255"]]}}
1626992769.056202: {"stream":"sushiusdt@depth@100ms","data":{"e":"depthUpdate","E":1626992769011,"T":1626992769005,"s":"SUSHIUSDT","U":600860363655,"u":600860366660,"pu":600860363418,"b":[["7.5930","2817"],["7.5950","972"],["7.6050","2168"],["7.6090","201"]],"a":[["7.6180","1853"],["7.6200","810"],["7.6240","3391"],["7.6250","1312"],["7.6290","3369"],["7.6440","2366"],["7.6490","10087"],["7.6560","347"]]}}
1626992769.075787: {"stream":"keepusdt@depth@100ms","data":{"e":"depthUpdate","E":1626992769031,"T":1626992769006,"s":"KEEPUSDT","U":600860364151,"u":600860366680,"pu":600860363540,"b":[["0.2438","23433"],["0.2443","5812"],["0.2452","6194"],["0.2453","4439"]],"a":[["0.2468","406"],["0.2469","1600"],["0.2470","1573"],["0.2472","6874"],["0.2473","22138"],["0.2475","7147"],["0.2477","17359"],["0.2494","13015"],["0.2496","2392"]]}}
1626992769.119412: {"stream":"ctkusdt@depth@100ms","data":{"e":"depthUpdate","E":1626992769074,"T":1626992769058,"s":"CTKUSDT","U":600860365590,"u":600860368496,"pu":600860363641,"b":[["0.98600","5077"],["1.00100","76591"]],"a":[["1.01200","19802"],["1.01400","13476"],["1.01500","16542"]]}}
1626992769.122612: {"stream":"akrousdt@depth@100ms","data":{"e":"depthUpdate","E":1626992769076,"T":1626992769066,"s":"AKROUSDT","U":600860365707,"u":600860368692,"pu":600860365262,"b":[["0.01731","170319"],["0.01732","786267"]],"a":[["0.01738","644688"]]}}
1626992769.131192: {"stream":"ctkusdt@bookTicker","data":{"e":"bookTicker","u":600860369125,"s":"CTKUSDT","b":"1.01000","B":"76733","a":"1.01100","A":"1140","T":1626992769081,"E":1626992769084}}
1626992769.131291: {"stream":"ctkusdt@kline_1m","data":{"e":"kline","E":1626992769085,"s":"CTKUSDT","k":{"t":1626992760000,"T":1626992819999,"s":"CTKUSDT","i":"1m","f":23961361,"L":23961395,"o":"1.01200","c":"1.01100","h":"1.01200","l":"1.01000","v":"9726","n":35,"x":false,"q":"9832.97400","V":"80","Q":"80.94000","B":"0"}}}
1626992769.144825: {"stream":"ctkusdt@bookTicker","data":{"e":"bookTicker","u":600860369315,"s":"CTKUSDT","b":"1.01000","B":"76733","a":"1.01100","A":"80","T":1626992769096,"E":1626992769100}}
1626992769.166734: {"stream":"sushiusdt@depth@100ms","data":{"e":"depthUpdate","E":1626992769123,"T":1626992769084,"s":"SUSHIUSDT","U":600860367063,"u":600860369161,"pu":600860366660,"b":[["7.5760","3309"],["7.5980","6694"],["7.6000","1690"],["7.6010","2909"],["7.6020","1609"]],"a":[["7.6330","1022"],["7.6360","4366"],["7.7750","71"]]}}
1626992769.218112: {"stream":"keepusdt@depth@100ms","data":{"e":"depthUpdate","E":1626992769172,"T":1626992769165,"s":"KEEPUSDT","U":600860368719,"u":600860370848,"pu":600860366680,"b":[["0.2444","4789"],["0.2450","103034"]],"a":[["0.2469","1939"]]}}
1626992769.2308: {"stream":"ctkusdt@depth@100ms","data":{"e":"depthUpdate","E":1626992769184,"T":1626992769171,"s":"CTKUSDT","U":600860369121,"u":600860371121,"pu":600860368496,"b":[["1.00800","12941"],["1.01400","0"]],"a":[["1.01100","80"],["1.01200","21384"]]}}
1626992769.2557068: {"stream":"akrousdt@depth@100ms","data":{"e":"depthUpdate","E":1626992769210,"T":1626992769180,"s":"AKROUSDT","U":600860369378,"u":600860371747,"pu":600860368692,"b":[["0.01726","355530"],["0.01730","539620"]],"a":[["0.01736","319457"],["0.01738","677477"],["0.01740","374794"]]}}
1626992769.2828338: {"stream":"ctkusdt@aggTrade","data":{"e":"aggTrade","E":1626992769235,"a":16599327,"s":"CTKUSDT","p":"1.01100","q":"10","f":23961395,"l":23961395,"T":1626992769081,"m":false}}
1626992769.282934: {"stream":"sushiusdt@depth@100ms","data":{"e":"depthUpdate","E":1626992769236,"T":1626992769229,"s":"SUSHIUSDT","U":600860369872,"u":600860373776,"pu":600860369161,"b":[["7.5940","2668"],["7.5960","1108"],["7.6070","1544"],["7.6090","279"]],"a":[["7.6210","1872"],["7.6230","1890"],["7.6240","3705"],["7.6270","1143"],["7.6300","1673"],["7.6540","455"]]}}
1626992769.329073: {"stream":"keepusdt@depth@100ms","data":{"e":"depthUpdate","E":1626992769284,"T":1626992769245,"s":"KEEPUSDT","U":600860371895,"u":600860374262,"pu":600860370848,"b":[["0.2457","7715"]],"a":[["0.2468","406"],["0.2469","1533"],["0.2470","1979"]]}}
