wss://stream.binance.us:9443/stream?streams=omgusd@depth@100ms/atomusdt@depth@100ms/bchusdt@depth@100ms/busdusd@depth@100ms/zrxusd@depth@100ms/ethbusd@depth@100ms/usdtusd@depth@100ms/zenusd@depth@100ms/btcusdt@depth@100ms/xlmusdt@depth@100ms/omgusd@aggTrade/atomusdt@aggTrade/bchusdt@aggTrade/busdusd@aggTrade/zrxusd@aggTrade/ethbusd@aggTrade/usdtusd@aggTrade/zenusd@aggTrade/btcusdt@aggTrade/xlmusdt@aggTrade/omgusd@bookTicker/atomusdt@bookTicker/bchusdt@bookTicker/busdusd@bookTicker/zrxusd@bookTicker/ethbusd@bookTicker/usdtusd@bookTicker/zenusd@bookTicker/btcusdt@bookTicker/xlmusdt@bookTicker <-> 1618677408.2868
1618677408.499744: {"stream":"bchusdt@depth@100ms","data":{"e":"depthUpdate","E":1618677408520,"s":"BCHUSDT","U":123517964,"u":123517964,"b":[["990.79000000","0.02524000"]],"a":[]}}
1618677408.697398: {"stream":"xlmusdt@depth@100ms","data":{"e":"depthUpdate","E":1618677408719,"s":"XLMUSDT","U":134557740,"u":134557740,"b":[["0.57499000","43.50000000"]],"a":[]}}
1618677408.735046: {"stream":"btcusdt@depth@100ms","data":{"e":"depthUpdate","E":1618677408719,"s":"BTCUSDT","U":372026684,"u":372026685,"b":[["60330.82000000","0.12512800"],["60276.25000000","0.01212200"]],"a":[]}}
1618677408.781831: {"stream":"bchusdt@depth@100ms","data":{"e":"depthUpdate","E":1618677408719,"s":"BCHUSDT","U":123517965,"u":123517966,"b":[["1045.68000000","0.67407000"]],"a":[["1055.33000000","4.68630000"]]}}
1618677408.9001658: {"stream":"btcusdt@depth@100ms","data":{"e":"depthUpdate","E":1618677408921,"s":"BTCUSDT","U":372026686,"u":372026687,"b":[],"a":[["60511.37000000","0.00904000"],["60561.32000000","0.00000000"]]}}
1618677408.9990559: {"stream":"bchusdt@depth@100ms","data":{"e":"depthUpdate","E":1618677409019,"s":"BCHUSDT","U":123517967,"u":123517967,"b":[],"a":[["1058.76000000","0.00000000"]]}}
1618677409.096801: {"stream":"bchusdt@depth@100ms","data":{"e":"depthUpdate","E":1618677409119,"s":"BCHUSDT","U":123517968,"u":123517970,"b":[],"a":[["1052.29000000","0.00000000"],["1053.25000000","0.95042000"],["1105.99000000","11.11568000"]]}}
1618677409.099061: {"stream":"btcusdt@depth@100ms","data":{"e":"depthUpdate","E":1618677409119,"s":"BTCUSDT","U":372026688,"u":372026688,"b":[["60330.82000000","0.00000000"]],"a":[]}}
1618677409.1241338: {"stream":"omgusd@bookTicker","data":{"u":66532560,"s":"OMGUSD","b":"9.5356","B":"94.04000000","a":"9.5584","A":"259.47000000"}}
1618677409.182063: {"stream":"bchusdt@bookTicker","data":{"u":123517978,"s":"BCHUSDT","b":"1049.99000000","B":"0.72672000","a":"1051.65000000","A":"0.42203000"}}
1618677409.197967: {"stream":"btcusdt@depth@100ms","data":{"e":"depthUpdate","E":1618677409219,"s":"BTCUSDT","U":372026689,"u":372026690,"b":[["60423.73000000","0.00000000"]],"a":[["60490.44000000","0.00000000"]]}}
1618677409.198158: {"stream":"bchusdt@depth@100ms","data":{"e":"depthUpdate","E":1618677409219,"s":"BCHUSDT","U":123517971,"u":123517978,"b":[["1049.99000000","0.72672000"],["1023.48000000","0.00000000"]],"a":[["1051.66000000","0.00000000"],["1129.40000000","0.00000000"],["1130.56000000","0.00000000"],["1131.98000000","0.00000000"],["1134.85000000","0.00000000"],["1136.21000000","0.00000000"]]}}
1618677409.198325: {"stream":"omgusd@depth@100ms","data":{"e":"depthUpdate","E":1618677409219,"s":"OMGUSD","U":66532560,"u":66532560,"b":[],"a":[["9.5584","259.47000000"]]}}
1618677409.236802: {"stream":"bchusdt@bookTicker","data":{"u":123517979,"s":"BCHUSDT","b":"1049.99000000","B":"0.72672000","a":"1052.15000000","A":"0.91759000"}}
1618677409.2994518: {"stream":"xlmusdt@depth@100ms","data":{"e":"depthUpdate","E":1618677409321,"s":"XLMUSDT","U":134557741,"u":134557741,"b":[["0.59989000","0.00000000"]],"a":[]}}
1618677409.299606: {"stream":"btcusdt@depth@100ms","data":{"e":"depthUpdate","E":1618677409321,"s":"BTCUSDT","U":372026691,"u":372026692,"b":[["60428.52000000","0.08000000"]],"a":[["60496.82000000","0.08000000"]]}}
1618677409.299705: {"stream":"bchusdt@depth@100ms","data":{"e":"depthUpdate","E":1618677409321,"s":"BCHUSDT","U":123517979,"u":123517980,"b":[],"a":[["1051.65000000","0.00000000"],["1052.59000000","0.40940000"]]}}
1618677409.362297: {"stream":"bchusdt@bookTicker","data":{"u":123517983,"s":"BCHUSDT","b":"1049.99000000","B":"0.72672000","a":"1052.16000000","A":"25.30878000"}}
1618677409.3996842: {"stream":"bchusdt@depth@100ms","data":{"e":"depthUpdate","E":1618677409419,"s":"BCHUSDT","U":123517981,"u":123517983,"b":[],"a":[["1052.15000000","0.00000000"],["1052.59000000","0.00000000"],["1053.24000000","0.40940000"]]}}
1618677409.49917: {"stream":"bchusdt@depth@100ms","data":{"e":"depthUpdate","E":1618677409520,"s":"BCHUSDT","U":123517984,"u":123517985,"b":[],"a":[["1052.59000000","0.40940000"],["1053.24000000","0.00000000"]]}}
1618677409.530423: {"stream":"bchusdt@bookTicker","data":{"u":123517986,"s":"BCHUSDT","b":"1049.99000000","B":"0.72672000","a":"1052.59000000","A":"0.40940000"}}
1618677409.601045: {"stream":"xlmusdt@depth@100ms","data":{"e":"depthUpdate","E":1618677409620,"s":"XLMUSDT","U":134557742,"u":134557744,"b":[["0.59989000","404.60000000"]],"a":[["0.60134000","0.00000000"],["0.60162000","3324.10000000"]]}}
1618677409.601239: {"stream":"bchusdt@depth@100ms","data":{"e":"depthUpdate","E":1618677409619,"s":"BCHUSDT","U":123517986,"u":123517986,"b":[],"a":[["1052.16000000","0.00000000"]]}}
1618677409.605571: {"stream":"bchusdt@bookTicker","data":{"u":123517987,"s":"BCHUSDT","b":"1049.99000000","B":"0.72672000","a":"1052.60000000","A":"0.86131000"}}
1618677409.649892: {"stream":"bchusdt@bookTicker","data":{"u":123517990,"s":"BCHUSDT","b":"1050.06000000","B":"0.95011000","a":"1052.60000000","A":"0.86131000"}}
1618677409.692658: {"stream":"xlmusdt@bookTicker","data":{"u":134557746,"s":"XLMUSDT","b":"0.60044000","B":"499.60000000","a":"0.60145000","A":"1925.20000000"}}
1618677409.699106: {"stream":"xlmusdt@depth@100ms","data":{"e":"depthUpdate","E":1618677409721,"s":"XLMUSDT","U":134557745,"u":134557747,"b":[["0.59989000","0.00000000"]],"a":[["0.60132000","0.00000000"],["0.64538000","26577.70000000"]]}}
1618677409.6992378: {"stream":"btcusdt@depth@100ms","data":{"e":"depthUpdate","E":1618677409721,"s":"BTCUSDT","U":372026693,"u":372026694,"b":[["60254.16000000","0.00000000"]],"a":[["60479.48000000","0.00000000"]]}}
1618677409.6992981: {"stream":"bchusdt@depth@100ms","data":{"e":"depthUpdate","E":1618677409721,"s":"BCHUSDT","U":123517987,"u":123517990,"b":[["1050.06000000","0.95011000"],["1049.15000000","0.00000000"]],"a":[["1052.59000000","0.00000000"],["1053.24000000","0.42169000"]]}}
1618677409.717985: {"stream":"btcusdt@bookTicker","data":{"u":372026697,"s":"BTCUSDT","b":"60457.34000000","B":"0.09916400","a":"60464.64000000","A":"0.02512800"}}
1618677409.7672582: {"stream":"btcusdt@bookTicker","data":{"u":372026699,"s":"BTCUSDT","b":"60457.34000000","B":"0.09916400","a":"60472.05000000","A":"0.00676700"}}
1618677409.770988: {"stream":"btcusdt@bookTicker","data":{"u":372026701,"s":"BTCUSDT","b":"60464.63000000","B":"0.02280400","a":"60472.05000000","A":"0.00676700"}}
1618677409.798316: {"stream":"btcusdt@depth@100ms","data":{"e":"depthUpdate","E":1618677409820,"s":"BTCUSDT","U":372026695,"u":372026703,"b":[["60464.63000000","0.02280400"],["60457.34000000","0.09916400"],["60451.66000000","0.00000000"]],"a":[["60464.64000000","0.00000000"],["60472.06000000","0.00000000"],["60490.46000000","0.00000000"],["60508.52000000","0.13221900"],["60733.48000000","0.33252600"],["60746.43000000","0.40686300"]]}}
1618677409.805426: {"stream":"btcusdt@bookTicker","data":{"u":372026705,"s":"BTCUSDT","b":"60464.63000000","B":"0.02280400","a":"60478.20000000","A":"0.03350600"}}
1618677409.8055098: {"stream":"btcusdt@bookTicker","data":{"u":372026706,"s":"BTCUSDT","b":"60464.64000000","B":"0.00670200","a":"60478.20000000","A":"0.03350600"}}
1618677409.829676: {"stream":"ethbusd@bookTicker","data":{"u":56401136,"s":"ETHBUSD","b":"2358.69000000","B":"0.11907000","a":"2363.54000000","A":"0.14071000"}}
1618677409.89844: {"stream":"xlmusdt@depth@100ms","data":{"e":"depthUpdate","E":1618677409920,"s":"XLMUSDT","U":134557748,"u":134557752,"b":[["0.60026000","3323.30000000"],["0.59994000","0.00000000"],["0.59990000","404.60000000"]],"a":[["0.60146000","0.00000000"],["0.60176000","3323.30000000"]]}}
1618677409.898654: {"stream":"btcusdt@depth@100ms","data":{"e":"depthUpdate","E":1618677409920,"s":"BTCUSDT","U":372026704,"u":372026707,"b":[["60464.64000000","0.00670200"],["60454.20000000","0.00000000"]],"a":[["60472.05000000","0.00000000"],["60479.58000000","0.00670200"]]}}
1618677409.898775: {"stream":"ethbusd@depth@100ms","data":{"e":"depthUpdate","E":1618677409920,"s":"ETHBUSD","U":56401136,"u":56401136,"b":[["2358.69000000","0.11907000"]],"a":[]}}
1618677409.962904: {"stream":"xlmusdt@bookTicker","data":{"u":134557753,"s":"XLMUSDT","b":"0.60044000","B":"499.60000000","a":"0.60162000","A":"3324.10000000"}}
1618677410.002133: {"stream":"xlmusdt@depth@100ms","data":{"e":"depthUpdate","E":1618677410021,"s":"XLMUSDT","U":134557753,"u":134557753,"b":[],"a":[["0.60145000","0.00000000"]]}}
1618677410.002283: {"stream":"btcusdt@depth@100ms","data":{"e":"depthUpdate","E":1618677410021,"s":"BTCUSDT","U":372026708,"u":372026712,"b":[["60454.19000000","0.00000000"],["60384.37000000","0.00000000"]],"a":[["60479.58000000","0.00000000"],["60479.59000000","0.00000000"],["60484.78000000","0.00670200"]]}}
1618677410.002444: {"stream":"ethbusd@depth@100ms","data":{"e":"depthUpdate","E":1618677410021,"s":"ETHBUSD","U":56401137,"u":56401138,"b":[["2357.62000000","0.00000000"]],"a":[["2423.35000000","0.00000000"]]}}
1618677410.09895: {"stream":"ethbusd@depth@100ms","data":{"e":"depthUpdate","E":1618677410120,"s":"ETHBUSD","U":56401139,"u":56401142,"b":[["2358.68000000","1.34695000"],["2354.02000000","0.05400000"],["2351.94000000","0.00000000"]],"a":[["2364.05000000","0.00000000"]]}}
1618677410.0991502: {"stream":"xlmusdt@depth@100ms","data":{"e":"depthUpdate","E":1618677410120,"s":"XLMUSDT","U":134557754,"u":134557754,"b":[["0.59990000","0.00000000"]],"a":[]}}
1618677410.0992482: {"stream":"btcusdt@depth@100ms","data":{"e":"depthUpdate","E":1618677410120,"s":"BTCUSDT","U":372026713,"u":372026717,"b":[["60456.31000000","0.00000000"],["60392.10000000","0.01000000"]],"a":[["60481.70000000","0.00000000"]]}}
1618677410.168457: {"stream":"xlmusdt@bookTicker","data":{"u":134557755,"s":"XLMUSDT","b":"0.60044000","B":"499.60000000","a":"0.60170000","A":"3570.60000000"}}
1618677410.1987011: {"stream":"zrxusd@depth@100ms","data":{"e":"depthUpdate","E":1618677410220,"s":"ZRXUSD","U":51775863,"u":51775863,"b":[],"a":[["2.0922","1245.12000000"]]}}
1618677410.262516: {"stream":"ethbusd@depth@100ms","data":{"e":"depthUpdate","E":1618677410220,"s":"ETHBUSD","U":56401143,"u":56401144,"b":[["2358.10000000","0.00000000"],["2356.36000000","1.36984000"]],"a":[]}}
1618677410.262581: {"stream":"omgusd@depth@100ms","data":{"e":"depthUpdate","E":1618677410220,"s":"OMGUSD","U":66532561,"u":66532562,"b":[],"a":[["9.5665","803.50000000"],["9.5804","0.00000000"]]}}
1618677410.262624: {"stream":"xlmusdt@depth@100ms","data":{"e":"depthUpdate","E":1618677410220,"s":"XLMUSDT","U":134557755,"u":134557755,"b":[],"a":[["0.60162000","0.00000000"]]}}
1618677410.262657: {"stream":"btcusdt@depth@100ms","data":{"e":"depthUpdate","E":1618677410220,"s":"BTCUSDT","U":372026718,"u":372026722,"b":[["60464.27000000","0.00000000"]],"a":[["60489.67000000","0.00000000"],["60496.82000000","0.00000000"]]}}
1618677410.2626932: {"stream":"btcusdt@bookTicker","data":{"u":372026725,"s":"BTCUSDT","b":"60465.78000000","B":"0.08026000","a":"60478.20000000","A":"0.03350600"}}
1618677410.26271: {"stream":"ethbusd@bookTicker","data":{"u":56401145,"s":"ETHBUSD","b":"2359.32000000","B":"0.84673000","a":"2363.54000000","A":"0.14071000"}}
1618677410.299105: {"stream":"xlmusdt@depth@100ms","data":{"e":"depthUpdate","E":1618677410320,"s":"XLMUSDT","U":134557756,"u":134557756,"b":[],"a":[["0.60189000","5581.20000000"]]}}
1618677410.299236: {"stream":"btcusdt@depth@100ms","data":{"e":"depthUpdate","E":1618677410320,"s":"BTCUSDT","U":372026723,"u":372026728,"b":[["60465.78000000","0.08026000"],["60457.34000000","0.00000000"],["60428.52000000","0.00000000"],["60428.46000000","0.00000000"]],"a":[["60491.18000000","0.07971000"],["60506.07000000","0.08000000"]]}}
1618677410.299387: {"stream":"zrxusd@depth@100ms","data":{"e":"depthUpdate","E":1618677410320,"s":"ZRXUSD","U":51775864,"u":51775865,"b":[["2.0793","495.00000000"],["2.0775","0.00000000"]],"a":[]}}
1618677410.299446: {"stream":"ethbusd@depth@100ms","data":{"e":"depthUpdate","E":1618677410320,"s":"ETHBUSD","U":56401145,"u":56401146,"b":[["2359.32000000","0.84673000"]],"a":[["2365.14000000","0.84689000"]]}}
1618677410.308347: {"stream":"btcusdt@bookTicker","data":{"u":372026730,"s":"BTCUSDT","b":"60465.79000000","B":"0.00670200","a":"60478.20000000","A":"0.03350600"}}
1618677410.327499: {"stream":"atomusdt@bookTicker","data":{"u":71292117,"s":"ATOMUSDT","b":"25.13400000","B":"39.70600000","a":"25.19200000","A":"39.68700000"}}
1618677410.3984761: {"stream":"atomusdt@depth@100ms","data":{"e":"depthUpdate","E":1618677410420,"s":"ATOMUSDT","U":71292116,"u":71292117,"b":[],"a":[["25.17700000","0.00000000"],["27.95100000","637.68500000"]]}}
1618677410.439168: {"stream":"btcusdt@depth@100ms","data":{"e":"depthUpdate","E":1618677410420,"s":"BTCUSDT","U":372026729,"u":372026734,"b":[["60465.79000000","0.00670200"],["60464.64000000","0.00000000"],["60463.34000000","0.09915500"],["60453.16000000","0.13220600"]],"a":[["60491.50000000","0.09915500"],["60511.36000000","0.02098500"]]}}
1618677410.43926: {"stream":"ethbusd@depth@100ms","data":{"e":"depthUpdate","E":1618677410420,"s":"ETHBUSD","U":56401147,"u":56401147,"b":[],"a":[["2364.65000000","0.00000000"]]}}
1618677410.4956238: {"stream":"zrxusd@bookTicker","data":{"u":51775869,"s":"ZRXUSD","b":"2.0821","B":"719.72000000","a":"2.0880","A":"274.77000000"}}
1618677410.500018: {"stream":"ethbusd@depth@100ms","data":{"e":"depthUpdate","E":1618677410520,"s":"ETHBUSD","U":56401148,"u":56401149,"b":[["2356.71000000","0.00000000"],["2356.36000000","0.00000000"]],"a":[]}}
1618677410.500183: {"stream":"xlmusdt@depth@100ms","data":{"e":"depthUpdate","E":1618677410520,"s":"XLMUSDT","U":134557757,"u":134557757,"b":[["0.60008000","0.00000000"]],"a":[]}}
1618677410.500275: {"stream":"btcusdt@depth@100ms","data":{"e":"depthUpdate","E":1618677410520,"s":"BTCUSDT","U":372026735,"u":372026740,"b":[["60465.78000000","0.00000000"],["60463.34000000","0.00000000"],["60453.18000000","0.08000000"]],"a":[["60491.18000000","0.00000000"],["60491.50000000","0.00000000"],["60498.85000000","0.00000000"]]}}
1618677410.5003672: {"stream":"zrxusd@depth@100ms","data":{"e":"depthUpdate","E":1618677410520,"s":"ZRXUSD","U":51775866,"u":51775869,"b":[["2.0793","0.00000000"],["2.0775","495.00000000"]],"a":[["2.0861","0.00000000"],["2.0936","627.68000000"]]}}
1618677410.523768: {"stream":"zrxusd@bookTicker","data":{"u":51775872,"s":"ZRXUSD","b":"2.0821","B":"719.72000000","a":"2.0869","A":"719.26000000"}}
1618677410.6016982: {"stream":"zenusd@depth@100ms","data":{"e":"depthUpdate","E":1618677410620,"s":"ZENUSD","U":6596069,"u":6596070,"b":[["120.7830","3.14000000"],["120.5510","10.61000000"]],"a":[]}}
1618677410.638726: {"stream":"bchusdt@depth@100ms","data":{"e":"depthUpdate","E":1618677410620,"s":"BCHUSDT","U":123517991,"u":123517991,"b":[["1048.99000000","6.00000000"]],"a":[]}}
1618677410.6387908: {"stream":"xlmusdt@depth@100ms","data":{"e":"depthUpdate","E":1618677410620,"s":"XLMUSDT","U":134557758,"u":134557758,"b":[["0.59992000","404.60000000"]],"a":[]}}
1618677410.63884: {"stream":"btcusdt@depth@100ms","data":{"e":"depthUpdate","E":1618677410620,"s":"BTCUSDT","U":372026741,"u":372026741,"b":[],"a":[["60497.68000000","0.08026000"]]}}
1618677410.638887: {"stream":"zrxusd@depth@100ms","data":{"e":"depthUpdate","E":1618677410620,"s":"ZRXUSD","U":51775870,"u":51775872,"b":[["2.0793","495.00000000"],["2.0775","0.00000000"]],"a":[["2.0869","719.26000000"]]}}
1618677410.638935: {"stream":"ethbusd@depth@100ms","data":{"e":"depthUpdate","E":1618677410620,"s":"ETHBUSD","U":56401150,"u":56401150,"b":[],"a":[["2365.76000000","0.84666000"]]}}
1618677410.638963: {"stream":"btcusdt@bookTicker","data":{"u":372026742,"s":"BTCUSDT","b":"60472.27000000","B":"0.07981000","a":"60478.20000000","A":"0.03350600"}}
1618677410.6471748: {"stream":"ethbusd@bookTicker","data":{"u":56401152,"s":"ETHBUSD","b":"2360.63000000","B":"1.16070000","a":"2363.54000000","A":"0.14071000"}}
1618677410.699431: {"stream":"ethbusd@depth@100ms","data":{"e":"depthUpdate","E":1618677410720,"s":"ETHBUSD","U":56401151,"u":56401153,"b":[["2360.63000000","1.16070000"],["2357.74000000","0.80293000"],["2304.59000000","0.00000000"]],"a":[]}}
1618677410.699615: {"stream":"xlmusdt@depth@100ms","data":{"e":"depthUpdate","E":1618677410720,"s":"XLMUSDT","U":134557759,"u":134557760,"b":[],"a":[["0.61101000","0.00000000"],["0.61726000","11790.00000000"]]}}
1618677410.699717: {"stream":"btcusdt@depth@100ms","data":{"e":"depthUpdate","E":1618677410720,"s":"BTCUSDT","U":372026742,"u":372026742,"b":[["60472.27000000","0.07981000"]],"a":[]}}
1618677410.6997828: {"stream":"zrxusd@depth@100ms","data":{"e":"depthUpdate","E":1618677410720,"s":"ZRXUSD","U":51775873,"u":51775873,"b":[],"a":[["2.0936","0.00000000"]]}}
1618677410.699824: {"stream":"bchusdt@depth@100ms","data":{"e":"depthUpdate","E":1618677410720,"s":"BCHUSDT","U":123517992,"u":123517992,"b":[],"a":[["1053.22000000","34.56625000"]]}}
1618677410.705722: {"stream":"ethbusd@bookTicker","data":{"u":56401154,"s":"ETHBUSD","b":"2360.63000000","B":"1.16070000","a":"2363.55000000","A":"1.70002000"}}
1618677410.773168: {"stream":"btcusdt@bookTicker","data":{"u":372026746,"s":"BTCUSDT","b":"60472.27000000","B":"0.07981000","a":"60484.79000000","A":"0.03385000"}}
1618677410.783231: {"stream":"btcusdt@bookTicker","data":{"u":372026748,"s":"BTCUSDT","b":"60474.69000000","B":"0.03012200","a":"60484.79000000","A":"0.03385000"}}
1618677410.799804: {"stream":"ethbusd@depth@100ms","data":{"e":"depthUpdate","E":1618677410821,"s":"ETHBUSD","U":56401154,"u":56401155,"b":[],"a":[["2363.54000000","0.00000000"],["2365.13000000","0.13108000"]]}}
1618677410.799973: {"stream":"btcusdt@depth@100ms","data":{"e":"depthUpdate","E":1618677410821,"s":"BTCUSDT","U":372026743,"u":372026749,"b":[["60474.69000000","0.03012200"],["60454.74000000","0.07894400"],["60268.69000000","0.00000000"]],"a":[["60478.20000000","0.00000000"],["60484.78000000","0.00000000"],["60491.16000000","0.00666000"],["60757.57000000","0.41021200"]]}}
1618677410.800137: {"stream":"bchusdt@depth@100ms","data":{"e":"depthUpdate","E":1618677410821,"s":"BCHUSDT","U":123517993,"u":123517997,"b":[["1048.99000000","0.00000000"],["1048.56000000","0.00000000"]],"a":[["1053.21000000","0.42507000"],["1053.24000000","0.00000000"],["1053.25000000","0.00000000"]]}}
1618677410.808047: {"stream":"btcusdt@bookTicker","data":{"u":372026751,"s":"BTCUSDT","b":"60474.70000000","B":"0.00666000","a":"60484.79000000","A":"0.03385000"}}
1618677410.9006772: {"stream":"xlmusdt@depth@100ms","data":{"e":"depthUpdate","E":1618677410920,"s":"XLMUSDT","U":134557761,"u":134557761,"b":[["0.60041000","3322.50000000"]],"a":[]}}
1618677410.9008331: {"stream":"btcusdt@depth@100ms","data":{"e":"depthUpdate","E":1618677410920,"s":"BTCUSDT","U":372026750,"u":372026751,"b":[["60474.70000000","0.00666000"],["60465.79000000","0.00000000"]],"a":[]}}
1618677410.900943: {"stream":"bchusdt@depth@100ms","data":{"e":"depthUpdate","E":1618677410920,"s":"BCHUSDT","U":123517998,"u":123518000,"b":[["1049.99000000","2.15114000"],["1049.09000000","6.00000000"]],"a":[["1054.14000000","0.94961000"]]}}
1618677410.901002: {"stream":"zrxusd@depth@100ms","data":{"e":"depthUpdate","E":1618677410920,"s":"ZRXUSD","U":51775874,"u":51775874,"b":[],"a":[["2.0938","628.14000000"]]}}
1618677410.940147: {"stream":"btcusdt@bookTicker","data":{"u":372026756,"s":"BTCUSDT","b":"60475.56000000","B":"0.08048000","a":"60484.79000000","A":"0.03385000"}}
1618677410.999922: {"stream":"atomusdt@depth@100ms","data":{"e":"depthUpdate","E":1618677411020,"s":"ATOMUSDT","U":71292118,"u":71292118,"b":[["24.98700000","0.00000000"]],"a":[]}}
1618677411.0000808: {"stream":"ethbusd@depth@100ms","data":{"e":"depthUpdate","E":1618677411020,"s":"ETHBUSD","U":56401156,"u":56401157,"b":[["2350.47000000","0.00000000"]],"a":[["2423.28000000","0.01025000"]]}}
1618677411.000191: {"stream":"xlmusdt@depth@100ms","data":{"e":"depthUpdate","E":1618677411020,"s":"XLMUSDT","U":134557762,"u":134557762,"b":[["0.59992000","0.00000000"]],"a":[]}}
1618677411.000235: {"stream":"btcusdt@depth@100ms","data":{"e":"depthUpdate","E":1618677411020,"s":"BTCUSDT","U":372026752,"u":372026762,"b":[["60475.56000000","0.08048000"],["60472.27000000","0.00000000"],["60469.78000000","0.00000000"],["60462.45000000","0.13218600"],["60444.77000000","0.00000000"]],"a":[["60497.60000000","0.00000000"],["60497.68000000","0.00000000"],["60500.97000000","0.07972000"],["60520.87000000","0.13219200"]]}}
1618677411.006228: {"stream":"btcusdt@bookTicker","data":{"u":372026764,"s":"BTCUSDT","b":"60475.57000000","B":"0.00666000","a":"60484.79000000","A":"0.03385000"}}
1618677411.099505: {"stream":"ethbusd@depth@100ms","data":{"e":"depthUpdate","E":1618677411121,"s":"ETHBUSD","U":56401158,"u":56401159,"b":[["2358.68000000","0.84695000"],["2354.02000000","0.00000000"]],"a":[]}}
1618677411.099676: {"stream":"btcusdt@depth@100ms","data":{"e":"depthUpdate","E":1618677411121,"s":"BTCUSDT","U":372026763,"u":372026769,"b":[["60475.57000000","0.00666000"],["60474.70000000","0.00000000"]],"a":[["60491.16000000","0.00000000"],["60497.54000000","0.00666000"],["60506.07000000","0.00000000"],["60516.40000000","0.00000000"],["60540.08000000","0.00866000"]]}}
1618677411.1988852: {"stream":"xlmusdt@depth@100ms","data":{"e":"depthUpdate","E":1618677411220,"s":"XLMUSDT","U":134557763,"u":134557766,"b":[["0.60026000","0.00000000"]],"a":[["0.60176000","0.00000000"],["0.60383000","0.00000000"],["0.60532000","80665.00000000"]]}}
1618677411.199105: {"stream":"btcusdt@depth@100ms","data":{"e":"depthUpdate","E":1618677411220,"s":"BTCUSDT","U":372026770,"u":372026772,"b":[["60444.88000000","0.02098200"]],"a":[["60491.16000000","0.00666000"],["60497.54000000","0.00000000"]]}}
1618677411.199177: {"stream":"zrxusd@depth@100ms","data":{"e":"depthUpdate","E":1618677411221,"s":"ZRXUSD","U":51775875,"u":51775875,"b":[],"a":[["2.0938","0.00000000"]]}}
1618677411.199221: {"stream":"ethbusd@depth@100ms","data":{"e":"depthUpdate","E":1618677411220,"s":"ETHBUSD","U":56401160,"u":56401160,"b":[["2351.94000000","0.05400000"]],"a":[]}}
1618677411.199258: {"stream":"bchusdt@depth@100ms","data":{"e":"depthUpdate","E":1618677411220,"s":"BCHUSDT","U":123518001,"u":123518001,"b":[["1049.16000000","0.00000000"]],"a":[]}}
1618677411.299695: {"stream":"xlmusdt@depth@100ms","data":{"e":"depthUpdate","E":1618677411321,"s":"XLMUSDT","U":134557767,"u":134557768,"b":[["0.60029000","5443.40000000"]],"a":[["0.60206000","3321.70000000"]]}}
1618677411.2998762: {"stream":"btcusdt@depth@100ms","data":{"e":"depthUpdate","E":1618677411321,"s":"BTCUSDT","U":372026773,"u":372026773,"b":[],"a":[["60516.23000000","0.08000000"]]}}
1618677411.299965: {"stream":"ethbusd@depth@100ms","data":{"e":"depthUpdate","E":1618677411321,"s":"ETHBUSD","U":56401161,"u":56401162,"b":[["2354.02000000","0.05400000"],["2351.94000000","0.00000000"]],"a":[]}}
1618677411.399083: {"stream":"zrxusd@depth@100ms","data":{"e":"depthUpdate","E":1618677411421,"s":"ZRXUSD","U":51775876,"u":51775876,"b":[],"a":[["2.0938","602.57000000"]]}}
1618677411.404116: {"stream":"btcusdt@bookTicker","data":{"u":372026775,"s":"BTCUSDT","b":"60475.79000000","B":"0.09913400","a":"60484.79000000","A":"0.03385000"}}
1618677411.419501: {"stream":"xlmusdt@bookTicker","data":{"u":134557769,"s":"XLMUSDT","b":"0.60045000","B":"1924.20000000","a":"0.60170000","A":"3570.60000000"}}
1618677411.501109: {"stream":"atomusdt@depth@100ms","data":{"e":"depthUpdate","E":1618677411521,"s":"ATOMUSDT","U":71292119,"u":71292120,"b":[["24.94700000","8.23300000"]],"a":[["25.34100000","44.72200000"]]}}
1618677411.501277: {"stream":"ethbusd@depth@100ms","data":{"e":"depthUpdate","E":1618677411521,"s":"ETHBUSD","U":56401163,"u":56401164,"b":[["2348.13000000","14.22198000"]],"a":[["2371.65000000","13.96857000"]]}}
1618677411.5013728: {"stream":"xlmusdt@depth@100ms","data":{"e":"depthUpdate","E":1618677411521,"s":"XLMUSDT","U":134557769,"u":134557770,"b":[["0.60045000","1924.20000000"],["0.59986000","404.60000000"]],"a":[]}}
1618677411.5014222: {"stream":"btcusdt@depth@100ms","data":{"e":"depthUpdate","E":1618677411521,"s":"BTCUSDT","U":372026774,"u":372026776,"b":[["60475.79000000","0.09913400"]],"a":[["60503.96000000","0.09913400"],["60511.36000000","0.00000000"]]}}
1618677411.506915: {"stream":"btcusdt@bookTicker","data":{"u":372026778,"s":"BTCUSDT","b":"60475.80000000","B":"0.00657300","a":"60484.79000000","A":"0.03385000"}}
1618677411.589149: {"stream":"xlmusdt@bookTicker","data":{"u":134557772,"s":"XLMUSDT","b":"0.60055000","B":"3321.80000000","a":"0.60170000","A":"3570.60000000"}}
1618677411.5987809: {"stream":"xlmusdt@depth@100ms","data":{"e":"depthUpdate","E":1618677411621,"s":"XLMUSDT","U":134557771,"u":134557772,"b":[["0.60055000","3321.80000000"],["0.60029000","2120.90000000"]],"a":[]}}
1618677411.598943: {"stream":"btcusdt@depth@100ms","data":{"e":"depthUpdate","E":1618677411621,"s":"BTCUSDT","U":372026777,"u":372026780,"b":[["60475.80000000","0.00657300"],["60475.57000000","0.00000000"]],"a":[["60491.16000000","0.00000000"],["60497.54000000","0.00657300"]]}}
1618677411.599093: {"stream":"zrxusd@depth@100ms","data":{"e":"depthUpdate","E":1618677411621,"s":"ZRXUSD","U":51775877,"u":51775878,"b":[["2.0793","0.00000000"],["2.0775","495.00000000"]],"a":[]}}
1618677411.700267: {"stream":"btcusdt@depth@100ms","data":{"e":"depthUpdate","E":1618677411721,"s":"BTCUSDT","U":372026781,"u":372026782,"b":[],"a":[["60491.16000000","0.00657300"],["60497.54000000","0.00000000"]]}}
1618677411.7004428: {"stream":"zrxusd@depth@100ms","data":{"e":"depthUpdate","E":1618677411721,"s":"ZRXUSD","U":51775879,"u":51775881,"b":[],"a":[["2.0880","0.00000000"],["2.0938","0.00000000"],["2.3237","4809.64000000"]]}}
1618677411.714272: {"stream":"xlmusdt@bookTicker","data":{"u":134557774,"s":"XLMUSDT","b":"0.60083000","B":"1315.60000000","a":"0.60170000","A":"3570.60000000"}}
1618677411.7775638: {"stream":"btcusdt@bookTicker","data":{"u":372026784,"s":"BTCUSDT","b":"60475.80000000","B":"0.00657300","a":"60491.16000000","A":"0.00657300"}}
1618677411.801461: {"stream":"atomusdt@depth@100ms","data":{"e":"depthUpdate","E":1618677411821,"s":"ATOMUSDT","U":71292121,"u":71292121,"b":[],"a":[["25.37700000","0.00000000"]]}}
1618677411.801614: {"stream":"xlmusdt@depth@100ms","data":{"e":"depthUpdate","E":1618677411821,"s":"XLMUSDT","U":134557773,"u":134557775,"b":[["0.60083000","1315.60000000"],["0.59986000","0.00000000"],["0.58531000","42.80000000"]],"a":[]}}
1618677411.801728: {"stream":"ethbusd@depth@100ms","data":{"e":"depthUpdate","E":1618677411821,"s":"ETHBUSD","U":56401165,"u":56401165,"b":[],"a":[["2375.35000000","0.00000000"]]}}
1618677411.801795: {"stream":"btcusdt@depth@100ms","data":{"e":"depthUpdate","E":1618677411821,"s":"BTCUSDT","U":372026783,"u":372026787,"b":[["60284.26000000","0.00000000"]],"a":[["60484.79000000","0.00000000"],["60491.17000000","0.00000000"],["60771.61000000","0.32068100"],["60784.22000000","0.46490500"]]}}
1618677411.8018718: {"stream":"zrxusd@depth@100ms","data":{"e":"depthUpdate","E":1618677411821,"s":"ZRXUSD","U":51775882,"u":51775883,"b":[["2.0793","495.00000000"],["2.0775","0.00000000"]],"a":[]}}
1618677411.801918: {"stream":"bchusdt@depth@100ms","data":{"e":"depthUpdate","E":1618677411821,"s":"BCHUSDT","U":123518002,"u":123518003,"b":[],"a":[["1053.93000000","0.00000000"],["1054.84000000","1.42429000"]]}}
1618677411.8070369: {"stream":"btcusdt@bookTicker","data":{"u":372026788,"s":"BTCUSDT","b":"60475.80000000","B":"0.00657300","a":"60497.55000000","A":"0.02870600"}}
1618677411.8071191: {"stream":"btcusdt@bookTicker","data":{"u":372026789,"s":"BTCUSDT","b":"60475.80000000","B":"0.00657300","a":"60497.54000000","A":"0.00657300"}}
1618677411.900906: {"stream":"xlmusdt@depth@100ms","data":{"e":"depthUpdate","E":1618677411923,"s":"XLMUSDT","U":134557776,"u":134557776,"b":[["0.60055000","0.00000000"]],"a":[]}}
1618677411.901085: {"stream":"btcusdt@depth@100ms","data":{"e":"depthUpdate","E":1618677411923,"s":"BTCUSDT","U":372026788,"u":372026789,"b":[],"a":[["60491.16000000","0.00000000"],["60497.54000000","0.00657300"]]}}
1618677412.003205: {"stream":"xlmusdt@depth@100ms","data":{"e":"depthUpdate","E":1618677412021,"s":"XLMUSDT","U":134557777,"u":134557779,"b":[["0.60029000","5443.40000000"]],"a":[["0.60173000","3322.80000000"],["0.60206000","0.00000000"]]}}
1618677412.088177: {"stream":"omgusd@bookTicker","data":{"u":66532564,"s":"OMGUSD","b":"9.5379","B":"88.05000000","a":"9.5584","A":"259.47000000"}}
1618677412.1009789: {"stream":"xlmusdt@depth@100ms","data":{"e":"depthUpdate","E":1618677412121,"s":"XLMUSDT","U":134557780,"u":134557780,"b":[["0.60041000","0.00000000"]],"a":[]}}
1618677412.101136: {"stream":"zrxusd@depth@100ms","data":{"e":"depthUpdate","E":1618677412121,"s":"ZRXUSD","U":51775884,"u":51775886,"b":[["2.0793","0.00000000"],["2.0775","495.00000000"]],"a":[["2.0939","630.26000000"]]}}
1618677412.101274: {"stream":"omgusd@depth@100ms","data":{"e":"depthUpdate","E":1618677412121,"s":"OMGUSD","U":66532563,"u":66532564,"b":[["9.5379","88.05000000"],["9.1421","0.00000000"]],"a":[]}}
1618677412.179378: {"stream":"bchusdt@bookTicker","data":{"u":123518004,"s":"BCHUSDT","b":"1050.59000000","B":"24.66957000","a":"1052.60000000","A":"0.86131000"}}
1618677412.186177: {"stream":"ethbusd@bookTicker","data":{"u":56401166,"s":"ETHBUSD","b":"2360.63000000","B":"1.66070000","a":"2363.55000000","A":"1.70002000"}}
1618677412.201625: {"stream":"zrxusd@depth@100ms","data":{"e":"depthUpdate","E":1618677412223,"s":"ZRXUSD","U":51775887,"u":51775887,"b":[["2.0775","0.00000000"]],"a":[]}}
1618677412.201779: {"stream":"bchusdt@depth@100ms","data":{"e":"depthUpdate","E":1618677412223,"s":"BCHUSDT","U":123518004,"u":123518004,"b":[["1050.59000000","24.66957000"]],"a":[]}}
1618677412.201858: {"stream":"omgusd@depth@100ms","data":{"e":"depthUpdate","E":1618677412223,"s":"OMGUSD","U":66532565,"u":66532565,"b":[["9.5356","0.00000000"]],"a":[]}}
1618677412.201925: {"stream":"ethbusd@depth@100ms","data":{"e":"depthUpdate","E":1618677412223,"s":"ETHBUSD","U":56401166,"u":56401166,"b":[["2360.63000000","1.66070000"]],"a":[]}}
1618677412.301811: {"stream":"btcusdt@depth@100ms","data":{"e":"depthUpdate","E":1618677412324,"s":"BTCUSDT","U":372026790,"u":372026790,"b":[["60444.88000000","0.00000000"]],"a":[]}}
1618677412.301961: {"stream":"zrxusd@depth@100ms","data":{"e":"depthUpdate","E":1618677412324,"s":"ZRXUSD","U":51775888,"u":51775888,"b":[["2.0793","495.00000000"]],"a":[]}}
1618677412.400597: {"stream":"zrxusd@depth@100ms","data":{"e":"depthUpdate","E":1618677412421,"s":"ZRXUSD","U":51775889,"u":51775892,"b":[["2.0793","495.00000000"],["2.0775","0.00000000"]],"a":[]}}
1618677412.400748: {"stream":"bchusdt@depth@100ms","data":{"e":"depthUpdate","E":1618677412421,"s":"BCHUSDT","U":123518005,"u":123518005,"b":[["1049.09000000","0.00000000"]],"a":[]}}
1618677412.401199: {"stream":"ethbusd@depth@100ms","data":{"e":"depthUpdate","E":1618677412421,"s":"ETHBUSD","U":56401167,"u":56401168,"b":[["2348.14000000","1.27100000"],["2344.63000000","0.00000000"]],"a":[]}}
1618677412.500698: {"stream":"usdtusd@depth@100ms","data":{"e":"depthUpdate","E":1618677412521,"s":"USDTUSD","U":34057434,"u":34057434,"b":[["0.9998","12.45000000"]],"a":[]}}
1618677412.535456: {"stream":"xlmusdt@depth@100ms","data":{"e":"depthUpdate","E":1618677412521,"s":"XLMUSDT","U":134557781,"u":134557781,"b":[["0.59249000","0.00000000"]],"a":[]}}
1618677412.599498: {"stream":"zenusd@depth@100ms","data":{"e":"depthUpdate","E":1618677412621,"s":"ZENUSD","U":6596071,"u":6596072,"b":[],"a":[["121.6910","0.00000000"],["121.9450","16.46300000"]]}}
1618677412.699703: {"stream":"zrxusd@depth@100ms","data":{"e":"depthUpdate","E":1618677412722,"s":"ZRXUSD","U":51775893,"u":51775893,"b":[],"a":[["2.0888","626.34000000"]]}}
1618677413.0002701: {"stream":"xlmusdt@depth@100ms","data":{"e":"depthUpdate","E":1618677413022,"s":"XLMUSDT","U":134557782,"u":134557782,"b":[["0.60018000","404.60000000"]],"a":[]}}
1618677413.1002932: {"stream":"zenusd@depth@100ms","data":{"e":"depthUpdate","E":1618677413122,"s":"ZENUSD","U":6596073,"u":6596073,"b":[],"a":[["121.7210","0.00000000"]]}}
1618677413.100448: {"stream":"omgusd@depth@100ms","data":{"e":"depthUpdate","E":1618677413122,"s":"OMGUSD","U":66532566,"u":66532567,"b":[],"a":[["9.5665","0.00000000"],["9.5804","803.50000000"]]}}
1618677413.2006452: {"stream":"zenusd@depth@100ms","data":{"e":"depthUpdate","E":1618677413222,"s":"ZENUSD","U":6596074,"u":6596074,"b":[],"a":[["121.9280","8.08000000"]]}}
1618677413.200792: {"stream":"xlmusdt@depth@100ms","data":{"e":"depthUpdate","E":1618677413222,"s":"XLMUSDT","U":134557783,"u":134557786,"b":[["0.60045000","5246.50000000"],["0.60018000","0.00000000"]],"a":[["0.60173000","0.00000000"],["0.60200000","3322.00000000"]]}}
1618677413.201948: {"stream":"bchusdt@bookTicker","data":{"u":123518007,"s":"BCHUSDT","b":"1050.59000000","B":"24.66957000","a":"1053.21000000","A":"0.42507000"}}
1618677413.205052: {"stream":"bchusdt@bookTicker","data":{"u":123518008,"s":"BCHUSDT","b":"1051.21000000","B":"0.64251000","a":"1053.21000000","A":"0.42507000"}}
1618677413.302262: {"stream":"bchusdt@depth@100ms","data":{"e":"depthUpdate","E":1618677413323,"s":"BCHUSDT","U":123518006,"u":123518009,"b":[["1051.21000000","0.64251000"],["1024.75000000","0.00000000"]],"a":[["1052.60000000","0.00000000"],["1129.98000000","17.80273000"]]}}
1618677413.3024: {"stream":"xlmusdt@depth@100ms","data":{"e":"depthUpdate","E":1618677413323,"s":"XLMUSDT","U":134557787,"u":134557788,"b":[["0.60029000","2120.90000000"],["0.60022000","404.60000000"]],"a":[]}}
1618677413.400745: {"stream":"btcusdt@depth@100ms","data":{"e":"depthUpdate","E":1618677413422,"s":"BTCUSDT","U":372026791,"u":372026794,"b":[["60475.56000000","0.00000000"],["60392.10000000","0.00000000"]],"a":[["60500.97000000","0.00000000"],["60511.37000000","0.00000000"]]}}
1618677413.4462621: {"stream":"zenusd@bookTicker","data":{"u":6596075,"s":"ZENUSD","b":"121.0370","B":"16.47800000","a":"121.6900","A":"3.14000000"}}
1618677413.508883: {"stream":"zenusd@depth@100ms","data":{"e":"depthUpdate","E":1618677413522,"s":"ZENUSD","U":6596075,"u":6596076,"b":[],"a":[["121.5210","0.00000000"],["139.3910","159.84000000"]]}}
1618677413.509055: {"stream":"ethbusd@depth@100ms","data":{"e":"depthUpdate","E":1618677413522,"s":"ETHBUSD","U":56401169,"u":56401170,"b":[["2358.68000000","0.00000000"]],"a":[["2365.14000000","0.00000000"]]}}
1618677413.509163: {"stream":"bchusdt@depth@100ms","data":{"e":"depthUpdate","E":1618677413522,"s":"BCHUSDT","U":123518010,"u":123518011,"b":[["1050.06000000","0.00000000"]],"a":[["1053.81000000","0.91615000"]]}}
1618677413.5092611: {"stream":"xlmusdt@depth@100ms","data":{"e":"depthUpdate","E":1618677413522,"s":"XLMUSDT","U":134557789,"u":134557789,"b":[["0.59582000","37.00000000"]],"a":[]}}
1618677413.514986: {"stream":"ethbusd@bookTicker","data":{"u":56401171,"s":"ETHBUSD","b":"2360.64000000","B":"0.10145000","a":"2363.55000000","A":"1.70002000"}}
1618677413.5721788: {"stream":"bchusdt@bookTicker","data":{"u":123518012,"s":"BCHUSDT","b":"1051.22000000","B":"0.91601000","a":"1053.21000000","A":"0.42507000"}}
1618677413.605288: {"stream":"xlmusdt@depth@100ms","data":{"e":"depthUpdate","E":1618677413622,"s":"XLMUSDT","U":134557790,"u":134557790,"b":[["0.60045000","3322.30000000"]],"a":[]}}
1618677413.6054442: {"stream":"btcusdt@depth@100ms","data":{"e":"depthUpdate","E":1618677413622,"s":"BTCUSDT","U":372026795,"u":372026796,"b":[["60403.25000000","0.01000000"]],"a":[["60552.20000000","0.00904000"]]}}
1618677413.605543: {"stream":"ethbusd@depth@100ms","data":{"e":"depthUpdate","E":1618677413622,"s":"ETHBUSD","U":56401171,"u":56401174,"b":[["2360.64000000","0.10145000"],["2359.89000000","0.84655000"],["2357.74000000","0.00000000"]],"a":[["2366.22000000","0.84647000"]]}}
1618677413.60565: {"stream":"bchusdt@depth@100ms","data":{"e":"depthUpdate","E":1618677413622,"s":"BCHUSDT","U":123518012,"u":123518013,"b":[["1051.22000000","0.91601000"],["1051.01000000","0.94926000"]],"a":[]}}
1618677413.61979: {"stream":"omgusd@bookTicker","data":{"u":66532568,"s":"OMGUSD","b":"9.5379","B":"88.05000000","a":"9.5584","A":"50.00000000"}}
1618677413.6760519: {"stream":"ethbusd@bookTicker","data":{"u":56401176,"s":"ETHBUSD","b":"2360.64000000","B":"0.10145000","a":"2365.13000000","A":"0.13108000"}}
1618677413.7052538: {"stream":"ethbusd@depth@100ms","data":{"e":"depthUpdate","E":1618677413723,"s":"ETHBUSD","U":56401175,"u":56401178,"b":[["2359.32000000","0.00000000"],["2358.62000000","0.80293000"]],"a":[["2363.55000000","0.00000000"],["2452.17000000","28.57665000"]]}}
1618677413.705458: {"stream":"zenusd@depth@100ms","data":{"e":"depthUpdate","E":1618677413723,"s":"ZENUSD","U":6596077,"u":6596077,"b":[],"a":[["122.5010","0.00000000"]]}}
1618677413.705534: {"stream":"xlmusdt@depth@100ms","data":{"e":"depthUpdate","E":1618677413723,"s":"XLMUSDT","U":134557791,"u":134557791,"b":[],"a":[["0.60189000","2258.60000000"]]}}
1618677413.7055879: {"stream":"btcusdt@depth@100ms","data":{"e":"depthUpdate","E":1618677413723,"s":"BTCUSDT","U":372026797,"u":372026797,"b":[["60376.20000000","0.08895100"]],"a":[]}}
1618677413.705646: {"stream":"bchusdt@depth@100ms","data":{"e":"depthUpdate","E":1618677413723,"s":"BCHUSDT","U":123518014,"u":123518014,"b":[],"a":[["1053.22000000","0.00000000"]]}}
1618677413.705701: {"stream":"omgusd@depth@100ms","data":{"e":"depthUpdate","E":1618677413723,"s":"OMGUSD","U":66532568,"u":66532569,"b":[],"a":[["9.5584","50.00000000"],["9.5652","209.37000000"]]}}
1618677413.735669: {"stream":"atomusdt@bookTicker","data":{"u":71292122,"s":"ATOMUSDT","b":"25.13400000","B":"39.70600000","a":"25.20100000","A":"1.80500000"}}
1618677413.7413719: {"stream":"bchusdt@aggTrade","data":{"e":"aggTrade","E":1618677413758,"s":"BCHUSDT","a":724813,"p":"1053.21000000","q":"0.42507000","f":736392,"l":736392,"T":1618677413757,"m":false,"M":true}}
1618677413.741479: {"stream":"bchusdt@bookTicker","data":{"u":123518016,"s":"BCHUSDT","b":"1051.22000000","B":"0.91601000","a":"1053.28000000","A":"0.68983000"}}
1618677413.7771862: {"stream":"bchusdt@aggTrade","data":{"e":"aggTrade","E":1618677413793,"s":"BCHUSDT","a":724814,"p":"1053.28000000","q":"0.68983000","f":736393,"l":736393,"T":1618677413793,"m":false,"M":true}}
1618677413.777259: {"stream":"bchusdt@bookTicker","data":{"u":123518019,"s":"BCHUSDT","b":"1051.22000000","B":"0.91601000","a":"1053.81000000","A":"0.91615000"}}
1618677413.7873: {"stream":"btcusdt@bookTicker","data":{"u":372026803,"s":"BTCUSDT","b":"60484.08000000","B":"0.03060800","a":"60497.54000000","A":"0.00657300"}}
1618677413.8075929: {"stream":"bchusdt@depth@100ms","data":{"e":"depthUpdate","E":1618677413822,"s":"BCHUSDT","U":123518015,"u":123518019,"b":[["1050.59000000","0.00000000"]],"a":[["1053.21000000","0.00000000"],["1053.28000000","0.00000000"],["1054.14000000","0.00000000"],["1054.84000000","0.00000000"]]}}
1618677413.807824: {"stream":"atomusdt@depth@100ms","data":{"e":"depthUpdate","E":1618677413822,"s":"ATOMUSDT","U":71292122,"u":71292123,"b":[],"a":[["25.19200000","0.00000000"],["25.20600000","70.07300000"]]}}
1618677413.807883: {"stream":"xlmusdt@depth@100ms","data":{"e":"depthUpdate","E":1618677413822,"s":"XLMUSDT","U":134557792,"u":134557793,"b":[["0.60059000","3321.50000000"]],"a":[["0.60217000","3321.10000000"]]}}
1618677413.807939: {"stream":"btcusdt@depth@100ms","data":{"e":"depthUpdate","E":1618677413822,"s":"BTCUSDT","U":372026798,"u":372026803,"b":[["60484.08000000","0.03060800"],["60475.79000000","0.00000000"],["60453.18000000","0.00000000"],["60453.16000000","0.00000000"],["60301.00000000","0.00000000"]],"a":[["60508.52000000","0.00000000"]]}}
1618677413.811659: {"stream":"bchusdt@bookTicker","data":{"u":123518020,"s":"BCHUSDT","b":"1051.23000000","B":"0.42573000","a":"1053.81000000","A":"0.91615000"}}
1618677413.9100502: {"stream":"xlmusdt@depth@100ms","data":{"e":"depthUpdate","E":1618677413922,"s":"XLMUSDT","U":134557794,"u":134557794,"b":[["0.60045000","0.00000000"]],"a":[]}}
1618677413.910207: {"stream":"bchusdt@depth@100ms","data":{"e":"depthUpdate","E":1618677413922,"s":"BCHUSDT","U":123518020,"u":123518021,"b":[["1051.23000000","0.42573000"],["1050.35000000","6.00000000"]],"a":[]}}
1618677413.9102972: {"stream":"btcusdt@depth@100ms","data":{"e":"depthUpdate","E":1618677413922,"s":"BTCUSDT","U":372026804,"u":372026809,"b":[["60480.69000000","0.09912600"],["60470.61000000","0.13216800"],["60466.93000000","0.08000000"],["60376.20000000","0.00000000"]],"a":[["60503.96000000","0.00000000"],["60531.02000000","0.13216800"]]}}
1618677413.910867: {"stream":"btcusdt@bookTicker","data":{"u":372026811,"s":"BTCUSDT","b":"60484.08000000","B":"0.03060800","a":"60497.55000000","A":"0.02870600"}}
1618677413.943536: {"stream":"bchusdt@bookTicker","data":{"u":123518022,"s":"BCHUSDT","b":"1051.23000000","B":"0.42573000","a":"1053.82000000","A":"1.80581000"}}
1618677413.988405: {"stream":"btcusdt@bookTicker","data":{"u":372026814,"s":"BTCUSDT","b":"60496.59000000","B":"0.07992000","a":"60497.55000000","A":"0.02870600"}}
1618677414.0085042: {"stream":"zrxusd@depth@100ms","data":{"e":"depthUpdate","E":1618677414022,"s":"ZRXUSD","U":51775894,"u":51775894,"b":[],"a":[["2.0939","0.00000000"]]}}
1618677414.008657: {"stream":"xlmusdt@depth@100ms","data":{"e":"depthUpdate","E":1618677414023,"s":"XLMUSDT","U":134557795,"u":134557797,"b":[["0.60059000","0.00000000"],["0.60022000","0.00000000"]],"a":[["0.60200000","0.00000000"]]}}
1618677414.008776: {"stream":"btcusdt@depth@100ms","data":{"e":"depthUpdate","E":1618677414023,"s":"BTCUSDT","U":372026810,"u":372026814,"b":[["60496.59000000","0.07992000"],["60480.69000000","0.00000000"],["60475.80000000","0.00000000"]],"a":[["60497.54000000","0.00000000"],["60522.00000000","0.08020000"]]}}
1618677414.0088809: {"stream":"ethbusd@depth@100ms","data":{"e":"depthUpdate","E":1618677414022,"s":"ETHBUSD","U":56401179,"u":56401179,"b":[["2300.68000000","0.00000000"]],"a":[]}}
1618677414.008922: {"stream":"bchusdt@depth@100ms","data":{"e":"depthUpdate","E":1618677414022,"s":"BCHUSDT","U":123518022,"u":123518023,"b":[["1051.01000000","0.00000000"]],"a":[["1053.81000000","0.00000000"]]}}
1618677414.0777118: {"stream":"btcusdt@aggTrade","data":{"e":"aggTrade","E":1618677414092,"s":"BTCUSDT","a":3612248,"p":"60497.55000000","q":"0.02870000","f":3667499,"l":3667499,"T":1618677414091,"m":false,"M":true}}
1618677414.077814: {"stream":"btcusdt@bookTicker","data":{"u":372026817,"s":"BTCUSDT","b":"60496.59000000","B":"0.07992000","a":"60497.55000000","A":"0.00000600"}}
1618677414.099744: {"stream":"bchusdt@bookTicker","data":{"u":123518028,"s":"BCHUSDT","b":"1051.91000000","B":"0.94847000","a":"1053.82000000","A":"1.80581000"}}
1618677414.105657: {"stream":"ethbusd@depth@100ms","data":{"e":"depthUpdate","E":1618677414125,"s":"ETHBUSD","U":56401180,"u":56401180,"b":[["2360.63000000","1.16070000"]],"a":[]}}
1618677414.1057868: {"stream":"bchusdt@depth@100ms","data":{"e":"depthUpdate","E":1618677414125,"s":"BCHUSDT","U":123518024,"u":123518028,"b":[["1051.91000000","0.94847000"],["1049.99000000","0.72672000"]],"a":[["1055.02000000","0.94885000"],["1055.25000000","0.00000000"],["1056.89000000","1.17100000"]]}}
1618677414.105938: {"stream":"xlmusdt@depth@100ms","data":{"e":"depthUpdate","E":1618677414125,"s":"XLMUSDT","U":134557798,"u":134557798,"b":[],"a":[["0.60217000","0.00000000"]]}}
1618677414.107628: {"stream":"btcusdt@depth@100ms","data":{"e":"depthUpdate","E":1618677414125,"s":"BTCUSDT","U":372026815,"u":372026817,"b":[["60462.45000000","0.00000000"]],"a":[["60497.55000000","0.00000600"],["60516.23000000","0.00000000"]]}}
1618677414.116884: {"stream":"btcusdt@bookTicker","data":{"u":372026819,"s":"BTCUSDT","b":"60496.60000000","B":"0.00622900","a":"60497.55000000","A":"0.00000600"}}
1618677414.2012491: {"stream":"btcusdt@depth@100ms","data":{"e":"depthUpdate","E":1618677414223,"s":"BTCUSDT","U":372026818,"u":372026822,"b":[["60496.60000000","0.00622900"],["60403.25000000","0.00000000"]],"a":[["60516.40000000","0.00622900"],["60520.60000000","0.00000000"],["60520.87000000","0.00000000"]]}}
1618677414.2059672: {"stream":"bchusdt@depth@100ms","data":{"e":"depthUpdate","E":1618677414223,"s":"BCHUSDT","U":123518029,"u":123518031,"b":[["1051.48000000","1.42242000"],["1051.23000000","0.00000000"]],"a":[["1055.73000000","1.42313000"]]}}
1618677414.2245162: {"stream":"bchusdt@bookTicker","data":{"u":123518032,"s":"BCHUSDT","b":"1051.92000000","B":"0.42558000","a":"1053.82000000","A":"1.80581000"}}
1618677414.3042839: {"stream":"ethbusd@depth@100ms","data":{"e":"depthUpdate","E":1618677414323,"s":"ETHBUSD","U":56401181,"u":56401181,"b":[["2360.49000000","0.84633000"]],"a":[]}}
1618677414.3044438: {"stream":"bchusdt@depth@100ms","data":{"e":"depthUpdate","E":1618677414323,"s":"BCHUSDT","U":123518032,"u":123518034,"b":[["1051.92000000","0.42558000"],["1050.35000000","0.00000000"]],"a":[["1055.01000000","0.91513000"]]}}
1618677414.3592708: {"stream":"atomusdt@bookTicker","data":{"u":71292124,"s":"ATOMUSDT","b":"25.15100000","B":"32.03800000","a":"25.20100000","A":"1.80500000"}}
1618677414.382113: {"stream":"xlmusdt@bookTicker","data":{"u":134557801,"s":"XLMUSDT","b":"0.60090000","B":"3319.80000000","a":"0.60170000","A":"3570.60000000"}}
1618677414.3877609: {"stream":"xlmusdt@bookTicker","data":{"u":134557802,"s":"XLMUSDT","b":"0.60103000","B":"3319.10000000","a":"0.60170000","A":"3570.60000000"}}
1618677414.408291: {"stream":"atomusdt@depth@100ms","data":{"e":"depthUpdate","E":1618677414423,"s":"ATOMUSDT","U":71292124,"u":71292125,"b":[["25.15100000","32.03800000"],["24.13000000","5.63600000"]],"a":[]}}
1618677414.408449: {"stream":"xlmusdt@depth@100ms","data":{"e":"depthUpdate","E":1618677414423,"s":"XLMUSDT","U":134557799,"u":134557803,"b":[["0.60103000","3319.10000000"],["0.60090000","3319.80000000"],["0.60039000","404.60000000"]],"a":[["0.60228000","3320.40000000"],["0.60244000","3319.60000000"]]}}
1618677414.408572: {"stream":"btcusdt@depth@100ms","data":{"e":"depthUpdate","E":1618677414423,"s":"BTCUSDT","U":372026823,"u":372026826,"b":[["60493.24000000","0.09910600"],["60479.95000000","0.13214800"]],"a":[["60523.38000000","0.09910100"],["60543.56000000","0.13214100"]]}}
1618677414.408652: {"stream":"bchusdt@depth@100ms","data":{"e":"depthUpdate","E":1618677414423,"s":"BCHUSDT","U":123518035,"u":123518036,"b":[],"a":[["1055.02000000","0.00000000"],["1055.91000000","0.94803000"]]}}
1618677414.4310231: {"stream":"omgusd@bookTicker","data":{"u":66532571,"s":"OMGUSD","b":"9.5422","B":"209.31000000","a":"9.5584","A":"50.00000000"}}
1618677414.482194: {"stream":"atomusdt@bookTicker","data":{"u":71292127,"s":"ATOMUSDT","b":"25.15800000","B":"39.66500000","a":"25.20100000","A":"1.80500000"}}
1618677414.504419: {"stream":"atomusdt@depth@100ms","data":{"e":"depthUpdate","E":1618677414523,"s":"ATOMUSDT","U":71292126,"u":71292127,"b":[["25.15800000","39.66500000"],["25.13400000","0.00000000"]],"a":[]}}
1618677414.504608: {"stream":"omgusd@depth@100ms","data":{"e":"depthUpdate","E":1618677414523,"s":"OMGUSD","U":66532570,"u":66532571,"b":[["9.5422","209.31000000"],["9.5355","0.00000000"]],"a":[]}}
1618677414.504724: {"stream":"zrxusd@depth@100ms","data":{"e":"depthUpdate","E":1618677414523,"s":"ZRXUSD","U":51775895,"u":51775898,"b":[["2.0774","0.00000000"],["2.0741","0.00000000"]],"a":[["2.0910","0.00000000"],["2.0949","0.00000000"]]}}
1618677414.604863: {"stream":"xlmusdt@depth@100ms","data":{"e":"depthUpdate","E":1618677414623,"s":"XLMUSDT","U":134557804,"u":134557804,"b":[["0.60039000","0.00000000"]],"a":[]}}
1618677414.6097689: {"stream":"bchusdt@depth@100ms","data":{"e":"depthUpdate","E":1618677414623,"s":"BCHUSDT","U":123518037,"u":123518038,"b":[["1051.02000000","6.00000000"]],"a":[["1055.73000000","0.00000000"]]}}
1618677414.609948: {"stream":"zrxusd@depth@100ms","data":{"e":"depthUpdate","E":1618677414623,"s":"ZRXUSD","U":51775899,"u":51775903,"b":[["2.0792","2237.18000000"],["2.0756","2209.00000000"]],"a":[["2.0928","2040.00000000"],["2.0942","612.85000000"],["2.0954","4517.28000000"]]}}
1618677414.7025652: {"stream":"zenusd@depth@100ms","data":{"e":"depthUpdate","E":1618677414723,"s":"ZENUSD","U":6596078,"u":6596078,"b":[],"a":[["122.7950","1.17700000"]]}}
1618677414.7027142: {"stream":"xlmusdt@depth@100ms","data":{"e":"depthUpdate","E":1618677414723,"s":"XLMUSDT","U":134557805,"u":134557806,"b":[],"a":[["0.60189000","0.00000000"],["0.60228000","0.00000000"]]}}
1618677414.702815: {"stream":"btcusdt@depth@100ms","data":{"e":"depthUpdate","E":1618677414723,"s":"BTCUSDT","U":372026827,"u":372026827,"b":[["60314.37000000","0.00000000"]],"a":[]}}
1618677414.787162: {"stream":"btcusdt@bookTicker","data":{"u":372026828,"s":"BTCUSDT","b":"60496.60000000","B":"0.00622900","a":"60506.98000000","A":"0.07688700"}}
1618677414.787224: {"stream":"btcusdt@bookTicker","data":{"u":372026829,"s":"BTCUSDT","b":"60496.60000000","B":"0.00622900","a":"60516.40000000","A":"0.00622900"}}
1618677414.790902: {"stream":"btcusdt@bookTicker","data":{"u":372026830,"s":"BTCUSDT","b":"60497.54000000","B":"0.02520200","a":"60516.40000000","A":"0.00622900"}}
1618677414.801478: {"stream":"btcusdt@depth@100ms","data":{"e":"depthUpdate","E":1618677414823,"s":"BTCUSDT","U":372026828,"u":372026832,"b":[["60497.54000000","0.02520200"]],"a":[["60497.55000000","0.00000000"],["60506.98000000","0.00000000"],["60798.16000000","0.41047000"],["60812.73000000","0.33970500"]]}}
1618677414.8016682: {"stream":"zrxusd@depth@100ms","data":{"e":"depthUpdate","E":1618677414823,"s":"ZRXUSD","U":51775904,"u":51775904,"b":[],"a":[["2.0888","0.00000000"]]}}
1618677414.8078148: {"stream":"omgusd@bookTicker","data":{"u":66532572,"s":"OMGUSD","b":"9.5422","B":"209.31000000","a":"9.5622","A":"3094.65000000"}}
1618677414.807899: {"stream":"btcusdt@bookTicker","data":{"u":372026834,"s":"BTCUSDT","b":"60497.55000000","B":"0.00604200","a":"60516.40000000","A":"0.00622900"}}
1618677414.901263: {"stream":"ethbusd@depth@100ms","data":{"e":"depthUpdate","E":1618677414923,"s":"ETHBUSD","U":56401182,"u":56401185,"b":[["2356.36000000","0.05400000"],["2354.71000000","0.17700000"],["2354.02000000","0.00000000"],["2350.48000000","0.00000000"]],"a":[]}}
1618677414.9014668: {"stream":"btcusdt@depth@100ms","data":{"e":"depthUpdate","E":1618677414923,"s":"BTCUSDT","U":372026833,"u":372026834,"b":[["60497.55000000","0.00604200"],["60496.60000000","0.00000000"]],"a":[]}}
1618677414.901574: {"stream":"omgusd@depth@100ms","data":{"e":"depthUpdate","E":1618677414923,"s":"OMGUSD","U":66532572,"u":66532572,"b":[],"a":[["9.5584","0.00000000"]]}}
1618677415.002143: {"stream":"ethbusd@depth@100ms","data":{"e":"depthUpdate","E":1618677415023,"s":"ETHBUSD","U":56401186,"u":56401186,"b":[["2302.16000000","0.01025000"]],"a":[]}}
1618677415.104167: {"stream":"xlmusdt@depth@100ms","data":{"e":"depthUpdate","E":1618677415123,"s":"XLMUSDT","U":134557807,"u":134557807,"b":[["0.60048000","404.60000000"]],"a":[]}}
1618677415.104325: {"stream":"bchusdt@depth@100ms","data":{"e":"depthUpdate","E":1618677415123,"s":"BCHUSDT","U":123518039,"u":123518039,"b":[],"a":[["1056.70000000","1.42185000"]]}}
1618677415.177184: {"stream":"ethbusd@bookTicker","data":{"u":56401187,"s":"ETHBUSD","b":"2360.64000000","B":"0.60145000","a":"2365.13000000","A":"0.13108000"}}
1618677415.191108: {"stream":"btcusdt@bookTicker","data":{"u":372026839,"s":"BTCUSDT","b":"60499.15000000","B":"0.09909500","a":"60516.40000000","A":"0.00622900"}}
1618677415.2021701: {"stream":"btcusdt@depth@100ms","data":{"e":"depthUpdate","E":1618677415223,"s":"BTCUSDT","U":372026835,"u":372026839,"b":[["60499.15000000","0.09909500"],["60493.24000000","0.00000000"],["60489.07000000","0.13212800"],["60470.61000000","0.00000000"],["60466.93000000","0.00000000"]],"a":[]}}
1618677415.2023869: {"stream":"ethbusd@depth@100ms","data":{"e":"depthUpdate","E":1618677415223,"s":"ETHBUSD","U":56401187,"u":56401187,"b":[["2360.64000000","0.60145000"]],"a":[]}}
1618677415.208458: {"stream":"ethbusd@bookTicker","data":{"u":56401188,"s":"ETHBUSD","b":"2360.64000000","B":"0.50000000","a":"2365.13000000","A":"0.13108000"}}
1618677415.208543: {"stream":"btcusdt@bookTicker","data":{"u":372026841,"s":"BTCUSDT","b":"60499.16000000","B":"0.00604200","a":"60516.40000000","A":"0.00622900"}}
1618677415.210718: {"stream":"bchusdt@bookTicker","data":{"u":123518042,"s":"BCHUSDT","b":"1051.92000000","B":"0.42558000","a":"1054.36000000","A":"0.78808000"}}
1618677415.210803: {"stream":"bchusdt@bookTicker","data":{"u":123518043,"s":"BCHUSDT","b":"1052.83000000","B":"0.89975000","a":"1054.36000000","A":"0.78808000"}}
1618677415.302319: {"stream":"ethbusd@depth@100ms","data":{"e":"depthUpdate","E":1618677415323,"s":"ETHBUSD","U":56401188,"u":56401188,"b":[["2360.64000000","0.50000000"]],"a":[]}}
1618677415.3024518: {"stream":"xlmusdt@depth@100ms","data":{"e":"depthUpdate","E":1618677415323,"s":"XLMUSDT","U":134557808,"u":134557811,"b":[["0.59942000","3460.00000000"],["0.59897000","0.00000000"]],"a":[["0.60261000","3460.00000000"],["0.60335000","12118.00000000"]]}}
1618677415.30259: {"stream":"btcusdt@depth@100ms","data":{"e":"depthUpdate","E":1618677415323,"s":"BTCUSDT","U":372026840,"u":372026842,"b":[["60499.16000000","0.00604200"],["60497.55000000","0.00000000"],["60480.01000000","0.08000000"]],"a":[]}}
1618677415.302651: {"stream":"bchusdt@depth@100ms","data":{"e":"depthUpdate","E":1618677415323,"s":"BCHUSDT","U":123518040,"u":123518045,"b":[["1052.83000000","0.89975000"],["1050.60000000","2.00724000"],["1026.18000000","0.00000000"]],"a":[["1053.82000000","0.00000000"],["1077.40000000","9.96762000"],["1131.87000000","15.61625000"]]}}
1618677415.311593: {"stream":"ethbusd@bookTicker","data":{"u":56401189,"s":"ETHBUSD","b":"2360.65000000","B":"0.10131000","a":"2365.13000000","A":"0.13108000"}}
1618677415.367866: {"stream":"omgusd@bookTicker","data":{"u":66532573,"s":"OMGUSD","b":"9.5422","B":"209.31000000","a":"9.5621","A":"80.00000000"}}
1618677415.402974: {"stream":"ethbusd@depth@100ms","data":{"e":"depthUpdate","E":1618677415423,"s":"ETHBUSD","U":56401189,"u":56401189,"b":[["2360.65000000","0.10131000"]],"a":[]}}
1618677415.403119: {"stream":"xlmusdt@depth@100ms","data":{"e":"depthUpdate","E":1618677415423,"s":"XLMUSDT","U":134557812,"u":134557812,"b":[],"a":[["0.60256000","3318.90000000"]]}}
1618677415.403195: {"stream":"bchusdt@depth@100ms","data":{"e":"depthUpdate","E":1618677415423,"s":"BCHUSDT","U":123518046,"u":123518047,"b":[["1051.92000000","0.00000000"],["1051.02000000","0.00000000"]],"a":[]}}
1618677415.403281: {"stream":"omgusd@depth@100ms","data":{"e":"depthUpdate","E":1618677415423,"s":"OMGUSD","U":66532573,"u":66532573,"b":[],"a":[["9.5621","80.00000000"]]}}
1618677415.411048: {"stream":"bchusdt@bookTicker","data":{"u":123518048,"s":"BCHUSDT","b":"1052.84000000","B":"0.42531000","a":"1054.36000000","A":"0.78808000"}}
1618677415.501552: {"stream":"bchusdt@depth@100ms","data":{"e":"depthUpdate","E":1618677415523,"s":"BCHUSDT","U":123518048,"u":123518048,"b":[["1052.84000000","0.42531000"]],"a":[]}}
1618677415.501704: {"stream":"omgusd@depth@100ms","data":{"e":"depthUpdate","E":1618677415523,"s":"OMGUSD","U":66532574,"u":66532574,"b":[],"a":[["9.5622","0.00000000"]]}}
1618677415.602706: {"stream":"btcusdt@depth@100ms","data":{"e":"depthUpdate","E":1618677415624,"s":"BTCUSDT","U":372026843,"u":372026843,"b":[],"a":[["60632.80000000","0.71722600"]]}}
1618677415.6028621: {"stream":"bchusdt@depth@100ms","data":{"e":"depthUpdate","E":1618677415624,"s":"BCHUSDT","U":123518049,"u":123518049,"b":[["1051.22000000","0.00000000"]],"a":[]}}
1618677415.704514: {"stream":"busdusd@depth@100ms","data":{"e":"depthUpdate","E":1618677415724,"s":"BUSDUSD","U":4191926,"u":4191929,"b":[],"a":[["1.0002","573574.76000000"],["1.0003","131.06000000"],["1.0004","613359.69000000"]]}}
1618677415.7407439: {"stream":"atomusdt@depth@100ms","data":{"e":"depthUpdate","E":1618677415724,"s":"ATOMUSDT","U":71292128,"u":71292128,"b":[["25.07500000","0.97800000"]],"a":[]}}
1618677415.740812: {"stream":"btcusdt@depth@100ms","data":{"e":"depthUpdate","E":1618677415724,"s":"BTCUSDT","U":372026844,"u":372026844,"b":[["60454.75000000","0.02097700"]],"a":[]}}
1618677415.740854: {"stream":"bchusdt@depth@100ms","data":{"e":"depthUpdate","E":1618677415724,"s":"BCHUSDT","U":123518050,"u":123518051,"b":[["1051.92000000","0.91485000"],["1046.39000000","0.84110000"]],"a":[]}}
1618677415.740897: {"stream":"zrxusd@bookTicker","data":{"u":51775905,"s":"ZRXUSD","b":"2.0821","B":"719.72000000","a":"2.0889","A":"495.00000000"}}
1618677415.740919: {"stream":"omgusd@bookTicker","data":{"u":66532575,"s":"OMGUSD","b":"9.5422","B":"209.31000000","a":"9.5652","A":"209.37000000"}}
1618677415.740936: {"stream":"zrxusd@bookTicker","data":{"u":51775906,"s":"ZRXUSD","b":"2.0821","B":"719.72000000","a":"2.0876","A":"719.00000000"}}
1618677415.74095: {"stream":"xlmusdt@bookTicker","data":{"u":134557814,"s":"XLMUSDT","b":"0.60130000","B":"1416.30000000","a":"0.60170000","A":"3570.60000000"}}
1618677415.7409651: {"stream":"xlmusdt@bookTicker","data":{"u":134557815,"s":"XLMUSDT","b":"0.60130000","B":"1416.30000000","a":"0.60216000","A":"6157.20000000"}}
1618677415.803261: {"stream":"xlmusdt@depth@100ms","data":{"e":"depthUpdate","E":1618677415824,"s":"XLMUSDT","U":134557813,"u":134557816,"b":[["0.60130000","1416.30000000"],["0.58600000","0.00000000"]],"a":[["0.60170000","0.00000000"],["0.60937000","8698.80000000"]]}}
1618677415.803402: {"stream":"omgusd@depth@100ms","data":{"e":"depthUpdate","E":1618677415824,"s":"OMGUSD","U":66532575,"u":66532575,"b":[],"a":[["9.5621","0.00000000"]]}}
1618677415.803453: {"stream":"btcusdt@depth@100ms","data":{"e":"depthUpdate","E":1618677415824,"s":"BTCUSDT","U":372026845,"u":372026846,"b":[["60490.81000000","0.07784100"],["59955.95000000","0.00000000"]],"a":[]}}
1618677415.803505: {"stream":"zrxusd@depth@100ms","data":{"e":"depthUpdate","E":1618677415824,"s":"ZRXUSD","U":51775905,"u":51775906,"b":[],"a":[["2.0869","0.00000000"],["2.0876","719.00000000"]]}}
1618677415.8107321: {"stream":"ethbusd@bookTicker","data":{"u":56401190,"s":"ETHBUSD","b":"2360.65000000","B":"0.10131000","a":"2365.13000000","A":"0.63108000"}}
1618677415.8289301: {"stream":"btcusdt@bookTicker","data":{"u":372026851,"s":"BTCUSDT","b":"60499.16000000","B":"0.00604200","a":"60516.41000000","A":"0.08705600"}}
1618677415.904477: {"stream":"ethbusd@depth@100ms","data":{"e":"depthUpdate","E":1618677415925,"s":"ETHBUSD","U":56401190,"u":56401190,"b":[],"a":[["2365.13000000","0.63108000"]]}}
1618677415.904608: {"stream":"xlmusdt@depth@100ms","data":{"e":"depthUpdate","E":1618677415926,"s":"XLMUSDT","U":134557817,"u":134557817,"b":[["0.60048000","0.00000000"]],"a":[]}}
1618677415.9046981: {"stream":"btcusdt@depth@100ms","data":{"e":"depthUpdate","E":1618677415926,"s":"BTCUSDT","U":372026847,"u":372026851,"b":[["60474.13000000","0.98275800"]],"a":[["60516.40000000","0.00000000"],["60521.99000000","0.00588100"],["60527.24000000","0.00000000"],["62215.30000000","3.46253700"]]}}
1618677415.932012: {"stream":"omgusd@bookTicker","data":{"u":66532576,"s":"OMGUSD","b":"9.5422","B":"209.31000000","a":"9.5621","A":"50.00000000"}}
1618677416.003149: {"stream":"busdusd@depth@100ms","data":{"e":"depthUpdate","E":1618677416024,"s":"BUSDUSD","U":4191930,"u":4191931,"b":[],"a":[["1.0003","10131.06000000"],["1.0004","633359.69000000"]]}}
1618677416.003288: {"stream":"btcusdt@depth@100ms","data":{"e":"depthUpdate","E":1618677416024,"s":"BTCUSDT","U":372026852,"u":372026853,"b":[],"a":[["60540.02000000","0.08000000"],["60673.25000000","0.00000000"]]}}
1618677416.0033998: {"stream":"zrxusd@depth@100ms","data":{"e":"depthUpdate","E":1618677416024,"s":"ZRXUSD","U":51775907,"u":51775907,"b":[],"a":[["2.0942","0.00000000"]]}}
1618677416.003445: {"stream":"bchusdt@depth@100ms","data":{"e":"depthUpdate","E":1618677416024,"s":"BCHUSDT","U":123518052,"u":123518052,"b":[["1045.68000000","0.00000000"]],"a":[]}}
1618677416.0034828: {"stream":"omgusd@depth@100ms","data":{"e":"depthUpdate","E":1618677416024,"s":"OMGUSD","U":66532576,"u":66532576,"b":[],"a":[["9.5621","50.00000000"]]}}
1618677416.011169: {"stream":"bchusdt@bookTicker","data":{"u":123518053,"s":"BCHUSDT","b":"1052.83000000","B":"0.89975000","a":"1054.36000000","A":"0.78808000"}}
1618677416.102255: {"stream":"bchusdt@depth@100ms","data":{"e":"depthUpdate","E":1618677416124,"s":"BCHUSDT","U":123518053,"u":123518054,"b":[["1052.84000000","0.00000000"]],"a":[["1055.25000000","0.42340000"]]}}
1618677416.203604: {"stream":"bchusdt@depth@100ms","data":{"e":"depthUpdate","E":1618677416224,"s":"BCHUSDT","U":123518055,"u":123518057,"b":[["1051.93000000","0.42340000"]],"a":[["1055.00000000","0.09948000"],["1055.25000000","0.00000000"]]}}
1618677416.303147: {"stream":"zrxusd@depth@100ms","data":{"e":"depthUpdate","E":1618677416324,"s":"ZRXUSD","U":51775908,"u":51775908,"b":[],"a":[["2.0948","634.63000000"]]}}
1618677416.303296: {"stream":"bchusdt@depth@100ms","data":{"e":"depthUpdate","E":1618677416324,"s":"BCHUSDT","U":123518058,"u":123518058,"b":[],"a":[["1055.01000000","0.00000000"]]}}
1618677416.833867: {"stream":"zrxusd@depth@100ms","data":{"e":"depthUpdate","E":1618677416824,"s":"ZRXUSD","U":51775909,"u":51775909,"b":[],"a":[["2.0948","0.00000000"]]}}
1618677416.8340192: {"stream":"btcusdt@depth@100ms","data":{"e":"depthUpdate","E":1618677416824,"s":"BTCUSDT","U":372026854,"u":372026854,"b":[["60328.17000000","0.00000000"]],"a":[]}}
1618677416.8341079: {"stream":"btcusdt@bookTicker","data":{"u":372026856,"s":"BTCUSDT","b":"60499.16000000","B":"0.00604200","a":"60516.40000000","A":"0.00599600"}}
1618677416.9038458: {"stream":"btcusdt@depth@100ms","data":{"e":"depthUpdate","E":1618677416924,"s":"BTCUSDT","U":372026855,"u":372026856,"b":[],"a":[["60516.40000000","0.00599600"],["60521.99000000","0.00000000"]]}}
1618677417.0029929: {"stream":"btcusdt@depth@100ms","data":{"e":"depthUpdate","E":1618677417024,"s":"BTCUSDT","U":372026857,"u":372026858,"b":[],"a":[["60540.08000000","0.00000000"],["60560.92000000","0.00866000"]]}}
1618677417.104196: {"stream":"bchusdt@depth@100ms","data":{"e":"depthUpdate","E":1618677417125,"s":"BCHUSDT","U":123518059,"u":123518059,"b":[],"a":[["1058.56000000","3.49234000"]]}}
1618677417.206872: {"stream":"bchusdt@depth@100ms","data":{"e":"depthUpdate","E":1618677417225,"s":"BCHUSDT","U":123518060,"u":123518061,"b":[["1052.74000000","0.94772000"],["1051.91000000","0.00000000"]],"a":[]}}
1618677417.207466: {"stream":"bchusdt@bookTicker","data":{"u":123518063,"s":"BCHUSDT","b":"1052.83000000","B":"0.89975000","a":"1055.00000000","A":"0.09948000"}}
1618677417.304179: {"stream":"zrxusd@depth@100ms","data":{"e":"depthUpdate","E":1618677417325,"s":"ZRXUSD","U":51775910,"u":51775910,"b":[],"a":[["2.0949","653.63000000"]]}}
1618677417.304333: {"stream":"bchusdt@depth@100ms","data":{"e":"depthUpdate","E":1618677417325,"s":"BCHUSDT","U":123518062,"u":123518065,"b":[["1052.02000000","2.20441000"],["1051.93000000","0.00000000"],["1027.52000000","0.00000000"]],"a":[["1054.36000000","0.00000000"]]}}
1618677417.309728: {"stream":"bchusdt@bookTicker","data":{"u":123518066,"s":"BCHUSDT","b":"1052.83000000","B":"0.89975000","a":"1055.26000000","A":"0.90017000"}}
1618677417.311886: {"stream":"bchusdt@bookTicker","data":{"u":123518068,"s":"BCHUSDT","b":"1052.84000000","B":"0.41932000","a":"1055.26000000","A":"0.90017000"}}
1618677417.4033: {"stream":"xlmusdt@depth@100ms","data":{"e":"depthUpdate","E":1618677417425,"s":"XLMUSDT","U":134557818,"u":134557821,"b":[["0.60090000","0.00000000"],["0.60065000","20000.00000000"]],"a":[["0.60244000","0.00000000"],["0.60274000","3318.00000000"]]}}
1618677417.403509: {"stream":"bchusdt@depth@100ms","data":{"e":"depthUpdate","E":1618677417425,"s":"BCHUSDT","U":123518066,"u":123518068,"b":[["1052.84000000","0.41932000"]],"a":[["1055.00000000","0.00000000"],["1055.90000000","0.41932000"]]}}
1618677417.49002: {"stream":"zenusd@bookTicker","data":{"u":6596080,"s":"ZENUSD","b":"121.3330","B":"6.93500000","a":"121.6900","A":"3.14000000"}}
1618677417.491904: {"stream":"zrxusd@bookTicker","data":{"u":51775911,"s":"ZRXUSD","b":"2.0821","B":"719.72000000","a":"2.0889","A":"495.00000000"}}
1618677417.505179: {"stream":"zrxusd@depth@100ms","data":{"e":"depthUpdate","E":1618677417525,"s":"ZRXUSD","U":51775911,"u":51775911,"b":[],"a":[["2.0876","0.00000000"]]}}
1618677417.505332: {"stream":"zenusd@depth@100ms","data":{"e":"depthUpdate","E":1618677417525,"s":"ZENUSD","U":6596079,"u":6596080,"b":[["121.3330","6.93500000"],["113.5660","0.00000000"]],"a":[]}}
1618677417.505445: {"stream":"xlmusdt@depth@100ms","data":{"e":"depthUpdate","E":1618677417525,"s":"XLMUSDT","U":134557822,"u":134557826,"b":[["0.60103000","0.00000000"],["0.60091000","404.60000000"],["0.60043000","0.00000000"]],"a":[["0.60256000","0.00000000"],["0.60274000","0.00000000"]]}}
1618677417.5055292: {"stream":"btcusdt@depth@100ms","data":{"e":"depthUpdate","E":1618677417525,"s":"BTCUSDT","U":372026859,"u":372026859,"b":[],"a":[["60523.38000000","0.00000000"]]}}
1618677417.55064: {"stream":"zrxusd@bookTicker","data":{"u":51775912,"s":"ZRXUSD","b":"2.0821","B":"719.72000000","a":"2.0883","A":"718.87000000"}}
1618677417.59701: {"stream":"xlmusdt@bookTicker","data":{"u":134557828,"s":"XLMUSDT","b":"0.60130000","B":"1416.30000000","a":"0.60261000","A":"3460.00000000"}}
1618677417.603211: {"stream":"zrxusd@depth@100ms","data":{"e":"depthUpdate","E":1618677417625,"s":"ZRXUSD","U":51775912,"u":51775912,"b":[],"a":[["2.0883","718.87000000"]]}}
1618677417.603366: {"stream":"zenusd@depth@100ms","data":{"e":"depthUpdate","E":1618677417625,"s":"ZENUSD","U":6596081,"u":6596081,"b":[["121.0370","0.00000000"]],"a":[]}}
1618677417.604286: {"stream":"ethbusd@depth@100ms","data":{"e":"depthUpdate","E":1618677417626,"s":"ETHBUSD","U":56401191,"u":56401191,"b":[],"a":[["2365.76000000","0.00000000"]]}}
1618677417.604426: {"stream":"atomusdt@depth@100ms","data":{"e":"depthUpdate","E":1618677417625,"s":"ATOMUSDT","U":71292129,"u":71292130,"b":[],"a":[["25.20600000","30.39700000"],["25.22300000","39.64900000"]]}}
1618677417.604513: {"stream":"xlmusdt@depth@100ms","data":{"e":"depthUpdate","E":1618677417626,"s":"XLMUSDT","U":134557827,"u":134557828,"b":[["0.60065000","0.00000000"]],"a":[["0.60216000","0.00000000"]]}}
1618677417.604861: {"stream":"btcusdt@depth@100ms","data":{"e":"depthUpdate","E":1618677417626,"s":"BTCUSDT","U":372026860,"u":372026860,"b":[["60454.75000000","0.00000000"]],"a":[]}}
1618677417.609718: {"stream":"ethbusd@bookTicker","data":{"u":56401192,"s":"ETHBUSD","b":"2360.64000000","B":"0.50000000","a":"2365.13000000","A":"0.63108000"}}
1618677417.652255: {"stream":"btcusdt@bookTicker","data":{"u":372026867,"s":"BTCUSDT","b":"60510.07000000","B":"0.02735900","a":"60516.40000000","A":"0.00599600"}}
1618677417.703107: {"stream":"ethbusd@depth@100ms","data":{"e":"depthUpdate","E":1618677417725,"s":"ETHBUSD","U":56401192,"u":56401192,"b":[["2360.65000000","0.00000000"]],"a":[]}}
1618677417.70326: {"stream":"zenusd@depth@100ms","data":{"e":"depthUpdate","E":1618677417725,"s":"ZENUSD","U":6596082,"u":6596082,"b":[["120.8810","0.00000000"]],"a":[]}}
1618677417.703743: {"stream":"xlmusdt@depth@100ms","data":{"e":"depthUpdate","E":1618677417725,"s":"XLMUSDT","U":134557829,"u":134557829,"b":[["0.60091000","0.00000000"]],"a":[]}}
1618677417.7038121: {"stream":"btcusdt@depth@100ms","data":{"e":"depthUpdate","E":1618677417725,"s":"BTCUSDT","U":372026861,"u":372026868,"b":[["60510.07000000","0.02735900"],["60498.76000000","0.07962000"],["60496.59000000","0.00000000"],["60345.53000000","0.00000000"]],"a":[["60516.41000000","0.00000000"],["60522.00000000","0.00000000"],["60524.17000000","0.07966000"],["60528.35000000","0.09909300"]]}}
1618677417.710825: {"stream":"btcusdt@bookTicker","data":{"u":372026869,"s":"BTCUSDT","b":"60510.07000000","B":"0.02735900","a":"60522.23000000","A":"0.09686400"}}
1618677417.710909: {"stream":"btcusdt@bookTicker","data":{"u":372026870,"s":"BTCUSDT","b":"60510.07000000","B":"0.02735900","a":"60522.22000000","A":"0.00583600"}}
1618677417.75749: {"stream":"ethbusd@bookTicker","data":{"u":56401195,"s":"ETHBUSD","b":"2360.64000000","B":"0.50000000","a":"2365.13000000","A":"0.50000000"}}
1618677417.7575738: {"stream":"xlmusdt@bookTicker","data":{"u":134557830,"s":"XLMUSDT","b":"0.60137000","B":"3316.70000000","a":"0.60261000","A":"3460.00000000"}}
1618677417.803647: {"stream":"xlmusdt@depth@100ms","data":{"e":"depthUpdate","E":1618677417825,"s":"XLMUSDT","U":134557830,"u":134557836,"b":[["0.60137000","3316.70000000"],["0.60122000","3317.50000000"]],"a":[["0.60279000","3317.40000000"],["0.60298000","3316.70000000"],["0.60396000","5450.80000000"],["0.60604000","8066.80000000"],["0.60605000","0.00000000"]]}}
1618677417.8038778: {"stream":"btcusdt@depth@100ms","data":{"e":"depthUpdate","E":1618677417825,"s":"BTCUSDT","U":372026869,"u":372026874,"b":[["60480.01000000","0.00000000"],["60426.58000000","0.01000000"]],"a":[["60516.40000000","0.00000000"],["60522.22000000","0.00583600"],["60632.80000000","0.00000000"],["60824.90000000","0.44104800"]]}}
1618677417.804011: {"stream":"ethbusd@depth@100ms","data":{"e":"depthUpdate","E":1618677417825,"s":"ETHBUSD","U":56401193,"u":56401196,"b":[["2359.89000000","0.00000000"]],"a":[["2365.13000000","0.50000000"],["2366.21000000","0.13663000"],["2366.22000000","0.00000000"]]}}
1618677417.8040771: {"stream":"bchusdt@depth@100ms","data":{"e":"depthUpdate","E":1618677417825,"s":"BCHUSDT","U":123518069,"u":123518070,"b":[["1051.92000000","0.00000000"]],"a":[["1055.33000000","0.00000000"]]}}
1618677417.863435: {"stream":"xlmusdt@bookTicker","data":{"u":134557837,"s":"XLMUSDT","b":"0.60130000","B":"1416.30000000","a":"0.60261000","A":"3460.00000000"}}
1618677417.896048: {"stream":"ethbusd@bookTicker","data":{"u":56401199,"s":"ETHBUSD","b":"2361.05000000","B":"0.84614000","a":"2365.13000000","A":"0.50000000"}}
1618677417.905351: {"stream":"zenusd@depth@100ms","data":{"e":"depthUpdate","E":1618677417926,"s":"ZENUSD","U":6596083,"u":6596084,"b":[["121.2730","16.45100000"],["121.1720","16.45100000"]],"a":[]}}
1618677417.9055412: {"stream":"atomusdt@depth@100ms","data":{"e":"depthUpdate","E":1618677417926,"s":"ATOMUSDT","U":71292131,"u":71292132,"b":[],"a":[["25.21500000","0.00000000"],["25.25200000","64.80000000"]]}}
1618677417.905625: {"stream":"xlmusdt@depth@100ms","data":{"e":"depthUpdate","E":1618677417926,"s":"XLMUSDT","U":134557837,"u":134557838,"b":[["0.60137000","0.00000000"]],"a":[["0.60279000","0.00000000"]]}}
1618677417.905685: {"stream":"btcusdt@depth@100ms","data":{"e":"depthUpdate","E":1618677417926,"s":"BTCUSDT","U":372026875,"u":372026876,"b":[["60489.12000000","0.08000000"],["60426.58000000","0.00000000"]],"a":[]}}
1618677417.905736: {"stream":"ethbusd@depth@100ms","data":{"e":"depthUpdate","E":1618677417926,"s":"ETHBUSD","U":56401197,"u":56401199,"b":[["2361.05000000","0.84614000"]],"a":[["2366.83000000","0.84625000"],["2367.30000000","0.84609000"]]}}
1618677418.00435: {"stream":"btcusdt@depth@100ms","data":{"e":"depthUpdate","E":1618677418025,"s":"BTCUSDT","U":372026877,"u":372026877,"b":[],"a":[["60531.02000000","0.00000000"]]}}
1618677418.164889: {"stream":"xlmusdt@bookTicker","data":{"u":134557840,"s":"XLMUSDT","b":"0.60130000","B":"1416.30000000","a":"0.60262000","A":"3696.90000000"}}
1618677418.171744: {"stream":"xlmusdt@bookTicker","data":{"u":134557842,"s":"XLMUSDT","b":"0.60139000","B":"3316.40000000","a":"0.60262000","A":"3696.90000000"}}
1618677418.203743: {"stream":"zrxusd@depth@100ms","data":{"e":"depthUpdate","E":1618677418225,"s":"ZRXUSD","U":51775913,"u":51775913,"b":[],"a":[["2.0949","0.00000000"]]}}
1618677418.213583: {"stream":"bchusdt@depth@100ms","data":{"e":"depthUpdate","E":1618677418229,"s":"BCHUSDT","U":123518071,"u":123518074,"b":[["1047.24000000","0.62822000"]],"a":[["1056.67000000","3.03270000"],["1056.89000000","0.00000000"],["1058.55000000","1.17100000"]]}}
1618677418.213801: {"stream":"xlmusdt@depth@100ms","data":{"e":"depthUpdate","E":1618677418229,"s":"XLMUSDT","U":134557839,"u":134557844,"b":[["0.60139000","3316.40000000"],["0.59719000","83759.00000000"],["0.59581000","0.00000000"]],"a":[["0.60261000","0.00000000"],["0.60309000","3316.40000000"],["0.60335000","15578.00000000"]]}}
1618677418.21392: {"stream":"btcusdt@depth@100ms","data":{"e":"depthUpdate","E":1618677418229,"s":"BTCUSDT","U":372026878,"u":372026879,"b":[],"a":[["60552.19000000","0.13212400"],["60662.93000000","0.77774000"]]}}
1618677418.405557: {"stream":"zrxusd@depth@100ms","data":{"e":"depthUpdate","E":1618677418425,"s":"ZRXUSD","U":51775914,"u":51775914,"b":[],"a":[["2.0950","647.70000000"]]}}
1618677418.4057071: {"stream":"atomusdt@depth@100ms","data":{"e":"depthUpdate","E":1618677418425,"s":"ATOMUSDT","U":71292133,"u":71292134,"b":[],"a":[["25.20600000","0.00000000"],["28.02900000","555.59800000"]]}}
1618677418.4058392: {"stream":"btcusdt@depth@100ms","data":{"e":"depthUpdate","E":1618677418425,"s":"BTCUSDT","U":372026880,"u":372026880,"b":[["60489.12000000","0.00000000"]],"a":[]}}
1618677418.5039601: {"stream":"bchusdt@depth@100ms","data":{"e":"depthUpdate","E":1618677418526,"s":"BCHUSDT","U":123518075,"u":123518075,"b":[["1046.39000000","0.00000000"]],"a":[]}}
1618677418.5062258: {"stream":"xlmusdt@depth@100ms","data":{"e":"depthUpdate","E":1618677418526,"s":"XLMUSDT","U":134557845,"u":134557845,"b":[],"a":[["0.60590000","0.00000000"]]}}
1618677418.603235: {"stream":"zenusd@depth@100ms","data":{"e":"depthUpdate","E":1618677418626,"s":"ZENUSD","U":6596085,"u":6596086,"b":[["120.1020","0.00000000"]],"a":[["121.8010","0.00000000"]]}}
1618677418.6034079: {"stream":"xlmusdt@depth@100ms","data":{"e":"depthUpdate","E":1618677418626,"s":"XLMUSDT","U":134557846,"u":134557846,"b":[["0.59582000","0.00000000"]],"a":[]}}
1618677418.603838: {"stream":"bchusdt@depth@100ms","data":{"e":"depthUpdate","E":1618677418626,"s":"BCHUSDT","U":123518076,"u":123518078,"b":[["1052.74000000","0.00000000"],["1051.76000000","0.94857000"]],"a":[["1055.89000000","6.00000000"]]}}
1618677418.707289: {"stream":"zenusd@depth@100ms","data":{"e":"depthUpdate","E":1618677418726,"s":"ZENUSD","U":6596087,"u":6596087,"b":[],"a":[["122.0700","16.45000000"]]}}
1618677418.7074392: {"stream":"ethbusd@depth@100ms","data":{"e":"depthUpdate","E":1618677418726,"s":"ETHBUSD","U":56401200,"u":56401200,"b":[],"a":[["2423.28000000","0.00000000"]]}}
1618677418.707527: {"stream":"xlmusdt@depth@100ms","data":{"e":"depthUpdate","E":1618677418726,"s":"XLMUSDT","U":134557847,"u":134557848,"b":[],"a":[["0.60281000","3317.10000000"],["0.60309000","0.00000000"]]}}
1618677418.707586: {"stream":"btcusdt@depth@100ms","data":{"e":"depthUpdate","E":1618677418726,"s":"BTCUSDT","U":372026881,"u":372026882,"b":[["60481.26000000","0.08000000"],["60395.78000000","0.08631400"]],"a":[]}}
1618677418.7076328: {"stream":"bchusdt@depth@100ms","data":{"e":"depthUpdate","E":1618677418726,"s":"BCHUSDT","U":123518079,"u":123518081,"b":[],"a":[["1055.88000000","0.10420000"],["1055.90000000","0.00000000"],["1055.91000000","0.00000000"]]}}
1618677418.731244: {"stream":"xlmusdt@bookTicker","data":{"u":134557849,"s":"XLMUSDT","b":"0.60130000","B":"1416.30000000","a":"0.60262000","A":"3696.90000000"}}
1618677418.796561: {"stream":"btcusdt@bookTicker","data":{"u":372026884,"s":"BTCUSDT","b":"60499.16000000","B":"0.00604200","a":"60522.22000000","A":"0.00583600"}}
1618677418.7966468: {"stream":"btcusdt@bookTicker","data":{"u":372026885,"s":"BTCUSDT","b":"60506.09000000","B":"0.02373500","a":"60522.22000000","A":"0.00583600"}}
1618677418.8054621: {"stream":"xlmusdt@depth@100ms","data":{"e":"depthUpdate","E":1618677418826,"s":"XLMUSDT","U":134557849,"u":134557849,"b":[["0.60139000","0.00000000"]],"a":[]}}
1618677418.8056252: {"stream":"btcusdt@depth@100ms","data":{"e":"depthUpdate","E":1618677418826,"s":"BTCUSDT","U":372026883,"u":372026886,"b":[["60510.07000000","0.00000000"],["60506.09000000","0.02373500"],["60358.53000000","0.00000000"],["60354.36000000","0.21555600"]],"a":[]}}
1618677418.875903: {"stream":"bchusdt@bookTicker","data":{"u":123518084,"s":"BCHUSDT","b":"1052.84000000","B":"0.41932000","a":"1055.01000000","A":"0.94870000"}}
1618677418.9055932: {"stream":"bchusdt@depth@100ms","data":{"e":"depthUpdate","E":1618677418926,"s":"BCHUSDT","U":123518082,"u":123518085,"b":[],"a":[["1055.01000000","0.94870000"],["1055.28000000","1.42354000"],["1055.89000000","0.00000000"],["1056.70000000","0.00000000"]]}}
1618677418.905792: {"stream":"omgusd@depth@100ms","data":{"e":"depthUpdate","E":1618677418926,"s":"OMGUSD","U":66532577,"u":66532578,"b":[["9.4987","1040.20000000"],["9.4849","0.00000000"]],"a":[]}}
1618677419.0052512: {"stream":"bchusdt@depth@100ms","data":{"e":"depthUpdate","E":1618677419026,"s":"BCHUSDT","U":123518086,"u":123518088,"b":[],"a":[["1055.25000000","0.41583000"],["1055.87000000","6.00000000"],["1055.88000000","0.00000000"]]}}
1618677419.005436: {"stream":"xlmusdt@depth@100ms","data":{"e":"depthUpdate","E":1618677419026,"s":"XLMUSDT","U":134557850,"u":134557850,"b":[],"a":[["0.60643000","292969.00000000"]]}}
1618677419.005523: {"stream":"btcusdt@depth@100ms","data":{"e":"depthUpdate","E":1618677419026,"s":"BTCUSDT","U":372026887,"u":372026887,"b":[["60433.50000000","0.01000000"]],"a":[]}}
1618677419.098349: {"stream":"zrxusd@bookTicker","data":{"u":51775915,"s":"ZRXUSD","b":"2.0821","B":"1078.94000000","a":"2.0883","A":"718.87000000"}}
1618677419.1064918: {"stream":"zrxusd@depth@100ms","data":{"e":"depthUpdate","E":1618677419127,"s":"ZRXUSD","U":51775915,"u":51775915,"b":[["2.0821","1078.94000000"]],"a":[]}}
1618677419.205776: {"stream":"bchusdt@depth@100ms","data":{"e":"depthUpdate","E":1618677419226,"s":"BCHUSDT","U":123518089,"u":123518089,"b":[],"a":[["1055.87000000","0.00000000"]]}}
1618677419.226061: {"stream":"bchusdt@bookTicker","data":{"u":123518096,"s":"BCHUSDT","b":"1052.84000000","B":"0.41932000","a":"1054.45000000","A":"0.70085000"}}
1618677419.248511: {"stream":"zenusd@bookTicker","data":{"u":6596088,"s":"ZENUSD","b":"121.3330","B":"6.93500000","a":"121.7220","A":"56.48600000"}}
1618677419.308042: {"stream":"zenusd@depth@100ms","data":{"e":"depthUpdate","E":1618677419329,"s":"ZENUSD","U":6596088,"u":6596089,"b":[],"a":[["121.6900","0.00000000"],["121.9280","11.22000000"]]}}
1618677419.308203: {"stream":"xlmusdt@depth@100ms","data":{"e":"depthUpdate","E":1618677419329,"s":"XLMUSDT","U":134557851,"u":134557853,"b":[["0.60110000","3317.20000000"]],"a":[["0.60266000","3317.70000000"],["0.60298000","0.00000000"]]}}
1618677419.30834: {"stream":"bchusdt@depth@100ms","data":{"e":"depthUpdate","E":1618677419329,"s":"BCHUSDT","U":123518090,"u":123518097,"b":[["1052.83000000","0.00000000"],["1052.02000000","0.00000000"],["1028.76000000","9.06555000"],["1027.42000000","11.74308000"]],"a":[["1054.45000000","0.70085000"],["1055.24000000","6.00000000"],["1131.87000000","0.00000000"]]}}
1618677419.315669: {"stream":"bchusdt@bookTicker","data":{"u":123518099,"s":"BCHUSDT","b":"1051.76000000","B":"0.94857000","a":"1054.45000000","A":"0.70085000"}}
1618677419.401621: {"stream":"zenusd@bookTicker","data":{"u":6596090,"s":"ZENUSD","b":"121.2730","B":"16.45100000","a":"121.7220","A":"56.48600000"}}
1618677419.420916: {"stream":"zenusd@depth@100ms","data":{"e":"depthUpdate","E":1618677419426,"s":"ZENUSD","U":6596090,"u":6596090,"b":[["121.3330","0.00000000"]],"a":[]}}
1618677419.421094: {"stream":"bchusdt@depth@100ms","data":{"e":"depthUpdate","E":1618677419426,"s":"BCHUSDT","U":123518098,"u":123518100,"b":[["1052.84000000","0.00000000"]],"a":[["1055.00000000","0.10748000"],["1055.25000000","0.00000000"]]}}
1618677419.4212081: {"stream":"btcusdt@depth@100ms","data":{"e":"depthUpdate","E":1618677419426,"s":"BTCUSDT","U":372026888,"u":372026888,"b":[],"a":[["60540.01000000","0.02097500"]]}}
1618677419.421567: {"stream":"bchusdt@bookTicker","data":{"u":123518102,"s":"BCHUSDT","b":"1051.77000000","B":"0.41583000","a":"1054.45000000","A":"0.70085000"}}
1618677419.425591: {"stream":"bchusdt@bookTicker","data":{"u":123518103,"s":"BCHUSDT","b":"1051.77000000","B":"0.41583000","a":"1054.44000000","A":"0.41583000"}}
1618677419.506003: {"stream":"zrxusd@depth@100ms","data":{"e":"depthUpdate","E":1618677419528,"s":"ZRXUSD","U":51775916,"u":51775917,"b":[["2.0792","237.18000000"]],"a":[["2.0928","40.00000000"]]}}
1618677419.506146: {"stream":"bchusdt@depth@100ms","data":{"e":"depthUpdate","E":1618677419528,"s":"BCHUSDT","U":123518101,"u":123518103,"b":[["1051.77000000","0.41583000"]],"a":[["1054.44000000","0.41583000"],["1055.00000000","0.00000000"]]}}
1618677419.605254: {"stream":"zenusd@depth@100ms","data":{"e":"depthUpdate","E":1618677419626,"s":"ZENUSD","U":6596091,"u":6596094,"b":[["121.2370","6.48000000"],["120.2480","9.06800000"],["113.9710","0.00000000"],["113.8990","108.04300000"]],"a":[]}}
1618677419.605449: {"stream":"xlmusdt@depth@100ms","data":{"e":"depthUpdate","E":1618677419626,"s":"XLMUSDT","U":134557854,"u":134557854,"b":[["0.59355000","37.00000000"]],"a":[]}}
1618677419.60554: {"stream":"zrxusd@depth@100ms","data":{"e":"depthUpdate","E":1618677419626,"s":"ZRXUSD","U":51775918,"u":51775919,"b":[["2.0803","2000.00000000"]],"a":[["2.0939","2000.00000000"]]}}
1618677419.632712: {"stream":"bchusdt@bookTicker","data":{"u":123518104,"s":"BCHUSDT","b":"1051.77000000","B":"0.41583000","a":"1054.43000000","A":"0.91608000"}}
1618677419.704503: {"stream":"ethbusd@depth@100ms","data":{"e":"depthUpdate","E":1618677419726,"s":"ETHBUSD","U":56401201,"u":56401201,"b":[],"a":[["2424.31000000","0.01025000"]]}}
1618677419.704656: {"stream":"atomusdt@depth@100ms","data":{"e":"depthUpdate","E":1618677419726,"s":"ATOMUSDT","U":71292135,"u":71292138,"b":[],"a":[["25.20500000","0.00000000"],["25.20800000","39.67300000"],["25.22300000","0.00000000"],["25.23100000","19.80000000"]]}}
1618677419.704791: {"stream":"bchusdt@depth@100ms","data":{"e":"depthUpdate","E":1618677419726,"s":"BCHUSDT","U":123518104,"u":123518104,"b":[],"a":[["1054.43000000","0.91608000"]]}}
1618677419.712663: {"stream":"bchusdt@bookTicker","data":{"u":123518105,"s":"BCHUSDT","b":"1051.77000000","B":"0.41583000","a":"1054.42000000","A":"0.10760000"}}
1618677419.768358: {"stream":"xlmusdt@bookTicker","data":{"u":134557857,"s":"XLMUSDT","b":"0.60130000","B":"1416.30000000","a":"0.60250000","A":"3318.50000000"}}
1618677419.805275: {"stream":"ethbusd@depth@100ms","data":{"e":"depthUpdate","E":1618677419826,"s":"ETHBUSD","U":56401202,"u":56401203,"b":[],"a":[["2366.25000000","0.84629000"],["2367.30000000","0.00000000"]]}}
1618677419.8054469: {"stream":"xlmusdt@depth@100ms","data":{"e":"depthUpdate","E":1618677419826,"s":"XLMUSDT","U":134557855,"u":134557858,"b":[["0.60122000","0.00000000"],["0.60090000","3318.20000000"]],"a":[["0.60250000","3318.50000000"],["0.60281000","0.00000000"]]}}
1618677419.805587: {"stream":"bchusdt@depth@100ms","data":{"e":"depthUpdate","E":1618677419826,"s":"BCHUSDT","U":123518105,"u":123518111,"b":[["1051.76000000","0.00000000"],["1051.48000000","0.00000000"],["1050.86000000","0.94927000"],["1050.24000000","1.42395000"]],"a":[["1054.42000000","0.10760000"],["1054.44000000","0.00000000"],["1055.24000000","0.00000000"]]}}
1618677419.8425221: {"stream":"btcusdt@bookTicker","data":{"u":372026891,"s":"BTCUSDT","b":"60506.09000000","B":"0.02373500","a":"60521.83000000","A":"0.07974000"}}
1618677419.892587: {"stream":"btcusdt@bookTicker","data":{"u":372026894,"s":"BTCUSDT","b":"60506.09000000","B":"0.02373500","a":"60522.22000000","A":"0.00583600"}}
1618677419.8954408: {"stream":"zrxusd@bookTicker","data":{"u":51775920,"s":"ZRXUSD","b":"2.0821","B":"719.72000000","a":"2.0883","A":"718.87000000"}}
1618677419.907825: {"stream":"btcusdt@depth@100ms","data":{"e":"depthUpdate","E":1618677419929,"s":"BTCUSDT","U":372026889,"u":372026897,"b":[["60499.15000000","0.00000000"],["60498.76000000","0.00000000"],["60496.41000000","0.00000000"],["60433.50000000","0.00000000"]],"a":[["60521.83000000","0.00000000"],["60524.17000000","0.00000000"],["60528.35000000","0.00000000"]]}}
1618677419.908052: {"stream":"zrxusd@depth@100ms","data":{"e":"depthUpdate","E":1618677419929,"s":"ZRXUSD","U":51775920,"u":51775920,"b":[["2.0821","719.72000000"]],"a":[]}}
1618677419.9081411: {"stream":"bchusdt@depth@100ms","data":{"e":"depthUpdate","E":1618677419929,"s":"BCHUSDT","U":123518112,"u":123518113,"b":[],"a":[["1055.01000000","0.00000000"],["1055.07000000","6.00000000"]]}}
1618677419.924133: {"stream":"btcusdt@bookTicker","data":{"u":372026899,"s":"BTCUSDT","b":"60506.09000000","B":"0.02373500","a":"60517.09000000","A":"0.08040000"}}
1618677420.005035: {"stream":"xlmusdt@depth@100ms","data":{"e":"depthUpdate","E":1618677420027,"s":"XLMUSDT","U":134557859,"u":134557859,"b":[["0.60110000","0.00000000"]],"a":[]}}
1618677420.005142: {"stream":"btcusdt@depth@100ms","data":{"e":"depthUpdate","E":1618677420027,"s":"BTCUSDT","U":372026898,"u":372026904,"b":[["60491.68000000","0.08016000"],["60489.07000000","0.00000000"],["60470.97000000","0.13213800"]],"a":[["60517.09000000","0.08040000"],["60523.17000000","0.09910300"],["60533.35000000","0.13213800"],["60552.19000000","0.00000000"]]}}
1618677420.015153: {"stream":"btcusdt@bookTicker","data":{"u":372026905,"s":"BTCUSDT","b":"60506.09000000","B":"0.02373500","a":"60517.08000000","A":"0.00565900"}}
1618677420.107546: {"stream":"zenusd@depth@100ms","data":{"e":"depthUpdate","E":1618677420127,"s":"ZENUSD","U":6596095,"u":6596096,"b":[],"a":[["121.8140","16.46000000"],["122.0700","0.00000000"]]}}
1618677420.1077209: {"stream":"btcusdt@depth@100ms","data":{"e":"depthUpdate","E":1618677420127,"s":"BTCUSDT","U":372026905,"u":372026908,"b":[["60481.26000000","0.00000000"]],"a":[["60517.08000000","0.00565900"],["60522.22000000","0.00000000"],["60540.02000000","0.00000000"]]}}
1618677420.107847: {"stream":"bchusdt@depth@100ms","data":{"e":"depthUpdate","E":1618677420127,"s":"BCHUSDT","U":123518114,"u":123518116,"b":[],"a":[["1055.07000000","0.00000000"],["1056.66000000","1.17100000"],["1058.55000000","0.00000000"]]}}
1618677420.1773891: {"stream":"ethbusd@bookTicker","data":{"u":56401204,"s":"ETHBUSD","b":"2361.05000000","B":"0.84614000","a":"2365.13000000","A":"1.80000000"}}
1618677420.1892228: {"stream":"ethbusd@bookTicker","data":{"u":56401205,"s":"ETHBUSD","b":"2361.05000000","B":"0.84614000","a":"2365.12000000","A":"1.30000000"}}
1618677420.198168: {"stream":"ethbusd@bookTicker","data":{"u":56401206,"s":"ETHBUSD","b":"2360.64000000","B":"0.50000000","a":"2365.12000000","A":"1.30000000"}}
1618677420.19825: {"stream":"ethbusd@bookTicker","data":{"u":56401207,"s":"ETHBUSD","b":"2360.64000000","B":"0.50000000","a":"2365.13000000","A":"1.80000000"}}
1618677420.205801: {"stream":"zenusd@depth@100ms","data":{"e":"depthUpdate","E":1618677420227,"s":"ZENUSD","U":6596097,"u":6596097,"b":[],"a":[["121.9280","8.08000000"]]}}
1618677420.2059379: {"stream":"ethbusd@depth@100ms","data":{"e":"depthUpdate","E":1618677420227,"s":"ETHBUSD","U":56401204,"u":56401207,"b":[["2361.05000000","0.00000000"]],"a":[["2365.12000000","0.00000000"],["2365.13000000","1.80000000"]]}}
1618677420.2060428: {"stream":"btcusdt@depth@100ms","data":{"e":"depthUpdate","E":1618677420227,"s":"BTCUSDT","U":372026909,"u":372026911,"b":[["60474.74000000","0.08000000"]],"a":[["60522.22000000","0.07632000"],["60533.32000000","0.08000000"]]}}
1618677420.2105181: {"stream":"zenusd@bookTicker","data":{"u":6596098,"s":"ZENUSD","b":"121.2730","B":"16.45100000","a":"121.7210","A":"3.14000000"}}
1618677420.2127402: {"stream":"ethbusd@bookTicker","data":{"u":56401208,"s":"ETHBUSD","b":"2360.64000000","B":"1.50000000","a":"2365.13000000","A":"1.80000000"}}
1618677420.3066938: {"stream":"zenusd@depth@100ms","data":{"e":"depthUpdate","E":1618677420327,"s":"ZENUSD","U":6596098,"u":6596098,"b":[],"a":[["121.7210","3.14000000"]]}}
1618677420.306849: {"stream":"ethbusd@depth@100ms","data":{"e":"depthUpdate","E":1618677420327,"s":"ETHBUSD","U":56401208,"u":56401211,"b":[["2360.64000000","1.50000000"],["2360.01000000","0.84638000"]],"a":[["2365.46000000","0.13650000"],["2366.21000000","0.00000000"]]}}
1618677420.505994: {"stream":"btcusdt@depth@100ms","data":{"e":"depthUpdate","E":1618677420527,"s":"BTCUSDT","U":372026912,"u":372026912,"b":[],"a":[["60540.01000000","0.00000000"]]}}
1618677420.513512: {"stream":"ethbusd@bookTicker","data":{"u":56401212,"s":"ETHBUSD","b":"2360.65000000","B":"1.00000000","a":"2365.13000000","A":"1.80000000"}}
1618677420.606975: {"stream":"ethbusd@depth@100ms","data":{"e":"depthUpdate","E":1618677420628,"s":"ETHBUSD","U":56401212,"u":56401212,"b":[["2360.65000000","1.00000000"]],"a":[]}}
1618677420.607127: {"stream":"xlmusdt@depth@100ms","data":{"e":"depthUpdate","E":1618677420628,"s":"XLMUSDT","U":134557860,"u":134557861,"b":[["0.60072000","102.90000000"]],"a":[["0.60298000","12153.70000000"]]}}
1618677420.613069: {"stream":"ethbusd@bookTicker","data":{"u":56401213,"s":"ETHBUSD","b":"2360.66000000","B":"0.10135000","a":"2365.13000000","A":"1.80000000"}}
1618677420.622689: {"stream":"ethbusd@bookTicker","data":{"u":56401215,"s":"ETHBUSD","b":"2360.66000000","B":"1.10135000","a":"2365.13000000","A":"1.80000000"}}
1618677420.6546712: {"stream":"ethbusd@bookTicker","data":{"u":56401216,"s":"ETHBUSD","b":"2360.67000000","B":"1.00000000","a":"2365.13000000","A":"1.80000000"}}
1618677420.705371: {"stream":"ethbusd@depth@100ms","data":{"e":"depthUpdate","E":1618677420727,"s":"ETHBUSD","U":56401213,"u":56401217,"b":[["2360.67000000","1.00000000"],["2360.66000000","0.10135000"],["2360.65000000","0.00000000"]],"a":[]}}
1618677420.705556: {"stream":"btcusdt@depth@100ms","data":{"e":"depthUpdate","E":1618677420727,"s":"BTCUSDT","U":372026913,"u":372026913,"b":[],"a":[["60533.32000000","0.00000000"]]}}
1618677420.806648: {"stream":"xlmusdt@depth@100ms","data":{"e":"depthUpdate","E":1618677420827,"s":"XLMUSDT","U":134557862,"u":134557862,"b":[["0.60072000","0.00000000"]],"a":[]}}
1618677420.806798: {"stream":"ethbusd@depth@100ms","data":{"e":"depthUpdate","E":1618677420827,"s":"ETHBUSD","U":56401218,"u":56401218,"b":[["2360.66000000","0.00000000"]],"a":[]}}
1618677420.813681: {"stream":"ethbusd@bookTicker","data":{"u":56401219,"s":"ETHBUSD","b":"2360.68000000","B":"0.10135000","a":"2365.13000000","A":"1.80000000"}}
1618677420.824215: {"stream":"ethbusd@bookTicker","data":{"u":56401221,"s":"ETHBUSD","b":"2360.68000000","B":"1.10135000","a":"2365.13000000","A":"1.80000000"}}
1618677420.8522382: {"stream":"ethbusd@bookTicker","data":{"u":56401222,"s":"ETHBUSD","b":"2360.69000000","B":"1.00000000","a":"2365.13000000","A":"1.80000000"}}
1618677420.9068859: {"stream":"ethbusd@depth@100ms","data":{"e":"depthUpdate","E":1618677420928,"s":"ETHBUSD","U":56401219,"u":56401223,"b":[["2360.69000000","1.00000000"],["2360.68000000","0.10135000"],["2360.67000000","0.00000000"]],"a":[]}}
1618677420.9070752: {"stream":"bchusdt@depth@100ms","data":{"e":"depthUpdate","E":1618677420928,"s":"BCHUSDT","U":123518117,"u":123518117,"b":[],"a":[["1055.21000000","6.00000000"]]}}
1618677420.907545: {"stream":"bchusdt@bookTicker","data":{"u":123518118,"s":"BCHUSDT","b":"1051.77000000","B":"0.41583000","a":"1053.96000000","A":"0.94957000"}}
1618677421.009606: {"stream":"ethbusd@depth@100ms","data":{"e":"depthUpdate","E":1618677421030,"s":"ETHBUSD","U":56401224,"u":56401224,"b":[["2360.68000000","0.00000000"]],"a":[]}}
1618677421.0097651: {"stream":"bchusdt@depth@100ms","data":{"e":"depthUpdate","E":1618677421030,"s":"BCHUSDT","U":123518118,"u":123518119,"b":[],"a":[["1053.96000000","0.94957000"],["1055.21000000","0.00000000"]]}}
1618677421.009862: {"stream":"btcusdt@depth@100ms","data":{"e":"depthUpdate","E":1618677421030,"s":"BTCUSDT","U":372026914,"u":372026914,"b":[],"a":[["60540.05000000","0.08000000"]]}}
1618677421.016435: {"stream":"ethbusd@bookTicker","data":{"u":56401225,"s":"ETHBUSD","b":"2360.70000000","B":"0.10135000","a":"2365.13000000","A":"1.80000000"}}
1618677421.045132: {"stream":"xlmusdt@bookTicker","data":{"u":134557864,"s":"XLMUSDT","b":"0.60130000","B":"1416.30000000","a":"0.60249000","A":"497.90000000"}}
1618677421.052193: {"stream":"bchusdt@bookTicker","data":{"u":123518120,"s":"BCHUSDT","b":"1051.77000000","B":"0.41583000","a":"1053.95000000","A":"0.28464000"}}
1618677421.058644: {"stream":"ethbusd@bookTicker","data":{"u":56401227,"s":"ETHBUSD","b":"2360.70000000","B":"1.10135000","a":"2365.13000000","A":"1.80000000"}}
1618677421.092014: {"stream":"omgusd@bookTicker","data":{"u":66532579,"s":"OMGUSD","b":"9.5379","B":"88.05000000","a":"9.5621","A":"50.00000000"}}
1618677421.107221: {"stream":"atomusdt@depth@100ms","data":{"e":"depthUpdate","E":1618677421127,"s":"ATOMUSDT","U":71292139,"u":71292139,"b":[],"a":[["25.34100000","0.00000000"]]}}
1618677421.107386: {"stream":"ethbusd@depth@100ms","data":{"e":"depthUpdate","E":1618677421127,"s":"ETHBUSD","U":56401225,"u":56401228,"b":[["2360.70000000","1.10135000"],["2360.69000000","0.00000000"]],"a":[["2371.65000000","0.00000000"]]}}
1618677421.107463: {"stream":"xlmusdt@depth@100ms","data":{"e":"depthUpdate","E":1618677421127,"s":"XLMUSDT","U":134557863,"u":134557864,"b":[["0.60091000","499.20000000"]],"a":[["0.60249000","497.90000000"]]}}
1618677421.107518: {"stream":"btcusdt@depth@100ms","data":{"e":"depthUpdate","E":1618677421127,"s":"BTCUSDT","U":372026915,"u":372026916,"b":[["60395.78000000","0.00000000"]],"a":[["60662.93000000","0.00000000"]]}}
1618677421.107569: {"stream":"bchusdt@depth@100ms","data":{"e":"depthUpdate","E":1618677421127,"s":"BCHUSDT","U":123518120,"u":123518123,"b":[["1051.22000000","0.28538000"]],"a":[["1053.95000000","0.28464000"],["1056.67000000","0.00000000"],["1129.98000000","0.00000000"]]}}
1618677421.1076322: {"stream":"omgusd@depth@100ms","data":{"e":"depthUpdate","E":1618677421127,"s":"OMGUSD","U":66532579,"u":66532579,"b":[["9.5422","0.00000000"]],"a":[]}}
1618677421.111107: {"stream":"ethbusd@bookTicker","data":{"u":56401229,"s":"ETHBUSD","b":"2360.70000000","B":"1.00000000","a":"2365.13000000","A":"1.80000000"}}
1618677421.195769: {"stream":"btcusdt@bookTicker","data":{"u":372026918,"s":"BTCUSDT","b":"60506.09000000","B":"0.02373500","a":"60516.61000000","A":"0.09911200"}}
1618677421.208713: {"stream":"xlmusdt@depth@100ms","data":{"e":"depthUpdate","E":1618677421227,"s":"XLMUSDT","U":134557865,"u":134557865,"b":[],"a":[["0.60266000","0.00000000"]]}}
1618677421.2088692: {"stream":"btcusdt@depth@100ms","data":{"e":"depthUpdate","E":1618677421227,"s":"BTCUSDT","U":372026917,"u":372026919,"b":[["60488.85000000","0.09911200"]],"a":[["60516.61000000","0.09911200"],["60523.17000000","0.00000000"]]}}
1618677421.2089899: {"stream":"ethbusd@depth@100ms","data":{"e":"depthUpdate","E":1618677421227,"s":"ETHBUSD","U":56401229,"u":56401229,"b":[["2360.70000000","1.00000000"]],"a":[]}}
1618677421.209028: {"stream":"omgusd@depth@100ms","data":{"e":"depthUpdate","E":1618677421227,"s":"OMGUSD","U":66532580,"u":66532580,"b":[["9.5355","209.41000000"]],"a":[]}}
1618677421.213591: {"stream":"ethbusd@bookTicker","data":{"u":56401230,"s":"ETHBUSD","b":"2360.71000000","B":"0.10139000","a":"2365.13000000","A":"1.80000000"}}
1618677421.213695: {"stream":"btcusdt@bookTicker","data":{"u":372026920,"s":"BTCUSDT","b":"60506.09000000","B":"0.02373500","a":"60516.60000000","A":"0.00556800"}}
1618677421.222935: {"stream":"xlmusdt@bookTicker","data":{"u":134557866,"s":"XLMUSDT","b":"0.60130000","B":"1416.30000000","a":"0.60229000","A":"3319.40000000"}}
1618677421.22737: {"stream":"ethbusd@bookTicker","data":{"u":56401231,"s":"ETHBUSD","b":"2360.71000000","B":"0.10139000","a":"2365.13000000","A":"0.50000000"}}
1618677421.229673: {"stream":"ethbusd@bookTicker","data":{"u":56401232,"s":"ETHBUSD","b":"2360.71000000","B":"1.10139000","a":"2365.13000000","A":"0.50000000"}}
1618677421.2340748: {"stream":"ethbusd@bookTicker","data":{"u":56401234,"s":"ETHBUSD","b":"2360.71000000","B":"1.10139000","a":"2365.12000000","A":"1.30000000"}}
1618677421.2359731: {"stream":"bchusdt@bookTicker","data":{"u":123518124,"s":"BCHUSDT","b":"1051.77000000","B":"0.41583000","a":"1053.49000000","A":"0.79564000"}}
1618677421.266947: {"stream":"ethbusd@bookTicker","data":{"u":56401235,"s":"ETHBUSD","b":"2360.71000000","B":"1.10139000","a":"2365.11000000","A":"1.30000000"}}
1618677421.273996: {"stream":"ethbusd@bookTicker","data":{"u":56401236,"s":"ETHBUSD","b":"2360.72000000","B":"1.00000000","a":"2365.11000000","A":"1.30000000"}}
1618677421.288739: {"stream":"ethbusd@bookTicker","data":{"u":56401238,"s":"ETHBUSD","b":"2360.72000000","B":"1.00000000","a":"2365.12000000","A":"1.30000000"}}
1618677421.306734: {"stream":"xlmusdt@depth@100ms","data":{"e":"depthUpdate","E":1618677421328,"s":"XLMUSDT","U":134557866,"u":134557868,"b":[["0.60090000","0.00000000"],["0.60082000","3318.70000000"]],"a":[["0.60229000","3319.40000000"]]}}
1618677421.306932: {"stream":"ethbusd@depth@100ms","data":{"e":"depthUpdate","E":1618677421327,"s":"ETHBUSD","U":56401230,"u":56401238,"b":[["2360.72000000","1.00000000"],["2360.71000000","0.10139000"],["2360.64000000","0.50000000"]],"a":[["2365.11000000","0.00000000"],["2365.12000000","1.30000000"],["2365.13000000","0.50000000"]]}}
1618677421.307029: {"stream":"btcusdt@depth@100ms","data":{"e":"depthUpdate","E":1618677421328,"s":"BTCUSDT","U":372026920,"u":372026921,"b":[],"a":[["60516.60000000","0.00556800"],["60517.08000000","0.00000000"]]}}
1618677421.307083: {"stream":"bchusdt@depth@100ms","data":{"e":"depthUpdate","E":1618677421327,"s":"BCHUSDT","U":123518124,"u":123518124,"b":[],"a":[["1053.49000000","0.79564000"]]}}
1618677421.30712: {"stream":"omgusd@depth@100ms","data":{"e":"depthUpdate","E":1618677421328,"s":"OMGUSD","U":66532581,"u":66532582,"b":[],"a":[["9.5665","803.50000000"],["9.5804","0.00000000"]]}}
1618677421.4057448: {"stream":"ethbusd@depth@100ms","data":{"e":"depthUpdate","E":1618677421428,"s":"ETHBUSD","U":56401239,"u":56401239,"b":[["2360.71000000","0.00000000"]],"a":[]}}
1618677421.4059021: {"stream":"btcusdt@depth@100ms","data":{"e":"depthUpdate","E":1618677421428,"s":"BTCUSDT","U":372026922,"u":372026925,"b":[],"a":[["60517.08000000","0.00000000"],["60522.21000000","0.07624800"],["60522.22000000","0.00000000"]]}}
1618677421.406469: {"stream":"bchusdt@depth@100ms","data":{"e":"depthUpdate","E":1618677421428,"s":"BCHUSDT","U":123518125,"u":123518126,"b":[],"a":[["1053.95000000","0.69234000"],["1054.42000000","0.00000000"]]}}
1618677421.412137: {"stream":"ethbusd@bookTicker","data":{"u":56401240,"s":"ETHBUSD","b":"2360.73000000","B":"0.10134000","a":"2365.12000000","A":"1.30000000"}}
1618677421.4272351: {"stream":"ethbusd@bookTicker","data":{"u":56401241,"s":"ETHBUSD","b":"2360.73000000","B":"1.10134000","a":"2365.12000000","A":"1.30000000"}}
1618677421.4567602: {"stream":"ethbusd@bookTicker","data":{"u":56401243,"s":"ETHBUSD","b":"2360.74000000","B":"1.00000000","a":"2365.12000000","A":"1.30000000"}}
1618677421.508215: {"stream":"ethbusd@depth@100ms","data":{"e":"depthUpdate","E":1618677421528,"s":"ETHBUSD","U":56401240,"u":56401244,"b":[["2360.74000000","1.00000000"],["2360.73000000","0.10134000"],["2360.72000000","0.00000000"]],"a":[]}}
1618677421.588626: {"stream":"usdtusd@aggTrade","data":{"e":"aggTrade","E":1618677421608,"s":"USDTUSD","a":4837006,"p":"1.0011","q":"114.06000000","f":5148734,"l":5148734,"T":1618677421608,"m":false,"M":true}}
1618677421.588753: {"stream":"usdtusd@bookTicker","data":{"u":34057435,"s":"USDTUSD","b":"1.0010","B":"218449.96000000","a":"1.0011","A":"13092.53000000"}}
1618677421.6121368: {"stream":"usdtusd@depth@100ms","data":{"e":"depthUpdate","E":1618677421628,"s":"USDTUSD","U":34057435,"u":34057435,"b":[],"a":[["1.0011","13092.53000000"]]}}
1618677421.61227: {"stream":"ethbusd@depth@100ms","data":{"e":"depthUpdate","E":1618677421628,"s":"ETHBUSD","U":56401245,"u":56401245,"b":[["2360.73000000","0.00000000"]],"a":[]}}
1618677421.612384: {"stream":"bchusdt@depth@100ms","data":{"e":"depthUpdate","E":1618677421628,"s":"BCHUSDT","U":123518127,"u":123518127,"b":[["1051.22000000","0.00000000"]],"a":[]}}
1618677421.619199: {"stream":"ethbusd@bookTicker","data":{"u":56401246,"s":"ETHBUSD","b":"2360.75000000","B":"0.10133000","a":"2365.12000000","A":"1.30000000"}}
1618677421.646375: {"stream":"ethbusd@bookTicker","data":{"u":56401248,"s":"ETHBUSD","b":"2360.75000000","B":"1.10133000","a":"2365.12000000","A":"1.30000000"}}
1618677421.6747441: {"stream":"btcusdt@bookTicker","data":{"u":372026928,"s":"BTCUSDT","b":"60506.09000000","B":"0.02373500","a":"60511.06000000","A":"0.03040100"}}
1618677421.7106738: {"stream":"zenusd@depth@100ms","data":{"e":"depthUpdate","E":1618677421728,"s":"ZENUSD","U":6596099,"u":6596100,"b":[["121.2370","0.00000000"],["113.3730","123.73200000"]],"a":[]}}
1618677421.71085: {"stream":"ethbusd@depth@100ms","data":{"e":"depthUpdate","E":1618677421728,"s":"ETHBUSD","U":56401246,"u":56401248,"b":[["2360.75000000","1.10133000"],["2360.74000000","0.00000000"]],"a":[]}}
1618677421.714816: {"stream":"btcusdt@depth@100ms","data":{"e":"depthUpdate","E":1618677421728,"s":"BTCUSDT","U":372026926,"u":372026928,"b":[["60341.53000000","0.20832500"]],"a":[["60511.06000000","0.03040100"],["60824.90000000","0.00000000"]]}}
1618677421.7208161: {"stream":"ethbusd@bookTicker","data":{"u":56401249,"s":"ETHBUSD","b":"2360.75000000","B":"1.00000000","a":"2365.12000000","A":"1.30000000"}}
1618677421.744457: {"stream":"xlmusdt@bookTicker","data":{"u":134557870,"s":"XLMUSDT","b":"0.60130000","B":"1416.30000000","a":"0.60214000","A":"1191.70000000"}}
1618677421.8147142: {"stream":"ethbusd@depth@100ms","data":{"e":"depthUpdate","E":1618677421829,"s":"ETHBUSD","U":56401249,"u":56401249,"b":[["2360.75000000","1.00000000"]],"a":[]}}
1618677421.814844: {"stream":"xlmusdt@depth@100ms","data":{"e":"depthUpdate","E":1618677421829,"s":"XLMUSDT","U":134557869,"u":134557870,"b":[],"a":[["0.60214000","1191.70000000"],["0.64538000","0.00000000"]]}}
1618677421.814954: {"stream":"bchusdt@depth@100ms","data":{"e":"depthUpdate","E":1618677421829,"s":"BCHUSDT","U":123518128,"u":123518128,"b":[],"a":[["1054.43000000","0.00000000"]]}}
1618677421.815028: {"stream":"btcusdt@bookTicker","data":{"u":372026929,"s":"BTCUSDT","b":"60499.16000000","B":"0.00604200","a":"60511.06000000","A":"0.03040100"}}
1618677421.820537: {"stream":"ethbusd@bookTicker","data":{"u":56401250,"s":"ETHBUSD","b":"2360.76000000","B":"0.10128000","a":"2365.12000000","A":"1.30000000"}}
1618677421.8350809: {"stream":"ethbusd@bookTicker","data":{"u":56401251,"s":"ETHBUSD","b":"2360.76000000","B":"1.10128000","a":"2365.12000000","A":"1.30000000"}}
1618677421.8826182: {"stream":"omgusd@bookTicker","data":{"u":66532583,"s":"OMGUSD","b":"9.5379","B":"88.05000000","a":"9.5652","A":"209.37000000"}}
1618677421.910385: {"stream":"btcusdt@depth@100ms","data":{"e":"depthUpdate","E":1618677421928,"s":"BTCUSDT","U":372026929,"u":372026929,"b":[["60506.09000000","0.00000000"]],"a":[]}}
1618677421.910538: {"stream":"ethbusd@depth@100ms","data":{"e":"depthUpdate","E":1618677421928,"s":"ETHBUSD","U":56401250,"u":56401252,"b":[["2360.76000000","1.10128000"],["2360.75000000","0.00000000"]],"a":[]}}
1618677421.910634: {"stream":"omgusd@depth@100ms","data":{"e":"depthUpdate","E":1618677421928,"s":"OMGUSD","U":66532583,"u":66532583,"b":[],"a":[["9.5621","0.00000000"]]}}
1618677421.915443: {"stream":"ethbusd@bookTicker","data":{"u":56401253,"s":"ETHBUSD","b":"2360.76000000","B":"0.10128000","a":"2365.12000000","A":"1.30000000"}}
1618677421.918943: {"stream":"btcusdt@bookTicker","data":{"u":372026931,"s":"BTCUSDT","b":"60497.54000000","B":"0.02520200","a":"60511.06000000","A":"0.03040100"}}
1618677421.919026: {"stream":"btcusdt@bookTicker","data":{"u":372026933,"s":"BTCUSDT","b":"60497.54000000","B":"0.02520200","a":"60511.05000000","A":"0.00548000"}}
1618677421.919064: {"stream":"ethbusd@bookTicker","data":{"u":56401254,"s":"ETHBUSD","b":"2360.70000000","B":"1.00000000","a":"2365.12000000","A":"1.30000000"}}
1618677422.011127: {"stream":"ethbusd@depth@100ms","data":{"e":"depthUpdate","E":1618677422029,"s":"ETHBUSD","U":56401253,"u":56401255,"b":[["2360.76000000","0.00000000"],["2360.01000000","0.00000000"]],"a":[]}}
1618677422.0158908: {"stream":"bchusdt@depth@100ms","data":{"e":"depthUpdate","E":1618677422029,"s":"BCHUSDT","U":123518129,"u":123518129,"b":[],"a":[["1053.96000000","0.00000000"]]}}
1618677422.016046: {"stream":"xlmusdt@depth@100ms","data":{"e":"depthUpdate","E":1618677422029,"s":"XLMUSDT","U":134557871,"u":134557871,"b":[],"a":[["0.60298000","0.00000000"]]}}
1618677422.016147: {"stream":"btcusdt@depth@100ms","data":{"e":"depthUpdate","E":1618677422029,"s":"BTCUSDT","U":372026930,"u":372026933,"b":[["60499.16000000","0.00000000"],["60491.69000000","0.00548000"]],"a":[["60511.05000000","0.00548000"],["60516.60000000","0.00000000"]]}}
1618677422.021251: {"stream":"ethbusd@bookTicker","data":{"u":56401256,"s":"ETHBUSD","b":"2360.71000000","B":"0.10117000","a":"2365.12000000","A":"1.30000000"}}
1618677422.0747788: {"stream":"ethbusd@bookTicker","data":{"u":56401257,"s":"ETHBUSD","b":"2361.07000000","B":"0.84617000","a":"2365.12000000","A":"1.30000000"}}
1618677422.113251: {"stream":"ethbusd@depth@100ms","data":{"e":"depthUpdate","E":1618677422129,"s":"ETHBUSD","U":56401256,"u":56401260,"b":[["2361.07000000","0.84617000"],["2360.71000000","0.10117000"],["2360.70000000","0.00000000"],["2358.62000000","0.00000000"]],"a":[["2366.25000000","0.00000000"]]}}
1618677422.113465: {"stream":"btcusdt@depth@100ms","data":{"e":"depthUpdate","E":1618677422129,"s":"BTCUSDT","U":372026934,"u":372026937,"b":[["60488.85000000","0.00000000"],["60426.58000000","0.01000000"]],"a":[["60516.61000000","0.00000000"],["60522.21000000","0.00000000"]]}}
1618677422.1185842: {"stream":"bchusdt@depth@100ms","data":{"e":"depthUpdate","E":1618677422129,"s":"BCHUSDT","U":123518130,"u":123518131,"b":[["1050.87000000","0.28548000"]],"a":[["1054.88000000","0.94876000"]]}}
1618677422.210903: {"stream":"ethbusd@depth@100ms","data":{"e":"depthUpdate","E":1618677422229,"s":"ETHBUSD","U":56401261,"u":56401263,"b":[["2360.71000000","0.00000000"]],"a":[["2365.46000000","0.00000000"],["2366.82000000","0.14585000"]]}}
1618677422.211091: {"stream":"atomusdt@depth@100ms","data":{"e":"depthUpdate","E":1618677422229,"s":"ATOMUSDT","U":71292140,"u":71292143,"b":[],"a":[["25.20700000","19.80000000"],["25.20800000","0.00000000"],["25.22200000","39.65100000"],["25.23100000","0.00000000"]]}}
1618677422.211207: {"stream":"bchusdt@depth@100ms","data":{"e":"depthUpdate","E":1618677422229,"s":"BCHUSDT","U":123518132,"u":123518133,"b":[["1050.87000000","0.00000000"],["1050.86000000","0.00000000"]],"a":[]}}
1618677422.211304: {"stream":"btcusdt@depth@100ms","data":{"e":"depthUpdate","E":1618677422229,"s":"BTCUSDT","U":372026938,"u":372026940,"b":[["60494.84000000","0.09910300"]],"a":[["60517.09000000","0.00000000"],["60523.05000000","0.09910300"]]}}
1618677422.219688: {"stream":"ethbusd@bookTicker","data":{"u":56401264,"s":"ETHBUSD","b":"2361.08000000","B":"0.10103000","a":"2365.12000000","A":"1.30000000"}}
1618677422.219771: {"stream":"btcusdt@bookTicker","data":{"u":372026942,"s":"BTCUSDT","b":"60497.55000000","B":"0.00548000","a":"60511.05000000","A":"0.00548000"}}
1618677422.219806: {"stream":"btcusdt@bookTicker","data":{"u":372026944,"s":"BTCUSDT","b":"60497.55000000","B":"0.00548000","a":"60511.06000000","A":"0.03040100"}}
1618677422.235168: {"stream":"omgusd@bookTicker","data":{"u":66532584,"s":"OMGUSD","b":"9.5379","B":"88.05000000","a":"9.5651","A":"200.00000000"}}
1618677422.279655: {"stream":"ethbusd@bookTicker","data":{"u":56401266,"s":"ETHBUSD","b":"2361.08000000","B":"0.10103000","a":"2365.13000000","A":"0.50000000"}}
1618677422.312203: {"stream":"btcusdt@depth@100ms","data":{"e":"depthUpdate","E":1618677422330,"s":"BTCUSDT","U":372026941,"u":372026947,"b":[["60497.55000000","0.00548000"],["60494.74000000","0.07961000"],["60491.69000000","0.00000000"],["60491.68000000","0.00000000"]],"a":[["60511.05000000","0.00000000"],["60520.15000000","0.07957000"],["60522.22000000","0.00548000"]]}}
1618677422.312444: {"stream":"omgusd@depth@100ms","data":{"e":"depthUpdate","E":1618677422330,"s":"OMGUSD","U":66532584,"u":66532584,"b":[],"a":[["9.5651","200.00000000"]]}}
1618677422.3125172: {"stream":"ethbusd@depth@100ms","data":{"e":"depthUpdate","E":1618677422330,"s":"ETHBUSD","U":56401264,"u":56401266,"b":[["2361.08000000","0.10103000"],["2358.70000000","0.79940000"]],"a":[["2365.12000000","0.00000000"]]}}
1618677422.409333: {"stream":"btcusdt@depth@100ms","data":{"e":"depthUpdate","E":1618677422428,"s":"BTCUSDT","U":372026948,"u":372026949,"b":[],"a":[["60520.14000000","0.00548000"],["60522.22000000","0.00000000"]]}}
1618677422.409512: {"stream":"ethbusd@depth@100ms","data":{"e":"depthUpdate","E":1618677422428,"s":"ETHBUSD","U":56401267,"u":56401267,"b":[],"a":[["2367.32000000","0.84606000"]]}}
1618677422.412896: {"stream":"bchusdt@depth@100ms","data":{"e":"depthUpdate","E":1618677422428,"s":"BCHUSDT","U":123518134,"u":123518134,"b":[],"a":[["1053.95000000","0.40770000"]]}}
1618677422.511515: {"stream":"xlmusdt@depth@100ms","data":{"e":"depthUpdate","E":1618677422528,"s":"XLMUSDT","U":134557872,"u":134557873,"b":[],"a":[["0.60249000","0.00000000"],["0.60305000","497.50000000"]]}}
1618677422.51169: {"stream":"bchusdt@depth@100ms","data":{"e":"depthUpdate","E":1618677422528,"s":"BCHUSDT","U":123518135,"u":123518135,"b":[["1050.62000000","6.00000000"]],"a":[]}}
1618677422.523058: {"stream":"omgusd@bookTicker","data":{"u":66532586,"s":"OMGUSD","b":"9.5379","B":"88.05000000","a":"9.5563","A":"82.39000000"}}
1618677422.610411: {"stream":"bchusdt@depth@100ms","data":{"e":"depthUpdate","E":1618677422629,"s":"BCHUSDT","U":123518136,"u":123518136,"b":[],"a":[["1055.25000000","0.91503000"]]}}
1618677422.610559: {"stream":"omgusd@depth@100ms","data":{"e":"depthUpdate","E":1618677422629,"s":"OMGUSD","U":66532585,"u":66532586,"b":[],"a":[["9.5563","82.39000000"],["10.6500","2.31000000"]]}}
1618677422.610646: {"stream":"xlmusdt@depth@100ms","data":{"e":"depthUpdate","E":1618677422629,"s":"XLMUSDT","U":134557874,"u":134557874,"b":[["0.60082000","3421.60000000"]],"a":[]}}
1618677422.6134431: {"stream":"btcusdt@depth@100ms","data":{"e":"depthUpdate","E":1618677422629,"s":"BTCUSDT","U":372026950,"u":372026951,"b":[["60487.96000000","0.13213100"],["60470.97000000","0.00000000"]],"a":[]}}
1618677422.711956: {"stream":"xlmusdt@depth@100ms","data":{"e":"depthUpdate","E":1618677422729,"s":"XLMUSDT","U":134557875,"u":134557876,"b":[["0.60061000","3319.60000000"]],"a":[["0.60305000","0.00000000"]]}}
1618677422.807719: {"stream":"zenusd@depth@100ms","data":{"e":"depthUpdate","E":1618677422829,"s":"ZENUSD","U":6596101,"u":6596102,"b":[["119.5850","42.81000000"],["118.9590","0.00000000"]],"a":[]}}
1618677422.81113: {"stream":"btcusdt@bookTicker","data":{"u":372026952,"s":"BTCUSDT","b":"60497.55000000","B":"0.00548000","a":"60520.14000000","A":"0.00548000"}}
1618677422.9068182: {"stream":"xlmusdt@depth@100ms","data":{"e":"depthUpdate","E":1618677422929,"s":"XLMUSDT","U":134557877,"u":134557877,"b":[["0.60082000","3318.70000000"]],"a":[]}}
1618677422.9069598: {"stream":"btcusdt@depth@100ms","data":{"e":"depthUpdate","E":1618677422929,"s":"BTCUSDT","U":372026952,"u":372026954,"b":[],"a":[["60511.06000000","0.00000000"],["60523.04000000","0.07632500"],["60825.01000000","0.34965500"]]}}
1618677422.997633: {"stream":"omgusd@bookTicker","data":{"u":66532587,"s":"OMGUSD","b":"9.5379","B":"88.05000000","a":"9.5563","A":"132.39000000"}}
1618677423.008285: {"stream":"btcusdt@depth@100ms","data":{"e":"depthUpdate","E":1618677423029,"s":"BTCUSDT","U":372026955,"u":372026955,"b":[["60474.74000000","0.00000000"]],"a":[]}}
1618677423.008446: {"stream":"omgusd@depth@100ms","data":{"e":"depthUpdate","E":1618677423029,"s":"OMGUSD","U":66532587,"u":66532587,"b":[],"a":[["9.5563","132.39000000"]]}}
1618677423.0741: {"stream":"bchusdt@bookTicker","data":{"u":123518138,"s":"BCHUSDT","b":"1051.78000000","B":"0.28523000","a":"1053.49000000","A":"0.79564000"}}
1618677423.108143: {"stream":"btcusdt@depth@100ms","data":{"e":"depthUpdate","E":1618677423129,"s":"BTCUSDT","U":372026956,"u":372026956,"b":[["60479.97000000","0.08000000"]],"a":[]}}
1618677423.108293: {"stream":"ethbusd@depth@100ms","data":{"e":"depthUpdate","E":1618677423129,"s":"ETHBUSD","U":56401268,"u":56401269,"b":[],"a":[["2366.27000000","0.84626000"],["2367.32000000","0.00000000"]]}}
1618677423.108393: {"stream":"bchusdt@depth@100ms","data":{"e":"depthUpdate","E":1618677423129,"s":"BCHUSDT","U":123518137,"u":123518138,"b":[["1051.78000000","0.28523000"]],"a":[["1054.44000000","0.28451000"]]}}
1618677423.2075882: {"stream":"ethbusd@depth@100ms","data":{"e":"depthUpdate","E":1618677423229,"s":"ETHBUSD","U":56401270,"u":56401271,"b":[],"a":[["2366.26000000","0.14299000"],["2366.82000000","0.00000000"]]}}
1618677423.2077608: {"stream":"xlmusdt@depth@100ms","data":{"e":"depthUpdate","E":1618677423229,"s":"XLMUSDT","U":134557878,"u":134557881,"b":[["0.60098000","3318.20000000"],["0.60061000","0.00000000"]],"a":[["0.60229000","0.00000000"],["0.60261000","3318.20000000"]]}}
1618677423.267078: {"stream":"bchusdt@bookTicker","data":{"u":123518140,"s":"BCHUSDT","b":"1051.78000000","B":"0.28523000","a":"1053.95000000","A":"0.40770000"}}
1618677423.267123: {"stream":"bchusdt@bookTicker","data":{"u":123518141,"s":"BCHUSDT","b":"1052.56000000","B":"0.79068000","a":"1053.95000000","A":"0.40770000"}}
1618677423.307111: {"stream":"bchusdt@depth@100ms","data":{"e":"depthUpdate","E":1618677423329,"s":"BCHUSDT","U":123518139,"u":123518143,"b":[["1052.56000000","0.79068000"],["1050.62000000","0.00000000"],["1027.42000000","0.00000000"]],"a":[["1053.49000000","0.00000000"],["1130.32000000","14.02798000"]]}}
1618677423.314877: {"stream":"bchusdt@bookTicker","data":{"u":123518145,"s":"BCHUSDT","b":"1052.56000000","B":"0.79068000","a":"1054.44000000","A":"0.28451000"}}
1618677423.4115462: {"stream":"bchusdt@depth@100ms","data":{"e":"depthUpdate","E":1618677423433,"s":"BCHUSDT","U":123518144,"u":123518145,"b":[],"a":[["1053.95000000","0.00000000"],["1054.87000000","0.11531000"]]}}
1618677423.418334: {"stream":"bchusdt@bookTicker","data":{"u":123518147,"s":"BCHUSDT","b":"1052.57000000","B":"0.00978000","a":"1054.44000000","A":"0.28451000"}}
1618677423.508074: {"stream":"bchusdt@depth@100ms","data":{"e":"depthUpdate","E":1618677423529,"s":"BCHUSDT","U":123518146,"u":123518147,"b":[["1052.57000000","0.00978000"],["1051.77000000","0.00000000"]],"a":[]}}
1618677423.6086059: {"stream":"bchusdt@depth@100ms","data":{"e":"depthUpdate","E":1618677423629,"s":"BCHUSDT","U":123518148,"u":123518148,"b":[["1051.78000000","0.00000000"]],"a":[]}}
1618677423.616034: {"stream":"bchusdt@bookTicker","data":{"u":123518150,"s":"BCHUSDT","b":"1052.56000000","B":"0.79068000","a":"1054.44000000","A":"0.28451000"}}
1618677423.707944: {"stream":"btcusdt@depth@100ms","data":{"e":"depthUpdate","E":1618677423729,"s":"BTCUSDT","U":372026957,"u":372026958,"b":[["60388.49000000","0.12513000"]],"a":[["60526.74000000","0.07632500"]]}}
1618677423.7081118: {"stream":"zrxusd@depth@100ms","data":{"e":"depthUpdate","E":1618677423729,"s":"ZRXUSD","U":51775921,"u":51775921,"b":[["1.9539","0.00000000"]],"a":[]}}
1618677423.708195: {"stream":"bchusdt@depth@100ms","data":{"e":"depthUpdate","E":1618677423729,"s":"BCHUSDT","U":123518149,"u":123518150,"b":[["1052.57000000","0.00000000"],["1051.22000000","0.39803000"]],"a":[]}}
1618677423.800958: {"stream":"zrxusd@bookTicker","data":{"u":51775922,"s":"ZRXUSD","b":"2.0827","B":"243.12000000","a":"2.0883","A":"718.87000000"}}
1618677423.808921: {"stream":"zrxusd@depth@100ms","data":{"e":"depthUpdate","E":1618677423830,"s":"ZRXUSD","U":51775922,"u":51775922,"b":[["2.0827","243.12000000"]],"a":[]}}
1618677423.860429: {"stream":"zrxusd@bookTicker","data":{"u":51775924,"s":"ZRXUSD","b":"2.0853","B":"718.67000000","a":"2.0883","A":"718.87000000"}}
1618677423.907818: {"stream":"zrxusd@depth@100ms","data":{"e":"depthUpdate","E":1618677423929,"s":"ZRXUSD","U":51775923,"u":51775924,"b":[["2.0853","718.67000000"],["2.0821","0.00000000"]],"a":[]}}
1618677423.90799: {"stream":"btcusdt@depth@100ms","data":{"e":"depthUpdate","E":1618677423929,"s":"BTCUSDT","U":372026959,"u":372026959,"b":[],"a":[["60526.74000000","0.00000000"]]}}
1618677423.9080782: {"stream":"bchusdt@depth@100ms","data":{"e":"depthUpdate","E":1618677423929,"s":"BCHUSDT","U":123518151,"u":123518151,"b":[["1051.71000000","0.94853000"]],"a":[]}}
1618677423.91568: {"stream":"bchusdt@bookTicker","data":{"u":123518153,"s":"BCHUSDT","b":"1052.57000000","B":"0.02758000","a":"1054.44000000","A":"0.28451000"}}
1618677423.948307: {"stream":"btcusdt@bookTicker","data":{"u":372026963,"s":"BTCUSDT","b":"60498.11000000","B":"0.08021000","a":"60520.14000000","A":"0.00548000"}}
1618677424.009056: {"stream":"btcusdt@depth@100ms","data":{"e":"depthUpdate","E":1618677424029,"s":"BTCUSDT","U":372026960,"u":372026965,"b":[["60498.11000000","0.08021000"],["60494.74000000","0.00000000"]],"a":[["60520.15000000","0.00000000"],["60523.04000000","0.00000000"],["60523.53000000","0.07997000"],["60526.72000000","0.07632500"]]}}
1618677424.009284: {"stream":"bchusdt@depth@100ms","data":{"e":"depthUpdate","E":1618677424029,"s":"BCHUSDT","U":123518152,"u":123518153,"b":[["1052.57000000","0.02758000"],["1051.22000000","0.00000000"]],"a":[]}}
1618677424.015373: {"stream":"btcusdt@bookTicker","data":{"u":372026966,"s":"BTCUSDT","b":"60498.12000000","B":"0.00527300","a":"60520.14000000","A":"0.00548000"}}
1618677424.0238001: {"stream":"bchusdt@bookTicker","data":{"u":123518155,"s":"BCHUSDT","b":"1052.56000000","B":"0.79068000","a":"1054.44000000","A":"0.28451000"}}
1618677424.107625: {"stream":"xlmusdt@depth@100ms","data":{"e":"depthUpdate","E":1618677424129,"s":"XLMUSDT","U":134557882,"u":134557882,"b":[],"a":[["0.60260000","497.80000000"]]}}
1618677424.107775: {"stream":"bchusdt@depth@100ms","data":{"e":"depthUpdate","E":1618677424129,"s":"BCHUSDT","U":123518154,"u":123518156,"b":[["1052.57000000","0.00000000"],["1051.72000000","0.68328000"]],"a":[]}}
1618677424.1078951: {"stream":"btcusdt@depth@100ms","data":{"e":"depthUpdate","E":1618677424130,"s":"BTCUSDT","U":372026966,"u":372026968,"b":[["60498.12000000","0.00527300"],["60497.55000000","0.00000000"]],"a":[["60523.04000000","0.07632500"]]}}
1618677424.11604: {"stream":"bchusdt@bookTicker","data":{"u":123518157,"s":"BCHUSDT","b":"1052.57000000","B":"0.02758000","a":"1054.44000000","A":"0.28451000"}}
1618677424.208501: {"stream":"ethbusd@depth@100ms","data":{"e":"depthUpdate","E":1618677424230,"s":"ETHBUSD","U":56401272,"u":56401272,"b":[["2358.69000000","0.00000000"]],"a":[]}}
1618677424.208651: {"stream":"bchusdt@depth@100ms","data":{"e":"depthUpdate","E":1618677424230,"s":"BCHUSDT","U":123518157,"u":123518158,"b":[["1052.57000000","0.02758000"],["1051.72000000","0.28525000"]],"a":[]}}
1618677424.2155788: {"stream":"ethbusd@bookTicker","data":{"u":56401273,"s":"ETHBUSD","b":"2361.07000000","B":"0.84617000","a":"2365.13000000","A":"0.50000000"}}
1618677424.2156641: {"stream":"bchusdt@bookTicker","data":{"u":123518159,"s":"BCHUSDT","b":"1052.56000000","B":"0.79068000","a":"1054.44000000","A":"0.28451000"}}
1618677424.2332869: {"stream":"ethbusd@bookTicker","data":{"u":56401274,"s":"ETHBUSD","b":"2361.09000000","B":"0.46165000","a":"2365.13000000","A":"0.50000000"}}
1618677424.309373: {"stream":"btcusdt@depth@100ms","data":{"e":"depthUpdate","E":1618677424330,"s":"BTCUSDT","U":372026969,"u":372026974,"b":[["60498.11000000","0.00000000"],["60496.76000000","0.08002000"]],"a":[["60522.17000000","0.07998000"],["60523.04000000","0.00000000"],["60523.52000000","0.07632500"],["60523.53000000","0.00000000"]]}}
1618677424.309619: {"stream":"ethbusd@depth@100ms","data":{"e":"depthUpdate","E":1618677424330,"s":"ETHBUSD","U":56401273,"u":56401274,"b":[["2361.09000000","0.46165000"],["2361.08000000","0.00000000"]],"a":[]}}
1618677424.309712: {"stream":"bchusdt@depth@100ms","data":{"e":"depthUpdate","E":1618677424330,"s":"BCHUSDT","U":123518159,"u":123518160,"b":[["1052.57000000","0.00000000"],["1051.72000000","0.68328000"]],"a":[]}}
1618677424.31633: {"stream":"bchusdt@bookTicker","data":{"u":123518162,"s":"BCHUSDT","b":"1052.57000000","B":"0.02758000","a":"1054.44000000","A":"0.28451000"}}
1618677424.3666089: {"stream":"btcusdt@bookTicker","data":{"u":372026980,"s":"BTCUSDT","b":"60500.40000000","B":"0.09909400","a":"60520.14000000","A":"0.00548000"}}
1618677424.410881: {"stream":"xlmusdt@depth@100ms","data":{"e":"depthUpdate","E":1618677424430,"s":"XLMUSDT","U":134557883,"u":134557883,"b":[],"a":[["0.60261000","0.00000000"]]}}
1618677424.411032: {"stream":"btcusdt@depth@100ms","data":{"e":"depthUpdate","E":1618677424430,"s":"BTCUSDT","U":372026975,"u":372026980,"b":[["60500.40000000","0.09909400"],["60494.84000000","0.00000000"]],"a":[["60522.16000000","0.07632500"],["60523.05000000","0.00000000"],["60523.52000000","0.00000000"],["60528.07000000","0.09909400"]]}}
1618677424.41117: {"stream":"ethbusd@depth@100ms","data":{"e":"depthUpdate","E":1618677424430,"s":"ETHBUSD","U":56401275,"u":56401275,"b":[["2361.07000000","0.00000000"]],"a":[]}}
1618677424.4112132: {"stream":"bchusdt@depth@100ms","data":{"e":"depthUpdate","E":1618677424430,"s":"BCHUSDT","U":123518161,"u":123518162,"b":[["1052.57000000","0.02758000"],["1051.72000000","0.28525000"]],"a":[]}}
1618677424.4189062: {"stream":"btcusdt@bookTicker","data":{"u":372026982,"s":"BTCUSDT","b":"60500.41000000","B":"0.00527300","a":"60520.14000000","A":"0.00548000"}}
1618677424.501822: {"stream":"ethbusd@bookTicker","data":{"u":56401278,"s":"ETHBUSD","b":"2360.64000000","B":"0.50000000","a":"2365.13000000","A":"0.50000000"}}
1618677424.510901: {"stream":"ethbusd@depth@100ms","data":{"e":"depthUpdate","E":1618677424530,"s":"ETHBUSD","U":56401276,"u":56401278,"b":[["2361.09000000","0.00000000"],["2360.05000000","0.84638000"],["2350.02000000","16.47403000"]],"a":[]}}
1618677424.511115: {"stream":"xlmusdt@depth@100ms","data":{"e":"depthUpdate","E":1618677424530,"s":"XLMUSDT","U":134557884,"u":134557886,"b":[["0.60098000","0.00000000"],["0.59577000","308.60000000"]],"a":[["0.60235000","3318.90000000"]]}}
1618677424.51119: {"stream":"btcusdt@depth@100ms","data":{"e":"depthUpdate","E":1618677424530,"s":"BTCUSDT","U":372026981,"u":372026982,"b":[["60500.41000000","0.00527300"],["60498.12000000","0.00000000"]],"a":[]}}
1618677424.511242: {"stream":"omgusd@depth@100ms","data":{"e":"depthUpdate","E":1618677424530,"s":"OMGUSD","U":66532588,"u":66532588,"b":[],"a":[["9.5650","94.06000000"]]}}
1618677424.6087658: {"stream":"ethbusd@depth@100ms","data":{"e":"depthUpdate","E":1618677424630,"s":"ETHBUSD","U":56401279,"u":56401279,"b":[],"a":[["2374.18000000","12.18184000"]]}}
1618677424.608914: {"stream":"atomusdt@depth@100ms","data":{"e":"depthUpdate","E":1618677424630,"s":"ATOMUSDT","U":71292144,"u":71292145,"b":[["24.97600000","12.85500000"]],"a":[["25.37200000","45.85100000"]]}}
1618677424.609004: {"stream":"btcusdt@depth@100ms","data":{"e":"depthUpdate","E":1618677424630,"s":"BTCUSDT","U":372026983,"u":372026984,"b":[["60309.47000000","0.01161300"]],"a":[["60688.16000000","0.64345000"]]}}
1618677424.624712: {"stream":"btcusdt@bookTicker","data":{"u":372026986,"s":"BTCUSDT","b":"60500.41000000","B":"0.00527300","a":"60520.14000000","A":"0.08580500"}}
1618677424.693609: {"stream":"bchusdt@bookTicker","data":{"u":123518164,"s":"BCHUSDT","b":"1052.57000000","B":"0.02758000","a":"1054.43000000","A":"0.91555000"}}
1618677424.709384: {"stream":"ethbusd@depth@100ms","data":{"e":"depthUpdate","E":1618677424730,"s":"ETHBUSD","U":56401280,"u":56401281,"b":[["2350.03000000","1.27100000"],["2348.14000000","0.00000000"]],"a":[]}}
1618677424.709578: {"stream":"bchusdt@depth@100ms","data":{"e":"depthUpdate","E":1618677424730,"s":"BCHUSDT","U":123518163,"u":123518164,"b":[],"a":[["1054.43000000","0.91555000"],["1055.25000000","0.00000000"]]}}
1618677424.7096388: {"stream":"atomusdt@depth@100ms","data":{"e":"depthUpdate","E":1618677424730,"s":"ATOMUSDT","U":71292146,"u":71292147,"b":[],"a":[["25.20800000","39.67300000"],["25.22200000","0.00000000"]]}}
1618677424.709692: {"stream":"xlmusdt@depth@100ms","data":{"e":"depthUpdate","E":1618677424730,"s":"XLMUSDT","U":134557887,"u":134557887,"b":[],"a":[["0.60250000","0.00000000"]]}}
1618677424.709731: {"stream":"btcusdt@depth@100ms","data":{"e":"depthUpdate","E":1618677424730,"s":"BTCUSDT","U":372026985,"u":372026986,"b":[],"a":[["60520.14000000","0.08580500"],["60522.16000000","0.00000000"]]}}
1618677424.7167308: {"stream":"btcusdt@bookTicker","data":{"u":372026988,"s":"BTCUSDT","b":"60500.41000000","B":"0.00527300","a":"60520.14000000","A":"0.08032500"}}
1618677424.716813: {"stream":"btcusdt@bookTicker","data":{"u":372026989,"s":"BTCUSDT","b":"60500.41000000","B":"0.00527300","a":"60520.13000000","A":"0.00544600"}}
1618677424.728873: {"stream":"btcusdt@bookTicker","data":{"u":372026991,"s":"BTCUSDT","b":"60500.41000000","B":"0.00527300","a":"60520.13000000","A":"0.08569900"}}
1618677424.810076: {"stream":"ethbusd@depth@100ms","data":{"e":"depthUpdate","E":1618677424831,"s":"ETHBUSD","U":56401282,"u":56401284,"b":[["2348.13000000","0.00000000"]],"a":[["2365.74000000","0.84644000"],["2366.83000000","0.00000000"]]}}
1618677424.811865: {"stream":"xlmusdt@depth@100ms","data":{"e":"depthUpdate","E":1618677424831,"s":"XLMUSDT","U":134557888,"u":134557888,"b":[["0.59466000","0.00000000"]],"a":[]}}
1618677424.8120189: {"stream":"btcusdt@depth@100ms","data":{"e":"depthUpdate","E":1618677424831,"s":"BTCUSDT","U":372026987,"u":372026991,"b":[],"a":[["60520.13000000","0.08569900"],["60520.14000000","0.00000000"],["60533.34000000","0.02097700"]]}}
1618677424.812156: {"stream":"zrxusd@depth@100ms","data":{"e":"depthUpdate","E":1618677424831,"s":"ZRXUSD","U":51775925,"u":51775925,"b":[["1.9916","0.00000000"]],"a":[]}}
1618677424.817203: {"stream":"btcusdt@bookTicker","data":{"u":372026992,"s":"BTCUSDT","b":"60500.41000000","B":"0.00527300","a":"60520.13000000","A":"0.08025300"}}
1618677424.819381: {"stream":"btcusdt@bookTicker","data":{"u":372026993,"s":"BTCUSDT","b":"60500.41000000","B":"0.00527300","a":"60520.12000000","A":"0.00544600"}}
1618677424.836191: {"stream":"btcusdt@bookTicker","data":{"u":372026994,"s":"BTCUSDT","b":"60500.41000000","B":"0.00527300","a":"60520.12000000","A":"0.08569900"}}
1618677424.908969: {"stream":"atomusdt@depth@100ms","data":{"e":"depthUpdate","E":1618677424930,"s":"ATOMUSDT","U":71292148,"u":71292148,"b":[["24.94700000","0.00000000"]],"a":[]}}
1618677424.909121: {"stream":"ethbusd@depth@100ms","data":{"e":"depthUpdate","E":1618677424930,"s":"ETHBUSD","U":56401285,"u":56401286,"b":[],"a":[["2365.47000000","1.37117000"],["2366.26000000","0.00000000"]]}}
1618677424.9092119: {"stream":"btcusdt@depth@100ms","data":{"e":"depthUpdate","E":1618677424930,"s":"BTCUSDT","U":372026992,"u":372026996,"b":[["60276.25000000","0.00000000"]],"a":[["60520.12000000","0.08569900"],["60520.13000000","0.00000000"]]}}
1618677424.9153411: {"stream":"btcusdt@bookTicker","data":{"u":372026997,"s":"BTCUSDT","b":"60500.41000000","B":"0.00527300","a":"60520.12000000","A":"0.08025300"}}
1618677424.915463: {"stream":"btcusdt@bookTicker","data":{"u":372026998,"s":"BTCUSDT","b":"60500.41000000","B":"0.00527300","a":"60520.11000000","A":"0.00544600"}}
1618677424.93588: {"stream":"btcusdt@bookTicker","data":{"u":372027000,"s":"BTCUSDT","b":"60500.41000000","B":"0.00527300","a":"60520.11000000","A":"0.08569900"}}
1618677425.00977: {"stream":"ethbusd@depth@100ms","data":{"e":"depthUpdate","E":1618677425031,"s":"ETHBUSD","U":56401287,"u":56401290,"b":[["2344.63000000","0.53400000"],["2339.80000000","0.00000000"]],"a":[["2365.46000000","0.13876000"],["2365.47000000","1.23241000"]]}}
1618677425.009965: {"stream":"btcusdt@depth@100ms","data":{"e":"depthUpdate","E":1618677425031,"s":"BTCUSDT","U":372026997,"u":372027000,"b":[],"a":[["60520.11000000","0.08569900"],["60520.12000000","0.00000000"]]}}
1618677425.016725: {"stream":"btcusdt@bookTicker","data":{"u":372027001,"s":"BTCUSDT","b":"60500.41000000","B":"0.00527300","a":"60520.10000000","A":"0.00544600"}}
1618677425.108507: {"stream":"btcusdt@depth@100ms","data":{"e":"depthUpdate","E":1618677425130,"s":"BTCUSDT","U":372027001,"u":372027003,"b":[],"a":[["60520.10000000","0.00544600"],["60520.11000000","0.08025300"],["60526.72000000","0.00000000"]]}}
1618677425.1086888: {"stream":"omgusd@depth@100ms","data":{"e":"depthUpdate","E":1618677425130,"s":"OMGUSD","U":66532589,"u":66532590,"b":[],"a":[["9.5589","209.50000000"],["9.5652","0.00000000"]]}}
1618677425.272779: {"stream":"ethbusd@bookTicker","data":{"u":56401291,"s":"ETHBUSD","b":"2360.64000000","B":"0.50000000","a":"2365.46000000","A":"0.13876000"}}
1618677425.309896: {"stream":"btcusdt@depth@100ms","data":{"e":"depthUpdate","E":1618677425330,"s":"BTCUSDT","U":372027004,"u":372027004,"b":[],"a":[["60540.05000000","0.00000000"]]}}
1618677425.310047: {"stream":"ethbusd@depth@100ms","data":{"e":"depthUpdate","E":1618677425330,"s":"ETHBUSD","U":56401291,"u":56401291,"b":[],"a":[["2365.13000000","0.00000000"]]}}
1618677425.310125: {"stream":"bchusdt@depth@100ms","data":{"e":"depthUpdate","E":1618677425330,"s":"BCHUSDT","U":123518165,"u":123518169,"b":[["1052.56000000","0.00000000"],["1052.02000000","0.94379000"],["1029.04000000","9.54123000"],["1028.76000000","0.00000000"]],"a":[["1058.82000000","0.00000000"]]}}
1618677425.411594: {"stream":"btcusdt@depth@100ms","data":{"e":"depthUpdate","E":1618677425433,"s":"BTCUSDT","U":372027005,"u":372027006,"b":[["60500.40000000","0.00000000"]],"a":[["60528.07000000","0.00000000"]]}}
1618677425.509579: {"stream":"xlmusdt@depth@100ms","data":{"e":"depthUpdate","E":1618677425531,"s":"XLMUSDT","U":134557889,"u":134557889,"b":[["0.60091000","0.00000000"]],"a":[]}}
1618677425.509734: {"stream":"btcusdt@depth@100ms","data":{"e":"depthUpdate","E":1618677425531,"s":"BTCUSDT","U":372027007,"u":372027012,"b":[["60496.76000000","0.00000000"],["60479.95000000","0.00000000"],["60471.82000000","0.13213900"]],"a":[["60522.17000000","0.00000000"],["60522.85000000","0.09910500"],["60533.29000000","0.08000000"]]}}
1618677425.58898: {"stream":"btcusdt@bookTicker","data":{"u":372027014,"s":"BTCUSDT","b":"60497.54000000","B":"0.02520200","a":"60500.00000000","A":"0.00168500"}}
1618677425.5895302: {"stream":"btcusdt@aggTrade","data":{"e":"aggTrade","E":1618677425599,"s":"BTCUSDT","a":3612249,"p":"60500.41000000","q":"0.00527300","f":3667500,"l":3667500,"T":1618677425598,"m":true,"M":true}}
1618677425.610035: {"stream":"xlmusdt@depth@100ms","data":{"e":"depthUpdate","E":1618677425631,"s":"XLMUSDT","U":134557890,"u":134557890,"b":[["0.60084000","499.30000000"]],"a":[]}}
1618677425.610193: {"stream":"btcusdt@depth@100ms","data":{"e":"depthUpdate","E":1618677425631,"s":"BTCUSDT","U":372027013,"u":372027015,"b":[["60500.41000000","0.00000000"],["60426.58000000","0.00000000"]],"a":[["60500.00000000","0.00168500"],["60520.09000000","0.16000000"]]}}
1618677425.675725: {"stream":"btcusdt@bookTicker","data":{"u":372027018,"s":"BTCUSDT","b":"60490.81000000","B":"0.07784100","a":"60500.00000000","A":"0.00168500"}}
1618677425.71195: {"stream":"ethbusd@depth@100ms","data":{"e":"depthUpdate","E":1618677425733,"s":"ETHBUSD","U":56401292,"u":56401292,"b":[["2302.16000000","0.00000000"]],"a":[]}}
1618677425.7121: {"stream":"xlmusdt@depth@100ms","data":{"e":"depthUpdate","E":1618677425733,"s":"XLMUSDT","U":134557891,"u":134557892,"b":[["0.60069000","3319.10000000"]],"a":[["0.60219000","3319.80000000"]]}}
1618677425.712196: {"stream":"btcusdt@depth@100ms","data":{"e":"depthUpdate","E":1618677425733,"s":"BTCUSDT","U":372027016,"u":372027021,"b":[["60497.54000000","0.00000000"],["60324.81000000","0.30852900"]],"a":[["60503.57000000","0.03597200"],["60520.08000000","0.00530000"],["60520.10000000","0.00000000"],["60825.01000000","0.00000000"]]}}
1618677425.8098502: {"stream":"btcusdt@depth@100ms","data":{"e":"depthUpdate","E":1618677425831,"s":"BTCUSDT","U":372027022,"u":372027025,"b":[["60465.49000000","0.13215300"]],"a":[["60516.56000000","0.09911500"],["60522.85000000","0.00000000"],["60533.34000000","0.00000000"]]}}
1618677425.869517: {"stream":"zrxusd@aggTrade","data":{"e":"aggTrade","E":1618677425890,"s":"ZRXUSD","a":591871,"p":"2.0853","q":"650.00000000","f":644457,"l":644457,"T":1618677425889,"m":true,"M":true}}
1618677425.869623: {"stream":"zrxusd@bookTicker","data":{"u":51775926,"s":"ZRXUSD","b":"2.0853","B":"68.67000000","a":"2.0883","A":"718.87000000"}}
1618677425.869664: {"stream":"zrxusd@bookTicker","data":{"u":51775927,"s":"ZRXUSD","b":"2.0827","B":"243.12000000","a":"2.0883","A":"718.87000000"}}
1618677425.8846421: {"stream":"zrxusd@bookTicker","data":{"u":51775928,"s":"ZRXUSD","b":"2.0845","B":"718.86000000","a":"2.0883","A":"718.87000000"}}
1618677425.909397: {"stream":"xlmusdt@depth@100ms","data":{"e":"depthUpdate","E":1618677425931,"s":"XLMUSDT","U":134557893,"u":134557893,"b":[["0.60082000","0.00000000"]],"a":[]}}
1618677425.909564: {"stream":"btcusdt@depth@100ms","data":{"e":"depthUpdate","E":1618677425931,"s":"BTCUSDT","U":372027026,"u":372027028,"b":[["60418.24000000","0.01000000"]],"a":[["60516.55000000","0.00530000"],["60520.08000000","0.00000000"]]}}
1618677425.9097002: {"stream":"zrxusd@depth@100ms","data":{"e":"depthUpdate","E":1618677425931,"s":"ZRXUSD","U":51775926,"u":51775928,"b":[["2.0853","0.00000000"],["2.0845","718.86000000"]],"a":[]}}
1618677426.010277: {"stream":"btcusdt@depth@100ms","data":{"e":"depthUpdate","E":1618677426031,"s":"BTCUSDT","U":372027029,"u":372027029,"b":[["60388.49000000","0.00000000"]],"a":[]}}
1618677426.0946162: {"stream":"xlmusdt@bookTicker","data":{"u":134557896,"s":"XLMUSDT","b":"0.60130000","B":"1416.30000000","a":"0.60202000","A":"3320.40000000"}}
1618677426.111354: {"stream":"xlmusdt@depth@100ms","data":{"e":"depthUpdate","E":1618677426131,"s":"XLMUSDT","U":134557894,"u":134557896,"b":[["0.60053000","3319.90000000"]],"a":[["0.60202000","3320.40000000"],["0.60235000","0.00000000"]]}}
1618677426.1148329: {"stream":"atomusdt@bookTicker","data":{"u":71292149,"s":"ATOMUSDT","b":"25.15100000","B":"32.03800000","a":"25.20100000","A":"1.80500000"}}
1618677426.210301: {"stream":"atomusdt@depth@100ms","data":{"e":"depthUpdate","E":1618677426231,"s":"ATOMUSDT","U":71292149,"u":71292150,"b":[["25.15800000","0.00000000"],["25.14400000","39.68700000"]],"a":[]}}
1618677426.2104871: {"stream":"btcusdt@depth@100ms","data":{"e":"depthUpdate","E":1618677426231,"s":"BTCUSDT","U":372027030,"u":372027030,"b":[],"a":[["60520.11000000","0.00000000"]]}}
1618677426.21054: {"stream":"zrxusd@depth@100ms","data":{"e":"depthUpdate","E":1618677426231,"s":"ZRXUSD","U":51775929,"u":51775929,"b":[],"a":[["2.0950","0.00000000"]]}}
1618677426.210807: {"stream":"zrxusd@bookTicker","data":{"u":51775930,"s":"ZRXUSD","b":"2.0827","B":"243.12000000","a":"2.0883","A":"718.87000000"}}
1618677426.227576: {"stream":"zrxusd@bookTicker","data":{"u":51775931,"s":"ZRXUSD","b":"2.0836","B":"719.15000000","a":"2.0883","A":"718.87000000"}}
1618677426.309779: {"stream":"btcusdt@depth@100ms","data":{"e":"depthUpdate","E":1618677426331,"s":"BTCUSDT","U":372027031,"u":372027031,"b":[["60479.97000000","0.00000000"]],"a":[]}}
1618677426.309936: {"stream":"zrxusd@depth@100ms","data":{"e":"depthUpdate","E":1618677426331,"s":"ZRXUSD","U":51775930,"u":51775931,"b":[["2.0845","0.00000000"],["2.0836","719.15000000"]],"a":[]}}
1618677426.378658: {"stream":"ethbusd@bookTicker","data":{"u":56401293,"s":"ETHBUSD","b":"2360.64000000","B":"0.50000000","a":"2365.46000000","A":"0.63876000"}}
1618677426.3972108: {"stream":"ethbusd@bookTicker","data":{"u":56401294,"s":"ETHBUSD","b":"2360.65000000","B":"0.09738000","a":"2365.46000000","A":"0.63876000"}}
1618677426.4099982: {"stream":"ethbusd@depth@100ms","data":{"e":"depthUpdate","E":1618677426431,"s":"ETHBUSD","U":56401293,"u":56401294,"b":[["2360.65000000","0.09738000"]],"a":[["2365.46000000","0.63876000"]]}}
1618677426.510466: {"stream":"atomusdt@depth@100ms","data":{"e":"depthUpdate","E":1618677426531,"s":"ATOMUSDT","U":71292151,"u":71292153,"b":[],"a":[["25.20500000","26.17900000"],["25.29400000","640.06300000"],["28.02900000","0.00000000"]]}}
1618677426.5151029: {"stream":"btcusdt@depth@100ms","data":{"e":"depthUpdate","E":1618677426536,"s":"BTCUSDT","U":372027032,"u":372027032,"b":[],"a":[["60543.56000000","0.00000000"]]}}
1618677426.515254: {"stream":"zrxusd@depth@100ms","data":{"e":"depthUpdate","E":1618677426536,"s":"ZRXUSD","U":51775932,"u":51775932,"b":[],"a":[["2.0938","655.06000000"]]}}
1618677426.515334: {"stream":"omgusd@depth@100ms","data":{"e":"depthUpdate","E":1618677426536,"s":"OMGUSD","U":66532591,"u":66532591,"b":[],"a":[["9.5650","0.00000000"]]}}
1618677426.526955: {"stream":"omgusd@bookTicker","data":{"u":66532592,"s":"OMGUSD","b":"9.5379","B":"88.05000000","a":"9.5562","A":"94.07000000"}}
1618677426.611538: {"stream":"xlmusdt@depth@100ms","data":{"e":"depthUpdate","E":1618677426631,"s":"XLMUSDT","U":134557897,"u":134557897,"b":[["0.59355000","0.00000000"]],"a":[]}}
1618677426.6116931: {"stream":"btcusdt@depth@100ms","data":{"e":"depthUpdate","E":1618677426631,"s":"BTCUSDT","U":372027033,"u":372027033,"b":[],"a":[["60525.32000000","0.13215300"]]}}
1618677426.611773: {"stream":"omgusd@depth@100ms","data":{"e":"depthUpdate","E":1618677426631,"s":"OMGUSD","U":66532592,"u":66532592,"b":[],"a":[["9.5562","94.07000000"]]}}
1618677426.6118348: {"stream":"zrxusd@depth@100ms","data":{"e":"depthUpdate","E":1618677426631,"s":"ZRXUSD","U":51775933,"u":51775934,"b":[["2.0793","0.00000000"],["2.0759","495.00000000"]],"a":[]}}
1618677426.711006: {"stream":"btcusdt@depth@100ms","data":{"e":"depthUpdate","E":1618677426731,"s":"BTCUSDT","U":372027034,"u":372027035,"b":[],"a":[["60522.22000000","0.02098200"],["60533.29000000","0.00000000"]]}}
1618677426.711178: {"stream":"ethbusd@depth@100ms","data":{"e":"depthUpdate","E":1618677426731,"s":"ETHBUSD","U":56401295,"u":56401297,"b":[["2360.49000000","0.00000000"],["2359.47000000","0.84660000"],["2302.33000000","0.01025000"]],"a":[]}}
1618677426.811157: {"stream":"btcusdt@depth@100ms","data":{"e":"depthUpdate","E":1618677426831,"s":"BTCUSDT","U":372027036,"u":372027036,"b":[],"a":[["60522.18000000","0.08000000"]]}}
1618677426.8113081: {"stream":"bchusdt@depth@100ms","data":{"e":"depthUpdate","E":1618677426831,"s":"BCHUSDT","U":123518170,"u":123518170,"b":[["1051.22000000","0.91577000"]],"a":[]}}
1618677426.81138: {"stream":"zrxusd@depth@100ms","data":{"e":"depthUpdate","E":1618677426832,"s":"ZRXUSD","U":51775935,"u":51775935,"b":[],"a":[["2.0938","0.00000000"]]}}
1618677426.910538: {"stream":"btcusdt@depth@100ms","data":{"e":"depthUpdate","E":1618677426932,"s":"BTCUSDT","U":372027037,"u":372027037,"b":[],"a":[["60512.90000000","0.06833700"]]}}
1618677426.9477088: {"stream":"ethbusd@bookTicker","data":{"u":56401298,"s":"ETHBUSD","b":"2360.65000000","B":"0.09738000","a":"2365.45000000","A":"0.09736000"}}
1618677427.010091: {"stream":"ethbusd@depth@100ms","data":{"e":"depthUpdate","E":1618677427032,"s":"ETHBUSD","U":56401298,"u":56401298,"b":[],"a":[["2365.45000000","0.09736000"]]}}
1618677427.010237: {"stream":"xlmusdt@depth@100ms","data":{"e":"depthUpdate","E":1618677427032,"s":"XLMUSDT","U":134557898,"u":134557899,"b":[["0.60069000","0.00000000"],["0.60040000","3320.60000000"]],"a":[]}}
1618677427.010337: {"stream":"btcusdt@depth@100ms","data":{"e":"depthUpdate","E":1618677427032,"s":"BTCUSDT","U":372027038,"u":372027043,"b":[["60487.96000000","0.00000000"],["60482.38000000","0.09912200"]],"a":[["60510.22000000","0.09912200"],["60512.89000000","0.00538800"],["60516.55000000","0.00000000"],["60516.56000000","0.00000000"]]}}
1618677427.0926778: {"stream":"zrxusd@bookTicker","data":{"u":51775937,"s":"ZRXUSD","b":"2.0827","B":"243.12000000","a":"2.0883","A":"718.87000000"}}
1618677427.110898: {"stream":"btcusdt@depth@100ms","data":{"e":"depthUpdate","E":1618677427132,"s":"BTCUSDT","U":372027044,"u":372027045,"b":[],"a":[["60510.21000000","0.00538800"],["60512.89000000","0.00000000"]]}}
1618677427.111076: {"stream":"zrxusd@depth@100ms","data":{"e":"depthUpdate","E":1618677427132,"s":"ZRXUSD","U":51775936,"u":51775937,"b":[["2.0836","0.00000000"]],"a":[["2.0943","608.28000000"]]}}
1618677427.1191711: {"stream":"zrxusd@bookTicker","data":{"u":51775938,"s":"ZRXUSD","b":"2.0827","B":"962.56000000","a":"2.0883","A":"718.87000000"}}
1618677427.210349: {"stream":"zrxusd@depth@100ms","data":{"e":"depthUpdate","E":1618677427232,"s":"ZRXUSD","U":51775938,"u":51775938,"b":[["2.0827","962.56000000"]],"a":[]}}
1618677427.2104828: {"stream":"bchusdt@depth@100ms","data":{"e":"depthUpdate","E":1618677427232,"s":"BCHUSDT","U":123518171,"u":123518171,"b":[],"a":[["1130.32000000","0.00000000"]]}}
1618677427.2874858: {"stream":"bchusdt@bookTicker","data":{"u":123518174,"s":"BCHUSDT","b":"1052.57000000","B":"0.02758000","a":"1053.63000000","A":"0.75962000"}}
1618677427.308845: {"stream":"bchusdt@bookTicker","data":{"u":123518175,"s":"BCHUSDT","b":"1052.57000000","B":"0.02758000","a":"1053.62000000","A":"0.28473000"}}
1618677427.310424: {"stream":"btcusdt@depth@100ms","data":{"e":"depthUpdate","E":1618677427332,"s":"BTCUSDT","U":372027046,"u":372027047,"b":[],"a":[["60507.13000000","0.08025700"],["60507.54000000","0.08025700"]]}}
1618677427.311014: {"stream":"zrxusd@depth@100ms","data":{"e":"depthUpdate","E":1618677427332,"s":"ZRXUSD","U":51775939,"u":51775941,"b":[["2.0793","495.00000000"],["2.0759","0.00000000"]],"a":[["2.0943","0.00000000"]]}}
1618677427.3111072: {"stream":"bchusdt@depth@100ms","data":{"e":"depthUpdate","E":1618677427332,"s":"BCHUSDT","U":123518172,"u":123518175,"b":[["1048.06000000","0.83726000"]],"a":[["1053.62000000","0.28473000"],["1053.63000000","0.75962000"],["1057.44000000","4.62915000"]]}}
1618677427.411037: {"stream":"btcusdt@depth@100ms","data":{"e":"depthUpdate","E":1618677427432,"s":"BTCUSDT","U":372027048,"u":372027051,"b":[],"a":[["60507.12000000","0.00538800"],["60507.13000000","0.00000000"],["60507.54000000","0.00000000"],["60510.21000000","0.00000000"]]}}
1618677427.411243: {"stream":"bchusdt@depth@100ms","data":{"e":"depthUpdate","E":1618677427432,"s":"BCHUSDT","U":123518176,"u":123518178,"b":[],"a":[["1054.42000000","0.37606000"],["1054.44000000","0.00000000"],["1054.87000000","0.00000000"]]}}
1618677427.512327: {"stream":"bchusdt@depth@100ms","data":{"e":"depthUpdate","E":1618677427533,"s":"BCHUSDT","U":123518179,"u":123518179,"b":[],"a":[["1054.43000000","0.00000000"]]}}
1618677427.6112928: {"stream":"xlmusdt@depth@100ms","data":{"e":"depthUpdate","E":1618677427632,"s":"XLMUSDT","U":134557900,"u":134557900,"b":[["0.59326000","73.50000000"]],"a":[]}}
1618677427.611425: {"stream":"zrxusd@depth@100ms","data":{"e":"depthUpdate","E":1618677427632,"s":"ZRXUSD","U":51775942,"u":51775942,"b":[],"a":[["2.0936","632.77000000"]]}}
1618677427.710931: {"stream":"zrxusd@depth@100ms","data":{"e":"depthUpdate","E":1618677427732,"s":"ZRXUSD","U":51775943,"u":51775943,"b":[["1.9558","3812.11000000"]],"a":[]}}
1618677427.7110841: {"stream":"btcusdt@depth@100ms","data":{"e":"depthUpdate","E":1618677427732,"s":"BTCUSDT","U":372027052,"u":372027053,"b":[],"a":[["60503.56000000","0.08025700"],["60812.73000000","0.00000000"]]}}
1618677427.7112079: {"stream":"bchusdt@depth@100ms","data":{"e":"depthUpdate","E":1618677427732,"s":"BCHUSDT","U":123518180,"u":123518180,"b":[["1047.24000000","0.00000000"]],"a":[]}}
1618677427.720682: {"stream":"xlmusdt@bookTicker","data":{"u":134557901,"s":"XLMUSDT","b":"0.60130000","B":"1416.30000000","a":"0.60201000","A":"1923.40000000"}}
1618677427.8119931: {"stream":"xlmusdt@depth@100ms","data":{"e":"depthUpdate","E":1618677427832,"s":"XLMUSDT","U":134557901,"u":134557901,"b":[],"a":[["0.60201000","1923.40000000"]]}}
1618677427.812145: {"stream":"btcusdt@depth@100ms","data":{"e":"depthUpdate","E":1618677427832,"s":"BTCUSDT","U":372027054,"u":372027057,"b":[["60484.09000000","0.00547400"]],"a":[["60503.55000000","0.00547400"],["60507.12000000","0.00000000"],["60522.22000000","0.00000000"]]}}
1618677427.812276: {"stream":"zrxusd@depth@100ms","data":{"e":"depthUpdate","E":1618677427832,"s":"ZRXUSD","U":51775944,"u":51775944,"b":[],"a":[["2.0936","0.00000000"]]}}
1618677427.8412: {"stream":"zrxusd@bookTicker","data":{"u":51775945,"s":"ZRXUSD","b":"2.0827","B":"719.44000000","a":"2.0883","A":"718.87000000"}}
1618677427.849084: {"stream":"bchusdt@bookTicker","data":{"u":123518181,"s":"BCHUSDT","b":"1052.57000000","B":"0.02758000","a":"1053.63000000","A":"0.75962000"}}
1618677427.91029: {"stream":"btcusdt@depth@100ms","data":{"e":"depthUpdate","E":1618677427932,"s":"BTCUSDT","U":372027058,"u":372027058,"b":[],"a":[["62215.30000000","0.00000000"]]}}
1618677427.91046: {"stream":"zrxusd@depth@100ms","data":{"e":"depthUpdate","E":1618677427932,"s":"ZRXUSD","U":51775945,"u":51775945,"b":[["2.0827","719.44000000"]],"a":[]}}
1618677427.910536: {"stream":"bchusdt@depth@100ms","data":{"e":"depthUpdate","E":1618677427932,"s":"BCHUSDT","U":123518181,"u":123518181,"b":[],"a":[["1053.62000000","0.00000000"]]}}
1618677428.010274: {"stream":"btcusdt@depth@100ms","data":{"e":"depthUpdate","E":1618677428032,"s":"BTCUSDT","U":372027059,"u":372027059,"b":[],"a":[["60531.88000000","0.85532900"]]}}
1618677428.0104241: {"stream":"ethbusd@depth@100ms","data":{"e":"depthUpdate","E":1618677428032,"s":"ETHBUSD","U":56401299,"u":56401300,"b":[["2344.63000000","0.00000000"],["2333.88000000","0.53400000"]],"a":[]}}
1618677428.0358121: {"stream":"ethbusd@bookTicker","data":{"u":56401302,"s":"ETHBUSD","b":"2360.65000000","B":"0.09738000","a":"2365.21000000","A":"0.84663000"}}
1618677428.111439: {"stream":"zrxusd@depth@100ms","data":{"e":"depthUpdate","E":1618677428132,"s":"ZRXUSD","U":51775946,"u":51775950,"b":[["2.0793","495.00000000"],["2.0759","0.00000000"]],"a":[["2.0937","639.29000000"]]}}
1618677428.111607: {"stream":"ethbusd@depth@100ms","data":{"e":"depthUpdate","E":1618677428132,"s":"ETHBUSD","U":56401301,"u":56401302,"b":[],"a":[["2365.21000000","0.84663000"],["2366.27000000","0.00000000"]]}}
1618677428.311373: {"stream":"xlmusdt@depth@100ms","data":{"e":"depthUpdate","E":1618677428333,"s":"XLMUSDT","U":134557902,"u":134557903,"b":[["0.60068000","3319.80000000"],["0.60040000","0.00000000"]],"a":[]}}
1618677428.311546: {"stream":"btcusdt@depth@100ms","data":{"e":"depthUpdate","E":1618677428333,"s":"BTCUSDT","U":372027060,"u":372027060,"b":[],"a":[["60503.56000000","0.00000000"]]}}
1618677428.410889: {"stream":"btcusdt@depth@100ms","data":{"e":"depthUpdate","E":1618677428433,"s":"BTCUSDT","U":372027061,"u":372027061,"b":[],"a":[["60506.36000000","0.08018900"]]}}
1618677428.480448: {"stream":"atomusdt@bookTicker","data":{"u":71292155,"s":"ATOMUSDT","b":"25.15800000","B":"39.66700000","a":"25.20100000","A":"1.80500000"}}
1618677428.51195: {"stream":"atomusdt@depth@100ms","data":{"e":"depthUpdate","E":1618677428533,"s":"ATOMUSDT","U":71292154,"u":71292155,"b":[["25.15800000","39.66700000"],["25.14400000","0.00000000"]],"a":[]}}
1618677428.5121238: {"stream":"btcusdt@depth@100ms","data":{"e":"depthUpdate","E":1618677428533,"s":"BTCUSDT","U":372027062,"u":372027062,"b":[],"a":[["60503.55000000","0.08964300"]]}}
1618677428.512191: {"stream":"zrxusd@depth@100ms","data":{"e":"depthUpdate","E":1618677428533,"s":"ZRXUSD","U":51775951,"u":51775954,"b":[["2.0793","495.00000000"],["2.0759","0.00000000"]],"a":[]}}
1618677428.544749: {"stream":"omgusd@bookTicker","data":{"u":66532593,"s":"OMGUSD","b":"9.5379","B":"88.05000000","a":"9.5563","A":"132.39000000"}}
1618677428.556426: {"stream":"btcusdt@bookTicker","data":{"u":372027065,"s":"BTCUSDT","b":"60490.81000000","B":"0.07784100","a":"60500.00000000","A":"0.09485400"}}
1618677428.597787: {"stream":"btcusdt@bookTicker","data":{"u":372027068,"s":"BTCUSDT","b":"60490.81000000","B":"0.07784100","a":"60499.99000000","A":"0.09316900"}}
1618677428.611459: {"stream":"zrxusd@depth@100ms","data":{"e":"depthUpdate","E":1618677428633,"s":"ZRXUSD","U":51775955,"u":51775956,"b":[["2.0793","0.00000000"],["2.0759","495.00000000"]],"a":[]}}
1618677428.611635: {"stream":"bchusdt@depth@100ms","data":{"e":"depthUpdate","E":1618677428633,"s":"BCHUSDT","U":123518182,"u":123518182,"b":[],"a":[["1054.41000000","0.28452000"]]}}
1618677428.611708: {"stream":"omgusd@depth@100ms","data":{"e":"depthUpdate","E":1618677428633,"s":"OMGUSD","U":66532593,"u":66532593,"b":[],"a":[["9.5562","0.00000000"]]}}
1618677428.6117718: {"stream":"btcusdt@depth@100ms","data":{"e":"depthUpdate","E":1618677428633,"s":"BTCUSDT","U":372027063,"u":372027069,"b":[["60418.24000000","0.00000000"]],"a":[["60499.99000000","0.09316900"],["60500.00000000","0.00168500"],["60503.54000000","0.00555600"],["60503.55000000","0.00000000"]]}}
1618677428.618521: {"stream":"btcusdt@bookTicker","data":{"u":372027070,"s":"BTCUSDT","b":"60490.81000000","B":"0.07784100","a":"60499.98000000","A":"0.00555600"}}
1618677428.6192482: {"stream":"btcusdt@bookTicker","data":{"u":372027073,"s":"BTCUSDT","b":"60490.81000000","B":"0.07784100","a":"60499.98000000","A":"0.09872500"}}
1618677428.639901: {"stream":"btcusdt@bookTicker","data":{"u":372027077,"s":"BTCUSDT","b":"60490.81000000","B":"0.07784100","a":"60499.98000000","A":"0.00555600"}}
1618677428.6428869: {"stream":"btcusdt@bookTicker","data":{"u":372027078,"s":"BTCUSDT","b":"60490.81000000","B":"0.07784100","a":"60499.97000000","A":"0.09316900"}}
1618677428.654909: {"stream":"btcusdt@bookTicker","data":{"u":372027079,"s":"BTCUSDT","b":"60490.81000000","B":"0.07784100","a":"60499.98000000","A":"0.00555600"}}
1618677428.6549911: {"stream":"btcusdt@bookTicker","data":{"u":372027080,"s":"BTCUSDT","b":"60490.81000000","B":"0.07784100","a":"60499.96000000","A":"0.09316900"}}
1618677428.6674979: {"stream":"btcusdt@bookTicker","data":{"u":372027082,"s":"BTCUSDT","b":"60490.81000000","B":"0.07784100","a":"60499.98000000","A":"0.00555600"}}
1618677428.67203: {"stream":"btcusdt@bookTicker","data":{"u":372027084,"s":"BTCUSDT","b":"60490.81000000","B":"0.07784100","a":"60499.95000000","A":"0.09316900"}}
1618677428.687867: {"stream":"btcusdt@bookTicker","data":{"u":372027088,"s":"BTCUSDT","b":"60490.81000000","B":"0.07784100","a":"60499.98000000","A":"0.00555600"}}
1618677428.690814: {"stream":"btcusdt@bookTicker","data":{"u":372027089,"s":"BTCUSDT","b":"60490.81000000","B":"0.07784100","a":"60499.94000000","A":"0.09316900"}}
1618677428.710403: {"stream":"btcusdt@bookTicker","data":{"u":372027092,"s":"BTCUSDT","b":"60490.81000000","B":"0.07784100","a":"60499.98000000","A":"0.09872500"}}
1618677428.7104871: {"stream":"zrxusd@depth@100ms","data":{"e":"depthUpdate","E":1618677428733,"s":"ZRXUSD","U":51775957,"u":51775958,"b":[["2.0759","0.00000000"]],"a":[["2.0937","0.00000000"]]}}
1618677428.711006: {"stream":"xlmusdt@depth@100ms","data":{"e":"depthUpdate","E":1618677428733,"s":"XLMUSDT","U":134557904,"u":134557907,"b":[["0.60068000","0.00000000"],["0.60053000","0.00000000"],["0.60040000","3320.70000000"]],"a":[["0.60219000","0.00000000"]]}}
1618677428.7111092: {"stream":"btcusdt@depth@100ms","data":{"e":"depthUpdate","E":1618677428733,"s":"BTCUSDT","U":372027070,"u":372027092,"b":[["60482.38000000","0.00000000"],["60474.97000000","0.07987000"],["60453.13000000","0.13217600"],["60366.27000000","0.08331200"]],"a":[["60499.94000000","0.00000000"],["60499.95000000","0.00000000"],["60499.96000000","0.00000000"],["60499.97000000","0.00000000"],["60499.98000000","0.09872500"],["60499.99000000","0.00000000"],["60500.38000000","0.07991000"],["60503.54000000","0.00000000"],["60505.22000000","0.09913200"],["60510.22000000","0.00000000"],["60515.39000000","0.13217600"],["60533.35000000","0.00000000"]]}}
1618677428.718854: {"stream":"btcusdt@bookTicker","data":{"u":372027094,"s":"BTCUSDT","b":"60490.81000000","B":"0.07784100","a":"60499.98000000","A":"0.09316900"}}
1618677428.722924: {"stream":"btcusdt@bookTicker","data":{"u":372027095,"s":"BTCUSDT","b":"60490.81000000","B":"0.07784100","a":"60499.97000000","A":"0.00555600"}}
1618677428.727402: {"stream":"btcusdt@bookTicker","data":{"u":372027098,"s":"BTCUSDT","b":"60490.81000000","B":"0.07784100","a":"60499.97000000","A":"0.09872500"}}
1618677428.730591: {"stream":"usdtusd@bookTicker","data":{"u":34057436,"s":"USDTUSD","b":"1.0010","B":"218449.96000000","a":"1.0011","A":"13361.76000000"}}
1618677428.7400131: {"stream":"btcusdt@bookTicker","data":{"u":372027099,"s":"BTCUSDT","b":"60490.81000000","B":"0.07784100","a":"60499.97000000","A":"0.00555600"}}
1618677428.74139: {"stream":"btcusdt@bookTicker","data":{"u":372027100,"s":"BTCUSDT","b":"60490.81000000","B":"0.07784100","a":"60499.96000000","A":"0.09316900"}}
1618677428.7682922: {"stream":"btcusdt@bookTicker","data":{"u":372027101,"s":"BTCUSDT","b":"60490.81000000","B":"0.07784100","a":"60499.97000000","A":"0.00555600"}}
1618677428.770391: {"stream":"btcusdt@bookTicker","data":{"u":372027102,"s":"BTCUSDT","b":"60490.81000000","B":"0.07784100","a":"60499.95000000","A":"0.09316900"}}
1618677428.790006: {"stream":"btcusdt@bookTicker","data":{"u":372027105,"s":"BTCUSDT","b":"60490.81000000","B":"0.07784100","a":"60499.94000000","A":"0.09316900"}}
1618677428.7957351: {"stream":"btcusdt@bookTicker","data":{"u":372027107,"s":"BTCUSDT","b":"60490.81000000","B":"0.07784100","a":"60497.68000000","A":"0.08050000"}}
1618677428.806997: {"stream":"btcusdt@bookTicker","data":{"u":372027109,"s":"BTCUSDT","b":"60490.81000000","B":"0.00000100","a":"60497.68000000","A":"0.08050000"}}
1618677428.810386: {"stream":"btcusdt@aggTrade","data":{"e":"aggTrade","E":1618677428829,"s":"BTCUSDT","a":3612250,"p":"60490.81000000","q":"0.07784000","f":3667501,"l":3667501,"T":1618677428828,"m":true,"M":true}}
1618677428.814803: {"stream":"btcusdt@bookTicker","data":{"u":372027111,"s":"BTCUSDT","b":"60490.81000000","B":"0.00000100","a":"60497.67000000","A":"0.09316900"}}
1618677428.814921: {"stream":"ethbusd@depth@100ms","data":{"e":"depthUpdate","E":1618677428833,"s":"ETHBUSD","U":56401303,"u":56401303,"b":[["2358.70000000","0.00000000"]],"a":[]}}
1618677428.814999: {"stream":"xlmusdt@depth@100ms","data":{"e":"depthUpdate","E":1618677428833,"s":"XLMUSDT","U":134557908,"u":134557908,"b":[["0.60084000","0.00000000"]],"a":[]}}
1618677428.815047: {"stream":"btcusdt@depth@100ms","data":{"e":"depthUpdate","E":1618677428833,"s":"BTCUSDT","U":372027093,"u":372027111,"b":[["60490.81000000","0.00000100"],["60484.09000000","0.00000000"],["60474.98000000","0.00555600"],["60474.97000000","0.00000000"],["60472.27000000","0.08028000"]],"a":[["60497.67000000","0.09316900"],["60497.68000000","0.08050000"],["60499.94000000","0.00000000"],["60499.95000000","0.00000000"],["60499.96000000","0.00000000"],["60499.97000000","0.00555600"],["60499.98000000","0.00000000"],["60500.38000000","0.00000000"]]}}
1618677428.815176: {"stream":"zrxusd@depth@100ms","data":{"e":"depthUpdate","E":1618677428833,"s":"ZRXUSD","U":51775959,"u":51775959,"b":[["2.0793","495.00000000"]],"a":[]}}
1618677428.815216: {"stream":"usdtusd@depth@100ms","data":{"e":"depthUpdate","E":1618677428833,"s":"USDTUSD","U":34057436,"u":34057438,"b":[],"a":[["1.0011","13361.76000000"],["1.0013","20251.83000000"],["1.0015","741778.39000000"]]}}
1618677428.815255: {"stream":"bchusdt@depth@100ms","data":{"e":"depthUpdate","E":1618677428833,"s":"BCHUSDT","U":123518183,"u":123518183,"b":[["1051.22000000","0.00000000"]],"a":[]}}
1618677428.823779: {"stream":"btcusdt@bookTicker","data":{"u":372027114,"s":"BTCUSDT","b":"60490.81000000","B":"0.00000100","a":"60497.66000000","A":"0.00555600"}}
1618677428.823861: {"stream":"btcusdt@bookTicker","data":{"u":372027115,"s":"BTCUSDT","b":"60484.08000000","B":"0.03060800","a":"60497.66000000","A":"0.00555600"}}
1618677428.8238962: {"stream":"btcusdt@bookTicker","data":{"u":372027117,"s":"BTCUSDT","b":"60484.08000000","B":"0.03060800","a":"60497.66000000","A":"0.09872500"}}
1618677428.8278458: {"stream":"btcusdt@bookTicker","data":{"u":372027119,"s":"BTCUSDT","b":"60484.08000000","B":"0.03060800","a":"60494.49000000","A":"0.03376600"}}
1618677428.912684: {"stream":"btcusdt@depth@100ms","data":{"e":"depthUpdate","E":1618677428933,"s":"BTCUSDT","U":372027112,"u":372027120,"b":[["60490.81000000","0.00000000"],["60474.98000000","0.00000000"],["60309.86000000","0.27373800"]],"a":[["60494.49000000","0.03376600"],["60497.66000000","0.09872500"],["60497.67000000","0.00000000"],["60499.97000000","0.00000000"],["60798.16000000","0.00000000"]]}}
1618677428.912947: {"stream":"bchusdt@depth@100ms","data":{"e":"depthUpdate","E":1618677428933,"s":"BCHUSDT","U":123518184,"u":123518185,"b":[["1051.73000000","0.91573000"]],"a":[["1054.41000000","0.00000000"]]}}
1618677428.914639: {"stream":"btcusdt@bookTicker","data":{"u":372027122,"s":"BTCUSDT","b":"60484.08000000","B":"0.03060800","a":"60494.49000000","A":"0.12693500"}}
1618677428.9187021: {"stream":"btcusdt@bookTicker","data":{"u":372027125,"s":"BTCUSDT","b":"60484.08000000","B":"0.03060800","a":"60494.48000000","A":"0.00555600"}}
1618677428.9468539: {"stream":"btcusdt@bookTicker","data":{"u":372027128,"s":"BTCUSDT","b":"60484.08000000","B":"0.03060800","a":"60494.48000000","A":"0.09872500"}}
1618677429.0130079: {"stream":"zrxusd@depth@100ms","data":{"e":"depthUpdate","E":1618677429033,"s":"ZRXUSD","U":51775960,"u":51775960,"b":[],"a":[["2.0938","628.84000000"]]}}
1618677429.0131588: {"stream":"btcusdt@depth@100ms","data":{"e":"depthUpdate","E":1618677429033,"s":"BTCUSDT","U":372027121,"u":372027129,"b":[["60474.70000000","0.00555600"]],"a":[["60494.48000000","0.09872500"],["60494.49000000","0.03376600"],["60497.66000000","0.00000000"],["60498.44000000","0.09914200"],["60505.22000000","0.00000000"]]}}
1618677429.013311: {"stream":"bchusdt@aggTrade","data":{"e":"aggTrade","E":1618677429034,"s":"BCHUSDT","a":724815,"p":"1052.57000000","q":"0.02758000","f":736394,"l":736394,"T":1618677429034,"m":true,"M":true}}
1618677429.013388: {"stream":"bchusdt@bookTicker","data":{"u":123518187,"s":"BCHUSDT","b":"1052.02000000","B":"0.94379000","a":"1053.63000000","A":"0.75962000"}}
1618677429.018558: {"stream":"btcusdt@bookTicker","data":{"u":372027131,"s":"BTCUSDT","b":"60484.08000000","B":"0.03060800","a":"60494.48000000","A":"0.09316900"}}
1618677429.018642: {"stream":"btcusdt@bookTicker","data":{"u":372027133,"s":"BTCUSDT","b":"60484.08000000","B":"0.03060800","a":"60494.47000000","A":"0.00555600"}}
1618677429.034577: {"stream":"btcusdt@bookTicker","data":{"u":372027135,"s":"BTCUSDT","b":"60484.08000000","B":"0.03060800","a":"60494.47000000","A":"0.09872500"}}
1618677429.089041: {"stream":"xlmusdt@bookTicker","data":{"u":134557911,"s":"XLMUSDT","b":"0.60130000","B":"1416.30000000","a":"0.60168000","A":"3322.20000000"}}
1618677429.1121979: {"stream":"xlmusdt@depth@100ms","data":{"e":"depthUpdate","E":1618677429133,"s":"XLMUSDT","U":134557909,"u":134557915,"b":[["0.60040000","0.00000000"],["0.60022000","3321.60000000"],["0.60012000","3322.20000000"]],"a":[["0.60168000","3322.20000000"],["0.60184000","3321.30000000"],["0.60202000","0.00000000"],["0.60335000","12118.00000000"]]}}
1618677429.112431: {"stream":"btcusdt@depth@100ms","data":{"e":"depthUpdate","E":1618677429133,"s":"BTCUSDT","U":372027130,"u":372027135,"b":[["60474.13000000","0.00000000"],["59945.22000000","2.80863300"]],"a":[["60494.47000000","0.09872500"],["60494.48000000","0.00000000"]]}}
1618677429.1125681: {"stream":"bchusdt@depth@100ms","data":{"e":"depthUpdate","E":1618677429133,"s":"BCHUSDT","U":123518186,"u":123518187,"b":[["1052.57000000","0.00000000"],["1051.72000000","0.00000000"]],"a":[]}}
1618677429.117883: {"stream":"btcusdt@bookTicker","data":{"u":372027136,"s":"BTCUSDT","b":"60484.08000000","B":"0.03060800","a":"60494.47000000","A":"0.09316900"}}
1618677429.1243489: {"stream":"btcusdt@bookTicker","data":{"u":372027137,"s":"BTCUSDT","b":"60484.08000000","B":"0.03060800","a":"60494.46000000","A":"0.00555600"}}
1618677429.135316: {"stream":"xlmusdt@bookTicker","data":{"u":134557917,"s":"XLMUSDT","b":"0.60130000","B":"1416.30000000","a":"0.60184000","A":"3321.30000000"}}
1618677429.137696: {"stream":"btcusdt@bookTicker","data":{"u":372027139,"s":"BTCUSDT","b":"60484.08000000","B":"0.03060800","a":"60494.46000000","A":"0.09867900"}}
1618677429.13778: {"stream":"xlmusdt@bookTicker","data":{"u":134557918,"s":"XLMUSDT","b":"0.60083000","B":"1315.60000000","a":"0.60184000","A":"3321.30000000"}}
1618677429.137815: {"stream":"xlmusdt@aggTrade","data":{"e":"aggTrade","E":1618677429160,"s":"XLMUSDT","a":849505,"p":"0.60130000","q":"1416.30000000","f":867866,"l":867866,"T":1618677429159,"m":true,"M":true}}
1618677429.150683: {"stream":"bchusdt@bookTicker","data":{"u":123518190,"s":"BCHUSDT","b":"1051.73000000","B":"0.91573000","a":"1053.63000000","A":"0.75962000"}}
1618677429.1771069: {"stream":"bchusdt@bookTicker","data":{"u":123518191,"s":"BCHUSDT","b":"1051.21000000","B":"0.64251000","a":"1053.63000000","A":"0.75962000"}}
1618677429.214842: {"stream":"xlmusdt@depth@100ms","data":{"e":"depthUpdate","E":1618677429234,"s":"XLMUSDT","U":134557916,"u":134557919,"b":[["0.60130000","0.00000000"],["0.60012000","0.00000000"]],"a":[["0.60168000","0.00000000"],["0.60259000","3460.00000000"]]}}
1618677429.2150478: {"stream":"btcusdt@depth@100ms","data":{"e":"depthUpdate","E":1618677429234,"s":"BTCUSDT","U":372027136,"u":372027140,"b":[["60454.78000000","0.08000000"]],"a":[["60494.46000000","0.09867900"],["60494.47000000","0.00000000"]]}}
1618677429.215175: {"stream":"bchusdt@depth@100ms","data":{"e":"depthUpdate","E":1618677429234,"s":"BCHUSDT","U":123518188,"u":123518192,"b":[["1052.02000000","0.00000000"],["1051.73000000","0.00000000"],["1051.71000000","0.00000000"],["1050.85000000","0.94929000"]],"a":[["1054.88000000","0.00000000"]]}}
1618677429.220544: {"stream":"btcusdt@bookTicker","data":{"u":372027141,"s":"BTCUSDT","b":"60484.08000000","B":"0.03060800","a":"60494.45000000","A":"0.00555600"}}
1618677429.261219: {"stream":"btcusdt@bookTicker","data":{"u":372027144,"s":"BTCUSDT","b":"60484.08000000","B":"0.03060800","a":"60494.45000000","A":"0.10071400"}}
1618677429.294726: {"stream":"btcusdt@bookTicker","data":{"u":372027145,"s":"BTCUSDT","b":"60484.08000000","B":"0.03060800","a":"60494.44000000","A":"0.09515800"}}
1618677429.3137338: {"stream":"ethbusd@depth@100ms","data":{"e":"depthUpdate","E":1618677429333,"s":"ETHBUSD","U":56401304,"u":56401305,"b":[["2360.05000000","0.00000000"],["2359.00000000","0.84677000"]],"a":[]}}
1618677429.3139148: {"stream":"btcusdt@depth@100ms","data":{"e":"depthUpdate","E":1618677429333,"s":"BTCUSDT","U":372027141,"u":372027147,"b":[],"a":[["60494.44000000","0.09515800"],["60494.45000000","0.00555600"],["60494.46000000","0.00000000"],["60522.18000000","0.00000000"]]}}
1618677429.314036: {"stream":"bchusdt@depth@100ms","data":{"e":"depthUpdate","E":1618677429333,"s":"BCHUSDT","U":123518193,"u":123518193,"b":[["1027.66000000","10.72498000"]],"a":[]}}
1618677429.314097: {"stream":"btcusdt@bookTicker","data":{"u":372027148,"s":"BTCUSDT","b":"60484.08000000","B":"0.03060800","a":"60494.43000000","A":"0.09515800"}}
1618677429.321357: {"stream":"btcusdt@bookTicker","data":{"u":372027150,"s":"BTCUSDT","b":"60484.08000000","B":"0.03060800","a":"60494.43000000","A":"0.10071400"}}
1618677429.335419: {"stream":"btcusdt@bookTicker","data":{"u":372027152,"s":"BTCUSDT","b":"60484.08000000","B":"0.03060800","a":"60494.43000000","A":"0.00555600"}}
1618677429.3986502: {"stream":"btcusdt@bookTicker","data":{"u":372027155,"s":"BTCUSDT","b":"60484.08000000","B":"0.03060800","a":"60492.21000000","A":"0.08004000"}}
1618677429.4057028: {"stream":"btcusdt@bookTicker","data":{"u":372027157,"s":"BTCUSDT","b":"60484.08000000","B":"0.03060800","a":"60492.20000000","A":"0.10508300"}}
1618677429.412711: {"stream":"xlmusdt@depth@100ms","data":{"e":"depthUpdate","E":1618677429433,"s":"XLMUSDT","U":134557920,"u":134557921,"b":[["0.60004000","3322.60000000"]],"a":[["0.60195000","3321.30000000"]]}}
1618677429.412879: {"stream":"btcusdt@depth@100ms","data":{"e":"depthUpdate","E":1618677429433,"s":"BTCUSDT","U":372027148,"u":372027157,"b":[["60472.27000000","0.00000000"],["60466.80000000","0.07987000"]],"a":[["60492.20000000","0.10508300"],["60492.21000000","0.08004000"],["60494.43000000","0.00555600"],["60494.44000000","0.00000000"],["60494.45000000","0.00000000"],["60497.68000000","0.00000000"]]}}
1618677429.41308: {"stream":"zrxusd@depth@100ms","data":{"e":"depthUpdate","E":1618677429433,"s":"ZRXUSD","U":51775961,"u":51775964,"b":[["2.0803","0.00000000"],["2.0793","0.00000000"],["2.0759","495.00000000"]],"a":[["2.0939","0.00000000"]]}}
1618677429.417129: {"stream":"btcusdt@bookTicker","data":{"u":372027159,"s":"BTCUSDT","b":"60484.08000000","B":"0.03060800","a":"60492.19000000","A":"0.10508300"}}
1618677429.4213068: {"stream":"btcusdt@bookTicker","data":{"u":372027162,"s":"BTCUSDT","b":"60484.08000000","B":"0.03060800","a":"60492.19000000","A":"0.11063900"}}
1618677429.429997: {"stream":"btcusdt@bookTicker","data":{"u":372027164,"s":"BTCUSDT","b":"60484.08000000","B":"0.03060800","a":"60492.19000000","A":"0.00555600"}}
1618677429.460117: {"stream":"btcusdt@aggTrade","data":{"e":"aggTrade","E":1618677429477,"s":"BTCUSDT","a":3612251,"p":"60484.08000000","q":"0.01253000","f":3667502,"l":3667502,"T":1618677429476,"m":true,"M":true}}
1618677429.4625669: {"stream":"btcusdt@bookTicker","data":{"u":372027169,"s":"BTCUSDT","b":"60484.08000000","B":"0.01807800","a":"60492.19000000","A":"0.00555600"}}
1618677429.518813: {"stream":"xlmusdt@depth@100ms","data":{"e":"depthUpdate","E":1618677429535,"s":"XLMUSDT","U":134557922,"u":134557922,"b":[["0.60020000","102.90000000"]],"a":[]}}
1618677429.518962: {"stream":"btcusdt@depth@100ms","data":{"e":"depthUpdate","E":1618677429535,"s":"BTCUSDT","U":372027158,"u":372027170,"b":[["60484.08000000","0.01807800"],["60465.49000000","0.00000000"],["60444.32000000","0.13219500"]],"a":[["60492.19000000","0.00555600"],["60494.43000000","0.00000000"],["60505.81000000","0.13219500"],["60506.33000000","0.08000000"],["60506.36000000","0.00000000"],["60525.32000000","0.00000000"],["60530.47000000","0.00866000"],["60560.92000000","0.00000000"]]}}
1618677429.519147: {"stream":"omgusd@depth@100ms","data":{"e":"depthUpdate","E":1618677429536,"s":"OMGUSD","U":66532594,"u":66532595,"b":[],"a":[["9.5665","0.00000000"],["9.5804","803.50000000"]]}}
1618677429.5192: {"stream":"zrxusd@depth@100ms","data":{"e":"depthUpdate","E":1618677429536,"s":"ZRXUSD","U":51775965,"u":51775966,"b":[["2.0780","2000.00000000"]],"a":[["2.0916","2000.00000000"]]}}
1618677429.5972219: {"stream":"btcusdt@aggTrade","data":{"e":"aggTrade","E":1618677429617,"s":"BTCUSDT","a":3612252,"p":"60484.08000000","q":"0.01807000","f":3667503,"l":3667503,"T":1618677429616,"m":true,"M":true}}
1618677429.602438: {"stream":"btcusdt@bookTicker","data":{"u":372027174,"s":"BTCUSDT","b":"60484.08000000","B":"0.00000800","a":"60492.19000000","A":"0.00555600"}}
1618677429.6025229: {"stream":"bchusdt@bookTicker","data":{"u":123518195,"s":"BCHUSDT","b":"1051.21000000","B":"0.64251000","a":"1053.62000000","A":"0.28473000"}}
1618677429.6120598: {"stream":"zrxusd@depth@100ms","data":{"e":"depthUpdate","E":1618677429633,"s":"ZRXUSD","U":51775967,"u":51775967,"b":[],"a":[["2.0938","0.00000000"]]}}
1618677429.619536: {"stream":"btcusdt@depth@100ms","data":{"e":"depthUpdate","E":1618677429635,"s":"BTCUSDT","U":372027171,"u":372027175,"b":[["60484.08000000","0.00000800"],["60474.70000000","0.00000000"],["60466.81000000","0.00582400"],["60423.68000000","0.02098900"],["60366.27000000","0.00000000"]],"a":[]}}
1618677429.619749: {"stream":"ethbusd@depth@100ms","data":{"e":"depthUpdate","E":1618677429635,"s":"ETHBUSD","U":56401306,"u":56401306,"b":[],"a":[["2367.12000000","4.49999000"]]}}
1618677429.619841: {"stream":"bchusdt@depth@100ms","data":{"e":"depthUpdate","E":1618677429635,"s":"BCHUSDT","U":123518194,"u":123518195,"b":[["1050.61000000","0.28555000"]],"a":[["1053.62000000","0.28473000"]]}}
1618677429.710173: {"stream":"btcusdt@bookTicker","data":{"u":372027182,"s":"BTCUSDT","b":"60484.08000000","B":"0.00000800","a":"60487.29000000","A":"0.08007000"}}
1618677429.7183518: {"stream":"ethbusd@depth@100ms","data":{"e":"depthUpdate","E":1618677429736,"s":"ETHBUSD","U":56401307,"u":56401307,"b":[],"a":[["2424.31000000","0.00000000"]]}}
1618677429.718503: {"stream":"xlmusdt@depth@100ms","data":{"e":"depthUpdate","E":1618677429736,"s":"XLMUSDT","U":134557923,"u":134557928,"b":[["0.59366000","0.00000000"],["0.59281000","0.00000000"],["0.59216000","0.00000000"],["0.59140000","0.00000000"],["0.59072000","0.00000000"],["0.58999000","0.00000000"]],"a":[]}}
1618677429.718648: {"stream":"btcusdt@depth@100ms","data":{"e":"depthUpdate","E":1618677429736,"s":"BTCUSDT","U":372027176,"u":372027182,"b":[["60474.69000000","0.00000000"],["60471.82000000","0.00000000"],["60466.80000000","0.00000000"],["60293.45000000","0.22669100"]],"a":[["60487.29000000","0.08007000"],["60492.21000000","0.00000000"],["60498.44000000","0.00000000"]]}}
1618677429.71875: {"stream":"zrxusd@depth@100ms","data":{"e":"depthUpdate","E":1618677429736,"s":"ZRXUSD","U":51775968,"u":51775969,"b":[["2.0781","495.00000000"],["2.0759","0.00000000"]],"a":[]}}
1618677429.7279968: {"stream":"btcusdt@bookTicker","data":{"u":372027185,"s":"BTCUSDT","b":"60484.08000000","B":"0.00000800","a":"60487.28000000","A":"0.00582400"}}
1618677429.7280798: {"stream":"btcusdt@bookTicker","data":{"u":372027186,"s":"BTCUSDT","b":"60484.08000000","B":"0.00000800","a":"60487.28000000","A":"0.11090700"}}
1618677429.738333: {"stream":"btcusdt@bookTicker","data":{"u":372027187,"s":"BTCUSDT","b":"60484.08000000","B":"0.00000800","a":"60487.28000000","A":"0.00582400"}}
1618677429.767987: {"stream":"xlmusdt@bookTicker","data":{"u":134557932,"s":"XLMUSDT","b":"0.60044000","B":"499.60000000","a":"0.60184000","A":"3321.30000000"}}
1618677429.811724: {"stream":"ethbusd@bookTicker","data":{"u":56401311,"s":"ETHBUSD","b":"2360.65000000","B":"0.09738000","a":"2363.79000000","A":"1.79212000"}}
1618677429.81661: {"stream":"ethbusd@depth@100ms","data":{"e":"depthUpdate","E":1618677429835,"s":"ETHBUSD","U":56401308,"u":56401311,"b":[["2354.71000000","0.00000000"],["2351.94000000","0.17700000"]],"a":[["2363.79000000","1.79212000"],["2452.17000000","0.00000000"]]}}
1618677429.8167648: {"stream":"xlmusdt@depth@100ms","data":{"e":"depthUpdate","E":1618677429835,"s":"XLMUSDT","U":134557929,"u":134557946,"b":[["0.60083000","0.00000000"],["0.60029000","0.00000000"],["0.60020000","0.00000000"],["0.59985000","0.00000000"],["0.59941000","0.00000000"],["0.59896000","0.00000000"],["0.59836000","0.00000000"],["0.59767000","0.00000000"],["0.59711000","0.00000000"],["0.59641000","0.00000000"],["0.59565000","0.00000000"],["0.59490000","0.00000000"],["0.59423000","0.00000000"],["0.58924000","0.00000000"],["0.58850000","0.00000000"],["0.58777000","0.00000000"],["0.58695000","0.00000000"]],"a":[["0.60201000","0.00000000"]]}}
1618677429.8169549: {"stream":"btcusdt@depth@100ms","data":{"e":"depthUpdate","E":1618677429835,"s":"BTCUSDT","U":372027183,"u":372027188,"b":[["60461.90000000","0.07960000"],["60454.78000000","0.00000000"]],"a":[["60487.28000000","0.00582400"],["60492.19000000","0.00000000"]]}}
1618677429.817031: {"stream":"xlmusdt@bookTicker","data":{"u":134557947,"s":"XLMUSDT","b":"0.60044000","B":"499.60000000","a":"0.60183000","A":"1924.00000000"}}
1618677429.838746: {"stream":"btcusdt@bookTicker","data":{"u":372027189,"s":"BTCUSDT","b":"60466.81000000","B":"0.00582400","a":"60487.28000000","A":"0.00582400"}}
1618677429.845771: {"stream":"btcusdt@bookTicker","data":{"u":372027191,"s":"BTCUSDT","b":"60466.81000000","B":"0.00582400","a":"60484.09000000","A":"0.02523900"}}
1618677429.861016: {"stream":"btcusdt@bookTicker","data":{"u":372027193,"s":"BTCUSDT","b":"60466.81000000","B":"0.00582400","a":"60484.09000000","A":"0.13032200"}}
1618677429.915045: {"stream":"atomusdt@depth@100ms","data":{"e":"depthUpdate","E":1618677429934,"s":"ATOMUSDT","U":71292156,"u":71292157,"b":[],"a":[["25.21500000","64.80000000"],["25.25200000","0.00000000"]]}}
1618677429.915224: {"stream":"ethbusd@depth@100ms","data":{"e":"depthUpdate","E":1618677429934,"s":"ETHBUSD","U":56401312,"u":56401315,"b":[],"a":[["2364.65000000","0.84683000"],["2365.20000000","0.12800000"],["2365.46000000","0.50000000"],["2365.74000000","0.00000000"]]}}
1618677429.915354: {"stream":"xlmusdt@depth@100ms","data":{"e":"depthUpdate","E":1618677429934,"s":"XLMUSDT","U":134557947,"u":134557947,"b":[],"a":[["0.60183000","1924.00000000"]]}}
1618677429.9153962: {"stream":"btcusdt@depth@100ms","data":{"e":"depthUpdate","E":1618677429934,"s":"BTCUSDT","U":372027189,"u":372027193,"b":[["60484.08000000","0.00000000"],["60279.27000000","0.28817300"]],"a":[["60484.09000000","0.13032200"],["60784.22000000","0.00000000"]]}}
1618677429.915468: {"stream":"zrxusd@depth@100ms","data":{"e":"depthUpdate","E":1618677429934,"s":"ZRXUSD","U":51775970,"u":51775970,"b":[],"a":[["2.0936","600.09000000"]]}}
1618677429.92101: {"stream":"btcusdt@bookTicker","data":{"u":372027194,"s":"BTCUSDT","b":"60464.63000000","B":"0.02280400","a":"60484.09000000","A":"0.13032200"}}
1618677429.9271822: {"stream":"btcusdt@bookTicker","data":{"u":372027196,"s":"BTCUSDT","b":"60464.63000000","B":"0.02280400","a":"60484.08000000","A":"0.00582400"}}
1618677429.943959: {"stream":"bchusdt@bookTicker","data":{"u":123518196,"s":"BCHUSDT","b":"1051.21000000","B":"0.64251000","a":"1053.61000000","A":"0.91686000"}}
1618677429.948669: {"stream":"btcusdt@bookTicker","data":{"u":372027200,"s":"BTCUSDT","b":"60464.63000000","B":"0.02280400","a":"60484.08000000","A":"0.11090700"}}
1618677430.024738: {"stream":"xlmusdt@depth@100ms","data":{"e":"depthUpdate","E":1618677430034,"s":"XLMUSDT","U":134557948,"u":134557952,"b":[["0.59942000","0.00000000"],["0.59837000","0.00000000"],["0.59739000","15578.00000000"]],"a":[["0.60195000","0.00000000"]]}}
1618677430.0249422: {"stream":"btcusdt@depth@100ms","data":{"e":"depthUpdate","E":1618677430034,"s":"BTCUSDT","U":372027194,"u":372027200,"b":[["60466.81000000","0.00000000"],["60461.91000000","0.00582400"],["60444.93000000","0.08000000"]],"a":[["60484.08000000","0.11090700"],["60484.09000000","0.02523900"],["60487.28000000","0.00000000"]]}}
1618677430.025068: {"stream":"ethbusd@depth@100ms","data":{"e":"depthUpdate","E":1618677430034,"s":"ETHBUSD","U":56401316,"u":56401316,"b":[],"a":[["2367.12000000","0.00000000"]]}}
1618677430.0251122: {"stream":"bchusdt@depth@100ms","data":{"e":"depthUpdate","E":1618677430034,"s":"BCHUSDT","U":123518196,"u":123518199,"b":[["1050.85000000","0.00000000"],["1050.61000000","0.00000000"]],"a":[["1053.61000000","0.91686000"],["1053.62000000","0.00000000"]]}}
1618677430.025179: {"stream":"btcusdt@bookTicker","data":{"u":372027201,"s":"BTCUSDT","b":"60464.63000000","B":"0.02280400","a":"60484.08000000","A":"0.10508300"}}
1618677430.025203: {"stream":"btcusdt@bookTicker","data":{"u":372027202,"s":"BTCUSDT","b":"60464.63000000","B":"0.02280400","a":"60484.07000000","A":"0.00582400"}}
1618677430.027759: {"stream":"bchusdt@bookTicker","data":{"u":123518202,"s":"BCHUSDT","b":"1051.21000000","B":"0.64251000","a":"1053.60000000","A":"0.17534000"}}
1618677430.033275: {"stream":"xlmusdt@bookTicker","data":{"u":134557953,"s":"XLMUSDT","b":"0.60044000","B":"499.60000000","a":"0.60170000","A":"3322.20000000"}}
1618677430.047619: {"stream":"btcusdt@bookTicker","data":{"u":372027204,"s":"BTCUSDT","b":"60464.63000000","B":"0.02280400","a":"60484.07000000","A":"0.11090700"}}
1618677430.076127: {"stream":"bchusdt@aggTrade","data":{"e":"aggTrade","E":1618677430096,"s":"BCHUSDT","a":724816,"p":"1051.21000000","q":"0.62217000","f":736395,"l":736395,"T":1618677430095,"m":true,"M":true}}
1618677430.076242: {"stream":"bchusdt@bookTicker","data":{"u":123518204,"s":"BCHUSDT","b":"1051.21000000","B":"0.02034000","a":"1053.60000000","A":"0.17534000"}}
1618677430.080983: {"stream":"bchusdt@aggTrade","data":{"e":"aggTrade","E":1618677430099,"s":"BCHUSDT","a":724817,"p":"1051.21000000","q":"0.02034000","f":736396,"l":736396,"T":1618677430099,"m":true,"M":true}}
1618677430.081054: {"stream":"bchusdt@bookTicker","data":{"u":123518206,"s":"BCHUSDT","b":"1050.60000000","B":"2.00724000","a":"1053.60000000","A":"0.17534000"}}
1618677430.091248: {"stream":"btcusdt@bookTicker","data":{"u":372027208,"s":"BTCUSDT","b":"60464.63000000","B":"0.02280400","a":"60484.07000000","A":"0.00582400"}}
1618677430.125333: {"stream":"bchusdt@depth@100ms","data":{"e":"depthUpdate","E":1618677430141,"s":"BCHUSDT","U":123518200,"u":123518207,"b":[["1051.21000000","0.00000000"],["1050.24000000","0.00000000"],["1049.84000000","0.95015000"]],"a":[["1053.60000000","0.17534000"],["1053.97000000","0.94955000"],["1054.42000000","0.00000000"],["1055.28000000","0.00000000"]]}}
1618677430.1255: {"stream":"xlmusdt@depth@100ms","data":{"e":"depthUpdate","E":1618677430141,"s":"XLMUSDT","U":134557953,"u":134557953,"b":[],"a":[["0.60170000","3322.20000000"]]}}
1618677430.12555: {"stream":"btcusdt@depth@100ms","data":{"e":"depthUpdate","E":1618677430141,"s":"BTCUSDT","U":372027201,"u":372027209,"b":[["60444.87000000","0.00000000"],["60410.27000000","0.00496600"],["60394.27000000","0.01000000"]],"a":[["60484.07000000","0.00582400"],["60484.08000000","0.00000000"],["60570.40000000","0.00000000"]]}}
1618677430.125637: {"stream":"zrxusd@depth@100ms","data":{"e":"depthUpdate","E":1618677430141,"s":"ZRXUSD","U":51775971,"u":51775971,"b":[],"a":[["2.0936","0.00000000"]]}}
1618677430.1413891: {"stream":"btcusdt@bookTicker","data":{"u":372027211,"s":"BTCUSDT","b":"60464.64000000","B":"0.00582400","a":"60484.07000000","A":"0.00582400"}}
1618677430.151511: {"stream":"atomusdt@bookTicker","data":{"u":71292158,"s":"ATOMUSDT","b":"25.15100000","B":"32.03800000","a":"25.20100000","A":"1.80500000"}}
1618677430.215227: {"stream":"ethbusd@depth@100ms","data":{"e":"depthUpdate","E":1618677430234,"s":"ETHBUSD","U":56401317,"u":56401317,"b":[],"a":[["2365.46000000","0.00000000"]]}}
1618677430.21538: {"stream":"atomusdt@depth@100ms","data":{"e":"depthUpdate","E":1618677430234,"s":"ATOMUSDT","U":71292158,"u":71292159,"b":[["25.15800000","0.00000000"],["25.14400000","39.68900000"]],"a":[]}}
1618677430.215477: {"stream":"xlmusdt@depth@100ms","data":{"e":"depthUpdate","E":1618677430234,"s":"XLMUSDT","U":134557954,"u":134557954,"b":[["0.60006000","102.90000000"]],"a":[]}}
1618677430.215539: {"stream":"btcusdt@depth@100ms","data":{"e":"depthUpdate","E":1618677430234,"s":"BTCUSDT","U":372027210,"u":372027211,"b":[["60464.64000000","0.00582400"],["60461.91000000","0.00000000"]],"a":[]}}
1618677430.3125918: {"stream":"atomusdt@depth@100ms","data":{"e":"depthUpdate","E":1618677430334,"s":"ATOMUSDT","U":71292160,"u":71292160,"b":[],"a":[["25.20800000","0.00000000"]]}}
1618677430.3127449: {"stream":"zrxusd@depth@100ms","data":{"e":"depthUpdate","E":1618677430334,"s":"ZRXUSD","U":51775972,"u":51775972,"b":[],"a":[["2.0927","622.03000000"]]}}
1618677430.416708: {"stream":"btcusdt@depth@100ms","data":{"e":"depthUpdate","E":1618677430437,"s":"BTCUSDT","U":372027212,"u":372027213,"b":[["60444.32000000","0.00000000"]],"a":[["60515.39000000","0.00000000"]]}}
1618677430.416884: {"stream":"bchusdt@depth@100ms","data":{"e":"depthUpdate","E":1618677430437,"s":"BCHUSDT","U":123518208,"u":123518208,"b":[],"a":[["1054.44000000","6.00000000"]]}}
1618677430.446412: {"stream":"omgusd@bookTicker","data":{"u":66532596,"s":"OMGUSD","b":"9.5355","B":"209.41000000","a":"9.5563","A":"132.39000000"}}
1618677430.512838: {"stream":"xlmusdt@depth@100ms","data":{"e":"depthUpdate","E":1618677430534,"s":"XLMUSDT","U":134557955,"u":134557956,"b":[],"a":[["0.60213000","498.20000000"],["0.60260000","0.00000000"]]}}
1618677430.5130181: {"stream":"btcusdt@depth@100ms","data":{"e":"depthUpdate","E":1618677430534,"s":"BTCUSDT","U":372027214,"u":372027218,"b":[["60458.71000000","0.09916200"],["60435.47000000","0.13221600"]],"a":[["60486.52000000","0.09916200"],["60492.20000000","0.00000000"],["60496.69000000","0.13221600"]]}}
1618677430.51317: {"stream":"ethbusd@depth@100ms","data":{"e":"depthUpdate","E":1618677430534,"s":"ETHBUSD","U":56401318,"u":56401319,"b":[["2359.47000000","0.00000000"],["2358.46000000","0.84696000"]],"a":[]}}
1618677430.513528: {"stream":"omgusd@depth@100ms","data":{"e":"depthUpdate","E":1618677430534,"s":"OMGUSD","U":66532596,"u":66532597,"b":[["9.5379","0.00000000"],["9.1471","1176.40000000"]],"a":[]}}
1618677430.598392: {"stream":"omgusd@bookTicker","data":{"u":66532599,"s":"OMGUSD","b":"9.5295","B":"432.34000000","a":"9.5563","A":"132.39000000"}}
1618677430.613596: {"stream":"usdtusd@depth@100ms","data":{"e":"depthUpdate","E":1618677430636,"s":"USDTUSD","U":34057439,"u":34057439,"b":[],"a":[["1.0015","741509.15000000"]]}}
1618677430.618508: {"stream":"ethbusd@depth@100ms","data":{"e":"depthUpdate","E":1618677430640,"s":"ETHBUSD","U":56401320,"u":56401322,"b":[["2360.64000000","0.00000000"]],"a":[["2364.64000000","0.13003000"],["2365.20000000","0.00000000"]]}}
1618677430.6187: {"stream":"bchusdt@depth@100ms","data":{"e":"depthUpdate","E":1618677430640,"s":"BCHUSDT","U":123518209,"u":123518209,"b":[],"a":[["1054.44000000","0.00000000"]]}}
1618677430.619412: {"stream":"omgusd@depth@100ms","data":{"e":"depthUpdate","E":1618677430640,"s":"OMGUSD","U":66532598,"u":66532599,"b":[["9.5355","0.00000000"]],"a":[["9.5651","0.00000000"]]}}
1618677430.619549: {"stream":"btcusdt@depth@100ms","data":{"e":"depthUpdate","E":1618677430640,"s":"BTCUSDT","U":372027219,"u":372027219,"b":[],"a":[["60506.33000000","0.00000000"]]}}
1618677430.619623: {"stream":"zrxusd@depth@100ms","data":{"e":"depthUpdate","E":1618677430640,"s":"ZRXUSD","U":51775973,"u":51775973,"b":[],"a":[["2.0927","17.57000000"]]}}
1618677430.626139: {"stream":"usdtusd@aggTrade","data":{"e":"aggTrade","E":1618677430647,"s":"USDTUSD","a":4837007,"p":"1.0010","q":"269.24000000","f":5148735,"l":5148735,"T":1618677430646,"m":true,"M":true}}
1618677430.626244: {"stream":"usdtusd@bookTicker","data":{"u":34057440,"s":"USDTUSD","b":"1.0010","B":"218180.72000000","a":"1.0011","A":"13361.76000000"}}
1618677430.633588: {"stream":"ethbusd@bookTicker","data":{"u":56401323,"s":"ETHBUSD","b":"2360.63000000","B":"1.16070000","a":"2363.79000000","A":"1.79212000"}}
1618677430.645282: {"stream":"bchusdt@bookTicker","data":{"u":123518211,"s":"BCHUSDT","b":"1050.60000000","B":"2.00724000","a":"1053.59000000","A":"0.28474000"}}
1618677430.712579: {"stream":"xlmusdt@depth@100ms","data":{"e":"depthUpdate","E":1618677430734,"s":"XLMUSDT","U":134557957,"u":134557958,"b":[["0.60022000","0.00000000"],["0.59994000","3323.10000000"]],"a":[]}}
1618677430.7127: {"stream":"usdtusd@depth@100ms","data":{"e":"depthUpdate","E":1618677430734,"s":"USDTUSD","U":34057440,"u":34057440,"b":[["1.0010","218180.72000000"]],"a":[]}}
1618677430.7127402: {"stream":"bchusdt@depth@100ms","data":{"e":"depthUpdate","E":1618677430734,"s":"BCHUSDT","U":123518210,"u":123518211,"b":[["1049.37000000","0.28589000"]],"a":[["1053.59000000","0.28474000"]]}}
1618677430.712787: {"stream":"ethbusd@depth@100ms","data":{"e":"depthUpdate","E":1618677430734,"s":"ETHBUSD","U":56401323,"u":56401326,"b":[["2360.65000000","0.00000000"],["2339.80000000","0.53400000"],["2333.88000000","0.00000000"]],"a":[["2423.42000000","0.01025000"]]}}
1618677430.712865: {"stream":"omgusd@depth@100ms","data":{"e":"depthUpdate","E":1618677430734,"s":"OMGUSD","U":66532600,"u":66532600,"b":[["9.5281","209.57000000"]],"a":[]}}
1618677430.7211242: {"stream":"btcusdt@bookTicker","data":{"u":372027221,"s":"BTCUSDT","b":"60464.64000000","B":"0.00582400","a":"60469.55000000","A":"0.03512000"}}
1618677430.8068218: {"stream":"omgusd@bookTicker","data":{"u":66532601,"s":"OMGUSD","b":"9.5296","B":"94.10000000","a":"9.5563","A":"132.39000000"}}
1618677430.8141599: {"stream":"bchusdt@depth@100ms","data":{"e":"depthUpdate","E":1618677430834,"s":"BCHUSDT","U":123518212,"u":123518213,"b":[["1049.37000000","0.00000000"]],"a":[["1053.96000000","6.00000000"]]}}
1618677430.814334: {"stream":"btcusdt@depth@100ms","data":{"e":"depthUpdate","E":1618677430834,"s":"BTCUSDT","U":372027220,"u":372027222,"b":[],"a":[["60469.55000000","0.03512000"],["60474.45000000","0.10507300"],["60489.29000000","0.09728700"]]}}
1618677430.8144588: {"stream":"omgusd@depth@100ms","data":{"e":"depthUpdate","E":1618677430834,"s":"OMGUSD","U":66532601,"u":66532601,"b":[["9.5296","94.10000000"]],"a":[]}}
1618677430.81689: {"stream":"omgusd@bookTicker","data":{"u":66532602,"s":"OMGUSD","b":"9.5296","B":"94.10000000","a":"9.5562","A":"160.00000000"}}
1618677430.8202791: {"stream":"btcusdt@bookTicker","data":{"u":372027225,"s":"BTCUSDT","b":"60464.63000000","B":"0.02280400","a":"60469.55000000","A":"0.03512000"}}
1618677430.846991: {"stream":"xlmusdt@bookTicker","data":{"u":134557959,"s":"XLMUSDT","b":"0.60006000","B":"102.90000000","a":"0.60170000","A":"3322.20000000"}}
1618677430.860836: {"stream":"btcusdt@bookTicker","data":{"u":372027228,"s":"BTCUSDT","b":"60461.90000000","B":"0.07960000","a":"60469.55000000","A":"0.03512000"}}
1618677430.913561: {"stream":"xlmusdt@depth@100ms","data":{"e":"depthUpdate","E":1618677430934,"s":"XLMUSDT","U":134557959,"u":134557959,"b":[["0.60044000","0.00000000"]],"a":[]}}
1618677430.913713: {"stream":"btcusdt@depth@100ms","data":{"e":"depthUpdate","E":1618677430934,"s":"BTCUSDT","U":372027223,"u":372027230,"b":[["60464.64000000","0.00000000"],["60464.63000000","0.00000000"],["60458.72000000","0.00566800"],["60444.93000000","0.00000000"],["60263.27000000","0.23067400"]],"a":[["60472.20000000","0.11000000"],["60494.45000000","0.08000000"],["60771.61000000","0.00000000"]]}}
1618677430.913881: {"stream":"zrxusd@depth@100ms","data":{"e":"depthUpdate","E":1618677430935,"s":"ZRXUSD","U":51775974,"u":51775974,"b":[],"a":[["2.0922","1888.27000000"]]}}
1618677430.913919: {"stream":"omgusd@depth@100ms","data":{"e":"depthUpdate","E":1618677430935,"s":"OMGUSD","U":66532602,"u":66532602,"b":[],"a":[["9.5562","160.00000000"]]}}
1618677430.962206: {"stream":"btcusdt@bookTicker","data":{"u":372027235,"s":"BTCUSDT","b":"60461.90000000","B":"0.07960000","a":"60469.55000000","A":"0.14512000"}}
1618677430.9822452: {"stream":"xlmusdt@bookTicker","data":{"u":134557960,"s":"XLMUSDT","b":"0.60004000","B":"3322.60000000","a":"0.60170000","A":"3322.20000000"}}
1618677431.0163672: {"stream":"xlmusdt@depth@100ms","data":{"e":"depthUpdate","E":1618677431037,"s":"XLMUSDT","U":134557960,"u":134557960,"b":[["0.60006000","0.00000000"]],"a":[]}}
1618677431.0165272: {"stream":"btcusdt@depth@100ms","data":{"e":"depthUpdate","E":1618677431037,"s":"BTCUSDT","U":372027231,"u":372027235,"b":[["60436.77000000","0.08000000"]],"a":[["60469.55000000","0.14512000"],["60472.19000000","0.00566800"],["60472.20000000","0.00000000"],["60484.07000000","0.00000000"]]}}
1618677431.016667: {"stream":"bchusdt@depth@100ms","data":{"e":"depthUpdate","E":1618677431037,"s":"BCHUSDT","U":123518214,"u":123518216,"b":[["1049.24000000","1.42522000"]],"a":[["1053.84000000","1.42531000"],["1053.96000000","0.00000000"]]}}
1618677431.023568: {"stream":"bchusdt@bookTicker","data":{"u":123518217,"s":"BCHUSDT","b":"1050.61000000","B":"0.34355000","a":"1053.59000000","A":"0.28474000"}}
1618677431.064137: {"stream":"btcusdt@bookTicker","data":{"u":372027237,"s":"BTCUSDT","b":"60461.90000000","B":"0.07960000","a":"60469.55000000","A":"0.03512000"}}
1618677431.074504: {"stream":"bchusdt@bookTicker","data":{"u":123518218,"s":"BCHUSDT","b":"1050.61000000","B":"0.34355000","a":"1053.58000000","A":"6.00000000"}}
1618677431.1141481: {"stream":"btcusdt@depth@100ms","data":{"e":"depthUpdate","E":1618677431135,"s":"BTCUSDT","U":372027236,"u":372027237,"b":[],"a":[["60469.55000000","0.03512000"],["60530.46000000","0.00495600"]]}}
1618677431.114332: {"stream":"bchusdt@depth@100ms","data":{"e":"depthUpdate","E":1618677431135,"s":"BCHUSDT","U":123518217,"u":123518218,"b":[["1050.61000000","0.34355000"]],"a":[["1053.58000000","6.00000000"]]}}
1618677431.125768: {"stream":"bchusdt@bookTicker","data":{"u":123518220,"s":"BCHUSDT","b":"1050.61000000","B":"0.34355000","a":"1053.57000000","A":"0.34355000"}}
1618677431.134922: {"stream":"xlmusdt@bookTicker","data":{"u":134557961,"s":"XLMUSDT","b":"0.60005000","B":"102.90000000","a":"0.60170000","A":"3322.20000000"}}
1618677431.2149508: {"stream":"xlmusdt@depth@100ms","data":{"e":"depthUpdate","E":1618677431236,"s":"XLMUSDT","U":134557961,"u":134557962,"b":[["0.60005000","102.90000000"],["0.59959000","19897.00000000"]],"a":[]}}
1618677431.215113: {"stream":"bchusdt@depth@100ms","data":{"e":"depthUpdate","E":1618677431236,"s":"BCHUSDT","U":123518219,"u":123518220,"b":[],"a":[["1053.57000000","0.34355000"],["1053.60000000","0.00000000"]]}}
1618677431.215221: {"stream":"omgusd@depth@100ms","data":{"e":"depthUpdate","E":1618677431236,"s":"OMGUSD","U":66532603,"u":66532605,"b":[["9.4987","236.70000000"],["9.4849","803.50000000"]],"a":[["9.5563","82.39000000"]]}}
1618677431.2299452: {"stream":"ethbusd@bookTicker","data":{"u":56401327,"s":"ETHBUSD","b":"2360.63000000","B":"1.16070000","a":"2363.79000000","A":"2.29212000"}}
1618677431.285428: {"stream":"xlmusdt@bookTicker","data":{"u":134557963,"s":"XLMUSDT","b":"0.60004000","B":"3322.60000000","a":"0.60170000","A":"3322.20000000"}}
1618677431.311209: {"stream":"bchusdt@bookTicker","data":{"u":123518225,"s":"BCHUSDT","b":"1050.61000000","B":"0.34355000","a":"1051.69000000","A":"0.93196000"}}
1618677431.313882: {"stream":"ethbusd@depth@100ms","data":{"e":"depthUpdate","E":1618677431335,"s":"ETHBUSD","U":56401327,"u":56401327,"b":[],"a":[["2363.79000000","2.29212000"]]}}
1618677431.3140118: {"stream":"xlmusdt@depth@100ms","data":{"e":"depthUpdate","E":1618677431335,"s":"XLMUSDT","U":134557963,"u":134557963,"b":[["0.60005000","0.00000000"]],"a":[]}}
1618677431.314102: {"stream":"bchusdt@depth@100ms","data":{"e":"depthUpdate","E":1618677431335,"s":"BCHUSDT","U":123518221,"u":123518225,"b":[["1050.60000000","0.00000000"],["1026.39000000","11.64016000"]],"a":[["1051.69000000","0.93196000"],["1053.58000000","0.00000000"],["1128.27000000","0.00000000"]]}}
1618677431.3201642: {"stream":"bchusdt@bookTicker","data":{"u":123518227,"s":"BCHUSDT","b":"1049.99000000","B":"0.72672000","a":"1051.69000000","A":"0.93196000"}}
1618677431.320247: {"stream":"bchusdt@bookTicker","data":{"u":123518228,"s":"BCHUSDT","b":"1050.00000000","B":"0.05564000","a":"1051.69000000","A":"0.93196000"}}
1618677431.4141839: {"stream":"bchusdt@depth@100ms","data":{"e":"depthUpdate","E":1618677431435,"s":"BCHUSDT","U":123518226,"u":123518229,"b":[["1050.61000000","0.00000000"],["1050.00000000","0.05564000"],["1025.04000000","12.09254000"]],"a":[["1053.96000000","6.00000000"]]}}
1618677431.5138812: {"stream":"xlmusdt@depth@100ms","data":{"e":"depthUpdate","E":1618677431535,"s":"XLMUSDT","U":134557964,"u":134557964,"b":[["0.59995000","85.00000000"]],"a":[]}}
1618677431.613937: {"stream":"btcusdt@depth@100ms","data":{"e":"depthUpdate","E":1618677431635,"s":"BTCUSDT","U":372027238,"u":372027239,"b":[["60453.13000000","0.00000000"]],"a":[["60496.68000000","0.02099100"]]}}
1618677431.614121: {"stream":"bchusdt@depth@100ms","data":{"e":"depthUpdate","E":1618677431635,"s":"BCHUSDT","U":123518230,"u":123518230,"b":[],"a":[["1053.96000000","0.00000000"]]}}
1618677431.699629: {"stream":"xlmusdt@bookTicker","data":{"u":134557965,"s":"XLMUSDT","b":"0.60005000","B":"500.00000000","a":"0.60170000","A":"3322.20000000"}}
1618677431.715446: {"stream":"xlmusdt@depth@100ms","data":{"e":"depthUpdate","E":1618677431735,"s":"XLMUSDT","U":134557965,"u":134557965,"b":[["0.60005000","500.00000000"]],"a":[]}}
1618677431.715592: {"stream":"btcusdt@depth@100ms","data":{"e":"depthUpdate","E":1618677431735,"s":"BTCUSDT","U":372027240,"u":372027240,"b":[["60431.36000000","0.13222400"]],"a":[]}}
1618677431.7156858: {"stream":"bchusdt@depth@100ms","data":{"e":"depthUpdate","E":1618677431735,"s":"BCHUSDT","U":123518231,"u":123518231,"b":[["1049.85000000","0.28576000"]],"a":[]}}
1618677431.7157462: {"stream":"ethbusd@bookTicker","data":{"u":56401328,"s":"ETHBUSD","b":"2360.63000000","B":"1.66070000","a":"2363.79000000","A":"2.29212000"}}
1618677431.770752: {"stream":"xlmusdt@bookTicker","data":{"u":134557967,"s":"XLMUSDT","b":"0.60080000","B":"1390.60000000","a":"0.60170000","A":"3322.20000000"}}
1618677431.78362: {"stream":"atomusdt@bookTicker","data":{"u":71292161,"s":"ATOMUSDT","b":"25.15100000","B":"32.03800000","a":"25.19300000","A":"39.69500000"}}
1618677431.815202: {"stream":"atomusdt@depth@100ms","data":{"e":"depthUpdate","E":1618677431837,"s":"ATOMUSDT","U":71292161,"u":71292161,"b":[],"a":[["25.19300000","39.69500000"]]}}
1618677431.815351: {"stream":"ethbusd@depth@100ms","data":{"e":"depthUpdate","E":1618677431837,"s":"ETHBUSD","U":56401328,"u":56401328,"b":[["2360.63000000","1.66070000"]],"a":[]}}
1618677431.8158588: {"stream":"xlmusdt@depth@100ms","data":{"e":"depthUpdate","E":1618677431837,"s":"XLMUSDT","U":134557966,"u":134557968,"b":[["0.60080000","1390.60000000"]],"a":[["0.60172000","1148.40000000"],["0.64445000","0.00000000"]]}}
1618677431.8159502: {"stream":"btcusdt@depth@100ms","data":{"e":"depthUpdate","E":1618677431837,"s":"BTCUSDT","U":372027241,"u":372027241,"b":[["60431.36000000","0.00000000"]],"a":[]}}
1618677431.858567: {"stream":"omgusd@bookTicker","data":{"u":66532606,"s":"OMGUSD","b":"9.5296","B":"94.10000000","a":"9.5561","A":"94.12000000"}}
1618677431.915658: {"stream":"xlmusdt@depth@100ms","data":{"e":"depthUpdate","E":1618677431937,"s":"XLMUSDT","U":134557969,"u":134557969,"b":[],"a":[["0.60183000","0.00000000"]]}}
1618677431.91581: {"stream":"btcusdt@depth@100ms","data":{"e":"depthUpdate","E":1618677431937,"s":"BTCUSDT","U":372027242,"u":372027243,"b":[],"a":[["60476.82000000","0.08599500"],["60757.57000000","0.00000000"]]}}
1618677431.915921: {"stream":"omgusd@depth@100ms","data":{"e":"depthUpdate","E":1618677431937,"s":"OMGUSD","U":66532606,"u":66532606,"b":[],"a":[["9.5561","94.12000000"]]}}
1618677431.9183848: {"stream":"xlmusdt@bookTicker","data":{"u":134557970,"s":"XLMUSDT","b":"0.60080000","B":"1390.60000000","a":"0.60169000","A":"1924.70000000"}}
1618677432.014526: {"stream":"xlmusdt@depth@100ms","data":{"e":"depthUpdate","E":1618677432035,"s":"XLMUSDT","U":134557970,"u":134557972,"b":[["0.59995000","0.00000000"],["0.59959000","0.00000000"]],"a":[["0.60169000","1924.70000000"]]}}
1618677432.01472: {"stream":"btcusdt@depth@100ms","data":{"e":"depthUpdate","E":1618677432035,"s":"BTCUSDT","U":372027244,"u":372027244,"b":[],"a":[["60474.45000000","0.00000000"]]}}
1618677432.014796: {"stream":"bchusdt@depth@100ms","data":{"e":"depthUpdate","E":1618677432035,"s":"BCHUSDT","U":123518232,"u":123518232,"b":[],"a":[["1053.61000000","0.00000000"]]}}
1618677432.014859: {"stream":"zrxusd@depth@100ms","data":{"e":"depthUpdate","E":1618677432035,"s":"ZRXUSD","U":51775975,"u":51775975,"b":[],"a":[["2.0922","1245.12000000"]]}}
1618677432.1158478: {"stream":"btcusdt@depth@100ms","data":{"e":"depthUpdate","E":1618677432136,"s":"BTCUSDT","U":372027245,"u":372027248,"b":[],"a":[["60472.19000000","0.10606200"],["60476.81000000","0.00586200"],["60494.45000000","0.00000000"]]}}
1618677432.116035: {"stream":"omgusd@depth@100ms","data":{"e":"depthUpdate","E":1618677432136,"s":"OMGUSD","U":66532607,"u":66532607,"b":[],"a":[["9.5562","0.00000000"]]}}
1618677432.2136588: {"stream":"zrxusd@depth@100ms","data":{"e":"depthUpdate","E":1618677432235,"s":"ZRXUSD","U":51775976,"u":51775976,"b":[],"a":[["2.0937","603.21000000"]]}}
1618677432.213809: {"stream":"btcusdt@depth@100ms","data":{"e":"depthUpdate","E":1618677432236,"s":"BTCUSDT","U":372027249,"u":372027251,"b":[],"a":[["60472.18000000","0.00586200"],["60476.81000000","0.00000000"],["60502.45000000","0.08000000"]]}}
1618677432.2695029: {"stream":"omgusd@bookTicker","data":{"u":66532608,"s":"OMGUSD","b":"9.5296","B":"94.10000000","a":"9.5561","A":"144.12000000"}}
1618677432.2958028: {"stream":"omgusd@bookTicker","data":{"u":66532609,"s":"OMGUSD","b":"9.5296","B":"94.10000000","a":"9.5560","A":"200.00000000"}}
1618677432.316042: {"stream":"xlmusdt@depth@100ms","data":{"e":"depthUpdate","E":1618677432337,"s":"XLMUSDT","U":134557973,"u":134557975,"b":[["0.60025000","102.90000000"],["0.60018000","3322.50000000"],["0.59994000","0.00000000"]],"a":[]}}
1618677432.3162298: {"stream":"omgusd@depth@100ms","data":{"e":"depthUpdate","E":1618677432337,"s":"OMGUSD","U":66532608,"u":66532609,"b":[],"a":[["9.5560","200.00000000"],["9.5561","144.12000000"]]}}
1618677432.4141598: {"stream":"xlmusdt@depth@100ms","data":{"e":"depthUpdate","E":1618677432436,"s":"XLMUSDT","U":134557976,"u":134557976,"b":[],"a":[["0.60184000","0.00000000"]]}}
1618677432.455961: {"stream":"atomusdt@bookTicker","data":{"u":71292163,"s":"ATOMUSDT","b":"25.14400000","B":"39.68900000","a":"25.19300000","A":"39.69500000"}}
1618677432.514709: {"stream":"atomusdt@depth@100ms","data":{"e":"depthUpdate","E":1618677432536,"s":"ATOMUSDT","U":71292162,"u":71292163,"b":[["25.15100000","0.00000000"],["24.14600000","377.74600000"]],"a":[]}}
1618677432.514882: {"stream":"xlmusdt@depth@100ms","data":{"e":"depthUpdate","E":1618677432536,"s":"XLMUSDT","U":134557977,"u":134557977,"b":[["0.60004000","0.00000000"]],"a":[]}}
1618677432.615544: {"stream":"ethbusd@depth@100ms","data":{"e":"depthUpdate","E":1618677432636,"s":"ETHBUSD","U":56401329,"u":56401330,"b":[["2359.53000000","0.84675000"],["2358.46000000","0.00000000"]],"a":[]}}
1618677432.615718: {"stream":"xlmusdt@depth@100ms","data":{"e":"depthUpdate","E":1618677432636,"s":"XLMUSDT","U":134557978,"u":134557978,"b":[["0.59326000","36.50000000"]],"a":[]}}
1618677432.615784: {"stream":"usdtusd@depth@100ms","data":{"e":"depthUpdate","E":1618677432636,"s":"USDTUSD","U":34057441,"u":34057441,"b":[],"a":[["1.0013","19982.60000000"]]}}
1618677432.6222668: {"stream":"ethbusd@bookTicker","data":{"u":56401331,"s":"ETHBUSD","b":"2360.64000000","B":"0.10176000","a":"2363.79000000","A":"2.29212000"}}
1618677432.625679: {"stream":"usdtusd@aggTrade","data":{"e":"aggTrade","E":1618677432647,"s":"USDTUSD","a":4837008,"p":"1.0010","q":"269.23000000","f":5148736,"l":5148736,"T":1618677432646,"m":true,"M":true}}
1618677432.625788: {"stream":"usdtusd@bookTicker","data":{"u":34057442,"s":"USDTUSD","b":"1.0010","B":"217911.49000000","a":"1.0011","A":"13361.76000000"}}
1618677432.7163572: {"stream":"ethbusd@depth@100ms","data":{"e":"depthUpdate","E":1618677432737,"s":"ETHBUSD","U":56401331,"u":56401331,"b":[["2360.64000000","0.10176000"]],"a":[]}}
1618677432.716504: {"stream":"btcusdt@depth@100ms","data":{"e":"depthUpdate","E":1618677432737,"s":"BTCUSDT","U":372027252,"u":372027252,"b":[],"a":[["60496.68000000","0.00000000"]]}}
1618677432.7165859: {"stream":"usdtusd@depth@100ms","data":{"e":"depthUpdate","E":1618677432737,"s":"USDTUSD","U":34057442,"u":34057442,"b":[["1.0010","217911.49000000"]],"a":[]}}
1618677432.819732: {"stream":"xlmusdt@depth@100ms","data":{"e":"depthUpdate","E":1618677432836,"s":"XLMUSDT","U":134557979,"u":134557981,"b":[["0.60025000","0.00000000"]],"a":[["0.60213000","0.00000000"],["0.60258000","497.90000000"]]}}
