1618677432.8713632: {"stream":"btcusdt@bookTicker","data":{"u":372027255,"s":"BTCUSDT","b":"60463.81000000","B":"0.03207500","a":"60469.55000000","A":"0.03512000"}}
1618677432.871449: {"stream":"btcusdt@bookTicker","data":{"u":372027256,"s":"BTCUSDT","b":"60463.81000000","B":"0.03207500","a":"60472.18000000","A":"0.00586200"}}
1618677432.877366: {"stream":"xlmusdt@bookTicker","data":{"u":134557982,"s":"XLMUSDT","b":"0.60080000","B":"1390.60000000","a":"0.60170000","A":"3322.20000000"}}
1618677432.916394: {"stream":"busdusd@depth@100ms","data":{"e":"depthUpdate","E":1618677432936,"s":"BUSDUSD","U":4191932,"u":4191932,"b":[],"a":[["1.0171","0.00000000"]]}}
1618677432.916543: {"stream":"xlmusdt@depth@100ms","data":{"e":"depthUpdate","E":1618677432936,"s":"XLMUSDT","U":134557982,"u":134557982,"b":[],"a":[["0.60169000","0.00000000"]]}}
1618677432.916619: {"stream":"btcusdt@depth@100ms","data":{"e":"depthUpdate","E":1618677432936,"s":"BTCUSDT","U":372027253,"u":372027257,"b":[["60463.81000000","0.03207500"],["60263.27000000","0.00000000"]],"a":[["60469.55000000","0.00000000"],["60746.16000000","0.32577600"],["60746.43000000","0.00000000"]]}}
1618677432.916746: {"stream":"bchusdt@depth@100ms","data":{"e":"depthUpdate","E":1618677432936,"s":"BCHUSDT","U":123518233,"u":123518233,"b":[],"a":[["1053.56000000","0.91734000"]]}}
1618677432.9211469: {"stream":"btcusdt@bookTicker","data":{"u":372027258,"s":"BTCUSDT","b":"60463.81000000","B":"0.03207500","a":"60472.19000000","A":"0.10606200"}}
1618677433.016675: {"stream":"xlmusdt@depth@100ms","data":{"e":"depthUpdate","E":1618677433036,"s":"XLMUSDT","U":134557983,"u":134557983,"b":[["0.60033000","102.90000000"]],"a":[]}}
1618677433.0168252: {"stream":"btcusdt@depth@100ms","data":{"e":"depthUpdate","E":1618677433036,"s":"BTCUSDT","U":372027258,"u":372027261,"b":[["60461.91000000","0.00604900"],["60458.72000000","0.00000000"]],"a":[["60472.18000000","0.00000000"],["60476.81000000","0.00604900"]]}}
1618677433.016961: {"stream":"zrxusd@depth@100ms","data":{"e":"depthUpdate","E":1618677433036,"s":"ZRXUSD","U":51775977,"u":51775977,"b":[],"a":[["2.0937","0.00000000"]]}}
1618677433.0170062: {"stream":"bchusdt@depth@100ms","data":{"e":"depthUpdate","E":1618677433036,"s":"BCHUSDT","U":123518234,"u":123518236,"b":[["1049.86000000","0.91733000"]],"a":[["1053.55000000","0.20803000"],["1053.57000000","0.00000000"]]}}
1618677433.053521: {"stream":"xlmusdt@bookTicker","data":{"u":134557984,"s":"XLMUSDT","b":"0.60080000","B":"1390.60000000","a":"0.60172000","A":"1148.40000000"}}
1618677433.1154401: {"stream":"xlmusdt@depth@100ms","data":{"e":"depthUpdate","E":1618677433137,"s":"XLMUSDT","U":134557984,"u":134557987,"b":[["0.60035000","3321.80000000"]],"a":[["0.60170000","0.00000000"],["0.60182000","3322.30000000"],["0.60197000","3321.20000000"]]}}
1618677433.1562061: {"stream":"btcusdt@bookTicker","data":{"u":372027265,"s":"BTCUSDT","b":"60463.91000000","B":"0.09915300","a":"60472.19000000","A":"0.10606200"}}
1618677433.168564: {"stream":"btcusdt@bookTicker","data":{"u":372027269,"s":"BTCUSDT","b":"60463.91000000","B":"0.09915300","a":"60476.81000000","A":"0.00604900"}}
1618677433.178587: {"stream":"btcusdt@bookTicker","data":{"u":372027270,"s":"BTCUSDT","b":"60463.91000000","B":"0.09915300","a":"60476.81000000","A":"0.11211600"}}
1618677433.215441: {"stream":"xlmusdt@depth@100ms","data":{"e":"depthUpdate","E":1618677433236,"s":"XLMUSDT","U":134557988,"u":134557988,"b":[["0.60005000","0.00000000"]],"a":[]}}
1618677433.215616: {"stream":"btcusdt@depth@100ms","data":{"e":"depthUpdate","E":1618677433236,"s":"BTCUSDT","U":372027262,"u":372027270,"b":[["60463.91000000","0.09915300"],["60458.71000000","0.00000000"],["60453.74000000","0.13220500"],["60444.44000000","0.13222400"],["60435.47000000","0.00000000"]],"a":[["60472.19000000","0.00000000"],["60476.81000000","0.11211600"],["60486.52000000","0.00000000"],["60515.00000000","0.13220500"]]}}
1618677433.215803: {"stream":"usdtusd@depth@100ms","data":{"e":"depthUpdate","E":1618677433236,"s":"USDTUSD","U":34057443,"u":34057443,"b":[["1.0004","0.00000000"]],"a":[]}}
1618677433.2228322: {"stream":"btcusdt@bookTicker","data":{"u":372027272,"s":"BTCUSDT","b":"60463.91000000","B":"0.09915300","a":"60476.81000000","A":"0.10606700"}}
1618677433.2229178: {"stream":"btcusdt@bookTicker","data":{"u":372027273,"s":"BTCUSDT","b":"60463.92000000","B":"0.00604900","a":"60476.81000000","A":"0.10606700"}}
1618677433.240757: {"stream":"btcusdt@bookTicker","data":{"u":372027276,"s":"BTCUSDT","b":"60463.92000000","B":"0.00604900","a":"60476.80000000","A":"0.10606700"}}
1618677433.265256: {"stream":"btcusdt@bookTicker","data":{"u":372027277,"s":"BTCUSDT","b":"60463.92000000","B":"0.00604900","a":"60476.81000000","A":"0.10606700"}}
1618677433.314188: {"stream":"zrxusd@depth@100ms","data":{"e":"depthUpdate","E":1618677433336,"s":"ZRXUSD","U":51775978,"u":51775978,"b":[],"a":[["2.0940","652.42000000"]]}}
1618677433.315056: {"stream":"xlmusdt@depth@100ms","data":{"e":"depthUpdate","E":1618677433336,"s":"XLMUSDT","U":134557989,"u":134557990,"b":[["0.60033000","0.00000000"],["0.60018000","0.00000000"]],"a":[]}}
1618677433.3151941: {"stream":"btcusdt@depth@100ms","data":{"e":"depthUpdate","E":1618677433336,"s":"BTCUSDT","U":372027271,"u":372027277,"b":[["60463.92000000","0.00604900"],["60461.91000000","0.00000000"]],"a":[["60476.80000000","0.00000000"],["60476.81000000","0.10606700"],["60484.08000000","0.00604900"],["60496.69000000","0.00000000"]]}}
1618677433.31533: {"stream":"bchusdt@depth@100ms","data":{"e":"depthUpdate","E":1618677433336,"s":"BCHUSDT","U":123518237,"u":123518237,"b":[],"a":[["1052.66000000","1.98794000"]]}}
1618677433.416558: {"stream":"bchusdt@depth@100ms","data":{"e":"depthUpdate","E":1618677433437,"s":"BCHUSDT","U":123518238,"u":123518241,"b":[],"a":[["1052.65000000","0.61251000"],["1053.55000000","0.00000000"],["1053.59000000","0.00000000"]]}}
1618677433.5165088: {"stream":"xlmusdt@depth@100ms","data":{"e":"depthUpdate","E":1618677433537,"s":"XLMUSDT","U":134557991,"u":134557994,"b":[["0.60051000","3320.90000000"],["0.60029000","85.00000000"]],"a":[["0.60182000","0.00000000"],["0.60209000","3320.60000000"]]}}
1618677433.516716: {"stream":"bchusdt@depth@100ms","data":{"e":"depthUpdate","E":1618677433537,"s":"BCHUSDT","U":123518242,"u":123518242,"b":[],"a":[["1052.65000000","0.32751000"]]}}
1618677433.5262551: {"stream":"usdtusd@bookTicker","data":{"u":34057444,"s":"USDTUSD","b":"1.0010","B":"217911.49000000","a":"1.0011","A":"13092.53000000"}}
1618677433.53583: {"stream":"bchusdt@aggTrade","data":{"e":"aggTrade","E":1618677433557,"s":"BCHUSDT","a":724818,"p":"1051.69000000","q":"0.93196000","f":736397,"l":736397,"T":1618677433556,"m":false,"M":true}}
1618677433.535935: {"stream":"bchusdt@bookTicker","data":{"u":123518243,"s":"BCHUSDT","b":"1050.00000000","B":"0.05564000","a":"1052.65000000","A":"0.32751000"}}
1618677433.542463: {"stream":"omgusd@bookTicker","data":{"u":66532610,"s":"OMGUSD","b":"9.5296","B":"94.10000000","a":"9.5561","A":"144.12000000"}}
1618677433.615113: {"stream":"xlmusdt@depth@100ms","data":{"e":"depthUpdate","E":1618677433637,"s":"XLMUSDT","U":134557995,"u":134557995,"b":[["0.59182000","37.00000000"]],"a":[]}}
1618677433.61526: {"stream":"btcusdt@depth@100ms","data":{"e":"depthUpdate","E":1618677433637,"s":"BTCUSDT","U":372027278,"u":372027278,"b":[["60436.77000000","0.00000000"]],"a":[]}}
1618677433.6157382: {"stream":"usdtusd@depth@100ms","data":{"e":"depthUpdate","E":1618677433637,"s":"USDTUSD","U":34057444,"u":34057444,"b":[],"a":[["1.0011","13092.53000000"]]}}
1618677433.615795: {"stream":"bchusdt@depth@100ms","data":{"e":"depthUpdate","E":1618677433637,"s":"BCHUSDT","U":123518243,"u":123518244,"b":[["1049.06000000","6.00000000"]],"a":[["1051.69000000","0.00000000"]]}}
1618677433.6158562: {"stream":"omgusd@depth@100ms","data":{"e":"depthUpdate","E":1618677433637,"s":"OMGUSD","U":66532610,"u":66532610,"b":[],"a":[["9.5560","0.00000000"]]}}
1618677433.623054: {"stream":"bchusdt@bookTicker","data":{"u":123518245,"s":"BCHUSDT","b":"1050.00000000","B":"0.05564000","a":"1052.66000000","A":"1.98794000"}}
1618677433.6257129: {"stream":"usdtusd@aggTrade","data":{"e":"aggTrade","E":1618677433648,"s":"USDTUSD","a":4837009,"p":"1.0010","q":"269.23000000","f":5148737,"l":5148737,"T":1618677433647,"m":true,"M":true}}
1618677433.625816: {"stream":"usdtusd@bookTicker","data":{"u":34057445,"s":"USDTUSD","b":"1.0010","B":"217642.26000000","a":"1.0011","A":"13092.53000000"}}
1618677433.715411: {"stream":"usdtusd@depth@100ms","data":{"e":"depthUpdate","E":1618677433737,"s":"USDTUSD","U":34057445,"u":34057445,"b":[["1.0010","217642.26000000"]],"a":[]}}
1618677433.715512: {"stream":"bchusdt@depth@100ms","data":{"e":"depthUpdate","E":1618677433737,"s":"BCHUSDT","U":123518245,"u":123518246,"b":[],"a":[["1052.65000000","0.00000000"],["1053.55000000","0.22384000"]]}}
1618677433.7155719: {"stream":"busdusd@depth@100ms","data":{"e":"depthUpdate","E":1618677433737,"s":"BUSDUSD","U":4191933,"u":4191933,"b":[],"a":[["1.0171","149.96000000"]]}}
1618677433.715604: {"stream":"xlmusdt@depth@100ms","data":{"e":"depthUpdate","E":1618677433737,"s":"XLMUSDT","U":134557996,"u":134558001,"b":[["0.60029000","0.00000000"],["0.59991000","3643.60000000"],["0.59937000","3613.70000000"],["0.59875000","5727.60000000"],["0.59813000","6417.10000000"]],"a":[["0.64426000","24689.60000000"]]}}
1618677433.749695: {"stream":"omgusd@bookTicker","data":{"u":66532611,"s":"OMGUSD","b":"9.5296","B":"94.10000000","a":"9.5560","A":"50.00000000"}}
1618677433.790648: {"stream":"xlmusdt@bookTicker","data":{"u":134558006,"s":"XLMUSDT","b":"0.60080000","B":"1390.60000000","a":"0.60197000","A":"3321.20000000"}}
1618677433.805668: {"stream":"xlmusdt@bookTicker","data":{"u":134558008,"s":"XLMUSDT","b":"0.60081000","B":"499.30000000","a":"0.60197000","A":"3321.20000000"}}
1618677433.8181992: {"stream":"bchusdt@depth@100ms","data":{"e":"depthUpdate","E":1618677433837,"s":"BCHUSDT","U":123518247,"u":123518247,"b":[],"a":[["1053.56000000","42.44915000"]]}}
1618677433.81833: {"stream":"omgusd@depth@100ms","data":{"e":"depthUpdate","E":1618677433837,"s":"OMGUSD","U":66532611,"u":66532611,"b":[],"a":[["9.5560","50.00000000"]]}}
1618677433.81844: {"stream":"xlmusdt@depth@100ms","data":{"e":"depthUpdate","E":1618677433837,"s":"XLMUSDT","U":134558002,"u":134558008,"b":[["0.60081000","499.30000000"],["0.60037000","2424.00000000"],["0.59938000","3460.00000000"],["0.59876000","12118.00000000"],["0.59739000","0.00000000"]],"a":[["0.60172000","0.00000000"]]}}
1618677433.818532: {"stream":"btcusdt@depth@100ms","data":{"e":"depthUpdate","E":1618677433837,"s":"BTCUSDT","U":372027279,"u":372027279,"b":[["60360.07000000","0.07871300"]],"a":[]}}
1618677433.822817: {"stream":"bchusdt@bookTicker","data":{"u":123518248,"s":"BCHUSDT","b":"1050.00000000","B":"0.05564000","a":"1052.65000000","A":"0.31988000"}}
1618677433.823335: {"stream":"btcusdt@bookTicker","data":{"u":372027281,"s":"BTCUSDT","b":"60463.92000000","B":"0.00604900","a":"60476.80000000","A":"0.00622100"}}
1618677433.833129: {"stream":"bchusdt@bookTicker","data":{"u":123518249,"s":"BCHUSDT","b":"1050.26000000","B":"24.66957000","a":"1052.65000000","A":"0.31988000"}}
1618677433.917838: {"stream":"xlmusdt@depth@100ms","data":{"e":"depthUpdate","E":1618677433937,"s":"XLMUSDT","U":134558009,"u":134558011,"b":[["0.60064000","3320.20000000"],["0.60052000","102.90000000"],["0.60035000","0.00000000"]],"a":[]}}
1618677433.918029: {"stream":"btcusdt@depth@100ms","data":{"e":"depthUpdate","E":1618677433937,"s":"BTCUSDT","U":372027280,"u":372027282,"b":[["60444.89000000","0.08000000"]],"a":[["60476.80000000","0.00622100"],["60484.08000000","0.00000000"]]}}
1618677433.9181252: {"stream":"bchusdt@depth@100ms","data":{"e":"depthUpdate","E":1618677433937,"s":"BCHUSDT","U":123518248,"u":123518250,"b":[["1050.26000000","24.66957000"]],"a":[["1052.65000000","0.31988000"],["1053.55000000","0.00000000"]]}}
1618677433.918184: {"stream":"omgusd@depth@100ms","data":{"e":"depthUpdate","E":1618677433937,"s":"OMGUSD","U":66532612,"u":66532612,"b":[],"a":[["9.5561","50.00000000"]]}}
1618677433.924726: {"stream":"bchusdt@bookTicker","data":{"u":123518251,"s":"BCHUSDT","b":"1050.26000000","B":"24.66957000","a":"1052.66000000","A":"1.98794000"}}
1618677433.924809: {"stream":"bchusdt@bookTicker","data":{"u":123518253,"s":"BCHUSDT","b":"1050.27000000","B":"0.31988000","a":"1052.66000000","A":"1.98794000"}}
1618677433.956307: {"stream":"omgusd@bookTicker","data":{"u":66532613,"s":"OMGUSD","b":"9.5296","B":"94.10000000","a":"9.5559","A":"94.07000000"}}
1618677434.016814: {"stream":"btcusdt@depth@100ms","data":{"e":"depthUpdate","E":1618677434038,"s":"BTCUSDT","U":372027283,"u":372027284,"b":[],"a":[["60515.69000000","0.00904000"],["60552.20000000","0.00000000"]]}}
1618677434.017005: {"stream":"bchusdt@depth@100ms","data":{"e":"depthUpdate","E":1618677434038,"s":"BCHUSDT","U":123518251,"u":123518254,"b":[["1050.27000000","0.31988000"],["1050.00000000","0.00000000"]],"a":[["1052.65000000","0.00000000"],["1053.55000000","0.23142000"]]}}
1618677434.017139: {"stream":"omgusd@depth@100ms","data":{"e":"depthUpdate","E":1618677434038,"s":"OMGUSD","U":66532613,"u":66532613,"b":[],"a":[["9.5559","94.07000000"]]}}
1618677434.1163268: {"stream":"bchusdt@depth@100ms","data":{"e":"depthUpdate","E":1618677434137,"s":"BCHUSDT","U":123518255,"u":123518256,"b":[],"a":[["1056.89000000","3.70000000"],["1058.83000000","0.00000000"]]}}
1618677434.216803: {"stream":"xlmusdt@depth@100ms","data":{"e":"depthUpdate","E":1618677434237,"s":"XLMUSDT","U":134558012,"u":134558013,"b":[["0.60064000","0.00000000"],["0.60037000","5745.10000000"]],"a":[]}}
1618677434.2169669: {"stream":"btcusdt@depth@100ms","data":{"e":"depthUpdate","E":1618677434237,"s":"BTCUSDT","U":372027285,"u":372027285,"b":[],"a":[["60540.75000000","3.68214700"]]}}
1618677434.3156831: {"stream":"omgusd@depth@100ms","data":{"e":"depthUpdate","E":1618677434337,"s":"OMGUSD","U":66532614,"u":66532614,"b":[],"a":[["9.5560","0.00000000"]]}}
1618677434.315833: {"stream":"btcusdt@depth@100ms","data":{"e":"depthUpdate","E":1618677434337,"s":"BTCUSDT","U":372027286,"u":372027286,"b":[],"a":[["60491.75000000","0.09915300"]]}}
1618677434.34561: {"stream":"omgusd@bookTicker","data":{"u":66532615,"s":"OMGUSD","b":"9.5296","B":"94.10000000","a":"9.5558","A":"50.00000000"}}
1618677434.417182: {"stream":"bchusdt@depth@100ms","data":{"e":"depthUpdate","E":1618677434439,"s":"BCHUSDT","U":123518257,"u":123518257,"b":[],"a":[["1053.54000000","0.28475000"]]}}
1618677434.417332: {"stream":"omgusd@depth@100ms","data":{"e":"depthUpdate","E":1618677434439,"s":"OMGUSD","U":66532615,"u":66532615,"b":[],"a":[["9.5558","50.00000000"]]}}
1618677434.449954: {"stream":"atomusdt@bookTicker","data":{"u":71292165,"s":"ATOMUSDT","b":"25.14900000","B":"25.62000000","a":"25.19300000","A":"39.69500000"}}
1618677434.5155709: {"stream":"atomusdt@depth@100ms","data":{"e":"depthUpdate","E":1618677434537,"s":"ATOMUSDT","U":71292164,"u":71292165,"b":[["25.14900000","25.62000000"],["24.14600000","0.00000000"]],"a":[]}}
1618677434.515738: {"stream":"xlmusdt@depth@100ms","data":{"e":"depthUpdate","E":1618677434537,"s":"XLMUSDT","U":134558014,"u":134558014,"b":[["0.60052000","0.00000000"]],"a":[]}}
1618677434.616451: {"stream":"xlmusdt@depth@100ms","data":{"e":"depthUpdate","E":1618677434637,"s":"XLMUSDT","U":134558015,"u":134558015,"b":[["0.60030000","102.90000000"]],"a":[]}}
1618677434.616617: {"stream":"bchusdt@depth@100ms","data":{"e":"depthUpdate","E":1618677434637,"s":"BCHUSDT","U":123518258,"u":123518258,"b":[["1049.06000000","0.00000000"]],"a":[]}}
1618677434.616699: {"stream":"omgusd@depth@100ms","data":{"e":"depthUpdate","E":1618677434637,"s":"OMGUSD","U":66532616,"u":66532617,"b":[],"a":[["9.5665","803.50000000"],["9.5804","0.00000000"]]}}
1618677434.71595: {"stream":"xlmusdt@depth@100ms","data":{"e":"depthUpdate","E":1618677434737,"s":"XLMUSDT","U":134558016,"u":134558016,"b":[],"a":[["0.60234000","2258.60000000"]]}}
1618677434.716583: {"stream":"atomusdt@bookTicker","data":{"u":71292166,"s":"ATOMUSDT","b":"25.14900000","B":"25.62000000","a":"25.20100000","A":"1.80500000"}}
1618677434.757589: {"stream":"omgusd@bookTicker","data":{"u":66532618,"s":"OMGUSD","b":"9.5296","B":"94.10000000","a":"9.5559","A":"94.07000000"}}
1618677434.816965: {"stream":"atomusdt@depth@100ms","data":{"e":"depthUpdate","E":1618677434838,"s":"ATOMUSDT","U":71292166,"u":71292167,"b":[],"a":[["25.19300000","0.00000000"],["25.20700000","59.47300000"]]}}
1618677434.817127: {"stream":"omgusd@depth@100ms","data":{"e":"depthUpdate","E":1618677434838,"s":"OMGUSD","U":66532618,"u":66532618,"b":[],"a":[["9.5558","0.00000000"]]}}
1618677434.918567: {"stream":"btcusdt@depth@100ms","data":{"e":"depthUpdate","E":1618677434938,"s":"BTCUSDT","U":372027287,"u":372027287,"b":[],"a":[["60512.89000000","0.02098700"]]}}
1618677434.918716: {"stream":"bchusdt@depth@100ms","data":{"e":"depthUpdate","E":1618677434938,"s":"BCHUSDT","U":123518259,"u":123518259,"b":[],"a":[["1053.56000000","41.53181000"]]}}
1618677435.038957: {"stream":"atomusdt@bookTicker","data":{"u":71292169,"s":"ATOMUSDT","b":"25.15700000","B":"39.66800000","a":"25.20100000","A":"1.80500000"}}
1618677435.051741: {"stream":"omgusd@bookTicker","data":{"u":66532619,"s":"OMGUSD","b":"9.5296","B":"94.10000000","a":"9.5558","A":"160.00000000"}}
1618677435.1148832: {"stream":"omgusd@bookTicker","data":{"u":66532620,"s":"OMGUSD","b":"9.5296","B":"94.10000000","a":"9.5559","A":"94.07000000"}}
1618677435.11656: {"stream":"atomusdt@depth@100ms","data":{"e":"depthUpdate","E":1618677435138,"s":"ATOMUSDT","U":71292168,"u":71292169,"b":[["25.15700000","39.66800000"],["25.14400000","0.00000000"]],"a":[]}}
1618677435.116731: {"stream":"bchusdt@depth@100ms","data":{"e":"depthUpdate","E":1618677435138,"s":"BCHUSDT","U":123518260,"u":123518260,"b":[["1049.86000000","0.00000000"]],"a":[]}}
1618677435.1168509: {"stream":"omgusd@depth@100ms","data":{"e":"depthUpdate","E":1618677435138,"s":"OMGUSD","U":66532619,"u":66532620,"b":[],"a":[["9.5558","0.00000000"]]}}
1618677435.216585: {"stream":"usdtusd@depth@100ms","data":{"e":"depthUpdate","E":1618677435238,"s":"USDTUSD","U":34057446,"u":34057446,"b":[["1.0003","0.00000000"]],"a":[]}}
1618677435.21673: {"stream":"bchusdt@depth@100ms","data":{"e":"depthUpdate","E":1618677435238,"s":"BCHUSDT","U":123518261,"u":123518262,"b":[],"a":[["1071.73000000","0.00000000"],["1073.99000000","0.00000000"]]}}
1618677435.2168179: {"stream":"omgusd@depth@100ms","data":{"e":"depthUpdate","E":1618677435238,"s":"OMGUSD","U":66532621,"u":66532622,"b":[],"a":[["9.5560","236.70000000"],["9.5664","0.00000000"]]}}
1618677435.316837: {"stream":"ethbusd@depth@100ms","data":{"e":"depthUpdate","E":1618677435338,"s":"ETHBUSD","U":56401332,"u":56401332,"b":[["2350.02000000","0.00000000"]],"a":[]}}
1618677435.316994: {"stream":"bchusdt@depth@100ms","data":{"e":"depthUpdate","E":1618677435338,"s":"BCHUSDT","U":123518263,"u":123518263,"b":[["1048.06000000","0.00000000"]],"a":[]}}
1618677435.317069: {"stream":"btcusdt@depth@100ms","data":{"e":"depthUpdate","E":1618677435338,"s":"BTCUSDT","U":372027288,"u":372027288,"b":[["60309.47000000","0.00000000"]],"a":[]}}
1618677435.332736: {"stream":"bchusdt@bookTicker","data":{"u":123518265,"s":"BCHUSDT","b":"1050.27000000","B":"0.31988000","a":"1053.54000000","A":"0.28475000"}}
1618677435.3919308: {"stream":"bchusdt@bookTicker","data":{"u":123518304,"s":"BCHUSDT","b":"1051.03000000","B":"0.68634000","a":"1053.54000000","A":"0.28475000"}}
1618677435.4179242: {"stream":"ethbusd@depth@100ms","data":{"e":"depthUpdate","E":1618677435438,"s":"ETHBUSD","U":56401333,"u":56401333,"b":[["2348.64000000","16.49222000"]],"a":[]}}
1618677435.418072: {"stream":"bchusdt@depth@100ms","data":{"e":"depthUpdate","E":1618677435438,"s":"BCHUSDT","U":123518264,"u":123518311,"b":[["1051.03000000","0.68634000"],["1046.31000000","0.56408000"],["1025.04000000","0.00000000"]],"a":[["1052.66000000","0.00000000"],["1053.63000000","0.00000000"],["1054.45000000","0.00000000"],["1055.26000000","0.00000000"],["1055.87000000","4.24202000"],["1056.08000000","0.00000000"],["1056.90000000","0.00000000"],["1057.73000000","0.00000000"],["1058.56000000","0.00000000"],["1059.38000000","0.00000000"],["1061.03000000","0.00000000"],["1062.26000000","0.00000000"],["1063.49000000","0.00000000"],["1065.14000000","0.00000000"],["1066.99000000","0.00000000"],["1068.85000000","0.00000000"],["1070.08000000","0.00000000"],["1072.86000000","0.00000000"],["1075.13000000","0.00000000"],["1076.26000000","0.00000000"],["1077.40000000","0.00000000"],["1078.53000000","0.00000000"],["1080.06000000","0.00000000"],["1081.60000000","0.00000000"],["1083.13000000","0.00000000"],["1084.66000000","0.00000000"],["1086.60000000","0.00000000"],["1088.54000000","0.00000000"],["1090.48000000","0.00000000"],["1092.42000000","0.00000000"],["1094.36000000","0.00000000"],["1096.30000000","0.00000000"],["1098.24000000","0.00000000"],["1100.18000000","0.00000000"],["1102.12000000","0.00000000"],["1104.05000000","0.00000000"],["1104.66000000","0.91741000"],["1105.99000000","0.00000000"],["1107.92000000","0.00000000"],["1109.86000000","0.00000000"],["1112.52000000","2.15899000"],["1114.01000000","3.30430000"],["1126.31000000","8.15187000"],["1126.77000000","0.00000000"],["1127.67000000","6.98958000"]]}}
1618677435.4243252: {"stream":"bchusdt@bookTicker","data":{"u":123518313,"s":"BCHUSDT","b":"1051.04000000","B":"0.07890000","a":"1053.54000000","A":"0.28475000"}}
1618677435.519489: {"stream":"bchusdt@depth@100ms","data":{"e":"depthUpdate","E":1618677435540,"s":"BCHUSDT","U":123518312,"u":123518313,"b":[["1051.04000000","0.07890000"],["1050.27000000","0.00000000"]],"a":[]}}
1618677435.519656: {"stream":"btcusdt@depth@100ms","data":{"e":"depthUpdate","E":1618677435540,"s":"BTCUSDT","U":372027289,"u":372027289,"b":[["60271.41000000","0.01136800"]],"a":[]}}
1618677435.519737: {"stream":"omgusd@depth@100ms","data":{"e":"depthUpdate","E":1618677435540,"s":"OMGUSD","U":66532623,"u":66532623,"b":[],"a":[["9.5610","3094.65000000"]]}}
1618677435.601472: {"stream":"omgusd@bookTicker","data":{"u":66532624,"s":"OMGUSD","b":"9.5296","B":"94.10000000","a":"9.5558","A":"200.00000000"}}
1618677435.619848: {"stream":"bchusdt@depth@100ms","data":{"e":"depthUpdate","E":1618677435640,"s":"BCHUSDT","U":123518314,"u":123518314,"b":[],"a":[["1054.33000000","2.44865000"]]}}
1618677435.6200042: {"stream":"omgusd@depth@100ms","data":{"e":"depthUpdate","E":1618677435640,"s":"OMGUSD","U":66532624,"u":66532624,"b":[],"a":[["9.5558","200.00000000"]]}}
1618677435.716866: {"stream":"xlmusdt@depth@100ms","data":{"e":"depthUpdate","E":1618677435738,"s":"XLMUSDT","U":134558017,"u":134558022,"b":[["0.60030000","0.00000000"],["0.59754000","5677.70000000"],["0.59699000","6274.40000000"],["0.59632000","9105.20000000"],["0.59558000","8550.90000000"],["0.59479000","8204.30000000"]],"a":[]}}
1618677435.81794: {"stream":"bchusdt@depth@100ms","data":{"e":"depthUpdate","E":1618677435838,"s":"BCHUSDT","U":123518315,"u":123518315,"b":[],"a":[["1054.33000000","0.00000000"]]}}
1618677435.895693: {"stream":"bchusdt@bookTicker","data":{"u":123518320,"s":"BCHUSDT","b":"1051.05000000","B":"0.28543000","a":"1053.54000000","A":"0.28475000"}}
1618677435.908947: {"stream":"bchusdt@bookTicker","data":{"u":123518322,"s":"BCHUSDT","b":"1051.06000000","B":"0.91621000","a":"1053.54000000","A":"0.28475000"}}
1618677435.917859: {"stream":"xlmusdt@depth@100ms","data":{"e":"depthUpdate","E":1618677435938,"s":"XLMUSDT","U":134558023,"u":134558023,"b":[["0.60021000","102.90000000"]],"a":[]}}
1618677435.918009: {"stream":"bchusdt@depth@100ms","data":{"e":"depthUpdate","E":1618677435938,"s":"BCHUSDT","U":123518316,"u":123518322,"b":[["1051.06000000","0.91621000"],["1051.05000000","0.28543000"],["1050.77000000","0.94941000"],["1049.85000000","0.00000000"],["1049.84000000","0.00000000"]],"a":[["1053.84000000","0.00000000"],["1054.82000000","1.42412000"]]}}
1618677435.92508: {"stream":"bchusdt@bookTicker","data":{"u":123518323,"s":"BCHUSDT","b":"1051.07000000","B":"0.30958000","a":"1053.54000000","A":"0.28475000"}}
1618677436.019813: {"stream":"btcusdt@depth@100ms","data":{"e":"depthUpdate","E":1618677436039,"s":"BTCUSDT","U":372027290,"u":372027290,"b":[["60423.68000000","0.00000000"]],"a":[]}}
1618677436.0199628: {"stream":"ethbusd@depth@100ms","data":{"e":"depthUpdate","E":1618677436039,"s":"ETHBUSD","U":56401334,"u":56401334,"b":[],"a":[["2364.65000000","0.00000000"]]}}
1618677436.020041: {"stream":"bchusdt@depth@100ms","data":{"e":"depthUpdate","E":1618677436039,"s":"BCHUSDT","U":123518323,"u":123518324,"b":[["1051.07000000","0.30958000"],["1051.04000000","0.00000000"]],"a":[]}}
1618677436.020124: {"stream":"omgusd@depth@100ms","data":{"e":"depthUpdate","E":1618677436039,"s":"OMGUSD","U":66532625,"u":66532625,"b":[],"a":[["9.5559","0.00000000"]]}}
1618677436.1191418: {"stream":"ethbusd@depth@100ms","data":{"e":"depthUpdate","E":1618677436138,"s":"ETHBUSD","U":56401335,"u":56401336,"b":[["2359.00000000","0.00000000"]],"a":[["2365.69000000","0.84664000"]]}}
1618677436.1193159: {"stream":"atomusdt@depth@100ms","data":{"e":"depthUpdate","E":1618677436138,"s":"ATOMUSDT","U":71292170,"u":71292171,"b":[],"a":[["25.20700000","19.80000000"],["25.22300000","39.64800000"]]}}
1618677436.1194: {"stream":"xlmusdt@depth@100ms","data":{"e":"depthUpdate","E":1618677436138,"s":"XLMUSDT","U":134558024,"u":134558025,"b":[["0.60065000","3320.30000000"],["0.60037000","2424.00000000"]],"a":[]}}
1618677436.119498: {"stream":"bchusdt@depth@100ms","data":{"e":"depthUpdate","E":1618677436138,"s":"BCHUSDT","U":123518325,"u":123518326,"b":[["1049.24000000","0.00000000"]],"a":[["1057.44000000","0.00000000"]]}}
1618677436.21755: {"stream":"ethbusd@depth@100ms","data":{"e":"depthUpdate","E":1618677436239,"s":"ETHBUSD","U":56401337,"u":56401337,"b":[["2358.06000000","0.79940000"]],"a":[]}}
1618677436.217728: {"stream":"bchusdt@depth@100ms","data":{"e":"depthUpdate","E":1618677436239,"s":"BCHUSDT","U":123518327,"u":123518328,"b":[["1050.26000000","0.00000000"]],"a":[["1053.97000000","0.00000000"]]}}
1618677436.217819: {"stream":"zenusd@depth@100ms","data":{"e":"depthUpdate","E":1618677436239,"s":"ZENUSD","U":6596103,"u":6596104,"b":[["120.7830","13.75000000"],["120.5510","0.00000000"]],"a":[]}}
1618677436.217868: {"stream":"xlmusdt@depth@100ms","data":{"e":"depthUpdate","E":1618677436239,"s":"XLMUSDT","U":134558026,"u":134558026,"b":[["0.60021000","0.00000000"]],"a":[]}}
1618677436.270081: {"stream":"bchusdt@bookTicker","data":{"u":123518332,"s":"BCHUSDT","b":"1051.07000000","B":"0.30958000","a":"1053.55000000","A":"0.23142000"}}
1618677436.318218: {"stream":"ethbusd@depth@100ms","data":{"e":"depthUpdate","E":1618677436339,"s":"ETHBUSD","U":56401338,"u":56401338,"b":[["2360.07000000","0.84655000"]],"a":[]}}
1618677436.3183649: {"stream":"bchusdt@depth@100ms","data":{"e":"depthUpdate","E":1618677436339,"s":"BCHUSDT","U":123518329,"u":123518334,"b":[["1050.77000000","0.00000000"],["1050.62000000","1.42354000"],["1050.04000000","6.00000000"]],"a":[["1053.54000000","0.00000000"],["1053.56000000","0.00000000"],["1054.80000000","0.94881000"]]}}
1618677436.325556: {"stream":"bchusdt@bookTicker","data":{"u":123518335,"s":"BCHUSDT","b":"1051.07000000","B":"0.30958000","a":"1054.80000000","A":"0.94881000"}}
1618677436.3279731: {"stream":"bchusdt@bookTicker","data":{"u":123518336,"s":"BCHUSDT","b":"1051.07000000","B":"0.30958000","a":"1054.79000000","A":"0.30958000"}}
1618677436.3568268: {"stream":"omgusd@bookTicker","data":{"u":66532626,"s":"OMGUSD","b":"9.5296","B":"94.10000000","a":"9.5560","A":"236.70000000"}}
1618677436.42005: {"stream":"bchusdt@depth@100ms","data":{"e":"depthUpdate","E":1618677436439,"s":"BCHUSDT","U":123518335,"u":123518340,"b":[],"a":[["1053.55000000","0.00000000"],["1054.79000000","0.30958000"],["1056.66000000","0.00000000"],["1056.89000000","0.00000000"],["1061.30000000","4.87100000"]]}}
1618677436.420258: {"stream":"omgusd@depth@100ms","data":{"e":"depthUpdate","E":1618677436439,"s":"OMGUSD","U":66532626,"u":66532626,"b":[],"a":[["9.5558","0.00000000"]]}}
1618677436.6134531: {"stream":"ethbusd@bookTicker","data":{"u":56401341,"s":"ETHBUSD","b":"2360.65000000","B":"0.09547000","a":"2363.79000000","A":"2.29212000"}}
1618677436.617633: {"stream":"zrxusd@depth@100ms","data":{"e":"depthUpdate","E":1618677436639,"s":"ZRXUSD","U":51775979,"u":51775980,"b":[["2.0780","0.00000000"]],"a":[["2.0916","0.00000000"]]}}
1618677436.6178079: {"stream":"ethbusd@depth@100ms","data":{"e":"depthUpdate","E":1618677436639,"s":"ETHBUSD","U":56401339,"u":56401341,"b":[["2360.65000000","0.09547000"]],"a":[["2365.21000000","0.00000000"],["2366.30000000","0.84641000"]]}}
1618677436.617922: {"stream":"bchusdt@depth@100ms","data":{"e":"depthUpdate","E":1618677436639,"s":"BCHUSDT","U":123518341,"u":123518343,"b":[["1050.04000000","0.00000000"]],"a":[["1054.82000000","0.00000000"],["1056.17000000","1.42217000"]]}}
1618677436.626273: {"stream":"bchusdt@bookTicker","data":{"u":123518344,"s":"BCHUSDT","b":"1051.59000000","B":"0.94874000","a":"1054.79000000","A":"0.30958000"}}
1618677436.667182: {"stream":"btcusdt@bookTicker","data":{"u":372027294,"s":"BTCUSDT","b":"60466.79000000","B":"0.08032000","a":"60476.80000000","A":"0.00622100"}}
1618677436.6875021: {"stream":"bchusdt@bookTicker","data":{"u":123518348,"s":"BCHUSDT","b":"1051.07000000","B":"0.30958000","a":"1054.79000000","A":"0.30958000"}}
1618677436.7129018: {"stream":"omgusd@bookTicker","data":{"u":66532627,"s":"OMGUSD","b":"9.5296","B":"94.10000000","a":"9.5559","A":"50.00000000"}}
1618677436.7184582: {"stream":"zenusd@depth@100ms","data":{"e":"depthUpdate","E":1618677436740,"s":"ZENUSD","U":6596105,"u":6596106,"b":[["120.7830","3.14000000"],["120.5510","10.61000000"]],"a":[]}}
1618677436.7185678: {"stream":"xlmusdt@depth@100ms","data":{"e":"depthUpdate","E":1618677436740,"s":"XLMUSDT","U":134558027,"u":134558027,"b":[["0.60036000","102.90000000"]],"a":[]}}
1618677436.7186282: {"stream":"btcusdt@depth@100ms","data":{"e":"depthUpdate","E":1618677436740,"s":"BTCUSDT","U":372027291,"u":372027294,"b":[["60466.79000000","0.08032000"],["60461.90000000","0.00000000"]],"a":[["60487.29000000","0.00000000"],["60492.20000000","0.08001000"]]}}
1618677436.718716: {"stream":"zrxusd@depth@100ms","data":{"e":"depthUpdate","E":1618677436740,"s":"ZRXUSD","U":51775981,"u":51775983,"b":[["2.0792","2237.18000000"]],"a":[["2.0928","2040.00000000"],["2.0940","0.00000000"]]}}
1618677436.71877: {"stream":"bchusdt@depth@100ms","data":{"e":"depthUpdate","E":1618677436740,"s":"BCHUSDT","U":123518344,"u":123518348,"b":[["1051.59000000","0.00000000"],["1051.05000000","0.00000000"],["1050.62000000","0.00000000"]],"a":[["1054.80000000","0.00000000"]]}}
1618677436.71883: {"stream":"omgusd@depth@100ms","data":{"e":"depthUpdate","E":1618677436740,"s":"OMGUSD","U":66532627,"u":66532627,"b":[],"a":[["9.5559","50.00000000"]]}}
1618677436.724531: {"stream":"bchusdt@bookTicker","data":{"u":123518350,"s":"BCHUSDT","b":"1051.07000000","B":"0.30958000","a":"1055.87000000","A":"4.24202000"}}
1618677436.724573: {"stream":"bchusdt@bookTicker","data":{"u":123518351,"s":"BCHUSDT","b":"1051.07000000","B":"0.30958000","a":"1055.86000000","A":"0.24082000"}}
1618677436.726589: {"stream":"btcusdt@bookTicker","data":{"u":372027296,"s":"BTCUSDT","b":"60466.79000000","B":"0.08032000","a":"60476.81000000","A":"0.10606700"}}
1618677436.744938: {"stream":"btcusdt@bookTicker","data":{"u":372027298,"s":"BTCUSDT","b":"60466.79000000","B":"0.08032000","a":"60476.82000000","A":"0.08599500"}}
1618677436.745024: {"stream":"btcusdt@bookTicker","data":{"u":372027299,"s":"BTCUSDT","b":"60466.79000000","B":"0.08032000","a":"60476.80000000","A":"0.10607300"}}
1618677436.750808: {"stream":"btcusdt@bookTicker","data":{"u":372027300,"s":"BTCUSDT","b":"60463.92000000","B":"0.00604900","a":"60476.80000000","A":"0.10607300"}}
1618677436.762461: {"stream":"btcusdt@bookTicker","data":{"u":372027302,"s":"BTCUSDT","b":"60463.92000000","B":"0.00604900","a":"60476.79000000","A":"0.10607300"}}
1618677436.76966: {"stream":"btcusdt@bookTicker","data":{"u":372027303,"s":"BTCUSDT","b":"60469.40000000","B":"0.07968000","a":"60476.79000000","A":"0.10607300"}}
1618677436.7735229: {"stream":"btcusdt@bookTicker","data":{"u":372027304,"s":"BTCUSDT","b":"60469.40000000","B":"0.07968000","a":"60476.80000000","A":"0.10607300"}}
1618677436.77614: {"stream":"omgusd@bookTicker","data":{"u":66532629,"s":"OMGUSD","b":"9.5348","B":"209.48000000","a":"9.5559","A":"50.00000000"}}
1618677436.818509: {"stream":"xlmusdt@depth@100ms","data":{"e":"depthUpdate","E":1618677436839,"s":"XLMUSDT","U":134558028,"u":134558028,"b":[["0.60036000","0.00000000"]],"a":[]}}
1618677436.8186681: {"stream":"btcusdt@depth@100ms","data":{"e":"depthUpdate","E":1618677436839,"s":"BTCUSDT","U":372027295,"u":372027304,"b":[["60469.40000000","0.07968000"],["60466.79000000","0.00000000"]],"a":[["60476.79000000","0.00000000"],["60476.80000000","0.10607300"],["60476.81000000","0.00000000"],["60484.08000000","0.00573800"],["60492.20000000","0.00000000"],["60494.81000000","0.08010000"]]}}
1618677436.818801: {"stream":"zrxusd@depth@100ms","data":{"e":"depthUpdate","E":1618677436839,"s":"ZRXUSD","U":51775984,"u":51775984,"b":[["2.0200","0.00000000"]],"a":[]}}
1618677436.818846: {"stream":"bchusdt@depth@100ms","data":{"e":"depthUpdate","E":1618677436839,"s":"BCHUSDT","U":123518349,"u":123518353,"b":[],"a":[["1054.79000000","0.00000000"],["1055.86000000","0.24082000"],["1055.87000000","0.00000000"],["1056.16000000","1.17100000"],["1061.30000000","3.70000000"]]}}
1618677436.8189151: {"stream":"omgusd@depth@100ms","data":{"e":"depthUpdate","E":1618677436839,"s":"OMGUSD","U":66532628,"u":66532629,"b":[["9.5348","209.48000000"],["9.5281","0.00000000"]],"a":[]}}
1618677436.884979: {"stream":"bchusdt@bookTicker","data":{"u":123518354,"s":"BCHUSDT","b":"1051.08000000","B":"0.28542000","a":"1055.86000000","A":"0.24082000"}}
1618677436.885062: {"stream":"bchusdt@bookTicker","data":{"u":123518355,"s":"BCHUSDT","b":"1051.08000000","B":"0.28542000","a":"1055.85000000","A":"0.28413000"}}
1618677436.919004: {"stream":"bchusdt@depth@100ms","data":{"e":"depthUpdate","E":1618677436939,"s":"BCHUSDT","U":123518354,"u":123518355,"b":[["1051.08000000","0.28542000"]],"a":[["1055.85000000","0.28413000"]]}}
1618677436.919168: {"stream":"omgusd@depth@100ms","data":{"e":"depthUpdate","E":1618677436939,"s":"OMGUSD","U":66532630,"u":66532630,"b":[["9.5296","0.00000000"]],"a":[]}}
1618677436.943669: {"stream":"omgusd@bookTicker","data":{"u":66532631,"s":"OMGUSD","b":"9.5349","B":"94.07000000","a":"9.5559","A":"50.00000000"}}
1618677437.001305: {"stream":"bchusdt@bookTicker","data":{"u":123518359,"s":"BCHUSDT","b":"1051.08000000","B":"6.28542000","a":"1055.85000000","A":"0.28413000"}}
1618677437.018028: {"stream":"xlmusdt@depth@100ms","data":{"e":"depthUpdate","E":1618677437039,"s":"XLMUSDT","U":134558029,"u":134558030,"b":[["0.60066000","102.90000000"]],"a":[["0.60208000","1923.30000000"]]}}
1618677437.018195: {"stream":"zrxusd@depth@100ms","data":{"e":"depthUpdate","E":1618677437039,"s":"ZRXUSD","U":51775985,"u":51775985,"b":[],"a":[["2.0944","627.61000000"]]}}
1618677437.018281: {"stream":"bchusdt@depth@100ms","data":{"e":"depthUpdate","E":1618677437039,"s":"BCHUSDT","U":123518356,"u":123518359,"b":[["1051.08000000","6.28542000"],["1046.94000000","0.57045000"]],"a":[["1056.31000000","6.00000000"],["1056.50000000","3.55585000"]]}}
1618677437.0183449: {"stream":"omgusd@depth@100ms","data":{"e":"depthUpdate","E":1618677437039,"s":"OMGUSD","U":66532631,"u":66532631,"b":[["9.5349","94.07000000"]],"a":[]}}
1618677437.034809: {"stream":"bchusdt@bookTicker","data":{"u":123518362,"s":"BCHUSDT","b":"1051.09000000","B":"0.08837000","a":"1055.85000000","A":"0.28413000"}}
1618677437.117684: {"stream":"zenusd@depth@100ms","data":{"e":"depthUpdate","E":1618677437139,"s":"ZENUSD","U":6596107,"u":6596108,"b":[["120.7830","13.75000000"],["120.5510","0.00000000"]],"a":[]}}
1618677437.1178591: {"stream":"btcusdt@depth@100ms","data":{"e":"depthUpdate","E":1618677437139,"s":"BTCUSDT","U":372027305,"u":372027305,"b":[["60360.07000000","0.00000000"]],"a":[]}}
1618677437.118349: {"stream":"bchusdt@depth@100ms","data":{"e":"depthUpdate","E":1618677437139,"s":"BCHUSDT","U":123518360,"u":123518364,"b":[["1051.09000000","0.08837000"],["1051.07000000","0.00000000"]],"a":[["1056.16000000","0.00000000"],["1056.31000000","0.00000000"],["1061.30000000","4.87100000"]]}}
1618677437.118453: {"stream":"omgusd@depth@100ms","data":{"e":"depthUpdate","E":1618677437139,"s":"OMGUSD","U":66532632,"u":66532636,"b":[["9.4987","1040.20000000"],["9.4849","0.00000000"],["9.4668","6369.20000000"],["9.4412","0.00000000"]],"a":[["9.5561","0.00000000"]]}}
1618677437.147625: {"stream":"zrxusd@aggTrade","data":{"e":"aggTrade","E":1618677437169,"s":"ZRXUSD","a":591872,"p":"2.0827","q":"28.83000000","f":644458,"l":644458,"T":1618677437168,"m":true,"M":true}}
1618677437.147729: {"stream":"zrxusd@bookTicker","data":{"u":51775986,"s":"ZRXUSD","b":"2.0827","B":"690.61000000","a":"2.0883","A":"718.87000000"}}
1618677437.1672719: {"stream":"bchusdt@bookTicker","data":{"u":123518366,"s":"BCHUSDT","b":"1052.39000000","B":"0.94805000","a":"1055.85000000","A":"0.28413000"}}
1618677437.169683: {"stream":"bchusdt@bookTicker","data":{"u":123518367,"s":"BCHUSDT","b":"1052.39000000","B":"0.94805000","a":"1055.61000000","A":"0.94805000"}}
1618677437.2179148: {"stream":"zrxusd@depth@100ms","data":{"e":"depthUpdate","E":1618677437239,"s":"ZRXUSD","U":51775986,"u":51775987,"b":[["2.0827","690.61000000"]],"a":[["2.0944","0.00000000"]]}}
1618677437.218077: {"stream":"bchusdt@depth@100ms","data":{"e":"depthUpdate","E":1618677437239,"s":"BCHUSDT","U":123518365,"u":123518372,"b":[["1052.39000000","0.94805000"],["1051.96000000","1.42185000"],["1051.08000000","0.28542000"],["1046.31000000","0.00000000"]],"a":[["1055.61000000","0.94805000"],["1108.23000000","2.55350000"],["1110.01000000","2.30224000"],["1127.71000000","10.05730000"]]}}
1618677437.230229: {"stream":"bchusdt@bookTicker","data":{"u":123518375,"s":"BCHUSDT","b":"1052.39000000","B":"0.94805000","a":"1055.60000000","A":"0.30133000"}}
1618677437.230325: {"stream":"bchusdt@bookTicker","data":{"u":123518376,"s":"BCHUSDT","b":"1052.40000000","B":"0.30133000","a":"1055.60000000","A":"0.30133000"}}
1618677437.3181598: {"stream":"bchusdt@depth@100ms","data":{"e":"depthUpdate","E":1618677437339,"s":"BCHUSDT","U":123518373,"u":123518378,"b":[["1052.40000000","0.30133000"],["1051.41000000","24.66957000"],["1051.09000000","0.00000000"],["1050.00000000","6.00000000"]],"a":[["1055.60000000","0.30133000"],["1055.86000000","0.00000000"]]}}
1618677437.318381: {"stream":"ethbusd@depth@100ms","data":{"e":"depthUpdate","E":1618677437339,"s":"ETHBUSD","U":56401342,"u":56401342,"b":[["2302.33000000","0.00000000"]],"a":[]}}
1618677437.353077: {"stream":"bchusdt@bookTicker","data":{"u":123518385,"s":"BCHUSDT","b":"1052.40000000","B":"0.30133000","a":"1054.13000000","A":"0.66007000"}}
1618677437.373198: {"stream":"btcusdt@bookTicker","data":{"u":372027307,"s":"BTCUSDT","b":"60469.40000000","B":"0.07968000","a":"60476.82000000","A":"0.08599500"}}
1618677437.423352: {"stream":"xlmusdt@depth@100ms","data":{"e":"depthUpdate","E":1618677437439,"s":"XLMUSDT","U":134558031,"u":134558031,"b":[["0.60066000","0.00000000"]],"a":[]}}
1618677437.423506: {"stream":"btcusdt@depth@100ms","data":{"e":"depthUpdate","E":1618677437439,"s":"BTCUSDT","U":372027306,"u":372027308,"b":[["60444.89000000","0.00000000"]],"a":[["60476.80000000","0.00000000"],["60480.56000000","0.10607300"]]}}
1618677437.4236212: {"stream":"bchusdt@depth@100ms","data":{"e":"depthUpdate","E":1618677437439,"s":"BCHUSDT","U":123518379,"u":123518386,"b":[["1052.04000000","0.75671000"],["1051.08000000","0.00000000"],["1050.51000000","1.78943000"],["1026.39000000","0.00000000"]],"a":[["1054.13000000","0.66007000"],["1054.72000000","23.36178000"],["1110.91000000","3.11735000"],["1127.67000000","0.00000000"]]}}
1618677437.427617: {"stream":"bchusdt@bookTicker","data":{"u":123518388,"s":"BCHUSDT","b":"1052.39000000","B":"0.94805000","a":"1054.13000000","A":"0.66007000"}}
1618677437.520571: {"stream":"busdusd@depth@100ms","data":{"e":"depthUpdate","E":1618677437540,"s":"BUSDUSD","U":4191934,"u":4191934,"b":[["0.9810","18.35000000"]],"a":[]}}
1618677437.5295749: {"stream":"xlmusdt@depth@100ms","data":{"e":"depthUpdate","E":1618677437540,"s":"XLMUSDT","U":134558032,"u":134558032,"b":[["0.60028000","102.90000000"]],"a":[]}}
1618677437.529732: {"stream":"btcusdt@depth@100ms","data":{"e":"depthUpdate","E":1618677437540,"s":"BTCUSDT","U":372027309,"u":372027310,"b":[],"a":[["60480.55000000","0.00573800"],["60484.08000000","0.00000000"]]}}
1618677437.529821: {"stream":"zrxusd@depth@100ms","data":{"e":"depthUpdate","E":1618677437540,"s":"ZRXUSD","U":51775988,"u":51775988,"b":[],"a":[["2.0946","651.96000000"]]}}
1618677437.529866: {"stream":"bchusdt@depth@100ms","data":{"e":"depthUpdate","E":1618677437540,"s":"BCHUSDT","U":123518387,"u":123518392,"b":[["1052.40000000","0.00000000"],["1051.42000000","0.09705000"],["1050.00000000","0.00000000"]],"a":[["1054.71000000","0.24963000"],["1055.60000000","0.00000000"],["1055.85000000","0.00000000"]]}}
1618677437.6104121: {"stream":"btcusdt@bookTicker","data":{"u":372027314,"s":"BTCUSDT","b":"60471.48000000","B":"0.09914000","a":"60476.82000000","A":"0.08599500"}}
1618677437.622379: {"stream":"xlmusdt@depth@100ms","data":{"e":"depthUpdate","E":1618677437640,"s":"XLMUSDT","U":134558033,"u":134558033,"b":[["0.60079000","71361.90000000"]],"a":[]}}
1618677437.622527: {"stream":"btcusdt@depth@100ms","data":{"e":"depthUpdate","E":1618677437640,"s":"BTCUSDT","U":372027311,"u":372027316,"b":[["60471.48000000","0.09914000"],["60463.91000000","0.00000000"],["60446.89000000","0.08000000"]],"a":[["60480.56000000","0.00000000"],["60491.75000000","0.00000000"],["60499.60000000","0.09914000"]]}}
1618677437.6227: {"stream":"bchusdt@depth@100ms","data":{"e":"depthUpdate","E":1618677437640,"s":"BCHUSDT","U":123518393,"u":123518393,"b":[],"a":[["1056.16000000","6.00000000"]]}}
1618677437.7192929: {"stream":"zrxusd@depth@100ms","data":{"e":"depthUpdate","E":1618677437740,"s":"ZRXUSD","U":51775989,"u":51775989,"b":[],"a":[["2.0946","0.00000000"]]}}
1618677437.719444: {"stream":"xlmusdt@depth@100ms","data":{"e":"depthUpdate","E":1618677437740,"s":"XLMUSDT","U":134558034,"u":134558034,"b":[["0.59129000","13142.00000000"]],"a":[]}}
1618677437.7256398: {"stream":"btcusdt@depth@100ms","data":{"e":"depthUpdate","E":1618677437740,"s":"BTCUSDT","U":372027317,"u":372027320,"b":[["60469.40000000","0.00000000"]],"a":[["60483.38000000","0.00000000"],["60494.81000000","0.00000000"]]}}
1618677437.725826: {"stream":"bchusdt@depth@100ms","data":{"e":"depthUpdate","E":1618677437740,"s":"BCHUSDT","U":123518394,"u":123518394,"b":[],"a":[["1056.16000000","0.00000000"]]}}
1618677437.7726479: {"stream":"btcusdt@bookTicker","data":{"u":372027326,"s":"BTCUSDT","b":"60474.96000000","B":"0.07973000","a":"60476.82000000","A":"0.08599500"}}
1618677437.8222551: {"stream":"zenusd@depth@100ms","data":{"e":"depthUpdate","E":1618677437840,"s":"ZENUSD","U":6596109,"u":6596109,"b":[["113.3730","0.00000000"]],"a":[]}}
1618677437.822409: {"stream":"bchusdt@depth@100ms","data":{"e":"depthUpdate","E":1618677437840,"s":"BCHUSDT","U":123518395,"u":123518396,"b":[["1051.97000000","0.29449000"],["1051.42000000","0.00000000"]],"a":[]}}
1618677437.822515: {"stream":"xlmusdt@depth@100ms","data":{"e":"depthUpdate","E":1618677437840,"s":"XLMUSDT","U":134558035,"u":134558035,"b":[["0.60028000","0.00000000"]],"a":[]}}
1618677437.8225589: {"stream":"btcusdt@depth@100ms","data":{"e":"depthUpdate","E":1618677437840,"s":"BTCUSDT","U":372027321,"u":372027328,"b":[["60474.96000000","0.07973000"],["60444.44000000","0.00000000"]],"a":[["60483.43000000","0.00000000"],["60500.37000000","0.08014000"],["60502.45000000","0.00000000"],["60512.89000000","0.00000000"],["60514.99000000","0.02098400"]]}}
1618677437.898798: {"stream":"btcusdt@bookTicker","data":{"u":372027331,"s":"BTCUSDT","b":"60474.96000000","B":"0.07973000","a":"60480.55000000","A":"0.00573800"}}
1618677437.898883: {"stream":"btcusdt@bookTicker","data":{"u":372027333,"s":"BTCUSDT","b":"60475.37000000","B":"0.02557100","a":"60480.55000000","A":"0.00573800"}}
1618677437.923193: {"stream":"atomusdt@depth@100ms","data":{"e":"depthUpdate","E":1618677437941,"s":"ATOMUSDT","U":71292172,"u":71292172,"b":[["25.11800000","19.50400000"]],"a":[]}}
1618677437.923342: {"stream":"xlmusdt@depth@100ms","data":{"e":"depthUpdate","E":1618677437941,"s":"XLMUSDT","U":134558036,"u":134558039,"b":[["0.59407000","10449.10000000"],["0.59326000","10336.00000000"],["0.59265000","12081.90000000"],["0.59193000","12013.90000000"]],"a":[]}}
1618677437.923444: {"stream":"btcusdt@depth@100ms","data":{"e":"depthUpdate","E":1618677437941,"s":"BTCUSDT","U":372027329,"u":372027336,"b":[["60475.37000000","0.02557100"],["60279.27000000","0.00000000"]],"a":[["60476.82000000","0.00000000"],["60484.09000000","0.00000000"],["60488.27000000","0.10607500"],["60512.88000000","0.08000000"],["60761.83000000","0.37948800"],["60774.05000000","0.37904000"]]}}
1618677437.9307148: {"stream":"btcusdt@bookTicker","data":{"u":372027337,"s":"BTCUSDT","b":"60475.37000000","B":"0.02557100","a":"60488.27000000","A":"0.10607500"}}
1618677437.930774: {"stream":"btcusdt@bookTicker","data":{"u":372027340,"s":"BTCUSDT","b":"60475.37000000","B":"0.02557100","a":"60488.26000000","A":"0.00609900"}}
1618677437.975471: {"stream":"xlmusdt@bookTicker","data":{"u":134558041,"s":"XLMUSDT","b":"0.60082000","B":"1923.40000000","a":"0.60197000","A":"3321.20000000"}}
1618677437.9880252: {"stream":"ethbusd@bookTicker","data":{"u":56401344,"s":"ETHBUSD","b":"2360.65000000","B":"0.94181000","a":"2363.79000000","A":"2.29212000"}}
1618677438.02001: {"stream":"zenusd@depth@100ms","data":{"e":"depthUpdate","E":1618677438040,"s":"ZENUSD","U":6596110,"u":6596110,"b":[["121.2590","9.28600000"]],"a":[]}}
1618677438.020156: {"stream":"xlmusdt@depth@100ms","data":{"e":"depthUpdate","E":1618677438040,"s":"XLMUSDT","U":134558040,"u":134558041,"b":[["0.60082000","1923.40000000"],["0.60052000","102.90000000"]],"a":[]}}
1618677438.020246: {"stream":"btcusdt@depth@100ms","data":{"e":"depthUpdate","E":1618677438040,"s":"BTCUSDT","U":372027337,"u":372027340,"b":[["60471.49000000","0.00609900"],["60463.92000000","0.00000000"]],"a":[["60480.55000000","0.00000000"],["60488.26000000","0.00609900"]]}}
1618677438.0247612: {"stream":"ethbusd@depth@100ms","data":{"e":"depthUpdate","E":1618677438040,"s":"ETHBUSD","U":56401343,"u":56401344,"b":[["2360.65000000","0.94181000"],["2359.53000000","0.00000000"]],"a":[]}}
1618677438.024875: {"stream":"bchusdt@depth@100ms","data":{"e":"depthUpdate","E":1618677438040,"s":"BCHUSDT","U":123518397,"u":123518399,"b":[["1052.05000000","0.28516000"],["1051.06000000","0.00000000"]],"a":[["1054.70000000","0.28444000"]]}}
1618677438.0603058: {"stream":"btcusdt@bookTicker","data":{"u":372027345,"s":"BTCUSDT","b":"60477.68000000","B":"0.09913100","a":"60488.26000000","A":"0.00609900"}}
1618677438.124516: {"stream":"ethbusd@depth@100ms","data":{"e":"depthUpdate","E":1618677438141,"s":"ETHBUSD","U":56401345,"u":56401347,"b":[["2360.64000000","0.00000000"],["2358.06000000","0.00000000"]],"a":[["2365.69000000","0.00000000"]]}}
1618677438.124707: {"stream":"bchusdt@depth@100ms","data":{"e":"depthUpdate","E":1618677438141,"s":"BCHUSDT","U":123518400,"u":123518402,"b":[["1052.05000000","0.38882000"],["1051.97000000","0.00000000"]],"a":[["1054.70000000","0.00000000"]]}}
1618677438.1248: {"stream":"omgusd@depth@100ms","data":{"e":"depthUpdate","E":1618677438141,"s":"OMGUSD","U":66532637,"u":66532638,"b":[["9.4987","236.70000000"],["9.4849","803.50000000"]],"a":[]}}
1618677438.12485: {"stream":"btcusdt@depth@100ms","data":{"e":"depthUpdate","E":1618677438141,"s":"BTCUSDT","U":372027341,"u":372027347,"b":[["60477.68000000","0.09913100"],["60471.48000000","0.00000000"],["60464.41000000","0.13218200"]],"a":[["60499.60000000","0.00000000"],["60505.81000000","0.00000000"],["60505.82000000","0.09913100"],["60529.07000000","0.13217500"]]}}
1618677438.131253: {"stream":"ethbusd@bookTicker","data":{"u":56401348,"s":"ETHBUSD","b":"2360.66000000","B":"0.10125000","a":"2363.79000000","A":"2.29212000"}}
1618677438.131354: {"stream":"btcusdt@bookTicker","data":{"u":372027348,"s":"BTCUSDT","b":"60477.68000000","B":"0.09913100","a":"60488.27000000","A":"0.10607500"}}
1618677438.189009: {"stream":"omgusd@bookTicker","data":{"u":66532641,"s":"OMGUSD","b":"9.5349","B":"94.07000000","a":"9.5560","A":"236.70000000"}}
1618677438.219386: {"stream":"omgusd@bookTicker","data":{"u":66532642,"s":"OMGUSD","b":"9.5349","B":"94.07000000","a":"9.5559","A":"50.00000000"}}
1618677438.2266219: {"stream":"btcusdt@depth@100ms","data":{"e":"depthUpdate","E":1618677438243,"s":"BTCUSDT","U":372027348,"u":372027351,"b":[["60475.38000000","0.00609900"],["60471.49000000","0.00000000"]],"a":[["60488.26000000","0.00000000"],["60494.48000000","0.00609900"]]}}
1618677438.22683: {"stream":"ethbusd@depth@100ms","data":{"e":"depthUpdate","E":1618677438243,"s":"ETHBUSD","U":56401348,"u":56401348,"b":[["2360.66000000","0.10125000"]],"a":[]}}
1618677438.2269042: {"stream":"zrxusd@depth@100ms","data":{"e":"depthUpdate","E":1618677438243,"s":"ZRXUSD","U":51775990,"u":51775990,"b":[],"a":[["2.0950","652.40000000"]]}}
1618677438.2269871: {"stream":"omgusd@depth@100ms","data":{"e":"depthUpdate","E":1618677438243,"s":"OMGUSD","U":66532639,"u":66532642,"b":[["9.4987","1040.20000000"],["9.4849","0.00000000"]],"a":[["9.5559","50.00000000"]]}}
1618677438.3206558: {"stream":"ethbusd@depth@100ms","data":{"e":"depthUpdate","E":1618677438341,"s":"ETHBUSD","U":56401349,"u":56401350,"b":[["2358.78000000","0.79940000"],["2301.52000000","0.01025000"]],"a":[]}}
1618677438.320823: {"stream":"xlmusdt@depth@100ms","data":{"e":"depthUpdate","E":1618677438341,"s":"XLMUSDT","U":134558042,"u":134558042,"b":[["0.60052000","0.00000000"]],"a":[]}}
1618677438.320919: {"stream":"btcusdt@depth@100ms","data":{"e":"depthUpdate","E":1618677438341,"s":"BTCUSDT","U":372027352,"u":372027353,"b":[],"a":[["60489.28000000","0.00609900"],["60494.48000000","0.00000000"]]}}
1618677438.5192478: {"stream":"busdusd@depth@100ms","data":{"e":"depthUpdate","E":1618677438540,"s":"BUSDUSD","U":4191935,"u":4191935,"b":[["0.9610","343.40000000"]],"a":[]}}
1618677438.5227761: {"stream":"xlmusdt@depth@100ms","data":{"e":"depthUpdate","E":1618677438544,"s":"XLMUSDT","U":134558043,"u":134558043,"b":[["0.60052000","102.90000000"]],"a":[]}}
1618677438.522926: {"stream":"omgusd@depth@100ms","data":{"e":"depthUpdate","E":1618677438545,"s":"OMGUSD","U":66532643,"u":66532644,"b":[["9.5348","0.00000000"]],"a":[["9.5589","0.00000000"]]}}
1618677438.531987: {"stream":"omgusd@bookTicker","data":{"u":66532645,"s":"OMGUSD","b":"9.5412","B":"209.34000000","a":"9.5559","A":"50.00000000"}}
1618677438.624962: {"stream":"omgusd@depth@100ms","data":{"e":"depthUpdate","E":1618677438645,"s":"OMGUSD","U":66532645,"u":66532646,"b":[["9.5412","209.34000000"]],"a":[["9.5657","209.35000000"]]}}
1618677438.625132: {"stream":"xlmusdt@depth@100ms","data":{"e":"depthUpdate","E":1618677438645,"s":"XLMUSDT","U":134558044,"u":134558044,"b":[["0.59182000","0.00000000"]],"a":[]}}
1618677438.720104: {"stream":"btcusdt@depth@100ms","data":{"e":"depthUpdate","E":1618677438740,"s":"BTCUSDT","U":372027354,"u":372027354,"b":[],"a":[["60512.88000000","0.00000000"]]}}
1618677438.7280252: {"stream":"ethbusd@bookTicker","data":{"u":56401351,"s":"ETHBUSD","b":"2360.66000000","B":"0.10125000","a":"2363.79000000","A":"1.79212000"}}
1618677438.75558: {"stream":"ethbusd@bookTicker","data":{"u":56401355,"s":"ETHBUSD","b":"2361.23000000","B":"0.84614000","a":"2363.79000000","A":"1.79212000"}}
1618677438.772888: {"stream":"btcusdt@bookTicker","data":{"u":372027357,"s":"BTCUSDT","b":"60477.68000000","B":"0.09913100","a":"60489.28000000","A":"0.00609900"}}
1618677438.819102: {"stream":"xlmusdt@depth@100ms","data":{"e":"depthUpdate","E":1618677438841,"s":"XLMUSDT","U":134558045,"u":134558045,"b":[["0.60052000","0.00000000"]],"a":[]}}
1618677438.819212: {"stream":"btcusdt@depth@100ms","data":{"e":"depthUpdate","E":1618677438841,"s":"BTCUSDT","U":372027355,"u":372027358,"b":[["60379.27000000","0.10218700"],["60293.45000000","0.00000000"]],"a":[["60488.27000000","0.00000000"],["60494.06000000","0.10607500"]]}}
1618677438.819299: {"stream":"ethbusd@depth@100ms","data":{"e":"depthUpdate","E":1618677438841,"s":"ETHBUSD","U":56401351,"u":56401355,"b":[["2361.23000000","0.84614000"],["2360.07000000","0.00000000"]],"a":[["2363.79000000","1.79212000"],["2366.75000000","0.84625000"],["2451.13000000","32.28210000"]]}}
1618677438.8254871: {"stream":"btcusdt@bookTicker","data":{"u":372027360,"s":"BTCUSDT","b":"60477.68000000","B":"0.09913100","a":"60489.29000000","A":"0.09728700"}}
1618677438.825571: {"stream":"btcusdt@bookTicker","data":{"u":372027361,"s":"BTCUSDT","b":"60477.69000000","B":"0.00657900","a":"60489.29000000","A":"0.09728700"}}
1618677438.847826: {"stream":"btcusdt@bookTicker","data":{"u":372027366,"s":"BTCUSDT","b":"60477.69000000","B":"0.00657900","a":"60489.28000000","A":"0.10607500"}}
1618677438.8702562: {"stream":"ethbusd@bookTicker","data":{"u":56401357,"s":"ETHBUSD","b":"2361.23000000","B":"0.84614000","a":"2364.64000000","A":"0.13003000"}}
1618677438.8703659: {"stream":"omgusd@bookTicker","data":{"u":66532648,"s":"OMGUSD","b":"9.5423","B":"80.27000000","a":"9.5559","A":"50.00000000"}}
1618677438.904916: {"stream":"btcusdt@bookTicker","data":{"u":372027369,"s":"BTCUSDT","b":"60484.72000000","B":"0.02747200","a":"60489.28000000","A":"0.10607500"}}
1618677438.920746: {"stream":"ethbusd@depth@100ms","data":{"e":"depthUpdate","E":1618677438941,"s":"ETHBUSD","U":56401356,"u":56401357,"b":[["2360.66000000","0.00000000"]],"a":[["2363.79000000","0.00000000"]]}}
1618677438.920915: {"stream":"btcusdt@depth@100ms","data":{"e":"depthUpdate","E":1618677438941,"s":"BTCUSDT","U":372027359,"u":372027371,"b":[["60484.72000000","0.02747200"],["60477.69000000","0.00657900"],["60475.38000000","0.00000000"],["60446.89000000","0.00000000"]],"a":[["60489.28000000","0.10607500"],["60489.29000000","0.00000000"],["60494.05000000","0.00657900"],["60494.49000000","0.00000000"],["60514.99000000","0.00000000"],["60520.05000000","0.08000000"],["60789.05000000","0.46178500"],["60802.40000000","0.33930900"]]}}
1618677438.9211369: {"stream":"omgusd@depth@100ms","data":{"e":"depthUpdate","E":1618677438941,"s":"OMGUSD","U":66532647,"u":66532648,"b":[["9.5423","80.27000000"],["9.1471","0.00000000"]],"a":[]}}
1618677438.92635: {"stream":"ethbusd@bookTicker","data":{"u":56401358,"s":"ETHBUSD","b":"2361.24000000","B":"0.10115000","a":"2364.64000000","A":"0.13003000"}}
1618677438.926435: {"stream":"ethbusd@bookTicker","data":{"u":56401360,"s":"ETHBUSD","b":"2361.24000000","B":"0.10115000","a":"2365.45000000","A":"0.09736000"}}
1618677439.001209: {"stream":"zrxusd@bookTicker","data":{"u":51775991,"s":"ZRXUSD","b":"2.0827","B":"690.61000000","a":"2.0882","A":"626.19000000"}}
1618677439.0208142: {"stream":"btcusdt@depth@100ms","data":{"e":"depthUpdate","E":1618677439042,"s":"BTCUSDT","U":372027372,"u":372027373,"b":[["60464.46000000","0.08000000"],["60444.87000000","0.02098200"]],"a":[]}}
1618677439.0209868: {"stream":"ethbusd@depth@100ms","data":{"e":"depthUpdate","E":1618677439042,"s":"ETHBUSD","U":56401358,"u":56401360,"b":[["2361.24000000","0.10115000"]],"a":[["2364.64000000","0.00000000"],["2366.29000000","0.16301000"]]}}
1618677439.021079: {"stream":"bchusdt@depth@100ms","data":{"e":"depthUpdate","E":1618677439042,"s":"BCHUSDT","U":123518403,"u":123518406,"b":[["1052.05000000","0.10366000"],["1051.42000000","0.28533000"]],"a":[["1054.70000000","1.19987000"]]}}
1618677439.021135: {"stream":"omgusd@depth@100ms","data":{"e":"depthUpdate","E":1618677439042,"s":"OMGUSD","U":66532649,"u":66532649,"b":[["9.5349","0.00000000"]],"a":[]}}
1618677439.021182: {"stream":"zrxusd@depth@100ms","data":{"e":"depthUpdate","E":1618677439042,"s":"ZRXUSD","U":51775991,"u":51775991,"b":[],"a":[["2.0882","626.19000000"]]}}
1618677439.119534: {"stream":"bchusdt@depth@100ms","data":{"e":"depthUpdate","E":1618677439141,"s":"BCHUSDT","U":123518407,"u":123518408,"b":[],"a":[["1054.69000000","0.29003000"],["1054.71000000","0.00000000"]]}}
1618677439.137496: {"stream":"btcusdt@bookTicker","data":{"u":372027374,"s":"BTCUSDT","b":"60484.72000000","B":"0.02747200","a":"60494.05000000","A":"0.00657900"}}
1618677439.222891: {"stream":"btcusdt@depth@100ms","data":{"e":"depthUpdate","E":1618677439244,"s":"BTCUSDT","U":372027374,"u":372027374,"b":[],"a":[["60489.28000000","0.00000000"]]}}
1618677439.2284338: {"stream":"bchusdt@bookTicker","data":{"u":123518409,"s":"BCHUSDT","b":"1052.05000000","B":"0.10366000","a":"1054.13000000","A":"0.66007000"}}
1618677439.228916: {"stream":"btcusdt@bookTicker","data":{"u":372027375,"s":"BTCUSDT","b":"60484.72000000","B":"0.02747200","a":"60494.06000000","A":"0.10607500"}}
1618677439.24325: {"stream":"btcusdt@bookTicker","data":{"u":372027377,"s":"BTCUSDT","b":"60484.72000000","B":"0.02747200","a":"60494.05000000","A":"0.10609500"}}
1618677439.263944: {"stream":"btcusdt@bookTicker","data":{"u":372027378,"s":"BTCUSDT","b":"60484.72000000","B":"0.02747200","a":"60494.06000000","A":"0.10607500"}}
1618677439.323797: {"stream":"atomusdt@depth@100ms","data":{"e":"depthUpdate","E":1618677439341,"s":"ATOMUSDT","U":71292173,"u":71292174,"b":[],"a":[["25.22300000","0.00000000"],["25.23700000","39.62700000"]]}}


