1618677480.104615: {"stream":"bchusd_210625@depth@100ms","data":{"e":"depthUpdate","E":1618677480052,"T":1618677480038,"s":"BCHUSD_210625","ps":"BCHUSD","U":86143353824,"u":86143354277,"pu":86143353818,"b":[["1126.67","0"],["1126.68","0"],["1127.43","0"],["1127.44","0"],["1127.47","35"],["1127.48","30"],["1127.50","0"]],"a":[["1142.06","113"]]}}
1618677480.6167371: {"stream":"egldusd_perp@depth@100ms","data":{"e":"depthUpdate","E":1618677480052,"T":1618677480047,"s":"EGLDUSD_PERP","ps":"EGLDUSD","U":86143353836,"u":86143354322,"pu":86143353645,"b":[["215.263","0"],["215.432","315"]],"a":[["216.379","0"],["216.382","0"],["216.469","238"],["217.674","1292"]]}}
1618677481.227155: {"stream":"btcusd_perp@depth@100ms","data":{"e":"depthUpdate","E":1618677480059,"T":1618677480049,"s":"BTCUSD_PERP","ps":"BTCUSD","U":86143353853,"u":86143354336,"pu":86143353805,"b":[["60581.0","5981"],["60581.2","0"]],"a":[["60580.9","0"],["60585.6","250"],["60596.9","0"],["60609.2","243"],["60609.7","0"],["60622.1","243"],["60622.5","0"],["60623.9","251"],["60624.4","0"],["60640.5","2090"],["60802.8","1821"]]}}
1618677481.8471549: {"stream":"ethusd_210924@depth@100ms","data":{"e":"depthUpdate","E":1618677480070,"T":1618677480047,"s":"ETHUSD_210924","ps":"ETHUSD","U":86143353881,"u":86143354321,"pu":86143353799,"b":[["2687.54","0"],["2687.58","1000"],["2687.59","0"],["2687.61","348"]],"a":[["2687.84","50"]]}}
1618677482.0197902: {"stream":"ethusd_210625@depth@100ms","data":{"e":"depthUpdate","E":1618677480079,"T":1618677480039,"s":"ETHUSD_210625","ps":"ETHUSD","U":86143353908,"u":86143354281,"pu":86143353774,"b":[["2508.27","2"],["2508.66","0"],["2509.10","1187"]],"a":[["2509.09","0"],["2509.11","8152"],["2509.29","121"],["2519.17","249"]]}}
1618677482.632788: {"stream":"linkusd_210625@depth@100ms","data":{"e":"depthUpdate","E":1618677480096,"T":1618677480078,"s":"LINKUSD_210625","ps":"LINKUSD","U":86143353987,"u":86143354525,"pu":86143353928,"b":[["43.561","0"],["43.578","447"],["43.726","0"]],"a":[["43.994","0"]]}}
1618677483.24287: {"stream":"xrpusd_210625@depth@100ms","data":{"e":"depthUpdate","E":1618677480108,"T":1618677480092,"s":"XRPUSD_210625","ps":"XRPUSD","U":86143354041,"u":86143354599,"pu":86143353495,"b":[["1.6882","206"],["1.6884","0"],["1.6887","82"],["1.6888","0"],["1.6891","0"]],"a":[["1.6905","45"],["1.6906","0"],["1.6907","145"],["1.6912","572"],["1.6913","12"]]}}
1618677483.851809: {"stream":"dotusd_210625@depth@100ms","data":{"e":"depthUpdate","E":1618677480135,"T":1618677480103,"s":"DOTUSD_210625","ps":"DOTUSD","U":86143354233,"u":86143354660,"pu":86143354024,"b":[["46.720","0"],["46.734","21"]],"a":[["46.764","0"],["46.787","42"],["46.870","1019"],["46.889","0"]]}}
1618677484.463382: {"stream":"egldusd_perp@depth@100ms","data":{"e":"depthUpdate","E":1618677480154,"T":1618677480050,"s":"EGLDUSD_PERP","ps":"EGLDUSD","U":86143354340,"u":86143354340,"pu":86143354322,"b":[],"a":[["216.377","129"]]}}
1618677484.463395: {"stream":"btcusd_perp@depth@100ms","data":{"e":"depthUpdate","E":1618677480159,"T":1618677480154,"s":"BTCUSD_PERP","ps":"BTCUSD","U":86143354359,"u":86143354951,"pu":86143354336,"b":[["60378.7","1944"],["60546.6","0"],["60568.6","300"],["60571.0","769"],["60573.4","0"],["60574.1","90"],["60574.5","574"],["60574.9","8"],["60576.6","0"],["60576.9","62"],["60581.0","6181"]],"a":[["60580.9","0"],["60590.0","50"],["60592.5","5"],["60596.5","122"],["60597.0","99"],["60604.9","40"],["60628.5","412"],["60641.6","0"],["60656.4","1"],["60695.3","1100"]]}}
1618677484.4634292: {"stream":"bchusd_210625@depth@100ms","data":{"e":"depthUpdate","E":1618677480161,"T":1618677480149,"s":"BCHUSD_210625","ps":"BCHUSD","U":86143354378,"u":86143354933,"pu":86143354277,"b":[["1124.21","173"],["1127.45","0"],["1127.46","35"],["1127.47","0"],["1127.48","0"],["1127.50","0"]],"a":[]}}
1618677484.463474: {"stream":"ethusd_210625@depth@100ms","data":{"e":"depthUpdate","E":1618677480188,"T":1618677480143,"s":"ETHUSD_210625","ps":"ETHUSD","U":86143354553,"u":86143354908,"pu":86143354281,"b":[],"a":[["2509.09","0"],["2509.11","8273"],["2509.15","0"],["2509.29","0"]]}}
1618677484.4635148: {"stream":"xrpusd_210625@depth@100ms","data":{"e":"depthUpdate","E":1618677480208,"T":1618677480200,"s":"XRPUSD_210625","ps":"XRPUSD","U":86143354666,"u":86143355181,"pu":86143354599,"b":[["1.6754","1000"],["1.6764","0"],["1.6787","100"],["1.6790","0"],["1.6846","1094"],["1.6856","0"],["1.6880","100"],["1.6882","161"],["1.6883","0"]],"a":[["1.6903","0"],["1.6904","200"],["1.6905","0"],["1.6907","0"],["1.6908","193"],["1.6912","0"],["1.6914","563"],["1.6928","1000"],["1.6937","12"],["1.6968","330"]]}}
1618677484.463558: {"stream":"linkusd_210625@depth@100ms","data":{"e":"depthUpdate","E":1618677480228,"T":1618677480212,"s":"LINKUSD_210625","ps":"LINKUSD","U":86143354796,"u":86143355236,"pu":86143354525,"b":[["42.574","0"],["43.578","467"]],"a":[["43.989","0"]]}}
1618677484.463635: {"stream":"egldusd_perp@depth@100ms","data":{"e":"depthUpdate","E":1618677480258,"T":1618677480202,"s":"EGLDUSD_PERP","ps":"EGLDUSD","U":86143354953,"u":86143355194,"pu":86143354340,"b":[],"a":[["217.205","0"],["217.431","1076"]]}}
1618677484.463671: {"stream":"bchusd_210625@depth@100ms","data":{"e":"depthUpdate","E":1618677480264,"T":1618677480255,"s":"BCHUSD_210625","ps":"BCHUSD","U":86143354978,"u":86143355439,"pu":86143354933,"b":[["1126.67","0"],["1126.68","64"],["1126.69","16"],["1126.70","35"],["1127.46","0"]],"a":[["1128.75","433"],["1128.88","0"],["1136.29","0"],["1137.20","1434"]]}}
1618677484.4636831: {"stream":"linkusd_210924@depth@100ms","data":{"e":"depthUpdate","E":1618677480265,"T":1618677480242,"s":"LINKUSD_210924","ps":"LINKUSD","U":86143354987,"u":86143355377,"pu":86143352612,"b":[],"a":[["45.289","30"],["45.292","40"],["45.302","0"],["45.319","0"],["45.786","40"],["45.796","0"]]}}
1618677484.637983: {"stream":"btcusd_perp@depth@100ms","data":{"e":"depthUpdate","E":1618677480275,"T":1618677480269,"s":"BTCUSD_PERP","ps":"BTCUSD","U":86143355025,"u":86143355531,"pu":86143354951,"b":[["60482.3","0"],["60506.9","740"],["60546.6","49"],["60571.6","10"],["60573.6","243"],["60573.7","0"],["60581.0","6182"],["60581.2","0"]],"a":[["60581.1","7974"],["60582.9","0"],["60585.6","250"],["60592.3","10"],["60594.3","0"],["60596.5","0"],["60597.0","139"],["60597.3","122"],["60601.5","7"],["60604.9","0"],["60609.2","0"],["60610.1","243"],["60622.1","0"],["60622.9","243"],["60623.9","8"],["60624.7","243"],["60625.2","45"],["60625.3","1405"],["60695.3","1100"]]}}
1618677484.638083: {"stream":"ethusd_210625@depth@100ms","data":{"e":"depthUpdate","E":1618677480306,"T":1618677480252,"s":"ETHUSD_210625","ps":"ETHUSD","U":86143355199,"u":86143355423,"pu":86143354908,"b":[["2498.63","2100"],["2503.51","3219"],["2509.10","2087"]],"a":[["2509.09","0"],["2509.11","5357"]]}}
1618677484.638123: {"stream":"xrpusd_210625@depth@100ms","data":{"e":"depthUpdate","E":1618677480320,"T":1618677480299,"s":"XRPUSD_210625","ps":"XRPUSD","U":86143355249,"u":86143355810,"pu":86143355181,"b":[["1.6817","8269"],["1.6875","60"],["1.6882","0"]],"a":[["1.6904","248"],["1.6908","145"],["1.6912","45"],["1.6921","1731"],["1.6932","0"],["1.6957","1945"],["1.6962","3600"],["1.6978","80"],["1.6985","0"]]}}
1618677484.63815: {"stream":"linkusd_210625@depth@100ms","data":{"e":"depthUpdate","E":1618677480341,"T":1618677480334,"s":"LINKUSD_210625","ps":"LINKUSD","U":86143355358,"u":86143356074,"pu":86143355236,"b":[["42.760","10583"],["43.726","7"]],"a":[["43.749","50"],["43.750","0"],["43.782","0"],["43.922","609"],["43.994","20"]]}}
1618677484.6381629: {"stream":"ethusd_210924@depth@100ms","data":{"e":"depthUpdate","E":1618677480350,"T":1618677480345,"s":"ETHUSD_210924","ps":"ETHUSD","U":86143355389,"u":86143356166,"pu":86143354321,"b":[["2687.54","0"],["2687.55","0"],["2687.58","0"],["2687.60","0"],["2687.61","350"]],"a":[["2687.84","50"]]}}
1618677484.63824: {"stream":"bchusd_210625@depth@100ms","data":{"e":"depthUpdate","E":1618677480370,"T":1618677480364,"s":"BCHUSD_210625","ps":"BCHUSD","U":86143355510,"u":86143356339,"pu":86143355439,"b":[["1116.30","0"],["1116.38","50"],["1119.87","0"],["1123.70","250"],["1123.95","500"],["1124.21","0"],["1124.47","0"],["1124.55","50"],["1126.70","0"],["1126.71","0"],["1126.72","64"],["1126.73","36"]],"a":[["1128.51","250"],["1128.56","250"],["1128.81","250"],["1128.96","0"],["1129.33","250"],["1129.45","250"],["1139.16","190"]]}}
1618677484.638282: {"stream":"btcusd_perp@depth@100ms","data":{"e":"depthUpdate","E":1618677480383,"T":1618677480369,"s":"BTCUSD_PERP","ps":"BTCUSD","U":86143355615,"u":86143356381,"pu":86143355531,"b":[["60506.9","0"],["60565.0","30"],["60575.5","35"],["60581.0","6175"],["60581.2","0"]],"a":[["60100.2","0"],["60580.9","0"],["60585.6","100"],["60585.7","15"],["60802.8","3628"]]}}
1618677484.638308: {"stream":"egldusd_perp@depth@100ms","data":{"e":"depthUpdate","E":1618677480389,"T":1618677480350,"s":"EGLDUSD_PERP","ps":"EGLDUSD","U":86143355661,"u":86143356239,"pu":86143355194,"b":[["215.537","0"],["215.623","789"],["216.075","0"]],"a":[]}}
1618677484.638318: {"stream":"linkusd_210924@depth@100ms","data":{"e":"depthUpdate","E":1618677480392,"T":1618677480327,"s":"LINKUSD_210924","ps":"LINKUSD","U":86143355683,"u":86143356018,"pu":86143355377,"b":[["45.199","1152"],["45.200","94"]],"a":[["45.310","90"]]}}
1618677484.638355: {"stream":"dotusd_210625@depth@100ms","data":{"e":"depthUpdate","E":1618677480405,"T":1618677480400,"s":"DOTUSD_210625","ps":"DOTUSD","U":86143355819,"u":86143356609,"pu":86143354660,"b":[["46.197","0"],["46.517","1393"],["46.542","0"],["46.673","5"],["46.733","0"]],"a":[["46.761","0"],["46.762","0"],["46.786","0"],["46.829","193"]]}}
1618677484.638409: {"stream":"xrpusd_210625@depth@100ms","data":{"e":"depthUpdate","E":1618677480420,"T":1618677480401,"s":"XRPUSD_210625","ps":"XRPUSD","U":86143355944,"u":86143356618,"pu":86143355810,"b":[["1.6657","0"],["1.6754","0"],["1.6764","1000"],["1.6815","410"],["1.6846","94"],["1.6854","250"],["1.6856","1250"],["1.6859","262"],["1.6863","250"],["1.6870","964"],["1.6882","0"]],"a":[["1.6911","45"],["1.6912","0"],["1.6975","20216"]]}}
1618677484.638422: {"stream":"ethusd_210625@depth@100ms","data":{"e":"depthUpdate","E":1618677480420,"T":1618677480414,"s":"ETHUSD_210625","ps":"ETHUSD","U":86143355939,"u":86143356692,"pu":86143355423,"b":[["2500.99","0"],["2502.17","38392"],["2508.27","0"],["2508.66","62"],["2509.10","1312"]],"a":[["2509.09","0"],["2509.11","7594"]]}}
1618677484.638459: {"stream":"ethusd_210924@depth@100ms","data":{"e":"depthUpdate","E":1618677480451,"T":1618677480432,"s":"ETHUSD_210924","ps":"ETHUSD","U":86143356206,"u":86143356809,"pu":86143356166,"b":[["2684.19","0"],["2685.45","3358"],["2685.46","736"],["2687.46","0"],["2687.47","660"],["2687.48","203"],["2687.58","0"],["2687.59","1000"],["2687.61","0"],["2687.62","0"],["2687.63","0"],["2687.64","321"],["2687.83","416"]],"a":[["2687.84","50"]]}}
1618677484.6384718: {"stream":"btcusd_210924@depth@100ms","data":{"e":"depthUpdate","E":1618677480451,"T":1618677480408,"s":"BTCUSD_210924","ps":"BTCUSD","U":86143356198,"u":86143356659,"pu":86143353052,"b":[["68589.9","0"],["68590.0","0"],["68590.7","0"]],"a":[["68674.8","384"]]}}
1618677485.252218: {"stream":"linkusd_210625@depth@100ms","data":{"e":"depthUpdate","E":1618677480453,"T":1618677480448,"s":"LINKUSD_210625","ps":"LINKUSD","U":86143356233,"u":86143356876,"pu":86143356074,"b":[],"a":[["43.749","0"],["43.774","0"],["43.777","50"],["43.924","180"]]}}
1618677485.252285: {"stream":"bchusd_210625@depth@100ms","data":{"e":"depthUpdate","E":1618677480473,"T":1618677480465,"s":"BCHUSD_210625","ps":"BCHUSD","U":86143356372,"u":86143356989,"pu":86143356339,"b":[["1116.38","0"],["1119.88","0"],["1122.93","0"],["1124.55","0"],["1126.68","0"],["1126.69","0"],["1126.74","0"],["1126.75","0"],["1126.77","64"],["1126.78","36"],["1126.79","35"]],"a":[]}}
1618677485.252324: {"stream":"btcusd_perp@depth@100ms","data":{"e":"depthUpdate","E":1618677480490,"T":1618677480483,"s":"BTCUSD_PERP","ps":"BTCUSD","U":86143356485,"u":86143357106,"pu":86143356381,"b":[["54522.9","1"],["60495.1","817"],["60519.6","0"],["60523.7","1049"],["60560.9","0"],["60569.5","50"],["60571.7","100"],["60572.1","32"],["60579.4","0"]],"a":[["60580.9","0"],["60585.6","250"],["60592.6","230"],["60595.2","100"],["60596.5","122"],["60597.3","0"],["60609.3","243"],["60610.1","0"],["60622.1","243"],["60622.9","0"],["60624.0","273"],["60624.7","0"],["60695.3","0"]]}}
1618677485.252463: {"stream":"dotusd_210625@depth@100ms","data":{"e":"depthUpdate","E":1618677480515,"T":1618677480503,"s":"DOTUSD_210625","ps":"DOTUSD","U":86143356672,"u":86143357210,"pu":86143356609,"b":[["46.207","40"],["46.517","0"],["46.542","1377"],["46.697","250"],["46.722","250"],["46.732","790"],["46.733","104"],["46.734","0"]],"a":[["46.763","256"],["46.786","0"],["46.810","0"],["46.858","250"],["46.876","250"],["46.886","0"],["46.892","250"],["46.908","250"],["46.916","250"],["46.967","502"],["47.178","0"],["47.233","1478"]]}}
1618677485.2524889: {"stream":"ethusd_210625@depth@100ms","data":{"e":"depthUpdate","E":1618677480523,"T":1618677480515,"s":"ETHUSD_210625","ps":"ETHUSD","U":86143356749,"u":86143357279,"pu":86143356692,"b":[["2507.00","3005"],["2508.27","88"],["2508.66","0"]],"a":[["2509.09","0"],["2513.12","2982"]]}}
1618677485.252522: {"stream":"xrpusd_210625@depth@100ms","data":{"e":"depthUpdate","E":1618677480531,"T":1618677480521,"s":"XRPUSD_210625","ps":"XRPUSD","U":86143356787,"u":86143357301,"pu":86143356618,"b":[["1.6648","5553"],["1.6888","0"],["1.6891","45"]],"a":[["1.6947","2044"],["1.6950","2364"],["1.6965","293"]]}}
1618677485.252542: {"stream":"linkusd_210924@depth@100ms","data":{"e":"depthUpdate","E":1618677480540,"T":1618677480496,"s":"LINKUSD_210924","ps":"LINKUSD","U":86143356828,"u":86143357164,"pu":86143356018,"b":[["45.200","187"]],"a":[["45.290","62"],["45.395","2411"],["45.405","0"]]}}
1618677485.252574: {"stream":"linkusd_210625@depth@100ms","data":{"e":"depthUpdate","E":1618677480557,"T":1618677480551,"s":"LINKUSD_210625","ps":"LINKUSD","U":86143356905,"u":86143357434,"pu":86143356876,"b":[["43.502","0"],["43.519","100"],["43.578","247"],["43.645","250"],["43.658","250"],["43.661","42"],["43.671","250"],["43.684","1561"],["43.709","250"]],"a":[["43.762","0"],["43.814","1815"],["43.843","250"],["43.859","250"]]}}
1618677485.252596: {"stream":"btcusd_210924@depth@100ms","data":{"e":"depthUpdate","E":1618677480561,"T":1618677480480,"s":"BTCUSD_210924","ps":"BTCUSD","U":86143356935,"u":86143357075,"pu":86143356659,"b":[["68561.0","728"]],"a":[["68624.0","20"],["68625.1","0"]]}}
1618677485.252605: {"stream":"ethusd_210924@depth@100ms","data":{"e":"depthUpdate","E":1618677480564,"T":1618677480535,"s":"ETHUSD_210924","ps":"ETHUSD","U":86143356957,"u":86143357366,"pu":86143356809,"b":[["2687.47","0"],["2687.48","0"],["2687.59","1000"],["2687.60","660"]],"a":[["2687.84","50"],["2696.98","15020"],["2697.44","0"]]}}
1618677485.2526138: {"stream":"egldusd_perp@depth@100ms","data":{"e":"depthUpdate","E":1618677480566,"T":1618677480526,"s":"EGLDUSD_PERP","ps":"EGLDUSD","U":86143356962,"u":86143357329,"pu":86143356239,"b":[["216.012","0"]],"a":[["216.350","463"],["216.377","0"],["216.378","0"]]}}
1618677485.2526348: {"stream":"bchusd_210625@depth@100ms","data":{"e":"depthUpdate","E":1618677480575,"T":1618677480562,"s":"BCHUSD_210625","ps":"BCHUSD","U":86143357025,"u":86143357503,"pu":86143356989,"b":[["1115.76","50"],["1116.10","0"],["1119.68","190"],["1119.75","0"],["1122.69","1000"],["1123.92","50"],["1124.27","0"],["1126.72","0"],["1126.73","0"],["1126.77","0"],["1126.78","0"],["1126.79","0"],["1126.80","0"],["1126.81","0"],["1126.82","64"],["1126.83","0"],["1126.84","36"],["1126.85","0"],["1126.86","0"],["1126.87","64"],["1126.88","43"]],"a":[]}}
1618677485.2527459: {"stream":"btcusd_perp@depth@100ms","data":{"e":"depthUpdate","E":1618677480594,"T":1618677480589,"s":"BTCUSD_PERP","ps":"BTCUSD","U":86143357130,"u":86143357651,"pu":86143357106,"b":[["60367.2","0"],["60368.4","1808"],["60372.6","1809"],["60560.6","251"],["60560.7","243"],["60560.9","0"],["60574.6","1"],["60575.6","1"],["60579.9","1138"]],"a":[["60580.9","0"],["60581.1","8014"],["60585.6","100"],["60586.2","0"],["60595.1","0"],["60596.3","254"],["60596.4","122"],["60596.5","0"],["60607.9","380"],["60609.3","0"],["60620.7","0"],["60622.1","0"],["60622.6","0"],["60624.0","30"],["60695.7","1214"]]}}
1618677485.252785: {"stream":"dotusd_210625@depth@100ms","data":{"e":"depthUpdate","E":1618677480616,"T":1618677480596,"s":"DOTUSD_210625","ps":"DOTUSD","U":86143357266,"u":86143357700,"pu":86143357210,"b":[["46.279","0"]],"a":[["46.786","200"],["46.797","0"]]}}
1618677485.252841: {"stream":"linkusd_210924@depth@100ms","data":{"e":"depthUpdate","E":1618677480642,"T":1618677480625,"s":"LINKUSD_210924","ps":"LINKUSD","U":86143357384,"u":86143357872,"pu":86143357164,"b":[["44.891","0"],["45.058","850"],["45.075","250"],["45.199","0"],["45.200","0"],["45.206","1227"],["45.207","153"],["45.212","121"],["45.232","0"],["45.233","440"],["45.244","0"]],"a":[["45.329","119"],["45.330","316"],["45.345","250"]]}}
1618677485.252875: {"stream":"ethusd_210625@depth@100ms","data":{"e":"depthUpdate","E":1618677480654,"T":1618677480646,"s":"ETHUSD_210625","ps":"ETHUSD","U":86143357436,"u":86143357977,"pu":86143357279,"b":[["2505.49","587"],["2505.63","0"],["2505.75","0"],["2505.97","4234"],["2506.11","2075"],["2508.66","0"],["2508.81","0"],["2508.82","299"]],"a":[["2509.09","0"],["2512.87","500"],["2513.01","0"]]}}
1618677485.252908: {"stream":"linkusd_210625@depth@100ms","data":{"e":"depthUpdate","E":1618677480670,"T":1618677480665,"s":"LINKUSD_210625","ps":"LINKUSD","U":86143357521,"u":86143358076,"pu":86143357434,"b":[["42.944","943"],["43.294","951"],["43.502","150"],["43.519","0"],["43.709","0"]],"a":[["43.754","0"],["43.762","50"]]}}
1618677485.252929: {"stream":"bchusd_210625@depth@100ms","data":{"e":"depthUpdate","E":1618677480681,"T":1618677480673,"s":"BCHUSD_210625","ps":"BCHUSD","U":86143357580,"u":86143358109,"pu":86143357503,"b":[["1119.59","190"],["1119.68","0"],["1126.63","414"],["1126.64","86"],["1126.82","0"],["1126.84","0"],["1126.87","0"],["1126.88","14"],["1126.89","0"],["1126.90","0"],["1126.91","0"],["1126.92","64"],["1126.93","10"],["1126.94","35"],["1126.95","35"],["1126.96","35"]],"a":[["1128.75","0"]]}}
1618677485.2530508: {"stream":"btcusd_perp@depth@100ms","data":{"e":"depthUpdate","E":1618677480694,"T":1618677480689,"s":"BTCUSD_PERP","ps":"BTCUSD","U":86143357657,"u":86143358203,"pu":86143357651,"b":[["60369.6","0"],["60375.7","0"],["60382.3","0"],["60550.0","20"],["60553.6","2076"],["60560.6","251"],["60560.8","363"],["60560.9","0"]],"a":[["60580.9","0"],["60585.6","250"],["60586.9","15"],["60596.4","0"],["60597.4","0"],["60609.2","0"],["60610.2","0"],["60622.0","0"],["60622.9","1225"],["60623.0","3"],["60623.3","0"],["60623.9","8"],["60624.9","0"],["60656.4","0"],["60665.0","1905"]]}}
1618677485.253089: {"stream":"ethusd_210924@depth@100ms","data":{"e":"depthUpdate","E":1618677480710,"T":1618677480698,"s":"ETHUSD_210924","ps":"ETHUSD","U":86143357760,"u":86143358252,"pu":86143357366,"b":[["2685.02","0"],["2685.03","3443"],["2685.04","968"],["2685.45","0"],["2685.46","0"],["2687.46","0"],["2687.47","0"],["2687.60","0"],["2687.65","660"]],"a":[]}}
1618677485.253099: {"stream":"egldusd_perp@depth@100ms","data":{"e":"depthUpdate","E":1618677480711,"T":1618677480607,"s":"EGLDUSD_PERP","ps":"EGLDUSD","U":86143357761,"u":86143357761,"pu":86143357329,"b":[["216.075","54"]],"a":[]}}
1618677485.253108: {"stream":"btcusd_210924@depth@100ms","data":{"e":"depthUpdate","E":1618677480716,"T":1618677480682,"s":"BTCUSD_210924","ps":"BTCUSD","U":86143357782,"u":86143358161,"pu":86143357075,"b":[["68561.1","1456"]],"a":[["69163.3","1292"]]}}
1618677485.253139: {"stream":"xrpusd_210625@depth@100ms","data":{"e":"depthUpdate","E":1618677480726,"T":1618677480670,"s":"XRPUSD_210625","ps":"XRPUSD","U":86143357862,"u":86143358094,"pu":86143357301,"b":[],"a":[["1.6910","45"],["1.6911","0"]]}}
1618677485.25316: {"stream":"dotusd_210625@depth@100ms","data":{"e":"depthUpdate","E":1618677480732,"T":1618677480721,"s":"DOTUSD_210625","ps":"DOTUSD","U":86143357886,"u":86143358322,"pu":86143357700,"b":[["46.517","1377"],["46.542","0"],["46.673","3"],["46.733","104"]],"a":[["46.785","42"],["46.787","0"]]}}
1618677485.253203: {"stream":"ethusd_210625@depth@100ms","data":{"e":"depthUpdate","E":1618677480760,"T":1618677480746,"s":"ETHUSD_210625","ps":"ETHUSD","U":86143358015,"u":86143358448,"pu":86143357977,"b":[["2505.36","4318"],["2505.47","2028"],["2505.97","1433"],["2506.07","23364"],["2507.42","300"],["2508.71","299"],["2508.82","0"]],"a":[["2509.09","0"]]}}
1618677485.2532349: {"stream":"linkusd_210924@depth@100ms","data":{"e":"depthUpdate","E":1618677480767,"T":1618677480721,"s":"LINKUSD_210924","ps":"LINKUSD","U":86143358060,"u":86143358326,"pu":86143357872,"b":[["44.497","0"],["45.197","2673"],["45.207","173"]],"a":[["45.345","0"]]}}
1618677485.253244: {"stream":"bchusd_210625@depth@100ms","data":{"e":"depthUpdate","E":1618677480785,"T":1618677480755,"s":"BCHUSD_210625","ps":"BCHUSD","U":86143358158,"u":86143358494,"pu":86143358109,"b":[["1121.53","290"],["1126.88","0"],["1126.92","0"],["1126.93","0"],["1126.94","0"],["1126.95","0"],["1126.96","0"],["1126.97","0"],["1126.98","64"],["1126.99","35"],["1127.00","0"],["1127.01","0"],["1127.02","0"],["1127.03","64"],["1127.04","35"]],"a":[["1139.16","0"]]}}
1618677485.253338: {"stream":"btcusd_perp@depth@100ms","data":{"e":"depthUpdate","E":1618677480798,"T":1618677480779,"s":"BTCUSD_PERP","ps":"BTCUSD","U":86143358217,"u":86143358615,"pu":86143358203,"b":[["60355.9","0"],["60372.6","0"],["60378.1","1780"]],"a":[["60580.9","0"],["60581.1","8008"],["60585.6","100"],["60586.3","175"],["60596.5","122"],["60609.3","243"],["60622.1","243"],["60624.0","273"]]}}
1618677485.2533948: {"stream":"ethusd_210924@depth@100ms","data":{"e":"depthUpdate","E":1618677480832,"T":1618677480827,"s":"ETHUSD_210924","ps":"ETHUSD","U":86143358357,"u":86143358882,"pu":86143358252,"b":[["2683.31","0"],["2686.13","0"],["2686.79","0"],["2687.38","660"],["2687.46","0"],["2687.47","0"],["2687.65","0"]],"a":[["2688.70","0"]]}}
1618677485.253428: {"stream":"dotusd_210625@depth@100ms","data":{"e":"depthUpdate","E":1618677480841,"T":1618677480811,"s":"DOTUSD_210625","ps":"DOTUSD","U":86143358403,"u":86143358791,"pu":86143358322,"b":[["46.673","5"],["46.722","0"],["46.732","540"]],"a":[["46.760","200"],["46.761","540"],["46.764","0"],["46.786","0"]]}}
1618677485.253505: {"stream":"ethusd_210625@depth@100ms","data":{"e":"depthUpdate","E":1618677480864,"T":1618677480842,"s":"ETHUSD_210625","ps":"ETHUSD","U":86143358517,"u":86143358957,"pu":86143358448,"b":[["2507.43","0"],["2508.12","0"],["2508.45","0"],["2508.66","299"],["2508.71","0"]],"a":[["2509.09","0"]]}}
1618677485.253525: {"stream":"xrpusd_210625@depth@100ms","data":{"e":"depthUpdate","E":1618677480876,"T":1618677480848,"s":"XRPUSD_210625","ps":"XRPUSD","U":86143358590,"u":86143358993,"pu":86143358094,"b":[["1.6815","330"],["1.6887","102"]],"a":[]}}
1618677485.253556: {"stream":"linkusd_210924@depth@100ms","data":{"e":"depthUpdate","E":1618677480880,"T":1618677480818,"s":"LINKUSD_210924","ps":"LINKUSD","U":86143358601,"u":86143358832,"pu":86143358326,"b":[["44.496","40"],["45.199","1152"],["45.200","175"],["45.206","75"],["45.207","20"]],"a":[]}}
1618677485.2535648: {"stream":"linkusd_210625@depth@100ms","data":{"e":"depthUpdate","E":1618677480885,"T":1618677480821,"s":"LINKUSD_210625","ps":"LINKUSD","U":86143358625,"u":86143358849,"pu":86143358076,"b":[],"a":[["43.750","50"],["43.762","0"],["44.841","1030"]]}}
1618677485.2535849: {"stream":"bchusd_210625@depth@100ms","data":{"e":"depthUpdate","E":1618677480891,"T":1618677480887,"s":"BCHUSD_210625","ps":"BCHUSD","U":86143358644,"u":86143359188,"pu":86143358494,"b":[["1115.76","0"],["1116.37","0"],["1123.92","0"],["1124.54","50"],["1126.98","0"],["1126.99","0"],["1127.03","0"],["1127.04","0"],["1127.05","0"],["1127.06","0"],["1127.07","0"],["1127.08","64"],["1127.09","0"],["1127.10","0"],["1127.11","0"],["1127.12","92"],["1127.13","35"]],"a":[["1139.15","190"]]}}
1618677485.2536662: {"stream":"btcusd_perp@depth@100ms","data":{"e":"depthUpdate","E":1618677480904,"T":1618677480883,"s":"BTCUSD_PERP","ps":"BTCUSD","U":86143358708,"u":86143359171,"pu":86143358615,"b":[["59308.3","0"],["60540.3","0"],["60579.9","198"],["60580.0","1157"]],"a":[["60580.9","0"],["60586.3","25"],["60669.7","538"],["60681.6","0"]]}}
1618677485.253678: {"stream":"btcusd_210924@depth@100ms","data":{"e":"depthUpdate","E":1618677480904,"T":1618677480799,"s":"BTCUSD_210924","ps":"BTCUSD","U":86143358704,"u":86143358707,"pu":86143358161,"b":[["68561.0","0"],["68578.6","728"]],"a":[]}}
1618677485.253792: {"stream":"dotusd_210625@depth@100ms","data":{"e":"depthUpdate","E":1618677480953,"T":1618677480925,"s":"DOTUSD_210625","ps":"DOTUSD","U":86143358989,"u":86143359429,"pu":86143358791,"b":[["46.517","0"],["46.542","1377"],["46.720","104"],["46.733","0"]],"a":[["46.755","0"],["46.756","256"],["46.758","540"],["46.760","0"],["46.761","0"],["46.784","200"],["46.785","0"],["46.787","42"],["46.788","232"],["46.829","0"]]}}
1618677485.253974: {"stream":"ethusd_210625@depth@100ms","data":{"e":"depthUpdate","E":1618677480987,"T":1618677480982,"s":"ETHUSD_210625","ps":"ETHUSD","U":86143359162,"u":86143359803,"pu":86143358957,"b":[["2500.02","213"],["2503.59","3035"],["2508.66","0"],["2508.81","299"]],"a":[["2509.09","0"],["2512.87","0"]]}}
1618677485.254017: {"stream":"ethusd_210924@depth@100ms","data":{"e":"depthUpdate","E":1618677480948,"T":1618677480930,"s":"ETHUSD_210924","ps":"ETHUSD","U":86143358977,"u":86143359451,"pu":86143358882,"b":[["2553.39","1000"],["2687.38","0"],["2687.46","660"],["2687.47","204"],["2687.59","0"],["2687.64","0"],["2687.65","0"]],"a":[["2687.84","50"],["2695.59","6661"],["2695.88","0"]]}}
1618677485.254038: {"stream":"egldusd_perp@depth@100ms","data":{"e":"depthUpdate","E":1618677480984,"T":1618677480879,"s":"EGLDUSD_PERP","ps":"EGLDUSD","U":86143359143,"u":86143359147,"pu":86143357761,"b":[],"a":[["216.471","0"],["216.598","597"]]}}
1618677485.254061: {"stream":"linkusd_210625@depth@100ms","data":{"e":"depthUpdate","E":1618677480987,"T":1618677480968,"s":"LINKUSD_210625","ps":"LINKUSD","U":86143359175,"u":86143359682,"pu":86143358849,"b":[["43.294","0"],["43.608","0"],["43.619","323"]],"a":[["43.747","45"],["43.759","32"],["43.784","0"],["43.785","100"],["43.804","2190"],["43.814","0"],["43.924","0"],["44.841","0"]]}}
1618677485.254072: {"stream":"bchusd_210625@depth@100ms","data":{"e":"depthUpdate","E":1618677480991,"T":1618677480986,"s":"BCHUSD_210625","ps":"BCHUSD","U":86143359189,"u":86143359855,"pu":86143359188,"b":[["1115.76","50"],["1119.59","0"],["1119.68","190"],["1123.93","50"],["1124.54","0"],["1127.08","0"],["1127.09","0"],["1127.12","64"],["1127.13","0"],["1127.14","35"],["1127.15","0"],["1127.16","0"],["1127.17","64"],["1127.18","0"],["1127.19","0"],["1127.20","40"]],"a":[]}}
1618677485.2542331: {"stream":"btcusd_perp@depth@100ms","data":{"e":"depthUpdate","E":1618677481008,"T":1618677481003,"s":"BTCUSD_PERP","ps":"BTCUSD","U":86143359301,"u":86143359953,"pu":86143359171,"b":[["60334.7","3614"],["60345.6","1807"],["60369.6","1781"],["60372.7","1809"],["60375.7","1808"],["60376.3","0"],["60378.1","0"],["60382.4","1809"],["60568.6","200"],["60570.8","100"],["60580.0","217"],["60580.1","940"],["60580.2","0"],["60581.2","0"]],"a":[["60581.9","0"],["60585.6","250"],["60586.0","96"],["60614.4","30"],["60651.9","1"],["60785.8","0"],["60788.2","0"],["60804.4","1821"],["60816.5","1821"],["60827.4","3611"]]}}
1618677485.254288: {"stream":"xrpusd_210625@depth@100ms","data":{"e":"depthUpdate","E":1618677481011,"T":1618677481006,"s":"XRPUSD_210625","ps":"XRPUSD","U":86143359319,"u":86143359972,"pu":86143358993,"b":[["1.6817","8349"],["1.6891","0"],["1.6892","0"],["1.6893","45"],["1.6894","0"],["1.6895","45"]],"a":[["1.6904","148"],["1.6908","0"],["1.6914","0"],["1.6928","0"],["1.6940","1139"],["1.6947","0"],["1.6953","2034"]]}}
1618677485.254299: {"stream":"linkusd_210924@depth@100ms","data":{"e":"depthUpdate","E":1618677481012,"T":1618677481005,"s":"LINKUSD_210924","ps":"LINKUSD","U":86143359324,"u":86143359965,"pu":86143358832,"b":[["45.199","0"],["45.200","0"],["45.208","1152"],["45.209","120"]],"a":[["45.329","0"],["45.330","0"]]}}
1618677485.254421: {"stream":"ethusd_210924@depth@100ms","data":{"e":"depthUpdate","E":1618677481059,"T":1618677481049,"s":"ETHUSD_210924","ps":"ETHUSD","U":86143359591,"u":86143360305,"pu":86143359451,"b":[["2687.46","0"],["2687.47","0"],["2687.48","660"],["2687.49","204"],["2687.65","0"],["2687.66","0"]],"a":[["2687.84","170"],["2695.58","13323"],["2695.60","0"]]}}
1618677485.254454: {"stream":"dotusd_210625@depth@100ms","data":{"e":"depthUpdate","E":1618677481067,"T":1618677481056,"s":"DOTUSD_210625","ps":"DOTUSD","U":86143359662,"u":86143360361,"pu":86143359429,"b":[["46.542","0"],["46.549","1376"]],"a":[["46.757","0"],["46.762","0"],["46.783","42"],["46.784","0"],["46.787","0"]]}}
1618677485.254498: {"stream":"bchusd_210625@depth@100ms","data":{"e":"depthUpdate","E":1618677481091,"T":1618677481086,"s":"BCHUSD_210625","ps":"BCHUSD","U":86143359863,"u":86143360497,"pu":86143359855,"b":[["1127.12","0"],["1127.14","0"],["1127.17","0"],["1127.18","0"],["1127.20","0"],["1127.21","0"],["1127.22","64"],["1127.23","0"],["1127.24","36"],["1127.25","0"],["1127.26","0"],["1127.27","64"],["1127.28","42"],["1127.29","35"]],"a":[]}}
1618677485.254564: {"stream":"linkusd_210625@depth@100ms","data":{"e":"depthUpdate","E":1618677481098,"T":1618677481069,"s":"LINKUSD_210625","ps":"LINKUSD","U":86143359893,"u":86143360430,"pu":86143359682,"b":[["42.944","0"],["43.706","48"]],"a":[["43.746","63"],["43.747","32"],["43.750","0"],["43.927","180"]]}}
1618677485.2546: {"stream":"btcusd_perp@depth@100ms","data":{"e":"depthUpdate","E":1618677481114,"T":1618677481100,"s":"BTCUSD_PERP","ps":"BTCUSD","U":86143359999,"u":86143360589,"pu":86143359953,"b":[["59296.7","132"],["59551.1","132"],["59781.3","66"],["59841.9","66"],["59975.2","134"],["60035.8","132"],["60205.4","189"],["60355.9","1808"],["60359.3","1775"],["60366.6","3599"],["60371.4","0"],["60378.1","1809"],["60380.5","0"],["60560.6","129"],["60560.9","122"],["60581.2","0"]],"a":[["60581.1","8007"],["60596.5","0"],["60597.3","122"],["60609.3","0"],["60610.0","243"],["60614.4","0"],["60622.1","0"],["60622.8","243"],["60624.0","30"],["60624.7","243"],["60789.5","1821"],["60790.7","0"],["60794.9","0"],["60802.8","1807"],["60811.3","0"]]}}
1618677485.254615: {"stream":"xrpusd_210625@depth@100ms","data":{"e":"depthUpdate","E":1618677481114,"T":1618677481100,"s":"XRPUSD_210625","ps":"XRPUSD","U":86143360009,"u":86143360593,"pu":86143359972,"b":[["1.6787","0"],["1.6789","100"],["1.6872","250"],["1.6875","12"],["1.6879","148"],["1.6880","0"],["1.6882","100"],["1.6891","45"],["1.6893","0"],["1.6895","0"]],"a":[["1.6910","0"],["1.6921","1212"]]}}
1618677485.2546718: {"stream":"btcusd_210924@depth@100ms","data":{"e":"depthUpdate","E":1618677481152,"T":1618677481065,"s":"BTCUSD_210924","ps":"BTCUSD","U":86143360299,"u":86143360402,"pu":86143358707,"b":[["68561.1","0"],["68590.7","1446"],["68592.0","325"]],"a":[]}}
1618677485.254681: {"stream":"ethusd_210924@depth@100ms","data":{"e":"depthUpdate","E":1618677481169,"T":1618677481066,"s":"ETHUSD_210924","ps":"ETHUSD","U":86143360409,"u":86143360409,"pu":86143360305,"b":[],"a":[["2687.84","50"]]}}
1618677485.254689: {"stream":"dotusd_210625@depth@100ms","data":{"e":"depthUpdate","E":1618677481170,"T":1618677481123,"s":"DOTUSD_210625","ps":"DOTUSD","U":86143360410,"u":86143360730,"pu":86143360361,"b":[],"a":[["46.755","200"],["46.757","0"],["46.783","0"],["46.787","42"],["47.066","610"]]}}
1618677485.25471: {"stream":"bchusd_210625@depth@100ms","data":{"e":"depthUpdate","E":1618677481198,"T":1618677481141,"s":"BCHUSD_210625","ps":"BCHUSD","U":86143360527,"u":86143360851,"pu":86143360497,"b":[["1127.22","0"],["1127.24","0"],["1127.28","14"],["1127.29","0"],["1127.30","0"],["1127.32","64"],["1127.33","5"]],"a":[["1128.58","0"]]}}
1618677485.254774: {"stream":"linkusd_210625@depth@100ms","data":{"e":"depthUpdate","E":1618677481218,"T":1618677481162,"s":"LINKUSD_210625","ps":"LINKUSD","U":86143360641,"u":86143360924,"pu":86143360430,"b":[["43.578","467"],["43.661","0"]],"a":[["43.746","50"],["43.759","45"],["43.927","0"]]}}
1618677485.254796: {"stream":"xrpusd_210625@depth@100ms","data":{"e":"depthUpdate","E":1618677481225,"T":1618677481215,"s":"XRPUSD_210625","ps":"XRPUSD","U":86143360716,"u":86143361221,"pu":86143360593,"b":[["1.6882","199"],["1.6887","102"],["1.6891","0"]],"a":[["1.6904","48"],["1.6907","0"],["1.6912","0"],["1.6923","12"],["1.6929","616"]]}}
1618677485.254805: {"stream":"linkusd_210924@depth@100ms","data":{"e":"depthUpdate","E":1618677481224,"T":1618677481177,"s":"LINKUSD_210924","ps":"LINKUSD","U":86143360704,"u":86143361002,"pu":86143359965,"b":[["44.878","40"]],"a":[["45.396","5514"],["45.406","0"]]}}
1618677485.254814: {"stream":"btcusd_perp@depth@100ms","data":{"e":"depthUpdate","E":1618677481246,"T":1618677481214,"s":"BTCUSD_PERP","ps":"BTCUSD","U":86143360853,"u":86143361216,"pu":86143360589,"b":[["60380.5","1808"],["60514.1","0"]],"a":[["60625.3","0"],["60626.6","1405"],["60795.5","3593"]]}}
1618677485.2548459: {"stream":"ethusd_210625@depth@100ms","data":{"e":"depthUpdate","E":1618677481275,"T":1618677481265,"s":"ETHUSD_210625","ps":"ETHUSD","U":86143360972,"u":86143361525,"pu":86143359803,"b":[["2504.43","0"],["2504.71","0"],["2505.08","0"],["2505.11","0"],["2505.76","1300"],["2505.84","0"],["2505.88","0"],["2505.90","0"],["2506.02","0"],["2506.03","0"],["2506.05","0"],["2506.11","2075"],["2506.14","0"],["2506.42","0"],["2506.47","0"],["2506.55","0"],["2508.66","0"],["2508.81","0"],["2508.82","299"]],"a":[["2509.09","0"],["2509.11","5357"],["2509.22","0"],["2509.26","0"],["2509.31","0"],["2509.38","0"],["2509.39","0"],["2509.64","1288"],["2509.65","2025"],["2509.81","0"],["2509.85","0"],["2510.02","1250"],["2510.12","2365"],["2510.15","0"],["2510.16","0"],["2510.31","0"],["2510.39","0"],["2510.65","1083"],["2510.66","0"],["2512.16","0"]]}}
1618677485.2548852: {"stream":"dotusd_210625@depth@100ms","data":{"e":"depthUpdate","E":1618677481290,"T":1618677481249,"s":"DOTUSD_210625","ps":"DOTUSD","U":86143361061,"u":86143361441,"pu":86143360730,"b":[["46.199","520"],["46.207","0"]],"a":[["46.849","1813"],["46.854","0"]]}}
1618677485.2549171: {"stream":"bchusd_210625@depth@100ms","data":{"e":"depthUpdate","E":1618677481305,"T":1618677481285,"s":"BCHUSD_210625","ps":"BCHUSD","U":86143361123,"u":86143361693,"pu":86143360851,"b":[["1115.76","0"],["1116.37","50"],["1123.93","0"],["1124.54","50"],["1127.27","0"],["1127.33","19"],["1127.34","35"]],"a":[["1131.19","96"],["1137.20","0"],["1137.62","1840"],["1145.35","0"],["1145.94","629"]]}}
1618677485.2551281: {"stream":"ethusd_210924@depth@100ms","data":{"e":"depthUpdate","E":1618677481325,"T":1618677481308,"s":"ETHUSD_210924","ps":"ETHUSD","U":86143361258,"u":86143361879,"pu":86143360409,"b":[["2685.03","0"],["2685.04","0"],["2685.45","3514"],["2685.46","770"],["2686.79","0"],["2687.48","0"],["2687.49","0"],["2687.50","725"]],"a":[["2687.84","170"]]}}
1618677485.2551382: {"stream":"linkusd_210625@depth@100ms","data":{"e":"depthUpdate","E":1618677481330,"T":1618677481298,"s":"LINKUSD_210625","ps":"LINKUSD","U":86143361276,"u":86143361794,"pu":86143360924,"b":[],"a":[["43.746","0"],["43.762","50"],["43.930","180"]]}}
1618677485.255147: {"stream":"xrpusd_210625@depth@100ms","data":{"e":"depthUpdate","E":1618677481333,"T":1618677481318,"s":"XRPUSD_210625","ps":"XRPUSD","U":86143361316,"u":86143361959,"pu":86143361221,"b":[["1.6817","8269"],["1.6818","189"],["1.6843","401"],["1.6854","422"],["1.6879","100"],["1.6883","48"],["1.6887","148"],["1.6891","63"]],"a":[["1.6904","0"],["1.6912","293"],["1.6913","157"],["1.6915","164"],["1.6919","0"],["1.6921","12"],["1.6929","1816"],["1.6953","144"],["1.6955","0"],["1.6956","0"],["1.6962","5461"],["1.6964","1670"]]}}
1618677485.255171: {"stream":"btcusd_210924@depth@100ms","data":{"e":"depthUpdate","E":1618677481339,"T":1618677481301,"s":"BTCUSD_210924","ps":"BTCUSD","U":86143361354,"u":86143361817,"pu":86143360402,"b":[["68560.9","0"],["68585.7","529"],["68585.8","176"]],"a":[["68616.1","90"]]}}
1618677485.255214: {"stream":"btcusd_perp@depth@100ms","data":{"e":"depthUpdate","E":1618677481359,"T":1618677481354,"s":"BTCUSD_PERP","ps":"BTCUSD","U":86143361473,"u":86143362181,"pu":86143361216,"b":[["59500.0","32127"],["59924.2","0"],["60372.3","0"],["60495.4","42"],["60502.7","19"],["60560.8","363"],["60560.9","0"],["60581.2","0"]],"a":[["60581.1","8013"],["60581.8","0"],["60584.2","130"],["60585.6","100"],["60586.0","246"],["60597.2","0"],["60597.3","0"],["60599.9","0"],["60602.3","122"],["60610.0","0"],["60612.7","0"],["60615.1","243"],["60622.8","0"],["60624.7","0"],["60625.5","0"],["60627.4","99"],["60627.9","245"],["60798.3","0"],["60811.2","1804"],["61141.2","0"]]}}
1618677485.255252: {"stream":"linkusd_210924@depth@100ms","data":{"e":"depthUpdate","E":1618677481366,"T":1618677481262,"s":"LINKUSD_210924","ps":"LINKUSD","U":86143361513,"u":86143361513,"pu":86143361002,"b":[],"a":[["45.396","365"]]}}
1618677485.255317: {"stream":"ethusd_210625@depth@100ms","data":{"e":"depthUpdate","E":1618677481378,"T":1618677481371,"s":"ETHUSD_210625","ps":"ETHUSD","U":86143361578,"u":86143362270,"pu":86143361525,"b":[["2504.91","1505"],["2505.08","1204"],["2505.28","1528"],["2505.30","1651"],["2505.84","963"],["2506.04","2316"],["2506.08","2048"],["2506.10","1359"],["2506.11","2845"],["2506.14","838"],["2506.25","1353"],["2506.39","856"],["2506.40","616"],["2506.62","1193"],["2506.63","835"],["2507.03","0"],["2508.27","0"],["2508.71","249"],["2509.10","1312"]],"a":[["2509.09","0"],["2509.21","0"],["2509.26","564"],["2509.31","1534"],["2509.32","835"],["2509.39","1353"],["2509.56","606"],["2509.60","616"],["2509.65","2863"],["2509.68","716"],["2509.82","770"],["2509.85","1132"],["2510.12","3724"],["2510.13","1651"],["2510.15","2491"],["2510.16","1204"],["2510.24","0"],["2510.31","1505"],["2510.66","1193"],["2513.02","500"],["2514.29","0"],["2514.72","0"],["2520.37","2000"]]}}
1618677485.255436: {"stream":"bchusd_210625@depth@100ms","data":{"e":"depthUpdate","E":1618677481406,"T":1618677481398,"s":"BCHUSD_210625","ps":"BCHUSD","U":86143361815,"u":86143362421,"pu":86143361693,"b":[["1116.37","50"],["1119.68","0"],["1119.74","543"],["1123.93","0"],["1124.54","0"],["1127.28","0"],["1127.32","0"],["1127.33","0"],["1127.34","0"],["1127.35","64"],["1127.36","0"],["1127.37","35"],["1127.38","64"]],"a":[["1131.49","0"]]}}
1618677485.255562: {"stream":"dotusd_210625@depth@100ms","data":{"e":"depthUpdate","E":1618677481412,"T":1618677481371,"s":"DOTUSD_210625","ps":"DOTUSD","U":86143361891,"u":86143362277,"pu":86143361441,"b":[["46.673","3"],["46.733","1"]],"a":[["46.755","0"],["46.756","0"],["46.762","200"],["46.763","0"],["46.786","0"],["46.961","0"],["46.993","1550"]]}}
1618677485.2556531: {"stream":"xrpusd_210625@depth@100ms","data":{"e":"depthUpdate","E":1618677481433,"T":1618677481421,"s":"XRPUSD_210625","ps":"XRPUSD","U":86143362047,"u":86143362569,"pu":86143361959,"b":[["1.6716","0"],["1.6818","1817"],["1.6891","18"],["1.6892","581"],["1.6893","45"]],"a":[["1.6910","100"],["1.6911","0"],["1.6912","193"],["1.6914","45"],["1.6959","2310"],["1.6962","3600"],["1.7021","0"]]}}
1618677485.2556858: {"stream":"btcusd_perp@depth@100ms","data":{"e":"depthUpdate","E":1618677481459,"T":1618677481452,"s":"BTCUSD_PERP","ps":"BTCUSD","U":86143362185,"u":86143362770,"pu":86143362181,"b":[["60253.1","100"],["60363.8","0"],["60371.5","1809"],["60372.7","3618"],["60376.3","1809"],["60561.1","0"],["60571.8","100"],["60571.9","0"],["60581.2","0"]],"a":[["60581.1","7973"],["60583.9","30"],["60584.2","100"],["60586.7","0"],["60586.9","55"],["60593.3","0"],["60597.0","99"],["60600.8","0"],["60601.1","0"],["60602.3","0"],["60613.5","243"],["60613.9","0"],["60615.1","0"],["60626.3","731"],["60626.7","0"],["60627.9","2"],["60628.2","243"],["60628.6","0"],["60629.8","634"],["60785.8","1821"],["60790.6","1821"],["60859.3","0"]]}}
1618677485.255736: {"stream":"egldusd_perp@depth@100ms","data":{"e":"depthUpdate","E":1618677481458,"T":1618677481421,"s":"EGLDUSD_PERP","ps":"EGLDUSD","U":86143362177,"u":86143362563,"pu":86143359147,"b":[],"a":[["216.171","0"],["216.218","0"],["216.252","97"],["216.309","29"],["216.347","104"],["216.348","463"],["216.349","0"],["216.350","0"],["216.486","15"],["216.505","503"]]}}
1618677485.2558122: {"stream":"linkusd_210924@depth@100ms","data":{"e":"depthUpdate","E":1618677481466,"T":1618677481443,"s":"LINKUSD_210924","ps":"LINKUSD","U":86143362228,"u":86143362712,"pu":86143361513,"b":[["45.209","187"]],"a":[["45.394","0"],["45.505","0"]]}}
1618677485.255928: {"stream":"btcusd_210924@depth@100ms","data":{"e":"depthUpdate","E":1618677481491,"T":1618677481478,"s":"BTCUSD_210924","ps":"BTCUSD","U":86143362356,"u":86143362933,"pu":86143361817,"b":[["68578.6","0"],["68592.1","716"]],"a":[["68616.1","90"]]}}
1618677485.255937: {"stream":"ethusd_210625@depth@100ms","data":{"e":"depthUpdate","E":1618677481496,"T":1618677481485,"s":"ETHUSD_210625","ps":"ETHUSD","U":86143362380,"u":86143362972,"pu":86143362270,"b":[["2504.52","2601"],["2505.47","0"],["2505.86","391"],["2506.07","25392"],["2508.66","182"],["2508.71","0"],["2508.81","299"],["2508.82","0"],["2509.10","1312"]],"a":[["2509.09","0"],["2509.11","7054"],["2509.25","1023"],["2509.30","1173"],["2509.56","0"],["2509.64","0"],["2510.65","1474"],["2512.15","2601"],["2513.02","0"],["2514.72","1000"]]}}
1618677485.255973: {"stream":"linkusd_210625@depth@100ms","data":{"e":"depthUpdate","E":1618677481502,"T":1618677481479,"s":"LINKUSD_210625","ps":"LINKUSD","U":86143362424,"u":86143362937,"pu":86143361794,"b":[["43.584","24"],["43.600","0"],["43.716","0"],["43.717","0"],["43.718","0"],["43.719","0"],["43.723","414"],["43.724","86"],["43.726","107"],["43.727","22"],["43.728","100"],["43.729","48"]],"a":[["43.744","0"],["43.746","0"],["43.747","0"],["43.750","0"],["43.756","0"],["43.758","1"],["43.760","0"],["43.762","0"],["43.764","100"],["43.766","202"],["43.768","100"],["43.784","24"],["43.792","411"],["43.849","0"]]}}
1618677485.255986: {"stream":"bchusd_210625@depth@100ms","data":{"e":"depthUpdate","E":1618677481508,"T":1618677481498,"s":"BCHUSD_210625","ps":"BCHUSD","U":86143362474,"u":86143363056,"pu":86143362421,"b":[["1119.74","353"],["1119.94","190"],["1124.54","141"],["1124.82","250"],["1127.37","0"],["1127.39","35"]],"a":[["1128.63","101"],["1131.48","100"],["1131.95","0"]]}}
1618677485.256038: {"stream":"ethusd_210924@depth@100ms","data":{"e":"depthUpdate","E":1618677481510,"T":1618677481468,"s":"ETHUSD_210924","ps":"ETHUSD","U":86143362479,"u":86143362864,"pu":86143361879,"b":[["2676.55","0"],["2686.79","0"],["2687.38","660"],["2687.50","65"]],"a":[["2695.24","6768"],["2695.59","0"]]}}
1618677485.256062: {"stream":"dotusd_210625@depth@100ms","data":{"e":"depthUpdate","E":1618677481520,"T":1618677481491,"s":"DOTUSD_210625","ps":"DOTUSD","U":86143362555,"u":86143363017,"pu":86143362277,"b":[["46.517","1386"],["46.549","0"],["46.673","5"],["46.733","0"]],"a":[["46.757","200"],["46.762","0"],["46.941","303"],["47.170","0"]]}}
1618677485.256106: {"stream":"btcusd_perp@depth@100ms","data":{"e":"depthUpdate","E":1618677481559,"T":1618677481552,"s":"BTCUSD_PERP","ps":"BTCUSD","U":86143362784,"u":86143363394,"pu":86143362770,"b":[["15555.0","0"],["60353.9","0"],["60369.8","1809"],["60560.9","122"],["60561.0","0"],["60566.8","823"],["60571.7","0"],["60574.2","100"],["60578.2","100"],["60581.0","6015"],["60581.1","0"],["60581.2","0"]],"a":[["60581.1","8003"],["60583.9","0"],["60585.7","15"],["60586.0","246"],["60593.7","50"],["60599.1","340"],["60599.9","0"],["60600.9","0"],["60604.3","40"],["60611.9","243"],["60612.7","0"],["60613.5","0"],["60624.7","243"],["60625.5","0"],["60626.3","488"],["60626.6","1648"],["60627.4","99"],["60628.2","0"],["60789.4","1821"],["60830.4","5445"],["60944.5","6"],["60956.6","66"]]}}
1618677485.2561212: {"stream":"xrpusd_210625@depth@100ms","data":{"e":"depthUpdate","E":1618677481565,"T":1618677481535,"s":"XRPUSD_210625","ps":"XRPUSD","U":86143362812,"u":86143363289,"pu":86143362569,"b":[["1.6789","0"],["1.6791","100"],["1.6882","99"],["1.6884","100"]],"a":[["1.6912","48"],["1.6913","12"],["1.6914","0"],["1.6919","0"]]}}
1618677485.2561421: {"stream":"egldusd_perp@depth@100ms","data":{"e":"depthUpdate","E":1618677481569,"T":1618677481533,"s":"EGLDUSD_PERP","ps":"EGLDUSD","U":86143362851,"u":86143363283,"pu":86143362563,"b":[["215.833","0"],["216.016","97"],["216.065","0"],["216.071","0"]],"a":[["216.161","0"],["216.190","170"],["216.231","97"],["216.245","4"],["216.252","0"],["216.308","78"],["216.310","0"],["216.343","97"],["216.344","466"],["216.345","0"],["216.346","0"],["216.347","0"],["216.348","0"],["216.747","41"]]}}
1618677485.256263: {"stream":"btcusd_210924@depth@100ms","data":{"e":"depthUpdate","E":1618677481593,"T":1618677481513,"s":"BTCUSD_210924","ps":"BTCUSD","U":86143363011,"u":86143363151,"pu":86143362933,"b":[["68585.5","15"],["68592.0","280"],["68592.2","47"]],"a":[["68624.0","0"],["68625.1","20"],["68722.8","15"]]}}
1618677485.256296: {"stream":"bchusd_210625@depth@100ms","data":{"e":"depthUpdate","E":1618677481616,"T":1618677481611,"s":"BCHUSD_210625","ps":"BCHUSD","U":86143363135,"u":86143363674,"pu":86143363056,"b":[["1115.89","400"],["1116.37","0"],["1119.77","0"],["1119.94","0"],["1124.06","141"],["1124.46","0"],["1124.54","0"],["1124.61","0"],["1124.82","0"],["1126.67","35"],["1127.38","0"],["1127.39","0"]],"a":[["1131.19","0"],["1131.48","0"],["1131.75","100"],["1139.13","0"],["1139.15","0"]]}}
1618677485.256383: {"stream":"ethusd_210924@depth@100ms","data":{"e":"depthUpdate","E":1618677481617,"T":1618677481611,"s":"ETHUSD_210924","ps":"ETHUSD","U":86143363155,"u":86143363675,"pu":86143362864,"b":[["2685.45","0"]],"a":[["2687.84","50"],["2691.37","0"],["2695.07","1776"]]}}
1618677485.256395: {"stream":"dotusd_210625@depth@100ms","data":{"e":"depthUpdate","E":1618677481628,"T":1618677481564,"s":"DOTUSD_210625","ps":"DOTUSD","U":86143363217,"u":86143363467,"pu":86143363017,"b":[],"a":[["46.757","200"],["46.764","0"]]}}
1618677485.256417: {"stream":"ethusd_210625@depth@100ms","data":{"e":"depthUpdate","E":1618677481636,"T":1618677481620,"s":"ETHUSD_210625","ps":"ETHUSD","U":86143363276,"u":86143363728,"pu":86143362972,"b":[],"a":[["2509.09","0"],["2509.11","7175"],["2509.25","902"],["2509.30","1173"],["2513.12","3482"]]}}
1618677485.256441: {"stream":"linkusd_210924@depth@100ms","data":{"e":"depthUpdate","E":1618677481657,"T":1618677481552,"s":"LINKUSD_210924","ps":"LINKUSD","U":86143363398,"u":86143363398,"pu":86143362712,"b":[],"a":[["45.406","5338"]]}}
1618677485.25645: {"stream":"btcusd_perp@depth@100ms","data":{"e":"depthUpdate","E":1618677481661,"T":1618677481637,"s":"BTCUSD_PERP","ps":"BTCUSD","U":86143363422,"u":86143363835,"pu":86143363394,"b":[["60352.9","0"],["60363.8","1808"],["60560.9","0"],["60561.0","122"],["60581.2","0"]],"a":[["60585.6","250"],["60586.0","96"],["60598.8","0"],["60599.1","218"],["60695.7","114"],["60698.3","1100"],["60798.3","1821"],["60935.5","0"]]}}
1618677485.256472: {"stream":"linkusd_210625@depth@100ms","data":{"e":"depthUpdate","E":1618677481666,"T":1618677481657,"s":"LINKUSD_210625","ps":"LINKUSD","U":86143363451,"u":86143363907,"pu":86143362937,"b":[["39.397","865"],["43.697","250"],["43.729","29"],["43.731","32"]],"a":[["43.758","51"],["43.765","0"]]}}
1618677485.256481: {"stream":"xrpusd_210625@depth@100ms","data":{"e":"depthUpdate","E":1618677481667,"T":1618677481654,"s":"XRPUSD_210625","ps":"XRPUSD","U":86143363464,"u":86143363898,"pu":86143363289,"b":[["1.6791","0"],["1.6794","100"],["1.6876","720"],["1.6884","0"],["1.6887","248"]],"a":[["1.6919","45"]]}}
1618677485.256489: {"stream":"egldusd_perp@depth@100ms","data":{"e":"depthUpdate","E":1618677481677,"T":1618677481635,"s":"EGLDUSD_PERP","ps":"EGLDUSD","U":86143363512,"u":86143363828,"pu":86143363283,"b":[["215.856","1041"],["216.016","0"],["216.017","0"],["216.031","97"],["216.075","0"],["216.085","54"]],"a":[["216.180","16"],["216.342","466"],["216.343","0"],["216.344","0"],["216.638","0"],["216.959","835"]]}}
1618677485.256701: {"stream":"btcusd_210924@depth@100ms","data":{"e":"depthUpdate","E":1618677481717,"T":1618677481705,"s":"BTCUSD_210924","ps":"BTCUSD","U":86143363685,"u":86143364143,"pu":86143363151,"b":[],"a":[["68616.1","90"],["68661.0","171"],["68661.1","790"],["68661.2","0"],["68661.3","0"],["68666.8","459"],["69233.8","4"]]}}
1618677485.2567098: {"stream":"ethusd_210924@depth@100ms","data":{"e":"depthUpdate","E":1618677481717,"T":1618677481705,"s":"ETHUSD_210924","ps":"ETHUSD","U":86143363686,"u":86143364142,"pu":86143363675,"b":[["2685.02","3753"],["2685.03","1033"],["2685.46","0"],["2687.38","0"],["2687.46","66"],["2687.50","0"],["2687.51","660"],["2687.52","0"]],"a":[["2687.84","50"],["2693.05","0"]]}}
1618677485.2567198: {"stream":"bchusd_210625@depth@100ms","data":{"e":"depthUpdate","E":1618677481723,"T":1618677481715,"s":"BCHUSD_210625","ps":"BCHUSD","U":86143363726,"u":86143364214,"pu":86143363674,"b":[["1119.87","190"],["1124.06","0"],["1124.61","50"],["1126.67","0"],["1126.68","0"],["1127.36","35"]],"a":[]}}
1618677485.256775: {"stream":"ethusd_210625@depth@100ms","data":{"e":"depthUpdate","E":1618677481738,"T":1618677481714,"s":"ETHUSD_210625","ps":"ETHUSD","U":86143363833,"u":86143364208,"pu":86143363728,"b":[["2505.50","2028"],["2506.07","23364"]],"a":[["2509.09","0"],["2509.11","7175"],["2509.24","0"]]}}
1618677485.256845: {"stream":"btcusd_perp@depth@100ms","data":{"e":"depthUpdate","E":1618677481764,"T":1618677481759,"s":"BTCUSD_PERP","ps":"BTCUSD","U":86143363920,"u":86143364501,"pu":86143363835,"b":[["60293.9","0"],["60324.2","0"],["60340.8","0"],["60348.6","1808"],["60361.3","0"],["60372.3","1808"],["60463.1","1"],["60560.0","987"],["60560.1","243"],["60560.2","0"],["60560.7","0"],["60561.0","0"],["60570.8","0"],["60572.4","0"],["60572.9","243"],["60573.6","0"],["60574.5","634"],["60574.8","243"],["60575.4","2559"],["60578.2","101"],["60579.5","40"],["60581.0","6009"],["60581.1","0"],["60581.2","0"]],"a":[["60581.1","7978"],["60585.6","250"],["60598.5","122"],["60599.4","0"],["60600.1","0"],["60611.2","243"],["60611.9","0"],["60612.1","0"],["60612.9","0"],["60624.1","243"],["60624.7","0"],["60625.0","0"],["60625.7","0"],["60626.0","245"],["60626.6","1405"],["60626.9","0"],["60627.7","0"],["60805.2","0"],["60830.4","7267"]]}}
1618677485.256902: {"stream":"linkusd_210625@depth@100ms","data":{"e":"depthUpdate","E":1618677481774,"T":1618677481743,"s":"LINKUSD_210625","ps":"LINKUSD","U":86143363974,"u":86143364388,"pu":86143363907,"b":[["43.625","0"],["43.697","0"],["43.718","100"],["43.720","100"],["43.726","0"],["43.727","0"],["43.728","0"],["43.729","0"]],"a":[["43.750","50"],["43.754","100"],["43.756","100"],["43.757","0"],["43.758","101"],["43.764","0"],["43.766","102"],["43.768","0"]]}}
1618677485.256958: {"stream":"dotusd_210625@depth@100ms","data":{"e":"depthUpdate","E":1618677481782,"T":1618677481774,"s":"DOTUSD_210625","ps":"DOTUSD","U":86143363987,"u":86143364577,"pu":86143363467,"b":[["46.517","0"],["46.542","1386"],["46.721","250"],["46.733","30"]],"a":[["46.757","170"]]}}
1618677485.256968: {"stream":"xrpusd_210625@depth@100ms","data":{"e":"depthUpdate","E":1618677481784,"T":1618677481771,"s":"XRPUSD_210625","ps":"XRPUSD","U":86143364011,"u":86143364556,"pu":86143363898,"b":[["1.6818","1737"],["1.6822","80"]],"a":[["1.6914","45"],["1.6919","0"],["1.6959","330"],["1.6964","3650"]]}}
1618677485.2569878: {"stream":"egldusd_perp@depth@100ms","data":{"e":"depthUpdate","E":1618677481790,"T":1618677481722,"s":"EGLDUSD_PERP","ps":"EGLDUSD","U":86143364055,"u":86143364249,"pu":86143363828,"b":[["215.349","0"],["215.854","0"],["216.061","583"],["216.085","0"],["216.115","54"],["216.125","170"]],"a":[]}}
1618677485.2570481: {"stream":"bchusd_210625@depth@100ms","data":{"e":"depthUpdate","E":1618677481826,"T":1618677481792,"s":"BCHUSD_210625","ps":"BCHUSD","U":86143364251,"u":86143364684,"pu":86143364214,"b":[["1119.87","0"],["1119.94","190"]],"a":[]}}
1618677485.2570739: {"stream":"ethusd_210924@depth@100ms","data":{"e":"depthUpdate","E":1618677481826,"T":1618677481804,"s":"ETHUSD_210924","ps":"ETHUSD","U":86143364252,"u":86143364764,"pu":86143364142,"b":[["2683.31","150"],["2685.02","0"],["2685.03","0"],["2685.45","3753"],["2685.46","819"],["2687.46","0"],["2687.52","140"]],"a":[["2687.84","170"],["2688.70","150"]]}}
1618677485.2570848: {"stream":"linkusd_210924@depth@100ms","data":{"e":"depthUpdate","E":1618677481826,"T":1618677481765,"s":"LINKUSD_210924","ps":"LINKUSD","U":86143364254,"u":86143364518,"pu":86143363398,"b":[["45.208","0"],["45.209","0"]],"a":[["45.330","250"],["45.345","250"],["45.404","0"],["45.440","2968"]]}}
1618677485.257094: {"stream":"btcusd_210924@depth@100ms","data":{"e":"depthUpdate","E":1618677481828,"T":1618677481801,"s":"BTCUSD_210924","ps":"BTCUSD","U":86143364263,"u":86143364748,"pu":86143364143,"b":[],"a":[["68616.1","90"],["68624.0","2"],["68625.1","0"],["68666.7","1581"],["68666.8","0"],["68667.0","0"],["69233.8","0"]]}}
1618677485.257138: {"stream":"ethusd_210625@depth@100ms","data":{"e":"depthUpdate","E":1618677481853,"T":1618677481822,"s":"ETHUSD_210625","ps":"ETHUSD","U":86143364435,"u":86143364841,"pu":86143364208,"b":[["2505.50","2028"],["2509.10","2212"]],"a":[["2509.09","0"],["2509.11","4163"],["2509.24","121"],["2536.08","6000"]]}}
1618677485.25717: {"stream":"btcusd_perp@depth@100ms","data":{"e":"depthUpdate","E":1618677481873,"T":1618677481865,"s":"BTCUSD_PERP","ps":"BTCUSD","U":86143364550,"u":86143365012,"pu":86143364501,"b":[["59813.5","0"],["60339.7","0"],["60347.2","3525"],["60350.3","0"],["60356.9","0"],["60359.3","3583"],["60359.4","0"],["60362.0","18"],["60366.6","1791"],["60368.4","3616"],["60378.1","3618"],["60560.0","865"],["60560.1","365"],["60568.6","250"],["60573.2","26"],["60574.5","664"],["60576.9","32"],["60581.0","6169"],["60581.2","0"]],"a":[["60585.6","100"],["60598.5","0"],["60598.7","1608"],["60793.7","3609"],["60795.5","5414"],["60800.8","1821"]]}}
1618677485.2572548: {"stream":"linkusd_210625@depth@100ms","data":{"e":"depthUpdate","E":1618677481888,"T":1618677481882,"s":"LINKUSD_210625","ps":"LINKUSD","U":86143364621,"u":86143365099,"pu":86143364388,"b":[["43.724","88"]],"a":[["43.793","2657"],["43.794","2538"],["43.804","0"]]}}
1618677485.25729: {"stream":"egldusd_perp@depth@100ms","data":{"e":"depthUpdate","E":1618677481902,"T":1618677481841,"s":"EGLDUSD_PERP","ps":"EGLDUSD","U":86143364734,"u":86143364911,"pu":86143364249,"b":[],"a":[["216.308","0"],["216.340","466"],["216.341","29"],["216.342","0"]]}}
1618677485.25734: {"stream":"dotusd_210625@depth@100ms","data":{"e":"depthUpdate","E":1618677481903,"T":1618677481846,"s":"DOTUSD_210625","ps":"DOTUSD","U":86143364736,"u":86143364936,"pu":86143364577,"b":[["46.542","0"],["46.549","1430"],["46.720","0"],["46.733","14"],["46.734","30"]],"a":[["46.789","1089"]]}}
1618677485.257388: {"stream":"xrpusd_210625@depth@100ms","data":{"e":"depthUpdate","E":1618677481926,"T":1618677481867,"s":"XRPUSD_210625","ps":"XRPUSD","U":86143364836,"u":86143365015,"pu":86143364556,"b":[],"a":[["1.6914","45"],["1.6919","0"]]}}
1618677485.257397: {"stream":"ethusd_210924@depth@100ms","data":{"e":"depthUpdate","E":1618677481929,"T":1618677481917,"s":"ETHUSD_210924","ps":"ETHUSD","U":86143364852,"u":86143365302,"pu":86143364764,"b":[["2687.38","0"],["2687.46","66"],["2687.51","0"],["2687.52","0"],["2687.53","660"]],"a":[["2687.84","50"],["2693.05","1001"]]}}
1618677485.257406: {"stream":"btcusd_210924@depth@100ms","data":{"e":"depthUpdate","E":1618677481936,"T":1618677481921,"s":"BTCUSD_210924","ps":"BTCUSD","U":86143364888,"u":86143365327,"pu":86143364748,"b":[["68128.8","18"],["68611.6","169"],["68611.7","72"]],"a":[["68616.1","90"],["68624.0","0"],["68632.0","20"]]}}
1618677485.257438: {"stream":"btcusd_perp@depth@100ms","data":{"e":"depthUpdate","E":1618677481974,"T":1618677481966,"s":"BTCUSD_PERP","ps":"BTCUSD","U":86143365032,"u":86143365529,"pu":86143365012,"b":[["60324.2","1807"],["60344.4","0"],["60352.9","1808"],["60359.5","0"],["60361.7","1808"],["60368.4","1808"],["60373.9","1809"],["60559.9","122"],["60560.1","243"],["60572.3","1"],["60572.8","40"],["60574.5","634"],["60576.4","35"],["60578.2","100"],["60579.5","0"],["60581.2","0"]],"a":[["60581.7","40"],["60583.7","151"],["60585.6","100"],["60586.9","15"],["60597.7","363"],["60597.8","483"],["60598.3","0"],["60598.7","1486"],["60600.0","50"],["60610.5","263"],["60611.2","0"],["60623.4","243"],["60624.1","0"],["60625.3","243"],["60626.0","2"],["60651.9","0"],["60700.0","475"],["60720.0","44"],["60817.7","0"],["60833.5","0"],["61222.0","2"]]}}
1618677485.25758: {"stream":"linkusd_210924@depth@100ms","data":{"e":"depthUpdate","E":1618677481981,"T":1618677481894,"s":"LINKUSD_210924","ps":"LINKUSD","U":86143365076,"u":86143365168,"pu":86143364518,"b":[["45.199","1149"]],"a":[["45.330","0"],["45.345","0"]]}}
1618677485.257652: {"stream":"bchusd_210625@depth@100ms","data":{"e":"depthUpdate","E":1618677481988,"T":1618677481921,"s":"BCHUSD_210625","ps":"BCHUSD","U":86143365110,"u":86143365328,"pu":86143364684,"b":[],"a":[["1137.37","1840"],["1137.62","0"],["1139.34","190"]]}}
1618677485.2576818: {"stream":"linkusd_210625@depth@100ms","data":{"e":"depthUpdate","E":1618677481995,"T":1618677481989,"s":"LINKUSD_210625","ps":"LINKUSD","U":86143365141,"u":86143365630,"pu":86143365099,"b":[["43.502","0"],["43.519","100"],["43.578","247"],["43.698","2639"],["43.715","100"],["43.724","0"]],"a":[["43.750","0"],["43.757","50"],["43.788","448"],["43.789","2125"],["43.790","0"],["43.791","87"],["43.793","532"]]}}
1618677485.257785: {"stream":"egldusd_perp@depth@100ms","data":{"e":"depthUpdate","E":1618677482017,"T":1618677482013,"s":"EGLDUSD_PERP","ps":"EGLDUSD","U":86143365282,"u":86143365756,"pu":86143364911,"b":[["216.031","0"],["216.075","97"],["216.105","0"],["216.115","0"],["216.135","54"]],"a":[["216.338","473"],["216.339","29"],["216.340","0"],["216.341","0"]]}}
1618677485.257904: {"stream":"ethusd_210924@depth@100ms","data":{"e":"depthUpdate","E":1618677482033,"T":1618677482022,"s":"ETHUSD_210924","ps":"ETHUSD","U":86143365364,"u":86143365801,"pu":86143365302,"b":[["2667.41","404"],["2674.82","2179"],["2687.54","140"],["2687.83","231"]],"a":[["2687.84","50"],["2695.24","0"],["2695.57","7227"]]}}
1618677485.257974: {"stream":"btcusd_210924@depth@100ms","data":{"e":"depthUpdate","E":1618677482049,"T":1618677481959,"s":"BTCUSD_210924","ps":"BTCUSD","U":86143365436,"u":86143365510,"pu":86143365327,"b":[["68572.7","544"],["68585.7","0"]],"a":[["68616.1","155"]]}}
1618677485.257995: {"stream":"ethusd_210625@depth@100ms","data":{"e":"depthUpdate","E":1618677482060,"T":1618677482045,"s":"ETHUSD_210625","ps":"ETHUSD","U":86143365467,"u":86143365959,"pu":86143364841,"b":[["2509.10","1312"]],"a":[["2509.09","0"],["2509.24","0"],["2509.68","837"]]}}
1618677485.258004: {"stream":"xrpusd_210625@depth@100ms","data":{"e":"depthUpdate","E":1618677482063,"T":1618677482043,"s":"XRPUSD_210625","ps":"XRPUSD","U":86143365513,"u":86143365949,"pu":86143365015,"b":[["1.6822","0"]],"a":[["1.6959","2310"],["1.6964","1670"]]}}
1618677485.258035: {"stream":"dotusd_210625@depth@100ms","data":{"e":"depthUpdate","E":1618677482069,"T":1618677482060,"s":"DOTUSD_210625","ps":"DOTUSD","U":86143365530,"u":86143366049,"pu":86143364936,"b":[["46.396","0"],["46.734","120"],["46.735","0"],["46.736","540"],["46.737","30"]],"a":[["46.753","170"],["46.754","0"],["46.755","0"],["46.757","0"],["46.763","120"]]}}
1618677485.2581792: {"stream":"btcusd_perp@depth@100ms","data":{"e":"depthUpdate","E":1618677482078,"T":1618677482073,"s":"BTCUSD_PERP","ps":"BTCUSD","U":86143365571,"u":86143366172,"pu":86143365529,"b":[["60293.9","1806"],["60315.9","0"],["60331.7","5396"],["60339.7","1807"],["60347.2","5331"],["60350.3","1807"],["60352.4","0"],["60355.3","0"],["60356.9","1808"],["60359.3","1808"],["60362.0","1826"],["60364.8","0"],["60369.8","3618"],["60559.9","0"],["60560.0","987"],["60568.6","200"],["60571.8","0"],["60579.8","0"],["60581.0","3955"],["60581.2","0"]],"a":[["60580.2","0"],["60580.9","0"],["60582.3","20"],["60583.7","151"],["60595.6","0"],["60595.7","122"],["60596.9","0"],["60597.7","241"],["60600.0","170"],["60608.3","243"],["60609.7","0"],["60610.5","20"],["60621.2","243"],["60622.5","0"],["60623.1","243"],["60623.4","0"],["60624.5","0"],["60625.3","0"],["60683.7","1649"],["60684.4","0"],["60698.3","0"],["60700.0","977"],["60720.0","594"],["60797.3","0"],["60805.2","1820"]]}}
1618677485.258434: {"stream":"bchusd_210625@depth@100ms","data":{"e":"depthUpdate","E":1618677482102,"T":1618677482045,"s":"BCHUSD_210625","ps":"BCHUSD","U":86143365670,"u":86143365962,"pu":86143365328,"b":[["1115.89","0"],["1116.44","400"]],"a":[["1131.60","100"],["1131.75","0"],["1131.92","0"],["1139.23","190"],["1139.34","0"]]}}
1618677485.2584808: {"stream":"linkusd_210625@depth@100ms","data":{"e":"depthUpdate","E":1618677482109,"T":1618677482062,"s":"LINKUSD_210625","ps":"LINKUSD","U":86143365701,"u":86143366066,"pu":86143365630,"b":[["43.661","44"],["43.719","22"],["43.721","21"],["43.723","0"]],"a":[["43.750","50"],["43.757","0"],["43.842","282"]]}}
1618677485.258493: {"stream":"egldusd_perp@depth@100ms","data":{"e":"depthUpdate","E":1618677482119,"T":1618677482100,"s":"EGLDUSD_PERP","ps":"EGLDUSD","U":86143365778,"u":86143366364,"pu":86143365756,"b":[["210.691","0"],["212.642","0"],["213.617","0"],["214.592","0"],["214.787","0"],["215.857","99"],["215.862","0"],["216.012","0"],["216.062","71"],["216.071","0"],["216.085","54"],["216.135","0"]],"a":[["216.180","16"],["216.221","0"],["216.336","107"],["216.337","38"],["216.339","0"],["216.392","0"],["216.639","0"],["216.819","225"],["217.625","0"],["218.687","0"],["220.811","0"]]}}
1618677485.258603: {"stream":"linkusd_210924@depth@100ms","data":{"e":"depthUpdate","E":1618677482129,"T":1618677482081,"s":"LINKUSD_210924","ps":"LINKUSD","U":86143365814,"u":86143366244,"pu":86143365168,"b":[["44.921","180"]],"a":[["45.405","3810"],["45.440","0"],["45.505","182"]]}}
1618677485.2586281: {"stream":"ethusd_210924@depth@100ms","data":{"e":"depthUpdate","E":1618677482144,"T":1618677482066,"s":"ETHUSD_210924","ps":"ETHUSD","U":86143365912,"u":86143366100,"pu":86143365801,"b":[["2671.63","500"],["2672.93","500"]],"a":[["2687.84","170"],["2693.26","500"]]}}
1618677485.2586749: {"stream":"ethusd_210625@depth@100ms","data":{"e":"depthUpdate","E":1618677482168,"T":1618677482151,"s":"ETHUSD_210625","ps":"ETHUSD","U":86143366077,"u":86143366636,"pu":86143365959,"b":[["2497.45","500"],["2497.84","0"],["2503.49","0"],["2509.10","1187"]],"a":[["2509.09","0"],["2509.24","121"],["2509.38","0"],["2509.68","716"]]}}
1618677485.258698: {"stream":"dotusd_210625@depth@100ms","data":{"e":"depthUpdate","E":1618677482171,"T":1618677482124,"s":"DOTUSD_210625","ps":"DOTUSD","U":86143366101,"u":86143366476,"pu":86143366049,"b":[["46.549","0"],["46.563","1932"],["46.722","104"],["46.733","0"]],"a":[["46.752","0"],["46.753","0"],["46.757","170"],["47.058","1"],["47.066","601"]]}}
1618677485.258708: {"stream":"btcusd_210924@depth@100ms","data":{"e":"depthUpdate","E":1618677482171,"T":1618677482143,"s":"BTCUSD_210924","ps":"BTCUSD","U":86143366106,"u":86143366599,"pu":86143365510,"b":[["68560.8","718"],["68572.7","0"],["68585.6","0"],["68585.8","0"],["68587.8","276"],["68590.7","0"],["68592.0","0"],["68592.1","0"],["68605.3","0"],["68609.2","90"],["68611.3","0"],["68616.0","134"]],"a":[["68616.1","242"],["68643.4","277"]]}}
1618677485.258742: {"stream":"btcusd_perp@depth@100ms","data":{"e":"depthUpdate","E":1618677482180,"T":1618677482174,"s":"BTCUSD_PERP","ps":"BTCUSD","U":86143366186,"u":86143366732,"pu":86143366172,"b":[["60334.7","1807"],["60340.8","1807"],["60348.6","0"],["60350.8","0"],["60359.4","1808"],["60359.5","1808"],["60361.4","1808"],["60361.8","1808"],["60366.6","1808"],["60368.4","3616"],["60369.8","1809"],["60384.1","0"],["60386.5","1200"],["60554.5","243"],["60554.7","122"],["60554.9","0"],["60555.1","0"],["60555.2","0"],["60560.0","865"],["60560.1","0"],["60560.8","463"],["60567.1","41"],["60567.4","243"],["60567.5","292"],["60567.9","0"],["60568.5","0"],["60569.3","243"],["60569.5","50"],["60569.8","0"],["60570.7","0"],["60571.7","30"],["60572.0","96"],["60572.8","0"],["60572.9","0"],["60573.0","126"],["60574.0","96"],["60574.8","0"],["60576.4","5"],["60578.0","0"],["60578.5","940"],["60579.0","0"],["60579.9","0"],["60580.0","121"],["60580.1","0"],["60581.0","3805"]],"a":[["60580.9","0"],["60581.1","8098"],["60585.9","45"],["60592.5","127"],["60593.4","0"],["60595.0","0"],["60595.7","0"],["60605.3","243"],["60606.2","0"],["60607.8","50"],["60608.3","0"],["60618.1","243"],["60619.0","555"],["60620.0","293"],["60620.6","0"],["60620.9","0"],["60621.2","0"],["60622.6","0"],["60623.1","0"],["60656.4","1"],["60683.0","1652"],["60683.7","0"],["60698.3","1100"],["60800.3","1821"]]}}
1618677485.2590668: {"stream":"linkusd_210625@depth@100ms","data":{"e":"depthUpdate","E":1618677482211,"T":1618677482207,"s":"LINKUSD_210625","ps":"LINKUSD","U":86143366413,"u":86143366925,"pu":86143366066,"b":[["43.504","50"],["43.519","0"],["43.700","50"],["43.715","0"],["43.726","0"]],"a":[["43.750","0"],["43.758","151"],["43.784","131"],["43.785","619"],["43.793","0"],["43.994","0"]]}}
1618677485.2591581: {"stream":"xrpusd_210625@depth@100ms","data":{"e":"depthUpdate","E":1618677482232,"T":1618677482223,"s":"XRPUSD_210625","ps":"XRPUSD","U":86143366497,"u":86143367039,"pu":86143365949,"b":[["1.6818","109"],["1.6888","0"],["1.6891","0"],["1.6893","45"]],"a":[["1.6909","100"],["1.6910","0"],["1.6912","193"]]}}
1618677485.259167: {"stream":"egldusd_perp@depth@100ms","data":{"e":"depthUpdate","E":1618677482232,"T":1618677482226,"s":"EGLDUSD_PERP","ps":"EGLDUSD","U":86143366492,"u":86143367072,"pu":86143366364,"b":[["214.166","0"],["214.598","0"],["214.612","1273"],["215.518","799"],["215.623","0"],["215.954","0"],["216.012","54"],["216.061","0"],["216.062","0"],["216.085","0"],["216.125","0"]],"a":[["216.337","0"],["216.399","95"]]}}
1618677485.2592819: {"stream":"linkusd_210924@depth@100ms","data":{"e":"depthUpdate","E":1618677482241,"T":1618677482137,"s":"LINKUSD_210924","ps":"LINKUSD","U":86143366559,"u":86143366559,"pu":86143366244,"b":[["45.200","131"]],"a":[]}}
1618677485.259291: {"stream":"bchusd_210625@depth@100ms","data":{"e":"depthUpdate","E":1618677482246,"T":1618677482161,"s":"BCHUSD_210625","ps":"BCHUSD","U":86143366603,"u":86143366660,"pu":86143365962,"b":[["1126.67","35"],["1126.68","11"],["1127.36","0"]],"a":[]}}
1618677485.2594812: {"stream":"btcusd_perp@depth@100ms","data":{"e":"depthUpdate","E":1618677482283,"T":1618677482273,"s":"BTCUSD_PERP","ps":"BTCUSD","U":86143366749,"u":86143367491,"pu":86143366732,"b":[["60331.7","3589"],["60337.7","1782"],["60343.2","0"],["60352.4","1808"],["60481.1","6184"],["60481.7","10"],["60553.4","243"],["60553.6","2198"],["60554.5","0"],["60554.7","0"],["60555.1","0"],["60555.2","0"],["60560.8","363"],["60565.2","15"],["60566.3","357"],["60566.9","50"],["60567.1","1"],["60567.4","0"],["60567.9","0"],["60568.2","243"],["60569.3","0"],["60569.5","50"],["60569.8","0"],["60570.3","0"],["60571.0","754"],["60571.3","30"],["60571.7","0"],["60572.4","70"],["60573.2","1"],["60573.4","25"],["60573.5","100"],["60573.9","0"],["60575.5","10"],["60578.5","940"],["60581.0","3925"]],"a":[["60580.9","0"],["60581.1","8078"],["60581.7","40"],["60583.7","1"],["60587.2","27"],["60589.5","0"],["60592.2","122"],["60592.3","10"],["60592.4","0"],["60592.5","5"],["60623.6","1405"],["60626.6","0"],["60662.2","6184"],["60662.7","0"],["60679.0","100"],["60781.6","0"],["60788.2","1821"],["60792.5","0"],["60802.6","1821"],["60837.9","0"]]}}
1618677485.259695: {"stream":"btcusd_210924@depth@100ms","data":{"e":"depthUpdate","E":1618677482287,"T":1618677482273,"s":"BTCUSD_210924","ps":"BTCUSD","U":86143366768,"u":86143367482,"pu":86143366599,"b":[["68592.0","202"],["68592.2","0"],["68606.7","90"],["68609.2","0"],["68609.3","0"],["68612.5","0"],["68616.0","264"]],"a":[["68624.0","20"],["68632.0","0"],["68658.9","139"]]}}
1618677485.259765: {"stream":"dotusd_210625@depth@100ms","data":{"e":"depthUpdate","E":1618677482297,"T":1618677482270,"s":"DOTUSD_210625","ps":"DOTUSD","U":86143366829,"u":86143367453,"pu":86143366476,"b":[["46.723","30"],["46.733","0"],["46.737","0"]],"a":[["46.754","170"],["46.755","256"],["46.757","0"],["46.959","0"]]}}
1618677485.2598531: {"stream":"ethusd_210924@depth@100ms","data":{"e":"depthUpdate","E":1618677482311,"T":1618677482305,"s":"ETHUSD_210924","ps":"ETHUSD","U":86143366932,"u":86143367701,"pu":86143366100,"b":[["2685.45","0"],["2685.46","0"],["2685.47","3886"],["2685.48","847"],["2686.13","0"],["2686.79","660"],["2687.38","0"],["2687.53","0"],["2687.54","0"],["2687.83","231"]],"a":[["2687.84","0"]]}}
1618677485.259952: {"stream":"linkusd_210625@depth@100ms","data":{"e":"depthUpdate","E":1618677482326,"T":1618677482282,"s":"LINKUSD_210625","ps":"LINKUSD","U":86143367038,"u":86143367545,"pu":86143366925,"b":[["43.726","8"]],"a":[["43.986","20"]]}}
1618677485.260007: {"stream":"egldusd_perp@depth@100ms","data":{"e":"depthUpdate","E":1618677482338,"T":1618677482312,"s":"EGLDUSD_PERP","ps":"EGLDUSD","U":86143367126,"u":86143367755,"pu":86143367072,"b":[["214.958","0"],["215.044","1277"],["215.103","44"],["215.299","0"],["215.420","59"],["215.432","0"],["215.518","0"],["215.855","0"],["215.857","176"],["215.858","0"],["215.867","0"],["215.954","54"],["215.955","0"],["215.958","97"],["215.959","20"],["216.002","0"],["216.005","0"],["216.012","0"],["216.013","0"],["216.018","0"],["216.022","0"],["216.023","0"],["216.026","0"],["216.027","0"],["216.031","0"],["216.037","170"],["216.075","0"]],"a":[["216.058","170"],["216.065","0"],["216.159","16"],["216.169","0"],["216.174","97"],["216.179","83"],["216.180","0"],["216.182","0"],["216.231","0"],["216.245","0"],["216.308","52"],["216.399","0"],["216.414","409"]]}}
1618677485.260216: {"stream":"xrpusd_210625@depth@100ms","data":{"e":"depthUpdate","E":1618677482343,"T":1618677482320,"s":"XRPUSD_210625","ps":"XRPUSD","U":86143367165,"u":86143367848,"pu":86143367039,"b":[["1.6750","4233"]],"a":[["1.6912","48"],["1.6914","45"],["1.6919","0"]]}}
1618677485.2602491: {"stream":"ethusd_210625@depth@100ms","data":{"e":"depthUpdate","E":1618677482352,"T":1618677482345,"s":"ETHUSD_210625","ps":"ETHUSD","U":86143367238,"u":86143368042,"pu":86143366636,"b":[["2497.84","2000"],["2503.49","1000"],["2507.81","0"],["2508.12","0"],["2508.27","0"],["2508.67","299"],["2508.81","0"],["2509.10","1312"]],"a":[["2509.09","0"],["2509.11","4163"],["2509.23","121"],["2509.24","0"]]}}
1618677485.26027: {"stream":"bchusd_210625@depth@100ms","data":{"e":"depthUpdate","E":1618677482358,"T":1618677482353,"s":"BCHUSD_210625","ps":"BCHUSD","U":86143367305,"u":86143368111,"pu":86143366660,"b":[["1119.94","0"],["1119.95","190"],["1126.67","0"],["1126.68","0"],["1126.69","0"],["1126.70","0"],["1127.36","35"],["1127.37","0"],["1127.38","64"],["1127.39","0"]],"a":[["1131.48","100"],["1131.60","0"]]}}
1618677485.260459: {"stream":"btcusd_210924@depth@100ms","data":{"e":"depthUpdate","E":1618677482395,"T":1618677482372,"s":"BTCUSD_210924","ps":"BTCUSD","U":86143367579,"u":86143368266,"pu":86143367482,"b":[["68558.7","1436"],["68576.6","303"],["68587.8","0"],["68606.7","0"],["68609.3","0"],["68614.1","0"],["68616.0","354"]],"a":[["68616.1","155"],["68643.4","0"]]}}
1618677485.26047: {"stream":"btcusd_perp@depth@100ms","data":{"e":"depthUpdate","E":1618677482395,"T":1618677482390,"s":"BTCUSD_PERP","ps":"BTCUSD","U":86143367590,"u":86143368394,"pu":86143367491,"b":[["59600.0","20358"],["59631.8","0"],["60328.2","0"],["60331.7","5396"],["60343.8","0"],["60348.6","1807"],["60351.0","11"],["60359.3","3583"],["60361.4","3616"],["60367.2","1808"],["60553.4","0"],["60553.6","2076"],["60558.8","369"],["60559.1","0"],["60559.3","0"],["60559.6","0"],["60559.7","0"],["60560.0","363"],["60561.1","243"],["60561.3","1621"],["60563.9","0"],["60566.3","114"],["60568.2","0"],["60570.8","100"],["60571.9","0"],["60572.0","0"],["60572.4","0"],["60573.0","30"],["60573.9","243"],["60574.0","0"],["60574.4","0"],["60574.5","534"],["60575.9","243"],["60576.2","48"],["60577.0","96"],["60577.8","40"],["60578.0","96"],["60578.4","30"],["60578.5","0"],["60579.0","1036"],["60580.0","1"],["60581.0","6088"],["60581.2","0"]],"a":[["60581.1","8008"],["60581.7","0"],["60582.3","39"],["60583.7","151"],["60585.7","45"],["60585.9","0"],["60586.9","55"],["60592.2","0"],["60592.4","0"],["60597.1","0"],["60598.4","322"],["60600.0","50"],["60605.3","0"],["60609.9","0"],["60611.2","243"],["60618.1","0"],["60620.0","50"],["60622.7","0"],["60624.0","273"],["60624.7","0"],["60625.9","243"],["60669.7","0"],["60679.1","602"],["60779.8","0"],["60789.5","0"],["60794.9","1821"],["60802.8","3628"],["60811.8","0"]]}}
1618677485.2607229: {"stream":"ethusd_210924@depth@100ms","data":{"e":"depthUpdate","E":1618677482417,"T":1618677482379,"s":"ETHUSD_210924","ps":"ETHUSD","U":86143367768,"u":86143368315,"pu":86143367701,"b":[["2553.39","1000"],["2553.59","0"],["2687.83","231"],["2687.84","0"]],"a":[["2687.84","2820"],["2688.22","2712"],["2688.23","0"],["2688.29","2760"],["2695.24","7253"],["2695.57","0"]]}}
1618677485.260789: {"stream":"linkusd_210924@depth@100ms","data":{"e":"depthUpdate","E":1618677482420,"T":1618677482319,"s":"LINKUSD_210924","ps":"LINKUSD","U":86143367794,"u":86143367841,"pu":86143366559,"b":[],"a":[["45.391","4778"],["45.406","0"]]}}
1618677485.260823: {"stream":"linkusd_210625@depth@100ms","data":{"e":"depthUpdate","E":1618677482432,"T":1618677482426,"s":"LINKUSD_210625","ps":"LINKUSD","U":86143367906,"u":86143368639,"pu":86143367545,"b":[["43.504","0"],["43.515","100"],["43.700","0"],["43.711","100"]],"a":[["43.750","63"],["43.758","101"],["43.759","32"],["43.787","284"],["43.788","448"],["43.789","0"],["43.791","0"],["43.804","1794"]]}}
1618677485.260879: {"stream":"egldusd_perp@depth@100ms","data":{"e":"depthUpdate","E":1618677482444,"T":1618677482428,"s":"EGLDUSD_PERP","ps":"EGLDUSD","U":86143368003,"u":86143368667,"pu":86143367755,"b":[["215.427","802"],["215.720","23"],["215.867","54"],["215.944","0"],["215.954","0"]],"a":[["216.048","0"],["216.148","97"],["216.149","0"],["216.159","0"],["216.173","21"],["216.174","0"],["216.372","16"],["216.588","301"],["216.950","0"]]}}
1618677485.2610078: {"stream":"ethusd_210625@depth@100ms","data":{"e":"depthUpdate","E":1618677482467,"T":1618677482446,"s":"ETHUSD_210625","ps":"ETHUSD","U":86143368186,"u":86143368829,"pu":86143368042,"b":[["2383.59","2000"],["2508.65","0"],["2508.66","0"],["2508.67","0"],["2508.71","34"],["2508.81","299"]],"a":[["2509.09","0"],["2509.11","8248"],["2509.22","0"],["2509.23","0"],["2509.30","100"],["2509.38","0"],["2511.25","11063"],["2511.26","0"],["2511.41","1981"]]}}
1618677485.26102: {"stream":"bchusd_210625@depth@100ms","data":{"e":"depthUpdate","E":1618677482470,"T":1618677482456,"s":"BCHUSD_210625","ps":"BCHUSD","U":86143368203,"u":86143368908,"pu":86143368111,"b":[["1115.90","50"],["1116.44","0"],["1124.06","141"],["1124.61","0"],["1126.67","35"],["1127.36","0"]],"a":[["1131.48","0"],["1131.60","100"],["1139.23","0"],["1139.24","190"]]}}
1618677485.261081: {"stream":"xrpusd_210625@depth@100ms","data":{"e":"depthUpdate","E":1618677482491,"T":1618677482481,"s":"XRPUSD_210625","ps":"XRPUSD","U":86143368372,"u":86143369090,"pu":86143367848,"b":[["1.6824","576"],["1.6846","0"],["1.6887","349"],["1.6893","124"],["1.6894","0"],["1.6895","0"],["1.6896","10"]],"a":[["1.6914","0"],["1.6920","0"],["1.6928","45"],["1.6929","1309"],["1.6959","330"],["1.6965","293"]]}}
1618677485.261107: {"stream":"btcusd_perp@depth@100ms","data":{"e":"depthUpdate","E":1618677482498,"T":1618677482492,"s":"BTCUSD_PERP","ps":"BTCUSD","U":86143368404,"u":86143369165,"pu":86143368394,"b":[["60331.7","7203"],["60332.1","0"],["60334.7","3614"],["60350.9","1775"],["60366.6","3584"],["60369.8","3618"],["60480.0","1052"],["60561.3","1499"],["60561.5","122"],["60570.0","120"],["60574.6","33"],["60575.6","0"],["60579.0","96"],["60579.1","940"],["60580.4","198"],["60581.2","0"]],"a":[["60583.0","30"],["60583.7","151"],["60584.2","100"],["60585.7","15"],["60587.2","0"],["60589.5","41"],["60590.0","170"],["60597.0","99"],["60597.5","257"],["60597.6","413"],["60598.4","200"],["60609.8","0"],["60610.2","243"],["60611.2","0"],["60622.6","0"],["60623.1","243"],["60624.0","30"],["60624.6","0"],["60625.1","243"],["60625.9","0"],["60667.6","541"],["60679.1","0"],["60781.6","1814"],["60792.5","1815"],["60793.7","1821"]]}}
1618677485.261347: {"stream":"ethusd_210924@depth@100ms","data":{"e":"depthUpdate","E":1618677482529,"T":1618677482519,"s":"ETHUSD_210924","ps":"ETHUSD","U":86143368629,"u":86143369416,"pu":86143368315,"b":[["2686.13","1160"],["2686.76","0"],["2686.78","0"],["2686.79","0"],["2686.80","0"],["2687.38","0"],["2687.83","416"]],"a":[["2687.84","204"],["2688.22","0"],["2688.29","0"]]}}
1618677485.261482: {"stream":"linkusd_210625@depth@100ms","data":{"e":"depthUpdate","E":1618677482546,"T":1618677482531,"s":"LINKUSD_210625","ps":"LINKUSD","U":86143368795,"u":86143369558,"pu":86143368639,"b":[],"a":[["43.747","32"],["43.749","0"],["43.750","0"],["43.787","0"],["43.788","0"],["43.793","470"]]}}
1618677485.261503: {"stream":"egldusd_perp@depth@100ms","data":{"e":"depthUpdate","E":1618677482551,"T":1618677482544,"s":"EGLDUSD_PERP","ps":"EGLDUSD","U":86143368849,"u":86143369707,"pu":86143368667,"b":[["215.867","0"],["215.969","54"]],"a":[["216.148","0"],["216.165","97"],["216.173","0"]]}}
1618677485.261581: {"stream":"dotusd_210625@depth@100ms","data":{"e":"depthUpdate","E":1618677482567,"T":1618677482532,"s":"DOTUSD_210625","ps":"DOTUSD","U":86143368951,"u":86143369569,"pu":86143367453,"b":[["46.673","3"],["46.723","0"],["46.735","0"],["46.737","31"]],"a":[["46.755","0"],["46.941","0"],["46.948","40"],["46.993","1117"],["47.055","1502"],["47.222","1338"]]}}
1618677485.261591: {"stream":"bchusd_210625@depth@100ms","data":{"e":"depthUpdate","E":1618677482570,"T":1618677482548,"s":"BCHUSD_210625","ps":"BCHUSD","U":86143368976,"u":86143369752,"pu":86143368908,"b":[["1115.90","0"],["1116.45","50"],["1119.95","0"],["1119.96","362"],["1124.46","250"],["1124.82","250"]],"a":[]}}
1618677485.261657: {"stream":"ethusd_210625@depth@100ms","data":{"e":"depthUpdate","E":1618677482579,"T":1618677482575,"s":"ETHUSD_210625","ps":"ETHUSD","U":86143369064,"u":86143370006,"pu":86143368829,"b":[["2501.46","0"],["2501.49","0"],["2501.90","0"],["2502.17","34977"],["2502.23","1000"],["2503.67","0"],["2503.83","500"],["2505.36","1517"],["2505.50","0"],["2505.63","2801"],["2505.74","2028"],["2506.67","0"],["2506.80","1072"],["2506.83","20"],["2506.86","1070"],["2506.87","1073"],["2506.94","0"],["2507.00","1935"],["2507.02","1526"],["2507.43","0"],["2508.02","0"],["2508.12","299"],["2508.27","394"],["2508.28","262"],["2508.71","0"],["2508.81","0"]],"a":[["2509.09","0"],["2509.11","21497"],["2509.24","0"],["2509.26","0"],["2509.57","0"],["2509.58","0"],["2509.59","0"],["2509.61","0"],["2509.63","0"],["2509.65","838"],["2509.68","0"],["2509.69","0"],["2514.29","1944"]]}}
1618677485.2617862: {"stream":"linkusd_210924@depth@100ms","data":{"e":"depthUpdate","E":1618677482590,"T":1618677482505,"s":"LINKUSD_210924","ps":"LINKUSD","U":86143369128,"u":86143369291,"pu":86143367841,"b":[["45.199","0"],["45.200","0"],["45.206","1224"],["45.207","99"]],"a":[]}}
1618677485.261796: {"stream":"xrpusd_210625@depth@100ms","data":{"e":"depthUpdate","E":1618677482592,"T":1618677482580,"s":"XRPUSD_210625","ps":"XRPUSD","U":86143369136,"u":86143370036,"pu":86143369090,"b":[["1.6824","496"],["1.6861","0"],["1.6870","2164"],["1.6883","0"],["1.6887","397"],["1.6894","45"],["1.6895","9"],["1.6896","0"]],"a":[["1.6909","0"],["1.6911","0"],["1.6924","352"],["1.6928","0"],["1.6934","45"],["1.6976","0"],["1.6998","0"]]}}
1618677485.261819: {"stream":"btcusd_210924@depth@100ms","data":{"e":"depthUpdate","E":1618677482593,"T":1618677482503,"s":"BTCUSD_210924","ps":"BTCUSD","U":86143369145,"u":86143369264,"pu":86143368266,"b":[["68542.2","498"],["68585.5","0"]],"a":[["68722.8","0"]]}}
1618677485.2618392: {"stream":"btcusd_perp@depth@100ms","data":{"e":"depthUpdate","E":1618677482602,"T":1618677482595,"s":"BTCUSD_PERP","ps":"BTCUSD","U":86143369224,"u":86143370153,"pu":86143369165,"b":[["60318.9","0"],["60328.2","1807"],["60343.8","1782"],["60348.6","3615"],["60355.3","1808"],["60364.2","0"],["60370.8","60"],["60569.4","25"],["60571.2","30"],["60572.6","40"],["60574.6","1"],["60575.0","23"],["60576.4","35"],["60577.8","0"],["60578.4","0"],["60581.2","0"]],"a":[["60582.3","0"],["60583.7","1"],["60591.3","25"],["60593.1","0"],["60595.5","24"],["60597.1","40"],["60597.6","291"],["60598.4","200"],["60598.7","1608"],["60604.3","0"],["60610.2","0"],["60611.1","243"],["60623.1","0"],["60623.9","8"],["60624.3","245"],["60625.1","0"],["60625.9","243"],["60656.4","0"],["60667.6","0"],["60779.7","1821"],["60789.4","3642"],["60821.4","0"],["60833.9","0"],["60837.9","1823"]]}}
1618677485.2620091: {"stream":"ethusd_210924@depth@100ms","data":{"e":"depthUpdate","E":1618677482633,"T":1618677482627,"s":"ETHUSD_210924","ps":"ETHUSD","U":86143369540,"u":86143370421,"pu":86143369416,"b":[["2685.02","4014"],["2685.03","1088"],["2685.47","0"],["2685.48","0"],["2685.82","0"],["2686.12","0"],["2686.13","500"],["2686.14","346"],["2686.76","660"],["2686.77","180"]],"a":[]}}
1618677485.262068: {"stream":"linkusd_210625@depth@100ms","data":{"e":"depthUpdate","E":1618677482646,"T":1618677482558,"s":"LINKUSD_210625","ps":"LINKUSD","U":86143369682,"u":86143369854,"pu":86143369558,"b":[],"a":[["43.747","45"],["43.754","150"]]}}
1618677485.262092: {"stream":"egldusd_perp@depth@100ms","data":{"e":"depthUpdate","E":1618677482668,"T":1618677482659,"s":"EGLDUSD_PERP","ps":"EGLDUSD","U":86143369915,"u":86143370669,"pu":86143369707,"b":[["215.259","329"],["215.957","97"],["215.958","0"],["215.959","0"],["215.969","0"],["215.983","0"]],"a":[]}}
1618677485.262146: {"stream":"bchusd_210625@depth@100ms","data":{"e":"depthUpdate","E":1618677482672,"T":1618677482659,"s":"BCHUSD_210625","ps":"BCHUSD","U":86143369926,"u":86143370675,"pu":86143369752,"b":[["1119.96","362"],["1124.06","0"],["1124.62","50"],["1126.67","0"],["1127.39","35"]],"a":[]}}
1618677485.262184: {"stream":"dotusd_210625@depth@100ms","data":{"e":"depthUpdate","E":1618677482677,"T":1618677482665,"s":"DOTUSD_210625","ps":"DOTUSD","U":86143369996,"u":86143370733,"pu":86143369569,"b":[],"a":[["46.754","0"],["46.757","0"]]}}
1618677485.262194: {"stream":"ethusd_210625@depth@100ms","data":{"e":"depthUpdate","E":1618677482679,"T":1618677482673,"s":"ETHUSD_210625","ps":"ETHUSD","U":86143370009,"u":86143370782,"pu":86143370006,"b":[["2501.48","0"],["2501.96","100"],["2502.05","3977"],["2503.83","0"],["2503.96","500"],["2506.80","0"],["2506.86","0"],["2506.87","0"],["2507.42","0"],["2507.71","2985"],["2508.12","0"],["2508.27","0"],["2508.45","0"],["2508.61","545"],["2508.71","299"]],"a":[["2509.09","0"],["2509.11","19260"],["2509.25","0"],["2509.81","119"],["2513.12","2982"],["2513.16","500"]]}}
1618677485.262295: {"stream":"xrpusd_210625@depth@100ms","data":{"e":"depthUpdate","E":1618677482692,"T":1618677482684,"s":"XRPUSD_210625","ps":"XRPUSD","U":86143370102,"u":86143370838,"pu":86143370036,"b":[["1.6823","80"],["1.6877","1037"],["1.6880","97"]],"a":[["1.6920","0"],["1.6924","0"],["1.6928","255"],["1.6929","1212"],["1.6933","158"],["1.6934","0"],["1.6938","127"],["1.6950","1963"],["1.6970","401"]]}}
1618677485.262322: {"stream":"btcusd_perp@depth@100ms","data":{"e":"depthUpdate","E":1618677482710,"T":1618677482703,"s":"BTCUSD_PERP","ps":"BTCUSD","U":86143370233,"u":86143370963,"pu":86143370153,"b":[["60322.0","4"],["60351.1","1807"],["60434.8","0"],["60443.9","0"],["60565.5","1179"],["60575.0","0"],["60576.0","2"],["60581.2","0"]],"a":[["60584.2","250"],["60598.7","1608"],["60598.8","0"],["60611.1","0"],["60611.5","243"],["60622.5","1225"],["60622.9","0"],["60667.5","540"],["60679.1","0"],["60680.5","2550"],["60680.6","0"],["60811.8","1789"]]}}
1618677485.262463: {"stream":"btcusd_210924@depth@100ms","data":{"e":"depthUpdate","E":1618677482763,"T":1618677482661,"s":"BTCUSD_210924","ps":"BTCUSD","U":86143370662,"u":86143370686,"pu":86143369264,"b":[["68542.2","0"],["68584.4","498"]],"a":[]}}
1618677485.262472: {"stream":"linkusd_210924@depth@100ms","data":{"e":"depthUpdate","E":1618677482763,"T":1618677482662,"s":"LINKUSD_210924","ps":"LINKUSD","U":86143370663,"u":86143370693,"pu":86143369291,"b":[],"a":[["45.390","2151"],["45.395","0"]]}}
1618677485.2624798: {"stream":"ethusd_210924@depth@100ms","data":{"e":"depthUpdate","E":1618677482763,"T":1618677482759,"s":"ETHUSD_210924","ps":"ETHUSD","U":86143370665,"u":86143371313,"pu":86143370421,"b":[["2684.20","0"],["2684.92","8028"],["2684.94","2104"],["2686.13","0"],["2686.14","0"],["2686.76","0"],["2686.77","0"],["2686.78","500"],["2687.38","0"]],"a":[["2687.84","324"]]}}
1618677485.26255: {"stream":"dotusd_210625@depth@100ms","data":{"e":"depthUpdate","E":1618677482778,"T":1618677482727,"s":"DOTUSD_210625","ps":"DOTUSD","U":86143370793,"u":86143371126,"pu":86143370733,"b":[["46.722","0"],["46.733","14"]],"a":[["46.757","170"],["46.786","0"],["47.177","0"]]}}
1618677485.262583: {"stream":"ethusd_210625@depth@100ms","data":{"e":"depthUpdate","E":1618677482784,"T":1618677482757,"s":"ETHUSD_210625","ps":"ETHUSD","U":86143370822,"u":86143371307,"pu":86143370782,"b":[["2505.77","2075"],["2506.11","770"],["2506.80","1072"],["2506.87","1073"],["2507.22","1070"],["2508.28","0"],["2508.45","320"],["2508.61","0"],["2508.81","0"]],"a":[["2509.09","0"],["2509.11","22126"]]}}
1618677485.262639: {"stream":"linkusd_210625@depth@100ms","data":{"e":"depthUpdate","E":1618677482784,"T":1618677482734,"s":"LINKUSD_210625","ps":"LINKUSD","U":86143370823,"u":86143371167,"pu":86143369854,"b":[["43.504","50"],["43.515","0"],["43.700","50"],["43.709","0"],["43.711","0"],["43.718","0"],["43.719","0"],["43.720","0"],["43.721","0"],["43.726","108"],["43.727","23"],["43.728","100"]],"a":[["43.754","150"],["43.784","24"],["43.785","100"]]}}
1618677485.262652: {"stream":"xrpusd_210625@depth@100ms","data":{"e":"depthUpdate","E":1618677482795,"T":1618677482785,"s":"XRPUSD_210625","ps":"XRPUSD","U":86143370880,"u":86143371439,"pu":86143370838,"b":[["1.6864","0"],["1.6867","187"]],"a":[["1.6920","45"],["1.6921","112"],["1.6923","12"],["1.6928","210"],["1.6941","0"],["1.6947","175"],["1.6948","0"],["1.6990","8382"]]}}
1618677485.262698: {"stream":"btcusd_perp@depth@100ms","data":{"e":"depthUpdate","E":1618677482812,"T":1618677482802,"s":"BTCUSD_PERP","ps":"BTCUSD","U":86143371012,"u":86143371536,"pu":86143370963,"b":[["60245.4","0"],["60319.0","1807"],["60374.5","0"],["60565.5","1168"],["60574.6","33"],["60576.0","0"],["60579.1","0"],["60580.3","0"],["60580.4","1138"],["60581.2","0"]],"a":[["60581.1","7988"],["60581.4","30"],["60583.0","0"],["60584.2","100"],["60596.7","30"],["60598.7","1486"],["60598.8","0"],["60598.9","122"],["60599.2","0"],["60611.5","0"],["60611.6","243"],["60612.0","0"],["60624.3","2"],["60624.4","243"],["60624.8","102"],["60625.9","0"],["60626.7","243"],["60649.2","1"],["60793.7","3610"],["60833.9","1822"],["60868.2","0"]]}}
1618677485.262861: {"stream":"egldusd_perp@depth@100ms","data":{"e":"depthUpdate","E":1618677482818,"T":1618677482811,"s":"EGLDUSD_PERP","ps":"EGLDUSD","U":86143371053,"u":86143371574,"pu":86143370669,"b":[["215.967","54"],["216.047","0"]],"a":[["216.155","16"],["216.326","0"]]}}
1618677485.26294: {"stream":"bchusd_210625@depth@100ms","data":{"e":"depthUpdate","E":1618677482844,"T":1618677482811,"s":"BCHUSD_210625","ps":"BCHUSD","U":86143371204,"u":86143371590,"pu":86143370675,"b":[],"a":[["1139.21","190"],["1139.24","0"]]}}
1618677485.2630138: {"stream":"ethusd_210924@depth@100ms","data":{"e":"depthUpdate","E":1618677482865,"T":1618677482811,"s":"ETHUSD_210924","ps":"ETHUSD","U":86143371319,"u":86143371575,"pu":86143371313,"b":[["2683.31","0"],["2686.11","500"],["2686.12","228"],["2686.78","0"],["2686.79","0"],["2687.38","660"]],"a":[["2687.84","204"],["2688.70","0"]]}}
1618677485.263062: {"stream":"btcusd_210924@depth@100ms","data":{"e":"depthUpdate","E":1618677482874,"T":1618677482842,"s":"BTCUSD_210924","ps":"BTCUSD","U":86143371358,"u":86143371843,"pu":86143370686,"b":[["68560.8","0"],["68592.1","826"],["68592.2","236"],["68616.0","441"]],"a":[["68616.1","90"],["68672.8","0"]]}}
1618677485.263086: {"stream":"dotusd_210625@depth@100ms","data":{"e":"depthUpdate","E":1618677482890,"T":1618677482822,"s":"DOTUSD_210625","ps":"DOTUSD","U":86143371449,"u":86143371665,"pu":86143371126,"b":[["46.673","5"],["46.722","104"],["46.733","0"],["46.737","30"]],"a":[["46.757","0"],["46.786","170"],["46.961","417"],["47.233","0"]]}}
1618677485.263108: {"stream":"ethusd_210625@depth@100ms","data":{"e":"depthUpdate","E":1618677482900,"T":1618677482893,"s":"ETHUSD_210625","ps":"ETHUSD","U":86143371494,"u":86143372244,"pu":86143371307,"b":[["2506.75","1070"],["2507.22","0"],["2508.27","324"],["2508.28","246"],["2508.45","0"],["2509.12","0"]],"a":[["2509.09","0"],["2509.11","22126"],["2509.26","0"],["2518.91","378"]]}}
1618677485.263199: {"stream":"xrpusd_210625@depth@100ms","data":{"e":"depthUpdate","E":1618677482913,"T":1618677482844,"s":"XRPUSD_210625","ps":"XRPUSD","U":86143371540,"u":86143371862,"pu":86143371439,"b":[["1.6750","2116"],["1.6822","1663"]],"a":[["1.6920","0"],["1.6922","45"],["1.6927","0"],["1.6940","1000"],["1.6956","737"],["1.7057","683"]]}}
1618677485.263221: {"stream":"btcusd_perp@depth@100ms","data":{"e":"depthUpdate","E":1618677482916,"T":1618677482912,"s":"BTCUSD_PERP","ps":"BTCUSD","U":86143371551,"u":86143372379,"pu":86143371536,"b":[["60055.7","0"],["60332.1","1807"],["60353.9","1808"],["60455.4","2"],["60460.1","30"],["60561.1","0"],["60561.5","0"],["60563.6","0"],["60563.7","0"],["60563.9","0"],["60564.9","243"],["60565.0","152"],["60565.2","0"],["60566.9","0"],["60571.0","734"],["60571.3","25"],["60572.6","0"],["60573.5","150"],["60573.9","0"],["60574.1","50"],["60574.6","1"],["60575.5","0"],["60575.9","0"],["60576.0","7"],["60576.4","5"],["60577.2","0"],["60577.7","258"],["60578.4","0"],["60578.6","40"],["60578.8","30"],["60579.6","243"],["60579.7","10"],["60580.4","198"],["60580.5","0"],["60580.9","0"],["60581.0","7878"],["60581.2","0"]],"a":[["60581.1","7588"],["60586.9","55"],["60587.1","158"],["60588.3","30"],["60589.4","0"],["60590.0","50"],["60590.6","0"],["60591.2","0"],["60591.7","0"],["60592.5","5"],["60594.7","0"],["60596.1","1"],["60596.7","0"],["60596.8","235"],["60597.1","0"],["60597.9","0"],["60598.9","0"],["60599.8","30"],["60602.1","0"],["60602.3","122"],["60603.8","40"],["60604.2","40"],["60611.6","0"],["60614.8","243"],["60624.4","0"],["60626.7","0"],["60627.6","243"],["60629.6","243"],["60630.9","0"],["60667.5","0"],["60678.7","600"],["60683.0","3"],["60686.7","2749"],["60688.8","0"],["60690.6","0"],["60784.0","1821"],["60811.1","0"],["60821.3","1822"]]}}
1618677485.263507: {"stream":"linkusd_210924@depth@100ms","data":{"e":"depthUpdate","E":1618677482928,"T":1618677482842,"s":"LINKUSD_210924","ps":"LINKUSD","U":86143371692,"u":86143371836,"pu":86143370693,"b":[["45.199","1149"],["45.200","161"],["45.206","75"],["45.207","20"]],"a":[]}}
1618677485.263541: {"stream":"btcusd_210924@depth@100ms","data":{"e":"depthUpdate","E":1618677482990,"T":1618677482898,"s":"BTCUSD_210924","ps":"BTCUSD","U":86143372187,"u":86143372291,"pu":86143371843,"b":[["68592.0","0"],["68592.3","16"]],"a":[]}}
1618677485.2635489: {"stream":"dotusd_210625@depth@100ms","data":{"e":"depthUpdate","E":1618677483001,"T":1618677482995,"s":"DOTUSD_210625","ps":"DOTUSD","U":86143372283,"u":86143373047,"pu":86143371665,"b":[["46.542","1450"],["46.563","502"]],"a":[["46.764","0"],["46.785","42"],["46.786","0"],["46.787","0"],["46.965","140"]]}}
1618677485.2635689: {"stream":"ethusd_210625@depth@100ms","data":{"e":"depthUpdate","E":1618677483011,"T":1618677482983,"s":"ETHUSD_210625","ps":"ETHUSD","U":86143372357,"u":86143372927,"pu":86143372244,"b":[["2502.05","0"],["2502.17","38954"],["2508.27","0"],["2508.28","0"],["2508.29","334"],["2508.81","2421"],["2509.12","0"]],"a":[["2509.11","19139"],["2509.29","121"],["2509.59","0"]]}}
1618677485.26367: {"stream":"bchusd_210625@depth@100ms","data":{"e":"depthUpdate","E":1618677482980,"T":1618677482972,"s":"BCHUSD_210625","ps":"BCHUSD","U":86143372111,"u":86143372851,"pu":86143371590,"b":[],"a":[["1131.14","174"],["1137.37","0"],["1138.28","1944"]]}}
1618677485.263701: {"stream":"ethusd_210924@depth@100ms","data":{"e":"depthUpdate","E":1618677482980,"T":1618677482943,"s":"ETHUSD_210924","ps":"ETHUSD","U":86143372124,"u":86143372598,"pu":86143371575,"b":[["2684.19","8014"],["2684.92","0"],["2684.94","1160"]],"a":[["2687.84","324"],["2696.98","0"]]}}
1618677485.263736: {"stream":"egldusd_perp@depth@100ms","data":{"e":"depthUpdate","E":1618677482983,"T":1618677482966,"s":"EGLDUSD_PERP","ps":"EGLDUSD","U":86143372136,"u":86143372814,"pu":86143371574,"b":[["215.427","0"],["215.517","799"],["215.967","0"],["216.047","54"]],"a":[["216.382","15"],["216.414","0"]]}}
1618677485.2637792: {"stream":"linkusd_210625@depth@100ms","data":{"e":"depthUpdate","E":1618677483001,"T":1618677482993,"s":"LINKUSD_210625","ps":"LINKUSD","U":86143372282,"u":86143373007,"pu":86143371167,"b":[["43.729","0"],["43.732","0"]],"a":[["43.754","0"],["43.756","0"],["43.758","1"],["43.762","150"],["43.764","100"],["43.766","202"],["43.843","0"]]}}
1618677485.2637901: {"stream":"btcusd_perp@depth@100ms","data":{"e":"depthUpdate","E":1618677483024,"T":1618677483015,"s":"BTCUSD_PERP","ps":"BTCUSD","U":86143372422,"u":86143373240,"pu":86143372379,"b":[["60245.4","1805"],["60322.0","1779"],["60480.0","550"],["60564.8","122"],["60565.0","30"],["60570.0","0"],["60573.1","16"],["60574.7","32"],["60576.0","0"],["60581.2","0"]],"a":[["60585.6","130"],["60585.8","0"],["60586.9","40"],["60588.2","0"],["60588.3","0"],["60589.5","0"],["60589.9","23"],["60592.0","0"],["60596.7","10"],["60600.0","170"],["60602.3","122"],["60602.5","0"],["60614.8","0"],["60615.3","243"],["60627.6","0"],["60628.1","243"],["60629.6","0"],["60630.0","257"],["60640.5","1090"],["60657.5","1000"],["60830.0","0"],["60860.9","0"],["60868.2","1824"],["61133.2","372"]]}}
1618677485.263985: {"stream":"xrpusd_210625@depth@100ms","data":{"e":"depthUpdate","E":1618677483040,"T":1618677482969,"s":"XRPUSD_210625","ps":"XRPUSD","U":86143372549,"u":86143372833,"pu":86143371862,"b":[["1.6764","0"],["1.6774","3656"],["1.6794","0"],["1.6798","100"],["1.6856","250"],["1.6866","1000"],["1.6887","297"],["1.6891","100"]],"a":[["1.6928","305"],["1.7057","351"]]}}
1618677485.264006: {"stream":"linkusd_210924@depth@100ms","data":{"e":"depthUpdate","E":1618677483042,"T":1618677482995,"s":"LINKUSD_210924","ps":"LINKUSD","U":86143372562,"u":86143373041,"pu":86143371836,"b":[["45.200","241"]],"a":[["45.391","0"],["45.404","3837"]]}}
1618677485.264102: {"stream":"linkusd_210625@depth@100ms","data":{"e":"depthUpdate","E":1618677483101,"T":1618677483088,"s":"LINKUSD_210625","ps":"LINKUSD","U":86143373051,"u":86143373954,"pu":86143373007,"b":[["43.727","0"],["43.729","0"],["43.732","405"]],"a":[["43.747","32"],["43.762","100"],["43.775","109"],["43.803","1450"],["43.804","0"],["43.805","588"],["43.930","0"],["43.933","180"]]}}
1618677485.2641122: {"stream":"bchusd_210625@depth@100ms","data":{"e":"depthUpdate","E":1618677483105,"T":1618677483081,"s":"BCHUSD_210625","ps":"BCHUSD","U":86143373081,"u":86143373895,"pu":86143372851,"b":[["1127.35","0"],["1127.36","0"],["1127.39","13"],["1127.40","0"],["1127.41","0"],["1127.42","64"],["1127.43","27"]],"a":[["1129.47","0"],["1131.14","0"],["1139.21","0"]]}}
1618677485.264163: {"stream":"dotusd_210625@depth@100ms","data":{"e":"depthUpdate","E":1618677483106,"T":1618677483037,"s":"DOTUSD_210625","ps":"DOTUSD","U":86143373094,"u":86143373473,"pu":86143373047,"b":[["46.542","0"],["46.549","1476"],["46.722","0"],["46.733","12"]],"a":[["46.757","170"],["46.785","0"],["46.787","42"]]}}
1618677485.2641861: {"stream":"ethusd_210625@depth@100ms","data":{"e":"depthUpdate","E":1618677483113,"T":1618677483102,"s":"ETHUSD_210625","ps":"ETHUSD","U":86143373196,"u":86143374042,"pu":86143372927,"b":[["2505.77","0"],["2506.25","3428"],["2506.80","0"],["2506.87","0"],["2507.09","1072"],["2507.16","1178"],["2508.27","317"],["2508.29","0"],["2508.35","850"],["2508.45","0"],["2508.71","0"],["2508.72","299"],["2508.82","0"],["2509.12","0"]],"a":[["2509.11","18277"],["2509.15","0"],["2509.26","121"],["2509.29","0"],["2509.42","0"]]}}
1618677485.2642848: {"stream":"btcusd_perp@depth@100ms","data":{"e":"depthUpdate","E":1618677483125,"T":1618677483115,"s":"BTCUSD_PERP","ps":"BTCUSD","U":86143373283,"u":86143374136,"pu":86143373240,"b":[["60560.0","865"],["60564.4","788"],["60564.5","122"],["60564.8","0"],["60564.9","0"],["60577.2","243"],["60577.7","15"],["60580.0","121"],["60581.2","0"]],"a":[["60581.1","7587"],["60583.0","30"],["60585.6","100"],["60588.4","0"],["60589.5","8"],["60589.9","0"],["60602.3","122"],["60602.4","0"],["60603.5","20"],["60698.3","0"],["60776.9","1100"],["60784.0","1821"],["60791.3","0"],["60792.3","1846"],["60797.9","0"],["60805.8","0"],["60811.0","3635"],["60813.5","3635"]]}}
1618677485.264389: {"stream":"ethusd_210924@depth@100ms","data":{"e":"depthUpdate","E":1618677483125,"T":1618677483115,"s":"ETHUSD_210924","ps":"ETHUSD","U":86143373287,"u":86143374137,"pu":86143372598,"b":[["2686.11","0"],["2686.76","500"],["2686.77","181"],["2687.38","0"],["2687.39","660"]],"a":[["2687.84","50"],["2697.90","13641"]]}}
1618677485.264435: {"stream":"egldusd_perp@depth@100ms","data":{"e":"depthUpdate","E":1618677483129,"T":1618677483114,"s":"EGLDUSD_PERP","ps":"EGLDUSD","U":86143373356,"u":86143374125,"pu":86143372814,"b":[],"a":[["216.307","474"],["216.338","0"],["216.959","0"]]}}
1618677485.264503: {"stream":"btcusd_210924@depth@100ms","data":{"e":"depthUpdate","E":1618677483156,"T":1618677483078,"s":"BTCUSD_210924","ps":"BTCUSD","U":86143373640,"u":86143373867,"pu":86143372291,"b":[["68558.7","0"],["68584.5","1652"],["68584.6","462"]],"a":[]}}
1618677485.264524: {"stream":"linkusd_210924@depth@100ms","data":{"e":"depthUpdate","E":1618677483160,"T":1618677483056,"s":"LINKUSD_210924","ps":"LINKUSD","U":86143373664,"u":86143373673,"pu":86143373041,"b":[["45.084","300"],["45.107","250"]],"a":[]}}
1618677485.2645319: {"stream":"xrpusd_210625@depth@100ms","data":{"e":"depthUpdate","E":1618677483169,"T":1618677483110,"s":"XRPUSD_210625","ps":"XRPUSD","U":86143373747,"u":86143374091,"pu":86143372833,"b":[],"a":[["1.6938","0"],["1.7002","630"],["1.7057","667"]]}}
1618677485.26464: {"stream":"bchusd_210625@depth@100ms","data":{"e":"depthUpdate","E":1618677483210,"T":1618677483205,"s":"BCHUSD_210625","ps":"BCHUSD","U":86143374068,"u":86143374785,"pu":86143373895,"b":[["1124.10","268"],["1126.68","100"],["1127.18","425"],["1127.38","0"],["1127.39","0"],["1127.44","0"],["1127.45","0"],["1127.46","0"],["1127.47","0"],["1127.49","64"],["1127.50","35"],["1127.51","35"]],"a":[["1128.63","0"],["1131.22","95"],["1131.54","0"]]}}
1618677485.264756: {"stream":"ethusd_210625@depth@100ms","data":{"e":"depthUpdate","E":1618677483218,"T":1618677483213,"s":"ETHUSD_210625","ps":"ETHUSD","U":86143374120,"u":86143374863,"pu":86143374042,"b":[["2504.66","0"],["2505.11","189"],["2506.25","1353"],["2506.50","2075"],["2506.58","0"],["2506.64","0"],["2506.75","0"],["2507.09","0"],["2507.14","1070"],["2507.16","105"],["2507.20","0"],["2507.62","1073"],["2508.27","0"],["2508.36","525"],["2509.10","2212"],["2509.12","0"]],"a":[["2509.11","14347"],["2509.25","0"],["2509.26","0"],["2509.30","100"],["2509.38","0"],["2509.59","1073"],["2509.60","1688"],["2509.67","1070"],["2509.80","121"],["2514.96","0"],["2515.88","1000"]]}}
1618677485.264864: {"stream":"dotusd_210625@depth@100ms","data":{"e":"depthUpdate","E":1618677483222,"T":1618677483215,"s":"DOTUSD_210625","ps":"DOTUSD","U":86143374156,"u":86143374883,"pu":86143373473,"b":[["46.722","104"],["46.733","0"]],"a":[["46.849","635"]]}}
1618677485.264888: {"stream":"btcusd_perp@depth@100ms","data":{"e":"depthUpdate","E":1618677483226,"T":1618677483220,"s":"BTCUSD_PERP","ps":"BTCUSD","U":86143374174,"u":86143374939,"pu":86143374136,"b":[["60337.7","3590"],["60344.4","1808"],["60553.6","45"],["60553.7","2032"],["60574.7","0"],["60575.0","32"],["60575.7","0"],["60579.2","243"],["60579.6","0"],["60581.0","7888"],["60581.2","0"]],"a":[["60581.9","0"],["60583.0","0"],["60584.8","30"],["60586.7","0"],["60586.9","190"],["60587.1","8"],["60589.5","0"],["60589.9","33"],["60601.8","122"],["60602.2","0"],["60602.3","0"],["60614.6","243"],["60615.3","0"],["60621.9","1405"],["60623.6","0"],["60627.4","342"],["60628.1","0"],["60629.4","243"],["60630.0","14"],["60800.8","0"],["60808.2","1821"],["60809.2","0"],["60813.5","1847"],["60824.4","3641"],["60840.1","0"]]}}
1618677485.265098: {"stream":"egldusd_perp@depth@100ms","data":{"e":"depthUpdate","E":1618677483241,"T":1618677483206,"s":"EGLDUSD_PERP","ps":"EGLDUSD","U":86143374309,"u":86143374798,"pu":86143374125,"b":[],"a":[["216.155","0"],["216.306","133"],["216.308","0"],["216.309","0"],["216.336","0"],["216.504","107"]]}}
1618677485.2652318: {"stream":"linkusd_210625@depth@100ms","data":{"e":"depthUpdate","E":1618677483260,"T":1618677483255,"s":"LINKUSD_210625","ps":"LINKUSD","U":86143374418,"u":86143375574,"pu":86143373954,"b":[["43.504","0"],["43.513","50"],["43.700","0"],["43.709","50"]],"a":[["43.747","0"],["43.757","0"],["43.764","0"],["43.766","102"],["43.770","100"],["43.772","100"],["43.774","100"]]}}
1618677485.26545: {"stream":"btcusd_210924@depth@100ms","data":{"e":"depthUpdate","E":1618677483269,"T":1618677483248,"s":"BTCUSD_210924","ps":"BTCUSD","U":86143374490,"u":86143375367,"pu":86143373867,"b":[["68560.8","220"],["68584.4","0"]],"a":[["68624.0","0"],["68625.2","0"],["68632.0","20"]]}}
1618677485.265459: {"stream":"linkusd_210924@depth@100ms","data":{"e":"depthUpdate","E":1618677483270,"T":1618677483222,"s":"LINKUSD_210924","ps":"LINKUSD","U":86143374469,"u":86143374948,"pu":86143373673,"b":[["45.199","0"],["45.200","0"],["45.211","1726"],["45.212","364"]],"a":[]}}
1618677485.26593: {"stream":"bchusd_210625@depth@100ms","data":{"e":"depthUpdate","E":1618677483311,"T":1618677483302,"s":"BCHUSD_210625","ps":"BCHUSD","U":86143374787,"u":86143376730,"pu":86143374785,"b":[["1117.38","0"],["1119.42","0"],["1121.46","0"],["1122.44","0"],["1122.50","1475"],["1122.61","0"],["1122.90","0"],["1123.50","0"],["1124.07","0"],["1125.55","0"],["1125.57","0"],["1127.19","89"],["1127.42","0"],["1127.43","0"],["1127.49","0"],["1127.50","15"],["1127.51","0"],["1127.52","0"],["1127.53","64"],["1127.54","35"],["1127.55","40"]],"a":[["1128.97","0"],["1131.29","0"],["1131.60","0"],["1131.92","50"],["1133.62","175"],["1135.95","0"],["1137.62","1817"],["1138.28","0"],["1138.29","0"]]}}
1618677485.266123: {"stream":"ethusd_210625@depth@100ms","data":{"e":"depthUpdate","E":1618677483318,"T":1618677483312,"s":"ETHUSD_210625","ps":"ETHUSD","U":86143374878,"u":86143376982,"pu":86143374863,"b":[["2383.59","0"],["2496.45","0"],["2498.77","500"],["2500.28","995"],["2501.96","0"],["2502.13","0"],["2502.17","34977"],["2502.23","1100"],["2502.32","5510"],["2503.44","0"],["2503.96","0"],["2504.75","0"],["2505.04","94"],["2505.28","0"],["2505.63","0"],["2505.64","1083"],["2505.67","0"],["2505.74","0"],["2505.84","963"],["2505.88","0"],["2506.07","0"],["2506.36","0"],["2506.49","2029"],["2506.50","0"],["2507.14","0"],["2507.38","0"],["2507.39","0"],["2507.54","1072"],["2507.60","1070"],["2507.68","0"],["2507.71","2385"],["2507.72","0"],["2507.80","0"],["2507.85","0"],["2508.03","1825"],["2508.09","60"],["2508.26","0"],["2508.35","0"],["2508.60","0"],["2508.65","0"],["2508.70","0"],["2508.72","0"],["2508.76","0"],["2508.80","0"],["2508.81","0"],["2508.82","0"],["2508.85","2000"],["2509.00","100"],["2509.07","99"],["2509.10","310"],["2509.11","9693"],["2509.12","0"],["2509.13","0"],["2509.14","0"],["2509.15","0"],["2509.16","2589"],["2509.18","0"],["2509.20","100"],["2509.21","211"],["2509.25","80"],["2509.26","1161"],["2509.27","302"],["2509.30","7714"],["2509.31","0"],["2509.32","0"],["2509.36","0"],["2509.39","0"],["2509.43","0"]],"a":[["2509.11","0"],["2509.16","0"],["2509.26","0"],["2509.27","0"],["2509.30","0"],["2509.31","1145"],["2509.32","1908"],["2509.33","1072"],["2509.40","1070"],["2509.41","0"],["2509.59","0"],["2509.60","616"],["2509.67","0"],["2509.80","0"],["2509.81","0"],["2509.88","121"],["2509.94","0"],["2509.95","0"],["2509.97","0"],["2509.98","0"],["2510.00","0"],["2510.09","1150"],["2510.10","0"],["2510.11","121"],["2510.12","1359"],["2510.30","0"],["2510.40","100"],["2510.41","0"],["2510.50","100"],["2510.95","0"],["2511.02","1839"],["2511.25","1734"],["2511.29","880"],["2511.42","0"],["2511.72","0"],["2512.35","11766"],["2512.86","0"],["2514.30","0"],["2514.87","2100"],["2515.74","0"],["2519.98","0"],["2634.61","0"],["2634.81","900"]]}}
1618677485.266528: {"stream":"ethusd_210924@depth@100ms","data":{"e":"depthUpdate","E":1618677483322,"T":1618677483317,"s":"ETHUSD_210924","ps":"ETHUSD","U":86143374906,"u":86143377098,"pu":86143374137,"b":[["2553.39","0"],["2553.79","0"],["2674.47","1860"],["2680.01","0"],["2682.09","0"],["2684.17","0"],["2684.18","0"],["2684.20","1683"],["2685.02","0"],["2685.03","0"],["2685.43","0"],["2685.45","4007"],["2685.46","862"],["2685.89","48"],["2686.10","0"],["2686.12","1495"],["2687.39","0"],["2687.83","0"],["2687.84","0"],["2687.90","0"],["2687.91","0"],["2688.12","0"],["2688.29","0"],["2688.36","0"],["2688.62","416"]],"a":[["2687.84","0"],["2688.23","0"],["2688.30","0"],["2688.56","0"],["2688.63","448"],["2688.64","0"],["2688.98","0"],["2689.09","0"],["2689.50","0"],["2690.07","0"],["2690.08","0"],["2690.26","487"],["2690.68","243"],["2690.69","1151"],["2690.70","0"],["2690.86","380"],["2691.20","100"],["2693.10","0"],["2694.44","0"],["2695.23","1563"],["2700.63","0"],["2701.28","1860"],["2702.08","15000"]]}}
1618677485.2668009: {"stream":"btcusd_perp@depth@100ms","data":{"e":"depthUpdate","E":1618677483327,"T":1618677483323,"s":"BTCUSD_PERP","ps":"BTCUSD","U":86143374949,"u":86143377234,"pu":86143374939,"b":[["60315.9","1807"],["60343.2","1807"],["60364.8","1808"],["60514.8","0"],["60553.3","1264"],["60564.4","545"],["60564.5","0"],["60565.8","0"],["60566.0","443"],["60567.0","243"],["60567.1","123"],["60569.4","0"],["60574.7","32"],["60575.0","0"],["60577.2","0"],["60578.6","40"],["60579.2","0"],["60579.8","243"],["60580.6","0"],["60581.0","8218"],["60581.2","0"],["60586.4","0"]],"a":[["60581.1","2927"],["60581.4","0"],["60582.6","0"],["60584.2","0"],["60584.8","0"],["60586.9","40"],["60587.3","2159"],["60589.6","210"],["60591.3","0"],["60593.7","0"],["60597.0","0"],["60601.8","0"],["60603.5","20"],["60604.5","122"],["60609.4","30"],["60614.6","0"],["60616.3","584"],["60619.8","0"],["60627.4","99"],["60629.1","0"],["60629.4","0"],["60630.1","0"],["60631.1","0"],["60632.1","0"],["60640.5","90"],["60641.0","0"],["60656.5","1009"],["60776.9","0"],["60792.3","3667"],["60814.9","0"],["60817.7","1822"],["60830.0","1788"],["60833.5","1822"],["60846.2","1823"],["60860.9","1789"]]}}
1618677485.267033: {"stream":"dotusd_210625@depth@100ms","data":{"e":"depthUpdate","E":1618677483333,"T":1618677483305,"s":"DOTUSD_210625","ps":"DOTUSD","U":86143375074,"u":86143376813,"pu":86143374883,"b":[],"a":[["46.757","0"],["46.764","170"],["46.857","1483"]]}}
1618677485.267328: {"stream":"linkusd_210625@depth@100ms","data":{"e":"depthUpdate","E":1618677483360,"T":1618677483352,"s":"LINKUSD_210625","ps":"LINKUSD","U":86143375580,"u":86143378067,"pu":86143375574,"b":[["43.513","0"],["43.519","150"],["43.709","0"],["43.712","349"],["43.715","140"],["43.724","100"],["43.725","0"],["43.726","8"],["43.728","0"],["43.733","86"],["43.736","0"],["43.737","23"],["43.738","0"],["43.739","0"],["43.740","12"],["43.744","100"],["43.745","21"],["43.746","100"],["43.747","44"]],"a":[["43.751","0"],["43.755","0"],["43.759","0"],["43.762","0"],["43.763","0"],["43.765","0"],["43.770","0"],["43.771","50"],["43.772","0"],["43.774","0"],["43.780","100"],["43.782","100"],["43.784","124"],["43.791","86"],["43.803","0"],["43.805","0"],["43.814","0"],["43.827","0"],["43.832","1221"]]}}
1618677485.267735: {"stream":"egldusd_perp@depth@100ms","data":{"e":"depthUpdate","E":1618677483378,"T":1618677483367,"s":"EGLDUSD_PERP","ps":"EGLDUSD","U":86143376114,"u":86143378428,"pu":86143374798,"b":[["215.517","15"],["215.537","784"],["215.857","0"],["215.858","389"],["215.943","0"],["216.031","539"],["216.047","0"],["216.057","170"],["216.067","54"]],"a":[["216.058","0"],["216.145","170"],["216.155","16"],["216.165","0"],["216.182","97"]]}}
1618677485.2679071: {"stream":"linkusd_210924@depth@100ms","data":{"e":"depthUpdate","E":1618677483388,"T":1618677483382,"s":"LINKUSD_210924","ps":"LINKUSD","U":86143375985,"u":86143378842,"pu":86143374948,"b":[["45.234","92"]],"a":[["45.289","0"],["45.290","50"],["45.374","0"],["45.390","0"],["45.404","0"],["45.405","1765"]]}}
1618677485.267918: {"stream":"btcusd_210924@depth@100ms","data":{"e":"depthUpdate","E":1618677483389,"T":1618677483377,"s":"BTCUSD_210924","ps":"BTCUSD","U":86143376380,"u":86143378713,"pu":86143375367,"b":[["68342.7","1049"],["68429.5","0"],["68498.2","0"],["68534.6","60"],["68539.6","0"],["68558.6","192"],["68559.0","60"],["68560.6","0"],["68560.7","0"],["68595.6","0"],["68612.0","0"],["68613.0","0"],["68614.0","0"],["68616.0","1"],["68616.1","0"],["68619.5","0"],["68619.6","0"],["68622.0","10"],["68623.0","10"],["68624.0","585"]],"a":[["68616.1","0"],["68624.0","0"],["68624.1","90"],["68639.2","0"],["68642.4","0"],["68643.1","0"],["68651.1","0"],["68658.9","0"],["68661.4","0"],["68666.7","0"],["68666.9","0"],["68765.3","0"],["68827.7","0"],["68890.6","1049"],["68896.4","0"]]}}
1618677485.268171: {"stream":"ethusd_210625@depth@100ms","data":{"e":"depthUpdate","E":1618677483418,"T":1618677483412,"s":"ETHUSD_210625","ps":"ETHUSD","U":86143376999,"u":86143379573,"pu":86143376982,"b":[["2498.77","0"],["2500.02","0"],["2500.28","0"],["2502.23","0"],["2502.32","0"],["2502.51","0"],["2502.52","0"],["2502.58","0"],["2502.84","3511"],["2502.99","0"],["2503.12","100"],["2503.72","0"],["2504.05","1002"],["2505.01","1000"],["2505.08","0"],["2505.12","0"],["2505.30","0"],["2505.36","0"],["2505.43","0"],["2505.55","694"],["2505.64","0"],["2505.76","0"],["2505.83","0"],["2505.84","0"],["2505.95","0"],["2506.01","391"],["2506.04","782"],["2506.08","916"],["2506.10","0"],["2506.11","0"],["2506.14","0"],["2506.25","0"],["2506.36","1528"],["2506.38","0"],["2506.40","0"],["2506.49","0"],["2506.62","0"],["2506.63","0"],["2506.76","0"],["2506.88","1500"],["2507.54","0"],["2507.60","0"],["2507.62","0"],["2507.81","0"],["2507.98","1072"],["2508.01","0"],["2508.05","1073"],["2508.09","0"],["2508.11","0"],["2508.12","1003"],["2508.19","0"],["2508.36","0"],["2508.43","0"],["2508.48","60"],["2508.82","0"],["2508.85","0"],["2508.87","0"],["2509.00","0"],["2509.03","100"],["2509.04","3585"],["2509.10","0"],["2509.11","7245"],["2509.12","966"],["2509.16","0"],["2509.20","0"],["2509.21","0"],["2509.22","0"],["2509.25","0"],["2509.26","0"],["2509.30","1399"],["2509.31","3218"],["2509.32","2707"],["2509.33","731"],["2509.34","0"],["2509.38","500"],["2509.39","0"],["2509.40","257"],["2509.58","0"],["2509.59","3828"],["2509.60","100"],["2509.70","100"],["2509.80","7939"],["2509.82","0"],["2509.88","0"]],"a":[["2509.31","0"],["2509.32","0"],["2509.33","0"],["2509.39","0"],["2509.40","0"],["2509.60","0"],["2509.63","0"],["2509.65","0"],["2509.81","152"],["2509.82","0"],["2509.85","0"],["2509.88","0"],["2509.89","0"],["2510.09","0"],["2510.11","0"],["2510.12","0"],["2510.13","0"],["2510.15","0"],["2510.16","0"],["2510.19","1072"],["2510.26","1070"],["2510.30","121"],["2510.31","0"],["2510.40","0"],["2510.42","0"],["2510.46","0"],["2510.50","0"],["2510.56","0"],["2510.57","2401"],["2510.62","367"],["2510.68","1052"],["2510.86","60"],["2510.93","0"],["2510.96","0"],["2511.00","830"],["2511.01","2026"],["2511.02","0"],["2511.04","2029"],["2511.10","2304"],["2511.15","4094"],["2511.57","2306"],["2511.80","6267"],["2512.35","2384"],["2512.41","0"],["2512.64","0"],["2513.69","9383"],["2513.81","0"],["2514.29","0"],["2514.87","0"],["2515.88","0"],["2516.84","2100"],["2517.14","2757"],["2517.80","0"],["2634.81","0"],["2635.21","900"]]}}
1618677485.2687192: {"stream":"bchusd_210625@depth@100ms","data":{"e":"depthUpdate","E":1618677483421,"T":1618677483417,"s":"BCHUSD_210625","ps":"BCHUSD","U":86143377097,"u":86143379652,"pu":86143376730,"b":[["1116.45","0"],["1116.67","50"],["1122.50","0"],["1122.78","340"],["1122.90","1475"],["1124.62","0"],["1124.84","50"],["1127.03","102"],["1127.50","0"],["1127.54","15"],["1127.55","0"],["1127.56","0"],["1127.57","64"],["1127.58","35"]],"a":[["1128.51","0"],["1128.89","0"],["1130.13","0"],["1131.70","101"],["1137.62","0"],["1138.57","1817"]]}}
1618677485.268817: {"stream":"xrpusd_210625@depth@100ms","data":{"e":"depthUpdate","E":1618677483425,"T":1618677483385,"s":"XRPUSD_210625","ps":"XRPUSD","U":86143377024,"u":86143378924,"pu":86143374091,"b":[["1.6874","0"],["1.6891","198"]],"a":[["1.6967","2092"],["1.6990","6402"],["1.6992","0"]]}}
1618677485.2688909: {"stream":"btcusd_perp@depth@100ms","data":{"e":"depthUpdate","E":1618677483427,"T":1618677483423,"s":"BTCUSD_PERP","ps":"BTCUSD","U":86143377240,"u":86143379776,"pu":86143377234,"b":[["60511.2","0"],["60543.3","0"],["60561.3","0"],["60562.0","0"],["60566.8","945"],["60567.0","0"],["60567.1","1"],["60568.6","0"],["60568.7","100"],["60572.4","25"],["60574.7","0"],["60575.0","200"],["60575.2","220"],["60575.3","397"],["60575.4","0"],["60575.5","32"],["60578.8","0"],["60579.8","0"],["60580.3","336"],["60581.0","8570"],["60581.2","0"],["60581.6","0"],["60581.8","0"],["60581.9","0"],["60582.1","0"],["60582.3","0"],["60582.5","0"],["60582.7","0"],["60582.9","0"],["60583.0","0"],["60583.2","0"],["60583.4","0"],["60583.6","0"],["60583.8","0"],["60583.9","0"],["60584.1","0"],["60584.3","0"],["60584.5","0"],["60584.7","0"],["60584.9","0"],["60585.0","0"],["60585.2","0"],["60585.4","0"],["60585.5","0"],["60585.6","0"],["60585.7","0"],["60585.8","0"],["60585.9","0"],["60586.1","0"],["60586.2","0"],["60586.3","0"],["60586.5","0"],["60586.7","0"],["60586.9","0"],["60587.0","0"],["60587.2","0"],["60587.4","0"],["60587.6","0"],["60587.8","0"],["60587.9","0"],["60588.1","0"],["60588.3","0"],["60588.5","0"],["60588.7","0"],["60588.9","0"],["60589.0","0"],["60589.2","0"],["60589.4","0"],["60589.6","0"],["60589.8","0"],["60589.9","0"],["60590.1","0"]],"a":[["60581.1","1880"],["60581.2","0"],["60582.1","201"],["60586.0","0"],["60587.3","30"],["60588.2","30"],["60590.8","200"],["60591.0","96"],["60591.3","100"],["60592.9","0"],["60593.5","5"],["60594.3","25"],["60594.8","0"],["60598.7","0"],["60599.5","1285"],["60604.5","0"],["60605.1","122"],["60608.0","0"],["60609.4","0"],["60618.1","0"],["60618.3","0"],["60630.9","0"],["60632.8","0"],["60632.9","0"],["60634.4","0"],["60636.4","2"],["60649.2","0"],["60649.3","0"],["60652.1","930"],["60655.1","500"],["60667.6","541"],["60678.7","0"],["60686.7","1100"],["60692.9","1649"],["60703.8","1100"],["60789.8","0"],["60795.5","3627"],["60797.3","1821"],["60806.2","168"],["60809.2","1822"],["60813.5","3668"],["60827.4","1822"],["60840.1","1822"]]}}
1618677485.269205: {"stream":"ethusd_210924@depth@100ms","data":{"e":"depthUpdate","E":1618677483428,"T":1618677483422,"s":"ETHUSD_210924","ps":"ETHUSD","U":86143377264,"u":86143379745,"pu":86143377098,"b":[["2660.83","0"],["2662.32","1000"],["2678.40","0"],["2679.12","0"],["2685.01","0"],["2685.80","0"],["2685.81","0"],["2686.58","2100"],["2686.59","441"],["2687.29","1394"],["2687.30","292"],["2687.46","0"],["2687.47","660"],["2687.48","0"],["2687.84","0"],["2687.85","0"],["2687.94","486"],["2687.95","103"],["2687.99","0"],["2688.00","0"],["2688.09","0"],["2688.23","1000"],["2688.62","891"],["2688.63","200"],["2688.68","416"]],"a":[["2688.63","0"],["2689.73","100"],["2690.26","0"],["2693.26","0"],["2695.23","0"],["2695.24","0"],["2695.58","0"]]}}
1618677485.269459: {"stream":"dotusd_210625@depth@100ms","data":{"e":"depthUpdate","E":1618677483444,"T":1618677483438,"s":"DOTUSD_210625","ps":"DOTUSD","U":86143377707,"u":86143380226,"pu":86143376813,"b":[["46.323","728"],["46.549","0"],["46.566","136"],["46.572","2145"],["46.714","188"],["46.719","0"],["46.733","115"],["46.735","250"],["46.737","817"],["46.738","178"],["46.739","0"],["46.740","100"],["46.741","235"]],"a":[["46.758","0"],["46.763","0"],["46.764","0"],["46.765","0"],["46.766","0"],["46.786","0"],["46.788","0"],["46.807","192"],["46.810","0"],["46.811","0"],["46.829","195"],["46.857","0"],["46.859","0"],["46.906","0"],["46.931","0"],["46.933","0"],["46.948","0"],["46.985","1200"],["47.140","0"],["47.215","0"],["47.267","1200"]]}}
1618677485.2696698: {"stream":"linkusd_210625@depth@100ms","data":{"e":"depthUpdate","E":1618677483461,"T":1618677483449,"s":"LINKUSD_210625","ps":"LINKUSD","U":86143378136,"u":86143380472,"pu":86143378067,"b":[["43.632","250"],["43.706","0"],["43.726","0"],["43.731","0"],["43.736","101"],["43.737","0"],["43.744","0"],["43.745","0"],["43.746","0"],["43.747","0"],["43.748","32"],["43.754","598"],["43.756","100"],["43.758","32"]],"a":[["43.758","0"],["43.771","0"],["43.775","13"],["43.779","50"],["43.780","0"],["43.782","0"],["43.784","24"],["43.788","100"],["43.790","100"],["43.791","0"],["43.792","511"],["43.793","0"],["43.832","0"],["43.847","1221"],["43.857","97"],["43.868","92"],["43.880","40"],["43.986","0"],["44.000","107"]]}}
1618677485.270028: {"stream":"btcusd_210924@depth@100ms","data":{"e":"depthUpdate","E":1618677483489,"T":1618677483477,"s":"BTCUSD_210924","ps":"BTCUSD","U":86143378922,"u":86143381394,"pu":86143378713,"b":[["68035.1","0"],["68046.8","12"],["68382.8","500"],["68433.3","0"],["68451.4","2000"],["68505.8","0"],["68513.8","1500"],["68555.7","20"],["68574.6","20"],["68578.4","0"],["68578.5","0"],["68592.3","0"],["68616.1","202"],["68620.1","214"]],"a":[["68646.3","0"],["68650.6","100"],["68652.3","304"],["68658.5","20"],["68677.5","20"],["68687.3","339"],["68687.4","1619"],["68687.5","0"],["68718.2","316"],["68718.3","1500"],["68719.1","0"],["68719.2","0"],["68780.7","2000"],["68792.2","0"],["68849.3","500"]]}}
1618677485.270143: {"stream":"egldusd_perp@depth@100ms","data":{"e":"depthUpdate","E":1618677483492,"T":1618677483467,"s":"EGLDUSD_PERP","ps":"EGLDUSD","U":86143379024,"u":86143381024,"pu":86143378428,"b":[["216.037","0"]],"a":[["216.155","0"],["216.306","110"],["216.382","0"],["216.468","32"],["216.932","807"]]}}
1618677485.270302: {"stream":"linkusd_210924@depth@100ms","data":{"e":"depthUpdate","E":1618677483503,"T":1618677483490,"s":"LINKUSD_210924","ps":"LINKUSD","U":86143379225,"u":86143381852,"pu":86143378842,"b":[["44.494","0"],["45.233","340"],["45.237","100"],["45.238","22"]],"a":[["45.290","0"],["45.291","0"],["45.357","0"],["45.405","0"],["45.505","0"]]}}
1618677485.2704651: {"stream":"ethusd_210625@depth@100ms","data":{"e":"depthUpdate","E":1618677483518,"T":1618677483513,"s":"ETHUSD_210625","ps":"ETHUSD","U":86143379592,"u":86143382512,"pu":86143379573,"b":[["2488.68","49"],["2497.75","0"],["2497.84","0"],["2498.59","0"],["2500.11","1243"],["2502.29","0"],["2503.08","0"],["2503.10","2000"],["2503.12","0"],["2503.37","100"],["2503.49","0"],["2503.56","0"],["2503.57","0"],["2503.59","0"],["2503.62","0"],["2503.89","0"],["2503.93","1841"],["2503.94","0"],["2504.04","172"],["2504.21","8"],["2504.27","0"],["2504.28","0"],["2504.32","0"],["2504.33","2505"],["2504.37","0"],["2504.40","3000"],["2504.48","32349"],["2504.52","0"],["2504.56","0"],["2504.70","0"],["2504.77","0"],["2504.78","0"],["2504.84","0"],["2504.85","0"],["2504.93","0"],["2504.95","100"],["2504.97","0"],["2504.98","0"],["2505.00","1951"],["2505.03","0"],["2505.06","0"],["2505.07","0"],["2505.15","0"],["2505.16","0"],["2505.22","0"],["2505.26","0"],["2505.31","0"],["2505.33","0"],["2505.38","500"],["2505.45","0"],["2505.48","0"],["2505.78","26958"],["2505.92","0"],["2506.38","1651"],["2506.74","1204"],["2506.77","0"],["2506.84","0"],["2507.08","21566"],["2507.16","1237"],["2507.18","1359"],["2507.19","1535"],["2507.26","963"],["2507.30","0"],["2507.56","1353"],["2507.59","770"],["2507.64","0"],["2507.65","0"],["2507.67","839"],["2507.69","0"],["2507.74","1070"],["2508.05","0"],["2508.06","1052"],["2508.07","616"],["2508.11","1378"],["2508.12","1193"],["2508.21","835"],["2508.38","21998"],["2508.46","2100"],["2508.48","0"],["2509.04","1585"],["2509.12","0"],["2509.13","0"],["2509.14","0"],["2509.31","2919"],["2509.32","2207"],["2509.33","0"],["2509.35","0"],["2509.38","0"],["2509.40","0"],["2509.59","862"],["2509.60","616"],["2509.61","2703"],["2509.62","0"],["2509.68","16822"],["2509.69","3442"],["2509.70","0"],["2509.80","299"],["2509.81","2618"],["2509.82","550"],["2509.86","250"],["2509.87","0"],["2509.88","0"],["2510.00","100"],["2510.02","0"],["2510.03","2000"],["2510.10","100"],["2510.15","0"],["2510.20","100"],["2510.29","0"],["2510.30","500"],["2510.32","255"],["2510.38","0"],["2510.39","0"],["2510.40","800"],["2510.41","460"],["2510.44","80"],["2510.56","842"],["2510.58","0"]],"a":[["2509.81","0"],["2510.01","0"],["2510.02","0"],["2510.19","0"],["2510.26","0"],["2510.29","0"],["2510.30","0"],["2510.56","0"],["2510.57","1353"],["2510.58","0"],["2510.63","0"],["2510.65","391"],["2510.70","0"],["2510.75","0"],["2510.80","0"],["2510.82","0"],["2510.83","0"],["2510.84","838"],["2510.86","0"],["2510.89","1250"],["2510.90","616"],["2510.92","835"],["2510.97","121"],["2510.98","0"],["2510.99","0"],["2511.01","0"],["2511.03","1132"],["2511.04","0"],["2511.06","2100"],["2511.10","870"],["2511.12","0"],["2511.13","1535"],["2511.14","587"],["2511.15","0"],["2511.16","0"],["2511.23","60"],["2511.25","0"],["2511.30","1359"],["2511.33","0"],["2511.34","2167"],["2511.44","0"],["2511.49","0"],["2511.52","1505"],["2511.56","0"],["2511.57","0"],["2511.59","0"],["2511.60","0"],["2511.61","1072"],["2511.62","0"],["2511.64","880"],["2511.68","1070"],["2511.73","0"],["2511.77","4445"],["2511.78","2306"],["2511.80","1981"],["2511.81","2803"],["2511.82","1529"],["2511.83","0"],["2511.85","2076"],["2511.95","0"],["2511.99","0"],["2512.02","0"],["2512.03","16746"],["2512.06","0"],["2512.08","0"],["2512.09","0"],["2512.14","1321"],["2512.15","0"],["2512.25","0"],["2512.29","0"],["2512.31","0"],["2512.35","0"],["2512.46","0"],["2512.51","0"],["2512.55","0"],["2512.61","0"],["2512.70","0"],["2512.83","1500"],["2512.96","0"],["2513.05","998"],["2513.06","0"],["2513.07","5180"],["2513.21","21899"],["2513.69","0"],["2513.70","1106"],["2513.71","105"],["2513.88","0"],["2514.38","2515"],["2514.39","21469"],["2514.57","0"],["2515.57","26837"],["2515.84","0"],["2516.76","32204"],["2516.84","0"],["2517.15","0"],["2518.91","0"],["2520.16","3550"],["2523.73","0"],["2530.32","0"],["2543.49","0"],["2635.21","0"],["2636.01","900"]]}}
1618677485.2714581: {"stream":"btcusd_perp@depth@100ms","data":{"e":"depthUpdate","E":1618677483529,"T":1618677483525,"s":"BTCUSD_PERP","ps":"BTCUSD","U":86143379783,"u":86143382983,"pu":86143379776,"b":[["57551.9","0"],["60501.3","0"],["60520.9","3124"],["60550.9","3748"],["60553.7","1"],["60555.4","2307"],["60558.6","0"],["60561.4","545"],["60562.0","80"],["60566.8","823"],["60567.6","1489"],["60569.5","172"],["60570.1","0"],["60570.4","9"],["60575.4","32"],["60575.5","0"],["60577.8","30"],["60581.0","11153"],["60581.2","0"],["60581.6","0"],["60581.8","0"],["60581.9","0"],["60582.0","360"],["60582.1","0"],["60582.3","0"],["60582.5","0"],["60582.7","0"],["60582.9","0"],["60583.0","0"],["60583.2","0"],["60583.4","0"],["60583.6","0"],["60583.8","0"],["60583.9","0"],["60584.1","0"],["60584.3","0"],["60584.5","0"],["60584.7","0"],["60584.9","0"],["60585.0","0"],["60585.2","0"],["60585.4","0"],["60585.5","0"],["60585.6","0"],["60585.7","0"],["60585.8","0"],["60585.9","0"],["60586.1","0"],["60586.2","0"],["60586.3","0"],["60586.4","0"],["60586.5","0"],["60586.7","0"],["60586.9","0"],["60587.0","0"],["60587.2","0"],["60587.4","0"],["60587.6","0"],["60587.8","0"],["60587.9","0"],["60588.1","0"],["60588.3","0"],["60588.5","0"],["60588.7","0"],["60588.9","0"],["60589.0","0"],["60589.2","0"],["60589.4","0"],["60589.6","0"],["60589.8","0"],["60589.9","0"],["60590.1","0"]],"a":[["60581.1","0"],["60582.1","1"],["60585.7","15"],["60588.2","0"],["60589.5","16"],["60589.9","0"],["60590.9","0"],["60591.0","0"],["60592.6","380"],["60594.3","25"],["60595.7","0"],["60596.0","96"],["60599.4","50"],["60599.8","0"],["60603.5","0"],["60604.6","30"],["60605.1","0"],["60605.3","30"],["60607.2","10"],["60607.9","50"],["60608.0","20"],["60608.9","122"],["60613.9","1927"],["60616.0","1658"],["60620.0","293"],["60621.1","0"],["60622.7","0"],["60625.6","0"],["60628.5","312"],["60632.8","0"],["60634.5","45"],["60634.8","0"],["60635.3","424"],["60636.4","2"],["60645.4","3061"],["60648.3","100"],["60660.6","0"],["60669.7","1010"],["60676.9","0"],["60677.0","2908"],["60677.6","501"],["60800.7","1821"]]}}
1618677485.2718039: {"stream":"ethusd_210924@depth@100ms","data":{"e":"depthUpdate","E":1618677483531,"T":1618677483525,"s":"ETHUSD_210924","ps":"ETHUSD","U":86143379917,"u":86143382955,"pu":86143379745,"b":[["2660.23","0"],["2665.60","0"],["2665.96","400"],["2668.44","405"],["2671.56","0"],["2671.97","0"],["2677.23","0"],["2678.77","250"],["2681.56","0"],["2682.90","0"],["2683.27","18207"],["2683.40","0"],["2683.75","0"],["2684.66","1200"],["2685.20","18571"],["2685.47","1168"],["2685.86","0"],["2685.89","0"],["2686.22","302"],["2686.68","48"],["2686.76","0"],["2686.77","0"],["2687.13","14201"],["2687.47","500"],["2687.48","204"],["2688.22","0"],["2688.23","0"],["2688.62","0"],["2688.64","0"],["2688.68","0"],["2688.69","0"],["2688.75","0"],["2688.76","0"],["2688.77","138"],["2688.79","0"],["2688.81","0"],["2688.83","0"],["2688.84","0"],["2688.85","1660"],["2688.87","431"],["2688.92","110"],["2689.72","0"]],"a":[["2688.69","0"],["2689.42","0"],["2689.73","274"],["2689.80","48"],["2690.01","2100"],["2690.68","0"],["2690.71","0"],["2690.86","0"],["2690.87","0"],["2690.98","14117"],["2691.72","0"],["2692.42","1680"],["2693.03","18461"],["2693.05","0"],["2694.38","0"],["2695.08","18099"],["2696.11","0"],["2697.44","0"],["2697.45","129"],["2697.90","0"],["2697.91","0"],["2701.57","0"],["2704.34","0"],["2712.38","0"],["2712.65","0"],["2713.61","40"],["2729.29","0"]]}}
1618677485.2721422: {"stream":"bchusd_210625@depth@100ms","data":{"e":"depthUpdate","E":1618677483534,"T":1618677483526,"s":"BCHUSD_210625","ps":"BCHUSD","U":86143380010,"u":86143382995,"pu":86143379652,"b":[["1063.83","0"],["1067.29","1905"],["1089.42","0"],["1092.13","1905"],["1102.21","0"],["1104.55","1905"],["1115.01","0"],["1116.46","400"],["1116.67","0"],["1116.98","1905"],["1118.92","519"],["1119.31","4299"],["1119.96","172"],["1121.23","3869"],["1122.77","0"],["1122.90","0"],["1123.16","3439"],["1123.17","1475"],["1123.44","286"],["1124.63","141"],["1124.70","173"],["1124.74","301"],["1124.84","0"],["1125.09","3611"],["1125.62","0"],["1125.77","0"],["1126.15","0"],["1126.46","0"],["1126.64","0"],["1127.02","3095"],["1127.04","671"],["1127.53","0"],["1127.59","35"],["1127.60","36"]],"a":[["1129.15","0"],["1129.38","0"],["1129.80","609"],["1129.81","2898"],["1131.61","3381"],["1131.97","0"],["1133.02","0"],["1133.39","0"],["1133.41","3220"],["1133.70","0"],["1134.05","1000"],["1135.21","4022"],["1135.22","519"],["1136.00","10"],["1137.02","4025"],["1137.44","1905"],["1139.24","190"],["1150.97","0"],["1151.73","1905"],["1165.95","0"],["1166.01","1905"],["1194.58","1905"],["1195.89","0"]]}}
1618677485.272518: {"stream":"dotusd_210625@depth@100ms","data":{"e":"depthUpdate","E":1618677483545,"T":1618677483541,"s":"DOTUSD_210625","ps":"DOTUSD","U":86143380311,"u":86143383399,"pu":86143380226,"b":[["46.199","480"],["46.480","0"],["46.703","12"],["46.707","0"],["46.722","0"],["46.732","0"],["46.733","0"],["46.735","0"],["46.736","0"],["46.738","0"],["46.740","0"],["46.741","0"],["46.742","244"],["46.743","293"],["46.744","640"],["46.745","255"],["46.746","30"],["46.747","688"],["46.990","0"]],"a":[["46.787","0"],["46.788","42"],["46.789","0"],["46.798","0"],["46.806","41"],["46.807","192"],["46.813","44"],["46.814","0"],["46.829","0"],["46.830","0"],["46.835","170"],["46.848","133"],["46.868","197"],["46.880","0"],["46.887","1000"],["46.891","0"],["46.956","0"],["46.960","110"],["46.993","668"],["47.096","321"],["47.134","0"],["47.161","0"],["47.169","1000"],["47.197","280"]]}}
1618677485.272734: {"stream":"linkusd_210625@depth@100ms","data":{"e":"depthUpdate","E":1618677483562,"T":1618677483555,"s":"LINKUSD_210625","ps":"LINKUSD","U":86143380686,"u":86143383880,"pu":86143380472,"b":[["43.395","290"],["43.470","0"],["43.546","0"],["43.578","227"],["43.621","0"],["43.622","0"],["43.654","1000"],["43.698","0"],["43.699","0"],["43.740","0"],["43.754","498"],["43.755","126"],["43.756","0"],["43.757","0"],["43.759","0"],["43.762","100"],["43.764","100"]],"a":[["43.777","51"],["43.779","0"],["43.792","100"],["43.794","0"],["43.816","88"],["43.842","107"],["43.846","0"],["43.847","0"],["43.848","0"],["43.854","326"],["43.858","1221"],["43.869","0"],["43.888","0"],["43.933","630"],["43.944","0"],["43.994","20"],["44.019","0"],["44.094","0"]]}}
1618677485.273036: {"stream":"xrpusd_210625@depth@100ms","data":{"e":"depthUpdate","E":1618677483568,"T":1618677483544,"s":"XRPUSD_210625","ps":"XRPUSD","U":86143380827,"u":86143383581,"pu":86143378924,"b":[["1.6735","0"],["1.6751","2377"],["1.6798","0"],["1.6800","204"],["1.6825","0"],["1.6843","1601"],["1.6887","249"],["1.6891","98"],["1.6892","629"],["1.6893","282"],["1.6896","0"],["1.6897","0"]],"a":[["1.6912","0"],["1.6920","48"],["1.6922","0"],["1.6927","45"],["1.6928","95"],["1.6929","12"],["1.6934","95"],["1.6936","254"],["1.6937","1212"],["1.6939","210"],["1.6947","805"],["1.6949","413"],["1.6959","651"],["1.6962","0"],["1.6978","3680"],["1.6984","173"],["1.7001","40"]]}}
1618677485.2733629: {"stream":"btcusd_210924@depth@100ms","data":{"e":"depthUpdate","E":1618677483597,"T":1618677483585,"s":"BTCUSD_210924","ps":"BTCUSD","U":86143381924,"u":86143384832,"pu":86143381394,"b":[["68580.6","30"],["68585.5","0"],["68590.8","10"],["68616.1","0"],["68620.2","43"],["68622.0","0"],["68623.0","0"],["68624.0","0"],["68624.1","90"],["68627.5","0"],["68627.6","0"],["68630.0","10"],["68631.0","10"],["68631.9","261"],["68632.0","555"]],"a":[["68624.1","0"],["68632.0","0"],["68632.1","175"],["68638.5","20"],["68638.6","0"],["68652.2","63"],["68661.0","0"],["68661.1","0"],["68677.4","809"],["68687.4","0"],["68716.4","0"],["68722.8","0"],["68740.3","251"]]}}
1618677485.273512: {"stream":"egldusd_perp@depth@100ms","data":{"e":"depthUpdate","E":1618677483608,"T":1618677483595,"s":"EGLDUSD_PERP","ps":"EGLDUSD","U":86143382302,"u":86143385159,"pu":86143381024,"b":[["215.720","0"],["215.958","10"]],"a":[["216.305","487"],["216.307","0"],["216.399","48"],["216.468","0"],["216.505","0"]]}}
1618677485.2737238: {"stream":"linkusd_210924@depth@100ms","data":{"e":"depthUpdate","E":1618677483623,"T":1618677483612,"s":"LINKUSD_210924","ps":"LINKUSD","U":86143382741,"u":86143385844,"pu":86143381852,"b":[["44.545","400"],["44.956","412"],["45.198","371"]],"a":[["45.366","54"],["45.384","0"],["45.390","250"],["45.392","0"],["45.396","0"],["45.440","1765"],["45.455","250"]]}}
1618677485.273802: {"stream":"ethusd_210924@depth@100ms","data":{"e":"depthUpdate","E":1618677483634,"T":1618677483625,"s":"ETHUSD_210924","ps":"ETHUSD","U":86143383065,"u":86143386279,"pu":86143382955,"b":[["2661.36","1687"],["2665.96","0"],["2665.98","0"],["2672.78","1687"],["2673.27","500"],["2674.14","500"],["2678.49","1687"],["2678.77","0"],["2684.20","1687"],["2684.94","0"],["2685.21","460"],["2685.47","0"],["2686.22","0"],["2686.58","0"],["2686.59","0"],["2686.75","0"],["2687.14","2983"],["2688.69","2100"],["2688.70","441"],["2688.77","0"],["2688.85","0"],["2688.86","0"],["2688.87","0"],["2688.88","0"],["2688.89","0"],["2688.92","0"],["2688.93","2100"],["2688.94","0"],["2688.95","0"],["2688.97","581"],["2689.00","0"],["2689.01","0"],["2689.02","0"],["2689.03","0"],["2689.08","0"],["2689.09","185"],["2689.16","0"],["2689.17","660"],["2689.22","1000"],["2689.57","100"],["2689.64","0"]],"a":[["2688.93","0"],["2689.01","0"],["2689.02","0"],["2689.10","0"],["2689.58","400"],["2689.66","0"],["2689.73","0"],["2690.01","0"],["2691.10","487"],["2691.65","2100"],["2693.02","3878"],["2695.04","0"],["2695.46","266"],["2695.88","460"],["2697.44","1687"],["2699.49","267"],["2700.62","0"],["2700.79","0"],["2704.21","0"],["2705.80","1687"],["2714.18","1687"],["2730.93","1687"]]}}
1618677485.27421: {"stream":"dotusd_210625@depth@100ms","data":{"e":"depthUpdate","E":1618677483646,"T":1618677483642,"s":"DOTUSD_210625","ps":"DOTUSD","U":86143383422,"u":86143386849,"pu":86143383399,"b":[["46.212","40"],["46.563","0"],["46.625","502"],["46.673","3"],["46.693","0"],["46.738","153"],["46.742","1"],["46.743","1463"],["46.744","166"],["46.745","0"],["46.746","0"],["46.747","8"],["46.748","206"],["46.749","34"],["46.750","540"],["46.751","119"],["46.752","177"],["46.753","100"],["46.754","540"]],"a":[["46.788","0"],["46.805","3"],["46.812","0"],["46.813","0"],["46.814","0"],["46.833","222"],["46.834","1094"],["46.835","0"],["46.845","0"],["46.849","685"],["46.858","0"],["46.870","0"],["46.876","0"],["46.887","0"],["46.914","140"],["46.915","1000"],["46.918","1131"],["46.961","0"],["46.965","0"],["46.980","40"],["46.984","0"],["46.993","1069"],["47.015","1625"],["47.024","0"],["47.055","789"],["47.056","0"],["47.063","0"],["47.068","465"],["47.096","141"],["47.115","1026"],["47.120","502"],["47.131","50"],["47.169","0"],["47.196","1000"],["47.256","1447"]]}}
1618677485.274241: {"stream":"bchusd_210625@depth@100ms","data":{"e":"depthUpdate","E":1618677483647,"T":1618677483640,"s":"BCHUSD_210625","ps":"BCHUSD","U":86143383552,"u":86143386794,"pu":86143382995,"b":[["1120.21","190"],["1120.35","85"],["1121.59","0"],["1124.63","0"],["1124.86","141"],["1126.10","85"],["1127.54","0"],["1127.59","0"],["1127.60","0"],["1127.61","64"],["1127.62","34"]],"a":[["1128.52","0"],["1128.56","0"],["1129.32","0"],["1129.83","0"],["1131.01","0"],["1131.74","115"],["1132.42","0"],["1133.98","40"],["1135.90","175"]]}}
1618677485.27439: {"stream":"btcusd_perp@depth@100ms","data":{"e":"depthUpdate","E":1618677483649,"T":1618677483609,"s":"BTCUSD_PERP","ps":"BTCUSD","U":86143382998,"u":86143385710,"pu":86143382983,"b":[["60502.5","80"],["60503.0","4"],["60523.0","8500"],["60542.6","8"],["60548.8","0"],["60555.4","276"],["60559.4","0"],["60561.2","8"],["60562.0","120"],["60562.2","2031"],["60563.3","0"],["60564.6","1180"],["60566.0","364"],["60567.0","0"],["60567.1","1"],["60568.7","179"],["60569.5","50"],["60569.9","79"],["60570.4","17"],["60571.2","0"],["60571.4","243"],["60571.6","340"],["60572.3","79"],["60572.9","79"],["60573.1","1"],["60573.5","50"],["60574.5","0"],["60574.6","0"],["60575.4","0"],["60575.7","15"],["60576.3","0"],["60577.8","0"],["60578.6","0"],["60579.1","1"],["60580.4","0"],["60580.9","30"],["60581.0","3901"],["60581.1","117"],["60581.2","0"],["60581.3","0"],["60582.0","3060"],["60582.1","782"],["60582.2","180"],["60582.3","180"],["60582.4","0"],["60582.5","180"],["60582.6","180"],["60582.7","360"],["60582.8","0"],["60582.9","603"],["60583.0","0"],["60583.1","360"],["60583.2","0"],["60583.3","0"],["60583.4","180"],["60583.5","180"],["60583.6","6859"],["60583.7","732"],["60583.8","180"],["60583.9","180"],["60584.0","940"],["60584.1","354"],["60584.2","180"],["60584.3","180"],["60584.4","180"],["60584.5","180"],["60584.6","180"],["60584.7","180"],["60584.8","180"],["60584.9","180"],["60585.0","0"],["60585.1","0"],["60585.2","180"],["60585.3","360"],["60585.4","0"],["60585.5","420"],["60585.6","380"],["60585.7","540"],["60585.8","180"],["60585.9","0"],["60586.0","5769"],["60586.1","460"],["60586.2","520"],["60586.3","360"],["60586.4","0"],["60586.5","360"],["60586.6","0"],["60586.7","180"],["60586.8","0"],["60586.9","180"],["60587.0","1007"],["60587.1","180"],["60587.3","516"],["60587.5","360"],["60587.7","180"],["60587.8","180"],["60587.9","180"],["60588.1","210"],["60588.2","180"],["60588.3","360"],["60588.5","360"],["60588.7","180"],["60588.8","940"],["60588.9","180"],["60589.1","107"],["60589.3","0"],["60589.4","107"],["60589.5","9886"],["60589.7","0"],["60589.9","0"],["60590.1","0"],["60590.3","0"],["60590.5","0"],["60590.7","0"],["60590.9","0"],["60591.1","0"],["60591.3","0"],["60591.5","0"],["60591.7","0"],["60591.9","0"],["60641.7","0"]],"a":[["60573.0","0"],["60573.2","0"],["60573.3","0"],["60573.5","0"],["60573.7","0"],["60573.9","0"],["60574.1","0"],["60574.2","0"],["60574.4","0"],["60574.6","0"],["60574.8","0"],["60575.0","0"],["60575.2","0"],["60575.3","0"],["60575.4","0"],["60575.5","0"],["60575.6","0"],["60575.7","0"],["60575.8","0"],["60575.9","0"],["60576.0","0"],["60576.1","0"],["60576.2","0"],["60576.4","0"],["60576.6","0"],["60576.7","0"],["60576.8","0"],["60576.9","0"],["60577.0","0"],["60577.2","0"],["60577.3","0"],["60577.4","0"],["60577.5","0"],["60577.6","0"],["60577.7","0"],["60577.8","0"],["60577.9","0"],["60578.0","0"],["60578.1","0"],["60578.2","0"],["60578.4","0"],["60578.5","0"],["60578.6","0"],["60578.8","0"],["60579.0","0"],["60579.2","0"],["60579.3","0"],["60579.4","0"],["60579.5","0"],["60579.6","0"],["60579.7","0"],["60579.9","0"],["60580.1","0"],["60580.2","0"],["60580.4","0"],["60580.6","0"],["60580.7","0"],["60580.8","0"],["60580.9","0"],["60581.0","0"],["60581.1","0"],["60581.2","0"],["60581.3","0"],["60581.4","0"],["60581.5","0"],["60581.6","0"],["60581.7","0"],["60581.8","0"],["60581.9","0"],["60582.0","0"],["60582.1","0"],["60582.2","0"],["60582.3","0"],["60582.4","0"],["60582.6","0"],["60582.7","0"],["60582.8","0"],["60583.0","0"],["60583.2","0"],["60583.3","0"],["60583.4","0"],["60583.5","0"],["60583.6","0"],["60583.7","0"],["60583.9","0"],["60584.1","0"],["60584.2","0"],["60584.3","0"],["60584.4","0"],["60584.6","0"],["60584.8","0"],["60585.0","0"],["60585.2","0"],["60585.3","0"],["60585.5","0"],["60585.6","0"],["60585.7","0"],["60585.8","0"],["60586.0","0"],["60586.1","0"],["60586.3","0"],["60586.9","0"],["60587.1","0"],["60587.3","0"],["60587.6","0"],["60589.5","0"],["60589.6","120"],["60590.1","100"],["60590.3","15"],["60592.6","260"],["60593.5","0"],["60594.5","40"],["60595.2","0"],["60595.5","0"],["60596.1","0"],["60596.7","160"],["60599.9","13"],["60604.6","10"],["60605.3","0"],["60608.9","0"],["60609.4","30"],["60611.5","20"],["60620.0","50"],["60622.0","243"],["60622.5","1555"],["60630.5","8"],["60634.8","0"],["60635.3","181"],["60636.1","9"],["60636.7","251"],["60637.3","0"],["60638.4","243"],["60651.2","0"],["60656.4","1"],["60657.6","307"],["60703.8","0"],["60708.3","1100"],["60796.5","1788"],["60815.8","1789"],["60818.9","0"],["60843.2","0"]]}}
1618677485.275081: {"stream":"ethusd_210625@depth@100ms","data":{"e":"depthUpdate","E":1618677483649,"T":1618677483609,"s":"ETHUSD_210625","ps":"ETHUSD","U":86143382621,"u":86143385706,"pu":86143382512,"b":[["2489.59","3375"],["2498.76","3375"],["2503.34","3375"],["2504.71","380"],["2504.82","3036"],["2504.94","3036"],["2505.00","0"],["2505.05","3253"],["2505.32","3470"],["2505.49","0"],["2505.59","1690"],["2505.69","2602"],["2505.70","2819"],["2505.86","0"],["2505.89","3036"],["2506.17","2386"],["2506.31","2168"],["2506.34","1982"],["2506.37","1982"],["2506.49","1321"],["2506.50","1952"],["2506.55","1735"],["2506.62","2169"],["2506.64","1952"],["2506.66","1321"],["2506.69","1952"],["2506.72","880"],["2506.74","2525"],["2506.75","1735"],["2506.79","1321"],["2506.80","1518"],["2506.82","880"],["2506.83","0"],["2506.86","880"],["2506.88","3235"],["2506.95","1518"],["2507.05","1517"],["2507.18","2239"],["2507.33","1301"],["2507.35","1084"],["2507.46","1301"],["2507.54","1084"],["2507.66","1301"],["2507.93","3375"],["2508.10","0"],["2508.11","0"],["2508.47","920"],["2508.89","60"],["2509.59","0"],["2509.60","0"],["2509.61","2493"],["2509.69","0"],["2509.70","2505"],["2509.80","0"],["2509.81","2917"],["2510.03","0"],["2510.04","0"],["2510.06","422"],["2510.11","2299"],["2510.12","442"],["2510.18","1203"],["2510.21","273"],["2510.30","0"],["2510.40","0"],["2510.41","0"],["2510.45","315"],["2510.56","1743"],["2510.58","0"]],"a":[["2510.56","0"],["2510.57","1393"],["2510.59","0"],["2510.66","0"],["2510.68","0"],["2510.97","0"],["2511.06","0"],["2511.12","54"],["2511.13","0"],["2511.24","0"],["2511.41","0"],["2511.44","2027"],["2511.46","1204"],["2511.48","2030"],["2511.56","1084"],["2511.62","1518"],["2511.63","1084"],["2511.66","0"],["2511.74","0"],["2511.76","1073"],["2511.77","3993"],["2511.78","0"],["2511.80","1301"],["2511.81","0"],["2511.84","1735"],["2511.85","0"],["2511.89","1518"],["2511.90","1517"],["2511.96","1735"],["2512.02","2398"],["2512.11","1301"],["2512.12","1301"],["2512.14","0"],["2512.17","1735"],["2512.19","0"],["2512.22","1951"],["2512.24","121"],["2512.28","3469"],["2512.44","1952"],["2512.49","1952"],["2512.54","1518"],["2512.55","1952"],["2512.60","0"],["2512.61","2168"],["2512.66","2100"],["2512.92","2168"],["2512.96","2168"],["2513.09","2168"],["2513.16","0"],["2513.23","2385"],["2513.26","2602"],["2513.27","2385"],["2513.51","2819"],["2513.60","2602"],["2513.63","5421"],["2513.68","1798"],["2513.69","2602"],["2513.74","2602"],["2513.75","5854"],["2513.76","3035"],["2513.77","2819"],["2513.95","2819"],["2514.09","3252"],["2514.21","3470"],["2514.22","3036"],["2514.48","3253"],["2514.57","500"],["2515.67","9388"],["2517.05","920"],["2518.37","3375"],["2525.03","3375"],["2528.07","5123"],["2531.69","3375"],["2545.01","3375"],["2576.06","0"],["2577.48","1000"]]}}
1618677485.2758741: {"stream":"linkusd_210625@depth@100ms","data":{"e":"depthUpdate","E":1618677483672,"T":1618677483650,"s":"LINKUSD_210625","ps":"LINKUSD","U":86143384273,"u":86143387028,"pu":86143383880,"b":[["43.519","0"],["43.535","100"],["43.594","20"],["43.715","0"],["43.731","100"],["43.763","23"],["43.765","43"],["43.766","0"],["43.767","0"]],"a":[["43.777","50"],["43.783","50"],["43.785","0"],["43.858","0"],["43.859","0"],["43.868","1313"],["43.872","0"],["43.948","180"]]}}
1618677485.276172: {"stream":"xrpusd_210625@depth@100ms","data":{"e":"depthUpdate","E":1618677483692,"T":1618677483686,"s":"XRPUSD_210625","ps":"XRPUSD","U":86143384906,"u":86143387825,"pu":86143383581,"b":[["1.6800","54"],["1.6806","100"],["1.6858","55"],["1.6859","306"],["1.6893","134"],["1.6894","0"],["1.6895","0"],["1.6899","626"],["1.6900","132"]],"a":[["1.6921","12"],["1.6927","0"],["1.6928","45"],["1.6967","0"]]}}
1618677485.276362: {"stream":"btcusd_210924@depth@100ms","data":{"e":"depthUpdate","E":1618677483700,"T":1618677483696,"s":"BTCUSD_210924","ps":"BTCUSD","U":86143385124,"u":86143388004,"pu":86143384832,"b":[["68141.2","4993"],["68388.6","0"],["68539.0","0"],["68576.6","0"],["68591.9","0"],["68597.2","303"],["68624.1","90"],["68631.9","124"],["68632.0","745"],["68632.1","0"],["68635.5","0"],["68638.4","0"]],"a":[["68632.1","10"],["68638.5","0"],["68650.5","20"],["68655.9","100"],["68677.3","175"],["68687.3","0"],["68780.6","422"],["68818.7","3134"],["68870.4","0"],["68904.7","0"],["69247.0","0"],["69260.1","138"]]}}
1618677485.2764668: {"stream":"egldusd_perp@depth@100ms","data":{"e":"depthUpdate","E":1618677483711,"T":1618677483647,"s":"EGLDUSD_PERP","ps":"EGLDUSD","U":86143385674,"u":86143386984,"pu":86143385159,"b":[["216.077","170"]],"a":[["216.306","0"],["216.399","0"],["216.468","18"],["216.504","0"]]}}
1618677485.2766788: {"stream":"ethusd_210924@depth@100ms","data":{"e":"depthUpdate","E":1618677483734,"T":1618677483727,"s":"ETHUSD_210924","ps":"ETHUSD","U":86143386514,"u":86143388564,"pu":86143386279,"b":[["2666.29","100"],["2666.77","480"],["2681.48","0"],["2682.96","1000"],["2686.56","100"],["2687.15","1209"],["2688.93","0"],["2689.03","0"],["2689.04","0"],["2689.09","0"],["2689.17","0"],["2689.22","0"],["2689.23","0"],["2689.40","1000"],["2689.57","3014"],["2689.64","185"],["2689.79","231"]],"a":[["2689.58","0"],["2690.69","0"],["2691.61","0"],["2692.32","0"],["2693.13","1000"],["2694.43","0"],["2695.46","732"],["2697.72","8301"],["2697.93","0"],["2698.15","652"],["2701.05","1871"]]}}
1618677485.276812: {"stream":"linkusd_210924@depth@100ms","data":{"e":"depthUpdate","E":1618677483740,"T":1618677483729,"s":"LINKUSD_210924","ps":"LINKUSD","U":86143386719,"u":86143388682,"pu":86143385844,"b":[["44.496","0"],["45.085","500"],["45.113","0"]],"a":[["45.308","0"],["45.309","24"],["45.385","0"],["45.390","0"],["45.406","96"],["45.419","500"],["45.445","0"],["45.451","0"],["45.520","600"],["45.528","0"],["45.880","0"],["45.914","500"],["45.939","0"],["45.946","0"],["46.015","600"]]}}
1618677485.2768698: {"stream":"dotusd_210625@depth@100ms","data":{"e":"depthUpdate","E":1618677483746,"T":1618677483740,"s":"DOTUSD_210625","ps":"DOTUSD","U":86143386857,"u":86143388892,"pu":86143386849,"b":[["46.714","0"],["46.738","0"],["46.744","0"],["46.745","1183"],["46.746","0"],["46.747","0"],["46.748","0"],["46.749","0"],["46.750","0"],["46.751","0"],["46.752","0"],["46.753","0"],["46.754","540"],["46.755","125"],["46.756","1000"],["46.757","540"],["46.758","0"],["46.772","50"],["46.773","0"],["46.774","30"],["46.775","0"]],"a":[["46.805","0"],["46.806","0"],["46.815","0"],["46.816","0"],["46.832","21"],["46.835","170"],["46.845","0"],["46.849","635"],["46.867","250"],["46.892","0"],["46.908","0"],["46.914","0"],["46.993","668"],["47.015","141"],["47.131","0"],["47.149","180"],["47.256","2830"]]}}
1618677485.2770371: {"stream":"bchusd_210625@depth@100ms","data":{"e":"depthUpdate","E":1618677483763,"T":1618677483756,"s":"BCHUSD_210625","ps":"BCHUSD","U":86143387162,"u":86143389261,"pu":86143386794,"b":[["1114.63","0"],["1115.23","1000"],["1116.46","0"],["1117.08","0"],["1117.31","200"],["1117.32","630"],["1122.69","0"],["1122.70","196"],["1123.17","0"],["1123.29","1000"],["1123.31","1476"],["1124.86","0"],["1125.49","141"]],"a":[["1128.81","0"],["1129.11","0"],["1129.37","0"],["1129.44","57"],["1129.81","2910"],["1138.56","1693"],["1138.57","0"],["1139.23","0"]]}}
1618677485.277162: {"stream":"btcusd_perp@depth@100ms","data":{"e":"depthUpdate","E":1618677483763,"T":1618677483743,"s":"BTCUSD_PERP","ps":"BTCUSD","U":86143385727,"u":86143388993,"pu":86143385710,"b":[["15555.0","1"],["60434.8","44"],["60442.0","0"],["60443.9","44"],["60450.5","500"],["60490.3","120"],["60490.5","388"],["60498.7","0"],["60498.8","544"],["60502.5","3"],["60503.5","0"],["60504.0","0"],["60505.5","1578"],["60506.0","77"],["60506.5","77"],["60520.6","1010"],["60557.0","0"],["60562.0","0"],["60562.2","0"],["60563.8","0"],["60564.3","485"],["60564.4","0"],["60566.5","2039"],["60567.6","1489"],["60567.9","120"],["60568.7","100"],["60569.9","0"],["60570.2","0"],["60570.3","0"],["60570.5","80"],["60571.0","739"],["60571.4","0"],["60571.9","243"],["60572.0","122"],["60572.3","0"],["60574.1","0"],["60575.2","200"],["60577.0","0"],["60577.7","0"],["60578.0","0"],["60579.0","0"],["60579.1","0"],["60580.9","0"],["60581.0","3546"],["60581.1","0"],["60581.4","0"],["60582.0","2010"],["60582.1","0"],["60582.2","40"],["60582.3","0"],["60582.5","0"],["60582.6","0"],["60582.7","0"],["60582.8","1"],["60582.9","0"],["60583.1","0"],["60583.2","30"],["60583.4","0"],["60583.5","0"],["60583.6","2247"],["60583.7","153"],["60583.8","0"],["60583.9","0"],["60584.0","0"],["60584.1","0"],["60584.2","0"],["60584.3","0"],["60584.4","0"],["60584.5","0"],["60584.6","0"],["60584.7","243"],["60584.8","0"],["60584.9","0"],["60585.2","0"],["60585.3","0"],["60585.5","0"],["60585.6","0"],["60585.7","0"],["60585.8","0"],["60586.0","0"],["60586.1","100"],["60586.2","0"],["60586.3","0"],["60586.5","0"],["60586.6","243"],["60586.7","0"],["60586.9","0"],["60587.0","96"],["60587.1","0"],["60587.2","647"],["60587.3","0"],["60587.4","130"],["60587.5","199"],["60587.7","0"],["60587.8","0"],["60587.9","0"],["60588.0","96"],["60588.1","30"],["60588.2","0"],["60588.3","0"],["60588.5","0"],["60588.7","0"],["60588.8","0"],["60588.9","0"],["60589.0","142"],["60589.1","0"],["60589.2","0"],["60589.4","0"],["60589.5","9468"],["60589.6","0"],["60589.7","0"],["60589.8","0"],["60589.9","0"],["60590.0","0"],["60590.1","0"],["60590.2","0"],["60590.3","0"],["60590.4","0"],["60590.6","0"],["60590.8","0"],["60591.0","0"],["60591.2","0"],["60591.4","0"],["60591.5","0"],["60591.6","0"],["60591.7","0"],["60591.8","0"],["60591.9","0"],["60592.0","0"],["60592.1","0"],["60592.2","0"],["60592.3","0"],["60592.4","0"],["60592.6","0"],["60592.8","0"],["60593.0","0"],["60593.2","0"],["60593.4","0"],["60593.5","0"],["60593.6","0"],["60593.7","0"],["60593.8","0"],["60593.9","0"],["60594.0","0"],["60594.1","0"],["60594.2","0"],["60594.3","0"],["60594.4","0"],["60594.6","0"],["60594.7","0"],["60594.8","0"],["60594.9","0"],["60595.0","0"],["60595.2","0"],["60595.4","0"],["60595.5","0"],["60595.6","0"],["60595.7","0"],["60595.8","0"],["60595.9","0"],["60596.0","0"],["60596.1","0"],["60596.2","0"],["60596.3","0"],["60596.4","0"],["60596.6","0"],["60596.8","0"],["60597.0","0"],["60597.2","0"],["60597.4","0"],["60597.5","0"],["60597.7","0"],["60597.9","0"],["60598.1","0"],["60598.3","0"],["60598.4","0"],["60598.6","0"]],"a":[["60580.2","0"],["60580.8","0"],["60581.1","0"],["60581.3","0"],["60581.5","0"],["60581.7","0"],["60581.9","0"],["60582.3","0"],["60582.7","0"],["60582.8","0"],["60582.9","0"],["60583.1","0"],["60583.2","0"],["60583.5","0"],["60583.7","0"],["60583.9","0"],["60585.9","0"],["60586.3","0"],["60586.5","0"],["60586.7","0"],["60586.9","0"],["60587.1","0"],["60587.3","0"],["60587.7","0"],["60587.9","0"],["60588.3","0"],["60588.5","0"],["60589.4","0"],["60589.5","0"],["60589.6","498"],["60589.9","30"],["60590.0","0"],["60590.3","0"],["60592.1","0"],["60593.2","0"],["60593.9","1"],["60594.5","0"],["60596.0","0"],["60596.7","10"],["60598.0","15"],["60598.2","202"],["60599.1","218"],["60599.5","0"],["60599.9","13"],["60600.5","100"],["60601.0","96"],["60601.2","5"],["60602.3","50"],["60603.8","80"],["60604.2","0"],["60604.6","0"],["60606.7","0"],["60608.6","0"],["60609.4","0"],["60610.8","0"],["60611.5","40"],["60612.2","0"],["60615.2","0"],["60615.4","0"],["60620.4","721"],["60622.0","0"],["60622.5","330"],["60624.3","295"],["60624.7","243"],["60628.5","0"],["60636.7","8"],["60637.6","0"],["60638.4","0"],["60639.6","0"],["60647.5","1225"],["60647.7","2108"],["60671.9","106"],["60720.4","0"],["60795.9","1821"],["60812.2","1821"],["60833.6","1821"]]}}
1618677485.2778602: {"stream":"ethusd_210625@depth@100ms","data":{"e":"depthUpdate","E":1618677483764,"T":1618677483744,"s":"ETHUSD_210625","ps":"ETHUSD","U":86143385738,"u":86143389042,"pu":86143385706,"b":[["2504.51","0"],["2504.65","3470"],["2504.91","0"],["2505.08","3036"],["2505.20","2819"],["2505.28","2819"],["2505.35","3253"],["2505.85","5204"],["2505.87","2819"],["2506.01","0"],["2506.04","0"],["2506.06","2386"],["2506.09","2602"],["2506.16","2169"],["2506.17","4772"],["2506.31","4337"],["2506.35","1952"],["2506.55","2322"],["2506.61","1982"],["2506.64","2539"],["2506.67","2386"],["2506.68","1982"],["2506.75","2322"],["2506.76","391"],["2507.00","0"],["2507.04","587"],["2507.05","3035"],["2509.18","1250"],["2509.61","0"],["2509.81","0"],["2510.07","0"],["2510.11","2000"],["2510.22","1307"],["2510.31","0"],["2510.44","0"],["2510.45","0"],["2510.53","210"],["2510.56","1823"],["2510.58","0"]],"a":[["2510.63","0"],["2510.71","1072"],["2510.78","0"],["2510.79","1070"],["2510.81","0"],["2510.88","121"],["2510.99","527"],["2511.00","100"],["2511.12","0"],["2511.14","0"],["2511.28","0"],["2511.36","0"],["2511.39","0"],["2511.41","0"],["2511.44","0"],["2511.47","0"],["2511.48","0"],["2511.59","1052"],["2511.61","0"],["2511.68","1194"],["2511.76","1073"],["2512.19","1535"],["2512.24","0"],["2512.90","1982"],["2513.16","1321"],["2513.21","23220"],["2513.27","4367"],["2513.29","2386"],["2513.53","1321"],["2514.00","1994"],["2514.08","1982"],["2514.65","189"],["2514.90","2988"],["2517.78","2101"],["2529.15","4804"]]}}
1618677485.2781599: {"stream":"linkusd_210625@depth@100ms","data":{"e":"depthUpdate","E":1618677483773,"T":1618677483759,"s":"LINKUSD_210625","ps":"LINKUSD","U":86143387461,"u":86143389323,"pu":86143387028,"b":[["43.444","344"],["43.475","1000"],["43.480","5925"],["43.544","5721"],["43.565","0"],["43.608","4147"],["43.672","4266"],["43.697","250"],["43.705","0"],["43.714","0"],["43.733","0"],["43.737","3555"],["43.738","746"],["43.767","0"]],"a":[["43.775","0"],["43.777","0"],["43.778","0"],["43.783","0"],["43.784","0"],["43.785","50"],["43.786","1"],["43.797","13"],["43.814","94"],["43.815","439"],["43.816","236"],["43.817","3242"],["43.832","24"],["43.854","23"],["43.872","3383"],["43.873","0"],["43.928","3289"],["43.948","0"],["43.983","4404"],["44.039","4800"]]}}
1618677485.278341: {"stream":"xrpusd_210625@depth@100ms","data":{"e":"depthUpdate","E":1618677483792,"T":1618677483786,"s":"XRPUSD_210625","ps":"XRPUSD","U":86143387866,"u":86143389858,"pu":86143387825,"b":[["1.6796","0"],["1.6823","0"],["1.6848","786"],["1.6849","0"],["1.6850","0"],["1.6878","470"],["1.6890","0"],["1.6896","101"],["1.6900","260"],["1.6901","26"],["1.6902","0"]],"a":[["1.6915","12"],["1.6924","352"],["1.6936","356"],["1.6957","0"],["1.6965","120"],["1.6975","20216"],["1.7038","80"]]}}
1618677485.278451: {"stream":"btcusd_210924@depth@100ms","data":{"e":"depthUpdate","E":1618677483800,"T":1618677483790,"s":"BTCUSD_210924","ps":"BTCUSD","U":86143388026,"u":86143389910,"pu":86143388004,"b":[["68134.0","0"],["68142.6","60"],["68460.0","3572"],["68534.9","4220"],["68560.9","261"],["68584.3","0"],["68590.6","0"],["68597.0","0"],["68599.3","60"],["68609.9","2657"],["68610.0","578"],["68620.2","0"],["68624.2","202"]],"a":[["68654.5","0"],["68667.1","0"],["68667.2","50"],["68674.8","0"],["68679.5","490"],["68679.6","2331"],["68697.0","354"],["68697.1","1619"],["68699.3","0"],["68712.9","30"],["68749.1","3702"],["68780.6","0"],["68789.4","0"],["68821.9","476"],["68856.3","477"]]}}
1618677485.278534: {"stream":"egldusd_perp@depth@100ms","data":{"e":"depthUpdate","E":1618677483813,"T":1618677483805,"s":"EGLDUSD_PERP","ps":"EGLDUSD","U":86143388267,"u":86143390201,"pu":86143386984,"b":[["215.957","0"],["216.044","97"],["216.057","0"],["216.067","0"],["216.087","54"]],"a":[["216.182","0"],["216.399","39"],["216.468","0"]]}}
1618677485.2787: {"stream":"ethusd_210924@depth@100ms","data":{"e":"depthUpdate","E":1618677483834,"T":1618677483826,"s":"ETHUSD_210924","ps":"ETHUSD","U":86143388701,"u":86143390557,"pu":86143388564,"b":[["2666.29","0"],["2666.61","350"],["2677.33","0"],["2679.29","250"],["2680.35","1000"],["2684.87","150"],["2686.56","0"],["2686.88","302"],["2687.47","0"],["2687.48","0"],["2688.98","500"],["2689.40","0"],["2689.57","2200"],["2689.58","0"],["2689.60","1000"],["2689.64","0"],["2689.74","0"],["2689.79","891"]],"a":[["2689.73","0"],["2689.80","418"],["2690.26","150"],["2690.97","430"],["2691.01","0"],["2692.22","1200"],["2693.01","1292"],["2695.89","0"],["2697.90","2400"]]}}
1618677485.27887: {"stream":"dotusd_210625@depth@100ms","data":{"e":"depthUpdate","E":1618677483849,"T":1618677483844,"s":"DOTUSD_210625","ps":"DOTUSD","U":86143389035,"u":86143390799,"pu":86143388892,"b":[["45.571","0"],["45.634","1960"],["46.020","0"],["46.073","1960"],["46.245","0"],["46.292","1960"],["46.469","0"],["46.511","1960"],["46.513","0"],["46.517","1699"],["46.520","448"],["46.554","534"],["46.572","528"],["46.632","0"],["46.681","137"],["46.745","0"],["46.754","0"],["46.755","0"],["46.757","0"],["46.758","0"],["46.772","50"],["46.773","0"],["46.774","0"],["46.775","63"],["46.776","0"]],"a":[["46.803","256"],["46.804","1200"],["46.805","540"],["46.816","0"],["46.826","0"],["46.835","0"],["46.845","200"],["46.849","685"],["46.867","0"],["46.907","0"],["46.915","0"],["46.922","0"],["46.941","534"],["46.950","1000"],["46.962","0"],["46.985","0"],["46.997","1960"],["47.027","1200"],["47.033","448"],["47.130","50"],["47.149","0"],["47.196","0"],["47.232","1000"],["47.257","0"],["47.290","1960"],["47.552","4453"],["47.584","1960"],["48.142","0"],["48.170","1960"]]}}
1618677485.27891: {"stream":"linkusd_210924@depth@100ms","data":{"e":"depthUpdate","E":1618677483854,"T":1618677483776,"s":"LINKUSD_210924","ps":"LINKUSD","U":86143389068,"u":86143389683,"pu":86143388682,"b":[["45.207","40"]],"a":[["45.332","124"],["45.333","593"],["45.454","3530"]]}}
1618677485.279001: {"stream":"btcusd_perp@depth@100ms","data":{"e":"depthUpdate","E":1618677483864,"T":1618677483853,"s":"BTCUSD_PERP","ps":"BTCUSD","U":86143389051,"u":86143390899,"pu":86143388993,"b":[["59004.7","0"],["59017.4","0"],["60204.5","0"],["60217.2","0"],["60221.4","0"],["60370.8","1869"],["60385.6","0"],["60434.8","0"],["60467.8","0"],["60504.5","0"],["60505.0","1"],["60505.5","1501"],["60506.0","0"],["60506.5","0"],["60507.1","30"],["60510.0","79"],["60510.5","77"],["60511.0","1575"],["60511.5","77"],["60512.0","100"],["60518.5","307"],["60521.4","128"],["60526.3","0"],["60543.3","500"],["60549.9","0"],["60564.3","0"],["60566.3","0"],["60566.5","8"],["60567.7","0"],["60568.0","2031"],["60571.3","0"],["60571.6","330"],["60573.4","0"],["60574.8","485"],["60575.4","545"],["60580.0","131"],["60581.0","3544"],["60583.2","0"],["60583.6","2207"],["60583.7","50"],["60583.8","18"],["60584.3","1030"],["60585.4","30"],["60587.3","500"],["60588.1","0"],["60589.0","110"],["60589.5","10203"],["60589.7","0"],["60590.0","0"]],"a":[["60589.6","4388"],["60589.9","0"],["60590.5","30"],["60592.3","0"],["60592.5","5"],["60596.3","444"],["60599.4","50"],["60600.7","10"],["60603.8","40"],["60611.8","40"],["60611.9","0"],["60613.0","122"],["60613.2","0"],["60614.0","0"],["60624.7","0"],["60626.0","245"],["60626.8","0"],["60638.3","0"],["60638.8","243"],["60639.6","0"],["60640.3","0"],["60640.8","243"],["60641.6","0"],["60680.4","500"],["60695.7","0"],["60708.3","1100"],["60716.2","0"],["60728.9","500"],["60806.4","1822"],["60806.8","25"],["60818.3","0"],["60818.6","0"],["60824.4","1822"],["60830.4","5445"],["60921.0","1"],["61125.9","0"]]}}
1618677485.2792718: {"stream":"ethusd_210625@depth@100ms","data":{"e":"depthUpdate","E":1618677483864,"T":1618677483858,"s":"ETHUSD_210625","ps":"ETHUSD","U":86143389084,"u":86143390960,"pu":86143389042,"b":[["2503.66","1000"],["2505.85","6709"],["2506.36","0"],["2506.88","1735"],["2507.08","21766"],["2507.59","2270"],["2507.79","391"],["2507.82","391"],["2507.83","391"],["2508.46","0"],["2509.34","2100"],["2509.70","3533"],["2509.82","0"],["2510.22","1008"],["2510.32","0"],["2510.33","299"],["2510.46","0"],["2510.56","1823"],["2510.58","0"]],"a":[["2510.57","405"],["2510.62","0"],["2510.63","330"],["2510.71","0"],["2510.79","0"],["2510.84","0"],["2510.88","567"],["2510.89","1250"],["2510.90","0"],["2510.92","0"],["2510.99","0"],["2511.02","83"],["2511.03","0"],["2511.10","100"],["2511.19","0"],["2511.22","0"],["2511.23","0"],["2511.26","0"],["2511.27","0"],["2511.30","0"],["2511.33","0"],["2511.34","0"],["2511.45","0"],["2511.48","906"],["2511.50","0"],["2511.51","2803"],["2511.52","0"],["2511.53","1299"],["2511.54","2794"],["2511.55","2306"],["2511.58","895"],["2511.59","2027"],["2511.62","5624"],["2511.63","1144"],["2511.68","0"],["2511.69","0"],["2511.75","121"],["2511.88","1072"],["2511.95","1070"],["2511.99","0"],["2512.01","0"],["2512.05","0"],["2512.08","0"],["2512.09","587"],["2512.14","587"],["2512.15","587"],["2512.42","587"],["2512.66","0"],["2512.77","1321"],["2513.12","0"],["2513.56","2100"],["2514.57","0"],["2520.17","0"],["2522.20","6000"]]}}
1618677485.279531: {"stream":"bchusd_210625@depth@100ms","data":{"e":"depthUpdate","E":1618677483867,"T":1618677483857,"s":"BCHUSD_210625","ps":"BCHUSD","U":86143389409,"u":86143390952,"pu":86143389261,"b":[["1115.23","0"],["1115.86","1000"],["1116.70","0"],["1123.29","0"],["1123.31","0"],["1123.45","1583"],["1123.92","1000"],["1127.63","35"],["1127.64","34"]],"a":[["1129.32","0"],["1129.33","0"],["1129.44","3"],["1129.45","0"],["1129.76","15"],["1129.84","250"],["1131.24","536"],["1131.55","576"],["1131.92","0"],["1132.32","301"],["1132.43","174"],["1132.81","100"],["1133.44","282"],["1133.81","100"],["1133.98","0"],["1134.05","0"],["1134.72","1000"]]}}
1618677485.279753: {"stream":"btcusd_210924@depth@100ms","data":{"e":"depthUpdate","E":1618677483901,"T":1618677483871,"s":"BTCUSD_210924","ps":"BTCUSD","U":86143390045,"u":86143391114,"pu":86143389910,"b":[["68170.9","80"],["68609.1","0"],["68611.5","276"],["68620.2","202"],["68620.3","87"],["68624.2","0"],["68632.0","841"]],"a":[["68650.6","0"],["68667.0","100"],["68688.4","88"]]}}
1618677485.279808: {"stream":"xrpusd_210625@depth@100ms","data":{"e":"depthUpdate","E":1618677483910,"T":1618677483896,"s":"XRPUSD_210625","ps":"XRPUSD","U":86143390204,"u":86143391397,"pu":86143389858,"b":[["1.6815","0"],["1.6821","20304"],["1.6835","291"],["1.6837","4468"],["1.6842","330"],["1.6858","1989"],["1.6870","964"],["1.6878","1670"],["1.6881","163"],["1.6883","12"],["1.6902","0"]],"a":[["1.6913","0"],["1.6915","0"],["1.6920","0"],["1.6921","164"],["1.6925","48"],["1.6928","0"],["1.6950","1633"],["1.6967","1946"],["1.7001","0"]]}}
1618677485.279926: {"stream":"linkusd_210625@depth@100ms","data":{"e":"depthUpdate","E":1618677483920,"T":1618677483914,"s":"LINKUSD_210625","ps":"LINKUSD","U":86143390385,"u":86143391710,"pu":86143389323,"b":[["43.596","174"],["43.632","0"],["43.767","0"]],"a":[["43.796","0"],["43.813","0"],["43.861","0"],["43.868","92"],["43.872","4329"],["43.877","0"],["43.880","0"],["43.883","1000"]]}}
1618677485.279999: {"stream":"egldusd_perp@depth@100ms","data":{"e":"depthUpdate","E":1618677483929,"T":1618677483919,"s":"EGLDUSD_PERP","ps":"EGLDUSD","U":86143390528,"u":86143391763,"pu":86143390201,"b":[["215.537","0"],["215.623","780"],["215.943","23"],["215.958","0"],["216.077","0"],["216.087","0"],["216.097","170"]],"a":[["216.399","0"],["216.468","11"]]}}
1618677485.280077: {"stream":"ethusd_210924@depth@100ms","data":{"e":"depthUpdate","E":1618677483935,"T":1618677483902,"s":"ETHUSD_210924","ps":"ETHUSD","U":86143390599,"u":86143391550,"pu":86143390557,"b":[["2685.78","2002"],["2688.97","0"],["2689.60","0"],["2689.69","1000"],["2689.79","891"]],"a":[["2689.80","218"],["2694.93","0"],["2695.19","0"],["2697.78","1200"],["2698.14","16605"],["2702.08","0"],["2702.52","0"]]}}
1618677485.280173: {"stream":"dotusd_210625@depth@100ms","data":{"e":"depthUpdate","E":1618677483954,"T":1618677483948,"s":"DOTUSD_210625","ps":"DOTUSD","U":86143390876,"u":86143392154,"pu":86143390799,"b":[["46.693","1163"],["46.757","63"],["46.758","0"],["46.772","0"],["46.773","0"],["46.775","0"]],"a":[["46.795","256"],["46.797","540"],["46.798","0"],["46.799","256"],["46.800","0"],["46.801","540"],["46.803","0"],["46.805","0"],["46.816","0"],["46.831","0"],["46.833","0"],["46.845","0"],["46.848","0"],["46.868","0"],["46.985","140"],["46.993","0"],["47.273","1417"]]}}
1618677485.2801862: {"stream":"btcusd_perp@depth@100ms","data":{"e":"depthUpdate","E":1618677483965,"T":1618677483954,"s":"BTCUSD_PERP","ps":"BTCUSD","U":86143390997,"u":86143392213,"pu":86143390899,"b":[["59377.7","100"],["59983.6","100"],["60356.3","1808"],["60480.7","0"],["60488.7","0"],["60490.3","0"],["60510.0","2"],["60512.5","77"],["60536.9","0"],["60538.2","0"],["60562.1","10"],["60568.7","0"],["60570.8","0"],["60571.9","0"],["60572.0","0"],["60572.3","0"],["60572.5","0"],["60573.2","0"],["60573.8","243"],["60573.9","122"],["60575.0","0"],["60578.0","300"],["60578.1","1500"],["60579.3","50"],["60580.8","25"],["60581.5","200"],["60582.7","25"],["60583.5","101"],["60584.2","30"],["60584.4","40"],["60584.7","0"],["60584.8","32"],["60585.1","0"],["60585.3","30"],["60585.4","0"],["60586.6","243"],["60587.1","0"],["60588.1","0"],["60588.6","243"],["60589.5","10245"],["60589.7","0"],["60590.0","0"]],"a":[["60589.6","4339"],["60590.8","0"],["60591.3","0"],["60592.6","60"],["60594.2","40"],["60595.8","1"],["60596.3","254"],["60597.5","407"],["60597.7","341"],["60598.8","400"],["60599.4","0"],["60600.4","201"],["60601.8","0"],["60603.8","0"],["60611.5","0"],["60613.0","0"],["60613.2","162"],["60613.4","0"],["60613.5","0"],["60616.3","0"],["60616.9","10"],["60620.2","56"],["60799.8","1821"],["60830.4","3626"],["60851.7","1822"]]}}
1618677485.28043: {"stream":"ethusd_210625@depth@100ms","data":{"e":"depthUpdate","E":1618677483970,"T":1618677483966,"s":"ETHUSD_210625","ps":"ETHUSD","U":86143391046,"u":86143392383,"pu":86143390960,"b":[["2504.40","0"],["2505.05","6253"],["2505.71","1001"],["2507.00","1529"],["2507.48","1072"],["2507.98","0"],["2509.87","299"],["2510.06","0"],["2510.33","0"],["2510.54","0"],["2510.58","0"]],"a":[["2511.01","121"],["2511.02","0"],["2511.17","527"],["2511.28","0"],["2511.45","0"],["2511.58","895"],["2511.62","4106"],["2511.68","1354"],["2511.75","0"],["2511.80","1917"],["2511.84","0"],["2511.89","0"],["2511.90","2356"],["2511.96","0"],["2512.14","1720"],["2512.16","771"],["2512.17","0"],["2512.22","0"],["2512.38","881"],["2512.44","0"],["2512.45","1204"],["2512.46","963"],["2512.49","2240"],["2512.55","0"],["2512.57","1623"],["2512.61","0"],["2512.67","1052"],["2512.68","1505"],["2512.76","999"],["2512.92","0"],["2512.96","0"],["2513.09","0"],["2513.27","3826"],["2513.29","0"],["2513.63","3036"],["2513.74","0"],["2513.94","0"],["2514.63","500"],["2515.67","0"]]}}
1618677485.2806132: {"stream":"btcusd_210924@depth@100ms","data":{"e":"depthUpdate","E":1618677484004,"T":1618677483997,"s":"BTCUSD_210924","ps":"BTCUSD","U":86143391541,"u":86143392722,"pu":86143391114,"b":[["68417.2","0"],["68531.8","0"],["68549.3","240"],["68590.8","0"],["68598.7","10"],["68620.2","0"],["68620.4","202"]],"a":[["68650.5","0"],["68652.1","20"],["68663.7","0"],["68665.1","20"],["68667.0","0"],["68677.3","0"],["68677.4","0"],["68697.0","0"],["68697.1","0"],["68698.4","0"],["68723.9","150"],["68787.6","150"]]}}
1618677485.2806442: {"stream":"linkusd_210924@depth@100ms","data":{"e":"depthUpdate","E":1618677484008,"T":1618677483954,"s":"LINKUSD_210924","ps":"LINKUSD","U":86143391561,"u":86143392211,"pu":86143389683,"b":[["45.107","0"]],"a":[["45.478","5860"]]}}
1618677485.2807958: {"stream":"bchusd_210625@depth@100ms","data":{"e":"depthUpdate","E":1618677483971,"T":1618677483917,"s":"BCHUSD_210625","ps":"BCHUSD","U":86143391060,"u":86143391738,"pu":86143390952,"b":[["1116.34","710"],["1121.53","0"],["1122.70","0"],["1125.63","0"],["1127.57","0"],["1127.58","0"],["1127.62","0"],["1127.63","0"],["1127.64","429"],["1127.65","125"],["1127.66","64"],["1127.67","124"]],"a":[["1131.11","298"],["1132.43","0"],["1134.16","40"]]}}
1618677485.2809432: {"stream":"xrpusd_210625@depth@100ms","data":{"e":"depthUpdate","E":1618677484018,"T":1618677484012,"s":"XRPUSD_210625","ps":"XRPUSD","U":86143391706,"u":86143392938,"pu":86143391397,"b":[["1.6774","2656"],["1.6783","9964"],["1.6806","0"],["1.6809","100"],["1.6866","172"],["1.6875","1012"],["1.6899","526"],["1.6902","145"],["1.6903","11"]],"a":[["1.6923","12"],["1.6924","0"],["1.6932","33"],["1.6934","140"],["1.6935","445"],["1.6939","12"],["1.6940","0"],["1.6946","170"],["1.6959","651"],["1.6964","470"],["1.6969","1000"],["1.6985","1200"],["1.7005","213"]]}}
1618677485.281024: {"stream":"linkusd_210625@depth@100ms","data":{"e":"depthUpdate","E":1618677484020,"T":1618677484001,"s":"LINKUSD_210625","ps":"LINKUSD","U":86143391737,"u":86143392785,"pu":86143391710,"b":[["43.580","180"],["43.619","310"],["43.623","13"],["43.767","0"]],"a":[["43.776","13"],["43.796","50"],["43.797","0"],["43.853","946"],["43.872","3383"],["43.902","40"]]}}
1618677485.281118: {"stream":"egldusd_perp@depth@100ms","data":{"e":"depthUpdate","E":1618677484046,"T":1618677484017,"s":"EGLDUSD_PERP","ps":"EGLDUSD","U":86143392106,"u":86143393045,"pu":86143391763,"b":[["215.944","130"]],"a":[["216.304","104"],["216.932","0"]]}}
1618677485.281146: {"stream":"ethusd_210924@depth@100ms","data":{"e":"depthUpdate","E":1618677484046,"T":1618677484038,"s":"ETHUSD_210924","ps":"ETHUSD","U":86143392095,"u":86143393301,"pu":86143391550,"b":[["2666.61","0"],["2666.77","0"],["2667.05","400"],["2686.88","0"],["2686.89","0"],["2687.33","302"],["2688.64","660"],["2688.99","0"],["2689.62","310"],["2689.79","231"]],"a":[["2690.07","310"],["2696.78","1000"],["2699.49","1068"]]}}
1618677485.281266: {"stream":"dotusd_210625@depth@100ms","data":{"e":"depthUpdate","E":1618677484059,"T":1618677484053,"s":"DOTUSD_210625","ps":"DOTUSD","U":86143392215,"u":86143393508,"pu":86143392154,"b":[["46.517","0"],["46.681","0"],["46.744","140"],["46.757","210"],["46.758","15"],["46.759","540"],["46.762","50"],["46.763","0"],["46.777","0"]],"a":[["46.789","540"],["46.790","200"],["46.791","256"],["46.793","540"],["46.794","84"],["46.797","0"],["46.799","0"],["46.801","0"],["46.826","0"],["46.832","0"],["46.985","0"],["46.991","0"],["47.173","0"],["47.243","0"]]}}
1618677485.281309: {"stream":"btcusd_perp@depth@100ms","data":{"e":"depthUpdate","E":1618677484069,"T":1618677484059,"s":"BTCUSD_PERP","ps":"BTCUSD","U":86143392375,"u":86143393578,"pu":86143392213,"b":[["60233.8","419"],["60366.6","5317"],["60399.8","419"],["60434.9","0"],["60461.1","1320"],["60482.8","419"],["60495.1","0"],["60503.3","0"],["60510.5","0"],["60511.0","1498"],["60511.4","721"],["60511.5","0"],["60513.0","277"],["60513.5","327"],["60514.0","77"],["60520.3","660"],["60554.1","1000"],["60558.8","0"],["60565.9","419"],["60566.1","361"],["60569.5","0"],["60571.6","0"],["60574.2","0"],["60577.0","50"],["60577.8","100"],["60579.5","330"],["60580.0","131"],["60581.0","3547"],["60582.3","114"],["60583.7","0"],["60583.8","0"],["60584.5","32"],["60584.8","0"],["60589.0","97"],["60589.5","10337"],["60589.7","0"]],"a":[["60589.6","4382"],["60590.5","0"],["60591.7","30"],["60592.6","30"],["60594.7","0"],["60595.9","0"],["60597.5","257"],["60597.6","341"],["60599.5","0"],["60599.9","0"],["60600.2","30"],["60602.3","0"],["60609.9","13"],["60613.1","122"],["60613.2","40"],["60613.5","0"],["60622.5","0"],["60632.5","330"],["60675.0","2003"],["60691.7","660"],["60708.3","0"],["60709.4","1100"],["60712.7","114"],["60726.2","0"],["60733.2","419"],["60750.8","1320"],["60810.8","0"],["60816.0","0"],["60834.9","299"],["60835.7","419"],["60838.9","1822"],["60844.7","299"],["60938.3","419"],["61143.4","419"]]}}
1618677485.281548: {"stream":"ethusd_210625@depth@100ms","data":{"e":"depthUpdate","E":1618677484071,"T":1618677484065,"s":"ETHUSD_210625","ps":"ETHUSD","U":86143392394,"u":86143393677,"pu":86143392383,"b":[["2505.09","1002"],["2507.68","0"],["2507.95","0"],["2508.90","0"],["2509.28","0"],["2509.35","0"],["2509.71","299"],["2509.87","0"],["2510.01","0"],["2510.21","0"],["2510.23","2212"],["2510.24","697"],["2510.58","0"]],"a":[["2510.63","355"],["2510.66","0"],["2510.87","121"],["2510.99","367"],["2511.01","0"],["2511.09","0"],["2511.16","289"],["2511.58","1529"],["2511.76","0"],["2512.27","1518"],["2512.28","4542"],["2512.49","3758"],["2512.55","1735"],["2512.63","1735"],["2512.71","2100"],["2512.89","1952"],["2513.04","1952"],["2513.17","1952"],["2513.20","1952"],["2513.31","2169"],["2513.56","0"],["2513.61","2169"],["2513.66","2169"],["2513.68","3967"],["2513.97","2386"],["2514.02","2386"],["2514.33","2386"],["2514.44","2602"],["2516.84","1000"],["2519.84","500"]]}}
1618677485.281798: {"stream":"bchusd_210625@depth@100ms","data":{"e":"depthUpdate","E":1618677484081,"T":1618677484048,"s":"BCHUSD_210625","ps":"BCHUSD","U":86143392500,"u":86143393442,"pu":86143391738,"b":[["1123.45","0"],["1123.75","0"],["1123.93","1583"],["1127.20","273"],["1127.21","59"]],"a":[["1129.44","0"],["1129.45","0"],["1132.81","0"],["1132.89","50"]]}}
1618677485.2819672: {"stream":"btcusd_210924@depth@100ms","data":{"e":"depthUpdate","E":1618677484111,"T":1618677484074,"s":"BTCUSD_210924","ps":"BTCUSD","U":86143392855,"u":86143393819,"pu":86143392722,"b":[],"a":[["68663.6","0"],["68681.0","240"],["68689.9","0"],["71720.1","0"]]}}
1618677485.281976: {"stream":"xrpusd_210625@depth@100ms","data":{"e":"depthUpdate","E":1618677484118,"T":1618677484098,"s":"XRPUSD_210625","ps":"XRPUSD","U":86143392960,"u":86143394137,"pu":86143392938,"b":[["1.6902","100"],["1.6903","31"]],"a":[["1.6925","48"],["1.6934","95"],["1.6935","545"],["1.6956","0"],["1.6959","651"],["1.6969","0"],["1.6970","1401"],["1.6993","2305"],["1.7002","0"]]}}
1618677485.282067: {"stream":"linkusd_210924@depth@100ms","data":{"e":"depthUpdate","E":1618677484127,"T":1618677484021,"s":"LINKUSD_210924","ps":"LINKUSD","U":86143393108,"u":86143393108,"pu":86143392211,"b":[],"a":[["45.752","0"]]}}
1618677485.2820952: {"stream":"linkusd_210625@depth@100ms","data":{"e":"depthUpdate","E":1618677484137,"T":1618677484068,"s":"LINKUSD_210625","ps":"LINKUSD","U":86143393248,"u":86143393728,"pu":86143392785,"b":[["43.767","0"]],"a":[["43.796","0"]]}}
1618677485.282166: {"stream":"ethusd_210924@depth@100ms","data":{"e":"depthUpdate","E":1618677484148,"T":1618677484143,"s":"ETHUSD_210924","ps":"ETHUSD","U":86143393363,"u":86143394661,"pu":86143393301,"b":[["2667.05","100"],["2667.40","480"],["2679.29","0"],["2685.52","2002"],["2685.78","0"],["2687.96","0"],["2688.39","1394"],["2688.64","0"],["2689.43","0"],["2689.49","1000"],["2689.69","0"],["2689.79","231"]],"a":[["2699.63","13467"]]}}
1618677485.282258: {"stream":"dotusd_210625@depth@100ms","data":{"e":"depthUpdate","E":1618677484159,"T":1618677484145,"s":"DOTUSD_210625","ps":"DOTUSD","U":86143393537,"u":86143394687,"pu":86143393508,"b":[["46.486","1699"],["46.744","284"],["46.756","0"],["46.757","0"],["46.758","0"],["46.760","45"],["46.761","189"],["46.762","0"],["46.763","0"]],"a":[["46.782","200"],["46.783","540"],["46.785","0"],["46.786","796"],["46.788","0"],["46.789","0"],["46.790","0"],["46.791","0"],["46.793","0"],["46.794","0"],["46.795","0"],["46.833","22"],["46.968","140"],["47.226","150"],["47.227","141"],["47.236","118"],["47.291","467"]]}}
1618677485.282332: {"stream":"btcusd_perp@depth@100ms","data":{"e":"depthUpdate","E":1618677484171,"T":1618677484165,"s":"BTCUSD_PERP","ps":"BTCUSD","U":86143393698,"u":86143394877,"pu":86143393578,"b":[["60495.4","0"],["60512.0","100"],["60512.5","77"],["60513.0","277"],["60572.4","0"],["60581.0","3572"],["60582.0","815"],["60584.2","0"],["60584.3","0"],["60584.4","0"],["60586.2","30"],["60587.3","0"],["60589.5","10987"],["60589.7","0"]],"a":[["60591.7","0"],["60593.8","30"],["60594.2","0"],["60594.3","0"],["60596.1","0"],["60597.5","407"],["60598.2","197"],["60600.0","210"],["60602.9","25"],["60611.7","15"],["60613.1","0"],["60613.4","122"],["60613.5","0"],["60618.9","1201"],["60626.4","0"],["60811.0","1814"],["60825.0","2"],["60826.8","1822"],["60830.4","1822"],["60836.5","0"],["60839.0","1828"]]}}
1618677485.282461: {"stream":"egldusd_perp@depth@100ms","data":{"e":"depthUpdate","E":1618677484173,"T":1618677484165,"s":"EGLDUSD_PERP","ps":"EGLDUSD","U":86143393706,"u":86143394880,"pu":86143393045,"b":[["215.943","0"],["215.945","23"],["216.097","0"],["216.107","0"],["216.117","170"]],"a":[["216.169","16"],["216.304","0"],["216.305","0"],["216.349","108"],["216.350","487"]]}}
1618677485.282527: {"stream":"ethusd_210625@depth@100ms","data":{"e":"depthUpdate","E":1618677484177,"T":1618677484169,"s":"ETHUSD_210625","ps":"ETHUSD","U":86143393797,"u":86143394912,"pu":86143393677,"b":[["2505.01","4101"],["2507.16","1132"],["2507.71","0"],["2507.96","105"],["2509.35","2677"],["2509.71","0"],["2509.72","0"],["2510.01","0"],["2510.13","0"],["2510.22","0"],["2510.25","1378"],["2510.58","0"]],"a":[["2510.87","0"],["2511.09","121"],["2511.15","527"],["2511.17","0"],["2511.29","0"],["2511.50","1072"],["2511.57","1070"],["2511.64","0"],["2511.88","0"],["2511.91","1073"],["2511.95","0"],["2512.28","3469"],["2512.75","1194"],["2512.82","1735"],["2513.71","0"],["2513.93","8476"],["2513.94","105"],["2515.38","435"],["2515.40","0"],["2516.85","3747"]]}}
1618677485.282719: {"stream":"bchusd_210625@depth@100ms","data":{"e":"depthUpdate","E":1618677484188,"T":1618677484183,"s":"BCHUSD_210625","ps":"BCHUSD","U":86143393956,"u":86143395075,"pu":86143393442,"b":[["1117.31","0"],["1117.66","150"],["1124.64","286"],["1125.19","173"],["1125.49","0"],["1125.84","141"],["1127.61","0"],["1127.67","15"],["1127.68","0"],["1127.69","0"],["1127.70","0"],["1127.71","64"],["1127.72","117"]],"a":[["1131.24","250"],["1131.46","0"],["1133.35","0"],["1134.50","100"]]}}
1618677485.28286: {"stream":"xrpusd_210625@depth@100ms","data":{"e":"depthUpdate","E":1618677484219,"T":1618677484214,"s":"XRPUSD_210625","ps":"XRPUSD","U":86143394308,"u":86143395463,"pu":86143394137,"b":[["1.6619","0"],["1.6724","0"],["1.6776","0"],["1.6777","0"],["1.6809","0"],["1.6812","100"],["1.6829","0"],["1.6835","211"],["1.6839","0"],["1.6880","0"],["1.6881","12"],["1.6887","346"],["1.6892","581"],["1.6902","0"],["1.6903","0"],["1.6904","152"],["1.6905","133"]],"a":[["1.6925","0"],["1.6931","41"],["1.6932","183"],["1.6933","61"],["1.6934","0"],["1.6935","0"],["1.6939","109"],["1.6949","0"],["1.6950","0"],["1.6951","354"],["1.6959","1651"],["1.6970","401"],["1.7003","0"],["1.7036","0"],["1.7121","0"],["1.7292","0"]]}}
1618677485.283058: {"stream":"btcusd_210924@depth@100ms","data":{"e":"depthUpdate","E":1618677484230,"T":1618677484208,"s":"BTCUSD_210924","ps":"BTCUSD","U":86143394474,"u":86143395402,"pu":86143393819,"b":[["68442.4","300"],["68560.8","0"],["68637.2","0"]],"a":[["68689.8","177"],["68689.9","789"],["68804.8","0"]]}}
1618677485.283067: {"stream":"linkusd_210924@depth@100ms","data":{"e":"depthUpdate","E":1618677484235,"T":1618677484204,"s":"LINKUSD_210924","ps":"LINKUSD","U":86143394542,"u":86143395358,"pu":86143393108,"b":[["44.767","0"],["44.874","0"],["44.982","0"],["45.089","0"],["45.092","95"],["45.127","83"],["45.197","0"],["45.198","0"]],"a":[["45.292","0"],["45.323","40"],["45.334","0"],["45.335","0"],["45.417","307"],["45.418","1465"],["45.440","0"],["45.441","0"],["45.451","72"],["45.453","743"],["45.548","0"],["45.654","0"],["45.761","0"],["45.786","0"],["45.818","40"]]}}
1618677485.283108: {"stream":"linkusd_210625@depth@100ms","data":{"e":"depthUpdate","E":1618677484244,"T":1618677484226,"s":"LINKUSD_210625","ps":"LINKUSD","U":86143394625,"u":86143395601,"pu":86143393728,"b":[["43.358","0"],["43.406","1200"],["43.534","135"],["43.535","0"],["43.549","100"],["43.553","0"],["43.601","1212"],["43.731","0"],["43.745","100"],["43.767","0"]],"a":[["43.789","50"]]}}
1618677485.283183: {"stream":"ethusd_210924@depth@100ms","data":{"e":"depthUpdate","E":1618677484253,"T":1618677484248,"s":"ETHUSD_210924","ps":"ETHUSD","U":86143394731,"u":86143395844,"pu":86143394661,"b":[["2687.36","0"],["2688.99","0"],["2689.19","502"],["2689.46","0"],["2689.49","1000"],["2689.63","0"],["2689.79","1076"]],"a":[["2690.69","599"],["2694.58","2002"],["2695.96","0"],["2704.15","406"]]}}
1618677485.283252: {"stream":"dotusd_210625@depth@100ms","data":{"e":"depthUpdate","E":1618677484264,"T":1618677484259,"s":"DOTUSD_210625","ps":"DOTUSD","U":86143394825,"u":86143395949,"pu":86143394687,"b":[["46.298","115"],["46.351","275"],["46.744","443"],["46.745","63"],["46.759","0"],["46.760","0"],["46.761","0"],["46.763","540"]],"a":[["46.779","0"],["46.780","540"],["46.782","0"],["46.783","0"],["46.786","256"],["46.803","200"],["46.953","40"],["47.115","0"]]}}
1618677485.283322: {"stream":"btcusd_perp@depth@100ms","data":{"e":"depthUpdate","E":1618677484277,"T":1618677484272,"s":"BTCUSD_PERP","ps":"BTCUSD","U":86143394942,"u":86143396082,"pu":86143394877,"b":[["60406.2","1812"],["60443.9","0"],["60492.7","93"],["60498.0","90"],["60499.9","799"],["60511.4","0"],["60512.0","23"],["60520.2","0"],["60532.2","1405"],["60534.3","1000"],["60550.1","50"],["60555.2","500"],["60566.0","0"],["60568.0","0"],["60568.1","571"],["60568.2","2031"],["60573.5","0"],["60575.7","0"],["60579.7","60"],["60580.0","146"],["60583.4","30"],["60583.7","1"],["60584.4","40"],["60584.5","0"],["60586.2","0"],["60588.7","0"],["60589.5","12062"],["60589.7","0"]],"a":[["60591.4","31"],["60593.8","0"],["60594.2","40"],["60596.3","404"],["60597.4","462"],["60597.5","257"],["60600.0","50"],["60612.9","0"],["60613.3","122"],["60613.4","0"],["60619.9","596"],["60620.4","0"],["60621.9","0"],["60628.7","1924"],["60632.5","909"],["60634.2","1089"],["60634.5","1450"],["60636.9","1095"],["60656.4","0"],["60720.0","44"],["60770.2","100"],["60787.6","501"],["60832.9","1822"]]}}
1618677485.283505: {"stream":"ethusd_210625@depth@100ms","data":{"e":"depthUpdate","E":1618677484278,"T":1618677484269,"s":"ETHUSD_210625","ps":"ETHUSD","U":86143394960,"u":86143396032,"pu":86143394912,"b":[["2498.64","15000"],["2502.30","0"],["2504.29","0"],["2506.18","1618"],["2509.12","768"],["2509.35","2378"],["2510.01","0"],["2510.18","0"],["2510.24","0"],["2510.26","2562"],["2510.54","0"],["2510.56","2323"],["2510.58","0"]],"a":[["2510.57","441"],["2510.63","0"],["2510.64","0"],["2510.65","0"],["2510.67","0"],["2510.87","0"],["2510.98","0"],["2511.08","0"],["2511.09","0"],["2511.15","0"],["2511.17","121"],["2511.45","527"],["2511.56","0"],["2511.80","616"],["2511.90","839"],["2512.11","0"],["2512.12","0"],["2512.88","881"],["2513.26","0"],["2513.51","0"],["2513.63","0"],["2513.74","1122"],["2513.75","3035"],["2513.76","0"],["2513.95","0"],["2514.48","0"],["2516.85","3996"],["2529.15","0"]]}}
1618677485.283691: {"stream":"bchusd_210625@depth@100ms","data":{"e":"depthUpdate","E":1618677484296,"T":1618677484287,"s":"BCHUSD_210625","ps":"BCHUSD","U":86143395162,"u":86143396325,"pu":86143395075,"b":[["1117.66","50"],["1122.54","271"],["1123.93","0"],["1125.84","50"],["1126.18","0"],["1127.05","1583"],["1127.06","332"],["1127.51","102"],["1127.66","0"],["1127.67","0"],["1127.72","13"],["1127.73","0"],["1127.74","6"],["1127.75","35"],["1127.76","43"],["1127.77","64"]],"a":[["1128.03","0"],["1129.45","3"],["1137.38","0"]]}}
1618677485.283787: {"stream":"xrpusd_210625@depth@100ms","data":{"e":"depthUpdate","E":1618677484320,"T":1618677484304,"s":"XRPUSD_210625","ps":"XRPUSD","U":86143395483,"u":86143396462,"pu":86143395463,"b":[["1.6622","1633"],["1.6732","1633"],["1.6787","1633"],["1.6842","1963"],["1.6852","595"],["1.6902","0"],["1.6906","729"],["1.6907","126"]],"a":[["1.6931","86"],["1.6939","12"],["1.6950","445"],["1.6952","2278"],["1.6965","1753"],["1.6966","790"],["1.6974","0"],["1.6999","841"],["1.7025","1219"],["1.7027","173"],["1.7054","1633"],["1.7142","1633"],["1.7319","1633"]]}}
1618677485.2839081: {"stream":"btcusd_210924@depth@100ms","data":{"e":"depthUpdate","E":1618677484347,"T":1618677484291,"s":"BTCUSD_210924","ps":"BTCUSD","U":86143395777,"u":86143396357,"pu":86143395402,"b":[],"a":[["68688.3","257"],["71722.5","1432"]]}}
1618677485.283975: {"stream":"ethusd_210924@depth@100ms","data":{"e":"depthUpdate","E":1618677484360,"T":1618677484355,"s":"ETHUSD_210924","ps":"ETHUSD","U":86143395914,"u":86143396859,"pu":86143395844,"b":[["2673.91","15000"],["2684.19","0"],["2685.46","0"],["2686.12","1267"],["2686.13","7298"],["2689.63","660"],["2689.79","231"]],"a":[]}}
1618677485.284043: {"stream":"dotusd_210625@depth@100ms","data":{"e":"depthUpdate","E":1618677484375,"T":1618677484363,"s":"DOTUSD_210625","ps":"DOTUSD","U":86143396055,"u":86143396900,"pu":86143395949,"b":[["46.764","114"]],"a":[["46.779","200"],["46.785","0"],["46.803","0"],["46.847","50"],["46.849","635"],["46.938","1000"],["46.950","0"],["46.968","0"],["47.129","50"],["47.130","0"],["47.220","1000"],["47.232","0"]]}}
1618677485.284062: {"stream":"btcusd_perp@depth@100ms","data":{"e":"depthUpdate","E":1618677484378,"T":1618677484374,"s":"BTCUSD_PERP","ps":"BTCUSD","U":86143396170,"u":86143396998,"pu":86143396082,"b":[["59862.4","100"],["60100.0","6096"],["60369.0","41"],["60512.0","100"],["60536.3","0"],["60567.1","0"],["60579.7","50"],["60588.6","353"],["60589.5","11547"],["60589.7","0"]],"a":[["60591.4","30"],["60596.3","404"],["60596.7","10"],["60608.0","0"],["60610.0","120"],["60613.0","122"],["60613.3","0"],["60615.7","0"],["60616.7","40"],["60793.1","0"]]}}
1618677485.2841442: {"stream":"ethusd_210625@depth@100ms","data":{"e":"depthUpdate","E":1618677484378,"T":1618677484372,"s":"ETHUSD_210625","ps":"ETHUSD","U":86143396159,"u":86143396980,"pu":86143396032,"b":[["2499.07","500"],["2505.05","3253"],["2505.39","0"],["2505.85","9709"],["2506.27","2979"],["2507.41","0"],["2508.40","1878"],["2509.12","0"],["2510.24","0"],["2510.25","0"],["2510.26","2263"],["2510.27","2669"],["2510.54","0"],["2510.56","2622"],["2510.58","0"]],"a":[["2510.57","588"],["2510.88","567"],["2510.99","488"],["2511.14","214"],["2511.15","527"],["2511.17","0"],["2511.45","0"],["2511.50","3378"],["2511.53","0"],["2511.55","0"],["2511.95","835"],["2512.17","1084"],["2512.27","1909"],["2512.28","3860"],["2512.30","391"],["2512.54","1909"],["2512.57","788"],["2512.66","1518"],["2512.70","1301"],["2512.88","3483"],["2513.23","3266"],["2514.28","2819"],["2514.50","3036"],["2514.51","2819"],["2515.23","3253"]]}}
1618677485.284276: {"stream":"egldusd_perp@depth@100ms","data":{"e":"depthUpdate","E":1618677484385,"T":1618677484365,"s":"EGLDUSD_PERP","ps":"EGLDUSD","U":86143396208,"u":86143396924,"pu":86143394880,"b":[],"a":[["216.169","0"],["216.310","487"],["216.350","0"],["216.470","666"]]}}
1618677485.2843058: {"stream":"linkusd_210625@depth@100ms","data":{"e":"depthUpdate","E":1618677484385,"T":1618677484376,"s":"LINKUSD_210625","ps":"LINKUSD","U":86143396224,"u":86143397031,"pu":86143395601,"b":[["43.552","300"],["43.659","12"],["43.665","12"],["43.702","0"],["43.757","96"],["43.763","0"],["43.765","0"],["43.766","0"]],"a":[["43.806","98"],["43.833","846"],["43.840","0"],["43.849","385"],["43.853","0"],["43.868","482"]]}}
1618677485.284377: {"stream":"bchusd_210625@depth@100ms","data":{"e":"depthUpdate","E":1618677484402,"T":1618677484397,"s":"BCHUSD_210625","ps":"BCHUSD","U":86143396406,"u":86143397191,"pu":86143396325,"b":[["1118.22","2970"],["1120.21","0"],["1127.05","0"],["1127.06","0"],["1127.18","2054"],["1127.19","433"],["1127.74","0"],["1127.75","0"],["1127.76","0"],["1127.77","64"],["1127.78","42"]],"a":[["1131.34","0"],["1132.27","1681"],["1134.66","0"]]}}
1618677485.284502: {"stream":"xrpusd_210625@depth@100ms","data":{"e":"depthUpdate","E":1618677484435,"T":1618677484421,"s":"XRPUSD_210625","ps":"XRPUSD","U":86143396691,"u":86143397362,"pu":86143396462,"b":[["1.6810","157"],["1.6840","80"],["1.6906","707"],["1.6907","45"]],"a":[["1.6931","41"],["1.7008","213"]]}}
1618677485.284579: {"stream":"linkusd_210924@depth@100ms","data":{"e":"depthUpdate","E":1618677484464,"T":1618677484445,"s":"LINKUSD_210924","ps":"LINKUSD","U":86143396888,"u":86143397581,"pu":86143395358,"b":[["44.505","40"]],"a":[["45.309","11"],["45.310","50"],["45.322","9"],["45.384","250"],["45.407","0"],["45.449","1028"],["45.450","4899"],["45.451","0"],["45.453","43"],["45.478","0"]]}}
1618677485.284597: {"stream":"btcusd_210924@depth@100ms","data":{"e":"depthUpdate","E":1618677484466,"T":1618677484443,"s":"BTCUSD_210924","ps":"BTCUSD","U":86143396898,"u":86143397560,"pu":86143396357,"b":[],"a":[["68703.4","358"],["68703.5","1546"],["68809.6","300"]]}}
1618677485.2846038: {"stream":"ethusd_210924@depth@100ms","data":{"e":"depthUpdate","E":1618677484470,"T":1618677484462,"s":"ETHUSD_210924","ps":"ETHUSD","U":86143396932,"u":86143397721,"pu":86143396859,"b":[["2662.32","0"],["2663.74","1000"],["2676.27","2405"],["2679.90","0"],["2680.04","250"],["2689.43","0"],["2689.49","1000"],["2689.63","0"],["2689.79","891"]],"a":[]}}
1618677485.2846441: {"stream":"dotusd_210625@depth@100ms","data":{"e":"depthUpdate","E":1618677484475,"T":1618677484469,"s":"DOTUSD_210625","ps":"DOTUSD","U":86143396966,"u":86143397767,"pu":86143396900,"b":[["46.212","0"],["46.239","0"],["46.379","0"],["46.737","0"]],"a":[["46.779","0"],["46.802","0"],["46.806","200"],["46.815","680"],["46.826","0"],["46.833","72"],["46.847","0"],["46.915","1486"],["46.953","180"],["47.115","100"],["47.129","0"],["47.172","166"],["47.191","0"]]}}
1618677485.284708: {"stream":"ethusd_210625@depth@100ms","data":{"e":"depthUpdate","E":1618677484479,"T":1618677484473,"s":"ETHUSD_210625","ps":"ETHUSD","U":86143397006,"u":86143397806,"pu":86143396980,"b":[["2502.84","0"],["2503.18","3218"],["2503.84","0"],["2505.92","1621"],["2510.58","0"]],"a":[["2510.88","688"],["2510.97","236"],["2510.98","527"],["2510.99","367"],["2511.15","0"],["2511.50","1072"],["2511.62","2076"],["2511.91","0"],["2514.02","4988"],["2514.36","3036"],["2514.67","2819"],["2516.04","1002"],["2528.07","0"]]}}
1618677485.2848: {"stream":"btcusd_perp@depth@100ms","data":{"e":"depthUpdate","E":1618677484483,"T":1618677484478,"s":"BTCUSD_PERP","ps":"BTCUSD","U":86143397048,"u":86143397835,"pu":86143396998,"b":[["60464.8","0"],["60473.8","0"],["60504.5","1100"],["60551.8","1218"],["60568.2","0"],["60572.9","0"],["60574.0","2031"],["60574.5","79"],["60577.3","1"],["60583.2","30"],["60583.4","0"],["60585.5","0"],["60589.5","11577"],["60589.7","0"]],"a":[["60596.3","404"],["60601.7","1"],["60604.6","1"],["60613.0","0"],["60613.1","122"],["60613.2","40"],["60615.6","0"],["60709.4","0"],["60720.0","44"],["61195.5","2"]]}}
1618677485.284898: {"stream":"egldusd_perp@depth@100ms","data":{"e":"depthUpdate","E":1618677484497,"T":1618677484484,"s":"EGLDUSD_PERP","ps":"EGLDUSD","U":86143397138,"u":86143397872,"pu":86143396924,"b":[["216.054","54"]],"a":[["216.180","4"],["216.256","0"],["216.339","16"],["216.349","0"]]}}
1618677485.28494: {"stream":"bchusd_210625@depth@100ms","data":{"e":"depthUpdate","E":1618677484502,"T":1618677484496,"s":"BCHUSD_210625","ps":"BCHUSD","U":86143397200,"u":86143397984,"pu":86143397191,"b":[["1124.98","250"],["1125.01","151"],["1126.45","1630"],["1127.18","425"],["1127.71","0"],["1127.72","0"],["1127.78","15"],["1127.79","0"],["1127.80","9"],["1127.81","35"],["1127.82","64"],["1127.83","0"]],"a":[["1129.67","7"],["1129.68","37"],["1129.84","500"],["1132.03","98"],["1132.47","100"],["1132.89","0"],["1136.57","1687"]]}}
1618677485.285008: {"stream":"linkusd_210625@depth@100ms","data":{"e":"depthUpdate","E":1618677484502,"T":1618677484484,"s":"LINKUSD_210625","ps":"LINKUSD","U":86143397192,"u":86143397877,"pu":86143397031,"b":[["43.594","0"],["43.713","0"],["43.766","0"]],"a":[["43.994","0"]]}}
1618677485.285124: {"stream":"linkusd_210924@depth@100ms","data":{"e":"depthUpdate","E":1618677484567,"T":1618677484549,"s":"LINKUSD_210924","ps":"LINKUSD","U":86143397722,"u":86143398393,"pu":86143397581,"b":[["44.811","5282"],["44.918","4754"],["45.025","3697"],["45.092","0"],["45.127","0"],["45.132","3803"],["45.164","0"],["45.240","3169"],["45.241","232"]],"a":[["45.342","40"],["45.370","551"],["45.371","2620"],["45.384","0"],["45.406","0"],["45.409","250"],["45.410","371"],["45.427","448"],["45.448","2449"],["45.449","0"],["45.454","0"],["45.455","0"],["45.478","3145"],["45.586","3418"],["45.694","3931"],["45.802","4367"]]}}
1618677485.285135: {"stream":"xrpusd_210625@depth@100ms","data":{"e":"depthUpdate","E":1618677484570,"T":1618677484555,"s":"XRPUSD_210625","ps":"XRPUSD","U":86143397746,"u":86143398433,"pu":86143397362,"b":[["1.6822","0"],["1.6879","806"]],"a":[["1.6922","0"],["1.6928","0"],["1.6932","33"],["1.6936","102"],["1.6937","12"],["1.6945","45"],["1.6989","260"],["1.7057","351"]]}}
1618677485.285195: {"stream":"ethusd_210625@depth@100ms","data":{"e":"depthUpdate","E":1618677484580,"T":1618677484576,"s":"ETHUSD_210625","ps":"ETHUSD","U":86143397822,"u":86143398609,"pu":86143397806,"b":[["2503.18","0"],["2503.74","2998"],["2508.39","20"],["2509.05","773"],["2509.36","0"],["2510.01","0"],["2510.13","0"],["2510.27","2669"],["2510.28","299"],["2510.56","2323"],["2510.58","0"]],"a":[["2510.74","66"],["2510.96","149"],["2510.98","0"],["2511.34","2803"],["2511.37","484"],["2511.38","2306"],["2511.42","2027"],["2511.44","681"],["2511.45","2030"],["2511.48","0"],["2511.49","812"],["2511.51","0"],["2511.58","0"],["2511.59","0"],["2511.63","60"],["2511.74","1073"],["2515.56","1777"],["2521.86","15000"]]}}
1618677485.2853131: {"stream":"dotusd_210625@depth@100ms","data":{"e":"depthUpdate","E":1618677484586,"T":1618677484579,"s":"DOTUSD_210625","ps":"DOTUSD","U":86143397859,"u":86143398634,"pu":86143397767,"b":[["45.538","0"],["45.595","586"],["46.005","0"],["46.063","592"],["46.220","40"],["46.296","504"],["46.437","367"],["46.620","528"],["46.722","63"],["46.740","250"],["46.745","0"]],"a":[["46.803","284"],["46.806","0"],["46.814","0"],["46.833","50"],["46.923","1000"],["46.938","0"],["46.980","0"],["47.204","1011"],["47.220","0"],["47.248","514"],["47.425","0"],["47.482","611"],["47.892","0"],["47.950","617"]]}}
1618677485.285412: {"stream":"btcusd_perp@depth@100ms","data":{"e":"depthUpdate","E":1618677484588,"T":1618677484583,"s":"BTCUSD_PERP","ps":"BTCUSD","U":86143397873,"u":86143398669,"pu":86143397835,"b":[["60328.6","0"],["60544.9","582"],["60574.0","0"],["60574.2","219"],["60575.3","2428"],["60581.3","100"],["60583.2","0"],["60583.5","1"],["60585.4","30"],["60589.7","0"]],"a":[["60596.3","404"],["60613.1","0"],["60640.7","368"],["60709.3","0"]]}}
1618677485.2854662: {"stream":"ethusd_210924@depth@100ms","data":{"e":"depthUpdate","E":1618677484591,"T":1618677484568,"s":"ETHUSD_210924","ps":"ETHUSD","U":86143397905,"u":86143398542,"pu":86143397721,"b":[["2680.04","0"],["2685.45","0"],["2686.68","3687"],["2689.46","1000"],["2689.49","0"],["2689.50","0"],["2689.63","0"],["2689.79","891"]],"a":[["2703.35","15000"]]}}
1618677485.2855282: {"stream":"bchusd_210625@depth@100ms","data":{"e":"depthUpdate","E":1618677484605,"T":1618677484594,"s":"BCHUSD_210625","ps":"BCHUSD","U":86143398013,"u":86143398796,"pu":86143397984,"b":[["1115.17","0"],["1121.26","190"],["1123.17","211"],["1125.19","0"],["1127.19","89"],["1127.77","0"],["1127.80","0"],["1127.81","0"],["1127.83","35"],["1127.84","35"],["1127.85","34"]],"a":[["1132.47","0"],["1133.15","359"],["1139.24","0"],["1140.54","190"]]}}
1618677485.285592: {"stream":"egldusd_perp@depth@100ms","data":{"e":"depthUpdate","E":1618677484613,"T":1618677484602,"s":"EGLDUSD_PERP","ps":"EGLDUSD","U":86143398099,"u":86143398860,"pu":86143397872,"b":[],"a":[["216.310","0"],["216.339","0"],["216.588","0"],["216.809","301"],["216.819","1068"]]}}
1618677485.285623: {"stream":"linkusd_210625@depth@100ms","data":{"e":"depthUpdate","E":1618677484613,"T":1618677484597,"s":"LINKUSD_210625","ps":"LINKUSD","U":86143398085,"u":86143398816,"pu":86143397877,"b":[["43.755","0"],["43.766","0"]],"a":[["43.816","381"],["43.963","1499"]]}}
1618677485.285706: {"stream":"btcusd_210924@depth@100ms","data":{"e":"depthUpdate","E":1618677484644,"T":1618677484617,"s":"BTCUSD_210924","ps":"BTCUSD","U":86143398347,"u":86143398989,"pu":86143397560,"b":[["68411.2","25"]],"a":[["68632.1","70"],["68703.3","379"],["68813.3","25"],["68979.0","0"],["69017.0","683"]]}}
1618677485.285732: {"stream":"xrpusd_210625@depth@100ms","data":{"e":"depthUpdate","E":1618677484670,"T":1618677484662,"s":"XRPUSD_210625","ps":"XRPUSD","U":86143398524,"u":86143399350,"pu":86143398433,"b":[["1.6886","0"],["1.6887","232"]],"a":[["1.6929","12"],["1.6930","0"],["1.6931","12"],["1.6932","183"],["1.6934","0"],["1.6935","31"],["1.6936","147"],["1.6945","0"],["1.6975","22754"],["1.6993","0"],["1.7038","0"],["1.7040","80"]]}}
1618677485.285783: {"stream":"linkusd_210924@depth@100ms","data":{"e":"depthUpdate","E":1618677484670,"T":1618677484638,"s":"LINKUSD_210924","ps":"LINKUSD","U":86143398512,"u":86143399159,"pu":86143398393,"b":[["45.197","0"],["45.207","0"],["45.216","20"]],"a":[["45.423","250"],["45.436","250"],["45.449","250"]]}}
1618677485.285874: {"stream":"ethusd_210924@depth@100ms","data":{"e":"depthUpdate","E":1618677484691,"T":1618677484685,"s":"ETHUSD_210924","ps":"ETHUSD","U":86143398717,"u":86143399513,"pu":86143398542,"b":[["2679.99","1605"],["2680.11","250"],["2689.46","0"],["2689.49","1000"],["2689.79","1076"]],"a":[["2690.88","100"],["2698.99","15606"],["2699.63","0"],["2702.75","250"]]}}
1618677485.285918: {"stream":"dotusd_210625@depth@100ms","data":{"e":"depthUpdate","E":1618677484691,"T":1618677484686,"s":"DOTUSD_210625","ps":"DOTUSD","U":86143398714,"u":86143399523,"pu":86143398634,"b":[["46.107","0"],["46.179","181"],["46.673","1"],["46.744","444"]],"a":[["46.779","200"],["46.785","0"],["46.803","84"],["46.874","250"],["46.889","250"],["46.908","250"],["46.993","315"],["47.000","41"],["47.065","724"],["47.256","1447"],["47.273","0"]]}}
1618677485.285975: {"stream":"btcusd_perp@depth@100ms","data":{"e":"depthUpdate","E":1618677484692,"T":1618677484686,"s":"BTCUSD_PERP","ps":"BTCUSD","U":86143398724,"u":86143399525,"pu":86143398669,"b":[["60383.0","1808"],["60518.6","0"],["60542.1","1225"],["60555.7","0"],["60578.2","0"],["60585.8","160"],["60589.5","11587"],["60589.7","0"],["60590.0","0"]],"a":[["60589.6","4381"],["60596.3","254"],["60612.8","0"],["60612.9","0"],["60613.0","122"],["60613.2","40"],["60625.7","243"],["60625.9","10"],["60626.0","2"],["60638.4","243"],["60638.5","1225"],["60638.8","0"],["60640.4","243"],["60640.8","0"],["60647.5","0"],["60709.5","1100"],["60796.1","1821"],["61195.5","0"]]}}
1618677485.286093: {"stream":"ethusd_210625@depth@100ms","data":{"e":"depthUpdate","E":1618677484697,"T":1618677484690,"s":"ETHUSD_210625","ps":"ETHUSD","U":86143398788,"u":86143399555,"pu":86143398609,"b":[["2509.36","2259"],["2510.27","1291"],["2510.28","0"],["2510.29","1378"],["2510.54","0"],["2510.56","2747"],["2510.58","0"]],"a":[["2510.57","0"],["2510.74","0"],["2510.88","567"],["2511.34","0"],["2511.36","121"],["2511.37","0"],["2511.38","250"],["2511.42","0"],["2511.45","0"],["2511.49","0"],["2511.54","0"],["2511.74","0"],["2511.76","967"],["2511.96","2803"],["2511.99","2794"],["2512.01","2306"],["2512.04","2027"],["2512.08","2030"],["2512.33","1926"],["2512.36","1073"],["2512.39","1084"],["2513.27","1982"],["2513.60","0"],["2513.75","0"],["2513.77","0"]]}}
1618677485.28628: {"stream":"bchusd_210625@depth@100ms","data":{"e":"depthUpdate","E":1618677484714,"T":1618677484706,"s":"BCHUSD_210625","ps":"BCHUSD","U":86143398923,"u":86143399765,"pu":86143398796,"b":[["1117.31","250"],["1117.66","0"],["1124.46","0"],["1124.91","0"],["1125.49","141"],["1125.84","0"],["1127.36","12"],["1127.78","0"],["1127.82","0"],["1127.83","0"],["1127.84","0"],["1127.85","0"],["1127.86","64"],["1127.87","35"],["1127.88","0"],["1127.89","0"],["1127.90","35"],["1127.91","0"],["1127.92","64"],["1127.93","36"]],"a":[["1129.45","0"],["1129.46","0"],["1130.09","250"],["1130.51","12"],["1131.24","0"],["1132.89","150"],["1133.15","0"],["1137.63","0"]]}}
1618677485.2864158: {"stream":"egldusd_perp@depth@100ms","data":{"e":"depthUpdate","E":1618677484731,"T":1618677484647,"s":"EGLDUSD_PERP","ps":"EGLDUSD","U":86143399073,"u":86143399235,"pu":86143398860,"b":[],"a":[["216.256","16"],["216.350","502"],["216.399","34"],["216.468","0"]]}}
1618677485.286568: {"stream":"linkusd_210625@depth@100ms","data":{"e":"depthUpdate","E":1618677484774,"T":1618677484752,"s":"LINKUSD_210625","ps":"LINKUSD","U":86143399383,"u":86143400469,"pu":86143398816,"b":[["43.258","0"],["43.282","414"],["43.608","4167"],["43.755","106"],["43.766","0"]],"a":[["44.002","20"]]}}
