1618677454.298938: {"stream":"yfiusdt@bookTicker","data":{"e":"bookTicker","u":335340778490,"s":"YFIUSDT","b":"49985.6","B":"0.055","a":"50004.1","A":"0.013","T":1618677454059,"E":1618677454064}}
1618677454.298968: {"stream":"xmrusdt@depth@100ms","data":{"e":"depthUpdate","E":1618677454070,"T":1618677454012,"s":"XMRUSDT","U":335340775007,"u":335340776577,"pu":335340770892,"b":[["351.35","0.000"],["351.37","0.000"],["351.55","184.836"],["352.34","6.019"]],"a":[["352.59","0.295"],["352.65","0.915"],["353.03","3.247"]]}}
1618677454.3002272: {"stream":"yfiusdt@bookTicker","data":{"e":"bookTicker","u":335340778965,"s":"YFIUSDT","b":"49985.7","B":"0.031","a":"50004.1","A":"0.013","T":1618677454070,"E":1618677454075}}
1618677454.3003101: {"stream":"yfiusdt@bookTicker","data":{"e":"bookTicker","u":335340779067,"s":"YFIUSDT","b":"49985.7","B":"0.031","a":"50004.3","A":"0.055","T":1618677454073,"E":1618677454076}}
1618677454.3012521: {"stream":"yfiusdt@bookTicker","data":{"e":"bookTicker","u":335340779117,"s":"YFIUSDT","b":"49985.7","B":"0.031","a":"50003.9","A":"0.012","T":1618677454076,"E":1618677454080}}
1618677454.3020601: {"stream":"dentusdt@depth@100ms","data":{"e":"depthUpdate","E":1618677454085,"T":1618677454077,"s":"DENTUSDT","U":335340775495,"u":335340779160,"pu":335340773506,"b":[],"a":[["0.012420","657620"],["0.012650","286416"]]}}
1618677454.302387: {"stream":"yfiusdt@bookTicker","data":{"e":"bookTicker","u":335340779349,"s":"YFIUSDT","b":"49985.6","B":"0.055","a":"50003.9","A":"0.012","T":1618677454083,"E":1618677454087}}
1618677454.307379: {"stream":"yfiusdt@bookTicker","data":{"e":"bookTicker","u":335340779654,"s":"YFIUSDT","b":"49985.7","B":"0.003","a":"50003.9","A":"0.012","T":1618677454095,"E":1618677454099}}
1618677454.307478: {"stream":"yfiusdt@depth@100ms","data":{"e":"depthUpdate","E":1618677454112,"T":1618677454095,"s":"YFIUSDT","U":335340776386,"u":335340779654,"pu":335340775669,"b":[["49734.6","0.000"],["49919.1","0.000"],["49923.8","0.060"],["49925.4","0.017"],["49929.6","0.000"],["49938.0","0.110"],["49942.2","0.110"],["49950.3","0.000"],["49952.5","0.259"],["49952.6","0.091"],["49966.2","0.000"],["49983.2","0.000"],["49983.3","0.020"],["49983.4","0.000"],["49985.6","0.055"],["49985.7","0.003"]],"a":[["50000.3","0.000"],["50000.4","0.000"],["50003.9","0.012"],["50004.1","0.000"],["50004.2","0.000"],["50006.1","0.000"],["50006.5","0.000"],["50008.9","0.012"],["50023.6","0.015"],["50023.7","0.000"],["50039.4","0.020"],["50039.5","0.082"],["50075.2","0.000"],["50093.0","0.052"],["50093.5","0.060"],["50134.0","0.016"]]}}
1618677454.308285: {"stream":"dentusdt@kline_1m","data":{"e":"kline","E":1618677454118,"s":"DENTUSDT","k":{"t":1618677420000,"T":1618677479999,"s":"DENTUSDT","i":"1m","f":15787262,"L":15787387,"o":"0.012366","c":"0.012350","h":"0.012366","l":"0.012339","v":"2035009","n":126,"x":false,"q":"25137.230787","V":"1043801","Q":"12896.298724","B":"0"}}}
1618677454.308343: {"stream":"dentusdt@aggTrade","data":{"e":"aggTrade","E":1618677454118,"a":8476403,"s":"DENTUSDT","p":"0.012350","q":"24514","f":15787387,"l":15787388,"T":1618677454113,"m":true}}
1618677454.308373: {"stream":"dentusdt@aggTrade","data":{"e":"aggTrade","E":1618677454118,"a":8476404,"s":"DENTUSDT","p":"0.012349","q":"54886","f":15787389,"l":15787390,"T":1618677454113,"m":true}}
1618677454.308395: {"stream":"dentusdt@aggTrade","data":{"e":"aggTrade","E":1618677454118,"a":8476405,"s":"DENTUSDT","p":"0.012348","q":"53957","f":15787391,"l":15787391,"T":1618677454113,"m":true}}
1618677454.308414: {"stream":"dentusdt@bookTicker","data":{"e":"bookTicker","u":335340779980,"s":"DENTUSDT","b":"0.012347","B":"35853","a":"0.012361","A":"55630","T":1618677454113,"E":1618677454118}}
1618677454.308434: {"stream":"ksmusdt@depth@100ms","data":{"e":"depthUpdate","E":1618677454121,"T":1618677454094,"s":"KSMUSDT","U":335340776777,"u":335340779635,"pu":335340775915,"b":[["456.380","1.5"],["458.110","1.6"],["458.158","2.3"],["458.204","2.4"],["458.229","1.1"],["458.428","0.0"],["458.497","0.0"],["458.655","0.0"],["458.719","0.0"],["458.787","0.0"],["458.844","2.5"],["458.862","0.0"],["458.863","0.2"],["458.885","0.4"],["458.911","0.2"],["458.937","1.2"],["458.967","0.0"]],"a":[["459.340","1.0"],["459.485","0.0"],["459.486","1.4"],["459.703","0.1"],["459.725","0.1"],["459.780","0.0"],["459.791","7.6"],["459.881","0.1"],["459.937","0.0"],["460.236","0.0"],["460.372","0.0"]]}}
1618677454.3113909: {"stream":"dentusdt@bookTicker","data":{"e":"bookTicker","u":335340780225,"s":"DENTUSDT","b":"0.012351","B":"8930","a":"0.012361","A":"55630","T":1618677454125,"E":1618677454129}}
1618677454.3114638: {"stream":"dentusdt@bookTicker","data":{"e":"bookTicker","u":335340780274,"s":"DENTUSDT","b":"0.012347","B":"35853","a":"0.012361","A":"55630","T":1618677454128,"E":1618677454133}}
1618677454.311491: {"stream":"yfiusdt@bookTicker","data":{"e":"bookTicker","u":335340780307,"s":"YFIUSDT","b":"49985.8","B":"0.031","a":"50003.9","A":"0.012","T":1618677454137,"E":1618677454139}}
1618677454.313515: {"stream":"dentusdt@bookTicker","data":{"e":"bookTicker","u":335340780513,"s":"DENTUSDT","b":"0.012346","B":"72910","a":"0.012361","A":"55630","T":1618677454142,"E":1618677454147}}
1618677454.3184798: {"stream":"dentusdt@bookTicker","data":{"e":"bookTicker","u":335340780801,"s":"DENTUSDT","b":"0.012346","B":"72910","a":"0.012361","A":"5843","T":1618677454161,"E":1618677454165}}
1618677454.31855: {"stream":"dentusdt@bookTicker","data":{"e":"bookTicker","u":335340780837,"s":"DENTUSDT","b":"0.012346","B":"82058","a":"0.012361","A":"5843","T":1618677454161,"E":1618677454167}}
1618677454.318578: {"stream":"dentusdt@bookTicker","data":{"e":"bookTicker","u":335340780928,"s":"DENTUSDT","b":"0.012348","B":"48561","a":"0.012361","A":"5843","T":1618677454163,"E":1618677454169}}
1618677454.31861: {"stream":"dentusdt@bookTicker","data":{"e":"bookTicker","u":335340780992,"s":"DENTUSDT","b":"0.012352","B":"9526","a":"0.012361","A":"5843","T":1618677454163,"E":1618677454170}}
1618677454.318631: {"stream":"xmrusdt@depth@100ms","data":{"e":"depthUpdate","E":1618677454175,"T":1618677454165,"s":"XMRUSDT","U":335340778984,"u":335340781083,"pu":335340776577,"b":[["348.13","4.734"],["350.89","17.462"]],"a":[["352.59","0.000"],["352.60","0.000"]]}}
1618677454.319593: {"stream":"yfiusdt@bookTicker","data":{"e":"bookTicker","u":335340781400,"s":"YFIUSDT","b":"49985.9","B":"0.003","a":"50003.9","A":"0.012","T":1618677454176,"E":1618677454180}}
1618677454.319693: {"stream":"dentusdt@bookTicker","data":{"e":"bookTicker","u":335340781506,"s":"DENTUSDT","b":"0.012348","B":"57539","a":"0.012361","A":"5843","T":1618677454179,"E":1618677454184}}
1618677454.3197381: {"stream":"yfiusdt@aggTrade","data":{"e":"aggTrade","E":1618677454187,"a":52599692,"s":"YFIUSDT","p":"50000.4","q":"0.080","f":64902170,"l":64902170,"T":1618677454032,"m":false}}
1618677454.322735: {"stream":"yfiusdt@bookTicker","data":{"e":"bookTicker","u":335340781852,"s":"YFIUSDT","b":"49986.0","B":"0.026","a":"50003.9","A":"0.012","T":1618677454186,"E":1618677454191}}
1618677454.322836: {"stream":"dentusdt@bookTicker","data":{"e":"bookTicker","u":335340782004,"s":"DENTUSDT","b":"0.012348","B":"57539","a":"0.012354","A":"31634","T":1618677454193,"E":1618677454198}}
1618677454.328894: {"stream":"dentusdt@depth@100ms","data":{"e":"depthUpdate","E":1618677454218,"T":1618677454202,"s":"DENTUSDT","U":335340779956,"u":335340782282,"pu":335340779160,"b":[["0.012325","705487"],["0.012327","496639"],["0.012328","54869"],["0.012337","27003"],["0.012340","3238"],["0.012341","9878"],["0.012342","304007"],["0.012343","101312"],["0.012346","72910"],["0.012347","0"],["0.012348","57539"],["0.012349","0"],["0.012350","0"],["0.012351","0"],["0.012352","0"]],"a":[["0.012354","31634"],["0.012360","50000"],["0.012361","113761"],["0.012362","98375"],["0.012367","400696"],["0.012368","24164"],["0.012369","57938"],["0.012371","134893"],["0.012375","16849"],["0.012379","54138"],["0.012380","12546"],["0.012381","22403"],["0.012383","373190"]]}}
1618677454.329227: {"stream":"yfiusdt@bookTicker","data":{"e":"bookTicker","u":335340782663,"s":"YFIUSDT","b":"49985.9","B":"0.003","a":"50003.9","A":"0.012","T":1618677454214,"E":1618677454219}}
1618677454.3292632: {"stream":"yfiusdt@bookTicker","data":{"e":"bookTicker","u":335340782751,"s":"YFIUSDT","b":"49985.9","B":"0.003","a":"50003.9","A":"0.023","T":1618677454216,"E":1618677454220}}
1618677454.3292868: {"stream":"yfiusdt@depth@100ms","data":{"e":"depthUpdate","E":1618677454221,"T":1618677454216,"s":"YFIUSDT","U":335340780017,"u":335340782751,"pu":335340779654,"b":[["48987.7","0.000"],["49640.3","0.004"],["49641.6","0.000"],["49649.7","0.000"],["49720.2","0.000"],["49938.7","0.000"],["49939.4","0.000"],["49943.7","0.013"],["49944.4","0.013"],["49951.7","0.000"],["49952.7","0.168"],["49975.0","0.000"],["49983.0","0.000"],["49985.6","0.000"],["49985.7","0.000"],["49985.8","0.000"],["49985.9","0.003"],["49986.0","0.000"]],"a":[["50003.9","0.023"],["50004.0","0.055"],["50008.9","0.000"],["50023.6","0.000"],["50117.2","0.000"],["50129.2","0.400"],["50258.5","0.006"],["50269.3","0.000"],["50346.7","0.005"],["50353.5","0.000"]]}}
1618677454.329497: {"stream":"dentusdt@aggTrade","data":{"e":"aggTrade","E":1618677454221,"a":8476406,"s":"DENTUSDT","p":"0.012347","q":"62708","f":15787392,"l":15787393,"T":1618677454113,"m":true}}
1618677454.329529: {"stream":"dentusdt@aggTrade","data":{"e":"aggTrade","E":1618677454221,"a":8476407,"s":"DENTUSDT","p":"0.012354","q":"31634","f":15787394,"l":15787394,"T":1618677454217,"m":false}}
1618677454.3295512: {"stream":"dentusdt@bookTicker","data":{"e":"bookTicker","u":335340782801,"s":"DENTUSDT","b":"0.012360","B":"18366","a":"0.012361","A":"113761","T":1618677454217,"E":1618677454221}}
1618677454.3295722: {"stream":"ksmusdt@depth@100ms","data":{"e":"depthUpdate","E":1618677454222,"T":1618677454199,"s":"KSMUSDT","U":335340780045,"u":335340782166,"pu":335340779635,"b":[["457.961","2.1"],["458.227","0.0"],["458.229","0.0"],["458.282","0.0"],["458.378","0.0"],["458.721","0.0"],["458.842","0.0"],["458.938","0.2"],["458.967","0.5"]],"a":[["459.351","0.1"]]}}
1618677454.329678: {"stream":"yfiusdt@bookTicker","data":{"e":"bookTicker","u":335340782849,"s":"YFIUSDT","b":"49983.3","B":"0.020","a":"50003.9","A":"0.023","T":1618677454218,"E":1618677454223}}
1618677454.3297012: {"stream":"yfiusdt@bookTicker","data":{"e":"bookTicker","u":335340782857,"s":"YFIUSDT","b":"49986.1","B":"0.003","a":"50003.9","A":"0.023","T":1618677454218,"E":1618677454224}}
1618677454.33141: {"stream":"yfiusdt@bookTicker","data":{"e":"bookTicker","u":335340783409,"s":"YFIUSDT","b":"49986.2","B":"0.017","a":"50003.9","A":"0.023","T":1618677454237,"E":1618677454242}}
1618677454.33148: {"stream":"dentusdt@aggTrade","data":{"e":"aggTrade","E":1618677454242,"a":8476408,"s":"DENTUSDT","p":"0.012360","q":"50000","f":15787395,"l":15787395,"T":1618677454217,"m":false}}
1618677454.331528: {"stream":"dentusdt@bookTicker","data":{"e":"bookTicker","u":335340783432,"s":"DENTUSDT","b":"0.012348","B":"57539","a":"0.012360","A":"10476","T":1618677454238,"E":1618677454242}}
1618677454.3315609: {"stream":"dentusdt@bookTicker","data":{"e":"bookTicker","u":335340783544,"s":"DENTUSDT","b":"0.012349","B":"24271","a":"0.012360","A":"10476","T":1618677454241,"E":1618677454245}}
1618677454.3318028: {"stream":"dentusdt@bookTicker","data":{"e":"bookTicker","u":335340783740,"s":"DENTUSDT","b":"0.012349","B":"24271","a":"0.012360","A":"28842","T":1618677454245,"E":1618677454249}}
1618677454.497267: {"stream":"yfiusdt@bookTicker","data":{"e":"bookTicker","u":335340783819,"s":"YFIUSDT","b":"49986.1","B":"0.003","a":"50003.9","A":"0.023","T":1618677454247,"E":1618677454251}}
1618677454.498061: {"stream":"yfiusdt@bookTicker","data":{"e":"bookTicker","u":335340783839,"s":"YFIUSDT","b":"49986.4","B":"0.014","a":"50003.9","A":"0.023","T":1618677454247,"E":1618677454251}}
1618677454.498122: {"stream":"dentusdt@bookTicker","data":{"e":"bookTicker","u":335340783968,"s":"DENTUSDT","b":"0.012350","B":"8846","a":"0.012360","A":"28842","T":1618677454252,"E":1618677454256}}
1618677454.498152: {"stream":"ksmusdt@bookTicker","data":{"e":"bookTicker","u":335340784202,"s":"KSMUSDT","b":"458.997","B":"0.1","a":"459.306","A":"6.4","T":1618677454257,"E":1618677454262}}
1618677454.4981802: {"stream":"ksmusdt@bookTicker","data":{"e":"bookTicker","u":335340784422,"s":"KSMUSDT","b":"458.966","B":"0.5","a":"459.306","A":"6.4","T":1618677454263,"E":1618677454267}}
1618677454.4982011: {"stream":"dentusdt@bookTicker","data":{"e":"bookTicker","u":335340784436,"s":"DENTUSDT","b":"0.012350","B":"8846","a":"0.012360","A":"34824","T":1618677454264,"E":1618677454268}}
1618677454.49822: {"stream":"dentusdt@bookTicker","data":{"e":"bookTicker","u":335340784695,"s":"DENTUSDT","b":"0.012350","B":"8846","a":"0.012360","A":"50852","T":1618677454272,"E":1618677454277}}
1618677454.4982378: {"stream":"yfiusdt@bookTicker","data":{"e":"bookTicker","u":335340784932,"s":"YFIUSDT","b":"49986.4","B":"0.014","a":"50001.5","A":"0.055","T":1618677454280,"E":1618677454286}}
1618677454.498256: {"stream":"ksmusdt@bookTicker","data":{"e":"bookTicker","u":335340785103,"s":"KSMUSDT","b":"458.966","B":"0.5","a":"459.294","A":"1.2","T":1618677454282,"E":1618677454287}}
1618677454.4982731: {"stream":"yfiusdt@bookTicker","data":{"e":"bookTicker","u":335340785501,"s":"YFIUSDT","b":"49986.5","B":"0.003","a":"50001.5","A":"0.055","T":1618677454289,"E":1618677454294}}
1618677454.498291: {"stream":"yfiusdt@bookTicker","data":{"e":"bookTicker","u":335340785665,"s":"YFIUSDT","b":"49986.5","B":"0.003","a":"49995.0","A":"0.005","T":1618677454295,"E":1618677454299}}
1618677454.4983082: {"stream":"yfiusdt@bookTicker","data":{"e":"bookTicker","u":335340785915,"s":"YFIUSDT","b":"49987.8","B":"0.006","a":"49995.0","A":"0.005","T":1618677454304,"E":1618677454305}}
1618677454.498325: {"stream":"xmrusdt@depth@100ms","data":{"e":"depthUpdate","E":1618677454319,"T":1618677454269,"s":"XMRUSDT","U":335340782666,"u":335340784627,"pu":335340781083,"b":[["350.99","16.277"]],"a":[["352.61","1.400"],["352.65","4.315"],["379.17","0.000"]]}}
1618677454.498402: {"stream":"yfiusdt@depth@100ms","data":{"e":"depthUpdate","E":1618677454321,"T":1618677454316,"s":"YFIUSDT","U":335340782787,"u":335340786360,"pu":335340782751,"b":[["49316.8","0.000"],["49320.0","0.000"],["49485.5","0.000"],["49509.3","0.000"],["49555.4","0.000"],["49629.0","0.002"],["49640.3","0.002"],["49736.7","0.004"],["49893.4","0.050"],["49981.0","0.000"],["49985.9","0.000"],["49986.0","0.000"],["49986.1","0.000"],["49986.2","0.000"],["49986.3","0.000"],["49986.4","0.000"],["49986.5","0.003"],["49987.8","0.006"]],"a":[["49995.0","0.005"],["50001.5","0.055"],["50003.9","0.012"],["50004.3","0.000"],["50007.5","0.013"],["50007.9","0.000"],["50039.8","0.003"],["50040.2","0.013"],["50040.7","0.003"],["50045.9","0.000"],["50047.2","0.000"],["50047.7","0.013"],["50052.0","0.000"],["50052.9","0.000"],["50053.4","0.000"],["50053.5","0.013"],["50059.2","0.010"],["50114.9","0.050"],["50248.4","0.012"],["50258.5","0.004"],["50262.4","0.200"],["50269.2","0.200"],["50273.3","0.200"],["50276.4","0.010"],["50301.7","0.002"],["50321.0","0.003"],["50378.9","0.009"],["50459.4","0.001"],["50510.7","0.000"],["50535.2","0.002"],["50589.4","0.000"],["50642.8","0.000"]]}}
1618677454.4987378: {"stream":"dentusdt@depth@100ms","data":{"e":"depthUpdate","E":1618677454321,"T":1618677454317,"s":"DENTUSDT","U":335340782793,"u":335340786379,"pu":335340782282,"b":[["0.012324","53723"],["0.012325","705503"],["0.012326","505950"],["0.012327","385644"],["0.012328","30588"],["0.012334","455"],["0.012338","467939"],["0.012339","3446"],["0.012342","0"],["0.012343","0"],["0.012344","81000"],["0.012345","110831"],["0.012346","0"],["0.012348","48561"],["0.012349","255669"],["0.012350","8846"],["0.012360","0"]],"a":[["0.012354","0"],["0.012360","50852"],["0.012361","0"],["0.012362","0"],["0.012367","217028"],["0.012368","57938"],["0.012369","0"],["0.012371","0"],["0.012375","5538"],["0.012382","625010"],["0.012383","49448"],["0.012385","834733"],["0.012386","80874"],["0.012388","979358"],["0.012389","217258"],["0.012394","45020"],["0.012637","4301"],["0.012877","0"],["0.012939","52347"],["0.013001","0"]]}}
1618677454.498973: {"stream":"ksmusdt@depth@100ms","data":{"e":"depthUpdate","E":1618677454323,"T":1618677454309,"s":"KSMUSDT","U":335340782843,"u":335340786111,"pu":335340782166,"b":[["457.274","0.3"],["457.482","2.0"],["457.558","0.0"],["458.021","0.0"],["458.229","1.1"],["458.438","0.0"],["458.627","24.1"],["458.885","0.2"],["458.911","0.2"],["458.937","0.0"],["458.938","0.0"],["458.967","0.0"],["458.997","0.0"]],"a":[["459.294","1.2"],["459.306","6.4"],["459.328","0.0"],["459.340","0.0"],["459.487","0.0"],["459.555","5.6"],["460.106","0.3"],["462.831","0.0"],["463.974","0.3"]]}}
1618677454.499156: {"stream":"dentusdt@bookTicker","data":{"e":"bookTicker","u":335340786851,"s":"DENTUSDT","b":"0.012350","B":"8846","a":"0.012360","A":"34824","T":1618677454336,"E":1618677454339}}
1618677454.4991841: {"stream":"dentusdt@bookTicker","data":{"e":"bookTicker","u":335340786864,"s":"DENTUSDT","b":"0.012350","B":"8846","a":"0.012360","A":"28842","T":1618677454336,"E":1618677454339}}
1618677454.499211: {"stream":"dentusdt@bookTicker","data":{"e":"bookTicker","u":335340787019,"s":"DENTUSDT","b":"0.012350","B":"8846","a":"0.012360","A":"18366","T":1618677454337,"E":1618677454340}}
1618677454.4992352: {"stream":"dentusdt@bookTicker","data":{"e":"bookTicker","u":335340787096,"s":"DENTUSDT","b":"0.012350","B":"13018","a":"0.012360","A":"18366","T":1618677454340,"E":1618677454342}}
1618677454.499265: {"stream":"ksmusdt@bookTicker","data":{"e":"bookTicker","u":335340787264,"s":"KSMUSDT","b":"458.997","B":"0.1","a":"459.294","A":"1.2","T":1618677454347,"E":1618677454351}}
1618677454.499279: {"stream":"dentusdt@aggTrade","data":{"e":"aggTrade","E":1618677454393,"a":8476409,"s":"DENTUSDT","p":"0.012360","q":"18366","f":15787396,"l":15787396,"T":1618677454238,"m":true}}
1618677454.499299: {"stream":"dentusdt@bookTicker","data":{"e":"bookTicker","u":335340789004,"s":"DENTUSDT","b":"0.012350","B":"230046","a":"0.012360","A":"18366","T":1618677454401,"E":1618677454404}}
1618677454.4993129: {"stream":"ksmusdt@bookTicker","data":{"e":"bookTicker","u":335340789185,"s":"KSMUSDT","b":"459.145","B":"0.2","a":"459.294","A":"1.2","T":1618677454407,"E":1618677454411}}
1618677454.499327: {"stream":"ksmusdt@bookTicker","data":{"e":"bookTicker","u":335340789594,"s":"KSMUSDT","b":"459.145","B":"0.2","a":"459.306","A":"6.4","T":1618677454418,"E":1618677454422}}
1618677454.499341: {"stream":"dentusdt@depth@100ms","data":{"e":"depthUpdate","E":1618677454424,"T":1618677454412,"s":"DENTUSDT","U":335340786473,"u":335340789320,"pu":335340786379,"b":[["0.012328","71433"],["0.012350","230046"]],"a":[["0.012360","18366"],["0.012362","133964"],["0.012368","57938"],["0.012371","49787"],["0.012379","50901"],["0.012381","76362"],["0.012392","1847"],["0.012395","155666"],["0.012753","10029"],["0.012815","1516066"]]}}
1618677454.49941: {"stream":"yfiusdt@depth@100ms","data":{"e":"depthUpdate","E":1618677454426,"T":1618677454422,"s":"YFIUSDT","U":335340786513,"u":335340789725,"pu":335340786360,"b":[["49388.3","0.000"],["49589.0","0.009"],["49645.8","0.002"],["49659.9","0.000"],["49716.6","0.000"],["49730.7","0.001"],["49735.8","0.200"],["49880.2","0.000"],["49902.6","0.210"],["49931.6","0.070"],["49950.7","0.000"],["49964.3","0.027"],["49967.4","0.012"],["49982.8","0.000"],["49983.3","0.000"],["49986.5","0.000"]],"a":[["50039.8","0.001"],["50040.7","0.001"],["50092.3","0.010"],["50148.6","0.007"],["50249.9","0.004"],["50258.5","0.000"],["50266.9","0.000"],["50272.1","0.000"],["50280.1","0.200"],["50283.2","0.000"],["50301.7","0.000"],["50335.1","0.002"],["50380.3","0.000"]]}}
1618677454.4995682: {"stream":"xmrusdt@depth@100ms","data":{"e":"depthUpdate","E":1618677454439,"T":1618677454337,"s":"XMRUSDT","U":335340786967,"u":335340786969,"pu":335340784627,"b":[],"a":[["352.64","0.095"],["352.66","4.255"]]}}
1618677454.4996018: {"stream":"ksmusdt@depth@100ms","data":{"e":"depthUpdate","E":1618677454439,"T":1618677454418,"s":"KSMUSDT","U":335340786854,"u":335340789610,"pu":335340786111,"b":[["453.805","4.5"],["455.848","5.2"],["457.441","0.8"],["458.229","1.1"],["458.901","0.2"],["458.911","0.0"],["458.997","0.1"],["459.145","0.2"]],"a":[["459.294","0.0"],["459.341","1.2"],["459.363","0.0"],["459.486","0.0"],["459.538","1.4"],["460.244","0.0"]]}}
1618677454.5189419: {"stream":"dentusdt@bookTicker","data":{"e":"bookTicker","u":335340790802,"s":"DENTUSDT","b":"0.012350","B":"225874","a":"0.012360","A":"18366","T":1618677454456,"E":1618677454458}}
1618677454.5250292: {"stream":"ksmusdt@kline_1m","data":{"e":"kline","E":1618677454464,"s":"KSMUSDT","k":{"t":1618677420000,"T":1618677479999,"s":"KSMUSDT","i":"1m","f":25426460,"L":25426561,"o":"459.607","c":"459.145","h":"459.671","l":"458.391","v":"100.8","n":102,"x":false,"q":"46271.9498","V":"51.4","Q":"23604.9943","B":"0"}}}
1618677454.525167: {"stream":"ksmusdt@aggTrade","data":{"e":"aggTrade","E":1618677454464,"a":21396968,"s":"KSMUSDT","p":"459.145","q":"0.2","f":25426561,"l":25426561,"T":1618677454459,"m":true}}
1618677454.525223: {"stream":"ksmusdt@aggTrade","data":{"e":"aggTrade","E":1618677454464,"a":21396969,"s":"KSMUSDT","p":"458.997","q":"0.1","f":25426562,"l":25426562,"T":1618677454459,"m":true}}
1618677454.525246: {"stream":"ksmusdt@aggTrade","data":{"e":"aggTrade","E":1618677454464,"a":21396970,"s":"KSMUSDT","p":"458.966","q":"0.5","f":25426563,"l":25426563,"T":1618677454459,"m":true}}
1618677454.525267: {"stream":"ksmusdt@aggTrade","data":{"e":"aggTrade","E":1618677454464,"a":21396971,"s":"KSMUSDT","p":"458.911","q":"0.2","f":25426564,"l":25426564,"T":1618677454459,"m":true}}
1618677454.525286: {"stream":"ksmusdt@aggTrade","data":{"e":"aggTrade","E":1618677454464,"a":21396972,"s":"KSMUSDT","p":"458.910","q":"0.1","f":25426565,"l":25426565,"T":1618677454459,"m":true}}
1618677454.525304: {"stream":"ksmusdt@aggTrade","data":{"e":"aggTrade","E":1618677454464,"a":21396973,"s":"KSMUSDT","p":"458.901","q":"0.2","f":25426566,"l":25426566,"T":1618677454459,"m":true}}
1618677454.525322: {"stream":"ksmusdt@aggTrade","data":{"e":"aggTrade","E":1618677454464,"a":21396974,"s":"KSMUSDT","p":"458.900","q":"0.5","f":25426567,"l":25426567,"T":1618677454459,"m":true}}
1618677454.5253398: {"stream":"ksmusdt@aggTrade","data":{"e":"aggTrade","E":1618677454464,"a":21396975,"s":"KSMUSDT","p":"458.885","q":"0.2","f":25426568,"l":25426568,"T":1618677454459,"m":true}}
1618677454.525358: {"stream":"ksmusdt@bookTicker","data":{"e":"bookTicker","u":335340790973,"s":"KSMUSDT","b":"458.863","B":"0.1","a":"459.306","A":"6.4","T":1618677454459,"E":1618677454464}}
1618677454.526155: {"stream":"xmrusdt@bookTicker","data":{"e":"bookTicker","u":335340791089,"s":"XMRUSDT","b":"352.48","B":"7.438","a":"352.49","A":"2.358","T":1618677454463,"E":1618677454467}}
1618677454.529779: {"stream":"ksmusdt@bookTicker","data":{"e":"bookTicker","u":335340791262,"s":"KSMUSDT","b":"458.863","B":"0.1","a":"459.226","A":"0.1","T":1618677454468,"E":1618677454471}}
1618677454.529898: {"stream":"ksmusdt@bookTicker","data":{"e":"bookTicker","u":335340791353,"s":"KSMUSDT","b":"458.885","B":"0.2","a":"459.226","A":"0.1","T":1618677454471,"E":1618677454473}}
1618677454.541355: {"stream":"ksmusdt@bookTicker","data":{"e":"bookTicker","u":335340791694,"s":"KSMUSDT","b":"458.863","B":"1.3","a":"459.226","A":"0.1","T":1618677454478,"E":1618677454482}}
1618677454.54143: {"stream":"ksmusdt@bookTicker","data":{"e":"bookTicker","u":335340791704,"s":"KSMUSDT","b":"458.863","B":"0.1","a":"459.226","A":"0.1","T":1618677454479,"E":1618677454482}}
1618677454.541683: {"stream":"ksmusdt@bookTicker","data":{"e":"bookTicker","u":335340791718,"s":"KSMUSDT","b":"458.894","B":"1.2","a":"459.226","A":"0.1","T":1618677454479,"E":1618677454484}}
1618677454.5538938: {"stream":"ksmusdt@bookTicker","data":{"e":"bookTicker","u":335340792083,"s":"KSMUSDT","b":"458.894","B":"1.2","a":"459.204","A":"6.4","T":1618677454492,"E":1618677454497}}
1618677454.566933: {"stream":"ksmusdt@bookTicker","data":{"e":"bookTicker","u":335340792472,"s":"KSMUSDT","b":"458.863","B":"0.1","a":"459.204","A":"6.4","T":1618677454503,"E":1618677454507}}
1618677454.567035: {"stream":"ksmusdt@bookTicker","data":{"e":"bookTicker","u":335340792513,"s":"KSMUSDT","b":"458.863","B":"0.1","a":"459.194","A":"1.2","T":1618677454505,"E":1618677454507}}
1618677454.574042: {"stream":"ksmusdt@bookTicker","data":{"e":"bookTicker","u":335340792778,"s":"KSMUSDT","b":"458.886","B":"0.2","a":"459.194","A":"1.2","T":1618677454512,"E":1618677454517}}
1618677454.586792: {"stream":"ksmusdt@bookTicker","data":{"e":"bookTicker","u":335340793147,"s":"KSMUSDT","b":"458.886","B":"0.2","a":"459.193","A":"0.3","T":1618677454523,"E":1618677454527}}
1618677454.586896: {"stream":"dentusdt@bookTicker","data":{"e":"bookTicker","u":335340793201,"s":"DENTUSDT","b":"0.012350","B":"225874","a":"0.012360","A":"17393","T":1618677454524,"E":1618677454527}}
1618677454.586941: {"stream":"dentusdt@kline_1m","data":{"e":"kline","E":1618677454528,"s":"DENTUSDT","k":{"t":1618677420000,"T":1618677479999,"s":"DENTUSDT","i":"1m","f":15787262,"L":15787397,"o":"0.012366","c":"0.012360","h":"0.012366","l":"0.012339","v":"2326934","n":136,"x":false,"q":"28742.973539","V":"1126408","Q":"13917.131440","B":"0"}}}
1618677454.587023: {"stream":"ksmusdt@bookTicker","data":{"e":"bookTicker","u":335340793243,"s":"KSMUSDT","b":"459.058","B":"1.5","a":"459.193","A":"0.3","T":1618677454526,"E":1618677454531}}
1618677454.59085: {"stream":"yfiusdt@depth@100ms","data":{"e":"depthUpdate","E":1618677454534,"T":1618677454527,"s":"YFIUSDT","U":335340790025,"u":335340793267,"pu":335340789725,"b":[["49633.4","0.006"],["49634.3","0.000"],["49641.4","0.000"],["49731.1","0.000"],["49734.7","0.000"],["49736.7","0.002"],["49904.4","0.004"],["49952.7","0.000"],["49964.3","0.024"],["49967.4","0.000"],["49967.5","0.000"],["49970.6","0.012"],["49970.7","0.003"]],"a":[["50039.8","0.000"],["50040.7","0.000"],["50050.0","0.002"],["50051.6","0.003"],["50052.5","0.003"],["50059.6","0.000"],["50086.4","0.004"],["50248.4","0.006"],["50302.5","0.000"],["50346.9","0.000"]]}}
1618677454.611032: {"stream":"ksmusdt@depth@100ms","data":{"e":"depthUpdate","E":1618677454552,"T":1618677454541,"s":"KSMUSDT","U":335340790576,"u":335340793624,"pu":335340789610,"b":[["454.296","0.2"],["454.924","0.0"],["455.224","3.7"],["457.572","2.4"],["457.697","3.2"],["458.000","0.0"],["458.215","0.0"],["458.229","1.1"],["458.404","1.9"],["458.626","0.0"],["458.627","0.0"],["458.663","0.0"],["458.733","0.0"],["458.734","0.3"],["458.751","0.3"],["458.752","1.5"],["458.757","0.0"],["458.843","2.6"],["458.844","0.0"],["458.863","0.1"],["458.885","0.0"],["458.886","0.2"],["458.894","0.0"],["458.899","1.2"],["458.900","0.0"],["458.901","0.0"],["458.910","0.0"],["458.911","0.0"],["458.966","0.0"],["458.997","0.0"],["459.058","1.5"],["459.145","0.0"]],"a":[["459.193","0.3"],["459.194","0.0"],["459.204","6.4"],["459.219","0.0"],["459.226","0.1"],["459.248","5.0"],["459.275","0.0"],["459.302","0.0"],["459.305","6.5"],["459.341","0.0"],["459.537","0.0"],["459.555","0.0"],["459.634","0.0"],["459.658","0.0"],["460.269","3.2"],["460.314","0.0"],["460.574","0.0"],["460.659","0.0"],["460.757","0.0"],["462.944","0.0"],["463.044","0.2"],["464.816","0.2"],["465.010","0.2"],["466.698","0.0"]]}}
1618677454.615933: {"stream":"dentusdt@depth@100ms","data":{"e":"depthUpdate","E":1618677454558,"T":1618677454540,"s":"DENTUSDT","U":335340790802,"u":335340793610,"pu":335340789320,"b":[["0.012290","186326"],["0.012350","225874"]],"a":[["0.012360","17393"],["0.012361","6785"],["0.012385","873599"],["0.012426","171565"]]}}
1618677454.622934: {"stream":"ksmusdt@bookTicker","data":{"e":"bookTicker","u":335340794213,"s":"KSMUSDT","b":"458.899","B":"1.2","a":"459.193","A":"0.3","T":1618677454558,"E":1618677454563}}
1618677454.6258109: {"stream":"xmrusdt@depth@100ms","data":{"e":"depthUpdate","E":1618677454567,"T":1618677454463,"s":"XMRUSDT","U":335340791089,"u":335340791089,"pu":335340786969,"b":[["352.48","7.438"]],"a":[]}}
1618677454.632611: {"stream":"ksmusdt@bookTicker","data":{"e":"bookTicker","u":335340794621,"s":"KSMUSDT","b":"458.886","B":"0.2","a":"459.193","A":"0.3","T":1618677454570,"E":1618677454573}}
1618677454.66432: {"stream":"ksmusdt@bookTicker","data":{"e":"bookTicker","u":335340795544,"s":"KSMUSDT","b":"459.089","B":"1.5","a":"459.193","A":"0.3","T":1618677454602,"E":1618677454606}}
1618677454.670779: {"stream":"ksmusdt@aggTrade","data":{"e":"aggTrade","E":1618677454615,"a":21396976,"s":"KSMUSDT","p":"458.863","q":"0.1","f":25426569,"l":25426569,"T":1618677454459,"m":true}}
1618677454.674083: {"stream":"ksmusdt@bookTicker","data":{"e":"bookTicker","u":335340795895,"s":"KSMUSDT","b":"459.089","B":"1.5","a":"459.192","A":"1.5","T":1618677454613,"E":1618677454617}}
1618677454.674185: {"stream":"ksmusdt@bookTicker","data":{"e":"bookTicker","u":335340795911,"s":"KSMUSDT","b":"458.886","B":"0.2","a":"459.192","A":"1.5","T":1618677454613,"E":1618677454617}}
1618677454.674228: {"stream":"ksmusdt@bookTicker","data":{"e":"bookTicker","u":335340795919,"s":"KSMUSDT","b":"458.886","B":"0.2","a":"459.192","A":"2.7","T":1618677454614,"E":1618677454617}}
1618677454.674643: {"stream":"dentusdt@aggTrade","data":{"e":"aggTrade","E":1618677454618,"a":8476410,"s":"DENTUSDT","p":"0.012360","q":"973","f":15787397,"l":15787397,"T":1618677454524,"m":false}}
1618677454.712521: {"stream":"dentusdt@bookTicker","data":{"e":"bookTicker","u":335340795946,"s":"DENTUSDT","b":"0.012350","B":"217782","a":"0.012360","A":"17393","T":1618677454614,"E":1618677454618}}
1618677454.712595: {"stream":"ksmusdt@bookTicker","data":{"e":"bookTicker","u":335340795987,"s":"KSMUSDT","b":"458.894","B":"1.2","a":"459.192","A":"2.7","T":1618677454615,"E":1618677454619}}
1618677454.712624: {"stream":"ksmusdt@bookTicker","data":{"e":"bookTicker","u":335340796328,"s":"KSMUSDT","b":"458.886","B":"0.2","a":"459.192","A":"2.7","T":1618677454624,"E":1618677454629}}
1618677454.7126458: {"stream":"ksmusdt@bookTicker","data":{"e":"bookTicker","u":335340796354,"s":"KSMUSDT","b":"458.886","B":"0.2","a":"459.161","A":"1.2","T":1618677454625,"E":1618677454629}}
1618677454.712665: {"stream":"dentusdt@bookTicker","data":{"e":"bookTicker","u":335340796366,"s":"DENTUSDT","b":"0.012350","B":"217782","a":"0.012359","A":"9090","T":1618677454626,"E":1618677454629}}
1618677454.712684: {"stream":"yfiusdt@kline_1m","data":{"e":"kline","E":1618677454637,"s":"YFIUSDT","k":{"t":1618677420000,"T":1618677479999,"s":"YFIUSDT","i":"1m","f":64902095,"L":64902171,"o":"50010.8","c":"49995.0","h":"50044.2","l":"49950.6","v":"0.945","n":77,"x":false,"q":"47249.6288","V":"0.640","Q":"32000.2104","B":"0"}}}
1618677454.712737: {"stream":"yfiusdt@bookTicker","data":{"e":"bookTicker","u":335340796557,"s":"YFIUSDT","b":"49987.8","B":"0.006","a":"50001.4","A":"0.123","T":1618677454633,"E":1618677454637}}
1618677454.712759: {"stream":"ksmusdt@bookTicker","data":{"e":"bookTicker","u":335340796736,"s":"KSMUSDT","b":"458.886","B":"0.2","a":"459.160","A":"0.3","T":1618677454639,"E":1618677454643}}
1618677454.712776: {"stream":"ksmusdt@bookTicker","data":{"e":"bookTicker","u":335340796780,"s":"KSMUSDT","b":"458.886","B":"0.2","a":"459.139","A":"6.4","T":1618677454640,"E":1618677454645}}
1618677454.712793: {"stream":"yfiusdt@depth@100ms","data":{"e":"depthUpdate","E":1618677454649,"T":1618677454643,"s":"YFIUSDT","U":335340793830,"u":335340796856,"pu":335340793267,"b":[["49431.0","0.000"],["49459.2","0.028"],["49530.0","0.022"],["49555.5","0.002"],["49736.7","0.000"],["49895.1","0.100"],["49947.3","0.000"],["49949.2","0.031"],["49952.5","0.000"],["49964.4","0.012"],["49970.6","0.000"],["49970.7","0.000"],["49971.6","0.000"],["49973.8","0.000"],["49973.9","0.003"],["50251.5","0.000"]],"a":[["49995.0","0.000"],["50001.4","0.123"],["50040.2","0.000"],["50043.0","0.011"],["50047.7","0.000"],["50050.5","0.011"],["50051.1","0.021"],["50053.5","0.000"],["50056.3","0.011"],["50230.7","0.042"],["50301.9","0.000"],["50444.2","0.004"],["50449.3","0.000"],["50544.2","0.008"],["50549.4","0.004"],["50644.3","0.002"]]}}
1618677454.716515: {"stream":"ksmusdt@bookTicker","data":{"e":"bookTicker","u":335340797141,"s":"KSMUSDT","b":"458.886","B":"0.2","a":"459.122","A":"1.2","T":1618677454653,"E":1618677454659}}
1618677454.7186902: {"stream":"ksmusdt@depth@100ms","data":{"e":"depthUpdate","E":1618677454661,"T":1618677454653,"s":"KSMUSDT","U":335340794153,"u":335340797141,"pu":335340793624,"b":[["453.357","0.2"],["453.378","0.2"],["454.274","0.2"],["454.296","0.4"],["455.214","0.4"],["457.669","0.0"],["457.995","1.9"],["458.187","0.0"],["458.203","0.0"],["458.229","1.1"],["458.610","5.5"],["458.734","0.0"],["458.753","2.6"],["458.786","0.3"],["458.844","0.0"],["458.856","0.0"],["458.863","0.0"],["458.864","0.0"],["458.894","0.0"],["458.899","0.0"],["459.058","0.0"],["459.089","0.0"]],"a":[["459.122","1.2"],["459.139","6.4"],["459.160","0.3"],["459.161","0.0"],["459.192","2.7"],["459.193","0.0"],["459.205","0.0"],["459.306","0.0"],["459.331","0.6"],["459.538","0.0"],["459.741","2.6"],["460.087","3.1"],["460.182","10.9"],["460.557","0.0"],["463.038","0.2"],["463.897","0.2"]]}}
1618677454.7253299: {"stream":"yfiusdt@bookTicker","data":{"e":"bookTicker","u":335340797476,"s":"YFIUSDT","b":"49987.8","B":"0.006","a":"49999.0","A":"0.055","T":1618677454664,"E":1618677454668}}
1618677454.7325451: {"stream":"ksmusdt@bookTicker","data":{"e":"bookTicker","u":335340797645,"s":"KSMUSDT","b":"458.886","B":"0.2","a":"459.121","A":"1.6","T":1618677454671,"E":1618677454674}}
1618677454.732629: {"stream":"yfiusdt@bookTicker","data":{"e":"bookTicker","u":335340797752,"s":"YFIUSDT","b":"49987.8","B":"0.006","a":"49998.9","A":"0.140","T":1618677454673,"E":1618677454677}}
1618677454.737489: {"stream":"yfiusdt@bookTicker","data":{"e":"bookTicker","u":335340797841,"s":"YFIUSDT","b":"49987.8","B":"0.006","a":"49994.6","A":"0.001","T":1618677454677,"E":1618677454680}}
1618677454.742778: {"stream":"yfiusdt@bookTicker","data":{"e":"bookTicker","u":335340797943,"s":"YFIUSDT","b":"49964.4","B":"0.012","a":"49994.6","A":"0.001","T":1618677454681,"E":1618677454683}}
1618677454.742883: {"stream":"ksmusdt@bookTicker","data":{"e":"bookTicker","u":335340798015,"s":"KSMUSDT","b":"458.886","B":"0.2","a":"459.120","A":"0.3","T":1618677454682,"E":1618677454685}}
1618677454.747961: {"stream":"ksmusdt@bookTicker","data":{"e":"bookTicker","u":335340798100,"s":"KSMUSDT","b":"458.886","B":"0.2","a":"459.099","A":"6.4","T":1618677454686,"E":1618677454689}}
1618677454.758719: {"stream":"yfiusdt@bookTicker","data":{"e":"bookTicker","u":335340798326,"s":"YFIUSDT","b":"49964.5","B":"0.010","a":"49994.6","A":"0.001","T":1618677454695,"E":1618677454700}}
1618677454.765047: {"stream":"yfiusdt@bookTicker","data":{"e":"bookTicker","u":335340798548,"s":"YFIUSDT","b":"49964.5","B":"0.013","a":"49994.6","A":"0.001","T":1618677454703,"E":1618677454708}}
1618677454.7693498: {"stream":"yfiusdt@bookTicker","data":{"e":"bookTicker","u":335340798783,"s":"YFIUSDT","b":"49964.5","B":"0.013","a":"49992.2","A":"0.055","T":1618677454708,"E":1618677454712}}
1618677454.7746902: {"stream":"dentusdt@depth@100ms","data":{"e":"depthUpdate","E":1618677454718,"T":1618677454699,"s":"DENTUSDT","U":335340795946,"u":335340798423,"pu":335340793610,"b":[["0.012290","182154"],["0.012350","217782"]],"a":[["0.012359","9090"],["0.012361","60746"],["0.012362","80005"],["0.012367","266815"],["0.012371","0"]]}}
1618677454.7790022: {"stream":"yfiusdt@bookTicker","data":{"e":"bookTicker","u":335340799064,"s":"YFIUSDT","b":"49964.5","B":"0.003","a":"49992.2","A":"0.055","T":1618677454717,"E":1618677454722}}
1618677454.7795572: {"stream":"yfiusdt@bookTicker","data":{"e":"bookTicker","u":335340799089,"s":"YFIUSDT","b":"49964.6","B":"0.003","a":"49992.2","A":"0.055","T":1618677454718,"E":1618677454723}}
1618677454.779635: {"stream":"ksmusdt@bookTicker","data":{"e":"bookTicker","u":335340799114,"s":"KSMUSDT","b":"458.886","B":"0.2","a":"459.098","A":"0.3","T":1618677454718,"E":1618677454723}}
1618677454.792887: {"stream":"yfiusdt@bookTicker","data":{"e":"bookTicker","u":335340799545,"s":"YFIUSDT","b":"49964.6","B":"0.008","a":"49992.2","A":"0.055","T":1618677454732,"E":1618677454736}}
1618677454.793479: {"stream":"yfiusdt@bookTicker","data":{"e":"bookTicker","u":335340799583,"s":"YFIUSDT","b":"49964.6","B":"0.005","a":"49992.2","A":"0.055","T":1618677454733,"E":1618677454738}}
1618677454.793561: {"stream":"yfiusdt@bookTicker","data":{"e":"bookTicker","u":335340799600,"s":"YFIUSDT","b":"49964.7","B":"0.006","a":"49992.2","A":"0.055","T":1618677454733,"E":1618677454738}}
1618677454.8079062: {"stream":"yfiusdt@depth@100ms","data":{"e":"depthUpdate","E":1618677454750,"T":1618677454742,"s":"YFIUSDT","U":335340796910,"u":335340799898,"pu":335340796856,"b":[["49435.6","0.000"],["49528.4","0.004"],["49531.1","0.000"],["49531.3","0.004"],["49541.0","0.002"],["49551.1","0.004"],["49631.1","0.000"],["49631.3","0.002"],["49634.6","0.000"],["49651.2","0.002"],["49655.7","0.002"],["49659.0","0.000"],["49769.0","0.016"],["49788.9","0.017"],["49893.4","0.000"],["49898.3","0.134"],["49904.4","0.114"],["49908.6","0.110"],["49911.0","0.080"],["49912.8","0.110"],["49931.2","0.000"],["49933.8","0.000"],["49935.5","0.130"],["49936.4","0.000"],["49938.0","0.000"],["49938.7","0.007"],["49939.1","0.018"],["49939.5","0.007"],["49942.2","0.000"],["49943.7","0.000"],["49943.8","0.000"],["49944.1","0.000"],["49944.4","0.000"],["49949.1","0.000"],["49949.2","0.009"],["49951.6","0.000"],["49952.6","0.000"],["49959.6","0.013"],["49961.8","0.000"],["49962.5","0.000"],["49964.2","0.000"],["49964.3","0.000"],["49964.4","0.012"],["49964.5","0.003"],["49964.6","0.005"],["49964.7","0.006"],["49973.9","0.000"],["49987.8","0.000"]],"a":[["49992.2","0.055"],["49994.6","0.001"],["49997.1","0.013"],["49997.6","0.009"],["49998.9","0.140"],["49999.0","0.055"],["50001.5","0.000"],["50001.8","0.000"],["50003.9","0.000"],["50004.0","0.000"],["50004.7","0.000"],["50007.5","0.000"],["50032.3","0.018"],["50036.7","0.005"],["50041.1","0.005"],["50043.0","0.000"],["50043.1","0.001"],["50044.0","0.003"],["50044.2","0.005"],["50050.0","0.012"],["50050.5","0.000"],["50051.6","0.000"],["50052.5","0.000"],["50056.3","0.000"],["50108.9","0.401"],["50114.9","0.000"],["50116.7","0.025"],["50129.2","0.000"],["50444.2","0.002"],["50484.1","0.000"],["50544.2","0.006"],["50584.2","0.000"],["50644.3","0.000"]]}}
1618677454.808935: {"stream":"yfiusdt@bookTicker","data":{"e":"bookTicker","u":335340800022,"s":"YFIUSDT","b":"49964.7","B":"0.008","a":"49992.2","A":"0.055","T":1618677454747,"E":1618677454752}}
1618677454.8217402: {"stream":"yfiusdt@bookTicker","data":{"e":"bookTicker","u":335340800401,"s":"YFIUSDT","b":"49964.7","B":"0.002","a":"49992.2","A":"0.055","T":1618677454760,"E":1618677454765}}
1618677454.821842: {"stream":"yfiusdt@bookTicker","data":{"e":"bookTicker","u":335340800406,"s":"YFIUSDT","b":"49964.5","B":"0.003","a":"49992.2","A":"0.055","T":1618677454760,"E":1618677454765}}
1618677454.823842: {"stream":"ksmusdt@aggTrade","data":{"e":"aggTrade","E":1618677454768,"a":21396977,"s":"KSMUSDT","p":"459.089","q":"1.5","f":25426570,"l":25426570,"T":1618677454613,"m":true}}
1618677454.8248892: {"stream":"dentusdt@aggTrade","data":{"e":"aggTrade","E":1618677454769,"a":8476411,"s":"DENTUSDT","p":"0.012350","q":"8092","f":15787398,"l":15787398,"T":1618677454614,"m":true}}
1618677454.82721: {"stream":"yfiusdt@bookTicker","data":{"e":"bookTicker","u":335340800584,"s":"YFIUSDT","b":"49964.4","B":"0.012","a":"49992.2","A":"0.055","T":1618677454767,"E":1618677454770}}
1618677454.8273091: {"stream":"ksmusdt@depth@100ms","data":{"e":"depthUpdate","E":1618677454771,"T":1618677454765,"s":"KSMUSDT","U":335340797586,"u":335340800532,"pu":335340797141,"b":[["454.274","0.4"],["454.924","0.2"],["455.192","0.2"],["456.618","0.2"],["457.950","11.1"],["458.128","0.0"],["458.159","1.1"],["458.204","0.0"],["458.221","0.0"],["458.228","0.0"],["458.229","0.0"],["458.592","1.4"],["458.611","0.3"],["458.753","1.3"],["458.786","0.0"]],"a":[["459.098","0.3"],["459.099","6.4"],["459.108","1.2"],["459.120","0.0"],["459.121","1.6"],["459.122","0.0"],["459.160","0.0"],["459.204","0.0"],["459.741","1.0"],["460.014","0.0"],["460.087","2.7"],["460.224","2.3"],["460.336","1.9"],["463.044","0.4"],["463.957","0.2"],["463.963","0.2"],["465.298","0.6"]]}}
1618677454.829181: {"stream":"yfiusdt@bookTicker","data":{"e":"bookTicker","u":335340800611,"s":"YFIUSDT","b":"49964.8","B":"0.003","a":"49992.2","A":"0.055","T":1618677454767,"E":1618677454772}}
1618677454.8431182: {"stream":"ksmusdt@bookTicker","data":{"e":"bookTicker","u":335340800958,"s":"KSMUSDT","b":"458.886","B":"0.2","a":"459.097","A":"1.6","T":1618677454780,"E":1618677454785}}
1618677454.843605: {"stream":"yfiusdt@aggTrade","data":{"e":"aggTrade","E":1618677454788,"a":52599693,"s":"YFIUSDT","p":"49995.0","q":"0.005","f":64902171,"l":64902171,"T":1618677454633,"m":false}}
1618677454.846624: {"stream":"dentusdt@bookTicker","data":{"e":"bookTicker","u":335340801079,"s":"DENTUSDT","b":"0.012350","B":"217782","a":"0.012359","A":"63047","T":1618677454785,"E":1618677454789}}
1618677454.852663: {"stream":"ksmusdt@bookTicker","data":{"e":"bookTicker","u":335340801295,"s":"KSMUSDT","b":"458.886","B":"0.2","a":"459.096","A":"0.3","T":1618677454792,"E":1618677454796}}
1618677454.8527622: {"stream":"xmrusdt@depth@100ms","data":{"e":"depthUpdate","E":1618677454797,"T":1618677454782,"s":"XMRUSDT","U":335340798281,"u":335340801015,"pu":335340791089,"b":[["351.56","36.945"],["351.61","17.305"]],"a":[["352.96","32.469"],["353.00","0.000"],["353.35","214.778"],["353.40","2.886"],["353.72","38.845"],["353.80","0.000"]]}}
1618677454.858071: {"stream":"ksmusdt@bookTicker","data":{"e":"bookTicker","u":335340801419,"s":"KSMUSDT","b":"458.886","B":"0.2","a":"459.075","A":"6.4","T":1618677454796,"E":1618677454800}}
1618677454.8676531: {"stream":"dentusdt@bookTicker","data":{"e":"bookTicker","u":335340801673,"s":"DENTUSDT","b":"0.012350","B":"217782","a":"0.012355","A":"2598","T":1618677454805,"E":1618677454809}}
1618677454.882485: {"stream":"dentusdt@depth@100ms","data":{"e":"depthUpdate","E":1618677454825,"T":1618677454819,"s":"DENTUSDT","U":335340799180,"u":335340802100,"pu":335340798423,"b":[["0.012309","47025"],["0.012318","154797"],["0.012348","0"]],"a":[["0.012355","2598"],["0.012356","9217"],["0.012359","53957"],["0.012361","140666"],["0.012362","26048"],["0.012367","274966"],["0.012368","0"],["0.012380","0"],["0.012381","81066"],["0.012394","4641"],["0.012401","152605"],["0.012411","48743"]]}}
1618677454.886493: {"stream":"ksmusdt@kline_1m","data":{"e":"kline","E":1618677454827,"s":"KSMUSDT","k":{"t":1618677420000,"T":1618677479999,"s":"KSMUSDT","i":"1m","f":25426460,"L":25426571,"o":"459.607","c":"458.919","h":"459.671","l":"458.391","v":"105.4","n":112,"x":false,"q":"48383.2355","V":"51.4","Q":"23604.9943","B":"0"}}}
1618677454.886875: {"stream":"ksmusdt@bookTicker","data":{"e":"bookTicker","u":335340802222,"s":"KSMUSDT","b":"458.919","B":"1.5","a":"459.075","A":"6.4","T":1618677454825,"E":1618677454827}}
1618677454.88694: {"stream":"ksmusdt@bookTicker","data":{"e":"bookTicker","u":335340802229,"s":"KSMUSDT","b":"458.919","B":"0.3","a":"459.075","A":"6.4","T":1618677454825,"E":1618677454827}}
1618677454.887784: {"stream":"ksmusdt@bookTicker","data":{"e":"bookTicker","u":335340802302,"s":"KSMUSDT","b":"458.919","B":"0.3","a":"459.074","A":"0.3","T":1618677454826,"E":1618677454831}}
1618677454.890264: {"stream":"ksmusdt@bookTicker","data":{"e":"bookTicker","u":335340802328,"s":"KSMUSDT","b":"458.886","B":"0.2","a":"459.074","A":"0.3","T":1618677454828,"E":1618677454831}}
1618677454.9084558: {"stream":"yfiusdt@depth@100ms","data":{"e":"depthUpdate","E":1618677454850,"T":1618677454842,"s":"YFIUSDT","U":335340800013,"u":335340802702,"pu":335340799898,"b":[["49534.7","0.000"],["49591.2","0.027"],["49629.0","0.000"],["49645.8","0.000"],["49655.4","0.023"],["49728.8","0.000"],["49733.5","0.000"],["49919.8","0.000"],["49919.9","0.000"],["49927.9","0.036"],["49931.2","0.036"],["49932.0","0.036"],["49935.4","0.026"],["49935.5","0.000"],["49935.6","0.168"],["49936.5","0.000"],["49938.7","0.000"],["49939.1","0.000"],["49939.5","0.000"],["49939.8","0.000"],["49940.6","0.000"],["49941.6","0.278"],["49941.7","0.130"],["49955.6","0.013"],["49959.6","0.000"],["49964.5","0.000"],["49964.6","0.000"],["49964.7","0.000"],["49964.8","0.003"]],"a":[["49993.6","0.013"],["49997.0","0.040"],["49997.1","0.000"],["50030.0","0.017"],["50035.0","0.017"],["50120.0","0.035"],["50133.0","0.000"],["50134.0","0.000"],["50156.3","0.019"],["50208.3","0.020"],["50249.9","0.000"],["50282.5","0.000"],["50335.1","0.000"],["50345.5","0.000"],["50368.2","0.000"],["50449.7","0.004"],["50467.8","0.000"],["50530.7","0.000"]]}}
1618677454.942591: {"stream":"ksmusdt@depth@100ms","data":{"e":"depthUpdate","E":1618677454885,"T":1618677454875,"s":"KSMUSDT","U":335340800958,"u":335340803570,"pu":335340800532,"b":[["454.498","0.2"],["457.926","10.9"],["457.961","0.0"],["458.157","0.0"],["458.158","0.0"],["458.223","2.1"],["458.753","2.6"],["458.843","1.3"],["458.919","0.0"]],"a":[["459.074","0.3"],["459.075","6.4"],["459.096","0.0"],["459.097","1.6"],["459.098","0.0"],["459.108","0.0"],["459.121","0.0"],["459.139","0.0"],["459.555","7.2"],["459.741","1.0"],["460.035","2.1"],["460.036","10.9"],["460.087","0.0"],["460.268","0.0"],["460.270","0.0"],["463.963","0.4"]]}}
1618677454.957003: {"stream":"ksmusdt@bookTicker","data":{"e":"bookTicker","u":335340804179,"s":"KSMUSDT","b":"458.886","B":"0.2","a":"459.073","A":"1.6","T":1618677454895,"E":1618677454899}}
1618677454.964469: {"stream":"xmrusdt@depth@100ms","data":{"e":"depthUpdate","E":1618677454907,"T":1618677454874,"s":"XMRUSDT","U":335340801617,"u":335340803562,"pu":335340801015,"b":[["352.21","2.500"],["352.30","0.000"]],"a":[["353.03","0.000"],["353.04","0.000"]]}}
1618677454.967606: {"stream":"xmrusdt@bookTicker","data":{"e":"bookTicker","u":335340804522,"s":"XMRUSDT","b":"352.46","B":"3.700","a":"352.49","A":"2.358","T":1618677454906,"E":1618677454909}}
1618677454.967675: {"stream":"xmrusdt@kline_1m","data":{"e":"kline","E":1618677454910,"s":"XMRUSDT","k":{"t":1618677420000,"T":1618677479999,"s":"XMRUSDT","i":"1m","f":34692938,"L":34692968,"o":"352.86","c":"352.48","h":"352.93","l":"352.40","v":"26.964","n":31,"x":false,"q":"9509.25462","V":"1.638","Q":"577.96953","B":"0"}}}
1618677454.970974: {"stream":"ksmusdt@bookTicker","data":{"e":"bookTicker","u":335340804633,"s":"KSMUSDT","b":"458.886","B":"0.2","a":"459.072","A":"0.3","T":1618677454909,"E":1618677454913}}
1618677454.971045: {"stream":"ksmusdt@bookTicker","data":{"e":"bookTicker","u":335340804684,"s":"KSMUSDT","b":"458.886","B":"0.2","a":"459.051","A":"6.4","T":1618677454910,"E":1618677454913}}
1618677454.981597: {"stream":"xmrusdt@bookTicker","data":{"e":"bookTicker","u":335340804873,"s":"XMRUSDT","b":"352.40","B":"0.513","a":"352.49","A":"2.358","T":1618677454918,"E":1618677454922}}
1618677454.981707: {"stream":"xmrusdt@bookTicker","data":{"e":"bookTicker","u":335340804875,"s":"XMRUSDT","b":"352.48","B":"3.700","a":"352.49","A":"2.358","T":1618677454918,"E":1618677454922}}
1618677454.982217: {"stream":"yfiusdt@bookTicker","data":{"e":"bookTicker","u":335340805002,"s":"YFIUSDT","b":"49964.8","B":"0.003","a":"49992.1","A":"0.013","T":1618677454921,"E":1618677454924}}
1618677454.983961: {"stream":"xmrusdt@bookTicker","data":{"e":"bookTicker","u":335340805038,"s":"XMRUSDT","b":"352.40","B":"0.513","a":"352.49","A":"2.358","T":1618677454923,"E":1618677454925}}
1618677454.991786: {"stream":"xmrusdt@bookTicker","data":{"e":"bookTicker","u":335340805193,"s":"XMRUSDT","b":"352.40","B":"0.513","a":"352.48","A":"3.700","T":1618677454929,"E":1618677454932}}
1618677454.99497: {"stream":"dentusdt@depth@100ms","data":{"e":"depthUpdate","E":1618677454936,"T":1618677454901,"s":"DENTUSDT","U":335340802459,"u":335340804356,"pu":335340802100,"b":[],"a":[["0.012358","53970"],["0.012359","0"],["0.012360","43441"],["0.012362","0"],["0.012363","283469"],["0.012366","49787"],["0.012367","217028"],["0.012381","27105"]]}}
1618677454.995208: {"stream":"ksmusdt@bookTicker","data":{"e":"bookTicker","u":335340805300,"s":"KSMUSDT","b":"458.937","B":"1.6","a":"459.051","A":"6.4","T":1618677454933,"E":1618677454936}}
1618677455.0034409: {"stream":"yfiusdt@bookTicker","data":{"e":"bookTicker","u":335340805568,"s":"YFIUSDT","b":"49973.0","B":"0.003","a":"49992.1","A":"0.013","T":1618677454942,"E":1618677454945}}
1618677455.008849: {"stream":"yfiusdt@depth@100ms","data":{"e":"depthUpdate","E":1618677454950,"T":1618677454945,"s":"YFIUSDT","U":335340802780,"u":335340805611,"pu":335340802702,"b":[["49290.6","0.000"],["49531.3","0.002"],["49532.1","0.000"],["49535.6","0.005"],["49535.9","0.002"],["49551.1","0.002"],["49552.6","0.000"],["49555.2","0.000"],["49563.6","0.000"],["49609.6","0.000"],["49626.6","0.000"],["49629.8","0.002"],["49632.1","0.000"],["49641.1","0.002"],["49651.2","0.000"],["49655.4","0.021"],["49663.7","0.000"],["49720.3","0.000"],["49728.5","0.000"],["49730.7","0.000"],["49749.6","0.000"],["49766.1","0.000"],["49885.6","0.011"],["49918.8","0.003"],["49922.1","0.003"],["49922.9","0.003"],["49927.9","0.000"],["49931.2","0.000"],["49932.0","0.000"],["49935.6","0.000"],["49941.7","0.000"],["49941.8","0.168"],["49941.9","0.130"],["49973.0","0.003"]],"a":[["49992.1","0.013"],["49992.8","0.000"],["49993.6","0.000"],["50098.7","0.000"],["50158.5","0.002"],["50224.4","0.000"],["50269.0","0.042"],["50277.1","0.000"],["50336.8","0.000"],["50340.7","0.000"],["50345.1","0.000"],["50346.2","0.002"],["50346.7","0.000"],["50347.0","0.000"],["50349.8","0.002"],["50420.4","0.006"],["50425.5","0.000"],["50436.7","0.000"],["50446.1","0.000"],["50449.7","0.002"],["50480.4","0.000"],["50489.4","0.000"],["50544.2","0.004"],["50580.6","0.000"]]}}
1618677455.00947: {"stream":"xmrusdt@bookTicker","data":{"e":"bookTicker","u":335340805650,"s":"XMRUSDT","b":"352.42","B":"3.894","a":"352.48","A":"3.700","T":1618677454946,"E":1618677454950}}
1618677455.010695: {"stream":"ksmusdt@bookTicker","data":{"e":"bookTicker","u":335340805716,"s":"KSMUSDT","b":"458.937","B":"1.6","a":"459.050","A":"0.3","T":1618677454948,"E":1618677454952}}
1618677455.010765: {"stream":"xmrusdt@bookTicker","data":{"e":"bookTicker","u":335340805756,"s":"XMRUSDT","b":"352.40","B":"0.513","a":"352.48","A":"3.700","T":1618677454950,"E":1618677454954}}
1618677455.017567: {"stream":"yfiusdt@bookTicker","data":{"e":"bookTicker","u":335340805885,"s":"YFIUSDT","b":"49973.0","B":"0.003","a":"49992.2","A":"0.055","T":1618677454955,"E":1618677454959}}
1618677455.0176718: {"stream":"xmrusdt@bookTicker","data":{"e":"bookTicker","u":335340805906,"s":"XMRUSDT","b":"352.40","B":"0.513","a":"352.49","A":"2.358","T":1618677454956,"E":1618677454959}}
1618677455.0180979: {"stream":"xmrusdt@bookTicker","data":{"e":"bookTicker","u":335340805937,"s":"XMRUSDT","b":"352.40","B":"0.513","a":"352.48","A":"0.566","T":1618677454957,"E":1618677454961}}
1618677455.018622: {"stream":"xmrusdt@bookTicker","data":{"e":"bookTicker","u":335340806000,"s":"XMRUSDT","b":"352.40","B":"4.213","a":"352.48","A":"0.566","T":1618677454959,"E":1618677454962}}
1618677455.0258381: {"stream":"ksmusdt@bookTicker","data":{"e":"bookTicker","u":335340806160,"s":"KSMUSDT","b":"458.886","B":"0.2","a":"459.050","A":"0.3","T":1618677454964,"E":1618677454968}}
1618677455.035373: {"stream":"ksmusdt@aggTrade","data":{"e":"aggTrade","E":1618677454978,"a":21396978,"s":"KSMUSDT","p":"458.919","q":"1.2","f":25426571,"l":25426571,"T":1618677454825,"m":true}}
1618677455.053088: {"stream":"xmrusdt@bookTicker","data":{"e":"bookTicker","u":335340806748,"s":"XMRUSDT","b":"352.40","B":"4.213","a":"352.49","A":"2.358","T":1618677454989,"E":1618677454994}}
1618677455.0577438: {"stream":"ksmusdt@depth@100ms","data":{"e":"depthUpdate","E":1618677454999,"T":1618677454993,"s":"KSMUSDT","U":335340804179,"u":335340806839,"pu":335340803570,"b":[["454.712","3.9"],["455.220","0.0"],["456.580","0.1"],["456.655","0.0"],["456.777","3.9"],["457.287","0.0"],["457.748","5.9"],["457.955","5.8"],["458.159","0.0"],["458.592","0.0"],["458.605","0.3"],["458.610","0.0"],["458.611","0.0"],["458.652","1.6"],["458.753","2.6"],["458.754","0.0"],["458.937","0.0"]],"a":[["459.050","0.3"],["459.051","6.4"],["459.072","0.0"],["459.073","1.6"],["459.074","0.0"],["459.097","0.0"],["459.099","0.0"],["459.574","2.2"],["459.718","1.0"],["459.741","1.0"],["459.764","0.0"],["459.919","5.8"],["460.906","3.9"],["461.420","0.0"],["462.970","3.9"],["463.487","0.0"]]}}
1618677455.066454: {"stream":"xmrusdt@depth@100ms","data":{"e":"depthUpdate","E":1618677455009,"T":1618677455003,"s":"XMRUSDT","U":335340804506,"u":335340807124,"pu":335340803562,"b":[["351.55","0.000"],["351.93","13.580"],["352.03","0.000"],["352.04","4.880"],["352.05","0.935"],["352.06","0.000"],["352.07","0.000"],["352.15","5.719"],["352.18","0.000"],["352.21","0.000"],["352.22","10.160"],["352.29","1.228"],["352.31","0.000"],["352.33","3.188"],["352.34","0.000"],["352.36","0.000"],["352.40","4.213"],["352.42","0.000"],["352.46","0.000"],["352.48","0.000"]],"a":[["352.48","0.000"],["352.51","2.813"],["352.55","0.000"],["352.56","0.000"],["352.57","0.000"],["352.58","1.400"],["352.60","0.947"],["352.61","0.000"],["352.64","0.000"],["352.66","0.000"],["352.82","2.500"],["352.83","13.860"],["352.88","0.000"],["352.91","14.280"],["352.93","9.100"],["353.07","15.462"],["353.19","0.000"],["353.28","3.993"]]}}
1618677455.077568: {"stream":"xmrusdt@bookTicker","data":{"e":"bookTicker","u":335340807472,"s":"XMRUSDT","b":"352.40","B":"4.213","a":"352.49","A":"1.000","T":1618677455013,"E":1618677455018}}
1618677455.0830662: {"stream":"xmrusdt@bookTicker","data":{"e":"bookTicker","u":335340807744,"s":"XMRUSDT","b":"352.40","B":"4.213","a":"352.45","A":"1.358","T":1618677455019,"E":1618677455024}}
1618677455.0949252: {"stream":"xmrusdt@bookTicker","data":{"e":"bookTicker","u":335340808369,"s":"XMRUSDT","b":"352.40","B":"4.213","a":"352.44","A":"2.500","T":1618677455034,"E":1618677455037}}
1618677455.095027: {"stream":"dentusdt@depth@100ms","data":{"e":"depthUpdate","E":1618677455038,"T":1618677455024,"s":"DENTUSDT","U":335340805334,"u":335340807982,"pu":335340804356,"b":[["0.012137","0"]],"a":[["0.012357","0"],["0.012358","0"],["0.012359","6793"],["0.012360","97411"],["0.012361","133881"],["0.012366","49787"],["0.012380","12547"],["0.012381","27105"],["0.012417","78907"],["0.012426","2390"]]}}
1618677455.1066298: {"stream":"xmrusdt@bookTicker","data":{"e":"bookTicker","u":335340808856,"s":"XMRUSDT","b":"352.40","B":"4.213","a":"352.45","A":"1.358","T":1618677455044,"E":1618677455048}}
1618677455.1070762: {"stream":"yfiusdt@depth@100ms","data":{"e":"depthUpdate","E":1618677455050,"T":1618677455044,"s":"YFIUSDT","U":335340805672,"u":335340808846,"pu":335340805611,"b":[["49529.7","0.000"],["49530.1","0.000"],["49544.7","0.000"],["49561.0","0.000"],["49576.8","0.000"],["49603.5","0.002"],["49629.8","0.000"],["49643.4","0.000"],["49644.8","0.000"],["49661.1","0.000"],["49904.4","0.004"],["49908.6","0.000"],["49917.0","0.110"],["49921.2","0.110"],["49941.8","0.000"],["49941.9","0.000"],["49942.0","0.168"],["49942.2","0.087"],["49942.3","0.130"],["49942.4","0.141"],["49950.5","0.012"],["49955.6","0.013"],["49955.7","0.010"],["49955.8","0.009"],["49964.9","0.004"]],"a":[["49992.1","0.000"],["49993.6","0.030"],["49993.7","0.000"],["49993.8","0.000"],["49995.8","0.013"],["49996.0","0.000"],["49997.0","0.000"],["49998.8","0.024"],["50066.5","0.010"],["50320.6","0.000"],["50346.2","0.000"],["50439.6","0.000"],["50440.6","0.000"],["50463.0","0.006"],["50505.5","0.000"],["50543.1","0.000"],["50579.3","0.000"]]}}
1618677455.234117: {"stream":"xmrusdt@aggTrade","data":{"e":"aggTrade","E":1618677455060,"a":23619025,"s":"XMRUSDT","p":"352.48","q":"7.438","f":34692968,"l":34692971,"T":1618677454906,"m":true}}
1618677455.244318: {"stream":"ksmusdt@depth@100ms","data":{"e":"depthUpdate","E":1618677455104,"T":1618677455093,"s":"KSMUSDT","U":335340807028,"u":335340810893,"pu":335340806839,"b":[["453.741","0.0"],["457.482","0.0"],["458.067","7.0"],["458.137","1.1"],["458.424","1.3"],["458.605","0.0"],["458.653","0.3"],["458.755","1.0"]],"a":[["459.073","0.0"],["459.074","1.6"],["459.226","0.0"],["459.550","0.1"],["459.646","1.0"],["459.695","0.1"],["459.703","0.0"],["459.707","0.1"],["459.718","0.0"],["459.725","0.0"],["459.741","1.0"],["459.881","0.0"],["459.931","0.0"],["460.043","0.0"],["460.702","0.0"],["460.788","0.0"],["461.180","0.1"],["461.255","0.0"],["461.486","0.0"],["461.778","0.0"],["465.731","3.2"],["467.724","0.0"]]}}
1618677455.247117: {"stream":"xmrusdt@depth@100ms","data":{"e":"depthUpdate","E":1618677455115,"T":1618677455102,"s":"XMRUSDT","U":335340807369,"u":335340811148,"pu":335340807124,"b":[["347.66","200.000"],["348.29","200.000"],["349.78","0.000"],["350.41","0.408"],["350.99","5.902"],["351.40","28.957"],["351.52","3.941"],["351.54","13.938"],["351.61","3.984"],["351.76","10.996"],["351.89","13.903"],["352.01","17.942"],["352.05","3.489"],["352.12","2.968"],["352.22","7.660"],["352.23","2.135"],["352.31","0.000"],["352.33","1.788"],["352.34","0.670"],["352.35","0.566"]],"a":[["352.44","0.000"],["352.45","1.358"],["352.48","0.000"],["352.49","1.000"],["352.52","0.240"],["352.58","0.000"],["352.60","5.203"],["352.81","0.000"],["352.82","2.500"],["352.84","2.269"],["352.95","6.819"],["352.96","32.753"],["353.06","3.249"],["353.68","0.000"],["354.53","0.000"],["356.42","200.000"]]}}
1618677455.253664: {"stream":"yfiusdt@depth@100ms","data":{"e":"depthUpdate","E":1618677455150,"T":1618677455138,"s":"YFIUSDT","U":335340808939,"u":335340811673,"pu":335340808846,"b":[["49515.5","0.000"],["49528.4","0.000"],["49551.1","0.000"],["49612.7","0.030"],["49615.6","0.000"],["49936.3","0.292"],["49941.6","0.000"],["49942.0","0.000"],["49942.3","0.000"],["49942.5","0.298"],["49950.6","0.008"],["49964.8","0.000"],["49965.0","0.003"]],"a":[["49993.6","0.000"],["49995.2","0.013"],["49995.8","0.000"],["50084.9","0.100"],["50253.8","0.020"],["50373.3","0.000"],["50420.4","0.004"],["50427.7","0.000"],["50463.8","0.000"],["50464.1","0.000"],["50549.4","0.000"],["50564.2","0.000"]]}}
1618677455.254087: {"stream":"dentusdt@depth@100ms","data":{"e":"depthUpdate","E":1618677455158,"T":1618677455056,"s":"DENTUSDT","U":335340809355,"u":335340809359,"pu":335340807982,"b":[],"a":[["0.012358","53957"],["0.012381","81075"]]}}
1618677455.262154: {"stream":"ksmusdt@bookTicker","data":{"e":"bookTicker","u":335340813313,"s":"KSMUSDT","b":"458.886","B":"0.2","a":"458.968","A":"0.1","T":1618677455191,"E":1618677455195}}
1618677455.2622552: {"stream":"yfiusdt@bookTicker","data":{"e":"bookTicker","u":335340813520,"s":"YFIUSDT","b":"49973.0","B":"0.003","a":"49982.6","A":"0.001","T":1618677455197,"E":1618677455200}}
1618677455.2623: {"stream":"ksmusdt@depth@100ms","data":{"e":"depthUpdate","E":1618677455204,"T":1618677455191,"s":"KSMUSDT","U":335340811114,"u":335340813313,"pu":335340810893,"b":[["455.241","3.1"],["455.830","2.9"],["457.195","2.4"],["457.864","2.0"],["458.127","20.6"],["458.128","4.6"],["458.451","0.0"],["458.653","0.0"],["458.753","2.6"],["458.756","0.3"]],"a":[["458.968","0.1"],["459.596","1.0"],["459.646","0.0"],["459.692","2.7"],["460.185","10.2"],["460.238","1.6"],["460.257","8.3"],["460.517","0.0"]]}}
1618677455.270126: {"stream":"ksmusdt@bookTicker","data":{"e":"bookTicker","u":335340813887,"s":"KSMUSDT","b":"458.887","B":"1.0","a":"458.968","A":"0.1","T":1618677455208,"E":1618677455211}}
1618677455.2737238: {"stream":"xmrusdt@depth@100ms","data":{"e":"depthUpdate","E":1618677455215,"T":1618677455190,"s":"XMRUSDT","U":335340811252,"u":335340813294,"pu":335340811148,"b":[["347.66","0.000"],["348.29","0.000"],["348.31","200.000"],["348.94","200.000"],["349.72","0.044"],["350.24","1.098"],["350.35","4.265"],["350.54","1.515"],["350.87","10.409"],["351.71","0.000"],["351.95","19.290"],["352.03","2.500"],["352.12","0.468"],["352.15","5.719"],["352.19","0.000"],["352.20","0.000"]],"a":[["352.59","3.592"],["352.82","0.000"],["354.50","0.847"],["355.90","211.638"],["356.42","0.000"]]}}
1618677455.323838: {"stream":"dentusdt@depth@100ms","data":{"e":"depthUpdate","E":1618677455266,"T":1618677455186,"s":"DENTUSDT","U":335340812220,"u":335340813132,"pu":335340809359,"b":[],"a":[["0.012382","547123"],["0.012424","83166"],["0.012460","28259"]]}}
1618677455.326387: {"stream":"yfiusdt@depth@100ms","data":{"e":"depthUpdate","E":1618677455267,"T":1618677455261,"s":"YFIUSDT","U":335340812361,"u":335340815892,"pu":335340811673,"b":[["49440.7","0.000"],["49528.7","0.002"],["49530.0","0.020"],["49541.0","0.000"],["49555.5","0.000"],["49628.8","0.002"],["49655.7","0.000"],["49790.8","0.000"],["49803.2","0.000"],["49807.6","0.000"],["49815.7","0.000"],["49909.2","0.026"],["49924.2","0.009"],["49935.4","0.000"],["49936.4","0.061"],["49942.2","0.000"],["49942.4","0.000"],["49942.5","0.168"],["49942.6","0.211"],["49950.4","0.000"],["49964.2","0.244"],["49964.4","0.000"]],"a":[["49982.6","0.001"],["49994.6","0.000"],["49995.2","0.000"],["49997.3","0.012"],["49997.6","0.000"],["49997.9","0.013"],["50058.2","0.005"],["50068.5","0.242"],["50087.4","0.000"],["50148.5","0.013"],["50150.0","0.006"],["50158.5","0.000"],["50246.6","0.007"],["50420.4","0.002"],["50444.2","0.000"],["50448.2","0.000"],["50463.0","0.004"],["50520.3","0.000"],["50547.2","0.000"],["50563.1","0.004"],["50647.3","0.000"]]}}
1618677455.355992: {"stream":"yfiusdt@bookTicker","data":{"e":"bookTicker","u":335340816989,"s":"YFIUSDT","b":"49974.3","B":"0.006","a":"49982.6","A":"0.001","T":1618677455292,"E":1618677455297}}
1618677455.369129: {"stream":"ksmusdt@depth@100ms","data":{"e":"depthUpdate","E":1618677455311,"T":1618677455297,"s":"KSMUSDT","U":335340813864,"u":335340817154,"pu":335340813313,"b":[["449.714","19.8"],["453.734","20.0"],["458.653","1.5"],["458.654","0.6"],["458.752","0.0"],["458.753","1.3"],["458.755","0.5"],["458.843","0.0"],["458.887","1.0"]],"a":[["458.975","0.1"],["459.074","0.0"],["459.075","0.0"],["459.427","1.9"],["459.554","1.6"],["459.595","1.0"],["459.596","0.0"],["459.793","14.2"],["459.871","0.5"],["459.955","0.0"],["460.035","0.0"],["460.122","1.9"],["460.647","3.0"],["461.775","19.9"],["463.084","0.0"]]}}
1618677455.3732722: {"stream":"dentusdt@bookTicker","data":{"e":"bookTicker","u":335340817573,"s":"DENTUSDT","b":"0.012350","B":"217782","a":"0.012356","A":"9217","T":1618677455311,"E":1618677455314}}
1618677455.3757818: {"stream":"xmrusdt@depth@100ms","data":{"e":"depthUpdate","E":1618677455318,"T":1618677455290,"s":"XMRUSDT","U":335340814143,"u":335340816921,"pu":335340813294,"b":[["348.31","0.000"],["348.94","0.000"],["349.69","207.088"],["350.19","6.343"],["350.32","248.784"],["351.33","14.353"],["351.72","2.604"],["351.93","14.147"],["352.03","0.000"],["352.04","4.313"],["352.09","23.208"],["352.18","2.500"]],"a":[["352.58","0.095"],["352.59","1.092"],["352.82","2.500"],["353.40","16.213"],["354.50","200.847"],["355.90","11.638"]]}}
1618677455.3833659: {"stream":"dentusdt@bookTicker","data":{"e":"bookTicker","u":335340817938,"s":"DENTUSDT","b":"0.012350","B":"217782","a":"0.012358","A":"53957","T":1618677455321,"E":1618677455325}}
1618677455.38349: {"stream":"dentusdt@bookTicker","data":{"e":"bookTicker","u":335340817958,"s":"DENTUSDT","b":"0.012350","B":"217782","a":"0.012353","A":"2598","T":1618677455321,"E":1618677455325}}
1618677455.3939881: {"stream":"ksmusdt@bookTicker","data":{"e":"bookTicker","u":335340818224,"s":"KSMUSDT","b":"458.886","B":"0.2","a":"458.968","A":"0.1","T":1618677455331,"E":1618677455336}}
1618677455.430516: {"stream":"yfiusdt@depth@100ms","data":{"e":"depthUpdate","E":1618677455369,"T":1618677455362,"s":"YFIUSDT","U":335340815997,"u":335340819086,"pu":335340815892,"b":[["49435.9","0.000"],["49451.0","0.000"],["49459.2","0.026"],["49528.7","0.000"],["49528.8","0.018"],["49535.6","0.003"],["49535.9","0.000"],["49563.5","0.000"],["49603.5","0.000"],["49628.8","0.000"],["49631.3","0.000"],["49641.1","0.000"],["49663.6","0.000"],["49805.2","0.000"],["49863.0","0.010"],["49881.1","0.050"],["49912.8","0.000"],["49917.0","0.000"],["49925.4","0.127"],["49929.6","0.110"],["49942.5","0.000"],["49942.6","0.130"],["49942.7","0.168"],["49942.8","0.062"],["49950.5","0.000"],["49950.6","0.000"],["49955.7","0.000"],["49964.9","0.053"],["49965.1","0.005"],["49974.3","0.006"]],"a":[["49997.3","0.000"],["49998.9","0.000"],["50001.4","0.000"],["50078.2","0.009"],["50084.8","0.050"],["50084.9","0.006"],["50107.9","0.000"],["50246.9","0.002"],["50348.3","0.000"],["50463.0","0.002"],["50474.3","0.000"],["50535.2","0.000"],["50542.1","0.000"],["50544.2","0.000"],["50563.1","0.002"],["50689.8","0.000"]]}}
1618677455.46369: {"stream":"dentusdt@depth@100ms","data":{"e":"depthUpdate","E":1618677455405,"T":1618677455393,"s":"DENTUSDT","U":335340817286,"u":335340819824,"pu":335340813132,"b":[["0.000011","19805663"],["0.012274","454829"],["0.012320","27114"]],"a":[["0.012353","2598"],["0.012355","0"],["0.012356","0"],["0.012357","53975"],["0.012359","140674"],["0.012360","43441"],["0.012361","0"],["0.012366","49787"],["0.012379","54139"]]}}
1618677455.476477: {"stream":"ksmusdt@depth@100ms","data":{"e":"depthUpdate","E":1618677455418,"T":1618677455372,"s":"KSMUSDT","U":335340817710,"u":335340819310,"pu":335340817154,"b":[["457.622","10.2"],["458.137","1.1"],["458.655","1.3"],["458.756","0.0"],["458.786","0.3"],["458.887","0.0"]],"a":[["459.191","1.6"],["459.554","0.0"],["459.595","0.0"],["459.718","1.0"]]}}
1618677455.488472: {"stream":"yfiusdt@bookTicker","data":{"e":"bookTicker","u":335340820631,"s":"YFIUSDT","b":"49974.4","B":"0.025","a":"49982.6","A":"0.001","T":1618677455427,"E":1618677455430}}
1618677455.493963: {"stream":"xmrusdt@depth@100ms","data":{"e":"depthUpdate","E":1618677455436,"T":1618677455417,"s":"XMRUSDT","U":335340818245,"u":335340820321,"pu":335340816921,"b":[["350.50","13.911"],["352.06","0.000"],["352.12","2.968"],["352.18","0.000"],["352.22","0.000"],["352.23","0.000"],["352.27","6.019"]],"a":[["352.68","32.868"],["352.82","0.000"],["352.94","0.612"],["353.31","2.269"],["360.99","0.154"]]}}
1618677455.497536: {"stream":"yfiusdt@bookTicker","data":{"e":"bookTicker","u":335340820845,"s":"YFIUSDT","b":"49975.7","B":"0.006","a":"49982.6","A":"0.001","T":1618677455436,"E":1618677455439}}
1618677455.537042: {"stream":"yfiusdt@depth@100ms","data":{"e":"depthUpdate","E":1618677455476,"T":1618677455470,"s":"YFIUSDT","U":335340819312,"u":335340821642,"pu":335340819086,"b":[["49531.3","0.000"],["49585.9","0.000"],["49633.4","0.000"],["49637.4","0.000"],["49640.3","0.000"],["49745.7","0.000"],["49822.5","0.000"],["49909.1","0.025"],["49909.2","0.000"],["49918.8","0.000"],["49922.1","0.000"],["49922.9","0.000"],["49928.8","0.005"],["49932.1","0.005"],["49932.9","0.005"],["49942.7","0.000"],["49942.9","0.168"],["49955.8","0.000"],["49965.0","0.000"],["49965.1","0.000"],["49965.2","0.000"],["49965.3","0.005"],["49974.3","0.000"],["49974.4","0.025"],["49974.5","0.003"],["49975.7","0.006"]],"a":[["50148.5","0.007"],["50180.1","0.021"],["50248.4","0.000"],["50339.4","0.000"],["50349.2","0.000"],["50349.8","0.000"],["50420.4","0.000"],["50435.2","0.000"],["50449.7","0.000"]]}}
1618677455.544132: {"stream":"dentusdt@bookTicker","data":{"e":"bookTicker","u":335340821953,"s":"DENTUSDT","b":"0.012350","B":"218581","a":"0.012353","A":"2598","T":1618677455480,"E":1618677455483}}
1618677455.576149: {"stream":"dentusdt@depth@100ms","data":{"e":"depthUpdate","E":1618677455516,"T":1618677455498,"s":"DENTUSDT","U":335340820093,"u":335340822512,"pu":335340819824,"b":[["0.000011","20805663"],["0.010304","268876"],["0.010573","86292"],["0.010850","880668"],["0.010996","198764"],["0.011124","28764"],["0.011225","64887"],["0.011293","40008"],["0.011350","1427755"],["0.011395","14382"],["0.011658","62091"],["0.011838","4794"],["0.011983","1598"],["0.012105","546183"],["0.012202","46337"],["0.012264","65593"],["0.012313","68811"],["0.012337","30241"],["0.012340","0"],["0.012350","218581"]],"a":[["0.012355","0"],["0.012356","9395"],["0.012357","70003"],["0.012358","63977"],["0.012360","17393"],["0.012361","57938"],["0.012363","225531"],["0.012380","0"],["0.012381","76378"],["0.012384","149469"]]}}
1618677455.5790322: {"stream":"ksmusdt@depth@100ms","data":{"e":"depthUpdate","E":1618677455519,"T":1618677455514,"s":"KSMUSDT","U":335340820265,"u":335340822960,"pu":335340819310,"b":[["452.514","0.2"],["457.160","0.0"],["457.882","4.1"],["458.038","0.3"],["458.048","6.1"],["458.655","4.5"]],"a":[["459.192","1.2"],["459.619","2.2"],["459.919","0.0"]]}}
1618677455.590521: {"stream":"xmrusdt@bookTicker","data":{"e":"bookTicker","u":335340823220,"s":"XMRUSDT","b":"352.40","B":"4.213","a":"352.49","A":"1.000","T":1618677455526,"E":1618677455531}}
1618677455.5949: {"stream":"xmrusdt@bookTicker","data":{"e":"bookTicker","u":335340823365,"s":"XMRUSDT","b":"352.40","B":"4.213","a":"352.43","A":"1.358","T":1618677455531,"E":1618677455536}}
1618677455.597347: {"stream":"xmrusdt@depth@100ms","data":{"e":"depthUpdate","E":1618677455539,"T":1618677455531,"s":"XMRUSDT","U":335340820830,"u":335340823365,"pu":335340820321,"b":[["351.10","0.660"],["352.12","0.468"],["352.18","0.000"],["352.30","2.500"]],"a":[["352.43","1.358"],["352.45","0.000"],["359.40","0.942"],["359.41","0.161"],["360.10","27.594"],["367.93","0.000"],["367.96","0.459"],["367.97","0.000"],["390.24","0.000"],["390.30","0.268"]]}}
1618677455.6082392: {"stream":"ksmusdt@bookTicker","data":{"e":"bookTicker","u":335340823746,"s":"KSMUSDT","b":"458.886","B":"0.2","a":"458.967","A":"1.5","T":1618677455546,"E":1618677455550}}
1618677455.642307: {"stream":"yfiusdt@depth@100ms","data":{"e":"depthUpdate","E":1618677455585,"T":1618677455574,"s":"YFIUSDT","U":335340822071,"u":335340824641,"pu":335340821642,"b":[["49850.1","0.000"],["49898.9","0.014"],["49930.5","0.026"],["49936.3","0.000"],["49936.4","0.000"],["49949.2","0.301"],["49965.3","0.012"],["49965.4","0.003"],["49974.5","0.000"]],"a":[["49986.7","0.001"],["50089.9","0.100"],["50098.8","0.000"],["50103.9","0.016"],["50207.8","0.083"],["50208.0","0.000"],["50432.7","0.083"],["50433.0","0.000"]]}}
1618677455.6579468: {"stream":"ksmusdt@bookTicker","data":{"e":"bookTicker","u":335340825139,"s":"KSMUSDT","b":"458.886","B":"0.2","a":"458.961","A":"6.4","T":1618677455593,"E":1618677455596}}
1618677455.681962: {"stream":"ksmusdt@depth@100ms","data":{"e":"depthUpdate","E":1618677455622,"T":1618677455610,"s":"KSMUSDT","U":335340823037,"u":335340825834,"pu":335340822960,"b":[["457.351","4.0"],["457.619","0.0"],["457.737","0.0"],["457.741","30.5"],["458.137","0.0"],["458.590","0.4"],["458.655","1.3"],["458.656","1.6"],["458.751","0.0"],["458.753","0.0"],["458.786","0.0"],["458.855","0.0"]],"a":[["458.961","6.4"],["458.967","1.5"],["459.741","0.0"],["459.978","6.2"],["460.087","0.4"]]}}
1618677455.6912022: {"stream":"ksmusdt@bookTicker","data":{"e":"bookTicker","u":335340826541,"s":"KSMUSDT","b":"458.886","B":"0.2","a":"458.960","A":"0.3","T":1618677455630,"E":1618677455634}}
1618677455.698977: {"stream":"dentusdt@depth@100ms","data":{"e":"depthUpdate","E":1618677455642,"T":1618677455623,"s":"DENTUSDT","U":335340823493,"u":335340826308,"pu":335340822512,"b":[["0.012160","315679"],["0.012291","604413"],["0.012337","115068"],["0.012347","69125"]],"a":[["0.012358","10020"],["0.012359","133881"],["0.012366","103744"],["0.012381","76378"],["0.012382","462293"],["0.012384","42260"],["0.012388","968021"],["0.012464","36668"]]}}
1618677455.7024: {"stream":"xmrusdt@depth@100ms","data":{"e":"depthUpdate","E":1618677455645,"T":1618677455611,"s":"XMRUSDT","U":335340823620,"u":335340825905,"pu":335340823365,"b":[["351.55","200.000"],["351.63","0.000"],["351.99","20.415"],["352.03","2.500"],["352.18","0.000"],["352.30","0.000"]],"a":[["353.27","200.056"],["353.35","14.778"],["353.51","15.283"],["353.69","4.055"],["359.40","0.958"],["367.92","0.044"],["390.23","0.165"]]}}
1618677455.7584262: {"stream":"yfiusdt@depth@100ms","data":{"e":"depthUpdate","E":1618677455701,"T":1618677455657,"s":"YFIUSDT","U":335340825538,"u":335340827293,"pu":335340824641,"b":[["49942.9","0.000"],["49949.3","0.168"]],"a":[["49997.8","0.003"],["50089.1","0.021"],["50104.9","0.010"]]}}
1618677455.765196: {"stream":"dentusdt@bookTicker","data":{"e":"bookTicker","u":335340828465,"s":"DENTUSDT","b":"0.012350","B":"218581","a":"0.012352","A":"535","T":1618677455702,"E":1618677455706}}
1618677455.769668: {"stream":"yfiusdt@bookTicker","data":{"e":"bookTicker","u":335340828585,"s":"YFIUSDT","b":"49975.7","B":"0.006","a":"49986.7","A":"0.001","T":1618677455707,"E":1618677455710}}
1618677455.7783182: {"stream":"yfiusdt@bookTicker","data":{"e":"bookTicker","u":335340828857,"s":"YFIUSDT","b":"49975.7","B":"0.006","a":"49979.2","A":"0.001","T":1618677455717,"E":1618677455720}}
1618677455.7832708: {"stream":"ksmusdt@bookTicker","data":{"e":"bookTicker","u":335340828975,"s":"KSMUSDT","b":"458.886","B":"0.2","a":"458.961","A":"6.4","T":1618677455722,"E":1618677455726}}
1618677455.790601: {"stream":"ksmusdt@depth@100ms","data":{"e":"depthUpdate","E":1618677455733,"T":1618677455723,"s":"KSMUSDT","U":335340826483,"u":335340828984,"pu":335340825834,"b":[["457.622","0.0"],["458.012","13.6"],["458.048","0.0"],["458.137","1.1"],["458.142","2.1"],["458.223","0.0"],["458.420","0.0"],["458.655","2.6"],["458.656","1.3"],["458.657","0.0"],["458.665","1.2"],["458.666","0.3"],["458.755","0.0"]],"a":[["458.960","0.0"],["459.048","0.3"],["459.049","1.6"],["459.050","0.0"],["459.191","0.0"],["459.192","0.0"],["459.316","6.2"],["459.741","0.0"],["459.743","9.4"],["459.793","12.1"],["460.171","0.0"],["460.373","0.0"],["460.653","0.0"]]}}
1618677455.808077: {"stream":"xmrusdt@depth@100ms","data":{"e":"depthUpdate","E":1618677455752,"T":1618677455723,"s":"XMRUSDT","U":335340827013,"u":335340828989,"pu":335340825905,"b":[["321.12","8.679"],["321.15","0.000"],["352.03","1.883"],["352.11","3.069"],["352.12","0.468"],["352.18","2.500"]],"a":[["357.05","0.721"],["359.40","1.092"],["359.41","0.027"],["368.08","0.444"],["368.09","0.000"],["373.02","0.074"],["391.03","1.392"],["391.04","0.000"],["391.57","0.000"],["391.59","8.606"]]}}
1618677455.814398: {"stream":"dentusdt@depth@100ms","data":{"e":"depthUpdate","E":1618677455757,"T":1618677455750,"s":"DENTUSDT","U":335340827161,"u":335340829776,"pu":335340826308,"b":[],"a":[["0.012352","535"],["0.012366","103744"],["0.012381","76380"],["0.012420","615331"],["0.012423","593945"]]}}
1618677455.86773: {"stream":"yfiusdt@depth@100ms","data":{"e":"depthUpdate","E":1618677455810,"T":1618677455790,"s":"YFIUSDT","U":335340828585,"u":335340830789,"pu":335340827293,"b":[["49940.8","0.087"],["49949.2","0.009"],["49965.4","0.012"],["49965.5","0.003"]],"a":[["49979.2","0.001"],["49982.6","0.000"],["49992.1","0.003"],["49997.8","0.000"]]}}
1618677455.889048: {"stream":"ksmusdt@bookTicker","data":{"e":"bookTicker","u":335340831790,"s":"KSMUSDT","b":"458.886","B":"0.2","a":"458.961","A":"6.7","T":1618677455826,"E":1618677455831}}
1618677455.893319: {"stream":"ksmusdt@depth@100ms","data":{"e":"depthUpdate","E":1618677455837,"T":1618677455826,"s":"KSMUSDT","U":335340829263,"u":335340831790,"pu":335340828984,"b":[["457.797","2.3"],["457.995","0.0"],["458.137","0.0"],["458.424","0.0"],["458.665","0.0"]],"a":[["458.961","6.7"],["458.968","0.0"],["458.970","1.2"],["459.046","0.0"],["459.047","1.6"],["459.048","0.0"],["459.049","0.0"],["459.741","0.0"],["463.498","0.0"]]}}
1618677455.908534: {"stream":"ksmusdt@bookTicker","data":{"e":"bookTicker","u":335340832392,"s":"KSMUSDT","b":"458.886","B":"0.2","a":"458.924","A":"0.1","T":1618677455845,"E":1618677455850}}
1618677455.913763: {"stream":"ksmusdt@kline_1m","data":{"e":"kline","E":1618677455856,"s":"KSMUSDT","k":{"t":1618677420000,"T":1618677479999,"s":"KSMUSDT","i":"1m","f":25426460,"L":25426572,"o":"459.607","c":"458.886","h":"459.671","l":"458.391","v":"105.6","n":113,"x":false,"q":"48475.0127","V":"51.4","Q":"23604.9943","B":"0"}}}
1618677455.917092: {"stream":"ksmusdt@bookTicker","data":{"e":"bookTicker","u":335340832616,"s":"KSMUSDT","b":"458.785","B":"0.5","a":"458.924","A":"0.1","T":1618677455853,"E":1618677455857}}
1618677455.91753: {"stream":"dentusdt@depth@100ms","data":{"e":"depthUpdate","E":1618677455860,"T":1618677455836,"s":"DENTUSDT","U":335340829940,"u":335340832065,"pu":335340829776,"b":[],"a":[["0.012353","0"],["0.012357","53975"],["0.012358","133881"],["0.012359","16028"],["0.012360","22269"],["0.012362","5144"],["0.012366","49787"],["0.012381","22403"],["0.012386","165697"]]}}
1618677455.9255402: {"stream":"ksmusdt@bookTicker","data":{"e":"bookTicker","u":335340833025,"s":"KSMUSDT","b":"458.886","B":"0.2","a":"458.924","A":"0.1","T":1618677455865,"E":1618677455868}}
1618677455.925644: {"stream":"xmrusdt@depth@100ms","data":{"e":"depthUpdate","E":1618677455868,"T":1618677455849,"s":"XMRUSDT","U":335340830162,"u":335340832501,"pu":335340828989,"b":[["321.76","0.000"],["341.94","0.000"],["350.25","0.027"],["352.18","2.500"],["352.27","6.019"]],"a":[["352.57","0.001"],["356.31","1.389"],["386.17","0.000"],["386.23","3.366"],["390.31","0.000"],["391.52","0.032"]]}}
1618677455.9372318: {"stream":"ksmusdt@bookTicker","data":{"e":"bookTicker","u":335340833222,"s":"KSMUSDT","b":"458.785","B":"0.5","a":"458.924","A":"0.1","T":1618677455874,"E":1618677455879}}
1618677455.965117: {"stream":"ksmusdt@aggTrade","data":{"e":"aggTrade","E":1618677455906,"a":21396979,"s":"KSMUSDT","p":"458.886","q":"0.2","f":25426572,"l":25426572,"T":1618677455853,"m":true}}
1618677455.965222: {"stream":"ksmusdt@aggTrade","data":{"e":"aggTrade","E":1618677455906,"a":21396980,"s":"KSMUSDT","p":"458.785","q":"0.5","f":25426573,"l":25426573,"T":1618677455902,"m":true}}
1618677455.965267: {"stream":"ksmusdt@bookTicker","data":{"e":"bookTicker","u":335340833968,"s":"KSMUSDT","b":"458.757","B":"0.3","a":"458.924","A":"0.1","T":1618677455902,"E":1618677455906}}
1618677455.9856188: {"stream":"ksmusdt@bookTicker","data":{"e":"bookTicker","u":335340834526,"s":"KSMUSDT","b":"458.666","B":"0.3","a":"458.924","A":"0.1","T":1618677455923,"E":1618677455926}}
1618677455.985743: {"stream":"ksmusdt@bookTicker","data":{"e":"bookTicker","u":335340834562,"s":"KSMUSDT","b":"458.744","B":"0.4","a":"458.924","A":"0.1","T":1618677455924,"E":1618677455927}}
1618677455.9877708: {"stream":"yfiusdt@depth@100ms","data":{"e":"depthUpdate","E":1618677455929,"T":1618677455879,"s":"YFIUSDT","U":335340831756,"u":335340833364,"pu":335340830789,"b":[["49909.1","0.000"],["49964.2","0.000"],["49964.9","0.000"]],"a":[["50068.5","0.000"],["50103.9","0.000"]]}}
1618677455.991945: {"stream":"dentusdt@bookTicker","data":{"e":"bookTicker","u":335340834796,"s":"DENTUSDT","b":"0.012350","B":"218581","a":"0.012351","A":"2598","T":1618677455932,"E":1618677455935}}
1618677456.007134: {"stream":"ksmusdt@depth@100ms","data":{"e":"depthUpdate","E":1618677455950,"T":1618677455944,"s":"KSMUSDT","U":335340832392,"u":335340835129,"pu":335340831790,"b":[["457.405","5.3"],["457.575","1.6"],["457.841","5.7"],["457.886","2.2"],["457.955","0.0"],["458.084","0.0"],["458.143","0.0"],["458.591","0.3"],["458.653","0.0"],["458.654","0.0"],["458.655","1.3"],["458.666","0.0"],["458.744","0.4"],["458.757","0.0"],["458.785","0.0"],["458.886","0.0"]],"a":[["458.924","0.1"],["458.960","0.3"],["458.961","6.4"],["459.047","0.0"],["459.247","1.6"],["459.304","13.9"],["459.512","1.2"],["459.593","1.2"],["459.718","0.0"],["459.741","0.0"],["459.742","0.0"],["459.793","0.0"],["459.884","5.7"],["459.910","10.9"],["460.148","0.0"],["460.182","0.0"],["460.378","0.0"],["460.498","1.6"],["460.933","0.0"],["463.026","0.2"]]}}
1618677456.018952: {"stream":"dentusdt@depth@100ms","data":{"e":"depthUpdate","E":1618677455962,"T":1618677455932,"s":"DENTUSDT","U":335340832804,"u":335340834796,"pu":335340832065,"b":[["0.012177","112368"]],"a":[["0.012351","2598"],["0.012357","80023"],["0.012359","0"],["0.012360","75331"],["0.012361","0"],["0.012362","0"],["0.012366","103744"],["0.012381","76380"],["0.012384","54807"]]}}
1618677456.060677: {"stream":"xmrusdt@depth@100ms","data":{"e":"depthUpdate","E":1618677456002,"T":1618677455971,"s":"XMRUSDT","U":335340833839,"u":335340835926,"pu":335340832501,"b":[["321.75","0.900"],["341.93","0.074"],["350.24","1.125"],["352.04","6.813"],["352.12","0.000"],["352.18","0.000"]],"a":[["355.82","293.567"]]}}
1618677456.090274: {"stream":"yfiusdt@depth@100ms","data":{"e":"depthUpdate","E":1618677456029,"T":1618677456017,"s":"YFIUSDT","U":335340834626,"u":335340837488,"pu":335340833364,"b":[["48984.1","0.000"],["49227.5","0.000"],["49885.6","0.000"],["49898.9","0.024"],["49944.1","0.000"],["49950.1","0.041"],["49955.7","0.012"],["49965.6","0.006"],["49974.4","0.000"]],"a":[["50019.0","0.090"],["50066.5","0.000"],["50079.8","0.011"],["50740.7","0.000"]]}}
1618677456.097813: {"stream":"xmrusdt@bookTicker","data":{"e":"bookTicker","u":335340838333,"s":"XMRUSDT","b":"352.40","B":"4.213","a":"352.49","A":"1.000","T":1618677456036,"E":1618677456039}}
1618677456.1078348: {"stream":"xmrusdt@bookTicker","data":{"e":"bookTicker","u":335340838629,"s":"XMRUSDT","b":"352.40","B":"4.213","a":"352.42","A":"1.358","T":1618677456043,"E":1618677456047}}
1618677456.110868: {"stream":"ksmusdt@depth@100ms","data":{"e":"depthUpdate","E":1618677456052,"T":1618677456039,"s":"KSMUSDT","U":335340835254,"u":335340838486,"pu":335340835129,"b":[["456.826","0.9"],["457.053","15.0"],["457.486","2.0"],["457.864","0.0"],["458.002","1.9"],["458.062","0.0"],["458.126","0.0"],["458.143","1.1"],["458.144","2.5"],["458.252","0.5"],["458.424","1.5"],["458.591","0.0"],["458.605","0.3"],["458.657","0.9"]],"a":[["459.050","1.6"],["459.247","0.0"],["459.695","0.0"],["459.707","0.0"],["459.712","0.4"],["459.790","1.0"],["459.893","2.2"],["460.279","0.0"],["461.555","15.0"],["463.806","15.0"]]}}
1618677456.115515: {"stream":"ksmusdt@aggTrade","data":{"e":"aggTrade","E":1618677456057,"a":21396981,"s":"KSMUSDT","p":"458.757","q":"0.1","f":25426574,"l":25426574,"T":1618677455902,"m":true}}
1618677456.231991: {"stream":"xmrusdt@bookTicker","data":{"e":"bookTicker","u":335340839053,"s":"XMRUSDT","b":"352.40","B":"4.778","a":"352.42","A":"1.358","T":1618677456053,"E":1618677456057}}
1618677456.2372742: {"stream":"dentusdt@depth@100ms","data":{"e":"depthUpdate","E":1618677456067,"T":1618677456008,"s":"DENTUSDT","U":335340835624,"u":335340837189,"pu":335340834796,"b":[],"a":[["0.012356","63374"],["0.012357","26048"],["0.012359","57938"],["0.012360","17393"],["0.012363","275318"],["0.012366","53957"],["0.012381","76382"]]}}
1618677456.2436879: {"stream":"xmrusdt@bookTicker","data":{"e":"bookTicker","u":335340840090,"s":"XMRUSDT","b":"352.40","B":"4.213","a":"352.42","A":"1.358","T":1618677456085,"E":1618677456089}}
1618677456.271654: {"stream":"xmrusdt@depth@100ms","data":{"e":"depthUpdate","E":1618677456114,"T":1618677456086,"s":"XMRUSDT","U":335340837252,"u":335340840103,"pu":335340835926,"b":[["352.04","4.313"],["352.12","2.500"],["352.27","0.000"],["352.28","0.000"],["352.35","0.565"],["352.40","4.213"]],"a":[["352.42","1.358"],["352.43","0.000"],["353.06","0.000"],["353.07","0.000"],["356.55","0.000"],["379.87","64.420"]]}}
1618677456.274702: {"stream":"yfiusdt@depth@100ms","data":{"e":"depthUpdate","E":1618677456137,"T":1618677456094,"s":"YFIUSDT","U":335340838249,"u":335340840354,"pu":335340837488,"b":[["49876.0","0.141"],["49876.3","0.000"],["49908.5","0.060"],["49923.8","0.000"],["49955.8","0.005"],["49965.5","0.000"],["49965.7","0.003"]],"a":[["50018.9","0.019"],["50079.2","0.060"],["50093.5","0.000"],["50105.2","0.000"],["50116.6","0.152"],["50121.1","0.157"],["50174.2","0.000"]]}}
1618677456.277628: {"stream":"ksmusdt@depth@100ms","data":{"e":"depthUpdate","E":1618677456152,"T":1618677456149,"s":"KSMUSDT","U":335340838863,"u":335340841194,"pu":335340838486,"b":[["452.834","3.6"],["454.802","15.0"],["457.439","24.4"],["457.805","6.4"],["458.002","0.0"],["458.020","2.8"],["458.065","0.0"]],"a":[["459.529","0.1"],["459.558","0.1"],["459.978","8.5"],["463.331","15.0"],["463.806","0.0"]]}}
1618677456.2857192: {"stream":"dentusdt@depth@100ms","data":{"e":"depthUpdate","E":1618677456197,"T":1618677456181,"s":"DENTUSDT","U":335340840344,"u":335340842142,"pu":335340837189,"b":[["0.012211","427853"]],"a":[["0.012357","159929"],["0.012358","0"],["0.012366","53957"],["0.012368","11205"],["0.012373","0"],["0.012381","76382"]]}}
1618677456.28895: {"stream":"xmrusdt@depth@100ms","data":{"e":"depthUpdate","E":1618677456222,"T":1618677456162,"s":"XMRUSDT","U":335340840645,"u":335340841597,"pu":335340840103,"b":[["352.12","0.000"],["352.18","2.500"]],"a":[["352.66","2.500"],["352.68","30.368"],["352.82","0.000"]]}}
1618677456.291239: {"stream":"yfiusdt@bookTicker","data":{"e":"bookTicker","u":335340843284,"s":"YFIUSDT","b":"49975.7","B":"0.006","a":"49986.7","A":"0.001","T":1618677456226,"E":1618677456230}}
1618677456.294776: {"stream":"yfiusdt@bookTicker","data":{"e":"bookTicker","u":335340843481,"s":"YFIUSDT","b":"49975.7","B":"0.006","a":"49977.5","A":"0.001","T":1618677456234,"E":1618677456237}}
1618677456.300627: {"stream":"dentusdt@bookTicker","data":{"e":"bookTicker","u":335340843637,"s":"DENTUSDT","b":"0.012350","B":"218581","a":"0.012351","A":"3133","T":1618677456238,"E":1618677456243}}
1618677456.310834: {"stream":"ksmusdt@depth@100ms","data":{"e":"depthUpdate","E":1618677456253,"T":1618677456233,"s":"KSMUSDT","U":335340841265,"u":335340843457,"pu":335340841194,"b":[["454.337","15.0"],["454.802","0.0"],["456.585","15.0"],["457.053","0.0"],["458.067","0.0"],["458.605","0.0"],["458.656","1.3"],["458.658","0.3"]],"a":[["459.401","0.1"],["459.550","0.0"],["459.690","0.5"],["460.010","2.3"],["461.083","18.0"],["461.555","0.0"]]}}
1618677456.313223: {"stream":"yfiusdt@depth@100ms","data":{"e":"depthUpdate","E":1618677456255,"T":1618677456236,"s":"YFIUSDT","U":335340841331,"u":335340843559,"pu":335340840354,"b":[["49834.5","0.122"],["49924.2","0.000"],["49928.8","0.001"],["49932.1","0.001"],["49932.9","0.001"],["49952.0","0.009"]],"a":[["49977.5","0.001"],["49979.2","0.000"],["50019.0","0.000"],["50043.5","0.009"],["50057.4","0.037"]]}}
1618677456.324139: {"stream":"xmrusdt@bookTicker","data":{"e":"bookTicker","u":335340844389,"s":"XMRUSDT","b":"352.40","B":"4.152","a":"352.42","A":"1.358","T":1618677456261,"E":1618677456264}}
1618677456.324239: {"stream":"xmrusdt@kline_1m","data":{"e":"kline","E":1618677456265,"s":"XMRUSDT","k":{"t":1618677420000,"T":1618677479999,"s":"XMRUSDT","i":"1m","f":34692938,"L":34692972,"o":"352.86","c":"352.40","h":"352.93","l":"352.40","v":"31.600","n":35,"x":false,"q":"11143.34702","V":"1.638","Q":"577.96953","B":"0"}}}
1618677456.357615: {"stream":"dentusdt@bookTicker","data":{"e":"bookTicker","u":335340845666,"s":"DENTUSDT","b":"0.012350","B":"71533","a":"0.012351","A":"3133","T":1618677456294,"E":1618677456297}}
1618677456.357715: {"stream":"dentusdt@kline_1m","data":{"e":"kline","E":1618677456299,"s":"DENTUSDT","k":{"t":1618677420000,"T":1618677479999,"s":"DENTUSDT","i":"1m","f":15787262,"L":15787399,"o":"0.012366","c":"0.012350","h":"0.012366","l":"0.012339","v":"2335780","n":138,"x":false,"q":"28852.221639","V":"1126408","Q":"13917.131440","B":"0"}}}
1618677456.383671: {"stream":"dentusdt@depth@100ms","data":{"e":"depthUpdate","E":1618677456325,"T":1618677456312,"s":"DENTUSDT","U":335340843163,"u":335340846340,"pu":335340842142,"b":[["0.012345","0"],["0.012349","0"],["0.012350","71533"]],"a":[["0.012351","3133"],["0.012352","0"],["0.012362","53957"],["0.012366","0"],["0.012370","11311"],["0.012381","76382"],["0.012388","620264"],["0.012389","82420"]]}}
1618677456.418137: {"stream":"xmrusdt@depth@100ms","data":{"e":"depthUpdate","E":1618677456360,"T":1618677456302,"s":"XMRUSDT","U":335340844240,"u":335340845913,"pu":335340841597,"b":[["352.40","4.152"]],"a":[["352.49","1.565"],["352.66","2.500"],["352.82","0.000"]]}}
1618677456.422412: {"stream":"ksmusdt@depth@100ms","data":{"e":"depthUpdate","E":1618677456364,"T":1618677456322,"s":"KSMUSDT","U":335340844328,"u":335340846660,"pu":335340843457,"b":[["454.337","30.0"],["455.496","16.0"],["455.733","0.9"],["456.585","30.0"],["457.218","16.0"],["457.454","0.0"]],"a":[["459.513","2.1"],["459.606","2.7"],["459.619","0.0"],["459.743","7.3"],["460.661","16.0"],["460.899","0.0"],["461.083","33.0"],["462.382","16.0"],["462.621","0.0"],["463.331","30.0"]]}}
1618677456.426657: {"stream":"yfiusdt@depth@100ms","data":{"e":"depthUpdate","E":1618677456367,"T":1618677456357,"s":"YFIUSDT","U":335340844470,"u":335340848115,"pu":335340843559,"b":[["49226.1","0.203"],["49362.8","0.000"],["49944.1","0.284"]],"a":[["50018.9","0.000"],["50140.5","0.014"],["50174.9","0.000"],["50244.0","0.020"]]}}
1618677456.469729: {"stream":"ksmusdt@bookTicker","data":{"e":"bookTicker","u":335340849836,"s":"KSMUSDT","b":"458.744","B":"0.4","a":"458.960","A":"0.3","T":1618677456408,"E":1618677456412}}
1618677456.4707232: {"stream":"xmrusdt@aggTrade","data":{"e":"aggTrade","E":1618677456415,"a":23619026,"s":"XMRUSDT","p":"352.40","q":"0.061","f":34692972,"l":34692972,"T":1618677456261,"m":true}}
1618677456.4874098: {"stream":"dentusdt@depth@100ms","data":{"e":"depthUpdate","E":1618677456428,"T":1618677456397,"s":"DENTUSDT","U":335340846688,"u":335340849449,"pu":335340846340,"b":[["0.012322","147531"],["0.012323","25847"],["0.012326","510142"],["0.012344","178162"]],"a":[["0.012362","0"],["0.012363","299502"],["0.012366","134947"],["0.012378","323874"],["0.012381","22403"],["0.012400","744907"]]}}
1618677456.4942331: {"stream":"yfiusdt@bookTicker","data":{"e":"bookTicker","u":335340850423,"s":"YFIUSDT","b":"49973.0","B":"0.003","a":"49977.5","A":"0.001","T":1618677456431,"E":1618677456435}}
1618677456.506002: {"stream":"dentusdt@aggTrade","data":{"e":"aggTrade","E":1618677456448,"a":8476412,"s":"DENTUSDT","p":"0.012350","q":"147048","f":15787399,"l":15787400,"T":1618677456294,"m":true}}
1618677456.516275: {"stream":"dentusdt@bookTicker","data":{"e":"bookTicker","u":335340850987,"s":"DENTUSDT","b":"0.012350","B":"799","a":"0.012351","A":"3133","T":1618677456454,"E":1618677456459}}
1618677456.516358: {"stream":"yfiusdt@bookTicker","data":{"e":"bookTicker","u":335340851052,"s":"YFIUSDT","b":"49974.3","B":"0.006","a":"49977.5","A":"0.001","T":1618677456457,"E":1618677456460}}
1618677456.539972: {"stream":"yfiusdt@depth@100ms","data":{"e":"depthUpdate","E":1618677456482,"T":1618677456457,"s":"YFIUSDT","U":335340848885,"u":335340851052,"pu":335340848115,"b":[["49974.3","0.006"],["49975.7","0.000"]],"a":[["50077.7","0.094"],["50728.9","0.197"]]}}
1618677456.5572531: {"stream":"ksmusdt@bookTicker","data":{"e":"bookTicker","u":335340852051,"s":"KSMUSDT","b":"458.744","B":"0.4","a":"458.852","A":"0.1","T":1618677456495,"E":1618677456499}}
1618677456.570634: {"stream":"ksmusdt@depth@100ms","data":{"e":"depthUpdate","E":1618677456512,"T":1618677456504,"s":"KSMUSDT","U":335340849836,"u":335340852358,"pu":335340846660,"b":[["457.537","10.2"],["458.655","0.0"]],"a":[["458.852","0.1"],["458.924","0.0"],["459.303","17.9"],["459.792","0.0"],["460.153","1.6"],["460.384","0.0"],["463.558","0.2"]]}}
1618677456.586328: {"stream":"dentusdt@depth@100ms","data":{"e":"depthUpdate","E":1618677456528,"T":1618677456507,"s":"DENTUSDT","U":335340850258,"u":335340852458,"pu":335340849449,"b":[["0.012326","505950"],["0.012339","7638"],["0.012344","129581"],["0.012350","799"]],"a":[["0.012355","53957"],["0.012362","53979"]]}}
1618677456.5865338: {"stream":"yfiusdt@bookTicker","data":{"e":"bookTicker","u":335340853007,"s":"YFIUSDT","b":"49973.0","B":"0.003","a":"49977.5","A":"0.001","T":1618677456525,"E":1618677456528}}
1618677456.59149: {"stream":"yfiusdt@bookTicker","data":{"e":"bookTicker","u":335340853021,"s":"YFIUSDT","b":"49973.0","B":"0.003","a":"49976.2","A":"0.009","T":1618677456526,"E":1618677456530}}
1618677456.6026309: {"stream":"xmrusdt@depth@100ms","data":{"e":"depthUpdate","E":1618677456544,"T":1618677456469,"s":"XMRUSDT","U":335340850677,"u":335340851386,"pu":335340845913,"b":[["351.40","212.968"],["352.26","7.052"]],"a":[]}}
1618677456.613472: {"stream":"xmrusdt@bookTicker","data":{"e":"bookTicker","u":335340853775,"s":"XMRUSDT","b":"352.40","B":"4.152","a":"352.49","A":"1.565","T":1618677456549,"E":1618677456554}}
1618677456.6176152: {"stream":"xmrusdt@bookTicker","data":{"e":"bookTicker","u":335340853949,"s":"XMRUSDT","b":"352.40","B":"4.152","a":"352.41","A":"1.358","T":1618677456556,"E":1618677456559}}
1618677456.628405: {"stream":"dentusdt@bookTicker","data":{"e":"bookTicker","u":335340854321,"s":"DENTUSDT","b":"0.012350","B":"3065","a":"0.012351","A":"3133","T":1618677456566,"E":1618677456570}}
1618677456.676251: {"stream":"yfiusdt@depth@100ms","data":{"e":"depthUpdate","E":1618677456619,"T":1618677456573,"s":"YFIUSDT","U":335340852741,"u":335340854523,"pu":335340851052,"b":[["49899.0","0.025"],["49944.1","0.000"],["49955.9","0.003"],["49965.7","0.000"],["49974.3","0.000"]],"a":[["49976.2","0.009"],["50156.3","0.000"],["50208.3","0.000"]]}}
1618677456.684878: {"stream":"yfiusdt@bookTicker","data":{"e":"bookTicker","u":335340855913,"s":"YFIUSDT","b":"49973.0","B":"0.003","a":"49976.1","A":"0.055","T":1618677456623,"E":1618677456627}}
1618677456.687005: {"stream":"ksmusdt@depth@100ms","data":{"e":"depthUpdate","E":1618677456630,"T":1618677456595,"s":"KSMUSDT","U":335340853015,"u":335340855068,"pu":335340852358,"b":[["458.143","0.0"],["458.145","1.1"],["458.425","8.4"],["458.656","0.0"],["458.657","0.0"]],"a":[["459.772","6.2"],["459.790","0.0"],["459.791","0.0"],["459.881","1.0"],["462.771","0.2"]]}}
1618677456.693463: {"stream":"yfiusdt@bookTicker","data":{"e":"bookTicker","u":335340856140,"s":"YFIUSDT","b":"49973.0","B":"0.003","a":"49974.8","A":"0.009","T":1618677456633,"E":1618677456636}}
1618677456.7012632: {"stream":"yfiusdt@bookTicker","data":{"e":"bookTicker","u":335340856331,"s":"YFIUSDT","b":"49973.0","B":"0.003","a":"49976.1","A":"0.055","T":1618677456640,"E":1618677456643}}
1618677456.7053282: {"stream":"yfiusdt@bookTicker","data":{"e":"bookTicker","u":335340856337,"s":"YFIUSDT","b":"49974.3","B":"0.006","a":"49976.1","A":"0.055","T":1618677456640,"E":1618677456645}}
1618677456.705431: {"stream":"dentusdt@depth@100ms","data":{"e":"depthUpdate","E":1618677456646,"T":1618677456586,"s":"DENTUSDT","U":335340853579,"u":335340854827,"pu":335340852458,"b":[["0.010304","1003060"],["0.010573","331020"],["0.010850","1125396"],["0.010996","280340"],["0.011124","110340"],["0.011225","105675"],["0.011293","80796"],["0.011350","1468543"],["0.011395","55170"],["0.011658","75687"],["0.011838","18390"],["0.011983","6130"],["0.012105","550715"],["0.012202","48603"],["0.012264","67859"],["0.012313","71077"],["0.012350","3065"]],"a":[["0.012355","74861"],["0.012357","139025"],["0.012391","44842"]]}}
1618677456.709127: {"stream":"yfiusdt@bookTicker","data":{"e":"bookTicker","u":335340856524,"s":"YFIUSDT","b":"49973.0","B":"0.003","a":"49976.1","A":"0.055","T":1618677456648,"E":1618677456651}}
1618677456.709234: {"stream":"yfiusdt@bookTicker","data":{"e":"bookTicker","u":335340856530,"s":"YFIUSDT","b":"49973.0","B":"0.003","a":"49974.8","A":"0.009","T":1618677456648,"E":1618677456651}}
1618677456.712299: {"stream":"xmrusdt@depth@100ms","data":{"e":"depthUpdate","E":1618677456654,"T":1618677456592,"s":"XMRUSDT","U":335340853775,"u":335340854987,"pu":335340851386,"b":[],"a":[["352.41","1.358"],["352.42","0.000"],["352.49","1.000"],["352.58","0.000"]]}}
1618677456.7146199: {"stream":"yfiusdt@bookTicker","data":{"e":"bookTicker","u":335340856618,"s":"YFIUSDT","b":"49973.0","B":"0.003","a":"49976.1","A":"0.055","T":1618677456652,"E":1618677456656}}
1618677456.7176478: {"stream":"yfiusdt@bookTicker","data":{"e":"bookTicker","u":335340856716,"s":"YFIUSDT","b":"49974.3","B":"0.006","a":"49976.1","A":"0.055","T":1618677456656,"E":1618677456659}}
1618677456.7241018: {"stream":"yfiusdt@bookTicker","data":{"e":"bookTicker","u":335340856868,"s":"YFIUSDT","b":"49973.0","B":"0.003","a":"49976.1","A":"0.055","T":1618677456661,"E":1618677456666}}
1618677456.724213: {"stream":"yfiusdt@bookTicker","data":{"e":"bookTicker","u":335340856873,"s":"YFIUSDT","b":"49973.0","B":"0.003","a":"49974.8","A":"0.009","T":1618677456661,"E":1618677456666}}
1618677456.724702: {"stream":"yfiusdt@bookTicker","data":{"e":"bookTicker","u":335340856993,"s":"YFIUSDT","b":"49973.0","B":"0.003","a":"49976.1","A":"0.055","T":1618677456665,"E":1618677456668}}
1618677456.732589: {"stream":"yfiusdt@bookTicker","data":{"e":"bookTicker","u":335340857153,"s":"YFIUSDT","b":"49974.3","B":"0.006","a":"49976.1","A":"0.055","T":1618677456672,"E":1618677456675}}
1618677456.7369752: {"stream":"yfiusdt@bookTicker","data":{"e":"bookTicker","u":335340857244,"s":"YFIUSDT","b":"49973.0","B":"0.003","a":"49976.1","A":"0.055","T":1618677456675,"E":1618677456679}}
1618677456.745779: {"stream":"ksmusdt@bookTicker","data":{"e":"bookTicker","u":335340857445,"s":"KSMUSDT","b":"458.744","B":"0.4","a":"458.830","A":"6.4","T":1618677456684,"E":1618677456688}}
1618677456.7704692: {"stream":"yfiusdt@bookTicker","data":{"e":"bookTicker","u":335340858077,"s":"YFIUSDT","b":"49973.0","B":"0.003","a":"49976.1","A":"0.028","T":1618677456708,"E":1618677456712}}
1618677456.770571: {"stream":"yfiusdt@kline_1m","data":{"e":"kline","E":1618677456713,"s":"YFIUSDT","k":{"t":1618677420000,"T":1618677479999,"s":"YFIUSDT","i":"1m","f":64902095,"L":64902172,"o":"50010.8","c":"49976.1","h":"50044.2","l":"49950.6","v":"0.972","n":78,"x":false,"q":"48598.9835","V":"0.667","Q":"33349.5651","B":"0"}}}
1618677456.7811542: {"stream":"yfiusdt@bookTicker","data":{"e":"bookTicker","u":335340858319,"s":"YFIUSDT","b":"49974.3","B":"0.006","a":"49976.1","A":"0.028","T":1618677456718,"E":1618677456723}}
1618677456.7873762: {"stream":"yfiusdt@depth@100ms","data":{"e":"depthUpdate","E":1618677456727,"T":1618677456722,"s":"YFIUSDT","U":335340855913,"u":335340858446,"pu":335340854523,"b":[["49281.3","0.020"],["49920.1","0.000"],["49923.3","0.000"],["49924.1","0.000"],["49928.8","0.000"],["49932.1","0.000"],["49932.9","0.000"],["49936.3","0.087"],["49940.8","0.000"],["49942.6","0.000"],["49942.8","0.192"],["49949.3","0.000"],["49949.4","0.000"],["49950.1","0.000"],["49952.4","0.027"],["49965.4","0.000"],["49965.6","0.000"],["49974.3","0.006"],["50226.0","0.000"]],"a":[["49974.8","0.000"],["49976.1","0.028"],["49976.2","0.000"],["49998.8","0.000"],["49999.0","0.000"],["50012.9","0.013"],["50013.9","0.000"],["50019.3","0.085"],["50021.3","0.000"],["50023.7","0.013"],["50025.0","0.000"],["50027.2","0.000"],["50032.2","0.011"],["50032.3","0.000"],["50035.9","0.000"],["50036.7","0.000"],["50036.8","0.000"],["50039.7","0.011"],["50043.0","0.000"],["50043.1","0.000"],["50043.9","0.100"],["50044.0","0.000"],["50044.2","0.000"],["50045.5","0.011"],["50050.0","0.002"]]}}
1618677456.797654: {"stream":"dentusdt@bookTicker","data":{"e":"bookTicker","u":335340858743,"s":"DENTUSDT","b":"0.012347","B":"69125","a":"0.012351","A":"3133","T":1618677456734,"E":1618677456738}}
1618677456.797759: {"stream":"dentusdt@kline_1m","data":{"e":"kline","E":1618677456739,"s":"DENTUSDT","k":{"t":1618677420000,"T":1618677479999,"s":"DENTUSDT","i":"1m","f":15787262,"L":15787401,"o":"0.012366","c":"0.012350","h":"0.012366","l":"0.012339","v":"2482873","n":140,"x":false,"q":"30668.820189","V":"1126408","Q":"13917.131440","B":"0"}}}
1618677456.801561: {"stream":"dentusdt@aggTrade","data":{"e":"aggTrade","E":1618677456740,"a":8476413,"s":"DENTUSDT","p":"0.012350","q":"3065","f":15787401,"l":15787402,"T":1618677456734,"m":true}}
1618677456.8016698: {"stream":"dentusdt@bookTicker","data":{"e":"bookTicker","u":335340858805,"s":"DENTUSDT","b":"0.012347","B":"69125","a":"0.012355","A":"74861","T":1618677456736,"E":1618677456740}}
1618677456.801718: {"stream":"yfiusdt@bookTicker","data":{"e":"bookTicker","u":335340858839,"s":"YFIUSDT","b":"49974.3","B":"0.006","a":"49977.5","A":"0.001","T":1618677456737,"E":1618677456740}}
1618677456.801753: {"stream":"ksmusdt@depth@100ms","data":{"e":"depthUpdate","E":1618677456743,"T":1618677456724,"s":"KSMUSDT","U":335340856318,"u":335340858464,"pu":335340855068,"b":[["457.697","0.0"],["458.017","1.9"],["458.145","0.0"],["458.426","2.9"],["458.427","1.1"],["458.591","0.3"],["458.658","0.0"]],"a":[["458.830","6.4"],["458.927","0.3"],["458.928","1.2"],["458.958","0.0"],["458.959","1.6"],["458.960","0.0"],["459.050","0.0"],["459.051","0.0"],["459.331","0.0"],["460.269","0.0"]]}}
1618677456.8041759: {"stream":"yfiusdt@bookTicker","data":{"e":"bookTicker","u":335340858964,"s":"YFIUSDT","b":"49974.3","B":"0.006","a":"49986.7","A":"0.001","T":1618677456742,"E":1618677456746}}
1618677456.8107479: {"stream":"dentusdt@bookTicker","data":{"e":"bookTicker","u":335340859119,"s":"DENTUSDT","b":"0.012347","B":"69125","a":"0.012354","A":"8766","T":1618677456748,"E":1618677456752}}
1618677456.81466: {"stream":"yfiusdt@bookTicker","data":{"e":"bookTicker","u":335340859202,"s":"YFIUSDT","b":"49974.3","B":"0.006","a":"49975.9","A":"0.001","T":1618677456751,"E":1618677456756}}
1618677456.849283: {"stream":"dentusdt@depth@100ms","data":{"e":"depthUpdate","E":1618677456793,"T":1618677456775,"s":"DENTUSDT","U":335340857548,"u":335340859893,"pu":335340854827,"b":[["0.012342","87167"],["0.012350","0"]],"a":[["0.012350","0"],["0.012351","0"],["0.012354","8766"],["0.012356","53979"],["0.012397","185611"]]}}
1618677456.86546: {"stream":"xmrusdt@depth@100ms","data":{"e":"depthUpdate","E":1618677456807,"T":1618677456798,"s":"XMRUSDT","U":335340857911,"u":335340860492,"pu":335340854987,"b":[["351.96","18.829"],["352.01","3.164"]],"a":[["352.66","0.000"],["352.82","2.500"]]}}
1618677456.8689501: {"stream":"yfiusdt@aggTrade","data":{"e":"aggTrade","E":1618677456810,"a":52599694,"s":"YFIUSDT","p":"49976.1","q":"0.027","f":64902172,"l":64902172,"T":1618677456708,"m":false}}
1618677456.869035: {"stream":"yfiusdt@bookTicker","data":{"e":"bookTicker","u":335340860793,"s":"YFIUSDT","b":"49974.3","B":"0.006","a":"49986.7","A":"0.001","T":1618677456807,"E":1618677456810}}
1618677456.888412: {"stream":"yfiusdt@depth@100ms","data":{"e":"depthUpdate","E":1618677456828,"T":1618677456822,"s":"YFIUSDT","U":335340858485,"u":335340861191,"pu":335340858446,"b":[["49426.0","0.162"],["49850.0","0.017"],["49898.3","0.054"],["49911.0","0.000"],["49921.2","0.000"],["49927.4","0.001"],["49930.7","0.001"],["49931.5","0.001"],["49933.8","0.110"],["49936.4","0.080"],["49942.4","0.130"],["49942.8","0.000"],["49949.1","0.080"],["49950.1","0.262"],["49952.4","0.009"],["49955.9","0.000"],["49965.4","0.003"]],"a":[["49975.9","0.000"],["49976.1","0.000"],["49977.5","0.000"],["50012.9","0.000"],["50013.9","0.000"],["50021.3","0.000"],["50023.7","0.000"],["50025.0","0.000"],["50027.2","0.000"],["50032.2","0.066"],["50035.8","0.000"],["50036.7","0.000"],["50039.6","0.015"],["50039.7","0.000"],["50042.9","0.003"],["50043.9","0.000"],["50045.5","0.021"],["50077.7","0.000"],["50104.9","0.000"],["50120.0","0.017"]]}}
1618677456.894989: {"stream":"yfiusdt@bookTicker","data":{"e":"bookTicker","u":335340861454,"s":"YFIUSDT","b":"49974.4","B":"0.025","a":"49986.7","A":"0.001","T":1618677456834,"E":1618677456836}}
1618677456.9065862: {"stream":"ksmusdt@bookTicker","data":{"e":"bookTicker","u":335340861749,"s":"KSMUSDT","b":"458.766","B":"2.3","a":"458.830","A":"6.4","T":1618677456845,"E":1618677456849}}
1618677456.90925: {"stream":"yfiusdt@bookTicker","data":{"e":"bookTicker","u":335340861796,"s":"YFIUSDT","b":"49975.7","B":"0.006","a":"49986.7","A":"0.001","T":1618677456847,"E":1618677456851}}
1618677456.910903: {"stream":"ksmusdt@bookTicker","data":{"e":"bookTicker","u":335340861843,"s":"KSMUSDT","b":"458.744","B":"0.4","a":"458.830","A":"6.4","T":1618677456849,"E":1618677456853}}
1618677456.911027: {"stream":"ksmusdt@depth@100ms","data":{"e":"depthUpdate","E":1618677456854,"T":1618677456849,"s":"KSMUSDT","U":335340859156,"u":335340861843,"pu":335340858464,"b":[["458.127","0.0"],["458.128","0.0"],["458.243","14.8"],["458.591","0.0"],["458.605","0.3"],["458.766","0.0"]],"a":[["458.898","0.3"],["458.899","0.0"],["458.927","0.0"],["458.928","0.0"],["458.959","0.0"],["459.247","1.6"],["469.296","0.8"]]}}
1618677456.945954: {"stream":"yfiusdt@bookTicker","data":{"e":"bookTicker","u":335340862814,"s":"YFIUSDT","b":"49975.8","B":"0.003","a":"49986.7","A":"0.001","T":1618677456884,"E":1618677456887}}
1618677456.946816: {"stream":"dentusdt@aggTrade","data":{"e":"aggTrade","E":1618677456891,"a":8476414,"s":"DENTUSDT","p":"0.012351","q":"3133","f":15787403,"l":15787404,"T":1618677456736,"m":false}}
1618677456.969721: {"stream":"dentusdt@bookTicker","data":{"e":"bookTicker","u":335340863376,"s":"DENTUSDT","b":"0.012347","B":"69125","a":"0.012354","A":"62723","T":1618677456908,"E":1618677456911}}
1618677456.969821: {"stream":"xmrusdt@depth@100ms","data":{"e":"depthUpdate","E":1618677456913,"T":1618677456904,"s":"XMRUSDT","U":335340860868,"u":335340863291,"pu":335340860492,"b":[["352.33","0.000"]],"a":[["352.59","1.187"],["352.68","32.868"],["352.82","0.000"],["353.40","2.886"],["362.20","0.446"],["362.54","0.181"]]}}
1618677456.9835021: {"stream":"dentusdt@depth@100ms","data":{"e":"depthUpdate","E":1618677456927,"T":1618677456912,"s":"DENTUSDT","U":335340861200,"u":335340863462,"pu":335340859893,"b":[["0.012116","123655"],["0.012344","81000"]],"a":[["0.012354","62723"],["0.012355","20904"],["0.012356","13298"],["0.012357","5144"],["0.012359","53979"],["0.012360","151274"],["0.012361","53979"],["0.012362","57938"],["0.012363","299502"],["0.012535","125874"],["0.012597","171681"],["0.012659","40008"],["0.012721","133573"],["0.012795","592"],["0.012869","939433"],["0.012943","133"],["0.013017","35502"],["0.013091","9137"]]}}
1618677456.9911392: {"stream":"yfiusdt@depth@100ms","data":{"e":"depthUpdate","E":1618677456935,"T":1618677456922,"s":"YFIUSDT","U":335340861377,"u":335340863689,"pu":335340861191,"b":[["48366.9","0.000"],["49524.4","0.000"],["49594.0","0.013"],["49800.3","0.000"],["49804.3","0.000"],["49804.7","0.000"],["49805.3","0.007"],["49856.3","0.157"],["49950.1","0.000"],["49965.4","0.000"],["49974.3","0.000"],["49974.4","0.025"],["49974.5","0.000"],["49975.7","0.006"],["49975.8","0.003"]],"a":[["49992.1","0.000"],["49997.8","0.003"],["50032.2","0.045"],["50036.6","0.016"],["50045.5","0.000"],["50050.0","0.018"],["50089.9","0.000"],["50119.9","0.100"],["50121.1","0.000"],["50126.6","0.157"],["50148.5","0.005"],["50226.0","0.014"],["50246.8","0.000"],["50253.8","0.000"],["50430.9","0.000"],["50463.0","0.000"],["50465.4","0.006"],["50563.1","0.000"]]}}
1618677457.017575: {"stream":"ksmusdt@depth@100ms","data":{"e":"depthUpdate","E":1618677456960,"T":1618677456952,"s":"KSMUSDT","U":335340862047,"u":335340864458,"pu":335340861843,"b":[["457.451","5.3"],["457.849","1.6"],["458.012","0.0"],["458.020","0.0"],["458.105","0.0"],["458.428","0.3"],["458.494","0.2"],["458.590","0.0"],["458.605","0.0"]],"a":[["459.389","2.2"],["459.486","2.3"],["459.509","1.4"],["459.512","0.0"],["460.022","3.2"]]}}
1618677457.0179079: {"stream":"yfiusdt@aggTrade","data":{"e":"aggTrade","E":1618677456961,"a":52599695,"s":"YFIUSDT","p":"49975.9","q":"0.001","f":64902173,"l":64902173,"T":1618677456807,"m":false}}
1618677457.059244: {"stream":"dentusdt@bookTicker","data":{"e":"bookTicker","u":335340865978,"s":"DENTUSDT","b":"0.012347","B":"69125","a":"0.012354","A":"8766","T":1618677456997,"E":1618677457000}}
1618677457.0892642: {"stream":"ksmusdt@bookTicker","data":{"e":"bookTicker","u":335340867431,"s":"KSMUSDT","b":"458.745","B":"0.2","a":"458.830","A":"6.4","T":1618677457025,"E":1618677457029}}
1618677457.089369: {"stream":"xmrusdt@depth@100ms","data":{"e":"depthUpdate","E":1618677457030,"T":1618677457003,"s":"XMRUSDT","U":335340863741,"u":335340866286,"pu":335340863291,"b":[["352.18","0.000"],["352.19","2.500"],["352.24","1.788"],["352.25","0.000"],["352.29","2.628"],["352.34","0.000"],["352.35","0.000"]],"a":[["352.48","0.565"],["352.51","2.813"],["355.15","21.889"],["357.19","1.763"],["357.28","0.551"]]}}
1618677457.09342: {"stream":"yfiusdt@bookTicker","data":{"e":"bookTicker","u":335340867600,"s":"YFIUSDT","b":"49975.9","B":"0.009","a":"49986.7","A":"0.001","T":1618677457029,"E":1618677457033}}
1618677457.0966551: {"stream":"yfiusdt@depth@100ms","data":{"e":"depthUpdate","E":1618677457037,"T":1618677457029,"s":"YFIUSDT","U":335340863901,"u":335340867630,"pu":335340863689,"b":[["48453.0","0.000"],["49572.2","0.000"],["49599.5","0.000"],["49604.2","0.000"],["49624.4","0.000"],["49794.3","0.000"],["49794.5","0.000"],["49801.8","0.002"],["49805.1","0.000"],["49805.8","0.000"],["49810.3","0.010"],["49812.5","0.000"],["49825.7","0.000"],["49917.0","0.110"],["49921.2","0.110"],["49929.6","0.000"],["49933.8","0.000"],["49936.5","0.035"],["49942.5","0.029"],["49949.3","0.019"],["49974.5","0.005"],["49975.9","0.009"]],"a":[["50019.2","0.018"],["50029.0","0.007"],["50032.2","0.000"],["50035.8","0.003"],["50042.9","0.000"],["50058.2","0.000"],["50078.2","0.000"],["50082.2","0.005"],["50084.8","0.000"],["50102.2","0.009"],["50114.9","0.050"],["50126.6","0.000"],["50150.0","0.000"],["50160.6","0.157"],["50253.0","0.000"],["50269.0","0.000"],["50378.9","0.000"],["50465.4","0.002"],["50520.5","0.000"]]}}
1618677457.101069: {"stream":"yfiusdt@bookTicker","data":{"e":"bookTicker","u":335340867954,"s":"YFIUSDT","b":"49977.2","B":"0.006","a":"49986.7","A":"0.001","T":1618677457038,"E":1618677457043}}
1618677457.1131148: {"stream":"yfiusdt@bookTicker","data":{"e":"bookTicker","u":335340868523,"s":"YFIUSDT","b":"49977.3","B":"0.011","a":"49986.7","A":"0.001","T":1618677457049,"E":1618677457053}}
1618677457.227905: {"stream":"dentusdt@depth@100ms","data":{"e":"depthUpdate","E":1618677457059,"T":1618677457039,"s":"DENTUSDT","U":335340864511,"u":335340868034,"pu":335340863462,"b":[],"a":[["0.012354","8766"],["0.012355","0"],["0.012356","0"],["0.012357","53957"],["0.012358","23745"],["0.012359","95085"],["0.012361","0"],["0.012363","249715"],["0.012378","327112"],["0.012379","50901"],["0.012380","9404"],["0.012384","40701"]]}}
1618677457.2281442: {"stream":"yfiusdt@bookTicker","data":{"e":"bookTicker","u":335340868924,"s":"YFIUSDT","b":"49977.3","B":"0.014","a":"49986.7","A":"0.001","T":1618677457058,"E":1618677457061}}
1618677457.228179: {"stream":"yfiusdt@bookTicker","data":{"e":"bookTicker","u":335340868986,"s":"YFIUSDT","b":"49978.6","B":"0.006","a":"49986.7","A":"0.001","T":1618677457059,"E":1618677457062}}
1618677457.22847: {"stream":"ksmusdt@depth@100ms","data":{"e":"depthUpdate","E":1618677457066,"T":1618677457050,"s":"KSMUSDT","U":335340864714,"u":335340868582,"pu":335340864458,"b":[["456.162","1.5"],["457.951","2.4"],["457.989","0.1"],["458.019","0.0"],["458.244","3.2"],["458.429","3.2"],["458.653","0.4"],["458.744","0.0"],["458.745","0.2"]],"a":[["458.895","0.3"],["458.896","1.2"],["458.898","0.0"],["459.272","0.1"],["459.302","6.4"],["459.401","0.0"],["459.406","1.4"],["459.430","0.1"],["459.509","1.2"],["459.516","0.1"],["459.529","0.0"],["459.558","0.0"],["459.593","0.0"],["460.566","1.6"],["460.862","0.0"],["463.392","1.6"]]}}
1618677457.232116: {"stream":"yfiusdt@bookTicker","data":{"e":"bookTicker","u":335340869404,"s":"YFIUSDT","b":"49978.7","B":"0.009","a":"49986.7","A":"0.001","T":1618677457068,"E":1618677457073}}
1618677457.2321868: {"stream":"ksmusdt@bookTicker","data":{"e":"bookTicker","u":335340869416,"s":"KSMUSDT","b":"458.745","B":"0.4","a":"458.830","A":"6.4","T":1618677457069,"E":1618677457073}}
1618677457.232215: {"stream":"yfiusdt@bookTicker","data":{"e":"bookTicker","u":335340869768,"s":"YFIUSDT","b":"49980.0","B":"0.006","a":"49986.7","A":"0.001","T":1618677457077,"E":1618677457081}}
1618677457.235407: {"stream":"yfiusdt@bookTicker","data":{"e":"bookTicker","u":335340870133,"s":"YFIUSDT","b":"49980.1","B":"0.003","a":"49986.7","A":"0.001","T":1618677457088,"E":1618677457091}}
1618677457.242235: {"stream":"xmrusdt@depth@100ms","data":{"e":"depthUpdate","E":1618677457134,"T":1618677457067,"s":"XMRUSDT","U":335340867672,"u":335340869364,"pu":335340866286,"b":[["350.96","0.625"],["351.11","0.000"],["351.96","18.523"],["351.97","3.232"],["352.27","1.480"],["352.30","0.553"]],"a":[]}}
1618677457.242388: {"stream":"yfiusdt@depth@100ms","data":{"e":"depthUpdate","E":1618677457141,"T":1618677457130,"s":"YFIUSDT","U":335340867939,"u":335340870921,"pu":335340867630,"b":[["49448.6","0.000"],["49597.0","0.000"],["49769.0","0.014"],["49796.6","0.000"],["49801.8","0.000"],["49804.1","0.000"],["49810.5","0.000"],["49927.4","0.000"],["49930.7","0.000"],["49931.5","0.000"],["49933.1","0.001"],["49936.4","0.081"],["49937.2","0.001"],["49975.7","0.000"],["49975.8","0.000"],["49975.9","0.000"],["49977.2","0.000"],["49977.3","0.003"],["49977.4","0.000"],["49978.6","0.000"],["49978.7","0.000"],["49980.0","0.006"],["49980.1","0.003"]],"a":[["49997.8","0.000"],["49997.9","0.000"],["50002.8","0.013"],["50011.1","0.003"],["50128.8","0.016"],["50150.5","0.000"],["50155.0","0.017"],["50163.3","0.000"],["50183.2","0.022"],["50244.4","0.000"],["50246.6","0.000"],["50246.9","0.000"],["50249.0","0.000"],["50352.3","0.009"],["50465.4","0.000"],["50609.4","0.000"]]}}
1618677457.244478: {"stream":"ksmusdt@bookTicker","data":{"e":"bookTicker","u":335340871432,"s":"KSMUSDT","b":"458.745","B":"0.4","a":"458.788","A":"0.1","T":1618677457154,"E":1618677457158}}
1618677457.247793: {"stream":"ksmusdt@depth@100ms","data":{"e":"depthUpdate","E":1618677457173,"T":1618677457154,"s":"KSMUSDT","U":335340869391,"u":335340871432,"pu":335340868582,"b":[["455.992","0.2"],["457.974","0.8"],["458.428","0.0"],["458.430","0.0"],["458.605","0.3"],["458.745","0.4"]],"a":[["458.788","0.1"],["458.852","0.0"],["459.703","2.4"],["459.980","1.9"],["463.550","0.2"]]}}
1618677457.249824: {"stream":"dentusdt@depth@100ms","data":{"e":"depthUpdate","E":1618677457186,"T":1618677457181,"s":"DENTUSDT","U":335340869925,"u":335340872497,"pu":335340868034,"b":[],"a":[["0.012355","53957"],["0.012356","53979"],["0.012357","0"],["0.012359","95085"],["0.012363","299502"],["0.012378","323874"],["0.012380","0"],["0.012384","54807"],["0.012477","111286"]]}}
1618677457.2955132: {"stream":"xmrusdt@depth@100ms","data":{"e":"depthUpdate","E":1618677457239,"T":1618677457224,"s":"XMRUSDT","U":335340871080,"u":335340874044,"pu":335340869364,"b":[["351.61","5.408"],["351.77","0.000"],["352.10","20.279"],["352.26","6.019"]],"a":[["352.94","33.964"],["352.95","0.000"],["352.96","0.752"],["360.72","41.802"]]}}
1618677457.334224: {"stream":"yfiusdt@depth@100ms","data":{"e":"depthUpdate","E":1618677457276,"T":1618677457265,"s":"YFIUSDT","U":335340871978,"u":335340875575,"pu":335340870921,"b":[["49930.5","0.000"],["49937.9","0.026"],["49952.5","0.252"],["49952.6","0.057"]],"a":[["50002.7","0.000"],["50011.1","0.000"],["50057.9","0.000"],["50062.1","0.026"]]}}
1618677457.3366442: {"stream":"ksmusdt@depth@100ms","data":{"e":"depthUpdate","E":1618677457277,"T":1618677457272,"s":"KSMUSDT","U":335340872166,"u":335340875853,"pu":335340871432,"b":[["457.927","2.2"],["457.950","0.2"],["457.951","0.0"],["458.425","7.1"]],"a":[["458.895","0.0"],["458.896","0.0"],["458.930","0.0"],["458.960","0.3"],["459.504","1.4"],["459.509","0.0"],["459.591","0.0"],["459.881","1.0"],["460.013","2.6"]]}}
1618677457.345581: {"stream":"dentusdt@bookTicker","data":{"e":"bookTicker","u":335340876132,"s":"DENTUSDT","b":"0.012347","B":"69125","a":"0.012354","A":"62723","T":1618677457281,"E":1618677457286}}
1618677457.361142: {"stream":"dentusdt@depth@100ms","data":{"e":"depthUpdate","E":1618677457304,"T":1618677457281,"s":"DENTUSDT","U":335340873325,"u":335340876143,"pu":335340872497,"b":[["0.012312","196787"],["0.012318","107772"],["0.012327","385644"],["0.012330","187039"],["0.012331","36708"],["0.012336","1243"],["0.012337","111830"],["0.012342","0"],["0.012344","0"]],"a":[["0.012354","62723"],["0.012355","18125"],["0.012356","0"],["0.012357","53979"],["0.012358","59604"],["0.012359","41106"],["0.012360","297017"],["0.012363","299502"],["0.012380","36490"],["0.012384","40701"]]}}
1618677457.422912: {"stream":"xmrusdt@depth@100ms","data":{"e":"depthUpdate","E":1618677457363,"T":1618677457298,"s":"XMRUSDT","U":335340875237,"u":335340876789,"pu":335340874044,"b":[["351.71","1.580"],["351.82","0.612"],["351.92","0.446"],["352.19","0.000"],["352.20","2.500"]],"a":[["352.68","32.868"],["352.82","0.000"]]}}
1618677457.436616: {"stream":"ksmusdt@depth@100ms","data":{"e":"depthUpdate","E":1618677457379,"T":1618677457362,"s":"KSMUSDT","U":335340875943,"u":335340879088,"pu":335340875853,"b":[["455.592","0.0"],["457.713","11.0"]],"a":[["458.917","1.2"],["458.928","0.3"],["458.929","0.0"],["458.960","0.0"]]}}
1618677457.462683: {"stream":"dentusdt@bookTicker","data":{"e":"bookTicker","u":335340880288,"s":"DENTUSDT","b":"0.012347","B":"69125","a":"0.012354","A":"8766","T":1618677457401,"E":1618677457405}}
1618677457.462789: {"stream":"dentusdt@depth@100ms","data":{"e":"depthUpdate","E":1618677457407,"T":1618677457401,"s":"DENTUSDT","U":335340876982,"u":335340880299,"pu":335340876143,"b":[["0.012337","27003"]],"a":[["0.012354","8766"],["0.012356","59605"],["0.012357","41113"],["0.012358","0"],["0.012359","0"],["0.012363","299502"],["0.012379","92093"],["0.012380","0"],["0.012384","40701"],["0.012391","44842"]]}}
1618677457.4851289: {"stream":"yfiusdt@depth@100ms","data":{"e":"depthUpdate","E":1618677457427,"T":1618677457323,"s":"YFIUSDT","U":335340877705,"u":335340877705,"pu":335340875575,"b":[],"a":[["50145.1","0.018"]]}}
1618677457.5058858: {"stream":"dentusdt@bookTicker","data":{"e":"bookTicker","u":335340881456,"s":"DENTUSDT","b":"0.012347","B":"69125","a":"0.012354","A":"62723","T":1618677457443,"E":1618677457448}}
1618677457.535669: {"stream":"xmrusdt@depth@100ms","data":{"e":"depthUpdate","E":1618677457480,"T":1618677457376,"s":"XMRUSDT","U":335340879511,"u":335340879511,"pu":335340876789,"b":[],"a":[["360.18","0.000"]]}}
1618677457.562633: {"stream":"ksmusdt@depth@100ms","data":{"e":"depthUpdate","E":1618677457507,"T":1618677457487,"s":"KSMUSDT","U":335340880335,"u":335340882768,"pu":335340879088,"b":[["453.252","0.2"],["454.157","0.2"],["457.741","0.0"],["457.850","31.5"],["458.605","0.0"],["458.653","0.7"]],"a":[["458.914","0.3"],["458.915","1.2"],["458.916","0.0"],["458.917","0.0"],["458.928","0.0"],["460.407","2.8"],["460.850","3.9"],["460.906","0.0"],["462.915","3.9"],["462.970","0.0"]]}}
1618677457.577047: {"stream":"dentusdt@depth@100ms","data":{"e":"depthUpdate","E":1618677457521,"T":1618677457491,"s":"DENTUSDT","U":335340880718,"u":335340882850,"pu":335340880299,"b":[["0.012286","491834"],["0.012295","186392"],["0.012339","56219"]],"a":[["0.012354","62723"],["0.012357","0"],["0.012358","53979"],["0.012359","41106"]]}}
1618677457.591344: {"stream":"yfiusdt@bookTicker","data":{"e":"bookTicker","u":335340883824,"s":"YFIUSDT","b":"49981.4","B":"0.006","a":"49986.7","A":"0.001","T":1618677457527,"E":1618677457532}}
1618677457.5963871: {"stream":"yfiusdt@depth@100ms","data":{"e":"depthUpdate","E":1618677457538,"T":1618677457527,"s":"YFIUSDT","U":335340881197,"u":335340883824,"pu":335340877705,"b":[["49666.7","0.030"],["49980.0","0.000"],["49981.4","0.006"]],"a":[]}}
1618677457.647031: {"stream":"xmrusdt@depth@100ms","data":{"e":"depthUpdate","E":1618677457590,"T":1618677457485,"s":"XMRUSDT","U":335340882694,"u":335340882694,"pu":335340879511,"b":[],"a":[["359.81","30.238"]]}}
1618677457.676203: {"stream":"dentusdt@bookTicker","data":{"e":"bookTicker","u":335340886168,"s":"DENTUSDT","b":"0.012347","B":"69125","a":"0.012354","A":"8766","T":1618677457615,"E":1618677457618}}
1618677457.68664: {"stream":"dentusdt@kline_1m","data":{"e":"kline","E":1618677457627,"s":"DENTUSDT","k":{"t":1618677420000,"T":1618677479999,"s":"DENTUSDT","i":"1m","f":15787262,"L":15787405,"o":"0.012366","c":"0.012347","h":"0.012366","l":"0.012339","v":"2496367","n":144,"x":false,"q":"30835.449937","V":"1129541","Q":"13955.827123","B":"0"}}}
1618677457.686765: {"stream":"dentusdt@bookTicker","data":{"e":"bookTicker","u":335340886339,"s":"DENTUSDT","b":"0.012347","B":"61030","a":"0.012354","A":"8766","T":1618677457623,"E":1618677457627}}
1618677457.691061: {"stream":"ksmusdt@depth@100ms","data":{"e":"depthUpdate","E":1618677457632,"T":1618677457619,"s":"KSMUSDT","U":335340883848,"u":335340886242,"pu":335340882768,"b":[["454.157","0.4"],["455.992","0.4"],["458.243","0.0"],["458.244","0.0"],["458.427","0.0"]],"a":[["458.912","0.3"],["458.913","0.0"],["458.914","0.0"],["458.915","0.0"],["461.605","0.2"]]}}
1618677457.691705: {"stream":"dentusdt@depth@100ms","data":{"e":"depthUpdate","E":1618677457636,"T":1618677457623,"s":"DENTUSDT","U":335340883925,"u":335340886339,"pu":335340882850,"b":[["0.012315","124833"],["0.012331","11427"],["0.012334","85294"],["0.012347","61030"]],"a":[["0.012354","8766"],["0.012356","5626"],["0.012357","41113"],["0.012358","0"],["0.012359","53979"],["0.012363","299502"]]}}
1618677457.697718: {"stream":"yfiusdt@depth@100ms","data":{"e":"depthUpdate","E":1618677457641,"T":1618677457627,"s":"YFIUSDT","U":335340884060,"u":335340886510,"pu":335340883824,"b":[["49936.3","0.000"],["49952.5","0.000"],["49952.7","0.252"],["49980.1","0.000"]],"a":[]}}
1618677457.716264: {"stream":"dentusdt@bookTicker","data":{"e":"bookTicker","u":335340887151,"s":"DENTUSDT","b":"0.012347","B":"61030","a":"0.012354","A":"62723","T":1618677457653,"E":1618677457658}}
1618677457.743861: {"stream":"ksmusdt@bookTicker","data":{"e":"bookTicker","u":335340887926,"s":"KSMUSDT","b":"458.745","B":"0.4","a":"458.830","A":"6.4","T":1618677457682,"E":1618677457685}}
1618677457.75206: {"stream":"ksmusdt@bookTicker","data":{"e":"bookTicker","u":335340888293,"s":"KSMUSDT","b":"458.745","B":"0.4","a":"458.767","A":"0.1","T":1618677457691,"E":1618677457695}}
1618677457.777521: {"stream":"yfiusdt@bookTicker","data":{"e":"bookTicker","u":335340889278,"s":"YFIUSDT","b":"49977.3","B":"0.003","a":"49986.7","A":"0.001","T":1618677457718,"E":1618677457721}}
1618677457.7938712: {"stream":"dentusdt@bookTicker","data":{"e":"bookTicker","u":335340889746,"s":"DENTUSDT","b":"0.012347","B":"61030","a":"0.012354","A":"8766","T":1618677457731,"E":1618677457735}}
1618677457.7945652: {"stream":"ksmusdt@depth@100ms","data":{"e":"depthUpdate","E":1618677457737,"T":1618677457732,"s":"KSMUSDT","U":335340886668,"u":335340889776,"pu":335340886242,"b":[["453.239","0.4"],["456.268","1.4"],["457.486","0.0"],["457.638","2.0"],["457.928","1.1"],["458.111","2.1"],["458.142","0.0"],["458.653","0.4"],["458.654","0.3"]],"a":[["458.767","0.1"],["458.788","0.0"],["458.901","1.2"],["458.911","0.3"],["458.912","0.0"],["459.933","8.3"],["460.257","0.0"]]}}
1618677457.8012538: {"stream":"dentusdt@depth@100ms","data":{"e":"depthUpdate","E":1618677457744,"T":1618677457731,"s":"DENTUSDT","U":335340886782,"u":335340889757,"pu":335340886339,"b":[["0.011882","18420"],["0.012322","192658"],["0.012326","460860"],["0.012327","391441"],["0.012331","5619"]],"a":[["0.012354","8766"],["0.012355","0"],["0.012356","0"],["0.012357","60778"],["0.012358","23745"],["0.012359","41106"],["0.012363","299502"],["0.012382","434833"],["0.012617","12962"]]}}
1618677457.8164952: {"stream":"yfiusdt@depth@100ms","data":{"e":"depthUpdate","E":1618677457758,"T":1618677457752,"s":"YFIUSDT","U":335340887154,"u":335340890387,"pu":335340886510,"b":[["48332.4","0.000"],["49721.9","0.013"],["49792.4","0.000"],["49952.6","0.000"],["49952.8","0.168"],["49981.4","0.000"]],"a":[["50019.2","0.000"],["50019.3","0.000"],["50058.3","0.011"],["50073.9","0.000"],["50086.1","0.094"]]}}
1618677457.8357701: {"stream":"dentusdt@aggTrade","data":{"e":"aggTrade","E":1618677457778,"a":8476415,"s":"DENTUSDT","p":"0.012347","q":"8095","f":15787405,"l":15787405,"T":1618677457623,"m":true}}
1618677457.90014: {"stream":"ksmusdt@depth@100ms","data":{"e":"depthUpdate","E":1618677457841,"T":1618677457801,"s":"KSMUSDT","U":335340889962,"u":335340891744,"pu":335340889776,"b":[["458.425","5.8"]],"a":[["458.900","0.3"],["458.901","0.0"],["458.911","0.0"],["463.513","0.2"],["464.468","0.2"]]}}
1618677457.9035342: {"stream":"xmrusdt@depth@100ms","data":{"e":"depthUpdate","E":1618677457846,"T":1618677457813,"s":"XMRUSDT","U":335340890076,"u":335340892019,"pu":335340882694,"b":[["351.99","0.000"],["352.00","24.999"]],"a":[["353.37","70.051"]]}}
1618677457.916725: {"stream":"yfiusdt@depth@100ms","data":{"e":"depthUpdate","E":1618677457860,"T":1618677457854,"s":"YFIUSDT","U":335340890573,"u":335340893066,"pu":335340890387,"b":[["48381.8","0.001"],["49868.9","0.014"],["49898.9","0.010"]],"a":[]}}
1618677457.928792: {"stream":"dentusdt@depth@100ms","data":{"e":"depthUpdate","E":1618677457871,"T":1618677457863,"s":"DENTUSDT","U":335340890938,"u":335340893283,"pu":335340889757,"b":[["0.011987","950789"]],"a":[["0.012356","53957"],["0.012357","114757"]]}}
1618677457.9682581: {"stream":"dentusdt@bookTicker","data":{"e":"bookTicker","u":335340894309,"s":"DENTUSDT","b":"0.012347","B":"62096","a":"0.012354","A":"8766","T":1618677457907,"E":1618677457911}}
1618677458.011008: {"stream":"ksmusdt@depth@100ms","data":{"e":"depthUpdate","E":1618677457954,"T":1618677457935,"s":"KSMUSDT","U":335340892879,"u":335340895145,"pu":335340891744,"b":[["458.430","1.3"]],"a":[["458.967","0.0"],["459.772","0.0"],["459.870","1.0"],["459.881","0.0"]]}}
1618677458.031174: {"stream":"xmrusdt@depth@100ms","data":{"e":"depthUpdate","E":1618677457973,"T":1618677457876,"s":"XMRUSDT","U":335340893408,"u":335340893606,"pu":335340892019,"b":[["349.73","0.724"],["350.47","2.333"],["350.56","0.000"]],"a":[]}}
1618677458.031731: {"stream":"yfiusdt@depth@100ms","data":{"e":"depthUpdate","E":1618677457975,"T":1618677457935,"s":"YFIUSDT","U":335340893507,"u":335340895136,"pu":335340893066,"b":[["49779.1","0.017"],["49792.2","0.000"],["49965.4","0.012"]],"a":[["50086.1","0.000"],["50118.9","0.017"],["50133.1","0.200"]]}}
1618677458.031826: {"stream":"dentusdt@kline_1m","data":{"e":"kline","E":1618677457975,"s":"DENTUSDT","k":{"t":1618677420000,"T":1618677479999,"s":"DENTUSDT","i":"1m","f":15787262,"L":15787406,"o":"0.012366","c":"0.012347","h":"0.012366","l":"0.012339","v":"2497866","n":145,"x":false,"q":"30853.958090","V":"1129541","Q":"13955.827123","B":"0"}}}
1618677458.034411: {"stream":"dentusdt@bookTicker","data":{"e":"bookTicker","u":335340896182,"s":"DENTUSDT","b":"0.012347","B":"60597","a":"0.012354","A":"8766","T":1618677457972,"E":1618677457976}}
1618677458.044992: {"stream":"dentusdt@depth@100ms","data":{"e":"depthUpdate","E":1618677457987,"T":1618677457972,"s":"DENTUSDT","U":335340893770,"u":335340896182,"pu":335340893283,"b":[["0.010301","345384"],["0.010571","316651"],["0.010847","115128"],["0.010994","38376"],["0.011121","38831"],["0.011222","19188"],["0.011290","24110"],["0.011347","43663"],["0.011393","1079313"],["0.011655","7069"],["0.011835","12702"],["0.011980","202783"],["0.012102","2132"],["0.012199","706785"],["0.012261","152735"],["0.012310","90210"],["0.012339","104800"],["0.012347","60597"]],"a":[["0.012356","117504"],["0.012358","0"],["0.012359","0"],["0.012391","85222"]]}}
1618677458.047412: {"stream":"ksmusdt@bookTicker","data":{"e":"bookTicker","u":335340896608,"s":"KSMUSDT","b":"458.745","B":"0.2","a":"458.767","A":"0.1","T":1618677457986,"E":1618677457989}}
1618677458.050434: {"stream":"ksmusdt@bookTicker","data":{"e":"bookTicker","u":335340896660,"s":"KSMUSDT","b":"458.746","B":"0.2","a":"458.767","A":"0.1","T":1618677457988,"E":1618677457993}}
1618677458.232878: {"stream":"dentusdt@bookTicker","data":{"e":"bookTicker","u":335340899780,"s":"DENTUSDT","b":"0.012347","B":"60597","a":"0.012354","A":"62723","T":1618677458058,"E":1618677458062}}
1618677458.232981: {"stream":"ksmusdt@depth@100ms","data":{"e":"depthUpdate","E":1618677458064,"T":1618677458058,"s":"KSMUSDT","U":335340895789,"u":335340899779,"pu":335340895145,"b":[["457.438","0.0"],["457.504","1.1"],["457.928","0.0"],["457.989","0.0"],["458.191","0.5"],["458.243","11.5"],["458.244","2.6"],["458.252","0.0"],["458.431","1.1"],["458.693","1.0"],["458.745","0.2"],["458.746","0.2"]],"a":[["458.786","1.5"],["459.243","0.1"],["459.272","0.0"],["459.400","0.1"],["459.430","0.0"],["459.516","0.0"],["459.605","0.4"],["459.712","0.0"],["459.870","0.0"],["460.294","1.1"],["460.838","0.0"]]}}
1618677458.233344: {"stream":"yfiusdt@bookTicker","data":{"e":"bookTicker","u":335340899984,"s":"YFIUSDT","b":"49977.4","B":"0.008","a":"49986.7","A":"0.001","T":1618677458061,"E":1618677458064}}
1618677458.235641: {"stream":"yfiusdt@bookTicker","data":{"e":"bookTicker","u":335340900361,"s":"YFIUSDT","b":"49978.7","B":"0.006","a":"49986.7","A":"0.001","T":1618677458071,"E":1618677458073}}
1618677458.2372491: {"stream":"dentusdt@depth@100ms","data":{"e":"depthUpdate","E":1618677458094,"T":1618677458058,"s":"DENTUSDT","U":335340896751,"u":335340899786,"pu":335340896182,"b":[["0.012320","1891"]],"a":[["0.012354","62723"],["0.012355","6803"],["0.012356","63547"],["0.012357","0"],["0.012359","53979"],["0.012363","249715"]]}}
1618677458.239747: {"stream":"yfiusdt@depth@100ms","data":{"e":"depthUpdate","E":1618677458118,"T":1618677458109,"s":"YFIUSDT","U":335340897583,"u":335340900987,"pu":335340895136,"b":[["45365.0","0.000"],["49296.4","0.000"],["49535.2","0.000"],["49760.1","0.000"],["49908.5","0.000"],["49916.9","0.060"],["49942.4","0.000"],["49943.6","0.075"],["49950.1","0.257"],["49952.7","0.000"],["49952.9","0.092"],["49965.5","0.005"],["49977.3","0.000"],["49977.4","0.008"],["49977.5","0.003"],["49978.7","0.006"]],"a":[["50002.5","0.012"],["50078.1","0.060"],["50079.2","0.000"],["50207.8","0.000"],["50210.2","0.083"],["50236.5","0.008"],["50432.7","0.000"],["50435.1","0.083"]]}}
1618677458.2401888: {"stream":"dentusdt@aggTrade","data":{"e":"aggTrade","E":1618677458126,"a":8476416,"s":"DENTUSDT","p":"0.012347","q":"1499","f":15787406,"l":15787406,"T":1618677457972,"m":true}}
1618677458.2402282: {"stream":"yfiusdt@bookTicker","data":{"e":"bookTicker","u":335340901186,"s":"YFIUSDT","b":"49978.8","B":"0.009","a":"49986.7","A":"0.001","T":1618677458133,"E":1618677458137}}
1618677458.240722: {"stream":"ksmusdt@depth@100ms","data":{"e":"depthUpdate","E":1618677458164,"T":1618677458139,"s":"KSMUSDT","U":335340899964,"u":335340901521,"pu":335340899779,"b":[["458.431","0.0"],["458.694","0.4"]],"a":[["459.881","1.0"],["462.437","0.2"],["464.431","0.2"]]}}
1618677458.2408378: {"stream":"yfiusdt@bookTicker","data":{"e":"bookTicker","u":335340902193,"s":"YFIUSDT","b":"49980.1","B":"0.006","a":"49986.7","A":"0.001","T":1618677458168,"E":1618677458172}}
1618677458.240871: {"stream":"xmrusdt@depth@100ms","data":{"e":"depthUpdate","E":1618677458173,"T":1618677458167,"s":"XMRUSDT","U":335340900315,"u":335340902160,"pu":335340893606,"b":[],"a":[["352.48","0.000"],["352.68","30.368"],["352.82","2.500"],["360.89","0.000"]]}}
1618677458.261455: {"stream":"ksmusdt@bookTicker","data":{"e":"bookTicker","u":335340903241,"s":"KSMUSDT","b":"458.746","B":"0.2","a":"458.786","A":"1.5","T":1618677458198,"E":1618677458203}}
1618677458.266894: {"stream":"ksmusdt@bookTicker","data":{"e":"bookTicker","u":335340903554,"s":"KSMUSDT","b":"458.746","B":"0.2","a":"458.757","A":"0.1","T":1618677458205,"E":1618677458209}}
1618677458.274134: {"stream":"dentusdt@depth@100ms","data":{"e":"depthUpdate","E":1618677458217,"T":1618677458196,"s":"DENTUSDT","U":335340901043,"u":335340903125,"pu":335340899786,"b":[],"a":[["0.012356","36294"],["0.012359","135204"],["0.012363","299502"],["0.012379","87391"]]}}
1618677458.295546: {"stream":"yfiusdt@depth@100ms","data":{"e":"depthUpdate","E":1618677458237,"T":1618677458224,"s":"YFIUSDT","U":335340901186,"u":335340904443,"pu":335340900987,"b":[["45710.7","0.015"],["49535.5","0.083"],["49760.4","0.083"],["49942.5","0.000"],["49942.7","0.130"],["49949.3","0.000"],["49950.2","0.055"],["49952.8","0.000"],["49952.9","0.000"],["49953.0","0.168"],["49953.1","0.038"],["49977.4","0.000"],["49978.7","0.000"],["49978.8","0.000"],["49980.1","0.006"]],"a":[["50002.5","0.000"],["50066.9","0.005"],["50079.8","0.000"],["50082.2","0.000"],["50090.0","0.027"],["50245.7","0.000"]]}}
1618677458.327567: {"stream":"ksmusdt@depth@100ms","data":{"e":"depthUpdate","E":1618677458269,"T":1618677458261,"s":"KSMUSDT","U":335340901936,"u":335340905943,"pu":335340901521,"b":[["453.991","0.1"],["455.992","0.6"],["457.928","0.0"],["457.945","6.1"],["457.991","0.1"],["458.237","5.0"],["458.385","5.9"],["458.654","0.0"],["458.695","0.3"],["458.700","0.7"]],"a":[["458.757","0.1"],["458.767","0.0"],["458.786","0.0"],["458.900","0.0"],["458.960","0.3"],["459.433","0.1"],["459.881","0.0"],["460.106","0.0"],["460.602","0.2"],["461.563","0.0"],["468.260","5.3"]]}}
1618677458.3441489: {"stream":"dentusdt@bookTicker","data":{"e":"bookTicker","u":335340906678,"s":"DENTUSDT","b":"0.012347","B":"60597","a":"0.012354","A":"8766","T":1618677458280,"E":1618677458285}}
1618677458.361826: {"stream":"xmrusdt@depth@100ms","data":{"e":"depthUpdate","E":1618677458303,"T":1618677458248,"s":"XMRUSDT","U":335340903264,"u":335340905428,"pu":335340902160,"b":[["345.42","2.541"]],"a":[["352.50","1.400"],["352.68","32.868"],["352.82","0.000"]]}}
1618677458.4018219: {"stream":"dentusdt@depth@100ms","data":{"e":"depthUpdate","E":1618677458342,"T":1618677458323,"s":"DENTUSDT","U":335340904952,"u":335340908128,"pu":335340903125,"b":[["0.012277","56756"]],"a":[["0.012354","8766"],["0.012355","0"],["0.012356","0"],["0.012357","107936"],["0.012358","35823"],["0.012359","27246"],["0.012363","249715"],["0.012417","131547"]]}}
1618677458.4589639: {"stream":"dentusdt@kline_1m","data":{"e":"kline","E":1618677458400,"s":"DENTUSDT","k":{"t":1618677420000,"T":1618677479999,"s":"DENTUSDT","i":"1m","f":15787262,"L":15787407,"o":"0.012366","c":"0.012354","h":"0.012366","l":"0.012339","v":"2503534","n":146,"x":false,"q":"30923.980562","V":"1135209","Q":"14025.849595","B":"0"}}}
1618677458.4590871: {"stream":"dentusdt@bookTicker","data":{"e":"bookTicker","u":335340909973,"s":"DENTUSDT","b":"0.012347","B":"60597","a":"0.012354","A":"3098","T":1618677458396,"E":1618677458400}}
1618677458.459137: {"stream":"ksmusdt@depth@100ms","data":{"e":"depthUpdate","E":1618677458400,"T":1618677458392,"s":"KSMUSDT","U":335340907309,"u":335340909920,"pu":335340905943,"b":[["456.139","0.8"],["458.431","1.1"]],"a":[["458.937","1.2"],["458.941","0.3"],["458.942","0.0"],["458.960","0.0"],["459.303","0.0"],["459.864","0.4"],["459.881","1.0"]]}}
1618677458.488329: {"stream":"yfiusdt@depth@100ms","data":{"e":"depthUpdate","E":1618677458432,"T":1618677458421,"s":"YFIUSDT","U":335340908210,"u":335340910488,"pu":335340904443,"b":[],"a":[["50201.7","0.001"],["50244.5","0.007"],["50339.3","0.031"]]}}
1618677458.50438: {"stream":"xmrusdt@depth@100ms","data":{"e":"depthUpdate","E":1618677458448,"T":1618677458345,"s":"XMRUSDT","U":335340908659,"u":335340908666,"pu":335340905428,"b":[["352.00","9.400"],["352.01","17.563"]],"a":[]}}
1618677458.5278609: {"stream":"dentusdt@depth@100ms","data":{"e":"depthUpdate","E":1618677458470,"T":1618677458460,"s":"DENTUSDT","U":335340909301,"u":335340911449,"pu":335340908128,"b":[["0.012220","169992"],["0.012334","455"],["0.012339","336394"],["0.012340","48581"]],"a":[["0.012354","3098"],["0.012355","53957"],["0.012356","71379"],["0.012357","0"],["0.012358","72405"],["0.012363","299502"],["0.012370","0"]]}}
1618677458.58787: {"stream":"ksmusdt@depth@100ms","data":{"e":"depthUpdate","E":1618677458529,"T":1618677458520,"s":"KSMUSDT","U":335340910637,"u":335340912937,"pu":335340909920,"b":[["458.695","0.0"],["458.701","0.3"]],"a":[["458.830","0.0"],["458.935","1.2"],["458.936","0.3"],["458.937","0.0"],["458.941","0.0"],["459.881","0.0"],["460.592","0.2"],["461.564","0.0"]]}}
1618677458.5989141: {"stream":"ksmusdt@kline_1m","data":{"e":"kline","E":1618677458538,"s":"KSMUSDT","k":{"t":1618677420000,"T":1618677479999,"s":"KSMUSDT","i":"1m","f":25426460,"L":25426575,"o":"459.607","c":"458.757","h":"459.671","l":"458.391","v":"106.3","n":116,"x":false,"q":"48796.1566","V":"51.5","Q":"23650.8700","B":"0"}}}
1618677458.599041: {"stream":"ksmusdt@bookTicker","data":{"e":"bookTicker","u":335340913444,"s":"KSMUSDT","b":"458.746","B":"0.2","a":"458.935","A":"1.2","T":1618677458535,"E":1618677458539}}
1618677458.609819: {"stream":"dentusdt@aggTrade","data":{"e":"aggTrade","E":1618677458550,"a":8476417,"s":"DENTUSDT","p":"0.012354","q":"5668","f":15787407,"l":15787407,"T":1618677458396,"m":false}}
1618677458.609926: {"stream":"ksmusdt@bookTicker","data":{"e":"bookTicker","u":335340913708,"s":"KSMUSDT","b":"458.747","B":"6.5","a":"458.935","A":"1.2","T":1618677458547,"E":1618677458550}}
1618677458.609974: {"stream":"ksmusdt@bookTicker","data":{"e":"bookTicker","u":335340913721,"s":"KSMUSDT","b":"458.747","B":"6.5","a":"458.936","A":"0.3","T":1618677458547,"E":1618677458551}}
1618677458.623936: {"stream":"ksmusdt@bookTicker","data":{"e":"bookTicker","u":335340914108,"s":"KSMUSDT","b":"458.747","B":"6.5","a":"458.961","A":"6.4","T":1618677458561,"E":1618677458564}}
1618677458.624038: {"stream":"ksmusdt@bookTicker","data":{"e":"bookTicker","u":335340914120,"s":"KSMUSDT","b":"458.748","B":"0.3","a":"458.961","A":"6.4","T":1618677458561,"E":1618677458566}}
1618677458.634101: {"stream":"yfiusdt@bookTicker","data":{"e":"bookTicker","u":335340914493,"s":"YFIUSDT","b":"49980.2","B":"0.003","a":"49986.7","A":"0.001","T":1618677458572,"E":1618677458576}}
1618677458.6418371: {"stream":"dentusdt@depth@100ms","data":{"e":"depthUpdate","E":1618677458584,"T":1618677458557,"s":"DENTUSDT","U":335340911954,"u":335340914006,"pu":335340911449,"b":[["0.012326","439145"]],"a":[["0.012355","59358"],["0.012356","24205"],["0.012357","80685"],["0.012358","67005"],["0.012359","0"],["0.012363","299502"],["0.012391","110318"],["0.012397","160517"]]}}
1618677458.656804: {"stream":"xmrusdt@depth@100ms","data":{"e":"depthUpdate","E":1618677458599,"T":1618677458563,"s":"XMRUSDT","U":335340912322,"u":335340914224,"pu":335340908666,"b":[["350.42","1.217"]],"a":[["361.92","132.566"]]}}
1618677458.6897411: {"stream":"ksmusdt@depth@100ms","data":{"e":"depthUpdate","E":1618677458630,"T":1618677458606,"s":"KSMUSDT","U":335340913152,"u":335340915641,"pu":335340912937,"b":[["458.066","9.4"],["458.243","0.0"],["458.245","1.1"],["458.340","12.0"],["458.425","0.0"],["458.426","0.0"],["458.429","0.0"],["458.430","0.0"],["458.431","0.0"],["458.694","0.0"],["458.701","0.0"],["458.747","6.5"],["458.748","0.3"]],"a":[["458.757","0.0"],["458.935","0.0"],["458.936","0.0"],["458.970","0.0"],["459.212","1.2"],["459.246","0.3"],["459.748","0.0"],["459.881","1.0"],["459.884","0.0"],["459.978","2.3"],["460.239","5.6"]]}}
1618677458.69677: {"stream":"ksmusdt@bookTicker","data":{"e":"bookTicker","u":335340916351,"s":"KSMUSDT","b":"458.748","B":"0.3","a":"458.855","A":"1.1","T":1618677458632,"E":1618677458634}}
1618677458.696874: {"stream":"yfiusdt@depth@100ms","data":{"e":"depthUpdate","E":1618677458635,"T":1618677458617,"s":"YFIUSDT","U":335340913349,"u":335340915906,"pu":335340910488,"b":[["48526.5","0.000"],["49917.0","0.000"],["49921.2","0.000"],["49929.6","0.110"],["49933.8","0.110"],["49943.8","0.087"],["49950.1","0.000"],["49950.2","0.000"],["49950.3","0.257"],["49977.5","0.000"],["49980.2","0.003"]],"a":[["49992.2","0.000"],["50002.8","0.000"],["50006.0","0.000"],["50009.0","0.012"],["50029.9","0.084"],["50036.6","0.000"],["50039.6","0.000"],["50040.6","0.002"],["50048.1","0.002"],["50050.0","0.002"],["50053.9","0.002"],["50077.8","0.000"],["50235.8","0.009"]]}}
1618677458.7247: {"stream":"xmrusdt@kline_1m","data":{"e":"kline","E":1618677458668,"s":"XMRUSDT","k":{"t":1618677420000,"T":1618677479999,"s":"XMRUSDT","i":"1m","f":34692938,"L":34692973,"o":"352.86","c":"352.41","h":"352.93","l":"352.40","v":"32.958","n":36,"x":false,"q":"11621.91980","V":"2.996","Q":"1056.54231","B":"0"}}}
1618677458.959507: {"stream":"xmrusdt@bookTicker","data":{"e":"bookTicker","u":335340917312,"s":"XMRUSDT","b":"352.40","B":"4.152","a":"352.49","A":"1.000","T":1618677458663,"E":1618677458669}}
1618677458.959578: {"stream":"ksmusdt@aggTrade","data":{"e":"aggTrade","E":1618677458689,"a":21396982,"s":"KSMUSDT","p":"458.757","q":"0.1","f":25426575,"l":25426575,"T":1618677458535,"m":false}}
1618677458.9596102: {"stream":"dentusdt@depth@100ms","data":{"e":"depthUpdate","E":1618677458700,"T":1618677458657,"s":"DENTUSDT","U":335340915346,"u":335340917074,"pu":335340914006,"b":[["0.011882","26919"],["0.012289","952517"],["0.012330","261339"],["0.012333","10535"],["0.012335","28201"]],"a":[["0.012356","36819"],["0.012358","53979"],["0.012378","323874"],["0.012379","50901"],["0.012380","41192"],["0.012391","44842"],["0.012617","21461"]]}}
1618677458.9597309: {"stream":"xmrusdt@bookTicker","data":{"e":"bookTicker","u":335340918417,"s":"XMRUSDT","b":"352.40","B":"4.716","a":"352.49","A":"1.000","T":1618677458707,"E":1618677458713}}
1618677458.959757: {"stream":"ksmusdt@depth@100ms","data":{"e":"depthUpdate","E":1618677458734,"T":1618677458725,"s":"KSMUSDT","U":335340916351,"u":335340918895,"pu":335340915641,"b":[["454.203","0.0"],["457.946","1.1"],["458.021","13.6"],["458.245","0.0"],["458.747","0.0"]],"a":[["458.855","1.1"],["459.211","1.6"],["459.212","0.0"],["459.246","0.0"],["459.247","0.0"],["459.316","0.0"],["459.498","0.8"],["459.504","0.0"],["460.105","6.1"]]}}
1618677458.959904: {"stream":"yfiusdt@depth@100ms","data":{"e":"depthUpdate","E":1618677458746,"T":1618677458724,"s":"YFIUSDT","U":335340916663,"u":335340918848,"pu":335340915906,"b":[["48355.2","0.050"]],"a":[["50028.9","0.003"],["50029.0","0.000"],["50040.6","0.000"],["50048.1","0.000"],["50052.7","0.003"],["50053.9","0.000"],["50060.2","0.003"],["50066.0","0.003"],["50141.1","0.000"],["50178.7","0.036"]]}}
1618677458.960038: {"stream":"xmrusdt@depth@100ms","data":{"e":"depthUpdate","E":1618677458767,"T":1618677458750,"s":"XMRUSDT","U":335340917272,"u":335340919587,"pu":335340914224,"b":[["351.47","37.221"],["351.56","0.000"],["351.72","0.335"],["351.92","15.224"],["351.96","3.745"],["351.97","0.000"],["352.01","3.164"],["352.26","0.000"],["352.27","0.000"],["352.29","0.023"],["352.30","7.972"],["352.40","4.716"]],"a":[["352.41","0.000"],["352.50","0.000"],["352.52","2.204"],["352.68","30.368"],["352.82","2.500"],["352.93","0.000"],["353.34","25.152"],["353.35","0.000"],["353.68","36.945"],["353.72","1.900"],["362.26","66.230"]]}}
1618677458.9601972: {"stream":"xmrusdt@bookTicker","data":{"e":"bookTicker","u":335340920459,"s":"XMRUSDT","b":"352.40","B":"4.152","a":"352.49","A":"1.000","T":1618677458782,"E":1618677458787}}
1618677458.960237: {"stream":"xmrusdt@aggTrade","data":{"e":"aggTrade","E":1618677458819,"a":23619027,"s":"XMRUSDT","p":"352.41","q":"1.358","f":34692973,"l":34692973,"T":1618677458663,"m":false}}
1618677458.9602618: {"stream":"dentusdt@depth@100ms","data":{"e":"depthUpdate","E":1618677458830,"T":1618677458816,"s":"DENTUSDT","U":335340918933,"u":335340921343,"pu":335340917074,"b":[["0.011939","29695"],["0.012178","154373"],["0.012249","150606"]],"a":[["0.012356","30014"],["0.012380","41192"],["0.012384","40701"]]}}
1618677458.960314: {"stream":"dentusdt@kline_1m","data":{"e":"kline","E":1618677458832,"s":"DENTUSDT","k":{"t":1618677420000,"T":1618677479999,"s":"DENTUSDT","i":"1m","f":15787262,"L":15787408,"o":"0.012366","c":"0.012354","h":"0.012366","l":"0.012339","v":"2506632","n":147,"x":false,"q":"30962.253254","V":"1138307","Q":"14064.122287","B":"0"}}}
1618677458.96035: {"stream":"dentusdt@aggTrade","data":{"e":"aggTrade","E":1618677458832,"a":8476418,"s":"DENTUSDT","p":"0.012354","q":"3098","f":15787408,"l":15787408,"T":1618677458827,"m":false}}
1618677458.960372: {"stream":"dentusdt@bookTicker","data":{"e":"bookTicker","u":335340921612,"s":"DENTUSDT","b":"0.012347","B":"60597","a":"0.012355","A":"59323","T":1618677458827,"E":1618677458832}}
1618677458.960392: {"stream":"dentusdt@bookTicker","data":{"e":"bookTicker","u":335340921906,"s":"DENTUSDT","b":"0.012347","B":"60597","a":"0.012354","A":"8766","T":1618677458839,"E":1618677458843}}
1618677458.96041: {"stream":"dentusdt@bookTicker","data":{"e":"bookTicker","u":335340921964,"s":"DENTUSDT","b":"0.012348","B":"8867","a":"0.012354","A":"8766","T":1618677458841,"E":1618677458846}}
1618677458.960427: {"stream":"ksmusdt@depth@100ms","data":{"e":"depthUpdate","E":1618677458846,"T":1618677458833,"s":"KSMUSDT","U":335340919352,"u":335340921765,"pu":335340918895,"b":[["456.207","1.6"],["457.946","0.0"],["458.425","1.1"]],"a":[["459.211","0.0"],["459.247","1.6"],["459.881","1.0"],["462.902","0.0"],["463.588","0.0"]]}}
1618677458.960513: {"stream":"ksmusdt@bookTicker","data":{"e":"bookTicker","u":335340922007,"s":"KSMUSDT","b":"458.748","B":"0.3","a":"458.854","A":"1.5","T":1618677458842,"E":1618677458847}}
1618677458.960534: {"stream":"ksmusdt@bookTicker","data":{"e":"bookTicker","u":335340922189,"s":"KSMUSDT","b":"458.748","B":"0.3","a":"458.831","A":"2.5","T":1618677458850,"E":1618677458853}}
1618677458.960552: {"stream":"xmrusdt@bookTicker","data":{"e":"bookTicker","u":335340922303,"s":"XMRUSDT","b":"352.40","B":"4.716","a":"352.49","A":"1.000","T":1618677458854,"E":1618677458857}}
1618677458.9605691: {"stream":"ksmusdt@bookTicker","data":{"e":"bookTicker","u":335340922298,"s":"KSMUSDT","b":"458.748","B":"0.3","a":"458.854","A":"1.5","T":1618677458854,"E":1618677458857}}
1618677458.960587: {"stream":"yfiusdt@depth@100ms","data":{"e":"depthUpdate","E":1618677458858,"T":1618677458846,"s":"YFIUSDT","U":335340919718,"u":335340922109,"pu":335340918848,"b":[["48444.9","0.047"]],"a":[["50028.8","0.000"],["50028.9","0.000"],["50035.8","0.000"],["50039.6","0.000"],["50041.2","0.017"],["50052.0","0.017"],["50276.4","0.000"],["50282.0","0.010"]]}}
1618677458.9606678: {"stream":"dentusdt@bookTicker","data":{"e":"bookTicker","u":335340922417,"s":"DENTUSDT","b":"0.012348","B":"8867","a":"0.012355","A":"59323","T":1618677458859,"E":1618677458863}}
1618677458.9606888: {"stream":"ksmusdt@bookTicker","data":{"e":"bookTicker","u":335340922495,"s":"KSMUSDT","b":"458.748","B":"0.3","a":"458.855","A":"1.1","T":1618677458862,"E":1618677458866}}
1618677458.9607072: {"stream":"xmrusdt@depth@100ms","data":{"e":"depthUpdate","E":1618677458872,"T":1618677458854,"s":"XMRUSDT","U":335340920171,"u":335340922303,"pu":335340919587,"b":[["351.70","7.784"],["352.05","5.989"],["352.18","0.000"],["352.20","0.000"],["352.30","6.572"],["352.31","20.406"],["352.40","4.716"]],"a":[["352.52","1.640"],["352.98","15.462"],["353.99","3.262"],["354.47","1.230"]]}}
1618677458.960783: {"stream":"dentusdt@bookTicker","data":{"e":"bookTicker","u":335340923292,"s":"DENTUSDT","b":"0.012348","B":"8867","a":"0.012355","A":"5401","T":1618677458893,"E":1618677458898}}
1618677458.978506: {"stream":"yfiusdt@bookTicker","data":{"e":"bookTicker","u":335340923611,"s":"YFIUSDT","b":"49980.3","B":"0.002","a":"49986.7","A":"0.001","T":1618677458905,"E":1618677458909}}
1618677458.989079: {"stream":"dentusdt@depth@100ms","data":{"e":"depthUpdate","E":1618677458932,"T":1618677458927,"s":"DENTUSDT","U":335340921608,"u":335340924197,"pu":335340921343,"b":[["0.012317","424971"],["0.012324","377597"],["0.012327","416615"],["0.012339","332202"],["0.012340","97162"],["0.012341","14066"],["0.012348","8867"]],"a":[["0.012354","0"],["0.012355","5401"],["0.012357","26706"],["0.012358","0"],["0.012359","53922"],["0.012360","151274"],["0.012362","0"],["0.012363","249715"],["0.012365","49787"],["0.012378","27290"],["0.012380","0"],["0.012381","62884"],["0.012384","108782"]]}}
1618677459.0136309: {"stream":"ksmusdt@depth@100ms","data":{"e":"depthUpdate","E":1618677458947,"T":1618677458909,"s":"KSMUSDT","U":335340922007,"u":335340923728,"pu":335340921765,"b":[["456.310","1.1"],["456.352","1.0"],["458.021","0.0"],["458.425","0.0"],["458.616","6.2"]],"a":[["458.831","0.0"],["458.854","0.0"],["458.960","0.0"],["459.881","0.0"],["462.160","1.1"]]}}
1618677459.0331142: {"stream":"dentusdt@bookTicker","data":{"e":"bookTicker","u":335340924877,"s":"DENTUSDT","b":"0.012348","B":"8867","a":"0.012356","A":"12614","T":1618677458955,"E":1618677458959}}
1618677459.033215: {"stream":"xmrusdt@kline_1m","data":{"e":"kline","E":1618677458961,"s":"XMRUSDT","k":{"t":1618677420000,"T":1618677479999,"s":"XMRUSDT","i":"1m","f":34692938,"L":34692974,"o":"352.86","c":"352.42","h":"352.93","l":"352.40","v":"34.117","n":37,"x":false,"q":"12030.37458","V":"2.996","Q":"1056.54231","B":"0"}}}
1618677459.0332859: {"stream":"xmrusdt@bookTicker","data":{"e":"bookTicker","u":335340924915,"s":"XMRUSDT","b":"352.42","B":"3.289","a":"352.49","A":"1.000","T":1618677458957,"E":1618677458961}}
1618677459.033325: {"stream":"xmrusdt@bookTicker","data":{"e":"bookTicker","u":335340924921,"s":"XMRUSDT","b":"352.42","B":"2.130","a":"352.49","A":"1.000","T":1618677458958,"E":1618677458961}}
1618677459.033355: {"stream":"dentusdt@bookTicker","data":{"e":"bookTicker","u":335340924956,"s":"DENTUSDT","b":"0.012348","B":"8867","a":"0.012358","A":"16914","T":1618677458959,"E":1618677458963}}
1618677459.0334132: {"stream":"xmrusdt@bookTicker","data":{"e":"bookTicker","u":335340925055,"s":"XMRUSDT","b":"352.40","B":"4.716","a":"352.49","A":"1.000","T":1618677458962,"E":1618677458965}}
1618677459.0651882: {"stream":"yfiusdt@depth@100ms","data":{"e":"depthUpdate","E":1618677458978,"T":1618677458934,"s":"YFIUSDT","U":335340922805,"u":335340924363,"pu":335340922109,"b":[["49980.3","0.002"]],"a":[["50039.4","0.000"],["50039.5","0.000"],["50224.3","0.008"]]}}
1618677459.06539: {"stream":"dentusdt@aggTrade","data":{"e":"aggTrade","E":1618677458983,"a":8476419,"s":"DENTUSDT","p":"0.012355","q":"35","f":15787409,"l":15787409,"T":1618677458827,"m":false}}
1618677459.0654469: {"stream":"xmrusdt@bookTicker","data":{"e":"bookTicker","u":335340926055,"s":"XMRUSDT","b":"352.40","B":"4.152","a":"352.49","A":"1.000","T":1618677458999,"E":1618677459003}}
1618677459.0654879: {"stream":"xmrusdt@bookTicker","data":{"e":"bookTicker","u":335340926062,"s":"XMRUSDT","b":"352.41","B":"0.564","a":"352.49","A":"1.000","T":1618677458999,"E":1618677459003}}
1618677459.080257: {"stream":"xmrusdt@depth@100ms","data":{"e":"depthUpdate","E":1618677459022,"T":1618677459016,"s":"XMRUSDT","U":335340923918,"u":335340926687,"pu":335340922303,"b":[["352.04","19.522"],["352.05","3.489"],["352.10","20.279"],["352.16","5.466"],["352.18","0.000"],["352.26","9.400"],["352.30","6.019"],["352.32","4.701"],["352.40","4.152"],["352.41","0.564"],["352.42","0.000"]],"a":[["352.52","0.240"],["352.59","1.092"],["352.67","8.879"],["352.82","0.000"],["352.93","7.132"],["353.26","10.381"],["353.31","0.000"],["353.47","1.500"],["355.09","0.563"]]}}
1618677459.090928: {"stream":"dentusdt@depth@100ms","data":{"e":"depthUpdate","E":1618677459033,"T":1618677459026,"s":"DENTUSDT","U":335340924250,"u":335340927011,"pu":335340924197,"b":[["0.000011","21805663"],["0.009245","0"],["0.012341","9878"]],"a":[["0.012355","0"],["0.012356","0"],["0.012357","0"],["0.012358","16914"],["0.012359","5250"],["0.012360","17393"],["0.012361","0"],["0.012362","38361"],["0.012364","174901"],["0.012365","0"],["0.012381","22403"],["0.012384","54807"],["0.012541","1225044"]]}}
1618677459.0973198: {"stream":"yfiusdt@bookTicker","data":{"e":"bookTicker","u":335340927430,"s":"YFIUSDT","b":"49980.4","B":"0.004","a":"49986.7","A":"0.001","T":1618677459034,"E":1618677459039}}
1618677459.106904: {"stream":"yfiusdt@bookTicker","data":{"e":"bookTicker","u":335340927773,"s":"YFIUSDT","b":"49981.7","B":"0.006","a":"49986.7","A":"0.001","T":1618677459044,"E":1618677459048}}
1618677459.107002: {"stream":"dentusdt@bookTicker","data":{"e":"bookTicker","u":335340927819,"s":"DENTUSDT","b":"0.012348","B":"13048","a":"0.012358","A":"16914","T":1618677459045,"E":1618677459048}}
1618677459.1074839: {"stream":"ksmusdt@depth@100ms","data":{"e":"depthUpdate","E":1618677459050,"T":1618677459041,"s":"KSMUSDT","U":335340924630,"u":335340927664,"pu":335340923728,"b":[["457.946","1.1"],["457.991","0.0"],["458.341","2.8"],["458.617","1.4"],["458.701","0.3"]],"a":[["459.242","1.4"],["459.400","0.0"],["459.433","0.0"],["459.881","1.0"],["463.299","15.0"],["463.331","15.0"]]}}
1618677459.23154: {"stream":"yfiusdt@bookTicker","data":{"e":"bookTicker","u":335340928304,"s":"YFIUSDT","b":"49981.8","B":"0.004","a":"49986.7","A":"0.001","T":1618677459055,"E":1618677459059}}
1618677459.231638: {"stream":"dentusdt@bookTicker","data":{"e":"bookTicker","u":335340928397,"s":"DENTUSDT","b":"0.012348","B":"13048","a":"0.012359","A":"5250","T":1618677459057,"E":1618677459063}}
1618677459.2335: {"stream":"yfiusdt@bookTicker","data":{"e":"bookTicker","u":335340928775,"s":"YFIUSDT","b":"49981.7","B":"0.006","a":"49986.7","A":"0.001","T":1618677459067,"E":1618677459070}}
1618677459.235918: {"stream":"yfiusdt@bookTicker","data":{"e":"bookTicker","u":335340928926,"s":"YFIUSDT","b":"49981.8","B":"0.004","a":"49986.7","A":"0.001","T":1618677459073,"E":1618677459077}}
1618677459.261791: {"stream":"dentusdt@bookTicker","data":{"e":"bookTicker","u":335340929318,"s":"DENTUSDT","b":"0.012348","B":"13048","a":"0.012360","A":"17393","T":1618677459092,"E":1618677459095}}
1618677459.2618911: {"stream":"yfiusdt@depth@100ms","data":{"e":"depthUpdate","E":1618677459096,"T":1618677459073,"s":"YFIUSDT","U":335340925870,"u":335340928926,"pu":335340924363,"b":[["48615.6","0.000"],["49950.3","0.000"],["49950.4","0.055"],["49952.5","0.254"],["49953.1","0.090"],["49980.1","0.000"],["49980.2","0.000"],["49980.4","0.004"],["49980.5","0.003"],["49981.7","0.006"],["49981.8","0.004"]],"a":[["50006.6","0.005"],["50008.9","0.004"],["50029.8","0.021"],["50116.2","0.094"]]}}
1618677459.2624562: {"stream":"xmrusdt@aggTrade","data":{"e":"aggTrade","E":1618677459112,"a":23619028,"s":"XMRUSDT","p":"352.42","q":"1.159","f":34692974,"l":34692974,"T":1618677458957,"m":true}}
1618677459.2669828: {"stream":"ksmusdt@bookTicker","data":{"e":"bookTicker","u":335340930327,"s":"KSMUSDT","b":"458.748","B":"0.3","a":"458.961","A":"6.4","T":1618677459136,"E":1618677459141}}
1618677459.2670841: {"stream":"xmrusdt@depth@100ms","data":{"e":"depthUpdate","E":1618677459142,"T":1618677459120,"s":"XMRUSDT","U":335340927538,"u":335340929855,"pu":335340926687,"b":[["352.16","2.966"],["352.18","2.500"],["352.25","0.000"]],"a":[["352.51","0.000"],["352.53","2.941"],["352.67","6.379"],["352.68","32.868"],["352.82","0.000"]]}}
1618677459.267712: {"stream":"ksmusdt@bookTicker","data":{"e":"bookTicker","u":335340930432,"s":"KSMUSDT","b":"458.748","B":"0.3","a":"458.802","A":"1.1","T":1618677459143,"E":1618677459147}}
1618677459.267772: {"stream":"dentusdt@depth@100ms","data":{"e":"depthUpdate","E":1618677459148,"T":1618677459130,"s":"DENTUSDT","U":335340927811,"u":335340930004,"pu":335340927011,"b":[["0.012348","13048"]],"a":[["0.012358","0"],["0.012359","0"],["0.012361","94398"],["0.012362","217998"],["0.012363","298286"],["0.012366","184734"]]}}
1618677459.268219: {"stream":"ksmusdt@depth@100ms","data":{"e":"depthUpdate","E":1618677459154,"T":1618677459145,"s":"KSMUSDT","U":335340928044,"u":335340930590,"pu":335340927664,"b":[["454.304","15.0"],["454.337","15.0"],["456.585","15.0"],["457.946","1.1"],["458.019","0.1"]],"a":[["458.802","1.1"],["458.855","0.0"],["459.241","1.6"],["459.243","0.0"],["459.247","0.0"],["459.260","0.1"],["459.418","0.1"],["459.422","0.1"],["461.050","15.0"],["461.083","3.0"],["463.331","0.0"]]}}
1618677459.277472: {"stream":"yfiusdt@bookTicker","data":{"e":"bookTicker","u":335340931797,"s":"YFIUSDT","b":"49981.7","B":"0.006","a":"49986.7","A":"0.001","T":1618677459191,"E":1618677459196}}
1618677459.2807438: {"stream":"yfiusdt@depth@100ms","data":{"e":"depthUpdate","E":1618677459213,"T":1618677459198,"s":"YFIUSDT","U":335340929560,"u":335340932002,"pu":335340928926,"b":[["48592.3","0.000"],["49950.4","0.000"],["49952.0","0.000"],["49952.9","0.009"],["49953.0","0.000"],["49953.2","0.168"],["49974.6","0.003"],["49980.4","0.000"],["49980.5","0.000"],["49981.7","0.006"],["49981.8","0.000"]],"a":[["50043.5","0.000"],["50049.1","0.009"]]}}
1618677459.280946: {"stream":"dentusdt@bookTicker","data":{"e":"bookTicker","u":335340932292,"s":"DENTUSDT","b":"0.012348","B":"13048","a":"0.012360","A":"71357","T":1618677459211,"E":1618677459215}}
1618677459.281239: {"stream":"ksmusdt@bookTicker","data":{"e":"bookTicker","u":335340932391,"s":"KSMUSDT","b":"458.749","B":"0.7","a":"458.802","A":"1.1","T":1618677459214,"E":1618677459217}}
1618677459.3063831: {"stream":"dentusdt@depth@100ms","data":{"e":"depthUpdate","E":1618677459249,"T":1618677459220,"s":"DENTUSDT","U":335340930521,"u":335340932629,"pu":335340930004,"b":[["0.009322","1071230"],["0.012299","78606"],["0.012309","0"],["0.012326","449680"],["0.012333","0"],["0.012335","24963"]],"a":[["0.012360","71357"],["0.012362","212601"],["0.012364","41020"],["0.012366","268828"],["0.012367","266815"],["0.012380","36490"],["0.012384","40701"],["0.012391","69940"],["0.012404","79696"],["0.012429","122799"],["0.012457","900"]]}}
1618677459.31509: {"stream":"xmrusdt@depth@100ms","data":{"e":"depthUpdate","E":1618677459258,"T":1618677459240,"s":"XMRUSDT","U":335340930852,"u":335340933237,"pu":335340929855,"b":[["352.11","3.069"],["352.18","2.500"]],"a":[["352.68","30.368"],["352.82","2.968"],["354.49","0.000"]]}}
1618677459.315296: {"stream":"ksmusdt@bookTicker","data":{"e":"bookTicker","u":335340933657,"s":"KSMUSDT","b":"458.748","B":"0.3","a":"458.802","A":"1.1","T":1618677459254,"E":1618677459258}}
1618677459.332066: {"stream":"ksmusdt@depth@100ms","data":{"e":"depthUpdate","E":1618677459274,"T":1618677459260,"s":"KSMUSDT","U":335340931219,"u":335340933872,"pu":335340930590,"b":[["454.337","0.0"],["456.553","15.0"],["456.585","0.0"],["457.946","1.1"],["458.340","0.0"],["458.341","0.0"],["458.342","13.7"],["458.343","3.2"],["458.726","0.0"],["458.745","0.2"],["458.749","0.0"]],"a":[["458.960","0.3"],["459.210","0.0"],["459.302","0.0"],["462.458","0.2"]]}}
1618677459.340405: {"stream":"dentusdt@bookTicker","data":{"e":"bookTicker","u":335340934451,"s":"DENTUSDT","b":"0.012348","B":"13048","a":"0.012360","A":"87932","T":1618677459279,"E":1618677459282}}
1618677459.344917: {"stream":"ksmusdt@kline_1m","data":{"e":"kline","E":1618677459288,"s":"KSMUSDT","k":{"t":1618677420000,"T":1618677479999,"s":"KSMUSDT","i":"1m","f":25426460,"L":25426576,"o":"459.607","c":"458.802","h":"459.671","l":"458.391","v":"107.4","n":117,"x":false,"q":"49300.8388","V":"52.6","Q":"24155.5522","B":"0"}}}
1618677459.345048: {"stream":"ksmusdt@bookTicker","data":{"e":"bookTicker","u":335340934635,"s":"KSMUSDT","b":"458.748","B":"0.3","a":"458.960","A":"0.3","T":1618677459285,"E":1618677459288}}
1618677459.348234: {"stream":"dentusdt@bookTicker","data":{"e":"bookTicker","u":335340934643,"s":"DENTUSDT","b":"0.012348","B":"13048","a":"0.012360","A":"93077","T":1618677459285,"E":1618677459289}}
1618677459.3581681: {"stream":"ksmusdt@bookTicker","data":{"e":"bookTicker","u":335340934898,"s":"KSMUSDT","b":"458.746","B":"0.2","a":"458.960","A":"0.3","T":1618677459294,"E":1618677459299}}
1618677459.358269: {"stream":"ksmusdt@bookTicker","data":{"e":"bookTicker","u":335340934950,"s":"KSMUSDT","b":"458.749","B":"6.5","a":"458.960","A":"0.3","T":1618677459296,"E":1618677459301}}
1618677459.3642502: {"stream":"ksmusdt@bookTicker","data":{"e":"bookTicker","u":335340935136,"s":"KSMUSDT","b":"458.770","B":"6.4","a":"458.960","A":"0.3","T":1618677459302,"E":1618677459306}}
1618677459.369607: {"stream":"yfiusdt@bookTicker","data":{"e":"bookTicker","u":335340935238,"s":"YFIUSDT","b":"49981.7","B":"0.006","a":"50006.6","A":"0.005","T":1618677459306,"E":1618677459310}}
1618677459.369707: {"stream":"yfiusdt@kline_1m","data":{"e":"kline","E":1618677459311,"s":"YFIUSDT","k":{"t":1618677420000,"T":1618677479999,"s":"YFIUSDT","i":"1m","f":64902095,"L":64902174,"o":"50010.8","c":"49986.7","h":"50044.2","l":"49950.6","v":"0.974","n":80,"x":false,"q":"48698.9461","V":"0.669","Q":"33449.5277","B":"0"}}}
1618677459.374569: {"stream":"dentusdt@bookTicker","data":{"e":"bookTicker","u":335340935375,"s":"DENTUSDT","b":"0.012348","B":"13048","a":"0.012360","A":"105240","T":1618677459311,"E":1618677459316}}
1618677459.377016: {"stream":"dentusdt@bookTicker","data":{"e":"bookTicker","u":335340935470,"s":"DENTUSDT","b":"0.012348","B":"13048","a":"0.012359","A":"6810","T":1618677459315,"E":1618677459318}}
1618677459.3833501: {"stream":"yfiusdt@bookTicker","data":{"e":"bookTicker","u":335340935683,"s":"YFIUSDT","b":"49981.7","B":"0.006","a":"50006.1","A":"0.055","T":1618677459320,"E":1618677459325}}
1618677459.387609: {"stream":"ksmusdt@bookTicker","data":{"e":"bookTicker","u":335340935913,"s":"KSMUSDT","b":"458.770","B":"6.4","a":"458.975","A":"0.1","T":1618677459327,"E":1618677459330}}
1618677459.3918579: {"stream":"ksmusdt@bookTicker","data":{"e":"bookTicker","u":335340935922,"s":"KSMUSDT","b":"458.771","B":"0.3","a":"458.975","A":"0.1","T":1618677459327,"E":1618677459332}}
1618677459.402123: {"stream":"ksmusdt@bookTicker","data":{"e":"bookTicker","u":335340936350,"s":"KSMUSDT","b":"458.786","B":"1.2","a":"458.975","A":"0.1","T":1618677459340,"E":1618677459343}}
1618677459.409454: {"stream":"yfiusdt@bookTicker","data":{"e":"bookTicker","u":335340936527,"s":"YFIUSDT","b":"49981.8","B":"0.003","a":"50006.1","A":"0.055","T":1618677459345,"E":1618677459350}}
1618677459.415814: {"stream":"dentusdt@bookTicker","data":{"e":"bookTicker","u":335340936700,"s":"DENTUSDT","b":"0.012348","B":"13048","a":"0.012359","A":"60776","T":1618677459352,"E":1618677459357}}
1618677459.4179761: {"stream":"yfiusdt@bookTicker","data":{"e":"bookTicker","u":335340936763,"s":"YFIUSDT","b":"49981.8","B":"0.003","a":"50006.0","A":"0.149","T":1618677459354,"E":1618677459359}}
1618677459.421237: {"stream":"yfiusdt@depth@100ms","data":{"e":"depthUpdate","E":1618677459364,"T":1618677459354,"s":"YFIUSDT","U":335340933841,"u":335340936763,"pu":335340932002,"b":[["49925.4","0.127"],["49929.6","0.110"],["49936.5","0.000"],["49938.0","0.000"],["49942.2","0.000"],["49955.7","0.000"],["49965.3","0.000"],["49965.4","0.000"],["49965.5","0.000"],["49965.9","0.239"],["49973.7","0.016"],["49974.5","0.017"],["49974.6","0.000"],["49974.7","0.010"],["49981.8","0.003"]],"a":[["49986.7","0.000"],["50006.0","0.149"],["50006.1","0.055"],["50006.6","0.000"],["50008.0","0.013"],["50009.0","0.000"],["50029.9","0.030"],["50030.0","0.000"],["50046.8","0.015"],["50052.7","0.000"],["50054.3","0.015"],["50060.1","0.015"],["50060.2","0.000"],["50066.0","0.000"],["50067.2","0.232"]]}}
1618677459.428638: {"stream":"ksmusdt@bookTicker","data":{"e":"bookTicker","u":335340937109,"s":"KSMUSDT","b":"458.787","B":"0.3","a":"458.975","A":"0.1","T":1618677459365,"E":1618677459370}}
1618677459.430613: {"stream":"xmrusdt@depth@100ms","data":{"e":"depthUpdate","E":1618677459373,"T":1618677459343,"s":"XMRUSDT","U":335340934131,"u":335340936439,"pu":335340933237,"b":[["339.85","0.000"],["350.17","1.841"],["352.06","2.500"],["352.18","0.000"]],"a":[]}}
1618677459.440428: {"stream":"dentusdt@depth@100ms","data":{"e":"depthUpdate","E":1618677459382,"T":1618677459373,"s":"DENTUSDT","U":335340934446,"u":335340937292,"pu":335340932629,"b":[["0.011664","38572"],["0.011911","0"],["0.012034","0"],["0.012229","92650"],["0.012323","47693"],["0.012330","176504"]],"a":[["0.012359","60776"],["0.012360","51276"],["0.012361","0"],["0.012362","171667"],["0.012366","318615"],["0.012367","217028"],["0.012424","252375"]]}}
1618677459.4406998: {"stream":"ksmusdt@bookTicker","data":{"e":"bookTicker","u":335340937465,"s":"KSMUSDT","b":"458.817","B":"0.2","a":"458.975","A":"0.1","T":1618677459378,"E":1618677459382}}
1618677459.4438348: {"stream":"yfiusdt@bookTicker","data":{"e":"bookTicker","u":335340937524,"s":"YFIUSDT","b":"49981.8","B":"0.003","a":"50003.6","A":"0.055","T":1618677459381,"E":1618677459385}}
1618677459.448025: {"stream":"ksmusdt@depth@100ms","data":{"e":"depthUpdate","E":1618677459388,"T":1618677459381,"s":"KSMUSDT","U":335340934635,"u":335340937505,"pu":335340933872,"b":[["454.304","30.0"],["455.994","0.2"],["456.553","30.0"],["457.748","0.0"],["457.849","0.0"],["457.927","0.0"],["457.946","1.1"],["458.273","6.2"],["458.494","0.0"],["458.652","0.0"],["458.653","0.0"],["458.654","0.0"],["458.748","0.0"],["458.749","6.5"],["458.770","6.4"],["458.771","0.0"],["458.786","1.2"],["458.787","0.3"],["458.817","0.2"]],"a":[["458.802","0.0"],["458.960","0.0"],["458.961","0.0"],["459.209","0.3"],["459.210","1.2"],["459.239","1.0"],["459.240","0.0"],["459.241","1.8"],["459.247","3.2"],["459.304","0.0"],["459.881","0.0"],["460.105","0.0"],["461.050","30.0"],["463.299","30.0"]]}}
1618677459.455112: {"stream":"yfiusdt@bookTicker","data":{"e":"bookTicker","u":335340937825,"s":"YFIUSDT","b":"49981.8","B":"0.003","a":"50003.6","A":"0.172","T":1618677459392,"E":1618677459396}}
1618677459.456218: {"stream":"dentusdt@bookTicker","data":{"e":"bookTicker","u":335340937910,"s":"DENTUSDT","b":"0.012348","B":"13048","a":"0.012359","A":"155172","T":1618677459395,"E":1618677459400}}
1618677459.472: {"stream":"ksmusdt@bookTicker","data":{"e":"bookTicker","u":335340938167,"s":"KSMUSDT","b":"458.839","B":"6.4","a":"458.975","A":"0.1","T":1618677459409,"E":1618677459413}}
1618677459.477449: {"stream":"ksmusdt@aggTrade","data":{"e":"aggTrade","E":1618677459418,"a":21396983,"s":"KSMUSDT","p":"458.802","q":"1.1","f":25426576,"l":25426576,"T":1618677459285,"m":false}}
1618677459.477553: {"stream":"ksmusdt@bookTicker","data":{"e":"bookTicker","u":335340938293,"s":"KSMUSDT","b":"458.839","B":"6.4","a":"459.208","A":"1.6","T":1618677459415,"E":1618677459419}}
1618677459.487978: {"stream":"ksmusdt@bookTicker","data":{"e":"bookTicker","u":335340938562,"s":"KSMUSDT","b":"458.843","B":"1.2","a":"459.208","A":"1.6","T":1618677459426,"E":1618677459430}}
1618677459.491437: {"stream":"ksmusdt@bookTicker","data":{"e":"bookTicker","u":335340938589,"s":"KSMUSDT","b":"458.843","B":"1.2","a":"459.187","A":"6.4","T":1618677459427,"E":1618677459432}}
1618677459.5024939: {"stream":"ksmusdt@bookTicker","data":{"e":"bookTicker","u":335340938867,"s":"KSMUSDT","b":"458.839","B":"6.4","a":"459.187","A":"6.4","T":1618677459439,"E":1618677459444}}
1618677459.5025952: {"stream":"ksmusdt@bookTicker","data":{"e":"bookTicker","u":335340938889,"s":"KSMUSDT","b":"458.839","B":"6.4","a":"459.181","A":"1.2","T":1618677459440,"E":1618677459444}}
1618677459.502639: {"stream":"ksmusdt@bookTicker","data":{"e":"bookTicker","u":335340938931,"s":"KSMUSDT","b":"458.844","B":"0.3","a":"459.181","A":"1.2","T":1618677459442,"E":1618677459446}}
1618677459.519052: {"stream":"yfiusdt@aggTrade","data":{"e":"aggTrade","E":1618677459461,"a":52599696,"s":"YFIUSDT","p":"49986.7","q":"0.001","f":64902174,"l":64902174,"T":1618677459306,"m":false}}
1618677459.530145: {"stream":"yfiusdt@depth@100ms","data":{"e":"depthUpdate","E":1618677459472,"T":1618677459463,"s":"YFIUSDT","U":335340937172,"u":335340939488,"pu":335340936763,"b":[["49731.9","0.001"],["49735.3","0.000"],["49950.1","0.253"],["49952.5","0.000"],["49953.2","0.000"],["49966.0","0.168"]],"a":[["50003.6","0.172"],["50005.6","0.013"],["50006.9","0.000"],["50008.0","0.000"],["50008.9","0.000"],["50029.8","0.000"],["50029.9","0.000"],["50041.4","0.043"],["50046.8","0.000"],["50048.9","0.043"],["50054.3","0.000"],["50054.7","0.043"],["50060.1","0.000"],["50069.0","0.002"],["50239.0","0.005"]]}}
1618677459.532908: {"stream":"dentusdt@bookTicker","data":{"e":"bookTicker","u":335340939680,"s":"DENTUSDT","b":"0.012348","B":"13048","a":"0.012359","A":"60776","T":1618677459471,"E":1618677459475}}
1618677459.535085: {"stream":"dentusdt@bookTicker","data":{"e":"bookTicker","u":335340939729,"s":"DENTUSDT","b":"0.012348","B":"13048","a":"0.012359","A":"6810","T":1618677459473,"E":1618677459477}}
1618677459.5351412: {"stream":"ksmusdt@bookTicker","data":{"e":"bookTicker","u":335340939772,"s":"KSMUSDT","b":"458.844","B":"0.3","a":"459.180","A":"0.3","T":1618677459474,"E":1618677459477}}
1618677459.535864: {"stream":"xmrusdt@kline_1m","data":{"e":"kline","E":1618677459480,"s":"XMRUSDT","k":{"t":1618677420000,"T":1618677479999,"s":"XMRUSDT","i":"1m","f":34692938,"L":34692975,"o":"352.86","c":"352.49","h":"352.93","l":"352.40","v":"34.697","n":38,"x":false,"q":"12234.81878","V":"3.576","Q":"1260.98651","B":"0"}}}
1618677459.5383198: {"stream":"xmrusdt@bookTicker","data":{"e":"bookTicker","u":335340939850,"s":"XMRUSDT","b":"352.41","B":"0.564","a":"352.49","A":"0.420","T":1618677459476,"E":1618677459480}}
1618677459.542146: {"stream":"dentusdt@depth@100ms","data":{"e":"depthUpdate","E":1618677459485,"T":1618677459477,"s":"DENTUSDT","U":335340937522,"u":335340939862,"pu":335340937292,"b":[["0.012286","18244"],["0.012294","533724"]],"a":[["0.012359","6810"],["0.012365","133881"],["0.012366","134947"],["0.012367","274966"],["0.012424","83166"],["0.012446","947179"],["0.012447","40114"],["0.012483","1434"]]}}
1618677459.551502: {"stream":"ksmusdt@depth@100ms","data":{"e":"depthUpdate","E":1618677459492,"T":1618677459486,"s":"KSMUSDT","U":335340937755,"u":335340940138,"pu":335340937505,"b":[["456.583","0.8"],["457.713","0.1"],["457.858","1.6"],["457.946","1.1"],["457.959","10.9"],["457.976","0.0"],["458.171","0.0"],["458.424","0.0"],["458.501","0.2"],["458.691","0.3"],["458.693","0.0"],["458.770","0.0"],["458.786","0.0"],["458.787","0.0"],["458.801","1.2"],["458.802","0.0"],["458.805","0.0"],["458.817","0.0"],["458.839","6.4"],["458.843","0.0"],["458.844","0.3"]],"a":[["458.975","0.0"],["459.180","0.3"],["459.181","1.2"],["459.186","0.0"],["459.187","6.4"],["459.208","1.6"],["459.209","0.0"],["459.210","0.0"],["459.239","0.0"],["459.241","0.0"],["459.247","0.0"],["459.346","0.6"],["459.427","0.0"],["459.640","1.9"],["459.980","0.0"],["460.122","0.0"],["460.184","1.0"],["460.239","0.0"],["461.760","0.9"]]}}
1618677459.5520551: {"stream":"xmrusdt@bookTicker","data":{"e":"bookTicker","u":335340940175,"s":"XMRUSDT","b":"352.41","B":"0.564","a":"352.52","A":"0.240","T":1618677459488,"E":1618677459492}}
1618677459.566022: {"stream":"ksmusdt@bookTicker","data":{"e":"bookTicker","u":335340940572,"s":"KSMUSDT","b":"458.844","B":"0.3","a":"459.179","A":"1.6","T":1618677459503,"E":1618677459507}}
1618677459.5693629: {"stream":"dentusdt@bookTicker","data":{"e":"bookTicker","u":335340940673,"s":"DENTUSDT","b":"0.012348","B":"13048","a":"0.012359","A":"60732","T":1618677459507,"E":1618677459512}}
1618677459.569464: {"stream":"dentusdt@bookTicker","data":{"e":"bookTicker","u":335340940674,"s":"DENTUSDT","b":"0.012348","B":"13048","a":"0.012359","A":"114698","T":1618677459507,"E":1618677459512}}
1618677459.573611: {"stream":"xmrusdt@depth@100ms","data":{"e":"depthUpdate","E":1618677459516,"T":1618677459500,"s":"XMRUSDT","U":335340938232,"u":335340940517,"pu":335340936439,"b":[["317.16","0.113"],["350.69","1.002"],["352.06","0.000"],["352.15","5.719"],["352.25","2.500"],["352.30","0.000"],["352.32","10.720"]],"a":[["352.49","0.000"],["352.53","3.088"],["352.60","4.256"],["352.63","1.000"],["352.83","0.000"]]}}
1618677459.5758111: {"stream":"ksmusdt@bookTicker","data":{"e":"bookTicker","u":335340940858,"s":"KSMUSDT","b":"458.844","B":"0.3","a":"459.160","A":"1.2","T":1618677459516,"E":1618677459519}}
1618677459.5992599: {"stream":"xmrusdt@bookTicker","data":{"e":"bookTicker","u":335340941368,"s":"XMRUSDT","b":"352.41","B":"0.564","a":"352.57","A":"0.001","T":1618677459536,"E":1618677459541}}
1618677459.599384: {"stream":"xmrusdt@bookTicker","data":{"e":"bookTicker","u":335340941373,"s":"XMRUSDT","b":"352.41","B":"0.564","a":"352.57","A":"0.241","T":1618677459537,"E":1618677459541}}
1618677459.606616: {"stream":"ksmusdt@bookTicker","data":{"e":"bookTicker","u":335340941557,"s":"KSMUSDT","b":"458.844","B":"0.3","a":"459.159","A":"0.3","T":1618677459544,"E":1618677459549}}
1618677459.612976: {"stream":"ksmusdt@bookTicker","data":{"e":"bookTicker","u":335340941681,"s":"KSMUSDT","b":"458.844","B":"0.3","a":"459.145","A":"6.4","T":1618677459550,"E":1618677459555}}
1618677459.624937: {"stream":"ksmusdt@bookTicker","data":{"e":"bookTicker","u":335340942062,"s":"KSMUSDT","b":"458.844","B":"0.3","a":"459.141","A":"1.2","T":1618677459562,"E":1618677459566}}
1618677459.625546: {"stream":"ksmusdt@aggTrade","data":{"e":"aggTrade","E":1618677459569,"a":21396984,"s":"KSMUSDT","p":"458.975","q":"0.1","f":25426577,"l":25426577,"T":1618677459415,"m":false}}
1618677459.6354449: {"stream":"yfiusdt@depth@100ms","data":{"e":"depthUpdate","E":1618677459577,"T":1618677459573,"s":"YFIUSDT","U":335340939753,"u":335340942354,"pu":335340939488,"b":[["48328.2","0.050"],["48390.1","0.047"],["49576.4","0.000"],["49890.4","0.000"],["49942.7","0.000"],["49953.1","0.000"],["49974.7","0.000"]],"a":[["50005.5","0.013"],["50005.6","0.000"],["50007.6","0.000"],["50082.7","0.050"],["50114.9","0.000"],["50116.7","0.000"],["50237.0","0.001"],["50240.4","0.022"]]}}
1618677459.6386602: {"stream":"ksmusdt@bookTicker","data":{"e":"bookTicker","u":335340942489,"s":"KSMUSDT","b":"458.844","B":"0.3","a":"459.140","A":"0.3","T":1618677459577,"E":1618677459580}}
1618677459.646111: {"stream":"xmrusdt@bookTicker","data":{"e":"bookTicker","u":335340942539,"s":"XMRUSDT","b":"352.40","B":"4.152","a":"352.57","A":"0.241","T":1618677459579,"E":1618677459583}}
1618677459.6655328: {"stream":"ksmusdt@depth@100ms","data":{"e":"depthUpdate","E":1618677459607,"T":1618677459601,"s":"KSMUSDT","U":335340940572,"u":335340943131,"pu":335340940138,"b":[["454.370","0.0"],["455.286","0.0"],["455.641","0.4"],["455.672","1.2"],["456.301","0.0"],["456.327","0.2"],["456.398","4.9"],["458.168","1.9"],["458.582","2.1"],["458.761","1.2"],["458.780","0.0"],["458.801","0.0"]],"a":[["459.140","0.3"],["459.141","0.0"],["459.145","6.4"],["459.159","0.0"],["459.160","0.0"],["459.179","1.6"],["459.180","0.0"],["459.181","0.0"],["459.208","0.0"],["459.574","0.0"],["460.144","1.0"],["460.184","0.0"],["460.269","6.2"],["460.477","5.6"],["462.147","0.2"],["462.324","0.5"],["462.352","0.4"],["463.576","0.0"],["463.770","0.0"]]}}
1618677459.666398: {"stream":"dentusdt@depth@100ms","data":{"e":"depthUpdate","E":1618677459609,"T":1618677459573,"s":"DENTUSDT","U":335340940582,"u":335340942351,"pu":335340939862,"b":[["0.012268","490174"]],"a":[["0.012359","114698"],["0.012361","40474"],["0.012366","184734"],["0.012384","78501"],["0.012461","48832"]]}}
1618677459.679323: {"stream":"dentusdt@bookTicker","data":{"e":"bookTicker","u":335340943457,"s":"DENTUSDT","b":"0.012348","B":"13048","a":"0.012359","A":"60776","T":1618677459614,"E":1618677459618}}
1618677459.679423: {"stream":"dentusdt@bookTicker","data":{"e":"bookTicker","u":335340943465,"s":"DENTUSDT","b":"0.012348","B":"13048","a":"0.012359","A":"6810","T":1618677459614,"E":1618677459618}}
1618677459.679467: {"stream":"ksmusdt@bookTicker","data":{"e":"bookTicker","u":335340943555,"s":"KSMUSDT","b":"458.844","B":"0.3","a":"459.139","A":"1.6","T":1618677459616,"E":1618677459620}}
1618677459.6823502: {"stream":"xmrusdt@depth@100ms","data":{"e":"depthUpdate","E":1618677459623,"T":1618677459617,"s":"XMRUSDT","U":335340940939,"u":335340943582,"pu":335340940517,"b":[["352.18","2.500"],["352.25","0.000"],["352.36","0.060"],["352.41","0.000"]],"a":[["352.52","0.000"],["352.53","0.000"],["352.57","0.241"],["352.58","2.930"],["352.67","40.194"],["352.68","0.000"],["352.82","0.468"],["353.27","0.056"],["353.53","166.213"],["355.09","0.000"]]}}
1618677459.683043: {"stream":"xmrusdt@bookTicker","data":{"e":"bookTicker","u":335340943692,"s":"XMRUSDT","b":"352.41","B":"0.550","a":"352.57","A":"0.241","T":1618677459622,"E":1618677459625}}
1618677459.6879191: {"stream":"xmrusdt@aggTrade","data":{"e":"aggTrade","E":1618677459631,"a":23619029,"s":"XMRUSDT","p":"352.49","q":"0.580","f":34692975,"l":34692975,"T":1618677459476,"m":false}}
1618677459.6910222: {"stream":"dentusdt@bookTicker","data":{"e":"bookTicker","u":335340943949,"s":"DENTUSDT","b":"0.012348","B":"13048","a":"0.012358","A":"16578","T":1618677459631,"E":1618677459634}}
1618677459.712908: {"stream":"ksmusdt@bookTicker","data":{"e":"bookTicker","u":335340944413,"s":"KSMUSDT","b":"458.844","B":"0.3","a":"459.138","A":"0.3","T":1618677459650,"E":1618677459654}}
1618677459.716693: {"stream":"ksmusdt@bookTicker","data":{"e":"bookTicker","u":335340944463,"s":"KSMUSDT","b":"458.844","B":"0.3","a":"459.136","A":"6.4","T":1618677459654,"E":1618677459658}}
1618677459.7214222: {"stream":"dentusdt@bookTicker","data":{"e":"bookTicker","u":335340944524,"s":"DENTUSDT","b":"0.012348","B":"13048","a":"0.012358","A":"70500","T":1618677459657,"E":1618677459662}}
1618677459.723553: {"stream":"xmrusdt@bookTicker","data":{"e":"bookTicker","u":335340944682,"s":"XMRUSDT","b":"352.41","B":"0.550","a":"352.57","A":"0.791","T":1618677459661,"E":1618677459665}}
1618677459.728838: {"stream":"ksmusdt@bookTicker","data":{"e":"bookTicker","u":335340944770,"s":"KSMUSDT","b":"458.844","B":"0.3","a":"459.130","A":"1.2","T":1618677459665,"E":1618677459671}}
1618677459.733079: {"stream":"xmrusdt@bookTicker","data":{"e":"bookTicker","u":335340944906,"s":"XMRUSDT","b":"352.41","B":"0.550","a":"352.56","A":"2.932","T":1618677459672,"E":1618677459676}}
1618677459.742835: {"stream":"ksmusdt@bookTicker","data":{"e":"bookTicker","u":335340945124,"s":"KSMUSDT","b":"458.839","B":"6.4","a":"459.130","A":"1.2","T":1618677459682,"E":1618677459686}}
1618677459.744902: {"stream":"ksmusdt@bookTicker","data":{"e":"bookTicker","u":335340945131,"s":"KSMUSDT","b":"458.839","B":"6.4","a":"459.129","A":"0.3","T":1618677459682,"E":1618677459688}}
1618677459.75607: {"stream":"xmrusdt@bookTicker","data":{"e":"bookTicker","u":335340945405,"s":"XMRUSDT","b":"352.41","B":"0.550","a":"352.56","A":"3.482","T":1618677459693,"E":1618677459698}}
1618677459.756171: {"stream":"xmrusdt@bookTicker","data":{"e":"bookTicker","u":335340945422,"s":"XMRUSDT","b":"352.41","B":"3.050","a":"352.56","A":"3.482","T":1618677459694,"E":1618677459699}}
1618677459.772098: {"stream":"ksmusdt@depth@100ms","data":{"e":"depthUpdate","E":1618677459713,"T":1618677459705,"s":"KSMUSDT","U":335340943301,"u":335340945649,"pu":335340943131,"b":[["455.641","0.2"],["455.672","0.8"],["456.327","0.0"],["456.620","1.0"],["457.951","2.1"],["457.977","0.4"],["458.111","0.0"],["458.586","0.1"],["458.762","0.3"],["458.844","0.0"]],"a":[["459.129","0.3"],["459.130","0.0"],["459.136","6.4"],["459.138","0.0"],["459.139","1.6"],["459.140","0.0"],["459.144","0.0"],["459.170","0.0"],["459.179","0.0"],["459.187","0.0"],["459.242","0.0"],["459.393","0.1"],["459.498","0.0"],["459.513","0.0"],["459.606","0.0"],["459.752","1.4"],["459.819","2.1"],["461.438","0.0"],["461.981","0.0"],["462.324","0.1"],["462.352","0.0"]]}}
1618677459.772931: {"stream":"yfiusdt@depth@100ms","data":{"e":"depthUpdate","E":1618677459715,"T":1618677459637,"s":"YFIUSDT","U":335340943387,"u":335340944119,"pu":335340942354,"b":[],"a":[["50004.0","0.013"],["50005.5","0.000"],["50145.4","0.010"],["50276.2","0.042"]]}}
1618677459.7774022: {"stream":"dentusdt@depth@100ms","data":{"e":"depthUpdate","E":1618677459718,"T":1618677459692,"s":"DENTUSDT","U":335340943457,"u":335340945373,"pu":335340942351,"b":[["0.010565","330000"],["0.012328","159503"]],"a":[["0.012358","70500"],["0.012359","101254"],["0.012360","60144"],["0.012361","0"],["0.012362","145713"],["0.012366","184734"],["0.012377","3238"]]}}
1618677459.783796: {"stream":"xmrusdt@depth@100ms","data":{"e":"depthUpdate","E":1618677459725,"T":1618677459695,"s":"XMRUSDT","U":335340943631,"u":335340945432,"pu":335340943582,"b":[["351.55","0.000"],["351.62","200.000"],["351.95","25.958"],["352.01","3.164"],["352.04","0.000"],["352.18","0.000"],["352.19","0.000"],["352.30","0.000"],["352.32","9.320"],["352.41","3.050"]],"a":[["352.56","3.482"],["352.57","0.241"],["352.58","0.000"],["352.67","37.694"],["352.81","0.000"],["352.93","0.000"],["352.94","0.612"],["353.35","200.000"],["353.68","39.445"],["354.00","24.081"],["354.48","6.176"]]}}
1618677459.786497: {"stream":"ksmusdt@bookTicker","data":{"e":"bookTicker","u":335340946094,"s":"KSMUSDT","b":"458.839","B":"6.4","a":"459.128","A":"1.6","T":1618677459723,"E":1618677459727}}
1618677459.7883031: {"stream":"ksmusdt@bookTicker","data":{"e":"bookTicker","u":335340946186,"s":"KSMUSDT","b":"458.840","B":"0.3","a":"459.128","A":"1.6","T":1618677459725,"E":1618677459729}}
1618677459.788426: {"stream":"xmrusdt@bookTicker","data":{"e":"bookTicker","u":335340946243,"s":"XMRUSDT","b":"352.41","B":"2.500","a":"352.56","A":"3.482","T":1618677459727,"E":1618677459731}}
1618677459.788471: {"stream":"xmrusdt@bookTicker","data":{"e":"bookTicker","u":335340946254,"s":"XMRUSDT","b":"352.42","B":"0.550","a":"352.56","A":"3.482","T":1618677459728,"E":1618677459731}}
1618677459.793386: {"stream":"xmrusdt@bookTicker","data":{"e":"bookTicker","u":335340946333,"s":"XMRUSDT","b":"352.42","B":"4.250","a":"352.56","A":"3.482","T":1618677459730,"E":1618677459735}}
1618677459.7934852: {"stream":"dentusdt@bookTicker","data":{"e":"bookTicker","u":335340946371,"s":"DENTUSDT","b":"0.012348","B":"13048","a":"0.012358","A":"75646","T":1618677459732,"E":1618677459736}}
1618677459.795551: {"stream":"dentusdt@bookTicker","data":{"e":"bookTicker","u":335340946392,"s":"DENTUSDT","b":"0.012348","B":"13048","a":"0.012358","A":"87811","T":1618677459733,"E":1618677459738}}
1618677459.8265731: {"stream":"ksmusdt@bookTicker","data":{"e":"bookTicker","u":335340947364,"s":"KSMUSDT","b":"458.839","B":"6.4","a":"459.128","A":"1.6","T":1618677459764,"E":1618677459768}}
1618677459.82906: {"stream":"ksmusdt@bookTicker","data":{"e":"bookTicker","u":335340947380,"s":"KSMUSDT","b":"458.839","B":"6.4","a":"459.127","A":"0.3","T":1618677459765,"E":1618677459770}}
1618677459.832201: {"stream":"xmrusdt@bookTicker","data":{"e":"bookTicker","u":335340947508,"s":"XMRUSDT","b":"352.42","B":"4.250","a":"352.56","A":"2.932","T":1618677459770,"E":1618677459774}}
1618677459.8323042: {"stream":"xmrusdt@bookTicker","data":{"e":"bookTicker","u":335340947511,"s":"XMRUSDT","b":"352.42","B":"3.700","a":"352.56","A":"2.932","T":1618677459770,"E":1618677459774}}
1618677459.8323488: {"stream":"xmrusdt@bookTicker","data":{"e":"bookTicker","u":335340947513,"s":"XMRUSDT","b":"352.43","B":"0.550","a":"352.56","A":"2.932","T":1618677459770,"E":1618677459774}}
1618677459.83267: {"stream":"ksmusdt@bookTicker","data":{"e":"bookTicker","u":335340947555,"s":"KSMUSDT","b":"458.839","B":"6.4","a":"459.106","A":"6.4","T":1618677459772,"E":1618677459776}}
1618677459.8363578: {"stream":"dentusdt@bookTicker","data":{"e":"bookTicker","u":335340947631,"s":"DENTUSDT","b":"0.012348","B":"13048","a":"0.012358","A":"33889","T":1618677459776,"E":1618677459779}}
1618677459.844309: {"stream":"xmrusdt@bookTicker","data":{"e":"bookTicker","u":335340947765,"s":"XMRUSDT","b":"352.43","B":"0.550","a":"352.57","A":"0.241","T":1618677459781,"E":1618677459785}}
1618677459.865291: {"stream":"ksmusdt@bookTicker","data":{"e":"bookTicker","u":335340948308,"s":"KSMUSDT","b":"458.839","B":"6.4","a":"459.105","A":"0.3","T":1618677459801,"E":1618677459805}}
1618677459.872532: {"stream":"dentusdt@bookTicker","data":{"e":"bookTicker","u":335340948489,"s":"DENTUSDT","b":"0.012348","B":"13048","a":"0.012358","A":"87811","T":1618677459809,"E":1618677459813}}
1618677459.8814652: {"stream":"ksmusdt@depth@100ms","data":{"e":"depthUpdate","E":1618677459825,"T":1618677459814,"s":"KSMUSDT","U":335340946022,"u":335340948554,"pu":335340945649,"b":[["455.672","0.2"],["455.992","0.4"],["455.994","0.0"],["456.621","0.0"],["457.841","0.0"],["457.946","0.0"],["457.960","1.1"],["458.366","5.9"],["458.750","0.0"],["458.754","1.2"],["458.755","0.3"],["458.761","0.0"],["458.762","0.0"],["458.840","0.0"]],"a":[["459.105","0.3"],["459.106","6.4"],["459.127","0.0"],["459.128","1.6"],["459.129","0.0"],["459.132","0.0"],["459.139","0.0"],["459.145","0.0"],["459.389","0.0"],["459.538","20.6"],["460.118","1.9"],["460.144","0.0"],["461.364","0.0"],["461.605","0.0"],["462.229","0.0"],["462.349","0.4"],["462.366","0.2"]]}}
1618677459.8868392: {"stream":"xmrusdt@depth@100ms","data":{"e":"depthUpdate","E":1618677459831,"T":1618677459809,"s":"XMRUSDT","U":335340946243,"u":335340948480,"pu":335340945432,"b":[["351.51","0.000"],["351.56","1.000"],["351.70","5.515"],["352.03","1.883"],["352.10","22.779"],["352.14","0.000"],["352.19","1.000"],["352.27","0.000"],["352.41","0.000"],["352.42","3.700"],["352.43","0.550"]],"a":[["352.56","0.000"],["352.58","3.427"],["352.60","0.000"],["352.67","0.000"],["353.46","0.000"],["353.68","36.945"],["353.82","9.897"],["354.19","0.000"],["360.61","41.815"]]}}
1618677459.8943439: {"stream":"dentusdt@depth@100ms","data":{"e":"depthUpdate","E":1618677459836,"T":1618677459809,"s":"DENTUSDT","U":335340946361,"u":335340948489,"pu":335340945373,"b":[["0.012328","156265"],["0.012344","81000"]],"a":[["0.012358","87811"],["0.012359","60778"],["0.012360","42836"],["0.012361","40476"],["0.012362","97142"],["0.012364","174901"],["0.012365","0"],["0.012366","242672"],["0.012367","217028"],["0.012392","42222"]]}}
1618677459.894612: {"stream":"ksmusdt@bookTicker","data":{"e":"bookTicker","u":335340948984,"s":"KSMUSDT","b":"458.839","B":"6.4","a":"459.104","A":"1.6","T":1618677459833,"E":1618677459836}}
1618677459.8969758: {"stream":"dentusdt@bookTicker","data":{"e":"bookTicker","u":335340949017,"s":"DENTUSDT","b":"0.012348","B":"13048","a":"0.012357","A":"6810","T":1618677459835,"E":1618677459838}}
1618677459.9303172: {"stream":"ksmusdt@bookTicker","data":{"e":"bookTicker","u":335340949935,"s":"KSMUSDT","b":"458.839","B":"6.4","a":"459.103","A":"0.3","T":1618677459867,"E":1618677459872}}
1618677459.936733: {"stream":"ksmusdt@bookTicker","data":{"e":"bookTicker","u":335340950141,"s":"KSMUSDT","b":"458.839","B":"6.4","a":"459.082","A":"6.4","T":1618677459872,"E":1618677459879}}
1618677459.938925: {"stream":"dentusdt@bookTicker","data":{"e":"bookTicker","u":335340950197,"s":"DENTUSDT","b":"0.012348","B":"8867","a":"0.012357","A":"6810","T":1618677459876,"E":1618677459881}}
1618677459.951804: {"stream":"yfiusdt@bookTicker","data":{"e":"bookTicker","u":335340950586,"s":"YFIUSDT","b":"49981.8","B":"0.003","a":"50003.5","A":"0.013","T":1618677459889,"E":1618677459895}}
1618677459.96301: {"stream":"yfiusdt@depth@100ms","data":{"e":"depthUpdate","E":1618677459905,"T":1618677459900,"s":"YFIUSDT","U":335340948341,"u":335340951040,"pu":335340944119,"b":[["49291.4","0.030"],["49917.0","0.110"],["49921.2","0.110"],["49929.6","0.000"],["49933.8","0.000"],["49943.0","0.130"],["49965.9","0.000"]],"a":[["50003.5","0.013"],["50003.8","0.000"],["50004.0","0.000"],["50050.0","0.019"],["50055.0","0.017"],["50067.2","0.000"],["50276.2","0.000"]]}}
1618677459.974656: {"stream":"ksmusdt@bookTicker","data":{"e":"bookTicker","u":335340951289,"s":"KSMUSDT","b":"458.839","B":"6.4","a":"459.081","A":"0.3","T":1618677459912,"E":1618677459917}}
1618677459.9814951: {"stream":"xmrusdt@bookTicker","data":{"e":"bookTicker","u":335340951510,"s":"XMRUSDT","b":"352.43","B":"3.050","a":"352.57","A":"0.241","T":1618677459918,"E":1618677459922}}
1618677459.9815948: {"stream":"dentusdt@bookTicker","data":{"e":"bookTicker","u":335340951525,"s":"DENTUSDT","b":"0.012348","B":"8867","a":"0.012357","A":"60732","T":1618677459918,"E":1618677459922}}
1618677459.9857512: {"stream":"ksmusdt@depth@100ms","data":{"e":"depthUpdate","E":1618677459927,"T":1618677459912,"s":"KSMUSDT","U":335340948711,"u":335340951289,"pu":335340948554,"b":[["454.712","0.0"],["454.799","3.9"],["455.672","0.0"],["455.992","0.0"],["456.398","4.7"],["456.777","0.0"],["456.865","5.0"],["457.938","2.3"],["457.960","1.1"]],"a":[["459.081","0.3"],["459.082","6.4"],["459.103","0.0"],["459.104","1.6"],["459.105","0.0"],["459.128","0.0"],["459.136","0.0"],["459.976","3.2"],["460.117","0.0"],["460.185","0.0"],["460.850","0.0"],["460.994","3.9"],["462.147","0.0"],["462.366","0.0"],["462.915","0.0"],["463.059","4.0"]]}}
1618677459.995578: {"stream":"dentusdt@depth@100ms","data":{"e":"depthUpdate","E":1618677459938,"T":1618677459929,"s":"DENTUSDT","U":335340949011,"u":335340951819,"pu":335340948489,"b":[["0.012340","101345"],["0.012348","8867"]],"a":[["0.012357","60732"],["0.012358","33889"],["0.012359","0"],["0.012360","83314"],["0.012361","53970"],["0.012363","432167"],["0.012364","41020"],["0.012365","49787"],["0.012366","134947"]]}}
1618677459.998944: {"stream":"xmrusdt@depth@100ms","data":{"e":"depthUpdate","E":1618677459942,"T":1618677459927,"s":"XMRUSDT","U":335340949146,"u":335340951787,"pu":335340948480,"b":[["351.75","58.779"],["352.10","20.279"],["352.18","13.580"],["352.30","0.000"],["352.32","3.301"],["352.35","6.019"],["352.37","0.000"],["352.43","3.050"]],"a":[["352.59","0.000"],["352.68","30.368"],["352.70","0.000"],["352.98","0.000"],["353.04","15.462"],["353.48","6.739"],["353.56","5.287"],["353.82","7.397"]]}}
1618677460.022423: {"stream":"xmrusdt@bookTicker","data":{"e":"bookTicker","u":335340952627,"s":"XMRUSDT","b":"352.43","B":"2.500","a":"352.57","A":"0.241","T":1618677459959,"E":1618677459964}}
1618677460.0225248: {"stream":"xmrusdt@bookTicker","data":{"e":"bookTicker","u":335340952654,"s":"XMRUSDT","b":"352.44","B":"0.550","a":"352.57","A":"0.241","T":1618677459960,"E":1618677459964}}
1618677460.02257: {"stream":"xmrusdt@bookTicker","data":{"e":"bookTicker","u":335340952701,"s":"XMRUSDT","b":"352.44","B":"4.250","a":"352.57","A":"0.241","T":1618677459961,"E":1618677459966}}
1618677460.03664: {"stream":"xmrusdt@bookTicker","data":{"e":"bookTicker","u":335340953028,"s":"XMRUSDT","b":"352.45","B":"2.500","a":"352.57","A":"0.241","T":1618677459972,"E":1618677459977}}
1618677460.065089: {"stream":"xmrusdt@bookTicker","data":{"e":"bookTicker","u":335340953859,"s":"XMRUSDT","b":"352.46","B":"0.550","a":"352.57","A":"0.241","T":1618677460001,"E":1618677460006}}
1618677460.0655239: {"stream":"xmrusdt@bookTicker","data":{"e":"bookTicker","u":335340953924,"s":"XMRUSDT","b":"352.46","B":"4.250","a":"352.57","A":"0.241","T":1618677460003,"E":1618677460008}}
1618677460.0769322: {"stream":"yfiusdt@bookTicker","data":{"e":"bookTicker","u":335340954243,"s":"YFIUSDT","b":"49981.7","B":"0.006","a":"50003.5","A":"0.013","T":1618677460012,"E":1618677460017}}
1618677460.077037: {"stream":"xmrusdt@bookTicker","data":{"e":"bookTicker","u":335340954300,"s":"XMRUSDT","b":"352.46","B":"4.250","a":"352.57","A":"0.418","T":1618677460014,"E":1618677460017}}
1618677460.0770812: {"stream":"ksmusdt@bookTicker","data":{"e":"bookTicker","u":335340954297,"s":"KSMUSDT","b":"458.755","B":"0.3","a":"459.081","A":"0.3","T":1618677460014,"E":1618677460017}}
1618677460.0774999: {"stream":"yfiusdt@kline_1m","data":{"e":"kline","E":1618677460019,"s":"YFIUSDT","k":{"t":1618677420000,"T":1618677479999,"s":"YFIUSDT","i":"1m","f":64902095,"L":64902175,"o":"50010.8","c":"49981.8","h":"50044.2","l":"49950.6","v":"0.977","n":81,"x":false,"q":"48848.8915","V":"0.669","Q":"33449.5277","B":"0"}}}
1618677460.077595: {"stream":"yfiusdt@depth@100ms","data":{"e":"depthUpdate","E":1618677460019,"T":1618677460015,"s":"YFIUSDT","U":335340951367,"u":335340954338,"pu":335340951040,"b":[["48604.2","0.000"],["49142.0","0.000"],["49772.2","0.000"],["49950.1","0.000"],["49953.0","0.259"],["49981.8","0.000"]],"a":[["50273.7","0.042"]]}}
1618677460.0810418: {"stream":"ksmusdt@bookTicker","data":{"e":"bookTicker","u":335340954458,"s":"KSMUSDT","b":"458.754","B":"1.2","a":"459.081","A":"0.3","T":1618677460017,"E":1618677460020}}
1618677460.081145: {"stream":"ksmusdt@bookTicker","data":{"e":"bookTicker","u":335340954470,"s":"KSMUSDT","b":"458.754","B":"1.2","a":"459.082","A":"6.4","T":1618677460017,"E":1618677460022}}
1618677460.0811882: {"stream":"ksmusdt@bookTicker","data":{"e":"bookTicker","u":335340954478,"s":"KSMUSDT","b":"458.756","B":"1.6","a":"459.082","A":"6.4","T":1618677460017,"E":1618677460022}}
1618677460.0812218: {"stream":"ksmusdt@bookTicker","data":{"e":"bookTicker","u":335340954480,"s":"KSMUSDT","b":"458.840","B":"0.3","a":"459.082","A":"6.4","T":1618677460017,"E":1618677460022}}
1618677460.081297: {"stream":"ksmusdt@bookTicker","data":{"e":"bookTicker","u":335340954488,"s":"KSMUSDT","b":"459.000","B":"1.5","a":"459.082","A":"6.4","T":1618677460017,"E":1618677460022}}
1618677460.084106: {"stream":"xmrusdt@bookTicker","data":{"e":"bookTicker","u":335340954573,"s":"XMRUSDT","b":"352.47","B":"2.500","a":"352.57","A":"0.418","T":1618677460019,"E":1618677460024}}
1618677460.0854552: {"stream":"yfiusdt@bookTicker","data":{"e":"bookTicker","u":335340954675,"s":"YFIUSDT","b":"49980.3","B":"0.002","a":"50003.5","A":"0.013","T":1618677460022,"E":1618677460026}}
1618677460.090996: {"stream":"yfiusdt@bookTicker","data":{"e":"bookTicker","u":335340954760,"s":"YFIUSDT","b":"49980.3","B":"0.002","a":"50003.4","A":"0.065","T":1618677460025,"E":1618677460029}}
1618677460.091098: {"stream":"yfiusdt@bookTicker","data":{"e":"bookTicker","u":335340954774,"s":"YFIUSDT","b":"49980.3","B":"0.002","a":"50003.4","A":"0.105","T":1618677460025,"E":1618677460029}}
1618677460.09114: {"stream":"ksmusdt@depth@100ms","data":{"e":"depthUpdate","E":1618677460030,"T":1618677460026,"s":"KSMUSDT","U":335340951740,"u":335340954794,"pu":335340951289,"b":[["449.714","0.0"],["453.734","0.0"],["455.641","0.0"],["455.795","0.0"],["457.984","0.5"],["458.191","0.0"],["458.754","0.0"],["458.755","0.0"],["458.756","1.6"],["458.839","0.0"],["458.840","0.3"],["459.000","1.5"]],"a":[["459.081","0.0"],["459.104","0.0"],["459.106","0.0"],["459.216","1.2"],["459.246","0.3"],["459.247","1.6"],["459.422","0.0"],["459.537","4.4"],["459.605","0.0"],["459.710","2.7"],["459.806","0.4"],["460.117","0.0"],["462.348","0.0"],["462.385","7.9"]]}}
1618677460.091451: {"stream":"xmrusdt@bookTicker","data":{"e":"bookTicker","u":335340954822,"s":"XMRUSDT","b":"352.47","B":"2.500","a":"352.57","A":"0.606","T":1618677460026,"E":1618677460031}}
1618677460.091481: {"stream":"xmrusdt@bookTicker","data":{"e":"bookTicker","u":335340954834,"s":"XMRUSDT","b":"352.47","B":"2.500","a":"352.56","A":"0.655","T":1618677460026,"E":1618677460031}}
1618677460.091501: {"stream":"xmrusdt@bookTicker","data":{"e":"bookTicker","u":335340954889,"s":"XMRUSDT","b":"352.46","B":"4.250","a":"352.56","A":"0.655","T":1618677460027,"E":1618677460031}}
1618677460.093623: {"stream":"xmrusdt@bookTicker","data":{"e":"bookTicker","u":335340955007,"s":"XMRUSDT","b":"352.46","B":"4.250","a":"352.57","A":"0.606","T":1618677460031,"E":1618677460035}}
1618677460.093698: {"stream":"xmrusdt@bookTicker","data":{"e":"bookTicker","u":335340955010,"s":"XMRUSDT","b":"352.46","B":"4.250","a":"352.57","A":"0.418","T":1618677460031,"E":1618677460035}}
1618677460.099303: {"stream":"ksmusdt@bookTicker","data":{"e":"bookTicker","u":335340955160,"s":"KSMUSDT","b":"459.000","B":"1.5","a":"459.081","A":"1.5","T":1618677460035,"E":1618677460040}}
1618677460.1039271: {"stream":"dentusdt@depth@100ms","data":{"e":"depthUpdate","E":1618677460043,"T":1618677459939,"s":"DENTUSDT","U":335340952062,"u":335340952062,"pu":335340951819,"b":[],"a":[["0.012365","107725"]]}}
1618677460.1040692: {"stream":"yfiusdt@bookTicker","data":{"e":"bookTicker","u":335340955299,"s":"YFIUSDT","b":"49980.3","B":"0.002","a":"50003.2","A":"0.013","T":1618677460039,"E":1618677460043}}
1618677460.10412: {"stream":"xmrusdt@bookTicker","data":{"e":"bookTicker","u":335340955394,"s":"XMRUSDT","b":"352.46","B":"4.250","a":"352.57","A":"0.658","T":1618677460041,"E":1618677460045}}
1618677460.1115148: {"stream":"yfiusdt@bookTicker","data":{"e":"bookTicker","u":335340955780,"s":"YFIUSDT","b":"49980.3","B":"0.002","a":"50003.1","A":"0.040","T":1618677460051,"E":1618677460054}}
1618677460.113614: {"stream":"yfiusdt@bookTicker","data":{"e":"bookTicker","u":335340955789,"s":"YFIUSDT","b":"49980.3","B":"0.002","a":"50001.0","A":"0.055","T":1618677460051,"E":1618677460055}}
1618677460.233312: {"stream":"xmrusdt@depth@100ms","data":{"e":"depthUpdate","E":1618677460062,"T":1618677460056,"s":"XMRUSDT","U":335340952594,"u":335340956051,"pu":335340951787,"b":[["344.92","29.800"],["351.52","3.941"],["351.56","0.000"],["351.58","0.000"],["351.60","1.073"],["352.15","5.719"],["352.19","0.000"],["352.21","0.000"],["352.32","0.000"],["352.40","0.452"],["352.42","0.000"],["352.43","0.000"],["352.44","3.700"],["352.45","0.000"],["352.46","4.250"],["352.47","0.000"]],"a":[["352.56","0.000"],["352.57","0.658"],["352.58","0.000"],["352.59","0.845"],["352.60","1.400"],["352.61","3.022"],["352.64","1.609"],["352.65","8.570"],["352.68","2.554"],["352.88","0.000"],["352.95","0.000"],["353.01","0.000"],["353.03","3.248"],["353.33","5.283"],["353.34","41.375"],["353.48","4.239"]]}}
1618677460.233763: {"stream":"ksmusdt@bookTicker","data":{"e":"bookTicker","u":335340956129,"s":"KSMUSDT","b":"459.000","B":"1.5","a":"459.080","A":"0.3","T":1618677460058,"E":1618677460063}}
1618677460.234349: {"stream":"yfiusdt@bookTicker","data":{"e":"bookTicker","u":335340956380,"s":"YFIUSDT","b":"49980.3","B":"0.002","a":"50000.9","A":"0.028","T":1618677460064,"E":1618677460068}}
1618677460.2374651: {"stream":"yfiusdt@bookTicker","data":{"e":"bookTicker","u":335340956793,"s":"YFIUSDT","b":"49980.3","B":"0.002","a":"50001.0","A":"0.055","T":1618677460076,"E":1618677460080}}
1618677460.237548: {"stream":"yfiusdt@bookTicker","data":{"e":"bookTicker","u":335340956867,"s":"YFIUSDT","b":"49980.3","B":"0.002","a":"50000.9","A":"0.029","T":1618677460079,"E":1618677460084}}
1618677460.237577: {"stream":"yfiusdt@bookTicker","data":{"e":"bookTicker","u":335340956870,"s":"YFIUSDT","b":"49980.3","B":"0.002","a":"50000.8","A":"0.003","T":1618677460079,"E":1618677460084}}
1618677460.239632: {"stream":"ksmusdt@bookTicker","data":{"e":"bookTicker","u":335340957235,"s":"KSMUSDT","b":"459.000","B":"1.5","a":"459.081","A":"1.5","T":1618677460090,"E":1618677460094}}
1618677460.239701: {"stream":"yfiusdt@bookTicker","data":{"e":"bookTicker","u":335340957267,"s":"YFIUSDT","b":"49980.3","B":"0.002","a":"50000.7","A":"0.025","T":1618677460091,"E":1618677460095}}
1618677460.247514: {"stream":"ksmusdt@bookTicker","data":{"e":"bookTicker","u":335340957646,"s":"KSMUSDT","b":"459.000","B":"0.5","a":"459.081","A":"1.5","T":1618677460101,"E":1618677460104}}
1618677460.247613: {"stream":"ksmusdt@kline_1m","data":{"e":"kline","E":1618677460105,"s":"KSMUSDT","k":{"t":1618677420000,"T":1618677479999,"s":"KSMUSDT","i":"1m","f":25426460,"L":25426578,"o":"459.607","c":"459.000","h":"459.671","l":"458.391","v":"108.5","n":119,"x":false,"q":"49805.7363","V":"52.7","Q":"24201.4497","B":"0"}}}
1618677460.2476852: {"stream":"yfiusdt@bookTicker","data":{"e":"bookTicker","u":335340957699,"s":"YFIUSDT","b":"49980.3","B":"0.002","a":"50000.8","A":"0.003","T":1618677460102,"E":1618677460106}}
1618677460.247724: {"stream":"yfiusdt@bookTicker","data":{"e":"bookTicker","u":335340957728,"s":"YFIUSDT","b":"49980.3","B":"0.002","a":"50000.5","A":"0.024","T":1618677460103,"E":1618677460106}}
1618677460.250516: {"stream":"dentusdt@kline_1m","data":{"e":"kline","E":1618677460126,"s":"DENTUSDT","k":{"t":1618677420000,"T":1618677479999,"s":"DENTUSDT","i":"1m","f":15787262,"L":15787410,"o":"0.012366","c":"0.012348","h":"0.012366","l":"0.012339","v":"2515534","n":149,"x":false,"q":"31072.175395","V":"1138342","Q":"14064.554712","B":"0"}}}
