1618677467.4722571: {"stream":"yfiusdt@depth@100ms","data":{"e":"depthUpdate","E":1618677467414,"T":1618677467406,"s":"YFIUSDT","U":335341178016,"u":335341180720,"pu":335341177765,"b":[["49572.7","0.000"],["49814.6","0.000"],["49958.9","0.011"],["49962.1","0.011"],["49962.9","0.011"],["49968.0","0.283"],["50000.4","0.001"],["50000.5","0.000"],["50004.1","0.000"],["50004.2","0.000"],["50006.4","0.025"]],"a":[["50025.4","0.002"],["50025.5","0.013"],["50026.2","0.000"],["50026.3","0.000"],["50026.5","0.000"],["50026.6","0.000"],["50069.8","0.000"],["50070.5","0.057"],["50109.2","0.000"],["50121.1","0.057"],["50132.8","0.073"],["50195.2","0.021"],["50289.3","0.010"]]}}
1618677467.502754: {"stream":"ksmusdt@depth@100ms","data":{"e":"depthUpdate","E":1618677467444,"T":1618677467428,"s":"KSMUSDT","U":335341178766,"u":335341181302,"pu":335341178559,"b":[["454.924","0.0"],["456.557","0.0"],["457.595","0.0"],["458.912","0.0"],["458.943","0.1"]],"a":[["459.180","0.0"],["459.181","0.0"],["459.239","0.3"],["461.317","0.0"]]}}
1618677467.521833: {"stream":"dentusdt@bookTicker","data":{"e":"bookTicker","u":335341182135,"s":"DENTUSDT","b":"0.012342","B":"52400","a":"0.012352","A":"56056","T":1618677467456,"E":1618677467461}}
1618677467.5358138: {"stream":"dentusdt@bookTicker","data":{"e":"bookTicker","u":335341182646,"s":"DENTUSDT","b":"0.012342","B":"52400","a":"0.012352","A":"2062","T":1618677467474,"E":1618677467478}}
1618677467.5568051: {"stream":"dentusdt@kline_1m","data":{"e":"kline","E":1618677467496,"s":"DENTUSDT","k":{"t":1618677420000,"T":1618677479999,"s":"DENTUSDT","i":"1m","f":15787262,"L":15787434,"o":"0.012366","c":"0.012352","h":"0.012366","l":"0.012339","v":"2701353","n":173,"x":false,"q":"33367.096937","V":"1215177","Q":"15013.860184","B":"0"}}}
1618677467.556938: {"stream":"dentusdt@aggTrade","data":{"e":"aggTrade","E":1618677467497,"a":8476435,"s":"DENTUSDT","p":"0.012352","q":"2062","f":15787434,"l":15787434,"T":1618677467493,"m":false}}
1618677467.556992: {"stream":"dentusdt@bookTicker","data":{"e":"bookTicker","u":335341183230,"s":"DENTUSDT","b":"0.012342","B":"52400","a":"0.012353","A":"26255","T":1618677467493,"E":1618677467497}}
1618677467.567264: {"stream":"dentusdt@bookTicker","data":{"e":"bookTicker","u":335341183614,"s":"DENTUSDT","b":"0.012343","B":"50000","a":"0.012353","A":"26255","T":1618677467504,"E":1618677467509}}
1618677467.567368: {"stream":"dentusdt@bookTicker","data":{"e":"bookTicker","u":335341183617,"s":"DENTUSDT","b":"0.012343","B":"100000","a":"0.012353","A":"26255","T":1618677467504,"E":1618677467509}}
1618677467.571456: {"stream":"dentusdt@bookTicker","data":{"e":"bookTicker","u":335341183757,"s":"DENTUSDT","b":"0.012343","B":"100000","a":"0.012353","A":"8893","T":1618677467508,"E":1618677467512}}
1618677467.576828: {"stream":"yfiusdt@depth@100ms","data":{"e":"depthUpdate","E":1618677467519,"T":1618677467481,"s":"YFIUSDT","U":335341180991,"u":335341182888,"pu":335341180720,"b":[["49950.7","0.025"],["49959.4","0.000"],["49968.6","0.023"]],"a":[["50085.6","0.021"],["50108.5","0.000"],["50121.0","0.010"],["50193.0","0.000"],["50716.2","0.000"],["50774.2","0.098"]]}}
1618677467.5811899: {"stream":"dentusdt@bookTicker","data":{"e":"bookTicker","u":335341184016,"s":"DENTUSDT","b":"0.012343","B":"100000","a":"0.012355","A":"30916","T":1618677467519,"E":1618677467524}}
1618677467.586674: {"stream":"yfiusdt@bookTicker","data":{"e":"bookTicker","u":335341184079,"s":"YFIUSDT","b":"50007.5","B":"0.055","a":"50023.8","A":"0.004","T":1618677467522,"E":1618677467527}}
1618677467.594523: {"stream":"dentusdt@depth@100ms","data":{"e":"depthUpdate","E":1618677467535,"T":1618677467519,"s":"DENTUSDT","U":335341181352,"u":335341184016,"pu":335341179424,"b":[["0.012265","1108681"],["0.012273","75406"],["0.012288","525690"],["0.012295","186392"],["0.012340","0"],["0.012342","52400"],["0.012343","100000"],["0.012599","0"]],"a":[["0.012352","0"],["0.012353","0"],["0.012355","30916"],["0.012356","0"],["0.012357","75362"],["0.012360","394926"],["0.012361","0"],["0.012376","20683"],["0.012377","0"],["0.012414","737900"],["0.012420","177346"],["0.012441","947179"],["0.012451","128317"]]}}
1618677467.594879: {"stream":"dentusdt@bookTicker","data":{"e":"bookTicker","u":335341184288,"s":"DENTUSDT","b":"0.012343","B":"100000","a":"0.012354","A":"9426","T":1618677467530,"E":1618677467535}}
1618677467.612015: {"stream":"dentusdt@bookTicker","data":{"e":"bookTicker","u":335341184743,"s":"DENTUSDT","b":"0.012343","B":"100000","a":"0.012354","A":"26788","T":1618677467547,"E":1618677467552}}
1618677467.618357: {"stream":"ksmusdt@depth@100ms","data":{"e":"depthUpdate","E":1618677467559,"T":1618677467497,"s":"KSMUSDT","U":335341182055,"u":335341183363,"pu":335341181302,"b":[],"a":[["459.207","0.3"],["459.208","1.2"],["459.238","1.6"],["459.239","0.0"],["459.240","0.0"],["459.880","1.0"]]}}
1618677467.6857212: {"stream":"yfiusdt@depth@100ms","data":{"e":"depthUpdate","E":1618677467627,"T":1618677467575,"s":"YFIUSDT","U":335341184079,"u":335341185736,"pu":335341182888,"b":[["49786.3","0.006"],["49822.8","0.022"],["49922.6","0.004"],["49940.8","0.002"],["50000.4","0.000"],["50007.5","0.055"]],"a":[["50124.4","0.000"]]}}
1618677467.6921148: {"stream":"dentusdt@depth@100ms","data":{"e":"depthUpdate","E":1618677467635,"T":1618677467596,"s":"DENTUSDT","U":335341184269,"u":335341186366,"pu":335341184016,"b":[["0.012131","494024"],["0.012244","73556"],["0.012340","36626"]],"a":[["0.012354","26788"],["0.012355","16028"],["0.012357","90089"],["0.012358","0"],["0.012360","519457"],["0.012366","426475"],["0.012376","17444"],["0.012377","53988"],["0.012401","176918"]]}}
1618677467.697428: {"stream":"dentusdt@bookTicker","data":{"e":"bookTicker","u":335341187438,"s":"DENTUSDT","b":"0.012343","B":"100000","a":"0.012354","A":"9426","T":1618677467637,"E":1618677467640}}
1618677467.704895: {"stream":"dentusdt@aggTrade","data":{"e":"aggTrade","E":1618677467648,"a":8476436,"s":"DENTUSDT","p":"0.012353","q":"368","f":15787435,"l":15787435,"T":1618677467493,"m":false}}
1618677467.706047: {"stream":"xmrusdt@depth@100ms","data":{"e":"depthUpdate","E":1618677467649,"T":1618677467629,"s":"XMRUSDT","U":335341184650,"u":335341187221,"pu":335341177014,"b":[["347.93","0.000"],["348.56","0.761"],["349.88","200.000"],["350.51","200.000"],["352.42","0.000"]],"a":[["352.97","42.148"],["352.98","0.000"],["352.99","14.280"],["354.55","200.000"],["356.47","2.964"],["356.96","0.000"]]}}
1618677467.732783: {"stream":"ksmusdt@depth@100ms","data":{"e":"depthUpdate","E":1618677467674,"T":1618677467667,"s":"KSMUSDT","U":335341185557,"u":335341188229,"pu":335341183363,"b":[["458.137","0.0"],["458.143","2.1"]],"a":[["459.185","0.3"],["459.186","0.0"],["459.206","1.6"],["459.207","0.0"],["459.208","0.0"],["459.238","0.0"],["459.793","2.1"],["460.013","2.6"]]}}
1618677467.7417119: {"stream":"dentusdt@bookTicker","data":{"e":"bookTicker","u":335341188470,"s":"DENTUSDT","b":"0.012343","B":"100000","a":"0.012354","A":"26788","T":1618677467678,"E":1618677467682}}
1618677467.787099: {"stream":"yfiusdt@bookTicker","data":{"e":"bookTicker","u":335341189671,"s":"YFIUSDT","b":"50007.6","B":"0.001","a":"50023.8","A":"0.004","T":1618677467725,"E":1618677467729}}
1618677467.7915258: {"stream":"yfiusdt@depth@100ms","data":{"e":"depthUpdate","E":1618677467732,"T":1618677467725,"s":"YFIUSDT","U":335341187179,"u":335341189671,"pu":335341185736,"b":[["49829.3","0.003"],["49950.7","0.000"],["49958.2","0.000"],["49964.0","0.014"],["49968.6","0.000"],["49969.0","0.000"],["49969.8","0.023"],["49974.8","0.014"],["49989.6","0.000"],["50001.7","0.000"],["50006.3","0.000"],["50006.4","0.000"],["50007.6","0.001"]],"a":[]}}
1618677467.796682: {"stream":"dentusdt@depth@100ms","data":{"e":"depthUpdate","E":1618677467740,"T":1618677467735,"s":"DENTUSDT","U":335341187436,"u":335341189942,"pu":335341186366,"b":[["0.012217","105037"],["0.012334","1698"],["0.012340","36626"]],"a":[["0.012354","26788"],["0.012357","11776"],["0.012358","53988"],["0.012359","74592"],["0.012360","465480"],["0.012362","53977"],["0.012377","0"],["0.012379","61122"],["0.012383","61996"]]}}
1618677467.806433: {"stream":"xmrusdt@depth@100ms","data":{"e":"depthUpdate","E":1618677467749,"T":1618677467735,"s":"XMRUSDT","U":335341187713,"u":335341189925,"pu":335341187221,"b":[["351.66","0.000"]],"a":[["353.38","2.281"],["356.96","1.981"]]}}
1618677467.8469398: {"stream":"ksmusdt@depth@100ms","data":{"e":"depthUpdate","E":1618677467789,"T":1618677467771,"s":"KSMUSDT","U":335341188658,"u":335341190890,"pu":335341188229,"b":[["457.850","0.0"],["457.999","31.4"]],"a":[["459.206","0.0"],["459.240","1.6"],["459.509","1.0"],["459.669","2.2"],["459.766","2.3"],["459.880","0.0"],["462.305","3.6"]]}}
1618677467.859873: {"stream":"dentusdt@bookTicker","data":{"e":"bookTicker","u":335341191431,"s":"DENTUSDT","b":"0.012343","B":"100000","a":"0.012354","A":"9426","T":1618677467797,"E":1618677467802}}
1618677467.879797: {"stream":"ksmusdt@kline_1m","data":{"e":"kline","E":1618677467822,"s":"KSMUSDT","k":{"t":1618677420000,"T":1618677479999,"s":"KSMUSDT","i":"1m","f":25426460,"L":25426584,"o":"459.607","c":"458.975","h":"459.671","l":"458.391","v":"113.0","n":125,"x":false,"q":"51870.8186","V":"53.7","Q":"24660.2600","B":"0"}}}
1618677467.8799329: {"stream":"ksmusdt@bookTicker","data":{"e":"bookTicker","u":335341191892,"s":"KSMUSDT","b":"459.000","B":"2.6","a":"459.163","A":"0.1","T":1618677467818,"E":1618677467822}}
1618677467.901398: {"stream":"dentusdt@depth@100ms","data":{"e":"depthUpdate","E":1618677467843,"T":1618677467837,"s":"DENTUSDT","U":335341190062,"u":335341192370,"pu":335341189942,"b":[["0.010073","57277"],["0.011192","30584"],["0.011781","19336"],["0.012070","309693"],["0.012288","52100"],["0.012291","561781"],["0.012297","108002"],["0.012319","932622"],["0.012340","36626"]],"a":[["0.012354","9426"],["0.012355","0"],["0.012356","17362"],["0.012357","27804"],["0.012358","53988"],["0.012395","573640"],["0.012404","41355"],["0.012410","195697"],["0.012414","264310"],["0.012429","337647"]]}}
1618677467.91638: {"stream":"yfiusdt@depth@100ms","data":{"e":"depthUpdate","E":1618677467859,"T":1618677467833,"s":"YFIUSDT","U":335341190451,"u":335341192245,"pu":335341189671,"b":[["49548.8","0.015"],["49938.0","0.000"],["49942.2","0.000"],["49950.6","0.110"],["49951.3","0.025"],["49954.8","0.110"]],"a":[["50024.5","0.013"],["50025.4","0.000"],["50025.5","0.000"],["50070.5","0.000"],["50070.6","0.000"],["50146.4","0.000"]]}}
1618677467.917251: {"stream":"xmrusdt@depth@100ms","data":{"e":"depthUpdate","E":1618677467861,"T":1618677467851,"s":"XMRUSDT","U":335341190571,"u":335341192794,"pu":335341189925,"b":[["351.01","3.930"],["351.36","1.019"],["351.66","200.000"]],"a":[["353.38","202.281"]]}}
1618677467.923768: {"stream":"ksmusdt@bookTicker","data":{"e":"bookTicker","u":335341193129,"s":"KSMUSDT","b":"459.017","B":"6.4","a":"459.163","A":"0.1","T":1618677467862,"E":1618677467866}}
1618677467.923869: {"stream":"ksmusdt@bookTicker","data":{"e":"bookTicker","u":335341193148,"s":"KSMUSDT","b":"459.081","B":"0.1","a":"459.163","A":"0.1","T":1618677467863,"E":1618677467866}}
1618677467.966549: {"stream":"dentusdt@kline_1m","data":{"e":"kline","E":1618677467909,"s":"DENTUSDT","k":{"t":1618677420000,"T":1618677479999,"s":"DENTUSDT","i":"1m","f":15787262,"L":15787436,"o":"0.012366","c":"0.012354","h":"0.012366","l":"0.012339","v":"2711147","n":175,"x":false,"q":"33488.091645","V":"1224971","Q":"15134.854892","B":"0"}}}
1618677467.966635: {"stream":"dentusdt@aggTrade","data":{"e":"aggTrade","E":1618677467908,"a":8476437,"s":"DENTUSDT","p":"0.012354","q":"9426","f":15787436,"l":15787436,"T":1618677467905,"m":false}}
1618677467.9666681: {"stream":"dentusdt@aggTrade","data":{"e":"aggTrade","E":1618677467908,"a":8476438,"s":"DENTUSDT","p":"0.012356","q":"17362","f":15787437,"l":15787437,"T":1618677467905,"m":false}}
1618677467.9666932: {"stream":"dentusdt@bookTicker","data":{"e":"bookTicker","u":335341194703,"s":"DENTUSDT","b":"0.012343","B":"100000","a":"0.012357","A":"3456","T":1618677467905,"E":1618677467909}}
1618677467.980863: {"stream":"dentusdt@bookTicker","data":{"e":"bookTicker","u":335341194993,"s":"DENTUSDT","b":"0.012344","B":"50000","a":"0.012357","A":"3456","T":1618677467916,"E":1618677467920}}
1618677467.9809659: {"stream":"dentusdt@bookTicker","data":{"e":"bookTicker","u":335341195005,"s":"DENTUSDT","b":"0.012344","B":"100000","a":"0.012357","A":"3456","T":1618677467916,"E":1618677467920}}
1618677467.981009: {"stream":"dentusdt@bookTicker","data":{"e":"bookTicker","u":335341195006,"s":"DENTUSDT","b":"0.012344","B":"150000","a":"0.012357","A":"3456","T":1618677467916,"E":1618677467920}}
1618677467.981042: {"stream":"dentusdt@bookTicker","data":{"e":"bookTicker","u":335341195009,"s":"DENTUSDT","b":"0.012344","B":"150000","a":"0.012354","A":"8650","T":1618677467916,"E":1618677467920}}
1618677467.98107: {"stream":"dentusdt@bookTicker","data":{"e":"bookTicker","u":335341195059,"s":"DENTUSDT","b":"0.012344","B":"150000","a":"0.012357","A":"3456","T":1618677467917,"E":1618677467921}}
1618677467.981098: {"stream":"ksmusdt@depth@100ms","data":{"e":"depthUpdate","E":1618677467922,"T":1618677467904,"s":"KSMUSDT","U":335341191888,"u":335341194612,"pu":335341190890,"b":[["457.451","2.1"],["457.716","0.0"],["457.774","3.2"],["458.028","10.9"],["458.254","5.9"],["458.300","0.0"],["458.302","1.1"],["458.365","5.8"],["458.564","0.0"],["458.589","0.0"],["458.590","0.0"],["458.593","0.0"],["458.700","0.0"],["458.713","0.0"],["458.722","0.0"],["458.739","0.2"],["458.822","0.0"],["458.823","0.0"],["458.894","0.0"],["458.943","0.0"],["459.000","2.6"],["459.017","6.4"],["459.018","0.3"],["459.081","0.1"]],"a":[["458.975","0.0"],["459.171","0.0"],["459.180","0.0"],["459.185","0.0"],["459.241","0.0"],["459.246","0.3"],["459.247","1.3"],["459.509","0.0"],["459.510","0.0"],["459.511","0.0"],["459.910","0.0"],["460.022","0.0"],["460.174","0.0"],["460.346","3.2"]]}}
1618677467.984117: {"stream":"dentusdt@bookTicker","data":{"e":"bookTicker","u":335341195208,"s":"DENTUSDT","b":"0.012344","B":"150000","a":"0.012357","A":"57437","T":1618677467922,"E":1618677467925}}
1618677468.010394: {"stream":"dentusdt@depth@100ms","data":{"e":"depthUpdate","E":1618677467953,"T":1618677467939,"s":"DENTUSDT","U":335341192682,"u":335341195715,"pu":335341192370,"b":[["0.012304","596616"],["0.012323","436586"],["0.012338","602518"],["0.012340","0"],["0.012343","326146"],["0.012344","150000"],["0.013500","0"]],"a":[["0.012354","0"],["0.012356","0"],["0.012357","57437"],["0.012359","20604"],["0.012360","283011"],["0.012362","0"],["0.012363","279508"],["0.012370","0"],["0.012378","429061"],["0.012383","49448"]]}}
1618677468.0190258: {"stream":"dentusdt@bookTicker","data":{"e":"bookTicker","u":335341196299,"s":"DENTUSDT","b":"0.012345","B":"8683","a":"0.012357","A":"57437","T":1618677467958,"E":1618677467961}}
1618677468.022107: {"stream":"xmrusdt@depth@100ms","data":{"e":"depthUpdate","E":1618677467964,"T":1618677467953,"s":"XMRUSDT","U":335341193059,"u":335341196095,"pu":335341192794,"b":[["351.18","50.569"],["351.43","13.719"],["352.06","2.500"],["352.30","0.000"],["352.41","3.700"]],"a":[]}}
1618677468.030772: {"stream":"ksmusdt@aggTrade","data":{"e":"aggTrade","E":1618677467973,"a":21396990,"s":"KSMUSDT","p":"458.975","q":"0.1","f":25426584,"l":25426584,"T":1618677467818,"m":false}}
1618677468.035425: {"stream":"yfiusdt@depth@100ms","data":{"e":"depthUpdate","E":1618677467977,"T":1618677467956,"s":"YFIUSDT","U":335341193447,"u":335341196228,"pu":335341192245,"b":[["49814.3","0.000"],["49986.4","0.032"],["50007.5","0.000"]],"a":[["50043.7","0.032"],["50119.3","0.021"]]}}
1618677468.05104: {"stream":"yfiusdt@bookTicker","data":{"e":"bookTicker","u":335341197347,"s":"YFIUSDT","b":"50007.6","B":"0.001","a":"50023.7","A":"0.055","T":1618677467990,"E":1618677467994}}
1618677468.0670452: {"stream":"dentusdt@bookTicker","data":{"e":"bookTicker","u":335341197833,"s":"DENTUSDT","b":"0.012345","B":"8683","a":"0.012357","A":"53981","T":1618677468002,"E":1618677468008}}
1618677468.0671349: {"stream":"dentusdt@bookTicker","data":{"e":"bookTicker","u":335341197970,"s":"DENTUSDT","b":"0.012345","B":"57262","a":"0.012357","A":"53981","T":1618677468004,"E":1618677468009}}
1618677468.0958111: {"stream":"ksmusdt@depth@100ms","data":{"e":"depthUpdate","E":1618677468037,"T":1618677468029,"s":"KSMUSDT","U":335341195528,"u":335341199062,"pu":335341194612,"b":[["457.945","0.0"],["458.082","0.5"],["458.190","0.0"],["458.302","0.0"],["458.405","1.1"]],"a":[["459.239","0.0"],["459.240","0.0"],["459.246","0.3"],["459.304","0.0"],["459.420","0.0"],["459.511","1.6"],["459.557","0.0"],["459.587","0.4"],["459.590","0.0"],["459.651","0.1"],["460.009","1.0"],["460.178","10.9"]]}}
1618677468.096164: {"stream":"yfiusdt@bookTicker","data":{"e":"bookTicker","u":335341199313,"s":"YFIUSDT","b":"50007.6","B":"0.001","a":"50023.4","A":"0.013","T":1618677468033,"E":1618677468037}}
1618677468.1054668: {"stream":"dentusdt@bookTicker","data":{"e":"bookTicker","u":335341199678,"s":"DENTUSDT","b":"0.012345","B":"57262","a":"0.012359","A":"24060","T":1618677468041,"E":1618677468047}}
1618677468.2215738: {"stream":"dentusdt@aggTrade","data":{"e":"aggTrade","E":1618677468059,"a":8476439,"s":"DENTUSDT","p":"0.012357","q":"24348","f":15787438,"l":15787440,"T":1618677467905,"m":false}}
1618677468.225299: {"stream":"dentusdt@depth@100ms","data":{"e":"depthUpdate","E":1618677468061,"T":1618677468053,"s":"DENTUSDT","U":335341196255,"u":335341200303,"pu":335341195715,"b":[["0.012170","35234"],["0.012213","773"],["0.012335","24963"],["0.012337","27003"],["0.012338","553924"],["0.012339","3446"],["0.012341","9878"],["0.012342","3825"],["0.012343","317028"],["0.012344","190484"],["0.012345","57262"]],"a":[["0.012357","0"],["0.012358","0"],["0.012359","24060"],["0.012360","331590"],["0.012363","225531"],["0.012377","40483"]]}}
1618677468.2298791: {"stream":"yfiusdt@bookTicker","data":{"e":"bookTicker","u":335341201162,"s":"YFIUSDT","b":"50007.6","B":"0.001","a":"50022.1","A":"0.006","T":1618677468071,"E":1618677468075}}
1618677468.229955: {"stream":"xmrusdt@depth@100ms","data":{"e":"depthUpdate","E":1618677468077,"T":1618677468054,"s":"XMRUSDT","U":335341196756,"u":335341200306,"pu":335341196095,"b":[["352.06","0.000"],["352.12","0.000"],["352.18","0.000"],["352.29","2.523"]],"a":[["352.96","8.851"]]}}
1618677468.236191: {"stream":"xmrusdt@bookTicker","data":{"e":"bookTicker","u":335341201342,"s":"XMRUSDT","b":"352.52","B":"0.043","a":"352.53","A":"0.189","T":1618677468079,"E":1618677468081}}
1618677468.236267: {"stream":"dentusdt@bookTicker","data":{"e":"bookTicker","u":335341201495,"s":"DENTUSDT","b":"0.012345","B":"57262","a":"0.012359","A":"78032","T":1618677468080,"E":1618677468083}}
1618677468.259379: {"stream":"yfiusdt@depth@100ms","data":{"e":"depthUpdate","E":1618677468093,"T":1618677468084,"s":"YFIUSDT","U":335341197282,"u":335341201549,"pu":335341196228,"b":[["49553.8","0.000"],["49565.1","0.083"],["49778.8","0.000"],["49790.2","0.083"],["49868.9","0.000"],["49898.9","0.014"],["49903.2","0.000"],["49942.2","0.060"],["49942.6","0.000"],["49948.5","0.000"],["49951.6","0.000"],["49952.4","0.000"],["49956.3","0.002"],["49958.1","0.000"],["49958.9","0.000"],["49959.5","0.002"],["49960.3","0.002"],["49962.1","0.000"],["49962.9","0.000"],["49963.9","0.003"],["49964.0","0.000"],["49968.0","0.000"],["49968.3","0.000"],["49968.9","0.000"],["49969.8","0.009"],["49974.8","0.000"],["49975.1","0.000"],["49975.2","0.000"],["49975.3","0.271"],["49975.4","0.077"],["49986.4","0.000"],["49986.5","0.051"],["49986.6","0.012"],["49997.8","0.007"],["50001.6","0.000"],["50001.7","0.000"],["50001.8","0.000"],["50001.9","0.008"]],"a":[["50022.1","0.006"],["50022.2","0.013"],["50023.4","0.000"],["50023.7","0.055"],["50023.8","0.004"],["50024.5","0.000"],["50031.6","0.002"],["50039.7","0.000"],["50039.9","0.000"],["50056.8","0.081"],["50061.4","0.013"],["50068.9","0.013"],["50074.8","0.013"],["50076.4","0.000"],["50083.9","0.000"],["50089.7","0.000"],["50108.6","0.078"],["50113.2","0.154"],["50128.3","0.000"],["50228.8","0.000"],["50240.3","0.084"],["50453.8","0.000"],["50465.3","0.083"]]}}
1618677468.268502: {"stream":"yfiusdt@bookTicker","data":{"e":"bookTicker","u":335341202228,"s":"YFIUSDT","b":"50007.6","B":"0.001","a":"50022.0","A":"0.013","T":1618677468128,"E":1618677468132}}
1618677468.268605: {"stream":"ksmusdt@depth@100ms","data":{"e":"depthUpdate","E":1618677468137,"T":1618677468127,"s":"KSMUSDT","U":335341199266,"u":335341202211,"pu":335341199062,"b":[["454.405","15.0"],["456.654","15.0"]],"a":[["459.401","0.0"],["459.432","0.1"],["459.494","0.1"],["461.152","15.0"],["463.401","0.0"],["463.622","15.0"]]}}
1618677468.268799: {"stream":"yfiusdt@bookTicker","data":{"e":"bookTicker","u":335341202487,"s":"YFIUSDT","b":"50007.6","B":"0.001","a":"50022.0","A":"0.145","T":1618677468148,"E":1618677468151}}
1618677468.274807: {"stream":"dentusdt@depth@100ms","data":{"e":"depthUpdate","E":1618677468163,"T":1618677468130,"s":"DENTUSDT","U":335341200571,"u":335341202324,"pu":335341200303,"b":[["0.012265","161502"],["0.012289","1899696"]],"a":[["0.012359","78032"],["0.012365","53977"],["0.012366","134942"],["0.012371","242876"],["0.012418","1036183"],["0.012441","0"]]}}
1618677468.2755551: {"stream":"xmrusdt@depth@100ms","data":{"e":"depthUpdate","E":1618677468181,"T":1618677468174,"s":"XMRUSDT","U":335341201342,"u":335341203203,"pu":335341200306,"b":[["352.21","0.000"],["352.26","1.033"],["352.29","0.821"],["352.52","0.043"]],"a":[]}}
1618677468.2788422: {"stream":"yfiusdt@bookTicker","data":{"e":"bookTicker","u":335341203431,"s":"YFIUSDT","b":"50007.6","B":"0.001","a":"50020.7","A":"0.006","T":1618677468184,"E":1618677468190}}
1618677468.281248: {"stream":"yfiusdt@depth@100ms","data":{"e":"depthUpdate","E":1618677468202,"T":1618677468192,"s":"YFIUSDT","U":335341201796,"u":335341203881,"pu":335341201549,"b":[["49905.0","0.158"],["49905.2","0.050"],["49916.1","0.000"],["49958.1","0.003"],["49968.9","0.003"],["49969.8","0.000"],["49997.7","0.000"],["49997.8","0.000"],["50001.9","0.000"],["50002.0","0.000"]],"a":[["50020.7","0.006"],["50021.9","0.002"],["50022.0","0.145"],["50022.1","0.000"],["50022.2","0.000"],["50023.6","0.002"],["50031.6","0.000"],["50066.0","0.000"],["50105.5","0.050"],["50141.1","0.141"]]}}
1618677468.281621: {"stream":"yfiusdt@bookTicker","data":{"e":"bookTicker","u":335341204225,"s":"YFIUSDT","b":"50007.6","B":"0.001","a":"50020.6","A":"0.117","T":1618677468200,"E":1618677468204}}
1618677468.283466: {"stream":"xmrusdt@kline_1m","data":{"e":"kline","E":1618677468209,"s":"XMRUSDT","k":{"t":1618677420000,"T":1618677479999,"s":"XMRUSDT","i":"1m","f":34692938,"L":34692976,"o":"352.86","c":"352.52","h":"352.93","l":"352.40","v":"34.717","n":39,"x":false,"q":"12241.86918","V":"3.576","Q":"1260.98651","B":"0"}}}
1618677468.283554: {"stream":"xmrusdt@bookTicker","data":{"e":"bookTicker","u":335341204572,"s":"XMRUSDT","b":"352.41","B":"3.700","a":"352.53","A":"0.189","T":1618677468205,"E":1618677468209}}
1618677468.283585: {"stream":"yfiusdt@bookTicker","data":{"e":"bookTicker","u":335341204913,"s":"YFIUSDT","b":"50007.6","B":"0.001","a":"50019.3","A":"0.006","T":1618677468210,"E":1618677468214}}
1618677468.285193: {"stream":"xmrusdt@bookTicker","data":{"e":"bookTicker","u":335341205168,"s":"XMRUSDT","b":"352.43","B":"2.862","a":"352.53","A":"0.189","T":1618677468215,"E":1618677468219}}
1618677468.2873101: {"stream":"xmrusdt@bookTicker","data":{"e":"bookTicker","u":335341205354,"s":"XMRUSDT","b":"352.41","B":"3.700","a":"352.53","A":"0.189","T":1618677468219,"E":1618677468223}}
1618677468.2940302: {"stream":"yfiusdt@bookTicker","data":{"e":"bookTicker","u":335341205844,"s":"YFIUSDT","b":"50007.6","B":"0.001","a":"50019.2","A":"0.002","T":1618677468231,"E":1618677468234}}
1618677468.307231: {"stream":"yfiusdt@bookTicker","data":{"e":"bookTicker","u":335341206387,"s":"YFIUSDT","b":"50007.6","B":"0.001","a":"50019.2","A":"0.015","T":1618677468245,"E":1618677468250}}
1618677468.3077261: {"stream":"ksmusdt@depth@100ms","data":{"e":"depthUpdate","E":1618677468251,"T":1618677468247,"s":"KSMUSDT","U":335341202490,"u":335341206461,"pu":335341202211,"b":[["454.405","0.0"],["454.622","15.0"],["456.654","0.0"],["456.872","15.0"],["458.739","0.0"]],"a":[["461.152","0.0"],["461.372","15.0"]]}}
1618677468.316097: {"stream":"yfiusdt@bookTicker","data":{"e":"bookTicker","u":335341206793,"s":"YFIUSDT","b":"50007.6","B":"0.001","a":"50017.9","A":"0.006","T":1618677468254,"E":1618677468257}}
1618677468.3401442: {"stream":"yfiusdt@bookTicker","data":{"e":"bookTicker","u":335341207642,"s":"YFIUSDT","b":"50007.6","B":"0.001","a":"50017.8","A":"0.125","T":1618677468275,"E":1618677468279}}
1618677468.341554: {"stream":"yfiusdt@bookTicker","data":{"e":"bookTicker","u":335341207831,"s":"YFIUSDT","b":"50007.6","B":"0.001","a":"50017.8","A":"0.138","T":1618677468279,"E":1618677468282}}
1618677468.344417: {"stream":"yfiusdt@kline_1m","data":{"e":"kline","E":1618677468285,"s":"YFIUSDT","k":{"t":1618677420000,"T":1618677479999,"s":"YFIUSDT","i":"1m","f":64902095,"L":64902193,"o":"50010.8","c":"50007.6","h":"50044.2","l":"49950.6","v":"1.108","n":99,"x":false,"q":"55398.6567","V":"0.790","Q":"39499.3525","B":"0"}}}
1618677468.344556: {"stream":"yfiusdt@bookTicker","data":{"e":"bookTicker","u":335341207917,"s":"YFIUSDT","b":"49986.7","B":"0.002","a":"50017.8","A":"0.138","T":1618677468280,"E":1618677468284}}
1618677468.3446069: {"stream":"yfiusdt@bookTicker","data":{"e":"bookTicker","u":335341208059,"s":"YFIUSDT","b":"49986.7","B":"0.002","a":"50016.5","A":"0.006","T":1618677468284,"E":1618677468286}}
1618677468.351312: {"stream":"xmrusdt@depth@100ms","data":{"e":"depthUpdate","E":1618677468292,"T":1618677468287,"s":"XMRUSDT","U":335341203573,"u":335341208209,"pu":335341203203,"b":[["347.73","0.000"],["348.36","0.022"],["349.82","200.000"],["349.88","0.000"],["350.45","200.000"],["350.51","0.000"],["351.83","6.046"],["351.95","21.790"],["352.02","3.916"],["352.27","0.000"],["352.28","0.000"],["352.29","0.023"],["352.43","0.000"],["352.52","0.000"]],"a":[["352.52","0.000"],["352.54","0.519"],["352.55","0.240"],["352.56","0.000"],["352.57","0.001"],["352.67","6.377"],["352.68","33.121"],["352.89","3.965"],["352.90","7.918"],["352.95","29.090"],["352.97","15.195"],["353.01","8.700"],["353.65","2.200"],["354.55","0.000"],["354.56","216.492"],["356.49","0.000"]]}}
1618677468.3517241: {"stream":"xmrusdt@bookTicker","data":{"e":"bookTicker","u":335341208242,"s":"XMRUSDT","b":"352.41","B":"3.700","a":"352.53","A":"3.006","T":1618677468288,"E":1618677468292}}
1618677468.3553972: {"stream":"xmrusdt@bookTicker","data":{"e":"bookTicker","u":335341208289,"s":"XMRUSDT","b":"352.41","B":"3.700","a":"352.52","A":"3.700","T":1618677468289,"E":1618677468294}}
1618677468.355497: {"stream":"yfiusdt@bookTicker","data":{"e":"bookTicker","u":335341208393,"s":"YFIUSDT","b":"49986.8","B":"0.025","a":"50016.5","A":"0.006","T":1618677468292,"E":1618677468296}}
1618677468.355542: {"stream":"yfiusdt@bookTicker","data":{"e":"bookTicker","u":335341208482,"s":"YFIUSDT","b":"49986.8","B":"0.038","a":"50016.5","A":"0.006","T":1618677468294,"E":1618677468297}}
1618677468.355575: {"stream":"yfiusdt@bookTicker","data":{"e":"bookTicker","u":335341208558,"s":"YFIUSDT","b":"49986.8","B":"0.038","a":"50016.4","A":"0.108","T":1618677468295,"E":1618677468297}}
1618677468.360037: {"stream":"yfiusdt@bookTicker","data":{"e":"bookTicker","u":335341208638,"s":"YFIUSDT","b":"49986.8","B":"0.038","a":"50016.4","A":"0.110","T":1618677468296,"E":1618677468301}}
1618677468.362729: {"stream":"yfiusdt@depth@100ms","data":{"e":"depthUpdate","E":1618677468303,"T":1618677468297,"s":"YFIUSDT","U":335341204068,"u":335341208713,"pu":335341203881,"b":[["49923.7","0.080"],["49933.8","0.110"],["49936.4","0.080"],["49938.0","0.110"],["49941.3","0.100"],["49942.2","0.170"],["49942.6","0.000"],["49944.5","0.100"],["49945.2","0.017"],["49945.4","0.100"],["49945.8","0.000"],["49946.4","0.000"],["49946.7","0.000"],["49948.5","0.000"],["49950.6","0.000"],["49951.1","0.009"],["49951.3","0.000"],["49951.6","0.000"],["49952.5","0.000"],["49954.8","0.000"],["49956.1","0.009"],["49956.3","0.000"],["49958.1","0.000"],["49958.5","0.000"],["49959.5","0.000"],["49960.3","0.000"],["49961.8","0.000"],["49963.5","0.000"],["49963.9","0.000"],["49964.3","0.000"],["49968.9","0.000"],["49969.3","0.000"],["49974.5","0.000"],["49975.0","0.009"],["49978.0","0.000"],["49986.6","0.000"],["49986.7","0.002"],["49986.8","0.038"],["50007.6","0.000"]],"a":[["50016.4","0.110"],["50016.5","0.006"],["50017.7","0.065"],["50017.8","0.138"],["50017.9","0.000"],["50019.1","0.000"],["50019.2","0.000"],["50019.3","0.000"],["50019.4","0.000"],["50019.6","0.055"],["50020.6","0.000"],["50020.7","0.000"],["50021.9","0.000"],["50022.0","0.000"],["50023.6","0.000"],["50059.7","0.014"],["50061.4","0.000"],["50067.2","0.011"],["50067.6","0.009"],["50068.9","0.000"],["50073.1","0.015"],["50074.8","0.000"],["50099.0","0.009"],["50122.2","0.000"]]}}
1618677468.367017: {"stream":"yfiusdt@bookTicker","data":{"e":"bookTicker","u":335341209004,"s":"YFIUSDT","b":"49986.8","B":"0.025","a":"50016.4","A":"0.110","T":1618677468302,"E":1618677468307}}
1618677468.3671172: {"stream":"yfiusdt@bookTicker","data":{"e":"bookTicker","u":335341209014,"s":"YFIUSDT","b":"49986.9","B":"0.013","a":"50016.4","A":"0.110","T":1618677468303,"E":1618677468307}}
1618677468.367158: {"stream":"yfiusdt@bookTicker","data":{"e":"bookTicker","u":335341209051,"s":"YFIUSDT","b":"49986.9","B":"0.017","a":"50016.4","A":"0.110","T":1618677468304,"E":1618677468308}}
1618677468.3757231: {"stream":"dentusdt@depth@100ms","data":{"e":"depthUpdate","E":1618677468316,"T":1618677468252,"s":"DENTUSDT","U":335341205002,"u":335341206723,"pu":335341202324,"b":[["0.012327","443561"],["0.012342","42846"]],"a":[["0.012387","47716"],["0.012406","88050"]]}}
1618677468.4712708: {"stream":"yfiusdt@bookTicker","data":{"e":"bookTicker","u":335341209650,"s":"YFIUSDT","b":"49986.9","B":"0.013","a":"50016.4","A":"0.110","T":1618677468316,"E":1618677468321}}
1618677468.472518: {"stream":"ksmusdt@kline_1m","data":{"e":"kline","E":1618677468329,"s":"KSMUSDT","k":{"t":1618677420000,"T":1618677479999,"s":"KSMUSDT","i":"1m","f":25426460,"L":25426585,"o":"459.607","c":"459.081","h":"459.671","l":"458.391","v":"113.1","n":126,"x":false,"q":"51916.7267","V":"53.7","Q":"24660.2600","B":"0"}}}
1618677468.47264: {"stream":"yfiusdt@bookTicker","data":{"e":"bookTicker","u":335341209991,"s":"YFIUSDT","b":"49986.9","B":"0.013","a":"50016.4","A":"0.130","T":1618677468323,"E":1618677468329}}
1618677468.4726882: {"stream":"ksmusdt@bookTicker","data":{"e":"bookTicker","u":335341210069,"s":"KSMUSDT","b":"459.018","B":"0.3","a":"459.163","A":"0.1","T":1618677468325,"E":1618677468330}}
1618677468.472723: {"stream":"xmrusdt@bookTicker","data":{"e":"bookTicker","u":335341210201,"s":"XMRUSDT","b":"352.41","B":"3.700","a":"352.51","A":"2.873","T":1618677468329,"E":1618677468333}}
1618677468.472754: {"stream":"yfiusdt@bookTicker","data":{"e":"bookTicker","u":335341210346,"s":"YFIUSDT","b":"49986.9","B":"0.013","a":"50016.4","A":"0.128","T":1618677468333,"E":1618677468337}}
1618677468.4727821: {"stream":"yfiusdt@bookTicker","data":{"e":"bookTicker","u":335341210351,"s":"YFIUSDT","b":"49986.9","B":"0.013","a":"50015.8","A":"0.013","T":1618677468333,"E":1618677468337}}
1618677468.472817: {"stream":"yfiusdt@bookTicker","data":{"e":"bookTicker","u":335341210369,"s":"YFIUSDT","b":"49987.0","B":"0.002","a":"50015.8","A":"0.013","T":1618677468333,"E":1618677468337}}
1618677468.472856: {"stream":"dentusdt@bookTicker","data":{"e":"bookTicker","u":335341210460,"s":"DENTUSDT","b":"0.012345","B":"64172","a":"0.012359","A":"78032","T":1618677468336,"E":1618677468342}}
1618677468.472874: {"stream":"yfiusdt@bookTicker","data":{"e":"bookTicker","u":335341210539,"s":"YFIUSDT","b":"49987.0","B":"0.002","a":"50013.9","A":"0.055","T":1618677468338,"E":1618677468344}}
1618677468.4728909: {"stream":"ksmusdt@depth@100ms","data":{"e":"depthUpdate","E":1618677468351,"T":1618677468333,"s":"KSMUSDT","U":335341206530,"u":335341210318,"pu":335341206461,"b":[["454.622","30.0"],["456.872","30.0"],["458.405","1.1"],["458.789","0.2"],["459.081","0.0"]],"a":[["459.579","4.5"],["459.586","17.9"],["460.009","0.0"],["461.372","30.0"],["463.622","30.0"]]}}
1618677468.4730182: {"stream":"xmrusdt@aggTrade","data":{"e":"aggTrade","E":1618677468360,"a":23619030,"s":"XMRUSDT","p":"352.52","q":"0.043","f":34692976,"l":34692977,"T":1618677468205,"m":true}}
1618677468.473045: {"stream":"yfiusdt@bookTicker","data":{"e":"bookTicker","u":335341211636,"s":"YFIUSDT","b":"49987.0","B":"0.002","a":"50013.8","A":"0.002","T":1618677468368,"E":1618677468372}}
1618677468.473065: {"stream":"ksmusdt@bookTicker","data":{"e":"bookTicker","u":335341211680,"s":"KSMUSDT","b":"459.018","B":"0.3","a":"459.091","A":"1.4","T":1618677468369,"E":1618677468374}}
1618677468.4730828: {"stream":"yfiusdt@bookTicker","data":{"e":"bookTicker","u":335341211681,"s":"YFIUSDT","b":"49987.0","B":"0.002","a":"50013.1","A":"0.012","T":1618677468369,"E":1618677468374}}
1618677468.4731: {"stream":"xmrusdt@bookTicker","data":{"e":"bookTicker","u":335341211939,"s":"XMRUSDT","b":"352.41","B":"3.700","a":"352.50","A":"3.700","T":1618677468378,"E":1618677468381}}
1618677468.4731169: {"stream":"yfiusdt@bookTicker","data":{"e":"bookTicker","u":335341212141,"s":"YFIUSDT","b":"49987.0","B":"0.002","a":"50013.0","A":"0.016","T":1618677468385,"E":1618677468390}}
1618677468.473134: {"stream":"xmrusdt@depth@100ms","data":{"e":"depthUpdate","E":1618677468392,"T":1618677468378,"s":"XMRUSDT","U":335341208242,"u":335341211939,"pu":335341208209,"b":[["351.71","0.000"],["351.86","3.866"],["351.95","19.290"],["352.03","0.000"],["352.18","2.500"],["352.19","0.000"],["352.20","0.000"]],"a":[["352.50","3.700"],["352.51","2.873"],["352.52","3.700"],["352.53","0.189"],["352.54","0.000"],["352.94","6.109"],["353.37","67.105"]]}}
1618677468.4732502: {"stream":"yfiusdt@bookTicker","data":{"e":"bookTicker","u":335341212582,"s":"YFIUSDT","b":"49987.0","B":"0.002","a":"50012.1","A":"0.013","T":1618677468398,"E":1618677468401}}
1618677468.473272: {"stream":"yfiusdt@depth@100ms","data":{"e":"depthUpdate","E":1618677468403,"T":1618677468398,"s":"YFIUSDT","U":335341208737,"u":335341212582,"pu":335341208713,"b":[["49898.8","0.000"],["49907.8","0.017"],["49925.4","0.110"],["49929.6","0.110"],["49934.4","0.000"],["49937.5","0.000"],["49938.0","0.000"],["49938.4","0.000"],["49941.3","0.005"],["49941.5","0.000"],["49942.2","0.060"],["49944.5","0.005"],["49944.7","0.000"],["49945.4","0.005"],["49945.6","0.000"],["49947.9","0.070"],["49970.1","0.000"],["49970.2","0.000"],["49972.4","0.012"],["49975.1","0.051"],["49975.3","0.000"],["49975.4","0.000"],["49977.6","0.000"],["49978.1","0.000"],["49986.5","0.000"],["49986.7","0.000"],["49986.8","0.025"],["49986.9","0.013"],["49987.0","0.002"]],"a":[["50012.1","0.013"],["50013.0","0.016"],["50013.1","0.000"],["50013.7","0.016"],["50013.8","0.002"],["50013.9","0.055"],["50015.7","0.000"],["50015.8","0.000"],["50016.3","0.000"],["50016.4","0.108"],["50016.7","0.055"],["50017.4","0.000"],["50017.8","0.125"],["50019.2","0.000"],["50019.6","0.000"],["50023.7","0.000"],["50043.7","0.000"],["50054.1","0.027"],["50059.7","0.000"],["50061.6","0.027"],["50067.2","0.000"],["50067.5","0.027"],["50072.2","0.000"],["50073.1","0.000"],["50105.5","0.000"]]}}
1618677468.473585: {"stream":"ksmusdt@bookTicker","data":{"e":"bookTicker","u":335341212893,"s":"KSMUSDT","b":"459.017","B":"6.4","a":"459.091","A":"1.4","T":1618677468408,"E":1618677468413}}
1618677468.4764202: {"stream":"yfiusdt@bookTicker","data":{"e":"bookTicker","u":335341213071,"s":"YFIUSDT","b":"49987.0","B":"0.002","a":"50012.0","A":"0.016","T":1618677468411,"E":1618677468416}}
1618677468.4765499: {"stream":"yfiusdt@bookTicker","data":{"e":"bookTicker","u":335341213102,"s":"YFIUSDT","b":"49987.0","B":"0.002","a":"50012.0","A":"0.018","T":1618677468412,"E":1618677468416}}
1618677468.476595: {"stream":"ksmusdt@bookTicker","data":{"e":"bookTicker","u":335341213136,"s":"KSMUSDT","b":"459.000","B":"2.6","a":"459.091","A":"1.4","T":1618677468412,"E":1618677468416}}
1618677468.47665: {"stream":"yfiusdt@bookTicker","data":{"e":"bookTicker","u":335341213166,"s":"YFIUSDT","b":"49987.0","B":"0.002","a":"50012.0","A":"0.026","T":1618677468414,"E":1618677468418}}
1618677468.47667: {"stream":"yfiusdt@bookTicker","data":{"e":"bookTicker","u":335341213222,"s":"YFIUSDT","b":"49987.0","B":"0.002","a":"50009.7","A":"0.055","T":1618677468415,"E":1618677468418}}
1618677468.476688: {"stream":"dentusdt@depth@100ms","data":{"e":"depthUpdate","E":1618677468419,"T":1618677468409,"s":"DENTUSDT","U":335341209560,"u":335341212975,"pu":335341206723,"b":[["0.012328","201334"],["0.012345","64172"]],"a":[["0.012413","250894"]]}}
1618677468.4865851: {"stream":"ksmusdt@bookTicker","data":{"e":"bookTicker","u":335341213399,"s":"KSMUSDT","b":"459.000","B":"2.6","a":"459.090","A":"0.5","T":1618677468423,"E":1618677468427}}
1618677468.486683: {"stream":"ksmusdt@bookTicker","data":{"e":"bookTicker","u":335341213434,"s":"KSMUSDT","b":"459.000","B":"2.6","a":"459.090","A":"1.7","T":1618677468424,"E":1618677468429}}
1618677468.490803: {"stream":"yfiusdt@bookTicker","data":{"e":"bookTicker","u":335341213563,"s":"YFIUSDT","b":"49987.0","B":"0.002","a":"50009.6","A":"0.014","T":1618677468429,"E":1618677468434}}
1618677468.490904: {"stream":"yfiusdt@aggTrade","data":{"e":"aggTrade","E":1618677468435,"a":52599713,"s":"YFIUSDT","p":"50007.6","q":"0.001","f":64902193,"l":64902193,"T":1618677468280,"m":true}}
1618677468.50484: {"stream":"yfiusdt@bookTicker","data":{"e":"bookTicker","u":335341213935,"s":"YFIUSDT","b":"49987.0","B":"0.002","a":"50009.6","A":"0.026","T":1618677468442,"E":1618677468447}}
1618677468.50494: {"stream":"yfiusdt@bookTicker","data":{"e":"bookTicker","u":335341213962,"s":"YFIUSDT","b":"49987.0","B":"0.002","a":"50009.5","A":"0.002","T":1618677468443,"E":1618677468447}}
1618677468.505446: {"stream":"yfiusdt@bookTicker","data":{"e":"bookTicker","u":335341214010,"s":"YFIUSDT","b":"49987.0","B":"0.002","a":"50009.5","A":"0.015","T":1618677468445,"E":1618677468449}}
1618677468.5080462: {"stream":"yfiusdt@bookTicker","data":{"e":"bookTicker","u":335341214027,"s":"YFIUSDT","b":"49987.0","B":"0.002","a":"50007.2","A":"0.055","T":1618677468446,"E":1618677468451}}
1618677468.5181131: {"stream":"yfiusdt@bookTicker","data":{"e":"bookTicker","u":335341214272,"s":"YFIUSDT","b":"49987.0","B":"0.002","a":"50007.2","A":"0.050","T":1618677468455,"E":1618677468460}}
1618677468.525909: {"stream":"ksmusdt@depth@100ms","data":{"e":"depthUpdate","E":1618677468469,"T":1618677468452,"s":"KSMUSDT","U":335341211435,"u":335341214190,"pu":335341210318,"b":[["455.470","0.0"],["455.612","0.1"],["457.191","0.0"],["457.334","0.1"],["458.365","0.0"],["458.848","0.2"],["458.856","1.2"],["458.878","0.0"],["459.017","0.0"],["459.018","0.0"]],"a":[["459.090","1.7"],["459.091","1.4"],["459.244","0.0"],["459.345","5.7"],["459.386","0.4"],["459.406","0.0"],["459.431","1.6"],["459.510","0.0"],["459.511","0.0"],["460.080","0.0"],["460.159","6.1"],["460.631","0.0"],["460.775","0.1"],["462.352","0.0"],["462.497","0.1"]]}}
1618677468.540416: {"stream":"ksmusdt@aggTrade","data":{"e":"aggTrade","E":1618677468481,"a":21396991,"s":"KSMUSDT","p":"459.081","q":"0.1","f":25426585,"l":25426585,"T":1618677468325,"m":true}}
1618677468.540522: {"stream":"yfiusdt@bookTicker","data":{"e":"bookTicker","u":335341214893,"s":"YFIUSDT","b":"49987.0","B":"0.002","a":"50007.1","A":"0.002","T":1618677468478,"E":1618677468482}}
1618677468.562628: {"stream":"yfiusdt@depth@100ms","data":{"e":"depthUpdate","E":1618677468504,"T":1618677468499,"s":"YFIUSDT","U":335341212630,"u":335341215599,"pu":335341212582,"b":[["49315.6","0.018"],["49607.9","0.107"],["49633.1","0.000"],["49795.3","0.107"],["49820.6","0.001"],["49850.6","0.023"],["49881.2","0.000"],["49898.9","0.000"],["49905.3","0.011"],["49933.7","0.026"],["49933.9","0.000"],["49948.7","0.009"],["49957.2","0.000"],["49959.2","0.087"],["49967.4","0.013"],["49972.4","0.000"],["49975.0","0.000"]],"a":[["50007.1","0.002"],["50007.2","0.050"],["50008.3","0.013"],["50009.1","0.000"],["50009.4","0.000"],["50009.5","0.000"],["50009.6","0.000"],["50009.7","0.055"],["50011.3","0.000"],["50011.9","0.000"],["50012.0","0.000"],["50012.1","0.000"],["50013.0","0.000"],["50013.7","0.000"],["50013.8","0.000"],["50013.9","0.000"],["50016.4","0.000"],["50016.7","0.000"],["50017.8","0.000"],["50046.7","0.005"],["50054.1","0.000"],["50059.7","0.000"],["50061.6","0.000"],["50065.9","0.041"],["50067.2","0.000"],["50067.5","0.000"],["50073.1","0.000"],["50073.4","0.035"],["50079.2","0.035"],["50090.0","0.027"],["50115.7","0.400"],["50121.0","0.000"],["50133.0","0.000"],["50139.7","0.000"],["50170.3","0.107"],["50195.8","0.000"],["50357.7","0.107"],["50383.3","0.000"]]}}
1618677468.60166: {"stream":"xmrusdt@depth@100ms","data":{"e":"depthUpdate","E":1618677468543,"T":1618677468528,"s":"XMRUSDT","U":335341213774,"u":335341216450,"pu":335341211939,"b":[["348.95","0.199"],["349.58","1.630"],["349.82","0.000"],["349.88","200.000"],["350.45","0.000"],["350.51","200.000"],["351.79","0.000"]],"a":[["352.59","0.000"],["352.62","4.064"],["352.63","0.000"],["352.97","0.000"],["359.52","0.544"]]}}
1618677468.6019452: {"stream":"xmrusdt@bookTicker","data":{"e":"bookTicker","u":335341216810,"s":"XMRUSDT","b":"352.45","B":"0.024","a":"352.50","A":"3.700","T":1618677468541,"E":1618677468544}}
1618677468.631382: {"stream":"dentusdt@depth@100ms","data":{"e":"depthUpdate","E":1618677468574,"T":1618677468547,"s":"DENTUSDT","U":335341214726,"u":335341216955,"pu":335341212975,"b":[["0.012234","66837"]],"a":[["0.012377","43721"],["0.012432","126172"]]}}
1618677468.638357: {"stream":"ksmusdt@depth@100ms","data":{"e":"depthUpdate","E":1618677468580,"T":1618677468518,"s":"KSMUSDT","U":335341214845,"u":335341216227,"pu":335341214190,"b":[["458.848","0.0"],["458.856","0.0"],["458.857","0.2"]],"a":[["459.244","0.2"],["459.245","2.6"],["459.246","0.0"],["459.431","0.0"],["461.068","0.0"]]}}
1618677468.667256: {"stream":"yfiusdt@depth@100ms","data":{"e":"depthUpdate","E":1618677468606,"T":1618677468569,"s":"YFIUSDT","U":335341215637,"u":335341217645,"pu":335341215599,"b":[["49708.0","0.024"],["49881.1","0.014"]],"a":[["50111.0","0.100"],["50212.3","0.009"]]}}
1618677468.667916: {"stream":"yfiusdt@aggTrade","data":{"e":"aggTrade","E":1618677468611,"a":52599714,"s":"YFIUSDT","p":"50007.2","q":"0.005","f":64902194,"l":64902194,"T":1618677468455,"m":false}}
1618677468.69344: {"stream":"xmrusdt@bookTicker","data":{"e":"bookTicker","u":335341219252,"s":"XMRUSDT","b":"352.45","B":"0.024","a":"352.48","A":"0.116","T":1618677468631,"E":1618677468634}}
1618677468.7018769: {"stream":"xmrusdt@depth@100ms","data":{"e":"depthUpdate","E":1618677468644,"T":1618677468631,"s":"XMRUSDT","U":335341216810,"u":335341219252,"pu":335341216450,"b":[["351.67","156.564"],["352.45","0.024"]],"a":[["352.48","0.116"],["352.53","0.073"],["352.83","16.920"],["352.96","0.468"]]}}
1618677468.7442582: {"stream":"dentusdt@depth@100ms","data":{"e":"depthUpdate","E":1618677468686,"T":1618677468598,"s":"DENTUSDT","U":335341217987,"u":335341218374,"pu":335341216955,"b":[["0.012304","123026"],["0.012312","728434"],["0.012326","30077"],["0.012328","240081"]],"a":[["0.012405","1045719"],["0.012433","515224"]]}}
1618677468.755548: {"stream":"ksmusdt@depth@100ms","data":{"e":"depthUpdate","E":1618677468697,"T":1618677468654,"s":"KSMUSDT","U":335341218220,"u":335341220037,"pu":335341216227,"b":[["455.335","1.1"]],"a":[["459.242","0.2"],["459.243","1.6"],["459.244","0.0"],["459.245","1.0"],["461.073","2.3"]]}}
1618677468.7886488: {"stream":"yfiusdt@depth@100ms","data":{"e":"depthUpdate","E":1618677468730,"T":1618677468720,"s":"YFIUSDT","U":335341219164,"u":335341221954,"pu":335341217645,"b":[["49655.1","0.008"],["49745.3","0.030"]],"a":[["50127.8","0.025"]]}}
1618677468.813385: {"stream":"xmrusdt@depth@100ms","data":{"e":"depthUpdate","E":1618677468754,"T":1618677468703,"s":"XMRUSDT","U":335341219913,"u":335341221484,"pu":335341219252,"b":[["352.18","0.000"],["352.27","2.500"],["352.36","0.000"]],"a":[["352.81","15.194"],["363.49","65.947"]]}}
1618677468.8277419: {"stream":"ksmusdt@kline_1m","data":{"e":"kline","E":1618677468771,"s":"KSMUSDT","k":{"t":1618677420000,"T":1618677479999,"s":"KSMUSDT","i":"1m","f":25426460,"L":25426586,"o":"459.607","c":"459.000","h":"459.671","l":"458.391","v":"115.7","n":127,"x":false,"q":"53110.1267","V":"53.7","Q":"24660.2600","B":"0"}}}
1618677468.828259: {"stream":"ksmusdt@bookTicker","data":{"e":"bookTicker","u":335341223280,"s":"KSMUSDT","b":"458.857","B":"0.2","a":"459.090","A":"1.7","T":1618677468767,"E":1618677468771}}
1618677468.841742: {"stream":"ksmusdt@bookTicker","data":{"e":"bookTicker","u":335341223678,"s":"KSMUSDT","b":"458.857","B":"0.2","a":"459.073","A":"6.4","T":1618677468780,"E":1618677468784}}
1618677468.8544252: {"stream":"ksmusdt@bookTicker","data":{"e":"bookTicker","u":335341224006,"s":"KSMUSDT","b":"458.847","B":"6.4","a":"459.073","A":"6.4","T":1618677468792,"E":1618677468795}}
1618677468.8549912: {"stream":"ksmusdt@bookTicker","data":{"e":"bookTicker","u":335341224033,"s":"KSMUSDT","b":"458.847","B":"6.4","a":"459.072","A":"0.2","T":1618677468793,"E":1618677468797}}
1618677468.855062: {"stream":"ksmusdt@bookTicker","data":{"e":"bookTicker","u":335341224089,"s":"KSMUSDT","b":"458.789","B":"0.2","a":"459.072","A":"0.2","T":1618677468794,"E":1618677468797}}
1618677468.855102: {"stream":"dentusdt@depth@100ms","data":{"e":"depthUpdate","E":1618677468798,"T":1618677468780,"s":"DENTUSDT","U":335341221202,"u":335341223669,"pu":335341218374,"b":[["0.012101","205354"],["0.012180","81408"],["0.012325","300809"],["0.012343","267028"]],"a":[["0.012396","200292"]]}}
1618677468.8672209: {"stream":"ksmusdt@bookTicker","data":{"e":"bookTicker","u":335341224464,"s":"KSMUSDT","b":"458.789","B":"0.2","a":"459.041","A":"1.2","T":1618677468805,"E":1618677468809}}
1618677468.867323: {"stream":"ksmusdt@depth@100ms","data":{"e":"depthUpdate","E":1618677468811,"T":1618677468805,"s":"KSMUSDT","U":335341221611,"u":335341224464,"pu":335341220037,"b":[["458.058","13.6"],["458.254","0.0"],["458.299","0.0"],["458.386","18.6"],["458.405","0.0"],["458.625","1.2"],["458.761","0.0"],["458.847","0.0"],["458.857","0.0"],["459.000","0.0"]],"a":[["459.041","1.2"],["459.072","0.2"],["459.073","6.4"],["459.132","0.0"],["459.240","0.0"],["459.241","1.6"],["459.242","0.0"],["459.243","0.0"],["459.245","0.0"],["459.247","0.0"],["461.728","1.4"],["461.755","0.8"],["463.300","0.0"]]}}
1618677468.883106: {"stream":"ksmusdt@bookTicker","data":{"e":"bookTicker","u":335341224885,"s":"KSMUSDT","b":"458.789","B":"0.2","a":"459.040","A":"1.6","T":1618677468820,"E":1618677468824}}
1618677468.8872268: {"stream":"ksmusdt@bookTicker","data":{"e":"bookTicker","u":335341225012,"s":"KSMUSDT","b":"458.789","B":"0.2","a":"459.040","A":"1.8","T":1618677468825,"E":1618677468829}}
1618677468.8915951: {"stream":"yfiusdt@depth@100ms","data":{"e":"depthUpdate","E":1618677468835,"T":1618677468823,"s":"YFIUSDT","U":335341222309,"u":335341224949,"pu":335341221954,"b":[["49737.1","0.022"],["49827.8","0.006"],["49932.0","0.025"],["49970.1","0.281"],["49975.1","0.040"]],"a":[]}}
1618677468.893974: {"stream":"xmrusdt@bookTicker","data":{"e":"bookTicker","u":335341225193,"s":"XMRUSDT","b":"352.45","B":"0.024","a":"352.48","A":"3.816","T":1618677468832,"E":1618677468836}}
1618677468.894038: {"stream":"ksmusdt@bookTicker","data":{"e":"bookTicker","u":335341225239,"s":"KSMUSDT","b":"458.789","B":"0.2","a":"459.009","A":"1.2","T":1618677468834,"E":1618677468837}}
1618677468.915631: {"stream":"ksmusdt@bookTicker","data":{"e":"bookTicker","u":335341225881,"s":"KSMUSDT","b":"458.745","B":"0.2","a":"459.009","A":"1.2","T":1618677468853,"E":1618677468857}}
1618677468.915734: {"stream":"xmrusdt@depth@100ms","data":{"e":"depthUpdate","E":1618677468858,"T":1618677468833,"s":"XMRUSDT","U":335341222877,"u":335341225218,"pu":335341221484,"b":[["352.18","2.500"],["352.27","0.000"],["352.33","1.788"],["352.39","0.000"]],"a":[["352.48","3.816"],["352.49","3.017"],["352.51","0.000"],["352.52","0.000"],["352.60","0.000"],["352.80","2.500"],["352.83","14.420"],["357.28","2.314"],["357.34","0.056"]]}}
1618677468.9185321: {"stream":"ksmusdt@bookTicker","data":{"e":"bookTicker","u":335341226007,"s":"KSMUSDT","b":"458.745","B":"0.2","a":"459.008","A":"0.2","T":1618677468857,"E":1618677468860}}
1618677468.932557: {"stream":"ksmusdt@bookTicker","data":{"e":"bookTicker","u":335341226456,"s":"KSMUSDT","b":"458.745","B":"0.2","a":"459.003","A":"1.2","T":1618677468868,"E":1618677468873}}
1618677468.9422982: {"stream":"ksmusdt@bookTicker","data":{"e":"bookTicker","u":335341226892,"s":"KSMUSDT","b":"458.745","B":"0.2","a":"458.874","A":"1.4","T":1618677468882,"E":1618677468885}}
1618677468.958258: {"stream":"ksmusdt@bookTicker","data":{"e":"bookTicker","u":335341227371,"s":"KSMUSDT","b":"458.745","B":"6.6","a":"458.874","A":"1.4","T":1618677468896,"E":1618677468901}}
1618677468.9624488: {"stream":"dentusdt@depth@100ms","data":{"e":"depthUpdate","E":1618677468905,"T":1618677468801,"s":"DENTUSDT","U":335341224348,"u":335341224348,"pu":335341223669,"b":[],"a":[["0.012412","84832"]]}}
1618677468.971736: {"stream":"ksmusdt@depth@100ms","data":{"e":"depthUpdate","E":1618677468913,"T":1618677468903,"s":"KSMUSDT","U":335341224588,"u":335341227583,"pu":335341224464,"b":[["457.774","0.0"],["457.999","0.0"],["458.028","0.0"],["458.159","0.0"],["458.301","0.0"],["458.385","0.0"],["458.386","0.0"],["458.387","6.7"],["458.424","0.0"],["458.600","0.0"],["458.625","0.0"],["458.626","0.2"],["458.714","0.2"],["458.745","6.6"],["458.789","0.0"]],"a":[["458.874","1.4"],["459.002","0.2"],["459.003","1.2"],["459.008","0.0"],["459.009","6.4"],["459.040","1.6"],["459.041","0.0"],["459.072","0.0"],["459.090","1.2"],["459.091","0.0"],["459.213","0.6"],["459.241","0.0"],["459.933","10.9"],["460.009","0.0"],["460.065","5.7"],["460.178","0.0"],["460.346","0.0"]]}}
1618677468.978522: {"stream":"ksmusdt@aggTrade","data":{"e":"aggTrade","E":1618677468922,"a":21396992,"s":"KSMUSDT","p":"459.000","q":"2.6","f":25426586,"l":25426586,"T":1618677468767,"m":true}}
1618677468.981654: {"stream":"ksmusdt@bookTicker","data":{"e":"bookTicker","u":335341228070,"s":"KSMUSDT","b":"458.772","B":"3.3","a":"458.874","A":"1.4","T":1618677468920,"E":1618677468924}}
1618677468.9817548: {"stream":"ksmusdt@bookTicker","data":{"e":"bookTicker","u":335341228075,"s":"KSMUSDT","b":"458.772","B":"1.4","a":"458.874","A":"1.4","T":1618677468920,"E":1618677468924}}
1618677468.9858692: {"stream":"ksmusdt@bookTicker","data":{"e":"bookTicker","u":335341228193,"s":"KSMUSDT","b":"458.745","B":"6.6","a":"458.874","A":"1.4","T":1618677468924,"E":1618677468928}}
1618677468.988095: {"stream":"ksmusdt@bookTicker","data":{"e":"bookTicker","u":335341228242,"s":"KSMUSDT","b":"458.745","B":"6.6","a":"458.873","A":"0.5","T":1618677468926,"E":1618677468930}}
1618677468.994347: {"stream":"ksmusdt@bookTicker","data":{"e":"bookTicker","u":335341228442,"s":"KSMUSDT","b":"458.745","B":"0.2","a":"458.873","A":"0.5","T":1618677468933,"E":1618677468937}}
1618677469.024332: {"stream":"xmrusdt@depth@100ms","data":{"e":"depthUpdate","E":1618677468967,"T":1618677468952,"s":"XMRUSDT","U":335341226310,"u":335341228857,"pu":335341225218,"b":[["347.67","0.000"],["347.68","0.019"],["352.08","0.000"],["352.16","26.174"]],"a":[["352.60","0.000"],["352.66","2.500"],["352.80","0.000"],["373.02","0.072"],["391.52","0.030"]]}}
1618677469.028539: {"stream":"ksmusdt@bookTicker","data":{"e":"bookTicker","u":335341229393,"s":"KSMUSDT","b":"458.745","B":"0.2","a":"458.872","A":"0.2","T":1618677468966,"E":1618677468970}}
1618677469.031467: {"stream":"yfiusdt@depth@100ms","data":{"e":"depthUpdate","E":1618677468973,"T":1618677468955,"s":"YFIUSDT","U":335341226475,"u":335341229070,"pu":335341224949,"b":[["44328.4","0.019"],["44359.5","0.000"]],"a":[["50226.5","0.000"],["55665.6","0.015"],["55701.2","0.000"]]}}
1618677469.03983: {"stream":"ksmusdt@bookTicker","data":{"e":"bookTicker","u":335341229722,"s":"KSMUSDT","b":"458.745","B":"0.2","a":"458.851","A":"6.4","T":1618677468978,"E":1618677468982}}
1618677469.054163: {"stream":"dentusdt@bookTicker","data":{"e":"bookTicker","u":335341230020,"s":"DENTUSDT","b":"0.012345","B":"65238","a":"0.012359","A":"78032","T":1618677468990,"E":1618677468996}}
1618677469.062758: {"stream":"ksmusdt@bookTicker","data":{"e":"bookTicker","u":335341230391,"s":"KSMUSDT","b":"458.745","B":"0.2","a":"458.850","A":"1.2","T":1618677469001,"E":1618677469003}}
1618677469.063183: {"stream":"ksmusdt@bookTicker","data":{"e":"bookTicker","u":335341230448,"s":"KSMUSDT","b":"458.745","B":"0.2","a":"458.850","A":"1.4","T":1618677469002,"E":1618677469005}}
1618677469.067167: {"stream":"dentusdt@bookTicker","data":{"e":"bookTicker","u":335341230491,"s":"DENTUSDT","b":"0.012345","B":"119238","a":"0.012359","A":"78032","T":1618677469003,"E":1618677469007}}
1618677469.0672681: {"stream":"ksmusdt@aggTrade","data":{"e":"aggTrade","E":1618677469007,"a":21396993,"s":"KSMUSDT","p":"458.772","q":"1.9","f":25426587,"l":25426587,"T":1618677468920,"m":true}}
1618677469.0673192: {"stream":"ksmusdt@bookTicker","data":{"e":"bookTicker","u":335341230532,"s":"KSMUSDT","b":"458.594","B":"0.1","a":"458.850","A":"1.4","T":1618677469004,"E":1618677469007}}
1618677469.07234: {"stream":"ksmusdt@depth@100ms","data":{"e":"depthUpdate","E":1618677469014,"T":1618677469010,"s":"KSMUSDT","U":335341227792,"u":335341230777,"pu":335341227583,"b":[["457.476","3.2"],["457.770","10.9"],["458.066","3.2"],["458.067","3.5"],["458.103","0.0"],["458.144","2.3"],["458.186","0.0"],["458.241","0.0"],["458.245","0.0"],["458.387","1.5"],["458.388","5.2"],["458.389","1.5"],["458.405","0.3"],["458.569","0.2"],["458.626","0.0"],["458.647","0.0"],["458.648","0.0"],["458.714","0.0"],["458.745","0.0"],["458.772","0.0"]],"a":[["458.850","1.4"],["458.851","6.4"],["458.872","0.0"],["458.873","0.5"],["458.971","0.0"],["459.002","0.0"],["459.003","0.0"],["459.040","0.0"],["459.073","0.0"],["459.090","0.0"],["459.162","1.6"],["459.710","0.0"],["459.880","0.0"],["459.933","16.7"],["460.047","3.2"],["460.077","1.9"],["460.477","0.0"],["462.417","0.8"],["470.838","2.4"]]}}
1618677469.075335: {"stream":"yfiusdt@bookTicker","data":{"e":"bookTicker","u":335341230823,"s":"YFIUSDT","b":"49987.1","B":"0.007","a":"50007.1","A":"0.002","T":1618677469011,"E":1618677469016}}
1618677469.083118: {"stream":"ksmusdt@bookTicker","data":{"e":"bookTicker","u":335341231113,"s":"KSMUSDT","b":"458.594","B":"0.1","a":"458.819","A":"1.2","T":1618677469019,"E":1618677469024}}
1618677469.095068: {"stream":"dentusdt@depth@100ms","data":{"e":"depthUpdate","E":1618677469036,"T":1618677469027,"s":"DENTUSDT","U":335341228390,"u":335341231520,"pu":335341224348,"b":[["0.010300","5900287"],["0.010569","359964"],["0.010846","370012"],["0.010992","152188"],["0.011120","224036"],["0.011221","83598"],["0.011288","85707"],["0.011345","114910"],["0.011391","81063"],["0.011653","19998"],["0.011833","19998"],["0.011978","6666"],["0.012100","329375"],["0.012150","119926"],["0.012197","86257"],["0.012259","4904"],["0.012299","122929"],["0.012308","5496"],["0.012311","50058"],["0.012312","681409"],["0.012320","48916"],["0.012328","201334"],["0.012338","483459"],["0.012339","93830"],["0.012344","239059"],["0.012345","119238"]],"a":[["0.012360","17393"],["0.012371","459904"],["0.012377","40483"],["0.012379","56420"],["0.012383","90640"],["0.012388","620264"],["0.012396","175195"],["0.012406","115407"],["0.012589","241276"]]}}
1618677469.095498: {"stream":"dentusdt@bookTicker","data":{"e":"bookTicker","u":335341231814,"s":"DENTUSDT","b":"0.012345","B":"119238","a":"0.012359","A":"24060","T":1618677469034,"E":1618677469038}}
1618677469.097832: {"stream":"ksmusdt@bookTicker","data":{"e":"bookTicker","u":335341231879,"s":"KSMUSDT","b":"458.594","B":"0.1","a":"458.818","A":"0.2","T":1618677469036,"E":1618677469039}}
1618677469.097903: {"stream":"yfiusdt@bookTicker","data":{"e":"bookTicker","u":335341231903,"s":"YFIUSDT","b":"49987.2","B":"0.002","a":"50007.1","A":"0.002","T":1618677469036,"E":1618677469040}}
1618677469.09822: {"stream":"ksmusdt@bookTicker","data":{"e":"bookTicker","u":335341231944,"s":"KSMUSDT","b":"458.594","B":"0.1","a":"458.797","A":"6.4","T":1618677469037,"E":1618677469041}}
1618677469.110624: {"stream":"yfiusdt@bookTicker","data":{"e":"bookTicker","u":335341232426,"s":"YFIUSDT","b":"49987.3","B":"0.008","a":"50007.1","A":"0.002","T":1618677469048,"E":1618677469053}}
1618677469.1160572: {"stream":"xmrusdt@bookTicker","data":{"e":"bookTicker","u":335341232602,"s":"XMRUSDT","b":"352.40","B":"0.452","a":"352.48","A":"3.816","T":1618677469052,"E":1618677469057}}
1618677469.2381701: {"stream":"xmrusdt@depth@100ms","data":{"e":"depthUpdate","E":1618677469067,"T":1618677469063,"s":"XMRUSDT","U":335341229326,"u":335341233069,"pu":335341228857,"b":[["350.65","0.957"],["351.62","1.424"],["351.67","2.844"],["351.78","4.081"],["351.79","0.000"],["351.90","2.500"],["351.97","3.167"],["352.12","0.000"],["352.16","2.966"],["352.17","1.598"],["352.18","0.000"],["352.41","0.000"],["352.45","0.000"]],"a":[["352.66","2.500"],["352.80","3.191"],["354.56","16.492"],["355.43","1.996"]]}}
1618677469.241768: {"stream":"ksmusdt@bookTicker","data":{"e":"bookTicker","u":335341233322,"s":"KSMUSDT","b":"458.594","B":"0.1","a":"458.796","A":"0.2","T":1618677469070,"E":1618677469075}}
1618677469.241869: {"stream":"yfiusdt@bookTicker","data":{"e":"bookTicker","u":335341233542,"s":"YFIUSDT","b":"49987.3","B":"0.008","a":"50007.2","A":"0.050","T":1618677469078,"E":1618677469081}}
1618677469.2419121: {"stream":"yfiusdt@bookTicker","data":{"e":"bookTicker","u":335341233553,"s":"YFIUSDT","b":"49987.4","B":"0.002","a":"50007.2","A":"0.050","T":1618677469078,"E":1618677469082}}
1618677469.2434402: {"stream":"yfiusdt@depth@100ms","data":{"e":"depthUpdate","E":1618677469096,"T":1618677469080,"s":"YFIUSDT","U":335341230021,"u":335341233616,"pu":335341229070,"b":[["49396.9","0.000"],["49933.7","0.000"],["49970.2","0.063"],["49975.2","0.008"],["49986.9","0.000"],["49987.0","0.000"],["49987.1","0.000"],["49987.2","0.000"],["49987.3","0.008"],["49987.4","0.002"]],"a":[["50007.1","0.000"],["50008.3","0.000"],["50009.7","0.000"],["50013.7","0.002"],["50013.8","0.013"],["50178.4","0.157"],["50186.2","0.000"]]}}
1618677469.2512598: {"stream":"xmrusdt@bookTicker","data":{"e":"bookTicker","u":335341234031,"s":"XMRUSDT","b":"352.44","B":"0.024","a":"352.48","A":"3.816","T":1618677469107,"E":1618677469115}}
1618677469.2513611: {"stream":"ksmusdt@depth@100ms","data":{"e":"depthUpdate","E":1618677469116,"T":1618677469090,"s":"KSMUSDT","U":335341230789,"u":335341233743,"pu":335341230777,"b":[["457.926","0.0"],["457.927","0.0"],["457.998","0.9"],["458.058","0.0"],["458.135","1.7"],["458.404","0.0"],["458.405","0.0"],["458.424","1.1"],["458.425","0.7"],["458.437","0.0"],["458.500","0.2"],["458.501","0.0"]],"a":[["458.796","0.2"],["458.797","6.4"],["458.818","0.0"],["458.819","0.0"],["458.844","1.2"],["458.849","1.6"],["458.850","1.4"],["459.009","0.0"],["459.152","5.8"],["459.162","0.0"],["459.343","0.1"],["459.432","0.0"],["459.469","0.1"],["459.494","0.0"],["459.501","0.1"],["459.651","0.0"],["459.669","0.0"],["459.806","0.0"],["459.880","1.0"],["459.961","0.0"],["460.036","0.0"],["460.194","0.0"]]}}
1618677469.251801: {"stream":"yfiusdt@bookTicker","data":{"e":"bookTicker","u":335341234055,"s":"YFIUSDT","b":"49987.5","B":"0.006","a":"50007.2","A":"0.050","T":1618677469107,"E":1618677469117}}
1618677469.253288: {"stream":"dentusdt@depth@100ms","data":{"e":"depthUpdate","E":1618677469137,"T":1618677469131,"s":"DENTUSDT","U":335341231796,"u":335341234526,"pu":335341231520,"b":[["0.012301","199710"],["0.012310","137235"],["0.012311","3033"],["0.012320","1891"],["0.012321","89635"],["0.012328","240081"],["0.012338","472924"],["0.012339","3446"],["0.012343","217028"],["0.012344","190484"]],"a":[["0.012359","24060"],["0.012362","102547"],["0.012363","274106"],["0.012365","53977"],["0.012370","40479"],["0.012377","0"],["0.012383","63554"]]}}
1618677469.254365: {"stream":"xmrusdt@bookTicker","data":{"e":"bookTicker","u":335341234938,"s":"XMRUSDT","b":"352.44","B":"0.024","a":"352.48","A":"3.700","T":1618677469151,"E":1618677469155}}
1618677469.2613351: {"stream":"ksmusdt@aggTrade","data":{"e":"aggTrade","E":1618677469158,"a":21396994,"s":"KSMUSDT","p":"458.745","q":"0.2","f":25426588,"l":25426588,"T":1618677469004,"m":true}}
1618677469.261442: {"stream":"xmrusdt@bookTicker","data":{"e":"bookTicker","u":335341235103,"s":"XMRUSDT","b":"352.44","B":"0.024","a":"352.47","A":"0.116","T":1618677469157,"E":1618677469162}}
1618677469.261491: {"stream":"xmrusdt@depth@100ms","data":{"e":"depthUpdate","E":1618677469167,"T":1618677469157,"s":"XMRUSDT","U":335341233101,"u":335341235103,"pu":335341233069,"b":[["351.48","2.000"],["351.52","3.941"],["351.90","0.000"],["351.99","44.502"],["352.06","2.500"],["352.08","0.000"],["352.09","0.000"],["352.11","9.917"],["352.15","5.719"],["352.18","0.335"],["352.34","0.377"],["352.44","0.024"]],"a":[["352.47","0.116"],["352.48","3.700"],["352.49","4.417"],["352.50","3.700"],["352.52","0.000"],["352.60","0.000"],["352.61","2.724"],["352.66","0.000"],["352.68","33.121"],["352.80","0.000"],["352.81","0.000"],["354.57","200.208"],["355.44","5.367"]]}}
1618677469.261784: {"stream":"yfiusdt@bookTicker","data":{"e":"bookTicker","u":335341235540,"s":"YFIUSDT","b":"49987.6","B":"0.002","a":"50007.2","A":"0.050","T":1618677469170,"E":1618677469173}}
1618677469.262976: {"stream":"yfiusdt@bookTicker","data":{"e":"bookTicker","u":335341236068,"s":"YFIUSDT","b":"49987.7","B":"0.007","a":"50007.2","A":"0.050","T":1618677469179,"E":1618677469183}}
1618677469.267338: {"stream":"yfiusdt@bookTicker","data":{"e":"bookTicker","u":335341236675,"s":"YFIUSDT","b":"49987.8","B":"0.002","a":"50007.2","A":"0.050","T":1618677469197,"E":1618677469202}}
1618677469.271443: {"stream":"yfiusdt@bookTicker","data":{"e":"bookTicker","u":335341237145,"s":"YFIUSDT","b":"49987.9","B":"0.008","a":"50007.2","A":"0.050","T":1618677469209,"E":1618677469213}}
1618677469.277028: {"stream":"ksmusdt@depth@100ms","data":{"e":"depthUpdate","E":1618677469217,"T":1618677469201,"s":"KSMUSDT","U":335341234047,"u":335341236833,"pu":335341233743,"b":[["451.946","0.0"],["452.308","0.0"],["457.439","24.4"],["457.509","0.0"],["457.537","0.0"],["457.653","10.9"],["457.758","0.0"],["457.771","2.8"],["458.067","0.0"],["458.390","1.1"],["458.424","0.0"],["458.425","0.0"],["458.426","0.3"],["458.427","0.2"]],"a":[["458.850","0.2"],["459.762","10.9"],["459.793","0.0"],["459.863","1.0"],["459.880","0.0"],["462.152","0.0"],["466.114","64.4"],["467.501","0.0"]]}}
1618677469.277431: {"stream":"yfiusdt@depth@100ms","data":{"e":"depthUpdate","E":1618677469217,"T":1618677469210,"s":"YFIUSDT","U":335341234049,"u":335341237152,"pu":335341233616,"b":[["49905.1","0.000"],["49935.9","0.026"],["49956.3","0.000"],["49970.1","0.000"],["49986.9","0.005"],["49987.3","0.000"],["49987.4","0.000"],["49987.5","0.000"],["49987.6","0.000"],["49987.7","0.000"],["49987.8","0.002"],["49987.9","0.008"]],"a":[["50013.8","0.000"],["50017.1","0.013"],["50017.7","0.000"]]}}
1618677469.28338: {"stream":"yfiusdt@bookTicker","data":{"e":"bookTicker","u":335341237545,"s":"YFIUSDT","b":"49988.1","B":"0.006","a":"50007.2","A":"0.050","T":1618677469220,"E":1618677469225}}
1618677469.286459: {"stream":"dentusdt@bookTicker","data":{"e":"bookTicker","u":335341237703,"s":"DENTUSDT","b":"0.012345","B":"119238","a":"0.012359","A":"3456","T":1618677469224,"E":1618677469228}}
1618677469.301553: {"stream":"yfiusdt@bookTicker","data":{"e":"bookTicker","u":335341238115,"s":"YFIUSDT","b":"49988.2","B":"0.002","a":"50007.2","A":"0.050","T":1618677469238,"E":1618677469241}}
1618677469.309005: {"stream":"dentusdt@bookTicker","data":{"e":"bookTicker","u":335341238451,"s":"DENTUSDT","b":"0.012345","B":"119238","a":"0.012360","A":"17393","T":1618677469246,"E":1618677469250}}
1618677469.3096802: {"stream":"yfiusdt@bookTicker","data":{"e":"bookTicker","u":335341238516,"s":"YFIUSDT","b":"49988.3","B":"0.007","a":"50007.2","A":"0.050","T":1618677469248,"E":1618677469252}}
1618677469.3134038: {"stream":"dentusdt@depth@100ms","data":{"e":"depthUpdate","E":1618677469255,"T":1618677469246,"s":"DENTUSDT","U":335341234933,"u":335341238463,"pu":335341234526,"b":[["0.011110","76393"]],"a":[["0.012359","0"],["0.012361","3456"],["0.012362","94198"],["0.012363","322681"],["0.012365","0"],["0.012370","0"],["0.012414","292652"]]}}
1618677469.3208058: {"stream":"ksmusdt@bookTicker","data":{"e":"bookTicker","u":335341238894,"s":"KSMUSDT","b":"458.594","B":"0.1","a":"458.795","A":"1.6","T":1618677469258,"E":1618677469262}}
1618677469.324309: {"stream":"yfiusdt@bookTicker","data":{"e":"bookTicker","u":335341238987,"s":"YFIUSDT","b":"49988.2","B":"0.002","a":"50007.2","A":"0.050","T":1618677469261,"E":1618677469266}}
1618677469.3244102: {"stream":"yfiusdt@bookTicker","data":{"e":"bookTicker","u":335341239022,"s":"YFIUSDT","b":"49989.9","B":"0.055","a":"50007.2","A":"0.050","T":1618677469262,"E":1618677469266}}
1618677469.32647: {"stream":"yfiusdt@bookTicker","data":{"e":"bookTicker","u":335341239086,"s":"YFIUSDT","b":"49989.9","B":"0.055","a":"50013.7","A":"0.002","T":1618677469263,"E":1618677469267}}
1618677469.327551: {"stream":"xmrusdt@depth@100ms","data":{"e":"depthUpdate","E":1618677469270,"T":1618677469263,"s":"XMRUSDT","U":335341235269,"u":335341239089,"pu":335341235103,"b":[["349.03","0.142"],["349.66","1.500"],["349.82","200.000"],["349.88","0.000"],["350.45","200.000"],["350.51","0.000"],["351.48","157.544"],["351.97","3.167"],["352.03","2.500"],["352.06","0.000"],["352.12","1.440"],["352.16","4.668"],["352.17","5.854"]],"a":[["352.49","3.017"],["352.50","3.700"],["352.60","0.000"],["352.61","0.224"],["352.68","35.621"]]}}
1618677469.337332: {"stream":"ksmusdt@bookTicker","data":{"e":"bookTicker","u":335341239480,"s":"KSMUSDT","b":"458.594","B":"0.1","a":"458.794","A":"0.2","T":1618677469274,"E":1618677469278}}
1618677469.3374321: {"stream":"yfiusdt@bookTicker","data":{"e":"bookTicker","u":335341239508,"s":"YFIUSDT","b":"49990.0","B":"0.018","a":"50013.7","A":"0.002","T":1618677469274,"E":1618677469278}}
1618677469.350144: {"stream":"yfiusdt@bookTicker","data":{"e":"bookTicker","u":335341240112,"s":"YFIUSDT","b":"49989.9","B":"0.055","a":"50013.7","A":"0.002","T":1618677469288,"E":1618677469291}}
1618677469.36889: {"stream":"yfiusdt@bookTicker","data":{"e":"bookTicker","u":335341240732,"s":"YFIUSDT","b":"49990.0","B":"0.002","a":"50013.7","A":"0.002","T":1618677469307,"E":1618677469310}}
1618677469.3742452: {"stream":"ksmusdt@depth@100ms","data":{"e":"depthUpdate","E":1618677469317,"T":1618677469312,"s":"KSMUSDT","U":335341237247,"u":335341240935,"pu":335341236833,"b":[["456.439","0.7"],["456.681","4.2"],["457.380","10.2"],["457.425","2.3"],["458.390","0.0"],["458.426","0.0"]],"a":[["458.794","0.2"],["458.795","1.6"],["458.796","0.0"],["458.797","0.0"],["458.825","1.2"],["458.844","0.0"],["458.849","0.0"],["459.332","2.2"],["459.433","1.4"],["459.512","0.0"],["459.563","2.1"],["459.926","1.9"]]}}
1618677469.3802938: {"stream":"ksmusdt@bookTicker","data":{"e":"bookTicker","u":335341241081,"s":"KSMUSDT","b":"458.616","B":"6.4","a":"458.794","A":"0.2","T":1618677469316,"E":1618677469320}}
1618677469.380397: {"stream":"yfiusdt@depth@100ms","data":{"e":"depthUpdate","E":1618677469321,"T":1618677469307,"s":"YFIUSDT","U":335341237425,"u":335341240748,"pu":335341237152,"b":[["49925.4","0.000"],["49929.6","0.000"],["49935.9","0.000"],["49938.0","0.110"],["49942.1","0.026"],["49942.2","0.170"],["49944.1","0.043"],["49949.2","0.020"],["49959.2","0.000"],["49960.8","0.087"],["49970.2","0.000"],["49970.3","0.168"],["49975.1","0.029"],["49975.3","0.012"],["49987.8","0.000"],["49987.9","0.000"],["49988.1","0.000"],["49988.2","0.000"],["49988.3","0.000"],["49988.4","0.000"],["49988.5","0.000"],["49989.9","0.055"],["49990.0","0.002"]],"a":[["50007.2","0.000"],["50040.3","0.036"],["50054.2","0.012"],["50061.7","0.001"],["50065.9","0.006"],["50067.5","0.001"],["50073.4","0.000"],["50076.7","0.026"],["50079.2","0.000"],["50081.1","0.000"],["50096.3","0.130"],["50121.0","0.050"]]}}
1618677469.393287: {"stream":"ksmusdt@bookTicker","data":{"e":"bookTicker","u":335341241461,"s":"KSMUSDT","b":"458.616","B":"6.4","a":"458.793","A":"1.6","T":1618677469327,"E":1618677469332}}
1618677469.418755: {"stream":"ksmusdt@bookTicker","data":{"e":"bookTicker","u":335341242302,"s":"KSMUSDT","b":"458.617","B":"0.2","a":"458.793","A":"1.6","T":1618677469355,"E":1618677469359}}
1618677469.4380438: {"stream":"ksmusdt@bookTicker","data":{"e":"bookTicker","u":335341242504,"s":"KSMUSDT","b":"458.617","B":"1.5","a":"458.793","A":"1.6","T":1618677469362,"E":1618677469367}}
1618677469.438167: {"stream":"xmrusdt@depth@100ms","data":{"e":"depthUpdate","E":1618677469371,"T":1618677469358,"s":"XMRUSDT","U":335341239228,"u":335341242392,"pu":335341239089,"b":[["351.84","4.602"],["352.03","0.000"],["352.13","0.000"],["352.16","2.966"],["352.17","10.110"],["352.18","4.066"]],"a":[["352.48","0.000"],["352.49","0.000"],["352.50","2.981"],["352.57","3.001"],["352.61","0.224"],["352.62","1.064"],["352.68","33.121"],["352.81","2.500"],["353.84","0.139"]]}}
1618677469.440008: {"stream":"dentusdt@depth@100ms","data":{"e":"depthUpdate","E":1618677469377,"T":1618677469365,"s":"DENTUSDT","U":335341239438,"u":335341242645,"pu":335341238463,"b":[["0.012263","42185"],["0.012328","201334"],["0.012329","15706"]],"a":[["0.012361","57426"],["0.012365","53977"],["0.012397","160784"],["0.012402","154030"]]}}
1618677469.4497569: {"stream":"ksmusdt@bookTicker","data":{"e":"bookTicker","u":335341243515,"s":"KSMUSDT","b":"458.617","B":"1.3","a":"458.793","A":"1.6","T":1618677469387,"E":1618677469390}}
1618677469.4498591: {"stream":"ksmusdt@bookTicker","data":{"e":"bookTicker","u":335341243516,"s":"KSMUSDT","b":"458.618","B":"0.2","a":"458.793","A":"1.6","T":1618677469387,"E":1618677469390}}
1618677469.457935: {"stream":"yfiusdt@bookTicker","data":{"e":"bookTicker","u":335341243872,"s":"YFIUSDT","b":"49990.1","B":"0.010","a":"50013.7","A":"0.002","T":1618677469394,"E":1618677469398}}
1618677469.461065: {"stream":"ksmusdt@bookTicker","data":{"e":"bookTicker","u":335341243987,"s":"KSMUSDT","b":"458.618","B":"0.2","a":"458.705","A":"1.4","T":1618677469397,"E":1618677469401}}
1618677469.472527: {"stream":"yfiusdt@bookTicker","data":{"e":"bookTicker","u":335341244436,"s":"YFIUSDT","b":"49990.0","B":"0.002","a":"50013.7","A":"0.002","T":1618677469410,"E":1618677469414}}
1618677469.480587: {"stream":"ksmusdt@depth@100ms","data":{"e":"depthUpdate","E":1618677469420,"T":1618677469412,"s":"KSMUSDT","U":335341241081,"u":335341244561,"pu":335341240935,"b":[["452.220","0.0"],["457.290","2.4"],["457.425","0.0"],["457.808","1.1"],["457.975","19.2"],["458.388","3.9"],["458.427","0.0"],["458.616","6.4"],["458.617","1.3"],["458.618","0.2"]],"a":[["458.705","1.4"],["458.793","1.6"],["458.794","0.0"],["458.795","0.0"],["458.825","0.0"],["458.850","0.0"],["458.851","0.0"],["458.874","0.0"],["459.151","5.5"],["459.432","2.2"],["459.450","2.7"],["459.716","3.2"],["459.863","0.0"],["460.429","3.0"],["466.114","21.5"]]}}
1618677469.4818711: {"stream":"yfiusdt@depth@100ms","data":{"e":"depthUpdate","E":1618677469423,"T":1618677469410,"s":"YFIUSDT","U":335341241198,"u":335341244436,"pu":335341240748,"b":[["49963.9","0.086"],["49975.1","0.000"],["49975.2","0.000"],["49982.1","0.016"],["49990.1","0.000"]],"a":[["50017.1","0.000"],["50019.6","0.013"],["50040.3","0.065"],["50111.0","0.000"],["50178.4","0.000"],["50186.2","0.157"]]}}
1618677469.481997: {"stream":"ksmusdt@bookTicker","data":{"e":"bookTicker","u":335341244821,"s":"KSMUSDT","b":"458.619","B":"1.5","a":"458.705","A":"1.4","T":1618677469420,"E":1618677469423}}
1618677469.5155468: {"stream":"ksmusdt@bookTicker","data":{"e":"bookTicker","u":335341246049,"s":"KSMUSDT","b":"458.620","B":"0.2","a":"458.705","A":"1.4","T":1618677469456,"E":1618677469458}}
1618677469.520071: {"stream":"ksmusdt@bookTicker","data":{"e":"bookTicker","u":335341246120,"s":"KSMUSDT","b":"458.641","B":"6.4","a":"458.705","A":"1.4","T":1618677469458,"E":1618677469462}}
1618677469.529074: {"stream":"ksmusdt@bookTicker","data":{"e":"bookTicker","u":335341246441,"s":"KSMUSDT","b":"458.641","B":"6.4","a":"459.119","A":"1.2","T":1618677469466,"E":1618677469469}}
1618677469.529723: {"stream":"ksmusdt@kline_1m","data":{"e":"kline","E":1618677469472,"s":"KSMUSDT","k":{"t":1618677420000,"T":1618677479999,"s":"KSMUSDT","i":"1m","f":25426460,"L":25426589,"o":"459.607","c":"458.705","h":"459.671","l":"458.391","v":"119.2","n":130,"x":false,"q":"54715.7295","V":"55.1","Q":"25302.4470","B":"0"}}}
1618677469.537754: {"stream":"xmrusdt@bookTicker","data":{"e":"bookTicker","u":335341246695,"s":"XMRUSDT","b":"352.44","B":"3.724","a":"352.47","A":"0.116","T":1618677469475,"E":1618677469478}}
1618677469.5401878: {"stream":"ksmusdt@bookTicker","data":{"e":"bookTicker","u":335341246758,"s":"KSMUSDT","b":"458.642","B":"6.5","a":"459.119","A":"1.2","T":1618677469478,"E":1618677469481}}
1618677469.540291: {"stream":"xmrusdt@depth@100ms","data":{"e":"depthUpdate","E":1618677469483,"T":1618677469475,"s":"XMRUSDT","U":335341243261,"u":335341246695,"pu":335341242392,"b":[["351.84","2.102"],["352.17","12.610"],["352.44","3.724"]],"a":[["352.50","0.000"],["352.52","1.400"],["352.55","0.000"],["352.56","3.039"],["352.68","33.121"],["352.81","2.500"]]}}
1618677469.5404842: {"stream":"ksmusdt@bookTicker","data":{"e":"bookTicker","u":335341246812,"s":"KSMUSDT","b":"458.672","B":"1.2","a":"459.119","A":"1.2","T":1618677469479,"E":1618677469483}}
1618677469.550751: {"stream":"ksmusdt@bookTicker","data":{"e":"bookTicker","u":335341247089,"s":"KSMUSDT","b":"458.672","B":"1.2","a":"459.118","A":"0.2","T":1618677469487,"E":1618677469492}}
1618677469.553667: {"stream":"ksmusdt@bookTicker","data":{"e":"bookTicker","u":335341247165,"s":"KSMUSDT","b":"458.672","B":"1.2","a":"459.097","A":"6.4","T":1618677469489,"E":1618677469494}}
1618677469.5635478: {"stream":"dentusdt@kline_1m","data":{"e":"kline","E":1618677469505,"s":"DENTUSDT","k":{"t":1618677420000,"T":1618677479999,"s":"DENTUSDT","i":"1m","f":15787262,"L":15787441,"o":"0.012366","c":"0.012345","h":"0.012366","l":"0.012339","v":"2760956","n":180,"x":false,"q":"34103.466908","V":"1266681","Q":"15650.248000","B":"0"}}}
1618677469.563673: {"stream":"dentusdt@bookTicker","data":{"e":"bookTicker","u":335341247599,"s":"DENTUSDT","b":"0.012345","B":"111139","a":"0.012360","A":"17393","T":1618677469502,"E":1618677469505}}
1618677469.5727549: {"stream":"dentusdt@depth@100ms","data":{"e":"depthUpdate","E":1618677469514,"T":1618677469502,"s":"DENTUSDT","U":335341244405,"u":335341247599,"pu":335341242645,"b":[["0.012308","479086"],["0.012312","207819"],["0.012344","239057"],["0.012345","111139"]],"a":[["0.012395","100050"],["0.012402","627620"],["0.012417","159880"]]}}
1618677469.5758011: {"stream":"ksmusdt@bookTicker","data":{"e":"bookTicker","u":335341247938,"s":"KSMUSDT","b":"458.672","B":"1.2","a":"459.066","A":"1.2","T":1618677469511,"E":1618677469516}}
1618677469.575901: {"stream":"dentusdt@bookTicker","data":{"e":"bookTicker","u":335341247972,"s":"DENTUSDT","b":"0.012345","B":"111139","a":"0.012359","A":"4423","T":1618677469512,"E":1618677469516}}
1618677469.575946: {"stream":"dentusdt@bookTicker","data":{"e":"bookTicker","u":335341248011,"s":"DENTUSDT","b":"0.012346","B":"4076","a":"0.012359","A":"4423","T":1618677469513,"E":1618677469518}}
1618677469.579113: {"stream":"dentusdt@bookTicker","data":{"e":"bookTicker","u":335341248081,"s":"DENTUSDT","b":"0.012346","B":"4076","a":"0.012359","A":"13917","T":1618677469514,"E":1618677469520}}
1618677469.584936: {"stream":"ksmusdt@depth@100ms","data":{"e":"depthUpdate","E":1618677469524,"T":1618677469520,"s":"KSMUSDT","U":335341244819,"u":335341248261,"pu":335341244561,"b":[["451.375","4.4"],["451.737","59.4"],["453.000","355.0"],["457.295","2.3"],["457.718","6.3"],["457.771","0.0"],["457.808","0.0"],["457.908","5.8"],["458.145","0.0"],["458.330","6.4"],["458.387","0.0"],["458.388","0.0"],["458.389","0.0"],["458.537","0.3"],["458.606","1.0"],["458.608","0.7"],["458.612","1.5"],["458.617","0.0"],["458.618","0.0"],["458.619","1.5"],["458.620","0.0"],["458.641","6.4"],["458.642","6.7"],["458.643","1.3"],["458.672","1.2"]],"a":[["458.705","0.0"],["458.793","0.0"],["458.873","0.0"],["459.066","1.2"],["459.097","6.4"],["459.110","0.0"],["459.118","0.2"],["459.119","0.0"],["459.150","1.6"],["459.151","0.0"],["459.152","0.0"],["459.164","1.7"],["459.640","0.0"],["459.864","0.4"],["459.881","0.0"],["459.933","10.9"],["460.096","3.7"],["465.675","21.5"],["466.114","0.0"],["467.060","4.3"]]}}
1618677469.585512: {"stream":"ksmusdt@bookTicker","data":{"e":"bookTicker","u":335341248308,"s":"KSMUSDT","b":"458.673","B":"0.2","a":"459.066","A":"1.2","T":1618677469521,"E":1618677469524}}
1618677469.596281: {"stream":"yfiusdt@depth@100ms","data":{"e":"depthUpdate","E":1618677469537,"T":1618677469522,"s":"YFIUSDT","U":335341245233,"u":335341248348,"pu":335341244436,"b":[["49905.3","0.000"],["49923.8","0.010"],["49925.1","0.100"],["49973.1","0.267"],["49975.3","0.000"],["49987.0","0.010"]],"a":[["50046.7","0.001"],["50056.8","0.000"],["50090.0","0.017"],["50108.1","0.011"],["50127.8","0.000"],["50130.9","0.100"]]}}
1618677469.614636: {"stream":"ksmusdt@bookTicker","data":{"e":"bookTicker","u":335341249407,"s":"KSMUSDT","b":"458.673","B":"0.2","a":"459.065","A":"0.2","T":1618677469551,"E":1618677469555}}
1618677469.63466: {"stream":"ksmusdt@bookTicker","data":{"e":"bookTicker","u":335341249738,"s":"KSMUSDT","b":"458.673","B":"0.2","a":"459.042","A":"1.2","T":1618677469564,"E":1618677469569}}
1618677469.639213: {"stream":"ksmusdt@bookTicker","data":{"e":"bookTicker","u":335341250022,"s":"KSMUSDT","b":"458.695","B":"6.4","a":"459.042","A":"1.2","T":1618677469575,"E":1618677469579}}
1618677469.655487: {"stream":"ksmusdt@bookTicker","data":{"e":"bookTicker","u":335341250281,"s":"KSMUSDT","b":"458.695","B":"6.4","a":"459.041","A":"0.2","T":1618677469587,"E":1618677469590}}
1618677469.655589: {"stream":"ksmusdt@bookTicker","data":{"e":"bookTicker","u":335341250291,"s":"KSMUSDT","b":"458.696","B":"0.2","a":"459.041","A":"0.2","T":1618677469587,"E":1618677469590}}
1618677469.655631: {"stream":"dentusdt@bookTicker","data":{"e":"bookTicker","u":335341250296,"s":"DENTUSDT","b":"0.012346","B":"44554","a":"0.012359","A":"13917","T":1618677469587,"E":1618677469590}}
1618677469.6556659: {"stream":"xmrusdt@depth@100ms","data":{"e":"depthUpdate","E":1618677469591,"T":1618677469577,"s":"XMRUSDT","U":335341247049,"u":335341250053,"pu":335341246695,"b":[["348.23","200.000"],["348.86","200.171"],["349.82","0.000"],["350.45","0.000"],["351.90","2.500"],["352.17","10.110"]],"a":[["352.52","0.000"],["352.55","1.400"],["352.67","6.377"],["352.81","0.000"],["352.98","2.500"],["353.01","0.000"],["353.79","2.965"]]}}
1618677469.655901: {"stream":"ksmusdt@bookTicker","data":{"e":"bookTicker","u":335341250362,"s":"KSMUSDT","b":"458.720","B":"1.2","a":"459.041","A":"0.2","T":1618677469589,"E":1618677469591}}
1618677469.6639519: {"stream":"ksmusdt@bookTicker","data":{"e":"bookTicker","u":335341250604,"s":"KSMUSDT","b":"458.696","B":"0.2","a":"459.041","A":"0.2","T":1618677469597,"E":1618677469602}}
1618677469.673228: {"stream":"xmrusdt@bookTicker","data":{"e":"bookTicker","u":335341250930,"s":"XMRUSDT","b":"352.44","B":"3.700","a":"352.47","A":"0.116","T":1618677469611,"E":1618677469614}}
1618677469.678669: {"stream":"dentusdt@depth@100ms","data":{"e":"depthUpdate","E":1618677469616,"T":1618677469587,"s":"DENTUSDT","U":335341247972,"u":335341250296,"pu":335341247599,"b":[["0.012105","55627"],["0.012180","82228"],["0.012330","184106"],["0.012344","148573"],["0.012346","44554"]],"a":[["0.012359","13917"],["0.012361","97904"],["0.012362","53719"],["0.012382","430406"],["0.012608","872989"]]}}
1618677469.69076: {"stream":"xmrusdt@bookTicker","data":{"e":"bookTicker","u":335341251063,"s":"XMRUSDT","b":"352.45","B":"0.024","a":"352.47","A":"0.116","T":1618677469616,"E":1618677469619}}
1618677469.690861: {"stream":"ksmusdt@aggTrade","data":{"e":"aggTrade","E":1618677469620,"a":21396995,"s":"KSMUSDT","p":"458.705","q":"1.4","f":25426589,"l":25426589,"T":1618677469466,"m":false}}
1618677469.690912: {"stream":"ksmusdt@depth@100ms","data":{"e":"depthUpdate","E":1618677469624,"T":1618677469614,"s":"KSMUSDT","U":335341248286,"u":335341251004,"pu":335341248261,"b":[["457.889","1.9"],["457.976","1.1"],["458.616","0.0"],["458.642","6.5"],["458.667","0.0"],["458.672","0.0"],["458.673","1.2"],["458.695","6.4"],["458.696","0.2"],["458.720","0.0"]],"a":[["459.041","0.2"],["459.042","0.0"],["459.065","0.0"],["459.066","0.0"],["459.092","1.2"],["459.096","1.5"],["459.118","0.0"],["459.150","0.0"],["459.162","1.6"],["459.164","0.0"],["459.345","0.0"],["459.500","1.7"],["459.926","0.0"],["460.009","1.0"],["460.077","0.0"],["465.675","57.7"]]}}
1618677469.714402: {"stream":"dentusdt@aggTrade","data":{"e":"aggTrade","E":1618677469656,"a":8476440,"s":"DENTUSDT","p":"0.012345","q":"8099","f":15787441,"l":15787441,"T":1618677469502,"m":true}}
1618677469.739501: {"stream":"yfiusdt@depth@100ms","data":{"e":"depthUpdate","E":1618677469677,"T":1618677469671,"s":"YFIUSDT","U":335341249972,"u":335341252618,"pu":335341248348,"b":[["49901.0","0.000"],["49907.8","0.000"]],"a":[["50040.2","0.011"],["50210.0","0.025"]]}}
1618677469.7611141: {"stream":"xmrusdt@depth@100ms","data":{"e":"depthUpdate","E":1618677469693,"T":1618677469649,"s":"XMRUSDT","U":335341250389,"u":335341251967,"pu":335341250053,"b":[["348.23","0.000"],["348.86","0.171"],["349.69","207.088"],["350.32","250.557"],["351.90","0.000"],["352.13","0.000"],["352.17","1.598"],["352.24","6.900"],["352.27","2.500"],["352.44","3.700"],["352.45","0.024"]],"a":[["352.98","2.500"],["353.07","0.284"]]}}
1618677469.795203: {"stream":"ksmusdt@depth@100ms","data":{"e":"depthUpdate","E":1618677469731,"T":1618677469719,"s":"KSMUSDT","U":335341251349,"u":335341254305,"pu":335341251004,"b":[["451.793","44.3"],["454.849","0.0"],["456.914","0.0"],["457.613","2.0"],["457.767","0.0"],["457.976","1.1"],["458.027","2.1"],["458.143","0.0"]],"a":[["459.162","0.0"],["459.247","1.6"],["459.332","0.0"],["459.433","0.0"],["459.450","0.0"],["459.541","1.4"],["459.557","2.1"],["459.563","0.0"],["459.986","8.3"],["460.009","0.0"],["460.050","0.0"],["461.036","0.0"],["463.101","0.0"]]}}
1618677469.819432: {"stream":"dentusdt@depth@100ms","data":{"e":"depthUpdate","E":1618677469759,"T":1618677469720,"s":"DENTUSDT","U":335341252160,"u":335341254342,"pu":335341250296,"b":[["0.012271","172733"]],"a":[["0.012417","192712"]]}}
1618677469.82983: {"stream":"dentusdt@bookTicker","data":{"e":"bookTicker","u":335341255745,"s":"DENTUSDT","b":"0.012346","B":"44554","a":"0.012359","A":"9494","T":1618677469764,"E":1618677469769}}
1618677469.82993: {"stream":"dentusdt@bookTicker","data":{"e":"bookTicker","u":335341255763,"s":"DENTUSDT","b":"0.012346","B":"40478","a":"0.012359","A":"9494","T":1618677469765,"E":1618677469769}}
1618677469.874491: {"stream":"xmrusdt@depth@100ms","data":{"e":"depthUpdate","E":1618677469811,"T":1618677469796,"s":"XMRUSDT","U":335341253894,"u":335341256731,"pu":335341251967,"b":[["351.48","155.544"],["351.53","6.476"],["351.98","1.224"],["352.11","7.917"],["352.16","5.966"],["352.18","0.335"],["352.25","2.500"],["352.27","0.000"]],"a":[["352.82","2.968"],["352.88","0.000"],["352.98","0.000"],["353.51","187.847"],["353.53","0.000"]]}}
1618677469.894918: {"stream":"yfiusdt@depth@100ms","data":{"e":"depthUpdate","E":1618677469836,"T":1618677469743,"s":"YFIUSDT","U":335341254740,"u":335341255082,"pu":335341252618,"b":[["49948.7","0.000"],["49975.7","0.009"]],"a":[]}}
1618677469.902024: {"stream":"ksmusdt@depth@100ms","data":{"e":"depthUpdate","E":1618677469841,"T":1618677469789,"s":"KSMUSDT","U":335341254904,"u":335341256551,"pu":335341254305,"b":[["451.816","22.1"],["454.753","3.9"],["456.818","3.9"]],"a":[["459.985","1.0"],["460.947","3.9"],["463.012","3.9"],["465.927","21.5"],["465.952","43.1"]]}}
1618677469.91791: {"stream":"dentusdt@depth@100ms","data":{"e":"depthUpdate","E":1618677469860,"T":1618677469851,"s":"DENTUSDT","U":335341255473,"u":335341258392,"pu":335341254342,"b":[["0.012180","83048"],["0.012264","106683"],["0.012274","444250"],["0.012286","10186"],["0.012346","40478"]],"a":[["0.012359","9494"],["0.012421","226532"],["0.012426","0"],["0.012437","12945"]]}}
1618677469.981588: {"stream":"xmrusdt@depth@100ms","data":{"e":"depthUpdate","E":1618677469917,"T":1618677469912,"s":"XMRUSDT","U":335341257142,"u":335341260590,"pu":335341256731,"b":[["352.11","7.917"],["352.25","0.000"],["352.27","2.500"]],"a":[["352.54","0.000"],["352.55","0.000"],["352.56","0.000"],["352.57","0.001"],["352.60","2.895"],["352.62","5.064"],["352.68","30.368"],["354.57","0.208"],["356.19","0.000"]]}}
1618677470.023595: {"stream":"ksmusdt@depth@100ms","data":{"e":"depthUpdate","E":1618677469964,"T":1618677469959,"s":"KSMUSDT","U":335341258727,"u":335341262288,"pu":335341256551,"b":[["457.852","31.1"],["458.211","5.9"]],"a":[["459.097","0.0"],["459.245","1.0"],["459.246","3.2"],["459.587","0.0"],["459.985","0.0"],["460.065","0.0"]]}}
1618677470.0536718: {"stream":"yfiusdt@depth@100ms","data":{"e":"depthUpdate","E":1618677469992,"T":1618677469980,"s":"YFIUSDT","U":335341259792,"u":335341263014,"pu":335341255082,"b":[["49734.5","0.001"],["49736.2","0.000"],["49980.7","0.032"]],"a":[["50038.1","0.032"],["50228.7","0.001"],["50239.6","0.001"],["50241.3","0.000"]]}}
1618677470.067402: {"stream":"dentusdt@depth@100ms","data":{"e":"depthUpdate","E":1618677470002,"T":1618677469997,"s":"DENTUSDT","U":335341260123,"u":335341263613,"pu":335341258392,"b":[["0.012265","153430"],["0.012267","134908"],["0.012290","128840"]],"a":[["0.012398","285912"],["0.012418","996322"],["0.012420","97636"]]}}
1618677470.083025: {"stream":"xmrusdt@depth@100ms","data":{"e":"depthUpdate","E":1618677470022,"T":1618677469999,"s":"XMRUSDT","U":335341260943,"u":335341263688,"pu":335341260590,"b":[["348.00","200.000"],["348.63","200.000"],["349.69","7.088"],["350.32","50.557"],["352.02","3.916"],["352.19","2.500"],["352.27","0.000"]],"a":[["352.57","1.401"],["354.59","5.933"],["356.23","200.015"]]}}
1618677470.090108: {"stream":"xmrusdt@kline_1m","data":{"e":"kline","E":1618677470028,"s":"XMRUSDT","k":{"t":1618677420000,"T":1618677479999,"s":"XMRUSDT","i":"1m","f":34692938,"L":34692978,"o":"352.86","c":"352.47","h":"352.93","l":"352.40","v":"34.856","n":41,"x":false,"q":"12290.86366","V":"3.692","Q":"1301.87303","B":"0"}}}
1618677470.097186: {"stream":"xmrusdt@bookTicker","data":{"e":"bookTicker","u":335341264581,"s":"XMRUSDT","b":"352.45","B":"0.024","a":"352.53","A":"0.073","T":1618677470024,"E":1618677470028}}
1618677470.09729: {"stream":"yfiusdt@bookTicker","data":{"e":"bookTicker","u":335341264642,"s":"YFIUSDT","b":"49990.1","B":"0.023","a":"50013.7","A":"0.002","T":1618677470026,"E":1618677470030}}
1618677470.1045399: {"stream":"yfiusdt@bookTicker","data":{"e":"bookTicker","u":335341265082,"s":"YFIUSDT","b":"49990.1","B":"0.096","a":"50013.7","A":"0.002","T":1618677470038,"E":1618677470042}}
1618677470.121614: {"stream":"yfiusdt@bookTicker","data":{"e":"bookTicker","u":335341265555,"s":"YFIUSDT","b":"49990.1","B":"0.073","a":"50013.7","A":"0.002","T":1618677470051,"E":1618677470056}}
1618677470.1217148: {"stream":"yfiusdt@bookTicker","data":{"e":"bookTicker","u":335341265567,"s":"YFIUSDT","b":"49990.2","B":"0.039","a":"50013.7","A":"0.002","T":1618677470051,"E":1618677470056}}
1618677470.243082: {"stream":"ksmusdt@depth@100ms","data":{"e":"depthUpdate","E":1618677470064,"T":1618677470058,"s":"KSMUSDT","U":335341262329,"u":335341265807,"pu":335341262288,"b":[["456.835","0.0"],["457.329","1.1"],["457.405","1.1"],["457.503","0.0"],["457.977","4.8"],["458.016","0.5"],["458.082","0.0"],["458.673","0.0"]],"a":[["459.244","1.6"],["459.247","0.0"],["459.343","0.0"],["459.533","0.0"],["459.539","0.2"],["459.584","0.4"],["459.761","2.7"],["460.096","0.0"],["460.273","1.1"],["460.279","0.0"],["463.410","0.0"],["464.533","0.0"]]}}
1618677470.243465: {"stream":"ksmusdt@bookTicker","data":{"e":"bookTicker","u":335341265970,"s":"KSMUSDT","b":"458.698","B":"1.2","a":"459.041","A":"0.2","T":1618677470063,"E":1618677470067}}
1618677470.249917: {"stream":"yfiusdt@bookTicker","data":{"e":"bookTicker","u":335341266195,"s":"YFIUSDT","b":"49990.2","B":"0.039","a":"50016.5","A":"0.006","T":1618677470069,"E":1618677470073}}
1618677470.250015: {"stream":"yfiusdt@bookTicker","data":{"e":"bookTicker","u":335341266202,"s":"YFIUSDT","b":"49990.3","B":"0.002","a":"50016.5","A":"0.006","T":1618677470069,"E":1618677470073}}
1618677470.250058: {"stream":"yfiusdt@bookTicker","data":{"e":"bookTicker","u":335341266671,"s":"YFIUSDT","b":"49990.4","B":"0.036","a":"50016.5","A":"0.006","T":1618677470083,"E":1618677470087}}
1618677470.250089: {"stream":"yfiusdt@depth@100ms","data":{"e":"depthUpdate","E":1618677470096,"T":1618677470083,"s":"YFIUSDT","U":335341263432,"u":335341266671,"pu":335341263014,"b":[["49930.3","0.060"],["49942.2","0.110"],["49944.1","0.000"],["49967.4","0.000"],["49970.3","0.000"],["49973.2","0.224"],["49982.1","0.000"],["49982.3","0.016"],["49985.3","0.013"],["49987.0","0.000"],["49987.9","0.000"],["49988.0","0.000"],["49990.0","0.000"],["49990.1","0.073"],["49990.2","0.000"],["49990.3","0.002"],["49990.4","0.036"]],"a":[["50013.7","0.000"],["50019.5","0.002"],["50019.6","0.000"],["50022.5","0.013"],["50038.0","0.007"],["50096.5","0.000"],["50119.5","0.077"]]}}
1618677470.2504241: {"stream":"ksmusdt@bookTicker","data":{"e":"bookTicker","u":335341267212,"s":"KSMUSDT","b":"458.699","B":"0.2","a":"459.041","A":"0.2","T":1618677470101,"E":1618677470105}}
1618677470.250489: {"stream":"yfiusdt@bookTicker","data":{"e":"bookTicker","u":335341267288,"s":"YFIUSDT","b":"49990.5","B":"0.002","a":"50016.5","A":"0.006","T":1618677470104,"E":1618677470108}}
1618677470.2548091: {"stream":"xmrusdt@depth@100ms","data":{"e":"depthUpdate","E":1618677470128,"T":1618677470120,"s":"XMRUSDT","U":335341264581,"u":335341267572,"pu":335341263688,"b":[["348.00","0.000"],["348.63","0.000"],["351.53","3.476"],["352.14","1.000"],["352.16","26.174"],["352.19","0.000"],["352.25","1.450"],["352.30","2.500"]],"a":[["352.47","0.000"],["352.56","2.894"],["352.57","1.899"],["352.59","0.000"],["352.60","0.000"],["352.61","1.063"],["352.82","0.468"],["353.72","4.400"],["356.23","0.015"],["383.50","0.000"]]}}
1618677470.255123: {"stream":"xmrusdt@bookTicker","data":{"e":"bookTicker","u":335341267637,"s":"XMRUSDT","b":"352.44","B":"3.700","a":"352.53","A":"0.073","T":1618677470126,"E":1618677470134}}
1618677470.2551758: {"stream":"xmrusdt@bookTicker","data":{"e":"bookTicker","u":335341267724,"s":"XMRUSDT","b":"352.49","B":"0.024","a":"352.53","A":"0.073","T":1618677470134,"E":1618677470138}}
1618677470.259209: {"stream":"dentusdt@depth@100ms","data":{"e":"depthUpdate","E":1618677470142,"T":1618677470118,"s":"DENTUSDT","U":335341265075,"u":335341267547,"pu":335341263613,"b":[["0.011900","185456"],["0.012190","819"],["0.012271","92055"],["0.012290","88204"]],"a":[["0.012420","57781"],["0.012421","146828"],["0.012428","37252"]]}}
1618677470.259407: {"stream":"yfiusdt@bookTicker","data":{"e":"bookTicker","u":335341267880,"s":"YFIUSDT","b":"49990.6","B":"0.036","a":"50016.5","A":"0.006","T":1618677470147,"E":1618677470151}}
1618677470.259458: {"stream":"ksmusdt@depth@100ms","data":{"e":"depthUpdate","E":1618677470164,"T":1618677470142,"s":"KSMUSDT","U":335341265890,"u":335341267783,"pu":335341265807,"b":[["449.706","0.0"],["453.727","0.0"],["458.601","7.7"],["458.696","0.0"],["458.698","1.2"],["458.699","0.2"]],"a":[["459.245","0.0"],["459.382","0.1"],["459.501","0.0"],["459.578","1.0"],["461.770","0.0"]]}}
1618677470.263097: {"stream":"xmrusdt@aggTrade","data":{"e":"aggTrade","E":1618677470179,"a":23619031,"s":"XMRUSDT","p":"352.47","q":"0.116","f":34692978,"l":34692978,"T":1618677470024,"m":false}}
1618677470.26647: {"stream":"yfiusdt@depth@100ms","data":{"e":"depthUpdate","E":1618677470197,"T":1618677470178,"s":"YFIUSDT","U":335341266951,"u":335341268461,"pu":335341266671,"b":[["49985.3","0.000"],["49986.6","0.013"],["49990.3","0.000"],["49990.4","0.000"],["49990.5","0.002"],["49990.6","0.036"]],"a":[["50085.9","0.000"],["50113.2","0.094"]]}}
1618677470.268706: {"stream":"yfiusdt@bookTicker","data":{"e":"bookTicker","u":335341269077,"s":"YFIUSDT","b":"49990.7","B":"0.002","a":"50016.5","A":"0.006","T":1618677470206,"E":1618677470210}}
1618677470.297924: {"stream":"xmrusdt@depth@100ms","data":{"e":"depthUpdate","E":1618677470234,"T":1618677470223,"s":"XMRUSDT","U":335341267637,"u":335341269453,"pu":335341267572,"b":[["349.82","200.000"],["350.45","200.000"],["351.51","1.000"],["352.11","4.951"],["352.12","0.000"],["352.16","2.966"],["352.17","1.598"],["352.45","0.000"],["352.49","0.024"]],"a":[["352.55","1.008"],["352.67","0.000"],["352.68","2.753"],["352.83","0.000"],["352.90","10.418"],["352.98","0.000"],["353.60","0.000"],["353.72","1.900"],["353.89","5.150"],["354.59","205.933"]]}}
1618677470.2982469: {"stream":"yfiusdt@bookTicker","data":{"e":"bookTicker","u":335341269752,"s":"YFIUSDT","b":"49990.8","B":"0.037","a":"50016.5","A":"0.006","T":1618677470231,"E":1618677470234}}
1618677470.30306: {"stream":"yfiusdt@bookTicker","data":{"e":"bookTicker","u":335341269925,"s":"YFIUSDT","b":"49992.7","B":"0.055","a":"50016.5","A":"0.006","T":1618677470233,"E":1618677470237}}
1618677470.311302: {"stream":"ksmusdt@bookTicker","data":{"e":"bookTicker","u":335341270410,"s":"KSMUSDT","b":"458.730","B":"1.2","a":"459.041","A":"0.2","T":1618677470246,"E":1618677470251}}
1618677470.311832: {"stream":"yfiusdt@bookTicker","data":{"e":"bookTicker","u":335341270677,"s":"YFIUSDT","b":"49992.8","B":"0.038","a":"50016.5","A":"0.006","T":1618677470252,"E":1618677470255}}
1618677470.330414: {"stream":"yfiusdt@bookTicker","data":{"e":"bookTicker","u":335341271213,"s":"YFIUSDT","b":"49992.7","B":"0.055","a":"50016.5","A":"0.006","T":1618677470262,"E":1618677470266}}
1618677470.336077: {"stream":"yfiusdt@bookTicker","data":{"e":"bookTicker","u":335341271368,"s":"YFIUSDT","b":"49992.9","B":"0.002","a":"50016.5","A":"0.006","T":1618677470266,"E":1618677470270}}
1618677470.347883: {"stream":"dentusdt@depth@100ms","data":{"e":"depthUpdate","E":1618677470281,"T":1618677470270,"s":"DENTUSDT","U":335341268197,"u":335341271526,"pu":335341267547,"b":[["0.012271","43648"],["0.012286","2128"],["0.012290","47568"],["0.012326","30077"],["0.012329","62731"],["0.012330","180868"],["0.012342","0"]],"a":[["0.012418","956461"],["0.012421","138858"],["0.012424","75198"]]}}
1618677470.348106: {"stream":"yfiusdt@bookTicker","data":{"e":"bookTicker","u":335341271780,"s":"YFIUSDT","b":"49993.0","B":"0.040","a":"50016.5","A":"0.006","T":1618677470277,"E":1618677470282}}
1618677470.35234: {"stream":"yfiusdt@bookTicker","data":{"e":"bookTicker","u":335341271924,"s":"YFIUSDT","b":"49995.3","B":"0.055","a":"50016.5","A":"0.006","T":1618677470281,"E":1618677470286}}
1618677470.352441: {"stream":"ksmusdt@bookTicker","data":{"e":"bookTicker","u":335341272052,"s":"KSMUSDT","b":"458.731","B":"0.2","a":"459.041","A":"0.2","T":1618677470285,"E":1618677470289}}
1618677470.362624: {"stream":"yfiusdt@depth@100ms","data":{"e":"depthUpdate","E":1618677470304,"T":1618677470295,"s":"YFIUSDT","U":335341268672,"u":335341272479,"pu":335341268461,"b":[["49941.3","0.000"],["49944.5","0.000"],["49945.4","0.000"],["49947.5","0.013"],["49949.2","0.000"],["49950.6","0.013"],["49951.5","0.013"],["49973.1","0.000"],["49975.8","0.271"],["49986.9","0.000"],["49989.9","0.000"],["49990.5","0.000"],["49990.6","0.000"],["49990.7","0.000"],["49990.8","0.000"],["49992.7","0.055"],["49992.8","0.000"],["49992.9","0.002"],["49993.0","0.000"],["49993.2","0.040"],["49995.3","0.055"]],"a":[["50038.1","0.000"],["50040.2","0.000"],["50055.6","0.088"],["50078.9","0.005"],["50105.3","0.060"]]}}
1618677470.363534: {"stream":"ksmusdt@bookTicker","data":{"e":"bookTicker","u":335341272707,"s":"KSMUSDT","b":"458.734","B":"1.2","a":"459.041","A":"0.2","T":1618677470301,"E":1618677470305}}
1618677470.367306: {"stream":"yfiusdt@bookTicker","data":{"e":"bookTicker","u":335341272778,"s":"YFIUSDT","b":"49995.4","B":"0.002","a":"50016.5","A":"0.006","T":1618677470302,"E":1618677470307}}
1618677470.367405: {"stream":"ksmusdt@depth@100ms","data":{"e":"depthUpdate","E":1618677470309,"T":1618677470301,"s":"KSMUSDT","U":335341268968,"u":335341272707,"pu":335341267783,"b":[["453.721","20.0"],["457.649","0.0"],["458.606","0.0"],["458.698","0.0"],["458.699","0.0"],["458.730","0.0"],["458.731","0.2"],["458.734","1.2"]],"a":[["459.092","0.0"],["459.096","0.2"],["459.132","1.2"],["459.432","0.0"],["459.468","0.1"],["459.469","0.0"],["460.177","1.9"],["461.767","19.6"]]}}
1618677470.3961868: {"stream":"xmrusdt@depth@100ms","data":{"e":"depthUpdate","E":1618677470336,"T":1618677470329,"s":"XMRUSDT","U":335341269855,"u":335341273678,"pu":335341269453,"b":[["349.51","17.836"],["352.03","2.966"],["352.36","0.000"]],"a":[["352.54","2.958"],["352.56","0.000"],["352.57","0.001"],["352.58","0.000"],["352.69","43.479"],["352.70","0.000"],["352.90","7.918"],["353.13","2.500"],["353.21","0.000"],["353.79","0.000"],["353.84","3.103"],["355.82","294.628"],["359.05","44.290"]]}}
1618677470.403132: {"stream":"ksmusdt@bookTicker","data":{"e":"bookTicker","u":335341273759,"s":"KSMUSDT","b":"458.735","B":"0.2","a":"459.041","A":"0.2","T":1618677470331,"E":1618677470336}}
1618677470.4032362: {"stream":"ksmusdt@bookTicker","data":{"e":"bookTicker","u":335341273767,"s":"KSMUSDT","b":"458.735","B":"0.2","a":"459.096","A":"0.2","T":1618677470331,"E":1618677470336}}
1618677470.412525: {"stream":"ksmusdt@bookTicker","data":{"e":"bookTicker","u":335341274142,"s":"KSMUSDT","b":"458.746","B":"1.2","a":"459.096","A":"0.2","T":1618677470344,"E":1618677470348}}
1618677470.433866: {"stream":"ksmusdt@bookTicker","data":{"e":"bookTicker","u":335341274981,"s":"KSMUSDT","b":"458.747","B":"0.2","a":"459.096","A":"0.2","T":1618677470366,"E":1618677470371}}
1618677470.443569: {"stream":"ksmusdt@bookTicker","data":{"e":"bookTicker","u":335341275425,"s":"KSMUSDT","b":"458.755","B":"1.2","a":"459.096","A":"0.2","T":1618677470379,"E":1618677470384}}
1618677470.4436722: {"stream":"dentusdt@depth@100ms","data":{"e":"depthUpdate","E":1618677470386,"T":1618677470375,"s":"DENTUSDT","U":335341271958,"u":335341275291,"pu":335341271526,"b":[["0.012293","8053"],["0.012325","597683"]],"a":[]}}
1618677470.467257: {"stream":"yfiusdt@depth@100ms","data":{"e":"depthUpdate","E":1618677470405,"T":1618677470394,"s":"YFIUSDT","U":335341272666,"u":335341275982,"pu":335341272479,"b":[["49594.7","0.008"],["49907.8","0.017"],["49933.8","0.000"],["49938.0","0.000"],["49945.2","0.000"],["49946.4","0.110"],["49950.6","0.123"],["49951.1","0.000"],["49951.8","0.049"],["49956.1","0.000"],["49957.6","0.013"],["49962.6","0.013"],["49973.2","0.000"],["49975.8","0.439"],["49980.7","0.000"],["49984.7","0.032"],["49992.7","0.000"],["49992.9","0.000"],["49993.2","0.000"],["49995.4","0.002"]],"a":[["50038.0","0.000"],["50042.4","0.032"]]}}
1618677470.472681: {"stream":"ksmusdt@bookTicker","data":{"e":"bookTicker","u":335341276441,"s":"KSMUSDT","b":"458.756","B":"0.2","a":"459.096","A":"0.2","T":1618677470405,"E":1618677470410}}
1618677470.4799051: {"stream":"ksmusdt@bookTicker","data":{"e":"bookTicker","u":335341276453,"s":"KSMUSDT","b":"458.756","B":"0.2","a":"458.922","A":"0.1","T":1618677470405,"E":1618677470413}}
1618677470.482507: {"stream":"ksmusdt@bookTicker","data":{"e":"bookTicker","u":335341276908,"s":"KSMUSDT","b":"458.757","B":"1.2","a":"458.922","A":"0.1","T":1618677470418,"E":1618677470422}}
1618677470.482608: {"stream":"ksmusdt@bookTicker","data":{"e":"bookTicker","u":335341276966,"s":"KSMUSDT","b":"458.756","B":"0.2","a":"458.922","A":"0.1","T":1618677470420,"E":1618677470424}}
1618677470.486103: {"stream":"ksmusdt@depth@100ms","data":{"e":"depthUpdate","E":1618677470427,"T":1618677470421,"s":"KSMUSDT","U":335341273510,"u":335341277000,"pu":335341272707,"b":[["449.699","19.8"],["457.718","0.0"],["457.976","0.0"],["457.978","1.1"],["458.726","1.2"],["458.731","0.0"],["458.734","0.0"],["458.735","0.0"],["458.746","0.0"],["458.747","0.0"],["458.755","0.0"],["458.756","0.2"],["458.757","0.0"]],"a":[["458.922","0.1"],["459.041","0.0"],["459.096","0.0"],["459.131","0.2"],["459.132","0.0"],["459.243","1.2"],["459.245","1.3"],["459.557","0.0"],["459.578","0.0"],["459.793","2.1"],["460.159","0.0"],["460.471","5.9"]]}}
1618677470.492321: {"stream":"ksmusdt@bookTicker","data":{"e":"bookTicker","u":335341277311,"s":"KSMUSDT","b":"458.726","B":"1.2","a":"458.922","A":"0.1","T":1618677470429,"E":1618677470432}}
1618677470.4924228: {"stream":"ksmusdt@bookTicker","data":{"e":"bookTicker","u":335341277320,"s":"KSMUSDT","b":"458.758","B":"0.2","a":"458.922","A":"0.1","T":1618677470429,"E":1618677470434}}
1618677470.5134761: {"stream":"xmrusdt@depth@100ms","data":{"e":"depthUpdate","E":1618677470451,"T":1618677470442,"s":"XMRUSDT","U":335341274216,"u":335341277631,"pu":335341273678,"b":[],"a":[["352.54","0.000"],["352.55","0.000"],["352.59","0.482"],["352.60","3.088"],["352.81","0.000"],["352.87","2.500"],["352.88","0.000"],["352.94","0.612"],["352.95","0.000"],["352.98","32.694"],["353.13","0.000"],["382.68","52.190"]]}}
1618677470.51718: {"stream":"dentusdt@aggTrade","data":{"e":"aggTrade","E":1618677470456,"a":8476441,"s":"DENTUSDT","p":"0.012346","q":"40478","f":15787442,"l":15787442,"T":1618677470452,"m":true}}
1618677470.517316: {"stream":"dentusdt@aggTrade","data":{"e":"aggTrade","E":1618677470456,"a":8476442,"s":"DENTUSDT","p":"0.012345","q":"111139","f":15787443,"l":15787447,"T":1618677470452,"m":true}}
1618677470.517364: {"stream":"dentusdt@bookTicker","data":{"e":"bookTicker","u":335341277925,"s":"DENTUSDT","b":"0.012344","B":"6098","a":"0.012359","A":"9494","T":1618677470452,"E":1618677470457}}
1618677470.5174038: {"stream":"dentusdt@kline_1m","data":{"e":"kline","E":1618677470457,"s":"DENTUSDT","k":{"t":1618677420000,"T":1618677479999,"s":"DENTUSDT","i":"1m","f":15787262,"L":15787442,"o":"0.012366","c":"0.012346","h":"0.012366","l":"0.012339","v":"2801434","n":181,"x":false,"q":"34603.208296","V":"1266681","Q":"15650.248000","B":"0"}}}
1618677470.535742: {"stream":"dentusdt@bookTicker","data":{"e":"bookTicker","u":335341278599,"s":"DENTUSDT","b":"0.012343","B":"217028","a":"0.012359","A":"9494","T":1618677470468,"E":1618677470473}}
1618677470.568258: {"stream":"dentusdt@bookTicker","data":{"e":"bookTicker","u":335341279610,"s":"DENTUSDT","b":"0.012346","B":"13444","a":"0.012359","A":"9494","T":1618677470503,"E":1618677470508}}
1618677470.5720818: {"stream":"dentusdt@bookTicker","data":{"e":"bookTicker","u":335341279768,"s":"DENTUSDT","b":"0.012346","B":"26888","a":"0.012359","A":"9494","T":1618677470507,"E":1618677470510}}
1618677470.582817: {"stream":"yfiusdt@depth@100ms","data":{"e":"depthUpdate","E":1618677470519,"T":1618677470513,"s":"YFIUSDT","U":335341276838,"u":335341279945,"pu":335341275982,"b":[["49558.8","0.083"],["49565.1","0.000"],["49783.8","0.083"],["49790.2","0.000"],["49850.6","0.000"],["49982.4","0.013"],["49986.6","0.000"]],"a":[["50020.0","0.013"],["50022.5","0.000"],["50108.1","0.000"],["50115.7","0.000"],["50233.8","0.083"],["50240.3","0.001"],["50458.8","0.083"],["50465.3","0.000"],["51210.7","0.000"]]}}
1618677470.592842: {"stream":"ksmusdt@depth@100ms","data":{"e":"depthUpdate","E":1618677470532,"T":1618677470505,"s":"KSMUSDT","U":335341277311,"u":335341279684,"pu":335341277000,"b":[["457.978","1.1"],["458.756","0.0"],["458.758","0.2"]],"a":[["459.116","0.2"],["459.117","1.2"],["459.131","0.0"],["459.212","1.6"],["459.243","0.2"],["459.244","0.0"],["459.578","1.0"],["463.236","0.9"]]}}
1618677470.594846: {"stream":"dentusdt@bookTicker","data":{"e":"bookTicker","u":335341280452,"s":"DENTUSDT","b":"0.012346","B":"26888","a":"0.012359","A":"103942","T":1618677470530,"E":1618677470535}}
1618677470.6099892: {"stream":"xmrusdt@depth@100ms","data":{"e":"depthUpdate","E":1618677470552,"T":1618677470539,"s":"XMRUSDT","U":335341277816,"u":335341280693,"pu":335341277631,"b":[["351.51","0.000"],["351.58","3.000"],["352.14","0.000"],["352.21","3.000"]],"a":[["352.57","0.483"],["352.58","2.962"],["352.59","0.000"],["352.60","0.000"],["352.81","0.000"],["352.87","0.000"],["352.88","2.500"],["352.93","0.000"]]}}
1618677470.617347: {"stream":"dentusdt@depth@100ms","data":{"e":"depthUpdate","E":1618677470557,"T":1618677470551,"s":"DENTUSDT","U":335341277893,"u":335341281018,"pu":335341275291,"b":[["0.000011","20805663"],["0.012323","1556"],["0.012324","164816"],["0.012325","621970"],["0.012329","5171"],["0.012330","224317"],["0.012332","287483"],["0.012338","217028"],["0.012339","16945"],["0.012340","40500"],["0.012344","0"],["0.012345","0"],["0.012346","26888"]],"a":[["0.012359","103942"],["0.012361","57426"],["0.012364","65196"],["0.012365","133881"],["0.012366","53977"],["0.012367","57938"],["0.012368","146130"],["0.012371","471215"],["0.012378","404875"],["0.012380","728696"],["0.012383","76103"],["0.012387","35168"]]}}
1618677470.664429: {"stream":"dentusdt@aggTrade","data":{"e":"aggTrade","E":1618677470607,"a":8476443,"s":"DENTUSDT","p":"0.012344","q":"142475","f":15787448,"l":15787450,"T":1618677470452,"m":true}}
1618677470.66486: {"stream":"dentusdt@bookTicker","data":{"e":"bookTicker","u":335341282378,"s":"DENTUSDT","b":"0.012346","B":"26888","a":"0.012358","A":"3456","T":1618677470603,"E":1618677470608}}
1618677470.679321: {"stream":"dentusdt@bookTicker","data":{"e":"bookTicker","u":335341282623,"s":"DENTUSDT","b":"0.012346","B":"26888","a":"0.012357","A":"9470","T":1618677470615,"E":1618677470619}}
1618677470.687395: {"stream":"yfiusdt@depth@100ms","data":{"e":"depthUpdate","E":1618677470630,"T":1618677470573,"s":"YFIUSDT","U":335341280365,"u":335341281643,"pu":335341279945,"b":[["49854.0","0.000"],["49890.2","0.020"],["49907.8","0.000"]],"a":[["50115.6","0.010"]]}}
1618677470.687605: {"stream":"yfiusdt@bookTicker","data":{"e":"bookTicker","u":335341282884,"s":"YFIUSDT","b":"49995.4","B":"0.002","a":"50006.0","A":"0.001","T":1618677470625,"E":1618677470630}}
1618677470.699627: {"stream":"yfiusdt@bookTicker","data":{"e":"bookTicker","u":335341283100,"s":"YFIUSDT","b":"49996.7","B":"0.012","a":"50006.0","A":"0.001","T":1618677470635,"E":1618677470639}}
1618677470.702603: {"stream":"yfiusdt@bookTicker","data":{"e":"bookTicker","u":335341283136,"s":"YFIUSDT","b":"49996.7","B":"0.012","a":"50019.5","A":"0.002","T":1618677470636,"E":1618677470641}}
1618677470.702703: {"stream":"yfiusdt@kline_1m","data":{"e":"kline","E":1618677470642,"s":"YFIUSDT","k":{"t":1618677420000,"T":1618677479999,"s":"YFIUSDT","i":"1m","f":64902095,"L":64902195,"o":"50010.8","c":"50006.0","h":"50044.2","l":"49950.6","v":"1.114","n":101,"x":false,"q":"55698.6987","V":"0.796","Q":"39799.3945","B":"0"}}}
1618677470.704779: {"stream":"ksmusdt@depth@100ms","data":{"e":"depthUpdate","E":1618677470646,"T":1618677470638,"s":"KSMUSDT","U":335341280747,"u":335341283197,"pu":335341279684,"b":[["457.975","0.0"],["457.977","0.0"],["457.978","0.0"],["458.244","18.0"],["458.696","1.1"]],"a":[["458.975","0.1"],["459.115","1.2"],["459.117","0.0"],["459.212","0.0"],["459.242","1.6"],["459.907","10.2"],["460.577","0.0"],["462.845","1.0"]]}}
1618677470.712082: {"stream":"xmrusdt@bookTicker","data":{"e":"bookTicker","u":335341283453,"s":"XMRUSDT","b":"352.44","B":"3.700","a":"352.53","A":"0.073","T":1618677470647,"E":1618677470651}}
1618677470.7166421: {"stream":"xmrusdt@depth@100ms","data":{"e":"depthUpdate","E":1618677470658,"T":1618677470650,"s":"XMRUSDT","U":335341281119,"u":335341283540,"pu":335341280693,"b":[["347.84","200.000"],["348.47","200.000"],["349.82","0.000"],["350.45","0.000"],["351.80","0.864"],["351.88","1.578"],["352.49","0.000"]],"a":[["352.81","2.500"],["352.88","0.000"],["352.97","0.000"],["352.98","0.000"],["354.18","2.425"]]}}
1618677470.724326: {"stream":"ksmusdt@bookTicker","data":{"e":"bookTicker","u":335341283847,"s":"KSMUSDT","b":"458.780","B":"6.4","a":"458.922","A":"0.1","T":1618677470664,"E":1618677470667}}
1618677470.7265768: {"stream":"yfiusdt@bookTicker","data":{"e":"bookTicker","u":335341283900,"s":"YFIUSDT","b":"49996.7","B":"0.012","a":"50006.0","A":"0.032","T":1618677470665,"E":1618677470669}}
1618677470.726677: {"stream":"dentusdt@depth@100ms","data":{"e":"depthUpdate","E":1618677470670,"T":1618677470663,"s":"DENTUSDT","U":335341281378,"u":335341283810,"pu":335341281018,"b":[["0.012275","484047"],["0.012330","185570"],["0.012333","13492"],["0.012339","3446"]],"a":[["0.012357","9470"],["0.012358","3456"],["0.012359","0"],["0.012360","22537"],["0.012361","0"],["0.012362","48575"],["0.012363","456562"],["0.012365","0"],["0.012366","0"],["0.012367","0"],["0.012404","0"],["0.012409","152260"]]}}
1618677470.73045: {"stream":"yfiusdt@bookTicker","data":{"e":"bookTicker","u":335341283988,"s":"YFIUSDT","b":"49996.8","B":"0.002","a":"50006.0","A":"0.032","T":1618677470668,"E":1618677470672}}
1618677470.741225: {"stream":"xmrusdt@bookTicker","data":{"e":"bookTicker","u":335341284227,"s":"XMRUSDT","b":"352.48","B":"0.024","a":"352.53","A":"0.073","T":1618677470677,"E":1618677470681}}
1618677470.741323: {"stream":"yfiusdt@bookTicker","data":{"e":"bookTicker","u":335341284226,"s":"YFIUSDT","b":"49999.2","B":"0.055","a":"50006.0","A":"0.032","T":1618677470677,"E":1618677470681}}
1618677470.741367: {"stream":"yfiusdt@bookTicker","data":{"e":"bookTicker","u":335341284239,"s":"YFIUSDT","b":"49999.2","B":"0.055","a":"50006.0","A":"0.016","T":1618677470677,"E":1618677470682}}
1618677470.755409: {"stream":"yfiusdt@bookTicker","data":{"e":"bookTicker","u":335341284543,"s":"YFIUSDT","b":"49999.2","B":"0.055","a":"50006.0","A":"0.001","T":1618677470689,"E":1618677470695}}
1618677470.755509: {"stream":"yfiusdt@bookTicker","data":{"e":"bookTicker","u":335341284551,"s":"YFIUSDT","b":"49999.2","B":"0.055","a":"50019.5","A":"0.002","T":1618677470689,"E":1618677470695}}
1618677470.762712: {"stream":"yfiusdt@bookTicker","data":{"e":"bookTicker","u":335341284855,"s":"YFIUSDT","b":"50000.5","B":"0.012","a":"50019.5","A":"0.002","T":1618677470699,"E":1618677470704}}
1618677470.7681332: {"stream":"ksmusdt@bookTicker","data":{"e":"bookTicker","u":335341284987,"s":"KSMUSDT","b":"458.781","B":"0.2","a":"458.922","A":"0.1","T":1618677470706,"E":1618677470711}}
1618677470.768234: {"stream":"yfiusdt@bookTicker","data":{"e":"bookTicker","u":335341284989,"s":"YFIUSDT","b":"50000.5","B":"0.012","a":"50023.6","A":"0.013","T":1618677470706,"E":1618677470711}}
1618677470.7884102: {"stream":"yfiusdt@depth@100ms","data":{"e":"depthUpdate","E":1618677470730,"T":1618677470720,"s":"YFIUSDT","U":335341282884,"u":335341285418,"pu":335341281643,"b":[["49402.4","0.022"],["49616.9","0.009"],["49711.4","0.004"],["49818.1","0.003"],["49923.7","0.000"],["49936.4","0.000"],["49942.2","0.000"],["49947.5","0.000"],["49950.6","0.110"],["49951.5","0.000"],["49954.0","0.013"],["49954.8","0.110"],["49957.1","0.013"],["49958.0","0.013"],["49961.8","0.080"],["49974.5","0.080"],["49975.8","0.271"],["49975.9","0.000"],["49982.3","0.000"],["49984.7","0.000"],["49995.4","0.000"],["49996.7","0.000"],["49996.8","0.000"],["49998.1","0.000"],["49999.2","0.055"],["49999.3","0.002"],["50000.5","0.012"]],"a":[["50006.0","0.000"],["50016.5","0.000"],["50019.5","0.000"],["50020.0","0.000"],["50023.6","0.013"],["50031.6","0.002"],["50042.4","0.000"],["50055.6","0.000"],["50097.8","0.068"]]}}
1618677470.802942: {"stream":"yfiusdt@bookTicker","data":{"e":"bookTicker","u":335341285983,"s":"YFIUSDT","b":"50000.6","B":"0.002","a":"50023.6","A":"0.013","T":1618677470742,"E":1618677470745}}
1618677470.816672: {"stream":"xmrusdt@depth@100ms","data":{"e":"depthUpdate","E":1618677470759,"T":1618677470754,"s":"XMRUSDT","U":335341283671,"u":335341286375,"pu":335341283540,"b":[["347.84","0.000"],["348.47","0.000"],["349.86","200.080"],["350.49","208.323"],["352.28","3.947"],["352.36","0.000"],["352.48","0.024"]],"a":[["352.81","0.000"],["352.88","0.000"],["352.90","10.418"],["352.98","0.000"],["353.04","15.462"],["355.84","1.363"]]}}
1618677470.822196: {"stream":"ksmusdt@depth@100ms","data":{"e":"depthUpdate","E":1618677470765,"T":1618677470744,"s":"KSMUSDT","U":335341283789,"u":335341286047,"pu":335341283197,"b":[["455.410","0.1"],["455.612","0.0"],["457.131","0.1"],["457.334","0.0"],["457.878","2.2"],["457.912","1.1"],["458.132","1.9"],["458.641","0.0"],["458.643","0.0"],["458.695","0.0"],["458.696","0.0"],["458.726","1.2"],["458.758","0.0"],["458.780","6.4"],["458.781","0.2"]],"a":[["459.114","0.0"],["459.115","0.0"],["459.116","0.0"],["459.134","1.2"],["459.212","0.2"],["459.578","1.0"],["460.571","0.1"],["460.667","2.8"],["460.775","0.0"],["462.292","0.1"],["462.497","0.0"]]}}
1618677470.827595: {"stream":"dentusdt@depth@100ms","data":{"e":"depthUpdate","E":1618677470770,"T":1618677470761,"s":"DENTUSDT","U":335341283931,"u":335341286588,"pu":335341283810,"b":[["0.012315","103582"],["0.012320","23116"],["0.012325","325096"]],"a":[["0.012359","148428"],["0.012363","590808"],["0.012364","119173"],["0.012365","57938"],["0.012800","342614"]]}}
1618677470.849858: {"stream":"yfiusdt@aggTrade","data":{"e":"aggTrade","E":1618677470792,"a":52599715,"s":"YFIUSDT","p":"50006.0","q":"0.033","f":64902195,"l":64902198,"T":1618677470636,"m":false}}
1618677470.876991: {"stream":"dentusdt@bookTicker","data":{"e":"bookTicker","u":335341287890,"s":"DENTUSDT","b":"0.012346","B":"26888","a":"0.012357","A":"49948","T":1618677470816,"E":1618677470819}}
1618677470.903272: {"stream":"yfiusdt@depth@100ms","data":{"e":"depthUpdate","E":1618677470845,"T":1618677470826,"s":"YFIUSDT","U":335341285975,"u":335341288102,"pu":335341285418,"b":[["49984.0","0.032"],["49995.3","0.000"],["49999.3","0.000"],["50000.6","0.002"]],"a":[["50043.4","0.032"],["50265.6","0.137"]]}}
1618677470.9352698: {"stream":"ksmusdt@depth@100ms","data":{"e":"depthUpdate","E":1618677470877,"T":1618677470857,"s":"KSMUSDT","U":335341286973,"u":335341288706,"pu":335341286047,"b":[["457.912","0.0"],["458.673","1.2"],["458.726","0.0"]],"a":[["459.132","0.2"],["459.133","1.6"],["459.134","0.0"],["459.212","0.0"],["459.242","0.0"],["459.578","1.0"],["460.157","6.0"]]}}
1618677470.93555: {"stream":"dentusdt@depth@100ms","data":{"e":"depthUpdate","E":1618677470877,"T":1618677470867,"s":"DENTUSDT","U":335341286906,"u":335341288969,"pu":335341286588,"b":[["0.012332","284245"]],"a":[["0.012357","49948"],["0.012358","57431"],["0.012359","0"],["0.012364","65196"],["0.012381","25641"],["0.012382","427168"],["0.012386","80874"],["0.012414","240525"],["0.012417","140072"],["0.012420","109791"],["0.012423","646513"]]}}
1618677470.9404979: {"stream":"yfiusdt@bookTicker","data":{"e":"bookTicker","u":335341289266,"s":"YFIUSDT","b":"50000.6","B":"0.002","a":"50012.1","A":"0.002","T":1618677470879,"E":1618677470882}}
1618677470.945725: {"stream":"xmrusdt@depth@100ms","data":{"e":"depthUpdate","E":1618677470889,"T":1618677470860,"s":"XMRUSDT","U":335341287201,"u":335341288764,"pu":335341286375,"b":[],"a":[["352.81","2.500"],["352.90","7.918"],["355.49","2.429"]]}}
1618677470.948193: {"stream":"yfiusdt@bookTicker","data":{"e":"bookTicker","u":335341289462,"s":"YFIUSDT","b":"50001.9","B":"0.012","a":"50012.1","A":"0.002","T":1618677470886,"E":1618677470890}}
1618677470.951205: {"stream":"dentusdt@bookTicker","data":{"e":"bookTicker","u":335341289509,"s":"DENTUSDT","b":"0.012346","B":"26888","a":"0.012357","A":"9470","T":1618677470888,"E":1618677470892}}
1618677470.951276: {"stream":"dentusdt@bookTicker","data":{"e":"bookTicker","u":335341289520,"s":"DENTUSDT","b":"0.012346","B":"26888","a":"0.012357","A":"63445","T":1618677470888,"E":1618677470892}}
1618677470.978761: {"stream":"ksmusdt@bookTicker","data":{"e":"bookTicker","u":335341290170,"s":"KSMUSDT","b":"458.781","B":"0.2","a":"458.975","A":"0.1","T":1618677470914,"E":1618677470920}}
1618677470.9830852: {"stream":"ksmusdt@bookTicker","data":{"e":"bookTicker","u":335341290292,"s":"KSMUSDT","b":"458.781","B":"0.2","a":"458.852","A":"0.1","T":1618677470919,"E":1618677470924}}
1618677470.9831538: {"stream":"yfiusdt@bookTicker","data":{"e":"bookTicker","u":335341290333,"s":"YFIUSDT","b":"50002.0","B":"0.002","a":"50012.1","A":"0.002","T":1618677470921,"E":1618677470926}}
1618677470.983999: {"stream":"ksmusdt@kline_1m","data":{"e":"kline","E":1618677470927,"s":"KSMUSDT","k":{"t":1618677420000,"T":1618677479999,"s":"KSMUSDT","i":"1m","f":25426460,"L":25426590,"o":"459.607","c":"458.852","h":"459.671","l":"458.391","v":"119.3","n":131,"x":false,"q":"54761.6147","V":"55.2","Q":"25348.3322","B":"0"}}}
1618677470.9864929: {"stream":"ksmusdt@aggTrade","data":{"e":"aggTrade","E":1618677470928,"a":21396996,"s":"KSMUSDT","p":"458.852","q":"0.1","f":25426590,"l":25426590,"T":1618677470923,"m":false}}
1618677470.986569: {"stream":"ksmusdt@bookTicker","data":{"e":"bookTicker","u":335341290375,"s":"KSMUSDT","b":"458.781","B":"0.2","a":"458.878","A":"3.7","T":1618677470923,"E":1618677470928}}
1618677470.989148: {"stream":"ksmusdt@bookTicker","data":{"e":"bookTicker","u":335341290429,"s":"KSMUSDT","b":"458.781","B":"0.2","a":"458.975","A":"0.1","T":1618677470925,"E":1618677470929}}
1618677470.994464: {"stream":"ksmusdt@bookTicker","data":{"e":"bookTicker","u":335341290590,"s":"KSMUSDT","b":"458.782","B":"1.0","a":"458.975","A":"0.1","T":1618677470931,"E":1618677470935}}
1618677470.998152: {"stream":"ksmusdt@bookTicker","data":{"e":"bookTicker","u":335341290701,"s":"KSMUSDT","b":"458.782","B":"7.5","a":"458.975","A":"0.1","T":1618677470936,"E":1618677470940}}
1618677471.005057: {"stream":"ksmusdt@bookTicker","data":{"e":"bookTicker","u":335341290845,"s":"KSMUSDT","b":"458.783","B":"0.2","a":"458.975","A":"0.1","T":1618677470943,"E":1618677470947}}
1618677471.008323: {"stream":"ksmusdt@bookTicker","data":{"e":"bookTicker","u":335341290994,"s":"KSMUSDT","b":"458.796","B":"1.2","a":"458.975","A":"0.1","T":1618677470948,"E":1618677470951}}
1618677471.0345569: {"stream":"ksmusdt@bookTicker","data":{"e":"bookTicker","u":335341291571,"s":"KSMUSDT","b":"458.797","B":"0.2","a":"458.975","A":"0.1","T":1618677470973,"E":1618677470977}}
1618677471.037411: {"stream":"dentusdt@depth@100ms","data":{"e":"depthUpdate","E":1618677470979,"T":1618677470932,"s":"DENTUSDT","U":335341289169,"u":335341290606,"pu":335341288969,"b":[["0.012135","695"]],"a":[["0.012357","63445"],["0.012358","10376"],["0.012359","94453"],["0.012364","119173"]]}}
1618677471.043808: {"stream":"yfiusdt@depth@100ms","data":{"e":"depthUpdate","E":1618677470982,"T":1618677470959,"s":"YFIUSDT","U":335341289266,"u":335341291269,"pu":335341288102,"b":[["49608.8","0.015"],["49737.4","0.009"],["50000.5","0.000"],["50000.6","0.000"],["50001.9","0.012"],["50002.0","0.002"]],"a":[["50012.1","0.002"],["50023.4","0.002"],["50023.5","0.055"],["50031.6","0.000"],["50131.8","0.400"]]}}
1618677471.046041: {"stream":"ksmusdt@bookTicker","data":{"e":"bookTicker","u":335341291818,"s":"KSMUSDT","b":"458.818","B":"6.4","a":"458.975","A":"0.1","T":1618677470981,"E":1618677470985}}
1618677471.0494652: {"stream":"ksmusdt@depth@100ms","data":{"e":"depthUpdate","E":1618677470990,"T":1618677470981,"s":"KSMUSDT","U":335341289464,"u":335341291818,"pu":335341288706,"b":[["457.912","0.0"],["458.601","0.0"],["458.673","0.0"],["458.781","0.0"],["458.782","7.5"],["458.783","0.0"],["458.796","1.2"],["458.797","0.2"],["458.818","6.4"]],"a":[["458.852","0.0"],["458.878","0.0"],["458.922","0.0"],["459.116","0.0"],["459.132","0.0"],["459.133","0.0"],["459.156","0.2"],["459.157","1.2"],["459.211","0.0"],["459.212","1.6"],["459.521","5.1"],["459.578","0.0"],["467.212","0.0"]]}}
1618677471.063154: {"stream":"yfiusdt@bookTicker","data":{"e":"bookTicker","u":335341292264,"s":"YFIUSDT","b":"50002.9","B":"0.055","a":"50012.1","A":"0.002","T":1618677471000,"E":1618677471004}}
1618677471.072726: {"stream":"yfiusdt@bookTicker","data":{"e":"bookTicker","u":335341292592,"s":"YFIUSDT","b":"50004.2","B":"0.012","a":"50012.1","A":"0.002","T":1618677471010,"E":1618677471014}}
1618677471.081308: {"stream":"ksmusdt@bookTicker","data":{"e":"bookTicker","u":335341292687,"s":"KSMUSDT","b":"458.819","B":"0.2","a":"458.975","A":"0.1","T":1618677471014,"E":1618677471019}}
1618677471.0834901: {"stream":"ksmusdt@bookTicker","data":{"e":"bookTicker","u":335341292729,"s":"KSMUSDT","b":"458.819","B":"4.8","a":"458.975","A":"0.1","T":1618677471016,"E":1618677471021}}
1618677471.089924: {"stream":"ksmusdt@bookTicker","data":{"e":"bookTicker","u":335341293229,"s":"KSMUSDT","b":"458.819","B":"0.2","a":"458.975","A":"0.1","T":1618677471028,"E":1618677471031}}
1618677471.090026: {"stream":"ksmusdt@bookTicker","data":{"e":"bookTicker","u":335341293238,"s":"KSMUSDT","b":"458.820","B":"4.7","a":"458.975","A":"0.1","T":1618677471028,"E":1618677471031}}
1618677471.10269: {"stream":"ksmusdt@bookTicker","data":{"e":"bookTicker","u":335341293549,"s":"KSMUSDT","b":"458.819","B":"0.2","a":"458.975","A":"0.1","T":1618677471038,"E":1618677471042}}
1618677471.1027899: {"stream":"ksmusdt@bookTicker","data":{"e":"bookTicker","u":335341293558,"s":"KSMUSDT","b":"458.822","B":"4.5","a":"458.975","A":"0.1","T":1618677471038,"E":1618677471042}}
1618677471.105825: {"stream":"yfiusdt@bookTicker","data":{"e":"bookTicker","u":335341293777,"s":"YFIUSDT","b":"50004.3","B":"0.002","a":"50012.1","A":"0.002","T":1618677471043,"E":1618677471047}}
1618677471.113643: {"stream":"ksmusdt@bookTicker","data":{"e":"bookTicker","u":335341294118,"s":"KSMUSDT","b":"458.819","B":"0.2","a":"458.975","A":"0.1","T":1618677471049,"E":1618677471053}}
1618677471.1137621: {"stream":"ksmusdt@bookTicker","data":{"e":"bookTicker","u":335341294135,"s":"KSMUSDT","b":"458.824","B":"4.6","a":"458.975","A":"0.1","T":1618677471050,"E":1618677471053}}
1618677471.222178: {"stream":"ksmusdt@bookTicker","data":{"e":"bookTicker","u":335341294400,"s":"KSMUSDT","b":"458.844","B":"6.4","a":"458.975","A":"0.1","T":1618677471055,"E":1618677471057}}
1618677471.229459: {"stream":"dentusdt@bookTicker","data":{"e":"bookTicker","u":335341295016,"s":"DENTUSDT","b":"0.012346","B":"26888","a":"0.012357","A":"9470","T":1618677471071,"E":1618677471074}}
1618677471.231858: {"stream":"ksmusdt@aggTrade","data":{"e":"aggTrade","E":1618677471079,"a":21396997,"s":"KSMUSDT","p":"458.878","q":"2.3","f":25426591,"l":25426591,"T":1618677470923,"m":false}}
1618677471.236801: {"stream":"xmrusdt@depth@100ms","data":{"e":"depthUpdate","E":1618677471089,"T":1618677471040,"s":"XMRUSDT","U":335341291914,"u":335341293646,"pu":335341288764,"b":[["348.22","1.467"],["352.03","0.000"]],"a":[["353.03","10.618"],["353.04","50.560"]]}}
1618677471.237002: {"stream":"ksmusdt@bookTicker","data":{"e":"bookTicker","u":335341295396,"s":"KSMUSDT","b":"458.845","B":"0.2","a":"458.975","A":"0.1","T":1618677471086,"E":1618677471090}}
1618677471.237053: {"stream":"dentusdt@depth@100ms","data":{"e":"depthUpdate","E":1618677471093,"T":1618677471071,"s":"DENTUSDT","U":335341292028,"u":335341295024,"pu":335341290606,"b":[["0.012234","99494"],["0.012268","110123"],["0.012282","393543"]],"a":[["0.012357","9470"],["0.012359","94453"],["0.012364","65196"],["0.012492","74190"]]}}
1618677471.237153: {"stream":"ksmusdt@depth@100ms","data":{"e":"depthUpdate","E":1618677471096,"T":1618677471086,"s":"KSMUSDT","U":335341292069,"u":335341295396,"pu":335341291818,"b":[["456.011","1.1"],["457.912","1.1"],["458.019","0.0"],["458.079","0.1"],["458.608","0.0"],["458.612","0.0"],["458.619","0.0"],["458.780","0.0"],["458.796","0.0"],["458.797","0.0"],["458.806","0.0"],["458.819","0.0"],["458.820","0.0"],["458.822","0.0"],["458.823","0.0"],["458.824","0.0"],["458.826","0.0"],["458.844","6.4"],["458.845","0.2"]],"a":[["459.156","0.0"],["459.157","0.0"],["459.191","0.0"],["459.212","0.2"],["459.241","0.5"],["459.242","1.6"],["459.304","1.3"],["459.382","0.0"],["459.460","0.1"],["459.468","0.0"],["459.539","0.1"],["459.540","0.1"],["459.881","0.0"],["460.157","0.0"],["461.372","15.0"],["463.395","15.0"],["463.622","0.0"]]}}
1618677471.2582028: {"stream":"yfiusdt@depth@100ms","data":{"e":"depthUpdate","E":1618677471104,"T":1618677471081,"s":"YFIUSDT","U":335341292264,"u":335341295299,"pu":335341291269,"b":[["49943.6","0.093"],["49951.8","0.000"],["49957.6","0.000"],["49959.4","0.049"],["49959.7","0.017"],["49960.8","0.000"],["49962.6","0.000"],["49965.2","0.013"],["49970.2","0.013"],["49975.8","0.000"],["49975.9","0.058"],["49976.0","0.271"],["49990.2","0.017"],["49991.4","0.000"],["49999.3","0.012"],["50001.9","0.000"],["50002.0","0.000"],["50002.1","0.000"],["50002.9","0.055"],["50004.2","0.012"],["50004.3","0.002"]],"a":[["50087.6","0.000"]]}}
1618677471.267843: {"stream":"dentusdt@bookTicker","data":{"e":"bookTicker","u":335341296162,"s":"DENTUSDT","b":"0.012346","B":"26888","a":"0.012357","A":"63445","T":1618677471140,"E":1618677471143}}
1618677471.273304: {"stream":"ksmusdt@bookTicker","data":{"e":"bookTicker","u":335341296427,"s":"KSMUSDT","b":"458.846","B":"1.5","a":"458.975","A":"0.1","T":1618677471164,"E":1618677471169}}
1618677471.277907: {"stream":"ksmusdt@bookTicker","data":{"e":"bookTicker","u":335341297389,"s":"KSMUSDT","b":"458.847","B":"0.2","a":"458.975","A":"0.1","T":1618677471192,"E":1618677471196}}
1618677471.2780092: {"stream":"xmrusdt@bookTicker","data":{"e":"bookTicker","u":335341297564,"s":"XMRUSDT","b":"352.44","B":"3.700","a":"352.53","A":"0.073","T":1618677471198,"E":1618677471201}}
1618677471.279336: {"stream":"yfiusdt@depth@100ms","data":{"e":"depthUpdate","E":1618677471211,"T":1618677471201,"s":"YFIUSDT","U":335341295667,"u":335341297621,"pu":335341295299,"b":[["49959.4","0.000"],["49959.5","0.001"],["49975.9","0.000"],["49976.1","0.058"]],"a":[["50067.6","0.000"],["50073.5","0.009"],["50075.4","0.227"],["50107.7","0.015"]]}}
1618677471.281644: {"stream":"dentusdt@depth@100ms","data":{"e":"depthUpdate","E":1618677471217,"T":1618677471187,"s":"DENTUSDT","U":335341295769,"u":335341297092,"pu":335341295024,"b":[],"a":[["0.012357","63445"],["0.012359","0"],["0.012364","119173"],["0.012381","22403"],["0.012382","511997"],["0.012623","15061"]]}}
1618677471.281845: {"stream":"yfiusdt@bookTicker","data":{"e":"bookTicker","u":335341298268,"s":"YFIUSDT","b":"50004.3","B":"0.057","a":"50012.1","A":"0.002","T":1618677471218,"E":1618677471223}}
1618677471.281897: {"stream":"xmrusdt@bookTicker","data":{"e":"bookTicker","u":335341298347,"s":"XMRUSDT","b":"352.48","B":"0.024","a":"352.53","A":"0.073","T":1618677471219,"E":1618677471223}}
1618677471.292834: {"stream":"yfiusdt@bookTicker","data":{"e":"bookTicker","u":335341298665,"s":"YFIUSDT","b":"50005.6","B":"0.012","a":"50012.1","A":"0.002","T":1618677471230,"E":1618677471233}}
1618677471.29955: {"stream":"xmrusdt@depth@100ms","data":{"e":"depthUpdate","E":1618677471240,"T":1618677471219,"s":"XMRUSDT","U":335341295987,"u":335341298347,"pu":335341293646,"b":[["351.93","16.546"],["352.15","28.927"],["352.48","0.024"]],"a":[["355.51","1.189"]]}}
1618677471.29971: {"stream":"ksmusdt@depth@100ms","data":{"e":"depthUpdate","E":1618677471240,"T":1618677471230,"s":"KSMUSDT","U":335341295938,"u":335341298765,"pu":335341295396,"b":[["454.398","15.0"],["454.622","0.0"],["456.647","15.3"],["456.872","0.0"],["457.912","1.1"],["458.516","6.7"],["458.822","0.0"],["458.845","0.0"],["458.846","1.5"],["458.847","0.2"]],"a":[["459.202","1.2"],["459.383","0.1"],["459.578","0.0"],["459.881","1.0"],["460.177","0.0"],["461.146","15.0"],["461.372","0.0"],["462.738","0.8"]]}}
1618677471.3081112: {"stream":"yfiusdt@bookTicker","data":{"e":"bookTicker","u":335341299225,"s":"YFIUSDT","b":"50004.3","B":"0.057","a":"50012.1","A":"0.002","T":1618677471243,"E":1618677471247}}
1618677471.310459: {"stream":"yfiusdt@bookTicker","data":{"e":"bookTicker","u":335341299406,"s":"YFIUSDT","b":"50004.3","B":"0.055","a":"50012.1","A":"0.002","T":1618677471247,"E":1618677471251}}
1618677471.3105621: {"stream":"yfiusdt@bookTicker","data":{"e":"bookTicker","u":335341299424,"s":"YFIUSDT","b":"50005.7","B":"0.002","a":"50012.1","A":"0.002","T":1618677471247,"E":1618677471251}}
1618677471.348799: {"stream":"ksmusdt@bookTicker","data":{"e":"bookTicker","u":335341300798,"s":"KSMUSDT","b":"458.868","B":"6.4","a":"458.975","A":"0.1","T":1618677471282,"E":1618677471289}}
1618677471.348898: {"stream":"yfiusdt@bookTicker","data":{"e":"bookTicker","u":335341300841,"s":"YFIUSDT","b":"50007.0","B":"0.012","a":"50012.1","A":"0.002","T":1618677471283,"E":1618677471289}}
1618677471.376016: {"stream":"yfiusdt@depth@100ms","data":{"e":"depthUpdate","E":1618677471317,"T":1618677471297,"s":"YFIUSDT","U":335341298064,"u":335341301456,"pu":335341297621,"b":[["49607.9","0.000"],["49632.8","0.107"],["49659.4","0.000"],["49795.3","0.000"],["49820.3","0.107"],["49954.0","0.000"],["49957.1","0.000"],["49958.0","0.000"],["49959.1","0.013"],["49962.2","0.013"],["49963.1","0.013"],["49967.6","0.087"],["49970.3","0.197"],["49984.0","0.000"],["49986.2","0.032"],["49999.2","0.000"],["49999.3","0.000"],["50004.2","0.000"],["50004.3","0.055"],["50005.6","0.000"],["50005.7","0.002"],["50007.0","0.012"]],"a":[["50023.4","0.000"],["50023.5","0.002"],["50031.6","0.000"],["50170.3","0.000"],["50172.2","0.000"],["50195.4","0.107"],["50357.7","0.000"],["50383.0","0.107"]]}}
1618677471.380495: {"stream":"dentusdt@depth@100ms","data":{"e":"depthUpdate","E":1618677471323,"T":1618677471290,"s":"DENTUSDT","U":335341298348,"u":335341301229,"pu":335341297092,"b":[],"a":[["0.012358","3456"],["0.012359","94453"],["0.012363","639385"],["0.012368","134925"],["0.012373","11191"],["0.012395","140428"],["0.012398","245538"]]}}
1618677471.391448: {"stream":"ksmusdt@bookTicker","data":{"e":"bookTicker","u":335341302679,"s":"KSMUSDT","b":"458.869","B":"0.2","a":"458.975","A":"0.1","T":1618677471328,"E":1618677471331}}
1618677471.394058: {"stream":"yfiusdt@bookTicker","data":{"e":"bookTicker","u":335341302764,"s":"YFIUSDT","b":"50004.3","B":"0.055","a":"50012.1","A":"0.002","T":1618677471331,"E":1618677471335}}
1618677471.394161: {"stream":"yfiusdt@bookTicker","data":{"e":"bookTicker","u":335341302779,"s":"YFIUSDT","b":"50004.3","B":"0.055","a":"50010.8","A":"0.006","T":1618677471332,"E":1618677471335}}
1618677471.4023302: {"stream":"xmrusdt@depth@100ms","data":{"e":"depthUpdate","E":1618677471342,"T":1618677471337,"s":"XMRUSDT","U":335341299059,"u":335341302918,"pu":335341298347,"b":[["352.16","6.076"],["352.36","0.000"]],"a":[["352.95","25.632"],["354.63","3.257"]]}}
1618677471.40384: {"stream":"ksmusdt@depth@100ms","data":{"e":"depthUpdate","E":1618677471345,"T":1618677471328,"s":"KSMUSDT","U":335341299121,"u":335341302689,"pu":335341298765,"b":[["454.398","30.0"],["456.647","30.3"],["457.912","1.1"],["458.244","2.6"],["458.340","14.8"],["458.643","1.5"],["458.782","1.0"],["458.818","0.0"],["458.847","0.0"],["458.868","6.4"],["458.869","0.2"]],"a":[["459.201","1.8"],["459.202","0.0"],["459.212","0.0"],["459.242","0.0"],["459.881","1.0"],["460.156","6.1"],["461.146","30.0"],["463.395","30.0"]]}}
1618677471.4067478: {"stream":"yfiusdt@bookTicker","data":{"e":"bookTicker","u":335341303164,"s":"YFIUSDT","b":"49990.3","B":"0.002","a":"50010.8","A":"0.006","T":1618677471343,"E":1618677471347}}
1618677471.438208: {"stream":"yfiusdt@bookTicker","data":{"e":"bookTicker","u":335341304177,"s":"YFIUSDT","b":"49992.8","B":"0.055","a":"50010.8","A":"0.006","T":1618677471375,"E":1618677471379}}
1618677471.451307: {"stream":"yfiusdt@bookTicker","data":{"e":"bookTicker","u":335341304535,"s":"YFIUSDT","b":"49992.8","B":"0.055","a":"50001.8","A":"0.002","T":1618677471388,"E":1618677471392}}
1618677471.460918: {"stream":"yfiusdt@bookTicker","data":{"e":"bookTicker","u":335341304815,"s":"YFIUSDT","b":"49994.1","B":"0.012","a":"50001.8","A":"0.002","T":1618677471398,"E":1618677471403}}
1618677471.4762518: {"stream":"yfiusdt@depth@100ms","data":{"e":"depthUpdate","E":1618677471418,"T":1618677471409,"s":"YFIUSDT","U":335341302088,"u":335341305100,"pu":335341301456,"b":[["49621.9","0.007"],["49923.7","0.080"],["49925.1","0.000"],["49933.8","0.110"],["49936.4","0.080"],["49938.0","0.110"],["49942.2","0.110"],["49943.6","0.075"],["49946.4","0.000"],["49946.5","0.100"],["49950.6","0.000"],["49954.8","0.000"],["49959.7","0.000"],["49961.8","0.000"],["49967.6","0.000"],["49974.5","0.000"],["49990.1","0.000"],["49990.2","0.000"],["49990.3","0.000"],["49992.8","0.055"],["49992.9","0.002"],["49994.1","0.012"],["50002.9","0.000"],["50004.3","0.000"],["50005.7","0.000"],["50007.0","0.000"]],"a":[["50001.8","0.002"],["50010.8","0.000"],["50012.1","0.000"],["50043.4","0.000"]]}}
1618677471.501995: {"stream":"ksmusdt@depth@100ms","data":{"e":"depthUpdate","E":1618677471445,"T":1618677471439,"s":"KSMUSDT","U":335341303118,"u":335341305934,"pu":335341302689,"b":[["457.912","1.1"],["458.594","0.0"]],"a":[["459.197","0.2"],["459.198","0.0"],["459.201","1.6"],["459.407","0.0"],["462.197","0.8"]]}}
1618677471.502225: {"stream":"yfiusdt@bookTicker","data":{"e":"bookTicker","u":335341306001,"s":"YFIUSDT","b":"49994.2","B":"0.002","a":"50001.8","A":"0.002","T":1618677471441,"E":1618677471446}}
1618677471.508945: {"stream":"yfiusdt@bookTicker","data":{"e":"bookTicker","u":335341306130,"s":"YFIUSDT","b":"49996.5","B":"0.055","a":"50001.8","A":"0.002","T":1618677471445,"E":1618677471450}}
1618677471.513686: {"stream":"dentusdt@depth@100ms","data":{"e":"depthUpdate","E":1618677471457,"T":1618677471451,"s":"DENTUSDT","U":335341303506,"u":335341306243,"pu":335341301229,"b":[["0.011111","955489"],["0.012096","495456"],["0.012197","4384"],["0.012308","5496"],["0.012315","63744"],["0.012325","622011"],["0.012330","180868"],["0.012331","47116"],["0.012333","13492"],["0.012344","48577"]],"a":[["0.012363","590810"],["0.012402","154030"],["0.012624","450889"]]}}
1618677471.513962: {"stream":"xmrusdt@depth@100ms","data":{"e":"depthUpdate","E":1618677471458,"T":1618677471375,"s":"XMRUSDT","U":335341303570,"u":335341304186,"pu":335341302918,"b":[["351.48","157.544"],["351.58","0.000"],["351.59","0.027"],["352.11","6.951"],["352.15","5.719"],["352.16","2.966"],["352.21","0.000"],["352.22","2.500"],["352.30","0.000"]],"a":[]}}
1618677471.514418: {"stream":"yfiusdt@kline_1m","data":{"e":"kline","E":1618677471458,"s":"YFIUSDT","k":{"t":1618677420000,"T":1618677479999,"s":"YFIUSDT","i":"1m","f":64902095,"L":64902199,"o":"50010.8","c":"50001.8","h":"50044.2","l":"49950.6","v":"1.148","n":105,"x":false,"q":"57398.8943","V":"0.830","Q":"41499.5901","B":"0"}}}
1618677471.518451: {"stream":"yfiusdt@bookTicker","data":{"e":"bookTicker","u":335341306334,"s":"YFIUSDT","b":"49997.8","B":"0.012","a":"50001.8","A":"0.002","T":1618677471454,"E":1618677471458}}
1618677471.518551: {"stream":"yfiusdt@bookTicker","data":{"e":"bookTicker","u":335341306358,"s":"YFIUSDT","b":"49997.8","B":"0.012","a":"50023.5","A":"0.002","T":1618677471455,"E":1618677471458}}
1618677471.534993: {"stream":"dentusdt@kline_1m","data":{"e":"kline","E":1618677471478,"s":"DENTUSDT","k":{"t":1618677420000,"T":1618677479999,"s":"DENTUSDT","i":"1m","f":15787262,"L":15787451,"o":"0.012366","c":"0.012348","h":"0.012366","l":"0.012339","v":"3056990","n":190,"x":false,"q":"37757.910467","V":"1266681","Q":"15650.248000","B":"0"}}}
1618677471.538261: {"stream":"yfiusdt@bookTicker","data":{"e":"bookTicker","u":335341306922,"s":"YFIUSDT","b":"49997.9","B":"0.002","a":"50023.5","A":"0.002","T":1618677471473,"E":1618677471479}}
1618677471.538363: {"stream":"dentusdt@bookTicker","data":{"e":"bookTicker","u":335341306960,"s":"DENTUSDT","b":"0.012348","B":"2595","a":"0.012357","A":"63445","T":1618677471474,"E":1618677471479}}
1618677471.538406: {"stream":"dentusdt@bookTicker","data":{"e":"bookTicker","u":335341306968,"s":"DENTUSDT","b":"0.012348","B":"653","a":"0.012357","A":"63445","T":1618677471474,"E":1618677471479}}
1618677471.543144: {"stream":"dentusdt@bookTicker","data":{"e":"bookTicker","u":335341307056,"s":"DENTUSDT","b":"0.012346","B":"26888","a":"0.012357","A":"63445","T":1618677471478,"E":1618677471483}}
1618677471.575496: {"stream":"yfiusdt@depth@100ms","data":{"e":"depthUpdate","E":1618677471519,"T":1618677471511,"s":"YFIUSDT","U":335341305296,"u":335341307921,"pu":335341305100,"b":[["49819.7","0.001"],["49823.1","0.000"],["49828.9","0.000"],["49838.2","0.001"],["49844.7","0.001"],["49933.8","0.000"],["49938.0","0.110"],["49942.2","0.110"],["49946.4","0.110"],["49946.5","0.000"],["49950.6","0.000"],["49952.1","0.006"],["49954.8","0.000"],["49955.2","0.006"],["49956.1","0.006"],["49959.1","0.000"],["49962.2","0.000"],["49963.1","0.000"],["49992.8","0.000"],["49992.9","0.000"],["49994.1","0.000"],["49994.2","0.000"],["49996.5","0.055"],["49997.8","0.012"],["49997.9","0.002"]],"a":[["50001.8","0.000"],["50040.2","0.000"],["50254.4","0.000"]]}}
1618677471.616069: {"stream":"ksmusdt@depth@100ms","data":{"e":"depthUpdate","E":1618677471558,"T":1618677471482,"s":"KSMUSDT","U":335341306320,"u":335341307159,"pu":335341305934,"b":[["458.132","0.0"]],"a":[["459.195","0.2"],["459.196","1.6"],["459.197","0.0"],["459.201","0.0"]]}}
1618677471.6163: {"stream":"yfiusdt@bookTicker","data":{"e":"bookTicker","u":335341308892,"s":"YFIUSDT","b":"49997.9","B":"0.002","a":"50023.2","A":"0.013","T":1618677471554,"E":1618677471558}}
1618677471.621037: {"stream":"dentusdt@depth@100ms","data":{"e":"depthUpdate","E":1618677471564,"T":1618677471507,"s":"DENTUSDT","U":335341306467,"u":335341307803,"pu":335341306243,"b":[["0.012145","455"],["0.012164","1248"],["0.012250","270721"],["0.012260","428471"],["0.012279","24883"],["0.012286","949307"],["0.012289","952517"],["0.012303","6310"],["0.012306","506677"],["0.012320","22355"],["0.012321","90332"],["0.012348","0"]],"a":[["0.012397","135091"],["0.012400","1249699"],["0.012407","89560"],["0.012411","47844"],["0.012418","9282"],["0.012419","1421426"],["0.012428","36246"],["0.012435","5799"],["0.012537","13162"]]}}
1618677471.626444: {"stream":"xmrusdt@depth@100ms","data":{"e":"depthUpdate","E":1618677471569,"T":1618677471555,"s":"XMRUSDT","U":335341306584,"u":335341308913,"pu":335341304186,"b":[["342.98","0.000"],["347.29","0.057"],["351.60","0.073"],["351.76","2.500"],["352.06","0.000"],["352.12","0.000"],["352.22","0.000"]],"a":[["352.80","2.500"],["352.81","0.000"],["352.88","0.000"]]}}
1618677471.645809: {"stream":"yfiusdt@bookTicker","data":{"e":"bookTicker","u":335341309582,"s":"YFIUSDT","b":"49997.9","B":"0.002","a":"50023.1","A":"0.002","T":1618677471584,"E":1618677471589}}
1618677471.6459131: {"stream":"yfiusdt@bookTicker","data":{"e":"bookTicker","u":335341309592,"s":"YFIUSDT","b":"50000.4","B":"0.055","a":"50023.1","A":"0.002","T":1618677471585,"E":1618677471589}}
1618677471.659884: {"stream":"yfiusdt@bookTicker","data":{"e":"bookTicker","u":335341309831,"s":"YFIUSDT","b":"50000.4","B":"0.055","a":"50022.9","A":"0.012","T":1618677471597,"E":1618677471601}}
1618677471.665756: {"stream":"yfiusdt@aggTrade","data":{"e":"aggTrade","E":1618677471609,"a":52599716,"s":"YFIUSDT","p":"50001.8","q":"0.002","f":64902199,"l":64902199,"T":1618677471455,"m":false}}
1618677471.6888099: {"stream":"yfiusdt@depth@100ms","data":{"e":"depthUpdate","E":1618677471629,"T":1618677471597,"s":"YFIUSDT","U":335341308268,"u":335341309831,"pu":335341307921,"b":[["49986.2","0.000"],["50000.4","0.055"]],"a":[["50022.9","0.012"],["50023.1","0.002"],["50023.2","0.000"],["50023.5","0.000"],["50023.6","0.000"],["50255.6","0.005"]]}}
1618677471.689055: {"stream":"dentusdt@aggTrade","data":{"e":"aggTrade","E":1618677471630,"a":8476444,"s":"DENTUSDT","p":"0.012348","q":"1942","f":15787451,"l":15787451,"T":1618677471474,"m":true}}
1618677471.695196: {"stream":"yfiusdt@bookTicker","data":{"e":"bookTicker","u":335341310721,"s":"YFIUSDT","b":"50000.4","B":"0.055","a":"50022.8","A":"0.002","T":1618677471633,"E":1618677471637}}
1618677471.6952949: {"stream":"yfiusdt@bookTicker","data":{"e":"bookTicker","u":335341310741,"s":"YFIUSDT","b":"50000.5","B":"0.002","a":"50022.8","A":"0.002","T":1618677471633,"E":1618677471637}}
1618677471.731159: {"stream":"ksmusdt@depth@100ms","data":{"e":"depthUpdate","E":1618677471672,"T":1618677471664,"s":"KSMUSDT","U":335341309170,"u":335341311511,"pu":335341307159,"b":[["457.804","0.0"],["458.027","0.0"],["458.197","2.1"]],"a":[["459.196","0.0"],["459.240","1.6"],["459.773","2.1"],["459.793","0.0"],["460.429","0.0"],["461.531","0.0"],["461.662","0.0"],["461.909","1.0"]]}}
1618677471.737034: {"stream":"xmrusdt@depth@100ms","data":{"e":"depthUpdate","E":1618677471677,"T":1618677471657,"s":"XMRUSDT","U":335341309248,"u":335341311293,"pu":335341308913,"b":[["343.69","0.000"],["351.76","0.000"],["351.90","0.000"],["351.99","47.002"]],"a":[["352.64","0.716"],["352.80","0.000"],["352.81","2.500"],["352.88","0.000"]]}}
1618677471.74785: {"stream":"xmrusdt@bookTicker","data":{"e":"bookTicker","u":335341312045,"s":"XMRUSDT","b":"352.50","B":"0.025","a":"352.53","A":"0.073","T":1618677471685,"E":1618677471689}}
1618677471.778827: {"stream":"dentusdt@depth@100ms","data":{"e":"depthUpdate","E":1618677471722,"T":1618677471674,"s":"DENTUSDT","U":335341310330,"u":335341311798,"pu":335341307803,"b":[["0.012275","452495"],["0.012305","158220"]],"a":[["0.012388","584518"],["0.012391","127436"],["0.012395","128236"],["0.012400","1218541"]]}}
1618677471.790684: {"stream":"yfiusdt@depth@100ms","data":{"e":"depthUpdate","E":1618677471732,"T":1618677471719,"s":"YFIUSDT","U":335341310550,"u":335341312769,"pu":335341309831,"b":[["49836.3","0.000"],["49890.2","0.000"],["49932.0","0.000"],["49938.0","0.000"],["49942.2","0.000"],["49950.6","0.110"],["49954.8","0.110"],["49997.9","0.000"],["50000.5","0.002"]],"a":[["50022.8","0.002"],["50023.1","0.000"],["50107.5","0.000"],["50137.5","0.000"],["50152.6","0.001"]]}}
1618677471.8126788: {"stream":"xmrusdt@bookTicker","data":{"e":"bookTicker","u":335341313461,"s":"XMRUSDT","b":"352.51","B":"0.024","a":"352.53","A":"0.073","T":1618677471750,"E":1618677471754}}
1618677471.8356779: {"stream":"xmrusdt@depth@100ms","data":{"e":"depthUpdate","E":1618677471777,"T":1618677471766,"s":"XMRUSDT","U":335341311674,"u":335341313799,"pu":335341311293,"b":[["351.99","44.502"],["352.12","2.500"],["352.19","0.000"],["352.48","0.000"],["352.50","0.025"],["352.51","0.024"]],"a":[["352.69","13.111"],["353.01","15.462"],["353.04","35.098"]]}}
1618677471.877347: {"stream":"yfiusdt@bookTicker","data":{"e":"bookTicker","u":335341314872,"s":"YFIUSDT","b":"50000.5","B":"0.002","a":"50011.7","A":"0.001","T":1618677471816,"E":1618677471820}}
1618677471.891884: {"stream":"yfiusdt@depth@100ms","data":{"e":"depthUpdate","E":1618677471833,"T":1618677471824,"s":"YFIUSDT","U":335341312990,"u":335341315023,"pu":335341312769,"b":[["49197.0","0.000"],["49850.6","0.027"],["49855.3","0.019"],["49891.8","0.018"],["49966.2","0.087"],["49970.3","0.000"],["49976.2","0.000"]],"a":[["50011.7","0.001"],["50075.4","0.000"],["50111.9","0.000"],["50127.3","0.001"],["50270.3","0.000"],["50307.1","0.042"]]}}
1618677471.89219: {"stream":"ksmusdt@depth@100ms","data":{"e":"depthUpdate","E":1618677471834,"T":1618677471826,"s":"KSMUSDT","U":335341313009,"u":335341315156,"pu":335341311511,"b":[["458.846","0.0"]],"a":[["459.881","0.0"],["463.259","0.0"]]}}
1618677471.936896: {"stream":"ksmusdt@bookTicker","data":{"e":"bookTicker","u":335341316228,"s":"KSMUSDT","b":"458.868","B":"6.4","a":"458.975","A":"0.1","T":1618677471872,"E":1618677471877}}
1618677471.938506: {"stream":"xmrusdt@depth@100ms","data":{"e":"depthUpdate","E":1618677471881,"T":1618677471865,"s":"XMRUSDT","U":335341314050,"u":335341316005,"pu":335341313799,"b":[["351.48","155.544"],["351.55","4.000"],["351.65","200.000"],["351.66","0.000"],["352.11","4.951"],["352.12","0.000"],["352.18","4.335"],["352.19","13.580"],["352.20","2.500"]],"a":[["352.81","0.000"],["352.88","2.500"],["352.90","38.286"],["352.92","0.000"],["353.38","202.281"],["354.28","6.179"]]}}
1618677471.953058: {"stream":"dentusdt@depth@100ms","data":{"e":"depthUpdate","E":1618677471893,"T":1618677471869,"s":"DENTUSDT","U":335341314235,"u":335341316121,"pu":335341311798,"b":[["0.012092","66319"],["0.012309","12274"]],"a":[["0.012382","508337"]]}}
1618677471.989088: {"stream":"xmrusdt@kline_1m","data":{"e":"kline","E":1618677471931,"s":"XMRUSDT","k":{"t":1618677420000,"T":1618677479999,"s":"XMRUSDT","i":"1m","f":34692938,"L":34692979,"o":"352.86","c":"352.51","h":"352.93","l":"352.40","v":"34.880","n":42,"x":false,"q":"12299.32390","V":"3.692","Q":"1301.87303","B":"0"}}}
1618677471.990614: {"stream":"xmrusdt@aggTrade","data":{"e":"aggTrade","E":1618677471932,"a":23619032,"s":"XMRUSDT","p":"352.51","q":"0.024","f":34692979,"l":34692979,"T":1618677471927,"m":true}}
1618677471.99072: {"stream":"xmrusdt@aggTrade","data":{"e":"aggTrade","E":1618677471932,"a":23619033,"s":"XMRUSDT","p":"352.50","q":"0.025","f":34692980,"l":34692980,"T":1618677471927,"m":true}}
1618677471.9907699: {"stream":"xmrusdt@bookTicker","data":{"e":"bookTicker","u":335341317500,"s":"XMRUSDT","b":"352.44","B":"2.151","a":"352.53","A":"0.073","T":1618677471928,"E":1618677471932}}
1618677471.9927108: {"stream":"ksmusdt@depth@100ms","data":{"e":"depthUpdate","E":1618677471934,"T":1618677471915,"s":"KSMUSDT","U":335341315255,"u":335341317159,"pu":335341315156,"b":[["456.207","0.0"],["456.431","2.7"],["457.912","1.1"],["458.783","0.0"],["458.813","1.2"],["458.814","0.2"],["458.844","0.0"],["458.869","0.0"]],"a":[["459.239","1.0"]]}}
1618677472.009799: {"stream":"dentusdt@kline_1m","data":{"e":"kline","E":1618677471952,"s":"DENTUSDT","k":{"t":1618677420000,"T":1618677479999,"s":"DENTUSDT","i":"1m","f":15787262,"L":15787452,"o":"0.012366","c":"0.012346","h":"0.012366","l":"0.012339","v":"3066181","n":191,"x":false,"q":"37871.382553","V":"1266681","Q":"15650.248000","B":"0"}}}
1618677472.009923: {"stream":"yfiusdt@depth@100ms","data":{"e":"depthUpdate","E":1618677471952,"T":1618677471889,"s":"YFIUSDT","U":335341315559,"u":335341316644,"pu":335341315023,"b":[["49686.7","0.005"],["49953.0","0.013"],["49958.8","0.013"],["49959.5","0.000"],["49963.8","0.013"],["49965.2","0.000"],["49970.2","0.000"]],"a":[["50206.9","0.042"]]}}
1618677472.012279: {"stream":"dentusdt@bookTicker","data":{"e":"bookTicker","u":335341318004,"s":"DENTUSDT","b":"0.012346","B":"17697","a":"0.012357","A":"63445","T":1618677471948,"E":1618677471953}}
1618677472.0588748: {"stream":"xmrusdt@depth@100ms","data":{"e":"depthUpdate","E":1618677472001,"T":1618677471984,"s":"XMRUSDT","U":335341316839,"u":335341318802,"pu":335341316005,"b":[["326.75","0.000"],["352.20","2.500"],["352.27","0.000"],["352.36","1.400"],["352.44","2.151"],["352.50","0.000"],["352.51","0.000"]],"a":[["352.68","33.121"],["352.81","2.500"],["352.88","0.000"],["352.90","7.918"],["353.00","36.493"],["353.04","0.000"],["353.86","5.909"],["354.17","0.058"],["379.04","0.000"]]}}
1618677472.0766551: {"stream":"dentusdt@depth@100ms","data":{"e":"depthUpdate","E":1618677472019,"T":1618677472006,"s":"DENTUSDT","U":335341317188,"u":335341319420,"pu":335341316121,"b":[["0.012131","494840"],["0.012322","112831"],["0.012346","17697"]],"a":[["0.012363","542235"],["0.012382","511575"],["0.012395","153332"],["0.012397","109992"],["0.012403","407177"],["0.012409","190613"]]}}
1618677472.0973: {"stream":"yfiusdt@bookTicker","data":{"e":"bookTicker","u":335341320343,"s":"YFIUSDT","b":"50000.6","B":"0.027","a":"50011.7","A":"0.001","T":1618677472035,"E":1618677472039}}
1618677472.108522: {"stream":"ksmusdt@depth@100ms","data":{"e":"depthUpdate","E":1618677472049,"T":1618677472035,"s":"KSMUSDT","U":335341317929,"u":335341320342,"pu":335341317159,"b":[["458.016","0.0"],["458.038","0.0"],["458.039","0.5"],["458.341","3.2"]],"a":[["459.212","1.6"],["459.240","0.0"],["459.383","0.0"],["459.399","0.1"],["459.460","0.0"],["459.537","4.5"],["459.538","19.8"],["459.540","0.0"],["459.555","0.1"],["459.579","0.0"],["459.583","0.4"],["459.584","0.0"],["459.586","0.0"],["461.775","0.0"]]}}
1618677472.214818: {"stream":"yfiusdt@bookTicker","data":{"e":"bookTicker","u":335341320998,"s":"YFIUSDT","b":"50001.9","B":"0.012","a":"50011.7","A":"0.001","T":1618677472054,"E":1618677472059}}
1618677472.214921: {"stream":"yfiusdt@depth@100ms","data":{"e":"depthUpdate","E":1618677472061,"T":1618677472054,"s":"YFIUSDT","U":335341318241,"u":335341320998,"pu":335341316644,"b":[["49641.9","0.011"],["49803.6","0.000"],["49886.7","0.000"],["49893.5","0.157"],["49930.3","0.000"],["49948.2","0.060"],["49990.5","0.012"],["49996.6","0.012"],["49997.8","0.000"],["50000.6","0.027"],["50001.9","0.012"]],"a":[["50082.8","0.000"],["50105.3","0.000"],["50114.2","0.060"],["50199.4","0.005"],["50307.1","0.000"]]}}
1618677472.216955: {"stream":"yfiusdt@bookTicker","data":{"e":"bookTicker","u":335341321317,"s":"YFIUSDT","b":"50002.0","B":"0.017","a":"50011.7","A":"0.001","T":1618677472065,"E":1618677472070}}
1618677472.219091: {"stream":"yfiusdt@bookTicker","data":{"e":"bookTicker","u":335341321650,"s":"YFIUSDT","b":"50003.3","B":"0.012","a":"50011.7","A":"0.001","T":1618677472075,"E":1618677472079}}
1618677472.219168: {"stream":"xmrusdt@aggTrade","data":{"e":"aggTrade","E":1618677472083,"a":23619034,"s":"XMRUSDT","p":"352.44","q":"1.549","f":34692981,"l":34692981,"T":1618677471928,"m":true}}
1618677472.222066: {"stream":"yfiusdt@bookTicker","data":{"e":"bookTicker","u":335341322077,"s":"YFIUSDT","b":"50003.4","B":"0.018","a":"50011.7","A":"0.001","T":1618677472087,"E":1618677472091}}
1618677472.2230551: {"stream":"yfiusdt@bookTicker","data":{"e":"bookTicker","u":335341322215,"s":"YFIUSDT","b":"50004.7","B":"0.012","a":"50011.7","A":"0.001","T":1618677472096,"E":1618677472100}}
1618677472.223149: {"stream":"dentusdt@aggTrade","data":{"e":"aggTrade","E":1618677472104,"a":8476445,"s":"DENTUSDT","p":"0.012346","q":"9191","f":15787452,"l":15787452,"T":1618677471948,"m":true}}
1618677472.22334: {"stream":"xmrusdt@depth@100ms","data":{"e":"depthUpdate","E":1618677472106,"T":1618677472093,"s":"XMRUSDT","U":335341319282,"u":335341322184,"pu":335341318802,"b":[["326.39","4.276"],["343.74","0.000"],["351.92","2.516"],["352.20","2.851"],["352.29","0.828"]],"a":[["352.67","4.863"],["352.68","30.368"],["352.94","5.384"],["353.03","0.000"],["353.75","2.954"],["378.64","3.397"]]}}
1618677472.229739: {"stream":"ksmusdt@bookTicker","data":{"e":"bookTicker","u":335341322490,"s":"KSMUSDT","b":"458.869","B":"0.2","a":"458.975","A":"0.1","T":1618677472114,"E":1618677472119}}
1618677472.2337868: {"stream":"ksmusdt@depth@100ms","data":{"e":"depthUpdate","E":1618677472152,"T":1618677472114,"s":"KSMUSDT","U":335341320809,"u":335341322490,"pu":335341320342,"b":[["456.162","0.0"],["456.370","1.5"],["458.169","2.7"],["458.287","2.2"],["458.814","0.0"],["458.859","1.5"],["458.869","0.2"]],"a":[["459.451","0.1"]]}}
1618677472.236043: {"stream":"yfiusdt@depth@100ms","data":{"e":"depthUpdate","E":1618677472162,"T":1618677472156,"s":"YFIUSDT","U":335341321117,"u":335341323332,"pu":335341320998,"b":[["49659.7","0.007"],["49819.1","0.007"],["49905.0","0.017"],["49908.4","0.141"],["49923.7","0.000"],["49936.4","0.000"],["49953.0","0.000"],["49958.5","0.038"],["49958.8","0.000"],["49961.8","0.080"],["49963.8","0.000"],["49964.3","0.038"],["49969.3","0.038"],["49973.1","0.292"],["49973.2","0.061"],["49976.0","0.000"],["49976.1","0.000"],["49990.5","0.000"],["49996.6","0.000"],["50000.5","0.000"],["50000.6","0.000"],["50001.9","0.000"],["50002.0","0.000"],["50002.1","0.002"],["50003.3","0.000"],["50003.4","0.000"],["50004.7","0.012"]],"a":[["50054.2","0.011"],["50061.7","0.000"],["50062.9","0.016"],["50067.5","0.000"],["50070.4","0.016"],["50076.1","0.016"],["50106.0","0.008"],["50111.1","0.001"],["50126.6","0.027"],["50132.1","0.000"],["50141.1","0.000"],["50147.2","0.142"],["51232.9","0.034"],["51393.5","0.000"]]}}
1618677472.236427: {"stream":"dentusdt@depth@100ms","data":{"e":"depthUpdate","E":1618677472164,"T":1618677472155,"s":"DENTUSDT","U":335341321185,"u":335341323237,"pu":335341319420,"b":[["0.012183","124226"],["0.012220","131119"],["0.012226","24774"],["0.012237","77322"],["0.012242","363585"],["0.012245","60853"],["0.012270","143502"],["0.012319","924739"],["0.012324","172690"],["0.012328","201334"],["0.012331","75328"],["0.012332","287483"]],"a":[["0.012394","40139"],["0.012443","710743"],["0.012448","56545"],["0.012470","435950"],["0.012472","71199"],["0.012495","2813424"],["0.012497","70030"],["0.012534","304609"]]}}
1618677472.238076: {"stream":"yfiusdt@bookTicker","data":{"e":"bookTicker","u":335341323737,"s":"YFIUSDT","b":"50004.8","B":"0.020","a":"50011.7","A":"0.001","T":1618677472174,"E":1618677472178}}
1618677472.244823: {"stream":"yfiusdt@bookTicker","data":{"e":"bookTicker","u":335341324099,"s":"YFIUSDT","b":"50006.1","B":"0.012","a":"50011.7","A":"0.001","T":1618677472183,"E":1618677472187}}
1618677472.267058: {"stream":"xmrusdt@depth@100ms","data":{"e":"depthUpdate","E":1618677472208,"T":1618677472179,"s":"XMRUSDT","U":335341322302,"u":335341323917,"pu":335341322184,"b":[["350.45","1.336"],["351.62","0.000"],["351.77","1.423"],["351.92","0.016"],["352.01","3.164"],["352.25","3.950"],["352.34","6.396"]],"a":[["352.56","0.240"]]}}
1618677472.2985852: {"stream":"dentusdt@bookTicker","data":{"e":"bookTicker","u":335341326124,"s":"DENTUSDT","b":"0.012346","B":"17697","a":"0.012356","A":"6924","T":1618677472234,"E":1618677472238}}
1618677472.2986848: {"stream":"ksmusdt@bookTicker","data":{"e":"bookTicker","u":335341326147,"s":"KSMUSDT","b":"458.868","B":"6.4","a":"458.975","A":"0.1","T":1618677472234,"E":1618677472238}}
1618677472.308269: {"stream":"xmrusdt@bookTicker","data":{"e":"bookTicker","u":335341326584,"s":"XMRUSDT","b":"352.46","B":"4.212","a":"352.53","A":"0.073","T":1618677472245,"E":1618677472248}}
1618677472.3083708: {"stream":"xmrusdt@bookTicker","data":{"e":"bookTicker","u":335341326728,"s":"XMRUSDT","b":"352.44","B":"2.151","a":"352.53","A":"0.073","T":1618677472248,"E":1618677472251}}
1618677472.313322: {"stream":"ksmusdt@depth@100ms","data":{"e":"depthUpdate","E":1618677472254,"T":1618677472235,"s":"KSMUSDT","U":335341323062,"u":335341326160,"pu":335341322490,"b":[["454.753","0.0"],["454.833","3.9"],["456.625","0.0"],["456.818","0.0"],["456.899","3.9"],["457.912","1.1"],["458.020","0.9"],["458.783","0.2"],["458.813","0.0"],["458.819","0.0"],["458.859","0.0"],["458.869","0.0"]],"a":[["460.947","0.0"],["461.028","3.9"],["463.012","0.0"],["463.094","3.9"]]}}
1618677472.324168: {"stream":"yfiusdt@depth@100ms","data":{"e":"depthUpdate","E":1618677472264,"T":1618677472226,"s":"YFIUSDT","U":335341323383,"u":335341325870,"pu":335341323332,"b":[["49663.3","0.004"],["49958.5","0.000"],["49961.2","0.018"],["49964.3","0.000"],["49967.0","0.018"],["49969.3","0.000"],["49972.0","0.018"],["49974.5","0.080"],["49996.5","0.000"],["49996.6","0.000"],["49996.7","0.000"],["50000.4","0.000"],["50000.5","0.011"],["50002.1","0.000"],["50002.4","0.055"],["50002.5","0.013"],["50004.7","0.000"],["50004.8","0.000"],["50005.6","0.055"],["50006.1","0.012"]],"a":[["50098.9","0.009"],["50099.0","0.000"],["51272.9","0.000"]]}}
1618677472.324543: {"stream":"dentusdt@depth@100ms","data":{"e":"depthUpdate","E":1618677472264,"T":1618677472250,"s":"DENTUSDT","U":335341323387,"u":335341326823,"pu":335341323237,"b":[["0.012242","347267"],["0.012267","102341"],["0.012281","35844"],["0.012306","502995"],["0.012319","905581"],["0.012324","191826"],["0.012325","325096"]],"a":[["0.012356","6924"],["0.012359","0"],["0.012363","407989"],["0.012382","508337"],["0.012383","373008"],["0.012469","33094"],["0.012470","427940"],["0.012474","9379"],["0.012495","2805430"],["0.012496","92963"],["0.012499","1330"]]}}
1618677472.348574: {"stream":"dentusdt@bookTicker","data":{"e":"bookTicker","u":335341328398,"s":"DENTUSDT","b":"0.012346","B":"17697","a":"0.012356","A":"47402","T":1618677472288,"E":1618677472291}}
1618677472.3794281: {"stream":"xmrusdt@depth@100ms","data":{"e":"depthUpdate","E":1618677472320,"T":1618677472310,"s":"XMRUSDT","U":335341325478,"u":335341329252,"pu":335341323917,"b":[["351.55","0.000"],["351.56","2.000"],["351.99","44.502"],["352.06","0.000"],["352.10","18.261"],["352.12","2.500"],["352.15","5.719"],["352.18","0.335"],["352.19","15.580"],["352.25","1.450"],["352.27","0.982"],["352.36","1.400"],["352.46","0.000"]],"a":[["352.55","0.783"],["352.56","3.726"],["352.57","0.001"],["352.58","0.000"],["352.67","6.379"],["353.99","2.269"],["354.16","10.437"]]}}
1618677472.3884149: {"stream":"dentusdt@bookTicker","data":{"e":"bookTicker","u":335341329734,"s":"DENTUSDT","b":"0.012346","B":"17697","a":"0.012356","A":"50858","T":1618677472326,"E":1618677472330}}
1618677472.390719: {"stream":"yfiusdt@bookTicker","data":{"e":"bookTicker","u":335341329851,"s":"YFIUSDT","b":"50006.1","B":"0.012","a":"50022.8","A":"0.002","T":1618677472330,"E":1618677472333}}
1618677472.4057002: {"stream":"yfiusdt@bookTicker","data":{"e":"bookTicker","u":335341330200,"s":"YFIUSDT","b":"50006.1","B":"0.012","a":"50014.5","A":"0.001","T":1618677472342,"E":1618677472347}}
1618677472.415603: {"stream":"dentusdt@bookTicker","data":{"e":"bookTicker","u":335341330505,"s":"DENTUSDT","b":"0.012346","B":"17697","a":"0.012356","A":"10380","T":1618677472354,"E":1618677472357}}
1618677472.4196281: {"stream":"ksmusdt@depth@100ms","data":{"e":"depthUpdate","E":1618677472360,"T":1618677472355,"s":"KSMUSDT","U":335341327003,"u":335341330549,"pu":335341326160,"b":[["456.654","0.1"],["457.912","1.1"],["458.185","0.3"],["458.783","0.0"],["458.813","1.2"],["458.814","0.2"]],"a":[["459.194","0.2"],["459.195","0.0"],["459.239","0.0"],["459.520","1.0"],["460.689","0.0"],["460.888","0.4"],["461.225","0.0"],["461.254","0.1"]]}}
1618677472.426164: {"stream":"dentusdt@depth@100ms","data":{"e":"depthUpdate","E":1618677472367,"T":1618677472358,"s":"DENTUSDT","U":335341327313,"u":335341330635,"pu":335341326823,"b":[["0.012218","95078"],["0.012220","114771"],["0.012237","69161"],["0.012242","322790"],["0.012244","65398"],["0.012245","52696"],["0.012267","77915"],["0.012269","59202"],["0.012270","135361"],["0.012301","194101"],["0.012305","163825"],["0.012321","64576"],["0.012324","163180"],["0.012329","33353"],["0.012330","81715"],["0.012333","13499"],["0.012334","100744"]],"a":[["0.012356","10380"],["0.012357","9470"],["0.012358","0"],["0.012361","0"],["0.012362","182456"],["0.012363","274108"],["0.012364","123134"],["0.012365","0"],["0.012398","256995"],["0.012402","129096"],["0.012410","151959"],["0.012464","25304"],["0.012469","9204"],["0.012470","387892"],["0.012495","2789442"],["0.012496","84970"],["0.012502","184715"],["0.012519","1729"],["0.012527","1468"]]}}
1618677472.426563: {"stream":"yfiusdt@depth@100ms","data":{"e":"depthUpdate","E":1618677472369,"T":1618677472361,"s":"YFIUSDT","U":335341327388,"u":335341330706,"pu":335341325870,"b":[["49380.6","0.000"],["49855.3","0.000"],["49891.8","0.000"],["49923.4","0.000"],["49923.9","0.100"],["50000.5","0.000"],["50002.5","0.000"],["50002.6","0.002"]],"a":[["50011.7","0.000"],["50014.5","0.001"],["50095.4","0.000"],["50195.3","0.000"],["51152.5","0.047"]]}}
1618677472.454277: {"stream":"dentusdt@bookTicker","data":{"e":"bookTicker","u":335341331629,"s":"DENTUSDT","b":"0.012346","B":"17697","a":"0.012356","A":"64357","T":1618677472392,"E":1618677472395}}
1618677472.4820101: {"stream":"xmrusdt@depth@100ms","data":{"e":"depthUpdate","E":1618677472423,"T":1618677472381,"s":"XMRUSDT","U":335341329519,"u":335341331317,"pu":335341329252,"b":[["351.48","157.544"],["351.56","0.000"],["351.59","0.027"],["352.11","5.069"],["352.12","0.000"],["352.19","15.460"],["352.21","2.500"],["352.22","0.000"]],"a":[["352.55","0.000"],["355.36","2.406"]]}}
1618677472.503989: {"stream":"dentusdt@bookTicker","data":{"e":"bookTicker","u":335341332943,"s":"DENTUSDT","b":"0.012346","B":"17697","a":"0.012356","A":"60901","T":1618677472443,"E":1618677472447}}
1618677472.522035: {"stream":"ksmusdt@depth@100ms","data":{"e":"depthUpdate","E":1618677472465,"T":1618677472449,"s":"KSMUSDT","U":335341330720,"u":335341333091,"pu":335341330549,"b":[["458.561","0.1"]],"a":[["459.193","1.4"],["459.194","0.0"],["459.415","0.1"]]}}
1618677472.529849: {"stream":"yfiusdt@depth@100ms","data":{"e":"depthUpdate","E":1618677472471,"T":1618677472441,"s":"YFIUSDT","U":335341330907,"u":335341332916,"pu":335341330706,"b":[["49219.0","0.000"],["49854.0","0.005"],["49942.8","0.025"]],"a":[["50736.0","0.394"]]}}
1618677472.534688: {"stream":"dentusdt@depth@100ms","data":{"e":"depthUpdate","E":1618677472476,"T":1618677472464,"s":"DENTUSDT","U":335341331073,"u":335341333414,"pu":335341330635,"b":[["0.012208","14737"],["0.012218","86903"],["0.012221","82526"],["0.012237","44675"],["0.012242","314631"],["0.012245","44539"],["0.012267","69773"],["0.012333","0"],["0.012339","16945"]],"a":[["0.012356","60901"],["0.012358","3456"],["0.012359","94455"],["0.012367","53977"],["0.012469","1193"],["0.012470","379882"],["0.012472","63261"],["0.012492","66265"],["0.012493","660569"],["0.012495","2781448"],["0.012497","46122"]]}}
1618677472.572778: {"stream":"ksmusdt@bookTicker","data":{"e":"bookTicker","u":335341334515,"s":"KSMUSDT","b":"458.869","B":"0.2","a":"458.975","A":"0.1","T":1618677472511,"E":1618677472515}}
1618677472.584355: {"stream":"dentusdt@bookTicker","data":{"e":"bookTicker","u":335341334780,"s":"DENTUSDT","b":"0.012346","B":"17697","a":"0.012356","A":"6924","T":1618677472524,"E":1618677472527}}
1618677472.612872: {"stream":"ksmusdt@bookTicker","data":{"e":"bookTicker","u":335341335355,"s":"KSMUSDT","b":"458.868","B":"6.4","a":"458.975","A":"0.1","T":1618677472550,"E":1618677472554}}
1618677472.624605: {"stream":"xmrusdt@depth@100ms","data":{"e":"depthUpdate","E":1618677472567,"T":1618677472562,"s":"XMRUSDT","U":335341333364,"u":335341335606,"pu":335341331317,"b":[["352.21","0.000"],["352.27","3.482"]],"a":[["352.83","16.570"],["353.00","0.000"]]}}
1618677472.62481: {"stream":"dentusdt@bookTicker","data":{"e":"bookTicker","u":335341335649,"s":"DENTUSDT","b":"0.012346","B":"17697","a":"0.012356","A":"60901","T":1618677472564,"E":1618677472567}}
1618677472.6298418: {"stream":"ksmusdt@depth@100ms","data":{"e":"depthUpdate","E":1618677472573,"T":1618677472562,"s":"KSMUSDT","U":335341333513,"u":335341335579,"pu":335341333091,"b":[["458.783","0.2"],["458.812","1.2"],["458.813","0.0"],["458.814","0.0"],["458.869","0.0"]],"a":[["459.183","0.2"],["459.184","1.2"],["459.191","0.0"],["459.192","1.6"],["459.193","0.0"],["459.212","0.0"],["459.564","2.2"],["459.949","3.2"],["460.330","3.7"],["462.870","5.6"],["464.621","6.5"]]}}
1618677472.642231: {"stream":"yfiusdt@depth@100ms","data":{"e":"depthUpdate","E":1618677472583,"T":1618677472576,"s":"YFIUSDT","U":335341333745,"u":335341335933,"pu":335341332916,"b":[["49410.2","0.030"],["49734.2","0.007"],["49850.6","0.000"],["49890.2","0.020"]],"a":[["50124.3","0.001"],["50127.6","0.009"],["50736.0","0.000"],["51282.4","0.022"]]}}
1618677472.643726: {"stream":"dentusdt@depth@100ms","data":{"e":"depthUpdate","E":1618677472585,"T":1618677472581,"s":"DENTUSDT","U":335341333764,"u":335341336034,"pu":335341333414,"b":[["0.012242","290154"],["0.012244","57242"],["0.012262","352890"],["0.012267","45347"],["0.012269","51063"],["0.012339","3446"],["0.012344","97156"]],"a":[["0.012356","60901"],["0.012358","0"],["0.012359","40478"],["0.012361","57433"],["0.012367","53977"],["0.012448","48592"],["0.012470","371872"],["0.012475","45779"],["0.012476","109230"],["0.012495","2765460"],["0.012500","68072"],["0.012502","176727"]]}}
1618677472.7142599: {"stream":"yfiusdt@bookTicker","data":{"e":"bookTicker","u":335341337556,"s":"YFIUSDT","b":"50005.6","B":"0.055","a":"50014.5","A":"0.001","T":1618677472651,"E":1618677472656}}
1618677472.71436: {"stream":"ksmusdt@bookTicker","data":{"e":"bookTicker","u":335341337576,"s":"KSMUSDT","b":"458.868","B":"6.4","a":"458.922","A":"0.1","T":1618677472652,"E":1618677472656}}
1618677472.724185: {"stream":"xmrusdt@depth@100ms","data":{"e":"depthUpdate","E":1618677472667,"T":1618677472563,"s":"XMRUSDT","U":335341335619,"u":335341335619,"pu":335341335606,"b":[],"a":[["352.99","49.742"]]}}
1618677472.740551: {"stream":"ksmusdt@depth@100ms","data":{"e":"depthUpdate","E":1618677472682,"T":1618677472675,"s":"KSMUSDT","U":335341336009,"u":335341338157,"pu":335341335579,"b":[["458.783","0.0"],["458.788","1.2"],["458.812","0.0"],["458.813","0.2"]],"a":[["458.922","0.1"],["459.181","0.2"],["459.182","1.6"],["459.183","0.0"],["459.184","0.0"],["459.192","0.0"],["459.212","0.2"],["459.240","1.0"],["459.243","0.0"],["459.520","0.0"]]}}
1618677472.740872: {"stream":"yfiusdt@depth@100ms","data":{"e":"depthUpdate","E":1618677472684,"T":1618677472671,"s":"YFIUSDT","U":335341336024,"u":335341338060,"pu":335341335933,"b":[["49518.8","0.000"],["49850.6","0.030"],["49890.2","0.000"],["50006.1","0.000"]],"a":[]}}
1618677472.742454: {"stream":"dentusdt@bookTicker","data":{"e":"bookTicker","u":335341338300,"s":"DENTUSDT","b":"0.012346","B":"17697","a":"0.012356","A":"6924","T":1618677472681,"E":1618677472684}}
1618677472.748825: {"stream":"dentusdt@kline_1m","data":{"e":"kline","E":1618677472691,"s":"DENTUSDT","k":{"t":1618677420000,"T":1618677479999,"s":"DENTUSDT","i":"1m","f":15787262,"L":15787453,"o":"0.012366","c":"0.012346","h":"0.012366","l":"0.012339","v":"3067181","n":192,"x":false,"q":"37883.728553","V":"1266681","Q":"15650.248000","B":"0"}}}
1618677472.748897: {"stream":"dentusdt@bookTicker","data":{"e":"bookTicker","u":335341338421,"s":"DENTUSDT","b":"0.012346","B":"16697","a":"0.012356","A":"6924","T":1618677472688,"E":1618677472691}}
1618677472.754362: {"stream":"dentusdt@depth@100ms","data":{"e":"depthUpdate","E":1618677472696,"T":1618677472688,"s":"DENTUSDT","U":335341336217,"u":335341338421,"pu":335341336034,"b":[["0.012245","36382"],["0.012270","127220"],["0.012339","16945"],["0.012346","16697"]],"a":[["0.012356","6924"],["0.012359","3456"],["0.012361","94455"],["0.012367","0"],["0.012396","202356"],["0.012472","55323"],["0.012477","87271"]]}}
1618677472.759886: {"stream":"yfiusdt@bookTicker","data":{"e":"bookTicker","u":335341338667,"s":"YFIUSDT","b":"50002.6","B":"0.002","a":"50014.5","A":"0.001","T":1618677472696,"E":1618677472700}}
1618677472.76177: {"stream":"dentusdt@bookTicker","data":{"e":"bookTicker","u":335341338764,"s":"DENTUSDT","b":"0.012346","B":"16697","a":"0.012357","A":"9470","T":1618677472700,"E":1618677472703}}
1618677472.771468: {"stream":"dentusdt@bookTicker","data":{"e":"bookTicker","u":335341339040,"s":"DENTUSDT","b":"0.012346","B":"16697","a":"0.012359","A":"3456","T":1618677472711,"E":1618677472715}}
1618677472.782175: {"stream":"dentusdt@bookTicker","data":{"e":"bookTicker","u":335341339242,"s":"DENTUSDT","b":"0.012346","B":"16697","a":"0.012359","A":"12375","T":1618677472718,"E":1618677472722}}
1618677472.7991092: {"stream":"yfiusdt@bookTicker","data":{"e":"bookTicker","u":335341339731,"s":"YFIUSDT","b":"50002.4","B":"0.055","a":"50014.5","A":"0.001","T":1618677472738,"E":1618677472742}}
1618677472.83153: {"stream":"xmrusdt@depth@100ms","data":{"e":"depthUpdate","E":1618677472773,"T":1618677472713,"s":"XMRUSDT","U":335341338007,"u":335341339111,"pu":335341335619,"b":[["351.48","155.544"],["351.55","4.000"],["352.11","3.069"],["352.18","4.335"]],"a":[["352.56","3.268"],["363.24","0.000"]]}}
1618677472.848403: {"stream":"ksmusdt@depth@100ms","data":{"e":"depthUpdate","E":1618677472789,"T":1618677472768,"s":"KSMUSDT","U":335341338393,"u":335341340496,"pu":335341338157,"b":[["457.912","0.0"],["458.175","1.9"],["458.342","1.1"],["458.788","0.0"],["458.847","0.0"]],"a":[["459.182","0.0"],["459.211","1.6"],["465.531","3.2"]]}}
1618677472.848655: {"stream":"dentusdt@bookTicker","data":{"e":"bookTicker","u":335341340861,"s":"DENTUSDT","b":"0.012346","B":"16697","a":"0.012359","A":"52853","T":1618677472788,"E":1618677472790}}
1618677472.854761: {"stream":"dentusdt@depth@100ms","data":{"e":"depthUpdate","E":1618677472796,"T":1618677472790,"s":"DENTUSDT","U":335341338590,"u":335341340904,"pu":335341338421,"b":[["0.000011","21805663"],["0.012112","536546"],["0.012242","249359"],["0.012243","147179"],["0.012267","8707"],["0.012268","101981"],["0.012309","15955"],["0.012339","3446"],["0.012344","110648"]],"a":[["0.012356","0"],["0.012357","0"],["0.012359","52853"],["0.012360","78292"],["0.012361","53970"],["0.012362","53719"],["0.012363","274108"],["0.012364","65196"],["0.012365","133881"],["0.012367","53977"],["0.012383","76103"],["0.012384","66054"],["0.012386","84532"],["0.012443","702787"],["0.012467","7941"],["0.012470","351847"],["0.012472","99439"],["0.012495","2749472"],["0.012497","30137"]]}}
1618677472.8587399: {"stream":"yfiusdt@depth@100ms","data":{"e":"depthUpdate","E":1618677472800,"T":1618677472784,"s":"YFIUSDT","U":335341338667,"u":335341340817,"pu":335341338060,"b":[["49256.0","0.567"],["49974.6","0.168"],["49986.9","0.002"],["49987.0","0.010"],["50002.6","0.000"],["50005.6","0.000"]],"a":[["50436.1","0.000"]]}}
1618677472.8647208: {"stream":"xmrusdt@bookTicker","data":{"e":"bookTicker","u":335341341211,"s":"XMRUSDT","b":"352.45","B":"1.787","a":"352.53","A":"0.073","T":1618677472804,"E":1618677472807}}
1618677472.893995: {"stream":"xmrusdt@bookTicker","data":{"e":"bookTicker","u":335341341721,"s":"XMRUSDT","b":"352.46","B":"3.700","a":"352.53","A":"0.073","T":1618677472828,"E":1618677472833}}
1618677472.899592: {"stream":"dentusdt@aggTrade","data":{"e":"aggTrade","E":1618677472842,"a":8476446,"s":"DENTUSDT","p":"0.012346","q":"1000","f":15787453,"l":15787453,"T":1618677472688,"m":true}}
1618677472.910315: {"stream":"yfiusdt@bookTicker","data":{"e":"bookTicker","u":335341342129,"s":"YFIUSDT","b":"50002.4","B":"0.055","a":"50022.8","A":"0.002","T":1618677472848,"E":1618677472852}}
1618677472.918838: {"stream":"yfiusdt@bookTicker","data":{"e":"bookTicker","u":335341342256,"s":"YFIUSDT","b":"50002.4","B":"0.055","a":"50008.5","A":"0.001","T":1618677472854,"E":1618677472859}}
1618677472.944544: {"stream":"xmrusdt@depth@100ms","data":{"e":"depthUpdate","E":1618677472887,"T":1618677472874,"s":"XMRUSDT","U":335341340789,"u":335341342620,"pu":335341339111,"b":[["352.20","5.351"],["352.27","0.982"],["352.33","0.000"],["352.36","0.000"],["352.44","2.609"],["352.45","1.787"],["352.46","3.700"]],"a":[["353.01","0.000"],["357.28","0.551"],["357.40","1.762"]]}}
1618677472.952371: {"stream":"ksmusdt@depth@100ms","data":{"e":"depthUpdate","E":1618677472894,"T":1618677472876,"s":"KSMUSDT","U":335341340887,"u":335341342634,"pu":335341340496,"b":[["458.516","0.0"],["458.790","1.2"]],"a":[["459.240","0.0"],["461.767","20.0"]]}}
1618677472.95665: {"stream":"dentusdt@depth@100ms","data":{"e":"depthUpdate","E":1618677472899,"T":1618677472868,"s":"DENTUSDT","U":335341340982,"u":335341342498,"pu":335341340904,"b":[["0.012243","139021"],["0.012267","565"],["0.012268","93839"]],"a":[["0.012360","24317"],["0.012362","107689"],["0.012367","53977"],["0.012381","34951"],["0.012383","63554"],["0.012443","694831"],["0.012470","335827"]]}}
1618677472.9649: {"stream":"dentusdt@aggTrade","data":{"e":"aggTrade","E":1618677472906,"a":8476447,"s":"DENTUSDT","p":"0.012346","q":"16697","f":15787454,"l":15787455,"T":1618677472902,"m":true}}
1618677472.965004: {"stream":"dentusdt@bookTicker","data":{"e":"bookTicker","u":335341343142,"s":"DENTUSDT","b":"0.012344","B":"107345","a":"0.012359","A":"52853","T":1618677472902,"E":1618677472906}}
1618677472.9650528: {"stream":"yfiusdt@depth@100ms","data":{"e":"depthUpdate","E":1618677472907,"T":1618677472894,"s":"YFIUSDT","U":335341341200,"u":335341342954,"pu":335341340817,"b":[["49650.3","0.009"],["49908.2","0.019"],["49923.9","0.000"],["49944.5","0.018"],["49960.6","0.017"],["49973.1","0.000"],["49973.2","0.000"],["49975.0","0.017"],["49975.8","0.311"],["49980.0","0.017"],["49986.9","0.000"],["49987.0","0.000"],["49987.1","0.000"],["49987.2","0.000"],["49987.3","0.002"]],"a":[["50008.5","0.001"],["50014.5","0.000"],["50022.9","0.000"],["50024.7","0.014"],["50211.4","0.008"],["50764.7","0.550"]]}}
1618677472.971207: {"stream":"dentusdt@bookTicker","data":{"e":"bookTicker","u":335341343265,"s":"DENTUSDT","b":"0.012344","B":"93853","a":"0.012359","A":"52853","T":1618677472909,"E":1618677472912}}
1618677472.9713101: {"stream":"dentusdt@bookTicker","data":{"e":"bookTicker","u":335341343267,"s":"DENTUSDT","b":"0.012344","B":"93853","a":"0.012359","A":"12375","T":1618677472909,"E":1618677472912}}
1618677472.989125: {"stream":"dentusdt@bookTicker","data":{"e":"bookTicker","u":335341343733,"s":"DENTUSDT","b":"0.012344","B":"48579","a":"0.012359","A":"12375","T":1618677472927,"E":1618677472931}}
1618677472.999976: {"stream":"yfiusdt@bookTicker","data":{"e":"bookTicker","u":335341343861,"s":"YFIUSDT","b":"50002.4","B":"0.055","a":"50007.2","A":"0.006","T":1618677472936,"E":1618677472940}}
1618677473.008085: {"stream":"dentusdt@bookTicker","data":{"e":"bookTicker","u":335341344066,"s":"DENTUSDT","b":"0.012344","B":"48579","a":"0.012359","A":"106828","T":1618677472944,"E":1618677472950}}
1618677473.0081909: {"stream":"ksmusdt@bookTicker","data":{"e":"bookTicker","u":335341344142,"s":"KSMUSDT","b":"458.879","B":"5.2","a":"458.922","A":"0.1","T":1618677472945,"E":1618677472950}}
1618677473.013257: {"stream":"ksmusdt@bookTicker","data":{"e":"bookTicker","u":335341344469,"s":"KSMUSDT","b":"458.868","B":"6.4","a":"458.922","A":"0.1","T":1618677472950,"E":1618677472954}}
1618677473.014233: {"stream":"dentusdt@bookTicker","data":{"e":"bookTicker","u":335341344547,"s":"DENTUSDT","b":"0.012344","B":"48579","a":"0.012358","A":"4425","T":1618677472952,"E":1618677472955}}
1618677473.014335: {"stream":"dentusdt@bookTicker","data":{"e":"bookTicker","u":335341344552,"s":"DENTUSDT","b":"0.012345","B":"4078","a":"0.012358","A":"4425","T":1618677472952,"E":1618677472956}}
1618677473.023916: {"stream":"dentusdt@bookTicker","data":{"e":"bookTicker","u":335341344850,"s":"DENTUSDT","b":"0.012345","B":"4078","a":"0.012357","A":"8990","T":1618677472963,"E":1618677472967}}
1618677473.064194: {"stream":"dentusdt@depth@100ms","data":{"e":"depthUpdate","E":1618677473006,"T":1618677473000,"s":"DENTUSDT","U":335341343134,"u":335341345701,"pu":335341342498,"b":[["0.012243","130863"],["0.012268","85697"],["0.012314","0"],["0.012326","353898"],["0.012335","0"],["0.012339","16943"],["0.012344","48579"],["0.012345","4078"],["0.012346","0"]],"a":[["0.012357","8990"],["0.012358","4425"],["0.012359","97909"],["0.012360","17393"],["0.012361","6929"],["0.012362","53719"],["0.012365","133881"],["0.012367","57938"],["0.012371","471215"],["0.012380","404875"],["0.012382","496134"],["0.012390","0"],["0.012394","43041"],["0.012443","686875"],["0.012467","0"],["0.012596","135125"]]}}
1618677473.072233: {"stream":"ksmusdt@depth@100ms","data":{"e":"depthUpdate","E":1618677473015,"T":1618677472982,"s":"KSMUSDT","U":335341343355,"u":335341345242,"pu":335341342634,"b":[["446.652","0.0"],["455.410","0.0"],["455.459","4.0"],["457.131","0.0"],["457.180","0.1"],["458.340","0.0"],["458.341","0.0"],["458.343","18.5"],["458.784","1.2"],["458.790","0.0"],["458.879","0.0"]],"a":[["459.210","1.0"],["460.571","0.0"],["460.621","0.1"],["462.292","0.0"],["462.342","0.1"]]}}
1618677473.082399: {"stream":"yfiusdt@bookTicker","data":{"e":"bookTicker","u":335341346481,"s":"YFIUSDT","b":"50002.5","B":"0.012","a":"50007.2","A":"0.006","T":1618677473020,"E":1618677473024}}
1618677473.096711: {"stream":"yfiusdt@depth@100ms","data":{"e":"depthUpdate","E":1618677473038,"T":1618677473022,"s":"YFIUSDT","U":335341343805,"u":335341346517,"pu":335341342954,"b":[["49554.4","0.083"],["49558.8","0.000"],["49740.5","0.000"],["49779.4","0.083"],["49783.8","0.000"],["49848.6","0.000"],["49975.9","0.072"],["49987.3","0.000"],["49988.7","0.012"],["49988.8","0.002"],["50002.5","0.012"]],"a":[["50007.2","0.006"],["50024.6","0.002"],["50054.2","0.024"],["50061.7","0.013"],["50062.9","0.000"],["50067.5","0.013"],["50070.4","0.000"],["50076.1","0.000"],["50200.2","0.000"],["50229.4","0.083"],["50233.8","0.000"],["50255.6","0.000"],["50454.4","0.083"],["50458.8","0.000"]]}}
1618677473.103094: {"stream":"xmrusdt@depth@100ms","data":{"e":"depthUpdate","E":1618677473044,"T":1618677473023,"s":"XMRUSDT","U":335341343980,"u":335341346553,"pu":335341342620,"b":[["352.03","0.000"],["352.20","2.851"],["352.28","6.447"],["352.44","2.151"]],"a":[["352.82","3.479"]]}}
1618677473.115872: {"stream":"dentusdt@aggTrade","data":{"e":"aggTrade","E":1618677473057,"a":8476448,"s":"DENTUSDT","p":"0.012344","q":"3303","f":15787456,"l":15787456,"T":1618677472902,"m":true}}
1618677473.238559: {"stream":"dentusdt@bookTicker","data":{"e":"bookTicker","u":335341348036,"s":"DENTUSDT","b":"0.012345","B":"4078","a":"0.012357","A":"49468","T":1618677473063,"E":1618677473066}}
1618677473.24342: {"stream":"ksmusdt@depth@100ms","data":{"e":"depthUpdate","E":1618677473116,"T":1618677473107,"s":"KSMUSDT","U":335341346154,"u":335341349268,"pu":335341345242,"b":[["456.973","2.1"],["457.205","1.1"],["458.344","4.4"],["458.643","1.5"]],"a":[["459.208","0.7"],["459.209","1.6"],["459.211","0.0"],["459.241","1.6"],["459.374","0.1"],["459.399","0.0"],["459.439","0.1"],["459.451","0.0"],["459.529","0.1"],["459.555","0.0"],["460.017","0.3"],["460.740","0.0"],["460.979","0.0"],["460.989","0.0"]]}}
1618677473.246473: {"stream":"dentusdt@depth@100ms","data":{"e":"depthUpdate","E":1618677473123,"T":1618677473107,"s":"DENTUSDT","U":335341346463,"u":335341349269,"pu":335341345701,"b":[],"a":[["0.012357","49468"],["0.012358","58402"],["0.012359","3456"],["0.012361","60906"],["0.012363","407989"],["0.012364","119173"],["0.012365","0"],["0.012367","0"]]}}
1618677473.2508328: {"stream":"yfiusdt@depth@100ms","data":{"e":"depthUpdate","E":1618677473146,"T":1618677473097,"s":"YFIUSDT","U":335341347309,"u":335341349021,"pu":335341346517,"b":[["49552.4","0.404"],["49606.4","0.000"],["49988.7","0.000"]],"a":[["50446.5","0.000"],["50458.6","0.396"]]}}
1618677473.255892: {"stream":"ksmusdt@bookTicker","data":{"e":"bookTicker","u":335341350202,"s":"KSMUSDT","b":"458.869","B":"1.3","a":"458.922","A":"0.1","T":1618677473170,"E":1618677473173}}
1618677473.256: {"stream":"ksmusdt@bookTicker","data":{"e":"bookTicker","u":335341350311,"s":"KSMUSDT","b":"458.868","B":"6.4","a":"458.922","A":"0.1","T":1618677473175,"E":1618677473179}}
1618677473.256046: {"stream":"ksmusdt@bookTicker","data":{"e":"bookTicker","u":335341350426,"s":"KSMUSDT","b":"458.868","B":"6.4","a":"458.975","A":"0.1","T":1618677473177,"E":1618677473181}}
1618677473.25608: {"stream":"dentusdt@bookTicker","data":{"e":"bookTicker","u":335341350489,"s":"DENTUSDT","b":"0.012345","B":"4078","a":"0.012357","A":"8990","T":1618677473180,"E":1618677473184}}
1618677473.2574131: {"stream":"ksmusdt@bookTicker","data":{"e":"bookTicker","u":335341350821,"s":"KSMUSDT","b":"458.868","B":"6.4","a":"458.896","A":"0.1","T":1618677473189,"E":1618677473197}}
1618677473.263906: {"stream":"dentusdt@bookTicker","data":{"e":"bookTicker","u":335341351179,"s":"DENTUSDT","b":"0.012345","B":"4078","a":"0.012357","A":"494467","T":1618677473201,"E":1618677473205}}
1618677473.264415: {"stream":"ksmusdt@bookTicker","data":{"e":"bookTicker","u":335341351193,"s":"KSMUSDT","b":"458.869","B":"1.5","a":"458.896","A":"0.1","T":1618677473202,"E":1618677473206}}
1618677473.270273: {"stream":"yfiusdt@bookTicker","data":{"e":"bookTicker","u":335341351359,"s":"YFIUSDT","b":"50002.4","B":"0.055","a":"50007.2","A":"0.006","T":1618677473206,"E":1618677473210}}
1618677473.270373: {"stream":"yfiusdt@bookTicker","data":{"e":"bookTicker","u":335341351472,"s":"YFIUSDT","b":"50002.5","B":"0.012","a":"50007.2","A":"0.006","T":1618677473211,"E":1618677473213}}
1618677473.277714: {"stream":"ksmusdt@bookTicker","data":{"e":"bookTicker","u":335341351618,"s":"KSMUSDT","b":"458.868","B":"6.4","a":"458.896","A":"0.1","T":1618677473215,"E":1618677473219}}
1618677473.279943: {"stream":"ksmusdt@depth@100ms","data":{"e":"depthUpdate","E":1618677473222,"T":1618677473217,"s":"KSMUSDT","U":335341349385,"u":335341351667,"pu":335341349268,"b":[["458.847","0.0"],["458.852","0.0"],["458.869","0.0"]],"a":[["458.896","0.1"],["458.922","0.0"],["459.208","0.0"],["459.534","0.8"],["459.541","0.0"],["460.017","0.6"],["460.951","0.4"]]}}
1618677473.299671: {"stream":"dentusdt@depth@100ms","data":{"e":"depthUpdate","E":1618677473242,"T":1618677473233,"s":"DENTUSDT","U":335341349599,"u":335341352173,"pu":335341349269,"b":[["0.012172","83169"],["0.012333","3238"],["0.012339","3446"]],"a":[["0.012357","494467"],["0.012358","4425"],["0.012360","76514"],["0.012361","47407"],["0.012362","102552"],["0.012364","119173"],["0.012365","57938"],["0.012380","408113"]]}}
1618677473.3160691: {"stream":"dentusdt@bookTicker","data":{"e":"bookTicker","u":335341352827,"s":"DENTUSDT","b":"0.012345","B":"4078","a":"0.012357","A":"497923","T":1618677473255,"E":1618677473258}}
1618677473.319277: {"stream":"dentusdt@bookTicker","data":{"e":"bookTicker","u":335341352861,"s":"DENTUSDT","b":"0.012345","B":"4078","a":"0.012356","A":"5144","T":1618677473256,"E":1618677473261}}
1618677473.323427: {"stream":"dentusdt@bookTicker","data":{"e":"bookTicker","u":335341352991,"s":"DENTUSDT","b":"0.012344","B":"48579","a":"0.012356","A":"5144","T":1618677473260,"E":1618677473265}}
1618677473.361823: {"stream":"yfiusdt@bookTicker","data":{"e":"bookTicker","u":335341354242,"s":"YFIUSDT","b":"49988.8","B":"0.002","a":"50007.2","A":"0.006","T":1618677473298,"E":1618677473304}}
1618677473.3624399: {"stream":"yfiusdt@depth@100ms","data":{"e":"depthUpdate","E":1618677473306,"T":1618677473298,"s":"YFIUSDT","U":335341351250,"u":335341354242,"pu":335341349021,"b":[["49942.1","0.000"],["49960.7","0.026"],["49961.2","0.000"],["49962.8","0.001"],["49967.0","0.000"],["49968.6","0.002"],["49972.0","0.000"],["49973.4","0.002"],["50002.4","0.000"],["50002.5","0.000"]],"a":[["50076.7","0.000"],["50087.6","0.026"]]}}
1618677473.367551: {"stream":"yfiusdt@bookTicker","data":{"e":"bookTicker","u":335341354353,"s":"YFIUSDT","b":"50002.5","B":"0.013","a":"50007.2","A":"0.006","T":1618677473304,"E":1618677473309}}
1618677473.3732202: {"stream":"yfiusdt@bookTicker","data":{"e":"bookTicker","u":335341354566,"s":"YFIUSDT","b":"49988.8","B":"0.002","a":"50007.2","A":"0.006","T":1618677473309,"E":1618677473314}}
1618677473.377931: {"stream":"yfiusdt@bookTicker","data":{"e":"bookTicker","u":335341354694,"s":"YFIUSDT","b":"49988.9","B":"0.006","a":"50007.2","A":"0.006","T":1618677473314,"E":1618677473318}}
1618677473.377999: {"stream":"yfiusdt@bookTicker","data":{"e":"bookTicker","u":335341354710,"s":"YFIUSDT","b":"49988.8","B":"0.002","a":"50007.2","A":"0.006","T":1618677473314,"E":1618677473318}}
1618677473.378026: {"stream":"yfiusdt@bookTicker","data":{"e":"bookTicker","u":335341354718,"s":"YFIUSDT","b":"50002.5","B":"0.013","a":"50007.2","A":"0.006","T":1618677473314,"E":1618677473320}}
1618677473.3842409: {"stream":"yfiusdt@bookTicker","data":{"e":"bookTicker","u":335341354909,"s":"YFIUSDT","b":"49988.8","B":"0.002","a":"50007.2","A":"0.006","T":1618677473322,"E":1618677473324}}
1618677473.3877099: {"stream":"yfiusdt@bookTicker","data":{"e":"bookTicker","u":335341355051,"s":"YFIUSDT","b":"49988.9","B":"0.008","a":"50007.2","A":"0.006","T":1618677473326,"E":1618677473329}}
1618677473.387773: {"stream":"yfiusdt@bookTicker","data":{"e":"bookTicker","u":335341355088,"s":"YFIUSDT","b":"49991.2","B":"0.055","a":"50007.2","A":"0.006","T":1618677473327,"E":1618677473329}}
1618677473.394474: {"stream":"ksmusdt@depth@100ms","data":{"e":"depthUpdate","E":1618677473336,"T":1618677473287,"s":"KSMUSDT","U":335341352160,"u":335341353908,"pu":335341351667,"b":[["458.784","0.0"],["458.787","0.0"]],"a":[["459.159","0.2"],["459.160","1.2"],["459.181","0.0"],["459.207","0.0"],["459.209","1.6"],["462.014","0.3"]]}}
1618677473.398995: {"stream":"yfiusdt@bookTicker","data":{"e":"bookTicker","u":335341355262,"s":"YFIUSDT","b":"49991.3","B":"0.018","a":"50007.2","A":"0.006","T":1618677473336,"E":1618677473340}}
1618677473.406402: {"stream":"dentusdt@bookTicker","data":{"e":"bookTicker","u":335341355498,"s":"DENTUSDT","b":"0.012344","B":"48579","a":"0.012356","A":"99603","T":1618677473344,"E":1618677473348}}
1618677473.4086452: {"stream":"ksmusdt@bookTicker","data":{"e":"bookTicker","u":335341355505,"s":"KSMUSDT","b":"458.868","B":"6.4","a":"458.882","A":"0.1","T":1618677473344,"E":1618677473348}}
1618677473.408747: {"stream":"dentusdt@bookTicker","data":{"e":"bookTicker","u":335341355506,"s":"DENTUSDT","b":"0.012344","B":"48579","a":"0.012356","A":"153584","T":1618677473344,"E":1618677473348}}
1618677473.4112482: {"stream":"yfiusdt@bookTicker","data":{"e":"bookTicker","u":335341355582,"s":"YFIUSDT","b":"49991.2","B":"0.055","a":"50007.2","A":"0.006","T":1618677473347,"E":1618677473352}}
1618677473.4149702: {"stream":"dentusdt@depth@100ms","data":{"e":"depthUpdate","E":1618677473356,"T":1618677473348,"s":"DENTUSDT","U":335341352747,"u":335341355605,"pu":335341352173,"b":[["0.012326","379260"],["0.012333","16737"],["0.012345","0"]],"a":[["0.012356","153584"],["0.012357","497923"],["0.012358","0"],["0.012359","6931"],["0.012360","0"],["0.012361","107712"],["0.012362","48575"],["0.012363","413389"],["0.012364","65196"],["0.012385","76459"]]}}
1618677473.4156108: {"stream":"yfiusdt@bookTicker","data":{"e":"bookTicker","u":335341355732,"s":"YFIUSDT","b":"49991.3","B":"0.017","a":"50007.2","A":"0.006","T":1618677473355,"E":1618677473358}}
1618677473.420372: {"stream":"yfiusdt@bookTicker","data":{"e":"bookTicker","u":335341355776,"s":"YFIUSDT","b":"49991.4","B":"0.002","a":"50007.2","A":"0.006","T":1618677473357,"E":1618677473362}}
1618677473.420477: {"stream":"yfiusdt@bookTicker","data":{"e":"bookTicker","u":335341355818,"s":"YFIUSDT","b":"49993.6","B":"0.055","a":"50007.2","A":"0.006","T":1618677473358,"E":1618677473362}}
1618677473.428326: {"stream":"yfiusdt@bookTicker","data":{"e":"bookTicker","u":335341355995,"s":"YFIUSDT","b":"49993.6","B":"0.055","a":"49999.3","A":"0.001","T":1618677473365,"E":1618677473369}}
1618677473.429962: {"stream":"yfiusdt@bookTicker","data":{"e":"bookTicker","u":335341356077,"s":"YFIUSDT","b":"49993.7","B":"0.025","a":"49999.3","A":"0.001","T":1618677473368,"E":1618677473371}}
1618677473.430063: {"stream":"dentusdt@bookTicker","data":{"e":"bookTicker","u":335341356101,"s":"DENTUSDT","b":"0.012344","B":"48579","a":"0.012355","A":"3456","T":1618677473369,"E":1618677473371}}
1618677473.436878: {"stream":"yfiusdt@bookTicker","data":{"e":"bookTicker","u":335341356209,"s":"YFIUSDT","b":"49994.9","B":"0.012","a":"49999.3","A":"0.001","T":1618677473374,"E":1618677473377}}
1618677473.436981: {"stream":"xmrusdt@depth@100ms","data":{"e":"depthUpdate","E":1618677473378,"T":1618677473274,"s":"XMRUSDT","U":335341353512,"u":335341353512,"pu":335341346553,"b":[["342.38","70.095"]],"a":[]}}
1618677473.4411929: {"stream":"dentusdt@bookTicker","data":{"e":"bookTicker","u":335341356365,"s":"DENTUSDT","b":"0.012344","B":"48579","a":"0.012354","A":"9260","T":1618677473379,"E":1618677473383}}
1618677473.454519: {"stream":"yfiusdt@bookTicker","data":{"e":"bookTicker","u":335341356768,"s":"YFIUSDT","b":"49995.0","B":"0.002","a":"49999.3","A":"0.001","T":1618677473391,"E":1618677473395}}
1618677473.462073: {"stream":"yfiusdt@kline_1m","data":{"e":"kline","E":1618677473403,"s":"YFIUSDT","k":{"t":1618677420000,"T":1618677479999,"s":"YFIUSDT","i":"1m","f":64902095,"L":64902200,"o":"50010.8","c":"49999.3","h":"50044.2","l":"49950.6","v":"1.149","n":106,"x":false,"q":"57448.8936","V":"0.831","Q":"41549.5894","B":"0"}}}
1618677473.462198: {"stream":"yfiusdt@bookTicker","data":{"e":"bookTicker","u":335341356936,"s":"YFIUSDT","b":"49995.0","B":"0.002","a":"50022.8","A":"0.002","T":1618677473399,"E":1618677473404}}
1618677473.466288: {"stream":"yfiusdt@depth@100ms","data":{"e":"depthUpdate","E":1618677473409,"T":1618677473400,"s":"YFIUSDT","U":335341354353,"u":335341356961,"pu":335341354242,"b":[["49640.1","0.040"],["49905.3","0.100"],["49923.7","0.080"],["49929.6","0.000"],["49933.8","0.000"],["49936.4","0.080"],["49938.0","0.000"],["49942.2","0.110"],["49942.8","0.000"],["49944.5","0.000"],["49945.5","0.004"],["49946.4","0.110"],["49950.6","0.110"],["49954.8","0.000"],["49957.6","0.087"],["49960.6","0.000"],["49961.8","0.000"],["49966.2","0.000"],["49974.5","0.000"],["49974.6","0.000"],["49975.9","0.104"],["49980.0","0.000"],["49982.4","0.013"],["49985.0","0.000"],["49986.9","0.005"],["49988.8","0.000"],["49988.9","0.000"],["49991.2","0.055"],["49991.3","0.000"],["49991.4","0.000"],["49991.5","0.018"],["49993.6","0.055"],["49993.7","0.000"],["49994.9","0.012"],["49995.0","0.002"],["50002.5","0.000"]],"a":[["49999.3","0.000"],["50007.2","0.000"],["50008.5","0.000"],["50022.0","0.000"]]}}
1618677473.477887: {"stream":"yfiusdt@bookTicker","data":{"e":"bookTicker","u":335341357337,"s":"YFIUSDT","b":"49995.0","B":"0.002","a":"50020.9","A":"0.055","T":1618677473414,"E":1618677473418}}
1618677473.495063: {"stream":"ksmusdt@depth@100ms","data":{"e":"depthUpdate","E":1618677473438,"T":1618677473390,"s":"KSMUSDT","U":335341355230,"u":335341356741,"pu":335341353908,"b":[],"a":[["458.882","0.1"],["459.159","0.2"],["459.160","0.0"],["459.864","0.0"]]}}
1618677473.5200078: {"stream":"yfiusdt@bookTicker","data":{"e":"bookTicker","u":335341358318,"s":"YFIUSDT","b":"49995.0","B":"0.002","a":"50020.8","A":"0.002","T":1618677473455,"E":1618677473460}}
1618677473.525711: {"stream":"dentusdt@bookTicker","data":{"e":"bookTicker","u":335341358436,"s":"DENTUSDT","b":"0.012344","B":"48579","a":"0.012354","A":"49738","T":1618677473462,"E":1618677473466}}
1618677473.529887: {"stream":"dentusdt@depth@100ms","data":{"e":"depthUpdate","E":1618677473471,"T":1618677473465,"s":"DENTUSDT","U":335341356100,"u":335341358502,"pu":335341355605,"b":[["0.012306","29405"]],"a":[["0.012354","49738"],["0.012355","10387"],["0.012356","113110"],["0.012357","485477"],["0.012359","0"],["0.012361","133881"],["0.012363","279508"],["0.012364","123134"],["0.012365","0"],["0.012397","583582"],["0.012400","744951"]]}}
1618677473.549408: {"stream":"yfiusdt@bookTicker","data":{"e":"bookTicker","u":335341359078,"s":"YFIUSDT","b":"49997.5","B":"0.055","a":"50020.8","A":"0.002","T":1618677473485,"E":1618677473489}}
1618677473.563995: {"stream":"dentusdt@bookTicker","data":{"e":"bookTicker","u":335341359463,"s":"DENTUSDT","b":"0.012343","B":"217028","a":"0.012354","A":"49738","T":1618677473502,"E":1618677473505}}
1618677473.574077: {"stream":"yfiusdt@depth@100ms","data":{"e":"depthUpdate","E":1618677473514,"T":1618677473489,"s":"YFIUSDT","U":335341357225,"u":335341359154,"pu":335341356961,"b":[["49216.8","0.034"],["49655.5","0.009"],["49938.0","0.110"],["49942.2","0.110"],["49950.6","0.000"],["49954.8","0.000"],["49991.2","0.000"],["49997.5","0.055"]],"a":[["50020.8","0.002"],["50020.9","0.055"],["50021.7","0.013"],["50022.0","0.000"],["50022.8","0.000"],["50023.7","0.000"],["50024.6","0.000"],["50024.7","0.000"],["50041.0","0.032"],["50244.9","0.010"],["50257.9","0.005"],["50467.7","0.040"]]}}
1618677473.574432: {"stream":"xmrusdt@depth@100ms","data":{"e":"depthUpdate","E":1618677473516,"T":1618677473412,"s":"XMRUSDT","U":335341357274,"u":335341357274,"pu":335341353512,"b":[["343.06","69.875"]],"a":[]}}
1618677473.585349: {"stream":"yfiusdt@bookTicker","data":{"e":"bookTicker","u":335341360074,"s":"YFIUSDT","b":"49997.6","B":"0.002","a":"50020.8","A":"0.002","T":1618677473524,"E":1618677473527}}
1618677473.599592: {"stream":"ksmusdt@depth@100ms","data":{"e":"depthUpdate","E":1618677473541,"T":1618677473534,"s":"KSMUSDT","U":335341357863,"u":335341360339,"pu":335341356741,"b":[],"a":[["459.864","0.4"],["463.167","1.4"]]}}
1618677473.6125572: {"stream":"yfiusdt@aggTrade","data":{"e":"aggTrade","E":1618677473555,"a":52599717,"s":"YFIUSDT","p":"49999.3","q":"0.001","f":64902200,"l":64902200,"T":1618677473399,"m":false}}
1618677473.6290429: {"stream":"dentusdt@depth@100ms","data":{"e":"depthUpdate","E":1618677473571,"T":1618677473556,"s":"DENTUSDT","U":335341358602,"u":335341360895,"pu":335341358502,"b":[["0.012310","610825"],["0.012317","345579"],["0.012337","128504"],["0.012344","0"]],"a":[["0.012356","59129"],["0.012360","133881"],["0.012361","0"],["0.012362","57938"],["0.012363","225531"],["0.012364","65196"],["0.012380","404875"],["0.012381","331878"]]}}
1618677473.685463: {"stream":"yfiusdt@depth@100ms","data":{"e":"depthUpdate","E":1618677473622,"T":1618677473605,"s":"YFIUSDT","U":335341359957,"u":335341362431,"pu":335341359154,"b":[["49936.0","0.025"],["49975.8","0.000"],["49975.9","0.032"],["49991.5","0.000"],["49995.0","0.000"],["49997.6","0.002"]],"a":[["50020.9","0.000"],["50021.7","0.000"],["50023.5","0.013"],["50023.7","0.000"],["50195.2","0.000"]]}}
1618677473.709336: {"stream":"xmrusdt@depth@100ms","data":{"e":"depthUpdate","E":1618677473647,"T":1618677473543,"s":"XMRUSDT","U":335341360529,"u":335341360529,"pu":335341357274,"b":[["352.15","28.927"]],"a":[]}}
1618677473.735774: {"stream":"dentusdt@depth@100ms","data":{"e":"depthUpdate","E":1618677473677,"T":1618677473627,"s":"DENTUSDT","U":335341361342,"u":335341363049,"pu":335341360895,"b":[["0.012333","16748"],["0.012338","242132"]],"a":[["0.012355","64375"],["0.012361","53977"],["0.012416","108013"]]}}
1618677473.7638159: {"stream":"ksmusdt@bookTicker","data":{"e":"bookTicker","u":335341365057,"s":"KSMUSDT","b":"458.868","B":"6.4","a":"458.875","A":"0.1","T":1618677473702,"E":1618677473705}}
1618677473.7691891: {"stream":"yfiusdt@bookTicker","data":{"e":"bookTicker","u":335341365206,"s":"YFIUSDT","b":"49997.6","B":"0.002","a":"50009.2","A":"0.008","T":1618677473707,"E":1618677473711}}
1618677473.769289: {"stream":"ksmusdt@depth@100ms","data":{"e":"depthUpdate","E":1618677473713,"T":1618677473702,"s":"KSMUSDT","U":335341362543,"u":335341365057,"pu":335341360339,"b":[["456.220","1.7"],["457.613","0.0"],["457.777","2.0"]],"a":[["458.875","0.1"],["458.896","0.0"],["459.623","2.1"],["459.773","0.0"],["459.986","0.0"],["460.060","8.3"]]}}
1618677473.793383: {"stream":"yfiusdt@depth@100ms","data":{"e":"depthUpdate","E":1618677473734,"T":1618677473715,"s":"YFIUSDT","U":335341363155,"u":335341365367,"pu":335341362431,"b":[["49647.1","0.016"],["49918.4","0.010"],["49957.6","0.000"],["49970.1","0.315"]],"a":[["50009.2","0.008"],["50213.8","0.034"]]}}
1618677473.8344839: {"stream":"xmrusdt@depth@100ms","data":{"e":"depthUpdate","E":1618677473776,"T":1618677473684,"s":"XMRUSDT","U":335341364241,"u":335341364588,"pu":335341360529,"b":[["348.97","200.172"],["349.60","377.447"],["349.86","0.080"],["350.49","8.323"]],"a":[]}}
1618677473.893833: {"stream":"yfiusdt@depth@100ms","data":{"e":"depthUpdate","E":1618677473836,"T":1618677473830,"s":"YFIUSDT","U":335341365821,"u":335341368448,"pu":335341365367,"b":[["49760.8","0.009"],["49891.8","0.018"],["49970.2","0.168"],["49975.9","0.000"],["49978.1","0.032"]],"a":[["50036.5","0.032"],["50041.0","0.000"],["50220.5","0.007"]]}}
1618677473.9123461: {"stream":"ksmusdt@depth@100ms","data":{"e":"depthUpdate","E":1618677473855,"T":1618677473799,"s":"KSMUSDT","U":335341366335,"u":335341367658,"pu":335341365057,"b":[],"a":[["462.104","0.1"],["464.296","0.0"]]}}
1618677473.912529: {"stream":"dentusdt@depth@100ms","data":{"e":"depthUpdate","E":1618677473855,"T":1618677473837,"s":"DENTUSDT","U":335341366339,"u":335341368648,"pu":335341363049,"b":[["0.012333","16748"]],"a":[["0.012379","68968"],["0.012381","319330"]]}}
1618677473.943807: {"stream":"xmrusdt@depth@100ms","data":{"e":"depthUpdate","E":1618677473884,"T":1618677473835,"s":"XMRUSDT","U":335341367146,"u":335341368559,"pu":335341364588,"b":[["348.97","0.172"],["349.60","177.447"],["349.86","200.080"],["350.49","208.323"]],"a":[["361.50","4.972"]]}}
1618677473.950921: {"stream":"ksmusdt@bookTicker","data":{"e":"bookTicker","u":335341369885,"s":"KSMUSDT","b":"458.868","B":"6.4","a":"458.872","A":"0.1","T":1618677473888,"E":1618677473893}}
1618677474.0127099: {"stream":"ksmusdt@bookTicker","data":{"e":"bookTicker","u":335341371086,"s":"KSMUSDT","b":"458.870","B":"0.1","a":"458.872","A":"0.1","T":1618677473948,"E":1618677473954}}
1618677474.022812: {"stream":"ksmusdt@depth@100ms","data":{"e":"depthUpdate","E":1618677473965,"T":1618677473960,"s":"KSMUSDT","U":335341369220,"u":335341371342,"pu":335341367658,"b":[["458.870","0.1"]],"a":[["458.872","0.1"],["458.882","0.0"],["459.210","0.0"],["459.528","17.0"],["459.537","0.0"],["459.538","0.0"],["459.583","0.0"]]}}
1618677474.023398: {"stream":"dentusdt@kline_1m","data":{"e":"kline","E":1618677473967,"s":"DENTUSDT","k":{"t":1618677420000,"T":1618677479999,"s":"DENTUSDT","i":"1m","f":15787262,"L":15787457,"o":"0.012366","c":"0.012354","h":"0.012366","l":"0.012339","v":"3091467","n":196,"x":false,"q":"38183.591191","V":"1270967","Q":"15703.197244","B":"0"}}}
1618677474.027225: {"stream":"dentusdt@bookTicker","data":{"e":"bookTicker","u":335341371441,"s":"DENTUSDT","b":"0.012343","B":"217028","a":"0.012354","A":"45452","T":1618677473963,"E":1618677473968}}
1618677474.0273259: {"stream":"yfiusdt@depth@100ms","data":{"e":"depthUpdate","E":1618677473970,"T":1618677473962,"s":"YFIUSDT","U":335341369433,"u":335341371390,"pu":335341368448,"b":[["49640.4","0.006"],["49961.7","0.087"]],"a":[["51144.0","0.047"],["51175.7","0.047"],["51291.2","0.047"]]}}
1618677474.037521: {"stream":"yfiusdt@bookTicker","data":{"e":"bookTicker","u":335341371737,"s":"YFIUSDT","b":"49998.9","B":"0.012","a":"50009.2","A":"0.008","T":1618677473974,"E":1618677473979}}
1618677474.039488: {"stream":"yfiusdt@kline_1m","data":{"e":"kline","E":1618677473981,"s":"YFIUSDT","k":{"t":1618677420000,"T":1618677479999,"s":"YFIUSDT","i":"1m","f":64902095,"L":64902201,"o":"50010.8","c":"50009.2","h":"50044.2","l":"49950.6","v":"1.152","n":107,"x":false,"q":"57598.9212","V":"0.834","Q":"41699.6170","B":"0"}}}
1618677474.039548: {"stream":"yfiusdt@bookTicker","data":{"e":"bookTicker","u":335341371801,"s":"YFIUSDT","b":"49998.9","B":"0.012","a":"50009.2","A":"0.005","T":1618677473977,"E":1618677473982}}
1618677474.039572: {"stream":"dentusdt@bookTicker","data":{"e":"bookTicker","u":335341371808,"s":"DENTUSDT","b":"0.012343","B":"225857","a":"0.012354","A":"45452","T":1618677473977,"E":1618677473982}}
1618677474.0569658: {"stream":"yfiusdt@bookTicker","data":{"e":"bookTicker","u":335341372146,"s":"YFIUSDT","b":"49999.0","B":"0.002","a":"50009.2","A":"0.005","T":1618677473994,"E":1618677473999}}
1618677474.062616: {"stream":"xmrusdt@depth@100ms","data":{"e":"depthUpdate","E":1618677474004,"T":1618677473899,"s":"XMRUSDT","U":335341370127,"u":335341370127,"pu":335341368559,"b":[["343.22","69.842"]],"a":[]}}
1618677474.062769: {"stream":"yfiusdt@bookTicker","data":{"e":"bookTicker","u":335341372326,"s":"YFIUSDT","b":"50001.4","B":"0.055","a":"50009.2","A":"0.005","T":1618677473999,"E":1618677474004}}
1618677474.0732381: {"stream":"yfiusdt@bookTicker","data":{"e":"bookTicker","u":335341372634,"s":"YFIUSDT","b":"50002.7","B":"0.012","a":"50009.2","A":"0.005","T":1618677474010,"E":1618677474015}}
1618677474.076544: {"stream":"dentusdt@aggTrade","data":{"e":"aggTrade","E":1618677474017,"a":8476449,"s":"DENTUSDT","p":"0.012354","q":"4286","f":15787457,"l":15787457,"T":1618677473963,"m":false}}
