1626916403.8471181: {"stream":"bchusd_perp@depth@100ms","data":{"e":"depthUpdate","E":1626916403873,"T":1626916403864,"s":"BCHUSD_PERP","ps":"BCHUSD","U":167006084465,"u":167006084895,"pu":167006084238,"b":[["427.27","0"],["427.53","260"],["427.61","17"],["427.69","0"],["427.75","228"],["427.84","24"],["427.91","0"]],"a":[["427.90","669"],["427.91","24"],["427.92","670"],["428.19","676"]]}}
1626916404.5482519: {"stream":"linkusd_perp@depth@100ms","data":{"e":"depthUpdate","E":1626916403879,"T":1626916403858,"s":"LINKUSD_PERP","ps":"LINKUSD","U":167006084476,"u":167006084856,"pu":167006084212,"b":[["15.055","562"],["15.057","2739"]],"a":[["15.070","0"],["15.077","704"],["15.079","2756"]]}}
1626916405.1661901: {"stream":"bchusd_210924@depth@100ms","data":{"e":"depthUpdate","E":1626916403894,"T":1626916403882,"s":"BCHUSD_210924","ps":"BCHUSD","U":167006084552,"u":167006085029,"pu":167006084178,"b":[["429.10","40"],["429.21","0"],["429.28","126"]],"a":[["429.73","0"],["430.27","525"]]}}
1626916405.772149: {"stream":"etcusd_perp@depth@100ms","data":{"e":"depthUpdate","E":1626916403933,"T":1626916403925,"s":"ETCUSD_PERP","ps":"ETCUSD","U":167006084710,"u":167006085323,"pu":167006084599,"b":[["42.213","995"],["42.239","1656"],["42.244","56"],["42.246","992"],["42.261","25"],["42.264","90"],["42.267","1214"],["42.272","278"],["42.273","0"]],"a":[["42.298","100"],["42.299","200"],["42.301","0"],["42.302","300"],["42.303","0"],["42.311","0"],["42.320","1550"],["42.344","0"],["42.348","790"],["42.349","796"],["42.350","73"],["42.359","1549"],["42.371","30"]]}}
1626916406.387914: {"stream":"ethusd_210924@depth@100ms","data":{"e":"depthUpdate","E":1626916403933,"T":1626916403919,"s":"ETHUSD_210924","ps":"ETHUSD","U":167006084708,"u":167006085291,"pu":167006084663,"b":[["1984.58","0"],["1987.53","500"],["1987.56","0"],["1987.60","533"],["1987.66","0"],["1987.81","4138"],["1987.97","470"],["1988.24","321"],["1988.36","414"],["1988.64","365"],["1989.38","1073"],["1989.97","1829"],["1991.48","750"],["1991.49","292"],["1991.63","0"],["1991.64","0"],["1991.65","270"],["1991.99","0"],["1992.00","263"],["1992.02","0"],["1992.03","0"],["1992.17","65"]],"a":[["1992.18","1809"],["1992.28","650"],["1992.82","1000"]]}}
1626916407.0171342: {"stream":"xrpusd_perp@depth@100ms","data":{"e":"depthUpdate","E":1626916403961,"T":1626916403955,"s":"XRPUSD_PERP","ps":"XRPUSD","U":167006084834,"u":167006085522,"pu":167006084818,"b":[["0.5660","12078"],["0.5662","5271"],["0.5663","11113"],["0.5664","4515"],["0.5666","566"]],"a":[["0.5666","0"],["0.5667","7128"],["0.5668","8136"],["0.5669","1673"],["0.5672","4473"],["0.5673","3379"],["0.5678","13373"],["0.5679","4500"],["0.5680","1911"],["0.5684","945"]]}}
1626916407.6341162: {"stream":"bchusd_perp@depth@100ms","data":{"e":"depthUpdate","E":1626916403976,"T":1626916403970,"s":"BCHUSD_PERP","ps":"BCHUSD","U":167006084917,"u":167006085628,"pu":167006084895,"b":[["427.20","200"],["427.50","4617"],["427.57","0"],["427.61","17"],["427.66","2841"],["427.68","100"],["427.69","1048"],["427.75","128"],["427.77","0"],["427.81","0"],["427.84","0"]],"a":[["427.85","150"],["427.87","630"],["427.88","150"],["427.89","0"],["427.90","539"],["427.91","124"],["427.92","520"],["427.93","0"],["427.96","0"],["428.29","57"],["429.59","0"]]}}
1626916407.6341481: {"stream":"btcusd_211231@depth@100ms","data":{"e":"depthUpdate","E":1626916403983,"T":1626916403971,"s":"BTCUSD_211231","ps":"BTCUSD","U":167006085008,"u":167006085632,"pu":167006083898,"b":[["32515.1","0"],["32516.8","2715"],["32602.4","0"]],"a":[["32636.8","153"],["32642.0","0"],["32648.4","75"],["32688.2","0"]]}}
1626916408.2504818: {"stream":"linkusd_perp@depth@100ms","data":{"e":"depthUpdate","E":1626916403985,"T":1626916403964,"s":"LINKUSD_PERP","ps":"LINKUSD","U":167006085020,"u":167006085586,"pu":167006084856,"b":[["15.026","1097"],["15.053","1841"],["15.056","1742"],["15.057","2839"],["15.059","2385"]],"a":[["15.073","5313"],["15.081","74"]]}}
1626916408.250505: {"stream":"trxusd_perp@depth@100ms","data":{"e":"depthUpdate","E":1626916403985,"T":1626916403963,"s":"TRXUSD_PERP","ps":"TRXUSD","U":167006085031,"u":167006085581,"pu":167006083464,"b":[["0.05342","671"]],"a":[["0.05349","233"],["0.05350","1926"],["0.05351","2125"],["0.05352","669"]]}}
1626916408.436425: {"stream":"linkusd_211231@depth@100ms","data":{"e":"depthUpdate","E":1626916404002,"T":1626916403978,"s":"LINKUSD_211231","ps":"LINKUSD","U":167006085152,"u":167006085668,"pu":167006084356,"b":[["14.763","100"],["14.839","100"],["14.914","100"],["14.989","100"],["15.065","100"],["15.167","158"]],"a":[["15.385","20"]]}}
1626916408.607359: {"stream":"bchusd_210924@depth@100ms","data":{"e":"depthUpdate","E":1626916404006,"T":1626916403972,"s":"BCHUSD_210924","ps":"BCHUSD","U":167006085183,"u":167006085646,"pu":167006085029,"b":[["428.87","0"]],"a":[["429.46","40"],["429.47","40"],["429.53","0"],["429.54","0"],["429.65","120"],["429.66","421"],["429.98","2595"],["430.06","123"]]}}
1626916408.607489: {"stream":"etcusd_perp@depth@100ms","data":{"e":"depthUpdate","E":1626916404035,"T":1626916404029,"s":"ETCUSD_PERP","ps":"ETCUSD","U":167006085335,"u":167006085976,"pu":167006085323,"b":[["41.983","0"],["42.223","1510"],["42.232","100"],["42.235","977"],["42.239","1556"],["42.255","200"],["42.260","92"],["42.261","1356"]],"a":[["42.292","345"],["42.293","100"],["42.294","369"],["42.295","0"],["42.296","200"],["42.297","0"],["42.298","0"],["42.299","500"],["42.302","0"],["42.304","400"],["42.312","90"],["42.313","0"],["42.320","1750"],["42.334","526"],["42.335","400"],["42.340","80"],["42.343","23382"],["42.349","396"],["42.350","73"],["42.353","200"],["42.359","1149"]]}}
1626916408.607512: {"stream":"ethusd_210924@depth@100ms","data":{"e":"depthUpdate","E":1626916404035,"T":1626916404030,"s":"ETHUSD_210924","ps":"ETHUSD","U":167006085329,"u":167006085979,"pu":167006085291,"b":[["1984.54","0"],["1984.63","0"],["1984.65","0"],["1985.77","2815"],["1986.99","533"],["1987.20","401"],["1987.22","0"],["1987.29","470"],["1987.37","1000"],["1987.43","321"],["1987.51","0"],["1987.60","0"],["1987.81","3737"],["1987.97","0"],["1988.10","190"],["1988.14","414"],["1988.24","0"],["1988.30","0"],["1988.35","365"],["1988.36","0"],["1988.38","2000"],["1988.40","406"],["1988.45","0"],["1988.64","0"],["1989.07","0"],["1989.14","405"],["1989.90","512"],["1989.92","0"],["1990.21","3480"],["1990.72","0"],["1991.29","0"],["1991.50","270"],["1991.65","0"],["1991.66","0"],["1991.68","0"],["1991.69","0"],["1991.72","0"],["1991.73","127"],["1991.76","360"],["1991.98","0"],["1992.00","0"]],"a":[["1992.34","270"],["1992.36","0"],["1992.44","480"],["1992.57","0"],["1992.59","81"],["1992.72","1701"],["1994.43","365"],["1996.42","0"],["2024.28","408"],["2034.20","409"],["2044.12","2941"],["2054.05","413"],["2063.97","416"]]}}
1626916408.607641: {"stream":"xrpusd_perp@depth@100ms","data":{"e":"depthUpdate","E":1626916404077,"T":1626916404067,"s":"XRPUSD_PERP","ps":"XRPUSD","U":167006085638,"u":167006086286,"pu":167006085522,"b":[["0.5661","2626"]],"a":[["0.5666","0"],["0.5667","7158"],["0.5668","8321"],["0.5669","2002"],["0.5671","6601"],["0.5672","4072"],["0.5679","5000"],["0.5682","6939"]]}}
1626916408.6076539: {"stream":"btcusd_211231@depth@100ms","data":{"e":"depthUpdate","E":1626916404084,"T":1626916404021,"s":"BTCUSD_211231","ps":"BTCUSD","U":167006085669,"u":167006085929,"pu":167006085632,"b":[["30531.7","0"]],"a":[["32636.8","153"],["32642.0","0"]]}}
1626916408.6076648: {"stream":"bchusd_perp@depth@100ms","data":{"e":"depthUpdate","E":1626916404089,"T":1626916404069,"s":"BCHUSD_PERP","ps":"BCHUSD","U":167006085703,"u":167006086306,"pu":167006085628,"b":[["385.11","1"],["426.47","0"],["427.49","764"]],"a":[["427.85","280"],["427.86","0"],["427.87","0"],["427.90","0"],["427.91","24"],["427.96","100"],["427.99","1"],["428.00","300"],["428.02","50"],["428.06","100"],["428.09","1717"],["428.10","427"],["428.18","200"],["428.21","0"],["428.31","0"],["429.28","264"],["429.36","0"]]}}
1626916408.60771: {"stream":"linkusd_perp@depth@100ms","data":{"e":"depthUpdate","E":1626916404098,"T":1626916404059,"s":"LINKUSD_PERP","ps":"LINKUSD","U":167006085735,"u":167006086226,"pu":167006085586,"b":[["14.988","12710"],["15.066","0"],["15.067","210"]],"a":[["15.109","291"]]}}
1626916408.607736: {"stream":"trxusd_perp@depth@100ms","data":{"e":"depthUpdate","E":1626916404104,"T":1626916404002,"s":"TRXUSD_PERP","ps":"TRXUSD","U":167006085784,"u":167006085792,"pu":167006085581,"b":[],"a":[["0.05349","333"],["0.05350","2026"],["0.05351","2025"],["0.05352","569"]]}}
1626916408.607775: {"stream":"eosusd_perp@depth@100ms","data":{"e":"depthUpdate","E":1626916404117,"T":1626916404035,"s":"EOSUSD_PERP","ps":"EOSUSD","U":167006085835,"u":167006086011,"pu":167006084601,"b":[["3.467","1380"],["3.468","0"]],"a":[]}}
1626916409.220139: {"stream":"bchusd_210924@depth@100ms","data":{"e":"depthUpdate","E":1626916404122,"T":1626916404064,"s":"BCHUSD_210924","ps":"BCHUSD","U":167006085893,"u":167006086266,"pu":167006085646,"b":[["428.78","1108"],["429.10","0"],["429.23","40"]],"a":[]}}
1626916409.2201548: {"stream":"linkusd_211231@depth@100ms","data":{"e":"depthUpdate","E":1626916404123,"T":1626916404017,"s":"LINKUSD_211231","ps":"LINKUSD","U":167006085892,"u":167006085892,"pu":167006085668,"b":[],"a":[["15.377","9"]]}}
1626916409.220163: {"stream":"etcusd_perp@depth@100ms","data":{"e":"depthUpdate","E":1626916404136,"T":1626916404101,"s":"ETCUSD_PERP","ps":"ETCUSD","U":167006085992,"u":167006086501,"pu":167006085976,"b":[["41.983","2000"],["42.184","70"],["42.196","145"],["42.206","0"],["42.254","90"],["42.255","0"],["42.260","22"],["42.264","0"],["42.267","1114"]],"a":[["42.289","100"],["42.290","410"],["42.291","0"],["42.293","0"],["42.303","90"],["42.312","0"],["42.325","22"],["42.330","1108"],["42.333","350"],["42.341","674"],["42.344","56"],["42.354","690"],["42.386","170"],["42.396","70"],["42.485","336"],["42.496","0"]]}}
1626916409.2201731: {"stream":"ethusd_210924@depth@100ms","data":{"e":"depthUpdate","E":1626916404142,"T":1626916404135,"s":"ETHUSD_210924","ps":"ETHUSD","U":167006086007,"u":167006086674,"pu":167006085979,"b":[["1985.78","0"],["1986.97","627"],["1987.37","1501"],["1988.10","0"],["1988.14","0"],["1988.18","414"],["1988.20","80"],["1988.71","290"],["1988.94","1221"],["1989.00","425"],["1989.12","363"],["1989.38","0"],["1989.67","2846"],["1989.86","0"],["1989.97","0"],["1989.99","0"],["1990.22","0"],["1990.54","400"],["1991.50","0"],["1991.52","0"],["1991.53","0"],["1991.73","0"],["1991.76","0"],["1991.77","270"],["1991.78","360"],["1991.79","220"]],"a":[["1992.18","2569"],["1992.37","0"],["1992.40","0"],["1993.15","405"],["1993.22","1423"],["1993.55","0"],["1993.57","2389"],["1993.74","0"],["1993.80","0"],["1993.81","0"],["1993.93","0"],["1994.25","249"],["1994.40","121"],["1998.00","0"]]}}
1626916409.2202141: {"stream":"xrpusd_perp@depth@100ms","data":{"e":"depthUpdate","E":1626916404181,"T":1626916404174,"s":"XRPUSD_PERP","ps":"XRPUSD","U":167006086345,"u":167006086964,"pu":167006086286,"b":[["0.5650","6579"],["0.5651","23381"],["0.5656","1805"],["0.5658","10039"],["0.5662","5499"],["0.5663","9069"]],"a":[["0.5666","0"],["0.5669","2044"],["0.5670","5001"],["0.5672","4447"],["0.5675","10443"],["0.5676","31421"]]}}
1626916409.220222: {"stream":"bchusd_perp@depth@100ms","data":{"e":"depthUpdate","E":1626916404190,"T":1626916404167,"s":"BCHUSD_PERP","ps":"BCHUSD","U":167006086397,"u":167006086920,"pu":167006086306,"b":[["426.39","264"],["427.20","0"],["427.61","317"],["427.75","258"],["427.84","0"]],"a":[["427.85","150"],["427.87","0"],["427.88","0"],["427.90","130"],["427.91","124"],["427.96","0"],["428.00","0"],["428.05","300"],["428.09","1717"],["428.11","200"],["428.18","0"],["428.20","44"],["428.21","1034"],["428.26","49"]]}}
1626916409.2202399: {"stream":"btcusd_211231@depth@100ms","data":{"e":"depthUpdate","E":1626916404228,"T":1626916404158,"s":"BTCUSD_211231","ps":"BTCUSD","U":167006086612,"u":167006086847,"pu":167006085929,"b":[],"a":[["32636.8","153"],["32642.0","0"]]}}
1626916409.220246: {"stream":"linkusd_211231@depth@100ms","data":{"e":"depthUpdate","E":1626916404235,"T":1626916404206,"s":"LINKUSD_211231","ps":"LINKUSD","U":167006086641,"u":167006087146,"pu":167006085892,"b":[["13.800","0"],["15.314","0"]],"a":[["15.331","150"],["15.385","0"]]}}
1626916409.2202518: {"stream":"trxusd_perp@depth@100ms","data":{"e":"depthUpdate","E":1626916404238,"T":1626916404136,"s":"TRXUSD_PERP","ps":"TRXUSD","U":167006086691,"u":167006086696,"pu":167006085792,"b":[["0.05343","1216"],["0.05345","743"]],"a":[]}}
1626916409.220258: {"stream":"ethusd_210924@depth@100ms","data":{"e":"depthUpdate","E":1626916404245,"T":1626916404238,"s":"ETHUSD_210924","ps":"ETHUSD","U":167006086722,"u":167006087311,"pu":167006086674,"b":[["1987.40","904"],["1987.72","1000"],["1988.48","1000"],["1989.12","0"],["1989.53","0"],["1989.59","0"],["1989.73","0"],["1989.74","0"],["1990.00","375"],["1990.22","343"],["1990.61","623"],["1990.74","280"],["1990.88","259"],["1991.01","50"],["1991.50","270"],["1991.53","0"],["1991.54","127"],["1991.57","360"],["1991.77","0"],["1991.78","0"],["1991.79","0"],["1991.80","0"],["1991.81","0"]],"a":[["1993.27","60"],["1993.54","1137"],["1996.20","190"],["1996.63","1010"],["2032.76","0"]]}}
1626916409.220267: {"stream":"etcusd_perp@depth@100ms","data":{"e":"depthUpdate","E":1626916404249,"T":1626916404232,"s":"ETCUSD_PERP","ps":"ETCUSD","U":167006086740,"u":167006087280,"pu":167006086501,"b":[["41.937","560"],["41.950","0"],["41.983","0"],["42.098","336"],["42.108","0"],["42.184","215"],["42.195","0"],["42.231","86"],["42.236","81"],["42.241","15"],["42.244","0"],["42.250","39"],["42.252","452"],["42.254","90"],["42.259","0"],["42.260","0"],["42.264","0"]],"a":[["42.320","1783"],["42.323","22"],["42.332","662"],["42.339","659"],["42.341","71"],["42.350","17"],["42.390","3492"],["42.401","15"]]}}
1626916409.220285: {"stream":"linkusd_perp@depth@100ms","data":{"e":"depthUpdate","E":1626916404251,"T":1626916404238,"s":"LINKUSD_PERP","ps":"LINKUSD","U":167006086753,"u":167006087313,"pu":167006086226,"b":[["14.978","687"],["15.057","2739"],["15.059","2485"]],"a":[["15.070","202"],["15.071","190"],["15.073","1629"],["15.074","3076"]]}}
1626916409.2202911: {"stream":"bchusd_210924@depth@100ms","data":{"e":"depthUpdate","E":1626916404284,"T":1626916404265,"s":"BCHUSD_210924","ps":"BCHUSD","U":167006086981,"u":167006087439,"pu":167006086266,"b":[["429.08","419"],["429.26","27"]],"a":[["429.73","120"],["429.83","0"]]}}
1626916409.220305: {"stream":"bchusd_perp@depth@100ms","data":{"e":"depthUpdate","E":1626916404301,"T":1626916404288,"s":"BCHUSD_PERP","ps":"BCHUSD","U":167006087088,"u":167006087516,"pu":167006086920,"b":[["426.63","1226"],["427.68","0"],["427.69","0"],["427.70","0"],["427.75","228"],["427.76","130"]],"a":[["427.91","24"],["427.92","0"],["427.96","100"],["428.11","0"],["428.16","2985"],["428.48","0"]]}}
1626916409.220312: {"stream":"xrpusd_perp@depth@100ms","data":{"e":"depthUpdate","E":1626916404303,"T":1626916404292,"s":"XRPUSD_PERP","ps":"XRPUSD","U":167006087098,"u":167006087531,"pu":167006086964,"b":[["0.5649","2892"],["0.5652","1412"],["0.5656","4092"],["0.5662","5727"],["0.5663","7723"]],"a":[["0.5666","0"],["0.5684","591"],["0.5685","5052"]]}}
1626916409.2203178: {"stream":"btcusd_211231@depth@100ms","data":{"e":"depthUpdate","E":1626916404330,"T":1626916404277,"s":"BTCUSD_211231","ps":"BTCUSD","U":167006087244,"u":167006087485,"pu":167006086847,"b":[["30512.8","304"],["32513.1","3062"],["32516.8","0"]],"a":[["32634.1","17"],["32636.8","153"],["32642.0","0"],["32663.3","0"]]}}
1626916409.2203321: {"stream":"ethusd_210924@depth@100ms","data":{"e":"depthUpdate","E":1626916404346,"T":1626916404333,"s":"ETHUSD_210924","ps":"ETHUSD","U":167006087318,"u":167006087694,"pu":167006087311,"b":[["1987.40","120"],["1989.58","100"],["1990.03","0"],["1991.54","0"],["1991.57","0"],["1991.58","0"],["1991.61","0"],["1991.62","127"],["1991.65","360"],["1991.81","0"]],"a":[["2019.53","0"]]}}
1626916409.220339: {"stream":"linkusd_211231@depth@100ms","data":{"e":"depthUpdate","E":1626916404348,"T":1626916404247,"s":"LINKUSD_211231","ps":"LINKUSD","U":167006087339,"u":167006087349,"pu":167006087146,"b":[],"a":[["15.334","55"],["15.377","29"]]}}
1626916409.220376: {"stream":"etcusd_perp@depth@100ms","data":{"e":"depthUpdate","E":1626916404363,"T":1626916404339,"s":"ETCUSD_PERP","ps":"ETCUSD","U":167006087402,"u":167006087721,"pu":167006087280,"b":[["41.983","0"],["42.254","90"],["42.264","0"]],"a":[]}}
1626916409.220413: {"stream":"linkusd_perp@depth@100ms","data":{"e":"depthUpdate","E":1626916404379,"T":1626916404373,"s":"LINKUSD_PERP","ps":"LINKUSD","U":167006087462,"u":167006088025,"pu":167006087313,"b":[["15.057","2739"],["15.059","2485"]],"a":[["15.070","100"],["15.076","279"],["15.077","704"],["15.079","2956"],["15.080","1179"]]}}
1626916409.220427: {"stream":"bchusd_210924@depth@100ms","data":{"e":"depthUpdate","E":1626916404388,"T":1626916404365,"s":"BCHUSD_210924","ps":"BCHUSD","U":167006087513,"u":167006087945,"pu":167006087439,"b":[],"a":[["429.65","0"],["429.66","107"],["429.68","0"],["429.86","0"],["429.92","0"],["429.97","374"],["430.31","0"],["431.16","0"]]}}
1626916409.220441: {"stream":"bchusd_perp@depth@100ms","data":{"e":"depthUpdate","E":1626916404412,"T":1626916404385,"s":"BCHUSD_PERP","ps":"BCHUSD","U":167006087589,"u":167006088095,"pu":167006087516,"b":[["427.84","0"]],"a":[["427.85","0"],["427.90","0"],["427.95","280"],["427.97","0"],["428.09","0"],["428.10","627"],["428.31","252"],["428.41","0"],["428.52","725"],["428.83","0"]]}}
1626916409.220455: {"stream":"xrpusd_perp@depth@100ms","data":{"e":"depthUpdate","E":1626916404420,"T":1626916404407,"s":"XRPUSD_PERP","ps":"XRPUSD","U":167006087621,"u":167006088222,"pu":167006087531,"b":[],"a":[["0.5666","0"]]}}
1626916409.220507: {"stream":"btcusd_211231@depth@100ms","data":{"e":"depthUpdate","E":1626916404445,"T":1626916404430,"s":"BTCUSD_211231","ps":"BTCUSD","U":167006087726,"u":167006088383,"pu":167006087485,"b":[["32615.0","0"],["32617.2","12"]],"a":[["32636.8","0"],["32641.0","143"],["32641.1","46"],["32642.0","153"]]}}
1626916409.220521: {"stream":"ethusd_210924@depth@100ms","data":{"e":"depthUpdate","E":1626916404454,"T":1626916404433,"s":"ETHUSD_210924","ps":"ETHUSD","U":167006087770,"u":167006088417,"pu":167006087694,"b":[["1985.96","0"],["1987.53","0"],["1988.34","779"],["1989.67","4269"],["1990.20","3600"],["1991.62","0"],["1991.65","0"],["1991.66","0"],["1991.69","0"],["1991.70","0"],["1991.72","360"],["1991.73","127"]],"a":[["1992.18","4638"],["1992.34","0"],["1992.64","0"],["1992.66","0"],["1994.56","0"],["2031.26","2536"]]}}
1626916409.2205288: {"stream":"linkusd_211231@depth@100ms","data":{"e":"depthUpdate","E":1626916404458,"T":1626916404386,"s":"LINKUSD_211231","ps":"LINKUSD","U":167006087802,"u":167006088100,"pu":167006087349,"b":[],"a":[["15.326","40"],["15.331","50"],["15.335","0"]]}}
1626916409.2205498: {"stream":"etcusd_perp@depth@100ms","data":{"e":"depthUpdate","E":1626916404467,"T":1626916404431,"s":"ETCUSD_PERP","ps":"ETCUSD","U":167006087862,"u":167006088387,"pu":167006087721,"b":[["39.544","0"],["41.983","2000"],["42.254","0"],["42.264","90"]],"a":[["42.321","1097"],["42.339","0"],["42.480","200"]]}}
1626916409.220609: {"stream":"bchusd_210924@depth@100ms","data":{"e":"depthUpdate","E":1626916404488,"T":1626916404481,"s":"BCHUSD_210924","ps":"BCHUSD","U":167006088096,"u":167006088679,"pu":167006087945,"b":[["428.76","6736"]],"a":[["429.46","0"],["429.47","0"],["429.64","0"],["429.65","0"],["429.66","40"],["429.73","0"],["429.83","121"],["429.98","2572"],["430.13","113"]]}}
1626916409.22067: {"stream":"bchusd_perp@depth@100ms","data":{"e":"depthUpdate","E":1626916404514,"T":1626916404502,"s":"BCHUSD_PERP","ps":"BCHUSD","U":167006088239,"u":167006088786,"pu":167006088095,"b":[["427.46","0"],["427.61","17"],["427.67","1196"],["427.68","106"],["427.82","0"],["427.83","642"],["427.84","0"],["427.85","150"],["427.86","444"],["427.88","150"],["427.89","0"],["427.90","19"]],"a":[["427.96","0"],["428.01","3214"],["428.06","0"],["428.11","0"],["428.16","2785"],["428.19","776"],["428.21","200"],["428.31","2258"],["429.03","366"]]}}
1626916409.2206929: {"stream":"xrpusd_perp@depth@100ms","data":{"e":"depthUpdate","E":1626916404537,"T":1626916404517,"s":"XRPUSD_PERP","ps":"XRPUSD","U":167006088407,"u":167006088879,"pu":167006088222,"b":[["0.5660","12682"]],"a":[["0.5666","0"],["0.5667","7158"],["0.5670","5453"]]}}
1626916409.220721: {"stream":"btcusd_211231@depth@100ms","data":{"e":"depthUpdate","E":1626916404556,"T":1626916404476,"s":"BTCUSD_211231","ps":"BTCUSD","U":167006088522,"u":167006088659,"pu":167006088383,"b":[["31884.9","0"]],"a":[["32636.8","153"],["32640.9","0"],["32641.0","0"],["32642.0","0"]]}}
1626916409.220727: {"stream":"ethusd_210924@depth@100ms","data":{"e":"depthUpdate","E":1626916404556,"T":1626916404549,"s":"ETHUSD_210924","ps":"ETHUSD","U":167006088513,"u":167006089047,"pu":167006088417,"b":[["1985.77","0"],["1986.65","0"],["1986.97","0"],["1986.99","0"],["1987.22","2270"],["1987.29","0"],["1987.37","1000"],["1988.23","5654"],["1989.01","667"],["1989.16","343"],["1989.23","322"],["1989.36","280"],["1989.37","6285"],["1990.00","12"],["1990.08","259"],["1990.22","0"],["1990.54","0"],["1990.61","0"],["1990.74","0"],["1990.75","314"],["1990.82","0"],["1990.88","0"],["1990.89","0"],["1991.29","0"],["1991.47","0"],["1991.49","373"],["1991.50","0"],["1991.53","0"],["1991.54","0"],["1991.57","360"],["1991.58","126"],["1991.72","0"],["1991.73","0"],["1991.74","270"],["1991.75","96"]],"a":[["1993.94","314"],["1994.14","0"],["2020.97","2522"]]}}
1626916409.220737: {"stream":"etcusd_perp@depth@100ms","data":{"e":"depthUpdate","E":1626916404580,"T":1626916404573,"s":"ETCUSD_PERP","ps":"ETCUSD","U":167006088648,"u":167006089176,"pu":167006088387,"b":[["41.983","2000"]],"a":[["42.288","301"],["42.321","438"],["42.329","660"],["42.334","0"],["42.367","70"]]}}
1626916409.220743: {"stream":"linkusd_perp@depth@100ms","data":{"e":"depthUpdate","E":1626916404582,"T":1626916404569,"s":"LINKUSD_PERP","ps":"LINKUSD","U":167006088662,"u":167006089153,"pu":167006088025,"b":[["15.062","110"],["15.066","155"],["15.067","0"]],"a":[]}}
1626916409.220756: {"stream":"bchusd_210924@depth@100ms","data":{"e":"depthUpdate","E":1626916404596,"T":1626916404589,"s":"BCHUSD_210924","ps":"BCHUSD","U":167006088729,"u":167006089249,"pu":167006088679,"b":[],"a":[["429.60","0"],["429.61","0"],["429.66","0"],["429.69","40"],["429.76","47"],["429.82","0"],["429.97","12"],["430.13","0"],["430.27","1069"],["430.30","186"],["430.96","1401"]]}}
1626916409.220763: {"stream":"bchusd_perp@depth@100ms","data":{"e":"depthUpdate","E":1626916404615,"T":1626916404601,"s":"BCHUSD_PERP","ps":"BCHUSD","U":167006088829,"u":167006089315,"pu":167006088786,"b":[["425.60","507"],["427.42","0"],["427.45","32"],["427.52","4869"],["427.67","1196"],["427.69","130"],["427.75","128"],["427.77","100"],["427.84","0"],["427.85","0"],["427.88","0"],["427.89","515"],["427.90","169"]],"a":[["427.95","150"],["427.97","130"],["428.01","3114"],["428.04","0"],["428.09","0"],["428.10","27"],["428.16","2885"],["428.20","0"],["428.22","200"],["428.25","144"],["428.27","44"],["428.31","0"],["428.37","257"],["428.40","263"],["428.47","0"],["428.52","353"],["428.77","5919"]]}}
1626916409.220842: {"stream":"xrpusd_perp@depth@100ms","data":{"e":"depthUpdate","E":1626916404646,"T":1626916404640,"s":"XRPUSD_PERP","ps":"XRPUSD","U":167006088997,"u":167006089487,"pu":167006088879,"b":[],"a":[["0.5666","0"],["0.5668","7321"]]}}
1626916409.220856: {"stream":"btcusd_211231@depth@100ms","data":{"e":"depthUpdate","E":1626916404656,"T":1626916404648,"s":"BTCUSD_211231","ps":"BTCUSD","U":167006089065,"u":167006089535,"pu":167006088659,"b":[["32513.1","0"],["32516.8","2856"]],"a":[["32636.8","153"],["32640.9","0"]]}}
1626916409.220862: {"stream":"ethusd_210924@depth@100ms","data":{"e":"depthUpdate","E":1626916404658,"T":1626916404654,"s":"ETHUSD_210924","ps":"ETHUSD","U":167006089069,"u":167006089556,"pu":167006089047,"b":[["1985.77","2817"],["1986.05","0"],["1987.22","0"],["1987.69","627"],["1987.79","501"],["1987.80","2892"],["1987.89","533"],["1988.36","470"],["1989.01","304"],["1989.14","0"],["1989.16","0"],["1989.23","0"],["1989.36","0"],["1989.37","5984"],["1989.67","2846"],["1989.81","1170"],["1989.89","363"],["1990.04","343"],["1990.05","3756"],["1990.08","0"],["1990.11","322"],["1990.24","0"],["1990.25","301"],["1990.54","400"],["1990.88","259"],["1991.57","0"],["1991.58","0"],["1991.61","0"],["1991.62","0"],["1991.75","360"],["1991.76","222"]],"a":[["1992.18","3968"],["1992.43","270"],["1992.51","1243"],["1992.52","3550"],["1993.57","1989"],["1994.34","5733"],["1999.28","0"]]}}
1626916409.220881: {"stream":"trxusd_perp@depth@100ms","data":{"e":"depthUpdate","E":1626916404661,"T":1626916404647,"s":"TRXUSD_PERP","ps":"TRXUSD","U":167006089078,"u":167006089533,"pu":167006086696,"b":[],"a":[["0.05350","1926"],["0.05351","2125"],["0.05352","769"]]}}
1626916409.220902: {"stream":"etcusd_perp@depth@100ms","data":{"e":"depthUpdate","E":1626916404683,"T":1626916404675,"s":"ETCUSD_PERP","ps":"ETCUSD","U":167006089198,"u":167006089678,"pu":167006089176,"b":[["41.983","2000"]],"a":[["42.353","0"],["42.358","200"],["42.505","336"],["42.518","0"]]}}
1626916409.220916: {"stream":"linkusd_perp@depth@100ms","data":{"e":"depthUpdate","E":1626916404698,"T":1626916404690,"s":"LINKUSD_PERP","ps":"LINKUSD","U":167006089260,"u":167006089767,"pu":167006089153,"b":[["15.045","515"],["15.062","110"],["15.066","155"],["15.068","77"]],"a":[]}}
1626916409.220921: {"stream":"linkusd_211231@depth@100ms","data":{"e":"depthUpdate","E":1626916404707,"T":1626916404600,"s":"LINKUSD_211231","ps":"LINKUSD","U":167006089312,"u":167006089312,"pu":167006088100,"b":[],"a":[["15.331","0"]]}}
1626916409.220927: {"stream":"bchusd_210924@depth@100ms","data":{"e":"depthUpdate","E":1626916404716,"T":1626916404703,"s":"BCHUSD_210924","ps":"BCHUSD","U":167006089349,"u":167006089829,"pu":167006089249,"b":[],"a":[["429.66","40"],["429.69","0"],["429.70","2638"],["429.76","27"],["429.83","0"],["429.93","0"],["430.13","0"],["430.27","1049"],["430.37","121"]]}}
1626916409.2209332: {"stream":"bchusd_perp@depth@100ms","data":{"e":"depthUpdate","E":1626916404721,"T":1626916404714,"s":"BCHUSD_PERP","ps":"BCHUSD","U":167006089385,"u":167006089882,"pu":167006089315,"b":[["426.39","0"],["426.49","1264"],["427.12","6095"],["427.13","0"],["427.15","84"],["427.22","465"],["427.29","0"],["427.30","4064"],["427.51","3034"],["427.52","1860"],["427.69","0"],["427.71","700"],["427.77","0"]],"a":[["428.00","894"],["428.15","100"],["428.16","2785"],["428.20","0"],["428.22","100"],["428.25","0"],["428.27","244"],["428.32","3215"],["428.50","6599"],["428.51","65"],["428.55","25"],["428.60","0"],["428.62","306"],["428.69","236"],["428.77","502"],["428.87","5417"],["429.28","0"],["429.38","264"]]}}
1626916409.221041: {"stream":"ethusd_210924@depth@100ms","data":{"e":"depthUpdate","E":1626916404762,"T":1626916404734,"s":"ETHUSD_210924","ps":"ETHUSD","U":167006089595,"u":167006089966,"pu":167006089556,"b":[["1987.58","784"],["1987.80","2702"],["1989.00","0"],["1989.78","425"],["1989.86","405"],["1990.04","0"],["1990.11","0"],["1990.25","0"],["1990.55","343"],["1990.61","322"],["1990.74","280"],["1990.76","301"]],"a":[["1992.18","4218"],["1993.56","2358"]]}}
1626916409.221057: {"stream":"xrpusd_perp@depth@100ms","data":{"e":"depthUpdate","E":1626916404768,"T":1626916404750,"s":"XRPUSD_PERP","ps":"XRPUSD","U":167006089622,"u":167006090029,"pu":167006089487,"b":[],"a":[["0.5666","0"],["0.5667","8158"],["0.5677","399"],["0.5680","1889"]]}}
1626916409.221071: {"stream":"btcusd_211231@depth@100ms","data":{"e":"depthUpdate","E":1626916404784,"T":1626916404775,"s":"BTCUSD_211231","ps":"BTCUSD","U":167006089697,"u":167006090304,"pu":167006089535,"b":[["31836.7","318"],["32598.9","0"]],"a":[["32648.4","0"],["32707.5","0"],["32719.5","385"]]}}
1626916409.221077: {"stream":"bchusd_210924@depth@100ms","data":{"e":"depthUpdate","E":1626916404819,"T":1626916404813,"s":"BCHUSD_210924","ps":"BCHUSD","U":167006089878,"u":167006090620,"pu":167006089829,"b":[["429.10","0"],["429.23","40"]],"a":[["429.58","40"],["429.59","20"],["429.66","0"],["429.70","2618"],["429.81","83"],["430.10","23"],["430.18","102"],["430.30","96"],["1335.84","0"]]}}
1626916409.2210839: {"stream":"bchusd_perp@depth@100ms","data":{"e":"depthUpdate","E":1626916404821,"T":1626916404783,"s":"BCHUSD_PERP","ps":"BCHUSD","U":167006089884,"u":167006090383,"pu":167006089882,"b":[["426.63","872"],["427.00","626"],["427.70","0"],["427.76","230"],["427.90","193"]],"a":[["427.91","174"],["428.09","100"],["428.15","0"],["428.22","300"],["428.27","44"]]}}
1626916409.221117: {"stream":"linkusd_211231@depth@100ms","data":{"e":"depthUpdate","E":1626916404823,"T":1626916404745,"s":"LINKUSD_211231","ps":"LINKUSD","U":167006089896,"u":167006089999,"pu":167006089312,"b":[],"a":[["15.331","658"],["15.528","0"],["15.603","0"],["15.679","0"],["15.754","0"],["15.829","0"]]}}
1626916409.2211251: {"stream":"linkusd_perp@depth@100ms","data":{"e":"depthUpdate","E":1626916404823,"T":1626916404788,"s":"LINKUSD_PERP","ps":"LINKUSD","U":167006089898,"u":167006090416,"pu":167006089767,"b":[["15.057","2839"],["15.059","2385"],["15.062","0"],["15.066","265"]],"a":[["15.073","5034"],["15.074","0"]]}}
1626916409.221131: {"stream":"trxusd_perp@depth@100ms","data":{"e":"depthUpdate","E":1626916404829,"T":1626916404748,"s":"TRXUSD_PERP","ps":"TRXUSD","U":167006089915,"u":167006090018,"pu":167006089533,"b":[],"a":[["0.05350","2126"],["0.05351","2125"],["0.05352","569"],["0.05379","180"]]}}
1626916409.2211368: {"stream":"etcusd_perp@depth@100ms","data":{"e":"depthUpdate","E":1626916404861,"T":1626916404854,"s":"ETCUSD_PERP","ps":"ETCUSD","U":167006090098,"u":167006091084,"pu":167006089678,"b":[["42.223","1310"],["42.228","200"],["42.247","1331"],["42.260","200"],["42.261","25"]],"a":[["42.293","266"],["42.298","90"],["42.299","200"],["42.303","0"],["42.319","0"],["42.343","23282"],["42.353","500"],["42.358","0"]]}}
1626916409.221144: {"stream":"xrpusd_perp@depth@100ms","data":{"e":"depthUpdate","E":1626916404872,"T":1626916404862,"s":"XRPUSD_PERP","ps":"XRPUSD","U":167006090216,"u":167006091159,"pu":167006090029,"b":[["0.5656","10998"],["0.5658","3133"]],"a":[["0.5666","0"],["0.5673","3499"],["0.5674","963"],["0.5678","6467"]]}}
1626916409.2211661: {"stream":"eosusd_perp@depth@100ms","data":{"e":"depthUpdate","E":1626916404883,"T":1626916404849,"s":"EOSUSD_PERP","ps":"EOSUSD","U":167006090324,"u":167006091025,"pu":167006086011,"b":[["3.468","0"]],"a":[["3.470","3895"],["3.472","5358"]]}}
1626916409.221171: {"stream":"ethusd_210924@depth@100ms","data":{"e":"depthUpdate","E":1626916404883,"T":1626916404875,"s":"ETHUSD_210924","ps":"ETHUSD","U":167006090341,"u":167006091321,"pu":167006089966,"b":[["1987.58","0"],["1987.69","0"],["1987.79","0"],["1988.36","0"],["1989.03","12"],["1989.19","0"],["1989.25","0"],["1989.38","280"],["1989.40","0"],["1989.89","0"],["1990.10","0"],["1990.22","0"],["1990.54","0"],["1990.55","0"],["1990.61","0"],["1990.74","0"],["1990.76","0"],["1990.78","0"],["1990.88","259"],["1991.02","0"],["1991.29","0"],["1991.50","0"],["1991.52","0"],["1991.53","0"],["1991.56","0"],["1991.57","126"],["1991.60","360"],["1991.74","0"],["1991.75","0"],["1991.76","0"],["1991.77","270"]],"a":[]}}
1626916409.221211: {"stream":"btcusd_211231@depth@100ms","data":{"e":"depthUpdate","E":1626916404912,"T":1626916404807,"s":"BTCUSD_211231","ps":"BTCUSD","U":167006090536,"u":167006090536,"pu":167006090304,"b":[],"a":[["32649.4","148"]]}}
1626916409.2212539: {"stream":"trxusd_perp@depth@100ms","data":{"e":"depthUpdate","E":1626916404930,"T":1626916404921,"s":"TRXUSD_PERP","ps":"TRXUSD","U":167006090730,"u":167006091708,"pu":167006090018,"b":[["0.01069","5432"],["0.03742","11572"],["0.04811","20126"],["0.05079","7548"]],"a":[["0.05368","71"],["0.05379","481"],["0.05383","353"],["0.05614","7549"],["0.05882","10064"],["0.06951","11572"],["0.22135","67932"]]}}
1626916409.221298: {"stream":"bchusd_perp@depth@100ms","data":{"e":"depthUpdate","E":1626916404937,"T":1626916404927,"s":"BCHUSD_PERP","ps":"BCHUSD","U":167006090831,"u":167006091758,"pu":167006090383,"b":[["427.71","300"],["427.87","381"]],"a":[["428.04","100"],["428.09","0"],["428.33","2006"]]}}
1626916409.221334: {"stream":"bchusd_210924@depth@100ms","data":{"e":"depthUpdate","E":1626916404943,"T":1626916404878,"s":"BCHUSD_210924","ps":"BCHUSD","U":167006090902,"u":167006091343,"pu":167006090620,"b":[],"a":[["430.22","1272"],["430.58","246"],["1336.24","9418"]]}}
1626916409.22134: {"stream":"linkusd_211231@depth@100ms","data":{"e":"depthUpdate","E":1626916404945,"T":1626916404860,"s":"LINKUSD_211231","ps":"LINKUSD","U":167006090939,"u":167006091142,"pu":167006089999,"b":[["15.284","351"],["15.298","150"]],"a":[["15.330","2247"],["15.331","0"],["15.332","0"],["15.334","205"]]}}
1626916409.2213619: {"stream":"etcusd_perp@depth@100ms","data":{"e":"depthUpdate","E":1626916404963,"T":1626916404937,"s":"ETCUSD_PERP","ps":"ETCUSD","U":167006091128,"u":167006091839,"pu":167006091084,"b":[["42.072","336"],["42.086","0"],["42.214","315"],["42.226","0"],["42.235","662"],["42.253","354"],["42.260","0"],["42.264","0"],["42.269","272"],["42.270","0"],["42.271","0"],["42.272","0"]],"a":[["42.287","0"],["42.288","0"],["42.289","100"],["42.290","560"],["42.298","0"],["42.299","0"],["42.303","90"],["42.319","0"],["42.321","1153"],["42.329","0"]]}}
1626916409.221378: {"stream":"xrpusd_perp@depth@100ms","data":{"e":"depthUpdate","E":1626916404975,"T":1626916404948,"s":"XRPUSD_PERP","ps":"XRPUSD","U":167006091252,"u":167006091947,"pu":167006091159,"b":[["0.5648","25033"],["0.5651","361"]],"a":[["0.5666","0"],["0.5667","7133"],["0.5677","7305"],["0.5686","24897"],["0.5687","1149"]]}}
1626916409.221392: {"stream":"linkusd_perp@depth@100ms","data":{"e":"depthUpdate","E":1626916404975,"T":1626916404960,"s":"LINKUSD_PERP","ps":"LINKUSD","U":167006091263,"u":167006092035,"pu":167006090416,"b":[["14.774","1070"],["15.061","263"],["15.065","262"],["15.066","155"]],"a":[["15.075","310"],["15.078","1934"]]}}
1626916409.221405: {"stream":"ethusd_210924@depth@100ms","data":{"e":"depthUpdate","E":1626916404987,"T":1626916404962,"s":"ETHUSD_210924","ps":"ETHUSD","U":167006091407,"u":167006092063,"pu":167006091321,"b":[["1987.67","784"],["1988.12","501"],["1988.23","0"],["1988.40","876"],["1989.38","0"],["1989.81","0"],["1989.89","363"],["1990.04","343"],["1990.05","0"],["1990.16","0"],["1990.46","322"],["1990.54","400"],["1990.61","301"],["1990.74","280"],["1991.53","50"],["1991.57","0"],["1991.61","125"],["1991.78","96"]],"a":[["1992.18","4488"],["1992.43","0"],["1992.51","0"],["1992.52","0"],["1994.34","0"],["2024.28","0"],["2034.20","0"],["2044.12","2529"],["2054.05","0"],["2063.97","0"]]}}
1626916409.22143: {"stream":"btcusd_211231@depth@100ms","data":{"e":"depthUpdate","E":1626916405021,"T":1626916404985,"s":"BTCUSD_211231","ps":"BTCUSD","U":167006091647,"u":167006092308,"pu":167006090536,"b":[["32546.0","25"]],"a":[["32636.8","153"],["32640.9","46"],["32641.0","0"],["32641.1","0"]]}}
1626916409.221459: {"stream":"bchusd_perp@depth@100ms","data":{"e":"depthUpdate","E":1626916405049,"T":1626916405014,"s":"BCHUSD_PERP","ps":"BCHUSD","U":167006091903,"u":167006092924,"pu":167006091758,"b":[["424.82","0"],["427.90","169"]],"a":[["428.22","1692"]]}}
1626916409.221478: {"stream":"linkusd_211231@depth@100ms","data":{"e":"depthUpdate","E":1626916405049,"T":1626916404945,"s":"LINKUSD_211231","ps":"LINKUSD","U":167006091897,"u":167006091901,"pu":167006091142,"b":[["14.763","0"],["14.839","0"],["14.914","0"],["14.989","0"],["15.065","0"]],"a":[]}}
1626916409.2214851: {"stream":"eosusd_perp@depth@100ms","data":{"e":"depthUpdate","E":1626916405053,"T":1626916405027,"s":"EOSUSD_PERP","ps":"EOSUSD","U":167006091907,"u":167006093148,"pu":167006091025,"b":[["3.456","1253"]],"a":[["3.485","5427"],["3.486","437"]]}}
1626916409.221542: {"stream":"etcusd_perp@depth@100ms","data":{"e":"depthUpdate","E":1626916405066,"T":1626916405055,"s":"ETCUSD_PERP","ps":"ETCUSD","U":167006092051,"u":167006093702,"pu":167006091839,"b":[["39.544","0"],["41.983","0"],["42.240","200"],["42.247","0"],["42.253","264"],["42.254","1335"],["42.262","90"],["42.278","0"]],"a":[["42.278","0"],["42.279","89"],["42.289","100"],["42.293","0"],["42.294","669"],["42.328","782"],["42.344","0"]]}}
1626916409.221597: {"stream":"xrpusd_perp@depth@100ms","data":{"e":"depthUpdate","E":1626916405078,"T":1626916405060,"s":"XRPUSD_PERP","ps":"XRPUSD","U":167006092156,"u":167006093798,"pu":167006091947,"b":[["0.5650","6232"],["0.5651","13"]],"a":[["0.5666","0"],["0.5667","8158"],["0.5668","7319"]]}}
1626916409.221653: {"stream":"ethusd_210924@depth@100ms","data":{"e":"depthUpdate","E":1626916405090,"T":1626916405083,"s":"ETHUSD_210924","ps":"ETHUSD","U":167006092307,"u":167006094289,"pu":167006092063,"b":[["1987.67","0"],["1987.89","0"],["1987.93","80"],["1988.10","0"],["1988.12","5827"],["1988.18","0"],["1988.20","0"],["1988.40","406"],["1988.89","11945"],["1989.49","363"],["1989.64","343"],["1989.70","322"],["1989.83","280"],["1989.85","301"],["1989.89","0"],["1989.96","3647"],["1989.97","259"],["1990.04","0"],["1990.22","50"],["1990.43","0"],["1990.46","0"],["1990.54","0"],["1990.61","0"],["1990.74","0"],["1990.88","0"],["1990.89","0"],["1991.20","0"],["1991.29","270"],["1991.44","0"],["1991.45","0"],["1991.53","0"],["1991.54","0"],["1991.56","0"],["1991.57","436"],["1991.59","360"],["1991.60","0"],["1991.61","0"],["1991.64","0"],["1991.65","0"],["1991.77","0"],["1991.78","0"],["1991.89","5"],["1992.07","60"],["1992.17","0"]],"a":[["1991.90","0"],["1992.07","0"],["1992.08","6791"],["1992.14","360"],["1992.16","1002"],["1992.17","275"],["1992.18","2588"],["1992.54","3584"],["1992.56","259"],["1992.57","280"],["1992.89","0"],["1992.90","0"],["1993.96","80"],["1994.25","169"],["1996.40","998"],["1997.40","0"]]}}
1626916409.2216818: {"stream":"linkusd_perp@depth@100ms","data":{"e":"depthUpdate","E":1626916405090,"T":1626916405042,"s":"LINKUSD_PERP","ps":"LINKUSD","U":167006092314,"u":167006093498,"pu":167006092035,"b":[],"a":[["15.073","5182"],["15.075","510"],["15.079","2756"],["15.094","651"],["15.102","550"],["15.106","121"]]}}
1626916409.221782: {"stream":"trxusd_perp@depth@100ms","data":{"e":"depthUpdate","E":1626916405106,"T":1626916404994,"s":"TRXUSD_PERP","ps":"TRXUSD","U":167006092480,"u":167006092480,"pu":167006091708,"b":[["0.05342","924"]],"a":[]}}
1626916409.222056: {"stream":"btcusd_211231@depth@100ms","data":{"e":"depthUpdate","E":1626916405155,"T":1626916405144,"s":"BTCUSD_211231","ps":"BTCUSD","U":167006093643,"u":167006095504,"pu":167006092308,"b":[["31373.4","55"],["31533.5","55"],["31693.6","55"],["31853.7","55"],["32013.7","55"]],"a":[["32636.8","0"],["32639.9","0"],["32640.8","0"],["32640.9","0"],["32641.1","46"],["32642.0","153"],["32711.6","12"],["33040.2","45"],["33200.2","376"],["33360.3","45"],["33520.4","46"],["33680.5","46"]]}}
1626916409.2221498: {"stream":"etcusd_perp@depth@100ms","data":{"e":"depthUpdate","E":1626916405173,"T":1626916405156,"s":"ETCUSD_PERP","ps":"ETCUSD","U":167006093915,"u":167006095789,"pu":167006093702,"b":[["41.983","2000"],["42.223","1510"],["42.228","0"]],"a":[["42.279","0"],["42.290","150"],["42.292","0"],["42.294","300"],["42.319","715"],["42.321","438"],["42.336","403"]]}}
1626916409.222165: {"stream":"bchusd_perp@depth@100ms","data":{"e":"depthUpdate","E":1626916405187,"T":1626916405158,"s":"BCHUSD_PERP","ps":"BCHUSD","U":167006094279,"u":167006095824,"pu":167006092924,"b":[["427.90","169"]],"a":[["427.99","101"],["428.04","0"],["429.03","15"]]}}
1626916409.2221959: {"stream":"ethusd_210924@depth@100ms","data":{"e":"depthUpdate","E":1626916405190,"T":1626916405185,"s":"ETHUSD_210924","ps":"ETHUSD","U":167006094324,"u":167006096264,"pu":167006094289,"b":[["1986.42","784"],["1987.02","533"],["1987.03","0"],["1987.07","501"],["1987.62","470"],["1988.08","414"],["1991.29","270"],["1991.50","0"],["1991.52","360"],["1991.53","125"],["1991.57","0"],["1991.59","0"],["1991.60","0"],["1991.89","115"],["1991.90","0"],["1992.06","0"],["1992.07","0"]],"a":[["1991.90","8092"],["1991.96","400"],["1991.97","0"],["1992.00","20"],["1992.04","840"],["1992.06","1420"],["1992.07","0"],["1992.08","3320"],["1992.14","0"],["1992.17","0"],["1992.18","2182"],["1992.32","1238"],["1992.35","0"],["1992.44","0"],["1992.53","1347"],["1992.58","0"],["1992.80","0"],["1993.22","425"],["1993.35","200"],["1993.56","2108"],["1993.88","0"],["1993.96","0"],["1993.99","80"],["1994.40","5912"],["1994.97","0"],["1995.29","500"],["1995.99","12"],["1996.12","0"],["1996.14","0"],["1996.30","6028"],["1996.31","0"],["1996.62","0"],["1996.67","0"],["1997.25","0"],["1997.43","0"],["2024.13","408"],["2034.06","410"],["2043.98","412"],["2053.90","414"],["2063.82","416"]]}}
1626916409.222218: {"stream":"xrpusd_perp@depth@100ms","data":{"e":"depthUpdate","E":1626916405192,"T":1626916405176,"s":"XRPUSD_PERP","ps":"XRPUSD","U":167006094380,"u":167006096150,"pu":167006093798,"b":[],"a":[["0.5666","0"]]}}
1626916409.2222238: {"stream":"linkusd_perp@depth@100ms","data":{"e":"depthUpdate","E":1626916405192,"T":1626916405104,"s":"LINKUSD_PERP","ps":"LINKUSD","U":167006094390,"u":167006094705,"pu":167006093498,"b":[["14.727","3646"],["15.058","1678"],["15.060","817"]],"a":[["19.056","0"]]}}
1626916409.2224488: {"stream":"eosusd_perp@depth@100ms","data":{"e":"depthUpdate","E":1626916405222,"T":1626916405201,"s":"EOSUSD_PERP","ps":"EOSUSD","U":167006094897,"u":167006096514,"pu":167006093148,"b":[["3.456","1354"],["3.467","980"]],"a":[["3.493","12121"]]}}
1626916409.222579: {"stream":"bchusd_210924@depth@100ms","data":{"e":"depthUpdate","E":1626916405257,"T":1626916405197,"s":"BCHUSD_210924","ps":"BCHUSD","U":167006095672,"u":167006096452,"pu":167006091343,"b":[],"a":[["429.56","40"],["429.57","20"],["429.58","0"],["429.59","0"]]}}
1626916409.2226: {"stream":"btcusd_211231@depth@100ms","data":{"e":"depthUpdate","E":1626916405264,"T":1626916405243,"s":"BTCUSD_211231","ps":"BTCUSD","U":167006095845,"u":167006097083,"pu":167006095504,"b":[["32535.5","679"],["32539.2","0"],["32580.4","379"],["32584.7","0"],["32623.2","0"]],"a":[["32636.8","0"],["32639.8","77"],["32639.9","75"],["32640.0","23"],["32640.8","0"],["32641.0","153"],["32641.1","0"],["32642.0","0"],["32649.5","0"],["32649.8","0"]]}}
1626916409.222647: {"stream":"etcusd_perp@depth@100ms","data":{"e":"depthUpdate","E":1626916405278,"T":1626916405270,"s":"ETCUSD_PERP","ps":"ETCUSD","U":167006096099,"u":167006097468,"pu":167006095789,"b":[["39.544","0"],["41.983","2000"],["42.223","1310"],["42.232","300"],["42.250","72"]],"a":[["42.286","100"],["42.287","200"],["42.289","0"],["42.291","291"],["42.294","0"],["42.302","34"],["42.313","322"],["42.320","1750"],["42.336","81"],["42.343","23482"],["42.353","300"]]}}
1626916409.222662: {"stream":"trxusd_perp@depth@100ms","data":{"e":"depthUpdate","E":1626916405283,"T":1626916405252,"s":"TRXUSD_PERP","ps":"TRXUSD","U":167006096165,"u":167006097217,"pu":167006092480,"b":[["0.05310","574"],["0.05330","252"],["0.05344","953"],["0.05345","943"],["0.05346","360"]],"a":[["0.05352","969"],["0.05363","96"],["0.05383","53"]]}}
1626916409.222736: {"stream":"ethusd_210924@depth@100ms","data":{"e":"depthUpdate","E":1626916405297,"T":1626916405290,"s":"ETHUSD_210924","ps":"ETHUSD","U":167006096358,"u":167006097864,"pu":167006096264,"b":[["1981.98","2500"],["1983.02","0"],["1986.32","627"],["1989.38","1306"],["1989.63","0"],["1989.67","0"],["1989.90","12"],["1989.98","50"],["1990.22","0"],["1990.39","0"],["1990.63","1500"],["1990.65","1052"],["1990.77","0"],["1990.94","1750"],["1991.16","0"],["1991.18","0"],["1991.20","522"],["1991.29","0"],["1991.30","259"],["1991.49","81"],["1991.50","0"],["1991.51","710"],["1991.52","0"],["1991.53","0"],["1991.59","0"],["1991.89","0"]],"a":[["1981.73","0"],["1991.51","0"],["1991.52","4646"],["1991.54","0"],["1991.60","20"],["1991.79","144"],["1991.80","240"],["1991.87","360"],["1991.88","1369"],["1991.89","3910"],["1991.90","2284"],["1991.96","0"],["1992.00","0"],["1992.04","480"],["1992.08","2034"],["1992.56","0"],["1992.60","1826"],["1992.66","1016"],["1993.01","60"],["1993.06","0"],["1993.14","0"],["1993.27","0"],["1993.31","0"],["1993.53","321"],["1993.54","0"],["1993.80","80"],["1993.99","0"],["1994.32","1500"],["1994.51","338"],["1994.64","338"],["1994.66","372"],["1994.82","372"],["1994.93","0"],["1995.14","406"],["1995.16","406"],["1995.67","440"],["1995.92","474"],["1996.30","0"],["1997.76","3000"],["1999.08","0"],["2001.85","2500"],["2002.90","360"]]}}
1626916409.222773: {"stream":"bchusd_perp@depth@100ms","data":{"e":"depthUpdate","E":1626916405304,"T":1626916405293,"s":"BCHUSD_PERP","ps":"BCHUSD","U":167006096477,"u":167006097897,"pu":167006095824,"b":[["424.92","610"],["427.71","0"],["427.90","169"]],"a":[["427.95","0"],["428.32","4249"],["428.40","63"]]}}
1626916409.22281: {"stream":"linkusd_211231@depth@100ms","data":{"e":"depthUpdate","E":1626916405311,"T":1626916405283,"s":"LINKUSD_211231","ps":"LINKUSD","U":167006096548,"u":167006097721,"pu":167006091901,"b":[["15.285","105"],["15.304","0"]],"a":[["15.327","44"]]}}
1626916409.222817: {"stream":"xrpusd_perp@depth@100ms","data":{"e":"depthUpdate","E":1626916405313,"T":1626916405293,"s":"XRPUSD_PERP","ps":"XRPUSD","U":167006096636,"u":167006097894,"pu":167006096150,"b":[["0.5662","5271"],["0.5663","8179"]],"a":[["0.5666","0"],["0.5667","8158"],["0.5670","5798"],["0.5671","6950"],["0.5672","4072"]]}}
1626916409.222836: {"stream":"eosusd_perp@depth@100ms","data":{"e":"depthUpdate","E":1626916405324,"T":1626916405309,"s":"EOSUSD_PERP","ps":"EOSUSD","U":167006096768,"u":167006098075,"pu":167006096514,"b":[["3.457","2994"],["3.464","5689"],["3.465","7831"],["3.466","2662"],["3.467","954"],["3.468","0"]],"a":[["3.468","400"],["3.474","3589"],["3.475","2916"],["3.478","6285"]]}}
1626916409.223028: {"stream":"btcusd_211231@depth@100ms","data":{"e":"depthUpdate","E":1626916405365,"T":1626916405355,"s":"BTCUSD_211231","ps":"BTCUSD","U":167006097324,"u":167006099242,"pu":167006097083,"b":[["31373.4","0"],["31533.5","0"],["31693.6","0"],["31853.7","0"],["32013.7","0"],["32582.7","179"],["32602.5","0"],["32623.3","0"],["32632.3","0"]],"a":[["32634.1","78"],["32635.6","5"],["32636.8","153"],["32638.9","46"],["32641.0","0"],["32644.4","185"],["32647.0","75"],["32662.5","0"],["32671.9","179"],["32691.8","0"]]}}
1626916409.22306: {"stream":"bchusd_210924@depth@100ms","data":{"e":"depthUpdate","E":1626916405368,"T":1626916405360,"s":"BCHUSD_210924","ps":"BCHUSD","U":167006097335,"u":167006099388,"pu":167006096452,"b":[["427.59","42"],["429.10","40"],["429.23","0"],["429.26","0"]],"a":[["429.54","20"],["429.57","0"],["429.59","300"],["429.83","121"],["430.10","438"],["430.26","1911"],["430.27","525"],["430.93","0"]]}}
1626916409.223302: {"stream":"etcusd_perp@depth@100ms","data":{"e":"depthUpdate","E":1626916405391,"T":1626916405379,"s":"ETCUSD_PERP","ps":"ETCUSD","U":167006097793,"u":167006100127,"pu":167006097468,"b":[["41.983","2000"],["42.203","498"],["42.208","0"],["42.213","515"],["42.247","1335"],["42.254","0"],["42.262","0"],["42.270","90"]],"a":[["42.285","460"],["42.301","90"],["42.303","0"],["42.312","0"],["42.316","22"],["42.320","1990"],["42.325","0"],["42.387","0"]]}}
1626916409.223388: {"stream":"ethusd_210924@depth@100ms","data":{"e":"depthUpdate","E":1626916405397,"T":1626916405390,"s":"ETHUSD_210924","ps":"ETHUSD","U":167006097873,"u":167006100725,"pu":167006097864,"b":[["1967.66","0"],["1972.73","1440"],["1973.07","0"],["1982.69","1440"],["1983.04","0"],["1985.54","3600"],["1985.76","0"],["1987.22","3867"],["1988.48","0"],["1988.50","0"],["1989.17","500"],["1989.38","0"],["1989.50","2943"],["1989.56","322"],["1989.64","0"],["1989.70","280"],["1989.71","301"],["1989.83","259"],["1989.85","0"],["1989.96","0"],["1989.97","0"],["1990.01","3600"],["1990.02","1266"],["1990.18","1000"],["1990.20","0"],["1990.21","0"],["1990.22","1080"],["1990.42","0"],["1990.53","0"],["1990.64","0"],["1990.66","270"],["1990.68","0"],["1990.69","0"],["1990.70","0"],["1990.75","0"],["1990.95","614"],["1991.01","0"],["1991.02","0"],["1991.08","750"],["1991.09","263"],["1991.19","0"],["1991.20","0"],["1991.28","0"],["1991.29","0"],["1991.30","259"],["1991.48","0"],["1991.51","0"]],"a":[["1991.51","0"],["1991.52","4886"],["1991.59","270"],["1991.60","0"],["1991.77","400"],["1991.80","0"],["1991.82","1323"],["1991.83","2544"],["1991.85","1595"],["1991.88","650"],["1991.89","0"],["1991.90","2014"],["1992.17","1612"],["1992.19","419"],["1992.27","259"],["1992.28","280"],["1992.32","0"],["1992.50","363"],["1992.57","0"],["1992.58","343"],["1992.65","0"],["1992.70","384"],["1992.88","0"],["1993.01","0"],["1993.13","100"],["1993.58","0"],["1994.11","6116"],["1994.53","1080"],["1994.96","0"],["1995.24","3600"],["1995.73","0"],["1995.97","0"],["1996.10","1000"],["1996.13","0"],["1996.20","0"],["1996.47","0"],["1997.70","190"],["2002.31","3600"],["2002.60","1440"],["2002.95","0"],["2003.34","0"],["2012.56","1440"],["2012.91","0"]]}}
1626916409.2234812: {"stream":"trxusd_perp@depth@100ms","data":{"e":"depthUpdate","E":1626916405400,"T":1626916405395,"s":"TRXUSD_PERP","ps":"TRXUSD","U":167006097917,"u":167006100989,"pu":167006097217,"b":[["0.05340","2179"],["0.05342","671"],["0.05345","943"],["0.05346","105"]],"a":[["0.05347","20735"]]}}
1626916409.223541: {"stream":"linkusd_perp@depth@100ms","data":{"e":"depthUpdate","E":1626916405403,"T":1626916405395,"s":"LINKUSD_PERP","ps":"LINKUSD","U":167006097941,"u":167006101031,"pu":167006094705,"b":[["15.039","1078"],["15.051","1753"],["15.052","952"],["15.053","1061"],["15.054","168"],["15.055","759"],["15.056","1742"],["15.057","1339"],["15.058","1298"],["15.059","1466"],["15.061","563"],["15.062","110"],["15.063","100"],["15.064","0"],["15.065","0"],["15.066","0"],["15.068","0"]],"a":[["15.068","292"],["15.069","546"],["15.070","0"],["15.071","490"],["15.072","62"],["15.073","4882"],["15.076","659"],["15.077","1831"],["15.078","1492"],["15.079","3056"],["15.080","979"],["15.090","67"],["19.072","4722"]]}}
1626916409.2237551: {"stream":"xrpusd_perp@depth@100ms","data":{"e":"depthUpdate","E":1626916405413,"T":1626916405405,"s":"XRPUSD_PERP","ps":"XRPUSD","U":167006098072,"u":167006101408,"pu":167006097894,"b":[["0.5638","0"],["0.5650","6617"],["0.5653","1758"],["0.5656","10149"],["0.5661","2241"],["0.5662","4874"],["0.5665","380"],["0.5666","0"]],"a":[["0.5666","7379"],["0.5667","8800"],["0.5668","3325"],["0.5669","1644"],["0.5674","1338"],["0.5677","8157"],["0.5680","1037"],["0.5700","8170"]]}}
1626916409.223763: {"stream":"bchusd_perp@depth@100ms","data":{"e":"depthUpdate","E":1626916405413,"T":1626916405398,"s":"BCHUSD_PERP","ps":"BCHUSD","U":167006098066,"u":167006101136,"pu":167006097897,"b":[["427.18","0"],["427.41","390"],["427.42","1288"],["427.49","0"],["427.53","0"],["427.57","0"],["427.65","349"],["427.67","1436"],["427.69","0"],["427.74","0"],["427.78","0"],["427.83","0"],["427.86","0"],["427.87","0"],["427.89","0"],["427.90","0"]],"a":[["427.89","1"],["427.90","0"],["427.97","280"],["428.13","117"],["428.19","676"],["428.37","0"],["428.41","249"],["429.24","56"]]}}
1626916409.224083: {"stream":"eosusd_perp@depth@100ms","data":{"e":"depthUpdate","E":1626916405425,"T":1626916405417,"s":"EOSUSD_PERP","ps":"EOSUSD","U":167006098279,"u":167006102034,"pu":167006098075,"b":[["3.455","2533"],["3.456","930"],["3.457","3294"],["3.459","676"],["3.461","951"],["3.462","5948"],["3.463","3056"],["3.464","2596"],["3.465","6015"],["3.466","2719"],["3.467","0"]],"a":[["3.467","2359"],["3.468","6403"],["3.469","2278"],["3.470","3454"],["3.471","5982"],["3.473","6040"],["3.474","2812"],["3.475","3416"],["3.476","2186"],["3.478","6585"],["3.481","4630"],["3.492","9368"]]}}
1626916409.224115: {"stream":"linkusd_211231@depth@100ms","data":{"e":"depthUpdate","E":1626916405435,"T":1626916405419,"s":"LINKUSD_211231","ps":"LINKUSD","U":167006098508,"u":167006102138,"pu":167006097721,"b":[["15.282","1432"],["15.284","351"],["15.286","49"],["15.288","2143"],["15.290","123"],["15.297","0"],["15.298","0"],["15.299","0"],["15.301","0"],["15.307","80"],["15.319","0"],["15.320","0"]],"a":[["15.334","55"]]}}
1626916409.224451: {"stream":"bchusd_210924@depth@100ms","data":{"e":"depthUpdate","E":1626916405470,"T":1626916405453,"s":"BCHUSD_210924","ps":"BCHUSD","U":167006099506,"u":167006103783,"pu":167006099388,"b":[["429.08","300"],["429.10","0"],["429.11","40"],["429.24","0"],["429.25","0"],["429.26","27"]],"a":[["429.53","40"],["429.56","0"],["429.59","0"],["429.61","102"],["429.65","83"],["429.80","121"],["429.81","0"],["1722.42","0"],["1722.54","12141"]]}}
1626916409.2244742: {"stream":"btcusd_211231@depth@100ms","data":{"e":"depthUpdate","E":1626916405473,"T":1626916405465,"s":"BTCUSD_211231","ps":"BTCUSD","U":167006099646,"u":167006104335,"pu":167006099242,"b":[["31370.0","55"],["31530.0","55"],["31690.1","55"],["31850.1","55"],["32010.2","55"],["32347.3","0"],["32516.8","0"],["32535.5","0"],["32536.2","179"],["32565.8","0"],["32573.0","10"],["32580.9","0"],["32593.7","0"],["32612.2","31"],["32626.0","0"],["32626.5","0"],["32626.6","0"],["32629.4","7"],["32631.1","0"],["32634.0","0"]],"a":[["32629.5","42"],["32629.7","14"],["32630.7","0"],["32631.4","0"],["32632.3","0"],["32632.4","0"],["32634.0","153"],["32634.1","47"],["32635.5","0"],["32635.6","0"],["32636.7","0"],["32636.8","0"],["32636.9","0"],["32637.0","30"],["32638.8","30"],["32638.9","0"],["32646.9","25"],["32664.6","0"],["32698.7","0"]]}}
1626916409.224627: {"stream":"etcusd_perp@depth@100ms","data":{"e":"depthUpdate","E":1626916405498,"T":1626916405478,"s":"ETCUSD_PERP","ps":"ETCUSD","U":167006100588,"u":167006104907,"pu":167006100127,"b":[["41.446","528"],["41.454","820"],["41.869","528"],["41.877","0"],["42.094","1320"],["42.095","0"],["42.188","0"],["42.223","1710"],["42.225","770"],["42.226","322"],["42.232","1320"],["42.237","1121"],["42.238","0"],["42.242","256"],["42.245","494"],["42.247","90"],["42.252","22"],["42.253","300"],["42.256","0"],["42.263","0"],["42.267","300"],["42.268","0"],["42.269","0"],["42.270","0"]],"a":[["42.268","300"],["42.269","0"],["42.270","0"],["42.271","68"],["42.274","252"],["42.282","0"],["42.283","0"],["42.284","0"],["42.286","0"],["42.287","0"],["42.290","90"],["42.291","0"],["42.296","0"],["42.301","0"],["42.310","795"],["42.322","0"],["42.334","500"],["42.338","1618"],["42.342","0"],["42.343","23282"],["42.349","0"],["42.350","1337"],["42.353","0"],["42.364","0"],["42.376","145"],["42.386","25"],["42.406","0"],["42.415","600"],["42.476","1620"],["42.491","105"],["42.713","528"],["42.721","0"],["43.136","528"],["43.144","0"],["109.554","0"]]}}
1626916409.2246559: {"stream":"ethusd_210924@depth@100ms","data":{"e":"depthUpdate","E":1626916405497,"T":1626916405493,"s":"ETHUSD_210924","ps":"ETHUSD","U":167006100754,"u":167006105742,"pu":167006100725,"b":[["1965.68","360"],["1986.93","5349"],["1987.46","3000"],["1987.56","1000"],["1987.73","80"],["1987.93","0"],["1988.31","5676"],["1988.93","12"],["1989.30","0"],["1989.37","0"],["1989.50","2469"],["1989.51","0"],["1989.54","3686"],["1989.58","0"],["1989.86","0"],["1989.92","50"],["1989.98","0"],["1990.14","0"],["1990.18","0"],["1990.23","270"],["1990.25","314"],["1990.64","1604"],["1990.65","1251"],["1990.66","0"],["1990.67","0"],["1990.68","94"],["1990.69","65"],["1990.88","0"],["1990.90","360"],["1990.94","144"],["1990.95","0"],["1990.98","10"],["1991.08","0"],["1991.09","0"],["1991.12","0"],["1991.30","0"],["1991.49","0"]],"a":[["1990.88","0"],["1990.96","0"],["1990.99","780"],["1991.09","0"],["1991.10","1020"],["1991.13","0"],["1991.24","480"],["1991.26","0"],["1991.48","0"],["1991.49","270"],["1991.50","0"],["1991.51","0"],["1991.52","0"],["1991.59","0"],["1991.77","0"],["1991.79","0"],["1991.85","357"],["1991.88","0"],["1992.04","0"],["1992.08","0"],["1992.60","1525"],["1992.81","1705"],["1993.06","400"],["1993.08","1281"],["1993.35","0"],["1993.71","0"],["1994.22","237"],["1994.36","1020"],["1994.64","3338"],["1994.86","0"],["1994.92","2702"],["1994.96","304"],["1995.84","999"],["1995.88","0"],["1996.09","12"],["1996.95","0"],["1997.17","0"],["2002.23","0"],["2005.41","0"]]}}
1626916409.2246778: {"stream":"linkusd_perp@depth@100ms","data":{"e":"depthUpdate","E":1626916405503,"T":1626916405496,"s":"LINKUSD_PERP","ps":"LINKUSD","U":167006101091,"u":167006105885,"pu":167006101031,"b":[["14.933","1267"],["14.951","780"],["14.957","19"],["14.967","0"],["14.986","1267"],["14.988","11443"],["15.004","444"],["15.008","0"],["15.012","851"],["15.013","1312"],["15.015","328"],["15.017","486"],["15.018","451"],["15.020","301"],["15.021","528"],["15.028","679"],["15.036","644"],["15.038","688"],["15.039","2153"],["15.043","61"],["15.045","395"],["15.046","1000"],["15.048","1890"],["15.049","0"],["15.050","373"],["15.051","40"],["15.052","559"],["15.053","1041"],["15.055","379"],["15.056","2023"],["15.057","0"],["15.059","1846"],["15.060","617"],["15.061","35"],["15.062","100"],["15.063","0"]],"a":[["15.065","290"],["15.066","102"],["15.067","760"],["15.068","192"],["15.069","356"],["15.070","0"],["15.071","4523"],["15.072","462"],["15.073","338"],["15.074","490"],["15.075","249"],["15.076","179"],["15.077","1180"],["15.079","3056"],["15.080","779"],["15.081","454"],["15.085","1092"],["15.086","0"],["15.087","1553"],["15.091","280"],["15.099","267"],["15.104","15253"],["15.105","0"],["15.112","2318"],["15.113","615"],["15.114","1525"],["15.118","164"],["15.131","0"],["15.133","300"],["15.138","1875"],["15.145","1"],["15.176","814"],["15.187","612"],["15.190","1287"],["15.199","0"]]}}
1626916409.224957: {"stream":"xrpusd_perp@depth@100ms","data":{"e":"depthUpdate","E":1626916405516,"T":1626916405508,"s":"XRPUSD_PERP","ps":"XRPUSD","U":167006101743,"u":167006106509,"pu":167006101408,"b":[["0.5582","1125"],["0.5583","6"],["0.5624","4810"],["0.5626","1261"],["0.5634","12027"],["0.5637","2008"],["0.5640","1762"],["0.5650","6317"],["0.5652","501"],["0.5656","10079"],["0.5658","5086"],["0.5659","2757"],["0.5660","10626"],["0.5661","3851"],["0.5662","1360"],["0.5663","3265"],["0.5664","1051"],["0.5665","0"]],"a":[["0.5665","5984"],["0.5666","6746"],["0.5667","4446"],["0.5668","3416"],["0.5669","1153"],["0.5670","3294"],["0.5671","4541"],["0.5672","2464"],["0.5674","2830"],["0.5675","8490"],["0.5678","5967"],["0.5686","24292"],["0.5687","844"],["0.5692","7133"],["0.5696","4093"],["0.5707","2329"],["0.5709","655"],["0.5749","781"],["0.5752","3086"]]}}
1626916409.224967: {"stream":"bchusd_perp@depth@100ms","data":{"e":"depthUpdate","E":1626916405516,"T":1626916405501,"s":"BCHUSD_PERP","ps":"BCHUSD","U":167006101582,"u":167006106161,"pu":167006101136,"b":[["427.00","226"],["427.50","3993"],["427.59","300"],["427.65","49"],["427.66","2868"],["427.68","0"],["427.69","100"],["427.70","130"],["427.76","0"],["427.77","0"],["427.78","0"]],"a":[["427.86","130"],["427.87","150"],["427.90","130"],["427.97","846"]]}}
1626916409.225015: {"stream":"trxusd_perp@depth@100ms","data":{"e":"depthUpdate","E":1626916405517,"T":1626916405510,"s":"TRXUSD_PERP","ps":"TRXUSD","U":167006101840,"u":167006106550,"pu":167006100989,"b":[["0.05307","783"],["0.05310","874"],["0.05330","402"],["0.05339","2185"],["0.05345","322"],["0.05346","5"]],"a":[["0.05347","20820"],["0.05357","1626"],["0.05363","246"],["0.05383","353"]]}}
1626916409.225079: {"stream":"eosusd_perp@depth@100ms","data":{"e":"depthUpdate","E":1626916405525,"T":1626916405510,"s":"EOSUSD_PERP","ps":"EOSUSD","U":167006102158,"u":167006106566,"pu":167006102034,"b":[["3.417","506"],["3.443","6420"],["3.444","10030"],["3.445","5021"],["3.446","13043"],["3.453","3141"],["3.454","4369"],["3.455","2209"],["3.461","1728"],["3.462","5375"],["3.463","4154"],["3.464","2829"],["3.465","3259"],["3.466","528"]],"a":[["3.467","2472"],["3.468","5390"],["3.469","2063"],["3.470","2683"],["3.471","6654"],["3.472","5972"],["3.473","3418"],["3.476","3946"],["3.478","4825"],["3.480","2067"],["3.481","4954"],["3.482","2809"],["3.491","702"],["3.493","12121"],["3.519","587"]]}}
1626916409.225166: {"stream":"linkusd_211231@depth@100ms","data":{"e":"depthUpdate","E":1626916405536,"T":1626916405521,"s":"LINKUSD_211231","ps":"LINKUSD","U":167006102641,"u":167006106884,"pu":167006102138,"b":[["14.760","1122"],["14.836","100"],["14.911","100"],["14.973","0"],["14.985","576"],["14.986","100"],["15.062","100"],["15.120","0"],["15.123","576"],["15.192","876"],["15.194","0"],["15.254","576"],["15.267","2295"],["15.274","295"],["15.275","0"],["15.278","1441"],["15.279","0"],["15.281","53"],["15.282","0"],["15.285","5"],["15.289","751"],["15.308","0"],["15.309","80"],["15.312","200"],["15.313","94"]],"a":[["15.330","2309"],["15.336","0"],["15.360","172"],["15.369","576"],["15.370","0"],["15.379","0"],["15.415","665"],["15.427","62"],["15.459","576"],["15.475","0"],["15.526","164"],["15.550","576"],["15.571","0"],["15.601","165"],["15.676","204"],["15.752","167"],["15.827","168"]]}}
1626916409.225462: {"stream":"btcusd_211231@depth@100ms","data":{"e":"depthUpdate","E":1626916405574,"T":1626916405564,"s":"BTCUSD_211231","ps":"BTCUSD","U":167006104448,"u":167006108582,"pu":167006104335,"b":[["32475.4","0"],["32492.9","0"],["32503.5","591"],["32529.1","0"],["32580.4","0"],["32586.9","401"],["32588.1","15"],["32600.3","0"],["32602.7","1059"],["32605.9","97"],["32606.8","77"],["32608.1","0"],["32610.7","0"],["32610.8","0"],["32612.3","160"],["32612.7","10"],["32614.5","8"],["32614.9","200"],["32616.7","0"],["32617.1","0"],["32617.2","0"],["32617.3","0"],["32618.9","0"],["32619.0","175"],["32619.5","0"],["32620.4","0"],["32620.7","14"],["32621.1","0"],["32621.2","0"],["32622.1","0"],["32625.3","0"],["32629.4","0"]],"a":[["32625.3","0"],["32625.4","0"],["32626.3","0"],["32626.4","0"],["32626.5","0"],["32626.6","0"],["32627.6","153"],["32627.7","16"],["32627.8","14"],["32627.9","0"],["32629.4","0"],["32629.5","0"],["32629.6","0"],["32629.7","0"],["32633.7","46"],["32634.0","0"],["32634.1","1"],["32636.0","10"],["32639.7","0"],["32643.8","0"],["32660.1","114"],["32662.1","372"],["32663.4","476"],["32672.9","0"],["32683.4","0"],["32699.9","601"],["32739.5","0"]]}}
1626916409.2255518: {"stream":"ethusd_210924@depth@100ms","data":{"e":"depthUpdate","E":1626916405597,"T":1626916405592,"s":"ETHUSD_210924","ps":"ETHUSD","U":167006105773,"u":167006109539,"pu":167006105742,"b":[["1972.18","1440"],["1972.73","0"],["1982.14","1440"],["1982.69","0"],["1983.74","0"],["1984.99","3600"],["1985.54","0"],["1986.43","0"],["1988.35","365"],["1988.68","1774"],["1988.73","0"],["1988.75","425"],["1988.87","642"],["1988.94","0"],["1989.17","0"],["1989.28","100"],["1989.50","6069"],["1989.51","992"],["1989.54","0"],["1989.55","2430"],["1989.57","1403"],["1989.66","0"],["1989.76","385"],["1989.78","0"],["1989.93","1080"],["1990.01","0"],["1990.02","0"],["1990.10","0"],["1990.11","1242"],["1990.15","0"],["1990.22","0"],["1990.23","0"],["1990.25","0"],["1990.26","0"],["1990.64","0"],["1990.67","0"],["1990.68","0"],["1990.69","0"],["1990.70","270"],["1990.72","0"],["1990.73","125"],["1990.76","360"],["1990.90","0"],["1990.91","0"],["1990.94","0"],["1990.98","379"]],"a":[["1990.99","1020"],["1991.10","0"],["1991.23","0"],["1991.31","435"],["1991.32","1238"],["1991.33","50"],["1991.48","270"],["1991.49","0"],["1991.81","0"],["1991.82","1015"],["1991.88","259"],["1991.89","280"],["1991.90","0"],["1992.04","322"],["1992.06","0"],["1992.18","383"],["1992.23","301"],["1992.27","0"],["1992.28","0"],["1992.60","269"],["1992.61","0"],["1992.68","289"],["1992.79","365"],["1993.06","0"],["1993.15","0"],["1993.21","401"],["1993.22","0"],["1993.24","0"],["1993.37","501"],["1993.56","0"],["1993.98","1080"],["1994.37","2427"],["1994.43","0"],["1994.53","0"],["1994.68","3600"],["1994.80","542"],["1994.83","0"],["1994.87","0"],["1995.22","155"],["1995.23","1056"],["1995.24","0"],["1995.39","0"],["1995.66","998"],["1995.71","0"],["1997.23","0"],["1997.40","190"],["1998.68","0"],["2000.25","0"],["2001.75","3600"],["2002.04","1440"],["2002.31","0"],["2002.60","0"],["2003.67","0"],["2003.80","2975"],["2005.93","6812"],["2012.00","1440"],["2012.56","0"],["2013.36","0"]]}}
1626916409.22557: {"stream":"etcusd_perp@depth@100ms","data":{"e":"depthUpdate","E":1626916405601,"T":1626916405595,"s":"ETCUSD_PERP","ps":"ETCUSD","U":167006105475,"u":167006109614,"pu":167006104907,"b":[["41.436","528"],["41.446","0"],["41.847","210"],["41.856","0"],["41.859","528"],["41.869","0"],["41.910","0"],["41.920","7447"],["41.937","0"],["42.069","953"],["42.072","0"],["42.080","336"],["42.084","1320"],["42.094","0"],["42.098","0"],["42.164","300"],["42.168","145"],["42.184","70"],["42.187","145"],["42.189","533"],["42.194","0"],["42.196","0"],["42.203","0"],["42.204","1626"],["42.208","200"],["42.214","0"],["42.216","56"],["42.218","56"],["42.219","100"],["42.221","1335"],["42.222","0"],["42.223","1310"],["42.225","1190"],["42.229","400"],["42.231","30"],["42.232","0"],["42.233","100"],["42.234","508"],["42.236","25"],["42.239","0"],["42.242","0"],["42.244","0"],["42.245","98"],["42.246","592"],["42.247","0"],["42.249","300"],["42.250","17"],["42.252","0"],["42.253","0"],["42.261","0"],["42.267","0"]],"a":[["42.265","100"],["42.266","652"],["42.267","0"],["42.268","1105"],["42.270","381"],["42.271","68"],["42.273","90"],["42.274","0"],["42.283","281"],["42.284","341"],["42.290","0"],["42.301","0"],["42.302","0"],["42.304","0"],["42.305","22"],["42.306","22"],["42.310","762"],["42.313","0"],["42.316","0"],["42.318","100"],["42.320","1516"],["42.323","0"],["42.325","56"],["42.327","396"],["42.330","38"],["42.334","900"],["42.335","0"],["42.336","25"],["42.338","0"],["42.340","1400"],["42.341","15"],["42.350","17"],["42.353","69"],["42.365","0"],["42.374","145"],["42.376","0"],["42.377","300"],["42.390","3347"],["42.465","1320"],["42.475","379"],["42.476","300"],["42.484","110"],["42.485","0"],["42.489","336"],["42.494","0"],["42.505","0"],["42.580","0"],["42.652","0"],["42.682","210"],["42.694","0"],["42.702","528"],["42.713","0"],["42.747","0"],["43.125","528"],["43.136","0"],["109.667","22799"]]}}
1626916409.22559: {"stream":"linkusd_perp@depth@100ms","data":{"e":"depthUpdate","E":1626916405604,"T":1626916405599,"s":"LINKUSD_PERP","ps":"LINKUSD","U":167006105933,"u":167006109735,"pu":167006105885,"b":[["14.929","1267"],["14.933","0"],["14.959","3025"],["14.961","612"],["14.963","0"],["14.982","1720"],["14.986","0"],["15.004","706"],["15.008","451"],["15.009","2783"],["15.010","500"],["15.013","45"],["15.018","0"],["15.026","597"],["15.033","15615"],["15.034","87"],["15.035","1433"],["15.036","452"],["15.037","3520"],["15.039","886"],["15.040","538"],["15.044","884"],["15.045","15"],["15.047","3362"],["15.048","178"],["15.049","200"],["15.050","225"],["15.051","1342"],["15.052","609"],["15.053","409"],["15.055","150"],["15.056","1913"],["15.057","669"],["15.058","144"],["15.059","180"],["15.060","101"],["15.061","4"],["15.062","0"],["15.063","0"]],"a":[["14.988","0"],["15.063","100"],["15.064","292"],["15.065","190"],["15.066","102"],["15.067","470"],["15.069","736"],["15.071","4633"],["15.074","229"],["15.076","150"],["15.077","1605"],["15.078","751"],["15.079","1546"],["15.081","48"],["15.082","2244"],["15.085","1145"],["15.087","286"],["15.092","191"],["15.093","1862"],["15.096","1046"],["15.103","3455"],["15.108","3502"],["15.112","1051"],["15.117","500"],["15.120","1544"],["15.124","245"],["15.129","1094"],["15.134","1447"],["15.138","608"],["15.159","1472"],["15.170","960"],["15.175","601"],["15.181","2505"],["15.186","1267"],["15.190","20"]]}}
1626916409.2257721: {"stream":"bchusd_perp@depth@100ms","data":{"e":"depthUpdate","E":1626916405616,"T":1626916405607,"s":"BCHUSD_PERP","ps":"BCHUSD","U":167006106234,"u":167006110001,"pu":167006106161,"b":[["425.60","507"],["426.49","1000"],["427.22","351"],["427.51","3034"],["427.57","100"],["427.65","0"],["427.66","0"],["427.67","240"],["427.68","130"],["427.69","0"],["427.70","0"]],"a":[["427.84","150"],["427.90","100"],["427.91","24"],["427.97","696"],["427.99","1"],["428.08","100"],["428.13","17"],["428.15","200"],["428.21","0"],["428.25","44"],["428.32","4205"],["428.60","114"],["428.62","192"],["428.69","122"],["429.38","0"]]}}
1626916409.225844: {"stream":"xrpusd_perp@depth@100ms","data":{"e":"depthUpdate","E":1626916405617,"T":1626916405609,"s":"XRPUSD_PERP","ps":"XRPUSD","U":167006106589,"u":167006110090,"pu":167006106509,"b":[["0.5633","2820"],["0.5635","531"],["0.5647","6169"],["0.5648","23761"],["0.5650","6012"],["0.5653","1758"],["0.5655","1097"],["0.5656","11289"],["0.5657","2646"],["0.5659","6746"],["0.5660","12554"],["0.5661","5860"],["0.5662","873"],["0.5663","2030"],["0.5664","67"]],"a":[["0.5662","0"],["0.5664","0"],["0.5665","7154"],["0.5666","5430"],["0.5667","6488"],["0.5668","3989"],["0.5669","3080"],["0.5670","3860"],["0.5671","4329"],["0.5672","2164"],["0.5674","3105"],["0.5675","8215"],["0.5676","31064"],["0.5679","4902"],["0.5683","1485"],["0.5684","1227"],["0.5685","4752"],["0.5686","23020"],["0.5703","360"],["0.5707","2024"]]}}
1626916409.225896: {"stream":"trxusd_perp@depth@100ms","data":{"e":"depthUpdate","E":1626916405624,"T":1626916405616,"s":"TRXUSD_PERP","ps":"TRXUSD","U":167006106812,"u":167006110278,"pu":167006106550,"b":[["0.05313","53"],["0.05327","152"],["0.05328","2547"],["0.05329","2005"],["0.05336","1216"],["0.05338","2017"],["0.05339","1358"],["0.05341","1744"],["0.05342","943"],["0.05343","494"],["0.05344","1150"]],"a":[["0.05347","20900"],["0.05348","535"],["0.05349","333"],["0.05350","1912"],["0.05351","2147"],["0.05352","1248"],["0.05355","957"],["0.05356","1531"],["0.05357","867"],["0.05358","1395"],["0.05361","349"],["0.05365","4064"],["0.05366","1257"],["0.05380","175"],["0.05385","1496"]]}}
1626916409.225921: {"stream":"eosusd_perp@depth@100ms","data":{"e":"depthUpdate","E":1626916405631,"T":1626916405621,"s":"EOSUSD_PERP","ps":"EOSUSD","U":167006106951,"u":167006110457,"pu":167006106566,"b":[["3.442","16296"],["3.445","4481"],["3.454","4045"],["3.455","1885"],["3.460","3330"],["3.461","1448"],["3.462","6213"],["3.463","3453"],["3.464","2547"],["3.465","3673"],["3.466","0"]],"a":[["3.467","2462"],["3.468","5790"],["3.469","2140"],["3.470","2884"],["3.471","7100"],["3.472","5672"],["3.473","3198"],["3.474","2532"],["3.475","2916"],["3.480","1743"],["3.481","4630"],["3.484","1647"],["3.490","2295"],["3.491","162"],["3.492","9908"],["3.494","1567"]]}}
1626916409.225929: {"stream":"bchusd_210924@depth@100ms","data":{"e":"depthUpdate","E":1626916405633,"T":1626916405617,"s":"BCHUSD_210924","ps":"BCHUSD","U":167006107228,"u":167006110283,"pu":167006103783,"b":[["429.02","0"],["429.10","40"],["429.11","0"]],"a":[["429.50","80"],["429.54","0"],["430.02","23"],["430.10","415"]]}}
1626916409.225981: {"stream":"linkusd_211231@depth@100ms","data":{"e":"depthUpdate","E":1626916405639,"T":1626916405619,"s":"LINKUSD_211231","ps":"LINKUSD","U":167006107323,"u":167006110340,"pu":167006106884,"b":[["15.269","1432"],["15.271","0"],["15.274","295"],["15.276","0"],["15.278","9"]],"a":[]}}
1626916409.226088: {"stream":"btcusd_211231@depth@100ms","data":{"e":"depthUpdate","E":1626916405675,"T":1626916405663,"s":"BTCUSD_211231","ps":"BTCUSD","U":167006108794,"u":167006111583,"pu":167006108582,"b":[["32302.7","20"],["32338.3","0"],["32573.0","0"],["32573.2","12"],["32581.7","240"],["32588.1","360"],["32590.7","0"],["32605.9","12"],["32606.8","0"],["32606.9","147"],["32608.0","10"],["32612.7","0"],["32614.5","0"],["32620.7","82"],["32621.1","0"],["32621.4","0"],["32622.4","0"],["32626.2","0"],["32627.6","0"]],"a":[["32620.8","0"],["32621.0","0"],["32621.2","0"],["32623.4","16"],["32624.2","0"],["32624.6","0"],["32625.0","153"],["32625.1","0"],["32625.9","14"],["32627.6","0"],["32627.7","0"],["32627.8","0"],["32629.3","86"],["32629.4","11"],["32629.8","77"],["32631.7","10"],["32636.0","0"],["32637.0","0"],["32639.8","0"],["32639.9","0"],["32640.0","0"]]}}
1626916409.226136: {"stream":"ethusd_210924@depth@100ms","data":{"e":"depthUpdate","E":1626916405698,"T":1626916405692,"s":"ETHUSD_210924","ps":"ETHUSD","U":167006109600,"u":167006112270,"pu":167006109539,"b":[["1986.01","1000"],["1986.04","0"],["1987.86","2197"],["1987.89","541"],["1987.91","0"],["1988.38","2100"],["1988.90","0"],["1988.91","4395"],["1988.96","0"],["1989.01","0"],["1989.11","0"],["1989.28","0"],["1989.46","0"],["1989.51","2252"],["1989.52","50"],["1989.92","0"],["1989.94","100"],["1990.12","270"],["1990.33","466"],["1990.64","0"],["1990.66","0"],["1990.69","360"],["1990.70","0"],["1990.73","0"],["1990.76","0"],["1990.77","125"]],"a":[["1991.31","435"],["1991.48","0"],["1991.81","270"],["1991.82","1096"],["1992.40","405"],["1992.59","0"],["1992.60","0"],["1992.65","425"],["1992.73","0"],["1993.20","532"],["1993.52","2000"],["1993.77","627"],["1994.70","0"],["1995.96","1000"],["1996.21","0"],["1996.56","0"],["2002.41","9911"],["2003.96","0"],["2008.08","397"]]}}
1626916409.226157: {"stream":"etcusd_perp@depth@100ms","data":{"e":"depthUpdate","E":1626916405703,"T":1626916405695,"s":"ETCUSD_PERP","ps":"ETCUSD","U":167006109696,"u":167006112358,"pu":167006109614,"b":[["41.866","560"],["41.890","4583"],["42.052","150"],["42.053","336"],["42.172","145"],["42.186","501"],["42.187","0"],["42.205","860"],["42.216","0"],["42.220","2547"],["42.225","0"],["42.227","0"],["42.231","289"],["42.233","100"],["42.234","418"],["42.237","0"],["42.243","0"],["42.244","282"],["42.249","0"]],"a":[["42.262","100"],["42.263","200"],["42.265","0"],["42.266","550"],["42.267","0"],["42.268","633"],["42.269","90"],["42.270","670"],["42.273","0"],["42.282","0"],["42.300","200"],["42.304","0"],["42.306","0"],["42.309","2354"],["42.322","56"],["42.325","0"],["42.354","0"],["42.364","145"],["42.368","915"],["42.415","0"],["42.460","336"],["42.467","152"],["42.475","43"],["42.631","560"],["42.691","84"]]}}
1626916409.226167: {"stream":"linkusd_perp@depth@100ms","data":{"e":"depthUpdate","E":1626916405705,"T":1626916405692,"s":"LINKUSD_PERP","ps":"LINKUSD","U":167006109763,"u":167006112281,"pu":167006109735,"b":[["14.910","1800"],["14.927","0"],["14.986","600"],["14.990","1113"],["15.000","2853"],["15.004","262"],["15.005","444"],["15.009","3283"],["15.020","0"],["15.024","391"],["15.032","620"],["15.033","15807"],["15.034","665"],["15.036","260"],["15.042","2449"],["15.049","580"],["15.051","781"],["15.052","580"],["15.053","3094"],["15.054","1493"],["15.055","0"],["15.056","1762"],["15.057","506"],["15.060","165"],["15.061","0"]],"a":[["15.062","190"],["15.065","0"],["15.066","602"],["15.069","684"],["15.070","1957"],["15.071","5042"],["15.072","691"],["15.073","338"],["15.074","0"],["15.090","259"],["15.112","1551"],["15.124","689"],["15.129","650"],["15.135","600"],["15.168","3821"],["15.173","0"]]}}
1626916409.226274: {"stream":"xrpusd_perp@depth@100ms","data":{"e":"depthUpdate","E":1626916405717,"T":1626916405708,"s":"XRPUSD_PERP","ps":"XRPUSD","U":167006110147,"u":167006112626,"pu":167006110090,"b":[["0.5631","2559"],["0.5646","1287"],["0.5647","6805"],["0.5649","3193"],["0.5651","0"],["0.5656","11564"],["0.5658","5246"],["0.5659","6844"],["0.5660","16461"],["0.5661","5825"],["0.5662","892"],["0.5663","1965"],["0.5664","32"]],"a":[["0.5664","0"],["0.5665","7548"],["0.5666","5392"],["0.5667","6523"],["0.5668","3996"],["0.5669","2954"],["0.5670","3604"],["0.5671","1438"],["0.5672","2246"],["0.5674","3380"],["0.5682","7239"],["0.5684","1863"],["0.5689","5800"],["0.5701","1820"]]}}
1626916409.226292: {"stream":"bchusd_perp@depth@100ms","data":{"e":"depthUpdate","E":1626916405719,"T":1626916405710,"s":"BCHUSD_PERP","ps":"BCHUSD","U":167006110161,"u":167006112688,"pu":167006110001,"b":[["426.40","1080"],["427.14","519"],["427.18","501"],["427.44","44"],["427.48","0"],["427.52","1816"],["427.54","468"],["427.57","0"],["427.59","0"],["427.62","0"],["427.64","100"],["427.66","27"],["427.67","0"],["427.77","0"]],"a":[["427.89","1"],["427.90","0"],["427.95","0"],["427.96","100"],["427.97","747"],["428.12","795"],["428.13","0"],["428.19","720"],["428.27","0"],["428.32","3171"],["428.51","15"],["428.54","114"],["429.29","264"],["431.00","0"]]}}
1626916409.226368: {"stream":"trxusd_perp@depth@100ms","data":{"e":"depthUpdate","E":1626916405728,"T":1626916405718,"s":"TRXUSD_PERP","ps":"TRXUSD","U":167006110496,"u":167006112870,"pu":167006110278,"b":[["0.05312","2217"],["0.05325","1554"],["0.05335","605"],["0.05337","1467"],["0.05338","2075"],["0.05341","1778"],["0.05342","821"],["0.05343","616"],["0.05345","403"]],"a":[["0.05348","935"],["0.05349","969"],["0.05350","1790"],["0.05351","2139"],["0.05353","1824"],["0.05354","1171"],["0.05355","835"],["0.05364","2231"],["0.05366","1005"],["0.05367","323"],["0.05379","481"],["0.05383","573"]]}}
1626916409.226378: {"stream":"eosusd_perp@depth@100ms","data":{"e":"depthUpdate","E":1626916405734,"T":1626916405726,"s":"EOSUSD_PERP","ps":"EOSUSD","U":167006110565,"u":167006113050,"pu":167006110457,"b":[["3.444","10570"],["3.453","3465"],["3.454","4369"],["3.458","16321"],["3.460","1783"],["3.462","8010"],["3.463","5259"],["3.464","1646"],["3.465","4204"],["3.466","0"]],"a":[["3.466","680"],["3.467","2382"],["3.468","4783"],["3.469","3169"],["3.470","2158"],["3.471","7074"],["3.473","2538"],["3.475","2102"],["3.479","4980"],["3.480","2067"]]}}
1626916409.2263958: {"stream":"bchusd_210924@depth@100ms","data":{"e":"depthUpdate","E":1626916405735,"T":1626916405723,"s":"BCHUSD_210924","ps":"BCHUSD","U":167006110662,"u":167006112981,"pu":167006110283,"b":[["429.26","0"],["429.27","27"]],"a":[["429.49","40"],["429.50","0"],["429.53","0"],["430.07","90"],["430.18","12"]]}}
1626916409.226489: {"stream":"btcusd_211231@depth@100ms","data":{"e":"depthUpdate","E":1626916405777,"T":1626916405767,"s":"BTCUSD_211231","ps":"BTCUSD","U":167006111772,"u":167006113922,"pu":167006111583,"b":[["32299.0","100"],["32322.6","0"],["32489.0","2"],["32503.5","0"],["32572.0","376"],["32588.1","345"],["32620.7","0"],["32623.3","77"]],"a":[["32623.4","16"],["32624.9","0"],["32625.0","0"],["32625.8","153"],["32629.2","0"],["32638.8","0"],["32648.3","75"],["32653.4","0"],["32719.5","0"],["32755.5","0"]]}}
1626916409.226497: {"stream":"linkusd_211231@depth@100ms","data":{"e":"depthUpdate","E":1626916405778,"T":1626916405765,"s":"LINKUSD_211231","ps":"LINKUSD","U":167006111765,"u":167006113877,"pu":167006110340,"b":[["15.160","331"],["15.177","240"],["15.268","0"],["15.312","0"]],"a":[["15.349","122"],["15.366","560"],["15.390","0"]]}}
1626916409.2265558: {"stream":"ethusd_210924@depth@100ms","data":{"e":"depthUpdate","E":1626916405802,"T":1626916405796,"s":"ETHUSD_210924","ps":"ETHUSD","U":167006112425,"u":167006114531,"pu":167006112270,"b":[["1840.88","0"],["1984.67","1400"],["1986.43","120"],["1988.03","0"],["1988.08","414"],["1988.23","169"],["1988.38","2000"],["1988.55","507"],["1989.52","0"],["1989.81","50"],["1990.12","0"],["1990.34","0"],["1990.64","0"],["1990.69","0"],["1990.70","0"],["1990.71","0"],["1990.72","0"],["1990.73","360"],["1990.77","0"],["1990.78","270"],["1990.79","576"]],"a":[["1991.24","0"],["1991.33","0"],["1992.40","0"],["1992.53","0"],["1992.54","0"],["1992.62","100"],["1992.87","300"],["1993.13","0"],["1994.26","372"],["1994.93","2244"],["1995.75","1500"],["1998.54","0"]]}}
1626916409.2265651: {"stream":"etcusd_perp@depth@100ms","data":{"e":"depthUpdate","E":1626916405804,"T":1626916405797,"s":"ETCUSD_PERP","ps":"ETCUSD","U":167006112393,"u":167006114578,"pu":167006112358,"b":[["42.093","452"],["42.157","145"],["42.162","70"],["42.168","0"],["42.202","0"],["42.204","1926"],["42.205","916"],["42.206","0"],["42.209","56"],["42.218","0"],["42.219","0"],["42.220","2457"],["42.224","290"],["42.225","22"],["42.230","107"],["42.234","396"],["42.240","0"],["42.244","0"]],"a":[["42.266","793"],["42.269","0"],["42.270","381"],["42.282","90"],["42.295","322"],["42.296","22"],["42.297","22"],["42.305","0"],["42.308","730"],["42.313","56"],["42.314","56"],["42.318","0"],["42.322","0"],["42.363","145"],["42.374","0"],["42.415","2509"],["42.440","300"],["42.476","0"],["42.504","400"],["42.549","0"],["42.671","8077"],["43.055","0"]]}}
1626916409.226584: {"stream":"linkusd_perp@depth@100ms","data":{"e":"depthUpdate","E":1626916405806,"T":1626916405801,"s":"LINKUSD_PERP","ps":"LINKUSD","U":167006112499,"u":167006114628,"pu":167006112281,"b":[["14.745","1459"],["14.761","0"],["14.890","5702"],["15.013","0"],["15.028","659"],["15.029","2647"],["15.033","15615"],["15.034","87"],["15.036","794"],["15.037","3020"],["15.039","766"],["15.042","737"],["15.044","1032"],["15.047","3214"],["15.049","638"],["15.052","551"],["15.054","1493"],["15.057","506"],["15.058","20"],["15.060","291"]],"a":[["15.070","2337"],["15.071","3472"],["15.072","491"],["15.074","274"],["15.076","224"],["15.077","1531"],["15.079","1472"],["15.087","478"],["15.090","259"],["15.093","1670"],["15.102","400"],["15.117","944"],["15.120","1100"],["15.133","700"],["15.154","110"]]}}
1626916409.226708: {"stream":"xrpusd_perp@depth@100ms","data":{"e":"depthUpdate","E":1626916405818,"T":1626916405813,"s":"XRPUSD_PERP","ps":"XRPUSD","U":167006112747,"u":167006114826,"pu":167006112626,"b":[["0.5628","9011"],["0.5630","1226"],["0.5647","6169"],["0.5648","23774"],["0.5652","487"],["0.5653","1758"],["0.5656","11289"],["0.5658","5086"],["0.5659","7071"],["0.5660","10484"],["0.5661","6128"],["0.5662","1863"],["0.5663","1615"],["0.5664","0"]],"a":[["0.5662","0"],["0.5664","8832"],["0.5665","7043"],["0.5666","2662"],["0.5667","6363"],["0.5668","4038"],["0.5669","2760"],["0.5670","3498"],["0.5673","3233"],["0.5676","30564"],["0.5683","1985"],["0.5701","2880"],["0.5702","577"]]}}
1626916409.226735: {"stream":"bchusd_perp@depth@100ms","data":{"e":"depthUpdate","E":1626916405822,"T":1626916405813,"s":"BCHUSD_PERP","ps":"BCHUSD","U":167006112868,"u":167006114844,"pu":167006112688,"b":[["426.20","374"],["426.31","0"],["426.63","1224"],["426.66","49"],["427.41","434"],["427.50","5111"],["427.53","100"],["427.54","485"],["427.55","17"],["427.61","0"],["427.64","0"],["427.77","0"]],"a":[["427.88","100"],["427.96","0"],["428.05","400"],["428.06","17"],["428.07","117"],["428.08","0"],["428.09","200"],["428.12","778"],["428.13","0"],["428.15","0"],["428.16","2785"],["428.20","400"],["428.22","1392"],["428.94","0"],["429.32","110"],["430.85","440"]]}}
1626916409.2268229: {"stream":"trxusd_perp@depth@100ms","data":{"e":"depthUpdate","E":1626916405831,"T":1626916405817,"s":"TRXUSD_PERP","ps":"TRXUSD","U":167006113035,"u":167006114878,"pu":167006112870,"b":[["0.05336","1330"],["0.05338","1995"],["0.05341","1340"],["0.05342","901"],["0.05343","1062"]],"a":[["0.05347","20815"],["0.05350","1230"],["0.05351","2261"],["0.05352","1727"],["0.05355","1071"],["0.05356","1417"],["0.05358","1438"],["0.05364","2363"],["0.05366","1137"],["0.05379","701"]]}}
1626916409.226848: {"stream":"eosusd_perp@depth@100ms","data":{"e":"depthUpdate","E":1626916405836,"T":1626916405826,"s":"EOSUSD_PERP","ps":"EOSUSD","U":167006113152,"u":167006115021,"pu":167006113050,"b":[["3.416","584"],["3.417","0"],["3.442","16802"],["3.443","5914"],["3.447","0"],["3.452","6916"],["3.453","2198"],["3.455","4963"],["3.456","829"],["3.458","13240"],["3.459","816"],["3.460","1643"],["3.461","1378"],["3.462","9447"],["3.463","4393"],["3.464","1245"]],"a":[["3.466","687"],["3.469","3548"],["3.470","3664"],["3.471","7976"],["3.472","4545"],["3.473","2898"],["3.474","3032"],["3.476","3446"],["3.479","5480"],["3.481","5897"],["3.482","1542"],["3.483","857"],["3.492","10414"],["3.493","11615"],["3.518","5579"],["3.519","81"]]}}
1626916409.226895: {"stream":"bchusd_210924@depth@100ms","data":{"e":"depthUpdate","E":1626916405846,"T":1626916405837,"s":"BCHUSD_210924","ps":"BCHUSD","U":167006113364,"u":167006115217,"pu":167006112981,"b":[["429.00","0"]],"a":[["429.46","40"],["429.47","40"],["429.49","0"],["429.60","0"],["429.94","3793"]]}}
1626916409.22695: {"stream":"btcusd_211231@depth@100ms","data":{"e":"depthUpdate","E":1626916405878,"T":1626916405863,"s":"BTCUSD_211231","ps":"BTCUSD","U":167006114023,"u":167006115625,"pu":167006113922,"b":[["32489.0","0"],["32494.0","591"],["32585.9","15"]],"a":[["32625.8","153"],["32629.2","0"],["32719.8","0"],["33040.2","0"],["33200.2","331"],["33360.3","0"],["33520.4","0"],["33680.5","0"]]}}
1626916409.2269728: {"stream":"linkusd_211231@depth@100ms","data":{"e":"depthUpdate","E":1626916405898,"T":1626916405884,"s":"LINKUSD_211231","ps":"LINKUSD","U":167006114400,"u":167006115902,"pu":167006113877,"b":[["13.797","303"],["15.264","40"],["15.267","3727"],["15.269","0"]],"a":[["15.330","1854"]]}}
1626916409.226979: {"stream":"etcusd_perp@depth@100ms","data":{"e":"depthUpdate","E":1626916405904,"T":1626916405895,"s":"ETCUSD_PERP","ps":"ETCUSD","U":167006114589,"u":167006116076,"pu":167006114578,"b":[["41.838","306"],["41.936","829"],["41.980","0"],["42.018","400"],["42.069","1289"],["42.080","0"],["42.190","314"],["42.193","1664"],["42.204","623"],["42.220","1467"],["42.221","1425"],["42.223","0"],["42.226","0"],["42.229","0"],["42.230","17"],["42.234","696"],["42.240","0"]],"a":[["42.266","550"],["42.270","471"],["42.282","0"],["42.323","200"],["42.334","500"],["42.354","145"],["42.364","0"],["42.489","0"],["42.570","2000"],["42.672","0"],["42.675","300"]]}}
1626916409.227011: {"stream":"ethusd_210924@depth@100ms","data":{"e":"depthUpdate","E":1626916405911,"T":1626916405887,"s":"ETHUSD_210924","ps":"ETHUSD","U":167006114655,"u":167006115953,"pu":167006114531,"b":[["1839.82","2276"],["1987.74","372"],["1987.90","1623"],["1988.16","316"],["1988.30","270"],["1988.43","100"],["1988.78","203"],["1989.07","3740"],["1989.08","1310"],["1990.79","480"],["1990.80","262"]],"a":[["1991.11","480"],["1991.57","400"],["1991.82","2298"],["1991.85","4018"],["1993.03","404"],["1994.92","3006"],["1997.13","9070"]]}}
1626916409.227027: {"stream":"linkusd_perp@depth@100ms","data":{"e":"depthUpdate","E":1626916405913,"T":1626916405908,"s":"LINKUSD_PERP","ps":"LINKUSD","U":167006114732,"u":167006116285,"pu":167006114628,"b":[["14.844","90"],["14.856","0"],["14.870","333"],["14.894","1474"],["14.910","324"],["14.946","740"],["14.951","40"],["14.959","2285"],["14.981","21"],["15.012","1296"],["15.014","1961"],["15.016","789"],["15.017","606"],["15.024","541"],["15.026","151"],["15.028","651"],["15.030","812"],["15.039","966"],["15.047","3414"],["15.049","438"],["15.054","1383"],["15.056","1562"],["15.057","616"],["15.060","291"]],"a":[["15.070","2366"],["15.071","3443"],["15.072","462"],["15.123","0"],["15.129","202"],["15.146","1145"],["15.157","0"]]}}
1626916409.227112: {"stream":"xrpusd_perp@depth@100ms","data":{"e":"depthUpdate","E":1626916405918,"T":1626916405912,"s":"XRPUSD_PERP","ps":"XRPUSD","U":167006114833,"u":167006116336,"pu":167006114826,"b":[["0.5580","1351"],["0.5582","344"],["0.5623","781"],["0.5624","4029"],["0.5637","2008"],["0.5646","1318"],["0.5655","1372"],["0.5656","14731"],["0.5657","5712"],["0.5658","3442"],["0.5659","5897"],["0.5660","8337"],["0.5661","6542"],["0.5662","757"],["0.5663","2000"],["0.5664","0"]],"a":[["0.5664","11610"],["0.5665","6480"],["0.5666","1400"],["0.5667","7403"],["0.5668","5262"],["0.5669","5682"],["0.5670","3748"],["0.5672","2698"],["0.5673","3733"],["0.5674","1152"],["0.5675","6005"],["0.5676","31064"],["0.5679","5002"],["0.5685","4152"],["0.5692","7133"],["0.5705","1294"],["0.5707","1243"],["0.5748","5566"],["0.5749","0"]]}}
1626916409.227179: {"stream":"trxusd_perp@depth@100ms","data":{"e":"depthUpdate","E":1626916405931,"T":1626916405917,"s":"TRXUSD_PERP","ps":"TRXUSD","U":167006115020,"u":167006116392,"pu":167006114878,"b":[["0.05339","1358"],["0.05342","935"],["0.05343","1461"],["0.05344","612"]],"a":[["0.05350","1311"]]}}
1626916409.2272298: {"stream":"eosusd_perp@depth@100ms","data":{"e":"depthUpdate","E":1626916405938,"T":1626916405929,"s":"EOSUSD_PERP","ps":"EOSUSD","U":167006115104,"u":167006116550,"pu":167006115021,"b":[["3.462","9501"],["3.463","4239"],["3.464","1745"]],"a":[["3.466","87"],["3.468","4825"],["3.469","3427"],["3.470","3681"],["3.472","4591"],["3.473","2956"]]}}
1626916409.227259: {"stream":"bchusd_perp@depth@100ms","data":{"e":"depthUpdate","E":1626916405942,"T":1626916405931,"s":"BCHUSD_PERP","ps":"BCHUSD","U":167006115220,"u":167006116585,"pu":167006114844,"b":[["427.52","0"],["427.54","185"],["427.55","1161"],["427.59","300"],["427.60","106"],["427.71","1"],["427.77","0"]],"a":[["427.83","130"],["427.86","0"],["428.47","122"]]}}
1626916409.227495: {"stream":"btcusd_211231@depth@100ms","data":{"e":"depthUpdate","E":1626916405981,"T":1626916405967,"s":"BTCUSD_211231","ps":"BTCUSD","U":167006115784,"u":167006117059,"pu":167006115625,"b":[["32358.3","0"],["32460.1","5500"],["32481.7","2"],["32494.0","0"],["32572.0","0"],["32614.9","0"]],"a":[["32646.2","1955"],["32660.0","170"],["32694.4","383"],["32928.1","701"],["32948.2","0"]]}}
1626916409.227653: {"stream":"etcusd_perp@depth@100ms","data":{"e":"depthUpdate","E":1626916406009,"T":1626916406002,"s":"ETCUSD_PERP","ps":"ETCUSD","U":167006116219,"u":167006117570,"pu":167006116076,"b":[["41.906","561"],["41.920","6887"],["41.963","2000"],["41.983","0"],["42.140","66"],["42.162","215"],["42.172","0"],["42.206","1155"],["42.221","1335"],["42.225","287"],["42.231","120"],["42.236","512"]],"a":[["42.259","17"],["42.260","250"],["42.261","0"],["42.262","0"],["42.266","400"],["42.294","244"],["42.342","70"],["42.356","0"],["42.475","379"],["42.616","560"],["42.631","0"]]}}
1626916409.2276711: {"stream":"linkusd_211231@depth@100ms","data":{"e":"depthUpdate","E":1626916406011,"T":1626916405929,"s":"LINKUSD_211231","ps":"LINKUSD","U":167006116237,"u":167006116547,"pu":167006115902,"b":[["15.261","5"],["15.285","0"]],"a":[]}}
1626916409.2276769: {"stream":"ethusd_210924@depth@100ms","data":{"e":"depthUpdate","E":1626916406011,"T":1626916405997,"s":"ETHUSD_210924","ps":"ETHUSD","U":167006116243,"u":167006117514,"pu":167006115953,"b":[["1979.32","2939"],["1980.63","0"],["1988.43","1102"],["1990.74","270"],["1990.77","750"],["1990.78","0"],["1990.80","525"],["1990.98","379"]],"a":[["1991.56","920"],["1991.80","268"],["1991.81","0"],["2024.13","0"],["2034.06","0"],["2043.98","0"],["2053.90","0"],["2063.82","0"]]}}
1626916409.227722: {"stream":"linkusd_perp@depth@100ms","data":{"e":"depthUpdate","E":1626916406019,"T":1626916406012,"s":"LINKUSD_PERP","ps":"LINKUSD","U":167006116356,"u":167006117733,"pu":167006116285,"b":[["14.956","3740"],["15.016","797"],["15.040","2250"],["15.053","3294"],["15.057","506"],["15.059","80"],["15.060","401"]],"a":[["15.068","221"],["15.069","1548"],["15.070","4423"],["15.118","613"],["15.155","88"]]}}
1626916409.227753: {"stream":"xrpusd_perp@depth@100ms","data":{"e":"depthUpdate","E":1626916406021,"T":1626916406014,"s":"XRPUSD_PERP","ps":"XRPUSD","U":167006116378,"u":167006117776,"pu":167006116336,"b":[["0.5628","3440"],["0.5631","439"],["0.5634","11027"],["0.5636","610"],["0.5641","3052"],["0.5642","1206"],["0.5645","9088"],["0.5646","46"],["0.5649","3175"],["0.5650","5489"],["0.5651","2200"],["0.5652","417"],["0.5653","910"],["0.5654","3403"],["0.5655","3909"],["0.5656","14813"],["0.5657","7661"],["0.5658","2303"],["0.5659","6532"],["0.5660","8576"],["0.5661","3459"],["0.5662","0"],["0.5663","0"]],"a":[["0.5661","0"],["0.5662","8045"],["0.5663","695"],["0.5664","8104"],["0.5665","1523"],["0.5666","1791"],["0.5667","7266"],["0.5668","7118"],["0.5669","5416"],["0.5670","2868"],["0.5671","2123"],["0.5673","4008"],["0.5674","1262"],["0.5675","2799"],["0.5677","7305"],["0.5678","5582"],["0.5680","967"],["0.5681","2321"],["0.5682","7240"],["0.5683","1380"],["0.5684","591"],["0.5691","2822"],["0.5692","8272"],["0.5696","3093"],["0.5698","112"],["0.5701","760"]]}}
1626916409.227842: {"stream":"bchusd_perp@depth@100ms","data":{"e":"depthUpdate","E":1626916406054,"T":1626916405983,"s":"BCHUSD_PERP","ps":"BCHUSD","U":167006116814,"u":167006117331,"pu":167006116585,"b":[["424.70","0"],["426.28","104"],["427.53","0"],["427.61","100"]],"a":[["427.81","150"],["427.87","0"],["429.37","0"],["430.95","0"]]}}
1626916409.2278788: {"stream":"eosusd_perp@depth@100ms","data":{"e":"depthUpdate","E":1626916406055,"T":1626916406048,"s":"EOSUSD_PERP","ps":"EOSUSD","U":167006116843,"u":167006118143,"pu":167006116550,"b":[["3.444","10771"],["3.461","1297"],["3.462","9601"],["3.466","0"]],"a":[["3.466","200"],["3.467","2269"],["3.468","4833"],["3.469","3448"],["3.470","3304"],["3.472","4517"],["3.483","604"]]}}
1626916409.227886: {"stream":"trxusd_perp@depth@100ms","data":{"e":"depthUpdate","E":1626916406059,"T":1626916406040,"s":"TRXUSD_PERP","ps":"TRXUSD","U":167006116878,"u":167006118041,"pu":167006116392,"b":[["0.05266","318"],["0.05267","0"],["0.05306","809"],["0.05307","687"],["0.05309","2110"],["0.05325","2346"],["0.05326","401"],["0.05338","2046"],["0.05339","1438"],["0.05340","2872"],["0.05341","785"],["0.05342","698"],["0.05343","1381"]],"a":[["0.05350","1797"],["0.05351","2816"],["0.05353","1032"],["0.05363","1038"],["0.05365","3272"],["0.05385","1812"],["0.05386","631"],["0.05425","316"],["0.05426","1"]]}}
1626916409.227911: {"stream":"btcusd_211231@depth@100ms","data":{"e":"depthUpdate","E":1626916406083,"T":1626916406059,"s":"BTCUSD_211231","ps":"BTCUSD","U":167006117253,"u":167006118227,"pu":167006117059,"b":[["29732.1","0"],["32340.1","701"],["32481.7","0"],["32565.6","379"]],"a":[["32625.8","0"],["32628.5","0"],["32629.2","153"],["32633.7","0"],["32744.6","2"]]}}
1626916409.227941: {"stream":"ethusd_210924@depth@100ms","data":{"e":"depthUpdate","E":1626916406111,"T":1626916406095,"s":"ETHUSD_210924","ps":"ETHUSD","U":167006117629,"u":167006118538,"pu":167006117514,"b":[["1987.29","80"],["1987.73","0"],["1987.81","0"],["1989.52","1640"],["1989.55","2116"],["1989.75","314"],["1989.94","1729"],["1989.95","984"],["1990.12","1562"],["1990.79","0"],["1990.80","262"]],"a":[["1991.79","1577"],["1991.81","1685"],["1992.57","2105"],["1992.81","60"],["1993.80","0"],["1993.83","314"],["1993.94","0"],["2001.02","10005"]]}}
1626916409.2279649: {"stream":"etcusd_perp@depth@100ms","data":{"e":"depthUpdate","E":1626916406111,"T":1626916406086,"s":"ETCUSD_PERP","ps":"ETCUSD","U":167006117608,"u":167006118490,"pu":167006117570,"b":[["42.207","1310"],["42.209","1161"],["42.216","22"],["42.220","1500"],["42.222","480"],["42.224","268"]],"a":[["42.258","100"],["42.259","17"],["42.260","150"],["42.285","0"],["42.288","22"],["42.297","0"],["42.320","240"],["42.321","0"],["42.449","336"],["42.460","0"]]}}
1626916409.227989: {"stream":"bchusd_210924@depth@100ms","data":{"e":"depthUpdate","E":1626916406118,"T":1626916406013,"s":"BCHUSD_210924","ps":"BCHUSD","U":167006117768,"u":167006117772,"pu":167006115217,"b":[["429.10","0"],["429.23","40"]],"a":[]}}
1626916409.228008: {"stream":"xrpusd_perp@depth@100ms","data":{"e":"depthUpdate","E":1626916406121,"T":1626916406111,"s":"XRPUSD_PERP","ps":"XRPUSD","U":167006117793,"u":167006118661,"pu":167006117776,"b":[["0.5448","25"],["0.5464","0"],["0.5579","6"],["0.5580","570"],["0.5621","6111"],["0.5623","0"],["0.5624","9596"],["0.5629","2235"],["0.5630","921"],["0.5633","10627"],["0.5634","11627"],["0.5635","507"],["0.5636","610"],["0.5637","55"],["0.5645","10360"],["0.5646","64"],["0.5647","6192"],["0.5648","23844"],["0.5649","2874"],["0.5650","5835"],["0.5651","3048"],["0.5652","538"],["0.5653","3535"],["0.5654","5379"],["0.5655","822"],["0.5656","13183"],["0.5658","3094"],["0.5659","2549"],["0.5660","2216"],["0.5661","3114"]],"a":[["0.5662","8971"],["0.5663","3667"],["0.5664","4183"],["0.5665","1949"],["0.5666","1300"],["0.5667","7090"],["0.5668","6484"],["0.5669","3431"],["0.5670","2282"],["0.5671","4076"],["0.5672","745"],["0.5673","3733"],["0.5676","55314"],["0.5677","7375"],["0.5679","2802"],["0.5680","3525"],["0.5682","7876"],["0.5683","2321"],["0.5685","3556"],["0.5689","7753"],["0.5692","6319"],["0.5699","2235"],["0.5701","1065"],["0.5704","14709"],["0.5705","513"],["0.5706","11526"],["0.5746","2"],["0.5748","4785"]]}}
1626916409.228039: {"stream":"linkusd_perp@depth@100ms","data":{"e":"depthUpdate","E":1626916406137,"T":1626916406125,"s":"LINKUSD_PERP","ps":"LINKUSD","U":167006117920,"u":167006118784,"pu":167006117733,"b":[["15.032","1250"],["15.054","1215"],["15.060","291"],["15.061","110"]],"a":[["15.066","602"],["15.068","221"],["15.070","4423"],["15.071","3483"],["15.074","384"],["15.108","3803"],["15.141","93"]]}}
1626916409.228069: {"stream":"bchusd_perp@depth@100ms","data":{"e":"depthUpdate","E":1626916406159,"T":1626916406126,"s":"BCHUSD_PERP","ps":"BCHUSD","U":167006118193,"u":167006118788,"pu":167006117331,"b":[["427.08","3502"],["427.61","0"],["427.67","100"],["427.77","150"],["427.79","0"]],"a":[["427.82","2909"],["427.91","0"],["428.06","362"]]}}
1626916409.228102: {"stream":"trxusd_perp@depth@100ms","data":{"e":"depthUpdate","E":1626916406159,"T":1626916406149,"s":"TRXUSD_PERP","ps":"TRXUSD","U":167006118195,"u":167006118901,"pu":167006118041,"b":[["0.05327","284"],["0.05328","2415"],["0.05335","305"],["0.05336","2381"],["0.05339","1358"],["0.05342","312"],["0.05343","1461"]],"a":[["0.05370","490"]]}}
1626916409.2281332: {"stream":"eosusd_perp@depth@100ms","data":{"e":"depthUpdate","E":1626916406159,"T":1626916406152,"s":"EOSUSD_PERP","ps":"EOSUSD","U":167006118198,"u":167006118912,"pu":167006118143,"b":[["3.440","288"],["3.465","3957"],["3.466","0"]],"a":[["3.469","3469"],["3.470","3556"],["3.471","8228"]]}}
1626916409.228184: {"stream":"btcusd_211231@depth@100ms","data":{"e":"depthUpdate","E":1626916406187,"T":1626916406178,"s":"BTCUSD_211231","ps":"BTCUSD","U":167006118412,"u":167006119142,"pu":167006118227,"b":[["32494.0","520"],["32606.9","154"]],"a":[["32629.2","153"],["32634.0","0"],["32642.0","154"]]}}
1626916409.228205: {"stream":"ethusd_210924@depth@100ms","data":{"e":"depthUpdate","E":1626916406211,"T":1626916406193,"s":"ETHUSD_210924","ps":"ETHUSD","U":167006118638,"u":167006119271,"pu":167006118538,"b":[["1981.04","1000"],["1988.06","4256"],["1990.59","50"]],"a":[["1991.78","1237"],["1993.26","80"],["2005.70","3349"]]}}
1626916409.2282188: {"stream":"etcusd_perp@depth@100ms","data":{"e":"depthUpdate","E":1626916406219,"T":1626916406208,"s":"ETCUSD_PERP","ps":"ETCUSD","U":167006118676,"u":167006119388,"pu":167006118490,"b":[["41.754","2702"],["42.154","0"]],"a":[["42.259","0"],["42.270","381"],["42.282","90"],["42.307","856"],["42.319","0"],["42.430","204"]]}}
1626916409.228255: {"stream":"xrpusd_perp@depth@100ms","data":{"e":"depthUpdate","E":1626916406224,"T":1626916406220,"s":"XRPUSD_PERP","ps":"XRPUSD","U":167006118732,"u":167006119509,"pu":167006118661,"b":[["0.5560","5595"],["0.5577","3278"],["0.5600","245"],["0.5617","4711"],["0.5618","5947"],["0.5621","6134"],["0.5625","9319"],["0.5629","2259"],["0.5634","11617"],["0.5635","2460"],["0.5640","1581"],["0.5643","952"],["0.5644","4978"],["0.5645","9088"],["0.5647","6169"],["0.5650","5850"],["0.5652","7444"],["0.5653","3810"],["0.5654","7057"],["0.5655","709"],["0.5656","4736"],["0.5657","8117"],["0.5658","2463"],["0.5659","3337"],["0.5661","1278"]],"a":[["0.5662","9383"],["0.5663","3070"],["0.5664","5236"],["0.5665","1182"],["0.5666","1342"],["0.5667","9120"],["0.5668","9337"],["0.5672","938"],["0.5676","53637"],["0.5678","2747"],["0.5681","2957"],["0.5682","7877"],["0.5683","1380"],["0.5685","3533"],["0.5687","494"]]}}
1626916409.228281: {"stream":"bchusd_210924@depth@100ms","data":{"e":"depthUpdate","E":1626916406238,"T":1626916406187,"s":"BCHUSD_210924","ps":"BCHUSD","U":167006118822,"u":167006119218,"pu":167006117772,"b":[["428.83","196"],["429.03","0"],["429.10","40"],["429.23","0"]],"a":[["429.77","12"]]}}
1626916409.2283258: {"stream":"eosusd_perp@depth@100ms","data":{"e":"depthUpdate","E":1626916406264,"T":1626916406238,"s":"EOSUSD_PERP","ps":"EOSUSD","U":167006118941,"u":167006119677,"pu":167006118912,"b":[["3.458","13134"],["3.461","2088"],["3.464","1937"],["3.465","3256"],["3.466","0"]],"a":[]}}
1626916409.22834: {"stream":"trxusd_perp@depth@100ms","data":{"e":"depthUpdate","E":1626916406266,"T":1626916406256,"s":"TRXUSD_PERP","ps":"TRXUSD","U":167006118976,"u":167006119815,"pu":167006118901,"b":[["0.05337","1475"],["0.05340","2952"],["0.05343","1381"]],"a":[["0.05347","20862"],["0.05349","1222"],["0.05353","1108"],["0.05363","23838"],["0.05365","3572"]]}}
1626916409.228346: {"stream":"linkusd_perp@depth@100ms","data":{"e":"depthUpdate","E":1626916406275,"T":1626916406258,"s":"LINKUSD_PERP","ps":"LINKUSD","U":167006119037,"u":167006119824,"pu":167006118784,"b":[["14.890","5767"],["14.906","0"],["15.044","1040"]],"a":[["15.066","602"],["15.068","221"],["15.071","3593"],["15.074","274"],["15.095","12059"],["15.118","605"]]}}
1626916409.228374: {"stream":"bchusd_perp@depth@100ms","data":{"e":"depthUpdate","E":1626916406282,"T":1626916406243,"s":"BCHUSD_PERP","ps":"BCHUSD","U":167006119125,"u":167006119714,"pu":167006118788,"b":[["427.50","8120"],["427.51","25"],["427.55","17"],["427.61","100"],["427.67","0"]],"a":[["427.83","230"],["427.88","0"],["428.02","50"],["428.05","100"],["428.12","2782"],["428.33","0"],["428.41","3258"],["428.50","3590"]]}}
1626916409.228532: {"stream":"etcusd_perp@depth@100ms","data":{"e":"depthUpdate","E":1626916406321,"T":1626916406315,"s":"ETCUSD_PERP","ps":"ETCUSD","U":167006119430,"u":167006120304,"pu":167006119388,"b":[["42.124","79"]],"a":[["42.258","0"],["42.259","189"],["42.262","0"],["42.270","471"],["42.282","0"],["42.290","0"],["42.295","1178"],["42.300","0"],["42.307","0"],["42.388","178"]]}}
1626916409.228539: {"stream":"ethusd_210924@depth@100ms","data":{"e":"depthUpdate","E":1626916406323,"T":1626916406297,"s":"ETHUSD_210924","ps":"ETHUSD","U":167006119499,"u":167006120154,"pu":167006119271,"b":[],"a":[["1991.31","435"],["1991.55","270"],["1991.56","650"],["1991.80","0"],["1991.81","0"],["1992.15","1751"],["2000.93","1000"]]}}
1626916409.228545: {"stream":"xrpusd_perp@depth@100ms","data":{"e":"depthUpdate","E":1626916406324,"T":1626916406318,"s":"XRPUSD_PERP","ps":"XRPUSD","U":167006119518,"u":167006120330,"pu":167006119509,"b":[["0.5464","500"],["0.5493","3144"],["0.5566","13"],["0.5577","3285"],["0.5583","0"],["0.5600","238"],["0.5630","1921"],["0.5634","11309"],["0.5639","1128"],["0.5642","1707"],["0.5643","1588"],["0.5644","3849"],["0.5645","9101"],["0.5647","6100"],["0.5648","23831"],["0.5651","4887"],["0.5652","8294"],["0.5653","3535"],["0.5654","6556"],["0.5655","830"],["0.5656","4948"],["0.5657","4793"],["0.5658","2833"],["0.5659","3037"],["0.5660","721"],["0.5661","0"]],"a":[["0.5661","10728"],["0.5662","5692"],["0.5663","2265"],["0.5664","2557"],["0.5665","866"],["0.5666","1106"],["0.5667","8380"],["0.5670","2967"],["0.5671","3941"],["0.5672","663"],["0.5679","2825"],["0.5681","3593"],["0.5682","7241"],["0.5685","3188"],["0.5692","7319"],["0.5698","2232"],["0.5699","115"],["0.5893","0"]]}}
1626916409.228571: {"stream":"btcusd_211231@depth@100ms","data":{"e":"depthUpdate","E":1626916406334,"T":1626916406285,"s":"BTCUSD_211231","ps":"BTCUSD","U":167006119589,"u":167006120020,"pu":167006119142,"b":[["29697.0","296"],["32439.0","86"],["32447.8","0"],["32458.9","216"],["32463.8","0"],["32476.1","2"],["32536.9","86"],["32545.8","0"],["32582.8","216"],["32590.8","0"],["32595.1","64"],["32601.4","891"],["32602.6","0"],["32602.7","0"]],"a":[["32629.1","46"],["32676.3","64"],["32689.3","216"],["32689.4","0"],["32698.5","0"],["32732.6","86"],["32741.4","0"],["32775.1","216"],["32787.2","0"],["32830.5","86"],["32839.4","0"]]}}
1626916409.228588: {"stream":"linkusd_211231@depth@100ms","data":{"e":"depthUpdate","E":1626916406343,"T":1626916406294,"s":"LINKUSD_211231","ps":"LINKUSD","U":167006119680,"u":167006120122,"pu":167006116547,"b":[["14.760","1022"],["14.836","0"],["14.911","0"],["14.986","0"],["15.062","0"],["15.267","3736"],["15.278","0"],["15.281","153"]],"a":[["15.526","0"],["15.601","0"],["15.676","38"],["15.752","0"],["15.827","0"]]}}
1626916409.228595: {"stream":"bchusd_210924@depth@100ms","data":{"e":"depthUpdate","E":1626916406343,"T":1626916406270,"s":"BCHUSD_210924","ps":"BCHUSD","U":167006119658,"u":167006119918,"pu":167006119218,"b":[["429.10","0"],["429.23","40"]],"a":[["429.79","824"],["430.22","300"]]}}
1626916409.228666: {"stream":"eosusd_perp@depth@100ms","data":{"e":"depthUpdate","E":1626916406365,"T":1626916406350,"s":"EOSUSD_PERP","ps":"EOSUSD","U":167006119851,"u":167006120579,"pu":167006119677,"b":[["3.451","4241"],["3.455","5069"],["3.466","0"]],"a":[["3.469","3448"]]}}
1626916409.228679: {"stream":"linkusd_perp@depth@100ms","data":{"e":"depthUpdate","E":1626916406377,"T":1626916406365,"s":"LINKUSD_PERP","ps":"LINKUSD","U":167006119941,"u":167006120732,"pu":167006119824,"b":[["14.926","1416"],["15.045","215"],["15.047","3214"],["15.051","1778"],["15.058","130"],["15.059","180"],["15.060","101"],["15.061","36"]],"a":[["15.066","302"],["15.068","521"],["15.069","4874"],["15.071","510"],["15.077","1407"],["15.107","575"],["15.387","0"]]}}
1626916409.228717: {"stream":"trxusd_perp@depth@100ms","data":{"e":"depthUpdate","E":1626916406379,"T":1626916406367,"s":"TRXUSD_PERP","ps":"TRXUSD","U":167006119960,"u":167006120764,"pu":167006119815,"b":[["0.05324","1134"],["0.05336","1630"],["0.05340","2872"],["0.05341","785"],["0.05342","685"],["0.05343","1780"],["0.05344","512"]],"a":[["0.05349","1594"],["0.05351","2431"],["0.05353","1208"]]}}
1626916409.2287328: {"stream":"bchusd_perp@depth@100ms","data":{"e":"depthUpdate","E":1626916406400,"T":1626916406390,"s":"BCHUSD_PERP","ps":"BCHUSD","U":167006120103,"u":167006121010,"pu":167006119714,"b":[["424.67","1987"],["426.25","1051"],["427.11","0"],["427.18","0"],["427.60","355"],["427.79","0"]],"a":[["427.78","0"],["427.80","250"],["427.81","0"],["427.83","0"],["427.84","0"],["428.01","3279"],["428.02","50"],["428.10","227"],["429.33","453"],["430.91","624"]]}}
1626916409.228838: {"stream":"xrpusd_perp@depth@100ms","data":{"e":"depthUpdate","E":1626916406425,"T":1626916406419,"s":"XRPUSD_PERP","ps":"XRPUSD","U":167006120334,"u":167006121227,"pu":167006120330,"b":[["0.5448","625"],["0.5582","10567"],["0.5590","21"],["0.5620","543"],["0.5626","961"],["0.5627","2120"],["0.5629","139"],["0.5641","3352"],["0.5647","6600"],["0.5648","24379"],["0.5650","5835"],["0.5652","1388"],["0.5653","9941"],["0.5654","9302"],["0.5655","4155"],["0.5656","7770"],["0.5657","6707"],["0.5659","2037"],["0.5660","0"]],"a":[["0.5660","2210"],["0.5661","11455"],["0.5662","6774"],["0.5663","1940"],["0.5664","5617"],["0.5666","2272"],["0.5667","3865"],["0.5668","8308"],["0.5670","3682"],["0.5672","1514"],["0.5673","9380"],["0.5677","469"],["0.5678","414"],["0.5681","3893"],["0.5685","1004"],["0.5688","8433"],["0.5690","333"],["0.5699","0"],["0.5702","877"],["0.5706","10926"],["0.5710","325"],["0.5711","0"],["0.5834","3524"],["0.6491","0"]]}}
1626916409.2289019: {"stream":"ethusd_210924@depth@100ms","data":{"e":"depthUpdate","E":1626916406449,"T":1626916406444,"s":"ETHUSD_210924","ps":"ETHUSD","U":167006120498,"u":167006121454,"pu":167006120154,"b":[["1983.24","0"],["1987.91","5002"],["1989.60","0"],["1989.81","50"],["1990.13","0"],["1990.28","1750"],["1990.34","270"],["1990.59","0"],["1990.60","0"],["1990.64","0"],["1990.67","360"],["1990.73","0"],["1990.74","0"],["1990.77","0"],["1990.80","0"],["1990.98","55"]],"a":[["1991.10","343"],["1991.11","980"],["1991.22","400"],["1991.31","705"],["1991.45","1750"],["1991.55","0"],["1991.56","0"],["1991.57","0"],["1992.50","0"],["1992.58","0"],["1992.62","500"],["1992.87","0"],["1993.03","0"],["1995.30","190"],["1997.27","0"],["1997.40","0"],["1999.15","0"],["2001.11","0"],["2006.36","139"],["2009.10","0"]]}}
1626916409.2289128: {"stream":"etcusd_perp@depth@100ms","data":{"e":"depthUpdate","E":1626916406449,"T":1626916406437,"s":"ETCUSD_PERP","ps":"ETCUSD","U":167006120511,"u":167006121387,"pu":167006120304,"b":[["41.963","0"],["42.039","377"],["42.053","0"],["42.165","524"],["42.177","2292"],["42.186","0"],["42.190","0"],["42.198","1155"],["42.206","0"]],"a":[["42.252","45"],["42.271","0"]]}}
1626916409.2289631: {"stream":"eosusd_perp@depth@100ms","data":{"e":"depthUpdate","E":1626916406471,"T":1626916406465,"s":"EOSUSD_PERP","ps":"EOSUSD","U":167006120744,"u":167006121632,"pu":167006120579,"b":[["3.458","12994"],["3.462","8771"],["3.463","4803"],["3.466","0"]],"a":[["3.468","4854"],["3.469","4124"],["3.470","4124"],["3.471","7119"],["3.472","2597"],["3.494","1679"]]}}
1626916409.22898: {"stream":"linkusd_perp@depth@100ms","data":{"e":"depthUpdate","E":1626916406479,"T":1626916406471,"s":"LINKUSD_PERP","ps":"LINKUSD","U":167006120886,"u":167006121716,"pu":167006120732,"b":[["14.910","560"],["15.045","15"],["15.047","3414"],["15.055","110"],["15.058","171"]],"a":[["15.062","191"],["15.068","221"],["15.070","4723"],["15.082","2074"],["15.363","243"]]}}
1626916409.229012: {"stream":"btcusd_211231@depth@100ms","data":{"e":"depthUpdate","E":1626916406479,"T":1626916406450,"s":"BTCUSD_211231","ps":"BTCUSD","U":167006120838,"u":167006121499,"pu":167006120020,"b":[["32570.2","10"]],"a":[["32623.4","17"],["32634.1","0"]]}}
1626916409.229019: {"stream":"linkusd_211231@depth@100ms","data":{"e":"depthUpdate","E":1626916406481,"T":1626916406451,"s":"LINKUSD_211231","ps":"LINKUSD","U":167006120913,"u":167006121518,"pu":167006120122,"b":[["14.758","100"],["14.834","100"],["14.909","100"],["14.984","100"],["15.060","100"],["15.160","571"],["15.177","0"]],"a":[["15.523","164"],["15.598","165"],["15.673","166"],["15.749","167"],["15.824","168"]]}}
1626916409.229035: {"stream":"bchusd_210924@depth@100ms","data":{"e":"depthUpdate","E":1626916406488,"T":1626916406479,"s":"BCHUSD_210924","ps":"BCHUSD","U":167006120953,"u":167006121776,"pu":167006119918,"b":[["429.05","0"],["429.36","30"]],"a":[["429.59","300"],["429.97","377"],["430.10","0"]]}}
1626916409.229085: {"stream":"bchusd_perp@depth@100ms","data":{"e":"depthUpdate","E":1626916406519,"T":1626916406497,"s":"BCHUSD_PERP","ps":"BCHUSD","U":167006121182,"u":167006121923,"pu":167006121010,"b":[["427.03","129"],["427.41","2199"],["427.42","0"],["427.59","0"],["427.64","300"]],"a":[]}}
1626916409.229125: {"stream":"xrpusd_perp@depth@100ms","data":{"e":"depthUpdate","E":1626916406525,"T":1626916406519,"s":"XRPUSD_PERP","ps":"XRPUSD","U":167006121233,"u":167006122084,"pu":167006121227,"b":[["0.5448","625"],["0.5464","500"],["0.5582","10249"],["0.5604","266"],["0.5616","0"],["0.5617","4643"],["0.5623","305"],["0.5625","9304"],["0.5630","1320"],["0.5633","10609"],["0.5634","11320"],["0.5635","2529"],["0.5643","1577"],["0.5644","4154"],["0.5646","46"],["0.5647","6600"],["0.5648","24445"],["0.5650","5835"],["0.5652","1548"],["0.5654","11886"],["0.5655","5157"],["0.5656","6295"],["0.5657","6291"],["0.5658","2906"],["0.5659","2707"]],"a":[["0.5660","8224"],["0.5661","2795"],["0.5662","4604"],["0.5663","6147"],["0.5664","6830"],["0.5665","824"],["0.5666","1638"],["0.5668","9449"],["0.5670","3957"],["0.5671","3666"],["0.5677","399"],["0.5688","7933"],["0.5701","1083"],["0.5705","543"],["0.5714","0"]]}}
1626916409.229145: {"stream":"trxusd_perp@depth@100ms","data":{"e":"depthUpdate","E":1626916406531,"T":1626916406465,"s":"TRXUSD_PERP","ps":"TRXUSD","U":167006121290,"u":167006121628,"pu":167006120764,"b":[["0.05340","2872"],["0.05343","1780"]],"a":[]}}
1626916409.229173: {"stream":"ethusd_210924@depth@100ms","data":{"e":"depthUpdate","E":1626916406550,"T":1626916406525,"s":"ETHUSD_210924","ps":"ETHUSD","U":167006121458,"u":167006122140,"pu":167006121454,"b":[["1984.97","572"],["1990.29","0"],["1990.34","0"],["1990.57","750"],["1990.66","0"],["1990.68","270"]],"a":[["1991.37","650"],["1991.96","363"],["1991.97","343"],["1992.21","404"],["1994.93","0"],["1995.47","0"],["1998.07","1400"]]}}
1626916409.2291799: {"stream":"etcusd_perp@depth@100ms","data":{"e":"depthUpdate","E":1626916406554,"T":1626916406547,"s":"ETCUSD_PERP","ps":"ETCUSD","U":167006121525,"u":167006122298,"pu":167006121387,"b":[["39.544","2000"],["42.124","210"],["42.153","0"],["42.169","411"],["42.204","523"],["42.205","860"],["42.209","1105"],["42.217","22"],["42.225","265"],["42.246","0"]],"a":[["42.256","100"],["42.257","240"],["42.259","0"],["42.265","361"],["42.270","381"],["42.280","200"],["42.282","90"],["42.296","0"],["42.313","0"],["42.314","0"],["42.388","310"],["42.430","72"]]}}
1626916409.2292612: {"stream":"eosusd_perp@depth@100ms","data":{"e":"depthUpdate","E":1626916406573,"T":1626916406558,"s":"EOSUSD_PERP","ps":"EOSUSD","U":167006121656,"u":167006122387,"pu":167006121632,"b":[["3.455","5208"],["3.461","3387"],["3.462","7438"],["3.465","696"],["3.466","0"]],"a":[["3.467","2574"],["3.468","5240"],["3.469","4103"],["3.471","6804"],["3.480","1967"]]}}
1626916409.229269: {"stream":"linkusd_perp@depth@100ms","data":{"e":"depthUpdate","E":1626916406580,"T":1626916406550,"s":"LINKUSD_PERP","ps":"LINKUSD","U":167006121759,"u":167006122328,"pu":167006121716,"b":[["15.036","840"],["15.047","3399"],["15.050","162"],["15.051","1738"],["15.053","3279"],["15.055","0"],["15.059","290"]],"a":[["15.068","521"],["15.069","5024"],["15.070","4043"],["15.071","890"],["15.075","264"],["15.077","1422"],["15.079","1487"],["15.081","73"]]}}
1626916409.2293062: {"stream":"linkusd_211231@depth@100ms","data":{"e":"depthUpdate","E":1626916406589,"T":1626916406555,"s":"LINKUSD_211231","ps":"LINKUSD","U":167006121844,"u":167006122362,"pu":167006121518,"b":[["15.264","0"],["15.265","0"],["15.266","36"],["15.267","3509"],["15.281","53"],["15.307","0"]],"a":[["15.325","50"],["15.338","1557"]]}}
1626916409.229322: {"stream":"bchusd_perp@depth@100ms","data":{"e":"depthUpdate","E":1626916406621,"T":1626916406605,"s":"BCHUSD_PERP","ps":"BCHUSD","U":167006122064,"u":167006122759,"pu":167006121923,"b":[["427.18","503"],["427.60","106"],["427.79","0"]],"a":[["427.80","150"],["427.81","100"],["427.88","0"],["428.05","0"],["428.11","100"]]}}
1626916409.2293508: {"stream":"xrpusd_perp@depth@100ms","data":{"e":"depthUpdate","E":1626916406629,"T":1626916406622,"s":"XRPUSD_PERP","ps":"XRPUSD","U":167006122102,"u":167006122892,"pu":167006122084,"b":[["0.5547","3"],["0.5559","492"],["0.5615","571"],["0.5618","5975"],["0.5620","561"],["0.5621","5968"],["0.5622","316"],["0.5624","9567"],["0.5643","959"],["0.5644","3849"],["0.5646","116"],["0.5647","1100"],["0.5651","2962"],["0.5652","813"],["0.5654","11765"],["0.5655","5263"],["0.5656","6506"],["0.5657","6093"],["0.5658","2217"],["0.5659","4007"]],"a":[["0.5661","2592"],["0.5662","2026"],["0.5663","6182"],["0.5664","6872"],["0.5665","782"],["0.5666","2518"],["0.5667","4165"],["0.5668","9801"],["0.5670","4232"],["0.5671","3391"],["0.5673","12480"],["0.5674","3532"],["0.5678","432"],["0.5680","4161"],["0.5681","3257"],["0.5682","7741"],["0.5685","986"],["0.5689","2253"]]}}
1626916409.229362: {"stream":"btcusd_211231@depth@100ms","data":{"e":"depthUpdate","E":1626916406630,"T":1626916406620,"s":"BTCUSD_211231","ps":"BTCUSD","U":167006122133,"u":167006122859,"pu":167006121499,"b":[["32494.1","1041"]],"a":[["32625.8","153"],["32629.0","0"],["32629.2","0"]]}}
1626916409.22941: {"stream":"ethusd_210924@depth@100ms","data":{"e":"depthUpdate","E":1626916406654,"T":1626916406648,"s":"ETHUSD_210924","ps":"ETHUSD","U":167006122320,"u":167006123057,"pu":167006122140,"b":[["1978.31","0"],["1980.76","9804"],["1982.17","0"],["1990.34","0"],["1990.35","0"],["1990.58","0"],["1990.68","126"],["1990.69","270"]],"a":[["1991.31","435"],["1991.77","270"],["1995.15","500"]]}}
1626916409.2294242: {"stream":"etcusd_perp@depth@100ms","data":{"e":"depthUpdate","E":1626916406667,"T":1626916406645,"s":"ETCUSD_PERP","ps":"ETCUSD","U":167006122410,"u":167006123033,"pu":167006122298,"b":[["42.196","56"],["42.198","0"],["42.201","56"],["42.202","1040"]],"a":[["42.269","0"],["42.279","1331"],["42.282","446"],["42.288","1747"],["42.305","112"],["42.309","1216"],["42.357","0"]]}}
1626916409.229504: {"stream":"eosusd_perp@depth@100ms","data":{"e":"depthUpdate","E":1626916406680,"T":1626916406674,"s":"EOSUSD_PERP","ps":"EOSUSD","U":167006122499,"u":167006123252,"pu":167006122387,"b":[["3.461","1939"],["3.462","7715"],["3.463","6102"],["3.464","1795"],["3.465","2066"],["3.466","0"]],"a":[["3.466","120"],["3.467","2194"],["3.469","4461"],["3.470","2772"],["3.471","6804"],["3.472","3841"],["3.504","61"]]}}
1626916409.229511: {"stream":"linkusd_perp@depth@100ms","data":{"e":"depthUpdate","E":1626916406687,"T":1626916406674,"s":"LINKUSD_PERP","ps":"LINKUSD","U":167006122578,"u":167006123251,"pu":167006122328,"b":[["15.022","0"],["15.031","886"],["15.040","538"],["15.042","2131"]],"a":[["15.071","780"],["15.074","384"],["15.144","110"],["15.276","3750"]]}}
1626916409.229537: {"stream":"linkusd_211231@depth@100ms","data":{"e":"depthUpdate","E":1626916406701,"T":1626916406596,"s":"LINKUSD_211231","ps":"LINKUSD","U":167006122704,"u":167006122713,"pu":167006122362,"b":[["15.267","2304"],["15.288","3348"]],"a":[]}}
1626916409.229553: {"stream":"xrpusd_perp@depth@100ms","data":{"e":"depthUpdate","E":1626916406731,"T":1626916406715,"s":"XRPUSD_PERP","ps":"XRPUSD","U":167006122906,"u":167006123538,"pu":167006122892,"b":[["0.5518","738"],["0.5553","0"],["0.5570","9219"],["0.5604","334"],["0.5609","3404"],["0.5615","737"],["0.5620","6724"],["0.5624","4000"],["0.5626","1517"],["0.5632","23987"],["0.5633","2802"],["0.5642","2343"],["0.5646","252"],["0.5648","24430"],["0.5652","1113"],["0.5656","6346"],["0.5657","5953"]],"a":[["0.5660","8254"],["0.5661","2187"],["0.5662","2326"],["0.5667","3865"],["0.5699","600"]]}}
1626916409.229569: {"stream":"btcusd_211231@depth@100ms","data":{"e":"depthUpdate","E":1626916406735,"T":1626916406670,"s":"BTCUSD_211231","ps":"BTCUSD","U":167006122932,"u":167006123207,"pu":167006122859,"b":[["32503.4","0"],["32619.0","0"],["32623.3","72"]],"a":[["32625.8","153"],["32628.1","46"],["32629.0","0"],["32629.1","0"],["32796.3","1196"]]}}
1626916409.229584: {"stream":"bchusd_perp@depth@100ms","data":{"e":"depthUpdate","E":1626916406743,"T":1626916406691,"s":"BCHUSD_PERP","ps":"BCHUSD","U":167006122978,"u":167006123359,"pu":167006122759,"b":[["427.56","298"],["427.78","0"],["427.79","0"]],"a":[["427.78","150"],["427.79","100"],["427.81","0"],["427.96","275"],["428.04","100"],["428.11","0"],["428.26","678"],["428.42","403"]]}}
1626916409.229645: {"stream":"ethusd_210924@depth@100ms","data":{"e":"depthUpdate","E":1626916406767,"T":1626916406758,"s":"ETHUSD_210924","ps":"ETHUSD","U":167006123139,"u":167006123882,"pu":167006123057,"b":[["1975.61","136"],["1987.90","0"],["1988.26","12"],["1988.56","2379"],["1989.80","0"],["1989.90","0"],["1990.00","0"],["1990.87","0"]],"a":[["1991.36","0"],["1991.77","270"],["1994.15","12"],["1994.25","181"],["1994.35","12"],["2181.65","5398"]]}}
1626916409.229661: {"stream":"etcusd_perp@depth@100ms","data":{"e":"depthUpdate","E":1626916406769,"T":1626916406756,"s":"ETCUSD_PERP","ps":"ETCUSD","U":167006123143,"u":167006123865,"pu":167006123033,"b":[["42.041","105"],["42.071","0"],["42.141","552"],["42.184","1219"],["42.201","71"],["42.208","862"],["42.210","17"],["42.212","0"],["42.221","1735"],["42.235","0"],["42.241","0"],["42.250","0"],["42.251","0"]],"a":[["42.252","0"],["42.269","0"],["42.279","1241"],["42.280","233"],["42.281","90"],["42.311","25"],["42.321","15"],["42.330","55"],["42.331","110"],["42.333","419"],["42.350","72"],["42.369","851"],["42.421","0"],["42.430","55"],["42.431","0"],["42.436","0"],["42.461","105"],["42.491","0"]]}}
1626916409.229758: {"stream":"eosusd_perp@depth@100ms","data":{"e":"depthUpdate","E":1626916406781,"T":1626916406762,"s":"EOSUSD_PERP","ps":"EOSUSD","U":167006123268,"u":167006123935,"pu":167006123252,"b":[["3.461","2439"],["3.462","7491"],["3.463","6061"],["3.464","2136"],["3.465","2266"],["3.466","0"]],"a":[["3.467","1889"],["3.468","4803"],["3.469","3774"],["3.470","3206"],["3.471","6804"],["3.472","3701"],["3.501","208"]]}}
1626916409.229784: {"stream":"linkusd_perp@depth@100ms","data":{"e":"depthUpdate","E":1626916406794,"T":1626916406784,"s":"LINKUSD_PERP","ps":"LINKUSD","U":167006123352,"u":167006124100,"pu":167006123251,"b":[["14.862","2000"],["14.911","1000"],["15.003","45"],["15.019","148"],["15.021","677"],["15.042","737"],["15.047","4793"],["15.058","20"],["15.059","180"],["15.060","291"],["15.061","110"]],"a":[["15.066","602"],["15.068","221"],["15.070","4521"],["15.071","400"],["15.115","62"]]}}
1626916409.229837: {"stream":"bchusd_210924@depth@100ms","data":{"e":"depthUpdate","E":1626916406809,"T":1626916406774,"s":"BCHUSD_210924","ps":"BCHUSD","U":167006123461,"u":167006124034,"pu":167006121776,"b":[],"a":[["429.84","1727"],["430.26","0"],["1335.62","9414"],["1336.24","0"]]}}
1626916409.229862: {"stream":"xrpusd_perp@depth@100ms","data":{"e":"depthUpdate","E":1626916406832,"T":1626916406814,"s":"XRPUSD_PERP","ps":"XRPUSD","U":167006123644,"u":167006124328,"pu":167006123538,"b":[["0.5535","199"],["0.5619","93"],["0.5629","7940"],["0.5631","346"],["0.5653","10222"],["0.5657","5793"]],"a":[["0.5661","2927"],["0.5665","882"],["0.5670","3780"],["0.5707","1227"]]}}
1626916409.229887: {"stream":"trxusd_perp@depth@100ms","data":{"e":"depthUpdate","E":1626916406853,"T":1626916406844,"s":"TRXUSD_PERP","ps":"TRXUSD","U":167006123821,"u":167006124560,"pu":167006121628,"b":[["0.05339","1358"],["0.05340","2952"],["0.05341","1345"],["0.05343","1140"],["0.05344","512"]],"a":[["0.05348","1184"],["0.05350","2357"],["0.05352","1167"]]}}
1626916409.229909: {"stream":"linkusd_211231@depth@100ms","data":{"e":"depthUpdate","E":1626916406868,"T":1626916406762,"s":"LINKUSD_211231","ps":"LINKUSD","U":167006123942,"u":167006123942,"pu":167006122713,"b":[["15.258","40"]],"a":[]}}
1626916409.229915: {"stream":"bchusd_perp@depth@100ms","data":{"e":"depthUpdate","E":1626916406873,"T":1626916406857,"s":"BCHUSD_PERP","ps":"BCHUSD","U":167006123969,"u":167006124625,"pu":167006123359,"b":[["427.00","626"],["427.77","150"]],"a":[["427.99","355"],["428.01","3114"]]}}
1626916409.229931: {"stream":"ethusd_210924@depth@100ms","data":{"e":"depthUpdate","E":1626916406878,"T":1626916406870,"s":"ETHUSD_210924","ps":"ETHUSD","U":167006124017,"u":167006124724,"pu":167006123882,"b":[["1990.68","0"],["1990.70","1009"]],"a":[["1991.21","270"],["1991.44","0"],["1991.77","0"]]}}
1626916409.229938: {"stream":"etcusd_perp@depth@100ms","data":{"e":"depthUpdate","E":1626916406878,"T":1626916406870,"s":"ETCUSD_PERP","ps":"ETCUSD","U":167006124007,"u":167006124721,"pu":167006123865,"b":[["42.000","365"],["42.118","30000"],["42.190","710"],["42.205","70"],["42.231","405"],["42.234","396"],["42.245","0"]],"a":[["42.256","0"],["42.257","0"],["42.258","0"],["42.259","279"],["42.260","150"],["42.264","90"],["42.281","0"],["42.293","839"],["42.295","322"],["42.323","0"],["42.328","982"],["42.661","0"]]}}
1626916409.229996: {"stream":"eosusd_perp@depth@100ms","data":{"e":"depthUpdate","E":1626916406883,"T":1626916406869,"s":"EOSUSD_PERP","ps":"EOSUSD","U":167006124055,"u":167006124704,"pu":167006123935,"b":[["3.432","0"],["3.455","6740"],["3.458","11461"],["3.463","6094"],["3.464","2348"],["3.466","0"]],"a":[["3.469","3595"],["3.470","3960"],["3.473","3096"]]}}
1626916409.230005: {"stream":"btcusd_211231@depth@100ms","data":{"e":"depthUpdate","E":1626916406891,"T":1626916406875,"s":"BTCUSD_211231","ps":"BTCUSD","U":167006124118,"u":167006124754,"pu":167006123207,"b":[["29360.9","1"],["32403.6","0"],["32515.1","1923"]],"a":[["32625.8","0"],["32627.7","46"],["32628.0","153"],["32628.1","0"],["32638.6","75"],["32641.9","190"]]}}
1626916409.230029: {"stream":"linkusd_perp@depth@100ms","data":{"e":"depthUpdate","E":1626916406918,"T":1626916406894,"s":"LINKUSD_PERP","ps":"LINKUSD","U":167006124320,"u":167006124853,"pu":167006124100,"b":[["15.047","4967"],["15.048","94"]],"a":[["15.066","302"],["15.068","521"],["15.071","510"],["15.074","274"],["15.086","500"],["15.094","151"],["15.102","400"]]}}
1626916409.230081: {"stream":"xrpusd_perp@depth@100ms","data":{"e":"depthUpdate","E":1626916406938,"T":1626916406916,"s":"XRPUSD_PERP","ps":"XRPUSD","U":167006124461,"u":167006124997,"pu":167006124328,"b":[["0.5464","0"],["0.5546","247"],["0.5607","5894"],["0.5648","24776"],["0.5649","5134"],["0.5650","6335"],["0.5653","11211"],["0.5654","9505"],["0.5656","7455"],["0.5657","4291"],["0.5659","2514"]],"a":[["0.5664","7156"],["0.5669","3787"],["0.5670","3095"],["0.5705","559"],["0.5772","115"],["0.5829","115"],["0.5830","10"],["0.5887","1454"]]}}
1626916409.2300968: {"stream":"trxusd_perp@depth@100ms","data":{"e":"depthUpdate","E":1626916406963,"T":1626916406941,"s":"TRXUSD_PERP","ps":"TRXUSD","U":167006124640,"u":167006125147,"pu":167006124560,"b":[["0.05340","2872"],["0.05342","765"]],"a":[["0.05347","21262"],["0.05348","784"],["0.05351","2309"]]}}
1626916409.2301261: {"stream":"ethusd_210924@depth@100ms","data":{"e":"depthUpdate","E":1626916406980,"T":1626916406971,"s":"ETHUSD_210924","ps":"ETHUSD","U":167006124750,"u":167006125375,"pu":167006124724,"b":[],"a":[["1991.21","0"],["1991.36","270"],["1991.44","0"],["1991.77","0"],["2182.17","2724"]]}}
1626916409.2301319: {"stream":"etcusd_perp@depth@100ms","data":{"e":"depthUpdate","E":1626916406989,"T":1626916406960,"s":"ETCUSD_PERP","ps":"ETCUSD","U":167006124802,"u":167006125269,"pu":167006124721,"b":[["42.202","0"],["42.205","1109"],["42.218","267"],["42.225","0"]],"a":[["42.268","200"],["42.270","0"],["42.609","73"]]}}
1626916409.23018: {"stream":"eosusd_perp@depth@100ms","data":{"e":"depthUpdate","E":1626916406995,"T":1626916406986,"s":"EOSUSD_PERP","ps":"EOSUSD","U":167006124820,"u":167006125464,"pu":167006124704,"b":[["3.429","695"],["3.466","0"]],"a":[["3.466","200"],["3.468","5103"]]}}
1626916409.230193: {"stream":"btcusd_211231@depth@100ms","data":{"e":"depthUpdate","E":1626916407010,"T":1626916406959,"s":"BTCUSD_211231","ps":"BTCUSD","U":167006124915,"u":167006125265,"pu":167006124754,"b":[["32366.1","1121"]],"a":[["32625.8","153"],["32627.6","0"],["32628.0","0"]]}}
1626916409.230199: {"stream":"linkusd_211231@depth@100ms","data":{"e":"depthUpdate","E":1626916407010,"T":1626916406991,"s":"LINKUSD_211231","ps":"LINKUSD","U":167006124924,"u":167006125479,"pu":167006123942,"b":[["15.288","2143"],["15.289","751"],["15.290","123"],["15.291","0"]],"a":[["15.328","0"],["15.330","1488"],["63.012","15283"],["63.029","0"]]}}
1626916409.2302358: {"stream":"linkusd_perp@depth@100ms","data":{"e":"depthUpdate","E":1626916407020,"T":1626916406979,"s":"LINKUSD_PERP","ps":"LINKUSD","U":167006124988,"u":167006125423,"pu":167006124853,"b":[["15.015","578"]],"a":[["15.066","602"],["15.068","221"],["15.079","1607"],["15.091","780"],["15.101","217"],["15.111","40"],["15.119","282"]]}}
1626916409.2302668: {"stream":"xrpusd_perp@depth@100ms","data":{"e":"depthUpdate","E":1626916407038,"T":1626916407027,"s":"XRPUSD_PERP","ps":"XRPUSD","U":167006125108,"u":167006125669,"pu":167006124997,"b":[["0.5037","1196"],["0.5067","0"],["0.5489","109"],["0.5549","4606"],["0.5640","1691"],["0.5644","3919"],["0.5647","1449"],["0.5648","24666"],["0.5650","6843"],["0.5651","2977"],["0.5652","758"],["0.5653","11243"],["0.5654","9551"],["0.5656","7377"],["0.5657","4826"],["0.5658","2305"],["0.5659","1995"]],"a":[["0.5660","5814"],["0.5662","2026"],["0.5666","2868"],["0.5667","4165"],["0.5668","9833"],["0.5669","3802"],["0.5670","3110"],["0.5671","3416"],["0.5673","12538"],["0.5676","53707"],["0.5684","576"],["0.5685","971"],["0.5696","3023"],["0.5802","1035"],["0.5832","143"],["0.5869","0"],["0.5963","354"],["0.6002","0"]]}}
1626916409.230277: {"stream":"bchusd_210924@depth@100ms","data":{"e":"depthUpdate","E":1626916407038,"T":1626916406952,"s":"BCHUSD_210924","ps":"BCHUSD","U":167006125109,"u":167006125206,"pu":167006124034,"b":[["429.10","157"]],"a":[["429.97","12"],["430.27","1049"]]}}
1626916409.2303329: {"stream":"bchusd_perp@depth@100ms","data":{"e":"depthUpdate","E":1626916407067,"T":1626916407049,"s":"BCHUSD_PERP","ps":"BCHUSD","U":167006125278,"u":167006125807,"pu":167006124625,"b":[["427.65","290"],["427.77","174"]],"a":[["427.78","250"],["427.79","0"],["427.99","1"],["428.20","1433"]]}}
1626916409.230366: {"stream":"trxusd_perp@depth@100ms","data":{"e":"depthUpdate","E":1626916407077,"T":1626916407044,"s":"TRXUSD_PERP","ps":"TRXUSD","U":167006125380,"u":167006125780,"pu":167006125147,"b":[["0.05341","1746"],["0.05342","613"]],"a":[["0.05347","20962"],["0.05348","1184"],["0.05350","2479"],["0.05353","1246"],["0.05354","1293"],["0.05355","949"],["0.05363","23970"],["0.05364","2231"],["0.05379","701"]]}}
1626916409.2303889: {"stream":"etcusd_perp@depth@100ms","data":{"e":"depthUpdate","E":1626916407090,"T":1626916407045,"s":"ETCUSD_PERP","ps":"ETCUSD","U":167006125459,"u":167006125782,"pu":167006125269,"b":[["42.176","500"],["42.185","960"]],"a":[["42.264","0"],["42.265","451"],["42.278","0"]]}}
1626916409.230426: {"stream":"eosusd_perp@depth@100ms","data":{"e":"depthUpdate","E":1626916407103,"T":1626916407088,"s":"EOSUSD_PERP","ps":"EOSUSD","U":167006125509,"u":167006126111,"pu":167006125464,"b":[["3.455","9818"],["3.458","8380"],["3.466","0"]],"a":[["3.469","3345"],["3.472","4349"],["3.474","3242"],["3.476","3236"],["3.483","853"]]}}
1626916409.230432: {"stream":"ethusd_210924@depth@100ms","data":{"e":"depthUpdate","E":1626916407107,"T":1626916407065,"s":"ETHUSD_210924","ps":"ETHUSD","U":167006125528,"u":167006125943,"pu":167006125375,"b":[["1986.80","500"],["1987.91","0"],["1988.39","9517"],["1990.67","0"],["1990.70","360"],["1990.71","1007"]],"a":[["1991.22","250"],["1991.36","0"],["1991.44","0"],["1991.77","270"],["1992.62","100"],["1992.65","525"],["1998.31","895"]]}}
1626916409.230491: {"stream":"linkusd_perp@depth@100ms","data":{"e":"depthUpdate","E":1626916407125,"T":1626916407076,"s":"LINKUSD_PERP","ps":"LINKUSD","U":167006125634,"u":167006126010,"pu":167006125423,"b":[["15.050","162"],["15.053","3279"],["15.061","110"]],"a":[["15.066","1429"],["15.067","4384"],["15.068","29"],["15.069","506"]]}}
1626916409.2305129: {"stream":"xrpusd_perp@depth@100ms","data":{"e":"depthUpdate","E":1626916407140,"T":1626916407132,"s":"XRPUSD_PERP","ps":"XRPUSD","U":167006125703,"u":167006126384,"pu":167006125669,"b":[["0.5639","1128"],["0.5640","7191"],["0.5646","603"],["0.5647","1796"],["0.5648","27211"],["0.5649","5479"],["0.5650","6683"],["0.5651","3326"],["0.5652","918"],["0.5653","11543"],["0.5655","6143"],["0.5656","7419"],["0.5657","4734"],["0.5658","2640"],["0.5659","1170"]],"a":[["0.5648","0"],["0.5659","0"],["0.5660","1509"],["0.5661","2170"],["0.5662","2026"],["0.5663","5954"],["0.5664","7384"],["0.5666","3242"],["0.5667","3865"],["0.5674","4032"],["0.5676","53207"],["0.5682","13241"],["0.5833","2940"],["0.5890","514"],["0.5916","0"]]}}
1626916409.230561: {"stream":"btcusd_211231@depth@100ms","data":{"e":"depthUpdate","E":1626916407168,"T":1626916407109,"s":"BTCUSD_211231","ps":"BTCUSD","U":167006125914,"u":167006126230,"pu":167006125265,"b":[["32332.7","371"]],"a":[["32625.8","153"],["32627.6","0"],["32747.7","0"],["33027.1","90"],["33187.1","90"],["33347.1","90"],["33507.1","46"],["33507.2","46"],["33667.1","46"],["33667.2","46"]]}}
1626916409.230575: {"stream":"linkusd_211231@depth@100ms","data":{"e":"depthUpdate","E":1626916407184,"T":1626916407108,"s":"LINKUSD_211231","ps":"LINKUSD","U":167006126040,"u":167006126222,"pu":167006125479,"b":[["15.288","3223"],["15.305","70"]],"a":[["15.329","522"]]}}
1626916409.230597: {"stream":"etcusd_perp@depth@100ms","data":{"e":"depthUpdate","E":1626916407208,"T":1626916407186,"s":"ETCUSD_PERP","ps":"ETCUSD","U":167006126187,"u":167006126814,"pu":167006125782,"b":[["41.863","72"],["41.913","0"],["42.231","153"],["42.236","600"]],"a":[["42.259","100"],["42.263","500"],["42.265","361"],["42.267","90"],["42.278","0"],["42.280","0"],["42.282","1555"]]}}
1626916409.230634: {"stream":"eosusd_perp@depth@100ms","data":{"e":"depthUpdate","E":1626916407210,"T":1626916407199,"s":"EOSUSD_PERP","ps":"EOSUSD","U":167006126199,"u":167006126945,"pu":167006126111,"b":[["3.450","18554"],["3.457","3636"],["3.460","1301"],["3.466","0"]],"a":[["3.470","6042"]]}}
1626916409.230641: {"stream":"bchusd_perp@depth@100ms","data":{"e":"depthUpdate","E":1626916407210,"T":1626916407156,"s":"BCHUSD_PERP","ps":"BCHUSD","U":167006126198,"u":167006126563,"pu":167006125807,"b":[["427.45","17"],["427.77","150"]],"a":[["428.01","5066"],["428.12","778"]]}}
1626916409.230658: {"stream":"ethusd_210924@depth@100ms","data":{"e":"depthUpdate","E":1626916407212,"T":1626916407180,"s":"ETHUSD_210924","ps":"ETHUSD","U":167006126224,"u":167006126757,"pu":167006125943,"b":[["1982.05","3484"],["1989.70","1780"],["1990.29","613"],["1990.58","262"],["1990.63","0"],["1990.65","0"],["1990.71","0"],["1990.72","222"],["1990.98","439"]],"a":[["1991.36","270"],["1991.77","0"],["1992.18","443"],["1992.81","0"],["1993.49","1500"],["1994.32","0"],["1999.92","2000"]]}}
1626916409.230726: {"stream":"trxusd_perp@depth@100ms","data":{"e":"depthUpdate","E":1626916407230,"T":1626916407217,"s":"TRXUSD_PERP","ps":"TRXUSD","U":167006126331,"u":167006127046,"pu":167006125780,"b":[["0.05342","533"],["0.05344","592"]],"a":[["0.05348","784"],["0.05349","1294"],["0.05350","2679"],["0.05351","2509"]]}}
1626916409.2307332: {"stream":"linkusd_perp@depth@100ms","data":{"e":"depthUpdate","E":1626916407232,"T":1626916407222,"s":"LINKUSD_PERP","ps":"LINKUSD","U":167006126338,"u":167006127092,"pu":167006126010,"b":[["15.061","300"]],"a":[["15.067","4114"],["15.069","150"],["15.071","400"],["15.073","448"],["15.076","224"]]}}
1626916409.230753: {"stream":"xrpusd_perp@depth@100ms","data":{"e":"depthUpdate","E":1626916407242,"T":1626916407217,"s":"XRPUSD_PERP","ps":"XRPUSD","U":167006126416,"u":167006127051,"pu":167006126384,"b":[["0.5599","2436"],["0.5640","7496"],["0.5652","758"],["0.5653","12031"],["0.5654","9711"],["0.5657","4737"],["0.5658","2637"],["0.5659","1470"]],"a":[["0.5660","1509"],["0.5661","1430"],["0.5663","6254"],["0.5665","1234"],["0.5679","3130"]]}}
1626916409.230761: {"stream":"bchusd_210924@depth@100ms","data":{"e":"depthUpdate","E":1626916407246,"T":1626916407217,"s":"BCHUSD_210924","ps":"BCHUSD","U":167006126461,"u":167006127052,"pu":167006125206,"b":[["428.78","0"],["428.92","210"],["429.10","1502"]],"a":[["433.25","171"],["433.70","0"]]}}
1626916409.230795: {"stream":"btcusd_211231@depth@100ms","data":{"e":"depthUpdate","E":1626916407273,"T":1626916407214,"s":"BTCUSD_211231","ps":"BTCUSD","U":167006126651,"u":167006127032,"pu":167006126230,"b":[["32494.1","0"],["32526.6","892"]],"a":[["32625.8","153"],["32627.6","0"],["32649.4","0"],["32721.3","2"],["33371.9","330"]]}}
1626916409.230832: {"stream":"eosusd_perp@depth@100ms","data":{"e":"depthUpdate","E":1626916407316,"T":1626916407295,"s":"EOSUSD_PERP","ps":"EOSUSD","U":167006127022,"u":167006127625,"pu":167006126945,"b":[["3.464","4362"],["3.465","2066"],["3.466","0"]],"a":[]}}
1626916409.230853: {"stream":"etcusd_perp@depth@100ms","data":{"e":"depthUpdate","E":1626916407325,"T":1626916407320,"s":"ETCUSD_PERP","ps":"ETCUSD","U":167006127083,"u":167006127753,"pu":167006126814,"b":[["42.121","260"],["42.130","80"],["42.205","70"],["42.209","1105"],["42.210","1027"],["42.220","1467"],["42.227","418"],["42.230","50"]],"a":[["42.267","0"],["42.278","90"]]}}
1626916409.2308962: {"stream":"bchusd_perp@depth@100ms","data":{"e":"depthUpdate","E":1626916407332,"T":1626916407291,"s":"BCHUSD_PERP","ps":"BCHUSD","U":167006127120,"u":167006127578,"pu":167006126563,"b":[["427.35","3305"],["427.77","174"]],"a":[["428.01","3114"]]}}
1626916409.230911: {"stream":"ethusd_210924@depth@100ms","data":{"e":"depthUpdate","E":1626916407334,"T":1626916407305,"s":"ETHUSD_210924","ps":"ETHUSD","U":167006127157,"u":167006127666,"pu":167006126757,"b":[["1990.36","50"],["1990.80","480"],["1990.81","170"]],"a":[["1991.11","500"],["1991.22","0"],["1992.21","0"],["1992.86","972"],["1993.26","0"],["1993.43","80"]]}}
1626916409.2309492: {"stream":"linkusd_perp@depth@100ms","data":{"e":"depthUpdate","E":1626916407334,"T":1626916407291,"s":"LINKUSD_PERP","ps":"LINKUSD","U":167006127151,"u":167006127580,"pu":167006127092,"b":[["15.047","3573"],["15.049","58"],["15.050","1767"]],"a":[["15.067","3814"],["15.070","4441"],["15.071","630"],["15.072","842"],["15.079","1487"]]}}
1626916409.230973: {"stream":"xrpusd_perp@depth@100ms","data":{"e":"depthUpdate","E":1626916407343,"T":1626916407335,"s":"XRPUSD_PERP","ps":"XRPUSD","U":167006127205,"u":167006127854,"pu":167006127051,"b":[["0.5591","473"],["0.5620","7163"],["0.5625","9483"],["0.5628","3000"],["0.5631","0"],["0.5633","3861"],["0.5640","6436"],["0.5642","2356"],["0.5645","9438"],["0.5659","2173"]],"a":[["0.5660","1509"],["0.5661","1405"],["0.5678","780"],["0.5774","49"],["0.5859","2953"]]}}
1626916409.230981: {"stream":"trxusd_perp@depth@100ms","data":{"e":"depthUpdate","E":1626916407377,"T":1626916407269,"s":"TRXUSD_PERP","ps":"TRXUSD","U":167006127385,"u":167006127422,"pu":167006127046,"b":[["0.05339","1333"],["0.05341","1714"]],"a":[["0.05347","20987"],["0.05351","2524"]]}}
1626916409.230987: {"stream":"btcusd_211231@depth@100ms","data":{"e":"depthUpdate","E":1626916407400,"T":1626916407384,"s":"BTCUSD_211231","ps":"BTCUSD","U":167006127620,"u":167006128113,"pu":167006127032,"b":[["31370.0","0"],["31530.0","0"],["31690.1","0"],["31850.1","0"],["32010.2","0"]],"a":[["32625.8","0"],["32627.6","153"],["32880.6","1139"],["32918.6","0"]]}}
1626916409.2309928: {"stream":"eosusd_perp@depth@100ms","data":{"e":"depthUpdate","E":1626916407420,"T":1626916407413,"s":"EOSUSD_PERP","ps":"EOSUSD","U":167006127726,"u":167006128284,"pu":167006127625,"b":[["3.463","5530"],["3.464","4819"],["3.466","0"]],"a":[["3.467","2389"],["3.471","7382"]]}}
1626916409.230999: {"stream":"linkusd_211231@depth@100ms","data":{"e":"depthUpdate","E":1626916407434,"T":1626916407357,"s":"LINKUSD_211231","ps":"LINKUSD","U":167006127824,"u":167006127963,"pu":167006126222,"b":[["15.279","100"]],"a":[["15.328","1426"],["15.329","0"],["15.330","62"]]}}
1626916409.231004: {"stream":"ethusd_210924@depth@100ms","data":{"e":"depthUpdate","E":1626916407434,"T":1626916407413,"s":"ETHUSD_210924","ps":"ETHUSD","U":167006127812,"u":167006128287,"pu":167006127666,"b":[["1988.06","12"],["1988.30","770"],["1988.56","7093"],["1989.57","2403"],["1990.37","0"],["1990.69","0"],["1990.70","0"],["1990.71","270"]],"a":[["1991.22","480"],["1991.41","200"],["1993.43","0"]]}}
1626916409.231053: {"stream":"xrpusd_perp@depth@100ms","data":{"e":"depthUpdate","E":1626916407444,"T":1626916407424,"s":"XRPUSD_PERP","ps":"XRPUSD","U":167006127868,"u":167006128342,"pu":167006127854,"b":[["0.5625","9650"],["0.5654","9551"],["0.5656","7579"]],"a":[["0.5661","1070"],["0.5685","958"],["0.5748","4855"],["0.5833","3156"]]}}
1626916409.231067: {"stream":"linkusd_perp@depth@100ms","data":{"e":"depthUpdate","E":1626916407460,"T":1626916407431,"s":"LINKUSD_PERP","ps":"LINKUSD","U":167006127956,"u":167006128375,"pu":167006127580,"b":[["15.040","658"],["15.054","1149"],["15.056","1862"]],"a":[["15.066","302"],["15.067","200"],["15.069","1555"],["15.071","1010"],["15.072","462"],["15.124","624"],["15.220","128"],["15.243","0"]]}}
1626916409.2310998: {"stream":"etcusd_perp@depth@100ms","data":{"e":"depthUpdate","E":1626916407492,"T":1626916407473,"s":"ETCUSD_PERP","ps":"ETCUSD","U":167006128134,"u":167006128620,"pu":167006127753,"b":[["41.912","0"],["42.109","37"],["42.144","97"]],"a":[["42.259","242"],["42.263","200"],["42.264","0"],["42.265","451"],["42.267","0"],["42.278","0"],["42.283","0"],["42.691","0"]]}}
1626916409.231146: {"stream":"btcusd_211231@depth@100ms","data":{"e":"depthUpdate","E":1626916407504,"T":1626916407496,"s":"BTCUSD_211231","ps":"BTCUSD","U":167006128206,"u":167006128741,"pu":167006128113,"b":[["31360.0","55"],["31520.0","90"],["31680.0","58"],["31840.0","55"],["32000.0","360"],["32610.1","170"],["32612.4","167"]],"a":[["32623.4","16"],["32625.8","153"],["32627.6","0"],["32653.9","10"],["33327.8","332"]]}}
1626916409.231161: {"stream":"bchusd_210924@depth@100ms","data":{"e":"depthUpdate","E":1626916407506,"T":1626916407483,"s":"BCHUSD_210924","ps":"BCHUSD","U":167006128215,"u":167006128672,"pu":167006127052,"b":[],"a":[["429.80","0"],["430.10","418"],["430.27","525"],["430.37","0"],["430.58","125"]]}}
1626916409.231185: {"stream":"bchusd_perp@depth@100ms","data":{"e":"depthUpdate","E":1626916407509,"T":1626916407476,"s":"BCHUSD_PERP","ps":"BCHUSD","U":167006128234,"u":167006128631,"pu":167006127578,"b":[["427.41","1809"],["427.57","250"],["427.77","150"]],"a":[["427.97","51"],["428.55","401"],["428.77","0"]]}}
1626916409.231234: {"stream":"ethusd_210924@depth@100ms","data":{"e":"depthUpdate","E":1626916407536,"T":1626916407522,"s":"ETHUSD_210924","ps":"ETHUSD","U":167006128368,"u":167006128882,"pu":167006128287,"b":[["1986.80","0"],["1989.75","0"]],"a":[["1993.13","314"],["1993.26","0"],["1993.83","0"],["1999.97","0"]]}}
1626916409.231275: {"stream":"eosusd_perp@depth@100ms","data":{"e":"depthUpdate","E":1626916407538,"T":1626916407518,"s":"EOSUSD_PERP","ps":"EOSUSD","U":167006128392,"u":167006128861,"pu":167006128284,"b":[["3.452","6831"],["3.458","5299"],["3.466","0"]],"a":[["3.470","6842"]]}}
1626916409.2312808: {"stream":"trxusd_perp@depth@100ms","data":{"e":"depthUpdate","E":1626916407549,"T":1626916407540,"s":"TRXUSD_PERP","ps":"TRXUSD","U":167006128446,"u":167006128972,"pu":167006127422,"b":[["0.05342","613"],["0.05344","512"]],"a":[["0.05356","529"]]}}
1626916409.231287: {"stream":"xrpusd_perp@depth@100ms","data":{"e":"depthUpdate","E":1626916407549,"T":1626916407541,"s":"XRPUSD_PERP","ps":"XRPUSD","U":167006128447,"u":167006128979,"pu":167006128342,"b":[["0.5645","4897"],["0.5650","6683"],["0.5651","5614"],["0.5656","7419"],["0.5657","4734"],["0.5658","2830"]],"a":[["0.5677","412"],["0.5826","0"]]}}
1626916409.231293: {"stream":"linkusd_211231@depth@100ms","data":{"e":"depthUpdate","E":1626916407554,"T":1626916407451,"s":"LINKUSD_211231","ps":"LINKUSD","U":167006128457,"u":167006128480,"pu":167006127963,"b":[["14.758","0"],["14.834","0"],["14.909","0"],["14.984","0"],["15.060","0"]],"a":[["15.523","0"],["15.598","0"],["15.673","0"],["15.749","0"],["15.824","0"]]}}
1626916409.231315: {"stream":"linkusd_perp@depth@100ms","data":{"e":"depthUpdate","E":1626916407574,"T":1626916407536,"s":"LINKUSD_PERP","ps":"LINKUSD","U":167006128597,"u":167006128956,"pu":167006128375,"b":[["15.034","618"],["15.039","454"],["15.058","171"],["15.059","80"],["15.060","391"],["15.061","110"]],"a":[["15.067","500"],["15.069","5507"],["15.070","4141"],["15.129","1702"],["15.274","7500"]]}}
1626916409.231346: {"stream":"etcusd_perp@depth@100ms","data":{"e":"depthUpdate","E":1626916407604,"T":1626916407568,"s":"ETCUSD_PERP","ps":"ETCUSD","U":167006128750,"u":167006129189,"pu":167006128620,"b":[["42.231","63"],["42.237","90"]],"a":[["42.259","100"],["42.262","542"],["42.265","361"],["42.278","90"],["42.310","0"],["42.326","200"],["42.328","782"],["42.334","500"],["42.388","348"],["42.423","0"]]}}
1626916409.2313862: {"stream":"bchusd_perp@depth@100ms","data":{"e":"depthUpdate","E":1626916407609,"T":1626916407527,"s":"BCHUSD_PERP","ps":"BCHUSD","U":167006128775,"u":167006128909,"pu":167006128631,"b":[["427.77","174"]],"a":[["427.96","0"]]}}
1626916409.231412: {"stream":"btcusd_211231@depth@100ms","data":{"e":"depthUpdate","E":1626916407622,"T":1626916407603,"s":"BTCUSD_211231","ps":"BTCUSD","U":167006128863,"u":167006129390,"pu":167006128741,"b":[["32494.0","0"],["32516.8","446"]],"a":[["32623.4","17"],["32627.7","0"],["35994.8","0"]]}}
1626916409.2314181: {"stream":"bchusd_210924@depth@100ms","data":{"e":"depthUpdate","E":1626916407627,"T":1626916407607,"s":"BCHUSD_210924","ps":"BCHUSD","U":167006128876,"u":167006129418,"pu":167006128672,"b":[["429.36","0"]],"a":[["429.65","0"],["429.73","120"],["1722.54","0"]]}}
1626916409.231442: {"stream":"ethusd_210924@depth@100ms","data":{"e":"depthUpdate","E":1626916407636,"T":1626916407621,"s":"ETHUSD_210924","ps":"ETHUSD","U":167006128932,"u":167006129529,"pu":167006128882,"b":[["1984.97","0"],["1988.08","979"],["1989.20","0"],["1989.69","314"],["1990.32","360"],["1990.35","2602"],["1990.36","1073"],["1990.98","1219"]],"a":[["1990.99","240"],["1991.10","0"],["1991.11","0"],["1991.21","169"],["1991.36","270"],["1991.77","0"],["1991.83","0"],["1993.44","80"],["1995.06","565"],["1995.74","0"],["1995.85","0"]]}}
1626916409.231503: {"stream":"eosusd_perp@depth@100ms","data":{"e":"depthUpdate","E":1626916407643,"T":1626916407628,"s":"EOSUSD_PERP","ps":"EOSUSD","U":167006128975,"u":167006129576,"pu":167006128861,"b":[["3.449","1026"],["3.455","12896"],["3.462","7433"],["3.463","4231"],["3.464","6075"],["3.466","0"]],"a":[["3.468","5503"]]}}
1626916409.231511: {"stream":"trxusd_perp@depth@100ms","data":{"e":"depthUpdate","E":1626916407652,"T":1626916407628,"s":"TRXUSD_PERP","ps":"TRXUSD","U":167006129003,"u":167006129578,"pu":167006128972,"b":[["0.05327","132"]],"a":[["0.05353","2134"],["0.05359","306"],["0.05366","982"]]}}
1626916409.2315168: {"stream":"linkusd_211231@depth@100ms","data":{"e":"depthUpdate","E":1626916407659,"T":1626916407584,"s":"LINKUSD_211231","ps":"LINKUSD","U":167006129074,"u":167006129281,"pu":167006128480,"b":[["14.759","100"],["14.835","100"],["14.910","100"],["14.985","676"],["15.061","100"],["15.287","1196"]],"a":[]}}
1626916409.231532: {"stream":"xrpusd_perp@depth@100ms","data":{"e":"depthUpdate","E":1626916407667,"T":1626916407659,"s":"XRPUSD_PERP","ps":"XRPUSD","U":167006129139,"u":167006129765,"pu":167006128979,"b":[],"a":[["0.5660","1479"],["0.5662","2326"],["0.5663","5954"],["0.5664","7342"],["0.5665","1804"]]}}
1626916409.2315772: {"stream":"linkusd_perp@depth@100ms","data":{"e":"depthUpdate","E":1626916407679,"T":1626916407672,"s":"LINKUSD_PERP","ps":"LINKUSD","U":167006129213,"u":167006129810,"pu":167006128956,"b":[["3.019","0"],["15.047","3373"],["15.050","1967"],["15.060","201"]],"a":[["15.067","200"],["15.069","5807"],["15.155","134"],["15.169","0"],["16.909","0"],["19.626","0"],["62.500","0"]]}}
1626916409.231711: {"stream":"etcusd_perp@depth@100ms","data":{"e":"depthUpdate","E":1626916407720,"T":1626916407689,"s":"ETCUSD_PERP","ps":"ETCUSD","U":167006129460,"u":167006129915,"pu":167006129189,"b":[["41.856","82"],["42.207","1310"],["42.210","17"],["42.225","1010"],["42.228","90"],["42.230","17"],["42.233","370"],["42.236","512"],["42.237","0"]],"a":[["42.265","451"],["42.278","0"],["42.641","84"]]}}
1626916409.231853: {"stream":"ethusd_210924@depth@100ms","data":{"e":"depthUpdate","E":1626916407738,"T":1626916407726,"s":"ETHUSD_210924","ps":"ETHUSD","U":167006129604,"u":167006130194,"pu":167006129529,"b":[["1988.56","4714"],["1988.91","0"],["1989.32","2364"],["1990.71","0"],["1990.72","0"],["1990.73","270"],["1990.98","1219"]],"a":[["1991.21","0"],["1991.22","0"],["1991.31","0"],["1991.32","360"],["1991.35","324"],["1991.44","612"],["1991.87","0"]]}}
1626916409.231934: {"stream":"eosusd_perp@depth@100ms","data":{"e":"depthUpdate","E":1626916407745,"T":1626916407739,"s":"EOSUSD_PERP","ps":"EOSUSD","U":167006129625,"u":167006130308,"pu":167006129576,"b":[["3.433","655"],["3.461","3236"],["3.462","4971"],["3.463","4231"],["3.464","7260"],["3.465","3187"],["3.466","3591"],["3.467","1826"]],"a":[["3.466","0"],["3.467","0"],["3.468","865"],["3.469","2298"],["3.470","4182"],["3.471","5697"],["3.472","1580"],["3.473","4588"],["3.474","4019"]]}}
1626916409.231963: {"stream":"bchusd_210924@depth@100ms","data":{"e":"depthUpdate","E":1626916407748,"T":1626916407645,"s":"BCHUSD_210924","ps":"BCHUSD","U":167006129643,"u":167006129660,"pu":167006129418,"b":[["428.76","4595"]],"a":[["1722.13","12138"]]}}
1626916409.231982: {"stream":"bchusd_perp@depth@100ms","data":{"e":"depthUpdate","E":1626916407750,"T":1626916407698,"s":"BCHUSD_PERP","ps":"BCHUSD","U":167006129651,"u":167006129960,"pu":167006128909,"b":[["427.47","3501"],["427.50","5111"]],"a":[["428.00","1877"],["428.04","2118"],["428.33","3009"],["428.41","249"],["429.24","15"]]}}
1626916409.232029: {"stream":"trxusd_perp@depth@100ms","data":{"e":"depthUpdate","E":1626916407763,"T":1626916407755,"s":"TRXUSD_PERP","ps":"TRXUSD","U":167006129729,"u":167006130408,"pu":167006129578,"b":[["0.05307","387"],["0.05340","2952"],["0.05342","533"],["0.05343","1140"]],"a":[["0.05347","20987"],["0.05348","784"],["0.05349","994"],["0.05350","2679"],["0.05351","2524"],["0.05354","1593"],["0.05355","1249"],["0.05357","2430"],["0.05358","1138"],["0.05362","623"],["0.05386","319"]]}}
1626916409.232048: {"stream":"linkusd_211231@depth@100ms","data":{"e":"depthUpdate","E":1626916407777,"T":1626916407745,"s":"LINKUSD_211231","ps":"LINKUSD","U":167006129814,"u":167006130348,"pu":167006129281,"b":[["3.143","0"],["15.191","3"],["15.208","0"],["15.237","0"]],"a":[]}}
1626916409.2320561: {"stream":"linkusd_perp@depth@100ms","data":{"e":"depthUpdate","E":1626916407781,"T":1626916407773,"s":"LINKUSD_PERP","ps":"LINKUSD","U":167006129845,"u":167006130530,"pu":167006129810,"b":[["10.567","0"],["13.284","0"],["15.048","494"],["15.049","1092"],["15.050","542"]],"a":[["15.067","500"],["15.069","5507"],["15.852","0"]]}}
1626916409.232102: {"stream":"btcusd_211231@depth@100ms","data":{"e":"depthUpdate","E":1626916407788,"T":1626916407683,"s":"BTCUSD_211231","ps":"BTCUSD","U":167006129877,"u":167006129877,"pu":167006129390,"b":[],"a":[["32694.4","0"]]}}
1626916409.232109: {"stream":"xrpusd_perp@depth@100ms","data":{"e":"depthUpdate","E":1626916407790,"T":1626916407772,"s":"XRPUSD_PERP","ps":"XRPUSD","U":167006129897,"u":167006130523,"pu":167006129765,"b":[["0.5448","25"],["0.5633","4461"],["0.5641","3353"]],"a":[["0.5661","1100"],["0.5705","24434"],["0.5724","0"]]}}
1626916409.232204: {"stream":"eosusd_perp@depth@100ms","data":{"e":"depthUpdate","E":1626916407845,"T":1626916407839,"s":"EOSUSD_PERP","ps":"EOSUSD","U":167006130320,"u":167006130864,"pu":167006130308,"b":[["3.450","18303"],["3.451","3988"],["3.453","1874"],["3.454","4045"],["3.455","13716"],["3.458","4478"],["3.459","676"],["3.460","1301"],["3.461","1959"],["3.462","4917"],["3.463","2550"],["3.464","7579"],["3.465","3598"],["3.466","3975"],["3.467","3746"],["3.468","0"]],"a":[["3.468","130"],["3.469","2615"],["3.470","4522"],["3.471","5175"],["3.472","2440"],["3.473","2456"],["3.474","3949"],["3.475","4095"],["3.476","4091"],["3.479","4871"],["3.480","1643"],["3.481","6221"],["3.485","5341"],["3.490","1755"],["3.492","9874"]]}}
1626916409.232225: {"stream":"ethusd_210924@depth@100ms","data":{"e":"depthUpdate","E":1626916407853,"T":1626916407846,"s":"ETHUSD_210924","ps":"ETHUSD","U":167006130369,"u":167006130912,"pu":167006130194,"b":[["1926.06","0"],["1990.73","0"],["1990.98","1489"]],"a":[["1991.25","360"],["1991.27","127"],["1991.28","0"],["1991.31","0"],["1991.32","0"],["1991.36","0"],["1991.44","0"],["1991.45","0"],["1991.77","270"],["1991.89","0"],["1991.96","0"],["1991.97","0"],["1992.04","0"],["1992.23","0"],["1993.13","636"],["1993.14","301"]]}}
1626916409.23231: {"stream":"trxusd_perp@depth@100ms","data":{"e":"depthUpdate","E":1626916407866,"T":1626916407854,"s":"TRXUSD_PERP","ps":"TRXUSD","U":167006130455,"u":167006130971,"pu":167006130408,"b":[["0.05340","2872"],["0.05343","1220"]],"a":[["0.05347","21187"],["0.05348","635"],["0.05349","1394"],["0.05350","2479"],["0.05351","2324"]]}}
1626916409.232329: {"stream":"etcusd_perp@depth@100ms","data":{"e":"depthUpdate","E":1626916407871,"T":1626916407840,"s":"ETCUSD_PERP","ps":"ETCUSD","U":167006130482,"u":167006130890,"pu":167006129915,"b":[["42.146","500"],["42.176","0"]],"a":[["42.293","0"],["42.303","863"],["42.304","548"]]}}
1626916409.23236: {"stream":"linkusd_perp@depth@100ms","data":{"e":"depthUpdate","E":1626916407883,"T":1626916407876,"s":"LINKUSD_PERP","ps":"LINKUSD","U":167006130546,"u":167006131101,"pu":167006130530,"b":[["14.341","0"],["15.050","162"],["15.051","2118"],["15.054","1149"],["15.058","20"],["15.060","1082"],["15.061","489"]],"a":[["15.067","200"],["15.069","5807"],["15.077","395"],["15.094","221"],["15.102","551"]]}}
1626916409.232397: {"stream":"btcusd_211231@depth@100ms","data":{"e":"depthUpdate","E":1626916407889,"T":1626916407878,"s":"BTCUSD_211231","ps":"BTCUSD","U":167006130583,"u":167006131106,"pu":167006129877,"b":[["32515.1","0"],["32516.9","1745"]],"a":[["32625.8","153"],["32628.5","46"],["32629.2","0"],["32638.5","145"],["32707.1","394"],["35937.3","358"]]}}
1626916409.232406: {"stream":"linkusd_211231@depth@100ms","data":{"e":"depthUpdate","E":1626916407897,"T":1626916407822,"s":"LINKUSD_211231","ps":"LINKUSD","U":167006130614,"u":167006130797,"pu":167006130348,"b":[["3.142","771"],["15.221","135"],["15.289","1066"]],"a":[["15.326","1360"],["15.328","0"]]}}
1626916409.2324128: {"stream":"bchusd_perp@depth@100ms","data":{"e":"depthUpdate","E":1626916407901,"T":1626916407851,"s":"BCHUSD_PERP","ps":"BCHUSD","U":167006130646,"u":167006130951,"pu":167006129960,"b":[["427.77","150"]],"a":[["427.78","150"],["427.79","100"],["427.80","0"],["427.88","0"],["428.21","48"]]}}
1626916409.232482: {"stream":"xrpusd_perp@depth@100ms","data":{"e":"depthUpdate","E":1626916407931,"T":1626916407887,"s":"XRPUSD_PERP","ps":"XRPUSD","U":167006130833,"u":167006131166,"pu":167006130523,"b":[["0.5641","3352"],["0.5644","4271"],["0.5652","7664"],["0.5653","5125"]],"a":[["0.5663","6182"],["0.5664","7114"],["0.5672","8420"],["0.5673","5632"]]}}
1626916409.232521: {"stream":"eosusd_perp@depth@100ms","data":{"e":"depthUpdate","E":1626916407948,"T":1626916407939,"s":"EOSUSD_PERP","ps":"EOSUSD","U":167006130894,"u":167006131442,"pu":167006130864,"b":[["3.442","16262"],["3.443","6454"],["3.444","10231"],["3.454","4369"],["3.455","14040"],["3.458","2718"],["3.460","2921"],["3.461","2239"],["3.463","2587"],["3.464","6142"],["3.465","5810"],["3.466","4037"],["3.467","3781"],["3.468","0"]],"a":[["3.469","1556"],["3.470","4237"],["3.471","3258"],["3.472","3320"],["3.473","2316"],["3.476","5772"],["3.479","3328"],["3.480","1967"],["3.483","939"],["3.491","702"],["3.494","2219"]]}}
1626916409.2325299: {"stream":"ethusd_210924@depth@100ms","data":{"e":"depthUpdate","E":1626916407963,"T":1626916407951,"s":"ETHUSD_210924","ps":"ETHUSD","U":167006130990,"u":167006131510,"pu":167006130912,"b":[["1987.80","2892"],["1988.56","0"],["1989.32","7093"]],"a":[["1991.24","0"],["1991.25","0"],["1991.27","0"],["1991.31","126"],["1991.32","360"],["1991.41","0"],["1991.58","1750"],["1991.59","50"],["1991.88","0"],["1992.15","0"],["1992.55","259"],["1992.56","1968"],["1992.65","0"],["1992.71","623"],["1992.98","50"],["1993.13","314"],["1993.14","0"],["1993.44","0"],["1993.67","425"],["1997.70","0"]]}}
1626916409.23262: {"stream":"trxusd_perp@depth@100ms","data":{"e":"depthUpdate","E":1626916408004,"T":1626916407989,"s":"TRXUSD_PERP","ps":"TRXUSD","U":167006131229,"u":167006131695,"pu":167006130971,"b":[["0.05329","1854"]],"a":[["0.05347","20987"],["0.05348","635"],["0.05349","1194"],["0.05350","2679"],["0.05351","2524"],["0.21129","0"]]}}
1626916409.2326279: {"stream":"etcusd_perp@depth@100ms","data":{"e":"depthUpdate","E":1626916408007,"T":1626916407960,"s":"ETCUSD_PERP","ps":"ETCUSD","U":167006131250,"u":167006131546,"pu":167006130890,"b":[["42.213","1526"],["42.228","0"],["42.233","100"],["42.236","683"],["42.237","428"]],"a":[["42.265","361"],["42.278","90"]]}}
1626916409.232673: {"stream":"xrpusd_perp@depth@100ms","data":{"e":"depthUpdate","E":1626916408041,"T":1626916408037,"s":"XRPUSD_PERP","ps":"XRPUSD","U":167006131421,"u":167006131941,"pu":167006131166,"b":[["0.5653","4825"],["0.5655","5563"],["0.5656","8299"],["0.5657","4849"],["0.5658","2430"],["0.5659","2543"],["0.5661","0"]],"a":[["0.5662","1726"],["0.5663","6254"],["0.5664","7642"],["0.5671","3416"],["0.5754","20"]]}}
1626916409.232704: {"stream":"eosusd_perp@depth@100ms","data":{"e":"depthUpdate","E":1626916408048,"T":1626916408028,"s":"EOSUSD_PERP","ps":"EOSUSD","U":167006131450,"u":167006131911,"pu":167006131442,"b":[["3.446","13583"],["3.455","13716"],["3.461","2099"],["3.462","5057"],["3.464","6250"],["3.465","5831"],["3.466","4207"],["3.468","0"]],"a":[["3.469","1286"],["3.470","4528"],["3.471","2595"],["3.474","6684"],["3.475","2242"],["3.480","1643"],["3.481","6221"],["3.482","1866"],["3.491","162"],["3.492","10414"]]}}
1626916409.2327209: {"stream":"ethusd_210924@depth@100ms","data":{"e":"depthUpdate","E":1626916408063,"T":1626916408052,"s":"ETHUSD_210924","ps":"ETHUSD","U":167006131520,"u":167006132007,"pu":167006131510,"b":[["1932.41","1929"],["1987.49","0"],["1989.08","0"],["1990.59","270"],["1990.82","0"],["1990.98","1219"]],"a":[["1991.27","126"],["1991.28","360"],["1991.31","0"],["1991.32","0"],["1991.57","632"],["1992.49","50"],["1992.54","1516"],["1993.59","80"],["1999.93","2201"]]}}
1626916409.232785: {"stream":"btcusd_211231@depth@100ms","data":{"e":"depthUpdate","E":1626916408073,"T":1626916408041,"s":"BTCUSD_211231","ps":"BTCUSD","U":167006131594,"u":167006131949,"pu":167006131106,"b":[["32605.9","432"]],"a":[["32625.8","153"],["32628.4","0"],["33027.1","0"],["33187.1","0"],["33347.1","0"],["33507.1","0"],["33507.2","0"],["33667.1","0"],["33667.2","0"]]}}
1626916409.2327921: {"stream":"linkusd_perp@depth@100ms","data":{"e":"depthUpdate","E":1626916408079,"T":1626916408072,"s":"LINKUSD_PERP","ps":"LINKUSD","U":167006131621,"u":167006132099,"pu":167006131101,"b":[["15.049","58"],["15.051","3152"]],"a":[["15.063","0"],["15.064","392"],["15.067","500"],["15.069","5507"],["15.073","338"],["15.077","505"]]}}
1626916409.232818: {"stream":"etcusd_perp@depth@100ms","data":{"e":"depthUpdate","E":1626916408112,"T":1626916408067,"s":"ETCUSD_PERP","ps":"ETCUSD","U":167006131800,"u":167006132067,"pu":167006131546,"b":[["42.234","648"],["42.236","512"]],"a":[["42.267","90"],["42.278","0"]]}}
1626916409.232857: {"stream":"bchusd_perp@depth@100ms","data":{"e":"depthUpdate","E":1626916408133,"T":1626916408127,"s":"BCHUSD_PERP","ps":"BCHUSD","U":167006131892,"u":167006132287,"pu":167006130951,"b":[["427.50","4193"]],"a":[["428.94","350"]]}}
1626916409.232873: {"stream":"trxusd_perp@depth@100ms","data":{"e":"depthUpdate","E":1626916408148,"T":1626916408100,"s":"TRXUSD_PERP","ps":"TRXUSD","U":167006131963,"u":167006132197,"pu":167006131695,"b":[["0.05329","2005"]],"a":[["0.05348","535"],["0.05349","1294"],["0.21123","1600"]]}}
1626916409.232887: {"stream":"eosusd_perp@depth@100ms","data":{"e":"depthUpdate","E":1626916408148,"T":1626916408143,"s":"EOSUSD_PERP","ps":"EOSUSD","U":167006131967,"u":167006132368,"pu":167006131911,"b":[["3.456","1153"],["3.462","4957"],["3.464","6350"],["3.468","0"]],"a":[["3.472","3320"],["3.474","4775"],["3.475","4151"],["3.484","1894"]]}}
1626916409.232894: {"stream":"xrpusd_perp@depth@100ms","data":{"e":"depthUpdate","E":1626916408148,"T":1626916408140,"s":"XRPUSD_PERP","ps":"XRPUSD","U":167006131964,"u":167006132350,"pu":167006131941,"b":[["0.5658","2460"],["0.5659","3683"]],"a":[["0.5670","2835"],["0.5683","1419"],["0.5687","429"]]}}
1626916409.2329118: {"stream":"linkusd_211231@depth@100ms","data":{"e":"depthUpdate","E":1626916408152,"T":1626916408064,"s":"LINKUSD_211231","ps":"LINKUSD","U":167006131991,"u":167006132055,"pu":167006130797,"b":[["15.288","2143"],["15.289","1902"]],"a":[["15.522","164"],["15.597","165"],["15.672","166"],["15.748","167"],["15.823","168"]]}}
1626916409.232932: {"stream":"ethusd_210924@depth@100ms","data":{"e":"depthUpdate","E":1626916408164,"T":1626916408149,"s":"ETHUSD_210924","ps":"ETHUSD","U":167006132030,"u":167006132384,"pu":167006132007,"b":[["1985.02","1000"],["1990.59","0"],["1990.82","0"],["1990.98","1489"]],"a":[["1991.24","127"],["1991.25","360"],["1991.27","0"],["1991.28","0"],["1991.56","270"],["1991.77","0"],["1992.69","12178"],["1994.96","1304"]]}}
1626916409.232987: {"stream":"btcusd_211231@depth@100ms","data":{"e":"depthUpdate","E":1626916408199,"T":1626916408109,"s":"BTCUSD_211231","ps":"BTCUSD","U":167006132170,"u":167006132222,"pu":167006131949,"b":[],"a":[["32625.8","153"],["32628.4","0"],["33027.1","45"],["33187.1","45"],["33347.1","45"],["33507.1","46"],["33667.1","46"]]}}
1626916409.2330098: {"stream":"linkusd_perp@depth@100ms","data":{"e":"depthUpdate","E":1626916408213,"T":1626916408143,"s":"LINKUSD_PERP","ps":"LINKUSD","U":167006132217,"u":167006132369,"pu":167006132099,"b":[["15.055","0"],["15.061","489"]],"a":[["15.074","384"],["15.077","395"]]}}
1626916409.233035: {"stream":"bchusd_210924@depth@100ms","data":{"e":"depthUpdate","E":1626916408231,"T":1626916408145,"s":"BCHUSD_210924","ps":"BCHUSD","U":167006132289,"u":167006132375,"pu":167006129660,"b":[["429.02","2864"]],"a":[["429.66","307"]]}}
1626916409.233052: {"stream":"bchusd_perp@depth@100ms","data":{"e":"depthUpdate","E":1626916408234,"T":1626916408222,"s":"BCHUSD_PERP","ps":"BCHUSD","U":167006132294,"u":167006132751,"pu":167006132287,"b":[["427.63","1166"],["427.65","549"],["427.77","174"]],"a":[["428.64","53"],["429.67","0"]]}}
1626916409.233091: {"stream":"eosusd_perp@depth@100ms","data":{"e":"depthUpdate","E":1626916408258,"T":1626916408240,"s":"EOSUSD_PERP","ps":"EOSUSD","U":167006132403,"u":167006132849,"pu":167006132368,"b":[["3.462","5457"],["3.463","2087"],["3.466","5007"],["3.467","3481"],["3.468","0"]],"a":[["3.471","2703"],["3.472","3370"],["3.474","4775"],["3.475","4151"]]}}
1626916409.233098: {"stream":"etcusd_perp@depth@100ms","data":{"e":"depthUpdate","E":1626916408263,"T":1626916408203,"s":"ETCUSD_PERP","ps":"ETCUSD","U":167006132419,"u":167006132657,"pu":167006132067,"b":[["42.237","338"],["42.238","90"]],"a":[["42.267","90"],["42.278","0"],["42.319","200"],["42.326","0"]]}}
1626916409.233147: {"stream":"xrpusd_perp@depth@100ms","data":{"e":"depthUpdate","E":1626916408274,"T":1626916408267,"s":"XRPUSD_PERP","ps":"XRPUSD","U":167006132457,"u":167006132965,"pu":167006132350,"b":[["0.5545","11"],["0.5653","5673"],["0.5658","2004"],["0.5659","4137"]],"a":[["0.5660","500"],["0.5661","700"],["0.5663","6054"],["0.5664","5494"],["0.5666","2868"],["0.5671","3691"]]}}
1626916409.233174: {"stream":"ethusd_210924@depth@100ms","data":{"e":"depthUpdate","E":1626916408278,"T":1626916408272,"s":"ETHUSD_210924","ps":"ETHUSD","U":167006132498,"u":167006132982,"pu":167006132384,"b":[["1980.04","1000"],["1988.39","0"],["1988.79","8965"]],"a":[["1991.24","0"],["1991.25","0"],["1991.27","126"],["1991.28","0"],["1991.31","0"],["1991.32","0"]]}}
1626916409.2332091: {"stream":"trxusd_perp@depth@100ms","data":{"e":"depthUpdate","E":1626916408305,"T":1626916408258,"s":"TRXUSD_PERP","ps":"TRXUSD","U":167006132636,"u":167006132920,"pu":167006132197,"b":[["0.05341","1714"],["0.05343","1220"]],"a":[["0.05347","20887"],["0.05348","635"]]}}
1626916409.233268: {"stream":"bchusd_perp@depth@100ms","data":{"e":"depthUpdate","E":1626916408336,"T":1626916408230,"s":"BCHUSD_PERP","ps":"BCHUSD","U":167006132798,"u":167006132798,"pu":167006132751,"b":[["427.77","150"]],"a":[]}}
1626916409.233283: {"stream":"btcusd_211231@depth@100ms","data":{"e":"depthUpdate","E":1626916408356,"T":1626916408265,"s":"BTCUSD_211231","ps":"BTCUSD","U":167006132898,"u":167006132946,"pu":167006132222,"b":[["32516.8","0"],["32517.0","463"]],"a":[]}}
1626916409.233299: {"stream":"eosusd_perp@depth@100ms","data":{"e":"depthUpdate","E":1626916408358,"T":1626916408350,"s":"EOSUSD_PERP","ps":"EOSUSD","U":167006132908,"u":167006133333,"pu":167006132849,"b":[["3.465","4761"],["3.466","4837"],["3.467","2695"],["3.468","0"]],"a":[["3.474","4775"],["3.475","4151"]]}}
1626916409.233307: {"stream":"linkusd_perp@depth@100ms","data":{"e":"depthUpdate","E":1626916408356,"T":1626916408313,"s":"LINKUSD_PERP","ps":"LINKUSD","U":167006132888,"u":167006133155,"pu":167006132369,"b":[["15.007","900"]],"a":[["15.067","1048"],["15.068","4116"],["15.069","150"],["15.074","401"],["15.079","1607"],["15.118","905"]]}}
1626916409.233331: {"stream":"etcusd_perp@depth@100ms","data":{"e":"depthUpdate","E":1626916408365,"T":1626916408361,"s":"ETCUSD_PERP","ps":"ETCUSD","U":167006132921,"u":167006133381,"pu":167006132657,"b":[],"a":[["42.257","100"],["42.258","0"],["42.259","0"],["42.262","242"],["42.267","0"],["42.278","90"],["42.281","130"],["42.290","33"]]}}
1626916409.233397: {"stream":"xrpusd_perp@depth@100ms","data":{"e":"depthUpdate","E":1626916408388,"T":1626916408372,"s":"XRPUSD_PERP","ps":"XRPUSD","U":167006133026,"u":167006133431,"pu":167006132965,"b":[["0.5655","5457"],["0.5656","8257"],["0.5657","4891"]],"a":[["0.5664","5452"],["0.5665","1746"],["0.5666","2762"],["0.5667","3971"],["0.5670","2560"],["0.5671","3966"],["0.5680","3525"]]}}
1626916409.233427: {"stream":"ethusd_210924@depth@100ms","data":{"e":"depthUpdate","E":1626916408397,"T":1626916408339,"s":"ETHUSD_210924","ps":"ETHUSD","U":167006133056,"u":167006133289,"pu":167006132982,"b":[["1984.72","382"]],"a":[["1991.27","0"]]}}
1626916409.233448: {"stream":"linkusd_211231@depth@100ms","data":{"e":"depthUpdate","E":1626916408417,"T":1626916408372,"s":"LINKUSD_211231","ps":"LINKUSD","U":167006133156,"u":167006133430,"pu":167006132055,"b":[["15.287","0"],["15.288","3432"]],"a":[["15.325","150"]]}}
1626916409.233484: {"stream":"btcusd_211231@depth@100ms","data":{"e":"depthUpdate","E":1626916408459,"T":1626916408361,"s":"BTCUSD_211231","ps":"BTCUSD","U":167006133344,"u":167006133380,"pu":167006132946,"b":[],"a":[["32625.8","153"],["32628.4","0"]]}}
1626916409.2335: {"stream":"bchusd_perp@depth@100ms","data":{"e":"depthUpdate","E":1626916408463,"T":1626916408444,"s":"BCHUSD_PERP","ps":"BCHUSD","U":167006133371,"u":167006133901,"pu":167006132798,"b":[["427.50","4147"]],"a":[["428.55","25"],["428.77","503"]]}}
1626916409.23352: {"stream":"eosusd_perp@depth@100ms","data":{"e":"depthUpdate","E":1626916408464,"T":1626916408455,"s":"EOSUSD_PERP","ps":"EOSUSD","U":167006133375,"u":167006134014,"pu":167006133333,"b":[["3.452","7242"],["3.463","2245"],["3.464","6420"],["3.465","4711"],["3.466","5224"],["3.468","0"]],"a":[["3.470","5491"],["3.471","2299"],["3.474","4775"],["3.475","3713"],["3.476","5665"]]}}
1626916409.23354: {"stream":"etcusd_perp@depth@100ms","data":{"e":"depthUpdate","E":1626916408471,"T":1626916408463,"s":"ETCUSD_PERP","ps":"ETCUSD","U":167006133406,"u":167006134082,"pu":167006133381,"b":[["39.544","0"],["42.225","0"],["42.227","1460"],["42.234","396"],["42.238","224"],["42.239","431"],["42.240","90"]],"a":[["42.257","0"],["42.259","100"],["42.260","150"],["42.262","542"],["42.265","361"],["42.278","0"],["42.280","200"],["42.290","0"],["42.293","90"],["42.303","0"],["42.307","0"],["42.310","899"],["42.319","0"],["42.325","0"],["42.333","619"]]}}
1626916409.233644: {"stream":"xrpusd_perp@depth@100ms","data":{"e":"depthUpdate","E":1626916408494,"T":1626916408489,"s":"XRPUSD_PERP","ps":"XRPUSD","U":167006133517,"u":167006134299,"pu":167006133431,"b":[["0.5635","2829"],["0.5652","7722"],["0.5655","5157"],["0.5656","8348"],["0.5658","1946"]],"a":[["0.5644","0"],["0.5664","5152"],["0.5672","8466"],["0.5681","3893"]]}}
1626916409.2336829: {"stream":"ethusd_210924@depth@100ms","data":{"e":"depthUpdate","E":1626916408511,"T":1626916408503,"s":"ETHUSD_210924","ps":"ETHUSD","U":167006133625,"u":167006134401,"pu":167006133289,"b":[["1986.87","500"],["1988.12","0"],["1989.07","0"]],"a":[["1991.56","0"],["1991.77","270"],["1991.82","81"],["1991.85","357"],["1992.49","0"],["1992.70","0"],["1993.59","0"],["1993.77","0"],["1994.36","237"],["1994.40","121"],["1995.30","0"],["1995.60","190"]]}}
1626916409.233742: {"stream":"linkusd_perp@depth@100ms","data":{"e":"depthUpdate","E":1626916408513,"T":1626916408492,"s":"LINKUSD_PERP","ps":"LINKUSD","U":167006133642,"u":167006134317,"pu":167006133155,"b":[["15.034","87"],["15.048","651"],["15.061","679"]],"a":[["15.064","290"],["15.067","200"],["15.068","0"],["15.069","4950"],["15.071","930"],["15.074","781"]]}}
1626916409.233794: {"stream":"bchusd_210924@depth@100ms","data":{"e":"depthUpdate","E":1626916408534,"T":1626916408516,"s":"BCHUSD_210924","ps":"BCHUSD","U":167006133801,"u":167006134476,"pu":167006132375,"b":[["429.01","0"],["429.11","249"],["429.23","40"]],"a":[]}}
1626916409.233815: {"stream":"trxusd_perp@depth@100ms","data":{"e":"depthUpdate","E":1626916408542,"T":1626916408447,"s":"TRXUSD_PERP","ps":"TRXUSD","U":167006133863,"u":167006133937,"pu":167006132920,"b":[],"a":[["0.05349","922"],["0.05350","3083"]]}}
1626916409.233888: {"stream":"eosusd_perp@depth@100ms","data":{"e":"depthUpdate","E":1626916408567,"T":1626916408552,"s":"EOSUSD_PERP","ps":"EOSUSD","U":167006134078,"u":167006134700,"pu":167006134014,"b":[["3.468","0"]],"a":[["3.470","3409"],["3.478","4932"]]}}
1626916409.2339048: {"stream":"etcusd_perp@depth@100ms","data":{"e":"depthUpdate","E":1626916408578,"T":1626916408573,"s":"ETCUSD_PERP","ps":"ETCUSD","U":167006134132,"u":167006134815,"pu":167006134082,"b":[["41.975","11450"],["42.000","165"],["42.165","0"],["42.227","418"],["42.228","90"],["42.230","17"],["42.231","1105"],["42.238","0"],["42.240","0"],["42.241","604"],["42.242","0"]],"a":[["42.259","0"],["42.260","250"],["42.262","0"],["42.263","0"],["42.268","500"],["42.275","0"],["42.280","0"],["42.288","22"],["42.293","0"],["42.294","0"],["42.303","269"],["42.305","56"],["42.307","90"],["42.310","0"],["42.312","1716"],["42.319","0"],["42.320","240"]]}}
1626916409.2340019: {"stream":"btcusd_211231@depth@100ms","data":{"e":"depthUpdate","E":1626916408602,"T":1626916408496,"s":"BTCUSD_211231","ps":"BTCUSD","U":167006134343,"u":167006134347,"pu":167006133380,"b":[["31360.0","0"],["31520.0","35"],["31680.0","3"],["31840.0","0"],["32000.0","305"]],"a":[]}}
1626916409.2340312: {"stream":"bchusd_perp@depth@100ms","data":{"e":"depthUpdate","E":1626916408604,"T":1626916408591,"s":"BCHUSD_PERP","ps":"BCHUSD","U":167006134358,"u":167006134909,"pu":167006133901,"b":[["427.63","425"],["427.65","290"],["427.73","300"],["427.77","150"]],"a":[["427.79","0"],["427.88","100"]]}}
1626916409.23406: {"stream":"xrpusd_perp@depth@100ms","data":{"e":"depthUpdate","E":1626916408612,"T":1626916408584,"s":"XRPUSD_PERP","ps":"XRPUSD","U":167006134407,"u":167006134870,"pu":167006134299,"b":[["0.5635","2529"],["0.5655","5457"],["0.5658","2281"],["0.5659","3802"]],"a":[["0.5664","5452"],["0.5668","10207"]]}}
1626916409.2340841: {"stream":"linkusd_perp@depth@100ms","data":{"e":"depthUpdate","E":1626916408614,"T":1626916408607,"s":"LINKUSD_PERP","ps":"LINKUSD","U":167006134427,"u":167006134964,"pu":167006134317,"b":[["15.019","0"],["15.058","171"],["15.060","982"],["15.061","1086"]],"a":[["15.069","5100"],["15.071","659"],["15.073","338"],["15.074","401"]]}}
1626916409.234112: {"stream":"ethusd_210924@depth@100ms","data":{"e":"depthUpdate","E":1626916408620,"T":1626916408609,"s":"ETHUSD_210924","ps":"ETHUSD","U":167006134458,"u":167006134981,"pu":167006134401,"b":[["1985.46","1437"],["1987.33","0"],["1987.57","5926"],["1989.32","4729"],["1989.37","3734"],["1989.58","2241"]],"a":[["1991.56","270"],["1991.77","0"],["1992.06","1265"],["1992.07","3611"],["1993.22","384"],["1993.71","80"],["1993.91","5653"],["1994.55","627"],["1994.89","783"],["2005.93","0"],["2008.98","6813"]]}}
1626916409.23419: {"stream":"linkusd_211231@depth@100ms","data":{"e":"depthUpdate","E":1626916408655,"T":1626916408604,"s":"LINKUSD_211231","ps":"LINKUSD","U":167006134683,"u":167006134953,"pu":167006133430,"b":[["14.759","0"],["14.835","0"],["14.910","0"],["14.985","576"],["15.061","0"]],"a":[["15.324","1186"],["15.325","50"],["15.326","40"]]}}
1626916409.234247: {"stream":"eosusd_perp@depth@100ms","data":{"e":"depthUpdate","E":1626916408669,"T":1626916408651,"s":"EOSUSD_PERP","ps":"EOSUSD","U":167006134765,"u":167006135198,"pu":167006134700,"b":[["3.466","5274"],["3.468","0"]],"a":[]}}
1626916409.2342541: {"stream":"etcusd_perp@depth@100ms","data":{"e":"depthUpdate","E":1626916408681,"T":1626916408670,"s":"ETCUSD_PERP","ps":"ETCUSD","U":167006134825,"u":167006135309,"pu":167006134815,"b":[["39.544","0"],["41.973","2049"],["41.975","9450"],["42.183","480"],["42.196","0"],["42.201","15"],["42.205","126"],["42.217","0"],["42.225","22"],["42.228","0"],["42.237","428"]],"a":[["42.278","34"],["42.283","90"],["42.288","0"],["42.294","0"],["42.296","22"],["42.297","22"],["42.300","200"],["42.305","0"],["42.307","0"],["42.314","56"],["42.315","56"],["42.321","914"]]}}
1626916409.2343402: {"stream":"bchusd_210924@depth@100ms","data":{"e":"depthUpdate","E":1626916408702,"T":1626916408612,"s":"BCHUSD_210924","ps":"BCHUSD","U":167006134920,"u":167006135011,"pu":167006134476,"b":[],"a":[["429.61","0"],["429.76","2387"],["429.84","117"]]}}
1626916409.23436: {"stream":"btcusd_211231@depth@100ms","data":{"e":"depthUpdate","E":1626916408717,"T":1626916408709,"s":"BTCUSD_211231","ps":"BTCUSD","U":167006134988,"u":167006135493,"pu":167006134347,"b":[["32516.9","0"],["32517.1","1664"],["32585.9","0"]],"a":[["32623.4","17"],["32625.8","0"],["32628.4","153"],["32629.2","0"],["32631.6","0"]]}}
1626916409.234398: {"stream":"linkusd_perp@depth@100ms","data":{"e":"depthUpdate","E":1626916408717,"T":1626916408673,"s":"LINKUSD_PERP","ps":"LINKUSD","U":167006135010,"u":167006135332,"pu":167006134964,"b":[["15.031","386"],["15.040","1158"],["15.048","251"],["15.053","3479"]],"a":[["15.074","671"],["15.077","505"],["15.079","1487"],["15.081","25"]]}}
1626916409.234425: {"stream":"bchusd_perp@depth@100ms","data":{"e":"depthUpdate","E":1626916408719,"T":1626916408699,"s":"BCHUSD_PERP","ps":"BCHUSD","U":167006135020,"u":167006135462,"pu":167006134909,"b":[["426.53","0"],["427.10","5533"],["427.12","678"],["427.61","100"],["427.77","174"]],"a":[["427.81","100"],["427.88","0"],["428.23","470"],["428.71","5835"],["428.87","0"],["429.30","46"],["430.90","0"]]}}
1626916409.234466: {"stream":"trxusd_perp@depth@100ms","data":{"e":"depthUpdate","E":1626916408721,"T":1626916408695,"s":"TRXUSD_PERP","ps":"TRXUSD","U":167006135031,"u":167006135439,"pu":167006133937,"b":[["0.05341","1714"],["0.05343","1220"]],"a":[["0.05347","20987"],["0.05348","835"],["0.05349","1022"],["0.05350","2883"],["0.05351","2324"]]}}
1626916409.234503: {"stream":"xrpusd_perp@depth@100ms","data":{"e":"depthUpdate","E":1626916408732,"T":1626916408695,"s":"XRPUSD_PERP","ps":"XRPUSD","U":167006135082,"u":167006135441,"pu":167006134870,"b":[],"a":[["0.5661","670"],["0.5668","7615"]]}}
1626916409.234519: {"stream":"linkusd_211231@depth@100ms","data":{"e":"depthUpdate","E":1626916408759,"T":1626916408714,"s":"LINKUSD_211231","ps":"LINKUSD","U":167006135230,"u":167006135504,"pu":167006134953,"b":[["15.258","0"],["15.263","40"]],"a":[]}}
1626916409.234539: {"stream":"ethusd_210924@depth@100ms","data":{"e":"depthUpdate","E":1626916408761,"T":1626916408735,"s":"ETHUSD_210924","ps":"ETHUSD","U":167006135242,"u":167006135582,"pu":167006134981,"b":[["1990.59","0"],["1990.82","0"],["1990.98","1489"]],"a":[["1991.56","270"],["1991.77","0"],["1994.89","0"]]}}
1626916409.234563: {"stream":"eosusd_perp@depth@100ms","data":{"e":"depthUpdate","E":1626916408769,"T":1626916408753,"s":"EOSUSD_PERP","ps":"EOSUSD","U":167006135264,"u":167006135674,"pu":167006135198,"b":[["3.455","13176"],["3.468","0"]],"a":[["3.472","3947"],["3.476","5525"]]}}
1626916409.234571: {"stream":"etcusd_perp@depth@100ms","data":{"e":"depthUpdate","E":1626916408785,"T":1626916408760,"s":"ETCUSD_PERP","ps":"ETCUSD","U":167006135351,"u":167006135698,"pu":167006135309,"b":[["42.210","73"],["42.231","63"],["42.233","100"]],"a":[["42.328","982"],["42.333","419"],["42.729","74"],["42.761","0"],["42.768","2768"]]}}
1626916409.234643: {"stream":"btcusd_211231@depth@100ms","data":{"e":"depthUpdate","E":1626916408837,"T":1626916408767,"s":"BTCUSD_211231","ps":"BTCUSD","U":167006135579,"u":167006135734,"pu":167006135493,"b":[["32583.3","15"]],"a":[["32691.4","395"],["32707.1","0"]]}}
1626916409.234667: {"stream":"linkusd_perp@depth@100ms","data":{"e":"depthUpdate","E":1626916408843,"T":1626916408823,"s":"LINKUSD_PERP","ps":"LINKUSD","U":167006135613,"u":167006135963,"pu":167006135332,"b":[["15.050","260"]],"a":[["15.064","190"],["15.069","2186"],["15.070","7642"],["15.073","718"],["15.074","291"],["15.085","1195"],["15.086","0"],["15.175","0"],["15.261","0"]]}}
1626916409.234703: {"stream":"bchusd_perp@depth@100ms","data":{"e":"depthUpdate","E":1626916408847,"T":1626916408808,"s":"BCHUSD_PERP","ps":"BCHUSD","U":167006135635,"u":167006135906,"pu":167006135462,"b":[],"a":[["427.81","0"],["427.88","100"],["430.76","610"]]}}
1626916409.234727: {"stream":"xrpusd_perp@depth@100ms","data":{"e":"depthUpdate","E":1626916408862,"T":1626916408849,"s":"XRPUSD_PERP","ps":"XRPUSD","U":167006135695,"u":167006136064,"pu":167006135441,"b":[["0.5655","5157"],["0.5658","1946"],["0.5662","0"]],"a":[["0.5663","5826"],["0.5664","5152"],["0.5665","1974"],["0.5671","4266"],["0.5710","540"]]}}
1626916409.234764: {"stream":"eosusd_perp@depth@100ms","data":{"e":"depthUpdate","E":1626916408872,"T":1626916408817,"s":"EOSUSD_PERP","ps":"EOSUSD","U":167006135725,"u":167006135939,"pu":167006135674,"b":[["3.451","4239"],["3.464","6672"],["3.468","0"]],"a":[["3.474","6246"],["3.475","2242"],["3.478","5072"]]}}
1626916409.234771: {"stream":"etcusd_perp@depth@100ms","data":{"e":"depthUpdate","E":1626916408886,"T":1626916408879,"s":"ETCUSD_PERP","ps":"ETCUSD","U":167006135787,"u":167006136229,"pu":167006135698,"b":[["42.205","56"],["42.219","98"],["42.226","70"],["42.228","90"]],"a":[["42.260","0"],["42.264","100"],["42.300","233"],["42.321","15"]]}}
1626916409.234815: {"stream":"trxusd_perp@depth@100ms","data":{"e":"depthUpdate","E":1626916408904,"T":1626916408888,"s":"TRXUSD_PERP","ps":"TRXUSD","U":167006135862,"u":167006136268,"pu":167006135439,"b":[["0.05339","1333"],["0.05343","1220"]],"a":[["0.05348","635"],["0.05349","822"],["0.05350","3083"],["0.05351","2524"],["0.05366","1230"]]}}
1626916409.2348402: {"stream":"linkusd_211231@depth@100ms","data":{"e":"depthUpdate","E":1626916408904,"T":1626916408798,"s":"LINKUSD_211231","ps":"LINKUSD","U":167006135857,"u":167006135857,"pu":167006135504,"b":[],"a":[["15.325","0"]]}}
1626916409.2348568: {"stream":"ethusd_210924@depth@100ms","data":{"e":"depthUpdate","E":1626916408908,"T":1626916408902,"s":"ETHUSD_210924","ps":"ETHUSD","U":167006135882,"u":167006136329,"pu":167006135582,"b":[["1988.79","0"],["1988.99","8821"]],"a":[["1991.15","175"],["1991.16","500"],["1991.56","538"],["1991.59","0"],["1991.82","0"],["1991.93","400"],["1992.98","0"],["1993.32","400"],["1994.63","783"],["2010.53","0"]]}}
1626916409.234911: {"stream":"bchusd_210924@depth@100ms","data":{"e":"depthUpdate","E":1626916408913,"T":1626916408866,"s":"BCHUSD_210924","ps":"BCHUSD","U":167006135903,"u":167006136167,"pu":167006135011,"b":[["429.03","271"],["429.10","1634"],["429.11","0"]],"a":[["429.46","40"],["429.58","0"]]}}
1626916409.234947: {"stream":"linkusd_perp@depth@100ms","data":{"e":"depthUpdate","E":1626916408946,"T":1626916408941,"s":"LINKUSD_PERP","ps":"LINKUSD","U":167006136031,"u":167006136580,"pu":167006135963,"b":[],"a":[["15.066","102"],["15.073","338"],["15.074","201"],["15.076","424"],["15.077","395"],["15.095","12559"],["15.152","661"]]}}
1626916409.235033: {"stream":"btcusd_211231@depth@100ms","data":{"e":"depthUpdate","E":1626916408965,"T":1626916408927,"s":"BTCUSD_211231","ps":"BTCUSD","U":167006136120,"u":167006136496,"pu":167006135734,"b":[["32614.0","200"],["32614.1","179"]],"a":[["32625.8","153"],["32628.4","0"]]}}
1626916409.23506: {"stream":"bchusd_perp@depth@100ms","data":{"e":"depthUpdate","E":1626916408965,"T":1626916408939,"s":"BCHUSD_PERP","ps":"BCHUSD","U":167006136124,"u":167006136565,"pu":167006135906,"b":[["426.39","310"],["427.77","150"]],"a":[["429.16","310"]]}}
1626916409.235137: {"stream":"xrpusd_perp@depth@100ms","data":{"e":"depthUpdate","E":1626916408972,"T":1626916408966,"s":"XRPUSD_PERP","ps":"XRPUSD","U":167006136169,"u":167006136718,"pu":167006136064,"b":[["0.5644","27291"],["0.5648","4191"],["0.5655","5457"],["0.5658","2281"],["0.5659","2562"],["0.5660","3296"]],"a":[["0.5660","0"],["0.5662","1639"],["0.5664","5224"],["0.5665","1850"],["0.5666","2656"],["0.5671","3966"],["0.5680","26545"],["0.5686","0"]]}}
1626916409.2352362: {"stream":"etcusd_perp@depth@100ms","data":{"e":"depthUpdate","E":1626916408986,"T":1626916408975,"s":"ETCUSD_PERP","ps":"ETCUSD","U":167006136242,"u":167006136780,"pu":167006136229,"b":[["41.969","2000"],["41.973","49"],["42.162","70"],["42.171","145"],["42.183","0"],["42.216","0"],["42.220","1267"],["42.227","440"],["42.228","335"],["42.233","100"],["42.237","338"],["42.242","362"]],"a":[["42.268","200"],["42.280","300"],["42.283","90"],["42.284","0"],["42.294","331"],["42.328","782"],["42.333","619"],["42.342","70"],["42.409","1241"],["42.449","0"],["42.461","441"]]}}
1626916409.235316: {"stream":"eosusd_perp@depth@100ms","data":{"e":"depthUpdate","E":1626916408995,"T":1626916408970,"s":"EOSUSD_PERP","ps":"EOSUSD","U":167006136292,"u":167006136736,"pu":167006135939,"b":[["3.416","78"],["3.417","506"],["3.442","15756"],["3.443","6960"],["3.451","3988"],["3.452","5975"],["3.453","3141"],["3.462","4190"],["3.463","1865"],["3.464","7939"],["3.465","5091"],["3.466","4974"],["3.467","2995"],["3.468","0"]],"a":[["3.469","1206"],["3.470","3109"],["3.471","1412"],["3.472","5214"],["3.481","4954"],["3.482","3133"],["3.485","5588"],["3.486","689"],["3.492","9908"],["3.493","12121"],["3.518","5073"],["3.519","587"]]}}
1626916409.235382: {"stream":"linkusd_perp@depth@100ms","data":{"e":"depthUpdate","E":1626916409048,"T":1626916409016,"s":"LINKUSD_PERP","ps":"LINKUSD","U":167006136594,"u":167006136980,"pu":167006136580,"b":[["15.050","260"],["15.053","3479"],["15.054","0"],["15.055","0"]],"a":[["15.075","844"],["15.090","209"],["15.254","54"]]}}
1626916409.235431: {"stream":"bchusd_210924@depth@100ms","data":{"e":"depthUpdate","E":1626916409061,"T":1626916408966,"s":"BCHUSD_210924","ps":"BCHUSD","U":167006136649,"u":167006136719,"pu":167006136167,"b":[],"a":[["429.46","40"],["429.58","0"]]}}
1626916409.235446: {"stream":"ethusd_210924@depth@100ms","data":{"e":"depthUpdate","E":1626916409064,"T":1626916409045,"s":"ETHUSD_210924","ps":"ETHUSD","U":167006136685,"u":167006137109,"pu":167006136329,"b":[["1989.69","0"],["1990.12","1876"],["1990.59","270"],["1990.98","1219"]],"a":[["1992.69","12521"],["1993.13","0"],["1993.54","314"],["1993.63","80"],["1993.71","0"],["1995.60","0"],["1997.40","190"]]}}
1626916409.2354932: {"stream":"bchusd_perp@depth@100ms","data":{"e":"depthUpdate","E":1626916409071,"T":1626916409035,"s":"BCHUSD_PERP","ps":"BCHUSD","U":167006136712,"u":167006137072,"pu":167006136565,"b":[["385.11","0"],["427.77","174"]],"a":[["427.81","100"],["427.88","0"]]}}
1626916409.23552: {"stream":"xrpusd_perp@depth@100ms","data":{"e":"depthUpdate","E":1626916409073,"T":1626916409064,"s":"XRPUSD_PERP","ps":"XRPUSD","U":167006136731,"u":167006137179,"pu":167006136718,"b":[["0.5644","27401"],["0.5648","4261"],["0.5653","5552"],["0.5655","5078"],["0.5658","2648"],["0.5659","2231"],["0.5660","7311"]],"a":[["0.5660","0"],["0.5663","5592"],["0.5664","5724"],["0.5665","4267"],["0.5667","4077"],["0.5668","7533"],["0.5672","8548"],["0.5677","812"],["0.5680","26655"],["0.5700","8060"]]}}
1626916409.235574: {"stream":"btcusd_211231@depth@100ms","data":{"e":"depthUpdate","E":1626916409092,"T":1626916409085,"s":"BTCUSD_211231","ps":"BTCUSD","U":167006136833,"u":167006137304,"pu":167006136496,"b":[["31360.4","55"],["31520.4","55"],["31680.4","55"],["31840.4","55"],["32000.4","55"],["32517.0","0"],["32517.2","509"]],"a":[["32623.4","17"],["32625.7","153"],["32625.8","0"]]}}
1626916409.235638: {"stream":"etcusd_perp@depth@100ms","data":{"e":"depthUpdate","E":1626916409094,"T":1626916409087,"s":"ETCUSD_PERP","ps":"ETCUSD","U":167006136845,"u":167006137305,"pu":167006136780,"b":[["41.969","0"],["42.170","70"],["42.197","0"],["42.220","1467"],["42.228","245"],["42.232","1064"],["42.233","500"],["42.237","428"]],"a":[["42.280","0"],["42.283","0"],["42.294","421"]]}}
1626916409.23568: {"stream":"eosusd_perp@depth@100ms","data":{"e":"depthUpdate","E":1626916409098,"T":1626916409068,"s":"EOSUSD_PERP","ps":"EOSUSD","U":167006136864,"u":167006137205,"pu":167006136736,"b":[["3.464","6741"],["3.465","7023"],["3.467","3095"],["3.468","0"]],"a":[["3.472","6226"],["3.474","4775"],["3.476","3984"],["3.478","6614"]]}}
1626916409.2357: {"stream":"trxusd_perp@depth@100ms","data":{"e":"depthUpdate","E":1626916409102,"T":1626916409087,"s":"TRXUSD_PERP","ps":"TRXUSD","U":167006136888,"u":167006137307,"pu":167006136268,"b":[["0.05338","2046"],["0.05339","1333"],["0.05340","3212"],["0.05342","613"],["0.05343","1140"]],"a":[["0.05347","20642"],["0.05348","635"],["0.05349","522"],["0.05350","2883"],["0.05351","2724"],["0.05352","1567"],["0.05354","1293"],["0.05355","1249"],["0.05356","829"]]}}
1626916409.2357671: {"stream":"linkusd_211231@depth@100ms","data":{"e":"depthUpdate","E":1626916409156,"T":1626916409151,"s":"LINKUSD_211231","ps":"LINKUSD","U":167006137139,"u":167006137550,"pu":167006135857,"b":[],"a":[["15.522","0"],["15.525","164"],["15.597","0"],["15.600","203"],["15.672","0"],["15.675","166"],["15.748","0"],["15.751","167"],["15.823","0"],["15.826","168"]]}}
1626916409.2358139: {"stream":"linkusd_perp@depth@100ms","data":{"e":"depthUpdate","E":1626916409156,"T":1626916409078,"s":"LINKUSD_PERP","ps":"LINKUSD","U":167006137146,"u":167006137268,"pu":167006136980,"b":[["15.050","460"],["15.053","3279"]],"a":[["15.069","1886"],["15.071","959"],["15.074","581"],["15.075","464"]]}}
1626916409.235847: {"stream":"ethusd_210924@depth@100ms","data":{"e":"depthUpdate","E":1626916409174,"T":1626916409163,"s":"ETHUSD_210924","ps":"ETHUSD","U":167006137245,"u":167006137622,"pu":167006137109,"b":[["1990.59","0"],["1990.82","0"],["1990.98","1489"]],"a":[["1991.56","268"],["1991.77","270"]]}}
1626916409.235873: {"stream":"xrpusd_perp@depth@100ms","data":{"e":"depthUpdate","E":1626916409191,"T":1626916409170,"s":"XRPUSD_PERP","ps":"XRPUSD","U":167006137297,"u":167006137660,"pu":167006137179,"b":[["0.5644","27049"],["0.5645","4547"],["0.5651","5339"],["0.5652","7997"],["0.5656","7468"],["0.5657","5771"],["0.5658","2313"],["0.5659","2196"],["0.5660","7376"]],"a":[["0.5662","1479"],["0.5663","5557"],["0.5664","5919"],["0.5666","652"],["0.5667","6172"],["0.5671","3691"],["0.5672","8823"]]}}
1626916409.235913: {"stream":"btcusd_211231@depth@100ms","data":{"e":"depthUpdate","E":1626916409193,"T":1626916409160,"s":"BTCUSD_211231","ps":"BTCUSD","U":167006137312,"u":167006137606,"pu":167006137304,"b":[["32583.3","0"]],"a":[["32623.4","17"],["32625.6","153"],["32625.7","0"],["33027.1","0"],["33187.1","0"],["33347.1","0"],["33507.1","0"],["33667.1","0"]]}}
1626916409.235959: {"stream":"etcusd_perp@depth@100ms","data":{"e":"depthUpdate","E":1626916409194,"T":1626916409188,"s":"ETCUSD_PERP","ps":"ETCUSD","U":167006137319,"u":167006137734,"pu":167006137305,"b":[["41.972","2002"],["42.204","323"],["42.213","1626"],["42.220","1267"]],"a":[["42.280","0"],["42.281","220"],["42.285","263"],["42.293","0"],["42.294","331"],["42.295","0"],["42.318","322"],["42.331","1012"],["42.333","419"],["42.342","270"],["42.616","0"],["42.628","560"]]}}
1626916409.2360198: {"stream":"eosusd_perp@depth@100ms","data":{"e":"depthUpdate","E":1626916409198,"T":1626916409154,"s":"EOSUSD_PERP","ps":"EOSUSD","U":167006137324,"u":167006137581,"pu":167006137205,"b":[["3.468","0"]],"a":[["3.469","1606"],["3.472","6176"],["3.473","2387"]]}}
1626916409.236028: {"stream":"trxusd_perp@depth@100ms","data":{"e":"depthUpdate","E":1626916409204,"T":1626916409198,"s":"TRXUSD_PERP","ps":"TRXUSD","U":167006137341,"u":167006137785,"pu":167006137307,"b":[["0.05340","3292"],["0.05342","533"]],"a":[["0.05347","20542"],["0.05348","535"],["0.05350","3083"],["0.05351","2924"],["0.05392","0"]]}}
1626916409.236067: {"stream":"bchusd_210924@depth@100ms","data":{"e":"depthUpdate","E":1626916409214,"T":1626916409119,"s":"BCHUSD_210924","ps":"BCHUSD","U":167006137386,"u":167006137402,"pu":167006136719,"b":[["428.94","3406"],["429.02","0"]],"a":[]}}
1626916409.236087: {"stream":"bchusd_perp@depth@100ms","data":{"e":"depthUpdate","E":1626916409216,"T":1626916409200,"s":"BCHUSD_PERP","ps":"BCHUSD","U":167006137388,"u":167006137805,"pu":167006137072,"b":[["427.47","492"],["427.48","3009"],["427.56","1036"]],"a":[["427.81","100"],["427.88","0"]]}}
1626916409.251965: {"stream":"ethusd_210924@depth@100ms","data":{"e":"depthUpdate","E":1626916409277,"T":1626916409263,"s":"ETHUSD_210924","ps":"ETHUSD","U":167006137663,"u":167006138181,"pu":167006137622,"b":[["1987.72","0"],["1989.32","0"],["1989.38","4595"],["1990.59","50"]],"a":[["1991.55","270"],["1991.77","0"],["1992.68","652"],["1996.63","10"]]}}
1626916409.267168: {"stream":"xrpusd_perp@depth@100ms","data":{"e":"depthUpdate","E":1626916409293,"T":1626916409256,"s":"XRPUSD_PERP","ps":"XRPUSD","U":167006137741,"u":167006138139,"pu":167006137660,"b":[["0.5655","4972"],["0.5656","7574"],["0.5657","5729"],["0.5658","2355"],["0.5659","1523"],["0.5660","5485"],["0.5661","2486"]],"a":[["0.5661","0"],["0.5662","1742"]]}}
1626916409.2695081: {"stream":"etcusd_perp@depth@100ms","data":{"e":"depthUpdate","E":1626916409296,"T":1626916409291,"s":"ETCUSD_PERP","ps":"ETCUSD","U":167006137758,"u":167006138361,"pu":167006137734,"b":[["42.039","41"],["42.053","336"]],"a":[["42.264","0"],["42.265","100"],["42.268","0"],["42.277","0"],["42.278","0"],["42.279","1541"],["42.281","130"],["42.284","90"],["42.285","0"],["42.293","0"],["42.300","200"],["42.304","0"],["42.336","225"],["42.342","0"],["42.354","0"],["42.363","290"]]}}
1626916409.269846: {"stream":"btcusd_211231@depth@100ms","data":{"e":"depthUpdate","E":1626916409298,"T":1626916409290,"s":"BTCUSD_211231","ps":"BTCUSD","U":167006137761,"u":167006138359,"pu":167006137606,"b":[["31360.4","0"],["31520.4","0"],["31680.4","0"],["31840.4","0"],["32000.4","0"],["32589.0","15"]],"a":[["32625.6","0"],["32625.8","0"],["32628.4","153"],["32638.6","0"]]}}
1626916409.272806: {"stream":"eosusd_perp@depth@100ms","data":{"e":"depthUpdate","E":1626916409300,"T":1626916409291,"s":"EOSUSD_PERP","ps":"EOSUSD","U":167006137776,"u":167006138370,"pu":167006137581,"b":[["3.464","8503"],["3.465","5091"],["3.467","3991"],["3.468","0"]],"a":[["3.470","3159"],["3.471","3552"],["3.472","6176"]]}}
1626916409.2776499: {"stream":"trxusd_perp@depth@100ms","data":{"e":"depthUpdate","E":1626916409304,"T":1626916409277,"s":"TRXUSD_PERP","ps":"TRXUSD","U":167006137802,"u":167006138276,"pu":167006137785,"b":[["0.05340","3212"],["0.05341","1714"],["0.05343","1220"]],"a":[["0.05350","3283"],["0.05351","2724"],["0.05352","1167"],["0.05394","320"]]}}
1626916409.291109: {"stream":"bchusd_perp@depth@100ms","data":{"e":"depthUpdate","E":1626916409318,"T":1626916409214,"s":"BCHUSD_PERP","ps":"BCHUSD","U":167006137890,"u":167006137891,"pu":167006137805,"b":[["427.55","117"],["427.61","0"]],"a":[]}}
1626916409.291753: {"stream":"bchusd_210924@depth@100ms","data":{"e":"depthUpdate","E":1626916409318,"T":1626916409270,"s":"BCHUSD_210924","ps":"BCHUSD","U":167006137886,"u":167006138210,"pu":167006137402,"b":[["429.11","0"],["429.23","40"]],"a":[]}}
1626916409.369626: {"stream":"etcusd_perp@depth@100ms","data":{"e":"depthUpdate","E":1626916409396,"T":1626916409392,"s":"ETCUSD_PERP","ps":"ETCUSD","U":167006138377,"u":167006138876,"pu":167006138361,"b":[["41.754","0"],["42.233","590"],["42.237","338"],["42.241","341"],["42.243","0"],["42.244","300"]],"a":[["42.310","33"],["42.326","902"],["42.331","110"],["42.768","0"]]}}
1626916409.37216: {"stream":"xrpusd_perp@depth@100ms","data":{"e":"depthUpdate","E":1626916409400,"T":1626916409368,"s":"XRPUSD_PERP","ps":"XRPUSD","U":167006138383,"u":167006138763,"pu":167006138139,"b":[["0.5598","1076"],["0.5640","6131"],["0.5652","1091"],["0.5653","12458"]],"a":[]}}
1626916409.372311: {"stream":"btcusd_211231@depth@100ms","data":{"e":"depthUpdate","E":1626916409400,"T":1626916409363,"s":"BTCUSD_211231","ps":"BTCUSD","U":167006138408,"u":167006138733,"pu":167006138359,"b":[["31915.5","0"],["32517.2","0"],["32526.7","546"],["32612.1","196"]],"a":[["32625.8","153"],["32628.4","0"],["33027.1","45"],["33187.1","45"],["33347.1","45"],["33507.1","46"],["33667.2","46"]]}}
1626916409.394776: {"stream":"eosusd_perp@depth@100ms","data":{"e":"depthUpdate","E":1626916409422,"T":1626916409407,"s":"EOSUSD_PERP","ps":"EOSUSD","U":167006138527,"u":167006138946,"pu":167006138370,"b":[["3.466","5144"],["3.468","0"]],"a":[["3.470","2788"],["3.471","4015"]]}}
1626916409.4087381: {"stream":"bchusd_perp@depth@100ms","data":{"e":"depthUpdate","E":1626916409437,"T":1626916409366,"s":"BCHUSD_PERP","ps":"BCHUSD","U":167006138598,"u":167006138756,"pu":167006137891,"b":[["427.55","17"],["427.61","100"]],"a":[["427.81","100"],["427.88","0"]]}}
1626916409.4307609: {"stream":"ethusd_210924@depth@100ms","data":{"e":"depthUpdate","E":1626916409454,"T":1626916409399,"s":"ETHUSD_210924","ps":"ETHUSD","U":167006138658,"u":167006138917,"pu":167006138181,"b":[["1990.45","460"]],"a":[["1991.15","0"],["1991.16","0"],["1991.55","270"],["1991.56","349"],["1991.77","0"]]}}
1626916409.4754639: {"stream":"btcusd_211231@depth@100ms","data":{"e":"depthUpdate","E":1626916409502,"T":1626916409492,"s":"BTCUSD_211231","ps":"BTCUSD","U":167006138901,"u":167006139323,"pu":167006138733,"b":[],"a":[["32625.7","0"],["32625.8","0"],["32628.4","153"]]}}
1626916409.478713: {"stream":"trxusd_perp@depth@100ms","data":{"e":"depthUpdate","E":1626916409506,"T":1626916409400,"s":"TRXUSD_PERP","ps":"TRXUSD","U":167006138921,"u":167006138923,"pu":167006138276,"b":[["0.05341","1794"],["0.05343","1140"]],"a":[]}}
1626916409.483677: {"stream":"xrpusd_perp@depth@100ms","data":{"e":"depthUpdate","E":1626916409511,"T":1626916409500,"s":"XRPUSD_PERP","ps":"XRPUSD","U":167006138957,"u":167006139360,"pu":167006138763,"b":[["0.5651","3051"],["0.5656","9209"],["0.5660","5150"],["0.5661","2821"]],"a":[["0.5662","1972"],["0.5694","0"],["0.5701","1099"],["0.5705","24418"],["0.5721","6918"]]}}
1626916409.483886: {"stream":"bchusd_210924@depth@100ms","data":{"e":"depthUpdate","E":1626916409510,"T":1626916409416,"s":"BCHUSD_210924","ps":"BCHUSD","U":167006138935,"u":167006139008,"pu":167006138210,"b":[["429.11","0"],["429.23","40"]],"a":[]}}
1626916409.4911659: {"stream":"linkusd_211231@depth@100ms","data":{"e":"depthUpdate","E":1626916409519,"T":1626916409468,"s":"LINKUSD_211231","ps":"LINKUSD","U":167006139001,"u":167006139246,"pu":167006137550,"b":[],"a":[["15.323","1655"],["15.324","100"],["15.330","0"]]}}
1626916409.51262: {"stream":"linkusd_perp@depth@100ms","data":{"e":"depthUpdate","E":1626916409539,"T":1626916409475,"s":"LINKUSD_PERP","ps":"LINKUSD","U":167006139090,"u":167006139260,"pu":167006137268,"b":[["15.051","1738"],["15.052","1839"],["15.054","0"],["15.061","1086"]],"a":[["15.070","6704"]]}}
1626916409.54578: {"stream":"bchusd_perp@depth@100ms","data":{"e":"depthUpdate","E":1626916409571,"T":1626916409535,"s":"BCHUSD_PERP","ps":"BCHUSD","U":167006139224,"u":167006139483,"pu":167006138756,"b":[],"a":[["427.81","100"],["427.88","0"],["428.31","247"],["428.41","0"],["428.52","719"],["428.77","0"]]}}
1626916409.546008: {"stream":"etcusd_perp@depth@100ms","data":{"e":"depthUpdate","E":1626916409573,"T":1626916409548,"s":"ETCUSD_PERP","ps":"ETCUSD","U":167006139238,"u":167006139514,"pu":167006138876,"b":[["42.232","90"],["42.233","1585"],["42.240","33"],["42.242","362"]],"a":[["42.303","0"],["42.307","244"],["42.320","0"],["42.347","493"]]}}
1626916409.551913: {"stream":"eosusd_perp@depth@100ms","data":{"e":"depthUpdate","E":1626916409579,"T":1626916409568,"s":"EOSUSD_PERP","ps":"EOSUSD","U":167006139254,"u":167006139608,"pu":167006138946,"b":[["3.462","4242"],["3.467","2851"],["3.468","0"]],"a":[["3.468","210"],["3.470","2708"],["3.476","3946"],["3.478","6652"]]}}
1626916409.586224: {"stream":"btcusd_211231@depth@100ms","data":{"e":"depthUpdate","E":1626916409614,"T":1626916409569,"s":"BTCUSD_211231","ps":"BTCUSD","U":167006139394,"u":167006139617,"pu":167006139323,"b":[["31867.5","318"]],"a":[["32625.8","0"],["32628.4","153"]]}}
1626916409.58917: {"stream":"xrpusd_perp@depth@100ms","data":{"e":"depthUpdate","E":1626916409616,"T":1626916409606,"s":"XRPUSD_PERP","ps":"XRPUSD","U":167006139400,"u":167006139771,"pu":167006139360,"b":[["0.5660","5120"],["0.5661","2851"]],"a":[["0.5662","2472"],["0.5663","4557"],["0.5688","7949"]]}}
1626916409.5892658: {"stream":"trxusd_perp@depth@100ms","data":{"e":"depthUpdate","E":1626916409617,"T":1626916409511,"s":"TRXUSD_PERP","ps":"TRXUSD","U":167006139401,"u":167006139403,"pu":167006138923,"b":[["0.05341","1714"],["0.05343","1220"]],"a":[]}}
1626916409.591321: {"stream":"ethusd_210924@depth@100ms","data":{"e":"depthUpdate","E":1626916409618,"T":1626916409585,"s":"ETHUSD_210924","ps":"ETHUSD","U":167006139408,"u":167006139686,"pu":167006138917,"b":[["1987.20","901"],["1988.99","0"],["1989.04","8545"]],"a":[["1995.90","190"],["1997.40","0"]]}}
1626916409.6382442: {"stream":"linkusd_perp@depth@100ms","data":{"e":"depthUpdate","E":1626916409664,"T":1626916409648,"s":"LINKUSD_PERP","ps":"LINKUSD","U":167006139571,"u":167006139998,"pu":167006139260,"b":[["15.039","254"],["15.048","451"],["15.052","1459"],["15.053","3659"],["15.055","152"],["15.059","0"],["15.061","1166"]],"a":[["15.062","1"],["15.070","6675"],["15.072","491"],["15.074","507"],["15.076","498"],["15.087","286"],["15.104","15404"]]}}
1626916409.657473: {"stream":"eosusd_perp@depth@100ms","data":{"e":"depthUpdate","E":1626916409679,"T":1626916409655,"s":"EOSUSD_PERP","ps":"EOSUSD","U":167006139633,"u":167006140038,"pu":167006139608,"b":[["3.456","1254"],["3.468","0"]],"a":[]}}
1626916409.670756: {"stream":"linkusd_211231@depth@100ms","data":{"e":"depthUpdate","E":1626916409699,"T":1626916409651,"s":"LINKUSD_211231","ps":"LINKUSD","U":167006139715,"u":167006140014,"pu":167006139246,"b":[["15.292","150"],["15.307","80"]],"a":[["15.328","150"]]}}
1626916409.6739242: {"stream":"bchusd_perp@depth@100ms","data":{"e":"depthUpdate","E":1626916409701,"T":1626916409679,"s":"BCHUSD_PERP","ps":"BCHUSD","U":167006139723,"u":167006140184,"pu":167006139483,"b":[["427.17","622"],["427.40","1028"],["427.77","150"]],"a":[]}}
1626916409.689218: {"stream":"xrpusd_perp@depth@100ms","data":{"e":"depthUpdate","E":1626916409716,"T":1626916409704,"s":"XRPUSD_PERP","ps":"XRPUSD","U":167006139782,"u":167006140315,"pu":167006139771,"b":[["0.5642","1720"],["0.5643","1595"],["0.5650","6183"],["0.5653","12058"],["0.5656","9094"],["0.5658","1970"],["0.5659","1069"],["0.5660","5776"],["0.5661","3892"]],"a":[["0.5662","2421"],["0.5663","4257"],["0.5664","5775"],["0.5665","4225"],["0.5666","854"],["0.5667","6066"],["0.5681","3257"],["0.5702","6521"],["0.5706","5278"]]}}
1626916409.6894562: {"stream":"etcusd_perp@depth@100ms","data":{"e":"depthUpdate","E":1626916409718,"T":1626916409699,"s":"ETCUSD_PERP","ps":"ETCUSD","U":167006139801,"u":167006140284,"pu":167006139514,"b":[["42.140","266"],["42.232","0"],["42.241","431"],["42.244","0"],["42.245","240"]],"a":[["42.311","840"],["42.326","0"]]}}
1626916409.710216: {"stream":"ethusd_210924@depth@100ms","data":{"e":"depthUpdate","E":1626916409737,"T":1626916409729,"s":"ETHUSD_210924","ps":"ETHUSD","U":167006139886,"u":167006140422,"pu":167006139686,"b":[["1986.53","1000"],["1987.29","0"],["1987.70","80"],["1989.81","0"],["1990.22","50"],["1990.60","0"],["1990.82","0"],["1990.98","1489"]],"a":[["1991.54","270"],["1991.55","0"],["1991.77","0"],["1991.93","0"],["1992.86","568"],["1992.93","405"],["1992.99","400"],["1993.32","0"],["1994.63","0"],["1995.15","0"],["1995.44","1000"]]}}
1626916409.731361: {"stream":"trxusd_perp@depth@100ms","data":{"e":"depthUpdate","E":1626916409758,"T":1626916409748,"s":"TRXUSD_PERP","ps":"TRXUSD","U":167006140023,"u":167006140489,"pu":167006139403,"b":[["0.05337","1475"],["0.05339","1413"],["0.05343","1140"]],"a":[["0.05348","835"],["0.05349","822"],["0.05350","2883"],["0.05351","2324"],["0.05352","1167"],["0.05355","1249"],["0.05356","829"],["0.05358","1138"],["0.05359","306"],["0.05366","982"]]}}
