wss://stream.binance.com:9443/stream?streams=swrvbusd@aggTrade/veteth@aggTrade/gtobtc@aggTrade/busdtry@aggTrade/qspbtc@aggTrade/adarub@aggTrade/perlbnb@aggTrade/aaveupusdt@aggTrade/onttry@aggTrade/steemeth@aggTrade/swrvbusd@kline_1m/veteth@kline_1m/gtobtc@kline_1m/busdtry@kline_1m/qspbtc@kline_1m/adarub@kline_1m/perlbnb@kline_1m/aaveupusdt@kline_1m/onttry@kline_1m/steemeth@kline_1m/swrvbusd@depth@100ms/veteth@depth@100ms/gtobtc@depth@100ms/busdtry@depth@100ms/qspbtc@depth@100ms/adarub@depth@100ms/perlbnb@depth@100ms/aaveupusdt@depth@100ms/onttry@depth@100ms/steemeth@depth@100ms/swrvbusd@bookTicker/veteth@bookTicker/gtobtc@bookTicker/busdtry@bookTicker/qspbtc@bookTicker/adarub@bookTicker/perlbnb@bookTicker/aaveupusdt@bookTicker/onttry@bookTicker/steemeth@bookTicker <-> 1618677371.364407
1618677372.1768699: {"stream":"busdtry@depth@100ms","data":{"e":"depthUpdate","E":1618677372122,"s":"BUSDTRY","U":10166139,"u":10166139,"b":[],"a":[["8.14000000","107821.20000000"]]}}
1618677372.5104241: {"stream":"swrvbusd@bookTicker","data":{"u":64830107,"s":"SWRVBUSD","b":"2.27200000","B":"218.40800000","a":"2.27700000","A":"1.19200000"}}
1618677372.510464: {"stream":"swrvbusd@bookTicker","data":{"u":64830110,"s":"SWRVBUSD","b":"2.27200000","B":"218.40800000","a":"2.27600000","A":"42.41700000"}}
1618677372.510485: {"stream":"swrvbusd@depth@100ms","data":{"e":"depthUpdate","E":1618677372222,"s":"SWRVBUSD","U":64830106,"u":64830110,"b":[["2.27000000","95.46200000"],["2.26800000","127.44300000"],["2.26500000","0.00000000"],["2.26400000","319.69100000"]],"a":[["2.27600000","42.41700000"]]}}
1618677372.719688: {"stream":"veteth@bookTicker","data":{"u":327912856,"s":"VETETH","b":"0.00009381","B":"95017.00000000","a":"0.00009401","A":"88406.00000000"}}
1618677372.719716: {"stream":"veteth@depth@100ms","data":{"e":"depthUpdate","E":1618677372321,"s":"VETETH","U":327912855,"u":327912858,"b":[["0.00009381","95017.00000000"],["0.00009374","0.00000000"],["0.00009372","0.00000000"]],"a":[]}}
1618677372.9304278: {"stream":"swrvbusd@depth@100ms","data":{"e":"depthUpdate","E":1618677372322,"s":"SWRVBUSD","U":64830111,"u":64830111,"b":[["2.27100000","166.33400000"]],"a":[]}}
1618677372.930447: {"stream":"veteth@bookTicker","data":{"u":327912859,"s":"VETETH","b":"0.00009380","B":"4016.00000000","a":"0.00009401","A":"88406.00000000"}}
1618677372.9304671: {"stream":"veteth@depth@100ms","data":{"e":"depthUpdate","E":1618677372421,"s":"VETETH","U":327912859,"u":327912864,"b":[["0.00009381","0.00000000"],["0.00009372","95017.00000000"]],"a":[]}}
1618677372.930478: {"stream":"veteth@depth@100ms","data":{"e":"depthUpdate","E":1618677372521,"s":"VETETH","U":327912865,"u":327912866,"b":[["0.00009373","95017.00000000"],["0.00009372","0.00000000"]],"a":[]}}
1618677372.930486: {"stream":"qspbtc@depth@100ms","data":{"e":"depthUpdate","E":1618677372522,"s":"QSPBTC","U":105811205,"u":105811205,"b":[["0.00000158","24324.00000000"]],"a":[]}}
1618677373.130495: {"stream":"aaveupusdt@depth@100ms","data":{"e":"depthUpdate","E":1618677372522,"s":"AAVEUPUSDT","U":82463711,"u":82463716,"b":[["84.39200000","0.00000000"],["84.23900000","9.90000000"],["84.11800000","0.74000000"],["83.66400000","0.27000000"]],"a":[["85.40400000","0.00000000"],["85.49900000","2.57000000"]]}}
1618677373.661197: {"stream":"veteth@bookTicker","data":{"u":327912869,"s":"VETETH","b":"0.00009381","B":"95017.00000000","a":"0.00009401","A":"88406.00000000"}}
1618677373.6612291: {"stream":"aaveupusdt@bookTicker","data":{"u":82463718,"s":"AAVEUPUSDT","b":"84.39100000","B":"11.85000000","a":"84.69900000","A":"0.39000000"}}
1618677373.661246: {"stream":"aaveupusdt@bookTicker","data":{"u":82463719,"s":"AAVEUPUSDT","b":"84.39200000","B":"0.25000000","a":"84.69900000","A":"0.39000000"}}
1618677373.661258: {"stream":"veteth@depth@100ms","data":{"e":"depthUpdate","E":1618677372621,"s":"VETETH","U":327912867,"u":327912869,"b":[["0.00009381","95017.00000000"],["0.00009373","0.00000000"],["0.00008086","0.00000000"]],"a":[]}}
1618677373.661271: {"stream":"aaveupusdt@depth@100ms","data":{"e":"depthUpdate","E":1618677372622,"s":"AAVEUPUSDT","U":82463717,"u":82463719,"b":[["84.39300000","0.00000000"],["84.39200000","0.25000000"]],"a":[["85.49900000","0.00000000"]]}}
1618677373.661282: {"stream":"aaveupusdt@depth@100ms","data":{"e":"depthUpdate","E":1618677372722,"s":"AAVEUPUSDT","U":82463720,"u":82463720,"b":[["83.91100000","121.07000000"]],"a":[]}}
1618677373.6612911: {"stream":"aaveupusdt@bookTicker","data":{"u":82463721,"s":"AAVEUPUSDT","b":"84.39400000","B":"0.17000000","a":"84.69900000","A":"0.39000000"}}
1618677373.661303: {"stream":"swrvbusd@bookTicker","data":{"u":64830113,"s":"SWRVBUSD","b":"2.27200000","B":"218.40800000","a":"2.27700000","A":"1.19200000"}}
1618677373.661314: {"stream":"aaveupusdt@bookTicker","data":{"u":82463723,"s":"AAVEUPUSDT","b":"84.39500000","B":"0.25000000","a":"84.69900000","A":"0.39000000"}}
1618677373.661325: {"stream":"veteth@depth@100ms","data":{"e":"depthUpdate","E":1618677372822,"s":"VETETH","U":327912870,"u":327912870,"b":[],"a":[["0.00009963","992.00000000"]]}}
1618677373.661334: {"stream":"swrvbusd@depth@100ms","data":{"e":"depthUpdate","E":1618677372822,"s":"SWRVBUSD","U":64830112,"u":64830113,"b":[["2.19000000","114.15500000"]],"a":[["2.27600000","0.00000000"]]}}
1618677373.661397: {"stream":"aaveupusdt@depth@100ms","data":{"e":"depthUpdate","E":1618677372822,"s":"AAVEUPUSDT","U":82463721,"u":82463723,"b":[["84.39500000","0.25000000"],["84.39400000","0.17000000"],["84.39200000","0.00000000"]],"a":[]}}
1618677373.6614091: {"stream":"swrvbusd@bookTicker","data":{"u":64830114,"s":"SWRVBUSD","b":"2.27200000","B":"218.40800000","a":"2.27600000","A":"42.41700000"}}
1618677373.661421: {"stream":"swrvbusd@depth@100ms","data":{"e":"depthUpdate","E":1618677372922,"s":"SWRVBUSD","U":64830114,"u":64830114,"b":[],"a":[["2.27600000","42.41700000"]]}}
1618677373.661449: {"stream":"veteth@depth@100ms","data":{"e":"depthUpdate","E":1618677373022,"s":"VETETH","U":327912871,"u":327912872,"b":[["0.00009353","296.00000000"]],"a":[["0.00009415","2680.00000000"]]}}
1618677373.6614752: {"stream":"swrvbusd@depth@100ms","data":{"e":"depthUpdate","E":1618677373022,"s":"SWRVBUSD","U":64830115,"u":64830115,"b":[["2.19700000","201.36300000"]],"a":[]}}
1618677373.661495: {"stream":"veteth@depth@100ms","data":{"e":"depthUpdate","E":1618677373122,"s":"VETETH","U":327912873,"u":327912875,"b":[["0.00008111","38038.00000000"]],"a":[["0.00009402","0.00000000"],["0.00009962","251.00000000"]]}}
1618677373.661535: {"stream":"veteth@bookTicker","data":{"u":327912876,"s":"VETETH","b":"0.00009381","B":"95017.00000000","a":"0.00009404","A":"9006.00000000"}}
1618677373.6615481: {"stream":"veteth@bookTicker","data":{"u":327912877,"s":"VETETH","b":"0.00009381","B":"95017.00000000","a":"0.00009403","A":"88406.00000000"}}
1618677373.661559: {"stream":"veteth@depth@100ms","data":{"e":"depthUpdate","E":1618677373222,"s":"VETETH","U":327912876,"u":327912877,"b":[],"a":[["0.00009401","0.00000000"],["0.00009403","88406.00000000"]]}}
1618677373.661591: {"stream":"swrvbusd@bookTicker","data":{"u":64830117,"s":"SWRVBUSD","b":"2.27200000","B":"218.40800000","a":"2.27700000","A":"1.19200000"}}
1618677373.6616042: {"stream":"swrvbusd@bookTicker","data":{"u":64830121,"s":"SWRVBUSD","b":"2.27200000","B":"218.40800000","a":"2.27600000","A":"42.41700000"}}
1618677373.6616142: {"stream":"veteth@depth@100ms","data":{"e":"depthUpdate","E":1618677373422,"s":"VETETH","U":327912878,"u":327912878,"b":[["0.00009271","547.00000000"]],"a":[]}}
1618677373.661634: {"stream":"swrvbusd@depth@100ms","data":{"e":"depthUpdate","E":1618677373422,"s":"SWRVBUSD","U":64830116,"u":64830121,"b":[["2.27100000","166.34100000"],["2.26900000","182.20000000"],["2.26800000","127.45100000"]],"a":[["2.27600000","42.41700000"]]}}
1618677373.661669: {"stream":"veteth@depth@100ms","data":{"e":"depthUpdate","E":1618677373522,"s":"VETETH","U":327912879,"u":327912879,"b":[["0.00009272","76304.00000000"]],"a":[]}}
1618677373.661689: {"stream":"aaveupusdt@depth@100ms","data":{"e":"depthUpdate","E":1618677373522,"s":"AAVEUPUSDT","U":82463724,"u":82463724,"b":[],"a":[["85.40400000","2.57000000"]]}}
1618677373.677193: {"stream":"aaveupusdt@bookTicker","data":{"u":82463727,"s":"AAVEUPUSDT","b":"84.39200000","B":"0.25000000","a":"84.69900000","A":"0.39000000"}}
1618677373.6821718: {"stream":"aaveupusdt@depth@100ms","data":{"e":"depthUpdate","E":1618677373622,"s":"AAVEUPUSDT","U":82463725,"u":82463727,"b":[["84.39500000","0.00000000"],["84.39400000","0.00000000"],["84.39200000","0.25000000"]],"a":[]}}
1618677374.0321941: {"stream":"swrvbusd@kline_1m","data":{"e":"kline","E":1618677373907,"s":"SWRVBUSD","k":{"t":1618677360000,"T":1618677419999,"s":"SWRVBUSD","i":"1m","f":1135631,"L":1135631,"o":"2.27700000","c":"2.27700000","h":"2.27700000","l":"2.27700000","v":"9.82600000","n":1,"x":false,"q":"22.37380200","V":"0.00000000","Q":"0.00000000","B":"0"}}}
1618677374.032321: {"stream":"swrvbusd@bookTicker","data":{"u":64830123,"s":"SWRVBUSD","b":"2.27200000","B":"218.40800000","a":"2.27600000","A":"20.45400000"}}
1618677374.032366: {"stream":"swrvbusd@aggTrade","data":{"e":"aggTrade","E":1618677373913,"s":"SWRVBUSD","a":749094,"p":"2.27600000","q":"21.96300000","f":1135632,"l":1135632,"T":1618677373912,"m":false,"M":true}}
1618677374.0323951: {"stream":"swrvbusd@bookTicker","data":{"u":64830124,"s":"SWRVBUSD","b":"2.27200000","B":"218.40800000","a":"2.27700000","A":"1.19200000"}}
1618677374.032413: {"stream":"swrvbusd@depth@100ms","data":{"e":"depthUpdate","E":1618677373922,"s":"SWRVBUSD","U":64830122,"u":64830124,"b":[["2.15300000","0.00000000"]],"a":[["2.27600000","0.00000000"]]}}
1618677374.041881: {"stream":"swrvbusd@bookTicker","data":{"u":64830125,"s":"SWRVBUSD","b":"2.27300000","B":"21.99200000","a":"2.27700000","A":"1.19200000"}}
1618677374.041963: {"stream":"swrvbusd@bookTicker","data":{"u":64830126,"s":"SWRVBUSD","b":"2.27300000","B":"21.99200000","a":"2.27600000","A":"20.45400000"}}
1618677374.083061: {"stream":"veteth@depth@100ms","data":{"e":"depthUpdate","E":1618677374022,"s":"VETETH","U":327912880,"u":327912880,"b":[["0.00009355","2064.00000000"]],"a":[]}}
1618677374.083214: {"stream":"swrvbusd@depth@100ms","data":{"e":"depthUpdate","E":1618677374022,"s":"SWRVBUSD","U":64830125,"u":64830126,"b":[["2.27300000","21.99200000"]],"a":[["2.27600000","20.45400000"]]}}
1618677374.1837702: {"stream":"aaveupusdt@depth@100ms","data":{"e":"depthUpdate","E":1618677374123,"s":"AAVEUPUSDT","U":82463728,"u":82463728,"b":[["83.95700000","0.00000000"]],"a":[]}}
1618677374.20286: {"stream":"veteth@bookTicker","data":{"u":327912881,"s":"VETETH","b":"0.00009381","B":"95017.00000000","a":"0.00009402","A":"20330.00000000"}}
1618677374.232706: {"stream":"veteth@bookTicker","data":{"u":327912883,"s":"VETETH","b":"0.00009381","B":"95017.00000000","a":"0.00009401","A":"88406.00000000"}}
1618677374.277387: {"stream":"veteth@depth@100ms","data":{"e":"depthUpdate","E":1618677374222,"s":"VETETH","U":327912881,"u":327912885,"b":[["0.00009352","0.00000000"],["0.00009350","142391.00000000"]],"a":[["0.00009401","88406.00000000"],["0.00009402","20330.00000000"],["0.00009403","0.00000000"]]}}
1618677374.277608: {"stream":"swrvbusd@depth@100ms","data":{"e":"depthUpdate","E":1618677374222,"s":"SWRVBUSD","U":64830127,"u":64830127,"b":[["2.16900000","22650.29100000"]],"a":[]}}
1618677374.377533: {"stream":"swrvbusd@depth@100ms","data":{"e":"depthUpdate","E":1618677374322,"s":"SWRVBUSD","U":64830128,"u":64830129,"b":[["2.27200000","0.00000000"],["2.19000000","0.00000000"]],"a":[]}}
1618677374.377651: {"stream":"aaveupusdt@depth@100ms","data":{"e":"depthUpdate","E":1618677374323,"s":"AAVEUPUSDT","U":82463729,"u":82463729,"b":[],"a":[["85.40400000","0.00000000"]]}}
1618677374.4773288: {"stream":"swrvbusd@depth@100ms","data":{"e":"depthUpdate","E":1618677374422,"s":"SWRVBUSD","U":64830130,"u":64830130,"b":[["2.27200000","6.15500000"]],"a":[]}}
1618677374.5797892: {"stream":"swrvbusd@depth@100ms","data":{"e":"depthUpdate","E":1618677374522,"s":"SWRVBUSD","U":64830131,"u":64830131,"b":[["2.27100000","133.36000000"],["2.26800000","95.75000000"]],"a":[]}}
1618677374.5799282: {"stream":"aaveupusdt@depth@100ms","data":{"e":"depthUpdate","E":1618677374523,"s":"AAVEUPUSDT","U":82463730,"u":82463731,"b":[["84.11900000","2.57000000"]],"a":[["85.49900000","2.57000000"]]}}
1618677374.5800278: {"stream":"swrvbusd@bookTicker","data":{"u":64830132,"s":"SWRVBUSD","b":"2.27200000","B":"6.15500000","a":"2.27600000","A":"20.45400000"}}
1618677374.5800672: {"stream":"swrvbusd@bookTicker","data":{"u":64830133,"s":"SWRVBUSD","b":"2.27200000","B":"6.15500000","a":"2.27700000","A":"1.19200000"}}
1618677374.585494: {"stream":"swrvbusd@bookTicker","data":{"u":64830134,"s":"SWRVBUSD","b":"2.27200000","B":"224.56300000","a":"2.27700000","A":"1.19200000"}}
1618677374.5914838: {"stream":"busdtry@kline_1m","data":{"e":"kline","E":1618677374538,"s":"BUSDTRY","k":{"t":1618677360000,"T":1618677419999,"s":"BUSDTRY","i":"1m","f":1734546,"L":1734548,"o":"8.14000000","c":"8.13000000","h":"8.14000000","l":"8.13000000","v":"347.29000000","n":3,"x":false,"q":"2823.82770000","V":"36.00000000","Q":"293.04000000","B":"0"}}}
1618677374.591614: {"stream":"busdtry@aggTrade","data":{"e":"aggTrade","E":1618677374538,"s":"BUSDTRY","a":1491245,"p":"8.13000000","q":"103.87000000","f":1734548,"l":1734548,"T":1618677374535,"m":true,"M":true}}
1618677374.593749: {"stream":"busdtry@bookTicker","data":{"u":10166140,"s":"BUSDTRY","b":"8.13000000","B":"125121.95000000","a":"8.14000000","A":"107821.20000000"}}
1618677374.6517088: {"stream":"swrvbusd@bookTicker","data":{"u":64830138,"s":"SWRVBUSD","b":"2.27300000","B":"21.99200000","a":"2.27700000","A":"1.19200000"}}
1618677374.6565409: {"stream":"swrvbusd@bookTicker","data":{"u":64830139,"s":"SWRVBUSD","b":"2.27300000","B":"21.99200000","a":"2.27600000","A":"20.45400000"}}
1618677374.671587: {"stream":"gtobtc@bookTicker","data":{"u":137196723,"s":"GTOBTC","b":"0.00000162","B":"49627.00000000","a":"0.00000163","A":"345860.00000000"}}
1618677374.678427: {"stream":"swrvbusd@depth@100ms","data":{"e":"depthUpdate","E":1618677374622,"s":"SWRVBUSD","U":64830132,"u":64830139,"b":[["2.27300000","21.99200000"],["2.27200000","224.56300000"],["2.27000000","128.43600000"],["2.26900000","213.89300000"],["2.19700000","315.15500000"]],"a":[["2.27600000","20.45400000"]]}}
1618677374.6785972: {"stream":"gtobtc@depth@100ms","data":{"e":"depthUpdate","E":1618677374623,"s":"GTOBTC","U":137196723,"u":137196723,"b":[["0.00000162","49627.00000000"]],"a":[]}}
1618677375.181122: {"stream":"busdtry@depth@100ms","data":{"e":"depthUpdate","E":1618677374623,"s":"BUSDTRY","U":10166140,"u":10166140,"b":[["8.13000000","125121.95000000"]],"a":[]}}
1618677375.181174: {"stream":"aaveupusdt@depth@100ms","data":{"e":"depthUpdate","E":1618677374723,"s":"AAVEUPUSDT","U":82463732,"u":82463734,"b":[["84.11900000","0.00000000"],["80.68700000","0.56000000"]],"a":[["85.49900000","0.00000000"]]}}
1618677375.181231: {"stream":"qspbtc@depth@100ms","data":{"e":"depthUpdate","E":1618677374922,"s":"QSPBTC","U":105811206,"u":105811206,"b":[["0.00000156","15323.00000000"]],"a":[]}}
1618677375.181259: {"stream":"swrvbusd@depth@100ms","data":{"e":"depthUpdate","E":1618677374923,"s":"SWRVBUSD","U":64830140,"u":64830140,"b":[["2.18700000","54.87000000"]],"a":[]}}
1618677375.181282: {"stream":"veteth@depth@100ms","data":{"e":"depthUpdate","E":1618677375022,"s":"VETETH","U":327912886,"u":327912886,"b":[],"a":[["0.00009411","4388.00000000"]]}}
1618677375.181304: {"stream":"swrvbusd@depth@100ms","data":{"e":"depthUpdate","E":1618677375023,"s":"SWRVBUSD","U":64830141,"u":64830141,"b":[["2.27200000","6.15500000"]],"a":[]}}
1618677375.1813262: {"stream":"swrvbusd@bookTicker","data":{"u":64830143,"s":"SWRVBUSD","b":"2.27200000","B":"6.15500000","a":"2.27600000","A":"20.45400000"}}
1618677375.181342: {"stream":"swrvbusd@bookTicker","data":{"u":64830144,"s":"SWRVBUSD","b":"2.27200000","B":"6.15500000","a":"2.27700000","A":"1.19200000"}}
1618677375.181685: {"stream":"swrvbusd@depth@100ms","data":{"e":"depthUpdate","E":1618677375123,"s":"SWRVBUSD","U":64830142,"u":64830145,"b":[["2.27300000","0.00000000"],["2.26900000","31.69300000"],["2.19500000","55.12500000"]],"a":[["2.27600000","0.00000000"]]}}
1618677375.181757: {"stream":"aaveupusdt@depth@100ms","data":{"e":"depthUpdate","E":1618677375123,"s":"AAVEUPUSDT","U":82463735,"u":82463735,"b":[],"a":[["85.13300000","0.00000000"]]}}
1618677375.191947: {"stream":"swrvbusd@bookTicker","data":{"u":64830146,"s":"SWRVBUSD","b":"2.27200000","B":"224.56300000","a":"2.27700000","A":"1.19200000"}}
1618677375.223924: {"stream":"veteth@bookTicker","data":{"u":327912887,"s":"VETETH","b":"0.00009381","B":"95017.00000000","a":"0.00009402","A":"20330.00000000"}}
1618677375.229515: {"stream":"swrvbusd@bookTicker","data":{"u":64830147,"s":"SWRVBUSD","b":"2.27300000","B":"21.99200000","a":"2.27700000","A":"1.19200000"}}
1618677375.229599: {"stream":"swrvbusd@bookTicker","data":{"u":64830148,"s":"SWRVBUSD","b":"2.27300000","B":"21.99200000","a":"2.27600000","A":"20.45400000"}}
1618677375.231759: {"stream":"aaveupusdt@bookTicker","data":{"u":82463736,"s":"AAVEUPUSDT","b":"84.39300000","B":"0.17000000","a":"84.69900000","A":"0.39000000"}}
1618677375.2424629: {"stream":"aaveupusdt@bookTicker","data":{"u":82463738,"s":"AAVEUPUSDT","b":"84.39300000","B":"10.77000000","a":"84.69900000","A":"0.39000000"}}
1618677375.2614741: {"stream":"aaveupusdt@bookTicker","data":{"u":82463740,"s":"AAVEUPUSDT","b":"84.39400000","B":"0.25000000","a":"84.69900000","A":"0.39000000"}}
1618677375.2765062: {"stream":"veteth@depth@100ms","data":{"e":"depthUpdate","E":1618677375223,"s":"VETETH","U":327912887,"u":327912888,"b":[],"a":[["0.00009401","0.00000000"],["0.00009403","88406.00000000"]]}}
1618677375.2766771: {"stream":"swrvbusd@depth@100ms","data":{"e":"depthUpdate","E":1618677375223,"s":"SWRVBUSD","U":64830146,"u":64830148,"b":[["2.27300000","21.99200000"],["2.27200000","224.56300000"]],"a":[["2.27600000","20.45400000"]]}}
1618677375.277035: {"stream":"aaveupusdt@depth@100ms","data":{"e":"depthUpdate","E":1618677375223,"s":"AAVEUPUSDT","U":82463736,"u":82463740,"b":[["84.39400000","0.25000000"],["84.39300000","10.77000000"],["84.39200000","0.00000000"],["83.57700000","0.00000000"]],"a":[]}}
1618677375.363967: {"stream":"aaveupusdt@bookTicker","data":{"u":82463741,"s":"AAVEUPUSDT","b":"84.39300000","B":"10.77000000","a":"84.69900000","A":"0.39000000"}}
1618677375.377793: {"stream":"veteth@depth@100ms","data":{"e":"depthUpdate","E":1618677375323,"s":"VETETH","U":327912889,"u":327912889,"b":[],"a":[["0.00009411","224.00000000"]]}}
1618677375.377933: {"stream":"aaveupusdt@depth@100ms","data":{"e":"depthUpdate","E":1618677375323,"s":"AAVEUPUSDT","U":82463741,"u":82463741,"b":[["84.39400000","0.00000000"]],"a":[]}}
1618677375.5784209: {"stream":"aaveupusdt@depth@100ms","data":{"e":"depthUpdate","E":1618677375523,"s":"AAVEUPUSDT","U":82463742,"u":82463742,"b":[["81.96200000","0.00000000"]],"a":[]}}
1618677375.6769989: {"stream":"veteth@depth@100ms","data":{"e":"depthUpdate","E":1618677375623,"s":"VETETH","U":327912890,"u":327912890,"b":[],"a":[["0.00009403","0.00000000"]]}}
1618677375.763478: {"stream":"swrvbusd@bookTicker","data":{"u":64830150,"s":"SWRVBUSD","b":"2.27200000","B":"224.56300000","a":"2.27600000","A":"20.45400000"}}
1618677375.769529: {"stream":"swrvbusd@bookTicker","data":{"u":64830151,"s":"SWRVBUSD","b":"2.27200000","B":"224.56300000","a":"2.27700000","A":"1.19200000"}}
1618677375.776769: {"stream":"swrvbusd@depth@100ms","data":{"e":"depthUpdate","E":1618677375723,"s":"SWRVBUSD","U":64830149,"u":64830151,"b":[["2.27300000","0.00000000"],["2.27000000","95.46200000"],["2.26900000","0.00000000"]],"a":[["2.27600000","0.00000000"]]}}
1618677375.781017: {"stream":"swrvbusd@bookTicker","data":{"u":64830153,"s":"SWRVBUSD","b":"2.27200000","B":"257.53700000","a":"2.27700000","A":"1.19200000"}}
1618677375.791889: {"stream":"aaveupusdt@bookTicker","data":{"u":82463743,"s":"AAVEUPUSDT","b":"84.39400000","B":"0.25000000","a":"84.69900000","A":"0.39000000"}}
1618677375.8342578: {"stream":"swrvbusd@bookTicker","data":{"u":64830154,"s":"SWRVBUSD","b":"2.27300000","B":"21.99200000","a":"2.27700000","A":"1.19200000"}}
1618677375.838805: {"stream":"swrvbusd@bookTicker","data":{"u":64830155,"s":"SWRVBUSD","b":"2.27300000","B":"21.99200000","a":"2.27600000","A":"20.45400000"}}
1618677375.878363: {"stream":"swrvbusd@depth@100ms","data":{"e":"depthUpdate","E":1618677375823,"s":"SWRVBUSD","U":64830152,"u":64830155,"b":[["2.27300000","21.99200000"],["2.27200000","257.53700000"],["2.27000000","127.15500000"]],"a":[["2.27600000","20.45400000"]]}}
1618677375.878551: {"stream":"aaveupusdt@depth@100ms","data":{"e":"depthUpdate","E":1618677375823,"s":"AAVEUPUSDT","U":82463743,"u":82463746,"b":[["84.39400000","0.25000000"],["84.11900000","2.57000000"],["82.20300000","2.45000000"]],"a":[["85.40400000","2.57000000"]]}}
1618677375.9736269: {"stream":"swrvbusd@kline_1m","data":{"e":"kline","E":1618677375917,"s":"SWRVBUSD","k":{"t":1618677360000,"T":1618677419999,"s":"SWRVBUSD","i":"1m","f":1135631,"L":1135632,"o":"2.27700000","c":"2.27600000","h":"2.27700000","l":"2.27600000","v":"31.78900000","n":2,"x":false,"q":"72.36159000","V":"21.96300000","Q":"49.98778800","B":"0"}}}
1618677375.978611: {"stream":"aaveupusdt@depth@100ms","data":{"e":"depthUpdate","E":1618677375923,"s":"AAVEUPUSDT","U":82463747,"u":82463747,"b":[["84.11900000","0.00000000"]],"a":[]}}
1618677376.079565: {"stream":"aaveupusdt@depth@100ms","data":{"e":"depthUpdate","E":1618677376023,"s":"AAVEUPUSDT","U":82463748,"u":82463748,"b":[],"a":[["85.13400000","242.66000000"]]}}
1618677376.104579: {"stream":"busdtry@bookTicker","data":{"u":10166141,"s":"BUSDTRY","b":"8.13000000","B":"125066.57000000","a":"8.14000000","A":"107821.20000000"}}
1618677376.104668: {"stream":"busdtry@aggTrade","data":{"e":"aggTrade","E":1618677376050,"s":"BUSDTRY","a":1491246,"p":"8.13000000","q":"55.38000000","f":1734549,"l":1734549,"T":1618677376040,"m":true,"M":true}}
1618677376.180864: {"stream":"veteth@kline_1m","data":{"e":"kline","E":1618677376124,"s":"VETETH","k":{"t":1618677360000,"T":1618677419999,"s":"VETETH","i":"1m","f":6849492,"L":6849495,"o":"0.00009392","c":"0.00009402","h":"0.00009402","l":"0.00009392","v":"10520.00000000","n":4,"x":false,"q":"0.98892018","V":"10520.00000000","Q":"0.98892018","B":"0"}}}
1618677376.1809962: {"stream":"veteth@depth@100ms","data":{"e":"depthUpdate","E":1618677376123,"s":"VETETH","U":327912891,"u":327912892,"b":[],"a":[["0.00009403","0.00000000"]]}}
1618677376.1810508: {"stream":"veteth@bookTicker","data":{"u":327912893,"s":"VETETH","b":"0.00009381","B":"95017.00000000","a":"0.00009402","A":"11859.00000000"}}
1618677376.1810749: {"stream":"swrvbusd@depth@100ms","data":{"e":"depthUpdate","E":1618677376123,"s":"SWRVBUSD","U":64830156,"u":64830156,"b":[["2.17300000","0.00000000"]],"a":[]}}
1618677376.18113: {"stream":"busdtry@depth@100ms","data":{"e":"depthUpdate","E":1618677376123,"s":"BUSDTRY","U":10166141,"u":10166141,"b":[["8.13000000","125066.57000000"]],"a":[]}}
1618677376.181165: {"stream":"veteth@aggTrade","data":{"e":"aggTrade","E":1618677376123,"s":"VETETH","a":5580637,"p":"0.00009402","q":"8471.00000000","f":6849495,"l":6849495,"T":1618677376110,"m":false,"M":true}}
1618677376.2082932: {"stream":"veteth@bookTicker","data":{"u":327912894,"s":"VETETH","b":"0.00009381","B":"95017.00000000","a":"0.00009404","A":"9006.00000000"}}
1618677376.238121: {"stream":"veteth@bookTicker","data":{"u":327912895,"s":"VETETH","b":"0.00009381","B":"95017.00000000","a":"0.00009403","A":"88406.00000000"}}
1618677376.2504058: {"stream":"veteth@bookTicker","data":{"u":327912896,"s":"VETETH","b":"0.00009381","B":"95017.00000000","a":"0.00009404","A":"9006.00000000"}}
1618677376.272929: {"stream":"veteth@bookTicker","data":{"u":327912897,"s":"VETETH","b":"0.00009381","B":"95017.00000000","a":"0.00009403","A":"88406.00000000"}}
1618677376.2781818: {"stream":"veteth@depth@100ms","data":{"e":"depthUpdate","E":1618677376223,"s":"VETETH","U":327912893,"u":327912897,"b":[],"a":[["0.00009402","0.00000000"],["0.00009403","88406.00000000"]]}}
1618677376.2783418: {"stream":"swrvbusd@depth@100ms","data":{"e":"depthUpdate","E":1618677376223,"s":"SWRVBUSD","U":64830157,"u":64830157,"b":[["2.27200000","39.12900000"]],"a":[]}}
1618677376.2783868: {"stream":"veteth@bookTicker","data":{"u":327912898,"s":"VETETH","b":"0.00009381","B":"95017.00000000","a":"0.00009404","A":"9006.00000000"}}
1618677376.278412: {"stream":"aaveupusdt@depth@100ms","data":{"e":"depthUpdate","E":1618677376223,"s":"AAVEUPUSDT","U":82463749,"u":82463749,"b":[["84.39300000","10.60000000"]],"a":[]}}
1618677376.30547: {"stream":"swrvbusd@bookTicker","data":{"u":64830158,"s":"SWRVBUSD","b":"2.27200000","B":"39.12900000","a":"2.27600000","A":"20.45400000"}}
1618677376.305553: {"stream":"swrvbusd@bookTicker","data":{"u":64830159,"s":"SWRVBUSD","b":"2.27200000","B":"39.12900000","a":"2.27700000","A":"1.19200000"}}
1618677376.377955: {"stream":"veteth@depth@100ms","data":{"e":"depthUpdate","E":1618677376323,"s":"VETETH","U":327912898,"u":327912899,"b":[],"a":[["0.00009403","0.00000000"],["0.00009405","88406.00000000"]]}}
1618677376.37813: {"stream":"qspbtc@depth@100ms","data":{"e":"depthUpdate","E":1618677376323,"s":"QSPBTC","U":105811207,"u":105811207,"b":[],"a":[["0.00000177","41200.00000000"]]}}
1618677376.378197: {"stream":"swrvbusd@depth@100ms","data":{"e":"depthUpdate","E":1618677376323,"s":"SWRVBUSD","U":64830158,"u":64830161,"b":[["2.27300000","0.00000000"],["2.26900000","182.20000000"],["2.26800000","0.00000000"]],"a":[["2.27600000","0.00000000"]]}}
1618677376.38352: {"stream":"swrvbusd@bookTicker","data":{"u":64830162,"s":"SWRVBUSD","b":"2.27300000","B":"21.99200000","a":"2.27700000","A":"1.19200000"}}
1618677376.3836029: {"stream":"swrvbusd@bookTicker","data":{"u":64830163,"s":"SWRVBUSD","b":"2.27300000","B":"21.99200000","a":"2.27600000","A":"20.45400000"}}
1618677376.391443: {"stream":"veteth@bookTicker","data":{"u":327912900,"s":"VETETH","b":"0.00009381","B":"95017.00000000","a":"0.00009405","A":"88406.00000000"}}
1618677376.4414232: {"stream":"veteth@bookTicker","data":{"u":327912901,"s":"VETETH","b":"0.00009381","B":"95017.00000000","a":"0.00009406","A":"555.00000000"}}
1618677376.458705: {"stream":"veteth@bookTicker","data":{"u":327912902,"s":"VETETH","b":"0.00009381","B":"95017.00000000","a":"0.00009404","A":"9006.00000000"}}
1618677376.4766378: {"stream":"veteth@depth@100ms","data":{"e":"depthUpdate","E":1618677376423,"s":"VETETH","U":327912900,"u":327912903,"b":[],"a":[["0.00009404","9006.00000000"],["0.00009405","88406.00000000"]]}}
1618677376.4773881: {"stream":"swrvbusd@depth@100ms","data":{"e":"depthUpdate","E":1618677376423,"s":"SWRVBUSD","U":64830162,"u":64830164,"b":[["2.27300000","21.99200000"],["2.18000000","111.72200000"]],"a":[["2.27600000","20.45400000"]]}}
1618677376.505218: {"stream":"swrvbusd@bookTicker","data":{"u":64830165,"s":"SWRVBUSD","b":"2.27300000","B":"240.30400000","a":"2.27600000","A":"20.45400000"}}
1618677376.761528: {"stream":"veteth@bookTicker","data":{"u":327912905,"s":"VETETH","b":"0.00009381","B":"95017.00000000","a":"0.00009406","A":"555.00000000"}}
1618677376.761586: {"stream":"veteth@bookTicker","data":{"u":327912909,"s":"VETETH","b":"0.00009381","B":"95017.00000000","a":"0.00009405","A":"88406.00000000"}}
1618677376.76161: {"stream":"veteth@depth@100ms","data":{"e":"depthUpdate","E":1618677376523,"s":"VETETH","U":327912904,"u":327912909,"b":[["0.00009361","0.00000000"]],"a":[["0.00009404","0.00000000"],["0.00009405","88406.00000000"],["0.00009407","0.00000000"]]}}
1618677376.761708: {"stream":"swrvbusd@depth@100ms","data":{"e":"depthUpdate","E":1618677376523,"s":"SWRVBUSD","U":64830165,"u":64830165,"b":[["2.27300000","240.30400000"]],"a":[]}}
1618677376.761748: {"stream":"swrvbusd@depth@100ms","data":{"e":"depthUpdate","E":1618677376623,"s":"SWRVBUSD","U":64830166,"u":64830166,"b":[["2.27200000","32.97400000"]],"a":[]}}
1618677376.8463192: {"stream":"veteth@bookTicker","data":{"u":327912910,"s":"VETETH","b":"0.00009382","B":"81077.00000000","a":"0.00009405","A":"88406.00000000"}}
1618677376.861952: {"stream":"veteth@bookTicker","data":{"u":327912911,"s":"VETETH","b":"0.00009382","B":"81077.00000000","a":"0.00009406","A":"555.00000000"}}
1618677376.944958: {"stream":"veteth@depth@100ms","data":{"e":"depthUpdate","E":1618677376823,"s":"VETETH","U":327912910,"u":327912912,"b":[["0.00009382","81077.00000000"],["0.00009381","0.00000000"]],"a":[["0.00009405","0.00000000"]]}}
1618677376.945148: {"stream":"aaveupusdt@depth@100ms","data":{"e":"depthUpdate","E":1618677376824,"s":"AAVEUPUSDT","U":82463750,"u":82463750,"b":[["84.19700000","2.57000000"]],"a":[]}}
1618677376.945224: {"stream":"veteth@bookTicker","data":{"u":327912914,"s":"VETETH","b":"0.00009383","B":"94966.00000000","a":"0.00009406","A":"555.00000000"}}
1618677376.9452622: {"stream":"swrvbusd@bookTicker","data":{"u":64830168,"s":"SWRVBUSD","b":"2.27300000","B":"218.31200000","a":"2.27600000","A":"20.45400000"}}
1618677376.94529: {"stream":"swrvbusd@bookTicker","data":{"u":64830169,"s":"SWRVBUSD","b":"2.27300000","B":"218.31200000","a":"2.27700000","A":"1.19200000"}}
1618677376.945316: {"stream":"swrvbusd@bookTicker","data":{"u":64830170,"s":"SWRVBUSD","b":"2.27300000","B":"251.28600000","a":"2.27700000","A":"1.19200000"}}
1618677376.974638: {"stream":"swrvbusd@bookTicker","data":{"u":64830172,"s":"SWRVBUSD","b":"2.27300000","B":"273.27800000","a":"2.27700000","A":"1.19200000"}}
1618677376.974719: {"stream":"swrvbusd@bookTicker","data":{"u":64830173,"s":"SWRVBUSD","b":"2.27300000","B":"273.27800000","a":"2.27600000","A":"20.45400000"}}
1618677376.976585: {"stream":"veteth@depth@100ms","data":{"e":"depthUpdate","E":1618677376923,"s":"VETETH","U":327912913,"u":327912918,"b":[["0.00009383","94966.00000000"],["0.00009382","0.00000000"],["0.00009351","100000.00000000"],["0.00009339","70.00000000"]],"a":[["0.00009407","0.00000000"]]}}
1618677376.97718: {"stream":"swrvbusd@depth@100ms","data":{"e":"depthUpdate","E":1618677376924,"s":"SWRVBUSD","U":64830167,"u":64830173,"b":[["2.27300000","273.27800000"],["2.27200000","0.00000000"],["2.27100000","165.05300000"],["2.27000000","95.46200000"]],"a":[["2.27600000","20.45400000"]]}}
1618677376.989415: {"stream":"swrvbusd@bookTicker","data":{"u":64830174,"s":"SWRVBUSD","b":"2.27300000","B":"54.96600000","a":"2.27600000","A":"20.45400000"}}
1618677377.040549: {"stream":"veteth@bookTicker","data":{"u":327912919,"s":"VETETH","b":"0.00009383","B":"94966.00000000","a":"0.00009405","A":"9005.00000000"}}
1618677377.047057: {"stream":"veteth@bookTicker","data":{"u":327912920,"s":"VETETH","b":"0.00009383","B":"94966.00000000","a":"0.00009406","A":"555.00000000"}}
1618677377.069469: {"stream":"veteth@bookTicker","data":{"u":327912921,"s":"VETETH","b":"0.00009380","B":"4016.00000000","a":"0.00009406","A":"555.00000000"}}
1618677377.0777879: {"stream":"veteth@depth@100ms","data":{"e":"depthUpdate","E":1618677377023,"s":"VETETH","U":327912919,"u":327912921,"b":[["0.00009383","0.00000000"]],"a":[["0.00009405","0.00000000"]]}}
1618677377.077909: {"stream":"swrvbusd@depth@100ms","data":{"e":"depthUpdate","E":1618677377024,"s":"SWRVBUSD","U":64830174,"u":64830174,"b":[["2.27300000","54.96600000"]],"a":[]}}
1618677377.187074: {"stream":"veteth@bookTicker","data":{"u":327912922,"s":"VETETH","b":"0.00009381","B":"94966.00000000","a":"0.00009406","A":"555.00000000"}}
1618677377.187156: {"stream":"veteth@depth@100ms","data":{"e":"depthUpdate","E":1618677377123,"s":"VETETH","U":327912922,"u":327912923,"b":[["0.00009381","94966.00000000"],["0.00009372","4220.00000000"]],"a":[]}}
1618677377.192831: {"stream":"perlbnb@bookTicker","data":{"u":97581315,"s":"PERLBNB","b":"0.00039200","B":"11110.00000000","a":"0.00039400","A":"311.00000000"}}
1618677377.2782211: {"stream":"veteth@depth@100ms","data":{"e":"depthUpdate","E":1618677377223,"s":"VETETH","U":327912924,"u":327912927,"b":[["0.00009350","0.00000000"]],"a":[["0.00009412","555.00000000"],["0.00009456","0.00000000"],["0.00009476","3071.00000000"]]}}
1618677377.278419: {"stream":"perlbnb@depth@100ms","data":{"e":"depthUpdate","E":1618677377223,"s":"PERLBNB","U":97581315,"u":97581315,"b":[["0.00039200","11110.00000000"]],"a":[]}}
1618677377.480522: {"stream":"qspbtc@depth@100ms","data":{"e":"depthUpdate","E":1618677377223,"s":"QSPBTC","U":105811208,"u":105811208,"b":[["0.00000155","44159.00000000"]],"a":[]}}
1618677377.480574: {"stream":"gtobtc@depth@100ms","data":{"e":"depthUpdate","E":1618677377224,"s":"GTOBTC","U":137196724,"u":137196726,"b":[["0.00000161","98021.00000000"],["0.00000160","382913.00000000"]],"a":[]}}
1618677377.480609: {"stream":"aaveupusdt@depth@100ms","data":{"e":"depthUpdate","E":1618677377224,"s":"AAVEUPUSDT","U":82463751,"u":82463751,"b":[],"a":[["85.13400000","0.00000000"]]}}
1618677377.480646: {"stream":"aaveupusdt@kline_1m","data":{"e":"kline","E":1618677377270,"s":"AAVEUPUSDT","k":{"t":1618677360000,"T":1618677419999,"s":"AAVEUPUSDT","i":"1m","f":1857323,"L":1857326,"o":"84.58500000","c":"84.69900000","h":"84.69900000","l":"84.58500000","v":"1.65000000","n":4,"x":false,"q":"139.62848000","V":"1.65000000","Q":"139.62848000","B":"0"}}}
1618677377.4806778: {"stream":"aaveupusdt@bookTicker","data":{"u":82463753,"s":"AAVEUPUSDT","b":"84.39400000","B":"0.25000000","a":"84.93500000","A":"0.74000000"}}
1618677377.480694: {"stream":"aaveupusdt@aggTrade","data":{"e":"aggTrade","E":1618677377270,"s":"AAVEUPUSDT","a":1779415,"p":"84.69900000","q":"0.39000000","f":1857326,"l":1857326,"T":1618677377265,"m":false,"M":true}}
1618677377.480714: {"stream":"veteth@bookTicker","data":{"u":327912930,"s":"VETETH","b":"0.00009382","B":"145759.00000000","a":"0.00009406","A":"555.00000000"}}
1618677377.480727: {"stream":"veteth@bookTicker","data":{"u":327912932,"s":"VETETH","b":"0.00009383","B":"4625.00000000","a":"0.00009406","A":"555.00000000"}}
1618677377.48074: {"stream":"veteth@bookTicker","data":{"u":327912933,"s":"VETETH","b":"0.00009383","B":"99591.00000000","a":"0.00009406","A":"555.00000000"}}
1618677377.480751: {"stream":"veteth@depth@100ms","data":{"e":"depthUpdate","E":1618677377323,"s":"VETETH","U":327912928,"u":327912934,"b":[["0.00009383","99591.00000000"],["0.00009382","0.00000000"],["0.00009381","0.00000000"],["0.00009372","0.00000000"],["0.00009354","0.00000000"]],"a":[]}}
1618677377.4808059: {"stream":"perlbnb@depth@100ms","data":{"e":"depthUpdate","E":1618677377323,"s":"PERLBNB","U":97581316,"u":97581316,"b":[],"a":[["0.00039500","5362.00000000"]]}}
1618677377.480818: {"stream":"swrvbusd@depth@100ms","data":{"e":"depthUpdate","E":1618677377324,"s":"SWRVBUSD","U":64830175,"u":64830175,"b":[["2.27000000","194.05300000"]],"a":[]}}
1618677377.480841: {"stream":"gtobtc@depth@100ms","data":{"e":"depthUpdate","E":1618677377324,"s":"GTOBTC","U":137196727,"u":137196727,"b":[["0.00000161","102863.00000000"]],"a":[]}}
1618677377.480863: {"stream":"aaveupusdt@depth@100ms","data":{"e":"depthUpdate","E":1618677377324,"s":"AAVEUPUSDT","U":82463752,"u":82463753,"b":[],"a":[["84.69900000","0.00000000"],["85.40400000","0.00000000"]]}}
1618677377.480895: {"stream":"veteth@bookTicker","data":{"u":327912935,"s":"VETETH","b":"0.00009384","B":"27186.00000000","a":"0.00009406","A":"555.00000000"}}
1618677377.48091: {"stream":"veteth@bookTicker","data":{"u":327912937,"s":"VETETH","b":"0.00009385","B":"94966.00000000","a":"0.00009406","A":"555.00000000"}}
1618677377.480921: {"stream":"swrvbusd@bookTicker","data":{"u":64830177,"s":"SWRVBUSD","b":"2.27300000","B":"32.97400000","a":"2.27600000","A":"20.45400000"}}
1618677377.4809332: {"stream":"swrvbusd@bookTicker","data":{"u":64830178,"s":"SWRVBUSD","b":"2.27300000","B":"32.97400000","a":"2.27700000","A":"1.19200000"}}
1618677377.481299: {"stream":"veteth@depth@100ms","data":{"e":"depthUpdate","E":1618677377423,"s":"VETETH","U":327912935,"u":327912939,"b":[["0.00009385","94966.00000000"],["0.00009384","27186.00000000"],["0.00009383","4625.00000000"],["0.00009355","144455.00000000"]],"a":[["0.00009417","157608.00000000"]]}}
1618677377.4813719: {"stream":"perlbnb@depth@100ms","data":{"e":"depthUpdate","E":1618677377423,"s":"PERLBNB","U":97581317,"u":97581317,"b":[["0.00039100","8135.00000000"]],"a":[]}}
1618677377.481387: {"stream":"swrvbusd@depth@100ms","data":{"e":"depthUpdate","E":1618677377424,"s":"SWRVBUSD","U":64830176,"u":64830178,"b":[["2.27300000","32.97400000"],["2.27200000","218.40800000"]],"a":[["2.27600000","0.00000000"]]}}
1618677377.4814332: {"stream":"aaveupusdt@depth@100ms","data":{"e":"depthUpdate","E":1618677377424,"s":"AAVEUPUSDT","U":82463754,"u":82463755,"b":[["83.97400000","239.29000000"],["83.91100000","0.00000000"]],"a":[]}}
1618677377.53032: {"stream":"swrvbusd@bookTicker","data":{"u":64830179,"s":"SWRVBUSD","b":"2.27300000","B":"54.96600000","a":"2.27700000","A":"1.19200000"}}
1618677377.530401: {"stream":"swrvbusd@bookTicker","data":{"u":64830180,"s":"SWRVBUSD","b":"2.27300000","B":"54.96600000","a":"2.27600000","A":"20.45400000"}}
1618677377.5798059: {"stream":"swrvbusd@depth@100ms","data":{"e":"depthUpdate","E":1618677377524,"s":"SWRVBUSD","U":64830179,"u":64830180,"b":[["2.27300000","54.96600000"]],"a":[["2.27600000","20.45400000"]]}}
1618677377.677635: {"stream":"swrvbusd@depth@100ms","data":{"e":"depthUpdate","E":1618677377624,"s":"SWRVBUSD","U":64830181,"u":64830181,"b":[["2.27200000","0.00000000"]],"a":[]}}
1618677377.7796228: {"stream":"swrvbusd@depth@100ms","data":{"e":"depthUpdate","E":1618677377724,"s":"SWRVBUSD","U":64830182,"u":64830182,"b":[["2.27200000","6.15500000"]],"a":[]}}
1618677377.854391: {"stream":"aaveupusdt@bookTicker","data":{"u":82463756,"s":"AAVEUPUSDT","b":"84.39500000","B":"0.17000000","a":"84.93500000","A":"0.74000000"}}
1618677377.871225: {"stream":"aaveupusdt@bookTicker","data":{"u":82463759,"s":"AAVEUPUSDT","b":"84.39600000","B":"0.25000000","a":"84.93500000","A":"0.74000000"}}
1618677377.8782122: {"stream":"perlbnb@depth@100ms","data":{"e":"depthUpdate","E":1618677377824,"s":"PERLBNB","U":97581318,"u":97581319,"b":[["0.00038900","142116.00000000"],["0.00038800","7705.00000000"]],"a":[]}}
1618677377.8819258: {"stream":"aaveupusdt@depth@100ms","data":{"e":"depthUpdate","E":1618677377824,"s":"AAVEUPUSDT","U":82463756,"u":82463759,"b":[["84.39600000","0.25000000"],["84.39500000","0.17000000"],["84.39400000","0.00000000"]],"a":[["85.58400000","2.57000000"]]}}
1618677377.938282: {"stream":"perlbnb@bookTicker","data":{"u":97581323,"s":"PERLBNB","b":"0.00039200","B":"11110.00000000","a":"0.00039300","A":"460.00000000"}}
1618677377.9383402: {"stream":"busdtry@bookTicker","data":{"u":10166142,"s":"BUSDTRY","b":"8.13000000","B":"125066.57000000","a":"8.14000000","A":"107758.20000000"}}
1618677377.9383628: {"stream":"busdtry@kline_1m","data":{"e":"kline","E":1618677377886,"s":"BUSDTRY","k":{"t":1618677360000,"T":1618677419999,"s":"BUSDTRY","i":"1m","f":1734546,"L":1734550,"o":"8.14000000","c":"8.14000000","h":"8.14000000","l":"8.13000000","v":"465.67000000","n":5,"x":false,"q":"3786.88710000","V":"99.00000000","Q":"805.86000000","B":"0"}}}
1618677377.938787: {"stream":"busdtry@aggTrade","data":{"e":"aggTrade","E":1618677377885,"s":"BUSDTRY","a":1491247,"p":"8.14000000","q":"63.00000000","f":1734550,"l":1734550,"T":1618677377884,"m":false,"M":true}}
1618677377.977945: {"stream":"perlbnb@depth@100ms","data":{"e":"depthUpdate","E":1618677377924,"s":"PERLBNB","U":97581320,"u":97581323,"b":[["0.00039100","6316.00000000"],["0.00039000","25217.00000000"]],"a":[["0.00039300","460.00000000"],["0.00039500","4902.00000000"]]}}
1618677377.978125: {"stream":"qspbtc@depth@100ms","data":{"e":"depthUpdate","E":1618677377924,"s":"QSPBTC","U":105811209,"u":105811209,"b":[["0.00000085","107313.00000000"]],"a":[]}}
1618677377.978643: {"stream":"busdtry@depth@100ms","data":{"e":"depthUpdate","E":1618677377924,"s":"BUSDTRY","U":10166142,"u":10166142,"b":[],"a":[["8.14000000","107758.20000000"]]}}
1618677377.978701: {"stream":"aaveupusdt@depth@100ms","data":{"e":"depthUpdate","E":1618677377924,"s":"AAVEUPUSDT","U":82463760,"u":82463760,"b":[],"a":[["85.20500000","66.62000000"]]}}
1618677378.003768: {"stream":"onttry@kline_1m","data":{"e":"kline","E":1618677377951,"s":"ONTTRY","k":{"t":1618677360000,"T":1618677419999,"s":"ONTTRY","i":"1m","f":9332,"L":9332,"o":"19.00000000","c":"19.00000000","h":"19.00000000","l":"19.00000000","v":"5.00000000","n":1,"x":false,"q":"95.00000000","V":"5.00000000","Q":"95.00000000","B":"0"}}}
1618677378.0038881: {"stream":"onttry@bookTicker","data":{"u":282105,"s":"ONTTRY","b":"18.98000000","B":"146.04000000","a":"19.03000000","A":"1177.09000000"}}
1618677378.0043032: {"stream":"onttry@aggTrade","data":{"e":"aggTrade","E":1618677377950,"s":"ONTTRY","a":8610,"p":"19.00000000","q":"5.00000000","f":9332,"l":9332,"T":1618677377949,"m":false,"M":true}}
1618677378.0520582: {"stream":"swrvbusd@bookTicker","data":{"u":64830183,"s":"SWRVBUSD","b":"2.27300000","B":"21.99200000","a":"2.27600000","A":"20.45400000"}}
1618677378.070102: {"stream":"swrvbusd@bookTicker","data":{"u":64830184,"s":"SWRVBUSD","b":"2.27200000","B":"6.15500000","a":"2.27600000","A":"20.45400000"}}
1618677378.070186: {"stream":"swrvbusd@bookTicker","data":{"u":64830185,"s":"SWRVBUSD","b":"2.27200000","B":"6.15500000","a":"2.27700000","A":"1.19200000"}}
1618677378.0816991: {"stream":"veteth@depth@100ms","data":{"e":"depthUpdate","E":1618677378024,"s":"VETETH","U":327912940,"u":327912940,"b":[],"a":[["0.00009415","616.00000000"]]}}
1618677378.081791: {"stream":"onttry@depth@100ms","data":{"e":"depthUpdate","E":1618677378024,"s":"ONTTRY","U":282105,"u":282105,"b":[],"a":[["19.00000000","0.00000000"]]}}
1618677378.5774772: {"stream":"swrvbusd@depth@100ms","data":{"e":"depthUpdate","E":1618677378024,"s":"SWRVBUSD","U":64830183,"u":64830185,"b":[["2.27300000","0.00000000"],["2.27100000","133.36000000"]],"a":[["2.27600000","0.00000000"]]}}
1618677378.577572: {"stream":"aaveupusdt@depth@100ms","data":{"e":"depthUpdate","E":1618677378024,"s":"AAVEUPUSDT","U":82463761,"u":82463761,"b":[["82.20300000","0.00000000"]],"a":[]}}
1618677378.57762: {"stream":"swrvbusd@bookTicker","data":{"u":64830186,"s":"SWRVBUSD","b":"2.27200000","B":"224.56300000","a":"2.27700000","A":"1.19200000"}}
1618677378.577644: {"stream":"swrvbusd@bookTicker","data":{"u":64830189,"s":"SWRVBUSD","b":"2.27200000","B":"224.56300000","a":"2.27600000","A":"20.45400000"}}
1618677378.5776598: {"stream":"swrvbusd@bookTicker","data":{"u":64830190,"s":"SWRVBUSD","b":"2.27300000","B":"21.99200000","a":"2.27600000","A":"20.45400000"}}
1618677378.577674: {"stream":"veteth@depth@100ms","data":{"e":"depthUpdate","E":1618677378124,"s":"VETETH","U":327912941,"u":327912941,"b":[["0.00009384","0.00000000"]],"a":[]}}
1618677378.577714: {"stream":"swrvbusd@depth@100ms","data":{"e":"depthUpdate","E":1618677378124,"s":"SWRVBUSD","U":64830186,"u":64830190,"b":[["2.27300000","21.99200000"],["2.27200000","224.56300000"],["2.27100000","166.33400000"],["2.27000000","225.74600000"]],"a":[["2.27600000","20.45400000"]]}}
1618677378.577771: {"stream":"veteth@bookTicker","data":{"u":327912943,"s":"VETETH","b":"0.00009383","B":"4625.00000000","a":"0.00009406","A":"555.00000000"}}
1618677378.5777888: {"stream":"gtobtc@bookTicker","data":{"u":137196728,"s":"GTOBTC","b":"0.00000162","B":"59627.00000000","a":"0.00000163","A":"345860.00000000"}}
1618677378.577803: {"stream":"veteth@bookTicker","data":{"u":327912945,"s":"VETETH","b":"0.00009384","B":"94966.00000000","a":"0.00009406","A":"555.00000000"}}
1618677378.5778172: {"stream":"gtobtc@bookTicker","data":{"u":137196729,"s":"GTOBTC","b":"0.00000162","B":"49627.00000000","a":"0.00000163","A":"345860.00000000"}}
1618677378.5778298: {"stream":"veteth@depth@100ms","data":{"e":"depthUpdate","E":1618677378224,"s":"VETETH","U":327912942,"u":327912947,"b":[["0.00009385","0.00000000"],["0.00009384","94966.00000000"],["0.00009383","0.00000000"],["0.00009381","0.00000000"],["0.00009356","26687.00000000"]],"a":[]}}
1618677378.577888: {"stream":"gtobtc@bookTicker","data":{"u":137196730,"s":"GTOBTC","b":"0.00000162","B":"59627.00000000","a":"0.00000163","A":"345860.00000000"}}
1618677378.577905: {"stream":"aaveupusdt@bookTicker","data":{"u":82463763,"s":"AAVEUPUSDT","b":"84.39300000","B":"10.60000000","a":"84.93500000","A":"0.74000000"}}
1618677378.577919: {"stream":"gtobtc@depth@100ms","data":{"e":"depthUpdate","E":1618677378224,"s":"GTOBTC","U":137196728,"u":137196729,"b":[["0.00000162","49627.00000000"]],"a":[]}}
1618677378.5779462: {"stream":"aaveupusdt@depth@100ms","data":{"e":"depthUpdate","E":1618677378224,"s":"AAVEUPUSDT","U":82463762,"u":82463762,"b":[["84.39500000","0.00000000"]],"a":[]}}
1618677378.577984: {"stream":"aaveupusdt@bookTicker","data":{"u":82463764,"s":"AAVEUPUSDT","b":"84.39400000","B":"0.25000000","a":"84.93500000","A":"0.74000000"}}
1618677378.5780008: {"stream":"gtobtc@bookTicker","data":{"u":137196731,"s":"GTOBTC","b":"0.00000162","B":"49627.00000000","a":"0.00000163","A":"345860.00000000"}}
1618677378.578015: {"stream":"steemeth@depth@100ms","data":{"e":"depthUpdate","E":1618677378324,"s":"STEEMETH","U":126265005,"u":126265005,"b":[["0.00050400","864.15000000"]],"a":[]}}
1618677378.78439: {"stream":"gtobtc@depth@100ms","data":{"e":"depthUpdate","E":1618677378324,"s":"GTOBTC","U":137196730,"u":137196731,"b":[["0.00000162","49627.00000000"]],"a":[]}}
1618677378.7844422: {"stream":"aaveupusdt@depth@100ms","data":{"e":"depthUpdate","E":1618677378324,"s":"AAVEUPUSDT","U":82463763,"u":82463765,"b":[["84.39600000","0.00000000"],["84.39400000","0.25000000"],["82.39200000","2.45000000"]],"a":[]}}
1618677378.784498: {"stream":"veteth@bookTicker","data":{"u":327912948,"s":"VETETH","b":"0.00009385","B":"4625.00000000","a":"0.00009406","A":"555.00000000"}}
1618677378.784518: {"stream":"veteth@bookTicker","data":{"u":327912950,"s":"VETETH","b":"0.00009386","B":"94966.00000000","a":"0.00009406","A":"555.00000000"}}
1618677378.784532: {"stream":"onttry@bookTicker","data":{"u":282106,"s":"ONTTRY","b":"19.00000000","B":"21.62000000","a":"19.03000000","A":"1177.09000000"}}
1618677378.784544: {"stream":"veteth@bookTicker","data":{"u":327912955,"s":"VETETH","b":"0.00009386","B":"94966.00000000","a":"0.00009405","A":"20330.00000000"}}
1618677378.7845562: {"stream":"veteth@depth@100ms","data":{"e":"depthUpdate","E":1618677378424,"s":"VETETH","U":327912948,"u":327912956,"b":[["0.00009386","94966.00000000"],["0.00009385","0.00000000"],["0.00009384","0.00000000"],["0.00009334","200000.00000000"],["0.00009324","225.00000000"]],"a":[["0.00009405","20330.00000000"],["0.00009407","0.00000000"]]}}
1618677378.784619: {"stream":"onttry@depth@100ms","data":{"e":"depthUpdate","E":1618677378424,"s":"ONTTRY","U":282106,"u":282106,"b":[["19.00000000","21.62000000"]],"a":[]}}
1618677378.784631: {"stream":"steemeth@depth@100ms","data":{"e":"depthUpdate","E":1618677378424,"s":"STEEMETH","U":126265006,"u":126265006,"b":[["0.00050400","1072.22000000"]],"a":[]}}
1618677378.784641: {"stream":"veteth@bookTicker","data":{"u":327912957,"s":"VETETH","b":"0.00009380","B":"4016.00000000","a":"0.00009405","A":"20330.00000000"}}
1618677378.784653: {"stream":"veteth@bookTicker","data":{"u":327912958,"s":"VETETH","b":"0.00009381","B":"94976.00000000","a":"0.00009405","A":"20330.00000000"}}
1618677378.7846642: {"stream":"veteth@depth@100ms","data":{"e":"depthUpdate","E":1618677378524,"s":"VETETH","U":327912957,"u":327912958,"b":[["0.00009386","0.00000000"],["0.00009381","94976.00000000"]],"a":[]}}
1618677378.784696: {"stream":"qspbtc@depth@100ms","data":{"e":"depthUpdate","E":1618677378624,"s":"QSPBTC","U":105811210,"u":105811210,"b":[["0.00000064","260.00000000"]],"a":[]}}
1618677378.784719: {"stream":"swrvbusd@bookTicker","data":{"u":64830191,"s":"SWRVBUSD","b":"2.27200000","B":"224.56300000","a":"2.27600000","A":"20.45400000"}}
1618677378.7847319: {"stream":"swrvbusd@bookTicker","data":{"u":64830192,"s":"SWRVBUSD","b":"2.27200000","B":"224.56300000","a":"2.27700000","A":"1.19200000"}}
1618677378.784744: {"stream":"veteth@bookTicker","data":{"u":327912960,"s":"VETETH","b":"0.00009382","B":"33473.00000000","a":"0.00009405","A":"20330.00000000"}}
1618677378.784754: {"stream":"swrvbusd@bookTicker","data":{"u":64830193,"s":"SWRVBUSD","b":"2.27200000","B":"224.56300000","a":"2.27600000","A":"20.45400000"}}
1618677378.784765: {"stream":"swrvbusd@bookTicker","data":{"u":64830194,"s":"SWRVBUSD","b":"2.27300000","B":"21.99200000","a":"2.27600000","A":"20.45400000"}}
1618677378.784775: {"stream":"veteth@bookTicker","data":{"u":327912961,"s":"VETETH","b":"0.00009382","B":"33473.00000000","a":"0.00009405","A":"108736.00000000"}}
1618677378.784786: {"stream":"veteth@bookTicker","data":{"u":327912963,"s":"VETETH","b":"0.00009383","B":"94976.00000000","a":"0.00009405","A":"108736.00000000"}}
1618677378.785098: {"stream":"veteth@depth@100ms","data":{"e":"depthUpdate","E":1618677378724,"s":"VETETH","U":327912959,"u":327912963,"b":[["0.00009383","94976.00000000"],["0.00009382","33473.00000000"],["0.00009381","0.00000000"]],"a":[["0.00009405","108736.00000000"],["0.00009411","14360.00000000"]]}}
1618677378.785186: {"stream":"swrvbusd@depth@100ms","data":{"e":"depthUpdate","E":1618677378724,"s":"SWRVBUSD","U":64830191,"u":64830194,"b":[["2.27300000","21.99200000"]],"a":[["2.27600000","20.45400000"]]}}
1618677378.785217: {"stream":"aaveupusdt@depth@100ms","data":{"e":"depthUpdate","E":1618677378724,"s":"AAVEUPUSDT","U":82463766,"u":82463766,"b":[],"a":[["85.58400000","0.00000000"]]}}
1618677378.81681: {"stream":"veteth@bookTicker","data":{"u":327912964,"s":"VETETH","b":"0.00009383","B":"94976.00000000","a":"0.00009405","A":"20330.00000000"}}
1618677378.855488: {"stream":"veteth@bookTicker","data":{"u":327912965,"s":"VETETH","b":"0.00009383","B":"94976.00000000","a":"0.00009405","A":"108736.00000000"}}
1618677378.879906: {"stream":"veteth@depth@100ms","data":{"e":"depthUpdate","E":1618677378824,"s":"VETETH","U":327912964,"u":327912965,"b":[],"a":[["0.00009405","108736.00000000"]]}}
1618677378.8799858: {"stream":"qspbtc@depth@100ms","data":{"e":"depthUpdate","E":1618677378824,"s":"QSPBTC","U":105811211,"u":105811211,"b":[],"a":[["0.00000177","40934.00000000"]]}}
1618677378.88002: {"stream":"swrvbusd@depth@100ms","data":{"e":"depthUpdate","E":1618677378824,"s":"SWRVBUSD","U":64830195,"u":64830195,"b":[["2.27200000","6.15500000"]],"a":[]}}
1618677378.888745: {"stream":"veteth@bookTicker","data":{"u":327912966,"s":"VETETH","b":"0.00009383","B":"94976.00000000","a":"0.00009405","A":"20330.00000000"}}
1618677378.978209: {"stream":"veteth@depth@100ms","data":{"e":"depthUpdate","E":1618677378924,"s":"VETETH","U":327912966,"u":327912966,"b":[],"a":[["0.00009405","20330.00000000"]]}}
1618677378.9787872: {"stream":"aaveupusdt@depth@100ms","data":{"e":"depthUpdate","E":1618677378924,"s":"AAVEUPUSDT","U":82463767,"u":82463767,"b":[],"a":[["85.49900000","2.57000000"]]}}
1618677379.001955: {"stream":"veteth@bookTicker","data":{"u":327912968,"s":"VETETH","b":"0.00009383","B":"94976.00000000","a":"0.00009405","A":"108736.00000000"}}
1618677379.0247948: {"stream":"veteth@bookTicker","data":{"u":327912969,"s":"VETETH","b":"0.00009383","B":"94976.00000000","a":"0.00009405","A":"20330.00000000"}}
1618677379.0786078: {"stream":"veteth@depth@100ms","data":{"e":"depthUpdate","E":1618677379024,"s":"VETETH","U":327912967,"u":327912971,"b":[["0.00009356","542.00000000"]],"a":[["0.00009405","20330.00000000"],["0.00009407","88406.00000000"],["0.00009418","2295.00000000"]]}}
1618677379.1055229: {"stream":"veteth@bookTicker","data":{"u":327912975,"s":"VETETH","b":"0.00009383","B":"94976.00000000","a":"0.00009405","A":"108736.00000000"}}
1618677379.1314418: {"stream":"veteth@bookTicker","data":{"u":327912977,"s":"VETETH","b":"0.00009383","B":"94976.00000000","a":"0.00009405","A":"20330.00000000"}}
1618677379.143677: {"stream":"veteth@bookTicker","data":{"u":327912978,"s":"VETETH","b":"0.00009383","B":"94976.00000000","a":"0.00009405","A":"108736.00000000"}}
1618677379.1504488: {"stream":"veteth@bookTicker","data":{"u":327912979,"s":"VETETH","b":"0.00009383","B":"94976.00000000","a":"0.00009405","A":"20330.00000000"}}
1618677379.16706: {"stream":"perlbnb@bookTicker","data":{"u":97581324,"s":"PERLBNB","b":"0.00039200","B":"26481.00000000","a":"0.00039300","A":"460.00000000"}}
1618677379.176728: {"stream":"perlbnb@bookTicker","data":{"u":97581327,"s":"PERLBNB","b":"0.00039200","B":"11110.00000000","a":"0.00039300","A":"460.00000000"}}
1618677379.17733: {"stream":"veteth@depth@100ms","data":{"e":"depthUpdate","E":1618677379124,"s":"VETETH","U":327912972,"u":327912980,"b":[["0.00009356","25486.00000000"],["0.00009270","196.00000000"]],"a":[["0.00009405","20330.00000000"],["0.00009407","88406.00000000"],["0.00009432","0.00000000"]]}}
1618677379.177494: {"stream":"perlbnb@depth@100ms","data":{"e":"depthUpdate","E":1618677379124,"s":"PERLBNB","U":97581324,"u":97581328,"b":[["0.00039200","11110.00000000"],["0.00039000","2250.00000000"],["0.00038800","7704.00000000"]],"a":[]}}
1618677379.2291179: {"stream":"swrvbusd@bookTicker","data":{"u":64830197,"s":"SWRVBUSD","b":"2.27300000","B":"21.99200000","a":"2.27700000","A":"1.19200000"}}
1618677379.231668: {"stream":"swrvbusd@bookTicker","data":{"u":64830198,"s":"SWRVBUSD","b":"2.27200000","B":"6.15500000","a":"2.27700000","A":"1.19200000"}}
1618677379.277899: {"stream":"veteth@depth@100ms","data":{"e":"depthUpdate","E":1618677379224,"s":"VETETH","U":327912981,"u":327912981,"b":[["0.00009280","163000.00000000"]],"a":[]}}
1618677379.278048: {"stream":"perlbnb@depth@100ms","data":{"e":"depthUpdate","E":1618677379224,"s":"PERLBNB","U":97581329,"u":97581329,"b":[["0.00039000","25217.00000000"]],"a":[]}}
1618677379.2793899: {"stream":"swrvbusd@depth@100ms","data":{"e":"depthUpdate","E":1618677379224,"s":"SWRVBUSD","U":64830196,"u":64830200,"b":[["2.27300000","0.00000000"],["2.27100000","166.33400000"],["2.27000000","225.74600000"]],"a":[["2.27600000","0.00000000"]]}}
1618677379.279582: {"stream":"aaveupusdt@depth@100ms","data":{"e":"depthUpdate","E":1618677379224,"s":"AAVEUPUSDT","U":82463768,"u":82463768,"b":[],"a":[["85.49900000","0.00000000"]]}}
1618677379.29149: {"stream":"swrvbusd@bookTicker","data":{"u":64830201,"s":"SWRVBUSD","b":"2.27200000","B":"224.56300000","a":"2.27700000","A":"1.19200000"}}
1618677379.298039: {"stream":"swrvbusd@bookTicker","data":{"u":64830202,"s":"SWRVBUSD","b":"2.27300000","B":"21.99200000","a":"2.27700000","A":"1.19200000"}}
1618677379.304099: {"stream":"swrvbusd@bookTicker","data":{"u":64830203,"s":"SWRVBUSD","b":"2.27300000","B":"21.99200000","a":"2.27600000","A":"20.45400000"}}
1618677379.3792791: {"stream":"swrvbusd@depth@100ms","data":{"e":"depthUpdate","E":1618677379324,"s":"SWRVBUSD","U":64830201,"u":64830203,"b":[["2.27300000","21.99200000"],["2.27200000","224.56300000"]],"a":[["2.27600000","20.45400000"]]}}
1618677379.4793348: {"stream":"aaveupusdt@depth@100ms","data":{"e":"depthUpdate","E":1618677379425,"s":"AAVEUPUSDT","U":82463769,"u":82463769,"b":[["84.19700000","0.00000000"]],"a":[]}}
1618677379.579798: {"stream":"qspbtc@depth@100ms","data":{"e":"depthUpdate","E":1618677379524,"s":"QSPBTC","U":105811212,"u":105811212,"b":[["0.00000153","14351.00000000"]],"a":[]}}
1618677379.6009028: {"stream":"veteth@bookTicker","data":{"u":327912983,"s":"VETETH","b":"0.00009383","B":"94976.00000000","a":"0.00009405","A":"108736.00000000"}}
1618677379.625727: {"stream":"aaveupusdt@bookTicker","data":{"u":82463770,"s":"AAVEUPUSDT","b":"84.57800000","B":"5.79000000","a":"84.93500000","A":"0.74000000"}}
1618677379.639446: {"stream":"aaveupusdt@bookTicker","data":{"u":82463774,"s":"AAVEUPUSDT","b":"84.57800000","B":"13.49000000","a":"84.93500000","A":"0.74000000"}}
1618677379.677748: {"stream":"veteth@depth@100ms","data":{"e":"depthUpdate","E":1618677379624,"s":"VETETH","U":327912982,"u":327912984,"b":[["0.00008730","353.00000000"]],"a":[["0.00009405","108736.00000000"],["0.00009407","0.00000000"]]}}
1618677379.6783779: {"stream":"aaveupusdt@depth@100ms","data":{"e":"depthUpdate","E":1618677379625,"s":"AAVEUPUSDT","U":82463770,"u":82463776,"b":[["84.57800000","13.49000000"],["84.38300000","4.34000000"],["84.19600000","0.00000000"],["83.72200000","0.00000000"]],"a":[]}}
1618677379.724975: {"stream":"aaveupusdt@bookTicker","data":{"u":82463778,"s":"AAVEUPUSDT","b":"84.57900000","B":"0.25000000","a":"84.93500000","A":"0.74000000"}}
1618677379.77833: {"stream":"veteth@depth@100ms","data":{"e":"depthUpdate","E":1618677379724,"s":"VETETH","U":327912985,"u":327912985,"b":[],"a":[["0.00009416","26636.00000000"]]}}
1618677379.778489: {"stream":"onttry@depth@100ms","data":{"e":"depthUpdate","E":1618677379724,"s":"ONTTRY","U":282107,"u":282107,"b":[["18.99000000","430.26000000"]],"a":[]}}
1618677379.779558: {"stream":"aaveupusdt@depth@100ms","data":{"e":"depthUpdate","E":1618677379725,"s":"AAVEUPUSDT","U":82463777,"u":82463779,"b":[["84.57900000","0.25000000"],["84.57800000","19.28000000"],["84.39400000","0.00000000"]],"a":[]}}
1618677379.839175: {"stream":"swrvbusd@bookTicker","data":{"u":64830204,"s":"SWRVBUSD","b":"2.27200000","B":"224.56300000","a":"2.27600000","A":"20.45400000"}}
1618677379.839699: {"stream":"swrvbusd@bookTicker","data":{"u":64830205,"s":"SWRVBUSD","b":"2.27200000","B":"224.56300000","a":"2.27700000","A":"1.19200000"}}
1618677379.878863: {"stream":"swrvbusd@aggTrade","data":{"e":"aggTrade","E":1618677379825,"s":"SWRVBUSD","a":749095,"p":"2.27200000","q":"244.73400000","f":1135633,"l":1135638,"T":1618677379823,"m":true,"M":true}}
1618677379.878965: {"stream":"swrvbusd@depth@100ms","data":{"e":"depthUpdate","E":1618677379824,"s":"SWRVBUSD","U":64830204,"u":64830205,"b":[["2.27300000","0.00000000"]],"a":[["2.27600000","0.00000000"]]}}
1618677379.879555: {"stream":"aaveupusdt@depth@100ms","data":{"e":"depthUpdate","E":1618677379825,"s":"AAVEUPUSDT","U":82463780,"u":82463780,"b":[["84.57800000","13.49000000"]],"a":[]}}
1618677379.879615: {"stream":"swrvbusd@bookTicker","data":{"u":64830206,"s":"SWRVBUSD","b":"2.27200000","B":"4.44900000","a":"2.27700000","A":"1.19200000"}}
1618677379.879641: {"stream":"swrvbusd@kline_1m","data":{"e":"kline","E":1618677379826,"s":"SWRVBUSD","k":{"t":1618677360000,"T":1618677419999,"s":"SWRVBUSD","i":"1m","f":1135631,"L":1135633,"o":"2.27700000","c":"2.27200000","h":"2.27700000","l":"2.27200000","v":"37.94400000","n":3,"x":false,"q":"86.34575000","V":"21.96300000","Q":"49.98778800","B":"0"}}}
1618677379.9063702: {"stream":"swrvbusd@bookTicker","data":{"u":64830208,"s":"SWRVBUSD","b":"2.27300000","B":"21.99200000","a":"2.27700000","A":"1.19200000"}}
1618677379.909369: {"stream":"swrvbusd@bookTicker","data":{"u":64830209,"s":"SWRVBUSD","b":"2.27300000","B":"21.99200000","a":"2.27600000","A":"20.45400000"}}
1618677379.9780622: {"stream":"veteth@depth@100ms","data":{"e":"depthUpdate","E":1618677379924,"s":"VETETH","U":327912986,"u":327912987,"b":[["0.00009359","112.00000000"]],"a":[["0.00009411","224.00000000"]]}}
1618677379.978224: {"stream":"swrvbusd@depth@100ms","data":{"e":"depthUpdate","E":1618677379924,"s":"SWRVBUSD","U":64830206,"u":64830211,"b":[["2.27300000","21.99200000"],["2.27200000","4.44900000"],["2.20900000","22.40800000"]],"a":[["2.27600000","20.45400000"],["2.28100000","229.30200000"],["2.28300000","9.26400000"]]}}
1618677379.981054: {"stream":"aaveupusdt@depth@100ms","data":{"e":"depthUpdate","E":1618677379925,"s":"AAVEUPUSDT","U":82463781,"u":82463781,"b":[["84.57800000","7.70000000"]],"a":[]}}
1618677380.079369: {"stream":"veteth@depth@100ms","data":{"e":"depthUpdate","E":1618677380024,"s":"VETETH","U":327912988,"u":327912988,"b":[["0.00009355","142391.00000000"]],"a":[]}}
1618677380.079503: {"stream":"swrvbusd@depth@100ms","data":{"e":"depthUpdate","E":1618677380024,"s":"SWRVBUSD","U":64830212,"u":64830212,"b":[["2.20300000","34.12400000"]],"a":[]}}
1618677380.079568: {"stream":"aaveupusdt@depth@100ms","data":{"e":"depthUpdate","E":1618677380025,"s":"AAVEUPUSDT","U":82463782,"u":82463783,"b":[["84.11900000","2.57000000"]],"a":[["85.49900000","2.57000000"]]}}
1618677380.111684: {"stream":"aaveupusdt@bookTicker","data":{"u":82463784,"s":"AAVEUPUSDT","b":"84.57900000","B":"0.42000000","a":"84.93500000","A":"0.74000000"}}
1618677380.136114: {"stream":"veteth@bookTicker","data":{"u":327912989,"s":"VETETH","b":"0.00009383","B":"94976.00000000","a":"0.00009404","A":"9006.00000000"}}
1618677380.174606: {"stream":"aaveupusdt@bookTicker","data":{"u":82463785,"s":"AAVEUPUSDT","b":"84.57900000","B":"0.17000000","a":"84.93500000","A":"0.74000000"}}
1618677380.174688: {"stream":"aaveupusdt@bookTicker","data":{"u":82463786,"s":"AAVEUPUSDT","b":"84.58000000","B":"0.25000000","a":"84.93500000","A":"0.74000000"}}
1618677380.188895: {"stream":"veteth@depth@100ms","data":{"e":"depthUpdate","E":1618677380124,"s":"VETETH","U":327912989,"u":327912989,"b":[],"a":[["0.00009404","9006.00000000"]]}}
1618677380.189047: {"stream":"aaveupusdt@depth@100ms","data":{"e":"depthUpdate","E":1618677380125,"s":"AAVEUPUSDT","U":82463784,"u":82463786,"b":[["84.58000000","0.25000000"],["84.57900000","0.17000000"]],"a":[]}}
1618677380.278479: {"stream":"veteth@depth@100ms","data":{"e":"depthUpdate","E":1618677380224,"s":"VETETH","U":327912990,"u":327912990,"b":[["0.00009355","0.00000000"]],"a":[]}}
1618677380.379782: {"stream":"veteth@depth@100ms","data":{"e":"depthUpdate","E":1618677380324,"s":"VETETH","U":327912991,"u":327912991,"b":[],"a":[["0.00009413","158163.00000000"]]}}
1618677380.380197: {"stream":"aaveupusdt@depth@100ms","data":{"e":"depthUpdate","E":1618677380325,"s":"AAVEUPUSDT","U":82463787,"u":82463790,"b":[["84.11900000","0.00000000"]],"a":[["85.20600000","0.00000000"],["85.27300000","130.43000000"],["85.49900000","0.00000000"]]}}
1618677380.4782941: {"stream":"swrvbusd@depth@100ms","data":{"e":"depthUpdate","E":1618677380425,"s":"SWRVBUSD","U":64830213,"u":64830213,"b":[["2.27100000","133.36000000"],["2.27000000","194.05300000"]],"a":[]}}
1618677380.480784: {"stream":"aaveupusdt@depth@100ms","data":{"e":"depthUpdate","E":1618677380425,"s":"AAVEUPUSDT","U":82463791,"u":82463791,"b":[["84.57800000","13.49000000"]],"a":[]}}
1618677380.487958: {"stream":"swrvbusd@bookTicker","data":{"u":64830214,"s":"SWRVBUSD","b":"2.27200000","B":"4.44900000","a":"2.27600000","A":"20.45400000"}}
1618677380.492151: {"stream":"swrvbusd@bookTicker","data":{"u":64830215,"s":"SWRVBUSD","b":"2.27200000","B":"4.44900000","a":"2.27700000","A":"1.19200000"}}
1618677380.579982: {"stream":"veteth@depth@100ms","data":{"e":"depthUpdate","E":1618677380525,"s":"VETETH","U":327912992,"u":327912994,"b":[["0.00009350","142391.00000000"]],"a":[["0.00009405","88406.00000000"],["0.00009417","0.00000000"]]}}
1618677380.580169: {"stream":"swrvbusd@depth@100ms","data":{"e":"depthUpdate","E":1618677380525,"s":"SWRVBUSD","U":64830214,"u":64830216,"b":[["2.27300000","0.00000000"]],"a":[["2.27600000","0.00000000"],["2.28500000","178.71400000"]]}}
1618677380.582369: {"stream":"aaveupusdt@depth@100ms","data":{"e":"depthUpdate","E":1618677380525,"s":"AAVEUPUSDT","U":82463792,"u":82463797,"b":[["84.03900000","309.70000000"],["83.97400000","0.00000000"],["83.95600000","0.00000000"],["83.87900000","0.00000000"],["83.48000000","0.00000000"],["83.47700000","0.00000000"]],"a":[]}}
1618677380.6164942: {"stream":"swrvbusd@bookTicker","data":{"u":64830217,"s":"SWRVBUSD","b":"2.27300000","B":"21.99200000","a":"2.27700000","A":"1.19200000"}}
1618677380.616577: {"stream":"swrvbusd@bookTicker","data":{"u":64830218,"s":"SWRVBUSD","b":"2.27300000","B":"21.99200000","a":"2.27600000","A":"20.45400000"}}
1618677380.679338: {"stream":"veteth@depth@100ms","data":{"e":"depthUpdate","E":1618677380625,"s":"VETETH","U":327912995,"u":327912996,"b":[["0.00009382","0.00000000"]],"a":[["0.00009405","0.00000000"]]}}
1618677380.679519: {"stream":"swrvbusd@depth@100ms","data":{"e":"depthUpdate","E":1618677380625,"s":"SWRVBUSD","U":64830217,"u":64830220,"b":[["2.27300000","21.99200000"],["2.27100000","166.33400000"],["2.27000000","225.74600000"]],"a":[["2.27600000","20.45400000"]]}}
1618677380.681838: {"stream":"aaveupusdt@depth@100ms","data":{"e":"depthUpdate","E":1618677380625,"s":"AAVEUPUSDT","U":82463798,"u":82463799,"b":[],"a":[["85.27300000","0.00000000"],["85.33800000","298.27000000"]]}}
1618677380.704314: {"stream":"busdtry@bookTicker","data":{"u":10166143,"s":"BUSDTRY","b":"8.13000000","B":"125066.57000000","a":"8.14000000","A":"82658.20000000"}}
1618677380.748736: {"stream":"veteth@bookTicker","data":{"u":327912998,"s":"VETETH","b":"0.00009383","B":"94976.00000000","a":"0.00009403","A":"88406.00000000"}}
1618677380.7605069: {"stream":"veteth@bookTicker","data":{"u":327912999,"s":"VETETH","b":"0.00009383","B":"94976.00000000","a":"0.00009404","A":"9006.00000000"}}
1618677380.778504: {"stream":"veteth@depth@100ms","data":{"e":"depthUpdate","E":1618677380725,"s":"VETETH","U":327912997,"u":327912999,"b":[["0.00009151","1642.00000000"]],"a":[["0.00009403","0.00000000"]]}}
1618677380.7811258: {"stream":"busdtry@depth@100ms","data":{"e":"depthUpdate","E":1618677380725,"s":"BUSDTRY","U":10166143,"u":10166143,"b":[],"a":[["8.14000000","82658.20000000"]]}}
1618677380.7812579: {"stream":"aaveupusdt@depth@100ms","data":{"e":"depthUpdate","E":1618677380725,"s":"AAVEUPUSDT","U":82463800,"u":82463801,"b":[["84.57900000","0.00000000"],["84.57800000","7.70000000"]],"a":[]}}
1618677380.821225: {"stream":"veteth@bookTicker","data":{"u":327913001,"s":"VETETH","b":"0.00009380","B":"4016.00000000","a":"0.00009404","A":"9006.00000000"}}
1618677380.872202: {"stream":"aaveupusdt@bookTicker","data":{"u":82463803,"s":"AAVEUPUSDT","b":"84.57900000","B":"0.25000000","a":"84.93500000","A":"0.74000000"}}
1618677380.8786938: {"stream":"veteth@depth@100ms","data":{"e":"depthUpdate","E":1618677380825,"s":"VETETH","U":327913000,"u":327913002,"b":[["0.00009383","0.00000000"]],"a":[["0.00009405","88406.00000000"],["0.00009416","0.00000000"]]}}
1618677380.880933: {"stream":"aaveupusdt@depth@100ms","data":{"e":"depthUpdate","E":1618677380825,"s":"AAVEUPUSDT","U":82463802,"u":82463803,"b":[["84.58000000","0.00000000"],["84.57900000","0.25000000"]],"a":[]}}
1618677380.890785: {"stream":"gtobtc@bookTicker","data":{"u":137196732,"s":"GTOBTC","b":"0.00000162","B":"44443.00000000","a":"0.00000163","A":"345860.00000000"}}
1618677380.908879: {"stream":"veteth@bookTicker","data":{"u":327913003,"s":"VETETH","b":"0.00009381","B":"94986.00000000","a":"0.00009404","A":"9006.00000000"}}
1618677380.949009: {"stream":"aaveupusdt@bookTicker","data":{"u":82463806,"s":"AAVEUPUSDT","b":"84.57800000","B":"7.70000000","a":"84.93500000","A":"0.74000000"}}
1618677380.9490938: {"stream":"veteth@bookTicker","data":{"u":327913005,"s":"VETETH","b":"0.00009381","B":"122684.00000000","a":"0.00009404","A":"9006.00000000"}}
1618677380.949132: {"stream":"aaveupusdt@bookTicker","data":{"u":82463807,"s":"AAVEUPUSDT","b":"84.58100000","B":"0.25000000","a":"84.93500000","A":"0.74000000"}}
1618677380.957439: {"stream":"veteth@bookTicker","data":{"u":327913006,"s":"VETETH","b":"0.00009381","B":"122684.00000000","a":"0.00009403","A":"20330.00000000"}}
1618677380.978527: {"stream":"veteth@depth@100ms","data":{"e":"depthUpdate","E":1618677380925,"s":"VETETH","U":327913003,"u":327913007,"b":[["0.00009381","122684.00000000"]],"a":[["0.00009403","20330.00000000"],["0.00009405","0.00000000"],["0.00009446","24931.00000000"]]}}
1618677380.980583: {"stream":"gtobtc@depth@100ms","data":{"e":"depthUpdate","E":1618677380925,"s":"GTOBTC","U":137196732,"u":137196732,"b":[["0.00000162","44443.00000000"]],"a":[]}}
1618677380.9806561: {"stream":"aaveupusdt@depth@100ms","data":{"e":"depthUpdate","E":1618677380925,"s":"AAVEUPUSDT","U":82463804,"u":82463807,"b":[["84.58100000","0.25000000"],["84.57900000","0.00000000"],["84.10500000","223.67000000"],["84.03900000","0.00000000"]],"a":[]}}
1618677380.984627: {"stream":"veteth@bookTicker","data":{"u":327913008,"s":"VETETH","b":"0.00009381","B":"94986.00000000","a":"0.00009403","A":"20330.00000000"}}
1618677380.9936829: {"stream":"veteth@bookTicker","data":{"u":327913009,"s":"VETETH","b":"0.00009381","B":"94986.00000000","a":"0.00009403","A":"108736.00000000"}}
1618677381.0204349: {"stream":"veteth@bookTicker","data":{"u":327913010,"s":"VETETH","b":"0.00009382","B":"19700.00000000","a":"0.00009403","A":"108736.00000000"}}
1618677381.0225558: {"stream":"veteth@bookTicker","data":{"u":327913011,"s":"VETETH","b":"0.00009381","B":"94986.00000000","a":"0.00009403","A":"108736.00000000"}}
1618677381.02779: {"stream":"aaveupusdt@bookTicker","data":{"u":82463809,"s":"AAVEUPUSDT","b":"84.57900000","B":"0.25000000","a":"84.93500000","A":"0.74000000"}}
1618677381.0561202: {"stream":"veteth@bookTicker","data":{"u":327913012,"s":"VETETH","b":"0.00009382","B":"66441.00000000","a":"0.00009403","A":"108736.00000000"}}
1618677381.0797372: {"stream":"veteth@depth@100ms","data":{"e":"depthUpdate","E":1618677381025,"s":"VETETH","U":327913008,"u":327913013,"b":[["0.00009382","66441.00000000"],["0.00009381","0.00000000"]],"a":[["0.00009403","108736.00000000"]]}}
1618677381.080888: {"stream":"aaveupusdt@depth@100ms","data":{"e":"depthUpdate","E":1618677381025,"s":"AAVEUPUSDT","U":82463808,"u":82463813,"b":[["84.58100000","0.00000000"],["84.57900000","0.25000000"],["84.39400000","2.56000000"]],"a":[["85.33800000","0.00000000"],["85.42500000","234.63000000"],["85.66200000","2.56000000"]]}}
1618677381.094677: {"stream":"swrvbusd@bookTicker","data":{"u":64830221,"s":"SWRVBUSD","b":"2.27200000","B":"4.44900000","a":"2.27600000","A":"20.45400000"}}
1618677381.098806: {"stream":"swrvbusd@bookTicker","data":{"u":64830222,"s":"SWRVBUSD","b":"2.27200000","B":"4.44900000","a":"2.27700000","A":"1.19200000"}}
1618677381.1213472: {"stream":"veteth@bookTicker","data":{"u":327913015,"s":"VETETH","b":"0.00009383","B":"94996.00000000","a":"0.00009403","A":"108736.00000000"}}
1618677381.180237: {"stream":"veteth@depth@100ms","data":{"e":"depthUpdate","E":1618677381125,"s":"VETETH","U":327913014,"u":327913016,"b":[["0.00009383","94996.00000000"],["0.00009382","0.00000000"],["0.00009357","2177.00000000"]],"a":[]}}
1618677381.180419: {"stream":"qspbtc@depth@100ms","data":{"e":"depthUpdate","E":1618677381125,"s":"QSPBTC","U":105811213,"u":105811213,"b":[],"a":[["0.00000196","73029.00000000"]]}}
1618677381.1805: {"stream":"swrvbusd@depth@100ms","data":{"e":"depthUpdate","E":1618677381125,"s":"SWRVBUSD","U":64830221,"u":64830223,"b":[["2.27300000","0.00000000"]],"a":[["2.27600000","0.00000000"],["2.28000000","6.15600000"]]}}
1618677381.180568: {"stream":"steemeth@depth@100ms","data":{"e":"depthUpdate","E":1618677381125,"s":"STEEMETH","U":126265007,"u":126265007,"b":[["0.00050100","471.02000000"]],"a":[]}}
1618677381.181176: {"stream":"aaveupusdt@depth@100ms","data":{"e":"depthUpdate","E":1618677381125,"s":"AAVEUPUSDT","U":82463814,"u":82463814,"b":[],"a":[["85.20500000","0.00000000"]]}}
1618677381.212012: {"stream":"swrvbusd@bookTicker","data":{"u":64830224,"s":"SWRVBUSD","b":"2.27200000","B":"4.44900000","a":"2.27600000","A":"20.45400000"}}
1618677381.212094: {"stream":"swrvbusd@bookTicker","data":{"u":64830225,"s":"SWRVBUSD","b":"2.27300000","B":"21.99200000","a":"2.27600000","A":"20.45400000"}}
1618677381.279922: {"stream":"swrvbusd@depth@100ms","data":{"e":"depthUpdate","E":1618677381225,"s":"SWRVBUSD","U":64830224,"u":64830227,"b":[["2.27300000","21.99200000"]],"a":[["2.27600000","20.45400000"],["2.28000000","224.56400000"],["2.28100000","10.89400000"]]}}
1618677381.2801049: {"stream":"aaveupusdt@depth@100ms","data":{"e":"depthUpdate","E":1618677381225,"s":"AAVEUPUSDT","U":82463815,"u":82463817,"b":[["84.57400000","11.58000000"],["80.90500000","0.00000000"]],"a":[]}}
1618677381.321236: {"stream":"veteth@bookTicker","data":{"u":327913017,"s":"VETETH","b":"0.00009380","B":"4016.00000000","a":"0.00009403","A":"108736.00000000"}}
1618677381.3590431: {"stream":"veteth@bookTicker","data":{"u":327913018,"s":"VETETH","b":"0.00009381","B":"94996.00000000","a":"0.00009403","A":"108736.00000000"}}
1618677381.383435: {"stream":"veteth@depth@100ms","data":{"e":"depthUpdate","E":1618677381325,"s":"VETETH","U":327913017,"u":327913018,"b":[["0.00009383","0.00000000"],["0.00009381","94996.00000000"]],"a":[]}}
1618677381.383606: {"stream":"swrvbusd@depth@100ms","data":{"e":"depthUpdate","E":1618677381325,"s":"SWRVBUSD","U":64830228,"u":64830228,"b":[],"a":[["2.28700000","10.99800000"]]}}
1618677381.389622: {"stream":"aaveupusdt@depth@100ms","data":{"e":"depthUpdate","E":1618677381325,"s":"AAVEUPUSDT","U":82463818,"u":82463820,"b":[["84.39400000","0.00000000"],["81.60800000","0.13000000"]],"a":[["85.66200000","0.00000000"]]}}
1618677381.482419: {"stream":"veteth@depth@100ms","data":{"e":"depthUpdate","E":1618677381425,"s":"VETETH","U":327913019,"u":327913019,"b":[["0.00009151","669.00000000"]],"a":[]}}
1618677381.490008: {"stream":"aaveupusdt@depth@100ms","data":{"e":"depthUpdate","E":1618677381425,"s":"AAVEUPUSDT","U":82463821,"u":82463821,"b":[["84.39100000","0.00000000"]],"a":[]}}
1618677381.613423: {"stream":"veteth@bookTicker","data":{"u":327913020,"s":"VETETH","b":"0.00009381","B":"94996.00000000","a":"0.00009403","A":"20330.00000000"}}
1618677381.6388412: {"stream":"veteth@bookTicker","data":{"u":327913021,"s":"VETETH","b":"0.00009381","B":"94996.00000000","a":"0.00009403","A":"108736.00000000"}}
1618677381.6477928: {"stream":"veteth@bookTicker","data":{"u":327913022,"s":"VETETH","b":"0.00009381","B":"94996.00000000","a":"0.00009403","A":"20330.00000000"}}
1618677381.6795578: {"stream":"swrvbusd@bookTicker","data":{"u":64830229,"s":"SWRVBUSD","b":"2.27200000","B":"4.44900000","a":"2.27600000","A":"20.45400000"}}
1618677381.679641: {"stream":"swrvbusd@bookTicker","data":{"u":64830230,"s":"SWRVBUSD","b":"2.27200000","B":"4.44900000","a":"2.27700000","A":"1.19200000"}}
1618677381.679677: {"stream":"veteth@depth@100ms","data":{"e":"depthUpdate","E":1618677381625,"s":"VETETH","U":327913020,"u":327913022,"b":[],"a":[["0.00009403","20330.00000000"]]}}
1618677381.682692: {"stream":"swrvbusd@depth@100ms","data":{"e":"depthUpdate","E":1618677381625,"s":"SWRVBUSD","U":64830229,"u":64830230,"b":[["2.27300000","0.00000000"]],"a":[["2.27600000","0.00000000"]]}}
1618677381.682814: {"stream":"aaveupusdt@depth@100ms","data":{"e":"depthUpdate","E":1618677381626,"s":"AAVEUPUSDT","U":82463822,"u":82463822,"b":[["84.57400000","17.37000000"]],"a":[]}}
1618677381.75948: {"stream":"swrvbusd@bookTicker","data":{"u":64830231,"s":"SWRVBUSD","b":"2.27200000","B":"4.44900000","a":"2.27600000","A":"20.45400000"}}
1618677381.759561: {"stream":"swrvbusd@bookTicker","data":{"u":64830232,"s":"SWRVBUSD","b":"2.27300000","B":"21.99200000","a":"2.27600000","A":"20.45400000"}}
1618677381.7853792: {"stream":"swrvbusd@depth@100ms","data":{"e":"depthUpdate","E":1618677381725,"s":"SWRVBUSD","U":64830231,"u":64830233,"b":[["2.27300000","21.99200000"],["2.27100000","133.36000000"],["2.27000000","194.05300000"]],"a":[["2.27600000","20.45400000"]]}}
1618677381.7855601: {"stream":"aaveupusdt@depth@100ms","data":{"e":"depthUpdate","E":1618677381726,"s":"AAVEUPUSDT","U":82463823,"u":82463825,"b":[["84.57400000","11.58000000"]],"a":[["85.34900000","282.12000000"],["85.42500000","0.00000000"]]}}
1618677381.881878: {"stream":"swrvbusd@depth@100ms","data":{"e":"depthUpdate","E":1618677381825,"s":"SWRVBUSD","U":64830234,"u":64830236,"b":[["2.27200000","0.00000000"],["2.27100000","166.33400000"],["2.27000000","225.74600000"]],"a":[]}}
1618677381.889241: {"stream":"aaveupusdt@depth@100ms","data":{"e":"depthUpdate","E":1618677381826,"s":"AAVEUPUSDT","U":82463826,"u":82463826,"b":[["84.57400000","5.79000000"]],"a":[]}}
1618677381.889376: {"stream":"veteth@bookTicker","data":{"u":327913023,"s":"VETETH","b":"0.00009381","B":"94996.00000000","a":"0.00009403","A":"108736.00000000"}}
1618677381.915036: {"stream":"veteth@bookTicker","data":{"u":327913024,"s":"VETETH","b":"0.00009381","B":"94996.00000000","a":"0.00009403","A":"20330.00000000"}}
1618677381.968451: {"stream":"veteth@bookTicker","data":{"u":327913025,"s":"VETETH","b":"0.00009382","B":"26856.00000000","a":"0.00009403","A":"20330.00000000"}}
1618677381.981874: {"stream":"veteth@bookTicker","data":{"u":327913026,"s":"VETETH","b":"0.00009381","B":"94996.00000000","a":"0.00009403","A":"20330.00000000"}}
1618677381.981956: {"stream":"veteth@depth@100ms","data":{"e":"depthUpdate","E":1618677381925,"s":"VETETH","U":327913023,"u":327913026,"b":[["0.00009382","0.00000000"]],"a":[["0.00009403","20330.00000000"]]}}
1618677381.989228: {"stream":"qspbtc@depth@100ms","data":{"e":"depthUpdate","E":1618677381925,"s":"QSPBTC","U":105811214,"u":105811214,"b":[["0.00000151","38785.00000000"]],"a":[]}}
1618677381.9893591: {"stream":"aaveupusdt@depth@100ms","data":{"e":"depthUpdate","E":1618677381926,"s":"AAVEUPUSDT","U":82463827,"u":82463829,"b":[["84.57800000","13.49000000"],["84.10500000","0.00000000"],["84.03500000","153.21000000"]],"a":[]}}
1618677381.993951: {"stream":"swrvbusd@kline_1m","data":{"e":"kline","E":1618677381932,"s":"SWRVBUSD","k":{"t":1618677360000,"T":1618677419999,"s":"SWRVBUSD","i":"1m","f":1135631,"L":1135638,"o":"2.27700000","c":"2.27200000","h":"2.27700000","l":"2.27200000","v":"276.52300000","n":8,"x":false,"q":"628.39723800","V":"21.96300000","Q":"49.98778800","B":"0"}}}
1618677381.994071: {"stream":"veteth@bookTicker","data":{"u":327913027,"s":"VETETH","b":"0.00009382","B":"21979.00000000","a":"0.00009403","A":"20330.00000000"}}
1618677381.994115: {"stream":"veteth@bookTicker","data":{"u":327913028,"s":"VETETH","b":"0.00009381","B":"94996.00000000","a":"0.00009403","A":"20330.00000000"}}
1618677382.002354: {"stream":"veteth@bookTicker","data":{"u":327913029,"s":"VETETH","b":"0.00009382","B":"17966.00000000","a":"0.00009403","A":"20330.00000000"}}
1618677382.028044: {"stream":"veteth@bookTicker","data":{"u":327913031,"s":"VETETH","b":"0.00009380","B":"4016.00000000","a":"0.00009403","A":"20330.00000000"}}
1618677382.099825: {"stream":"veteth@depth@100ms","data":{"e":"depthUpdate","E":1618677382025,"s":"VETETH","U":327913027,"u":327913031,"b":[["0.00009382","0.00000000"],["0.00009381","0.00000000"]],"a":[]}}
1618677382.099984: {"stream":"perlbnb@depth@100ms","data":{"e":"depthUpdate","E":1618677382025,"s":"PERLBNB","U":97581330,"u":97581331,"b":[],"a":[["0.00039500","15.00000000"]]}}
1618677382.100069: {"stream":"swrvbusd@depth@100ms","data":{"e":"depthUpdate","E":1618677382025,"s":"SWRVBUSD","U":64830237,"u":64830237,"b":[["2.26900000","0.00000000"]],"a":[]}}
1618677382.1001139: {"stream":"aaveupusdt@depth@100ms","data":{"e":"depthUpdate","E":1618677382026,"s":"AAVEUPUSDT","U":82463830,"u":82463833,"b":[["84.57800000","11.58000000"],["84.57400000","5.79000000"]],"a":[]}}
1618677382.100153: {"stream":"veteth@bookTicker","data":{"u":327913032,"s":"VETETH","b":"0.00009383","B":"94996.00000000","a":"0.00009403","A":"20330.00000000"}}
1618677382.185785: {"stream":"veteth@depth@100ms","data":{"e":"depthUpdate","E":1618677382125,"s":"VETETH","U":327913032,"u":327913033,"b":[["0.00009383","94996.00000000"],["0.00009280","0.00000000"]],"a":[]}}
1618677382.185961: {"stream":"perlbnb@depth@100ms","data":{"e":"depthUpdate","E":1618677382125,"s":"PERLBNB","U":97581332,"u":97581332,"b":[],"a":[["0.00039600","3676.00000000"]]}}
1618677382.186027: {"stream":"swrvbusd@depth@100ms","data":{"e":"depthUpdate","E":1618677382125,"s":"SWRVBUSD","U":64830238,"u":64830238,"b":[["2.16900000","0.00000000"]],"a":[]}}
1618677382.186118: {"stream":"aaveupusdt@depth@100ms","data":{"e":"depthUpdate","E":1618677382126,"s":"AAVEUPUSDT","U":82463834,"u":82463836,"b":[["84.57400000","11.58000000"],["84.11900000","2.57000000"]],"a":[["85.58400000","2.57000000"]]}}
1618677382.245286: {"stream":"veteth@bookTicker","data":{"u":327913034,"s":"VETETH","b":"0.00009380","B":"4016.00000000","a":"0.00009403","A":"20330.00000000"}}
1618677382.278508: {"stream":"veteth@depth@100ms","data":{"e":"depthUpdate","E":1618677382225,"s":"VETETH","U":327913034,"u":327913034,"b":[["0.00009383","0.00000000"]],"a":[]}}
1618677382.278659: {"stream":"perlbnb@depth@100ms","data":{"e":"depthUpdate","E":1618677382225,"s":"PERLBNB","U":97581333,"u":97581334,"b":[],"a":[["0.00039600","3731.00000000"]]}}
1618677382.281625: {"stream":"aaveupusdt@depth@100ms","data":{"e":"depthUpdate","E":1618677382226,"s":"AAVEUPUSDT","U":82463837,"u":82463840,"b":[["84.57800000","5.79000000"],["84.55800000","5.79000000"]],"a":[["85.27600000","254.24000000"],["85.34900000","0.00000000"]]}}
1618677382.336234: {"stream":"veteth@bookTicker","data":{"u":327913035,"s":"VETETH","b":"0.00009381","B":"94996.00000000","a":"0.00009403","A":"20330.00000000"}}
1618677382.3535979: {"stream":"swrvbusd@bookTicker","data":{"u":64830239,"s":"SWRVBUSD","b":"2.27300000","B":"21.99200000","a":"2.27700000","A":"1.19200000"}}
1618677382.357711: {"stream":"swrvbusd@bookTicker","data":{"u":64830240,"s":"SWRVBUSD","b":"2.27100000","B":"166.33400000","a":"2.27700000","A":"1.19200000"}}
1618677382.379478: {"stream":"veteth@depth@100ms","data":{"e":"depthUpdate","E":1618677382325,"s":"VETETH","U":327913035,"u":327913036,"b":[["0.00009381","94996.00000000"],["0.00009372","4220.00000000"]],"a":[]}}
1618677382.379641: {"stream":"perlbnb@depth@100ms","data":{"e":"depthUpdate","E":1618677382325,"s":"PERLBNB","U":97581335,"u":97581335,"b":[],"a":[["0.00039500","2490.00000000"]]}}
1618677382.3797052: {"stream":"swrvbusd@depth@100ms","data":{"e":"depthUpdate","E":1618677382326,"s":"SWRVBUSD","U":64830239,"u":64830240,"b":[["2.27300000","0.00000000"]],"a":[["2.27600000","0.00000000"]]}}
1618677382.381461: {"stream":"aaveupusdt@depth@100ms","data":{"e":"depthUpdate","E":1618677382326,"s":"AAVEUPUSDT","U":82463841,"u":82463843,"b":[["84.57800000","0.00000000"],["84.39300000","0.00000000"],["84.23900000","0.00000000"]],"a":[]}}
1618677382.390947: {"stream":"aaveupusdt@bookTicker","data":{"u":82463844,"s":"AAVEUPUSDT","b":"84.58000000","B":"0.17000000","a":"84.93500000","A":"0.74000000"}}
1618677382.4809961: {"stream":"veteth@depth@100ms","data":{"e":"depthUpdate","E":1618677382425,"s":"VETETH","U":327913037,"u":327913037,"b":[["0.00009270","163196.00000000"]],"a":[]}}
1618677382.481089: {"stream":"perlbnb@depth@100ms","data":{"e":"depthUpdate","E":1618677382425,"s":"PERLBNB","U":97581336,"u":97581336,"b":[],"a":[["0.00039500","15.00000000"]]}}
1618677382.481131: {"stream":"swrvbusd@depth@100ms","data":{"e":"depthUpdate","E":1618677382426,"s":"SWRVBUSD","U":64830241,"u":64830243,"b":[["2.26500000","133.36000000"],["2.15300000","22818.61600000"]],"a":[["2.28300000","107.85500000"]]}}
1618677382.4814389: {"stream":"aaveupusdt@depth@100ms","data":{"e":"depthUpdate","E":1618677382426,"s":"AAVEUPUSDT","U":82463844,"u":82463847,"b":[["84.58000000","0.17000000"],["84.57400000","5.79000000"],["84.55800000","0.00000000"],["83.98200000","0.39000000"]],"a":[]}}
1618677382.4828281: {"stream":"swrvbusd@bookTicker","data":{"u":64830244,"s":"SWRVBUSD","b":"2.27200000","B":"22.00200000","a":"2.27700000","A":"1.19200000"}}
1618677382.484421: {"stream":"swrvbusd@bookTicker","data":{"u":64830245,"s":"SWRVBUSD","b":"2.27200000","B":"22.00200000","a":"2.27600000","A":"20.45400000"}}
1618677382.490007: {"stream":"veteth@bookTicker","data":{"u":327913038,"s":"VETETH","b":"0.00009380","B":"4016.00000000","a":"0.00009403","A":"20330.00000000"}}
1618677382.5084531: {"stream":"aaveupusdt@bookTicker","data":{"u":82463849,"s":"AAVEUPUSDT","b":"84.58100000","B":"0.25000000","a":"84.93500000","A":"0.74000000"}}
1618677382.556649: {"stream":"veteth@bookTicker","data":{"u":327913040,"s":"VETETH","b":"0.00009380","B":"4016.00000000","a":"0.00009403","A":"108736.00000000"}}
1618677382.567648: {"stream":"veteth@bookTicker","data":{"u":327913042,"s":"VETETH","b":"0.00009381","B":"94996.00000000","a":"0.00009403","A":"108736.00000000"}}
1618677382.5799859: {"stream":"veteth@depth@100ms","data":{"e":"depthUpdate","E":1618677382525,"s":"VETETH","U":327913038,"u":327913042,"b":[["0.00009381","94996.00000000"],["0.00009373","1127.00000000"],["0.00009372","0.00000000"]],"a":[["0.00009403","108736.00000000"]]}}
1618677382.580183: {"stream":"perlbnb@depth@100ms","data":{"e":"depthUpdate","E":1618677382525,"s":"PERLBNB","U":97581337,"u":97581338,"b":[],"a":[["0.00039600","3736.00000000"]]}}
1618677382.580247: {"stream":"swrvbusd@depth@100ms","data":{"e":"depthUpdate","E":1618677382526,"s":"SWRVBUSD","U":64830244,"u":64830247,"b":[["2.27200000","22.00200000"],["2.27100000","32.97400000"]],"a":[["2.27600000","20.45400000"],["2.28200000","97.50100000"]]}}
1618677382.582929: {"stream":"aaveupusdt@depth@100ms","data":{"e":"depthUpdate","E":1618677382526,"s":"AAVEUPUSDT","U":82463848,"u":82463853,"b":[["84.58100000","0.25000000"],["84.57900000","0.00000000"],["84.44100000","23.68000000"],["82.39200000","0.00000000"]],"a":[["85.58400000","0.00000000"]]}}
1618677382.6796548: {"stream":"veteth@depth@100ms","data":{"e":"depthUpdate","E":1618677382625,"s":"VETETH","U":327913043,"u":327913045,"b":[["0.00009373","0.00000000"],["0.00009372","0.00000000"]],"a":[]}}
1618677382.679817: {"stream":"swrvbusd@depth@100ms","data":{"e":"depthUpdate","E":1618677382626,"s":"SWRVBUSD","U":64830248,"u":64830248,"b":[],"a":[["2.28400000","12.61200000"]]}}
1618677382.683917: {"stream":"aaveupusdt@depth@100ms","data":{"e":"depthUpdate","E":1618677382627,"s":"AAVEUPUSDT","U":82463854,"u":82463854,"b":[["84.58000000","5.96000000"]],"a":[]}}
1618677382.723508: {"stream":"veteth@bookTicker","data":{"u":327913046,"s":"VETETH","b":"0.00009381","B":"94996.00000000","a":"0.00009403","A":"20330.00000000"}}
1618677382.7558908: {"stream":"veteth@bookTicker","data":{"u":327913047,"s":"VETETH","b":"0.00009381","B":"94996.00000000","a":"0.00009403","A":"108736.00000000"}}
1618677382.779474: {"stream":"veteth@depth@100ms","data":{"e":"depthUpdate","E":1618677382725,"s":"VETETH","U":327913046,"u":327913047,"b":[],"a":[["0.00009403","108736.00000000"]]}}
1618677382.779606: {"stream":"perlbnb@depth@100ms","data":{"e":"depthUpdate","E":1618677382725,"s":"PERLBNB","U":97581339,"u":97581339,"b":[["0.00039000","2250.00000000"]],"a":[]}}
1618677382.7816792: {"stream":"aaveupusdt@depth@100ms","data":{"e":"depthUpdate","E":1618677382726,"s":"AAVEUPUSDT","U":82463855,"u":82463858,"b":[["84.11900000","0.00000000"],["84.03500000","0.00000000"],["83.97000000","333.48000000"],["82.20300000","2.45000000"]],"a":[]}}
1618677382.879479: {"stream":"perlbnb@depth@100ms","data":{"e":"depthUpdate","E":1618677382825,"s":"PERLBNB","U":97581340,"u":97581340,"b":[["0.00039000","25217.00000000"]],"a":[]}}
1618677382.8826728: {"stream":"aaveupusdt@depth@100ms","data":{"e":"depthUpdate","E":1618677382826,"s":"AAVEUPUSDT","U":82463859,"u":82463859,"b":[["84.55800000","5.79000000"]],"a":[]}}
1618677382.907228: {"stream":"swrvbusd@bookTicker","data":{"u":64830249,"s":"SWRVBUSD","b":"2.27200000","B":"22.00200000","a":"2.27700000","A":"1.19200000"}}
1618677382.916818: {"stream":"aaveupusdt@bookTicker","data":{"u":82463862,"s":"AAVEUPUSDT","b":"84.58100000","B":"0.25000000","a":"84.93400000","A":"94.16000000"}}
1618677382.9286761: {"stream":"aaveupusdt@bookTicker","data":{"u":82463863,"s":"AAVEUPUSDT","b":"84.58100000","B":"0.25000000","a":"84.93400000","A":"200.09000000"}}
1618677382.934381: {"stream":"aaveupusdt@bookTicker","data":{"u":82463864,"s":"AAVEUPUSDT","b":"84.58100000","B":"0.25000000","a":"84.93400000","A":"221.49000000"}}
1618677382.946265: {"stream":"veteth@bookTicker","data":{"u":327913048,"s":"VETETH","b":"0.00009381","B":"128469.00000000","a":"0.00009403","A":"108736.00000000"}}
1618677382.981556: {"stream":"veteth@depth@100ms","data":{"e":"depthUpdate","E":1618677382925,"s":"VETETH","U":327913048,"u":327913048,"b":[["0.00009381","128469.00000000"]],"a":[]}}
1618677382.982112: {"stream":"swrvbusd@depth@100ms","data":{"e":"depthUpdate","E":1618677382926,"s":"SWRVBUSD","U":64830249,"u":64830250,"b":[["2.27100000","39.12900000"]],"a":[["2.27600000","0.00000000"]]}}
1618677382.985363: {"stream":"steemeth@depth@100ms","data":{"e":"depthUpdate","E":1618677382926,"s":"STEEMETH","U":126265008,"u":126265008,"b":[["0.00050100","749.97000000"]],"a":[]}}
1618677382.985494: {"stream":"aaveupusdt@depth@100ms","data":{"e":"depthUpdate","E":1618677382926,"s":"AAVEUPUSDT","U":82463860,"u":82463865,"b":[["84.58000000","0.00000000"],["84.57400000","0.00000000"]],"a":[["84.93400000","221.49000000"]]}}
1618677382.985641: {"stream":"veteth@bookTicker","data":{"u":327913049,"s":"VETETH","b":"0.00009381","B":"128469.00000000","a":"0.00009403","A":"88406.00000000"}}
1618677382.9856791: {"stream":"swrvbusd@bookTicker","data":{"u":64830251,"s":"SWRVBUSD","b":"2.27200000","B":"22.00200000","a":"2.27600000","A":"20.45400000"}}
1618677382.994633: {"stream":"veteth@bookTicker","data":{"u":327913050,"s":"VETETH","b":"0.00009381","B":"94996.00000000","a":"0.00009403","A":"88406.00000000"}}
1618677383.000163: {"stream":"gtobtc@bookTicker","data":{"u":137196733,"s":"GTOBTC","b":"0.00000162","B":"49627.00000000","a":"0.00000163","A":"345860.00000000"}}
1618677383.0786262: {"stream":"veteth@depth@100ms","data":{"e":"depthUpdate","E":1618677383025,"s":"VETETH","U":327913049,"u":327913050,"b":[["0.00009381","94996.00000000"]],"a":[["0.00009403","88406.00000000"]]}}
1618677383.08092: {"stream":"swrvbusd@depth@100ms","data":{"e":"depthUpdate","E":1618677383026,"s":"SWRVBUSD","U":64830251,"u":64830254,"b":[["2.27100000","6.15500000"],["2.27000000","194.05300000"],["2.26600000","32.98100000"],["2.26500000","165.06100000"]],"a":[["2.27600000","20.45400000"]]}}
1618677383.0810308: {"stream":"gtobtc@depth@100ms","data":{"e":"depthUpdate","E":1618677383026,"s":"GTOBTC","U":137196733,"u":137196733,"b":[["0.00000162","49627.00000000"]],"a":[]}}
1618677383.0810728: {"stream":"aaveupusdt@depth@100ms","data":{"e":"depthUpdate","E":1618677383026,"s":"AAVEUPUSDT","U":82463866,"u":82463870,"b":[["84.58000000","5.79000000"],["84.57400000","5.79000000"],["84.55800000","0.00000000"],["84.11900000","2.57000000"]],"a":[["85.49900000","2.57000000"]]}}
1618677383.189112: {"stream":"perlbnb@depth@100ms","data":{"e":"depthUpdate","E":1618677383125,"s":"PERLBNB","U":97581341,"u":97581342,"b":[],"a":[["0.00039600","3731.00000000"]]}}
1618677383.1892421: {"stream":"aaveupusdt@depth@100ms","data":{"e":"depthUpdate","E":1618677383126,"s":"AAVEUPUSDT","U":82463871,"u":82463871,"b":[["84.58000000","11.58000000"]],"a":[]}}
1618677383.2725: {"stream":"veteth@bookTicker","data":{"u":327913051,"s":"VETETH","b":"0.00009381","B":"94996.00000000","a":"0.00009402","A":"20330.00000000"}}
1618677383.281024: {"stream":"veteth@depth@100ms","data":{"e":"depthUpdate","E":1618677383225,"s":"VETETH","U":327913051,"u":327913051,"b":[],"a":[["0.00009402","20330.00000000"]]}}
1618677383.281178: {"stream":"perlbnb@depth@100ms","data":{"e":"depthUpdate","E":1618677383225,"s":"PERLBNB","U":97581343,"u":97581343,"b":[],"a":[["0.00039500","2488.00000000"]]}}
1618677383.2812438: {"stream":"aaveupusdt@depth@100ms","data":{"e":"depthUpdate","E":1618677383226,"s":"AAVEUPUSDT","U":82463872,"u":82463873,"b":[["84.44100000","0.00000000"]],"a":[]}}
1618677383.314156: {"stream":"veteth@bookTicker","data":{"u":327913054,"s":"VETETH","b":"0.00009381","B":"94996.00000000","a":"0.00009401","A":"88406.00000000"}}
1618677383.3792698: {"stream":"veteth@depth@100ms","data":{"e":"depthUpdate","E":1618677383325,"s":"VETETH","U":327913052,"u":327913054,"b":[],"a":[["0.00009401","88406.00000000"],["0.00009403","0.00000000"],["0.00009446","174.00000000"]]}}
1618677383.3794591: {"stream":"perlbnb@depth@100ms","data":{"e":"depthUpdate","E":1618677383325,"s":"PERLBNB","U":97581344,"u":97581344,"b":[],"a":[["0.00039600","1262.00000000"]]}}
1618677383.3798249: {"stream":"swrvbusd@depth@100ms","data":{"e":"depthUpdate","E":1618677383326,"s":"SWRVBUSD","U":64830255,"u":64830255,"b":[["2.27000000","95.46200000"]],"a":[]}}
1618677383.381547: {"stream":"aaveupusdt@depth@100ms","data":{"e":"depthUpdate","E":1618677383326,"s":"AAVEUPUSDT","U":82463874,"u":82463876,"b":[["84.57400000","11.58000000"],["84.11900000","0.00000000"]],"a":[["85.49900000","0.00000000"]]}}
1618677383.472119: {"stream":"swrvbusd@bookTicker","data":{"u":64830257,"s":"SWRVBUSD","b":"2.27000000","B":"95.46200000","a":"2.27600000","A":"20.45400000"}}
1618677383.472202: {"stream":"swrvbusd@bookTicker","data":{"u":64830258,"s":"SWRVBUSD","b":"2.27000000","B":"95.46200000","a":"2.27700000","A":"1.19200000"}}
1618677383.4802718: {"stream":"veteth@depth@100ms","data":{"e":"depthUpdate","E":1618677383425,"s":"VETETH","U":327913055,"u":327913055,"b":[],"a":[["0.00009412","27336.00000000"]]}}
1618677383.480403: {"stream":"perlbnb@depth@100ms","data":{"e":"depthUpdate","E":1618677383425,"s":"PERLBNB","U":97581345,"u":97581347,"b":[["0.00039000","2250.00000000"]],"a":[["0.00039500","15.00000000"],["0.00039600","3738.00000000"]]}}
1618677383.480486: {"stream":"swrvbusd@depth@100ms","data":{"e":"depthUpdate","E":1618677383426,"s":"SWRVBUSD","U":64830256,"u":64830258,"b":[["2.27200000","0.00000000"],["2.27100000","0.00000000"]],"a":[["2.27600000","0.00000000"]]}}
1618677383.48088: {"stream":"gtobtc@depth@100ms","data":{"e":"depthUpdate","E":1618677383426,"s":"GTOBTC","U":137196734,"u":137196735,"b":[["0.00000161","102929.00000000"]],"a":[]}}
1618677383.537965: {"stream":"swrvbusd@bookTicker","data":{"u":64830259,"s":"SWRVBUSD","b":"2.27100000","B":"22.01100000","a":"2.27700000","A":"1.19200000"}}
1618677383.540481: {"stream":"swrvbusd@bookTicker","data":{"u":64830260,"s":"SWRVBUSD","b":"2.27100000","B":"22.01100000","a":"2.27600000","A":"20.45400000"}}
1618677383.58205: {"stream":"swrvbusd@depth@100ms","data":{"e":"depthUpdate","E":1618677383526,"s":"SWRVBUSD","U":64830259,"u":64830261,"b":[["2.27100000","22.01100000"],["2.26700000","191.48800000"]],"a":[["2.27600000","20.45400000"]]}}
1618677383.582226: {"stream":"aaveupusdt@depth@100ms","data":{"e":"depthUpdate","E":1618677383526,"s":"AAVEUPUSDT","U":82463877,"u":82463877,"b":[],"a":[["102.00000000","71.43000000"]]}}
1618677383.681608: {"stream":"aaveupusdt@depth@100ms","data":{"e":"depthUpdate","E":1618677383626,"s":"AAVEUPUSDT","U":82463878,"u":82463878,"b":[["84.57400000","17.37000000"]],"a":[]}}
1618677383.781742: {"stream":"aaveupusdt@depth@100ms","data":{"e":"depthUpdate","E":1618677383726,"s":"AAVEUPUSDT","U":82463879,"u":82463883,"b":[["84.58000000","0.00000000"],["84.57400000","11.58000000"]],"a":[]}}
1618677383.8590631: {"stream":"aaveupusdt@bookTicker","data":{"u":82463886,"s":"AAVEUPUSDT","b":"84.57800000","B":"5.79000000","a":"84.93400000","A":"221.49000000"}}
1618677383.881448: {"stream":"aaveupusdt@depth@100ms","data":{"e":"depthUpdate","E":1618677383826,"s":"AAVEUPUSDT","U":82463884,"u":82463886,"b":[["84.58100000","0.00000000"],["84.57800000","5.79000000"],["84.57500000","0.25000000"]],"a":[]}}
1618677383.9818702: {"stream":"aaveupusdt@depth@100ms","data":{"e":"depthUpdate","E":1618677383926,"s":"AAVEUPUSDT","U":82463887,"u":82463887,"b":[["84.57400000","5.79000000"]],"a":[]}}
1618677384.0070689: {"stream":"aaveupusdt@bookTicker","data":{"u":82463889,"s":"AAVEUPUSDT","b":"84.57900000","B":"0.25000000","a":"84.93400000","A":"221.49000000"}}
1618677384.0822039: {"stream":"aaveupusdt@depth@100ms","data":{"e":"depthUpdate","E":1618677384027,"s":"AAVEUPUSDT","U":82463888,"u":82463894,"b":[["84.57900000","0.25000000"],["84.57800000","0.00000000"],["84.57500000","0.00000000"],["84.57400000","11.58000000"],["84.55700000","6.80000000"]],"a":[]}}
1618677384.090813: {"stream":"swrvbusd@bookTicker","data":{"u":64830262,"s":"SWRVBUSD","b":"2.27100000","B":"22.01100000","a":"2.27700000","A":"1.19200000"}}
1618677384.181001: {"stream":"perlbnb@depth@100ms","data":{"e":"depthUpdate","E":1618677384126,"s":"PERLBNB","U":97581348,"u":97581348,"b":[],"a":[["0.00039600","6207.00000000"]]}}
1618677384.181133: {"stream":"swrvbusd@depth@100ms","data":{"e":"depthUpdate","E":1618677384126,"s":"SWRVBUSD","U":64830262,"u":64830262,"b":[],"a":[["2.27600000","0.00000000"]]}}
1618677384.181223: {"stream":"aaveupusdt@depth@100ms","data":{"e":"depthUpdate","E":1618677384126,"s":"AAVEUPUSDT","U":82463895,"u":82463897,"b":[["84.57400000","17.37000000"],["84.11900000","2.57000000"]],"a":[["85.49900000","2.57000000"]]}}
1618677384.185869: {"stream":"swrvbusd@bookTicker","data":{"u":64830264,"s":"SWRVBUSD","b":"2.27100000","B":"22.01100000","a":"2.27600000","A":"20.45400000"}}
1618677384.21117: {"stream":"aaveupusdt@bookTicker","data":{"u":82463898,"s":"AAVEUPUSDT","b":"84.57400000","B":"17.37000000","a":"84.93400000","A":"221.49000000"}}
1618677384.211228: {"stream":"aaveupusdt@bookTicker","data":{"u":82463899,"s":"AAVEUPUSDT","b":"84.57500000","B":"0.25000000","a":"84.93400000","A":"221.49000000"}}
1618677384.232981: {"stream":"aaveupusdt@bookTicker","data":{"u":82463901,"s":"AAVEUPUSDT","b":"84.57500000","B":"0.25000000","a":"84.93300000","A":"1.50000000"}}
1618677384.28548: {"stream":"perlbnb@depth@100ms","data":{"e":"depthUpdate","E":1618677384226,"s":"PERLBNB","U":97581349,"u":97581349,"b":[["0.00039000","31235.00000000"]],"a":[]}}
1618677384.285614: {"stream":"qspbtc@depth@100ms","data":{"e":"depthUpdate","E":1618677384226,"s":"QSPBTC","U":105811215,"u":105811215,"b":[["0.00000149","11076.00000000"]],"a":[]}}
1618677384.28568: {"stream":"swrvbusd@depth@100ms","data":{"e":"depthUpdate","E":1618677384226,"s":"SWRVBUSD","U":64830263,"u":64830266,"b":[["2.26800000","32.98100000"],["2.26600000","0.00000000"],["2.26500000","165.06100000"]],"a":[["2.27600000","20.45400000"]]}}
1618677384.285797: {"stream":"aaveupusdt@depth@100ms","data":{"e":"depthUpdate","E":1618677384227,"s":"AAVEUPUSDT","U":82463898,"u":82463901,"b":[["84.57900000","0.00000000"],["84.57500000","0.25000000"],["84.57400000","11.58000000"]],"a":[["84.93300000","1.50000000"]]}}
1618677384.382524: {"stream":"aaveupusdt@depth@100ms","data":{"e":"depthUpdate","E":1618677384327,"s":"AAVEUPUSDT","U":82463902,"u":82463903,"b":[["84.57400000","0.00000000"]],"a":[]}}
1618677384.409149: {"stream":"aaveupusdt@bookTicker","data":{"u":82463904,"s":"AAVEUPUSDT","b":"84.55700000","B":"6.80000000","a":"84.93300000","A":"1.50000000"}}
1618677384.415723: {"stream":"aaveupusdt@bookTicker","data":{"u":82463905,"s":"AAVEUPUSDT","b":"84.58000000","B":"5.79000000","a":"84.93300000","A":"1.50000000"}}
1618677384.433951: {"stream":"aaveupusdt@bookTicker","data":{"u":82463907,"s":"AAVEUPUSDT","b":"84.58000000","B":"5.79000000","a":"84.93400000","A":"221.49000000"}}
1618677384.48107: {"stream":"swrvbusd@depth@100ms","data":{"e":"depthUpdate","E":1618677384426,"s":"SWRVBUSD","U":64830267,"u":64830267,"b":[["2.26800000","131.57200000"]],"a":[]}}
1618677384.481199: {"stream":"aaveupusdt@depth@100ms","data":{"e":"depthUpdate","E":1618677384427,"s":"AAVEUPUSDT","U":82463904,"u":82463908,"b":[["84.58000000","5.79000000"],["84.57500000","0.00000000"],["84.57400000","5.79000000"],["84.55800000","0.25000000"]],"a":[["84.93300000","0.00000000"]]}}
1618677384.4966981: {"stream":"aaveupusdt@bookTicker","data":{"u":82463910,"s":"AAVEUPUSDT","b":"84.58100000","B":"0.25000000","a":"84.93400000","A":"221.49000000"}}
1618677384.583342: {"stream":"aaveupusdt@depth@100ms","data":{"e":"depthUpdate","E":1618677384527,"s":"AAVEUPUSDT","U":82463909,"u":82463913,"b":[["84.58100000","0.25000000"],["84.58000000","0.00000000"],["84.55800000","0.00000000"]],"a":[["85.21300000","128.04000000"],["85.27600000","0.00000000"]]}}
1618677384.6010292: {"stream":"aaveupusdt@bookTicker","data":{"u":82463914,"s":"AAVEUPUSDT","b":"84.57400000","B":"5.79000000","a":"84.93400000","A":"221.49000000"}}
1618677384.601113: {"stream":"aaveupusdt@bookTicker","data":{"u":82463915,"s":"AAVEUPUSDT","b":"84.57500000","B":"0.25000000","a":"84.93400000","A":"221.49000000"}}
1618677384.6720672: {"stream":"veteth@aggTrade","data":{"e":"aggTrade","E":1618677384619,"s":"VETETH","a":5580638,"p":"0.00009401","q":"5615.00000000","f":6849496,"l":6849496,"T":1618677384617,"m":false,"M":true}}
1618677384.67212: {"stream":"veteth@kline_1m","data":{"e":"kline","E":1618677384619,"s":"VETETH","k":{"t":1618677360000,"T":1618677419999,"s":"VETETH","i":"1m","f":6849492,"L":6849496,"o":"0.00009392","c":"0.00009401","h":"0.00009402","l":"0.00009392","v":"16135.00000000","n":5,"x":false,"q":"1.51678633","V":"16135.00000000","Q":"1.51678633","B":"0"}}}
1618677384.6721501: {"stream":"veteth@bookTicker","data":{"u":327913056,"s":"VETETH","b":"0.00009381","B":"94996.00000000","a":"0.00009401","A":"82791.00000000"}}
1618677384.6805482: {"stream":"veteth@depth@100ms","data":{"e":"depthUpdate","E":1618677384626,"s":"VETETH","U":327913056,"u":327913057,"b":[],"a":[["0.00009401","82791.00000000"],["0.00009402","0.00000000"]]}}
1618677384.681222: {"stream":"aaveupusdt@depth@100ms","data":{"e":"depthUpdate","E":1618677384627,"s":"AAVEUPUSDT","U":82463914,"u":82463916,"b":[["84.58100000","0.00000000"],["84.57500000","0.25000000"],["84.57400000","0.00000000"]],"a":[]}}
1618677384.683627: {"stream":"veteth@bookTicker","data":{"u":327913058,"s":"VETETH","b":"0.00009381","B":"94996.00000000","a":"0.00009404","A":"9006.00000000"}}
1618677384.6856818: {"stream":"swrvbusd@bookTicker","data":{"u":64830268,"s":"SWRVBUSD","b":"2.27100000","B":"22.01100000","a":"2.27700000","A":"1.19200000"}}
1618677384.686729: {"stream":"aaveupusdt@bookTicker","data":{"u":82463917,"s":"AAVEUPUSDT","b":"84.55700000","B":"6.80000000","a":"84.93400000","A":"221.49000000"}}
1618677384.691138: {"stream":"aaveupusdt@bookTicker","data":{"u":82463918,"s":"AAVEUPUSDT","b":"84.55800000","B":"0.25000000","a":"84.93400000","A":"221.49000000"}}
1618677384.753064: {"stream":"swrvbusd@bookTicker","data":{"u":64830270,"s":"SWRVBUSD","b":"2.27100000","B":"22.01100000","a":"2.27600000","A":"20.45400000"}}
1618677384.782592: {"stream":"veteth@depth@100ms","data":{"e":"depthUpdate","E":1618677384726,"s":"VETETH","U":327913058,"u":327913061,"b":[],"a":[["0.00009401","0.00000000"],["0.00009405","0.00000000"],["0.00009412","555.00000000"]]}}
1618677384.7827158: {"stream":"perlbnb@depth@100ms","data":{"e":"depthUpdate","E":1618677384726,"s":"PERLBNB","U":97581350,"u":97581351,"b":[],"a":[["0.00039500","2489.00000000"],["0.00039600","3731.00000000"]]}}
1618677384.782763: {"stream":"swrvbusd@depth@100ms","data":{"e":"depthUpdate","E":1618677384726,"s":"SWRVBUSD","U":64830268,"u":64830270,"b":[["2.26800000","137.72800000"]],"a":[["2.27600000","20.45400000"]]}}
1618677384.7828019: {"stream":"aaveupusdt@depth@100ms","data":{"e":"depthUpdate","E":1618677384727,"s":"AAVEUPUSDT","U":82463917,"u":82463918,"b":[["84.57500000","0.00000000"],["84.55800000","0.25000000"]],"a":[]}}
1618677384.832424: {"stream":"aaveupusdt@bookTicker","data":{"u":82463919,"s":"AAVEUPUSDT","b":"84.57400000","B":"5.79000000","a":"84.93400000","A":"221.49000000"}}
1618677384.848286: {"stream":"veteth@bookTicker","data":{"u":327913063,"s":"VETETH","b":"0.00009382","B":"28968.00000000","a":"0.00009404","A":"9006.00000000"}}
1618677384.8649511: {"stream":"veteth@bookTicker","data":{"u":327913065,"s":"VETETH","b":"0.00009383","B":"96556.00000000","a":"0.00009404","A":"9006.00000000"}}
1618677384.880546: {"stream":"veteth@depth@100ms","data":{"e":"depthUpdate","E":1618677384826,"s":"VETETH","U":327913062,"u":327913065,"b":[["0.00009383","96556.00000000"],["0.00009382","28968.00000000"],["0.00009381","0.00000000"]],"a":[["0.00009446","26044.00000000"]]}}
1618677384.880681: {"stream":"perlbnb@depth@100ms","data":{"e":"depthUpdate","E":1618677384826,"s":"PERLBNB","U":97581352,"u":97581352,"b":[],"a":[["0.00039600","1262.00000000"]]}}
1618677384.882447: {"stream":"aaveupusdt@depth@100ms","data":{"e":"depthUpdate","E":1618677384827,"s":"AAVEUPUSDT","U":82463919,"u":82463920,"b":[["84.57400000","5.79000000"],["84.55800000","0.00000000"]],"a":[]}}
1618677384.884953: {"stream":"aaveupusdt@bookTicker","data":{"u":82463921,"s":"AAVEUPUSDT","b":"84.57500000","B":"0.25000000","a":"84.93400000","A":"221.49000000"}}
1618677384.932658: {"stream":"aaveupusdt@bookTicker","data":{"u":82463923,"s":"AAVEUPUSDT","b":"84.57500000","B":"0.25000000","a":"84.93400000","A":"127.33000000"}}
1618677384.938636: {"stream":"aaveupusdt@bookTicker","data":{"u":82463924,"s":"AAVEUPUSDT","b":"84.57500000","B":"0.25000000","a":"84.93400000","A":"21.40000000"}}
1618677384.940031: {"stream":"aaveupusdt@bookTicker","data":{"u":82463925,"s":"AAVEUPUSDT","b":"84.57500000","B":"0.25000000","a":"84.93500000","A":"0.74000000"}}
1618677384.978566: {"stream":"veteth@depth@100ms","data":{"e":"depthUpdate","E":1618677384926,"s":"VETETH","U":327913066,"u":327913066,"b":[["0.00009356","542.00000000"]],"a":[]}}
1618677384.982743: {"stream":"gtobtc@depth@100ms","data":{"e":"depthUpdate","E":1618677384926,"s":"GTOBTC","U":137196736,"u":137196736,"b":[["0.00000151","115632.00000000"]],"a":[]}}
1618677384.982789: {"stream":"aaveupusdt@depth@100ms","data":{"e":"depthUpdate","E":1618677384927,"s":"AAVEUPUSDT","U":82463921,"u":82463926,"b":[["84.57500000","0.25000000"],["84.57400000","5.79000000"]],"a":[["84.93400000","0.00000000"]]}}
1618677384.9945369: {"stream":"veteth@bookTicker","data":{"u":327913067,"s":"VETETH","b":"0.00009383","B":"96556.00000000","a":"0.00009403","A":"82791.00000000"}}
1618677385.07915: {"stream":"veteth@depth@100ms","data":{"e":"depthUpdate","E":1618677385026,"s":"VETETH","U":327913067,"u":327913067,"b":[],"a":[["0.00009403","82791.00000000"]]}}
1618677385.0812302: {"stream":"aaveupusdt@depth@100ms","data":{"e":"depthUpdate","E":1618677385027,"s":"AAVEUPUSDT","U":82463927,"u":82463927,"b":[["84.57400000","0.00000000"]],"a":[]}}
1618677385.179803: {"stream":"veteth@depth@100ms","data":{"e":"depthUpdate","E":1618677385126,"s":"VETETH","U":327913068,"u":327913068,"b":[["0.00009352","24985.00000000"]],"a":[]}}
1618677385.179896: {"stream":"gtobtc@depth@100ms","data":{"e":"depthUpdate","E":1618677385126,"s":"GTOBTC","U":137196737,"u":137196737,"b":[["0.00000151","119406.00000000"]],"a":[]}}
1618677385.180235: {"stream":"aaveupusdt@depth@100ms","data":{"e":"depthUpdate","E":1618677385127,"s":"AAVEUPUSDT","U":82463928,"u":82463929,"b":[],"a":[["85.49900000","0.00000000"],["85.58400000","2.57000000"]]}}
1618677385.206534: {"stream":"aaveupusdt@bookTicker","data":{"u":82463931,"s":"AAVEUPUSDT","b":"84.57600000","B":"0.17000000","a":"84.93500000","A":"0.74000000"}}
1618677385.279723: {"stream":"aaveupusdt@bookTicker","data":{"u":82463932,"s":"AAVEUPUSDT","b":"84.57700000","B":"0.25000000","a":"84.93500000","A":"0.74000000"}}
1618677385.2797492: {"stream":"veteth@depth@100ms","data":{"e":"depthUpdate","E":1618677385226,"s":"VETETH","U":327913069,"u":327913069,"b":[["0.00009382","0.00000000"]],"a":[]}}
1618677385.281573: {"stream":"aaveupusdt@depth@100ms","data":{"e":"depthUpdate","E":1618677385227,"s":"AAVEUPUSDT","U":82463930,"u":82463932,"b":[["84.57700000","0.25000000"],["84.57600000","0.17000000"]],"a":[["85.58400000","0.00000000"]]}}
1618677385.300082: {"stream":"swrvbusd@bookTicker","data":{"u":64830271,"s":"SWRVBUSD","b":"2.27100000","B":"22.01100000","a":"2.27700000","A":"1.19200000"}}
1618677385.3644009: {"stream":"swrvbusd@bookTicker","data":{"u":64830272,"s":"SWRVBUSD","b":"2.27100000","B":"22.01100000","a":"2.27600000","A":"20.45400000"}}
1618677385.379437: {"stream":"swrvbusd@depth@100ms","data":{"e":"depthUpdate","E":1618677385326,"s":"SWRVBUSD","U":64830271,"u":64830273,"b":[["2.26800000","104.74700000"],["2.26500000","133.36000000"]],"a":[["2.27600000","20.45400000"]]}}
1618677385.381967: {"stream":"aaveupusdt@depth@100ms","data":{"e":"depthUpdate","E":1618677385327,"s":"AAVEUPUSDT","U":82463933,"u":82463933,"b":[["84.57500000","0.00000000"]],"a":[]}}
1618677385.3943198: {"stream":"veteth@bookTicker","data":{"u":327913070,"s":"VETETH","b":"0.00009380","B":"4016.00000000","a":"0.00009403","A":"82791.00000000"}}
1618677385.4060621: {"stream":"veteth@bookTicker","data":{"u":327913071,"s":"VETETH","b":"0.00009381","B":"96556.00000000","a":"0.00009403","A":"82791.00000000"}}
1618677385.4814458: {"stream":"veteth@depth@100ms","data":{"e":"depthUpdate","E":1618677385426,"s":"VETETH","U":327913070,"u":327913071,"b":[["0.00009383","0.00000000"],["0.00009381","96556.00000000"]],"a":[]}}
1618677385.4816399: {"stream":"swrvbusd@depth@100ms","data":{"e":"depthUpdate","E":1618677385426,"s":"SWRVBUSD","U":64830274,"u":64830275,"b":[["2.26800000","137.73500000"],["2.26600000","31.70800000"]],"a":[]}}
1618677385.5801358: {"stream":"veteth@depth@100ms","data":{"e":"depthUpdate","E":1618677385526,"s":"VETETH","U":327913072,"u":327913072,"b":[],"a":[["0.00009404","0.00000000"]]}}
1618677385.581432: {"stream":"aaveupusdt@depth@100ms","data":{"e":"depthUpdate","E":1618677385527,"s":"AAVEUPUSDT","U":82463934,"u":82463934,"b":[],"a":[["85.21200000","66.62000000"]]}}
1618677385.5922549: {"stream":"aaveupusdt@bookTicker","data":{"u":82463935,"s":"AAVEUPUSDT","b":"84.57700000","B":"0.25000000","a":"84.93400000","A":"21.40000000"}}
1618677385.599995: {"stream":"veteth@bookTicker","data":{"u":327913073,"s":"VETETH","b":"0.00009382","B":"4632.00000000","a":"0.00009403","A":"82791.00000000"}}
1618677385.602335: {"stream":"aaveupusdt@bookTicker","data":{"u":82463937,"s":"AAVEUPUSDT","b":"84.57700000","B":"0.25000000","a":"84.93400000","A":"115.56000000"}}
1618677385.602419: {"stream":"aaveupusdt@bookTicker","data":{"u":82463938,"s":"AAVEUPUSDT","b":"84.57700000","B":"0.25000000","a":"84.93400000","A":"221.49000000"}}
1618677385.6228192: {"stream":"veteth@bookTicker","data":{"u":327913075,"s":"VETETH","b":"0.00009383","B":"96556.00000000","a":"0.00009403","A":"82791.00000000"}}
1618677385.644211: {"stream":"veteth@bookTicker","data":{"u":327913076,"s":"VETETH","b":"0.00009383","B":"96556.00000000","a":"0.00009406","A":"555.00000000"}}
1618677385.651867: {"stream":"veteth@bookTicker","data":{"u":327913077,"s":"VETETH","b":"0.00009383","B":"96556.00000000","a":"0.00009405","A":"82791.00000000"}}
1618677385.658185: {"stream":"veteth@bookTicker","data":{"u":327913078,"s":"VETETH","b":"0.00009383","B":"96556.00000000","a":"0.00009404","A":"9006.00000000"}}
1618677385.673324: {"stream":"veteth@bookTicker","data":{"u":327913080,"s":"VETETH","b":"0.00009383","B":"96556.00000000","a":"0.00009403","A":"82791.00000000"}}
1618677385.679297: {"stream":"veteth@depth@100ms","data":{"e":"depthUpdate","E":1618677385626,"s":"VETETH","U":327913073,"u":327913081,"b":[["0.00009383","96556.00000000"],["0.00009382","4632.00000000"],["0.00009381","0.00000000"]],"a":[["0.00009403","82791.00000000"],["0.00009404","0.00000000"],["0.00009405","0.00000000"]]}}
1618677385.681639: {"stream":"aaveupusdt@depth@100ms","data":{"e":"depthUpdate","E":1618677385627,"s":"AAVEUPUSDT","U":82463935,"u":82463941,"b":[["84.57600000","0.00000000"],["84.57400000","17.37000000"]],"a":[["84.93400000","221.49000000"]]}}
1618677385.68172: {"stream":"veteth@bookTicker","data":{"u":327913082,"s":"VETETH","b":"0.00009383","B":"96556.00000000","a":"0.00009406","A":"555.00000000"}}
1618677385.695219: {"stream":"aaveupusdt@bookTicker","data":{"u":82463943,"s":"AAVEUPUSDT","b":"84.57500000","B":"0.25000000","a":"84.93400000","A":"221.49000000"}}
1618677385.695904: {"stream":"veteth@bookTicker","data":{"u":327913083,"s":"VETETH","b":"0.00009383","B":"96556.00000000","a":"0.00009405","A":"82791.00000000"}}
1618677385.7037718: {"stream":"veteth@bookTicker","data":{"u":327913084,"s":"VETETH","b":"0.00009383","B":"96556.00000000","a":"0.00009406","A":"555.00000000"}}
1618677385.779598: {"stream":"veteth@depth@100ms","data":{"e":"depthUpdate","E":1618677385726,"s":"VETETH","U":327913082,"u":327913085,"b":[],"a":[["0.00009403","0.00000000"],["0.00009405","0.00000000"],["0.00009407","82791.00000000"]]}}
1618677385.782388: {"stream":"aaveupusdt@depth@100ms","data":{"e":"depthUpdate","E":1618677385727,"s":"AAVEUPUSDT","U":82463942,"u":82463943,"b":[["84.57700000","0.00000000"],["84.57500000","0.25000000"]],"a":[]}}
1618677385.8490381: {"stream":"veteth@bookTicker","data":{"u":327913086,"s":"VETETH","b":"0.00009384","B":"125854.00000000","a":"0.00009406","A":"555.00000000"}}
1618677385.8738308: {"stream":"veteth@bookTicker","data":{"u":327913089,"s":"VETETH","b":"0.00009385","B":"96556.00000000","a":"0.00009406","A":"555.00000000"}}
1618677385.880192: {"stream":"veteth@depth@100ms","data":{"e":"depthUpdate","E":1618677385826,"s":"VETETH","U":327913086,"u":327913089,"b":[["0.00009385","96556.00000000"],["0.00009384","125854.00000000"],["0.00009383","0.00000000"]],"a":[["0.00009407","0.00000000"]]}}
1618677385.882679: {"stream":"aaveupusdt@depth@100ms","data":{"e":"depthUpdate","E":1618677385827,"s":"AAVEUPUSDT","U":82463944,"u":82463949,"b":[["84.57400000","0.00000000"],["84.39700000","11.85000000"],["84.11900000","0.00000000"]],"a":[["85.40000000","7.50000000"]]}}
1618677385.8942668: {"stream":"aaveupusdt@bookTicker","data":{"u":82463951,"s":"AAVEUPUSDT","b":"84.55800000","B":"0.25000000","a":"84.93400000","A":"221.49000000"}}
1618677385.918852: {"stream":"swrvbusd@bookTicker","data":{"u":64830276,"s":"SWRVBUSD","b":"2.27100000","B":"22.01100000","a":"2.27700000","A":"1.19200000"}}
1618677385.980767: {"stream":"swrvbusd@depth@100ms","data":{"e":"depthUpdate","E":1618677385926,"s":"SWRVBUSD","U":64830276,"u":64830276,"b":[],"a":[["2.27600000","0.00000000"]]}}
1618677385.982199: {"stream":"aaveupusdt@depth@100ms","data":{"e":"depthUpdate","E":1618677385927,"s":"AAVEUPUSDT","U":82463950,"u":82463951,"b":[["84.57500000","0.00000000"],["84.55800000","0.25000000"]],"a":[]}}
1618677385.994708: {"stream":"swrvbusd@bookTicker","data":{"u":64830277,"s":"SWRVBUSD","b":"2.27100000","B":"22.01100000","a":"2.27600000","A":"20.45400000"}}
1618677386.0793831: {"stream":"veteth@depth@100ms","data":{"e":"depthUpdate","E":1618677386026,"s":"VETETH","U":327913090,"u":327913090,"b":[],"a":[["0.00009418","231.00000000"]]}}
1618677386.081857: {"stream":"swrvbusd@depth@100ms","data":{"e":"depthUpdate","E":1618677386026,"s":"SWRVBUSD","U":64830277,"u":64830278,"b":[["2.26700000","9.28800000"]],"a":[["2.27600000","20.45400000"]]}}
1618677386.153582: {"stream":"veteth@bookTicker","data":{"u":327913092,"s":"VETETH","b":"0.00009386","B":"75920.00000000","a":"0.00009406","A":"555.00000000"}}
1618677386.187518: {"stream":"veteth@bookTicker","data":{"u":327913094,"s":"VETETH","b":"0.00009387","B":"96556.00000000","a":"0.00009406","A":"555.00000000"}}
1618677386.188048: {"stream":"veteth@depth@100ms","data":{"e":"depthUpdate","E":1618677386126,"s":"VETETH","U":327913091,"u":327913094,"b":[["0.00009387","96556.00000000"],["0.00009386","75920.00000000"],["0.00009385","0.00000000"],["0.00009384","0.00000000"]],"a":[]}}
1618677386.189644: {"stream":"swrvbusd@depth@100ms","data":{"e":"depthUpdate","E":1618677386127,"s":"SWRVBUSD","U":64830279,"u":64830279,"b":[["2.26800000","131.57900000"]],"a":[]}}
1618677386.2807791: {"stream":"veteth@depth@100ms","data":{"e":"depthUpdate","E":1618677386226,"s":"VETETH","U":327913095,"u":327913097,"b":[["0.00009350","0.00000000"],["0.00009347","142391.00000000"]],"a":[["0.00009413","555.00000000"]]}}
1618677386.28286: {"stream":"aaveupusdt@depth@100ms","data":{"e":"depthUpdate","E":1618677386227,"s":"AAVEUPUSDT","U":82463952,"u":82463952,"b":[],"a":[["85.58400000","2.57000000"]]}}
1618677386.3796759: {"stream":"veteth@depth@100ms","data":{"e":"depthUpdate","E":1618677386326,"s":"VETETH","U":327913098,"u":327913101,"b":[["0.00009386","0.00000000"],["0.00009382","0.00000000"],["0.00009352","0.00000000"],["0.00009194","0.00000000"]],"a":[]}}
1618677386.381189: {"stream":"swrvbusd@depth@100ms","data":{"e":"depthUpdate","E":1618677386327,"s":"SWRVBUSD","U":64830280,"u":64830280,"b":[["2.21600000","14.55500000"]],"a":[]}}
1618677386.3832152: {"stream":"aaveupusdt@depth@100ms","data":{"e":"depthUpdate","E":1618677386327,"s":"AAVEUPUSDT","U":82463953,"u":82463955,"b":[["84.11900000","0.00000000"]],"a":[["85.58400000","0.00000000"]]}}
1618677386.4809868: {"stream":"veteth@bookTicker","data":{"u":327913102,"s":"VETETH","b":"0.00009380","B":"4016.00000000","a":"0.00009406","A":"555.00000000"}}
1618677386.481025: {"stream":"veteth@depth@100ms","data":{"e":"depthUpdate","E":1618677386426,"s":"VETETH","U":327913102,"u":327913102,"b":[["0.00009387","0.00000000"]],"a":[]}}
1618677386.4810722: {"stream":"veteth@bookTicker","data":{"u":327913103,"s":"VETETH","b":"0.00009381","B":"96556.00000000","a":"0.00009406","A":"555.00000000"}}
1618677386.484728: {"stream":"veteth@bookTicker","data":{"u":327913104,"s":"VETETH","b":"0.00009388","B":"27136.00000000","a":"0.00009406","A":"555.00000000"}}
1618677386.5039701: {"stream":"swrvbusd@bookTicker","data":{"u":64830282,"s":"SWRVBUSD","b":"2.27100000","B":"22.01100000","a":"2.27700000","A":"1.19200000"}}
1618677386.506042: {"stream":"veteth@bookTicker","data":{"u":327913112,"s":"VETETH","b":"0.00009381","B":"250650.00000000","a":"0.00009406","A":"555.00000000"}}
1618677386.515192: {"stream":"veteth@bookTicker","data":{"u":327913114,"s":"VETETH","b":"0.00009389","B":"96556.00000000","a":"0.00009406","A":"555.00000000"}}
1618677386.559604: {"stream":"veteth@bookTicker","data":{"u":327913120,"s":"VETETH","b":"0.00009389","B":"96556.00000000","a":"0.00009405","A":"20116.00000000"}}
1618677386.569895: {"stream":"swrvbusd@bookTicker","data":{"u":64830284,"s":"SWRVBUSD","b":"2.27100000","B":"22.01100000","a":"2.27600000","A":"20.45400000"}}
1618677386.580011: {"stream":"veteth@depth@100ms","data":{"e":"depthUpdate","E":1618677386526,"s":"VETETH","U":327913103,"u":327913120,"b":[["0.00009389","96556.00000000"],["0.00009388","0.00000000"],["0.00009381","0.00000000"],["0.00009380","0.00000000"],["0.00009372","4220.00000000"],["0.00009236","5359.00000000"]],"a":[["0.00009405","20116.00000000"],["0.00009407","0.00000000"],["0.00009410","158148.00000000"]]}}
1618677386.5825448: {"stream":"swrvbusd@depth@100ms","data":{"e":"depthUpdate","E":1618677386527,"s":"SWRVBUSD","U":64830281,"u":64830284,"b":[["2.26800000","103.59100000"],["2.26600000","0.00000000"]],"a":[["2.27600000","20.45400000"]]}}
1618677386.582601: {"stream":"gtobtc@depth@100ms","data":{"e":"depthUpdate","E":1618677386527,"s":"GTOBTC","U":137196738,"u":137196739,"b":[["0.00000161","98021.00000000"],["0.00000160","387819.00000000"]],"a":[]}}
1618677386.63344: {"stream":"veteth@bookTicker","data":{"u":327913122,"s":"VETETH","b":"0.00009372","B":"4220.00000000","a":"0.00009405","A":"20116.00000000"}}
1618677386.642091: {"stream":"veteth@bookTicker","data":{"u":327913123,"s":"VETETH","b":"0.00009373","B":"1128.00000000","a":"0.00009405","A":"20116.00000000"}}
1618677386.6428092: {"stream":"veteth@bookTicker","data":{"u":327913124,"s":"VETETH","b":"0.00009373","B":"97684.00000000","a":"0.00009405","A":"20116.00000000"}}
1618677386.653743: {"stream":"veteth@bookTicker","data":{"u":327913125,"s":"VETETH","b":"0.00009374","B":"9034.00000000","a":"0.00009405","A":"20116.00000000"}}
1618677386.661124: {"stream":"veteth@bookTicker","data":{"u":327913127,"s":"VETETH","b":"0.00009374","B":"13659.00000000","a":"0.00009405","A":"20116.00000000"}}
1618677386.6698549: {"stream":"veteth@bookTicker","data":{"u":327913128,"s":"VETETH","b":"0.00009375","B":"96556.00000000","a":"0.00009405","A":"20116.00000000"}}
1618677386.681552: {"stream":"veteth@depth@100ms","data":{"e":"depthUpdate","E":1618677386626,"s":"VETETH","U":327913121,"u":327913128,"b":[["0.00009389","0.00000000"],["0.00009375","96556.00000000"],["0.00009374","13659.00000000"],["0.00009373","1128.00000000"],["0.00009352","25850.00000000"]],"a":[]}}
1618677386.681751: {"stream":"swrvbusd@depth@100ms","data":{"e":"depthUpdate","E":1618677386627,"s":"SWRVBUSD","U":64830285,"u":64830286,"b":[["2.26600000","32.98100000"],["2.26500000","165.06100000"]],"a":[]}}
1618677386.68207: {"stream":"gtobtc@depth@100ms","data":{"e":"depthUpdate","E":1618677386627,"s":"GTOBTC","U":137196740,"u":137196741,"b":[["0.00000161","102932.00000000"],["0.00000160","382913.00000000"]],"a":[]}}
1618677386.7293801: {"stream":"veteth@bookTicker","data":{"u":327913130,"s":"VETETH","b":"0.00009376","B":"1352.00000000","a":"0.00009405","A":"20116.00000000"}}
1618677386.729465: {"stream":"veteth@bookTicker","data":{"u":327913131,"s":"VETETH","b":"0.00009376","B":"4880.00000000","a":"0.00009405","A":"20116.00000000"}}
1618677386.729509: {"stream":"veteth@bookTicker","data":{"u":327913132,"s":"VETETH","b":"0.00009376","B":"6232.00000000","a":"0.00009405","A":"20116.00000000"}}
1618677386.729548: {"stream":"veteth@kline_1m","data":{"e":"kline","E":1618677386672,"s":"VETETH","k":{"t":1618677360000,"T":1618677419999,"s":"VETETH","i":"1m","f":6849492,"L":6849497,"o":"0.00009392","c":"0.00009405","h":"0.00009405","l":"0.00009392","v":"33755.00000000","n":6,"x":false,"q":"3.17394733","V":"33755.00000000","Q":"3.17394733","B":"0"}}}
1618677386.7295942: {"stream":"veteth@bookTicker","data":{"u":327913133,"s":"VETETH","b":"0.00009376","B":"6232.00000000","a":"0.00009405","A":"2496.00000000"}}
1618677386.729612: {"stream":"veteth@aggTrade","data":{"e":"aggTrade","E":1618677386671,"s":"VETETH","a":5580639,"p":"0.00009405","q":"17620.00000000","f":6849497,"l":6849497,"T":1618677386670,"m":false,"M":true}}
1618677386.748443: {"stream":"veteth@bookTicker","data":{"u":327913135,"s":"VETETH","b":"0.00009377","B":"96556.00000000","a":"0.00009405","A":"2496.00000000"}}
1618677386.7809181: {"stream":"veteth@depth@100ms","data":{"e":"depthUpdate","E":1618677386726,"s":"VETETH","U":327913129,"u":327913135,"b":[["0.00009377","96556.00000000"],["0.00009376","6232.00000000"],["0.00009375","0.00000000"],["0.00009372","0.00000000"]],"a":[["0.00009405","2496.00000000"]]}}
1618677386.7811341: {"stream":"perlbnb@depth@100ms","data":{"e":"depthUpdate","E":1618677386727,"s":"PERLBNB","U":97581353,"u":97581353,"b":[],"a":[["0.00039500","15.00000000"]]}}
1618677386.781203: {"stream":"qspbtc@depth@100ms","data":{"e":"depthUpdate","E":1618677386727,"s":"QSPBTC","U":105811216,"u":105811216,"b":[["0.00000148","7438.00000000"]],"a":[]}}
1618677386.8117151: {"stream":"veteth@bookTicker","data":{"u":327913136,"s":"VETETH","b":"0.00009377","B":"96556.00000000","a":"0.00009405","A":"85287.00000000"}}
1618677386.820343: {"stream":"veteth@bookTicker","data":{"u":327913138,"s":"VETETH","b":"0.00009377","B":"96556.00000000","a":"0.00009404","A":"9006.00000000"}}
1618677386.833854: {"stream":"veteth@bookTicker","data":{"u":327913140,"s":"VETETH","b":"0.00009377","B":"96556.00000000","a":"0.00009403","A":"20116.00000000"}}
1618677386.8814988: {"stream":"veteth@depth@100ms","data":{"e":"depthUpdate","E":1618677386827,"s":"VETETH","U":327913136,"u":327913140,"b":[["0.00009374","9034.00000000"],["0.00009373","0.00000000"]],"a":[["0.00009403","20116.00000000"],["0.00009404","9006.00000000"],["0.00009405","85287.00000000"]]}}
1618677386.881644: {"stream":"perlbnb@depth@100ms","data":{"e":"depthUpdate","E":1618677386827,"s":"PERLBNB","U":97581354,"u":97581355,"b":[],"a":[["0.00039600","6203.00000000"]]}}
1618677386.892969: {"stream":"veteth@bookTicker","data":{"u":327913141,"s":"VETETH","b":"0.00009378","B":"4632.00000000","a":"0.00009403","A":"20116.00000000"}}
1618677386.911155: {"stream":"veteth@bookTicker","data":{"u":327913145,"s":"VETETH","b":"0.00009378","B":"4632.00000000","a":"0.00009402","A":"82791.00000000"}}
1618677386.915166: {"stream":"veteth@bookTicker","data":{"u":327913148,"s":"VETETH","b":"0.00009379","B":"96556.00000000","a":"0.00009402","A":"82791.00000000"}}
1618677386.9798331: {"stream":"veteth@depth@100ms","data":{"e":"depthUpdate","E":1618677386927,"s":"VETETH","U":327913141,"u":327913149,"b":[["0.00009379","96556.00000000"],["0.00009378","4632.00000000"],["0.00009377","0.00000000"],["0.00009376","0.00000000"],["0.00009270","196.00000000"]],"a":[["0.00009402","82791.00000000"],["0.00009405","2496.00000000"]]}}
1618677386.981987: {"stream":"aaveupusdt@depth@100ms","data":{"e":"depthUpdate","E":1618677386927,"s":"AAVEUPUSDT","U":82463956,"u":82463956,"b":[["82.20300000","0.00000000"]],"a":[]}}
1618677387.08231: {"stream":"veteth@depth@100ms","data":{"e":"depthUpdate","E":1618677387027,"s":"VETETH","U":327913150,"u":327913151,"b":[["0.00009357","113.00000000"]],"a":[["0.00009414","2897.00000000"]]}}
1618677387.119264: {"stream":"swrvbusd@bookTicker","data":{"u":64830287,"s":"SWRVBUSD","b":"2.27100000","B":"22.01100000","a":"2.27700000","A":"1.19200000"}}
1618677387.181141: {"stream":"veteth@depth@100ms","data":{"e":"depthUpdate","E":1618677387127,"s":"VETETH","U":327913152,"u":327913152,"b":[["0.00009260","165696.00000000"]],"a":[]}}
1618677387.1812842: {"stream":"swrvbusd@depth@100ms","data":{"e":"depthUpdate","E":1618677387127,"s":"SWRVBUSD","U":64830287,"u":64830287,"b":[],"a":[["2.27600000","0.00000000"]]}}
1618677387.181737: {"stream":"aaveupusdt@depth@100ms","data":{"e":"depthUpdate","E":1618677387127,"s":"AAVEUPUSDT","U":82463957,"u":82463957,"b":[["82.01600000","2.46000000"]],"a":[]}}
1618677387.184232: {"stream":"swrvbusd@bookTicker","data":{"u":64830288,"s":"SWRVBUSD","b":"2.27100000","B":"22.01100000","a":"2.27600000","A":"20.45400000"}}
1618677387.229126: {"stream":"aaveupusdt@bookTicker","data":{"u":82463958,"s":"AAVEUPUSDT","b":"84.55800000","B":"0.25000000","a":"84.93300000","A":"1.50000000"}}
1618677387.281455: {"stream":"swrvbusd@depth@100ms","data":{"e":"depthUpdate","E":1618677387227,"s":"SWRVBUSD","U":64830288,"u":64830289,"b":[["2.26500000","171.21800000"]],"a":[["2.27600000","20.45400000"]]}}
1618677387.28162: {"stream":"aaveupusdt@depth@100ms","data":{"e":"depthUpdate","E":1618677387227,"s":"AAVEUPUSDT","U":82463958,"u":82463958,"b":[],"a":[["84.93300000","1.50000000"]]}}
1618677387.381631: {"stream":"veteth@depth@100ms","data":{"e":"depthUpdate","E":1618677387327,"s":"VETETH","U":327913153,"u":327913153,"b":[["0.00009216","0.00000000"]],"a":[]}}
1618677387.381783: {"stream":"aaveupusdt@depth@100ms","data":{"e":"depthUpdate","E":1618677387327,"s":"AAVEUPUSDT","U":82463959,"u":82463960,"b":[["84.11900000","2.57000000"]],"a":[["85.49900000","2.57000000"]]}}
1618677387.451655: {"stream":"aaveupusdt@bookTicker","data":{"u":82463962,"s":"AAVEUPUSDT","b":"84.55800000","B":"0.25000000","a":"84.93400000","A":"221.49000000"}}
1618677387.4576619: {"stream":"veteth@bookTicker","data":{"u":327913154,"s":"VETETH","b":"0.00009378","B":"4632.00000000","a":"0.00009402","A":"82791.00000000"}}
1618677387.459208: {"stream":"veteth@bookTicker","data":{"u":327913155,"s":"VETETH","b":"0.00009374","B":"9034.00000000","a":"0.00009402","A":"82791.00000000"}}
1618677387.4655628: {"stream":"veteth@bookTicker","data":{"u":327913156,"s":"VETETH","b":"0.00009375","B":"96556.00000000","a":"0.00009402","A":"82791.00000000"}}
1618677387.465597: {"stream":"veteth@bookTicker","data":{"u":327913157,"s":"VETETH","b":"0.00009374","B":"9034.00000000","a":"0.00009402","A":"82791.00000000"}}
1618677387.475509: {"stream":"veteth@bookTicker","data":{"u":327913158,"s":"VETETH","b":"0.00009375","B":"96556.00000000","a":"0.00009402","A":"82791.00000000"}}
1618677387.481289: {"stream":"veteth@depth@100ms","data":{"e":"depthUpdate","E":1618677387427,"s":"VETETH","U":327913154,"u":327913158,"b":[["0.00009379","0.00000000"],["0.00009378","0.00000000"],["0.00009375","96556.00000000"]],"a":[]}}
1618677387.481476: {"stream":"aaveupusdt@depth@100ms","data":{"e":"depthUpdate","E":1618677387427,"s":"AAVEUPUSDT","U":82463961,"u":82463962,"b":[],"a":[["84.93300000","0.00000000"],["85.49900000","0.00000000"]]}}
1618677387.610077: {"stream":"aaveupusdt@bookTicker","data":{"u":82463963,"s":"AAVEUPUSDT","b":"84.55800000","B":"0.25000000","a":"84.93400000","A":"200.09000000"}}
1618677387.619128: {"stream":"aaveupusdt@bookTicker","data":{"u":82463964,"s":"AAVEUPUSDT","b":"84.55800000","B":"0.25000000","a":"84.93400000","A":"94.16000000"}}
1618677387.620439: {"stream":"aaveupusdt@bookTicker","data":{"u":82463965,"s":"AAVEUPUSDT","b":"84.55800000","B":"0.25000000","a":"84.93500000","A":"0.74000000"}}
1618677387.681655: {"stream":"veteth@depth@100ms","data":{"e":"depthUpdate","E":1618677387627,"s":"VETETH","U":327913159,"u":327913159,"b":[["0.00009227","3395.00000000"]],"a":[]}}
1618677387.68208: {"stream":"aaveupusdt@depth@100ms","data":{"e":"depthUpdate","E":1618677387627,"s":"AAVEUPUSDT","U":82463963,"u":82463965,"b":[],"a":[["84.93400000","0.00000000"]]}}
1618677387.727773: {"stream":"swrvbusd@bookTicker","data":{"u":64830291,"s":"SWRVBUSD","b":"2.27100000","B":"22.01100000","a":"2.27700000","A":"1.19200000"}}
1618677387.781369: {"stream":"swrvbusd@depth@100ms","data":{"e":"depthUpdate","E":1618677387727,"s":"SWRVBUSD","U":64830290,"u":64830292,"b":[["2.26600000","0.00000000"],["2.26500000","171.22500000"]],"a":[["2.27600000","0.00000000"]]}}
1618677387.781562: {"stream":"aaveupusdt@depth@100ms","data":{"e":"depthUpdate","E":1618677387727,"s":"AAVEUPUSDT","U":82463966,"u":82463966,"b":[["84.55700000","0.00000000"]],"a":[]}}
1618677387.793329: {"stream":"swrvbusd@bookTicker","data":{"u":64830294,"s":"SWRVBUSD","b":"2.27100000","B":"22.01100000","a":"2.27600000","A":"20.45400000"}}
1618677387.834017: {"stream":"aaveupusdt@bookTicker","data":{"u":82463967,"s":"AAVEUPUSDT","b":"84.39700000","B":"11.85000000","a":"84.93500000","A":"0.74000000"}}
1618677387.834102: {"stream":"aaveupusdt@bookTicker","data":{"u":82463968,"s":"AAVEUPUSDT","b":"84.39800000","B":"0.25000000","a":"84.93500000","A":"0.74000000"}}
1618677387.881738: {"stream":"swrvbusd@depth@100ms","data":{"e":"depthUpdate","E":1618677387827,"s":"SWRVBUSD","U":64830293,"u":64830294,"b":[["2.26600000","32.98800000"]],"a":[["2.27600000","20.45400000"]]}}
1618677387.881917: {"stream":"aaveupusdt@depth@100ms","data":{"e":"depthUpdate","E":1618677387827,"s":"AAVEUPUSDT","U":82463967,"u":82463968,"b":[["84.55800000","0.00000000"],["84.39800000","0.25000000"]],"a":[]}}
1618677387.963555: {"stream":"veteth@bookTicker","data":{"u":327913160,"s":"VETETH","b":"0.00009376","B":"960.00000000","a":"0.00009402","A":"82791.00000000"}}
1618677387.9818392: {"stream":"veteth@depth@100ms","data":{"e":"depthUpdate","E":1618677387927,"s":"VETETH","U":327913160,"u":327913160,"b":[["0.00009376","960.00000000"]],"a":[]}}
1618677387.9819882: {"stream":"qspbtc@depth@100ms","data":{"e":"depthUpdate","E":1618677387927,"s":"QSPBTC","U":105811217,"u":105811217,"b":[],"a":[["0.00000196","73563.00000000"]]}}
1618677388.004709: {"stream":"veteth@bookTicker","data":{"u":327913162,"s":"VETETH","b":"0.00009377","B":"96556.00000000","a":"0.00009402","A":"82791.00000000"}}
1618677388.082143: {"stream":"veteth@depth@100ms","data":{"e":"depthUpdate","E":1618677388027,"s":"VETETH","U":327913161,"u":327913164,"b":[["0.00009377","96556.00000000"],["0.00009375","0.00000000"],["0.00009353","2360.00000000"]],"a":[["0.00009446","174.00000000"]]}}
1618677388.082342: {"stream":"swrvbusd@depth@100ms","data":{"e":"depthUpdate","E":1618677388027,"s":"SWRVBUSD","U":64830295,"u":64830295,"b":[["2.21400000","327.38700000"]],"a":[]}}
1618677388.180983: {"stream":"veteth@depth@100ms","data":{"e":"depthUpdate","E":1618677388127,"s":"VETETH","U":327913165,"u":327913165,"b":[],"a":[["0.00009407","26679.00000000"]]}}
1618677388.1815748: {"stream":"aaveupusdt@depth@100ms","data":{"e":"depthUpdate","E":1618677388128,"s":"AAVEUPUSDT","U":82463969,"u":82463969,"b":[["84.11900000","0.00000000"]],"a":[]}}
1618677388.210363: {"stream":"veteth@bookTicker","data":{"u":327913166,"s":"VETETH","b":"0.00009376","B":"960.00000000","a":"0.00009402","A":"82791.00000000"}}
1618677388.2805948: {"stream":"veteth@depth@100ms","data":{"e":"depthUpdate","E":1618677388227,"s":"VETETH","U":327913166,"u":327913167,"b":[["0.00009377","0.00000000"],["0.00009375","96556.00000000"]],"a":[]}}
1618677388.330981: {"stream":"swrvbusd@bookTicker","data":{"u":64830296,"s":"SWRVBUSD","b":"2.27100000","B":"22.01100000","a":"2.27700000","A":"1.19200000"}}
1618677388.3479738: {"stream":"veteth@bookTicker","data":{"u":327913173,"s":"VETETH","b":"0.00009377","B":"96556.00000000","a":"0.00009402","A":"82791.00000000"}}
1618677388.349652: {"stream":"veteth@bookTicker","data":{"u":327913174,"s":"VETETH","b":"0.00009377","B":"116672.00000000","a":"0.00009402","A":"82791.00000000"}}
1618677388.382234: {"stream":"veteth@depth@100ms","data":{"e":"depthUpdate","E":1618677388327,"s":"VETETH","U":327913168,"u":327913174,"b":[["0.00009377","116672.00000000"],["0.00009375","0.00000000"]],"a":[]}}
1618677388.382407: {"stream":"swrvbusd@depth@100ms","data":{"e":"depthUpdate","E":1618677388327,"s":"SWRVBUSD","U":64830296,"u":64830296,"b":[],"a":[["2.27600000","0.00000000"]]}}
1618677388.4164832: {"stream":"swrvbusd@bookTicker","data":{"u":64830297,"s":"SWRVBUSD","b":"2.27100000","B":"22.01100000","a":"2.27600000","A":"20.45400000"}}
1618677388.4829319: {"stream":"swrvbusd@depth@100ms","data":{"e":"depthUpdate","E":1618677388427,"s":"SWRVBUSD","U":64830297,"u":64830297,"b":[],"a":[["2.27600000","20.45400000"]]}}
1618677388.483087: {"stream":"aaveupusdt@depth@100ms","data":{"e":"depthUpdate","E":1618677388427,"s":"AAVEUPUSDT","U":82463970,"u":82463971,"b":[["83.98300000","2.57000000"]],"a":[["85.49900000","2.57000000"]]}}
1618677388.494907: {"stream":"aaveupusdt@bookTicker","data":{"u":82463972,"s":"AAVEUPUSDT","b":"84.39900000","B":"0.17000000","a":"84.93500000","A":"0.74000000"}}
1618677388.58252: {"stream":"veteth@depth@100ms","data":{"e":"depthUpdate","E":1618677388527,"s":"VETETH","U":327913175,"u":327913175,"b":[],"a":[["0.00009405","0.00000000"]]}}
1618677388.58268: {"stream":"aaveupusdt@depth@100ms","data":{"e":"depthUpdate","E":1618677388528,"s":"AAVEUPUSDT","U":82463972,"u":82463974,"b":[["84.39900000","0.17000000"],["83.98300000","0.00000000"]],"a":[["85.49900000","0.00000000"]]}}
1618677388.631082: {"stream":"veteth@bookTicker","data":{"u":327913176,"s":"VETETH","b":"0.00009377","B":"20116.00000000","a":"0.00009402","A":"82791.00000000"}}
1618677388.6385548: {"stream":"veteth@bookTicker","data":{"u":327913177,"s":"VETETH","b":"0.00009377","B":"116672.00000000","a":"0.00009402","A":"82791.00000000"}}
1618677388.682695: {"stream":"veteth@depth@100ms","data":{"e":"depthUpdate","E":1618677388627,"s":"VETETH","U":327913176,"u":327913177,"b":[["0.00009377","116672.00000000"]],"a":[]}}
1618677388.703701: {"stream":"aaveupusdt@bookTicker","data":{"u":82463976,"s":"AAVEUPUSDT","b":"84.40000000","B":"0.25000000","a":"84.93500000","A":"0.74000000"}}
1618677388.7819781: {"stream":"aaveupusdt@depth@100ms","data":{"e":"depthUpdate","E":1618677388728,"s":"AAVEUPUSDT","U":82463975,"u":82463976,"b":[["84.40000000","0.25000000"],["84.39800000","0.00000000"]],"a":[]}}
1618677388.8409972: {"stream":"veteth@bookTicker","data":{"u":327913180,"s":"VETETH","b":"0.00009378","B":"1127.00000000","a":"0.00009402","A":"82791.00000000"}}
1618677388.848384: {"stream":"veteth@bookTicker","data":{"u":327913183,"s":"VETETH","b":"0.00009378","B":"3788.00000000","a":"0.00009402","A":"82791.00000000"}}
1618677388.859164: {"stream":"veteth@bookTicker","data":{"u":327913186,"s":"VETETH","b":"0.00009379","B":"96556.00000000","a":"0.00009402","A":"82791.00000000"}}
1618677388.867726: {"stream":"veteth@bookTicker","data":{"u":327913187,"s":"VETETH","b":"0.00009378","B":"3788.00000000","a":"0.00009402","A":"82791.00000000"}}
1618677388.877781: {"stream":"veteth@bookTicker","data":{"u":327913188,"s":"VETETH","b":"0.00009378","B":"100344.00000000","a":"0.00009402","A":"82791.00000000"}}
1618677388.882189: {"stream":"veteth@depth@100ms","data":{"e":"depthUpdate","E":1618677388827,"s":"VETETH","U":327913178,"u":327913188,"b":[["0.00009379","0.00000000"],["0.00009378","100344.00000000"],["0.00009377","20116.00000000"],["0.00009351","0.00000000"],["0.00009338","100175.00000000"],["0.00009324","3145.00000000"],["0.00009301","833.00000000"]],"a":[["0.00009403","0.00000000"]]}}
1618677388.912055: {"stream":"swrvbusd@bookTicker","data":{"u":64830299,"s":"SWRVBUSD","b":"2.27100000","B":"22.01100000","a":"2.27700000","A":"1.19200000"}}
1618677388.943441: {"stream":"veteth@bookTicker","data":{"u":327913189,"s":"VETETH","b":"0.00009378","B":"97683.00000000","a":"0.00009402","A":"82791.00000000"}}
1618677388.953032: {"stream":"veteth@bookTicker","data":{"u":327913191,"s":"VETETH","b":"0.00009378","B":"96556.00000000","a":"0.00009402","A":"82791.00000000"}}
1618677388.962894: {"stream":"veteth@bookTicker","data":{"u":327913193,"s":"VETETH","b":"0.00009378","B":"96556.00000000","a":"0.00009404","A":"9006.00000000"}}
1618677388.972466: {"stream":"swrvbusd@bookTicker","data":{"u":64830302,"s":"SWRVBUSD","b":"2.27100000","B":"22.01100000","a":"2.27600000","A":"20.45400000"}}
1618677388.982166: {"stream":"veteth@depth@100ms","data":{"e":"depthUpdate","E":1618677388927,"s":"VETETH","U":327913189,"u":327913195,"b":[["0.00009378","96556.00000000"],["0.00009376","0.00000000"],["0.00009324","225.00000000"],["0.00009303","2965.00000000"]],"a":[["0.00009402","0.00000000"],["0.00009405","82791.00000000"]]}}
1618677388.98239: {"stream":"swrvbusd@depth@100ms","data":{"e":"depthUpdate","E":1618677388927,"s":"SWRVBUSD","U":64830298,"u":64830302,"b":[["2.26600000","32.98800000"],["2.26500000","171.22500000"]],"a":[["2.27600000","20.45400000"]]}}
1618677389.014139: {"stream":"veteth@bookTicker","data":{"u":327913197,"s":"VETETH","b":"0.00009378","B":"96556.00000000","a":"0.00009404","A":"91797.00000000"}}
1618677389.08199: {"stream":"veteth@depth@100ms","data":{"e":"depthUpdate","E":1618677389027,"s":"VETETH","U":327913196,"u":327913198,"b":[],"a":[["0.00009404","91797.00000000"],["0.00009405","0.00000000"],["0.00009407","0.00000000"]]}}
1618677389.145165: {"stream":"veteth@kline_1m","data":{"e":"kline","E":1618677389078,"s":"VETETH","k":{"t":1618677360000,"T":1618677419999,"s":"VETETH","i":"1m","f":6849492,"L":6849498,"o":"0.00009392","c":"0.00009378","h":"0.00009405","l":"0.00009378","v":"34423.00000000","n":7,"x":false,"q":"3.23659237","V":"33755.00000000","Q":"3.17394733","B":"0"}}}
1618677389.1452959: {"stream":"veteth@bookTicker","data":{"u":327913199,"s":"VETETH","b":"0.00009378","B":"95888.00000000","a":"0.00009404","A":"91797.00000000"}}
1618677389.145818: {"stream":"veteth@aggTrade","data":{"e":"aggTrade","E":1618677389078,"s":"VETETH","a":5580640,"p":"0.00009378","q":"668.00000000","f":6849498,"l":6849498,"T":1618677389077,"m":true,"M":true}}
1618677389.149293: {"stream":"veteth@bookTicker","data":{"u":327913200,"s":"VETETH","b":"0.00009378","B":"95888.00000000","a":"0.00009404","A":"82791.00000000"}}
1618677389.174958: {"stream":"veteth@bookTicker","data":{"u":327913201,"s":"VETETH","b":"0.00009379","B":"119794.00000000","a":"0.00009404","A":"82791.00000000"}}
1618677389.184083: {"stream":"veteth@depth@100ms","data":{"e":"depthUpdate","E":1618677389127,"s":"VETETH","U":327913199,"u":327913204,"b":[["0.00009379","119794.00000000"],["0.00009378","0.00000000"]],"a":[["0.00009404","82791.00000000"]]}}
1618677389.184265: {"stream":"qspbtc@depth@100ms","data":{"e":"depthUpdate","E":1618677389127,"s":"QSPBTC","U":105811218,"u":105811218,"b":[["0.00000146","8216.00000000"]],"a":[]}}
1618677389.18433: {"stream":"steemeth@depth@100ms","data":{"e":"depthUpdate","E":1618677389128,"s":"STEEMETH","U":126265009,"u":126265009,"b":[["0.00050200","2052.14000000"]],"a":[]}}
1618677389.184638: {"stream":"busdtry@depth@100ms","data":{"e":"depthUpdate","E":1618677389128,"s":"BUSDTRY","U":10166144,"u":10166144,"b":[["8.10000000","83261.62000000"]],"a":[]}}
1618677389.185324: {"stream":"veteth@bookTicker","data":{"u":327913205,"s":"VETETH","b":"0.00009379","B":"119794.00000000","a":"0.00009406","A":"555.00000000"}}
1618677389.1883159: {"stream":"veteth@bookTicker","data":{"u":327913206,"s":"VETETH","b":"0.00009380","B":"96556.00000000","a":"0.00009406","A":"555.00000000"}}
1618677389.2821429: {"stream":"veteth@depth@100ms","data":{"e":"depthUpdate","E":1618677389227,"s":"VETETH","U":327913205,"u":327913209,"b":[["0.00009380","96556.00000000"],["0.00009379","0.00000000"],["0.00009352","125850.00000000"],["0.00009338","175.00000000"]],"a":[["0.00009404","0.00000000"]]}}
1618677389.302688: {"stream":"aaveupusdt@bookTicker","data":{"u":82463978,"s":"AAVEUPUSDT","b":"84.39700000","B":"11.85000000","a":"84.93500000","A":"0.74000000"}}
1618677389.302772: {"stream":"aaveupusdt@bookTicker","data":{"u":82463979,"s":"AAVEUPUSDT","b":"84.39800000","B":"0.25000000","a":"84.93500000","A":"0.74000000"}}
1618677389.31196: {"stream":"veteth@bookTicker","data":{"u":327913210,"s":"VETETH","b":"0.00009380","B":"97907.00000000","a":"0.00009406","A":"555.00000000"}}
1618677389.3172932: {"stream":"veteth@bookTicker","data":{"u":327913212,"s":"VETETH","b":"0.00009380","B":"99258.00000000","a":"0.00009406","A":"555.00000000"}}
1618677389.319517: {"stream":"veteth@bookTicker","data":{"u":327913213,"s":"VETETH","b":"0.00009380","B":"102170.00000000","a":"0.00009406","A":"555.00000000"}}
1618677389.349838: {"stream":"gtobtc@bookTicker","data":{"u":137196742,"s":"GTOBTC","b":"0.00000162","B":"44443.00000000","a":"0.00000163","A":"345860.00000000"}}
1618677389.382401: {"stream":"veteth@depth@100ms","data":{"e":"depthUpdate","E":1618677389327,"s":"VETETH","U":327913210,"u":327913213,"b":[["0.00009380","102170.00000000"]],"a":[["0.00009446","26454.00000000"]]}}
1618677389.3825479: {"stream":"swrvbusd@depth@100ms","data":{"e":"depthUpdate","E":1618677389328,"s":"SWRVBUSD","U":64830303,"u":64830303,"b":[["2.26800000","5.00000000"]],"a":[]}}
1618677389.3826098: {"stream":"gtobtc@depth@100ms","data":{"e":"depthUpdate","E":1618677389328,"s":"GTOBTC","U":137196742,"u":137196742,"b":[["0.00000162","44443.00000000"]],"a":[]}}
1618677389.38309: {"stream":"aaveupusdt@depth@100ms","data":{"e":"depthUpdate","E":1618677389328,"s":"AAVEUPUSDT","U":82463977,"u":82463979,"b":[["84.40000000","0.00000000"],["84.39900000","0.00000000"],["84.39800000","0.25000000"]],"a":[]}}
1618677389.462301: {"stream":"swrvbusd@bookTicker","data":{"u":64830306,"s":"SWRVBUSD","b":"2.27100000","B":"22.01100000","a":"2.27700000","A":"1.19200000"}}
1618677389.4742012: {"stream":"veteth@bookTicker","data":{"u":327913214,"s":"VETETH","b":"0.00009381","B":"171738.00000000","a":"0.00009406","A":"555.00000000"}}
1618677389.481866: {"stream":"veteth@depth@100ms","data":{"e":"depthUpdate","E":1618677389427,"s":"VETETH","U":327913214,"u":327913214,"b":[["0.00009381","171738.00000000"]],"a":[]}}
1618677389.482017: {"stream":"swrvbusd@depth@100ms","data":{"e":"depthUpdate","E":1618677389428,"s":"SWRVBUSD","U":64830304,"u":64830306,"b":[["2.25100000","0.00000000"],["2.24300000","980.18000000"]],"a":[["2.27600000","0.00000000"]]}}
1618677389.48257: {"stream":"aaveupusdt@depth@100ms","data":{"e":"depthUpdate","E":1618677389428,"s":"AAVEUPUSDT","U":82463980,"u":82463983,"b":[["84.39000000","23.70000000"],["83.98300000","2.57000000"]],"a":[["85.49900000","2.57000000"]]}}
1618677389.4944088: {"stream":"veteth@bookTicker","data":{"u":327913216,"s":"VETETH","b":"0.00009382","B":"96556.00000000","a":"0.00009406","A":"555.00000000"}}
1618677389.526504: {"stream":"swrvbusd@bookTicker","data":{"u":64830307,"s":"SWRVBUSD","b":"2.27100000","B":"22.01100000","a":"2.27600000","A":"20.45400000"}}
1618677389.5697742: {"stream":"veteth@bookTicker","data":{"u":327913219,"s":"VETETH","b":"0.00009383","B":"4632.00000000","a":"0.00009406","A":"555.00000000"}}
1618677389.5845702: {"stream":"veteth@depth@100ms","data":{"e":"depthUpdate","E":1618677389528,"s":"VETETH","U":327913215,"u":327913221,"b":[["0.00009383","4632.00000000"],["0.00009382","0.00000000"],["0.00009381","0.00000000"],["0.00009380","5614.00000000"],["0.00009374","0.00000000"],["0.00009272","5338.00000000"]],"a":[]}}
1618677389.584778: {"stream":"perlbnb@depth@100ms","data":{"e":"depthUpdate","E":1618677389528,"s":"PERLBNB","U":97581356,"u":97581356,"b":[],"a":[["0.00041000","9590.00000000"]]}}
1618677389.586078: {"stream":"swrvbusd@depth@100ms","data":{"e":"depthUpdate","E":1618677389528,"s":"SWRVBUSD","U":64830307,"u":64830307,"b":[],"a":[["2.27600000","20.45400000"]]}}
1618677389.593832: {"stream":"aaveupusdt@depth@100ms","data":{"e":"depthUpdate","E":1618677389528,"s":"AAVEUPUSDT","U":82463984,"u":82463984,"b":[["84.39000000","35.55000000"]],"a":[]}}
1618677389.593965: {"stream":"veteth@bookTicker","data":{"u":327913222,"s":"VETETH","b":"0.00009384","B":"96556.00000000","a":"0.00009406","A":"555.00000000"}}
1618677389.670441: {"stream":"adarub@bookTicker","data":{"u":1720411,"s":"ADARUB","b":"106.00000000","B":"1138.44000000","a":"106.09000000","A":"7.54000000"}}
1618677389.691766: {"stream":"adarub@depth@100ms","data":{"e":"depthUpdate","E":1618677389628,"s":"ADARUB","U":1720410,"u":1720412,"b":[["106.00000000","1138.44000000"],["105.92000000","0.00000000"],["104.53000000","0.00000000"]],"a":[]}}
1618677389.895134: {"stream":"veteth@depth@100ms","data":{"e":"depthUpdate","E":1618677389628,"s":"VETETH","U":327913222,"u":327913223,"b":[["0.00009384","96556.00000000"],["0.00009261","71050.00000000"]],"a":[]}}
1618677389.8951979: {"stream":"aaveupusdt@depth@100ms","data":{"e":"depthUpdate","E":1618677389628,"s":"AAVEUPUSDT","U":82463985,"u":82463985,"b":[["83.98300000","0.00000000"]],"a":[]}}
1618677389.8952389: {"stream":"adarub@bookTicker","data":{"u":1720413,"s":"ADARUB","b":"106.01000000","B":"301.56000000","a":"106.09000000","A":"7.54000000"}}
1618677389.895259: {"stream":"aaveupusdt@bookTicker","data":{"u":82463987,"s":"AAVEUPUSDT","b":"84.39800000","B":"11.05000000","a":"84.93500000","A":"0.74000000"}}
1618677389.895273: {"stream":"adarub@depth@100ms","data":{"e":"depthUpdate","E":1618677389728,"s":"ADARUB","U":1720413,"u":1720413,"b":[["106.01000000","301.56000000"]],"a":[]}}
1618677389.895284: {"stream":"gtobtc@depth@100ms","data":{"e":"depthUpdate","E":1618677389728,"s":"GTOBTC","U":137196743,"u":137196743,"b":[["0.00000143","19533.00000000"]],"a":[]}}
1618677389.895309: {"stream":"aaveupusdt@depth@100ms","data":{"e":"depthUpdate","E":1618677389728,"s":"AAVEUPUSDT","U":82463986,"u":82463987,"b":[["84.39800000","11.05000000"]],"a":[["85.49900000","0.00000000"]]}}
1618677389.895344: {"stream":"aaveupusdt@bookTicker","data":{"u":82463988,"s":"AAVEUPUSDT","b":"84.39900000","B":"0.25000000","a":"84.93500000","A":"0.74000000"}}
1618677389.895359: {"stream":"perlbnb@depth@100ms","data":{"e":"depthUpdate","E":1618677389828,"s":"PERLBNB","U":97581357,"u":97581357,"b":[],"a":[["0.00040900","16946.00000000"]]}}
1618677389.895382: {"stream":"aaveupusdt@depth@100ms","data":{"e":"depthUpdate","E":1618677389828,"s":"AAVEUPUSDT","U":82463988,"u":82463989,"b":[["84.39900000","0.25000000"],["84.39800000","10.80000000"]],"a":[]}}
1618677389.8997838: {"stream":"veteth@bookTicker","data":{"u":327913224,"s":"VETETH","b":"0.00009385","B":"66420.00000000","a":"0.00009406","A":"555.00000000"}}
1618677389.945086: {"stream":"veteth@bookTicker","data":{"u":327913226,"s":"VETETH","b":"0.00009386","B":"96556.00000000","a":"0.00009406","A":"555.00000000"}}
1618677389.9625: {"stream":"veteth@bookTicker","data":{"u":327913228,"s":"VETETH","b":"0.00009386","B":"97682.00000000","a":"0.00009406","A":"555.00000000"}}
1618677389.973641: {"stream":"veteth@bookTicker","data":{"u":327913229,"s":"VETETH","b":"0.00009386","B":"97990.00000000","a":"0.00009406","A":"555.00000000"}}
1618677389.982518: {"stream":"veteth@bookTicker","data":{"u":327913231,"s":"VETETH","b":"0.00009386","B":"97990.00000000","a":"0.00009405","A":"20116.00000000"}}
1618677389.982602: {"stream":"veteth@bookTicker","data":{"u":327913232,"s":"VETETH","b":"0.00009386","B":"96864.00000000","a":"0.00009405","A":"20116.00000000"}}
1618677389.991488: {"stream":"veteth@depth@100ms","data":{"e":"depthUpdate","E":1618677389928,"s":"VETETH","U":327913224,"u":327913232,"b":[["0.00009386","96864.00000000"],["0.00009385","0.00000000"],["0.00009384","0.00000000"],["0.00009383","0.00000000"]],"a":[["0.00009405","20116.00000000"]]}}
1618677389.9917068: {"stream":"aaveupusdt@depth@100ms","data":{"e":"depthUpdate","E":1618677389928,"s":"AAVEUPUSDT","U":82463990,"u":82463991,"b":[["84.39800000","0.00000000"],["83.97000000","0.00000000"]],"a":[]}}
1618677389.991812: {"stream":"aaveupusdt@bookTicker","data":{"u":82463993,"s":"AAVEUPUSDT","b":"84.39800000","B":"0.25000000","a":"84.93500000","A":"0.74000000"}}
1618677389.9977012: {"stream":"veteth@bookTicker","data":{"u":327913233,"s":"VETETH","b":"0.00009386","B":"96864.00000000","a":"0.00009405","A":"19561.00000000"}}
1618677389.99776: {"stream":"veteth@aggTrade","data":{"e":"aggTrade","E":1618677389940,"s":"VETETH","a":5580641,"p":"0.00009405","q":"555.00000000","f":6849499,"l":6849499,"T":1618677389936,"m":false,"M":true}}
1618677390.084979: {"stream":"veteth@depth@100ms","data":{"e":"depthUpdate","E":1618677390028,"s":"VETETH","U":327913233,"u":327913233,"b":[],"a":[["0.00009405","19561.00000000"]]}}
1618677390.085119: {"stream":"swrvbusd@depth@100ms","data":{"e":"depthUpdate","E":1618677390028,"s":"SWRVBUSD","U":64830308,"u":64830308,"b":[["2.26600000","0.00000000"],["2.26500000","139.51700000"]],"a":[]}}
1618677390.08522: {"stream":"gtobtc@depth@100ms","data":{"e":"depthUpdate","E":1618677390028,"s":"GTOBTC","U":137196744,"u":137196744,"b":[["0.00000161","98021.00000000"]],"a":[]}}
1618677390.0852742: {"stream":"aaveupusdt@depth@100ms","data":{"e":"depthUpdate","E":1618677390028,"s":"AAVEUPUSDT","U":82463992,"u":82463994,"b":[["84.39900000","0.00000000"],["84.39800000","0.25000000"]],"a":[["85.13900000","336.23000000"]]}}
1618677390.091558: {"stream":"swrvbusd@bookTicker","data":{"u":64830309,"s":"SWRVBUSD","b":"2.27100000","B":"22.01100000","a":"2.27700000","A":"1.19200000"}}
1618677390.123669: {"stream":"veteth@bookTicker","data":{"u":327913234,"s":"VETETH","b":"0.00009386","B":"308.00000000","a":"0.00009405","A":"19561.00000000"}}
1618677390.1609: {"stream":"veteth@bookTicker","data":{"u":327913237,"s":"VETETH","b":"0.00009387","B":"4632.00000000","a":"0.00009405","A":"19561.00000000"}}
1618677390.1777909: {"stream":"swrvbusd@bookTicker","data":{"u":64830312,"s":"SWRVBUSD","b":"2.27100000","B":"22.01100000","a":"2.27600000","A":"20.45400000"}}
1618677390.184206: {"stream":"veteth@depth@100ms","data":{"e":"depthUpdate","E":1618677390128,"s":"VETETH","U":327913234,"u":327913237,"b":[["0.00009387","4632.00000000"],["0.00009386","308.00000000"],["0.00009381","97682.00000000"]],"a":[]}}
1618677390.190351: {"stream":"swrvbusd@depth@100ms","data":{"e":"depthUpdate","E":1618677390128,"s":"SWRVBUSD","U":64830309,"u":64830312,"b":[["2.26600000","32.98800000"],["2.26500000","171.22500000"]],"a":[["2.27600000","20.45400000"]]}}
1618677390.1905222: {"stream":"gtobtc@depth@100ms","data":{"e":"depthUpdate","E":1618677390128,"s":"GTOBTC","U":137196745,"u":137196748,"b":[["0.00000160","382913.00000000"]],"a":[]}}
1618677390.194315: {"stream":"veteth@bookTicker","data":{"u":327913239,"s":"VETETH","b":"0.00009388","B":"9021.00000000","a":"0.00009405","A":"19561.00000000"}}
1618677390.199557: {"stream":"aaveupusdt@bookTicker","data":{"u":82463995,"s":"AAVEUPUSDT","b":"84.39800000","B":"0.25000000","a":"84.93400000","A":"94.16000000"}}
1618677390.199639: {"stream":"aaveupusdt@bookTicker","data":{"u":82463996,"s":"AAVEUPUSDT","b":"84.39800000","B":"0.25000000","a":"84.93400000","A":"200.09000000"}}
1618677390.220215: {"stream":"veteth@bookTicker","data":{"u":327913241,"s":"VETETH","b":"0.00009388","B":"105577.00000000","a":"0.00009405","A":"19561.00000000"}}
1618677390.239006: {"stream":"aaveupusdt@bookTicker","data":{"u":82463997,"s":"AAVEUPUSDT","b":"84.39800000","B":"0.25000000","a":"84.93400000","A":"221.49000000"}}
1618677390.282023: {"stream":"veteth@depth@100ms","data":{"e":"depthUpdate","E":1618677390228,"s":"VETETH","U":327913238,"u":327913241,"b":[["0.00009388","105577.00000000"],["0.00009381","0.00000000"]],"a":[]}}
1618677390.283563: {"stream":"gtobtc@depth@100ms","data":{"e":"depthUpdate","E":1618677390228,"s":"GTOBTC","U":137196749,"u":137196749,"b":[["0.00000161","103006.00000000"]],"a":[]}}
1618677390.285012: {"stream":"aaveupusdt@depth@100ms","data":{"e":"depthUpdate","E":1618677390228,"s":"AAVEUPUSDT","U":82463995,"u":82463997,"b":[],"a":[["84.93400000","221.49000000"]]}}
1618677390.331084: {"stream":"veteth@bookTicker","data":{"u":327913243,"s":"VETETH","b":"0.00009388","B":"105577.00000000","a":"0.00009405","A":"103020.00000000"}}
1618677390.353324: {"stream":"veteth@bookTicker","data":{"u":327913246,"s":"VETETH","b":"0.00009388","B":"105577.00000000","a":"0.00009405","A":"19561.00000000"}}
1618677390.3832269: {"stream":"veteth@depth@100ms","data":{"e":"depthUpdate","E":1618677390328,"s":"VETETH","U":327913242,"u":327913247,"b":[["0.00009380","0.00000000"],["0.00009377","0.00000000"]],"a":[["0.00009405","19561.00000000"]]}}
1618677390.3834088: {"stream":"onttry@depth@100ms","data":{"e":"depthUpdate","E":1618677390328,"s":"ONTTRY","U":282108,"u":282109,"b":[["18.98000000","0.00000000"],["18.65000000","1862.91000000"]],"a":[]}}
1618677390.3835268: {"stream":"swrvbusd@depth@100ms","data":{"e":"depthUpdate","E":1618677390328,"s":"SWRVBUSD","U":64830313,"u":64830313,"b":[["2.26600000","131.57900000"]],"a":[]}}
1618677390.428981: {"stream":"perlbnb@bookTicker","data":{"u":97581358,"s":"PERLBNB","b":"0.00039200","B":"11110.00000000","a":"0.00039400","A":"311.00000000"}}
1618677390.4565508: {"stream":"perlbnb@bookTicker","data":{"u":97581359,"s":"PERLBNB","b":"0.00039200","B":"11110.00000000","a":"0.00039300","A":"460.00000000"}}
1618677390.483447: {"stream":"perlbnb@depth@100ms","data":{"e":"depthUpdate","E":1618677390428,"s":"PERLBNB","U":97581358,"u":97581359,"b":[],"a":[["0.00039300","460.00000000"]]}}
1618677390.4835799: {"stream":"swrvbusd@depth@100ms","data":{"e":"depthUpdate","E":1618677390428,"s":"SWRVBUSD","U":64830314,"u":64830314,"b":[["2.26800000","0.00000000"]],"a":[]}}
1618677390.484034: {"stream":"aaveupusdt@depth@100ms","data":{"e":"depthUpdate","E":1618677390428,"s":"AAVEUPUSDT","U":82463998,"u":82463999,"b":[["83.98300000","2.57000000"]],"a":[["85.39900000","2.57000000"]]}}
1618677390.491852: {"stream":"perlbnb@bookTicker","data":{"u":97581360,"s":"PERLBNB","b":"0.00039200","B":"11110.00000000","a":"0.00039400","A":"311.00000000"}}
1618677390.514834: {"stream":"perlbnb@bookTicker","data":{"u":97581361,"s":"PERLBNB","b":"0.00039200","B":"11110.00000000","a":"0.00039300","A":"460.00000000"}}
1618677390.568508: {"stream":"aaveupusdt@bookTicker","data":{"u":82464002,"s":"AAVEUPUSDT","b":"84.39800000","B":"0.25000000","a":"84.93300000","A":"66.62000000"}}
1618677390.5827131: {"stream":"perlbnb@depth@100ms","data":{"e":"depthUpdate","E":1618677390528,"s":"PERLBNB","U":97581360,"u":97581361,"b":[],"a":[["0.00039300","460.00000000"]]}}
1618677390.583271: {"stream":"aaveupusdt@depth@100ms","data":{"e":"depthUpdate","E":1618677390529,"s":"AAVEUPUSDT","U":82464000,"u":82464002,"b":[],"a":[["84.93300000","66.62000000"],["85.21200000","0.00000000"],["85.39900000","0.00000000"]]}}
1618677390.6063411: {"stream":"perlbnb@bookTicker","data":{"u":97581362,"s":"PERLBNB","b":"0.00039200","B":"11110.00000000","a":"0.00039400","A":"311.00000000"}}
1618677390.615884: {"stream":"perlbnb@bookTicker","data":{"u":97581363,"s":"PERLBNB","b":"0.00039200","B":"11110.00000000","a":"0.00039300","A":"460.00000000"}}
1618677390.626545: {"stream":"perlbnb@bookTicker","data":{"u":97581364,"s":"PERLBNB","b":"0.00039200","B":"11110.00000000","a":"0.00039400","A":"311.00000000"}}
1618677390.6829782: {"stream":"veteth@depth@100ms","data":{"e":"depthUpdate","E":1618677390628,"s":"VETETH","U":327913248,"u":327913248,"b":[["0.00009387","0.00000000"]],"a":[]}}
1618677390.683133: {"stream":"perlbnb@depth@100ms","data":{"e":"depthUpdate","E":1618677390628,"s":"PERLBNB","U":97581362,"u":97581365,"b":[],"a":[["0.00039300","0.00000000"],["0.00039500","475.00000000"]]}}
1618677390.683224: {"stream":"qspbtc@depth@100ms","data":{"e":"depthUpdate","E":1618677390628,"s":"QSPBTC","U":105811219,"u":105811219,"b":[],"a":[["0.00000225","119334.00000000"]]}}
1618677390.6944242: {"stream":"swrvbusd@bookTicker","data":{"u":64830315,"s":"SWRVBUSD","b":"2.27100000","B":"22.01100000","a":"2.27700000","A":"1.19200000"}}
1618677390.760692: {"stream":"swrvbusd@bookTicker","data":{"u":64830316,"s":"SWRVBUSD","b":"2.27100000","B":"22.01100000","a":"2.27600000","A":"20.45400000"}}
1618677390.7841878: {"stream":"swrvbusd@depth@100ms","data":{"e":"depthUpdate","E":1618677390728,"s":"SWRVBUSD","U":64830315,"u":64830316,"b":[],"a":[["2.27600000","20.45400000"]]}}
1618677390.78432: {"stream":"gtobtc@depth@100ms","data":{"e":"depthUpdate","E":1618677390728,"s":"GTOBTC","U":137196750,"u":137196750,"b":[],"a":[["0.00000166","159319.00000000"]]}}
1618677390.797504: {"stream":"gtobtc@bookTicker","data":{"u":137196751,"s":"GTOBTC","b":"0.00000162","B":"49627.00000000","a":"0.00000163","A":"345860.00000000"}}
1618677390.8014789: {"stream":"veteth@bookTicker","data":{"u":327913249,"s":"VETETH","b":"0.00009388","B":"105577.00000000","a":"0.00009404","A":"83459.00000000"}}
1618677390.882036: {"stream":"veteth@depth@100ms","data":{"e":"depthUpdate","E":1618677390828,"s":"VETETH","U":327913249,"u":327913249,"b":[],"a":[["0.00009404","83459.00000000"]]}}
1618677390.885797: {"stream":"gtobtc@depth@100ms","data":{"e":"depthUpdate","E":1618677390828,"s":"GTOBTC","U":137196751,"u":137196751,"b":[["0.00000162","49627.00000000"]],"a":[]}}
1618677390.8943691: {"stream":"aaveupusdt@bookTicker","data":{"u":82464003,"s":"AAVEUPUSDT","b":"84.39900000","B":"0.17000000","a":"84.93300000","A":"66.62000000"}}
1618677390.910439: {"stream":"aaveupusdt@bookTicker","data":{"u":82464004,"s":"AAVEUPUSDT","b":"84.40000000","B":"0.25000000","a":"84.93300000","A":"66.62000000"}}
1618677390.965827: {"stream":"busdtry@bookTicker","data":{"u":10166145,"s":"BUSDTRY","b":"8.13000000","B":"125188.34000000","a":"8.14000000","A":"82658.20000000"}}
1618677390.98133: {"stream":"veteth@bookTicker","data":{"u":327913250,"s":"VETETH","b":"0.00009389","B":"23271.00000000","a":"0.00009404","A":"83459.00000000"}}
1618677390.9814122: {"stream":"veteth@depth@100ms","data":{"e":"depthUpdate","E":1618677390928,"s":"VETETH","U":327913250,"u":327913250,"b":[["0.00009389","23271.00000000"]],"a":[]}}
1618677390.982356: {"stream":"busdtry@depth@100ms","data":{"e":"depthUpdate","E":1618677390928,"s":"BUSDTRY","U":10166145,"u":10166145,"b":[["8.13000000","125188.34000000"]],"a":[]}}
1618677390.984768: {"stream":"aaveupusdt@depth@100ms","data":{"e":"depthUpdate","E":1618677390928,"s":"AAVEUPUSDT","U":82464003,"u":82464005,"b":[["84.40000000","0.25000000"],["84.39900000","0.17000000"],["84.39800000","0.00000000"]],"a":[]}}
1618677390.998229: {"stream":"veteth@bookTicker","data":{"u":327913252,"s":"VETETH","b":"0.00009390","B":"96556.00000000","a":"0.00009404","A":"83459.00000000"}}
1618677391.018688: {"stream":"busdtry@bookTicker","data":{"u":10166146,"s":"BUSDTRY","b":"8.13000000","B":"125188.34000000","a":"8.14000000","A":"82668.19000000"}}
1618677391.082366: {"stream":"veteth@depth@100ms","data":{"e":"depthUpdate","E":1618677391028,"s":"VETETH","U":327913251,"u":327913254,"b":[["0.00009390","96556.00000000"],["0.00009388","9021.00000000"],["0.00009322","738.00000000"],["0.00009312","122.00000000"]],"a":[]}}
1618677391.083391: {"stream":"busdtry@depth@100ms","data":{"e":"depthUpdate","E":1618677391028,"s":"BUSDTRY","U":10166146,"u":10166146,"b":[],"a":[["8.14000000","82668.19000000"]]}}
1618677391.083485: {"stream":"aaveupusdt@depth@100ms","data":{"e":"depthUpdate","E":1618677391029,"s":"AAVEUPUSDT","U":82464006,"u":82464009,"b":[["84.39700000","0.00000000"],["84.39000000","0.00000000"]],"a":[]}}
1618677391.102061: {"stream":"veteth@bookTicker","data":{"u":327913255,"s":"VETETH","b":"0.00009390","B":"96556.00000000","a":"0.00009405","A":"19561.00000000"}}
1618677391.15971: {"stream":"perlbnb@bookTicker","data":{"u":97581369,"s":"PERLBNB","b":"0.00039200","B":"11110.00000000","a":"0.00039300","A":"460.00000000"}}
1618677391.182718: {"stream":"veteth@depth@100ms","data":{"e":"depthUpdate","E":1618677391128,"s":"VETETH","U":327913255,"u":327913256,"b":[["0.00009389","0.00000000"]],"a":[["0.00009404","0.00000000"]]}}
1618677391.182899: {"stream":"perlbnb@depth@100ms","data":{"e":"depthUpdate","E":1618677391128,"s":"PERLBNB","U":97581366,"u":97581369,"b":[],"a":[["0.00039300","460.00000000"],["0.00039500","2443.00000000"],["0.00039600","3731.00000000"]]}}
1618677391.196183: {"stream":"veteth@bookTicker","data":{"u":327913258,"s":"VETETH","b":"0.00009390","B":"96556.00000000","a":"0.00009405","A":"103020.00000000"}}
1618677391.218713: {"stream":"veteth@bookTicker","data":{"u":327913259,"s":"VETETH","b":"0.00009392","B":"308.00000000","a":"0.00009405","A":"103020.00000000"}}
1618677391.283249: {"stream":"veteth@depth@100ms","data":{"e":"depthUpdate","E":1618677391228,"s":"VETETH","U":327913257,"u":327913260,"b":[["0.00009392","308.00000000"],["0.00009386","0.00000000"],["0.00009126","1130.00000000"]],"a":[["0.00009405","103020.00000000"]]}}
1618677391.283436: {"stream":"perlbnb@depth@100ms","data":{"e":"depthUpdate","E":1618677391228,"s":"PERLBNB","U":97581370,"u":97581370,"b":[],"a":[["0.00039600","1262.00000000"]]}}
1618677391.283509: {"stream":"swrvbusd@depth@100ms","data":{"e":"depthUpdate","E":1618677391228,"s":"SWRVBUSD","U":64830317,"u":64830317,"b":[["2.26600000","98.59100000"],["2.26500000","139.51700000"]],"a":[]}}
1618677391.283804: {"stream":"aaveupusdt@depth@100ms","data":{"e":"depthUpdate","E":1618677391229,"s":"AAVEUPUSDT","U":82464010,"u":82464010,"b":[["83.98300000","0.00000000"]],"a":[]}}
1618677391.289423: {"stream":"swrvbusd@bookTicker","data":{"u":64830318,"s":"SWRVBUSD","b":"2.27100000","B":"22.01100000","a":"2.27700000","A":"1.19200000"}}
1618677391.3363159: {"stream":"gtobtc@bookTicker","data":{"u":137196752,"s":"GTOBTC","b":"0.00000162","B":"59627.00000000","a":"0.00000163","A":"345860.00000000"}}
1618677391.336374: {"stream":"aaveupusdt@bookTicker","data":{"u":82464012,"s":"AAVEUPUSDT","b":"84.40000000","B":"3.25000000","a":"84.93300000","A":"66.62000000"}}
1618677391.355915: {"stream":"gtobtc@bookTicker","data":{"u":137196753,"s":"GTOBTC","b":"0.00000162","B":"49627.00000000","a":"0.00000163","A":"345860.00000000"}}
1618677391.359361: {"stream":"swrvbusd@bookTicker","data":{"u":64830321,"s":"SWRVBUSD","b":"2.27100000","B":"22.01100000","a":"2.27600000","A":"20.45400000"}}
1618677391.359443: {"stream":"gtobtc@bookTicker","data":{"u":137196754,"s":"GTOBTC","b":"0.00000162","B":"59627.00000000","a":"0.00000163","A":"345860.00000000"}}
1618677391.3679411: {"stream":"aaveupusdt@bookTicker","data":{"u":82464013,"s":"AAVEUPUSDT","b":"84.40000000","B":"3.25000000","a":"84.93300000","A":"69.62000000"}}
1618677391.368014: {"stream":"gtobtc@bookTicker","data":{"u":137196755,"s":"GTOBTC","b":"0.00000162","B":"49627.00000000","a":"0.00000163","A":"345860.00000000"}}
1618677391.382148: {"stream":"veteth@depth@100ms","data":{"e":"depthUpdate","E":1618677391328,"s":"VETETH","U":327913261,"u":327913262,"b":[["0.00009390","0.00000000"],["0.00009389","96556.00000000"]],"a":[]}}
1618677391.3823218: {"stream":"swrvbusd@depth@100ms","data":{"e":"depthUpdate","E":1618677391328,"s":"SWRVBUSD","U":64830318,"u":64830321,"b":[["2.26600000","131.57900000"],["2.26500000","171.22500000"]],"a":[["2.27600000","20.45400000"]]}}
1618677391.384382: {"stream":"gtobtc@depth@100ms","data":{"e":"depthUpdate","E":1618677391329,"s":"GTOBTC","U":137196752,"u":137196755,"b":[["0.00000162","49627.00000000"]],"a":[]}}
1618677391.3844721: {"stream":"aaveupusdt@depth@100ms","data":{"e":"depthUpdate","E":1618677391329,"s":"AAVEUPUSDT","U":82464011,"u":82464013,"b":[["84.40000000","3.25000000"],["84.39900000","0.00000000"]],"a":[["84.93300000","69.62000000"]]}}
1618677391.384544: {"stream":"gtobtc@bookTicker","data":{"u":137196756,"s":"GTOBTC","b":"0.00000162","B":"59627.00000000","a":"0.00000163","A":"345860.00000000"}}
1618677391.388461: {"stream":"aaveupusdt@bookTicker","data":{"u":82464014,"s":"AAVEUPUSDT","b":"84.40000000","B":"3.00000000","a":"84.93300000","A":"69.62000000"}}
1618677391.391905: {"stream":"aaveupusdt@bookTicker","data":{"u":82464015,"s":"AAVEUPUSDT","b":"84.40100000","B":"0.25000000","a":"84.93300000","A":"69.62000000"}}
1618677391.409218: {"stream":"gtobtc@bookTicker","data":{"u":137196757,"s":"GTOBTC","b":"0.00000162","B":"49627.00000000","a":"0.00000163","A":"345860.00000000"}}
1618677391.482322: {"stream":"qspbtc@depth@100ms","data":{"e":"depthUpdate","E":1618677391428,"s":"QSPBTC","U":105811220,"u":105811220,"b":[["0.00000144","145517.00000000"]],"a":[]}}
1618677391.4851341: {"stream":"gtobtc@depth@100ms","data":{"e":"depthUpdate","E":1618677391429,"s":"GTOBTC","U":137196756,"u":137196757,"b":[["0.00000162","49627.00000000"]],"a":[]}}
1618677391.485269: {"stream":"aaveupusdt@depth@100ms","data":{"e":"depthUpdate","E":1618677391429,"s":"AAVEUPUSDT","U":82464014,"u":82464018,"b":[["84.40100000","0.25000000"],["84.40000000","3.00000000"],["83.84600000","2.57000000"],["82.01600000","0.00000000"]],"a":[["85.34900000","2.57000000"]]}}
1618677391.585166: {"stream":"gtobtc@depth@100ms","data":{"e":"depthUpdate","E":1618677391529,"s":"GTOBTC","U":137196758,"u":137196758,"b":[["0.00000143","14349.00000000"]],"a":[]}}
1618677391.629914: {"stream":"veteth@bookTicker","data":{"u":327913263,"s":"VETETH","b":"0.00009392","B":"308.00000000","a":"0.00009404","A":"9006.00000000"}}
1618677391.6848269: {"stream":"veteth@depth@100ms","data":{"e":"depthUpdate","E":1618677391628,"s":"VETETH","U":327913263,"u":327913263,"b":[],"a":[["0.00009404","9006.00000000"]]}}
1618677391.698567: {"stream":"veteth@bookTicker","data":{"u":327913264,"s":"VETETH","b":"0.00009392","B":"308.00000000","a":"0.00009405","A":"103020.00000000"}}
1618677391.7449741: {"stream":"veteth@bookTicker","data":{"u":327913265,"s":"VETETH","b":"0.00009389","B":"96556.00000000","a":"0.00009405","A":"103020.00000000"}}
1618677391.784684: {"stream":"veteth@depth@100ms","data":{"e":"depthUpdate","E":1618677391728,"s":"VETETH","U":327913264,"u":327913265,"b":[["0.00009392","0.00000000"]],"a":[["0.00009404","0.00000000"]]}}
1618677391.7848608: {"stream":"perlbnb@depth@100ms","data":{"e":"depthUpdate","E":1618677391728,"s":"PERLBNB","U":97581371,"u":97581371,"b":[["0.00038800","5222.00000000"]],"a":[]}}
1618677391.784928: {"stream":"aaveupusdt@depth@100ms","data":{"e":"depthUpdate","E":1618677391729,"s":"AAVEUPUSDT","U":82464019,"u":82464019,"b":[["81.46100000","2.48000000"]],"a":[]}}
1618677391.883541: {"stream":"perlbnb@depth@100ms","data":{"e":"depthUpdate","E":1618677391828,"s":"PERLBNB","U":97581372,"u":97581372,"b":[["0.00038900","144525.00000000"]],"a":[]}}
1618677391.890433: {"stream":"swrvbusd@bookTicker","data":{"u":64830322,"s":"SWRVBUSD","b":"2.27100000","B":"22.01100000","a":"2.27700000","A":"1.19200000"}}
1618677391.95556: {"stream":"swrvbusd@bookTicker","data":{"u":64830323,"s":"SWRVBUSD","b":"2.27100000","B":"22.01100000","a":"2.27600000","A":"20.45400000"}}
1618677391.9694579: {"stream":"veteth@bookTicker","data":{"u":327913266,"s":"VETETH","b":"0.00009389","B":"96556.00000000","a":"0.00009404","A":"9006.00000000"}}
1618677391.983381: {"stream":"veteth@depth@100ms","data":{"e":"depthUpdate","E":1618677391928,"s":"VETETH","U":327913266,"u":327913267,"b":[],"a":[["0.00009404","9006.00000000"],["0.00009405","19561.00000000"]]}}
1618677391.983547: {"stream":"swrvbusd@depth@100ms","data":{"e":"depthUpdate","E":1618677391929,"s":"SWRVBUSD","U":64830322,"u":64830323,"b":[],"a":[["2.27600000","20.45400000"]]}}
1618677391.984055: {"stream":"aaveupusdt@depth@100ms","data":{"e":"depthUpdate","E":1618677391929,"s":"AAVEUPUSDT","U":82464020,"u":82464021,"b":[["83.84600000","0.00000000"]],"a":[["85.34900000","0.00000000"]]}}
1618677391.992692: {"stream":"veteth@bookTicker","data":{"u":327913268,"s":"VETETH","b":"0.00009389","B":"96556.00000000","a":"0.00009403","A":"83459.00000000"}}
1618677392.015401: {"stream":"veteth@kline_1m","data":{"e":"kline","E":1618677391949,"s":"VETETH","k":{"t":1618677360000,"T":1618677419999,"s":"VETETH","i":"1m","f":6849492,"L":6849499,"o":"0.00009392","c":"0.00009405","h":"0.00009405","l":"0.00009378","v":"34978.00000000","n":8,"x":false,"q":"3.28879012","V":"34310.00000000","Q":"3.22614508","B":"0"}}}
1618677392.083288: {"stream":"veteth@depth@100ms","data":{"e":"depthUpdate","E":1618677392028,"s":"VETETH","U":327913268,"u":327913271,"b":[["0.00009342","5887.00000000"],["0.00009332","7826.00000000"]],"a":[["0.00009403","83459.00000000"],["0.00009405","0.00000000"]]}}
1618677392.199492: {"stream":"veteth@depth@100ms","data":{"e":"depthUpdate","E":1618677392129,"s":"VETETH","U":327913272,"u":327913272,"b":[],"a":[["0.00009414","833.00000000"]]}}
1618677392.28285: {"stream":"veteth@depth@100ms","data":{"e":"depthUpdate","E":1618677392229,"s":"VETETH","U":327913273,"u":327913275,"b":[["0.00009355","142391.00000000"]],"a":[["0.00009410","540.00000000"],["0.00009418","157839.00000000"]]}}
1618677392.2854662: {"stream":"aaveupusdt@depth@100ms","data":{"e":"depthUpdate","E":1618677392229,"s":"AAVEUPUSDT","U":82464022,"u":82464024,"b":[],"a":[["84.93400000","0.00000000"]]}}
1618677392.3833878: {"stream":"veteth@depth@100ms","data":{"e":"depthUpdate","E":1618677392329,"s":"VETETH","U":327913276,"u":327913277,"b":[["0.00009372","296.00000000"],["0.00009353","2064.00000000"]],"a":[]}}
1618677392.383553: {"stream":"steemeth@depth@100ms","data":{"e":"depthUpdate","E":1618677392329,"s":"STEEMETH","U":126265010,"u":126265011,"b":[["0.00050500","711.00000000"],["0.00050400","864.15000000"]],"a":[]}}
1618677392.4644191: {"stream":"swrvbusd@bookTicker","data":{"u":64830325,"s":"SWRVBUSD","b":"2.27100000","B":"22.01100000","a":"2.27700000","A":"1.19200000"}}
1618677392.483725: {"stream":"veteth@depth@100ms","data":{"e":"depthUpdate","E":1618677392429,"s":"VETETH","U":327913278,"u":327913278,"b":[["0.00009347","0.00000000"]],"a":[]}}
1618677392.4838789: {"stream":"swrvbusd@depth@100ms","data":{"e":"depthUpdate","E":1618677392429,"s":"SWRVBUSD","U":64830324,"u":64830326,"b":[["2.26700000","191.48800000"],["2.26600000","98.59100000"],["2.26500000","139.51700000"]],"a":[["2.27600000","0.00000000"]]}}
1618677392.533542: {"stream":"swrvbusd@bookTicker","data":{"u":64830329,"s":"SWRVBUSD","b":"2.27100000","B":"22.01100000","a":"2.27600000","A":"20.45400000"}}
1618677392.5373492: {"stream":"aaveupusdt@bookTicker","data":{"u":82464027,"s":"AAVEUPUSDT","b":"84.40100000","B":"0.25000000","a":"84.93200000","A":"94.16000000"}}
1618677392.584067: {"stream":"swrvbusd@depth@100ms","data":{"e":"depthUpdate","E":1618677392529,"s":"SWRVBUSD","U":64830327,"u":64830330,"b":[["2.26600000","131.57900000"],["2.26500000","165.06800000"]],"a":[["2.27600000","20.45400000"]]}}
1618677392.5842402: {"stream":"steemeth@depth@100ms","data":{"e":"depthUpdate","E":1618677392529,"s":"STEEMETH","U":126265012,"u":126265013,"b":[["0.00050500","908.15000000"]],"a":[]}}
1618677392.584325: {"stream":"aaveupusdt@depth@100ms","data":{"e":"depthUpdate","E":1618677392529,"s":"AAVEUPUSDT","U":82464025,"u":82464027,"b":[["83.98300000","2.57000000"]],"a":[["84.93200000","94.16000000"],["85.39900000","2.57000000"]]}}
1618677392.601155: {"stream":"aaveupusdt@bookTicker","data":{"u":82464029,"s":"AAVEUPUSDT","b":"84.40100000","B":"0.25000000","a":"84.93200000","A":"200.09000000"}}
1618677392.669644: {"stream":"aaveupusdt@bookTicker","data":{"u":82464030,"s":"AAVEUPUSDT","b":"84.40100000","B":"0.25000000","a":"84.93200000","A":"221.49000000"}}
1618677392.6845288: {"stream":"aaveupusdt@depth@100ms","data":{"e":"depthUpdate","E":1618677392629,"s":"AAVEUPUSDT","U":82464028,"u":82464030,"b":[],"a":[["84.93200000","221.49000000"],["85.39900000","0.00000000"]]}}
1618677392.88531: {"stream":"adarub@depth@100ms","data":{"e":"depthUpdate","E":1618677392829,"s":"ADARUB","U":1720414,"u":1720414,"b":[],"a":[["106.72000000","0.00000000"]]}}
1618677392.885466: {"stream":"aaveupusdt@depth@100ms","data":{"e":"depthUpdate","E":1618677392829,"s":"AAVEUPUSDT","U":82464031,"u":82464033,"b":[["84.27300000","35.61000000"]],"a":[]}}
1618677392.92114: {"stream":"aaveupusdt@bookTicker","data":{"u":82464034,"s":"AAVEUPUSDT","b":"84.40200000","B":"0.17000000","a":"84.93200000","A":"221.49000000"}}
1618677392.9844632: {"stream":"aaveupusdt@depth@100ms","data":{"e":"depthUpdate","E":1618677392929,"s":"AAVEUPUSDT","U":82464034,"u":82464034,"b":[["84.40200000","0.17000000"]],"a":[]}}
1618677393.028393: {"stream":"aaveupusdt@bookTicker","data":{"u":82464035,"s":"AAVEUPUSDT","b":"84.40300000","B":"0.25000000","a":"84.93200000","A":"221.49000000"}}
1618677393.070553: {"stream":"swrvbusd@bookTicker","data":{"u":64830331,"s":"SWRVBUSD","b":"2.27100000","B":"22.01100000","a":"2.27700000","A":"1.19200000"}}
1618677393.0830898: {"stream":"veteth@depth@100ms","data":{"e":"depthUpdate","E":1618677393029,"s":"VETETH","U":327913279,"u":327913279,"b":[],"a":[["0.00009420","2064.00000000"]]}}
1618677393.083245: {"stream":"swrvbusd@depth@100ms","data":{"e":"depthUpdate","E":1618677393029,"s":"SWRVBUSD","U":64830331,"u":64830331,"b":[],"a":[["2.27600000","0.00000000"]]}}
1618677393.0863318: {"stream":"aaveupusdt@depth@100ms","data":{"e":"depthUpdate","E":1618677393029,"s":"AAVEUPUSDT","U":82464035,"u":82464036,"b":[["84.40300000","0.25000000"],["84.40100000","0.00000000"]],"a":[]}}
1618677393.0906081: {"stream":"onttry@bookTicker","data":{"u":282110,"s":"ONTTRY","b":"18.99000000","B":"430.26000000","a":"19.03000000","A":"1177.09000000"}}
1618677393.0906901: {"stream":"onttry@kline_1m","data":{"e":"kline","E":1618677393036,"s":"ONTTRY","k":{"t":1618677360000,"T":1618677419999,"s":"ONTTRY","i":"1m","f":9332,"L":9333,"o":"19.00000000","c":"19.00000000","h":"19.00000000","l":"19.00000000","v":"26.62000000","n":2,"x":false,"q":"505.78000000","V":"5.00000000","Q":"95.00000000","B":"0"}}}
1618677393.090764: {"stream":"onttry@aggTrade","data":{"e":"aggTrade","E":1618677393036,"s":"ONTTRY","a":8611,"p":"19.00000000","q":"21.62000000","f":9333,"l":9333,"T":1618677393033,"m":true,"M":true}}
1618677393.145191: {"stream":"swrvbusd@bookTicker","data":{"u":64830332,"s":"SWRVBUSD","b":"2.27100000","B":"22.01100000","a":"2.27600000","A":"20.45400000"}}
1618677393.183664: {"stream":"adarub@depth@100ms","data":{"e":"depthUpdate","E":1618677393129,"s":"ADARUB","U":1720415,"u":1720415,"b":[],"a":[["106.83000000","146.07000000"]]}}
1618677393.183818: {"stream":"veteth@depth@100ms","data":{"e":"depthUpdate","E":1618677393129,"s":"VETETH","U":327913280,"u":327913280,"b":[],"a":[["0.00009446","174.00000000"]]}}
1618677393.183881: {"stream":"onttry@depth@100ms","data":{"e":"depthUpdate","E":1618677393129,"s":"ONTTRY","U":282110,"u":282110,"b":[["19.00000000","0.00000000"]],"a":[]}}
1618677393.184387: {"stream":"swrvbusd@depth@100ms","data":{"e":"depthUpdate","E":1618677393129,"s":"SWRVBUSD","U":64830332,"u":64830332,"b":[],"a":[["2.27600000","20.45400000"]]}}
1618677393.28431: {"stream":"perlbnb@depth@100ms","data":{"e":"depthUpdate","E":1618677393229,"s":"PERLBNB","U":97581373,"u":97581373,"b":[["0.00039000","2250.00000000"]],"a":[]}}
1618677393.3342988: {"stream":"onttry@bookTicker","data":{"u":282111,"s":"ONTTRY","b":"18.99000000","B":"429.20000000","a":"19.03000000","A":"1177.09000000"}}
1618677393.334383: {"stream":"onttry@aggTrade","data":{"e":"aggTrade","E":1618677393278,"s":"ONTTRY","a":8612,"p":"18.99000000","q":"1.06000000","f":9334,"l":9334,"T":1618677393275,"m":true,"M":true}}
1618677393.3400981: {"stream":"aaveupusdt@bookTicker","data":{"u":82464038,"s":"AAVEUPUSDT","b":"84.40000000","B":"3.00000000","a":"84.93200000","A":"221.49000000"}}
1618677393.34018: {"stream":"aaveupusdt@bookTicker","data":{"u":82464039,"s":"AAVEUPUSDT","b":"84.40100000","B":"0.25000000","a":"84.93200000","A":"221.49000000"}}
1618677393.384467: {"stream":"perlbnb@depth@100ms","data":{"e":"depthUpdate","E":1618677393329,"s":"PERLBNB","U":97581374,"u":97581377,"b":[["0.00039100","6316.00000000"],["0.00039000","2250.00000000"]],"a":[]}}
1618677393.384608: {"stream":"onttry@depth@100ms","data":{"e":"depthUpdate","E":1618677393329,"s":"ONTTRY","U":282111,"u":282111,"b":[["18.99000000","429.20000000"]],"a":[]}}
1618677393.384916: {"stream":"aaveupusdt@depth@100ms","data":{"e":"depthUpdate","E":1618677393329,"s":"AAVEUPUSDT","U":82464037,"u":82464039,"b":[["84.40300000","0.00000000"],["84.40200000","0.00000000"],["84.40100000","0.25000000"]],"a":[]}}
1618677393.481766: {"stream":"onttry@bookTicker","data":{"u":282112,"s":"ONTTRY","b":"18.96000000","B":"189.58000000","a":"19.03000000","A":"1177.09000000"}}
1618677393.4818492: {"stream":"onttry@aggTrade","data":{"e":"aggTrade","E":1618677393428,"s":"ONTTRY","a":8613,"p":"18.99000000","q":"429.20000000","f":9335,"l":9335,"T":1618677393427,"m":true,"M":true}}
1618677393.4846761: {"stream":"onttry@depth@100ms","data":{"e":"depthUpdate","E":1618677393429,"s":"ONTTRY","U":282112,"u":282112,"b":[["18.99000000","0.00000000"]],"a":[]}}
1618677393.492875: {"stream":"onttry@bookTicker","data":{"u":282113,"s":"ONTTRY","b":"18.96000000","B":"189.58000000","a":"19.02000000","A":"440.98000000"}}
1618677393.583968: {"stream":"onttry@depth@100ms","data":{"e":"depthUpdate","E":1618677393529,"s":"ONTTRY","U":282113,"u":282115,"b":[["18.86000000","146.32000000"],["18.82000000","475.59000000"]],"a":[["19.02000000","440.98000000"]]}}
1618677393.5857239: {"stream":"aaveupusdt@depth@100ms","data":{"e":"depthUpdate","E":1618677393530,"s":"AAVEUPUSDT","U":82464040,"u":82464040,"b":[],"a":[["85.34900000","2.57000000"]]}}
1618677393.6337762: {"stream":"perlbnb@bookTicker","data":{"u":97581379,"s":"PERLBNB","b":"0.00039200","B":"11110.00000000","a":"0.00039400","A":"311.00000000"}}
1618677393.6403499: {"stream":"perlbnb@bookTicker","data":{"u":97581380,"s":"PERLBNB","b":"0.00039200","B":"11110.00000000","a":"0.00039400","A":"771.00000000"}}
1618677393.649017: {"stream":"swrvbusd@bookTicker","data":{"u":64830334,"s":"SWRVBUSD","b":"2.27100000","B":"22.01100000","a":"2.27700000","A":"1.19200000"}}
1618677393.6835442: {"stream":"perlbnb@depth@100ms","data":{"e":"depthUpdate","E":1618677393629,"s":"PERLBNB","U":97581378,"u":97581382,"b":[],"a":[["0.00039300","0.00000000"],["0.00039400","771.00000000"],["0.00039500","15.00000000"],["0.00039600","6165.00000000"]]}}
1618677393.683725: {"stream":"swrvbusd@depth@100ms","data":{"e":"depthUpdate","E":1618677393629,"s":"SWRVBUSD","U":64830333,"u":64830337,"b":[["2.26800000","39.14500000"],["2.26600000","130.29900000"],["2.26500000","133.36000000"]],"a":[["2.27600000","0.00000000"]]}}
1618677393.728279: {"stream":"swrvbusd@bookTicker","data":{"u":64830338,"s":"SWRVBUSD","b":"2.27100000","B":"22.01100000","a":"2.27600000","A":"20.45400000"}}
1618677393.784417: {"stream":"swrvbusd@depth@100ms","data":{"e":"depthUpdate","E":1618677393729,"s":"SWRVBUSD","U":64830338,"u":64830338,"b":[],"a":[["2.27600000","20.45400000"]]}}
1618677393.88416: {"stream":"qspbtc@depth@100ms","data":{"e":"depthUpdate","E":1618677393829,"s":"QSPBTC","U":105811221,"u":105811221,"b":[["0.00000142","3126.00000000"]],"a":[]}}
1618677393.895627: {"stream":"veteth@bookTicker","data":{"u":327913281,"s":"VETETH","b":"0.00009388","B":"9021.00000000","a":"0.00009403","A":"83459.00000000"}}
1618677393.943855: {"stream":"veteth@bookTicker","data":{"u":327913285,"s":"VETETH","b":"0.00009389","B":"96556.00000000","a":"0.00009403","A":"83459.00000000"}}
1618677393.947343: {"stream":"veteth@bookTicker","data":{"u":327913286,"s":"VETETH","b":"0.00009388","B":"9021.00000000","a":"0.00009403","A":"83459.00000000"}}
1618677393.97278: {"stream":"veteth@bookTicker","data":{"u":327913290,"s":"VETETH","b":"0.00009388","B":"9021.00000000","a":"0.00009402","A":"20116.00000000"}}
1618677393.983561: {"stream":"veteth@depth@100ms","data":{"e":"depthUpdate","E":1618677393929,"s":"VETETH","U":327913281,"u":327913291,"b":[["0.00009389","0.00000000"],["0.00009374","96556.00000000"],["0.00009373","1126.00000000"]],"a":[["0.00009402","20116.00000000"],["0.00009403","0.00000000"]]}}
1618677393.990742: {"stream":"veteth@bookTicker","data":{"u":327913293,"s":"VETETH","b":"0.00009388","B":"9021.00000000","a":"0.00009401","A":"83459.00000000"}}
1618677394.083432: {"stream":"veteth@depth@100ms","data":{"e":"depthUpdate","E":1618677394029,"s":"VETETH","U":327913292,"u":327913295,"b":[["0.00009373","0.00000000"],["0.00009353","0.00000000"]],"a":[["0.00009401","83459.00000000"],["0.00009417","26005.00000000"]]}}
1618677394.108858: {"stream":"veteth@bookTicker","data":{"u":327913296,"s":"VETETH","b":"0.00009374","B":"96556.00000000","a":"0.00009401","A":"83459.00000000"}}
1618677394.1847901: {"stream":"veteth@depth@100ms","data":{"e":"depthUpdate","E":1618677394129,"s":"VETETH","U":327913296,"u":327913297,"b":[["0.00009388","0.00000000"],["0.00009352","25850.00000000"]],"a":[]}}
1618677394.188695: {"stream":"veteth@bookTicker","data":{"u":327913298,"s":"VETETH","b":"0.00009375","B":"9033.00000000","a":"0.00009401","A":"83459.00000000"}}
1618677394.2454348: {"stream":"veteth@bookTicker","data":{"u":327913302,"s":"VETETH","b":"0.00009376","B":"96556.00000000","a":"0.00009401","A":"83459.00000000"}}
1618677394.270453: {"stream":"swrvbusd@bookTicker","data":{"u":64830339,"s":"SWRVBUSD","b":"2.27100000","B":"22.01100000","a":"2.27700000","A":"1.19200000"}}
1618677394.285129: {"stream":"veteth@depth@100ms","data":{"e":"depthUpdate","E":1618677394229,"s":"VETETH","U":327913298,"u":327913303,"b":[["0.00009376","96556.00000000"],["0.00009375","9033.00000000"],["0.00009374","0.00000000"],["0.00009342","105887.00000000"]],"a":[["0.00009442","0.00000000"],["0.00012500","123124.00000000"]]}}
1618677394.285356: {"stream":"swrvbusd@depth@100ms","data":{"e":"depthUpdate","E":1618677394230,"s":"SWRVBUSD","U":64830339,"u":64830339,"b":[],"a":[["2.27600000","0.00000000"]]}}
1618677394.287273: {"stream":"veteth@bookTicker","data":{"u":327913304,"s":"VETETH","b":"0.00009377","B":"4638.00000000","a":"0.00009401","A":"83459.00000000"}}
1618677394.332463: {"stream":"veteth@bookTicker","data":{"u":327913306,"s":"VETETH","b":"0.00009375","B":"9033.00000000","a":"0.00009401","A":"83459.00000000"}}
1618677394.341036: {"stream":"veteth@bookTicker","data":{"u":327913307,"s":"VETETH","b":"0.00009378","B":"96556.00000000","a":"0.00009401","A":"83459.00000000"}}
1618677394.347219: {"stream":"swrvbusd@bookTicker","data":{"u":64830340,"s":"SWRVBUSD","b":"2.27100000","B":"22.01100000","a":"2.27600000","A":"20.45400000"}}
1618677394.3496141: {"stream":"aaveupusdt@bookTicker","data":{"u":82464041,"s":"AAVEUPUSDT","b":"84.40100000","B":"0.25000000","a":"84.93100000","A":"1.50000000"}}
1618677394.3692539: {"stream":"aaveupusdt@bookTicker","data":{"u":82464042,"s":"AAVEUPUSDT","b":"84.40100000","B":"0.25000000","a":"84.93100000","A":"8.20000000"}}
1618677394.3841732: {"stream":"veteth@depth@100ms","data":{"e":"depthUpdate","E":1618677394329,"s":"VETETH","U":327913304,"u":327913307,"b":[["0.00009378","96556.00000000"],["0.00009377","0.00000000"],["0.00009376","0.00000000"]],"a":[]}}
1618677394.3843598: {"stream":"swrvbusd@depth@100ms","data":{"e":"depthUpdate","E":1618677394330,"s":"SWRVBUSD","U":64830340,"u":64830340,"b":[],"a":[["2.27600000","20.45400000"]]}}
1618677394.384796: {"stream":"aaveupusdt@depth@100ms","data":{"e":"depthUpdate","E":1618677394330,"s":"AAVEUPUSDT","U":82464041,"u":82464042,"b":[],"a":[["84.93100000","8.20000000"]]}}
1618677394.392124: {"stream":"onttry@bookTicker","data":{"u":282116,"s":"ONTTRY","b":"18.94000000","B":"204.81000000","a":"19.02000000","A":"440.98000000"}}
1618677394.4003258: {"stream":"onttry@bookTicker","data":{"u":282119,"s":"ONTTRY","b":"18.94000000","B":"204.81000000","a":"18.99000000","A":"210.27000000"}}
1618677394.485601: {"stream":"onttry@depth@100ms","data":{"e":"depthUpdate","E":1618677394430,"s":"ONTTRY","U":282116,"u":282123,"b":[["18.96000000","0.00000000"],["18.62000000","1448.43000000"]],"a":[["18.99000000","210.27000000"],["19.40000000","1561.09000000"],["20.17000000","2756.31000000"],["20.21000000","3870.04000000"],["20.24000000","3526.13000000"]]}}
1618677394.4857569: {"stream":"aaveupusdt@depth@100ms","data":{"e":"depthUpdate","E":1618677394430,"s":"AAVEUPUSDT","U":82464043,"u":82464043,"b":[],"a":[["85.34900000","0.00000000"]]}}
1618677394.524405: {"stream":"perlbnb@bookTicker","data":{"u":97581383,"s":"PERLBNB","b":"0.00039200","B":"26442.00000000","a":"0.00039400","A":"771.00000000"}}
1618677394.5830169: {"stream":"perlbnb@depth@100ms","data":{"e":"depthUpdate","E":1618677394530,"s":"PERLBNB","U":97581383,"u":97581383,"b":[["0.00039200","26442.00000000"]],"a":[]}}
1618677394.5852292: {"stream":"swrvbusd@depth@100ms","data":{"e":"depthUpdate","E":1618677394530,"s":"SWRVBUSD","U":64830341,"u":64830342,"b":[["2.26800000","32.98800000"],["2.26700000","9.28800000"]],"a":[]}}
1618677394.5853739: {"stream":"aaveupusdt@depth@100ms","data":{"e":"depthUpdate","E":1618677394530,"s":"AAVEUPUSDT","U":82464044,"u":82464044,"b":[],"a":[["84.93200000","127.33000000"]]}}
1618677394.6170912: {"stream":"perlbnb@bookTicker","data":{"u":97581384,"s":"PERLBNB","b":"0.00039200","B":"11110.00000000","a":"0.00039400","A":"771.00000000"}}
1618677394.683718: {"stream":"perlbnb@depth@100ms","data":{"e":"depthUpdate","E":1618677394630,"s":"PERLBNB","U":97581384,"u":97581384,"b":[["0.00039200","11110.00000000"]],"a":[]}}
1618677394.686781: {"stream":"aaveupusdt@depth@100ms","data":{"e":"depthUpdate","E":1618677394630,"s":"AAVEUPUSDT","U":82464045,"u":82464045,"b":[],"a":[["84.93200000","21.40000000"]]}}
1618677394.707105: {"stream":"perlbnb@bookTicker","data":{"u":97581385,"s":"PERLBNB","b":"0.00039200","B":"26442.00000000","a":"0.00039400","A":"771.00000000"}}
1618677394.785119: {"stream":"perlbnb@depth@100ms","data":{"e":"depthUpdate","E":1618677394730,"s":"PERLBNB","U":97581385,"u":97581385,"b":[["0.00039200","26442.00000000"]],"a":[]}}
1618677394.785742: {"stream":"aaveupusdt@depth@100ms","data":{"e":"depthUpdate","E":1618677394730,"s":"AAVEUPUSDT","U":82464046,"u":82464046,"b":[],"a":[["84.93200000","0.00000000"]]}}
1618677394.8318038: {"stream":"aaveupusdt@bookTicker","data":{"u":82464047,"s":"AAVEUPUSDT","b":"84.40100000","B":"0.25000000","a":"84.93000000","A":"94.16000000"}}
1618677394.831887: {"stream":"swrvbusd@bookTicker","data":{"u":64830344,"s":"SWRVBUSD","b":"2.27100000","B":"22.01100000","a":"2.27700000","A":"1.19200000"}}
1618677394.88538: {"stream":"swrvbusd@depth@100ms","data":{"e":"depthUpdate","E":1618677394830,"s":"SWRVBUSD","U":64830343,"u":64830346,"b":[["2.26800000","0.00000000"],["2.26600000","131.57900000"],["2.26500000","165.06800000"]],"a":[["2.27600000","0.00000000"]]}}
1618677394.885571: {"stream":"aaveupusdt@depth@100ms","data":{"e":"depthUpdate","E":1618677394830,"s":"AAVEUPUSDT","U":82464047,"u":82464050,"b":[["84.09900000","0.00000000"]],"a":[["84.93000000","94.16000000"],["85.39900000","0.00000000"]]}}
1618677394.897345: {"stream":"swrvbusd@bookTicker","data":{"u":64830347,"s":"SWRVBUSD","b":"2.27100000","B":"22.01100000","a":"2.27600000","A":"20.45400000"}}
1618677394.905134: {"stream":"aaveupusdt@bookTicker","data":{"u":82464051,"s":"AAVEUPUSDT","b":"84.40100000","B":"0.25000000","a":"84.93000000","A":"200.09000000"}}
1618677394.935874: {"stream":"aaveupusdt@bookTicker","data":{"u":82464055,"s":"AAVEUPUSDT","b":"84.40100000","B":"0.25000000","a":"84.93000000","A":"200.26000000"}}
1618677394.973095: {"stream":"aaveupusdt@bookTicker","data":{"u":82464056,"s":"AAVEUPUSDT","b":"84.40100000","B":"0.25000000","a":"84.92900000","A":"21.40000000"}}
1618677394.984473: {"stream":"swrvbusd@depth@100ms","data":{"e":"depthUpdate","E":1618677394930,"s":"SWRVBUSD","U":64830347,"u":64830347,"b":[],"a":[["2.27600000","20.45400000"]]}}
1618677394.985139: {"stream":"aaveupusdt@depth@100ms","data":{"e":"depthUpdate","E":1618677394930,"s":"AAVEUPUSDT","U":82464051,"u":82464056,"b":[["77.41000000","0.00000000"]],"a":[["84.92900000","21.40000000"],["84.93000000","200.26000000"],["85.06600000","133.42000000"],["85.13900000","0.00000000"]]}}
1618677395.0491478: {"stream":"veteth@bookTicker","data":{"u":327913309,"s":"VETETH","b":"0.00009375","B":"9033.00000000","a":"0.00009401","A":"83459.00000000"}}
1618677395.0607932: {"stream":"veteth@bookTicker","data":{"u":327913310,"s":"VETETH","b":"0.00009376","B":"96556.00000000","a":"0.00009401","A":"83459.00000000"}}
1618677395.061535: {"stream":"veteth@bookTicker","data":{"u":327913311,"s":"VETETH","b":"0.00009376","B":"100454.00000000","a":"0.00009401","A":"83459.00000000"}}
1618677395.0854452: {"stream":"veteth@depth@100ms","data":{"e":"depthUpdate","E":1618677395030,"s":"VETETH","U":327913308,"u":327913311,"b":[["0.00009378","0.00000000"],["0.00009376","100454.00000000"],["0.00009356","2606.00000000"]],"a":[]}}
1618677395.085612: {"stream":"swrvbusd@depth@100ms","data":{"e":"depthUpdate","E":1618677395030,"s":"SWRVBUSD","U":64830348,"u":64830348,"b":[["2.26600000","313.77900000"]],"a":[]}}
1618677395.085679: {"stream":"aaveupusdt@depth@100ms","data":{"e":"depthUpdate","E":1618677395030,"s":"AAVEUPUSDT","U":82464057,"u":82464057,"b":[["83.98300000","0.00000000"]],"a":[]}}
1618677395.088035: {"stream":"veteth@bookTicker","data":{"u":327913312,"s":"VETETH","b":"0.00009376","B":"96556.00000000","a":"0.00009401","A":"83459.00000000"}}
1618677395.122646: {"stream":"aaveupusdt@bookTicker","data":{"u":82464062,"s":"AAVEUPUSDT","b":"84.69900000","B":"5.00000000","a":"84.92900000","A":"21.40000000"}}
1618677395.1523468: {"stream":"aaveupusdt@bookTicker","data":{"u":82464066,"s":"AAVEUPUSDT","b":"84.40100000","B":"0.25000000","a":"84.92900000","A":"21.40000000"}}
1618677395.15243: {"stream":"aaveupusdt@kline_1m","data":{"e":"kline","E":1618677395082,"s":"AAVEUPUSDT","k":{"t":1618677360000,"T":1618677419999,"s":"AAVEUPUSDT","i":"1m","f":1857323,"L":1857327,"o":"84.58500000","c":"84.69900000","h":"84.69900000","l":"84.58500000","v":"6.65000000","n":5,"x":false,"q":"563.12348000","V":"1.65000000","Q":"139.62848000","B":"0"}}}
1618677395.1525052: {"stream":"aaveupusdt@aggTrade","data":{"e":"aggTrade","E":1618677395082,"s":"AAVEUPUSDT","a":1779416,"p":"84.69900000","q":"5.00000000","f":1857327,"l":1857327,"T":1618677395081,"m":true,"M":true}}
1618677395.195256: {"stream":"veteth@depth@100ms","data":{"e":"depthUpdate","E":1618677395130,"s":"VETETH","U":327913312,"u":327913312,"b":[["0.00009376","96556.00000000"]],"a":[]}}
1618677395.195384: {"stream":"aaveupusdt@depth@100ms","data":{"e":"depthUpdate","E":1618677395130,"s":"AAVEUPUSDT","U":82464058,"u":82464067,"b":[["84.69900000","0.00000000"],["84.38300000","0.00000000"],["84.18200000","4.35000000"],["83.84500000","0.00000000"],["83.76900000","132.62000000"],["78.12000000","88.70000000"]],"a":[["84.93300000","66.62000000"]]}}
1618677395.285268: {"stream":"veteth@depth@100ms","data":{"e":"depthUpdate","E":1618677395230,"s":"VETETH","U":327913313,"u":327913316,"b":[["0.00009355","0.00000000"],["0.00009347","142391.00000000"]],"a":[["0.00009418","231.00000000"],["0.00009446","375.00000000"]]}}
1618677395.361048: {"stream":"veteth@bookTicker","data":{"u":327913317,"s":"VETETH","b":"0.00009377","B":"20116.00000000","a":"0.00009401","A":"83459.00000000"}}
1618677395.376322: {"stream":"veteth@bookTicker","data":{"u":327913320,"s":"VETETH","b":"0.00009378","B":"96556.00000000","a":"0.00009401","A":"83459.00000000"}}
1618677395.383898: {"stream":"veteth@depth@100ms","data":{"e":"depthUpdate","E":1618677395330,"s":"VETETH","U":327913317,"u":327913320,"b":[["0.00009378","96556.00000000"],["0.00009377","20116.00000000"],["0.00009376","0.00000000"]],"a":[["0.00009410","158148.00000000"]]}}
1618677395.386938: {"stream":"aaveupusdt@depth@100ms","data":{"e":"depthUpdate","E":1618677395330,"s":"AAVEUPUSDT","U":82464068,"u":82464068,"b":[],"a":[["84.93000000","200.09000000"]]}}
1618677395.437954: {"stream":"swrvbusd@bookTicker","data":{"u":64830349,"s":"SWRVBUSD","b":"2.27100000","B":"22.01100000","a":"2.27700000","A":"1.19200000"}}
1618677395.485708: {"stream":"swrvbusd@depth@100ms","data":{"e":"depthUpdate","E":1618677395430,"s":"SWRVBUSD","U":64830349,"u":64830349,"b":[],"a":[["2.27600000","0.00000000"]]}}
1618677395.493043: {"stream":"veteth@bookTicker","data":{"u":327913321,"s":"VETETH","b":"0.00009377","B":"20116.00000000","a":"0.00009401","A":"83459.00000000"}}
1618677395.50032: {"stream":"swrvbusd@bookTicker","data":{"u":64830350,"s":"SWRVBUSD","b":"2.27100000","B":"22.01100000","a":"2.27600000","A":"20.45400000"}}
1618677395.5070221: {"stream":"veteth@bookTicker","data":{"u":327913322,"s":"VETETH","b":"0.00009378","B":"96556.00000000","a":"0.00009401","A":"83459.00000000"}}
1618677395.507087: {"stream":"veteth@bookTicker","data":{"u":327913323,"s":"VETETH","b":"0.00009378","B":"96556.00000000","a":"0.00009400","A":"4178.00000000"}}
1618677395.526664: {"stream":"veteth@bookTicker","data":{"u":327913325,"s":"VETETH","b":"0.00009378","B":"96556.00000000","a":"0.00009399","A":"83459.00000000"}}
1618677395.583085: {"stream":"veteth@depth@100ms","data":{"e":"depthUpdate","E":1618677395530,"s":"VETETH","U":327913321,"u":327913325,"b":[["0.00009378","96556.00000000"]],"a":[["0.00009399","83459.00000000"],["0.00009400","4178.00000000"],["0.00009401","0.00000000"]]}}
1618677395.58544: {"stream":"swrvbusd@depth@100ms","data":{"e":"depthUpdate","E":1618677395530,"s":"SWRVBUSD","U":64830350,"u":64830350,"b":[],"a":[["2.27600000","20.45400000"]]}}
1618677395.641783: {"stream":"veteth@bookTicker","data":{"u":327913326,"s":"VETETH","b":"0.00009378","B":"96556.00000000","a":"0.00009400","A":"4178.00000000"}}
1618677395.650191: {"stream":"veteth@bookTicker","data":{"u":327913327,"s":"VETETH","b":"0.00009378","B":"96556.00000000","a":"0.00009399","A":"83459.00000000"}}
1618677395.683265: {"stream":"veteth@depth@100ms","data":{"e":"depthUpdate","E":1618677395630,"s":"VETETH","U":327913326,"u":327913327,"b":[],"a":[["0.00009399","83459.00000000"]]}}
1618677395.885769: {"stream":"onttry@depth@100ms","data":{"e":"depthUpdate","E":1618677395830,"s":"ONTTRY","U":282124,"u":282125,"b":[],"a":[["19.11000000","1997.36000000"],["19.16000000","0.00000000"]]}}
1618677395.985827: {"stream":"veteth@depth@100ms","data":{"e":"depthUpdate","E":1618677395930,"s":"VETETH","U":327913328,"u":327913328,"b":[],"a":[["0.00009400","0.00000000"]]}}
1618677395.989273: {"stream":"swrvbusd@depth@100ms","data":{"e":"depthUpdate","E":1618677395930,"s":"SWRVBUSD","U":64830351,"u":64830351,"b":[["2.26600000","280.79100000"],["2.26500000","133.36000000"]],"a":[]}}
1618677395.9893901: {"stream":"aaveupusdt@depth@100ms","data":{"e":"depthUpdate","E":1618677395930,"s":"AAVEUPUSDT","U":82464069,"u":82464069,"b":[["81.46100000","0.00000000"]],"a":[]}}
1618677395.9927301: {"stream":"swrvbusd@bookTicker","data":{"u":64830353,"s":"SWRVBUSD","b":"2.27100000","B":"22.01100000","a":"2.27700000","A":"1.19200000"}}
1618677396.009254: {"stream":"onttry@kline_1m","data":{"e":"kline","E":1618677395952,"s":"ONTTRY","k":{"t":1618677360000,"T":1618677419999,"s":"ONTTRY","i":"1m","f":9332,"L":9335,"o":"19.00000000","c":"18.99000000","h":"19.00000000","l":"18.99000000","v":"456.88000000","n":4,"x":false,"q":"8676.41740000","V":"5.00000000","Q":"95.00000000","B":"0"}}}
1618677396.063297: {"stream":"swrvbusd@bookTicker","data":{"u":64830356,"s":"SWRVBUSD","b":"2.27100000","B":"22.01100000","a":"2.27600000","A":"20.45400000"}}
1618677396.0706408: {"stream":"veteth@bookTicker","data":{"u":327913330,"s":"VETETH","b":"0.00009378","B":"96556.00000000","a":"0.00009404","A":"9006.00000000"}}
1618677396.0841851: {"stream":"veteth@depth@100ms","data":{"e":"depthUpdate","E":1618677396030,"s":"VETETH","U":327913329,"u":327913330,"b":[],"a":[["0.00009399","0.00000000"],["0.00009402","0.00000000"]]}}
1618677396.084338: {"stream":"swrvbusd@depth@100ms","data":{"e":"depthUpdate","E":1618677396030,"s":"SWRVBUSD","U":64830352,"u":64830356,"b":[["2.26700000","48.43300000"],["2.26600000","312.49900000"]],"a":[["2.27600000","20.45400000"]]}}
1618677396.0847669: {"stream":"veteth@bookTicker","data":{"u":327913331,"s":"VETETH","b":"0.00009378","B":"96556.00000000","a":"0.00009403","A":"83459.00000000"}}
1618677396.08623: {"stream":"aaveupusdt@depth@100ms","data":{"e":"depthUpdate","E":1618677396030,"s":"AAVEUPUSDT","U":82464070,"u":82464073,"b":[["83.79600000","2.57000000"]],"a":[["84.99600000","250.96000000"],["85.06600000","0.00000000"],["85.25000000","2.57000000"]]}}
1618677396.152603: {"stream":"qspbtc@bookTicker","data":{"u":105811222,"s":"QSPBTC","b":"0.00000168","B":"197838.00000000","a":"0.00000169","A":"96439.00000000"}}
1618677396.184376: {"stream":"veteth@depth@100ms","data":{"e":"depthUpdate","E":1618677396130,"s":"VETETH","U":327913331,"u":327913331,"b":[],"a":[["0.00009403","83459.00000000"]]}}
1618677396.184499: {"stream":"qspbtc@depth@100ms","data":{"e":"depthUpdate","E":1618677396130,"s":"QSPBTC","U":105811222,"u":105811222,"b":[["0.00000168","197838.00000000"]],"a":[]}}
1618677396.184565: {"stream":"swrvbusd@depth@100ms","data":{"e":"depthUpdate","E":1618677396130,"s":"SWRVBUSD","U":64830357,"u":64830357,"b":[["2.26600000","130.29900000"]],"a":[]}}
1618677396.185468: {"stream":"aaveupusdt@depth@100ms","data":{"e":"depthUpdate","E":1618677396131,"s":"AAVEUPUSDT","U":82464074,"u":82464075,"b":[["84.19000000","23.76000000"]],"a":[]}}
1618677396.2332091: {"stream":"veteth@bookTicker","data":{"u":327913334,"s":"VETETH","b":"0.00009379","B":"200.00000000","a":"0.00009403","A":"83459.00000000"}}
1618677396.285919: {"stream":"veteth@depth@100ms","data":{"e":"depthUpdate","E":1618677396230,"s":"VETETH","U":327913332,"u":327913334,"b":[["0.00009379","200.00000000"]],"a":[["0.00009436","41684.00000000"],["0.00009447","0.00000000"]]}}
1618677396.2860758: {"stream":"swrvbusd@depth@100ms","data":{"e":"depthUpdate","E":1618677396230,"s":"SWRVBUSD","U":64830358,"u":64830358,"b":[["2.26700000","42.27600000"]],"a":[]}}
1618677396.2861419: {"stream":"aaveupusdt@depth@100ms","data":{"e":"depthUpdate","E":1618677396231,"s":"AAVEUPUSDT","U":82464076,"u":82464076,"b":[["81.65900000","2.47000000"]],"a":[]}}
1618677396.305304: {"stream":"veteth@bookTicker","data":{"u":327913335,"s":"VETETH","b":"0.00009379","B":"200.00000000","a":"0.00009402","A":"20116.00000000"}}
1618677396.338735: {"stream":"veteth@bookTicker","data":{"u":327913337,"s":"VETETH","b":"0.00009379","B":"200.00000000","a":"0.00009401","A":"83459.00000000"}}
1618677396.383562: {"stream":"veteth@depth@100ms","data":{"e":"depthUpdate","E":1618677396330,"s":"VETETH","U":327913335,"u":327913337,"b":[],"a":[["0.00009401","83459.00000000"],["0.00009402","20116.00000000"],["0.00009403","0.00000000"]]}}
1618677396.662165: {"stream":"swrvbusd@bookTicker","data":{"u":64830359,"s":"SWRVBUSD","b":"2.27100000","B":"22.01100000","a":"2.27700000","A":"1.19200000"}}
1618677396.666783: {"stream":"swrvbusd@bookTicker","data":{"u":64830360,"s":"SWRVBUSD","b":"2.27100000","B":"22.01100000","a":"2.27600000","A":"20.45400000"}}
1618677396.678744: {"stream":"aaveupusdt@bookTicker","data":{"u":82464079,"s":"AAVEUPUSDT","b":"84.40000000","B":"1.25000000","a":"84.92900000","A":"21.40000000"}}
1618677396.678808: {"stream":"aaveupusdt@aggTrade","data":{"e":"aggTrade","E":1618677396625,"s":"AAVEUPUSDT","a":1779417,"p":"84.40100000","q":"0.25000000","f":1857328,"l":1857328,"T":1618677396624,"m":true,"M":true}}
1618677396.6788669: {"stream":"aaveupusdt@aggTrade","data":{"e":"aggTrade","E":1618677396625,"s":"AAVEUPUSDT","a":1779418,"p":"84.40000000","q":"1.75000000","f":1857329,"l":1857329,"T":1618677396624,"m":true,"M":true}}
1618677396.6851: {"stream":"swrvbusd@depth@100ms","data":{"e":"depthUpdate","E":1618677396630,"s":"SWRVBUSD","U":64830359,"u":64830360,"b":[],"a":[["2.27600000","20.45400000"]]}}
