wss://fstream.binance.com/stream?streams=sushiusdt@aggTrade/akrousdt@aggTrade/keepusdt@aggTrade/ctkusdt@aggTrade/sushiusdt@depth@100ms/akrousdt@depth@100ms/keepusdt@depth@100ms/ctkusdt@depth@100ms/sushiusdt@kline_1m/akrousdt@kline_1m/keepusdt@kline_1m/ctkusdt@kline_1m/sushiusdt@bookTicker/akrousdt@bookTicker/keepusdt@bookTicker/ctkusdt@bookTicker <-> 1626992740.179554
1626992741.06217: {"stream":"sushiusdt@bookTicker","data":{"e":"bookTicker","u":600859600576,"s":"SUSHIUSDT","b":"7.6110","B":"2","a":"7.6120","A":"297","T":1626992741012,"E":1626992741017}}
1626992741.081672: {"stream":"sushiusdt@depth@100ms","data":{"e":"depthUpdate","E":1626992741037,"T":1626992741024,"s":"SUSHIUSDT","U":600859599090,"u":600859600917,"pu":600859598061,"b":[["7.5040","813"],["7.6090","0"],["7.6110","2"]],"a":[["7.6150","1563"],["7.6220","3284"]]}}
1626992741.3105128: {"stream":"akrousdt@depth@100ms","data":{"e":"depthUpdate","E":1626992741077,"T":1626992740974,"s":"AKROUSDT","U":600859599831,"u":600859599831,"pu":600859598737,"b":[],"a":[["0.01737","437848"]]}}
1626992741.481688: {"stream":"sushiusdt@depth@100ms","data":{"e":"depthUpdate","E":1626992741140,"T":1626992741123,"s":"SUSHIUSDT","U":600859601193,"u":600859602861,"pu":600859600917,"b":[["7.5980","1433"],["7.6000","3995"],["7.6030","648"],["7.6050","1234"],["7.6100","7"]],"a":[["7.6170","534"]]}}
1626992741.481712: {"stream":"keepusdt@depth@100ms","data":{"e":"depthUpdate","E":1626992741142,"T":1626992741093,"s":"KEEPUSDT","U":600859601246,"u":600859602316,"pu":600859581808,"b":[["0.2443","3688"],["0.2445","72866"]],"a":[["0.2465","0"]]}}
1626992742.115394: {"stream":"sushiusdt@bookTicker","data":{"e":"bookTicker","u":600859603936,"s":"SUSHIUSDT","b":"7.6110","B":"6","a":"7.6120","A":"297","T":1626992741163,"E":1626992741167}}
1626992742.115438: {"stream":"ctkusdt@depth@100ms","data":{"e":"depthUpdate","E":1626992741203,"T":1626992741156,"s":"CTKUSDT","U":600859602414,"u":600859603788,"pu":600859587990,"b":[["1.00600","14217"]],"a":[["1.01300","17718"],["1.01500","20835"]]}}
1626992742.28941: {"stream":"keepusdt@depth@100ms","data":{"e":"depthUpdate","E":1626992741252,"T":1626992741145,"s":"KEEPUSDT","U":600859603268,"u":600859603268,"pu":600859602316,"b":[],"a":[["0.2465","812"]]}}
1626992742.2894342: {"stream":"sushiusdt@depth@100ms","data":{"e":"depthUpdate","E":1626992741254,"T":1626992741208,"s":"SUSHIUSDT","U":600859603343,"u":600859604824,"pu":600859602861,"b":[["7.5930","3291"],["7.6030","771"],["7.6060","581"],["7.6070","285"],["7.6080","161"],["7.6100","0"],["7.6110","6"]],"a":[["7.6180","1632"],["7.6300","3145"],["7.6340","1006"],["7.6790","71"]]}}
1626992742.289448: {"stream":"akrousdt@depth@100ms","data":{"e":"depthUpdate","E":1626992741257,"T":1626992741238,"s":"AKROUSDT","U":600859603597,"u":600859605486,"pu":600859599831,"b":[["0.01730","183887"]],"a":[["0.01736","874535"]]}}
1626992742.2894888: {"stream":"ctkusdt@depth@100ms","data":{"e":"depthUpdate","E":1626992741312,"T":1626992741262,"s":"CTKUSDT","U":600859604807,"u":600859605954,"pu":600859603788,"b":[["1.00600","14217"]],"a":[["1.01500","20835"]]}}
1626992742.289501: {"stream":"sushiusdt@depth@100ms","data":{"e":"depthUpdate","E":1626992741364,"T":1626992741335,"s":"SUSHIUSDT","U":600859605926,"u":600859607423,"pu":600859604824,"b":[["7.5600","478"],["7.5840","2164"],["7.5940","3737"],["7.6030","751"]],"a":[["7.6170","1324"],["7.6200","674"],["7.6240","2806"],["7.6320","240"],["7.6440","4418"],["7.6500","590"]]}}
1626992742.28955: {"stream":"keepusdt@depth@100ms","data":{"e":"depthUpdate","E":1626992741379,"T":1626992741354,"s":"KEEPUSDT","U":600859606259,"u":600859607807,"pu":600859603268,"b":[["0.2438","5105"],["0.2456","17662"],["0.2457","15918"]],"a":[["0.2465","812"]]}}
1626992742.28956: {"stream":"ctkusdt@depth@100ms","data":{"e":"depthUpdate","E":1626992741415,"T":1626992741362,"s":"CTKUSDT","U":600859606973,"u":600859607977,"pu":600859605954,"b":[["1.00600","14217"]],"a":[["1.01500","20835"]]}}
1626992742.2895691: {"stream":"ctkusdt@kline_1m","data":{"e":"kline","E":1626992741424,"s":"CTKUSDT","k":{"t":1626992700000,"T":1626992759999,"s":"CTKUSDT","i":"1m","f":23961275,"L":23961322,"o":"1.01000","c":"1.01100","h":"1.01100","l":"1.01000","v":"3917","n":48,"x":false,"q":"3957.89900","V":"1729","Q":"1748.01900","B":"0"}}}
1626992742.289597: {"stream":"ctkusdt@bookTicker","data":{"e":"bookTicker","u":600859609004,"s":"CTKUSDT","b":"1.01000","B":"85782","a":"1.01100","A":"6483","T":1626992741421,"E":1626992741429}}
1626992742.289614: {"stream":"sushiusdt@depth@100ms","data":{"e":"depthUpdate","E":1626992741467,"T":1626992741441,"s":"SUSHIUSDT","U":600859607950,"u":600859609417,"pu":600859607423,"b":[["7.5300","3027"],["7.5600","3539"],["7.5610","1326"],["7.5840","3665"],["7.5940","3717"],["7.6030","771"],["7.6080","202"]],"a":[["7.6220","3284"],["7.6230","4205"],["7.6240","2826"],["7.6320","220"],["7.6440","5887"],["7.6500","3559"],["7.6590","633"],["7.6680","2599"],["7.7100","1237"]]}}
1626992742.289674: {"stream":"ctkusdt@depth@100ms","data":{"e":"depthUpdate","E":1626992741515,"T":1626992741485,"s":"CTKUSDT","U":600859608797,"u":600859610151,"pu":600859607977,"b":[["1.00600","9269"],["1.01400","0"]],"a":[["1.01100","6483"],["1.01500","15887"]]}}
1626992742.289684: {"stream":"akrousdt@depth@100ms","data":{"e":"depthUpdate","E":1626992741559,"T":1626992741467,"s":"AKROUSDT","U":600859609657,"u":600859609902,"pu":600859605486,"b":[["0.01714","1474950"]],"a":[]}}
1626992742.2897038: {"stream":"sushiusdt@depth@100ms","data":{"e":"depthUpdate","E":1626992741573,"T":1626992741546,"s":"SUSHIUSDT","U":600859609903,"u":600859611095,"pu":600859609417,"b":[["7.5750","5089"],["7.6000","4045"],["7.6040","129"],["7.6080","209"]],"a":[["7.6220","4643"],["7.6230","2846"],["7.6470","3931"]]}}
1626992742.289739: {"stream":"ctkusdt@aggTrade","data":{"e":"aggTrade","E":1626992741575,"a":16599292,"s":"CTKUSDT","p":"1.01100","q":"10","f":23961322,"l":23961322,"T":1626992741421,"m":false}}
1626992742.289757: {"stream":"akrousdt@depth@100ms","data":{"e":"depthUpdate","E":1626992741664,"T":1626992741585,"s":"AKROUSDT","U":600859611301,"u":600859611654,"pu":600859609902,"b":[["0.01724","641929"],["0.01725","955685"]],"a":[]}}
1626992742.28978: {"stream":"sushiusdt@depth@100ms","data":{"e":"depthUpdate","E":1626992741703,"T":1626992741672,"s":"SUSHIUSDT","U":600859611803,"u":600859613122,"pu":600859611095,"b":[["7.6000","3995"],["7.6030","821"],["7.6050","1953"],["7.6060","613"],["7.6070","349"]],"a":[["7.6160","2007"],["7.6180","1308"]]}}
1626992742.289814: {"stream":"sushiusdt@depth@100ms","data":{"e":"depthUpdate","E":1626992741816,"T":1626992741802,"s":"SUSHIUSDT","U":600859613954,"u":600859615762,"pu":600859613122,"b":[["7.6010","2353"],["7.6040","460"],["7.6060","203"],["7.6070","255"],["7.6080","209"]],"a":[["7.6170","2060"],["7.6200","1464"],["7.6220","3284"],["7.6230","4205"]]}}
1626992742.289852: {"stream":"akrousdt@depth@100ms","data":{"e":"depthUpdate","E":1626992741880,"T":1626992741846,"s":"AKROUSDT","U":600859615248,"u":600859616677,"pu":600859611654,"b":[["0.01724","678101"],["0.01725","919534"]],"a":[["0.01737","426900"],["0.01741","291748"],["0.01742","206748"]]}}
1626992742.289886: {"stream":"ctkusdt@depth@100ms","data":{"e":"depthUpdate","E":1626992741880,"T":1626992741836,"s":"CTKUSDT","U":600859615246,"u":600859616469,"pu":600859610151,"b":[["1.00600","14217"]],"a":[["1.01300","17472"],["1.01500","20835"]]}}
1626992742.289897: {"stream":"sushiusdt@depth@100ms","data":{"e":"depthUpdate","E":1626992741949,"T":1626992741890,"s":"SUSHIUSDT","U":600859616612,"u":600859617450,"pu":600859615762,"b":[["3.8060","0"]],"a":[["7.6160","3533"],["7.6170","534"],["7.6240","3014"]]}}
1626992742.289922: {"stream":"ctkusdt@depth@100ms","data":{"e":"depthUpdate","E":1626992741983,"T":1626992741972,"s":"CTKUSDT","U":600859617271,"u":600859618836,"pu":600859616469,"b":[["1.00600","9269"],["1.00900","14455"]],"a":[["1.01200","11149"],["1.01500","15887"]]}}
1626992742.289949: {"stream":"akrousdt@depth@100ms","data":{"e":"depthUpdate","E":1626992741991,"T":1626992741973,"s":"AKROUSDT","U":600859617409,"u":600859618858,"pu":600859616677,"b":[["0.01728","772928"],["0.01729","742325"],["0.01730","153887"]],"a":[]}}
1626992742.289977: {"stream":"keepusdt@depth@100ms","data":{"e":"depthUpdate","E":1626992742029,"T":1626992742012,"s":"KEEPUSDT","U":600859618057,"u":600859619434,"pu":600859607807,"b":[["0.2350","26711"]],"a":[["0.2465","812"]]}}
1626992742.289999: {"stream":"sushiusdt@depth@100ms","data":{"e":"depthUpdate","E":1626992742066,"T":1626992742050,"s":"SUSHIUSDT","U":600859618572,"u":600859620017,"pu":600859617450,"b":[["7.5760","2478"],["7.6080","230"]],"a":[["7.6160","3209"]]}}
1626992742.290022: {"stream":"akrousdt@depth@100ms","data":{"e":"depthUpdate","E":1626992742092,"T":1626992742071,"s":"AKROUSDT","U":600859619076,"u":600859620192,"pu":600859618858,"b":[["0.01724","695656"],["0.01725","901990"],["0.01727","1133143"]],"a":[]}}
1626992742.290046: {"stream":"akrousdt@kline_1m","data":{"e":"kline","E":1626992742139,"s":"AKROUSDT","k":{"t":1626992700000,"T":1626992759999,"s":"AKROUSDT","i":"1m","f":27931328,"L":27931348,"o":"0.01731","c":"0.01731","h":"0.01733","l":"0.01731","v":"156058","n":21,"x":false,"q":"2702.20770","V":"68508","Q":"1186.71720","B":"0"}}}
1626992742.290069: {"stream":"akrousdt@bookTicker","data":{"e":"bookTicker","u":600859621226,"s":"AKROUSDT","b":"0.01731","B":"57306","a":"0.01732","A":"72524","T":1626992742134,"E":1626992742140}}
1626992742.2900841: {"stream":"sushiusdt@depth@100ms","data":{"e":"depthUpdate","E":1626992742235,"T":1626992742205,"s":"SUSHIUSDT","U":600859621087,"u":600859622865,"pu":600859620017,"b":[["7.6040","129"],["7.6080","237"]],"a":[["7.6490","12589"],["7.6890","2925"]]}}
1626992742.290396: {"stream":"akrousdt@depth@100ms","data":{"e":"depthUpdate","E":1626992742240,"T":1626992742197,"s":"AKROUSDT","U":600859621222,"u":600859622706,"pu":600859620192,"b":[["0.01727","1271644"],["0.01728","633891"],["0.01731","57306"]],"a":[["0.01731","0"],["0.01736","943461"],["0.01737","357242"],["0.01738","1028223"]]}}
1626992742.334986: {"stream":"akrousdt@aggTrade","data":{"e":"aggTrade","E":1626992742291,"a":14888302,"s":"AKROUSDT","p":"0.01731","q":"312","f":27931348,"l":27931348,"T":1626992742134,"m":true}}
1626992742.384615: {"stream":"akrousdt@depth@100ms","data":{"e":"depthUpdate","E":1626992742340,"T":1626992742292,"s":"AKROUSDT","U":600859623427,"u":600859624403,"pu":600859622706,"b":[["0.01727","1235427"],["0.01728","670087"]],"a":[["0.01754","176629"]]}}
1626992742.3879738: {"stream":"ctkusdt@depth@100ms","data":{"e":"depthUpdate","E":1626992742342,"T":1626992742237,"s":"CTKUSDT","U":600859623471,"u":600859623471,"pu":600859618836,"b":[["0.98100","11355"]],"a":[]}}
1626992742.396429: {"stream":"akrousdt@bookTicker","data":{"e":"bookTicker","u":600859625483,"s":"AKROUSDT","b":"0.01731","B":"57306","a":"0.01732","A":"74607","T":1626992742347,"E":1626992742351}}
1626992742.400584: {"stream":"sushiusdt@depth@100ms","data":{"e":"depthUpdate","E":1626992742356,"T":1626992742273,"s":"SUSHIUSDT","U":600859623709,"u":600859624129,"pu":600859622865,"b":[],"a":[["7.6150","1502"],["7.6180","1632"]]}}
1626992742.4931378: {"stream":"akrousdt@depth@100ms","data":{"e":"depthUpdate","E":1626992742448,"T":1626992742409,"s":"AKROUSDT","U":600859625421,"u":600859626824,"pu":600859624403,"b":[["0.01727","1271644"],["0.01728","633891"]],"a":[["0.01732","74607"],["0.01736","943446"],["0.01737","357242"],["0.01739","1111678"],["0.01768","54694"]]}}
1626992742.51103: {"stream":"keepusdt@depth@100ms","data":{"e":"depthUpdate","E":1626992742465,"T":1626992742450,"s":"KEEPUSDT","U":600859625705,"u":600859627652,"pu":600859619434,"b":[["0.2398","181"]],"a":[["0.2465","812"]]}}
1626992742.524482: {"stream":"sushiusdt@depth@100ms","data":{"e":"depthUpdate","E":1626992742480,"T":1626992742469,"s":"SUSHIUSDT","U":600859626100,"u":600859628043,"pu":600859624129,"b":[["3.8060","26"],["7.5420","227"],["7.5430","3399"],["7.5600","3479"],["7.5610","1386"],["7.5760","2009"],["7.5770","1335"],["7.6080","237"]],"a":[["7.6430","2761"],["7.6450","1324"],["7.6490","12557"],["7.6590","633"],["7.6770","3706"],["7.6790","540"]]}}
1626992742.610713: {"stream":"akrousdt@depth@100ms","data":{"e":"depthUpdate","E":1626992742567,"T":1626992742462,"s":"AKROUSDT","U":600859627889,"u":600859627889,"pu":600859626824,"b":[],"a":[["0.01739","903107"]]}}
1626992742.720344: {"stream":"akrousdt@depth@100ms","data":{"e":"depthUpdate","E":1626992742674,"T":1626992742583,"s":"AKROUSDT","U":600859629894,"u":600859630152,"pu":600859627889,"b":[],"a":[["0.01739","1111844"],["0.01770","148789"]]}}
1626992742.740339: {"stream":"sushiusdt@depth@100ms","data":{"e":"depthUpdate","E":1626992742696,"T":1626992742682,"s":"SUSHIUSDT","U":600859630298,"u":600859632018,"pu":600859628043,"b":[["7.5600","478"],["7.5840","2164"],["7.5930","3155"],["7.5940","585"],["7.5960","4292"],["7.6030","801"]],"a":[["7.6200","1601"],["7.6220","3147"],["7.6240","2994"],["7.6440","4418"],["7.6500","590"],["7.6640","2698"]]}}
1626992742.740546: {"stream":"keepusdt@bookTicker","data":{"e":"bookTicker","u":600859632247,"s":"KEEPUSDT","b":"0.2459","B":"1490","a":"0.2464","A":"317","T":1626992742693,"E":1626992742697}}
1626992742.7408798: {"stream":"sushiusdt@bookTicker","data":{"e":"bookTicker","u":600859632276,"s":"SUSHIUSDT","b":"7.6110","B":"7","a":"7.6120","A":"297","T":1626992742695,"E":1626992742699}}
1626992742.750103: {"stream":"keepusdt@bookTicker","data":{"e":"bookTicker","u":600859632369,"s":"KEEPUSDT","b":"0.2463","B":"3155","a":"0.2464","A":"317","T":1626992742700,"E":1626992742707}}
1626992742.760793: {"stream":"ctkusdt@kline_1m","data":{"e":"kline","E":1626992742718,"s":"CTKUSDT","k":{"t":1626992700000,"T":1626992759999,"s":"CTKUSDT","i":"1m","f":23961275,"L":23961323,"o":"1.01000","c":"1.01100","h":"1.01100","l":"1.01000","v":"3927","n":49,"x":false,"q":"3968.00900","V":"1739","Q":"1758.12900","B":"0"}}}
1626992742.762948: {"stream":"ctkusdt@bookTicker","data":{"e":"bookTicker","u":600859632653,"s":"CTKUSDT","b":"1.01000","B":"85782","a":"1.01100","A":"6473","T":1626992742715,"E":1626992742718}}
1626992742.781861: {"stream":"ctkusdt@depth@100ms","data":{"e":"depthUpdate","E":1626992742737,"T":1626992742715,"s":"CTKUSDT","U":600859631050,"u":600859632653,"pu":600859623471,"b":[["1.00300","5766"],["1.00600","14217"],["1.01400","0"]],"a":[["1.01100","6473"],["1.01500","20835"]]}}
1626992742.805907: {"stream":"sushiusdt@bookTicker","data":{"e":"bookTicker","u":600859633461,"s":"SUSHIUSDT","b":"7.6110","B":"23","a":"7.6120","A":"297","T":1626992742755,"E":1626992742761}}
1626992742.841134: {"stream":"keepusdt@depth@100ms","data":{"e":"depthUpdate","E":1626992742797,"T":1626992742771,"s":"KEEPUSDT","U":600859632247,"u":600859633700,"pu":600859627652,"b":[["0.2448","8461"],["0.2449","23953"],["0.2456","21760"],["0.2457","11820"],["0.2463","3155"]],"a":[["0.2465","0"],["0.2466","1248"]]}}
1626992742.8441541: {"stream":"sushiusdt@depth@100ms","data":{"e":"depthUpdate","E":1626992742799,"T":1626992742780,"s":"SUSHIUSDT","U":600859632276,"u":600859633823,"pu":600859632018,"b":[["7.6010","2283"],["7.6020","1385"],["7.6080","209"],["7.6090","28"],["7.6110","23"]],"a":[["7.6210","2138"],["7.6220","3277"],["7.6490","12589"],["7.6750","902"]]}}
1626992742.899214: {"stream":"akrousdt@depth@100ms","data":{"e":"depthUpdate","E":1626992742834,"T":1626992742771,"s":"AKROUSDT","U":600859632937,"u":600859633696,"pu":600859630152,"b":[],"a":[["0.01738","1017279"],["0.01830","1108967"]]}}
1626992742.902057: {"stream":"ctkusdt@depth@100ms","data":{"e":"depthUpdate","E":1626992742839,"T":1626992742791,"s":"CTKUSDT","U":600859633007,"u":600859634010,"pu":600859632653,"b":[["1.00600","14453"],["1.00700","10765"]],"a":[["1.01500","20835"]]}}
1626992742.914284: {"stream":"ctkusdt@aggTrade","data":{"e":"aggTrade","E":1626992742869,"a":16599293,"s":"CTKUSDT","p":"1.01100","q":"10","f":23961323,"l":23961323,"T":1626992742715,"m":false}}
1626992742.924844: {"stream":"ctkusdt@bookTicker","data":{"e":"bookTicker","u":600859635329,"s":"CTKUSDT","b":"1.01000","B":"85782","a":"1.01100","A":"6695","T":1626992742874,"E":1626992742879}}
1626992742.968535: {"stream":"keepusdt@depth@100ms","data":{"e":"depthUpdate","E":1626992742924,"T":1626992742817,"s":"KEEPUSDT","U":600859634370,"u":600859634370,"pu":600859633700,"b":[["0.2443","5160"]],"a":[]}}
1626992742.9686668: {"stream":"sushiusdt@depth@100ms","data":{"e":"depthUpdate","E":1626992742924,"T":1626992742862,"s":"SUSHIUSDT","U":600859634374,"u":600859635105,"pu":600859633823,"b":[["7.6060","335"]],"a":[["7.6640","2542"]]}}
1626992742.987565: {"stream":"ctkusdt@depth@100ms","data":{"e":"depthUpdate","E":1626992742944,"T":1626992742930,"s":"CTKUSDT","U":600859634747,"u":600859636212,"pu":600859634010,"b":[["1.00600","9505"]],"a":[["1.01100","6695"],["1.01500","20835"]]}}
1626992743.07383: {"stream":"akrousdt@depth@100ms","data":{"e":"depthUpdate","E":1626992743029,"T":1626992742925,"s":"AKROUSDT","U":600859636147,"u":600859636147,"pu":600859633696,"b":[],"a":[["0.01823","755935"]]}}
1626992743.0857012: {"stream":"sushiusdt@depth@100ms","data":{"e":"depthUpdate","E":1626992743039,"T":1626992742946,"s":"SUSHIUSDT","U":600859636243,"u":600859636440,"pu":600859635105,"b":[["7.5600","3479"],["7.5840","3665"],["7.6000","2391"],["7.6010","3850"],["7.6030","821"]],"a":[["7.6240","3014"],["7.6440","5887"],["7.6500","3559"]]}}
1626992743.120369: {"stream":"ctkusdt@depth@100ms","data":{"e":"depthUpdate","E":1626992743074,"T":1626992743028,"s":"CTKUSDT","U":600859636711,"u":600859637761,"pu":600859636212,"b":[["1.00600","9505"]],"a":[["1.01500","20835"]]}}
1626992743.176419: {"stream":"akrousdt@depth@100ms","data":{"e":"depthUpdate","E":1626992743131,"T":1626992743026,"s":"AKROUSDT","U":600859637750,"u":600859637750,"pu":600859636147,"b":[["0.01685","457106"]],"a":[]}}
1626992743.192523: {"stream":"sushiusdt@depth@100ms","data":{"e":"depthUpdate","E":1626992743149,"T":1626992743116,"s":"SUSHIUSDT","U":600859638056,"u":600859638886,"pu":600859636440,"b":[["7.6000","3958"],["7.6010","2283"],["7.6020","1061"],["7.6030","1145"],["7.6080","202"]],"a":[["7.6220","4683"],["7.6230","2846"]]}}
1626992743.231433: {"stream":"ctkusdt@depth@100ms","data":{"e":"depthUpdate","E":1626992743185,"T":1626992743177,"s":"CTKUSDT","U":600859638490,"u":600859640198,"pu":600859637761,"b":[["1.00900","14528"]],"a":[["1.01500","15887"]]}}
1626992743.294283: {"stream":"sushiusdt@depth@100ms","data":{"e":"depthUpdate","E":1626992743250,"T":1626992743231,"s":"SUSHIUSDT","U":600859639496,"u":600859641199,"pu":600859638886,"b":[["7.6000","2391"],["7.6010","3820"],["7.6020","1061"],["7.6040","457"],["7.6080","209"]],"a":[["7.6490","12557"]]}}
1626992743.337534: {"stream":"akrousdt@depth@100ms","data":{"e":"depthUpdate","E":1626992743291,"T":1626992743190,"s":"AKROUSDT","U":600859640391,"u":600859640425,"pu":600859637750,"b":[["0.01715","613323"]],"a":[]}}
1626992743.402935: {"stream":"sushiusdt@depth@100ms","data":{"e":"depthUpdate","E":1626992743357,"T":1626992743342,"s":"SUSHIUSDT","U":600859641542,"u":600859643454,"pu":600859641199,"b":[["7.6010","3820"],["7.6020","1339"],["7.6040","129"]],"a":[["7.6180","1435"],["7.6200","1851"],["7.6240","2826"],["7.6620","593"]]}}
1626992743.441356: {"stream":"keepusdt@depth@100ms","data":{"e":"depthUpdate","E":1626992743397,"T":1626992743385,"s":"KEEPUSDT","U":600859642305,"u":600859644386,"pu":600859634370,"b":[["0.2399","19599"]],"a":[["0.2466","1248"]]}}
1626992743.480968: {"stream":"akrousdt@depth@100ms","data":{"e":"depthUpdate","E":1626992743437,"T":1626992743422,"s":"AKROUSDT","U":600859643146,"u":600859645184,"pu":600859640425,"b":[["0.01726","457314"],["0.01730","106887"]],"a":[]}}
1626992743.542628: {"stream":"sushiusdt@depth@100ms","data":{"e":"depthUpdate","E":1626992743499,"T":1626992743480,"s":"SUSHIUSDT","U":600859644640,"u":600859646316,"pu":600859643454,"b":[["7.5980","1433"],["7.5990","655"],["7.6000","2391"],["7.6010","3860"],["7.6080","209"]],"a":[["7.6130","665"],["7.6150","1014"]]}}
1626992743.5785449: {"stream":"keepusdt@depth@100ms","data":{"e":"depthUpdate","E":1626992743532,"T":1626992743425,"s":"KEEPUSDT","U":600859645270,"u":600859645270,"pu":600859644386,"b":[],"a":[["0.2589","0"]]}}
1626992743.6379762: {"stream":"akrousdt@depth@100ms","data":{"e":"depthUpdate","E":1626992743595,"T":1626992743489,"s":"AKROUSDT","U":600859646460,"u":600859646460,"pu":600859645184,"b":[["0.01726","516729"]],"a":[]}}
1626992743.6685739: {"stream":"sushiusdt@depth@100ms","data":{"e":"depthUpdate","E":1626992743622,"T":1626992743530,"s":"SUSHIUSDT","U":600859646885,"u":600859647094,"pu":600859646316,"b":[["7.5750","3589"],["7.6000","3928"],["7.6010","2323"]],"a":[["7.6470","2431"]]}}
1626992743.722871: {"stream":"keepusdt@depth@100ms","data":{"e":"depthUpdate","E":1626992743678,"T":1626992743662,"s":"KEEPUSDT","U":600859647746,"u":600859649155,"pu":600859645270,"b":[["0.2396","36727"],["0.2399","10025"]],"a":[["0.2466","1248"],["0.2529","18563"]]}}
1626992743.829213: {"stream":"akrousdt@depth@100ms","data":{"e":"depthUpdate","E":1626992743784,"T":1626992743679,"s":"AKROUSDT","U":600859649496,"u":600859649496,"pu":600859646460,"b":[],"a":[["0.01737","368191"]]}}
1626992743.860758: {"stream":"sushiusdt@depth@100ms","data":{"e":"depthUpdate","E":1626992743816,"T":1626992743804,"s":"SUSHIUSDT","U":600859650094,"u":600859651899,"pu":600859647094,"b":[["7.5990","675"],["7.6000","3943"],["7.6010","2233"],["7.6060","257"],["7.6080","209"]],"a":[["7.6200","1926"],["7.6240","3014"],["7.6490","12589"],["8.0990","542"]]}}
1626992743.927226: {"stream":"ctkusdt@depth@100ms","data":{"e":"depthUpdate","E":1626992743883,"T":1626992743835,"s":"CTKUSDT","U":600859651458,"u":600859652389,"pu":600859640198,"b":[["1.00600","14453"],["1.00900","14455"]],"a":[["1.01500","20835"]]}}
1626992743.988127: {"stream":"keepusdt@depth@100ms","data":{"e":"depthUpdate","E":1626992743944,"T":1626992743919,"s":"KEEPUSDT","U":600859652443,"u":600859653721,"pu":600859649155,"b":[["0.2396","46313"]],"a":[["0.2466","1248"],["0.2525","16399"],["0.2530","5210"]]}}
1626992744.015452: {"stream":"akrousdt@depth@100ms","data":{"e":"depthUpdate","E":1626992743971,"T":1626992743897,"s":"AKROUSDT","U":600859652856,"u":600859653363,"pu":600859649496,"b":[],"a":[["0.01738","1053267"],["0.01739","1075877"]]}}
1626992744.0205288: {"stream":"sushiusdt@depth@100ms","data":{"e":"depthUpdate","E":1626992743975,"T":1626992743871,"s":"SUSHIUSDT","U":600859652903,"u":600859652903,"pu":600859651899,"b":[],"a":[["7.6200","2001"]]}}
1626992744.035795: {"stream":"ctkusdt@depth@100ms","data":{"e":"depthUpdate","E":1626992743989,"T":1626992743942,"s":"CTKUSDT","U":600859653147,"u":600859654093,"pu":600859652389,"b":[["1.00600","14453"]],"a":[["1.01500","20835"]]}}
1626992744.128565: {"stream":"akrousdt@depth@100ms","data":{"e":"depthUpdate","E":1626992744082,"T":1626992744072,"s":"AKROUSDT","U":600859654527,"u":600859656018,"pu":600859653363,"b":[],"a":[["0.01735","403895"],["0.01737","357242"],["0.01738","1017279"],["0.01739","1111844"],["0.01775","600186"]]}}
1626992744.139202: {"stream":"ctkusdt@depth@100ms","data":{"e":"depthUpdate","E":1626992744094,"T":1626992744049,"s":"CTKUSDT","U":600859654671,"u":600859655590,"pu":600859654093,"b":[["1.00600","14453"]],"a":[["1.01500","20835"]]}}
1626992744.15638: {"stream":"sushiusdt@kline_1m","data":{"e":"kline","E":1626992744112,"s":"SUSHIUSDT","k":{"t":1626992700000,"T":1626992759999,"s":"SUSHIUSDT","i":"1m","f":126902874,"L":126902924,"o":"7.6080","c":"7.6120","h":"7.6120","l":"7.6070","v":"1458","n":51,"x":false,"q":"11096.6410","V":"715","Q":"5441.3360","B":"0"}}}
1626992744.1564999: {"stream":"sushiusdt@bookTicker","data":{"e":"bookTicker","u":600859656430,"s":"SUSHIUSDT","b":"7.6110","B":"23","a":"7.6120","A":"127","T":1626992744108,"E":1626992744111}}
1626992744.1569579: {"stream":"ctkusdt@kline_1m","data":{"e":"kline","E":1626992744114,"s":"CTKUSDT","k":{"t":1626992700000,"T":1626992759999,"s":"CTKUSDT","i":"1m","f":23961275,"L":23961324,"o":"1.01000","c":"1.01100","h":"1.01100","l":"1.01000","v":"3937","n":50,"x":false,"q":"3978.11900","V":"1749","Q":"1768.23900","B":"0"}}}
1626992744.157011: {"stream":"ctkusdt@bookTicker","data":{"e":"bookTicker","u":600859656448,"s":"CTKUSDT","b":"1.01000","B":"85782","a":"1.01100","A":"6685","T":1626992744109,"E":1626992744114}}
1626992744.157608: {"stream":"sushiusdt@bookTicker","data":{"e":"bookTicker","u":600859656456,"s":"SUSHIUSDT","b":"7.6110","B":"23","a":"7.6120","A":"77","T":1626992744109,"E":1626992744114}}
1626992744.157655: {"stream":"sushiusdt@bookTicker","data":{"e":"bookTicker","u":600859656469,"s":"SUSHIUSDT","b":"7.6110","B":"23","a":"7.6130","A":"28","T":1626992744109,"E":1626992744114}}
1626992744.16051: {"stream":"keepusdt@depth@100ms","data":{"e":"depthUpdate","E":1626992744116,"T":1626992744055,"s":"KEEPUSDT","U":600859654994,"u":600859655724,"pu":600859653721,"b":[["0.2456","17662"],["0.2457","15918"]],"a":[["0.2466","436"]]}}
1626992744.18734: {"stream":"sushiusdt@depth@100ms","data":{"e":"depthUpdate","E":1626992744142,"T":1626992744137,"s":"SUSHIUSDT","U":600859655347,"u":600859656756,"pu":600859652903,"b":[["7.5480","566"],["7.5860","543"],["7.5930","2957"],["7.5950","1060"],["7.5970","1895"],["7.5990","655"],["7.6000","2391"],["7.6010","3860"],["7.6030","1017"],["7.6060","385"],["7.6070","332"],["7.6080","202"],["7.6090","73"],["7.6120","0"]],"a":[["7.6120","0"],["7.6130","28"],["7.6140","404"],["7.6150","582"],["7.6160","3646"],["7.6170","484"],["7.6180","1286"],["7.6190","1044"],["7.6200","1949"],["7.6210","2005"],["7.6220","3689"],["7.6230","2749"],["7.6250","28"],["7.6260","2713"],["7.6280","3552"],["7.6330","1088"]]}}
1626992744.20093: {"stream":"sushiusdt@bookTicker","data":{"e":"bookTicker","u":600859656948,"s":"SUSHIUSDT","b":"7.6110","B":"23","a":"7.6140","A":"404","T":1626992744149,"E":1626992744153}}
1626992744.2216861: {"stream":"sushiusdt@bookTicker","data":{"e":"bookTicker","u":600859657077,"s":"SUSHIUSDT","b":"7.6110","B":"23","a":"7.6140","A":"424","T":1626992744161,"E":1626992744167}}
1626992744.221756: {"stream":"sushiusdt@bookTicker","data":{"e":"bookTicker","u":600859657124,"s":"SUSHIUSDT","b":"7.6110","B":"23","a":"7.6140","A":"455","T":1626992744162,"E":1626992744169}}
1626992744.221784: {"stream":"sushiusdt@bookTicker","data":{"e":"bookTicker","u":600859657131,"s":"SUSHIUSDT","b":"7.6110","B":"23","a":"7.6140","A":"485","T":1626992744162,"E":1626992744169}}
1626992744.221807: {"stream":"sushiusdt@bookTicker","data":{"e":"bookTicker","u":600859657214,"s":"SUSHIUSDT","b":"7.6110","B":"23","a":"7.6140","A":"285","T":1626992744164,"E":1626992744169}}
1626992744.2249758: {"stream":"sushiusdt@bookTicker","data":{"e":"bookTicker","u":600859657495,"s":"SUSHIUSDT","b":"7.6110","B":"19","a":"7.6140","A":"285","T":1626992744174,"E":1626992744180}}
1626992744.225044: {"stream":"sushiusdt@bookTicker","data":{"e":"bookTicker","u":600859657506,"s":"SUSHIUSDT","b":"7.6110","B":"19","a":"7.6140","A":"265","T":1626992744175,"E":1626992744180}}
1626992744.227721: {"stream":"sushiusdt@bookTicker","data":{"e":"bookTicker","u":600859657526,"s":"SUSHIUSDT","b":"7.6110","B":"19","a":"7.6140","A":"235","T":1626992744176,"E":1626992744182}}
1626992744.231988: {"stream":"sushiusdt@bookTicker","data":{"e":"bookTicker","u":600859657609,"s":"SUSHIUSDT","b":"7.6120","B":"4","a":"7.6140","A":"235","T":1626992744181,"E":1626992744186}}
1626992744.242777: {"stream":"ctkusdt@depth@100ms","data":{"e":"depthUpdate","E":1626992744198,"T":1626992744182,"s":"CTKUSDT","U":600859656276,"u":600859657630,"pu":600859655590,"b":[["1.00600","9269"],["1.00700","11003"],["1.00900","14528"],["1.01400","0"]],"a":[["1.01100","6685"],["1.01500","20835"]]}}
1626992744.252334: {"stream":"sushiusdt@bookTicker","data":{"e":"bookTicker","u":600859657964,"s":"SUSHIUSDT","b":"7.6120","B":"4","a":"7.6140","A":"163","T":1626992744201,"E":1626992744207}}
1626992744.2675462: {"stream":"sushiusdt@bookTicker","data":{"e":"bookTicker","u":600859658242,"s":"SUSHIUSDT","b":"7.6120","B":"4","a":"7.6140","A":"31","T":1626992744215,"E":1626992744221}}
1626992744.26762: {"stream":"sushiusdt@bookTicker","data":{"e":"bookTicker","u":600859658255,"s":"SUSHIUSDT","b":"7.6120","B":"5","a":"7.6140","A":"31","T":1626992744216,"E":1626992744223}}
1626992744.277267: {"stream":"keepusdt@depth@100ms","data":{"e":"depthUpdate","E":1626992744232,"T":1626992744127,"s":"KEEPUSDT","U":600859656608,"u":600859656608,"pu":600859655724,"b":[],"a":[["0.2466","1248"]]}}
1626992744.291293: {"stream":"sushiusdt@depth@100ms","data":{"e":"depthUpdate","E":1626992744244,"T":1626992744239,"s":"SUSHIUSDT","U":600859656759,"u":600859658576,"pu":600859656756,"b":[["7.5610","1326"],["7.5690","1952"],["7.5800","4012"],["7.5820","1066"],["7.5850","1810"],["7.5860","513"],["7.5890","1075"],["7.5910","4320"],["7.5920","1603"],["7.5930","3857"],["7.5940","609"],["7.5950","1650"],["7.5960","4318"],["7.5980","1183"],["7.5990","562"],["7.6000","1584"],["7.6010","3670"],["7.6020","1410"],["7.6030","1337"],["7.6040","4"],["7.6050","445"],["7.6060","1282"],["7.6070","347"],["7.6080","130"],["7.6090","45"],["7.6100","193"],["7.6110","95"],["7.6120","5"]],"a":[["7.6130","0"],["7.6140","31"],["7.6150","984"],["7.6160","980"],["7.6170","1995"],["7.6180","1871"],["7.6190","1410"],["7.6200","2235"],["7.6210","1938"],["7.6220","3048"],["7.6230","3088"],["7.6240","2332"],["7.6250","974"],["7.6260","2397"],["7.6300","2528"],["7.6310","3569"],["7.6350","2514"],["7.6360","1160"],["7.6370","912"],["7.6380","1298"],["7.6390","3362"],["7.6510","580"],["9.3480","9"]]}}
1626992744.3115578: {"stream":"sushiusdt@aggTrade","data":{"e":"aggTrade","E":1626992744262,"a":87353230,"s":"SUSHIUSDT","p":"7.6120","q":"297","f":126902924,"l":126902927,"T":1626992744108,"m":false}}
1626992744.311664: {"stream":"ctkusdt@aggTrade","data":{"e":"aggTrade","E":1626992744265,"a":16599294,"s":"CTKUSDT","p":"1.01100","q":"10","f":23961324,"l":23961324,"T":1626992744109,"m":false}}
1626992744.370202: {"stream":"ctkusdt@depth@100ms","data":{"e":"depthUpdate","E":1626992744323,"T":1626992744277,"s":"CTKUSDT","U":600859658261,"u":600859659099,"pu":600859657630,"b":[["1.00600","9269"]],"a":[["1.01500","20835"]]}}
1626992744.395426: {"stream":"sushiusdt@depth@100ms","data":{"e":"depthUpdate","E":1626992744349,"T":1626992744344,"s":"SUSHIUSDT","U":600859658661,"u":600859659938,"pu":600859658576,"b":[["7.5790","1000"],["7.5830","4474"],["7.5850","2010"],["7.5860","338"],["7.5880","1481"],["7.5910","4387"],["7.5970","1962"],["7.6000","603"],["7.6010","2969"],["7.6020","2131"],["7.6030","1267"],["7.6040","593"],["7.6060","1154"],["7.6080","849"],["7.6090","297"]],"a":[["7.6150","589"],["7.6160","797"],["7.6170","2275"],["7.6180","1860"],["7.6200","2186"],["7.6220","2053"],["7.6230","4136"],["7.6240","2372"],["7.6260","1414"],["7.6300","3511"],["7.6310","3394"],["7.6330","1263"],["7.6400","845"],["7.7100","1470"]]}}
1626992744.473613: {"stream":"ctkusdt@depth@100ms","data":{"e":"depthUpdate","E":1626992744429,"T":1626992744381,"s":"CTKUSDT","U":600859659675,"u":600859660379,"pu":600859659099,"b":[["1.00600","9269"]],"a":[["1.01500","15887"]]}}
1626992744.500339: {"stream":"sushiusdt@depth@100ms","data":{"e":"depthUpdate","E":1626992744453,"T":1626992744443,"s":"SUSHIUSDT","U":600859659973,"u":600859661092,"pu":600859659938,"b":[["7.5300","2353"],["7.5400","861"],["7.5960","4098"],["7.5990","1543"],["7.6000","791"],["7.6070","270"],["7.6080","842"],["7.6090","304"]],"a":[["7.6160","777"],["7.6170","2143"],["7.6180","1536"],["7.6190","1078"],["7.6260","1347"],["7.6270","736"],["7.6280","2659"],["7.6290","2756"],["7.6300","4128"],["7.6310","2777"],["7.6320","837"],["7.6350","2377"]]}}
1626992744.6123111: {"stream":"sushiusdt@depth@100ms","data":{"e":"depthUpdate","E":1626992744567,"T":1626992744560,"s":"SUSHIUSDT","U":600859661438,"u":600859662907,"pu":600859661092,"b":[["7.5340","10009"],["7.5760","3509"],["7.6000","765"],["7.6020","2157"],["7.6030","1197"],["7.6040","663"],["7.6090","298"]],"a":[["7.6190","1402"],["7.6230","4006"],["7.6240","2502"],["7.6300","4471"],["7.6370","1049"],["7.6490","14089"],["7.6770","2403"]]}}
1626992744.6336892: {"stream":"sushiusdt@bookTicker","data":{"e":"bookTicker","u":600859663188,"s":"SUSHIUSDT","b":"7.6120","B":"7","a":"7.6140","A":"31","T":1626992744583,"E":1626992744589}}
1626992744.727846: {"stream":"sushiusdt@depth@100ms","data":{"e":"depthUpdate","E":1626992744682,"T":1626992744664,"s":"SUSHIUSDT","U":600859663096,"u":600859664422,"pu":600859662907,"b":[["7.1760","12"],["7.5900","2019"],["7.6090","298"],["7.6110","93"],["7.6120","7"]],"a":[["7.6150","617"],["7.6160","799"],["7.6170","2351"],["7.6180","1521"],["7.6190","777"],["7.6210","2254"],["7.6220","1737"],["7.6240","2818"],["7.6270","2242"],["7.7920","598"]]}}
1626992744.7335: {"stream":"sushiusdt@bookTicker","data":{"e":"bookTicker","u":600859664729,"s":"SUSHIUSDT","b":"7.6120","B":"13","a":"7.6140","A":"31","T":1626992744682,"E":1626992744688}}
1626992744.753501: {"stream":"sushiusdt@bookTicker","data":{"e":"bookTicker","u":600859665007,"s":"SUSHIUSDT","b":"7.6120","B":"14","a":"7.6140","A":"31","T":1626992744702,"E":1626992744708}}
1626992744.8296: {"stream":"sushiusdt@depth@100ms","data":{"e":"depthUpdate","E":1626992744785,"T":1626992744777,"s":"SUSHIUSDT","U":600859664715,"u":600859665989,"pu":600859664422,"b":[["7.5430","4725"],["7.6010","2949"],["7.6050","465"],["7.6120","14"]],"a":[["7.6170","2468"],["7.6240","2798"],["7.6250","994"],["7.6430","3045"],["7.6530","758"]]}}
1626992744.917224: {"stream":"akrousdt@depth@100ms","data":{"e":"depthUpdate","E":1626992744872,"T":1626992744867,"s":"AKROUSDT","U":600859665843,"u":600859667598,"pu":600859656018,"b":[["0.01724","678101"],["0.01725","919534"],["0.01727","1235427"],["0.01728","633891"]],"a":[["0.01735","463895"]]}}
1626992744.9325929: {"stream":"sushiusdt@depth@100ms","data":{"e":"depthUpdate","E":1626992744887,"T":1626992744862,"s":"SUSHIUSDT","U":600859666059,"u":600859667487,"pu":600859665989,"b":[["6.8830","8"],["6.8940","201"],["7.5720","4056"],["7.6010","3042"],["7.6020","1985"]],"a":[["7.6170","2518"],["7.6200","2136"],["7.6260","1487"],["7.6830","1365"],["8.3200","49"],["8.3310","165"]]}}
1626992745.033658: {"stream":"akrousdt@depth@100ms","data":{"e":"depthUpdate","E":1626992744988,"T":1626992744882,"s":"AKROUSDT","U":600859667898,"u":600859667898,"pu":600859667598,"b":[["0.01727","1271644"]],"a":[]}}
1626992745.043317: {"stream":"sushiusdt@depth@100ms","data":{"e":"depthUpdate","E":1626992744997,"T":1626992744974,"s":"SUSHIUSDT","U":600859668126,"u":600859669677,"pu":600859667487,"b":[["7.5430","4256"],["7.5450","1849"],["7.5770","866"],["7.5790","1469"],["7.5910","4357"],["7.5920","1633"],["7.6000","963"],["7.6060","1122"],["7.6070","238"],["7.6080","906"],["7.6090","298"],["7.6110","77"]],"a":[["7.6160","863"],["7.6170","2550"],["7.6450","855"],["7.6470","2900"],["7.6790","71"],["7.6810","3110"]]}}
1626992745.079113: {"stream":"keepusdt@depth@100ms","data":{"e":"depthUpdate","E":1626992745031,"T":1626992745016,"s":"KEEPUSDT","U":600859668902,"u":600859670352,"pu":600859656608,"b":[],"a":[["0.2466","1248"],["0.2529","0"],["0.2544","9446"]]}}
1626992745.137321: {"stream":"akrousdt@bookTicker","data":{"e":"bookTicker","u":600859671625,"s":"AKROUSDT","b":"0.01731","B":"53451","a":"0.01732","A":"74607","T":1626992745085,"E":1626992745091}}
1626992745.152098: {"stream":"akrousdt@bookTicker","data":{"e":"bookTicker","u":600859671739,"s":"AKROUSDT","b":"0.01731","B":"451","a":"0.01732","A":"74607","T":1626992745101,"E":1626992745107}}
1626992745.184099: {"stream":"sushiusdt@depth@100ms","data":{"e":"depthUpdate","E":1626992745139,"T":1626992745114,"s":"SUSHIUSDT","U":600859670685,"u":600859671852,"pu":600859669677,"b":[["7.5800","4032"]],"a":[["7.6230","3717"],["7.6510","561"],["8.3250","195"]]}}
1626992745.191552: {"stream":"akrousdt@bookTicker","data":{"e":"bookTicker","u":600859672217,"s":"AKROUSDT","b":"0.01731","B":"8108","a":"0.01732","A":"74607","T":1626992745144,"E":1626992745148}}
1626992745.2137191: {"stream":"keepusdt@depth@100ms","data":{"e":"depthUpdate","E":1626992745170,"T":1626992745066,"s":"KEEPUSDT","U":600859671377,"u":600859671377,"pu":600859670352,"b":[["0.2417","407"]],"a":[]}}
1626992745.218251: {"stream":"akrousdt@depth@100ms","data":{"e":"depthUpdate","E":1626992745174,"T":1626992745157,"s":"AKROUSDT","U":600859671484,"u":600859672436,"pu":600859667898,"b":[["0.01727","1096926"],["0.01728","809177"],["0.01729","759179"],["0.01731","8108"]],"a":[["0.01736","874520"],["0.01737","426815"]]}}
1626992745.218347: {"stream":"sushiusdt@bookTicker","data":{"e":"bookTicker","u":600859672724,"s":"SUSHIUSDT","b":"7.6120","B":"30","a":"7.6140","A":"31","T":1626992745167,"E":1626992745175}}
1626992745.292011: {"stream":"sushiusdt@depth@100ms","data":{"e":"depthUpdate","E":1626992745248,"T":1626992745240,"s":"SUSHIUSDT","U":600859672223,"u":600859674031,"pu":600859671852,"b":[["7.1760","44"],["7.5400","861"],["7.6020","2642"],["7.6090","291"],["7.6120","30"]],"a":[["7.6150","545"],["7.6160","910"],["7.6170","2500"],["7.6180","1229"],["7.6190","832"],["7.6200","1886"],["7.6210","2304"],["7.6220","1987"],["7.6230","3855"],["7.6250","1130"],["7.6300","7621"],["7.6860","351"],["7.7920","599"]]}}
1626992745.320519: {"stream":"keepusdt@depth@100ms","data":{"e":"depthUpdate","E":1626992745274,"T":1626992745250,"s":"KEEPUSDT","U":600859672692,"u":600859674197,"pu":600859671377,"b":[],"a":[["0.2466","1248"],["0.2525","25497"],["0.2532","3621"],["0.2540","9073"],["0.2542","0"],["0.2577","14725"]]}}
1626992745.348516: {"stream":"ctkusdt@bookTicker","data":{"e":"bookTicker","u":600859674936,"s":"CTKUSDT","b":"1.01000","B":"85782","a":"1.01100","A":"6675","T":1626992745298,"E":1626992745304}}
1626992745.348614: {"stream":"ctkusdt@kline_1m","data":{"e":"kline","E":1626992745304,"s":"CTKUSDT","k":{"t":1626992700000,"T":1626992759999,"s":"CTKUSDT","i":"1m","f":23961275,"L":23961325,"o":"1.01000","c":"1.01100","h":"1.01100","l":"1.01000","v":"3947","n":51,"x":false,"q":"3988.22900","V":"1759","Q":"1778.34900","B":"0"}}}
1626992745.392014: {"stream":"sushiusdt@depth@100ms","data":{"e":"depthUpdate","E":1626992745348,"T":1626992745334,"s":"SUSHIUSDT","U":600859674095,"u":600859675536,"pu":600859674031,"b":[["7.6090","298"]],"a":[["7.6210","2596"],["8.3250","31"]]}}
1626992745.4312499: {"stream":"akrousdt@depth@100ms","data":{"e":"depthUpdate","E":1626992745387,"T":1626992745281,"s":"AKROUSDT","U":600859674694,"u":600859674694,"pu":600859672436,"b":[],"a":[["0.01738","1028223"]]}}
1626992745.4358678: {"stream":"keepusdt@depth@100ms","data":{"e":"depthUpdate","E":1626992745391,"T":1626992745286,"s":"KEEPUSDT","U":600859674763,"u":600859674763,"pu":600859674197,"b":[],"a":[["0.2525","34991"]]}}
1626992745.449876: {"stream":"ctkusdt@depth@100ms","data":{"e":"depthUpdate","E":1626992745404,"T":1626992745356,"s":"CTKUSDT","U":600859674932,"u":600859675869,"pu":600859660379,"b":[["1.00600","9269"],["1.01400","0"]],"a":[["1.01100","6675"],["1.01500","15887"]]}}
1626992745.5020711: {"stream":"ctkusdt@aggTrade","data":{"e":"aggTrade","E":1626992745454,"a":16599295,"s":"CTKUSDT","p":"1.01100","q":"10","f":23961325,"l":23961325,"T":1626992745298,"m":false}}
1626992745.544609: {"stream":"keepusdt@depth@100ms","data":{"e":"depthUpdate","E":1626992745501,"T":1626992745483,"s":"KEEPUSDT","U":600859676430,"u":600859677570,"pu":600859674763,"b":[["0.2458","9117"]],"a":[["0.2466","1248"],["0.2530","14288"]]}}
1626992745.550635: {"stream":"ctkusdt@depth@100ms","data":{"e":"depthUpdate","E":1626992745507,"T":1626992745499,"s":"CTKUSDT","U":600859676505,"u":600859677831,"pu":600859675869,"b":[["1.00600","9269"]],"a":[["1.01500","20835"]]}}
1626992745.5806541: {"stream":"sushiusdt@depth@100ms","data":{"e":"depthUpdate","E":1626992745537,"T":1626992745524,"s":"SUSHIUSDT","U":600859676869,"u":600859678240,"pu":600859675536,"b":[["7.6090","298"]],"a":[["7.6180","1279"],["7.6200","2210"],["7.6210","2546"],["7.6280","2989"]]}}
1626992745.633792: {"stream":"akrousdt@depth@100ms","data":{"e":"depthUpdate","E":1626992745587,"T":1626992745483,"s":"AKROUSDT","U":600859677580,"u":600859677580,"pu":600859674694,"b":[],"a":[["0.01752","218714"]]}}
1626992745.658509: {"stream":"ctkusdt@depth@100ms","data":{"e":"depthUpdate","E":1626992745614,"T":1626992745605,"s":"CTKUSDT","U":600859677944,"u":600859679654,"pu":600859677831,"b":[["1.00600","14217"]],"a":[["1.01500","20835"]]}}
1626992745.6753721: {"stream":"sushiusdt@bookTicker","data":{"e":"bookTicker","u":600859680111,"s":"SUSHIUSDT","b":"7.6120","B":"30","a":"7.6140","A":"93","T":1626992745625,"E":1626992745630}}
1626992745.67547: {"stream":"sushiusdt@bookTicker","data":{"e":"bookTicker","u":600859680153,"s":"SUSHIUSDT","b":"7.6120","B":"30","a":"7.6140","A":"62","T":1626992745626,"E":1626992745630}}
1626992745.6904461: {"stream":"sushiusdt@bookTicker","data":{"e":"bookTicker","u":600859680503,"s":"SUSHIUSDT","b":"7.6120","B":"30","a":"7.6140","A":"91","T":1626992745638,"E":1626992745644}}
1626992745.732047: {"stream":"sushiusdt@depth@100ms","data":{"e":"depthUpdate","E":1626992745686,"T":1626992745678,"s":"SUSHIUSDT","U":600859679119,"u":600859681916,"pu":600859678240,"b":[["7.5300","5354"],["7.5600","1979"],["7.5840","2164"],["7.5890","1049"],["7.5960","4118"],["7.6050","445"],["7.6070","406"],["7.6080","187"],["7.6090","52"],["7.6900","0"]],"a":[["7.6140","91"],["7.6150","576"],["7.6250","1110"],["7.6310","1772"],["7.6340","1026"],["7.6440","4418"],["7.6470","3905"],["7.6500","590"],["7.6800","1843"],["7.7100","4439"]]}}
1626992745.7983081: {"stream":"ctkusdt@depth@100ms","data":{"e":"depthUpdate","E":1626992745756,"T":1626992745706,"s":"CTKUSDT","U":600859680922,"u":600859682662,"pu":600859679654,"b":[["0.93700","24"],["1.00600","14217"]],"a":[["1.01500","20835"]]}}
1626992745.809984: {"stream":"keepusdt@depth@100ms","data":{"e":"depthUpdate","E":1626992745768,"T":1626992745753,"s":"KEEPUSDT","U":600859681415,"u":600859683733,"pu":600859677570,"b":[],"a":[["0.2466","1248"],["0.2527","27"]]}}
1626992745.857472: {"stream":"sushiusdt@depth@100ms","data":{"e":"depthUpdate","E":1626992745813,"T":1626992745803,"s":"SUSHIUSDT","U":600859682658,"u":600859684918,"pu":600859681916,"b":[["7.5940","559"],["7.5950","1700"],["7.6020","2774"],["7.6060","1841"],["7.6070","645"],["7.6090","51"]],"a":[["7.6250","2275"],["7.6270","736"]]}}
1626992745.90397: {"stream":"ctkusdt@depth@100ms","data":{"e":"depthUpdate","E":1626992745859,"T":1626992745754,"s":"CTKUSDT","U":600859683751,"u":600859683759,"pu":600859682662,"b":[["1.00600","9269"]],"a":[["1.01500","15887"]]}}
1626992745.907136: {"stream":"akrousdt@depth@100ms","data":{"e":"depthUpdate","E":1626992745863,"T":1626992745785,"s":"AKROUSDT","U":600859683892,"u":600859684454,"pu":600859677580,"b":[["0.01721","530480"],["0.01722","483338"],["0.01724","695656"],["0.01725","901990"],["0.01727","1133143"],["0.01728","772981"]],"a":[]}}
1626992745.957802: {"stream":"sushiusdt@bookTicker","data":{"e":"bookTicker","u":600859687098,"s":"SUSHIUSDT","b":"7.6120","B":"29","a":"7.6140","A":"91","T":1626992745907,"E":1626992745911}}
1626992745.9579039: {"stream":"sushiusdt@kline_1m","data":{"e":"kline","E":1626992745912,"s":"SUSHIUSDT","k":{"t":1626992700000,"T":1626992759999,"s":"SUSHIUSDT","i":"1m","f":126902874,"L":126902928,"o":"7.6080","c":"7.6120","h":"7.6120","l":"7.6070","v":"1590","n":55,"x":false,"q":"12101.4250","V":"846","Q":"6438.5080","B":"0"}}}
1626992745.967078: {"stream":"sushiusdt@depth@100ms","data":{"e":"depthUpdate","E":1626992745924,"T":1626992745907,"s":"SUSHIUSDT","U":600859685356,"u":600859687098,"pu":600859684918,"b":[["7.5500","3231"],["7.5930","3883"],["7.6040","535"],["7.6070","773"],["7.6090","58"],["7.6120","29"]],"a":[["7.6510","580"]]}}
1626992746.054925: {"stream":"sushiusdt@bookTicker","data":{"e":"bookTicker","u":600859689013,"s":"SUSHIUSDT","b":"7.6120","B":"29","a":"7.6140","A":"173","T":1626992746001,"E":1626992746008}}
1626992746.075108: {"stream":"sushiusdt@depth@100ms","data":{"e":"depthUpdate","E":1626992746030,"T":1626992746001,"s":"SUSHIUSDT","U":600859687422,"u":600859689013,"pu":600859687098,"b":[["7.6110","49"]],"a":[["7.6140","173"]]}}
1626992746.093312: {"stream":"akrousdt@depth@100ms","data":{"e":"depthUpdate","E":1626992746048,"T":1626992745943,"s":"AKROUSDT","U":600859687760,"u":600859687760,"pu":600859684454,"b":[["0.01729","828179"]],"a":[]}}
1626992746.107203: {"stream":"sushiusdt@aggTrade","data":{"e":"aggTrade","E":1626992746062,"a":87353231,"s":"SUSHIUSDT","p":"7.6120","q":"1","f":126902928,"l":126902928,"T":1626992745907,"m":true}}
1626992746.2095082: {"stream":"sushiusdt@depth@100ms","data":{"e":"depthUpdate","E":1626992746163,"T":1626992746154,"s":"SUSHIUSDT","U":600859690151,"u":600859691638,"pu":600859689013,"b":[["7.5200","371"],["7.5300","2353"],["7.5600","478"],["7.5650","798"],["7.5960","4098"],["7.5980","1175"],["7.6020","2782"],["7.6050","465"],["7.6090","58"],["7.6100","194"]],"a":[["7.6210","2230"],["7.6230","4171"],["7.6240","2648"],["7.6260","1803"],["7.6270","756"],["7.6340","1006"],["7.6800","374"],["7.7100","1470"]]}}
1626992746.227455: {"stream":"keepusdt@depth@100ms","data":{"e":"depthUpdate","E":1626992746182,"T":1626992746151,"s":"KEEPUSDT","U":600859690441,"u":600859691419,"pu":600859683733,"b":[],"a":[["0.2466","1248"],["0.2469","12397"]]}}
1626992746.3161469: {"stream":"sushiusdt@depth@100ms","data":{"e":"depthUpdate","E":1626992746271,"T":1626992746257,"s":"SUSHIUSDT","U":600859691838,"u":600859693451,"pu":600859691638,"b":[["7.5600","3479"],["7.5690","1978"],["7.5780","302"],["7.5820","1074"],["7.5840","3665"],["7.5880","1473"],["7.5920","1641"],["7.6040","600"],["7.6050","465"]],"a":[["7.6370","1048"],["7.6410","619"],["7.6440","5887"],["7.6500","3559"],["7.6590","632"],["7.6650","327"]]}}
1626992746.4086971: {"stream":"ctkusdt@depth@100ms","data":{"e":"depthUpdate","E":1626992746362,"T":1626992746329,"s":"CTKUSDT","U":600859693480,"u":600859694528,"pu":600859683759,"b":[],"a":[["1.01300","17748"],["1.01800","9180"],["1.03500","2407"]]}}
1626992746.415699: {"stream":"sushiusdt@depth@100ms","data":{"e":"depthUpdate","E":1626992746371,"T":1626992746365,"s":"SUSHIUSDT","U":600859693578,"u":600859695051,"pu":600859693451,"b":[["7.5910","2592"],["7.5920","3406"],["7.5990","562"],["7.6010","2486"],["7.6020","4523"],["7.6090","51"],["7.6100","272"],["7.6110","97"]],"a":[["7.6230","3190"],["7.6240","3629"],["7.6250","2139"],["7.6270","892"],["7.6280","2511"],["7.6300","5856"],["7.6320","2602"],["7.6840","289"],["7.6880","238"]]}}
1626992746.513629: {"stream":"ctkusdt@depth@100ms","data":{"e":"depthUpdate","E":1626992746470,"T":1626992746462,"s":"CTKUSDT","U":600859695038,"u":600859696524,"pu":600859694528,"b":[["0.99500","14174"],["1.00600","9269"]],"a":[["1.01500","15887"]]}}
1626992746.5255349: {"stream":"ctkusdt@kline_1m","data":{"e":"kline","E":1626992746482,"s":"CTKUSDT","k":{"t":1626992700000,"T":1626992759999,"s":"CTKUSDT","i":"1m","f":23961275,"L":23961326,"o":"1.01000","c":"1.01100","h":"1.01100","l":"1.01000","v":"3957","n":52,"x":false,"q":"3998.33900","V":"1769","Q":"1788.45900","B":"0"}}}
1626992746.527724: {"stream":"ctkusdt@bookTicker","data":{"e":"bookTicker","u":600859696772,"s":"CTKUSDT","b":"1.01000","B":"85782","a":"1.01100","A":"6665","T":1626992746479,"E":1626992746483}}
1626992746.527762: {"stream":"sushiusdt@depth@100ms","data":{"e":"depthUpdate","E":1626992746484,"T":1626992746424,"s":"SUSHIUSDT","U":600859695258,"u":600859695944,"pu":600859695051,"b":[["7.6090","58"],["7.6100","271"]],"a":[["7.6300","6334"]]}}
1626992746.628593: {"stream":"ctkusdt@depth@100ms","data":{"e":"depthUpdate","E":1626992746583,"T":1626992746559,"s":"CTKUSDT","U":600859696699,"u":600859698044,"pu":600859696524,"b":[["1.00600","9269"],["1.01400","0"]],"a":[["1.01100","6665"],["1.01500","15887"],["1.02600","9260"]]}}
1626992746.677471: {"stream":"sushiusdt@depth@100ms","data":{"e":"depthUpdate","E":1626992746632,"T":1626992746577,"s":"SUSHIUSDT","U":600859697601,"u":600859698314,"pu":600859695944,"b":[["7.5760","2009"],["7.6090","52"]],"a":[["7.6490","12589"]]}}
1626992746.680446: {"stream":"ctkusdt@aggTrade","data":{"e":"aggTrade","E":1626992746634,"a":16599296,"s":"CTKUSDT","p":"1.01100","q":"10","f":23961326,"l":23961326,"T":1626992746479,"m":false}}
1626992746.766315: {"stream":"akrousdt@depth@100ms","data":{"e":"depthUpdate","E":1626992746720,"T":1626992746614,"s":"AKROUSDT","U":600859698982,"u":600859698982,"pu":600859687760,"b":[],"a":[["0.01736","891820"]]}}
1626992746.83428: {"stream":"ctkusdt@depth@100ms","data":{"e":"depthUpdate","E":1626992746790,"T":1626992746685,"s":"CTKUSDT","U":600859700016,"u":600859700016,"pu":600859698044,"b":[],"a":[["1.03900","6267"]]}}
1626992746.869872: {"stream":"sushiusdt@bookTicker","data":{"e":"bookTicker","u":600859702284,"s":"SUSHIUSDT","b":"7.6120","B":"29","a":"7.6130","A":"1","T":1626992746820,"E":1626992746824}}
1626992746.93632: {"stream":"keepusdt@depth@100ms","data":{"e":"depthUpdate","E":1626992746892,"T":1626992746846,"s":"KEEPUSDT","U":600859701458,"u":600859702880,"pu":600859691419,"b":[["0.2415","521"]],"a":[["0.2466","1248"]]}}
1626992746.968745: {"stream":"sushiusdt@depth@100ms","data":{"e":"depthUpdate","E":1626992746924,"T":1626992746875,"s":"SUSHIUSDT","U":600859702284,"u":600859703381,"pu":600859698314,"b":[["7.5610","1386"],["7.5690","1918"],["7.5910","2622"],["7.5920","3376"],["7.5930","3730"],["7.6090","45"]],"a":[["7.6130","1"],["7.6150","583"]]}}
1626992747.0162282: {"stream":"akrousdt@depth@100ms","data":{"e":"depthUpdate","E":1626992746972,"T":1626992746865,"s":"AKROUSDT","U":600859703217,"u":600859703217,"pu":600859698982,"b":[["0.01722","468761"]],"a":[]}}
1626992747.039265: {"stream":"ctkusdt@depth@100ms","data":{"e":"depthUpdate","E":1626992746993,"T":1626992746934,"s":"CTKUSDT","U":600859703570,"u":600859704478,"pu":600859700016,"b":[["0.99500","24224"],["1.00600","9269"]],"a":[["1.01500","15887"],["1.02600","19007"]]}}
1626992747.0799072: {"stream":"sushiusdt@depth@100ms","data":{"e":"depthUpdate","E":1626992747036,"T":1626992746974,"s":"SUSHIUSDT","U":600859704438,"u":600859705357,"pu":600859703381,"b":[["7.6040","728"],["7.6070","645"]],"a":[["7.6240","4489"],["7.6250","974"]]}}
1626992747.157471: {"stream":"ctkusdt@depth@100ms","data":{"e":"depthUpdate","E":1626992747112,"T":1626992747101,"s":"CTKUSDT","U":600859706182,"u":600859708159,"pu":600859704478,"b":[["0.99500","20987"]],"a":[["1.01800","8902"]]}}
1626992747.1899571: {"stream":"sushiusdt@bookTicker","data":{"e":"bookTicker","u":600859708803,"s":"SUSHIUSDT","b":"7.6120","B":"35","a":"7.6130","A":"1","T":1626992747138,"E":1626992747143}}
1626992747.195327: {"stream":"keepusdt@depth@100ms","data":{"e":"depthUpdate","E":1626992747149,"T":1626992747135,"s":"KEEPUSDT","U":600859707034,"u":600859708674,"pu":600859702880,"b":[],"a":[["0.2465","812"],["0.2466","436"],["0.2538","9050"]]}}
1626992747.203754: {"stream":"sushiusdt@depth@100ms","data":{"e":"depthUpdate","E":1626992747158,"T":1626992747141,"s":"SUSHIUSDT","U":600859707279,"u":600859708986,"pu":600859705357,"b":[["7.6120","35"]],"a":[["7.6150","647"],["7.6160","878"],["7.6170","2468"],["8.2890","165"]]}}
1626992747.2908359: {"stream":"ctkusdt@kline_1m","data":{"e":"kline","E":1626992747245,"s":"CTKUSDT","k":{"t":1626992700000,"T":1626992759999,"s":"CTKUSDT","i":"1m","f":23961275,"L":23961327,"o":"1.01000","c":"1.01000","h":"1.01100","l":"1.01000","v":"3962","n":53,"x":false,"q":"4003.38900","V":"1769","Q":"1788.45900","B":"0"}}}
1626992747.2909582: {"stream":"ctkusdt@bookTicker","data":{"e":"bookTicker","u":600859712557,"s":"CTKUSDT","b":"1.01000","B":"85777","a":"1.01100","A":"6665","T":1626992747239,"E":1626992747244}}
1626992747.323531: {"stream":"ctkusdt@depth@100ms","data":{"e":"depthUpdate","E":1626992747277,"T":1626992747239,"s":"CTKUSDT","U":600859710087,"u":600859712557,"pu":600859708159,"b":[["1.01000","85777"]],"a":[["1.01000","0"],["1.02600","15868"]]}}
1626992747.348076: {"stream":"akrousdt@depth@100ms","data":{"e":"depthUpdate","E":1626992747303,"T":1626992747217,"s":"AKROUSDT","U":600859711154,"u":600859711908,"pu":600859703217,"b":[["0.01721","545066"]],"a":[["0.01753","32964"]]}}
1626992747.4123452: {"stream":"sushiusdt@depth@100ms","data":{"e":"depthUpdate","E":1626992747363,"T":1626992747272,"s":"SUSHIUSDT","U":600859712999,"u":600859713298,"pu":600859708986,"b":[["7.5990","536"]],"a":[["7.6510","561"]]}}
1626992747.440077: {"stream":"ctkusdt@aggTrade","data":{"e":"aggTrade","E":1626992747395,"a":16599297,"s":"CTKUSDT","p":"1.01000","q":"5","f":23961327,"l":23961327,"T":1626992747239,"m":true}}
1626992747.53163: {"stream":"ctkusdt@depth@100ms","data":{"e":"depthUpdate","E":1626992747486,"T":1626992747381,"s":"CTKUSDT","U":600859716030,"u":600859716030,"pu":600859712557,"b":[["0.93700","35"]],"a":[]}}
1626992747.5382788: {"stream":"sushiusdt@depth@100ms","data":{"e":"depthUpdate","E":1626992747493,"T":1626992747387,"s":"SUSHIUSDT","U":600859716174,"u":600859716174,"pu":600859713298,"b":[["7.6030","1223"]],"a":[]}}
1626992747.602156: {"stream":"akrousdt@depth@100ms","data":{"e":"depthUpdate","E":1626992747559,"T":1626992747487,"s":"AKROUSDT","U":600859717521,"u":600859718111,"pu":600859711908,"b":[["0.01724","678101"],["0.01725","919534"],["0.01727","1096926"],["0.01728","809177"]],"a":[]}}
1626992747.6118379: {"stream":"keepusdt@depth@100ms","data":{"e":"depthUpdate","E":1626992747568,"T":1626992747523,"s":"KEEPUSDT","U":600859717682,"u":600859718682,"pu":600859708674,"b":[["0.2388","404"]],"a":[["0.2465","812"],["0.2523","9609"]]}}
1626992747.672689: {"stream":"sushiusdt@depth@100ms","data":{"e":"depthUpdate","E":1626992747628,"T":1626992747613,"s":"SUSHIUSDT","U":600859718718,"u":600859720026,"pu":600859716174,"b":[["3.8060","0"],["7.4580","21"],["7.5760","3509"],["7.6070","777"]],"a":[["7.6480","2310"]]}}
1626992747.714344: {"stream":"ctkusdt@kline_1m","data":{"e":"kline","E":1626992747671,"s":"CTKUSDT","k":{"t":1626992700000,"T":1626992759999,"s":"CTKUSDT","i":"1m","f":23961275,"L":23961328,"o":"1.01000","c":"1.01100","h":"1.01100","l":"1.01000","v":"3972","n":54,"x":false,"q":"4013.49900","V":"1779","Q":"1798.56900","B":"0"}}}
1626992747.7164001: {"stream":"ctkusdt@bookTicker","data":{"e":"bookTicker","u":600859720756,"s":"CTKUSDT","b":"1.01000","B":"85777","a":"1.01100","A":"6655","T":1626992747667,"E":1626992747671}}
1626992747.761178: {"stream":"ctkusdt@depth@100ms","data":{"e":"depthUpdate","E":1626992747716,"T":1626992747700,"s":"CTKUSDT","U":600859720023,"u":600859721168,"pu":600859716030,"b":[["0.99500","29227"],["1.00600","9269"],["1.01400","0"]],"a":[["1.01100","6655"],["1.01200","10902"],["1.01500","20835"]]}}
1626992747.8113558: {"stream":"akrousdt@depth@100ms","data":{"e":"depthUpdate","E":1626992747766,"T":1626992747662,"s":"AKROUSDT","U":600859720666,"u":600859720686,"pu":600859718111,"b":[],"a":[["0.01734","375032"],["0.01737","447979"]]}}
1626992747.867845: {"stream":"ctkusdt@aggTrade","data":{"e":"aggTrade","E":1626992747822,"a":16599298,"s":"CTKUSDT","p":"1.01100","q":"10","f":23961328,"l":23961328,"T":1626992747667,"m":false}}
1626992747.8940291: {"stream":"ctkusdt@depth@100ms","data":{"e":"depthUpdate","E":1626992747832,"T":1626992747812,"s":"CTKUSDT","U":600859721655,"u":600859722957,"pu":600859721168,"b":[["1.00600","14217"]],"a":[["1.01200","11149"],["1.01500","15887"],["1.02600","23859"]]}}
1626992747.896787: {"stream":"sushiusdt@depth@100ms","data":{"e":"depthUpdate","E":1626992747850,"T":1626992747745,"s":"SUSHIUSDT","U":600859721932,"u":600859721932,"pu":600859720026,"b":[],"a":[["7.6550","1141"]]}}
1626992747.99104: {"stream":"ctkusdt@depth@100ms","data":{"e":"depthUpdate","E":1626992747947,"T":1626992747914,"s":"CTKUSDT","U":600859723373,"u":600859724523,"pu":600859722957,"b":[["1.00600","14217"]],"a":[]}}
1626992748.0266812: {"stream":"akrousdt@depth@100ms","data":{"e":"depthUpdate","E":1626992747982,"T":1626992747970,"s":"AKROUSDT","U":600859723888,"u":600859725527,"pu":600859720686,"b":[["0.01715","592943"],["0.01721","530480"]],"a":[["0.01738","1048423"]]}}
1626992748.103023: {"stream":"ctkusdt@depth@100ms","data":{"e":"depthUpdate","E":1626992748055,"T":1626992748013,"s":"CTKUSDT","U":600859725246,"u":600859726162,"pu":600859724523,"b":[["1.00600","9269"]],"a":[["1.01200","10902"]]}}
1626992748.103946: {"stream":"sushiusdt@depth@100ms","data":{"e":"depthUpdate","E":1626992748059,"T":1626992748036,"s":"SUSHIUSDT","U":600859725321,"u":600859726614,"pu":600859721932,"b":[["7.5600","478"],["7.5840","2164"],["7.5960","4118"],["7.6020","4523"],["7.6040","743"],["7.6050","495"],["7.6060","923"],["7.6070","762"]],"a":[["7.6160","763"],["7.6170","1615"],["7.6180","1239"],["7.6200","2160"],["7.6210","1900"],["7.6220","2137"],["7.6270","872"],["7.6340","1026"],["7.6440","4418"],["7.6500","590"],["7.6710","1153"],["8.2890","1"]]}}
1626992748.127603: {"stream":"akrousdt@depth@100ms","data":{"e":"depthUpdate","E":1626992748084,"T":1626992747980,"s":"AKROUSDT","U":600859725662,"u":600859725662,"pu":600859725527,"b":[["0.01715","572559"]],"a":[]}}
1626992748.216848: {"stream":"sushiusdt@depth@100ms","data":{"e":"depthUpdate","E":1626992748171,"T":1626992748160,"s":"SUSHIUSDT","U":600859727023,"u":600859728872,"pu":600859726614,"b":[["7.5300","5354"],["7.5600","2039"],["7.5610","1326"],["7.5970","1825"],["7.6020","4573"],["7.6050","270"],["7.6060","938"],["7.6070","762"]],"a":[["7.6160","978"],["7.6170","942"],["7.6180","1179"],["7.6190","1607"],["7.6200","1370"],["7.6210","1900"],["7.6270","684"],["7.6800","1843"],["7.7100","4439"]]}}
1626992748.225743: {"stream":"keepusdt@depth@100ms","data":{"e":"depthUpdate","E":1626992748182,"T":1626992748172,"s":"KEEPUSDT","U":600859727131,"u":600859729258,"pu":600859718682,"b":[["0.2446","8650"]],"a":[["0.2465","812"]]}}
1626992748.273739: {"stream":"akrousdt@depth@100ms","data":{"e":"depthUpdate","E":1626992748228,"T":1626992748125,"s":"AKROUSDT","U":600859727859,"u":600859727859,"pu":600859725662,"b":[],"a":[["0.01751","744031"]]}}
1626992748.275605: {"stream":"ctkusdt@depth@100ms","data":{"e":"depthUpdate","E":1626992748231,"T":1626992748126,"s":"CTKUSDT","U":600859727961,"u":600859727961,"pu":600859726162,"b":[],"a":[["1.01800","8624"]]}}
1626992748.315776: {"stream":"sushiusdt@depth@100ms","data":{"e":"depthUpdate","E":1626992748272,"T":1626992748242,"s":"SUSHIUSDT","U":600859729042,"u":600859730539,"pu":600859728872,"b":[["7.5990","673"],["7.6030","1123"],["7.6050","1238"],["7.6060","923"],["7.6070","792"]],"a":[["7.6180","1194"],["7.6190","2475"],["7.6640","2730"]]}}
1626992748.41183: {"stream":"ctkusdt@kline_1m","data":{"e":"kline","E":1626992748367,"s":"CTKUSDT","k":{"t":1626992700000,"T":1626992759999,"s":"CTKUSDT","i":"1m","f":23961275,"L":23961329,"o":"1.01000","c":"1.01000","h":"1.01100","l":"1.01000","v":"3977","n":55,"x":false,"q":"4018.54900","V":"1779","Q":"1798.56900","B":"0"}}}
1626992748.4143202: {"stream":"ctkusdt@bookTicker","data":{"e":"bookTicker","u":600859732722,"s":"CTKUSDT","b":"1.01000","B":"85772","a":"1.01100","A":"6655","T":1626992748362,"E":1626992748369}}
1626992748.419512: {"stream":"sushiusdt@depth@100ms","data":{"e":"depthUpdate","E":1626992748375,"T":1626992748363,"s":"SUSHIUSDT","U":600859731062,"u":600859732730,"pu":600859730539,"b":[["7.5950","1650"],["7.5970","1875"],["7.6000","775"],["7.6020","4523"],["7.6040","728"],["7.6050","1288"]],"a":[["7.6180","2852"],["7.6190","1475"],["7.6200","1520"],["7.6220","1987"]]}}
1626992748.510135: {"stream":"akrousdt@depth@100ms","data":{"e":"depthUpdate","E":1626992748463,"T":1626992748357,"s":"AKROUSDT","U":600859732624,"u":600859732624,"pu":600859727859,"b":[["0.01729","759179"]],"a":[]}}
1626992748.513781: {"stream":"ctkusdt@depth@100ms","data":{"e":"depthUpdate","E":1626992748469,"T":1626992748430,"s":"CTKUSDT","U":600859732718,"u":600859733659,"pu":600859727961,"b":[["1.00600","9269"],["1.01000","85772"]],"a":[["1.01000","0"],["1.01300","17994"]]}}
1626992748.5221398: {"stream":"sushiusdt@depth@100ms","data":{"e":"depthUpdate","E":1626992748477,"T":1626992748459,"s":"SUSHIUSDT","U":600859732841,"u":600859734027,"pu":600859732730,"b":[["7.5300","2353"],["7.5600","3539"],["7.5840","3665"],["7.5960","4098"],["7.5980","1057"],["7.6000","963"],["7.6050","1308"],["7.6060","938"]],"a":[["7.6170","1228"],["7.6180","3510"],["7.6190","379"],["7.6270","704"],["7.6340","1006"],["7.6440","5887"],["7.6500","3559"],["7.6800","374"],["7.7100","1470"],["8.9200","6507"]]}}
1626992748.5650072: {"stream":"ctkusdt@aggTrade","data":{"e":"aggTrade","E":1626992748519,"a":16599299,"s":"CTKUSDT","p":"1.01000","q":"5","f":23961329,"l":23961329,"T":1626992748362,"m":true}}
1626992748.6254551: {"stream":"sushiusdt@depth@100ms","data":{"e":"depthUpdate","E":1626992748581,"T":1626992748499,"s":"SUSHIUSDT","U":600859734268,"u":600859734576,"pu":600859734027,"b":[],"a":[["7.6170","2018"],["7.6180","2705"],["7.6190","394"]]}}
1626992748.639376: {"stream":"ctkusdt@bookTicker","data":{"e":"bookTicker","u":600859735767,"s":"CTKUSDT","b":"1.01000","B":"85757","a":"1.01100","A":"6655","T":1626992748587,"E":1626992748593}}
1626992748.737916: {"stream":"ctkusdt@depth@100ms","data":{"e":"depthUpdate","E":1626992748693,"T":1626992748640,"s":"CTKUSDT","U":600859735767,"u":600859736383,"pu":600859733659,"b":[["1.01000","85757"]],"a":[["1.01500","20835"],["1.13100","2275"]]}}
1626992748.749761: {"stream":"sushiusdt@depth@100ms","data":{"e":"depthUpdate","E":1626992748704,"T":1626992748682,"s":"SUSHIUSDT","U":600859735910,"u":600859736895,"pu":600859734576,"b":[],"a":[["7.6150","647"],["7.6160","978"],["7.6170","1281"],["7.6190","339"],["7.6200","2310"],["7.6220","1982"],["7.6240","4461"]]}}
1626992748.786471: {"stream":"akrousdt@depth@100ms","data":{"e":"depthUpdate","E":1626992748743,"T":1626992748734,"s":"AKROUSDT","U":600859736363,"u":600859737532,"pu":600859732624,"b":[["0.01722","483338"],["0.01729","729162"],["0.01730","136887"]],"a":[["0.01735","455250"],["0.01741","271726"],["0.01742","226758"]]}}
1626992748.839978: {"stream":"ctkusdt@depth@100ms","data":{"e":"depthUpdate","E":1626992748793,"T":1626992748742,"s":"CTKUSDT","U":600859736958,"u":600859737663,"pu":600859736383,"b":[],"a":[["1.01500","20835"]]}}
1626992748.850402: {"stream":"sushiusdt@depth@100ms","data":{"e":"depthUpdate","E":1626992748807,"T":1626992748795,"s":"SUSHIUSDT","U":600859737146,"u":600859738524,"pu":600859736895,"b":[["7.5440","524"],["7.5980","729"],["7.6010","2486"],["7.6020","4511"]],"a":[["7.6190","1129"],["7.6200","1520"],["7.6260","1475"],["7.6280","2539"],["7.6300","6662"],["8.7480","1620"]]}}
1626992748.918247: {"stream":"ctkusdt@bookTicker","data":{"e":"bookTicker","u":600859739836,"s":"CTKUSDT","b":"1.01000","B":"85757","a":"1.01100","A":"6645","T":1626992748866,"E":1626992748871}}
1626992748.9183512: {"stream":"ctkusdt@kline_1m","data":{"e":"kline","E":1626992748872,"s":"CTKUSDT","k":{"t":1626992700000,"T":1626992759999,"s":"CTKUSDT","i":"1m","f":23961275,"L":23961330,"o":"1.01000","c":"1.01100","h":"1.01100","l":"1.01000","v":"3987","n":56,"x":false,"q":"4028.65900","V":"1789","Q":"1808.67900","B":"0"}}}
1626992748.9262102: {"stream":"sushiusdt@bookTicker","data":{"e":"bookTicker","u":600859739988,"s":"SUSHIUSDT","b":"7.6120","B":"38","a":"7.6130","A":"1","T":1626992748875,"E":1626992748880}}
1626992748.9405801: {"stream":"keepusdt@depth@100ms","data":{"e":"depthUpdate","E":1626992748897,"T":1626992748887,"s":"KEEPUSDT","U":600859738494,"u":600859740225,"pu":600859729258,"b":[["0.2443","5160"],["0.2444","4095"]],"a":[["0.2465","812"]]}}
1626992748.942678: {"stream":"ctkusdt@depth@100ms","data":{"e":"depthUpdate","E":1626992748899,"T":1626992748866,"s":"CTKUSDT","U":600859738531,"u":600859739836,"pu":600859737663,"b":[["1.00600","9269"],["1.00800","23078"],["1.01400","0"]],"a":[["1.01100","6645"],["1.01500","20835"]]}}
1626992748.95883: {"stream":"sushiusdt@depth@100ms","data":{"e":"depthUpdate","E":1626992748914,"T":1626992748894,"s":"SUSHIUSDT","U":600859738790,"u":600859740346,"pu":600859738524,"b":[["7.3720","95"],["7.5470","2917"],["7.6030","799"],["7.6040","1052"],["7.6120","38"]],"a":[["7.6180","2720"],["7.6190","1114"],["7.6360","1129"],["7.6380","1329"]]}}
1626992749.051672: {"stream":"akrousdt@depth@100ms","data":{"e":"depthUpdate","E":1626992749008,"T":1626992748905,"s":"AKROUSDT","U":600859740512,"u":600859740512,"pu":600859737532,"b":[],"a":[["0.01746","146731"]]}}
1626992749.059073: {"stream":"ctkusdt@depth@100ms","data":{"e":"depthUpdate","E":1626992749014,"T":1626992749002,"s":"CTKUSDT","U":600859740591,"u":600859742221,"pu":600859739836,"b":[["1.00600","9269"]],"a":[["1.01500","15887"]]}}
1626992749.066515: {"stream":"ctkusdt@aggTrade","data":{"e":"aggTrade","E":1626992749022,"a":16599300,"s":"CTKUSDT","p":"1.01100","q":"10","f":23961330,"l":23961330,"T":1626992748866,"m":false}}
1626992749.0718138: {"stream":"sushiusdt@depth@100ms","data":{"e":"depthUpdate","E":1626992749026,"T":1626992749017,"s":"SUSHIUSDT","U":600859740783,"u":600859742454,"pu":600859740346,"b":[["7.5790","1469"],["7.5990","697"]],"a":[]}}
1626992749.186792: {"stream":"ctkusdt@depth@100ms","data":{"e":"depthUpdate","E":1626992749141,"T":1626992749078,"s":"CTKUSDT","U":600859742795,"u":600859743456,"pu":600859742221,"b":[],"a":[["1.01500","15887"]]}}
1626992749.204993: {"stream":"sushiusdt@depth@100ms","data":{"e":"depthUpdate","E":1626992749159,"T":1626992749137,"s":"SUSHIUSDT","U":600859743115,"u":600859744184,"pu":600859742454,"b":[],"a":[["7.6200","1845"],["7.6260","1449"]]}}
1626992749.2330601: {"stream":"keepusdt@depth@100ms","data":{"e":"depthUpdate","E":1626992749188,"T":1626992749150,"s":"KEEPUSDT","U":600859743605,"u":600859744606,"pu":600859740225,"b":[["0.2443","4341"]],"a":[["0.2465","812"]]}}
1626992749.3084302: {"stream":"sushiusdt@depth@100ms","data":{"e":"depthUpdate","E":1626992749262,"T":1626992749177,"s":"SUSHIUSDT","U":600859744839,"u":600859745417,"pu":600859744184,"b":[["7.5600","3479"],["7.5610","1386"]],"a":[["7.6200","1819"]]}}
1626992749.335795: {"stream":"akrousdt@depth@100ms","data":{"e":"depthUpdate","E":1626992749290,"T":1626992749185,"s":"AKROUSDT","U":600859745577,"u":600859745577,"pu":600859740512,"b":[],"a":[["0.01746","132431"]]}}
1626992749.3974211: {"stream":"keepusdt@depth@100ms","data":{"e":"depthUpdate","E":1626992749352,"T":1626992749304,"s":"KEEPUSDT","U":600859746645,"u":600859747597,"pu":600859744606,"b":[["0.2388","10022"],["0.2444","4913"]],"a":[["0.2465","812"]]}}
1626992749.454253: {"stream":"sushiusdt@depth@100ms","data":{"e":"depthUpdate","E":1626992749410,"T":1626992749359,"s":"SUSHIUSDT","U":600859747628,"u":600859748638,"pu":600859745417,"b":[["6.1010","6480"],["6.4920","1621"],["7.1810","643"],["7.5500","3198"],["7.5570","1156"]],"a":[["7.6240","4487"],["7.6320","2628"]]}}
1626992749.5557911: {"stream":"akrousdt@depth@100ms","data":{"e":"depthUpdate","E":1626992749510,"T":1626992749442,"s":"AKROUSDT","U":600859749317,"u":600859749786,"pu":600859745577,"b":[["0.01720","497182"],["0.01722","477531"]],"a":[["0.01767","165443"]]}}
1626992749.583147: {"stream":"ctkusdt@depth@100ms","data":{"e":"depthUpdate","E":1626992749537,"T":1626992749525,"s":"CTKUSDT","U":600859749642,"u":600859751258,"pu":600859743456,"b":[["1.00600","14217"]],"a":[["1.01500","15887"]]}}
1626992749.601336: {"stream":"sushiusdt@depth@100ms","data":{"e":"depthUpdate","E":1626992749556,"T":1626992749452,"s":"SUSHIUSDT","U":600859749927,"u":600859749927,"pu":600859748638,"b":[["7.5580","916"]],"a":[]}}
1626992749.648269: {"stream":"keepusdt@depth@100ms","data":{"e":"depthUpdate","E":1626992749602,"T":1626992749552,"s":"KEEPUSDT","U":600859750686,"u":600859751785,"pu":600859747597,"b":[["0.2434","23376"]],"a":[["0.2465","812"]]}}
1626992749.66781: {"stream":"akrousdt@depth@100ms","data":{"e":"depthUpdate","E":1626992749622,"T":1626992749516,"s":"AKROUSDT","U":600859751045,"u":600859751045,"pu":600859749786,"b":[["0.01724","683901"]],"a":[]}}
1626992749.692548: {"stream":"ctkusdt@depth@100ms","data":{"e":"depthUpdate","E":1626992749648,"T":1626992749544,"s":"CTKUSDT","U":600859751599,"u":600859751599,"pu":600859751258,"b":[["1.00600","9269"]],"a":[]}}
1626992749.769561: {"stream":"sushiusdt@depth@100ms","data":{"e":"depthUpdate","E":1626992749725,"T":1626992749688,"s":"SUSHIUSDT","U":600859752969,"u":600859754113,"pu":600859749927,"b":[["7.5760","2009"],["7.6010","2579"]],"a":[["7.6480","810"]]}}
1626992749.870105: {"stream":"ctkusdt@depth@100ms","data":{"e":"depthUpdate","E":1626992749826,"T":1626992749801,"s":"CTKUSDT","U":600859754630,"u":600859755811,"pu":600859751599,"b":[["1.00600","9269"]],"a":[["1.01500","15887"]]}}
1626992749.892693: {"stream":"akrousdt@depth@100ms","data":{"e":"depthUpdate","E":1626992749834,"T":1626992749819,"s":"AKROUSDT","U":600859754799,"u":600859756034,"pu":600859751045,"b":[],"a":[["0.01741","271726"],["0.01742","206748"]]}}
1626992749.930295: {"stream":"sushiusdt@depth@100ms","data":{"e":"depthUpdate","E":1626992749885,"T":1626992749838,"s":"SUSHIUSDT","U":600859755492,"u":600859756288,"pu":600859754113,"b":[["7.6040","728"],["7.6060","1248"],["7.6070","807"]],"a":[]}}
1626992749.956822: {"stream":"keepusdt@depth@100ms","data":{"e":"depthUpdate","E":1626992749911,"T":1626992749865,"s":"KEEPUSDT","U":600859755902,"u":600859756651,"pu":600859751785,"b":[["0.2443","5813"]],"a":[["0.2465","812"]]}}
1626992749.977552: {"stream":"ctkusdt@bookTicker","data":{"e":"bookTicker","u":600859757555,"s":"CTKUSDT","b":"1.01000","B":"85601","a":"1.01100","A":"6645","T":1626992749926,"E":1626992749930}}
1626992749.977651: {"stream":"ctkusdt@kline_1m","data":{"e":"kline","E":1626992749931,"s":"CTKUSDT","k":{"t":1626992700000,"T":1626992759999,"s":"CTKUSDT","i":"1m","f":23961275,"L":23961331,"o":"1.01000","c":"1.01000","h":"1.01100","l":"1.01000","v":"4143","n":57,"x":false,"q":"4186.21900","V":"1789","Q":"1808.67900","B":"0"}}}
1626992749.980458: {"stream":"akrousdt@depth@100ms","data":{"e":"depthUpdate","E":1626992749936,"T":1626992749900,"s":"AKROUSDT","U":600859756228,"u":600859757160,"pu":600859756034,"b":[["0.01557","82643"]],"a":[["0.01738","1179748"],["0.01739","980519"],["0.01742","226758"],["0.01753","33818"]]}}
1626992749.99006: {"stream":"ctkusdt@depth@100ms","data":{"e":"depthUpdate","E":1626992749945,"T":1626992749926,"s":"CTKUSDT","U":600859756299,"u":600859757555,"pu":600859755811,"b":[["1.00600","9269"],["1.01000","85601"]],"a":[["1.01500","15887"]]}}
1626992750.011575: {"stream":"ctkusdt@aggTrade","data":{"e":"aggTrade","E":1626992749966,"a":16599301,"s":"CTKUSDT","p":"1.01000","q":"156","f":23961331,"l":23961331,"T":1626992749926,"m":true}}
1626992750.011675: {"stream":"ctkusdt@bookTicker","data":{"e":"bookTicker","u":600859758124,"s":"CTKUSDT","b":"1.01000","B":"85601","a":"1.01100","A":"5656","T":1626992749963,"E":1626992749966}}
1626992750.0282738: {"stream":"ctkusdt@bookTicker","data":{"e":"bookTicker","u":600859758330,"s":"CTKUSDT","b":"1.01000","B":"85601","a":"1.01100","A":"5661","T":1626992749978,"E":1626992749982}}
1626992750.0824761: {"stream":"keepusdt@depth@100ms","data":{"e":"depthUpdate","E":1626992750036,"T":1626992749942,"s":"KEEPUSDT","U":600859757642,"u":600859757767,"pu":600859756651,"b":[["0.2456","17662"],["0.2457","15918"]],"a":[]}}
1626992750.086731: {"stream":"akrousdt@depth@100ms","data":{"e":"depthUpdate","E":1626992750041,"T":1626992750035,"s":"AKROUSDT","U":600859757686,"u":600859759358,"pu":600859757160,"b":[["0.01714","1498260"]],"a":[["0.01741","291748"],["0.01742","206748"]]}}
1626992750.099683: {"stream":"ctkusdt@bookTicker","data":{"e":"bookTicker","u":600859759614,"s":"CTKUSDT","b":"1.01000","B":"85601","a":"1.01100","A":"5651","T":1626992750047,"E":1626992750052}}
1626992750.0997849: {"stream":"ctkusdt@depth@100ms","data":{"e":"depthUpdate","E":1626992750054,"T":1626992750047,"s":"CTKUSDT","U":600859757881,"u":600859759614,"pu":600859757555,"b":[["1.00600","14217"],["1.01100","0"],["1.01400","0"]],"a":[["1.01100","5651"],["1.01300","17375"],["1.01400","12294"],["1.01500","22293"]]}}
1626992750.161553: {"stream":"ctkusdt@aggTrade","data":{"e":"aggTrade","E":1626992750117,"a":16599302,"s":"CTKUSDT","p":"1.01100","q":"999","f":23961332,"l":23961334,"T":1626992749963,"m":false}}
1626992750.191493: {"stream":"ctkusdt@bookTicker","data":{"e":"bookTicker","u":600859760954,"s":"CTKUSDT","b":"1.01000","B":"85601","a":"1.01100","A":"4551","T":1626992750141,"E":1626992750144}}
1626992750.2005079: {"stream":"ctkusdt@depth@100ms","data":{"e":"depthUpdate","E":1626992750155,"T":1626992750141,"s":"CTKUSDT","U":600859759635,"u":600859760954,"pu":600859759614,"b":[["1.00600","9269"]],"a":[["1.01100","4551"],["1.01500","17345"]]}}
1626992750.2048059: {"stream":"akrousdt@depth@100ms","data":{"e":"depthUpdate","E":1626992750161,"T":1626992750144,"s":"AKROUSDT","U":600859759871,"u":600859761067,"pu":600859759358,"b":[["0.01707","1041036"]],"a":[["0.01741","271726"]]}}
1626992750.213731: {"stream":"sushiusdt@kline_1m","data":{"e":"kline","E":1626992750168,"s":"SUSHIUSDT","k":{"t":1626992700000,"T":1626992759999,"s":"SUSHIUSDT","i":"1m","f":126902874,"L":126902929,"o":"7.6080","c":"7.6130","h":"7.6130","l":"7.6070","v":"1591","n":56,"x":false,"q":"12109.0380","V":"847","Q":"6446.1210","B":"0"}}}
1626992750.213815: {"stream":"sushiusdt@aggTrade","data":{"e":"aggTrade","E":1626992750168,"a":87353232,"s":"SUSHIUSDT","p":"7.6130","q":"1","f":126902929,"l":126902929,"T":1626992750163,"m":false}}
1626992750.213862: {"stream":"sushiusdt@aggTrade","data":{"e":"aggTrade","E":1626992750168,"a":87353233,"s":"SUSHIUSDT","p":"7.6140","q":"173","f":126902930,"l":126902932,"T":1626992750163,"m":false}}
1626992750.213888: {"stream":"sushiusdt@bookTicker","data":{"e":"bookTicker","u":600859761587,"s":"SUSHIUSDT","b":"7.6120","B":"38","a":"7.6150","A":"165","T":1626992750163,"E":1626992750168}}
1626992750.221267: {"stream":"sushiusdt@bookTicker","data":{"e":"bookTicker","u":600859761772,"s":"SUSHIUSDT","b":"7.6120","B":"38","a":"7.6130","A":"28","T":1626992750173,"E":1626992750177}}
1626992750.2271512: {"stream":"sushiusdt@bookTicker","data":{"e":"bookTicker","u":600859761843,"s":"SUSHIUSDT","b":"7.6120","B":"38","a":"7.6150","A":"165","T":1626992750176,"E":1626992750181}}
1626992750.229724: {"stream":"sushiusdt@bookTicker","data":{"e":"bookTicker","u":600859761872,"s":"SUSHIUSDT","b":"7.6130","B":"78","a":"7.6150","A":"165","T":1626992750177,"E":1626992750183}}
1626992750.235671: {"stream":"sushiusdt@bookTicker","data":{"e":"bookTicker","u":600859762002,"s":"SUSHIUSDT","b":"7.6130","B":"78","a":"7.6150","A":"133","T":1626992750187,"E":1626992750192}}
1626992750.237897: {"stream":"sushiusdt@bookTicker","data":{"e":"bookTicker","u":600859762013,"s":"SUSHIUSDT","b":"7.6130","B":"78","a":"7.6150","A":"101","T":1626992750188,"E":1626992750194}}
1626992750.242815: {"stream":"sushiusdt@bookTicker","data":{"e":"bookTicker","u":600859762096,"s":"SUSHIUSDT","b":"7.6130","B":"78","a":"7.6150","A":"94","T":1626992750193,"E":1626992750198}}
1626992750.2429152: {"stream":"sushiusdt@bookTicker","data":{"e":"bookTicker","u":600859762103,"s":"SUSHIUSDT","b":"7.6130","B":"78","a":"7.6150","A":"66","T":1626992750194,"E":1626992750198}}
1626992750.248565: {"stream":"sushiusdt@bookTicker","data":{"e":"bookTicker","u":600859762187,"s":"SUSHIUSDT","b":"7.6130","B":"78","a":"7.6150","A":"31","T":1626992750200,"E":1626992750205}}
1626992750.280203: {"stream":"sushiusdt@bookTicker","data":{"e":"bookTicker","u":600859762704,"s":"SUSHIUSDT","b":"7.6140","B":"1","a":"7.6150","A":"31","T":1626992750230,"E":1626992750234}}
1626992750.297109: {"stream":"sushiusdt@depth@100ms","data":{"e":"depthUpdate","E":1626992750251,"T":1626992750246,"s":"SUSHIUSDT","U":600859761085,"u":600859763017,"pu":600859756288,"b":[["7.5450","1380"],["7.5470","3386"],["7.5610","1326"],["7.5650","198"],["7.5690","1978"],["7.5730","3627"],["7.5800","3375"],["7.5890","1009"],["7.5910","2592"],["7.5920","3153"],["7.5930","3760"],["7.5950","1913"],["7.6010","1922"],["7.6020","2732"],["7.6030","2751"],["7.6040","458"],["7.6050","510"],["7.6060","457"],["7.6070","1675"],["7.6080","64"],["7.6100","240"],["7.6110","128"],["7.6120","21"],["7.6130","78"],["7.6140","1"],["7.6150","0"]],"a":[["7.6130","0"],["7.6140","0"],["7.6150","31"],["7.6160","557"],["7.6170","667"],["7.6180","1168"],["7.6190","1617"],["7.6200","2858"],["7.6210","1351"],["7.6220","1575"],["7.6230","3340"],["7.6240","3385"],["7.6250","1328"],["7.6260","2111"],["7.6290","2493"],["7.6300","6903"],["7.6340","642"],["7.6350","2114"],["7.6380","1359"],["7.6390","3007"],["7.6420","1029"],["7.6440","6150"],["7.6520","761"],["7.6810","2641"],["7.6830","1834"]]}}
1626992750.3015769: {"stream":"sushiusdt@bookTicker","data":{"e":"bookTicker","u":600859763051,"s":"SUSHIUSDT","b":"7.6140","B":"17","a":"7.6150","A":"31","T":1626992750249,"E":1626992750254}}
1626992750.30821: {"stream":"akrousdt@depth@100ms","data":{"e":"depthUpdate","E":1626992750263,"T":1626992750157,"s":"AKROUSDT","U":600859761417,"u":600859761417,"pu":600859761067,"b":[],"a":[["0.01742","226758"]]}}
1626992750.3383198: {"stream":"sushiusdt@bookTicker","data":{"e":"bookTicker","u":600859763802,"s":"SUSHIUSDT","b":"7.6140","B":"20","a":"7.6150","A":"31","T":1626992750287,"E":1626992750293}}
1626992750.343199: {"stream":"ctkusdt@aggTrade","data":{"e":"aggTrade","E":1626992750295,"a":16599303,"s":"CTKUSDT","p":"1.01100","q":"1100","f":23961335,"l":23961338,"T":1626992750141,"m":false}}
1626992750.3561668: {"stream":"sushiusdt@bookTicker","data":{"e":"bookTicker","u":600859764076,"s":"SUSHIUSDT","b":"7.6140","B":"20","a":"7.6160","A":"427","T":1626992750304,"E":1626992750308}}
1626992750.356267: {"stream":"sushiusdt@bookTicker","data":{"e":"bookTicker","u":600859764099,"s":"SUSHIUSDT","b":"7.6140","B":"20","a":"7.6160","A":"458","T":1626992750306,"E":1626992750311}}
1626992750.3642612: {"stream":"sushiusdt@aggTrade","data":{"e":"aggTrade","E":1626992750319,"a":87353234,"s":"SUSHIUSDT","p":"7.6150","q":"482","f":126902933,"l":126902936,"T":1626992750163,"m":false}}
1626992750.379945: {"stream":"sushiusdt@bookTicker","data":{"e":"bookTicker","u":600859765182,"s":"SUSHIUSDT","b":"7.6140","B":"20","a":"7.6160","A":"129","T":1626992750327,"E":1626992750333}}
1626992750.39766: {"stream":"sushiusdt@depth@100ms","data":{"e":"depthUpdate","E":1626992750352,"T":1626992750344,"s":"SUSHIUSDT","U":600859763031,"u":600859766009,"pu":600859763017,"b":[["7.5800","3089"],["7.5920","1388"],["7.5930","3103"],["7.5940","419"],["7.5960","4072"],["7.5970","2465"],["7.5980","755"],["7.6010","1829"],["7.6020","1325"],["7.6030","2500"],["7.6050","460"],["7.6060","857"],["7.6070","1655"],["7.6080","1324"],["7.6090","464"],["7.6100","381"],["7.6110","136"],["7.6120","18"],["7.6140","20"]],"a":[["7.6150","0"],["7.6160","129"],["7.6170","253"],["7.6180","1174"],["7.6190","1567"],["7.6200","2189"],["7.6210","1877"],["7.6220","1549"],["7.6230","2416"],["7.6240","2292"],["7.6250","2625"],["7.6260","1795"],["7.6270","1033"],["7.6280","2198"],["7.6290","2605"],["7.6320","863"],["7.6330","3948"],["7.6370","911"],["7.6390","744"],["7.6410","444"],["7.6420","2635"],["7.6440","6325"],["7.6510","574"],["7.6540","305"],["7.6570","793"],["7.6610","424"],["7.6900","178"]]}}
1626992750.469816: {"stream":"akrousdt@depth@100ms","data":{"e":"depthUpdate","E":1626992750424,"T":1626992750331,"s":"AKROUSDT","U":600859764964,"u":600859765387,"pu":600859761417,"b":[],"a":[["0.01741","291748"],["0.01742","206748"]]}}
1626992750.4699578: {"stream":"sushiusdt@bookTicker","data":{"e":"bookTicker","u":600859768397,"s":"SUSHIUSDT","b":"7.6140","B":"23","a":"7.6160","A":"129","T":1626992750420,"E":1626992750425}}
1626992750.498245: {"stream":"sushiusdt@depth@100ms","data":{"e":"depthUpdate","E":1626992750452,"T":1626992750445,"s":"SUSHIUSDT","U":600859766025,"u":600859769104,"pu":600859766009,"b":[["7.5040","413"],["7.5390","5820"],["7.5540","241"],["7.5580","607"],["7.5670","33"],["7.5770","691"],["7.5800","3264"],["7.5810","42"],["7.5870","854"],["7.5880","1298"],["7.5900","2194"],["7.5910","3961"],["7.5930","2861"],["7.5940","486"],["7.5950","2242"],["7.5980","557"],["7.5990","764"],["7.6000","332"],["7.6010","1631"],["7.6020","604"],["7.6030","1673"],["7.6040","2614"],["7.6050","1571"],["7.6060","1317"],["7.6080","1304"],["7.6090","592"],["7.6110","111"],["7.6120","46"],["7.6140","23"]],"a":[["7.6170","166"],["7.6180","504"],["7.6190","777"],["7.6200","2128"],["7.6220","2365"],["7.6240","2278"],["7.6250","3228"],["7.6260","1593"],["7.6270","1178"],["7.6280","2131"],["7.6290","2717"],["7.6300","3753"],["7.6310","1430"],["7.6320","246"],["7.6330","4115"],["7.6340","1259"],["7.6350","2045"],["7.6620","539"],["7.6650","333"],["7.6770","2442"],["7.6780","546"],["7.8970","97"]]}}
1626992750.571916: {"stream":"sushiusdt@bookTicker","data":{"e":"bookTicker","u":600859770928,"s":"SUSHIUSDT","b":"7.6140","B":"23","a":"7.6160","A":"103","T":1626992750518,"E":1626992750525}}
1626992750.573663: {"stream":"akrousdt@depth@100ms","data":{"e":"depthUpdate","E":1626992750527,"T":1626992750510,"s":"AKROUSDT","U":600859768536,"u":600859770707,"pu":600859765387,"b":[["0.01724","647729"],["0.01725","955616"]],"a":[["0.01741","271726"],["0.01742","226758"]]}}
1626992750.58742: {"stream":"sushiusdt@bookTicker","data":{"e":"bookTicker","u":600859771315,"s":"SUSHIUSDT","b":"7.6150","B":"6","a":"7.6160","A":"103","T":1626992750535,"E":1626992750542}}
1626992750.598132: {"stream":"sushiusdt@bookTicker","data":{"e":"bookTicker","u":600859771545,"s":"SUSHIUSDT","b":"7.6150","B":"7","a":"7.6160","A":"103","T":1626992750546,"E":1626992750552}}
1626992750.6002738: {"stream":"sushiusdt@depth@100ms","data":{"e":"depthUpdate","E":1626992750554,"T":1626992750546,"s":"SUSHIUSDT","U":600859769245,"u":600859771545,"pu":600859769104,"b":[["7.4920","446"],["7.4970","737"],["7.5640","800"],["7.5680","8661"],["7.5700","672"],["7.5840","3047"],["7.5970","2404"],["7.6000","200"],["7.6020","578"],["7.6030","1537"],["7.6050","1571"],["7.6080","1628"],["7.6110","111"],["7.6120","39"],["7.6150","7"]],"a":[["7.6160","103"],["7.6170","367"],["7.6180","480"],["7.6190","1552"],["7.6200","2848"],["7.6220","1575"],["7.6300","3820"],["7.6350","2220"],["7.6370","979"],["7.6620","461"],["7.6920","16"],["7.6960","1060"]]}}
1626992750.700384: {"stream":"sushiusdt@depth@100ms","data":{"e":"depthUpdate","E":1626992750654,"T":1626992750648,"s":"SUSHIUSDT","U":600859771612,"u":600859773956,"pu":600859771545,"b":[["7.5570","1070"],["7.5610","1412"],["7.5740","704"],["7.5860","995"],["7.5880","1915"],["7.5990","1022"],["7.6040","2690"],["7.6070","655"],["7.6080","2431"],["7.6090","890"],["7.6100","486"],["7.6110","170"],["7.6120","40"]],"a":[["7.6170","226"],["7.6180","454"],["7.6190","762"],["7.6200","1322"],["7.6210","1892"],["7.6220","2415"],["7.6230","2085"],["7.6240","2428"],["7.6290","2060"],["7.6300","3342"],["7.6310","1157"],["7.6340","1178"],["7.6370","1060"],["7.6450","1512"],["7.6590","572"],["7.6860","231"],["7.6920","196"]]}}
1626992750.707904: {"stream":"sushiusdt@bookTicker","data":{"e":"bookTicker","u":600859774204,"s":"SUSHIUSDT","b":"7.6150","B":"13","a":"7.6160","A":"103","T":1626992750657,"E":1626992750663}}
1626992750.708004: {"stream":"sushiusdt@bookTicker","data":{"e":"bookTicker","u":600859774246,"s":"SUSHIUSDT","b":"7.6150","B":"15","a":"7.6160","A":"103","T":1626992750659,"E":1626992750663}}
1626992750.728881: {"stream":"ctkusdt@depth@100ms","data":{"e":"depthUpdate","E":1626992750683,"T":1626992750580,"s":"CTKUSDT","U":600859772359,"u":600859772359,"pu":600859760954,"b":[["0.99900","9777"]],"a":[]}}
1626992750.7951932: {"stream":"sushiusdt@bookTicker","data":{"e":"bookTicker","u":600859776170,"s":"SUSHIUSDT","b":"7.6150","B":"16","a":"7.6160","A":"103","T":1626992750744,"E":1626992750748}}
1626992750.799223: {"stream":"sushiusdt@depth@100ms","data":{"e":"depthUpdate","E":1626992750756,"T":1626992750744,"s":"SUSHIUSDT","U":600859774023,"u":600859776170,"pu":600859773956,"b":[["7.5760","1695"],["7.5780","620"],["7.5790","2969"],["7.5840","3063"],["7.6010","1691"],["7.6020","617"],["7.6030","1517"],["7.6040","2640"],["7.6050","1371"],["7.6060","1517"],["7.6070","725"],["7.6080","1712"],["7.6120","38"],["7.6140","19"],["7.6150","16"]],"a":[["7.6170","216"],["7.6210","1802"],["7.6260","1580"],["7.6330","4389"],["7.6510","2074"]]}}
1626992750.816618: {"stream":"sushiusdt@bookTicker","data":{"e":"bookTicker","u":600859776661,"s":"SUSHIUSDT","b":"7.6150","B":"32","a":"7.6160","A":"103","T":1626992750767,"E":1626992750771}}
1626992750.839191: {"stream":"ctkusdt@depth@100ms","data":{"e":"depthUpdate","E":1626992750794,"T":1626992750722,"s":"CTKUSDT","U":600859774917,"u":600859775614,"pu":600859772359,"b":[["0.90900","536"],["0.98500","21773"]],"a":[["1.01300","17993"],["1.01500","16727"]]}}
1626992750.8529449: {"stream":"sushiusdt@bookTicker","data":{"e":"bookTicker","u":600859777317,"s":"SUSHIUSDT","b":"7.6150","B":"35","a":"7.6160","A":"103","T":1626992750801,"E":1626992750806}}
1626992750.8535721: {"stream":"akrousdt@depth@100ms","data":{"e":"depthUpdate","E":1626992750810,"T":1626992750705,"s":"AKROUSDT","U":600859775247,"u":600859775247,"pu":600859770707,"b":[["0.01720","488462"]],"a":[]}}
1626992750.9054568: {"stream":"sushiusdt@depth@100ms","data":{"e":"depthUpdate","E":1626992750861,"T":1626992750856,"s":"SUSHIUSDT","U":600859776411,"u":600859778243,"pu":600859776170,"b":[["3.8080","30"],["7.6040","2838"],["7.6080","1592"],["7.6090","1729"],["7.6110","275"],["7.6120","38"],["7.6140","25"],["7.6150","35"]],"a":[["7.6210","2592"],["7.6220","1625"],["7.6260","1821"],["7.6280","1231"],["7.6360","2029"],["7.6380","1495"]]}}
1626992750.959994: {"stream":"ctkusdt@depth@100ms","data":{"e":"depthUpdate","E":1626992750915,"T":1626992750876,"s":"CTKUSDT","U":600859777488,"u":600859778576,"pu":600859775614,"b":[["1.00600","14217"]],"a":[["1.01400","12294"],["1.01500","16727"]]}}
1626992751.017868: {"stream":"sushiusdt@depth@100ms","data":{"e":"depthUpdate","E":1626992750972,"T":1626992750957,"s":"SUSHIUSDT","U":600859778440,"u":600859779866,"pu":600859778243,"b":[["7.5600","3810"],["7.5930","2831"],["7.5940","516"],["7.5970","2888"],["7.5980","531"],["7.6000","226"],["7.6010","2131"],["7.6020","815"],["7.6030","914"],["7.6040","3850"],["7.6050","1271"],["7.6070","825"],["7.6090","1586"],["7.6100","629"]],"a":[["7.6220","1375"],["7.6240","2512"],["7.6340","1848"],["7.6380","1465"],["7.6410","474"]]}}
1626992751.048105: {"stream":"akrousdt@depth@100ms","data":{"e":"depthUpdate","E":1626992751003,"T":1626992750898,"s":"AKROUSDT","U":600859778897,"u":600859778897,"pu":600859775247,"b":[["0.01721","539195"]],"a":[]}}
1626992751.0641642: {"stream":"ctkusdt@depth@100ms","data":{"e":"depthUpdate","E":1626992751019,"T":1626992750915,"s":"CTKUSDT","U":600859779203,"u":600859779203,"pu":600859778576,"b":[["1.00600","9269"]],"a":[]}}
1626992751.13986: {"stream":"sushiusdt@depth@100ms","data":{"e":"depthUpdate","E":1626992751095,"T":1626992751081,"s":"SUSHIUSDT","U":600859780367,"u":600859782130,"pu":600859779866,"b":[["7.5620","2086"],["7.5670","146"],["7.5800","3466"],["7.5880","2097"],["7.5940","677"],["7.5990","955"],["7.6010","2198"],["7.6120","31"]],"a":[["7.6250","4076"],["7.6490","12452"]]}}
1626992751.17484: {"stream":"akrousdt@depth@100ms","data":{"e":"depthUpdate","E":1626992751129,"T":1626992751055,"s":"AKROUSDT","U":600859780939,"u":600859781779,"pu":600859778897,"b":[["0.01729","777162"]],"a":[["0.01737","489979"],["0.01739","938519"]]}}
1626992751.1772952: {"stream":"keepusdt@depth@100ms","data":{"e":"depthUpdate","E":1626992751133,"T":1626992751057,"s":"KEEPUSDT","U":600859781083,"u":600859781822,"pu":600859757767,"b":[],"a":[["0.2465","0"],["0.2469","9146"]]}}
1626992751.188739: {"stream":"sushiusdt@bookTicker","data":{"e":"bookTicker","u":600859782972,"s":"SUSHIUSDT","b":"7.6150","B":"35","a":"7.6160","A":"31","T":1626992751139,"E":1626992751143}}
1626992751.2084491: {"stream":"sushiusdt@bookTicker","data":{"e":"bookTicker","u":600859783726,"s":"SUSHIUSDT","b":"7.6150","B":"35","a":"7.6170","A":"247","T":1626992751153,"E":1626992751160}}
1626992751.2199008: {"stream":"sushiusdt@bookTicker","data":{"e":"bookTicker","u":600859784159,"s":"SUSHIUSDT","b":"7.6150","B":"35","a":"7.6170","A":"70","T":1626992751169,"E":1626992751174}}
1626992751.24887: {"stream":"sushiusdt@depth@100ms","data":{"e":"depthUpdate","E":1626992751204,"T":1626992751194,"s":"SUSHIUSDT","U":600859782345,"u":600859784705,"pu":600859782130,"b":[["7.5720","4365"],["7.5930","2558"],["7.5970","2838"],["7.5980","804"],["7.5990","1005"],["7.6050","1201"],["7.6060","1587"],["7.6100","590"],["7.6120","38"],["7.6130","117"]],"a":[["7.6160","0"],["7.6170","70"],["7.6180","210"],["7.6190","1028"],["7.6200","1336"],["7.6210","2150"],["7.6230","1420"],["7.6250","3621"],["7.6260","1951"],["7.6270","1010"],["7.6280","1338"],["7.6300","3181"],["7.6330","3949"],["7.6420","2035"],["7.6430","2946"],["7.6470","4004"],["7.6480","687"],["7.6520","1498"],["7.6530","912"]]}}
1626992751.285152: {"stream":"ctkusdt@kline_1m","data":{"e":"kline","E":1626992751239,"s":"CTKUSDT","k":{"t":1626992700000,"T":1626992759999,"s":"CTKUSDT","i":"1m","f":23961275,"L":23961339,"o":"1.01000","c":"1.01100","h":"1.01100","l":"1.01000","v":"6252","n":65,"x":false,"q":"6318.41800","V":"3898","Q":"3940.87800","B":"0"}}}
1626992751.285275: {"stream":"ctkusdt@bookTicker","data":{"e":"bookTicker","u":600859785509,"s":"CTKUSDT","b":"1.01000","B":"85601","a":"1.01100","A":"4541","T":1626992751234,"E":1626992751239}}
1626992751.2882931: {"stream":"keepusdt@depth@100ms","data":{"e":"depthUpdate","E":1626992751243,"T":1626992751139,"s":"KEEPUSDT","U":600859782988,"u":600859782988,"pu":600859781822,"b":[],"a":[["0.2466","1248"]]}}
1626992751.291501: {"stream":"akrousdt@depth@100ms","data":{"e":"depthUpdate","E":1626992751246,"T":1626992751200,"s":"AKROUSDT","U":600859783112,"u":600859784824,"pu":600859781779,"b":[["0.01725","919980"]],"a":[["0.01759","189380"]]}}
1626992751.304375: {"stream":"sushiusdt@bookTicker","data":{"e":"bookTicker","u":600859785823,"s":"SUSHIUSDT","b":"7.6150","B":"34","a":"7.6170","A":"70","T":1626992751253,"E":1626992751258}}
1626992751.310722: {"stream":"sushiusdt@bookTicker","data":{"e":"bookTicker","u":600859785956,"s":"SUSHIUSDT","b":"7.6160","B":"1","a":"7.6170","A":"70","T":1626992751262,"E":1626992751266}}
1626992751.3505092: {"stream":"sushiusdt@bookTicker","data":{"e":"bookTicker","u":600859786585,"s":"SUSHIUSDT","b":"7.6160","B":"17","a":"7.6170","A":"70","T":1626992751299,"E":1626992751304}}
1626992751.35061: {"stream":"sushiusdt@depth@100ms","data":{"e":"depthUpdate","E":1626992751305,"T":1626992751299,"s":"SUSHIUSDT","U":600859784862,"u":600859786605,"pu":600859784705,"b":[["7.5850","1810"],["7.5890","1209"],["7.5900","2019"],["7.5950","993"],["7.5970","1851"],["7.6010","3185"],["7.6020","1012"],["7.6040","3757"],["7.6080","724"],["7.6090","1735"],["7.6120","7"],["7.6130","148"],["7.6140","51"],["7.6150","18"],["7.6160","17"]],"a":[["7.6180","360"],["7.6190","765"],["7.6200","1021"],["7.6210","2135"],["7.6220","1364"],["7.6240","1546"],["7.6250","2937"],["7.6260","1977"],["7.6270","1666"],["7.6290","1640"],["7.6300","2236"],["7.6310","1888"],["7.6320","863"],["7.6330","3607"],["7.6380","1055"],["7.6390","1184"],["7.6400","781"],["7.6410","557"],["7.6420","2031"],["7.6430","3146"],["7.6480","604"],["7.6760","2128"],["7.6790","475"]]}}
1626992751.360739: {"stream":"sushiusdt@bookTicker","data":{"e":"bookTicker","u":600859786805,"s":"SUSHIUSDT","b":"7.6160","B":"20","a":"7.6170","A":"70","T":1626992751310,"E":1626992751315}}
1626992751.3844821: {"stream":"ctkusdt@depth@100ms","data":{"e":"depthUpdate","E":1626992751339,"T":1626992751308,"s":"CTKUSDT","U":600859785505,"u":600859786769,"pu":600859779203,"b":[["1.00600","9269"],["1.01400","0"]],"a":[["1.01100","4541"],["1.01500","16727"]]}}
1626992751.39831: {"stream":"akrousdt@depth@100ms","data":{"e":"depthUpdate","E":1626992751354,"T":1626992751255,"s":"AKROUSDT","U":600859785743,"u":600859785847,"pu":600859784824,"b":[["0.01705","109040"],["0.01726","552302"]],"a":[]}}
1626992751.435932: {"stream":"ctkusdt@aggTrade","data":{"e":"aggTrade","E":1626992751390,"a":16599304,"s":"CTKUSDT","p":"1.01100","q":"10","f":23961339,"l":23961339,"T":1626992751234,"m":false}}
1626992751.4549499: {"stream":"sushiusdt@depth@100ms","data":{"e":"depthUpdate","E":1626992751409,"T":1626992751404,"s":"SUSHIUSDT","U":600859786666,"u":600859788443,"pu":600859786605,"b":[["7.5790","2500"],["7.5830","4943"],["7.5870","414"],["7.5920","1563"],["7.5980","1067"],["7.5990","1543"],["7.6060","1587"],["7.6070","796"],["7.6080","724"],["7.6090","1703"],["7.6100","658"],["7.6110","307"],["7.6120","64"],["7.6130","155"],["7.6150","15"],["7.6160","20"]],"a":[["7.6180","336"],["7.6190","852"],["7.6200","1053"],["7.6210","1345"],["7.6230","1606"],["7.6240","2362"],["7.6290","1971"],["7.6310","1944"],["7.6330","3333"],["7.6350","2862"],["7.6410","831"],["7.6470","3535"],["7.6500","4028"],["7.6520","1225"],["7.6540","376"],["7.6560","258"]]}}
1626992751.461594: {"stream":"sushiusdt@aggTrade","data":{"e":"aggTrade","E":1626992751415,"a":87353235,"s":"SUSHIUSDT","p":"7.6160","q":"20","f":126902937,"l":126902939,"T":1626992751410,"m":true}}
1626992751.461697: {"stream":"sushiusdt@aggTrade","data":{"e":"aggTrade","E":1626992751415,"a":87353236,"s":"SUSHIUSDT","p":"7.6150","q":"15","f":126902940,"l":126902943,"T":1626992751410,"m":true}}
1626992751.4617422: {"stream":"sushiusdt@bookTicker","data":{"e":"bookTicker","u":600859788582,"s":"SUSHIUSDT","b":"7.6140","B":"28","a":"7.6170","A":"70","T":1626992751410,"E":1626992751415}}
1626992751.461782: {"stream":"sushiusdt@kline_1m","data":{"e":"kline","E":1626992751416,"s":"SUSHIUSDT","k":{"t":1626992700000,"T":1626992759999,"s":"SUSHIUSDT","i":"1m","f":126902874,"L":126902937,"o":"7.6080","c":"7.6160","h":"7.6160","l":"7.6070","v":"2247","n":64,"x":false,"q":"17104.3060","V":"1502","Q":"11433.7730","B":"0"}}}
1626992751.4731772: {"stream":"sushiusdt@bookTicker","data":{"e":"bookTicker","u":600859788775,"s":"SUSHIUSDT","b":"7.6140","B":"8","a":"7.6170","A":"70","T":1626992751418,"E":1626992751425}}
1626992751.4732742: {"stream":"sushiusdt@bookTicker","data":{"e":"bookTicker","u":600859788819,"s":"SUSHIUSDT","b":"7.6140","B":"36","a":"7.6170","A":"70","T":1626992751422,"E":1626992751426}}
1626992751.481457: {"stream":"sushiusdt@bookTicker","data":{"e":"bookTicker","u":600859788978,"s":"SUSHIUSDT","b":"7.6140","B":"36","a":"7.6170","A":"93","T":1626992751429,"E":1626992751435}}
1626992751.492299: {"stream":"ctkusdt@depth@100ms","data":{"e":"depthUpdate","E":1626992751447,"T":1626992751341,"s":"CTKUSDT","U":600859787342,"u":600859787342,"pu":600859786769,"b":[],"a":[["1.13100","1039"]]}}
1626992751.5049229: {"stream":"sushiusdt@bookTicker","data":{"e":"bookTicker","u":600859789482,"s":"SUSHIUSDT","b":"7.6140","B":"35","a":"7.6170","A":"93","T":1626992751453,"E":1626992751459}}
1626992751.516769: {"stream":"akrousdt@depth@100ms","data":{"e":"depthUpdate","E":1626992751474,"T":1626992751369,"s":"AKROUSDT","U":600859787838,"u":600859787838,"pu":600859785847,"b":[],"a":[["0.01758","315854"]]}}
1626992751.534462: {"stream":"sushiusdt@bookTicker","data":{"e":"bookTicker","u":600859789958,"s":"SUSHIUSDT","b":"7.6140","B":"25","a":"7.6170","A":"93","T":1626992751483,"E":1626992751487}}
1626992751.556194: {"stream":"sushiusdt@depth@100ms","data":{"e":"depthUpdate","E":1626992751513,"T":1626992751495,"s":"SUSHIUSDT","U":600859788529,"u":600859790169,"pu":600859788443,"b":[["7.5020","243"],["7.5230","3701"],["7.5470","2982"],["7.5510","1286"],["7.5920","2003"],["7.5990","1872"],["7.6070","1119"],["7.6080","1592"],["7.6090","1554"],["7.6110","274"],["7.6120","0"],["7.6130","125"],["7.6140","25"],["7.6150","0"],["7.6160","0"]],"a":[["7.6170","93"],["7.6180","453"],["7.6190","829"],["7.6220","2154"],["7.6240","1572"],["7.6340","2175"],["7.6350","2687"],["7.6370","1235"],["7.6470","3570"],["7.6550","1414"],["7.6570","389"],["7.6600","8907"]]}}
1626992751.610762: {"stream":"sushiusdt@aggTrade","data":{"e":"aggTrade","E":1626992751566,"a":87353237,"s":"SUSHIUSDT","p":"7.6140","q":"54","f":126902944,"l":126902949,"T":1626992751410,"m":true}}
1626992751.637398: {"stream":"sushiusdt@bookTicker","data":{"e":"bookTicker","u":600859791653,"s":"SUSHIUSDT","b":"7.6140","B":"25","a":"7.6170","A":"70","T":1626992751589,"E":1626992751593}}
1626992751.664139: {"stream":"sushiusdt@depth@100ms","data":{"e":"depthUpdate","E":1626992751619,"T":1626992751613,"s":"SUSHIUSDT","U":600859790458,"u":600859792061,"pu":600859790169,"b":[["7.5920","1674"],["7.6010","2533"],["7.6040","4007"],["7.6080","868"],["7.6090","1973"]],"a":[["7.6170","70"],["7.6180","476"],["7.6210","2135"],["7.6220","1349"],["7.6290","2300"],["7.6300","1893"],["7.6330","3810"],["7.6540","305"],["7.6590","632"],["7.6860","171"]]}}
1626992751.678977: {"stream":"sushiusdt@bookTicker","data":{"e":"bookTicker","u":600859792277,"s":"SUSHIUSDT","b":"7.6140","B":"25","a":"7.6160","A":"131","T":1626992751627,"E":1626992751633}}
1626992751.687466: {"stream":"akrousdt@depth@100ms","data":{"e":"depthUpdate","E":1626992751643,"T":1626992751539,"s":"AKROUSDT","U":600859790864,"u":600859790864,"pu":600859787838,"b":[],"a":[["0.01734","370326"]]}}
1626992751.712152: {"stream":"ctkusdt@depth@100ms","data":{"e":"depthUpdate","E":1626992751668,"T":1626992751641,"s":"CTKUSDT","U":600859791252,"u":600859792554,"pu":600859787342,"b":[["1.00600","9269"]],"a":[["1.01500","21675"]]}}
1626992751.7185862: {"stream":"sushiusdt@bookTicker","data":{"e":"bookTicker","u":600859793033,"s":"SUSHIUSDT","b":"7.6130","B":"118","a":"7.6160","A":"131","T":1626992751668,"E":1626992751675}}
1626992751.7223969: {"stream":"sushiusdt@bookTicker","data":{"e":"bookTicker","u":600859793084,"s":"SUSHIUSDT","b":"7.6130","B":"118","a":"7.6160","A":"162","T":1626992751671,"E":1626992751677}}
1626992751.7331269: {"stream":"sushiusdt@bookTicker","data":{"e":"bookTicker","u":600859793258,"s":"SUSHIUSDT","b":"7.6130","B":"118","a":"7.6140","A":"70","T":1626992751683,"E":1626992751688}}
1626992751.764918: {"stream":"sushiusdt@depth@100ms","data":{"e":"depthUpdate","E":1626992751720,"T":1626992751713,"s":"SUSHIUSDT","U":600859792098,"u":600859793805,"pu":600859792061,"b":[["7.5890","1249"],["7.5920","1664"],["7.5940","647"],["7.6000","246"],["7.6020","1027"],["7.6040","4257"],["7.6050","1271"],["7.6060","2048"],["7.6080","15"],["7.6090","930"],["7.6100","538"],["7.6110","194"],["7.6130","118"],["7.6140","0"]],"a":[["7.6140","70"],["7.6150","46"],["7.6160","324"],["7.6170","793"],["7.6180","412"],["7.6190","341"],["7.6200","1318"],["7.6220","1099"],["7.6230","1506"],["7.6250","3067"],["7.6260","1847"],["7.6280","2156"],["7.6310","2612"],["7.6350","2717"],["7.6410","801"]]}}
1626992751.769192: {"stream":"sushiusdt@bookTicker","data":{"e":"bookTicker","u":600859793912,"s":"SUSHIUSDT","b":"7.6130","B":"118","a":"7.6150","A":"46","T":1626992751720,"E":1626992751725}}
1626992751.806117: {"stream":"sushiusdt@bookTicker","data":{"e":"bookTicker","u":600859794497,"s":"SUSHIUSDT","b":"7.6130","B":"117","a":"7.6150","A":"46","T":1626992751753,"E":1626992751758}}
1626992751.8070889: {"stream":"sushiusdt@kline_1m","data":{"e":"kline","E":1626992751762,"s":"SUSHIUSDT","k":{"t":1626992700000,"T":1626992759999,"s":"SUSHIUSDT","i":"1m","f":126902874,"L":126902950,"o":"7.6080","c":"7.6130","h":"7.6160","l":"7.6070","v":"2353","n":77,"x":false,"q":"17911.4250","V":"1502","Q":"11433.7730","B":"0"}}}
1626992751.808598: {"stream":"sushiusdt@bookTicker","data":{"e":"bookTicker","u":600859794544,"s":"SUSHIUSDT","b":"7.6130","B":"117","a":"7.6150","A":"77","T":1626992751756,"E":1626992751761}}
1626992751.8107688: {"stream":"sushiusdt@bookTicker","data":{"e":"bookTicker","u":600859794582,"s":"SUSHIUSDT","b":"7.6130","B":"99","a":"7.6150","A":"77","T":1626992751758,"E":1626992751762}}
1626992751.810868: {"stream":"sushiusdt@bookTicker","data":{"e":"bookTicker","u":600859794664,"s":"SUSHIUSDT","b":"7.6130","B":"95","a":"7.6150","A":"77","T":1626992751761,"E":1626992751766}}
1626992751.8160582: {"stream":"sushiusdt@bookTicker","data":{"e":"bookTicker","u":600859794733,"s":"SUSHIUSDT","b":"7.6130","B":"37","a":"7.6150","A":"77","T":1626992751766,"E":1626992751770}}
1626992751.828581: {"stream":"sushiusdt@bookTicker","data":{"e":"bookTicker","u":600859794941,"s":"SUSHIUSDT","b":"7.6110","B":"31","a":"7.6150","A":"77","T":1626992751777,"E":1626992751782}}
1626992751.8286788: {"stream":"sushiusdt@bookTicker","data":{"e":"bookTicker","u":600859794945,"s":"SUSHIUSDT","b":"7.6110","B":"31","a":"7.6120","A":"43","T":1626992751777,"E":1626992751782}}
1626992751.828722: {"stream":"ctkusdt@depth@100ms","data":{"e":"depthUpdate","E":1626992751784,"T":1626992751679,"s":"CTKUSDT","U":600859793200,"u":600859793200,"pu":600859792554,"b":[],"a":[["1.01500","16727"]]}}
1626992751.831464: {"stream":"sushiusdt@bookTicker","data":{"e":"bookTicker","u":600859795023,"s":"SUSHIUSDT","b":"7.6110","B":"175","a":"7.6120","A":"43","T":1626992751782,"E":1626992751786}}
1626992751.835226: {"stream":"sushiusdt@bookTicker","data":{"e":"bookTicker","u":600859795080,"s":"SUSHIUSDT","b":"7.6110","B":"31","a":"7.6120","A":"43","T":1626992751785,"E":1626992751789}}
1626992751.835325: {"stream":"sushiusdt@bookTicker","data":{"e":"bookTicker","u":600859795112,"s":"SUSHIUSDT","b":"7.6110","B":"31","a":"7.6150","A":"77","T":1626992751786,"E":1626992751789}}
1626992751.838538: {"stream":"sushiusdt@bookTicker","data":{"e":"bookTicker","u":600859795166,"s":"SUSHIUSDT","b":"7.6110","B":"31","a":"7.6120","A":"229","T":1626992751789,"E":1626992751793}}
1626992751.84185: {"stream":"sushiusdt@bookTicker","data":{"e":"bookTicker","u":600859795180,"s":"SUSHIUSDT","b":"7.6100","B":"410","a":"7.6120","A":"229","T":1626992751790,"E":1626992751795}}
1626992751.841949: {"stream":"sushiusdt@bookTicker","data":{"e":"bookTicker","u":600859795205,"s":"SUSHIUSDT","b":"7.6100","B":"441","a":"7.6120","A":"229","T":1626992751792,"E":1626992751795}}
1626992751.845221: {"stream":"sushiusdt@bookTicker","data":{"e":"bookTicker","u":600859795283,"s":"SUSHIUSDT","b":"7.6100","B":"441","a":"7.6150","A":"77","T":1626992751794,"E":1626992751800}}
1626992751.848665: {"stream":"akrousdt@depth@100ms","data":{"e":"depthUpdate","E":1626992751803,"T":1626992751721,"s":"AKROUSDT","U":600859793517,"u":600859793937,"pu":600859790864,"b":[["0.01725","955574"],["0.01726","516729"]],"a":[]}}
1626992751.85134: {"stream":"sushiusdt@bookTicker","data":{"e":"bookTicker","u":600859795540,"s":"SUSHIUSDT","b":"7.6100","B":"441","a":"7.6150","A":"100","T":1626992751800,"E":1626992751806}}
1626992751.8662279: {"stream":"sushiusdt@bookTicker","data":{"e":"bookTicker","u":600859795928,"s":"SUSHIUSDT","b":"7.6100","B":"318","a":"7.6150","A":"100","T":1626992751815,"E":1626992751820}}
1626992751.866326: {"stream":"sushiusdt@depth@100ms","data":{"e":"depthUpdate","E":1626992751821,"T":1626992751816,"s":"SUSHIUSDT","U":600859793819,"u":600859795949,"pu":600859793805,"b":[["7.5020","4"],["7.5220","745"],["7.5860","1035"],["7.5890","1209"],["7.5930","2558"],["7.5970","1668"],["7.5980","804"],["7.5990","1613"],["7.6000","476"],["7.6010","2533"],["7.6020","1210"],["7.6030","914"],["7.6040","4007"],["7.6050","1435"],["7.6060","1948"],["7.6070","1040"],["7.6080","15"],["7.6090","0"],["7.6100","318"],["7.6110","0"],["7.6130","0"]],"a":[["7.5370","0"],["7.6120","0"],["7.6140","0"],["7.6150","100"],["7.6160","492"],["7.6170","378"],["7.6180","798"],["7.6190","865"],["7.6200","751"],["7.6210","2146"],["7.6220","1624"],["7.6230","1251"],["7.6240","1322"],["7.6250","2006"],["7.6260","1336"],["7.6280","2774"],["7.6300","910"],["7.6310","1995"],["7.6320","246"],["7.6340","1848"],["7.6530","880"]]}}
1626992751.8965728: {"stream":"sushiusdt@bookTicker","data":{"e":"bookTicker","u":600859796350,"s":"SUSHIUSDT","b":"7.6100","B":"523","a":"7.6150","A":"100","T":1626992751833,"E":1626992751839}}
1626992751.896658: {"stream":"sushiusdt@aggTrade","data":{"e":"aggTrade","E":1626992751840,"a":87353238,"s":"SUSHIUSDT","p":"7.6130","q":"80","f":126902950,"l":126902953,"T":1626992751758,"m":true}}
1626992751.8966908: {"stream":"sushiusdt@bookTicker","data":{"e":"bookTicker","u":600859796406,"s":"SUSHIUSDT","b":"7.6100","B":"465","a":"7.6150","A":"100","T":1626992751835,"E":1626992751840}}
1626992751.906056: {"stream":"sushiusdt@bookTicker","data":{"e":"bookTicker","u":600859796760,"s":"SUSHIUSDT","b":"7.6100","B":"465","a":"7.6150","A":"69","T":1626992751855,"E":1626992751859}}
1626992751.906157: {"stream":"sushiusdt@bookTicker","data":{"e":"bookTicker","u":600859796765,"s":"SUSHIUSDT","b":"7.6100","B":"465","a":"7.6140","A":"31","T":1626992751856,"E":1626992751861}}
1626992751.9062011: {"stream":"sushiusdt@bookTicker","data":{"e":"bookTicker","u":600859796772,"s":"SUSHIUSDT","b":"7.6100","B":"445","a":"7.6140","A":"31","T":1626992751856,"E":1626992751861}}
1626992751.911187: {"stream":"sushiusdt@bookTicker","data":{"e":"bookTicker","u":600859796887,"s":"SUSHIUSDT","b":"7.6110","B":"1","a":"7.6140","A":"31","T":1626992751861,"E":1626992751865}}
1626992751.9655838: {"stream":"sushiusdt@depth@100ms","data":{"e":"depthUpdate","E":1626992751921,"T":1626992751914,"s":"SUSHIUSDT","U":600859795979,"u":600859798008,"pu":600859795949,"b":[["7.5660","186"],["7.5860","995"],["7.5890","1009"],["7.5940","960"],["7.5950","1650"],["7.5960","3743"],["7.5980","954"],["7.5990","947"],["7.6000","226"],["7.6010","1479"],["7.6020","885"],["7.6040","1739"],["7.6050","1457"],["7.6060","1766"],["7.6070","1020"],["7.6100","313"],["7.6110","1"]],"a":[["7.6140","31"],["7.6150","69"],["7.6160","1205"],["7.6170","630"],["7.6180","583"],["7.6190","1115"],["7.6200","705"],["7.6210","1860"],["7.6220","1650"],["7.6230","988"],["7.6240","1953"],["7.6250","2073"],["7.6270","1579"],["7.6300","1547"],["7.6310","3269"],["7.6340","1191"],["7.6350","2892"],["7.6370","1060"],["7.6430","2946"],["7.6490","12224"],["7.6500","1059"],["7.6510","2055"],["7.6600","8503"],["7.6860","351"],["7.6900","139"],["7.6920","16"]]}}
1626992751.992843: {"stream":"ctkusdt@depth@100ms","data":{"e":"depthUpdate","E":1626992751948,"T":1626992751841,"s":"CTKUSDT","U":600859796525,"u":600859796525,"pu":600859793200,"b":[],"a":[["1.03700","4202"]]}}
1626992751.9981382: {"stream":"sushiusdt@bookTicker","data":{"e":"bookTicker","u":600859798731,"s":"SUSHIUSDT","b":"7.6100","B":"236","a":"7.6140","A":"31","T":1626992751948,"E":1626992751953}}
1626992752.02758: {"stream":"sushiusdt@bookTicker","data":{"e":"bookTicker","u":600859799219,"s":"SUSHIUSDT","b":"7.6100","B":"236","a":"7.6140","A":"55","T":1626992751975,"E":1626992751981}}
1626992752.035022: {"stream":"sushiusdt@aggTrade","data":{"e":"aggTrade","E":1626992751991,"a":87353239,"s":"SUSHIUSDT","p":"7.6100","q":"58","f":126902954,"l":126902954,"T":1626992751835,"m":true}}
1626992752.037159: {"stream":"sushiusdt@bookTicker","data":{"e":"bookTicker","u":600859799472,"s":"SUSHIUSDT","b":"7.6100","B":"236","a":"7.6130","A":"19","T":1626992751988,"E":1626992751992}}
1626992752.0562649: {"stream":"akrousdt@depth@100ms","data":{"e":"depthUpdate","E":1626992752011,"T":1626992751908,"s":"AKROUSDT","U":600859797865,"u":600859797865,"pu":600859793937,"b":[],"a":[["0.01736","909120"]]}}
1626992752.067883: {"stream":"sushiusdt@depth@100ms","data":{"e":"depthUpdate","E":1626992752022,"T":1626992752015,"s":"SUSHIUSDT","U":600859798107,"u":600859800057,"pu":600859798008,"b":[["7.5510","882"],["7.5690","1918"],["7.5850","2010"],["7.5860","1035"],["7.5890","1184"],["7.5920","1489"],["7.5950","1833"],["7.5990","1494"],["7.6000","12"],["7.6020","1747"],["7.6030","726"],["7.6040","1775"],["7.6050","565"],["7.6070","1125"],["7.6080","15"],["7.6100","236"],["7.6110","0"]],"a":[["7.6130","19"],["7.6140","55"],["7.6150","64"],["7.6160","1310"],["7.6170","618"],["7.6180","598"],["7.6190","475"],["7.6200","1804"],["7.6210","1536"],["7.6240","1979"],["7.6260","1310"],["7.6290","1971"],["7.6310","2944"],["7.6390","1384"],["7.6570","793"],["7.6800","3343"],["7.9350","359"]]}}
1626992752.0986319: {"stream":"ctkusdt@depth@100ms","data":{"e":"depthUpdate","E":1626992752051,"T":1626992751986,"s":"CTKUSDT","U":600859798697,"u":600859799430,"pu":600859796525,"b":[["1.00600","9269"]],"a":[["1.01500","16727"]]}}
1626992752.125273: {"stream":"ctkusdt@bookTicker","data":{"e":"bookTicker","u":600859801058,"s":"CTKUSDT","b":"1.01000","B":"85601","a":"1.01100","A":"5530","T":1626992752074,"E":1626992752079}}
1626992752.1701372: {"stream":"sushiusdt@depth@100ms","data":{"e":"depthUpdate","E":1626992752124,"T":1626992752118,"s":"SUSHIUSDT","U":600859800151,"u":600859801665,"pu":600859800057,"b":[["7.5470","3386"],["7.5610","1472"],["7.5980","707"],["7.6000","112"],["7.6020","1717"],["7.6040","1755"],["7.6050","693"],["7.6070","1012"],["7.6080","29"]],"a":[["7.6150","71"],["7.6180","844"],["7.6190","1265"],["7.6200","690"],["7.6220","1754"],["7.6230","769"],["7.6250","1943"],["7.6270","1539"],["7.6300","2204"],["7.6330","2890"],["7.6450","855"],["7.6490","12192"]]}}
1626992752.22458: {"stream":"ctkusdt@depth@100ms","data":{"e":"depthUpdate","E":1626992752179,"T":1626992752140,"s":"CTKUSDT","U":600859801058,"u":600859802266,"pu":600859799430,"b":[],"a":[["1.01100","5530"],["1.03700","6417"]]}}
1626992752.2709131: {"stream":"sushiusdt@depth@100ms","data":{"e":"depthUpdate","E":1626992752226,"T":1626992752214,"s":"SUSHIUSDT","U":600859801794,"u":600859803776,"pu":600859801665,"b":[["7.5960","4016"],["7.5970","1532"],["7.5990","1016"],["7.6030","786"],["7.6040","1695"],["7.6050","693"],["7.6070","689"],["7.6080","0"]],"a":[["7.6150","563"],["7.6160","1436"],["7.6170","840"],["7.6180","894"],["7.6200","611"],["7.6210","1435"],["7.6220","1704"],["7.6240","2019"],["7.6410","1458"],["7.6610","651"]]}}
1626992752.3802261: {"stream":"sushiusdt@depth@100ms","data":{"e":"depthUpdate","E":1626992752334,"T":1626992752328,"s":"SUSHIUSDT","U":600859804012,"u":600859806092,"pu":600859803776,"b":[["7.5920","1556"],["7.5940","893"],["7.6020","2698"],["7.6060","785"]],"a":[["7.6140","81"],["7.6160","1305"],["7.6170","855"],["7.6180","2405"],["7.6190","1765"],["7.6230","1162"],["7.6240","3000"],["7.6250","895"],["7.6280","2841"],["7.6300","1639"],["7.6330","3065"],["7.6350","2717"]]}}
1626992752.470804: {"stream":"ctkusdt@kline_1m","data":{"e":"kline","E":1626992752425,"s":"CTKUSDT","k":{"t":1626992700000,"T":1626992759999,"s":"CTKUSDT","i":"1m","f":23961275,"L":23961340,"o":"1.01000","c":"1.01100","h":"1.01100","l":"1.01000","v":"6262","n":66,"x":false,"q":"6328.52800","V":"3908","Q":"3950.98800","B":"0"}}}
1626992752.470887: {"stream":"ctkusdt@bookTicker","data":{"e":"bookTicker","u":600859808035,"s":"CTKUSDT","b":"1.01000","B":"85601","a":"1.01100","A":"5520","T":1626992752420,"E":1626992752425}}
1626992752.482561: {"stream":"sushiusdt@depth@100ms","data":{"e":"depthUpdate","E":1626992752438,"T":1626992752428,"s":"SUSHIUSDT","U":600859806193,"u":600859808202,"pu":600859806092,"b":[["7.5910","3991"],["7.5920","1526"],["7.6000","1782"],["7.6020","2628"],["7.6050","1087"],["7.6060","800"],["7.6070","674"]],"a":[["7.6170","3171"],["7.6180","879"],["7.6190","1172"],["7.6200","195"],["7.6220","1566"],["7.6320","276"],["7.6350","2687"],["7.6600","8352"],["7.7180","1107"]]}}
1626992752.547047: {"stream":"akrousdt@depth@100ms","data":{"e":"depthUpdate","E":1626992752503,"T":1626992752496,"s":"AKROUSDT","U":600859807602,"u":600859809649,"pu":600859797865,"b":[["0.01725","919980"],["0.01726","516729"],["0.01729","729162"]],"a":[]}}
1626992752.5612469: {"stream":"sushiusdt@bookTicker","data":{"e":"bookTicker","u":600859809944,"s":"SUSHIUSDT","b":"7.6100","B":"236","a":"7.6130","A":"56","T":1626992752511,"E":1626992752515}}
1626992752.5713139: {"stream":"ctkusdt@depth@100ms","data":{"e":"depthUpdate","E":1626992752525,"T":1626992752508,"s":"CTKUSDT","U":600859808031,"u":600859809893,"pu":600859802266,"b":[["1.01400","0"]],"a":[["1.01100","5520"],["1.01800","8346"]]}}
1626992752.5755389: {"stream":"sushiusdt@bookTicker","data":{"e":"bookTicker","u":600859810207,"s":"SUSHIUSDT","b":"7.6100","B":"205","a":"7.6130","A":"56","T":1626992752524,"E":1626992752530}}
1626992752.591838: {"stream":"sushiusdt@bookTicker","data":{"e":"bookTicker","u":600859810490,"s":"SUSHIUSDT","b":"7.6070","B":"674","a":"7.6130","A":"56","T":1626992752540,"E":1626992752545}}
1626992752.595176: {"stream":"sushiusdt@depth@100ms","data":{"e":"depthUpdate","E":1626992752549,"T":1626992752540,"s":"SUSHIUSDT","U":600859808548,"u":600859810490,"pu":600859808202,"b":[["7.5870","678"],["7.5950","2162"],["7.5960","4213"],["7.5970","2519"],["7.6000","2439"],["7.6040","2563"],["7.6100","0"]],"a":[["7.6130","56"],["7.6140","159"],["7.6150","554"],["7.6160","2095"],["7.6170","2381"],["7.6270","1867"],["7.6290","2954"],["7.6300","1902"]]}}
1626992752.598454: {"stream":"sushiusdt@bookTicker","data":{"e":"bookTicker","u":600859810591,"s":"SUSHIUSDT","b":"7.6070","B":"674","a":"7.6130","A":"173","T":1626992752545,"E":1626992752552}}
1626992752.598551: {"stream":"sushiusdt@bookTicker","data":{"e":"bookTicker","u":600859810620,"s":"SUSHIUSDT","b":"7.6080","B":"205","a":"7.6130","A":"173","T":1626992752546,"E":1626992752552}}
1626992752.609306: {"stream":"sushiusdt@bookTicker","data":{"e":"bookTicker","u":600859811165,"s":"SUSHIUSDT","b":"7.6080","B":"253","a":"7.6130","A":"173","T":1626992752555,"E":1626992752562}}
1626992752.6094038: {"stream":"sushiusdt@bookTicker","data":{"e":"bookTicker","u":600859811203,"s":"SUSHIUSDT","b":"7.6080","B":"284","a":"7.6130","A":"173","T":1626992752557,"E":1626992752564}}
1626992752.6116228: {"stream":"sushiusdt@bookTicker","data":{"e":"bookTicker","u":600859811255,"s":"SUSHIUSDT","b":"7.6080","B":"253","a":"7.6130","A":"173","T":1626992752561,"E":1626992752566}}
1626992752.611722: {"stream":"sushiusdt@bookTicker","data":{"e":"bookTicker","u":600859811257,"s":"SUSHIUSDT","b":"7.6090","B":"31","a":"7.6130","A":"173","T":1626992752561,"E":1626992752566}}
1626992752.611767: {"stream":"sushiusdt@bookTicker","data":{"e":"bookTicker","u":600859811262,"s":"SUSHIUSDT","b":"7.6090","B":"31","a":"7.6130","A":"197","T":1626992752561,"E":1626992752566}}
1626992752.6206322: {"stream":"ctkusdt@aggTrade","data":{"e":"aggTrade","E":1626992752576,"a":16599305,"s":"CTKUSDT","p":"1.01100","q":"10","f":23961340,"l":23961340,"T":1626992752420,"m":false}}
1626992752.67709: {"stream":"akrousdt@depth@100ms","data":{"e":"depthUpdate","E":1626992752630,"T":1626992752524,"s":"AKROUSDT","U":600859810210,"u":600859810210,"pu":600859809649,"b":[["0.01725","955574"]],"a":[]}}
1626992752.682546: {"stream":"ctkusdt@depth@100ms","data":{"e":"depthUpdate","E":1626992752635,"T":1626992752541,"s":"CTKUSDT","U":600859810331,"u":600859810520,"pu":600859809893,"b":[],"a":[["1.03600","12186"],["1.11400","3369"]]}}
1626992752.684288: {"stream":"akrousdt@bookTicker","data":{"e":"bookTicker","u":600859813834,"s":"AKROUSDT","b":"0.01731","B":"5464","a":"0.01732","A":"74607","T":1626992752632,"E":1626992752636}}
1626992752.684392: {"stream":"akrousdt@kline_1m","data":{"e":"kline","E":1626992752637,"s":"AKROUSDT","k":{"t":1626992700000,"T":1626992759999,"s":"AKROUSDT","i":"1m","f":27931328,"L":27931349,"o":"0.01731","c":"0.01731","h":"0.01733","l":"0.01731","v":"156509","n":22,"x":false,"q":"2710.01451","V":"68508","Q":"1186.71720","B":"0"}}}
1626992752.698445: {"stream":"sushiusdt@depth@100ms","data":{"e":"depthUpdate","E":1626992752652,"T":1626992752641,"s":"SUSHIUSDT","U":600859810591,"u":600859814264,"pu":600859810490,"b":[["7.5430","4725"],["7.5470","2917"],["7.5770","509"],["7.5930","3544"],["7.5960","4463"],["7.5970","1862"],["7.5990","404"],["7.6010","1549"],["7.6020","2558"],["7.6030","900"],["7.6040","1167"],["7.6050","615"],["7.6060","340"],["7.6070","309"],["7.6080","283"],["7.6090","31"]],"a":[["7.6130","197"],["7.6140","135"],["7.6150","1359"],["7.6160","1665"],["7.6170","640"],["7.6190","1523"],["7.6200","720"],["7.6210","1565"],["7.6220","911"],["7.6240","2343"],["7.6260","1330"],["7.6300","1882"],["7.6790","875"],["7.6830","1365"]]}}
1626992752.717383: {"stream":"sushiusdt@bookTicker","data":{"e":"bookTicker","u":600859815079,"s":"SUSHIUSDT","b":"7.6110","B":"37","a":"7.6130","A":"197","T":1626992752666,"E":1626992752670}}
1626992752.736224: {"stream":"sushiusdt@bookTicker","data":{"e":"bookTicker","u":600859815607,"s":"SUSHIUSDT","b":"7.6110","B":"37","a":"7.6130","A":"80","T":1626992752683,"E":1626992752689}}
1626992752.742684: {"stream":"sushiusdt@bookTicker","data":{"e":"bookTicker","u":600859815935,"s":"SUSHIUSDT","b":"7.6110","B":"37","a":"7.6130","A":"56","T":1626992752693,"E":1626992752697}}
1626992752.784541: {"stream":"akrousdt@depth@100ms","data":{"e":"depthUpdate","E":1626992752736,"T":1626992752728,"s":"AKROUSDT","U":600859813826,"u":600859817051,"pu":600859810210,"b":[["0.01725","919980"],["0.01726","552302"],["0.01731","5464"]],"a":[["0.01731","0"],["0.01741","288079"],["0.01746","116085"]]}}
1626992752.790032: {"stream":"sushiusdt@kline_1m","data":{"e":"kline","E":1626992752744,"s":"SUSHIUSDT","k":{"t":1626992700000,"T":1626992759999,"s":"SUSHIUSDT","i":"1m","f":126902874,"L":126902955,"o":"7.6080","c":"7.6110","h":"7.6160","l":"7.6070","v":"2497","n":82,"x":false,"q":"19007.4750","V":"1502","Q":"11433.7730","B":"0"}}}
1626992752.790171: {"stream":"sushiusdt@bookTicker","data":{"e":"bookTicker","u":600859818086,"s":"SUSHIUSDT","b":"7.6110","B":"13","a":"7.6130","A":"56","T":1626992752742,"E":1626992752744}}
1626992752.797487: {"stream":"sushiusdt@depth@100ms","data":{"e":"depthUpdate","E":1626992752752,"T":1626992752743,"s":"SUSHIUSDT","U":600859814495,"u":600859818131,"pu":600859814264,"b":[["7.5690","1814"],["7.5730","3730"],["7.5760","1601"],["7.5790","1000"],["7.5800","3559"],["7.5900","2172"],["7.5960","4601"],["7.5970","1929"],["7.6030","910"],["7.6040","448"],["7.6050","387"],["7.6060","325"],["7.6070","659"],["7.6080","319"],["7.6090","31"],["7.6110","13"]],"a":[["7.6110","0"],["7.6130","56"],["7.6140","159"],["7.6150","954"],["7.6160","1305"],["7.6180","1669"],["7.6230","1300"],["7.6240","2297"],["7.6270","1715"],["7.6280","2887"],["7.6290","2757"],["7.6510","555"],["7.6760","2532"],["7.6790","540"]]}}
1626992752.83039: {"stream":"akrousdt@aggTrade","data":{"e":"aggTrade","E":1626992752787,"a":14888303,"s":"AKROUSDT","p":"0.01731","q":"2644","f":27931349,"l":27931350,"T":1626992752632,"m":true}}
1626992752.8485188: {"stream":"keepusdt@depth@100ms","data":{"e":"depthUpdate","E":1626992752804,"T":1626992752758,"s":"KEEPUSDT","U":600859816033,"u":600859818724,"pu":600859782988,"b":[],"a":[["0.2466","1248"],["0.2528","0"]]}}
1626992752.853278: {"stream":"ctkusdt@depth@100ms","data":{"e":"depthUpdate","E":1626992752808,"T":1626992752784,"s":"CTKUSDT","U":600859816270,"u":600859819913,"pu":600859810520,"b":[["1.00700","10942"]],"a":[["1.01500","16727"],["1.01800","8068"]]}}
1626992752.8579671: {"stream":"sushiusdt@bookTicker","data":{"e":"bookTicker","u":600859820957,"s":"SUSHIUSDT","b":"7.6120","B":"20","a":"7.6130","A":"56","T":1626992752809,"E":1626992752813}}
1626992752.895376: {"stream":"sushiusdt@aggTrade","data":{"e":"aggTrade","E":1626992752837,"a":87353240,"s":"SUSHIUSDT","p":"7.6110","q":"24","f":126902955,"l":126902955,"T":1626992752742,"m":true}}
1626992752.895475: {"stream":"sushiusdt@aggTrade","data":{"e":"aggTrade","E":1626992752837,"a":87353241,"s":"SUSHIUSDT","p":"7.6120","q":"20","f":126902956,"l":126902956,"T":1626992752833,"m":true}}
1626992752.89552: {"stream":"sushiusdt@bookTicker","data":{"e":"bookTicker","u":600859821940,"s":"SUSHIUSDT","b":"7.6110","B":"9","a":"7.6130","A":"56","T":1626992752833,"E":1626992752837}}
1626992752.898612: {"stream":"sushiusdt@bookTicker","data":{"e":"bookTicker","u":600859822395,"s":"SUSHIUSDT","b":"7.6110","B":"9","a":"7.6130","A":"19","T":1626992752848,"E":1626992752852}}
1626992752.90021: {"stream":"sushiusdt@depth@100ms","data":{"e":"depthUpdate","E":1626992752855,"T":1626992752848,"s":"SUSHIUSDT","U":600859818354,"u":600859822395,"pu":600859818131,"b":[["7.5670","550"],["7.5700","268"],["7.5800","3065"],["7.5820","956"],["7.5840","3181"],["7.5890","1079"],["7.5910","4328"],["7.5920","1631"],["7.5930","4227"],["7.6000","2459"],["7.6010","1220"],["7.6030","727"],["7.6040","616"],["7.6050","371"],["7.6070","491"],["7.6080","397"],["7.6090","109"],["7.6100","40"],["7.6110","9"],["7.6120","0"]],"a":[["7.6110","0"],["7.6130","19"],["7.6140","57"],["7.6150","978"],["7.6160","1233"],["7.6190","1673"],["7.6210","1285"],["7.6220","1133"],["7.6240","2610"],["7.6290","2920"],["7.6350","2193"],["7.6370","1909"],["7.6390","1540"],["7.6470","2565"],["7.6790","471"]]}}
1626992752.9005802: {"stream":"akrousdt@depth@100ms","data":{"e":"depthUpdate","E":1626992752856,"T":1626992752795,"s":"AKROUSDT","U":600859818436,"u":600859820371,"pu":600859817051,"b":[["0.01718","107546"],["0.01725","916231"],["0.01729","780162"]],"a":[["0.01735","448334"],["0.01743","341359"]]}}
1626992752.952189: {"stream":"sushiusdt@bookTicker","data":{"e":"bookTicker","u":600859824053,"s":"SUSHIUSDT","b":"7.6120","B":"42","a":"7.6130","A":"19","T":1626992752902,"E":1626992752906}}
1626992752.966579: {"stream":"sushiusdt@bookTicker","data":{"e":"bookTicker","u":600859824614,"s":"SUSHIUSDT","b":"7.6120","B":"42","a":"7.6130","A":"47","T":1626992752917,"E":1626992752920}}
1626992752.966676: {"stream":"ctkusdt@depth@100ms","data":{"e":"depthUpdate","E":1626992752921,"T":1626992752903,"s":"CTKUSDT","U":600859821284,"u":600859824081,"pu":600859819913,"b":[["1.00200","21322"],["1.00600","14217"],["1.00800","23139"]],"a":[["1.01500","16727"],["1.03600","14500"]]}}
1626992752.9878132: {"stream":"sushiusdt@bookTicker","data":{"e":"bookTicker","u":600859825288,"s":"SUSHIUSDT","b":"7.6120","B":"42","a":"7.6130","A":"19","T":1626992752936,"E":1626992752941}}
1626992753.001705: {"stream":"sushiusdt@depth@100ms","data":{"e":"depthUpdate","E":1626992752956,"T":1626992752946,"s":"SUSHIUSDT","U":600859822448,"u":600859825680,"pu":600859822395,"b":[["7.5390","5466"],["7.5790","714"],["7.5900","2019"],["7.5960","4463"],["7.6040","576"],["7.6050","371"],["7.6090","110"],["7.6100","0"],["7.6120","42"]],"a":[["7.6130","19"],["7.6140","57"],["7.6150","607"],["7.6190","1173"],["7.6280","2770"],["7.6300","2000"],["7.6590","577"],["7.6670","455"],["7.6740","1877"],["7.6750","811"],["7.6760","2441"]]}}
1626992753.00865: {"stream":"akrousdt@depth@100ms","data":{"e":"depthUpdate","E":1626992752963,"T":1626992752929,"s":"AKROUSDT","U":600859822701,"u":600859825056,"pu":600859820371,"b":[["0.01721","522611"],["0.01723","366230"],["0.01725","893954"],["0.01727","1100522"]],"a":[["0.01735","439689"],["0.01736","926420"],["0.01738","1186652"],["0.01746","133267"]]}}
1626992753.0315351: {"stream":"sushiusdt@aggTrade","data":{"e":"aggTrade","E":1626992752988,"a":87353242,"s":"SUSHIUSDT","p":"7.6110","q":"4","f":126902957,"l":126902957,"T":1626992752833,"m":true}}
1626992753.072971: {"stream":"ctkusdt@depth@100ms","data":{"e":"depthUpdate","E":1626992753028,"T":1626992752985,"s":"CTKUSDT","U":600859824925,"u":600859826979,"pu":600859824081,"b":[["1.00600","9269"]],"a":[["1.01400","11123"],["1.01500","16727"],["1.01600","19516"]]}}
1626992753.104309: {"stream":"sushiusdt@depth@100ms","data":{"e":"depthUpdate","E":1626992753056,"T":1626992753046,"s":"SUSHIUSDT","U":600859825876,"u":600859829093,"pu":600859825680,"b":[["7.5850","1668"],["7.5900","1402"],["7.5930","4844"],["7.5940","732"],["7.5960","4213"],["7.5980","957"],["7.6010","1150"],["7.6030","797"],["7.6040","616"],["7.6050","366"],["7.6060","325"],["7.6080","390"],["7.6090","116"],["7.6890","0"]],"a":[["7.6150","557"],["7.6160","1283"],["7.6180","1684"],["7.6220","1458"],["7.6230","2087"],["7.6290","6316"],["7.6360","2293"],["7.6660","767"],["7.6670","285"],["7.6740","1695"]]}}
1626992753.1050088: {"stream":"keepusdt@depth@100ms","data":{"e":"depthUpdate","E":1626992753059,"T":1626992753046,"s":"KEEPUSDT","U":600859825968,"u":600859829072,"pu":600859818724,"b":[],"a":[["0.2466","1248"],["0.2525","44089"]]}}
1626992753.1286771: {"stream":"akrousdt@depth@100ms","data":{"e":"depthUpdate","E":1626992753082,"T":1626992753044,"s":"AKROUSDT","U":600859826673,"u":600859828988,"pu":600859825056,"b":[["0.01705","114898"],["0.01719","165285"],["0.01726","574543"]],"a":[["0.01738","1156742"]]}}
1626992753.187863: {"stream":"sushiusdt@kline_1m","data":{"e":"kline","E":1626992753144,"s":"SUSHIUSDT","k":{"t":1626992700000,"T":1626992759999,"s":"SUSHIUSDT","i":"1m","f":126902874,"L":126902958,"o":"7.6080","c":"7.6120","h":"7.6160","l":"7.6070","v":"2523","n":85,"x":false,"q":"19205.3830","V":"1502","Q":"11433.7730","B":"0"}}}
1626992753.189706: {"stream":"sushiusdt@bookTicker","data":{"e":"bookTicker","u":600859831393,"s":"SUSHIUSDT","b":"7.6120","B":"40","a":"7.6130","A":"19","T":1626992753138,"E":1626992753144}}
1626992753.202506: {"stream":"sushiusdt@depth@100ms","data":{"e":"depthUpdate","E":1626992753157,"T":1626992753154,"s":"SUSHIUSDT","U":600859829240,"u":600859832808,"pu":600859829093,"b":[["7.5180","807"],["7.5960","4455"],["7.5970","1687"],["7.6040","576"],["7.6050","441"],["7.6120","40"]],"a":[["7.6240","3267"],["7.6290","6562"],["7.6360","2469"],["7.6390","1521"],["7.6580","267"],["7.6660","682"],["7.6730","1213"]]}}
1626992753.21634: {"stream":"ctkusdt@depth@100ms","data":{"e":"depthUpdate","E":1626992753170,"T":1626992753162,"s":"CTKUSDT","U":600859829460,"u":600859833536,"pu":600859826979,"b":[["1.00300","6015"]],"a":[["1.01300","18269"],["1.02100","36118"],["1.02200","5296"]]}}
1626992753.2776902: {"stream":"sushiusdt@bookTicker","data":{"e":"bookTicker","u":600859836819,"s":"SUSHIUSDT","b":"7.6120","B":"49","a":"7.6130","A":"19","T":1626992753225,"E":1626992753230}}
1626992753.288363: {"stream":"keepusdt@depth@100ms","data":{"e":"depthUpdate","E":1626992753244,"T":1626992753232,"s":"KEEPUSDT","U":600859831354,"u":600859837116,"pu":600859829072,"b":[["0.2456","17662"],["0.2457","15918"]],"a":[["0.2465","812"],["0.2466","436"]]}}
1626992753.288543: {"stream":"akrousdt@depth@100ms","data":{"e":"depthUpdate","E":1626992753244,"T":1626992753149,"s":"AKROUSDT","U":600859831399,"u":600859832357,"pu":600859828988,"b":[],"a":[["0.01735","379689"],["0.01737","498614"]]}}
1626992753.3052008: {"stream":"sushiusdt@depth@100ms","data":{"e":"depthUpdate","E":1626992753260,"T":1626992753252,"s":"SUSHIUSDT","U":600859833152,"u":600859837969,"pu":600859832808,"b":[["7.5680","8642"],["7.5850","1190"],["7.5890","1109"],["7.5900","1744"],["7.5910","4298"],["7.5990","684"],["7.6000","2554"],["7.6020","2494"],["7.6030","782"],["7.6040","1297"],["7.6050","456"],["7.6090","109"],["7.6110","0"],["7.6120","49"]],"a":[["7.6180","1622"],["7.6260","1184"],["7.6290","6644"],["7.6320","246"],["7.6340","1221"],["7.6360","2557"]]}}
1626992753.3395689: {"stream":"sushiusdt@aggTrade","data":{"e":"aggTrade","E":1626992753295,"a":87353243,"s":"SUSHIUSDT","p":"7.6120","q":"2","f":126902958,"l":126902958,"T":1626992753138,"m":true}}
1626992753.408525: {"stream":"sushiusdt@depth@100ms","data":{"e":"depthUpdate","E":1626992753363,"T":1626992753336,"s":"SUSHIUSDT","U":600859838291,"u":600859841206,"pu":600859837969,"b":[["7.5550","190"],["7.5570","1079"],["7.5760","1620"],["7.5980","781"],["7.6000","2704"],["7.6040","1169"],["7.6050","584"],["7.6080","495"],["7.6090","117"]],"a":[["7.6150","637"],["7.6160","1233"],["7.6190","2699"],["7.6210","1360"],["7.6370","2386"],["7.6470","2584"],["7.7030","777"],["7.7160","19"],["7.7690","4"]]}}
1626992753.52536: {"stream":"akrousdt@depth@100ms","data":{"e":"depthUpdate","E":1626992753479,"T":1626992753396,"s":"AKROUSDT","U":600859842640,"u":600859843335,"pu":600859832357,"b":[["0.01722","484499"]],"a":[["0.01743","327016"]]}}
1626992753.5425532: {"stream":"sushiusdt@depth@100ms","data":{"e":"depthUpdate","E":1626992753496,"T":1626992753486,"s":"SUSHIUSDT","U":600859843187,"u":600859846092,"pu":600859841206,"b":[["7.4390","917"],["7.5690","2035"],["7.5860","995"],["7.5890","1149"],["7.5910","4750"],["7.6000","2609"],["7.6020","2539"],["7.6030","875"],["7.6040","1493"],["7.6060","1044"],["7.6070","523"],["7.6080","559"],["7.6090","173"]],"a":[["7.6140","87"],["7.6150","661"],["7.6160","1265"],["7.6180","3148"],["7.6190","1109"],["7.6200","688"],["7.6260","1044"],["7.6380","1046"],["7.6390","1475"],["7.6400","790"],["7.6430","2992"],["8.4260","164"]]}}
1626992753.559477: {"stream":"sushiusdt@bookTicker","data":{"e":"bookTicker","u":600859846902,"s":"SUSHIUSDT","b":"7.6120","B":"50","a":"7.6130","A":"19","T":1626992753510,"E":1626992753515}}
1626992753.62983: {"stream":"ctkusdt@depth@100ms","data":{"e":"depthUpdate","E":1626992753586,"T":1626992753481,"s":"CTKUSDT","U":600859845920,"u":600859845920,"pu":600859833536,"b":[],"a":[["1.02400","6937"]]}}
1626992753.629961: {"stream":"akrousdt@depth@100ms","data":{"e":"depthUpdate","E":1626992753586,"T":1626992753513,"s":"AKROUSDT","U":600859845937,"u":600859847025,"pu":600859843335,"b":[["0.01699","208875"]],"a":[["0.01745","230372"]]}}
1626992753.6503491: {"stream":"ctkusdt@kline_1m","data":{"e":"kline","E":1626992753605,"s":"CTKUSDT","k":{"t":1626992700000,"T":1626992759999,"s":"CTKUSDT","i":"1m","f":23961275,"L":23961341,"o":"1.01000","c":"1.01100","h":"1.01100","l":"1.01000","v":"6272","n":67,"x":false,"q":"6338.63800","V":"3918","Q":"3961.09800","B":"0"}}}
1626992753.650431: {"stream":"ctkusdt@bookTicker","data":{"e":"bookTicker","u":600859849394,"s":"CTKUSDT","b":"1.01000","B":"85601","a":"1.01100","A":"5510","T":1626992753602,"E":1626992753605}}
1626992753.650464: {"stream":"sushiusdt@depth@100ms","data":{"e":"depthUpdate","E":1626992753607,"T":1626992753598,"s":"SUSHIUSDT","U":600859846602,"u":600859849324,"pu":600859846092,"b":[["7.5600","809"],["7.5840","1680"],["7.5910","4719"],["7.5930","4875"],["7.5950","2182"],["7.6000","2489"],["7.6010","1150"],["7.6020","2669"],["7.6030","870"],["7.6040","1560"],["7.6050","1577"],["7.6070","538"],["7.6090","173"],["7.6100","0"],["7.6120","50"]],"a":[["7.6140","87"],["7.6150","133"],["7.6160","605"],["7.6170","1430"],["7.6180","2358"],["7.6200","163"],["7.6220","1983"],["7.6260","1024"],["7.6280","2967"],["7.6330","3085"],["7.6440","4856"],["7.6800","374"],["7.7770","334"]]}}
1626992753.717689: {"stream":"akrousdt@kline_1m","data":{"e":"kline","E":1626992753672,"s":"AKROUSDT","k":{"t":1626992700000,"T":1626992759999,"s":"AKROUSDT","i":"1m","f":27931328,"L":27931351,"o":"0.01731","c":"0.01731","h":"0.01733","l":"0.01731","v":"158992","n":24,"x":false,"q":"2752.99524","V":"68508","Q":"1186.71720","B":"0"}}}
1626992753.7198641: {"stream":"akrousdt@bookTicker","data":{"e":"bookTicker","u":600859850925,"s":"AKROUSDT","b":"0.01731","B":"5174","a":"0.01732","A":"74607","T":1626992753668,"E":1626992753673}}
1626992753.7496939: {"stream":"ctkusdt@depth@100ms","data":{"e":"depthUpdate","E":1626992753705,"T":1626992753686,"s":"CTKUSDT","U":600859849390,"u":600859851298,"pu":600859845920,"b":[["1.01400","0"]],"a":[["1.01100","5510"],["1.01300","17158"],["1.01400","11123"],["1.01500","16352"],["1.01600","19516"]]}}
1626992753.7548878: {"stream":"sushiusdt@depth@100ms","data":{"e":"depthUpdate","E":1626992753710,"T":1626992753652,"s":"SUSHIUSDT","U":600859849458,"u":600859850602,"pu":600859849324,"b":[["7.5300","5354"],["7.5600","2370"],["7.5610","1412"],["7.6050","1449"],["7.6060","1172"],["7.6100","40"]],"a":[["7.6140","57"],["7.6160","595"],["7.6170","2150"],["7.6580","189"],["7.6920","1485"],["7.7100","4439"],["7.7920","304"]]}}
1626992753.800748: {"stream":"ctkusdt@aggTrade","data":{"e":"aggTrade","E":1626992753756,"a":16599306,"s":"CTKUSDT","p":"1.01100","q":"10","f":23961341,"l":23961341,"T":1626992753602,"m":false}}
1626992753.8190038: {"stream":"akrousdt@depth@100ms","data":{"e":"depthUpdate","E":1626992753773,"T":1626992753668,"s":"AKROUSDT","U":600859850921,"u":600859850925,"pu":600859847025,"b":[["0.01731","5174"]],"a":[["0.01731","0"]]}}
1626992753.852133: {"stream":"sushiusdt@depth@100ms","data":{"e":"depthUpdate","E":1626992753810,"T":1626992753805,"s":"SUSHIUSDT","U":600859851673,"u":600859853577,"pu":600859850602,"b":[["7.4450","645"],["7.5300","2353"],["7.5600","3870"],["7.5760","3120"],["7.5830","4474"],["7.5840","3181"],["7.5870","659"],["7.5950","2162"],["7.6000","819"],["7.6030","619"],["7.6040","3141"]],"a":[["7.6150","183"],["7.6160","545"],["7.6170","1360"],["7.6180","2308"],["7.6200","953"],["7.6210","1410"],["7.6260","1044"],["7.6330","3046"],["7.6440","6325"],["7.6480","2104"],["7.6500","590"],["7.6660","597"],["7.6800","3343"],["7.6920","16"],["7.7100","1470"]]}}
1626992753.868094: {"stream":"akrousdt@aggTrade","data":{"e":"aggTrade","E":1626992753824,"a":14888304,"s":"AKROUSDT","p":"0.01731","q":"290","f":27931351,"l":27931351,"T":1626992753668,"m":true}}
1626992753.895724: {"stream":"ctkusdt@depth@100ms","data":{"e":"depthUpdate","E":1626992753833,"T":1626992753805,"s":"CTKUSDT","U":600859852111,"u":600859853588,"pu":600859851298,"b":[],"a":[["1.01400","10877"],["1.01500","16352"]]}}
1626992753.901691: {"stream":"sushiusdt@bookTicker","data":{"e":"bookTicker","u":600859854523,"s":"SUSHIUSDT","b":"7.6120","B":"55","a":"7.6130","A":"19","T":1626992753854,"E":1626992753858}}
1626992753.920697: {"stream":"akrousdt@depth@100ms","data":{"e":"depthUpdate","E":1626992753876,"T":1626992753855,"s":"AKROUSDT","U":600859852952,"u":600859854563,"pu":600859850925,"b":[["0.01703","168768"],["0.01722","472874"],["0.01723","366230"]],"a":[["0.01736","917770"]]}}
1626992753.958688: {"stream":"sushiusdt@depth@100ms","data":{"e":"depthUpdate","E":1626992753910,"T":1626992753897,"s":"SUSHIUSDT","U":600859853609,"u":600859855317,"pu":600859853577,"b":[["7.5790","1183"],["7.6000","1151"],["7.6010","1170"],["7.6020","2787"],["7.6090","173"],["7.6120","55"]],"a":[["7.6150","133"],["7.6170","1520"],["7.6290","7054"],["7.6470","3053"],["8.0990","542"]]}}
1626992753.9886699: {"stream":"ctkusdt@depth@100ms","data":{"e":"depthUpdate","E":1626992753942,"T":1626992753895,"s":"CTKUSDT","U":600859854203,"u":600859855256,"pu":600859853588,"b":[["1.00200","16339"],["1.00600","9269"]],"a":[["1.01500","16352"],["1.01800","7790"]]}}
1626992753.990973: {"stream":"ctkusdt@bookTicker","data":{"e":"bookTicker","u":600859856282,"s":"CTKUSDT","b":"1.01000","B":"85601","a":"1.01100","A":"6301","T":1626992753940,"E":1626992753944}}
1626992754.056582: {"stream":"sushiusdt@depth@100ms","data":{"e":"depthUpdate","E":1626992754012,"T":1626992754002,"s":"SUSHIUSDT","U":600859855468,"u":600859857903,"pu":600859855317,"b":[["7.4190","329"],["7.5490","205"]],"a":[["7.6210","1360"],["7.6240","3317"],["7.6270","1387"],["7.6310","3272"],["7.6630","383"],["7.7990","688"]]}}
1626992754.088537: {"stream":"ctkusdt@depth@100ms","data":{"e":"depthUpdate","E":1626992754044,"T":1626992753995,"s":"CTKUSDT","U":600859856282,"u":600859857711,"pu":600859855256,"b":[["1.00600","9269"],["1.00900","14571"]],"a":[["1.01100","6301"]]}}
1626992754.140904: {"stream":"akrousdt@depth@100ms","data":{"e":"depthUpdate","E":1626992754096,"T":1626992754053,"s":"AKROUSDT","U":600859857660,"u":600859859625,"pu":600859854563,"b":[["0.01720","502996"],["0.01725","882349"]],"a":[["0.01736","914045"],["0.01739","927008"]]}}
1626992754.159538: {"stream":"sushiusdt@depth@100ms","data":{"e":"depthUpdate","E":1626992754114,"T":1626992754087,"s":"SUSHIUSDT","U":600859858106,"u":600859860027,"pu":600859857903,"b":[["7.4170","209"],["7.5580","848"],["7.5720","4278"],["7.5760","3207"],["7.5800","3040"]],"a":[["7.6150","136"],["7.6160","1358"],["7.6170","1360"],["7.6200","1003"],["7.6210","1749"],["7.6220","2075"],["7.6230","2356"],["7.6240","3581"],["7.6250","581"],["7.6280","2653"],["7.6700","514"]]}}
1626992754.192634: {"stream":"ctkusdt@depth@100ms","data":{"e":"depthUpdate","E":1626992754148,"T":1626992754113,"s":"CTKUSDT","U":600859859348,"u":600859860578,"pu":600859857711,"b":[["1.00600","9269"]],"a":[["1.01500","16352"]]}}
1626992754.2776551: {"stream":"sushiusdt@depth@100ms","data":{"e":"depthUpdate","E":1626992754233,"T":1626992754182,"s":"SUSHIUSDT","U":600859860719,"u":600859862561,"pu":600859860027,"b":[["7.5590","6978"],["7.5810","328"],["7.6020","3183"],["7.6090","251"]],"a":[["7.6180","2622"],["7.6210","1749"],["7.6240","3267"],["7.6270","1527"],["7.6930","11022"]]}}
1626992754.296882: {"stream":"akrousdt@depth@100ms","data":{"e":"depthUpdate","E":1626992754251,"T":1626992754151,"s":"AKROUSDT","U":600859861455,"u":600859861719,"pu":600859859625,"b":[],"a":[["0.01736","906594"],["0.01738","1160316"]]}}
1626992754.298054: {"stream":"keepusdt@depth@100ms","data":{"e":"depthUpdate","E":1626992754253,"T":1626992754236,"s":"KEEPUSDT","U":600859861572,"u":600859863888,"pu":600859837116,"b":[["0.2433","33338"]],"a":[["0.2465","812"]]}}
1626992754.308588: {"stream":"ctkusdt@depth@100ms","data":{"e":"depthUpdate","E":1626992754265,"T":1626992754212,"s":"CTKUSDT","U":600859861959,"u":600859863326,"pu":600859860578,"b":[],"a":[["1.01500","16352"],["1.01600","19762"]]}}
1626992754.385442: {"stream":"sushiusdt@depth@100ms","data":{"e":"depthUpdate","E":1626992754340,"T":1626992754334,"s":"SUSHIUSDT","U":600859863884,"u":600859866135,"pu":600859862561,"b":[["7.4280","319"],["7.5910","2954"],["7.6000","1339"]],"a":[["7.6170","2150"],["7.6200","213"],["7.6210","1811"],["7.6230","3337"],["7.6240","2286"],["7.6330","1281"]]}}
1626992754.418682: {"stream":"keepusdt@depth@100ms","data":{"e":"depthUpdate","E":1626992754374,"T":1626992754268,"s":"KEEPUSDT","U":600859864578,"u":600859864578,"pu":600859863888,"b":[["0.2429","23021"]],"a":[]}}
1626992754.427542: {"stream":"akrousdt@depth@100ms","data":{"e":"depthUpdate","E":1626992754381,"T":1626992754370,"s":"AKROUSDT","U":600859864767,"u":600859867032,"pu":600859861719,"b":[["0.01724","636702"],["0.01726","586139"]],"a":[["0.01739","934152"],["0.01740","257404"]]}}
1626992754.48112: {"stream":"ctkusdt@bookTicker","data":{"e":"bookTicker","u":600859868424,"s":"CTKUSDT","b":"1.01000","B":"83601","a":"1.01100","A":"6301","T":1626992754430,"E":1626992754435}}
1626992754.49246: {"stream":"sushiusdt@depth@100ms","data":{"e":"depthUpdate","E":1626992754446,"T":1626992754434,"s":"SUSHIUSDT","U":600859866300,"u":600859868491,"pu":600859866135,"b":[["7.4260","324"],["7.5920","3396"],["7.6090","166"]],"a":[["7.6180","2308"],["7.6200","527"],["7.6210","1497"],["7.6230","3651"],["7.6240","3296"],["7.6280","1835"],["7.6320","2011"]]}}
1626992754.541638: {"stream":"akrousdt@depth@100ms","data":{"e":"depthUpdate","E":1626992754498,"T":1626992754418,"s":"AKROUSDT","U":600859867553,"u":600859868145,"pu":600859867032,"b":[],"a":[["0.01735","311195"],["0.01738","1168855"],["0.01740","248784"],["0.01760","126984"]]}}
1626992754.5441139: {"stream":"sushiusdt@bookTicker","data":{"e":"bookTicker","u":600859869580,"s":"SUSHIUSDT","b":"7.6120","B":"56","a":"7.6130","A":"19","T":1626992754494,"E":1626992754500}}
1626992754.563265: {"stream":"ctkusdt@depth@100ms","data":{"e":"depthUpdate","E":1626992754519,"T":1626992754484,"s":"CTKUSDT","U":600859868046,"u":600859869464,"pu":600859863326,"b":[["1.01000","83601"]],"a":[["1.01300","18262"],["1.01400","9747"]]}}
1626992754.627507: {"stream":"sushiusdt@depth@100ms","data":{"e":"depthUpdate","E":1626992754583,"T":1626992754564,"s":"SUSHIUSDT","U":600859869326,"u":600859870961,"pu":600859868491,"b":[["7.6020","3168"],["7.6040","3176"],["7.6090","173"],["7.6100","145"],["7.6120","56"]],"a":[["7.6170","1360"],["7.6200","477"],["7.6210","2287"],["7.6230","3701"]]}}
1626992754.643615: {"stream":"keepusdt@depth@100ms","data":{"e":"depthUpdate","E":1626992754600,"T":1626992754584,"s":"KEEPUSDT","U":600859869575,"u":600859871364,"pu":600859864578,"b":[["0.2429","23021"],["0.2442","10218"],["0.2444","3442"]],"a":[["0.2465","812"]]}}
1626992754.685847: {"stream":"akrousdt@depth@100ms","data":{"e":"depthUpdate","E":1626992754639,"T":1626992754624,"s":"AKROUSDT","U":600859870397,"u":600859872208,"pu":600859868145,"b":[],"a":[["0.01736","966014"],["0.01743","335621"]]}}
1626992754.703252: {"stream":"ctkusdt@depth@100ms","data":{"e":"depthUpdate","E":1626992754660,"T":1626992754559,"s":"CTKUSDT","U":600859870795,"u":600859870867,"pu":600859869464,"b":[],"a":[["1.02200","4060"],["1.31400","2472"]]}}
1626992754.741696: {"stream":"sushiusdt@depth@100ms","data":{"e":"depthUpdate","E":1626992754698,"T":1626992754675,"s":"SUSHIUSDT","U":600859871544,"u":600859873241,"pu":600859870961,"b":[["7.5390","5467"],["7.5600","3810"],["7.5610","1472"],["7.6040","3314"],["7.6060","1304"]],"a":[["7.6200","527"],["7.6230","3500"]]}}
1626992754.795022: {"stream":"ctkusdt@bookTicker","data":{"e":"bookTicker","u":600859874714,"s":"CTKUSDT","b":"1.01000","B":"83389","a":"1.01100","A":"6301","T":1626992754747,"E":1626992754750}}
1626992754.814131: {"stream":"ctkusdt@bookTicker","data":{"e":"bookTicker","u":600859875046,"s":"CTKUSDT","b":"1.01000","B":"83637","a":"1.01100","A":"6301","T":1626992754765,"E":1626992754769}}
1626992754.835736: {"stream":"ctkusdt@kline_1m","data":{"e":"kline","E":1626992754790,"s":"CTKUSDT","k":{"t":1626992700000,"T":1626992759999,"s":"CTKUSDT","i":"1m","f":23961275,"L":23961342,"o":"1.01000","c":"1.01100","h":"1.01100","l":"1.01000","v":"6282","n":68,"x":false,"q":"6348.74800","V":"3928","Q":"3971.20800","B":"0"}}}
1626992754.835853: {"stream":"ctkusdt@bookTicker","data":{"e":"bookTicker","u":600859875535,"s":"CTKUSDT","b":"1.01000","B":"83637","a":"1.01100","A":"6291","T":1626992754785,"E":1626992754789}}
1626992754.897042: {"stream":"ctkusdt@depth@100ms","data":{"e":"depthUpdate","E":1626992754850,"T":1626992754785,"s":"CTKUSDT","U":600859874714,"u":600859875535,"pu":600859870867,"b":[["1.01000","83637"],["1.01400","0"]],"a":[["1.01100","6291"]]}}
1626992754.966878: {"stream":"sushiusdt@depth@100ms","data":{"e":"depthUpdate","E":1626992754921,"T":1626992754903,"s":"SUSHIUSDT","U":600859876240,"u":600859877822,"pu":600859873241,"b":[["7.5840","3126"],["7.5880","2152"],["7.6090","173"]],"a":[["7.6160","1436"]]}}
1626992754.984878: {"stream":"ctkusdt@aggTrade","data":{"e":"aggTrade","E":1626992754940,"a":16599307,"s":"CTKUSDT","p":"1.01100","q":"10","f":23961342,"l":23961342,"T":1626992754785,"m":false}}
1626992755.0220869: {"stream":"ctkusdt@depth@100ms","data":{"e":"depthUpdate","E":1626992754976,"T":1626992754869,"s":"CTKUSDT","U":600859877278,"u":600859877278,"pu":600859875535,"b":[],"a":[["1.03300","6008"]]}}
1626992755.070276: {"stream":"akrousdt@depth@100ms","data":{"e":"depthUpdate","E":1626992755026,"T":1626992754976,"s":"AKROUSDT","U":600859878155,"u":600859879127,"pu":600859872208,"b":[["0.01722","449762"],["0.01723","389243"],["0.01725","893377"]],"a":[]}}
1626992755.122006: {"stream":"sushiusdt@depth@100ms","data":{"e":"depthUpdate","E":1626992755076,"T":1626992755062,"s":"SUSHIUSDT","U":600859879014,"u":600859880852,"pu":600859877822,"b":[],"a":[["7.6200","213"],["7.6230","3500"],["7.6260","1358"],["7.6420","2005"]]}}
1626992755.2363079: {"stream":"sushiusdt@depth@100ms","data":{"e":"depthUpdate","E":1626992755191,"T":1626992755185,"s":"SUSHIUSDT","U":600859881242,"u":600859883258,"pu":600859880852,"b":[["7.5430","4256"],["7.5450","1849"],["7.5900","1763"],["7.5960","1305"],["7.5990","3834"],["7.6090","166"]],"a":[["7.6150","186"],["7.6160","1111"],["7.6230","3186"],["7.6250","895"],["7.6260","1044"],["7.6280","2149"],["7.6360","2576"],["7.6460","430"],["7.6790","2"],["7.6810","3110"]]}}
1626992755.307185: {"stream":"akrousdt@depth@100ms","data":{"e":"depthUpdate","E":1626992755263,"T":1626992755208,"s":"AKROUSDT","U":600859882325,"u":600859883858,"pu":600859879127,"b":[["0.01714","1490559"],["0.01717","2895154"],["0.01723","400859"]],"a":[["0.01737","507257"]]}}
1626992755.341186: {"stream":"ctkusdt@bookTicker","data":{"e":"bookTicker","u":600859885532,"s":"CTKUSDT","b":"1.01000","B":"83637","a":"1.01100","A":"5970","T":1626992755291,"E":1626992755295}}
1626992755.341283: {"stream":"ctkusdt@kline_1m","data":{"e":"kline","E":1626992755296,"s":"CTKUSDT","k":{"t":1626992700000,"T":1626992759999,"s":"CTKUSDT","i":"1m","f":23961275,"L":23961343,"o":"1.01000","c":"1.01100","h":"1.01100","l":"1.01000","v":"6603","n":69,"x":false,"q":"6673.27900","V":"4249","Q":"4295.73900","B":"0"}}}
1626992755.346445: {"stream":"sushiusdt@depth@100ms","data":{"e":"depthUpdate","E":1626992755301,"T":1626992755293,"s":"SUSHIUSDT","U":600859883540,"u":600859885574,"pu":600859883258,"b":[["7.5400","861"],["7.5910","2502"],["7.6090","173"]],"a":[["7.6200","1003"],["7.6210","1497"]]}}
1626992755.411707: {"stream":"keepusdt@bookTicker","data":{"e":"bookTicker","u":600859886824,"s":"KEEPUSDT","b":"0.2459","B":"1490","a":"0.2464","A":"317","T":1626992755361,"E":1626992755366}}
1626992755.419465: {"stream":"keepusdt@bookTicker","data":{"e":"bookTicker","u":600859886959,"s":"KEEPUSDT","b":"0.2463","B":"3214","a":"0.2464","A":"317","T":1626992755369,"E":1626992755374}}
1626992755.423776: {"stream":"sushiusdt@bookTicker","data":{"e":"bookTicker","u":600859887049,"s":"SUSHIUSDT","b":"7.6120","B":"51","a":"7.6130","A":"19","T":1626992755374,"E":1626992755378}}
1626992755.424299: {"stream":"ctkusdt@depth@100ms","data":{"e":"depthUpdate","E":1626992755381,"T":1626992755291,"s":"CTKUSDT","U":600859885206,"u":600859885532,"pu":600859877278,"b":[["1.00300","5915"]],"a":[["1.01100","5970"]]}}
1626992755.43519: {"stream":"sushiusdt@bookTicker","data":{"e":"bookTicker","u":600859887278,"s":"SUSHIUSDT","b":"7.6120","B":"58","a":"7.6130","A":"19","T":1626992755386,"E":1626992755390}}
1626992755.473165: {"stream":"sushiusdt@depth@100ms","data":{"e":"depthUpdate","E":1626992755424,"T":1626992755401,"s":"SUSHIUSDT","U":600859886038,"u":600859887557,"pu":600859885574,"b":[["7.5010","5"],["7.6050","1159"],["7.6120","58"]],"a":[["7.6150","183"],["7.6580","176"]]}}
1626992755.490579: {"stream":"ctkusdt@aggTrade","data":{"e":"aggTrade","E":1626992755446,"a":16599308,"s":"CTKUSDT","p":"1.01100","q":"321","f":23961343,"l":23961343,"T":1626992755291,"m":false}}
1626992755.511513: {"stream":"keepusdt@depth@100ms","data":{"e":"depthUpdate","E":1626992755466,"T":1626992755455,"s":"KEEPUSDT","U":600859886824,"u":600859888727,"pu":600859871364,"b":[["0.2448","7489"],["0.2449","24940"],["0.2456","21760"],["0.2457","11820"],["0.2463","3214"]],"a":[["0.2465","812"]]}}
1626992755.536714: {"stream":"akrousdt@bookTicker","data":{"e":"bookTicker","u":600859889628,"s":"AKROUSDT","b":"0.01730","B":"187887","a":"0.01732","A":"74607","T":1626992755487,"E":1626992755491}}
1626992755.5538502: {"stream":"akrousdt@bookTicker","data":{"e":"bookTicker","u":600859890142,"s":"AKROUSDT","b":"0.01730","B":"174018","a":"0.01732","A":"74607","T":1626992755505,"E":1626992755509}}
1626992755.556158: {"stream":"akrousdt@bookTicker","data":{"e":"bookTicker","u":600859890202,"s":"AKROUSDT","b":"0.01731","B":"13753","a":"0.01732","A":"74607","T":1626992755507,"E":1626992755511}}
1626992755.570105: {"stream":"akrousdt@depth@100ms","data":{"e":"depthUpdate","E":1626992755524,"T":1626992755516,"s":"AKROUSDT","U":600859887887,"u":600859890422,"pu":600859883858,"b":[["0.01715","565562"],["0.01726","516930"],["0.01727","1170587"],["0.01729","765724"],["0.01730","174018"],["0.01731","13753"]],"a":[["0.01736","910014"],["0.01737","455346"],["0.01738","1220269"]]}}
1626992755.580056: {"stream":"sushiusdt@depth@100ms","data":{"e":"depthUpdate","E":1626992755535,"T":1626992755491,"s":"SUSHIUSDT","U":600859888159,"u":600859889718,"pu":600859887557,"b":[["7.6050","1287"],["7.6060","1176"],["7.6090","173"]],"a":[["7.6660","610"]]}}
1626992755.641765: {"stream":"keepusdt@depth@100ms","data":{"e":"depthUpdate","E":1626992755598,"T":1626992755496,"s":"KEEPUSDT","U":600859889746,"u":600859889897,"pu":600859888727,"b":[["0.2456","17662"],["0.2457","15918"]],"a":[]}}
1626992755.651739: {"stream":"sushiusdt@bookTicker","data":{"e":"bookTicker","u":600859892654,"s":"SUSHIUSDT","b":"7.6120","B":"50","a":"7.6130","A":"19","T":1626992755601,"E":1626992755606}}
1626992755.651838: {"stream":"akrousdt@bookTicker","data":{"e":"bookTicker","u":600859892674,"s":"AKROUSDT","b":"0.01731","B":"23515","a":"0.01732","A":"74607","T":1626992755602,"E":1626992755606}}
1626992755.651884: {"stream":"sushiusdt@kline_1m","data":{"e":"kline","E":1626992755607,"s":"SUSHIUSDT","k":{"t":1626992700000,"T":1626992759999,"s":"SUSHIUSDT","i":"1m","f":126902874,"L":126902959,"o":"7.6080","c":"7.6120","h":"7.6160","l":"7.6070","v":"2531","n":86,"x":false,"q":"19266.2790","V":"1502","Q":"11433.7730","B":"0"}}}
1626992755.668263: {"stream":"akrousdt@depth@100ms","data":{"e":"depthUpdate","E":1626992755625,"T":1626992755602,"s":"AKROUSDT","U":600859890554,"u":600859892674,"pu":600859890422,"b":[["0.01713","6075"],["0.01717","2902142"],["0.01726","499549"],["0.01728","852503"],["0.01729","736848"],["0.01731","23515"]],"a":[]}}
1626992755.690343: {"stream":"sushiusdt@bookTicker","data":{"e":"bookTicker","u":600859893656,"s":"SUSHIUSDT","b":"7.6120","B":"58","a":"7.6130","A":"19","T":1626992755639,"E":1626992755644}}
1626992755.7237818: {"stream":"ctkusdt@depth@100ms","data":{"e":"depthUpdate","E":1626992755679,"T":1626992755635,"s":"CTKUSDT","U":600859892081,"u":600859893560,"pu":600859885532,"b":[["0.99000","22831"],["1.00600","14217"]],"a":[["1.01500","21202"],["1.04100","2569"]]}}
1626992755.726349: {"stream":"sushiusdt@depth@100ms","data":{"e":"depthUpdate","E":1626992755681,"T":1626992755646,"s":"SUSHIUSDT","U":600859892111,"u":600859893809,"pu":600859889718,"b":[["7.5300","5354"],["7.5600","2310"],["7.5830","4499"],["7.5840","1625"],["7.5880","2070"],["7.5950","2182"],["7.6010","1150"],["7.6040","4182"],["7.6120","58"]],"a":[["7.6210","1477"],["7.6260","1024"],["7.6330","1301"],["7.6440","4856"],["7.6800","374"],["7.6920","1485"],["7.7100","4439"]]}}
1626992755.751507: {"stream":"ctkusdt@bookTicker","data":{"e":"bookTicker","u":600859895110,"s":"CTKUSDT","b":"1.01000","B":"83637","a":"1.01100","A":"5569","T":1626992755704,"E":1626992755707}}
1626992755.7545679: {"stream":"sushiusdt@bookTicker","data":{"e":"bookTicker","u":600859895147,"s":"SUSHIUSDT","b":"7.6120","B":"74","a":"7.6130","A":"19","T":1626992755705,"E":1626992755709}}
1626992755.802478: {"stream":"sushiusdt@aggTrade","data":{"e":"aggTrade","E":1626992755757,"a":87353244,"s":"SUSHIUSDT","p":"7.6120","q":"8","f":126902959,"l":126902959,"T":1626992755601,"m":true}}
1626992755.8252969: {"stream":"ctkusdt@depth@100ms","data":{"e":"depthUpdate","E":1626992755781,"T":1626992755704,"s":"CTKUSDT","U":600859894523,"u":600859895110,"pu":600859893560,"b":[["1.00600","9269"]],"a":[["1.01100","5569"],["1.01500","16254"],["1.01700","10637"]]}}
1626992755.838319: {"stream":"sushiusdt@depth@100ms","data":{"e":"depthUpdate","E":1626992755793,"T":1626992755785,"s":"SUSHIUSDT","U":600859894833,"u":600859897227,"pu":600859893809,"b":[["7.5600","2370"],["7.5610","1412"],["7.5760","1741"],["7.5870","1227"],["7.5910","2584"],["7.6090","173"],["7.6120","74"]],"a":[["7.6190","1156"],["7.6210","1490"],["7.6240","2286"],["7.6260","1044"],["7.6380","938"],["7.6420","2113"],["7.6480","604"],["7.6490","12226"],["7.6550","1180"],["7.6830","1332"],["7.7970","16"]]}}
1626992755.875969: {"stream":"akrousdt@depth@100ms","data":{"e":"depthUpdate","E":1626992755830,"T":1626992755821,"s":"AKROUSDT","U":600859895648,"u":600859898061,"pu":600859892674,"b":[["0.01717","2931262"]],"a":[["0.01735","291209"],["0.01736","889863"],["0.01737","475485"],["0.01739","887028"],["0.01740","295825"],["0.01746","102752"]]}}
1626992755.943135: {"stream":"sushiusdt@depth@100ms","data":{"e":"depthUpdate","E":1626992755898,"T":1626992755882,"s":"SUSHIUSDT","U":600859897424,"u":600859899561,"pu":600859897227,"b":[["3.8080","4"],["7.5300","2353"],["7.5600","869"],["7.5890","1109"],["7.5920","3436"],["7.5940","682"],["7.5950","2162"],["7.5960","1355"],["7.6020","3108"],["7.6040","4141"],["7.6050","1307"]],"a":[["7.6170","1341"],["7.6180","2132"],["7.6190","1170"],["7.6210","1640"],["7.6260","2356"],["7.6330","1281"],["7.6380","885"],["7.6920","16"],["7.7100","1470"],["7.7930","114"]]}}
1626992755.961775: {"stream":"ctkusdt@bookTicker","data":{"e":"bookTicker","u":600859900268,"s":"CTKUSDT","b":"1.01000","B":"83637","a":"1.01100","A":"5970","T":1626992755912,"E":1626992755916}}
1626992755.961877: {"stream":"ctkusdt@depth@100ms","data":{"e":"depthUpdate","E":1626992755917,"T":1626992755912,"s":"CTKUSDT","U":600859897843,"u":600859900268,"pu":600859895110,"b":[],"a":[["1.01100","5970"],["1.01900","1606"],["1.04100","4776"]]}}
1626992755.96752: {"stream":"sushiusdt@bookTicker","data":{"e":"bookTicker","u":600859900390,"s":"SUSHIUSDT","b":"7.6120","B":"74","a":"7.6140","A":"31","T":1626992755917,"E":1626992755921}}
1626992755.9697769: {"stream":"sushiusdt@bookTicker","data":{"e":"bookTicker","u":600859900470,"s":"SUSHIUSDT","b":"7.6120","B":"74","a":"7.6150","A":"136","T":1626992755921,"E":1626992755925}}
1626992755.9698749: {"stream":"sushiusdt@bookTicker","data":{"e":"bookTicker","u":600859900481,"s":"SUSHIUSDT","b":"7.6120","B":"74","a":"7.6150","A":"167","T":1626992755921,"E":1626992755925}}
1626992755.977207: {"stream":"akrousdt@depth@100ms","data":{"e":"depthUpdate","E":1626992755933,"T":1626992755894,"s":"AKROUSDT","U":600859898187,"u":600859899818,"pu":600859898061,"b":[],"a":[["0.01736","898306"],["0.01750","1499699"]]}}
1626992755.9932868: {"stream":"sushiusdt@bookTicker","data":{"e":"bookTicker","u":600859900970,"s":"SUSHIUSDT","b":"7.6120","B":"74","a":"7.6150","A":"135","T":1626992755943,"E":1626992755948}}
1626992755.993385: {"stream":"sushiusdt@bookTicker","data":{"e":"bookTicker","u":600859900975,"s":"SUSHIUSDT","b":"7.6120","B":"74","a":"7.6150","A":"103","T":1626992755943,"E":1626992755948}}
1626992756.011261: {"stream":"sushiusdt@bookTicker","data":{"e":"bookTicker","u":600859901411,"s":"SUSHIUSDT","b":"7.6120","B":"74","a":"7.6150","A":"80","T":1626992755961,"E":1626992755966}}
1626992756.0167859: {"stream":"ctkusdt@kline_1m","data":{"e":"kline","E":1626992755971,"s":"CTKUSDT","k":{"t":1626992700000,"T":1626992759999,"s":"CTKUSDT","i":"1m","f":23961275,"L":23961344,"o":"1.01000","c":"1.01100","h":"1.01100","l":"1.01000","v":"6613","n":70,"x":false,"q":"6683.38900","V":"4259","Q":"4305.84900","B":"0"}}}
1626992756.0169091: {"stream":"ctkusdt@bookTicker","data":{"e":"bookTicker","u":600859901546,"s":"CTKUSDT","b":"1.01000","B":"83637","a":"1.01100","A":"5960","T":1626992755967,"E":1626992755972}}
1626992756.044523: {"stream":"sushiusdt@depth@100ms","data":{"e":"depthUpdate","E":1626992755998,"T":1626992755992,"s":"SUSHIUSDT","U":600859899783,"u":600859902127,"pu":600859899561,"b":[["7.5610","1343"],["7.5890","1079"],["7.5930","4905"],["7.6000","682"],["7.6010","930"],["7.6020","2910"],["7.6030","523"],["7.6040","3019"],["7.6050","2100"],["7.6060","1526"],["7.6070","538"],["7.6090","135"],["7.6110","31"]],"a":[["7.6130","0"],["7.6140","0"],["7.6150","80"],["7.6160","513"],["7.6170","1192"],["7.6180","1094"],["7.6190","1123"],["7.6200","2583"],["7.6220","1539"],["7.6230","3165"],["7.6240","2952"],["7.6290","3873"],["7.6400","720"],["7.6470","2936"],["7.6490","12172"]]}}
1626992756.057259: {"stream":"keepusdt@depth@100ms","data":{"e":"depthUpdate","E":1626992756012,"T":1626992755994,"s":"KEEPUSDT","U":600859900172,"u":600859902177,"pu":600859889897,"b":[["0.2444","2623"]],"a":[["0.2465","812"]]}}
1626992756.068036: {"stream":"sushiusdt@bookTicker","data":{"e":"bookTicker","u":600859902899,"s":"SUSHIUSDT","b":"7.6120","B":"73","a":"7.6150","A":"80","T":1626992756020,"E":1626992756023}}
1626992756.077539: {"stream":"sushiusdt@bookTicker","data":{"e":"bookTicker","u":600859903094,"s":"SUSHIUSDT","b":"7.6130","B":"1","a":"7.6150","A":"80","T":1626992756028,"E":1626992756034}}
1626992756.090324: {"stream":"akrousdt@depth@100ms","data":{"e":"depthUpdate","E":1626992756046,"T":1626992756019,"s":"AKROUSDT","U":600859900935,"u":600859902862,"pu":600859899818,"b":[["0.01722","425488"],["0.01728","869864"]],"a":[["0.01744","165911"]]}}
1626992756.115977: {"stream":"ctkusdt@depth@100ms","data":{"e":"depthUpdate","E":1626992756072,"T":1626992755996,"s":"CTKUSDT","U":600859901542,"u":600859902210,"pu":600859900268,"b":[["1.01400","0"]],"a":[["1.01100","5960"],["1.02200","4353"]]}}
1626992756.144258: {"stream":"sushiusdt@depth@100ms","data":{"e":"depthUpdate","E":1626992756099,"T":1626992756090,"s":"SUSHIUSDT","U":600859902141,"u":600859904211,"pu":600859902127,"b":[["3.8070","26"],["7.1760","12"],["7.5600","3870"],["7.5840","3126"],["7.5980","531"],["7.6000","782"],["7.6010","950"],["7.6020","3284"],["7.6040","3119"],["7.6050","1104"],["7.6060","2420"],["7.6070","666"],["7.6090","142"],["7.6120","73"],["7.6130","1"]],"a":[["7.6160","611"],["7.6170","1170"],["7.6190","1663"],["7.6200","267"],["7.6260","2291"],["7.6310","3085"],["7.6340","1408"],["7.6400","608"],["7.6440","6437"],["7.6630","213"],["7.6800","3343"],["7.7920","303"]]}}
1626992756.165359: {"stream":"keepusdt@depth@100ms","data":{"e":"depthUpdate","E":1626992756121,"T":1626992756016,"s":"KEEPUSDT","U":600859902525,"u":600859902738,"pu":600859902177,"b":[],"a":[["0.2476","2326"],["0.2482","160"],["0.2499","36239"]]}}
1626992756.167448: {"stream":"ctkusdt@aggTrade","data":{"e":"aggTrade","E":1626992756123,"a":16599309,"s":"CTKUSDT","p":"1.01100","q":"10","f":23961344,"l":23961344,"T":1626992755967,"m":false}}
1626992756.184599: {"stream":"sushiusdt@bookTicker","data":{"e":"bookTicker","u":600859905222,"s":"SUSHIUSDT","b":"7.6140","B":"1","a":"7.6150","A":"80","T":1626992756136,"E":1626992756139}}
1626992756.194606: {"stream":"sushiusdt@bookTicker","data":{"e":"bookTicker","u":600859905574,"s":"SUSHIUSDT","b":"7.6140","B":"1","a":"7.6150","A":"110","T":1626992756143,"E":1626992756149}}
1626992756.194977: {"stream":"sushiusdt@bookTicker","data":{"e":"bookTicker","u":600859905836,"s":"SUSHIUSDT","b":"7.6140","B":"1","a":"7.6150","A":"130","T":1626992756146,"E":1626992756151}}
1626992756.20304: {"stream":"sushiusdt@bookTicker","data":{"e":"bookTicker","u":600859906177,"s":"SUSHIUSDT","b":"7.6140","B":"1","a":"7.6150","A":"127","T":1626992756154,"E":1626992756159}}
1626992756.2467892: {"stream":"sushiusdt@kline_1m","data":{"e":"kline","E":1626992756201,"s":"SUSHIUSDT","k":{"t":1626992700000,"T":1626992759999,"s":"SUSHIUSDT","i":"1m","f":126902874,"L":126902960,"o":"7.6080","c":"7.6140","h":"7.6160","l":"7.6070","v":"2532","n":87,"x":false,"q":"19273.8930","V":"1502","Q":"11433.7730","B":"0"}}}
1626992756.24689: {"stream":"sushiusdt@bookTicker","data":{"e":"bookTicker","u":600859907408,"s":"SUSHIUSDT","b":"7.6130","B":"1","a":"7.6150","A":"127","T":1626992756197,"E":1626992756201}}
1626992756.2574651: {"stream":"sushiusdt@bookTicker","data":{"e":"bookTicker","u":600859907696,"s":"SUSHIUSDT","b":"7.6130","B":"1","a":"7.6140","A":"30","T":1626992756207,"E":1626992756212}}
1626992756.2617338: {"stream":"sushiusdt@depth@100ms","data":{"e":"depthUpdate","E":1626992756215,"T":1626992756211,"s":"SUSHIUSDT","U":600859904520,"u":600859907798,"pu":600859904211,"b":[["7.5690","2103"],["7.5780","302"],["7.5800","3354"],["7.5920","3216"],["7.5930","3722"],["7.5960","1881"],["7.5970","2430"],["7.5990","3703"],["7.6020","2737"],["7.6030","420"],["7.6060","1701"],["7.6070","1385"],["7.6090","141"],["7.6110","38"],["7.6120","64"],["7.6140","0"]],"a":[["7.6140","30"],["7.6150","127"],["7.6170","378"],["7.6180","1799"],["7.6190","873"],["7.6200","1380"],["7.6210","1983"],["7.6230","3297"],["7.6250","581"],["7.6280","1835"],["7.6300","2085"],["7.6310","3401"],["7.6340","1378"],["7.6350","2223"],["7.6380","854"],["7.6400","639"],["7.6420","2144"],["7.6480","671"],["7.6500","787"],["7.6520","1342"]]}}
1626992756.2724302: {"stream":"sushiusdt@aggTrade","data":{"e":"aggTrade","E":1626992756227,"a":87353245,"s":"SUSHIUSDT","p":"7.6140","q":"1","f":126902960,"l":126902960,"T":1626992756197,"m":true}}
1626992756.272535: {"stream":"sushiusdt@bookTicker","data":{"e":"bookTicker","u":600859908188,"s":"SUSHIUSDT","b":"7.6120","B":"64","a":"7.6140","A":"30","T":1626992756222,"E":1626992756227}}
1626992756.283176: {"stream":"sushiusdt@bookTicker","data":{"e":"bookTicker","u":600859908527,"s":"SUSHIUSDT","b":"7.6120","B":"64","a":"7.6150","A":"127","T":1626992756233,"E":1626992756237}}
1626992756.283276: {"stream":"sushiusdt@bookTicker","data":{"e":"bookTicker","u":600859908564,"s":"SUSHIUSDT","b":"7.6120","B":"64","a":"7.6130","A":"28","T":1626992756234,"E":1626992756239}}
1626992756.296937: {"stream":"keepusdt@depth@100ms","data":{"e":"depthUpdate","E":1626992756252,"T":1626992756243,"s":"KEEPUSDT","U":600859905883,"u":600859908851,"pu":600859902738,"b":[["0.2441","4216"]],"a":[["0.2465","0"],["0.2466","1248"],["0.2469","4338"],["0.2472","22188"],["0.2473","28685"],["0.2475","11558"]]}}
1626992756.30521: {"stream":"akrousdt@depth@100ms","data":{"e":"depthUpdate","E":1626992756259,"T":1626992756254,"s":"AKROUSDT","U":600859906173,"u":600859909091,"pu":600859902862,"b":[["0.01688","421365"],["0.01725","873169"],["0.01727","1165922"]],"a":[["0.01735","255267"],["0.01746","85570"],["0.01747","111788"]]}}
1626992756.319625: {"stream":"sushiusdt@aggTrade","data":{"e":"aggTrade","E":1626992756274,"a":87353246,"s":"SUSHIUSDT","p":"7.6130","q":"1","f":126902961,"l":126902961,"T":1626992756222,"m":true}}
1626992756.3197272: {"stream":"sushiusdt@aggTrade","data":{"e":"aggTrade","E":1626992756274,"a":87353247,"s":"SUSHIUSDT","p":"7.6130","q":"28","f":126902962,"l":126902962,"T":1626992756268,"m":false}}
1626992756.3197749: {"stream":"sushiusdt@bookTicker","data":{"e":"bookTicker","u":600859909451,"s":"SUSHIUSDT","b":"7.6120","B":"64","a":"7.6150","A":"74","T":1626992756269,"E":1626992756274}}
1626992756.3236322: {"stream":"sushiusdt@bookTicker","data":{"e":"bookTicker","u":600859909547,"s":"SUSHIUSDT","b":"7.6120","B":"64","a":"7.6150","A":"81","T":1626992756273,"E":1626992756278}}
1626992756.32414: {"stream":"sushiusdt@bookTicker","data":{"e":"bookTicker","u":600859909564,"s":"SUSHIUSDT","b":"7.6120","B":"64","a":"7.6150","A":"102","T":1626992756274,"E":1626992756280}}
1626992756.327959: {"stream":"sushiusdt@bookTicker","data":{"e":"bookTicker","u":600859909588,"s":"SUSHIUSDT","b":"7.6140","B":"7","a":"7.6150","A":"102","T":1626992756279,"E":1626992756282}}
1626992756.344917: {"stream":"sushiusdt@bookTicker","data":{"e":"bookTicker","u":600859910029,"s":"SUSHIUSDT","b":"7.6140","B":"16","a":"7.6150","A":"102","T":1626992756297,"E":1626992756300}}
1626992756.362268: {"stream":"sushiusdt@depth@100ms","data":{"e":"depthUpdate","E":1626992756316,"T":1626992756304,"s":"SUSHIUSDT","U":600859907877,"u":600859910209,"pu":600859907798,"b":[["7.5540","142"],["7.5940","526"],["7.5980","686"],["7.6040","3049"],["7.6060","833"],["7.6070","1242"],["7.6080","702"],["7.6090","246"],["7.6110","31"],["7.6120","39"],["7.6130","0"],["7.6140","16"]],"a":[["7.6130","0"],["7.6140","0"],["7.6150","102"],["7.6160","472"],["7.6170","357"],["7.6200","1694"],["7.6210","1733"],["7.6230","3861"],["7.6370","2305"],["7.6380","763"],["7.6420","2234"],["7.6470","2467"],["7.6530","934"]]}}
1626992756.362592: {"stream":"sushiusdt@bookTicker","data":{"e":"bookTicker","u":600859910423,"s":"SUSHIUSDT","b":"7.6140","B":"16","a":"7.6150","A":"81","T":1626992756314,"E":1626992756318}}
1626992756.362647: {"stream":"sushiusdt@bookTicker","data":{"e":"bookTicker","u":600859910470,"s":"SUSHIUSDT","b":"7.6140","B":"16","a":"7.6150","A":"74","T":1626992756316,"E":1626992756318}}
1626992756.372779: {"stream":"sushiusdt@bookTicker","data":{"e":"bookTicker","u":600859910609,"s":"SUSHIUSDT","b":"7.6140","B":"32","a":"7.6150","A":"74","T":1626992756325,"E":1626992756328}}
1626992756.4071949: {"stream":"akrousdt@depth@100ms","data":{"e":"depthUpdate","E":1626992756363,"T":1626992756300,"s":"AKROUSDT","U":600859909192,"u":600859910096,"pu":600859909091,"b":[["0.01723","425105"],["0.01726","519745"]],"a":[["0.01735","314408"],["0.01738","1205885"]]}}
1626992756.452826: {"stream":"sushiusdt@bookTicker","data":{"e":"bookTicker","u":600859912135,"s":"SUSHIUSDT","b":"7.6140","B":"39","a":"7.6150","A":"74","T":1626992756404,"E":1626992756407}}
1626992756.465823: {"stream":"sushiusdt@depth@100ms","data":{"e":"depthUpdate","E":1626992756418,"T":1626992756406,"s":"SUSHIUSDT","U":600859910423,"u":600859912161,"pu":600859910209,"b":[["7.4270","112"],["7.5470","2902"],["7.5580","947"],["7.5790","714"],["7.5820","1425"],["7.6010","1931"],["7.6020","1606"],["7.6040","3269"],["7.6100","223"],["7.6120","32"],["7.6140","39"]],"a":[["7.6150","74"],["7.6170","378"],["7.6180","1799"],["7.6230","3936"],["7.6370","2141"],["7.6400","720"],["7.6420","2263"],["7.6490","12641"],["7.6530","913"],["7.6820","1103"]]}}
1626992756.469599: {"stream":"sushiusdt@aggTrade","data":{"e":"aggTrade","E":1626992756425,"a":87353248,"s":"SUSHIUSDT","p":"7.6150","q":"53","f":126902963,"l":126902964,"T":1626992756269,"m":false}}
1626992756.469663: {"stream":"sushiusdt@bookTicker","data":{"e":"bookTicker","u":600859912492,"s":"SUSHIUSDT","b":"7.6140","B":"7","a":"7.6150","A":"74","T":1626992756421,"E":1626992756426}}
1626992756.534106: {"stream":"sushiusdt@kline_1m","data":{"e":"kline","E":1626992756490,"s":"SUSHIUSDT","k":{"t":1626992700000,"T":1626992759999,"s":"SUSHIUSDT","i":"1m","f":126902874,"L":126902968,"o":"7.6080","c":"7.6140","h":"7.6160","l":"7.6070","v":"2653","n":95,"x":false,"q":"20195.2110","V":"1583","Q":"12050.5320","B":"0"}}}
1626992756.535795: {"stream":"sushiusdt@aggTrade","data":{"e":"aggTrade","E":1626992756490,"a":87353249,"s":"SUSHIUSDT","p":"7.6140","q":"39","f":126902965,"l":126902968,"T":1626992756421,"m":true}}
1626992756.535866: {"stream":"sushiusdt@bookTicker","data":{"e":"bookTicker","u":600859913715,"s":"SUSHIUSDT","b":"7.6110","B":"23","a":"7.6150","A":"74","T":1626992756486,"E":1626992756490}}
1626992756.5469491: {"stream":"akrousdt@depth@100ms","data":{"e":"depthUpdate","E":1626992756503,"T":1626992756471,"s":"AKROUSDT","U":600859912047,"u":600859913496,"pu":600859910096,"b":[["0.01729","741414"]],"a":[["0.01736","934160"],["0.01739","901404"],["0.01750","1516841"]]}}
1626992756.550482: {"stream":"akrousdt@bookTicker","data":{"e":"bookTicker","u":600859913947,"s":"AKROUSDT","b":"0.01731","B":"79515","a":"0.01732","A":"74607","T":1626992756500,"E":1626992756504}}
1626992756.5505888: {"stream":"ctkusdt@bookTicker","data":{"e":"bookTicker","u":600859913950,"s":"CTKUSDT","b":"1.01000","B":"83063","a":"1.01100","A":"5960","T":1626992756500,"E":1626992756505}}
1626992756.553951: {"stream":"sushiusdt@bookTicker","data":{"e":"bookTicker","u":600859913991,"s":"SUSHIUSDT","b":"7.6110","B":"228","a":"7.6150","A":"74","T":1626992756503,"E":1626992756509}}
1626992756.5623481: {"stream":"sushiusdt@bookTicker","data":{"e":"bookTicker","u":600859914159,"s":"SUSHIUSDT","b":"7.6110","B":"228","a":"7.6150","A":"95","T":1626992756514,"E":1626992756518}}
1626992756.567023: {"stream":"ctkusdt@bookTicker","data":{"e":"bookTicker","u":600859914257,"s":"CTKUSDT","b":"1.01000","B":"83646","a":"1.01100","A":"5960","T":1626992756518,"E":1626992756522}}
1626992756.573643: {"stream":"sushiusdt@depth@100ms","data":{"e":"depthUpdate","E":1626992756526,"T":1626992756519,"s":"SUSHIUSDT","U":600859912467,"u":600859914316,"pu":600859912161,"b":[["7.1760","44"],["7.5570","1094"],["7.5620","2048"],["7.5680","8541"],["7.5720","4378"],["7.5740","742"],["7.5910","2848"],["7.6000","1002"],["7.6050","1154"],["7.6080","638"],["7.6090","245"],["7.6110","228"],["7.6120","0"],["7.6140","0"]],"a":[["7.6150","95"],["7.6170","339"],["7.6200","1929"],["7.6220","1539"],["7.6230","3749"],["7.6240","2822"],["7.6250","648"],["7.6310","6453"],["7.6510","462"],["7.6520","1374"],["7.6550","1272"],["7.6610","671"],["7.6740","1688"],["7.7920","304"],["8.4260","0"]]}}
1626992756.648939: {"stream":"akrousdt@depth@100ms","data":{"e":"depthUpdate","E":1626992756604,"T":1626992756527,"s":"AKROUSDT","U":600859913947,"u":600859914460,"pu":600859913496,"b":[["0.01728","826538"],["0.01729","784728"],["0.01731","79515"]],"a":[]}}
1626992756.6491132: {"stream":"ctkusdt@depth@100ms","data":{"e":"depthUpdate","E":1626992756605,"T":1626992756549,"s":"CTKUSDT","U":600859913950,"u":600859914902,"pu":600859902210,"b":[["1.01000","83646"]],"a":[["1.01500","21202"]]}}
1626992756.673735: {"stream":"sushiusdt@depth@100ms","data":{"e":"depthUpdate","E":1626992756628,"T":1626992756613,"s":"SUSHIUSDT","U":600859914370,"u":600859916221,"pu":600859914316,"b":[["7.6040","2410"],["7.6060","829"],["7.6080","249"],["7.6100","301"]],"a":[["7.6170","354"],["7.6350","2321"],["7.6820","1034"]]}}
1626992756.6871529: {"stream":"sushiusdt@aggTrade","data":{"e":"aggTrade","E":1626992756641,"a":87353250,"s":"SUSHIUSDT","p":"7.6110","q":"9","f":126902969,"l":126902969,"T":1626992756486,"m":true}}
1626992756.701788: {"stream":"sushiusdt@bookTicker","data":{"e":"bookTicker","u":600859917393,"s":"SUSHIUSDT","b":"7.6110","B":"227","a":"7.6150","A":"95","T":1626992756650,"E":1626992756655}}
1626992756.7514381: {"stream":"ctkusdt@bookTicker","data":{"e":"bookTicker","u":600859920333,"s":"CTKUSDT","b":"1.01000","B":"83646","a":"1.01100","A":"5178","T":1626992756694,"E":1626992756699}}
1626992756.751507: {"stream":"sushiusdt@bookTicker","data":{"e":"bookTicker","u":600859920368,"s":"SUSHIUSDT","b":"7.6110","B":"227","a":"7.6160","A":"472","T":1626992756694,"E":1626992756699}}
1626992756.7515361: {"stream":"ctkusdt@bookTicker","data":{"e":"bookTicker","u":600859920375,"s":"CTKUSDT","b":"1.01000","B":"83646","a":"1.01100","A":"4385","T":1626992756694,"E":1626992756699}}
1626992756.754347: {"stream":"keepusdt@bookTicker","data":{"e":"bookTicker","u":600859920661,"s":"KEEPUSDT","b":"0.2463","B":"3214","a":"0.2466","A":"1248","T":1626992756696,"E":1626992756701}}
1626992756.754415: {"stream":"akrousdt@bookTicker","data":{"e":"bookTicker","u":600859920720,"s":"AKROUSDT","b":"0.01731","B":"79515","a":"0.01732","A":"47121","T":1626992756696,"E":1626992756701}}
1626992756.761046: {"stream":"ctkusdt@bookTicker","data":{"e":"bookTicker","u":600859921268,"s":"CTKUSDT","b":"1.01000","B":"83646","a":"1.01100","A":"3885","T":1626992756699,"E":1626992756704}}
1626992756.7611442: {"stream":"ctkusdt@bookTicker","data":{"e":"bookTicker","u":600859921288,"s":"CTKUSDT","b":"1.01000","B":"83646","a":"1.01100","A":"3757","T":1626992756699,"E":1626992756705}}
1626992756.764253: {"stream":"ctkusdt@bookTicker","data":{"e":"bookTicker","u":600859921533,"s":"CTKUSDT","b":"1.01000","B":"83646","a":"1.01100","A":"3457","T":1626992756701,"E":1626992756705}}
1626992756.764351: {"stream":"ctkusdt@depth@100ms","data":{"e":"depthUpdate","E":1626992756706,"T":1626992756701,"s":"CTKUSDT","U":600859916014,"u":600859921533,"pu":600859914902,"b":[["1.00600","9269"],["1.01100","0"]],"a":[["1.01100","3457"],["1.01500","21202"]]}}
1626992756.764459: {"stream":"ctkusdt@bookTicker","data":{"e":"bookTicker","u":600859921614,"s":"CTKUSDT","b":"1.01000","B":"83646","a":"1.01100","A":"257","T":1626992756702,"E":1626992756706}}
1626992756.764502: {"stream":"ctkusdt@bookTicker","data":{"e":"bookTicker","u":600859921704,"s":"CTKUSDT","b":"1.01100","B":"43","a":"1.01200","A":"10902","T":1626992756702,"E":1626992756706}}
1626992756.764535: {"stream":"keepusdt@kline_1m","data":{"e":"kline","E":1626992756710,"s":"KEEPUSDT","k":{"t":1626992700000,"T":1626992759999,"s":"KEEPUSDT","i":"1m","f":2398346,"L":2398358,"o":"0.2463","c":"0.2464","h":"0.2464","l":"0.2458","v":"8437","n":13,"x":false,"q":"2075.8217","V":"317","Q":"78.1088","B":"0"}}}
1626992756.764618: {"stream":"ctkusdt@bookTicker","data":{"e":"bookTicker","u":600859921774,"s":"CTKUSDT","b":"1.01100","B":"1443","a":"1.01200","A":"10902","T":1626992756703,"E":1626992756706}}
1626992756.7664158: {"stream":"ctkusdt@kline_1m","data":{"e":"kline","E":1626992756711,"s":"CTKUSDT","k":{"t":1626992700000,"T":1626992759999,"s":"CTKUSDT","i":"1m","f":23961275,"L":23961345,"o":"1.01000","c":"1.01100","h":"1.01100","l":"1.01000","v":"7113","n":71,"x":false,"q":"7188.88900","V":"4759","Q":"4811.34900","B":"0"}}}
1626992756.769665: {"stream":"ctkusdt@bookTicker","data":{"e":"bookTicker","u":600859922175,"s":"CTKUSDT","b":"1.01100","B":"1565","a":"1.01200","A":"10902","T":1626992756706,"E":1626992756709}}
1626992756.774165: {"stream":"sushiusdt@bookTicker","data":{"e":"bookTicker","u":600859923072,"s":"SUSHIUSDT","b":"7.6110","B":"227","a":"7.6150","A":"30","T":1626992756713,"E":1626992756715}}
1626992756.774246: {"stream":"sushiusdt@bookTicker","data":{"e":"bookTicker","u":600859923187,"s":"SUSHIUSDT","b":"7.6110","B":"227","a":"7.6150","A":"50","T":1626992756714,"E":1626992756717}}
1626992756.776577: {"stream":"sushiusdt@bookTicker","data":{"e":"bookTicker","u":600859923445,"s":"SUSHIUSDT","b":"7.6110","B":"227","a":"7.6150","A":"81","T":1626992756717,"E":1626992756720}}
1626992756.7766452: {"stream":"sushiusdt@bookTicker","data":{"e":"bookTicker","u":600859923567,"s":"SUSHIUSDT","b":"7.6110","B":"697","a":"7.6150","A":"81","T":1626992756718,"E":1626992756721}}
1626992756.776673: {"stream":"akrousdt@bookTicker","data":{"e":"bookTicker","u":600859923582,"s":"AKROUSDT","b":"0.01731","B":"79515","a":"0.01732","A":"33121","T":1626992756718,"E":1626992756722}}
1626992756.780266: {"stream":"ctkusdt@bookTicker","data":{"e":"bookTicker","u":600859924006,"s":"CTKUSDT","b":"1.01100","B":"1665","a":"1.01200","A":"10902","T":1626992756723,"E":1626992756725}}
1626992756.7826939: {"stream":"ctkusdt@bookTicker","data":{"e":"bookTicker","u":600859924334,"s":"CTKUSDT","b":"1.01100","B":"1665","a":"1.01200","A":"5602","T":1626992756725,"E":1626992756728}}
1626992756.782791: {"stream":"sushiusdt@bookTicker","data":{"e":"bookTicker","u":600859924612,"s":"SUSHIUSDT","b":"7.6110","B":"697","a":"7.6150","A":"51","T":1626992756727,"E":1626992756730}}
1626992756.786596: {"stream":"sushiusdt@bookTicker","data":{"e":"bookTicker","u":600859925051,"s":"SUSHIUSDT","b":"7.6120","B":"48","a":"7.6150","A":"51","T":1626992756731,"E":1626992756734}}
1626992756.786693: {"stream":"ctkusdt@bookTicker","data":{"e":"bookTicker","u":600859925252,"s":"CTKUSDT","b":"1.01100","B":"2495","a":"1.01200","A":"5602","T":1626992756733,"E":1626992756736}}
1626992756.786749: {"stream":"sushiusdt@bookTicker","data":{"e":"bookTicker","u":600859925648,"s":"SUSHIUSDT","b":"7.6120","B":"48","a":"7.6150","A":"81","T":1626992756736,"E":1626992756739}}
1626992756.788673: {"stream":"keepusdt@bookTicker","data":{"e":"bookTicker","u":600859925617,"s":"KEEPUSDT","b":"0.2463","B":"3214","a":"0.2466","A":"839","T":1626992756736,"E":1626992756740}}
1626992756.7887402: {"stream":"sushiusdt@depth@100ms","data":{"e":"depthUpdate","E":1626992756741,"T":1626992756736,"s":"SUSHIUSDT","U":600859916895,"u":600859925648,"pu":600859916221,"b":[["7.4360","1078"],["7.5600","3810"],["7.5830","4423"],["7.6000","1099"],["7.6050","2022"],["7.6060","861"],["7.6070","1274"],["7.6090","239"],["7.6110","697"],["7.6120","48"]],"a":[["7.6150","81"],["7.6170","318"],["7.6180","1831"],["7.6190","1663"],["7.6200","889"],["7.6230","3965"],["7.6520","1342"],["7.6790","9"]]}}
1626992756.789123: {"stream":"keepusdt@bookTicker","data":{"e":"bookTicker","u":600859925761,"s":"KEEPUSDT","b":"0.2463","B":"3598","a":"0.2466","A":"839","T":1626992756737,"E":1626992756741}}
1626992756.789997: {"stream":"sushiusdt@bookTicker","data":{"e":"bookTicker","u":600859925872,"s":"SUSHIUSDT","b":"7.6120","B":"48","a":"7.6150","A":"61","T":1626992756738,"E":1626992756742}}
1626992756.790064: {"stream":"sushiusdt@bookTicker","data":{"e":"bookTicker","u":600859925898,"s":"SUSHIUSDT","b":"7.6130","B":"8","a":"7.6150","A":"61","T":1626992756738,"E":1626992756742}}
1626992756.816503: {"stream":"sushiusdt@kline_1m","data":{"e":"kline","E":1626992756769,"s":"SUSHIUSDT","k":{"t":1626992700000,"T":1626992759999,"s":"SUSHIUSDT","i":"1m","f":126902874,"L":126902974,"o":"7.6080","c":"7.6150","h":"7.6160","l":"7.6070","v":"2782","n":101,"x":false,"q":"21177.5100","V":"1703","Q":"12964.3320","B":"0"}}}
1626992756.816622: {"stream":"sushiusdt@bookTicker","data":{"e":"bookTicker","u":600859929252,"s":"SUSHIUSDT","b":"7.6130","B":"8","a":"7.6150","A":"36","T":1626992756765,"E":1626992756769}}
1626992756.821463: {"stream":"ctkusdt@bookTicker","data":{"e":"bookTicker","u":600859929987,"s":"CTKUSDT","b":"1.01100","B":"2495","a":"1.01200","A":"6392","T":1626992756771,"E":1626992756774}}
1626992756.821562: {"stream":"sushiusdt@bookTicker","data":{"e":"bookTicker","u":600859930016,"s":"SUSHIUSDT","b":"7.6130","B":"8","a":"7.6160","A":"386","T":1626992756771,"E":1626992756774}}
1626992756.8216069: {"stream":"sushiusdt@bookTicker","data":{"e":"bookTicker","u":600859930049,"s":"SUSHIUSDT","b":"7.6130","B":"213","a":"7.6160","A":"386","T":1626992756771,"E":1626992756774}}
1626992756.827949: {"stream":"ctkusdt@bookTicker","data":{"e":"bookTicker","u":600859931219,"s":"CTKUSDT","b":"1.01100","B":"3295","a":"1.01200","A":"6392","T":1626992756780,"E":1626992756783}}
1626992756.828445: {"stream":"akrousdt@depth@100ms","data":{"e":"depthUpdate","E":1626992756785,"T":1626992756781,"s":"AKROUSDT","U":600859918805,"u":600859931301,"pu":600859914460,"b":[["0.01709","373783"],["0.01726","505261"],["0.01728","821330"]],"a":[["0.01732","33121"],["0.01736","919760"],["0.01737","413408"],["0.01738","1198291"],["0.01740","302965"],["0.01743","321278"]]}}
1626992756.838635: {"stream":"sushiusdt@bookTicker","data":{"e":"bookTicker","u":600859932408,"s":"SUSHIUSDT","b":"7.6130","B":"213","a":"7.6160","A":"314","T":1626992756790,"E":1626992756793}}
1626992756.8410492: {"stream":"ctkusdt@bookTicker","data":{"e":"bookTicker","u":600859932719,"s":"CTKUSDT","b":"1.01100","B":"3295","a":"1.01200","A":"1444","T":1626992756793,"E":1626992756795}}
1626992756.8411179: {"stream":"ctkusdt@bookTicker","data":{"e":"bookTicker","u":600859932890,"s":"CTKUSDT","b":"1.01100","B":"3295","a":"1.01200","A":"2234","T":1626992756794,"E":1626992756796}}
1626992756.8411462: {"stream":"sushiusdt@bookTicker","data":{"e":"bookTicker","u":600859932917,"s":"SUSHIUSDT","b":"7.6130","B":"213","a":"7.6160","A":"283","T":1626992756794,"E":1626992756796}}
1626992756.843307: {"stream":"ctkusdt@bookTicker","data":{"e":"bookTicker","u":600859933144,"s":"CTKUSDT","b":"1.01100","B":"3374","a":"1.01200","A":"2234","T":1626992756796,"E":1626992756799}}
1626992756.843969: {"stream":"ctkusdt@bookTicker","data":{"e":"bookTicker","u":600859933364,"s":"CTKUSDT","b":"1.01100","B":"3374","a":"1.01200","A":"3024","T":1626992756798,"E":1626992756800}}
1626992756.8440478: {"stream":"keepusdt@depth@100ms","data":{"e":"depthUpdate","E":1626992756801,"T":1626992756789,"s":"KEEPUSDT","U":600859920657,"u":600859932255,"pu":600859908851,"b":[["0.2445","73684"],["0.2456","14402"],["0.2459","4738"],["0.2463","3598"],["0.2464","0"]],"a":[["0.2464","0"],["0.2466","839"],["0.2471","14846"]]}}
1626992756.847627: {"stream":"akrousdt@bookTicker","data":{"e":"bookTicker","u":600859933568,"s":"AKROUSDT","b":"0.01731","B":"79515","a":"0.01732","A":"13121","T":1626992756800,"E":1626992756802}}
1626992756.865802: {"stream":"akrousdt@kline_1m","data":{"e":"kline","E":1626992756803,"s":"AKROUSDT","k":{"t":1626992700000,"T":1626992759999,"s":"AKROUSDT","i":"1m","f":27931328,"L":27931352,"o":"0.01731","c":"0.01732","h":"0.01733","l":"0.01731","v":"178992","n":25,"x":false,"q":"3099.39524","V":"88508","Q":"1533.11720","B":"0"}}}
1626992756.8658729: {"stream":"ctkusdt@depth@100ms","data":{"e":"depthUpdate","E":1626992756806,"T":1626992756803,"s":"CTKUSDT","U":600859921586,"u":600859933879,"pu":600859921533,"b":[["1.00500","34205"],["1.00600","9269"],["1.00700","6942"],["1.00800","21391"],["1.00900","11039"],["1.01000","85375"],["1.01100","3374"]],"a":[["1.01100","0"],["1.01200","3024"],["1.01300","8026"],["1.01400","14888"],["1.01500","18365"],["1.01600","20237"],["1.01700","8093"],["1.01800","9790"]]}}
1626992756.8659909: {"stream":"sushiusdt@aggTrade","data":{"e":"aggTrade","E":1626992756809,"a":87353251,"s":"SUSHIUSDT","p":"7.6150","q":"156","f":126902970,"l":126902976,"T":1626992756694,"m":false}}
1626992756.866019: {"stream":"sushiusdt@bookTicker","data":{"e":"bookTicker","u":600859934201,"s":"SUSHIUSDT","b":"7.6130","B":"213","a":"7.6160","A":"270","T":1626992756807,"E":1626992756809}}
1626992756.86604: {"stream":"sushiusdt@bookTicker","data":{"e":"bookTicker","u":600859935396,"s":"SUSHIUSDT","b":"7.6130","B":"244","a":"7.6160","A":"270","T":1626992756815,"E":1626992756818}}
1626992756.867811: {"stream":"ctkusdt@bookTicker","data":{"e":"bookTicker","u":600859935792,"s":"CTKUSDT","b":"1.01100","B":"3399","a":"1.01200","A":"3024","T":1626992756820,"E":1626992756822}}
1626992756.8743732: {"stream":"ctkusdt@bookTicker","data":{"e":"bookTicker","u":600859936616,"s":"CTKUSDT","b":"1.01100","B":"3399","a":"1.01200","A":"2620","T":1626992756826,"E":1626992756829}}
1626992756.9166589: {"stream":"ctkusdt@bookTicker","data":{"e":"bookTicker","u":600859937462,"s":"CTKUSDT","b":"1.01100","B":"3399","a":"1.01200","A":"2625","T":1626992756834,"E":1626992756837}}
1626992756.921033: {"stream":"sushiusdt@depth@100ms","data":{"e":"depthUpdate","E":1626992756842,"T":1626992756839,"s":"SUSHIUSDT","U":600859925872,"u":600859938069,"pu":600859925648,"b":[["7.5600","809"],["7.5690","2163"],["7.5750","3569"],["7.5770","2009"],["7.5840","1625"],["7.5860","1071"],["7.5930","3509"],["7.5950","2320"],["7.5960","2073"],["7.5980","706"],["7.6000","849"],["7.6010","2109"],["7.6040","2205"],["7.6050","1084"],["7.6060","1574"],["7.6070","1274"],["7.6080","94"],["7.6090","134"],["7.6100","145"],["7.6110","831"],["7.6120","197"],["7.6130","244"]],"a":[["7.6150","0"],["7.6160","270"],["7.6170","15"],["7.6180","1251"],["7.6190","742"],["7.6200","471"],["7.6210","1483"],["7.6220","1264"],["7.6230","3821"],["7.6240","2073"],["7.6260","959"],["7.6280","1809"],["7.6360","2596"],["7.6390","1319"],["7.6410","1613"],["7.6440","4968"],["7.6490","14141"],["7.6520","1239"],["7.6560","360"],["7.6730","1198"],["7.6800","374"]]}}
1626992756.924324: {"stream":"keepusdt@aggTrade","data":{"e":"aggTrade","E":1626992756852,"a":1211537,"s":"KEEPUSDT","p":"0.2464","q":"317","f":2398358,"l":2398358,"T":1626992756696,"m":false}}
1626992756.928465: {"stream":"ctkusdt@aggTrade","data":{"e":"aggTrade","E":1626992756855,"a":16599310,"s":"CTKUSDT","p":"1.01100","q":"4385","f":23961345,"l":23961355,"T":1626992756699,"m":false}}
1626992756.928535: {"stream":"sushiusdt@bookTicker","data":{"e":"bookTicker","u":600859939739,"s":"SUSHIUSDT","b":"7.6130","B":"244","a":"7.6160","A":"189","T":1626992756852,"E":1626992756855}}
1626992756.9285681: {"stream":"ctkusdt@bookTicker","data":{"e":"bookTicker","u":600859939766,"s":"CTKUSDT","b":"1.01100","B":"3399","a":"1.01200","A":"1835","T":1626992756852,"E":1626992756855}}
1626992756.928592: {"stream":"sushiusdt@bookTicker","data":{"e":"bookTicker","u":600859939917,"s":"SUSHIUSDT","b":"7.6130","B":"244","a":"7.6160","A":"63","T":1626992756853,"E":1626992756856}}
1626992756.934913: {"stream":"ctkusdt@bookTicker","data":{"e":"bookTicker","u":600859940871,"s":"CTKUSDT","b":"1.01100","B":"6219","a":"1.01200","A":"1835","T":1626992756861,"E":1626992756864}}
1626992756.935009: {"stream":"ctkusdt@bookTicker","data":{"e":"bookTicker","u":600859940969,"s":"CTKUSDT","b":"1.01100","B":"6348","a":"1.01200","A":"1835","T":1626992756863,"E":1626992756865}}
1626992756.935055: {"stream":"ctkusdt@bookTicker","data":{"e":"bookTicker","u":600859941040,"s":"CTKUSDT","b":"1.01100","B":"6348","a":"1.01200","A":"1045","T":1626992756863,"E":1626992756866}}
1626992756.9350982: {"stream":"akrousdt@bookTicker","data":{"e":"bookTicker","u":600859941159,"s":"AKROUSDT","b":"0.01732","B":"14000","a":"0.01733","A":"355270","T":1626992756864,"E":1626992756867}}
1626992756.935141: {"stream":"ctkusdt@bookTicker","data":{"e":"bookTicker","u":600859941222,"s":"CTKUSDT","b":"1.01100","B":"6348","a":"1.01200","A":"1040","T":1626992756865,"E":1626992756867}}
1626992756.9370198: {"stream":"ctkusdt@bookTicker","data":{"e":"bookTicker","u":600859941879,"s":"CTKUSDT","b":"1.01100","B":"6348","a":"1.01200","A":"250","T":1626992756871,"E":1626992756874}}
1626992756.937852: {"stream":"sushiusdt@bookTicker","data":{"e":"bookTicker","u":600859942382,"s":"SUSHIUSDT","b":"7.6140","B":"87","a":"7.6160","A":"63","T":1626992756875,"E":1626992756878}}
1626992756.942711: {"stream":"akrousdt@bookTicker","data":{"e":"bookTicker","u":600859943291,"s":"AKROUSDT","b":"0.01732","B":"78000","a":"0.01733","A":"355270","T":1626992756883,"E":1626992756886}}
1626992756.94281: {"stream":"sushiusdt@bookTicker","data":{"e":"bookTicker","u":600859943406,"s":"SUSHIUSDT","b":"7.6140","B":"87","a":"7.6160","A":"20","T":1626992756884,"E":1626992756887}}
1626992756.944612: {"stream":"akrousdt@bookTicker","data":{"e":"bookTicker","u":600859943764,"s":"AKROUSDT","b":"0.01732","B":"78000","a":"0.01733","A":"340832","T":1626992756888,"E":1626992756890}}
1626992756.9489212: {"stream":"keepusdt@bookTicker","data":{"e":"bookTicker","u":600859944392,"s":"KEEPUSDT","b":"0.2463","B":"384","a":"0.2466","A":"839","T":1626992756893,"E":1626992756896}}
1626992756.953212: {"stream":"akrousdt@depth@100ms","data":{"e":"depthUpdate","E":1626992756902,"T":1626992756892,"s":"AKROUSDT","U":600859933564,"u":600859944291,"pu":600859931301,"b":[["0.01723","416400"],["0.01725","815169"],["0.01727","1156559"],["0.01728","835797"],["0.01729","787719"],["0.01732","78000"]],"a":[["0.01732","0"],["0.01733","340832"],["0.01738","1075893"],["0.01739","1040164"],["0.01741","265304"],["0.01745","244698"]]}}
1626992756.955743: {"stream":"ctkusdt@bookTicker","data":{"e":"bookTicker","u":600859945840,"s":"CTKUSDT","b":"1.01100","B":"6353","a":"1.01200","A":"250","T":1626992756905,"E":1626992756908}}
1626992756.955841: {"stream":"akrousdt@bookTicker","data":{"e":"bookTicker","u":600859946037,"s":"AKROUSDT","b":"0.01732","B":"78000","a":"0.01733","A":"326394","T":1626992756907,"E":1626992756909}}
1626992756.9593658: {"stream":"ctkusdt@depth@100ms","data":{"e":"depthUpdate","E":1626992756913,"T":1626992756907,"s":"CTKUSDT","U":600859934721,"u":600859946052,"pu":600859933879,"b":[["1.00800","18985"],["1.00900","13411"],["1.01000","87003"],["1.01100","6353"]],"a":[["1.01200","250"],["1.01300","11578"],["1.01400","12804"],["1.01500","14978"],["1.01600","20466"],["1.01700","8041"],["1.01800","9657"],["1.01900","1018"]]}}
1626992756.959572: {"stream":"sushiusdt@aggTrade","data":{"e":"aggTrade","E":1626992756913,"a":87353252,"s":"SUSHIUSDT","p":"7.6160","q":"137","f":126902977,"l":126902980,"T":1626992756807,"m":false}}
1626992756.959626: {"stream":"sushiusdt@bookTicker","data":{"e":"bookTicker","u":600859946583,"s":"SUSHIUSDT","b":"7.6140","B":"72","a":"7.6160","A":"20","T":1626992756911,"E":1626992756913}}
1626992756.9658408: {"stream":"akrousdt@bookTicker","data":{"e":"bookTicker","u":600859946777,"s":"AKROUSDT","b":"0.01732","B":"78000","a":"0.01733","A":"239739","T":1626992756913,"E":1626992756915}}
1626992756.965922: {"stream":"sushiusdt@bookTicker","data":{"e":"bookTicker","u":600859946797,"s":"SUSHIUSDT","b":"7.6140","B":"120","a":"7.6160","A":"20","T":1626992756913,"E":1626992756915}}
1626992756.965953: {"stream":"sushiusdt@bookTicker","data":{"e":"bookTicker","u":600859947079,"s":"SUSHIUSDT","b":"7.6140","B":"151","a":"7.6160","A":"20","T":1626992756916,"E":1626992756918}}
1626992756.9663382: {"stream":"akrousdt@bookTicker","data":{"e":"bookTicker","u":600859947484,"s":"AKROUSDT","b":"0.01732","B":"78000","a":"0.01733","A":"193537","T":1626992756919,"E":1626992756921}}
1626992756.970764: {"stream":"ctkusdt@bookTicker","data":{"e":"bookTicker","u":600859947773,"s":"CTKUSDT","b":"1.01100","B":"6601","a":"1.01200","A":"250","T":1626992756922,"E":1626992756924}}
1626992756.976141: {"stream":"keepusdt@depth@100ms","data":{"e":"depthUpdate","E":1626992756931,"T":1626992756893,"s":"KEEPUSDT","U":600859936755,"u":600859944392,"pu":600859932255,"b":[["0.2449","19071"],["0.2450","98947"],["0.2463","384"]],"a":[["0.2492","13977"],["0.2502","3364"]]}}
1626992756.979769: {"stream":"keepusdt@bookTicker","data":{"e":"bookTicker","u":600859948772,"s":"KEEPUSDT","b":"0.2464","B":"3218","a":"0.2466","A":"839","T":1626992756931,"E":1626992756934}}
1626992756.9818938: {"stream":"sushiusdt@bookTicker","data":{"e":"bookTicker","u":600859948888,"s":"SUSHIUSDT","b":"7.6140","B":"103","a":"7.6160","A":"20","T":1626992756932,"E":1626992756935}}
1626992756.9819431: {"stream":"sushiusdt@bookTicker","data":{"e":"bookTicker","u":600859948919,"s":"SUSHIUSDT","b":"7.6140","B":"103","a":"7.6170","A":"27","T":1626992756932,"E":1626992756935}}
1626992756.984373: {"stream":"akrousdt@bookTicker","data":{"e":"bookTicker","u":600859949166,"s":"AKROUSDT","b":"0.01732","B":"78000","a":"0.01733","A":"158885","T":1626992756934,"E":1626992756937}}
1626992756.988789: {"stream":"sushiusdt@depth@100ms","data":{"e":"depthUpdate","E":1626992756942,"T":1626992756938,"s":"SUSHIUSDT","U":600859938152,"u":600859949617,"pu":600859938069,"b":[["7.5300","5354"],["7.5410","2533"],["7.5600","2310"],["7.5670","146"],["7.5700","672"],["7.5770","1925"],["7.5800","3152"],["7.5840","1612"],["7.5850","990"],["7.5880","1888"],["7.5920","3149"],["7.5930","3478"],["7.5940","556"],["7.5950","2351"],["7.5960","1876"],["7.5970","2277"],["7.5980","748"],["7.6010","2306"],["7.6040","2055"],["7.6050","1334"],["7.6060","553"],["7.6070","1443"],["7.6080","340"],["7.6090","424"],["7.6120","290"],["7.6130","213"],["7.6140","103"],["7.6160","0"]],"a":[["7.6160","0"],["7.6170","27"],["7.6180","623"],["7.6190","678"],["7.6200","1788"],["7.6210","2581"],["7.6220","1077"],["7.6230","2657"],["7.6240","2062"],["7.6250","643"],["7.6260","1474"],["7.6280","1742"],["7.6290","4317"],["7.6310","3303"],["7.6320","2037"],["7.6330","1106"],["7.6340","1363"],["7.6350","2466"],["7.6360","2626"],["7.6390","1119"],["7.6460","413"],["7.6470","2448"],["7.6510","445"],["7.6840","304"],["7.6920","1485"],["7.7100","4439"],["7.8020","2565"]]}}
1626992756.99735: {"stream":"akrousdt@bookTicker","data":{"e":"bookTicker","u":600859950877,"s":"AKROUSDT","b":"0.01732","B":"78000","a":"0.01733","A":"144885","T":1626992756949,"E":1626992756951}}
1626992756.997453: {"stream":"sushiusdt@bookTicker","data":{"e":"bookTicker","u":600859950906,"s":"SUSHIUSDT","b":"7.6140","B":"104","a":"7.6170","A":"27","T":1626992756949,"E":1626992756951}}
1626992756.997499: {"stream":"akrousdt@aggTrade","data":{"e":"aggTrade","E":1626992756953,"a":14888305,"s":"AKROUSDT","p":"0.01732","q":"33121","f":27931352,"l":27931354,"T":1626992756800,"m":false}}
1626992757.0034199: {"stream":"sushiusdt@bookTicker","data":{"e":"bookTicker","u":600859951560,"s":"SUSHIUSDT","b":"7.6140","B":"104","a":"7.6180","A":"472","T":1626992756955,"E":1626992756958}}
1626992757.003497: {"stream":"sushiusdt@bookTicker","data":{"e":"bookTicker","u":600859951561,"s":"SUSHIUSDT","b":"7.6140","B":"104","a":"7.6180","A":"382","T":1626992756955,"E":1626992756958}}
1626992757.027959: {"stream":"sushiusdt@bookTicker","data":{"e":"bookTicker","u":600859954102,"s":"SUSHIUSDT","b":"7.6140","B":"104","a":"7.6180","A":"350","T":1626992756979,"E":1626992756982}}
1626992757.050421: {"stream":"akrousdt@depth@100ms","data":{"e":"depthUpdate","E":1626992757004,"T":1626992757000,"s":"AKROUSDT","U":600859945413,"u":600859956388,"pu":600859944291,"b":[["0.01688","291216"],["0.01706","257820"],["0.01719","150742"],["0.01721","500492"],["0.01724","347935"],["0.01726","490777"],["0.01727","867792"],["0.01729","207263"],["0.01730","179220"],["0.01731","93515"]],"a":[["0.01733","144885"],["0.01734","46984"],["0.01735","289068"],["0.01736","581233"],["0.01737","407408"],["0.01738","501413"],["0.01739","1092163"],["0.01741","272439"],["0.01742","249520"]]}}
1626992757.05899: {"stream":"ctkusdt@depth@100ms","data":{"e":"depthUpdate","E":1626992757013,"T":1626992757004,"s":"CTKUSDT","U":600859946466,"u":600859956787,"pu":600859946052,"b":[["1.00600","9021"],["1.00800","15029"],["1.00900","13322"],["1.01100","6601"]],"a":[["1.01300","13948"],["1.01400","11305"],["1.01500","16627"],["1.01600","20079"],["1.01700","8222"],["1.01800","9902"],["1.02100","35883"],["1.02200","4646"],["1.04000","1724"]]}}
1626992757.059069: {"stream":"ctkusdt@bookTicker","data":{"e":"bookTicker","u":600859957586,"s":"CTKUSDT","b":"1.01100","B":"6601","a":"1.01200","A":"123","T":1626992757012,"E":1626992757015}}
1626992757.0621388: {"stream":"akrousdt@bookTicker","data":{"e":"bookTicker","u":600859957766,"s":"AKROUSDT","b":"0.01732","B":"78000","a":"0.01733","A":"98683","T":1626992757014,"E":1626992757017}}
1626992757.072028: {"stream":"akrousdt@bookTicker","data":{"e":"bookTicker","u":600859958952,"s":"AKROUSDT","b":"0.01732","B":"78000","a":"0.01734","A":"46984","T":1626992757025,"E":1626992757027}}
1626992757.0784361: {"stream":"keepusdt@depth@100ms","data":{"e":"depthUpdate","E":1626992757034,"T":1626992757030,"s":"KEEPUSDT","U":600859948772,"u":600859959566,"pu":600859944392,"b":[["0.2427","8937"],["0.2429","23315"],["0.2435","37873"],["0.2437","14334"],["0.2439","12436"],["0.2464","3218"]],"a":[["0.2467","1900"],["0.2469","3090"],["0.2470","14119"],["0.2471","16094"],["0.2472","19925"],["0.2473","24476"],["0.2477","10542"]]}}
1626992757.088083: {"stream":"sushiusdt@depth@100ms","data":{"e":"depthUpdate","E":1626992757042,"T":1626992757039,"s":"SUSHIUSDT","U":600859949778,"u":600859960405,"pu":600859949617,"b":[["7.5300","2353"],["7.5410","2526"],["7.5470","2886"],["7.5510","897"],["7.5570","1110"],["7.5600","809"],["7.5680","8450"],["7.5760","1708"],["7.5800","3172"],["7.5890","1104"],["7.5920","3219"],["7.5930","3491"],["7.5940","293"],["7.5950","1893"],["7.5980","652"],["7.5990","3326"],["7.6010","2373"],["7.6020","1462"],["7.6060","673"],["7.6070","555"],["7.6080","1193"],["7.6090","134"],["7.6110","1887"],["7.6140","104"]],"a":[["7.6170","0"],["7.6180","350"],["7.6190","912"],["7.6200","1748"],["7.6210","2156"],["7.6220","823"],["7.6230","3182"],["7.6240","1388"],["7.6260","1708"],["7.6270","2063"],["7.6280","1545"],["7.6290","3719"],["7.6300","1889"],["7.6350","2440"],["7.6360","2342"],["7.6410","1253"],["7.6420","2244"],["7.6430","3192"],["7.6450","941"],["7.6540","332"],["7.6560","376"],["7.6660","798"],["7.6760","2037"],["7.6920","16"],["7.7100","1470"]]}}
1626992757.093767: {"stream":"akrousdt@bookTicker","data":{"e":"bookTicker","u":600859960958,"s":"AKROUSDT","b":"0.01732","B":"92000","a":"0.01734","A":"46984","T":1626992757044,"E":1626992757047}}
1626992757.093795: {"stream":"akrousdt@bookTicker","data":{"e":"bookTicker","u":600859961028,"s":"AKROUSDT","b":"0.01732","B":"92000","a":"0.01733","A":"16444","T":1626992757045,"E":1626992757047}}
1626992757.111757: {"stream":"sushiusdt@aggTrade","data":{"e":"aggTrade","E":1626992757064,"a":87353253,"s":"SUSHIUSDT","p":"7.6140","q":"15","f":126902981,"l":126902981,"T":1626992756911,"m":true}}
1626992757.115189: {"stream":"ctkusdt@bookTicker","data":{"e":"bookTicker","u":600859962827,"s":"CTKUSDT","b":"1.01100","B":"8666","a":"1.01200","A":"123","T":1626992757062,"E":1626992757065}}
1626992757.1492832: {"stream":"akrousdt@depth@100ms","data":{"e":"depthUpdate","E":1626992757104,"T":1626992757093,"s":"AKROUSDT","U":600859956486,"u":600859964224,"pu":600859956388,"b":[["0.01721","515018"],["0.01722","422584"],["0.01723","401891"],["0.01726","499467"],["0.01727","847722"],["0.01728","850264"],["0.01729","306575"],["0.01730","160050"],["0.01731","183245"],["0.01732","92000"]],"a":[["0.01733","16444"],["0.01734","32546"],["0.01735","270408"],["0.01736","450355"],["0.01737","445582"],["0.01738","412013"],["0.01739","1099063"]]}}
1626992757.158287: {"stream":"ctkusdt@depth@100ms","data":{"e":"depthUpdate","E":1626992757115,"T":1626992757107,"s":"CTKUSDT","U":600859957586,"u":600859964432,"pu":600859956787,"b":[["1.00300","6015"],["1.00700","8162"],["1.00800","15021"],["1.01000","83217"],["1.01100","8666"]],"a":[["1.01200","123"],["1.01300","13940"],["1.01400","11251"],["1.01900","1312"],["1.10000","15520"],["1.11400","2133"]]}}
1626992757.182135: {"stream":"keepusdt@depth@100ms","data":{"e":"depthUpdate","E":1626992757139,"T":1626992757109,"s":"KEEPUSDT","U":600859960124,"u":600859964514,"pu":600859959566,"b":[["0.2436","7135"],["0.2439","7522"],["0.2446","8446"]],"a":[["0.2472","6227"],["0.2473","25115"]]}}
1626992757.186317: {"stream":"sushiusdt@depth@100ms","data":{"e":"depthUpdate","E":1626992757142,"T":1626992757136,"s":"SUSHIUSDT","U":600859960546,"u":600859965112,"pu":600859960405,"b":[["7.4450","323"],["7.5820","1399"],["7.5840","3113"],["7.5920","3179"],["7.5930","3162"],["7.5980","678"],["7.6000","593"],["7.6040","2089"],["7.6060","623"],["7.6070","808"],["7.6080","1165"],["7.6090","441"],["7.6110","1772"],["7.6120","677"]],"a":[["7.6190","795"],["7.6200","958"],["7.6210","2106"],["7.6250","576"],["7.6290","3765"],["7.6300","1857"],["7.6310","3331"],["7.6410","1170"],["7.6530","881"]]}}
1626992757.2169778: {"stream":"sushiusdt@bookTicker","data":{"e":"bookTicker","u":600859966722,"s":"SUSHIUSDT","b":"7.6140","B":"104","a":"7.6180","A":"26","T":1626992757167,"E":1626992757170}}
1626992757.220567: {"stream":"akrousdt@bookTicker","data":{"e":"bookTicker","u":600859967348,"s":"AKROUSDT","b":"0.01732","B":"92000","a":"0.01734","A":"32546","T":1626992757173,"E":1626992757176}}
1626992757.2312388: {"stream":"ctkusdt@bookTicker","data":{"e":"bookTicker","u":600859968227,"s":"CTKUSDT","b":"1.01100","B":"9249","a":"1.01200","A":"123","T":1626992757180,"E":1626992757183}}
1626992757.23568: {"stream":"ctkusdt@kline_1m","data":{"e":"kline","E":1626992757189,"s":"CTKUSDT","k":{"t":1626992700000,"T":1626992759999,"s":"CTKUSDT","i":"1m","f":23961275,"L":23961356,"o":"1.01000","c":"1.01200","h":"1.01200","l":"1.01000","v":"11008","n":82,"x":false,"q":"11126.74400","V":"8654","Q":"8749.20400","B":"0"}}}
1626992757.235726: {"stream":"ctkusdt@bookTicker","data":{"e":"bookTicker","u":600859968971,"s":"CTKUSDT","b":"1.01100","B":"9249","a":"1.01200","A":"113","T":1626992757187,"E":1626992757189}}
1626992757.239754: {"stream":"akrousdt@bookTicker","data":{"e":"bookTicker","u":600859969401,"s":"AKROUSDT","b":"0.01732","B":"92000","a":"0.01733","A":"11392","T":1626992757192,"E":1626992757195}}
1626992757.243998: {"stream":"ctkusdt@bookTicker","data":{"e":"bookTicker","u":600859969623,"s":"CTKUSDT","b":"1.01100","B":"10387","a":"1.01200","A":"113","T":1626992757195,"E":1626992757197}}
1626992757.252596: {"stream":"akrousdt@depth@100ms","data":{"e":"depthUpdate","E":1626992757208,"T":1626992757201,"s":"AKROUSDT","U":600859964365,"u":600859970114,"pu":600859964224,"b":[["0.01714","1467249"],["0.01715","558565"],["0.01716","315083"],["0.01721","506303"],["0.01723","404793"],["0.01728","711174"],["0.01730","165882"],["0.01731","195181"]],"a":[["0.01733","11392"],["0.01734","105261"],["0.01735","346882"],["0.01736","126177"],["0.01738","481061"],["0.01739","826873"],["0.01742","312674"]]}}
1626992757.252662: {"stream":"sushiusdt@bookTicker","data":{"e":"bookTicker","u":600859970532,"s":"SUSHIUSDT","b":"7.6140","B":"73","a":"7.6180","A":"26","T":1626992757206,"E":1626992757208}}
1626992757.263646: {"stream":"sushiusdt@bookTicker","data":{"e":"bookTicker","u":600859970872,"s":"SUSHIUSDT","b":"7.6150","B":"31","a":"7.6180","A":"26","T":1626992757210,"E":1626992757213}}
1626992757.279312: {"stream":"ctkusdt@aggTrade","data":{"e":"aggTrade","E":1626992757232,"a":16599311,"s":"CTKUSDT","p":"1.01200","q":"10","f":23961356,"l":23961356,"T":1626992757187,"m":false}}
1626992757.279435: {"stream":"ctkusdt@bookTicker","data":{"e":"bookTicker","u":600859972620,"s":"CTKUSDT","b":"1.01100","B":"10341","a":"1.01200","A":"113","T":1626992757230,"E":1626992757232}}
