1618677460.250658: {"stream":"yfiusdt@depth@100ms","data":{"e":"depthUpdate","E":1618677460126,"T":1618677460116,"s":"YFIUSDT","U":335340954675,"u":335340957929,"pu":335340954338,"b":[["47170.8","0.000"],["49876.0","0.000"],["49883.4","0.141"],["49916.9","0.000"],["49919.5","0.060"],["49944.1","0.035"],["49948.4","0.017"],["49949.3","0.018"],["49953.0","0.000"],["49953.1","0.168"],["49966.0","0.000"],["49966.1","0.000"],["49973.7","0.000"],["49974.4","0.000"],["49981.7","0.000"]],"a":[["50000.5","0.024"],["50000.7","0.000"],["50000.8","0.000"],["50000.9","0.000"],["50001.0","0.055"],["50001.8","0.009"],["50002.8","0.000"],["50002.9","0.000"],["50003.0","0.020"],["50003.1","0.000"],["50003.2","0.000"],["50003.3","0.000"],["50003.4","0.065"],["50003.5","0.000"],["50005.8","0.000"],["50006.0","0.149"],["50006.1","0.000"],["50078.1","0.000"],["50087.8","0.060"],["50108.9","0.000"],["50116.6","0.011"],["50119.8","0.400"],["50121.6","0.141"]]}}
1618677460.251051: {"stream":"dentusdt@aggTrade","data":{"e":"aggTrade","E":1618677460126,"a":8476420,"s":"DENTUSDT","p":"0.012348","q":"8867","f":15787410,"l":15787410,"T":1618677460122,"m":true}}
1618677460.2510872: {"stream":"dentusdt@bookTicker","data":{"e":"bookTicker","u":335340958016,"s":"DENTUSDT","b":"0.012347","B":"32702","a":"0.012357","A":"60732","T":1618677460122,"E":1618677460126}}
1618677460.251113: {"stream":"ksmusdt@depth@100ms","data":{"e":"depthUpdate","E":1618677460133,"T":1618677460109,"s":"KSMUSDT","U":335340954949,"u":335340957847,"pu":335340954794,"b":[["457.960","1.1"],["457.977","0.0"],["458.757","1.3"],["458.764","0.0"],["458.778","1.2"],["458.779","0.0"],["458.780","0.6"],["458.840","0.0"],["459.000","0.5"]],"a":[["459.080","0.0"],["459.081","1.5"],["459.083","1.2"],["459.163","0.1"],["459.214","0.3"],["459.215","1.6"],["459.246","0.0"],["459.247","0.0"],["459.260","0.0"],["459.368","0.1"],["459.418","0.0"],["459.526","0.1"],["459.623","1.2"],["459.649","0.0"],["459.655","0.1"],["459.752","0.0"],["460.117","1.0"],["461.775","0.3"]]}}
1618677460.2513201: {"stream":"xmrusdt@bookTicker","data":{"e":"bookTicker","u":335340958182,"s":"XMRUSDT","b":"352.46","B":"4.250","a":"352.57","A":"0.918","T":1618677460137,"E":1618677460141}}
1618677460.2513459: {"stream":"ksmusdt@bookTicker","data":{"e":"bookTicker","u":335340958160,"s":"KSMUSDT","b":"458.780","B":"0.6","a":"459.081","A":"1.5","T":1618677460136,"E":1618677460141}}
1618677460.2513669: {"stream":"yfiusdt@bookTicker","data":{"e":"bookTicker","u":335340958163,"s":"YFIUSDT","b":"49980.3","B":"0.002","a":"50000.4","A":"0.003","T":1618677460137,"E":1618677460141}}
1618677460.251385: {"stream":"yfiusdt@bookTicker","data":{"e":"bookTicker","u":335340958258,"s":"YFIUSDT","b":"49980.3","B":"0.002","a":"50000.3","A":"0.013","T":1618677460139,"E":1618677460142}}
1618677460.2516532: {"stream":"ksmusdt@bookTicker","data":{"e":"bookTicker","u":335340958462,"s":"KSMUSDT","b":"458.781","B":"0.4","a":"459.081","A":"1.5","T":1618677460156,"E":1618677460157}}
1618677460.251689: {"stream":"xmrusdt@depth@100ms","data":{"e":"depthUpdate","E":1618677460163,"T":1618677460148,"s":"XMRUSDT","U":335340956086,"u":335340958414,"pu":335340956051,"b":[["343.51","0.047"],["352.23","1.000"]],"a":[["352.57","0.918"],["352.58","0.000"],["352.61","0.000"],["353.72","2.520"],["353.88","0.000"]]}}
1618677460.279458: {"stream":"dentusdt@bookTicker","data":{"e":"bookTicker","u":335340958646,"s":"DENTUSDT","b":"0.012347","B":"32702","a":"0.012356","A":"9499","T":1618677460161,"E":1618677460165}}
1618677460.279574: {"stream":"yfiusdt@aggTrade","data":{"e":"aggTrade","E":1618677460168,"a":52599697,"s":"YFIUSDT","p":"49981.8","q":"0.003","f":64902175,"l":64902175,"T":1618677460012,"m":true}}
1618677460.279626: {"stream":"yfiusdt@bookTicker","data":{"e":"bookTicker","u":335340959085,"s":"YFIUSDT","b":"49980.3","B":"0.002","a":"50000.3","A":"0.035","T":1618677460180,"E":1618677460183}}
1618677460.279671: {"stream":"yfiusdt@bookTicker","data":{"e":"bookTicker","u":335340959087,"s":"YFIUSDT","b":"49980.3","B":"0.002","a":"49999.0","A":"0.009","T":1618677460180,"E":1618677460183}}
1618677460.2797031: {"stream":"ksmusdt@bookTicker","data":{"e":"bookTicker","u":335340959088,"s":"KSMUSDT","b":"458.781","B":"2.2","a":"459.081","A":"1.5","T":1618677460180,"E":1618677460184}}
1618677460.279732: {"stream":"dentusdt@bookTicker","data":{"e":"bookTicker","u":335340959184,"s":"DENTUSDT","b":"0.012348","B":"9195","a":"0.012356","A":"9499","T":1618677460184,"E":1618677460187}}
1618677460.27976: {"stream":"xmrusdt@bookTicker","data":{"e":"bookTicker","u":335340959257,"s":"XMRUSDT","b":"352.46","B":"4.250","a":"352.56","A":"3.039","T":1618677460185,"E":1618677460189}}
1618677460.279787: {"stream":"ksmusdt@bookTicker","data":{"e":"bookTicker","u":335340959509,"s":"KSMUSDT","b":"458.782","B":"0.3","a":"459.081","A":"1.5","T":1618677460194,"E":1618677460199}}
1618677460.2798212: {"stream":"ksmusdt@bookTicker","data":{"e":"bookTicker","u":335340959513,"s":"KSMUSDT","b":"458.782","B":"0.3","a":"459.080","A":"0.3","T":1618677460194,"E":1618677460199}}
1618677460.2798588: {"stream":"yfiusdt@bookTicker","data":{"e":"bookTicker","u":335340959832,"s":"YFIUSDT","b":"49980.3","B":"0.002","a":"49998.9","A":"0.017","T":1618677460200,"E":1618677460204}}
1618677460.279876: {"stream":"yfiusdt@bookTicker","data":{"e":"bookTicker","u":335340959962,"s":"YFIUSDT","b":"49980.3","B":"0.002","a":"49998.9","A":"0.020","T":1618677460204,"E":1618677460207}}
1618677460.279893: {"stream":"ksmusdt@bookTicker","data":{"e":"bookTicker","u":335340960098,"s":"KSMUSDT","b":"458.783","B":"2.0","a":"459.080","A":"0.3","T":1618677460206,"E":1618677460210}}
1618677460.2799091: {"stream":"yfiusdt@bookTicker","data":{"e":"bookTicker","u":335340960320,"s":"YFIUSDT","b":"49980.3","B":"0.002","a":"49997.6","A":"0.009","T":1618677460210,"E":1618677460214}}
1618677460.279926: {"stream":"ksmusdt@bookTicker","data":{"e":"bookTicker","u":335340960354,"s":"KSMUSDT","b":"458.783","B":"2.0","a":"459.080","A":"6.8","T":1618677460211,"E":1618677460215}}
1618677460.283301: {"stream":"dentusdt@depth@100ms","data":{"e":"depthUpdate","E":1618677460226,"T":1618677460218,"s":"DENTUSDT","U":335340958012,"u":335340960526,"pu":335340952062,"b":[["0.012312","199713"],["0.012323","23402"],["0.012324","53723"],["0.012325","729790"],["0.012339","100608"],["0.012347","32702"],["0.012348","9195"]],"a":[["0.012356","9499"],["0.012359","53972"],["0.012361","0"],["0.012363","407983"],["0.012364","123134"],["0.012365","49787"],["0.012371","11311"],["0.012380","360311"]]}}
1618677460.2877219: {"stream":"xmrusdt@bookTicker","data":{"e":"bookTicker","u":335340960824,"s":"XMRUSDT","b":"352.46","B":"3.700","a":"352.56","A":"3.039","T":1618677460226,"E":1618677460229}}
1618677460.28783: {"stream":"yfiusdt@bookTicker","data":{"e":"bookTicker","u":335340960826,"s":"YFIUSDT","b":"49980.3","B":"0.002","a":"49997.5","A":"0.009","T":1618677460226,"E":1618677460229}}
1618677460.2898052: {"stream":"xmrusdt@bookTicker","data":{"e":"bookTicker","u":335340960917,"s":"XMRUSDT","b":"352.46","B":"3.700","a":"352.57","A":"0.241","T":1618677460228,"E":1618677460232}}
1618677460.2899048: {"stream":"ksmusdt@depth@100ms","data":{"e":"depthUpdate","E":1618677460233,"T":1618677460218,"s":"KSMUSDT","U":335340958092,"u":335340960519,"pu":335340957847,"b":[["449.752","0.1"],["457.960","0.0"],["458.366","0.0"],["458.780","0.0"],["458.781","0.0"],["458.782","0.3"],["458.783","2.0"],["459.000","0.0"]],"a":[["459.080","6.8"],["459.081","0.0"],["459.083","0.0"],["459.214","0.0"],["459.216","0.0"],["459.623","0.0"],["459.723","1.4"],["460.117","1.0"]]}}
1618677460.296784: {"stream":"xmrusdt@bookTicker","data":{"e":"bookTicker","u":335340961159,"s":"XMRUSDT","b":"352.46","B":"3.700","a":"352.56","A":"3.019","T":1618677460236,"E":1618677460239}}
1618677460.2968829: {"stream":"yfiusdt@bookTicker","data":{"e":"bookTicker","u":335340961138,"s":"YFIUSDT","b":"49980.3","B":"0.002","a":"49997.6","A":"0.009","T":1618677460235,"E":1618677460239}}
1618677460.297281: {"stream":"yfiusdt@depth@100ms","data":{"e":"depthUpdate","E":1618677460241,"T":1618677460235,"s":"YFIUSDT","U":335340958163,"u":335340961138,"pu":335340957929,"b":[["47457.3","0.009"],["49778.0","0.042"],["49953.1","0.000"],["49953.2","0.058"],["49953.3","0.168"],["49974.5","0.005"]],"a":[["49997.5","0.000"],["49997.6","0.009"],["49998.5","0.055"],["49998.7","0.013"],["49998.8","0.000"],["49998.9","0.003"],["49999.0","0.000"],["49999.1","0.000"],["50000.2","0.000"],["50000.3","0.022"],["50000.4","0.000"],["50000.5","0.000"],["50000.6","0.004"],["50000.7","0.008"],["50000.8","0.000"],["50000.9","0.015"],["50001.8","0.000"],["50003.0","0.000"],["50003.6","0.117"],["50038.3","0.000"],["50041.4","0.000"],["50044.2","0.003"],["50045.8","0.000"],["50046.8","0.011"],["50048.9","0.000"],["50050.0","0.022"],["50051.6","0.000"],["50054.7","0.000"],["50086.4","0.013"],["50102.2","0.000"]]}}
1618677460.302191: {"stream":"xmrusdt@bookTicker","data":{"e":"bookTicker","u":335340961215,"s":"XMRUSDT","b":"352.46","B":"3.700","a":"352.57","A":"0.241","T":1618677460238,"E":1618677460243}}
1618677460.302291: {"stream":"ksmusdt@bookTicker","data":{"e":"bookTicker","u":335340961217,"s":"KSMUSDT","b":"458.783","B":"2.0","a":"459.080","A":"6.5","T":1618677460238,"E":1618677460243}}
1618677460.302335: {"stream":"ksmusdt@bookTicker","data":{"e":"bookTicker","u":335340961233,"s":"KSMUSDT","b":"458.783","B":"2.0","a":"459.058","A":"6.4","T":1618677460238,"E":1618677460243}}
1618677460.302367: {"stream":"yfiusdt@bookTicker","data":{"e":"bookTicker","u":335340961248,"s":"YFIUSDT","b":"49980.3","B":"0.002","a":"49997.5","A":"0.010","T":1618677460238,"E":1618677460243}}
1618677460.3024158: {"stream":"ksmusdt@bookTicker","data":{"e":"bookTicker","u":335340961277,"s":"KSMUSDT","b":"458.784","B":"0.3","a":"459.058","A":"6.4","T":1618677460239,"E":1618677460243}}
1618677460.302447: {"stream":"yfiusdt@bookTicker","data":{"e":"bookTicker","u":335340961285,"s":"YFIUSDT","b":"49980.3","B":"0.002","a":"49997.4","A":"0.003","T":1618677460239,"E":1618677460243}}
1618677460.308413: {"stream":"xmrusdt@bookTicker","data":{"e":"bookTicker","u":335340961600,"s":"XMRUSDT","b":"352.46","B":"3.700","a":"352.56","A":"2.903","T":1618677460246,"E":1618677460251}}
1618677460.310556: {"stream":"yfiusdt@bookTicker","data":{"e":"bookTicker","u":335340961718,"s":"YFIUSDT","b":"49980.3","B":"0.002","a":"49996.2","A":"0.009","T":1618677460249,"E":1618677460253}}
1618677460.5147789: {"stream":"xmrusdt@bookTicker","data":{"e":"bookTicker","u":335340961750,"s":"XMRUSDT","b":"352.46","B":"3.700","a":"352.57","A":"0.241","T":1618677460250,"E":1618677460254}}
1618677460.626295: {"stream":"ksmusdt@bookTicker","data":{"e":"bookTicker","u":335340961754,"s":"KSMUSDT","b":"458.785","B":"2.2","a":"459.058","A":"6.4","T":1618677460250,"E":1618677460254}}
1618677460.6263711: {"stream":"ksmusdt@aggTrade","data":{"e":"aggTrade","E":1618677460255,"a":21396985,"s":"KSMUSDT","p":"459.000","q":"1.5","f":25426578,"l":25426579,"T":1618677460101,"m":true}}
1618677460.626406: {"stream":"xmrusdt@bookTicker","data":{"e":"bookTicker","u":335340962005,"s":"XMRUSDT","b":"352.46","B":"3.700","a":"352.56","A":"2.874","T":1618677460258,"E":1618677460262}}
1618677460.62643: {"stream":"xmrusdt@depth@100ms","data":{"e":"depthUpdate","E":1618677460266,"T":1618677460261,"s":"XMRUSDT","U":335340958790,"u":335340962140,"pu":335340958414,"b":[["352.16","18.878"],["352.46","3.700"]],"a":[["352.56","2.874"],["352.57","0.241"],["352.58","0.410"],["352.60","0.000"],["352.61","0.224"],["352.69","13.111"],["354.48","0.243"]]}}
1618677460.626548: {"stream":"xmrusdt@bookTicker","data":{"e":"bookTicker","u":335340962194,"s":"XMRUSDT","b":"352.46","B":"3.700","a":"352.57","A":"0.241","T":1618677460262,"E":1618677460267}}
1618677460.6265721: {"stream":"yfiusdt@bookTicker","data":{"e":"bookTicker","u":335340962357,"s":"YFIUSDT","b":"49980.3","B":"0.002","a":"49995.1","A":"0.055","T":1618677460267,"E":1618677460270}}
1618677460.626592: {"stream":"dentusdt@aggTrade","data":{"e":"aggTrade","E":1618677460277,"a":8476421,"s":"DENTUSDT","p":"0.012347","q":"27895","f":15787411,"l":15787411,"T":1618677460122,"m":true}}
1618677460.626615: {"stream":"yfiusdt@bookTicker","data":{"e":"bookTicker","u":335340962714,"s":"YFIUSDT","b":"49980.3","B":"0.002","a":"49993.8","A":"0.009","T":1618677460277,"E":1618677460283}}
1618677460.626633: {"stream":"ksmusdt@bookTicker","data":{"e":"bookTicker","u":335340962856,"s":"KSMUSDT","b":"458.785","B":"2.2","a":"459.057","A":"0.3","T":1618677460281,"E":1618677460286}}
1618677460.62665: {"stream":"ksmusdt@bookTicker","data":{"e":"bookTicker","u":335340962860,"s":"KSMUSDT","b":"458.786","B":"0.3","a":"459.057","A":"0.3","T":1618677460281,"E":1618677460286}}
1618677460.626667: {"stream":"dentusdt@bookTicker","data":{"e":"bookTicker","u":335340963040,"s":"DENTUSDT","b":"0.012348","B":"9195","a":"0.012357","A":"53922","T":1618677460284,"E":1618677460290}}
1618677460.626685: {"stream":"dentusdt@bookTicker","data":{"e":"bookTicker","u":335340963575,"s":"DENTUSDT","b":"0.012348","B":"9195","a":"0.012356","A":"9400","T":1618677460298,"E":1618677460302}}
1618677460.626702: {"stream":"yfiusdt@bookTicker","data":{"e":"bookTicker","u":335340963825,"s":"YFIUSDT","b":"49980.3","B":"0.002","a":"49993.7","A":"0.003","T":1618677460305,"E":1618677460308}}
1618677460.626719: {"stream":"yfiusdt@bookTicker","data":{"e":"bookTicker","u":335340963912,"s":"YFIUSDT","b":"49980.3","B":"0.002","a":"49993.7","A":"0.035","T":1618677460307,"E":1618677460312}}
1618677460.62674: {"stream":"xmrusdt@bookTicker","data":{"e":"bookTicker","u":335340964085,"s":"XMRUSDT","b":"352.47","B":"2.500","a":"352.57","A":"0.241","T":1618677460315,"E":1618677460319}}
1618677460.6267579: {"stream":"yfiusdt@bookTicker","data":{"e":"bookTicker","u":335340964219,"s":"YFIUSDT","b":"49980.3","B":"0.002","a":"49992.4","A":"0.009","T":1618677460318,"E":1618677460321}}
1618677460.626775: {"stream":"xmrusdt@bookTicker","data":{"e":"bookTicker","u":335340964480,"s":"XMRUSDT","b":"352.47","B":"2.500","a":"352.57","A":"3.193","T":1618677460326,"E":1618677460330}}
1618677460.626792: {"stream":"ksmusdt@depth@100ms","data":{"e":"depthUpdate","E":1618677460339,"T":1618677460321,"s":"KSMUSDT","U":335340961142,"u":335340964350,"pu":335340960519,"b":[["449.709","19.8"],["453.730","20.0"],["454.265","0.4"],["454.490","0.2"],["454.790","0.7"],["455.460","0.2"],["457.960","0.0"],["457.977","0.4"],["458.273","0.0"],["458.758","0.0"],["458.778","0.0"],["458.782","0.0"],["458.783","0.0"],["458.784","0.0"],["458.785","0.0"],["458.786","0.3"]],"a":[["459.057","0.3"],["459.058","6.4"],["459.076","0.0"],["459.079","0.0"],["459.080","6.5"],["459.132","0.0"],["459.215","0.0"],["459.247","1.6"],["459.881","1.0"],["460.117","0.0"],["460.275","10.2"],["461.642","3.3"],["461.773","19.6"],["463.066","0.2"],["463.268","0.2"],["463.985","0.0"],["464.190","0.0"]]}}
1618677460.627025: {"stream":"yfiusdt@bookTicker","data":{"e":"bookTicker","u":335340964814,"s":"YFIUSDT","b":"49980.3","B":"0.002","a":"49992.3","A":"0.003","T":1618677460338,"E":1618677460342}}
1618677460.62705: {"stream":"yfiusdt@depth@100ms","data":{"e":"depthUpdate","E":1618677460343,"T":1618677460338,"s":"YFIUSDT","U":335340961232,"u":335340964814,"pu":335340961138,"b":[["48524.3","0.047"],["49531.3","0.013"],["49953.2","0.012"],["49953.4","0.043"],["49953.5","0.042"],["49957.0","0.017"],["49957.1","0.010"],["49959.8","0.012"],["49974.5","0.000"]],"a":[["49992.3","0.003"],["49992.4","0.009"],["49993.6","0.030"],["49993.7","0.000"],["49993.8","0.000"],["49995.1","0.055"],["49996.1","0.000"],["49996.2","0.000"],["49997.3","0.000"],["49997.4","0.000"],["49997.5","0.000"],["49997.6","0.000"],["49998.0","0.000"],["49998.4","0.000"],["49998.7","0.000"],["49998.8","0.000"],["49998.9","0.000"],["50000.2","0.000"],["50000.3","0.022"],["50000.4","0.000"],["50000.6","0.000"],["50000.7","0.000"],["50000.9","0.000"],["50001.0","0.000"],["50001.2","0.013"],["50031.9","0.027"],["50032.9","0.013"],["50041.2","0.000"],["50042.6","0.027"],["50044.2","0.000"],["50046.8","0.000"],["50050.0","0.019"],["50052.0","0.000"],["50054.3","0.027"],["50060.1","0.027"],["50239.0","0.000"],["50273.7","0.000"]]}}
1618677460.62733: {"stream":"dentusdt@depth@100ms","data":{"e":"depthUpdate","E":1618677460345,"T":1618677460328,"s":"DENTUSDT","U":335340961343,"u":335340964536,"pu":335340960526,"b":[["0.012104","299451"]],"a":[["0.012356","9400"],["0.012357","53922"],["0.012358","74368"],["0.012359","0"],["0.012360","42836"],["0.012365","0"],["0.012401","532456"]]}}
1618677460.6274061: {"stream":"xmrusdt@bookTicker","data":{"e":"bookTicker","u":335340965060,"s":"XMRUSDT","b":"352.48","B":"3.700","a":"352.57","A":"3.193","T":1618677460345,"E":1618677460348}}
1618677460.627429: {"stream":"yfiusdt@bookTicker","data":{"e":"bookTicker","u":335340965445,"s":"YFIUSDT","b":"49980.3","B":"0.002","a":"49991.0","A":"0.009","T":1618677460353,"E":1618677460357}}
1618677460.627448: {"stream":"xmrusdt@depth@100ms","data":{"e":"depthUpdate","E":1618677460367,"T":1618677460357,"s":"XMRUSDT","U":335340962194,"u":335340965577,"pu":335340962140,"b":[["352.06","2.269"],["352.32","0.000"],["352.35","0.000"],["352.37","6.019"],["352.41","2.500"],["352.44","0.000"],["352.47","0.000"],["352.48","3.700"]],"a":[["352.56","0.000"],["352.57","3.193"],["352.58","0.000"],["352.59","0.000"],["352.60","0.000"]]}}
1618677460.62755: {"stream":"dentusdt@bookTicker","data":{"e":"bookTicker","u":335340967238,"s":"DENTUSDT","b":"0.012348","B":"9195","a":"0.012356","A":"63322","T":1618677460405,"E":1618677460409}}
1618677460.627573: {"stream":"ksmusdt@bookTicker","data":{"e":"bookTicker","u":335340967662,"s":"KSMUSDT","b":"458.757","B":"1.3","a":"459.057","A":"0.3","T":1618677460421,"E":1618677460424}}
1618677460.6275918: {"stream":"yfiusdt@depth@100ms","data":{"e":"depthUpdate","E":1618677460446,"T":1618677460430,"s":"YFIUSDT","U":335340964925,"u":335340967936,"pu":335340964814,"b":[["49654.1","0.010"],["49944.1","0.000"],["49944.2","0.261"],["49957.1","0.022"]],"a":[["49991.0","0.009"],["49992.4","0.000"],["49993.6","0.000"],["49998.5","0.000"]]}}
1618677460.627669: {"stream":"ksmusdt@depth@100ms","data":{"e":"depthUpdate","E":1618677460450,"T":1618677460440,"s":"KSMUSDT","U":335340965068,"u":335340968226,"pu":335340964350,"b":[["453.239","0.2"],["454.157","0.2"],["454.274","0.2"],["454.490","0.0"],["454.561","0.8"],["454.782","0.2"],["454.874","0.0"],["455.153","0.5"],["455.214","0.2"],["455.460","0.0"],["455.480","0.0"],["455.497","0.2"],["455.702","0.4"],["455.793","0.6"],["455.805","0.0"],["457.960","0.0"],["458.342","0.0"],["458.343","0.0"],["458.424","15.9"],["458.617","2.9"],["458.618","5.2"],["458.701","0.6"],["458.749","0.0"],["458.756","0.0"],["458.786","0.0"]],"a":[["459.881","1.0"],["460.093","5.8"],["462.953","0.0"],["463.026","0.0"],["463.041","0.0"],["463.266","0.0"],["463.271","0.4"],["463.285","0.0"],["463.304","0.0"],["463.513","0.0"],["463.711","0.0"],["463.960","0.0"],["463.963","0.2"],["464.045","0.0"],["464.185","0.0"],["464.187","0.2"],["464.204","0.0"],["464.431","0.0"]]}}
1618677460.627936: {"stream":"dentusdt@depth@100ms","data":{"e":"depthUpdate","E":1618677460452,"T":1618677460414,"s":"DENTUSDT","U":335340965296,"u":335340967474,"pu":335340964536,"b":[["0.012266","876060"],["0.012275","466666"]],"a":[["0.012356","63322"],["0.012357","53972"],["0.012358","33889"],["0.012359","40479"],["0.012362","231023"],["0.012363","274102"],["0.012365","49787"],["0.012378","39840"],["0.012384","65954"],["0.012447","0"]]}}
1618677460.628025: {"stream":"ksmusdt@bookTicker","data":{"e":"bookTicker","u":335340968686,"s":"KSMUSDT","b":"458.757","B":"1.3","a":"459.056","A":"1.6","T":1618677460458,"E":1618677460462}}
1618677460.628048: {"stream":"dentusdt@bookTicker","data":{"e":"bookTicker","u":335340968944,"s":"DENTUSDT","b":"0.012348","B":"9195","a":"0.012356","A":"79350","T":1618677460465,"E":1618677460469}}
1618677460.628067: {"stream":"xmrusdt@depth@100ms","data":{"e":"depthUpdate","E":1618677460472,"T":1618677460466,"s":"XMRUSDT","U":335340965941,"u":335340968982,"pu":335340965577,"b":[["351.52","4.941"],["351.54","13.938"],["351.60","0.073"],["352.15","6.719"],["352.16","2.966"],["352.17","1.031"],["352.23","0.000"],["352.31","0.000"],["352.32","2.500"],["352.41","0.000"],["352.46","0.000"]],"a":[["352.61","0.780"],["352.81","2.500"],["357.71","1.175"]]}}
1618677460.628163: {"stream":"yfiusdt@bookTicker","data":{"e":"bookTicker","u":335340969303,"s":"YFIUSDT","b":"49980.3","B":"0.002","a":"49991.0","A":"0.012","T":1618677460475,"E":1618677460479}}
1618677460.628185: {"stream":"yfiusdt@bookTicker","data":{"e":"bookTicker","u":335340969591,"s":"YFIUSDT","b":"49980.3","B":"0.002","a":"49991.0","A":"0.003","T":1618677460484,"E":1618677460487}}
1618677460.628203: {"stream":"yfiusdt@bookTicker","data":{"e":"bookTicker","u":335340969603,"s":"YFIUSDT","b":"49980.3","B":"0.002","a":"49989.7","A":"0.009","T":1618677460485,"E":1618677460489}}
1618677460.6282198: {"stream":"ksmusdt@bookTicker","data":{"e":"bookTicker","u":335340969822,"s":"KSMUSDT","b":"458.757","B":"1.3","a":"459.055","A":"0.3","T":1618677460491,"E":1618677460494}}
1618677460.628237: {"stream":"ksmusdt@bookTicker","data":{"e":"bookTicker","u":335340969931,"s":"KSMUSDT","b":"458.757","B":"1.3","a":"459.034","A":"6.4","T":1618677460494,"E":1618677460498}}
1618677460.628254: {"stream":"dentusdt@bookTicker","data":{"e":"bookTicker","u":335340969977,"s":"DENTUSDT","b":"0.012348","B":"9195","a":"0.012356","A":"25428","T":1618677460495,"E":1618677460499}}
1618677460.628271: {"stream":"xmrusdt@bookTicker","data":{"e":"bookTicker","u":335340970304,"s":"XMRUSDT","b":"352.48","B":"3.700","a":"352.56","A":"3.700","T":1618677460505,"E":1618677460508}}
1618677460.628288: {"stream":"xmrusdt@bookTicker","data":{"e":"bookTicker","u":335340970601,"s":"XMRUSDT","b":"352.48","B":"3.700","a":"352.55","A":"3.001","T":1618677460514,"E":1618677460519}}
1618677460.628305: {"stream":"ksmusdt@bookTicker","data":{"e":"bookTicker","u":335340971012,"s":"KSMUSDT","b":"458.757","B":"1.3","a":"459.033","A":"0.3","T":1618677460530,"E":1618677460534}}
1618677460.628672: {"stream":"dentusdt@kline_1m","data":{"e":"kline","E":1618677460543,"s":"DENTUSDT","k":{"t":1618677420000,"T":1618677479999,"s":"DENTUSDT","i":"1m","f":15787262,"L":15787412,"o":"0.012366","c":"0.012348","h":"0.012366","l":"0.012339","v":"2548022","n":151,"x":false,"q":"31473.309324","V":"1138342","Q":"14064.554712","B":"0"}}}
1618677460.628714: {"stream":"ksmusdt@bookTicker","data":{"e":"bookTicker","u":335340971227,"s":"KSMUSDT","b":"458.746","B":"0.2","a":"459.033","A":"0.3","T":1618677460539,"E":1618677460543}}
1618677460.6287339: {"stream":"dentusdt@bookTicker","data":{"e":"bookTicker","u":335340971274,"s":"DENTUSDT","b":"0.012348","B":"4602","a":"0.012356","A":"25428","T":1618677460541,"E":1618677460543}}
1618677460.62875: {"stream":"ksmusdt@depth@100ms","data":{"e":"depthUpdate","E":1618677460552,"T":1618677460540,"s":"KSMUSDT","U":335340968455,"u":335340971259,"pu":335340968226,"b":[["455.793","0.4"],["457.960","1.1"],["458.757","0.0"]],"a":[["459.033","0.3"],["459.034","6.4"],["459.050","0.0"],["459.055","0.0"],["459.056","1.6"],["459.057","0.0"],["459.082","0.0"],["459.247","0.0"],["459.881","0.0"],["463.044","0.2"],["463.148","0.0"],["463.945","0.2"],["464.067","0.2"]]}}
1618677460.6288629: {"stream":"yfiusdt@depth@100ms","data":{"e":"depthUpdate","E":1618677460552,"T":1618677460520,"s":"YFIUSDT","U":335340968434,"u":335340970739,"pu":335340967936,"b":[["49823.1","0.001"],["49953.2","0.000"],["49957.1","0.012"],["49957.7","0.000"],["49957.8","0.000"],["49957.9","0.008"],["49959.8","0.000"]],"a":[["49989.7","0.009"],["49991.0","0.003"],["49992.3","0.000"],["50003.4","0.000"]]}}
1618677460.6289349: {"stream":"xmrusdt@bookTicker","data":{"e":"bookTicker","u":335340971411,"s":"XMRUSDT","b":"352.48","B":"3.700","a":"352.55","A":"6.701","T":1618677460548,"E":1618677460552}}
1618677460.6289542: {"stream":"dentusdt@depth@100ms","data":{"e":"depthUpdate","E":1618677460556,"T":1618677460549,"s":"DENTUSDT","U":335340968543,"u":335340971441,"pu":335340967474,"b":[["0.000011","20805663"],["0.011912","192812"],["0.012159","91155"],["0.012240","46707"],["0.012299","105697"],["0.012322","81499"],["0.012348","4602"]],"a":[["0.012356","25428"],["0.012357","107894"],["0.012358","41734"],["0.012359","0"],["0.012360","17393"],["0.012361","40479"],["0.012363","225531"],["0.012365","49787"],["0.012366","0"],["0.012401","152605"]]}}
1618677460.629046: {"stream":"yfiusdt@bookTicker","data":{"e":"bookTicker","u":335340971641,"s":"YFIUSDT","b":"49980.3","B":"0.002","a":"49989.7","A":"0.003","T":1618677460558,"E":1618677460561}}
1618677460.6290638: {"stream":"yfiusdt@kline_1m","data":{"e":"kline","E":1618677460562,"s":"YFIUSDT","k":{"t":1618677420000,"T":1618677479999,"s":"YFIUSDT","i":"1m","f":64902095,"L":64902176,"o":"50010.8","c":"49989.7","h":"50044.2","l":"49950.6","v":"0.983","n":82,"x":false,"q":"49148.8297","V":"0.675","Q":"33749.4659","B":"0"}}}
1618677460.661092: {"stream":"yfiusdt@bookTicker","data":{"e":"bookTicker","u":335340971729,"s":"YFIUSDT","b":"49980.3","B":"0.002","a":"49989.6","A":"0.003","T":1618677460560,"E":1618677460565}}
1618677460.661192: {"stream":"ksmusdt@bookTicker","data":{"e":"bookTicker","u":335340971769,"s":"KSMUSDT","b":"458.746","B":"0.2","a":"459.032","A":"1.6","T":1618677460562,"E":1618677460566}}
1618677460.661234: {"stream":"dentusdt@bookTicker","data":{"e":"bookTicker","u":335340971962,"s":"DENTUSDT","b":"0.012348","B":"4602","a":"0.012356","A":"30368","T":1618677460571,"E":1618677460575}}
1618677460.661269: {"stream":"ksmusdt@bookTicker","data":{"e":"bookTicker","u":335340972040,"s":"KSMUSDT","b":"458.746","B":"0.2","a":"459.025","A":"1.2","T":1618677460574,"E":1618677460578}}
1618677460.661299: {"stream":"dentusdt@bookTicker","data":{"e":"bookTicker","u":335340972152,"s":"DENTUSDT","b":"0.012347","B":"32702","a":"0.012356","A":"30368","T":1618677460579,"E":1618677460583}}
1618677460.6613262: {"stream":"xmrusdt@depth@100ms","data":{"e":"depthUpdate","E":1618677460592,"T":1618677460572,"s":"XMRUSDT","U":335340969723,"u":335340971987,"pu":335340968982,"b":[["352.06","0.000"],["352.30","2.500"],["352.32","0.000"],["352.38","0.000"]],"a":[["352.55","6.701"],["352.56","0.000"],["352.57","0.241"],["352.61","0.224"],["354.50","0.847"],["356.63","200.000"]]}}
1618677460.67666: {"stream":"yfiusdt@bookTicker","data":{"e":"bookTicker","u":335340972589,"s":"YFIUSDT","b":"49980.3","B":"0.002","a":"49989.7","A":"0.003","T":1618677460599,"E":1618677460602}}
1618677460.676759: {"stream":"ksmusdt@bookTicker","data":{"e":"bookTicker","u":335340972708,"s":"KSMUSDT","b":"458.746","B":"0.2","a":"459.024","A":"0.3","T":1618677460605,"E":1618677460608}}
1618677460.676801: {"stream":"ksmusdt@bookTicker","data":{"e":"bookTicker","u":335340972758,"s":"KSMUSDT","b":"458.746","B":"0.2","a":"459.003","A":"6.4","T":1618677460606,"E":1618677460611}}
1618677460.69536: {"stream":"yfiusdt@bookTicker","data":{"e":"bookTicker","u":335340973259,"s":"YFIUSDT","b":"49980.3","B":"0.002","a":"49985.0","A":"0.001","T":1618677460633,"E":1618677460636}}
1618677460.710363: {"stream":"ksmusdt@bookTicker","data":{"e":"bookTicker","u":335340973525,"s":"KSMUSDT","b":"458.746","B":"0.2","a":"459.002","A":"0.3","T":1618677460646,"E":1618677460651}}
1618677460.71047: {"stream":"ksmusdt@depth@100ms","data":{"e":"depthUpdate","E":1618677460652,"T":1618677460646,"s":"KSMUSDT","U":335340971400,"u":335340973525,"pu":335340971259,"b":[["454.513","1.1"],["454.783","0.6"],["455.408","0.2"],["457.960","1.1"],["457.977","0.0"],["458.619","1.3"]],"a":[["459.002","0.3"],["459.003","6.4"],["459.024","0.0"],["459.025","1.2"],["459.032","1.6"],["459.033","0.0"],["459.046","0.0"],["459.056","0.0"],["459.058","0.0"],["459.634","1.4"],["459.723","0.0"],["459.881","0.0"],["466.894","0.0"]]}}
1618677460.7135448: {"stream":"dentusdt@depth@100ms","data":{"e":"depthUpdate","E":1618677460656,"T":1618677460610,"s":"DENTUSDT","U":335340971502,"u":335340972825,"pu":335340971441,"b":[["0.012287","150868"],["0.012324","164833"],["0.012348","0"]],"a":[["0.012356","30368"],["0.012357","53972"],["0.012358","12165"],["0.012360","41812"],["0.012361","0"],["0.012367","351959"]]}}
1618677460.715602: {"stream":"dentusdt@bookTicker","data":{"e":"bookTicker","u":335340973645,"s":"DENTUSDT","b":"0.012347","B":"32702","a":"0.012356","A":"84290","T":1618677460653,"E":1618677460659}}
1618677460.816339: {"stream":"yfiusdt@depth@100ms","data":{"e":"depthUpdate","E":1618677460661,"T":1618677460657,"s":"YFIUSDT","U":335340971641,"u":335340973711,"pu":335340970739,"b":[["48788.7","0.010"],["49530.5","0.083"],["49535.5","0.000"],["49755.4","0.083"],["49760.4","0.000"],["49874.3","0.000"],["49957.9","0.000"],["49958.0","0.010"]],"a":[["49985.0","0.001"],["49989.6","0.000"],["49989.7","0.000"],["49991.0","0.000"],["49995.0","0.003"],["50003.6","0.000"],["50006.0","0.000"],["50040.3","0.012"],["50046.2","0.026"],["50054.3","0.000"],["50060.1","0.000"],["50109.5","0.025"],["50119.8","0.000"],["50128.8","0.000"],["50195.3","0.008"],["50205.1","0.087"],["50210.2","0.000"],["50430.0","0.083"],["50435.1","0.000"]]}}
1618677460.816688: {"stream":"ksmusdt@bookTicker","data":{"e":"bookTicker","u":335340973810,"s":"KSMUSDT","b":"458.746","B":"0.2","a":"459.001","A":"1.6","T":1618677460661,"E":1618677460665}}
1618677460.816724: {"stream":"dentusdt@bookTicker","data":{"e":"bookTicker","u":335340974069,"s":"DENTUSDT","b":"0.012347","B":"32702","a":"0.012356","A":"79350","T":1618677460674,"E":1618677460678}}
1618677460.816749: {"stream":"ksmusdt@bookTicker","data":{"e":"bookTicker","u":335340974349,"s":"KSMUSDT","b":"458.746","B":"0.2","a":"459.000","A":"0.3","T":1618677460686,"E":1618677460689}}
1618677460.8167691: {"stream":"ksmusdt@bookTicker","data":{"e":"bookTicker","u":335340974413,"s":"KSMUSDT","b":"458.746","B":"0.2","a":"458.979","A":"6.4","T":1618677460690,"E":1618677460693}}
1618677460.816787: {"stream":"dentusdt@aggTrade","data":{"e":"aggTrade","E":1618677460694,"a":8476422,"s":"DENTUSDT","p":"0.012348","q":"4593","f":15787412,"l":15787412,"T":1618677460541,"m":true}}
1618677460.816812: {"stream":"dentusdt@bookTicker","data":{"e":"bookTicker","u":335340974430,"s":"DENTUSDT","b":"0.012347","B":"32702","a":"0.012356","A":"63322","T":1618677460690,"E":1618677460695}}
1618677460.8168309: {"stream":"xmrusdt@depth@100ms","data":{"e":"depthUpdate","E":1618677460702,"T":1618677460610,"s":"XMRUSDT","U":335340972578,"u":335340972826,"pu":335340971987,"b":[],"a":[["354.62","210.742"],["356.63","0.000"]]}}
1618677460.8168802: {"stream":"yfiusdt@aggTrade","data":{"e":"aggTrade","E":1618677460712,"a":52599698,"s":"YFIUSDT","p":"49989.7","q":"0.006","f":64902176,"l":64902176,"T":1618677460558,"m":false}}
1618677460.8169029: {"stream":"yfiusdt@bookTicker","data":{"e":"bookTicker","u":335340975256,"s":"YFIUSDT","b":"49980.3","B":"0.002","a":"49983.7","A":"0.006","T":1618677460724,"E":1618677460727}}
1618677460.8169222: {"stream":"ksmusdt@bookTicker","data":{"e":"bookTicker","u":335340975369,"s":"KSMUSDT","b":"458.746","B":"0.2","a":"458.978","A":"0.3","T":1618677460727,"E":1618677460730}}
1618677460.822701: {"stream":"ksmusdt@depth@100ms","data":{"e":"depthUpdate","E":1618677460755,"T":1618677460749,"s":"KSMUSDT","U":335340973605,"u":335340975908,"pu":335340973525,"b":[["454.157","0.0"],["454.498","0.0"],["454.561","0.4"],["454.782","0.0"],["454.783","0.4"],["455.497","0.0"],["455.702","0.0"],["458.618","3.9"]],"a":[["458.978","0.3"],["458.979","6.4"],["459.000","0.0"],["459.001","1.6"],["459.002","0.0"],["459.025","0.0"],["459.032","0.0"],["459.034","0.0"],["459.881","1.0"],["460.811","0.0"],["462.092","0.0"],["462.771","0.0"],["463.064","0.0"],["463.244","0.0"],["463.339","0.0"],["463.550","0.0"],["463.983","0.0"],["464.163","0.2"]]}}
1618677460.823093: {"stream":"yfiusdt@bookTicker","data":{"e":"bookTicker","u":335340975964,"s":"YFIUSDT","b":"49980.3","B":"0.002","a":"49982.0","A":"0.002","T":1618677460751,"E":1618677460755}}
1618677460.8231292: {"stream":"dentusdt@depth@100ms","data":{"e":"depthUpdate","E":1618677460757,"T":1618677460696,"s":"DENTUSDT","U":335340973636,"u":335340974555,"pu":335340972825,"b":[],"a":[["0.012356","63322"],["0.012357","0"],["0.012358","33132"],["0.012359","40481"],["0.012361","53975"],["0.012365","0"],["0.012366","49787"]]}}
1618677460.823219: {"stream":"xmrusdt@bookTicker","data":{"e":"bookTicker","u":335340976143,"s":"XMRUSDT","b":"352.40","B":"0.452","a":"352.55","A":"6.701","T":1618677460757,"E":1618677460760}}
1618677460.823246: {"stream":"yfiusdt@depth@100ms","data":{"e":"depthUpdate","E":1618677460762,"T":1618677460756,"s":"YFIUSDT","U":335340973723,"u":335340976138,"pu":335340973711,"b":[["49890.7","0.021"]],"a":[["49982.0","0.002"],["49983.7","0.006"],["50031.9","0.000"],["50036.1","0.003"],["50042.6","0.000"],["50046.8","0.003"],["50096.8","0.401"],["50212.8","0.007"]]}}
1618677460.8233469: {"stream":"yfiusdt@bookTicker","data":{"e":"bookTicker","u":335340976235,"s":"YFIUSDT","b":"49981.6","B":"0.009","a":"49982.0","A":"0.002","T":1618677460759,"E":1618677460763}}
1618677460.824848: {"stream":"dentusdt@bookTicker","data":{"e":"bookTicker","u":335340976389,"s":"DENTUSDT","b":"0.012347","B":"32702","a":"0.012356","A":"47089","T":1618677460763,"E":1618677460765}}
1618677460.827591: {"stream":"ksmusdt@bookTicker","data":{"e":"bookTicker","u":335340976420,"s":"KSMUSDT","b":"458.746","B":"0.2","a":"458.977","A":"1.6","T":1618677460764,"E":1618677460769}}
1618677460.837858: {"stream":"dentusdt@bookTicker","data":{"e":"bookTicker","u":335340976764,"s":"DENTUSDT","b":"0.012347","B":"32702","a":"0.012356","A":"56170","T":1618677460776,"E":1618677460781}}
1618677460.8379588: {"stream":"yfiusdt@bookTicker","data":{"e":"bookTicker","u":335340976785,"s":"YFIUSDT","b":"49981.6","B":"0.009","a":"49981.8","A":"0.001","T":1618677460777,"E":1618677460781}}
1618677460.8474848: {"stream":"xmrusdt@bookTicker","data":{"e":"bookTicker","u":335340976964,"s":"XMRUSDT","b":"352.40","B":"0.452","a":"352.55","A":"7.257","T":1618677460785,"E":1618677460790}}
1618677460.8475919: {"stream":"xmrusdt@bookTicker","data":{"e":"bookTicker","u":335340977013,"s":"XMRUSDT","b":"352.41","B":"3.700","a":"352.55","A":"7.257","T":1618677460786,"E":1618677460790}}
1618677460.855807: {"stream":"ksmusdt@bookTicker","data":{"e":"bookTicker","u":335340977165,"s":"KSMUSDT","b":"458.746","B":"0.2","a":"458.976","A":"0.3","T":1618677460792,"E":1618677460797}}
1618677460.856499: {"stream":"ksmusdt@bookTicker","data":{"e":"bookTicker","u":335340977257,"s":"KSMUSDT","b":"458.746","B":"0.2","a":"458.955","A":"6.4","T":1618677460793,"E":1618677460798}}
1618677460.863908: {"stream":"yfiusdt@bookTicker","data":{"e":"bookTicker","u":335340977570,"s":"YFIUSDT","b":"49981.7","B":"0.017","a":"49981.8","A":"0.001","T":1618677460801,"E":1618677460805}}
1618677460.864009: {"stream":"dentusdt@bookTicker","data":{"e":"bookTicker","u":335340977587,"s":"DENTUSDT","b":"0.012347","B":"32702","a":"0.012356","A":"9081","T":1618677460801,"E":1618677460805}}
1618677460.86621: {"stream":"xmrusdt@depth@100ms","data":{"e":"depthUpdate","E":1618677460808,"T":1618677460800,"s":"XMRUSDT","U":335340974719,"u":335340977555,"pu":335340972826,"b":[["351.92","0.446"],["351.96","18.523"],["352.19","1.250"],["352.24","0.000"],["352.26","11.188"],["352.35","6.019"],["352.37","0.000"],["352.41","3.700"],["352.48","0.000"]],"a":[["352.55","7.257"],["357.19","0.000"]]}}
1618677460.872712: {"stream":"yfiusdt@bookTicker","data":{"e":"bookTicker","u":335340977867,"s":"YFIUSDT","b":"49981.7","B":"0.026","a":"49981.8","A":"0.001","T":1618677460811,"E":1618677460816}}
1618677460.874885: {"stream":"dentusdt@bookTicker","data":{"e":"bookTicker","u":335340977913,"s":"DENTUSDT","b":"0.012347","B":"32702","a":"0.012358","A":"33132","T":1618677460813,"E":1618677460818}}
1618677460.886989: {"stream":"dentusdt@bookTicker","data":{"e":"bookTicker","u":335340978281,"s":"DENTUSDT","b":"0.012347","B":"32702","a":"0.012357","A":"9421","T":1618677460825,"E":1618677460829}}
1618677460.8904388: {"stream":"xmrusdt@bookTicker","data":{"e":"bookTicker","u":335340978389,"s":"XMRUSDT","b":"352.41","B":"3.700","a":"352.55","A":"6.701","T":1618677460828,"E":1618677460833}}
1618677460.890539: {"stream":"ksmusdt@bookTicker","data":{"e":"bookTicker","u":335340978425,"s":"KSMUSDT","b":"458.746","B":"0.2","a":"458.954","A":"0.3","T":1618677460828,"E":1618677460833}}
1618677460.8978639: {"stream":"dentusdt@bookTicker","data":{"e":"bookTicker","u":335340978602,"s":"DENTUSDT","b":"0.012347","B":"32702","a":"0.012357","A":"56510","T":1618677460836,"E":1618677460840}}
1618677460.913253: {"stream":"ksmusdt@bookTicker","data":{"e":"bookTicker","u":335340979036,"s":"KSMUSDT","b":"458.746","B":"0.2","a":"458.901","A":"3.2","T":1618677460850,"E":1618677460855}}
1618677460.913354: {"stream":"ksmusdt@bookTicker","data":{"e":"bookTicker","u":335340979087,"s":"KSMUSDT","b":"458.746","B":"0.2","a":"458.954","A":"0.3","T":1618677460853,"E":1618677460857}}
1618677460.917669: {"stream":"ksmusdt@depth@100ms","data":{"e":"depthUpdate","E":1618677460860,"T":1618677460853,"s":"KSMUSDT","U":335340976140,"u":335340979087,"pu":335340975908,"b":[["453.357","0.0"],["454.296","0.2"],["455.192","0.0"],["455.408","0.0"],["456.096","0.0"],["456.989","0.0"],["457.960","0.0"],["458.424","0.0"],["458.691","0.0"]],"a":[["458.901","0.0"],["458.954","0.3"],["458.955","6.4"],["458.976","0.0"],["458.977","1.6"],["458.978","0.0"],["459.001","0.0"],["459.003","0.0"],["459.881","1.0"],["463.044","0.0"],["463.897","0.0"],["463.963","0.0"],["464.163","0.0"],["464.468","0.0"],["464.816","0.0"]]}}
1618677460.91808: {"stream":"yfiusdt@depth@100ms","data":{"e":"depthUpdate","E":1618677460862,"T":1618677460811,"s":"YFIUSDT","U":335340976221,"u":335340977867,"pu":335340976138,"b":[["48622.6","0.049"],["49709.5","0.000"],["49957.0","0.000"],["49981.6","0.000"],["49981.7","0.026"]],"a":[["49981.8","0.001"],["49983.7","0.000"],["50109.5","0.000"]]}}
1618677460.920822: {"stream":"dentusdt@depth@100ms","data":{"e":"depthUpdate","E":1618677460864,"T":1618677460858,"s":"DENTUSDT","U":335340976296,"u":335340979273,"pu":335340974555,"b":[["0.012337","30241"],["0.012339","3446"],["0.012340","328736"],["0.012341","65339"]],"a":[["0.012356","0"],["0.012357","56510"],["0.012359","0"],["0.012360","95784"],["0.012361","0"],["0.012364","65196"],["0.012366","0"],["0.012371","0"]]}}
1618677460.955185: {"stream":"yfiusdt@bookTicker","data":{"e":"bookTicker","u":335340980274,"s":"YFIUSDT","b":"49981.7","B":"0.017","a":"49981.8","A":"0.001","T":1618677460893,"E":1618677460898}}
1618677460.9552882: {"stream":"yfiusdt@bookTicker","data":{"e":"bookTicker","u":335340980297,"s":"YFIUSDT","b":"49981.7","B":"0.017","a":"49981.8","A":"0.007","T":1618677460893,"E":1618677460898}}
1618677460.9733849: {"stream":"dentusdt@bookTicker","data":{"e":"bookTicker","u":335340980923,"s":"DENTUSDT","b":"0.012347","B":"32702","a":"0.012357","A":"9421","T":1618677460912,"E":1618677460915}}
1618677460.973485: {"stream":"dentusdt@aggTrade","data":{"e":"aggTrade","E":1618677460916,"a":8476423,"s":"DENTUSDT","p":"0.012356","q":"16233","f":15787413,"l":15787414,"T":1618677460763,"m":false}}
1618677460.987252: {"stream":"xmrusdt@depth@100ms","data":{"e":"depthUpdate","E":1618677460929,"T":1618677460904,"s":"XMRUSDT","U":335340978256,"u":335340980698,"pu":335340977555,"b":[["351.45","0.040"],["351.65","2.500"],["352.06","15.912"],["352.19","0.000"],["352.30","0.000"]],"a":[["352.55","6.701"],["353.37","56.724"],["357.21","1.763"]]}}
1618677460.9977448: {"stream":"xmrusdt@bookTicker","data":{"e":"bookTicker","u":335340981556,"s":"XMRUSDT","b":"352.41","B":"3.700","a":"352.55","A":"7.257","T":1618677460932,"E":1618677460937}}
1618677461.006289: {"stream":"ksmusdt@bookTicker","data":{"e":"bookTicker","u":335340981926,"s":"KSMUSDT","b":"458.746","B":"0.2","a":"458.955","A":"6.4","T":1618677460944,"E":1618677460948}}
1618677461.013712: {"stream":"dentusdt@bookTicker","data":{"e":"bookTicker","u":335340982144,"s":"DENTUSDT","b":"0.012347","B":"32702","a":"0.012357","A":"56510","T":1618677460952,"E":1618677460956}}
1618677461.023318: {"stream":"ksmusdt@depth@100ms","data":{"e":"depthUpdate","E":1618677460964,"T":1618677460955,"s":"KSMUSDT","U":335340979306,"u":335340982248,"pu":335340979087,"b":[["453.239","0.0"],["457.960","0.0"],["458.616","0.0"],["458.617","1.5"]],"a":[["458.954","0.0"],["458.977","0.0"],["458.979","0.0"],["459.049","1.2"],["459.079","0.3"],["459.247","1.6"],["459.536","1.0"],["459.539","18.0"],["459.881","0.0"],["459.976","9.3"]]}}
1618677461.030248: {"stream":"dentusdt@depth@100ms","data":{"e":"depthUpdate","E":1618677460972,"T":1618677460959,"s":"DENTUSDT","U":335340979537,"u":335340982354,"pu":335340979273,"b":[["0.012345","4185"]],"a":[["0.012357","56510"],["0.012358","20967"],["0.012359","6817"],["0.012360","95784"],["0.012361","53972"],["0.012362","97142"],["0.012363","359412"],["0.012366","49787"],["0.012420","650936"]]}}
1618677461.041356: {"stream":"ksmusdt@bookTicker","data":{"e":"bookTicker","u":335340982833,"s":"KSMUSDT","b":"458.746","B":"0.2","a":"458.954","A":"1.6","T":1618677460975,"E":1618677460979}}
1618677461.050237: {"stream":"ksmusdt@bookTicker","data":{"e":"bookTicker","u":335340983164,"s":"KSMUSDT","b":"458.746","B":"0.2","a":"458.954","A":"1.9","T":1618677460988,"E":1618677460992}}
1618677461.0545092: {"stream":"yfiusdt@depth@100ms","data":{"e":"depthUpdate","E":1618677460998,"T":1618677460966,"s":"YFIUSDT","U":335340980274,"u":335340982597,"pu":335340977867,"b":[["48593.0","0.049"],["49836.3","0.005"],["49944.2","0.000"],["49949.2","0.283"],["49981.7","0.017"]],"a":[["49981.8","0.007"]]}}
1618677461.078448: {"stream":"yfiusdt@bookTicker","data":{"e":"bookTicker","u":335340984051,"s":"YFIUSDT","b":"49981.7","B":"0.017","a":"49982.0","A":"0.002","T":1618677461015,"E":1618677461019}}
1618677461.078549: {"stream":"ksmusdt@bookTicker","data":{"e":"bookTicker","u":335340984207,"s":"KSMUSDT","b":"458.746","B":"0.2","a":"458.954","A":"1.6","T":1618677461018,"E":1618677461021}}
1618677461.079795: {"stream":"yfiusdt@kline_1m","data":{"e":"kline","E":1618677461021,"s":"YFIUSDT","k":{"t":1618677420000,"T":1618677479999,"s":"YFIUSDT","i":"1m","f":64902095,"L":64902177,"o":"50010.8","c":"49981.8","h":"50044.2","l":"49950.6","v":"0.984","n":83,"x":false,"q":"49198.8115","V":"0.676","Q":"33799.4477","B":"0"}}}
1618677461.079884: {"stream":"ksmusdt@bookTicker","data":{"e":"bookTicker","u":335340984251,"s":"KSMUSDT","b":"458.746","B":"0.2","a":"458.953","A":"0.3","T":1618677461018,"E":1618677461022}}
1618677461.079917: {"stream":"ksmusdt@bookTicker","data":{"e":"bookTicker","u":335340984352,"s":"KSMUSDT","b":"458.746","B":"0.2","a":"458.932","A":"6.4","T":1618677461019,"E":1618677461022}}
1618677461.088301: {"stream":"yfiusdt@bookTicker","data":{"e":"bookTicker","u":335340984502,"s":"YFIUSDT","b":"49981.7","B":"0.029","a":"49982.0","A":"0.002","T":1618677461025,"E":1618677461028}}
1618677461.0884092: {"stream":"yfiusdt@bookTicker","data":{"e":"bookTicker","u":335340984509,"s":"YFIUSDT","b":"49981.9","B":"0.012","a":"49982.0","A":"0.002","T":1618677461025,"E":1618677461028}}
1618677461.091091: {"stream":"xmrusdt@depth@100ms","data":{"e":"depthUpdate","E":1618677461032,"T":1618677461025,"s":"XMRUSDT","U":335340981445,"u":335340984499,"pu":335340980698,"b":[["345.43","0.507"],["351.65","0.000"],["351.83","6.046"],["351.95","28.458"],["351.97","3.168"],["352.19","2.851"],["352.27","2.351"],["352.38","0.000"]],"a":[["352.55","7.257"],["352.56","1.400"],["352.67","5.458"],["352.68","30.368"],["352.70","0.000"],["352.80","0.000"],["352.81","0.000"],["352.88","2.500"],["352.98","0.000"],["353.03","0.000"],["353.04","0.000"],["353.26","0.000"]]}}
1618677461.091326: {"stream":"yfiusdt@bookTicker","data":{"e":"bookTicker","u":335340984667,"s":"YFIUSDT","b":"49981.9","B":"0.019","a":"49982.0","A":"0.002","T":1618677461029,"E":1618677461033}}
1618677461.0966332: {"stream":"yfiusdt@bookTicker","data":{"e":"bookTicker","u":335340984812,"s":"YFIUSDT","b":"49981.9","B":"0.007","a":"49982.0","A":"0.002","T":1618677461033,"E":1618677461037}}
1618677461.096737: {"stream":"yfiusdt@bookTicker","data":{"e":"bookTicker","u":335340984827,"s":"YFIUSDT","b":"49981.9","B":"0.007","a":"49982.0","A":"0.008","T":1618677461034,"E":1618677461037}}
1618677461.1019032: {"stream":"yfiusdt@bookTicker","data":{"e":"bookTicker","u":335340984991,"s":"YFIUSDT","b":"49981.9","B":"0.007","a":"49982.0","A":"0.002","T":1618677461039,"E":1618677461042}}
1618677461.10693: {"stream":"yfiusdt@bookTicker","data":{"e":"bookTicker","u":335340985033,"s":"YFIUSDT","b":"49981.7","B":"0.017","a":"49982.0","A":"0.002","T":1618677461040,"E":1618677461044}}
1618677461.113703: {"stream":"yfiusdt@bookTicker","data":{"e":"bookTicker","u":335340985317,"s":"YFIUSDT","b":"49981.9","B":"0.012","a":"49982.0","A":"0.002","T":1618677461048,"E":1618677461052}}
1618677461.115221: {"stream":"dentusdt@bookTicker","data":{"e":"bookTicker","u":335340985440,"s":"DENTUSDT","b":"0.012347","B":"32702","a":"0.012357","A":"9421","T":1618677461052,"E":1618677461056}}
1618677461.239143: {"stream":"yfiusdt@bookTicker","data":{"e":"bookTicker","u":335340985677,"s":"YFIUSDT","b":"49981.7","B":"0.017","a":"49982.0","A":"0.002","T":1618677461058,"E":1618677461062}}
1618677461.23925: {"stream":"yfiusdt@bookTicker","data":{"e":"bookTicker","u":335340985701,"s":"YFIUSDT","b":"49981.7","B":"0.017","a":"49982.0","A":"0.008","T":1618677461059,"E":1618677461062}}
1618677461.239298: {"stream":"yfiusdt@aggTrade","data":{"e":"aggTrade","E":1618677461068,"a":52599699,"s":"YFIUSDT","p":"49981.8","q":"0.007","f":64902177,"l":64902178,"T":1618677461015,"m":false}}
1618677461.239326: {"stream":"yfiusdt@bookTicker","data":{"e":"bookTicker","u":335340985955,"s":"YFIUSDT","b":"49981.7","B":"0.017","a":"49985.0","A":"0.001","T":1618677461064,"E":1618677461068}}
1618677461.239346: {"stream":"yfiusdt@bookTicker","data":{"e":"bookTicker","u":335340986088,"s":"YFIUSDT","b":"49981.9","B":"0.012","a":"49985.0","A":"0.001","T":1618677461068,"E":1618677461072}}
1618677461.2393641: {"stream":"yfiusdt@bookTicker","data":{"e":"bookTicker","u":335340986183,"s":"YFIUSDT","b":"49981.7","B":"0.017","a":"49985.0","A":"0.001","T":1618677461071,"E":1618677461076}}
1618677461.239381: {"stream":"yfiusdt@bookTicker","data":{"e":"bookTicker","u":335340986240,"s":"YFIUSDT","b":"49983.0","B":"0.012","a":"49985.0","A":"0.001","T":1618677461073,"E":1618677461079}}
1618677461.239398: {"stream":"ksmusdt@depth@100ms","data":{"e":"depthUpdate","E":1618677461079,"T":1618677461074,"s":"KSMUSDT","U":335340982833,"u":335340986281,"pu":335340982248,"b":[["452.863","0.0"],["456.511","0.1"],["456.532","0.4"],["456.580","0.0"],["457.960","2.7"],["458.145","1.1"],["458.299","16.7"],["458.617","0.0"],["458.618","1.3"],["458.620","1.6"]],"a":[["458.932","6.4"],["458.953","0.3"],["458.954","1.6"],["458.975","0.1"],["459.049","0.0"],["459.079","0.0"],["459.247","0.0"],["459.317","0.1"],["459.368","0.0"],["459.475","0.1"],["459.526","0.0"],["459.536","1.0"],["459.537","8.2"],["459.538","38.5"],["459.539","0.1"],["459.557","1.4"],["459.563","0.1"],["459.634","0.0"],["459.655","0.0"],["460.080","2.1"],["461.180","0.0"]]}}
1618677461.2396789: {"stream":"yfiusdt@bookTicker","data":{"e":"bookTicker","u":335340986382,"s":"YFIUSDT","b":"49981.7","B":"0.017","a":"49985.0","A":"0.001","T":1618677461077,"E":1618677461080}}
1618677461.239706: {"stream":"yfiusdt@bookTicker","data":{"e":"bookTicker","u":335340986433,"s":"YFIUSDT","b":"49982.3","B":"0.008","a":"49985.0","A":"0.001","T":1618677461079,"E":1618677461083}}
1618677461.2426581: {"stream":"yfiusdt@bookTicker","data":{"e":"bookTicker","u":335340986743,"s":"YFIUSDT","b":"49981.7","B":"0.017","a":"49985.0","A":"0.001","T":1618677461089,"E":1618677461094}}
1618677461.242729: {"stream":"dentusdt@bookTicker","data":{"e":"bookTicker","u":335340986848,"s":"DENTUSDT","b":"0.012347","B":"32702","a":"0.012357","A":"56510","T":1618677461093,"E":1618677461098}}
1618677461.24276: {"stream":"ksmusdt@bookTicker","data":{"e":"bookTicker","u":335340986867,"s":"KSMUSDT","b":"458.746","B":"0.2","a":"458.931","A":"0.3","T":1618677461094,"E":1618677461098}}
1618677461.2427819: {"stream":"yfiusdt@bookTicker","data":{"e":"bookTicker","u":335340987018,"s":"YFIUSDT","b":"49983.0","B":"0.012","a":"49985.0","A":"0.001","T":1618677461099,"E":1618677461103}}
1618677461.242802: {"stream":"yfiusdt@depth@100ms","data":{"e":"depthUpdate","E":1618677461107,"T":1618677461099,"s":"YFIUSDT","U":335340983600,"u":335340987018,"pu":335340982597,"b":[["48477.4","0.000"],["49895.1","0.000"],["49915.1","0.100"],["49917.0","0.000"],["49921.2","0.000"],["49925.4","0.017"],["49929.6","0.000"],["49933.8","0.110"],["49938.0","0.110"],["49942.2","0.110"],["49949.3","0.080"],["49958.1","0.000"],["49959.5","0.000"],["49980.3","0.000"],["49981.7","0.017"],["49981.9","0.000"],["49982.0","0.000"],["49982.3","0.000"],["49983.0","0.012"]],"a":[["49981.8","0.000"],["49982.0","0.000"],["49994.8","0.000"],["49994.9","0.014"],["49995.0","0.000"],["49999.4","0.000"],["50000.2","0.003"]]}}
1618677461.243017: {"stream":"yfiusdt@bookTicker","data":{"e":"bookTicker","u":335340987194,"s":"YFIUSDT","b":"49981.7","B":"0.017","a":"49985.0","A":"0.001","T":1618677461108,"E":1618677461112}}
1618677461.243045: {"stream":"dentusdt@depth@100ms","data":{"e":"depthUpdate","E":1618677461113,"T":1618677461093,"s":"DENTUSDT","U":335340983877,"u":335340986855,"pu":335340982354,"b":[],"a":[["0.012357","56510"],["0.012360","95784"],["0.012361","0"],["0.012366","0"],["0.012376","33231"],["0.012377","41192"],["0.012378","27290"],["0.012380","323821"]]}}
1618677461.243124: {"stream":"xmrusdt@bookTicker","data":{"e":"bookTicker","u":335340987323,"s":"XMRUSDT","b":"352.41","B":"3.700","a":"352.55","A":"6.701","T":1618677461117,"E":1618677461121}}
1618677461.243362: {"stream":"xmrusdt@bookTicker","data":{"e":"bookTicker","u":335340987333,"s":"XMRUSDT","b":"352.41","B":"3.700","a":"352.54","A":"0.556","T":1618677461118,"E":1618677461124}}
1618677461.245694: {"stream":"xmrusdt@depth@100ms","data":{"e":"depthUpdate","E":1618677461141,"T":1618677461118,"s":"XMRUSDT","U":335340984924,"u":335340987333,"pu":335340984499,"b":[["351.95","25.958"],["352.04","0.000"],["352.07","3.135"],["352.11","5.569"],["352.18","0.000"],["352.19","0.000"],["352.35","0.000"]],"a":[["352.54","0.556"],["352.55","6.701"],["352.79","2.500"],["352.88","0.000"],["354.62","10.742"],["355.79","1.176"]]}}
1618677461.246907: {"stream":"yfiusdt@bookTicker","data":{"e":"bookTicker","u":335340987718,"s":"YFIUSDT","b":"49983.0","B":"0.012","a":"49985.0","A":"0.001","T":1618677461145,"E":1618677461149}}
1618677461.246976: {"stream":"yfiusdt@bookTicker","data":{"e":"bookTicker","u":335340987778,"s":"YFIUSDT","b":"49983.0","B":"0.012","a":"49994.9","A":"0.017","T":1618677461146,"E":1618677461150}}
1618677461.2470038: {"stream":"yfiusdt@bookTicker","data":{"e":"bookTicker","u":335340987848,"s":"YFIUSDT","b":"49981.7","B":"0.017","a":"49994.9","A":"0.017","T":1618677461149,"E":1618677461153}}
1618677461.247027: {"stream":"yfiusdt@bookTicker","data":{"e":"bookTicker","u":335340987870,"s":"YFIUSDT","b":"49981.7","B":"0.017","a":"49994.9","A":"0.014","T":1618677461150,"E":1618677461153}}
1618677461.2474601: {"stream":"yfiusdt@bookTicker","data":{"e":"bookTicker","u":335340987929,"s":"YFIUSDT","b":"49983.1","B":"0.025","a":"49994.9","A":"0.014","T":1618677461155,"E":1618677461161}}
1618677461.247531: {"stream":"yfiusdt@bookTicker","data":{"e":"bookTicker","u":335340987950,"s":"YFIUSDT","b":"49983.1","B":"0.025","a":"49994.8","A":"0.012","T":1618677461158,"E":1618677461162}}
1618677461.251491: {"stream":"yfiusdt@bookTicker","data":{"e":"bookTicker","u":335340988198,"s":"YFIUSDT","b":"49983.1","B":"0.025","a":"49986.7","A":"0.001","T":1618677461169,"E":1618677461172}}
1618677461.251561: {"stream":"yfiusdt@bookTicker","data":{"e":"bookTicker","u":335340988244,"s":"YFIUSDT","b":"49983.1","B":"0.025","a":"49983.4","A":"0.001","T":1618677461170,"E":1618677461173}}
1618677461.251588: {"stream":"dentusdt@bookTicker","data":{"e":"bookTicker","u":335340988370,"s":"DENTUSDT","b":"0.012347","B":"32702","a":"0.012357","A":"9421","T":1618677461178,"E":1618677461182}}
1618677461.2680871: {"stream":"ksmusdt@depth@100ms","data":{"e":"depthUpdate","E":1618677461196,"T":1618677461189,"s":"KSMUSDT","U":335340986782,"u":335340988730,"pu":335340986281,"b":[["458.044","13.6"],["458.045","3.3"],["458.145","0.0"],["458.300","3.7"],["458.386","1.2"],["458.405","1.1"],["458.587","0.4"],["458.618","0.0"],["458.620","0.4"],["458.621","0.3"],["458.701","0.3"]],"a":[["458.931","0.3"],["458.953","0.0"],["459.536","0.0"],["461.111","0.1"],["470.901","4.2"]]}}
1618677461.2684171: {"stream":"yfiusdt@aggTrade","data":{"e":"aggTrade","E":1618677461204,"a":52599700,"s":"YFIUSDT","p":"49982.0","q":"0.008","f":64902179,"l":64902180,"T":1618677461064,"m":false}}
1618677461.2684731: {"stream":"yfiusdt@bookTicker","data":{"e":"bookTicker","u":335340989200,"s":"YFIUSDT","b":"49983.1","B":"0.025","a":"49986.7","A":"0.001","T":1618677461200,"E":1618677461204}}
1618677461.270444: {"stream":"yfiusdt@depth@100ms","data":{"e":"depthUpdate","E":1618677461212,"T":1618677461206,"s":"YFIUSDT","U":335340987194,"u":335340989436,"pu":335340987018,"b":[["49925.4","0.127"],["49929.6","0.110"],["49938.0","0.000"],["49942.2","0.000"],["49953.3","0.000"],["49961.1","0.000"],["49983.0","0.000"],["49983.1","0.025"],["49984.4","0.000"],["49984.6","0.000"]],"a":[["49983.4","0.000"],["49985.0","0.000"],["49986.7","0.001"],["49994.7","0.003"],["49994.8","0.012"],["49994.9","0.000"],["50000.2","0.000"],["50000.3","0.000"],["50001.2","0.000"],["50007.4","0.014"],["50046.2","0.013"],["50066.0","0.005"],["50066.9","0.000"]]}}
1618677461.271134: {"stream":"yfiusdt@bookTicker","data":{"e":"bookTicker","u":335340989553,"s":"YFIUSDT","b":"49984.4","B":"0.012","a":"49986.7","A":"0.001","T":1618677461210,"E":1618677461214}}
1618677461.275962: {"stream":"yfiusdt@bookTicker","data":{"e":"bookTicker","u":335340989696,"s":"YFIUSDT","b":"49984.8","B":"0.001","a":"49986.7","A":"0.001","T":1618677461214,"E":1618677461218}}
1618677461.283519: {"stream":"dentusdt@bookTicker","data":{"e":"bookTicker","u":335340989893,"s":"DENTUSDT","b":"0.012347","B":"32702","a":"0.012357","A":"56510","T":1618677461220,"E":1618677461226}}
1618677461.288938: {"stream":"yfiusdt@bookTicker","data":{"e":"bookTicker","u":335340990127,"s":"YFIUSDT","b":"49983.1","B":"0.025","a":"49986.7","A":"0.001","T":1618677461226,"E":1618677461231}}
1618677461.2963998: {"stream":"dentusdt@depth@100ms","data":{"e":"depthUpdate","E":1618677461240,"T":1618677461223,"s":"DENTUSDT","U":335340987605,"u":335340989989,"pu":335340986855,"b":[["0.012342","48575"]],"a":[["0.012357","56510"],["0.012360","41812"],["0.012361","53972"],["0.012362","199689"],["0.012366","49787"],["0.012424","252379"]]}}
1618677461.2988532: {"stream":"yfiusdt@bookTicker","data":{"e":"bookTicker","u":335340990475,"s":"YFIUSDT","b":"49984.4","B":"0.012","a":"49986.7","A":"0.001","T":1618677461236,"E":1618677461241}}
1618677461.306549: {"stream":"xmrusdt@depth@100ms","data":{"e":"depthUpdate","E":1618677461249,"T":1618677461200,"s":"XMRUSDT","U":335340987707,"u":335340989207,"pu":335340987333,"b":[["339.72","70.562"],["352.09","0.000"],["352.11","3.069"],["352.16","2.966"],["352.27","4.851"],["352.30","6.019"],["352.31","1.264"]],"a":[["354.69","817.465"]]}}
1618677461.308749: {"stream":"yfiusdt@bookTicker","data":{"e":"bookTicker","u":335340990812,"s":"YFIUSDT","b":"49983.1","B":"0.025","a":"49986.7","A":"0.001","T":1618677461246,"E":1618677461250}}
1618677461.320035: {"stream":"yfiusdt@bookTicker","data":{"e":"bookTicker","u":335340991125,"s":"YFIUSDT","b":"49984.4","B":"0.012","a":"49986.7","A":"0.001","T":1618677461256,"E":1618677461260}}
1618677461.32901: {"stream":"yfiusdt@bookTicker","data":{"e":"bookTicker","u":335340991579,"s":"YFIUSDT","b":"49983.1","B":"0.025","a":"49986.7","A":"0.001","T":1618677461266,"E":1618677461271}}
1618677461.3406012: {"stream":"yfiusdt@bookTicker","data":{"e":"bookTicker","u":335340991913,"s":"YFIUSDT","b":"49984.4","B":"0.012","a":"49986.7","A":"0.001","T":1618677461277,"E":1618677461281}}
1618677461.349445: {"stream":"yfiusdt@bookTicker","data":{"e":"bookTicker","u":335340992219,"s":"YFIUSDT","b":"49983.1","B":"0.025","a":"49986.7","A":"0.001","T":1618677461287,"E":1618677461291}}
1618677461.427262: {"stream":"ksmusdt@depth@100ms","data":{"e":"depthUpdate","E":1618677461297,"T":1618677461291,"s":"KSMUSDT","U":335340988828,"u":335340992302,"pu":335340988730,"b":[["458.299","0.0"]],"a":[["458.954","0.0"],["458.955","0.0"],["459.079","1.6"],["459.536","1.0"],["459.557","0.0"],["459.634","1.4"],["459.692","0.0"],["459.974","1.9"]]}}
1618677461.427534: {"stream":"dentusdt@bookTicker","data":{"e":"bookTicker","u":335340992789,"s":"DENTUSDT","b":"0.012347","B":"32702","a":"0.012357","A":"9421","T":1618677461307,"E":1618677461312}}
1618677461.427587: {"stream":"yfiusdt@depth@100ms","data":{"e":"depthUpdate","E":1618677461313,"T":1618677461301,"s":"YFIUSDT","U":335340989496,"u":335340992604,"pu":335340989436,"b":[["49722.8","0.021"],["49898.9","0.000"],["49919.6","0.011"],["49925.4","0.127"],["49929.6","0.110"],["49930.6","0.025"],["49937.9","0.000"],["49938.0","0.000"],["49942.2","0.000"],["49944.1","0.026"],["49949.4","0.168"],["49953.4","0.000"],["49953.5","0.000"],["49953.6","0.000"],["49958.1","0.012"],["49981.7","0.019"],["49984.4","0.000"],["49984.8","0.000"]],"a":[["49994.7","0.000"],["50007.3","0.003"],["50062.1","0.000"],["50072.0","0.026"],["50082.7","0.000"],["50090.0","0.017"],["50096.7","0.010"],["50114.9","0.050"],["50125.0","0.042"]]}}
1618677461.427853: {"stream":"ksmusdt@bookTicker","data":{"e":"bookTicker","u":335340992801,"s":"KSMUSDT","b":"458.746","B":"0.2","a":"458.932","A":"6.4","T":1618677461308,"E":1618677461314}}
1618677461.42788: {"stream":"yfiusdt@aggTrade","data":{"e":"aggTrade","E":1618677461355,"a":52599701,"s":"YFIUSDT","p":"49983.4","q":"0.001","f":64902181,"l":64902181,"T":1618677461200,"m":false}}
1618677461.427907: {"stream":"dentusdt@bookTicker","data":{"e":"bookTicker","u":335340994282,"s":"DENTUSDT","b":"0.012347","B":"32702","a":"0.012357","A":"56510","T":1618677461352,"E":1618677461357}}
1618677461.427927: {"stream":"xmrusdt@depth@100ms","data":{"e":"depthUpdate","E":1618677461366,"T":1618677461361,"s":"XMRUSDT","U":335340991316,"u":335340994648,"pu":335340989207,"b":[["350.08","0.000"],["350.63","0.000"],["351.05","2.500"],["352.18","0.000"],["352.27","2.351"]],"a":[["353.28","14.374"],["354.50","6.780"]]}}
1618677461.427985: {"stream":"dentusdt@depth@100ms","data":{"e":"depthUpdate","E":1618677461369,"T":1618677461352,"s":"DENTUSDT","U":335340991545,"u":335340994291,"pu":335340989989,"b":[["0.012341","58453"],["0.012343","6883"]],"a":[["0.012357","56510"],["0.012361","53972"],["0.012362","145717"],["0.012366","0"]]}}
1618677461.4642031: {"stream":"ksmusdt@depth@100ms","data":{"e":"depthUpdate","E":1618677461406,"T":1618677461400,"s":"KSMUSDT","U":335340992623,"u":335340995981,"pu":335340992302,"b":[["453.028","0.0"],["458.245","1.1"],["458.300","0.0"],["458.405","0.0"],["458.582","0.0"],["458.621","0.0"],["458.701","0.6"]],"a":[["458.931","0.0"],["459.016","1.2"],["459.047","0.3"],["459.048","0.0"],["459.078","0.0"],["459.536","1.0"]]}}
1618677461.486958: {"stream":"yfiusdt@depth@100ms","data":{"e":"depthUpdate","E":1618677461429,"T":1618677461417,"s":"YFIUSDT","U":335340993219,"u":335340996596,"pu":335340992604,"b":[["49949.2","0.009"],["49955.9","0.000"],["49958.2","0.012"],["49981.7","0.002"]],"a":[["49994.7","0.003"],["50007.3","0.000"],["50024.0","0.001"],["50034.8","0.001"],["50036.1","0.000"],["50046.8","0.000"],["50128.8","0.016"]]}}
1618677461.4936829: {"stream":"dentusdt@bookTicker","data":{"e":"bookTicker","u":335340997115,"s":"DENTUSDT","b":"0.012347","B":"32702","a":"0.012357","A":"9421","T":1618677461435,"E":1618677461437}}
1618677461.540837: {"stream":"dentusdt@bookTicker","data":{"e":"bookTicker","u":335340998330,"s":"DENTUSDT","b":"0.012347","B":"32702","a":"0.012357","A":"56510","T":1618677461479,"E":1618677461481}}
1618677461.5507: {"stream":"ksmusdt@bookTicker","data":{"e":"bookTicker","u":335340998770,"s":"KSMUSDT","b":"458.746","B":"0.2","a":"458.839","A":"0.6","T":1618677461489,"E":1618677461492}}
1618677461.5550442: {"stream":"dentusdt@depth@100ms","data":{"e":"depthUpdate","E":1618677461497,"T":1618677461479,"s":"DENTUSDT","U":335340995771,"u":335340998330,"pu":335340994291,"b":[["0.012322","36372"],["0.012325","774890"]],"a":[["0.012357","56510"],["0.012361","53972"],["0.012362","199689"],["0.012366","49787"],["0.012377","36490"]]}}
1618677461.559353: {"stream":"xmrusdt@depth@100ms","data":{"e":"depthUpdate","E":1618677461501,"T":1618677461490,"s":"XMRUSDT","U":335340995884,"u":335340998813,"pu":335340994648,"b":[["351.05","0.000"],["351.35","0.000"],["351.52","3.941"],["351.55","2.500"],["351.56","1.000"],["351.95","19.290"],["352.05","7.620"],["352.08","23.208"],["352.15","5.719"],["352.19","1.000"]],"a":[["352.94","26.982"],["352.96","0.468"],["354.69","617.465"],["356.11","200.000"]]}}
1618677461.5596302: {"stream":"dentusdt@bookTicker","data":{"e":"bookTicker","u":335340999061,"s":"DENTUSDT","b":"0.012347","B":"32702","a":"0.012357","A":"17730","T":1618677461497,"E":1618677461501}}
1618677461.5596821: {"stream":"dentusdt@kline_1m","data":{"e":"kline","E":1618677461502,"s":"DENTUSDT","k":{"t":1618677420000,"T":1618677479999,"s":"DENTUSDT","i":"1m","f":15787262,"L":15787415,"o":"0.012366","c":"0.012357","h":"0.012366","l":"0.012339","v":"2573676","n":154,"x":false,"q":"31790.299569","V":"1163996","Q":"14381.544957","B":"0"}}}
1618677461.571928: {"stream":"dentusdt@bookTicker","data":{"e":"bookTicker","u":335340999407,"s":"DENTUSDT","b":"0.012347","B":"32702","a":"0.012356","A":"8645","T":1618677461508,"E":1618677461514}}
1618677461.57516: {"stream":"dentusdt@bookTicker","data":{"e":"bookTicker","u":335340999499,"s":"DENTUSDT","b":"0.012348","B":"9272","a":"0.012356","A":"8645","T":1618677461512,"E":1618677461515}}
1618677461.582623: {"stream":"ksmusdt@depth@100ms","data":{"e":"depthUpdate","E":1618677461524,"T":1618677461513,"s":"KSMUSDT","U":335340996655,"u":335340999566,"pu":335340995981,"b":[["458.017","0.0"],["458.145","1.1"],["458.168","0.0"],["458.245","0.0"],["458.583","1.5"],["458.587","2.6"],["458.621","0.3"],["458.701","0.3"],["458.730","1.0"]],"a":[["458.839","0.6"],["458.931","0.3"],["458.984","0.0"],["459.014","0.0"],["459.015","1.6"],["459.016","0.0"],["459.047","0.0"],["459.079","0.0"],["459.346","0.0"],["459.532","1.4"],["459.536","0.0"],["459.634","0.0"]]}}
1618677461.59125: {"stream":"yfiusdt@depth@100ms","data":{"e":"depthUpdate","E":1618677461535,"T":1618677461497,"s":"YFIUSDT","U":335340996992,"u":335340999077,"pu":335340996596,"b":[["49949.3","0.000"],["49958.0","0.000"],["49958.3","0.000"],["49958.4","0.008"],["49981.7","0.000"]],"a":[["49994.7","0.000"],["49994.8","0.000"],["50007.3","0.003"]]}}
1618677461.6582289: {"stream":"dentusdt@depth@100ms","data":{"e":"depthUpdate","E":1618677461601,"T":1618677461565,"s":"DENTUSDT","U":335340999057,"u":335341001098,"pu":335340998330,"b":[["0.012325","1074437"],["0.012340","353015"],["0.012343","22749"],["0.012348","9272"]],"a":[["0.012356","8645"],["0.012357","17730"],["0.012362","151114"],["0.012364","41020"],["0.012376","17444"],["0.012377","0"],["0.012379","79113"],["0.012380","24178"],["0.012395","167858"]]}}
1618677461.665576: {"stream":"xmrusdt@depth@100ms","data":{"e":"depthUpdate","E":1618677461607,"T":1618677461539,"s":"XMRUSDT","U":335340999200,"u":335341000327,"pu":335340998813,"b":[["351.55","0.000"],["351.74","0.381"],["352.16","5.466"]],"a":[["352.78","2.500"],["352.79","0.000"],["352.88","0.000"],["353.40","16.211"],["354.50","0.847"],["354.69","817.465"],["356.11","0.000"]]}}
1618677461.673773: {"stream":"xmrusdt@bookTicker","data":{"e":"bookTicker","u":335341002209,"s":"XMRUSDT","b":"352.47","B":"0.020","a":"352.54","A":"0.556","T":1618677461612,"E":1618677461615}}
1618677461.696668: {"stream":"yfiusdt@bookTicker","data":{"e":"bookTicker","u":335341002821,"s":"YFIUSDT","b":"49983.2","B":"0.002","a":"49986.7","A":"0.001","T":1618677461633,"E":1618677461637}}
1618677461.69672: {"stream":"ksmusdt@depth@100ms","data":{"e":"depthUpdate","E":1618677461639,"T":1618677461620,"s":"KSMUSDT","U":335341000117,"u":335341002457,"pu":335340999566,"b":[["458.583","0.0"],["458.587","0.0"],["458.621","0.3"],["458.701","0.3"]],"a":[["458.931","0.3"],["459.014","0.0"],["459.015","0.0"],["459.078","0.0"],["459.079","1.6"],["459.452","2.2"],["459.531","1.0"],["459.974","0.0"]]}}
1618677461.699587: {"stream":"yfiusdt@depth@100ms","data":{"e":"depthUpdate","E":1618677461641,"T":1618677461633,"s":"YFIUSDT","U":335341000270,"u":335341002821,"pu":335340999077,"b":[["49902.7","0.012"],["49909.3","0.026"],["49915.1","0.000"],["49919.6","0.001"],["49924.3","0.009"],["49930.6","0.000"],["49944.1","0.000"],["49952.9","0.000"],["49958.4","0.010"],["49983.2","0.002"]],"a":[["49995.0","0.000"],["49995.1","0.058"],["50007.3","0.000"],["50024.0","0.000"],["50031.8","0.003"],["50034.8","0.000"],["50042.6","0.028"]]}}
1618677461.709516: {"stream":"xmrusdt@bookTicker","data":{"e":"bookTicker","u":335341003262,"s":"XMRUSDT","b":"352.47","B":"0.020","a":"352.55","A":"6.701","T":1618677461649,"E":1618677461651}}
1618677461.709622: {"stream":"dentusdt@aggTrade","data":{"e":"aggTrade","E":1618677461652,"a":8476424,"s":"DENTUSDT","p":"0.012357","q":"38780","f":15787415,"l":15787416,"T":1618677461497,"m":false}}
1618677461.725062: {"stream":"dentusdt@bookTicker","data":{"e":"bookTicker","u":335341003566,"s":"DENTUSDT","b":"0.012348","B":"9272","a":"0.012359","A":"6817","T":1618677461661,"E":1618677461666}}
1618677461.743668: {"stream":"dentusdt@bookTicker","data":{"e":"bookTicker","u":335341004181,"s":"DENTUSDT","b":"0.012348","B":"9272","a":"0.012359","A":"24547","T":1618677461681,"E":1618677461685}}
1618677461.760789: {"stream":"dentusdt@depth@100ms","data":{"e":"depthUpdate","E":1618677461704,"T":1618677461695,"s":"DENTUSDT","U":335341001922,"u":335341004475,"pu":335341001098,"b":[["0.012343","0"],["0.012345","0"]],"a":[["0.012356","0"],["0.012357","0"],["0.012358","0"],["0.012359","24547"],["0.012360","62716"],["0.012361","40474"],["0.012362","97142"],["0.012363","225531"],["0.012366","0"],["0.012379","91662"],["0.012416","64939"],["0.012419","474247"],["0.012424","83166"]]}}
1618677461.767046: {"stream":"xmrusdt@depth@100ms","data":{"e":"depthUpdate","E":1618677461711,"T":1618677461701,"s":"XMRUSDT","U":335341002124,"u":335341004641,"pu":335341000327,"b":[["351.98","0.794"],["352.06","15.912"],["352.16","2.966"],["352.17","3.531"],["352.28","11.670"],["352.30","0.000"],["352.31","0.000"],["352.47","0.020"]],"a":[["352.54","0.000"],["352.56","1.400"],["352.61","0.776"],["352.67","0.000"],["352.68","0.000"]]}}
1618677461.781973: {"stream":"dentusdt@bookTicker","data":{"e":"bookTicker","u":335341005056,"s":"DENTUSDT","b":"0.012348","B":"13451","a":"0.012359","A":"24547","T":1618677461721,"E":1618677461726}}
1618677461.803692: {"stream":"ksmusdt@depth@100ms","data":{"e":"depthUpdate","E":1618677461746,"T":1618677461719,"s":"KSMUSDT","U":335341003045,"u":335341004993,"pu":335341002457,"b":[["457.638","0.0"],["457.711","2.0"],["457.951","0.0"],["458.127","2.1"],["458.145","17.7"],["458.502","5.4"],["458.730","0.0"]],"a":[["459.623","2.1"],["459.819","0.0"],["459.864","0.4"],["459.933","0.0"],["460.050","8.3"]]}}
1618677461.807909: {"stream":"yfiusdt@depth@100ms","data":{"e":"depthUpdate","E":1618677461751,"T":1618677461723,"s":"YFIUSDT","U":335341003228,"u":335341005091,"pu":335341002821,"b":[["49219.9","0.010"],["49727.8","0.009"]],"a":[["49995.1","0.055"],["50007.3","0.003"],["50114.9","0.000"],["50193.3","0.005"]]}}
1618677461.8816361: {"stream":"xmrusdt@depth@100ms","data":{"e":"depthUpdate","E":1618677461824,"T":1618677461797,"s":"XMRUSDT","U":335341004997,"u":335341006546,"pu":335341004641,"b":[["352.06","0.000"],["352.07","0.000"],["352.17","1.031"],["352.20","2.500"],["352.27","2.351"]],"a":[["353.04","15.462"]]}}
1618677461.88186: {"stream":"dentusdt@depth@100ms","data":{"e":"depthUpdate","E":1618677461825,"T":1618677461789,"s":"DENTUSDT","U":335341005050,"u":335341006365,"pu":335341004475,"b":[["0.012345","22744"],["0.012348","13451"]],"a":[["0.012362","151108"],["0.012366","49787"],["0.012391","44842"],["0.012392","1847"],["0.012429","291996"]]}}
1618677461.8908548: {"stream":"ksmusdt@bookTicker","data":{"e":"bookTicker","u":335341007171,"s":"KSMUSDT","b":"458.747","B":"1.5","a":"458.839","A":"0.6","T":1618677461823,"E":1618677461827}}
1618677461.896838: {"stream":"dentusdt@bookTicker","data":{"e":"bookTicker","u":335341007371,"s":"DENTUSDT","b":"0.012348","B":"17276","a":"0.012359","A":"24547","T":1618677461833,"E":1618677461837}}
1618677461.904605: {"stream":"ksmusdt@bookTicker","data":{"e":"bookTicker","u":335341007580,"s":"KSMUSDT","b":"458.746","B":"0.2","a":"458.839","A":"0.6","T":1618677461841,"E":1618677461845}}
1618677461.9098828: {"stream":"yfiusdt@depth@100ms","data":{"e":"depthUpdate","E":1618677461853,"T":1618677461801,"s":"YFIUSDT","U":335341005569,"u":335341006654,"pu":335341005091,"b":[["48598.0","0.047"]],"a":[["50035.8","0.001"]]}}
1618677461.921639: {"stream":"ksmusdt@depth@100ms","data":{"e":"depthUpdate","E":1618677461864,"T":1618677461856,"s":"KSMUSDT","U":335341005781,"u":335341007966,"pu":335341004993,"b":[["450.876","0.0"],["458.144","0.0"],["458.747","0.0"]],"a":[["459.370","6.4"],["468.009","5.3"]]}}
1618677461.996383: {"stream":"dentusdt@depth@100ms","data":{"e":"depthUpdate","E":1618677461937,"T":1618677461849,"s":"DENTUSDT","U":335341007371,"u":335341007761,"pu":335341006365,"b":[["0.012348","17276"]],"a":[["0.012402","132377"]]}}
1618677462.017486: {"stream":"yfiusdt@depth@100ms","data":{"e":"depthUpdate","E":1618677461954,"T":1618677461908,"s":"YFIUSDT","U":335341007751,"u":335341009218,"pu":335341006654,"b":[["49856.3","0.000"],["49875.3","0.157"],["49909.3","0.000"],["49936.6","0.026"],["49944.1","0.280"]],"a":[["50024.2","0.003"],["50031.8","0.000"]]}}
1618677462.0341601: {"stream":"xmrusdt@depth@100ms","data":{"e":"depthUpdate","E":1618677461972,"T":1618677461962,"s":"XMRUSDT","U":335341008255,"u":335341010446,"pu":335341006546,"b":[["343.38","69.841"],["349.69","7.088"],["350.32","48.784"],["352.20","0.000"],["352.29","2.523"]],"a":[]}}
1618677462.0364008: {"stream":"ksmusdt@depth@100ms","data":{"e":"depthUpdate","E":1618677461974,"T":1618677461961,"s":"KSMUSDT","U":335341008337,"u":335341010409,"pu":335341007966,"b":[["457.984","0.0"]],"a":[["459.806","0.0"],["461.530","0.6"]]}}
1618677462.066459: {"stream":"ksmusdt@bookTicker","data":{"e":"bookTicker","u":335341011289,"s":"KSMUSDT","b":"458.746","B":"0.2","a":"458.931","A":"0.3","T":1618677461997,"E":1618677462000}}
1618677462.072523: {"stream":"ksmusdt@bookTicker","data":{"e":"bookTicker","u":335341011648,"s":"KSMUSDT","b":"458.746","B":"0.2","a":"458.793","A":"0.6","T":1618677462007,"E":1618677462011}}
1618677462.0997179: {"stream":"ksmusdt@bookTicker","data":{"e":"bookTicker","u":335341012532,"s":"KSMUSDT","b":"458.747","B":"0.3","a":"458.793","A":"0.6","T":1618677462034,"E":1618677462037}}
1618677462.2315688: {"stream":"xmrusdt@depth@100ms","data":{"e":"depthUpdate","E":1618677462074,"T":1618677462061,"s":"XMRUSDT","U":335341010683,"u":335341013561,"pu":335341010446,"b":[["349.06","15.259"],["349.69","207.088"],["350.32","248.784"],["352.30","0.531"]],"a":[["352.68","2.753"],["352.93","5.667"],["353.03","3.249"],["353.07","0.284"],["354.59","5.933"]]}}
1618677462.231806: {"stream":"ksmusdt@depth@100ms","data":{"e":"depthUpdate","E":1618677462074,"T":1618677462066,"s":"KSMUSDT","U":335341010662,"u":335341013740,"pu":335341010409,"b":[["454.304","15.0"],["456.553","15.0"],["457.503","1.1"],["457.504","0.0"],["457.959","0.0"],["458.146","3.7"],["458.190","0.5"],["458.503","1.3"],["458.712","1.0"],["458.713","0.4"],["458.747","0.3"]],"a":[["458.793","0.6"],["458.839","0.0"],["459.443","0.1"],["459.460","0.1"],["459.475","0.0"],["459.563","0.0"],["459.596","0.4"],["460.285","1.1"],["460.294","0.0"],["461.050","0.0"],["463.290","15.0"],["463.299","0.0"]]}}
1618677462.265286: {"stream":"yfiusdt@depth@100ms","data":{"e":"depthUpdate","E":1618677462119,"T":1618677462059,"s":"YFIUSDT","U":335341011845,"u":335341013463,"pu":335341009218,"b":[["49803.6","0.007"],["49916.9","0.060"],["49919.5","0.000"],["49944.2","0.094"],["49950.1","0.039"],["49958.5","0.009"],["49960.9","0.000"]],"a":[["49995.0","0.013"],["50003.6","0.012"],["50078.7","0.060"],["50087.8","0.000"]]}}
1618677462.271751: {"stream":"dentusdt@depth@100ms","data":{"e":"depthUpdate","E":1618677462147,"T":1618677462130,"s":"DENTUSDT","U":335341012858,"u":335341014901,"pu":335341007761,"b":[["0.012000","1827399"],["0.012170","33592"],["0.012211","411493"],["0.012224","15602"]],"a":[["0.012377","3237"],["0.012460","12226"],["0.012477","95275"]]}}
1618677462.271956: {"stream":"xmrusdt@bookTicker","data":{"e":"bookTicker","u":335341015481,"s":"XMRUSDT","b":"352.41","B":"3.700","a":"352.55","A":"6.701","T":1618677462153,"E":1618677462156}}
1618677462.280031: {"stream":"xmrusdt@bookTicker","data":{"e":"bookTicker","u":335341015916,"s":"XMRUSDT","b":"352.51","B":"0.020","a":"352.55","A":"6.701","T":1618677462165,"E":1618677462169}}
1618677462.280131: {"stream":"ksmusdt@depth@100ms","data":{"e":"depthUpdate","E":1618677462174,"T":1618677462166,"s":"KSMUSDT","U":335341013879,"u":335341015956,"pu":335341013740,"b":[["454.295","15.0"],["454.304","0.0"],["456.544","15.0"],["456.553","0.0"],["456.744","0.4"],["457.716","10.9"],["457.960","0.0"],["458.103","1.9"],["458.604","0.0"]],"a":[["459.286","0.1"],["459.317","0.0"],["459.951","1.9"],["461.041","15.0"]]}}
1618677462.280393: {"stream":"xmrusdt@depth@100ms","data":{"e":"depthUpdate","E":1618677462176,"T":1618677462168,"s":"XMRUSDT","U":335341013944,"u":335341016077,"pu":335341013561,"b":[["349.69","7.088"],["350.32","48.784"],["351.99","31.864"],["352.47","0.000"],["352.51","0.020"]],"a":[["352.68","33.121"],["352.70","0.000"]]}}
1618677462.28543: {"stream":"yfiusdt@bookTicker","data":{"e":"bookTicker","u":335341017514,"s":"YFIUSDT","b":"49983.2","B":"0.002","a":"49985.0","A":"0.005","T":1618677462217,"E":1618677462222}}
1618677462.3297222: {"stream":"yfiusdt@depth@100ms","data":{"e":"depthUpdate","E":1618677462270,"T":1618677462217,"s":"YFIUSDT","U":335341015982,"u":335341017514,"pu":335341013463,"b":[["49902.8","0.100"],["49924.3","0.000"],["49956.6","0.009"],["49958.3","0.012"],["49958.4","0.000"],["49958.6","0.005"]],"a":[["49985.0","0.005"],["50003.6","0.000"],["50048.5","0.009"],["50049.1","0.000"]]}}
1618677462.3385012: {"stream":"xmrusdt@depth@100ms","data":{"e":"depthUpdate","E":1618677462277,"T":1618677462216,"s":"XMRUSDT","U":335341016277,"u":335341017455,"pu":335341016077,"b":[["329.69","200.248"],["330.29","200.016"]],"a":[["352.51","0.000"],["352.68","2.753"]]}}
1618677462.345802: {"stream":"ksmusdt@bookTicker","data":{"e":"bookTicker","u":335341019710,"s":"KSMUSDT","b":"458.746","B":"0.2","a":"458.793","A":"0.6","T":1618677462281,"E":1618677462284}}
1618677462.405351: {"stream":"ksmusdt@depth@100ms","data":{"e":"depthUpdate","E":1618677462345,"T":1618677462318,"s":"KSMUSDT","U":335341018257,"u":335341021160,"pu":335341015956,"b":[["451.944","0.0"],["454.295","30.0"],["454.799","0.0"],["456.544","30.0"],["456.570","0.0"],["456.865","1.1"],["458.145","16.6"],["458.712","0.0"],["458.713","0.0"],["458.747","0.0"]],"a":[["460.994","0.0"],["461.041","30.0"],["463.059","0.1"],["463.290","30.0"],["466.341","12.0"]]}}
1618677462.4169412: {"stream":"dentusdt@bookTicker","data":{"e":"bookTicker","u":335341022063,"s":"DENTUSDT","b":"0.012348","B":"17276","a":"0.012359","A":"6817","T":1618677462346,"E":1618677462350}}
1618677462.4202628: {"stream":"dentusdt@bookTicker","data":{"e":"bookTicker","u":335341022287,"s":"DENTUSDT","b":"0.012348","B":"21101","a":"0.012359","A":"6817","T":1618677462354,"E":1618677462357}}
1618677462.4327612: {"stream":"yfiusdt@depth@100ms","data":{"e":"depthUpdate","E":1618677462374,"T":1618677462287,"s":"YFIUSDT","U":335341019139,"u":335341019987,"pu":335341017514,"b":[["49958.6","0.010"]],"a":[["50114.9","0.050"]]}}
1618677462.4461792: {"stream":"xmrusdt@depth@100ms","data":{"e":"depthUpdate","E":1618677462385,"T":1618677462378,"s":"XMRUSDT","U":335341019720,"u":335341023016,"pu":335341017455,"b":[["329.69","0.248"],["330.29","0.016"],["346.07","28.578"],["349.69","207.088"],["350.32","248.784"],["350.54","0.041"],["352.28","9.968"]],"a":[["352.51","0.000"],["352.64","0.716"],["352.65","4.315"]]}}
1618677462.454942: {"stream":"dentusdt@bookTicker","data":{"e":"bookTicker","u":335341023272,"s":"DENTUSDT","b":"0.012348","B":"21101","a":"0.012359","A":"24547","T":1618677462389,"E":1618677462392}}
1618677462.4550421: {"stream":"yfiusdt@bookTicker","data":{"e":"bookTicker","u":335341023318,"s":"YFIUSDT","b":"49983.2","B":"0.001","a":"49985.0","A":"0.005","T":1618677462391,"E":1618677462394}}
1618677462.4550881: {"stream":"yfiusdt@kline_1m","data":{"e":"kline","E":1618677462395,"s":"YFIUSDT","k":{"t":1618677420000,"T":1618677479999,"s":"YFIUSDT","i":"1m","f":64902095,"L":64902182,"o":"50010.8","c":"49983.2","h":"50044.2","l":"49950.6","v":"1.000","n":88,"x":false,"q":"49998.5249","V":"0.691","Q":"34549.1779","B":"0"}}}
1618677462.4646442: {"stream":"dentusdt@depth@100ms","data":{"e":"depthUpdate","E":1618677462407,"T":1618677462389,"s":"DENTUSDT","U":335341020620,"u":335341023282,"pu":335341014901,"b":[["0.012348","21101"]],"a":[["0.012359","24547"],["0.012361","0"],["0.012362","48571"],["0.012366","0"],["0.012377","0"],["0.012381","62877"],["0.012390","27985"]]}}
1618677462.525884: {"stream":"dentusdt@bookTicker","data":{"e":"bookTicker","u":335341025068,"s":"DENTUSDT","b":"0.012348","B":"21101","a":"0.012359","A":"6817","T":1618677462458,"E":1618677462462}}
1618677462.525984: {"stream":"ksmusdt@depth@100ms","data":{"e":"depthUpdate","E":1618677462464,"T":1618677462438,"s":"KSMUSDT","U":335341022479,"u":335341024575,"pu":335341021160,"b":[["454.654","3.9"],["456.719","3.9"],["456.736","1.1"],["457.254","0.0"],["458.147","1.1"],["458.727","0.0"]],"a":[["460.847","3.9"],["462.912","3.9"]]}}
1618677462.550161: {"stream":"yfiusdt@depth@100ms","data":{"e":"depthUpdate","E":1618677462494,"T":1618677462471,"s":"YFIUSDT","U":335341023314,"u":335341025655,"pu":335341019987,"b":[["49917.0","0.110"],["49921.2","0.110"],["49929.6","0.000"],["49933.8","0.000"],["49944.1","0.000"],["49944.3","0.281"],["49983.2","0.001"]],"a":[["49733.2","0.000"],["50024.2","0.001"],["50114.9","0.000"],["50119.9","0.000"]]}}
1618677462.568371: {"stream":"dentusdt@bookTicker","data":{"e":"bookTicker","u":335341026433,"s":"DENTUSDT","b":"0.012348","B":"21101","a":"0.012359","A":"24547","T":1618677462499,"E":1618677462502}}
1618677462.5787609: {"stream":"xmrusdt@depth@100ms","data":{"e":"depthUpdate","E":1618677462517,"T":1618677462505,"s":"XMRUSDT","U":335341023984,"u":335341026598,"pu":335341023016,"b":[],"a":[["352.48","0.000"],["352.51","0.000"]]}}
1618677462.58262: {"stream":"dentusdt@depth@100ms","data":{"e":"depthUpdate","E":1618677462521,"T":1618677462499,"s":"DENTUSDT","U":335341024092,"u":335341026438,"pu":335341023282,"b":[],"a":[["0.012359","24547"],["0.012360","38297"],["0.012362","107681"],["0.012366","49787"],["0.012381","62877"]]}}
1618677462.583329: {"stream":"ksmusdt@bookTicker","data":{"e":"bookTicker","u":335341027139,"s":"KSMUSDT","b":"458.746","B":"0.2","a":"458.931","A":"0.3","T":1618677462520,"E":1618677462524}}
1618677462.602776: {"stream":"ksmusdt@bookTicker","data":{"e":"bookTicker","u":335341027436,"s":"KSMUSDT","b":"458.746","B":"0.2","a":"458.770","A":"0.6","T":1618677462532,"E":1618677462536}}
1618677462.6157818: {"stream":"yfiusdt@aggTrade","data":{"e":"aggTrade","E":1618677462545,"a":52599702,"s":"YFIUSDT","p":"49983.2","q":"0.001","f":64902182,"l":64902182,"T":1618677462391,"m":true}}
1618677462.6348832: {"stream":"yfiusdt@bookTicker","data":{"e":"bookTicker","u":335341028154,"s":"YFIUSDT","b":"49983.1","B":"0.025","a":"49985.0","A":"0.005","T":1618677462559,"E":1618677462562}}
1618677462.6349819: {"stream":"ksmusdt@depth@100ms","data":{"e":"depthUpdate","E":1618677462565,"T":1618677462543,"s":"KSMUSDT","U":335341025132,"u":335341027757,"pu":335341024575,"b":[["455.070","0.0"],["458.147","1.1"],["458.589","5.3"],["458.713","1.0"]],"a":[["458.770","0.6"],["458.793","0.0"],["459.304","22.1"],["459.370","0.0"],["459.531","0.0"],["459.537","4.4"],["459.538","17.9"],["459.881","1.0"]]}}
1618677462.63522: {"stream":"yfiusdt@bookTicker","data":{"e":"bookTicker","u":335341028370,"s":"YFIUSDT","b":"49973.0","B":"0.003","a":"49985.0","A":"0.005","T":1618677462567,"E":1618677462571}}
1618677462.66257: {"stream":"yfiusdt@depth@100ms","data":{"e":"depthUpdate","E":1618677462595,"T":1618677462586,"s":"YFIUSDT","U":335341026194,"u":335341029005,"pu":335341025655,"b":[["49941.5","0.000"],["49943.8","0.000"],["49944.2","0.000"],["49946.5","0.009"],["49949.4","0.000"],["49957.1","0.000"],["49958.1","0.000"],["49958.5","0.000"],["49958.7","0.012"],["49958.9","0.032"],["49983.1","0.000"],["49983.2","0.000"]],"a":[["50016.5","0.032"],["50024.2","0.000"],["50031.8","0.030"],["50035.8","0.000"],["50043.5","0.030"]]}}
1618677462.6729422: {"stream":"xmrusdt@bookTicker","data":{"e":"bookTicker","u":335341029752,"s":"XMRUSDT","b":"352.51","B":"0.020","a":"352.53","A":"0.116","T":1618677462610,"E":1618677462613}}
1618677462.7057989: {"stream":"ksmusdt@bookTicker","data":{"e":"bookTicker","u":335341030645,"s":"KSMUSDT","b":"458.746","B":"0.2","a":"458.758","A":"0.1","T":1618677462642,"E":1618677462646}}
1618677462.714915: {"stream":"xmrusdt@depth@100ms","data":{"e":"depthUpdate","E":1618677462655,"T":1618677462610,"s":"XMRUSDT","U":335341027988,"u":335341029752,"pu":335341026598,"b":[["350.58","7.132"]],"a":[["352.53","0.116"]]}}
1618677462.7363331: {"stream":"ksmusdt@kline_1m","data":{"e":"kline","E":1618677462671,"s":"KSMUSDT","k":{"t":1618677420000,"T":1618677479999,"s":"KSMUSDT","i":"1m","f":25426460,"L":25426580,"o":"459.607","c":"458.758","h":"459.671","l":"458.391","v":"109.1","n":121,"x":false,"q":"50081.1121","V":"52.8","Q":"24247.3255","B":"0"}}}
1618677462.7424698: {"stream":"ksmusdt@bookTicker","data":{"e":"bookTicker","u":335341031252,"s":"KSMUSDT","b":"458.746","B":"0.2","a":"458.770","A":"0.6","T":1618677462667,"E":1618677462671}}
1618677462.74257: {"stream":"xmrusdt@bookTicker","data":{"e":"bookTicker","u":335341031364,"s":"XMRUSDT","b":"352.41","B":"3.700","a":"352.53","A":"0.116","T":1618677462670,"E":1618677462675}}
1618677462.750719: {"stream":"xmrusdt@bookTicker","data":{"e":"bookTicker","u":335341031537,"s":"XMRUSDT","b":"352.52","B":"0.020","a":"352.53","A":"0.116","T":1618677462675,"E":1618677462680}}
1618677462.7561758: {"stream":"ksmusdt@depth@100ms","data":{"e":"depthUpdate","E":1618677462686,"T":1618677462667,"s":"KSMUSDT","U":335341028908,"u":335341031252,"pu":335341027757,"b":[["458.147","1.1"]],"a":[["458.758","0.0"]]}}
1618677462.7648268: {"stream":"yfiusdt@depth@100ms","data":{"e":"depthUpdate","E":1618677462702,"T":1618677462685,"s":"YFIUSDT","U":335341029351,"u":335341031881,"pu":335341029005,"b":[["49943.7","0.009"],["49944.3","0.000"],["49950.1","0.000"],["49956.6","0.000"],["49958.6","0.000"],["49959.0","0.010"]],"a":[["50117.2","0.157"],["50160.6","0.000"]]}}
1618677462.824487: {"stream":"xmrusdt@depth@100ms","data":{"e":"depthUpdate","E":1618677462763,"T":1618677462751,"s":"XMRUSDT","U":335341031082,"u":335341033681,"pu":335341029752,"b":[["348.31","0.000"],["348.94","0.000"],["349.69","7.088"],["349.73","200.724"],["350.32","48.784"],["350.36","207.696"],["351.47","0.276"],["351.52","40.886"],["351.96","3.745"],["351.97","0.000"],["351.98","15.572"],["352.51","0.000"],["352.52","0.020"]],"a":[["353.34","26.597"],["353.36","29.574"],["353.68","0.000"],["353.70","37.306"]]}}
1618677462.8356411: {"stream":"yfiusdt@bookTicker","data":{"e":"bookTicker","u":335341034200,"s":"YFIUSDT","b":"49973.0","B":"0.003","a":"49986.7","A":"0.001","T":1618677462770,"E":1618677462773}}
1618677462.844668: {"stream":"yfiusdt@bookTicker","data":{"e":"bookTicker","u":335341034426,"s":"YFIUSDT","b":"49973.0","B":"0.003","a":"49979.0","A":"0.005","T":1618677462779,"E":1618677462783}}
1618677462.855653: {"stream":"ksmusdt@depth@100ms","data":{"e":"depthUpdate","E":1618677462794,"T":1618677462769,"s":"KSMUSDT","U":335341032012,"u":335341034168,"pu":335341031252,"b":[],"a":[["458.930","0.3"],["458.931","1.3"],["459.951","0.0"]]}}
1618677462.8673248: {"stream":"yfiusdt@depth@100ms","data":{"e":"depthUpdate","E":1618677462806,"T":1618677462788,"s":"YFIUSDT","U":335341032346,"u":335341034696,"pu":335341031881,"b":[["49919.6","0.007"],["49922.8","0.006"],["49923.6","0.006"],["49933.1","0.000"],["49934.6","0.087"],["49936.4","0.080"],["49937.2","0.000"],["49944.4","0.000"],["49949.2","0.009"],["49952.4","0.000"],["49957.4","0.009"],["49958.9","0.000"]],"a":[["49979.0","0.005"],["49985.0","0.000"],["50024.0","0.003"],["50031.8","0.000"],["50034.7","0.003"],["50035.6","0.003"],["50042.6","0.000"],["50043.5","0.000"]]}}
1618677462.883081: {"stream":"ksmusdt@aggTrade","data":{"e":"aggTrade","E":1618677462822,"a":21396986,"s":"KSMUSDT","p":"458.758","q":"0.1","f":25426580,"l":25426580,"T":1618677462667,"m":false}}
1618677462.933707: {"stream":"xmrusdt@depth@100ms","data":{"e":"depthUpdate","E":1618677462876,"T":1618677462846,"s":"XMRUSDT","U":335341034235,"u":335341036566,"pu":335341033681,"b":[["350.10","631.358"]],"a":[["353.03","0.000"],["353.04","0.000"],["353.36","14.796"],["353.40","2.886"],["353.58","17.664"]]}}
1618677462.943555: {"stream":"ksmusdt@bookTicker","data":{"e":"bookTicker","u":335341037635,"s":"KSMUSDT","b":"458.746","B":"0.2","a":"458.765","A":"6.0","T":1618677462875,"E":1618677462879}}
1618677462.947835: {"stream":"ksmusdt@bookTicker","data":{"e":"bookTicker","u":335341037782,"s":"KSMUSDT","b":"458.746","B":"0.2","a":"458.770","A":"0.6","T":1618677462879,"E":1618677462883}}
1618677462.965353: {"stream":"ksmusdt@depth@100ms","data":{"e":"depthUpdate","E":1618677462904,"T":1618677462895,"s":"KSMUSDT","U":335341035147,"u":335341038366,"pu":335341034168,"b":[["448.029","0.0"],["452.461","3.3"],["454.783","0.2"],["455.082","0.0"],["455.793","0.0"],["457.509","2.3"]],"a":[["458.765","0.0"],["462.959","0.0"],["463.268","0.0"],["463.305","0.0"],["464.067","0.0"],["464.187","0.0"],["470.630","11.3"],["470.834","0.0"],["471.844","0.0"],["473.598","0.0"],["474.213","14.6"],["476.355","5.5"],["477.483","8.2"],["478.608","12.9"]]}}
1618677462.971684: {"stream":"yfiusdt@depth@100ms","data":{"e":"depthUpdate","E":1618677462914,"T":1618677462903,"s":"YFIUSDT","U":335341035371,"u":335341038676,"pu":335341034696,"b":[["48471.6","0.047"],["49488.0","0.026"],["49919.6","0.001"],["49922.8","0.000"],["49923.6","0.000"],["49927.5","0.037"],["49930.7","0.037"],["49931.5","0.037"],["49943.0","0.000"],["49943.7","0.139"],["49948.4","0.000"],["49950.7","0.032"],["49959.0","0.000"]],"a":[["50010.6","0.032"],["50016.5","0.000"]]}}
1618677463.06512: {"stream":"ksmusdt@depth@100ms","data":{"e":"depthUpdate","E":1618677463008,"T":1618677463002,"s":"KSMUSDT","U":335341038702,"u":335341041922,"pu":335341038366,"b":[["453.379","2.4"],["454.561","0.2"],["454.783","0.0"],["455.315","0.1"],["455.701","0.0"],["457.036","0.1"],["458.044","0.0"],["458.045","0.0"]],"a":[["459.972","1.9"],["460.475","0.1"],["462.196","0.1"],["462.458","0.0"],["463.269","0.0"],["464.188","0.0"],["471.889","6.4"],["472.023","0.0"],["473.112","14.7"],["477.483","0.0"],["478.608","0.0"]]}}
1618677463.071842: {"stream":"dentusdt@bookTicker","data":{"e":"bookTicker","u":335341042359,"s":"DENTUSDT","b":"0.012348","B":"21101","a":"0.012359","A":"20547","T":1618677463010,"E":1618677463013}}
1618677463.0719512: {"stream":"dentusdt@kline_1m","data":{"e":"kline","E":1618677463014,"s":"DENTUSDT","k":{"t":1618677420000,"T":1618677479999,"s":"DENTUSDT","i":"1m","f":15787262,"L":15787417,"o":"0.012366","c":"0.012359","h":"0.012366","l":"0.012339","v":"2607035","n":156,"x":false,"q":"32202.524732","V":"1197355","Q":"14793.770120","B":"0"}}}
1618677463.0834181: {"stream":"ksmusdt@bookTicker","data":{"e":"bookTicker","u":335341042905,"s":"KSMUSDT","b":"458.747","B":"0.2","a":"458.770","A":"0.6","T":1618677463021,"E":1618677463025}}
1618677463.084158: {"stream":"xmrusdt@depth@100ms","data":{"e":"depthUpdate","E":1618677463026,"T":1618677463003,"s":"XMRUSDT","U":335341039337,"u":335341041990,"pu":335341036566,"b":[["350.84","4.932"],["351.92","0.016"],["351.98","16.002"]],"a":[["352.54","0.517"],["353.28","3.993"],["353.34","38.114"],["353.68","13.324"],["354.18","1.764"],["355.07","1.114"],["355.26","128.816"]]}}
1618677463.084856: {"stream":"yfiusdt@depth@100ms","data":{"e":"depthUpdate","E":1618677463028,"T":1618677463011,"s":"YFIUSDT","U":335341039366,"u":335341042421,"pu":335341038676,"b":[["49863.0","0.000"],["49873.0","0.008"],["49902.6","0.000"],["49915.4","0.026"],["49930.4","0.009"],["49936.5","0.281"],["49936.6","0.000"],["49943.7","0.130"],["49958.7","0.012"]],"a":[]}}
1618677463.094264: {"stream":"yfiusdt@bookTicker","data":{"e":"bookTicker","u":335341043445,"s":"YFIUSDT","b":"49974.3","B":"0.012","a":"49979.0","A":"0.005","T":1618677463032,"E":1618677463035}}
1618677463.094365: {"stream":"dentusdt@bookTicker","data":{"e":"bookTicker","u":335341043467,"s":"DENTUSDT","b":"0.012348","B":"21101","a":"0.012359","A":"17730","T":1618677463032,"E":1618677463035}}
1618677463.100325: {"stream":"ksmusdt@kline_1m","data":{"e":"kline","E":1618677463041,"s":"KSMUSDT","k":{"t":1618677420000,"T":1618677479999,"s":"KSMUSDT","i":"1m","f":25426460,"L":25426581,"o":"459.607","c":"458.770","h":"459.671","l":"458.391","v":"109.7","n":122,"x":false,"q":"50356.3741","V":"53.4","Q":"24522.5875","B":"0"}}}
1618677463.1004522: {"stream":"ksmusdt@bookTicker","data":{"e":"bookTicker","u":335341043673,"s":"KSMUSDT","b":"458.747","B":"0.2","a":"458.930","A":"0.3","T":1618677463037,"E":1618677463041}}
1618677463.108053: {"stream":"yfiusdt@bookTicker","data":{"e":"bookTicker","u":335341044052,"s":"YFIUSDT","b":"49978.9","B":"0.002","a":"49979.0","A":"0.005","T":1618677463046,"E":1618677463050}}
1618677463.116981: {"stream":"ksmusdt@bookTicker","data":{"e":"bookTicker","u":335341044372,"s":"KSMUSDT","b":"458.747","B":"0.2","a":"458.909","A":"6.4","T":1618677463052,"E":1618677463056}}
1618677463.235577: {"stream":"yfiusdt@bookTicker","data":{"e":"bookTicker","u":335341044615,"s":"YFIUSDT","b":"49973.0","B":"0.003","a":"49979.0","A":"0.005","T":1618677463058,"E":1618677463062}}
1618677463.238158: {"stream":"ksmusdt@bookTicker","data":{"e":"bookTicker","u":335341044903,"s":"KSMUSDT","b":"458.747","B":"1.0","a":"458.909","A":"6.4","T":1618677463065,"E":1618677463069}}
1618677463.238261: {"stream":"yfiusdt@bookTicker","data":{"e":"bookTicker","u":335341044983,"s":"YFIUSDT","b":"49974.3","B":"0.012","a":"49979.0","A":"0.005","T":1618677463067,"E":1618677463071}}
1618677463.240045: {"stream":"yfiusdt@bookTicker","data":{"e":"bookTicker","u":335341045152,"s":"YFIUSDT","b":"49973.0","B":"0.003","a":"49979.0","A":"0.005","T":1618677463071,"E":1618677463075}}
1618677463.240473: {"stream":"ksmusdt@bookTicker","data":{"e":"bookTicker","u":335341045398,"s":"KSMUSDT","b":"458.747","B":"1.0","a":"458.932","A":"6.4","T":1618677463079,"E":1618677463083}}
1618677463.2454028: {"stream":"yfiusdt@bookTicker","data":{"e":"bookTicker","u":335341045876,"s":"YFIUSDT","b":"49978.9","B":"0.004","a":"49979.0","A":"0.005","T":1618677463107,"E":1618677463112}}
1618677463.245503: {"stream":"dentusdt@depth@100ms","data":{"e":"depthUpdate","E":1618677463113,"T":1618677463054,"s":"DENTUSDT","U":335341042359,"u":335341044427,"pu":335341026438,"b":[],"a":[["0.012359","17730"],["0.012361","6819"],["0.012377","3237"],["0.012390","68360"]]}}
1618677463.245985: {"stream":"ksmusdt@depth@100ms","data":{"e":"depthUpdate","E":1618677463122,"T":1618677463106,"s":"KSMUSDT","U":335341042702,"u":335341045847,"pu":335341041922,"b":[["454.274","0.0"],["456.380","1.4"],["457.316","0.0"],["458.502","4.1"],["458.590","1.3"],["458.621","0.0"],["458.701","0.0"],["458.706","1.5"],["458.713","2.5"],["458.714","1.0"],["458.747","1.0"]],"a":[["458.770","0.0"],["458.909","0.0"],["458.930","0.0"],["458.931","0.0"],["459.078","0.3"],["459.242","0.1"],["459.286","0.0"],["459.303","4.0"],["459.399","0.1"],["459.440","0.1"],["459.443","0.0"],["459.460","0.0"],["459.555","0.0"],["459.881","0.0"],["459.976","3.2"],["462.324","0.0"],["463.038","0.0"],["469.577","8.4"]]}}
1618677463.248637: {"stream":"ksmusdt@bookTicker","data":{"e":"bookTicker","u":335341046251,"s":"KSMUSDT","b":"458.748","B":"0.3","a":"458.932","A":"6.4","T":1618677463129,"E":1618677463133}}
1618677463.248739: {"stream":"yfiusdt@depth@100ms","data":{"e":"depthUpdate","E":1618677463135,"T":1618677463129,"s":"YFIUSDT","U":335341043445,"u":335341046282,"pu":335341042421,"b":[["49526.9","0.083"],["49530.5","0.000"],["49751.8","0.083"],["49755.4","0.000"],["49927.5","0.000"],["49930.7","0.000"],["49931.5","0.000"],["49934.6","0.000"],["49936.6","0.077"],["49944.1","0.043"],["49949.3","0.020"],["49950.8","0.009"],["49958.8","0.007"],["49974.3","0.000"],["49974.4","0.002"],["49978.9","0.004"]],"a":[["50007.3","0.000"],["50010.5","0.010"],["50201.5","0.083"],["50205.1","0.004"],["50426.4","0.083"],["50430.0","0.000"]]}}
1618677463.250308: {"stream":"xmrusdt@depth@100ms","data":{"e":"depthUpdate","E":1618677463152,"T":1618677463105,"s":"XMRUSDT","U":335341044235,"u":335341045759,"pu":335341041990,"b":[],"a":[["352.56","0.000"],["353.29","10.781"],["353.58","2.886"]]}}
1618677463.250684: {"stream":"yfiusdt@bookTicker","data":{"e":"bookTicker","u":335341046574,"s":"YFIUSDT","b":"49978.9","B":"0.016","a":"49979.0","A":"0.005","T":1618677463149,"E":1618677463152}}
1618677463.25073: {"stream":"yfiusdt@bookTicker","data":{"e":"bookTicker","u":335341046703,"s":"YFIUSDT","b":"49978.9","B":"0.012","a":"49979.0","A":"0.005","T":1618677463151,"E":1618677463155}}
1618677463.254713: {"stream":"dentusdt@aggTrade","data":{"e":"aggTrade","E":1618677463164,"a":8476425,"s":"DENTUSDT","p":"0.012359","q":"4000","f":15787417,"l":15787417,"T":1618677463010,"m":false}}
1618677463.254805: {"stream":"yfiusdt@bookTicker","data":{"e":"bookTicker","u":335341046995,"s":"YFIUSDT","b":"49974.3","B":"0.012","a":"49979.0","A":"0.005","T":1618677463159,"E":1618677463164}}
1618677463.254835: {"stream":"yfiusdt@bookTicker","data":{"e":"bookTicker","u":335341047023,"s":"YFIUSDT","b":"49973.0","B":"0.003","a":"49979.0","A":"0.005","T":1618677463161,"E":1618677463164}}
1618677463.254858: {"stream":"ksmusdt@bookTicker","data":{"e":"bookTicker","u":335341047194,"s":"KSMUSDT","b":"458.749","B":"1.1","a":"458.932","A":"6.4","T":1618677463163,"E":1618677463167}}
1618677463.258744: {"stream":"yfiusdt@bookTicker","data":{"e":"bookTicker","u":335341047652,"s":"YFIUSDT","b":"49974.4","B":"0.004","a":"49979.0","A":"0.005","T":1618677463171,"E":1618677463175}}
1618677463.258844: {"stream":"yfiusdt@bookTicker","data":{"e":"bookTicker","u":335341047656,"s":"YFIUSDT","b":"49978.9","B":"0.003","a":"49979.0","A":"0.005","T":1618677463171,"E":1618677463175}}
1618677463.2588868: {"stream":"yfiusdt@bookTicker","data":{"e":"bookTicker","u":335341047761,"s":"YFIUSDT","b":"49974.4","B":"0.004","a":"49979.0","A":"0.005","T":1618677463176,"E":1618677463178}}
1618677463.258921: {"stream":"yfiusdt@bookTicker","data":{"e":"bookTicker","u":335341047763,"s":"YFIUSDT","b":"49973.0","B":"0.003","a":"49979.0","A":"0.005","T":1618677463176,"E":1618677463178}}
1618677463.258951: {"stream":"yfiusdt@bookTicker","data":{"e":"bookTicker","u":335341047830,"s":"YFIUSDT","b":"49975.7","B":"0.012","a":"49979.0","A":"0.005","T":1618677463180,"E":1618677463183}}
1618677463.2589781: {"stream":"yfiusdt@bookTicker","data":{"e":"bookTicker","u":335341047896,"s":"YFIUSDT","b":"49973.0","B":"0.003","a":"49979.0","A":"0.005","T":1618677463183,"E":1618677463187}}
1618677463.2590048: {"stream":"ksmusdt@aggTrade","data":{"e":"aggTrade","E":1618677463192,"a":21396987,"s":"KSMUSDT","p":"458.770","q":"0.6","f":25426581,"l":25426581,"T":1618677463037,"m":false}}
1618677463.259051: {"stream":"yfiusdt@bookTicker","data":{"e":"bookTicker","u":335341047995,"s":"YFIUSDT","b":"49978.9","B":"0.002","a":"49979.0","A":"0.005","T":1618677463188,"E":1618677463192}}
1618677463.2590861: {"stream":"yfiusdt@bookTicker","data":{"e":"bookTicker","u":335341048092,"s":"YFIUSDT","b":"49975.8","B":"0.003","a":"49979.0","A":"0.005","T":1618677463192,"E":1618677463196}}
1618677463.259103: {"stream":"yfiusdt@bookTicker","data":{"e":"bookTicker","u":335341048093,"s":"YFIUSDT","b":"49973.0","B":"0.003","a":"49979.0","A":"0.005","T":1618677463192,"E":1618677463196}}
1618677463.26061: {"stream":"yfiusdt@bookTicker","data":{"e":"bookTicker","u":335341048216,"s":"YFIUSDT","b":"49978.9","B":"0.004","a":"49979.0","A":"0.005","T":1618677463197,"E":1618677463202}}
1618677463.265963: {"stream":"ksmusdt@bookTicker","data":{"e":"bookTicker","u":335341048383,"s":"KSMUSDT","b":"458.750","B":"0.3","a":"458.932","A":"6.4","T":1618677463202,"E":1618677463207}}
1618677463.267458: {"stream":"yfiusdt@bookTicker","data":{"e":"bookTicker","u":335341048506,"s":"YFIUSDT","b":"49977.1","B":"0.012","a":"49979.0","A":"0.005","T":1618677463205,"E":1618677463209}}
1618677463.2675571: {"stream":"yfiusdt@bookTicker","data":{"e":"bookTicker","u":335341048543,"s":"YFIUSDT","b":"49975.9","B":"0.003","a":"49979.0","A":"0.005","T":1618677463206,"E":1618677463210}}
1618677463.2675998: {"stream":"yfiusdt@bookTicker","data":{"e":"bookTicker","u":335341048549,"s":"YFIUSDT","b":"49978.9","B":"0.012","a":"49979.0","A":"0.005","T":1618677463206,"E":1618677463210}}
1618677463.272799: {"stream":"yfiusdt@bookTicker","data":{"e":"bookTicker","u":335341048630,"s":"YFIUSDT","b":"49978.9","B":"0.016","a":"49979.0","A":"0.005","T":1618677463210,"E":1618677463214}}
1618677463.2728992: {"stream":"ksmusdt@bookTicker","data":{"e":"bookTicker","u":335341048719,"s":"KSMUSDT","b":"458.751","B":"1.2","a":"458.932","A":"6.4","T":1618677463213,"E":1618677463215}}
1618677463.274982: {"stream":"yfiusdt@bookTicker","data":{"e":"bookTicker","u":335341048763,"s":"YFIUSDT","b":"49978.9","B":"0.004","a":"49979.0","A":"0.005","T":1618677463214,"E":1618677463217}}
1618677463.288893: {"stream":"ksmusdt@depth@100ms","data":{"e":"depthUpdate","E":1618677463230,"T":1618677463213,"s":"KSMUSDT","U":335341046142,"u":335341048719,"pu":335341045847,"b":[["449.752","0.0"],["453.252","0.0"],["454.561","0.0"],["455.214","0.0"],["458.714","0.0"],["458.715","0.9"],["458.747","0.0"],["458.748","0.0"],["458.749","0.0"],["458.750","0.3"],["458.751","1.2"]],"a":[["459.859","30.8"],["459.881","0.0"],["460.437","0.0"],["461.405","0.0"],["463.271","0.2"],["463.558","0.0"],["463.818","0.0"],["463.957","0.0"],["472.577","0.0"]]}}
1618677463.2892559: {"stream":"yfiusdt@bookTicker","data":{"e":"bookTicker","u":335341049027,"s":"YFIUSDT","b":"49973.0","B":"0.003","a":"49979.0","A":"0.005","T":1618677463226,"E":1618677463231}}
1618677463.294029: {"stream":"yfiusdt@depth@100ms","data":{"e":"depthUpdate","E":1618677463235,"T":1618677463231,"s":"YFIUSDT","U":335341046334,"u":335341049152,"pu":335341046282,"b":[["49917.7","0.001"],["49919.6","0.001"],["49921.0","0.001"],["49921.8","0.001"],["49922.8","0.000"],["49923.6","0.000"],["49935.6","0.000"],["49958.9","0.010"],["49964.8","0.237"],["49974.3","0.000"],["49974.4","0.000"],["49975.7","0.000"],["49975.8","0.000"],["49975.9","0.000"],["49977.1","0.000"],["49977.2","0.000"],["49978.9","0.000"]],"a":[["50094.9","0.100"]]}}
1618677463.3053172: {"stream":"ksmusdt@bookTicker","data":{"e":"bookTicker","u":335341049560,"s":"KSMUSDT","b":"458.752","B":"0.3","a":"458.932","A":"6.4","T":1618677463244,"E":1618677463247}}
1618677463.313341: {"stream":"xmrusdt@depth@100ms","data":{"e":"depthUpdate","E":1618677463256,"T":1618677463193,"s":"XMRUSDT","U":335341046814,"u":335341048126,"pu":335341045759,"b":[["350.52","3.676"]],"a":[["352.92","30.368"],["352.93","0.000"],["352.94","0.612"],["352.97","5.928"],["352.98","28.222"],["353.36","29.574"]]}}
1618677463.316488: {"stream":"ksmusdt@bookTicker","data":{"e":"bookTicker","u":335341049848,"s":"KSMUSDT","b":"458.753","B":"0.7","a":"458.932","A":"6.4","T":1618677463253,"E":1618677463257}}
1618677463.322986: {"stream":"ksmusdt@bookTicker","data":{"e":"bookTicker","u":335341050108,"s":"KSMUSDT","b":"458.752","B":"0.3","a":"458.932","A":"6.4","T":1618677463263,"E":1618677463265}}
1618677463.327141: {"stream":"ksmusdt@bookTicker","data":{"e":"bookTicker","u":335341050129,"s":"KSMUSDT","b":"458.755","B":"0.7","a":"458.932","A":"6.4","T":1618677463263,"E":1618677463267}}
1618677463.334729: {"stream":"ksmusdt@bookTicker","data":{"e":"bookTicker","u":335341050463,"s":"KSMUSDT","b":"458.752","B":"0.3","a":"458.932","A":"6.4","T":1618677463272,"E":1618677463276}}
1618677463.334827: {"stream":"ksmusdt@bookTicker","data":{"e":"bookTicker","u":335341050473,"s":"KSMUSDT","b":"458.757","B":"0.8","a":"458.932","A":"6.4","T":1618677463272,"E":1618677463276}}
1618677463.442091: {"stream":"yfiusdt@bookTicker","data":{"e":"bookTicker","u":335341051032,"s":"YFIUSDT","b":"49973.0","B":"0.003","a":"49986.7","A":"0.001","T":1618677463287,"E":1618677463291}}
1618677463.442199: {"stream":"ksmusdt@bookTicker","data":{"e":"bookTicker","u":335341051038,"s":"KSMUSDT","b":"458.752","B":"0.3","a":"458.932","A":"6.4","T":1618677463288,"E":1618677463292}}
1618677463.442227: {"stream":"ksmusdt@bookTicker","data":{"e":"bookTicker","u":335341051052,"s":"KSMUSDT","b":"458.759","B":"0.2","a":"458.932","A":"6.4","T":1618677463288,"E":1618677463292}}
1618677463.4422479: {"stream":"yfiusdt@bookTicker","data":{"e":"bookTicker","u":335341051396,"s":"YFIUSDT","b":"49973.1","B":"0.025","a":"49986.7","A":"0.001","T":1618677463296,"E":1618677463299}}
1618677463.4422662: {"stream":"yfiusdt@bookTicker","data":{"e":"bookTicker","u":335341051431,"s":"YFIUSDT","b":"49973.1","B":"0.025","a":"49976.0","A":"0.005","T":1618677463297,"E":1618677463300}}
1618677463.442284: {"stream":"yfiusdt@kline_1m","data":{"e":"kline","E":1618677463311,"s":"YFIUSDT","k":{"t":1618677420000,"T":1618677479999,"s":"YFIUSDT","i":"1m","f":64902095,"L":64902183,"o":"50010.8","c":"49976.0","h":"50044.2","l":"49950.6","v":"1.005","n":89,"x":false,"q":"50248.4049","V":"0.696","Q":"34799.0579","B":"0"}}}
1618677463.442324: {"stream":"yfiusdt@bookTicker","data":{"e":"bookTicker","u":335341051821,"s":"YFIUSDT","b":"49973.2","B":"0.006","a":"49976.0","A":"0.005","T":1618677463307,"E":1618677463310}}
1618677463.442343: {"stream":"yfiusdt@bookTicker","data":{"e":"bookTicker","u":335341051836,"s":"YFIUSDT","b":"49973.2","B":"0.006","a":"49986.7","A":"0.001","T":1618677463307,"E":1618677463310}}
1618677463.4423602: {"stream":"yfiusdt@bookTicker","data":{"e":"bookTicker","u":335341051858,"s":"YFIUSDT","b":"49975.9","B":"0.007","a":"49986.7","A":"0.001","T":1618677463307,"E":1618677463310}}
1618677463.4423769: {"stream":"yfiusdt@bookTicker","data":{"e":"bookTicker","u":335341052162,"s":"YFIUSDT","b":"49977.2","B":"0.012","a":"49986.7","A":"0.001","T":1618677463316,"E":1618677463320}}
1618677463.442394: {"stream":"dentusdt@depth@100ms","data":{"e":"depthUpdate","E":1618677463324,"T":1618677463275,"s":"DENTUSDT","U":335341048912,"u":335341050577,"pu":335341044427,"b":[["0.012220","170809"],["0.012317","127900"],["0.012345","26795"]],"a":[]}}
1618677463.4425159: {"stream":"ksmusdt@depth@100ms","data":{"e":"depthUpdate","E":1618677463340,"T":1618677463321,"s":"KSMUSDT","U":335341049272,"u":335341052316,"pu":335341048719,"b":[["455.041","0.0"],["455.709","0.0"],["456.575","0.0"],["458.750","0.0"],["458.751","0.0"],["458.752","0.3"],["458.753","0.0"],["458.755","0.0"],["458.757","0.0"],["458.759","0.2"]],"a":[["459.023","1.2"],["459.047","0.3"],["459.048","0.0"],["459.077","1.6"],["459.078","0.0"],["459.079","0.0"],["459.858","0.0"],["463.066","0.0"],["463.945","0.0"],["471.624","0.0"]]}}
1618677463.4426959: {"stream":"yfiusdt@depth@100ms","data":{"e":"depthUpdate","E":1618677463342,"T":1618677463337,"s":"YFIUSDT","U":335341049341,"u":335341052878,"pu":335341049152,"b":[["49917.0","0.000"],["49917.7","0.000"],["49921.0","0.000"],["49921.2","0.000"],["49921.8","0.000"],["49923.4","0.018"],["49926.5","0.000"],["49929.6","0.110"],["49929.8","0.000"],["49930.6","0.000"],["49931.8","0.002"],["49933.8","0.110"],["49935.8","0.002"],["49950.7","0.000"],["49955.6","0.000"],["49958.2","0.000"],["49958.3","0.000"],["49958.7","0.000"],["49958.8","0.000"],["49958.9","0.000"],["49959.3","0.032"],["49964.9","0.012"],["49965.0","0.050"],["49965.1","0.013"],["49973.1","0.025"],["49973.2","0.000"],["49974.5","0.000"],["49975.9","0.000"],["49977.2","0.012"]],"a":[["49976.0","0.000"],["49979.0","0.000"],["50010.5","0.000"],["50010.6","0.000"],["50015.7","0.032"],["50065.0","0.236"],["50096.7","0.000"],["50099.9","0.050"],["50117.2","0.000"],["50124.7","0.157"]]}}
1618677463.442956: {"stream":"xmrusdt@depth@100ms","data":{"e":"depthUpdate","E":1618677463374,"T":1618677463312,"s":"XMRUSDT","U":335341050343,"u":335341052010,"pu":335341048126,"b":[],"a":[["352.89","8.040"],["352.90","38.286"],["352.92","0.000"]]}}
1618677463.452522: {"stream":"ksmusdt@bookTicker","data":{"e":"bookTicker","u":335341054437,"s":"KSMUSDT","b":"458.759","B":"0.2","a":"458.932","A":"6.7","T":1618677463391,"E":1618677463395}}
1618677463.483233: {"stream":"ksmusdt@bookTicker","data":{"e":"bookTicker","u":335341055497,"s":"KSMUSDT","b":"458.759","B":"0.2","a":"458.932","A":"6.4","T":1618677463422,"E":1618677463425}}
1618677463.489675: {"stream":"dentusdt@depth@100ms","data":{"e":"depthUpdate","E":1618677463434,"T":1618677463397,"s":"DENTUSDT","U":335341052623,"u":335341054665,"pu":335341050577,"b":[["0.012203","0"]],"a":[["0.012400","776065"],["0.012428","45218"]]}}
1618677463.5003982: {"stream":"yfiusdt@depth@100ms","data":{"e":"depthUpdate","E":1618677463442,"T":1618677463389,"s":"YFIUSDT","U":335341052881,"u":335341054374,"pu":335341052878,"b":[["49927.6","0.001"],["49930.8","0.001"],["49931.6","0.071"],["49931.8","0.000"],["49935.0","0.000"],["49935.8","0.000"],["49950.8","0.000"],["49955.8","0.000"],["49964.9","0.000"],["49965.2","0.012"]],"a":[["50078.6","0.011"]]}}
1618677463.506924: {"stream":"ksmusdt@depth@100ms","data":{"e":"depthUpdate","E":1618677463451,"T":1618677463423,"s":"KSMUSDT","U":335341053155,"u":335341055525,"pu":335341052316,"b":[["453.378","0.0"],["454.265","0.2"],["454.296","0.0"]],"a":[["458.932","6.4"],["459.021","0.3"],["459.022","1.6"],["459.023","0.0"],["459.047","0.0"],["459.077","0.0"],["459.858","1.0"],["465.010","0.0"],["470.739","3.7"]]}}
1618677463.517598: {"stream":"yfiusdt@aggTrade","data":{"e":"aggTrade","E":1618677463461,"a":52599703,"s":"YFIUSDT","p":"49976.0","q":"0.005","f":64902183,"l":64902183,"T":1618677463307,"m":false}}
1618677463.53559: {"stream":"dentusdt@bookTicker","data":{"e":"bookTicker","u":335341057068,"s":"DENTUSDT","b":"0.012348","B":"21101","a":"0.012360","A":"38297","T":1618677463474,"E":1618677463479}}
1618677463.5603259: {"stream":"xmrusdt@depth@100ms","data":{"e":"depthUpdate","E":1618677463504,"T":1618677463438,"s":"XMRUSDT","U":335341054723,"u":335341056017,"pu":335341052010,"b":[["351.87","0.000"]],"a":[["352.77","2.500"],["352.78","0.000"],["352.88","0.000"],["354.98","1.426"]]}}
1618677463.5764322: {"stream":"dentusdt@bookTicker","data":{"e":"bookTicker","u":335341058310,"s":"DENTUSDT","b":"0.012348","B":"13005","a":"0.012360","A":"38297","T":1618677463515,"E":1618677463518}}
1618677463.57655: {"stream":"dentusdt@kline_1m","data":{"e":"kline","E":1618677463519,"s":"DENTUSDT","k":{"t":1618677420000,"T":1618677479999,"s":"DENTUSDT","i":"1m","f":15787262,"L":15787418,"o":"0.012366","c":"0.012348","h":"0.012366","l":"0.012339","v":"2615131","n":157,"x":false,"q":"32302.494140","V":"1197355","Q":"14793.770120","B":"0"}}}
1618677463.587035: {"stream":"dentusdt@bookTicker","data":{"e":"bookTicker","u":335341058664,"s":"DENTUSDT","b":"0.012348","B":"13005","a":"0.012359","A":"8899","T":1618677463527,"E":1618677463529}}
1618677463.593513: {"stream":"dentusdt@depth@100ms","data":{"e":"depthUpdate","E":1618677463535,"T":1618677463527,"s":"DENTUSDT","U":335341055715,"u":335341058664,"pu":335341054665,"b":[["0.012196","296033"],["0.012241","485139"],["0.012272","163997"],["0.012273","959279"],["0.012294","60134"],["0.012295","659982"],["0.012324","53723"],["0.012348","13005"]],"a":[["0.012359","8899"],["0.012361","24549"],["0.012362","156250"],["0.012367","217028"],["0.012381","62876"],["0.012446","0"],["0.012451","1075496"]]}}
1618677463.5992599: {"stream":"dentusdt@bookTicker","data":{"e":"bookTicker","u":335341059030,"s":"DENTUSDT","b":"0.012348","B":"8826","a":"0.012359","A":"8899","T":1618677463537,"E":1618677463541}}
1618677463.615784: {"stream":"ksmusdt@depth@100ms","data":{"e":"depthUpdate","E":1618677463552,"T":1618677463539,"s":"KSMUSDT","U":335341056227,"u":335341059080,"pu":335341055525,"b":[["450.549","12.3"],["456.240","1.2"],["456.246","1.1"],["456.687","3.4"]],"a":[["459.022","0.0"],["459.079","1.6"],["459.858","1.0"],["462.866","3.4"]]}}
1618677463.641899: {"stream":"dentusdt@bookTicker","data":{"e":"bookTicker","u":335341060264,"s":"DENTUSDT","b":"0.012348","B":"8826","a":"0.012359","A":"62865","T":1618677463578,"E":1618677463581}}
1618677463.642: {"stream":"yfiusdt@depth@100ms","data":{"e":"depthUpdate","E":1618677463582,"T":1618677463572,"s":"YFIUSDT","U":335341057191,"u":335341060040,"pu":335341054374,"b":[["49890.1","0.210"],["49969.2","0.016"]],"a":[["50124.7","0.000"],["50138.6","0.000"],["50920.5","0.010"]]}}
1618677463.680036: {"stream":"dentusdt@bookTicker","data":{"e":"bookTicker","u":335341061416,"s":"DENTUSDT","b":"0.012348","B":"8826","a":"0.012359","A":"80595","T":1618677463615,"E":1618677463619}}
1618677463.6801338: {"stream":"yfiusdt@bookTicker","data":{"e":"bookTicker","u":335341061476,"s":"YFIUSDT","b":"49977.3","B":"0.001","a":"49986.7","A":"0.001","T":1618677463618,"E":1618677463620}}
1618677463.6875992: {"stream":"ksmusdt@bookTicker","data":{"e":"bookTicker","u":335341061787,"s":"KSMUSDT","b":"458.759","B":"0.2","a":"458.975","A":"0.1","T":1618677463626,"E":1618677463630}}
1618677463.698246: {"stream":"dentusdt@depth@100ms","data":{"e":"depthUpdate","E":1618677463639,"T":1618677463622,"s":"DENTUSDT","U":335341059006,"u":335341061653,"pu":335341058664,"b":[["0.012212","702962"],["0.012260","408640"],["0.012326","560724"],["0.012345","30974"],["0.012348","8826"]],"a":[["0.012359","80595"],["0.012361","47293"],["0.012362","102284"],["0.012366","49787"],["0.012367","274966"],["0.012369","134909"],["0.012381","22403"]]}}
1618677463.716167: {"stream":"yfiusdt@bookTicker","data":{"e":"bookTicker","u":335341062724,"s":"YFIUSDT","b":"49978.6","B":"0.012","a":"49986.7","A":"0.001","T":1618677463653,"E":1618677463657}}
1618677463.7182: {"stream":"ksmusdt@bookTicker","data":{"e":"bookTicker","u":335341062775,"s":"KSMUSDT","b":"458.774","B":"6.4","a":"458.975","A":"0.1","T":1618677463655,"E":1618677463659}}
1618677463.7255669: {"stream":"xmrusdt@depth@100ms","data":{"e":"depthUpdate","E":1618677463667,"T":1618677463661,"s":"XMRUSDT","U":335341059626,"u":335341062983,"pu":335341056017,"b":[["340.81","1.869"],["348.80","24.768"],["349.43","0.000"],["349.73","0.724"],["350.36","7.696"]],"a":[["352.55","3.001"],["354.55","200.000"],["354.69","617.465"],["355.98","0.284"]]}}
1618677463.725673: {"stream":"dentusdt@aggTrade","data":{"e":"aggTrade","E":1618677463669,"a":8476426,"s":"DENTUSDT","p":"0.012348","q":"8096","f":15787418,"l":15787418,"T":1618677463515,"m":true}}
1618677463.727551: {"stream":"ksmusdt@depth@100ms","data":{"e":"depthUpdate","E":1618677463672,"T":1618677463665,"s":"KSMUSDT","U":335341059873,"u":335341063152,"pu":335341059080,"b":[["458.147","0.0"],["458.159","5.7"],["458.759","0.0"],["458.774","6.4"]],"a":[["458.932","0.0"],["459.304","0.0"],["459.537","0.0"],["459.538","0.0"],["459.858","0.0"],["460.145","0.0"],["461.981","0.1"],["462.440","0.2"],["462.711","0.0"],["463.170","0.0"]]}}
1618677463.731122: {"stream":"yfiusdt@kline_1m","data":{"e":"kline","E":1618677463674,"s":"YFIUSDT","k":{"t":1618677420000,"T":1618677479999,"s":"YFIUSDT","i":"1m","f":64902095,"L":64902184,"o":"50010.8","c":"49986.7","h":"50044.2","l":"49950.6","v":"1.006","n":90,"x":false,"q":"50298.3916","V":"0.697","Q":"34849.0446","B":"0"}}}
1618677463.7312021: {"stream":"yfiusdt@bookTicker","data":{"e":"bookTicker","u":335341063284,"s":"YFIUSDT","b":"49978.6","B":"0.012","a":"50006.7","A":"0.001","T":1618677463670,"E":1618677463674}}
1618677463.7475681: {"stream":"yfiusdt@bookTicker","data":{"e":"bookTicker","u":335341063889,"s":"YFIUSDT","b":"49978.7","B":"0.010","a":"50006.7","A":"0.001","T":1618677463684,"E":1618677463688}}
1618677463.75148: {"stream":"ksmusdt@bookTicker","data":{"e":"bookTicker","u":335341064018,"s":"KSMUSDT","b":"458.775","B":"0.3","a":"458.975","A":"0.1","T":1618677463690,"E":1618677463692}}
1618677463.7570791: {"stream":"yfiusdt@depth@100ms","data":{"e":"depthUpdate","E":1618677463700,"T":1618677463695,"s":"YFIUSDT","U":335341060894,"u":335341064239,"pu":335341060040,"b":[["49925.4","0.017"],["49927.6","0.000"],["49929.6","0.000"],["49930.8","0.000"],["49931.6","0.070"],["49933.2","0.002"],["49936.4","0.082"],["49937.2","0.002"],["49938.0","0.110"],["49941.3","0.087"],["49942.2","0.110"],["49965.1","0.000"],["49965.2","0.000"],["49973.5","0.000"],["49975.0","0.013"],["49977.2","0.055"],["49977.3","0.001"],["49978.6","0.012"],["49978.7","0.010"]],"a":[["49986.7","0.000"],["49995.0","0.000"],["49995.1","0.000"],["50007.4","0.000"],["50015.7","0.000"],["50023.7","0.060"],["50023.9","0.001"],["50024.0","0.000"],["50032.9","0.000"],["50034.7","0.001"],["50035.6","0.001"],["50040.3","0.000"],["50046.2","0.000"],["50046.8","0.015"],["50054.3","0.015"],["50058.3","0.000"],["50060.0","0.015"],["50068.4","0.011"],["50078.6","0.000"],["50080.7","0.130"],["50092.9","0.019"],["50096.8","0.000"],["50110.3","0.404"],["50160.6","0.157"]]}}
1618677463.7607832: {"stream":"yfiusdt@bookTicker","data":{"e":"bookTicker","u":335341064360,"s":"YFIUSDT","b":"49981.1","B":"0.055","a":"50006.7","A":"0.001","T":1618677463699,"E":1618677463702}}
1618677463.774061: {"stream":"yfiusdt@bookTicker","data":{"e":"bookTicker","u":335341064837,"s":"YFIUSDT","b":"49981.2","B":"0.005","a":"50006.7","A":"0.001","T":1618677463712,"E":1618677463716}}
1618677463.798041: {"stream":"yfiusdt@bookTicker","data":{"e":"bookTicker","u":335341065712,"s":"YFIUSDT","b":"49981.2","B":"0.010","a":"50006.7","A":"0.001","T":1618677463736,"E":1618677463740}}
1618677463.802755: {"stream":"ksmusdt@bookTicker","data":{"e":"bookTicker","u":335341065917,"s":"KSMUSDT","b":"458.775","B":"0.3","a":"458.875","A":"0.2","T":1618677463741,"E":1618677463745}}
1618677463.807669: {"stream":"yfiusdt@bookTicker","data":{"e":"bookTicker","u":335341066122,"s":"YFIUSDT","b":"49982.5","B":"0.012","a":"50006.7","A":"0.001","T":1618677463745,"E":1618677463750}}
1618677463.8250089: {"stream":"yfiusdt@bookTicker","data":{"e":"bookTicker","u":335341066761,"s":"YFIUSDT","b":"49982.6","B":"0.005","a":"50006.7","A":"0.001","T":1618677463761,"E":1618677463766}}
1618677463.835063: {"stream":"xmrusdt@depth@100ms","data":{"e":"depthUpdate","E":1618677463776,"T":1618677463761,"s":"XMRUSDT","U":335341063361,"u":335341066762,"pu":335341062983,"b":[["348.95","0.199"],["349.58","1.630"],["349.73","0.724"],["350.16","4.606"],["350.36","7.696"],["351.62","0.000"],["351.66","200.000"],["352.11","6.035"]],"a":[["352.98","0.000"],["353.02","35.512"],["353.33","0.000"],["353.34","10.374"],["353.35","0.000"],["353.38","202.281"],["354.55","0.000"]]}}
1618677463.835346: {"stream":"ksmusdt@depth@100ms","data":{"e":"depthUpdate","E":1618677463776,"T":1618677463766,"s":"KSMUSDT","U":335341063395,"u":335341067019,"pu":335341063152,"b":[["458.160","0.0"],["458.255","6.2"],["458.502","1.5"],["458.503","0.0"],["458.619","0.0"],["458.620","0.0"],["458.748","0.0"],["458.752","0.0"],["458.775","0.3"]],"a":[["458.875","0.2"],["459.079","3.2"],["459.080","0.0"],["459.246","2.9"],["459.247","1.6"],["459.303","0.0"],["459.452","0.0"],["459.858","0.0"],["459.859","0.0"],["459.972","0.0"],["459.976","0.0"],["460.093","0.0"],["460.118","0.0"],["460.167","6.0"],["470.745","4.5"]]}}
1618677463.839034: {"stream":"ksmusdt@kline_1m","data":{"e":"kline","E":1618677463780,"s":"KSMUSDT","k":{"t":1618677420000,"T":1618677479999,"s":"KSMUSDT","i":"1m","f":25426460,"L":25426582,"o":"459.607","c":"458.875","h":"459.671","l":"458.391","v":"109.9","n":123,"x":false,"q":"50448.1491","V":"53.6","Q":"24614.3625","B":"0"}}}
1618677463.842861: {"stream":"ksmusdt@bookTicker","data":{"e":"bookTicker","u":335341067407,"s":"KSMUSDT","b":"458.775","B":"0.3","a":"458.975","A":"0.1","T":1618677463775,"E":1618677463781}}
1618677463.84296: {"stream":"yfiusdt@bookTicker","data":{"e":"bookTicker","u":335341067503,"s":"YFIUSDT","b":"49982.6","B":"0.010","a":"50006.7","A":"0.001","T":1618677463777,"E":1618677463781}}
1618677463.851134: {"stream":"yfiusdt@bookTicker","data":{"e":"bookTicker","u":335341067848,"s":"YFIUSDT","b":"49983.9","B":"0.012","a":"50006.7","A":"0.001","T":1618677463787,"E":1618677463790}}
1618677463.851234: {"stream":"dentusdt@bookTicker","data":{"e":"bookTicker","u":335341067896,"s":"DENTUSDT","b":"0.012348","B":"8826","a":"0.012358","A":"2826","T":1618677463789,"E":1618677463792}}
1618677463.858621: {"stream":"yfiusdt@depth@100ms","data":{"e":"depthUpdate","E":1618677463800,"T":1618677463795,"s":"YFIUSDT","U":335341064248,"u":335341068202,"pu":335341064239,"b":[["49930.4","0.000"],["49936.6","0.000"],["49941.3","0.000"],["49949.2","0.009"],["49955.8","0.009"],["49959.3","0.000"],["49965.1","0.168"],["49968.3","0.067"],["49975.0","0.000"],["49976.6","0.000"],["49977.3","0.013"],["49977.6","0.013"],["49978.6","0.000"],["49978.7","0.000"],["49981.1","0.055"],["49981.2","0.000"],["49982.5","0.000"],["49982.6","0.010"],["49983.9","0.012"]],"a":[["50011.8","0.000"],["50015.0","0.013"],["50023.9","0.000"],["50034.7","0.000"],["50035.6","0.000"],["50041.1","0.007"],["50046.8","0.000"],["50051.9","0.009"],["50052.7","0.003"],["50052.8","0.002"],["50054.3","0.000"],["50060.0","0.000"],["50060.2","0.003"],["50060.4","0.000"],["50065.9","0.009"],["50080.7","0.000"],["50094.9","0.000"],["50108.8","0.000"],["50140.5","0.000"],["50169.9","0.014"]]}}
1618677463.863411: {"stream":"yfiusdt@bookTicker","data":{"e":"bookTicker","u":335341068357,"s":"YFIUSDT","b":"49984.0","B":"0.005","a":"50006.7","A":"0.001","T":1618677463799,"E":1618677463801}}
1618677463.8637838: {"stream":"dentusdt@bookTicker","data":{"e":"bookTicker","u":335341068391,"s":"DENTUSDT","b":"0.012348","B":"8826","a":"0.012357","A":"8967","T":1618677463800,"E":1618677463803}}
1618677463.8734279: {"stream":"yfiusdt@bookTicker","data":{"e":"bookTicker","u":335341068833,"s":"YFIUSDT","b":"49983.9","B":"0.012","a":"50006.7","A":"0.001","T":1618677463811,"E":1618677463815}}
1618677463.8864472: {"stream":"yfiusdt@aggTrade","data":{"e":"aggTrade","E":1618677463825,"a":52599704,"s":"YFIUSDT","p":"49986.7","q":"0.001","f":64902184,"l":64902184,"T":1618677463670,"m":false}}
1618677463.901584: {"stream":"yfiusdt@bookTicker","data":{"e":"bookTicker","u":335341069813,"s":"YFIUSDT","b":"49984.9","B":"0.055","a":"50006.7","A":"0.001","T":1618677463835,"E":1618677463839}}
1618677463.9381702: {"stream":"xmrusdt@depth@100ms","data":{"e":"depthUpdate","E":1618677463877,"T":1618677463863,"s":"XMRUSDT","U":335341067327,"u":335341071061,"pu":335341066762,"b":[["347.94","0.106"],["348.57","0.034"],["349.69","7.088"],["350.32","48.784"],["351.71","0.000"],["351.80","2.443"]],"a":[["352.54","0.000"],["352.55","0.000"],["352.57","0.001"],["352.60","2.871"],["352.97","0.000"],["354.55","0.000"],["356.17","6.210"]]}}
1618677463.9395661: {"stream":"ksmusdt@depth@100ms","data":{"e":"depthUpdate","E":1618677463881,"T":1618677463804,"s":"KSMUSDT","U":335341067407,"u":335341068532,"pu":335341067019,"b":[["458.256","1.1"],["458.755","1.2"]],"a":[["458.875","0.0"],["459.245","1.5"],["459.247","0.0"],["459.405","1.6"],["459.881","1.0"],["460.167","0.0"]]}}
1618677463.949378: {"stream":"dentusdt@depth@100ms","data":{"e":"depthUpdate","E":1618677463892,"T":1618677463885,"s":"DENTUSDT","U":335341067879,"u":335341071961,"pu":335341061653,"b":[["0.011794","5396"],["0.012306","91402"],["0.012341","62636"],["0.012345","4051"]],"a":[["0.012357","8967"],["0.012358","2826"],["0.012359","53966"],["0.012361","0"],["0.012362","150857"],["0.012363","359412"],["0.012365","57938"],["0.012367","217028"],["0.012378","39838"],["0.012379","79113"]]}}
1618677463.960425: {"stream":"yfiusdt@depth@100ms","data":{"e":"depthUpdate","E":1618677463901,"T":1618677463883,"s":"YFIUSDT","U":335341068349,"u":335341071893,"pu":335341068202,"b":[["49551.6","0.000"],["49564.8","0.003"],["49902.8","0.000"],["49915.4","0.000"],["49933.2","0.000"],["49936.4","0.080"],["49937.2","0.000"],["49939.5","0.013"],["49942.3","0.026"],["49942.7","0.013"],["49943.6","0.088"],["49964.8","0.000"],["49965.0","0.000"],["49977.2","0.000"],["49977.3","0.001"],["49981.2","0.010"],["49982.6","0.000"],["49984.0","0.000"],["49984.9","0.055"]],"a":[["50023.9","0.000"],["50031.8","0.000"],["50032.6","0.003"],["50034.7","0.000"],["50035.6","0.000"],["50041.1","0.020"],["50042.5","0.000"],["50043.4","0.000"],["50051.1","0.000"],["50051.9","0.021"],["50052.8","0.015"],["50065.0","0.000"],["50089.1","0.000"],["50096.5","0.074"],["50201.7","0.000"],["50321.0","0.000"],["50741.1","0.001"]]}}
1618677463.970475: {"stream":"dentusdt@bookTicker","data":{"e":"bookTicker","u":335341072632,"s":"DENTUSDT","b":"0.012348","B":"8826","a":"0.012357","A":"26697","T":1618677463901,"E":1618677463904}}
1618677463.9705758: {"stream":"xmrusdt@bookTicker","data":{"e":"bookTicker","u":335341072923,"s":"XMRUSDT","b":"352.52","B":"3.720","a":"352.53","A":"0.116","T":1618677463909,"E":1618677463911}}
1618677463.973854: {"stream":"yfiusdt@bookTicker","data":{"e":"bookTicker","u":335341072998,"s":"YFIUSDT","b":"49985.0","B":"0.012","a":"50006.7","A":"0.001","T":1618677463911,"E":1618677463914}}
1618677463.991575: {"stream":"ksmusdt@aggTrade","data":{"e":"aggTrade","E":1618677463932,"a":21396988,"s":"KSMUSDT","p":"458.875","q":"0.2","f":25426582,"l":25426582,"T":1618677463775,"m":false}}
1618677464.0222: {"stream":"yfiusdt@bookTicker","data":{"e":"bookTicker","u":335341074420,"s":"YFIUSDT","b":"49986.3","B":"0.012","a":"50006.7","A":"0.001","T":1618677463955,"E":1618677463958}}
1618677464.0394938: {"stream":"xmrusdt@depth@100ms","data":{"e":"depthUpdate","E":1618677463980,"T":1618677463957,"s":"XMRUSDT","U":335341071567,"u":335341074519,"pu":335341071061,"b":[["347.96","200.616"],["348.59","6.360"],["349.69","207.088"],["350.32","248.784"],["352.19","15.280"],["352.28","0.000"],["352.42","6.600"],["352.52","3.720"]],"a":[["352.57","3.077"],["352.58","0.000"],["352.60","0.000"],["353.09","0.000"],["354.59","205.933"],["356.19","0.000"]]}}
1618677464.053153: {"stream":"yfiusdt@bookTicker","data":{"e":"bookTicker","u":335341075690,"s":"YFIUSDT","b":"49986.3","B":"0.012","a":"49996.5","A":"0.008","T":1618677463989,"E":1618677463993}}
1618677464.0532548: {"stream":"ksmusdt@depth@100ms","data":{"e":"depthUpdate","E":1618677463994,"T":1618677463974,"s":"KSMUSDT","U":335341072142,"u":335341075208,"pu":335341068532,"b":[],"a":[["459.162","1.6"],["459.405","0.0"],["459.579","23.5"],["459.591","0.4"],["459.596","0.0"],["459.881","1.0"]]}}
1618677464.059764: {"stream":"yfiusdt@bookTicker","data":{"e":"bookTicker","u":335341076040,"s":"YFIUSDT","b":"49988.7","B":"0.055","a":"49996.5","A":"0.008","T":1618677463996,"E":1618677464000}}
1618677464.062724: {"stream":"yfiusdt@bookTicker","data":{"e":"bookTicker","u":335341076159,"s":"YFIUSDT","b":"49988.7","B":"0.055","a":"50006.7","A":"0.001","T":1618677463999,"E":1618677464003}}
1618677464.062827: {"stream":"dentusdt@depth@100ms","data":{"e":"depthUpdate","E":1618677464004,"T":1618677463902,"s":"DENTUSDT","U":335341072626,"u":335341072636,"pu":335341071961,"b":[["0.012343","22748"]],"a":[["0.012357","26697"],["0.012361","40478"]]}}
1618677464.062954: {"stream":"yfiusdt@kline_1m","data":{"e":"kline","E":1618677464004,"s":"YFIUSDT","k":{"t":1618677420000,"T":1618677479999,"s":"YFIUSDT","i":"1m","f":64902095,"L":64902185,"o":"50010.8","c":"49996.5","h":"50044.2","l":"49950.6","v":"1.014","n":91,"x":false,"q":"50698.3636","V":"0.705","Q":"35249.0166","B":"0"}}}
1618677464.069164: {"stream":"yfiusdt@bookTicker","data":{"e":"bookTicker","u":335341076469,"s":"YFIUSDT","b":"49990.0","B":"0.012","a":"50006.7","A":"0.001","T":1618677464006,"E":1618677464010}}
1618677464.0698218: {"stream":"yfiusdt@depth@100ms","data":{"e":"depthUpdate","E":1618677464013,"T":1618677464006,"s":"YFIUSDT","U":335341072971,"u":335341076519,"pu":335341071893,"b":[["49257.4","0.000"],["49929.3","0.025"],["49951.4","0.087"],["49965.1","0.000"],["49978.2","0.000"],["49981.1","0.000"],["49983.9","0.000"],["49985.0","0.012"],["49986.3","0.000"],["49988.7","0.055"],["49990.0","0.012"]],"a":[["49996.5","0.000"],["50014.9","0.012"],["50048.5","0.000"],["50066.0","0.000"],["50069.8","0.030"],["50086.4","0.004"],["50099.9","0.000"],["50102.3","0.005"],["50107.3","0.000"],["50109.2","0.021"],["50122.4","0.017"],["50140.6","0.000"],["50145.4","0.000"],["50160.6","0.000"],["50186.2","0.157"]]}}
1618677464.0745459: {"stream":"yfiusdt@bookTicker","data":{"e":"bookTicker","u":335341076766,"s":"YFIUSDT","b":"49990.0","B":"0.012","a":"50006.6","A":"0.003","T":1618677464011,"E":1618677464015}}
1618677464.0783072: {"stream":"ksmusdt@bookTicker","data":{"e":"bookTicker","u":335341076922,"s":"KSMUSDT","b":"458.776","B":"1.8","a":"458.975","A":"0.1","T":1618677464015,"E":1618677464019}}
1618677464.091347: {"stream":"ksmusdt@bookTicker","data":{"e":"bookTicker","u":335341077580,"s":"KSMUSDT","b":"458.776","B":"3.0","a":"458.975","A":"0.1","T":1618677464027,"E":1618677464032}}
1618677464.091452: {"stream":"ksmusdt@bookTicker","data":{"e":"bookTicker","u":335341077598,"s":"KSMUSDT","b":"458.776","B":"1.8","a":"458.975","A":"0.1","T":1618677464028,"E":1618677464032}}
1618677464.0914938: {"stream":"ksmusdt@bookTicker","data":{"e":"bookTicker","u":335341077638,"s":"KSMUSDT","b":"458.777","B":"1.2","a":"458.975","A":"0.1","T":1618677464028,"E":1618677464032}}
1618677464.107491: {"stream":"ksmusdt@bookTicker","data":{"e":"bookTicker","u":335341078356,"s":"KSMUSDT","b":"458.777","B":"3.2","a":"458.975","A":"0.1","T":1618677464043,"E":1618677464047}}
1618677464.109688: {"stream":"ksmusdt@bookTicker","data":{"e":"bookTicker","u":335341078490,"s":"KSMUSDT","b":"458.777","B":"1.2","a":"458.975","A":"0.1","T":1618677464046,"E":1618677464050}}
1618677464.109791: {"stream":"ksmusdt@bookTicker","data":{"e":"bookTicker","u":335341078498,"s":"KSMUSDT","b":"458.778","B":"2.1","a":"458.975","A":"0.1","T":1618677464046,"E":1618677464050}}
1618677464.113017: {"stream":"yfiusdt@aggTrade","data":{"e":"aggTrade","E":1618677464054,"a":52599705,"s":"YFIUSDT","p":"49996.5","q":"0.008","f":64902185,"l":64902185,"T":1618677463999,"m":false}}
1618677464.1131241: {"stream":"yfiusdt@bookTicker","data":{"e":"bookTicker","u":335341078739,"s":"YFIUSDT","b":"49990.0","B":"0.012","a":"50003.0","A":"0.094","T":1618677464051,"E":1618677464054}}
1618677464.1131709: {"stream":"yfiusdt@bookTicker","data":{"e":"bookTicker","u":335341078744,"s":"YFIUSDT","b":"49990.0","B":"0.012","a":"50003.0","A":"0.022","T":1618677464051,"E":1618677464054}}
1618677464.251601: {"stream":"yfiusdt@bookTicker","data":{"e":"bookTicker","u":335341078938,"s":"YFIUSDT","b":"49990.0","B":"0.012","a":"50006.6","A":"0.003","T":1618677464055,"E":1618677464060}}
1618677464.251713: {"stream":"ksmusdt@bookTicker","data":{"e":"bookTicker","u":335341079046,"s":"KSMUSDT","b":"458.778","B":"2.4","a":"458.975","A":"0.1","T":1618677464057,"E":1618677464060}}
1618677464.2521322: {"stream":"ksmusdt@bookTicker","data":{"e":"bookTicker","u":335341079217,"s":"KSMUSDT","b":"458.779","B":"1.2","a":"458.975","A":"0.1","T":1618677464060,"E":1618677464064}}
1618677464.252685: {"stream":"yfiusdt@aggTrade","data":{"e":"aggTrade","E":1618677464065,"a":52599706,"s":"YFIUSDT","p":"50003.0","q":"0.072","f":64902186,"l":64902186,"T":1618677464051,"m":false}}
1618677464.252738: {"stream":"yfiusdt@bookTicker","data":{"e":"bookTicker","u":335341079285,"s":"YFIUSDT","b":"49990.0","B":"0.012","a":"50006.7","A":"0.001","T":1618677464063,"E":1618677464065}}
1618677464.252963: {"stream":"ksmusdt@bookTicker","data":{"e":"bookTicker","u":335341079394,"s":"KSMUSDT","b":"458.780","B":"2.2","a":"458.975","A":"0.1","T":1618677464064,"E":1618677464067}}
1618677464.260631: {"stream":"yfiusdt@bookTicker","data":{"e":"bookTicker","u":335341079562,"s":"YFIUSDT","b":"49990.0","B":"0.012","a":"50002.9","A":"0.005","T":1618677464068,"E":1618677464072}}
1618677464.260742: {"stream":"yfiusdt@bookTicker","data":{"e":"bookTicker","u":335341079790,"s":"YFIUSDT","b":"49990.0","B":"0.012","a":"50006.7","A":"0.001","T":1618677464072,"E":1618677464077}}
1618677464.261166: {"stream":"ksmusdt@bookTicker","data":{"e":"bookTicker","u":335341080013,"s":"KSMUSDT","b":"458.780","B":"2.6","a":"458.975","A":"0.1","T":1618677464076,"E":1618677464080}}
1618677464.263252: {"stream":"ksmusdt@bookTicker","data":{"e":"bookTicker","u":335341080185,"s":"KSMUSDT","b":"458.780","B":"2.2","a":"458.975","A":"0.1","T":1618677464079,"E":1618677464083}}
1618677464.263322: {"stream":"ksmusdt@bookTicker","data":{"e":"bookTicker","u":335341080186,"s":"KSMUSDT","b":"458.779","B":"1.2","a":"458.975","A":"0.1","T":1618677464079,"E":1618677464083}}
1618677464.26335: {"stream":"ksmusdt@bookTicker","data":{"e":"bookTicker","u":335341080196,"s":"KSMUSDT","b":"458.781","B":"2.1","a":"458.975","A":"0.1","T":1618677464079,"E":1618677464083}}
1618677464.263371: {"stream":"ksmusdt@bookTicker","data":{"e":"bookTicker","u":335341080253,"s":"KSMUSDT","b":"458.799","B":"6.4","a":"458.975","A":"0.1","T":1618677464081,"E":1618677464085}}
1618677464.265325: {"stream":"yfiusdt@bookTicker","data":{"e":"bookTicker","u":335341080359,"s":"YFIUSDT","b":"49990.0","B":"0.095","a":"50006.7","A":"0.001","T":1618677464084,"E":1618677464087}}
1618677464.2695: {"stream":"yfiusdt@bookTicker","data":{"e":"bookTicker","u":335341080605,"s":"YFIUSDT","b":"49990.0","B":"0.083","a":"50006.7","A":"0.001","T":1618677464091,"E":1618677464096}}
1618677464.272993: {"stream":"ksmusdt@depth@100ms","data":{"e":"depthUpdate","E":1618677464103,"T":1618677464089,"s":"KSMUSDT","U":335341076191,"u":335341080534,"pu":335341075208,"b":[["451.555","3.7"],["457.455","0.0"],["458.256","0.0"],["458.755","0.0"],["458.775","0.0"],["458.776","0.0"],["458.777","0.0"],["458.778","0.0"],["458.779","1.2"],["458.780","0.0"],["458.781","2.1"],["458.799","6.4"]],"a":[["459.241","2.0"],["459.242","0.0"],["459.342","0.1"],["459.399","0.0"],["459.426","0.1"],["459.440","0.0"],["459.499","0.1"],["459.577","9.1"],["459.578","17.9"],["459.580","2.3"],["459.881","0.0"],["460.639","0.0"]]}}
1618677464.273401: {"stream":"xmrusdt@depth@100ms","data":{"e":"depthUpdate","E":1618677464107,"T":1618677464079,"s":"XMRUSDT","U":335341076280,"u":335341080168,"pu":335341074519,"b":[["345.43","0.335"],["345.87","58.198"],["347.24","0.000"],["350.47","0.000"],["350.59","7.128"],["351.52","41.886"],["351.56","0.000"],["352.15","6.719"],["352.19","14.280"],["352.20","2.999"]],"a":[["352.56","0.648"],["352.77","0.000"],["352.83","0.000"],["352.93","2.500"],["353.01","7.457"]]}}
1618677464.273581: {"stream":"yfiusdt@depth@100ms","data":{"e":"depthUpdate","E":1618677464114,"T":1618677464091,"s":"YFIUSDT","U":335341076671,"u":335341080605,"pu":335341076519,"b":[["49556.0","0.000"],["49609.7","0.099"],["49675.6","0.008"],["49883.4","0.000"],["49893.3","0.000"],["49916.9","0.000"],["49935.2","0.060"],["49965.2","0.000"],["49969.2","0.000"],["49981.3","0.000"],["49985.1","0.014"],["49986.4","0.000"],["49990.0","0.083"]],"a":[["50002.9","0.000"],["50003.0","0.000"],["50006.6","0.000"],["50014.9","0.000"],["50023.6","0.013"],["50023.7","0.030"],["50078.7","0.000"],["50096.9","0.060"],["50121.6","0.000"],["50161.1","0.001"]]}}
1618677464.274011: {"stream":"yfiusdt@bookTicker","data":{"e":"bookTicker","u":335341080972,"s":"YFIUSDT","b":"49991.3","B":"0.012","a":"50006.7","A":"0.001","T":1618677464115,"E":1618677464120}}
1618677464.274053: {"stream":"ksmusdt@bookTicker","data":{"e":"bookTicker","u":335341081114,"s":"KSMUSDT","b":"458.800","B":"3.7","a":"458.975","A":"0.1","T":1618677464116,"E":1618677464122}}
1618677464.277964: {"stream":"dentusdt@depth@100ms","data":{"e":"depthUpdate","E":1618677464137,"T":1618677464053,"s":"DENTUSDT","U":335341077846,"u":335341078824,"pu":335341072636,"b":[["0.000011","19805663"]],"a":[["0.012358","0"],["0.012359","56792"]]}}
1618677464.285751: {"stream":"ksmusdt@bookTicker","data":{"e":"bookTicker","u":335341082077,"s":"KSMUSDT","b":"458.800","B":"4.0","a":"458.975","A":"0.1","T":1618677464161,"E":1618677464167}}
1618677464.286459: {"stream":"ksmusdt@bookTicker","data":{"e":"bookTicker","u":335341082372,"s":"KSMUSDT","b":"458.800","B":"3.7","a":"458.975","A":"0.1","T":1618677464164,"E":1618677464171}}
1618677464.2910862: {"stream":"ksmusdt@bookTicker","data":{"e":"bookTicker","u":335341083246,"s":"KSMUSDT","b":"458.799","B":"6.4","a":"458.975","A":"0.1","T":1618677464179,"E":1618677464182}}
1618677464.291187: {"stream":"ksmusdt@bookTicker","data":{"e":"bookTicker","u":335341083337,"s":"KSMUSDT","b":"458.801","B":"0.3","a":"458.975","A":"0.1","T":1618677464180,"E":1618677464184}}
1618677464.291231: {"stream":"ksmusdt@bookTicker","data":{"e":"bookTicker","u":335341083500,"s":"KSMUSDT","b":"458.801","B":"3.3","a":"458.975","A":"0.1","T":1618677464182,"E":1618677464185}}
1618677464.2951539: {"stream":"ksmusdt@bookTicker","data":{"e":"bookTicker","u":335341083950,"s":"KSMUSDT","b":"458.801","B":"0.3","a":"458.975","A":"0.1","T":1618677464191,"E":1618677464195}}
1618677464.2952561: {"stream":"ksmusdt@bookTicker","data":{"e":"bookTicker","u":335341083967,"s":"KSMUSDT","b":"458.802","B":"3.8","a":"458.975","A":"0.1","T":1618677464192,"E":1618677464195}}
1618677464.299679: {"stream":"ksmusdt@bookTicker","data":{"e":"bookTicker","u":335341084489,"s":"KSMUSDT","b":"458.803","B":"0.3","a":"458.975","A":"0.1","T":1618677464206,"E":1618677464210}}
1618677464.299777: {"stream":"yfiusdt@aggTrade","data":{"e":"aggTrade","E":1618677464216,"a":52599707,"s":"YFIUSDT","p":"50006.6","q":"0.003","f":64902187,"l":64902187,"T":1618677464063,"m":false}}
1618677464.302015: {"stream":"xmrusdt@depth@100ms","data":{"e":"depthUpdate","E":1618677464220,"T":1618677464197,"s":"XMRUSDT","U":335341081064,"u":335341084163,"pu":335341080168,"b":[["347.29","11.561"],["351.61","3.984"],["351.78","5.503"],["352.29","0.023"],["352.30","0.000"],["352.31","2.500"],["352.37","0.000"]],"a":[["352.83","2.500"],["352.93","0.000"]]}}
1618677464.3022668: {"stream":"yfiusdt@depth@100ms","data":{"e":"depthUpdate","E":1618677464220,"T":1618677464213,"s":"YFIUSDT","U":335341080934,"u":335341084772,"pu":335341080605,"b":[["49862.5","0.000"],["49903.2","0.141"],["49930.1","0.100"],["49936.5","0.000"],["49939.5","0.000"],["49942.7","0.000"],["49943.6","0.075"],["49944.6","0.021"],["49947.8","0.021"],["49948.7","0.021"],["49957.5","0.259"],["49957.6","0.058"],["49977.3","0.000"],["49985.1","0.000"],["49985.4","0.000"],["49988.7","0.055"],["49989.2","0.012"],["49991.3","0.012"]],"a":[["50070.0","0.000"],["50083.2","0.000"],["50085.5","0.007"],["50102.1","0.005"],["50102.3","0.000"],["50113.2","0.094"],["50116.2","0.000"],["50122.1","0.094"],["50122.2","0.009"],["50122.4","0.008"],["50125.0","0.017"],["50128.3","0.141"],["50133.0","0.100"],["50170.9","0.007"],["50175.2","0.000"],["50230.7","0.000"],["50352.3","0.000"]]}}
1618677464.302669: {"stream":"ksmusdt@depth@100ms","data":{"e":"depthUpdate","E":1618677464220,"T":1618677464213,"s":"KSMUSDT","U":335341081073,"u":335341084747,"pu":335341080534,"b":[["427.856","0.0"],["455.631","0.0"],["456.517","0.0"],["456.699","0.0"],["457.092","0.0"],["458.160","1.1"],["458.256","0.0"],["458.715","0.0"],["458.781","0.0"],["458.783","0.0"],["458.800","0.0"],["458.801","0.0"],["458.802","3.8"],["458.803","0.3"]],"a":[["459.021","0.0"],["459.078","0.3"],["459.161","0.0"],["459.576","1.0"],["459.806","2.2"],["460.194","3.2"],["460.529","0.2"],["461.334","0.0"],["461.927","5.4"]]}}
1618677464.314535: {"stream":"yfiusdt@bookTicker","data":{"e":"bookTicker","u":335341086488,"s":"YFIUSDT","b":"49991.4","B":"0.003","a":"50006.7","A":"0.001","T":1618677464250,"E":1618677464254}}
1618677464.326248: {"stream":"yfiusdt@bookTicker","data":{"e":"bookTicker","u":335341087110,"s":"YFIUSDT","b":"49991.3","B":"0.012","a":"50006.7","A":"0.001","T":1618677464264,"E":1618677464268}}
1618677464.334922: {"stream":"yfiusdt@bookTicker","data":{"e":"bookTicker","u":335341087598,"s":"YFIUSDT","b":"49991.4","B":"0.005","a":"50006.7","A":"0.001","T":1618677464275,"E":1618677464277}}
1618677464.341254: {"stream":"yfiusdt@bookTicker","data":{"e":"bookTicker","u":335341087765,"s":"YFIUSDT","b":"49992.4","B":"0.055","a":"50006.7","A":"0.001","T":1618677464278,"E":1618677464282}}
1618677464.341354: {"stream":"ksmusdt@bookTicker","data":{"e":"bookTicker","u":335341087781,"s":"KSMUSDT","b":"458.822","B":"6.4","a":"458.975","A":"0.1","T":1618677464278,"E":1618677464282}}
1618677464.3486662: {"stream":"yfiusdt@bookTicker","data":{"e":"bookTicker","u":335341088266,"s":"YFIUSDT","b":"49993.7","B":"0.012","a":"50006.7","A":"0.001","T":1618677464288,"E":1618677464291}}
1618677464.37743: {"stream":"ksmusdt@bookTicker","data":{"e":"bookTicker","u":335341089580,"s":"KSMUSDT","b":"458.823","B":"0.3","a":"458.975","A":"0.1","T":1618677464315,"E":1618677464319}}
1618677464.3774989: {"stream":"ksmusdt@depth@100ms","data":{"e":"depthUpdate","E":1618677464320,"T":1618677464316,"s":"KSMUSDT","U":335341084918,"u":335341089590,"pu":335341084747,"b":[["431.524","0.9"],["455.023","0.0"],["456.107","0.0"],["456.235","1.8"],["457.181","0.2"],["458.160","0.0"],["458.241","1.9"],["458.256","1.1"],["458.502","0.0"],["458.774","0.0"],["458.779","0.0"],["458.780","0.0"],["458.787","0.0"],["458.800","0.0"],["458.802","0.0"],["458.803","0.0"],["458.822","6.4"],["458.823","0.3"]],"a":[["459.078","0.0"],["459.079","0.0"],["459.159","0.3"],["459.160","0.0"],["459.161","0.0"],["459.162","0.0"],["459.239","1.0"],["459.240","1.6"],["459.245","0.0"],["459.512","0.8"],["459.532","0.0"],["459.576","0.0"],["459.578","0.0"],["460.700","0.0"],["461.366","0.0"],["462.866","0.0"]]}}
1618677464.394808: {"stream":"yfiusdt@bookTicker","data":{"e":"bookTicker","u":335341090083,"s":"YFIUSDT","b":"49993.7","B":"0.012","a":"50011.2","A":"0.009","T":1618677464328,"E":1618677464332}}
1618677464.394857: {"stream":"yfiusdt@depth@100ms","data":{"e":"depthUpdate","E":1618677464333,"T":1618677464328,"s":"YFIUSDT","U":335341085547,"u":335341090083,"pu":335341084772,"b":[["49779.1","0.000"],["49796.7","0.017"],["49981.2","0.000"],["49984.9","0.000"],["49985.0","0.000"],["49989.2","0.000"],["49990.1","0.000"],["49991.3","0.000"],["49991.4","0.000"],["49992.4","0.055"],["49993.7","0.012"]],"a":[["50006.7","0.000"],["50100.5","0.057"],["50114.9","0.050"],["50118.9","0.000"],["50136.6","0.017"],["50210.4","0.020"],["50378.0","0.009"]]}}
1618677464.3950489: {"stream":"yfiusdt@kline_1m","data":{"e":"kline","E":1618677464333,"s":"YFIUSDT","k":{"t":1618677420000,"T":1618677479999,"s":"YFIUSDT","i":"1m","f":64902095,"L":64902188,"o":"50010.8","c":"50006.7","h":"50044.2","l":"49950.6","v":"1.090","n":94,"x":false,"q":"54498.6061","V":"0.781","Q":"39049.2591","B":"0"}}}
1618677464.4033349: {"stream":"dentusdt@depth@100ms","data":{"e":"depthUpdate","E":1618677464344,"T":1618677464240,"s":"DENTUSDT","U":335341085925,"u":335341085960,"pu":335341078824,"b":[["0.012218","103253"]],"a":[["0.012378","12548"]]}}
1618677464.46098: {"stream":"xmrusdt@depth@100ms","data":{"e":"depthUpdate","E":1618677464349,"T":1618677464304,"s":"XMRUSDT","U":335341086179,"u":335341089102,"pu":335341084163,"b":[["348.57","200.034"],["349.20","208.598"],["349.69","7.088"],["350.32","48.784"],["352.03","0.000"],["352.11","7.917"],["352.31","0.000"],["352.41","5.100"],["352.43","2.500"]],"a":[["353.72","1.900"],["353.87","0.619"],["355.19","8.222"]]}}
1618677464.489425: {"stream":"ksmusdt@depth@100ms","data":{"e":"depthUpdate","E":1618677464431,"T":1618677464426,"s":"KSMUSDT","U":335341090033,"u":335341093654,"pu":335341089590,"b":[["455.785","1.4"],["457.643","0.0"],["457.828","0.2"],["458.256","0.0"],["458.814","1.2"]],"a":[["459.159","0.0"],["459.206","1.2"],["459.237","0.0"],["459.238","1.6"],["459.239","0.0"],["459.240","0.0"],["459.246","1.6"],["462.917","0.2"]]}}
1618677464.497628: {"stream":"yfiusdt@depth@100ms","data":{"e":"depthUpdate","E":1618677464439,"T":1618677464431,"s":"YFIUSDT","U":335341090343,"u":335341093833,"pu":335341090083,"b":[["49844.1","0.000"],["49881.2","0.021"],["49902.7","0.000"],["49923.3","0.021"],["49933.9","0.010"],["49949.2","0.000"],["49951.4","0.000"],["49954.5","0.015"],["49990.1","0.001"]],"a":[["50035.0","0.000"],["50082.7","0.073"],["50092.9","0.009"],["50108.5","0.009"],["50143.7","0.000"],["50162.5","0.021"],["50237.3","0.042"]]}}
1618677464.506204: {"stream":"dentusdt@depth@100ms","data":{"e":"depthUpdate","E":1618677464449,"T":1618677464420,"s":"DENTUSDT","U":335341090702,"u":335341093488,"pu":335341085960,"b":[["0.012278","104887"],["0.012280","41896"],["0.012327","385644"],["0.012331","11502"]],"a":[["0.012700","438457"]]}}
1618677464.523255: {"stream":"xmrusdt@depth@100ms","data":{"e":"depthUpdate","E":1618677464467,"T":1618677464422,"s":"XMRUSDT","U":335341091283,"u":335341093553,"pu":335341089102,"b":[["348.57","0.034"],["349.20","8.598"],["349.60","177.447"],["349.73","200.724"],["350.36","207.696"],["350.65","0.957"],["352.10","19.244"],["352.26","12.221"],["352.28","0.000"],["352.41","7.600"],["352.43","0.000"]],"a":[["354.82","12.152"]]}}
1618677464.5392718: {"stream":"yfiusdt@aggTrade","data":{"e":"aggTrade","E":1618677464483,"a":52599708,"s":"YFIUSDT","p":"50006.7","q":"0.001","f":64902188,"l":64902188,"T":1618677464328,"m":false}}
1618677464.5490701: {"stream":"dentusdt@bookTicker","data":{"e":"bookTicker","u":335341095425,"s":"DENTUSDT","b":"0.012348","B":"8826","a":"0.012353","A":"1768","T":1618677464486,"E":1618677464490}}
1618677464.58522: {"stream":"yfiusdt@bookTicker","data":{"e":"bookTicker","u":335341096737,"s":"YFIUSDT","b":"49993.7","B":"0.004","a":"50011.2","A":"0.009","T":1618677464522,"E":1618677464526}}
1618677464.5885599: {"stream":"ksmusdt@depth@100ms","data":{"e":"depthUpdate","E":1618677464531,"T":1618677464512,"s":"KSMUSDT","U":335341093671,"u":335341096360,"pu":335341093654,"b":[["454.907","0.0"],["458.256","1.1"]],"a":[["459.190","0.3"],["459.191","1.2"],["459.204","0.0"],["459.205","1.6"],["459.206","0.0"],["459.236","0.0"],["459.238","0.0"],["463.428","3.4"]]}}
1618677464.600152: {"stream":"dentusdt@bookTicker","data":{"e":"bookTicker","u":335341097221,"s":"DENTUSDT","b":"0.012348","B":"8826","a":"0.012351","A":"13992","T":1618677464536,"E":1618677464541}}
1618677464.610982: {"stream":"dentusdt@depth@100ms","data":{"e":"depthUpdate","E":1618677464555,"T":1618677464541,"s":"DENTUSDT","U":335341094439,"u":335341097437,"pu":335341093488,"b":[["0.012301","152685"],["0.012306","33087"],["0.012312","257770"],["0.012341","58453"]],"a":[["0.012351","13992"],["0.012353","1768"],["0.012359","136707"],["0.012363","225531"],["0.012366","0"]]}}
1618677464.624862: {"stream":"xmrusdt@depth@100ms","data":{"e":"depthUpdate","E":1618677464567,"T":1618677464464,"s":"XMRUSDT","U":335341094735,"u":335341094790,"pu":335341093553,"b":[["352.30","2.500"],["352.41","5.100"]],"a":[]}}
1618677464.625023: {"stream":"yfiusdt@depth@100ms","data":{"e":"depthUpdate","E":1618677464569,"T":1618677464522,"s":"YFIUSDT","U":335341094799,"u":335341096737,"pu":335341093833,"b":[["49985.7","0.016"],["49993.7","0.004"]],"a":[["50082.7","0.000"],["50339.3","0.000"]]}}
1618677464.699326: {"stream":"ksmusdt@depth@100ms","data":{"e":"depthUpdate","E":1618677464641,"T":1618677464630,"s":"KSMUSDT","U":335341097235,"u":335341100443,"pu":335341096360,"b":[["455.773","1.0"],["456.739","0.6"],["457.179","0.1"]],"a":[["459.187","0.3"],["459.188","0.0"],["459.189","1.6"],["459.190","0.0"],["459.191","0.0"],["459.205","0.0"],["460.152","1.0"],["466.163","0.0"]]}}
1618677464.720635: {"stream":"dentusdt@depth@100ms","data":{"e":"depthUpdate","E":1618677464660,"T":1618677464632,"s":"DENTUSDT","U":335341097958,"u":335341100509,"pu":335341097437,"b":[["0.012196","214154"],["0.012292","30269"],["0.012319","552993"],["0.012325","669743"],["0.012327","389840"],["0.012343","22757"],["0.012345","0"]],"a":[["0.012352","2062"],["0.012355","17730"],["0.012356","53983"],["0.012357","8967"],["0.012358","26048"],["0.012360","57880"],["0.012361","57938"],["0.012362","195500"],["0.012365","0"],["0.012378","417423"],["0.012380","429053"],["0.012385","64260"]]}}
1618677464.738744: {"stream":"yfiusdt@aggTrade","data":{"e":"aggTrade","E":1618677464677,"a":52599709,"s":"YFIUSDT","p":"49993.7","q":"0.008","f":64902189,"l":64902189,"T":1618677464522,"m":true}}
1618677464.7388532: {"stream":"yfiusdt@depth@100ms","data":{"e":"depthUpdate","E":1618677464677,"T":1618677464672,"s":"YFIUSDT","U":335341098481,"u":335341101662,"pu":335341096737,"b":[["49641.7","0.007"],["49661.2","0.000"],["49942.3","0.000"],["49990.1","0.000"]],"a":[["50015.0","0.000"],["50018.4","0.040"],["50018.5","0.012"],["50072.0","0.000"],["50092.7","0.026"],["50093.0","0.000"],["50110.0","0.069"],["50122.1","0.000"],["50131.3","0.123"],["50236.4","0.031"]]}}
1618677464.762645: {"stream":"xmrusdt@depth@100ms","data":{"e":"depthUpdate","E":1618677464705,"T":1618677464690,"s":"XMRUSDT","U":335341099511,"u":335341102163,"pu":335341094790,"b":[["352.26","10.433"],["352.30","0.000"],["352.37","2.500"],["352.39","1.787"]],"a":[["354.78","1.006"],["357.21","0.000"]]}}
1618677464.773234: {"stream":"xmrusdt@bookTicker","data":{"e":"bookTicker","u":335341102743,"s":"XMRUSDT","b":"352.52","B":"3.743","a":"352.53","A":"0.116","T":1618677464711,"E":1618677464715}}
1618677464.804675: {"stream":"ksmusdt@depth@100ms","data":{"e":"depthUpdate","E":1618677464748,"T":1618677464704,"s":"KSMUSDT","U":335341100878,"u":335341102548,"pu":335341100443,"b":[["456.807","0.5"],["458.586","0.0"]],"a":[["459.189","0.0"],["459.393","0.0"],["459.405","1.6"],["459.576","1.0"],["460.152","0.0"],["463.912","0.0"]]}}
1618677464.835674: {"stream":"yfiusdt@bookTicker","data":{"e":"bookTicker","u":335341104710,"s":"YFIUSDT","b":"49993.8","B":"0.001","a":"50011.2","A":"0.009","T":1618677464769,"E":1618677464775}}
1618677464.8408818: {"stream":"dentusdt@depth@100ms","data":{"e":"depthUpdate","E":1618677464783,"T":1618677464778,"s":"DENTUSDT","U":335341101872,"u":335341104957,"pu":335341100509,"b":[["0.012269","67341"],["0.012273","1022585"],["0.012343","22757"]],"a":[["0.012355","33758"],["0.012356","64003"],["0.012357","142848"],["0.012358","0"],["0.012359","60764"],["0.012361","0"]]}}
1618677464.84516: {"stream":"yfiusdt@depth@100ms","data":{"e":"depthUpdate","E":1618677464787,"T":1618677464769,"s":"YFIUSDT","U":335341101939,"u":335341104710,"pu":335341101662,"b":[["49689.0","0.015"],["49912.6","0.006"],["49916.0","0.007"],["49922.6","0.002"],["49957.5","0.000"],["49963.6","0.026"],["49968.4","0.427"],["49993.8","0.001"]],"a":[["50018.4","0.000"],["50094.2","0.073"],["50104.6","0.002"],["50110.3","0.003"],["50129.4","0.400"],["50131.3","0.029"]]}}
1618677464.866484: {"stream":"xmrusdt@depth@100ms","data":{"e":"depthUpdate","E":1618677464808,"T":1618677464800,"s":"XMRUSDT","U":335341102511,"u":335341105769,"pu":335341102163,"b":[["350.40","4.930"],["352.28","3.909"],["352.30","2.500"],["352.37","0.000"],["352.52","3.743"]],"a":[["357.34","1.819"]]}}
1618677464.907712: {"stream":"dentusdt@bookTicker","data":{"e":"bookTicker","u":335341107401,"s":"DENTUSDT","b":"0.012348","B":"10425","a":"0.012351","A":"13992","T":1618677464845,"E":1618677464848}}
1618677464.912321: {"stream":"ksmusdt@depth@100ms","data":{"e":"depthUpdate","E":1618677464856,"T":1618677464841,"s":"KSMUSDT","U":335341103831,"u":335341107292,"pu":335341102548,"b":[["454.654","0.0"],["454.849","3.9"],["456.719","0.0"],["456.914","3.9"]],"a":[["459.247","1.3"],["459.576","1.0"],["460.012","31.3"],["460.847","0.0"],["461.044","3.9"],["462.912","0.0"],["462.917","0.0"],["463.110","3.9"]]}}
1618677464.942264: {"stream":"xmrusdt@bookTicker","data":{"e":"bookTicker","u":335341108606,"s":"XMRUSDT","b":"352.52","B":"3.743","a":"352.53","A":"0.189","T":1618677464880,"E":1618677464883}}
1618677464.944669: {"stream":"ksmusdt@bookTicker","data":{"e":"bookTicker","u":335341108678,"s":"KSMUSDT","b":"458.853","B":"3.7","a":"458.975","A":"0.1","T":1618677464881,"E":1618677464886}}
1618677464.947016: {"stream":"ksmusdt@bookTicker","data":{"e":"bookTicker","u":335341108776,"s":"KSMUSDT","b":"458.823","B":"0.3","a":"458.975","A":"0.1","T":1618677464885,"E":1618677464889}}
1618677464.95995: {"stream":"ksmusdt@bookTicker","data":{"e":"bookTicker","u":335341109122,"s":"KSMUSDT","b":"458.830","B":"1.2","a":"458.975","A":"0.1","T":1618677464896,"E":1618677464900}}
1618677464.960049: {"stream":"yfiusdt@depth@100ms","data":{"e":"depthUpdate","E":1618677464902,"T":1618677464897,"s":"YFIUSDT","U":335341105752,"u":335341109152,"pu":335341104710,"b":[["49731.9","0.000"],["49736.2","0.001"],["49957.6","0.000"],["49968.4","0.168"]],"a":[["50068.4","0.000"],["50078.8","0.011"],["50175.0","0.023"],["50237.0","0.000"],["50241.3","0.001"]]}}
1618677464.968462: {"stream":"ksmusdt@bookTicker","data":{"e":"bookTicker","u":335341109352,"s":"KSMUSDT","b":"458.823","B":"0.3","a":"458.975","A":"0.1","T":1618677464903,"E":1618677464909}}
1618677464.971443: {"stream":"ksmusdt@bookTicker","data":{"e":"bookTicker","u":335341109556,"s":"KSMUSDT","b":"458.822","B":"6.4","a":"458.975","A":"0.1","T":1618677464909,"E":1618677464913}}
1618677464.971515: {"stream":"ksmusdt@bookTicker","data":{"e":"bookTicker","u":335341109569,"s":"KSMUSDT","b":"458.831","B":"0.3","a":"458.975","A":"0.1","T":1618677464909,"E":1618677464913}}
1618677464.980911: {"stream":"xmrusdt@depth@100ms","data":{"e":"depthUpdate","E":1618677464923,"T":1618677464911,"s":"XMRUSDT","U":335341106511,"u":335341109609,"pu":335341105769,"b":[],"a":[["352.53","0.189"],["352.61","0.224"],["353.25","6.400"],["353.29","0.400"],["353.36","14.796"],["353.60","14.778"],["353.70","0.361"],["354.02","37.607"],["355.12","2.260"]]}}
1618677465.0066402: {"stream":"dentusdt@depth@100ms","data":{"e":"depthUpdate","E":1618677464948,"T":1618677464940,"s":"DENTUSDT","U":335341107401,"u":335341110551,"pu":335341104957,"b":[["0.010302","518076"],["0.010572","178899"],["0.010800","11138948"],["0.010848","178215"],["0.010994","95940"],["0.011122","106551"],["0.011223","55430"],["0.011291","34712"],["0.011348","31130"],["0.011393","1108095"],["0.011656","9594"],["0.011836","9594"],["0.011981","3198"],["0.012103","309102"],["0.012200","166254"],["0.012262","361036"],["0.012285","78184"],["0.012304","95142"],["0.012311","3033"],["0.012325","624643"],["0.012328","201334"],["0.012348","10425"]],"a":[["0.012359","57938"]]}}
1618677465.025225: {"stream":"ksmusdt@depth@100ms","data":{"e":"depthUpdate","E":1618677464967,"T":1618677464948,"s":"KSMUSDT","U":335341108091,"u":335341110741,"pu":335341107292,"b":[["456.136","1.6"],["458.094","0.0"],["458.233","0.3"],["458.256","1.1"],["458.713","1.5"],["458.799","0.0"],["458.813","1.2"],["458.814","0.0"],["458.823","0.0"],["458.830","0.0"],["458.831","0.3"],["458.853","0.0"]],"a":[["459.185","0.3"],["459.186","1.6"],["459.187","0.0"],["459.240","1.0"],["459.405","0.0"],["459.576","0.0"],["460.174","5.9"],["461.800","0.3"]]}}
1618677465.0613492: {"stream":"dentusdt@bookTicker","data":{"e":"bookTicker","u":335341112263,"s":"DENTUSDT","b":"0.012348","B":"10425","a":"0.012350","A":"1768","T":1618677464998,"E":1618677465002}}
1618677465.064358: {"stream":"yfiusdt@depth@100ms","data":{"e":"depthUpdate","E":1618677465005,"T":1618677464991,"s":"YFIUSDT","U":335341109292,"u":335341111981,"pu":335341109152,"b":[["49634.9","0.000"],["49692.9","0.008"],["49919.3","0.021"]],"a":[]}}
1618677465.111527: {"stream":"xmrusdt@depth@100ms","data":{"e":"depthUpdate","E":1618677465054,"T":1618677465005,"s":"XMRUSDT","U":335341110744,"u":335341112559,"pu":335341109609,"b":[["350.12","2.003"]],"a":[["353.16","0.000"],["353.34","13.340"],["353.57","0.000"]]}}
1618677465.2364101: {"stream":"dentusdt@depth@100ms","data":{"e":"depthUpdate","E":1618677465061,"T":1618677465039,"s":"DENTUSDT","U":335341110938,"u":335341114098,"pu":335341110551,"b":[["0.012304","123026"],["0.012317","102569"],["0.012321","52218"],["0.012331","36581"],["0.012340","304434"]],"a":[["0.012350","1768"],["0.012353","0"],["0.012356","10020"],["0.012362","145713"],["0.012376","33231"],["0.012377","36490"],["0.012378","404875"],["0.012379","50901"],["0.012382","462475"]]}}
1618677465.239403: {"stream":"ksmusdt@depth@100ms","data":{"e":"depthUpdate","E":1618677465072,"T":1618677465067,"s":"KSMUSDT","U":335341111294,"u":335341115121,"pu":335341110741,"b":[["449.709","0.0"],["453.730","0.0"],["456.544","15.0"],["458.255","0.0"],["458.777","1.2"],["458.813","0.0"]],"a":[["459.161","0.3"],["459.162","1.6"],["459.185","0.0"],["459.186","0.0"],["459.426","0.0"],["459.440","0.1"],["459.499","0.0"],["459.529","0.1"],["459.881","2.8"],["461.041","15.0"],["463.290","0.0"]]}}
1618677465.2487192: {"stream":"yfiusdt@depth@100ms","data":{"e":"depthUpdate","E":1618677465111,"T":1618677465034,"s":"YFIUSDT","U":335341112710,"u":335341113877,"pu":335341111981,"b":[["49754.3","0.008"],["49968.5","0.049"],["49990.0","0.083"]],"a":[["50079.9","0.000"],["50108.9","0.020"]]}}
1618677465.278416: {"stream":"xmrusdt@depth@100ms","data":{"e":"depthUpdate","E":1618677465160,"T":1618677465086,"s":"XMRUSDT","U":335341114787,"u":335341115697,"pu":335341112559,"b":[],"a":[["353.25","9.364"],["353.29","10.774"]]}}
1618677465.279019: {"stream":"dentusdt@depth@100ms","data":{"e":"depthUpdate","E":1618677465173,"T":1618677465161,"s":"DENTUSDT","U":335341115167,"u":335341117210,"pu":335341114098,"b":[["0.012287","182416"],["0.012343","22759"]],"a":[["0.012351","0"],["0.012354","53985"],["0.012355","16028"],["0.012357","8967"],["0.012358","57938"],["0.012359","0"],["0.012360","17393"],["0.012361","58219"],["0.012362","195500"]]}}
1618677465.282998: {"stream":"ksmusdt@depth@100ms","data":{"e":"depthUpdate","E":1618677465179,"T":1618677465170,"s":"KSMUSDT","U":335341115389,"u":335341117439,"pu":335341115121,"b":[["454.295","0.0"],["454.405","15.0"],["456.544","0.0"]],"a":[["459.342","0.0"],["459.372","0.1"],["461.041","0.0"],["461.152","15.0"],["461.773","0.0"],["463.401","15.0"]]}}
1618677465.28949: {"stream":"yfiusdt@depth@100ms","data":{"e":"depthUpdate","E":1618677465219,"T":1618677465209,"s":"YFIUSDT","U":335341116281,"u":335341118836,"pu":335341113877,"b":[["49656.3","0.007"],["49729.2","0.010"],["49750.7","0.007"],["49955.8","0.000"],["49968.4","0.000"],["49968.5","0.000"],["49968.6","0.168"],["49968.7","0.050"],["49969.8","0.009"],["49985.7","0.000"]],"a":[["50066.0","0.009"],["50069.8","0.021"],["50116.1","0.094"],["50205.8","0.000"],["50236.4","0.000"]]}}
1618677465.308865: {"stream":"dentusdt@bookTicker","data":{"e":"bookTicker","u":335341119877,"s":"DENTUSDT","b":"0.012348","B":"10425","a":"0.012349","A":"13992","T":1618677465247,"E":1618677465250}}
1618677465.331142: {"stream":"dentusdt@depth@100ms","data":{"e":"depthUpdate","E":1618677465273,"T":1618677465267,"s":"DENTUSDT","U":335341117332,"u":335341120529,"pu":335341117210,"b":[["0.012170","34413"],["0.012323","1556"]],"a":[["0.012349","13992"],["0.012354","63121"],["0.012356","143901"],["0.012357","0"],["0.012361","0"],["0.012374","0"],["0.013778","4418"]]}}
1618677465.337449: {"stream":"ksmusdt@depth@100ms","data":{"e":"depthUpdate","E":1618677465280,"T":1618677465272,"s":"KSMUSDT","U":335341117654,"u":335341120741,"pu":335341117439,"b":[["449.706","19.8"],["453.727","20.0"],["456.654","15.0"]],"a":[["459.160","1.6"],["459.162","0.0"],["461.152","30.0"],["461.770","19.6"],["463.401","30.0"]]}}
1618677465.3794298: {"stream":"yfiusdt@depth@100ms","data":{"e":"depthUpdate","E":1618677465321,"T":1618677465281,"s":"YFIUSDT","U":335341119087,"u":335341121073,"pu":335341118836,"b":[["49662.4","0.002"],["49957.2","0.026"],["49963.6","0.000"],["49968.6","0.000"],["49968.7","0.000"],["49968.8","0.168"],["49968.9","0.051"]],"a":[["50081.1","0.026"],["50092.7","0.000"],["50116.1","0.000"]]}}
1618677465.405061: {"stream":"xmrusdt@depth@100ms","data":{"e":"depthUpdate","E":1618677465348,"T":1618677465301,"s":"XMRUSDT","U":335341119828,"u":335341121719,"pu":335341115697,"b":[["351.73","1.200"],["351.91","1.730"],["351.93","13.580"],["352.17","1.598"]],"a":[["353.00","6.686"],["353.01","39.292"],["353.02","4.064"],["364.61","0.000"]]}}
1618677465.4335601: {"stream":"dentusdt@depth@100ms","data":{"e":"depthUpdate","E":1618677465373,"T":1618677465353,"s":"DENTUSDT","U":335341120626,"u":335341123325,"pu":335341120529,"b":[["0.012285","146012"],["0.012299","139369"],["0.012312","254844"],["0.012316","69037"],["0.012343","0"]],"a":[["0.012353","33758"],["0.012354","73141"],["0.012355","133881"],["0.012356","0"],["0.012361","291534"],["0.012362","49787"],["0.012376","29992"],["0.012377","0"],["0.012379","69709"]]}}
1618677465.442859: {"stream":"ksmusdt@depth@100ms","data":{"e":"depthUpdate","E":1618677465384,"T":1618677465326,"s":"KSMUSDT","U":335341120969,"u":335341122432,"pu":335341120741,"b":[["454.405","30.0"],["456.654","30.0"]],"a":[["459.159","0.3"],["459.161","0.0"]]}}
1618677465.479629: {"stream":"yfiusdt@depth@100ms","data":{"e":"depthUpdate","E":1618677465422,"T":1618677465412,"s":"YFIUSDT","U":335341122209,"u":335341125198,"pu":335341121073,"b":[["49648.1","0.000"],["49749.0","0.000"],["49968.8","0.000"],["49968.9","0.000"],["49969.0","0.168"],["49973.2","0.266"]],"a":[["50122.0","0.000"],["50233.2","0.010"]]}}
1618677465.5030038: {"stream":"dentusdt@bookTicker","data":{"e":"bookTicker","u":335341126012,"s":"DENTUSDT","b":"0.012348","B":"6600","a":"0.012349","A":"13992","T":1618677465439,"E":1618677465444}}
1618677465.5470479: {"stream":"dentusdt@depth@100ms","data":{"e":"depthUpdate","E":1618677465489,"T":1618677465470,"s":"DENTUSDT","U":335341124355,"u":335341126888,"pu":335341123325,"b":[["0.012317","90299"],["0.012342","71336"],["0.012348","6600"]],"a":[["0.012352","19792"],["0.012353","16028"],["0.012357","57938"],["0.012358","0"],["0.012359","40491"],["0.012360","234421"],["0.012361","251043"],["0.012367","0"],["0.012375","0"],["0.012376","17444"],["0.012379","75228"],["0.012400","739326"],["0.012401","121069"],["0.012406","58009"]]}}
1618677465.5554938: {"stream":"ksmusdt@depth@100ms","data":{"e":"depthUpdate","E":1618677465498,"T":1618677465489,"s":"KSMUSDT","U":335341124627,"u":335341127367,"pu":335341122432,"b":[["456.982","0.0"],["457.488","0.7"],["457.678","0.8"]],"a":[["459.157","0.3"],["459.158","1.6"],["459.159","0.0"],["459.160","0.0"]]}}
1618677465.565421: {"stream":"xmrusdt@depth@100ms","data":{"e":"depthUpdate","E":1618677465506,"T":1618677465402,"s":"XMRUSDT","U":335341124845,"u":335341124845,"pu":335341121719,"b":[["340.69","70.376"]],"a":[]}}
1618677465.572751: {"stream":"dentusdt@bookTicker","data":{"e":"bookTicker","u":335341127977,"s":"DENTUSDT","b":"0.012348","B":"6600","a":"0.012349","A":"15760","T":1618677465510,"E":1618677465515}}
1618677465.582465: {"stream":"yfiusdt@depth@100ms","data":{"e":"depthUpdate","E":1618677465525,"T":1618677465504,"s":"YFIUSDT","U":335341125394,"u":335341127804,"pu":335341125198,"b":[["49526.9","0.000"],["49650.8","0.007"],["49684.0","0.073"],["49703.6","0.008"],["49751.8","0.000"],["49772.6","0.011"]],"a":[["50052.2","0.000"],["50084.9","0.000"],["50085.5","0.000"],["50105.6","0.008"],["50110.3","0.000"],["50201.5","0.000"],["50426.4","0.000"]]}}
1618677465.659489: {"stream":"dentusdt@depth@100ms","data":{"e":"depthUpdate","E":1618677465601,"T":1618677465590,"s":"DENTUSDT","U":335341127614,"u":335341130215,"pu":335341126888,"b":[["0.011845","168611"],["0.012220","171626"],["0.012294","28185"],["0.012318","76562"],["0.012322","67557"]],"a":[["0.012349","15760"],["0.012350","0"],["0.012352","19792"],["0.012359","40491"],["0.012379","87776"],["0.012395","100050"],["0.012400","776109"],["0.012401","151728"],["0.012415","7793"],["0.012421","246458"]]}}
1618677465.66944: {"stream":"ksmusdt@depth@100ms","data":{"e":"depthUpdate","E":1618677465611,"T":1618677465580,"s":"KSMUSDT","U":335341127908,"u":335341129931,"pu":335341127367,"b":[["456.949","0.0"],["457.014","2.7"],["457.127","1.0"],["457.386","0.0"]],"a":[["459.155","0.3"],["459.156","1.6"],["459.157","0.0"],["459.158","0.0"],["459.864","0.0"]]}}
1618677465.6878111: {"stream":"xmrusdt@depth@100ms","data":{"e":"depthUpdate","E":1618677465631,"T":1618677465570,"s":"XMRUSDT","U":335341128484,"u":335341129720,"pu":335341124845,"b":[["352.12","0.000"],["352.18","2.500"],["352.30","0.000"]],"a":[]}}
1618677465.6906261: {"stream":"yfiusdt@depth@100ms","data":{"e":"depthUpdate","E":1618677465631,"T":1618677465577,"s":"YFIUSDT","U":335341128496,"u":335341129872,"pu":335341127804,"b":[["49553.8","0.083"],["49778.8","0.083"],["49988.7","0.000"],["49990.0","0.000"]],"a":[["50071.1","0.000"],["50102.8","0.000"],["50109.0","0.000"],["50228.8","0.083"],["50236.4","0.031"],["50453.8","0.083"],["50789.6","0.274"]]}}
1618677465.702615: {"stream":"dentusdt@bookTicker","data":{"e":"bookTicker","u":335341131589,"s":"DENTUSDT","b":"0.012348","B":"10425","a":"0.012349","A":"15760","T":1618677465641,"E":1618677465645}}
1618677465.744956: {"stream":"dentusdt@kline_1m","data":{"e":"kline","E":1618677465686,"s":"DENTUSDT","k":{"t":1618677420000,"T":1618677479999,"s":"DENTUSDT","i":"1m","f":15787262,"L":15787419,"o":"0.012366","c":"0.012348","h":"0.012366","l":"0.012339","v":"2616307","n":158,"x":false,"q":"32317.015388","V":"1197355","Q":"14793.770120","B":"0"}}}
1618677465.745076: {"stream":"dentusdt@bookTicker","data":{"e":"bookTicker","u":335341132508,"s":"DENTUSDT","b":"0.012348","B":"4861","a":"0.012349","A":"15760","T":1618677465681,"E":1618677465686}}
1618677465.757043: {"stream":"yfiusdt@kline_1m","data":{"e":"kline","E":1618677465699,"s":"YFIUSDT","k":{"t":1618677420000,"T":1618677479999,"s":"YFIUSDT","i":"1m","f":64902095,"L":64902190,"o":"50010.8","c":"50011.2","h":"50044.2","l":"49950.6","v":"1.101","n":96,"x":false,"q":"55048.5893","V":"0.784","Q":"39199.2927","B":"0"}}}
1618677465.759192: {"stream":"yfiusdt@bookTicker","data":{"e":"bookTicker","u":335341133099,"s":"YFIUSDT","b":"49993.8","B":"0.001","a":"50011.2","A":"0.006","T":1618677465695,"E":1618677465699}}
1618677465.780033: {"stream":"ksmusdt@depth@100ms","data":{"e":"depthUpdate","E":1618677465723,"T":1618677465703,"s":"KSMUSDT","U":335341131031,"u":335341133334,"pu":335341129931,"b":[["457.569","0.8"],["457.711","0.0"],["457.767","2.0"],["457.946","1.1"],["458.127","0.0"],["458.137","2.1"],["458.145","0.0"],["458.146","0.0"],["458.256","0.0"],["458.386","0.0"],["458.387","16.7"]],"a":[["459.156","0.0"],["459.162","1.6"],["459.864","0.4"]]}}
1618677465.7851222: {"stream":"dentusdt@depth@100ms","data":{"e":"depthUpdate","E":1618677465725,"T":1618677465719,"s":"DENTUSDT","U":335341131052,"u":335341133790,"pu":335341130215,"b":[["0.011882","13957"],["0.012299","171197"],["0.012348","4861"]],"a":[["0.012352","2062"],["0.012359","0"],["0.012391","154834"],["0.012496","100956"],["0.012617","8499"]]}}
1618677465.8264189: {"stream":"yfiusdt@depth@100ms","data":{"e":"depthUpdate","E":1618677465766,"T":1618677465757,"s":"YFIUSDT","U":335341132057,"u":335341134833,"pu":335341129872,"b":[["49805.3","0.000"],["49824.8","0.007"],["49905.1","0.100"],["49929.3","0.000"],["49930.1","0.000"],["49933.8","0.000"],["49938.0","0.000"],["49944.1","0.000"],["49946.4","0.110"],["49950.6","0.110"],["50011.2","0.000"]],"a":[["50011.2","0.006"],["50086.0","0.005"],["50102.1","0.000"]]}}
1618677465.884734: {"stream":"dentusdt@depth@100ms","data":{"e":"depthUpdate","E":1618677465826,"T":1618677465820,"s":"DENTUSDT","U":335341133920,"u":335341136748,"pu":335341133790,"b":[["0.010074","0"],["0.010500","7505877"],["0.011194","38228"],["0.012258","109031"],["0.012299","169954"],["0.012336","0"]],"a":[["0.012352","19792"],["0.012359","40491"],["0.012718","1562"],["0.012793","94"],["0.012867","94"],["0.012941","1617"],["0.013015","937861"],["0.013089","2081"]]}}
1618677465.895798: {"stream":"dentusdt@aggTrade","data":{"e":"aggTrade","E":1618677465837,"a":8476427,"s":"DENTUSDT","p":"0.012348","q":"5564","f":15787419,"l":15787421,"T":1618677465681,"m":true}}
1618677465.908664: {"stream":"yfiusdt@aggTrade","data":{"e":"aggTrade","E":1618677465850,"a":52599710,"s":"YFIUSDT","p":"50011.2","q":"0.003","f":64902190,"l":64902190,"T":1618677465695,"m":false}}
1618677465.910966: {"stream":"dentusdt@bookTicker","data":{"e":"bookTicker","u":335341137581,"s":"DENTUSDT","b":"0.012348","B":"4861","a":"0.012349","A":"12052","T":1618677465849,"E":1618677465852}}
1618677465.9110699: {"stream":"xmrusdt@depth@100ms","data":{"e":"depthUpdate","E":1618677465853,"T":1618677465749,"s":"XMRUSDT","U":335341134619,"u":335341134633,"pu":335341129720,"b":[["352.18","0.000"],["352.30","2.500"]],"a":[]}}
1618677465.920594: {"stream":"dentusdt@bookTicker","data":{"e":"bookTicker","u":335341137852,"s":"DENTUSDT","b":"0.012348","B":"4861","a":"0.012352","A":"2062","T":1618677465858,"E":1618677465862}}
1618677465.9228349: {"stream":"dentusdt@bookTicker","data":{"e":"bookTicker","u":335341137891,"s":"DENTUSDT","b":"0.012348","B":"4861","a":"0.012352","A":"19792","T":1618677465860,"E":1618677465865}}
1618677465.930057: {"stream":"yfiusdt@depth@100ms","data":{"e":"depthUpdate","E":1618677465874,"T":1618677465790,"s":"YFIUSDT","U":335341135159,"u":335341135755,"pu":335341134833,"b":[["49310.7","0.115"]],"a":[["50126.8","0.009"],["50127.2","0.010"]]}}
1618677465.930603: {"stream":"ksmusdt@depth@100ms","data":{"e":"depthUpdate","E":1618677465875,"T":1618677465791,"s":"KSMUSDT","U":335341135220,"u":335341135784,"pu":335341133334,"b":[["457.236","1.0"]],"a":[["461.468","0.0"]]}}
1618677465.988817: {"stream":"dentusdt@depth@100ms","data":{"e":"depthUpdate","E":1618677465930,"T":1618677465914,"s":"DENTUSDT","U":335341136934,"u":335341139234,"pu":335341136748,"b":[["0.011783","0"],["0.012219","814286"],["0.012322","391483"],["0.012325","300809"],["0.012327","385644"],["0.012337","261874"],["0.012340","72869"],["0.012342","48575"],["0.012345","4059"],["0.012349","0"],["0.012601","0"]],"a":[["0.012349","0"],["0.012352","19792"],["0.012354","19156"],["0.012355","0"],["0.012357","0"],["0.012358","133881"],["0.012359","40491"],["0.012362","0"],["0.012409","110921"]]}}
1618677466.006428: {"stream":"dentusdt@bookTicker","data":{"e":"bookTicker","u":335341139922,"s":"DENTUSDT","b":"0.012348","B":"4861","a":"0.012352","A":"2062","T":1618677465943,"E":1618677465948}}
1618677466.0597398: {"stream":"dentusdt@aggTrade","data":{"e":"aggTrade","E":1618677466003,"a":8476428,"s":"DENTUSDT","p":"0.012349","q":"15760","f":15787422,"l":15787424,"T":1618677465849,"m":false}}
1618677466.0709062: {"stream":"xmrusdt@depth@100ms","data":{"e":"depthUpdate","E":1618677466013,"T":1618677465908,"s":"XMRUSDT","U":335341139104,"u":335341139104,"pu":335341134633,"b":[],"a":[["354.02","36.945"]]}}
1618677466.079315: {"stream":"ksmusdt@depth@100ms","data":{"e":"depthUpdate","E":1618677466021,"T":1618677466004,"s":"KSMUSDT","U":335341139271,"u":335341141242,"pu":335341135784,"b":[["457.329","0.0"]],"a":[["459.590","0.4"],["459.591","0.0"],["460.279","1.1"],["460.285","0.0"],["460.462","0.0"],["461.068","2.3"]]}}
1618677466.1020422: {"stream":"dentusdt@depth@100ms","data":{"e":"depthUpdate","E":1618677466039,"T":1618677466016,"s":"DENTUSDT","U":335341139735,"u":335341141627,"pu":335341139234,"b":[["0.012200","215366"],["0.012290","136967"],["0.012343","0"],["0.012345","8253"]],"a":[["0.012352","2062"],["0.012353","0"],["0.012354","17730"],["0.012355","0"],["0.012356","9110"],["0.012357","37354"],["0.012359","94467"],["0.012363","275318"]]}}
1618677466.211885: {"stream":"yfiusdt@depth@100ms","data":{"e":"depthUpdate","E":1618677466059,"T":1618677466050,"s":"YFIUSDT","U":335341140196,"u":335341142689,"pu":335341135755,"b":[["49788.1","0.000"],["49935.2","0.000"],["49942.6","0.060"],["49947.9","0.025"],["49973.2","0.000"],["49973.3","0.061"],["49973.4","0.266"]],"a":[["50096.9","0.000"],["50101.8","0.006"],["50108.6","0.138"]]}}
1618677466.227791: {"stream":"ksmusdt@depth@100ms","data":{"e":"depthUpdate","E":1618677466121,"T":1618677466112,"s":"KSMUSDT","U":335341141693,"u":335341144061,"pu":335341141242,"b":[["457.946","0.0"],["458.388","4.8"]],"a":[["459.369","0.1"],["459.372","0.0"],["459.431","0.1"],["459.440","0.0"],["459.526","0.1"],["459.529","0.0"],["459.797","2.3"]]}}
1618677466.230218: {"stream":"xmrusdt@depth@100ms","data":{"e":"depthUpdate","E":1618677466152,"T":1618677466074,"s":"XMRUSDT","U":335341142602,"u":335341143561,"pu":335341139104,"b":[["347.81","11.487"],["347.82","11.486"],["348.40","202.153"],["349.03","200.142"],["349.73","0.724"],["350.36","7.696"]],"a":[["354.59","5.933"],["356.41","200.000"]]}}
1618677466.230434: {"stream":"dentusdt@depth@100ms","data":{"e":"depthUpdate","E":1618677466157,"T":1618677466138,"s":"DENTUSDT","U":335341142872,"u":335341144478,"pu":335341141627,"b":[["0.012342","48575"]],"a":[["0.012354","0"],["0.012356","17730"],["0.012357","91335"],["0.012359","40486"],["0.012363","275318"]]}}
1618677466.230552: {"stream":"yfiusdt@depth@100ms","data":{"e":"depthUpdate","E":1618677466161,"T":1618677466140,"s":"YFIUSDT","U":335341143000,"u":335341144563,"pu":335341142689,"b":[["44561.3","0.000"],["45012.8","0.018"],["49556.9","0.000"],["49692.7","0.000"],["49716.5","0.010"],["49969.9","0.038"],["49973.5","0.063"]],"a":[["50115.4","0.000"]]}}
1618677466.302336: {"stream":"ksmusdt@depth@100ms","data":{"e":"depthUpdate","E":1618677466242,"T":1618677466203,"s":"KSMUSDT","U":335341144369,"u":335341146096,"pu":335341144061,"b":[["458.405","1.1"],["458.823","1.3"]],"a":[]}}
1618677466.316132: {"stream":"ksmusdt@bookTicker","data":{"e":"bookTicker","u":335341148123,"s":"KSMUSDT","b":"458.847","B":"6.4","a":"458.975","A":"0.1","T":1618677466253,"E":1618677466257}}
1618677466.322438: {"stream":"yfiusdt@depth@100ms","data":{"e":"depthUpdate","E":1618677466263,"T":1618677466256,"s":"YFIUSDT","U":335341144743,"u":335341148291,"pu":335341144563,"b":[["49947.9","0.000"],["49973.3","0.000"]],"a":[["50126.6","0.003"],["50130.2","0.094"]]}}
1618677466.325804: {"stream":"dentusdt@depth@100ms","data":{"e":"depthUpdate","E":1618677466267,"T":1618677466242,"s":"DENTUSDT","U":335341144811,"u":335341147765,"pu":335341144478,"b":[["0.012325","597754"],["0.012342","71331"],["0.012345","4194"]],"a":[["0.012355","0"],["0.012356","29450"],["0.012357","37354"],["0.012363","225531"],["0.012377","3238"]]}}
1618677466.326012: {"stream":"ksmusdt@bookTicker","data":{"e":"bookTicker","u":335341148653,"s":"KSMUSDT","b":"458.848","B":"1.0","a":"458.975","A":"0.1","T":1618677466264,"E":1618677466268}}
1618677466.350297: {"stream":"xmrusdt@depth@100ms","data":{"e":"depthUpdate","E":1618677466293,"T":1618677466285,"s":"XMRUSDT","U":335341145613,"u":335341149416,"pu":335341143561,"b":[["348.40","2.153"],["349.03","0.142"],["351.76","0.000"],["351.99","44.502"]],"a":[["352.98","8.983"],["352.99","42.771"],["353.00","0.000"],["353.01","0.000"],["356.41","0.000"]]}}
1618677466.357731: {"stream":"ksmusdt@bookTicker","data":{"e":"bookTicker","u":335341149718,"s":"KSMUSDT","b":"458.849","B":"0.3","a":"458.975","A":"0.1","T":1618677466292,"E":1618677466298}}
1618677466.412148: {"stream":"ksmusdt@depth@100ms","data":{"e":"depthUpdate","E":1618677466353,"T":1618677466329,"s":"KSMUSDT","U":335341147999,"u":335341150774,"pu":335341146096,"b":[["455.315","0.0"],["455.470","0.1"],["457.036","0.0"],["457.191","0.1"],["457.946","1.1"],["458.405","0.0"],["458.594","0.1"],["458.777","0.0"],["458.831","0.0"],["458.847","6.4"],["458.848","1.0"],["458.849","0.3"]],"a":[["459.155","0.0"],["459.162","0.0"],["459.207","1.2"],["459.238","0.3"],["459.239","1.6"],["459.240","3.2"],["459.407","0.1"],["459.576","1.0"],["460.475","0.0"],["460.631","0.1"],["462.196","0.0"],["462.352","0.1"],["466.206","3.6"]]}}
1618677466.427764: {"stream":"dentusdt@depth@100ms","data":{"e":"depthUpdate","E":1618677466369,"T":1618677466354,"s":"DENTUSDT","U":335341148679,"u":335341151630,"pu":335341147765,"b":[["0.012072","4592"],["0.012178","236373"],["0.012321","64482"],["0.012327","407531"],["0.012342","48575"],["0.012343","22756"]],"a":[["0.012354","26556"],["0.012355","53981"],["0.012356","2828"],["0.012359","40486"],["0.012363","275318"]]}}
1618677466.4571772: {"stream":"xmrusdt@depth@100ms","data":{"e":"depthUpdate","E":1618677466400,"T":1618677466386,"s":"XMRUSDT","U":335341149814,"u":335341152810,"pu":335341149416,"b":[["348.12","0.000"],["348.75","0.000"],["349.86","0.080"],["350.22","0.000"],["350.49","8.323"]],"a":[["354.55","200.000"]]}}
1618677466.492983: {"stream":"yfiusdt@depth@100ms","data":{"e":"depthUpdate","E":1618677466434,"T":1618677466329,"s":"YFIUSDT","U":335341150762,"u":335341150762,"pu":335341148291,"b":[["49949.4","0.025"]],"a":[]}}
1618677466.5162659: {"stream":"ksmusdt@depth@100ms","data":{"e":"depthUpdate","E":1618677466458,"T":1618677466443,"s":"KSMUSDT","U":335341151655,"u":335341154375,"pu":335341150774,"b":[["457.946","1.1"]],"a":[["459.185","0.3"],["459.186","1.2"],["459.205","0.0"],["459.206","1.6"],["459.207","0.0"],["459.238","0.0"],["459.239","0.0"],["459.576","1.0"],["460.196","0.0"],["462.782","0.2"]]}}
1618677466.5279748: {"stream":"dentusdt@depth@100ms","data":{"e":"depthUpdate","E":1618677466469,"T":1618677466441,"s":"DENTUSDT","U":335341152069,"u":335341154318,"pu":335341151630,"b":[["0.012343","22756"]],"a":[["0.012354","0"],["0.012355","8937"],["0.012356","0"],["0.012357","94163"],["0.012359","0"],["0.012363","275318"],["0.012405","1041394"]]}}
1618677466.55478: {"stream":"dentusdt@kline_1m","data":{"e":"kline","E":1618677466497,"s":"DENTUSDT","k":{"t":1618677420000,"T":1618677479999,"s":"DENTUSDT","i":"1m","f":15787262,"L":15787425,"o":"0.012366","c":"0.012348","h":"0.012366","l":"0.012339","v":"2637491","n":164,"x":false,"q":"32578.611180","V":"1213115","Q":"14988.390360","B":"0"}}}
1618677466.554868: {"stream":"dentusdt@bookTicker","data":{"e":"bookTicker","u":335341155671,"s":"DENTUSDT","b":"0.012348","B":"2435","a":"0.012352","A":"2062","T":1618677466493,"E":1618677466497}}
1618677466.55965: {"stream":"yfiusdt@bookTicker","data":{"e":"bookTicker","u":335341155715,"s":"YFIUSDT","b":"49996.3","B":"0.055","a":"50011.2","A":"0.006","T":1618677466495,"E":1618677466499}}
1618677466.5597188: {"stream":"xmrusdt@depth@100ms","data":{"e":"depthUpdate","E":1618677466500,"T":1618677466480,"s":"XMRUSDT","U":335341153122,"u":335341155302,"pu":335341152810,"b":[["349.20","0.017"],["349.24","0.000"],["349.86","200.080"],["350.49","208.323"],["352.30","0.000"],["352.40","2.952"]],"a":[["352.83","0.000"],["352.93","2.500"]]}}
1618677466.59118: {"stream":"yfiusdt@depth@100ms","data":{"e":"depthUpdate","E":1618677466535,"T":1618677466525,"s":"YFIUSDT","U":335341154077,"u":335341156490,"pu":335341150762,"b":[["49946.5","0.000"],["49952.8","0.013"],["49957.4","0.000"],["49963.6","0.013"],["49969.0","0.000"],["49969.9","0.000"],["49973.6","0.168"],["49992.5","0.000"],["49996.3","0.055"]],"a":[["50088.0","0.006"],["50205.8","0.006"]]}}
1618677466.63147: {"stream":"ksmusdt@depth@100ms","data":{"e":"depthUpdate","E":1618677466571,"T":1618677466550,"s":"KSMUSDT","U":335341155011,"u":335341157130,"pu":335341154375,"b":[["456.728","0.7"]],"a":[["459.183","0.3"],["459.184","1.6"],["459.185","0.0"],["459.186","0.0"],["459.206","0.0"],["459.247","0.0"],["459.511","17.8"],["459.579","0.0"],["460.585","0.0"],["460.770","0.5"]]}}
1618677466.654059: {"stream":"dentusdt@depth@100ms","data":{"e":"depthUpdate","E":1618677466588,"T":1618677466567,"s":"DENTUSDT","U":335341155444,"u":335341157510,"pu":335341154318,"b":[["0.012342","71331"],["0.012343","0"],["0.012348","2435"]],"a":[["0.012354","17730"],["0.012355","0"],["0.012356","9193"],["0.012359","40486"],["0.012378","404875"],["0.012379","61122"],["0.012390","2887"],["0.012414","264310"]]}}
1618677466.702136: {"stream":"yfiusdt@depth@100ms","data":{"e":"depthUpdate","E":1618677466641,"T":1618677466634,"s":"YFIUSDT","U":335341156724,"u":335341159132,"pu":335341156490,"b":[["49885.8","0.000"],["49911.3","0.000"],["49936.3","0.022"],["49936.5","0.020"],["49973.4","0.000"],["49973.5","0.000"],["49977.7","0.280"]],"a":[["50023.6","0.000"],["50023.7","0.000"],["50039.9","0.058"],["50050.0","0.017"],["50068.2","0.002"],["50086.1","0.130"]]}}
1618677466.70243: {"stream":"dentusdt@bookTicker","data":{"e":"bookTicker","u":335341159175,"s":"DENTUSDT","b":"0.012350","B":"5846","a":"0.012352","A":"2062","T":1618677466636,"E":1618677466641}}
1618677466.705535: {"stream":"dentusdt@aggTrade","data":{"e":"aggTrade","E":1618677466648,"a":8476429,"s":"DENTUSDT","p":"0.012348","q":"2426","f":15787425,"l":15787426,"T":1618677466493,"m":true}}
1618677466.727266: {"stream":"xmrusdt@depth@100ms","data":{"e":"depthUpdate","E":1618677466668,"T":1618677466567,"s":"XMRUSDT","U":335341157462,"u":335341157543,"pu":335341155302,"b":[["352.30","2.500"],["352.40","0.452"]],"a":[["352.83","2.500"],["352.93","0.000"]]}}
1618677466.744673: {"stream":"ksmusdt@depth@100ms","data":{"e":"depthUpdate","E":1618677466685,"T":1618677466666,"s":"KSMUSDT","U":335341157893,"u":335341159920,"pu":335341157130,"b":[["457.713","0.0"],["457.851","0.1"]],"a":[["459.184","0.0"],["459.239","1.6"],["459.576","0.0"],["459.577","0.0"],["459.880","1.0"]]}}
1618677466.767581: {"stream":"dentusdt@depth@100ms","data":{"e":"depthUpdate","E":1618677466710,"T":1618677466704,"s":"DENTUSDT","U":335341158465,"u":335341160778,"pu":335341157510,"b":[["0.011882","26915"],["0.012342","97154"],["0.012343","22753"],["0.012345","8251"],["0.012350","5846"]],"a":[["0.012354","0"],["0.012355","0"],["0.012356","26707"],["0.012357","37354"],["0.012358","2831"],["0.012359","94460"],["0.012363","225531"],["0.012367","49787"],["0.012384","28154"],["0.012617","21457"],["0.012718","1468"],["0.012737","1244"],["0.012793","0"],["0.012867","0"],["0.012941","1523"],["0.013015","937767"],["0.013089","1988"]]}}
1618677466.8445: {"stream":"xmrusdt@depth@100ms","data":{"e":"depthUpdate","E":1618677466787,"T":1618677466751,"s":"XMRUSDT","U":335341160216,"u":335341162074,"pu":335341157543,"b":[["351.52","4.941"],["351.54","50.883"],["351.96","18.523"],["351.98","1.224"]],"a":[["353.44","23.178"],["353.60","0.000"],["353.77","47.316"],["353.81","1.200"],["353.96","0.666"],["354.02","0.000"]]}}
1618677466.859918: {"stream":"yfiusdt@depth@100ms","data":{"e":"depthUpdate","E":1618677466801,"T":1618677466720,"s":"YFIUSDT","U":335341160653,"u":335341161214,"pu":335341159132,"b":[["49993.8","0.000"]],"a":[["50131.0","0.007"],["50153.8","0.029"]]}}
1618677466.8850508: {"stream":"dentusdt@depth@100ms","data":{"e":"depthUpdate","E":1618677466829,"T":1618677466804,"s":"DENTUSDT","U":335341161397,"u":335341163727,"pu":335341160778,"b":[["0.012227","87562"]],"a":[["0.012355","17730"],["0.012356","8977"],["0.012357","16028"],["0.012359","93101"],["0.012377","43721"],["0.012397","135685"]]}}
1618677466.8946261: {"stream":"ksmusdt@bookTicker","data":{"e":"bookTicker","u":335341164644,"s":"KSMUSDT","b":"458.912","B":"0.1","a":"458.975","A":"0.1","T":1618677466830,"E":1618677466834}}
1618677466.927577: {"stream":"yfiusdt@bookTicker","data":{"e":"bookTicker","u":335341165488,"s":"YFIUSDT","b":"49996.3","B":"0.055","a":"50003.8","A":"0.001","T":1618677466864,"E":1618677466868}}
1618677466.9364579: {"stream":"yfiusdt@bookTicker","data":{"e":"bookTicker","u":335341165772,"s":"YFIUSDT","b":"49997.6","B":"0.012","a":"50003.8","A":"0.001","T":1618677466874,"E":1618677466878}}
1618677466.936558: {"stream":"yfiusdt@kline_1m","data":{"e":"kline","E":1618677466879,"s":"YFIUSDT","k":{"t":1618677420000,"T":1618677479999,"s":"YFIUSDT","i":"1m","f":64902095,"L":64902191,"o":"50010.8","c":"50003.8","h":"50044.2","l":"49950.6","v":"1.102","n":97,"x":false,"q":"55098.5931","V":"0.785","Q":"39249.2965","B":"0"}}}
1618677466.939415: {"stream":"yfiusdt@aggTrade","data":{"e":"aggTrade","E":1618677466880,"a":52599711,"s":"YFIUSDT","p":"50003.8","q":"0.001","f":64902191,"l":64902191,"T":1618677466875,"m":false}}
1618677466.939518: {"stream":"yfiusdt@bookTicker","data":{"e":"bookTicker","u":335341165825,"s":"YFIUSDT","b":"49997.6","B":"0.012","a":"50011.2","A":"0.001","T":1618677466875,"E":1618677466880}}
1618677466.960036: {"stream":"yfiusdt@depth@100ms","data":{"e":"depthUpdate","E":1618677466901,"T":1618677466891,"s":"YFIUSDT","U":335341163453,"u":335341166243,"pu":335341161214,"b":[["49681.5","0.000"],["49694.8","0.000"],["49771.0","0.000"],["49923.7","0.000"],["49936.4","0.000"],["49942.2","0.000"],["49944.6","0.000"],["49947.8","0.000"],["49948.7","0.000"],["49949.3","0.000"],["49949.4","0.000"],["49951.0","0.051"],["49954.2","0.051"],["49954.8","0.110"],["49955.0","0.051"],["49961.8","0.080"],["49970.0","0.017"],["49973.1","0.000"],["49973.6","0.000"],["49974.5","0.080"],["49975.0","0.017"],["49993.7","0.000"],["49997.6","0.012"]],"a":[["50003.8","0.000"],["50011.2","0.001"],["50018.5","0.000"],["50074.3","0.008"],["50080.9","0.000"],["50106.2","0.015"],["50135.0","0.026"],["50194.4","0.000"]]}}
1618677466.965791: {"stream":"ksmusdt@depth@100ms","data":{"e":"depthUpdate","E":1618677466905,"T":1618677466899,"s":"KSMUSDT","U":335341163609,"u":335341166444,"pu":335341159920,"b":[["455.005","0.0"],["457.221","1.0"],["458.912","0.1"]],"a":[["459.240","0.0"],["459.246","0.0"],["460.841","0.0"],["460.934","1.2"]]}}
1618677466.966036: {"stream":"xmrusdt@depth@100ms","data":{"e":"depthUpdate","E":1618677466909,"T":1618677466836,"s":"XMRUSDT","U":335341163810,"u":335341164759,"pu":335341162074,"b":[["350.17","0.065"],["350.32","50.557"]],"a":[]}}
1618677466.969054: {"stream":"ksmusdt@kline_1m","data":{"e":"kline","E":1618677466911,"s":"KSMUSDT","k":{"t":1618677420000,"T":1618677479999,"s":"KSMUSDT","i":"1m","f":25426460,"L":25426583,"o":"459.607","c":"458.924","h":"459.671","l":"458.391","v":"112.9","n":124,"x":false,"q":"51824.9211","V":"53.6","Q":"24614.3625","B":"0"}}}
1618677466.969179: {"stream":"ksmusdt@bookTicker","data":{"e":"bookTicker","u":335341166668,"s":"KSMUSDT","b":"458.924","B":"5.0","a":"458.975","A":"0.1","T":1618677466907,"E":1618677466911}}
1618677466.969228: {"stream":"ksmusdt@bookTicker","data":{"e":"bookTicker","u":335341166673,"s":"KSMUSDT","b":"458.924","B":"2.0","a":"458.975","A":"0.1","T":1618677466907,"E":1618677466911}}
1618677466.969877: {"stream":"ksmusdt@bookTicker","data":{"e":"bookTicker","u":335341166743,"s":"KSMUSDT","b":"458.912","B":"0.1","a":"458.975","A":"0.1","T":1618677466910,"E":1618677466913}}
1618677466.98116: {"stream":"ksmusdt@bookTicker","data":{"e":"bookTicker","u":335341167029,"s":"KSMUSDT","b":"458.925","B":"0.3","a":"458.975","A":"0.1","T":1618677466918,"E":1618677466922}}
1618677466.992361: {"stream":"dentusdt@depth@100ms","data":{"e":"depthUpdate","E":1618677466934,"T":1618677466896,"s":"DENTUSDT","U":335341164611,"u":335341166381,"pu":335341163727,"b":[["0.012317","48652"],["0.012322","355631"]],"a":[["0.012382","427168"],["0.012387","35168"],["0.012393","17032"]]}}
1618677467.014164: {"stream":"ksmusdt@bookTicker","data":{"e":"bookTicker","u":335341167876,"s":"KSMUSDT","b":"458.912","B":"0.1","a":"458.975","A":"0.1","T":1618677466951,"E":1618677466956}}
1618677467.027315: {"stream":"yfiusdt@bookTicker","data":{"e":"bookTicker","u":335341168139,"s":"YFIUSDT","b":"49997.6","B":"0.012","a":"50023.5","A":"0.013","T":1618677466963,"E":1618677466967}}
1618677467.0274339: {"stream":"dentusdt@kline_1m","data":{"e":"kline","E":1618677466969,"s":"DENTUSDT","k":{"t":1618677420000,"T":1618677479999,"s":"DENTUSDT","i":"1m","f":15787262,"L":15787427,"o":"0.012366","c":"0.012350","h":"0.012366","l":"0.012339","v":"2644727","n":166,"x":false,"q":"32667.973000","V":"1213115","Q":"14988.390360","B":"0"}}}
1618677467.03365: {"stream":"dentusdt@aggTrade","data":{"e":"aggTrade","E":1618677466969,"a":8476430,"s":"DENTUSDT","p":"0.012350","q":"5846","f":15787427,"l":15787427,"T":1618677466965,"m":true}}
1618677467.0337222: {"stream":"dentusdt@aggTrade","data":{"e":"aggTrade","E":1618677466969,"a":8476431,"s":"DENTUSDT","p":"0.012348","q":"2435","f":15787428,"l":15787428,"T":1618677466965,"m":true}}
1618677467.033751: {"stream":"dentusdt@aggTrade","data":{"e":"aggTrade","E":1618677466969,"a":8476432,"s":"DENTUSDT","p":"0.012347","q":"32702","f":15787429,"l":15787430,"T":1618677466965,"m":true}}
1618677467.0337741: {"stream":"dentusdt@aggTrade","data":{"e":"aggTrade","E":1618677466969,"a":8476433,"s":"DENTUSDT","p":"0.012345","q":"8251","f":15787431,"l":15787432,"T":1618677466965,"m":true}}
1618677467.033795: {"stream":"dentusdt@bookTicker","data":{"e":"bookTicker","u":335341168210,"s":"DENTUSDT","b":"0.012344","B":"69824","a":"0.012352","A":"2062","T":1618677466965,"E":1618677466969}}
1618677467.052308: {"stream":"yfiusdt@bookTicker","data":{"e":"bookTicker","u":335341168958,"s":"YFIUSDT","b":"49997.7","B":"0.025","a":"50023.5","A":"0.013","T":1618677466991,"E":1618677466994}}
1618677467.06219: {"stream":"yfiusdt@depth@100ms","data":{"e":"depthUpdate","E":1618677467004,"T":1618677466993,"s":"YFIUSDT","U":335341166460,"u":335341169030,"pu":335341166243,"b":[["49721.9","0.000"],["49743.0","0.013"],["49787.2","0.000"],["49875.3","0.000"],["49886.7","0.157"],["49911.2","0.000"],["49938.0","0.110"],["49942.2","0.110"],["49950.6","0.000"],["49954.8","0.000"],["49970.1","0.087"],["49973.7","0.000"],["49977.8","0.168"],["49989.6","0.016"],["49992.4","0.000"],["49996.4","0.001"],["49997.7","0.025"]],"a":[["50011.2","0.000"],["50023.5","0.013"],["50039.8","0.011"],["50040.0","0.000"],["50045.0","0.000"],["50046.6","0.081"],["50050.0","0.000"],["50052.7","0.000"],["50059.8","0.000"],["50060.2","0.000"],["50065.9","0.006"],["50072.3","0.000"],["50076.4","0.004"],["50083.9","0.004"],["50086.1","0.000"],["50089.7","0.004"],["50092.2","0.007"],["50130.2","0.000"],["50138.7","0.094"],["50187.0","0.000"],["50254.4","0.005"]]}}
1618677467.0674372: {"stream":"ksmusdt@depth@100ms","data":{"e":"depthUpdate","E":1618677467009,"T":1618677466998,"s":"KSMUSDT","U":335341166630,"u":335341169118,"pu":335341166444,"b":[["456.268","0.0"],["456.465","1.4"],["457.517","0.8"],["457.946","0.0"],["458.387","0.0"],["458.388","0.0"],["458.706","0.0"],["458.849","0.0"],["458.893","1.5"],["458.894","0.3"],["458.924","0.0"],["458.925","0.0"]],"a":[["459.183","0.0"],["459.208","1.2"],["459.239","0.3"],["459.240","1.6"],["459.880","0.0"],["460.494","0.0"]]}}
1618677467.067616: {"stream":"yfiusdt@bookTicker","data":{"e":"bookTicker","u":335341169425,"s":"YFIUSDT","b":"49997.8","B":"0.020","a":"50023.5","A":"0.013","T":1618677467006,"E":1618677467009}}
1618677467.075785: {"stream":"xmrusdt@depth@100ms","data":{"e":"depthUpdate","E":1618677467017,"T":1618677466912,"s":"XMRUSDT","U":335341166842,"u":335341166842,"pu":335341164759,"b":[],"a":[["363.83","0.000"]]}}
1618677467.089807: {"stream":"yfiusdt@aggTrade","data":{"e":"aggTrade","E":1618677467031,"a":52599712,"s":"YFIUSDT","p":"50011.2","q":"0.005","f":64902192,"l":64902192,"T":1618677466875,"m":false}}
1618677467.0899122: {"stream":"yfiusdt@bookTicker","data":{"e":"bookTicker","u":335341170291,"s":"YFIUSDT","b":"49997.8","B":"0.020","a":"50023.8","A":"0.004","T":1618677467028,"E":1618677467031}}
1618677467.0943549: {"stream":"dentusdt@depth@100ms","data":{"e":"depthUpdate","E":1618677467034,"T":1618677467027,"s":"DENTUSDT","U":335341167352,"u":335341170211,"pu":335341166381,"b":[["0.012260","429120"],["0.012296","64840"],["0.012322","73335"],["0.012323","136989"],["0.012326","44986"],["0.012337","30241"],["0.012338","217028"],["0.012340","48581"],["0.012342","48575"],["0.012343","0"],["0.012344","69824"],["0.012345","0"],["0.012347","0"],["0.012348","0"],["0.012350","0"]],"a":[["0.012337","0"],["0.012354","9338"],["0.012355","0"],["0.012356","0"],["0.012358","136712"],["0.012359","39124"],["0.012360","283011"],["0.012363","249713"],["0.012366","134942"],["0.012367","0"],["0.012369","0"],["0.012370","11311"],["0.012377","3238"],["0.012378","728735"],["0.012380","404875"],["0.012429","313197"]]}}
1618677467.094784: {"stream":"yfiusdt@bookTicker","data":{"e":"bookTicker","u":335341170370,"s":"YFIUSDT","b":"50000.3","B":"0.055","a":"50023.8","A":"0.004","T":1618677467031,"E":1618677467034}}
1618677467.112619: {"stream":"yfiusdt@bookTicker","data":{"e":"bookTicker","u":335341170899,"s":"YFIUSDT","b":"50000.4","B":"0.033","a":"50023.8","A":"0.004","T":1618677467048,"E":1618677467051}}
1618677467.112722: {"stream":"yfiusdt@bookTicker","data":{"e":"bookTicker","u":335341171079,"s":"YFIUSDT","b":"50001.6","B":"0.012","a":"50023.8","A":"0.004","T":1618677467051,"E":1618677467055}}
1618677467.236493: {"stream":"ksmusdt@aggTrade","data":{"e":"aggTrade","E":1618677467062,"a":21396989,"s":"KSMUSDT","p":"458.924","q":"3.0","f":25426583,"l":25426583,"T":1618677466907,"m":true}}
1618677467.237362: {"stream":"yfiusdt@bookTicker","data":{"e":"bookTicker","u":335341171458,"s":"YFIUSDT","b":"50001.7","B":"0.010","a":"50023.8","A":"0.004","T":1618677467065,"E":1618677467069}}
1618677467.2374341: {"stream":"yfiusdt@bookTicker","data":{"e":"bookTicker","u":335341171498,"s":"YFIUSDT","b":"50001.7","B":"0.027","a":"50023.8","A":"0.004","T":1618677467066,"E":1618677467069}}
1618677467.243847: {"stream":"yfiusdt@depth@100ms","data":{"e":"depthUpdate","E":1618677467107,"T":1618677467088,"s":"YFIUSDT","U":335341169300,"u":335341171981,"pu":335341169030,"b":[["49607.6","0.000"],["49633.1","0.107"],["49690.3","0.010"],["49795.0","0.017"],["49808.3","0.009"],["49820.6","0.108"],["49828.7","0.100"],["49931.6","0.000"],["49954.5","0.000"],["49955.1","0.025"],["49959.4","0.016"],["49963.5","0.070"],["49977.8","0.000"],["49977.9","0.096"],["49978.0","0.168"],["49996.5","0.013"],["49997.6","0.000"],["49997.8","0.000"],["50000.3","0.055"],["50000.4","0.000"],["50000.5","0.016"],["50001.6","0.012"],["50001.7","0.027"]],"a":[["50023.5","0.000"],["50025.2","0.002"],["50025.3","0.000"],["50027.3","0.000"],["50039.7","0.017"],["50039.8","0.000"],["50060.9","0.000"],["50083.8","0.024"],["50158.1","0.000"],["50168.1","0.000"],["50170.0","0.017"],["50183.3","0.024"],["50193.3","0.011"],["50195.8","0.107"],["50228.9","0.100"],["50357.4","0.000"],["50383.3","0.107"]]}}
1618677467.2442582: {"stream":"dentusdt@bookTicker","data":{"e":"bookTicker","u":335341172214,"s":"DENTUSDT","b":"0.012344","B":"69824","a":"0.012352","A":"11317","T":1618677467107,"E":1618677467112}}
1618677467.245846: {"stream":"dentusdt@aggTrade","data":{"e":"aggTrade","E":1618677467120,"a":8476434,"s":"DENTUSDT","p":"0.012344","q":"11176","f":15787433,"l":15787433,"T":1618677466965,"m":true}}
1618677467.2459068: {"stream":"ksmusdt@depth@100ms","data":{"e":"depthUpdate","E":1618677467120,"T":1618677467069,"s":"KSMUSDT","U":335341169850,"u":335341171594,"pu":335341169118,"b":[["457.946","1.1"],["458.564","0.2"],["458.746","0.0"],["458.848","0.0"],["458.883","1.0"],["458.893","0.0"]],"a":[["459.186","0.3"],["459.187","1.2"],["459.206","0.0"],["459.207","1.6"],["459.208","0.0"],["459.239","0.0"],["459.240","0.0"],["459.369","0.0"],["459.401","0.1"],["459.420","0.1"],["459.431","0.0"],["459.510","4.1"],["459.526","0.0"],["459.557","0.1"],["459.880","1.0"]]}}
1618677467.2461288: {"stream":"xmrusdt@depth@100ms","data":{"e":"depthUpdate","E":1618677467130,"T":1618677467097,"s":"XMRUSDT","U":335341170199,"u":335341172082,"pu":335341166842,"b":[["351.40","28.957"],["351.79","156.419"]],"a":[["364.32","65.797"]]}}
1618677467.246484: {"stream":"dentusdt@depth@100ms","data":{"e":"depthUpdate","E":1618677467138,"T":1618677467129,"s":"DENTUSDT","U":335341170471,"u":335341172445,"pu":335341170211,"b":[["0.012319","957917"],["0.012331","36581"],["0.012332","284245"]],"a":[["0.012352","11317"],["0.012353","71720"],["0.012354","0"],["0.012356","40492"],["0.012360","340949"],["0.012362","53977"],["0.012717","32225"],["0.012791","179776"],["0.012866","178"],["0.012940","288105"],["0.013014","178"],["0.013088","7065"]]}}
1618677467.270717: {"stream":"yfiusdt@depth@100ms","data":{"e":"depthUpdate","E":1618677467212,"T":1618677467190,"s":"YFIUSDT","U":335341172234,"u":335341174189,"pu":335341171981,"b":[["49727.5","0.010"],["49881.1","0.000"],["49916.1","0.050"],["49952.8","0.000"],["49955.1","0.000"],["49958.2","0.020"],["49962.7","0.010"],["49963.6","0.000"],["49969.0","0.020"],["49996.4","0.000"]],"a":[["50025.2","0.000"],["50026.5","0.004"],["50026.6","0.012"],["50039.9","0.029"],["50062.7","0.009"],["50070.6","0.298"],["50085.9","0.005"],["50086.0","0.000"],["50114.9","0.000"],["50122.7","0.094"],["50129.4","0.000"],["50139.7","0.400"],["50146.4","0.050"],["50147.9","0.000"],["50177.6","0.001"],["50180.1","0.000"],["50227.6","0.009"],["50237.3","0.000"],["50282.0","0.000"]]}}
1618677467.2715101: {"stream":"yfiusdt@bookTicker","data":{"e":"bookTicker","u":335341174769,"s":"YFIUSDT","b":"50004.1","B":"0.055","a":"50023.8","A":"0.004","T":1618677467210,"E":1618677467214}}
1618677467.271571: {"stream":"dentusdt@bookTicker","data":{"e":"bookTicker","u":335341174799,"s":"DENTUSDT","b":"0.012344","B":"69824","a":"0.012352","A":"2062","T":1618677467211,"E":1618677467214}}
1618677467.2844741: {"stream":"yfiusdt@bookTicker","data":{"e":"bookTicker","u":335341175142,"s":"YFIUSDT","b":"50004.2","B":"0.025","a":"50023.8","A":"0.004","T":1618677467222,"E":1618677467226}}
1618677467.292703: {"stream":"ksmusdt@depth@100ms","data":{"e":"depthUpdate","E":1618677467234,"T":1618677467221,"s":"KSMUSDT","U":335341172523,"u":335341175096,"pu":335341171594,"b":[["453.759","0.0"],["456.618","0.0"],["457.044","0.0"],["458.883","0.0"]],"a":[["459.486","0.0"],["459.623","0.0"],["459.797","0.0"],["460.013","4.7"],["460.521","0.0"]]}}
1618677467.293875: {"stream":"yfiusdt@bookTicker","data":{"e":"bookTicker","u":335341175414,"s":"YFIUSDT","b":"50004.1","B":"0.055","a":"50023.8","A":"0.004","T":1618677467232,"E":1618677467236}}
1618677467.298547: {"stream":"xmrusdt@depth@100ms","data":{"e":"depthUpdate","E":1618677467240,"T":1618677467168,"s":"XMRUSDT","U":335341172658,"u":335341173307,"pu":335341172082,"b":[["350.16","2.829"],["350.31","1.775"]],"a":[]}}
1618677467.304829: {"stream":"yfiusdt@bookTicker","data":{"e":"bookTicker","u":335341175767,"s":"YFIUSDT","b":"50004.2","B":"0.025","a":"50023.8","A":"0.004","T":1618677467242,"E":1618677467246}}
1618677467.310094: {"stream":"dentusdt@bookTicker","data":{"e":"bookTicker","u":335341175857,"s":"DENTUSDT","b":"0.012342","B":"48575","a":"0.012352","A":"2062","T":1618677467245,"E":1618677467250}}
1618677467.328233: {"stream":"dentusdt@depth@100ms","data":{"e":"depthUpdate","E":1618677467270,"T":1618677467256,"s":"DENTUSDT","U":335341173222,"u":335341176291,"pu":335341172445,"b":[["0.012326","40612"],["0.012330","180868"],["0.012333","22762"],["0.012335","28202"],["0.012337","27003"],["0.012344","0"]],"a":[["0.012352","2062"],["0.012353","26623"],["0.012355","53990"],["0.012356","47390"],["0.012357","52490"],["0.012358","133881"],["0.012359","0"],["0.012362","53977"],["0.012398","245538"],["0.012611","7232"]]}}
1618677467.359349: {"stream":"yfiusdt@bookTicker","data":{"e":"bookTicker","u":335341177682,"s":"YFIUSDT","b":"50006.3","B":"0.055","a":"50023.8","A":"0.004","T":1618677467298,"E":1618677467301}}
1618677467.37185: {"stream":"yfiusdt@depth@100ms","data":{"e":"depthUpdate","E":1618677467313,"T":1618677467300,"s":"YFIUSDT","U":335341174743,"u":335341177765,"pu":335341174189,"b":[["49951.0","0.000"],["49954.2","0.000"],["49955.0","0.000"],["49975.1","0.271"],["49975.2","0.078"],["49977.7","0.000"],["49977.9","0.000"],["49978.1","0.040"],["49996.3","0.000"],["49996.5","0.000"],["50000.3","0.000"],["50001.7","0.003"],["50004.1","0.055"],["50004.2","0.025"],["50006.3","0.055"]],"a":[["50072.2","0.001"],["50100.5","0.000"],["50252.2","0.042"],["51280.0","0.041"]]}}
1618677467.37252: {"stream":"yfiusdt@bookTicker","data":{"e":"bookTicker","u":335341178016,"s":"YFIUSDT","b":"50006.4","B":"0.025","a":"50023.8","A":"0.004","T":1618677467310,"E":1618677467314}}
1618677467.382835: {"stream":"yfiusdt@bookTicker","data":{"e":"bookTicker","u":335341178310,"s":"YFIUSDT","b":"50006.3","B":"0.055","a":"50023.8","A":"0.004","T":1618677467320,"E":1618677467324}}
1618677467.388567: {"stream":"yfiusdt@bookTicker","data":{"e":"bookTicker","u":335341178471,"s":"YFIUSDT","b":"50006.4","B":"0.025","a":"50023.8","A":"0.004","T":1618677467326,"E":1618677467330}}
1618677467.395166: {"stream":"ksmusdt@depth@100ms","data":{"e":"depthUpdate","E":1618677467336,"T":1618677467330,"s":"KSMUSDT","U":335341175424,"u":335341178559,"pu":335341175096,"b":[["422.024","2.0"],["422.489","0.0"],["456.511","0.0"],["456.557","0.2"],["456.589","0.4"],["456.625","0.1"],["457.135","0.0"],["457.411","0.0"],["457.946","0.0"],["458.299","17.5"],["458.300","1.1"],["458.301","4.1"]],"a":[["459.180","0.3"],["459.181","1.2"],["459.182","0.0"],["459.186","0.0"],["459.187","0.0"],["459.207","0.0"],["459.240","1.6"],["459.533","5.6"],["460.087","2.7"],["460.407","0.0"],["460.602","0.0"],["460.604","0.0"],["460.644","0.0"],["461.036","3.9"],["461.044","0.0"],["461.111","0.0"],["461.225","0.1"],["461.358","0.0"],["461.543","0.0"],["461.550","0.0"],["462.437","0.0"],["463.101","3.9"],["463.110","0.0"],["495.863","1.7"],["496.340","0.2"]]}}
1618677467.4020102: {"stream":"ksmusdt@bookTicker","data":{"e":"bookTicker","u":335341178766,"s":"KSMUSDT","b":"458.894","B":"0.3","a":"458.975","A":"0.1","T":1618677467337,"E":1618677467344}}
1618677467.411618: {"stream":"ksmusdt@bookTicker","data":{"e":"bookTicker","u":335341179112,"s":"KSMUSDT","b":"458.943","B":"0.1","a":"458.975","A":"0.1","T":1618677467348,"E":1618677467353}}
1618677467.424282: {"stream":"dentusdt@bookTicker","data":{"e":"bookTicker","u":335341179418,"s":"DENTUSDT","b":"0.012342","B":"48575","a":"0.012352","A":"56056","T":1618677467359,"E":1618677467364}}
1618677467.424528: {"stream":"xmrusdt@depth@100ms","data":{"e":"depthUpdate","E":1618677467367,"T":1618677467276,"s":"XMRUSDT","U":335341176493,"u":335341177014,"pu":335341173307,"b":[["347.93","200.000"],["348.56","200.761"],["349.86","0.080"],["350.49","8.323"]],"a":[["354.55","0.000"],["356.47","202.964"]]}}
1618677467.434133: {"stream":"dentusdt@depth@100ms","data":{"e":"depthUpdate","E":1618677467375,"T":1618677467360,"s":"DENTUSDT","U":335341176809,"u":335341179424,"pu":335341176291,"b":[["0.012333","0"],["0.012337","108343"],["0.012338","346622"],["0.012339","52040"],["0.012340","22766"]],"a":[["0.012352","56056"],["0.012355","20904"],["0.012357","31586"],["0.012358","133881"],["0.012360","394926"],["0.012362","0"],["0.012379","73670"]]}}
