1626992769.3589299: {"stream":"ctkusdt@depth@100ms","data":{"e":"depthUpdate","E":1626992769313,"T":1626992769302,"s":"CTKUSDT","U":600860373056,"u":600860376301,"pu":600860371121,"b":[["1.00700","13477"],["1.00800","12743"]],"a":[["1.01300","11441"]]}}
1626992769.365367: {"stream":"akrousdt@kline_1m","data":{"e":"kline","E":1626992769319,"s":"AKROUSDT","k":{"t":1626992760000,"T":1626992819999,"s":"AKROUSDT","i":"1m","f":27931357,"L":27931361,"o":"0.01734","c":"0.01734","h":"0.01735","l":"0.01734","v":"72905","n":5,"x":false,"q":"1264.62610","V":"60253","Q":"1045.24042","B":"0"}}}
1626992769.365484: {"stream":"akrousdt@bookTicker","data":{"e":"bookTicker","u":600860376785,"s":"AKROUSDT","b":"0.01734","B":"3315","a":"0.01735","A":"50697","T":1626992769315,"E":1626992769318}}
1626992769.369471: {"stream":"akrousdt@depth@100ms","data":{"e":"depthUpdate","E":1626992769324,"T":1626992769315,"s":"AKROUSDT","U":600860373434,"u":600860376785,"pu":600860371747,"b":[["0.01726","344498"],["0.01727","731666"],["0.01732","795679"],["0.01733","40443"],["0.01734","3315"]],"a":[["0.01739","324785"],["0.01740","441655"]]}}
1626992769.37267: {"stream":"akrousdt@bookTicker","data":{"e":"bookTicker","u":600860377154,"s":"AKROUSDT","b":"0.01734","B":"3315","a":"0.01735","A":"280697","T":1626992769323,"E":1626992769327}}
1626992769.381218: {"stream":"akrousdt@bookTicker","data":{"e":"bookTicker","u":600860377573,"s":"AKROUSDT","b":"0.01734","B":"3315","a":"0.01735","A":"50697","T":1626992769332,"E":1626992769337}}
1626992769.402397: {"stream":"akrousdt@bookTicker","data":{"e":"bookTicker","u":600860378282,"s":"AKROUSDT","b":"0.01734","B":"502","a":"0.01735","A":"50697","T":1626992769348,"E":1626992769354}}
1626992769.402494: {"stream":"akrousdt@bookTicker","data":{"e":"bookTicker","u":600860378430,"s":"AKROUSDT","b":"0.01734","B":"502","a":"0.01735","A":"86571","T":1626992769352,"E":1626992769356}}
1626992769.4421551: {"stream":"sushiusdt@depth@100ms","data":{"e":"depthUpdate","E":1626992769395,"T":1626992769381,"s":"SUSHIUSDT","U":600860375852,"u":600860379645,"pu":600860373776,"b":[["7.5800","4071"],["7.5860","1188"],["7.5900","1919"],["7.5950","953"],["7.6000","1940"],["7.6010","3129"],["7.6030","2127"],["7.6110","3"]],"a":[["7.6170","699"],["7.6190","2282"],["7.6230","2226"],["7.6240","3823"],["7.6260","1182"],["7.6410","2771"],["7.6510","1906"],["7.7040","1086"],["7.7060","523"]]}}
1626992769.457032: {"stream":"akrousdt@bookTicker","data":{"e":"bookTicker","u":600860380605,"s":"AKROUSDT","b":"0.01734","B":"502","a":"0.01735","A":"106557","T":1626992769407,"E":1626992769411}}
1626992769.463108: {"stream":"ctkusdt@depth@100ms","data":{"e":"depthUpdate","E":1626992769417,"T":1626992769382,"s":"CTKUSDT","U":600860376670,"u":600860379679,"pu":600860376301,"b":[["1.00700","13279"]],"a":[["1.01300","11393"]]}}
1626992769.472905: {"stream":"akrousdt@depth@100ms","data":{"e":"depthUpdate","E":1626992769427,"T":1626992769415,"s":"AKROUSDT","U":600860377154,"u":600860380924,"pu":600860376785,"b":[["0.01729","299327"],["0.01733","46779"],["0.01734","502"]],"a":[["0.01735","106557"],["0.01736","303832"],["0.01737","751363"],["0.01740","446032"],["0.01746","83847"],["0.01748","2650934"]]}}
1626992769.514473: {"stream":"akrousdt@aggTrade","data":{"e":"aggTrade","E":1626992769469,"a":14888309,"s":"AKROUSDT","p":"0.01734","q":"14165","f":27931361,"l":27931362,"T":1626992769315,"m":true}}
1626992769.531496: {"stream":"keepusdt@depth@100ms","data":{"e":"depthUpdate","E":1626992769485,"T":1626992769380,"s":"KEEPUSDT","U":600860379624,"u":600860379625,"pu":600860374262,"b":[],"a":[["0.2476","19021"],["0.2510","15356"]]}}
1626992769.568463: {"stream":"ctkusdt@depth@100ms","data":{"e":"depthUpdate","E":1626992769523,"T":1626992769512,"s":"CTKUSDT","U":600860381046,"u":600860384439,"pu":600860379679,"b":[["1.00600","9967"]],"a":[["1.01200","22175"],["1.01400","13951"],["1.01500","16542"],["1.01600","21071"]]}}
1626992769.580278: {"stream":"akrousdt@depth@100ms","data":{"e":"depthUpdate","E":1626992769534,"T":1626992769521,"s":"AKROUSDT","U":600860381449,"u":600860384796,"pu":600860380924,"b":[["0.01697","462788"],["0.01700","468431"],["0.01704","73359"],["0.01707","1200446"],["0.01709","363833"],["0.01711","699741"],["0.01713","16011"],["0.01714","1488366"],["0.01716","564157"],["0.01718","225373"],["0.01720","593900"],["0.01733","44695"]],"a":[["0.01736","303832"],["0.01737","771502"],["0.01739","371853"],["0.01741","1270944"],["0.01742","433426"]]}}
1626992769.58053: {"stream":"sushiusdt@depth@100ms","data":{"e":"depthUpdate","E":1626992769534,"T":1626992769519,"s":"SUSHIUSDT","U":600860381385,"u":600860384748,"pu":600860379645,"b":[["6.1010","6480"],["6.4920","1621"],["7.1810","643"],["7.5470","2861"],["7.5510","688"],["7.6000","2040"],["7.6090","357"]],"a":[["7.6190","2432"],["7.6210","1722"]]}}
1626992769.6718478: {"stream":"ctkusdt@depth@100ms","data":{"e":"depthUpdate","E":1626992769626,"T":1626992769600,"s":"CTKUSDT","U":600860384821,"u":600860387305,"pu":600860384439,"b":[["0.98600","5128"],["1.00300","9005"]],"a":[["1.05200","13127"]]}}
1626992769.696594: {"stream":"akrousdt@depth@100ms","data":{"e":"depthUpdate","E":1626992769651,"T":1626992769643,"s":"AKROUSDT","U":600860385671,"u":600860388703,"pu":600860384796,"b":[["0.01729","421756"],["0.01730","417191"]],"a":[["0.01739","461285"],["0.01740","314707"],["0.01742","373839"]]}}
1626992769.7019851: {"stream":"keepusdt@depth@100ms","data":{"e":"depthUpdate","E":1626992769657,"T":1626992769647,"s":"KEEPUSDT","U":600860385867,"u":600860388866,"pu":600860379625,"b":[["0.2455","23574"],["0.2460","1358"]],"a":[["0.2468","406"],["0.2469","1939"],["0.2470","1573"]]}}
1626992769.713952: {"stream":"sushiusdt@depth@100ms","data":{"e":"depthUpdate","E":1626992769669,"T":1626992769659,"s":"SUSHIUSDT","U":600860386203,"u":600860389254,"pu":600860384748,"b":[["7.5070","1109"],["7.5860","1213"],["7.6040","1819"],["7.6110","45"]],"a":[["7.6320","1166"],["7.6430","2781"]]}}
1626992769.7721658: {"stream":"ctkusdt@depth@100ms","data":{"e":"depthUpdate","E":1626992769726,"T":1626992769718,"s":"CTKUSDT","U":600860387945,"u":600860391033,"pu":600860387305,"b":[["0.90900","575"],["1.00700","13279"],["1.00800","12743"]],"a":[["1.01200","22355"],["1.01300","11640"]]}}
1626992769.816183: {"stream":"akrousdt@bookTicker","data":{"e":"bookTicker","u":600860392269,"s":"AKROUSDT","b":"0.01734","B":"502","a":"0.01735","A":"86571","T":1626992769765,"E":1626992769770}}
1626992769.822582: {"stream":"akrousdt@depth@100ms","data":{"e":"depthUpdate","E":1626992769777,"T":1626992769765,"s":"AKROUSDT","U":600860389752,"u":600860392269,"pu":600860388703,"b":[["0.01717","267889"]],"a":[["0.01735","86571"],["0.01740","329127"],["0.01741","1291044"],["0.01742","433417"]]}}
1626992769.8279722: {"stream":"keepusdt@depth@100ms","data":{"e":"depthUpdate","E":1626992769783,"T":1626992769752,"s":"KEEPUSDT","U":600860389898,"u":600860391901,"pu":600860388866,"b":[["0.2442","10133"],["0.2447","448"],["0.2448","8856"],["0.2454","4675"],["0.2455","22896"]],"a":[]}}
1626992769.838691: {"stream":"sushiusdt@depth@100ms","data":{"e":"depthUpdate","E":1626992769794,"T":1626992769760,"s":"SUSHIUSDT","U":600860390265,"u":600860392137,"pu":600860389254,"b":[["7.6060","218"]],"a":[["7.6190","2564"]]}}
1626992769.919797: {"stream":"ctkusdt@depth@100ms","data":{"e":"depthUpdate","E":1626992769875,"T":1626992769769,"s":"CTKUSDT","U":600860392359,"u":600860392359,"pu":600860391033,"b":[["1.00300","9254"]],"a":[]}}
1626992769.9290009: {"stream":"akrousdt@depth@100ms","data":{"e":"depthUpdate","E":1626992769883,"T":1626992769834,"s":"AKROUSDT","U":600860392527,"u":600860394182,"pu":600860392269,"b":[["0.01729","299327"],["0.01730","539620"]],"a":[["0.01736","323806"],["0.01741","1331244"]]}}
1626992769.9358: {"stream":"keepusdt@depth@100ms","data":{"e":"depthUpdate","E":1626992769891,"T":1626992769787,"s":"KEEPUSDT","U":600860392720,"u":600860392756,"pu":600860391901,"b":[["0.2445","69676"],["0.2446","11676"]],"a":[]}}
1626992769.94441: {"stream":"ctkusdt@bookTicker","data":{"e":"bookTicker","u":600860395664,"s":"CTKUSDT","b":"1.01000","B":"76639","a":"1.01100","A":"80","T":1626992769895,"E":1626992769899}}
1626992769.9445262: {"stream":"ctkusdt@bookTicker","data":{"e":"bookTicker","u":600860395715,"s":"CTKUSDT","b":"1.01000","B":"76545","a":"1.01100","A":"80","T":1626992769896,"E":1626992769901}}
1626992769.953836: {"stream":"sushiusdt@depth@100ms","data":{"e":"depthUpdate","E":1626992769907,"T":1626992769874,"s":"SUSHIUSDT","U":600860393212,"u":600860395249,"pu":600860392137,"b":[["7.5950","1610"],["7.6030","2277"],["7.6070","1394"],["7.6090","357"]],"a":[["7.6260","1050"],["7.6440","824"],["7.6560","1817"]]}}
1626992770.043604: {"stream":"ctkusdt@depth@100ms","data":{"e":"depthUpdate","E":1626992769999,"T":1626992769896,"s":"CTKUSDT","U":600860395664,"u":600860395715,"pu":600860392359,"b":[["1.01000","76545"]],"a":[]}}
1626992770.063194: {"stream":"keepusdt@depth@100ms","data":{"e":"depthUpdate","E":1626992770017,"T":1626992770004,"s":"KEEPUSDT","U":600860396086,"u":600860398056,"pu":600860392756,"b":[["0.2457","9918"]],"a":[["0.2475","8598"],["0.2485","1811"]]}}
1626992770.0902941: {"stream":"sushiusdt@depth@100ms","data":{"e":"depthUpdate","E":1626992770045,"T":1626992770040,"s":"SUSHIUSDT","U":600860396615,"u":600860398899,"pu":600860395249,"b":[["7.5400","861"],["7.6030","750"],["7.6040","3165"],["7.6070","1824"]],"a":[["7.6170","289"],["7.6440","2294"],["7.6560","347"],["7.6620","380"]]}}
1626992770.12272: {"stream":"akrousdt@depth@100ms","data":{"e":"depthUpdate","E":1626992770078,"T":1626992769973,"s":"AKROUSDT","U":600860397442,"u":600860397442,"pu":600860394182,"b":[],"a":[["0.01786","381634"]]}}
1626992770.169334: {"stream":"ctkusdt@depth@100ms","data":{"e":"depthUpdate","E":1626992770123,"T":1626992770093,"s":"CTKUSDT","U":600860398399,"u":600860400960,"pu":600860395715,"b":[["1.00000","84417"],["1.00600","14915"],["1.00800","12751"],["1.00900","13862"]],"a":[]}}
1626992770.200583: {"stream":"sushiusdt@depth@100ms","data":{"e":"depthUpdate","E":1626992770156,"T":1626992770132,"s":"SUSHIUSDT","U":600860399246,"u":600860401403,"pu":600860398899,"b":[["7.6090","350"],["7.6100","209"],["7.6110","74"]],"a":[["7.6220","875"]]}}
1626992770.2247198: {"stream":"sushiusdt@bookTicker","data":{"e":"bookTicker","u":600860402198,"s":"SUSHIUSDT","b":"7.6120","B":"6","a":"7.6150","A":"117","T":1626992770174,"E":1626992770179}}
1626992770.2441878: {"stream":"sushiusdt@bookTicker","data":{"e":"bookTicker","u":600860403563,"s":"SUSHIUSDT","b":"7.6120","B":"6","a":"7.6140","A":"42","T":1626992770195,"E":1626992770199}}
1626992770.292326: {"stream":"ctkusdt@depth@100ms","data":{"e":"depthUpdate","E":1626992770249,"T":1626992770144,"s":"CTKUSDT","U":600860401699,"u":600860401699,"pu":600860400960,"b":[["1.00600","9967"]],"a":[]}}
1626992770.3062809: {"stream":"ctkusdt@bookTicker","data":{"e":"bookTicker","u":600860405841,"s":"CTKUSDT","b":"1.01000","B":"77174","a":"1.01100","A":"80","T":1626992770256,"E":1626992770261}}
1626992770.309438: {"stream":"sushiusdt@depth@100ms","data":{"e":"depthUpdate","E":1626992770263,"T":1626992770254,"s":"SUSHIUSDT","U":600860401998,"u":600860405758,"pu":600860401403,"b":[["7.5710","2035"],["7.5750","413"],["7.6010","3059"],["7.6030","820"],["7.6090","279"],["7.6100","178"],["7.6110","105"]],"a":[["7.6140","42"],["7.6160","286"],["7.6220","745"],["7.6230","2550"],["7.6240","3953"],["7.6310","4263"],["7.6320","1192"],["7.6360","4340"],["7.6440","824"]]}}
1626992770.3352342: {"stream":"akrousdt@depth@100ms","data":{"e":"depthUpdate","E":1626992770291,"T":1626992770277,"s":"AKROUSDT","U":600860402962,"u":600860406455,"pu":600860397442,"b":[],"a":[["0.01742","641946"],["0.01786","253035"],["0.01789","937475"]]}}
1626992770.337728: {"stream":"ctkusdt@kline_1m","data":{"e":"kline","E":1626992770292,"s":"CTKUSDT","k":{"t":1626992760000,"T":1626992819999,"s":"CTKUSDT","i":"1m","f":23961361,"L":23961396,"o":"1.01200","c":"1.01100","h":"1.01200","l":"1.01000","v":"9806","n":36,"x":false,"q":"9913.85400","V":"160","Q":"161.82000","B":"0"}}}
1626992770.337847: {"stream":"ctkusdt@bookTicker","data":{"e":"bookTicker","u":600860406610,"s":"CTKUSDT","b":"1.01100","B":"269","a":"1.01200","A":"22355","T":1626992770285,"E":1626992770291}}
1626992770.351274: {"stream":"ctkusdt@bookTicker","data":{"e":"bookTicker","u":600860406977,"s":"CTKUSDT","b":"1.01100","B":"269","a":"1.01200","A":"17055","T":1626992770301,"E":1626992770306}}
1626992770.3856409: {"stream":"ctkusdt@bookTicker","data":{"e":"bookTicker","u":600860407771,"s":"CTKUSDT","b":"1.01100","B":"269","a":"1.01200","A":"16264","T":1626992770335,"E":1626992770339}}
1626992770.387701: {"stream":"ctkusdt@bookTicker","data":{"e":"bookTicker","u":600860407793,"s":"CTKUSDT","b":"1.01100","B":"269","a":"1.01200","A":"15473","T":1626992770336,"E":1626992770341}}
1626992770.3932428: {"stream":"ctkusdt@bookTicker","data":{"e":"bookTicker","u":600860407975,"s":"CTKUSDT","b":"1.01100","B":"269","a":"1.01200","A":"14682","T":1626992770342,"E":1626992770346}}
1626992770.3933718: {"stream":"ctkusdt@bookTicker","data":{"e":"bookTicker","u":600860407981,"s":"CTKUSDT","b":"1.01100","B":"269","a":"1.01200","A":"13891","T":1626992770342,"E":1626992770346}}
1626992770.393704: {"stream":"akrousdt@bookTicker","data":{"e":"bookTicker","u":600860408095,"s":"AKROUSDT","b":"0.01734","B":"502","a":"0.01735","A":"50697","T":1626992770346,"E":1626992770350}}
1626992770.3984199: {"stream":"ctkusdt@bookTicker","data":{"e":"bookTicker","u":600860408146,"s":"CTKUSDT","b":"1.01100","B":"269","a":"1.01200","A":"13896","T":1626992770348,"E":1626992770352}}
1626992770.403907: {"stream":"ctkusdt@depth@100ms","data":{"e":"depthUpdate","E":1626992770358,"T":1626992770354,"s":"CTKUSDT","U":600860405682,"u":600860408302,"pu":600860401699,"b":[["1.00700","9279"],["1.00800","17761"],["1.01000","78749"],["1.01100","269"]],"a":[["1.01100","0"],["1.01200","13896"],["1.01300","13853"],["1.01400","13312"],["1.01500","17355"],["1.01600","21350"],["1.01700","7863"],["1.01800","7046"]]}}
1626992770.412193: {"stream":"ctkusdt@bookTicker","data":{"e":"bookTicker","u":600860408516,"s":"CTKUSDT","b":"1.01100","B":"269","a":"1.01200","A":"13105","T":1626992770362,"E":1626992770368}}
1626992770.41693: {"stream":"ctkusdt@aggTrade","data":{"e":"aggTrade","E":1626992770370,"a":16599328,"s":"CTKUSDT","p":"1.01100","q":"80","f":23961396,"l":23961396,"T":1626992770285,"m":false}}
1626992770.4170291: {"stream":"ctkusdt@bookTicker","data":{"e":"bookTicker","u":600860408588,"s":"CTKUSDT","b":"1.01100","B":"269","a":"1.01200","A":"13095","T":1626992770366,"E":1626992770370}}
1626992770.417079: {"stream":"ctkusdt@bookTicker","data":{"e":"bookTicker","u":600860408635,"s":"CTKUSDT","b":"1.01100","B":"269","a":"1.01200","A":"12304","T":1626992770369,"E":1626992770373}}
1626992770.427058: {"stream":"ctkusdt@bookTicker","data":{"e":"bookTicker","u":600860408826,"s":"CTKUSDT","b":"1.01100","B":"269","a":"1.01200","A":"10843","T":1626992770378,"E":1626992770382}}
1626992770.427161: {"stream":"sushiusdt@depth@100ms","data":{"e":"depthUpdate","E":1626992770383,"T":1626992770374,"s":"SUSHIUSDT","U":600860406494,"u":600860408754,"pu":600860405758,"b":[["7.5450","1848"],["7.5460","1179"],["7.5940","4433"],["7.5980","4929"],["7.6090","272"]],"a":[["7.6240","2972"],["7.6250","2293"],["7.6300","4823"],["7.6330","2787"],["7.6340","1760"],["7.6360","2575"],["7.6380","824"],["7.6510","1848"],["7.6810","704"],["7.6820","1050"],["7.7060","508"],["7.7080","1979"]]}}
1626992770.4816608: {"stream":"ctkusdt@bookTicker","data":{"e":"bookTicker","u":600860410454,"s":"CTKUSDT","b":"1.01100","B":"1069","a":"1.01200","A":"10843","T":1626992770432,"E":1626992770436}}
1626992770.494386: {"stream":"akrousdt@depth@100ms","data":{"e":"depthUpdate","E":1626992770450,"T":1626992770420,"s":"AKROUSDT","U":600860408095,"u":600860410064,"pu":600860406455,"b":[["0.01731","220319"]],"a":[["0.01735","50697"],["0.01736","359660"],["0.01737","795550"],["0.01738","653449"]]}}
1626992770.504821: {"stream":"ctkusdt@depth@100ms","data":{"e":"depthUpdate","E":1626992770459,"T":1626992770448,"s":"CTKUSDT","U":600860408350,"u":600860410848,"pu":600860408302,"b":[["1.00600","9719"],["1.01000","79539"],["1.01100","1069"],["1.01500","0"]],"a":[["1.01200","10843"],["1.01400","16351"],["1.01500","16486"],["1.01600","26293"],["1.01700","8338"]]}}
1626992770.505285: {"stream":"keepusdt@depth@100ms","data":{"e":"depthUpdate","E":1626992770462,"T":1626992770412,"s":"KEEPUSDT","U":600860408443,"u":600860409799,"pu":600860398056,"b":[["0.2456","14400"],["0.2458","8434"]],"a":[["0.2477","19045"],["0.2479","107347"]]}}
1626992770.534153: {"stream":"sushiusdt@depth@100ms","data":{"e":"depthUpdate","E":1626992770487,"T":1626992770474,"s":"SUSHIUSDT","U":600860408928,"u":600860411470,"pu":600860408754,"b":[["7.5840","4373"],["7.5890","1175"],["7.5910","2807"],["7.6090","279"]],"a":[["7.6170","209"],["7.6240","1860"],["7.6250","3643"],["7.6330","2885"],["7.6370","2085"],["7.6450","1355"],["7.6610","996"]]}}
1626992770.566407: {"stream":"ctkusdt@aggTrade","data":{"e":"aggTrade","E":1626992770521,"a":16599329,"s":"CTKUSDT","p":"1.01200","q":"10","f":23961397,"l":23961397,"T":1626992770366,"m":false}}
1626992770.6170828: {"stream":"ctkusdt@depth@100ms","data":{"e":"depthUpdate","E":1626992770573,"T":1626992770561,"s":"CTKUSDT","U":600860411364,"u":600860414086,"pu":600860410848,"b":[["1.00500","33595"],["1.00600","9259"]],"a":[["1.01300","13912"],["1.01400","17004"],["1.01500","16031"],["1.01600","21350"],["1.01700","8011"],["1.06500","1167"],["1.10500","130"],["1.25800","2286"],["1.31400","0"]]}}
1626992770.633996: {"stream":"sushiusdt@depth@100ms","data":{"e":"depthUpdate","E":1626992770589,"T":1626992770548,"s":"SUSHIUSDT","U":600860411803,"u":600860413738,"pu":600860411470,"b":[["7.5770","500"],["7.5810","365"],["7.5860","1239"],["7.6040","2444"],["7.6060","186"],["7.6070","1792"],["7.6080","1308"]],"a":[["7.6160","318"],["7.6220","820"],["7.6450","1441"],["7.6480","430"],["7.6490","10001"]]}}
1626992770.640859: {"stream":"keepusdt@depth@100ms","data":{"e":"depthUpdate","E":1626992770596,"T":1626992770491,"s":"KEEPUSDT","U":600860411997,"u":600860411997,"pu":600860409799,"b":[],"a":[["0.2484","16003"]]}}
1626992770.648756: {"stream":"akrousdt@depth@100ms","data":{"e":"depthUpdate","E":1626992770603,"T":1626992770573,"s":"AKROUSDT","U":600860412201,"u":600860414336,"pu":600860410064,"b":[["0.01712","961738"],["0.01716","567075"],["0.01717","265851"],["0.01720","595937"],["0.01729","288317"]],"a":[["0.01737","771502"]]}}
1626992770.702488: {"stream":"sushiusdt@bookTicker","data":{"e":"bookTicker","u":600860416195,"s":"SUSHIUSDT","b":"7.6120","B":"98","a":"7.6140","A":"42","T":1626992770652,"E":1626992770657}}
1626992770.7344341: {"stream":"ctkusdt@depth@100ms","data":{"e":"depthUpdate","E":1626992770688,"T":1626992770633,"s":"CTKUSDT","U":600860414515,"u":600860415721,"pu":600860414086,"b":[["0.98700","17246"],["1.00000","84817"],["1.00500","32936"],["1.00600","9918"],["1.00900","14632"]],"a":[["1.01400","16351"],["1.01500","16684"],["1.01600","21546"]]}}
1626992770.737608: {"stream":"sushiusdt@bookTicker","data":{"e":"bookTicker","u":600860416871,"s":"SUSHIUSDT","b":"7.6120","B":"98","a":"7.6160","A":"318","T":1626992770688,"E":1626992770692}}
1626992770.747124: {"stream":"sushiusdt@depth@100ms","data":{"e":"depthUpdate","E":1626992770702,"T":1626992770690,"s":"SUSHIUSDT","U":600860414773,"u":600860416890,"pu":600860413738,"b":[["7.5880","1906"],["7.6090","279"],["7.6120","98"]],"a":[["7.6140","0"],["7.6150","0"],["7.6170","189"],["7.6230","2680"],["7.6240","1730"],["7.6410","2699"]]}}
1626992770.7558231: {"stream":"sushiusdt@bookTicker","data":{"e":"bookTicker","u":600860417237,"s":"SUSHIUSDT","b":"7.6120","B":"303","a":"7.6160","A":"318","T":1626992770707,"E":1626992770713}}
1626992770.7590022: {"stream":"sushiusdt@bookTicker","data":{"e":"bookTicker","u":600860417386,"s":"SUSHIUSDT","b":"7.6120","B":"303","a":"7.6160","A":"286","T":1626992770713,"E":1626992770715}}
1626992770.77835: {"stream":"sushiusdt@bookTicker","data":{"e":"bookTicker","u":600860417749,"s":"SUSHIUSDT","b":"7.6120","B":"303","a":"7.6160","A":"267","T":1626992770728,"E":1626992770735}}
1626992770.819266: {"stream":"ctkusdt@bookTicker","data":{"e":"bookTicker","u":600860418636,"s":"CTKUSDT","b":"1.01100","B":"1698","a":"1.01200","A":"10843","T":1626992770770,"E":1626992770774}}
1626992770.825095: {"stream":"akrousdt@depth@100ms","data":{"e":"depthUpdate","E":1626992770780,"T":1626992770676,"s":"AKROUSDT","U":600860416646,"u":600860416646,"pu":600860414336,"b":[],"a":[["0.01776","60486"]]}}
1626992770.8308852: {"stream":"keepusdt@depth@100ms","data":{"e":"depthUpdate","E":1626992770785,"T":1626992770726,"s":"KEEPUSDT","U":600860416749,"u":600860417705,"pu":600860411997,"b":[["0.2408","408"],["0.2417","1233"],["0.2431","1229"],["0.2437","16381"],["0.2439","29431"],["0.2443","6262"],["0.2445","67406"],["0.2449","16873"],["0.2451","6649"]],"a":[]}}
1626992770.835161: {"stream":"ctkusdt@bookTicker","data":{"e":"bookTicker","u":600860419015,"s":"CTKUSDT","b":"1.01100","B":"1698","a":"1.01200","A":"10123","T":1626992770784,"E":1626992770789}}
1626992770.849233: {"stream":"sushiusdt@depth@100ms","data":{"e":"depthUpdate","E":1626992770804,"T":1626992770795,"s":"SUSHIUSDT","U":600860417058,"u":600860419272,"pu":600860416890,"b":[["7.5920","1930"],["7.5940","4463"],["7.6020","1589"],["7.6030","1471"],["7.6040","2514"],["7.6050","1300"],["7.6060","1074"],["7.6080","1293"],["7.6090","294"],["7.6120","303"]],"a":[["7.6160","267"],["7.6170","242"],["7.6180","1152"],["7.6190","1038"],["7.6200","1136"],["7.6210","3248"],["7.6220","1144"],["7.6230","2356"],["7.6260","1055"],["7.6520","3664"]]}}
1626992770.849484: {"stream":"ctkusdt@depth@100ms","data":{"e":"depthUpdate","E":1626992770806,"T":1626992770784,"s":"CTKUSDT","U":600860417133,"u":600860419015,"pu":600860415721,"b":[["1.00500","33595"],["1.00600","9259"],["1.01000","78910"],["1.01100","1698"]],"a":[["1.01200","10123"],["1.01400","17004"],["1.01500","15834"]]}}
1626992770.928054: {"stream":"akrousdt@depth@100ms","data":{"e":"depthUpdate","E":1626992770881,"T":1626992770775,"s":"AKROUSDT","U":600860418751,"u":600860418751,"pu":600860416646,"b":[],"a":[["0.01739","450336"]]}}
1626992770.957921: {"stream":"sushiusdt@depth@100ms","data":{"e":"depthUpdate","E":1626992770913,"T":1626992770878,"s":"SUSHIUSDT","U":600860419673,"u":600860421380,"pu":600860419272,"b":[["7.6030","1339"],["7.6060","916"],["7.6080","1421"]],"a":[["7.6170","261"],["7.6180","1133"],["7.6200","2662"],["7.6210","1722"],["7.6220","820"],["7.6240","1862"],["7.6560","1817"],["7.8440","190"]]}}
1626992770.978262: {"stream":"ctkusdt@depth@100ms","data":{"e":"depthUpdate","E":1626992770931,"T":1626992770883,"s":"CTKUSDT","U":600860420145,"u":600860421470,"pu":600860419015,"b":[["0.98900","2284"],["0.99900","9777"],["1.00700","14222"]],"a":[["1.01600","21350"],["1.22600","4809"]]}}
1626992770.9810581: {"stream":"keepusdt@depth@100ms","data":{"e":"depthUpdate","E":1626992770935,"T":1626992770831,"s":"KEEPUSDT","U":600860420312,"u":600860420312,"pu":600860417705,"b":[["0.2442","10174"]],"a":[]}}
1626992771.044234: {"stream":"akrousdt@depth@100ms","data":{"e":"depthUpdate","E":1626992770999,"T":1626992770988,"s":"AKROUSDT","U":600860421742,"u":600860423964,"pu":600860418751,"b":[["0.01718","227117"]],"a":[["0.01779","217382"]]}}
1626992771.088487: {"stream":"sushiusdt@depth@100ms","data":{"e":"depthUpdate","E":1626992771042,"T":1626992771036,"s":"SUSHIUSDT","U":600860422707,"u":600860425198,"pu":600860421380,"b":[["7.5790","712"],["7.6040","3171"],["7.6090","294"]],"a":[["7.6230","2226"],["7.6240","1992"],["7.6410","3430"],["7.6470","2247"],["7.6490","8501"]]}}
1626992771.0886679: {"stream":"ctkusdt@depth@100ms","data":{"e":"depthUpdate","E":1626992771044,"T":1626992770956,"s":"CTKUSDT","U":600860422819,"u":600860423222,"pu":600860421470,"b":[["1.00700","10499"]],"a":[["1.01400","17280"]]}}
1626992771.201806: {"stream":"sushiusdt@bookTicker","data":{"e":"bookTicker","u":600860427282,"s":"SUSHIUSDT","b":"7.6120","B":"303","a":"7.6150","A":"56","T":1626992771149,"E":1626992771154}}
