1626916409.737151: {"stream":"bchusd_210924@depth@100ms","data":{"e":"depthUpdate","E":1626916409762,"T":1626916409659,"s":"BCHUSD_210924","ps":"BCHUSD","U":167006140048,"u":167006140056,"pu":167006139008,"b":[],"a":[["429.73","1508"],["429.79","0"]]}}
1626916409.737309: {"stream":"linkusd_perp@depth@100ms","data":{"e":"depthUpdate","E":1626916409764,"T":1626916409727,"s":"LINKUSD_PERP","ps":"LINKUSD","U":167006140054,"u":167006140415,"pu":167006139998,"b":[["15.049","29"],["15.051","1767"],["15.052","551"],["15.053","4699"]],"a":[["15.065","100"],["15.074","127"],["15.076","878"],["15.090","401"],["15.117","500"],["15.120","1600"]]}}
1626916409.767135: {"stream":"eosusd_perp@depth@100ms","data":{"e":"depthUpdate","E":1626916409793,"T":1626916409782,"s":"EOSUSD_PERP","ps":"EOSUSD","U":167006140230,"u":167006140598,"pu":167006140038,"b":[["3.449","941"],["3.451","4072"]],"a":[["3.483","853"],["3.485","5341"],["3.486","437"]]}}
1626916409.770151: {"stream":"btcusd_211231@depth@100ms","data":{"e":"depthUpdate","E":1626916409798,"T":1626916409728,"s":"BTCUSD_211231","ps":"BTCUSD","U":167006140250,"u":167006140416,"pu":167006139617,"b":[["32494.0","2344"],["32517.1","0"],["32592.3","20"]],"a":[["32623.4","17"]]}}
1626916409.799221: {"stream":"xrpusd_perp@depth@100ms","data":{"e":"depthUpdate","E":1626916409826,"T":1626916409810,"s":"XRPUSD_PERP","ps":"XRPUSD","U":167006140400,"u":167006140708,"pu":167006140315,"b":[["0.5642","2025"],["0.5653","12558"],["0.5657","5687"],["0.5658","1950"],["0.5660","5936"]],"a":[["0.5664","5935"],["0.5666","694"],["0.5668","7639"],["0.5671","3514"],["0.5672","9098"],["0.5681","2621"],["0.5682","14513"]]}}
1626916409.8168: {"stream":"ethusd_210924@depth@100ms","data":{"e":"depthUpdate","E":1626916409843,"T":1626916409810,"s":"ETHUSD_210924","ps":"ETHUSD","U":167006140448,"u":167006140697,"pu":167006140422,"b":[["1987.20","401"],["1989.70","1500"],["1989.83","0"],["1990.20","280"],["1990.98","1849"]],"a":[["1991.60","400"],["1992.29","280"],["1992.55","0"],["1992.69","12241"],["1994.64","4121"]]}}
1626916409.831608: {"stream":"bchusd_perp@depth@100ms","data":{"e":"depthUpdate","E":1626916409859,"T":1626916409754,"s":"BCHUSD_PERP","ps":"BCHUSD","U":167006140509,"u":167006140509,"pu":167006140184,"b":[["427.77","174"]],"a":[]}}
1626916409.8483782: {"stream":"etcusd_perp@depth@100ms","data":{"e":"depthUpdate","E":1626916409875,"T":1626916409869,"s":"ETCUSD_PERP","ps":"ETCUSD","U":167006140561,"u":167006140972,"pu":167006140284,"b":[["42.233","500"],["42.235","1085"]],"a":[["42.255","5"]]}}
1626916409.8662531: {"stream":"trxusd_perp@depth@100ms","data":{"e":"depthUpdate","E":1626916409894,"T":1626916409880,"s":"TRXUSD_PERP","ps":"TRXUSD","U":167006140628,"u":167006141047,"pu":167006140489,"b":[["0.05339","1333"],["0.05341","1794"]],"a":[["0.05349","1122"]]}}
1626916409.871878: {"stream":"linkusd_211231@depth@100ms","data":{"e":"depthUpdate","E":1626916409897,"T":1626916409854,"s":"LINKUSD_211231","ps":"LINKUSD","U":167006140635,"u":167006140917,"pu":167006140014,"b":[["14.760","1122"],["14.836","100"],["14.911","100"],["14.986","100"],["15.062","100"],["15.290","0"],["15.293","123"]],"a":[]}}
1626916409.876317: {"stream":"linkusd_perp@depth@100ms","data":{"e":"depthUpdate","E":1626916409903,"T":1626916409886,"s":"LINKUSD_PERP","ps":"LINKUSD","U":167006140646,"u":167006141077,"pu":167006140415,"b":[["15.044","966"],["15.056","1562"],["15.058","471"]],"a":[["15.075","844"],["15.076","424"],["15.079","1561"],["15.090","209"]]}}
1626916409.8909361: {"stream":"eosusd_perp@depth@100ms","data":{"e":"depthUpdate","E":1626916409918,"T":1626916409906,"s":"EOSUSD_PERP","ps":"EOSUSD","U":167006140723,"u":167006141192,"pu":167006140598,"b":[["3.463","1945"],["3.465","5011"],["3.468","0"]],"a":[["3.470","2708"],["3.471","4014"],["3.485","5427"]]}}
1626916409.901224: {"stream":"xrpusd_perp@depth@100ms","data":{"e":"depthUpdate","E":1626916409927,"T":1626916409856,"s":"XRPUSD_PERP","ps":"XRPUSD","U":167006140744,"u":167006140934,"pu":167006140708,"b":[["0.5627","0"],["0.5629","10060"]],"a":[]}}
1626916409.939739: {"stream":"bchusd_perp@depth@100ms","data":{"e":"depthUpdate","E":1626916409968,"T":1626916409920,"s":"BCHUSD_PERP","ps":"BCHUSD","U":167006140954,"u":167006141253,"pu":167006140509,"b":[["427.77","150"]],"a":[["428.04","2018"],["428.11","100"],["434.97","0"]]}}
1626916409.940407: {"stream":"ethusd_210924@depth@100ms","data":{"e":"depthUpdate","E":1626916409968,"T":1626916409863,"s":"ETHUSD_210924","ps":"ETHUSD","U":167006140957,"u":167006140957,"pu":167006140697,"b":[["1990.36","1023"]],"a":[]}}
1626916409.946822: {"stream":"bchusd_210924@depth@100ms","data":{"e":"depthUpdate","E":1626916409974,"T":1626916409875,"s":"BCHUSD_210924","ps":"BCHUSD","U":167006140973,"u":167006141018,"pu":167006140056,"b":[],"a":[["429.72","120"],["429.73","1388"]]}}
1626916409.967079: {"stream":"etcusd_perp@depth@100ms","data":{"e":"depthUpdate","E":1626916409994,"T":1626916409961,"s":"ETCUSD_PERP","ps":"ETCUSD","U":167006141095,"u":167006141439,"pu":167006140972,"b":[],"a":[["42.279","1241"],["42.311","25"],["42.318","1137"]]}}
1626916409.975559: {"stream":"trxusd_perp@depth@100ms","data":{"e":"depthUpdate","E":1626916410003,"T":1626916409956,"s":"TRXUSD_PERP","ps":"TRXUSD","U":167006141154,"u":167006141412,"pu":167006141047,"b":[["0.05341","1714"],["0.05343","1220"]],"a":[["0.05348","635"],["0.05349","922"],["0.05350","3083"],["0.05351","2524"]]}}
1626916409.9830668: {"stream":"linkusd_perp@depth@100ms","data":{"e":"depthUpdate","E":1626916410010,"T":1626916409973,"s":"LINKUSD_PERP","ps":"LINKUSD","U":167006141185,"u":167006141484,"pu":167006141077,"b":[["15.046","1074"],["15.050","260"],["15.052","751"]],"a":[["15.093","1862"]]}}
1626916409.987734: {"stream":"btcusd_211231@depth@100ms","data":{"e":"depthUpdate","E":1626916410014,"T":1626916409909,"s":"BTCUSD_211231","ps":"BTCUSD","U":167006141199,"u":167006141200,"pu":167006140416,"b":[],"a":[["32625.8","153"],["32628.4","0"]]}}
1626916409.992456: {"stream":"eosusd_perp@depth@100ms","data":{"e":"depthUpdate","E":1626916410018,"T":1626916410011,"s":"EOSUSD_PERP","ps":"EOSUSD","U":167006141222,"u":167006141687,"pu":167006141192,"b":[["3.463","1887"],["3.466","5396"],["3.468","0"]],"a":[]}}
1626916410.003964: {"stream":"xrpusd_perp@depth@100ms","data":{"e":"depthUpdate","E":1626916410031,"T":1626916409977,"s":"XRPUSD_PERP","ps":"XRPUSD","U":167006141278,"u":167006141498,"pu":167006140934,"b":[["0.5656","9215"]],"a":[["0.5679","3485"],["0.5683","1118"]]}}
1626916410.078569: {"stream":"etcusd_perp@depth@100ms","data":{"e":"depthUpdate","E":1626916410105,"T":1626916410035,"s":"ETCUSD_PERP","ps":"ETCUSD","U":167006141630,"u":167006141768,"pu":167006141439,"b":[],"a":[["42.280","34"],["42.310","0"]]}}
1626916410.092254: {"stream":"linkusd_perp@depth@100ms","data":{"e":"depthUpdate","E":1626916410117,"T":1626916410107,"s":"LINKUSD_PERP","ps":"LINKUSD","U":167006141690,"u":167006142079,"pu":167006141484,"b":[["15.045","105"],["15.050","460"],["15.052","551"]],"a":[["15.066","0"],["15.067","0"],["15.069","2186"],["15.071","659"]]}}
1626916410.10396: {"stream":"eosusd_perp@depth@100ms","data":{"e":"depthUpdate","E":1626916410128,"T":1626916410097,"s":"EOSUSD_PERP","ps":"EOSUSD","U":167006141733,"u":167006142031,"pu":167006141687,"b":[["3.463","1807"],["3.465","5091"],["3.468","0"]],"a":[["3.479","3227"]]}}
1626916410.1196811: {"stream":"ethusd_210924@depth@100ms","data":{"e":"depthUpdate","E":1626916410147,"T":1626916410122,"s":"ETHUSD_210924","ps":"ETHUSD","U":167006141796,"u":167006142140,"pu":167006140957,"b":[["1990.60","0"],["1990.82","270"],["1990.98","1579"]],"a":[["1991.17","176"],["1991.18","500"]]}}
1626916410.13804: {"stream":"xrpusd_perp@depth@100ms","data":{"e":"depthUpdate","E":1626916410165,"T":1626916410137,"s":"XRPUSD_PERP","ps":"XRPUSD","U":167006141849,"u":167006142223,"pu":167006141498,"b":[["0.5658","2297"],["0.5659","1420"],["0.5660","5966"],["0.5661","3862"]],"a":[["0.5662","2191"],["0.5666","890"],["0.5677","1113"]]}}
1626916410.140237: {"stream":"btcusd_211231@depth@100ms","data":{"e":"depthUpdate","E":1626916410169,"T":1626916410163,"s":"BTCUSD_211231","ps":"BTCUSD","U":167006141861,"u":167006142357,"pu":167006141200,"b":[["32526.6","0"],["32526.8","1172"],["32618.5","33"]],"a":[["32625.8","153"],["32628.4","0"]]}}
1626916410.144246: {"stream":"bchusd_perp@depth@100ms","data":{"e":"depthUpdate","E":1626916410172,"T":1626916410106,"s":"BCHUSD_PERP","ps":"BCHUSD","U":167006141864,"u":167006142073,"pu":167006141253,"b":[["427.56","298"],["427.62","777"],["427.65","562"],["427.77","174"]],"a":[["434.20","41"]]}}
1626916410.165268: {"stream":"linkusd_211231@depth@100ms","data":{"e":"depthUpdate","E":1626916410193,"T":1626916410152,"s":"LINKUSD_211231","ps":"LINKUSD","U":167006141995,"u":167006142290,"pu":167006140917,"b":[["15.300","52"]],"a":[["15.323","0"],["15.325","1341"],["15.525","0"],["15.600","38"],["15.675","0"],["15.751","0"],["15.826","0"]]}}
1626916410.207125: {"stream":"linkusd_perp@depth@100ms","data":{"e":"depthUpdate","E":1626916410232,"T":1626916410200,"s":"LINKUSD_PERP","ps":"LINKUSD","U":167006142169,"u":167006142528,"pu":167006142079,"b":[],"a":[["15.065","0"],["15.066","100"],["15.067","89"],["15.068","150"]]}}
1626916410.2073238: {"stream":"bchusd_210924@depth@100ms","data":{"e":"depthUpdate","E":1626916410232,"T":1626916410127,"s":"BCHUSD_210924","ps":"BCHUSD","U":167006142168,"u":167006142172,"pu":167006141018,"b":[],"a":[["429.76","27"],["429.82","2899"]]}}
1626916410.2371142: {"stream":"xrpusd_perp@depth@100ms","data":{"e":"depthUpdate","E":1626916410265,"T":1626916410224,"s":"XRPUSD_PERP","ps":"XRPUSD","U":167006142314,"u":167006142622,"pu":167006142223,"b":[["0.5656","9109"],["0.5657","5793"]],"a":[["0.5708","117"],["0.5729","448"],["0.5737","0"]]}}
1626916410.2426612: {"stream":"btcusd_211231@depth@100ms","data":{"e":"depthUpdate","E":1626916410270,"T":1626916410243,"s":"BTCUSD_211231","ps":"BTCUSD","U":167006142363,"u":167006142705,"pu":167006142357,"b":[],"a":[["32625.8","153"],["32628.4","0"],["32638.5","220"]]}}
1626916410.249451: {"stream":"ethusd_210924@depth@100ms","data":{"e":"depthUpdate","E":1626916410275,"T":1626916410208,"s":"ETHUSD_210924","ps":"ETHUSD","U":167006142383,"u":167006142549,"pu":167006142140,"b":[["1976.61","0"],["1990.82","0"],["1990.98","1849"]],"a":[["1997.42","1198"]]}}
1626916410.25707: {"stream":"eosusd_perp@depth@100ms","data":{"e":"depthUpdate","E":1626916410282,"T":1626916410274,"s":"EOSUSD_PERP","ps":"EOSUSD","U":167006142418,"u":167006142840,"pu":167006142031,"b":[["3.452","5723"],["3.454","4978"]],"a":[]}}
1626916410.338211: {"stream":"etcusd_perp@depth@100ms","data":{"e":"depthUpdate","E":1626916410346,"T":1626916410266,"s":"ETCUSD_PERP","ps":"ETCUSD","U":167006142687,"u":167006142787,"pu":167006141768,"b":[["42.245","0"],["42.246","300"],["42.254","80"]],"a":[["42.278","1038"]]}}
1626916410.3470001: {"stream":"xrpusd_perp@depth@100ms","data":{"e":"depthUpdate","E":1626916410374,"T":1626916410362,"s":"XRPUSD_PERP","ps":"XRPUSD","U":167006142811,"u":167006143265,"pu":167006142622,"b":[["0.5656","8924"],["0.5657","5953"],["0.5659","1648"],["0.5660","5806"]],"a":[["0.5701","1544"]]}}
1626916410.34956: {"stream":"ethusd_210924@depth@100ms","data":{"e":"depthUpdate","E":1626916410376,"T":1626916410360,"s":"ETHUSD_210924","ps":"ETHUSD","U":167006142823,"u":167006143254,"pu":167006142549,"b":[],"a":[["1992.86","0"],["2008.42","0"],["2011.83","4879"],["2014.26","0"]]}}
1626916410.377734: {"stream":"btcusd_211231@depth@100ms","data":{"e":"depthUpdate","E":1626916410403,"T":1626916410398,"s":"BTCUSD_211231","ps":"BTCUSD","U":167006142948,"u":167006143439,"pu":167006142705,"b":[["32129.4","0"],["32620.2","0"]],"a":[["33027.1","45"],["33187.1","45"],["33347.1","45"],["33507.1","46"],["33667.1","46"],["33667.2","0"]]}}
1626916410.3779478: {"stream":"eosusd_perp@depth@100ms","data":{"e":"depthUpdate","E":1626916410405,"T":1626916410393,"s":"EOSUSD_PERP","ps":"EOSUSD","U":167006142964,"u":167006143417,"pu":167006142840,"b":[["3.461","2239"],["3.462","4102"],["3.464","6571"],["3.466","7512"],["3.468","0"]],"a":[["3.469","1206"],["3.471","4976"],["3.472","5164"],["3.479","3328"]]}}
1626916410.385947: {"stream":"bchusd_perp@depth@100ms","data":{"e":"depthUpdate","E":1626916410414,"T":1626916410389,"s":"BCHUSD_PERP","ps":"BCHUSD","U":167006143022,"u":167006143391,"pu":167006142073,"b":[["424.92","0"],["427.61","0"],["427.66","127"],["427.77","150"]],"a":[["432.71","0"]]}}
1626916410.438231: {"stream":"etcusd_perp@depth@100ms","data":{"e":"depthUpdate","E":1626916410464,"T":1626916410358,"s":"ETCUSD_PERP","ps":"ETCUSD","U":167006143244,"u":167006143244,"pu":167006142787,"b":[["42.240","233"]],"a":[]}}
1626916410.466951: {"stream":"linkusd_211231@depth@100ms","data":{"e":"depthUpdate","E":1626916410493,"T":1626916410387,"s":"LINKUSD_211231","ps":"LINKUSD","U":167006143379,"u":167006143379,"pu":167006142290,"b":[],"a":[["15.327","0"]]}}
1626916410.47053: {"stream":"ethusd_210924@depth@100ms","data":{"e":"depthUpdate","E":1626916410496,"T":1626916410473,"s":"ETHUSD_210924","ps":"ETHUSD","U":167006143398,"u":167006143843,"pu":167006143254,"b":[["1988.94","0"],["1989.03","8323"],["1989.04","0"],["1989.89","50"],["1990.22","0"],["1990.46","0"],["1990.60","0"],["1990.82","270"],["1990.98","1579"]],"a":[["1992.28","322"],["1992.29","581"],["1992.55","384"],["1992.71","0"],["1993.22","0"],["1993.67","0"],["2005.85","4865"]]}}
1626916410.47086: {"stream":"xrpusd_perp@depth@100ms","data":{"e":"depthUpdate","E":1626916410498,"T":1626916410467,"s":"XRPUSD_PERP","ps":"XRPUSD","U":167006143406,"u":167006143809,"pu":167006143265,"b":[["0.5657","5953"],["0.5659","1648"]],"a":[]}}
1626916410.473877: {"stream":"linkusd_perp@depth@100ms","data":{"e":"depthUpdate","E":1626916410500,"T":1626916410493,"s":"LINKUSD_PERP","ps":"LINKUSD","U":167006143424,"u":167006143964,"pu":167006142528,"b":[["15.030","854"],["15.052","751"],["15.053","4419"],["15.054","380"]],"a":[["15.066","0"],["15.067","100"],["15.069","1299"],["15.070","6777"],["15.071","959"],["15.073","536"],["15.075","944"]]}}
1626916410.485303: {"stream":"btcusd_211231@depth@100ms","data":{"e":"depthUpdate","E":1626916410511,"T":1626916410483,"s":"BTCUSD_211231","ps":"BTCUSD","U":167006143479,"u":167006143907,"pu":167006143439,"b":[["32526.7","0"],["32526.9","629"]],"a":[["32625.8","0"],["32628.4","0"],["32638.4","153"],["32691.4","0"],["32707.7","381"]]}}
1626916410.485533: {"stream":"eosusd_perp@depth@100ms","data":{"e":"depthUpdate","E":1626916410511,"T":1626916410505,"s":"EOSUSD_PERP","ps":"EOSUSD","U":167006143482,"u":167006144020,"pu":167006143417,"b":[["3.460","2848"],["3.466","9412"],["3.468","0"]],"a":[]}}
1626916410.49867: {"stream":"bchusd_perp@depth@100ms","data":{"e":"depthUpdate","E":1626916410525,"T":1626916410511,"s":"BCHUSD_PERP","ps":"BCHUSD","U":167006143545,"u":167006144051,"pu":167006143391,"b":[["424.79","610"]],"a":[["428.94","0"]]}}
1626916410.504894: {"stream":"trxusd_perp@depth@100ms","data":{"e":"depthUpdate","E":1626916410531,"T":1626916410425,"s":"TRXUSD_PERP","ps":"TRXUSD","U":167006143578,"u":167006143580,"pu":167006141412,"b":[["0.05345","803"]],"a":[]}}
1626916410.56882: {"stream":"linkusd_211231@depth@100ms","data":{"e":"depthUpdate","E":1626916410596,"T":1626916410553,"s":"LINKUSD_211231","ps":"LINKUSD","U":167006143963,"u":167006144315,"pu":167006143379,"b":[["15.289","751"],["15.292","0"],["15.293","1278"]],"a":[["15.324","0"],["15.328","0"],["15.329","0"],["15.338","0"],["15.526","164"],["15.601","165"],["15.676","204"],["15.752","167"],["15.827","168"]]}}
1626916410.57682: {"stream":"linkusd_perp@depth@100ms","data":{"e":"depthUpdate","E":1626916410603,"T":1626916410598,"s":"LINKUSD_PERP","ps":"LINKUSD","U":167006143981,"u":167006144581,"pu":167006143964,"b":[["14.956","3000"],["15.030","662"],["15.052","851"],["15.054","380"],["15.057","506"],["15.061","1166"]],"a":[["15.070","4214"],["15.071","2949"],["15.073","385"],["15.074","17"],["15.075","1254"],["15.078","861"]]}}
1626916410.577019: {"stream":"bchusd_210924@depth@100ms","data":{"e":"depthUpdate","E":1626916410603,"T":1626916410506,"s":"BCHUSD_210924","ps":"BCHUSD","U":167006143977,"u":167006144034,"pu":167006142172,"b":[],"a":[["429.81","246"],["429.91","0"]]}}
1626916410.5877361: {"stream":"etcusd_perp@depth@100ms","data":{"e":"depthUpdate","E":1626916410614,"T":1626916410568,"s":"ETCUSD_PERP","ps":"ETCUSD","U":167006144050,"u":167006144390,"pu":167006143244,"b":[],"a":[["42.336","425"],["42.390","3647"],["42.551","80"],["42.636","0"]]}}
1626916410.587938: {"stream":"ethusd_210924@depth@100ms","data":{"e":"depthUpdate","E":1626916410612,"T":1626916410580,"s":"ETHUSD_210924","ps":"ETHUSD","U":167006144037,"u":167006144462,"pu":167006143843,"b":[["1989.89","0"],["1990.12","1562"],["1990.21","314"],["1990.22","50"],["1990.60","270"],["1990.82","0"],["1990.98","1579"]],"a":[["1993.54","0"],["1993.84","314"],["2011.04","3416"]]}}
1626916410.599762: {"stream":"eosusd_perp@depth@100ms","data":{"e":"depthUpdate","E":1626916410626,"T":1626916410564,"s":"EOSUSD_PERP","ps":"EOSUSD","U":167006144108,"u":167006144367,"pu":167006144020,"b":[["3.461","1448"],["3.462","4602"],["3.463","2559"],["3.468","0"]],"a":[["3.471","5176"]]}}
1626916410.599926: {"stream":"bchusd_perp@depth@100ms","data":{"e":"depthUpdate","E":1626916410628,"T":1626916410572,"s":"BCHUSD_PERP","ps":"BCHUSD","U":167006144122,"u":167006144415,"pu":167006144051,"b":[["427.77","174"]],"a":[["428.02","1841"],["428.04","0"],["432.93","70"]]}}
1626916410.656172: {"stream":"btcusd_211231@depth@100ms","data":{"e":"depthUpdate","E":1626916410682,"T":1626916410659,"s":"BTCUSD_211231","ps":"BTCUSD","U":167006144443,"u":167006144934,"pu":167006143907,"b":[["32152.5","321"]],"a":[["32628.4","153"],["32629.7","0"],["32631.6","0"],["32638.4","0"],["32638.5","145"],["33407.8","0"]]}}
1626916410.6624231: {"stream":"xrpusd_perp@depth@100ms","data":{"e":"depthUpdate","E":1626916410690,"T":1626916410655,"s":"XRPUSD_PERP","ps":"XRPUSD","U":167006144498,"u":167006144904,"pu":167006143809,"b":[["0.5656","8660"],["0.5657","5793"],["0.5659","2136"],["0.5660","5806"]],"a":[["0.5663","4257"],["0.5666","1630"],["0.5667","6392"],["0.5731","734"]]}}
1626916410.6789389: {"stream":"linkusd_perp@depth@100ms","data":{"e":"depthUpdate","E":1626916410704,"T":1626916410674,"s":"LINKUSD_PERP","ps":"LINKUSD","U":167006144584,"u":167006145019,"pu":167006144581,"b":[["14.960","1036"],["15.017","306"],["15.033","15807"],["15.041","1143"],["15.044","892"],["15.047","3447"],["15.049","0"],["15.050","260"],["15.052","980"],["15.054","480"],["15.055","0"]],"a":[["15.073","285"],["15.074","168"],["15.075","1454"],["15.078","751"],["15.114","1225"]]}}
1626916410.691773: {"stream":"bchusd_210924@depth@100ms","data":{"e":"depthUpdate","E":1626916410718,"T":1626916410613,"s":"BCHUSD_210924","ps":"BCHUSD","U":167006144705,"u":167006144707,"pu":167006144034,"b":[],"a":[["429.87","5045"],["429.94","195"]]}}
1626916410.697299: {"stream":"ethusd_210924@depth@100ms","data":{"e":"depthUpdate","E":1626916410724,"T":1626916410710,"s":"ETHUSD_210924","ps":"ETHUSD","U":167006144760,"u":167006145194,"pu":167006144462,"b":[["1989.58","0"],["1989.96","2077"],["1990.60","0"],["1990.82","0"],["1990.98","1849"]],"a":[["1992.49","50"]]}}
1626916410.727191: {"stream":"trxusd_perp@depth@100ms","data":{"e":"depthUpdate","E":1626916410755,"T":1626916410720,"s":"TRXUSD_PERP","ps":"TRXUSD","U":167006144887,"u":167006145269,"pu":167006143580,"b":[["0.05307","696"],["0.05327","287"]],"a":[["0.05348","882"],["0.05366","1138"],["0.05386","628"]]}}
1626916410.7656991: {"stream":"linkusd_211231@depth@100ms","data":{"e":"depthUpdate","E":1626916410792,"T":1626916410730,"s":"LINKUSD_211231","ps":"LINKUSD","U":167006145078,"u":167006145305,"pu":167006144315,"b":[["15.293","123"],["15.294","1030"]],"a":[]}}
1626916410.775929: {"stream":"xrpusd_perp@depth@100ms","data":{"e":"depthUpdate","E":1626916410803,"T":1626916410788,"s":"XRPUSD_PERP","ps":"XRPUSD","U":167006145130,"u":167006145577,"pu":167006144904,"b":[["0.5657","5793"],["0.5659","1976"],["0.5660","5966"]],"a":[["0.5679","3130"],["0.5906","0"]]}}
1626916410.779125: {"stream":"btcusd_211231@depth@100ms","data":{"e":"depthUpdate","E":1626916410806,"T":1626916410799,"s":"BTCUSD_211231","ps":"BTCUSD","U":167006145155,"u":167006145629,"pu":167006144934,"b":[["31362.9","55"],["31522.9","55"],["31682.9","55"],["31842.9","55"],["32003.0","55"],["32526.8","0"],["32527.0","1296"]],"a":[["32623.4","16"],["32666.6","0"],["33463.1","334"]]}}
1626916410.785401: {"stream":"linkusd_perp@depth@100ms","data":{"e":"depthUpdate","E":1626916410812,"T":1626916410766,"s":"LINKUSD_PERP","ps":"LINKUSD","U":167006145176,"u":167006145462,"pu":167006145019,"b":[["14.961","12"],["15.021","528"],["15.037","2970"]],"a":[["15.170","360"]]}}
1626916410.80739: {"stream":"ethusd_210924@depth@100ms","data":{"e":"depthUpdate","E":1626916410836,"T":1626916410802,"s":"ETHUSD_210924","ps":"ETHUSD","U":167006145306,"u":167006145648,"pu":167006145194,"b":[["1989.96","0"],["1990.33","725"]],"a":[["1992.12","259"],["1995.05","500"]]}}
1626916410.807486: {"stream":"etcusd_perp@depth@100ms","data":{"e":"depthUpdate","E":1626916410836,"T":1626916410828,"s":"ETCUSD_PERP","ps":"ETCUSD","U":167006145308,"u":167006145763,"pu":167006144390,"b":[["41.838","0"],["42.052","0"],["42.182","900"]],"a":[["42.319","100"],["42.320","200"],["42.454","300"],["42.467","0"],["42.522","400"],["42.675","0"]]}}
1626916410.82284: {"stream":"bchusd_perp@depth@100ms","data":{"e":"depthUpdate","E":1626916410849,"T":1626916410800,"s":"BCHUSD_PERP","ps":"BCHUSD","U":167006145360,"u":167006145636,"pu":167006144415,"b":[["427.77","150"]],"a":[["431.22","0"]]}}
1626916410.8511949: {"stream":"eosusd_perp@depth@100ms","data":{"e":"depthUpdate","E":1626916410877,"T":1626916410861,"s":"EOSUSD_PERP","ps":"EOSUSD","U":167006145505,"u":167006145929,"pu":167006144367,"b":[["3.468","0"]],"a":[["3.470","2960"],["3.471","5427"]]}}
1626916410.8873081: {"stream":"btcusd_211231@depth@100ms","data":{"e":"depthUpdate","E":1626916410914,"T":1626916410906,"s":"BTCUSD_211231","ps":"BTCUSD","U":167006145675,"u":167006146160,"pu":167006145629,"b":[],"a":[["32623.4","17"],["32625.8","0"],["32628.3","153"],["32628.4","0"],["32628.5","0"],["32629.2","0"],["32631.6","0"],["32656.0","15"]]}}
1626916410.893785: {"stream":"linkusd_perp@depth@100ms","data":{"e":"depthUpdate","E":1626916410919,"T":1626916410912,"s":"LINKUSD_PERP","ps":"LINKUSD","U":167006145698,"u":167006146198,"pu":167006145462,"b":[["15.054","100"]],"a":[["15.104","15253"]]}}
1626916410.905529: {"stream":"xrpusd_perp@depth@100ms","data":{"e":"depthUpdate","E":1626916410932,"T":1626916410921,"s":"XRPUSD_PERP","ps":"XRPUSD","U":167006145759,"u":167006146278,"pu":167006145577,"b":[["0.5579","787"],["0.5617","2690"],["0.5621","6749"],["0.5635","576"],["0.5636","2563"],["0.5644","25096"],["0.5654","7598"],["0.5655","6925"],["0.5656","8660"],["0.5658","2457"],["0.5660","5806"]],"a":[["0.5669","3802"],["0.5671","3514"],["0.5672","2192"],["0.5673","12538"],["0.5680","24702"],["0.5689","2253"],["0.5704","15490"],["0.5706","3325"],["0.5746","783"]]}}
1626916410.910323: {"stream":"etcusd_perp@depth@100ms","data":{"e":"depthUpdate","E":1626916410936,"T":1626916410909,"s":"ETCUSD_PERP","ps":"ETCUSD","U":167006145770,"u":167006146181,"pu":167006145763,"b":[["41.836","312"],["42.047","156"]],"a":[["42.265","0"],["42.266","500"],["42.277","90"],["42.284","0"],["42.293","0"],["42.300","233"],["42.673","553"]]}}
1626916410.931435: {"stream":"linkusd_211231@depth@100ms","data":{"e":"depthUpdate","E":1626916410958,"T":1626916410852,"s":"LINKUSD_211231","ps":"LINKUSD","U":167006145882,"u":167006145886,"pu":167006145305,"b":[["14.760","1022"],["14.836","0"],["14.911","0"],["14.986","0"],["15.062","0"]],"a":[]}}
1626916410.941312: {"stream":"ethusd_210924@depth@100ms","data":{"e":"depthUpdate","E":1626916410968,"T":1626916410934,"s":"ETHUSD_210924","ps":"ETHUSD","U":167006145943,"u":167006146363,"pu":167006145648,"b":[["1989.58","2077"]],"a":[["1991.54","0"],["1991.77","270"]]}}
1626916410.954051: {"stream":"bchusd_perp@depth@100ms","data":{"e":"depthUpdate","E":1626916410982,"T":1626916410910,"s":"BCHUSD_PERP","ps":"BCHUSD","U":167006146006,"u":167006146186,"pu":167006145636,"b":[["427.77","174"]],"a":[["427.81","0"],["427.88","100"]]}}
1626916410.9640908: {"stream":"eosusd_perp@depth@100ms","data":{"e":"depthUpdate","E":1626916410990,"T":1626916410970,"s":"EOSUSD_PERP","ps":"EOSUSD","U":167006146055,"u":167006146537,"pu":167006145929,"b":[["3.468","0"]],"a":[["3.470","2708"],["3.471","4976"],["3.472","5564"]]}}
1626916410.990104: {"stream":"btcusd_211231@depth@100ms","data":{"e":"depthUpdate","E":1626916411016,"T":1626916411009,"s":"BTCUSD_211231","ps":"BTCUSD","U":167006146190,"u":167006146707,"pu":167006146160,"b":[],"a":[["32625.8","153"],["32628.2","0"],["32628.3","0"]]}}
1626916411.002683: {"stream":"linkusd_perp@depth@100ms","data":{"e":"depthUpdate","E":1626916411027,"T":1626916410974,"s":"LINKUSD_PERP","ps":"LINKUSD","U":167006146255,"u":167006146558,"pu":167006146198,"b":[["15.052","980"],["15.054","100"],["15.055","380"],["15.056","1562"]],"a":[["15.071","2799"]]}}
1626916411.0066292: {"stream":"trxusd_perp@depth@100ms","data":{"e":"depthUpdate","E":1626916411035,"T":1626916410930,"s":"TRXUSD_PERP","ps":"TRXUSD","U":167006146331,"u":167006146331,"pu":167006145269,"b":[],"a":[["0.05348","635"]]}}
1626916411.022481: {"stream":"xrpusd_perp@depth@100ms","data":{"e":"depthUpdate","E":1626916411050,"T":1626916411018,"s":"XRPUSD_PERP","ps":"XRPUSD","U":167006146418,"u":167006146779,"pu":167006146278,"b":[["0.5655","7085"],["0.5661","4362"]],"a":[["0.5662","2020"],["0.5663","4287"],["0.5664","6946"],["0.5666","1790"]]}}
1626916411.023235: {"stream":"etcusd_perp@depth@100ms","data":{"e":"depthUpdate","E":1626916411052,"T":1626916410980,"s":"ETCUSD_PERP","ps":"ETCUSD","U":167006146429,"u":167006146589,"pu":167006146181,"b":[],"a":[["42.336","325"],["42.341","15"],["42.462","150"]]}}
1626916411.0481448: {"stream":"ethusd_210924@depth@100ms","data":{"e":"depthUpdate","E":1626916411075,"T":1626916411032,"s":"ETHUSD_210924","ps":"ETHUSD","U":167006146540,"u":167006146830,"pu":167006146363,"b":[["1987.09","500"],["1989.75","1884"]],"a":[["1991.55","270"],["1991.77","0"],["1993.11","420"],["1995.05","0"]]}}
1626916411.0709639: {"stream":"eosusd_perp@depth@100ms","data":{"e":"depthUpdate","E":1626916411097,"T":1626916411085,"s":"EOSUSD_PERP","ps":"EOSUSD","U":167006146643,"u":167006147063,"pu":167006146537,"b":[["3.468","0"]],"a":[]}}
1626916411.103936: {"stream":"linkusd_perp@depth@100ms","data":{"e":"depthUpdate","E":1626916411130,"T":1626916411074,"s":"LINKUSD_PERP","ps":"LINKUSD","U":167006146797,"u":167006146991,"pu":167006146558,"b":[["15.052","980"],["15.053","4712"],["15.054","0"],["15.056","1662"]],"a":[["15.070","6204"],["15.071","809"]]}}
1626916411.131118: {"stream":"etcusd_perp@depth@100ms","data":{"e":"depthUpdate","E":1626916411158,"T":1626916411147,"s":"ETCUSD_PERP","ps":"ETCUSD","U":167006146898,"u":167006147285,"pu":167006146589,"b":[["42.235","0"],["42.238","0"],["42.239","1446"],["42.242","752"]],"a":[["42.306","737"],["42.318","322"],["42.331","110"],["42.336","425"]]}}
1626916411.133582: {"stream":"trxusd_perp@depth@100ms","data":{"e":"depthUpdate","E":1626916411160,"T":1626916411146,"s":"TRXUSD_PERP","ps":"TRXUSD","U":167006146900,"u":167006147278,"pu":167006146331,"b":[["0.05341","1313"],["0.05342","937"],["0.05343","1220"]],"a":[["0.05352","652"],["0.05355","1249"]]}}
1626916411.140185: {"stream":"xrpusd_perp@depth@100ms","data":{"e":"depthUpdate","E":1626916411166,"T":1626916411160,"s":"XRPUSD_PERP","ps":"XRPUSD","U":167006146935,"u":167006147333,"pu":167006146779,"b":[["0.5646","904"],["0.5647","1496"],["0.5652","816"],["0.5653","12833"],["0.5655","6925"],["0.5657","4913"],["0.5658","3177"],["0.5659","2136"],["0.5660","5741"],["0.5661","4397"]],"a":[["0.5664","6911"],["0.5665","4260"],["0.5667","5406"],["0.5668","8625"],["0.5675","2845"],["0.5676","53265"],["0.5682","14213"],["0.5687","383"],["0.5688","7891"]]}}
1626916411.15904: {"stream":"btcusd_211231@depth@100ms","data":{"e":"depthUpdate","E":1626916411185,"T":1626916411171,"s":"BTCUSD_211231","ps":"BTCUSD","U":167006147009,"u":167006147384,"pu":167006146707,"b":[["27412.9","0"]],"a":[["32625.8","0"],["32629.2","153"]]}}
1626916411.159242: {"stream":"bchusd_210924@depth@100ms","data":{"e":"depthUpdate","E":1626916411187,"T":1626916411142,"s":"BCHUSD_210924","ps":"BCHUSD","U":167006147033,"u":167006147272,"pu":167006144707,"b":[["428.94","0"],["429.00","3623"],["429.11","0"],["429.12","0"],["429.23","40"]],"a":[]}}
1626916411.159688: {"stream":"bchusd_perp@depth@100ms","data":{"e":"depthUpdate","E":1626916411187,"T":1626916411113,"s":"BCHUSD_PERP","ps":"BCHUSD","U":167006147030,"u":167006147170,"pu":167006146186,"b":[["427.58","100"],["427.62","0"],["427.63","1186"],["427.66","27"]],"a":[["427.81","100"],["427.88","0"]]}}
1626916411.1881201: {"stream":"eosusd_perp@depth@100ms","data":{"e":"depthUpdate","E":1626916411214,"T":1626916411198,"s":"EOSUSD_PERP","ps":"EOSUSD","U":167006147154,"u":167006147516,"pu":167006147063,"b":[["3.468","0"]],"a":[]}}
1626916411.231885: {"stream":"ethusd_210924@depth@100ms","data":{"e":"depthUpdate","E":1626916411255,"T":1626916411232,"s":"ETHUSD_210924","ps":"ETHUSD","U":167006147293,"u":167006147729,"pu":167006146830,"b":[],"a":[["1991.17","0"],["1991.18","0"],["1991.55","0"],["1991.77","270"],["1992.49","0"],["1992.88","425"]]}}
1626916411.236793: {"stream":"trxusd_perp@depth@100ms","data":{"e":"depthUpdate","E":1626916411262,"T":1626916411156,"s":"TRXUSD_PERP","ps":"TRXUSD","U":167006147321,"u":167006147321,"pu":167006147278,"b":[],"a":[["0.05352","1144"]]}}
1626916411.2401888: {"stream":"xrpusd_perp@depth@100ms","data":{"e":"depthUpdate","E":1626916411269,"T":1626916411245,"s":"XRPUSD_PERP","ps":"XRPUSD","U":167006147347,"u":167006147798,"pu":167006147333,"b":[["0.5646","834"],["0.5655","6625"],["0.5660","5707"],["0.5661","5131"],["0.5662","0"]],"a":[["0.5662","568"],["0.5663","3547"],["0.5664","6771"],["0.5666","1888"],["0.5667","3507"],["0.5671","3514"],["0.5672","2192"],["0.5674","3962"],["0.5679","3430"]]}}
1626916411.244692: {"stream":"linkusd_perp@depth@100ms","data":{"e":"depthUpdate","E":1626916411271,"T":1626916411247,"s":"LINKUSD_PERP","ps":"LINKUSD","U":167006147366,"u":167006147830,"pu":167006146991,"b":[["15.030","1162"],["15.040","658"]],"a":[["15.070","4214"],["15.071","2705"],["15.091","280"],["15.123","500"]]}}
1626916411.263365: {"stream":"bchusd_210924@depth@100ms","data":{"e":"depthUpdate","E":1626916411291,"T":1626916411254,"s":"BCHUSD_210924","ps":"BCHUSD","U":167006147447,"u":167006147897,"pu":167006147272,"b":[],"a":[["429.81","0"],["429.86","244"],["430.62","0"]]}}
1626916411.2939131: {"stream":"btcusd_211231@depth@100ms","data":{"e":"depthUpdate","E":1626916411321,"T":1626916411295,"s":"BTCUSD_211231","ps":"BTCUSD","U":167006147611,"u":167006148226,"pu":167006147384,"b":[["32526.9","0"],["32527.1","648"],["32620.5","175"]],"a":[["32623.4","1"],["32625.9","0"]]}}
1626916411.2982762: {"stream":"eosusd_perp@depth@100ms","data":{"e":"depthUpdate","E":1626916411325,"T":1626916411309,"s":"EOSUSD_PERP","ps":"EOSUSD","U":167006147656,"u":167006148331,"pu":167006147516,"b":[["3.452","5971"],["3.465","7370"],["3.466","7296"],["3.468","0"]],"a":[]}}
1626916411.303898: {"stream":"etcusd_perp@depth@100ms","data":{"e":"depthUpdate","E":1626916411331,"T":1626916411299,"s":"ETCUSD_PERP","ps":"ETCUSD","U":167006147700,"u":167006148253,"pu":167006147285,"b":[],"a":[["42.266","400"],["42.276","478"],["42.328","0"]]}}
1626916411.3155782: {"stream":"bchusd_perp@depth@100ms","data":{"e":"depthUpdate","E":1626916411342,"T":1626916411282,"s":"BCHUSD_PERP","ps":"BCHUSD","U":167006147740,"u":167006148128,"pu":167006147170,"b":[["427.58","0"],["427.64","400"]],"a":[["427.81","0"],["427.88","100"],["428.31","0"],["428.37","257"],["428.52","353"],["428.77","502"]]}}
1626916411.3296971: {"stream":"ethusd_210924@depth@100ms","data":{"e":"depthUpdate","E":1626916411357,"T":1626916411345,"s":"ETHUSD_210924","ps":"ETHUSD","U":167006147891,"u":167006148638,"pu":167006147729,"b":[["1987.56","1000"],["1989.03","12"],["1989.14","7839"],["1989.56","0"],["1990.06","322"],["1990.59","0"],["1990.60","0"],["1990.72","0"],["1990.81","0"],["1990.82","0"],["1990.83","0"],["1990.98","2399"]],"a":[["1991.56","619"],["1991.57","0"],["1991.58","0"],["1991.77","0"],["1992.05","0"],["1992.18","383"],["1992.38","60"]]}}
1626916411.35174: {"stream":"linkusd_perp@depth@100ms","data":{"e":"depthUpdate","E":1626916411378,"T":1626916411351,"s":"LINKUSD_PERP","ps":"LINKUSD","U":167006148021,"u":167006148693,"pu":167006147830,"b":[["15.053","3379"],["15.054","1433"],["15.056","1562"]],"a":[["15.075","1074"],["15.076","224"],["15.077","775"],["15.078","951"]]}}
1626916411.352415: {"stream":"xrpusd_perp@depth@100ms","data":{"e":"depthUpdate","E":1626916411380,"T":1626916411373,"s":"XRPUSD_PERP","ps":"XRPUSD","U":167006148048,"u":167006148855,"pu":167006147798,"b":[["0.5643","959"],["0.5644","25732"],["0.5649","5549"],["0.5652","541"],["0.5656","8554"],["0.5660","5737"]],"a":[["0.5664","6611"],["0.5666","1538"],["0.5668","8785"],["0.5670","2440"],["0.5672","1917"],["0.5673","12813"],["0.5677","1183"],["0.5698","112"],["0.5700","10180"]]}}
1626916411.406503: {"stream":"btcusd_211231@depth@100ms","data":{"e":"depthUpdate","E":1626916411433,"T":1626916411398,"s":"BTCUSD_211231","ps":"BTCUSD","U":167006148470,"u":167006149026,"pu":167006148226,"b":[["27403.6","273"],["32612.0","86"]],"a":[["32623.4","17"],["33027.1","0"],["33187.1","0"],["33347.1","0"],["33507.1","0"],["33667.1","0"]]}}
1626916411.408542: {"stream":"eosusd_perp@depth@100ms","data":{"e":"depthUpdate","E":1626916411435,"T":1626916411424,"s":"EOSUSD_PERP","ps":"EOSUSD","U":167006148482,"u":167006149155,"pu":167006148331,"b":[["3.464","6671"],["3.467","2857"],["3.468","0"]],"a":[]}}
1626916411.4168582: {"stream":"trxusd_perp@depth@100ms","data":{"e":"depthUpdate","E":1626916411444,"T":1626916411371,"s":"TRXUSD_PERP","ps":"TRXUSD","U":167006148543,"u":167006148843,"pu":167006147321,"b":[],"a":[["0.05348","535"],["0.05349","522"],["0.05350","2983"],["0.05351","2624"],["0.05352","1344"],["0.05355","949"],["0.05356","529"],["0.05358","1438"],["0.05359","606"]]}}
1626916411.4561222: {"stream":"linkusd_perp@depth@100ms","data":{"e":"depthUpdate","E":1626916411483,"T":1626916411400,"s":"LINKUSD_PERP","ps":"LINKUSD","U":167006148912,"u":167006149047,"pu":167006148693,"b":[["15.052","580"],["15.057","906"]],"a":[["15.070","3497"],["15.071","2405"],["15.072","91"],["15.077","1175"]]}}
1626916411.45821: {"stream":"xrpusd_perp@depth@100ms","data":{"e":"depthUpdate","E":1626916411486,"T":1626916411475,"s":"XRPUSD_PERP","ps":"XRPUSD","U":167006148919,"u":167006149472,"pu":167006148855,"b":[["0.5643","323"],["0.5653","13108"],["0.5657","5019"],["0.5658","3135"],["0.5659","2178"],["0.5661","5133"]],"a":[["0.5663","3517"],["0.5664","6311"],["0.5665","4560"],["0.5666","1656"],["0.5667","2292"],["0.5668","8519"],["0.5670","4074"],["0.5682","13577"]]}}
1626916411.466625: {"stream":"etcusd_perp@depth@100ms","data":{"e":"depthUpdate","E":1626916411493,"T":1626916411459,"s":"ETCUSD_PERP","ps":"ETCUSD","U":167006148957,"u":167006149349,"pu":167006148253,"b":[["42.208","662"],["42.215","200"],["42.246","0"],["42.249","265"],["42.254","94"]],"a":[["42.336","25"],["42.341","515"]]}}
1626916411.482421: {"stream":"ethusd_210924@depth@100ms","data":{"e":"depthUpdate","E":1626916411508,"T":1626916411494,"s":"ETHUSD_210924","ps":"ETHUSD","U":167006149065,"u":167006149590,"pu":167006148638,"b":[["1987.56","0"],["1989.50","5726"],["1989.71","0"],["1990.00","343"],["1990.81","0"],["1990.82","653"]],"a":[["1991.55","270"],["1991.56","349"],["1991.77","0"]]}}
1626916411.50949: {"stream":"btcusd_211231@depth@100ms","data":{"e":"depthUpdate","E":1626916411536,"T":1626916411505,"s":"BTCUSD_211231","ps":"BTCUSD","U":167006149199,"u":167006149637,"pu":167006149026,"b":[],"a":[["32695.3","389"],["32707.7","0"],["33029.4","45"],["33189.4","45"],["33349.5","45"],["33509.5","46"],["33669.5","46"]]}}
1626916411.5097332: {"stream":"bchusd_perp@depth@100ms","data":{"e":"depthUpdate","E":1626916411536,"T":1626916411522,"s":"BCHUSD_PERP","ps":"BCHUSD","U":167006149209,"u":167006149706,"pu":167006148128,"b":[["427.35","3467"],["427.63","425"],["427.65","290"]],"a":[["427.81","0"],["427.88","100"],["428.77","0"]]}}
1626916411.509852: {"stream":"linkusd_211231@depth@100ms","data":{"e":"depthUpdate","E":1626916411536,"T":1626916411431,"s":"LINKUSD_211231","ps":"LINKUSD","U":167006149211,"u":167006149211,"pu":167006145886,"b":[["15.313","294"]],"a":[]}}
1626916411.510263: {"stream":"eosusd_perp@depth@100ms","data":{"e":"depthUpdate","E":1626916411538,"T":1626916411530,"s":"EOSUSD_PERP","ps":"EOSUSD","U":167006149215,"u":167006149736,"pu":167006149155,"b":[["3.457","3336"],["3.462","5433"],["3.463","1807"],["3.467","2868"],["3.468","0"]],"a":[["3.468","211"],["3.478","6352"]]}}
1626916411.560283: {"stream":"xrpusd_perp@depth@100ms","data":{"e":"depthUpdate","E":1626916411588,"T":1626916411523,"s":"XRPUSD_PERP","ps":"XRPUSD","U":167006149503,"u":167006149715,"pu":167006149472,"b":[["0.5644","26368"]],"a":[["0.5667","2334"],["0.5669","3908"],["0.5670","3479"],["0.5683","1754"],["0.5685","1554"]]}}
1626916411.568958: {"stream":"linkusd_perp@depth@100ms","data":{"e":"depthUpdate","E":1626916411596,"T":1626916411567,"s":"LINKUSD_PERP","ps":"LINKUSD","U":167006149563,"u":167006149891,"pu":167006149047,"b":[["15.058","320"]],"a":[["15.071","2405"],["15.076","604"],["15.077","795"]]}}
1626916411.569109: {"stream":"etcusd_perp@depth@100ms","data":{"e":"depthUpdate","E":1626916411596,"T":1626916411577,"s":"ETCUSD_PERP","ps":"ETCUSD","U":167006149559,"u":167006149932,"pu":167006149349,"b":[["42.254","108"]],"a":[["42.282","1109"],["42.293","98"],["42.341","415"],["42.388","250"]]}}
1626916411.579073: {"stream":"trxusd_perp@depth@100ms","data":{"e":"depthUpdate","E":1626916411605,"T":1626916411552,"s":"TRXUSD_PERP","ps":"TRXUSD","U":167006149619,"u":167006149833,"pu":167006148843,"b":[],"a":[["0.05348","635"],["0.05349","622"],["0.05350","3083"],["0.05351","2524"],["0.05352","1144"],["0.05355","1249"],["0.05356","829"],["0.05358","1138"],["0.05359","306"]]}}
1626916411.593419: {"stream":"ethusd_210924@depth@100ms","data":{"e":"depthUpdate","E":1626916411620,"T":1626916411597,"s":"ETHUSD_210924","ps":"ETHUSD","U":167006149680,"u":167006150006,"pu":167006149590,"b":[["1988.08","414"],["1988.24","1000"],["1988.57","565"],["1989.04","7839"],["1989.14","0"],["1990.82","0"]],"a":[["1991.55","0"],["1991.77","270"],["1995.06","0"],["1995.45","565"]]}}
1626916411.609965: {"stream":"bchusd_perp@depth@100ms","data":{"e":"depthUpdate","E":1626916411637,"T":1626916411597,"s":"BCHUSD_PERP","ps":"BCHUSD","U":167006149740,"u":167006150008,"pu":167006149706,"b":[["427.56","1069"],["427.77","151"]],"a":[["427.81","100"],["427.88","0"],["428.55","386"],["428.94","347"]]}}
1626916411.615912: {"stream":"eosusd_perp@depth@100ms","data":{"e":"depthUpdate","E":1626916411643,"T":1626916411625,"s":"EOSUSD_PERP","ps":"EOSUSD","U":167006149768,"u":167006150168,"pu":167006149736,"b":[["3.452","5560"],["3.457","3636"],["3.468","0"]],"a":[["3.470","3079"],["3.471","4514"],["3.478","6652"]]}}
1626916411.630199: {"stream":"linkusd_211231@depth@100ms","data":{"e":"depthUpdate","E":1626916411656,"T":1626916411553,"s":"LINKUSD_211231","ps":"LINKUSD","U":167006149835,"u":167006149839,"pu":167006149211,"b":[],"a":[["15.526","0"],["15.601","0"],["15.676","38"],["15.752","0"],["15.827","0"]]}}
1626916411.646361: {"stream":"btcusd_211231@depth@100ms","data":{"e":"depthUpdate","E":1626916411671,"T":1626916411664,"s":"BTCUSD_211231","ps":"BTCUSD","U":167006149889,"u":167006150376,"pu":167006149637,"b":[["32363.2","0"],["32527.0","0"],["32527.2","1360"]],"a":[["32629.2","0"],["32631.6","0"],["32638.4","153"],["32639.2","75"]]}}
1626916411.662444: {"stream":"xrpusd_perp@depth@100ms","data":{"e":"depthUpdate","E":1626916411690,"T":1626916411685,"s":"XRPUSD_PERP","ps":"XRPUSD","U":167006149968,"u":167006150488,"pu":167006149715,"b":[["0.5644","26668"],["0.5661","4733"]],"a":[["0.5664","6611"],["0.5665","4260"],["0.5667","3470"],["0.5671","2425"],["0.5693","7890"],["0.5700","2280"]]}}
1626916411.685706: {"stream":"trxusd_perp@depth@100ms","data":{"e":"depthUpdate","E":1626916411708,"T":1626916411662,"s":"TRXUSD_PERP","ps":"TRXUSD","U":167006150043,"u":167006150359,"pu":167006149833,"b":[],"a":[["0.05348","635"],["0.05349","622"],["0.05350","3083"],["0.05351","2524"],["0.05364","2080"]]}}
1626916411.7017128: {"stream":"ethusd_210924@depth@100ms","data":{"e":"depthUpdate","E":1626916411727,"T":1626916411721,"s":"ETHUSD_210924","ps":"ETHUSD","U":167006150144,"u":167006150638,"pu":167006150006,"b":[["1987.09","0"],["1989.58","0"],["1989.89","50"],["1989.92","259"],["1990.22","0"],["1990.33","466"],["1990.59","0"],["1990.81","0"],["1990.98","2399"]],"a":[["1991.55","270"],["1991.65","613"],["1991.66","1750"],["1991.77","0"]]}}
1626916411.715696: {"stream":"linkusd_perp@depth@100ms","data":{"e":"depthUpdate","E":1626916411741,"T":1626916411686,"s":"LINKUSD_PERP","ps":"LINKUSD","U":167006150198,"u":167006150497,"pu":167006149891,"b":[["15.055","528"]],"a":[["15.071","2705"]]}}
1626916411.7162602: {"stream":"bchusd_perp@depth@100ms","data":{"e":"depthUpdate","E":1626916411744,"T":1626916411720,"s":"BCHUSD_PERP","ps":"BCHUSD","U":167006150233,"u":167006150635,"pu":167006150008,"b":[["427.77","175"]],"a":[["427.81","0"],["427.88","100"]]}}
1626916411.721092: {"stream":"etcusd_perp@depth@100ms","data":{"e":"depthUpdate","E":1626916411748,"T":1626916411644,"s":"ETCUSD_PERP","ps":"ETCUSD","U":167006150241,"u":167006150241,"pu":167006149932,"b":[],"a":[["42.255","6"]]}}
1626916411.7255309: {"stream":"eosusd_perp@depth@100ms","data":{"e":"depthUpdate","E":1626916411752,"T":1626916411731,"s":"EOSUSD_PERP","ps":"EOSUSD","U":167006150255,"u":167006150696,"pu":167006150168,"b":[["3.468","0"]],"a":[["3.470","3479"],["3.473","2287"],["3.474","4875"]]}}
1626916411.731513: {"stream":"linkusd_211231@depth@100ms","data":{"e":"depthUpdate","E":1626916411758,"T":1626916411652,"s":"LINKUSD_211231","ps":"LINKUSD","U":167006150286,"u":167006150286,"pu":167006149839,"b":[],"a":[["15.326","140"]]}}
1626916411.738434: {"stream":"bchusd_210924@depth@100ms","data":{"e":"depthUpdate","E":1626916411765,"T":1626916411659,"s":"BCHUSD_210924","ps":"BCHUSD","U":167006150336,"u":167006150345,"pu":167006147897,"b":[["428.93","3813"],["429.00","0"]],"a":[]}}
1626916411.749335: {"stream":"btcusd_211231@depth@100ms","data":{"e":"depthUpdate","E":1626916411777,"T":1626916411702,"s":"BTCUSD_211231","ps":"BTCUSD","U":167006150415,"u":167006150562,"pu":167006150376,"b":[["31362.9","0"],["31522.9","0"],["31682.9","0"],["31842.9","0"],["32003.0","0"],["32608.0","0"],["32612.2","41"]],"a":[["32629.2","153"],["32638.4","0"]]}}
1626916411.773791: {"stream":"xrpusd_perp@depth@100ms","data":{"e":"depthUpdate","E":1626916411801,"T":1626916411796,"s":"XRPUSD_PERP","ps":"XRPUSD","U":167006150551,"u":167006150923,"pu":167006150488,"b":[["0.5660","5707"]],"a":[["0.5664","6471"],["0.5665","4032"],["0.5666","1496"]]}}
1626916411.785606: {"stream":"trxusd_perp@depth@100ms","data":{"e":"depthUpdate","E":1626916411812,"T":1626916411769,"s":"TRXUSD_PERP","ps":"TRXUSD","U":167006150582,"u":167006150825,"pu":167006150359,"b":[["0.05314","0"]],"a":[["0.05348","635"],["0.05349","622"],["0.05350","3083"],["0.05351","2524"],["0.05364","2231"]]}}
1626916411.807677: {"stream":"ethusd_210924@depth@100ms","data":{"e":"depthUpdate","E":1626916411834,"T":1626916411798,"s":"ETHUSD_210924","ps":"ETHUSD","U":167006150693,"u":167006150927,"pu":167006150638,"b":[],"a":[["1995.90","0"],["1997.70","0"],["2191.61","2712"]]}}
1626916411.8260212: {"stream":"eosusd_perp@depth@100ms","data":{"e":"depthUpdate","E":1626916411853,"T":1626916411837,"s":"EOSUSD_PERP","ps":"EOSUSD","U":167006150747,"u":167006151060,"pu":167006150696,"b":[["3.468","0"]],"a":[]}}
1626916411.828127: {"stream":"linkusd_perp@depth@100ms","data":{"e":"depthUpdate","E":1626916411853,"T":1626916411842,"s":"LINKUSD_PERP","ps":"LINKUSD","U":167006150751,"u":167006151075,"pu":167006150497,"b":[["15.015","328"],["15.056","1713"],["15.057","1054"]],"a":[["15.071","2405"]]}}
1626916411.83174: {"stream":"bchusd_perp@depth@100ms","data":{"e":"depthUpdate","E":1626916411860,"T":1626916411815,"s":"BCHUSD_PERP","ps":"BCHUSD","U":167006150758,"u":167006150978,"pu":167006150635,"b":[["427.56","1714"]],"a":[["427.81","0"],["427.88","100"]]}}
1626916411.8807821: {"stream":"btcusd_211231@depth@100ms","data":{"e":"depthUpdate","E":1626916411909,"T":1626916411892,"s":"BTCUSD_211231","ps":"BTCUSD","U":167006150954,"u":167006151247,"pu":167006150562,"b":[["29360.9","0"],["31365.1","55"],["31525.1","55"],["31685.2","55"],["31845.2","55"],["32005.2","55"],["32565.6","0"],["32574.5","393"]],"a":[["32623.4","17"]]}}
1626916411.895152: {"stream":"xrpusd_perp@depth@100ms","data":{"e":"depthUpdate","E":1626916411920,"T":1626916411818,"s":"XRPUSD_PERP","ps":"XRPUSD","U":167006150982,"u":167006151005,"pu":167006150923,"b":[["0.5660","5737"]],"a":[["0.5679","3777"]]}}
1626916411.932986: {"stream":"linkusd_perp@depth@100ms","data":{"e":"depthUpdate","E":1626916411960,"T":1626916411901,"s":"LINKUSD_PERP","ps":"LINKUSD","U":167006151129,"u":167006151269,"pu":167006151075,"b":[["14.911","0"]],"a":[["15.104","15402"],["15.274","0"]]}}
1626916411.9377558: {"stream":"eosusd_perp@depth@100ms","data":{"e":"depthUpdate","E":1626916411965,"T":1626916411948,"s":"EOSUSD_PERP","ps":"EOSUSD","U":167006151142,"u":167006151434,"pu":167006151060,"b":[["3.468","0"]],"a":[["3.485","5678"],["3.486","683"]]}}
1626916411.95513: {"stream":"trxusd_perp@depth@100ms","data":{"e":"depthUpdate","E":1626916411981,"T":1626916411967,"s":"TRXUSD_PERP","ps":"TRXUSD","U":167006151184,"u":167006151487,"pu":167006150825,"b":[["0.05314","301"],["0.05341","1313"],["0.05343","1220"]],"a":[["0.05366","1389"]]}}
1626916411.9583092: {"stream":"ethusd_210924@depth@100ms","data":{"e":"depthUpdate","E":1626916411986,"T":1626916411975,"s":"ETHUSD_210924","ps":"ETHUSD","U":167006151203,"u":167006151511,"pu":167006150927,"b":[["1976.83","2447"],["1989.32","1927"]],"a":[["1997.40","190"]]}}
1626916411.997473: {"stream":"bchusd_perp@depth@100ms","data":{"e":"depthUpdate","E":1626916412026,"T":1626916412021,"s":"BCHUSD_PERP","ps":"BCHUSD","U":167006151343,"u":167006151791,"pu":167006150978,"b":[["424.67","1387"],["426.25","751"],["427.77","151"]],"a":[["427.81","100"],["427.88","0"],["430.91","0"]]}}
1626916412.037271: {"stream":"linkusd_perp@depth@100ms","data":{"e":"depthUpdate","E":1626916412062,"T":1626916412056,"s":"LINKUSD_PERP","ps":"LINKUSD","U":167006151457,"u":167006152032,"pu":167006151269,"b":[["15.018","250"]],"a":[["15.070","2257"],["15.071","2854"],["15.073","995"]]}}
1626916412.047164: {"stream":"eosusd_perp@depth@100ms","data":{"e":"depthUpdate","E":1626916412072,"T":1626916412064,"s":"EOSUSD_PERP","ps":"EOSUSD","U":167006151499,"u":167006152083,"pu":167006151434,"b":[["3.468","0"]],"a":[]}}
1626916412.0624268: {"stream":"xrpusd_perp@depth@100ms","data":{"e":"depthUpdate","E":1626916412088,"T":1626916412082,"s":"XRPUSD_PERP","ps":"XRPUSD","U":167006151538,"u":167006152168,"pu":167006151005,"b":[["0.5620","6563"],["0.5654","7898"],["0.5661","4833"]],"a":[["0.5664","6471"],["0.5665","3504"],["0.5666","1724"],["0.5699","0"]]}}
1626916412.077288: {"stream":"etcusd_perp@depth@100ms","data":{"e":"depthUpdate","E":1626916412106,"T":1626916412029,"s":"ETCUSD_PERP","ps":"ETCUSD","U":167006151633,"u":167006151856,"pu":167006150241,"b":[],"a":[["42.313","514"],["42.344","70"]]}}
1626916412.081442: {"stream":"ethusd_210924@depth@100ms","data":{"e":"depthUpdate","E":1626916412108,"T":1626916412066,"s":"ETHUSD_210924","ps":"ETHUSD","U":167006151653,"u":167006152090,"pu":167006151511,"b":[["1990.08","314"],["1990.21","0"]],"a":[["1993.74","314"],["1993.84","0"],["1994.96","304"],["1995.35","500"],["1999.93","1201"],["2193.08","5475"]]}}
1626916412.101911: {"stream":"bchusd_perp@depth@100ms","data":{"e":"depthUpdate","E":1626916412127,"T":1626916412075,"s":"BCHUSD_PERP","ps":"BCHUSD","U":167006151818,"u":167006152132,"pu":167006151791,"b":[["427.77","175"]],"a":[["427.81","0"],["427.88","100"],["428.02","50"],["429.33","141"]]}}
1626916412.115165: {"stream":"btcusd_211231@depth@100ms","data":{"e":"depthUpdate","E":1626916412142,"T":1626916412043,"s":"BTCUSD_211231","ps":"BTCUSD","U":167006151894,"u":167006151933,"pu":167006151247,"b":[["32527.1","0"],["32527.3","747"]],"a":[]}}
1626916412.135455: {"stream":"linkusd_perp@depth@100ms","data":{"e":"depthUpdate","E":1626916412162,"T":1626916412145,"s":"LINKUSD_PERP","ps":"LINKUSD","U":167006152040,"u":167006152425,"pu":167006152032,"b":[["14.276","2108"],["14.930","1000"]],"a":[]}}
1626916412.164247: {"stream":"bchusd_210924@depth@100ms","data":{"e":"depthUpdate","E":1626916412191,"T":1626916412158,"s":"BCHUSD_210924","ps":"BCHUSD","U":167006152185,"u":167006152490,"pu":167006150345,"b":[],"a":[["429.46","0"],["429.58","40"],["429.87","12"],["429.93","4263"]]}}
1626916412.164435: {"stream":"eosusd_perp@depth@100ms","data":{"e":"depthUpdate","E":1626916412191,"T":1626916412177,"s":"EOSUSD_PERP","ps":"EOSUSD","U":167006152189,"u":167006152607,"pu":167006152083,"b":[["3.468","0"]],"a":[]}}
1626916412.180216: {"stream":"xrpusd_perp@depth@100ms","data":{"e":"depthUpdate","E":1626916412207,"T":1626916412101,"s":"XRPUSD_PERP","ps":"XRPUSD","U":167006152240,"u":167006152240,"pu":167006152168,"b":[],"a":[["0.5665","3804"]]}}
1626916412.188065: {"stream":"etcusd_perp@depth@100ms","data":{"e":"depthUpdate","E":1626916412215,"T":1626916412126,"s":"ETCUSD_PERP","ps":"ETCUSD","U":167006152288,"u":167006152349,"pu":167006151856,"b":[],"a":[["42.292","475"],["42.297","706"],["42.299","0"],["42.306","0"]]}}
1626916412.207676: {"stream":"ethusd_210924@depth@100ms","data":{"e":"depthUpdate","E":1626916412234,"T":1626916412211,"s":"ETHUSD_210924","ps":"ETHUSD","U":167006152354,"u":167006152769,"pu":167006152090,"b":[["1980.04","0"],["1985.02","0"],["1989.96","50"]],"a":[["1997.40","0"]]}}
1626916412.239991: {"stream":"bchusd_perp@depth@100ms","data":{"e":"depthUpdate","E":1626916412267,"T":1626916412187,"s":"BCHUSD_PERP","ps":"BCHUSD","U":167006152523,"u":167006152664,"pu":167006152132,"b":[],"a":[["428.11","1748"],["428.33","0"],["428.34","3356"]]}}
1626916412.242561: {"stream":"linkusd_perp@depth@100ms","data":{"e":"depthUpdate","E":1626916412269,"T":1626916412248,"s":"LINKUSD_PERP","ps":"LINKUSD","U":167006152541,"u":167006152928,"pu":167006152425,"b":[["3.005","702"],["10.519","2811"],["13.224","2108"],["15.057","1164"],["15.061","1056"]],"a":[["15.852","2108"],["16.908","2108"],["19.626","2811"],["62.499","17572"]]}}
1626916412.269623: {"stream":"eosusd_perp@depth@100ms","data":{"e":"depthUpdate","E":1626916412296,"T":1626916412283,"s":"EOSUSD_PERP","ps":"EOSUSD","U":167006152693,"u":167006153075,"pu":167006152607,"b":[["3.468","0"]],"a":[["13.735","3725"],["13.737","0"]]}}
1626916412.275004: {"stream":"bchusd_210924@depth@100ms","data":{"e":"depthUpdate","E":1626916412300,"T":1626916412196,"s":"BCHUSD_210924","ps":"BCHUSD","U":167006152704,"u":167006152707,"pu":167006152490,"b":[],"a":[["429.46","40"],["429.58","0"]]}}
1626916412.287711: {"stream":"trxusd_perp@depth@100ms","data":{"e":"depthUpdate","E":1626916412314,"T":1626916412300,"s":"TRXUSD_PERP","ps":"TRXUSD","U":167006152763,"u":167006153161,"pu":167006151487,"b":[],"a":[["0.05348","835"],["0.05349","822"],["0.05350","2883"],["0.05351","2324"]]}}
1626916412.3306398: {"stream":"ethusd_210924@depth@100ms","data":{"e":"depthUpdate","E":1626916412357,"T":1626916412349,"s":"ETHUSD_210924","ps":"ETHUSD","U":167006152932,"u":167006153327,"pu":167006152769,"b":[["1989.32","0"],["1989.58","1820"],["1989.89","0"],["1990.23","50"]],"a":[["1998.00","190"]]}}
1626916412.333824: {"stream":"xrpusd_perp@depth@100ms","data":{"e":"depthUpdate","E":1626916412361,"T":1626916412350,"s":"XRPUSD_PERP","ps":"XRPUSD","U":167006152940,"u":167006153328,"pu":167006152240,"b":[["0.5660","5737"]],"a":[["0.5663","3547"],["0.5664","6771"],["0.5665","3504"],["0.5673","5907"],["0.5674","10868"],["0.5681","2971"],["0.5723","25"]]}}
1626916412.355157: {"stream":"linkusd_perp@depth@100ms","data":{"e":"depthUpdate","E":1626916412383,"T":1626916412377,"s":"LINKUSD_PERP","ps":"LINKUSD","U":167006153059,"u":167006153420,"pu":167006152928,"b":[["15.013","300"],["15.057","548"],["15.061","956"],["15.062","1562"],["15.063","1017"]],"a":[["15.062","0"],["15.110","944"],["15.280","7500"]]}}
1626916412.361682: {"stream":"btcusd_211231@depth@100ms","data":{"e":"depthUpdate","E":1626916412388,"T":1626916412349,"s":"BTCUSD_211231","ps":"BTCUSD","U":167006153083,"u":167006153326,"pu":167006151933,"b":[],"a":[["32695.3","0"],["32708.4","389"]]}}
1626916412.363122: {"stream":"etcusd_perp@depth@100ms","data":{"e":"depthUpdate","E":1626916412390,"T":1626916412285,"s":"ETCUSD_PERP","ps":"ETCUSD","U":167006153101,"u":167006153109,"pu":167006152349,"b":[["42.239","431"],["42.241","1427"]],"a":[]}}
1626916412.438578: {"stream":"xrpusd_perp@depth@100ms","data":{"e":"depthUpdate","E":1626916412465,"T":1626916412456,"s":"XRPUSD_PERP","ps":"XRPUSD","U":167006153372,"u":167006153669,"pu":167006153328,"b":[],"a":[["0.5667","4024"],["0.5898","16794"]]}}
1626916412.438686: {"stream":"ethusd_210924@depth@100ms","data":{"e":"depthUpdate","E":1626916412467,"T":1626916412460,"s":"ETHUSD_210924","ps":"ETHUSD","U":167006153376,"u":167006153672,"pu":167006153327,"b":[["1982.05","1484"],["1989.92","0"],["1990.33","725"]],"a":[["1991.55","270"],["1991.77","0"],["1998.00","0"],["1999.92","0"],["2144.40","2653"],["2145.51","0"]]}}
1626916412.459384: {"stream":"bchusd_perp@depth@100ms","data":{"e":"depthUpdate","E":1626916412487,"T":1626916412384,"s":"BCHUSD_PERP","ps":"BCHUSD","U":167006153450,"u":167006153454,"pu":167006152664,"b":[],"a":[["427.81","100"],["427.88","0"]]}}
1626916412.470237: {"stream":"linkusd_perp@depth@100ms","data":{"e":"depthUpdate","E":1626916412498,"T":1626916412453,"s":"LINKUSD_PERP","ps":"LINKUSD","U":167006153466,"u":167006153662,"pu":167006153420,"b":[["14.957","619"],["15.057","1107"],["15.062","252"]],"a":[["15.074","1397"],["15.166","900"]]}}
1626916412.474546: {"stream":"etcusd_perp@depth@100ms","data":{"e":"depthUpdate","E":1626916412502,"T":1626916412397,"s":"ETCUSD_PERP","ps":"ETCUSD","U":167006153481,"u":167006153493,"pu":167006153109,"b":[],"a":[["42.297","22"],["42.310","684"]]}}
1626916412.494324: {"stream":"btcusd_211231@depth@100ms","data":{"e":"depthUpdate","E":1626916412520,"T":1626916412503,"s":"BTCUSD_211231","ps":"BTCUSD","U":167006153553,"u":167006153828,"pu":167006153326,"b":[["32527.2","0"],["32527.4","1675"],["32605.9","12"]],"a":[["33029.4","0"],["33189.4","0"],["33349.5","0"],["33509.5","0"],["33669.5","0"]]}}
1626916412.543443: {"stream":"eosusd_perp@depth@100ms","data":{"e":"depthUpdate","E":1626916412568,"T":1626916412484,"s":"EOSUSD_PERP","ps":"EOSUSD","U":167006153677,"u":167006153774,"pu":167006153075,"b":[["3.468","0"]],"a":[["3.468","210"]]}}
1626916412.550464: {"stream":"xrpusd_perp@depth@100ms","data":{"e":"depthUpdate","E":1626916412578,"T":1626916412552,"s":"XRPUSD_PERP","ps":"XRPUSD","U":167006153729,"u":167006154038,"pu":167006153669,"b":[["0.5622","916"],["0.5654","7598"],["0.5660","6037"]],"a":[["0.5662","500"],["0.5701","2144"]]}}
1626916412.59149: {"stream":"linkusd_211231@depth@100ms","data":{"e":"depthUpdate","E":1626916412617,"T":1626916412566,"s":"LINKUSD_211231","ps":"LINKUSD","U":167006153864,"u":167006154110,"pu":167006150286,"b":[["15.288","3142"],["15.294","123"]],"a":[["15.341","1973"],["15.525","164"],["15.600","203"],["15.675","166"],["15.751","167"],["15.826","168"]]}}
1626916412.59555: {"stream":"linkusd_perp@depth@100ms","data":{"e":"depthUpdate","E":1626916412621,"T":1626916412614,"s":"LINKUSD_PERP","ps":"LINKUSD","U":167006153881,"u":167006154319,"pu":167006153662,"b":[["15.037","3018"],["15.041","1094"],["15.051","2964"],["15.052","580"],["15.053","3279"],["15.054","100"],["15.055","528"],["15.056","1813"],["15.058","320"],["15.061","649"],["15.063","691"]],"a":[["15.076","804"],["15.078","751"]]}}
1626916412.6192188: {"stream":"etcusd_perp@depth@100ms","data":{"e":"depthUpdate","E":1626916412646,"T":1626916412632,"s":"ETCUSD_PERP","ps":"ETCUSD","U":167006153998,"u":167006154454,"pu":167006153493,"b":[],"a":[["42.336","340"],["42.368","600"],["762.588","158542"],["762.597","0"]]}}
1626916412.643819: {"stream":"btcusd_211231@depth@100ms","data":{"e":"depthUpdate","E":1626916412669,"T":1626916412659,"s":"BTCUSD_211231","ps":"BTCUSD","U":167006154099,"u":167006154616,"pu":167006153828,"b":[],"a":[["32629.2","0"],["32629.3","239"],["32631.6","0"],["32638.4","0"],["36322.1","0"]]}}
1626916412.698587: {"stream":"linkusd_perp@depth@100ms","data":{"e":"depthUpdate","E":1626916412725,"T":1626916412716,"s":"LINKUSD_PERP","ps":"LINKUSD","U":167006154356,"u":167006155027,"pu":167006154319,"b":[["15.050","260"],["15.051","2147"],["15.052","680"],["15.054","100"],["15.055","148"],["15.056","2013"],["15.058","20"],["15.061","459"],["15.062","62"],["15.063","212"]],"a":[["15.067","388"],["15.069","3149"],["15.070","2257"],["15.071","958"],["15.074","1777"],["15.076","424"]]}}
1626916412.720056: {"stream":"trxusd_perp@depth@100ms","data":{"e":"depthUpdate","E":1626916412746,"T":1626916412714,"s":"TRXUSD_PERP","ps":"TRXUSD","U":167006154508,"u":167006155013,"pu":167006153161,"b":[],"a":[["0.05347","20642"],["0.05348","735"],["0.05349","822"],["0.05350","2883"],["0.05351","2324"]]}}
1626916412.7231: {"stream":"ethusd_210924@depth@100ms","data":{"e":"depthUpdate","E":1626916412748,"T":1626916412740,"s":"ETHUSD_210924","ps":"ETHUSD","U":167006154529,"u":167006155173,"pu":167006153672,"b":[["1981.99","0"],["1986.32","0"],["1986.99","500"],["1987.02","0"],["1987.07","0"],["1987.20","0"],["1987.43","0"],["1987.62","0"],["1987.74","0"],["1987.86","1723"],["1987.89","0"],["1988.08","0"],["1988.23","0"],["1988.40","0"],["1988.46","0"],["1988.47","372"],["1988.51","0"],["1988.55","304"],["1988.68","1098"],["1988.71","0"],["1988.78","0"],["1988.87","405"],["1988.88","0"],["1988.98","0"],["1989.04","0"],["1989.14","6921"]],"a":[["1991.55","270"],["1991.77","0"],["1992.68","363"],["1993.20","0"],["1993.21","0"],["1993.37","0"],["1993.53","0"],["1994.22","0"],["1994.23","0"],["1994.25","12"],["1994.26","0"],["1994.36","0"],["1994.37","1957"],["1994.47","0"],["1994.51","0"],["1994.55","0"],["1994.64","3783"],["1994.66","0"],["1994.80","0"],["1994.96","0"],["1995.16","0"],["1995.67","0"],["1995.72","0"],["1995.92","0"],["1996.44","0"]]}}
1626916412.742877: {"stream":"linkusd_211231@depth@100ms","data":{"e":"depthUpdate","E":1626916412769,"T":1626916412733,"s":"LINKUSD_211231","ps":"LINKUSD","U":167006154667,"u":167006155134,"pu":167006154110,"b":[["14.759","100"],["14.835","100"],["14.910","100"],["14.985","676"],["15.061","100"],["15.292","150"]],"a":[["15.324","1692"],["15.325","0"],["15.330","212"]]}}
1626916412.743472: {"stream":"bchusd_perp@depth@100ms","data":{"e":"depthUpdate","E":1626916412772,"T":1626916412742,"s":"BCHUSD_PERP","ps":"BCHUSD","U":167006154687,"u":167006155175,"pu":167006153454,"b":[["427.51","295"],["427.56","943"],["427.57","100"],["427.64","1076"],["427.65","560"]],"a":[]}}
1626916412.749475: {"stream":"etcusd_perp@depth@100ms","data":{"e":"depthUpdate","E":1626916412778,"T":1626916412692,"s":"ETCUSD_PERP","ps":"ETCUSD","U":167006154720,"u":167006154859,"pu":167006154454,"b":[["37.000","37"]],"a":[["42.275","559"],["42.276","739"]]}}
1626916412.765783: {"stream":"btcusd_211231@depth@100ms","data":{"e":"depthUpdate","E":1626916412793,"T":1626916412781,"s":"BTCUSD_211231","ps":"BTCUSD","U":167006154825,"u":167006155343,"pu":167006154616,"b":[],"a":[["32629.3","0"],["32629.4","0"],["32629.8","0"],["32631.6","153"],["32638.4","0"],["32639.2","0"],["36427.3","363"]]}}
1626916412.787374: {"stream":"eosusd_perp@depth@100ms","data":{"e":"depthUpdate","E":1626916412813,"T":1626916412805,"s":"EOSUSD_PERP","ps":"EOSUSD","U":167006154974,"u":167006155441,"pu":167006153774,"b":[["3.457","3136"],["3.460","3348"],["3.465","7395"],["3.466","7296"],["3.468","0"]],"a":[["3.470","3608"]]}}
1626916412.804595: {"stream":"bchusd_210924@depth@100ms","data":{"e":"depthUpdate","E":1626916412829,"T":1626916412764,"s":"BCHUSD_210924","ps":"BCHUSD","U":167006155078,"u":167006155257,"pu":167006152707,"b":[["428.93","415"],["429.11","0"],["429.23","40"]],"a":[]}}
1626916412.810803: {"stream":"linkusd_perp@depth@100ms","data":{"e":"depthUpdate","E":1626916412837,"T":1626916412821,"s":"LINKUSD_PERP","ps":"LINKUSD","U":167006155132,"u":167006155530,"pu":167006155027,"b":[["15.039","454"],["15.048","251"],["15.052","780"],["15.054","0"],["15.055","110"],["15.057","959"],["15.059","0"],["15.062","162"],["15.063","56"]],"a":[["15.067","100"],["15.068","0"]]}}
1626916412.8227232: {"stream":"ethusd_210924@depth@100ms","data":{"e":"depthUpdate","E":1626916412849,"T":1626916412845,"s":"ETHUSD_210924","ps":"ETHUSD","U":167006155194,"u":167006155661,"pu":167006155173,"b":[["1987.38","627"],["1987.53","532"],["1987.58","501"],["1987.74","401"],["1987.82","469"],["1987.97","321"],["1988.09","414"],["1988.62","289"],["1989.75","0"]],"a":[["1991.55","0"],["1991.77","270"],["1993.06","289"],["1993.31","321"],["1993.32","414"],["1993.46","469"],["1993.47","401"],["1993.56","532"],["1993.71","501"],["1994.17","627"],["1997.70","190"]]}}
1626916412.823104: {"stream":"trxusd_perp@depth@100ms","data":{"e":"depthUpdate","E":1626916412850,"T":1626916412791,"s":"TRXUSD_PERP","ps":"TRXUSD","U":167006155206,"u":167006155392,"pu":167006155013,"b":[["0.05307","387"],["0.05310","574"],["0.05327","132"],["0.05330","252"]],"a":[["0.05349","1122"],["0.05363","23820"],["0.05366","1233"],["0.05383","273"],["0.05386","319"]]}}
1626916412.851594: {"stream":"xrpusd_perp@depth@100ms","data":{"e":"depthUpdate","E":1626916412878,"T":1626916412863,"s":"XRPUSD_PERP","ps":"XRPUSD","U":167006155309,"u":167006155754,"pu":167006154038,"b":[["0.5660","6037"]],"a":[["0.5662","501"],["0.5663","3517"],["0.5671","2457"],["0.5683","1722"]]}}
1626916412.872731: {"stream":"btcusd_211231@depth@100ms","data":{"e":"depthUpdate","E":1626916412900,"T":1626916412890,"s":"BTCUSD_211231","ps":"BTCUSD","U":167006155402,"u":167006155954,"pu":167006155343,"b":[["32476.1","0"],["32484.3","2"],["32516.8","1841"],["32527.4","0"],["32596.3","20"]],"a":[["32631.6","0"],["32637.5","46"],["32638.4","153"],["32641.8","30"]]}}
1626916412.893961: {"stream":"eosusd_perp@depth@100ms","data":{"e":"depthUpdate","E":1626916412920,"T":1626916412885,"s":"EOSUSD_PERP","ps":"EOSUSD","U":167006155480,"u":167006155914,"pu":167006155441,"b":[["3.465","5091"],["3.466","9600"],["3.468","0"]],"a":[["3.470","3981"],["3.471","4514"]]}}
1626916412.900892: {"stream":"bchusd_perp@depth@100ms","data":{"e":"depthUpdate","E":1626916412926,"T":1626916412908,"s":"BCHUSD_PERP","ps":"BCHUSD","U":167006155538,"u":167006156103,"pu":167006155175,"b":[["427.57","0"],["427.66","127"]],"a":[["427.81","0"],["427.88","100"]]}}
1626916412.922173: {"stream":"ethusd_210924@depth@100ms","data":{"e":"depthUpdate","E":1626916412950,"T":1626916412934,"s":"ETHUSD_210924","ps":"ETHUSD","U":167006155666,"u":167006156292,"pu":167006155661,"b":[["1986.43","1492"],["1987.96","406"],["1987.99","372"],["1988.02","914"],["1988.07","2108"],["1988.10","541"],["1988.25","338"],["1988.42","458"],["1988.49","643"],["1988.55","0"],["1988.73","237"],["1988.94","203"],["1989.02","169"],["1989.12","169"],["1989.25","203"],["1990.29","663"],["1990.59","0"],["1990.81","270"],["1990.98","2129"]],"a":[["1991.76","270"],["1991.77","0"],["1991.84","0"],["1992.05","0"],["1992.27","0"],["1993.95","169"],["1994.00","169"],["1994.22","203"],["1994.46","338"],["1994.53","237"],["1994.59","338"],["1994.61","372"],["1994.63","237"],["1995.00","304"],["1995.01","541"],["1995.11","406"],["1995.47","440"],["1995.65","440"],["1995.89","486"],["1996.06","474"]]}}
1626916412.926023: {"stream":"linkusd_perp@depth@100ms","data":{"e":"depthUpdate","E":1626916412946,"T":1626916412926,"s":"LINKUSD_PERP","ps":"LINKUSD","U":167006155639,"u":167006156257,"pu":167006155530,"b":[["15.048","1448"],["15.050","460"],["15.052","480"],["15.054","100"],["15.055","0"],["15.059","110"],["15.062","62"],["15.063","156"]],"a":[["15.066","100"],["15.067","88"],["15.068","150"],["15.069","1299"],["15.141","72"],["15.249","1"],["15.395","0"]]}}
1626916412.926235: {"stream":"trxusd_perp@depth@100ms","data":{"e":"depthUpdate","E":1626916412952,"T":1626916412867,"s":"TRXUSD_PERP","ps":"TRXUSD","U":167006155676,"u":167006155771,"pu":167006155392,"b":[["0.05307","693"],["0.05327","287"]],"a":[["0.05366","1386"],["0.05386","622"]]}}
1626916412.9417942: {"stream":"etcusd_perp@depth@100ms","data":{"e":"depthUpdate","E":1626916412969,"T":1626916412942,"s":"ETCUSD_PERP","ps":"ETCUSD","U":167006155765,"u":167006156327,"pu":167006154859,"b":[["42.186","497"],["42.213","1111"],["42.220","1467"],["42.233","1497"],["42.236","512"],["42.237","671"],["42.239","0"],["42.240","33"],["42.241","90"],["42.242","0"],["42.246","280"],["42.249","0"]],"a":[["42.266","657"],["42.270","0"],["42.275","0"],["42.276","478"],["42.289","322"],["42.310","784"],["42.318","0"],["42.319","0"]]}}
1626916412.9548512: {"stream":"xrpusd_perp@depth@100ms","data":{"e":"depthUpdate","E":1626916412981,"T":1626916412973,"s":"XRPUSD_PERP","ps":"XRPUSD","U":167006155841,"u":167006156500,"pu":167006155754,"b":[["0.5644","3648"],["0.5645","27567"]],"a":[["0.5664","5771"],["0.5680","1682"],["0.5682","36597"]]}}
1626916412.983371: {"stream":"btcusd_211231@depth@100ms","data":{"e":"depthUpdate","E":1626916413010,"T":1626916412997,"s":"BTCUSD_211231","ps":"BTCUSD","U":167006156064,"u":167006156633,"pu":167006155954,"b":[["32623.3","0"],["32625.0","15"],["32627.9","0"]],"a":[["32623.4","0"],["32625.1","12"],["32625.5","16"],["32625.8","0"],["32626.1","0"],["32626.8","0"],["32627.2","0"],["32628.0","0"],["32629.7","0"],["32629.8","153"],["32629.9","0"],["32630.4","0"],["32631.6","1"],["32637.4","0"],["32637.9","98"],["32638.3","78"],["32638.4","0"],["33371.9","0"]]}}
1626916412.997702: {"stream":"linkusd_211231@depth@100ms","data":{"e":"depthUpdate","E":1626916413023,"T":1626916412980,"s":"LINKUSD_211231","ps":"LINKUSD","U":167006156191,"u":167006156517,"pu":167006155134,"b":[["3.142","771"],["15.289","1067"]],"a":[["15.324","0"],["15.329","1223"]]}}
1626916413.025571: {"stream":"ethusd_210924@depth@100ms","data":{"e":"depthUpdate","E":1626916413052,"T":1626916412972,"s":"ETHUSD_210924","ps":"ETHUSD","U":167006156349,"u":167006156492,"pu":167006156292,"b":[["1990.81","0"],["1990.98","2399"]],"a":[["1994.73","203"]]}}
1626916413.033319: {"stream":"linkusd_perp@depth@100ms","data":{"e":"depthUpdate","E":1626916413059,"T":1626916413052,"s":"LINKUSD_PERP","ps":"LINKUSD","U":167006156386,"u":167006156848,"pu":167006156257,"b":[["15.051","1767"],["15.052","860"],["15.058","20"],["15.059","0"],["15.062","62"],["15.063","266"]],"a":[["15.071","728"],["15.135","621"],["15.229","1965"],["15.378","1522"]]}}
1626916413.044092: {"stream":"etcusd_perp@depth@100ms","data":{"e":"depthUpdate","E":1626916413070,"T":1626916413026,"s":"ETCUSD_PERP","ps":"ETCUSD","U":167006156428,"u":167006156754,"pu":167006156327,"b":[["42.240","0"],["42.254","28"]],"a":[["42.300","200"],["42.315","256"],["42.320","0"],["42.331","210"],["42.336","340"],["42.341","415"]]}}
1626916413.057238: {"stream":"xrpusd_perp@depth@100ms","data":{"e":"depthUpdate","E":1626916413084,"T":1626916413074,"s":"XRPUSD_PERP","ps":"XRPUSD","U":167006156515,"u":167006156954,"pu":167006156500,"b":[["0.5646","713"],["0.5648","1940"],["0.5656","6748"],["0.5657","5704"],["0.5658","2255"],["0.5660","5581"],["0.5661","6287"]],"a":[["0.5663","2510"],["0.5664","5471"],["0.5665","4069"],["0.5667","2100"],["0.5668","5642"],["0.5669","5598"],["0.5670","6629"]]}}
1626916413.062243: {"stream":"bchusd_perp@depth@100ms","data":{"e":"depthUpdate","E":1626916413089,"T":1626916413066,"s":"BCHUSD_PERP","ps":"BCHUSD","U":167006156549,"u":167006156912,"pu":167006156103,"b":[["427.77","151"]],"a":[["427.81","100"],["427.88","0"]]}}
1626916413.0839329: {"stream":"btcusd_211231@depth@100ms","data":{"e":"depthUpdate","E":1626916413110,"T":1626916413086,"s":"BTCUSD_211231","ps":"BTCUSD","U":167006156666,"u":167006157035,"pu":167006156633,"b":[["31365.1","0"],["31525.1","0"],["31685.2","0"],["31845.2","0"],["32005.2","0"],["32625.0","77"]],"a":[["32629.8","0"],["32631.5","153"],["32675.8","519"],["33031.0","45"],["33191.0","45"],["33351.1","45"],["33511.1","46"],["33671.1","46"]]}}
1626916413.1379259: {"stream":"linkusd_211231@depth@100ms","data":{"e":"depthUpdate","E":1626916413165,"T":1626916413159,"s":"LINKUSD_211231","ps":"LINKUSD","U":167006156877,"u":167006157319,"pu":167006156517,"b":[["14.759","0"],["14.835","0"],["14.910","0"],["14.985","576"],["15.061","0"]],"a":[["15.326","140"],["15.329","1178"],["15.525","0"],["15.600","38"],["15.675","0"],["15.751","0"],["15.826","0"]]}}
1626916413.138186: {"stream":"ethusd_210924@depth@100ms","data":{"e":"depthUpdate","E":1626916413165,"T":1626916413131,"s":"ETHUSD_210924","ps":"ETHUSD","U":167006156878,"u":167006157205,"pu":167006156492,"b":[["1989.58","0"],["1989.95","984"]],"a":[["1991.55","270"],["1991.76","0"],["2002.89","700"],["2006.88","701"]]}}
1626916413.1576: {"stream":"xrpusd_perp@depth@100ms","data":{"e":"depthUpdate","E":1626916413185,"T":1626916413175,"s":"XRPUSD_PERP","ps":"XRPUSD","U":167006157003,"u":167006157403,"pu":167006156954,"b":[["0.5618","28"],["0.5641","7835"],["0.5651","5251"],["0.5657","5825"],["0.5659","3058"]],"a":[["0.5664","5471"],["0.5666","1759"],["0.5667","2065"],["0.5674","13130"],["0.5675","1708"]]}}
1626916413.167577: {"stream":"etcusd_perp@depth@100ms","data":{"e":"depthUpdate","E":1626916413197,"T":1626916413126,"s":"ETCUSD_PERP","ps":"ETCUSD","U":167006157070,"u":167006157199,"pu":167006156754,"b":[],"a":[["42.290","33"],["42.309","1863"],["42.310","100"]]}}
1626916413.2214358: {"stream":"linkusd_perp@depth@100ms","data":{"e":"depthUpdate","E":1626916413249,"T":1626916413144,"s":"LINKUSD_PERP","ps":"LINKUSD","U":167006157259,"u":167006157259,"pu":167006156848,"b":[],"a":[["15.071","2562"]]}}
1626916413.2362812: {"stream":"btcusd_211231@depth@100ms","data":{"e":"depthUpdate","E":1626916413263,"T":1626916413255,"s":"BTCUSD_211231","ps":"BTCUSD","U":167006157320,"u":167006157810,"pu":167006157035,"b":[["31366.6","55"],["31526.6","55"],["31686.7","55"],["31846.7","55"],["32006.8","55"]],"a":[["32631.5","153"],["32637.4","0"],["32648.3","0"],["32708.4","0"],["33327.7","332"]]}}
1626916413.240437: {"stream":"ethusd_210924@depth@100ms","data":{"e":"depthUpdate","E":1626916413267,"T":1626916413250,"s":"ETHUSD_210924","ps":"ETHUSD","U":167006157348,"u":167006157786,"pu":167006157205,"b":[["1988.12","304"]],"a":[["1997.70","0"],["1998.00","190"]]}}
1626916413.253273: {"stream":"bchusd_perp@depth@100ms","data":{"e":"depthUpdate","E":1626916413281,"T":1626916413268,"s":"BCHUSD_PERP","ps":"BCHUSD","U":167006157385,"u":167006157912,"pu":167006156912,"b":[["427.61","0"],["427.66","127"],["427.77","151"]],"a":[["427.81","0"],["427.88","100"],["428.06","1958"],["428.11","100"]]}}
1626916413.316826: {"stream":"xrpusd_perp@depth@100ms","data":{"e":"depthUpdate","E":1626916413342,"T":1626916413271,"s":"XRPUSD_PERP","ps":"XRPUSD","U":167006157697,"u":167006157933,"pu":167006157403,"b":[],"a":[["0.5664","5311"],["0.5665","3769"],["0.5666","1919"]]}}
1626916413.3386: {"stream":"linkusd_perp@depth@100ms","data":{"e":"depthUpdate","E":1626916413364,"T":1626916413356,"s":"LINKUSD_PERP","ps":"LINKUSD","U":167006157829,"u":167006158409,"pu":167006157259,"b":[["15.039","254"],["15.048","1648"],["15.052","860"],["15.054","100"],["15.059","0"],["15.062","172"],["15.063","156"]],"a":[["15.099","767"],["15.123","0"]]}}
1626916413.338804: {"stream":"btcusd_211231@depth@100ms","data":{"e":"depthUpdate","E":1626916413366,"T":1626916413360,"s":"BTCUSD_211231","ps":"BTCUSD","U":167006157866,"u":167006158435,"pu":167006157810,"b":[["32379.1","313"],["32516.8","0"],["32527.4","1841"],["32581.7","0"],["32612.2","31"]],"a":[["32631.5","0"],["32631.7","0"],["32636.5","46"],["32637.3","184"],["32637.4","153"],["32637.5","0"],["32712.4","381"]]}}
1626916413.33901: {"stream":"bchusd_210924@depth@100ms","data":{"e":"depthUpdate","E":1626916413366,"T":1626916413327,"s":"BCHUSD_210924","ps":"BCHUSD","U":167006157862,"u":167006158186,"pu":167006155257,"b":[["429.04","3235"]],"a":[["429.47","0"],["429.55","60"],["429.72","0"]]}}
1626916413.342562: {"stream":"eosusd_perp@depth@100ms","data":{"e":"depthUpdate","E":1626916413369,"T":1626916413312,"s":"EOSUSD_PERP","ps":"EOSUSD","U":167006157889,"u":167006158107,"pu":167006155914,"b":[["3.465","5091"],["3.466","9536"],["3.468","0"]],"a":[["3.470","3881"],["3.471","4614"]]}}
1626916413.358846: {"stream":"ethusd_210924@depth@100ms","data":{"e":"depthUpdate","E":1626916413386,"T":1626916413348,"s":"ETHUSD_210924","ps":"ETHUSD","U":167006157991,"u":167006158323,"pu":167006157786,"b":[],"a":[["1991.55","270"],["1991.77","0"],["1998.00","0"]]}}
1626916413.367456: {"stream":"bchusd_perp@depth@100ms","data":{"e":"depthUpdate","E":1626916413394,"T":1626916413289,"s":"BCHUSD_PERP","ps":"BCHUSD","U":167006158027,"u":167006158030,"pu":167006157912,"b":[],"a":[["427.81","100"],["427.88","0"]]}}
1626916413.404948: {"stream":"etcusd_perp@depth@100ms","data":{"e":"depthUpdate","E":1626916413431,"T":1626916413406,"s":"ETCUSD_PERP","ps":"ETCUSD","U":167006158184,"u":167006158666,"pu":167006157199,"b":[["42.230","50"]],"a":[["42.255","1"]]}}
1626916413.435464: {"stream":"xrpusd_perp@depth@100ms","data":{"e":"depthUpdate","E":1626916413460,"T":1626916413446,"s":"XRPUSD_PERP","ps":"XRPUSD","U":167006158404,"u":167006158815,"pu":167006157933,"b":[["0.5660","5581"]],"a":[["0.5662","500"],["0.5664","5471"],["0.5666","1759"]]}}
1626916413.44532: {"stream":"bchusd_210924@depth@100ms","data":{"e":"depthUpdate","E":1626916413471,"T":1626916413386,"s":"BCHUSD_210924","ps":"BCHUSD","U":167006158458,"u":167006158579,"pu":167006158186,"b":[],"a":[["429.46","0"],["429.54","40"],["429.86","0"],["429.92","282"],["430.26","121"]]}}
1626916413.445531: {"stream":"btcusd_211231@depth@100ms","data":{"e":"depthUpdate","E":1626916413473,"T":1626916413414,"s":"BTCUSD_211231","ps":"BTCUSD","U":167006158477,"u":167006158722,"pu":167006158435,"b":[["32590.5","240"],["32616.8","10"]],"a":[["32631.5","153"],["32635.5","0"],["32636.4","0"],["32636.5","0"],["32637.4","0"],["32639.1","10"]]}}
1626916413.462416: {"stream":"linkusd_perp@depth@100ms","data":{"e":"depthUpdate","E":1626916413489,"T":1626916413383,"s":"LINKUSD_PERP","ps":"LINKUSD","U":167006158567,"u":167006158567,"pu":167006158409,"b":[["15.048","1448"]],"a":[]}}
1626916413.462549: {"stream":"linkusd_211231@depth@100ms","data":{"e":"depthUpdate","E":1626916413489,"T":1626916413387,"s":"LINKUSD_211231","ps":"LINKUSD","U":167006158573,"u":167006158582,"pu":167006157319,"b":[],"a":[["15.326","1318"],["15.329","0"]]}}
1626916413.4778712: {"stream":"bchusd_perp@depth@100ms","data":{"e":"depthUpdate","E":1626916413504,"T":1626916413467,"s":"BCHUSD_PERP","ps":"BCHUSD","U":167006158640,"u":167006158886,"pu":167006158030,"b":[["427.61","100"],["427.64","300"],["427.65","290"],["427.66","27"],["427.77","175"]],"a":[["427.81","150"],["427.88","100"]]}}
1626916413.5143979: {"stream":"ethusd_210924@depth@100ms","data":{"e":"depthUpdate","E":1626916413541,"T":1626916413536,"s":"ETHUSD_210924","ps":"ETHUSD","U":167006158774,"u":167006159174,"pu":167006158323,"b":[["1982.05","0"],["1989.58","1891"],["1989.96","0"]],"a":[["1997.40","190"],["2000.94","499"],["2004.93","500"]]}}
1626916413.5337942: {"stream":"etcusd_perp@depth@100ms","data":{"e":"depthUpdate","E":1626916413562,"T":1626916413553,"s":"ETCUSD_PERP","ps":"ETCUSD","U":167006158857,"u":167006159249,"pu":167006158666,"b":[["42.233","500"],["42.234","1393"]],"a":[["42.255","16"],["42.265","150"],["42.266","400"],["42.269","300"],["42.299","647"],["42.309","1216"]]}}
1626916413.539232: {"stream":"xrpusd_perp@depth@100ms","data":{"e":"depthUpdate","E":1626916413567,"T":1626916413485,"s":"XRPUSD_PERP","ps":"XRPUSD","U":167006158870,"u":167006158968,"pu":167006158815,"b":[["0.5661","6401"]],"a":[["0.5662","650"],["0.5665","4723"]]}}
1626916413.549959: {"stream":"eosusd_perp@depth@100ms","data":{"e":"depthUpdate","E":1626916413577,"T":1626916413485,"s":"EOSUSD_PERP","ps":"EOSUSD","U":167006158898,"u":167006158973,"pu":167006158107,"b":[["3.465","5091"],["3.466","9502"]],"a":[]}}
1626916413.594431: {"stream":"btcusd_211231@depth@100ms","data":{"e":"depthUpdate","E":1626916413621,"T":1626916413607,"s":"BTCUSD_211231","ps":"BTCUSD","U":167006159095,"u":167006159500,"pu":167006158722,"b":[["31366.6","0"],["31526.6","0"],["31686.7","0"],["31846.7","0"],["32006.8","0"],["32592.3","0"]],"a":[["33031.0","0"],["33033.6","45"],["33191.0","0"],["33193.6","45"],["33351.1","0"],["33353.7","45"],["33511.1","0"],["33513.7","46"],["33671.1","0"],["33673.7","46"]]}}
1626916413.6446562: {"stream":"etcusd_perp@depth@100ms","data":{"e":"depthUpdate","E":1626916413673,"T":1626916413615,"s":"ETCUSD_PERP","ps":"ETCUSD","U":167006159311,"u":167006159518,"pu":167006159249,"b":[],"a":[["42.264","242"],["42.268","90"],["42.269","0"],["42.276","0"],["42.277","0"]]}}
1626916413.654279: {"stream":"linkusd_perp@depth@100ms","data":{"e":"depthUpdate","E":1626916413680,"T":1626916413655,"s":"LINKUSD_PERP","ps":"LINKUSD","U":167006159349,"u":167006159676,"pu":167006158567,"b":[["15.048","251"],["15.050","1537"],["15.055","0"],["15.058","130"],["15.059","0"],["15.062","62"]],"a":[]}}
1626916413.692551: {"stream":"bchusd_perp@depth@100ms","data":{"e":"depthUpdate","E":1626916413719,"T":1626916413615,"s":"BCHUSD_PERP","ps":"BCHUSD","U":167006159516,"u":167006159517,"pu":167006158886,"b":[],"a":[["427.81","250"],["427.88","0"]]}}
1626916413.742646: {"stream":"linkusd_211231@depth@100ms","data":{"e":"depthUpdate","E":1626916413769,"T":1626916413750,"s":"LINKUSD_211231","ps":"LINKUSD","U":167006159721,"u":167006160101,"pu":167006158582,"b":[["14.760","1122"],["14.836","100"],["14.911","100"],["14.986","100"],["15.062","100"],["15.279","0"],["15.280","305"],["15.292","0"]],"a":[["15.330","62"]]}}
1626916413.75554: {"stream":"etcusd_perp@depth@100ms","data":{"e":"depthUpdate","E":1626916413783,"T":1626916413734,"s":"ETCUSD_PERP","ps":"ETCUSD","U":167006159780,"u":167006160040,"pu":167006159518,"b":[],"a":[["42.262","150"],["42.263","278"],["42.265","0"],["42.268","0"],["42.277","90"]]}}
1626916413.768254: {"stream":"linkusd_perp@depth@100ms","data":{"e":"depthUpdate","E":1626916413794,"T":1626916413782,"s":"LINKUSD_PERP","ps":"LINKUSD","U":167006159851,"u":167006160256,"pu":167006159676,"b":[["15.030","662"],["15.041","1594"],["15.052","960"],["15.054","0"],["15.058","20"],["15.063","266"]],"a":[["15.070","4064"],["15.071","728"]]}}
1626916413.7796202: {"stream":"btcusd_211231@depth@100ms","data":{"e":"depthUpdate","E":1626916413808,"T":1626916413789,"s":"BTCUSD_211231","ps":"BTCUSD","U":167006159889,"u":167006160303,"pu":167006159500,"b":[["32439.0","0"],["32447.8","86"],["32458.9","0"],["32467.7","216"],["32516.8","2079"],["32527.4","0"],["32536.9","0"],["32545.8","86"],["32582.8","0"],["32590.6","216"],["32595.1","0"],["32606.8","64"]],"a":[["32631.5","153"],["32637.2","0"],["32676.3","0"],["32684.0","64"],["32689.3","0"],["32693.1","216"],["32732.6","0"],["32741.4","86"],["32775.1","0"],["32784.0","216"],["32830.5","0"],["32839.4","86"]]}}
1626916413.823179: {"stream":"bchusd_perp@depth@100ms","data":{"e":"depthUpdate","E":1626916413852,"T":1626916413847,"s":"BCHUSD_PERP","ps":"BCHUSD","U":167006160086,"u":167006160601,"pu":167006159517,"b":[["427.60","896"],["427.77","151"]],"a":[["427.81","150"],["427.88","100"],["430.76","0"]]}}
1626916413.82782: {"stream":"ethusd_210924@depth@100ms","data":{"e":"depthUpdate","E":1626916413855,"T":1626916413846,"s":"ETHUSD_210924","ps":"ETHUSD","U":167006160092,"u":167006160597,"pu":167006159174,"b":[["1986.42","0"],["1987.22","4650"],["1987.32","501"],["1987.33","627"],["1987.37","1532"],["1987.38","0"],["1987.53","0"],["1987.58","0"],["1987.74","401"],["1987.82","469"],["1987.96","0"],["1987.97","321"],["1987.99","0"],["1988.02","0"],["1988.07","1194"],["1988.09","414"],["1988.10","0"],["1988.12","0"],["1988.16","12"],["1988.30","500"],["1988.32","365"],["1988.35","0"],["1988.42","120"],["1988.47","0"],["1988.49","0"],["1988.62","289"],["1988.73","0"],["1988.94","0"],["1989.02","0"],["1989.12","0"],["1989.25","0"]],"a":[["1991.48","361"],["1991.55","270"],["1991.77","0"],["1992.79","0"],["1993.06","289"],["1993.15","365"],["1993.31","321"],["1993.32","414"],["1993.46","469"],["1993.47","401"],["1993.56","532"],["1993.71","501"],["1993.95","0"],["1994.00","0"],["1994.12","627"],["1994.17","0"],["1994.22","0"],["1994.41","783"],["1994.46","0"],["1994.53","0"],["1994.61","0"],["1994.63","0"],["1994.64","3000"],["1994.73","0"],["1994.82","0"],["1994.92","2702"],["1995.00","0"],["1995.01","0"],["1995.11","0"],["1995.14","0"],["1995.31","0"],["1995.47","0"],["1995.65","0"],["1995.89","12"],["1996.06","0"]]}}
1626916413.859606: {"stream":"linkusd_211231@depth@100ms","data":{"e":"depthUpdate","E":1626916413884,"T":1626916413834,"s":"LINKUSD_211231","ps":"LINKUSD","U":167006160233,"u":167006160549,"pu":167006160101,"b":[["15.280","205"],["15.288","2143"],["15.289","0"],["15.290","1162"]],"a":[]}}
1626916413.859794: {"stream":"eosusd_perp@depth@100ms","data":{"e":"depthUpdate","E":1626916413885,"T":1626916413817,"s":"EOSUSD_PERP","ps":"EOSUSD","U":167006160246,"u":167006160441,"pu":167006158973,"b":[["3.468","0"]],"a":[["3.469","1093"],["3.471","5290"]]}}
1626916413.8638122: {"stream":"xrpusd_perp@depth@100ms","data":{"e":"depthUpdate","E":1626916413891,"T":1626916413875,"s":"XRPUSD_PERP","ps":"XRPUSD","U":167006160292,"u":167006160730,"pu":167006158968,"b":[["0.5653","5053"],["0.5654","14504"],["0.5656","7897"],["0.5660","5551"]],"a":[["0.5663","2540"]]}}
1626916413.881023: {"stream":"linkusd_perp@depth@100ms","data":{"e":"depthUpdate","E":1626916413906,"T":1626916413874,"s":"LINKUSD_PERP","ps":"LINKUSD","U":167006160348,"u":167006160727,"pu":167006160256,"b":[["15.021","679"],["15.052","860"],["15.054","249"]],"a":[["15.072","255"],["15.074","1877"],["15.075","674"],["15.077","995"]]}}
1626916413.8939478: {"stream":"bchusd_210924@depth@100ms","data":{"e":"depthUpdate","E":1626916413921,"T":1626916413819,"s":"BCHUSD_210924","ps":"BCHUSD","U":167006160424,"u":167006160463,"pu":167006158579,"b":[],"a":[["429.87","4231"],["429.93","0"]]}}
1626916413.896363: {"stream":"etcusd_perp@depth@100ms","data":{"e":"depthUpdate","E":1626916413923,"T":1626916413818,"s":"ETCUSD_PERP","ps":"ETCUSD","U":167006160443,"u":167006160459,"pu":167006160040,"b":[],"a":[["42.296","654"],["42.299","0"]]}}
1626916413.931185: {"stream":"btcusd_211231@depth@100ms","data":{"e":"depthUpdate","E":1626916413957,"T":1626916413915,"s":"BTCUSD_211231","ps":"BTCUSD","U":167006160624,"u":167006160938,"pu":167006160303,"b":[],"a":[["32631.5","153"],["32637.2","0"],["32637.3","0"],["32675.8","0"]]}}
1626916413.940487: {"stream":"ethusd_210924@depth@100ms","data":{"e":"depthUpdate","E":1626916413966,"T":1626916413960,"s":"ETHUSD_210924","ps":"ETHUSD","U":167006160666,"u":167006161160,"pu":167006160597,"b":[["1969.71","6710"],["1973.01","0"],["1982.05","2000"],["1987.96","406"],["1988.02","474"],["1988.10","541"],["1988.12","304"],["1988.28","304"],["1988.46","237"],["1988.50","237"],["1988.93","181"],["1988.98","203"],["1989.03","181"],["1989.74","301"]],"a":[["1991.55","270"],["1991.77","0"],["1993.84","169"],["1993.85","169"],["1994.34","237"],["1994.48","237"],["1994.82","541"],["1994.94","406"],["1995.07","304"],["1995.72","474"],["1999.92","2000"]]}}
1626916413.9693792: {"stream":"bchusd_perp@depth@100ms","data":{"e":"depthUpdate","E":1626916413997,"T":1626916413978,"s":"BCHUSD_PERP","ps":"BCHUSD","U":167006160807,"u":167006161225,"pu":167006160601,"b":[["426.39","0"],["427.51","25"],["427.61","340"]],"a":[["427.81","250"],["427.88","0"],["429.16","0"],["430.76","610"]]}}
1626916413.9695559: {"stream":"xrpusd_perp@depth@100ms","data":{"e":"depthUpdate","E":1626916413997,"T":1626916413956,"s":"XRPUSD_PERP","ps":"XRPUSD","U":167006160805,"u":167006161141,"pu":167006160730,"b":[["0.5627","3000"],["0.5628","0"],["0.5660","5581"]],"a":[["0.5664","5771"],["0.5665","4423"],["0.5693","8490"],["0.5697","1"],["0.5704","18490"],["0.5706","325"]]}}
1626916413.990437: {"stream":"linkusd_perp@depth@100ms","data":{"e":"depthUpdate","E":1626916414017,"T":1626916414003,"s":"LINKUSD_PERP","ps":"LINKUSD","U":167006160905,"u":167006161341,"pu":167006160727,"b":[["15.050","460"],["15.053","4293"],["15.057","959"],["15.063","266"]],"a":[["15.074","2077"],["15.076","424"],["15.077","795"]]}}
1626916414.0022452: {"stream":"eosusd_perp@depth@100ms","data":{"e":"depthUpdate","E":1626916414027,"T":1626916413923,"s":"EOSUSD_PERP","ps":"EOSUSD","U":167006160959,"u":167006160960,"pu":167006160441,"b":[],"a":[["3.485","5427"],["3.486","437"]]}}
1626916414.006529: {"stream":"trxusd_perp@depth@100ms","data":{"e":"depthUpdate","E":1626916414034,"T":1626916414020,"s":"TRXUSD_PERP","ps":"TRXUSD","U":167006160976,"u":167006161406,"pu":167006155771,"b":[["0.05309","110"],["0.05311","2057"],["0.05320","2567"],["0.05321","5969"],["0.05328","2715"],["0.05329","1705"]],"a":[["0.05364","2231"],["0.05366","1135"],["0.05370","90"],["0.05371","437"]]}}
1626916414.018062: {"stream":"linkusd_211231@depth@100ms","data":{"e":"depthUpdate","E":1626916414045,"T":1626916413942,"s":"LINKUSD_211231","ps":"LINKUSD","U":167006161040,"u":167006161071,"pu":167006160549,"b":[["15.290","0"],["15.293","1285"]],"a":[]}}
1626916414.042091: {"stream":"ethusd_210924@depth@100ms","data":{"e":"depthUpdate","E":1626916414067,"T":1626916414061,"s":"ETHUSD_210924","ps":"ETHUSD","U":167006161168,"u":167006161566,"pu":167006161160,"b":[["1988.13","440"],["1988.14","474"],["1988.17","372"],["1988.23","372"],["1988.25","744"],["1988.42","458"],["1988.43","1372"],["1988.58","203"]],"a":[["1991.55","0"],["1992.05","270"],["1994.29","338"],["1994.44","372"],["1994.57","203"],["1994.60","372"],["1994.71","1270"],["1994.81","304"],["1994.92","3108"],["1995.47","440"],["1995.60","190"],["1995.89","486"],["1997.40","0"]]}}
1626916414.0935621: {"stream":"btcusd_211231@depth@100ms","data":{"e":"depthUpdate","E":1626916414120,"T":1626916414053,"s":"BTCUSD_211231","ps":"BTCUSD","U":167006161398,"u":167006161550,"pu":167006160938,"b":[],"a":[["32625.1","13"],["32631.6","0"]]}}
1626916414.1129248: {"stream":"xrpusd_perp@depth@100ms","data":{"e":"depthUpdate","E":1626916414138,"T":1626916414046,"s":"XRPUSD_PERP","ps":"XRPUSD","U":167006161462,"u":167006161508,"pu":167006161141,"b":[["0.5655","6925"],["0.5660","5175"],["0.5661","6345"]],"a":[["0.5655","0"],["0.5662","2130"]]}}
1626916414.113003: {"stream":"trxusd_perp@depth@100ms","data":{"e":"depthUpdate","E":1626916414141,"T":1626916414049,"s":"TRXUSD_PERP","ps":"TRXUSD","U":167006161469,"u":167006161530,"pu":167006161406,"b":[["0.05309","2110"]],"a":[["0.05371","439"]]}}
1626916414.12363: {"stream":"bchusd_210924@depth@100ms","data":{"e":"depthUpdate","E":1626916414150,"T":1626916414140,"s":"BCHUSD_210924","ps":"BCHUSD","U":167006161506,"u":167006161921,"pu":167006160463,"b":[],"a":[["429.52","40"],["429.53","20"],["429.54","0"],["429.55","0"],["1722.13","0"],["1722.46","12141"]]}}
1626916414.145854: {"stream":"ethusd_210924@depth@100ms","data":{"e":"depthUpdate","E":1626916414171,"T":1626916414161,"s":"ETHUSD_210924","ps":"ETHUSD","U":167006161589,"u":167006162005,"pu":167006161566,"b":[["1990.98","1849"]],"a":[["1991.55","270"],["1991.77","0"],["1992.05","0"],["1992.27","0"]]}}
1626916414.153955: {"stream":"bchusd_perp@depth@100ms","data":{"e":"depthUpdate","E":1626916414180,"T":1626916414154,"s":"BCHUSD_PERP","ps":"BCHUSD","U":167006161649,"u":167006161973,"pu":167006161225,"b":[["424.65","612"],["427.61","240"],["427.66","127"],["427.67","299"]],"a":[["427.81","150"],["427.88","100"],["430.90","600"]]}}
1626916414.154163: {"stream":"linkusd_perp@depth@100ms","data":{"e":"depthUpdate","E":1626916414178,"T":1626916414117,"s":"LINKUSD_PERP","ps":"LINKUSD","U":167006161638,"u":167006161829,"pu":167006161341,"b":[],"a":[["15.074","2077"],["15.076","424"]]}}
1626916414.205934: {"stream":"btcusd_211231@depth@100ms","data":{"e":"depthUpdate","E":1626916414231,"T":1626916414207,"s":"BTCUSD_211231","ps":"BTCUSD","U":167006161861,"u":167006162216,"pu":167006161550,"b":[["31365.2","55"],["31525.2","55"],["31685.2","55"],["31845.3","55"],["32005.3","55"],["32516.8","0"],["32526.6","2079"]],"a":[["32631.5","0"],["32636.8","46"],["32637.7","169"],["32637.8","153"]]}}
1626916414.2180219: {"stream":"xrpusd_perp@depth@100ms","data":{"e":"depthUpdate","E":1626916414244,"T":1626916414158,"s":"XRPUSD_PERP","ps":"XRPUSD","U":167006161919,"u":167006161999,"pu":167006161508,"b":[["0.5661","6010"]],"a":[["0.5662","985"],["0.5663","3133"]]}}
1626916414.2417789: {"stream":"etcusd_perp@depth@100ms","data":{"e":"depthUpdate","E":1626916414270,"T":1626916414261,"s":"ETCUSD_PERP","ps":"ETCUSD","U":167006162023,"u":167006162449,"pu":167006160459,"b":[["42.223","247"],["42.228","0"]],"a":[["42.263","0"],["42.264","0"],["42.266","500"],["42.267","300"]]}}
1626916414.252458: {"stream":"linkusd_perp@depth@100ms","data":{"e":"depthUpdate","E":1626916414278,"T":1626916414174,"s":"LINKUSD_PERP","ps":"LINKUSD","U":167006162051,"u":167006162054,"pu":167006161829,"b":[],"a":[["15.072","355"],["15.074","1977"]]}}
1626916414.257536: {"stream":"ethusd_210924@depth@100ms","data":{"e":"depthUpdate","E":1626916414284,"T":1626916414262,"s":"ETHUSD_210924","ps":"ETHUSD","U":167006162084,"u":167006162451,"pu":167006162005,"b":[["1988.12","744"],["1990.80","0"]],"a":[["1990.99","930"],["1991.21","170"],["1991.22","480"],["1991.55","0"],["1991.77","270"],["1992.05","0"],["1994.06","203"],["1995.32","440"],["2023.52","408"],["2033.44","410"],["2043.36","2963"],["2053.28","414"],["2063.20","416"]]}}
1626916414.2578409: {"stream":"bchusd_210924@depth@100ms","data":{"e":"depthUpdate","E":1626916414284,"T":1626916414181,"s":"BCHUSD_210924","ps":"BCHUSD","U":167006162083,"u":167006162083,"pu":167006161921,"b":[],"a":[["429.76","148"]]}}
1626916414.25827: {"stream":"bchusd_perp@depth@100ms","data":{"e":"depthUpdate","E":1626916414286,"T":1626916414185,"s":"BCHUSD_PERP","ps":"BCHUSD","U":167006162096,"u":167006162099,"pu":167006161973,"b":[],"a":[["427.80","100"],["427.88","0"]]}}
1626916414.308799: {"stream":"btcusd_211231@depth@100ms","data":{"e":"depthUpdate","E":1626916414334,"T":1626916414261,"s":"BTCUSD_211231","ps":"BTCUSD","U":167006162317,"u":167006162448,"pu":167006162216,"b":[],"a":[["32635.8","46"],["32636.7","153"],["32636.8","0"],["32637.8","0"],["32699.6","375"],["32712.4","0"]]}}
1626916414.3381991: {"stream":"eosusd_perp@depth@100ms","data":{"e":"depthUpdate","E":1626916414365,"T":1626916414328,"s":"EOSUSD_PERP","ps":"EOSUSD","U":167006162430,"u":167006162741,"pu":167006160960,"b":[["3.466","7602"],["3.467","3268"],["3.468","0"]],"a":[]}}
1626916414.358082: {"stream":"ethusd_210924@depth@100ms","data":{"e":"depthUpdate","E":1626916414386,"T":1626916414371,"s":"ETHUSD_210924","ps":"ETHUSD","U":167006162513,"u":167006162891,"pu":167006162451,"b":[["1981.60","1484"],["1990.59","270"],["1990.98","1579"]],"a":[["1991.47","270"],["1991.77","0"],["1992.69","12291"],["2002.89","0"],["2006.88","0"]]}}
1626916414.369693: {"stream":"linkusd_perp@depth@100ms","data":{"e":"depthUpdate","E":1626916414396,"T":1626916414390,"s":"LINKUSD_PERP","ps":"LINKUSD","U":167006162563,"u":167006163060,"pu":167006162054,"b":[["15.021","528"],["15.057","959"],["15.060","101"],["15.061","150"],["15.063","266"]],"a":[["15.082","2704"],["15.085","565"]]}}
1626916414.3741162: {"stream":"bchusd_perp@depth@100ms","data":{"e":"depthUpdate","E":1626916414402,"T":1626916414387,"s":"BCHUSD_PERP","ps":"BCHUSD","U":167006162601,"u":167006163031,"pu":167006162099,"b":[["86.58","0"],["303.05","0"],["414.96","0"],["426.24","309"],["427.57","790"],["427.60","106"],["427.77","175"]],"a":[["429.31","306"],["440.63","0"],["563.37","0"],["1794.10","0"]]}}
1626916414.374302: {"stream":"xrpusd_perp@depth@100ms","data":{"e":"depthUpdate","E":1626916414402,"T":1626916414392,"s":"XRPUSD_PERP","ps":"XRPUSD","U":167006162590,"u":167006163071,"pu":167006161999,"b":[["0.5646","698"],["0.5659","3083"],["0.5660","5145"],["0.5661","6345"]],"a":[["0.5663","3133"]]}}
1626916414.382588: {"stream":"etcusd_perp@depth@100ms","data":{"e":"depthUpdate","E":1626916414410,"T":1626916414318,"s":"ETCUSD_PERP","ps":"ETCUSD","U":167006162639,"u":167006162707,"pu":167006162449,"b":[],"a":[["42.264","245"],["42.265","100"],["42.266","400"],["42.267","0"]]}}
1626916414.391218: {"stream":"linkusd_211231@depth@100ms","data":{"e":"depthUpdate","E":1626916414416,"T":1626916414313,"s":"LINKUSD_211231","ps":"LINKUSD","U":167006162655,"u":167006162660,"pu":167006161071,"b":[],"a":[["15.339","4093"],["15.341","94"]]}}
1626916414.415817: {"stream":"btcusd_211231@depth@100ms","data":{"e":"depthUpdate","E":1626916414444,"T":1626916414425,"s":"BTCUSD_211231","ps":"BTCUSD","U":167006162783,"u":167006163186,"pu":167006162448,"b":[["16300.0","0"]],"a":[["32634.8","46"],["32635.7","153"],["32635.8","0"],["32636.7","0"],["32639.8","75"]]}}
1626916414.4395862: {"stream":"eosusd_perp@depth@100ms","data":{"e":"depthUpdate","E":1626916414465,"T":1626916414360,"s":"EOSUSD_PERP","ps":"EOSUSD","U":167006162849,"u":167006162849,"pu":167006162741,"b":[["3.446","15234"]],"a":[]}}
1626916414.459792: {"stream":"bchusd_210924@depth@100ms","data":{"e":"depthUpdate","E":1626916414484,"T":1626916414379,"s":"BCHUSD_210924","ps":"BCHUSD","U":167006162930,"u":167006162930,"pu":167006162083,"b":[["429.04","0"]],"a":[]}}
1626916414.470304: {"stream":"linkusd_perp@depth@100ms","data":{"e":"depthUpdate","E":1626916414496,"T":1626916414404,"s":"LINKUSD_PERP","ps":"LINKUSD","U":167006163066,"u":167006163124,"pu":167006163060,"b":[["15.024","391"],["15.056","1862"],["15.058","172"]],"a":[]}}
1626916414.478085: {"stream":"bchusd_perp@depth@100ms","data":{"e":"depthUpdate","E":1626916414506,"T":1626916414502,"s":"BCHUSD_PERP","ps":"BCHUSD","U":167006163119,"u":167006163517,"pu":167006163031,"b":[["389.64","0"],["426.39","310"],["427.51","295"],["427.61","0"],["427.73","0"]],"a":[["476.70","30"]]}}
1626916414.4844959: {"stream":"xrpusd_perp@depth@100ms","data":{"e":"depthUpdate","E":1626916414512,"T":1626916414489,"s":"XRPUSD_PERP","ps":"XRPUSD","U":167006163144,"u":167006163479,"pu":167006163071,"b":[["0.5647","1511"]],"a":[["0.5662","650"],["0.5663","2540"]]}}
1626916414.497194: {"stream":"ethusd_210924@depth@100ms","data":{"e":"depthUpdate","E":1626916414524,"T":1626916414512,"s":"ETHUSD_210924","ps":"ETHUSD","U":167006163179,"u":167006163561,"pu":167006162891,"b":[["1791.01","0"],["1986.99","0"],["1989.38","0"],["1989.58","0"],["1989.59","4336"],["1990.01","2168"],["1990.59","270"],["1990.77","480"],["1990.98","1579"]],"a":[["2051.00","2538"],["2145.08","10616"]]}}
1626916414.523711: {"stream":"btcusd_211231@depth@100ms","data":{"e":"depthUpdate","E":1626916414550,"T":1626916414475,"s":"BTCUSD_211231","ps":"BTCUSD","U":167006163297,"u":167006163404,"pu":167006163186,"b":[],"a":[["32633.8","46"],["32634.7","153"],["32634.8","0"],["32635.7","0"],["32639.8","0"]]}}
1626916414.557857: {"stream":"etcusd_perp@depth@100ms","data":{"e":"depthUpdate","E":1626916414584,"T":1626916414574,"s":"ETCUSD_PERP","ps":"ETCUSD","U":167006163420,"u":167006163839,"pu":167006162707,"b":[["34.729","0"],["42.146","0"],["42.173","500"],["42.228","70"],["42.242","300"],["42.246","0"]],"a":[["42.255","0"],["42.262","0"],["42.265","0"],["42.266","0"],["42.296","22"],["42.299","633"]]}}
1626916414.5701718: {"stream":"bchusd_210924@depth@100ms","data":{"e":"depthUpdate","E":1626916414597,"T":1626916414502,"s":"BCHUSD_210924","ps":"BCHUSD","U":167006163482,"u":167006163518,"pu":167006162930,"b":[],"a":[["429.81","246"],["429.92","0"]]}}
1626916414.577868: {"stream":"eosusd_perp@depth@100ms","data":{"e":"depthUpdate","E":1626916414605,"T":1626916414522,"s":"EOSUSD_PERP","ps":"EOSUSD","U":167006163516,"u":167006163589,"pu":167006162849,"b":[["3.467","3368"],["3.468","0"]],"a":[]}}
1626916414.5800462: {"stream":"bchusd_perp@depth@100ms","data":{"e":"depthUpdate","E":1626916414607,"T":1626916414571,"s":"BCHUSD_PERP","ps":"BCHUSD","U":167006163520,"u":167006163818,"pu":167006163517,"b":[["427.61","100"],["427.66","27"],["427.77","175"]],"a":[["427.81","0"],["429.16","310"]]}}
1626916414.594733: {"stream":"xrpusd_perp@depth@100ms","data":{"e":"depthUpdate","E":1626916414622,"T":1626916414516,"s":"XRPUSD_PERP","ps":"XRPUSD","U":167006163570,"u":167006163570,"pu":167006163479,"b":[],"a":[["0.5662","500"]]}}
1626916414.604516: {"stream":"ethusd_210924@depth@100ms","data":{"e":"depthUpdate","E":1626916414630,"T":1626916414614,"s":"ETHUSD_210924","ps":"ETHUSD","U":167006163601,"u":167006164062,"pu":167006163561,"b":[["1989.14","8901"],["1989.60","1517"]],"a":[["1991.21","0"],["1991.22","0"]]}}
1626916414.632511: {"stream":"btcusd_211231@depth@100ms","data":{"e":"depthUpdate","E":1626916414660,"T":1626916414613,"s":"BTCUSD_211231","ps":"BTCUSD","U":167006163714,"u":167006164044,"pu":167006163404,"b":[["32526.6","0"],["32527.4","1745"]],"a":[["32632.8","46"],["32633.7","153"],["32633.8","0"],["32634.7","0"],["65400.0","3"]]}}
1626916414.636022: {"stream":"linkusd_perp@depth@100ms","data":{"e":"depthUpdate","E":1626916414662,"T":1626916414613,"s":"LINKUSD_PERP","ps":"LINKUSD","U":167006163718,"u":167006164040,"pu":167006163124,"b":[],"a":[["15.069","3073"],["15.070","2257"],["15.074","1597"],["15.075","1054"]]}}
1626916414.6525812: {"stream":"trxusd_perp@depth@100ms","data":{"e":"depthUpdate","E":1626916414679,"T":1626916414668,"s":"TRXUSD_PERP","ps":"TRXUSD","U":167006163849,"u":167006164330,"pu":167006161530,"b":[["0.05341","1393"],["0.05342","1137"],["0.05343","1240"],["0.05344","512"],["0.05345","403"]],"a":[["0.05347","20842"],["0.05348","935"],["0.05349","822"]]}}
1626916414.688202: {"stream":"etcusd_perp@depth@100ms","data":{"e":"depthUpdate","E":1626916414715,"T":1626916414709,"s":"ETCUSD_PERP","ps":"ETCUSD","U":167006164029,"u":167006164532,"pu":167006163839,"b":[["42.229","1022"],["42.234","396"],["42.237","338"],["42.238","150"],["42.239","300"],["42.242","0"]],"a":[["42.264","0"],["42.299","0"],["42.306","629"],["42.595","843"],["42.669","1267"]]}}
1626916414.709847: {"stream":"ethusd_210924@depth@100ms","data":{"e":"depthUpdate","E":1626916414735,"T":1626916414699,"s":"ETHUSD_210924","ps":"ETHUSD","U":167006164134,"u":167006164475,"pu":167006164062,"b":[["1791.89","2236"],["1989.59","0"],["1989.60","0"],["1989.91","50"],["1990.01","0"],["1990.23","0"]],"a":[["1991.23","480"],["2051.94","2562"],["2144.15","2676"]]}}
1626916414.727625: {"stream":"bchusd_perp@depth@100ms","data":{"e":"depthUpdate","E":1626916414754,"T":1626916414706,"s":"BCHUSD_PERP","ps":"BCHUSD","U":167006164202,"u":167006164521,"pu":167006163818,"b":[["427.77","1"]],"a":[]}}
1626916414.740143: {"stream":"linkusd_211231@depth@100ms","data":{"e":"depthUpdate","E":1626916414767,"T":1626916414667,"s":"LINKUSD_211231","ps":"LINKUSD","U":167006164277,"u":167006164317,"pu":167006162660,"b":[["14.760","1022"],["14.836","0"],["14.911","0"],["14.986","0"],["15.062","0"],["15.292","43"],["15.300","0"]],"a":[]}}
1626916414.7434251: {"stream":"btcusd_211231@depth@100ms","data":{"e":"depthUpdate","E":1626916414771,"T":1626916414753,"s":"BTCUSD_211231","ps":"BTCUSD","U":167006164295,"u":167006164778,"pu":167006164044,"b":[],"a":[["32631.8","46"],["32632.7","153"],["32632.8","0"],["32633.7","0"],["32639.6","75"]]}}
1626916414.777048: {"stream":"trxusd_perp@depth@100ms","data":{"e":"depthUpdate","E":1626916414804,"T":1626916414746,"s":"TRXUSD_PERP","ps":"TRXUSD","U":167006164476,"u":167006164742,"pu":167006164330,"b":[["0.05310","874"],["0.05330","402"],["0.05341","1313"],["0.05342","937"],["0.05343","1420"],["0.05344","612"]],"a":[["0.05348","835"],["0.05349","822"],["0.05363","23970"],["0.05383","573"]]}}
1626916414.7899761: {"stream":"etcusd_perp@depth@100ms","data":{"e":"depthUpdate","E":1626916414817,"T":1626916414757,"s":"ETCUSD_PERP","ps":"ETCUSD","U":167006164544,"u":167006164805,"pu":167006164532,"b":[["42.209","1305"],["42.215","0"],["42.228","0"],["42.229","0"],["42.230","1072"]],"a":[["42.264","0"],["42.271","394"],["42.272","400"],["42.276","479"],["42.280","0"],["42.281","0"],["42.296","225"],["42.308","0"],["42.317","770"],["42.331","110"],["42.335","100"]]}}
1626916414.798932: {"stream":"linkusd_perp@depth@100ms","data":{"e":"depthUpdate","E":1626916414826,"T":1626916414773,"s":"LINKUSD_PERP","ps":"LINKUSD","U":167006164630,"u":167006164875,"pu":167006164040,"b":[["15.062","162"],["15.063","166"]],"a":[["15.070","2257"],["15.072","355"]]}}
1626916414.810813: {"stream":"ethusd_210924@depth@100ms","data":{"e":"depthUpdate","E":1626916414837,"T":1626916414805,"s":"ETHUSD_210924","ps":"ETHUSD","U":167006164675,"u":167006164998,"pu":167006164475,"b":[["1990.59","0"],["1990.64","480"],["1990.77","0"],["1990.98","1849"]],"a":[["1996.61","1399"]]}}
1626916414.827755: {"stream":"bchusd_perp@depth@100ms","data":{"e":"depthUpdate","E":1626916414855,"T":1626916414847,"s":"BCHUSD_PERP","ps":"BCHUSD","U":167006164767,"u":167006165156,"pu":167006164521,"b":[["427.77","1"]],"a":[["427.80","0"],["427.81","0"],["427.88","100"]]}}
1626916414.848696: {"stream":"linkusd_211231@depth@100ms","data":{"e":"depthUpdate","E":1626916414875,"T":1626916414860,"s":"LINKUSD_211231","ps":"LINKUSD","U":167006164858,"u":167006165218,"pu":167006164317,"b":[["15.281","153"],["15.288","3253"]],"a":[]}}
1626916414.855498: {"stream":"btcusd_211231@depth@100ms","data":{"e":"depthUpdate","E":1626916414882,"T":1626916414850,"s":"BTCUSD_211231","ps":"BTCUSD","U":167006164883,"u":167006165178,"pu":167006164778,"b":[["32620.5","0"]],"a":[["32631.6","46"],["32631.7","153"],["32631.8","0"],["32632.7","0"]]}}
1626916414.885643: {"stream":"eosusd_perp@depth@100ms","data":{"e":"depthUpdate","E":1626916414911,"T":1626916414828,"s":"EOSUSD_PERP","ps":"EOSUSD","U":167006165003,"u":167006165069,"pu":167006163589,"b":[["3.464","4657"],["3.468","0"]],"a":[]}}
1626916414.8980072: {"stream":"xrpusd_perp@depth@100ms","data":{"e":"depthUpdate","E":1626916414924,"T":1626916414874,"s":"XRPUSD_PERP","ps":"XRPUSD","U":167006165043,"u":167006165293,"pu":167006163570,"b":[],"a":[["0.5662","839"],["0.5663","2711"]]}}
1626916414.90151: {"stream":"linkusd_perp@depth@100ms","data":{"e":"depthUpdate","E":1626916414928,"T":1626916414881,"s":"LINKUSD_PERP","ps":"LINKUSD","U":167006165056,"u":167006165319,"pu":167006164875,"b":[],"a":[["15.070","2357"],["15.072","565"],["15.074","1397"],["15.075","944"]]}}
1626916414.913127: {"stream":"etcusd_perp@depth@100ms","data":{"e":"depthUpdate","E":1626916414939,"T":1626916414913,"s":"ETCUSD_PERP","ps":"ETCUSD","U":167006165109,"u":167006165441,"pu":167006164805,"b":[],"a":[["42.267","100"],["42.268","294"],["42.269","0"],["42.270","90"],["42.271","0"],["42.276","0"],["42.277","0"],["42.329","1053"],["42.602","104"],["42.666","35"]]}}
1626916414.9313579: {"stream":"ethusd_210924@depth@100ms","data":{"e":"depthUpdate","E":1626916414956,"T":1626916414851,"s":"ETHUSD_210924","ps":"ETHUSD","U":167006165181,"u":167006165184,"pu":167006164998,"b":[["1986.53","0"]],"a":[["1995.44","0"]]}}
1626916414.931543: {"stream":"bchusd_perp@depth@100ms","data":{"e":"depthUpdate","E":1626916414959,"T":1626916414950,"s":"BCHUSD_PERP","ps":"BCHUSD","U":167006165193,"u":167006165538,"pu":167006165156,"b":[["427.77","25"]],"a":[["427.81","100"],["427.88","0"],["428.01","4628"],["428.06","362"]]}}
1626916414.9401479: {"stream":"trxusd_perp@depth@100ms","data":{"e":"depthUpdate","E":1626916414965,"T":1626916414870,"s":"TRXUSD_PERP","ps":"TRXUSD","U":167006165219,"u":167006165264,"pu":167006164742,"b":[["0.05341","1717"],["0.05342","533"]],"a":[]}}
1626916414.984393: {"stream":"btcusd_211231@depth@100ms","data":{"e":"depthUpdate","E":1626916415011,"T":1626916414906,"s":"BTCUSD_211231","ps":"BTCUSD","U":167006165423,"u":167006165423,"pu":167006165178,"b":[],"a":[["32639.6","0"]]}}
1626916415.007447: {"stream":"bchusd_210924@depth@100ms","data":{"e":"depthUpdate","E":1626916415034,"T":1626916414929,"s":"BCHUSD_210924","ps":"BCHUSD","U":167006165491,"u":167006165491,"pu":167006163518,"b":[["429.00","3355"]],"a":[]}}
1626916415.027112: {"stream":"linkusd_perp@depth@100ms","data":{"e":"depthUpdate","E":1626916415054,"T":1626916415030,"s":"LINKUSD_PERP","ps":"LINKUSD","U":167006165537,"u":167006165814,"pu":167006165319,"b":[["15.055","0"],["15.062","272"],["15.063","97"]],"a":[["15.070","2257"],["15.072","755"],["15.073","1105"],["15.076","424"],["15.104","15253"]]}}
1626916415.0316002: {"stream":"eosusd_perp@depth@100ms","data":{"e":"depthUpdate","E":1626916415059,"T":1626916415053,"s":"EOSUSD_PERP","ps":"EOSUSD","U":167006165550,"u":167006165922,"pu":167006165069,"b":[],"a":[["3.485","5427"],["3.486","437"]]}}
1626916415.056889: {"stream":"linkusd_211231@depth@100ms","data":{"e":"depthUpdate","E":1626916415082,"T":1626916414998,"s":"LINKUSD_211231","ps":"LINKUSD","U":167006165611,"u":167006165709,"pu":167006165218,"b":[["15.293","123"],["15.294","1137"]],"a":[["15.326","1111"]]}}
1626916415.0591528: {"stream":"trxusd_perp@depth@100ms","data":{"e":"depthUpdate","E":1626916415086,"T":1626916414981,"s":"TRXUSD_PERP","ps":"TRXUSD","U":167006165631,"u":167006165631,"pu":167006165264,"b":[],"a":[["0.05348","1086"]]}}
1626916415.080502: {"stream":"bchusd_perp@depth@100ms","data":{"e":"depthUpdate","E":1626916415105,"T":1626916415096,"s":"BCHUSD_PERP","ps":"BCHUSD","U":167006165713,"u":167006166110,"pu":167006165538,"b":[["427.52","0"],["427.57","890"],["427.61","0"],["427.66","0"],["427.67","0"],["427.77","1"]],"a":[["428.55","25"],["428.80","636"]]}}
1626916415.085767: {"stream":"ethusd_210924@depth@100ms","data":{"e":"depthUpdate","E":1626916415112,"T":1626916415084,"s":"ETHUSD_210924","ps":"ETHUSD","U":167006165738,"u":167006166059,"pu":167006165184,"b":[["1987.22","3867"],["1987.33","0"],["1987.74","0"],["1987.82","0"],["1987.97","0"],["1988.09","0"],["1988.32","0"],["1988.62","0"],["1989.04","2622"],["1989.14","0"],["1989.37","0"],["1989.91","0"],["1990.35","0"],["1990.36","0"],["1990.64","0"],["1990.65","270"],["1990.66","205"],["1990.98","799"]],"a":[["1990.99","1710"],["1993.06","0"],["1993.15","0"],["1993.31","0"],["1993.32","0"],["1993.46","0"],["1993.47","0"],["1993.54","314"],["1993.74","0"],["1994.12","0"],["1994.41","0"]]}}
1626916415.1261299: {"stream":"etcusd_perp@depth@100ms","data":{"e":"depthUpdate","E":1626916415154,"T":1626916415137,"s":"ETCUSD_PERP","ps":"ETCUSD","U":167006165897,"u":167006166328,"pu":167006165441,"b":[["42.209","1505"],["42.213","1011"],["42.221","1805"],["42.226","0"]],"a":[["42.330","155"],["42.332","862"],["42.335","0"],["42.341","15"]]}}
1626916415.1305442: {"stream":"bchusd_210924@depth@100ms","data":{"e":"depthUpdate","E":1626916415156,"T":1626916415133,"s":"BCHUSD_210924","ps":"BCHUSD","U":167006165907,"u":167006166304,"pu":167006165491,"b":[["429.11","674"],["429.23","40"]],"a":[["429.81","0"],["429.86","248"]]}}
1626916415.162118: {"stream":"btcusd_211231@depth@100ms","data":{"e":"depthUpdate","E":1626916415189,"T":1626916415141,"s":"BTCUSD_211231","ps":"BTCUSD","U":167006166060,"u":167006166339,"pu":167006165423,"b":[["32527.3","0"],["32527.5","744"]],"a":[["32625.1","13"],["33033.6","0"],["33193.6","0"],["33353.7","0"],["33513.7","0"],["33673.7","0"]]}}
1626916415.1834009: {"stream":"bchusd_perp@depth@100ms","data":{"e":"depthUpdate","E":1626916415210,"T":1626916415200,"s":"BCHUSD_PERP","ps":"BCHUSD","U":167006166159,"u":167006166723,"pu":167006166110,"b":[["427.66","130"],["427.67","301"],["427.68","0"]],"a":[["427.87","84"],["428.03","0"]]}}
1626916415.184083: {"stream":"ethusd_210924@depth@100ms","data":{"e":"depthUpdate","E":1626916415212,"T":1626916415190,"s":"ETHUSD_210924","ps":"ETHUSD","U":167006166163,"u":167006166674,"pu":167006166059,"b":[["1986.53","1000"],["1987.16","783"],["1987.27","627"],["1987.48","401"],["1987.56","469"],["1987.71","321"],["1987.83","414"],["1987.96","0"],["1988.06","377"],["1988.12","440"],["1988.36","289"],["1988.78","3542"],["1988.93","12"],["1989.03","12"],["1989.91","50"],["1990.24","0"],["1990.69","0"],["1990.70","125"],["1990.73","360"],["1990.98","439"]],"a":[["1990.99","2210"],["1991.22","270"],["1991.47","0"],["1991.73","945"],["1991.74","2698"],["1993.06","289"],["1993.12","365"],["1993.28","321"],["1993.29","414"],["1993.43","469"],["1993.44","401"],["1993.84","0"],["1993.85","0"],["1994.12","627"],["1994.38","783"],["1994.44","0"],["1994.81","0"],["1994.94","0"],["1995.44","1000"],["2023.52","0"],["2033.44","0"],["2043.36","2551"],["2053.28","0"],["2063.20","0"]]}}
1626916415.208423: {"stream":"eosusd_perp@depth@100ms","data":{"e":"depthUpdate","E":1626916415234,"T":1626916415216,"s":"EOSUSD_PERP","ps":"EOSUSD","U":167006166268,"u":167006166815,"pu":167006165922,"b":[["3.468","0"]],"a":[["3.470","4557"],["3.471","4714"]]}}
1626916415.242093: {"stream":"bchusd_210924@depth@100ms","data":{"e":"depthUpdate","E":1626916415270,"T":1626916415229,"s":"BCHUSD_210924","ps":"BCHUSD","U":167006166536,"u":167006166876,"pu":167006166304,"b":[["429.27","0"]],"a":[["1335.62","0"],["1335.81","9415"]]}}
1626916415.251631: {"stream":"etcusd_perp@depth@100ms","data":{"e":"depthUpdate","E":1626916415280,"T":1626916415237,"s":"ETCUSD_PERP","ps":"ETCUSD","U":167006166600,"u":167006166931,"pu":167006166328,"b":[],"a":[["42.324","0"],["42.330","55"],["42.332","962"]]}}
1626916415.2876391: {"stream":"ethusd_210924@depth@100ms","data":{"e":"depthUpdate","E":1626916415313,"T":1626916415305,"s":"ETHUSD_210924","ps":"ETHUSD","U":167006166773,"u":167006167223,"pu":167006166674,"b":[["1980.86","1879"],["1984.53","0"],["1988.01","710"],["1988.17","0"],["1988.65","169"],["1988.75","594"],["1990.70","0"],["1990.73","0"],["1990.74","0"],["1990.77","0"],["1990.78","0"],["1990.81","360"],["1990.82","126"],["1990.98","115"]],"a":[["1993.72","169"],["1993.73","169"],["1994.81","304"],["1994.86","406"],["2023.61","408"],["2033.53","410"],["2043.45","412"],["2053.37","414"],["2063.29","416"]]}}
1626916415.2880309: {"stream":"btcusd_211231@depth@100ms","data":{"e":"depthUpdate","E":1626916415313,"T":1626916415237,"s":"BTCUSD_211231","ps":"BTCUSD","U":167006166761,"u":167006166936,"pu":167006166339,"b":[["16300.0","1858"],["31365.2","0"],["31525.2","0"],["31685.2","0"],["31845.3","0"],["32005.3","0"]],"a":[["33029.5","45"],["33189.5","45"],["33349.5","45"],["33509.6","46"],["33669.6","46"]]}}
1626916415.299406: {"stream":"bchusd_perp@depth@100ms","data":{"e":"depthUpdate","E":1626916415327,"T":1626916415276,"s":"BCHUSD_PERP","ps":"BCHUSD","U":167006166844,"u":167006167095,"pu":167006166723,"b":[["427.66","0"],["427.67","0"],["427.72","130"],["427.77","25"]],"a":[["428.55","404"],["428.80","120"]]}}
1626916415.3078249: {"stream":"eosusd_perp@depth@100ms","data":{"e":"depthUpdate","E":1626916415334,"T":1626916415319,"s":"EOSUSD_PERP","ps":"EOSUSD","U":167006166878,"u":167006167364,"pu":167006166815,"b":[["3.468","0"]],"a":[]}}
1626916415.349674: {"stream":"bchusd_210924@depth@100ms","data":{"e":"depthUpdate","E":1626916415376,"T":1626916415281,"s":"BCHUSD_210924","ps":"BCHUSD","U":167006167060,"u":167006167125,"pu":167006166876,"b":[["429.03","0"],["429.12","244"]],"a":[]}}
1626916415.371784: {"stream":"linkusd_perp@depth@100ms","data":{"e":"depthUpdate","E":1626916415396,"T":1626916415382,"s":"LINKUSD_PERP","ps":"LINKUSD","U":167006167166,"u":167006167670,"pu":167006165814,"b":[["15.014","1660"],["15.048","451"],["15.053","3279"],["15.054","1301"]],"a":[["15.108","3502"]]}}
1626916415.3762822: {"stream":"trxusd_perp@depth@100ms","data":{"e":"depthUpdate","E":1626916415404,"T":1626916415320,"s":"TRXUSD_PERP","ps":"TRXUSD","U":167006167201,"u":167006167381,"pu":167006165631,"b":[["0.05341","2436"],["0.05342","852"],["0.05343","1220"]],"a":[]}}
1626916415.3873768: {"stream":"btcusd_211231@depth@100ms","data":{"e":"depthUpdate","E":1626916415414,"T":1626916415310,"s":"BTCUSD_211231","ps":"BTCUSD","U":167006167262,"u":167006167267,"pu":167006166936,"b":[["31364.4","55"],["31524.4","55"],["31684.5","55"],["31844.5","55"],["32004.5","55"]],"a":[]}}
1626916415.38757: {"stream":"ethusd_210924@depth@100ms","data":{"e":"depthUpdate","E":1626916415413,"T":1626916415390,"s":"ETHUSD_210924","ps":"ETHUSD","U":167006167260,"u":167006167692,"pu":167006167223,"b":[["1983.49","9591"],["1990.69","360"],["1990.70","125"],["1990.81","0"],["1990.82","0"],["1990.85","0"],["1990.86","0"]],"a":[]}}
1626916415.4105449: {"stream":"bchusd_perp@depth@100ms","data":{"e":"depthUpdate","E":1626916415437,"T":1626916415381,"s":"BCHUSD_PERP","ps":"BCHUSD","U":167006167417,"u":167006167660,"pu":167006167095,"b":[["427.57","790"],["427.64","400"],["427.77","25"]],"a":[["427.99","1889"],["428.00","2598"]]}}
1626916415.416286: {"stream":"xrpusd_perp@depth@100ms","data":{"e":"depthUpdate","E":1626916415443,"T":1626916415363,"s":"XRPUSD_PERP","ps":"XRPUSD","U":167006167444,"u":167006167537,"pu":167006165293,"b":[],"a":[["0.5662","839"],["0.5667","3506"]]}}
1626916415.416425: {"stream":"eosusd_perp@depth@100ms","data":{"e":"depthUpdate","E":1626916415443,"T":1626916415426,"s":"EOSUSD_PERP","ps":"EOSUSD","U":167006167445,"u":167006167797,"pu":167006167364,"b":[["3.459","466"],["3.463","2017"],["3.468","0"]],"a":[]}}
1626916415.4705422: {"stream":"linkusd_perp@depth@100ms","data":{"e":"depthUpdate","E":1626916415497,"T":1626916415437,"s":"LINKUSD_PERP","ps":"LINKUSD","U":167006167707,"u":167006167833,"pu":167006167670,"b":[["15.014","1961"],["15.021","678"],["15.024","542"],["15.053","4414"],["15.054","249"]],"a":[["15.102","400"]]}}
1626916415.499861: {"stream":"ethusd_210924@depth@100ms","data":{"e":"depthUpdate","E":1626916415527,"T":1626916415521,"s":"ETHUSD_210924","ps":"ETHUSD","U":167006167773,"u":167006168136,"pu":167006167692,"b":[["1986.87","0"],["1987.93","372"],["1988.79","5133"],["1990.69","0"],["1990.70","0"],["1990.73","0"],["1990.74","0"],["1990.77","0"],["1990.78","127"],["1990.81","360"]],"a":[["1994.36","372"],["2001.85","0"]]}}
1626916415.509907: {"stream":"linkusd_211231@depth@100ms","data":{"e":"depthUpdate","E":1626916415537,"T":1626916415482,"s":"LINKUSD_211231","ps":"LINKUSD","U":167006167826,"u":167006168004,"pu":167006165709,"b":[["15.294","123"],["15.295","1352"]],"a":[["15.324","971"],["15.325","40"],["15.326","140"],["15.398","120"]]}}
1626916415.5100968: {"stream":"bchusd_perp@depth@100ms","data":{"e":"depthUpdate","E":1626916415537,"T":1626916415523,"s":"BCHUSD_PERP","ps":"BCHUSD","U":167006167825,"u":167006168143,"pu":167006167660,"b":[["427.77","1"]],"a":[["442.09","0"]]}}
1626916415.527732: {"stream":"eosusd_perp@depth@100ms","data":{"e":"depthUpdate","E":1626916415554,"T":1626916415533,"s":"EOSUSD_PERP","ps":"EOSUSD","U":167006167882,"u":167006168183,"pu":167006167797,"b":[["3.468","0"]],"a":[]}}
1626916415.5283232: {"stream":"btcusd_211231@depth@100ms","data":{"e":"depthUpdate","E":1626916415556,"T":1626916415537,"s":"BTCUSD_211231","ps":"BTCUSD","U":167006167889,"u":167006168201,"pu":167006167267,"b":[["32527.4","0"],["32527.6","1256"]],"a":[["32639.8","75"],["32894.7","0"],["65300.0","7444"]]}}
1626916415.548079: {"stream":"bchusd_210924@depth@100ms","data":{"e":"depthUpdate","E":1626916415573,"T":1626916415472,"s":"BCHUSD_210924","ps":"BCHUSD","U":167006167956,"u":167006167967,"pu":167006167125,"b":[["428.94","3439"],["429.00","0"]],"a":[]}}
1626916415.591344: {"stream":"xrpusd_perp@depth@100ms","data":{"e":"depthUpdate","E":1626916415618,"T":1626916415521,"s":"XRPUSD_PERP","ps":"XRPUSD","U":167006168125,"u":167006168137,"pu":167006167537,"b":[],"a":[["0.5662","530"],["0.5664","5471"],["0.5665","4723"]]}}
1626916415.599503: {"stream":"ethusd_210924@depth@100ms","data":{"e":"depthUpdate","E":1626916415627,"T":1626916415607,"s":"ETHUSD_210924","ps":"ETHUSD","U":167006168142,"u":167006168482,"pu":167006168136,"b":[["1880.56","2327"],["1988.47","565"],["1988.57","0"],["1990.69","360"],["1990.78","0"],["1990.81","0"],["1990.82","0"],["1990.85","0"],["1990.86","126"]],"a":[["1994.88","1811"],["1995.14","565"],["1995.45","0"],["1997.42","0"]]}}
1626916415.614635: {"stream":"bchusd_perp@depth@100ms","data":{"e":"depthUpdate","E":1626916415642,"T":1626916415621,"s":"BCHUSD_PERP","ps":"BCHUSD","U":167006168189,"u":167006168534,"pu":167006168143,"b":[["427.56","298"],["427.57","0"],["427.61","745"],["427.77","25"]],"a":[["441.24","3136"]]}}
1626916415.6335921: {"stream":"eosusd_perp@depth@100ms","data":{"e":"depthUpdate","E":1626916415661,"T":1626916415655,"s":"EOSUSD_PERP","ps":"EOSUSD","U":167006168284,"u":167006168657,"pu":167006168183,"b":[["3.465","7337"],["3.468","0"]],"a":[["3.508","0"]]}}
1626916415.651952: {"stream":"linkusd_perp@depth@100ms","data":{"e":"depthUpdate","E":1626916415679,"T":1626916415617,"s":"LINKUSD_PERP","ps":"LINKUSD","U":167006168335,"u":167006168527,"pu":167006167833,"b":[],"a":[["15.068","1923"],["15.069","1299"],["15.072","865"],["15.073","995"],["15.074","1777"],["15.075","564"],["15.076","424"],["15.109","592"]]}}
1626916415.666709: {"stream":"trxusd_perp@depth@100ms","data":{"e":"depthUpdate","E":1626916415694,"T":1626916415664,"s":"TRXUSD_PERP","ps":"TRXUSD","U":167006168392,"u":167006168705,"pu":167006167381,"b":[["0.05307","387"],["0.05327","132"],["0.05341","2236"],["0.05342","852"],["0.05343","1320"],["0.05344","512"]],"a":[["0.05351","2210"],["0.05366","982"],["0.05386","319"]]}}
1626916415.689513: {"stream":"bchusd_210924@depth@100ms","data":{"e":"depthUpdate","E":1626916415716,"T":1626916415621,"s":"BCHUSD_210924","ps":"BCHUSD","U":167006168505,"u":167006168533,"pu":167006167967,"b":[["429.00","285"],["429.12","0"]],"a":[]}}
1626916415.6896791: {"stream":"etcusd_perp@depth@100ms","data":{"e":"depthUpdate","E":1626916415717,"T":1626916415688,"s":"ETCUSD_PERP","ps":"ETCUSD","U":167006168515,"u":167006168789,"pu":167006166931,"b":[["42.213","0"],["42.226","90"],["42.227","1462"],["42.230","50"],["42.235","300"],["42.239","0"],["42.241","0"]],"a":[["42.255","42"],["42.261","200"],["42.262","375"],["42.263","100"],["42.264","563"],["42.265","241"],["42.266","326"],["42.267","0"],["42.268","0"],["42.277","34"],["42.323","100"],["42.332","862"],["42.363","145"]]}}
1626916415.70398: {"stream":"ethusd_210924@depth@100ms","data":{"e":"depthUpdate","E":1626916415731,"T":1626916415723,"s":"ETHUSD_210924","ps":"ETHUSD","U":167006168567,"u":167006169180,"pu":167006168482,"b":[["1990.69","0"],["1990.70","0"],["1990.73","0"],["1990.74","0"],["1990.77","360"],["1990.78","126"],["1990.86","0"]],"a":[["1990.99","1710"],["1991.03","500"]]}}
1626916415.742199: {"stream":"bchusd_perp@depth@100ms","data":{"e":"depthUpdate","E":1626916415769,"T":1626916415663,"s":"BCHUSD_PERP","ps":"BCHUSD","U":167006168688,"u":167006168688,"pu":167006168534,"b":[["427.77","1"]],"a":[]}}
1626916415.7468932: {"stream":"eosusd_perp@depth@100ms","data":{"e":"depthUpdate","E":1626916415774,"T":1626916415759,"s":"EOSUSD_PERP","ps":"EOSUSD","U":167006168722,"u":167006169558,"pu":167006168657,"b":[["3.468","0"]],"a":[]}}
1626916415.7661388: {"stream":"linkusd_perp@depth@100ms","data":{"e":"depthUpdate","E":1626916415790,"T":1626916415687,"s":"LINKUSD_PERP","ps":"LINKUSD","U":167006168786,"u":167006168788,"pu":167006168527,"b":[["15.050","660"],["15.052","760"]],"a":[]}}
1626916415.7863219: {"stream":"trxusd_perp@depth@100ms","data":{"e":"depthUpdate","E":1626916415814,"T":1626916415800,"s":"TRXUSD_PERP","ps":"TRXUSD","U":167006168999,"u":167006169782,"pu":167006168705,"b":[["0.05341","2122"]],"a":[["0.05348","886"],["0.05349","1022"],["0.05350","2997"]]}}
1626916415.7907462: {"stream":"etcusd_perp@depth@100ms","data":{"e":"depthUpdate","E":1626916415819,"T":1626916415809,"s":"ETCUSD_PERP","ps":"ETCUSD","U":167006169029,"u":167006169851,"pu":167006168789,"b":[["42.140","66"],["42.171","0"],["42.212","90"],["42.218","289"],["42.223","1185"],["42.226","0"],["42.227","418"],["42.233","732"],["42.235","0"],["42.238","0"]],"a":[["42.260","100"],["42.261","464"],["42.263","0"],["42.265","0"],["42.276","446"],["42.295","241"],["42.299","635"],["42.300","300"],["42.306","0"],["42.307","0"],["42.310","200"],["42.315","56"],["42.316","321"],["42.347","0"],["42.353","214"],["42.461","105"]]}}
1626916415.812203: {"stream":"xrpusd_perp@depth@100ms","data":{"e":"depthUpdate","E":1626916415838,"T":1626916415819,"s":"XRPUSD_PERP","ps":"XRPUSD","U":167006169261,"u":167006169920,"pu":167006168137,"b":[["0.5646","347"]],"a":[["0.5664","5611"],["0.5665","4423"],["0.5666","1919"]]}}
1626916415.82998: {"stream":"ethusd_210924@depth@100ms","data":{"e":"depthUpdate","E":1626916415855,"T":1626916415846,"s":"ETHUSD_210924","ps":"ETHUSD","U":167006169470,"u":167006170124,"pu":167006169180,"b":[["1881.48","2349"],["1981.98","0"],["1990.13","0"],["1990.34","0"],["1990.59","270"],["1990.62","360"],["1990.65","0"],["1990.66","0"],["1990.69","0"],["1990.77","0"],["1990.78","0"],["1990.81","0"],["1990.82","0"],["1990.85","0"],["1990.86","125"]],"a":[["1990.90","0"]]}}
1626916415.8581572: {"stream":"eosusd_perp@depth@100ms","data":{"e":"depthUpdate","E":1626916415885,"T":1626916415865,"s":"EOSUSD_PERP","ps":"EOSUSD","U":167006169698,"u":167006170204,"pu":167006169558,"b":[["3.468","0"]],"a":[]}}
1626916415.890692: {"stream":"trxusd_perp@depth@100ms","data":{"e":"depthUpdate","E":1626916415918,"T":1626916415812,"s":"TRXUSD_PERP","ps":"TRXUSD","U":167006169872,"u":167006169872,"pu":167006169782,"b":[["0.05340","3326"]],"a":[]}}
1626916415.892907: {"stream":"etcusd_perp@depth@100ms","data":{"e":"depthUpdate","E":1626916415920,"T":1626916415914,"s":"ETCUSD_PERP","ps":"ETCUSD","U":167006169892,"u":167006170556,"pu":167006169851,"b":[["41.425","528"],["41.436","0"],["41.836","0"],["41.848","528"],["41.859","0"],["42.000","365"],["42.047","0"],["42.073","1320"],["42.084","0"],["42.162","215"],["42.210","1337"],["42.212","938"],["42.219","246"],["42.220","200"],["42.221","575"],["42.223","0"],["42.224","664"],["42.229","300"],["42.231","30"],["42.232","98"],["42.233","500"],["42.234","0"],["42.236","25"],["42.254","0"]],"a":[["42.254","90"],["42.255","242"],["42.258","240"],["42.261","200"],["42.264","363"],["42.270","0"],["42.288","22"],["42.289","344"],["42.290","735"],["42.294","0"],["42.296","0"],["42.297","0"],["42.299","0"],["42.300","200"],["42.306","56"],["42.310","0"],["42.314","0"],["42.315","100"],["42.316","717"],["42.321","215"],["42.323","0"],["42.327","0"],["42.329","2373"],["42.332","662"],["42.340","80"],["42.377","0"],["42.450","336"],["42.454","1620"],["42.462","0"],["42.465","0"],["42.615","560"],["42.628","0"],["42.673","253"],["42.691","528"],["42.702","0"],["43.114","528"],["43.125","0"]]}}
1626916415.8968801: {"stream":"bchusd_perp@depth@100ms","data":{"e":"depthUpdate","E":1626916415924,"T":1626916415907,"s":"BCHUSD_PERP","ps":"BCHUSD","U":167006169925,"u":167006170520,"pu":167006168688,"b":[["424.79","0"],["427.61","0"]],"a":[]}}
1626916415.9162822: {"stream":"xrpusd_perp@depth@100ms","data":{"e":"depthUpdate","E":1626916415943,"T":1626916415889,"s":"XRPUSD_PERP","ps":"XRPUSD","U":167006170083,"u":167006170404,"pu":167006169920,"b":[["0.5660","5142"],["0.5661","6010"]],"a":[["0.5662","835"],["0.5663","2741"]]}}
1626916415.926816: {"stream":"btcusd_211231@depth@100ms","data":{"e":"depthUpdate","E":1626916415955,"T":1626916415851,"s":"BTCUSD_211231","ps":"BTCUSD","U":167006170141,"u":167006170141,"pu":167006168201,"b":[["32596.3","0"]],"a":[]}}
1626916415.933734: {"stream":"ethusd_210924@depth@100ms","data":{"e":"depthUpdate","E":1626916415959,"T":1626916415944,"s":"ETHUSD_210924","ps":"ETHUSD","U":167006170154,"u":167006170705,"pu":167006170124,"b":[["1987.51","80"],["1987.70","0"],["1988.69","2315"],["1988.78","0"],["1988.79","0"],["1988.95","363"],["1989.00","384"],["1989.04","0"],["1989.31","1303"],["1989.47","3658"],["1989.49","0"],["1989.74","0"],["1989.76","0"],["1990.00","0"],["1990.06","0"],["1990.20","0"],["1990.29","613"],["1990.32","0"],["1990.33","466"],["1990.62","0"],["1990.63","0"],["1990.66","0"],["1990.67","0"],["1990.70","360"],["1990.71","125"],["1990.86","0"]],"a":[["1990.90","0"],["1992.29","301"],["1992.69","11898"],["1993.51","80"],["1993.63","0"],["1995.60","0"],["1997.40","0"]]}}
1626916415.947605: {"stream":"linkusd_perp@depth@100ms","data":{"e":"depthUpdate","E":1626916415975,"T":1626916415967,"s":"LINKUSD_PERP","ps":"LINKUSD","U":167006170234,"u":167006170850,"pu":167006168788,"b":[["15.048","251"],["15.049","380"],["15.052","880"],["15.053","3279"],["15.054","898"],["15.057","639"],["15.059","110"],["15.061","100"],["15.062","62"],["15.063","3"]],"a":[["15.065","276"],["15.067","673"],["15.068","1773"],["15.069","1409"],["15.072","1155"],["15.073","1475"],["15.074","1597"],["15.075","464"],["15.076","224"],["15.077","395"]]}}
1626916415.9497972: {"stream":"linkusd_211231@depth@100ms","data":{"e":"depthUpdate","E":1626916415977,"T":1626916415968,"s":"LINKUSD_211231","ps":"LINKUSD","U":167006170239,"u":167006170853,"pu":167006168004,"b":[["15.284","0"],["15.289","953"],["15.295","0"],["15.307","0"]],"a":[["15.332","1842"],["15.339","2086"]]}}
1626916415.967257: {"stream":"eosusd_perp@depth@100ms","data":{"e":"depthUpdate","E":1626916415994,"T":1626916415979,"s":"EOSUSD_PERP","ps":"EOSUSD","U":167006170401,"u":167006170918,"pu":167006170204,"b":[["3.468","0"]],"a":[]}}
1626916415.993309: {"stream":"etcusd_perp@depth@100ms","data":{"e":"depthUpdate","E":1626916416021,"T":1626916416009,"s":"ETCUSD_PERP","ps":"ETCUSD","U":167006170576,"u":167006171089,"pu":167006170556,"b":[["41.827","312"],["41.959","2000"],["41.972","2"],["42.026","0"],["42.038","150"],["42.039","377"],["42.053","0"],["42.069","953"],["42.133","300"],["42.135","600"],["42.157","0"],["42.164","0"],["42.173","0"],["42.182","300"],["42.186","0"],["42.192","800"],["42.194","1157"],["42.196","56"],["42.202","56"],["42.205","0"],["42.206","938"],["42.209","1105"],["42.210","1605"],["42.212","90"],["42.213","70"],["42.217","22"],["42.219","0"],["42.220","0"],["42.221","415"],["42.225","0"],["42.228","387"],["42.230","17"],["42.237","0"]],"a":[["42.237","45"],["42.245","1"],["42.253","90"],["42.254","100"],["42.255","200"],["42.256","0"],["42.257","279"],["42.258","0"],["42.260","0"],["42.263","38"],["42.266","669"],["42.288","657"],["42.290","300"],["42.300","0"],["42.306","112"],["42.312","2711"],["42.321","15"],["42.330","17"],["42.349","300"],["42.353","69"],["42.363","0"],["42.408","452"],["42.453","152"],["42.470","0"],["42.527","0"]]}}
1626916416.008561: {"stream":"bchusd_perp@depth@100ms","data":{"e":"depthUpdate","E":1626916416037,"T":1626916416023,"s":"BCHUSD_PERP","ps":"BCHUSD","U":167006170638,"u":167006171162,"pu":167006170520,"b":[["425.60","907"],["427.00","226"],["427.27","162"],["427.28","162"],["427.29","162"],["427.30","4226"],["427.31","358"],["427.35","3305"],["427.38","0"],["427.57","725"]],"a":[["428.06","462"],["428.11","0"],["428.18","44"],["428.25","0"]]}}
1626916416.0360699: {"stream":"ethusd_210924@depth@100ms","data":{"e":"depthUpdate","E":1626916416060,"T":1626916416048,"s":"ETHUSD_210924","ps":"ETHUSD","U":167006170744,"u":167006171281,"pu":167006170705,"b":[["1987.42","80"],["1987.51","0"],["1989.50","5985"],["1989.57","2453"],["1989.91","0"],["1990.70","0"],["1990.71","0"],["1990.74","0"],["1990.75","0"],["1990.78","360"],["1990.79","127"]],"a":[["1990.80","0"],["1994.88","0"],["2023.61","0"],["2033.53","0"],["2043.45","0"],["2053.37","0"],["2063.29","0"]]}}
1626916416.046222: {"stream":"trxusd_perp@depth@100ms","data":{"e":"depthUpdate","E":1626916416074,"T":1626916416002,"s":"TRXUSD_PERP","ps":"TRXUSD","U":167006170863,"u":167006171063,"pu":167006169872,"b":[["0.05343","1570"],["0.05344","833"],["0.05345","187"],["0.05346","0"]],"a":[["0.05346","2256"],["0.05347","20797"],["0.05349","722"],["0.05351","2110"]]}}
1626916416.054805: {"stream":"linkusd_perp@depth@100ms","data":{"e":"depthUpdate","E":1626916416079,"T":1626916416062,"s":"LINKUSD_PERP","ps":"LINKUSD","U":167006170875,"u":167006171348,"pu":167006170850,"b":[["15.039","454"],["15.049","29"],["15.050","1240"],["15.052","761"],["15.054","1148"],["15.058","172"],["15.059","62"]],"a":[["15.064","290"],["15.066","0"],["15.069","1709"],["15.071","528"],["15.073","1375"],["15.075","264"],["15.079","1487"]]}}
1626916416.0629041: {"stream":"linkusd_211231@depth@100ms","data":{"e":"depthUpdate","E":1626916416089,"T":1626916415989,"s":"LINKUSD_211231","ps":"LINKUSD","U":167006170927,"u":167006170979,"pu":167006170853,"b":[["14.759","100"],["14.835","100"],["14.910","100"],["14.985","676"],["15.061","100"],["15.260","351"],["15.294","273"]],"a":[["15.330","212"],["15.523","164"],["15.598","165"],["15.673","166"],["15.749","167"],["15.824","168"]]}}
1626916416.082797: {"stream":"eosusd_perp@depth@100ms","data":{"e":"depthUpdate","E":1626916416109,"T":1626916416093,"s":"EOSUSD_PERP","ps":"EOSUSD","U":167006171069,"u":167006171506,"pu":167006170918,"b":[["3.468","0"]],"a":[["3.470","4807"],["3.471","4966"]]}}
1626916416.093996: {"stream":"etcusd_perp@depth@100ms","data":{"e":"depthUpdate","E":1626916416121,"T":1626916416106,"s":"ETCUSD_PERP","ps":"ETCUSD","U":167006171125,"u":167006171575,"pu":167006171089,"b":[["42.059","336"],["42.141","622"],["42.144","242"],["42.162","70"],["42.174","488"],["42.202","0"],["42.204","1261"],["42.206","0"],["42.207","1332"],["42.212","0"],["42.213","400"],["42.214","98"],["42.218","267"],["42.221","15"],["42.222","90"],["42.232","0"]],"a":[["42.249","400"],["42.252","300"],["42.257","0"],["42.261","0"],["42.262","0"],["42.264","0"],["42.266","343"],["42.272","0"],["42.280","200"],["42.288","0"],["42.289","322"],["42.290","935"],["42.306","56"],["42.310","100"],["42.315","0"],["42.343","23427"],["42.350","217"],["42.365","300"],["42.390","3347"],["42.450","0"],["42.664","306"]]}}
1626916416.0947871: {"stream":"xrpusd_perp@depth@100ms","data":{"e":"depthUpdate","E":1626916416123,"T":1626916416028,"s":"XRPUSD_PERP","ps":"XRPUSD","U":167006171143,"u":167006171189,"pu":167006170404,"b":[["0.5661","6012"]],"a":[["0.5664","5771"],["0.5666","1759"]]}}
1626916416.101894: {"stream":"btcusd_211231@depth@100ms","data":{"e":"depthUpdate","E":1626916416129,"T":1626916416022,"s":"BTCUSD_211231","ps":"BTCUSD","U":167006171154,"u":167006171158,"pu":167006170141,"b":[["32494.0","0"],["32516.8","1877"]],"a":[]}}
1626916416.1334221: {"stream":"bchusd_perp@depth@100ms","data":{"e":"depthUpdate","E":1626916416161,"T":1626916416131,"s":"BCHUSD_PERP","ps":"BCHUSD","U":167006171328,"u":167006171728,"pu":167006171162,"b":[["427.77","1"]],"a":[["427.96","100"],["428.06","462"],["428.07","17"]]}}
1626916416.147265: {"stream":"ethusd_210924@depth@100ms","data":{"e":"depthUpdate","E":1626916416172,"T":1626916416162,"s":"ETHUSD_210924","ps":"ETHUSD","U":167006171384,"u":167006171929,"pu":167006171281,"b":[["1981.33","0"],["1986.07","1193"],["1987.42","0"],["1988.07","0"],["1989.57","2403"],["1990.62","0"],["1990.63","0"],["1990.66","0"],["1990.67","126"],["1990.70","360"],["1990.78","0"],["1990.79","0"]],"a":[["1990.80","0"],["1990.90","0"],["1995.60","190"],["2000.94","1198"],["2004.93","1201"]]}}
1626916416.159979: {"stream":"bchusd_210924@depth@100ms","data":{"e":"depthUpdate","E":1626916416187,"T":1626916416081,"s":"BCHUSD_210924","ps":"BCHUSD","U":167006171438,"u":167006171452,"pu":167006168533,"b":[],"a":[["429.87","12"],["429.93","5064"]]}}
1626916416.1617842: {"stream":"linkusd_perp@depth@100ms","data":{"e":"depthUpdate","E":1626916416189,"T":1626916416174,"s":"LINKUSD_PERP","ps":"LINKUSD","U":167006171458,"u":167006171980,"pu":167006171348,"b":[["15.044","966"],["15.047","3373"],["15.048","451"],["15.050","940"],["15.052","651"],["15.055","0"],["15.059","172"]],"a":[["15.070","2408"],["15.077","469"],["15.078","871"]]}}
1626916416.18665: {"stream":"eosusd_perp@depth@100ms","data":{"e":"depthUpdate","E":1626916416212,"T":1626916416192,"s":"EOSUSD_PERP","ps":"EOSUSD","U":167006171577,"u":167006172069,"pu":167006171506,"b":[["3.468","0"]],"a":[["3.470","4434"],["3.471","5429"]]}}
1626916416.203619: {"stream":"etcusd_perp@depth@100ms","data":{"e":"depthUpdate","E":1626916416230,"T":1626916416203,"s":"ETCUSD_PERP","ps":"ETCUSD","U":167006171684,"u":167006172127,"pu":167006171575,"b":[["42.109","147"],["42.119","97"],["42.145","568"],["42.152","145"],["42.159","0"],["42.169","314"],["42.174","0"],["42.194","1213"],["42.204","323"],["42.205","1180"],["42.209","1563"],["42.210","1337"],["42.226","300"],["42.229","0"]],"a":[["42.253","0"],["42.262","0"],["42.276","536"],["42.279","1263"],["42.280","222"],["42.289","957"],["42.290","100"],["42.297","56"],["42.298","256"],["42.306","0"],["42.309","0"],["42.432","849"],["42.440","636"],["42.475","43"]]}}
1626916416.2234628: {"stream":"btcusd_211231@depth@100ms","data":{"e":"depthUpdate","E":1626916416251,"T":1626916416239,"s":"BTCUSD_211231","ps":"BTCUSD","U":167006171810,"u":167006172284,"pu":167006171158,"b":[["32589.0","0"]],"a":[["32625.1","13"],["32689.5","157"],["32717.4","0"],["33029.5","0"],["33189.5","0"],["33349.5","0"],["33509.6","0"],["33669.6","0"]]}}
1626916416.24959: {"stream":"ethusd_210924@depth@100ms","data":{"e":"depthUpdate","E":1626916416276,"T":1626916416270,"s":"ETHUSD_210924","ps":"ETHUSD","U":167006171969,"u":167006172373,"pu":167006171929,"b":[["1980.45","9902"],["1987.22","3947"],["1989.50","5726"],["1989.81","50"],["1989.84","259"],["1990.67","0"],["1990.70","0"],["1990.71","0"],["1990.74","0"],["1990.75","0"],["1990.77","360"],["1990.78","126"]],"a":[["1991.13","0"],["1991.42","400"],["1991.60","0"],["1992.68","0"],["1992.74","400"],["1992.99","0"],["1993.26","0"],["1993.51","0"],["2301.61","0"]]}}
1626916416.273422: {"stream":"linkusd_perp@depth@100ms","data":{"e":"depthUpdate","E":1626916416300,"T":1626916416288,"s":"LINKUSD_PERP","ps":"LINKUSD","U":167006172085,"u":167006172486,"pu":167006171980,"b":[["15.048","1666"]],"a":[["15.066","200"],["15.069","1599"],["15.072","1265"],["15.088","1138"],["15.090","209"],["15.093","1670"]]}}
1626916416.273612: {"stream":"linkusd_211231@depth@100ms","data":{"e":"depthUpdate","E":1626916416300,"T":1626916416288,"s":"LINKUSD_211231","ps":"LINKUSD","U":167006172075,"u":167006172475,"pu":167006170979,"b":[["14.759","0"],["14.835","0"],["14.910","0"],["14.985","576"],["15.061","0"]],"a":[["15.340","70"],["15.361","0"],["15.523","0"],["15.598","0"],["15.673","0"],["15.749","0"],["15.824","0"]]}}
1626916416.287372: {"stream":"bchusd_perp@depth@100ms","data":{"e":"depthUpdate","E":1626916416315,"T":1626916416282,"s":"BCHUSD_PERP","ps":"BCHUSD","U":167006172165,"u":167006172446,"pu":167006171728,"b":[["424.79","610"],["427.77","1"]],"a":[]}}
1626916416.2963352: {"stream":"eosusd_perp@depth@100ms","data":{"e":"depthUpdate","E":1626916416322,"T":1626916416305,"s":"EOSUSD_PERP","ps":"EOSUSD","U":167006172199,"u":167006172547,"pu":167006172069,"b":[["3.468","0"]],"a":[]}}
1626916416.29955: {"stream":"bchusd_210924@depth@100ms","data":{"e":"depthUpdate","E":1626916416326,"T":1626916416267,"s":"BCHUSD_210924","ps":"BCHUSD","U":167006172216,"u":167006172364,"pu":167006171452,"b":[],"a":[["1722.38","12140"],["1722.46","0"]]}}
1626916416.310207: {"stream":"etcusd_perp@depth@100ms","data":{"e":"depthUpdate","E":1626916416336,"T":1626916416320,"s":"ETCUSD_PERP","ps":"ETCUSD","U":167006172246,"u":167006172639,"pu":167006172127,"b":[["34.644","7267"],["41.968","1260"],["42.130","2372"],["42.177","0"],["42.200","200"],["42.210","1337"],["42.219","90"],["42.222","0"],["42.229","33"]],"a":[["42.237","0"],["42.262","90"],["42.263","0"],["42.265","0"],["42.275","0"],["42.276","446"],["42.290","100"],["42.298","256"],["42.310","762"],["42.332","0"],["42.462","336"]]}}
1626916416.3386712: {"stream":"trxusd_perp@depth@100ms","data":{"e":"depthUpdate","E":1626916416365,"T":1626916416314,"s":"TRXUSD_PERP","ps":"TRXUSD","U":167006172347,"u":167006172594,"pu":167006171063,"b":[],"a":[["0.05347","20597"],["0.05348","886"],["0.05349","522"],["0.05350","3197"],["0.05351","2310"],["0.05356","899"]]}}
1626916416.3591418: {"stream":"ethusd_210924@depth@100ms","data":{"e":"depthUpdate","E":1626916416385,"T":1626916416329,"s":"ETHUSD_210924","ps":"ETHUSD","U":167006172437,"u":167006172660,"pu":167006172373,"b":[["1989.32","3992"],["1990.62","360"],["1990.63","127"],["1990.77","0"],["1990.78","0"]],"a":[["1993.35","80"],["2023.39","408"],["2033.31","410"],["2043.23","412"],["2053.15","414"],["2063.06","416"]]}}
1626916416.359416: {"stream":"xrpusd_perp@depth@100ms","data":{"e":"depthUpdate","E":1626916416387,"T":1626916416376,"s":"XRPUSD_PERP","ps":"XRPUSD","U":167006172452,"u":167006172796,"pu":167006171189,"b":[["0.5657","5985"],["0.5659","2923"]],"a":[["0.5663","2711"]]}}
1626916416.365441: {"stream":"btcusd_211231@depth@100ms","data":{"e":"depthUpdate","E":1626916416392,"T":1626916416309,"s":"BTCUSD_211231","ps":"BTCUSD","U":167006172462,"u":167006172565,"pu":167006172284,"b":[["31364.4","0"],["31524.4","0"],["31684.5","0"],["31844.5","0"],["32004.5","0"],["32589.0","15"]],"a":[]}}
1626916416.406208: {"stream":"eosusd_perp@depth@100ms","data":{"e":"depthUpdate","E":1626916416431,"T":1626916416419,"s":"EOSUSD_PERP","ps":"EOSUSD","U":167006172653,"u":167006172952,"pu":167006172547,"b":[["3.462","5381"],["3.468","0"]],"a":[]}}
1626916416.453544: {"stream":"etcusd_perp@depth@100ms","data":{"e":"depthUpdate","E":1626916416482,"T":1626916416477,"s":"ETCUSD_PERP","ps":"ETCUSD","U":167006172800,"u":167006173164,"pu":167006172639,"b":[["42.169","0"],["42.219","0"],["42.228","477"]],"a":[["42.262","0"],["42.265","90"],["42.275","0"],["42.280","255"],["42.334","0"]]}}
1626916416.461501: {"stream":"ethusd_210924@depth@100ms","data":{"e":"depthUpdate","E":1626916416487,"T":1626916416463,"s":"ETHUSD_210924","ps":"ETHUSD","U":167006172820,"u":167006173130,"pu":167006172660,"b":[["1986.52","500"],["1990.62","0"],["1990.63","0"],["1990.66","0"],["1990.67","125"],["1990.70","360"]],"a":[["2299.59","2871"]]}}
1626916416.470332: {"stream":"trxusd_perp@depth@100ms","data":{"e":"depthUpdate","E":1626916416499,"T":1626916416488,"s":"TRXUSD_PERP","ps":"TRXUSD","U":167006172875,"u":167006173217,"pu":167006172594,"b":[],"a":[["0.05392","372"],["0.05393","677"],["0.05397","3925"]]}}
1626916416.474876: {"stream":"xrpusd_perp@depth@100ms","data":{"e":"depthUpdate","E":1626916416502,"T":1626916416428,"s":"XRPUSD_PERP","ps":"XRPUSD","U":167006172881,"u":167006172997,"pu":167006172796,"b":[["0.5626","2118"],["0.5657","5825"],["0.5659","3083"]],"a":[["0.5663","2741"],["0.5704","17889"]]}}
1626916416.495158: {"stream":"bchusd_perp@depth@100ms","data":{"e":"depthUpdate","E":1626916416524,"T":1626916416481,"s":"BCHUSD_PERP","ps":"BCHUSD","U":167006172954,"u":167006173176,"pu":167006172446,"b":[["427.57","0"],["427.77","25"]],"a":[]}}
1626916416.507553: {"stream":"eosusd_perp@depth@100ms","data":{"e":"depthUpdate","E":1626916416534,"T":1626916416518,"s":"EOSUSD_PERP","ps":"EOSUSD","U":167006172998,"u":167006173344,"pu":167006172952,"b":[["3.468","0"]],"a":[["3.472","5662"],["3.473","2189"]]}}
1626916416.515198: {"stream":"linkusd_perp@depth@100ms","data":{"e":"depthUpdate","E":1626916416542,"T":1626916416516,"s":"LINKUSD_PERP","ps":"LINKUSD","U":167006173024,"u":167006173339,"pu":167006172486,"b":[],"a":[["15.064","190"],["15.065","376"],["15.067","825"]]}}
1626916416.520227: {"stream":"bchusd_210924@depth@100ms","data":{"e":"depthUpdate","E":1626916416546,"T":1626916416440,"s":"BCHUSD_210924","ps":"BCHUSD","U":167006173038,"u":167006173038,"pu":167006172364,"b":[["429.36","30"]],"a":[]}}
1626916416.556759: {"stream":"etcusd_perp@depth@100ms","data":{"e":"depthUpdate","E":1626916416583,"T":1626916416533,"s":"ETCUSD_PERP","ps":"ETCUSD","U":167006173165,"u":167006173384,"pu":167006173164,"b":[["42.141","1122"],["42.171","314"],["42.205","242"],["42.209","2550"]],"a":[["42.241","1"],["42.245","0"],["42.249","0"],["42.308","500"]]}}
1626916416.561614: {"stream":"ethusd_210924@depth@100ms","data":{"e":"depthUpdate","E":1626916416588,"T":1626916416574,"s":"ETHUSD_210924","ps":"ETHUSD","U":167006173189,"u":167006173587,"pu":167006173130,"b":[["999.00","0"],["1985.46","0"],["1990.07","314"],["1990.08","0"],["1990.67","0"],["1990.70","0"],["1990.71","0"],["1990.74","0"],["1990.75","0"],["1990.77","360"],["1990.78","125"]],"a":[["1991.22","0"],["1991.47","270"],["1991.84","0"],["1993.46","314"],["1993.54","0"],["2008.46","0"]]}}
1626916416.582203: {"stream":"btcusd_211231@depth@100ms","data":{"e":"depthUpdate","E":1626916416609,"T":1626916416507,"s":"BTCUSD_211231","ps":"BTCUSD","U":167006173283,"u":167006173287,"pu":167006172565,"b":[["32526.6","469"],["32527.5","0"]],"a":[]}}
1626916416.610068: {"stream":"eosusd_perp@depth@100ms","data":{"e":"depthUpdate","E":1626916416635,"T":1626916416618,"s":"EOSUSD_PERP","ps":"EOSUSD","U":167006173374,"u":167006173747,"pu":167006173344,"b":[["3.468","0"]],"a":[]}}
1626916416.6297789: {"stream":"bchusd_perp@depth@100ms","data":{"e":"depthUpdate","E":1626916416657,"T":1626916416550,"s":"BCHUSD_PERP","ps":"BCHUSD","U":167006173481,"u":167006173482,"pu":167006173176,"b":[["427.57","100"],["427.64","300"]],"a":[]}}
1626916416.639235: {"stream":"xrpusd_perp@depth@100ms","data":{"e":"depthUpdate","E":1626916416669,"T":1626916416659,"s":"XRPUSD_PERP","ps":"XRPUSD","U":167006173531,"u":167006173924,"pu":167006172997,"b":[["0.5159","0"],["0.5526","983"],["0.5659","2414"],["0.5660","5148"],["0.5661","5271"]],"a":[["0.5696","3624"]]}}
1626916416.643424: {"stream":"linkusd_perp@depth@100ms","data":{"e":"depthUpdate","E":1626916416669,"T":1626916416612,"s":"LINKUSD_PERP","ps":"LINKUSD","U":167006173544,"u":167006173737,"pu":167006173339,"b":[["15.032","620"],["15.042","1367"]],"a":[["15.072","1155"],["15.079","1597"],["15.082","2704"]]}}
1626916416.670351: {"stream":"linkusd_211231@depth@100ms","data":{"e":"depthUpdate","E":1626916416697,"T":1626916416593,"s":"LINKUSD_211231","ps":"LINKUSD","U":167006173638,"u":167006173656,"pu":167006172475,"b":[],"a":[["15.332","0"],["15.338","1895"]]}}
1626916416.672373: {"stream":"etcusd_perp@depth@100ms","data":{"e":"depthUpdate","E":1626916416700,"T":1626916416655,"s":"ETCUSD_PERP","ps":"ETCUSD","U":167006173657,"u":167006173912,"pu":167006173384,"b":[["42.190","727"],["42.191","30"],["42.220","33"],["42.227","0"],["42.230","0"],["42.231","0"]],"a":[["42.281","1248"],["42.311","55"],["42.330","72"],["42.411","25"]]}}
1626916416.67262: {"stream":"trxusd_perp@depth@100ms","data":{"e":"depthUpdate","E":1626916416700,"T":1626916416690,"s":"TRXUSD_PERP","ps":"TRXUSD","U":167006173660,"u":167006174079,"pu":167006173217,"b":[["0.05306","1115"],["0.05326","553"],["0.05343","1470"],["0.05344","933"],["0.05345","291"]],"a":[["0.05346","2359"],["0.05347","19997"],["0.05348","451"],["0.05349","622"],["0.05350","3397"],["0.05351","2410"],["0.05365","3724"],["0.05385","2121"]]}}
1626916416.705021: {"stream":"ethusd_210924@depth@100ms","data":{"e":"depthUpdate","E":1626916416732,"T":1626916416725,"s":"ETHUSD_210924","ps":"ETHUSD","U":167006173794,"u":167006174229,"pu":167006173587,"b":[["1990.37","50"],["1990.62","0"],["1990.63","0"],["1990.66","0"],["1990.67","127"],["1990.70","360"],["1990.77","0"],["1990.78","0"]],"a":[["1991.03","0"],["1991.41","270"],["1991.47","0"],["1991.72","0"]]}}
1626916416.70844: {"stream":"eosusd_perp@depth@100ms","data":{"e":"depthUpdate","E":1626916416735,"T":1626916416715,"s":"EOSUSD_PERP","ps":"EOSUSD","U":167006173806,"u":167006174197,"pu":167006173747,"b":[["3.468","0"]],"a":[]}}
1626916416.72659: {"stream":"btcusd_211231@depth@100ms","data":{"e":"depthUpdate","E":1626916416755,"T":1626916416650,"s":"BTCUSD_211231","ps":"BTCUSD","U":167006173887,"u":167006173887,"pu":167006173287,"b":[["32591.9","20"]],"a":[]}}
1626916416.73397: {"stream":"bchusd_perp@depth@100ms","data":{"e":"depthUpdate","E":1626916416759,"T":1626916416689,"s":"BCHUSD_PERP","ps":"BCHUSD","U":167006173909,"u":167006174069,"pu":167006173482,"b":[["425.60","507"],["427.00","626"],["427.51","983"]],"a":[["428.33","3009"],["428.34","347"]]}}
1626916416.746871: {"stream":"linkusd_perp@depth@100ms","data":{"e":"depthUpdate","E":1626916416773,"T":1626916416710,"s":"LINKUSD_PERP","ps":"LINKUSD","U":167006173981,"u":167006174177,"pu":167006173737,"b":[["15.059","62"],["15.062","172"]],"a":[["15.076","334"],["15.079","1487"]]}}
1626916416.76112: {"stream":"xrpusd_perp@depth@100ms","data":{"e":"depthUpdate","E":1626916416788,"T":1626916416763,"s":"XRPUSD_PERP","ps":"XRPUSD","U":167006174043,"u":167006174391,"pu":167006173924,"b":[["0.1146","1479"],["0.4013","0"]],"a":[["0.6307","0"],["0.7453","0"]]}}
1626916416.768359: {"stream":"bchusd_210924@depth@100ms","data":{"e":"depthUpdate","E":1626916416794,"T":1626916416690,"s":"BCHUSD_210924","ps":"BCHUSD","U":167006174075,"u":167006174075,"pu":167006173038,"b":[["428.94","0"]],"a":[]}}
1626916416.770402: {"stream":"linkusd_211231@depth@100ms","data":{"e":"depthUpdate","E":1626916416797,"T":1626916416706,"s":"LINKUSD_211231","ps":"LINKUSD","U":167006174096,"u":167006174170,"pu":167006173656,"b":[],"a":[["15.324","1011"],["15.326","140"]]}}
1626916416.776526: {"stream":"trxusd_perp@depth@100ms","data":{"e":"depthUpdate","E":1626916416804,"T":1626916416793,"s":"TRXUSD_PERP","ps":"TRXUSD","U":167006174126,"u":167006174539,"pu":167006174079,"b":[["0.05329","1554"],["0.05343","1470"],["0.05344","933"]],"a":[["0.05348","451"],["0.05349","422"],["0.05350","3397"],["0.05351","2610"]]}}
1626916416.815903: {"stream":"eosusd_perp@depth@100ms","data":{"e":"depthUpdate","E":1626916416843,"T":1626916416828,"s":"EOSUSD_PERP","ps":"EOSUSD","U":167006174281,"u":167006174689,"pu":167006174197,"b":[["3.468","0"]],"a":[]}}
1626916416.819408: {"stream":"ethusd_210924@depth@100ms","data":{"e":"depthUpdate","E":1626916416846,"T":1626916416835,"s":"ETHUSD_210924","ps":"ETHUSD","U":167006174286,"u":167006174719,"pu":167006174229,"b":[["1989.04","7315"],["1989.31","1002"],["1990.67","0"],["1990.70","0"],["1990.71","0"],["1990.74","0"],["1990.75","0"],["1990.78","360"],["1990.79","127"]],"a":[["4000.00","0"]]}}
1626916416.854024: {"stream":"etcusd_perp@depth@100ms","data":{"e":"depthUpdate","E":1626916416880,"T":1626916416868,"s":"ETCUSD_PERP","ps":"ETCUSD","U":167006174437,"u":167006174851,"pu":167006173912,"b":[["42.202","987"],["42.204","323"],["42.206","0"],["42.209","1563"],["42.210","1370"],["42.217","0"],["42.220","0"],["42.229","0"]],"a":[["42.248","400"],["42.252","450"],["42.265","90"],["42.275","0"],["42.280","496"],["42.295","0"],["42.431","926"],["42.501","0"]]}}
1626916416.859245: {"stream":"bchusd_perp@depth@100ms","data":{"e":"depthUpdate","E":1626916416886,"T":1626916416882,"s":"BCHUSD_PERP","ps":"BCHUSD","U":167006174465,"u":167006174895,"pu":167006174069,"b":[["426.40","264"],["427.77","25"]],"a":[["427.78","250"],["427.81","0"]]}}
1626916416.8593879: {"stream":"linkusd_perp@depth@100ms","data":{"e":"depthUpdate","E":1626916416886,"T":1626916416878,"s":"LINKUSD_PERP","ps":"LINKUSD","U":167006174463,"u":167006174880,"pu":167006174177,"b":[["15.031","1454"],["15.041","526"],["15.048","451"],["15.051","2912"],["15.059","172"],["15.062","62"]],"a":[["15.072","1265"],["15.076","224"]]}}
1626916416.8680818: {"stream":"xrpusd_perp@depth@100ms","data":{"e":"depthUpdate","E":1626916416894,"T":1626916416879,"s":"XRPUSD_PERP","ps":"XRPUSD","U":167006174513,"u":167006174881,"pu":167006174391,"b":[["0.5645","4547"],["0.5660","5142"],["0.5661","5621"]],"a":[["0.5833","216"],["2.3735","0"]]}}
1626916416.923051: {"stream":"ethusd_210924@depth@100ms","data":{"e":"depthUpdate","E":1626916416949,"T":1626916416943,"s":"ETHUSD_210924","ps":"ETHUSD","U":167006174752,"u":167006175172,"pu":167006174719,"b":[["1981.08","2500"],["1987.22","3867"],["1987.43","80"],["1988.87","0"],["1988.95","0"],["1989.00","0"],["1989.60","384"],["1989.76","322"],["1989.81","0"],["1989.84","0"],["1989.91","301"],["1990.05","50"],["1990.12","1821"],["1990.59","0"],["1990.78","0"],["1990.79","0"],["1990.80","270"],["1990.98","1015"]],"a":[["1990.99","1188"],["1991.10","176"],["1991.11","500"],["1991.22","168"],["1993.35","0"],["2000.94","3698"]]}}
1626916416.932126: {"stream":"eosusd_perp@depth@100ms","data":{"e":"depthUpdate","E":1626916416959,"T":1626916416947,"s":"EOSUSD_PERP","ps":"EOSUSD","U":167006174783,"u":167006175188,"pu":167006174689,"b":[["3.468","0"]],"a":[]}}
1626916416.955043: {"stream":"etcusd_perp@depth@100ms","data":{"e":"depthUpdate","E":1626916416982,"T":1626916416975,"s":"ETCUSD_PERP","ps":"ETCUSD","U":167006174867,"u":167006175266,"pu":167006174851,"b":[["42.202","0"],["42.208","1649"],["42.209","1585"],["42.213","0"]],"a":[["42.275","100"],["42.290","0"],["42.298","56"],["42.299","200"],["42.651","560"],["42.671","7517"]]}}
1626916416.961494: {"stream":"linkusd_perp@depth@100ms","data":{"e":"depthUpdate","E":1626916416988,"T":1626916416976,"s":"LINKUSD_PERP","ps":"LINKUSD","U":167006174918,"u":167006175270,"pu":167006174880,"b":[["15.039","254"],["15.050","560"],["15.051","2147"],["15.055","0"],["15.059","62"],["15.060","101"],["15.061","210"]],"a":[["15.066","0"],["15.073","995"],["15.076","604"]]}}
1626916416.970069: {"stream":"xrpusd_perp@depth@100ms","data":{"e":"depthUpdate","E":1626916416999,"T":1626916416970,"s":"XRPUSD_PERP","ps":"XRPUSD","U":167006174977,"u":167006175260,"pu":167006174881,"b":[["0.5644","3348"],["0.5646","23367"],["0.5660","5148"]],"a":[["0.5663","2741"],["0.5664","5471"],["0.5665","4723"],["0.5667","3706"]]}}
1626916416.98609: {"stream":"linkusd_211231@depth@100ms","data":{"e":"depthUpdate","E":1626916417012,"T":1626916416997,"s":"LINKUSD_211231","ps":"LINKUSD","U":167006175030,"u":167006175364,"pu":167006174170,"b":[["15.288","2143"],["15.289","1209"],["15.294","123"],["15.295","916"]],"a":[["15.330","62"],["63.012","0"]]}}
1626916416.990172: {"stream":"trxusd_perp@depth@100ms","data":{"e":"depthUpdate","E":1626916417018,"T":1626916417000,"s":"TRXUSD_PERP","ps":"TRXUSD","U":167006175060,"u":167006175381,"pu":167006174539,"b":[["0.05328","2866"]],"a":[["0.05347","19897"],["0.05348","451"],["0.05349","522"]]}}
1626916417.0131881: {"stream":"bchusd_perp@depth@100ms","data":{"e":"depthUpdate","E":1626916417039,"T":1626916416934,"s":"BCHUSD_PERP","ps":"BCHUSD","U":167006175148,"u":167006175148,"pu":167006174895,"b":[["427.77","1"]],"a":[]}}
1626916417.030396: {"stream":"ethusd_210924@depth@100ms","data":{"e":"depthUpdate","E":1626916417055,"T":1626916417044,"s":"ETHUSD_210924","ps":"ETHUSD","U":167006175195,"u":167006175531,"pu":167006175172,"b":[["1990.59","270"],["1990.80","0"]],"a":[["1991.11","0"],["1993.50","80"]]}}
1626916417.0456362: {"stream":"eosusd_perp@depth@100ms","data":{"e":"depthUpdate","E":1626916417073,"T":1626916417054,"s":"EOSUSD_PERP","ps":"EOSUSD","U":167006175254,"u":167006175575,"pu":167006175188,"b":[["3.468","0"]],"a":[]}}
1626916417.064946: {"stream":"linkusd_perp@depth@100ms","data":{"e":"depthUpdate","E":1626916417092,"T":1626916417086,"s":"LINKUSD_PERP","ps":"LINKUSD","U":167006175317,"u":167006175668,"pu":167006175270,"b":[["15.048","251"],["15.050","760"],["15.051","1767"],["15.055","148"]],"a":[["15.069","1299"],["15.071","828"],["15.075","464"],["15.076","224"]]}}
1626916417.068289: {"stream":"btcusd_211231@depth@100ms","data":{"e":"depthUpdate","E":1626916417096,"T":1626916416991,"s":"BTCUSD_211231","ps":"BTCUSD","U":167006175335,"u":167006175336,"pu":167006173887,"b":[["32516.9","457"],["32526.6","0"]],"a":[]}}
1626916417.0904949: {"stream":"linkusd_211231@depth@100ms","data":{"e":"depthUpdate","E":1626916417117,"T":1626916417015,"s":"LINKUSD_211231","ps":"LINKUSD","U":167006175415,"u":167006175443,"pu":167006175364,"b":[["14.758","100"],["14.834","100"],["14.909","100"],["14.984","100"],["15.060","100"]],"a":[["15.524","164"],["15.599","165"],["15.674","166"],["15.750","167"],["15.825","168"],["62.990","15278"]]}}
1626916417.106634: {"stream":"xrpusd_perp@depth@100ms","data":{"e":"depthUpdate","E":1626916417134,"T":1626916417086,"s":"XRPUSD_PERP","ps":"XRPUSD","U":167006175475,"u":167006175666,"pu":167006175260,"b":[],"a":[["0.5664","5771"],["0.5665","4423"],["0.5667","3506"],["0.5679","3477"]]}}
1626916417.120467: {"stream":"etcusd_perp@depth@100ms","data":{"e":"depthUpdate","E":1626916417149,"T":1626916417139,"s":"ETCUSD_PERP","ps":"ETCUSD","U":167006175530,"u":167006175863,"pu":167006175266,"b":[["41.847","770"],["41.866","0"],["41.894","560"],["41.906","1"],["42.187","56"],["42.196","0"],["42.208","662"],["42.209","1585"],["42.210","2440"],["42.211","455"]],"a":[["42.241","0"],["42.242","1"]]}}
1626916417.1418009: {"stream":"ethusd_210924@depth@100ms","data":{"e":"depthUpdate","E":1626916417169,"T":1626916417151,"s":"ETHUSD_210924","ps":"ETHUSD","U":167006175597,"u":167006175910,"pu":167006175531,"b":[["1987.27","1127"]],"a":[["1990.99","1968"],["1991.10","0"],["2043.92","0"]]}}
1626916417.156388: {"stream":"eosusd_perp@depth@100ms","data":{"e":"depthUpdate","E":1626916417182,"T":1626916417166,"s":"EOSUSD_PERP","ps":"EOSUSD","U":167006175656,"u":167006175987,"pu":167006175575,"b":[["3.468","0"]],"a":[]}}
1626916417.1608: {"stream":"bchusd_perp@depth@100ms","data":{"e":"depthUpdate","E":1626916417187,"T":1626916417084,"s":"BCHUSD_PERP","ps":"BCHUSD","U":167006175663,"u":167006175664,"pu":167006175148,"b":[],"a":[["427.96","0"],["428.02","150"]]}}
1626916417.169811: {"stream":"linkusd_perp@depth@100ms","data":{"e":"depthUpdate","E":1626916417196,"T":1626916417094,"s":"LINKUSD_PERP","ps":"LINKUSD","U":167006175700,"u":167006175716,"pu":167006175668,"b":[["15.052","1031"]],"a":[["15.075","844"],["15.280","0"]]}}
1626916417.215803: {"stream":"xrpusd_perp@depth@100ms","data":{"e":"depthUpdate","E":1626916417243,"T":1626916417139,"s":"XRPUSD_PERP","ps":"XRPUSD","U":167006175862,"u":167006175862,"pu":167006175666,"b":[["0.5660","5142"]],"a":[]}}
1626916417.2427561: {"stream":"ethusd_210924@depth@100ms","data":{"e":"depthUpdate","E":1626916417269,"T":1626916417255,"s":"ETHUSD_210924","ps":"ETHUSD","U":167006175988,"u":167006176326,"pu":167006175910,"b":[["1984.67","0"],["1986.52","0"],["1987.27","627"],["1988.69","0"],["1989.33","1828"],["1989.36","301"],["1989.91","0"],["1990.13","0"],["1990.34","270"],["1990.38","0"],["1990.59","0"]],"a":[]}}
1626916417.2593658: {"stream":"eosusd_perp@depth@100ms","data":{"e":"depthUpdate","E":1626916417286,"T":1626916417271,"s":"EOSUSD_PERP","ps":"EOSUSD","U":167006176040,"u":167006176398,"pu":167006175987,"b":[["3.429","492"],["3.468","0"]],"a":[["3.469","1703"]]}}
1626916417.30426: {"stream":"etcusd_perp@depth@100ms","data":{"e":"depthUpdate","E":1626916417332,"T":1626916417250,"s":"ETCUSD_PERP","ps":"ETCUSD","U":167006176201,"u":167006176293,"pu":167006175863,"b":[["42.210","1337"],["42.212","1103"]],"a":[["42.265","0"],["42.275","0"],["42.280","496"],["42.281","1338"],["42.300","100"]]}}
1626916417.317709: {"stream":"linkusd_perp@depth@100ms","data":{"e":"depthUpdate","E":1626916417344,"T":1626916417331,"s":"LINKUSD_PERP","ps":"LINKUSD","U":167006176250,"u":167006176637,"pu":167006175716,"b":[["15.016","1047"],["15.048","451"],["15.052","2176"]],"a":[["15.069","1599"],["15.071","528"],["15.274","7500"]]}}
1626916417.3182101: {"stream":"btcusd_211231@depth@100ms","data":{"e":"depthUpdate","E":1626916417346,"T":1626916417314,"s":"BTCUSD_211231","ps":"BTCUSD","U":167006176264,"u":167006176567,"pu":167006175336,"b":[],"a":[["32625.1","13"],["32894.1","318"],["33028.9","45"],["33188.9","45"],["33348.9","45"],["33508.9","46"],["33668.9","46"]]}}
1626916417.3496819: {"stream":"ethusd_210924@depth@100ms","data":{"e":"depthUpdate","E":1626916417377,"T":1626916417367,"s":"ETHUSD_210924","ps":"ETHUSD","U":167006176400,"u":167006176758,"pu":167006176326,"b":[["1985.62","1400"],["1987.42","6141"],["1987.57","0"],["1989.28","3744"],["1989.47","0"],["1990.34","0"],["1990.59","270"],["1990.98","895"]],"a":[["1992.06","0"],["1992.07","0"],["1993.91","0"],["2002.41","0"],["2023.39","0"],["2033.31","0"],["2042.78","2550"],["2043.23","0"],["2053.15","0"],["2063.06","0"]]}}
1626916417.354367: {"stream":"bchusd_perp@depth@100ms","data":{"e":"depthUpdate","E":1626916417382,"T":1626916417302,"s":"BCHUSD_PERP","ps":"BCHUSD","U":167006176416,"u":167006176510,"pu":167006175664,"b":[["426.17","712"]],"a":[["428.00","3961"],["428.01","3114"]]}}
1626916417.3578749: {"stream":"xrpusd_perp@depth@100ms","data":{"e":"depthUpdate","E":1626916417386,"T":1626916417284,"s":"XRPUSD_PERP","ps":"XRPUSD","U":167006176430,"u":167006176437,"pu":167006175862,"b":[["0.5644","3648"]],"a":[["0.5679","3777"]]}}
1626916417.361749: {"stream":"eosusd_perp@depth@100ms","data":{"e":"depthUpdate","E":1626916417390,"T":1626916417381,"s":"EOSUSD_PERP","ps":"EOSUSD","U":167006176446,"u":167006176808,"pu":167006176398,"b":[["3.468","0"]],"a":[["3.470","4798"],["3.471","4966"],["3.489","4378"],["3.503","2848"]]}}
1626916417.376856: {"stream":"bchusd_210924@depth@100ms","data":{"e":"depthUpdate","E":1626916417405,"T":1626916417300,"s":"BCHUSD_210924","ps":"BCHUSD","U":167006176505,"u":167006176505,"pu":167006174075,"b":[["428.87","3842"]],"a":[]}}
1626916417.391092: {"stream":"trxusd_perp@depth@100ms","data":{"e":"depthUpdate","E":1626916417420,"T":1626916417365,"s":"TRXUSD_PERP","ps":"TRXUSD","U":167006176577,"u":167006176757,"pu":167006175381,"b":[],"a":[["0.05392","0"],["0.05394","693"]]}}
1626916417.415029: {"stream":"etcusd_perp@depth@100ms","data":{"e":"depthUpdate","E":1626916417441,"T":1626916417355,"s":"ETCUSD_PERP","ps":"ETCUSD","U":167006176659,"u":167006176723,"pu":167006176293,"b":[["42.216","478"]],"a":[["42.265","90"],["42.270","33"],["42.280","463"],["42.281","1248"],["42.290","0"],["42.298","156"],["42.300","0"]]}}
1626916417.4598908: {"stream":"btcusd_211231@depth@100ms","data":{"e":"depthUpdate","E":1626916417487,"T":1626916417450,"s":"BTCUSD_211231","ps":"BTCUSD","U":167006176802,"u":167006177054,"pu":167006176567,"b":[["31363.0","55"],["31523.0","55"],["31683.0","55"],["31843.1","55"],["32003.1","55"]],"a":[["32646.2","1975"],["33028.9","0"],["33188.9","0"],["33348.9","0"],["33508.9","0"],["33668.9","0"]]}}
1626916417.463609: {"stream":"linkusd_perp@depth@100ms","data":{"e":"depthUpdate","E":1626916417490,"T":1626916417468,"s":"LINKUSD_PERP","ps":"LINKUSD","U":167006176828,"u":167006177120,"pu":167006176637,"b":[["15.056","1862"],["15.058","172"],["15.061","100"],["15.062","172"],["15.063","60"]],"a":[["15.076","1049"]]}}
1626916417.463795: {"stream":"eosusd_perp@depth@100ms","data":{"e":"depthUpdate","E":1626916417492,"T":1626916417476,"s":"EOSUSD_PERP","ps":"EOSUSD","U":167006176831,"u":167006177164,"pu":167006176808,"b":[["3.431","206"],["3.468","0"]],"a":[]}}
1626916417.4709299: {"stream":"ethusd_210924@depth@100ms","data":{"e":"depthUpdate","E":1626916417497,"T":1626916417490,"s":"ETHUSD_210924","ps":"ETHUSD","U":167006176848,"u":167006177229,"pu":167006176758,"b":[["996.00","42579"]],"a":[["1991.41","270"],["1991.55","1375"],["1991.56","3925"],["1991.64","0"],["1992.51","50"],["1993.38","5685"],["2001.20","9905"],["2023.72","407"],["2033.64","409"],["2043.56","412"],["2053.48","413"],["2063.40","416"]]}}
1626916417.493427: {"stream":"xrpusd_perp@depth@100ms","data":{"e":"depthUpdate","E":1626916417520,"T":1626916417510,"s":"XRPUSD_PERP","ps":"XRPUSD","U":167006176911,"u":167006177313,"pu":167006176437,"b":[["0.5661","5620"]],"a":[["0.5662","865"],["0.5663","2711"]]}}
1626916417.5270138: {"stream":"etcusd_perp@depth@100ms","data":{"e":"depthUpdate","E":1626916417554,"T":1626916417547,"s":"ETCUSD_PERP","ps":"ETCUSD","U":167006177053,"u":167006177438,"pu":167006176723,"b":[["41.779","0"],["42.212","0"],["42.214","1201"],["42.226","0"],["42.229","300"]],"a":[["42.248","0"],["42.265","0"],["42.270","0"],["42.275","90"],["42.289","1133"],["42.490","0"]]}}
1626916417.536729: {"stream":"bchusd_perp@depth@100ms","data":{"e":"depthUpdate","E":1626916417563,"T":1626916417459,"s":"BCHUSD_PERP","ps":"BCHUSD","U":167006177085,"u":167006177085,"pu":167006176510,"b":[["427.50","4730"]],"a":[]}}
1626916417.558835: {"stream":"btcusd_211231@depth@100ms","data":{"e":"depthUpdate","E":1626916417587,"T":1626916417573,"s":"BTCUSD_211231","ps":"BTCUSD","U":167006177176,"u":167006177619,"pu":167006177054,"b":[["32516.8","0"],["32517.0","1779"],["32613.0","10"],["32616.8","0"]],"a":[["32625.1","75"],["32634.9","10"],["32639.1","0"],["33031.1","45"],["33191.1","45"],["33351.2","45"],["33511.2","46"],["33671.3","46"]]}}
1626916417.5687292: {"stream":"eosusd_perp@depth@100ms","data":{"e":"depthUpdate","E":1626916417595,"T":1626916417586,"s":"EOSUSD_PERP","ps":"EOSUSD","U":167006177209,"u":167006177717,"pu":167006177164,"b":[["3.468","0"]],"a":[["3.470","4434"],["3.471","5425"]]}}
1626916417.572118: {"stream":"linkusd_perp@depth@100ms","data":{"e":"depthUpdate","E":1626916417598,"T":1626916417577,"s":"LINKUSD_PERP","ps":"LINKUSD","U":167006177242,"u":167006177664,"pu":167006177120,"b":[["15.013","0"],["15.050","560"],["15.052","2376"]],"a":[["15.110","644"]]}}
1626916417.572317: {"stream":"linkusd_211231@depth@100ms","data":{"e":"depthUpdate","E":1626916417598,"T":1626916417493,"s":"LINKUSD_211231","ps":"LINKUSD","U":167006177239,"u":167006177239,"pu":167006175443,"b":[],"a":[["15.363","57"]]}}
1626916417.573911: {"stream":"trxusd_perp@depth@100ms","data":{"e":"depthUpdate","E":1626916417602,"T":1626916417517,"s":"TRXUSD_PERP","ps":"TRXUSD","U":167006177257,"u":167006177327,"pu":167006176757,"b":[],"a":[["0.05349","620"],["0.05353","2036"]]}}
1626916417.580321: {"stream":"ethusd_210924@depth@100ms","data":{"e":"depthUpdate","E":1626916417606,"T":1626916417586,"s":"ETHUSD_210924","ps":"ETHUSD","U":167006177267,"u":167006177723,"pu":167006177229,"b":[["1966.69","0"]],"a":[["1991.14","500"],["1991.41","270"],["1991.64","0"],["1994.85","500"]]}}
1626916417.6335208: {"stream":"etcusd_perp@depth@100ms","data":{"e":"depthUpdate","E":1626916417660,"T":1626916417648,"s":"ETCUSD_PERP","ps":"ETCUSD","U":167006177461,"u":167006177986,"pu":167006177438,"b":[["41.746","72"],["42.208","732"]],"a":[["42.239","1"],["42.242","0"],["42.255","600"],["42.265","0"],["42.274","90"],["42.275","0"],["42.277","72"],["42.490","200"]]}}
1626916417.653795: {"stream":"xrpusd_perp@depth@100ms","data":{"e":"depthUpdate","E":1626916417680,"T":1626916417595,"s":"XRPUSD_PERP","ps":"XRPUSD","U":167006177644,"u":167006177787,"pu":167006177313,"b":[["0.5622","316"],["0.5660","5148"]],"a":[["0.5701","1544"]]}}
1626916417.666909: {"stream":"bchusd_perp@depth@100ms","data":{"e":"depthUpdate","E":1626916417694,"T":1626916417663,"s":"BCHUSD_PERP","ps":"BCHUSD","U":167006177754,"u":167006178044,"pu":167006177085,"b":[["85.58","978"],["299.54","4890"],["385.13","4890"],["415.08","2445"],["427.00","226"],["427.77","1"]],"a":[["440.77","2445"],["470.72","4890"],["556.31","4890"],["1771.61","24452"]]}}
1626916417.680587: {"stream":"eosusd_perp@depth@100ms","data":{"e":"depthUpdate","E":1626916417708,"T":1626916417687,"s":"EOSUSD_PERP","ps":"EOSUSD","U":167006177819,"u":167006178170,"pu":167006177717,"b":[["3.468","0"]],"a":[]}}
1626916417.682818: {"stream":"linkusd_perp@depth@100ms","data":{"e":"depthUpdate","E":1626916417710,"T":1626916417690,"s":"LINKUSD_PERP","ps":"LINKUSD","U":167006177831,"u":167006178178,"pu":167006177664,"b":[["14.957","19"],["15.018","0"],["15.055","0"]],"a":[["15.068","2619"],["15.069","1299"],["15.071","828"],["15.166","300"]]}}
1626916417.689742: {"stream":"ethusd_210924@depth@100ms","data":{"e":"depthUpdate","E":1626916417716,"T":1626916417612,"s":"ETHUSD_210924","ps":"ETHUSD","U":167006177859,"u":167006177859,"pu":167006177723,"b":[],"a":[["3980.00","100000"]]}}
1626916417.744799: {"stream":"etcusd_perp@depth@100ms","data":{"e":"depthUpdate","E":1626916417772,"T":1626916417666,"s":"ETCUSD_PERP","ps":"ETCUSD","U":167006178065,"u":167006178066,"pu":167006177986,"b":[],"a":[["42.265","90"],["42.274","0"]]}}
1626916417.7544582: {"stream":"btcusd_211231@depth@100ms","data":{"e":"depthUpdate","E":1626916417781,"T":1626916417727,"s":"BTCUSD_211231","ps":"BTCUSD","U":167006178096,"u":167006178321,"pu":167006177619,"b":[["31363.0","0"],["31523.0","0"],["31683.0","0"],["31843.1","0"],["32003.1","0"],["32517.0","0"],["32527.6","0"]],"a":[["32626.5","5"],["32646.9","0"]]}}
1626916417.786122: {"stream":"eosusd_perp@depth@100ms","data":{"e":"depthUpdate","E":1626916417814,"T":1626916417795,"s":"EOSUSD_PERP","ps":"EOSUSD","U":167006178249,"u":167006178661,"pu":167006178170,"b":[["3.468","0"]],"a":[]}}
1626916417.7936819: {"stream":"linkusd_211231@depth@100ms","data":{"e":"depthUpdate","E":1626916417822,"T":1626916417817,"s":"LINKUSD_211231","ps":"LINKUSD","U":167006178282,"u":167006178751,"pu":167006177239,"b":[["15.296","321"]],"a":[["15.322","1045"],["15.323","355"],["15.324","0"],["15.358","1649"]]}}
1626916417.7944372: {"stream":"trxusd_perp@depth@100ms","data":{"e":"depthUpdate","E":1626916417822,"T":1626916417812,"s":"TRXUSD_PERP","ps":"TRXUSD","U":167006178281,"u":167006178727,"pu":167006177327,"b":[["0.05306","809"],["0.05326","401"],["0.05343","1470"],["0.05344","833"],["0.05345","391"]],"a":[["0.05365","3572"],["0.05385","1812"]]}}
1626916417.812851: {"stream":"bchusd_perp@depth@100ms","data":{"e":"depthUpdate","E":1626916417840,"T":1626916417745,"s":"BCHUSD_PERP","ps":"BCHUSD","U":167006178350,"u":167006178392,"pu":167006178044,"b":[],"a":[["427.87","184"],["428.02","50"],["428.49","500"],["428.78","0"]]}}
1626916417.817167: {"stream":"ethusd_210924@depth@100ms","data":{"e":"depthUpdate","E":1626916417844,"T":1626916417775,"s":"ETHUSD_210924","ps":"ETHUSD","U":167006178369,"u":167006178564,"pu":167006177859,"b":[["1987.24","1144"],["1988.94","7339"],["1989.04","0"],["1990.34","0"],["1990.59","270"]],"a":[["1992.51","0"]]}}
1626916417.8596869: {"stream":"etcusd_perp@depth@100ms","data":{"e":"depthUpdate","E":1626916417886,"T":1626916417865,"s":"ETCUSD_PERP","ps":"ETCUSD","U":167006178582,"u":167006178978,"pu":167006178066,"b":[["42.225","33"]],"a":[["42.265","90"],["42.275","0"]]}}
1626916417.859848: {"stream":"btcusd_211231@depth@100ms","data":{"e":"depthUpdate","E":1626916417886,"T":1626916417830,"s":"BTCUSD_211231","ps":"BTCUSD","U":167006178581,"u":167006178810,"pu":167006178321,"b":[["31362.9","55"],["31522.9","55"],["31682.9","55"],["31843.0","55"],["32003.0","55"],["32556.3","12"],["32605.9","0"]],"a":[["32626.4","153"],["32631.6","0"],["32631.7","0"]]}}
1626916417.8678741: {"stream":"xrpusd_perp@depth@100ms","data":{"e":"depthUpdate","E":1626916417895,"T":1626916417790,"s":"XRPUSD_PERP","ps":"XRPUSD","U":167006178631,"u":167006178631,"pu":167006177787,"b":[["0.5660","5142"]],"a":[]}}
1626916417.895157: {"stream":"eosusd_perp@depth@100ms","data":{"e":"depthUpdate","E":1626916417921,"T":1626916417913,"s":"EOSUSD_PERP","ps":"EOSUSD","U":167006178757,"u":167006179237,"pu":167006178661,"b":[["3.456","1153"],["3.468","0"]],"a":[["3.473","2399"],["3.476","3736"]]}}
1626916417.9080582: {"stream":"linkusd_211231@depth@100ms","data":{"e":"depthUpdate","E":1626916417934,"T":1626916417828,"s":"LINKUSD_211231","ps":"LINKUSD","U":167006178788,"u":167006178788,"pu":167006178751,"b":[],"a":[["15.323","0"]]}}
1626916417.92879: {"stream":"linkusd_perp@depth@100ms","data":{"e":"depthUpdate","E":1626916417955,"T":1626916417899,"s":"LINKUSD_PERP","ps":"LINKUSD","U":167006178894,"u":167006179111,"pu":167006178178,"b":[],"a":[["15.065","0"],["15.066","100"],["15.067","673"],["15.069","1299"],["15.070","2257"],["15.071","828"]]}}
1626916417.980157: {"stream":"trxusd_perp@depth@100ms","data":{"e":"depthUpdate","E":1626916418005,"T":1626916417971,"s":"TRXUSD_PERP","ps":"TRXUSD","U":167006179122,"u":167006179590,"pu":167006178727,"b":[["0.05306","1121"],["0.05326","557"],["0.05344","933"],["0.05345","291"]],"a":[["0.05347","19997"],["0.05348","451"],["0.05349","520"],["0.05365","3724"],["0.05385","2112"]]}}
1626916417.999413: {"stream":"xrpusd_perp@depth@100ms","data":{"e":"depthUpdate","E":1626916418025,"T":1626916418000,"s":"XRPUSD_PERP","ps":"XRPUSD","U":167006179282,"u":167006179798,"pu":167006178631,"b":[["0.5622","916"]],"a":[["0.5662","1404"],["0.5701","2144"]]}}
1626916417.9995131: {"stream":"etcusd_perp@depth@100ms","data":{"e":"depthUpdate","E":1626916418025,"T":1626916417983,"s":"ETCUSD_PERP","ps":"ETCUSD","U":167006179273,"u":167006179686,"pu":167006178978,"b":[["42.214","98"],["42.217","0"],["42.218","1741"],["42.219","0"]],"a":[["42.252","150"],["42.258","300"],["42.265","0"],["42.275","90"],["42.298","56"],["42.299","0"],["42.303","200"],["42.306","200"]]}}
1626916417.9996521: {"stream":"bchusd_perp@depth@100ms","data":{"e":"depthUpdate","E":1626916418026,"T":1626916418021,"s":"BCHUSD_PERP","ps":"BCHUSD","U":167006179277,"u":167006179940,"pu":167006178392,"b":[["422.45","0"],["425.60","907"],["427.51","295"],["427.58","658"],["427.77","25"]],"a":[["427.87","84"]]}}
1626916418.0063732: {"stream":"eosusd_perp@depth@100ms","data":{"e":"depthUpdate","E":1626916418033,"T":1626916418027,"s":"EOSUSD_PERP","ps":"EOSUSD","U":167006179298,"u":167006179995,"pu":167006179237,"b":[["3.456","1254"],["3.468","0"]],"a":[["3.470","4534"],["3.471","5225"]]}}
1626916418.030126: {"stream":"btcusd_211231@depth@100ms","data":{"e":"depthUpdate","E":1626916418057,"T":1626916418042,"s":"BTCUSD_211231","ps":"BTCUSD","U":167006179394,"u":167006180084,"pu":167006178810,"b":[["32591.9","0"],["32609.1","345"],["32625.0","77"]],"a":[["32626.4","0"],["32634.8","153"]]}}
1626916418.054904: {"stream":"bchusd_210924@depth@100ms","data":{"e":"depthUpdate","E":1626916418079,"T":1626916418065,"s":"BCHUSD_210924","ps":"BCHUSD","U":167006179604,"u":167006180209,"pu":167006176505,"b":[["428.87","0"]],"a":[["429.47","0"],["429.48","0"],["429.49","40"],["429.50","40"],["429.51","0"],["429.52","0"],["429.53","0"],["429.57","0"],["429.58","0"],["429.70","2701"]]}}
1626916418.0639539: {"stream":"linkusd_perp@depth@100ms","data":{"e":"depthUpdate","E":1626916418091,"T":1626916418072,"s":"LINKUSD_PERP","ps":"LINKUSD","U":167006179713,"u":167006180267,"pu":167006179111,"b":[["15.052","1231"],["15.053","4296"],["15.054","1504"]],"a":[["15.068","0"],["15.069","1599"],["15.071","528"]]}}
1626916418.075715: {"stream":"ethusd_210924@depth@100ms","data":{"e":"depthUpdate","E":1626916418101,"T":1626916418093,"s":"ETHUSD_210924","ps":"ETHUSD","U":167006179770,"u":167006180347,"pu":167006178564,"b":[["1987.11","501"],["1987.16","0"],["1987.27","0"],["1987.32","0"],["1987.37","1000"],["1987.48","0"],["1987.56","0"],["1987.71","0"],["1987.83","0"],["1988.06","12"],["1988.10","0"],["1988.36","0"],["1989.79","0"],["1990.05","0"],["1990.06","50"],["1990.12","1562"],["1990.38","0"],["1990.59","270"],["1990.98","1015"]],"a":[["1991.41","0"],["1992.53","270"],["1993.06","0"],["1993.12","0"],["1993.24","314"],["1993.28","0"],["1993.29","0"],["1993.43","0"],["1993.44","501"],["1993.46","0"],["1993.56","0"],["1993.71","0"],["1994.12","0"],["1994.38","0"],["1994.82","0"]]}}
1626916418.090548: {"stream":"linkusd_211231@depth@100ms","data":{"e":"depthUpdate","E":1626916418115,"T":1626916418012,"s":"LINKUSD_211231","ps":"LINKUSD","U":167006179864,"u":167006179874,"pu":167006178788,"b":[["14.758","0"],["14.834","0"],["14.909","0"],["14.984","0"],["15.060","0"]],"a":[["15.524","0"],["15.599","0"],["15.674","0"],["15.750","0"],["15.825","0"]]}}
1626916418.0978718: {"stream":"etcusd_perp@depth@100ms","data":{"e":"depthUpdate","E":1626916418125,"T":1626916418119,"s":"ETCUSD_PERP","ps":"ETCUSD","U":167006179934,"u":167006180464,"pu":167006179686,"b":[["42.145","0"],["42.172","488"],["42.216","1952"],["42.218","267"]],"a":[["42.238","1"],["42.239","0"],["42.252","0"],["42.258","0"],["42.260","253"],["42.280","22"],["42.288","246"],["42.289","322"],["42.291","876"],["42.300","200"],["42.465","38"],["42.529","0"],["42.756","594"]]}}
1626916418.098987: {"stream":"xrpusd_perp@depth@100ms","data":{"e":"depthUpdate","E":1626916418127,"T":1626916418027,"s":"XRPUSD_PERP","ps":"XRPUSD","U":167006179944,"u":167006179989,"pu":167006179798,"b":[["0.5657","5704"],["0.5658","2376"]],"a":[]}}
1626916418.10129: {"stream":"bchusd_perp@depth@100ms","data":{"e":"depthUpdate","E":1626916418127,"T":1626916418031,"s":"BCHUSD_PERP","ps":"BCHUSD","U":167006179946,"u":167006180012,"pu":167006179940,"b":[],"a":[["427.87","184"],["428.02","50"]]}}
1626916418.117959: {"stream":"eosusd_perp@depth@100ms","data":{"e":"depthUpdate","E":1626916418144,"T":1626916418129,"s":"EOSUSD_PERP","ps":"EOSUSD","U":167006180059,"u":167006180508,"pu":167006179995,"b":[["3.452","5312"],["3.468","0"]],"a":[]}}
1626916418.1289: {"stream":"btcusd_211231@depth@100ms","data":{"e":"depthUpdate","E":1626916418157,"T":1626916418145,"s":"BTCUSD_211231","ps":"BTCUSD","U":167006180135,"u":167006180584,"pu":167006180084,"b":[["32494.0","902"],["32589.0","0"]],"a":[["32699.6","0"]]}}
1626916418.170369: {"stream":"linkusd_perp@depth@100ms","data":{"e":"depthUpdate","E":1626916418197,"T":1626916418186,"s":"LINKUSD_PERP","ps":"LINKUSD","U":167006180348,"u":167006180852,"pu":167006180267,"b":[["15.063","250"]],"a":[["15.066","100"],["15.067","150"],["15.068","0"],["15.069","1599"],["15.071","528"],["15.074","1397"],["15.076","1249"]]}}
1626916418.178138: {"stream":"trxusd_perp@depth@100ms","data":{"e":"depthUpdate","E":1626916418205,"T":1626916418200,"s":"TRXUSD_PERP","ps":"TRXUSD","U":167006180374,"u":167006180923,"pu":167006179590,"b":[["0.05333","2855"],["0.05337","2363"],["0.05338","183"],["0.05340","2438"],["0.05344","833"],["0.05345","391"]],"a":[["0.05347","19897"],["0.05348","451"],["0.05349","520"],["0.05350","3397"],["0.05351","2410"],["0.05352","1144"]]}}
1626916418.181793: {"stream":"bchusd_210924@depth@100ms","data":{"e":"depthUpdate","E":1626916418207,"T":1626916418188,"s":"BCHUSD_210924","ps":"BCHUSD","U":167006180378,"u":167006180860,"pu":167006180209,"b":[["429.36","0"]],"a":[["429.75","121"],["429.76","27"],["1722.25","12139"],["1722.38","0"]]}}
1626916418.1824288: {"stream":"ethusd_210924@depth@100ms","data":{"e":"depthUpdate","E":1626916418209,"T":1626916418190,"s":"ETHUSD_210924","ps":"ETHUSD","U":167006180397,"u":167006180868,"pu":167006180347,"b":[["1986.84","783"],["1986.95","627"],["1987.20","532"],["1987.42","6542"],["1987.50","469"],["1987.65","321"],["1987.76","414"],["1988.00","365"],["1988.12","981"],["1988.30","789"]],"a":[["1991.54","270"],["1991.78","1237"],["1992.11","0"],["1992.53","0"],["1992.79","289"],["1992.89","365"],["1993.04","321"],["1993.06","414"],["1993.19","469"],["1993.21","401"],["1993.29","532"],["1993.85","627"],["1994.16","783"],["1994.62","541"]]}}
1626916418.197323: {"stream":"linkusd_211231@depth@100ms","data":{"e":"depthUpdate","E":1626916418223,"T":1626916418186,"s":"LINKUSD_211231","ps":"LINKUSD","U":167006180453,"u":167006180850,"pu":167006179874,"b":[["3.141","770"],["3.142","0"],["14.760","1122"],["14.836","100"],["14.911","100"],["14.986","100"],["15.062","100"],["15.294","273"]],"a":[["15.330","212"]]}}
1626916418.216293: {"stream":"etcusd_perp@depth@100ms","data":{"e":"depthUpdate","E":1626916418242,"T":1626916418219,"s":"ETCUSD_PERP","ps":"ETCUSD","U":167006180541,"u":167006181012,"pu":167006180464,"b":[["42.200","0"],["42.208","1758"],["42.216","478"],["42.218","1741"],["42.229","0"],["42.233","780"],["42.237","684"]],"a":[["42.254","0"],["42.255","600"],["42.259","134"],["42.260","0"],["42.265","90"],["42.268","130"],["42.275","0"],["42.312","1716"]]}}
1626916418.220576: {"stream":"eosusd_perp@depth@100ms","data":{"e":"depthUpdate","E":1626916418247,"T":1626916418236,"s":"EOSUSD_PERP","ps":"EOSUSD","U":167006180573,"u":167006181069,"pu":167006180508,"b":[["3.464","4557"],["3.465","7437"],["3.468","0"]],"a":[]}}
1626916418.224971: {"stream":"xrpusd_perp@depth@100ms","data":{"e":"depthUpdate","E":1626916418254,"T":1626916418206,"s":"XRPUSD_PERP","ps":"XRPUSD","U":167006180608,"u":167006180951,"pu":167006179989,"b":[["0.5655","6625"],["0.5660","5442"],["0.5661","5270"]],"a":[["0.5662","865"],["0.5665","4623"]]}}
1626916418.225129: {"stream":"bchusd_perp@depth@100ms","data":{"e":"depthUpdate","E":1626916418254,"T":1626916418244,"s":"BCHUSD_PERP","ps":"BCHUSD","U":167006180615,"u":167006181106,"pu":167006180012,"b":[["422.61","69"],["425.60","507"],["427.27","0"],["427.28","0"]],"a":[["427.87","84"],["428.02","150"]]}}
1626916418.231919: {"stream":"btcusd_211231@depth@100ms","data":{"e":"depthUpdate","E":1626916418259,"T":1626916418168,"s":"BTCUSD_211231","ps":"BTCUSD","U":167006180645,"u":167006180735,"pu":167006180584,"b":[["32589.0","15"]],"a":[["32625.1","13"],["32633.9","46"]]}}
1626916418.2787452: {"stream":"trxusd_perp@depth@100ms","data":{"e":"depthUpdate","E":1626916418306,"T":1626916418282,"s":"TRXUSD_PERP","ps":"TRXUSD","U":167006180924,"u":167006181276,"pu":167006180923,"b":[["0.05337","3092"],["0.05339","775"]],"a":[["0.05348","451"],["0.05349","620"],["0.05350","3397"],["0.05351","2610"],["0.05352","1144"],["0.05355","1249"],["0.05356","899"],["0.05397","2857"]]}}
1626916418.283479: {"stream":"linkusd_perp@depth@100ms","data":{"e":"depthUpdate","E":1626916418310,"T":1626916418225,"s":"LINKUSD_PERP","ps":"LINKUSD","U":167006180950,"u":167006181040,"pu":167006180852,"b":[["15.015","628"],["15.063","60"]],"a":[["15.069","1299"],["15.071","828"],["15.112","1851"]]}}
1626916418.299995: {"stream":"ethusd_210924@depth@100ms","data":{"e":"depthUpdate","E":1626916418327,"T":1626916418322,"s":"ETHUSD_210924","ps":"ETHUSD","U":167006181030,"u":167006181439,"pu":167006180868,"b":[["1986.45","500"],["1987.27","500"],["1989.33","0"],["1989.36","0"],["1989.37","2141"],["1989.99","280"],["1990.01","301"]],"a":[["1991.54","0"],["1991.64","270"],["1991.93","280"],["1992.11","0"],["2009.16","2950"]]}}
1626916418.318985: {"stream":"etcusd_perp@depth@100ms","data":{"e":"depthUpdate","E":1626916418346,"T":1626916418327,"s":"ETCUSD_PERP","ps":"ETCUSD","U":167006181097,"u":167006181461,"pu":167006181012,"b":[["42.192","0"],["42.202","200"],["42.204","423"],["42.215","70"],["42.218","267"],["42.219","1474"],["42.220","200"],["42.221","15"],["42.228","0"],["42.237","774"]],"a":[["42.255","200"],["42.258","100"],["42.265","0"],["42.275","498"],["42.276","536"],["42.291","0"],["42.296","875"],["42.303","0"],["42.304","100"],["42.306","0"],["42.324","200"]]}}
1626916418.327756: {"stream":"linkusd_211231@depth@100ms","data":{"e":"depthUpdate","E":1626916418354,"T":1626916418252,"s":"LINKUSD_211231","ps":"LINKUSD","U":167006181138,"u":167006181152,"pu":167006180850,"b":[["15.294","150"],["15.296","444"]],"a":[]}}
1626916418.332312: {"stream":"btcusd_211231@depth@100ms","data":{"e":"depthUpdate","E":1626916418360,"T":1626916418342,"s":"BTCUSD_211231","ps":"BTCUSD","U":167006181160,"u":167006181512,"pu":167006180735,"b":[["32609.1","0"]],"a":[["32625.1","12"],["32632.9","46"],["32633.8","153"],["32633.9","0"],["32634.8","0"],["32708.6","387"]]}}
1626916418.335608: {"stream":"eosusd_perp@depth@100ms","data":{"e":"depthUpdate","E":1626916418362,"T":1626916418344,"s":"EOSUSD_PERP","ps":"EOSUSD","U":167006181175,"u":167006181523,"pu":167006181069,"b":[["3.462","5474"],["3.468","0"]],"a":[]}}
1626916418.340101: {"stream":"bchusd_perp@depth@100ms","data":{"e":"depthUpdate","E":1626916418366,"T":1626916418338,"s":"BCHUSD_PERP","ps":"BCHUSD","U":167006181191,"u":167006181493,"pu":167006181106,"b":[["427.57","0"],["427.64","400"]],"a":[["427.78","150"],["427.81","100"],["427.86","0"]]}}
1626916418.376173: {"stream":"xrpusd_perp@depth@100ms","data":{"e":"depthUpdate","E":1626916418404,"T":1626916418363,"s":"XRPUSD_PERP","ps":"XRPUSD","U":167006181331,"u":167006181596,"pu":167006180951,"b":[["0.5658","3256"],["0.5659","1534"]],"a":[["0.5665","4658"],["0.5666","1724"],["0.5677","882"]]}}
1626916418.392343: {"stream":"trxusd_perp@depth@100ms","data":{"e":"depthUpdate","E":1626916418418,"T":1626916418315,"s":"TRXUSD_PERP","ps":"TRXUSD","U":167006181406,"u":167006181411,"pu":167006181276,"b":[],"a":[["0.05348","351"],["0.05349","620"],["0.05350","3497"],["0.05394","1761"]]}}
1626916418.4045482: {"stream":"ethusd_210924@depth@100ms","data":{"e":"depthUpdate","E":1626916418430,"T":1626916418425,"s":"ETHUSD_210924","ps":"ETHUSD","U":167006181457,"u":167006181850,"pu":167006181439,"b":[["1989.34","0"],["1989.79","0"],["1989.99","0"],["1990.06","50"],["1990.13","0"],["1990.46","270"],["1990.59","0"]],"a":[["1991.41","270"],["1991.64","0"]]}}
1626916418.424202: {"stream":"etcusd_perp@depth@100ms","data":{"e":"depthUpdate","E":1626916418450,"T":1626916418431,"s":"ETCUSD_PERP","ps":"ETCUSD","U":167006181535,"u":167006181871,"pu":167006181461,"b":[["42.187","0"],["42.209","1563"],["42.217","22"],["42.219","0"],["42.220","1674"]],"a":[["42.267","90"],["42.275","0"],["42.276","446"]]}}
1626916418.440133: {"stream":"linkusd_perp@depth@100ms","data":{"e":"depthUpdate","E":1626916418466,"T":1626916418455,"s":"LINKUSD_PERP","ps":"LINKUSD","U":167006181591,"u":167006181963,"pu":167006181040,"b":[["14.959","2885"]],"a":[["15.069","4629"],["15.071","728"],["15.075","944"],["15.121","150"],["15.168","4421"]]}}
1626916418.444538: {"stream":"eosusd_perp@depth@100ms","data":{"e":"depthUpdate","E":1626916418471,"T":1626916418445,"s":"EOSUSD_PERP","ps":"EOSUSD","U":167006181633,"u":167006181912,"pu":167006181523,"b":[["3.464","4657"],["3.465","7337"],["3.468","0"]],"a":[]}}
1626916418.444682: {"stream":"btcusd_211231@depth@100ms","data":{"e":"depthUpdate","E":1626916418471,"T":1626916418414,"s":"BTCUSD_211231","ps":"BTCUSD","U":167006181622,"u":167006181799,"pu":167006181512,"b":[["32261.6","0"]],"a":[["32625.1","13"],["32631.9","46"],["32632.8","153"],["32632.9","0"],["32633.8","0"]]}}
1626916418.51001: {"stream":"linkusd_211231@depth@100ms","data":{"e":"depthUpdate","E":1626916418535,"T":1626916418485,"s":"LINKUSD_211231","ps":"LINKUSD","U":167006181873,"u":167006182091,"pu":167006181152,"b":[["15.307","80"]],"a":[["15.328","0"],["15.330","150"],["15.544","0"]]}}
1626916418.5229309: {"stream":"xrpusd_perp@depth@100ms","data":{"e":"depthUpdate","E":1626916418550,"T":1626916418465,"s":"XRPUSD_PERP","ps":"XRPUSD","U":167006181915,"u":167006181997,"pu":167006181596,"b":[],"a":[["0.5662","835"],["0.5663","2741"]]}}
1626916418.523028: {"stream":"etcusd_perp@depth@100ms","data":{"e":"depthUpdate","E":1626916418550,"T":1626916418547,"s":"ETCUSD_PERP","ps":"ETCUSD","U":167006181916,"u":167006182336,"pu":167006181871,"b":[["42.197","56"],["42.205","0"],["42.207","1310"],["42.215","92"],["42.226","90"],["42.237","684"]],"a":[["42.258","0"],["42.259","0"],["42.264","400"],["42.265","100"],["42.279","1241"],["42.288","0"],["42.290","33"]]}}
1626916418.530179: {"stream":"ethusd_210924@depth@100ms","data":{"e":"depthUpdate","E":1626916418557,"T":1626916418551,"s":"ETHUSD_210924","ps":"ETHUSD","U":167006181947,"u":167006182360,"pu":167006181850,"b":[["1986.43","120"],["1989.99","280"]],"a":[["2023.72","0"],["2033.64","0"],["2043.56","0"],["2053.48","0"],["2063.40","0"],["2072.09","0"],["2145.08","7962"]]}}
1626916418.54703: {"stream":"eosusd_perp@depth@100ms","data":{"e":"depthUpdate","E":1626916418573,"T":1626916418489,"s":"EOSUSD_PERP","ps":"EOSUSD","U":167006182002,"u":167006182107,"pu":167006181912,"b":[["3.468","0"]],"a":[]}}
1626916418.555557: {"stream":"btcusd_211231@depth@100ms","data":{"e":"depthUpdate","E":1626916418580,"T":1626916418565,"s":"BTCUSD_211231","ps":"BTCUSD","U":167006182056,"u":167006182411,"pu":167006181799,"b":[],"a":[["32626.4","153"],["32630.9","46"],["32631.8","0"],["32631.9","0"],["32632.8","0"],["32957.6","0"]]}}
1626916418.591441: {"stream":"trxusd_perp@depth@100ms","data":{"e":"depthUpdate","E":1626916418618,"T":1626916418514,"s":"TRXUSD_PERP","ps":"TRXUSD","U":167006182189,"u":167006182197,"pu":167006181411,"b":[],"a":[["0.05348","451"],["0.05349","620"],["0.05350","3397"]]}}
1626916418.591594: {"stream":"bchusd_perp@depth@100ms","data":{"e":"depthUpdate","E":1626916418619,"T":1626916418613,"s":"BCHUSD_PERP","ps":"BCHUSD","U":167006182190,"u":167006182594,"pu":167006181493,"b":[["427.58","0"],["427.61","658"]],"a":[["427.81","0"],["427.86","100"],["427.96","0"],["428.10","325"],["428.46","0"]]}}
1626916418.628386: {"stream":"etcusd_perp@depth@100ms","data":{"e":"depthUpdate","E":1626916418656,"T":1626916418648,"s":"ETCUSD_PERP","ps":"ETCUSD","U":167006182355,"u":167006182721,"pu":167006182336,"b":[["42.194","56"],["42.217","264"],["42.220","200"],["42.221","1489"],["42.226","0"],["42.237","774"]],"a":[["42.263","100"],["42.265","0"],["42.287","22"],["42.295","253"],["42.300","0"],["42.310","779"],["42.410","0"]]}}
1626916418.6494908: {"stream":"ethusd_210924@depth@100ms","data":{"e":"depthUpdate","E":1626916418674,"T":1626916418655,"s":"ETHUSD_210924","ps":"ETHUSD","U":167006182425,"u":167006182742,"pu":167006182360,"b":[["1987.27","0"],["1990.98","895"]],"a":[["1992.66","1066"],["2023.38","408"],["2033.30","410"],["2043.22","412"],["2053.13","414"],["2063.05","416"],["2143.43","2652"]]}}
1626916418.649737: {"stream":"bchusd_210924@depth@100ms","data":{"e":"depthUpdate","E":1626916418676,"T":1626916418595,"s":"BCHUSD_210924","ps":"BCHUSD","U":167006182428,"u":167006182533,"pu":167006180860,"b":[],"a":[["429.49","40"],["429.58","0"]]}}
1626916418.667936: {"stream":"xrpusd_perp@depth@100ms","data":{"e":"depthUpdate","E":1626916418695,"T":1626916418600,"s":"XRPUSD_PERP","ps":"XRPUSD","U":167006182508,"u":167006182544,"pu":167006181997,"b":[],"a":[["0.5662","1144"],["0.5677","1183"]]}}
1626916418.668073: {"stream":"btcusd_211231@depth@100ms","data":{"e":"depthUpdate","E":1626916418695,"T":1626916418660,"s":"BTCUSD_211231","ps":"BTCUSD","U":167006182509,"u":167006182759,"pu":167006182411,"b":[["32494.1","1782"]],"a":[["32626.4","0"],["32629.9","46"],["32630.8","153"],["32630.9","0"]]}}
1626916418.707551: {"stream":"bchusd_perp@depth@100ms","data":{"e":"depthUpdate","E":1626916418736,"T":1626916418728,"s":"BCHUSD_PERP","ps":"BCHUSD","U":167006182648,"u":167006183038,"pu":167006182594,"b":[["427.00","626"],["427.56","598"],["427.65","520"],["427.77","1"]],"a":[]}}
1626916418.7079308: {"stream":"linkusd_211231@depth@100ms","data":{"e":"depthUpdate","E":1626916418736,"T":1626916418720,"s":"LINKUSD_211231","ps":"LINKUSD","U":167006182654,"u":167006183002,"pu":167006182091,"b":[],"a":[["15.327","0"],["15.328","62"],["15.508","5515"]]}}
1626916418.750153: {"stream":"ethusd_210924@depth@100ms","data":{"e":"depthUpdate","E":1626916418776,"T":1626916418762,"s":"ETHUSD_210924","ps":"ETHUSD","U":167006182800,"u":167006183148,"pu":167006182742,"b":[["1989.37","0"],["1989.77","2249"],["1990.98","1015"]],"a":[["1991.40","0"],["1991.41","0"],["1991.64","0"],["1991.84","270"],["2073.41","2587"],["2143.43","5304"],["2145.08","5308"]]}}
1626916418.753332: {"stream":"eosusd_perp@depth@100ms","data":{"e":"depthUpdate","E":1626916418780,"T":1626916418774,"s":"EOSUSD_PERP","ps":"EOSUSD","U":167006182813,"u":167006183196,"pu":167006182107,"b":[["3.462","5381"],["3.468","0"]],"a":[["3.479","3227"]]}}
1626916418.764357: {"stream":"linkusd_perp@depth@100ms","data":{"e":"depthUpdate","E":1626916418789,"T":1626916418756,"s":"LINKUSD_PERP","ps":"LINKUSD","U":167006182863,"u":167006183127,"pu":167006181963,"b":[["15.019","0"],["15.053","3279"],["15.054","2455"],["15.061","0"],["15.063","160"]],"a":[]}}
1626916418.772724: {"stream":"xrpusd_perp@depth@100ms","data":{"e":"depthUpdate","E":1626916418801,"T":1626916418715,"s":"XRPUSD_PERP","ps":"XRPUSD","U":167006182896,"u":167006182981,"pu":167006182544,"b":[["0.5660","5478"]],"a":[]}}
1626916418.777977: {"stream":"btcusd_211231@depth@100ms","data":{"e":"depthUpdate","E":1626916418805,"T":1626916418763,"s":"BTCUSD_211231","ps":"BTCUSD","U":167006182928,"u":167006183152,"pu":167006182759,"b":[["32410.7","128"],["32476.0","129"]],"a":[["32629.8","153"],["32629.9","0"],["32630.8","0"]]}}
1626916418.8181791: {"stream":"bchusd_perp@depth@100ms","data":{"e":"depthUpdate","E":1626916418844,"T":1626916418827,"s":"BCHUSD_PERP","ps":"BCHUSD","U":167006183081,"u":167006183329,"pu":167006183038,"b":[["427.77","25"]],"a":[["427.81","100"],["427.86","0"]]}}
1626916418.8183548: {"stream":"etcusd_perp@depth@100ms","data":{"e":"depthUpdate","E":1626916418844,"T":1626916418806,"s":"ETCUSD_PERP","ps":"ETCUSD","U":167006183078,"u":167006183275,"pu":167006182721,"b":[],"a":[["42.280","22"]]}}
1626916418.8520808: {"stream":"ethusd_210924@depth@100ms","data":{"e":"depthUpdate","E":1626916418879,"T":1626916418812,"s":"ETHUSD_210924","ps":"ETHUSD","U":167006183191,"u":167006183287,"pu":167006183148,"b":[["1989.25","301"],["1990.01","0"]],"a":[["1991.54","270"],["1991.84","0"]]}}
1626916418.872307: {"stream":"eosusd_perp@depth@100ms","data":{"e":"depthUpdate","E":1626916418900,"T":1626916418888,"s":"EOSUSD_PERP","ps":"EOSUSD","U":167006183235,"u":167006183523,"pu":167006183196,"b":[["3.468","0"]],"a":[["3.479","3328"]]}}
1626916418.8765812: {"stream":"trxusd_perp@depth@100ms","data":{"e":"depthUpdate","E":1626916418904,"T":1626916418800,"s":"TRXUSD_PERP","ps":"TRXUSD","U":167006183242,"u":167006183243,"pu":167006182197,"b":[["0.05344","933"],["0.05345","291"]],"a":[]}}
1626916418.880856: {"stream":"btcusd_211231@depth@100ms","data":{"e":"depthUpdate","E":1626916418908,"T":1626916418902,"s":"BTCUSD_211231","ps":"BTCUSD","U":167006183272,"u":167006183543,"pu":167006183152,"b":[["32245.3","0"],["32410.7","48"],["32476.0","48"],["32622.2","175"]],"a":[["32629.8","0"],["32633.9","46"],["32634.8","153"]]}}
1626916418.91646: {"stream":"linkusd_perp@depth@100ms","data":{"e":"depthUpdate","E":1626916418943,"T":1626916418909,"s":"LINKUSD_PERP","ps":"LINKUSD","U":167006183354,"u":167006183562,"pu":167006183127,"b":[["15.021","528"]],"a":[["15.069","4777"],["15.074","1597"],["15.076","1049"],["15.102","550"]]}}
1626916418.945947: {"stream":"linkusd_211231@depth@100ms","data":{"e":"depthUpdate","E":1626916418973,"T":1626916418886,"s":"LINKUSD_211231","ps":"LINKUSD","U":167006183482,"u":167006183518,"pu":167006183002,"b":[],"a":[["15.327","62"],["15.328","0"]]}}
1626916418.952851: {"stream":"ethusd_210924@depth@100ms","data":{"e":"depthUpdate","E":1626916418980,"T":1626916418956,"s":"ETHUSD_210924","ps":"ETHUSD","U":167006183491,"u":167006183762,"pu":167006183287,"b":[],"a":[["1991.72","0"],["1992.15","1953"],["1992.56","0"],["2143.42","2652"],["2145.08","2654"]]}}
1626916418.9691892: {"stream":"xrpusd_perp@depth@100ms","data":{"e":"depthUpdate","E":1626916418995,"T":1626916418982,"s":"XRPUSD_PERP","ps":"XRPUSD","U":167006183524,"u":167006183854,"pu":167006182981,"b":[["0.5660","5478"]],"a":[["0.5663","2711"]]}}
1626916418.983829: {"stream":"bchusd_perp@depth@100ms","data":{"e":"depthUpdate","E":1626916419013,"T":1626916418909,"s":"BCHUSD_PERP","ps":"BCHUSD","U":167006183563,"u":167006183563,"pu":167006183329,"b":[],"a":[["430.76","0"]]}}
1626916418.9859898: {"stream":"eosusd_perp@depth@100ms","data":{"e":"depthUpdate","E":1626916419013,"T":1626916419002,"s":"EOSUSD_PERP","ps":"EOSUSD","U":167006183564,"u":167006183926,"pu":167006183523,"b":[["3.468","0"]],"a":[]}}
1626916418.9891572: {"stream":"btcusd_211231@depth@100ms","data":{"e":"depthUpdate","E":1626916419017,"T":1626916418970,"s":"BTCUSD_211231","ps":"BTCUSD","U":167006183591,"u":167006183804,"pu":167006183543,"b":[["32461.9","32"]],"a":[["32632.9","46"],["32633.8","153"],["32633.9","0"],["32634.8","0"]]}}
1626916419.024909: {"stream":"etcusd_perp@depth@100ms","data":{"e":"depthUpdate","E":1626916419051,"T":1626916418971,"s":"ETCUSD_PERP","ps":"ETCUSD","U":167006183715,"u":167006183807,"pu":167006183275,"b":[["42.230","33"]],"a":[["42.294","810"],["42.296","0"]]}}
1626916419.034627: {"stream":"linkusd_perp@depth@100ms","data":{"e":"depthUpdate","E":1626916419061,"T":1626916418958,"s":"LINKUSD_PERP","ps":"LINKUSD","U":167006183763,"u":167006183764,"pu":167006183562,"b":[],"a":[["15.069","4629"],["15.121","73"]]}}
1626916419.087219: {"stream":"bchusd_perp@depth@100ms","data":{"e":"depthUpdate","E":1626916419114,"T":1626916419097,"s":"BCHUSD_PERP","ps":"BCHUSD","U":167006183957,"u":167006184434,"pu":167006183563,"b":[["427.29","0"],["427.77","25"]],"a":[["427.81","0"],["427.86","100"],["428.00","3240"],["428.94","0"]]}}
1626916419.096842: {"stream":"xrpusd_perp@depth@100ms","data":{"e":"depthUpdate","E":1626916419124,"T":1626916419106,"s":"XRPUSD_PERP","ps":"XRPUSD","U":167006183983,"u":167006184501,"pu":167006183854,"b":[["0.5661","5605"]],"a":[["0.5662","500"],["0.5664","5471"],["0.5665","4758"],["0.5667","2065"]]}}
1626916419.1007948: {"stream":"btcusd_211231@depth@100ms","data":{"e":"depthUpdate","E":1626916419127,"T":1626916419111,"s":"BTCUSD_211231","ps":"BTCUSD","U":167006184002,"u":167006184516,"pu":167006183804,"b":[["31362.9","0"],["31522.9","0"],["31682.9","0"],["31843.0","0"],["32003.0","0"],["32396.6","32"],["32494.0","0"],["32526.6","997"],["32536.2","0"],["32582.7","0"],["32612.1","118"]],"a":[["32631.9","46"],["32632.8","153"],["32632.9","0"],["32633.8","0"],["32638.3","0"],["32671.9","0"],["32735.2","0"]]}}
1626916419.101147: {"stream":"eosusd_perp@depth@100ms","data":{"e":"depthUpdate","E":1626916419128,"T":1626916419114,"s":"EOSUSD_PERP","ps":"EOSUSD","U":167006184017,"u":167006184528,"pu":167006183926,"b":[["3.444","10113"],["3.452","5563"],["3.456","1136"],["3.466","7540"],["3.468","0"]],"a":[["3.471","5169"],["3.480","1524"],["3.492","9788"]]}}
1626916419.110419: {"stream":"linkusd_211231@depth@100ms","data":{"e":"depthUpdate","E":1626916419134,"T":1626916419121,"s":"LINKUSD_211231","ps":"LINKUSD","U":167006184054,"u":167006184583,"pu":167006183518,"b":[["14.760","1022"],["14.836","0"],["14.911","0"],["14.986","0"],["15.062","0"]],"a":[["15.327","0"],["15.328","62"]]}}
1626916419.1309729: {"stream":"ethusd_210924@depth@100ms","data":{"e":"depthUpdate","E":1626916419157,"T":1626916419150,"s":"ETHUSD_210924","ps":"ETHUSD","U":167006184154,"u":167006184753,"pu":167006183762,"b":[["1982.00","356"],["1986.07","0"],["1989.25","0"],["1989.74","301"]],"a":[["1991.21","270"],["1991.23","0"],["1991.54","0"],["1991.55","0"],["1991.56","349"],["1991.85","0"],["1995.22","12"],["1995.23","0"],["1999.93","0"]]}}
1626916419.1427789: {"stream":"etcusd_perp@depth@100ms","data":{"e":"depthUpdate","E":1626916419170,"T":1626916419121,"s":"ETCUSD_PERP","ps":"ETCUSD","U":167006184243,"u":167006184578,"pu":167006183807,"b":[["42.212","1240"]],"a":[["42.266","0"],["42.275","339"],["42.304","0"],["42.314","200"],["42.324","300"],["42.366","38"],["42.388","132"],["42.452","453"],["42.528","0"]]}}
1626916419.193846: {"stream":"trxusd_perp@depth@100ms","data":{"e":"depthUpdate","E":1626916419219,"T":1626916419142,"s":"TRXUSD_PERP","ps":"TRXUSD","U":167006184531,"u":167006184655,"pu":167006183243,"b":[],"a":[["0.05348","351"],["0.05349","520"],["0.05350","3297"],["0.05351","2710"],["0.05352","1344"],["0.05355","949"],["0.05356","599"],["0.05358","1438"],["0.05359","606"]]}}
1626916419.202653: {"stream":"bchusd_perp@depth@100ms","data":{"e":"depthUpdate","E":1626916419229,"T":1626916419217,"s":"BCHUSD_PERP","ps":"BCHUSD","U":167006184591,"u":167006185308,"pu":167006184434,"b":[["424.89","0"],["426.44","0"],["427.60","0"],["427.64","3314"],["427.68","825"],["427.77","175"]],"a":[["427.87","0"],["427.97","0"],["429.34","151"],["430.67","0"]]}}
1626916419.2118661: {"stream":"btcusd_211231@depth@100ms","data":{"e":"depthUpdate","E":1626916419238,"T":1626916419210,"s":"BTCUSD_211231","ps":"BTCUSD","U":167006184620,"u":167006185253,"pu":167006184516,"b":[["27402.7","0"],["31365.2","0"],["31525.2","0"],["31685.2","0"],["31845.2","0"],["32005.3","0"],["32396.6","112"],["32461.9","113"]],"a":[["32630.9","0"],["32631.8","153"],["32631.9","0"],["32632.8","0"],["32633.9","46"],["32634.8","0"],["32694.5","375"],["32708.6","0"],["33031.1","0"],["33191.1","0"],["33351.2","0"],["33511.2","0"],["33671.3","0"]]}}
1626916419.2168021: {"stream":"eosusd_perp@depth@100ms","data":{"e":"depthUpdate","E":1626916419242,"T":1626916419232,"s":"EOSUSD_PERP","ps":"EOSUSD","U":167006184642,"u":167006185434,"pu":167006184528,"b":[["3.452","5312"],["3.468","0"]],"a":[["3.470","4434"],["3.471","5169"]]}}
1626916419.216952: {"stream":"linkusd_211231@depth@100ms","data":{"e":"depthUpdate","E":1626916419243,"T":1626916419219,"s":"LINKUSD_211231","ps":"LINKUSD","U":167006184644,"u":167006185342,"pu":167006184583,"b":[["15.294","0"]],"a":[["15.328","0"],["15.330","0"],["15.368","9"],["15.377","20"],["15.525","164"],["15.600","203"],["15.675","166"],["15.751","167"],["15.826","168"]]}}
1626916419.2301672: {"stream":"xrpusd_perp@depth@100ms","data":{"e":"depthUpdate","E":1626916419258,"T":1626916419236,"s":"XRPUSD_PERP","ps":"XRPUSD","U":167006184778,"u":167006185452,"pu":167006184501,"b":[["0.5646","23066"],["0.5653","5353"],["0.5660","5148"],["0.5661","5983"]],"a":[["0.5663","2510"],["0.5665","4530"],["0.5667","2293"]]}}
1626916419.230242: {"stream":"ethusd_210924@depth@100ms","data":{"e":"depthUpdate","E":1626916419258,"T":1626916419251,"s":"ETHUSD_210924","ps":"ETHUSD","U":167006184765,"u":167006185552,"pu":167006184753,"b":[["1988.94","0"],["1988.99","9342"],["1990.37","510"],["1990.74","480"]],"a":[["1991.14","0"],["1991.22","0"],["1991.52","1288"],["1991.53","3680"],["1992.16","1345"],["1994.85","0"],["1997.45","0"],["1998.53","270"]]}}
1626916419.239746: {"stream":"bchusd_210924@depth@100ms","data":{"e":"depthUpdate","E":1626916419266,"T":1626916419161,"s":"BCHUSD_210924","ps":"BCHUSD","U":167006184838,"u":167006184842,"pu":167006182533,"b":[["426.42","0"],["428.12","0"]],"a":[["429.70","2618"],["431.03","0"],["432.23","0"]]}}
1626916419.239819: {"stream":"linkusd_perp@depth@100ms","data":{"e":"depthUpdate","E":1626916419269,"T":1626916419260,"s":"LINKUSD_PERP","ps":"LINKUSD","U":167006184861,"u":167006185656,"pu":167006183764,"b":[["14.965","95"],["15.030","306"],["15.057","559"],["15.063","350"]],"a":[["15.069","1299"],["15.070","6043"],["15.072","1203"],["15.074","1397"],["15.076","1249"],["15.132","0"],["15.170","0"]]}}
1626916419.242891: {"stream":"etcusd_perp@depth@100ms","data":{"e":"depthUpdate","E":1626916419271,"T":1626916419246,"s":"ETCUSD_PERP","ps":"ETCUSD","U":167006184875,"u":167006185516,"pu":167006184578,"b":[["42.213","250"],["42.217","22"],["42.221","15"],["42.224","2144"],["42.233","500"],["42.237","977"]],"a":[["42.280","0"],["42.288","22"],["42.365","512"],["42.388","0"]]}}
1626916419.310005: {"stream":"bchusd_perp@depth@100ms","data":{"e":"depthUpdate","E":1626916419338,"T":1626916419293,"s":"BCHUSD_PERP","ps":"BCHUSD","U":167006185420,"u":167006185924,"pu":167006185308,"b":[["424.65","0"],["426.24","0"],["427.77","151"]],"a":[["427.81","100"],["427.86","0"],["427.97","1581"],["428.00","1363"],["428.26","49"],["428.28","1073"],["429.31","0"],["430.76","610"],["430.90","0"]]}}
1626916419.3145401: {"stream":"btcusd_211231@depth@100ms","data":{"e":"depthUpdate","E":1626916419341,"T":1626916419306,"s":"BTCUSD_211231","ps":"BTCUSD","U":167006185456,"u":167006185986,"pu":167006185253,"b":[],"a":[["32626.5","0"],["32630.9","0"],["32631.8","0"],["32632.9","46"],["32633.8","153"],["32633.9","0"],["32639.8","0"]]}}
1626916419.314595: {"stream":"eosusd_perp@depth@100ms","data":{"e":"depthUpdate","E":1626916419343,"T":1626916419247,"s":"EOSUSD_PERP","ps":"EOSUSD","U":167006185475,"u":167006185521,"pu":167006185434,"b":[["3.468","0"]],"a":[["3.470","4534"]]}}
