1704643984.093291: {"channel":"depth","timestamp":1704643983957,"data":{"type":"snapshot","instrument_id":"NEAR-USDT-PERPETUAL","sequence":1702545259448208,"bids":[["3.35100000","110.00000000"],["3.34900000","420.00000000"],["3.34800000","510.00000000"],["3.34700000","1150.00000000"],["3.34600000","200.00000000"],["3.34500000","210.00000000"],["3.34400000","200.00000000"],["3.34300000","190.00000000"],["3.34200000","200.00000000"],["3.34000000","1160.00000000"],["3.33800000","1150.00000000"],["3.33600000","1170.00000000"],["3.30000000","50.00000000"]],"asks":[["3.35800000","370.00000000"],["3.35900000","110.00000000"],["3.36000000","1690.00000000"],["3.36100000","220.00000000"],["3.36300000","200.00000000"],["3.36400000","190.00000000"],["3.36500000","220.00000000"],["3.36700000","790.00000000"],["3.36900000","660.00000000"],["3.37100000","1160.00000000"],["3.90000000","70.00000000"]]},"module":"linear"}
1704643984.716704: {"channel":"depth","timestamp":1704643984627,"data":{"type":"snapshot","instrument_id":"NEAR-USDT-PERPETUAL","sequence":1702545259448226,"bids":[["3.34900000","410.00000000"],["3.34800000","510.00000000"],["3.34700000","1160.00000000"],["3.34600000","200.00000000"],["3.34500000","200.00000000"],["3.34400000","200.00000000"],["3.34300000","190.00000000"],["3.34200000","190.00000000"],["3.34000000","1150.00000000"],["3.33800000","1150.00000000"],["3.33600000","1170.00000000"],["3.30000000","50.00000000"]],"asks":[["3.35800000","370.00000000"],["3.35900000","110.00000000"],["3.36000000","1690.00000000"],["3.36100000","220.00000000"],["3.36200000","200.00000000"],["3.36300000","200.00000000"],["3.36400000","190.00000000"],["3.36500000","220.00000000"],["3.36700000","790.00000000"],["3.36900000","660.00000000"],["3.37100000","1160.00000000"],["3.90000000","70.00000000"]]},"module":"linear"}
1704643984.7422552: {"channel":"depth","timestamp":1704643984649,"data":{"type":"update","instrument_id":"NEAR-USDT-PERPETUAL","sequence":1702545259448227,"prev_sequence":1702545259448226,"changes":[["sell","3.35800000","0.00000000"]]},"module":"linear"}
1704643984.742365: {"channel":"depth","timestamp":1704643984649,"data":{"type":"update","instrument_id":"NEAR-USDT-PERPETUAL","sequence":1702545259448228,"prev_sequence":1702545259448227,"changes":[["sell","3.35700000","370.00000000"]]},"module":"linear"}
1704643984.742414: {"channel":"depth","timestamp":1704643984649,"data":{"type":"update","instrument_id":"NEAR-USDT-PERPETUAL","sequence":1702545259448229,"prev_sequence":1702545259448228,"changes":[["buy","3.34900000","0.00000000"]]},"module":"linear"}
1704643984.742461: {"channel":"depth","timestamp":1704643984650,"data":{"type":"update","instrument_id":"NEAR-USDT-PERPETUAL","sequence":1702545259448230,"prev_sequence":1702545259448229,"changes":[["buy","3.34800000","930.00000000"]]},"module":"linear"}
1704643984.742506: {"channel":"depth","timestamp":1704643984650,"data":{"type":"update","instrument_id":"NEAR-USDT-PERPETUAL","sequence":1702545259448231,"prev_sequence":1702545259448230,"changes":[["sell","3.36000000","510.00000000"]]},"module":"linear"}
1704643984.742528: {"channel":"depth","timestamp":1704643984650,"data":{"type":"update","instrument_id":"NEAR-USDT-PERPETUAL","sequence":1702545259448232,"prev_sequence":1702545259448231,"changes":[["sell","3.35900000","1280.00000000"]]},"module":"linear"}
1704643984.742548: {"channel":"depth","timestamp":1704643984650,"data":{"type":"update","instrument_id":"NEAR-USDT-PERPETUAL","sequence":1702545259448233,"prev_sequence":1702545259448232,"changes":[["buy","3.34700000","0.00000000"]]},"module":"linear"}
1704643984.7425768: {"channel":"depth","timestamp":1704643984650,"data":{"type":"update","instrument_id":"NEAR-USDT-PERPETUAL","sequence":1702545259448234,"prev_sequence":1702545259448233,"changes":[["buy","3.34600000","1350.00000000"]]},"module":"linear"}
1704643984.742603: {"channel":"depth","timestamp":1704643984650,"data":{"type":"update","instrument_id":"NEAR-USDT-PERPETUAL","sequence":1702545259448235,"prev_sequence":1702545259448234,"changes":[["sell","3.36100000","0.00000000"]]},"module":"linear"}
1704643984.742623: {"channel":"depth","timestamp":1704643984650,"data":{"type":"update","instrument_id":"NEAR-USDT-PERPETUAL","sequence":1702545259448236,"prev_sequence":1702545259448235,"changes":[["sell","3.36000000","710.00000000"]]},"module":"linear"}
1704643984.806315: {"channel":"depth","timestamp":1704643984650,"data":{"type":"update","instrument_id":"NEAR-USDT-PERPETUAL","sequence":1702545259448237,"prev_sequence":1702545259448236,"changes":[["buy","3.34600000","1150.00000000"]]},"module":"linear"}
1704643984.806429: {"channel":"depth","timestamp":1704643984650,"data":{"type":"update","instrument_id":"NEAR-USDT-PERPETUAL","sequence":1702545259448238,"prev_sequence":1702545259448237,"changes":[["buy","3.34500000","430.00000000"]]},"module":"linear"}
1704643984.80648: {"channel":"depth","timestamp":1704643984650,"data":{"type":"update","instrument_id":"NEAR-USDT-PERPETUAL","sequence":1702545259448239,"prev_sequence":1702545259448238,"changes":[["sell","3.36200000","0.00000000"]]},"module":"linear"}
1704643984.806505: {"channel":"depth","timestamp":1704643984650,"data":{"type":"update","instrument_id":"NEAR-USDT-PERPETUAL","sequence":1702545259448240,"prev_sequence":1702545259448239,"changes":[["sell","3.36100000","230.00000000"]]},"module":"linear"}
1704643984.806528: {"channel":"depth","timestamp":1704643984650,"data":{"type":"update","instrument_id":"NEAR-USDT-PERPETUAL","sequence":1702545259448241,"prev_sequence":1702545259448240,"changes":[["buy","3.34500000","230.00000000"]]},"module":"linear"}
1704643984.8065479: {"channel":"depth","timestamp":1704643984650,"data":{"type":"update","instrument_id":"NEAR-USDT-PERPETUAL","sequence":1702545259448242,"prev_sequence":1702545259448241,"changes":[["buy","3.34400000","420.00000000"]]},"module":"linear"}
1704643984.8065689: {"channel":"depth","timestamp":1704643984650,"data":{"type":"update","instrument_id":"NEAR-USDT-PERPETUAL","sequence":1702545259448243,"prev_sequence":1702545259448242,"changes":[["sell","3.36300000","0.00000000"]]},"module":"linear"}
1704643984.806605: {"channel":"depth","timestamp":1704643984650,"data":{"type":"update","instrument_id":"NEAR-USDT-PERPETUAL","sequence":1702545259448244,"prev_sequence":1702545259448243,"changes":[["sell","3.36200000","220.00000000"]]},"module":"linear"}
1704643984.806626: {"channel":"depth","timestamp":1704643984650,"data":{"type":"update","instrument_id":"NEAR-USDT-PERPETUAL","sequence":1702545259448245,"prev_sequence":1702545259448244,"changes":[["buy","3.34400000","220.00000000"]]},"module":"linear"}
1704643984.806645: {"channel":"depth","timestamp":1704643984650,"data":{"type":"update","instrument_id":"NEAR-USDT-PERPETUAL","sequence":1702545259448246,"prev_sequence":1702545259448245,"changes":[["buy","3.34300000","400.00000000"]]},"module":"linear"}
1704643984.973821: {"channel":"depth","timestamp":1704643984698,"data":{"type":"update","instrument_id":"NEAR-USDT-PERPETUAL","sequence":1702545259448247,"prev_sequence":1702545259448246,"changes":[["sell","3.36400000","0.00000000"]]},"module":"linear"}
1704643984.973888: {"channel":"depth","timestamp":1704643984698,"data":{"type":"update","instrument_id":"NEAR-USDT-PERPETUAL","sequence":1702545259448248,"prev_sequence":1702545259448247,"changes":[["sell","3.36300000","230.00000000"]]},"module":"linear"}
1704643984.9739509: {"channel":"depth","timestamp":1704643984698,"data":{"type":"update","instrument_id":"NEAR-USDT-PERPETUAL","sequence":1702545259448249,"prev_sequence":1702545259448248,"changes":[["buy","3.34300000","210.00000000"]]},"module":"linear"}
1704643984.9739761: {"channel":"depth","timestamp":1704643984698,"data":{"type":"update","instrument_id":"NEAR-USDT-PERPETUAL","sequence":1702545259448250,"prev_sequence":1702545259448249,"changes":[["buy","3.34200000","390.00000000"]]},"module":"linear"}
1704643984.973996: {"channel":"depth","timestamp":1704643984698,"data":{"type":"update","instrument_id":"NEAR-USDT-PERPETUAL","sequence":1702545259448251,"prev_sequence":1702545259448250,"changes":[["sell","3.36500000","0.00000000"]]},"module":"linear"}
1704643984.974017: {"channel":"depth","timestamp":1704643984698,"data":{"type":"update","instrument_id":"NEAR-USDT-PERPETUAL","sequence":1702545259448252,"prev_sequence":1702545259448251,"changes":[["sell","3.36400000","210.00000000"]]},"module":"linear"}
1704643984.983038: {"channel":"depth","timestamp":1704643984698,"data":{"type":"update","instrument_id":"NEAR-USDT-PERPETUAL","sequence":1702545259448253,"prev_sequence":1702545259448252,"changes":[["buy","3.34200000","200.00000000"]]},"module":"linear"}
1704643984.983114: {"channel":"depth","timestamp":1704643984698,"data":{"type":"update","instrument_id":"NEAR-USDT-PERPETUAL","sequence":1702545259448254,"prev_sequence":1702545259448253,"changes":[["buy","3.34100000","220.00000000"]]},"module":"linear"}
1704643984.983144: {"channel":"depth","timestamp":1704643984698,"data":{"type":"update","instrument_id":"NEAR-USDT-PERPETUAL","sequence":1702545259448255,"prev_sequence":1702545259448254,"changes":[["sell","3.36700000","0.00000000"]]},"module":"linear"}
1704643984.983168: {"channel":"depth","timestamp":1704643984698,"data":{"type":"update","instrument_id":"NEAR-USDT-PERPETUAL","sequence":1702545259448256,"prev_sequence":1702545259448255,"changes":[["sell","3.36600000","880.00000000"]]},"module":"linear"}
1704643984.98319: {"channel":"depth","timestamp":1704643984698,"data":{"type":"update","instrument_id":"NEAR-USDT-PERPETUAL","sequence":1702545259448257,"prev_sequence":1702545259448256,"changes":[["buy","3.34000000","0.00000000"]]},"module":"linear"}
1704643984.9832242: {"channel":"depth","timestamp":1704643984698,"data":{"type":"update","instrument_id":"NEAR-USDT-PERPETUAL","sequence":1702545259448258,"prev_sequence":1702545259448257,"changes":[["buy","3.33900000","1170.00000000"]]},"module":"linear"}
1704643984.9832451: {"channel":"depth","timestamp":1704643984698,"data":{"type":"update","instrument_id":"NEAR-USDT-PERPETUAL","sequence":1702545259448259,"prev_sequence":1702545259448258,"changes":[["sell","3.36900000","0.00000000"]]},"module":"linear"}
1704643984.983265: {"channel":"depth","timestamp":1704643984698,"data":{"type":"update","instrument_id":"NEAR-USDT-PERPETUAL","sequence":1702545259448260,"prev_sequence":1702545259448259,"changes":[["sell","3.36800000","510.00000000"]]},"module":"linear"}
1704643984.983284: {"channel":"depth","timestamp":1704643984698,"data":{"type":"update","instrument_id":"NEAR-USDT-PERPETUAL","sequence":1702545259448261,"prev_sequence":1702545259448260,"changes":[["buy","3.33800000","0.00000000"]]},"module":"linear"}
1704643984.9833028: {"channel":"depth","timestamp":1704643984698,"data":{"type":"update","instrument_id":"NEAR-USDT-PERPETUAL","sequence":1702545259448262,"prev_sequence":1702545259448261,"changes":[["buy","3.33700000","1080.00000000"]]},"module":"linear"}
1704643984.9833221: {"channel":"depth","timestamp":1704643984698,"data":{"type":"update","instrument_id":"NEAR-USDT-PERPETUAL","sequence":1702545259448263,"prev_sequence":1702545259448262,"changes":[["sell","3.37100000","0.00000000"]]},"module":"linear"}
1704643984.9833422: {"channel":"depth","timestamp":1704643984698,"data":{"type":"update","instrument_id":"NEAR-USDT-PERPETUAL","sequence":1702545259448264,"prev_sequence":1702545259448263,"changes":[["sell","3.37000000","1160.00000000"]]},"module":"linear"}
1704643984.983361: {"channel":"depth","timestamp":1704643984698,"data":{"type":"update","instrument_id":"NEAR-USDT-PERPETUAL","sequence":1702545259448265,"prev_sequence":1702545259448264,"changes":[["buy","3.33600000","0.00000000"]]},"module":"linear"}
1704643984.983381: {"channel":"depth","timestamp":1704643984698,"data":{"type":"update","instrument_id":"NEAR-USDT-PERPETUAL","sequence":1702545259448266,"prev_sequence":1702545259448265,"changes":[["buy","3.33500000","1180.00000000"]]},"module":"linear"}
1704643984.9833999: {"channel":"depth","timestamp":1704643984742,"data":{"type":"update","instrument_id":"NEAR-USDT-PERPETUAL","sequence":1702545259448267,"prev_sequence":1702545259448266,"changes":[["buy","3.35000000","110.00000000"]]},"module":"linear"}
1704643985.336027: {"channel":"depth","timestamp":1704643985246,"data":{"type":"update","instrument_id":"NEAR-USDT-PERPETUAL","sequence":1702545259448268,"prev_sequence":1702545259448267,"changes":[["buy","3.35000000","0.00000000"]]},"module":"linear"}
1704643985.3963141: {"channel":"depth","timestamp":1704643985302,"data":{"type":"update","instrument_id":"NEAR-USDT-PERPETUAL","sequence":1702545259448269,"prev_sequence":1702545259448268,"changes":[["sell","3.35700000","0.00000000"]]},"module":"linear"}
1704643985.396373: {"channel":"depth","timestamp":1704643985302,"data":{"type":"update","instrument_id":"NEAR-USDT-PERPETUAL","sequence":1702545259448270,"prev_sequence":1702545259448269,"changes":[["sell","3.35600000","360.00000000"]]},"module":"linear"}
1704643985.396399: {"channel":"depth","timestamp":1704643985302,"data":{"type":"update","instrument_id":"NEAR-USDT-PERPETUAL","sequence":1702545259448271,"prev_sequence":1702545259448270,"changes":[["buy","3.34800000","510.00000000"]]},"module":"linear"}
1704643985.396419: {"channel":"depth","timestamp":1704643985302,"data":{"type":"update","instrument_id":"NEAR-USDT-PERPETUAL","sequence":1702545259448272,"prev_sequence":1702545259448271,"changes":[["buy","3.34700000","390.00000000"]]},"module":"linear"}
1704643985.396436: {"channel":"depth","timestamp":1704643985302,"data":{"type":"update","instrument_id":"NEAR-USDT-PERPETUAL","sequence":1702545259448273,"prev_sequence":1702545259448272,"changes":[["sell","3.35900000","110.00000000"]]},"module":"linear"}
1704643985.3964522: {"channel":"depth","timestamp":1704643985302,"data":{"type":"update","instrument_id":"NEAR-USDT-PERPETUAL","sequence":1702545259448274,"prev_sequence":1702545259448273,"changes":[["sell","3.35800000","1150.00000000"]]},"module":"linear"}
1704643985.3971221: {"channel":"depth","timestamp":1704643985302,"data":{"type":"update","instrument_id":"NEAR-USDT-PERPETUAL","sequence":1702545259448275,"prev_sequence":1702545259448274,"changes":[["buy","3.34600000","0.00000000"]]},"module":"linear"}
1704643985.397155: {"channel":"depth","timestamp":1704643985302,"data":{"type":"update","instrument_id":"NEAR-USDT-PERPETUAL","sequence":1702545259448276,"prev_sequence":1702545259448275,"changes":[["buy","3.34500000","1420.00000000"]]},"module":"linear"}
1704643985.397173: {"channel":"depth","timestamp":1704643985302,"data":{"type":"update","instrument_id":"NEAR-USDT-PERPETUAL","sequence":1702545259448277,"prev_sequence":1702545259448276,"changes":[["sell","3.36000000","510.00000000"]]},"module":"linear"}
1704643985.3971891: {"channel":"depth","timestamp":1704643985302,"data":{"type":"update","instrument_id":"NEAR-USDT-PERPETUAL","sequence":1702545259448278,"prev_sequence":1702545259448277,"changes":[["sell","3.35900000","310.00000000"]]},"module":"linear"}
1704643985.3972049: {"channel":"depth","timestamp":1704643985302,"data":{"type":"update","instrument_id":"NEAR-USDT-PERPETUAL","sequence":1702545259448279,"prev_sequence":1702545259448278,"changes":[["buy","3.34500000","1190.00000000"]]},"module":"linear"}
1704643985.3972201: {"channel":"depth","timestamp":1704643985302,"data":{"type":"update","instrument_id":"NEAR-USDT-PERPETUAL","sequence":1702545259448280,"prev_sequence":1702545259448279,"changes":[["buy","3.34400000","410.00000000"]]},"module":"linear"}
1704643985.397235: {"channel":"depth","timestamp":1704643985302,"data":{"type":"update","instrument_id":"NEAR-USDT-PERPETUAL","sequence":1702545259448281,"prev_sequence":1702545259448280,"changes":[["sell","3.36100000","0.00000000"]]},"module":"linear"}
1704643985.39725: {"channel":"depth","timestamp":1704643985302,"data":{"type":"update","instrument_id":"NEAR-USDT-PERPETUAL","sequence":1702545259448282,"prev_sequence":1702545259448281,"changes":[["sell","3.36000000","700.00000000"]]},"module":"linear"}
1704643985.3972638: {"channel":"depth","timestamp":1704643985302,"data":{"type":"update","instrument_id":"NEAR-USDT-PERPETUAL","sequence":1702545259448283,"prev_sequence":1702545259448282,"changes":[["buy","3.34400000","190.00000000"]]},"module":"linear"}
1704643985.397279: {"channel":"depth","timestamp":1704643985302,"data":{"type":"update","instrument_id":"NEAR-USDT-PERPETUAL","sequence":1702545259448284,"prev_sequence":1702545259448283,"changes":[["buy","3.34300000","430.00000000"]]},"module":"linear"}
1704643985.397293: {"channel":"depth","timestamp":1704643985302,"data":{"type":"update","instrument_id":"NEAR-USDT-PERPETUAL","sequence":1702545259448285,"prev_sequence":1702545259448284,"changes":[["sell","3.36200000","0.00000000"]]},"module":"linear"}
1704643985.397307: {"channel":"depth","timestamp":1704643985302,"data":{"type":"update","instrument_id":"NEAR-USDT-PERPETUAL","sequence":1702545259448286,"prev_sequence":1702545259448285,"changes":[["sell","3.36100000","190.00000000"]]},"module":"linear"}
1704643985.397322: {"channel":"depth","timestamp":1704643985302,"data":{"type":"update","instrument_id":"NEAR-USDT-PERPETUAL","sequence":1702545259448287,"prev_sequence":1702545259448286,"changes":[["buy","3.34300000","220.00000000"]]},"module":"linear"}
1704643985.3973382: {"channel":"depth","timestamp":1704643985302,"data":{"type":"update","instrument_id":"NEAR-USDT-PERPETUAL","sequence":1702545259448288,"prev_sequence":1702545259448287,"changes":[["buy","3.34200000","420.00000000"]]},"module":"linear"}
1704643985.4820008: {"channel":"depth","timestamp":1704643985394,"data":{"type":"update","instrument_id":"NEAR-USDT-PERPETUAL","sequence":1702545259448289,"prev_sequence":1702545259448288,"changes":[["buy","3.34900000","110.00000000"]]},"module":"linear"}
1704643985.5131001: {"channel":"depth","timestamp":1704643985423,"data":{"type":"update","instrument_id":"NEAR-USDT-PERPETUAL","sequence":1702545259448290,"prev_sequence":1702545259448289,"changes":[["sell","3.35900000","200.00000000"]]},"module":"linear"}
1704643985.788002: {"channel":"depth","timestamp":1704643985699,"data":{"type":"update","instrument_id":"NEAR-USDT-PERPETUAL","sequence":1702545259448291,"prev_sequence":1702545259448290,"changes":[["sell","3.35500000","110.00000000"]]},"module":"linear"}
1704643986.552547: {"channel":"depth","timestamp":1704643986369,"data":{"type":"update","instrument_id":"NEAR-USDT-PERPETUAL","sequence":1702545259448292,"prev_sequence":1702545259448291,"changes":[["sell","3.35600000","0.00000000"]]},"module":"linear"}
1704643986.55265: {"channel":"depth","timestamp":1704643986369,"data":{"type":"update","instrument_id":"NEAR-USDT-PERPETUAL","sequence":1702545259448293,"prev_sequence":1702545259448292,"changes":[["sell","3.35600000","360.00000000"]]},"module":"linear"}
1704643986.5526972: {"channel":"depth","timestamp":1704643986369,"data":{"type":"update","instrument_id":"NEAR-USDT-PERPETUAL","sequence":1702545259448294,"prev_sequence":1702545259448293,"changes":[["buy","3.34700000","0.00000000"]]},"module":"linear"}
1704643986.552737: {"channel":"depth","timestamp":1704643986369,"data":{"type":"update","instrument_id":"NEAR-USDT-PERPETUAL","sequence":1702545259448295,"prev_sequence":1702545259448294,"changes":[["buy","3.34700000","400.00000000"]]},"module":"linear"}
1704643986.552771: {"channel":"depth","timestamp":1704643986369,"data":{"type":"update","instrument_id":"NEAR-USDT-PERPETUAL","sequence":1702545259448296,"prev_sequence":1702545259448295,"changes":[["sell","3.36100000","0.00000000"]]},"module":"linear"}
1704643986.552802: {"channel":"depth","timestamp":1704643986369,"data":{"type":"update","instrument_id":"NEAR-USDT-PERPETUAL","sequence":1702545259448297,"prev_sequence":1702545259448296,"changes":[["sell","3.36100000","190.00000000"]]},"module":"linear"}
1704643986.552833: {"channel":"depth","timestamp":1704643986370,"data":{"type":"update","instrument_id":"NEAR-USDT-PERPETUAL","sequence":1702545259448298,"prev_sequence":1702545259448297,"changes":[["buy","3.34500000","0.00000000"]]},"module":"linear"}
1704643986.552887: {"channel":"depth","timestamp":1704643986370,"data":{"type":"update","instrument_id":"NEAR-USDT-PERPETUAL","sequence":1702545259448299,"prev_sequence":1702545259448298,"changes":[["buy","3.34500000","1150.00000000"]]},"module":"linear"}
1704643986.552918: {"channel":"depth","timestamp":1704643986370,"data":{"type":"update","instrument_id":"NEAR-USDT-PERPETUAL","sequence":1702545259448300,"prev_sequence":1702545259448299,"changes":[["sell","3.36600000","0.00000000"]]},"module":"linear"}
1704643986.5534642: {"channel":"depth","timestamp":1704643986370,"data":{"type":"update","instrument_id":"NEAR-USDT-PERPETUAL","sequence":1702545259448301,"prev_sequence":1702545259448300,"changes":[["sell","3.36500000","1150.00000000"]]},"module":"linear"}
1704643986.553505: {"channel":"depth","timestamp":1704643986370,"data":{"type":"update","instrument_id":"NEAR-USDT-PERPETUAL","sequence":1702545259448302,"prev_sequence":1702545259448301,"changes":[["buy","3.34200000","200.00000000"]]},"module":"linear"}
1704643986.553532: {"channel":"depth","timestamp":1704643986370,"data":{"type":"update","instrument_id":"NEAR-USDT-PERPETUAL","sequence":1702545259448303,"prev_sequence":1702545259448302,"changes":[["buy","3.34200000","410.00000000"]]},"module":"linear"}
1704643986.553552: {"channel":"depth","timestamp":1704643986370,"data":{"type":"update","instrument_id":"NEAR-USDT-PERPETUAL","sequence":1702545259448304,"prev_sequence":1702545259448303,"changes":[["buy","3.34200000","210.00000000"]]},"module":"linear"}
1704643986.5535722: {"channel":"depth","timestamp":1704643986370,"data":{"type":"update","instrument_id":"NEAR-USDT-PERPETUAL","sequence":1702545259448305,"prev_sequence":1702545259448304,"changes":[["buy","3.34100000","440.00000000"]]},"module":"linear"}
1704643986.553591: {"channel":"depth","timestamp":1704643986370,"data":{"type":"update","instrument_id":"NEAR-USDT-PERPETUAL","sequence":1702545259448306,"prev_sequence":1702545259448305,"changes":[["buy","3.34100000","220.00000000"]]},"module":"linear"}
1704643986.553611: {"channel":"depth","timestamp":1704643986370,"data":{"type":"update","instrument_id":"NEAR-USDT-PERPETUAL","sequence":1702545259448307,"prev_sequence":1702545259448306,"changes":[["buy","3.34000000","220.00000000"]]},"module":"linear"}
1704643986.553633: {"channel":"depth","timestamp":1704643986370,"data":{"type":"update","instrument_id":"NEAR-USDT-PERPETUAL","sequence":1702545259448308,"prev_sequence":1702545259448307,"changes":[["buy","3.33700000","0.00000000"]]},"module":"linear"}
1704643986.553653: {"channel":"depth","timestamp":1704643986370,"data":{"type":"update","instrument_id":"NEAR-USDT-PERPETUAL","sequence":1702545259448309,"prev_sequence":1702545259448308,"changes":[["buy","3.33600000","1160.00000000"]]},"module":"linear"}
1704643986.5536718: {"channel":"depth","timestamp":1704643986370,"data":{"type":"update","instrument_id":"NEAR-USDT-PERPETUAL","sequence":1702545259448310,"prev_sequence":1702545259448309,"changes":[["buy","3.33500000","0.00000000"]]},"module":"linear"}
1704643986.553691: {"channel":"depth","timestamp":1704643986370,"data":{"type":"update","instrument_id":"NEAR-USDT-PERPETUAL","sequence":1702545259448311,"prev_sequence":1702545259448310,"changes":[["buy","3.33400000","1160.00000000"]]},"module":"linear"}
1704643987.0811038: {"channel":"depth","timestamp":1704643986992,"data":{"type":"update","instrument_id":"NEAR-USDT-PERPETUAL","sequence":1702545259448312,"prev_sequence":1702545259448311,"changes":[["sell","3.36000000","190.00000000"]]},"module":"linear"}
1704643987.130713: {"channel":"depth","timestamp":1704643987041,"data":{"type":"update","instrument_id":"NEAR-USDT-PERPETUAL","sequence":1702545259448313,"prev_sequence":1702545259448312,"changes":[["sell","3.35600000","0.00000000"]]},"module":"linear"}
1704643987.1307871: {"channel":"depth","timestamp":1704643987041,"data":{"type":"update","instrument_id":"NEAR-USDT-PERPETUAL","sequence":1702545259448314,"prev_sequence":1702545259448313,"changes":[["sell","3.35500000","500.00000000"]]},"module":"linear"}
1704643987.130819: {"channel":"depth","timestamp":1704643987041,"data":{"type":"update","instrument_id":"NEAR-USDT-PERPETUAL","sequence":1702545259448315,"prev_sequence":1702545259448314,"changes":[["buy","3.34700000","0.00000000"]]},"module":"linear"}
1704643987.1308749: {"channel":"depth","timestamp":1704643987041,"data":{"type":"update","instrument_id":"NEAR-USDT-PERPETUAL","sequence":1702545259448316,"prev_sequence":1702545259448315,"changes":[["buy","3.34600000","410.00000000"]]},"module":"linear"}
1704643987.130898: {"channel":"depth","timestamp":1704643987041,"data":{"type":"update","instrument_id":"NEAR-USDT-PERPETUAL","sequence":1702545259448317,"prev_sequence":1702545259448316,"changes":[["sell","3.35800000","0.00000000"]]},"module":"linear"}
1704643987.130919: {"channel":"depth","timestamp":1704643987041,"data":{"type":"update","instrument_id":"NEAR-USDT-PERPETUAL","sequence":1702545259448318,"prev_sequence":1702545259448317,"changes":[["sell","3.35700000","1170.00000000"]]},"module":"linear"}
1704643987.13094: {"channel":"depth","timestamp":1704643987041,"data":{"type":"update","instrument_id":"NEAR-USDT-PERPETUAL","sequence":1702545259448319,"prev_sequence":1702545259448318,"changes":[["buy","3.34500000","0.00000000"]]},"module":"linear"}
1704643987.130961: {"channel":"depth","timestamp":1704643987041,"data":{"type":"update","instrument_id":"NEAR-USDT-PERPETUAL","sequence":1702545259448320,"prev_sequence":1702545259448319,"changes":[["buy","3.34400000","1340.00000000"]]},"module":"linear"}
1704643987.1309812: {"channel":"depth","timestamp":1704643987041,"data":{"type":"update","instrument_id":"NEAR-USDT-PERPETUAL","sequence":1702545259448321,"prev_sequence":1702545259448320,"changes":[["sell","3.35900000","0.00000000"]]},"module":"linear"}
1704643987.131009: {"channel":"depth","timestamp":1704643987041,"data":{"type":"update","instrument_id":"NEAR-USDT-PERPETUAL","sequence":1702545259448322,"prev_sequence":1702545259448321,"changes":[["sell","3.35800000","220.00000000"]]},"module":"linear"}
1704643987.131029: {"channel":"depth","timestamp":1704643987041,"data":{"type":"update","instrument_id":"NEAR-USDT-PERPETUAL","sequence":1702545259448323,"prev_sequence":1702545259448322,"changes":[["buy","3.34400000","1150.00000000"]]},"module":"linear"}
1704643987.131049: {"channel":"depth","timestamp":1704643987041,"data":{"type":"update","instrument_id":"NEAR-USDT-PERPETUAL","sequence":1702545259448324,"prev_sequence":1702545259448323,"changes":[["buy","3.34300000","450.00000000"]]},"module":"linear"}
1704643987.131069: {"channel":"depth","timestamp":1704643987041,"data":{"type":"update","instrument_id":"NEAR-USDT-PERPETUAL","sequence":1702545259448325,"prev_sequence":1702545259448324,"changes":[["sell","3.36000000","0.00000000"]]},"module":"linear"}
1704643987.131089: {"channel":"depth","timestamp":1704643987041,"data":{"type":"update","instrument_id":"NEAR-USDT-PERPETUAL","sequence":1702545259448326,"prev_sequence":1702545259448325,"changes":[["sell","3.35900000","220.00000000"]]},"module":"linear"}
1704643987.131108: {"channel":"depth","timestamp":1704643987041,"data":{"type":"update","instrument_id":"NEAR-USDT-PERPETUAL","sequence":1702545259448327,"prev_sequence":1702545259448326,"changes":[["buy","3.34300000","230.00000000"]]},"module":"linear"}
1704643987.131129: {"channel":"depth","timestamp":1704643987041,"data":{"type":"update","instrument_id":"NEAR-USDT-PERPETUAL","sequence":1702545259448328,"prev_sequence":1702545259448327,"changes":[["buy","3.34200000","440.00000000"]]},"module":"linear"}
1704643987.131149: {"channel":"depth","timestamp":1704643987041,"data":{"type":"update","instrument_id":"NEAR-USDT-PERPETUAL","sequence":1702545259448329,"prev_sequence":1702545259448328,"changes":[["sell","3.36100000","0.00000000"]]},"module":"linear"}
1704643987.131167: {"channel":"depth","timestamp":1704643987041,"data":{"type":"update","instrument_id":"NEAR-USDT-PERPETUAL","sequence":1702545259448330,"prev_sequence":1702545259448329,"changes":[["sell","3.36000000","200.00000000"]]},"module":"linear"}
1704643987.131187: {"channel":"depth","timestamp":1704643987041,"data":{"type":"update","instrument_id":"NEAR-USDT-PERPETUAL","sequence":1702545259448331,"prev_sequence":1702545259448330,"changes":[["buy","3.34200000","230.00000000"]]},"module":"linear"}
1704643987.131205: {"channel":"depth","timestamp":1704643987041,"data":{"type":"update","instrument_id":"NEAR-USDT-PERPETUAL","sequence":1702545259448332,"prev_sequence":1702545259448331,"changes":[["buy","3.34100000","410.00000000"]]},"module":"linear"}
1704643987.1312242: {"channel":"depth","timestamp":1704643987041,"data":{"type":"update","instrument_id":"NEAR-USDT-PERPETUAL","sequence":1702545259448333,"prev_sequence":1702545259448332,"changes":[["buy","3.34800000","0.00000000"]]},"module":"linear"}
1704643987.179179: {"channel":"depth","timestamp":1704643987088,"data":{"type":"update","instrument_id":"NEAR-USDT-PERPETUAL","sequence":1702545259448334,"prev_sequence":1702545259448333,"changes":[["sell","3.36300000","0.00000000"]]},"module":"linear"}
1704643987.179256: {"channel":"depth","timestamp":1704643987088,"data":{"type":"update","instrument_id":"NEAR-USDT-PERPETUAL","sequence":1702545259448335,"prev_sequence":1702545259448334,"changes":[["sell","3.36100000","230.00000000"]]},"module":"linear"}
1704643987.1792881: {"channel":"depth","timestamp":1704643987088,"data":{"type":"update","instrument_id":"NEAR-USDT-PERPETUAL","sequence":1702545259448336,"prev_sequence":1702545259448335,"changes":[["buy","3.34100000","190.00000000"]]},"module":"linear"}
1704643987.179313: {"channel":"depth","timestamp":1704643987088,"data":{"type":"update","instrument_id":"NEAR-USDT-PERPETUAL","sequence":1702545259448337,"prev_sequence":1702545259448336,"changes":[["buy","3.34000000","450.00000000"]]},"module":"linear"}
1704643987.1793349: {"channel":"depth","timestamp":1704643987088,"data":{"type":"update","instrument_id":"NEAR-USDT-PERPETUAL","sequence":1702545259448338,"prev_sequence":1702545259448337,"changes":[["sell","3.36400000","0.00000000"]]},"module":"linear"}
1704643987.1793642: {"channel":"depth","timestamp":1704643987088,"data":{"type":"update","instrument_id":"NEAR-USDT-PERPETUAL","sequence":1702545259448339,"prev_sequence":1702545259448338,"changes":[["sell","3.36200000","230.00000000"]]},"module":"linear"}
1704643987.1793861: {"channel":"depth","timestamp":1704643987088,"data":{"type":"update","instrument_id":"NEAR-USDT-PERPETUAL","sequence":1702545259448340,"prev_sequence":1702545259448339,"changes":[["buy","3.34000000","230.00000000"]]},"module":"linear"}
1704643987.179405: {"channel":"depth","timestamp":1704643987088,"data":{"type":"update","instrument_id":"NEAR-USDT-PERPETUAL","sequence":1702545259448341,"prev_sequence":1702545259448340,"changes":[["buy","3.33900000","1400.00000000"]]},"module":"linear"}
1704643987.179425: {"channel":"depth","timestamp":1704643987088,"data":{"type":"update","instrument_id":"NEAR-USDT-PERPETUAL","sequence":1702545259448342,"prev_sequence":1702545259448341,"changes":[["sell","3.36500000","0.00000000"]]},"module":"linear"}
1704643987.179445: {"channel":"depth","timestamp":1704643987088,"data":{"type":"update","instrument_id":"NEAR-USDT-PERPETUAL","sequence":1702545259448343,"prev_sequence":1702545259448342,"changes":[["sell","3.36400000","650.00000000"]]},"module":"linear"}
1704643987.1794639: {"channel":"depth","timestamp":1704643987088,"data":{"type":"update","instrument_id":"NEAR-USDT-PERPETUAL","sequence":1702545259448344,"prev_sequence":1702545259448343,"changes":[["buy","3.33900000","230.00000000"]]},"module":"linear"}
1704643987.179483: {"channel":"depth","timestamp":1704643987088,"data":{"type":"update","instrument_id":"NEAR-USDT-PERPETUAL","sequence":1702545259448345,"prev_sequence":1702545259448344,"changes":[["buy","3.33700000","1190.00000000"]]},"module":"linear"}
1704643987.1795032: {"channel":"depth","timestamp":1704643987088,"data":{"type":"update","instrument_id":"NEAR-USDT-PERPETUAL","sequence":1702545259448346,"prev_sequence":1702545259448345,"changes":[["sell","3.36800000","0.00000000"]]},"module":"linear"}
1704643987.179529: {"channel":"depth","timestamp":1704643987088,"data":{"type":"update","instrument_id":"NEAR-USDT-PERPETUAL","sequence":1702545259448347,"prev_sequence":1702545259448346,"changes":[["sell","3.36600000","1160.00000000"]]},"module":"linear"}
1704643987.179549: {"channel":"depth","timestamp":1704643987088,"data":{"type":"update","instrument_id":"NEAR-USDT-PERPETUAL","sequence":1702545259448348,"prev_sequence":1702545259448347,"changes":[["buy","3.33600000","0.00000000"]]},"module":"linear"}
1704643987.179568: {"channel":"depth","timestamp":1704643987088,"data":{"type":"update","instrument_id":"NEAR-USDT-PERPETUAL","sequence":1702545259448349,"prev_sequence":1702545259448348,"changes":[["buy","3.33500000","1150.00000000"]]},"module":"linear"}
1704643987.1796029: {"channel":"depth","timestamp":1704643987088,"data":{"type":"update","instrument_id":"NEAR-USDT-PERPETUAL","sequence":1702545259448350,"prev_sequence":1702545259448349,"changes":[["sell","3.37000000","0.00000000"]]},"module":"linear"}
1704643987.179623: {"channel":"depth","timestamp":1704643987089,"data":{"type":"update","instrument_id":"NEAR-USDT-PERPETUAL","sequence":1702545259448351,"prev_sequence":1702545259448350,"changes":[["sell","3.36800000","660.00000000"]]},"module":"linear"}
1704643987.1796422: {"channel":"depth","timestamp":1704643987089,"data":{"type":"update","instrument_id":"NEAR-USDT-PERPETUAL","sequence":1702545259448352,"prev_sequence":1702545259448351,"changes":[["buy","3.33400000","0.00000000"]]},"module":"linear"}
1704643987.179661: {"channel":"depth","timestamp":1704643987089,"data":{"type":"update","instrument_id":"NEAR-USDT-PERPETUAL","sequence":1702545259448353,"prev_sequence":1702545259448352,"changes":[["buy","3.33300000","1150.00000000"]]},"module":"linear"}
1704643987.219092: {"channel":"depth","timestamp":1704643987130,"data":{"type":"update","instrument_id":"NEAR-USDT-PERPETUAL","sequence":1702545259448354,"prev_sequence":1702545259448353,"changes":[["buy","3.34900000","0.00000000"]]},"module":"linear"}
1704643987.2192: {"channel":"depth","timestamp":1704643987130,"data":{"type":"update","instrument_id":"NEAR-USDT-PERPETUAL","sequence":1702545259448355,"prev_sequence":1702545259448354,"changes":[["sell","3.35600000","510.00000000"]]},"module":"linear"}
1704643987.269873: {"channel":"depth","timestamp":1704643987174,"data":{"type":"update","instrument_id":"NEAR-USDT-PERPETUAL","sequence":1702545259448356,"prev_sequence":1702545259448355,"changes":[["buy","3.34600000","920.00000000"]]},"module":"linear"}
1704643987.341155: {"channel":"depth","timestamp":1704643987253,"data":{"type":"update","instrument_id":"NEAR-USDT-PERPETUAL","sequence":1702545259448357,"prev_sequence":1702545259448356,"changes":[["buy","3.34700000","110.00000000"]]},"module":"linear"}
1704643987.831427: {"channel":"depth","timestamp":1704643987743,"data":{"type":"update","instrument_id":"NEAR-USDT-PERPETUAL","sequence":1702545259448358,"prev_sequence":1702545259448357,"changes":[["sell","3.35500000","110.00000000"]]},"module":"linear"}
1704643987.831538: {"channel":"depth","timestamp":1704643987743,"data":{"type":"update","instrument_id":"NEAR-USDT-PERPETUAL","sequence":1702545259448359,"prev_sequence":1702545259448358,"changes":[["sell","3.35600000","900.00000000"]]},"module":"linear"}
1704643987.8334248: {"channel":"depth","timestamp":1704643987743,"data":{"type":"update","instrument_id":"NEAR-USDT-PERPETUAL","sequence":1702545259448360,"prev_sequence":1702545259448359,"changes":[["buy","3.34600000","510.00000000"]]},"module":"linear"}
1704643987.833498: {"channel":"depth","timestamp":1704643987743,"data":{"type":"update","instrument_id":"NEAR-USDT-PERPETUAL","sequence":1702545259448361,"prev_sequence":1702545259448360,"changes":[["buy","3.34700000","500.00000000"]]},"module":"linear"}
1704643987.833529: {"channel":"depth","timestamp":1704643987743,"data":{"type":"update","instrument_id":"NEAR-USDT-PERPETUAL","sequence":1702545259448362,"prev_sequence":1702545259448361,"changes":[["sell","3.35700000","0.00000000"]]},"module":"linear"}
1704643987.833567: {"channel":"depth","timestamp":1704643987743,"data":{"type":"update","instrument_id":"NEAR-USDT-PERPETUAL","sequence":1702545259448363,"prev_sequence":1702545259448362,"changes":[["sell","3.35800000","1410.00000000"]]},"module":"linear"}
1704643987.8335922: {"channel":"depth","timestamp":1704643987743,"data":{"type":"update","instrument_id":"NEAR-USDT-PERPETUAL","sequence":1702545259448364,"prev_sequence":1702545259448363,"changes":[["buy","3.34400000","0.00000000"]]},"module":"linear"}
1704643987.833614: {"channel":"depth","timestamp":1704643987743,"data":{"type":"update","instrument_id":"NEAR-USDT-PERPETUAL","sequence":1702545259448365,"prev_sequence":1702545259448364,"changes":[["buy","3.34500000","1190.00000000"]]},"module":"linear"}
1704643987.8336341: {"channel":"depth","timestamp":1704643987743,"data":{"type":"update","instrument_id":"NEAR-USDT-PERPETUAL","sequence":1702545259448366,"prev_sequence":1702545259448365,"changes":[["sell","3.35800000","1190.00000000"]]},"module":"linear"}
1704643987.833654: {"channel":"depth","timestamp":1704643987743,"data":{"type":"update","instrument_id":"NEAR-USDT-PERPETUAL","sequence":1702545259448367,"prev_sequence":1702545259448366,"changes":[["sell","3.35900000","420.00000000"]]},"module":"linear"}
1704643987.833674: {"channel":"depth","timestamp":1704643987743,"data":{"type":"update","instrument_id":"NEAR-USDT-PERPETUAL","sequence":1702545259448368,"prev_sequence":1702545259448367,"changes":[["buy","3.34300000","0.00000000"]]},"module":"linear"}
1704643987.833694: {"channel":"depth","timestamp":1704643987743,"data":{"type":"update","instrument_id":"NEAR-USDT-PERPETUAL","sequence":1702545259448369,"prev_sequence":1702545259448368,"changes":[["buy","3.34400000","210.00000000"]]},"module":"linear"}
1704643987.833729: {"channel":"depth","timestamp":1704643987743,"data":{"type":"update","instrument_id":"NEAR-USDT-PERPETUAL","sequence":1702545259448370,"prev_sequence":1702545259448369,"changes":[["sell","3.35900000","200.00000000"]]},"module":"linear"}
1704643987.833749: {"channel":"depth","timestamp":1704643987743,"data":{"type":"update","instrument_id":"NEAR-USDT-PERPETUAL","sequence":1702545259448371,"prev_sequence":1702545259448370,"changes":[["sell","3.36000000","400.00000000"]]},"module":"linear"}
1704643987.8337688: {"channel":"depth","timestamp":1704643987743,"data":{"type":"update","instrument_id":"NEAR-USDT-PERPETUAL","sequence":1702545259448372,"prev_sequence":1702545259448371,"changes":[["buy","3.34200000","0.00000000"]]},"module":"linear"}
1704643987.8337889: {"channel":"depth","timestamp":1704643987743,"data":{"type":"update","instrument_id":"NEAR-USDT-PERPETUAL","sequence":1702545259448373,"prev_sequence":1702545259448372,"changes":[["buy","3.34300000","230.00000000"]]},"module":"linear"}
1704643987.833808: {"channel":"depth","timestamp":1704643987743,"data":{"type":"update","instrument_id":"NEAR-USDT-PERPETUAL","sequence":1702545259448374,"prev_sequence":1702545259448373,"changes":[["sell","3.36000000","200.00000000"]]},"module":"linear"}
1704643987.8338282: {"channel":"depth","timestamp":1704643987743,"data":{"type":"update","instrument_id":"NEAR-USDT-PERPETUAL","sequence":1702545259448375,"prev_sequence":1702545259448374,"changes":[["sell","3.36100000","440.00000000"]]},"module":"linear"}
1704643987.8338492: {"channel":"depth","timestamp":1704643987743,"data":{"type":"update","instrument_id":"NEAR-USDT-PERPETUAL","sequence":1702545259448376,"prev_sequence":1702545259448375,"changes":[["buy","3.34100000","0.00000000"]]},"module":"linear"}
1704643987.833868: {"channel":"depth","timestamp":1704643987743,"data":{"type":"update","instrument_id":"NEAR-USDT-PERPETUAL","sequence":1702545259448377,"prev_sequence":1702545259448376,"changes":[["buy","3.34200000","230.00000000"]]},"module":"linear"}
1704643988.940026: {"channel":"depth","timestamp":1704643988852,"data":{"type":"update","instrument_id":"NEAR-USDT-PERPETUAL","sequence":1702545259448378,"prev_sequence":1702545259448377,"changes":[["sell","3.35800000","0.00000000"]]},"module":"linear"}
1704643988.9401019: {"channel":"depth","timestamp":1704643988852,"data":{"type":"update","instrument_id":"NEAR-USDT-PERPETUAL","sequence":1702545259448379,"prev_sequence":1702545259448378,"changes":[["sell","3.35800000","1170.00000000"]]},"module":"linear"}
1704643988.9438589: {"channel":"depth","timestamp":1704643988852,"data":{"type":"update","instrument_id":"NEAR-USDT-PERPETUAL","sequence":1702545259448380,"prev_sequence":1702545259448379,"changes":[["buy","3.34700000","110.00000000"]]},"module":"linear"}
1704643988.943955: {"channel":"depth","timestamp":1704643988852,"data":{"type":"update","instrument_id":"NEAR-USDT-PERPETUAL","sequence":1702545259448381,"prev_sequence":1702545259448380,"changes":[["buy","3.34700000","510.00000000"]]},"module":"linear"}
1704643988.943988: {"channel":"depth","timestamp":1704643988852,"data":{"type":"update","instrument_id":"NEAR-USDT-PERPETUAL","sequence":1702545259448382,"prev_sequence":1702545259448381,"changes":[["sell","3.36100000","210.00000000"]]},"module":"linear"}
1704643988.944013: {"channel":"depth","timestamp":1704643988852,"data":{"type":"update","instrument_id":"NEAR-USDT-PERPETUAL","sequence":1702545259448383,"prev_sequence":1702545259448382,"changes":[["sell","3.36200000","420.00000000"]]},"module":"linear"}
1704643988.944035: {"channel":"depth","timestamp":1704643988852,"data":{"type":"update","instrument_id":"NEAR-USDT-PERPETUAL","sequence":1702545259448384,"prev_sequence":1702545259448383,"changes":[["buy","3.34500000","0.00000000"]]},"module":"linear"}
1704643988.944056: {"channel":"depth","timestamp":1704643988852,"data":{"type":"update","instrument_id":"NEAR-USDT-PERPETUAL","sequence":1702545259448385,"prev_sequence":1702545259448384,"changes":[["buy","3.34500000","1160.00000000"]]},"module":"linear"}
1704643988.944077: {"channel":"depth","timestamp":1704643988852,"data":{"type":"update","instrument_id":"NEAR-USDT-PERPETUAL","sequence":1702545259448386,"prev_sequence":1702545259448385,"changes":[["sell","3.36400000","0.00000000"]]},"module":"linear"}
1704643988.944097: {"channel":"depth","timestamp":1704643988852,"data":{"type":"update","instrument_id":"NEAR-USDT-PERPETUAL","sequence":1702545259448387,"prev_sequence":1702545259448386,"changes":[["sell","3.36500000","1190.00000000"]]},"module":"linear"}
1704643988.944117: {"channel":"depth","timestamp":1704643988852,"data":{"type":"update","instrument_id":"NEAR-USDT-PERPETUAL","sequence":1702545259448388,"prev_sequence":1702545259448387,"changes":[["buy","3.34400000","0.00000000"]]},"module":"linear"}
1704643988.944136: {"channel":"depth","timestamp":1704643988852,"data":{"type":"update","instrument_id":"NEAR-USDT-PERPETUAL","sequence":1702545259448389,"prev_sequence":1702545259448388,"changes":[["buy","3.34400000","210.00000000"]]},"module":"linear"}
1704643988.944155: {"channel":"depth","timestamp":1704643988852,"data":{"type":"update","instrument_id":"NEAR-USDT-PERPETUAL","sequence":1702545259448390,"prev_sequence":1702545259448389,"changes":[["sell","3.36600000","0.00000000"]]},"module":"linear"}
1704643988.944174: {"channel":"depth","timestamp":1704643988852,"data":{"type":"update","instrument_id":"NEAR-USDT-PERPETUAL","sequence":1702545259448391,"prev_sequence":1702545259448390,"changes":[["sell","3.36700000","1150.00000000"]]},"module":"linear"}
1704643988.9441931: {"channel":"depth","timestamp":1704643988852,"data":{"type":"update","instrument_id":"NEAR-USDT-PERPETUAL","sequence":1702545259448392,"prev_sequence":1702545259448391,"changes":[["buy","3.34300000","0.00000000"]]},"module":"linear"}
1704643988.944212: {"channel":"depth","timestamp":1704643988852,"data":{"type":"update","instrument_id":"NEAR-USDT-PERPETUAL","sequence":1702545259448393,"prev_sequence":1702545259448392,"changes":[["buy","3.34300000","230.00000000"]]},"module":"linear"}
1704643988.944232: {"channel":"depth","timestamp":1704643988852,"data":{"type":"update","instrument_id":"NEAR-USDT-PERPETUAL","sequence":1702545259448394,"prev_sequence":1702545259448393,"changes":[["sell","3.36800000","0.00000000"]]},"module":"linear"}
1704643988.9442508: {"channel":"depth","timestamp":1704643988852,"data":{"type":"update","instrument_id":"NEAR-USDT-PERPETUAL","sequence":1702545259448395,"prev_sequence":1702545259448394,"changes":[["sell","3.36900000","710.00000000"]]},"module":"linear"}
1704643988.944269: {"channel":"depth","timestamp":1704643988852,"data":{"type":"update","instrument_id":"NEAR-USDT-PERPETUAL","sequence":1702545259448396,"prev_sequence":1702545259448395,"changes":[["buy","3.34200000","0.00000000"]]},"module":"linear"}
1704643988.944296: {"channel":"depth","timestamp":1704643988852,"data":{"type":"update","instrument_id":"NEAR-USDT-PERPETUAL","sequence":1702545259448397,"prev_sequence":1702545259448396,"changes":[["buy","3.34200000","210.00000000"]]},"module":"linear"}
1704643989.115516: {"channel":"depth","timestamp":1704643989024,"data":{"type":"update","instrument_id":"NEAR-USDT-PERPETUAL","sequence":1702545259448398,"prev_sequence":1702545259448397,"changes":[["sell","3.35600000","510.00000000"]]},"module":"linear"}
1704643989.1155899: {"channel":"depth","timestamp":1704643989024,"data":{"type":"update","instrument_id":"NEAR-USDT-PERPETUAL","sequence":1702545259448399,"prev_sequence":1702545259448398,"changes":[["sell","3.35700000","370.00000000"]]},"module":"linear"}
1704643989.1156359: {"channel":"depth","timestamp":1704643989024,"data":{"type":"update","instrument_id":"NEAR-USDT-PERPETUAL","sequence":1702545259448400,"prev_sequence":1702545259448399,"changes":[["buy","3.34700000","110.00000000"]]},"module":"linear"}
1704643989.115675: {"channel":"depth","timestamp":1704643989024,"data":{"type":"update","instrument_id":"NEAR-USDT-PERPETUAL","sequence":1702545259448401,"prev_sequence":1702545259448400,"changes":[["buy","3.34800000","380.00000000"]]},"module":"linear"}
1704643989.1156979: {"channel":"depth","timestamp":1704643989024,"data":{"type":"update","instrument_id":"NEAR-USDT-PERPETUAL","sequence":1702545259448402,"prev_sequence":1702545259448401,"changes":[["sell","3.35800000","0.00000000"]]},"module":"linear"}
1704643989.1157188: {"channel":"depth","timestamp":1704643989024,"data":{"type":"update","instrument_id":"NEAR-USDT-PERPETUAL","sequence":1702545259448403,"prev_sequence":1702545259448402,"changes":[["sell","3.35900000","1270.00000000"]]},"module":"linear"}
1704643989.1157398: {"channel":"depth","timestamp":1704643989024,"data":{"type":"update","instrument_id":"NEAR-USDT-PERPETUAL","sequence":1702545259448404,"prev_sequence":1702545259448403,"changes":[["buy","3.34500000","0.00000000"]]},"module":"linear"}
1704643989.11576: {"channel":"depth","timestamp":1704643989024,"data":{"type":"update","instrument_id":"NEAR-USDT-PERPETUAL","sequence":1702545259448405,"prev_sequence":1702545259448404,"changes":[["buy","3.34600000","1690.00000000"]]},"module":"linear"}
1704643989.115781: {"channel":"depth","timestamp":1704643989024,"data":{"type":"update","instrument_id":"NEAR-USDT-PERPETUAL","sequence":1702545259448406,"prev_sequence":1702545259448405,"changes":[["sell","3.35900000","1070.00000000"]]},"module":"linear"}
1704643989.1158001: {"channel":"depth","timestamp":1704643989024,"data":{"type":"update","instrument_id":"NEAR-USDT-PERPETUAL","sequence":1702545259448407,"prev_sequence":1702545259448406,"changes":[["sell","3.36000000","430.00000000"]]},"module":"linear"}
1704643989.11582: {"channel":"depth","timestamp":1704643989024,"data":{"type":"update","instrument_id":"NEAR-USDT-PERPETUAL","sequence":1702545259448408,"prev_sequence":1702545259448407,"changes":[["buy","3.34400000","0.00000000"]]},"module":"linear"}
1704643989.11584: {"channel":"depth","timestamp":1704643989024,"data":{"type":"update","instrument_id":"NEAR-USDT-PERPETUAL","sequence":1702545259448409,"prev_sequence":1702545259448408,"changes":[["buy","3.34500000","230.00000000"]]},"module":"linear"}
1704643989.115859: {"channel":"depth","timestamp":1704643989024,"data":{"type":"update","instrument_id":"NEAR-USDT-PERPETUAL","sequence":1702545259448410,"prev_sequence":1702545259448409,"changes":[["sell","3.36000000","230.00000000"]]},"module":"linear"}
1704643989.1158779: {"channel":"depth","timestamp":1704643989024,"data":{"type":"update","instrument_id":"NEAR-USDT-PERPETUAL","sequence":1702545259448411,"prev_sequence":1702545259448410,"changes":[["sell","3.36100000","410.00000000"]]},"module":"linear"}
1704643989.115896: {"channel":"depth","timestamp":1704643989024,"data":{"type":"update","instrument_id":"NEAR-USDT-PERPETUAL","sequence":1702545259448412,"prev_sequence":1702545259448411,"changes":[["buy","3.34300000","0.00000000"]]},"module":"linear"}
1704643989.115916: {"channel":"depth","timestamp":1704643989024,"data":{"type":"update","instrument_id":"NEAR-USDT-PERPETUAL","sequence":1702545259448413,"prev_sequence":1702545259448412,"changes":[["buy","3.34400000","230.00000000"]]},"module":"linear"}
1704643989.115942: {"channel":"depth","timestamp":1704643989024,"data":{"type":"update","instrument_id":"NEAR-USDT-PERPETUAL","sequence":1702545259448414,"prev_sequence":1702545259448413,"changes":[["sell","3.36100000","200.00000000"]]},"module":"linear"}
1704643989.115962: {"channel":"depth","timestamp":1704643989024,"data":{"type":"update","instrument_id":"NEAR-USDT-PERPETUAL","sequence":1702545259448415,"prev_sequence":1702545259448414,"changes":[["sell","3.36200000","620.00000000"]]},"module":"linear"}
1704643989.1159801: {"channel":"depth","timestamp":1704643989024,"data":{"type":"update","instrument_id":"NEAR-USDT-PERPETUAL","sequence":1702545259448416,"prev_sequence":1702545259448415,"changes":[["buy","3.34200000","0.00000000"]]},"module":"linear"}
1704643989.115999: {"channel":"depth","timestamp":1704643989024,"data":{"type":"update","instrument_id":"NEAR-USDT-PERPETUAL","sequence":1702545259448417,"prev_sequence":1702545259448416,"changes":[["buy","3.34300000","200.00000000"]]},"module":"linear"}
1704643989.137656: {"channel":"depth","timestamp":1704643989048,"data":{"type":"update","instrument_id":"NEAR-USDT-PERPETUAL","sequence":1702545259448418,"prev_sequence":1702545259448417,"changes":[["sell","3.35500000","0.00000000"]]},"module":"linear"}
1704643989.137764: {"channel":"depth","timestamp":1704643989048,"data":{"type":"update","instrument_id":"NEAR-USDT-PERPETUAL","sequence":1702545259448419,"prev_sequence":1702545259448418,"changes":[["sell","3.35600000","0.00000000"]]},"module":"linear"}
1704643989.448359: {"channel":"depth","timestamp":1704643989359,"data":{"type":"update","instrument_id":"NEAR-USDT-PERPETUAL","sequence":1702545259448420,"prev_sequence":1702545259448419,"changes":[["sell","3.35600000","110.00000000"]]},"module":"linear"}
1704643989.551262: {"channel":"depth","timestamp":1704643989414,"data":{"type":"update","instrument_id":"NEAR-USDT-PERPETUAL","sequence":1702545259448421,"prev_sequence":1702545259448420,"changes":[["sell","3.35800000","510.00000000"]]},"module":"linear"}
1704643990.382112: {"channel":"depth","timestamp":1704643990291,"data":{"type":"update","instrument_id":"NEAR-USDT-PERPETUAL","sequence":1702545259448422,"prev_sequence":1702545259448421,"changes":[["sell","3.35700000","0.00000000"]]},"module":"linear"}
1704643990.382188: {"channel":"depth","timestamp":1704643990291,"data":{"type":"update","instrument_id":"NEAR-USDT-PERPETUAL","sequence":1702545259448423,"prev_sequence":1702545259448422,"changes":[["sell","3.35700000","360.00000000"]]},"module":"linear"}
1704643990.382227: {"channel":"depth","timestamp":1704643990291,"data":{"type":"update","instrument_id":"NEAR-USDT-PERPETUAL","sequence":1702545259448424,"prev_sequence":1702545259448423,"changes":[["buy","3.34800000","0.00000000"]]},"module":"linear"}
1704643990.3822532: {"channel":"depth","timestamp":1704643990291,"data":{"type":"update","instrument_id":"NEAR-USDT-PERPETUAL","sequence":1702545259448425,"prev_sequence":1702545259448424,"changes":[["buy","3.34800000","380.00000000"]]},"module":"linear"}
1704643990.3822742: {"channel":"depth","timestamp":1704643990291,"data":{"type":"update","instrument_id":"NEAR-USDT-PERPETUAL","sequence":1702545259448426,"prev_sequence":1702545259448425,"changes":[["sell","3.36000000","0.00000000"]]},"module":"linear"}
1704643990.3822951: {"channel":"depth","timestamp":1704643990291,"data":{"type":"update","instrument_id":"NEAR-USDT-PERPETUAL","sequence":1702545259448427,"prev_sequence":1702545259448426,"changes":[["sell","3.36000000","220.00000000"]]},"module":"linear"}
1704643990.382316: {"channel":"depth","timestamp":1704643990291,"data":{"type":"update","instrument_id":"NEAR-USDT-PERPETUAL","sequence":1702545259448428,"prev_sequence":1702545259448427,"changes":[["buy","3.34600000","510.00000000"]]},"module":"linear"}
1704643990.382338: {"channel":"depth","timestamp":1704643990291,"data":{"type":"update","instrument_id":"NEAR-USDT-PERPETUAL","sequence":1702545259448429,"prev_sequence":1702545259448428,"changes":[["buy","3.34600000","1670.00000000"]]},"module":"linear"}
1704643990.382358: {"channel":"depth","timestamp":1704643990291,"data":{"type":"update","instrument_id":"NEAR-USDT-PERPETUAL","sequence":1702545259448430,"prev_sequence":1702545259448429,"changes":[["sell","3.36200000","420.00000000"]]},"module":"linear"}
1704643990.382378: {"channel":"depth","timestamp":1704643990291,"data":{"type":"update","instrument_id":"NEAR-USDT-PERPETUAL","sequence":1702545259448431,"prev_sequence":1702545259448430,"changes":[["sell","3.36200000","620.00000000"]]},"module":"linear"}
1704643990.382397: {"channel":"depth","timestamp":1704643990291,"data":{"type":"update","instrument_id":"NEAR-USDT-PERPETUAL","sequence":1702545259448432,"prev_sequence":1702545259448431,"changes":[["buy","3.34500000","0.00000000"]]},"module":"linear"}
1704643990.382417: {"channel":"depth","timestamp":1704643990291,"data":{"type":"update","instrument_id":"NEAR-USDT-PERPETUAL","sequence":1702545259448433,"prev_sequence":1702545259448432,"changes":[["buy","3.34500000","220.00000000"]]},"module":"linear"}
1704643990.382445: {"channel":"depth","timestamp":1704643990291,"data":{"type":"update","instrument_id":"NEAR-USDT-PERPETUAL","sequence":1702545259448434,"prev_sequence":1702545259448433,"changes":[["sell","3.36200000","430.00000000"]]},"module":"linear"}
1704643990.382464: {"channel":"depth","timestamp":1704643990291,"data":{"type":"update","instrument_id":"NEAR-USDT-PERPETUAL","sequence":1702545259448435,"prev_sequence":1702545259448434,"changes":[["sell","3.36300000","190.00000000"]]},"module":"linear"}
1704643990.382483: {"channel":"depth","timestamp":1704643990291,"data":{"type":"update","instrument_id":"NEAR-USDT-PERPETUAL","sequence":1702545259448436,"prev_sequence":1702545259448435,"changes":[["buy","3.34400000","0.00000000"]]},"module":"linear"}
1704643990.3825028: {"channel":"depth","timestamp":1704643990291,"data":{"type":"update","instrument_id":"NEAR-USDT-PERPETUAL","sequence":1702545259448437,"prev_sequence":1702545259448436,"changes":[["buy","3.34400000","220.00000000"]]},"module":"linear"}
1704643990.382522: {"channel":"depth","timestamp":1704643990291,"data":{"type":"update","instrument_id":"NEAR-USDT-PERPETUAL","sequence":1702545259448438,"prev_sequence":1702545259448437,"changes":[["sell","3.36200000","200.00000000"]]},"module":"linear"}
1704643990.382541: {"channel":"depth","timestamp":1704643990291,"data":{"type":"update","instrument_id":"NEAR-USDT-PERPETUAL","sequence":1702545259448439,"prev_sequence":1702545259448438,"changes":[["sell","3.36400000","190.00000000"]]},"module":"linear"}
1704643990.38256: {"channel":"depth","timestamp":1704643990291,"data":{"type":"update","instrument_id":"NEAR-USDT-PERPETUAL","sequence":1702545259448440,"prev_sequence":1702545259448439,"changes":[["buy","3.34000000","0.00000000"]]},"module":"linear"}
1704643990.3825788: {"channel":"depth","timestamp":1704643990291,"data":{"type":"update","instrument_id":"NEAR-USDT-PERPETUAL","sequence":1702545259448441,"prev_sequence":1702545259448440,"changes":[["buy","3.34200000","200.00000000"]]},"module":"linear"}
1704643990.4186418: {"channel":"depth","timestamp":1704643990329,"data":{"type":"update","instrument_id":"NEAR-USDT-PERPETUAL","sequence":1702545259448442,"prev_sequence":1702545259448441,"changes":[["sell","3.36500000","0.00000000"]]},"module":"linear"}
1704643990.4186869: {"channel":"depth","timestamp":1704643990329,"data":{"type":"update","instrument_id":"NEAR-USDT-PERPETUAL","sequence":1702545259448443,"prev_sequence":1702545259448442,"changes":[["sell","3.36600000","1150.00000000"]]},"module":"linear"}
1704643990.418723: {"channel":"depth","timestamp":1704643990329,"data":{"type":"update","instrument_id":"NEAR-USDT-PERPETUAL","sequence":1702545259448444,"prev_sequence":1702545259448443,"changes":[["buy","3.33900000","0.00000000"]]},"module":"linear"}
1704643990.418746: {"channel":"depth","timestamp":1704643990329,"data":{"type":"update","instrument_id":"NEAR-USDT-PERPETUAL","sequence":1702545259448445,"prev_sequence":1702545259448444,"changes":[["buy","3.34100000","190.00000000"]]},"module":"linear"}
1704643990.4187672: {"channel":"depth","timestamp":1704643990329,"data":{"type":"update","instrument_id":"NEAR-USDT-PERPETUAL","sequence":1702545259448446,"prev_sequence":1702545259448445,"changes":[["sell","3.36700000","0.00000000"]]},"module":"linear"}
1704643990.418787: {"channel":"depth","timestamp":1704643990329,"data":{"type":"update","instrument_id":"NEAR-USDT-PERPETUAL","sequence":1702545259448447,"prev_sequence":1702545259448446,"changes":[["sell","3.36800000","660.00000000"]]},"module":"linear"}
1704643990.418807: {"channel":"depth","timestamp":1704643990329,"data":{"type":"update","instrument_id":"NEAR-USDT-PERPETUAL","sequence":1702545259448448,"prev_sequence":1702545259448447,"changes":[["buy","3.33700000","0.00000000"]]},"module":"linear"}
1704643990.4188428: {"channel":"depth","timestamp":1704643990329,"data":{"type":"update","instrument_id":"NEAR-USDT-PERPETUAL","sequence":1702545259448449,"prev_sequence":1702545259448448,"changes":[["buy","3.33900000","1160.00000000"]]},"module":"linear"}
1704643990.418863: {"channel":"depth","timestamp":1704643990329,"data":{"type":"update","instrument_id":"NEAR-USDT-PERPETUAL","sequence":1702545259448450,"prev_sequence":1702545259448449,"changes":[["sell","3.36900000","0.00000000"]]},"module":"linear"}
1704643990.418883: {"channel":"depth","timestamp":1704643990329,"data":{"type":"update","instrument_id":"NEAR-USDT-PERPETUAL","sequence":1702545259448451,"prev_sequence":1702545259448450,"changes":[["sell","3.37000000","1170.00000000"]]},"module":"linear"}
1704643990.418902: {"channel":"depth","timestamp":1704643990329,"data":{"type":"update","instrument_id":"NEAR-USDT-PERPETUAL","sequence":1702545259448452,"prev_sequence":1702545259448451,"changes":[["buy","3.33500000","0.00000000"]]},"module":"linear"}
1704643990.418921: {"channel":"depth","timestamp":1704643990329,"data":{"type":"update","instrument_id":"NEAR-USDT-PERPETUAL","sequence":1702545259448453,"prev_sequence":1702545259448452,"changes":[["buy","3.33700000","930.00000000"]]},"module":"linear"}
1704643990.4189398: {"channel":"depth","timestamp":1704643990329,"data":{"type":"update","instrument_id":"NEAR-USDT-PERPETUAL","sequence":1702545259448454,"prev_sequence":1702545259448453,"changes":[["buy","3.33300000","0.00000000"]]},"module":"linear"}
1704643990.4189591: {"channel":"depth","timestamp":1704643990329,"data":{"type":"update","instrument_id":"NEAR-USDT-PERPETUAL","sequence":1702545259448455,"prev_sequence":1702545259448454,"changes":[["buy","3.33500000","1150.00000000"]]},"module":"linear"}
1704643991.829976: {"channel":"depth","timestamp":1704643991713,"data":{"type":"update","instrument_id":"NEAR-USDT-PERPETUAL","sequence":1702545259448456,"prev_sequence":1702545259448455,"changes":[["sell","3.35700000","0.00000000"]]},"module":"linear"}
1704643991.830078: {"channel":"depth","timestamp":1704643991713,"data":{"type":"update","instrument_id":"NEAR-USDT-PERPETUAL","sequence":1702545259448457,"prev_sequence":1702545259448456,"changes":[["sell","3.35600000","510.00000000"]]},"module":"linear"}
1704643991.8301098: {"channel":"depth","timestamp":1704643991713,"data":{"type":"update","instrument_id":"NEAR-USDT-PERPETUAL","sequence":1702545259448458,"prev_sequence":1702545259448457,"changes":[["buy","3.34800000","0.00000000"]]},"module":"linear"}
1704643991.830135: {"channel":"depth","timestamp":1704643991713,"data":{"type":"update","instrument_id":"NEAR-USDT-PERPETUAL","sequence":1702545259448459,"prev_sequence":1702545259448458,"changes":[["buy","3.34700000","490.00000000"]]},"module":"linear"}
1704643991.830157: {"channel":"depth","timestamp":1704643991713,"data":{"type":"update","instrument_id":"NEAR-USDT-PERPETUAL","sequence":1702545259448460,"prev_sequence":1702545259448459,"changes":[["sell","3.35900000","0.00000000"]]},"module":"linear"}
1704643991.830178: {"channel":"depth","timestamp":1704643991713,"data":{"type":"update","instrument_id":"NEAR-USDT-PERPETUAL","sequence":1702545259448461,"prev_sequence":1702545259448460,"changes":[["sell","3.35800000","1690.00000000"]]},"module":"linear"}
1704643991.8302011: {"channel":"depth","timestamp":1704643991713,"data":{"type":"update","instrument_id":"NEAR-USDT-PERPETUAL","sequence":1702545259448462,"prev_sequence":1702545259448461,"changes":[["buy","3.34600000","510.00000000"]]},"module":"linear"}
1704643991.830221: {"channel":"depth","timestamp":1704643991713,"data":{"type":"update","instrument_id":"NEAR-USDT-PERPETUAL","sequence":1702545259448463,"prev_sequence":1702545259448462,"changes":[["buy","3.34500000","1410.00000000"]]},"module":"linear"}
1704643991.830241: {"channel":"depth","timestamp":1704643991713,"data":{"type":"update","instrument_id":"NEAR-USDT-PERPETUAL","sequence":1702545259448464,"prev_sequence":1702545259448463,"changes":[["sell","3.36000000","0.00000000"]]},"module":"linear"}
1704643991.830261: {"channel":"depth","timestamp":1704643991713,"data":{"type":"update","instrument_id":"NEAR-USDT-PERPETUAL","sequence":1702545259448465,"prev_sequence":1702545259448464,"changes":[["sell","3.35900000","200.00000000"]]},"module":"linear"}
1704643991.8302798: {"channel":"depth","timestamp":1704643991713,"data":{"type":"update","instrument_id":"NEAR-USDT-PERPETUAL","sequence":1702545259448466,"prev_sequence":1702545259448465,"changes":[["buy","3.34500000","1190.00000000"]]},"module":"linear"}
1704643991.8303099: {"channel":"depth","timestamp":1704643991713,"data":{"type":"update","instrument_id":"NEAR-USDT-PERPETUAL","sequence":1702545259448467,"prev_sequence":1702545259448466,"changes":[["buy","3.34400000","450.00000000"]]},"module":"linear"}
1704643991.830339: {"channel":"depth","timestamp":1704643991713,"data":{"type":"update","instrument_id":"NEAR-USDT-PERPETUAL","sequence":1702545259448468,"prev_sequence":1702545259448467,"changes":[["sell","3.36100000","0.00000000"]]},"module":"linear"}
1704643991.830358: {"channel":"depth","timestamp":1704643991713,"data":{"type":"update","instrument_id":"NEAR-USDT-PERPETUAL","sequence":1702545259448469,"prev_sequence":1702545259448468,"changes":[["sell","3.36000000","210.00000000"]]},"module":"linear"}
1704643991.8303812: {"channel":"depth","timestamp":1704643991713,"data":{"type":"update","instrument_id":"NEAR-USDT-PERPETUAL","sequence":1702545259448470,"prev_sequence":1702545259448469,"changes":[["buy","3.34400000","230.00000000"]]},"module":"linear"}
1704643991.830401: {"channel":"depth","timestamp":1704643991713,"data":{"type":"update","instrument_id":"NEAR-USDT-PERPETUAL","sequence":1702545259448471,"prev_sequence":1702545259448470,"changes":[["buy","3.34300000","430.00000000"]]},"module":"linear"}
1704643991.83042: {"channel":"depth","timestamp":1704643991713,"data":{"type":"update","instrument_id":"NEAR-USDT-PERPETUAL","sequence":1702545259448472,"prev_sequence":1702545259448471,"changes":[["sell","3.36200000","0.00000000"]]},"module":"linear"}
1704643991.8304389: {"channel":"depth","timestamp":1704643991714,"data":{"type":"update","instrument_id":"NEAR-USDT-PERPETUAL","sequence":1702545259448473,"prev_sequence":1702545259448472,"changes":[["sell","3.36100000","230.00000000"]]},"module":"linear"}
1704643991.8304582: {"channel":"depth","timestamp":1704643991714,"data":{"type":"update","instrument_id":"NEAR-USDT-PERPETUAL","sequence":1702545259448474,"prev_sequence":1702545259448473,"changes":[["buy","3.34300000","230.00000000"]]},"module":"linear"}
1704643991.830477: {"channel":"depth","timestamp":1704643991714,"data":{"type":"update","instrument_id":"NEAR-USDT-PERPETUAL","sequence":1702545259448475,"prev_sequence":1702545259448474,"changes":[["buy","3.34200000","390.00000000"]]},"module":"linear"}
1704643992.8500211: {"channel":"depth","timestamp":1704643992698,"data":{"type":"update","instrument_id":"NEAR-USDT-PERPETUAL","sequence":1702545259448476,"prev_sequence":1702545259448475,"changes":[["sell","3.35600000","110.00000000"]]},"module":"linear"}
1704643992.850105: {"channel":"depth","timestamp":1704643992698,"data":{"type":"update","instrument_id":"NEAR-USDT-PERPETUAL","sequence":1702545259448477,"prev_sequence":1702545259448476,"changes":[["sell","3.35500000","380.00000000"]]},"module":"linear"}
1704643992.850137: {"channel":"depth","timestamp":1704643992698,"data":{"type":"update","instrument_id":"NEAR-USDT-PERPETUAL","sequence":1702545259448478,"prev_sequence":1702545259448477,"changes":[["buy","3.34700000","110.00000000"]]},"module":"linear"}
1704643992.8501601: {"channel":"depth","timestamp":1704643992698,"data":{"type":"update","instrument_id":"NEAR-USDT-PERPETUAL","sequence":1702545259448479,"prev_sequence":1702545259448478,"changes":[["buy","3.34600000","920.00000000"]]},"module":"linear"}
1704643992.8501818: {"channel":"depth","timestamp":1704643992698,"data":{"type":"update","instrument_id":"NEAR-USDT-PERPETUAL","sequence":1702545259448480,"prev_sequence":1702545259448479,"changes":[["sell","3.35800000","510.00000000"]]},"module":"linear"}
1704643992.850202: {"channel":"depth","timestamp":1704643992698,"data":{"type":"update","instrument_id":"NEAR-USDT-PERPETUAL","sequence":1702545259448481,"prev_sequence":1702545259448480,"changes":[["sell","3.35700000","1150.00000000"]]},"module":"linear"}
1704643992.850222: {"channel":"depth","timestamp":1704643992698,"data":{"type":"update","instrument_id":"NEAR-USDT-PERPETUAL","sequence":1702545259448482,"prev_sequence":1702545259448481,"changes":[["buy","3.34500000","0.00000000"]]},"module":"linear"}
1704643992.850243: {"channel":"depth","timestamp":1704643992698,"data":{"type":"update","instrument_id":"NEAR-USDT-PERPETUAL","sequence":1702545259448483,"prev_sequence":1702545259448482,"changes":[["buy","3.34400000","1380.00000000"]]},"module":"linear"}
1704643992.850262: {"channel":"depth","timestamp":1704643992698,"data":{"type":"update","instrument_id":"NEAR-USDT-PERPETUAL","sequence":1702545259448484,"prev_sequence":1702545259448483,"changes":[["sell","3.35900000","0.00000000"]]},"module":"linear"}
1704643992.850282: {"channel":"depth","timestamp":1704643992698,"data":{"type":"update","instrument_id":"NEAR-USDT-PERPETUAL","sequence":1702545259448485,"prev_sequence":1702545259448484,"changes":[["sell","3.35800000","730.00000000"]]},"module":"linear"}
1704643992.850301: {"channel":"depth","timestamp":1704643992698,"data":{"type":"update","instrument_id":"NEAR-USDT-PERPETUAL","sequence":1702545259448486,"prev_sequence":1702545259448485,"changes":[["buy","3.34400000","1150.00000000"]]},"module":"linear"}
1704643992.850327: {"channel":"depth","timestamp":1704643992698,"data":{"type":"update","instrument_id":"NEAR-USDT-PERPETUAL","sequence":1702545259448487,"prev_sequence":1702545259448486,"changes":[["buy","3.34300000","420.00000000"]]},"module":"linear"}
1704643992.850345: {"channel":"depth","timestamp":1704643992698,"data":{"type":"update","instrument_id":"NEAR-USDT-PERPETUAL","sequence":1702545259448488,"prev_sequence":1702545259448487,"changes":[["sell","3.36000000","0.00000000"]]},"module":"linear"}
1704643992.850365: {"channel":"depth","timestamp":1704643992698,"data":{"type":"update","instrument_id":"NEAR-USDT-PERPETUAL","sequence":1702545259448489,"prev_sequence":1702545259448488,"changes":[["sell","3.35900000","220.00000000"]]},"module":"linear"}
1704643992.850383: {"channel":"depth","timestamp":1704643992698,"data":{"type":"update","instrument_id":"NEAR-USDT-PERPETUAL","sequence":1702545259448490,"prev_sequence":1702545259448489,"changes":[["buy","3.34300000","190.00000000"]]},"module":"linear"}
1704643992.850402: {"channel":"depth","timestamp":1704643992698,"data":{"type":"update","instrument_id":"NEAR-USDT-PERPETUAL","sequence":1702545259448491,"prev_sequence":1702545259448490,"changes":[["buy","3.34200000","610.00000000"]]},"module":"linear"}
1704643992.85042: {"channel":"depth","timestamp":1704643992698,"data":{"type":"update","instrument_id":"NEAR-USDT-PERPETUAL","sequence":1702545259448492,"prev_sequence":1702545259448491,"changes":[["sell","3.36100000","0.00000000"]]},"module":"linear"}
1704643992.8504388: {"channel":"depth","timestamp":1704643992698,"data":{"type":"update","instrument_id":"NEAR-USDT-PERPETUAL","sequence":1702545259448493,"prev_sequence":1702545259448492,"changes":[["sell","3.36000000","220.00000000"]]},"module":"linear"}
1704643992.8504572: {"channel":"depth","timestamp":1704643992699,"data":{"type":"update","instrument_id":"NEAR-USDT-PERPETUAL","sequence":1702545259448494,"prev_sequence":1702545259448493,"changes":[["buy","3.34200000","420.00000000"]]},"module":"linear"}
1704643992.850476: {"channel":"depth","timestamp":1704643992699,"data":{"type":"update","instrument_id":"NEAR-USDT-PERPETUAL","sequence":1702545259448495,"prev_sequence":1702545259448494,"changes":[["buy","3.34100000","380.00000000"]]},"module":"linear"}
1704643992.850525: {"channel":"depth","timestamp":1704643992755,"data":{"type":"update","instrument_id":"NEAR-USDT-PERPETUAL","sequence":1702545259448496,"prev_sequence":1702545259448495,"changes":[["sell","3.36300000","0.00000000"]]},"module":"linear"}
1704643992.851072: {"channel":"depth","timestamp":1704643992755,"data":{"type":"update","instrument_id":"NEAR-USDT-PERPETUAL","sequence":1702545259448497,"prev_sequence":1702545259448496,"changes":[["sell","3.36100000","230.00000000"]]},"module":"linear"}
1704643992.851112: {"channel":"depth","timestamp":1704643992755,"data":{"type":"update","instrument_id":"NEAR-USDT-PERPETUAL","sequence":1702545259448498,"prev_sequence":1702545259448497,"changes":[["buy","3.34200000","220.00000000"]]},"module":"linear"}
1704643992.85114: {"channel":"depth","timestamp":1704643992755,"data":{"type":"update","instrument_id":"NEAR-USDT-PERPETUAL","sequence":1702545259448499,"prev_sequence":1702545259448498,"changes":[["buy","3.34000000","220.00000000"]]},"module":"linear"}
1704643992.851163: {"channel":"depth","timestamp":1704643992755,"data":{"type":"update","instrument_id":"NEAR-USDT-PERPETUAL","sequence":1702545259448500,"prev_sequence":1702545259448499,"changes":[["sell","3.36400000","0.00000000"]]},"module":"linear"}
1704643992.8511841: {"channel":"depth","timestamp":1704643992755,"data":{"type":"update","instrument_id":"NEAR-USDT-PERPETUAL","sequence":1702545259448501,"prev_sequence":1702545259448500,"changes":[["sell","3.36200000","200.00000000"]]},"module":"linear"}
1704643992.851205: {"channel":"depth","timestamp":1704643992755,"data":{"type":"update","instrument_id":"NEAR-USDT-PERPETUAL","sequence":1702545259448502,"prev_sequence":1702545259448501,"changes":[["buy","3.34100000","190.00000000"]]},"module":"linear"}
1704643992.8512251: {"channel":"depth","timestamp":1704643992755,"data":{"type":"update","instrument_id":"NEAR-USDT-PERPETUAL","sequence":1702545259448503,"prev_sequence":1702545259448502,"changes":[["buy","3.33900000","1380.00000000"]]},"module":"linear"}
1704643992.851244: {"channel":"depth","timestamp":1704643992755,"data":{"type":"update","instrument_id":"NEAR-USDT-PERPETUAL","sequence":1702545259448504,"prev_sequence":1702545259448503,"changes":[["sell","3.36600000","0.00000000"]]},"module":"linear"}
1704643992.851264: {"channel":"depth","timestamp":1704643992755,"data":{"type":"update","instrument_id":"NEAR-USDT-PERPETUAL","sequence":1702545259448505,"prev_sequence":1702545259448504,"changes":[["sell","3.36400000","730.00000000"]]},"module":"linear"}
1704643992.8512828: {"channel":"depth","timestamp":1704643992755,"data":{"type":"update","instrument_id":"NEAR-USDT-PERPETUAL","sequence":1702545259448506,"prev_sequence":1702545259448505,"changes":[["buy","3.33900000","220.00000000"]]},"module":"linear"}
1704643992.8513029: {"channel":"depth","timestamp":1704643992755,"data":{"type":"update","instrument_id":"NEAR-USDT-PERPETUAL","sequence":1702545259448507,"prev_sequence":1702545259448506,"changes":[["buy","3.33700000","2050.00000000"]]},"module":"linear"}
1704643992.8513222: {"channel":"depth","timestamp":1704643992755,"data":{"type":"update","instrument_id":"NEAR-USDT-PERPETUAL","sequence":1702545259448508,"prev_sequence":1702545259448507,"changes":[["sell","3.36800000","0.00000000"]]},"module":"linear"}
1704643992.851342: {"channel":"depth","timestamp":1704643992755,"data":{"type":"update","instrument_id":"NEAR-USDT-PERPETUAL","sequence":1702545259448509,"prev_sequence":1702545259448508,"changes":[["sell","3.36600000","1160.00000000"]]},"module":"linear"}
1704643992.851362: {"channel":"depth","timestamp":1704643992755,"data":{"type":"update","instrument_id":"NEAR-USDT-PERPETUAL","sequence":1702545259448510,"prev_sequence":1702545259448509,"changes":[["buy","3.33700000","1120.00000000"]]},"module":"linear"}
1704643992.8513799: {"channel":"depth","timestamp":1704643992755,"data":{"type":"update","instrument_id":"NEAR-USDT-PERPETUAL","sequence":1702545259448511,"prev_sequence":1702545259448510,"changes":[["buy","3.33500000","2330.00000000"]]},"module":"linear"}
1704643992.851399: {"channel":"depth","timestamp":1704643992755,"data":{"type":"update","instrument_id":"NEAR-USDT-PERPETUAL","sequence":1702545259448512,"prev_sequence":1702545259448511,"changes":[["sell","3.37000000","0.00000000"]]},"module":"linear"}
1704643992.851419: {"channel":"depth","timestamp":1704643992755,"data":{"type":"update","instrument_id":"NEAR-USDT-PERPETUAL","sequence":1702545259448513,"prev_sequence":1702545259448512,"changes":[["sell","3.36800000","740.00000000"]]},"module":"linear"}
1704643992.851438: {"channel":"depth","timestamp":1704643992755,"data":{"type":"update","instrument_id":"NEAR-USDT-PERPETUAL","sequence":1702545259448514,"prev_sequence":1702545259448513,"changes":[["buy","3.33500000","1180.00000000"]]},"module":"linear"}
1704643992.851456: {"channel":"depth","timestamp":1704643992755,"data":{"type":"update","instrument_id":"NEAR-USDT-PERPETUAL","sequence":1702545259448515,"prev_sequence":1702545259448514,"changes":[["buy","3.33300000","1130.00000000"]]},"module":"linear"}
1704643994.015693: {"channel":"depth","timestamp":1704643993926,"data":{"type":"update","instrument_id":"NEAR-USDT-PERPETUAL","sequence":1702545259448516,"prev_sequence":1702545259448515,"changes":[["sell","3.35500000","0.00000000"]]},"module":"linear"}
1704643994.015767: {"channel":"depth","timestamp":1704643993926,"data":{"type":"update","instrument_id":"NEAR-USDT-PERPETUAL","sequence":1702545259448517,"prev_sequence":1702545259448516,"changes":[["sell","3.35500000","380.00000000"]]},"module":"linear"}
1704643994.0158029: {"channel":"depth","timestamp":1704643993926,"data":{"type":"update","instrument_id":"NEAR-USDT-PERPETUAL","sequence":1702545259448518,"prev_sequence":1702545259448517,"changes":[["buy","3.34600000","510.00000000"]]},"module":"linear"}
1704643994.015829: {"channel":"depth","timestamp":1704643993926,"data":{"type":"update","instrument_id":"NEAR-USDT-PERPETUAL","sequence":1702545259448519,"prev_sequence":1702545259448518,"changes":[["buy","3.34600000","900.00000000"]]},"module":"linear"}
1704643994.015852: {"channel":"depth","timestamp":1704643993926,"data":{"type":"update","instrument_id":"NEAR-USDT-PERPETUAL","sequence":1702545259448520,"prev_sequence":1702545259448519,"changes":[["sell","3.35800000","510.00000000"]]},"module":"linear"}
1704643994.015873: {"channel":"depth","timestamp":1704643993926,"data":{"type":"update","instrument_id":"NEAR-USDT-PERPETUAL","sequence":1702545259448521,"prev_sequence":1702545259448520,"changes":[["sell","3.35800000","720.00000000"]]},"module":"linear"}
1704643994.015894: {"channel":"depth","timestamp":1704643993926,"data":{"type":"update","instrument_id":"NEAR-USDT-PERPETUAL","sequence":1702545259448522,"prev_sequence":1702545259448521,"changes":[["buy","3.34400000","0.00000000"]]},"module":"linear"}
1704643994.015915: {"channel":"depth","timestamp":1704643993926,"data":{"type":"update","instrument_id":"NEAR-USDT-PERPETUAL","sequence":1702545259448523,"prev_sequence":1702545259448522,"changes":[["buy","3.34400000","1170.00000000"]]},"module":"linear"}
1704643994.015945: {"channel":"depth","timestamp":1704643993926,"data":{"type":"update","instrument_id":"NEAR-USDT-PERPETUAL","sequence":1702545259448524,"prev_sequence":1702545259448523,"changes":[["sell","3.35900000","0.00000000"]]},"module":"linear"}
1704643994.015966: {"channel":"depth","timestamp":1704643993926,"data":{"type":"update","instrument_id":"NEAR-USDT-PERPETUAL","sequence":1702545259448525,"prev_sequence":1702545259448524,"changes":[["sell","3.35900000","190.00000000"]]},"module":"linear"}
1704643994.016001: {"channel":"depth","timestamp":1704643993926,"data":{"type":"update","instrument_id":"NEAR-USDT-PERPETUAL","sequence":1702545259448526,"prev_sequence":1702545259448525,"changes":[["buy","3.34300000","0.00000000"]]},"module":"linear"}
1704643994.016022: {"channel":"depth","timestamp":1704643993926,"data":{"type":"update","instrument_id":"NEAR-USDT-PERPETUAL","sequence":1702545259448527,"prev_sequence":1702545259448526,"changes":[["buy","3.34300000","190.00000000"]]},"module":"linear"}
1704643994.016042: {"channel":"depth","timestamp":1704643993926,"data":{"type":"update","instrument_id":"NEAR-USDT-PERPETUAL","sequence":1702545259448528,"prev_sequence":1702545259448527,"changes":[["sell","3.36000000","0.00000000"]]},"module":"linear"}
1704643994.0160608: {"channel":"depth","timestamp":1704643993926,"data":{"type":"update","instrument_id":"NEAR-USDT-PERPETUAL","sequence":1702545259448529,"prev_sequence":1702545259448528,"changes":[["sell","3.36000000","220.00000000"]]},"module":"linear"}
1704643994.0160809: {"channel":"depth","timestamp":1704643993926,"data":{"type":"update","instrument_id":"NEAR-USDT-PERPETUAL","sequence":1702545259448530,"prev_sequence":1702545259448529,"changes":[["buy","3.34200000","0.00000000"]]},"module":"linear"}
1704643994.0161002: {"channel":"depth","timestamp":1704643993926,"data":{"type":"update","instrument_id":"NEAR-USDT-PERPETUAL","sequence":1702545259448531,"prev_sequence":1702545259448530,"changes":[["buy","3.34200000","220.00000000"]]},"module":"linear"}
1704643994.01612: {"channel":"depth","timestamp":1704643993926,"data":{"type":"update","instrument_id":"NEAR-USDT-PERPETUAL","sequence":1702545259448532,"prev_sequence":1702545259448531,"changes":[["sell","3.36100000","0.00000000"]]},"module":"linear"}
1704643994.016139: {"channel":"depth","timestamp":1704643993926,"data":{"type":"update","instrument_id":"NEAR-USDT-PERPETUAL","sequence":1702545259448533,"prev_sequence":1702545259448532,"changes":[["sell","3.36100000","200.00000000"]]},"module":"linear"}
1704643994.0161579: {"channel":"depth","timestamp":1704643993926,"data":{"type":"update","instrument_id":"NEAR-USDT-PERPETUAL","sequence":1702545259448534,"prev_sequence":1702545259448533,"changes":[["buy","3.34000000","0.00000000"]]},"module":"linear"}
1704643994.016178: {"channel":"depth","timestamp":1704643993926,"data":{"type":"update","instrument_id":"NEAR-USDT-PERPETUAL","sequence":1702545259448535,"prev_sequence":1702545259448534,"changes":[["buy","3.34000000","220.00000000"]]},"module":"linear"}
1704643995.1949172: {"channel":"depth","timestamp":1704643995103,"data":{"type":"update","instrument_id":"NEAR-USDT-PERPETUAL","sequence":1702545259448536,"prev_sequence":1702545259448535,"changes":[["sell","3.36000000","0.00000000"]]},"module":"linear"}
1704643995.194999: {"channel":"depth","timestamp":1704643995103,"data":{"type":"update","instrument_id":"NEAR-USDT-PERPETUAL","sequence":1702545259448537,"prev_sequence":1702545259448536,"changes":[["sell","3.36000000","210.00000000"]]},"module":"linear"}
1704643995.1950321: {"channel":"depth","timestamp":1704643995103,"data":{"type":"update","instrument_id":"NEAR-USDT-PERPETUAL","sequence":1702545259448538,"prev_sequence":1702545259448537,"changes":[["buy","3.34200000","0.00000000"]]},"module":"linear"}
1704643995.195061: {"channel":"depth","timestamp":1704643995103,"data":{"type":"update","instrument_id":"NEAR-USDT-PERPETUAL","sequence":1702545259448539,"prev_sequence":1702545259448538,"changes":[["buy","3.34200000","210.00000000"]]},"module":"linear"}
1704643995.195084: {"channel":"depth","timestamp":1704643995103,"data":{"type":"update","instrument_id":"NEAR-USDT-PERPETUAL","sequence":1702545259448540,"prev_sequence":1702545259448539,"changes":[["sell","3.36100000","0.00000000"]]},"module":"linear"}
1704643995.195105: {"channel":"depth","timestamp":1704643995103,"data":{"type":"update","instrument_id":"NEAR-USDT-PERPETUAL","sequence":1702545259448541,"prev_sequence":1702545259448540,"changes":[["sell","3.36100000","200.00000000"]]},"module":"linear"}
1704643995.195126: {"channel":"depth","timestamp":1704643995103,"data":{"type":"update","instrument_id":"NEAR-USDT-PERPETUAL","sequence":1702545259448542,"prev_sequence":1702545259448541,"changes":[["buy","3.34100000","0.00000000"]]},"module":"linear"}
1704643995.195145: {"channel":"depth","timestamp":1704643995103,"data":{"type":"update","instrument_id":"NEAR-USDT-PERPETUAL","sequence":1702545259448543,"prev_sequence":1702545259448542,"changes":[["buy","3.34100000","190.00000000"]]},"module":"linear"}
1704643995.195165: {"channel":"depth","timestamp":1704643995103,"data":{"type":"update","instrument_id":"NEAR-USDT-PERPETUAL","sequence":1702545259448544,"prev_sequence":1702545259448543,"changes":[["sell","3.36400000","0.00000000"]]},"module":"linear"}
1704643995.195185: {"channel":"depth","timestamp":1704643995103,"data":{"type":"update","instrument_id":"NEAR-USDT-PERPETUAL","sequence":1702545259448545,"prev_sequence":1702545259448544,"changes":[["sell","3.36400000","640.00000000"]]},"module":"linear"}
1704643995.195221: {"channel":"depth","timestamp":1704643995103,"data":{"type":"update","instrument_id":"NEAR-USDT-PERPETUAL","sequence":1702545259448546,"prev_sequence":1702545259448545,"changes":[["buy","3.34000000","0.00000000"]]},"module":"linear"}
1704643995.195241: {"channel":"depth","timestamp":1704643995103,"data":{"type":"update","instrument_id":"NEAR-USDT-PERPETUAL","sequence":1702545259448547,"prev_sequence":1702545259448546,"changes":[["buy","3.34000000","190.00000000"]]},"module":"linear"}
1704643995.1952598: {"channel":"depth","timestamp":1704643995103,"data":{"type":"update","instrument_id":"NEAR-USDT-PERPETUAL","sequence":1702545259448548,"prev_sequence":1702545259448547,"changes":[["buy","3.33700000","0.00000000"]]},"module":"linear"}
1704643995.1952791: {"channel":"depth","timestamp":1704643995103,"data":{"type":"update","instrument_id":"NEAR-USDT-PERPETUAL","sequence":1702545259448549,"prev_sequence":1702545259448548,"changes":[["buy","3.33700000","1120.00000000"]]},"module":"linear"}
1704643995.195298: {"channel":"depth","timestamp":1704643995103,"data":{"type":"update","instrument_id":"NEAR-USDT-PERPETUAL","sequence":1702545259448550,"prev_sequence":1702545259448549,"changes":[["buy","3.33500000","0.00000000"]]},"module":"linear"}
1704643995.195317: {"channel":"depth","timestamp":1704643995103,"data":{"type":"update","instrument_id":"NEAR-USDT-PERPETUAL","sequence":1702545259448551,"prev_sequence":1702545259448550,"changes":[["buy","3.33500000","1160.00000000"]]},"module":"linear"}
1704643996.386266: {"channel":"depth","timestamp":1704643996294,"data":{"type":"update","instrument_id":"NEAR-USDT-PERPETUAL","sequence":1702545259448552,"prev_sequence":1702545259448551,"changes":[["buy","3.34600000","510.00000000"]]},"module":"linear"}
1704643996.386382: {"channel":"depth","timestamp":1704643996294,"data":{"type":"update","instrument_id":"NEAR-USDT-PERPETUAL","sequence":1702545259448553,"prev_sequence":1702545259448552,"changes":[["buy","3.34600000","920.00000000"]]},"module":"linear"}
1704643996.386438: {"channel":"depth","timestamp":1704643996294,"data":{"type":"update","instrument_id":"NEAR-USDT-PERPETUAL","sequence":1702545259448554,"prev_sequence":1702545259448553,"changes":[["sell","3.35500000","0.00000000"]]},"module":"linear"}
1704643996.38648: {"channel":"depth","timestamp":1704643996294,"data":{"type":"update","instrument_id":"NEAR-USDT-PERPETUAL","sequence":1702545259448555,"prev_sequence":1702545259448554,"changes":[["sell","3.35500000","360.00000000"]]},"module":"linear"}
1704643996.386503: {"channel":"depth","timestamp":1704643996295,"data":{"type":"update","instrument_id":"NEAR-USDT-PERPETUAL","sequence":1702545259448556,"prev_sequence":1702545259448555,"changes":[["buy","3.33900000","0.00000000"]]},"module":"linear"}
1704643996.386532: {"channel":"depth","timestamp":1704643996295,"data":{"type":"update","instrument_id":"NEAR-USDT-PERPETUAL","sequence":1702545259448557,"prev_sequence":1702545259448556,"changes":[["buy","3.33900000","200.00000000"]]},"module":"linear"}
1704643996.386553: {"channel":"depth","timestamp":1704643996295,"data":{"type":"update","instrument_id":"NEAR-USDT-PERPETUAL","sequence":1702545259448558,"prev_sequence":1702545259448557,"changes":[["sell","3.36100000","0.00000000"]]},"module":"linear"}
1704643996.386573: {"channel":"depth","timestamp":1704643996295,"data":{"type":"update","instrument_id":"NEAR-USDT-PERPETUAL","sequence":1702545259448559,"prev_sequence":1702545259448558,"changes":[["sell","3.36100000","190.00000000"]]},"module":"linear"}
1704643996.386592: {"channel":"depth","timestamp":1704643996295,"data":{"type":"update","instrument_id":"NEAR-USDT-PERPETUAL","sequence":1702545259448560,"prev_sequence":1702545259448559,"changes":[["buy","3.33700000","0.00000000"]]},"module":"linear"}
1704643996.386612: {"channel":"depth","timestamp":1704643996295,"data":{"type":"update","instrument_id":"NEAR-USDT-PERPETUAL","sequence":1702545259448561,"prev_sequence":1702545259448560,"changes":[["buy","3.33700000","930.00000000"]]},"module":"linear"}
1704643996.386631: {"channel":"depth","timestamp":1704643996295,"data":{"type":"update","instrument_id":"NEAR-USDT-PERPETUAL","sequence":1702545259448562,"prev_sequence":1702545259448561,"changes":[["sell","3.36400000","0.00000000"]]},"module":"linear"}
1704643996.3866508: {"channel":"depth","timestamp":1704643996295,"data":{"type":"update","instrument_id":"NEAR-USDT-PERPETUAL","sequence":1702545259448563,"prev_sequence":1702545259448562,"changes":[["sell","3.36400000","640.00000000"]]},"module":"linear"}
1704643996.38667: {"channel":"depth","timestamp":1704643996295,"data":{"type":"update","instrument_id":"NEAR-USDT-PERPETUAL","sequence":1702545259448564,"prev_sequence":1702545259448563,"changes":[["sell","3.36800000","0.00000000"]]},"module":"linear"}
1704643996.3866901: {"channel":"depth","timestamp":1704643996295,"data":{"type":"update","instrument_id":"NEAR-USDT-PERPETUAL","sequence":1702545259448565,"prev_sequence":1702545259448564,"changes":[["sell","3.36800000","740.00000000"]]},"module":"linear"}
1704643996.6893609: {"channel":"depth","timestamp":1704643996599,"data":{"type":"update","instrument_id":"NEAR-USDT-PERPETUAL","sequence":1702545259448566,"prev_sequence":1702545259448565,"changes":[["sell","3.35500000","0.00000000"]]},"module":"linear"}
1704643996.6894379: {"channel":"depth","timestamp":1704643996599,"data":{"type":"update","instrument_id":"NEAR-USDT-PERPETUAL","sequence":1702545259448567,"prev_sequence":1702545259448566,"changes":[["sell","3.35600000","480.00000000"]]},"module":"linear"}
1704643996.689471: {"channel":"depth","timestamp":1704643996599,"data":{"type":"update","instrument_id":"NEAR-USDT-PERPETUAL","sequence":1702545259448568,"prev_sequence":1702545259448567,"changes":[["buy","3.34600000","510.00000000"]]},"module":"linear"}
1704643996.689496: {"channel":"depth","timestamp":1704643996599,"data":{"type":"update","instrument_id":"NEAR-USDT-PERPETUAL","sequence":1702545259448569,"prev_sequence":1702545259448568,"changes":[["buy","3.34700000","530.00000000"]]},"module":"linear"}
1704643996.689518: {"channel":"depth","timestamp":1704643996599,"data":{"type":"update","instrument_id":"NEAR-USDT-PERPETUAL","sequence":1702545259448570,"prev_sequence":1702545259448569,"changes":[["sell","3.35700000","0.00000000"]]},"module":"linear"}
1704643996.689539: {"channel":"depth","timestamp":1704643996599,"data":{"type":"update","instrument_id":"NEAR-USDT-PERPETUAL","sequence":1702545259448571,"prev_sequence":1702545259448570,"changes":[["sell","3.35800000","1880.00000000"]]},"module":"linear"}
1704643996.6895602: {"channel":"depth","timestamp":1704643996599,"data":{"type":"update","instrument_id":"NEAR-USDT-PERPETUAL","sequence":1702545259448572,"prev_sequence":1702545259448571,"changes":[["buy","3.34400000","0.00000000"]]},"module":"linear"}
1704643996.68958: {"channel":"depth","timestamp":1704643996599,"data":{"type":"update","instrument_id":"NEAR-USDT-PERPETUAL","sequence":1702545259448573,"prev_sequence":1702545259448572,"changes":[["buy","3.34500000","1180.00000000"]]},"module":"linear"}
1704643996.689601: {"channel":"depth","timestamp":1704643996599,"data":{"type":"update","instrument_id":"NEAR-USDT-PERPETUAL","sequence":1702545259448574,"prev_sequence":1702545259448573,"changes":[["sell","3.35800000","1670.00000000"]]},"module":"linear"}
1704643996.68962: {"channel":"depth","timestamp":1704643996599,"data":{"type":"update","instrument_id":"NEAR-USDT-PERPETUAL","sequence":1702545259448575,"prev_sequence":1702545259448574,"changes":[["sell","3.35900000","400.00000000"]]},"module":"linear"}
1704643996.689646: {"channel":"depth","timestamp":1704643996599,"data":{"type":"update","instrument_id":"NEAR-USDT-PERPETUAL","sequence":1702545259448576,"prev_sequence":1702545259448575,"changes":[["buy","3.34300000","0.00000000"]]},"module":"linear"}
1704643996.689667: {"channel":"depth","timestamp":1704643996599,"data":{"type":"update","instrument_id":"NEAR-USDT-PERPETUAL","sequence":1702545259448577,"prev_sequence":1702545259448576,"changes":[["buy","3.34400000","190.00000000"]]},"module":"linear"}
1704643996.689686: {"channel":"depth","timestamp":1704643996599,"data":{"type":"update","instrument_id":"NEAR-USDT-PERPETUAL","sequence":1702545259448578,"prev_sequence":1702545259448577,"changes":[["sell","3.35900000","210.00000000"]]},"module":"linear"}
1704643996.689706: {"channel":"depth","timestamp":1704643996599,"data":{"type":"update","instrument_id":"NEAR-USDT-PERPETUAL","sequence":1702545259448579,"prev_sequence":1702545259448578,"changes":[["sell","3.36000000","440.00000000"]]},"module":"linear"}
1704643996.690038: {"channel":"depth","timestamp":1704643996599,"data":{"type":"update","instrument_id":"NEAR-USDT-PERPETUAL","sequence":1702545259448580,"prev_sequence":1702545259448579,"changes":[["buy","3.34200000","0.00000000"]]},"module":"linear"}
1704643996.690078: {"channel":"depth","timestamp":1704643996599,"data":{"type":"update","instrument_id":"NEAR-USDT-PERPETUAL","sequence":1702545259448581,"prev_sequence":1702545259448580,"changes":[["buy","3.34300000","210.00000000"]]},"module":"linear"}
1704643996.690102: {"channel":"depth","timestamp":1704643996599,"data":{"type":"update","instrument_id":"NEAR-USDT-PERPETUAL","sequence":1702545259448582,"prev_sequence":1702545259448581,"changes":[["sell","3.36000000","230.00000000"]]},"module":"linear"}
1704643996.696503: {"channel":"depth","timestamp":1704643996599,"data":{"type":"update","instrument_id":"NEAR-USDT-PERPETUAL","sequence":1702545259448583,"prev_sequence":1702545259448582,"changes":[["sell","3.36100000","420.00000000"]]},"module":"linear"}
1704643996.696575: {"channel":"depth","timestamp":1704643996599,"data":{"type":"update","instrument_id":"NEAR-USDT-PERPETUAL","sequence":1702545259448584,"prev_sequence":1702545259448583,"changes":[["buy","3.34100000","0.00000000"]]},"module":"linear"}
1704643996.6966069: {"channel":"depth","timestamp":1704643996599,"data":{"type":"update","instrument_id":"NEAR-USDT-PERPETUAL","sequence":1702545259448585,"prev_sequence":1702545259448584,"changes":[["buy","3.34200000","230.00000000"]]},"module":"linear"}
1704643996.6966321: {"channel":"depth","timestamp":1704643996599,"data":{"type":"update","instrument_id":"NEAR-USDT-PERPETUAL","sequence":1702545259448586,"prev_sequence":1702545259448585,"changes":[["sell","3.36100000","230.00000000"]]},"module":"linear"}
1704643996.696654: {"channel":"depth","timestamp":1704643996599,"data":{"type":"update","instrument_id":"NEAR-USDT-PERPETUAL","sequence":1702545259448587,"prev_sequence":1702545259448586,"changes":[["sell","3.36200000","430.00000000"]]},"module":"linear"}
1704643996.696674: {"channel":"depth","timestamp":1704643996599,"data":{"type":"update","instrument_id":"NEAR-USDT-PERPETUAL","sequence":1702545259448588,"prev_sequence":1702545259448587,"changes":[["buy","3.34000000","0.00000000"]]},"module":"linear"}
1704643996.696695: {"channel":"depth","timestamp":1704643996600,"data":{"type":"update","instrument_id":"NEAR-USDT-PERPETUAL","sequence":1702545259448589,"prev_sequence":1702545259448588,"changes":[["buy","3.34100000","210.00000000"]]},"module":"linear"}
1704643996.696714: {"channel":"depth","timestamp":1704643996600,"data":{"type":"update","instrument_id":"NEAR-USDT-PERPETUAL","sequence":1702545259448590,"prev_sequence":1702545259448589,"changes":[["sell","3.36200000","230.00000000"]]},"module":"linear"}
1704643996.696734: {"channel":"depth","timestamp":1704643996600,"data":{"type":"update","instrument_id":"NEAR-USDT-PERPETUAL","sequence":1702545259448591,"prev_sequence":1702545259448590,"changes":[["sell","3.36300000","210.00000000"]]},"module":"linear"}
1704643996.6967528: {"channel":"depth","timestamp":1704643996600,"data":{"type":"update","instrument_id":"NEAR-USDT-PERPETUAL","sequence":1702545259448592,"prev_sequence":1702545259448591,"changes":[["buy","3.33900000","0.00000000"]]},"module":"linear"}
1704643996.696773: {"channel":"depth","timestamp":1704643996600,"data":{"type":"update","instrument_id":"NEAR-USDT-PERPETUAL","sequence":1702545259448593,"prev_sequence":1702545259448592,"changes":[["buy","3.34000000","190.00000000"]]},"module":"linear"}
1704643996.696812: {"channel":"depth","timestamp":1704643996600,"data":{"type":"update","instrument_id":"NEAR-USDT-PERPETUAL","sequence":1702545259448594,"prev_sequence":1702545259448593,"changes":[["sell","3.36400000","0.00000000"]]},"module":"linear"}
1704643996.696832: {"channel":"depth","timestamp":1704643996600,"data":{"type":"update","instrument_id":"NEAR-USDT-PERPETUAL","sequence":1702545259448595,"prev_sequence":1702545259448594,"changes":[["sell","3.36500000","1160.00000000"]]},"module":"linear"}
1704643996.696852: {"channel":"depth","timestamp":1704643996600,"data":{"type":"update","instrument_id":"NEAR-USDT-PERPETUAL","sequence":1702545259448596,"prev_sequence":1702545259448595,"changes":[["buy","3.33700000","0.00000000"]]},"module":"linear"}
1704643996.6968708: {"channel":"depth","timestamp":1704643996600,"data":{"type":"update","instrument_id":"NEAR-USDT-PERPETUAL","sequence":1702545259448597,"prev_sequence":1702545259448596,"changes":[["buy","3.33800000","620.00000000"]]},"module":"linear"}
1704643996.69689: {"channel":"depth","timestamp":1704643996600,"data":{"type":"update","instrument_id":"NEAR-USDT-PERPETUAL","sequence":1702545259448598,"prev_sequence":1702545259448597,"changes":[["sell","3.36600000","0.00000000"]]},"module":"linear"}
1704643996.696909: {"channel":"depth","timestamp":1704643996600,"data":{"type":"update","instrument_id":"NEAR-USDT-PERPETUAL","sequence":1702545259448599,"prev_sequence":1702545259448598,"changes":[["sell","3.36700000","1150.00000000"]]},"module":"linear"}
1704643996.696929: {"channel":"depth","timestamp":1704643996600,"data":{"type":"update","instrument_id":"NEAR-USDT-PERPETUAL","sequence":1702545259448600,"prev_sequence":1702545259448599,"changes":[["buy","3.33500000","0.00000000"]]},"module":"linear"}
1704643996.696948: {"channel":"depth","timestamp":1704643996600,"data":{"type":"update","instrument_id":"NEAR-USDT-PERPETUAL","sequence":1702545259448601,"prev_sequence":1702545259448600,"changes":[["buy","3.33600000","1170.00000000"]]},"module":"linear"}
1704643996.696967: {"channel":"depth","timestamp":1704643996600,"data":{"type":"update","instrument_id":"NEAR-USDT-PERPETUAL","sequence":1702545259448602,"prev_sequence":1702545259448601,"changes":[["sell","3.36800000","0.00000000"]]},"module":"linear"}
1704643996.696985: {"channel":"depth","timestamp":1704643996600,"data":{"type":"update","instrument_id":"NEAR-USDT-PERPETUAL","sequence":1702545259448603,"prev_sequence":1702545259448602,"changes":[["sell","3.36900000","530.00000000"]]},"module":"linear"}
1704643996.697004: {"channel":"depth","timestamp":1704643996600,"data":{"type":"update","instrument_id":"NEAR-USDT-PERPETUAL","sequence":1702545259448604,"prev_sequence":1702545259448603,"changes":[["buy","3.33300000","0.00000000"]]},"module":"linear"}
1704643996.697023: {"channel":"depth","timestamp":1704643996600,"data":{"type":"update","instrument_id":"NEAR-USDT-PERPETUAL","sequence":1702545259448605,"prev_sequence":1702545259448604,"changes":[["buy","3.33400000","1190.00000000"]]},"module":"linear"}
1704643997.301876: {"channel":"depth","timestamp":1704643997048,"data":{"type":"update","instrument_id":"NEAR-USDT-PERPETUAL","sequence":1702545259448606,"prev_sequence":1702545259448605,"changes":[["sell","3.35600000","110.00000000"]]},"module":"linear"}
1704643997.301939: {"channel":"depth","timestamp":1704643997048,"data":{"type":"update","instrument_id":"NEAR-USDT-PERPETUAL","sequence":1702545259448607,"prev_sequence":1702545259448606,"changes":[["sell","3.35500000","360.00000000"]]},"module":"linear"}
1704643997.301965: {"channel":"depth","timestamp":1704643997048,"data":{"type":"update","instrument_id":"NEAR-USDT-PERPETUAL","sequence":1702545259448608,"prev_sequence":1702545259448607,"changes":[["buy","3.34700000","110.00000000"]]},"module":"linear"}
1704643997.301985: {"channel":"depth","timestamp":1704643997048,"data":{"type":"update","instrument_id":"NEAR-USDT-PERPETUAL","sequence":1702545259448609,"prev_sequence":1702545259448608,"changes":[["buy","3.34600000","920.00000000"]]},"module":"linear"}
1704643997.302002: {"channel":"depth","timestamp":1704643997048,"data":{"type":"update","instrument_id":"NEAR-USDT-PERPETUAL","sequence":1702545259448610,"prev_sequence":1702545259448609,"changes":[["sell","3.35800000","510.00000000"]]},"module":"linear"}
1704643997.30202: {"channel":"depth","timestamp":1704643997048,"data":{"type":"update","instrument_id":"NEAR-USDT-PERPETUAL","sequence":1702545259448611,"prev_sequence":1702545259448610,"changes":[["sell","3.35700000","1170.00000000"]]},"module":"linear"}
1704643997.302036: {"channel":"depth","timestamp":1704643997048,"data":{"type":"update","instrument_id":"NEAR-USDT-PERPETUAL","sequence":1702545259448612,"prev_sequence":1702545259448611,"changes":[["buy","3.34500000","0.00000000"]]},"module":"linear"}
1704643997.3020532: {"channel":"depth","timestamp":1704643997048,"data":{"type":"update","instrument_id":"NEAR-USDT-PERPETUAL","sequence":1702545259448613,"prev_sequence":1702545259448612,"changes":[["buy","3.34400000","1340.00000000"]]},"module":"linear"}
1704643997.30207: {"channel":"depth","timestamp":1704643997048,"data":{"type":"update","instrument_id":"NEAR-USDT-PERPETUAL","sequence":1702545259448614,"prev_sequence":1702545259448613,"changes":[["sell","3.35900000","0.00000000"]]},"module":"linear"}
1704643997.3020859: {"channel":"depth","timestamp":1704643997048,"data":{"type":"update","instrument_id":"NEAR-USDT-PERPETUAL","sequence":1702545259448615,"prev_sequence":1702545259448614,"changes":[["sell","3.35800000","710.00000000"]]},"module":"linear"}
1704643997.302102: {"channel":"depth","timestamp":1704643997048,"data":{"type":"update","instrument_id":"NEAR-USDT-PERPETUAL","sequence":1702545259448616,"prev_sequence":1702545259448615,"changes":[["buy","3.34400000","1150.00000000"]]},"module":"linear"}
1704643997.3021178: {"channel":"depth","timestamp":1704643997048,"data":{"type":"update","instrument_id":"NEAR-USDT-PERPETUAL","sequence":1702545259448617,"prev_sequence":1702545259448616,"changes":[["buy","3.34300000","400.00000000"]]},"module":"linear"}
1704643997.302133: {"channel":"depth","timestamp":1704643997048,"data":{"type":"update","instrument_id":"NEAR-USDT-PERPETUAL","sequence":1702545259448618,"prev_sequence":1702545259448617,"changes":[["sell","3.36000000","0.00000000"]]},"module":"linear"}
1704643997.302149: {"channel":"depth","timestamp":1704643997048,"data":{"type":"update","instrument_id":"NEAR-USDT-PERPETUAL","sequence":1702545259448619,"prev_sequence":1702545259448618,"changes":[["sell","3.35900000","190.00000000"]]},"module":"linear"}
1704643997.3021739: {"channel":"depth","timestamp":1704643997048,"data":{"type":"update","instrument_id":"NEAR-USDT-PERPETUAL","sequence":1702545259448620,"prev_sequence":1702545259448619,"changes":[["buy","3.34300000","190.00000000"]]},"module":"linear"}
1704643997.30219: {"channel":"depth","timestamp":1704643997048,"data":{"type":"update","instrument_id":"NEAR-USDT-PERPETUAL","sequence":1702545259448621,"prev_sequence":1702545259448620,"changes":[["buy","3.34200000","420.00000000"]]},"module":"linear"}
1704643997.302206: {"channel":"depth","timestamp":1704643997048,"data":{"type":"update","instrument_id":"NEAR-USDT-PERPETUAL","sequence":1702545259448622,"prev_sequence":1702545259448621,"changes":[["sell","3.36100000","0.00000000"]]},"module":"linear"}
1704643997.302221: {"channel":"depth","timestamp":1704643997048,"data":{"type":"update","instrument_id":"NEAR-USDT-PERPETUAL","sequence":1702545259448623,"prev_sequence":1702545259448622,"changes":[["sell","3.36000000","200.00000000"]]},"module":"linear"}
1704643997.3022358: {"channel":"depth","timestamp":1704643997048,"data":{"type":"update","instrument_id":"NEAR-USDT-PERPETUAL","sequence":1702545259448624,"prev_sequence":1702545259448623,"changes":[["buy","3.34200000","190.00000000"]]},"module":"linear"}
1704643997.302252: {"channel":"depth","timestamp":1704643997048,"data":{"type":"update","instrument_id":"NEAR-USDT-PERPETUAL","sequence":1702545259448625,"prev_sequence":1702545259448624,"changes":[["buy","3.34100000","410.00000000"]]},"module":"linear"}
1704643997.504266: {"channel":"depth","timestamp":1704643997350,"data":{"type":"update","instrument_id":"NEAR-USDT-PERPETUAL","sequence":1702545259448626,"prev_sequence":1702545259448625,"changes":[["sell","3.35100000","450.00000000"]]},"module":"linear"}
1704643997.75985: {"channel":"depth","timestamp":1704643997671,"data":{"type":"update","instrument_id":"NEAR-USDT-PERPETUAL","sequence":1702545259448627,"prev_sequence":1702545259448626,"changes":[["sell","3.35100000","0.00000000"]]},"module":"linear"}
1704643998.531777: {"channel":"depth","timestamp":1704643998332,"data":{"type":"update","instrument_id":"NEAR-USDT-PERPETUAL","sequence":1702545259448628,"prev_sequence":1702545259448627,"changes":[["buy","3.34600000","510.00000000"]]},"module":"linear"}
1704643998.53185: {"channel":"depth","timestamp":1704643998332,"data":{"type":"update","instrument_id":"NEAR-USDT-PERPETUAL","sequence":1702545259448629,"prev_sequence":1702545259448628,"changes":[["buy","3.34600000","900.00000000"]]},"module":"linear"}
1704643998.531882: {"channel":"depth","timestamp":1704643998332,"data":{"type":"update","instrument_id":"NEAR-USDT-PERPETUAL","sequence":1702545259448630,"prev_sequence":1702545259448629,"changes":[["sell","3.35500000","0.00000000"]]},"module":"linear"}
1704643998.531907: {"channel":"depth","timestamp":1704643998332,"data":{"type":"update","instrument_id":"NEAR-USDT-PERPETUAL","sequence":1702545259448631,"prev_sequence":1702545259448630,"changes":[["sell","3.35500000","360.00000000"]]},"module":"linear"}
1704643998.5319302: {"channel":"depth","timestamp":1704643998332,"data":{"type":"update","instrument_id":"NEAR-USDT-PERPETUAL","sequence":1702545259448632,"prev_sequence":1702545259448631,"changes":[["buy","3.34400000","0.00000000"]]},"module":"linear"}
1704643998.5319512: {"channel":"depth","timestamp":1704643998332,"data":{"type":"update","instrument_id":"NEAR-USDT-PERPETUAL","sequence":1702545259448633,"prev_sequence":1702545259448632,"changes":[["buy","3.34400000","1190.00000000"]]},"module":"linear"}
1704643998.5319722: {"channel":"depth","timestamp":1704643998332,"data":{"type":"update","instrument_id":"NEAR-USDT-PERPETUAL","sequence":1702545259448634,"prev_sequence":1702545259448633,"changes":[["sell","3.35700000","0.00000000"]]},"module":"linear"}
1704643998.531994: {"channel":"depth","timestamp":1704643998332,"data":{"type":"update","instrument_id":"NEAR-USDT-PERPETUAL","sequence":1702545259448635,"prev_sequence":1702545259448634,"changes":[["sell","3.35700000","1170.00000000"]]},"module":"linear"}
1704643998.5320141: {"channel":"depth","timestamp":1704643998332,"data":{"type":"update","instrument_id":"NEAR-USDT-PERPETUAL","sequence":1702545259448636,"prev_sequence":1702545259448635,"changes":[["buy","3.34300000","0.00000000"]]},"module":"linear"}
1704643998.5320342: {"channel":"depth","timestamp":1704643998332,"data":{"type":"update","instrument_id":"NEAR-USDT-PERPETUAL","sequence":1702545259448637,"prev_sequence":1702545259448636,"changes":[["buy","3.34300000","190.00000000"]]},"module":"linear"}
1704643998.532053: {"channel":"depth","timestamp":1704643998332,"data":{"type":"update","instrument_id":"NEAR-USDT-PERPETUAL","sequence":1702545259448638,"prev_sequence":1702545259448637,"changes":[["sell","3.35800000","510.00000000"]]},"module":"linear"}
1704643998.532073: {"channel":"depth","timestamp":1704643998332,"data":{"type":"update","instrument_id":"NEAR-USDT-PERPETUAL","sequence":1702545259448639,"prev_sequence":1702545259448638,"changes":[["sell","3.35800000","700.00000000"]]},"module":"linear"}
1704643998.5320919: {"channel":"depth","timestamp":1704643998332,"data":{"type":"update","instrument_id":"NEAR-USDT-PERPETUAL","sequence":1702545259448640,"prev_sequence":1702545259448639,"changes":[["buy","3.34100000","200.00000000"]]},"module":"linear"}
1704643998.5321112: {"channel":"depth","timestamp":1704643998332,"data":{"type":"update","instrument_id":"NEAR-USDT-PERPETUAL","sequence":1702545259448641,"prev_sequence":1702545259448640,"changes":[["buy","3.34000000","400.00000000"]]},"module":"linear"}
1704643998.532131: {"channel":"depth","timestamp":1704643998332,"data":{"type":"update","instrument_id":"NEAR-USDT-PERPETUAL","sequence":1702545259448642,"prev_sequence":1702545259448641,"changes":[["sell","3.35900000","0.00000000"]]},"module":"linear"}
1704643998.53215: {"channel":"depth","timestamp":1704643998332,"data":{"type":"update","instrument_id":"NEAR-USDT-PERPETUAL","sequence":1702545259448643,"prev_sequence":1702545259448642,"changes":[["sell","3.35900000","190.00000000"]]},"module":"linear"}
1704643998.53217: {"channel":"depth","timestamp":1704643998332,"data":{"type":"update","instrument_id":"NEAR-USDT-PERPETUAL","sequence":1702545259448644,"prev_sequence":1702545259448643,"changes":[["buy","3.33600000","0.00000000"]]},"module":"linear"}
1704643998.532189: {"channel":"depth","timestamp":1704643998332,"data":{"type":"update","instrument_id":"NEAR-USDT-PERPETUAL","sequence":1702545259448645,"prev_sequence":1702545259448644,"changes":[["buy","3.33500000","1150.00000000"]]},"module":"linear"}
1704643998.5322082: {"channel":"depth","timestamp":1704643998332,"data":{"type":"update","instrument_id":"NEAR-USDT-PERPETUAL","sequence":1702545259448646,"prev_sequence":1702545259448645,"changes":[["sell","3.36200000","0.00000000"]]},"module":"linear"}
1704643998.532227: {"channel":"depth","timestamp":1704643998332,"data":{"type":"update","instrument_id":"NEAR-USDT-PERPETUAL","sequence":1702545259448647,"prev_sequence":1702545259448646,"changes":[["sell","3.36100000","210.00000000"]]},"module":"linear"}
1704644000.035867: {"channel":"depth","timestamp":1704643999945,"data":{"type":"update","instrument_id":"NEAR-USDT-PERPETUAL","sequence":1702545259448648,"prev_sequence":1702545259448647,"changes":[["sell","3.35900000","0.00000000"]]},"module":"linear"}
1704644000.0359418: {"channel":"depth","timestamp":1704643999945,"data":{"type":"update","instrument_id":"NEAR-USDT-PERPETUAL","sequence":1702545259448649,"prev_sequence":1702545259448648,"changes":[["sell","3.35900000","190.00000000"]]},"module":"linear"}
1704644000.0359738: {"channel":"depth","timestamp":1704643999945,"data":{"type":"update","instrument_id":"NEAR-USDT-PERPETUAL","sequence":1702545259448650,"prev_sequence":1702545259448649,"changes":[["buy","3.34400000","0.00000000"]]},"module":"linear"}
1704644000.036015: {"channel":"depth","timestamp":1704643999945,"data":{"type":"update","instrument_id":"NEAR-USDT-PERPETUAL","sequence":1702545259448651,"prev_sequence":1702545259448650,"changes":[["buy","3.34400000","1170.00000000"]]},"module":"linear"}
1704644000.0360389: {"channel":"depth","timestamp":1704643999945,"data":{"type":"update","instrument_id":"NEAR-USDT-PERPETUAL","sequence":1702545259448652,"prev_sequence":1702545259448651,"changes":[["sell","3.36000000","0.00000000"]]},"module":"linear"}
1704644000.0360599: {"channel":"depth","timestamp":1704643999945,"data":{"type":"update","instrument_id":"NEAR-USDT-PERPETUAL","sequence":1702545259448653,"prev_sequence":1702545259448652,"changes":[["sell","3.36000000","190.00000000"]]},"module":"linear"}
1704644000.0360801: {"channel":"depth","timestamp":1704643999945,"data":{"type":"update","instrument_id":"NEAR-USDT-PERPETUAL","sequence":1702545259448654,"prev_sequence":1702545259448653,"changes":[["buy","3.34200000","0.00000000"]]},"module":"linear"}
1704644000.0361001: {"channel":"depth","timestamp":1704643999946,"data":{"type":"update","instrument_id":"NEAR-USDT-PERPETUAL","sequence":1702545259448655,"prev_sequence":1702545259448654,"changes":[["buy","3.34200000","190.00000000"]]},"module":"linear"}
1704644000.0361202: {"channel":"depth","timestamp":1704643999946,"data":{"type":"update","instrument_id":"NEAR-USDT-PERPETUAL","sequence":1702545259448656,"prev_sequence":1702545259448655,"changes":[["sell","3.36500000","0.00000000"]]},"module":"linear"}
1704644000.036139: {"channel":"depth","timestamp":1704643999946,"data":{"type":"update","instrument_id":"NEAR-USDT-PERPETUAL","sequence":1702545259448657,"prev_sequence":1702545259448656,"changes":[["sell","3.36400000","640.00000000"]]},"module":"linear"}
1704644000.036159: {"channel":"depth","timestamp":1704643999946,"data":{"type":"update","instrument_id":"NEAR-USDT-PERPETUAL","sequence":1702545259448658,"prev_sequence":1702545259448657,"changes":[["buy","3.34000000","190.00000000"]]},"module":"linear"}
1704644000.0361779: {"channel":"depth","timestamp":1704643999946,"data":{"type":"update","instrument_id":"NEAR-USDT-PERPETUAL","sequence":1702545259448659,"prev_sequence":1702545259448658,"changes":[["buy","3.34000000","380.00000000"]]},"module":"linear"}
1704644000.036198: {"channel":"depth","timestamp":1704643999946,"data":{"type":"update","instrument_id":"NEAR-USDT-PERPETUAL","sequence":1702545259448660,"prev_sequence":1702545259448659,"changes":[["sell","3.36700000","0.00000000"]]},"module":"linear"}
1704644000.036217: {"channel":"depth","timestamp":1704643999946,"data":{"type":"update","instrument_id":"NEAR-USDT-PERPETUAL","sequence":1702545259448661,"prev_sequence":1702545259448660,"changes":[["sell","3.36600000","1150.00000000"]]},"module":"linear"}
1704644000.036242: {"channel":"depth","timestamp":1704643999946,"data":{"type":"update","instrument_id":"NEAR-USDT-PERPETUAL","sequence":1702545259448662,"prev_sequence":1702545259448661,"changes":[["buy","3.34000000","190.00000000"]]},"module":"linear"}
1704644000.036261: {"channel":"depth","timestamp":1704643999946,"data":{"type":"update","instrument_id":"NEAR-USDT-PERPETUAL","sequence":1702545259448663,"prev_sequence":1702545259448662,"changes":[["buy","3.33900000","210.00000000"]]},"module":"linear"}
1704644000.036279: {"channel":"depth","timestamp":1704643999946,"data":{"type":"update","instrument_id":"NEAR-USDT-PERPETUAL","sequence":1702545259448664,"prev_sequence":1702545259448663,"changes":[["sell","3.36900000","0.00000000"]]},"module":"linear"}
1704644000.036298: {"channel":"depth","timestamp":1704643999946,"data":{"type":"update","instrument_id":"NEAR-USDT-PERPETUAL","sequence":1702545259448665,"prev_sequence":1702545259448664,"changes":[["sell","3.36800000","580.00000000"]]},"module":"linear"}
1704644000.036322: {"channel":"depth","timestamp":1704643999946,"data":{"type":"update","instrument_id":"NEAR-USDT-PERPETUAL","sequence":1702545259448666,"prev_sequence":1702545259448665,"changes":[["buy","3.33400000","0.00000000"]]},"module":"linear"}
1704644000.036341: {"channel":"depth","timestamp":1704643999946,"data":{"type":"update","instrument_id":"NEAR-USDT-PERPETUAL","sequence":1702545259448667,"prev_sequence":1702545259448666,"changes":[["buy","3.33300000","1130.00000000"]]},"module":"linear"}
1704644001.208947: {"channel":"depth","timestamp":1704644001117,"data":{"type":"update","instrument_id":"NEAR-USDT-PERPETUAL","sequence":1702545259448668,"prev_sequence":1702545259448667,"changes":[["sell","3.35500000","0.00000000"]]},"module":"linear"}
1704644001.209022: {"channel":"depth","timestamp":1704644001117,"data":{"type":"update","instrument_id":"NEAR-USDT-PERPETUAL","sequence":1702545259448669,"prev_sequence":1702545259448668,"changes":[["sell","3.35600000","480.00000000"]]},"module":"linear"}
1704644001.209055: {"channel":"depth","timestamp":1704644001117,"data":{"type":"update","instrument_id":"NEAR-USDT-PERPETUAL","sequence":1702545259448670,"prev_sequence":1702545259448669,"changes":[["buy","3.34600000","510.00000000"]]},"module":"linear"}
1704644001.20908: {"channel":"depth","timestamp":1704644001117,"data":{"type":"update","instrument_id":"NEAR-USDT-PERPETUAL","sequence":1702545259448671,"prev_sequence":1702545259448670,"changes":[["buy","3.34700000","530.00000000"]]},"module":"linear"}
1704644001.2091022: {"channel":"depth","timestamp":1704644001117,"data":{"type":"update","instrument_id":"NEAR-USDT-PERPETUAL","sequence":1702545259448672,"prev_sequence":1702545259448671,"changes":[["sell","3.35700000","0.00000000"]]},"module":"linear"}
1704644001.2091389: {"channel":"depth","timestamp":1704644001117,"data":{"type":"update","instrument_id":"NEAR-USDT-PERPETUAL","sequence":1702545259448673,"prev_sequence":1702545259448672,"changes":[["sell","3.35800000","1850.00000000"]]},"module":"linear"}
1704644001.2091599: {"channel":"depth","timestamp":1704644001117,"data":{"type":"update","instrument_id":"NEAR-USDT-PERPETUAL","sequence":1702545259448674,"prev_sequence":1702545259448673,"changes":[["buy","3.34400000","0.00000000"]]},"module":"linear"}
1704644001.2091892: {"channel":"depth","timestamp":1704644001117,"data":{"type":"update","instrument_id":"NEAR-USDT-PERPETUAL","sequence":1702545259448675,"prev_sequence":1702545259448674,"changes":[["buy","3.34500000","1160.00000000"]]},"module":"linear"}
1704644001.2092102: {"channel":"depth","timestamp":1704644001117,"data":{"type":"update","instrument_id":"NEAR-USDT-PERPETUAL","sequence":1702545259448676,"prev_sequence":1702545259448675,"changes":[["sell","3.35800000","1660.00000000"]]},"module":"linear"}
1704644001.2092302: {"channel":"depth","timestamp":1704644001117,"data":{"type":"update","instrument_id":"NEAR-USDT-PERPETUAL","sequence":1702545259448677,"prev_sequence":1702545259448676,"changes":[["sell","3.35900000","390.00000000"]]},"module":"linear"}
1704644001.20925: {"channel":"depth","timestamp":1704644001117,"data":{"type":"update","instrument_id":"NEAR-USDT-PERPETUAL","sequence":1702545259448678,"prev_sequence":1702545259448677,"changes":[["buy","3.34300000","0.00000000"]]},"module":"linear"}
1704644001.209269: {"channel":"depth","timestamp":1704644001117,"data":{"type":"update","instrument_id":"NEAR-USDT-PERPETUAL","sequence":1702545259448679,"prev_sequence":1702545259448678,"changes":[["buy","3.34400000","190.00000000"]]},"module":"linear"}
1704644001.209288: {"channel":"depth","timestamp":1704644001117,"data":{"type":"update","instrument_id":"NEAR-USDT-PERPETUAL","sequence":1702545259448680,"prev_sequence":1702545259448679,"changes":[["sell","3.35900000","200.00000000"]]},"module":"linear"}
1704644001.209307: {"channel":"depth","timestamp":1704644001117,"data":{"type":"update","instrument_id":"NEAR-USDT-PERPETUAL","sequence":1702545259448681,"prev_sequence":1702545259448680,"changes":[["sell","3.36000000","380.00000000"]]},"module":"linear"}
1704644001.209326: {"channel":"depth","timestamp":1704644001117,"data":{"type":"update","instrument_id":"NEAR-USDT-PERPETUAL","sequence":1702545259448682,"prev_sequence":1702545259448681,"changes":[["buy","3.34200000","0.00000000"]]},"module":"linear"}
1704644001.209345: {"channel":"depth","timestamp":1704644001117,"data":{"type":"update","instrument_id":"NEAR-USDT-PERPETUAL","sequence":1702545259448683,"prev_sequence":1702545259448682,"changes":[["buy","3.34300000","230.00000000"]]},"module":"linear"}
1704644001.209363: {"channel":"depth","timestamp":1704644001117,"data":{"type":"update","instrument_id":"NEAR-USDT-PERPETUAL","sequence":1702545259448684,"prev_sequence":1702545259448683,"changes":[["sell","3.36000000","190.00000000"]]},"module":"linear"}
1704644001.2093818: {"channel":"depth","timestamp":1704644001117,"data":{"type":"update","instrument_id":"NEAR-USDT-PERPETUAL","sequence":1702545259448685,"prev_sequence":1702545259448684,"changes":[["sell","3.36100000","420.00000000"]]},"module":"linear"}
1704644001.2094011: {"channel":"depth","timestamp":1704644001117,"data":{"type":"update","instrument_id":"NEAR-USDT-PERPETUAL","sequence":1702545259448686,"prev_sequence":1702545259448685,"changes":[["buy","3.34100000","0.00000000"]]},"module":"linear"}
1704644001.20942: {"channel":"depth","timestamp":1704644001117,"data":{"type":"update","instrument_id":"NEAR-USDT-PERPETUAL","sequence":1702545259448687,"prev_sequence":1702545259448686,"changes":[["buy","3.34200000","210.00000000"]]},"module":"linear"}
1704644001.52355: {"channel":"depth","timestamp":1704644001433,"data":{"type":"update","instrument_id":"NEAR-USDT-PERPETUAL","sequence":1702545259448688,"prev_sequence":1702545259448687,"changes":[["sell","3.36100000","210.00000000"]]},"module":"linear"}
1704644001.523659: {"channel":"depth","timestamp":1704644001433,"data":{"type":"update","instrument_id":"NEAR-USDT-PERPETUAL","sequence":1702545259448689,"prev_sequence":1702545259448688,"changes":[["sell","3.36200000","200.00000000"]]},"module":"linear"}
1704644001.523722: {"channel":"depth","timestamp":1704644001433,"data":{"type":"update","instrument_id":"NEAR-USDT-PERPETUAL","sequence":1702545259448690,"prev_sequence":1702545259448689,"changes":[["buy","3.34000000","0.00000000"]]},"module":"linear"}
1704644001.523793: {"channel":"depth","timestamp":1704644001433,"data":{"type":"update","instrument_id":"NEAR-USDT-PERPETUAL","sequence":1702545259448691,"prev_sequence":1702545259448690,"changes":[["buy","3.34100000","190.00000000"]]},"module":"linear"}
1704644001.523842: {"channel":"depth","timestamp":1704644001433,"data":{"type":"update","instrument_id":"NEAR-USDT-PERPETUAL","sequence":1702545259448692,"prev_sequence":1702545259448691,"changes":[["sell","3.36300000","0.00000000"]]},"module":"linear"}
1704644001.523864: {"channel":"depth","timestamp":1704644001433,"data":{"type":"update","instrument_id":"NEAR-USDT-PERPETUAL","sequence":1702545259448693,"prev_sequence":1702545259448692,"changes":[["sell","3.36300000","200.00000000"]]},"module":"linear"}
1704644001.524405: {"channel":"depth","timestamp":1704644001433,"data":{"type":"update","instrument_id":"NEAR-USDT-PERPETUAL","sequence":1702545259448694,"prev_sequence":1702545259448693,"changes":[["buy","3.33900000","0.00000000"]]},"module":"linear"}
1704644001.524448: {"channel":"depth","timestamp":1704644001433,"data":{"type":"update","instrument_id":"NEAR-USDT-PERPETUAL","sequence":1702545259448695,"prev_sequence":1702545259448694,"changes":[["buy","3.34000000","200.00000000"]]},"module":"linear"}
1704644001.5244741: {"channel":"depth","timestamp":1704644001433,"data":{"type":"update","instrument_id":"NEAR-USDT-PERPETUAL","sequence":1702545259448696,"prev_sequence":1702545259448695,"changes":[["sell","3.36400000","0.00000000"]]},"module":"linear"}
1704644001.5244968: {"channel":"depth","timestamp":1704644001433,"data":{"type":"update","instrument_id":"NEAR-USDT-PERPETUAL","sequence":1702545259448697,"prev_sequence":1702545259448696,"changes":[["sell","3.36500000","1180.00000000"]]},"module":"linear"}
1704644001.524522: {"channel":"depth","timestamp":1704644001433,"data":{"type":"update","instrument_id":"NEAR-USDT-PERPETUAL","sequence":1702545259448698,"prev_sequence":1702545259448697,"changes":[["buy","3.33800000","0.00000000"]]},"module":"linear"}
1704644001.5245419: {"channel":"depth","timestamp":1704644001433,"data":{"type":"update","instrument_id":"NEAR-USDT-PERPETUAL","sequence":1702545259448699,"prev_sequence":1702545259448698,"changes":[["buy","3.33800000","620.00000000"]]},"module":"linear"}
1704644001.5245628: {"channel":"depth","timestamp":1704644001433,"data":{"type":"update","instrument_id":"NEAR-USDT-PERPETUAL","sequence":1702545259448700,"prev_sequence":1702545259448699,"changes":[["sell","3.36600000","0.00000000"]]},"module":"linear"}
1704644001.5245829: {"channel":"depth","timestamp":1704644001434,"data":{"type":"update","instrument_id":"NEAR-USDT-PERPETUAL","sequence":1702545259448701,"prev_sequence":1702545259448700,"changes":[["sell","3.36700000","1050.00000000"]]},"module":"linear"}
1704644001.5246022: {"channel":"depth","timestamp":1704644001434,"data":{"type":"update","instrument_id":"NEAR-USDT-PERPETUAL","sequence":1702545259448702,"prev_sequence":1702545259448701,"changes":[["buy","3.33500000","0.00000000"]]},"module":"linear"}
1704644001.5246232: {"channel":"depth","timestamp":1704644001434,"data":{"type":"update","instrument_id":"NEAR-USDT-PERPETUAL","sequence":1702545259448703,"prev_sequence":1702545259448702,"changes":[["buy","3.33600000","1150.00000000"]]},"module":"linear"}
1704644001.524642: {"channel":"depth","timestamp":1704644001434,"data":{"type":"update","instrument_id":"NEAR-USDT-PERPETUAL","sequence":1702545259448704,"prev_sequence":1702545259448703,"changes":[["sell","3.36800000","0.00000000"]]},"module":"linear"}
1704644001.524661: {"channel":"depth","timestamp":1704644001434,"data":{"type":"update","instrument_id":"NEAR-USDT-PERPETUAL","sequence":1702545259448705,"prev_sequence":1702545259448704,"changes":[["sell","3.36900000","530.00000000"]]},"module":"linear"}
1704644001.52468: {"channel":"depth","timestamp":1704644001434,"data":{"type":"update","instrument_id":"NEAR-USDT-PERPETUAL","sequence":1702545259448706,"prev_sequence":1702545259448705,"changes":[["buy","3.33300000","0.00000000"]]},"module":"linear"}
1704644001.524714: {"channel":"depth","timestamp":1704644001434,"data":{"type":"update","instrument_id":"NEAR-USDT-PERPETUAL","sequence":1702545259448707,"prev_sequence":1702545259448706,"changes":[["buy","3.33400000","1180.00000000"]]},"module":"linear"}
1704644002.710259: {"channel":"depth","timestamp":1704644002620,"data":{"type":"update","instrument_id":"NEAR-USDT-PERPETUAL","sequence":1702545259448708,"prev_sequence":1702545259448707,"changes":[["sell","3.35800000","510.00000000"]]},"module":"linear"}
1704644002.710369: {"channel":"depth","timestamp":1704644002620,"data":{"type":"update","instrument_id":"NEAR-USDT-PERPETUAL","sequence":1702545259448709,"prev_sequence":1702545259448708,"changes":[["sell","3.35800000","1660.00000000"]]},"module":"linear"}
1704644002.710418: {"channel":"depth","timestamp":1704644002620,"data":{"type":"update","instrument_id":"NEAR-USDT-PERPETUAL","sequence":1702545259448710,"prev_sequence":1702545259448709,"changes":[["buy","3.34700000","110.00000000"]]},"module":"linear"}
1704644002.710457: {"channel":"depth","timestamp":1704644002620,"data":{"type":"update","instrument_id":"NEAR-USDT-PERPETUAL","sequence":1702545259448711,"prev_sequence":1702545259448710,"changes":[["buy","3.34700000","500.00000000"]]},"module":"linear"}
1704644002.710491: {"channel":"depth","timestamp":1704644002620,"data":{"type":"update","instrument_id":"NEAR-USDT-PERPETUAL","sequence":1702545259448712,"prev_sequence":1702545259448711,"changes":[["sell","3.36000000","0.00000000"]]},"module":"linear"}
1704644002.710551: {"channel":"depth","timestamp":1704644002620,"data":{"type":"update","instrument_id":"NEAR-USDT-PERPETUAL","sequence":1702545259448713,"prev_sequence":1702545259448712,"changes":[["sell","3.36000000","190.00000000"]]},"module":"linear"}
1704644002.7207072: {"channel":"depth","timestamp":1704644002621,"data":{"type":"update","instrument_id":"NEAR-USDT-PERPETUAL","sequence":1702545259448714,"prev_sequence":1702545259448713,"changes":[["buy","3.34500000","0.00000000"]]},"module":"linear"}
1704644002.7208178: {"channel":"depth","timestamp":1704644002621,"data":{"type":"update","instrument_id":"NEAR-USDT-PERPETUAL","sequence":1702545259448715,"prev_sequence":1702545259448714,"changes":[["buy","3.34500000","1170.00000000"]]},"module":"linear"}
1704644002.720866: {"channel":"depth","timestamp":1704644002621,"data":{"type":"update","instrument_id":"NEAR-USDT-PERPETUAL","sequence":1702545259448716,"prev_sequence":1702545259448715,"changes":[["sell","3.36200000","0.00000000"]]},"module":"linear"}
1704644002.720903: {"channel":"depth","timestamp":1704644002621,"data":{"type":"update","instrument_id":"NEAR-USDT-PERPETUAL","sequence":1702545259448717,"prev_sequence":1702545259448716,"changes":[["sell","3.36200000","190.00000000"]]},"module":"linear"}
1704644002.720962: {"channel":"depth","timestamp":1704644002621,"data":{"type":"update","instrument_id":"NEAR-USDT-PERPETUAL","sequence":1702545259448718,"prev_sequence":1702545259448717,"changes":[["buy","3.34300000","0.00000000"]]},"module":"linear"}
1704644002.7209952: {"channel":"depth","timestamp":1704644002621,"data":{"type":"update","instrument_id":"NEAR-USDT-PERPETUAL","sequence":1702545259448719,"prev_sequence":1702545259448718,"changes":[["buy","3.34300000","190.00000000"]]},"module":"linear"}
1704644002.721026: {"channel":"depth","timestamp":1704644002621,"data":{"type":"update","instrument_id":"NEAR-USDT-PERPETUAL","sequence":1702545259448720,"prev_sequence":1702545259448719,"changes":[["sell","3.36500000","0.00000000"]]},"module":"linear"}
1704644002.7210581: {"channel":"depth","timestamp":1704644002621,"data":{"type":"update","instrument_id":"NEAR-USDT-PERPETUAL","sequence":1702545259448721,"prev_sequence":1702545259448720,"changes":[["sell","3.36500000","1160.00000000"]]},"module":"linear"}
1704644002.721096: {"channel":"depth","timestamp":1704644002621,"data":{"type":"update","instrument_id":"NEAR-USDT-PERPETUAL","sequence":1702545259448722,"prev_sequence":1702545259448721,"changes":[["buy","3.34100000","0.00000000"]]},"module":"linear"}
1704644002.721129: {"channel":"depth","timestamp":1704644002621,"data":{"type":"update","instrument_id":"NEAR-USDT-PERPETUAL","sequence":1702545259448723,"prev_sequence":1702545259448722,"changes":[["buy","3.34100000","190.00000000"]]},"module":"linear"}
1704644002.72116: {"channel":"depth","timestamp":1704644002621,"data":{"type":"update","instrument_id":"NEAR-USDT-PERPETUAL","sequence":1702545259448724,"prev_sequence":1702545259448723,"changes":[["sell","3.36700000","0.00000000"]]},"module":"linear"}
1704644002.72119: {"channel":"depth","timestamp":1704644002621,"data":{"type":"update","instrument_id":"NEAR-USDT-PERPETUAL","sequence":1702545259448725,"prev_sequence":1702545259448724,"changes":[["sell","3.36700000","970.00000000"]]},"module":"linear"}
1704644002.721787: {"channel":"depth","timestamp":1704644002621,"data":{"type":"update","instrument_id":"NEAR-USDT-PERPETUAL","sequence":1702545259448726,"prev_sequence":1702545259448725,"changes":[["buy","3.33800000","0.00000000"]]},"module":"linear"}
1704644002.721828: {"channel":"depth","timestamp":1704644002621,"data":{"type":"update","instrument_id":"NEAR-USDT-PERPETUAL","sequence":1702545259448727,"prev_sequence":1702545259448726,"changes":[["buy","3.33800000","620.00000000"]]},"module":"linear"}
1704644003.241429: {"channel":"depth","timestamp":1704644003086,"data":{"type":"update","instrument_id":"NEAR-USDT-PERPETUAL","sequence":1702545259448728,"prev_sequence":1702545259448727,"changes":[["sell","3.35600000","110.00000000"]]},"module":"linear"}
1704644003.2415402: {"channel":"depth","timestamp":1704644003086,"data":{"type":"update","instrument_id":"NEAR-USDT-PERPETUAL","sequence":1702545259448729,"prev_sequence":1702545259448728,"changes":[["sell","3.35500000","360.00000000"]]},"module":"linear"}
1704644003.2415879: {"channel":"depth","timestamp":1704644003087,"data":{"type":"update","instrument_id":"NEAR-USDT-PERPETUAL","sequence":1702545259448730,"prev_sequence":1702545259448729,"changes":[["buy","3.34700000","110.00000000"]]},"module":"linear"}
1704644003.241624: {"channel":"depth","timestamp":1704644003087,"data":{"type":"update","instrument_id":"NEAR-USDT-PERPETUAL","sequence":1702545259448731,"prev_sequence":1702545259448730,"changes":[["buy","3.34600000","900.00000000"]]},"module":"linear"}
1704644003.242613: {"channel":"depth","timestamp":1704644003087,"data":{"type":"update","instrument_id":"NEAR-USDT-PERPETUAL","sequence":1702545259448732,"prev_sequence":1702545259448731,"changes":[["sell","3.35800000","510.00000000"]]},"module":"linear"}
1704644003.242657: {"channel":"depth","timestamp":1704644003087,"data":{"type":"update","instrument_id":"NEAR-USDT-PERPETUAL","sequence":1702545259448733,"prev_sequence":1702545259448732,"changes":[["sell","3.35700000","1190.00000000"]]},"module":"linear"}
1704644003.242696: {"channel":"depth","timestamp":1704644003087,"data":{"type":"update","instrument_id":"NEAR-USDT-PERPETUAL","sequence":1702545259448734,"prev_sequence":1702545259448733,"changes":[["buy","3.34500000","0.00000000"]]},"module":"linear"}
1704644003.2427258: {"channel":"depth","timestamp":1704644003087,"data":{"type":"update","instrument_id":"NEAR-USDT-PERPETUAL","sequence":1702545259448735,"prev_sequence":1702545259448734,"changes":[["buy","3.34400000","1370.00000000"]]},"module":"linear"}
1704644003.242748: {"channel":"depth","timestamp":1704644003087,"data":{"type":"update","instrument_id":"NEAR-USDT-PERPETUAL","sequence":1702545259448736,"prev_sequence":1702545259448735,"changes":[["sell","3.35900000","0.00000000"]]},"module":"linear"}
1704644003.242769: {"channel":"depth","timestamp":1704644003087,"data":{"type":"update","instrument_id":"NEAR-USDT-PERPETUAL","sequence":1702545259448737,"prev_sequence":1702545259448736,"changes":[["sell","3.35800000","700.00000000"]]},"module":"linear"}
1704644003.242789: {"channel":"depth","timestamp":1704644003087,"data":{"type":"update","instrument_id":"NEAR-USDT-PERPETUAL","sequence":1702545259448738,"prev_sequence":1702545259448737,"changes":[["buy","3.34400000","1180.00000000"]]},"module":"linear"}
1704644003.242808: {"channel":"depth","timestamp":1704644003087,"data":{"type":"update","instrument_id":"NEAR-USDT-PERPETUAL","sequence":1702545259448739,"prev_sequence":1702545259448738,"changes":[["buy","3.34300000","420.00000000"]]},"module":"linear"}
1704644003.242827: {"channel":"depth","timestamp":1704644003087,"data":{"type":"update","instrument_id":"NEAR-USDT-PERPETUAL","sequence":1702545259448740,"prev_sequence":1702545259448739,"changes":[["sell","3.36000000","0.00000000"]]},"module":"linear"}
1704644003.242846: {"channel":"depth","timestamp":1704644003087,"data":{"type":"update","instrument_id":"NEAR-USDT-PERPETUAL","sequence":1702545259448741,"prev_sequence":1702545259448740,"changes":[["sell","3.35900000","230.00000000"]]},"module":"linear"}
1704644003.2428648: {"channel":"depth","timestamp":1704644003087,"data":{"type":"update","instrument_id":"NEAR-USDT-PERPETUAL","sequence":1702545259448742,"prev_sequence":1702545259448741,"changes":[["buy","3.34300000","230.00000000"]]},"module":"linear"}
1704644003.2428842: {"channel":"depth","timestamp":1704644003087,"data":{"type":"update","instrument_id":"NEAR-USDT-PERPETUAL","sequence":1702545259448743,"prev_sequence":1702545259448742,"changes":[["buy","3.34200000","440.00000000"]]},"module":"linear"}
1704644003.242903: {"channel":"depth","timestamp":1704644003087,"data":{"type":"update","instrument_id":"NEAR-USDT-PERPETUAL","sequence":1702545259448744,"prev_sequence":1702545259448743,"changes":[["sell","3.36100000","0.00000000"]]},"module":"linear"}
1704644003.242922: {"channel":"depth","timestamp":1704644003087,"data":{"type":"update","instrument_id":"NEAR-USDT-PERPETUAL","sequence":1702545259448745,"prev_sequence":1702545259448744,"changes":[["sell","3.36000000","230.00000000"]]},"module":"linear"}
1704644003.24294: {"channel":"depth","timestamp":1704644003087,"data":{"type":"update","instrument_id":"NEAR-USDT-PERPETUAL","sequence":1702545259448746,"prev_sequence":1702545259448745,"changes":[["buy","3.34200000","230.00000000"]]},"module":"linear"}
1704644003.242959: {"channel":"depth","timestamp":1704644003087,"data":{"type":"update","instrument_id":"NEAR-USDT-PERPETUAL","sequence":1702545259448747,"prev_sequence":1702545259448746,"changes":[["buy","3.34100000","410.00000000"]]},"module":"linear"}
1704644004.5732539: {"channel":"depth","timestamp":1704644004466,"data":{"type":"update","instrument_id":"NEAR-USDT-PERPETUAL","sequence":1702545259448748,"prev_sequence":1702545259448747,"changes":[["sell","3.35700000","0.00000000"]]},"module":"linear"}
1704644004.5733: {"channel":"depth","timestamp":1704644004466,"data":{"type":"update","instrument_id":"NEAR-USDT-PERPETUAL","sequence":1702545259448749,"prev_sequence":1702545259448748,"changes":[["sell","3.35700000","1190.00000000"]]},"module":"linear"}
1704644004.573329: {"channel":"depth","timestamp":1704644004466,"data":{"type":"update","instrument_id":"NEAR-USDT-PERPETUAL","sequence":1702545259448750,"prev_sequence":1702545259448749,"changes":[["buy","3.34400000","0.00000000"]]},"module":"linear"}
1704644004.5733519: {"channel":"depth","timestamp":1704644004466,"data":{"type":"update","instrument_id":"NEAR-USDT-PERPETUAL","sequence":1702545259448751,"prev_sequence":1702545259448750,"changes":[["buy","3.34400000","1170.00000000"]]},"module":"linear"}
1704644004.5733728: {"channel":"depth","timestamp":1704644004466,"data":{"type":"update","instrument_id":"NEAR-USDT-PERPETUAL","sequence":1702545259448752,"prev_sequence":1702545259448751,"changes":[["sell","3.35900000","0.00000000"]]},"module":"linear"}
1704644004.5733929: {"channel":"depth","timestamp":1704644004466,"data":{"type":"update","instrument_id":"NEAR-USDT-PERPETUAL","sequence":1702545259448753,"prev_sequence":1702545259448752,"changes":[["sell","3.35900000","190.00000000"]]},"module":"linear"}
1704644004.5734138: {"channel":"depth","timestamp":1704644004466,"data":{"type":"update","instrument_id":"NEAR-USDT-PERPETUAL","sequence":1702545259448754,"prev_sequence":1702545259448753,"changes":[["buy","3.34300000","0.00000000"]]},"module":"linear"}
1704644004.573434: {"channel":"depth","timestamp":1704644004466,"data":{"type":"update","instrument_id":"NEAR-USDT-PERPETUAL","sequence":1702545259448755,"prev_sequence":1702545259448754,"changes":[["buy","3.34300000","210.00000000"]]},"module":"linear"}
1704644004.573453: {"channel":"depth","timestamp":1704644004466,"data":{"type":"update","instrument_id":"NEAR-USDT-PERPETUAL","sequence":1702545259448756,"prev_sequence":1702545259448755,"changes":[["sell","3.36000000","0.00000000"]]},"module":"linear"}
1704644004.573472: {"channel":"depth","timestamp":1704644004466,"data":{"type":"update","instrument_id":"NEAR-USDT-PERPETUAL","sequence":1702545259448757,"prev_sequence":1702545259448756,"changes":[["sell","3.36000000","220.00000000"]]},"module":"linear"}
1704644004.573492: {"channel":"depth","timestamp":1704644004466,"data":{"type":"update","instrument_id":"NEAR-USDT-PERPETUAL","sequence":1702545259448758,"prev_sequence":1702545259448757,"changes":[["buy","3.34200000","0.00000000"]]},"module":"linear"}
1704644004.573514: {"channel":"depth","timestamp":1704644004466,"data":{"type":"update","instrument_id":"NEAR-USDT-PERPETUAL","sequence":1702545259448759,"prev_sequence":1702545259448758,"changes":[["buy","3.34200000","220.00000000"]]},"module":"linear"}
1704644004.573549: {"channel":"depth","timestamp":1704644004466,"data":{"type":"update","instrument_id":"NEAR-USDT-PERPETUAL","sequence":1702545259448760,"prev_sequence":1702545259448759,"changes":[["sell","3.36300000","0.00000000"]]},"module":"linear"}
1704644004.57357: {"channel":"depth","timestamp":1704644004466,"data":{"type":"update","instrument_id":"NEAR-USDT-PERPETUAL","sequence":1702545259448761,"prev_sequence":1702545259448760,"changes":[["sell","3.36200000","410.00000000"]]},"module":"linear"}
1704644004.57359: {"channel":"depth","timestamp":1704644004466,"data":{"type":"update","instrument_id":"NEAR-USDT-PERPETUAL","sequence":1702545259448762,"prev_sequence":1702545259448761,"changes":[["buy","3.34100000","190.00000000"]]},"module":"linear"}
1704644004.573616: {"channel":"depth","timestamp":1704644004466,"data":{"type":"update","instrument_id":"NEAR-USDT-PERPETUAL","sequence":1702545259448763,"prev_sequence":1702545259448762,"changes":[["buy","3.34100000","390.00000000"]]},"module":"linear"}
1704644004.573636: {"channel":"depth","timestamp":1704644004466,"data":{"type":"update","instrument_id":"NEAR-USDT-PERPETUAL","sequence":1702545259448764,"prev_sequence":1702545259448763,"changes":[["sell","3.36900000","0.00000000"]]},"module":"linear"}
1704644004.573656: {"channel":"depth","timestamp":1704644004466,"data":{"type":"update","instrument_id":"NEAR-USDT-PERPETUAL","sequence":1702545259448765,"prev_sequence":1702545259448764,"changes":[["sell","3.36800000","480.00000000"]]},"module":"linear"}
1704644004.573674: {"channel":"depth","timestamp":1704644004466,"data":{"type":"update","instrument_id":"NEAR-USDT-PERPETUAL","sequence":1702545259448766,"prev_sequence":1702545259448765,"changes":[["buy","3.34000000","0.00000000"]]},"module":"linear"}
1704644004.573693: {"channel":"depth","timestamp":1704644004466,"data":{"type":"update","instrument_id":"NEAR-USDT-PERPETUAL","sequence":1702545259448767,"prev_sequence":1702545259448766,"changes":[["buy","3.33900000","220.00000000"]]},"module":"linear"}
1704644004.616079: {"channel":"depth","timestamp":1704644004526,"data":{"type":"update","instrument_id":"NEAR-USDT-PERPETUAL","sequence":1702545259448768,"prev_sequence":1702545259448767,"changes":[["buy","3.33600000","0.00000000"]]},"module":"linear"}
1704644004.616182: {"channel":"depth","timestamp":1704644004526,"data":{"type":"update","instrument_id":"NEAR-USDT-PERPETUAL","sequence":1702545259448769,"prev_sequence":1702545259448768,"changes":[["buy","3.33500000","1160.00000000"]]},"module":"linear"}
1704644004.6162298: {"channel":"depth","timestamp":1704644004526,"data":{"type":"update","instrument_id":"NEAR-USDT-PERPETUAL","sequence":1702545259448770,"prev_sequence":1702545259448769,"changes":[["buy","3.33400000","0.00000000"]]},"module":"linear"}
1704644004.6162932: {"channel":"depth","timestamp":1704644004526,"data":{"type":"update","instrument_id":"NEAR-USDT-PERPETUAL","sequence":1702545259448771,"prev_sequence":1702545259448770,"changes":[["buy","3.33300000","1130.00000000"]]},"module":"linear"}
1704644006.1103308: {"channel":"depth","timestamp":1704644005997,"data":{"type":"update","instrument_id":"NEAR-USDT-PERPETUAL","sequence":1702545259448772,"prev_sequence":1702545259448771,"changes":[["sell","3.35700000","0.00000000"]]},"module":"linear"}
1704644006.1104598: {"channel":"depth","timestamp":1704644005997,"data":{"type":"update","instrument_id":"NEAR-USDT-PERPETUAL","sequence":1702545259448773,"prev_sequence":1702545259448772,"changes":[["sell","3.35700000","1160.00000000"]]},"module":"linear"}
1704644006.110492: {"channel":"depth","timestamp":1704644005997,"data":{"type":"update","instrument_id":"NEAR-USDT-PERPETUAL","sequence":1702545259448774,"prev_sequence":1702545259448773,"changes":[["buy","3.34600000","510.00000000"]]},"module":"linear"}
1704644006.110517: {"channel":"depth","timestamp":1704644005997,"data":{"type":"update","instrument_id":"NEAR-USDT-PERPETUAL","sequence":1702545259448775,"prev_sequence":1702545259448774,"changes":[["buy","3.34600000","900.00000000"]]},"module":"linear"}
1704644006.110541: {"channel":"depth","timestamp":1704644005997,"data":{"type":"update","instrument_id":"NEAR-USDT-PERPETUAL","sequence":1702545259448776,"prev_sequence":1702545259448775,"changes":[["sell","3.36200000","190.00000000"]]},"module":"linear"}
1704644006.110562: {"channel":"depth","timestamp":1704644005997,"data":{"type":"update","instrument_id":"NEAR-USDT-PERPETUAL","sequence":1702545259448777,"prev_sequence":1702545259448776,"changes":[["sell","3.36200000","400.00000000"]]},"module":"linear"}
1704644006.110581: {"channel":"depth","timestamp":1704644005998,"data":{"type":"update","instrument_id":"NEAR-USDT-PERPETUAL","sequence":1702545259448778,"prev_sequence":1702545259448777,"changes":[["buy","3.34400000","0.00000000"]]},"module":"linear"}
1704644006.110601: {"channel":"depth","timestamp":1704644005998,"data":{"type":"update","instrument_id":"NEAR-USDT-PERPETUAL","sequence":1702545259448779,"prev_sequence":1702545259448778,"changes":[["buy","3.34400000","1160.00000000"]]},"module":"linear"}
1704644006.110621: {"channel":"depth","timestamp":1704644006013,"data":{"type":"update","instrument_id":"NEAR-USDT-PERPETUAL","sequence":1702545259448780,"prev_sequence":1702545259448779,"changes":[["sell","3.36800000","0.00000000"]]},"module":"linear"}
1704644006.11064: {"channel":"depth","timestamp":1704644006013,"data":{"type":"update","instrument_id":"NEAR-USDT-PERPETUAL","sequence":1702545259448781,"prev_sequence":1702545259448780,"changes":[["sell","3.36800000","480.00000000"]]},"module":"linear"}
1704644006.1106591: {"channel":"depth","timestamp":1704644006013,"data":{"type":"update","instrument_id":"NEAR-USDT-PERPETUAL","sequence":1702545259448782,"prev_sequence":1702545259448781,"changes":[["buy","3.34300000","0.00000000"]]},"module":"linear"}
1704644006.110678: {"channel":"depth","timestamp":1704644006013,"data":{"type":"update","instrument_id":"NEAR-USDT-PERPETUAL","sequence":1702545259448783,"prev_sequence":1702545259448782,"changes":[["buy","3.34300000","230.00000000"]]},"module":"linear"}
1704644006.110707: {"channel":"depth","timestamp":1704644006013,"data":{"type":"update","instrument_id":"NEAR-USDT-PERPETUAL","sequence":1702545259448784,"prev_sequence":1702545259448783,"changes":[["buy","3.34200000","0.00000000"]]},"module":"linear"}
1704644006.1107259: {"channel":"depth","timestamp":1704644006013,"data":{"type":"update","instrument_id":"NEAR-USDT-PERPETUAL","sequence":1702545259448785,"prev_sequence":1702545259448784,"changes":[["buy","3.34200000","190.00000000"]]},"module":"linear"}
1704644006.1107452: {"channel":"depth","timestamp":1704644006013,"data":{"type":"update","instrument_id":"NEAR-USDT-PERPETUAL","sequence":1702545259448786,"prev_sequence":1702545259448785,"changes":[["buy","3.33900000","0.00000000"]]},"module":"linear"}
1704644006.110763: {"channel":"depth","timestamp":1704644006013,"data":{"type":"update","instrument_id":"NEAR-USDT-PERPETUAL","sequence":1702545259448787,"prev_sequence":1702545259448786,"changes":[["buy","3.33900000","190.00000000"]]},"module":"linear"}
1704644006.110782: {"channel":"depth","timestamp":1704644006014,"data":{"type":"update","instrument_id":"NEAR-USDT-PERPETUAL","sequence":1702545259448788,"prev_sequence":1702545259448787,"changes":[["buy","3.33800000","0.00000000"]]},"module":"linear"}
1704644006.110801: {"channel":"depth","timestamp":1704644006014,"data":{"type":"update","instrument_id":"NEAR-USDT-PERPETUAL","sequence":1702545259448789,"prev_sequence":1702545259448788,"changes":[["buy","3.33700000","1160.00000000"]]},"module":"linear"}
1704644006.11082: {"channel":"depth","timestamp":1704644006014,"data":{"type":"update","instrument_id":"NEAR-USDT-PERPETUAL","sequence":1702545259448790,"prev_sequence":1702545259448789,"changes":[["buy","3.33300000","0.00000000"]]},"module":"linear"}
1704644006.110838: {"channel":"depth","timestamp":1704644006014,"data":{"type":"update","instrument_id":"NEAR-USDT-PERPETUAL","sequence":1702545259448791,"prev_sequence":1702545259448790,"changes":[["buy","3.33300000","1130.00000000"]]},"module":"linear"}
1704644007.0332632: {"channel":"depth","timestamp":1704644006848,"data":{"type":"update","instrument_id":"NEAR-USDT-PERPETUAL","sequence":1702545259448792,"prev_sequence":1702545259448791,"changes":[["sell","3.35500000","0.00000000"]]},"module":"linear"}
1704644007.033335: {"channel":"depth","timestamp":1704644006848,"data":{"type":"update","instrument_id":"NEAR-USDT-PERPETUAL","sequence":1702545259448793,"prev_sequence":1702545259448792,"changes":[["sell","3.35400000","380.00000000"]]},"module":"linear"}
1704644007.033374: {"channel":"depth","timestamp":1704644006849,"data":{"type":"update","instrument_id":"NEAR-USDT-PERPETUAL","sequence":1702545259448794,"prev_sequence":1702545259448793,"changes":[["buy","3.34600000","510.00000000"]]},"module":"linear"}
1704644007.033399: {"channel":"depth","timestamp":1704644006849,"data":{"type":"update","instrument_id":"NEAR-USDT-PERPETUAL","sequence":1702545259448795,"prev_sequence":1702545259448794,"changes":[["buy","3.34500000","390.00000000"]]},"module":"linear"}
1704644007.033421: {"channel":"depth","timestamp":1704644006849,"data":{"type":"update","instrument_id":"NEAR-USDT-PERPETUAL","sequence":1702545259448796,"prev_sequence":1702545259448795,"changes":[["sell","3.35700000","0.00000000"]]},"module":"linear"}
1704644007.033451: {"channel":"depth","timestamp":1704644006849,"data":{"type":"update","instrument_id":"NEAR-USDT-PERPETUAL","sequence":1702545259448797,"prev_sequence":1702545259448796,"changes":[["sell","3.35600000","1270.00000000"]]},"module":"linear"}
1704644007.033473: {"channel":"depth","timestamp":1704644006849,"data":{"type":"update","instrument_id":"NEAR-USDT-PERPETUAL","sequence":1702545259448798,"prev_sequence":1702545259448797,"changes":[["buy","3.34400000","0.00000000"]]},"module":"linear"}
1704644007.033493: {"channel":"depth","timestamp":1704644006849,"data":{"type":"update","instrument_id":"NEAR-USDT-PERPETUAL","sequence":1702545259448799,"prev_sequence":1702545259448798,"changes":[["buy","3.34300000","900.00000000"]]},"module":"linear"}
1704644007.0335119: {"channel":"depth","timestamp":1704644006849,"data":{"type":"update","instrument_id":"NEAR-USDT-PERPETUAL","sequence":1702545259448800,"prev_sequence":1702545259448799,"changes":[["sell","3.35800000","510.00000000"]]},"module":"linear"}
1704644007.0335329: {"channel":"depth","timestamp":1704644006849,"data":{"type":"update","instrument_id":"NEAR-USDT-PERPETUAL","sequence":1702545259448801,"prev_sequence":1702545259448800,"changes":[["sell","3.35700000","230.00000000"]]},"module":"linear"}
1704644007.033552: {"channel":"depth","timestamp":1704644006849,"data":{"type":"update","instrument_id":"NEAR-USDT-PERPETUAL","sequence":1702545259448802,"prev_sequence":1702545259448801,"changes":[["buy","3.34300000","670.00000000"]]},"module":"linear"}
1704644007.0335722: {"channel":"depth","timestamp":1704644006849,"data":{"type":"update","instrument_id":"NEAR-USDT-PERPETUAL","sequence":1702545259448803,"prev_sequence":1702545259448802,"changes":[["buy","3.34200000","390.00000000"]]},"module":"linear"}
1704644007.033591: {"channel":"depth","timestamp":1704644006849,"data":{"type":"update","instrument_id":"NEAR-USDT-PERPETUAL","sequence":1702545259448804,"prev_sequence":1702545259448803,"changes":[["sell","3.35900000","0.00000000"]]},"module":"linear"}
1704644007.033611: {"channel":"depth","timestamp":1704644006849,"data":{"type":"update","instrument_id":"NEAR-USDT-PERPETUAL","sequence":1702545259448805,"prev_sequence":1702545259448804,"changes":[["sell","3.35800000","730.00000000"]]},"module":"linear"}
1704644007.03363: {"channel":"depth","timestamp":1704644006849,"data":{"type":"update","instrument_id":"NEAR-USDT-PERPETUAL","sequence":1702545259448806,"prev_sequence":1702545259448805,"changes":[["buy","3.34200000","200.00000000"]]},"module":"linear"}
1704644007.033649: {"channel":"depth","timestamp":1704644006849,"data":{"type":"update","instrument_id":"NEAR-USDT-PERPETUAL","sequence":1702545259448807,"prev_sequence":1702545259448806,"changes":[["buy","3.34100000","590.00000000"]]},"module":"linear"}
1704644007.0336692: {"channel":"depth","timestamp":1704644006849,"data":{"type":"update","instrument_id":"NEAR-USDT-PERPETUAL","sequence":1702545259448808,"prev_sequence":1702545259448807,"changes":[["sell","3.36000000","0.00000000"]]},"module":"linear"}
1704644007.033689: {"channel":"depth","timestamp":1704644006849,"data":{"type":"update","instrument_id":"NEAR-USDT-PERPETUAL","sequence":1702545259448809,"prev_sequence":1702545259448808,"changes":[["sell","3.35900000","230.00000000"]]},"module":"linear"}
1704644007.033708: {"channel":"depth","timestamp":1704644006849,"data":{"type":"update","instrument_id":"NEAR-USDT-PERPETUAL","sequence":1702545259448810,"prev_sequence":1702545259448809,"changes":[["buy","3.34100000","390.00000000"]]},"module":"linear"}
1704644007.033727: {"channel":"depth","timestamp":1704644006849,"data":{"type":"update","instrument_id":"NEAR-USDT-PERPETUAL","sequence":1702545259448811,"prev_sequence":1702545259448810,"changes":[["buy","3.34000000","230.00000000"]]},"module":"linear"}
1704644007.033783: {"channel":"depth","timestamp":1704644006904,"data":{"type":"update","instrument_id":"NEAR-USDT-PERPETUAL","sequence":1702545259448812,"prev_sequence":1702545259448811,"changes":[["sell","3.36200000","210.00000000"]]},"module":"linear"}
1704644007.033804: {"channel":"depth","timestamp":1704644006904,"data":{"type":"update","instrument_id":"NEAR-USDT-PERPETUAL","sequence":1702545259448813,"prev_sequence":1702545259448812,"changes":[["sell","3.36000000","190.00000000"]]},"module":"linear"}
1704644007.033824: {"channel":"depth","timestamp":1704644006904,"data":{"type":"update","instrument_id":"NEAR-USDT-PERPETUAL","sequence":1702545259448814,"prev_sequence":1702545259448813,"changes":[["buy","3.34100000","200.00000000"]]},"module":"linear"}
1704644007.033843: {"channel":"depth","timestamp":1704644006904,"data":{"type":"update","instrument_id":"NEAR-USDT-PERPETUAL","sequence":1702545259448815,"prev_sequence":1702545259448814,"changes":[["buy","3.33900000","410.00000000"]]},"module":"linear"}
1704644007.0338619: {"channel":"depth","timestamp":1704644006904,"data":{"type":"update","instrument_id":"NEAR-USDT-PERPETUAL","sequence":1702545259448816,"prev_sequence":1702545259448815,"changes":[["sell","3.36200000","0.00000000"]]},"module":"linear"}
1704644007.0338812: {"channel":"depth","timestamp":1704644006904,"data":{"type":"update","instrument_id":"NEAR-USDT-PERPETUAL","sequence":1702545259448817,"prev_sequence":1702545259448816,"changes":[["sell","3.36100000","220.00000000"]]},"module":"linear"}
1704644007.033901: {"channel":"depth","timestamp":1704644006904,"data":{"type":"update","instrument_id":"NEAR-USDT-PERPETUAL","sequence":1702545259448818,"prev_sequence":1702545259448817,"changes":[["buy","3.33900000","220.00000000"]]},"module":"linear"}
1704644007.03392: {"channel":"depth","timestamp":1704644006904,"data":{"type":"update","instrument_id":"NEAR-USDT-PERPETUAL","sequence":1702545259448819,"prev_sequence":1702545259448818,"changes":[["buy","3.33800000","230.00000000"]]},"module":"linear"}
1704644007.033939: {"channel":"depth","timestamp":1704644006904,"data":{"type":"update","instrument_id":"NEAR-USDT-PERPETUAL","sequence":1702545259448820,"prev_sequence":1702545259448819,"changes":[["sell","3.36500000","0.00000000"]]},"module":"linear"}
1704644007.033959: {"channel":"depth","timestamp":1704644006904,"data":{"type":"update","instrument_id":"NEAR-USDT-PERPETUAL","sequence":1702545259448821,"prev_sequence":1702545259448820,"changes":[["sell","3.36300000","590.00000000"]]},"module":"linear"}
1704644007.0339782: {"channel":"depth","timestamp":1704644006904,"data":{"type":"update","instrument_id":"NEAR-USDT-PERPETUAL","sequence":1702545259448822,"prev_sequence":1702545259448821,"changes":[["buy","3.33700000","0.00000000"]]},"module":"linear"}
1704644007.033997: {"channel":"depth","timestamp":1704644006904,"data":{"type":"update","instrument_id":"NEAR-USDT-PERPETUAL","sequence":1702545259448823,"prev_sequence":1702545259448822,"changes":[["buy","3.33600000","1160.00000000"]]},"module":"linear"}
1704644007.034016: {"channel":"depth","timestamp":1704644006904,"data":{"type":"update","instrument_id":"NEAR-USDT-PERPETUAL","sequence":1702545259448824,"prev_sequence":1702545259448823,"changes":[["sell","3.36700000","0.00000000"]]},"module":"linear"}
1704644007.034034: {"channel":"depth","timestamp":1704644006904,"data":{"type":"update","instrument_id":"NEAR-USDT-PERPETUAL","sequence":1702545259448825,"prev_sequence":1702545259448824,"changes":[["sell","3.36500000","1150.00000000"]]},"module":"linear"}
1704644007.034053: {"channel":"depth","timestamp":1704644006904,"data":{"type":"update","instrument_id":"NEAR-USDT-PERPETUAL","sequence":1702545259448826,"prev_sequence":1702545259448825,"changes":[["buy","3.33500000","0.00000000"]]},"module":"linear"}
1704644007.0340722: {"channel":"depth","timestamp":1704644006904,"data":{"type":"update","instrument_id":"NEAR-USDT-PERPETUAL","sequence":1702545259448827,"prev_sequence":1702545259448826,"changes":[["buy","3.33400000","1150.00000000"]]},"module":"linear"}
1704644007.034091: {"channel":"depth","timestamp":1704644006904,"data":{"type":"update","instrument_id":"NEAR-USDT-PERPETUAL","sequence":1702545259448828,"prev_sequence":1702545259448827,"changes":[["sell","3.36800000","0.00000000"]]},"module":"linear"}
1704644007.0341172: {"channel":"depth","timestamp":1704644006904,"data":{"type":"update","instrument_id":"NEAR-USDT-PERPETUAL","sequence":1702545259448829,"prev_sequence":1702545259448828,"changes":[["sell","3.36700000","1050.00000000"]]},"module":"linear"}
1704644007.034136: {"channel":"depth","timestamp":1704644006904,"data":{"type":"update","instrument_id":"NEAR-USDT-PERPETUAL","sequence":1702545259448830,"prev_sequence":1702545259448829,"changes":[["buy","3.33300000","0.00000000"]]},"module":"linear"}
1704644007.034155: {"channel":"depth","timestamp":1704644006904,"data":{"type":"update","instrument_id":"NEAR-USDT-PERPETUAL","sequence":1702545259448831,"prev_sequence":1702545259448830,"changes":[["buy","3.33200000","1170.00000000"]]},"module":"linear"}
1704644008.0966148: {"channel":"depth","timestamp":1704644008008,"data":{"type":"update","instrument_id":"NEAR-USDT-PERPETUAL","sequence":1702545259448832,"prev_sequence":1702545259448831,"changes":[["sell","3.35600000","110.00000000"]]},"module":"linear"}
1704644008.096742: {"channel":"depth","timestamp":1704644008008,"data":{"type":"update","instrument_id":"NEAR-USDT-PERPETUAL","sequence":1702545259448833,"prev_sequence":1702545259448832,"changes":[["sell","3.35600000","1220.00000000"]]},"module":"linear"}
1704644008.0967948: {"channel":"depth","timestamp":1704644008008,"data":{"type":"update","instrument_id":"NEAR-USDT-PERPETUAL","sequence":1702545259448834,"prev_sequence":1702545259448833,"changes":[["buy","3.34500000","0.00000000"]]},"module":"linear"}
1704644008.098237: {"channel":"depth","timestamp":1704644008009,"data":{"type":"update","instrument_id":"NEAR-USDT-PERPETUAL","sequence":1702545259448835,"prev_sequence":1702545259448834,"changes":[["buy","3.34500000","390.00000000"]]},"module":"linear"}
1704644008.0983412: {"channel":"depth","timestamp":1704644008009,"data":{"type":"update","instrument_id":"NEAR-USDT-PERPETUAL","sequence":1702545259448836,"prev_sequence":1702545259448835,"changes":[["sell","3.35700000","0.00000000"]]},"module":"linear"}
1704644008.0984: {"channel":"depth","timestamp":1704644008009,"data":{"type":"update","instrument_id":"NEAR-USDT-PERPETUAL","sequence":1702545259448837,"prev_sequence":1702545259448836,"changes":[["sell","3.35700000","230.00000000"]]},"module":"linear"}
1704644008.098457: {"channel":"depth","timestamp":1704644008009,"data":{"type":"update","instrument_id":"NEAR-USDT-PERPETUAL","sequence":1702545259448838,"prev_sequence":1702545259448837,"changes":[["buy","3.34300000","0.00000000"]]},"module":"linear"}
1704644008.098498: {"channel":"depth","timestamp":1704644008009,"data":{"type":"update","instrument_id":"NEAR-USDT-PERPETUAL","sequence":1702545259448839,"prev_sequence":1702545259448838,"changes":[["buy","3.34300000","750.00000000"]]},"module":"linear"}
1704644008.098519: {"channel":"depth","timestamp":1704644008009,"data":{"type":"update","instrument_id":"NEAR-USDT-PERPETUAL","sequence":1702545259448840,"prev_sequence":1702545259448839,"changes":[["sell","3.35900000","0.00000000"]]},"module":"linear"}
1704644008.09854: {"channel":"depth","timestamp":1704644008009,"data":{"type":"update","instrument_id":"NEAR-USDT-PERPETUAL","sequence":1702545259448841,"prev_sequence":1702545259448840,"changes":[["sell","3.35900000","220.00000000"]]},"module":"linear"}
1704644008.098559: {"channel":"depth","timestamp":1704644008009,"data":{"type":"update","instrument_id":"NEAR-USDT-PERPETUAL","sequence":1702545259448842,"prev_sequence":1702545259448841,"changes":[["buy","3.34000000","0.00000000"]]},"module":"linear"}
1704644008.09858: {"channel":"depth","timestamp":1704644008009,"data":{"type":"update","instrument_id":"NEAR-USDT-PERPETUAL","sequence":1702545259448843,"prev_sequence":1702545259448842,"changes":[["buy","3.34000000","220.00000000"]]},"module":"linear"}
1704644008.0986: {"channel":"depth","timestamp":1704644008009,"data":{"type":"update","instrument_id":"NEAR-USDT-PERPETUAL","sequence":1702545259448844,"prev_sequence":1702545259448843,"changes":[["sell","3.36100000","0.00000000"]]},"module":"linear"}
1704644008.0989661: {"channel":"depth","timestamp":1704644008009,"data":{"type":"update","instrument_id":"NEAR-USDT-PERPETUAL","sequence":1702545259448845,"prev_sequence":1702545259448844,"changes":[["sell","3.36100000","210.00000000"]]},"module":"linear"}
1704644008.099006: {"channel":"depth","timestamp":1704644008009,"data":{"type":"update","instrument_id":"NEAR-USDT-PERPETUAL","sequence":1702545259448846,"prev_sequence":1702545259448845,"changes":[["buy","3.33900000","0.00000000"]]},"module":"linear"}
1704644008.099031: {"channel":"depth","timestamp":1704644008009,"data":{"type":"update","instrument_id":"NEAR-USDT-PERPETUAL","sequence":1702545259448847,"prev_sequence":1702545259448846,"changes":[["buy","3.33900000","220.00000000"]]},"module":"linear"}
1704644008.099055: {"channel":"depth","timestamp":1704644008009,"data":{"type":"update","instrument_id":"NEAR-USDT-PERPETUAL","sequence":1702545259448848,"prev_sequence":1702545259448847,"changes":[["sell","3.36700000","0.00000000"]]},"module":"linear"}
1704644008.099076: {"channel":"depth","timestamp":1704644008009,"data":{"type":"update","instrument_id":"NEAR-USDT-PERPETUAL","sequence":1702545259448849,"prev_sequence":1702545259448848,"changes":[["sell","3.36700000","970.00000000"]]},"module":"linear"}
1704644008.099095: {"channel":"depth","timestamp":1704644008009,"data":{"type":"update","instrument_id":"NEAR-USDT-PERPETUAL","sequence":1702545259448850,"prev_sequence":1702545259448849,"changes":[["buy","3.33800000","0.00000000"]]},"module":"linear"}
1704644008.099115: {"channel":"depth","timestamp":1704644008009,"data":{"type":"update","instrument_id":"NEAR-USDT-PERPETUAL","sequence":1702545259448851,"prev_sequence":1702545259448850,"changes":[["buy","3.33800000","220.00000000"]]},"module":"linear"}
1704644009.349113: {"channel":"depth","timestamp":1704644009255,"data":{"type":"update","instrument_id":"NEAR-USDT-PERPETUAL","sequence":1702545259448852,"prev_sequence":1702545259448851,"changes":[["sell","3.35700000","0.00000000"]]},"module":"linear"}
1704644009.3492212: {"channel":"depth","timestamp":1704644009255,"data":{"type":"update","instrument_id":"NEAR-USDT-PERPETUAL","sequence":1702545259448853,"prev_sequence":1702545259448852,"changes":[["sell","3.35700000","230.00000000"]]},"module":"linear"}
1704644009.349296: {"channel":"depth","timestamp":1704644009255,"data":{"type":"update","instrument_id":"NEAR-USDT-PERPETUAL","sequence":1702545259448854,"prev_sequence":1702545259448853,"changes":[["buy","3.34100000","0.00000000"]]},"module":"linear"}
1704644009.349322: {"channel":"depth","timestamp":1704644009255,"data":{"type":"update","instrument_id":"NEAR-USDT-PERPETUAL","sequence":1702545259448855,"prev_sequence":1702545259448854,"changes":[["buy","3.34100000","200.00000000"]]},"module":"linear"}
1704644009.349345: {"channel":"depth","timestamp":1704644009255,"data":{"type":"update","instrument_id":"NEAR-USDT-PERPETUAL","sequence":1702545259448856,"prev_sequence":1702545259448855,"changes":[["sell","3.35800000","510.00000000"]]},"module":"linear"}
1704644009.3493671: {"channel":"depth","timestamp":1704644009255,"data":{"type":"update","instrument_id":"NEAR-USDT-PERPETUAL","sequence":1702545259448857,"prev_sequence":1702545259448856,"changes":[["sell","3.35800000","700.00000000"]]},"module":"linear"}
1704644009.349387: {"channel":"depth","timestamp":1704644009255,"data":{"type":"update","instrument_id":"NEAR-USDT-PERPETUAL","sequence":1702545259448858,"prev_sequence":1702545259448857,"changes":[["buy","3.34000000","0.00000000"]]},"module":"linear"}
1704644009.349407: {"channel":"depth","timestamp":1704644009255,"data":{"type":"update","instrument_id":"NEAR-USDT-PERPETUAL","sequence":1702545259448859,"prev_sequence":1702545259448858,"changes":[["buy","3.34000000","200.00000000"]]},"module":"linear"}
1704644009.349426: {"channel":"depth","timestamp":1704644009255,"data":{"type":"update","instrument_id":"NEAR-USDT-PERPETUAL","sequence":1702545259448860,"prev_sequence":1702545259448859,"changes":[["sell","3.35900000","0.00000000"]]},"module":"linear"}
1704644009.3494458: {"channel":"depth","timestamp":1704644009255,"data":{"type":"update","instrument_id":"NEAR-USDT-PERPETUAL","sequence":1702545259448861,"prev_sequence":1702545259448860,"changes":[["sell","3.35900000","200.00000000"]]},"module":"linear"}
1704644009.35133: {"channel":"depth","timestamp":1704644009255,"data":{"type":"update","instrument_id":"NEAR-USDT-PERPETUAL","sequence":1702545259448862,"prev_sequence":1702545259448861,"changes":[["buy","3.33900000","0.00000000"]]},"module":"linear"}
1704644009.351403: {"channel":"depth","timestamp":1704644009255,"data":{"type":"update","instrument_id":"NEAR-USDT-PERPETUAL","sequence":1702545259448863,"prev_sequence":1702545259448862,"changes":[["buy","3.33900000","200.00000000"]]},"module":"linear"}
1704644009.351434: {"channel":"depth","timestamp":1704644009255,"data":{"type":"update","instrument_id":"NEAR-USDT-PERPETUAL","sequence":1702545259448864,"prev_sequence":1702545259448863,"changes":[["buy","3.33800000","0.00000000"]]},"module":"linear"}
1704644009.351458: {"channel":"depth","timestamp":1704644009255,"data":{"type":"update","instrument_id":"NEAR-USDT-PERPETUAL","sequence":1702545259448865,"prev_sequence":1702545259448864,"changes":[["buy","3.33800000","190.00000000"]]},"module":"linear"}
1704644009.35148: {"channel":"depth","timestamp":1704644009255,"data":{"type":"update","instrument_id":"NEAR-USDT-PERPETUAL","sequence":1702545259448866,"prev_sequence":1702545259448865,"changes":[["buy","3.33200000","0.00000000"]]},"module":"linear"}
1704644009.3515: {"channel":"depth","timestamp":1704644009255,"data":{"type":"update","instrument_id":"NEAR-USDT-PERPETUAL","sequence":1702545259448867,"prev_sequence":1702545259448866,"changes":[["buy","3.33200000","1150.00000000"]]},"module":"linear"}
1704644010.5735402: {"channel":"depth","timestamp":1704644010480,"data":{"type":"update","instrument_id":"NEAR-USDT-PERPETUAL","sequence":1702545259448868,"prev_sequence":1702545259448867,"changes":[["buy","3.34500000","0.00000000"]]},"module":"linear"}
1704644010.573628: {"channel":"depth","timestamp":1704644010480,"data":{"type":"update","instrument_id":"NEAR-USDT-PERPETUAL","sequence":1702545259448869,"prev_sequence":1702545259448868,"changes":[["buy","3.34500000","420.00000000"]]},"module":"linear"}
1704644010.573659: {"channel":"depth","timestamp":1704644010480,"data":{"type":"update","instrument_id":"NEAR-USDT-PERPETUAL","sequence":1702545259448870,"prev_sequence":1702545259448869,"changes":[["sell","3.35400000","0.00000000"]]},"module":"linear"}
1704644010.573683: {"channel":"depth","timestamp":1704644010480,"data":{"type":"update","instrument_id":"NEAR-USDT-PERPETUAL","sequence":1702545259448871,"prev_sequence":1702545259448870,"changes":[["sell","3.35400000","360.00000000"]]},"module":"linear"}
1704644010.573705: {"channel":"depth","timestamp":1704644010480,"data":{"type":"update","instrument_id":"NEAR-USDT-PERPETUAL","sequence":1702545259448872,"prev_sequence":1702545259448871,"changes":[["buy","3.34000000","0.00000000"]]},"module":"linear"}
1704644010.573726: {"channel":"depth","timestamp":1704644010480,"data":{"type":"update","instrument_id":"NEAR-USDT-PERPETUAL","sequence":1702545259448873,"prev_sequence":1702545259448872,"changes":[["buy","3.34000000","200.00000000"]]},"module":"linear"}
1704644010.5737731: {"channel":"depth","timestamp":1704644010480,"data":{"type":"update","instrument_id":"NEAR-USDT-PERPETUAL","sequence":1702545259448874,"prev_sequence":1702545259448873,"changes":[["sell","3.35700000","0.00000000"]]},"module":"linear"}
1704644010.573795: {"channel":"depth","timestamp":1704644010480,"data":{"type":"update","instrument_id":"NEAR-USDT-PERPETUAL","sequence":1702545259448875,"prev_sequence":1702545259448874,"changes":[["sell","3.35700000","220.00000000"]]},"module":"linear"}
1704644010.573815: {"channel":"depth","timestamp":1704644010480,"data":{"type":"update","instrument_id":"NEAR-USDT-PERPETUAL","sequence":1702545259448876,"prev_sequence":1702545259448875,"changes":[["buy","3.33900000","0.00000000"]]},"module":"linear"}
1704644010.573835: {"channel":"depth","timestamp":1704644010480,"data":{"type":"update","instrument_id":"NEAR-USDT-PERPETUAL","sequence":1702545259448877,"prev_sequence":1702545259448876,"changes":[["buy","3.33900000","190.00000000"]]},"module":"linear"}
1704644010.573854: {"channel":"depth","timestamp":1704644010480,"data":{"type":"update","instrument_id":"NEAR-USDT-PERPETUAL","sequence":1702545259448878,"prev_sequence":1702545259448877,"changes":[["sell","3.35900000","0.00000000"]]},"module":"linear"}
1704644010.5738728: {"channel":"depth","timestamp":1704644010480,"data":{"type":"update","instrument_id":"NEAR-USDT-PERPETUAL","sequence":1702545259448879,"prev_sequence":1702545259448878,"changes":[["sell","3.35900000","200.00000000"]]},"module":"linear"}
1704644010.573892: {"channel":"depth","timestamp":1704644010480,"data":{"type":"update","instrument_id":"NEAR-USDT-PERPETUAL","sequence":1702545259448880,"prev_sequence":1702545259448879,"changes":[["sell","3.36100000","0.00000000"]]},"module":"linear"}
1704644010.573911: {"channel":"depth","timestamp":1704644010480,"data":{"type":"update","instrument_id":"NEAR-USDT-PERPETUAL","sequence":1702545259448881,"prev_sequence":1702545259448880,"changes":[["sell","3.36100000","210.00000000"]]},"module":"linear"}
1704644011.180843: {"channel":"depth","timestamp":1704644011090,"data":{"type":"update","instrument_id":"NEAR-USDT-PERPETUAL","sequence":1702545259448882,"prev_sequence":1702545259448881,"changes":[["sell","3.35400000","0.00000000"]]},"module":"linear"}
1704644011.1809149: {"channel":"depth","timestamp":1704644011090,"data":{"type":"update","instrument_id":"NEAR-USDT-PERPETUAL","sequence":1702545259448883,"prev_sequence":1702545259448882,"changes":[["sell","3.35500000","390.00000000"]]},"module":"linear"}
1704644011.1809459: {"channel":"depth","timestamp":1704644011090,"data":{"type":"update","instrument_id":"NEAR-USDT-PERPETUAL","sequence":1702545259448884,"prev_sequence":1702545259448883,"changes":[["buy","3.34500000","0.00000000"]]},"module":"linear"}
1704644011.180972: {"channel":"depth","timestamp":1704644011090,"data":{"type":"update","instrument_id":"NEAR-USDT-PERPETUAL","sequence":1702545259448885,"prev_sequence":1702545259448884,"changes":[["buy","3.34600000","890.00000000"]]},"module":"linear"}
1704644011.180994: {"channel":"depth","timestamp":1704644011090,"data":{"type":"update","instrument_id":"NEAR-USDT-PERPETUAL","sequence":1702545259448886,"prev_sequence":1702545259448885,"changes":[["sell","3.35600000","110.00000000"]]},"module":"linear"}
1704644011.181015: {"channel":"depth","timestamp":1704644011090,"data":{"type":"update","instrument_id":"NEAR-USDT-PERPETUAL","sequence":1702545259448887,"prev_sequence":1702545259448886,"changes":[["sell","3.35700000","1390.00000000"]]},"module":"linear"}
1704644011.1810439: {"channel":"depth","timestamp":1704644011090,"data":{"type":"update","instrument_id":"NEAR-USDT-PERPETUAL","sequence":1702545259448888,"prev_sequence":1702545259448887,"changes":[["buy","3.34300000","0.00000000"]]},"module":"linear"}
1704644011.1810648: {"channel":"depth","timestamp":1704644011090,"data":{"type":"update","instrument_id":"NEAR-USDT-PERPETUAL","sequence":1702545259448889,"prev_sequence":1702545259448888,"changes":[["buy","3.34400000","1160.00000000"]]},"module":"linear"}
1704644011.1810849: {"channel":"depth","timestamp":1704644011090,"data":{"type":"update","instrument_id":"NEAR-USDT-PERPETUAL","sequence":1702545259448890,"prev_sequence":1702545259448889,"changes":[["sell","3.35700000","1170.00000000"]]},"module":"linear"}
1704644011.181105: {"channel":"depth","timestamp":1704644011090,"data":{"type":"update","instrument_id":"NEAR-USDT-PERPETUAL","sequence":1702545259448891,"prev_sequence":1702545259448890,"changes":[["sell","3.35800000","930.00000000"]]},"module":"linear"}
1704644011.1811242: {"channel":"depth","timestamp":1704644011090,"data":{"type":"update","instrument_id":"NEAR-USDT-PERPETUAL","sequence":1702545259448892,"prev_sequence":1702545259448891,"changes":[["buy","3.34200000","0.00000000"]]},"module":"linear"}
1704644011.181144: {"channel":"depth","timestamp":1704644011090,"data":{"type":"update","instrument_id":"NEAR-USDT-PERPETUAL","sequence":1702545259448893,"prev_sequence":1702545259448892,"changes":[["buy","3.34300000","220.00000000"]]},"module":"linear"}
1704644011.181163: {"channel":"depth","timestamp":1704644011090,"data":{"type":"update","instrument_id":"NEAR-USDT-PERPETUAL","sequence":1702545259448894,"prev_sequence":1702545259448893,"changes":[["sell","3.35800000","740.00000000"]]},"module":"linear"}
1704644011.181182: {"channel":"depth","timestamp":1704644011090,"data":{"type":"update","instrument_id":"NEAR-USDT-PERPETUAL","sequence":1702545259448895,"prev_sequence":1702545259448894,"changes":[["sell","3.35900000","420.00000000"]]},"module":"linear"}
1704644011.181202: {"channel":"depth","timestamp":1704644011090,"data":{"type":"update","instrument_id":"NEAR-USDT-PERPETUAL","sequence":1702545259448896,"prev_sequence":1702545259448895,"changes":[["buy","3.34100000","0.00000000"]]},"module":"linear"}
1704644011.181222: {"channel":"depth","timestamp":1704644011090,"data":{"type":"update","instrument_id":"NEAR-USDT-PERPETUAL","sequence":1702545259448897,"prev_sequence":1702545259448896,"changes":[["buy","3.34200000","220.00000000"]]},"module":"linear"}
1704644011.1812491: {"channel":"depth","timestamp":1704644011090,"data":{"type":"update","instrument_id":"NEAR-USDT-PERPETUAL","sequence":1702545259448898,"prev_sequence":1702545259448897,"changes":[["sell","3.35900000","220.00000000"]]},"module":"linear"}
1704644011.181269: {"channel":"depth","timestamp":1704644011090,"data":{"type":"update","instrument_id":"NEAR-USDT-PERPETUAL","sequence":1702545259448899,"prev_sequence":1702545259448898,"changes":[["sell","3.36000000","390.00000000"]]},"module":"linear"}
1704644011.181288: {"channel":"depth","timestamp":1704644011090,"data":{"type":"update","instrument_id":"NEAR-USDT-PERPETUAL","sequence":1702545259448900,"prev_sequence":1702545259448899,"changes":[["buy","3.34000000","0.00000000"]]},"module":"linear"}
1704644011.1813068: {"channel":"depth","timestamp":1704644011090,"data":{"type":"update","instrument_id":"NEAR-USDT-PERPETUAL","sequence":1702545259448901,"prev_sequence":1702545259448900,"changes":[["buy","3.34100000","230.00000000"]]},"module":"linear"}
1704644011.270304: {"channel":"depth","timestamp":1704644011179,"data":{"type":"update","instrument_id":"NEAR-USDT-PERPETUAL","sequence":1702545259448902,"prev_sequence":1702545259448901,"changes":[["sell","3.36000000","200.00000000"]]},"module":"linear"}
1704644011.27038: {"channel":"depth","timestamp":1704644011179,"data":{"type":"update","instrument_id":"NEAR-USDT-PERPETUAL","sequence":1702545259448903,"prev_sequence":1702545259448902,"changes":[["sell","3.36100000","440.00000000"]]},"module":"linear"}
1704644011.270412: {"channel":"depth","timestamp":1704644011179,"data":{"type":"update","instrument_id":"NEAR-USDT-PERPETUAL","sequence":1702545259448904,"prev_sequence":1702545259448903,"changes":[["buy","3.33900000","0.00000000"]]},"module":"linear"}
1704644011.270445: {"channel":"depth","timestamp":1704644011179,"data":{"type":"update","instrument_id":"NEAR-USDT-PERPETUAL","sequence":1702545259448905,"prev_sequence":1702545259448904,"changes":[["buy","3.34000000","200.00000000"]]},"module":"linear"}
1704644011.2704692: {"channel":"depth","timestamp":1704644011179,"data":{"type":"update","instrument_id":"NEAR-USDT-PERPETUAL","sequence":1702545259448906,"prev_sequence":1702545259448905,"changes":[["sell","3.36100000","230.00000000"]]},"module":"linear"}
1704644011.270506: {"channel":"depth","timestamp":1704644011179,"data":{"type":"update","instrument_id":"NEAR-USDT-PERPETUAL","sequence":1702545259448907,"prev_sequence":1702545259448906,"changes":[["sell","3.36200000","230.00000000"]]},"module":"linear"}
1704644011.270528: {"channel":"depth","timestamp":1704644011179,"data":{"type":"update","instrument_id":"NEAR-USDT-PERPETUAL","sequence":1702545259448908,"prev_sequence":1702545259448907,"changes":[["buy","3.33800000","0.00000000"]]},"module":"linear"}
1704644011.2705479: {"channel":"depth","timestamp":1704644011179,"data":{"type":"update","instrument_id":"NEAR-USDT-PERPETUAL","sequence":1702545259448909,"prev_sequence":1702545259448908,"changes":[["buy","3.33900000","210.00000000"]]},"module":"linear"}
1704644011.270568: {"channel":"depth","timestamp":1704644011179,"data":{"type":"update","instrument_id":"NEAR-USDT-PERPETUAL","sequence":1702545259448910,"prev_sequence":1702545259448909,"changes":[["sell","3.36300000","0.00000000"]]},"module":"linear"}
1704644011.270588: {"channel":"depth","timestamp":1704644011179,"data":{"type":"update","instrument_id":"NEAR-USDT-PERPETUAL","sequence":1702545259448911,"prev_sequence":1702545259448910,"changes":[["sell","3.36400000","860.00000000"]]},"module":"linear"}
1704644011.270607: {"channel":"depth","timestamp":1704644011179,"data":{"type":"update","instrument_id":"NEAR-USDT-PERPETUAL","sequence":1702545259448912,"prev_sequence":1702545259448911,"changes":[["buy","3.33600000","0.00000000"]]},"module":"linear"}
1704644011.270626: {"channel":"depth","timestamp":1704644011179,"data":{"type":"update","instrument_id":"NEAR-USDT-PERPETUAL","sequence":1702545259448913,"prev_sequence":1702545259448912,"changes":[["buy","3.33700000","1180.00000000"]]},"module":"linear"}
1704644011.2706518: {"channel":"depth","timestamp":1704644011179,"data":{"type":"update","instrument_id":"NEAR-USDT-PERPETUAL","sequence":1702545259448914,"prev_sequence":1702545259448913,"changes":[["sell","3.36500000","0.00000000"]]},"module":"linear"}
1704644011.2706711: {"channel":"depth","timestamp":1704644011179,"data":{"type":"update","instrument_id":"NEAR-USDT-PERPETUAL","sequence":1702545259448915,"prev_sequence":1702545259448914,"changes":[["sell","3.36600000","1180.00000000"]]},"module":"linear"}
1704644011.2706912: {"channel":"depth","timestamp":1704644011179,"data":{"type":"update","instrument_id":"NEAR-USDT-PERPETUAL","sequence":1702545259448916,"prev_sequence":1702545259448915,"changes":[["buy","3.33400000","0.00000000"]]},"module":"linear"}
1704644011.270713: {"channel":"depth","timestamp":1704644011179,"data":{"type":"update","instrument_id":"NEAR-USDT-PERPETUAL","sequence":1702545259448917,"prev_sequence":1702545259448916,"changes":[["buy","3.33500000","1170.00000000"]]},"module":"linear"}
1704644011.270732: {"channel":"depth","timestamp":1704644011179,"data":{"type":"update","instrument_id":"NEAR-USDT-PERPETUAL","sequence":1702545259448918,"prev_sequence":1702545259448917,"changes":[["sell","3.36700000","0.00000000"]]},"module":"linear"}
1704644011.27075: {"channel":"depth","timestamp":1704644011179,"data":{"type":"update","instrument_id":"NEAR-USDT-PERPETUAL","sequence":1702545259448919,"prev_sequence":1702545259448918,"changes":[["sell","3.36800000","580.00000000"]]},"module":"linear"}
1704644011.270769: {"channel":"depth","timestamp":1704644011180,"data":{"type":"update","instrument_id":"NEAR-USDT-PERPETUAL","sequence":1702545259448920,"prev_sequence":1702545259448919,"changes":[["buy","3.33200000","0.00000000"]]},"module":"linear"}
1704644011.2707882: {"channel":"depth","timestamp":1704644011180,"data":{"type":"update","instrument_id":"NEAR-USDT-PERPETUAL","sequence":1702545259448921,"prev_sequence":1702545259448920,"changes":[["buy","3.33300000","1170.00000000"]]},"module":"linear"}
1704644012.354518: {"channel":"depth","timestamp":1704644012249,"data":{"type":"update","instrument_id":"NEAR-USDT-PERPETUAL","sequence":1702545259448922,"prev_sequence":1702545259448921,"changes":[["sell","3.35800000","510.00000000"]]},"module":"linear"}
1704644012.3545759: {"channel":"depth","timestamp":1704644012249,"data":{"type":"update","instrument_id":"NEAR-USDT-PERPETUAL","sequence":1702545259448923,"prev_sequence":1702545259448922,"changes":[["sell","3.35800000","710.00000000"]]},"module":"linear"}
1704644012.354601: {"channel":"depth","timestamp":1704644012249,"data":{"type":"update","instrument_id":"NEAR-USDT-PERPETUAL","sequence":1702545259448924,"prev_sequence":1702545259448923,"changes":[["buy","3.34200000","0.00000000"]]},"module":"linear"}
1704644012.354632: {"channel":"depth","timestamp":1704644012249,"data":{"type":"update","instrument_id":"NEAR-USDT-PERPETUAL","sequence":1702545259448925,"prev_sequence":1702545259448924,"changes":[["buy","3.34200000","220.00000000"]]},"module":"linear"}
1704644012.354649: {"channel":"depth","timestamp":1704644012249,"data":{"type":"update","instrument_id":"NEAR-USDT-PERPETUAL","sequence":1702545259448926,"prev_sequence":1702545259448925,"changes":[["sell","3.36000000","0.00000000"]]},"module":"linear"}
1704644012.354665: {"channel":"depth","timestamp":1704644012249,"data":{"type":"update","instrument_id":"NEAR-USDT-PERPETUAL","sequence":1702545259448927,"prev_sequence":1702545259448926,"changes":[["sell","3.36000000","200.00000000"]]},"module":"linear"}
1704644012.3546848: {"channel":"depth","timestamp":1704644012249,"data":{"type":"update","instrument_id":"NEAR-USDT-PERPETUAL","sequence":1702545259448928,"prev_sequence":1702545259448927,"changes":[["buy","3.34100000","0.00000000"]]},"module":"linear"}
1704644012.354702: {"channel":"depth","timestamp":1704644012249,"data":{"type":"update","instrument_id":"NEAR-USDT-PERPETUAL","sequence":1702545259448929,"prev_sequence":1702545259448928,"changes":[["buy","3.34100000","190.00000000"]]},"module":"linear"}
1704644012.354717: {"channel":"depth","timestamp":1704644012249,"data":{"type":"update","instrument_id":"NEAR-USDT-PERPETUAL","sequence":1702545259448930,"prev_sequence":1702545259448929,"changes":[["sell","3.36100000","0.00000000"]]},"module":"linear"}
1704644012.354733: {"channel":"depth","timestamp":1704644012249,"data":{"type":"update","instrument_id":"NEAR-USDT-PERPETUAL","sequence":1702545259448931,"prev_sequence":1702545259448930,"changes":[["sell","3.36100000","200.00000000"]]},"module":"linear"}
1704644012.354748: {"channel":"depth","timestamp":1704644012249,"data":{"type":"update","instrument_id":"NEAR-USDT-PERPETUAL","sequence":1702545259448932,"prev_sequence":1702545259448931,"changes":[["buy","3.34000000","0.00000000"]]},"module":"linear"}
1704644012.354762: {"channel":"depth","timestamp":1704644012249,"data":{"type":"update","instrument_id":"NEAR-USDT-PERPETUAL","sequence":1702545259448933,"prev_sequence":1702545259448932,"changes":[["buy","3.34000000","190.00000000"]]},"module":"linear"}
1704644012.354777: {"channel":"depth","timestamp":1704644012249,"data":{"type":"update","instrument_id":"NEAR-USDT-PERPETUAL","sequence":1702545259448934,"prev_sequence":1702545259448933,"changes":[["sell","3.36200000","0.00000000"]]},"module":"linear"}
1704644012.354791: {"channel":"depth","timestamp":1704644012249,"data":{"type":"update","instrument_id":"NEAR-USDT-PERPETUAL","sequence":1702545259448935,"prev_sequence":1702545259448934,"changes":[["sell","3.36200000","210.00000000"]]},"module":"linear"}
1704644012.3548071: {"channel":"depth","timestamp":1704644012249,"data":{"type":"update","instrument_id":"NEAR-USDT-PERPETUAL","sequence":1702545259448936,"prev_sequence":1702545259448935,"changes":[["buy","3.33900000","0.00000000"]]},"module":"linear"}
1704644012.354822: {"channel":"depth","timestamp":1704644012249,"data":{"type":"update","instrument_id":"NEAR-USDT-PERPETUAL","sequence":1702545259448937,"prev_sequence":1702545259448936,"changes":[["buy","3.33900000","200.00000000"]]},"module":"linear"}
1704644012.354837: {"channel":"depth","timestamp":1704644012249,"data":{"type":"update","instrument_id":"NEAR-USDT-PERPETUAL","sequence":1702545259448938,"prev_sequence":1702545259448937,"changes":[["sell","3.36400000","0.00000000"]]},"module":"linear"}
1704644012.354851: {"channel":"depth","timestamp":1704644012249,"data":{"type":"update","instrument_id":"NEAR-USDT-PERPETUAL","sequence":1702545259448939,"prev_sequence":1702545259448938,"changes":[["sell","3.36400000","860.00000000"]]},"module":"linear"}
1704644012.354866: {"channel":"depth","timestamp":1704644012249,"data":{"type":"update","instrument_id":"NEAR-USDT-PERPETUAL","sequence":1702545259448940,"prev_sequence":1702545259448939,"changes":[["buy","3.33700000","0.00000000"]]},"module":"linear"}
1704644012.35488: {"channel":"depth","timestamp":1704644012249,"data":{"type":"update","instrument_id":"NEAR-USDT-PERPETUAL","sequence":1702545259448941,"prev_sequence":1702545259448940,"changes":[["buy","3.33700000","1170.00000000"]]},"module":"linear"}
