1626318016.660508: {"jsonrpc":"2.0","method":"updateOrderbook","params":{"ask":[{"price":"0.00055060","size":"843.90"},{"price":"0.00055113","size":"0"}],"bid":[{"price":"0.00054571","size":"9.62"},{"price":"0.00054565","size":"0"}],"sequence":19513019,"timestamp":"2021-07-15T03:00:16.606Z","symbol":"UNIBTC"}}
1626318016.746468: {"jsonrpc":"2.0","method":"updateOrderbook","params":{"ask":[],"bid":[{"price":"12.066","size":"5.7269"},{"price":"12.065","size":"5.8922"}],"sequence":2190659,"timestamp":"2021-07-15T03:00:16.702Z","symbol":"SPIUSD"}}
1626318016.75398: {"jsonrpc":"2.0","method":"updateOrderbook","params":{"ask":[{"price":"0.662654","size":"399058.8"}],"bid":[{"price":"0.614838","size":"0"},{"price":"0.614758","size":"44970.5"}],"sequence":20584020,"timestamp":"2021-07-15T03:00:16.711Z","symbol":"XRPUSDT"}}
1626318016.771198: {"jsonrpc":"2.0","method":"updateOrderbook","params":{"ask":[{"price":"0.00000065973","size":"15229800"},{"price":"0.00000094569","size":"2767840"}],"bid":[{"price":"0.00000036521","size":"0"},{"price":"0.00000036504","size":"1000"}],"sequence":10532211,"timestamp":"2021-07-15T03:00:16.703Z","symbol":"SCBTC"}}
1626318016.771449: {"jsonrpc":"2.0","method":"updateOrderbook","params":{"ask":[],"bid":[{"price":"0.00054586","size":"0"},{"price":"0.00054585","size":"5.18"},{"price":"0.00054286","size":"84.00"},{"price":"0.00054234","size":"0"}],"sequence":19513020,"timestamp":"2021-07-15T03:00:16.739Z","symbol":"UNIBTC"}}
1626318016.851085: {"jsonrpc":"2.0","method":"updateOrderbook","params":{"ask":[{"price":"0.662654","size":"399059.1"}],"bid":[{"price":"0.615608","size":"1591.6"},{"price":"0.615603","size":"0"}],"sequence":20584021,"timestamp":"2021-07-15T03:00:16.800Z","symbol":"XRPUSDT"}}
1626318016.868692: {"jsonrpc":"2.0","method":"updateOrderbook","params":{"ask":[{"price":"0.00000041218","size":"1016210"},{"price":"0.00000042978","size":"0"},{"price":"0.00000043922","size":"1381850"},{"price":"0.00000063201","size":"0"},{"price":"0.00000065973","size":"15229830"},{"price":"0.00000094569","size":"2767870"}],"bid":[{"price":"0.00000034658","size":"4600"},{"price":"0.00000034622","size":"230000"}],"sequence":10532212,"timestamp":"2021-07-15T03:00:16.823Z","symbol":"SCBTC"}}
1626318016.868937: {"jsonrpc":"2.0","method":"updateOrderbook","params":{"ask":[{"price":"0.00054803","size":"658.12"},{"price":"0.00055031","size":"0"}],"bid":[{"price":"0.00054286","size":"0"},{"price":"0.00054234","size":"84.00"}],"sequence":19513021,"timestamp":"2021-07-15T03:00:16.828Z","symbol":"UNIBTC"}}
1626318016.949016: {"jsonrpc":"2.0","method":"updateOrderbook","params":{"ask":[{"price":"0.616627","size":"6433.6"},{"price":"0.616682","size":"0"},{"price":"0.662654","size":"399059.4"}],"bid":[{"price":"0.615479","size":"2955.8"},{"price":"0.615445","size":"0"}],"sequence":20584022,"timestamp":"2021-07-15T03:00:16.914Z","symbol":"XRPUSDT"}}
1626318016.961303: {"jsonrpc":"2.0","method":"updateOrderbook","params":{"ask":[{"price":"0.00000065973","size":"15229850"},{"price":"0.00000094569","size":"2767890"}],"bid":[],"sequence":10532213,"timestamp":"2021-07-15T03:00:16.930Z","symbol":"SCBTC"}}
1626318016.961343: {"jsonrpc":"2.0","method":"updateOrderbook","params":{"ask":[{"price":"0.00054606","size":"4.33"},{"price":"0.00054608","size":"0"}],"bid":[{"price":"0.00054585","size":"0"},{"price":"0.00054581","size":"5.18"},{"price":"0.00054571","size":"0"},{"price":"0.00054566","size":"9.62"},{"price":"0.00054286","size":"84.00"},{"price":"0.00054234","size":"0"}],"sequence":19513022,"timestamp":"2021-07-15T03:00:16.942Z","symbol":"UNIBTC"}}
1626318017.0449688: {"jsonrpc":"2.0","method":"updateOrderbook","params":{"ask":[],"bid":[{"price":"12.067","size":"5.8913"},{"price":"12.065","size":"0"}],"sequence":2190660,"timestamp":"2021-07-15T03:00:17.024Z","symbol":"SPIUSD"}}
1626318017.051033: {"jsonrpc":"2.0","method":"updateOrderbook","params":{"ask":[{"price":"0.662654","size":"399059.8"},{"price":"0.701424","size":"0"},{"price":"0.703123","size":"228479.7"}],"bid":[{"price":"0.615646","size":"1591.6"},{"price":"0.615608","size":"0"}],"sequence":20584023,"timestamp":"2021-07-15T03:00:17.023Z","symbol":"XRPUSDT"}}
1626318017.0662222: {"jsonrpc":"2.0","method":"updateOrderbook","params":{"ask":[{"price":"0.00000065973","size":"15229870"},{"price":"0.00000094569","size":"2767910"}],"bid":[],"sequence":10532214,"timestamp":"2021-07-15T03:00:17.036Z","symbol":"SCBTC"}}
1626318017.071718: {"jsonrpc":"2.0","method":"updateOrderbook","params":{"ask":[{"price":"0.00054604","size":"4.33"},{"price":"0.00054606","size":"0"},{"price":"0.00054851","size":"433.80"},{"price":"0.00054977","size":"0"}],"bid":[{"price":"0.00054292","size":"914.50"},{"price":"0.00054203","size":"0"}],"sequence":19513023,"timestamp":"2021-07-15T03:00:17.034Z","symbol":"UNIBTC"}}
1626318017.071777: {"jsonrpc":"2.0","method":"updateOrderbook","params":{"ask":[{"price":"0.0004396","size":"0"},{"price":"0.0004397","size":"47.197"}],"bid":[],"sequence":2198423,"timestamp":"2021-07-15T03:00:16.980Z","symbol":"NUTBTC"}}
1626318017.1457028: {"jsonrpc":"2.0","method":"updateOrderbook","params":{"ask":[],"bid":[{"price":"12.068","size":"5.7295"},{"price":"12.066","size":"0"}],"sequence":2190661,"timestamp":"2021-07-15T03:00:17.084Z","symbol":"SPIUSD"}}
1626318017.163727: {"jsonrpc":"2.0","method":"updateOrderbook","params":{"ask":[{"price":"0.627039","size":"0"},{"price":"0.628174","size":"129038.8"},{"price":"0.651700","size":"0"},{"price":"0.652912","size":"181214.3"},{"price":"0.662654","size":"399060.0"},{"price":"0.703123","size":"0"}],"bid":[{"price":"0.615646","size":"0"},{"price":"0.615641","size":"1591.6"},{"price":"0.615513","size":"2955.8"},{"price":"0.615479","size":"0"}],"sequence":20584024,"timestamp":"2021-07-15T03:00:17.099Z","symbol":"XRPUSDT"}}
1626318017.1692538: {"jsonrpc":"2.0","method":"updateOrderbook","params":{"ask":[{"price":"0.00000065973","size":"15229890"},{"price":"0.00000094569","size":"2767940"}],"bid":[],"sequence":10532215,"timestamp":"2021-07-15T03:00:17.141Z","symbol":"SCBTC"}}
1626318017.169396: {"jsonrpc":"2.0","method":"updateOrderbook","params":{"ask":[{"price":"0.00054602","size":"4.33"},{"price":"0.00054604","size":"0"},{"price":"0.00065925","size":"2343.84"},{"price":"0.00068731","size":"0"}],"bid":[{"price":"0.00054581","size":"0"},{"price":"0.00054579","size":"5.18"},{"price":"0.00054286","size":"0"},{"price":"0.00054234","size":"84.00"}],"sequence":19513024,"timestamp":"2021-07-15T03:00:17.135Z","symbol":"UNIBTC"}}
1626318017.2516632: {"jsonrpc":"2.0","method":"updateOrderbook","params":{"ask":[{"price":"0.615742","size":"1331.7"},{"price":"0.615749","size":"0"},{"price":"0.641894","size":"0"},{"price":"0.643681","size":"347706.3"},{"price":"0.662654","size":"399060.3"}],"bid":[{"price":"0.615651","size":"1591.6"},{"price":"0.615641","size":"0"}],"sequence":20584025,"timestamp":"2021-07-15T03:00:17.206Z","symbol":"XRPUSDT"}}
1626318017.263156: {"jsonrpc":"2.0","method":"updateOrderbook","params":{"ask":[{"price":"0.00000043863","size":"1381850"},{"price":"0.00000043922","size":"0"},{"price":"0.00000065973","size":"15229910"},{"price":"0.00000094569","size":"2767960"}],"bid":[],"sequence":10532216,"timestamp":"2021-07-15T03:00:17.219Z","symbol":"SCBTC"}}
1626318017.264863: {"jsonrpc":"2.0","method":"updateOrderbook","params":{"ask":[{"price":"0.00054598","size":"4.33"},{"price":"0.00054602","size":"0"},{"price":"0.00054642","size":"66.20"},{"price":"0.00054657","size":"0"}],"bid":[{"price":"0.00053567","size":"2974.71"},{"price":"0.00052741","size":"0"}],"sequence":19513025,"timestamp":"2021-07-15T03:00:17.210Z","symbol":"UNIBTC"}}
1626318017.349529: {"jsonrpc":"2.0","method":"updateOrderbook","params":{"ask":[{"price":"0.662654","size":"399060.6"}],"bid":[],"sequence":20584026,"timestamp":"2021-07-15T03:00:17.279Z","symbol":"XRPUSDT"}}
1626318017.366852: {"jsonrpc":"2.0","method":"updateOrderbook","params":{"ask":[{"price":"0.00000036888","size":"417100"},{"price":"0.00000036912","size":"0"},{"price":"0.00000065973","size":"15229930"},{"price":"0.00000087979","size":"2001500"},{"price":"0.00000094569","size":"2767980"},{"price":"0.00000107948","size":"0"},{"price":"0.00000124326","size":"2705250"},{"price":"0.00000132071","size":"0"}],"bid":[{"price":"0.00000036534","size":"28670"},{"price":"0.00000036520","size":"0"},{"price":"0.00000036514","size":"110390"},{"price":"0.00000036503","size":"0"}],"sequence":10532217,"timestamp":"2021-07-15T03:00:17.322Z","symbol":"SCBTC"}}
1626318017.368886: {"jsonrpc":"2.0","method":"updateOrderbook","params":{"ask":[{"price":"0.00054738","size":"666.24"},{"price":"0.00054773","size":"963.50"},{"price":"0.00054785","size":"0"},{"price":"0.00054824","size":"0"},{"price":"0.00054841","size":"375.71"},{"price":"0.00054870","size":"0"}],"bid":[],"sequence":19513026,"timestamp":"2021-07-15T03:00:17.317Z","symbol":"UNIBTC"}}
1626318017.455265: {"jsonrpc":"2.0","method":"updateOrderbook","params":{"ask":[{"price":"0.662654","size":"399060.9"}],"bid":[],"sequence":20584027,"timestamp":"2021-07-15T03:00:17.385Z","symbol":"XRPUSDT"}}
1626318017.4620318: {"jsonrpc":"2.0","method":"updateOrderbook","params":{"ask":[{"price":"0.00000065973","size":"15229950"},{"price":"0.00000094569","size":"2767990"}],"bid":[],"sequence":10532218,"timestamp":"2021-07-15T03:00:17.427Z","symbol":"SCBTC"}}
1626318017.4621718: {"jsonrpc":"2.0","method":"updateOrderbook","params":{"ask":[{"price":"0.00054613","size":"10.47"},{"price":"0.00054619","size":"0"}],"bid":[],"sequence":19513027,"timestamp":"2021-07-15T03:00:17.394Z","symbol":"UNIBTC"}}
1626318017.549458: {"jsonrpc":"2.0","method":"updateOrderbook","params":{"ask":[{"price":"0.662654","size":"399061.2"}],"bid":[],"sequence":20584028,"timestamp":"2021-07-15T03:00:17.485Z","symbol":"XRPUSDT"}}
1626318017.5625641: {"jsonrpc":"2.0","method":"updateOrderbook","params":{"ask":[{"price":"0.00000043863","size":"0"},{"price":"0.00000043994","size":"1381850"},{"price":"0.00000065973","size":"15229960"},{"price":"0.00000087979","size":"0"},{"price":"0.00000088323","size":"2001500"},{"price":"0.00000094569","size":"2768000"},{"price":"0.00000124326","size":"0"},{"price":"0.00000124431","size":"2705250"}],"bid":[{"price":"0.00000034658","size":"234600"},{"price":"0.00000034622","size":"0"}],"sequence":10532219,"timestamp":"2021-07-15T03:00:17.496Z","symbol":"SCBTC"}}
1626318017.573469: {"jsonrpc":"2.0","method":"updateOrderbook","params":{"ask":[{"price":"0.00054653","size":"199.63"},{"price":"0.00054664","size":"296.51"},{"price":"0.00054693","size":"0"},{"price":"0.00054711","size":"0"},{"price":"0.00055048","size":"662.81"},{"price":"0.00055297","size":"0"},{"price":"0.00055868","size":"881.76"},{"price":"0.00058185","size":"0"}],"bid":[],"sequence":19513028,"timestamp":"2021-07-15T03:00:17.493Z","symbol":"UNIBTC"}}
1626318017.648782: {"jsonrpc":"2.0","method":"updateOrderbook","params":{"ask":[{"price":"0.662654","size":"399061.5"}],"bid":[{"price":"0.615656","size":"1591.6"},{"price":"0.615651","size":"0"}],"sequence":20584029,"timestamp":"2021-07-15T03:00:17.601Z","symbol":"XRPUSDT"}}
1626318017.6594539: {"jsonrpc":"2.0","method":"updateOrderbook","params":{"ask":[{"price":"0.00000036737","size":"101590"},{"price":"0.00000036833","size":"0"},{"price":"0.00000065973","size":"15229970"},{"price":"0.00000094569","size":"2768020"}],"bid":[],"sequence":10532220,"timestamp":"2021-07-15T03:00:17.590Z","symbol":"SCBTC"}}
1626318017.665772: {"jsonrpc":"2.0","method":"updateOrderbook","params":{"ask":[{"price":"0.00054655","size":"18.08"},{"price":"0.00054676","size":"0"},{"price":"0.00054823","size":"1388.32"},{"price":"0.00055008","size":"0"}],"bid":[{"price":"0.00054580","size":"5.18"},{"price":"0.00054579","size":"0"}],"sequence":19513029,"timestamp":"2021-07-15T03:00:17.573Z","symbol":"UNIBTC"}}
1626318017.7446458: {"jsonrpc":"2.0","method":"updateOrderbook","params":{"ask":[],"bid":[{"price":"12.067","size":"0"}],"sequence":2190662,"timestamp":"2021-07-15T03:00:17.722Z","symbol":"SPIUSD"}}
1626318017.750149: {"jsonrpc":"2.0","method":"updateOrderbook","params":{"ask":[{"price":"0.662654","size":"399061.9"}],"bid":[],"sequence":20584030,"timestamp":"2021-07-15T03:00:17.704Z","symbol":"XRPUSDT"}}
1626318017.763865: {"jsonrpc":"2.0","method":"updateOrderbook","params":{"ask":[{"price":"0.00000065973","size":"15229990"},{"price":"0.00000094569","size":"2768030"}],"bid":[],"sequence":10532221,"timestamp":"2021-07-15T03:00:17.696Z","symbol":"SCBTC"}}
1626318017.764981: {"jsonrpc":"2.0","method":"updateOrderbook","params":{"ask":[{"price":"0.00054597","size":"4.33"},{"price":"0.00054598","size":"0"}],"bid":[],"sequence":19513030,"timestamp":"2021-07-15T03:00:17.728Z","symbol":"UNIBTC"}}
1626318017.8496919: {"jsonrpc":"2.0","method":"updateOrderbook","params":{"ask":[],"bid":[{"price":"12.069","size":"5.8903"},{"price":"12.068","size":"0"},{"price":"12.060","size":"5.7321"}],"sequence":2190663,"timestamp":"2021-07-15T03:00:17.826Z","symbol":"SPIUSD"}}
1626318017.851348: {"jsonrpc":"2.0","method":"updateOrderbook","params":{"ask":[{"price":"0.662654","size":"399062.2"}],"bid":[],"sequence":20584031,"timestamp":"2021-07-15T03:00:17.809Z","symbol":"XRPUSDT"}}
1626318017.8726442: {"jsonrpc":"2.0","method":"updateOrderbook","params":{"ask":[{"price":"0.00000065973","size":"15230000"},{"price":"0.00000094569","size":"2768050"},{"price":"0.00000146767","size":"3222000"},{"price":"0.00000148986","size":"0"},{"price":"0.00000159009","size":"4634410"},{"price":"0.00000167678","size":"0"}],"bid":[{"price":"0.00000036515","size":"1000"},{"price":"0.00000036504","size":"0"},{"price":"0.00000036454","size":"284390"},{"price":"0.00000036392","size":"0"}],"sequence":10532222,"timestamp":"2021-07-15T03:00:17.789Z","symbol":"SCBTC"}}
1626318017.87271: {"jsonrpc":"2.0","method":"updateOrderbook","params":{"ask":[{"price":"0.00054822","size":"84.00"},{"price":"0.00054869","size":"0"}],"bid":[],"sequence":19513031,"timestamp":"2021-07-15T03:00:17.836Z","symbol":"UNIBTC"}}
1626318017.9459121: {"jsonrpc":"2.0","method":"updateOrderbook","params":{"ask":[],"bid":[{"price":"12.070","size":"5.7347"},{"price":"12.060","size":"0"}],"sequence":2190664,"timestamp":"2021-07-15T03:00:17.867Z","symbol":"SPIUSD"}}
1626318017.954609: {"jsonrpc":"2.0","method":"updateOrderbook","params":{"ask":[{"price":"0.662654","size":"399062.4"}],"bid":[],"sequence":20584032,"timestamp":"2021-07-15T03:00:17.894Z","symbol":"XRPUSDT"}}
1626318017.959944: {"jsonrpc":"2.0","method":"updateOrderbook","params":{"ask":[{"price":"0.00000065973","size":"15230020"},{"price":"0.00000094569","size":"2768060"}],"bid":[{"price":"0.00000034658","size":"4600"},{"price":"0.00000034622","size":"230000"}],"sequence":10532223,"timestamp":"2021-07-15T03:00:17.872Z","symbol":"SCBTC"}}
1626318017.9601212: {"jsonrpc":"2.0","method":"updateOrderbook","params":{"ask":[{"price":"0.00054593","size":"4.33"},{"price":"0.00054597","size":"0"}],"bid":[{"price":"0.00054580","size":"0"},{"price":"0.00054576","size":"5.18"},{"price":"0.00054566","size":"0"},{"price":"0.00054559","size":"9.62"},{"price":"0.00054417","size":"0"},{"price":"0.00054408","size":"1.17"}],"sequence":19513032,"timestamp":"2021-07-15T03:00:17.937Z","symbol":"UNIBTC"}}
1626318018.0624971: {"jsonrpc":"2.0","method":"updateOrderbook","params":{"ask":[{"price":"0.662654","size":"399062.8"},{"price":"0.702918","size":"228479.7"}],"bid":[],"sequence":20584033,"timestamp":"2021-07-15T03:00:18.006Z","symbol":"XRPUSDT"}}
1626318018.071171: {"jsonrpc":"2.0","method":"updateOrderbook","params":{"ask":[{"price":"0.00000041218","size":"0"},{"price":"0.00000041336","size":"1016210"},{"price":"0.00000043994","size":"0"},{"price":"0.00000044175","size":"1381850"},{"price":"0.00000065973","size":"15230040"},{"price":"0.00000088323","size":"0"},{"price":"0.00000088939","size":"2001500"},{"price":"0.00000094569","size":"2768080"},{"price":"0.00000124431","size":"0"},{"price":"0.00000124589","size":"2705250"},{"price":"0.00000146767","size":"0"},{"price":"0.00000146941","size":"3222000"},{"price":"0.00000159009","size":"0"},{"price":"0.00000161545","size":"4634410"}],"bid":[],"sequence":10532224,"timestamp":"2021-07-15T03:00:18.012Z","symbol":"SCBTC"}}
1626318018.07124: {"jsonrpc":"2.0","method":"updateOrderbook","params":{"ask":[{"price":"0.00068955","size":"1125.76"},{"price":"0.00077082","size":"0"}],"bid":[{"price":"0.00054286","size":"84.00"},{"price":"0.00054234","size":"0"}],"sequence":19513033,"timestamp":"2021-07-15T03:00:18.031Z","symbol":"UNIBTC"}}
1626318018.151124: {"jsonrpc":"2.0","method":"updateOrderbook","params":{"ask":[{"price":"0.662654","size":"399063.0"},{"price":"0.702918","size":"0"}],"bid":[],"sequence":20584034,"timestamp":"2021-07-15T03:00:18.075Z","symbol":"XRPUSDT"}}
1626318018.159884: {"jsonrpc":"2.0","method":"updateOrderbook","params":{"ask":[{"price":"0.00000036748","size":"255050"},{"price":"0.00000036784","size":"408320"},{"price":"0.00000036877","size":"0"},{"price":"0.00000036909","size":"0"},{"price":"0.00000065973","size":"15230060"},{"price":"0.00000088939","size":"0"},{"price":"0.00000089027","size":"2001500"},{"price":"0.00000094569","size":"2768090"}],"bid":[{"price":"0.00000036411","size":"384900"},{"price":"0.00000036354","size":"0"}],"sequence":10532225,"timestamp":"2021-07-15T03:00:18.139Z","symbol":"SCBTC"}}
1626318018.15995: {"jsonrpc":"2.0","method":"updateOrderbook","params":{"ask":[],"bid":[{"price":"0.00054576","size":"0"},{"price":"0.00054575","size":"5.18"}],"sequence":19513034,"timestamp":"2021-07-15T03:00:18.120Z","symbol":"UNIBTC"}}
1626318018.250197: {"jsonrpc":"2.0","method":"updateOrderbook","params":{"ask":[{"price":"0.641909","size":"347706.3"},{"price":"0.643681","size":"0"},{"price":"0.662654","size":"399063.4"}],"bid":[],"sequence":20584035,"timestamp":"2021-07-15T03:00:18.210Z","symbol":"XRPUSDT"}}
1626318018.263884: {"jsonrpc":"2.0","method":"updateOrderbook","params":{"ask":[{"price":"0.00000043202","size":"522810"},{"price":"0.00000043635","size":"0"},{"price":"0.00000054581","size":"757990"},{"price":"0.00000054811","size":"0"},{"price":"0.00000065973","size":"15230070"},{"price":"0.00000094569","size":"2768110"}],"bid":[{"price":"0.00000034658","size":"234600"},{"price":"0.00000034622","size":"0"}],"sequence":10532226,"timestamp":"2021-07-15T03:00:18.230Z","symbol":"SCBTC"}}
1626318018.2640588: {"jsonrpc":"2.0","method":"updateOrderbook","params":{"ask":[{"price":"0.00054593","size":"0"},{"price":"0.00054594","size":"4.33"},{"price":"0.00054621","size":"16.70"},{"price":"0.00054632","size":"0"}],"bid":[],"sequence":19513035,"timestamp":"2021-07-15T03:00:18.203Z","symbol":"UNIBTC"}}
1626318018.389641: {"jsonrpc":"2.0","method":"updateOrderbook","params":{"ask":[{"price":"0.662654","size":"399063.6"}],"bid":[],"sequence":20584036,"timestamp":"2021-07-15T03:00:18.277Z","symbol":"XRPUSDT"}}
1626318018.389768: {"jsonrpc":"2.0","method":"updateOrderbook","params":{"ask":[{"price":"0.00000041336","size":"0"},{"price":"0.00000041390","size":"1016210"},{"price":"0.00000044175","size":"0"},{"price":"0.00000044361","size":"1381850"},{"price":"0.00000065973","size":"15230080"},{"price":"0.00000089027","size":"0"},{"price":"0.00000089590","size":"2001500"},{"price":"0.00000094569","size":"2768120"},{"price":"0.00000124589","size":"0"},{"price":"0.00000124728","size":"2705250"},{"price":"0.00000146941","size":"0"},{"price":"0.00000147053","size":"3222000"},{"price":"0.00000384260","size":"7466230"},{"price":"0.00000472388","size":"0"}],"bid":[{"price":"0.00000034658","size":"4600"},{"price":"0.00000034622","size":"230000"}],"sequence":10532227,"timestamp":"2021-07-15T03:00:18.305Z","symbol":"SCBTC"}}
1626318018.390054: {"jsonrpc":"2.0","method":"updateOrderbook","params":{"ask":[{"price":"0.00054772","size":"331.40"},{"price":"0.00054811","size":"0"}],"bid":[{"price":"0.00054286","size":"0"},{"price":"0.00054234","size":"84.00"}],"sequence":19513036,"timestamp":"2021-07-15T03:00:18.327Z","symbol":"UNIBTC"}}
1626318018.459628: {"jsonrpc":"2.0","method":"updateOrderbook","params":{"ask":[{"price":"0.662654","size":"399064.0"}],"bid":[{"price":"0.581347","size":"195374.1"},{"price":"0.576549","size":"0"}],"sequence":20584037,"timestamp":"2021-07-15T03:00:18.408Z","symbol":"XRPUSDT"}}
1626318018.464036: {"jsonrpc":"2.0","method":"updateOrderbook","params":{"ask":[{"price":"0.00000065973","size":"15230100"},{"price":"0.00000094569","size":"2768140"},{"price":"0.00000095828","size":"2754880"},{"price":"0.00000095888","size":"0"}],"bid":[],"sequence":10532228,"timestamp":"2021-07-15T03:00:18.404Z","symbol":"SCBTC"}}
1626318018.550018: {"jsonrpc":"2.0","method":"updateOrderbook","params":{"ask":[{"price":"0.662654","size":"399064.3"}],"bid":[],"sequence":20584038,"timestamp":"2021-07-15T03:00:18.511Z","symbol":"XRPUSDT"}}
1626318018.5616572: {"jsonrpc":"2.0","method":"updateOrderbook","params":{"ask":[{"price":"0.00000065973","size":"15230120"},{"price":"0.00000094569","size":"2768150"}],"bid":[],"sequence":10532229,"timestamp":"2021-07-15T03:00:18.515Z","symbol":"SCBTC"}}
1626318018.566032: {"jsonrpc":"2.0","method":"updateOrderbook","params":{"ask":[],"bid":[{"price":"0.00054576","size":"5.18"},{"price":"0.00054575","size":"0"},{"price":"0.00054486","size":"0"},{"price":"0.00054460","size":"261.13"},{"price":"0.00054292","size":"0"},{"price":"0.00054241","size":"914.50"},{"price":"0.00053567","size":"0"},{"price":"0.00053397","size":"2974.71"}],"sequence":19513037,"timestamp":"2021-07-15T03:00:18.531Z","symbol":"UNIBTC"}}
1626318018.6521258: {"jsonrpc":"2.0","method":"updateOrderbook","params":{"ask":[{"price":"0.662654","size":"399064.6"},{"price":"0.702918","size":"228479.7"}],"bid":[{"price":"0.615238","size":"0"},{"price":"0.615195","size":"1337.0"},{"price":"0.614682","size":"0"},{"price":"0.614441","size":"1950.1"}],"sequence":20584039,"timestamp":"2021-07-15T03:00:18.593Z","symbol":"XRPUSDT"}}
1626318018.6677299: {"jsonrpc":"2.0","method":"updateOrderbook","params":{"ask":[{"price":"0.00000036910","size":"603920"},{"price":"0.00000037415","size":"661850"},{"price":"0.00000038125","size":"0"},{"price":"0.00000041214","size":"0"},{"price":"0.00000065973","size":"15230130"},{"price":"0.00000094569","size":"2768170"}],"bid":[],"sequence":10532230,"timestamp":"2021-07-15T03:00:18.620Z","symbol":"SCBTC"}}
1626318018.667781: {"jsonrpc":"2.0","method":"updateOrderbook","params":{"ask":[{"price":"0.00054590","size":"4.33"},{"price":"0.00054594","size":"0"},{"price":"0.00054654","size":"77.40"},{"price":"0.00054665","size":"0"},{"price":"0.00054671","size":"201.47"},{"price":"0.00054688","size":"0"}],"bid":[{"price":"0.00054576","size":"0"},{"price":"0.00054567","size":"5.18"},{"price":"0.00054559","size":"0"},{"price":"0.00054553","size":"0"},{"price":"0.00054548","size":"9.62"},{"price":"0.00054533","size":"18.03"},{"price":"0.00054531","size":"0"},{"price":"0.00054508","size":"17.87"}],"sequence":19513038,"timestamp":"2021-07-15T03:00:18.624Z","symbol":"UNIBTC"}}
1626318018.7520268: {"jsonrpc":"2.0","method":"updateOrderbook","params":{"ask":[{"price":"0.662654","size":"399064.9"}],"bid":[],"sequence":20584040,"timestamp":"2021-07-15T03:00:18.686Z","symbol":"XRPUSDT"}}
1626318018.761482: {"jsonrpc":"2.0","method":"updateOrderbook","params":{"ask":[{"price":"0.00000065973","size":"15230150"},{"price":"0.00000094569","size":"2768180"}],"bid":[],"sequence":10532231,"timestamp":"2021-07-15T03:00:18.732Z","symbol":"SCBTC"}}
1626318018.761624: {"jsonrpc":"2.0","method":"updateOrderbook","params":{"ask":[{"price":"0.00054586","size":"4.33"},{"price":"0.00054590","size":"0"},{"price":"0.00054768","size":"291.41"},{"price":"0.00054795","size":"0"},{"price":"0.00055097","size":"1244.50"},{"price":"0.00055157","size":"0"}],"bid":[{"price":"0.00054567","size":"0"},{"price":"0.00054566","size":"5.18"}],"sequence":19513039,"timestamp":"2021-07-15T03:00:18.741Z","symbol":"UNIBTC"}}
1626318018.853516: {"jsonrpc":"2.0","method":"updateOrderbook","params":{"ask":[{"price":"0.662654","size":"399065.2"}],"bid":[],"sequence":20584041,"timestamp":"2021-07-15T03:00:18.790Z","symbol":"XRPUSDT"}}
1626318018.866959: {"jsonrpc":"2.0","method":"updateOrderbook","params":{"ask":[{"price":"0.00000065973","size":"15230170"},{"price":"0.00000094569","size":"2768200"}],"bid":[],"sequence":10532232,"timestamp":"2021-07-15T03:00:18.839Z","symbol":"SCBTC"}}
1626318018.867098: {"jsonrpc":"2.0","method":"updateOrderbook","params":{"ask":[{"price":"0.00054602","size":"10.47"},{"price":"0.00054613","size":"0"},{"price":"0.00054664","size":"363.27"},{"price":"0.00054691","size":"0"},{"price":"0.00054716","size":"193.61"},{"price":"0.00054737","size":"0"}],"bid":[{"price":"0.00054466","size":"0"},{"price":"0.00054435","size":"275.31"}],"sequence":19513040,"timestamp":"2021-07-15T03:00:18.798Z","symbol":"UNIBTC"}}
1626318018.948858: {"jsonrpc":"2.0","method":"updateOrderbook","params":{"ask":[{"price":"0.662654","size":"399065.6"}],"bid":[{"price":"0.615662","size":"1591.6"},{"price":"0.615656","size":"0"}],"sequence":20584042,"timestamp":"2021-07-15T03:00:18.921Z","symbol":"XRPUSDT"}}
1626318018.96601: {"jsonrpc":"2.0","method":"updateOrderbook","params":{"ask":[{"price":"0.00000037415","size":"0"},{"price":"0.00000037470","size":"661850"},{"price":"0.00000044361","size":"0"},{"price":"0.00000044405","size":"1381850"},{"price":"0.00000065973","size":"15230180"},{"price":"0.00000089590","size":"0"},{"price":"0.00000089742","size":"2001500"},{"price":"0.00000094569","size":"2768210"},{"price":"0.00000384260","size":"0"},{"price":"0.00000384793","size":"7466230"}],"bid":[],"sequence":10532233,"timestamp":"2021-07-15T03:00:18.925Z","symbol":"SCBTC"}}
1626318018.966283: {"jsonrpc":"2.0","method":"updateOrderbook","params":{"ask":[{"price":"0.00054584","size":"4.33"},{"price":"0.00054586","size":"0"},{"price":"0.00054803","size":"0"},{"price":"0.00054870","size":"658.12"},{"price":"0.00055060","size":"0"},{"price":"0.00055133","size":"843.90"},{"price":"0.00055683","size":"0"},{"price":"0.00056011","size":"2539.46"}],"bid":[{"price":"0.00054566","size":"0"},{"price":"0.00054565","size":"5.18"},{"price":"0.00054549","size":"0"},{"price":"0.00054537","size":"18.33"},{"price":"0.00054516","size":"0"},{"price":"0.00054495","size":"80.24"},{"price":"0.00054485","size":"0"},{"price":"0.00054447","size":"196.86"}],"sequence":19513041,"timestamp":"2021-07-15T03:00:18.917Z","symbol":"UNIBTC"}}
1626318019.0518131: {"jsonrpc":"2.0","method":"updateOrderbook","params":{"ask":[{"price":"0.615747","size":"0"},{"price":"0.616285","size":"0"},{"price":"0.616410","size":"160.9"},{"price":"0.616627","size":"0"},{"price":"0.616896","size":"6433.6"},{"price":"0.617115","size":"0"},{"price":"0.617484","size":"0"},{"price":"0.617536","size":"4276.9"},{"price":"0.617909","size":"12316.2"},{"price":"0.662654","size":"399065.9"}],"bid":[{"price":"0.615715","size":"11000.0"},{"price":"0.615238","size":"1337.0"},{"price":"0.615195","size":"0"}],"sequence":20584043,"timestamp":"2021-07-15T03:00:19.012Z","symbol":"XRPUSDT"}}
1626318019.065057: {"jsonrpc":"2.0","method":"updateOrderbook","params":{"ask":[{"price":"0.00000065973","size":"15230200"},{"price":"0.00000094569","size":"2768230"}],"bid":[],"sequence":10532234,"timestamp":"2021-07-15T03:00:19.033Z","symbol":"SCBTC"}}
1626318019.068465: {"jsonrpc":"2.0","method":"updateOrderbook","params":{"ask":[{"price":"0.00054629","size":"66.20"},{"price":"0.00054642","size":"0"},{"price":"0.00054780","size":"375.71"},{"price":"0.00054802","size":"484.13"},{"price":"0.00054841","size":"0"},{"price":"0.00054870","size":"0"},{"price":"0.00054874","size":"0"},{"price":"0.00054918","size":"658.12"},{"price":"0.00055279","size":"0"},{"price":"0.00055346","size":"1811.87"},{"price":"0.00056011","size":"0"},{"price":"0.00056209","size":"2539.46"}],"bid":[],"sequence":19513042,"timestamp":"2021-07-15T03:00:19.041Z","symbol":"UNIBTC"}}
1626318019.151892: {"jsonrpc":"2.0","method":"updateOrderbook","params":{"ask":[{"price":"0.615742","size":"0"},{"price":"0.615756","size":"1331.7"},{"price":"0.617074","size":"0"},{"price":"0.617188","size":"7700.0"},{"price":"0.622068","size":"0"},{"price":"0.626104","size":"272131.6"},{"price":"0.641909","size":"0"},{"price":"0.648232","size":"347706.3"},{"price":"0.657744","size":"0"},{"price":"0.659380","size":"485414.3"},{"price":"0.662654","size":"399066.2"},{"price":"0.666845","size":"229002.7"},{"price":"0.672296","size":"0"},{"price":"0.841249","size":"324970.5"},{"price":"0.848572","size":"0"}],"bid":[{"price":"0.615715","size":"0"},{"price":"0.615700","size":"11000.0"},{"price":"0.615688","size":"1591.6"},{"price":"0.615662","size":"0"}],"sequence":20584044,"timestamp":"2021-07-15T03:00:19.132Z","symbol":"XRPUSDT"}}
1626318019.162904: {"jsonrpc":"2.0","method":"updateOrderbook","params":{"ask":[{"price":"0.00000065973","size":"15230210"},{"price":"0.00000094569","size":"2768240"}],"bid":[{"price":"0.00000034658","size":"234600"},{"price":"0.00000034622","size":"0"}],"sequence":10532235,"timestamp":"2021-07-15T03:00:19.140Z","symbol":"SCBTC"}}
1626318019.255741: {"jsonrpc":"2.0","method":"updateOrderbook","params":{"ask":[{"price":"0.615756","size":"0"},{"price":"0.615779","size":"1331.7"},{"price":"0.616078","size":"0"},{"price":"0.616239","size":"495.8"},{"price":"0.616286","size":"0"},{"price":"0.616419","size":"508.4"},{"price":"0.616488","size":"2136.6"},{"price":"0.616533","size":"0"},{"price":"0.616685","size":"0"},{"price":"0.616785","size":"1800.0"},{"price":"0.616809","size":"0"},{"price":"0.616923","size":"5500.0"},{"price":"0.617107","size":"523.2"},{"price":"0.617168","size":"2281.9"},{"price":"0.617424","size":"0"},{"price":"0.617504","size":"7145.7"},{"price":"0.617562","size":"0"},{"price":"0.618034","size":"0"},{"price":"0.628174","size":"0"},{"price":"0.629622","size":"129038.8"},{"price":"0.652912","size":"0"},{"price":"0.654112","size":"181214.3"},{"price":"0.662654","size":"399066.5"},{"price":"0.702918","size":"0"}],"bid":[{"price":"0.615688","size":"0"},{"price":"0.615685","size":"1591.6"},{"price":"0.615561","size":"2955.8"},{"price":"0.615513","size":"0"}],"sequence":20584045,"timestamp":"2021-07-15T03:00:19.242Z","symbol":"XRPUSDT"}}
1626318019.277739: {"jsonrpc":"2.0","method":"updateOrderbook","params":{"ask":[{"price":"0.00000065973","size":"15230220"},{"price":"0.00000094569","size":"2768250"}],"bid":[],"sequence":10532236,"timestamp":"2021-07-15T03:00:19.193Z","symbol":"SCBTC"}}
1626318019.352483: {"jsonrpc":"2.0","method":"updateOrderbook","params":{"ask":[{"price":"0.615767","size":"1331.7"},{"price":"0.615779","size":"0"},{"price":"0.662654","size":"399066.7"}],"bid":[{"price":"0.615701","size":"11000.0"},{"price":"0.615700","size":"0"},{"price":"0.615690","size":"1596.5"},{"price":"0.615685","size":"0"}],"sequence":20584046,"timestamp":"2021-07-15T03:00:19.304Z","symbol":"XRPUSDT"}}
1626318019.369427: {"jsonrpc":"2.0","method":"updateOrderbook","params":{"ask":[{"price":"0.00000065973","size":"15230230"},{"price":"0.00000077938","size":"2003810"},{"price":"0.00000078433","size":"0"},{"price":"0.00000094569","size":"2768260"}],"bid":[{"price":"0.00000034658","size":"4600"},{"price":"0.00000034622","size":"230000"}],"sequence":10532237,"timestamp":"2021-07-15T03:00:19.258Z","symbol":"SCBTC"}}
1626318019.369448: {"jsonrpc":"2.0","method":"updateOrderbook","params":{"ask":[],"bid":[{"price":"0.00054566","size":"5.18"},{"price":"0.00054565","size":"0"},{"price":"0.00054480","size":"261.13"},{"price":"0.00054460","size":"0"}],"sequence":19513043,"timestamp":"2021-07-15T03:00:19.289Z","symbol":"UNIBTC"}}
1626318019.448768: {"jsonrpc":"2.0","method":"updateOrderbook","params":{"ask":[{"price":"0.615759","size":"11000.0"},{"price":"0.615764","size":"1331.7"},{"price":"0.615767","size":"0"},{"price":"0.616300","size":"160.9"},{"price":"0.616410","size":"0"},{"price":"0.624269","size":"272131.6"},{"price":"0.626104","size":"0"},{"price":"0.629622","size":"0"},{"price":"0.631987","size":"129038.8"},{"price":"0.654112","size":"0"},{"price":"0.656074","size":"181214.3"},{"price":"0.662654","size":"399067.0"}],"bid":[{"price":"0.615701","size":"0"}],"sequence":20584047,"timestamp":"2021-07-15T03:00:19.394Z","symbol":"XRPUSDT"}}
1626318019.458726: {"jsonrpc":"2.0","method":"updateOrderbook","params":{"ask":[{"price":"0.00000065973","size":"15230250"},{"price":"0.00000094569","size":"2768270"}],"bid":[{"price":"0.00000032828","size":"1993120"},{"price":"0.00000022599","size":"0"},{"price":"0.00000004908","size":"2752080"},{"price":"0.00000000436","size":"0"}],"sequence":10532238,"timestamp":"2021-07-15T03:00:19.358Z","symbol":"SCBTC"}}
1626318019.465156: {"jsonrpc":"2.0","method":"updateOrderbook","params":{"ask":[{"price":"0.00054867","size":"587.36"},{"price":"0.00054922","size":"805.27"},{"price":"0.00054947","size":"0"},{"price":"0.00055065","size":"0"}],"bid":[],"sequence":19513044,"timestamp":"2021-07-15T03:00:19.392Z","symbol":"UNIBTC"}}
1626318019.550071: {"jsonrpc":"2.0","method":"updateOrderbook","params":{"ask":[{"price":"0.615764","size":"0"},{"price":"0.615767","size":"1331.7"},{"price":"0.616853","size":"5500.0"},{"price":"0.616923","size":"0"},{"price":"0.662654","size":"399067.4"}],"bid":[],"sequence":20584048,"timestamp":"2021-07-15T03:00:19.531Z","symbol":"XRPUSDT"}}
1626318019.566908: {"jsonrpc":"2.0","method":"updateOrderbook","params":{"ask":[{"price":"0.00000065973","size":"15230270"},{"price":"0.00000089742","size":"0"},{"price":"0.00000089834","size":"2001500"},{"price":"0.00000094569","size":"2768300"},{"price":"0.00000384793","size":"0"},{"price":"0.00000384932","size":"7466230"}],"bid":[],"sequence":10532239,"timestamp":"2021-07-15T03:00:19.527Z","symbol":"SCBTC"}}
1626318019.566931: {"jsonrpc":"2.0","method":"updateOrderbook","params":{"ask":[{"price":"0.00054584","size":"0"},{"price":"0.00054586","size":"4.33"}],"bid":[{"price":"0.00054566","size":"0"},{"price":"0.00054564","size":"5.18"}],"sequence":19513045,"timestamp":"2021-07-15T03:00:19.512Z","symbol":"UNIBTC"}}
1626318019.65958: {"jsonrpc":"2.0","method":"updateOrderbook","params":{"ask":[{"price":"0.616323","size":"0"},{"price":"0.616354","size":"6528.8"},{"price":"0.662654","size":"399067.7"}],"bid":[{"price":"0.615253","size":"5489.4"},{"price":"0.615238","size":"0"},{"price":"0.615237","size":"0"},{"price":"0.615195","size":"1337.0"}],"sequence":20584049,"timestamp":"2021-07-15T03:00:19.619Z","symbol":"XRPUSDT"}}
1626318019.6837928: {"jsonrpc":"2.0","method":"updateOrderbook","params":{"ask":[{"price":"0.00000037470","size":"0"},{"price":"0.00000037542","size":"661850"},{"price":"0.00000044405","size":"0"},{"price":"0.00000044539","size":"1381850"},{"price":"0.00000065973","size":"15230280"},{"price":"0.00000089834","size":"0"},{"price":"0.00000090214","size":"2001500"},{"price":"0.00000094569","size":"2768310"},{"price":"0.00000124728","size":"0"},{"price":"0.00000124862","size":"2705250"},{"price":"0.00000147053","size":"0"},{"price":"0.00000147160","size":"3222000"},{"price":"0.00000384932","size":"0"},{"price":"0.00000385651","size":"7466230"}],"bid":[],"sequence":10532240,"timestamp":"2021-07-15T03:00:19.600Z","symbol":"SCBTC"}}
1626318019.68382: {"jsonrpc":"2.0","method":"updateOrderbook","params":{"ask":[{"price":"0.00054584","size":"4.33"},{"price":"0.00054586","size":"0"}],"bid":[{"price":"0.00054533","size":"0"},{"price":"0.00054495","size":"0"},{"price":"0.00054494","size":"18.03"},{"price":"0.00054458","size":"80.24"},{"price":"0.00054317","size":"0"},{"price":"0.00054267","size":"929.35"}],"sequence":19513046,"timestamp":"2021-07-15T03:00:19.590Z","symbol":"UNIBTC"}}
1626318019.746358: {"jsonrpc":"2.0","method":"updateOrderbook","params":{"ask":[],"bid":[{"price":"12.069","size":"0"}],"sequence":2190665,"timestamp":"2021-07-15T03:00:19.702Z","symbol":"SPIUSD"}}
1626318019.7631161: {"jsonrpc":"2.0","method":"updateOrderbook","params":{"ask":[{"price":"0.662654","size":"399068.0"}],"bid":[],"sequence":20584050,"timestamp":"2021-07-15T03:00:19.722Z","symbol":"XRPUSDT"}}
1626318019.7798772: {"jsonrpc":"2.0","method":"updateOrderbook","params":{"ask":[{"price":"0.00000065973","size":"15230300"},{"price":"0.00000094569","size":"2768320"},{"price":"0.00000273316","size":"4472830"},{"price":"0.00000286068","size":"0"}],"bid":[],"sequence":10532241,"timestamp":"2021-07-15T03:00:19.711Z","symbol":"SCBTC"}}
1626318019.7800698: {"jsonrpc":"2.0","method":"updateOrderbook","params":{"ask":[{"price":"0.00055241","size":"1757.02"},{"price":"0.00056173","size":"0"}],"bid":[{"price":"0.00054564","size":"0"},{"price":"0.00054562","size":"5.18"},{"price":"0.00054548","size":"0"},{"price":"0.00054541","size":"9.62"}],"sequence":19513047,"timestamp":"2021-07-15T03:00:19.699Z","symbol":"UNIBTC"}}
1626318019.854253: {"jsonrpc":"2.0","method":"updateOrderbook","params":{"ask":[],"bid":[{"price":"12.071","size":"5.8893"},{"price":"12.070","size":"0"},{"price":"12.060","size":"5.7381"}],"sequence":2190666,"timestamp":"2021-07-15T03:00:19.773Z","symbol":"SPIUSD"}}
1626318019.889338: {"jsonrpc":"2.0","method":"updateOrderbook","params":{"ask":[{"price":"0.615764","size":"1331.7"},{"price":"0.615767","size":"0"},{"price":"0.662654","size":"399068.1"}],"bid":[],"sequence":20584051,"timestamp":"2021-07-15T03:00:19.768Z","symbol":"XRPUSDT"}}
1626318019.9587562: {"jsonrpc":"2.0","method":"updateOrderbook","params":{"ask":[{"price":"0.00000065973","size":"15230320"},{"price":"0.00000094569","size":"2768340"}],"bid":[],"sequence":10532242,"timestamp":"2021-07-15T03:00:19.815Z","symbol":"SCBTC"}}
1626318019.969884: {"jsonrpc":"2.0","method":"updateOrderbook","params":{"ask":[{"price":"0.00054582","size":"4.33"},{"price":"0.00054584","size":"0"}],"bid":[{"price":"0.00054562","size":"0"},{"price":"0.00054558","size":"5.18"},{"price":"0.00054511","size":"0"},{"price":"0.00054508","size":"0"},{"price":"0.00054505","size":"0"},{"price":"0.00054484","size":"17.87"},{"price":"0.00054480","size":"199.39"},{"price":"0.00054460","size":"21.05"},{"price":"0.00054457","size":"500.70"},{"price":"0.00054241","size":"0"},{"price":"0.00054226","size":"914.50"},{"price":"0.00053397","size":"0"},{"price":"0.00053242","size":"2974.71"}],"sequence":19513048,"timestamp":"2021-07-15T03:00:19.825Z","symbol":"UNIBTC"}}
1626318019.999525: {"jsonrpc":"2.0","method":"updateOrderbook","params":{"ask":[],"bid":[{"price":"12.072","size":"5.7415"},{"price":"12.060","size":"0"}],"sequence":2190667,"timestamp":"2021-07-15T03:00:19.870Z","symbol":"SPIUSD"}}
1626318020.012098: {"jsonrpc":"2.0","method":"updateOrderbook","params":{"ask":[{"price":"0.662654","size":"399068.5"}],"bid":[],"sequence":20584052,"timestamp":"2021-07-15T03:00:19.876Z","symbol":"XRPUSDT"}}
1626318020.041785: {"jsonrpc":"2.0","method":"updateOrderbook","params":{"ask":[{"price":"0.00000065973","size":"15230330"},{"price":"0.00000094569","size":"2768350"},{"price":"0.00000273316","size":"0"},{"price":"0.00000283983","size":"4472830"}],"bid":[{"price":"0.00000036534","size":"0"},{"price":"0.00000036526","size":"28670"},{"price":"0.00000036514","size":"0"},{"price":"0.00000036504","size":"110390"},{"price":"0.00000032828","size":"0"},{"price":"0.00000032029","size":"1993120"},{"price":"0.00000004908","size":"0"},{"price":"0.00000004259","size":"2752080"}],"sequence":10532243,"timestamp":"2021-07-15T03:00:19.907Z","symbol":"SCBTC"}}
1626318020.052531: {"jsonrpc":"2.0","method":"updateOrderbook","params":{"ask":[{"price":"0.00056209","size":"0"},{"price":"0.00056345","size":"2539.46"},{"price":"0.00059460","size":"2343.84"},{"price":"0.00065925","size":"0"},{"price":"0.00078428","size":"3484.36"},{"price":"0.00080159","size":"0"}],"bid":[{"price":"0.00054558","size":"0"},{"price":"0.00054557","size":"5.18"},{"price":"0.00054226","size":"0"},{"price":"0.00054173","size":"914.50"},{"price":"0.00053242","size":"0"},{"price":"0.00052895","size":"2974.71"}],"sequence":19513049,"timestamp":"2021-07-15T03:00:19.937Z","symbol":"UNIBTC"}}
1626318020.075457: {"jsonrpc":"2.0","method":"updateOrderbook","params":{"ask":[{"price":"0.662654","size":"399068.8"}],"bid":[],"sequence":20584053,"timestamp":"2021-07-15T03:00:19.993Z","symbol":"XRPUSDT"}}
1626318020.086951: {"jsonrpc":"2.0","method":"updateOrderbook","params":{"ask":[{"price":"0.00000065973","size":"15230350"},{"price":"0.00000094569","size":"2768370"}],"bid":[{"price":"0.00000036515","size":"0"},{"price":"0.00000036505","size":"1000"}],"sequence":10532244,"timestamp":"2021-07-15T03:00:20.003Z","symbol":"SCBTC"}}
1626318020.087143: {"jsonrpc":"2.0","method":"updateOrderbook","params":{"ask":[{"price":"0.00054918","size":"0"},{"price":"0.00054961","size":"658.12"},{"price":"0.00056345","size":"0"},{"price":"0.00056453","size":"2539.46"}],"bid":[{"price":"0.00054558","size":"5.18"},{"price":"0.00054557","size":"0"},{"price":"0.00054537","size":"0"},{"price":"0.00054527","size":"18.33"}],"sequence":19513050,"timestamp":"2021-07-15T03:00:20.013Z","symbol":"UNIBTC"}}
1626318020.154038: {"jsonrpc":"2.0","method":"updateOrderbook","params":{"ask":[],"bid":[{"price":"12.073","size":"5.8883"},{"price":"12.071","size":"0"}],"sequence":2190668,"timestamp":"2021-07-15T03:00:20.122Z","symbol":"SPIUSD"}}
1626318020.1542542: {"jsonrpc":"2.0","method":"updateOrderbook","params":{"ask":[{"price":"0.662654","size":"399069.3"}],"bid":[{"price":"0.615691","size":"11000.0"}],"sequence":20584054,"timestamp":"2021-07-15T03:00:20.141Z","symbol":"XRPUSDT"}}
1626318020.18137: {"jsonrpc":"2.0","method":"updateOrderbook","params":{"ask":[{"price":"0.00000065973","size":"15230370"},{"price":"0.00000094569","size":"0"},{"price":"0.00000094570","size":"2768390"}],"bid":[],"sequence":10532245,"timestamp":"2021-07-15T03:00:20.114Z","symbol":"SCBTC"}}
1626318020.181387: {"jsonrpc":"2.0","method":"updateOrderbook","params":{"ask":[{"price":"0.00054580","size":"4.33"},{"price":"0.00054582","size":"0"},{"price":"0.00054609","size":"16.70"},{"price":"0.00054621","size":"0"},{"price":"0.00054641","size":"18.88"},{"price":"0.00054650","size":"0"},{"price":"0.00056453","size":"0"},{"price":"0.00056934","size":"2539.46"}],"bid":[{"price":"0.00054558","size":"0"},{"price":"0.00054553","size":"5.18"},{"price":"0.00054541","size":"0"},{"price":"0.00054534","size":"9.62"},{"price":"0.00054509","size":"0"},{"price":"0.00054480","size":"268.62"},{"price":"0.00054220","size":"914.50"},{"price":"0.00054173","size":"0"}],"sequence":19513051,"timestamp":"2021-07-15T03:00:20.138Z","symbol":"UNIBTC"}}
1626318020.248234: {"jsonrpc":"2.0","method":"updateOrderbook","params":{"ask":[],"bid":[{"price":"12.074","size":"5.7479"},{"price":"12.072","size":"0"}],"sequence":2190669,"timestamp":"2021-07-15T03:00:20.207Z","symbol":"SPIUSD"}}
1626318020.260776: {"jsonrpc":"2.0","method":"updateOrderbook","params":{"ask":[{"price":"0.615752","size":"11000.0"},{"price":"0.615759","size":"0"},{"price":"0.662654","size":"399069.4"},{"price":"0.702918","size":"228479.7"}],"bid":[{"price":"0.615691","size":"0"},{"price":"0.615690","size":"4.9"},{"price":"0.615685","size":"1591.6"}],"sequence":20584055,"timestamp":"2021-07-15T03:00:20.176Z","symbol":"XRPUSDT"}}
1626318020.262843: {"jsonrpc":"2.0","method":"updateOrderbook","params":{"ask":[{"price":"0.00000065973","size":"15230380"},{"price":"0.00000094570","size":"2768410"}],"bid":[],"sequence":10532246,"timestamp":"2021-07-15T03:00:20.196Z","symbol":"SCBTC"}}
1626318020.268146: {"jsonrpc":"2.0","method":"updateOrderbook","params":{"ask":[{"price":"0.00054578","size":"4.33"},{"price":"0.00054580","size":"0"}],"bid":[{"price":"0.00054553","size":"0"},{"price":"0.00054552","size":"5.18"},{"price":"0.00054490","size":"72.79"},{"price":"0.00054457","size":"261.13"},{"price":"0.00054455","size":"353.16"},{"price":"0.00054434","size":"417.56"},{"price":"0.00054416","size":"0"},{"price":"0.00054398","size":"0"},{"price":"0.00054382","size":"345.92"},{"price":"0.00054349","size":"269.93"},{"price":"0.00054321","size":"331.21"},{"price":"0.00054220","size":"0"},{"price":"0.00054175","size":"914.50"},{"price":"0.00053050","size":"0"},{"price":"0.00052999","size":"2974.71"},{"price":"0.00052895","size":"0"}],"sequence":19513052,"timestamp":"2021-07-15T03:00:20.241Z","symbol":"UNIBTC"}}
1626318020.353375: {"jsonrpc":"2.0","method":"updateOrderbook","params":{"ask":[{"price":"0.615752","size":"0"},{"price":"0.662654","size":"399069.8"}],"bid":[{"price":"0.615690","size":"11004.9"},{"price":"0.615254","size":"1337.0"},{"price":"0.615195","size":"0"}],"sequence":20584056,"timestamp":"2021-07-15T03:00:20.305Z","symbol":"XRPUSDT"}}
1626318020.3625338: {"jsonrpc":"2.0","method":"updateOrderbook","params":{"ask":[{"price":"0.00000065973","size":"15230400"},{"price":"0.00000094570","size":"2768430"}],"bid":[],"sequence":10532247,"timestamp":"2021-07-15T03:00:20.302Z","symbol":"SCBTC"}}
1626318020.371233: {"jsonrpc":"2.0","method":"updateOrderbook","params":{"ask":[],"bid":[{"price":"0.00054554","size":"5.18"},{"price":"0.00054552","size":"0"},{"price":"0.00054515","size":"18.03"},{"price":"0.00054496","size":"80.24"},{"price":"0.00054494","size":"0"},{"price":"0.00054458","size":"0"},{"price":"0.00052896","size":"443.78"}],"sequence":19513053,"timestamp":"2021-07-15T03:00:20.310Z","symbol":"UNIBTC"}}
1626318020.449718: {"jsonrpc":"2.0","method":"updateOrderbook","params":{"ask":[{"price":"0.615739","size":"11000.0"},{"price":"0.662654","size":"399070.1"}],"bid":[{"price":"0.615690","size":"4.9"},{"price":"0.615254","size":"0"},{"price":"0.615195","size":"1337.0"}],"sequence":20584057,"timestamp":"2021-07-15T03:00:20.410Z","symbol":"XRPUSDT"}}
1626318020.470307: {"jsonrpc":"2.0","method":"updateOrderbook","params":{"ask":[{"price":"0.00000042892","size":"522810"},{"price":"0.00000043202","size":"0"},{"price":"0.00000054417","size":"757990"},{"price":"0.00000054581","size":"0"},{"price":"0.00000065973","size":"15230420"},{"price":"0.00000094570","size":"2768450"},{"price":"0.00000124775","size":"2705250"},{"price":"0.00000124862","size":"0"},{"price":"0.00000147091","size":"3222000"},{"price":"0.00000147160","size":"0"}],"bid":[{"price":"0.00000035817","size":"0"}],"sequence":10532248,"timestamp":"2021-07-15T03:00:20.396Z","symbol":"SCBTC"}}
1626318020.470602: {"jsonrpc":"2.0","method":"updateOrderbook","params":{"ask":[{"price":"0.00054688","size":"169.84"},{"price":"0.00054718","size":"0"},{"price":"0.00054719","size":"250.69"},{"price":"0.00054763","size":"0"}],"bid":[],"sequence":19513054,"timestamp":"2021-07-15T03:00:20.362Z","symbol":"UNIBTC"}}
1626318020.579104: {"jsonrpc":"2.0","method":"updateOrderbook","params":{"ask":[{"price":"0.662654","size":"399070.2"}],"bid":[],"sequence":20584058,"timestamp":"2021-07-15T03:00:20.457Z","symbol":"XRPUSDT"}}
1626318020.579159: {"jsonrpc":"2.0","method":"updateOrderbook","params":{"ask":[{"price":"0.00000065973","size":"15230440"},{"price":"0.00000094570","size":"2768470"}],"bid":[],"sequence":10532249,"timestamp":"2021-07-15T03:00:20.503Z","symbol":"SCBTC"}}
1626318020.579185: {"jsonrpc":"2.0","method":"updateOrderbook","params":{"ask":[{"price":"0.00054578","size":"0"},{"price":"0.00054581","size":"4.33"},{"price":"0.00054618","size":"66.20"},{"price":"0.00054629","size":"199.63"},{"price":"0.00054639","size":"296.51"},{"price":"0.00054653","size":"0"},{"price":"0.00054664","size":"66.76"},{"price":"0.00059460","size":"0"},{"price":"0.00060103","size":"2343.84"},{"price":"0.00078428","size":"0"},{"price":"0.00078698","size":"3484.36"}],"bid":[{"price":"0.00054554","size":"0"},{"price":"0.00054552","size":"5.18"},{"price":"0.00052896","size":"0"}],"sequence":19513055,"timestamp":"2021-07-15T03:00:20.530Z","symbol":"UNIBTC"}}
1626318020.6610649: {"jsonrpc":"2.0","method":"updateOrderbook","params":{"ask":[],"bid":[{"price":"12.075","size":"5.8874"},{"price":"12.073","size":"0"}],"sequence":2190670,"timestamp":"2021-07-15T03:00:20.620Z","symbol":"SPIUSD"}}
1626318020.684205: {"jsonrpc":"2.0","method":"updateOrderbook","params":{"ask":[{"price":"0.662654","size":"399070.6"}],"bid":[],"sequence":20584059,"timestamp":"2021-07-15T03:00:20.564Z","symbol":"XRPUSDT"}}
1626318020.684335: {"jsonrpc":"2.0","method":"updateOrderbook","params":{"ask":[{"price":"0.00000065973","size":"15230460"},{"price":"0.00000094570","size":"2768480"}],"bid":[{"price":"0.00000035843","size":"9990"}],"sequence":10532250,"timestamp":"2021-07-15T03:00:20.592Z","symbol":"SCBTC"}}
1626318020.684439: {"jsonrpc":"2.0","method":"updateOrderbook","params":{"ask":[{"price":"0.00055656","size":"0"}],"bid":[{"price":"0.00054555","size":"5.18"},{"price":"0.00054552","size":"0"},{"price":"0.00053050","size":"442.49"}],"sequence":19513056,"timestamp":"2021-07-15T03:00:20.639Z","symbol":"UNIBTC"}}
1626318020.752092: {"jsonrpc":"2.0","method":"updateOrderbook","params":{"ask":[],"bid":[{"price":"12.076","size":"5.7543"},{"price":"12.074","size":"0"}],"sequence":2190671,"timestamp":"2021-07-15T03:00:20.683Z","symbol":"SPIUSD"}}
1626318020.769214: {"jsonrpc":"2.0","method":"updateOrderbook","params":{"ask":[{"price":"0.662654","size":"399070.9"}],"bid":[],"sequence":20584060,"timestamp":"2021-07-15T03:00:20.667Z","symbol":"XRPUSDT"}}
1626318020.769274: {"jsonrpc":"2.0","method":"updateOrderbook","params":{"ask":[{"price":"0.00000065973","size":"15230480"},{"price":"0.00000094570","size":"2768500"}],"bid":[],"sequence":10532251,"timestamp":"2021-07-15T03:00:20.702Z","symbol":"SCBTC"}}
1626318020.769383: {"jsonrpc":"2.0","method":"updateOrderbook","params":{"ask":[],"bid":[{"price":"0.00054556","size":"5.18"},{"price":"0.00054555","size":"0"}],"sequence":19513057,"timestamp":"2021-07-15T03:00:20.669Z","symbol":"UNIBTC"}}
1626318020.874639: {"jsonrpc":"2.0","method":"updateOrderbook","params":{"ask":[{"price":"0.662654","size":"399071.3"}],"bid":[],"sequence":20584061,"timestamp":"2021-07-15T03:00:20.804Z","symbol":"XRPUSDT"}}
1626318020.8746939: {"jsonrpc":"2.0","method":"updateOrderbook","params":{"ask":[{"price":"0.00000065973","size":"15230500"},{"price":"0.00000094570","size":"2768530"}],"bid":[],"sequence":10532252,"timestamp":"2021-07-15T03:00:20.812Z","symbol":"SCBTC"}}
1626318020.874719: {"jsonrpc":"2.0","method":"updateOrderbook","params":{"ask":[],"bid":[{"price":"0.00053050","size":"443.28"}],"sequence":19513058,"timestamp":"2021-07-15T03:00:20.840Z","symbol":"UNIBTC"}}
1626318020.962324: {"jsonrpc":"2.0","method":"updateOrderbook","params":{"ask":[{"price":"0.639732","size":"1.2"},{"price":"0.662654","size":"399071.6"}],"bid":[],"sequence":20584062,"timestamp":"2021-07-15T03:00:20.939Z","symbol":"XRPUSDT"}}
1626318020.980211: {"jsonrpc":"2.0","method":"updateOrderbook","params":{"ask":[{"price":"0.00000065973","size":"15230520"},{"price":"0.00000094570","size":"2768550"}],"bid":[],"sequence":10532253,"timestamp":"2021-07-15T03:00:20.918Z","symbol":"SCBTC"}}
1626318020.980351: {"jsonrpc":"2.0","method":"updateOrderbook","params":{"ask":[{"price":"0.00054577","size":"4.33"},{"price":"0.00054581","size":"0"}],"bid":[{"price":"0.00054556","size":"0"},{"price":"0.00054555","size":"5.18"},{"price":"0.00054523","size":"0"},{"price":"0.00054501","size":"18.61"}],"sequence":19513059,"timestamp":"2021-07-15T03:00:20.937Z","symbol":"UNIBTC"}}
1626318021.052278: {"jsonrpc":"2.0","method":"updateOrderbook","params":{"ask":[{"price":"0.662654","size":"399072.0"}],"bid":[],"sequence":20584063,"timestamp":"2021-07-15T03:00:21.028Z","symbol":"XRPUSDT"}}
1626318021.1884658: {"jsonrpc":"2.0","method":"updateOrderbook","params":{"ask":[{"price":"0.00000065973","size":"15230540"},{"price":"0.00000094570","size":"2768570"}],"bid":[],"sequence":10532254,"timestamp":"2021-07-15T03:00:21.027Z","symbol":"SCBTC"}}
1626318021.190994: {"jsonrpc":"2.0","method":"updateOrderbook","params":{"ask":[],"bid":[{"price":"0.00052999","size":"0"},{"price":"0.00052836","size":"2974.71"}],"sequence":19513060,"timestamp":"2021-07-15T03:00:21.031Z","symbol":"UNIBTC"}}
1626318021.210756: {"jsonrpc":"2.0","method":"updateOrderbook","params":{"ask":[],"bid":[{"price":"12.075","size":"0"}],"sequence":2190672,"timestamp":"2021-07-15T03:00:21.127Z","symbol":"SPIUSD"}}
1626318021.225548: {"jsonrpc":"2.0","method":"updateOrderbook","params":{"ask":[{"price":"0.635952","size":"1.2"},{"price":"0.662654","size":"399072.1"}],"bid":[],"sequence":20584064,"timestamp":"2021-07-15T03:00:21.071Z","symbol":"XRPUSDT"}}
1626318021.2256799: {"jsonrpc":"2.0","method":"updateOrderbook","params":{"ask":[{"price":"0.00000065973","size":"15230560"},{"price":"0.00000094570","size":"2768590"}],"bid":[],"sequence":10532255,"timestamp":"2021-07-15T03:00:21.137Z","symbol":"SCBTC"}}
1626318021.246965: {"jsonrpc":"2.0","method":"updateOrderbook","params":{"ask":[],"bid":[{"price":"12.077","size":"5.8864"}],"sequence":2190673,"timestamp":"2021-07-15T03:00:21.181Z","symbol":"SPIUSD"}}
1626318021.2591722: {"jsonrpc":"2.0","method":"updateOrderbook","params":{"ask":[{"price":"0.632172","size":"1.2"},{"price":"0.662654","size":"399072.5"}],"bid":[],"sequence":20584065,"timestamp":"2021-07-15T03:00:21.213Z","symbol":"XRPUSDT"}}
1626318021.259201: {"jsonrpc":"2.0","method":"updateOrderbook","params":{"ask":[{"price":"0.00000065973","size":"15230570"},{"price":"0.00000094560","size":"2756060"},{"price":"0.00000094570","size":"0"}],"bid":[{"price":"0.00000036564","size":"28670"},{"price":"0.00000036526","size":"0"},{"price":"0.00000036525","size":"110390"},{"price":"0.00000036504","size":"0"}],"sequence":10532256,"timestamp":"2021-07-15T03:00:21.198Z","symbol":"SCBTC"}}
1626318021.267393: {"jsonrpc":"2.0","method":"updateOrderbook","params":{"ask":[],"bid":[{"price":"0.00054556","size":"5.18"},{"price":"0.00054555","size":"0"}],"sequence":19513061,"timestamp":"2021-07-15T03:00:21.217Z","symbol":"UNIBTC"}}
1626318021.352837: {"jsonrpc":"2.0","method":"updateOrderbook","params":{"ask":[],"bid":[{"price":"12.076","size":"0"},{"price":"12.060","size":"5.7607"}],"sequence":2190674,"timestamp":"2021-07-15T03:00:21.272Z","symbol":"SPIUSD"}}
1626318021.359947: {"jsonrpc":"2.0","method":"updateOrderbook","params":{"ask":[{"price":"0.628392","size":"1.2"},{"price":"0.662654","size":"399072.9"}],"bid":[],"sequence":20584066,"timestamp":"2021-07-15T03:00:21.336Z","symbol":"XRPUSDT"}}
1626318021.372401: {"jsonrpc":"2.0","method":"updateOrderbook","params":{"ask":[{"price":"0.00000147008","size":"3222000"},{"price":"0.00000147091","size":"0"}],"bid":[{"price":"0.00000036526","size":"1000"},{"price":"0.00000036505","size":"0"},{"price":"0.00000034658","size":"234600"},{"price":"0.00000034622","size":"0"}],"sequence":10532257,"timestamp":"2021-07-15T03:00:21.339Z","symbol":"SCBTC"}}
1626318021.375551: {"jsonrpc":"2.0","method":"updateOrderbook","params":{"ask":[{"price":"0.00054649","size":"18.19"},{"price":"0.00054665","size":"72.32"},{"price":"0.00054666","size":"0"},{"price":"0.00054682","size":"0"},{"price":"0.00055868","size":"0"},{"price":"0.00057237","size":"881.76"},{"price":"0.00068955","size":"0"},{"price":"0.00074841","size":"1125.76"},{"price":"0.00083296","size":"0"},{"price":"0.00084011","size":"1585.64"}],"bid":[{"price":"0.00053050","size":"0.79"}],"sequence":19513062,"timestamp":"2021-07-15T03:00:21.315Z","symbol":"UNIBTC"}}
1626318021.447479: {"jsonrpc":"2.0","method":"updateOrderbook","params":{"ask":[],"bid":[{"price":"12.078","size":"5.7671"},{"price":"12.060","size":"0"}],"sequence":2190675,"timestamp":"2021-07-15T03:00:21.350Z","symbol":"SPIUSD"}}
1626318021.457095: {"jsonrpc":"2.0","method":"updateOrderbook","params":{"ask":[{"price":"0.662654","size":"399073.2"}],"bid":[],"sequence":20584067,"timestamp":"2021-07-15T03:00:21.430Z","symbol":"XRPUSDT"}}
1626318021.474335: {"jsonrpc":"2.0","method":"updateOrderbook","params":{"ask":[],"bid":[{"price":"0.00054556","size":"0"},{"price":"0.00054555","size":"5.18"},{"price":"0.00053050","size":"0"},{"price":"0.00052837","size":"444.27"}],"sequence":19513063,"timestamp":"2021-07-15T03:00:21.431Z","symbol":"UNIBTC"}}
1626318021.553376: {"jsonrpc":"2.0","method":"updateOrderbook","params":{"ask":[{"price":"0.624613","size":"1.2"},{"price":"0.662654","size":"399073.3"}],"bid":[],"sequence":20584068,"timestamp":"2021-07-15T03:00:21.466Z","symbol":"XRPUSDT"}}
1626318021.608072: {"jsonrpc":"2.0","method":"updateOrderbook","params":{"ask":[{"price":"0.00000065973","size":"15230580"}],"bid":[],"sequence":10532258,"timestamp":"2021-07-15T03:00:21.443Z","symbol":"SCBTC"}}
1626318021.60813: {"jsonrpc":"2.0","method":"updateOrderbook","params":{"ask":[{"price":"0.00054577","size":"0"},{"price":"0.00054582","size":"4.33"}],"bid":[],"sequence":19513064,"timestamp":"2021-07-15T03:00:21.520Z","symbol":"UNIBTC"}}
1626318021.688597: {"jsonrpc":"2.0","method":"updateOrderbook","params":{"ask":[{"price":"10000.000","size":"0.0012"}],"bid":[{"price":"0.010","size":"1000.0012"}],"sequence":2190676,"timestamp":"2021-07-15T03:00:21.590Z","symbol":"SPIUSD"}}
1626318021.688627: {"jsonrpc":"2.0","method":"updateOrderbook","params":{"ask":[{"price":"0.627159","size":"129038.8"},{"price":"0.631987","size":"0"},{"price":"0.651855","size":"181214.3"},{"price":"0.656074","size":"0"},{"price":"0.662654","size":"399073.7"}],"bid":[],"sequence":20584069,"timestamp":"2021-07-15T03:00:21.590Z","symbol":"XRPUSDT"}}
1626318021.688651: {"jsonrpc":"2.0","method":"updateOrderbook","params":{"ask":[{"price":"0.00054580","size":"4.33"},{"price":"0.00054582","size":"0"},{"price":"0.00054648","size":"16.96"},{"price":"0.00054658","size":"0"}],"bid":[{"price":"0.00054557","size":"5.18"},{"price":"0.00054555","size":"0"},{"price":"0.00054470","size":"196.86"},{"price":"0.00054447","size":"0"},{"price":"0.00052968","size":"2974.71"},{"price":"0.00052836","size":"0"}],"sequence":19513065,"timestamp":"2021-07-15T03:00:21.640Z","symbol":"UNIBTC"}}
1626318021.777011: {"jsonrpc":"2.0","method":"updateOrderbook","params":{"ask":[{"price":"0.645449","size":"347706.3"},{"price":"0.648232","size":"0"},{"price":"0.662654","size":"399074.0"}],"bid":[],"sequence":20584070,"timestamp":"2021-07-15T03:00:21.692Z","symbol":"XRPUSDT"}}
1626318021.799055: {"jsonrpc":"2.0","method":"updateOrderbook","params":{"ask":[{"price":"0.00000065973","size":"15230590"}],"bid":[],"sequence":10532259,"timestamp":"2021-07-15T03:00:21.721Z","symbol":"SCBTC"}}
1626318021.8022552: {"jsonrpc":"2.0","method":"updateOrderbook","params":{"ask":[],"bid":[{"price":"0.00052837","size":"445.07"}],"sequence":19513066,"timestamp":"2021-07-15T03:00:21.650Z","symbol":"UNIBTC"}}
1626318021.8621461: {"jsonrpc":"2.0","method":"updateOrderbook","params":{"ask":[{"price":"0.616746","size":"6433.6"},{"price":"0.616896","size":"0"},{"price":"0.617115","size":"4276.9"},{"price":"0.617506","size":"12316.2"},{"price":"0.617536","size":"0"},{"price":"0.617909","size":"0"},{"price":"0.662654","size":"399074.2"}],"bid":[],"sequence":20584071,"timestamp":"2021-07-15T03:00:21.763Z","symbol":"XRPUSDT"}}
1626318021.8835561: {"jsonrpc":"2.0","method":"updateOrderbook","params":{"ask":[{"price":"0.00000094560","size":"0"},{"price":"0.00000094570","size":"2768580"},{"price":"0.00000159405","size":"4634410"},{"price":"0.00000161545","size":"0"}],"bid":[{"price":"0.00000036564","size":"0"},{"price":"0.00000036525","size":"28670"},{"price":"0.00000036504","size":"110390"},{"price":"0.00000034658","size":"4600"},{"price":"0.00000034622","size":"230000"}],"sequence":10532260,"timestamp":"2021-07-15T03:00:21.813Z","symbol":"SCBTC"}}
1626318021.8836942: {"jsonrpc":"2.0","method":"updateOrderbook","params":{"ask":[{"price":"0.00054670","size":"333.84"},{"price":"0.00054701","size":"346.36"},{"price":"0.00054706","size":"0"},{"price":"0.00054733","size":"0"},{"price":"0.00054742","size":"528.37"},{"price":"0.00054776","size":"0"},{"price":"0.00055281","size":"1811.87"},{"price":"0.00055346","size":"0"}],"bid":[],"sequence":19513067,"timestamp":"2021-07-15T03:00:21.830Z","symbol":"UNIBTC"}}
1626318021.9496262: {"jsonrpc":"2.0","method":"updateOrderbook","params":{"ask":[],"bid":[{"price":"12.077","size":"0"}],"sequence":2190677,"timestamp":"2021-07-15T03:00:21.920Z","symbol":"SPIUSD"}}
1626318021.955724: {"jsonrpc":"2.0","method":"updateOrderbook","params":{"ask":[{"price":"0.627159","size":"0"},{"price":"0.629647","size":"129038.8"},{"price":"0.651855","size":"0"},{"price":"0.654131","size":"181214.3"},{"price":"0.662654","size":"399074.6"},{"price":"0.702918","size":"0"}],"bid":[{"price":"0.614734","size":"6216.0"},{"price":"0.614601","size":"0"},{"price":"0.614356","size":"3391.2"},{"price":"0.614231","size":"0"}],"sequence":20584072,"timestamp":"2021-07-15T03:00:21.881Z","symbol":"XRPUSDT"}}
1626318021.967367: {"jsonrpc":"2.0","method":"updateOrderbook","params":{"ask":[{"price":"0.00000037386","size":"3970500"},{"price":"0.00000037542","size":"0"},{"price":"0.00000065973","size":"15230610"},{"price":"0.00000094570","size":"2768600"},{"price":"0.00000124704","size":"2705250"},{"price":"0.00000124775","size":"0"}],"bid":[{"price":"0.00000036526","size":"0"},{"price":"0.00000036505","size":"1000"}],"sequence":10532261,"timestamp":"2021-07-15T03:00:21.913Z","symbol":"SCBTC"}}
1626318021.981636: {"jsonrpc":"2.0","method":"updateOrderbook","params":{"ask":[{"price":"0.00054578","size":"4.33"},{"price":"0.00054580","size":"0"}],"bid":[{"price":"0.00054558","size":"5.18"},{"price":"0.00054557","size":"0"},{"price":"0.00054416","size":"269.93"},{"price":"0.00054349","size":"0"},{"price":"0.00054255","size":"914.50"},{"price":"0.00054175","size":"0"},{"price":"0.00052837","size":"0.80"}],"sequence":19513068,"timestamp":"2021-07-15T03:00:21.940Z","symbol":"UNIBTC"}}
1626318022.0450208: {"jsonrpc":"2.0","method":"updateOrderbook","params":{"ask":[],"bid":[{"price":"12.079","size":"5.8854"},{"price":"12.078","size":"0"},{"price":"12.060","size":"5.7735"}],"sequence":2190678,"timestamp":"2021-07-15T03:00:21.975Z","symbol":"SPIUSD"}}
1626318022.057738: {"jsonrpc":"2.0","method":"updateOrderbook","params":{"ask":[{"price":"0.662654","size":"399074.9"},{"price":"0.701643","size":"228479.7"}],"bid":[],"sequence":20584073,"timestamp":"2021-07-15T03:00:21.988Z","symbol":"XRPUSDT"}}
1626318022.071765: {"jsonrpc":"2.0","method":"updateOrderbook","params":{"ask":[{"price":"0.00000036888","size":"0"},{"price":"0.00000036908","size":"417100"},{"price":"0.00000042892","size":"0"},{"price":"0.00000043201","size":"522810"},{"price":"0.00000054417","size":"0"},{"price":"0.00000054581","size":"757990"},{"price":"0.00000065973","size":"15230630"},{"price":"0.00000077938","size":"0"},{"price":"0.00000078144","size":"2003810"},{"price":"0.00000094570","size":"2768620"},{"price":"0.00000283983","size":"0"},{"price":"0.00000284851","size":"4472830"}],"bid":[{"price":"0.00000034658","size":"234600"},{"price":"0.00000034622","size":"0"}],"sequence":10532262,"timestamp":"2021-07-15T03:00:22.000Z","symbol":"SCBTC"}}
1626318022.072097: {"jsonrpc":"2.0","method":"updateOrderbook","params":{"ask":[{"price":"0.00054632","size":"18.88"},{"price":"0.00054641","size":"0"},{"price":"0.00054643","size":"77.40"},{"price":"0.00054654","size":"0"},{"price":"0.00055621","size":"2539.46"},{"price":"0.00056934","size":"0"}],"bid":[{"price":"0.00054558","size":"0"},{"price":"0.00054557","size":"5.18"},{"price":"0.00053050","size":"442.49"},{"price":"0.00052837","size":"0"}],"sequence":19513069,"timestamp":"2021-07-15T03:00:22.037Z","symbol":"UNIBTC"}}
1626318022.152858: {"jsonrpc":"2.0","method":"updateOrderbook","params":{"ask":[],"bid":[{"price":"12.080","size":"5.7799"},{"price":"12.060","size":"0"}],"sequence":2190679,"timestamp":"2021-07-15T03:00:22.075Z","symbol":"SPIUSD"}}
1626318022.155102: {"jsonrpc":"2.0","method":"updateOrderbook","params":{"ask":[{"price":"0.616299","size":"160.9"},{"price":"0.616300","size":"0"},{"price":"0.662654","size":"399075.3"}],"bid":[{"price":"0.615413","size":"0"},{"price":"0.615339","size":"2848.3"},{"price":"0.609918","size":"0"},{"price":"0.609817","size":"491.9"},{"price":"0.584700","size":"195384.3"},{"price":"0.581347","size":"0"}],"sequence":20584074,"timestamp":"2021-07-15T03:00:22.122Z","symbol":"XRPUSDT"}}
1626318022.174937: {"jsonrpc":"2.0","method":"updateOrderbook","params":{"ask":[{"price":"0.00000065973","size":"15230650"},{"price":"0.00000094570","size":"2768640"}],"bid":[{"price":"0.00000034658","size":"4600"},{"price":"0.00000034622","size":"230000"}],"sequence":10532263,"timestamp":"2021-07-15T03:00:22.106Z","symbol":"SCBTC"}}
1626318022.174999: {"jsonrpc":"2.0","method":"updateOrderbook","params":{"ask":[],"bid":[{"price":"0.00054558","size":"5.18"},{"price":"0.00054557","size":"0"}],"sequence":19513070,"timestamp":"2021-07-15T03:00:22.130Z","symbol":"UNIBTC"}}
1626318022.185791: {"jsonrpc":"2.0","method":"updateOrderbook","params":{"ask":[{"price":"0.0004397","size":"0"},{"price":"0.0004398","size":"47.197"}],"bid":[],"sequence":2198424,"timestamp":"2021-07-15T03:00:22.079Z","symbol":"NUTBTC"}}
1626318022.259713: {"jsonrpc":"2.0","method":"updateOrderbook","params":{"ask":[{"price":"0.662654","size":"399075.5"}],"bid":[{"price":"0.615685","size":"0"},{"price":"0.615679","size":"1591.6"}],"sequence":20584075,"timestamp":"2021-07-15T03:00:22.201Z","symbol":"XRPUSDT"}}
1626318022.2780852: {"jsonrpc":"2.0","method":"updateOrderbook","params":{"ask":[{"price":"0.00000065973","size":"15230660"},{"price":"0.00000094570","size":"2768660"}],"bid":[],"sequence":10532264,"timestamp":"2021-07-15T03:00:22.199Z","symbol":"SCBTC"}}
1626318022.278125: {"jsonrpc":"2.0","method":"updateOrderbook","params":{"ask":[{"price":"0.00054575","size":"4.33"},{"price":"0.00054578","size":"0"}],"bid":[{"price":"0.00054558","size":"0"},{"price":"0.00054553","size":"5.18"}],"sequence":19513071,"timestamp":"2021-07-15T03:00:22.235Z","symbol":"UNIBTC"}}
1626318022.357653: {"jsonrpc":"2.0","method":"updateOrderbook","params":{"ask":[{"price":"0.662654","size":"399075.8"}],"bid":[{"price":"0.615679","size":"0"},{"price":"0.615674","size":"1591.6"}],"sequence":20584076,"timestamp":"2021-07-15T03:00:22.277Z","symbol":"XRPUSDT"}}
1626318022.3685539: {"jsonrpc":"2.0","method":"updateOrderbook","params":{"ask":[{"price":"0.00000065973","size":"15230690"},{"price":"0.00000094570","size":"2768680"}],"bid":[{"price":"0.00000036454","size":"0"},{"price":"0.00000036428","size":"284390"},{"price":"0.00000034658","size":"234600"},{"price":"0.00000034622","size":"0"}],"sequence":10532265,"timestamp":"2021-07-15T03:00:22.318Z","symbol":"SCBTC"}}
1626318022.368617: {"jsonrpc":"2.0","method":"updateOrderbook","params":{"ask":[{"price":"0.00054571","size":"4.33"},{"price":"0.00054575","size":"0"}],"bid":[{"price":"0.00053050","size":"443.28"}],"sequence":19513072,"timestamp":"2021-07-15T03:00:22.307Z","symbol":"UNIBTC"}}
1626318022.445778: {"jsonrpc":"2.0","method":"updateOrderbook","params":{"ask":[],"bid":[{"price":"12.079","size":"0"}],"sequence":2190680,"timestamp":"2021-07-15T03:00:22.405Z","symbol":"SPIUSD"}}
1626318022.45966: {"jsonrpc":"2.0","method":"updateOrderbook","params":{"ask":[{"price":"0.662654","size":"399076.2"}],"bid":[],"sequence":20584077,"timestamp":"2021-07-15T03:00:22.419Z","symbol":"XRPUSDT"}}
1626318022.4700491: {"jsonrpc":"2.0","method":"updateOrderbook","params":{"ask":[{"price":"0.00000043201","size":"0"},{"price":"0.00000043635","size":"522810"},{"price":"0.00000044087","size":"1381850"},{"price":"0.00000044539","size":"0"},{"price":"0.00000054581","size":"0"},{"price":"0.00000054811","size":"757990"},{"price":"0.00000065973","size":"15230710"},{"price":"0.00000078144","size":"0"},{"price":"0.00000078433","size":"2003810"},{"price":"0.00000094570","size":"2768700"},{"price":"0.00000095828","size":"0"},{"price":"0.00000095888","size":"2754880"},{"price":"0.00000284851","size":"0"},{"price":"0.00000286067","size":"4472830"}],"bid":[{"price":"0.00000036504","size":"0"},{"price":"0.00000036492","size":"110390"},{"price":"0.00000034658","size":"4600"},{"price":"0.00000034622","size":"230000"}],"sequence":10532266,"timestamp":"2021-07-15T03:00:22.441Z","symbol":"SCBTC"}}
1626318022.470444: {"jsonrpc":"2.0","method":"updateOrderbook","params":{"ask":[{"price":"0.00054570","size":"4.33"},{"price":"0.00054571","size":"0"},{"price":"0.00054591","size":"10.47"},{"price":"0.00054602","size":"0"}],"bid":[{"price":"0.00054553","size":"0"},{"price":"0.00054552","size":"5.18"},{"price":"0.00054366","size":"331.21"},{"price":"0.00054321","size":"0"}],"sequence":19513073,"timestamp":"2021-07-15T03:00:22.396Z","symbol":"UNIBTC"}}
1626318022.551372: {"jsonrpc":"2.0","method":"updateOrderbook","params":{"ask":[],"bid":[{"price":"12.080","size":"0"},{"price":"12.060","size":"5.7863"}],"sequence":2190681,"timestamp":"2021-07-15T03:00:22.478Z","symbol":"SPIUSD"}}
1626318022.570116: {"jsonrpc":"2.0","method":"updateOrderbook","params":{"ask":[{"price":"0.662654","size":"399076.4"}],"bid":[],"sequence":20584078,"timestamp":"2021-07-15T03:00:22.484Z","symbol":"XRPUSDT"}}
1626318022.570155: {"jsonrpc":"2.0","method":"updateOrderbook","params":{"ask":[{"price":"0.00000044087","size":"0"},{"price":"0.00000044130","size":"1381850"},{"price":"0.00000065973","size":"15230720"},{"price":"0.00000094570","size":"2768720"}],"bid":[{"price":"0.00000036505","size":"0"},{"price":"0.00000036493","size":"1000"}],"sequence":10532267,"timestamp":"2021-07-15T03:00:22.522Z","symbol":"SCBTC"}}
1626318022.653614: {"jsonrpc":"2.0","method":"updateOrderbook","params":{"ask":[{"price":"0.616853","size":"0"},{"price":"0.616917","size":"5500.0"},{"price":"0.662654","size":"399076.8"}],"bid":[{"price":"0.615679","size":"1591.6"},{"price":"0.615674","size":"0"}],"sequence":20584079,"timestamp":"2021-07-15T03:00:22.631Z","symbol":"XRPUSDT"}}
1626318022.6703942: {"jsonrpc":"2.0","method":"updateOrderbook","params":{"ask":[{"price":"0.00000065973","size":"15230750"},{"price":"0.00000094570","size":"2768740"}],"bid":[{"price":"0.00000036493","size":"0"},{"price":"0.00000036492","size":"0"},{"price":"0.00000036482","size":"110390"},{"price":"0.00000034658","size":"234600"},{"price":"0.00000034622","size":"0"}],"sequence":10532268,"timestamp":"2021-07-15T03:00:22.640Z","symbol":"SCBTC"}}
1626318022.670443: {"jsonrpc":"2.0","method":"updateOrderbook","params":{"ask":[{"price":"0.00059499","size":"2343.84"},{"price":"0.00060103","size":"0"},{"price":"0.00078446","size":"3484.36"},{"price":"0.00078698","size":"0"}],"bid":[],"sequence":19513074,"timestamp":"2021-07-15T03:00:22.608Z","symbol":"UNIBTC"}}
1626318022.748095: {"jsonrpc":"2.0","method":"updateOrderbook","params":{"ask":[],"bid":[{"price":"12.081","size":"5.8844"}],"sequence":2190682,"timestamp":"2021-07-15T03:00:22.653Z","symbol":"SPIUSD"}}
1626318022.755946: {"jsonrpc":"2.0","method":"updateOrderbook","params":{"ask":[{"price":"0.615739","size":"0"},{"price":"0.615754","size":"11000.0"},{"price":"0.615764","size":"0"},{"price":"0.615773","size":"1331.7"},{"price":"0.662654","size":"399077.1"}],"bid":[{"price":"0.615700","size":"1591.6"},{"price":"0.615679","size":"0"},{"price":"0.614316","size":"5500.0"},{"price":"0.614241","size":"1768.2"}],"sequence":20584080,"timestamp":"2021-07-15T03:00:22.730Z","symbol":"XRPUSDT"}}
1626318022.770921: {"jsonrpc":"2.0","method":"updateOrderbook","params":{"ask":[{"price":"0.00000036719","size":"25530"},{"price":"0.00000036726","size":"0"},{"price":"0.00000065973","size":"15230760"},{"price":"0.00000094570","size":"2768760"}],"bid":[{"price":"0.00000036483","size":"1000"}],"sequence":10532269,"timestamp":"2021-07-15T03:00:22.717Z","symbol":"SCBTC"}}
1626318022.7711842: {"jsonrpc":"2.0","method":"updateOrderbook","params":{"ask":[{"price":"0.00054616","size":"17.10"},{"price":"0.00054681","size":"218.69"},{"price":"0.00054689","size":"0"},{"price":"0.00054730","size":"373.82"},{"price":"0.00054767","size":"0"},{"price":"0.00054806","size":"0"},{"price":"0.00055087","size":"843.90"},{"price":"0.00055133","size":"0"},{"price":"0.00055621","size":"0"},{"price":"0.00055730","size":"2539.46"}],"bid":[],"sequence":19513075,"timestamp":"2021-07-15T03:00:22.654Z","symbol":"UNIBTC"}}
1626318022.851466: {"jsonrpc":"2.0","method":"updateOrderbook","params":{"ask":[],"bid":[{"price":"12.082","size":"5.7927"},{"price":"12.060","size":"0"}],"sequence":2190683,"timestamp":"2021-07-15T03:00:22.766Z","symbol":"SPIUSD"}}
1626318022.855005: {"jsonrpc":"2.0","method":"updateOrderbook","params":{"ask":[{"price":"0.615773","size":"0"},{"price":"0.615776","size":"1331.7"},{"price":"0.662654","size":"399077.4"}],"bid":[{"price":"0.615700","size":"0"},{"price":"0.615685","size":"1591.6"},{"price":"0.610018","size":"491.7"},{"price":"0.609817","size":"0"}],"sequence":20584081,"timestamp":"2021-07-15T03:00:22.820Z","symbol":"XRPUSDT"}}
1626318022.8721302: {"jsonrpc":"2.0","method":"updateOrderbook","params":{"ask":[{"price":"0.00000065973","size":"15230780"},{"price":"0.00000094570","size":"2768780"}],"bid":[{"price":"0.00000036265","size":"0"},{"price":"0.00000036202","size":"1248220"},{"price":"0.00000034658","size":"4600"},{"price":"0.00000034622","size":"230000"},{"price":"0.00000032029","size":"0"},{"price":"0.00000023134","size":"1993120"},{"price":"0.00000004259","size":"0"},{"price":"0.00000000546","size":"2752080"}],"sequence":10532270,"timestamp":"2021-07-15T03:00:22.811Z","symbol":"SCBTC"}}
1626318022.8721762: {"jsonrpc":"2.0","method":"updateOrderbook","params":{"ask":[{"price":"0.00054570","size":"0"},{"price":"0.00054571","size":"4.33"},{"price":"0.00054800","size":"658.12"},{"price":"0.00054961","size":"0"},{"price":"0.00059499","size":"0"},{"price":"0.00059880","size":"2343.84"},{"price":"0.00078446","size":"0"},{"price":"0.00078612","size":"3484.36"}],"bid":[],"sequence":19513076,"timestamp":"2021-07-15T03:00:22.829Z","symbol":"UNIBTC"}}
1626318022.953297: {"jsonrpc":"2.0","method":"updateOrderbook","params":{"ask":[{"price":"0.615768","size":"1331.7"},{"price":"0.615776","size":"0"},{"price":"0.662654","size":"399077.7"}],"bid":[{"price":"0.615685","size":"0"},{"price":"0.615675","size":"1591.6"}],"sequence":20584082,"timestamp":"2021-07-15T03:00:22.909Z","symbol":"XRPUSDT"}}
1626318022.971115: {"jsonrpc":"2.0","method":"updateOrderbook","params":{"ask":[{"price":"0.00000065973","size":"15230800"},{"price":"0.00000088533","size":"2001500"},{"price":"0.00000090214","size":"0"},{"price":"0.00000094570","size":"2768800"}],"bid":[{"price":"0.00000036534","size":"28670"},{"price":"0.00000036525","size":"0"}],"sequence":10532271,"timestamp":"2021-07-15T03:00:22.918Z","symbol":"SCBTC"}}
1626318022.975274: {"jsonrpc":"2.0","method":"updateOrderbook","params":{"ask":[{"price":"0.00054569","size":"4.33"},{"price":"0.00054571","size":"0"}],"bid":[{"price":"0.00054552","size":"0"},{"price":"0.00054551","size":"5.18"},{"price":"0.00054527","size":"0"},{"price":"0.00054517","size":"18.33"},{"price":"0.00054255","size":"0"},{"price":"0.00054195","size":"914.50"}],"sequence":19513077,"timestamp":"2021-07-15T03:00:22.935Z","symbol":"UNIBTC"}}
1626318023.057069: {"jsonrpc":"2.0","method":"updateOrderbook","params":{"ask":[{"price":"0.662654","size":"399078.0"}],"bid":[],"sequence":20584083,"timestamp":"2021-07-15T03:00:23.014Z","symbol":"XRPUSDT"}}
1626318023.080607: {"jsonrpc":"2.0","method":"updateOrderbook","params":{"ask":[{"price":"0.00000065973","size":"15230810"},{"price":"0.00000088533","size":"0"},{"price":"0.00000088679","size":"2001500"},{"price":"0.00000094570","size":"2768810"}],"bid":[{"price":"0.00000034658","size":"234600"},{"price":"0.00000034622","size":"0"}],"sequence":10532272,"timestamp":"2021-07-15T03:00:23.020Z","symbol":"SCBTC"}}
1626318023.08063: {"jsonrpc":"2.0","method":"updateOrderbook","params":{"ask":[{"price":"0.00054566","size":"4.33"},{"price":"0.00054569","size":"0"}],"bid":[{"price":"0.00054551","size":"0"},{"price":"0.00054549","size":"5.18"},{"price":"0.00054534","size":"0"},{"price":"0.00054528","size":"9.62"},{"price":"0.00054455","size":"0"},{"price":"0.00054423","size":"733.95"},{"price":"0.00054414","size":"0"},{"price":"0.00054382","size":"814.44"},{"price":"0.00052968","size":"0"},{"price":"0.00052929","size":"2974.71"}],"sequence":19513078,"timestamp":"2021-07-15T03:00:22.995Z","symbol":"UNIBTC"}}
1626318023.149224: {"jsonrpc":"2.0","method":"updateOrderbook","params":{"ask":[{"price":"0.662654","size":"399078.3"}],"bid":[],"sequence":20584084,"timestamp":"2021-07-15T03:00:23.133Z","symbol":"XRPUSDT"}}
1626318023.173701: {"jsonrpc":"2.0","method":"updateOrderbook","params":{"ask":[{"price":"0.00000065973","size":"15230830"},{"price":"0.00000094570","size":"2768830"}],"bid":[],"sequence":10532273,"timestamp":"2021-07-15T03:00:23.132Z","symbol":"SCBTC"}}
1626318023.1747808: {"jsonrpc":"2.0","method":"updateOrderbook","params":{"ask":[{"price":"0.00054635","size":"16.96"},{"price":"0.00054648","size":"0"}],"bid":[{"price":"0.00054549","size":"0"},{"price":"0.00054546","size":"5.18"},{"price":"0.00054423","size":"353.16"},{"price":"0.00054407","size":"0"},{"price":"0.00054395","size":"380.79"},{"price":"0.00054369","size":"482.00"},{"price":"0.00054305","size":"0"},{"price":"0.00054268","size":"86.00"},{"price":"0.00053050","size":"0.79"}],"sequence":19513079,"timestamp":"2021-07-15T03:00:23.132Z","symbol":"UNIBTC"}}
1626318023.248356: {"jsonrpc":"2.0","method":"updateOrderbook","params":{"ask":[],"bid":[{"price":"12.081","size":"0"}],"sequence":2190684,"timestamp":"2021-07-15T03:00:23.201Z","symbol":"SPIUSD"}}
1626318023.252018: {"jsonrpc":"2.0","method":"updateOrderbook","params":{"ask":[{"price":"0.615764","size":"1331.7"},{"price":"0.615768","size":"0"},{"price":"0.616846","size":"5500.0"},{"price":"0.616917","size":"0"},{"price":"0.662654","size":"399078.4"}],"bid":[{"price":"0.615681","size":"1591.6"},{"price":"0.615675","size":"0"}],"sequence":20584085,"timestamp":"2021-07-15T03:00:23.159Z","symbol":"XRPUSDT"}}
1626318023.278839: {"jsonrpc":"2.0","method":"updateOrderbook","params":{"ask":[{"price":"0.00000036719","size":"0"},{"price":"0.00000036726","size":"25530"},{"price":"0.00000041341","size":"1016210"},{"price":"0.00000041390","size":"0"},{"price":"0.00000044130","size":"0"},{"price":"0.00000044188","size":"1381850"},{"price":"0.00000065973","size":"15230840"},{"price":"0.00000088679","size":"0"},{"price":"0.00000088985","size":"2001500"},{"price":"0.00000094570","size":"2768840"}],"bid":[],"sequence":10532274,"timestamp":"2021-07-15T03:00:23.189Z","symbol":"SCBTC"}}
1626318023.279063: {"jsonrpc":"2.0","method":"updateOrderbook","params":{"ask":[{"price":"0.00054564","size":"4.33"},{"price":"0.00054566","size":"0"},{"price":"0.00055082","size":"3878.47"},{"price":"0.00055158","size":"4111.40"},{"price":"0.00055196","size":"0"},{"price":"0.00055237","size":"4023.92"},{"price":"0.00055268","size":"0"},{"price":"0.00055312","size":"4002.23"},{"price":"0.00055363","size":"0"},{"price":"0.00055440","size":"0"},{"price":"0.00059880","size":"0"},{"price":"0.00060290","size":"2343.84"},{"price":"0.00078612","size":"0"},{"price":"0.00078772","size":"3484.36"}],"bid":[{"price":"0.00054517","size":"0"},{"price":"0.00054507","size":"18.33"},{"price":"0.00054501","size":"0"},{"price":"0.00054492","size":"18.61"},{"price":"0.00054470","size":"0"},{"price":"0.00054453","size":"196.86"},{"price":"0.00053050","size":"0"},{"price":"0.00052969","size":"443.17"}],"sequence":19513080,"timestamp":"2021-07-15T03:00:23.234Z","symbol":"UNIBTC"}}
1626318023.352349: {"jsonrpc":"2.0","method":"updateOrderbook","params":{"ask":[],"bid":[{"price":"12.083","size":"5.8835"},{"price":"12.082","size":"0"},{"price":"12.060","size":"5.8119"}],"sequence":2190685,"timestamp":"2021-07-15T03:00:23.279Z","symbol":"SPIUSD"}}
1626318023.358619: {"jsonrpc":"2.0","method":"updateOrderbook","params":{"ask":[{"price":"0.662654","size":"399078.9"}],"bid":[],"sequence":20584086,"timestamp":"2021-07-15T03:00:23.312Z","symbol":"XRPUSDT"}}
1626318023.369338: {"jsonrpc":"2.0","method":"updateOrderbook","params":{"ask":[{"price":"0.00000065973","size":"15230860"},{"price":"0.00000094570","size":"2768850"}],"bid":[],"sequence":10532275,"timestamp":"2021-07-15T03:00:23.300Z","symbol":"SCBTC"}}
1626318023.3693728: {"jsonrpc":"2.0","method":"updateOrderbook","params":{"ask":[{"price":"0.00054592","size":"16.70"},{"price":"0.00054606","size":"66.20"},{"price":"0.00054609","size":"0"},{"price":"0.00054618","size":"0"}],"bid":[{"price":"0.00054506","size":"0"},{"price":"0.00054490","size":"0"},{"price":"0.00054489","size":"18.58"},{"price":"0.00054473","size":"72.79"},{"price":"0.00054457","size":"0"},{"price":"0.00054426","size":"261.13"},{"price":"0.00054353","size":"0"},{"price":"0.00054350","size":"0"},{"price":"0.00054304","size":"0"},{"price":"0.00054292","size":"634.39"},{"price":"0.00054283","size":"1.47"},{"price":"0.00054243","size":"200.63"},{"price":"0.00054233","size":"0"},{"price":"0.00054149","size":"1015.38"},{"price":"0.00052929","size":"0"},{"price":"0.00052792","size":"2974.71"}],"sequence":19513081,"timestamp":"2021-07-15T03:00:23.338Z","symbol":"UNIBTC"}}
1626318023.447383: {"jsonrpc":"2.0","method":"updateOrderbook","params":{"ask":[],"bid":[{"price":"12.084","size":"5.8311"},{"price":"12.060","size":"0"}],"sequence":2190686,"timestamp":"2021-07-15T03:00:23.370Z","symbol":"SPIUSD"}}
1626318023.457932: {"jsonrpc":"2.0","method":"updateOrderbook","params":{"ask":[{"price":"0.662654","size":"399079.3"},{"price":"0.663943","size":"229002.7"},{"price":"0.666845","size":"0"},{"price":"0.836239","size":"324970.5"},{"price":"0.841249","size":"0"}],"bid":[],"sequence":20584087,"timestamp":"2021-07-15T03:00:23.438Z","symbol":"XRPUSDT"}}
1626318023.4669912: {"jsonrpc":"2.0","method":"updateOrderbook","params":{"ask":[{"price":"0.00000065973","size":"15230870"},{"price":"0.00000094570","size":"2768870"},{"price":"0.00000095822","size":"2754880"},{"price":"0.00000095888","size":"0"}],"bid":[],"sequence":10532276,"timestamp":"2021-07-15T03:00:23.406Z","symbol":"SCBTC"}}
1626318023.4670122: {"jsonrpc":"2.0","method":"updateOrderbook","params":{"ask":[],"bid":[{"price":"0.00054547","size":"5.18"},{"price":"0.00054546","size":"0"},{"price":"0.00052792","size":"0"},{"price":"0.00052657","size":"2974.71"}],"sequence":19513082,"timestamp":"2021-07-15T03:00:23.382Z","symbol":"UNIBTC"}}
1626318023.551441: {"jsonrpc":"2.0","method":"updateOrderbook","params":{"ask":[{"price":"0.662654","size":"399079.6"}],"bid":[],"sequence":20584088,"timestamp":"2021-07-15T03:00:23.541Z","symbol":"XRPUSDT"}}
1626318023.565484: {"jsonrpc":"2.0","method":"updateOrderbook","params":{"ask":[{"price":"0.00000065973","size":"15230890"},{"price":"0.00000094570","size":"2768880"}],"bid":[],"sequence":10532277,"timestamp":"2021-07-15T03:00:23.512Z","symbol":"SCBTC"}}
1626318023.5738182: {"jsonrpc":"2.0","method":"updateOrderbook","params":{"ask":[{"price":"0.00054562","size":"4.33"},{"price":"0.00054564","size":"0"},{"price":"0.00054654","size":"201.47"},{"price":"0.00054671","size":"0"},{"price":"0.00054779","size":"86.00"},{"price":"0.00054823","size":"1302.32"}],"bid":[{"price":"0.00054547","size":"0"},{"price":"0.00054543","size":"5.18"},{"price":"0.00054528","size":"0"},{"price":"0.00054521","size":"9.62"},{"price":"0.00052969","size":"0"},{"price":"0.00052788","size":"2974.71"},{"price":"0.00052657","size":"0"}],"sequence":19513083,"timestamp":"2021-07-15T03:00:23.540Z","symbol":"UNIBTC"}}
1626318023.6546261: {"jsonrpc":"2.0","method":"updateOrderbook","params":{"ask":[{"price":"0.662654","size":"399079.7"}],"bid":[],"sequence":20584089,"timestamp":"2021-07-15T03:00:23.570Z","symbol":"XRPUSDT"}}
1626318023.668973: {"jsonrpc":"2.0","method":"updateOrderbook","params":{"ask":[{"price":"0.00000065973","size":"15230900"},{"price":"0.00000094570","size":"2768890"}],"bid":[],"sequence":10532278,"timestamp":"2021-07-15T03:00:23.590Z","symbol":"SCBTC"}}
1626318023.669014: {"jsonrpc":"2.0","method":"updateOrderbook","params":{"ask":[{"price":"0.00054562","size":"0"},{"price":"0.00054565","size":"4.33"},{"price":"0.00054592","size":"0"},{"price":"0.00054606","size":"0"},{"price":"0.00054621","size":"16.70"},{"price":"0.00054629","size":"0"},{"price":"0.00054639","size":"0"},{"price":"0.00054642","size":"66.20"},{"price":"0.00054666","size":"199.63"},{"price":"0.00054670","size":"0"},{"price":"0.00054684","size":"296.51"},{"price":"0.00054707","size":"333.84"}],"bid":[{"price":"0.00054547","size":"5.18"},{"price":"0.00054543","size":"0"},{"price":"0.00052910","size":"443.66"}],"sequence":19513084,"timestamp":"2021-07-15T03:00:23.632Z","symbol":"UNIBTC"}}
1626318023.762414: {"jsonrpc":"2.0","method":"updateOrderbook","params":{"ask":[{"price":"0.662654","size":"399080.1"}],"bid":[],"sequence":20584090,"timestamp":"2021-07-15T03:00:23.738Z","symbol":"XRPUSDT"}}
1626318023.774421: {"jsonrpc":"2.0","method":"updateOrderbook","params":{"ask":[{"price":"0.00000065973","size":"15230920"},{"price":"0.00000094570","size":"2768910"}],"bid":[],"sequence":10532279,"timestamp":"2021-07-15T03:00:23.696Z","symbol":"SCBTC"}}
1626318023.7744808: {"jsonrpc":"2.0","method":"updateOrderbook","params":{"ask":[{"price":"0.00054565","size":"0"},{"price":"0.00054568","size":"4.33"}],"bid":[],"sequence":19513085,"timestamp":"2021-07-15T03:00:23.718Z","symbol":"UNIBTC"}}
1626318023.845473: {"jsonrpc":"2.0","method":"updateOrderbook","params":{"ask":[],"bid":[{"price":"12.083","size":"0"}],"sequence":2190687,"timestamp":"2021-07-15T03:00:23.783Z","symbol":"SPIUSD"}}
1626318023.851112: {"jsonrpc":"2.0","method":"updateOrderbook","params":{"ask":[{"price":"0.616846","size":"0"},{"price":"0.616910","size":"5500.0"},{"price":"0.662654","size":"399080.3"}],"bid":[],"sequence":20584091,"timestamp":"2021-07-15T03:00:23.770Z","symbol":"XRPUSDT"}}
1626318023.8643358: {"jsonrpc":"2.0","method":"updateOrderbook","params":{"ask":[{"price":"0.00000065973","size":"15230940"},{"price":"0.00000094570","size":"2768930"}],"bid":[{"price":"0.00000034002","size":"0"},{"price":"0.00000034001","size":"0"},{"price":"0.00000033944","size":"234600"}],"sequence":10532280,"timestamp":"2021-07-15T03:00:23.838Z","symbol":"SCBTC"}}
1626318023.866957: {"jsonrpc":"2.0","method":"updateOrderbook","params":{"ask":[{"price":"0.00054621","size":"35.58"},{"price":"0.00054632","size":"0"},{"price":"0.00054823","size":"0"},{"price":"0.00054894","size":"1302.32"}],"bid":[{"price":"0.00054549","size":"5.18"},{"price":"0.00054547","size":"0"},{"price":"0.00054527","size":"9.62"},{"price":"0.00054521","size":"0"},{"price":"0.00052910","size":"0"},{"price":"0.00052788","size":"0"},{"price":"0.00052486","size":"2974.71"}],"sequence":19513086,"timestamp":"2021-07-15T03:00:23.815Z","symbol":"UNIBTC"}}
1626318023.946647: {"jsonrpc":"2.0","method":"updateOrderbook","params":{"ask":[],"bid":[{"price":"12.085","size":"5.8825"},{"price":"12.084","size":"0"},{"price":"12.060","size":"5.8503"}],"sequence":2190688,"timestamp":"2021-07-15T03:00:23.866Z","symbol":"SPIUSD"}}
1626318023.9542131: {"jsonrpc":"2.0","method":"updateOrderbook","params":{"ask":[{"price":"0.662654","size":"399080.6"}],"bid":[],"sequence":20584092,"timestamp":"2021-07-15T03:00:23.872Z","symbol":"XRPUSDT"}}
1626318023.963983: {"jsonrpc":"2.0","method":"updateOrderbook","params":{"ask":[{"price":"0.00000094570","size":"2768940"},{"price":"0.00000146884","size":"3222000"},{"price":"0.00000147008","size":"0"}],"bid":[],"sequence":10532281,"timestamp":"2021-07-15T03:00:23.942Z","symbol":"SCBTC"}}
1626318023.964164: {"jsonrpc":"2.0","method":"updateOrderbook","params":{"ask":[{"price":"0.00054567","size":"4.33"},{"price":"0.00054568","size":"0"},{"price":"0.00054597","size":"16.70"},{"price":"0.00054610","size":"66.20"},{"price":"0.00054621","size":"18.88"},{"price":"0.00054642","size":"0"},{"price":"0.00055042","size":"843.90"},{"price":"0.00055087","size":"0"}],"bid":[{"price":"0.00054434","size":"177.91"},{"price":"0.00054412","size":"239.70"},{"price":"0.00054408","size":"0"},{"price":"0.00054396","size":"1.17"},{"price":"0.00052789","size":"444.68"}],"sequence":19513087,"timestamp":"2021-07-15T03:00:23.940Z","symbol":"UNIBTC"}}
1626318024.047641: {"jsonrpc":"2.0","method":"updateOrderbook","params":{"ask":[],"bid":[{"price":"12.086","size":"5.8695"},{"price":"12.060","size":"0"}],"sequence":2190689,"timestamp":"2021-07-15T03:00:23.971Z","symbol":"SPIUSD"}}
1626318024.062165: {"jsonrpc":"2.0","method":"updateOrderbook","params":{"ask":[{"price":"0.662654","size":"399080.9"}],"bid":[],"sequence":20584093,"timestamp":"2021-07-15T03:00:23.975Z","symbol":"XRPUSDT"}}
1626318024.06229: {"jsonrpc":"2.0","method":"updateOrderbook","params":{"ask":[{"price":"0.00000065973","size":"15230950"},{"price":"0.00000380755","size":"7466230"},{"price":"0.00000385651","size":"0"}],"bid":[],"sequence":10532282,"timestamp":"2021-07-15T03:00:23.946Z","symbol":"SCBTC"}}
1626318024.066435: {"jsonrpc":"2.0","method":"updateOrderbook","params":{"ask":[{"price":"0.00054566","size":"4.33"},{"price":"0.00054567","size":"0"}],"bid":[{"price":"0.00054549","size":"0"},{"price":"0.00054548","size":"5.18"}],"sequence":19513088,"timestamp":"2021-07-15T03:00:24.018Z","symbol":"UNIBTC"}}
1626318024.157048: {"jsonrpc":"2.0","method":"updateOrderbook","params":{"ask":[{"price":"0.627206","size":"129038.8"},{"price":"0.629647","size":"0"},{"price":"0.643665","size":"347706.3"},{"price":"0.645449","size":"0"},{"price":"0.651907","size":"181214.3"},{"price":"0.654131","size":"0"},{"price":"0.657746","size":"485414.3"},{"price":"0.659380","size":"0"},{"price":"0.662654","size":"399081.3"}],"bid":[],"sequence":20584094,"timestamp":"2021-07-15T03:00:24.098Z","symbol":"XRPUSDT"}}
1626318024.1860511: {"jsonrpc":"2.0","method":"updateOrderbook","params":{"ask":[{"price":"0.00000065973","size":"15230980"},{"price":"0.00000094570","size":"2768970"}],"bid":[{"price":"0.00000034658","size":"4600"},{"price":"0.00000034622","size":"230000"}],"sequence":10532283,"timestamp":"2021-07-15T03:00:24.094Z","symbol":"SCBTC"}}
1626318024.186114: {"jsonrpc":"2.0","method":"updateOrderbook","params":{"ask":[{"price":"0.00054565","size":"4.33"},{"price":"0.00054566","size":"0"},{"price":"0.00054631","size":"77.40"},{"price":"0.00054643","size":"0"},{"price":"0.00054645","size":"66.76"},{"price":"0.00054664","size":"0"}],"bid":[{"price":"0.00052789","size":"0"}],"sequence":19513089,"timestamp":"2021-07-15T03:00:24.105Z","symbol":"UNIBTC"}}
1626318024.186208: {"jsonrpc":"2.0","method":"updateOrderbook","params":{"ask":[{"price":"0.0004397","size":"47.197"},{"price":"0.0004398","size":"0"}],"bid":[],"sequence":2198425,"timestamp":"2021-07-15T03:00:24.099Z","symbol":"NUTBTC"}}
1626318024.254339: {"jsonrpc":"2.0","method":"updateOrderbook","params":{"ask":[{"price":"0.662654","size":"399081.5"}],"bid":[{"price":"0.610018","size":"0"},{"price":"0.609918","size":"491.8"}],"sequence":20584095,"timestamp":"2021-07-15T03:00:24.192Z","symbol":"XRPUSDT"}}
1626318024.263102: {"jsonrpc":"2.0","method":"updateOrderbook","params":{"ask":[{"price":"0.00000041289","size":"1016210"},{"price":"0.00000041341","size":"0"},{"price":"0.00000065973","size":"15230990"},{"price":"0.00000094570","size":"2768980"},{"price":"0.00000380755","size":"0"},{"price":"0.00000381291","size":"7466230"}],"bid":[],"sequence":10532284,"timestamp":"2021-07-15T03:00:24.202Z","symbol":"SCBTC"}}
1626318024.2632298: {"jsonrpc":"2.0","method":"updateOrderbook","params":{"ask":[{"price":"0.00054563","size":"4.33"},{"price":"0.00054565","size":"0"},{"price":"0.00054581","size":"10.47"},{"price":"0.00054591","size":"0"},{"price":"0.00054612","size":"199.63"},{"price":"0.00054622","size":"296.51"},{"price":"0.00054666","size":"0"},{"price":"0.00054684","size":"0"},{"price":"0.00054913","size":"3933.58"},{"price":"0.00054982","size":"0"}],"bid":[{"price":"0.00054548","size":"0"},{"price":"0.00054545","size":"5.18"},{"price":"0.00054435","size":"0"},{"price":"0.00054412","size":"515.01"},{"price":"0.00052694","size":"445.48"}],"sequence":19513090,"timestamp":"2021-07-15T03:00:24.224Z","symbol":"UNIBTC"}}
1626318024.348468: {"jsonrpc":"2.0","method":"updateOrderbook","params":{"ask":[{"price":"0.0000013617","size":"111546"},{"price":"0.0000013623","size":"0"},{"price":"0.0000013676","size":"0"},{"price":"0.0000013687","size":"210934"},{"price":"0.0000013838","size":"0"},{"price":"0.0000013851","size":"259015"},{"price":"0.0000014016","size":"0"},{"price":"0.0000014021","size":"368558"},{"price":"0.0000014222","size":"0"},{"price":"0.0000014243","size":"481455"},{"price":"0.0000015022","size":"724406"},{"price":"0.0000015029","size":"0"},{"price":"0.0000016641","size":"982126"},{"price":"0.0000016648","size":"0"},{"price":"0.0000017873","size":"0"},{"price":"0.0000017890","size":"1389932"}],"bid":[],"sequence":495980,"timestamp":"2021-07-15T03:00:24.282Z","symbol":"STPTBTC"}}
1626318024.348495: {"jsonrpc":"2.0","method":"updateOrderbook","params":{"ask":[],"bid":[{"price":"12.085","size":"0"}],"sequence":2190690,"timestamp":"2021-07-15T03:00:24.296Z","symbol":"SPIUSD"}}
1626318024.352711: {"jsonrpc":"2.0","method":"updateOrderbook","params":{"ask":[{"price":"0.662654","size":"399081.8"}],"bid":[],"sequence":20584096,"timestamp":"2021-07-15T03:00:24.277Z","symbol":"XRPUSDT"}}
1626318024.376406: {"jsonrpc":"2.0","method":"updateOrderbook","params":{"ask":[{"price":"0.00000065973","size":"15231010"},{"price":"0.00000094570","size":"2769000"}],"bid":[],"sequence":10532285,"timestamp":"2021-07-15T03:00:24.308Z","symbol":"SCBTC"}}
1626318024.376425: {"jsonrpc":"2.0","method":"updateOrderbook","params":{"ask":[{"price":"0.00054826","size":"4260.24"},{"price":"0.00054876","size":"0"}],"bid":[{"price":"0.00054546","size":"5.18"},{"price":"0.00054545","size":"0"},{"price":"0.00054376","size":"0"},{"price":"0.00054348","size":"0"},{"price":"0.00054333","size":"679.54"},{"price":"0.00054302","size":"1046.45"}],"sequence":19513091,"timestamp":"2021-07-15T03:00:24.322Z","symbol":"UNIBTC"}}
1626318024.3764648: {"jsonrpc":"2.0","method":"updateOrderbook","params":{"ask":[{"price":"0.0004397","size":"0"},{"price":"0.0004398","size":"47.197"}],"bid":[],"sequence":2198426,"timestamp":"2021-07-15T03:00:24.331Z","symbol":"NUTBTC"}}
1626318024.453442: {"jsonrpc":"2.0","method":"updateOrderbook","params":{"ask":[],"bid":[{"price":"12.087","size":"5.8815"},{"price":"12.086","size":"0"},{"price":"12.060","size":"5.8930"}],"sequence":2190691,"timestamp":"2021-07-15T03:00:24.398Z","symbol":"SPIUSD"}}
1626318024.45353: {"jsonrpc":"2.0","method":"updateOrderbook","params":{"ask":[{"price":"0.662654","size":"0"},{"price":"0.662655","size":"399082.1"}],"bid":[],"sequence":20584097,"timestamp":"2021-07-15T03:00:24.384Z","symbol":"XRPUSDT"}}
1626318024.470772: {"jsonrpc":"2.0","method":"updateOrderbook","params":{"ask":[{"price":"0.00000037254","size":"661850"},{"price":"0.00000037386","size":"3308650"},{"price":"0.00000040717","size":"522810"},{"price":"0.00000043635","size":"0"},{"price":"0.00000052883","size":"757990"},{"price":"0.00000054811","size":"0"},{"price":"0.00000065973","size":"15231030"},{"price":"0.00000094570","size":"2769010"},{"price":"0.00000159405","size":"0"},{"price":"0.00000161010","size":"4634410"},{"price":"0.00000381291","size":"0"},{"price":"0.00000416349","size":"7466230"}],"bid":[{"price":"0.00000034658","size":"234600"},{"price":"0.00000034622","size":"0"}],"sequence":10532286,"timestamp":"2021-07-15T03:00:24.436Z","symbol":"SCBTC"}}
1626318024.470811: {"jsonrpc":"2.0","method":"updateOrderbook","params":{"ask":[],"bid":[{"price":"0.00054507","size":"0"},{"price":"0.00054497","size":"18.34"},{"price":"0.00054292","size":"0"},{"price":"0.00054281","size":"634.39"},{"price":"0.00052694","size":"446.28"},{"price":"0.00052486","size":"0"},{"price":"0.00052288","size":"2974.71"}],"sequence":19513092,"timestamp":"2021-07-15T03:00:24.439Z","symbol":"UNIBTC"}}
1626318024.546425: {"jsonrpc":"2.0","method":"updateOrderbook","params":{"ask":[],"bid":[{"price":"12.088","size":"5.9165"},{"price":"12.060","size":"0"}],"sequence":2190692,"timestamp":"2021-07-15T03:00:24.469Z","symbol":"SPIUSD"}}
1626318024.56384: {"jsonrpc":"2.0","method":"updateOrderbook","params":{"ask":[{"price":"0.662655","size":"399082.4"}],"bid":[],"sequence":20584098,"timestamp":"2021-07-15T03:00:24.490Z","symbol":"XRPUSDT"}}
1626318024.5754151: {"jsonrpc":"2.0","method":"updateOrderbook","params":{"ask":[{"price":"0.00000065973","size":"15231040"},{"price":"0.00000094570","size":"2769030"}],"bid":[],"sequence":10532287,"timestamp":"2021-07-15T03:00:24.532Z","symbol":"SCBTC"}}
1626318024.577583: {"jsonrpc":"2.0","method":"updateOrderbook","params":{"ask":[{"price":"0.00054663","size":"333.84"},{"price":"0.00054707","size":"0"}],"bid":[{"price":"0.00054480","size":"69.23"},{"price":"0.00054457","size":"199.39"}],"sequence":19513093,"timestamp":"2021-07-15T03:00:24.540Z","symbol":"UNIBTC"}}
1626318024.662806: {"jsonrpc":"2.0","method":"updateOrderbook","params":{"ask":[{"price":"0.615764","size":"0"},{"price":"0.615771","size":"1331.7"},{"price":"0.616298","size":"6528.9"},{"price":"0.616354","size":"0"},{"price":"0.662655","size":"399082.9"}],"bid":[{"price":"0.615696","size":"1591.6"},{"price":"0.615681","size":"0"}],"sequence":20584099,"timestamp":"2021-07-15T03:00:24.632Z","symbol":"XRPUSDT"}}
1626318024.679382: {"jsonrpc":"2.0","method":"updateOrderbook","params":{"ask":[{"price":"0.00000037254","size":"0"},{"price":"0.00000037334","size":"661850"},{"price":"0.00000065973","size":"15231060"},{"price":"0.00000094570","size":"2769040"}],"bid":[],"sequence":10532288,"timestamp":"2021-07-15T03:00:24.627Z","symbol":"SCBTC"}}
1626318024.67942: {"jsonrpc":"2.0","method":"updateOrderbook","params":{"ask":[{"price":"0.00054639","size":"18.09"},{"price":"0.00054655","size":"0"}],"bid":[],"sequence":19513094,"timestamp":"2021-07-15T03:00:24.576Z","symbol":"UNIBTC"}}
1626318024.752407: {"jsonrpc":"2.0","method":"updateOrderbook","params":{"ask":[{"price":"0.615767","size":"1331.7"},{"price":"0.615771","size":"0"},{"price":"0.662655","size":"399083.2"}],"bid":[{"price":"0.615696","size":"0"},{"price":"0.615686","size":"1591.6"}],"sequence":20584100,"timestamp":"2021-07-15T03:00:24.739Z","symbol":"XRPUSDT"}}
1626318024.772476: {"jsonrpc":"2.0","method":"updateOrderbook","params":{"ask":[{"price":"0.00000065973","size":"15231070"},{"price":"0.00000094570","size":"2769060"}],"bid":[{"price":"0.00000036507","size":"110390"},{"price":"0.00000036482","size":"0"}],"sequence":10532289,"timestamp":"2021-07-15T03:00:24.737Z","symbol":"SCBTC"}}
1626318024.772521: {"jsonrpc":"2.0","method":"updateOrderbook","params":{"ask":[{"price":"0.00054561","size":"4.33"},{"price":"0.00054563","size":"0"},{"price":"0.00054779","size":"170.00"},{"price":"0.00054822","size":"0"},{"price":"0.00055042","size":"0"},{"price":"0.00055112","size":"843.90"},{"price":"0.00055730","size":"0"},{"price":"0.00055901","size":"2539.46"}],"bid":[{"price":"0.00054546","size":"0"},{"price":"0.00054529","size":"5.18"},{"price":"0.00054527","size":"0"},{"price":"0.00054512","size":"9.62"},{"price":"0.00054484","size":"0"},{"price":"0.00054457","size":"217.26"}],"sequence":19513095,"timestamp":"2021-07-15T03:00:24.740Z","symbol":"UNIBTC"}}
1626318024.847178: {"jsonrpc":"2.0","method":"updateOrderbook","params":{"ask":[],"bid":[{"price":"12.087","size":"0"}],"sequence":2190693,"timestamp":"2021-07-15T03:00:24.819Z","symbol":"SPIUSD"}}
1626318024.871041: {"jsonrpc":"2.0","method":"updateOrderbook","params":{"ask":[{"price":"0.00000065973","size":"15231090"},{"price":"0.00000094570","size":"2769070"}],"bid":[{"price":"0.00000036508","size":"1000"},{"price":"0.00000036483","size":"0"}],"sequence":10532290,"timestamp":"2021-07-15T03:00:24.813Z","symbol":"SCBTC"}}
1626318024.879112: {"jsonrpc":"2.0","method":"updateOrderbook","params":{"ask":[{"price":"0.00054552","size":"4.33"},{"price":"0.00054561","size":"0"},{"price":"0.00054689","size":"440.89"},{"price":"0.00054731","size":"0"},{"price":"0.00054766","size":"484.13"},{"price":"0.00054802","size":"0"},{"price":"0.00055901","size":"0"},{"price":"0.00055992","size":"2539.46"}],"bid":[{"price":"0.00054529","size":"0"},{"price":"0.00054517","size":"5.18"},{"price":"0.00054515","size":"0"},{"price":"0.00054512","size":"0"},{"price":"0.00054497","size":"9.62"},{"price":"0.00054496","size":"0"},{"price":"0.00054489","size":"0"},{"price":"0.00054486","size":"36.37"},{"price":"0.00054473","size":"0"},{"price":"0.00054467","size":"18.58"},{"price":"0.00054460","size":"0"},{"price":"0.00054457","size":"98.11"},{"price":"0.00054453","size":"0"},{"price":"0.00054451","size":"72.79"},{"price":"0.00054438","size":"199.39"},{"price":"0.00054436","size":"196.86"},{"price":"0.00054423","size":"0"},{"price":"0.00054411","size":"21.05"},{"price":"0.00054393","size":"353.16"},{"price":"0.00054335","size":"634.39"},{"price":"0.00054281","size":"0"}],"sequence":19513096,"timestamp":"2021-07-15T03:00:24.834Z","symbol":"UNIBTC"}}
1626318024.9476779: {"jsonrpc":"2.0","method":"updateOrderbook","params":{"ask":[],"bid":[{"price":"12.089","size":"5.8806"},{"price":"12.088","size":"0"},{"price":"12.060","size":"5.9817"}],"sequence":2190694,"timestamp":"2021-07-15T03:00:24.894Z","symbol":"SPIUSD"}}
1626318024.955861: {"jsonrpc":"2.0","method":"updateOrderbook","params":{"ask":[{"price":"0.662655","size":"399083.7"}],"bid":[],"sequence":20584101,"timestamp":"2021-07-15T03:00:24.895Z","symbol":"XRPUSDT"}}
1626318025.0095549: {"jsonrpc":"2.0","method":"updateOrderbook","params":{"ask":[{"price":"0.00000040717","size":"0"},{"price":"0.00000042892","size":"522810"},{"price":"0.00000052883","size":"0"},{"price":"0.00000054417","size":"757990"},{"price":"0.00000065973","size":"15231100"},{"price":"0.00000094570","size":"2769080"}],"bid":[{"price":"0.00000036507","size":"0"},{"price":"0.00000036495","size":"110390"}],"sequence":10532291,"timestamp":"2021-07-15T03:00:24.903Z","symbol":"SCBTC"}}
1626318025.009621: {"jsonrpc":"2.0","method":"updateOrderbook","params":{"ask":[{"price":"0.00054543","size":"4.33"},{"price":"0.00054552","size":"0"},{"price":"0.00054566","size":"10.47"},{"price":"0.00054581","size":"0"},{"price":"0.00054621","size":"85.64"},{"price":"0.00054645","size":"0"},{"price":"0.00054800","size":"0"},{"price":"0.00054867","size":"1245.48"},{"price":"0.00055992","size":"0"},{"price":"0.00056289","size":"2539.46"}],"bid":[{"price":"0.00054517","size":"0"},{"price":"0.00054511","size":"5.18"},{"price":"0.00054497","size":"0"},{"price":"0.00054490","size":"9.62"},{"price":"0.00054486","size":"18.34"},{"price":"0.00054480","size":"0"},{"price":"0.00054472","size":"18.03"},{"price":"0.00054450","size":"69.23"}],"sequence":19513097,"timestamp":"2021-07-15T03:00:24.941Z","symbol":"UNIBTC"}}
1626318025.046667: {"jsonrpc":"2.0","method":"updateOrderbook","params":{"ask":[],"bid":[{"price":"12.090","size":"6.0469"},{"price":"12.060","size":"0"}],"sequence":2190695,"timestamp":"2021-07-15T03:00:25.010Z","symbol":"SPIUSD"}}
1626318025.0558841: {"jsonrpc":"2.0","method":"updateOrderbook","params":{"ask":[{"price":"0.615754","size":"0"},{"price":"0.662655","size":"399084.0"}],"bid":[{"price":"0.615254","size":"1337.0"},{"price":"0.615195","size":"0"}],"sequence":20584102,"timestamp":"2021-07-15T03:00:25.016Z","symbol":"XRPUSDT"}}
1626318025.070687: {"jsonrpc":"2.0","method":"updateOrderbook","params":{"ask":[{"price":"0.00000042892","size":"0"},{"price":"0.00000043201","size":"522810"},{"price":"0.00000054417","size":"0"},{"price":"0.00000054581","size":"757990"},{"price":"0.00000065973","size":"15231120"},{"price":"0.00000094570","size":"2769100"},{"price":"0.00000095822","size":"0"},{"price":"0.00000095882","size":"2754880"}],"bid":[{"price":"0.00000036508","size":"0"},{"price":"0.00000036496","size":"1000"}],"sequence":10532292,"timestamp":"2021-07-15T03:00:25.025Z","symbol":"SCBTC"}}
1626318025.070959: {"jsonrpc":"2.0","method":"updateOrderbook","params":{"ask":[{"price":"0.00054543","size":"0"},{"price":"0.00054546","size":"4.33"},{"price":"0.00054621","size":"18.88"},{"price":"0.00054640","size":"66.76"},{"price":"0.00054693","size":"193.61"},{"price":"0.00054716","size":"0"},{"price":"0.00054727","size":"963.50"},{"price":"0.00054773","size":"0"},{"price":"0.00055281","size":"0"},{"price":"0.00055340","size":"1811.87"}],"bid":[{"price":"0.00054511","size":"0"},{"price":"0.00054500","size":"5.18"},{"price":"0.00054490","size":"0"},{"price":"0.00054481","size":"9.62"},{"price":"0.00054457","size":"80.24"},{"price":"0.00054429","size":"17.87"},{"price":"0.00054382","size":"0"},{"price":"0.00054346","size":"468.52"},{"price":"0.00054345","size":"346.15"},{"price":"0.00054335","size":"0"},{"price":"0.00054333","size":"0"},{"price":"0.00054281","size":"679.54"},{"price":"0.00054267","size":"0"},{"price":"0.00054250","size":"634.39"},{"price":"0.00054221","size":"929.35"}],"sequence":19513098,"timestamp":"2021-07-15T03:00:25.018Z","symbol":"UNIBTC"}}
1626318025.160931: {"jsonrpc":"2.0","method":"updateOrderbook","params":{"ask":[{"price":"0.615767","size":"0"},{"price":"0.615778","size":"1331.7"},{"price":"0.616297","size":"160.9"},{"price":"0.616299","size":"0"},{"price":"0.662624","size":"11000.0"},{"price":"0.662655","size":"399084.4"}],"bid":[{"price":"0.615707","size":"11000.0"},{"price":"0.615686","size":"0"},{"price":"0.615677","size":"1591.6"}],"sequence":20584103,"timestamp":"2021-07-15T03:00:25.141Z","symbol":"XRPUSDT"}}
1626318025.168695: {"jsonrpc":"2.0","method":"updateOrderbook","params":{"ask":[{"price":"0.00000065973","size":"15231140"},{"price":"0.00000094570","size":"2769110"}],"bid":[],"sequence":10532293,"timestamp":"2021-07-15T03:00:25.138Z","symbol":"SCBTC"}}
1626318025.168834: {"jsonrpc":"2.0","method":"updateOrderbook","params":{"ask":[{"price":"0.00054567","size":"16.70"},{"price":"0.00054581","size":"66.20"},{"price":"0.00054597","size":"0"},{"price":"0.00054610","size":"0"},{"price":"0.00054616","size":"34.06"},{"price":"0.00054619","size":"77.40"},{"price":"0.00054631","size":"0"},{"price":"0.00054635","size":"0"},{"price":"0.00054673","size":"276.50"},{"price":"0.00054696","size":"0"},{"price":"0.00054867","size":"587.36"},{"price":"0.00054919","size":"658.12"},{"price":"0.00056289","size":"0"},{"price":"0.00056714","size":"2539.46"}],"bid":[{"price":"0.00054426","size":"0"},{"price":"0.00054412","size":"275.31"},{"price":"0.00054400","size":"261.13"},{"price":"0.00054393","size":"0"},{"price":"0.00054390","size":"239.81"},{"price":"0.00054360","size":"353.16"},{"price":"0.00054346","size":"0"},{"price":"0.00054296","size":"468.52"},{"price":"0.00054285","size":"0"},{"price":"0.00054250","size":"0"},{"price":"0.00054226","size":"977.91"},{"price":"0.00054185","size":"634.39"},{"price":"0.00054179","size":"0"},{"price":"0.00054080","size":"986.13"},{"price":"0.00052288","size":"0"},{"price":"0.00051951","size":"2974.71"}],"sequence":19513099,"timestamp":"2021-07-15T03:00:25.127Z","symbol":"UNIBTC"}}
1626318025.253642: {"jsonrpc":"2.0","method":"updateOrderbook","params":{"ask":[{"price":"0.615765","size":"1331.7"},{"price":"0.615778","size":"0"},{"price":"0.662655","size":"399084.6"}],"bid":[{"price":"0.615677","size":"0"},{"price":"0.615661","size":"1591.6"}],"sequence":20584104,"timestamp":"2021-07-15T03:00:25.208Z","symbol":"XRPUSDT"}}
1626318025.263863: {"jsonrpc":"2.0","method":"updateOrderbook","params":{"ask":[{"price":"0.00000094570","size":"2769120"}],"bid":[],"sequence":10532294,"timestamp":"2021-07-15T03:00:25.146Z","symbol":"SCBTC"}}
1626318025.263937: {"jsonrpc":"2.0","method":"updateOrderbook","params":{"ask":[{"price":"0.00054539","size":"4.33"},{"price":"0.00054546","size":"0"},{"price":"0.00054607","size":"18.88"},{"price":"0.00054621","size":"0"},{"price":"0.00054867","size":"1245.48"},{"price":"0.00054919","size":"0"}],"bid":[{"price":"0.00054503","size":"5.18"},{"price":"0.00054500","size":"0"},{"price":"0.00054369","size":"0"},{"price":"0.00054327","size":"482.00"},{"price":"0.00051951","size":"0"},{"price":"0.00051486","size":"2974.71"}],"sequence":19513100,"timestamp":"2021-07-15T03:00:25.222Z","symbol":"UNIBTC"}}
1626318025.3569431: {"jsonrpc":"2.0","method":"updateOrderbook","params":{"ask":[{"price":"0.662655","size":"399085.0"}],"bid":[{"price":"0.615080","size":"13468.6"},{"price":"0.614980","size":"0"}],"sequence":20584105,"timestamp":"2021-07-15T03:00:25.338Z","symbol":"XRPUSDT"}}
1626318025.371419: {"jsonrpc":"2.0","method":"updateOrderbook","params":{"ask":[{"price":"0.00000065973","size":"15231170"},{"price":"0.00000094570","size":"2769140"}],"bid":[{"price":"0.00000034003","size":"14700"}],"sequence":10532295,"timestamp":"2021-07-15T03:00:25.338Z","symbol":"SCBTC"}}
1626318025.371587: {"jsonrpc":"2.0","method":"updateOrderbook","params":{"ask":[],"bid":[{"price":"0.00054467","size":"0"},{"price":"0.00054451","size":"0"},{"price":"0.00054447","size":"18.58"},{"price":"0.00054434","size":"0"},{"price":"0.00054431","size":"72.79"},{"price":"0.00054416","size":"0"},{"price":"0.00054409","size":"177.91"},{"price":"0.00054367","size":"269.93"},{"price":"0.00054366","size":"0"},{"price":"0.00054279","size":"331.21"},{"price":"0.00054006","size":"0"},{"price":"0.00053899","size":"1151.25"}],"sequence":19513101,"timestamp":"2021-07-15T03:00:25.311Z","symbol":"UNIBTC"}}
1626318025.44474: {"jsonrpc":"2.0","method":"updateOrderbook","params":{"ask":[],"bid":[{"price":"12.089","size":"0"}],"sequence":2190696,"timestamp":"2021-07-15T03:00:25.376Z","symbol":"SPIUSD"}}
1626318025.4530659: {"jsonrpc":"2.0","method":"updateOrderbook","params":{"ask":[{"price":"0.662655","size":"399085.1"}],"bid":[{"price":"0.615669","size":"1591.6"},{"price":"0.615661","size":"0"}],"sequence":20584106,"timestamp":"2021-07-15T03:00:25.401Z","symbol":"XRPUSDT"}}
1626318025.462039: {"jsonrpc":"2.0","method":"updateOrderbook","params":{"ask":[{"price":"0.00000094570","size":"2769150"}],"bid":[{"price":"0.00000034004","size":"230000"},{"price":"0.00000033944","size":"4600"}],"sequence":10532296,"timestamp":"2021-07-15T03:00:25.355Z","symbol":"SCBTC"}}
1626318025.471322: {"jsonrpc":"2.0","method":"updateOrderbook","params":{"ask":[{"price":"0.00054539","size":"0"},{"price":"0.00054554","size":"4.33"},{"price":"0.00054566","size":"0"},{"price":"0.00054578","size":"10.47"},{"price":"0.00054588","size":"199.63"},{"price":"0.00054598","size":"296.51"},{"price":"0.00054612","size":"0"},{"price":"0.00054622","size":"0"},{"price":"0.00054637","size":"201.47"},{"price":"0.00054654","size":"0"},{"price":"0.00054725","size":"291.41"},{"price":"0.00054768","size":"0"}],"bid":[{"price":"0.00054503","size":"0"},{"price":"0.00054502","size":"5.18"},{"price":"0.00054486","size":"0"},{"price":"0.00054476","size":"18.34"},{"price":"0.00054395","size":"0"},{"price":"0.00054368","size":"380.79"}],"sequence":19513102,"timestamp":"2021-07-15T03:00:25.419Z","symbol":"UNIBTC"}}
1626318025.5503192: {"jsonrpc":"2.0","method":"updateOrderbook","params":{"ask":[],"bid":[{"price":"12.091","size":"5.8796"},{"price":"12.090","size":"0"},{"price":"12.060","size":"6.1121"}],"sequence":2190697,"timestamp":"2021-07-15T03:00:25.470Z","symbol":"SPIUSD"}}
1626318025.5519319: {"jsonrpc":"2.0","method":"updateOrderbook","params":{"ask":[{"price":"0.616848","size":"5500.0"},{"price":"0.616910","size":"0"},{"price":"0.627206","size":"0"},{"price":"0.629667","size":"129038.8"},{"price":"0.651907","size":"0"},{"price":"0.654145","size":"181214.3"},{"price":"0.662655","size":"399085.5"},{"price":"0.701643","size":"0"},{"price":"0.701808","size":"228479.7"}],"bid":[{"price":"0.615669","size":"0"},{"price":"0.615664","size":"1591.6"}],"sequence":20584107,"timestamp":"2021-07-15T03:00:25.537Z","symbol":"XRPUSDT"}}
1626318025.569886: {"jsonrpc":"2.0","method":"updateOrderbook","params":{"ask":[{"price":"0.00000065973","size":"15231190"},{"price":"0.00000078071","size":"2003810"},{"price":"0.00000078433","size":"0"},{"price":"0.00000094570","size":"2769160"},{"price":"0.00000124479","size":"2705250"},{"price":"0.00000124704","size":"0"}],"bid":[],"sequence":10532297,"timestamp":"2021-07-15T03:00:25.469Z","symbol":"SCBTC"}}
1626318025.570109: {"jsonrpc":"2.0","method":"updateOrderbook","params":{"ask":[{"price":"0.00054542","size":"4.33"},{"price":"0.00054554","size":"0"},{"price":"0.00054567","size":"0"},{"price":"0.00054581","size":"0"},{"price":"0.00054585","size":"16.70"},{"price":"0.00054588","size":"0"},{"price":"0.00054598","size":"0"},{"price":"0.00054602","size":"66.20"},{"price":"0.00054638","size":"199.63"},{"price":"0.00054661","size":"296.51"},{"price":"0.00054727","size":"0"},{"price":"0.00054778","size":"963.50"}],"bid":[{"price":"0.00054509","size":"5.18"},{"price":"0.00054502","size":"0"}],"sequence":19513103,"timestamp":"2021-07-15T03:00:25.530Z","symbol":"UNIBTC"}}
1626318025.6467981: {"jsonrpc":"2.0","method":"updateOrderbook","params":{"ask":[],"bid":[{"price":"12.092","size":"6.1773"},{"price":"12.060","size":"0"}],"sequence":2190698,"timestamp":"2021-07-15T03:00:25.573Z","symbol":"SPIUSD"}}
1626318025.651115: {"jsonrpc":"2.0","method":"updateOrderbook","params":{"ask":[{"price":"0.662655","size":"399085.6"}],"bid":[{"price":"0.615678","size":"1591.6"},{"price":"0.615664","size":"0"}],"sequence":20584108,"timestamp":"2021-07-15T03:00:25.561Z","symbol":"XRPUSDT"}}
1626318025.6589: {"jsonrpc":"2.0","method":"updateOrderbook","params":{"ask":[{"price":"0.00000065973","size":"15231200"},{"price":"0.00000094570","size":"2769180"}],"bid":[{"price":"0.00000036265","size":"1248220"},{"price":"0.00000036202","size":"0"}],"sequence":10532298,"timestamp":"2021-07-15T03:00:25.578Z","symbol":"SCBTC"}}
1626318025.663094: {"jsonrpc":"2.0","method":"updateOrderbook","params":{"ask":[{"price":"0.00054536","size":"4.33"},{"price":"0.00054542","size":"0"},{"price":"0.00054562","size":"10.47"},{"price":"0.00054578","size":"0"},{"price":"0.00054597","size":"16.96"},{"price":"0.00054616","size":"17.10"}],"bid":[{"price":"0.00054509","size":"0"},{"price":"0.00054499","size":"5.18"},{"price":"0.00054492","size":"0"},{"price":"0.00054481","size":"0"},{"price":"0.00054473","size":"9.62"},{"price":"0.00054462","size":"18.61"},{"price":"0.00054327","size":"0"},{"price":"0.00054281","size":"0"},{"price":"0.00054279","size":"813.21"},{"price":"0.00054234","size":"763.54"}],"sequence":19513104,"timestamp":"2021-07-15T03:00:25.641Z","symbol":"UNIBTC"}}
1626318025.750568: {"jsonrpc":"2.0","method":"updateOrderbook","params":{"ask":[{"price":"0.662655","size":"399085.9"}],"bid":[],"sequence":20584109,"timestamp":"2021-07-15T03:00:25.665Z","symbol":"XRPUSDT"}}
1626318025.77125: {"jsonrpc":"2.0","method":"updateOrderbook","params":{"ask":[{"price":"0.00000065973","size":"15231220"},{"price":"0.00000094570","size":"2769190"}],"bid":[],"sequence":10532299,"timestamp":"2021-07-15T03:00:25.683Z","symbol":"SCBTC"}}
1626318025.771389: {"jsonrpc":"2.0","method":"updateOrderbook","params":{"ask":[{"price":"0.00054536","size":"0"},{"price":"0.00054545","size":"4.33"},{"price":"0.00054736","size":"375.71"},{"price":"0.00054780","size":"0"}],"bid":[{"price":"0.00054503","size":"5.18"},{"price":"0.00054499","size":"0"},{"price":"0.00054231","size":"0"},{"price":"0.00054166","size":"1587.01"}],"sequence":19513105,"timestamp":"2021-07-15T03:00:25.715Z","symbol":"UNIBTC"}}
1626318025.849428: {"jsonrpc":"2.0","method":"updateOrderbook","params":{"ask":[{"price":"0.662655","size":"399086.3"}],"bid":[],"sequence":20584110,"timestamp":"2021-07-15T03:00:25.805Z","symbol":"XRPUSDT"}}
1626318025.866488: {"jsonrpc":"2.0","method":"updateOrderbook","params":{"ask":[{"price":"0.00000065973","size":"15231230"},{"price":"0.00000094570","size":"2769210"}],"bid":[],"sequence":10532300,"timestamp":"2021-07-15T03:00:25.787Z","symbol":"SCBTC"}}
1626318025.866504: {"jsonrpc":"2.0","method":"updateOrderbook","params":{"ask":[{"price":"0.00054542","size":"4.33"},{"price":"0.00054545","size":"0"},{"price":"0.00054562","size":"0"},{"price":"0.00054570","size":"10.47"},{"price":"0.00054574","size":"16.70"},{"price":"0.00054585","size":"66.20"},{"price":"0.00054602","size":"0"}],"bid":[{"price":"0.00054511","size":"5.18"},{"price":"0.00054503","size":"0"},{"price":"0.00054490","size":"9.62"},{"price":"0.00054473","size":"0"}],"sequence":19513106,"timestamp":"2021-07-15T03:00:25.835Z","symbol":"UNIBTC"}}
1626318025.945927: {"jsonrpc":"2.0","method":"updateOrderbook","params":{"ask":[],"bid":[{"price":"12.091","size":"0"}],"sequence":2190699,"timestamp":"2021-07-15T03:00:25.927Z","symbol":"SPIUSD"}}
1626318025.950721: {"jsonrpc":"2.0","method":"updateOrderbook","params":{"ask":[{"price":"0.616297","size":"0"},{"price":"0.616410","size":"160.9"},{"price":"0.622891","size":"272131.6"},{"price":"0.624269","size":"0"},{"price":"0.662655","size":"399086.7"}],"bid":[{"price":"0.615097","size":"0"},{"price":"0.615081","size":"15950.8"}],"sequence":20584111,"timestamp":"2021-07-15T03:00:25.938Z","symbol":"XRPUSDT"}}
1626318025.965673: {"jsonrpc":"2.0","method":"updateOrderbook","params":{"ask":[{"price":"0.00000065973","size":"15231250"},{"price":"0.00000094570","size":"2769220"},{"price":"0.00000124479","size":"0"},{"price":"0.00000124541","size":"2705250"},{"price":"0.00000284543","size":"4472830"},{"price":"0.00000286067","size":"0"}],"bid":[],"sequence":10532301,"timestamp":"2021-07-15T03:00:25.904Z","symbol":"SCBTC"}}
1626318025.973671: {"jsonrpc":"2.0","method":"updateOrderbook","params":{"ask":[{"price":"0.00054542","size":"0"},{"price":"0.00054556","size":"4.33"},{"price":"0.00054570","size":"0"},{"price":"0.00054581","size":"10.47"},{"price":"0.00054742","size":"0"},{"price":"0.00054772","size":"0"},{"price":"0.00054794","size":"528.37"},{"price":"0.00054830","size":"331.40"},{"price":"0.00054851","size":"0"},{"price":"0.00054867","size":"587.36"},{"price":"0.00054903","size":"433.80"},{"price":"0.00055048","size":"0"},{"price":"0.00055061","size":"658.12"},{"price":"0.00055205","size":"662.81"},{"price":"0.00055340","size":"0"},{"price":"0.00055404","size":"1811.87"},{"price":"0.00056714","size":"0"},{"price":"0.00057165","size":"2539.46"}],"bid":[{"price":"0.00054516","size":"5.18"},{"price":"0.00054511","size":"0"},{"price":"0.00054401","size":"1.17"},{"price":"0.00054396","size":"0"}],"sequence":19513107,"timestamp":"2021-07-15T03:00:25.935Z","symbol":"UNIBTC"}}
1626318026.044744: {"jsonrpc":"2.0","method":"updateOrderbook","params":{"ask":[],"bid":[{"price":"12.093","size":"5.8786"},{"price":"12.092","size":"0"},{"price":"12.060","size":"6.2425"}],"sequence":2190700,"timestamp":"2021-07-15T03:00:26.001Z","symbol":"SPIUSD"}}
1626318026.0533938: {"jsonrpc":"2.0","method":"updateOrderbook","params":{"ask":[{"price":"0.615885","size":"10632.9"},{"price":"0.662655","size":"399087.0"}],"bid":[{"price":"0.615678","size":"0"},{"price":"0.615673","size":"1591.6"},{"price":"0.615255","size":"1337.0"},{"price":"0.615254","size":"0"},{"price":"0.610018","size":"491.7"},{"price":"0.609928","size":"0"},{"price":"0.609918","size":"0"},{"price":"0.608987","size":"245838.0"}],"sequence":20584112,"timestamp":"2021-07-15T03:00:26.039Z","symbol":"XRPUSDT"}}
1626318026.0691268: {"jsonrpc":"2.0","method":"updateOrderbook","params":{"ask":[{"price":"0.00000065973","size":"15231270"},{"price":"0.00000094570","size":"2769240"}],"bid":[{"price":"0.00000032529","size":"1993120"},{"price":"0.00000023134","size":"0"},{"price":"0.00000004684","size":"2752080"},{"price":"0.00000000546","size":"0"}],"sequence":10532302,"timestamp":"2021-07-15T03:00:26.015Z","symbol":"SCBTC"}}
1626318026.071528: {"jsonrpc":"2.0","method":"updateOrderbook","params":{"ask":[{"price":"0.00054549","size":"4.33"},{"price":"0.00054556","size":"0"},{"price":"0.00054574","size":"0"},{"price":"0.00054585","size":"0"},{"price":"0.00054609","size":"66.76"},{"price":"0.00054625","size":"16.70"},{"price":"0.00054639","size":"84.29"},{"price":"0.00054640","size":"0"},{"price":"0.00054779","size":"86.00"},{"price":"0.00054825","size":"84.00"}],"bid":[{"price":"0.00054525","size":"5.18"},{"price":"0.00054516","size":"0"},{"price":"0.00054500","size":"9.62"},{"price":"0.00054490","size":"0"}],"sequence":19513108,"timestamp":"2021-07-15T03:00:26.028Z","symbol":"UNIBTC"}}
1626318026.14551: {"jsonrpc":"2.0","method":"updateOrderbook","params":{"ask":[],"bid":[{"price":"12.094","size":"6.3077"},{"price":"12.060","size":"0"}],"sequence":2190701,"timestamp":"2021-07-15T03:00:26.070Z","symbol":"SPIUSD"}}
1626318026.1558971: {"jsonrpc":"2.0","method":"updateOrderbook","params":{"ask":[{"price":"0.615885","size":"0"},{"price":"0.616137","size":"10632.2"},{"price":"0.616301","size":"0"},{"price":"0.616322","size":"0"},{"price":"0.616480","size":"10632.3"},{"price":"0.616481","size":"8515.0"},{"price":"0.629667","size":"0"},{"price":"0.632729","size":"129038.8"},{"price":"0.654145","size":"0"},{"price":"0.656715","size":"181214.3"},{"price":"0.662655","size":"399087.3"},{"price":"0.701808","size":"0"}],"bid":[{"price":"0.615685","size":"1591.6"},{"price":"0.615673","size":"0"},{"price":"0.615339","size":"0"},{"price":"0.615255","size":"0"},{"price":"0.615254","size":"1337.0"}],"sequence":20584113,"timestamp":"2021-07-15T03:00:26.137Z","symbol":"XRPUSDT"}}
1626318026.170345: {"jsonrpc":"2.0","method":"updateOrderbook","params":{"ask":[{"price":"0.00000036816","size":"26770"},{"price":"0.00000036828","size":"0"},{"price":"0.00000065973","size":"15231290"},{"price":"0.00000094570","size":"2769260"}],"bid":[],"sequence":10532303,"timestamp":"2021-07-15T03:00:26.131Z","symbol":"SCBTC"}}
1626318026.1703649: {"jsonrpc":"2.0","method":"updateOrderbook","params":{"ask":[{"price":"0.00054549","size":"0"},{"price":"0.00054551","size":"4.33"},{"price":"0.00054609","size":"0"},{"price":"0.00054637","size":"0"},{"price":"0.00054639","size":"151.05"},{"price":"0.00054654","size":"201.47"},{"price":"0.00054719","size":"0"},{"price":"0.00054747","size":"250.69"},{"price":"0.00054830","size":"0"},{"price":"0.00054903","size":"0"},{"price":"0.00055028","size":"331.40"},{"price":"0.00055205","size":"0"},{"price":"0.00055263","size":"433.80"},{"price":"0.00055449","size":"662.81"},{"price":"0.00057237","size":"0"},{"price":"0.00060692","size":"881.76"},{"price":"0.00074841","size":"0"},{"price":"0.00079071","size":"1125.76"},{"price":"0.00084011","size":"0"}],"bid":[{"price":"0.00054526","size":"5.18"},{"price":"0.00054525","size":"0"},{"price":"0.00054491","size":"18.03"},{"price":"0.00054472","size":"0"}],"sequence":19513109,"timestamp":"2021-07-15T03:00:26.137Z","symbol":"UNIBTC"}}
1626318026.251953: {"jsonrpc":"2.0","method":"updateOrderbook","params":{"ask":[{"price":"0.662655","size":"399087.4"}],"bid":[{"price":"0.615562","size":"2839.8"}],"sequence":20584114,"timestamp":"2021-07-15T03:00:26.192Z","symbol":"XRPUSDT"}}
1626318026.2611468: {"jsonrpc":"2.0","method":"updateOrderbook","params":{"ask":[{"price":"0.00000065973","size":"15231300"}],"bid":[],"sequence":10532304,"timestamp":"2021-07-15T03:00:26.239Z","symbol":"SCBTC"}}
1626318026.261274: {"jsonrpc":"2.0","method":"updateOrderbook","params":{"ask":[{"price":"0.00054551","size":"0"},{"price":"0.00054562","size":"4.33"},{"price":"0.00054597","size":"0"},{"price":"0.00054639","size":"84.29"},{"price":"0.00054650","size":"16.96"},{"price":"0.00054679","size":"66.76"},{"price":"0.00054693","size":"0"},{"price":"0.00054712","size":"193.61"}],"bid":[{"price":"0.00054526","size":"0"},{"price":"0.00054523","size":"5.18"},{"price":"0.00054491","size":"0"},{"price":"0.00054476","size":"36.37"}],"sequence":19513110,"timestamp":"2021-07-15T03:00:26.218Z","symbol":"UNIBTC"}}
1626318026.354916: {"jsonrpc":"2.0","method":"updateOrderbook","params":{"ask":[{"price":"0.662655","size":"399087.8"}],"bid":[{"price":"0.615562","size":"0"},{"price":"0.615413","size":"2839.8"}],"sequence":20584115,"timestamp":"2021-07-15T03:00:26.311Z","symbol":"XRPUSDT"}}
1626318026.364755: {"jsonrpc":"2.0","method":"updateOrderbook","params":{"ask":[{"price":"0.00000094570","size":"2769270"}],"bid":[],"sequence":10532305,"timestamp":"2021-07-15T03:00:26.244Z","symbol":"SCBTC"}}
1626318026.364885: {"jsonrpc":"2.0","method":"updateOrderbook","params":{"ask":[{"price":"0.00054593","size":"16.70"},{"price":"0.00054622","size":"66.20"},{"price":"0.00054625","size":"0"},{"price":"0.00054639","size":"18.09"},{"price":"0.00054663","size":"0"},{"price":"0.00054690","size":"333.84"},{"price":"0.00054894","size":"0"},{"price":"0.00054949","size":"1302.32"},{"price":"0.00083984","size":"1585.64"}],"bid":[{"price":"0.00054528","size":"5.18"},{"price":"0.00054523","size":"0"},{"price":"0.00054395","size":"269.93"},{"price":"0.00054367","size":"0"}],"sequence":19513111,"timestamp":"2021-07-15T03:00:26.288Z","symbol":"UNIBTC"}}
1626318026.452033: {"jsonrpc":"2.0","method":"updateOrderbook","params":{"ask":[{"price":"0.615885","size":"10632.6"},{"price":"0.616137","size":"0"},{"price":"0.662655","size":"399088.0"}],"bid":[],"sequence":20584116,"timestamp":"2021-07-15T03:00:26.392Z","symbol":"XRPUSDT"}}
1626318026.4680462: {"jsonrpc":"2.0","method":"updateOrderbook","params":{"ask":[{"price":"0.00000041289","size":"0"},{"price":"0.00000041356","size":"1016210"},{"price":"0.00000065973","size":"15231320"},{"price":"0.00000088985","size":"0"},{"price":"0.00000089093","size":"2001500"},{"price":"0.00000094570","size":"2769290"},{"price":"0.00000124541","size":"0"},{"price":"0.00000124621","size":"2705250"},{"price":"0.00000146884","size":"0"},{"price":"0.00000146968","size":"3222000"}],"bid":[],"sequence":10532306,"timestamp":"2021-07-15T03:00:26.382Z","symbol":"SCBTC"}}
1626318026.4680672: {"jsonrpc":"2.0","method":"updateOrderbook","params":{"ask":[],"bid":[{"price":"0.00054531","size":"5.18"},{"price":"0.00054528","size":"0"}],"sequence":19513112,"timestamp":"2021-07-15T03:00:26.344Z","symbol":"UNIBTC"}}
1626318026.5442948: {"jsonrpc":"2.0","method":"updateOrderbook","params":{"ask":[],"bid":[{"price":"12.093","size":"0"}],"sequence":2190702,"timestamp":"2021-07-15T03:00:26.468Z","symbol":"SPIUSD"}}
1626318026.550708: {"jsonrpc":"2.0","method":"updateOrderbook","params":{"ask":[{"price":"0.615885","size":"10632.7"},{"price":"0.662655","size":"399088.2"}],"bid":[{"price":"0.615690","size":"1596.5"},{"price":"0.615685","size":"0"}],"sequence":20584117,"timestamp":"2021-07-15T03:00:26.474Z","symbol":"XRPUSDT"}}
1626318026.585873: {"jsonrpc":"2.0","method":"updateOrderbook","params":{"ask":[{"price":"0.00000065973","size":"15231340"},{"price":"0.00000094570","size":"2769310"}],"bid":[],"sequence":10532307,"timestamp":"2021-07-15T03:00:26.490Z","symbol":"SCBTC"}}
1626318026.5859149: {"jsonrpc":"2.0","method":"updateOrderbook","params":{"ask":[{"price":"0.00054560","size":"4.33"},{"price":"0.00054562","size":"0"}],"bid":[{"price":"0.00054531","size":"0"},{"price":"0.00054528","size":"5.18"},{"price":"0.00054335","size":"468.52"},{"price":"0.00054296","size":"0"},{"price":"0.00054229","size":"634.39"},{"price":"0.00054185","size":"0"}],"sequence":19513113,"timestamp":"2021-07-15T03:00:26.532Z","symbol":"UNIBTC"}}
1626318026.6446788: {"jsonrpc":"2.0","method":"updateOrderbook","params":{"ask":[{"price":"10000.000","size":"0.0010"}],"bid":[{"price":"12.095","size":"5.8776"},{"price":"12.094","size":"0"},{"price":"12.060","size":"6.3729"},{"price":"0.010","size":"1000.0010"}],"sequence":2190703,"timestamp":"2021-07-15T03:00:26.591Z","symbol":"SPIUSD"}}
1626318026.654919: {"jsonrpc":"2.0","method":"updateOrderbook","params":{"ask":[{"price":"0.621553","size":"0"},{"price":"0.623377","size":"44632.4"},{"price":"0.662655","size":"399088.6"},{"price":"0.663943","size":"0"},{"price":"0.671037","size":"229002.7"},{"price":"0.836239","size":"0"},{"price":"0.847046","size":"324970.5"}],"bid":[],"sequence":20584118,"timestamp":"2021-07-15T03:00:26.611Z","symbol":"XRPUSDT"}}
1626318026.667427: {"jsonrpc":"2.0","method":"updateOrderbook","params":{"ask":[{"price":"0.00000065973","size":"15231360"},{"price":"0.00000094570","size":"2769320"}],"bid":[],"sequence":10532308,"timestamp":"2021-07-15T03:00:26.599Z","symbol":"SCBTC"}}
1626318026.667565: {"jsonrpc":"2.0","method":"updateOrderbook","params":{"ask":[{"price":"0.00054553","size":"4.33"},{"price":"0.00054560","size":"0"},{"price":"0.00057165","size":"0"},{"price":"0.00057270","size":"2539.46"}],"bid":[{"price":"0.00054528","size":"0"},{"price":"0.00054525","size":"5.18"},{"price":"0.00054489","size":"18.03"},{"price":"0.00054476","size":"18.34"},{"price":"0.00052694","size":"0.80"}],"sequence":19513114,"timestamp":"2021-07-15T03:00:26.639Z","symbol":"UNIBTC"}}
1626318026.750734: {"jsonrpc":"2.0","method":"updateOrderbook","params":{"ask":[],"bid":[{"price":"12.096","size":"6.4381"},{"price":"12.060","size":"0"}],"sequence":2190704,"timestamp":"2021-07-15T03:00:26.668Z","symbol":"SPIUSD"}}
1626318026.750776: {"jsonrpc":"2.0","method":"updateOrderbook","params":{"ask":[{"price":"0.662655","size":"399088.7"}],"bid":[],"sequence":20584119,"timestamp":"2021-07-15T03:00:26.644Z","symbol":"XRPUSDT"}}
1626318026.7711291: {"jsonrpc":"2.0","method":"updateOrderbook","params":{"ask":[{"price":"0.00000065973","size":"15231370"},{"price":"0.00000094570","size":"2769340"}],"bid":[],"sequence":10532309,"timestamp":"2021-07-15T03:00:26.704Z","symbol":"SCBTC"}}
1626318026.771275: {"jsonrpc":"2.0","method":"updateOrderbook","params":{"ask":[{"price":"0.00054551","size":"4.33"},{"price":"0.00054553","size":"0"},{"price":"0.00054607","size":"85.08"},{"price":"0.00054611","size":"16.96"},{"price":"0.00054619","size":"0"},{"price":"0.00054622","size":"0"},{"price":"0.00054633","size":"77.40"},{"price":"0.00054650","size":"66.76"},{"price":"0.00054679","size":"0"},{"price":"0.00054692","size":"193.61"},{"price":"0.00054712","size":"0"},{"price":"0.00057270","size":"0"},{"price":"0.00057461","size":"2539.46"}],"bid":[{"price":"0.00054525","size":"0"},{"price":"0.00054523","size":"5.18"},{"price":"0.00054368","size":"862.79"},{"price":"0.00054279","size":"331.21"},{"price":"0.00052694","size":"0"}],"sequence":19513115,"timestamp":"2021-07-15T03:00:26.733Z","symbol":"UNIBTC"}}
1626318026.8500748: {"jsonrpc":"2.0","method":"updateOrderbook","params":{"ask":[{"price":"0.662655","size":"399089.1"}],"bid":[],"sequence":20584120,"timestamp":"2021-07-15T03:00:26.768Z","symbol":"XRPUSDT"}}
1626318026.863523: {"jsonrpc":"2.0","method":"updateOrderbook","params":{"ask":[{"price":"0.00000065973","size":"15231390"},{"price":"0.00000094570","size":"2769360"}],"bid":[{"price":"0.00000036496","size":"0"}],"sequence":10532310,"timestamp":"2021-07-15T03:00:26.836Z","symbol":"SCBTC"}}
1626318026.863693: {"jsonrpc":"2.0","method":"updateOrderbook","params":{"ask":[{"price":"0.00054547","size":"4.33"},{"price":"0.00054551","size":"0"}],"bid":[{"price":"0.00054524","size":"5.18"},{"price":"0.00054523","size":"0"},{"price":"0.00053050","size":"442.49"}],"sequence":19513116,"timestamp":"2021-07-15T03:00:26.839Z","symbol":"UNIBTC"}}
1626318026.9534101: {"jsonrpc":"2.0","method":"updateOrderbook","params":{"ask":[{"price":"0.662655","size":"399089.3"}],"bid":[],"sequence":20584121,"timestamp":"2021-07-15T03:00:26.844Z","symbol":"XRPUSDT"}}
1626318026.962792: {"jsonrpc":"2.0","method":"updateOrderbook","params":{"ask":[{"price":"0.00000065973","size":"15231400"},{"price":"0.00000094570","size":"2769370"}],"bid":[{"price":"0.00000036496","size":"1000"}],"sequence":10532311,"timestamp":"2021-07-15T03:00:26.901Z","symbol":"SCBTC"}}
1626318026.962958: {"jsonrpc":"2.0","method":"updateOrderbook","params":{"ask":[{"price":"0.00054547","size":"0"},{"price":"0.00054548","size":"4.33"},{"price":"0.00054571","size":"10.47"},{"price":"0.00054581","size":"0"},{"price":"0.00055325","size":"1811.87"},{"price":"0.00055404","size":"0"}],"bid":[{"price":"0.00054475","size":"18.61"},{"price":"0.00054462","size":"0"},{"price":"0.00054389","size":"353.16"},{"price":"0.00054369","size":"468.52"},{"price":"0.00054360","size":"0"},{"price":"0.00054335","size":"0"}],"sequence":19513117,"timestamp":"2021-07-15T03:00:26.919Z","symbol":"UNIBTC"}}
1626318027.045114: {"jsonrpc":"2.0","method":"updateOrderbook","params":{"ask":[],"bid":[{"price":"12.095","size":"0"}],"sequence":2190705,"timestamp":"2021-07-15T03:00:27.019Z","symbol":"SPIUSD"}}
1626318027.051521: {"jsonrpc":"2.0","method":"updateOrderbook","params":{"ask":[{"price":"0.662655","size":"399089.8"}],"bid":[{"price":"0.615696","size":"1591.6"},{"price":"0.615690","size":"4.9"}],"sequence":20584122,"timestamp":"2021-07-15T03:00:27.023Z","symbol":"XRPUSDT"}}
1626318027.068317: {"jsonrpc":"2.0","method":"updateOrderbook","params":{"ask":[{"price":"0.00000037334","size":"0"},{"price":"0.00000037368","size":"661850"},{"price":"0.00000044188","size":"0"},{"price":"0.00000044263","size":"1381850"},{"price":"0.00000065973","size":"15231420"},{"price":"0.00000089093","size":"0"},{"price":"0.00000089245","size":"2001500"},{"price":"0.00000094570","size":"2769380"}],"bid":[],"sequence":10532312,"timestamp":"2021-07-15T03:00:27.005Z","symbol":"SCBTC"}}
1626318027.0685718: {"jsonrpc":"2.0","method":"updateOrderbook","params":{"ask":[{"price":"0.00054615","size":"199.63"},{"price":"0.00054621","size":"77.40"},{"price":"0.00054625","size":"296.51"},{"price":"0.00054633","size":"0"},{"price":"0.00054638","size":"0"},{"price":"0.00054661","size":"0"}],"bid":[{"price":"0.00054526","size":"5.18"},{"price":"0.00054524","size":"0"},{"price":"0.00054345","size":"1025.69"},{"price":"0.00054270","size":"929.35"},{"price":"0.00054234","size":"84.00"},{"price":"0.00054221","size":"0"}],"sequence":19513118,"timestamp":"2021-07-15T03:00:26.996Z","symbol":"UNIBTC"}}
1626318027.146666: {"jsonrpc":"2.0","method":"updateOrderbook","params":{"ask":[],"bid":[{"price":"12.097","size":"5.8767"},{"price":"12.096","size":"0"},{"price":"12.060","size":"6.5033"}],"sequence":2190706,"timestamp":"2021-07-15T03:00:27.097Z","symbol":"SPIUSD"}}
1626318027.151287: {"jsonrpc":"2.0","method":"updateOrderbook","params":{"ask":[{"price":"0.662655","size":"399090.0"}],"bid":[{"price":"0.615701","size":"1591.6"},{"price":"0.615696","size":"0"}],"sequence":20584123,"timestamp":"2021-07-15T03:00:27.099Z","symbol":"XRPUSDT"}}
1626318027.168559: {"jsonrpc":"2.0","method":"updateOrderbook","params":{"ask":[{"price":"0.00000043091","size":"522810"},{"price":"0.00000043201","size":"0"},{"price":"0.00000054523","size":"757990"},{"price":"0.00000054581","size":"0"},{"price":"0.00000065973","size":"15231430"},{"price":"0.00000094570","size":"2769400"}],"bid":[],"sequence":10532313,"timestamp":"2021-07-15T03:00:27.112Z","symbol":"SCBTC"}}
1626318027.168779: {"jsonrpc":"2.0","method":"updateOrderbook","params":{"ask":[{"price":"0.00054548","size":"0"},{"price":"0.00054551","size":"4.33"},{"price":"0.00054621","size":"144.16"},{"price":"0.00054650","size":"0"}],"bid":[{"price":"0.00054527","size":"5.18"},{"price":"0.00054526","size":"0"},{"price":"0.00054425","size":"261.13"},{"price":"0.00054400","size":"0"},{"price":"0.00053422","size":"2974.71"},{"price":"0.00051486","size":"0"}],"sequence":19513119,"timestamp":"2021-07-15T03:00:27.112Z","symbol":"UNIBTC"}}
1626318027.2445: {"jsonrpc":"2.0","method":"updateOrderbook","params":{"ask":[],"bid":[{"price":"12.098","size":"6.5684"},{"price":"12.060","size":"0"}],"sequence":2190707,"timestamp":"2021-07-15T03:00:27.172Z","symbol":"SPIUSD"}}
1626318027.253054: {"jsonrpc":"2.0","method":"updateOrderbook","params":{"ask":[{"price":"0.615765","size":"0"},{"price":"0.615777","size":"1331.7"},{"price":"0.615885","size":"0"},{"price":"0.662655","size":"399090.4"}],"bid":[{"price":"0.615703","size":"1591.6"},{"price":"0.615701","size":"0"}],"sequence":20584124,"timestamp":"2021-07-15T03:00:27.239Z","symbol":"XRPUSDT"}}
1626318027.274137: {"jsonrpc":"2.0","method":"updateOrderbook","params":{"ask":[{"price":"0.00000065973","size":"15231450"},{"price":"0.00000094570","size":"2769410"}],"bid":[],"sequence":10532314,"timestamp":"2021-07-15T03:00:27.198Z","symbol":"SCBTC"}}
1626318027.274195: {"jsonrpc":"2.0","method":"updateOrderbook","params":{"ask":[],"bid":[{"price":"0.00054527","size":"0"},{"price":"0.00054526","size":"5.18"}],"sequence":19513120,"timestamp":"2021-07-15T03:00:27.220Z","symbol":"UNIBTC"}}
1626318027.35498: {"jsonrpc":"2.0","method":"updateOrderbook","params":{"ask":[{"price":"0.615770","size":"1331.7"},{"price":"0.615777","size":"0"},{"price":"0.615885","size":"10633.1"},{"price":"0.616848","size":"0"},{"price":"0.616911","size":"5500.0"},{"price":"0.662655","size":"399090.6"}],"bid":[],"sequence":20584125,"timestamp":"2021-07-15T03:00:27.312Z","symbol":"XRPUSDT"}}
1626318027.3795562: {"jsonrpc":"2.0","method":"updateOrderbook","params":{"ask":[{"price":"0.00000065973","size":"15231470"},{"price":"0.00000094570","size":"2769430"}],"bid":[],"sequence":10532315,"timestamp":"2021-07-15T03:00:27.332Z","symbol":"SCBTC"}}
1626318027.379596: {"jsonrpc":"2.0","method":"updateOrderbook","params":{"ask":[{"price":"0.00054551","size":"0"},{"price":"0.00054553","size":"4.33"},{"price":"0.00054571","size":"0"},{"price":"0.00054579","size":"10.47"},{"price":"0.00054621","size":"66.76"},{"price":"0.00054633","size":"77.40"},{"price":"0.00054662","size":"333.84"},{"price":"0.00054690","size":"0"},{"price":"0.00058871","size":"2343.84"},{"price":"0.00060290","size":"0"},{"price":"0.00078164","size":"3484.36"},{"price":"0.00078772","size":"0"}],"bid":[{"price":"0.00054530","size":"5.18"},{"price":"0.00054526","size":"0"},{"price":"0.00054467","size":"18.58"},{"price":"0.00054462","size":"69.23"},{"price":"0.00054451","size":"72.79"},{"price":"0.00054450","size":"0"},{"price":"0.00054447","size":"0"},{"price":"0.00054431","size":"0"},{"price":"0.00053050","size":"443.28"}],"sequence":19513121,"timestamp":"2021-07-15T03:00:27.332Z","symbol":"UNIBTC"}}
1626318027.453722: {"jsonrpc":"2.0","method":"updateOrderbook","params":{"ask":[{"price":"0.662655","size":"399090.8"}],"bid":[{"price":"0.615594","size":"2955.8"},{"price":"0.615561","size":"0"}],"sequence":20584126,"timestamp":"2021-07-15T03:00:27.390Z","symbol":"XRPUSDT"}}
1626318027.4726882: {"jsonrpc":"2.0","method":"updateOrderbook","params":{"ask":[{"price":"0.00000065973","size":"15231480"},{"price":"0.00000094570","size":"2769440"}],"bid":[],"sequence":10532316,"timestamp":"2021-07-15T03:00:27.438Z","symbol":"SCBTC"}}
1626318027.472718: {"jsonrpc":"2.0","method":"updateOrderbook","params":{"ask":[{"price":"0.00054553","size":"0"},{"price":"0.00054555","size":"4.33"},{"price":"0.00054593","size":"0"},{"price":"0.00054603","size":"16.70"},{"price":"0.00058871","size":"0"},{"price":"0.00059115","size":"2343.84"},{"price":"0.00078164","size":"0"},{"price":"0.00078270","size":"3484.36"}],"bid":[],"sequence":19513122,"timestamp":"2021-07-15T03:00:27.422Z","symbol":"UNIBTC"}}
1626318027.5583732: {"jsonrpc":"2.0","method":"updateOrderbook","params":{"ask":[{"price":"0.662655","size":"399091.1"}],"bid":[],"sequence":20584127,"timestamp":"2021-07-15T03:00:27.492Z","symbol":"XRPUSDT"}}
1626318027.565779: {"jsonrpc":"2.0","method":"updateOrderbook","params":{"ask":[{"price":"0.00000065973","size":"15231500"},{"price":"0.00000094570","size":"2769460"}],"bid":[],"sequence":10532317,"timestamp":"2021-07-15T03:00:27.534Z","symbol":"SCBTC"}}
1626318027.567002: {"jsonrpc":"2.0","method":"updateOrderbook","params":{"ask":[{"price":"0.00054555","size":"0"},{"price":"0.00054561","size":"4.33"},{"price":"0.00054621","size":"0"},{"price":"0.00054645","size":"66.76"},{"price":"0.00059115","size":"0"},{"price":"0.00059359","size":"2343.84"},{"price":"0.00068214","size":"1054.50"},{"price":"0.00069040","size":"0"},{"price":"0.00078270","size":"0"},{"price":"0.00078382","size":"3484.36"}],"bid":[{"price":"0.00054533","size":"5.18"},{"price":"0.00054530","size":"0"},{"price":"0.00053422","size":"0"},{"price":"0.00053290","size":"2974.71"}],"sequence":19513123,"timestamp":"2021-07-15T03:00:27.530Z","symbol":"UNIBTC"}}
1626318027.676927: {"jsonrpc":"2.0","method":"updateOrderbook","params":{"ask":[],"bid":[{"price":"12.097","size":"0"}],"sequence":2190708,"timestamp":"2021-07-15T03:00:27.571Z","symbol":"SPIUSD"}}
1626318027.6769862: {"jsonrpc":"2.0","method":"updateOrderbook","params":{"ask":[{"price":"0.662655","size":"399091.4"}],"bid":[],"sequence":20584128,"timestamp":"2021-07-15T03:00:27.596Z","symbol":"XRPUSDT"}}
1626318027.677011: {"jsonrpc":"2.0","method":"updateOrderbook","params":{"ask":[{"price":"0.00000065973","size":"15231510"},{"price":"0.00000094570","size":"2769470"}],"bid":[],"sequence":10532318,"timestamp":"2021-07-15T03:00:27.641Z","symbol":"SCBTC"}}
1626318027.6770308: {"jsonrpc":"2.0","method":"updateOrderbook","params":{"ask":[{"price":"0.00054579","size":"0"},{"price":"0.00054587","size":"10.47"},{"price":"0.00054607","size":"18.88"},{"price":"0.00054615","size":"0"},{"price":"0.00054621","size":"66.20"},{"price":"0.00054625","size":"0"},{"price":"0.00054649","size":"217.82"},{"price":"0.00054664","size":"296.51"}],"bid":[{"price":"0.00054537","size":"5.18"},{"price":"0.00054533","size":"0"},{"price":"0.00054512","size":"9.62"},{"price":"0.00054500","size":"0"}],"sequence":19513124,"timestamp":"2021-07-15T03:00:27.606Z","symbol":"UNIBTC"}}
1626318027.745814: {"jsonrpc":"2.0","method":"updateOrderbook","params":{"ask":[],"bid":[{"price":"12.099","size":"5.8757"},{"price":"12.098","size":"0"},{"price":"12.060","size":"6.6335"}],"sequence":2190709,"timestamp":"2021-07-15T03:00:27.668Z","symbol":"SPIUSD"}}
1626318027.7616482: {"jsonrpc":"2.0","method":"updateOrderbook","params":{"ask":[{"price":"0.643665","size":"0"},{"price":"0.645373","size":"347706.3"},{"price":"0.662655","size":"399091.8"}],"bid":[],"sequence":20584129,"timestamp":"2021-07-15T03:00:27.719Z","symbol":"XRPUSDT"}}
1626318027.849907: {"jsonrpc":"2.0","method":"updateOrderbook","params":{"ask":[],"bid":[{"price":"12.100","size":"6.6986"},{"price":"12.060","size":"0"}],"sequence":2190710,"timestamp":"2021-07-15T03:00:27.769Z","symbol":"SPIUSD"}}
1626318027.852242: {"jsonrpc":"2.0","method":"updateOrderbook","params":{"ask":[{"price":"0.662655","size":"399092.1"}],"bid":[{"price":"0.615703","size":"0"},{"price":"0.615693","size":"1591.6"}],"sequence":20584130,"timestamp":"2021-07-15T03:00:27.832Z","symbol":"XRPUSDT"}}
1626318027.865128: {"jsonrpc":"2.0","method":"updateOrderbook","params":{"ask":[{"price":"0.00000065973","size":"15231530"},{"price":"0.00000094570","size":"2769490"}],"bid":[],"sequence":10532319,"timestamp":"2021-07-15T03:00:27.747Z","symbol":"SCBTC"}}
1626318027.865152: {"jsonrpc":"2.0","method":"updateOrderbook","params":{"ask":[{"price":"0.00054592","size":"16.70"},{"price":"0.00054603","size":"0"},{"price":"0.00054712","size":"250.69"},{"price":"0.00054745","size":"528.37"},{"price":"0.00054747","size":"0"},{"price":"0.00054779","size":"0"},{"price":"0.00054794","size":"0"},{"price":"0.00054825","size":"170.00"},{"price":"0.00055013","size":"3677.57"},{"price":"0.00055086","size":"0"}],"bid":[],"sequence":19513125,"timestamp":"2021-07-15T03:00:27.834Z","symbol":"UNIBTC"}}
1626318027.9589708: {"jsonrpc":"2.0","method":"updateOrderbook","params":{"ask":[{"price":"0.662655","size":"399092.4"}],"bid":[],"sequence":20584131,"timestamp":"2021-07-15T03:00:27.930Z","symbol":"XRPUSDT"}}
1626318027.962485: {"jsonrpc":"2.0","method":"updateOrderbook","params":{"ask":[{"price":"0.00000065973","size":"15231550"},{"price":"0.00000094570","size":"2769500"}],"bid":[],"sequence":10532320,"timestamp":"2021-07-15T03:00:27.851Z","symbol":"SCBTC"}}
1626318027.962543: {"jsonrpc":"2.0","method":"updateOrderbook","params":{"ask":[],"bid":[{"price":"0.00054413","size":"1.17"},{"price":"0.00054401","size":"0"},{"price":"0.00053377","size":"2974.71"},{"price":"0.00053290","size":"0"}],"sequence":19513126,"timestamp":"2021-07-15T03:00:27.887Z","symbol":"UNIBTC"}}
1626318028.0514529: {"jsonrpc":"2.0","method":"updateOrderbook","params":{"ask":[{"price":"0.662655","size":"399092.6"}],"bid":[],"sequence":20584132,"timestamp":"2021-07-15T03:00:28.011Z","symbol":"XRPUSDT"}}
1626318028.069352: {"jsonrpc":"2.0","method":"updateOrderbook","params":{"ask":[{"price":"0.00000065973","size":"15231560"},{"price":"0.00000094570","size":"2769520"}],"bid":[],"sequence":10532321,"timestamp":"2021-07-15T03:00:27.956Z","symbol":"SCBTC"}}
1626318028.069493: {"jsonrpc":"2.0","method":"updateOrderbook","params":{"ask":[{"price":"0.00054862","size":"658.12"},{"price":"0.00055061","size":"0"}],"bid":[{"price":"0.00054345","size":"1356.90"},{"price":"0.00054279","size":"0"},{"price":"0.00053377","size":"0"},{"price":"0.00053298","size":"2974.71"}],"sequence":19513127,"timestamp":"2021-07-15T03:00:28.036Z","symbol":"UNIBTC"}}
1626318028.152491: {"jsonrpc":"2.0","method":"updateOrderbook","params":{"ask":[{"price":"0.662655","size":"399092.9"}],"bid":[],"sequence":20584133,"timestamp":"2021-07-15T03:00:28.110Z","symbol":"XRPUSDT"}}
1626318028.169369: {"jsonrpc":"2.0","method":"updateOrderbook","params":{"ask":[{"price":"0.00000065973","size":"15231580"},{"price":"0.00000094570","size":"2769530"}],"bid":[],"sequence":10532322,"timestamp":"2021-07-15T03:00:28.060Z","symbol":"SCBTC"}}
1626318028.169427: {"jsonrpc":"2.0","method":"updateOrderbook","params":{"ask":[],"bid":[{"price":"0.00054487","size":"18.61"},{"price":"0.00054475","size":"0"},{"price":"0.00054312","size":"634.39"},{"price":"0.00054229","size":"0"}],"sequence":19513128,"timestamp":"2021-07-15T03:00:28.141Z","symbol":"UNIBTC"}}
1626318028.246779: {"jsonrpc":"2.0","method":"updateOrderbook","params":{"ask":[],"bid":[{"price":"12.099","size":"0"}],"sequence":2190711,"timestamp":"2021-07-15T03:00:28.234Z","symbol":"SPIUSD"}}
1626318028.275167: {"jsonrpc":"2.0","method":"updateOrderbook","params":{"ask":[{"price":"0.662655","size":"399093.1"}],"bid":[{"price":"0.615698","size":"1591.6"},{"price":"0.615693","size":"0"}],"sequence":20584134,"timestamp":"2021-07-15T03:00:28.170Z","symbol":"XRPUSDT"}}
1626318028.2752268: {"jsonrpc":"2.0","method":"updateOrderbook","params":{"ask":[{"price":"0.00000065973","size":"15231590"},{"price":"0.00000094570","size":"2769550"}],"bid":[],"sequence":10532323,"timestamp":"2021-07-15T03:00:28.165Z","symbol":"SCBTC"}}
1626318028.275253: {"jsonrpc":"2.0","method":"updateOrderbook","params":{"ask":[{"price":"0.00054624","size":"66.76"},{"price":"0.00054645","size":"0"}],"bid":[{"price":"0.00054537","size":"0"},{"price":"0.00054535","size":"5.18"}],"sequence":19513129,"timestamp":"2021-07-15T03:00:28.224Z","symbol":"UNIBTC"}}
1626318028.345938: {"jsonrpc":"2.0","method":"updateOrderbook","params":{"ask":[],"bid":[{"price":"12.101","size":"5.8747"},{"price":"12.100","size":"0"},{"price":"12.060","size":"6.7637"}],"sequence":2190712,"timestamp":"2021-07-15T03:00:28.310Z","symbol":"SPIUSD"}}
1626318028.356641: {"jsonrpc":"2.0","method":"updateOrderbook","params":{"ask":[{"price":"0.616419","size":"0"},{"price":"0.616530","size":"508.2"},{"price":"0.662655","size":"399093.4"}],"bid":[],"sequence":20584135,"timestamp":"2021-07-15T03:00:28.278Z","symbol":"XRPUSDT"}}
1626318028.37427: {"jsonrpc":"2.0","method":"updateOrderbook","params":{"ask":[{"price":"0.00000065973","size":"15231610"},{"price":"0.00000094570","size":"2769560"}],"bid":[],"sequence":10532324,"timestamp":"2021-07-15T03:00:28.277Z","symbol":"SCBTC"}}
1626318028.374327: {"jsonrpc":"2.0","method":"updateOrderbook","params":{"ask":[{"price":"0.00054624","size":"0"},{"price":"0.00054646","size":"66.76"},{"price":"0.00054755","size":"331.40"},{"price":"0.00054992","size":"433.80"},{"price":"0.00055028","size":"0"},{"price":"0.00055263","size":"0"}],"bid":[{"price":"0.00054535","size":"0"},{"price":"0.00054531","size":"5.18"}],"sequence":19513130,"timestamp":"2021-07-15T03:00:28.320Z","symbol":"UNIBTC"}}
1626318028.4517581: {"jsonrpc":"2.0","method":"updateOrderbook","params":{"ask":[],"bid":[{"price":"12.102","size":"6.8288"},{"price":"12.060","size":"0"}],"sequence":2190713,"timestamp":"2021-07-15T03:00:28.374Z","symbol":"SPIUSD"}}
1626318028.460384: {"jsonrpc":"2.0","method":"updateOrderbook","params":{"ask":[{"price":"0.662655","size":"399093.7"}],"bid":[],"sequence":20584136,"timestamp":"2021-07-15T03:00:28.387Z","symbol":"XRPUSDT"}}
1626318028.487802: {"jsonrpc":"2.0","method":"updateOrderbook","params":{"ask":[{"price":"0.00000065973","size":"15231630"},{"price":"0.00000094570","size":"2769580"}],"bid":[],"sequence":10532325,"timestamp":"2021-07-15T03:00:28.382Z","symbol":"SCBTC"}}
1626318028.4878578: {"jsonrpc":"2.0","method":"updateOrderbook","params":{"ask":[{"price":"0.00054556","size":"4.33"},{"price":"0.00054561","size":"0"}],"bid":[],"sequence":19513131,"timestamp":"2021-07-15T03:00:28.391Z","symbol":"UNIBTC"}}
1626318028.553919: {"jsonrpc":"2.0","method":"updateOrderbook","params":{"ask":[{"price":"0.615770","size":"0"},{"price":"0.615772","size":"1331.7"},{"price":"0.662655","size":"399094.1"}],"bid":[{"price":"0.615704","size":"1591.6"},{"price":"0.615698","size":"0"}],"sequence":20584137,"timestamp":"2021-07-15T03:00:28.524Z","symbol":"XRPUSDT"}}
1626318028.5722098: {"jsonrpc":"2.0","method":"updateOrderbook","params":{"ask":[{"price":"0.00000036716","size":"25530"},{"price":"0.00000036726","size":"0"},{"price":"0.00000065973","size":"15231650"},{"price":"0.00000094570","size":"2769600"}],"bid":[],"sequence":10532326,"timestamp":"2021-07-15T03:00:28.526Z","symbol":"SCBTC"}}
1626318028.58269: {"jsonrpc":"2.0","method":"updateOrderbook","params":{"ask":[{"price":"0.00056035","size":"2539.46"},{"price":"0.00057461","size":"0"}],"bid":[{"price":"0.00054512","size":"0"},{"price":"0.00054505","size":"9.62"}],"sequence":19513132,"timestamp":"2021-07-15T03:00:28.541Z","symbol":"UNIBTC"}}
1626318028.684014: {"jsonrpc":"2.0","method":"updateOrderbook","params":{"ask":[{"price":"0.615772","size":"0"},{"price":"0.615778","size":"1331.7"},{"price":"0.615885","size":"0"},{"price":"0.616137","size":"10633.0"},{"price":"0.662655","size":"399094.4"}],"bid":[{"price":"0.615704","size":"0"},{"price":"0.615686","size":"1591.6"}],"sequence":20584138,"timestamp":"2021-07-15T03:00:28.630Z","symbol":"XRPUSDT"}}
1626318028.684124: {"jsonrpc":"2.0","method":"updateOrderbook","params":{"ask":[{"price":"0.00000036716","size":"0"},{"price":"0.00000036726","size":"25530"},{"price":"0.00000065973","size":"15231660"},{"price":"0.00000089245","size":"0"},{"price":"0.00000089324","size":"2001500"},{"price":"0.00000094570","size":"2769610"}],"bid":[],"sequence":10532327,"timestamp":"2021-07-15T03:00:28.625Z","symbol":"SCBTC"}}
1626318028.684192: {"jsonrpc":"2.0","method":"updateOrderbook","params":{"ask":[{"price":"0.00054556","size":"0"},{"price":"0.00054559","size":"4.33"},{"price":"0.00054607","size":"85.08"},{"price":"0.00054620","size":"66.76"},{"price":"0.00054621","size":"0"},{"price":"0.00054646","size":"0"},{"price":"0.00054777","size":"86.00"},{"price":"0.00054825","size":"84.00"}],"bid":[],"sequence":19513133,"timestamp":"2021-07-15T03:00:28.641Z","symbol":"UNIBTC"}}
1626318028.7737799: {"jsonrpc":"2.0","method":"updateOrderbook","params":{"ask":[{"price":"0.616137","size":"10633.1"},{"price":"0.662655","size":"399094.7"}],"bid":[],"sequence":20584139,"timestamp":"2021-07-15T03:00:28.732Z","symbol":"XRPUSDT"}}
1626318028.790704: {"jsonrpc":"2.0","method":"updateOrderbook","params":{"ask":[{"price":"0.00000065973","size":"15231680"},{"price":"0.00000094570","size":"2769630"},{"price":"0.00000161010","size":"0"},{"price":"0.00000161321","size":"4634410"},{"price":"0.00000416349","size":"0"},{"price":"0.00000419436","size":"7466230"}],"bid":[],"sequence":10532328,"timestamp":"2021-07-15T03:00:28.732Z","symbol":"SCBTC"}}
1626318028.790946: {"jsonrpc":"2.0","method":"updateOrderbook","params":{"ask":[{"price":"0.00054559","size":"0"},{"price":"0.00054561","size":"4.33"},{"price":"0.00054607","size":"18.88"},{"price":"0.00054620","size":"66.20"},{"price":"0.00054662","size":"400.60"},{"price":"0.00054777","size":"0"},{"price":"0.00054825","size":"170.00"},{"price":"0.00059359","size":"0"},{"price":"0.00059528","size":"2343.84"}],"bid":[{"price":"0.00054533","size":"5.18"},{"price":"0.00054531","size":"0"}],"sequence":19513134,"timestamp":"2021-07-15T03:00:28.705Z","symbol":"UNIBTC"}}
1626318028.8542678: {"jsonrpc":"2.0","method":"updateOrderbook","params":{"ask":[{"price":"0.615885","size":"10633.3"},{"price":"0.616137","size":"0"},{"price":"0.662655","size":"399095.0"}],"bid":[],"sequence":20584140,"timestamp":"2021-07-15T03:00:28.832Z","symbol":"XRPUSDT"}}
1626318028.8641: {"jsonrpc":"2.0","method":"updateOrderbook","params":{"ask":[{"price":"0.00000065973","size":"15231690"},{"price":"0.00000094570","size":"2769640"}],"bid":[],"sequence":10532329,"timestamp":"2021-07-15T03:00:28.837Z","symbol":"SCBTC"}}
1626318028.873291: {"jsonrpc":"2.0","method":"updateOrderbook","params":{"ask":[],"bid":[{"price":"0.00054535","size":"5.18"},{"price":"0.00054533","size":"0"}],"sequence":19513135,"timestamp":"2021-07-15T03:00:28.774Z","symbol":"UNIBTC"}}
1626318028.9563498: {"jsonrpc":"2.0","method":"updateOrderbook","params":{"ask":[{"price":"0.615774","size":"1331.7"},{"price":"0.615778","size":"0"},{"price":"0.643805","size":"347706.3"},{"price":"0.645373","size":"0"},{"price":"0.662655","size":"399095.3"}],"bid":[{"price":"0.615081","size":"6397.5"}],"sequence":20584141,"timestamp":"2021-07-15T03:00:28.937Z","symbol":"XRPUSDT"}}
1626318028.956484: {"jsonrpc":"2.0","method":"updateOrderbook","params":{"ask":[{"price":"0.00000065973","size":"15231710"},{"price":"0.00000094570","size":"2769660"}],"bid":[],"sequence":10532330,"timestamp":"2021-07-15T03:00:28.942Z","symbol":"SCBTC"}}
1626318028.969954: {"jsonrpc":"2.0","method":"updateOrderbook","params":{"ask":[{"price":"0.00054559","size":"4.33"},{"price":"0.00054561","size":"0"},{"price":"0.00054622","size":"77.40"},{"price":"0.00054633","size":"0"},{"price":"0.00055615","size":"881.76"},{"price":"0.00060692","size":"0"}],"bid":[{"price":"0.00054535","size":"0"},{"price":"0.00054533","size":"5.18"},{"price":"0.00054413","size":"0"},{"price":"0.00054410","size":"1.17"}],"sequence":19513136,"timestamp":"2021-07-15T03:00:28.913Z","symbol":"UNIBTC"}}
1626318029.044769: {"jsonrpc":"2.0","method":"updateOrderbook","params":{"ask":[],"bid":[{"price":"12.101","size":"0"}],"sequence":2190714,"timestamp":"2021-07-15T03:00:28.987Z","symbol":"SPIUSD"}}
1626318029.0564759: {"jsonrpc":"2.0","method":"updateOrderbook","params":{"ask":[{"price":"0.662655","size":"399095.4"}],"bid":[{"price":"0.615691","size":"1591.6"},{"price":"0.615686","size":"0"}],"sequence":20584142,"timestamp":"2021-07-15T03:00:28.998Z","symbol":"XRPUSDT"}}
1626318029.077735: {"jsonrpc":"2.0","method":"updateOrderbook","params":{"ask":[{"price":"0.00054607","size":"0"},{"price":"0.00054620","size":"85.08"},{"price":"0.00054622","size":"0"},{"price":"0.00054638","size":"77.40"}],"bid":[{"price":"0.00054487","size":"0"},{"price":"0.00054476","size":"36.95"},{"price":"0.00054462","size":"0"},{"price":"0.00054451","size":"142.02"}],"sequence":19513137,"timestamp":"2021-07-15T03:00:29.033Z","symbol":"UNIBTC"}}
1626318029.1488981: {"jsonrpc":"2.0","method":"updateOrderbook","params":{"ask":[],"bid":[{"price":"12.103","size":"12.8327"},{"price":"12.102","size":"0"}],"sequence":2190715,"timestamp":"2021-07-15T03:00:29.102Z","symbol":"SPIUSD"}}
1626318029.155076: {"jsonrpc":"2.0","method":"updateOrderbook","params":{"ask":[{"price":"0.662655","size":"399095.7"}],"bid":[],"sequence":20584143,"timestamp":"2021-07-15T03:00:29.085Z","symbol":"XRPUSDT"}}
1626318029.16567: {"jsonrpc":"2.0","method":"updateOrderbook","params":{"ask":[{"price":"0.00000065973","size":"15231730"},{"price":"0.00000094570","size":"2769670"}],"bid":[],"sequence":10532331,"timestamp":"2021-07-15T03:00:29.047Z","symbol":"SCBTC"}}
1626318029.165729: {"jsonrpc":"2.0","method":"updateOrderbook","params":{"ask":[{"price":"0.00054777","size":"86.00"},{"price":"0.00054825","size":"84.00"}],"bid":[],"sequence":19513138,"timestamp":"2021-07-15T03:00:29.095Z","symbol":"UNIBTC"}}
1626318029.2685921: {"jsonrpc":"2.0","method":"updateOrderbook","params":{"ask":[{"price":"0.615885","size":"10633.2"},{"price":"0.629354","size":"129038.8"},{"price":"0.632729","size":"0"},{"price":"0.653889","size":"181214.3"},{"price":"0.656715","size":"0"},{"price":"0.662655","size":"399096.0"}],"bid":[],"sequence":20584144,"timestamp":"2021-07-15T03:00:29.206Z","symbol":"XRPUSDT"}}
1626318029.2686348: {"jsonrpc":"2.0","method":"updateOrderbook","params":{"ask":[{"price":"0.00000065973","size":"15231740"},{"price":"0.00000094570","size":"2769690"}],"bid":[],"sequence":10532332,"timestamp":"2021-07-15T03:00:29.157Z","symbol":"SCBTC"}}
1626318029.27477: {"jsonrpc":"2.0","method":"updateOrderbook","params":{"ask":[{"price":"0.00054625","size":"66.76"},{"price":"0.00054662","size":"333.84"},{"price":"0.00055054","size":"662.81"},{"price":"0.00055449","size":"0"}],"bid":[],"sequence":19513139,"timestamp":"2021-07-15T03:00:29.200Z","symbol":"UNIBTC"}}
1626318029.36557: {"jsonrpc":"2.0","method":"updateOrderbook","params":{"ask":[{"price":"0.662655","size":"399096.3"}],"bid":[{"price":"0.615696","size":"1591.6"},{"price":"0.615691","size":"0"}],"sequence":20584145,"timestamp":"2021-07-15T03:00:29.315Z","symbol":"XRPUSDT"}}
1626318029.376557: {"jsonrpc":"2.0","method":"updateOrderbook","params":{"ask":[{"price":"0.00000065973","size":"15231760"},{"price":"0.00000094570","size":"2769700"}],"bid":[],"sequence":10532333,"timestamp":"2021-07-15T03:00:29.267Z","symbol":"SCBTC"}}
1626318029.378434: {"jsonrpc":"2.0","method":"updateOrderbook","params":{"ask":[{"price":"0.00054555","size":"4.33"},{"price":"0.00054559","size":"0"},{"price":"0.00067877","size":"1125.76"},{"price":"0.00079071","size":"0"}],"bid":[{"price":"0.00054533","size":"0"},{"price":"0.00054531","size":"5.18"},{"price":"0.00054476","size":"18.34"},{"price":"0.00054464","size":"18.61"}],"sequence":19513140,"timestamp":"2021-07-15T03:00:29.341Z","symbol":"UNIBTC"}}
1626318029.383295: {"jsonrpc":"2.0","method":"updateOrderbook","params":{"ask":[{"price":"0.0004397","size":"47.197"},{"price":"0.0004398","size":"0"}],"bid":[],"sequence":2198427,"timestamp":"2021-07-15T03:00:29.340Z","symbol":"NUTBTC"}}
1626318029.464349: {"jsonrpc":"2.0","method":"updateOrderbook","params":{"ask":[{"price":"0.662655","size":"399096.6"}],"bid":[],"sequence":20584146,"timestamp":"2021-07-15T03:00:29.418Z","symbol":"XRPUSDT"}}
1626318029.4698281: {"jsonrpc":"2.0","method":"updateOrderbook","params":{"ask":[{"price":"0.00000065973","size":"15231780"},{"price":"0.00000094570","size":"2769740"}],"bid":[],"sequence":10532334,"timestamp":"2021-07-15T03:00:29.441Z","symbol":"SCBTC"}}
1626318029.4699671: {"jsonrpc":"2.0","method":"updateOrderbook","params":{"ask":[{"price":"0.00054555","size":"0"},{"price":"0.00054558","size":"4.33"}],"bid":[],"sequence":19513141,"timestamp":"2021-07-15T03:00:29.430Z","symbol":"UNIBTC"}}
1626318029.5579: {"jsonrpc":"2.0","method":"updateOrderbook","params":{"ask":[{"price":"0.662655","size":"399096.9"}],"bid":[],"sequence":20584147,"timestamp":"2021-07-15T03:00:29.520Z","symbol":"XRPUSDT"}}
1626318029.5693812: {"jsonrpc":"2.0","method":"updateOrderbook","params":{"ask":[{"price":"0.00000065973","size":"15231800"},{"price":"0.00000094570","size":"2769750"}],"bid":[],"sequence":10532335,"timestamp":"2021-07-15T03:00:29.527Z","symbol":"SCBTC"}}
1626318029.569439: {"jsonrpc":"2.0","method":"updateOrderbook","params":{"ask":[{"price":"0.00054556","size":"4.33"},{"price":"0.00054558","size":"0"},{"price":"0.00054610","size":"18.88"},{"price":"0.00054620","size":"143.60"},{"price":"0.00054638","size":"0"},{"price":"0.00054819","size":"658.12"},{"price":"0.00054862","size":"0"},{"price":"0.00055066","size":"843.90"},{"price":"0.00055112","size":"0"}],"bid":[{"price":"0.00054489","size":"0"},{"price":"0.00054471","size":"18.03"}],"sequence":19513142,"timestamp":"2021-07-15T03:00:29.533Z","symbol":"UNIBTC"}}
1626318029.651836: {"jsonrpc":"2.0","method":"updateOrderbook","params":{"ask":[{"price":"0.615881","size":"3215.6"},{"price":"0.615886","size":"0"},{"price":"0.616151","size":"5554.2"},{"price":"0.616183","size":"0"},{"price":"0.616283","size":"6528.7"},{"price":"0.616298","size":"0"},{"price":"0.662655","size":"399097.2"}],"bid":[{"price":"0.615696","size":"1591.5"},{"price":"0.615594","size":"0"},{"price":"0.615587","size":"2955.7"},{"price":"0.615317","size":"5489.3"},{"price":"0.615254","size":"0"},{"price":"0.615253","size":"0"},{"price":"0.615195","size":"1337.0"},{"price":"0.615181","size":"6463.7"},{"price":"0.614984","size":"0"}],"sequence":20584148,"timestamp":"2021-07-15T03:00:29.621Z","symbol":"XRPUSDT"}}
1626318029.673673: {"jsonrpc":"2.0","method":"updateOrderbook","params":{"ask":[{"price":"0.00000065973","size":"15231810"},{"price":"0.00000094570","size":"2769770"}],"bid":[],"sequence":10532336,"timestamp":"2021-07-15T03:00:29.636Z","symbol":"SCBTC"}}
1626318029.765433: {"jsonrpc":"2.0","method":"updateOrderbook","params":{"ask":[{"price":"0.616839","size":"5500.0"},{"price":"0.616911","size":"0"},{"price":"0.629354","size":"0"},{"price":"0.632203","size":"129038.8"},{"price":"0.653889","size":"0"},{"price":"0.656260","size":"181214.3"},{"price":"0.662655","size":"399097.5"}],"bid":[],"sequence":20584149,"timestamp":"2021-07-15T03:00:29.730Z","symbol":"XRPUSDT"}}
1626318029.765496: {"jsonrpc":"2.0","method":"updateOrderbook","params":{"ask":[{"price":"0.00000065973","size":"15231830"}],"bid":[],"sequence":10532337,"timestamp":"2021-07-15T03:00:29.740Z","symbol":"SCBTC"}}
1626318029.7655191: {"jsonrpc":"2.0","method":"updateOrderbook","params":{"ask":[{"price":"0.00083080","size":"1585.64"},{"price":"0.00083984","size":"0"}],"bid":[],"sequence":19513143,"timestamp":"2021-07-15T03:00:29.721Z","symbol":"UNIBTC"}}
1626318029.866672: {"jsonrpc":"2.0","method":"updateOrderbook","params":{"ask":[{"price":"0.662655","size":"399097.8"}],"bid":[],"sequence":20584150,"timestamp":"2021-07-15T03:00:29.834Z","symbol":"XRPUSDT"}}
1626318029.86673: {"jsonrpc":"2.0","method":"updateOrderbook","params":{"ask":[{"price":"0.00000094570","size":"2769790"}],"bid":[],"sequence":10532338,"timestamp":"2021-07-15T03:00:29.749Z","symbol":"SCBTC"}}
1626318029.866754: {"jsonrpc":"2.0","method":"updateOrderbook","params":{"ask":[],"bid":[{"price":"0.00054531","size":"0"},{"price":"0.00054530","size":"5.18"},{"price":"0.00054477","size":"18.61"},{"price":"0.00054464","size":"0"}],"sequence":19513144,"timestamp":"2021-07-15T03:00:29.789Z","symbol":"UNIBTC"}}
1626318029.866838: {"jsonrpc":"2.0","method":"updateOrderbook","params":{"ask":[{"price":"0.0004397","size":"0"},{"price":"0.0004398","size":"47.197"}],"bid":[],"sequence":2198428,"timestamp":"2021-07-15T03:00:29.837Z","symbol":"NUTBTC"}}
1626318029.959954: {"jsonrpc":"2.0","method":"updateOrderbook","params":{"ask":[{"price":"0.615885","size":"0"},{"price":"0.616383","size":"160.9"},{"price":"0.616410","size":"0"},{"price":"0.662655","size":"399098.1"}],"bid":[{"price":"0.615707","size":"0"},{"price":"0.615703","size":"11000.0"},{"price":"0.615696","size":"0"},{"price":"0.615694","size":"1591.5"}],"sequence":20584151,"timestamp":"2021-07-15T03:00:29.938Z","symbol":"XRPUSDT"}}
1626318030.004771: {"jsonrpc":"2.0","method":"updateOrderbook","params":{"ask":[{"price":"0.00000037368","size":"0"},{"price":"0.00000037408","size":"661850"},{"price":"0.00000044263","size":"0"},{"price":"0.00000044325","size":"1381850"},{"price":"0.00000065973","size":"15231860"},{"price":"0.00000089324","size":"0"},{"price":"0.00000089465","size":"2001500"},{"price":"0.00000094570","size":"2769820"},{"price":"0.00000124621","size":"0"},{"price":"0.00000124701","size":"2705250"}],"bid":[],"sequence":10532339,"timestamp":"2021-07-15T03:00:29.910Z","symbol":"SCBTC"}}
1626318030.004997: {"jsonrpc":"2.0","method":"updateOrderbook","params":{"ask":[],"bid":[{"price":"0.00054531","size":"5.18"},{"price":"0.00054530","size":"0"},{"price":"0.00054481","size":"18.03"},{"price":"0.00054471","size":"0"},{"price":"0.00054466","size":"69.23"},{"price":"0.00054451","size":"72.79"}],"sequence":19513145,"timestamp":"2021-07-15T03:00:29.923Z","symbol":"UNIBTC"}}
1626318030.052047: {"jsonrpc":"2.0","method":"updateOrderbook","params":{"ask":[{"price":"0.616137","size":"10632.8"},{"price":"0.662655","size":"399098.4"}],"bid":[{"price":"0.615196","size":"1337.0"},{"price":"0.615195","size":"0"}],"sequence":20584152,"timestamp":"2021-07-15T03:00:30.041Z","symbol":"XRPUSDT"}}
1626318030.062258: {"jsonrpc":"2.0","method":"updateOrderbook","params":{"ask":[{"price":"0.00000065973","size":"15231870"},{"price":"0.00000094570","size":"2769840"}],"bid":[],"sequence":10532340,"timestamp":"2021-07-15T03:00:30.015Z","symbol":"SCBTC"}}
1626318030.1812632: {"jsonrpc":"2.0","method":"updateOrderbook","params":{"ask":[{"price":"0.615880","size":"10632.7"},{"price":"0.616137","size":"0"},{"price":"0.662655","size":"399098.7"}],"bid":[{"price":"0.615318","size":"1337.0"},{"price":"0.615196","size":"0"}],"sequence":20584153,"timestamp":"2021-07-15T03:00:30.138Z","symbol":"XRPUSDT"}}
1626318030.181324: {"jsonrpc":"2.0","method":"updateOrderbook","params":{"ask":[{"price":"0.00000065973","size":"15231890"},{"price":"0.00000094570","size":"2769860"}],"bid":[],"sequence":10532341,"timestamp":"2021-07-15T03:00:30.123Z","symbol":"SCBTC"}}
1626318030.18135: {"jsonrpc":"2.0","method":"updateOrderbook","params":{"ask":[{"price":"0.00054556","size":"0"},{"price":"0.00054559","size":"4.33"}],"bid":[{"price":"0.00054531","size":"0"},{"price":"0.00054526","size":"5.18"}],"sequence":19513146,"timestamp":"2021-07-15T03:00:30.123Z","symbol":"UNIBTC"}}
1626318030.2706938: {"jsonrpc":"2.0","method":"updateOrderbook","params":{"ask":[{"price":"0.615880","size":"0"},{"price":"0.616137","size":"10632.2"}],"bid":[{"price":"0.615318","size":"0"},{"price":"0.615196","size":"1337.0"}],"sequence":20584154,"timestamp":"2021-07-15T03:00:30.156Z","symbol":"XRPUSDT"}}
1626318030.2766578: {"jsonrpc":"2.0","method":"updateOrderbook","params":{"ask":[{"price":"0.00000065973","size":"15231900"},{"price":"0.00000094570","size":"2769880"}],"bid":[{"price":"0.00000036495","size":"0"},{"price":"0.00000036482","size":"110390"},{"price":"0.00000032529","size":"0"},{"price":"0.00000032212","size":"1993120"},{"price":"0.00000004684","size":"0"},{"price":"0.00000004424","size":"2752080"}],"sequence":10532342,"timestamp":"2021-07-15T03:00:30.238Z","symbol":"SCBTC"}}
1626318030.276682: {"jsonrpc":"2.0","method":"updateOrderbook","params":{"ask":[{"price":"0.00054551","size":"4.33"},{"price":"0.00054559","size":"0"}],"bid":[],"sequence":19513147,"timestamp":"2021-07-15T03:00:30.226Z","symbol":"UNIBTC"}}
1626318030.347923: {"jsonrpc":"2.0","method":"updateOrderbook","params":{"ask":[{"price":"0.662655","size":"399099.1"}],"bid":[],"sequence":20584155,"timestamp":"2021-07-15T03:00:30.277Z","symbol":"XRPUSDT"}}
1626318030.378716: {"jsonrpc":"2.0","method":"updateOrderbook","params":{"ask":[{"price":"0.00000037357","size":"661850"},{"price":"0.00000037408","size":"0"},{"price":"0.00000065973","size":"15231920"},{"price":"0.00000094570","size":"2769900"},{"price":"0.00000124640","size":"2705250"},{"price":"0.00000124701","size":"0"}],"bid":[{"price":"0.00000036496","size":"0"},{"price":"0.00000036483","size":"1000"}],"sequence":10532343,"timestamp":"2021-07-15T03:00:30.333Z","symbol":"SCBTC"}}
1626318030.378761: {"jsonrpc":"2.0","method":"updateOrderbook","params":{"ask":[{"price":"0.00054575","size":"10.47"},{"price":"0.00054587","size":"0"}],"bid":[],"sequence":19513148,"timestamp":"2021-07-15T03:00:30.302Z","symbol":"UNIBTC"}}
1626318030.4538612: {"jsonrpc":"2.0","method":"updateOrderbook","params":{"ask":[{"price":"0.615880","size":"10632.6"},{"price":"0.616137","size":"0"},{"price":"0.662655","size":"399099.5"}],"bid":[{"price":"0.615196","size":"0"},{"price":"0.615195","size":"1337.0"},{"price":"0.610018","size":"0"},{"price":"0.609918","size":"491.8"}],"sequence":20584156,"timestamp":"2021-07-15T03:00:30.414Z","symbol":"XRPUSDT"}}
1626318030.4539268: {"jsonrpc":"2.0","method":"updateOrderbook","params":{"ask":[{"price":"0.00000065973","size":"15231930"},{"price":"0.00000094570","size":"2769920"}],"bid":[],"sequence":10532344,"timestamp":"2021-07-15T03:00:30.441Z","symbol":"SCBTC"}}
1626318030.456577: {"jsonrpc":"2.0","method":"updateOrderbook","params":{"ask":[{"price":"0.00055615","size":"0"},{"price":"0.00056925","size":"881.76"},{"price":"0.00067877","size":"0"},{"price":"0.00073715","size":"1125.76"},{"price":"0.00083080","size":"0"},{"price":"0.00083870","size":"1585.64"}],"bid":[],"sequence":19513149,"timestamp":"2021-07-15T03:00:30.400Z","symbol":"UNIBTC"}}
1626318030.562335: {"jsonrpc":"2.0","method":"updateOrderbook","params":{"ask":[{"price":"0.616382","size":"160.9"},{"price":"0.616383","size":"0"},{"price":"0.662655","size":"399099.8"},{"price":"0.701792","size":"228479.7"}],"bid":[{"price":"0.615703","size":"0"},{"price":"0.615698","size":"11000.0"},{"price":"0.615694","size":"0"},{"price":"0.615646","size":"1591.5"},{"price":"0.615587","size":"0"},{"price":"0.615541","size":"2955.7"}],"sequence":20584157,"timestamp":"2021-07-15T03:00:30.529Z","symbol":"XRPUSDT"}}
1626318030.568373: {"jsonrpc":"2.0","method":"updateOrderbook","params":{"ask":[{"price":"0.00000065973","size":"15231950"},{"price":"0.00000094570","size":"2769930"}],"bid":[],"sequence":10532345,"timestamp":"2021-07-15T03:00:30.526Z","symbol":"SCBTC"}}
1626318030.6510022: {"jsonrpc":"2.0","method":"updateOrderbook","params":{"ask":[{"price":"0.616722","size":"9601.1"},{"price":"0.617137","size":"0"},{"price":"0.662655","size":"399100.1"}],"bid":[{"price":"0.615646","size":"0"},{"price":"0.615619","size":"1591.5"}],"sequence":20584158,"timestamp":"2021-07-15T03:00:30.615Z","symbol":"XRPUSDT"}}
1626318030.6711879: {"jsonrpc":"2.0","method":"updateOrderbook","params":{"ask":[{"price":"0.00000065973","size":"15231960"},{"price":"0.00000094570","size":"2769950"}],"bid":[],"sequence":10532346,"timestamp":"2021-07-15T03:00:30.631Z","symbol":"SCBTC"}}
1626318030.676469: {"jsonrpc":"2.0","method":"updateOrderbook","params":{"ask":[{"price":"0.00054549","size":"4.33"},{"price":"0.00054551","size":"0"},{"price":"0.00054580","size":"16.70"},{"price":"0.00054592","size":"0"},{"price":"0.00054594","size":"66.20"},{"price":"0.00054620","size":"77.40"},{"price":"0.00055054","size":"0"},{"price":"0.00055196","size":"662.81"},{"price":"0.00058544","size":"2343.84"},{"price":"0.00059528","size":"0"},{"price":"0.00078017","size":"3484.36"},{"price":"0.00078382","size":"0"}],"bid":[{"price":"0.00054526","size":"0"},{"price":"0.00054525","size":"5.18"}],"sequence":19513150,"timestamp":"2021-07-15T03:00:30.624Z","symbol":"UNIBTC"}}
1626318030.755956: {"jsonrpc":"2.0","method":"updateOrderbook","params":{"ask":[{"price":"0.615880","size":"0"},{"price":"0.616137","size":"10632.5"},{"price":"0.662655","size":"399100.4"}],"bid":[{"price":"0.615619","size":"0"},{"price":"0.615613","size":"1591.5"},{"price":"0.615541","size":"0"},{"price":"0.615508","size":"2955.7"}],"sequence":20584159,"timestamp":"2021-07-15T03:00:30.725Z","symbol":"XRPUSDT"}}
1626318030.763746: {"jsonrpc":"2.0","method":"updateOrderbook","params":{"ask":[{"price":"0.00000065973","size":"15231980"},{"price":"0.00000094570","size":"2769970"}],"bid":[],"sequence":10532347,"timestamp":"2021-07-15T03:00:30.736Z","symbol":"SCBTC"}}
1626318030.85105: {"jsonrpc":"2.0","method":"updateOrderbook","params":{"ask":[{"price":"0.662655","size":"399100.7"},{"price":"0.802748","size":"0"},{"price":"0.803952","size":"0"},{"price":"0.805157","size":"0"},{"price":"0.806361","size":"0"},{"price":"0.807565","size":"0"},{"price":"0.808769","size":"0"},{"price":"0.809973","size":"0"},{"price":"0.811177","size":"0"},{"price":"0.812381","size":"0"},{"price":"0.813585","size":"0"}],"bid":[{"price":"0.609049","size":"0"},{"price":"0.595517","size":"0"},{"price":"0.581984","size":"0"},{"price":"0.568451","size":"0"},{"price":"0.554919","size":"0"}],"sequence":20584160,"timestamp":"2021-07-15T03:00:30.823Z","symbol":"XRPUSDT"}}
1626318030.86656: {"jsonrpc":"2.0","method":"updateOrderbook","params":{"ask":[{"price":"0.00000065973","size":"15231990"},{"price":"0.00000094570","size":"2769990"}],"bid":[],"sequence":10532348,"timestamp":"2021-07-15T03:00:30.842Z","symbol":"SCBTC"}}
1626318030.9498901: {"jsonrpc":"2.0","method":"updateOrderbook","params":{"ask":[{"price":"0.662655","size":"399101.0"}],"bid":[],"sequence":20584161,"timestamp":"2021-07-15T03:00:30.926Z","symbol":"XRPUSDT"}}
1626318030.966656: {"jsonrpc":"2.0","method":"updateOrderbook","params":{"ask":[{"price":"0.00000065973","size":"15232000"}],"bid":[],"sequence":10532349,"timestamp":"2021-07-15T03:00:30.845Z","symbol":"SCBTC"}}
1626318030.966696: {"jsonrpc":"2.0","method":"updateOrderbook","params":{"ask":[{"price":"0.00054607","size":"199.63"},{"price":"0.00054617","size":"296.51"},{"price":"0.00054649","size":"18.19"},{"price":"0.00054664","size":"0"},{"price":"0.00055750","size":"2539.46"},{"price":"0.00056035","size":"0"}],"bid":[{"price":"0.00054410","size":"0"},{"price":"0.00054396","size":"1.17"}],"sequence":19513151,"timestamp":"2021-07-15T03:00:30.923Z","symbol":"UNIBTC"}}
1626318031.061224: {"jsonrpc":"2.0","method":"updateOrderbook","params":{"ask":[{"price":"0.616746","size":"0"},{"price":"0.617115","size":"0"},{"price":"0.617189","size":"6433.6"},{"price":"0.617506","size":"0"},{"price":"0.617559","size":"4276.9"},{"price":"0.617928","size":"12316.2"},{"price":"0.662655","size":"399101.3"}],"bid":[],"sequence":20584162,"timestamp":"2021-07-15T03:00:31.027Z","symbol":"XRPUSDT"}}
1626318031.0692968: {"jsonrpc":"2.0","method":"updateOrderbook","params":{"ask":[{"price":"0.00000065973","size":"15232010"},{"price":"0.00000094570","size":"2770010"}],"bid":[],"sequence":10532350,"timestamp":"2021-07-15T03:00:30.950Z","symbol":"SCBTC"}}
1626318031.069437: {"jsonrpc":"2.0","method":"updateOrderbook","params":{"ask":[{"price":"0.00054625","size":"0"},{"price":"0.00054638","size":"66.76"},{"price":"0.00054818","size":"84.00"},{"price":"0.00054825","size":"0"},{"price":"0.00058544","size":"0"},{"price":"0.00058953","size":"2343.84"},{"price":"0.00078017","size":"0"},{"price":"0.00078201","size":"3484.36"}],"bid":[{"price":"0.00054525","size":"0"},{"price":"0.00054523","size":"5.18"},{"price":"0.00054505","size":"0"},{"price":"0.00054497","size":"9.62"}],"sequence":19513152,"timestamp":"2021-07-15T03:00:31.019Z","symbol":"UNIBTC"}}
1626318031.1526: {"jsonrpc":"2.0","method":"updateOrderbook","params":{"ask":[{"price":"0.615774","size":"0"},{"price":"0.615800","size":"1331.7"},{"price":"0.662655","size":"399101.6"},{"price":"0.701792","size":"0"}],"bid":[{"price":"0.615318","size":"6394.5"},{"price":"0.615081","size":"0"},{"price":"0.614734","size":"0"},{"price":"0.614645","size":"6216.0"},{"price":"0.614356","size":"0"},{"price":"0.614249","size":"3391.2"},{"price":"0.610018","size":"491.7"},{"price":"0.609918","size":"0"}],"sequence":20584163,"timestamp":"2021-07-15T03:00:31.137Z","symbol":"XRPUSDT"}}
1626318031.164222: {"jsonrpc":"2.0","method":"updateOrderbook","params":{"ask":[{"price":"0.00000065973","size":"15232030"},{"price":"0.00000094570","size":"0"},{"price":"0.00000094571","size":"2770030"}],"bid":[],"sequence":10532351,"timestamp":"2021-07-15T03:00:31.055Z","symbol":"SCBTC"}}
1626318031.170332: {"jsonrpc":"2.0","method":"updateOrderbook","params":{"ask":[{"price":"0.00054549","size":"0"},{"price":"0.00054559","size":"4.33"},{"price":"0.00054575","size":"0"},{"price":"0.00054585","size":"10.47"},{"price":"0.00054637","size":"201.47"},{"price":"0.00054654","size":"0"}],"bid":[{"price":"0.00054524","size":"5.18"},{"price":"0.00054523","size":"0"}],"sequence":19513153,"timestamp":"2021-07-15T03:00:31.125Z","symbol":"UNIBTC"}}
1626318031.250536: {"jsonrpc":"2.0","method":"updateOrderbook","params":{"ask":[{"price":"0.615800","size":"0"},{"price":"0.615848","size":"1331.7"},{"price":"0.615881","size":"0"},{"price":"0.615955","size":"3215.6"},{"price":"0.616411","size":"0"},{"price":"0.616515","size":"0"},{"price":"0.616534","size":"503.2"},{"price":"0.616547","size":"0"},{"price":"0.616641","size":"0"},{"price":"0.616675","size":"5468.7"},{"price":"0.616839","size":"7289.7"},{"price":"0.616887","size":"2193.4"},{"price":"0.616904","size":"5500.0"},{"price":"0.617188","size":"0"},{"price":"0.617300","size":"7700.0"},{"price":"0.618246","size":"0"},{"price":"0.619259","size":"49654.6"},{"price":"0.619643","size":"0"},{"price":"0.620850","size":"63061.3"},{"price":"0.623969","size":"0"},{"price":"0.625253","size":"124095.9"},{"price":"0.632203","size":"0"},{"price":"0.633625","size":"129038.8"},{"price":"0.643805","size":"0"},{"price":"0.645321","size":"347706.3"},{"price":"0.656260","size":"0"},{"price":"0.657498","size":"181214.3"},{"price":"0.662655","size":"399101.9"}],"bid":[{"price":"0.615727","size":"1591.5"},{"price":"0.615639","size":"2955.7"},{"price":"0.615613","size":"0"},{"price":"0.615508","size":"0"},{"price":"0.615319","size":"1337.0"},{"price":"0.615318","size":"0"},{"price":"0.615195","size":"0"},{"price":"0.615182","size":"6394.1"}],"sequence":20584164,"timestamp":"2021-07-15T03:00:31.242Z","symbol":"XRPUSDT"}}
1626318031.265206: {"jsonrpc":"2.0","method":"updateOrderbook","params":{"ask":[{"price":"0.00000065973","size":"15232040"},{"price":"0.00000094571","size":"2770050"}],"bid":[],"sequence":10532352,"timestamp":"2021-07-15T03:00:31.160Z","symbol":"SCBTC"}}
1626318031.265235: {"jsonrpc":"2.0","method":"updateOrderbook","params":{"ask":[{"price":"0.00054551","size":"4.33"},{"price":"0.00054559","size":"0"},{"price":"0.00054580","size":"0"},{"price":"0.00054594","size":"0"},{"price":"0.00054603","size":"16.70"},{"price":"0.00054607","size":"0"},{"price":"0.00054617","size":"0"},{"price":"0.00054631","size":"66.20"},{"price":"0.00054644","size":"199.63"},{"price":"0.00054663","size":"296.51"}],"bid":[{"price":"0.00054525","size":"5.18"},{"price":"0.00054524","size":"0"}],"sequence":19513154,"timestamp":"2021-07-15T03:00:31.243Z","symbol":"UNIBTC"}}
1626318031.3509781: {"jsonrpc":"2.0","method":"updateOrderbook","params":{"ask":[{"price":"0.615848","size":"0"},{"price":"0.615870","size":"1331.7"},{"price":"0.616239","size":"0"},{"price":"0.616418","size":"495.8"},{"price":"0.622891","size":"0"},{"price":"0.625541","size":"272131.6"},{"price":"0.645321","size":"0"},{"price":"0.647695","size":"347706.3"},{"price":"0.662655","size":"399102.1"}],"bid":[{"price":"0.615760","size":"1591.5"},{"price":"0.615727","size":"0"},{"price":"0.614661","size":"7411.2"},{"price":"0.614575","size":"1800.0"},{"price":"0.614423","size":"5500.0"},{"price":"0.614378","size":"0"},{"price":"0.614375","size":"0"},{"price":"0.614316","size":"0"},{"price":"0.614061","size":"7700.0"},{"price":"0.613967","size":"0"}],"sequence":20584165,"timestamp":"2021-07-15T03:00:31.342Z","symbol":"XRPUSDT"}}
1626318031.357313: {"jsonrpc":"2.0","method":"updateOrderbook","params":{"ask":[{"price":"0.00000065973","size":"15232060"},{"price":"0.00000094571","size":"2770070"}],"bid":[],"sequence":10532353,"timestamp":"2021-07-15T03:00:31.274Z","symbol":"SCBTC"}}
1626318031.359696: {"jsonrpc":"2.0","method":"updateOrderbook","params":{"ask":[{"price":"0.00054576","size":"10.47"},{"price":"0.00054585","size":"0"}],"bid":[],"sequence":19513155,"timestamp":"2021-07-15T03:00:31.311Z","symbol":"UNIBTC"}}
1626318031.452545: {"jsonrpc":"2.0","method":"updateOrderbook","params":{"ask":[{"price":"0.615870","size":"0"},{"price":"0.615875","size":"1331.7"},{"price":"0.616382","size":"0"},{"price":"0.616383","size":"160.9"},{"price":"0.616904","size":"0"},{"price":"0.616987","size":"5500.0"},{"price":"0.662655","size":"399102.3"}],"bid":[{"price":"0.615789","size":"1591.5"},{"price":"0.615760","size":"0"},{"price":"0.615685","size":"2955.7"},{"price":"0.615639","size":"0"}],"sequence":20584166,"timestamp":"2021-07-15T03:00:31.442Z","symbol":"XRPUSDT"}}
1626318031.464152: {"jsonrpc":"2.0","method":"updateOrderbook","params":{"ask":[{"price":"0.00000065973","size":"15232080"},{"price":"0.00000094571","size":"2770090"}],"bid":[],"sequence":10532354,"timestamp":"2021-07-15T03:00:31.379Z","symbol":"SCBTC"}}
1626318031.555427: {"jsonrpc":"2.0","method":"updateOrderbook","params":{"ask":[{"price":"0.615874","size":"1331.7"},{"price":"0.615875","size":"0"},{"price":"0.615955","size":"0"},{"price":"0.615982","size":"3215.6"},{"price":"0.616534","size":"0"},{"price":"0.616773","size":"503.2"},{"price":"0.662655","size":"399102.5"}],"bid":[{"price":"0.606754","size":"165690.2"},{"price":"0.605370","size":"0"},{"price":"0.584700","size":"10.2"},{"price":"0.581616","size":"195374.1"}],"sequence":20584167,"timestamp":"2021-07-15T03:00:31.542Z","symbol":"XRPUSDT"}}
1626318031.573071: {"jsonrpc":"2.0","method":"updateOrderbook","params":{"ask":[{"price":"0.00000065973","size":"15232100"},{"price":"0.00000094571","size":"2770120"}],"bid":[],"sequence":10532355,"timestamp":"2021-07-15T03:00:31.527Z","symbol":"SCBTC"}}
1626318031.573146: {"jsonrpc":"2.0","method":"updateOrderbook","params":{"ask":[{"price":"0.00054551","size":"0"},{"price":"0.00054557","size":"4.33"},{"price":"0.00054579","size":"16.70"},{"price":"0.00054593","size":"66.20"},{"price":"0.00054603","size":"0"},{"price":"0.00054631","size":"0"}],"bid":[{"price":"0.00054526","size":"5.18"},{"price":"0.00054525","size":"0"}],"sequence":19513156,"timestamp":"2021-07-15T03:00:31.532Z","symbol":"UNIBTC"}}
1626318031.6476932: {"jsonrpc":"2.0","method":"updateOrderbook","params":{"ask":[{"price":"10000.000","size":"0.0012"}],"bid":[{"price":"0.010","size":"1000.0012"}],"sequence":2190716,"timestamp":"2021-07-15T03:00:31.593Z","symbol":"SPIUSD"}}
1626318031.655116: {"jsonrpc":"2.0","method":"updateOrderbook","params":{"ask":[{"price":"0.615874","size":"0"},{"price":"0.615875","size":"1331.7"},{"price":"0.616722","size":"0"},{"price":"0.616888","size":"5500.0"},{"price":"0.616987","size":"0"},{"price":"0.617126","size":"9601.1"},{"price":"0.617205","size":"7700.0"},{"price":"0.617300","size":"0"},{"price":"0.618549","size":"0"},{"price":"0.619460","size":"68872.3"},{"price":"0.633625","size":"0"},{"price":"0.635140","size":"129038.8"},{"price":"0.657498","size":"0"},{"price":"0.658817","size":"181214.3"},{"price":"0.662655","size":"399102.8"}],"bid":[{"price":"0.615789","size":"0"},{"price":"0.615772","size":"1591.5"},{"price":"0.615063","size":"538.8"},{"price":"0.614927","size":"0"},{"price":"0.614423","size":"0"},{"price":"0.614340","size":"5500.0"}],"sequence":20584168,"timestamp":"2021-07-15T03:00:31.627Z","symbol":"XRPUSDT"}}
1626318031.6740422: {"jsonrpc":"2.0","method":"updateOrderbook","params":{"ask":[{"price":"0.00000065973","size":"15232110"},{"price":"0.00000094571","size":"2770140"}],"bid":[],"sequence":10532356,"timestamp":"2021-07-15T03:00:31.633Z","symbol":"SCBTC"}}
1626318031.677037: {"jsonrpc":"2.0","method":"updateOrderbook","params":{"ask":[{"price":"0.00054593","size":"0"},{"price":"0.00054612","size":"66.20"},{"price":"0.00055066","size":"0"},{"price":"0.00055110","size":"843.90"},{"price":"0.00055750","size":"0"},{"price":"0.00055851","size":"2539.46"}],"bid":[{"price":"0.00054526","size":"0"},{"price":"0.00054525","size":"5.18"},{"price":"0.00054507","size":"9.62"},{"price":"0.00054497","size":"0"},{"price":"0.00054455","size":"199.39"},{"price":"0.00054438","size":"0"}],"sequence":19513157,"timestamp":"2021-07-15T03:00:31.640Z","symbol":"UNIBTC"}}
1626318031.753001: {"jsonrpc":"2.0","method":"updateOrderbook","params":{"ask":[{"price":"0.615844","size":"1331.7"},{"price":"0.615875","size":"0"},{"price":"0.616383","size":"0"},{"price":"0.616417","size":"160.9"},{"price":"0.662655","size":"399103.0"},{"price":"0.671037","size":"0"},{"price":"0.679721","size":"229002.7"},{"price":"0.847046","size":"0"},{"price":"0.857446","size":"324970.5"}],"bid":[{"price":"0.615772","size":"0"},{"price":"0.615742","size":"1591.5"},{"price":"0.615685","size":"0"},{"price":"0.615654","size":"2955.7"},{"price":"0.614575","size":"0"},{"price":"0.614504","size":"1800.0"},{"price":"0.606754","size":"0"},{"price":"0.605348","size":"165690.2"}],"sequence":20584169,"timestamp":"2021-07-15T03:00:31.741Z","symbol":"XRPUSDT"}}
1626318031.758421: {"jsonrpc":"2.0","method":"updateOrderbook","params":{"ask":[{"price":"0.00000065973","size":"15232130"},{"price":"0.00000094571","size":"2770160"}],"bid":[],"sequence":10532357,"timestamp":"2021-07-15T03:00:31.738Z","symbol":"SCBTC"}}
1626318031.765553: {"jsonrpc":"2.0","method":"updateOrderbook","params":{"ask":[{"price":"0.00054550","size":"4.33"},{"price":"0.00054557","size":"0"},{"price":"0.00054797","size":"1302.32"},{"price":"0.00054949","size":"0"},{"price":"0.00055196","size":"0"},{"price":"0.00055287","size":"662.81"}],"bid":[{"price":"0.00054507","size":"0"},{"price":"0.00054499","size":"9.62"}],"sequence":19513158,"timestamp":"2021-07-15T03:00:31.720Z","symbol":"UNIBTC"}}
1626318031.856522: {"jsonrpc":"2.0","method":"updateOrderbook","params":{"ask":[{"price":"0.615831","size":"1331.7"},{"price":"0.615844","size":"0"},{"price":"0.615942","size":"10631.4"},{"price":"0.615943","size":"3215.6"},{"price":"0.615982","size":"0"},{"price":"0.616137","size":"0"},{"price":"0.662655","size":"399103.2"}],"bid":[{"price":"0.615746","size":"1591.5"},{"price":"0.615742","size":"0"}],"sequence":20584170,"timestamp":"2021-07-15T03:00:31.790Z","symbol":"XRPUSDT"}}
1626318031.8594098: {"jsonrpc":"2.0","method":"updateOrderbook","params":{"ask":[{"price":"0.00000065973","size":"15232140"},{"price":"0.00000094571","size":"2770170"}],"bid":[],"sequence":10532358,"timestamp":"2021-07-15T03:00:31.824Z","symbol":"SCBTC"}}
1626318031.859468: {"jsonrpc":"2.0","method":"updateOrderbook","params":{"ask":[{"price":"0.00054550","size":"0"},{"price":"0.00054554","size":"4.33"},{"price":"0.00054607","size":"199.63"},{"price":"0.00054617","size":"296.51"},{"price":"0.00054644","size":"0"},{"price":"0.00054663","size":"0"},{"price":"0.00054797","size":"0"},{"price":"0.00054853","size":"1302.32"}],"bid":[{"price":"0.00054528","size":"5.18"},{"price":"0.00054525","size":"0"}],"sequence":19513159,"timestamp":"2021-07-15T03:00:31.818Z","symbol":"UNIBTC"}}
1626318031.954657: {"jsonrpc":"2.0","method":"updateOrderbook","params":{"ask":[{"price":"0.615828","size":"1331.7"},{"price":"0.615831","size":"0"},{"price":"0.615942","size":"0"},{"price":"0.616137","size":"10631.5"},{"price":"0.662655","size":"399103.5"},{"price":"0.679721","size":"0"},{"price":"0.684350","size":"229002.7"},{"price":"0.857446","size":"0"},{"price":"0.862547","size":"324970.5"}],"bid":[{"price":"0.614504","size":"0"},{"price":"0.614436","size":"1800.0"},{"price":"0.581616","size":"0"},{"price":"0.579277","size":"195374.1"}],"sequence":20584171,"timestamp":"2021-07-15T03:00:31.922Z","symbol":"XRPUSDT"}}
1626318031.965236: {"jsonrpc":"2.0","method":"updateOrderbook","params":{"ask":[{"price":"0.00000065973","size":"15232160"},{"price":"0.00000094571","size":"2770190"}],"bid":[{"price":"0.00000034658","size":"4600"},{"price":"0.00000034622","size":"230000"}],"sequence":10532359,"timestamp":"2021-07-15T03:00:31.929Z","symbol":"SCBTC"}}
1626318031.96702: {"jsonrpc":"2.0","method":"updateOrderbook","params":{"ask":[{"price":"0.00054554","size":"0"},{"price":"0.00054557","size":"4.33"},{"price":"0.00054576","size":"0"},{"price":"0.00054584","size":"10.47"},{"price":"0.00054607","size":"0"},{"price":"0.00054617","size":"0"},{"price":"0.00054642","size":"199.63"},{"price":"0.00054661","size":"296.51"},{"price":"0.00054777","size":"0"},{"price":"0.00054818","size":"170.00"},{"price":"0.00054853","size":"0"},{"price":"0.00054917","size":"1302.32"}],"bid":[{"price":"0.00054531","size":"5.18"},{"price":"0.00054528","size":"0"},{"price":"0.00053478","size":"2974.71"},{"price":"0.00053298","size":"0"}],"sequence":19513160,"timestamp":"2021-07-15T03:00:31.924Z","symbol":"UNIBTC"}}
1626318032.0526211: {"jsonrpc":"2.0","method":"updateOrderbook","params":{"ask":[{"price":"0.615942","size":"10631.5"},{"price":"0.616137","size":"0"},{"price":"0.662655","size":"399103.8"}],"bid":[{"price":"0.615748","size":"1591.5"},{"price":"0.615746","size":"0"},{"price":"0.579277","size":"0"},{"price":"0.576918","size":"195374.1"}],"sequence":20584172,"timestamp":"2021-07-15T03:00:32.031Z","symbol":"XRPUSDT"}}
1626318032.0703151: {"jsonrpc":"2.0","method":"updateOrderbook","params":{"ask":[{"price":"0.00000065973","size":"15232170"},{"price":"0.00000094571","size":"2770210"}],"bid":[{"price":"0.00000034658","size":"234600"},{"price":"0.00000034622","size":"0"}],"sequence":10532360,"timestamp":"2021-07-15T03:00:32.023Z","symbol":"SCBTC"}}
1626318032.070496: {"jsonrpc":"2.0","method":"updateOrderbook","params":{"ask":[{"price":"0.00054555","size":"4.33"},{"price":"0.00054557","size":"0"},{"price":"0.00054579","size":"0"},{"price":"0.00054612","size":"0"},{"price":"0.00054618","size":"16.70"},{"price":"0.00054624","size":"66.76"},{"price":"0.00054631","size":"66.20"},{"price":"0.00054637","size":"0"},{"price":"0.00054638","size":"0"},{"price":"0.00054657","size":"201.47"}],"bid":[{"price":"0.00054531","size":"0"},{"price":"0.00054530","size":"5.18"},{"price":"0.00053050","size":"0.79"}],"sequence":19513161,"timestamp":"2021-07-15T03:00:32.036Z","symbol":"UNIBTC"}}
1626318032.153718: {"jsonrpc":"2.0","method":"updateOrderbook","params":{"ask":[{"price":"0.662655","size":"399103.9"}],"bid":[],"sequence":20584173,"timestamp":"2021-07-15T03:00:32.087Z","symbol":"XRPUSDT"}}
1626318032.166486: {"jsonrpc":"2.0","method":"updateOrderbook","params":{"ask":[{"price":"0.00000065973","size":"15232190"},{"price":"0.00000094571","size":"2770230"}],"bid":[],"sequence":10532361,"timestamp":"2021-07-15T03:00:32.128Z","symbol":"SCBTC"}}
1626318032.1709309: {"jsonrpc":"2.0","method":"updateOrderbook","params":{"ask":[{"price":"0.00054551","size":"4.33"},{"price":"0.00054555","size":"0"}],"bid":[{"price":"0.00054530","size":"0"},{"price":"0.00054528","size":"5.18"},{"price":"0.00053050","size":"0"}],"sequence":19513162,"timestamp":"2021-07-15T03:00:32.123Z","symbol":"UNIBTC"}}
1626318032.24992: {"jsonrpc":"2.0","method":"updateOrderbook","params":{"ask":[{"price":"0.615825","size":"1331.7"},{"price":"0.615828","size":"0"},{"price":"0.662655","size":"399104.3"}],"bid":[{"price":"0.615748","size":"0"},{"price":"0.615738","size":"1591.5"}],"sequence":20584174,"timestamp":"2021-07-15T03:00:32.241Z","symbol":"XRPUSDT"}}
1626318032.2678971: {"jsonrpc":"2.0","method":"updateOrderbook","params":{"ask":[{"price":"0.00000065973","size":"15232200"},{"price":"0.00000094571","size":"2770240"}],"bid":[],"sequence":10532362,"timestamp":"2021-07-15T03:00:32.196Z","symbol":"SCBTC"}}
1626318032.267921: {"jsonrpc":"2.0","method":"updateOrderbook","params":{"ask":[{"price":"0.00054777","size":"86.00"},{"price":"0.00054818","size":"84.00"}],"bid":[{"price":"0.00054528","size":"0"},{"price":"0.00054527","size":"5.18"},{"price":"0.00052694","size":"445.48"}],"sequence":19513163,"timestamp":"2021-07-15T03:00:32.221Z","symbol":"UNIBTC"}}
1626318032.354178: {"jsonrpc":"2.0","method":"updateOrderbook","params":{"ask":[{"price":"0.662655","size":"399104.5"}],"bid":[{"price":"0.576918","size":"0"},{"price":"0.574270","size":"195374.1"}],"sequence":20584175,"timestamp":"2021-07-15T03:00:32.326Z","symbol":"XRPUSDT"}}
1626318032.3668869: {"jsonrpc":"2.0","method":"updateOrderbook","params":{"ask":[{"price":"0.00000065973","size":"15232210"},{"price":"0.00000094571","size":"2770260"}],"bid":[],"sequence":10532363,"timestamp":"2021-07-15T03:00:32.308Z","symbol":"SCBTC"}}
1626318032.3670259: {"jsonrpc":"2.0","method":"updateOrderbook","params":{"ask":[{"price":"0.00054547","size":"4.33"},{"price":"0.00054551","size":"0"},{"price":"0.00054572","size":"10.47"},{"price":"0.00054584","size":"0"},{"price":"0.00054587","size":"16.70"},{"price":"0.00054601","size":"66.20"},{"price":"0.00054618","size":"0"},{"price":"0.00054631","size":"0"}],"bid":[],"sequence":19513164,"timestamp":"2021-07-15T03:00:32.328Z","symbol":"UNIBTC"}}
1626318032.4562938: {"jsonrpc":"2.0","method":"updateOrderbook","params":{"ask":[{"price":"0.615818","size":"1331.7"},{"price":"0.615825","size":"0"},{"price":"0.662655","size":"399104.7"}],"bid":[],"sequence":20584176,"timestamp":"2021-07-15T03:00:32.399Z","symbol":"XRPUSDT"}}
1626318032.464208: {"jsonrpc":"2.0","method":"updateOrderbook","params":{"ask":[{"price":"0.00000065973","size":"15232230"},{"price":"0.00000094571","size":"2770280"},{"price":"0.00000095824","size":"2754880"},{"price":"0.00000095882","size":"0"}],"bid":[],"sequence":10532364,"timestamp":"2021-07-15T03:00:32.404Z","symbol":"SCBTC"}}
1626318032.464257: {"jsonrpc":"2.0","method":"updateOrderbook","params":{"ask":[{"price":"0.00054547","size":"0"},{"price":"0.00054552","size":"4.33"}],"bid":[{"price":"0.00054528","size":"5.18"},{"price":"0.00054527","size":"0"}],"sequence":19513165,"timestamp":"2021-07-15T03:00:32.424Z","symbol":"UNIBTC"}}
1626318032.553904: {"jsonrpc":"2.0","method":"updateOrderbook","params":{"ask":[{"price":"0.662655","size":"399105.0"}],"bid":[],"sequence":20584177,"timestamp":"2021-07-15T03:00:32.502Z","symbol":"XRPUSDT"}}
1626318032.5569339: {"jsonrpc":"2.0","method":"updateOrderbook","params":{"ask":[{"price":"0.00000037314","size":"661850"},{"price":"0.00000037357","size":"0"},{"price":"0.00000044040","size":"1381850"},{"price":"0.00000044325","size":"0"},{"price":"0.00000065973","size":"15232250"},{"price":"0.00000094571","size":"2770300"}],"bid":[],"sequence":10532365,"timestamp":"2021-07-15T03:00:32.521Z","symbol":"SCBTC"}}
1626318032.557157: {"jsonrpc":"2.0","method":"updateOrderbook","params":{"ask":[{"price":"0.00054550","size":"4.33"},{"price":"0.00054552","size":"0"},{"price":"0.00054587","size":"0"},{"price":"0.00054601","size":"0"},{"price":"0.00054603","size":"16.70"},{"price":"0.00054614","size":"66.20"},{"price":"0.00054915","size":"433.80"},{"price":"0.00054992","size":"0"}],"bid":[{"price":"0.00052694","size":"0"}],"sequence":19513166,"timestamp":"2021-07-15T03:00:32.522Z","symbol":"UNIBTC"}}
1626318032.6499681: {"jsonrpc":"2.0","method":"updateOrderbook","params":{"ask":[{"price":"0.615800","size":"11000.0"},{"price":"0.615810","size":"1331.7"},{"price":"0.615818","size":"0"},{"price":"0.616417","size":"0"},{"price":"0.616479","size":"160.9"},{"price":"0.662655","size":"399105.3"}],"bid":[{"price":"0.615738","size":"0"},{"price":"0.615726","size":"1591.5"},{"price":"0.615654","size":"0"},{"price":"0.615619","size":"2955.7"},{"price":"0.615319","size":"0"},{"price":"0.615195","size":"1337.0"}],"sequence":20584178,"timestamp":"2021-07-15T03:00:32.627Z","symbol":"XRPUSDT"}}
1626318032.658342: {"jsonrpc":"2.0","method":"updateOrderbook","params":{"ask":[{"price":"0.00000065973","size":"15232260"},{"price":"0.00000094571","size":"2770320"}],"bid":[],"sequence":10532366,"timestamp":"2021-07-15T03:00:32.629Z","symbol":"SCBTC"}}
1626318032.675547: {"jsonrpc":"2.0","method":"updateOrderbook","params":{"ask":[{"price":"0.00054613","size":"199.63"},{"price":"0.00054623","size":"296.51"},{"price":"0.00054642","size":"0"},{"price":"0.00054661","size":"0"}],"bid":[{"price":"0.00054529","size":"5.18"},{"price":"0.00054528","size":"0"},{"price":"0.00053050","size":"442.49"}],"sequence":19513167,"timestamp":"2021-07-15T03:00:32.586Z","symbol":"UNIBTC"}}
1626318032.750719: {"jsonrpc":"2.0","method":"updateOrderbook","params":{"ask":[{"price":"0.615800","size":"0"},{"price":"0.615806","size":"1331.7"},{"price":"0.615810","size":"0"},{"price":"0.616417","size":"160.9"},{"price":"0.616479","size":"0"},{"price":"0.616552","size":"503.2"},{"price":"0.616773","size":"0"},{"price":"0.616951","size":"12967.5"},{"price":"0.617377","size":"0"},{"price":"0.618514","size":"68872.3"},{"price":"0.619460","size":"0"},{"price":"0.662655","size":"399105.6"},{"price":"0.702158","size":"228479.7"}],"bid":[{"price":"0.615726","size":"0"},{"price":"0.615660","size":"1591.5"},{"price":"0.615619","size":"0"},{"price":"0.615571","size":"2955.7"},{"price":"0.615339","size":"1337.0"},{"price":"0.615195","size":"0"}],"sequence":20584179,"timestamp":"2021-07-15T03:00:32.734Z","symbol":"XRPUSDT"}}
1626318032.771929: {"jsonrpc":"2.0","method":"updateOrderbook","params":{"ask":[{"price":"0.00000065973","size":"15232280"},{"price":"0.00000094571","size":"2770340"}],"bid":[],"sequence":10532367,"timestamp":"2021-07-15T03:00:32.734Z","symbol":"SCBTC"}}
1626318032.771986: {"jsonrpc":"2.0","method":"updateOrderbook","params":{"ask":[{"price":"0.00054651","size":"218.82"},{"price":"0.00054681","size":"0"}],"bid":[{"price":"0.00054529","size":"0"},{"price":"0.00054525","size":"5.18"}],"sequence":19513168,"timestamp":"2021-07-15T03:00:32.718Z","symbol":"UNIBTC"}}
1626318032.857427: {"jsonrpc":"2.0","method":"updateOrderbook","params":{"ask":[{"price":"0.615776","size":"12331.7"},{"price":"0.615806","size":"0"},{"price":"0.616265","size":"495.8"},{"price":"0.616418","size":"0"},{"price":"0.616480","size":"0"},{"price":"0.662655","size":"399105.9"}],"bid":[{"price":"0.615698","size":"0"},{"price":"0.615660","size":"0"},{"price":"0.615652","size":"1591.5"},{"price":"0.615339","size":"0"},{"price":"0.615195","size":"1337.0"},{"price":"0.614340","size":"0"},{"price":"0.614277","size":"5500.0"}],"sequence":20584180,"timestamp":"2021-07-15T03:00:32.840Z","symbol":"XRPUSDT"}}
1626318032.8811982: {"jsonrpc":"2.0","method":"updateOrderbook","params":{"ask":[{"price":"0.00000065973","size":"15232290"},{"price":"0.00000094571","size":"2770360"}],"bid":[],"sequence":10532368,"timestamp":"2021-07-15T03:00:32.839Z","symbol":"SCBTC"}}
1626318032.881243: {"jsonrpc":"2.0","method":"updateOrderbook","params":{"ask":[{"price":"0.00054548","size":"4.33"},{"price":"0.00054550","size":"0"},{"price":"0.00054586","size":"16.70"},{"price":"0.00054599","size":"66.20"},{"price":"0.00054603","size":"0"},{"price":"0.00054614","size":"0"}],"bid":[{"price":"0.00054486","size":"18.61"},{"price":"0.00054477","size":"0"}],"sequence":19513169,"timestamp":"2021-07-15T03:00:32.785Z","symbol":"UNIBTC"}}
1626318032.951154: {"jsonrpc":"2.0","method":"updateOrderbook","params":{"ask":[{"price":"0.615776","size":"11000.0"},{"price":"0.615824","size":"1331.7"},{"price":"0.616282","size":"10633.0"},{"price":"0.616816","size":"5500.0"},{"price":"0.616888","size":"0"},{"price":"0.617102","size":"7700.0"},{"price":"0.617205","size":"0"},{"price":"0.662655","size":"399106.2"},{"price":"0.702158","size":"0"}],"bid":[{"price":"0.615698","size":"1591.5"},{"price":"0.615652","size":"0"},{"price":"0.615571","size":"0"},{"price":"0.615535","size":"2955.7"},{"price":"0.615063","size":"0"},{"price":"0.614883","size":"538.8"}],"sequence":20584181,"timestamp":"2021-07-15T03:00:32.937Z","symbol":"XRPUSDT"}}
