1618677512.982621: {"jsonrpc":"2.0","method":"snapshotOrderbook","params":{"ask":[{"price":"0.00015787","size":"42.78"},{"price":"0.00015788","size":"290.61"},{"price":"0.00015792","size":"72.33"},{"price":"0.00015793","size":"370.08"},{"price":"0.00015801","size":"245.28"},{"price":"0.00015802","size":"500.06"},{"price":"0.00015807","size":"429.72"},{"price":"0.00015809","size":"692.41"},{"price":"0.00015810","size":"200.00"},{"price":"0.00015811","size":"80.55"},{"price":"0.00015812","size":"550.49"},{"price":"0.00015815","size":"929.39"},{"price":"0.00015816","size":"103.39"},{"price":"0.00015818","size":"1272.79"},{"price":"0.00015820","size":"349.45"},{"price":"0.00015824","size":"528.19"},{"price":"0.00015825","size":"162.38"},{"price":"0.00015826","size":"660.54"},{"price":"0.00015830","size":"298.44"},{"price":"0.00015831","size":"1774.39"},{"price":"0.00015832","size":"112.21"},{"price":"0.00015835","size":"280.67"},{"price":"0.00015836","size":"112.89"},{"price":"0.00015839","size":"424.96"},{"price":"0.00015840","size":"371.28"},{"price":"0.00015841","size":"149.59"},{"price":"0.00015854","size":"551.24"},{"price":"0.00015856","size":"156.33"},{"price":"0.00015860","size":"164.72"},{"price":"0.00015865","size":"245.17"},{"price":"0.00015870","size":"227.54"},{"price":"0.00015875","size":"2128.07"},{"price":"0.00015876","size":"633.98"},{"price":"0.00015889","size":"241.71"},{"price":"0.00015894","size":"410.92"},{"price":"0.00015899","size":"373.07"},{"price":"0.00015901","size":"3008.25"},{"price":"0.00015903","size":"734.91"},{"price":"0.00015904","size":"463.05"},{"price":"0.00015909","size":"549.86"},{"price":"0.00015912","size":"830.99"},{"price":"0.00015914","size":"466.51"},{"price":"0.00015926","size":"787.61"},{"price":"0.00015933","size":"981.99"},{"price":"0.00015938","size":"890.55"},{"price":"0.00015943","size":"2.45"},{"price":"0.00015944","size":"517.66"},{"price":"0.00015949","size":"1230.48"},{"price":"0.00015954","size":"751.92"},{"price":"0.00015958","size":"940.51"},{"price":"0.00015963","size":"1213.98"},{"price":"0.00015968","size":"2625.22"},{"price":"0.00015969","size":"4402.08"},{"price":"0.00015973","size":"1828.03"},{"price":"0.00015988","size":"1100.41"},{"price":"0.00015993","size":"1597.46"},{"price":"0.00015997","size":"1734.47"},{"price":"0.00016003","size":"2157.55"},{"price":"0.00016032","size":"503.30"},{"price":"0.00016035","size":"2221.20"},{"price":"0.00016045","size":"3079.22"},{"price":"0.00016064","size":"2804.74"},{"price":"0.00016071","size":"0.04"},{"price":"0.00016164","size":"5617.94"},{"price":"0.00016173","size":"0.03"},{"price":"0.00016288","size":"0.04"},{"price":"0.00016420","size":"0.04"},{"price":"0.00016546","size":"825.34"},{"price":"0.00016553","size":"0.04"},{"price":"0.00016646","size":"1269.92"},{"price":"0.00016688","size":"0.04"},{"price":"0.00016721","size":"4405.71"},{"price":"0.00016750","size":"4264.80"},{"price":"0.00016770","size":"4211.26"},{"price":"0.00016785","size":"3937.00"},{"price":"0.00016798","size":"4090.47"},{"price":"0.00016800","size":"2.00"},{"price":"0.00016810","size":"4147.51"},{"price":"0.00016811","size":"43523.35"},{"price":"0.00016821","size":"4260.42"},{"price":"0.00016824","size":"0.04"},{"price":"0.00016832","size":"3918.74"},{"price":"0.00016843","size":"4534.56"},{"price":"0.00016868","size":"4229.04"},{"price":"0.00016880","size":"10.00"},{"price":"0.00016895","size":"4174.56"},{"price":"0.00016907","size":"5948.76"},{"price":"0.00016961","size":"0.04"},{"price":"0.00016989","size":"425.88"},{"price":"0.00017055","size":"1.74"},{"price":"0.00017099","size":"0.04"},{"price":"0.00017108","size":"415.04"},{"price":"0.00017200","size":"2.00"},{"price":"0.00017201","size":"2376.13"},{"price":"0.00017238","size":"0.02"},{"price":"0.00017295","size":"11689.40"},{"price":"0.00017396","size":"0.02"},{"price":"0.00017397","size":"658.86"},{"price":"0.00017500","size":"104.03"},{"price":"0.00017509","size":"0.58"},{"price":"0.00017538","size":"2646.87"},{"price":"0.00017555","size":"0.02"},{"price":"0.00017567","size":"1363.60"},{"price":"0.00017600","size":"2.03"},{"price":"0.00017670","size":"1152.32"},{"price":"0.00017715","size":"0.02"},{"price":"0.00017756","size":"7176.99"},{"price":"0.00017792","size":"2362.68"},{"price":"0.00017800","size":"2.00"},{"price":"0.00017859","size":"383.97"},{"price":"0.00017877","size":"0.02"},{"price":"0.00017880","size":"10.00"},{"price":"0.00017900","size":"2.02"},{"price":"0.00017962","size":"5740.59"},{"price":"0.00018000","size":"8.03"},{"price":"0.00018074","size":"9038.64"},{"price":"0.00018152","size":"4497.32"},{"price":"0.00018200","size":"2.00"},{"price":"0.00018242","size":"603.85"},{"price":"0.00018317","size":"8.98"},{"price":"0.00018349","size":"10438.11"},{"price":"0.00018404","size":"0.02"},{"price":"0.00018448","size":"10737.29"},{"price":"0.00018500","size":"2.00"},{"price":"0.00018541","size":"3363.41"},{"price":"0.00018572","size":"0.02"},{"price":"0.00018643","size":"8673.72"},{"price":"0.00018666","size":"0.96"},{"price":"0.00018728","size":"9263.49"},{"price":"0.00018742","size":"0.02"},{"price":"0.00018800","size":"2.00"},{"price":"0.00018817","size":"1382.22"},{"price":"0.00018880","size":"20.00"},{"price":"0.00018911","size":"278.58"},{"price":"0.00018913","size":"0.02"},{"price":"0.00019000","size":"1.00"},{"price":"0.00019015","size":"700.79"},{"price":"0.00019086","size":"0.02"},{"price":"0.00019104","size":"166.43"},{"price":"0.00019200","size":"2.00"},{"price":"0.00019220","size":"2987.04"},{"price":"0.00019260","size":"0.01"},{"price":"0.00019299","size":"2232.96"},{"price":"0.00019396","size":"1292.81"},{"price":"0.00019400","size":"2.00"},{"price":"0.00019436","size":"0.03"},{"price":"0.00019440","size":"10.00"},{"price":"0.00019486","size":"2035.67"},{"price":"0.00019489","size":"0.03"},{"price":"0.00019500","size":"2.00"},{"price":"0.00019550","size":"0.07"},{"price":"0.00019576","size":"6719.32"},{"price":"0.00019600","size":"0.01"},{"price":"0.00019650","size":"0.10"},{"price":"0.00019669","size":"3137.61"},{"price":"0.00019750","size":"2.07"},{"price":"0.00019778","size":"289.40"},{"price":"0.00019813","size":"0.04"},{"price":"0.00019850","size":"0.07"},{"price":"0.00019862","size":"0.03"},{"price":"0.00019876","size":"1752.62"},{"price":"0.00019880","size":"10.00"},{"price":"0.00019940","size":"13.16"},{"price":"0.00019950","size":"0.07"},{"price":"0.00019963","size":"10822.75"},{"price":"0.00019987","size":"0.61"},{"price":"0.00020000","size":"16.10"},{"price":"0.00020050","size":"0.07"},{"price":"0.00020064","size":"8346.39"},{"price":"0.00020150","size":"0.07"},{"price":"0.00020173","size":"1445.44"},{"price":"0.00020200","size":"0.03"},{"price":"0.00020234","size":"0.03"},{"price":"0.00020250","size":"0.07"},{"price":"0.00020258","size":"2758.64"},{"price":"0.00020350","size":"0.07"},{"price":"0.00020352","size":"284.53"},{"price":"0.00020444","size":"2.00"},{"price":"0.00020450","size":"0.07"},{"price":"0.00020452","size":"349.87"},{"price":"0.00020455","size":"1.00"},{"price":"0.00020543","size":"318.56"},{"price":"0.00020550","size":"0.07"},{"price":"0.00020600","size":"0.01"},{"price":"0.00020607","size":"0.03"},{"price":"0.00020637","size":"4211.12"},{"price":"0.00020641","size":"1.00"},{"price":"0.00020650","size":"0.11"},{"price":"0.00020684","size":"0.86"},{"price":"0.00020723","size":"11455.41"},{"price":"0.00020750","size":"0.07"},{"price":"0.00020827","size":"148.97"},{"price":"0.00020850","size":"0.07"},{"price":"0.00020934","size":"468.05"},{"price":"0.00020950","size":"0.07"},{"price":"0.00020979","size":"0.03"},{"price":"0.00021000","size":"0.01"},{"price":"0.00021019","size":"3286.98"},{"price":"0.00021050","size":"0.08"},{"price":"0.00021114","size":"6065.63"},{"price":"0.00021127","size":"0.17"},{"price":"0.00021150","size":"0.08"},{"price":"0.00021200","size":"0.04"},{"price":"0.00021218","size":"5323.48"},{"price":"0.00021250","size":"0.08"},{"price":"0.00021321","size":"6447.14"},{"price":"0.00021350","size":"0.08"},{"price":"0.00021351","size":"0.03"},{"price":"0.00021394","size":"5945.88"},{"price":"0.00021436","size":"1.00"},{"price":"0.00021450","size":"0.08"},{"price":"0.00021496","size":"866.87"},{"price":"0.00021550","size":"0.08"},{"price":"0.00021593","size":"2211.55"},{"price":"0.00021600","size":"0.01"},{"price":"0.00021650","size":"0.12"},{"price":"0.00021683","size":"158.80"},{"price":"0.00021724","size":"0.03"},{"price":"0.00021750","size":"0.08"},{"price":"0.00021784","size":"178.89"},{"price":"0.00021850","size":"0.08"},{"price":"0.00021880","size":"10.00"},{"price":"0.00021883","size":"2535.68"},{"price":"0.00021920","size":"22.00"},{"price":"0.00021950","size":"0.08"},{"price":"0.00021985","size":"642.90"},{"price":"0.00022035","size":"272.07"},{"price":"0.00022050","size":"0.08"},{"price":"0.00022066","size":"2662.60"},{"price":"0.00022096","size":"0.03"},{"price":"0.00022150","size":"0.08"},{"price":"0.00022186","size":"1294.85"},{"price":"0.00022200","size":"20.05"},{"price":"0.00022240","size":"10.00"},{"price":"0.00022250","size":"0.08"},{"price":"0.00022255","size":"5003.55"},{"price":"0.00022256","size":"272.07"},{"price":"0.00022350","size":"0.08"},{"price":"0.00022376","size":"1521.14"},{"price":"0.00022440","size":"20.00"},{"price":"0.00022450","size":"0.08"},{"price":"0.00022453","size":"951.78"},{"price":"0.00022469","size":"0.03"},{"price":"0.00022476","size":"272.07"},{"price":"0.00022500","size":"1.00"},{"price":"0.00022550","size":"0.08"},{"price":"0.00022554","size":"112.45"},{"price":"0.00022600","size":"0.01"},{"price":"0.00022650","size":"0.13"},{"price":"0.00022666","size":"189.85"},{"price":"0.00022696","size":"272.07"},{"price":"0.00022750","size":"0.08"},{"price":"0.00022759","size":"6493.49"},{"price":"0.00022800","size":"25.00"},{"price":"0.00022841","size":"0.04"},{"price":"0.00022848","size":"2999.20"},{"price":"0.00022850","size":"0.08"},{"price":"0.00022878","size":"0.53"},{"price":"0.00022917","size":"272.07"},{"price":"0.00022938","size":"2525.40"},{"price":"0.00022950","size":"0.08"},{"price":"0.00023038","size":"2415.08"},{"price":"0.00023050","size":"0.08"},{"price":"0.00023137","size":"272.07"},{"price":"0.00023144","size":"795.79"},{"price":"0.00023150","size":"0.08"},{"price":"0.00023156","size":"1.48"},{"price":"0.00023200","size":"0.05"},{"price":"0.00023213","size":"0.03"},{"price":"0.00023231","size":"113.71"},{"price":"0.00023250","size":"0.08"},{"price":"0.00023322","size":"109.94"},{"price":"0.00023350","size":"0.08"},{"price":"0.00023357","size":"272.07"},{"price":"0.00023430","size":"421.66"},{"price":"0.00023440","size":"20.00"},{"price":"0.00023450","size":"0.08"},{"price":"0.00023526","size":"1198.86"},{"price":"0.00023550","size":"0.08"},{"price":"0.00023578","size":"272.07"},{"price":"0.00023586","size":"0.03"},{"price":"0.00023600","size":"0.01"},{"price":"0.00023621","size":"3039.42"},{"price":"0.00023650","size":"0.08"},{"price":"0.00023691","size":"564.38"},{"price":"0.00023750","size":"0.08"},{"price":"0.00023777","size":"31.05"},{"price":"0.00023798","size":"272.07"},{"price":"0.00023811","size":"1335.12"},{"price":"0.00023850","size":"0.08"},{"price":"0.00023894","size":"5982.80"},{"price":"0.00023899","size":"25.00"},{"price":"0.00023950","size":"0.08"},{"price":"0.00023958","size":"0.03"},{"price":"0.00023987","size":"5.00"},{"price":"0.00024000","size":"0.20"},{"price":"0.00024004","size":"5406.04"},{"price":"0.00024018","size":"272.07"},{"price":"0.00024050","size":"0.09"},{"price":"0.00024077","size":"2158.23"},{"price":"0.00024150","size":"0.09"},{"price":"0.00024200","size":"2753.62"},{"price":"0.00024242","size":"15.00"},{"price":"0.00024250","size":"0.09"},{"price":"0.00024278","size":"7797.95"},{"price":"0.00024330","size":"0.03"},{"price":"0.00024350","size":"0.09"},{"price":"0.00024369","size":"2322.96"},{"price":"0.00024450","size":"0.09"},{"price":"0.00024480","size":"5751.32"},{"price":"0.00024550","size":"0.09"},{"price":"0.00024566","size":"2716.63"},{"price":"0.00024600","size":"0.01"},{"price":"0.00024650","size":"0.09"},{"price":"0.00024670","size":"3765.91"},{"price":"0.00024703","size":"0.03"},{"price":"0.00024750","size":"0.09"},{"price":"0.00024752","size":"3437.76"},{"price":"0.00024770","size":"26.96"},{"price":"0.00024840","size":"20.00"},{"price":"0.00024850","size":"0.09"},{"price":"0.00024861","size":"1271.93"},{"price":"0.00024884","size":"0.27"},{"price":"0.00024949","size":"1327.15"},{"price":"0.00024950","size":"0.09"},{"price":"0.00025000","size":"1.06"},{"price":"0.00025037","size":"202.48"},{"price":"0.00025075","size":"0.03"},{"price":"0.00025147","size":"545.60"},{"price":"0.00025150","size":"0.20"},{"price":"0.00025200","size":"0.06"},{"price":"0.00025225","size":"277.20"},{"price":"0.00025340","size":"2336.93"},{"price":"0.00025350","size":"0.20"},{"price":"0.00025425","size":"3924.25"},{"price":"0.00025448","size":"0.03"},{"price":"0.00025520","size":"3646.28"},{"price":"0.00025527","size":"4.02"},{"price":"0.00025550","size":"0.20"},{"price":"0.00025600","size":"0.01"},{"price":"0.00025634","size":"1808.36"},{"price":"0.00025724","size":"2069.99"},{"price":"0.00025750","size":"0.20"},{"price":"0.00025810","size":"1416.53"},{"price":"0.00025820","size":"0.03"},{"price":"0.00025910","size":"106.47"},{"price":"0.00025950","size":"0.20"},{"price":"0.00026000","size":"0.27"},{"price":"0.00026001","size":"99.74"},{"price":"0.00026088","size":"2385.14"},{"price":"0.00026192","size":"0.03"},{"price":"0.00026201","size":"3880.87"},{"price":"0.00026282","size":"263.99"},{"price":"0.00026565","size":"0.03"},{"price":"0.00026600","size":"0.01"},{"price":"0.00026937","size":"0.03"},{"price":"0.00027310","size":"0.03"},{"price":"0.00027486","size":"5.00"},{"price":"0.00027500","size":"0.49"},{"price":"0.00027600","size":"0.01"},{"price":"0.00027682","size":"0.03"},{"price":"0.00027880","size":"20.00"},{"price":"0.00028000","size":"0.07"},{"price":"0.00028054","size":"0.03"},{"price":"0.00028427","size":"0.03"},{"price":"0.00028600","size":"0.01"},{"price":"0.00028799","size":"0.03"},{"price":"0.00029000","size":"68.48"},{"price":"0.00029172","size":"0.03"},{"price":"0.00029440","size":"20.00"},{"price":"0.00029544","size":"0.03"},{"price":"0.00029600","size":"0.02"},{"price":"0.00029666","size":"0.95"},{"price":"0.00029916","size":"0.03"},{"price":"0.00030000","size":"10.21"},{"price":"0.00030289","size":"0.03"},{"price":"0.00030600","size":"0.01"},{"price":"0.00030661","size":"0.03"},{"price":"0.00030758","size":"0.01"},{"price":"0.00031033","size":"0.03"},{"price":"0.00031177","size":"0.01"},{"price":"0.00031353","size":"4.82"},{"price":"0.00031406","size":"0.03"},{"price":"0.00031477","size":"0.01"},{"price":"0.00031600","size":"0.01"},{"price":"0.00031778","size":"0.03"},{"price":"0.00032000","size":"0.06"},{"price":"0.00032151","size":"0.03"},{"price":"0.00032523","size":"0.03"},{"price":"0.00032600","size":"0.01"},{"price":"0.00032666","size":"0.40"},{"price":"0.00032895","size":"0.03"},{"price":"0.00033000","size":"0.06"},{"price":"0.00033268","size":"0.03"},{"price":"0.00033600","size":"0.01"},{"price":"0.00033640","size":"0.03"},{"price":"0.00034000","size":"0.11"},{"price":"0.00034013","size":"0.03"},{"price":"0.00034385","size":"0.03"},{"price":"0.00034600","size":"0.01"},{"price":"0.00034740","size":"32.00"},{"price":"0.00034757","size":"0.03"},{"price":"0.00035000","size":"1.13"},{"price":"0.00035130","size":"0.04"},{"price":"0.00035502","size":"0.03"},{"price":"0.00035600","size":"0.01"},{"price":"0.00035874","size":"0.03"},{"price":"0.00036247","size":"0.03"},{"price":"0.00036350","size":"0.01"},{"price":"0.00036400","size":"290.65"},{"price":"0.00036550","size":"0.01"},{"price":"0.00036600","size":"0.99"},{"price":"0.00036619","size":"0.03"},{"price":"0.00036660","size":"0.10"},{"price":"0.00036992","size":"0.03"},{"price":"0.00037000","size":"0.11"},{"price":"0.00037001","size":"1.00"},{"price":"0.00037364","size":"0.03"},{"price":"0.00037600","size":"0.01"},{"price":"0.00037666","size":"0.95"},{"price":"0.00037736","size":"0.03"},{"price":"0.00038109","size":"0.03"},{"price":"0.00038199","size":"1.31"},{"price":"0.00038481","size":"0.03"},{"price":"0.00038600","size":"0.01"},{"price":"0.00038666","size":"1.00"},{"price":"0.00038854","size":"0.03"},{"price":"0.00039000","size":"5.95"},{"price":"0.00039226","size":"0.03"},{"price":"0.00039395","size":"47.10"},{"price":"0.00039598","size":"0.03"},{"price":"0.00039600","size":"0.01"},{"price":"0.00039666","size":"0.97"},{"price":"0.00039846","size":"8.54"},{"price":"0.00039865","size":"2.35"},{"price":"0.00039899","size":"50.00"},{"price":"0.00039971","size":"0.03"},{"price":"0.00040000","size":"11.12"},{"price":"0.00040168","size":"1.26"},{"price":"0.00040196","size":"1.02"},{"price":"0.00040343","size":"0.03"},{"price":"0.00040600","size":"0.01"},{"price":"0.00040716","size":"0.03"},{"price":"0.00041088","size":"0.03"},{"price":"0.00041460","size":"0.03"},{"price":"0.00041600","size":"0.01"},{"price":"0.00041660","size":"73.38"},{"price":"0.00041833","size":"0.03"},{"price":"0.00042205","size":"0.03"},{"price":"0.00042577","size":"0.03"},{"price":"0.00042600","size":"0.01"},{"price":"0.00042950","size":"0.03"},{"price":"0.00043234","size":"50.00"},{"price":"0.00043322","size":"0.03"},{"price":"0.00043600","size":"0.01"},{"price":"0.00043695","size":"0.03"},{"price":"0.00044000","size":"0.01"},{"price":"0.00044067","size":"0.03"},{"price":"0.00044439","size":"0.03"},{"price":"0.00044600","size":"0.01"},{"price":"0.00044812","size":"0.03"},{"price":"0.00045000","size":"1.14"},{"price":"0.00045184","size":"0.03"},{"price":"0.00045395","size":"50.00"},{"price":"0.00045557","size":"0.03"},{"price":"0.00045600","size":"0.01"},{"price":"0.00045929","size":"0.03"},{"price":"0.00046270","size":"0.02"},{"price":"0.00046301","size":"0.03"},{"price":"0.00046600","size":"0.01"},{"price":"0.00046674","size":"0.03"},{"price":"0.00046700","size":"0.01"},{"price":"0.00046800","size":"0.01"},{"price":"0.00046900","size":"0.01"},{"price":"0.00047000","size":"0.01"},{"price":"0.00047002","size":"20.00"},{"price":"0.00047046","size":"0.03"},{"price":"0.00047419","size":"0.04"},{"price":"0.00047486","size":"4.00"},{"price":"0.00047600","size":"0.01"},{"price":"0.00047666","size":"0.90"},{"price":"0.00048580","size":"4.00"},{"price":"0.00048600","size":"0.01"},{"price":"0.00049045","size":"0.01"},{"price":"0.00049600","size":"0.01"},{"price":"0.00049899","size":"25.00"},{"price":"0.00050000","size":"28.40"},{"price":"0.00050395","size":"50.00"},{"price":"0.00050600","size":"0.01"},{"price":"0.00051600","size":"0.01"},{"price":"0.00052600","size":"0.01"},{"price":"0.00053117","size":"20.62"},{"price":"0.00053600","size":"0.01"},{"price":"0.00054570","size":"50.00"},{"price":"0.00054600","size":"0.01"},{"price":"0.00054666","size":"0.90"},{"price":"0.00055000","size":"1.07"},{"price":"0.00055600","size":"0.01"},{"price":"0.00056600","size":"0.01"},{"price":"0.00057600","size":"0.01"},{"price":"0.00058434","size":"5.61"},{"price":"0.00058600","size":"0.01"},{"price":"0.00059600","size":"0.01"},{"price":"0.00060000","size":"100.20"},{"price":"0.00060600","size":"0.01"},{"price":"0.00060638","size":"0.01"},{"price":"0.00061600","size":"0.01"},{"price":"0.00061988","size":"0.01"},{"price":"0.00062600","size":"0.01"},{"price":"0.00063518","size":"28.40"},{"price":"0.00063600","size":"0.01"},{"price":"0.00064570","size":"50.00"},{"price":"0.00064600","size":"0.01"},{"price":"0.00065000","size":"1.00"},{"price":"0.00065600","size":"0.01"},{"price":"0.00066000","size":"0.06"},{"price":"0.00066600","size":"0.01"},{"price":"0.00067486","size":"3.50"},{"price":"0.00067600","size":"0.01"},{"price":"0.00068600","size":"0.01"},{"price":"0.00069080","size":"4.16"},{"price":"0.00069600","size":"0.01"},{"price":"0.00070000","size":"21.00"},{"price":"0.00070600","size":"0.01"},{"price":"0.00071600","size":"0.01"},{"price":"0.00071988","size":"0.01"},{"price":"0.00072600","size":"0.01"},{"price":"0.00072988","size":"0.01"},{"price":"0.00073600","size":"0.01"},{"price":"0.00073682","size":"30.00"},{"price":"0.00073988","size":"0.01"},{"price":"0.00074000","size":"0.05"},{"price":"0.00074600","size":"0.01"},{"price":"0.00075000","size":"1.00"},{"price":"0.00075485","size":"100.00"},{"price":"0.00075600","size":"0.01"},{"price":"0.00075988","size":"0.01"},{"price":"0.00076600","size":"0.01"},{"price":"0.00077000","size":"3.00"},{"price":"0.00077519","size":"3.00"},{"price":"0.00077600","size":"0.01"},{"price":"0.00078600","size":"0.11"},{"price":"0.00078691","size":"600.00"},{"price":"0.00079111","size":"5.00"},{"price":"0.00079350","size":"1.50"},{"price":"0.00079600","size":"0.01"},{"price":"0.00080000","size":"1.05"},{"price":"0.00080424","size":"5.21"},{"price":"0.00080584","size":"28.00"},{"price":"0.00080600","size":"0.01"},{"price":"0.00080638","size":"0.01"},{"price":"0.00080889","size":"0.02"},{"price":"0.00081000","size":"20.00"},{"price":"0.00081110","size":"0.01"},{"price":"0.00081465","size":"10.00"},{"price":"0.00081600","size":"0.01"},{"price":"0.00082000","size":"0.05"},{"price":"0.00082480","size":"0.05"},{"price":"0.00082600","size":"0.01"},{"price":"0.00083000","size":"0.05"},{"price":"0.00083350","size":"0.01"},{"price":"0.00083378","size":"0.05"},{"price":"0.00083600","size":"0.01"},{"price":"0.00083682","size":"30.00"},{"price":"0.00084000","size":"0.05"},{"price":"0.00084111","size":"5.00"},{"price":"0.00084275","size":"0.06"},{"price":"0.00084600","size":"0.01"},{"price":"0.00085000","size":"0.05"},{"price":"0.00085173","size":"0.05"},{"price":"0.00085600","size":"0.01"},{"price":"0.00085988","size":"0.01"},{"price":"0.00086000","size":"0.05"},{"price":"0.00086070","size":"0.05"},{"price":"0.00086600","size":"0.01"},{"price":"0.00086660","size":"0.90"},{"price":"0.00086968","size":"0.05"},{"price":"0.00087000","size":"0.05"},{"price":"0.00087600","size":"0.01"},{"price":"0.00087866","size":"0.05"},{"price":"0.00088000","size":"0.05"},{"price":"0.00088600","size":"0.01"},{"price":"0.00088763","size":"0.05"},{"price":"0.00088988","size":"0.01"},{"price":"0.00089000","size":"0.05"},{"price":"0.00089111","size":"5.00"},{"price":"0.00089600","size":"0.01"},{"price":"0.00089661","size":"0.05"},{"price":"0.00089988","size":"0.01"},{"price":"0.00090000","size":"1.05"},{"price":"0.00090168","size":"0.01"},{"price":"0.00090559","size":"0.06"},{"price":"0.00090600","size":"0.01"},{"price":"0.00090638","size":"0.01"},{"price":"0.00091000","size":"0.05"},{"price":"0.00091456","size":"0.05"},{"price":"0.00091600","size":"0.01"},{"price":"0.00092000","size":"0.05"},{"price":"0.00092216","size":"90.57"},{"price":"0.00092354","size":"0.05"},{"price":"0.00092500","size":"50.00"},{"price":"0.00092600","size":"0.01"},{"price":"0.00092718","size":"0.10"},{"price":"0.00093000","size":"0.05"},{"price":"0.00093251","size":"0.05"},{"price":"0.00093600","size":"0.01"},{"price":"0.00093682","size":"30.70"},{"price":"0.00094000","size":"0.05"},{"price":"0.00094111","size":"5.00"},{"price":"0.00094149","size":"0.05"},{"price":"0.00094600","size":"0.01"},{"price":"0.00095000","size":"0.06"},{"price":"0.00095047","size":"0.05"},{"price":"0.00095060","size":"3.00"},{"price":"0.00095600","size":"0.01"},{"price":"0.00095718","size":"0.10"},{"price":"0.00095944","size":"0.05"},{"price":"0.00096000","size":"0.15"},{"price":"0.00096230","size":"0.03"},{"price":"0.00096600","size":"0.01"},{"price":"0.00096660","size":"0.20"},{"price":"0.00096842","size":"0.06"},{"price":"0.00097000","size":"0.05"},{"price":"0.00097600","size":"0.01"},{"price":"0.00097740","size":"0.05"},{"price":"0.00098000","size":"0.05"},{"price":"0.00098600","size":"0.01"},{"price":"0.00099000","size":"0.05"},{"price":"0.00099111","size":"5.00"},{"price":"0.00099600","size":"0.01"},{"price":"0.00099718","size":"0.10"},{"price":"0.00100000","size":"26.05"},{"price":"0.00100500","size":"0.01"},{"price":"0.00100600","size":"0.01"},{"price":"0.00101000","size":"0.05"},{"price":"0.00101600","size":"0.01"},{"price":"0.00102000","size":"0.05"},{"price":"0.00103000","size":"0.05"},{"price":"0.00104000","size":"0.05"},{"price":"0.00105000","size":"0.05"},{"price":"0.00105519","size":"2.50"},{"price":"0.00106000","size":"0.05"},{"price":"0.00107000","size":"0.05"},{"price":"0.00107899","size":"50.00"},{"price":"0.00108000","size":"0.05"},{"price":"0.00109000","size":"0.35"},{"price":"0.00110000","size":"1.05"},{"price":"0.00110500","size":"10.00"},{"price":"0.00110833","size":"0.01"},{"price":"0.00111000","size":"0.05"},{"price":"0.00112000","size":"62.98"},{"price":"0.00112299","size":"30.00"},{"price":"0.00113000","size":"0.05"},{"price":"0.00114000","size":"0.05"},{"price":"0.00114499","size":"30.00"},{"price":"0.00115000","size":"1.06"},{"price":"0.00115999","size":"32.00"},{"price":"0.00116000","size":"1.05"},{"price":"0.00116172","size":"130.00"},{"price":"0.00117000","size":"0.05"},{"price":"0.00118000","size":"0.05"},{"price":"0.00119000","size":"0.05"},{"price":"0.00119718","size":"0.10"},{"price":"0.00120000","size":"2.05"},{"price":"0.00121000","size":"0.05"},{"price":"0.00121166","size":"0.01"},{"price":"0.00121735","size":"0.50"},{"price":"0.00122000","size":"0.05"},{"price":"0.00123000","size":"0.05"},{"price":"0.00124000","size":"0.05"},{"price":"0.00125000","size":"0.05"},{"price":"0.00126000","size":"0.05"},{"price":"0.00127000","size":"0.05"},{"price":"0.00128000","size":"0.05"},{"price":"0.00129000","size":"0.05"},{"price":"0.00129158","size":"20.00"},{"price":"0.00129899","size":"50.00"},{"price":"0.00130000","size":"1.05"},{"price":"0.00131000","size":"0.05"},{"price":"0.00131499","size":"0.01"},{"price":"0.00132000","size":"0.05"},{"price":"0.00133000","size":"0.05"},{"price":"0.00134000","size":"0.05"},{"price":"0.00135000","size":"0.05"},{"price":"0.00135060","size":"3.00"},{"price":"0.00136000","size":"0.05"},{"price":"0.00137000","size":"0.05"},{"price":"0.00138000","size":"0.05"},{"price":"0.00139718","size":"0.30"},{"price":"0.00140000","size":"2.03"},{"price":"0.00141831","size":"0.01"},{"price":"0.00142491","size":"8.00"},{"price":"0.00142600","size":"1.00"},{"price":"0.00146660","size":"0.04"},{"price":"0.00149111","size":"5.00"},{"price":"0.00149158","size":"29.22"},{"price":"0.00150000","size":"9.50"},{"price":"0.00150241","size":"0.01"},{"price":"0.00152164","size":"0.01"},{"price":"0.00153555","size":"31.00"},{"price":"0.00154155","size":"30.00"},{"price":"0.00155000","size":"177.59"},{"price":"0.00159718","size":"0.30"},{"price":"0.00160000","size":"1.00"},{"price":"0.00162497","size":"0.01"},{"price":"0.00166600","size":"0.90"},{"price":"0.00167200","size":"0.01"},{"price":"0.00167993","size":"2.00"},{"price":"0.00169240","size":"1.00"},{"price":"0.00170000","size":"4.00"},{"price":"0.00171060","size":"5.00"},{"price":"0.00171735","size":"0.50"},{"price":"0.00172549","size":"6.00"},{"price":"0.00172830","size":"0.01"},{"price":"0.00173333","size":"1.00"},{"price":"0.00175000","size":"10.00"},{"price":"0.00175080","size":"3.00"},{"price":"0.00178470","size":"3.00"},{"price":"0.00179111","size":"5.00"},{"price":"0.00179999","size":"13.00"},{"price":"0.00180000","size":"107.57"},{"price":"0.00180099","size":"7.00"},{"price":"0.00182355","size":"1.20"},{"price":"0.00183162","size":"0.01"},{"price":"0.00183636","size":"1.00"},{"price":"0.00184098","size":"175.00"},{"price":"0.00185000","size":"1.00"},{"price":"0.00185026","size":"9.00"},{"price":"0.00186363","size":"1.00"},{"price":"0.00189718","size":"0.30"},{"price":"0.00189999","size":"1.00"},{"price":"0.00190000","size":"4.00"},{"price":"0.00191000","size":"1.00"},{"price":"0.00192000","size":"1.00"},{"price":"0.00193403","size":"3.00"},{"price":"0.00193495","size":"0.01"},{"price":"0.00194000","size":"1.00"},{"price":"0.00195000","size":"7.00"},{"price":"0.00196660","size":"0.07"},{"price":"0.00199111","size":"5.00"},{"price":"0.00199718","size":"0.30"},{"price":"0.00199800","size":"100.00"},{"price":"0.00199999","size":"1.01"},{"price":"0.00200000","size":"908.28"},{"price":"0.00202718","size":"0.30"},{"price":"0.00203828","size":"0.01"},{"price":"0.00205000","size":"1.00"},{"price":"0.00205080","size":"2.00"},{"price":"0.00205350","size":"26.00"},{"price":"0.00205768","size":"8.64"},{"price":"0.00205899","size":"50.00"},{"price":"0.00207960","size":"10.00"},{"price":"0.00208691","size":"661.63"},{"price":"0.00210000","size":"10.00"},{"price":"0.00211735","size":"0.50"},{"price":"0.00212499","size":"0.02"},{"price":"0.00212718","size":"0.30"},{"price":"0.00214161","size":"0.01"},{"price":"0.00220000","size":"4.00"},{"price":"0.00224493","size":"0.01"},{"price":"0.00224999","size":"0.03"},{"price":"0.00225000","size":"6.00"},{"price":"0.00230000","size":"5.00"},{"price":"0.00232718","size":"0.30"},{"price":"0.00234826","size":"0.01"},{"price":"0.00235000","size":"1.00"},{"price":"0.00236000","size":"1.00"},{"price":"0.00237207","size":"5.00"},{"price":"0.00237499","size":"0.05"},{"price":"0.00240000","size":"47.00"},{"price":"0.00243000","size":"10.00"},{"price":"0.00245000","size":"4.00"},{"price":"0.00245159","size":"0.01"},{"price":"0.00248380","size":"65.00"},{"price":"0.00249999","size":"0.08"},{"price":"0.00250000","size":"15.00"},{"price":"0.00255492","size":"0.01"},{"price":"0.00259000","size":"9.00"},{"price":"0.00270000","size":"10.00"},{"price":"0.00280000","size":"217.00"},{"price":"0.00290000","size":"1.00"},{"price":"0.00291437","size":"25.00"},{"price":"0.00300000","size":"54.51"},{"price":"0.00300001","size":"3.00"},{"price":"0.00310475","size":"1.00"},{"price":"0.00320000","size":"5.00"},{"price":"0.00332718","size":"0.30"},{"price":"0.00333899","size":"50.00"},{"price":"0.00350000","size":"5.00"},{"price":"0.00366784","size":"3.00"},{"price":"0.00382718","size":"0.30"},{"price":"0.00400000","size":"4.22"},{"price":"0.00412718","size":"0.30"},{"price":"0.00450000","size":"5.00"},{"price":"0.00452718","size":"0.30"},{"price":"0.00490000","size":"2.00"},{"price":"0.00500000","size":"50.01"},{"price":"0.00550241","size":"0.01"},{"price":"0.00552718","size":"0.30"},{"price":"0.00800000","size":"0.05"},{"price":"0.00999999","size":"2.00"},{"price":"0.01000000","size":"1.14"},{"price":"0.01550241","size":"0.01"},{"price":"0.03298880","size":"0.10"},{"price":"0.04999999","size":"2.00"},{"price":"0.05000000","size":"0.05"},{"price":"0.05550241","size":"0.01"},{"price":"0.09000000","size":"3.00"},{"price":"0.09999999","size":"2.00"},{"price":"0.10000000","size":"0.06"},{"price":"0.12500000","size":"8.00"},{"price":"0.15550241","size":"0.01"},{"price":"0.49999999","size":"2.00"},{"price":"0.50000000","size":"0.05"},{"price":"0.55550241","size":"0.01"},{"price":"0.70000000","size":"0.02"},{"price":"0.97000000","size":"0.02"},{"price":"0.99999999","size":"2.00"},{"price":"1.00000000","size":"0.05"},{"price":"1.55550241","size":"0.01"},{"price":"2.32558140","size":"0.43"},{"price":"4.99999999","size":"1.00"},{"price":"5.00000000","size":"0.05"},{"price":"7.55550241","size":"0.01"},{"price":"7.97000000","size":"0.02"},{"price":"10.00000000","size":"0.05"},{"price":"13.55550241","size":"0.01"},{"price":"17.97939000","size":"0.02"},{"price":"27.55550241","size":"0.01"},{"price":"77.55550241","size":"0.01"},{"price":"133.55550241","size":"0.01"},{"price":"433.55550241","size":"0.01"},{"price":"833.55550241","size":"0.01"},{"price":"1333.55550241","size":"0.01"},{"price":"3727.19793900","size":"0.02"},{"price":"4333.55550241","size":"0.01"},{"price":"8333.55550241","size":"0.01"},{"price":"12333.55550241","size":"0.01"},{"price":"42333.55550241","size":"0.01"},{"price":"82333.55550241","size":"0.01"},{"price":"122333.55550241","size":"0.01"}],"bid":[{"price":"0.00015752","size":"0.01"},{"price":"0.00015749","size":"160.91"},{"price":"0.00015748","size":"67.05"},{"price":"0.00015742","size":"246.65"},{"price":"0.00015739","size":"400.00"},{"price":"0.00015738","size":"603.33"},{"price":"0.00015737","size":"170.13"},{"price":"0.00015736","size":"19.60"},{"price":"0.00015735","size":"1002.22"},{"price":"0.00015734","size":"58.80"},{"price":"0.00015733","size":"100.65"},{"price":"0.00015731","size":"63.49"},{"price":"0.00015721","size":"9.55"},{"price":"0.00015719","size":"780.80"},{"price":"0.00015718","size":"448.50"},{"price":"0.00015708","size":"670.43"},{"price":"0.00015701","size":"1394.00"},{"price":"0.00015698","size":"110.32"},{"price":"0.00015694","size":"91.76"},{"price":"0.00015691","size":"1.69"},{"price":"0.00015689","size":"835.34"},{"price":"0.00015684","size":"100.54"},{"price":"0.00015680","size":"477.14"},{"price":"0.00015679","size":"140.33"},{"price":"0.00015677","size":"151.30"},{"price":"0.00015675","size":"685.27"},{"price":"0.00015670","size":"442.84"},{"price":"0.00015665","size":"278.35"},{"price":"0.00015662","size":"1821.71"},{"price":"0.00015661","size":"382.59"},{"price":"0.00015658","size":"496.67"},{"price":"0.00015656","size":"425.16"},{"price":"0.00015651","size":"555.11"},{"price":"0.00015646","size":"505.47"},{"price":"0.00015645","size":"710.85"},{"price":"0.00015642","size":"768.36"},{"price":"0.00015641","size":"325.79"},{"price":"0.00015636","size":"1025.46"},{"price":"0.00015635","size":"2504.10"},{"price":"0.00015626","size":"749.15"},{"price":"0.00015624","size":"676.21"},{"price":"0.00015622","size":"1029.97"},{"price":"0.00015621","size":"533.77"},{"price":"0.00015620","size":"4189.92"},{"price":"0.00015617","size":"732.55"},{"price":"0.00015612","size":"724.18"},{"price":"0.00015611","size":"931.13"},{"price":"0.00015607","size":"735.16"},{"price":"0.00015606","size":"741.62"},{"price":"0.00015600","size":"564.59"},{"price":"0.00015597","size":"1590.83"},{"price":"0.00015595","size":"613.58"},{"price":"0.00015593","size":"1448.30"},{"price":"0.00015592","size":"4043.77"},{"price":"0.00015589","size":"854.09"},{"price":"0.00015584","size":"1149.96"},{"price":"0.00015567","size":"0.04"},{"price":"0.00015560","size":"185.32"},{"price":"0.00015559","size":"2677.17"},{"price":"0.00015552","size":"1746.35"},{"price":"0.00015551","size":"2391.01"},{"price":"0.00015525","size":"5478.09"},{"price":"0.00015519","size":"2597.99"},{"price":"0.00015415","size":"64.87"},{"price":"0.00015256","size":"2.62"},{"price":"0.00015255","size":"8.23"},{"price":"0.00015001","size":"1.86"},{"price":"0.00015000","size":"104.11"},{"price":"0.00014992","size":"825.34"},{"price":"0.00014982","size":"13.35"},{"price":"0.00014895","size":"1269.92"},{"price":"0.00014850","size":"104.11"},{"price":"0.00014809","size":"4839.06"},{"price":"0.00014767","size":"5673.46"},{"price":"0.00014749","size":"4996.86"},{"price":"0.00014733","size":"5431.98"},{"price":"0.00014716","size":"5414.50"},{"price":"0.00014700","size":"104.11"},{"price":"0.00014696","size":"17085.09"},{"price":"0.00014687","size":"5680.32"},{"price":"0.00014665","size":"5096.42"},{"price":"0.00014643","size":"4795.76"},{"price":"0.00014622","size":"5774.22"},{"price":"0.00014606","size":"4864.84"},{"price":"0.00014605","size":"504.10"},{"price":"0.00014588","size":"4962.11"},{"price":"0.00014550","size":"104.11"},{"price":"0.00014519","size":"1979.38"},{"price":"0.00014400","size":"104.11"},{"price":"0.00014346","size":"0.09"},{"price":"0.00014314","size":"657.70"},{"price":"0.00014309","size":"1901.77"},{"price":"0.00014250","size":"104.11"},{"price":"0.00014223","size":"1984.80"},{"price":"0.00014210","size":"0.09"},{"price":"0.00014121","size":"330.50"},{"price":"0.00014100","size":"104.11"},{"price":"0.00014013","size":"8395.72"},{"price":"0.00014010","size":"0.09"},{"price":"0.00014000","size":"1.00"},{"price":"0.00013950","size":"104.11"},{"price":"0.00013944","size":"13013.53"},{"price":"0.00013842","size":"1981.28"},{"price":"0.00013802","size":"8.03"},{"price":"0.00013800","size":"104.11"},{"price":"0.00013783","size":"725.53"},{"price":"0.00013757","size":"1889.21"},{"price":"0.00013753","size":"0.10"},{"price":"0.00013666","size":"0.50"},{"price":"0.00013654","size":"245.67"},{"price":"0.00013650","size":"104.11"},{"price":"0.00013552","size":"5659.86"},{"price":"0.00013500","size":"1.00"},{"price":"0.00013408","size":"7252.36"},{"price":"0.00013363","size":"3846.83"},{"price":"0.00013273","size":"504.68"},{"price":"0.00013173","size":"1600.57"},{"price":"0.00013068","size":"250.27"},{"price":"0.00013000","size":"1.00"},{"price":"0.00012976","size":"3019.21"},{"price":"0.00012875","size":"1776.07"},{"price":"0.00012790","size":"2897.14"},{"price":"0.00012622","size":"0.55"},{"price":"0.00012621","size":"829.60"},{"price":"0.00012609","size":"2782.74"},{"price":"0.00012500","size":"1.00"},{"price":"0.00012490","size":"5827.95"},{"price":"0.00012423","size":"1315.54"},{"price":"0.00012302","size":"1697.71"},{"price":"0.00012223","size":"593.84"},{"price":"0.00012126","size":"1712.52"},{"price":"0.00012038","size":"2417.47"},{"price":"0.00012000","size":"1.00"},{"price":"0.00011933","size":"4286.94"},{"price":"0.00011855","size":"3868.61"},{"price":"0.00011732","size":"956.01"},{"price":"0.00011636","size":"356.54"},{"price":"0.00011550","size":"5448.01"},{"price":"0.00011500","size":"1.37"},{"price":"0.00011449","size":"831.54"},{"price":"0.00011340","size":"2869.59"},{"price":"0.00011256","size":"437.94"},{"price":"0.00011163","size":"2381.19"},{"price":"0.00011064","size":"129.30"},{"price":"0.00011000","size":"1.16"},{"price":"0.00010974","size":"2401.07"},{"price":"0.00010881","size":"5936.34"},{"price":"0.00010795","size":"3579.96"},{"price":"0.00010692","size":"725.86"},{"price":"0.00010586","size":"2064.90"},{"price":"0.00010501","size":"713.61"},{"price":"0.00010500","size":"1.16"},{"price":"0.00010407","size":"1573.62"},{"price":"0.00010304","size":"2182.20"},{"price":"0.00010202","size":"1007.64"},{"price":"0.00010129","size":"2870.13"},{"price":"0.00010028","size":"834.19"},{"price":"0.00010000","size":"6.20"},{"price":"0.00009932","size":"4428.83"},{"price":"0.00009900","size":"0.01"},{"price":"0.00009842","size":"6984.39"},{"price":"0.00009742","size":"2854.15"},{"price":"0.00009644","size":"2322.11"},{"price":"0.00009630","size":"2.78"},{"price":"0.00009600","size":"0.01"},{"price":"0.00009543","size":"115.12"},{"price":"0.00009511","size":"0.01"},{"price":"0.00009500","size":"1.17"},{"price":"0.00009462","size":"1340.44"},{"price":"0.00009343","size":"4875.36"},{"price":"0.00009333","size":"0.10"},{"price":"0.00009300","size":"0.01"},{"price":"0.00009275","size":"917.97"},{"price":"0.00009154","size":"408.24"},{"price":"0.00009079","size":"0.98"},{"price":"0.00009078","size":"414.27"},{"price":"0.00009040","size":"0.05"},{"price":"0.00009000","size":"1.41"},{"price":"0.00008977","size":"798.22"},{"price":"0.00008866","size":"1375.32"},{"price":"0.00008774","size":"180.81"},{"price":"0.00008686","size":"2437.96"},{"price":"0.00008611","size":"0.01"},{"price":"0.00008597","size":"140.17"},{"price":"0.00008557","size":"2.00"},{"price":"0.00008500","size":"1.20"},{"price":"0.00008498","size":"7701.64"},{"price":"0.00008392","size":"6009.13"},{"price":"0.00008333","size":"0.20"},{"price":"0.00008306","size":"3218.85"},{"price":"0.00008250","size":"1.00"},{"price":"0.00008215","size":"445.89"},{"price":"0.00008109","size":"3463.36"},{"price":"0.00008090","size":"0.16"},{"price":"0.00008014","size":"2140.11"},{"price":"0.00008000","size":"1.45"},{"price":"0.00007923","size":"0.70"},{"price":"0.00007919","size":"3391.99"},{"price":"0.00007900","size":"0.90"},{"price":"0.00007849","size":"588.92"},{"price":"0.00007800","size":"1.00"},{"price":"0.00007750","size":"1.00"},{"price":"0.00007730","size":"4748.23"},{"price":"0.00007723","size":"0.80"},{"price":"0.00007700","size":"1.10"},{"price":"0.00007647","size":"129.91"},{"price":"0.00007600","size":"1.44"},{"price":"0.00007539","size":"2121.12"},{"price":"0.00007523","size":"0.90"},{"price":"0.00007504","size":"1.06"},{"price":"0.00007500","size":"729.50"},{"price":"0.00007466","size":"116.80"},{"price":"0.00007400","size":"1.40"},{"price":"0.00007344","size":"164.09"},{"price":"0.00007333","size":"0.30"},{"price":"0.00007323","size":"1.00"},{"price":"0.00007300","size":"1.72"},{"price":"0.00007288","size":"1.00"},{"price":"0.00007267","size":"111.43"},{"price":"0.00007250","size":"1.00"},{"price":"0.00007240","size":"1.00"},{"price":"0.00007200","size":"0.50"},{"price":"0.00007176","size":"584.31"},{"price":"0.00007141","size":"1.00"},{"price":"0.00007123","size":"1.20"},{"price":"0.00007100","size":"0.10"},{"price":"0.00007071","size":"50.00"},{"price":"0.00007066","size":"116.74"},{"price":"0.00007023","size":"1.40"},{"price":"0.00007011","size":"10.00"},{"price":"0.00007004","size":"1.14"},{"price":"0.00007000","size":"1.28"},{"price":"0.00006981","size":"5365.64"},{"price":"0.00006923","size":"1.50"},{"price":"0.00006878","size":"444.00"},{"price":"0.00006870","size":"0.80"},{"price":"0.00006797","size":"1928.87"},{"price":"0.00006750","size":"0.21"},{"price":"0.00006689","size":"2244.90"},{"price":"0.00006666","size":"2.00"},{"price":"0.00006601","size":"457.36"},{"price":"0.00006514","size":"1.68"},{"price":"0.00006513","size":"675.21"},{"price":"0.00006504","size":"1.23"},{"price":"0.00006500","size":"2.17"},{"price":"0.00006404","size":"263.60"},{"price":"0.00006333","size":"0.40"},{"price":"0.00006327","size":"3282.78"},{"price":"0.00006290","size":"50.00"},{"price":"0.00006250","size":"0.17"},{"price":"0.00006213","size":"2246.83"},{"price":"0.00006128","size":"1409.43"},{"price":"0.00006100","size":"0.20"},{"price":"0.00006034","size":"223.81"},{"price":"0.00006011","size":"10.00"},{"price":"0.00006000","size":"2.24"},{"price":"0.00005921","size":"87.46"},{"price":"0.00005870","size":"0.90"},{"price":"0.00005832","size":"1234.56"},{"price":"0.00005746","size":"1802.80"},{"price":"0.00005647","size":"1844.34"},{"price":"0.00005556","size":"123.29"},{"price":"0.00005471","size":"210.95"},{"price":"0.00005358","size":"258.11"},{"price":"0.00005333","size":"0.50"},{"price":"0.00005278","size":"147.57"},{"price":"0.00005101","size":"50.00"},{"price":"0.00005100","size":"0.40"},{"price":"0.00005030","size":"1.00"},{"price":"0.00005011","size":"10.00"},{"price":"0.00005000","size":"203.21"},{"price":"0.00004870","size":"1.00"},{"price":"0.00004500","size":"0.01"},{"price":"0.00004400","size":"2.00"},{"price":"0.00004333","size":"0.60"},{"price":"0.00004200","size":"0.01"},{"price":"0.00004100","size":"0.80"},{"price":"0.00004031","size":"2.82"},{"price":"0.00004030","size":"1.00"},{"price":"0.00004011","size":"10.00"},{"price":"0.00004000","size":"1.25"},{"price":"0.00003500","size":"0.02"},{"price":"0.00003333","size":"0.70"},{"price":"0.00003200","size":"0.35"},{"price":"0.00003100","size":"1.60"},{"price":"0.00003030","size":"1.00"},{"price":"0.00003011","size":"10.00"},{"price":"0.00003000","size":"4.01"},{"price":"0.00002700","size":"0.01"},{"price":"0.00002500","size":"0.40"},{"price":"0.00002333","size":"1.00"},{"price":"0.00002132","size":"5.36"},{"price":"0.00002131","size":"100.00"},{"price":"0.00002100","size":"3.20"},{"price":"0.00002030","size":"1.00"},{"price":"0.00002011","size":"10.00"},{"price":"0.00002000","size":"5.01"},{"price":"0.00001878","size":"159.74"},{"price":"0.00001700","size":"0.50"},{"price":"0.00001675","size":"23.88"},{"price":"0.00001600","size":"10.00"},{"price":"0.00001511","size":"100.00"},{"price":"0.00001333","size":"2.00"},{"price":"0.00001250","size":"0.80"},{"price":"0.00001200","size":"9.00"},{"price":"0.00001131","size":"100.00"},{"price":"0.00001100","size":"6.40"},{"price":"0.00001011","size":"100.00"},{"price":"0.00001000","size":"220.02"},{"price":"0.00000933","size":"2.00"},{"price":"0.00000833","size":"3.00"},{"price":"0.00000800","size":"5.00"},{"price":"0.00000751","size":"266.31"},{"price":"0.00000733","size":"3.00"},{"price":"0.00000700","size":"15.00"},{"price":"0.00000633","size":"4.00"},{"price":"0.00000533","size":"4.00"},{"price":"0.00000500","size":"20.01"},{"price":"0.00000440","size":"20.00"},{"price":"0.00000433","size":"4.00"},{"price":"0.00000333","size":"5.00"},{"price":"0.00000300","size":"30.01"},{"price":"0.00000233","size":"8.00"},{"price":"0.00000200","size":"52.30"},{"price":"0.00000167","size":"239.52"},{"price":"0.00000160","size":"100.00"},{"price":"0.00000133","size":"12.00"},{"price":"0.00000120","size":"90.00"},{"price":"0.00000100","size":"210.00"},{"price":"0.00000093","size":"11.00"},{"price":"0.00000083","size":"15.00"},{"price":"0.00000073","size":"17.00"},{"price":"0.00000063","size":"20.00"},{"price":"0.00000061","size":"819.67"},{"price":"0.00000060","size":"3333.33"},{"price":"0.00000059","size":"847.45"},{"price":"0.00000053","size":"23.00"},{"price":"0.00000043","size":"26.00"},{"price":"0.00000033","size":"33.00"},{"price":"0.00000023","size":"45.00"},{"price":"0.00000021","size":"9523.80"},{"price":"0.00000016","size":"2500.00"},{"price":"0.00000013","size":"80.00"},{"price":"0.00000010","size":"1100.00"},{"price":"0.00000003","size":"10000.00"},{"price":"0.00000002","size":"500.00"},{"price":"0.00000001","size":"11000.00"}],"sequence":18307654,"timestamp":"2021-04-17T16:38:32.492Z","symbol":"OMGBTC"}}
1618677512.9871: {"jsonrpc":"2.0","method":"snapshotOrderbook","params":{"ask":[{"price":"0.00007618","size":"133.38"},{"price":"0.00007622","size":"1731.48"},{"price":"0.00007626","size":"27.34"},{"price":"0.00007628","size":"2663.82"},{"price":"0.00007631","size":"20.87"},{"price":"0.00007646","size":"0.55"},{"price":"0.00007675","size":"7907.32"},{"price":"0.00007753","size":"7289.51"},{"price":"0.00007832","size":"7949.34"},{"price":"0.00007896","size":"7232.85"},{"price":"0.00007962","size":"6941.84"},{"price":"0.00008015","size":"8110.39"},{"price":"0.00008056","size":"7519.66"},{"price":"0.00008092","size":"7976.78"},{"price":"0.00008122","size":"7674.37"},{"price":"0.00008144","size":"7110.55"},{"price":"0.00008208","size":"3.74"},{"price":"0.00008900","size":"50.00"},{"price":"0.00009000","size":"0.10"},{"price":"0.00009320","size":"10.00"},{"price":"0.00010000","size":"96.09"},{"price":"0.00010150","size":"800.65"},{"price":"0.00011600","size":"0.20"},{"price":"0.00011999","size":"40.00"},{"price":"0.00012000","size":"0.20"},{"price":"0.00012500","size":"0.19"},{"price":"0.00012945","size":"3.00"},{"price":"0.00013000","size":"21.45"},{"price":"0.00013500","size":"0.17"},{"price":"0.00014000","size":"0.17"},{"price":"0.00014500","size":"0.67"},{"price":"0.00014600","size":"0.16"},{"price":"0.00015200","size":"0.15"},{"price":"0.00016000","size":"0.15"},{"price":"0.00017000","size":"0.14"},{"price":"0.00017992","size":"0.20"},{"price":"0.00018000","size":"0.13"},{"price":"0.00019000","size":"10.12"},{"price":"0.00020000","size":"15.22"},{"price":"0.00021000","size":"10.16"},{"price":"0.00024000","size":"10.00"},{"price":"0.00024704","size":"18.67"},{"price":"0.00030000","size":"10.10"},{"price":"0.00038000","size":"11.10"},{"price":"0.00040000","size":"2.50"},{"price":"0.00058000","size":"10.00"},{"price":"0.00065370","size":"10.00"},{"price":"0.00068000","size":"10.00"},{"price":"0.00070000","size":"13.12"},{"price":"0.00080000","size":"11.25"},{"price":"0.00100000","size":"9.00"},{"price":"0.00150000","size":"270.71"},{"price":"0.00160000","size":"0.62"},{"price":"0.00200000","size":"0.07"},{"price":"0.00250000","size":"0.57"},{"price":"0.00252228","size":"0.01"},{"price":"0.00330000","size":"0.31"},{"price":"0.00660000","size":"0.16"},{"price":"0.01400000","size":"0.08"},{"price":"0.02800000","size":"0.08"},{"price":"0.10000000","size":"0.14"},{"price":"0.99999998","size":"0.28"},{"price":"0.99999999","size":"0.06"},{"price":"21.00000000","size":"0.02"}],"bid":[{"price":"0.00007524","size":"0.05"},{"price":"0.00007523","size":"133.28"},{"price":"0.00007508","size":"53.95"},{"price":"0.00007494","size":"1737.67"},{"price":"0.00007482","size":"26.97"},{"price":"0.00007464","size":"2667.73"},{"price":"0.00007200","size":"69.44"},{"price":"0.00007199","size":"5.55"},{"price":"0.00007197","size":"4.02"},{"price":"0.00007000","size":"0.01"},{"price":"0.00006971","size":"18464.79"},{"price":"0.00006892","size":"145.09"},{"price":"0.00006891","size":"19429.36"},{"price":"0.00006836","size":"20436.14"},{"price":"0.00006789","size":"20314.20"},{"price":"0.00006714","size":"20658.46"},{"price":"0.00006597","size":"19098.81"},{"price":"0.00006482","size":"18768.36"},{"price":"0.00006374","size":"313.77"},{"price":"0.00006370","size":"20863.18"},{"price":"0.00006232","size":"19596.73"},{"price":"0.00006086","size":"20242.22"},{"price":"0.00005755","size":"3.22"},{"price":"0.00005600","size":"0.28"},{"price":"0.00005400","size":"0.27"},{"price":"0.00005200","size":"0.32"},{"price":"0.00005055","size":"2.00"},{"price":"0.00005000","size":"0.41"},{"price":"0.00004910","size":"5.70"},{"price":"0.00004800","size":"0.75"},{"price":"0.00004655","size":"2.00"},{"price":"0.00004600","size":"0.40"},{"price":"0.00004400","size":"0.35"},{"price":"0.00004200","size":"0.36"},{"price":"0.00004014","size":"0.74"},{"price":"0.00004000","size":"2.91"},{"price":"0.00003999","size":"166.00"},{"price":"0.00003800","size":"0.43"},{"price":"0.00003600","size":"6.48"},{"price":"0.00003400","size":"0.53"},{"price":"0.00003200","size":"0.37"},{"price":"0.00003000","size":"0.40"},{"price":"0.00002284","size":"3.00"},{"price":"0.00001090","size":"1.00"},{"price":"0.00000990","size":"2.00"},{"price":"0.00000890","size":"3.00"},{"price":"0.00000791","size":"12.64"},{"price":"0.00000790","size":"4.00"},{"price":"0.00000693","size":"1.42"},{"price":"0.00000692","size":"28.90"},{"price":"0.00000690","size":"5.00"},{"price":"0.00000592","size":"16.89"},{"price":"0.00000590","size":"6.00"},{"price":"0.00000492","size":"20.32"},{"price":"0.00000490","size":"7.00"},{"price":"0.00000446","size":"2.85"},{"price":"0.00000445","size":"22.47"},{"price":"0.00000392","size":"25.51"},{"price":"0.00000390","size":"8.00"},{"price":"0.00000360","size":"60.00"},{"price":"0.00000312","size":"64.10"},{"price":"0.00000309","size":"32.36"},{"price":"0.00000291","size":"34.36"},{"price":"0.00000290","size":"9.00"},{"price":"0.00000213","size":"7.29"},{"price":"0.00000212","size":"94.33"},{"price":"0.00000192","size":"52.08"},{"price":"0.00000190","size":"10.00"},{"price":"0.00000172","size":"116.27"},{"price":"0.00000168","size":"59.52"},{"price":"0.00000153","size":"65.35"},{"price":"0.00000152","size":"663.64"},{"price":"0.00000045","size":"222.22"},{"price":"0.00000028","size":"357.14"},{"price":"0.00000022","size":"454.54"},{"price":"0.00000021","size":"476.19"},{"price":"0.00000020","size":"500.00"},{"price":"0.00000002","size":"10000.00"}],"sequence":5856016,"timestamp":"2021-04-17T16:38:32.468Z","symbol":"DODOBTC"}}
1618677512.988275: {"jsonrpc":"2.0","method":"snapshotOrderbook","params":{"ask":[{"price":"4.60172","size":"15077.08"},{"price":"4.60313","size":"4170.50"},{"price":"4.60914","size":"20.52"},{"price":"4.61869","size":"8443.15"},{"price":"4.65481","size":"0.05"},{"price":"4.67713","size":"0.05"},{"price":"4.68122","size":"10836.10"},{"price":"4.69956","size":"0.05"},{"price":"4.72209","size":"0.05"},{"price":"4.73153","size":"15561.71"},{"price":"4.73611","size":"0.01"},{"price":"4.74472","size":"0.05"},{"price":"4.76745","size":"0.05"},{"price":"4.79030","size":"0.05"},{"price":"4.80020","size":"21772.25"},{"price":"4.81325","size":"0.05"},{"price":"4.83631","size":"0.05"},{"price":"4.85949","size":"0.05"},{"price":"4.88277","size":"0.05"},{"price":"4.88757","size":"28569.63"},{"price":"4.90183","size":"0.01"},{"price":"4.90617","size":"0.05"},{"price":"4.92477","size":"3035.47"},{"price":"4.92968","size":"0.05"},{"price":"4.95329","size":"0.05"},{"price":"4.96746","size":"51739.23"},{"price":"4.97702","size":"0.05"},{"price":"4.99491","size":"114636.29"},{"price":"5.00087","size":"0.05"},{"price":"5.02068","size":"8679.61"},{"price":"5.02483","size":"0.05"},{"price":"5.03637","size":"0.01"},{"price":"5.04890","size":"0.05"},{"price":"5.05011","size":"4199.58"},{"price":"5.07137","size":"21559.60"},{"price":"5.07309","size":"0.05"},{"price":"5.09740","size":"0.05"},{"price":"5.09881","size":"14636.32"},{"price":"5.12182","size":"0.05"},{"price":"5.12718","size":"15682.90"},{"price":"5.14636","size":"0.05"},{"price":"5.15542","size":"10111.52"},{"price":"5.17102","size":"0.05"},{"price":"5.17813","size":"10980.93"},{"price":"5.19579","size":"0.05"},{"price":"5.20226","size":"8716.44"},{"price":"5.22069","size":"0.05"},{"price":"5.23484","size":"12272.92"},{"price":"5.24570","size":"0.05"},{"price":"5.26221","size":"31304.46"},{"price":"5.27084","size":"0.05"},{"price":"5.28481","size":"49052.87"},{"price":"5.29610","size":"0.05"},{"price":"5.30939","size":"20571.28"},{"price":"5.32148","size":"0.05"},{"price":"5.33717","size":"1117.17"},{"price":"5.34698","size":"0.05"},{"price":"5.36138","size":"0.01"},{"price":"5.36239","size":"27532.65"},{"price":"5.37260","size":"0.04"},{"price":"5.39472","size":"6036.36"},{"price":"5.39834","size":"0.04"},{"price":"5.41724","size":"16638.47"},{"price":"5.42421","size":"0.04"},{"price":"5.45020","size":"0.04"},{"price":"5.46922","size":"649.10"},{"price":"5.47631","size":"0.04"},{"price":"5.49670","size":"3695.41"},{"price":"5.49924","size":"2097.06"},{"price":"5.50255","size":"0.04"},{"price":"5.52891","size":"0.04"},{"price":"5.54349","size":"0.01"},{"price":"5.55117","size":"20120.34"},{"price":"5.55540","size":"0.04"},{"price":"5.57181","size":"31438.16"},{"price":"5.57329","size":"622.26"},{"price":"5.57470","size":"48.76"},{"price":"5.58202","size":"0.04"},{"price":"5.60442","size":"2087.74"},{"price":"5.60877","size":"0.04"},{"price":"5.62671","size":"3474.47"},{"price":"5.63564","size":"0.04"},{"price":"5.65000","size":"5.02"},{"price":"5.65251","size":"12233.30"},{"price":"5.66264","size":"0.04"},{"price":"5.68175","size":"508.80"},{"price":"5.70643","size":"10565.73"},{"price":"5.73068","size":"16945.29"},{"price":"5.73492","size":"0.01"},{"price":"5.79206","size":"861.15"},{"price":"5.81117","size":"1355.64"},{"price":"5.81596","size":"25635.02"},{"price":"5.83589","size":"880.93"},{"price":"5.89212","size":"9254.42"},{"price":"5.92555","size":"3488.16"},{"price":"5.93369","size":"0.01"},{"price":"5.94969","size":"6181.76"},{"price":"5.97103","size":"6097.05"},{"price":"6.00000","size":"56.75"},{"price":"6.00379","size":"4769.41"},{"price":"6.03054","size":"8951.00"},{"price":"6.05646","size":"2873.81"},{"price":"6.07670","size":"1.00"},{"price":"6.08372","size":"2683.10"},{"price":"6.10000","size":"100.00"},{"price":"6.10366","size":"1115.01"},{"price":"6.13604","size":"3593.77"},{"price":"6.13823","size":"0.01"},{"price":"6.16206","size":"17693.57"},{"price":"6.18830","size":"374.51"},{"price":"6.21127","size":"7055.66"},{"price":"6.23942","size":"3561.26"},{"price":"6.26434","size":"28189.74"},{"price":"6.29625","size":"4027.74"},{"price":"6.30000","size":"52.11"},{"price":"6.32193","size":"28647.63"},{"price":"6.33000","size":"26.71"},{"price":"6.34256","size":"9979.51"},{"price":"6.34732","size":"0.01"},{"price":"6.37230","size":"16487.32"},{"price":"6.40000","size":"6.70"},{"price":"6.40230","size":"10787.07"},{"price":"6.42766","size":"555.46"},{"price":"6.45021","size":"3030.82"},{"price":"6.47839","size":"659.59"},{"price":"6.50000","size":"349.37"},{"price":"6.50509","size":"18043.39"},{"price":"6.53209","size":"442.03"},{"price":"6.55793","size":"13562.55"},{"price":"6.58374","size":"7055.48"},{"price":"6.61175","size":"1268.43"},{"price":"6.63627","size":"4009.01"},{"price":"6.66593","size":"11226.55"},{"price":"6.68844","size":"2213.07"},{"price":"6.71909","size":"22586.56"},{"price":"6.74816","size":"1086.15"},{"price":"6.76823","size":"302.89"},{"price":"6.77534","size":"0.01"},{"price":"6.80000","size":"10.00"},{"price":"6.80061","size":"3515.81"},{"price":"6.82303","size":"865.73"},{"price":"6.84734","size":"13428.09"},{"price":"6.87488","size":"693.44"},{"price":"6.90488","size":"10130.20"},{"price":"6.92733","size":"10098.53"},{"price":"6.95531","size":"1391.55"},{"price":"6.98656","size":"11052.70"},{"price":"6.99285","size":"0.01"},{"price":"7.00000","size":"114.10"},{"price":"7.01253","size":"25165.50"},{"price":"7.04006","size":"4406.17"},{"price":"7.06658","size":"19561.45"},{"price":"7.09110","size":"798.71"},{"price":"7.09416","size":"157.05"},{"price":"7.11922","size":"3463.01"},{"price":"7.13893","size":"1218.91"},{"price":"7.16661","size":"287.81"},{"price":"7.19564","size":"18485.72"},{"price":"7.21194","size":"0.01"},{"price":"7.22417","size":"5900.82"},{"price":"7.25193","size":"21477.62"},{"price":"7.27502","size":"2289.30"},{"price":"7.29707","size":"15287.26"},{"price":"7.30952","size":"2.09"},{"price":"7.32998","size":"309.22"},{"price":"7.35342","size":"5542.47"},{"price":"7.38285","size":"24125.73"},{"price":"7.40487","size":"2367.40"},{"price":"7.43219","size":"0.01"},{"price":"7.43587","size":"3377.28"},{"price":"7.46195","size":"21441.44"},{"price":"7.48806","size":"313.18"},{"price":"7.51004","size":"379.13"},{"price":"7.54165","size":"5941.08"},{"price":"7.56376","size":"7386.92"},{"price":"7.59507","size":"21028.69"},{"price":"7.61954","size":"10108.40"},{"price":"7.65324","size":"0.01"},{"price":"7.87482","size":"0.01"},{"price":"8.00000","size":"50.00"},{"price":"8.10000","size":"4.00"},{"price":"8.24379","size":"10.00"},{"price":"8.31862","size":"0.01"},{"price":"8.46339","size":"1.53"},{"price":"8.54048","size":"0.01"},{"price":"8.76214","size":"0.01"},{"price":"8.98346","size":"0.01"},{"price":"9.20437","size":"0.01"},{"price":"9.24379","size":"10.00"},{"price":"9.42479","size":"0.01"},{"price":"9.70000","size":"2.81"},{"price":"9.86391","size":"0.01"},{"price":"10.00000","size":"50.01"},{"price":"10.08252","size":"0.01"},{"price":"10.30045","size":"0.01"},{"price":"10.51766","size":"0.01"},{"price":"10.73415","size":"0.01"},{"price":"10.94988","size":"0.01"},{"price":"11.16486","size":"0.01"},{"price":"11.59248","size":"0.01"},{"price":"11.80513","size":"0.01"},{"price":"12.01698","size":"0.01"},{"price":"12.22806","size":"0.01"},{"price":"12.43835","size":"0.01"},{"price":"12.64786","size":"0.01"},{"price":"13.06456","size":"0.01"},{"price":"13.27176","size":"0.01"},{"price":"13.47819","size":"0.01"},{"price":"13.68387","size":"0.01"},{"price":"13.88881","size":"0.01"},{"price":"14.09300","size":"0.01"},{"price":"14.49920","size":"0.01"},{"price":"14.70122","size":"0.01"},{"price":"14.90253","size":"0.01"},{"price":"15.00000","size":"10.29"},{"price":"16.00000","size":"107.44"},{"price":"20.00000","size":"5.23"},{"price":"36.01020","size":"5.39"},{"price":"39.78490","size":"12.94"},{"price":"42.21047","size":"1.00"},{"price":"65.00000","size":"1.44"},{"price":"80.00000","size":"1.00"},{"price":"380.67007","size":"1.62"},{"price":"10000.00000","size":"2.33"},{"price":"20900.00000","size":"2.33"},{"price":"27000.00000","size":"2.33"},{"price":"40000.00000","size":"2.00"},{"price":"64999.99998","size":"0.28"},{"price":"65000.00000","size":"0.01"},{"price":"100000.00000","size":"0.35"}],"bid":[{"price":"4.60171","size":"0.05"},{"price":"4.57976","size":"0.05"},{"price":"4.55790","size":"0.05"},{"price":"4.55025","size":"570.65"},{"price":"4.54625","size":"902.75"},{"price":"4.54113","size":"1196.81"},{"price":"4.53616","size":"0.05"},{"price":"4.53422","size":"2.63"},{"price":"4.53200","size":"1626.22"},{"price":"4.52427","size":"2203.89"},{"price":"4.51652","size":"2740.00"},{"price":"4.51451","size":"0.05"},{"price":"4.50456","size":"4091.22"},{"price":"4.49297","size":"0.05"},{"price":"4.48680","size":"1661.53"},{"price":"4.47153","size":"0.05"},{"price":"4.45020","size":"0.05"},{"price":"4.42897","size":"0.06"},{"price":"4.40783","size":"0.06"},{"price":"4.38680","size":"0.06"},{"price":"4.36587","size":"0.06"},{"price":"4.34504","size":"0.06"},{"price":"4.32431","size":"0.06"},{"price":"4.30367","size":"0.06"},{"price":"4.28314","size":"0.06"},{"price":"4.26270","size":"0.06"},{"price":"4.24236","size":"0.06"},{"price":"4.22000","size":"10.00"},{"price":"4.20059","size":"133.44"},{"price":"4.18227","size":"3003.49"},{"price":"4.14568","size":"52528.13"},{"price":"4.12947","size":"83693.54"},{"price":"4.10552","size":"1937.75"},{"price":"4.05510","size":"56368.55"},{"price":"4.05258","size":"40622.04"},{"price":"4.01981","size":"10432.35"},{"price":"3.99901","size":"3130.29"},{"price":"3.95045","size":"10472.30"},{"price":"3.93633","size":"5390.76"},{"price":"3.92996","size":"862.01"},{"price":"3.89638","size":"1081.52"},{"price":"3.87406","size":"7175.70"},{"price":"3.81992","size":"768.89"},{"price":"3.81725","size":"21151.24"},{"price":"3.79209","size":"1345.73"},{"price":"3.75714","size":"1502.78"},{"price":"3.73820","size":"13690.14"},{"price":"3.71219","size":"6601.52"},{"price":"3.68446","size":"529.51"},{"price":"3.66010","size":"9338.91"},{"price":"3.63140","size":"1029.91"},{"price":"3.60000","size":"13.98"},{"price":"3.59825","size":"1220.42"},{"price":"3.58153","size":"1127.76"},{"price":"3.53109","size":"15937.93"},{"price":"3.52181","size":"31085.92"},{"price":"3.51544","size":"38748.89"},{"price":"3.47540","size":"17693.28"},{"price":"3.44290","size":"21008.14"},{"price":"3.39826","size":"3973.25"},{"price":"3.39541","size":"1621.03"},{"price":"3.37622","size":"837.67"},{"price":"3.35692","size":"1.00"},{"price":"3.33510","size":"2296.94"},{"price":"3.29530","size":"4487.79"},{"price":"3.26779","size":"2729.70"},{"price":"3.24445","size":"59.28"},{"price":"3.23523","size":"2290.68"},{"price":"3.22598","size":"175.17"},{"price":"3.21173","size":"18325.81"},{"price":"3.20000","size":"4.30"},{"price":"3.19095","size":"4131.92"},{"price":"3.15904","size":"418.75"},{"price":"3.13299","size":"587.86"},{"price":"3.10775","size":"10729.22"},{"price":"3.10001","size":"1.00"},{"price":"3.08119","size":"6275.58"},{"price":"3.06178","size":"23316.29"},{"price":"3.03025","size":"13994.84"},{"price":"3.00490","size":"528.05"},{"price":"3.00000","size":"10.00"},{"price":"2.97935","size":"9820.76"},{"price":"2.95698","size":"385.88"},{"price":"2.92956","size":"837.87"},{"price":"2.90529","size":"370.16"},{"price":"2.87422","size":"15409.81"},{"price":"2.84921","size":"1909.60"},{"price":"2.82912","size":"1302.52"},{"price":"2.80016","size":"2230.13"},{"price":"2.80000","size":"150.00"},{"price":"2.77093","size":"21451.93"},{"price":"2.74624","size":"2758.05"},{"price":"2.72428","size":"5367.42"},{"price":"2.69683","size":"1939.85"},{"price":"2.67084","size":"9711.32"},{"price":"2.64454","size":"1286.90"},{"price":"2.61938","size":"1559.31"},{"price":"2.59424","size":"2205.10"},{"price":"2.56696","size":"5537.40"},{"price":"2.54308","size":"8080.11"},{"price":"2.51419","size":"17429.81"},{"price":"2.49227","size":"1287.75"},{"price":"2.46242","size":"4382.33"},{"price":"2.43411","size":"526.92"},{"price":"2.41878","size":"0.04"},{"price":"2.41457","size":"13869.45"},{"price":"2.38303","size":"9082.44"},{"price":"2.37725","size":"0.30"},{"price":"2.36120","size":"23196.84"},{"price":"2.33752","size":"348.69"},{"price":"2.33572","size":"0.31"},{"price":"2.31070","size":"4939.24"},{"price":"2.30431","size":"0.01"},{"price":"2.29419","size":"0.30"},{"price":"2.28149","size":"4268.56"},{"price":"2.28001","size":"0.43"},{"price":"2.28000","size":"19.68"},{"price":"2.25962","size":"10186.71"},{"price":"2.25266","size":"0.30"},{"price":"2.23237","size":"10522.43"},{"price":"2.21113","size":"0.31"},{"price":"2.20194","size":"292.00"},{"price":"2.17665","size":"16801.51"},{"price":"2.16960","size":"0.30"},{"price":"2.14983","size":"18361.26"},{"price":"2.12807","size":"0.30"},{"price":"2.12401","size":"13838.73"},{"price":"2.10013","size":"19689.66"},{"price":"2.08654","size":"0.31"},{"price":"2.07274","size":"6420.96"},{"price":"2.05355","size":"7080.23"},{"price":"2.04500","size":"0.30"},{"price":"2.02659","size":"808.97"},{"price":"2.00347","size":"0.30"},{"price":"2.00000","size":"5.00"},{"price":"1.99289","size":"11786.36"},{"price":"1.97053","size":"305.53"},{"price":"1.96194","size":"0.31"},{"price":"1.93822","size":"482.27"},{"price":"1.92041","size":"0.30"},{"price":"1.91579","size":"3661.57"},{"price":"1.89954","size":"294.61"},{"price":"1.87888","size":"0.30"},{"price":"1.86749","size":"4073.59"},{"price":"1.83965","size":"5228.63"},{"price":"1.83735","size":"0.31"},{"price":"1.79582","size":"0.30"},{"price":"1.78257","size":"12657.45"},{"price":"1.76436","size":"13736.76"},{"price":"1.76152","size":"2959.28"},{"price":"1.75429","size":"0.30"},{"price":"1.73897","size":"501.78"},{"price":"1.71354","size":"2193.56"},{"price":"1.71276","size":"0.31"},{"price":"1.67123","size":"0.30"},{"price":"1.66098","size":"16981.58"},{"price":"1.63076","size":"1687.97"},{"price":"1.62970","size":"0.30"},{"price":"1.60963","size":"3201.74"},{"price":"1.58817","size":"0.31"},{"price":"1.57970","size":"12603.93"},{"price":"1.55630","size":"5890.22"},{"price":"1.54664","size":"0.30"},{"price":"1.50511","size":"0.30"},{"price":"1.46358","size":"0.31"},{"price":"1.42205","size":"0.30"},{"price":"1.38052","size":"0.30"},{"price":"1.33898","size":"0.31"},{"price":"1.29745","size":"0.30"},{"price":"1.25592","size":"0.30"},{"price":"1.21439","size":"0.31"},{"price":"1.17286","size":"0.30"},{"price":"1.13133","size":"0.30"},{"price":"1.08980","size":"0.31"},{"price":"1.04827","size":"0.30"},{"price":"1.00674","size":"0.30"},{"price":"1.00011","size":"0.99"},{"price":"1.00000","size":"6.00"},{"price":"0.96521","size":"0.31"},{"price":"0.92368","size":"0.30"},{"price":"0.88215","size":"0.30"},{"price":"0.84062","size":"0.31"},{"price":"0.79909","size":"0.30"},{"price":"0.75756","size":"0.30"},{"price":"0.71603","size":"0.31"},{"price":"0.70001","size":"1.42"},{"price":"0.67449","size":"0.30"},{"price":"0.63296","size":"0.30"},{"price":"0.59143","size":"0.31"},{"price":"0.54990","size":"0.30"},{"price":"0.50837","size":"50.48"},{"price":"0.50001","size":"1.99"},{"price":"0.50000","size":"20.00"},{"price":"0.46684","size":"0.31"},{"price":"0.42531","size":"0.30"},{"price":"0.38378","size":"0.30"},{"price":"0.34225","size":"0.31"},{"price":"0.30073","size":"7.35"},{"price":"0.30072","size":"33.55"},{"price":"0.25920","size":"38.58"},{"price":"0.25919","size":"0.30"},{"price":"0.21768","size":"45.93"},{"price":"0.21766","size":"0.31"},{"price":"0.17616","size":"20.92"},{"price":"0.17615","size":"56.76"},{"price":"0.17613","size":"0.30"},{"price":"0.13462","size":"74.28"},{"price":"0.13461","size":"7.42"},{"price":"0.13460","size":"0.30"},{"price":"0.12002","size":"83.31"},{"price":"0.12001","size":"8.33"},{"price":"0.11515","size":"86.84"},{"price":"0.11511","size":"8.68"},{"price":"0.10515","size":"95.10"},{"price":"0.10511","size":"9.51"},{"price":"0.10501","size":"485.66"},{"price":"0.10500","size":"2000.00"},{"price":"0.10000","size":"100.00"},{"price":"0.09308","size":"53.71"},{"price":"0.09307","size":"0.31"},{"price":"0.05157","size":"78.60"},{"price":"0.05156","size":"96.97"},{"price":"0.05155","size":"19.39"},{"price":"0.05154","size":"0.30"},{"price":"0.02022","size":"247.27"},{"price":"0.01015","size":"492.61"},{"price":"0.01013","size":"98.71"},{"price":"0.01012","size":"520.47"},{"price":"0.01000","size":"100.30"},{"price":"0.00725","size":"137.93"},{"price":"0.00658","size":"151.97"},{"price":"0.00515","size":"194.17"},{"price":"0.00458","size":"218.34"},{"price":"0.00425","size":"235.29"},{"price":"0.00423","size":"236.40"},{"price":"0.00321","size":"311.52"},{"price":"0.00210","size":"476.19"},{"price":"0.00111","size":"3603.60"},{"price":"0.00109","size":"917.43"},{"price":"0.00108","size":"925.92"},{"price":"0.00107","size":"47661.67"},{"price":"0.00101","size":"990.09"},{"price":"0.00100","size":"7000.00"},{"price":"0.00050","size":"2000.00"},{"price":"0.00032","size":"3125.00"},{"price":"0.00020","size":"5000.00"},{"price":"0.00010","size":"10000.00"},{"price":"0.00006","size":"16633.32"},{"price":"0.00005","size":"20000.00"},{"price":"0.00003","size":"66666.66"},{"price":"0.00002","size":"100000.00"},{"price":"0.00001","size":"164237.26"}],"sequence":7132736,"timestamp":"2021-04-17T16:38:32.461Z","symbol":"DODOUSD"}}
1618677512.98963: {"jsonrpc":"2.0","method":"updateOrderbook","params":{"ask":[],"bid":[{"price":"0.00015743","size":"9.55"},{"price":"0.00015721","size":"0"}],"sequence":18307655,"timestamp":"2021-04-17T16:38:32.565Z","symbol":"OMGBTC"}}
1618677512.989707: {"jsonrpc":"2.0","method":"updateOrderbook","params":{"ask":[{"price":"6.07537","size":"1.00"},{"price":"6.07670","size":"0"}],"bid":[{"price":"4.55025","size":"0"},{"price":"4.54986","size":"570.65"},{"price":"3.35692","size":"0"},{"price":"3.35618","size":"1.00"}],"sequence":7132737,"timestamp":"2021-04-17T16:38:32.539Z","symbol":"DODOUSD"}}
1618677512.9897869: {"jsonrpc":"2.0","method":"updateOrderbook","params":{"ask":[{"price":"0.00012945","size":"0"},{"price":"0.00012946","size":"3.00"}],"bid":[{"price":"0.00007524","size":"0"}],"sequence":5856017,"timestamp":"2021-04-17T16:38:32.611Z","symbol":"DODOBTC"}}
1618677512.989873: {"jsonrpc":"2.0","method":"updateOrderbook","params":{"ask":[{"price":"0.00025519","size":"7870.9"},{"price":"0.00025529","size":"0"}],"bid":[],"sequence":9316092,"timestamp":"2021-04-17T16:38:32.530Z","symbol":"XLMETH"}}
1618677512.9899242: {"jsonrpc":"2.0","method":"updateOrderbook","params":{"ask":[],"bid":[{"price":"0.00015752","size":"160.92"},{"price":"0.00015749","size":"0"},{"price":"0.00015740","size":"170.13"},{"price":"0.00015737","size":"0"},{"price":"0.00015560","size":"0"},{"price":"0.00014648","size":"4795.76"},{"price":"0.00014643","size":"0"},{"price":"0.00014629","size":"5774.25"},{"price":"0.00014622","size":"0"},{"price":"0.00014613","size":"4864.84"},{"price":"0.00014606","size":"0"},{"price":"0.00014593","size":"4962.08"},{"price":"0.00014588","size":"0"}],"sequence":18307656,"timestamp":"2021-04-17T16:38:32.718Z","symbol":"OMGBTC"}}
1618677512.990029: {"jsonrpc":"2.0","method":"updateOrderbook","params":{"ask":[{"price":"0.001386461","size":"0"},{"price":"0.001386945","size":"49151"}],"bid":[],"sequence":5053508,"timestamp":"2021-04-17T16:38:32.718Z","symbol":"ADABCH"}}
1618677512.9900732: {"jsonrpc":"2.0","method":"updateOrderbook","params":{"ask":[{"price":"0.00015841","size":"0"},{"price":"0.00015848","size":"149.59"}],"bid":[{"price":"0.00015526","size":"185.73"}],"sequence":18307657,"timestamp":"2021-04-17T16:38:32.756Z","symbol":"OMGBTC"}}
1618677512.990124: {"jsonrpc":"2.0","method":"updateOrderbook","params":{"ask":[{"price":"0.00026796","size":"56304.5"},{"price":"0.00026804","size":"0"}],"bid":[{"price":"0.00025410","size":"0"},{"price":"0.00025397","size":"5900.0"},{"price":"0.00025226","size":"38.8"},{"price":"0.00025220","size":"0"}],"sequence":9316093,"timestamp":"2021-04-17T16:38:32.794Z","symbol":"XLMETH"}}
1618677512.990217: {"jsonrpc":"2.0","method":"updateOrderbook","params":{"ask":[{"price":"0.00015955","size":"4402.08"},{"price":"0.00015969","size":"0"},{"price":"0.00015992","size":"5617.94"},{"price":"0.00016164","size":"0"}],"bid":[{"price":"0.00015736","size":"468.10"},{"price":"0.00015718","size":"1394.00"},{"price":"0.00015701","size":"0"},{"price":"0.00015690","size":"1821.71"},{"price":"0.00015662","size":"0"},{"price":"0.00015644","size":"2504.10"},{"price":"0.00015635","size":"0"}],"sequence":18307658,"timestamp":"2021-04-17T16:38:32.908Z","symbol":"OMGBTC"}}
1618677513.064847: {"jsonrpc":"2.0","method":"updateOrderbook","params":{"ask":[{"price":"0.00015787","size":"0"},{"price":"0.00015792","size":"0"},{"price":"0.00015794","size":"72.33"},{"price":"0.00015800","size":"42.78"}],"bid":[{"price":"0.00015749","size":"9.55"},{"price":"0.00015743","size":"0"},{"price":"0.00015735","size":"39.20"},{"price":"0.00015719","size":"1743.82"},{"price":"0.00015718","size":"0"},{"price":"0.00015698","size":"1504.32"},{"price":"0.00015690","size":"0"},{"price":"0.00015659","size":"1821.71"},{"price":"0.00015644","size":"0"},{"price":"0.00015635","size":"2504.10"}],"sequence":18307659,"timestamp":"2021-04-17T16:38:32.964Z","symbol":"OMGBTC"}}
1618677513.07411: {"jsonrpc":"2.0","method":"updateOrderbook","params":{"ask":[{"price":"0.001319853","size":"0"},{"price":"0.001320261","size":"4338"},{"price":"0.001355049","size":"0"},{"price":"0.001355550","size":"58712"},{"price":"0.001361158","size":"0"},{"price":"0.001361602","size":"48908"},{"price":"0.001366766","size":"0"},{"price":"0.001367163","size":"53172"},{"price":"0.001377169","size":"0"},{"price":"0.001377596","size":"54827"},{"price":"0.001381918","size":"0"},{"price":"0.001382395","size":"49524"}],"bid":[{"price":"0.001310920","size":"0"},{"price":"0.001310475","size":"520"},{"price":"0.001308993","size":"0"},{"price":"0.001308494","size":"1735"}],"sequence":5053509,"timestamp":"2021-04-17T16:38:32.993Z","symbol":"ADABCH"}}
1618677513.0784562: {"jsonrpc":"2.0","method":"updateOrderbook","params":{"ask":[{"price":"0.0167412","size":"72.92"}],"bid":[],"sequence":6928563,"timestamp":"2021-04-17T16:38:32.996Z","symbol":"ETCETH"}}
1618677513.150363: {"jsonrpc":"2.0","method":"updateOrderbook","params":{"ask":[{"price":"0.00015787","size":"42.78"},{"price":"0.00015794","size":"0"},{"price":"0.00015797","size":"72.33"},{"price":"0.00015800","size":"0"},{"price":"0.00015802","size":"0"},{"price":"0.00015807","size":"929.78"},{"price":"0.00015812","size":"0"},{"price":"0.00015817","size":"550.49"},{"price":"0.00015832","size":"0"},{"price":"0.00015836","size":"0"},{"price":"0.00015842","size":"112.21"},{"price":"0.00015846","size":"112.89"},{"price":"0.00015865","size":"0"},{"price":"0.00015870","size":"0"},{"price":"0.00015875","size":"2373.24"},{"price":"0.00015880","size":"227.54"}],"bid":[{"price":"0.00015749","size":"0"},{"price":"0.00015743","size":"9.55"}],"sequence":18307660,"timestamp":"2021-04-17T16:38:33.116Z","symbol":"OMGBTC"}}
1618677513.269022: {"jsonrpc":"2.0","method":"updateOrderbook","params":{"ask":[],"bid":[{"price":"0.00006236","size":"19596.73"},{"price":"0.00006232","size":"0"},{"price":"0.00006089","size":"20241.70"},{"price":"0.00006086","size":"0"}],"sequence":5856018,"timestamp":"2021-04-17T16:38:33.224Z","symbol":"DODOBTC"}}
1618677513.276211: {"jsonrpc":"2.0","method":"updateOrderbook","params":{"ask":[{"price":"0.001315727","size":"0"},{"price":"0.001316239","size":"520"}],"bid":[],"sequence":5053510,"timestamp":"2021-04-17T16:38:33.133Z","symbol":"ADABCH"}}
1618677513.35452: {"jsonrpc":"2.0","method":"updateOrderbook","params":{"ask":[{"price":"0.00015867","size":"633.98"},{"price":"0.00015876","size":"0"}],"bid":[{"price":"0.00015736","size":"19.60"},{"price":"0.00015707","size":"448.50"},{"price":"0.00015675","size":"162.11"},{"price":"0.00015672","size":"523.16"}],"sequence":18307661,"timestamp":"2021-04-17T16:38:33.305Z","symbol":"OMGBTC"}}
1618677513.45427: {"jsonrpc":"2.0","method":"updateOrderbook","params":{"ask":[],"bid":[{"price":"0.00015743","size":"0"},{"price":"0.00015720","size":"9.55"},{"price":"0.00014772","size":"5673.49"},{"price":"0.00014767","size":"0"}],"sequence":18307662,"timestamp":"2021-04-17T16:38:33.419Z","symbol":"OMGBTC"}}
1618677513.467041: {"jsonrpc":"2.0","method":"updateOrderbook","params":{"ask":[{"price":"0.00025561","size":"0"},{"price":"0.00025589","size":"8.4"}],"bid":[],"sequence":9316094,"timestamp":"2021-04-17T16:38:33.392Z","symbol":"XLMETH"}}
1618677513.555585: {"jsonrpc":"2.0","method":"updateOrderbook","params":{"ask":[{"price":"0.00015796","size":"72.33"},{"price":"0.00015797","size":"0"},{"price":"0.00015824","size":"0"},{"price":"0.00015828","size":"528.19"},{"price":"0.00015839","size":"0"},{"price":"0.00015842","size":"537.17"},{"price":"0.00015867","size":"0"},{"price":"0.00015874","size":"633.98"}],"bid":[{"price":"0.00015729","size":"448.50"},{"price":"0.00015707","size":"0"},{"price":"0.00015676","size":"523.16"},{"price":"0.00015672","size":"0"}],"sequence":18307663,"timestamp":"2021-04-17T16:38:33.506Z","symbol":"OMGBTC"}}
1618677513.555917: {"jsonrpc":"2.0","method":"updateOrderbook","params":{"ask":[{"price":"5.57225","size":"48.76"},{"price":"5.57470","size":"0"}],"bid":[],"sequence":7132738,"timestamp":"2021-04-17T16:38:33.454Z","symbol":"DODOUSD"}}
1618677513.5614562: {"jsonrpc":"2.0","method":"updateOrderbook","params":{"ask":[],"bid":[{"price":"0.00007524","size":"0.05"}],"sequence":5856019,"timestamp":"2021-04-17T16:38:33.469Z","symbol":"DODOBTC"}}
1618677513.6584058: {"jsonrpc":"2.0","method":"updateOrderbook","params":{"ask":[],"bid":[{"price":"0.00015749","size":"200.00"},{"price":"0.00015739","size":"200.00"},{"price":"0.00015736","size":"29.15"},{"price":"0.00015734","size":"1021.82"},{"price":"0.00015720","size":"0"},{"price":"0.00015719","size":"780.80"}],"sequence":18307664,"timestamp":"2021-04-17T16:38:33.570Z","symbol":"OMGBTC"}}
1618677513.667103: {"jsonrpc":"2.0","method":"updateOrderbook","params":{"ask":[],"bid":[{"price":"0.00007524","size":"0"}],"sequence":5856020,"timestamp":"2021-04-17T16:38:33.602Z","symbol":"DODOBTC"}}
1618677513.75592: {"jsonrpc":"2.0","method":"updateOrderbook","params":{"ask":[{"price":"0.00015787","size":"0"},{"price":"0.00015792","size":"42.78"}],"bid":[{"price":"0.00015751","size":"67.05"},{"price":"0.00015748","size":"0"},{"price":"0.00015743","size":"9.55"},{"price":"0.00015736","size":"19.60"},{"price":"0.00015734","size":"58.80"},{"price":"0.00015721","size":"963.02"}],"sequence":18307665,"timestamp":"2021-04-17T16:38:33.692Z","symbol":"OMGBTC"}}
1618677513.8576589: {"jsonrpc":"2.0","method":"updateOrderbook","params":{"ask":[{"price":"0.00015824","size":"528.19"},{"price":"0.00015828","size":"0"},{"price":"0.00015839","size":"424.96"},{"price":"0.00015842","size":"112.21"}],"bid":[{"price":"0.00015743","size":"0"},{"price":"0.00015736","size":"29.15"}],"sequence":18307666,"timestamp":"2021-04-17T16:38:33.810Z","symbol":"OMGBTC"}}
1618677513.857926: {"jsonrpc":"2.0","method":"updateOrderbook","params":{"ask":[{"price":"6.02539","size":"1.00"},{"price":"6.07537","size":"0"}],"bid":[{"price":"3.40616","size":"1.00"},{"price":"3.35618","size":"0"}],"sequence":7132739,"timestamp":"2021-04-17T16:38:33.748Z","symbol":"DODOUSD"}}
1618677513.867384: {"jsonrpc":"2.0","method":"updateOrderbook","params":{"ask":[],"bid":[{"price":"0.00025424","size":"1181.2"},{"price":"0.00025409","size":"0"}],"sequence":9316095,"timestamp":"2021-04-17T16:38:33.796Z","symbol":"XLMETH"}}
1618677514.051811: {"jsonrpc":"2.0","method":"updateOrderbook","params":{"ask":[],"bid":[{"price":"4.55058","size":"570.65"},{"price":"4.54986","size":"0"},{"price":"4.54754","size":"902.75"},{"price":"4.54625","size":"0"},{"price":"4.54295","size":"1196.81"},{"price":"4.54113","size":"0"},{"price":"4.53361","size":"1626.22"},{"price":"4.53200","size":"0"},{"price":"4.50629","size":"4091.22"},{"price":"4.50456","size":"0"}],"sequence":7132740,"timestamp":"2021-04-17T16:38:33.977Z","symbol":"DODOUSD"}}
1618677514.0619369: {"jsonrpc":"2.0","method":"updateOrderbook","params":{"ask":[],"bid":[{"price":"0.00007498","size":"1734.72"},{"price":"0.00007494","size":"3.65"}],"sequence":5856021,"timestamp":"2021-04-17T16:38:34.021Z","symbol":"DODOBTC"}}
1618677514.154321: {"jsonrpc":"2.0","method":"updateOrderbook","params":{"ask":[],"bid":[{"price":"0.00015749","size":"0"},{"price":"0.00015741","size":"200.00"}],"sequence":18307667,"timestamp":"2021-04-17T16:38:34.075Z","symbol":"OMGBTC"}}
1618677514.162743: {"jsonrpc":"2.0","method":"updateOrderbook","params":{"ask":[],"bid":[{"price":"0.00006717","size":"20658.13"},{"price":"0.00006714","size":"0"}],"sequence":5856022,"timestamp":"2021-04-17T16:38:34.109Z","symbol":"DODOBTC"}}
1618677514.172529: {"jsonrpc":"2.0","method":"updateOrderbook","params":{"ask":[{"price":"0.0167413","size":"0"},{"price":"0.0167548","size":"786.06"},{"price":"0.0168019","size":"0"},{"price":"0.0168158","size":"1200.63"},{"price":"0.0168872","size":"0"},{"price":"0.0169036","size":"2146.28"}],"bid":[],"sequence":6928564,"timestamp":"2021-04-17T16:38:34.057Z","symbol":"ETCETH"}}
1618677514.259742: {"jsonrpc":"2.0","method":"updateOrderbook","params":{"ask":[{"price":"0.00015787","size":"42.78"},{"price":"0.00015792","size":"0"},{"price":"0.00015836","size":"112.21"},{"price":"0.00015842","size":"0"},{"price":"0.00017792","size":"0"},{"price":"0.00017857","size":"2362.68"}],"bid":[{"price":"0.00015744","size":"246.65"},{"price":"0.00015743","size":"9.55"},{"price":"0.00015742","size":"0"},{"price":"0.00015741","size":"648.50"},{"price":"0.00015736","size":"19.60"},{"price":"0.00015729","size":"0"},{"price":"0.00015694","size":"679.14"},{"price":"0.00015689","size":"247.96"}],"sequence":18307668,"timestamp":"2021-04-17T16:38:34.209Z","symbol":"OMGBTC"}}
1618677514.269043: {"jsonrpc":"2.0","method":"updateOrderbook","params":{"ask":[],"bid":[{"price":"0.00025363","size":"0"},{"price":"0.00025355","size":"7874.9"}],"sequence":9316096,"timestamp":"2021-04-17T16:38:34.129Z","symbol":"XLMETH"}}
1618677514.354368: {"jsonrpc":"2.0","method":"updateOrderbook","params":{"ask":[{"price":"0.00015787","size":"0"},{"price":"0.00015792","size":"42.78"}],"bid":[{"price":"0.00015745","size":"9.55"},{"price":"0.00015743","size":"0"}],"sequence":18307669,"timestamp":"2021-04-17T16:38:34.288Z","symbol":"OMGBTC"}}
1618677514.354677: {"jsonrpc":"2.0","method":"updateOrderbook","params":{"ask":[],"bid":[{"price":"4.54754","size":"0"},{"price":"4.54702","size":"902.75"},{"price":"4.54295","size":"0"},{"price":"4.54194","size":"1196.81"},{"price":"4.53361","size":"0"},{"price":"4.53257","size":"1626.22"}],"sequence":7132741,"timestamp":"2021-04-17T16:38:34.314Z","symbol":"DODOUSD"}}
1618677514.381901: {"jsonrpc":"2.0","method":"updateOrderbook","params":{"ask":[{"price":"0.00025482","size":"5900.0"},{"price":"0.00025483","size":"3937.4"},{"price":"0.00025503","size":"0"},{"price":"0.00025504","size":"0"}],"bid":[],"sequence":9316097,"timestamp":"2021-04-17T16:38:34.319Z","symbol":"XLMETH"}}
1618677514.4522188: {"jsonrpc":"2.0","method":"updateOrderbook","params":{"ask":[],"bid":[{"price":"0.00015737","size":"963.02"},{"price":"0.00015721","size":"0"}],"sequence":18307670,"timestamp":"2021-04-17T16:38:34.379Z","symbol":"OMGBTC"}}
1618677514.463265: {"jsonrpc":"2.0","method":"updateOrderbook","params":{"ask":[],"bid":[{"price":"0.000000045","size":"50631.6"},{"price":"0.000000044","size":"10.0"}],"sequence":651384,"timestamp":"2021-04-17T16:38:34.406Z","symbol":"HUBBTC"}}
1618677514.4696882: {"jsonrpc":"2.0","method":"updateOrderbook","params":{"ask":[{"price":"0.00025561","size":"8.4"},{"price":"0.00025589","size":"0"}],"bid":[],"sequence":9316098,"timestamp":"2021-04-17T16:38:34.424Z","symbol":"XLMETH"}}
1618677514.561654: {"jsonrpc":"2.0","method":"updateOrderbook","params":{"ask":[{"price":"0.00015796","size":"0"},{"price":"0.00015797","size":"72.33"}],"bid":[{"price":"0.00015752","size":"0.01"},{"price":"0.00015749","size":"160.91"},{"price":"0.00015740","size":"0"},{"price":"0.00015737","size":"1133.15"},{"price":"0.00015689","size":"92.21"},{"price":"0.00015680","size":"632.89"},{"price":"0.00015670","size":"226.36"},{"price":"0.00015661","size":"827.97"},{"price":"0.00015660","size":"216.48"},{"price":"0.00015645","size":"265.47"}],"sequence":18307671,"timestamp":"2021-04-17T16:38:34.510Z","symbol":"OMGBTC"}}
1618677514.663886: {"jsonrpc":"2.0","method":"updateOrderbook","params":{"ask":[{"price":"0.00017807","size":"2362.68"},{"price":"0.00017857","size":"0"}],"bid":[{"price":"0.00015751","size":"0"},{"price":"0.00015749","size":"227.96"},{"price":"0.00015642","size":"768.35"},{"price":"0.00015637","size":"0.01"}],"sequence":18307672,"timestamp":"2021-04-17T16:38:34.615Z","symbol":"OMGBTC"}}
1618677514.7553432: {"jsonrpc":"2.0","method":"updateOrderbook","params":{"ask":[],"bid":[{"price":"0.00015750","size":"9.55"},{"price":"0.00015745","size":"0"}],"sequence":18307673,"timestamp":"2021-04-17T16:38:34.662Z","symbol":"OMGBTC"}}
1618677514.765086: {"jsonrpc":"2.0","method":"updateOrderbook","params":{"ask":[],"bid":[{"price":"0.00007467","size":"2667.37"},{"price":"0.00007464","size":"0"}],"sequence":5856023,"timestamp":"2021-04-17T16:38:34.688Z","symbol":"DODOBTC"}}
1618677514.765297: {"jsonrpc":"2.0","method":"updateOrderbook","params":{"ask":[],"bid":[{"price":"0.00023656","size":"81066.8"},{"price":"0.00023647","size":"0"}],"sequence":9316099,"timestamp":"2021-04-17T16:38:34.661Z","symbol":"XLMETH"}}
1618677514.850587: {"jsonrpc":"2.0","method":"updateOrderbook","params":{"ask":[],"bid":[{"price":"0.00015750","size":"209.55"},{"price":"0.00015741","size":"448.50"}],"sequence":18307674,"timestamp":"2021-04-17T16:38:34.733Z","symbol":"OMGBTC"}}
1618677514.966785: {"jsonrpc":"2.0","method":"updateOrderbook","params":{"ask":[{"price":"0.00015792","size":"0"},{"price":"0.00015796","size":"115.11"},{"price":"0.00015797","size":"0"},{"price":"0.00015949","size":"508.38"},{"price":"0.00015971","size":"722.10"}],"bid":[{"price":"0.00015752","size":"160.92"},{"price":"0.00015750","size":"200.00"},{"price":"0.00015749","size":"67.05"},{"price":"0.00015747","size":"170.13"},{"price":"0.00015745","size":"9.55"},{"price":"0.00015743","size":"100.65"},{"price":"0.00015742","size":"603.33"},{"price":"0.00015738","size":"0"},{"price":"0.00015737","size":"963.02"},{"price":"0.00015733","size":"0"},{"price":"0.00015728","size":"780.80"},{"price":"0.00015719","size":"0"},{"price":"0.00015713","size":"670.43"},{"price":"0.00015708","size":"110.32"},{"price":"0.00015698","size":"1394.00"}],"sequence":18307675,"timestamp":"2021-04-17T16:38:34.888Z","symbol":"OMGBTC"}}
1618677515.0738308: {"jsonrpc":"2.0","method":"updateOrderbook","params":{"ask":[{"price":"0.00015796","size":"72.33"},{"price":"0.00015800","size":"42.78"}],"bid":[{"price":"0.00015752","size":"0.01"},{"price":"0.00015749","size":"227.96"},{"price":"0.00015748","size":"9.55"},{"price":"0.00015747","size":"0"},{"price":"0.00015745","size":"0"},{"price":"0.00015743","size":"0"},{"price":"0.00015742","size":"0"},{"price":"0.00015741","size":"0"},{"price":"0.00015737","size":"773.46"},{"price":"0.00015733","size":"100.65"},{"price":"0.00015728","size":"0"},{"price":"0.00015725","size":"1411.52"},{"price":"0.00015719","size":"780.80"},{"price":"0.00015713","size":"0"},{"price":"0.00015708","size":"670.43"},{"price":"0.00015698","size":"1504.32"},{"price":"0.00015694","size":"0"},{"price":"0.00015689","size":"679.59"},{"price":"0.00015685","size":"91.76"},{"price":"0.00015677","size":"0"},{"price":"0.00015666","size":"151.30"},{"price":"0.00015661","size":"382.59"},{"price":"0.00015650","size":"445.38"}],"sequence":18307676,"timestamp":"2021-04-17T16:38:35.011Z","symbol":"OMGBTC"}}
1618677515.151142: {"jsonrpc":"2.0","method":"updateOrderbook","params":{"ask":[{"price":"0.00015792","size":"42.78"},{"price":"0.00015800","size":"0"}],"bid":[{"price":"0.00015748","size":"0"},{"price":"0.00015740","size":"9.55"}],"sequence":18307677,"timestamp":"2021-04-17T16:38:35.066Z","symbol":"OMGBTC"}}
1618677515.151389: {"jsonrpc":"2.0","method":"updateOrderbook","params":{"ask":[{"price":"6.02539","size":"0"},{"price":"6.02605","size":"1.00"}],"bid":[{"price":"4.54250","size":"1196.81"},{"price":"4.54194","size":"0"},{"price":"3.40653","size":"1.00"},{"price":"3.40616","size":"0"}],"sequence":7132742,"timestamp":"2021-04-17T16:38:35.088Z","symbol":"DODOUSD"}}
1618677515.357944: {"jsonrpc":"2.0","method":"updateOrderbook","params":{"ask":[{"price":"0.00015868","size":"633.98"},{"price":"0.00015874","size":"0"}],"bid":[],"sequence":18307678,"timestamp":"2021-04-17T16:38:35.269Z","symbol":"OMGBTC"}}
1618677515.366868: {"jsonrpc":"2.0","method":"updateOrderbook","params":{"ask":[],"bid":[{"price":"0.00006485","size":"18768.19"},{"price":"0.00006482","size":"0"}],"sequence":5856024,"timestamp":"2021-04-17T16:38:35.273Z","symbol":"DODOBTC"}}
1618677515.454319: {"jsonrpc":"2.0","method":"updateOrderbook","params":{"ask":[{"price":"0.00015802","size":"500.06"},{"price":"0.00015807","size":"429.72"},{"price":"0.00015812","size":"550.49"},{"price":"0.00015817","size":"0"},{"price":"0.00015836","size":"225.10"},{"price":"0.00015846","size":"0"},{"price":"0.00015865","size":"245.17"},{"price":"0.00015875","size":"2128.07"}],"bid":[],"sequence":18307679,"timestamp":"2021-04-17T16:38:35.331Z","symbol":"OMGBTC"}}
1618677515.4606888: {"jsonrpc":"2.0","method":"updateOrderbook","params":{"ask":[{"price":"0.00025482","size":"0"},{"price":"0.00025483","size":"0"},{"price":"0.00025491","size":"5900.0"},{"price":"0.00025492","size":"3937.4"},{"price":"0.00025561","size":"0"},{"price":"0.00025589","size":"8.4"}],"bid":[],"sequence":9316100,"timestamp":"2021-04-17T16:38:35.410Z","symbol":"XLMETH"}}
1618677515.463829: {"jsonrpc":"2.0","method":"updateOrderbook","params":{"ask":[],"bid":[{"price":"0.0149059","size":"785.75"},{"price":"0.0149002","size":"0"}],"sequence":6928565,"timestamp":"2021-04-17T16:38:35.338Z","symbol":"ETCETH"}}
1618677515.555111: {"jsonrpc":"2.0","method":"updateOrderbook","params":{"ask":[{"price":"0.00015787","size":"42.78"},{"price":"0.00015792","size":"0"}],"bid":[{"price":"0.00015740","size":"0"},{"price":"0.00015736","size":"29.15"}],"sequence":18307680,"timestamp":"2021-04-17T16:38:35.453Z","symbol":"OMGBTC"}}
1618677515.562428: {"jsonrpc":"2.0","method":"updateOrderbook","params":{"ask":[],"bid":[{"price":"0.00007524","size":"0.05"}],"sequence":5856025,"timestamp":"2021-04-17T16:38:35.514Z","symbol":"DODOBTC"}}
1618677515.6619022: {"jsonrpc":"2.0","method":"updateOrderbook","params":{"ask":[],"bid":[{"price":"0.00007524","size":"0"}],"sequence":5856026,"timestamp":"2021-04-17T16:38:35.529Z","symbol":"DODOBTC"}}
1618677515.672178: {"jsonrpc":"2.0","method":"updateOrderbook","params":{"ask":[{"price":"0.001347782","size":"0"},{"price":"0.001348238","size":"57535"}],"bid":[],"sequence":5053511,"timestamp":"2021-04-17T16:38:35.559Z","symbol":"ADABCH"}}
1618677515.7531571: {"jsonrpc":"2.0","method":"updateOrderbook","params":{"ask":[],"bid":[{"price":"0.00015740","size":"448.50"},{"price":"0.00015725","size":"963.02"}],"sequence":18307681,"timestamp":"2021-04-17T16:38:35.690Z","symbol":"OMGBTC"}}
1618677515.8812149: {"jsonrpc":"2.0","method":"updateOrderbook","params":{"ask":[{"price":"0.00015787","size":"0"},{"price":"0.00015792","size":"42.78"}],"bid":[{"price":"0.00015736","size":"19.60"},{"price":"0.00015734","size":"68.35"}],"sequence":18307682,"timestamp":"2021-04-17T16:38:35.768Z","symbol":"OMGBTC"}}
1618677515.954986: {"jsonrpc":"2.0","method":"updateOrderbook","params":{"ask":[],"bid":[{"price":"0.00015750","size":"0"},{"price":"0.00015741","size":"200.00"},{"price":"0.00015740","size":"0"},{"price":"0.00015734","size":"516.85"}],"sequence":18307683,"timestamp":"2021-04-17T16:38:35.886Z","symbol":"OMGBTC"}}
1618677515.955221: {"jsonrpc":"2.0","method":"updateOrderbook","params":{"ask":[],"bid":[{"price":"4.50629","size":"0"},{"price":"4.50399","size":"4091.22"}],"sequence":7132743,"timestamp":"2021-04-17T16:38:35.866Z","symbol":"DODOUSD"}}
1618677515.9657369: {"jsonrpc":"2.0","method":"updateOrderbook","params":{"ask":[{"price":"0.001336324","size":"0"},{"price":"0.001336722","size":"52325"}],"bid":[],"sequence":5053512,"timestamp":"2021-04-17T16:38:35.922Z","symbol":"ADABCH"}}
1618677516.057625: {"jsonrpc":"2.0","method":"updateOrderbook","params":{"ask":[{"price":"0.00015787","size":"42.78"},{"price":"0.00015792","size":"0"},{"price":"0.00015796","size":"0"},{"price":"0.00015797","size":"72.33"}],"bid":[{"price":"0.00015745","size":"9.55"},{"price":"0.00015742","size":"603.33"},{"price":"0.00015737","size":"170.13"},{"price":"0.00015736","size":"982.62"},{"price":"0.00015734","size":"507.30"},{"price":"0.00015733","size":"0"},{"price":"0.00015732","size":"100.65"},{"price":"0.00015725","size":"0"},{"price":"0.00015719","size":"0"},{"price":"0.00015718","size":"780.80"},{"price":"0.00015708","size":"0"},{"price":"0.00015706","size":"670.43"}],"sequence":18307684,"timestamp":"2021-04-17T16:38:36.007Z","symbol":"OMGBTC"}}
1618677516.0700989: {"jsonrpc":"2.0","method":"updateOrderbook","params":{"ask":[{"price":"0.001327433","size":"0"},{"price":"0.001327900","size":"51644"},{"price":"0.001332146","size":"0"},{"price":"0.001332668","size":"56575"},{"price":"0.001341659","size":"0"},{"price":"0.001342276","size":"56233"}],"bid":[{"price":"0.001311572","size":"520"},{"price":"0.001310475","size":"0"},{"price":"0.001309089","size":"1735"},{"price":"0.001308494","size":"0"}],"sequence":5053513,"timestamp":"2021-04-17T16:38:36.003Z","symbol":"ADABCH"}}
1618677516.1616561: {"jsonrpc":"2.0","method":"updateOrderbook","params":{"ask":[{"price":"0.00015787","size":"0"},{"price":"0.00015792","size":"42.78"},{"price":"0.00015937","size":"2.45"},{"price":"0.00015943","size":"0"}],"bid":[{"price":"0.00015750","size":"9.55"},{"price":"0.00015745","size":"0"},{"price":"0.00015734","size":"58.80"},{"price":"0.00015725","size":"448.50"},{"price":"0.00015710","size":"670.43"},{"price":"0.00015706","size":"0"},{"price":"0.00015694","size":"91.76"},{"price":"0.00015685","size":"0"},{"price":"0.00015675","size":"313.41"},{"price":"0.00015666","size":"0"}],"sequence":18307685,"timestamp":"2021-04-17T16:38:36.110Z","symbol":"OMGBTC"}}
1618677516.1737988: {"jsonrpc":"2.0","method":"updateOrderbook","params":{"ask":[{"price":"0.001348238","size":"0"},{"price":"0.001348637","size":"57535"}],"bid":[],"sequence":5053514,"timestamp":"2021-04-17T16:38:36.125Z","symbol":"ADABCH"}}
1618677516.174013: {"jsonrpc":"2.0","method":"updateOrderbook","params":{"ask":[{"price":"0.00025562","size":"0"},{"price":"0.00025574","size":"10000.0"}],"bid":[],"sequence":9316101,"timestamp":"2021-04-17T16:38:36.043Z","symbol":"XLMETH"}}
1618677516.269172: {"jsonrpc":"2.0","method":"updateOrderbook","params":{"ask":[],"bid":[{"price":"0.00015750","size":"0"},{"price":"0.00015745","size":"9.55"}],"sequence":18307686,"timestamp":"2021-04-17T16:38:36.155Z","symbol":"OMGBTC"}}
1618677516.269386: {"jsonrpc":"2.0","method":"updateOrderbook","params":{"ask":[],"bid":[{"price":"4.50570","size":"4091.22"},{"price":"4.50399","size":"0"}],"sequence":7132744,"timestamp":"2021-04-17T16:38:36.162Z","symbol":"DODOUSD"}}
1618677516.361469: {"jsonrpc":"2.0","method":"updateOrderbook","params":{"ask":[],"bid":[{"price":"0.00015732","size":"549.15"},{"price":"0.00015725","size":"0"},{"price":"0.00015723","size":"1394.00"},{"price":"0.00015698","size":"110.32"},{"price":"0.00015693","size":"1821.71"},{"price":"0.00015659","size":"0"}],"sequence":18307687,"timestamp":"2021-04-17T16:38:36.292Z","symbol":"OMGBTC"}}
1618677516.453282: {"jsonrpc":"2.0","method":"updateOrderbook","params":{"ask":[{"price":"0.00015796","size":"72.33"},{"price":"0.00015797","size":"0"}],"bid":[{"price":"0.00015750","size":"9.55"},{"price":"0.00015745","size":"0"}],"sequence":18307688,"timestamp":"2021-04-17T16:38:36.372Z","symbol":"OMGBTC"}}
1618677516.469252: {"jsonrpc":"2.0","method":"updateOrderbook","params":{"ask":[],"bid":[{"price":"0.001311572","size":"0"},{"price":"0.001311032","size":"520"}],"sequence":5053515,"timestamp":"2021-04-17T16:38:36.399Z","symbol":"ADABCH"}}
1618677516.469527: {"jsonrpc":"2.0","method":"updateOrderbook","params":{"ask":[{"price":"0.00025573","size":"8.4"},{"price":"0.00025589","size":"0"}],"bid":[],"sequence":9316102,"timestamp":"2021-04-17T16:38:36.394Z","symbol":"XLMETH"}}
1618677516.557169: {"jsonrpc":"2.0","method":"updateOrderbook","params":{"ask":[],"bid":[{"price":"0.00015741","size":"648.50"},{"price":"0.00015732","size":"100.65"},{"price":"0.00015700","size":"587.38"},{"price":"0.00015689","size":"92.21"}],"sequence":18307689,"timestamp":"2021-04-17T16:38:36.493Z","symbol":"OMGBTC"}}
1618677516.5619159: {"jsonrpc":"2.0","method":"updateOrderbook","params":{"ask":[],"bid":[{"price":"0.00007524","size":"0.05"}],"sequence":5856027,"timestamp":"2021-04-17T16:38:36.484Z","symbol":"DODOBTC"}}
1618677516.669433: {"jsonrpc":"2.0","method":"updateOrderbook","params":{"ask":[{"price":"0.00015937","size":"0"},{"price":"0.00015943","size":"2.45"}],"bid":[{"price":"0.00015694","size":"0"},{"price":"0.00015689","size":"183.97"},{"price":"0.00015645","size":"2769.57"},{"price":"0.00015635","size":"0"},{"price":"0.00015631","size":"3145.03"},{"price":"0.00015620","size":"1044.89"}],"sequence":18307690,"timestamp":"2021-04-17T16:38:36.615Z","symbol":"OMGBTC"}}
1618677516.6697118: {"jsonrpc":"2.0","method":"updateOrderbook","params":{"ask":[{"price":"4.61869","size":"0"},{"price":"4.62181","size":"8443.15"},{"price":"4.68122","size":"0"},{"price":"4.68443","size":"10836.10"}],"bid":[],"sequence":7132745,"timestamp":"2021-04-17T16:38:36.562Z","symbol":"DODOUSD"}}
1618677516.6771042: {"jsonrpc":"2.0","method":"updateOrderbook","params":{"ask":[],"bid":[{"price":"0.00007524","size":"0"}],"sequence":5856028,"timestamp":"2021-04-17T16:38:36.614Z","symbol":"DODOBTC"}}
1618677516.881749: {"jsonrpc":"2.0","method":"updateOrderbook","params":{"ask":[],"bid":[{"price":"0.001243214","size":"40326"},{"price":"0.001242497","size":"0"},{"price":"0.001236465","size":"44200"},{"price":"0.001235728","size":"0"},{"price":"0.001230640","size":"40497"},{"price":"0.001229974","size":"0"},{"price":"0.001225861","size":"37521"},{"price":"0.001225248","size":"0"}],"sequence":5053516,"timestamp":"2021-04-17T16:38:36.535Z","symbol":"ADABCH"}}
1618677516.882036: {"jsonrpc":"2.0","method":"updateOrderbook","params":{"ask":[{"price":"6.02605","size":"0"},{"price":"6.02804","size":"1.00"}],"bid":[{"price":"4.55277","size":"570.65"},{"price":"4.55058","size":"0"},{"price":"4.54935","size":"902.75"},{"price":"4.54702","size":"0"},{"price":"4.54416","size":"1196.81"},{"price":"4.54250","size":"0"},{"price":"4.53587","size":"1626.22"},{"price":"4.53257","size":"0"},{"price":"4.52644","size":"2203.89"},{"price":"4.52427","size":"0"},{"price":"4.51846","size":"2740.00"},{"price":"4.51652","size":"0"},{"price":"4.50941","size":"4091.22"},{"price":"4.50570","size":"0"},{"price":"4.48907","size":"1661.53"},{"price":"4.48680","size":"0"},{"price":"3.40766","size":"1.00"},{"price":"3.40653","size":"0"}],"sequence":7132746,"timestamp":"2021-04-17T16:38:36.721Z","symbol":"DODOUSD"}}
1618677516.882299: {"jsonrpc":"2.0","method":"updateOrderbook","params":{"ask":[],"bid":[{"price":"0.001294047","size":"40483"},{"price":"0.001293553","size":"0"},{"price":"0.001286335","size":"37612"},{"price":"0.001285932","size":"0"},{"price":"0.001261474","size":"37938"},{"price":"0.001261062","size":"0"}],"sequence":5053517,"timestamp":"2021-04-17T16:38:36.675Z","symbol":"ADABCH"}}
1618677516.882389: {"jsonrpc":"2.0","method":"updateOrderbook","params":{"ask":[{"price":"0.00025491","size":"0"}],"bid":[{"price":"0.00025397","size":"0"},{"price":"0.00025356","size":"5900.0"}],"sequence":9316103,"timestamp":"2021-04-17T16:38:36.691Z","symbol":"XLMETH"}}
1618677516.882462: {"jsonrpc":"2.0","method":"updateOrderbook","params":{"ask":[{"price":"6.02804","size":"0"},{"price":"6.03134","size":"1.00"}],"bid":[{"price":"4.55336","size":"570.65"},{"price":"4.55277","size":"0"},{"price":"3.40952","size":"1.00"},{"price":"3.40766","size":"0"}],"sequence":7132747,"timestamp":"2021-04-17T16:38:36.814Z","symbol":"DODOUSD"}}
1618677516.882997: {"jsonrpc":"2.0","method":"updateOrderbook","params":{"ask":[{"price":"0.00025491","size":"2900.0"},{"price":"0.00025518","size":"3000.0"},{"price":"0.00025519","size":"0"},{"price":"0.00025527","size":"7887.6"},{"price":"0.00026472","size":"0"},{"price":"0.00026481","size":"63541.2"}],"bid":[{"price":"0.00025397","size":"5900.0"},{"price":"0.00025356","size":"0"}],"sequence":9316104,"timestamp":"2021-04-17T16:38:36.749Z","symbol":"XLMETH"}}
1618677516.953093: {"jsonrpc":"2.0","method":"updateOrderbook","params":{"ask":[],"bid":[{"price":"0.00015568","size":"5478.09"},{"price":"0.00015525","size":"0"}],"sequence":18307691,"timestamp":"2021-04-17T16:38:36.925Z","symbol":"OMGBTC"}}
1618677516.953303: {"jsonrpc":"2.0","method":"updateOrderbook","params":{"ask":[],"bid":[{"price":"4.55493","size":"570.65"},{"price":"4.55336","size":"0"},{"price":"4.55320","size":"902.75"},{"price":"4.54968","size":"1196.81"},{"price":"4.54935","size":"0"},{"price":"4.54416","size":"0"},{"price":"4.54323","size":"1626.22"},{"price":"4.53587","size":"0"},{"price":"4.53263","size":"2203.89"},{"price":"4.52644","size":"0"},{"price":"4.52249","size":"2740.00"},{"price":"4.51846","size":"0"},{"price":"4.51239","size":"4091.22"},{"price":"4.50941","size":"0"}],"sequence":7132748,"timestamp":"2021-04-17T16:38:36.857Z","symbol":"DODOUSD"}}
1618677517.052191: {"jsonrpc":"2.0","method":"updateOrderbook","params":{"ask":[{"price":"6.02870","size":"1.00"},{"price":"6.03134","size":"0"}],"bid":[{"price":"4.55493","size":"0"},{"price":"4.55320","size":"0"},{"price":"4.55257","size":"570.65"},{"price":"4.54968","size":"0"},{"price":"4.54932","size":"902.75"},{"price":"4.54421","size":"1196.81"},{"price":"4.54323","size":"0"},{"price":"4.53590","size":"1626.22"},{"price":"4.53263","size":"0"},{"price":"4.52637","size":"2203.89"},{"price":"4.52249","size":"0"},{"price":"4.51817","size":"2740.00"},{"price":"4.51239","size":"0"},{"price":"4.50333","size":"4091.22"},{"price":"4.48907","size":"0"},{"price":"4.48703","size":"1661.53"},{"price":"3.40952","size":"0"},{"price":"3.40803","size":"1.00"}],"sequence":7132749,"timestamp":"2021-04-17T16:38:37.022Z","symbol":"DODOUSD"}}
1618677517.0581188: {"jsonrpc":"2.0","method":"updateOrderbook","params":{"ask":[],"bid":[{"price":"0.00007529","size":"133.36"},{"price":"0.00007523","size":"0.09"}],"sequence":5856029,"timestamp":"2021-04-17T16:38:37.013Z","symbol":"DODOBTC"}}
1618677517.070862: {"jsonrpc":"2.0","method":"updateOrderbook","params":{"ask":[{"price":"0.00025491","size":"5900.0"},{"price":"0.00025518","size":"0"}],"bid":[],"sequence":9316105,"timestamp":"2021-04-17T16:38:37.000Z","symbol":"XLMETH"}}
1618677517.1562822: {"jsonrpc":"2.0","method":"updateOrderbook","params":{"ask":[],"bid":[{"price":"4.52073","size":"2740.00"},{"price":"4.51817","size":"0"},{"price":"4.50827","size":"4091.22"},{"price":"4.50333","size":"0"}],"sequence":7132750,"timestamp":"2021-04-17T16:38:37.059Z","symbol":"DODOUSD"}}
1618677517.253407: {"jsonrpc":"2.0","method":"updateOrderbook","params":{"ask":[{"price":"0.00015796","size":"0"},{"price":"0.00015797","size":"72.33"}],"bid":[],"sequence":18307692,"timestamp":"2021-04-17T16:38:37.223Z","symbol":"OMGBTC"}}
1618677517.253563: {"jsonrpc":"2.0","method":"updateOrderbook","params":{"ask":[],"bid":[{"price":"4.52073","size":"0"},{"price":"4.51824","size":"2740.00"},{"price":"4.50827","size":"0"},{"price":"4.50431","size":"4091.22"}],"sequence":7132751,"timestamp":"2021-04-17T16:38:37.160Z","symbol":"DODOUSD"}}
1618677517.354101: {"jsonrpc":"2.0","method":"updateOrderbook","params":{"ask":[],"bid":[{"price":"0.00015694","size":"91.76"},{"price":"0.00015689","size":"92.21"},{"price":"0.00015666","size":"445.38"},{"price":"0.00015650","size":"0"},{"price":"0.00015560","size":"185.32"},{"price":"0.00015526","size":"0"}],"sequence":18307693,"timestamp":"2021-04-17T16:38:37.308Z","symbol":"OMGBTC"}}
1618677517.354364: {"jsonrpc":"2.0","method":"updateOrderbook","params":{"ask":[],"bid":[{"price":"4.51992","size":"2740.00"},{"price":"4.51824","size":"0"},{"price":"4.50835","size":"4091.22"},{"price":"4.50431","size":"0"}],"sequence":7132752,"timestamp":"2021-04-17T16:38:37.262Z","symbol":"DODOUSD"}}
1618677517.3804889: {"jsonrpc":"2.0","method":"updateOrderbook","params":{"ask":[],"bid":[{"price":"0.00025410","size":"2900.0"},{"price":"0.00025409","size":"3937.4"},{"price":"0.00025397","size":"0"},{"price":"0.00025396","size":"0"},{"price":"0.00025356","size":"3000.0"}],"sequence":9316106,"timestamp":"2021-04-17T16:38:37.309Z","symbol":"XLMETH"}}
1618677517.4533749: {"jsonrpc":"2.0","method":"updateOrderbook","params":{"ask":[],"bid":[{"price":"0.00015733","size":"100.65"},{"price":"0.00015732","size":"0"},{"price":"0.00015719","size":"780.80"},{"price":"0.00015718","size":"0"}],"sequence":18307694,"timestamp":"2021-04-17T16:38:37.376Z","symbol":"OMGBTC"}}
1618677517.470484: {"jsonrpc":"2.0","method":"updateOrderbook","params":{"ask":[{"price":"0.0168134","size":"1199.97"},{"price":"0.0168158","size":"0"}],"bid":[],"sequence":6928566,"timestamp":"2021-04-17T16:38:37.359Z","symbol":"ETCETH"}}
1618677517.556421: {"jsonrpc":"2.0","method":"updateOrderbook","params":{"ask":[],"bid":[{"price":"0.00015753","size":"9.55"},{"price":"0.00015750","size":"0"}],"sequence":18307695,"timestamp":"2021-04-17T16:38:37.471Z","symbol":"OMGBTC"}}
1618677517.658198: {"jsonrpc":"2.0","method":"updateOrderbook","params":{"ask":[{"price":"0.00015796","size":"72.33"},{"price":"0.00015797","size":"0"},{"price":"0.00015812","size":"0"},{"price":"0.00015815","size":"1479.88"},{"price":"0.00015836","size":"112.21"},{"price":"0.00015841","size":"112.89"}],"bid":[],"sequence":18307696,"timestamp":"2021-04-17T16:38:37.582Z","symbol":"OMGBTC"}}
1618677517.672928: {"jsonrpc":"2.0","method":"updateOrderbook","params":{"ask":[{"price":"0.0168134","size":"0"},{"price":"0.0168222","size":"1199.97"},{"price":"0.0169603","size":"0"},{"price":"0.0169774","size":"3136.09"},{"price":"0.0180695","size":"0"},{"price":"0.0182223","size":"6952.63"}],"bid":[],"sequence":6928567,"timestamp":"2021-04-17T16:38:37.620Z","symbol":"ETCETH"}}
1618677517.765631: {"jsonrpc":"2.0","method":"updateOrderbook","params":{"ask":[{"price":"0.00015796","size":"0"},{"price":"0.00015799","size":"72.33"},{"price":"0.00015801","size":"0"},{"price":"0.00015807","size":"245.28"},{"price":"0.00015809","size":"0"},{"price":"0.00015811","size":"510.27"},{"price":"0.00015812","size":"692.41"},{"price":"0.00015815","size":"550.49"},{"price":"0.00015818","size":"0"},{"price":"0.00015824","size":"929.39"},{"price":"0.00015830","size":"826.63"},{"price":"0.00015831","size":"0"},{"price":"0.00015839","size":"0"},{"price":"0.00015841","size":"1385.68"},{"price":"0.00015844","size":"424.96"},{"price":"0.00015868","size":"0"},{"price":"0.00015875","size":"0"},{"price":"0.00015877","size":"633.98"},{"price":"0.00015887","size":"1774.39"},{"price":"0.00015891","size":"2128.07"},{"price":"0.00015901","size":"0"},{"price":"0.00015936","size":"3008.25"},{"price":"0.00015955","size":"0"},{"price":"0.00015967","size":"4402.08"},{"price":"0.00015992","size":"0"},{"price":"0.00016186","size":"5617.94"}],"bid":[{"price":"0.00015746","size":"246.65"},{"price":"0.00015744","size":"0"},{"price":"0.00015723","size":"0"},{"price":"0.00015713","size":"1394.00"},{"price":"0.00015693","size":"0"},{"price":"0.00015686","size":"1821.71"},{"price":"0.00015645","size":"265.47"},{"price":"0.00015636","size":"3529.56"}],"sequence":18307697,"timestamp":"2021-04-17T16:38:37.715Z","symbol":"OMGBTC"}}
1618677517.776674: {"jsonrpc":"2.0","method":"updateOrderbook","params":{"ask":[{"price":"0.00025491","size":"2900.0"},{"price":"0.00025526","size":"3000.0"}],"bid":[],"sequence":9316107,"timestamp":"2021-04-17T16:38:37.706Z","symbol":"XLMETH"}}
1618677517.8605928: {"jsonrpc":"2.0","method":"updateOrderbook","params":{"ask":[{"price":"0.00015792","size":"0"},{"price":"0.00015798","size":"42.78"},{"price":"0.00015811","size":"80.55"},{"price":"0.00015814","size":"429.72"},{"price":"0.00015830","size":"298.44"},{"price":"0.00015833","size":"528.19"},{"price":"0.00015844","size":"0"},{"price":"0.00015848","size":"574.55"},{"price":"0.00015877","size":"0"},{"price":"0.00015885","size":"633.98"},{"price":"0.00015944","size":"0"}],"bid":[{"price":"0.00015750","size":"200.00"},{"price":"0.00015742","size":"0"},{"price":"0.00015741","size":"448.50"},{"price":"0.00015738","size":"603.33"},{"price":"0.00015736","size":"19.60"},{"price":"0.00015718","size":"963.02"},{"price":"0.00015713","size":"0"},{"price":"0.00015697","size":"1394.00"},{"price":"0.00015686","size":"0"},{"price":"0.00015656","size":"2246.87"},{"price":"0.00015631","size":"0"},{"price":"0.00015618","size":"3145.03"},{"price":"0.00015568","size":"0"},{"price":"0.00015510","size":"5478.09"}],"sequence":18307698,"timestamp":"2021-04-17T16:38:37.820Z","symbol":"OMGBTC"}}
1618677517.8610802: {"jsonrpc":"2.0","method":"updateOrderbook","params":{"ask":[{"price":"6.02870","size":"0"},{"price":"6.34474","size":"1.00"}],"bid":[{"price":"3.40803","size":"0"},{"price":"3.09199","size":"1.00"}],"sequence":7132753,"timestamp":"2021-04-17T16:38:37.753Z","symbol":"DODOUSD"}}
1618677517.964245: {"jsonrpc":"2.0","method":"updateOrderbook","params":{"ask":[{"price":"0.00015812","size":"1122.13"},{"price":"0.00015814","size":"0"},{"price":"0.00015831","size":"528.19"},{"price":"0.00015833","size":"0"},{"price":"0.00015844","size":"424.96"},{"price":"0.00015848","size":"149.59"},{"price":"0.00015865","size":"0"},{"price":"0.00015875","size":"245.17"},{"price":"0.00015944","size":"517.66"}],"bid":[{"price":"0.00015753","size":"0"},{"price":"0.00015752","size":"67.06"},{"price":"0.00015749","size":"160.91"},{"price":"0.00015735","size":"48.75"},{"price":"0.00015718","size":"0"},{"price":"0.00015717","size":"587.38"},{"price":"0.00015715","size":"963.02"},{"price":"0.00015700","size":"0"},{"price":"0.00015683","size":"477.14"},{"price":"0.00015680","size":"155.75"}],"sequence":18307699,"timestamp":"2021-04-17T16:38:37.911Z","symbol":"OMGBTC"}}
1618677517.975175: {"jsonrpc":"2.0","method":"updateOrderbook","params":{"ask":[{"price":"0.00025491","size":"5900.0"},{"price":"0.00025526","size":"0"}],"bid":[{"price":"0.00025374","size":"3000.0"},{"price":"0.00025373","size":"7870.9"},{"price":"0.00025356","size":"0"},{"price":"0.00025355","size":"0"}],"sequence":9316108,"timestamp":"2021-04-17T16:38:37.921Z","symbol":"XLMETH"}}
1618677517.975438: {"jsonrpc":"2.0","method":"updateOrderbook","params":{"ask":[{"price":"0.0167548","size":"0"},{"price":"0.0167606","size":"785.63"}],"bid":[],"sequence":6928568,"timestamp":"2021-04-17T16:38:37.900Z","symbol":"ETCETH"}}
1618677518.0618901: {"jsonrpc":"2.0","method":"updateOrderbook","params":{"ask":[{"price":"0.00015798","size":"115.11"},{"price":"0.00015799","size":"0"},{"price":"0.00015805","size":"245.28"},{"price":"0.00015807","size":"0"}],"bid":[],"sequence":18307700,"timestamp":"2021-04-17T16:38:38.020Z","symbol":"OMGBTC"}}
1618677518.062145: {"jsonrpc":"2.0","method":"updateOrderbook","params":{"ask":[{"price":"6.34404","size":"1.00"},{"price":"6.34474","size":"0"}],"bid":[{"price":"4.55257","size":"0"},{"price":"4.55159","size":"570.65"},{"price":"4.54932","size":"0"},{"price":"4.54699","size":"902.75"},{"price":"4.54421","size":"0"},{"price":"4.54210","size":"1196.81"},{"price":"4.53590","size":"0"},{"price":"4.53311","size":"1626.22"},{"price":"4.52637","size":"0"},{"price":"4.52490","size":"2203.89"},{"price":"4.50835","size":"0"},{"price":"4.50585","size":"4091.22"},{"price":"3.09199","size":"0"},{"price":"3.09165","size":"1.00"}],"sequence":7132754,"timestamp":"2021-04-17T16:38:37.934Z","symbol":"DODOUSD"}}
1618677518.073598: {"jsonrpc":"2.0","method":"updateOrderbook","params":{"ask":[{"price":"0.0167606","size":"0"},{"price":"0.0167659","size":"785.63"},{"price":"0.0168222","size":"0"},{"price":"0.0168301","size":"1199.97"},{"price":"0.0169036","size":"0"},{"price":"0.0169173","size":"2145.10"},{"price":"0.0170802","size":"0"},{"price":"0.0171051","size":"4442.60"}],"bid":[],"sequence":6928569,"timestamp":"2021-04-17T16:38:38.018Z","symbol":"ETCETH"}}
1618677518.1592581: {"jsonrpc":"2.0","method":"updateOrderbook","params":{"ask":[{"price":"0.00015937","size":"2.45"},{"price":"0.00015943","size":"0"}],"bid":[],"sequence":18307701,"timestamp":"2021-04-17T16:38:38.085Z","symbol":"OMGBTC"}}
1618677518.15947: {"jsonrpc":"2.0","method":"updateOrderbook","params":{"ask":[{"price":"4.61959","size":"8443.15"},{"price":"4.62181","size":"0"},{"price":"4.68153","size":"10836.10"},{"price":"4.68443","size":"0"},{"price":"6.34404","size":"0"},{"price":"6.34474","size":"1.00"}],"bid":[{"price":"4.55217","size":"570.65"},{"price":"4.55159","size":"0"},{"price":"4.54265","size":"1196.81"},{"price":"4.54210","size":"0"},{"price":"4.49296","size":"1661.53"},{"price":"4.48703","size":"0"},{"price":"3.09199","size":"1.00"},{"price":"3.09165","size":"0"}],"sequence":7132755,"timestamp":"2021-04-17T16:38:38.124Z","symbol":"DODOUSD"}}
1618677518.254797: {"jsonrpc":"2.0","method":"updateOrderbook","params":{"ask":[],"bid":[{"price":"4.55217","size":"0"},{"price":"4.55163","size":"570.65"}],"sequence":7132756,"timestamp":"2021-04-17T16:38:38.163Z","symbol":"DODOUSD"}}
1618677518.255012: {"jsonrpc":"2.0","method":"updateOrderbook","params":{"ask":[],"bid":[{"price":"0.00015717","size":"0"},{"price":"0.00015711","size":"587.38"}],"sequence":18307702,"timestamp":"2021-04-17T16:38:38.189Z","symbol":"OMGBTC"}}
1618677518.263479: {"jsonrpc":"2.0","method":"updateOrderbook","params":{"ask":[{"price":"0.00025491","size":"2900.0"},{"price":"0.00025526","size":"3000.0"}],"bid":[],"sequence":9316109,"timestamp":"2021-04-17T16:38:38.147Z","symbol":"XLMETH"}}
1618677518.369693: {"jsonrpc":"2.0","method":"updateOrderbook","params":{"ask":[{"price":"0.00025472","size":"0"},{"price":"0.00025480","size":"1180.6"},{"price":"0.00025491","size":"0"},{"price":"0.00025526","size":"5900.0"}],"bid":[],"sequence":9316110,"timestamp":"2021-04-17T16:38:38.318Z","symbol":"XLMETH"}}
1618677518.461607: {"jsonrpc":"2.0","method":"updateOrderbook","params":{"ask":[{"price":"0.00015808","size":"692.41"},{"price":"0.00015811","size":"1009.94"},{"price":"0.00015812","size":"429.72"},{"price":"0.00015824","size":"0"}],"bid":[{"price":"0.00015711","size":"0"},{"price":"0.00015694","size":"679.14"},{"price":"0.00015666","size":"0"},{"price":"0.00015662","size":"445.38"}],"sequence":18307703,"timestamp":"2021-04-17T16:38:38.399Z","symbol":"OMGBTC"}}
1618677518.557037: {"jsonrpc":"2.0","method":"updateOrderbook","params":{"ask":[{"price":"0.00015792","size":"42.78"},{"price":"0.00015798","size":"72.33"}],"bid":[{"price":"0.00015752","size":"227.97"},{"price":"0.00015749","size":"0"},{"price":"0.00015747","size":"170.13"},{"price":"0.00015743","size":"100.65"},{"price":"0.00015737","size":"0"},{"price":"0.00015735","size":"39.20"},{"price":"0.00015733","size":"0"},{"price":"0.00015728","size":"780.80"},{"price":"0.00015720","size":"9.55"},{"price":"0.00015719","size":"0"},{"price":"0.00015708","size":"110.32"},{"price":"0.00015704","size":"91.76"},{"price":"0.00015698","size":"0"},{"price":"0.00015694","size":"587.38"}],"sequence":18307704,"timestamp":"2021-04-17T16:38:38.468Z","symbol":"OMGBTC"}}
1618677518.5591009: {"jsonrpc":"2.0","method":"updateOrderbook","params":{"ask":[],"bid":[{"price":"0.00007530","size":"0.05"}],"sequence":5856030,"timestamp":"2021-04-17T16:38:38.468Z","symbol":"DODOBTC"}}
1618677518.577303: {"jsonrpc":"2.0","method":"updateOrderbook","params":{"ask":[{"price":"0.00025491","size":"2900.0"},{"price":"0.00025492","size":"0"},{"price":"0.00025499","size":"3000.0"},{"price":"0.00025500","size":"3935.4"},{"price":"0.00025526","size":"0"}],"bid":[],"sequence":9316111,"timestamp":"2021-04-17T16:38:38.482Z","symbol":"XLMETH"}}
1618677518.654164: {"jsonrpc":"2.0","method":"updateOrderbook","params":{"ask":[{"price":"0.00015792","size":"0"},{"price":"0.00015797","size":"42.78"},{"price":"0.00015798","size":"0"},{"price":"0.00015801","size":"72.33"}],"bid":[{"price":"0.00015756","size":"67.05"},{"price":"0.00015752","size":"160.92"},{"price":"0.00015735","size":"1011.77"},{"price":"0.00015720","size":"0"},{"price":"0.00015715","size":"0"}],"sequence":18307705,"timestamp":"2021-04-17T16:38:38.583Z","symbol":"OMGBTC"}}
1618677518.6655989: {"jsonrpc":"2.0","method":"updateOrderbook","params":{"ask":[],"bid":[{"price":"0.00007530","size":"0"}],"sequence":5856031,"timestamp":"2021-04-17T16:38:38.539Z","symbol":"DODOBTC"}}
1618677518.758571: {"jsonrpc":"2.0","method":"updateOrderbook","params":{"ask":[{"price":"0.00015797","size":"0"},{"price":"0.00015800","size":"42.78"},{"price":"0.00015808","size":"0"},{"price":"0.00015811","size":"772.96"},{"price":"0.00015823","size":"929.39"},{"price":"0.00015839","size":"1272.79"},{"price":"0.00015841","size":"112.89"},{"price":"0.00015884","size":"1774.39"},{"price":"0.00015887","size":"0"}],"bid":[{"price":"0.00015748","size":"9.55"},{"price":"0.00015735","size":"1002.22"}],"sequence":18307706,"timestamp":"2021-04-17T16:38:38.666Z","symbol":"OMGBTC"}}
1618677518.858666: {"jsonrpc":"2.0","method":"updateOrderbook","params":{"ask":[],"bid":[{"price":"0.00015756","size":"0"},{"price":"0.00015753","size":"67.05"},{"price":"0.00015746","size":"0"},{"price":"0.00015744","size":"246.65"}],"sequence":18307707,"timestamp":"2021-04-17T16:38:38.794Z","symbol":"OMGBTC"}}
1618677518.858976: {"jsonrpc":"2.0","method":"updateOrderbook","params":{"ask":[],"bid":[{"price":"4.54265","size":"0"},{"price":"4.54198","size":"1196.81"}],"sequence":7132757,"timestamp":"2021-04-17T16:38:38.759Z","symbol":"DODOUSD"}}
1618677518.952632: {"jsonrpc":"2.0","method":"updateOrderbook","params":{"ask":[{"price":"0.00015803","size":"429.72"},{"price":"0.00015812","size":"0"},{"price":"0.00015825","size":"690.57"},{"price":"0.00015831","size":"0"},{"price":"0.00015839","size":"1697.75"},{"price":"0.00015844","size":"0"}],"bid":[{"price":"0.00015735","size":"39.20"},{"price":"0.00015716","size":"963.02"}],"sequence":18307708,"timestamp":"2021-04-17T16:38:38.900Z","symbol":"OMGBTC"}}
1618677519.05661: {"jsonrpc":"2.0","method":"updateOrderbook","params":{"ask":[{"price":"0.00015799","size":"72.33"},{"price":"0.00015801","size":"0"},{"price":"0.00015803","size":"675.00"},{"price":"0.00015805","size":"0"},{"price":"0.00015867","size":"633.98"},{"price":"0.00015885","size":"0"}],"bid":[{"price":"0.00015748","size":"0"},{"price":"0.00015745","size":"9.55"}],"sequence":18307709,"timestamp":"2021-04-17T16:38:38.972Z","symbol":"OMGBTC"}}
1618677519.160504: {"jsonrpc":"2.0","method":"updateOrderbook","params":{"ask":[{"price":"0.00015798","size":"42.78"},{"price":"0.00015800","size":"0"},{"price":"0.00015937","size":"0"},{"price":"0.00015943","size":"2.45"}],"bid":[{"price":"0.00015753","size":"0"},{"price":"0.00015751","size":"67.05"},{"price":"0.00015746","size":"246.65"},{"price":"0.00015744","size":"0"}],"sequence":18307710,"timestamp":"2021-04-17T16:38:39.085Z","symbol":"OMGBTC"}}
1618677519.252504: {"jsonrpc":"2.0","method":"updateOrderbook","params":{"ask":[],"bid":[{"price":"0.00015746","size":"0"},{"price":"0.00015745","size":"0"},{"price":"0.00015744","size":"246.65"},{"price":"0.00015736","size":"29.15"}],"sequence":18307711,"timestamp":"2021-04-17T16:38:39.191Z","symbol":"OMGBTC"}}
1618677519.252736: {"jsonrpc":"2.0","method":"updateOrderbook","params":{"ask":[{"price":"4.61715","size":"8443.15"},{"price":"4.61959","size":"0"}],"bid":[],"sequence":7132758,"timestamp":"2021-04-17T16:38:39.168Z","symbol":"DODOUSD"}}
1618677519.263983: {"jsonrpc":"2.0","method":"updateOrderbook","params":{"ask":[{"price":"0.0165849","size":"0"}],"bid":[],"sequence":6928570,"timestamp":"2021-04-17T16:38:39.215Z","symbol":"ETCETH"}}
1618677519.353952: {"jsonrpc":"2.0","method":"updateOrderbook","params":{"ask":[{"price":"0.00015806","size":"692.41"},{"price":"0.00015809","size":"929.39"},{"price":"0.00015811","size":"80.55"},{"price":"0.00015823","size":"0"},{"price":"0.00015991","size":"5617.94"},{"price":"0.00016186","size":"0"}],"bid":[{"price":"0.00015745","size":"9.55"},{"price":"0.00015736","size":"19.60"}],"sequence":18307712,"timestamp":"2021-04-17T16:38:39.263Z","symbol":"OMGBTC"}}
1618677519.371901: {"jsonrpc":"2.0","method":"updateOrderbook","params":{"ask":[{"price":"0.0165903","size":"0.59"}],"bid":[],"sequence":6928571,"timestamp":"2021-04-17T16:38:39.274Z","symbol":"ETCETH"}}
1618677519.4552808: {"jsonrpc":"2.0","method":"updateOrderbook","params":{"ask":[{"price":"0.00015792","size":"42.78"},{"price":"0.00015798","size":"0"},{"price":"0.00015803","size":"245.28"},{"price":"0.00015807","size":"429.72"},{"price":"0.00015860","size":"0"},{"price":"0.00015869","size":"164.72"}],"bid":[{"price":"0.00015745","size":"0"},{"price":"0.00015732","size":"9.55"}],"sequence":18307713,"timestamp":"2021-04-17T16:38:39.392Z","symbol":"OMGBTC"}}
1618677519.5559921: {"jsonrpc":"2.0","method":"updateOrderbook","params":{"ask":[],"bid":[{"price":"0.00015752","size":"227.97"},{"price":"0.00015751","size":"0"},{"price":"0.00015746","size":"246.65"},{"price":"0.00015744","size":"0"},{"price":"0.00015735","size":"48.75"},{"price":"0.00015732","size":"0"},{"price":"0.00015699","size":"155.75"},{"price":"0.00015688","size":"151.30"},{"price":"0.00015680","size":"216.48"},{"price":"0.00015675","size":"162.11"},{"price":"0.00015660","size":"0"}],"sequence":18307714,"timestamp":"2021-04-17T16:38:39.510Z","symbol":"OMGBTC"}}
1618677519.5562088: {"jsonrpc":"2.0","method":"updateOrderbook","params":{"ask":[],"bid":[{"price":"4.20059","size":"0"},{"price":"3.87315","size":"133.36"},{"price":"3.22598","size":"0"},{"price":"1.96392","size":"175.25"}],"sequence":7132759,"timestamp":"2021-04-17T16:38:39.518Z","symbol":"DODOUSD"}}
1618677519.567065: {"jsonrpc":"2.0","method":"updateOrderbook","params":{"ask":[],"bid":[{"price":"0.00006374","size":"0"}],"sequence":5856032,"timestamp":"2021-04-17T16:38:39.511Z","symbol":"DODOBTC"}}
1618677519.656985: {"jsonrpc":"2.0","method":"updateOrderbook","params":{"ask":[{"price":"0.00015803","size":"0"},{"price":"0.00015805","size":"245.28"},{"price":"0.00015806","size":"0"},{"price":"0.00015809","size":"0"},{"price":"0.00015814","size":"692.41"},{"price":"0.00015824","size":"929.39"},{"price":"0.00015839","size":"424.96"},{"price":"0.00015848","size":"1422.38"},{"price":"0.00015884","size":"0"},{"price":"0.00015894","size":"2185.31"},{"price":"0.00015991","size":"0"},{"price":"0.00016236","size":"5617.94"}],"bid":[{"price":"0.00015745","size":"448.50"},{"price":"0.00015741","size":"0"},{"price":"0.00015707","size":"587.38"},{"price":"0.00015694","size":"0"},{"price":"0.00015644","size":"2504.10"},{"price":"0.00015636","size":"1025.46"}],"sequence":18307715,"timestamp":"2021-04-17T16:38:39.605Z","symbol":"OMGBTC"}}
1618677519.6574001: {"jsonrpc":"2.0","method":"updateOrderbook","params":{"ask":[{"price":"6.33987","size":"1.00"},{"price":"6.34474","size":"0"}],"bid":[{"price":"4.55163","size":"0"},{"price":"4.54772","size":"570.65"},{"price":"4.54699","size":"0"},{"price":"4.54456","size":"902.75"},{"price":"4.54198","size":"0"},{"price":"4.53767","size":"1196.81"},{"price":"4.53311","size":"0"},{"price":"4.52955","size":"1626.22"},{"price":"4.52490","size":"0"},{"price":"4.52339","size":"2203.89"},{"price":"4.51992","size":"0"},{"price":"4.51668","size":"2740.00"},{"price":"4.50585","size":"0"},{"price":"4.50241","size":"4091.22"},{"price":"4.49296","size":"0"},{"price":"4.48994","size":"1661.53"},{"price":"3.09199","size":"0"},{"price":"3.08962","size":"1.00"}],"sequence":7132760,"timestamp":"2021-04-17T16:38:39.582Z","symbol":"DODOUSD"}}
1618677519.6696398: {"jsonrpc":"2.0","method":"updateOrderbook","params":{"ask":[],"bid":[{"price":"0.00007529","size":"0"},{"price":"0.00007521","size":"133.36"},{"price":"0.00007498","size":"0"},{"price":"0.00007494","size":"1737.44"},{"price":"0.00007467","size":"0"},{"price":"0.00007464","size":"2667.37"}],"sequence":5856033,"timestamp":"2021-04-17T16:38:39.535Z","symbol":"DODOBTC"}}
1618677519.6699688: {"jsonrpc":"2.0","method":"updateOrderbook","params":{"ask":[],"bid":[{"price":"0.001305876","size":"4338"},{"price":"0.001305418","size":"0"}],"sequence":5053518,"timestamp":"2021-04-17T16:38:39.562Z","symbol":"ADABCH"}}
1618677519.760524: {"jsonrpc":"2.0","method":"updateOrderbook","params":{"ask":[{"price":"0.00015792","size":"0"},{"price":"0.00015798","size":"42.78"},{"price":"0.00015943","size":"0"}],"bid":[{"price":"0.00015637","size":"0"},{"price":"0.00015627","size":"0.01"}],"sequence":18307716,"timestamp":"2021-04-17T16:38:39.685Z","symbol":"OMGBTC"}}
1618677519.7607849: {"jsonrpc":"2.0","method":"updateOrderbook","params":{"ask":[],"bid":[{"price":"4.53767","size":"0"},{"price":"4.53672","size":"1196.81"},{"price":"4.52339","size":"0"},{"price":"4.52232","size":"2203.89"},{"price":"4.51668","size":"0"},{"price":"4.51227","size":"2740.00"},{"price":"4.50241","size":"0"},{"price":"4.48994","size":"0"},{"price":"4.48396","size":"4091.22"},{"price":"4.47082","size":"1661.53"},{"price":"3.87315","size":"0"},{"price":"3.87163","size":"133.44"}],"sequence":7132761,"timestamp":"2021-04-17T16:38:39.673Z","symbol":"DODOUSD"}}
1618677519.7674282: {"jsonrpc":"2.0","method":"updateOrderbook","params":{"ask":[],"bid":[{"price":"0.00007464","size":"0"},{"price":"0.00007453","size":"2668.80"}],"sequence":5856034,"timestamp":"2021-04-17T16:38:39.668Z","symbol":"DODOBTC"}}
1618677519.767638: {"jsonrpc":"2.0","method":"updateOrderbook","params":{"ask":[{"price":"0.001332258","size":"56575"},{"price":"0.001332668","size":"0"},{"price":"0.001341720","size":"56233"},{"price":"0.001342276","size":"0"},{"price":"0.001348155","size":"57535"},{"price":"0.001348637","size":"0"},{"price":"0.001371549","size":"52341"},{"price":"0.001372056","size":"0"},{"price":"0.001377169","size":"54827"},{"price":"0.001377596","size":"0"}],"bid":[],"sequence":5053519,"timestamp":"2021-04-17T16:38:39.689Z","symbol":"ADABCH"}}
1618677519.852221: {"jsonrpc":"2.0","method":"updateOrderbook","params":{"ask":[],"bid":[{"price":"0.00015735","size":"1011.77"},{"price":"0.00015716","size":"0"},{"price":"0.00015712","size":"587.38"},{"price":"0.00015707","size":"0"}],"sequence":18307717,"timestamp":"2021-04-17T16:38:39.792Z","symbol":"OMGBTC"}}
1618677519.852467: {"jsonrpc":"2.0","method":"updateOrderbook","params":{"ask":[{"price":"6.33917","size":"1.00"},{"price":"6.33987","size":"0"}],"bid":[{"price":"4.51500","size":"2740.00"},{"price":"4.51227","size":"0"},{"price":"4.49752","size":"4091.22"},{"price":"4.48396","size":"0"},{"price":"3.08962","size":"0"},{"price":"3.08928","size":"1.00"}],"sequence":7132762,"timestamp":"2021-04-17T16:38:39.759Z","symbol":"DODOUSD"}}
1618677519.862675: {"jsonrpc":"2.0","method":"updateOrderbook","params":{"ask":[],"bid":[{"price":"0.00023748","size":"71327.4"},{"price":"0.00023739","size":"0"}],"sequence":9316112,"timestamp":"2021-04-17T16:38:39.751Z","symbol":"XLMETH"}}
1618677519.9556239: {"jsonrpc":"2.0","method":"updateOrderbook","params":{"ask":[{"price":"0.00015798","size":"0"},{"price":"0.00015801","size":"42.78"}],"bid":[{"price":"0.00015757","size":"67.05"},{"price":"0.00015753","size":"9.55"},{"price":"0.00015752","size":"160.92"},{"price":"0.00015750","size":"446.65"},{"price":"0.00015746","size":"0"},{"price":"0.00015735","size":"1002.22"}],"sequence":18307718,"timestamp":"2021-04-17T16:38:39.873Z","symbol":"OMGBTC"}}
1618677520.0667279: {"jsonrpc":"2.0","method":"updateOrderbook","params":{"ask":[{"price":"0.00015798","size":"42.78"},{"price":"0.00015801","size":"0"}],"bid":[{"price":"0.00015667","size":"271.61"},{"price":"0.00015658","size":"225.06"}],"sequence":18307719,"timestamp":"2021-04-17T16:38:39.963Z","symbol":"OMGBTC"}}
1618677520.151519: {"jsonrpc":"2.0","method":"updateOrderbook","params":{"ask":[],"bid":[{"price":"0.00015723","size":"1394.00"},{"price":"0.00015697","size":"0"},{"price":"0.00015693","size":"1821.71"},{"price":"0.00015656","size":"425.16"},{"price":"0.00015637","size":"0.01"},{"price":"0.00015627","size":"0"}],"sequence":18307720,"timestamp":"2021-04-17T16:38:40.104Z","symbol":"OMGBTC"}}
1618677520.1517801: {"jsonrpc":"2.0","method":"updateOrderbook","params":{"ask":[{"price":"6.33917","size":"0"},{"price":"6.33987","size":"1.00"}],"bid":[{"price":"4.54810","size":"570.65"},{"price":"4.54772","size":"0"},{"price":"4.53990","size":"1196.81"},{"price":"4.53672","size":"0"},{"price":"4.53585","size":"1626.22"},{"price":"4.52955","size":"0"},{"price":"4.52671","size":"2203.89"},{"price":"4.52232","size":"0"},{"price":"4.51860","size":"2740.00"},{"price":"4.51500","size":"0"},{"price":"4.50617","size":"4091.22"},{"price":"4.49752","size":"0"},{"price":"3.08962","size":"1.00"},{"price":"3.08928","size":"0"}],"sequence":7132763,"timestamp":"2021-04-17T16:38:40.095Z","symbol":"DODOUSD"}}
1618677520.163332: {"jsonrpc":"2.0","method":"updateOrderbook","params":{"ask":[],"bid":[{"price":"0.00023705","size":"71611.8"},{"price":"0.00023695","size":"0"}],"sequence":9316113,"timestamp":"2021-04-17T16:38:40.091Z","symbol":"XLMETH"}}
1618677520.2649758: {"jsonrpc":"2.0","method":"updateOrderbook","params":{"ask":[{"price":"0.00015836","size":"0"},{"price":"0.00015841","size":"0"},{"price":"0.00015842","size":"112.21"},{"price":"0.00015846","size":"112.89"},{"price":"0.00015856","size":"0"},{"price":"0.00015866","size":"156.33"},{"price":"0.00015937","size":"2.45"}],"bid":[{"price":"0.00015761","size":"67.05"},{"price":"0.00015757","size":"0"}],"sequence":18307721,"timestamp":"2021-04-17T16:38:40.199Z","symbol":"OMGBTC"}}
1618677520.266349: {"jsonrpc":"2.0","method":"updateOrderbook","params":{"ask":[],"bid":[{"price":"0.00024008","size":"84667.4"},{"price":"0.00023999","size":"0"},{"price":"0.00023944","size":"75814.7"},{"price":"0.00023935","size":"0"},{"price":"0.00023888","size":"75673.3"},{"price":"0.00023879","size":"0"},{"price":"0.00023840","size":"71128.4"},{"price":"0.00023830","size":"0"},{"price":"0.00023792","size":"73259.1"},{"price":"0.00023783","size":"0"}],"sequence":9316114,"timestamp":"2021-04-17T16:38:40.218Z","symbol":"XLMETH"}}
1618677520.269783: {"jsonrpc":"2.0","method":"updateOrderbook","params":{"ask":[],"bid":[{"price":"0.0162571","size":"48.69"}],"sequence":6928572,"timestamp":"2021-04-17T16:38:40.154Z","symbol":"ETCETH"}}
1618677520.3630562: {"jsonrpc":"2.0","method":"updateOrderbook","params":{"ask":[],"bid":[{"price":"0.00015761","size":"0"},{"price":"0.00015757","size":"67.05"},{"price":"0.00015750","size":"200.00"},{"price":"0.00015746","size":"246.65"},{"price":"0.00015745","size":"0"},{"price":"0.00015742","size":"448.50"},{"price":"0.00015723","size":"0"},{"price":"0.00015718","size":"1394.00"},{"price":"0.00015712","size":"0"},{"price":"0.00015700","size":"587.38"},{"price":"0.00014901","size":"1269.27"},{"price":"0.00014895","size":"0"}],"sequence":18307722,"timestamp":"2021-04-17T16:38:40.322Z","symbol":"OMGBTC"}}
1618677520.363453: {"jsonrpc":"2.0","method":"updateOrderbook","params":{"ask":[{"price":"6.33987","size":"0"},{"price":"6.34056","size":"1.00"}],"bid":[{"price":"3.08996","size":"1.00"},{"price":"3.08962","size":"0"}],"sequence":7132764,"timestamp":"2021-04-17T16:38:40.301Z","symbol":"DODOUSD"}}
1618677520.381496: {"jsonrpc":"2.0","method":"updateOrderbook","params":{"ask":[],"bid":[{"price":"0.001299124","size":"39208"},{"price":"0.001298418","size":"0"},{"price":"0.001294480","size":"40483"},{"price":"0.001294047","size":"0"},{"price":"0.001277373","size":"39117"},{"price":"0.001276843","size":"0"},{"price":"0.001268567","size":"44239"},{"price":"0.001268115","size":"0"}],"sequence":5053520,"timestamp":"2021-04-17T16:38:40.252Z","symbol":"ADABCH"}}
1618677520.4623518: {"jsonrpc":"2.0","method":"updateOrderbook","params":{"ask":[{"price":"0.00015815","size":"1479.88"},{"price":"0.00015824","size":"0"}],"bid":[{"price":"0.00015753","size":"0"},{"price":"0.00015751","size":"9.55"},{"price":"0.00015631","size":"3145.03"},{"price":"0.00015618","size":"0"}],"sequence":18307723,"timestamp":"2021-04-17T16:38:40.392Z","symbol":"OMGBTC"}}
1618677520.4626272: {"jsonrpc":"2.0","method":"updateOrderbook","params":{"ask":[{"price":"6.33987","size":"1.00"},{"price":"6.34056","size":"0"}],"bid":[{"price":"3.08996","size":"0"},{"price":"3.08962","size":"1.00"}],"sequence":7132765,"timestamp":"2021-04-17T16:38:40.367Z","symbol":"DODOUSD"}}
1618677520.487471: {"jsonrpc":"2.0","method":"updateOrderbook","params":{"ask":[],"bid":[{"price":"0.00025234","size":"38.8"},{"price":"0.00025226","size":"0"}],"sequence":9316115,"timestamp":"2021-04-17T16:38:40.398Z","symbol":"XLMETH"}}
1618677520.556119: {"jsonrpc":"2.0","method":"updateOrderbook","params":{"ask":[{"price":"0.00015819","size":"1272.79"},{"price":"0.00015848","size":"149.59"}],"bid":[{"price":"0.00015751","size":"0"},{"price":"0.00015748","size":"9.55"}],"sequence":18307724,"timestamp":"2021-04-17T16:38:40.510Z","symbol":"OMGBTC"}}
1618677520.560935: {"jsonrpc":"2.0","method":"updateOrderbook","params":{"ask":[],"bid":[{"price":"0.00007524","size":"0.05"}],"sequence":5856035,"timestamp":"2021-04-17T16:38:40.491Z","symbol":"DODOBTC"}}
1618677520.5677671: {"jsonrpc":"2.0","method":"updateOrderbook","params":{"ask":[],"bid":[{"price":"0.00025410","size":"5900.0"},{"price":"0.00025374","size":"0"}],"sequence":9316116,"timestamp":"2021-04-17T16:38:40.499Z","symbol":"XLMETH"}}
1618677520.654412: {"jsonrpc":"2.0","method":"updateOrderbook","params":{"ask":[{"price":"0.00015937","size":"0"},{"price":"0.00015943","size":"2.45"}],"bid":[{"price":"0.00015757","size":"0"},{"price":"0.00015756","size":"67.05"},{"price":"0.00015669","size":"445.38"},{"price":"0.00015662","size":"0"}],"sequence":18307725,"timestamp":"2021-04-17T16:38:40.600Z","symbol":"OMGBTC"}}
1618677520.654755: {"jsonrpc":"2.0","method":"updateOrderbook","params":{"ask":[{"price":"4.60857","size":"8443.15"},{"price":"4.61715","size":"0"},{"price":"4.66402","size":"10836.10"},{"price":"4.68153","size":"0"}],"bid":[],"sequence":7132766,"timestamp":"2021-04-17T16:38:40.562Z","symbol":"DODOUSD"}}
1618677520.676437: {"jsonrpc":"2.0","method":"updateOrderbook","params":{"ask":[{"price":"0.001371549","size":"0"},{"price":"0.001372041","size":"52341"},{"price":"0.001377169","size":"0"},{"price":"0.001377617","size":"54827"}],"bid":[],"sequence":5053521,"timestamp":"2021-04-17T16:38:40.590Z","symbol":"ADABCH"}}
1618677520.676672: {"jsonrpc":"2.0","method":"updateOrderbook","params":{"ask":[],"bid":[{"price":"0.00025434","size":"1180.6"},{"price":"0.00025424","size":"0"}],"sequence":9316117,"timestamp":"2021-04-17T16:38:40.547Z","symbol":"XLMETH"}}
1618677520.676855: {"jsonrpc":"2.0","method":"updateOrderbook","params":{"ask":[{"price":"0.0168018","size":"0"}],"bid":[],"sequence":6928573,"timestamp":"2021-04-17T16:38:40.577Z","symbol":"ETCETH"}}
1618677520.759562: {"jsonrpc":"2.0","method":"updateOrderbook","params":{"ask":[{"price":"0.00015835","size":"2055.06"},{"price":"0.00015894","size":"410.92"}],"bid":[{"price":"0.00015564","size":"5478.09"},{"price":"0.00015510","size":"0"},{"price":"0.00014815","size":"4839.10"},{"price":"0.00014809","size":"0"},{"price":"0.00014721","size":"5414.54"},{"price":"0.00014716","size":"0"}],"sequence":18307726,"timestamp":"2021-04-17T16:38:40.679Z","symbol":"OMGBTC"}}
1618677520.764361: {"jsonrpc":"2.0","method":"updateOrderbook","params":{"ask":[],"bid":[{"price":"0.00025410","size":"2900.0"},{"price":"0.00025374","size":"3000.0"}],"sequence":9316118,"timestamp":"2021-04-17T16:38:40.645Z","symbol":"XLMETH"}}
1618677520.8544362: {"jsonrpc":"2.0","method":"updateOrderbook","params":{"ask":[{"price":"0.00015811","size":"772.96"},{"price":"0.00015814","size":"0"},{"price":"0.00015955","size":"4402.08"},{"price":"0.00015967","size":"0"}],"bid":[{"price":"0.00015756","size":"0"},{"price":"0.00015752","size":"227.97"},{"price":"0.00015746","size":"0"},{"price":"0.00015743","size":"347.30"},{"price":"0.00015693","size":"0"},{"price":"0.00015687","size":"1821.71"}],"sequence":18307727,"timestamp":"2021-04-17T16:38:40.805Z","symbol":"OMGBTC"}}
1618677520.854819: {"jsonrpc":"2.0","method":"updateOrderbook","params":{"ask":[{"price":"6.33987","size":"0"},{"price":"6.34126","size":"1.00"}],"bid":[{"price":"4.48937","size":"1661.53"},{"price":"4.47082","size":"0"},{"price":"3.09029","size":"1.00"},{"price":"3.08962","size":"0"}],"sequence":7132767,"timestamp":"2021-04-17T16:38:40.806Z","symbol":"DODOUSD"}}
1618677520.867435: {"jsonrpc":"2.0","method":"updateOrderbook","params":{"ask":[],"bid":[{"price":"0.00025410","size":"5900.0"},{"price":"0.00025374","size":"0"}],"sequence":9316119,"timestamp":"2021-04-17T16:38:40.737Z","symbol":"XLMETH"}}
1618677520.956626: {"jsonrpc":"2.0","method":"updateOrderbook","params":{"ask":[],"bid":[{"price":"0.00015753","size":"9.55"},{"price":"0.00015752","size":"160.92"},{"price":"0.00015748","size":"67.05"},{"price":"0.00015735","size":"39.20"},{"price":"0.00015718","size":"0"},{"price":"0.00015714","size":"963.02"},{"price":"0.00015693","size":"1394.00"},{"price":"0.00015687","size":"0"},{"price":"0.00015651","size":"2376.82"},{"price":"0.00015644","size":"0"},{"price":"0.00015636","size":"3529.56"},{"price":"0.00015631","size":"0"},{"price":"0.00015615","size":"3145.03"},{"price":"0.00015564","size":"0"},{"price":"0.00015560","size":"0"},{"price":"0.00015497","size":"5478.09"}],"sequence":18307728,"timestamp":"2021-04-17T16:38:40.896Z","symbol":"OMGBTC"}}
1618677520.95706: {"jsonrpc":"2.0","method":"updateOrderbook","params":{"ask":[],"bid":[{"price":"4.54810","size":"0"},{"price":"4.54774","size":"570.65"}],"sequence":7132768,"timestamp":"2021-04-17T16:38:40.862Z","symbol":"DODOUSD"}}
1618677520.968215: {"jsonrpc":"2.0","method":"updateOrderbook","params":{"ask":[],"bid":[{"price":"0.00025410","size":"2900.0"},{"price":"0.00025374","size":"3000.0"}],"sequence":9316120,"timestamp":"2021-04-17T16:38:40.918Z","symbol":"XLMETH"}}
1618677521.056423: {"jsonrpc":"2.0","method":"updateOrderbook","params":{"ask":[{"price":"0.00015792","size":"42.78"},{"price":"0.00015798","size":"0"},{"price":"0.00015871","size":"2128.07"},{"price":"0.00015891","size":"0"},{"price":"0.00015901","size":"3008.25"},{"price":"0.00015936","size":"0"}],"bid":[{"price":"0.00015753","size":"0"},{"price":"0.00015732","size":"9.55"},{"price":"0.00015648","size":"768.35"},{"price":"0.00015642","size":"0"},{"price":"0.00015565","size":"185.26"}],"sequence":18307729,"timestamp":"2021-04-17T16:38:40.991Z","symbol":"OMGBTC"}}
1618677521.059784: {"jsonrpc":"2.0","method":"updateOrderbook","params":{"ask":[],"bid":[{"price":"0.00006371","size":"313.92"}],"sequence":5856036,"timestamp":"2021-04-17T16:38:41.014Z","symbol":"DODOBTC"}}
1618677521.070652: {"jsonrpc":"2.0","method":"updateOrderbook","params":{"ask":[],"bid":[{"price":"0.0148667","size":"0"}],"sequence":6928574,"timestamp":"2021-04-17T16:38:40.938Z","symbol":"ETCETH"}}
1618677521.160693: {"jsonrpc":"2.0","method":"updateOrderbook","params":{"ask":[{"price":"0.00015797","size":"72.33"},{"price":"0.00015799","size":"0"},{"price":"0.00015801","size":"245.28"},{"price":"0.00015805","size":"0"},{"price":"0.00015990","size":"5617.94"},{"price":"0.00016236","size":"0"}],"bid":[],"sequence":18307730,"timestamp":"2021-04-17T16:38:41.091Z","symbol":"OMGBTC"}}
1618677521.160963: {"jsonrpc":"2.0","method":"updateOrderbook","params":{"ask":[{"price":"4.72248","size":"15561.71"},{"price":"4.73153","size":"0"},{"price":"4.79082","size":"21772.25"},{"price":"4.80020","size":"0"},{"price":"4.88027","size":"28569.63"},{"price":"4.88757","size":"0"}],"bid":[],"sequence":7132769,"timestamp":"2021-04-17T16:38:41.059Z","symbol":"DODOUSD"}}
1618677521.173033: {"jsonrpc":"2.0","method":"updateOrderbook","params":{"ask":[{"price":"0.00007664","size":"7907.32"},{"price":"0.00007675","size":"0"},{"price":"0.00007740","size":"7289.51"},{"price":"0.00007753","size":"0"},{"price":"0.00007819","size":"7949.34"},{"price":"0.00007832","size":"0"}],"bid":[],"sequence":5856037,"timestamp":"2021-04-17T16:38:41.113Z","symbol":"DODOBTC"}}
1618677521.263315: {"jsonrpc":"2.0","method":"updateOrderbook","params":{"ask":[{"price":"0.00015848","size":"0"},{"price":"0.00015854","size":"700.83"},{"price":"0.00015937","size":"2.45"},{"price":"0.00015943","size":"0"}],"bid":[{"price":"0.00015752","size":"227.97"},{"price":"0.00015748","size":"0"}],"sequence":18307731,"timestamp":"2021-04-17T16:38:41.203Z","symbol":"OMGBTC"}}
1618677521.3560588: {"jsonrpc":"2.0","method":"updateOrderbook","params":{"ask":[{"price":"0.00015827","size":"1774.39"},{"price":"0.00015835","size":"280.67"}],"bid":[{"price":"0.00015752","size":"160.92"},{"price":"0.00015751","size":"67.05"},{"price":"0.00015648","size":"3272.45"},{"price":"0.00015636","size":"1025.46"},{"price":"0.00015509","size":"5478.09"},{"price":"0.00015497","size":"0"}],"sequence":18307732,"timestamp":"2021-04-17T16:38:41.322Z","symbol":"OMGBTC"}}
1618677521.363758: {"jsonrpc":"2.0","method":"updateOrderbook","params":{"ask":[],"bid":[{"price":"0.00025410","size":"5900.0"},{"price":"0.00025374","size":"0"}],"sequence":9316121,"timestamp":"2021-04-17T16:38:41.323Z","symbol":"XLMETH"}}
1618677521.462313: {"jsonrpc":"2.0","method":"updateOrderbook","params":{"ask":[],"bid":[{"price":"0.00015745","size":"448.50"},{"price":"0.00015742","size":"0"},{"price":"0.00015712","size":"587.38"},{"price":"0.00015700","size":"0"},{"price":"0.00015653","size":"768.35"},{"price":"0.00015648","size":"2504.10"},{"price":"0.00015565","size":"0"},{"price":"0.00015520","size":"185.80"}],"sequence":18307733,"timestamp":"2021-04-17T16:38:41.403Z","symbol":"OMGBTC"}}
1618677521.464882: {"jsonrpc":"2.0","method":"updateOrderbook","params":{"ask":[{"price":"0.0167609","size":"784.70"},{"price":"0.0167659","size":"0"}],"bid":[],"sequence":6928575,"timestamp":"2021-04-17T16:38:41.359Z","symbol":"ETCETH"}}
1618677521.56752: {"jsonrpc":"2.0","method":"updateOrderbook","params":{"ask":[],"bid":[{"price":"0.00015735","size":"48.75"},{"price":"0.00015732","size":"0"}],"sequence":18307734,"timestamp":"2021-04-17T16:38:41.458Z","symbol":"OMGBTC"}}
1618677521.567727: {"jsonrpc":"2.0","method":"updateOrderbook","params":{"ask":[],"bid":[{"price":"0.00025410","size":"2900.0"},{"price":"0.00025374","size":"3000.0"}],"sequence":9316122,"timestamp":"2021-04-17T16:38:41.475Z","symbol":"XLMETH"}}
1618677521.654995: {"jsonrpc":"2.0","method":"updateOrderbook","params":{"ask":[],"bid":[],"sequence":18307735,"timestamp":"2021-04-17T16:38:41.559Z","symbol":"OMGBTC"}}
1618677521.659213: {"jsonrpc":"2.0","method":"updateOrderbook","params":{"ask":[{"price":"0.00008004","size":"8110.39"},{"price":"0.00008015","size":"0"}],"bid":[],"sequence":5856038,"timestamp":"2021-04-17T16:38:41.573Z","symbol":"DODOBTC"}}
1618677521.6655989: {"jsonrpc":"2.0","method":"updateOrderbook","params":{"ask":[],"bid":[{"price":"0.00025373","size":"0"},{"price":"0.00025351","size":"7870.9"}],"sequence":9316123,"timestamp":"2021-04-17T16:38:41.620Z","symbol":"XLMETH"}}
1618677521.756018: {"jsonrpc":"2.0","method":"updateOrderbook","params":{"ask":[],"bid":[{"price":"0.00015752","size":"227.97"},{"price":"0.00015751","size":"0"},{"price":"0.00015746","size":"246.65"},{"price":"0.00015743","size":"100.65"}],"sequence":18307736,"timestamp":"2021-04-17T16:38:41.665Z","symbol":"OMGBTC"}}
1618677521.770187: {"jsonrpc":"2.0","method":"updateOrderbook","params":{"ask":[],"bid":[{"price":"0.00025410","size":"0"},{"price":"0.00025374","size":"0"},{"price":"0.00025352","size":"5900.0"}],"sequence":9316124,"timestamp":"2021-04-17T16:38:41.684Z","symbol":"XLMETH"}}
1618677521.861509: {"jsonrpc":"2.0","method":"updateOrderbook","params":{"ask":[{"price":"0.00015792","size":"0"},{"price":"0.00015796","size":"42.78"}],"bid":[{"price":"0.00015735","size":"39.20"},{"price":"0.00015732","size":"9.55"}],"sequence":18307737,"timestamp":"2021-04-17T16:38:41.777Z","symbol":"OMGBTC"}}
1618677521.861755: {"jsonrpc":"2.0","method":"updateOrderbook","params":{"ask":[{"price":"6.18856","size":"1.00"},{"price":"6.34126","size":"0"}],"bid":[{"price":"3.24299","size":"1.00"},{"price":"3.09029","size":"0"}],"sequence":7132770,"timestamp":"2021-04-17T16:38:41.751Z","symbol":"DODOUSD"}}
1618677521.861896: {"jsonrpc":"2.0","method":"updateOrderbook","params":{"ask":[],"bid":[{"price":"0.00025434","size":"0"},{"price":"0.00025424","size":"1183.3"}],"sequence":9316125,"timestamp":"2021-04-17T16:38:41.732Z","symbol":"XLMETH"}}
1618677521.978313: {"jsonrpc":"2.0","method":"updateOrderbook","params":{"ask":[{"price":"0.00025479","size":"2900.0"},{"price":"0.00025491","size":"0"}],"bid":[],"sequence":9316126,"timestamp":"2021-04-17T16:38:41.833Z","symbol":"XLMETH"}}
1618677522.057555: {"jsonrpc":"2.0","method":"updateOrderbook","params":{"ask":[{"price":"0.00015825","size":"162.38"},{"price":"0.00015828","size":"528.19"},{"price":"0.00015839","size":"0"},{"price":"0.00015843","size":"424.96"},{"price":"0.00015867","size":"0"},{"price":"0.00015875","size":"879.15"}],"bid":[{"price":"0.00015742","size":"603.33"},{"price":"0.00015738","size":"963.02"},{"price":"0.00015714","size":"0"}],"sequence":18307738,"timestamp":"2021-04-17T16:38:41.997Z","symbol":"OMGBTC"}}
1618677522.102423: {"jsonrpc":"2.0","method":"updateOrderbook","params":{"ask":[{"price":"0.00025479","size":"0"},{"price":"0.00025499","size":"5900.0"}],"bid":[],"sequence":9316127,"timestamp":"2021-04-17T16:38:42.022Z","symbol":"XLMETH"}}
1618677522.156661: {"jsonrpc":"2.0","method":"updateOrderbook","params":{"ask":[{"price":"0.00015796","size":"0"},{"price":"0.00015800","size":"42.78"}],"bid":[{"price":"0.00015753","size":"9.55"},{"price":"0.00015732","size":"0"}],"sequence":18307739,"timestamp":"2021-04-17T16:38:42.075Z","symbol":"OMGBTC"}}
1618677522.175437: {"jsonrpc":"2.0","method":"updateOrderbook","params":{"ask":[{"price":"0.0168133","size":"134.07"}],"bid":[],"sequence":6928576,"timestamp":"2021-04-17T16:38:42.075Z","symbol":"ETCETH"}}
1618677522.268366: {"jsonrpc":"2.0","method":"updateOrderbook","params":{"ask":[{"price":"0.00015825","size":"690.57"},{"price":"0.00015828","size":"0"},{"price":"0.00015839","size":"424.96"},{"price":"0.00015843","size":"0"}],"bid":[{"price":"0.00015731","size":"844.29"},{"price":"0.00015728","size":"0"}],"sequence":18307740,"timestamp":"2021-04-17T16:38:42.194Z","symbol":"OMGBTC"}}
1618677522.268644: {"jsonrpc":"2.0","method":"updateOrderbook","params":{"ask":[{"price":"0.00007949","size":"6941.84"},{"price":"0.00007962","size":"0"}],"bid":[],"sequence":5856039,"timestamp":"2021-04-17T16:38:42.173Z","symbol":"DODOBTC"}}
1618677522.359107: {"jsonrpc":"2.0","method":"updateOrderbook","params":{"ask":[],"bid":[{"price":"0.00015727","size":"1394.00"},{"price":"0.00015696","size":"1821.71"},{"price":"0.00015693","size":"0"},{"price":"0.00015651","size":"555.11"}],"sequence":18307741,"timestamp":"2021-04-17T16:38:42.238Z","symbol":"OMGBTC"}}
1618677522.457133: {"jsonrpc":"2.0","method":"updateOrderbook","params":{"ask":[],"bid":[{"price":"0.00015747","size":"618.63"},{"price":"0.00015745","size":"0"},{"price":"0.00015730","size":"587.38"},{"price":"0.00015712","size":"0"}],"sequence":18307742,"timestamp":"2021-04-17T16:38:42.396Z","symbol":"OMGBTC"}}
1618677522.556788: {"jsonrpc":"2.0","method":"updateOrderbook","params":{"ask":[],"bid":[{"price":"0.00015631","size":"3145.03"},{"price":"0.00015615","size":"0"}],"sequence":18307743,"timestamp":"2021-04-17T16:38:42.519Z","symbol":"OMGBTC"}}
1618677522.567719: {"jsonrpc":"2.0","method":"updateOrderbook","params":{"ask":[],"bid":[{"price":"0.00007525","size":"0.05"}],"sequence":5856040,"timestamp":"2021-04-17T16:38:42.469Z","symbol":"DODOBTC"}}
1618677522.567984: {"jsonrpc":"2.0","method":"updateOrderbook","params":{"ask":[{"price":"0.0167529","size":"784.70"},{"price":"0.0167609","size":"0"},{"price":"0.0168169","size":"1198.56"},{"price":"0.0168301","size":"0"}],"bid":[],"sequence":6928577,"timestamp":"2021-04-17T16:38:42.449Z","symbol":"ETCETH"}}
1618677522.653945: {"jsonrpc":"2.0","method":"updateOrderbook","params":{"ask":[{"price":"0.00015858","size":"2128.07"},{"price":"0.00015871","size":"0"}],"bid":[],"sequence":18307744,"timestamp":"2021-04-17T16:38:42.527Z","symbol":"OMGBTC"}}
1618677522.753254: {"jsonrpc":"2.0","method":"updateOrderbook","params":{"ask":[],"bid":[{"price":"0.00015756","size":"67.05"},{"price":"0.00015752","size":"160.92"},{"price":"0.00015749","size":"246.65"},{"price":"0.00015746","size":"0"}],"sequence":18307745,"timestamp":"2021-04-17T16:38:42.632Z","symbol":"OMGBTC"}}
1618677522.7617018: {"jsonrpc":"2.0","method":"updateOrderbook","params":{"ask":[],"bid":[{"price":"0.00007525","size":"0"}],"sequence":5856041,"timestamp":"2021-04-17T16:38:42.634Z","symbol":"DODOBTC"}}
1618677522.850975: {"jsonrpc":"2.0","method":"updateOrderbook","params":{"ask":[],"bid":[{"price":"0.00401","size":"1100.00"},{"price":"0.00251","size":"1200.00"}],"sequence":4905791,"timestamp":"2021-04-17T16:38:42.780Z","symbol":"HEDGUSD"}}
1618677522.8597498: {"jsonrpc":"2.0","method":"updateOrderbook","params":{"ask":[],"bid":[{"price":"0.00007469","size":"2668.80"},{"price":"0.00007453","size":"0"},{"price":"0.00006974","size":"18464.79"},{"price":"0.00006971","size":"0"}],"sequence":5856042,"timestamp":"2021-04-17T16:38:42.780Z","symbol":"DODOBTC"}}
1618677522.86949: {"jsonrpc":"2.0","method":"updateOrderbook","params":{"ask":[{"price":"0.00025479","size":"2900.0"},{"price":"0.00025499","size":"3000.0"}],"bid":[],"sequence":9316128,"timestamp":"2021-04-17T16:38:42.779Z","symbol":"XLMETH"}}
1618677522.957979: {"jsonrpc":"2.0","method":"updateOrderbook","params":{"ask":[],"bid":[{"price":"0.00015730","size":"0"},{"price":"0.00015712","size":"587.38"},{"price":"0.00015574","size":"5478.09"},{"price":"0.00015509","size":"0"}],"sequence":18307746,"timestamp":"2021-04-17T16:38:42.894Z","symbol":"OMGBTC"}}
1618677522.97139: {"jsonrpc":"2.0","method":"updateOrderbook","params":{"ask":[{"price":"0.001327481","size":"51644"},{"price":"0.001327900","size":"0"}],"bid":[],"sequence":5053522,"timestamp":"2021-04-17T16:38:42.845Z","symbol":"ADABCH"}}
1618677522.974415: {"jsonrpc":"2.0","method":"updateOrderbook","params":{"ask":[{"price":"0.00025479","size":"0"},{"price":"0.00025499","size":"5900.0"}],"bid":[{"price":"0.00025410","size":"2900.0"},{"price":"0.00025352","size":"3000.0"}],"sequence":9316129,"timestamp":"2021-04-17T16:38:42.866Z","symbol":"XLMETH"}}
1618677523.063553: {"jsonrpc":"2.0","method":"updateOrderbook","params":{"ask":[],"bid":[{"price":"0.00015714","size":"587.38"},{"price":"0.00015712","size":"0"}],"sequence":18307747,"timestamp":"2021-04-17T16:38:43.017Z","symbol":"OMGBTC"}}
1618677523.072064: {"jsonrpc":"2.0","method":"updateOrderbook","params":{"ask":[{"price":"0.001348155","size":"0"},{"price":"0.001348659","size":"57592"},{"price":"0.001361602","size":"0"},{"price":"0.001362058","size":"48957"},{"price":"0.001367163","size":"0"},{"price":"0.001367757","size":"53225"},{"price":"0.001372041","size":"0"},{"price":"0.001372832","size":"52392"},{"price":"0.001377617","size":"0"},{"price":"0.001378429","size":"54882"},{"price":"0.001382395","size":"0"},{"price":"0.001383273","size":"49573"},{"price":"0.001386945","size":"0"},{"price":"0.001387837","size":"49200"}],"bid":[{"price":"0.001312161","size":"11"},{"price":"0.001236465","size":"0"},{"price":"0.001236048","size":"44259"},{"price":"0.001230640","size":"0"},{"price":"0.001230161","size":"40551"},{"price":"0.001225861","size":"0"},{"price":"0.001225324","size":"37571"}],"sequence":5053523,"timestamp":"2021-04-17T16:38:42.986Z","symbol":"ADABCH"}}
1618677523.159675: {"jsonrpc":"2.0","method":"updateOrderbook","params":{"ask":[],"bid":[{"price":"0.00015758","size":"160.91"},{"price":"0.00015752","size":"0.01"},{"price":"0.00015734","size":"839.60"},{"price":"0.00015731","size":"63.49"},{"price":"0.00015715","size":"670.43"},{"price":"0.00015710","size":"0"},{"price":"0.00015689","size":"308.69"},{"price":"0.00015680","size":"0"}],"sequence":18307748,"timestamp":"2021-04-17T16:38:43.117Z","symbol":"OMGBTC"}}
1618677523.165594: {"jsonrpc":"2.0","method":"updateOrderbook","params":{"ask":[],"bid":[{"price":"0.00007498","size":"1734.72"},{"price":"0.00007494","size":"3.65"}],"sequence":5856043,"timestamp":"2021-04-17T16:38:43.074Z","symbol":"DODOBTC"}}
1618677523.179243: {"jsonrpc":"2.0","method":"updateOrderbook","params":{"ask":[{"price":"0.00025591","size":"0"}],"bid":[{"price":"0.00025410","size":"5900.0"},{"price":"0.00025352","size":"0"},{"price":"0.00025308","size":"6000.0"},{"price":"0.00025288","size":"0"}],"sequence":9316130,"timestamp":"2021-04-17T16:38:43.112Z","symbol":"XLMETH"}}
1618677523.253931: {"jsonrpc":"2.0","method":"updateOrderbook","params":{"ask":[{"price":"0.00015825","size":"162.38"},{"price":"0.00015826","size":"0"},{"price":"0.00015827","size":"2302.58"},{"price":"0.00015830","size":"958.98"},{"price":"0.00015839","size":"0"},{"price":"0.00015845","size":"424.96"},{"price":"0.00015875","size":"245.17"},{"price":"0.00015879","size":"633.98"}],"bid":[{"price":"0.00015762","size":"160.91"},{"price":"0.00015758","size":"0"},{"price":"0.00015757","size":"170.13"},{"price":"0.00015753","size":"100.65"},{"price":"0.00015748","size":"9.55"},{"price":"0.00015747","size":"448.50"},{"price":"0.00015744","size":"780.80"},{"price":"0.00015743","size":"0"},{"price":"0.00015742","size":"0"},{"price":"0.00015739","size":"803.33"},{"price":"0.00015738","size":"0"},{"price":"0.00015734","size":"58.80"},{"price":"0.00015727","size":"670.43"},{"price":"0.00015723","size":"963.02"},{"price":"0.00015715","size":"0"},{"price":"0.00015700","size":"1394.00"},{"price":"0.00015696","size":"0"},{"price":"0.00015661","size":"2204.30"},{"price":"0.00015648","size":"0"},{"price":"0.00015635","size":"2504.10"},{"price":"0.00015631","size":"0"},{"price":"0.00015620","size":"4189.92"},{"price":"0.00015603","size":"4043.77"},{"price":"0.00015592","size":"0"},{"price":"0.00015574","size":"0"},{"price":"0.00015522","size":"5478.09"}],"sequence":18307749,"timestamp":"2021-04-17T16:38:43.224Z","symbol":"OMGBTC"}}
1618677523.2545002: {"jsonrpc":"2.0","method":"updateOrderbook","params":{"ask":[],"bid":[{"price":"4.54813","size":"570.65"},{"price":"4.54774","size":"0"}],"sequence":7132771,"timestamp":"2021-04-17T16:38:43.168Z","symbol":"DODOUSD"}}
1618677523.264711: {"jsonrpc":"2.0","method":"updateOrderbook","params":{"ask":[{"price":"0.00025599","size":"38.8"}],"bid":[],"sequence":9316131,"timestamp":"2021-04-17T16:38:43.206Z","symbol":"XLMETH"}}
1618677523.353179: {"jsonrpc":"2.0","method":"updateOrderbook","params":{"ask":[{"price":"0.00015802","size":"0"},{"price":"0.00015807","size":"929.78"},{"price":"0.00015810","size":"0"},{"price":"0.00015815","size":"929.39"},{"price":"0.00015818","size":"200.00"},{"price":"0.00015821","size":"550.49"},{"price":"0.00015830","size":"298.44"},{"price":"0.00015838","size":"660.54"},{"price":"0.00015842","size":"0"},{"price":"0.00015846","size":"0"},{"price":"0.00015852","size":"112.21"},{"price":"0.00015854","size":"551.24"},{"price":"0.00015856","size":"112.89"},{"price":"0.00015861","size":"149.59"},{"price":"0.00017807","size":"0"},{"price":"0.00017864","size":"2362.68"}],"bid":[{"price":"0.00015748","size":"0"},{"price":"0.00015732","size":"679.98"},{"price":"0.00015727","size":"0"},{"price":"0.00015714","size":"697.70"},{"price":"0.00015708","size":"0"},{"price":"0.00015655","size":"325.79"},{"price":"0.00015641","size":"0"},{"price":"0.00015581","size":"1746.35"},{"price":"0.00015552","size":"0"},{"price":"0.00015520","size":"0"}],"sequence":18307750,"timestamp":"2021-04-17T16:38:43.307Z","symbol":"OMGBTC"}}
1618677523.3668969: {"jsonrpc":"2.0","method":"updateOrderbook","params":{"ask":[{"price":"0.00025499","size":"2900.0"},{"price":"0.00025526","size":"3000.0"},{"price":"0.00025574","size":"0"},{"price":"0.00025586","size":"10000.0"},{"price":"0.00026576","size":"60813.9"},{"price":"0.00026593","size":"0"},{"price":"0.00026594","size":"0"},{"price":"0.00026668","size":"64506.9"},{"price":"0.00026708","size":"0"},{"price":"0.00026746","size":"56304.9"},{"price":"0.00026796","size":"0"}],"bid":[],"sequence":9316132,"timestamp":"2021-04-17T16:38:43.312Z","symbol":"XLMETH"}}
1618677523.459563: {"jsonrpc":"2.0","method":"updateOrderbook","params":{"ask":[{"price":"0.00015807","size":"429.72"},{"price":"0.00015810","size":"500.06"},{"price":"0.00015821","size":"0"},{"price":"0.00015825","size":"712.87"},{"price":"0.00015838","size":"0"},{"price":"0.00015842","size":"660.54"},{"price":"0.00015858","size":"0"},{"price":"0.00015869","size":"2292.79"},{"price":"0.00015880","size":"0"},{"price":"0.00015890","size":"227.54"},{"price":"0.00015909","size":"0"},{"price":"0.00015926","size":"0"},{"price":"0.00015929","size":"549.86"},{"price":"0.00015951","size":"787.61"}],"bid":[{"price":"0.00015745","size":"9.55"},{"price":"0.00015732","size":"670.43"},{"price":"0.00015560","size":"185.32"}],"sequence":18307751,"timestamp":"2021-04-17T16:38:43.389Z","symbol":"OMGBTC"}}
1618677523.46703: {"jsonrpc":"2.0","method":"updateOrderbook","params":{"ask":[{"price":"0.00025499","size":"5900.0"},{"price":"0.00025526","size":"0"},{"price":"0.00026575","size":"10050.9"}],"bid":[],"sequence":9316133,"timestamp":"2021-04-17T16:38:43.417Z","symbol":"XLMETH"}}
1618677523.558149: {"jsonrpc":"2.0","method":"updateOrderbook","params":{"ask":[{"price":"0.00015797","size":"0"},{"price":"0.00015798","size":"72.33"},{"price":"0.00015801","size":"0"},{"price":"0.00015804","size":"245.28"},{"price":"0.00015820","size":"149.45"},{"price":"0.00015834","size":"200.00"}],"bid":[{"price":"0.00015758","size":"200.00"},{"price":"0.00015750","size":"0"},{"price":"0.00015748","size":"9.55"},{"price":"0.00015745","size":"0"},{"price":"0.00015714","size":"110.32"},{"price":"0.00015707","size":"587.38"}],"sequence":18307752,"timestamp":"2021-04-17T16:38:43.523Z","symbol":"OMGBTC"}}
1618677523.558523: {"jsonrpc":"2.0","method":"updateOrderbook","params":{"ask":[],"bid":[{"price":"4.20069","size":"133.36"},{"price":"3.87163","size":"0"},{"price":"3.22645","size":"175.25"},{"price":"1.96392","size":"0"}],"sequence":7132772,"timestamp":"2021-04-17T16:38:43.499Z","symbol":"DODOUSD"}}
1618677523.588107: {"jsonrpc":"2.0","method":"updateOrderbook","params":{"ask":[{"price":"0.001319841","size":"3810"},{"price":"0.001320261","size":"0"}],"bid":[],"sequence":5053524,"timestamp":"2021-04-17T16:38:43.444Z","symbol":"ADABCH"}}
1618677523.588327: {"jsonrpc":"2.0","method":"updateOrderbook","params":{"ask":[{"price":"0.00025499","size":"2900.0"},{"price":"0.00025526","size":"3000.0"}],"bid":[],"sequence":9316134,"timestamp":"2021-04-17T16:38:43.446Z","symbol":"XLMETH"}}
1618677523.5884318: {"jsonrpc":"2.0","method":"updateOrderbook","params":{"ask":[{"price":"0.0167412","size":"0"}],"bid":[],"sequence":6928578,"timestamp":"2021-04-17T16:38:43.513Z","symbol":"ETCETH"}}
1618677523.6729238: {"jsonrpc":"2.0","method":"updateOrderbook","params":{"ask":[{"price":"0.00015788","size":"0"},{"price":"0.00015793","size":"0"},{"price":"0.00015798","size":"0"},{"price":"0.00015799","size":"72.33"},{"price":"0.00015800","size":"0"},{"price":"0.00015803","size":"42.78"},{"price":"0.00015804","size":"290.61"},{"price":"0.00015810","size":"245.28"},{"price":"0.00015811","size":"80.55"},{"price":"0.00015813","size":"370.08"},{"price":"0.00015815","size":"0"},{"price":"0.00015818","size":"0"},{"price":"0.00015819","size":"0"},{"price":"0.00015823","size":"692.41"},{"price":"0.00015825","size":"162.38"},{"price":"0.00015827","size":"1028.25"},{"price":"0.00015829","size":"200.00"},{"price":"0.00015830","size":"234.96"},{"price":"0.00015837","size":"550.49"},{"price":"0.00015838","size":"929.39"},{"price":"0.00015842","size":"0"},{"price":"0.00015847","size":"660.54"},{"price":"0.00015853","size":"63.44"},{"price":"0.00015861","size":"0"},{"price":"0.00015866","size":"0"},{"price":"0.00015869","size":"149.59"},{"price":"0.00015875","size":"0"},{"price":"0.00015876","size":"1429.12"},{"price":"0.00015881","size":"164.72"},{"price":"0.00015885","size":"245.17"},{"price":"0.00015894","size":"2185.31"},{"price":"0.00015897","size":"2128.07"},{"price":"0.00015901","size":"0"},{"price":"0.00015904","size":"0"},{"price":"0.00015914","size":"0"},{"price":"0.00015926","size":"463.05"},{"price":"0.00015937","size":"0"},{"price":"0.00015943","size":"2.45"},{"price":"0.00015944","size":"984.17"},{"price":"0.00015951","size":"0"},{"price":"0.00015955","size":"0"},{"price":"0.00015960","size":"3008.25"},{"price":"0.00015969","size":"4402.08"},{"price":"0.00015970","size":"787.61"},{"price":"0.00015990","size":"0"},{"price":"0.00016342","size":"5617.94"},{"price":"0.00017864","size":"0"},{"price":"0.00017980","size":"2362.68"}],"bid":[{"price":"0.00015750","size":"200.00"},{"price":"0.00015739","size":"603.33"}],"sequence":18307753,"timestamp":"2021-04-17T16:38:43.622Z","symbol":"OMGBTC"}}
1618677523.673624: {"jsonrpc":"2.0","method":"updateOrderbook","params":{"ask":[{"price":"0.00007883","size":"7233.03"},{"price":"0.00007896","size":"0"},{"price":"0.00008047","size":"7519.84"},{"price":"0.00008056","size":"0"},{"price":"0.00008085","size":"7976.98"},{"price":"0.00008092","size":"0"},{"price":"0.00008114","size":"7674.28"},{"price":"0.00008122","size":"0"},{"price":"0.00008138","size":"7110.11"},{"price":"0.00008144","size":"0"}],"bid":[],"sequence":5856044,"timestamp":"2021-04-17T16:38:43.569Z","symbol":"DODOBTC"}}
1618677523.677462: {"jsonrpc":"2.0","method":"updateOrderbook","params":{"ask":[{"price":"0.00025499","size":"5900.0"},{"price":"0.00025526","size":"0"}],"bid":[],"sequence":9316135,"timestamp":"2021-04-17T16:38:43.549Z","symbol":"XLMETH"}}
1618677523.7620301: {"jsonrpc":"2.0","method":"updateOrderbook","params":{"ask":[{"price":"0.00015799","size":"0"},{"price":"0.00015800","size":"72.33"},{"price":"0.00015804","size":"0"},{"price":"0.00015807","size":"0"},{"price":"0.00015810","size":"290.61"},{"price":"0.00015812","size":"245.28"},{"price":"0.00015813","size":"0"},{"price":"0.00015823","size":"1062.49"},{"price":"0.00015826","size":"429.72"},{"price":"0.00015827","size":"0"},{"price":"0.00015833","size":"500.06"},{"price":"0.00015837","size":"0"},{"price":"0.00015838","size":"0"},{"price":"0.00015842","size":"550.49"},{"price":"0.00015843","size":"528.19"},{"price":"0.00015844","size":"929.39"},{"price":"0.00015845","size":"0"},{"price":"0.00015847","size":"0"},{"price":"0.00015850","size":"424.96"},{"price":"0.00015851","size":"660.54"},{"price":"0.00015852","size":"0"},{"price":"0.00015854","size":"0"},{"price":"0.00015856","size":"0"},{"price":"0.00015862","size":"112.21"},{"price":"0.00015863","size":"551.24"},{"price":"0.00015866","size":"112.89"},{"price":"0.00015876","size":"156.33"},{"price":"0.00015879","size":"0"},{"price":"0.00015887","size":"1272.79"},{"price":"0.00015889","size":"0"},{"price":"0.00015892","size":"633.98"},{"price":"0.00015899","size":"0"},{"price":"0.00015912","size":"0"},{"price":"0.00015915","size":"241.71"},{"price":"0.00015921","size":"830.99"},{"price":"0.00015923","size":"373.07"},{"price":"0.00015929","size":"0"},{"price":"0.00015944","size":"466.51"},{"price":"0.00015963","size":"1763.84"},{"price":"0.00016342","size":"0"},{"price":"0.00016385","size":"5617.94"}],"bid":[{"price":"0.00015763","size":"67.05"},{"price":"0.00015756","size":"246.65"},{"price":"0.00015754","size":"9.55"},{"price":"0.00015749","size":"0"},{"price":"0.00015748","size":"0"},{"price":"0.00015723","size":"1073.34"},{"price":"0.00015720","size":"587.38"},{"price":"0.00015714","size":"91.76"},{"price":"0.00015707","size":"0"},{"price":"0.00015704","size":"0"},{"price":"0.00015657","size":"768.35"},{"price":"0.00015653","size":"0"},{"price":"0.00015631","size":"3145.03"},{"price":"0.00015620","size":"1044.89"}],"sequence":18307754,"timestamp":"2021-04-17T16:38:43.725Z","symbol":"OMGBTC"}}
1618677523.853916: {"jsonrpc":"2.0","method":"updateOrderbook","params":{"ask":[{"price":"0.00015803","size":"0"},{"price":"0.00015809","size":"42.78"},{"price":"0.00015810","size":"0"},{"price":"0.00015817","size":"290.61"},{"price":"0.00015833","size":"0"},{"price":"0.00015835","size":"780.73"},{"price":"0.00015890","size":"0"},{"price":"0.00015908","size":"227.54"},{"price":"0.00015926","size":"0"},{"price":"0.00015942","size":"463.05"},{"price":"0.00016032","size":"0"},{"price":"0.00016048","size":"503.30"}],"bid":[{"price":"0.00015764","size":"9.55"},{"price":"0.00015754","size":"0"},{"price":"0.00015742","size":"603.33"},{"price":"0.00015739","size":"0"},{"price":"0.00015631","size":"0"},{"price":"0.00015621","size":"3678.80"}],"sequence":18307755,"timestamp":"2021-04-17T16:38:43.763Z","symbol":"OMGBTC"}}
1618677523.854388: {"jsonrpc":"2.0","method":"updateOrderbook","params":{"ask":[{"price":"4.66402","size":"0"},{"price":"4.66719","size":"10836.10"}],"bid":[],"sequence":7132773,"timestamp":"2021-04-17T16:38:43.759Z","symbol":"DODOUSD"}}
1618677523.956424: {"jsonrpc":"2.0","method":"updateOrderbook","params":{"ask":[{"price":"0.00015808","size":"290.61"},{"price":"0.00015809","size":"0"},{"price":"0.00015810","size":"42.78"},{"price":"0.00015814","size":"370.08"},{"price":"0.00015817","size":"0"},{"price":"0.00015823","size":"692.41"},{"price":"0.00015826","size":"0"},{"price":"0.00015828","size":"929.78"},{"price":"0.00015835","size":"280.67"},{"price":"0.00015840","size":"528.19"},{"price":"0.00015843","size":"0"},{"price":"0.00015847","size":"660.54"},{"price":"0.00015851","size":"0"},{"price":"0.00015863","size":"0"},{"price":"0.00015866","size":"664.13"},{"price":"0.00015885","size":"371.28"},{"price":"0.00015905","size":"245.17"},{"price":"0.00015921","size":"0"},{"price":"0.00015926","size":"830.99"},{"price":"0.00016048","size":"0"},{"price":"0.00016082","size":"503.30"},{"price":"0.00017980","size":"0"},{"price":"0.00018206","size":"2362.68"}],"bid":[{"price":"0.00015757","size":"189.73"},{"price":"0.00015756","size":"285.85"},{"price":"0.00015755","size":"58.80"},{"price":"0.00015750","size":"648.50"},{"price":"0.00015747","size":"0"},{"price":"0.00015736","size":"0"},{"price":"0.00015735","size":"0"},{"price":"0.00015734","size":"0"},{"price":"0.00015727","size":"587.38"},{"price":"0.00015720","size":"0"},{"price":"0.00015657","size":"0"},{"price":"0.00015645","size":"1033.82"}],"sequence":18307756,"timestamp":"2021-04-17T16:38:43.920Z","symbol":"OMGBTC"}}
1618677524.0566442: {"jsonrpc":"2.0","method":"updateOrderbook","params":{"ask":[{"price":"0.00015800","size":"0"},{"price":"0.00015807","size":"42.78"},{"price":"0.00015810","size":"72.33"},{"price":"0.00015812","size":"0"},{"price":"0.00015818","size":"245.28"}],"bid":[{"price":"0.00015764","size":"76.60"},{"price":"0.00015763","size":"0"},{"price":"0.00015742","size":"0"},{"price":"0.00015739","size":"603.33"},{"price":"0.00015723","size":"110.32"},{"price":"0.00015714","size":"1054.78"},{"price":"0.00015700","size":"0"},{"price":"0.00015694","size":"1394.00"},{"price":"0.00015661","size":"382.59"},{"price":"0.00015653","size":"1821.71"},{"price":"0.00015641","size":"533.77"},{"price":"0.00015621","size":"3145.03"},{"price":"0.00015522","size":"0"},{"price":"0.00015502","size":"5478.09"}],"sequence":18307757,"timestamp":"2021-04-17T16:38:43.961Z","symbol":"OMGBTC"}}
1618677524.0712729: {"jsonrpc":"2.0","method":"updateOrderbook","params":{"ask":[],"bid":[{"price":"0.00025335","size":"10000.0"},{"price":"0.00025323","size":"0"}],"sequence":9316136,"timestamp":"2021-04-17T16:38:44.024Z","symbol":"XLMETH"}}
1618677524.156963: {"jsonrpc":"2.0","method":"updateOrderbook","params":{"ask":[{"price":"0.00015941","size":"2.45"},{"price":"0.00015943","size":"0"}],"bid":[{"price":"0.00015727","size":"0"},{"price":"0.00015714","size":"1642.16"},{"price":"0.00015645","size":"265.47"},{"price":"0.00015640","size":"768.35"}],"sequence":18307758,"timestamp":"2021-04-17T16:38:44.096Z","symbol":"OMGBTC"}}
1618677524.160706: {"jsonrpc":"2.0","method":"updateOrderbook","params":{"ask":[{"price":"0.001355550","size":"0"},{"price":"0.001356040","size":"58770"}],"bid":[{"price":"0.001243214","size":"0"},{"price":"0.001242799","size":"40379"}],"sequence":5053525,"timestamp":"2021-04-17T16:38:44.059Z","symbol":"ADABCH"}}
1618677524.26883: {"jsonrpc":"2.0","method":"updateOrderbook","params":{"ask":[{"price":"0.00015820","size":"0"},{"price":"0.00015825","size":"0"},{"price":"0.00015829","size":"0"},{"price":"0.00015830","size":"0"},{"price":"0.00015835","size":"0"},{"price":"0.00015839","size":"200.00"},{"price":"0.00015885","size":"0"},{"price":"0.00015902","size":"149.45"},{"price":"0.00015925","size":"162.38"},{"price":"0.00015930","size":"234.96"},{"price":"0.00015935","size":"280.67"},{"price":"0.00015940","size":"371.28"},{"price":"0.00015973","size":"0"},{"price":"0.00016022","size":"1828.03"}],"bid":[{"price":"0.00015758","size":"446.65"},{"price":"0.00015756","size":"39.20"}],"sequence":18307759,"timestamp":"2021-04-17T16:38:44.186Z","symbol":"OMGBTC"}}
1618677524.377557: {"jsonrpc":"2.0","method":"updateOrderbook","params":{"ask":[],"bid":[{"price":"0.00015748","size":"780.80"},{"price":"0.00015744","size":"0"},{"price":"0.00015736","size":"670.43"},{"price":"0.00015732","size":"0"},{"price":"0.00015728","size":"110.32"},{"price":"0.00015724","size":"91.76"},{"price":"0.00015723","size":"0"},{"price":"0.00015714","size":"1550.40"},{"price":"0.00015671","size":"325.79"},{"price":"0.00015655","size":"0"}],"sequence":18307760,"timestamp":"2021-04-17T16:38:44.294Z","symbol":"OMGBTC"}}
1618677524.4698591: {"jsonrpc":"2.0","method":"updateOrderbook","params":{"ask":[{"price":"0.00015807","size":"0"},{"price":"0.00015813","size":"42.78"},{"price":"0.00015822","size":"500.06"},{"price":"0.00015825","size":"929.39"},{"price":"0.00015828","size":"429.72"},{"price":"0.00015838","size":"550.49"},{"price":"0.00015842","size":"0"},{"price":"0.00015844","size":"0"},{"price":"0.00015852","size":"112.21"},{"price":"0.00015856","size":"112.89"},{"price":"0.00015862","size":"0"},{"price":"0.00015866","size":"551.24"},{"price":"0.00015907","size":"373.07"},{"price":"0.00015923","size":"0"},{"price":"0.00015941","size":"552.31"},{"price":"0.00015963","size":"1213.98"}],"bid":[{"price":"0.00015760","size":"246.65"},{"price":"0.00015758","size":"200.00"}],"sequence":18307761,"timestamp":"2021-04-17T16:38:44.382Z","symbol":"OMGBTC"}}
1618677524.470313: {"jsonrpc":"2.0","method":"updateOrderbook","params":{"ask":[{"price":"4.66719","size":"0"},{"price":"4.67567","size":"10836.10"},{"price":"4.72248","size":"0"},{"price":"4.72772","size":"15561.71"},{"price":"4.79082","size":"0"},{"price":"4.79707","size":"21772.25"},{"price":"4.88027","size":"0"},{"price":"4.88543","size":"28569.63"}],"bid":[],"sequence":7132774,"timestamp":"2021-04-17T16:38:44.365Z","symbol":"DODOUSD"}}
1618677524.4704251: {"jsonrpc":"2.0","method":"updateOrderbook","params":{"ask":[{"price":"0.00007664","size":"0"},{"price":"0.00007669","size":"7907.51"},{"price":"0.00007740","size":"0"},{"price":"0.00007746","size":"7289.69"},{"price":"0.00007819","size":"0"},{"price":"0.00007826","size":"7949.54"},{"price":"0.00007883","size":"0"},{"price":"0.00007891","size":"7233.03"},{"price":"0.00007949","size":"0"},{"price":"0.00007955","size":"6942.01"},{"price":"0.00008004","size":"0"},{"price":"0.00008010","size":"8110.60"},{"price":"0.00008047","size":"0"},{"price":"0.00008052","size":"7519.84"},{"price":"0.00008085","size":"0"},{"price":"0.00008089","size":"7976.98"},{"price":"0.00008114","size":"0"},{"price":"0.00008118","size":"7674.28"},{"price":"0.00008138","size":"0"},{"price":"0.00008142","size":"7110.11"}],"bid":[],"sequence":5856045,"timestamp":"2021-04-17T16:38:44.382Z","symbol":"DODOBTC"}}
1618677524.477799: {"jsonrpc":"2.0","method":"updateOrderbook","params":{"ask":[{"price":"0.00025573","size":"0"},{"price":"0.00025585","size":"8.4"}],"bid":[{"price":"0.00025324","size":"0"},{"price":"0.00025309","size":"0.3"},{"price":"0.00025275","size":"5000.0"},{"price":"0.00025252","size":"0"}],"sequence":9316137,"timestamp":"2021-04-17T16:38:44.420Z","symbol":"XLMETH"}}
1618677524.562335: {"jsonrpc":"2.0","method":"updateOrderbook","params":{"ask":[{"price":"0.00015807","size":"42.78"},{"price":"0.00015813","size":"0"},{"price":"0.00015828","size":"0"},{"price":"0.00015829","size":"200.00"},{"price":"0.00015830","size":"429.72"},{"price":"0.00015839","size":"0"},{"price":"0.00015840","size":"0"},{"price":"0.00015843","size":"528.19"},{"price":"0.00015866","size":"0"},{"price":"0.00015874","size":"551.24"}],"bid":[{"price":"0.00015765","size":"67.05"},{"price":"0.00015764","size":"9.55"},{"price":"0.00015714","size":"963.02"},{"price":"0.00015703","size":"587.38"},{"price":"0.00015646","size":"1273.82"},{"price":"0.00015640","size":"0"}],"sequence":18307762,"timestamp":"2021-04-17T16:38:44.501Z","symbol":"OMGBTC"}}
1618677524.57456: {"jsonrpc":"2.0","method":"updateOrderbook","params":{"ask":[],"bid":[{"price":"0.00007525","size":"0.05"}],"sequence":5856046,"timestamp":"2021-04-17T16:38:44.468Z","symbol":"DODOBTC"}}
1618677524.663687: {"jsonrpc":"2.0","method":"updateOrderbook","params":{"ask":[{"price":"0.00015939","size":"2.45"},{"price":"0.00015941","size":"549.86"}],"bid":[{"price":"0.00015766","size":"9.55"},{"price":"0.00015764","size":"0"},{"price":"0.00015749","size":"963.02"},{"price":"0.00015748","size":"0"},{"price":"0.00015745","size":"780.80"},{"price":"0.00015728","size":"0"},{"price":"0.00015724","size":"0"},{"price":"0.00015723","size":"110.32"},{"price":"0.00015714","size":"91.76"}],"sequence":18307763,"timestamp":"2021-04-17T16:38:44.616Z","symbol":"OMGBTC"}}
1618677524.677: {"jsonrpc":"2.0","method":"updateOrderbook","params":{"ask":[],"bid":[{"price":"0.00007525","size":"0"}],"sequence":5856047,"timestamp":"2021-04-17T16:38:44.598Z","symbol":"DODOBTC"}}
1618677524.6771772: {"jsonrpc":"2.0","method":"updateOrderbook","params":{"ask":[{"price":"0.001315836","size":"457"},{"price":"0.001316239","size":"0"}],"bid":[],"sequence":5053526,"timestamp":"2021-04-17T16:38:44.575Z","symbol":"ADABCH"}}
1618677524.768814: {"jsonrpc":"2.0","method":"updateOrderbook","params":{"ask":[{"price":"0.00015827","size":"429.72"},{"price":"0.00015830","size":"1272.79"},{"price":"0.00015840","size":"528.19"},{"price":"0.00015843","size":"0"},{"price":"0.00015849","size":"1774.39"},{"price":"0.00015866","size":"551.24"},{"price":"0.00015874","size":"0"},{"price":"0.00015887","size":"0"},{"price":"0.00015894","size":"410.92"}],"bid":[{"price":"0.00015752","size":"603.34"},{"price":"0.00015739","size":"0"},{"price":"0.00015685","size":"271.61"},{"price":"0.00015680","size":"225.06"},{"price":"0.00015675","size":"427.58"},{"price":"0.00015667","size":"0"},{"price":"0.00015658","size":"0"},{"price":"0.00015645","size":"0"}],"sequence":18307764,"timestamp":"2021-04-17T16:38:44.723Z","symbol":"OMGBTC"}}
1618677524.8060591: {"jsonrpc":"2.0","method":"updateOrderbook","params":{"ask":[{"price":"0.0167529","size":"0"},{"price":"0.0167587","size":"784.52"}],"bid":[],"sequence":6928579,"timestamp":"2021-04-17T16:38:44.720Z","symbol":"ETCETH"}}
1618677524.871122: {"jsonrpc":"2.0","method":"updateOrderbook","params":{"ask":[{"price":"0.00015889","size":"2128.07"},{"price":"0.00015897","size":"0"}],"bid":[],"sequence":18307765,"timestamp":"2021-04-17T16:38:44.818Z","symbol":"OMGBTC"}}
1618677524.886179: {"jsonrpc":"2.0","method":"updateOrderbook","params":{"ask":[{"price":"0.0168169","size":"0"},{"price":"0.0168258","size":"1198.28"}],"bid":[],"sequence":6928580,"timestamp":"2021-04-17T16:38:44.736Z","symbol":"ETCETH"}}
1618677524.981266: {"jsonrpc":"2.0","method":"updateOrderbook","params":{"ask":[{"price":"0.00015823","size":"1122.13"},{"price":"0.00015827","size":"0"},{"price":"0.00015837","size":"528.19"},{"price":"0.00015840","size":"0"},{"price":"0.00015860","size":"551.24"},{"price":"0.00015866","size":"0"},{"price":"0.00015888","size":"633.98"},{"price":"0.00015892","size":"0"},{"price":"0.00015910","size":"830.99"},{"price":"0.00015926","size":"0"},{"price":"0.00015944","size":"984.17"},{"price":"0.00016032","size":"503.30"},{"price":"0.00016082","size":"0"}],"bid":[{"price":"0.00015753","size":"549.15"},{"price":"0.00015750","size":"200.00"},{"price":"0.00015732","size":"1394.00"},{"price":"0.00015717","size":"587.38"},{"price":"0.00015703","size":"0"},{"price":"0.00015697","size":"1821.71"},{"price":"0.00015694","size":"0"},{"price":"0.00015653","size":"0"}],"sequence":18307766,"timestamp":"2021-04-17T16:38:44.905Z","symbol":"OMGBTC"}}
1618677524.996555: {"jsonrpc":"2.0","method":"updateOrderbook","params":{"ask":[],"bid":[{"price":"0.00025376","size":"7870.9"},{"price":"0.00025351","size":"0"}],"sequence":9316138,"timestamp":"2021-04-17T16:38:44.833Z","symbol":"XLMETH"}}
1618677525.072955: {"jsonrpc":"2.0","method":"updateOrderbook","params":{"ask":[{"price":"0.00015901","size":"3008.25"},{"price":"0.00015960","size":"0"}],"bid":[],"sequence":18307767,"timestamp":"2021-04-17T16:38:45.010Z","symbol":"OMGBTC"}}
1618677525.07317: {"jsonrpc":"2.0","method":"updateOrderbook","params":{"ask":[],"bid":[{"price":"0.001312161","size":"0"}],"sequence":5053527,"timestamp":"2021-04-17T16:38:44.973Z","symbol":"ADABCH"}}
1618677525.07333: {"jsonrpc":"2.0","method":"updateOrderbook","params":{"ask":[{"price":"0.0167658","size":"72.92"}],"bid":[],"sequence":6928581,"timestamp":"2021-04-17T16:38:45.008Z","symbol":"ETCETH"}}
1618677525.376621: {"jsonrpc":"2.0","method":"updateOrderbook","params":{"ask":[{"price":"0.00015810","size":"0"},{"price":"0.00015811","size":"152.88"},{"price":"0.00015823","size":"692.41"},{"price":"0.00015827","size":"429.72"},{"price":"0.00015837","size":"0"},{"price":"0.00015840","size":"528.19"},{"price":"0.00015860","size":"0"},{"price":"0.00015866","size":"551.24"}],"bid":[],"sequence":18307768,"timestamp":"2021-04-17T16:38:45.094Z","symbol":"OMGBTC"}}
1618677525.376907: {"jsonrpc":"2.0","method":"updateOrderbook","params":{"ask":[],"bid":[{"price":"0.001311032","size":"0"},{"price":"0.001310504","size":"520"}],"sequence":5053528,"timestamp":"2021-04-17T16:38:45.196Z","symbol":"ADABCH"}}
1618677525.3811111: {"jsonrpc":"2.0","method":"updateOrderbook","params":{"ask":[{"price":"0.00016008","size":"5617.94"},{"price":"0.00016385","size":"0"}],"bid":[{"price":"0.00015766","size":"209.55"},{"price":"0.00015758","size":"0"}],"sequence":18307769,"timestamp":"2021-04-17T16:38:45.312Z","symbol":"OMGBTC"}}
1618677525.3812768: {"jsonrpc":"2.0","method":"updateOrderbook","params":{"ask":[{"price":"4.87989","size":"28569.63"},{"price":"4.88543","size":"0"}],"bid":[],"sequence":7132775,"timestamp":"2021-04-17T16:38:45.264Z","symbol":"DODOUSD"}}
1618677525.381351: {"jsonrpc":"2.0","method":"updateOrderbook","params":{"ask":[],"bid":[{"price":"0.001305876","size":"0"},{"price":"0.001305482","size":"4338"}],"sequence":5053529,"timestamp":"2021-04-17T16:38:45.308Z","symbol":"ADABCH"}}
1618677525.381414: {"jsonrpc":"2.0","method":"updateOrderbook","params":{"ask":[],"bid":[{"price":"0.00025436","size":"1180.6"},{"price":"0.00025424","size":"0"}],"sequence":9316139,"timestamp":"2021-04-17T16:38:45.236Z","symbol":"XLMETH"}}
1618677525.479917: {"jsonrpc":"2.0","method":"updateOrderbook","params":{"ask":[{"price":"0.00015810","size":"72.33"},{"price":"0.00015811","size":"80.55"},{"price":"0.00015815","size":"245.28"},{"price":"0.00015818","size":"0"},{"price":"0.00015885","size":"245.17"},{"price":"0.00015890","size":"227.54"},{"price":"0.00015895","size":"241.71"},{"price":"0.00015905","size":"0"},{"price":"0.00015908","size":"0"},{"price":"0.00015915","size":"0"},{"price":"0.00015925","size":"625.43"},{"price":"0.00015942","size":"0"}],"bid":[{"price":"0.00015766","size":"200.00"},{"price":"0.00015763","size":"9.55"},{"price":"0.00015697","size":"0"},{"price":"0.00015687","size":"1821.71"},{"price":"0.00015637","size":"2504.11"},{"price":"0.00015635","size":"0"},{"price":"0.00015631","size":"3145.03"},{"price":"0.00015621","size":"0"}],"sequence":18307770,"timestamp":"2021-04-17T16:38:45.414Z","symbol":"OMGBTC"}}
1618677525.558629: {"jsonrpc":"2.0","method":"updateOrderbook","params":{"ask":[],"bid":[{"price":"0.00015766","size":"267.05"},{"price":"0.00015765","size":"0"},{"price":"0.00015559","size":"8155.26"},{"price":"0.00015502","size":"0"}],"sequence":18307771,"timestamp":"2021-04-17T16:38:45.475Z","symbol":"OMGBTC"}}
1618677525.669814: {"jsonrpc":"2.0","method":"updateOrderbook","params":{"ask":[{"price":"0.00015829","size":"0"},{"price":"0.00015837","size":"200.00"},{"price":"0.00015910","size":"0"},{"price":"0.00015915","size":"830.99"}],"bid":[{"price":"0.00015767","size":"9.55"},{"price":"0.00015763","size":"0"}],"sequence":18307772,"timestamp":"2021-04-17T16:38:45.621Z","symbol":"OMGBTC"}}
1618677525.673592: {"jsonrpc":"2.0","method":"updateOrderbook","params":{"ask":[{"price":"4.66327","size":"10836.10"},{"price":"4.67567","size":"0"}],"bid":[],"sequence":7132776,"timestamp":"2021-04-17T16:38:45.558Z","symbol":"DODOUSD"}}
1618677525.6801238: {"jsonrpc":"2.0","method":"updateOrderbook","params":{"ask":[{"price":"0.00012946","size":"0"},{"price":"0.00012947","size":"3.00"}],"bid":[],"sequence":5856048,"timestamp":"2021-04-17T16:38:45.597Z","symbol":"DODOBTC"}}
1618677525.7741911: {"jsonrpc":"2.0","method":"updateOrderbook","params":{"ask":[{"price":"0.00015985","size":"1828.03"},{"price":"0.00016022","size":"0"}],"bid":[{"price":"0.00015736","size":"0"},{"price":"0.00015732","size":"2064.43"},{"price":"0.00015723","size":"0"},{"price":"0.00015718","size":"110.32"},{"price":"0.00015671","size":"0"},{"price":"0.00015657","size":"325.79"}],"sequence":18307773,"timestamp":"2021-04-17T16:38:45.684Z","symbol":"OMGBTC"}}
1618677525.794708: {"jsonrpc":"2.0","method":"updateOrderbook","params":{"ask":[],"bid":[{"price":"0.000000045","size":"454.4"},{"price":"0.000000044","size":"50187.2"}],"sequence":651385,"timestamp":"2021-04-17T16:38:45.708Z","symbol":"HUBBTC"}}
1618677525.7948852: {"jsonrpc":"2.0","method":"updateOrderbook","params":{"ask":[],"bid":[{"price":"0.00018807","size":"9176.9"},{"price":"0.00018733","size":"0"}],"sequence":9316140,"timestamp":"2021-04-17T16:38:45.643Z","symbol":"XLMETH"}}
1618677525.856998: {"jsonrpc":"2.0","method":"updateOrderbook","params":{"ask":[{"price":"6.01866","size":"1.00"},{"price":"6.18856","size":"0"}],"bid":[{"price":"3.41289","size":"1.00"},{"price":"3.24299","size":"0"}],"sequence":7132777,"timestamp":"2021-04-17T16:38:45.761Z","symbol":"DODOUSD"}}
1618677525.954768: {"jsonrpc":"2.0","method":"updateOrderbook","params":{"ask":[],"bid":[{"price":"0.00401","size":"2300.00"},{"price":"0.00251","size":"0"}],"sequence":4905792,"timestamp":"2021-04-17T16:38:45.887Z","symbol":"HEDGUSD"}}
1618677525.965518: {"jsonrpc":"2.0","method":"updateOrderbook","params":{"ask":[],"bid":[{"price":"0.00024545","size":"78820.3"},{"price":"0.00024537","size":"0"}],"sequence":9316141,"timestamp":"2021-04-17T16:38:45.856Z","symbol":"XLMETH"}}
1618677526.05898: {"jsonrpc":"2.0","method":"updateOrderbook","params":{"ask":[{"price":"0.00015829","size":"200.00"},{"price":"0.00015837","size":"0"}],"bid":[{"price":"0.00015654","size":"768.35"},{"price":"0.00015646","size":"505.47"}],"sequence":18307774,"timestamp":"2021-04-17T16:38:45.961Z","symbol":"OMGBTC"}}
1618677526.0684428: {"jsonrpc":"2.0","method":"updateOrderbook","params":{"ask":[{"price":"0.00012946","size":"3.00"},{"price":"0.00012947","size":"0"}],"bid":[],"sequence":5856049,"timestamp":"2021-04-17T16:38:45.988Z","symbol":"DODOBTC"}}
1618677526.159675: {"jsonrpc":"2.0","method":"updateOrderbook","params":{"ask":[],"bid":[{"price":"0.00015767","size":"76.60"},{"price":"0.00015766","size":"200.00"}],"sequence":18307775,"timestamp":"2021-04-17T16:38:46.067Z","symbol":"OMGBTC"}}
1618677526.2625458: {"jsonrpc":"2.0","method":"updateOrderbook","params":{"ask":[],"bid":[{"price":"0.00015767","size":"67.05"},{"price":"0.00015763","size":"9.55"}],"sequence":18307776,"timestamp":"2021-04-17T16:38:46.160Z","symbol":"OMGBTC"}}
1618677526.269161: {"jsonrpc":"2.0","method":"updateOrderbook","params":{"ask":[{"price":"0.001331783","size":"56575"},{"price":"0.001332258","size":"0"},{"price":"0.001336082","size":"52325"},{"price":"0.001336722","size":"0"},{"price":"0.001348119","size":"57535"},{"price":"0.001348659","size":"0"},{"price":"0.001366858","size":"53172"},{"price":"0.001367757","size":"0"},{"price":"0.001371622","size":"52341"},{"price":"0.001372832","size":"0"},{"price":"0.001376982","size":"54827"},{"price":"0.001378429","size":"0"},{"price":"0.001381781","size":"49524"},{"price":"0.001383273","size":"0"},{"price":"0.001386334","size":"49151"},{"price":"0.001387837","size":"0"}],"bid":[],"sequence":5053530,"timestamp":"2021-04-17T16:38:46.172Z","symbol":"ADABCH"}}
1618677526.3696861: {"jsonrpc":"2.0","method":"updateOrderbook","params":{"ask":[],"bid":[{"price":"0.00015573","size":"5478.09"},{"price":"0.00015559","size":"2677.17"}],"sequence":18307777,"timestamp":"2021-04-17T16:38:46.312Z","symbol":"OMGBTC"}}
1618677526.4590678: {"jsonrpc":"2.0","method":"updateOrderbook","params":{"ask":[{"price":"0.00015821","size":"149.45"},{"price":"0.00015825","size":"1091.77"},{"price":"0.00015834","size":"750.49"},{"price":"0.00015838","size":"0"},{"price":"0.00015843","size":"1774.39"},{"price":"0.00015849","size":"0"},{"price":"0.00015861","size":"149.59"},{"price":"0.00015869","size":"0"},{"price":"0.00015902","size":"0"},{"price":"0.00015925","size":"463.05"},{"price":"0.00015957","size":"4402.08"},{"price":"0.00015969","size":"0"}],"bid":[{"price":"0.00015708","size":"1821.71"},{"price":"0.00015687","size":"0"}],"sequence":18307778,"timestamp":"2021-04-17T16:38:46.414Z","symbol":"OMGBTC"}}
1618677526.5548632: {"jsonrpc":"2.0","method":"updateOrderbook","params":{"ask":[],"bid":[{"price":"0.00015747","size":"63.42"},{"price":"0.00015731","size":"0"},{"price":"0.00014997","size":"824.50"},{"price":"0.00014992","size":"0"}],"sequence":18307779,"timestamp":"2021-04-17T16:38:46.499Z","symbol":"OMGBTC"}}
1618677526.574962: {"jsonrpc":"2.0","method":"updateOrderbook","params":{"ask":[{"price":"0.00025527","size":"0"},{"price":"0.00025535","size":"7870.9"}],"bid":[],"sequence":9316142,"timestamp":"2021-04-17T16:38:46.458Z","symbol":"XLMETH"}}
1618677526.6606588: {"jsonrpc":"2.0","method":"updateOrderbook","params":{"ask":[{"price":"0.00015937","size":"2.45"},{"price":"0.00015939","size":"0"},{"price":"0.00015944","size":"466.51"}],"bid":[{"price":"0.00015763","size":"256.20"},{"price":"0.00015760","size":"0"},{"price":"0.00015732","size":"1394.00"},{"price":"0.00015727","size":"670.43"},{"price":"0.00015718","size":"0"},{"price":"0.00015714","size":"0"},{"price":"0.00015708","size":"1932.03"},{"price":"0.00015704","size":"91.76"},{"price":"0.00015637","size":"2504.10"},{"price":"0.00015632","size":"0.01"}],"sequence":18307780,"timestamp":"2021-04-17T16:38:46.617Z","symbol":"OMGBTC"}}
1618677526.6610088: {"jsonrpc":"2.0","method":"updateOrderbook","params":{"ask":[],"bid":[{"price":"4.54456","size":"0"},{"price":"4.54307","size":"902.75"},{"price":"4.53585","size":"0"},{"price":"4.53438","size":"1626.22"},{"price":"4.52671","size":"0"},{"price":"4.52512","size":"2203.89"},{"price":"4.48937","size":"0"},{"price":"4.48659","size":"1661.53"}],"sequence":7132778,"timestamp":"2021-04-17T16:38:46.562Z","symbol":"DODOUSD"}}
1618677526.675491: {"jsonrpc":"2.0","method":"updateOrderbook","params":{"ask":[],"bid":[{"price":"0.00025234","size":"0"}],"sequence":9316143,"timestamp":"2021-04-17T16:38:46.598Z","symbol":"XLMETH"}}
1618677526.6756742: {"jsonrpc":"2.0","method":"updateOrderbook","params":{"ask":[],"bid":[{"price":"0.0162889","size":"15.69"},{"price":"0.0162570","size":"0"},{"price":"0.0150045","size":"784.70"},{"price":"0.0149059","size":"0"},{"price":"0.0143507","size":"1198.56"},{"price":"0.0142697","size":"0"},{"price":"0.0138151","size":"2142.57"},{"price":"0.0137718","size":"0"},{"price":"0.0135645","size":"3132.40"},{"price":"0.0135355","size":"0"},{"price":"0.0134204","size":"3532.62"},{"price":"0.0133861","size":"0"}],"sequence":6928582,"timestamp":"2021-04-17T16:38:46.556Z","symbol":"ETCETH"}}
1618677526.758582: {"jsonrpc":"2.0","method":"updateOrderbook","params":{"ask":[{"price":"0.00015840","size":"591.61"},{"price":"0.00015853","size":"0"},{"price":"0.00015944","size":"984.17"}],"bid":[{"price":"0.00015763","size":"246.65"},{"price":"0.00015758","size":"9.55"}],"sequence":18307781,"timestamp":"2021-04-17T16:38:46.690Z","symbol":"OMGBTC"}}
1618677526.787491: {"jsonrpc":"2.0","method":"updateOrderbook","params":{"ask":[],"bid":[{"price":"0.00025242","size":"38.8"}],"sequence":9316144,"timestamp":"2021-04-17T16:38:46.648Z","symbol":"XLMETH"}}
1618677526.862384: {"jsonrpc":"2.0","method":"updateOrderbook","params":{"ask":[{"price":"0.00015888","size":"0"},{"price":"0.00015893","size":"633.98"},{"price":"0.00015894","size":"0"},{"price":"0.00015903","size":"0"},{"price":"0.00015914","size":"410.92"},{"price":"0.00015915","size":"0"},{"price":"0.00015922","size":"734.91"},{"price":"0.00015927","size":"830.99"},{"price":"0.00015933","size":"0"},{"price":"0.00015938","size":"0"}],"bid":[],"sequence":18307782,"timestamp":"2021-04-17T16:38:46.798Z","symbol":"OMGBTC"}}
1618677526.8732522: {"jsonrpc":"2.0","method":"updateOrderbook","params":{"ask":[],"bid":[{"price":"0.00006792","size":"20313.87"},{"price":"0.00006789","size":"0"},{"price":"0.00006600","size":"19098.50"},{"price":"0.00006597","size":"0"}],"sequence":5856050,"timestamp":"2021-04-17T16:38:46.753Z","symbol":"DODOBTC"}}
1618677526.9523761: {"jsonrpc":"2.0","method":"updateOrderbook","params":{"ask":[{"price":"0.00015830","size":"1507.75"},{"price":"0.00015930","size":"0"}],"bid":[],"sequence":18307783,"timestamp":"2021-04-17T16:38:46.894Z","symbol":"OMGBTC"}}
1618677526.952935: {"jsonrpc":"2.0","method":"updateOrderbook","params":{"ask":[{"price":"4.72171","size":"15561.71"},{"price":"4.72772","size":"0"},{"price":"4.79004","size":"21772.25"},{"price":"4.79707","size":"0"}],"bid":[],"sequence":7132779,"timestamp":"2021-04-17T16:38:46.863Z","symbol":"DODOUSD"}}
1618677527.054281: {"jsonrpc":"2.0","method":"updateOrderbook","params":{"ask":[{"price":"0.00015818","size":"500.06"},{"price":"0.00015822","size":"0"}],"bid":[{"price":"0.00015757","size":"793.06"},{"price":"0.00015752","size":"0.01"}],"sequence":18307784,"timestamp":"2021-04-17T16:38:46.960Z","symbol":"OMGBTC"}}
1618677527.148979: {"jsonrpc":"2.0","method":"updateOrderbook","params":{"ask":[],"bid":[{"price":"0.00401","size":"0"},{"price":"0.00251","size":"2300.00"}],"sequence":4905793,"timestamp":"2021-04-17T16:38:47.067Z","symbol":"HEDGUSD"}}
1618677527.1610591: {"jsonrpc":"2.0","method":"updateOrderbook","params":{"ask":[{"price":"0.00015937","size":"0"},{"price":"0.00015939","size":"2.45"}],"bid":[{"price":"0.00015560","size":"0"}],"sequence":18307785,"timestamp":"2021-04-17T16:38:47.119Z","symbol":"OMGBTC"}}
1618677527.1726909: {"jsonrpc":"2.0","method":"updateOrderbook","params":{"ask":[{"price":"0.00012946","size":"0"},{"price":"0.00012947","size":"3.00"}],"bid":[],"sequence":5856051,"timestamp":"2021-04-17T16:38:47.033Z","symbol":"DODOBTC"}}
1618677527.2887628: {"jsonrpc":"2.0","method":"updateOrderbook","params":{"ask":[],"bid":[{"price":"0.00015574","size":"185.16"}],"sequence":18307786,"timestamp":"2021-04-17T16:38:47.167Z","symbol":"OMGBTC"}}
1618677527.288949: {"jsonrpc":"2.0","method":"updateOrderbook","params":{"ask":[{"price":"6.01800","size":"1.00"},{"price":"6.01866","size":"0"}],"bid":[{"price":"4.54869","size":"570.65"},{"price":"4.54813","size":"0"},{"price":"4.54367","size":"902.75"},{"price":"4.54307","size":"0"},{"price":"3.41289","size":"0"},{"price":"3.41252","size":"1.00"}],"sequence":7132780,"timestamp":"2021-04-17T16:38:47.197Z","symbol":"DODOUSD"}}
1618677527.359342: {"jsonrpc":"2.0","method":"updateOrderbook","params":{"ask":[],"bid":[{"price":"0.00015738","size":"1394.00"},{"price":"0.00015732","size":"0"}],"sequence":18307787,"timestamp":"2021-04-17T16:38:47.276Z","symbol":"OMGBTC"}}
1618677527.359553: {"jsonrpc":"2.0","method":"updateOrderbook","params":{"ask":[{"price":"4.60614","size":"8443.15"},{"price":"4.60857","size":"0"}],"bid":[],"sequence":7132781,"timestamp":"2021-04-17T16:38:47.271Z","symbol":"DODOUSD"}}
1618677527.4566789: {"jsonrpc":"2.0","method":"updateOrderbook","params":{"ask":[{"price":"0.00015866","size":"707.57"},{"price":"0.00015876","size":"0"}],"bid":[],"sequence":18307788,"timestamp":"2021-04-17T16:38:47.355Z","symbol":"OMGBTC"}}
1618677527.4568808: {"jsonrpc":"2.0","method":"updateOrderbook","params":{"ask":[{"price":"4.66059","size":"10836.10"},{"price":"4.66327","size":"0"}],"bid":[],"sequence":7132782,"timestamp":"2021-04-17T16:38:47.362Z","symbol":"DODOUSD"}}
1618677527.569437: {"jsonrpc":"2.0","method":"updateOrderbook","params":{"ask":[{"price":"0.00015820","size":"692.41"},{"price":"0.00015823","size":"429.72"},{"price":"0.00015827","size":"0"},{"price":"0.00015837","size":"2302.58"},{"price":"0.00015840","size":"63.42"},{"price":"0.00015843","size":"0"},{"price":"0.00015854","size":"551.24"},{"price":"0.00015866","size":"156.33"},{"price":"0.00015946","size":"4402.08"},{"price":"0.00015957","size":"0"}],"bid":[{"price":"0.00015686","size":"477.14"},{"price":"0.00015683","size":"0"}],"sequence":18307789,"timestamp":"2021-04-17T16:38:47.501Z","symbol":"OMGBTC"}}
1618677527.569777: {"jsonrpc":"2.0","method":"updateOrderbook","params":{"ask":[{"price":"6.01602","size":"1.00"},{"price":"6.01800","size":"0"}],"bid":[{"price":"4.54869","size":"0"},{"price":"4.54758","size":"570.65"},{"price":"4.54367","size":"0"},{"price":"4.54197","size":"902.75"},{"price":"4.53438","size":"0"},{"price":"4.53344","size":"1626.22"},{"price":"4.51860","size":"0"},{"price":"4.51735","size":"2740.00"},{"price":"4.50617","size":"0"},{"price":"4.50396","size":"4091.22"},{"price":"3.41252","size":"0"},{"price":"3.41139","size":"1.00"}],"sequence":7132783,"timestamp":"2021-04-17T16:38:47.520Z","symbol":"DODOUSD"}}
1618677527.660816: {"jsonrpc":"2.0","method":"updateOrderbook","params":{"ask":[{"price":"0.00015865","size":"2128.07"},{"price":"0.00015889","size":"0"}],"bid":[{"price":"0.00015650","size":"2504.10"},{"price":"0.00015637","size":"0"}],"sequence":18307790,"timestamp":"2021-04-17T16:38:47.541Z","symbol":"OMGBTC"}}
1618677527.661062: {"jsonrpc":"2.0","method":"updateOrderbook","params":{"ask":[{"price":"6.01602","size":"0"},{"price":"6.01668","size":"1.00"}],"bid":[{"price":"4.54258","size":"902.75"},{"price":"4.54197","size":"0"},{"price":"3.41177","size":"1.00"},{"price":"3.41139","size":"0"}],"sequence":7132784,"timestamp":"2021-04-17T16:38:47.565Z","symbol":"DODOUSD"}}
1618677527.669174: {"jsonrpc":"2.0","method":"updateOrderbook","params":{"ask":[],"bid":[{"price":"0.0150708","size":"784.52"},{"price":"0.0150045","size":"0"},{"price":"0.0144052","size":"1198.28"},{"price":"0.0143507","size":"0"},{"price":"0.0138423","size":"2142.07"},{"price":"0.0138151","size":"0"}],"sequence":6928583,"timestamp":"2021-04-17T16:38:47.537Z","symbol":"ETCETH"}}
1618677527.7599301: {"jsonrpc":"2.0","method":"updateOrderbook","params":{"ask":[{"price":"0.00015837","size":"1774.39"},{"price":"0.00015840","size":"591.61"},{"price":"0.00015854","size":"0"},{"price":"0.00015860","size":"551.24"},{"price":"0.00015893","size":"0"},{"price":"0.00015899","size":"280.67"},{"price":"0.00015906","size":"633.98"},{"price":"0.00015935","size":"0"},{"price":"0.00015944","size":"466.51"}],"bid":[{"price":"0.00015719","size":"587.38"},{"price":"0.00015717","size":"0"}],"sequence":18307791,"timestamp":"2021-04-17T16:38:47.699Z","symbol":"OMGBTC"}}
1618677527.7602508: {"jsonrpc":"2.0","method":"updateOrderbook","params":{"ask":[],"bid":[{"price":"4.54758","size":"0"},{"price":"4.54459","size":"570.65"},{"price":"4.54258","size":"0"},{"price":"4.54162","size":"902.75"}],"sequence":7132785,"timestamp":"2021-04-17T16:38:47.669Z","symbol":"DODOUSD"}}
1618677527.764611: {"jsonrpc":"2.0","method":"updateOrderbook","params":{"ask":[],"bid":[{"price":"0.00007521","size":"0"},{"price":"0.00007516","size":"133.36"}],"sequence":5856052,"timestamp":"2021-04-17T16:38:47.681Z","symbol":"DODOBTC"}}
1618677527.859104: {"jsonrpc":"2.0","method":"updateOrderbook","params":{"ask":[{"price":"6.01602","size":"1.00"},{"price":"6.01668","size":"0"}],"bid":[{"price":"4.54459","size":"0"},{"price":"4.54440","size":"570.65"},{"price":"4.54162","size":"0"},{"price":"4.54103","size":"902.75"},{"price":"4.53990","size":"0"},{"price":"4.53344","size":"0"},{"price":"4.53311","size":"1196.81"},{"price":"4.52654","size":"1626.22"},{"price":"4.52512","size":"0"},{"price":"4.52045","size":"2203.89"},{"price":"4.51735","size":"0"},{"price":"4.51328","size":"2740.00"},{"price":"4.50396","size":"0"},{"price":"4.49463","size":"4091.22"},{"price":"4.20069","size":"0"},{"price":"4.19862","size":"133.52"},{"price":"3.41177","size":"0"},{"price":"3.41139","size":"1.00"}],"sequence":7132786,"timestamp":"2021-04-17T16:38:47.782Z","symbol":"DODOUSD"}}
1618677527.869649: {"jsonrpc":"2.0","method":"updateOrderbook","params":{"ask":[],"bid":[{"price":"0.00007498","size":"0"},{"price":"0.00007489","size":"1733.79"},{"price":"0.00007469","size":"0"},{"price":"0.00007457","size":"2667.37"}],"sequence":5856053,"timestamp":"2021-04-17T16:38:47.768Z","symbol":"DODOBTC"}}
1618677527.869812: {"jsonrpc":"2.0","method":"updateOrderbook","params":{"ask":[{"price":"0.001355350","size":"58712"},{"price":"0.001356040","size":"0"}],"bid":[],"sequence":5053531,"timestamp":"2021-04-17T16:38:47.774Z","symbol":"ADABCH"}}
1618677527.874978: {"jsonrpc":"2.0","method":"updateOrderbook","params":{"ask":[],"bid":[{"price":"0.0150708","size":"0"},{"price":"0.0150032","size":"784.70"},{"price":"0.0144052","size":"0"},{"price":"0.0143499","size":"1198.56"},{"price":"0.0138423","size":"0"},{"price":"0.0138141","size":"2142.57"}],"sequence":6928584,"timestamp":"2021-04-17T16:38:47.748Z","symbol":"ETCETH"}}
1618677527.960751: {"jsonrpc":"2.0","method":"updateOrderbook","params":{"ask":[{"price":"0.00015818","size":"0"},{"price":"0.00015824","size":"500.06"},{"price":"0.00015986","size":"5617.94"},{"price":"0.00016008","size":"0"},{"price":"0.00016546","size":"0"},{"price":"0.00016551","size":"824.50"},{"price":"0.00016721","size":"0"},{"price":"0.00016726","size":"4405.77"}],"bid":[{"price":"0.00015767","size":"0"},{"price":"0.00015766","size":"267.05"},{"price":"0.00015755","size":"507.30"},{"price":"0.00015753","size":"100.65"},{"price":"0.00015738","size":"1981.38"},{"price":"0.00015719","size":"0"},{"price":"0.00015680","size":"748.22"},{"price":"0.00015676","size":"0"}],"sequence":18307792,"timestamp":"2021-04-17T16:38:47.924Z","symbol":"OMGBTC"}}
1618677527.9612072: {"jsonrpc":"2.0","method":"updateOrderbook","params":{"ask":[{"price":"6.01602","size":"0"},{"price":"6.01668","size":"1.00"}],"bid":[{"price":"4.53422","size":"0"},{"price":"4.52924","size":"2.63"},{"price":"4.19862","size":"0"},{"price":"4.19247","size":"133.52"},{"price":"3.41177","size":"1.00"},{"price":"3.41139","size":"0"},{"price":"3.22645","size":"0"},{"price":"3.20805","size":"175.09"}],"sequence":7132787,"timestamp":"2021-04-17T16:38:47.908Z","symbol":"DODOUSD"}}
1618677527.9652312: {"jsonrpc":"2.0","method":"updateOrderbook","params":{"ask":[{"price":"0.00012947","size":"0"},{"price":"0.00012948","size":"3.00"}],"bid":[{"price":"0.00007494","size":"0"},{"price":"0.00007486","size":"3.65"}],"sequence":5856054,"timestamp":"2021-04-17T16:38:47.910Z","symbol":"DODOBTC"}}
1618677527.973305: {"jsonrpc":"2.0","method":"updateOrderbook","params":{"ask":[],"bid":[{"price":"0.001286944","size":"37612"},{"price":"0.001286335","size":"0"}],"sequence":5053532,"timestamp":"2021-04-17T16:38:47.906Z","symbol":"ADABCH"}}
1618677527.977896: {"jsonrpc":"2.0","method":"updateOrderbook","params":{"ask":[],"bid":[],"sequence":9316145,"timestamp":"2021-04-17T16:38:47.865Z","symbol":"XLMETH"}}
1618677528.065525: {"jsonrpc":"2.0","method":"updateOrderbook","params":{"ask":[],"bid":[{"price":"0.00015767","size":"9.55"},{"price":"0.00015766","size":"67.05"},{"price":"0.00015758","size":"200.00"}],"sequence":18307793,"timestamp":"2021-04-17T16:38:48.016Z","symbol":"OMGBTC"}}
