1626318032.97768: {"jsonrpc":"2.0","method":"updateOrderbook","params":{"ask":[{"price":"0.00000036726","size":"0"},{"price":"0.00000036737","size":"0"},{"price":"0.00000036748","size":"0"},{"price":"0.00000036761","size":"25530"},{"price":"0.00000036784","size":"0"},{"price":"0.00000036826","size":"101590"},{"price":"0.00000036877","size":"255050"},{"price":"0.00000036909","size":"408320"},{"price":"0.00000036910","size":"0"},{"price":"0.00000037314","size":"0"},{"price":"0.00000037986","size":"603920"},{"price":"0.00000041211","size":"666450"},{"price":"0.00000041356","size":"0"},{"price":"0.00000042829","size":"1016210"},{"price":"0.00000044040","size":"0"},{"price":"0.00000060970","size":"1381850"},{"price":"0.00000065973","size":"15232310"},{"price":"0.00000089465","size":"0"},{"price":"0.00000094571","size":"2770370"},{"price":"0.00000106078","size":"2001500"},{"price":"0.00000124640","size":"0"},{"price":"0.00000131433","size":"2705250"},{"price":"0.00000146968","size":"0"},{"price":"0.00000148900","size":"3222000"},{"price":"0.00000161321","size":"0"},{"price":"0.00000167169","size":"4634410"},{"price":"0.00000419436","size":"0"},{"price":"0.00000462426","size":"7466230"}],"bid":[{"price":"0.00000036428","size":"0"},{"price":"0.00000036411","size":"0"},{"price":"0.00000036388","size":"284390"},{"price":"0.00000036356","size":"0"},{"price":"0.00000036342","size":"384900"},{"price":"0.00000036330","size":"586390"},{"price":"0.00000036265","size":"0"},{"price":"0.00000036210","size":"1248220"},{"price":"0.00000032212","size":"0"},{"price":"0.00000023946","size":"1993120"},{"price":"0.00000004424","size":"0"},{"price":"0.00000000735","size":"2752080"}],"sequence":10532369,"timestamp":"2021-07-15T03:00:32.933Z","symbol":"SCBTC"}}
1626318032.977792: {"jsonrpc":"2.0","method":"updateOrderbook","params":{"ask":[{"price":"0.00054548","size":"0"},{"price":"0.00054550","size":"4.33"},{"price":"0.00054633","size":"333.84"},{"price":"0.00054647","size":"440.89"},{"price":"0.00054662","size":"0"},{"price":"0.00054689","size":"0"}],"bid":[{"price":"0.00053050","size":"443.28"}],"sequence":19513170,"timestamp":"2021-07-15T03:00:32.920Z","symbol":"UNIBTC"}}
1626318033.0541608: {"jsonrpc":"2.0","method":"updateOrderbook","params":{"ask":[{"price":"0.615776","size":"0"},{"price":"0.615801","size":"11000.0"},{"price":"0.615824","size":"0"},{"price":"0.615830","size":"1331.7"},{"price":"0.616282","size":"0"},{"price":"0.616384","size":"0"},{"price":"0.616417","size":"0"},{"price":"0.616479","size":"160.9"},{"price":"0.616480","size":"10632.0"},{"price":"0.616562","size":"2020.2"},{"price":"0.646107","size":"347706.3"},{"price":"0.647695","size":"0"},{"price":"0.662655","size":"399106.5"}],"bid":[{"price":"0.615713","size":"1591.5"},{"price":"0.615698","size":"0"},{"price":"0.615608","size":"2955.7"},{"price":"0.615535","size":"0"}],"sequence":20584182,"timestamp":"2021-07-15T03:00:33.042Z","symbol":"XRPUSDT"}}
1626318033.080076: {"jsonrpc":"2.0","method":"updateOrderbook","params":{"ask":[{"price":"0.00000065973","size":"15232320"},{"price":"0.00000094571","size":"2770380"}],"bid":[{"price":"0.00000036535","size":"1000"},{"price":"0.00000036483","size":"0"}],"sequence":10532370,"timestamp":"2021-07-15T03:00:32.994Z","symbol":"SCBTC"}}
1626318033.080108: {"jsonrpc":"2.0","method":"updateOrderbook","params":{"ask":[{"price":"0.00054550","size":"0"},{"price":"0.00054556","size":"4.33"},{"price":"0.00054572","size":"0"},{"price":"0.00054582","size":"10.47"},{"price":"0.00054594","size":"17.11"},{"price":"0.00054616","size":"0"},{"price":"0.00054647","size":"0"},{"price":"0.00054684","size":"440.89"},{"price":"0.00055429","size":"881.76"},{"price":"0.00056925","size":"0"}],"bid":[{"price":"0.00054528","size":"5.18"},{"price":"0.00054525","size":"0"}],"sequence":19513171,"timestamp":"2021-07-15T03:00:33.027Z","symbol":"UNIBTC"}}
1626318033.155751: {"jsonrpc":"2.0","method":"updateOrderbook","params":{"ask":[{"price":"0.615801","size":"0"},{"price":"0.615830","size":"0"},{"price":"0.615853","size":"1331.7"},{"price":"0.624064","size":"272131.6"},{"price":"0.625541","size":"0"},{"price":"0.662655","size":"399106.7"}],"bid":[{"price":"0.615743","size":"11000.0"},{"price":"0.615713","size":"0"},{"price":"0.615696","size":"1591.5"},{"price":"0.615318","size":"1337.0"},{"price":"0.615195","size":"0"},{"price":"0.614436","size":"0"},{"price":"0.614368","size":"1800.0"}],"sequence":20584183,"timestamp":"2021-07-15T03:00:33.133Z","symbol":"XRPUSDT"}}
1626318033.168567: {"jsonrpc":"2.0","method":"updateOrderbook","params":{"ask":[{"price":"0.00000065973","size":"15232330"},{"price":"0.00000094571","size":"2770400"}],"bid":[],"sequence":10532371,"timestamp":"2021-07-15T03:00:33.101Z","symbol":"SCBTC"}}
1626318033.176053: {"jsonrpc":"2.0","method":"updateOrderbook","params":{"ask":[{"price":"0.00054613","size":"0"},{"price":"0.00054623","size":"0"},{"price":"0.00054633","size":"0"},{"price":"0.00054637","size":"201.47"},{"price":"0.00054639","size":"217.72"},{"price":"0.00054657","size":"0"},{"price":"0.00054661","size":"296.51"},{"price":"0.00054685","size":"333.84"},{"price":"0.00055063","size":"843.90"},{"price":"0.00055110","size":"0"}],"bid":[{"price":"0.00054528","size":"0"},{"price":"0.00054526","size":"5.18"},{"price":"0.00053478","size":"0"},{"price":"0.00053387","size":"2974.71"}],"sequence":19513172,"timestamp":"2021-07-15T03:00:33.143Z","symbol":"UNIBTC"}}
1626318033.254163: {"jsonrpc":"2.0","method":"updateOrderbook","params":{"ask":[{"price":"0.615819","size":"11000.0"},{"price":"0.615841","size":"1331.7"},{"price":"0.615853","size":"0"},{"price":"0.633757","size":"129038.8"},{"price":"0.635140","size":"0"},{"price":"0.657613","size":"181214.3"},{"price":"0.658817","size":"0"},{"price":"0.662655","size":"399107.0"}],"bid":[{"price":"0.615709","size":"1591.5"},{"price":"0.615696","size":"0"},{"price":"0.615318","size":"0"},{"price":"0.615195","size":"1337.0"},{"price":"0.606732","size":"165690.2"},{"price":"0.605348","size":"0"}],"sequence":20584184,"timestamp":"2021-07-15T03:00:33.228Z","symbol":"XRPUSDT"}}
1626318033.2644322: {"jsonrpc":"2.0","method":"updateOrderbook","params":{"ask":[{"price":"0.00000065973","size":"15232350"},{"price":"0.00000094571","size":"2770420"}],"bid":[],"sequence":10532372,"timestamp":"2021-07-15T03:00:33.194Z","symbol":"SCBTC"}}
1626318033.2774038: {"jsonrpc":"2.0","method":"updateOrderbook","params":{"ask":[{"price":"0.00054551","size":"4.33"},{"price":"0.00054556","size":"0"},{"price":"0.00054586","size":"0"},{"price":"0.00054596","size":"16.70"},{"price":"0.00054599","size":"0"},{"price":"0.00054610","size":"85.08"}],"bid":[],"sequence":19513173,"timestamp":"2021-07-15T03:00:33.181Z","symbol":"UNIBTC"}}
1626318033.3584971: {"jsonrpc":"2.0","method":"updateOrderbook","params":{"ask":[{"price":"0.615819","size":"0"},{"price":"0.615838","size":"1331.7"},{"price":"0.615841","size":"0"},{"price":"0.662655","size":"399107.2"}],"bid":[{"price":"0.615743","size":"0"},{"price":"0.615731","size":"11000.0"},{"price":"0.615719","size":"1591.5"},{"price":"0.615709","size":"0"}],"sequence":20584185,"timestamp":"2021-07-15T03:00:33.318Z","symbol":"XRPUSDT"}}
1626318033.35969: {"jsonrpc":"2.0","method":"updateOrderbook","params":{"ask":[{"price":"0.00000065973","size":"15232360"},{"price":"0.00000094571","size":"2770440"}],"bid":[],"sequence":10532373,"timestamp":"2021-07-15T03:00:33.303Z","symbol":"SCBTC"}}
1626318033.3638022: {"jsonrpc":"2.0","method":"updateOrderbook","params":{"ask":[],"bid":[{"price":"0.00054529","size":"5.18"},{"price":"0.00054526","size":"0"}],"sequence":19513174,"timestamp":"2021-07-15T03:00:33.282Z","symbol":"UNIBTC"}}
1626318033.4548311: {"jsonrpc":"2.0","method":"updateOrderbook","params":{"ask":[{"price":"0.662655","size":"399107.5"}],"bid":[{"price":"0.615719","size":"0"},{"price":"0.615688","size":"1591.5"},{"price":"0.606732","size":"0"},{"price":"0.605158","size":"165690.2"}],"sequence":20584186,"timestamp":"2021-07-15T03:00:33.420Z","symbol":"XRPUSDT"}}
1626318033.464319: {"jsonrpc":"2.0","method":"updateOrderbook","params":{"ask":[{"price":"0.00000065973","size":"15232380"},{"price":"0.00000094571","size":"2770460"}],"bid":[],"sequence":10532374,"timestamp":"2021-07-15T03:00:33.410Z","symbol":"SCBTC"}}
1626318033.5742478: {"jsonrpc":"2.0","method":"updateOrderbook","params":{"ask":[{"price":"0.615811","size":"1331.7"},{"price":"0.615838","size":"0"},{"price":"0.616387","size":"160.9"},{"price":"0.616388","size":"2020.2"},{"price":"0.616479","size":"0"},{"price":"0.616562","size":"0"},{"price":"0.617102","size":"0"},{"price":"0.617196","size":"7700.0"},{"price":"0.662655","size":"399107.7"}],"bid":[{"price":"0.614061","size":"0"},{"price":"0.613962","size":"7700.0"}],"sequence":20584187,"timestamp":"2021-07-15T03:00:33.519Z","symbol":"XRPUSDT"}}
1626318033.5789518: {"jsonrpc":"2.0","method":"updateOrderbook","params":{"ask":[{"price":"0.00000065973","size":"15232390"},{"price":"0.00000094571","size":"2770480"}],"bid":[],"sequence":10532375,"timestamp":"2021-07-15T03:00:33.516Z","symbol":"SCBTC"}}
1626318033.579011: {"jsonrpc":"2.0","method":"updateOrderbook","params":{"ask":[{"price":"0.00054624","size":"0"},{"price":"0.00054638","size":"66.76"},{"price":"0.00054843","size":"1302.32"},{"price":"0.00054917","size":"0"},{"price":"0.00058935","size":"2343.84"},{"price":"0.00058953","size":"0"},{"price":"0.00062612","size":"1125.76"},{"price":"0.00073715","size":"0"},{"price":"0.00078195","size":"3484.36"},{"price":"0.00078201","size":"0"},{"price":"0.00081742","size":"1585.64"},{"price":"0.00083870","size":"0"}],"bid":[],"sequence":19513175,"timestamp":"2021-07-15T03:00:33.530Z","symbol":"UNIBTC"}}
1626318033.650347: {"jsonrpc":"2.0","method":"updateOrderbook","params":{"ask":[{"price":"0.615790","size":"1331.7"},{"price":"0.615811","size":"0"},{"price":"0.615888","size":"3215.6"},{"price":"0.615943","size":"0"},{"price":"0.616906","size":"6433.6"},{"price":"0.617189","size":"0"},{"price":"0.662655","size":"399108.0"}],"bid":[{"price":"0.615688","size":"0"},{"price":"0.615682","size":"1591.5"},{"price":"0.615608","size":"0"},{"price":"0.615576","size":"2955.7"}],"sequence":20584188,"timestamp":"2021-07-15T03:00:33.628Z","symbol":"XRPUSDT"}}
1626318033.657407: {"jsonrpc":"2.0","method":"updateOrderbook","params":{"ask":[{"price":"0.00000065973","size":"15232410"},{"price":"0.00000094571","size":"2770490"}],"bid":[],"sequence":10532376,"timestamp":"2021-07-15T03:00:33.621Z","symbol":"SCBTC"}}
1626318033.657423: {"jsonrpc":"2.0","method":"updateOrderbook","params":{"ask":[{"price":"0.00054777","size":"0"},{"price":"0.00054818","size":"170.00"}],"bid":[{"price":"0.00054529","size":"0"},{"price":"0.00054526","size":"5.18"}],"sequence":19513176,"timestamp":"2021-07-15T03:00:33.627Z","symbol":"UNIBTC"}}
1626318033.747904: {"jsonrpc":"2.0","method":"updateOrderbook","params":{"ask":[{"price":"0.662655","size":"399108.2"}],"bid":[{"price":"0.614890","size":"6216.0"},{"price":"0.614645","size":"0"},{"price":"0.614474","size":"3391.2"},{"price":"0.614249","size":"0"},{"price":"0.614071","size":"13252.5"},{"price":"0.613909","size":"0"}],"sequence":20584189,"timestamp":"2021-07-15T03:00:33.698Z","symbol":"XRPUSDT"}}
1626318033.7578309: {"jsonrpc":"2.0","method":"updateOrderbook","params":{"ask":[{"price":"0.00000065973","size":"15232420"},{"price":"0.00000094571","size":"2770510"}],"bid":[],"sequence":10532377,"timestamp":"2021-07-15T03:00:33.727Z","symbol":"SCBTC"}}
1626318033.761036: {"jsonrpc":"2.0","method":"updateOrderbook","params":{"ask":[{"price":"0.00054551","size":"0"},{"price":"0.00054553","size":"4.33"}],"bid":[{"price":"0.00054527","size":"5.18"},{"price":"0.00054526","size":"0"}],"sequence":19513177,"timestamp":"2021-07-15T03:00:33.740Z","symbol":"UNIBTC"}}
1626318033.854848: {"jsonrpc":"2.0","method":"updateOrderbook","params":{"ask":[{"price":"0.662655","size":"399108.5"}],"bid":[{"price":"0.615690","size":"1596.4"},{"price":"0.615682","size":"0"}],"sequence":20584190,"timestamp":"2021-07-15T03:00:33.824Z","symbol":"XRPUSDT"}}
1626318033.865104: {"jsonrpc":"2.0","method":"updateOrderbook","params":{"ask":[{"price":"0.00000065973","size":"15232440"},{"price":"0.00000094571","size":"2770530"}],"bid":[],"sequence":10532378,"timestamp":"2021-07-15T03:00:33.831Z","symbol":"SCBTC"}}
1626318033.865143: {"jsonrpc":"2.0","method":"updateOrderbook","params":{"ask":[{"price":"0.00054553","size":"0"},{"price":"0.00054558","size":"4.33"},{"price":"0.00054616","size":"199.63"},{"price":"0.00054626","size":"296.51"},{"price":"0.00054639","size":"18.09"},{"price":"0.00054661","size":"0"}],"bid":[{"price":"0.00054530","size":"5.18"},{"price":"0.00054527","size":"0"}],"sequence":19513178,"timestamp":"2021-07-15T03:00:33.816Z","symbol":"UNIBTC"}}
1626318033.949242: {"jsonrpc":"2.0","method":"updateOrderbook","params":{"ask":[{"price":"0.615760","size":"11000.0"},{"price":"0.615790","size":"0"},{"price":"0.615795","size":"1331.7"},{"price":"0.662655","size":"399108.7"}],"bid":[{"price":"0.615731","size":"0"},{"price":"0.615690","size":"4.9"},{"price":"0.615609","size":"1591.5"},{"price":"0.615576","size":"0"},{"price":"0.615511","size":"2955.7"}],"sequence":20584191,"timestamp":"2021-07-15T03:00:33.895Z","symbol":"XRPUSDT"}}
1626318033.960138: {"jsonrpc":"2.0","method":"updateOrderbook","params":{"ask":[{"price":"0.00000065973","size":"15232450"},{"price":"0.00000094571","size":"2770550"}],"bid":[],"sequence":10532379,"timestamp":"2021-07-15T03:00:33.937Z","symbol":"SCBTC"}}
1626318033.960278: {"jsonrpc":"2.0","method":"updateOrderbook","params":{"ask":[{"price":"0.00054596","size":"0"},{"price":"0.00054609","size":"16.70"},{"price":"0.00054610","size":"18.88"},{"price":"0.00054616","size":"0"},{"price":"0.00054626","size":"0"},{"price":"0.00054630","size":"66.20"},{"price":"0.00054643","size":"199.63"},{"price":"0.00054662","size":"296.51"},{"price":"0.00054843","size":"0"},{"price":"0.00054920","size":"1302.32"}],"bid":[{"price":"0.00054509","size":"9.62"},{"price":"0.00054499","size":"0"}],"sequence":19513179,"timestamp":"2021-07-15T03:00:33.918Z","symbol":"UNIBTC"}}
1626318034.057688: {"jsonrpc":"2.0","method":"updateOrderbook","params":{"ask":[{"price":"0.662655","size":"399109.1"}],"bid":[{"price":"0.615679","size":"1591.5"},{"price":"0.615609","size":"0"}],"sequence":20584192,"timestamp":"2021-07-15T03:00:34.024Z","symbol":"XRPUSDT"}}
1626318034.060547: {"jsonrpc":"2.0","method":"updateOrderbook","params":{"ask":[{"price":"0.00000065973","size":"15232470"},{"price":"0.00000094571","size":"2770570"}],"bid":[],"sequence":10532380,"timestamp":"2021-07-15T03:00:34.043Z","symbol":"SCBTC"}}
1626318034.154163: {"jsonrpc":"2.0","method":"updateOrderbook","params":{"ask":[{"price":"0.617284","size":"4276.9"},{"price":"0.617559","size":"0"},{"price":"0.617687","size":"12316.2"},{"price":"0.617928","size":"0"},{"price":"0.662655","size":"399109.3"}],"bid":[],"sequence":20584193,"timestamp":"2021-07-15T03:00:34.090Z","symbol":"XRPUSDT"}}
1626318034.161909: {"jsonrpc":"2.0","method":"updateOrderbook","params":{"ask":[{"price":"0.00054556","size":"4.33"},{"price":"0.00054558","size":"0"},{"price":"0.00055063","size":"0"},{"price":"0.00055110","size":"843.90"}],"bid":[{"price":"0.00054530","size":"0"},{"price":"0.00054528","size":"5.18"}],"sequence":19513180,"timestamp":"2021-07-15T03:00:34.120Z","symbol":"UNIBTC"}}
1626318034.2509289: {"jsonrpc":"2.0","method":"updateOrderbook","params":{"ask":[],"bid":[{"price":"12.104","size":"5.7265"},{"price":"12.103","size":"5.8737"}],"sequence":2190717,"timestamp":"2021-07-15T03:00:34.206Z","symbol":"SPIUSD"}}
1626318034.250974: {"jsonrpc":"2.0","method":"updateOrderbook","params":{"ask":[{"price":"0.618282","size":"49654.6"},{"price":"0.619259","size":"0"},{"price":"0.623770","size":"124095.9"},{"price":"0.625253","size":"0"},{"price":"0.662655","size":"399109.7"}],"bid":[{"price":"0.615575","size":"2955.7"},{"price":"0.615511","size":"0"}],"sequence":20584194,"timestamp":"2021-07-15T03:00:34.238Z","symbol":"XRPUSDT"}}
1626318034.258178: {"jsonrpc":"2.0","method":"updateOrderbook","params":{"ask":[{"price":"0.00000065973","size":"15232480"},{"price":"0.00000094571","size":"2770590"}],"bid":[],"sequence":10532381,"timestamp":"2021-07-15T03:00:34.147Z","symbol":"SCBTC"}}
1626318034.2583208: {"jsonrpc":"2.0","method":"updateOrderbook","params":{"ask":[{"price":"0.00054591","size":"16.70"},{"price":"0.00054605","size":"66.20"},{"price":"0.00054609","size":"0"},{"price":"0.00054630","size":"0"},{"price":"0.00054915","size":"0"},{"price":"0.00054992","size":"433.80"}],"bid":[{"price":"0.00054530","size":"5.18"},{"price":"0.00054528","size":"0"}],"sequence":19513181,"timestamp":"2021-07-15T03:00:34.172Z","symbol":"UNIBTC"}}
1626318034.354861: {"jsonrpc":"2.0","method":"updateOrderbook","params":{"ask":[{"price":"0.615760","size":"0"},{"price":"0.615786","size":"1331.7"},{"price":"0.615795","size":"0"},{"price":"0.662655","size":"399109.9"}],"bid":[{"price":"0.615720","size":"11000.0"},{"price":"0.615679","size":"0"},{"price":"0.615673","size":"1591.5"}],"sequence":20584195,"timestamp":"2021-07-15T03:00:34.297Z","symbol":"XRPUSDT"}}
1626318034.3621938: {"jsonrpc":"2.0","method":"updateOrderbook","params":{"ask":[{"price":"0.00000065973","size":"15232500"},{"price":"0.00000094571","size":"2770610"}],"bid":[],"sequence":10532382,"timestamp":"2021-07-15T03:00:34.257Z","symbol":"SCBTC"}}
1626318034.371507: {"jsonrpc":"2.0","method":"updateOrderbook","params":{"ask":[{"price":"0.00055054","size":"662.81"},{"price":"0.00055287","size":"0"}],"bid":[{"price":"0.00054530","size":"0"},{"price":"0.00054529","size":"5.18"},{"price":"0.00054490","size":"18.03"},{"price":"0.00054481","size":"0"}],"sequence":19513182,"timestamp":"2021-07-15T03:00:34.327Z","symbol":"UNIBTC"}}
1626318034.4490938: {"jsonrpc":"2.0","method":"updateOrderbook","params":{"ask":[],"bid":[{"price":"12.103","size":"0"}],"sequence":2190718,"timestamp":"2021-07-15T03:00:34.437Z","symbol":"SPIUSD"}}
1626318034.454319: {"jsonrpc":"2.0","method":"updateOrderbook","params":{"ask":[{"price":"0.615785","size":"1331.7"},{"price":"0.615786","size":"0"},{"price":"0.662655","size":"399110.3"}],"bid":[{"price":"0.615686","size":"1591.5"},{"price":"0.615673","size":"0"},{"price":"0.615575","size":"0"},{"price":"0.615540","size":"2955.7"},{"price":"0.577301","size":"195374.1"},{"price":"0.574270","size":"0"}],"sequence":20584196,"timestamp":"2021-07-15T03:00:34.442Z","symbol":"XRPUSDT"}}
1626318034.474025: {"jsonrpc":"2.0","method":"updateOrderbook","params":{"ask":[{"price":"0.00000036725","size":"25530"},{"price":"0.00000036737","size":"101590"},{"price":"0.00000036761","size":"0"},{"price":"0.00000036826","size":"0"},{"price":"0.00000065973","size":"15232520"},{"price":"0.00000094571","size":"2770630"}],"bid":[],"sequence":10532383,"timestamp":"2021-07-15T03:00:34.373Z","symbol":"SCBTC"}}
1626318034.474066: {"jsonrpc":"2.0","method":"updateOrderbook","params":{"ask":[{"price":"0.00054591","size":"0"},{"price":"0.00054603","size":"16.70"},{"price":"0.00054605","size":"0"},{"price":"0.00054619","size":"66.20"}],"bid":[{"price":"0.00054529","size":"0"},{"price":"0.00054527","size":"5.18"}],"sequence":19513183,"timestamp":"2021-07-15T03:00:34.369Z","symbol":"UNIBTC"}}
1626318034.547128: {"jsonrpc":"2.0","method":"updateOrderbook","params":{"ask":[],"bid":[{"price":"12.105","size":"5.8728"},{"price":"12.104","size":"0"},{"price":"12.060","size":"5.7399"}],"sequence":2190719,"timestamp":"2021-07-15T03:00:34.498Z","symbol":"SPIUSD"}}
1626318034.551407: {"jsonrpc":"2.0","method":"updateOrderbook","params":{"ask":[{"price":"0.615942","size":"0"},{"price":"0.616137","size":"10632.9"},{"price":"0.662655","size":"399110.5"}],"bid":[{"price":"0.615686","size":"0"},{"price":"0.615646","size":"1591.5"},{"price":"0.615318","size":"1337.0"},{"price":"0.615195","size":"0"},{"price":"0.614438","size":"1800.0"},{"price":"0.614368","size":"0"},{"price":"0.614346","size":"5500.0"},{"price":"0.614277","size":"0"},{"price":"0.614063","size":"7700.0"},{"price":"0.613962","size":"0"}],"sequence":20584197,"timestamp":"2021-07-15T03:00:34.508Z","symbol":"XRPUSDT"}}
1626318034.557345: {"jsonrpc":"2.0","method":"updateOrderbook","params":{"ask":[{"price":"0.00000065973","size":"15232540"},{"price":"0.00000094571","size":"2770650"}],"bid":[{"price":"0.00000036535","size":"0"},{"price":"0.00000036483","size":"1000"},{"price":"0.00000036426","size":"284390"},{"price":"0.00000036411","size":"384900"},{"price":"0.00000036388","size":"0"},{"price":"0.00000036342","size":"0"}],"sequence":10532384,"timestamp":"2021-07-15T03:00:34.508Z","symbol":"SCBTC"}}
1626318034.56433: {"jsonrpc":"2.0","method":"updateOrderbook","params":{"ask":[{"price":"0.00054556","size":"0"},{"price":"0.00054568","size":"4.33"},{"price":"0.00054582","size":"0"},{"price":"0.00054593","size":"10.47"},{"price":"0.00054620","size":"199.63"},{"price":"0.00054630","size":"296.51"},{"price":"0.00054635","size":"77.40"},{"price":"0.00054637","size":"0"},{"price":"0.00054638","size":"0"},{"price":"0.00054643","size":"0"},{"price":"0.00054662","size":"0"},{"price":"0.00054663","size":"201.47"},{"price":"0.00054666","size":"66.76"},{"price":"0.00055851","size":"0"},{"price":"0.00056018","size":"2539.46"},{"price":"0.00058935","size":"0"},{"price":"0.00059258","size":"2343.84"},{"price":"0.00078195","size":"0"},{"price":"0.00078338","size":"3484.36"}],"bid":[{"price":"0.00054532","size":"5.18"},{"price":"0.00054527","size":"0"},{"price":"0.00054478","size":"69.23"},{"price":"0.00054466","size":"0"},{"price":"0.00053467","size":"2974.71"},{"price":"0.00053387","size":"0"}],"sequence":19513184,"timestamp":"2021-07-15T03:00:34.534Z","symbol":"UNIBTC"}}
1626318034.6542091: {"jsonrpc":"2.0","method":"updateOrderbook","params":{"ask":[],"bid":[{"price":"12.106","size":"5.7533"},{"price":"12.060","size":"0"}],"sequence":2190720,"timestamp":"2021-07-15T03:00:34.568Z","symbol":"SPIUSD"}}
1626318034.654264: {"jsonrpc":"2.0","method":"updateOrderbook","params":{"ask":[{"price":"0.615779","size":"1331.6"},{"price":"0.615785","size":"0"},{"price":"0.615888","size":"0"},{"price":"0.615892","size":"10632.8"},{"price":"0.615893","size":"3215.5"},{"price":"0.616137","size":"0"},{"price":"0.616142","size":"5554.1"},{"price":"0.616151","size":"0"},{"price":"0.616263","size":"6528.5"},{"price":"0.616283","size":"0"},{"price":"0.616816","size":"0"},{"price":"0.616879","size":"5500.0"},{"price":"0.662655","size":"399110.7"}],"bid":[{"price":"0.615658","size":"1591.5"},{"price":"0.615646","size":"0"},{"price":"0.615318","size":"0"},{"price":"0.615317","size":"0"},{"price":"0.615293","size":"1337.0"},{"price":"0.615292","size":"5489.1"},{"price":"0.615181","size":"0"},{"price":"0.615170","size":"6463.5"}],"sequence":20584198,"timestamp":"2021-07-15T03:00:34.596Z","symbol":"XRPUSDT"}}
1626318034.6733499: {"jsonrpc":"2.0","method":"updateOrderbook","params":{"ask":[{"price":"0.00000065973","size":"15232550"},{"price":"0.00000094571","size":"2770670"}],"bid":[],"sequence":10532385,"timestamp":"2021-07-15T03:00:34.618Z","symbol":"SCBTC"}}
1626318034.673377: {"jsonrpc":"2.0","method":"updateOrderbook","params":{"ask":[{"price":"0.00054567","size":"4.33"},{"price":"0.00054568","size":"0"},{"price":"0.00054620","size":"0"},{"price":"0.00054630","size":"0"},{"price":"0.00054639","size":"0"},{"price":"0.00054650","size":"199.63"},{"price":"0.00054658","size":"18.08"},{"price":"0.00054671","size":"296.51"},{"price":"0.00054684","size":"0"},{"price":"0.00054720","size":"440.89"},{"price":"0.00054778","size":"0"},{"price":"0.00054826","size":"5223.74"}],"bid":[{"price":"0.00054540","size":"5.18"},{"price":"0.00054532","size":"0"}],"sequence":19513185,"timestamp":"2021-07-15T03:00:34.641Z","symbol":"UNIBTC"}}
1626318034.7505028: {"jsonrpc":"2.0","method":"updateOrderbook","params":{"ask":[{"price":"0.615892","size":"0"},{"price":"0.616137","size":"10632.6"},{"price":"0.644533","size":"347706.3"},{"price":"0.646107","size":"0"},{"price":"0.662655","size":"399111.0"}],"bid":[{"price":"0.615116","size":"538.8"},{"price":"0.614883","size":"0"},{"price":"0.614346","size":"0"},{"price":"0.614284","size":"5500.0"}],"sequence":20584199,"timestamp":"2021-07-15T03:00:34.712Z","symbol":"XRPUSDT"}}
1626318034.7602282: {"jsonrpc":"2.0","method":"updateOrderbook","params":{"ask":[{"price":"0.00000065973","size":"15232570"},{"price":"0.00000094571","size":"2770690"}],"bid":[],"sequence":10532386,"timestamp":"2021-07-15T03:00:34.723Z","symbol":"SCBTC"}}
1626318034.7636049: {"jsonrpc":"2.0","method":"updateOrderbook","params":{"ask":[{"price":"0.00054567","size":"0"},{"price":"0.00054571","size":"4.33"},{"price":"0.00054594","size":"0"},{"price":"0.00054604","size":"17.11"},{"price":"0.00054611","size":"0"},{"price":"0.00054625","size":"16.96"},{"price":"0.00054819","size":"0"},{"price":"0.00054923","size":"658.12"},{"price":"0.00056018","size":"0"},{"price":"0.00056284","size":"2539.46"}],"bid":[{"price":"0.00054542","size":"5.18"},{"price":"0.00054540","size":"0"},{"price":"0.00054395","size":"650.72"},{"price":"0.00054368","size":"482.00"}],"sequence":19513186,"timestamp":"2021-07-15T03:00:34.731Z","symbol":"UNIBTC"}}
1626318034.856894: {"jsonrpc":"2.0","method":"updateOrderbook","params":{"ask":[{"price":"0.615892","size":"10632.5"},{"price":"0.616137","size":"0"},{"price":"0.662655","size":"399111.3"}],"bid":[],"sequence":20584200,"timestamp":"2021-07-15T03:00:34.793Z","symbol":"XRPUSDT"}}
1626318034.869993: {"jsonrpc":"2.0","method":"updateOrderbook","params":{"ask":[{"price":"0.00000036748","size":"255050"},{"price":"0.00000036787","size":"408320"},{"price":"0.00000036877","size":"0"},{"price":"0.00000036909","size":"0"},{"price":"0.00000065973","size":"15232580"},{"price":"0.00000094571","size":"2770710"}],"bid":[],"sequence":10532387,"timestamp":"2021-07-15T03:00:34.833Z","symbol":"SCBTC"}}
1626318034.870013: {"jsonrpc":"2.0","method":"updateOrderbook","params":{"ask":[{"price":"0.00054571","size":"0"},{"price":"0.00054577","size":"4.33"},{"price":"0.00054593","size":"0"},{"price":"0.00054601","size":"10.47"},{"price":"0.00054604","size":"0"},{"price":"0.00054615","size":"17.11"},{"price":"0.00054692","size":"0"},{"price":"0.00054715","size":"193.61"},{"price":"0.00059258","size":"0"},{"price":"0.00059866","size":"2343.84"},{"price":"0.00078338","size":"0"},{"price":"0.00078605","size":"3484.36"}],"bid":[{"price":"0.00054545","size":"5.18"},{"price":"0.00054542","size":"0"},{"price":"0.00054523","size":"9.62"},{"price":"0.00054509","size":"0"},{"price":"0.00053467","size":"0"},{"price":"0.00053289","size":"2974.71"}],"sequence":19513187,"timestamp":"2021-07-15T03:00:34.819Z","symbol":"UNIBTC"}}
1626318034.9500742: {"jsonrpc":"2.0","method":"updateOrderbook","params":{"ask":[{"price":"0.618240","size":"22946.4"},{"price":"0.619032","size":"0"},{"price":"0.662655","size":"399111.5"},{"price":"0.671039","size":"229002.7"},{"price":"0.684350","size":"0"},{"price":"0.847048","size":"324970.5"},{"price":"0.862547","size":"0"}],"bid":[],"sequence":20584201,"timestamp":"2021-07-15T03:00:34.941Z","symbol":"XRPUSDT"}}
1626318034.961749: {"jsonrpc":"2.0","method":"updateOrderbook","params":{"ask":[{"price":"0.00000065973","size":"0"},{"price":"0.00000065974","size":"15232600"},{"price":"0.00000094571","size":"2770730"}],"bid":[],"sequence":10532388,"timestamp":"2021-07-15T03:00:34.938Z","symbol":"SCBTC"}}
1626318034.961934: {"jsonrpc":"2.0","method":"updateOrderbook","params":{"ask":[{"price":"0.00054577","size":"0"},{"price":"0.00054582","size":"4.33"},{"price":"0.00054601","size":"0"},{"price":"0.00054603","size":"0"},{"price":"0.00054609","size":"10.47"},{"price":"0.00054615","size":"0"},{"price":"0.00054619","size":"0"},{"price":"0.00054624","size":"16.70"},{"price":"0.00054625","size":"34.07"},{"price":"0.00054635","size":"0"},{"price":"0.00054637","size":"66.20"},{"price":"0.00054647","size":"77.40"},{"price":"0.00054651","size":"0"},{"price":"0.00054673","size":"0"},{"price":"0.00054678","size":"218.78"},{"price":"0.00054694","size":"276.50"},{"price":"0.00054725","size":"0"},{"price":"0.00054736","size":"0"},{"price":"0.00054766","size":"0"},{"price":"0.00054777","size":"291.41"},{"price":"0.00054825","size":"375.71"},{"price":"0.00054879","size":"484.13"},{"price":"0.00054922","size":"0"},{"price":"0.00055059","size":"805.27"},{"price":"0.00055097","size":"0"},{"price":"0.00055157","size":"1244.50"},{"price":"0.00055241","size":"0"},{"price":"0.00055429","size":"0"},{"price":"0.00055557","size":"881.76"},{"price":"0.00056166","size":"1757.02"},{"price":"0.00059866","size":"0"},{"price":"0.00062612","size":"0"},{"price":"0.00066197","size":"2343.84"},{"price":"0.00067260","size":"1125.76"},{"price":"0.00078605","size":"0"},{"price":"0.00080159","size":"3484.36"},{"price":"0.00081742","size":"0"},{"price":"0.00082961","size":"1585.64"}],"bid":[{"price":"0.00054550","size":"5.18"},{"price":"0.00054545","size":"0"},{"price":"0.00054500","size":"18.03"},{"price":"0.00054490","size":"0"},{"price":"0.00054445","size":"177.91"},{"price":"0.00054409","size":"0"}],"sequence":19513188,"timestamp":"2021-07-15T03:00:34.942Z","symbol":"UNIBTC"}}
1626318035.065683: {"jsonrpc":"2.0","method":"updateOrderbook","params":{"ask":[{"price":"0.662655","size":"399111.7"}],"bid":[],"sequence":20584202,"timestamp":"2021-07-15T03:00:34.947Z","symbol":"XRPUSDT"}}
1626318035.068052: {"jsonrpc":"2.0","method":"updateOrderbook","params":{"ask":[{"price":"0.00054647","size":"0"},{"price":"0.00054666","size":"144.16"},{"price":"0.00054715","size":"0"},{"price":"0.00054734","size":"193.61"},{"price":"0.00056166","size":"0"},{"price":"0.00056230","size":"1757.02"},{"price":"0.00066197","size":"0"},{"price":"0.00066759","size":"2343.84"}],"bid":[{"price":"0.00054489","size":"80.24"},{"price":"0.00054464","size":"17.87"},{"price":"0.00054457","size":"0"},{"price":"0.00054429","size":"0"},{"price":"0.00053289","size":"0"},{"price":"0.00053181","size":"2974.71"}],"sequence":19513189,"timestamp":"2021-07-15T03:00:35.038Z","symbol":"UNIBTC"}}
1626318035.149075: {"jsonrpc":"2.0","method":"updateOrderbook","params":{"ask":[{"price":"0.662655","size":"399112.0"}],"bid":[],"sequence":20584203,"timestamp":"2021-07-15T03:00:35.052Z","symbol":"XRPUSDT"}}
1626318035.169122: {"jsonrpc":"2.0","method":"updateOrderbook","params":{"ask":[{"price":"0.00000065974","size":"15232620"},{"price":"0.00000094571","size":"2770750"}],"bid":[],"sequence":10532389,"timestamp":"2021-07-15T03:00:35.044Z","symbol":"SCBTC"}}
1626318035.169143: {"jsonrpc":"2.0","method":"updateOrderbook","params":{"ask":[{"price":"0.00054582","size":"0"},{"price":"0.00054590","size":"4.33"},{"price":"0.00054610","size":"0"},{"price":"0.00054625","size":"17.11"},{"price":"0.00054644","size":"16.96"},{"price":"0.00054649","size":"0"},{"price":"0.00054650","size":"218.51"},{"price":"0.00054663","size":"219.66"},{"price":"0.00054666","size":"77.40"},{"price":"0.00054685","size":"400.60"}],"bid":[{"price":"0.00054550","size":"0"},{"price":"0.00054546","size":"5.18"}],"sequence":19513190,"timestamp":"2021-07-15T03:00:35.135Z","symbol":"UNIBTC"}}
1626318035.249103: {"jsonrpc":"2.0","method":"updateOrderbook","params":{"ask":[],"bid":[{"price":"12.107","size":"5.8718"},{"price":"12.105","size":"0"}],"sequence":2190721,"timestamp":"2021-07-15T03:00:35.229Z","symbol":"SPIUSD"}}
1626318035.251008: {"jsonrpc":"2.0","method":"updateOrderbook","params":{"ask":[{"price":"0.662655","size":"399112.4"}],"bid":[{"price":"0.615667","size":"1591.5"},{"price":"0.615658","size":"0"}],"sequence":20584204,"timestamp":"2021-07-15T03:00:35.202Z","symbol":"XRPUSDT"}}
1626318035.2571352: {"jsonrpc":"2.0","method":"updateOrderbook","params":{"ask":[{"price":"0.00000065974","size":"15232630"},{"price":"0.00000094571","size":"2770770"}],"bid":[],"sequence":10532390,"timestamp":"2021-07-15T03:00:35.149Z","symbol":"SCBTC"}}
1626318035.2572749: {"jsonrpc":"2.0","method":"updateOrderbook","params":{"ask":[{"price":"0.00054590","size":"0"},{"price":"0.00054592","size":"4.33"},{"price":"0.00054609","size":"0"},{"price":"0.00054618","size":"10.47"}],"bid":[{"price":"0.00054550","size":"5.18"},{"price":"0.00054546","size":"0"},{"price":"0.00054498","size":"18.61"},{"price":"0.00054486","size":"0"},{"price":"0.00054336","size":"929.35"},{"price":"0.00054312","size":"0"},{"price":"0.00054270","size":"0"},{"price":"0.00054263","size":"634.39"},{"price":"0.00053181","size":"0"},{"price":"0.00052751","size":"2974.71"}],"sequence":19513191,"timestamp":"2021-07-15T03:00:35.231Z","symbol":"UNIBTC"}}
1626318035.391365: {"jsonrpc":"2.0","method":"updateOrderbook","params":{"ask":[],"bid":[{"price":"12.108","size":"5.7667"},{"price":"12.106","size":"0"}],"sequence":2190722,"timestamp":"2021-07-15T03:00:35.304Z","symbol":"SPIUSD"}}
1626318035.3914912: {"jsonrpc":"2.0","method":"updateOrderbook","params":{"ask":[{"price":"0.662655","size":"399112.6"}],"bid":[],"sequence":20584205,"timestamp":"2021-07-15T03:00:35.277Z","symbol":"XRPUSDT"}}
1626318035.391516: {"jsonrpc":"2.0","method":"updateOrderbook","params":{"ask":[{"price":"0.00000065974","size":"15232650"},{"price":"0.00000094571","size":"2770790"}],"bid":[],"sequence":10532391,"timestamp":"2021-07-15T03:00:35.264Z","symbol":"SCBTC"}}
1626318035.391535: {"jsonrpc":"2.0","method":"updateOrderbook","params":{"ask":[{"price":"0.00054592","size":"0"},{"price":"0.00054597","size":"4.33"},{"price":"0.00054671","size":"0"},{"price":"0.00054685","size":"66.76"},{"price":"0.00054694","size":"573.01"},{"price":"0.00054720","size":"0"},{"price":"0.00054725","size":"333.84"},{"price":"0.00054738","size":"0"},{"price":"0.00054764","size":"440.89"},{"price":"0.00054826","size":"4926.48"},{"price":"0.00054910","size":"963.50"},{"price":"0.00054920","size":"0"},{"price":"0.00055005","size":"1302.32"}],"bid":[{"price":"0.00054553","size":"5.18"},{"price":"0.00054550","size":"0"},{"price":"0.00054509","size":"18.03"},{"price":"0.00054500","size":"0"},{"price":"0.00054474","size":"196.86"},{"price":"0.00054436","size":"0"}],"sequence":19513192,"timestamp":"2021-07-15T03:00:35.341Z","symbol":"UNIBTC"}}
1626318035.4571772: {"jsonrpc":"2.0","method":"updateOrderbook","params":{"ask":[{"price":"0.615765","size":"11000.0"},{"price":"0.662655","size":"399112.9"},{"price":"0.701117","size":"228479.7"}],"bid":[{"price":"0.615720","size":"0"},{"price":"0.615293","size":"0"},{"price":"0.615195","size":"1337.0"}],"sequence":20584206,"timestamp":"2021-07-15T03:00:35.412Z","symbol":"XRPUSDT"}}
1626318035.461699: {"jsonrpc":"2.0","method":"updateOrderbook","params":{"ask":[{"price":"0.00000036911","size":"603920"},{"price":"0.00000037466","size":"661850"},{"price":"0.00000037986","size":"0"},{"price":"0.00000041211","size":"4600"},{"price":"0.00000065974","size":"15232670"},{"price":"0.00000094571","size":"2770820"}],"bid":[{"price":"0.00000036265","size":"1248220"},{"price":"0.00000036210","size":"0"}],"sequence":10532392,"timestamp":"2021-07-15T03:00:35.439Z","symbol":"SCBTC"}}
1626318035.461733: {"jsonrpc":"2.0","method":"updateOrderbook","params":{"ask":[{"price":"0.00054594","size":"4.33"},{"price":"0.00054597","size":"0"},{"price":"0.00054755","size":"0"},{"price":"0.00054826","size":"997.64"},{"price":"0.00054873","size":"4260.24"}],"bid":[{"price":"0.00054553","size":"0"},{"price":"0.00054547","size":"5.18"},{"price":"0.00054432","size":"269.93"},{"price":"0.00054395","size":"380.79"},{"price":"0.00054263","size":"0"},{"price":"0.00054222","size":"634.39"},{"price":"0.00052751","size":"0"},{"price":"0.00052358","size":"2974.71"}],"sequence":19513193,"timestamp":"2021-07-15T03:00:35.441Z","symbol":"UNIBTC"}}
1626318035.5581539: {"jsonrpc":"2.0","method":"updateOrderbook","params":{"ask":[{"price":"0.615772","size":"1331.6"},{"price":"0.615779","size":"0"},{"price":"0.662655","size":"399113.3"}],"bid":[{"price":"0.615569","size":"2955.7"},{"price":"0.615540","size":"0"}],"sequence":20584207,"timestamp":"2021-07-15T03:00:35.543Z","symbol":"XRPUSDT"}}
1626318035.566133: {"jsonrpc":"2.0","method":"updateOrderbook","params":{"ask":[{"price":"0.00000065974","size":"15232690"},{"price":"0.00000094571","size":"2770830"}],"bid":[],"sequence":10532393,"timestamp":"2021-07-15T03:00:35.528Z","symbol":"SCBTC"}}
1626318035.566272: {"jsonrpc":"2.0","method":"updateOrderbook","params":{"ask":[{"price":"0.00054658","size":"0"},{"price":"0.00054690","size":"18.08"}],"bid":[{"price":"0.00054320","size":"1215.25"},{"price":"0.00054209","size":"0"},{"price":"0.00052358","size":"0"},{"price":"0.00052259","size":"2974.71"}],"sequence":19513194,"timestamp":"2021-07-15T03:00:35.538Z","symbol":"UNIBTC"}}
1626318035.655068: {"jsonrpc":"2.0","method":"updateOrderbook","params":{"ask":[{"price":"0.615765","size":"0"},{"price":"0.615772","size":"0"},{"price":"0.615780","size":"1331.6"},{"price":"0.662655","size":"399113.6"}],"bid":[{"price":"0.615709","size":"11000.0"},{"price":"0.615667","size":"0"},{"price":"0.615657","size":"1591.5"},{"price":"0.615293","size":"1337.0"},{"price":"0.615195","size":"0"}],"sequence":20584208,"timestamp":"2021-07-15T03:00:35.641Z","symbol":"XRPUSDT"}}
1626318035.6631281: {"jsonrpc":"2.0","method":"updateOrderbook","params":{"ask":[{"price":"0.00000037466","size":"0"},{"price":"0.00000037510","size":"661850"},{"price":"0.00000065974","size":"15232700"},{"price":"0.00000094571","size":"2770850"}],"bid":[{"price":"0.00000036497","size":"110390"},{"price":"0.00000036482","size":"0"}],"sequence":10532394,"timestamp":"2021-07-15T03:00:35.614Z","symbol":"SCBTC"}}
1626318035.663321: {"jsonrpc":"2.0","method":"updateOrderbook","params":{"ask":[{"price":"0.00054588","size":"4.33"},{"price":"0.00054594","size":"0"}],"bid":[{"price":"0.00054534","size":"18.34"},{"price":"0.00054514","size":"18.61"},{"price":"0.00054498","size":"0"},{"price":"0.00054476","size":"0"},{"price":"0.00054441","size":"239.72"},{"price":"0.00054390","size":"0"},{"price":"0.00054388","size":"346.03"},{"price":"0.00054345","size":"1010.75"},{"price":"0.00052259","size":"0"},{"price":"0.00052065","size":"2974.71"}],"sequence":19513195,"timestamp":"2021-07-15T03:00:35.614Z","symbol":"UNIBTC"}}
1626318035.754923: {"jsonrpc":"2.0","method":"updateOrderbook","params":{"ask":[{"price":"0.662655","size":"399113.7"}],"bid":[],"sequence":20584209,"timestamp":"2021-07-15T03:00:35.683Z","symbol":"XRPUSDT"}}
1626318035.771927: {"jsonrpc":"2.0","method":"updateOrderbook","params":{"ask":[{"price":"0.00000065974","size":"15232720"},{"price":"0.00000094571","size":"2770870"}],"bid":[{"price":"0.00000036498","size":"1000"},{"price":"0.00000036483","size":"0"}],"sequence":10532395,"timestamp":"2021-07-15T03:00:35.720Z","symbol":"SCBTC"}}
1626318035.771965: {"jsonrpc":"2.0","method":"updateOrderbook","params":{"ask":[{"price":"0.00054712","size":"0"},{"price":"0.00054756","size":"250.69"}],"bid":[],"sequence":19513196,"timestamp":"2021-07-15T03:00:35.668Z","symbol":"UNIBTC"}}
1626318035.852674: {"jsonrpc":"2.0","method":"updateOrderbook","params":{"ask":[{"price":"0.662655","size":"399114.0"}],"bid":[],"sequence":20584210,"timestamp":"2021-07-15T03:00:35.783Z","symbol":"XRPUSDT"}}
1626318035.86176: {"jsonrpc":"2.0","method":"updateOrderbook","params":{"ask":[{"price":"0.00000041405","size":"1016210"},{"price":"0.00000042829","size":"0"},{"price":"0.00000044445","size":"10293110"},{"price":"0.00000060970","size":"0"},{"price":"0.00000065974","size":"15232730"},{"price":"0.00000094571","size":"2770890"}],"bid":[{"price":"0.00000034003","size":"0"}],"sequence":10532396,"timestamp":"2021-07-15T03:00:35.838Z","symbol":"SCBTC"}}
1626318035.875124: {"jsonrpc":"2.0","method":"updateOrderbook","params":{"ask":[{"price":"0.00054586","size":"4.33"},{"price":"0.00054588","size":"0"},{"price":"0.00054610","size":"10.47"},{"price":"0.00054613","size":"16.70"},{"price":"0.00054618","size":"0"},{"price":"0.00054624","size":"0"},{"price":"0.00054867","size":"0"},{"price":"0.00054910","size":"1550.86"},{"price":"0.00055054","size":"0"},{"price":"0.00055288","size":"662.81"},{"price":"0.00055557","size":"0"},{"price":"0.00057411","size":"881.76"},{"price":"0.00066759","size":"0"},{"price":"0.00067076","size":"2343.84"},{"price":"0.00067260","size":"0"},{"price":"0.00075423","size":"1125.76"},{"price":"0.00080159","size":"0"},{"price":"0.00080246","size":"3484.36"},{"price":"0.00082961","size":"0"},{"price":"0.00084103","size":"1585.64"}],"bid":[{"price":"0.00054549","size":"5.18"},{"price":"0.00054547","size":"0"}],"sequence":19513197,"timestamp":"2021-07-15T03:00:35.809Z","symbol":"UNIBTC"}}
1626318035.953599: {"jsonrpc":"2.0","method":"updateOrderbook","params":{"ask":[],"bid":[{"price":"12.107","size":"0"}],"sequence":2190723,"timestamp":"2021-07-15T03:00:35.888Z","symbol":"SPIUSD"}}
1626318035.96359: {"jsonrpc":"2.0","method":"updateOrderbook","params":{"ask":[{"price":"0.615780","size":"0"},{"price":"0.615788","size":"1331.6"},{"price":"0.662655","size":"399114.4"}],"bid":[{"price":"0.615663","size":"1591.5"},{"price":"0.615657","size":"0"}],"sequence":20584211,"timestamp":"2021-07-15T03:00:35.937Z","symbol":"XRPUSDT"}}
1626318035.9727612: {"jsonrpc":"2.0","method":"updateOrderbook","params":{"ask":[{"price":"0.00000036816","size":"0"},{"price":"0.00000036828","size":"26770"},{"price":"0.00000043091","size":"0"},{"price":"0.00000043194","size":"522810"},{"price":"0.00000044445","size":"8911260"},{"price":"0.00000044488","size":"1381850"},{"price":"0.00000054523","size":"0"},{"price":"0.00000054577","size":"757990"},{"price":"0.00000065974","size":"15232750"},{"price":"0.00000078071","size":"0"},{"price":"0.00000078139","size":"2003810"},{"price":"0.00000094571","size":"2770910"},{"price":"0.00000095824","size":"0"},{"price":"0.00000095882","size":"2754880"},{"price":"0.00000284543","size":"0"},{"price":"0.00000284830","size":"4472830"}],"bid":[{"price":"0.00000034004","size":"0"},{"price":"0.00000033944","size":"234600"},{"price":"0.00000032343","size":"1993120"},{"price":"0.00000023946","size":"0"},{"price":"0.00000004529","size":"2752080"},{"price":"0.00000000735","size":"0"}],"sequence":10532397,"timestamp":"2021-07-15T03:00:35.929Z","symbol":"SCBTC"}}
1626318035.9731882: {"jsonrpc":"2.0","method":"updateOrderbook","params":{"ask":[],"bid":[{"price":"0.00054551","size":"5.18"},{"price":"0.00054549","size":"0"},{"price":"0.00054506","size":"18.58"},{"price":"0.00054503","size":"69.23"},{"price":"0.00054490","size":"72.79"},{"price":"0.00054478","size":"0"},{"price":"0.00054467","size":"0"},{"price":"0.00054451","size":"0"}],"sequence":19513198,"timestamp":"2021-07-15T03:00:35.912Z","symbol":"UNIBTC"}}
1626318036.0573928: {"jsonrpc":"2.0","method":"updateOrderbook","params":{"ask":[],"bid":[{"price":"12.109","size":"5.8708"},{"price":"12.108","size":"0"},{"price":"12.060","size":"5.7745"}],"sequence":2190724,"timestamp":"2021-07-15T03:00:35.972Z","symbol":"SPIUSD"}}
1626318036.060075: {"jsonrpc":"2.0","method":"updateOrderbook","params":{"ask":[{"price":"0.620782","size":"0"},{"price":"0.620879","size":"483.1"},{"price":"0.662655","size":"399114.6"}],"bid":[],"sequence":20584212,"timestamp":"2021-07-15T03:00:36.007Z","symbol":"XRPUSDT"}}
1626318036.075338: {"jsonrpc":"2.0","method":"updateOrderbook","params":{"ask":[{"price":"0.00000065974","size":"15232760"},{"price":"0.00000094571","size":"2770930"}],"bid":[],"sequence":10532398,"timestamp":"2021-07-15T03:00:36.039Z","symbol":"SCBTC"}}
1626318036.0753531: {"jsonrpc":"2.0","method":"updateOrderbook","params":{"ask":[{"price":"0.00054840","size":"658.12"},{"price":"0.00054923","size":"0"}],"bid":[{"price":"0.00054474","size":"0"},{"price":"0.00054453","size":"196.86"}],"sequence":19513199,"timestamp":"2021-07-15T03:00:35.969Z","symbol":"UNIBTC"}}
1626318036.151427: {"jsonrpc":"2.0","method":"updateOrderbook","params":{"ask":[],"bid":[{"price":"12.110","size":"5.7773"},{"price":"12.060","size":"0"}],"sequence":2190725,"timestamp":"2021-07-15T03:00:36.090Z","symbol":"SPIUSD"}}
1626318036.151464: {"jsonrpc":"2.0","method":"updateOrderbook","params":{"ask":[{"price":"0.615892","size":"0"},{"price":"0.616137","size":"10632.6"},{"price":"0.662655","size":"399115.0"}],"bid":[{"price":"0.615671","size":"1591.5"},{"price":"0.615663","size":"0"}],"sequence":20584213,"timestamp":"2021-07-15T03:00:36.128Z","symbol":"XRPUSDT"}}
1626318036.162061: {"jsonrpc":"2.0","method":"updateOrderbook","params":{"ask":[{"price":"0.00000065974","size":"15232780"},{"price":"0.00000094571","size":"2770940"}],"bid":[],"sequence":10532399,"timestamp":"2021-07-15T03:00:36.144Z","symbol":"SCBTC"}}
1626318036.162084: {"jsonrpc":"2.0","method":"updateOrderbook","params":{"ask":[{"price":"0.00054646","size":"296.51"},{"price":"0.00054694","size":"276.50"}],"bid":[{"price":"0.00054267","size":"1587.01"},{"price":"0.00054166","size":"0"}],"sequence":19513200,"timestamp":"2021-07-15T03:00:36.064Z","symbol":"UNIBTC"}}
1626318036.2709591: {"jsonrpc":"2.0","method":"updateOrderbook","params":{"ask":[{"price":"0.662655","size":"399115.1"}],"bid":[{"price":"0.614367","size":"5500.0"},{"price":"0.614284","size":"0"}],"sequence":20584214,"timestamp":"2021-07-15T03:00:36.185Z","symbol":"XRPUSDT"}}
1626318036.270994: {"jsonrpc":"2.0","method":"updateOrderbook","params":{"ask":[{"price":"0.00000094571","size":"2770950"}],"bid":[],"sequence":10532400,"timestamp":"2021-07-15T03:00:36.149Z","symbol":"SCBTC"}}
1626318036.2710028: {"jsonrpc":"2.0","method":"updateOrderbook","params":{"ask":[],"bid":[{"price":"0.00054552","size":"5.18"},{"price":"0.00054551","size":"0"}],"sequence":19513201,"timestamp":"2021-07-15T03:00:36.238Z","symbol":"UNIBTC"}}
1626318036.368358: {"jsonrpc":"2.0","method":"updateOrderbook","params":{"ask":[{"price":"0.615788","size":"0"},{"price":"0.615797","size":"1331.6"},{"price":"0.616906","size":"0"},{"price":"0.616976","size":"6433.6"},{"price":"0.617284","size":"0"},{"price":"0.617459","size":"4276.9"},{"price":"0.617687","size":"0"},{"price":"0.617880","size":"12316.2"},{"price":"0.627015","size":"129038.8"},{"price":"0.633757","size":"0"},{"price":"0.644533","size":"0"},{"price":"0.646630","size":"347706.3"},{"price":"0.651679","size":"181214.3"},{"price":"0.657613","size":"0"},{"price":"0.662655","size":"399115.4"}],"bid":[],"sequence":20584215,"timestamp":"2021-07-15T03:00:36.287Z","symbol":"XRPUSDT"}}
1626318036.374036: {"jsonrpc":"2.0","method":"updateOrderbook","params":{"ask":[{"price":"0.00000065974","size":"15232810"},{"price":"0.00000090036","size":"2001500"},{"price":"0.00000094571","size":"2770980"},{"price":"0.00000106078","size":"0"},{"price":"0.00000124824","size":"2705250"},{"price":"0.00000131433","size":"0"}],"bid":[],"sequence":10532401,"timestamp":"2021-07-15T03:00:36.343Z","symbol":"SCBTC"}}
1626318036.374058: {"jsonrpc":"2.0","method":"updateOrderbook","params":{"ask":[{"price":"0.00054586","size":"0"},{"price":"0.00054588","size":"4.33"},{"price":"0.00054646","size":"0"},{"price":"0.00054690","size":"314.59"},{"price":"0.00054826","size":"666.24"},{"price":"0.00054961","size":"331.40"},{"price":"0.00054992","size":"0"},{"price":"0.00055057","size":"433.80"},{"price":"0.00055288","size":"0"},{"price":"0.00055404","size":"662.81"},{"price":"0.00057411","size":"0"},{"price":"0.00060060","size":"881.76"},{"price":"0.00075423","size":"0"},{"price":"0.00078640","size":"1125.76"},{"price":"0.00084103","size":"0"}],"bid":[{"price":"0.00054555","size":"5.18"},{"price":"0.00054552","size":"0"}],"sequence":19513202,"timestamp":"2021-07-15T03:00:36.329Z","symbol":"UNIBTC"}}
1626318036.455518: {"jsonrpc":"2.0","method":"updateOrderbook","params":{"ask":[{"price":"0.615797","size":"0"},{"price":"0.615859","size":"1331.6"},{"price":"0.615893","size":"0"},{"price":"0.615956","size":"3215.5"},{"price":"0.619854","size":"64176.0"},{"price":"0.620909","size":"0"},{"price":"0.627015","size":"0"},{"price":"0.629095","size":"129038.8"},{"price":"0.651679","size":"0"},{"price":"0.653682","size":"181214.3"},{"price":"0.662655","size":"399115.8"},{"price":"0.701117","size":"0"}],"bid":[{"price":"0.615737","size":"1591.5"},{"price":"0.615671","size":"0"},{"price":"0.615339","size":"1337.0"},{"price":"0.615293","size":"0"}],"sequence":20584216,"timestamp":"2021-07-15T03:00:36.429Z","symbol":"XRPUSDT"}}
1626318036.457639: {"jsonrpc":"2.0","method":"updateOrderbook","params":{"ask":[{"price":"0.00000065974","size":"15232820"},{"price":"0.00000094571","size":"2770990"},{"price":"0.00000096947","size":"3422070"},{"price":"0.00000097026","size":"0"}],"bid":[{"price":"0.00000036497","size":"0"},{"price":"0.00000036485","size":"110390"},{"price":"0.00000032343","size":"0"},{"price":"0.00000032019","size":"1993120"},{"price":"0.00000004529","size":"0"},{"price":"0.00000004273","size":"2752080"}],"sequence":10532402,"timestamp":"2021-07-15T03:00:36.399Z","symbol":"SCBTC"}}
1626318036.4602041: {"jsonrpc":"2.0","method":"updateOrderbook","params":{"ask":[{"price":"0.00054661","size":"66.76"},{"price":"0.00054685","size":"0"}],"bid":[{"price":"0.00054555","size":"0"},{"price":"0.00054550","size":"5.18"},{"price":"0.00052065","size":"0"},{"price":"0.00051929","size":"2974.71"}],"sequence":19513203,"timestamp":"2021-07-15T03:00:36.441Z","symbol":"UNIBTC"}}
