1626318026.3528981: {"jsonrpc":"2.0","method":"updateOrderbook","params":{"ask":[{"price":"0.662655","size":"399087.8"}],"bid":[{"price":"0.615562","size":"0"},{"price":"0.615413","size":"2839.8"}],"sequence":20584115,"timestamp":"2021-07-15T03:00:26.311Z","symbol":"XRPUSDT"}}
1626318026.3697338: {"jsonrpc":"2.0","method":"updateOrderbook","params":{"ask":[{"price":"0.00000094570","size":"2769270"}],"bid":[],"sequence":10532305,"timestamp":"2021-07-15T03:00:26.244Z","symbol":"SCBTC"}}
1626318026.36976: {"jsonrpc":"2.0","method":"updateOrderbook","params":{"ask":[{"price":"0.00054593","size":"16.70"},{"price":"0.00054622","size":"66.20"},{"price":"0.00054625","size":"0"},{"price":"0.00054639","size":"18.09"},{"price":"0.00054663","size":"0"},{"price":"0.00054690","size":"333.84"},{"price":"0.00054894","size":"0"},{"price":"0.00054949","size":"1302.32"},{"price":"0.00083984","size":"1585.64"}],"bid":[{"price":"0.00054528","size":"5.18"},{"price":"0.00054523","size":"0"},{"price":"0.00054395","size":"269.93"},{"price":"0.00054367","size":"0"}],"sequence":19513111,"timestamp":"2021-07-15T03:00:26.288Z","symbol":"UNIBTC"}}
1626318026.457908: {"jsonrpc":"2.0","method":"updateOrderbook","params":{"ask":[{"price":"0.615885","size":"10632.6"},{"price":"0.616137","size":"0"},{"price":"0.662655","size":"399088.0"}],"bid":[],"sequence":20584116,"timestamp":"2021-07-15T03:00:26.392Z","symbol":"XRPUSDT"}}
1626318026.467776: {"jsonrpc":"2.0","method":"updateOrderbook","params":{"ask":[{"price":"0.00000041289","size":"0"},{"price":"0.00000041356","size":"1016210"},{"price":"0.00000065973","size":"15231320"},{"price":"0.00000088985","size":"0"},{"price":"0.00000089093","size":"2001500"},{"price":"0.00000094570","size":"2769290"},{"price":"0.00000124541","size":"0"},{"price":"0.00000124621","size":"2705250"},{"price":"0.00000146884","size":"0"},{"price":"0.00000146968","size":"3222000"}],"bid":[],"sequence":10532306,"timestamp":"2021-07-15T03:00:26.382Z","symbol":"SCBTC"}}
1626318026.4678211: {"jsonrpc":"2.0","method":"updateOrderbook","params":{"ask":[],"bid":[{"price":"0.00054531","size":"5.18"},{"price":"0.00054528","size":"0"}],"sequence":19513112,"timestamp":"2021-07-15T03:00:26.344Z","symbol":"UNIBTC"}}
1626318026.543921: {"jsonrpc":"2.0","method":"updateOrderbook","params":{"ask":[],"bid":[{"price":"12.093","size":"0"}],"sequence":2190702,"timestamp":"2021-07-15T03:00:26.468Z","symbol":"SPIUSD"}}
1626318026.570105: {"jsonrpc":"2.0","method":"updateOrderbook","params":{"ask":[{"price":"0.615885","size":"10632.7"},{"price":"0.662655","size":"399088.2"}],"bid":[{"price":"0.615690","size":"1596.5"},{"price":"0.615685","size":"0"}],"sequence":20584117,"timestamp":"2021-07-15T03:00:26.474Z","symbol":"XRPUSDT"}}
1626318026.570165: {"jsonrpc":"2.0","method":"updateOrderbook","params":{"ask":[{"price":"0.00000065973","size":"15231340"},{"price":"0.00000094570","size":"2769310"}],"bid":[],"sequence":10532307,"timestamp":"2021-07-15T03:00:26.490Z","symbol":"SCBTC"}}
1626318026.5701902: {"jsonrpc":"2.0","method":"updateOrderbook","params":{"ask":[{"price":"0.00054560","size":"4.33"},{"price":"0.00054562","size":"0"}],"bid":[{"price":"0.00054531","size":"0"},{"price":"0.00054528","size":"5.18"},{"price":"0.00054335","size":"468.52"},{"price":"0.00054296","size":"0"},{"price":"0.00054229","size":"634.39"},{"price":"0.00054185","size":"0"}],"sequence":19513113,"timestamp":"2021-07-15T03:00:26.532Z","symbol":"UNIBTC"}}
1626318026.645018: {"jsonrpc":"2.0","method":"updateOrderbook","params":{"ask":[{"price":"10000.000","size":"0.0010"}],"bid":[{"price":"12.095","size":"5.8776"},{"price":"12.094","size":"0"},{"price":"12.060","size":"6.3729"},{"price":"0.010","size":"1000.0010"}],"sequence":2190703,"timestamp":"2021-07-15T03:00:26.591Z","symbol":"SPIUSD"}}
1626318026.652928: {"jsonrpc":"2.0","method":"updateOrderbook","params":{"ask":[{"price":"0.621553","size":"0"},{"price":"0.623377","size":"44632.4"},{"price":"0.662655","size":"399088.6"},{"price":"0.663943","size":"0"},{"price":"0.671037","size":"229002.7"},{"price":"0.836239","size":"0"},{"price":"0.847046","size":"324970.5"}],"bid":[],"sequence":20584118,"timestamp":"2021-07-15T03:00:26.611Z","symbol":"XRPUSDT"}}
1626318026.6690948: {"jsonrpc":"2.0","method":"updateOrderbook","params":{"ask":[{"price":"0.00000065973","size":"15231360"},{"price":"0.00000094570","size":"2769320"}],"bid":[],"sequence":10532308,"timestamp":"2021-07-15T03:00:26.599Z","symbol":"SCBTC"}}
1626318026.669135: {"jsonrpc":"2.0","method":"updateOrderbook","params":{"ask":[{"price":"0.00054553","size":"4.33"},{"price":"0.00054560","size":"0"},{"price":"0.00057165","size":"0"},{"price":"0.00057270","size":"2539.46"}],"bid":[{"price":"0.00054528","size":"0"},{"price":"0.00054525","size":"5.18"},{"price":"0.00054489","size":"18.03"},{"price":"0.00054476","size":"18.34"},{"price":"0.00052694","size":"0.80"}],"sequence":19513114,"timestamp":"2021-07-15T03:00:26.639Z","symbol":"UNIBTC"}}
1626318026.750619: {"jsonrpc":"2.0","method":"updateOrderbook","params":{"ask":[],"bid":[{"price":"12.096","size":"6.4381"},{"price":"12.060","size":"0"}],"sequence":2190704,"timestamp":"2021-07-15T03:00:26.668Z","symbol":"SPIUSD"}}
1626318026.750684: {"jsonrpc":"2.0","method":"updateOrderbook","params":{"ask":[{"price":"0.662655","size":"399088.7"}],"bid":[],"sequence":20584119,"timestamp":"2021-07-15T03:00:26.644Z","symbol":"XRPUSDT"}}
1626318026.773767: {"jsonrpc":"2.0","method":"updateOrderbook","params":{"ask":[{"price":"0.00000065973","size":"15231370"},{"price":"0.00000094570","size":"2769340"}],"bid":[],"sequence":10532309,"timestamp":"2021-07-15T03:00:26.704Z","symbol":"SCBTC"}}
1626318026.773814: {"jsonrpc":"2.0","method":"updateOrderbook","params":{"ask":[{"price":"0.00054551","size":"4.33"},{"price":"0.00054553","size":"0"},{"price":"0.00054607","size":"85.08"},{"price":"0.00054611","size":"16.96"},{"price":"0.00054619","size":"0"},{"price":"0.00054622","size":"0"},{"price":"0.00054633","size":"77.40"},{"price":"0.00054650","size":"66.76"},{"price":"0.00054679","size":"0"},{"price":"0.00054692","size":"193.61"},{"price":"0.00054712","size":"0"},{"price":"0.00057270","size":"0"},{"price":"0.00057461","size":"2539.46"}],"bid":[{"price":"0.00054525","size":"0"},{"price":"0.00054523","size":"5.18"},{"price":"0.00054368","size":"862.79"},{"price":"0.00054279","size":"331.21"},{"price":"0.00052694","size":"0"}],"sequence":19513115,"timestamp":"2021-07-15T03:00:26.733Z","symbol":"UNIBTC"}}
1626318026.866473: {"jsonrpc":"2.0","method":"updateOrderbook","params":{"ask":[{"price":"0.662655","size":"399089.1"}],"bid":[],"sequence":20584120,"timestamp":"2021-07-15T03:00:26.768Z","symbol":"XRPUSDT"}}
1626318026.86653: {"jsonrpc":"2.0","method":"updateOrderbook","params":{"ask":[{"price":"0.00000065973","size":"15231390"},{"price":"0.00000094570","size":"2769360"}],"bid":[{"price":"0.00000036496","size":"0"}],"sequence":10532310,"timestamp":"2021-07-15T03:00:26.836Z","symbol":"SCBTC"}}
1626318026.866556: {"jsonrpc":"2.0","method":"updateOrderbook","params":{"ask":[{"price":"0.00054547","size":"4.33"},{"price":"0.00054551","size":"0"}],"bid":[{"price":"0.00054524","size":"5.18"},{"price":"0.00054523","size":"0"},{"price":"0.00053050","size":"442.49"}],"sequence":19513116,"timestamp":"2021-07-15T03:00:26.839Z","symbol":"UNIBTC"}}
1626318026.9637928: {"jsonrpc":"2.0","method":"updateOrderbook","params":{"ask":[{"price":"0.662655","size":"399089.3"}],"bid":[],"sequence":20584121,"timestamp":"2021-07-15T03:00:26.844Z","symbol":"XRPUSDT"}}
1626318026.963809: {"jsonrpc":"2.0","method":"updateOrderbook","params":{"ask":[{"price":"0.00000065973","size":"15231400"},{"price":"0.00000094570","size":"2769370"}],"bid":[{"price":"0.00000036496","size":"1000"}],"sequence":10532311,"timestamp":"2021-07-15T03:00:26.901Z","symbol":"SCBTC"}}
1626318026.9638221: {"jsonrpc":"2.0","method":"updateOrderbook","params":{"ask":[{"price":"0.00054547","size":"0"},{"price":"0.00054548","size":"4.33"},{"price":"0.00054571","size":"10.47"},{"price":"0.00054581","size":"0"},{"price":"0.00055325","size":"1811.87"},{"price":"0.00055404","size":"0"}],"bid":[{"price":"0.00054475","size":"18.61"},{"price":"0.00054462","size":"0"},{"price":"0.00054389","size":"353.16"},{"price":"0.00054369","size":"468.52"},{"price":"0.00054360","size":"0"},{"price":"0.00054335","size":"0"}],"sequence":19513117,"timestamp":"2021-07-15T03:00:26.919Z","symbol":"UNIBTC"}}
1626318027.051661: {"jsonrpc":"2.0","method":"updateOrderbook","params":{"ask":[],"bid":[{"price":"12.095","size":"0"}],"sequence":2190705,"timestamp":"2021-07-15T03:00:27.019Z","symbol":"SPIUSD"}}
1626318027.053746: {"jsonrpc":"2.0","method":"updateOrderbook","params":{"ask":[{"price":"0.662655","size":"399089.8"}],"bid":[{"price":"0.615696","size":"1591.6"},{"price":"0.615690","size":"4.9"}],"sequence":20584122,"timestamp":"2021-07-15T03:00:27.023Z","symbol":"XRPUSDT"}}
1626318027.072171: {"jsonrpc":"2.0","method":"updateOrderbook","params":{"ask":[{"price":"0.00000037334","size":"0"},{"price":"0.00000037368","size":"661850"},{"price":"0.00000044188","size":"0"},{"price":"0.00000044263","size":"1381850"},{"price":"0.00000065973","size":"15231420"},{"price":"0.00000089093","size":"0"},{"price":"0.00000089245","size":"2001500"},{"price":"0.00000094570","size":"2769380"}],"bid":[],"sequence":10532312,"timestamp":"2021-07-15T03:00:27.005Z","symbol":"SCBTC"}}
1626318027.072236: {"jsonrpc":"2.0","method":"updateOrderbook","params":{"ask":[{"price":"0.00054615","size":"199.63"},{"price":"0.00054621","size":"77.40"},{"price":"0.00054625","size":"296.51"},{"price":"0.00054633","size":"0"},{"price":"0.00054638","size":"0"},{"price":"0.00054661","size":"0"}],"bid":[{"price":"0.00054526","size":"5.18"},{"price":"0.00054524","size":"0"},{"price":"0.00054345","size":"1025.69"},{"price":"0.00054270","size":"929.35"},{"price":"0.00054234","size":"84.00"},{"price":"0.00054221","size":"0"}],"sequence":19513118,"timestamp":"2021-07-15T03:00:26.996Z","symbol":"UNIBTC"}}
1626318027.169033: {"jsonrpc":"2.0","method":"updateOrderbook","params":{"ask":[],"bid":[{"price":"12.097","size":"5.8767"},{"price":"12.096","size":"0"},{"price":"12.060","size":"6.5033"}],"sequence":2190706,"timestamp":"2021-07-15T03:00:27.097Z","symbol":"SPIUSD"}}
1626318027.169079: {"jsonrpc":"2.0","method":"updateOrderbook","params":{"ask":[{"price":"0.662655","size":"399090.0"}],"bid":[{"price":"0.615701","size":"1591.6"},{"price":"0.615696","size":"0"}],"sequence":20584123,"timestamp":"2021-07-15T03:00:27.099Z","symbol":"XRPUSDT"}}
1626318027.1788821: {"jsonrpc":"2.0","method":"updateOrderbook","params":{"ask":[{"price":"0.00000043091","size":"522810"},{"price":"0.00000043201","size":"0"},{"price":"0.00000054523","size":"757990"},{"price":"0.00000054581","size":"0"},{"price":"0.00000065973","size":"15231430"},{"price":"0.00000094570","size":"2769400"}],"bid":[],"sequence":10532313,"timestamp":"2021-07-15T03:00:27.112Z","symbol":"SCBTC"}}
1626318027.178945: {"jsonrpc":"2.0","method":"updateOrderbook","params":{"ask":[{"price":"0.00054548","size":"0"},{"price":"0.00054551","size":"4.33"},{"price":"0.00054621","size":"144.16"},{"price":"0.00054650","size":"0"}],"bid":[{"price":"0.00054527","size":"5.18"},{"price":"0.00054526","size":"0"},{"price":"0.00054425","size":"261.13"},{"price":"0.00054400","size":"0"},{"price":"0.00053422","size":"2974.71"},{"price":"0.00051486","size":"0"}],"sequence":19513119,"timestamp":"2021-07-15T03:00:27.112Z","symbol":"UNIBTC"}}
1626318027.247148: {"jsonrpc":"2.0","method":"updateOrderbook","params":{"ask":[],"bid":[{"price":"12.098","size":"6.5684"},{"price":"12.060","size":"0"}],"sequence":2190707,"timestamp":"2021-07-15T03:00:27.172Z","symbol":"SPIUSD"}}
1626318027.2685142: {"jsonrpc":"2.0","method":"updateOrderbook","params":{"ask":[{"price":"0.615765","size":"0"},{"price":"0.615777","size":"1331.7"},{"price":"0.615885","size":"0"},{"price":"0.662655","size":"399090.4"}],"bid":[{"price":"0.615703","size":"1591.6"},{"price":"0.615701","size":"0"}],"sequence":20584124,"timestamp":"2021-07-15T03:00:27.239Z","symbol":"XRPUSDT"}}
1626318027.2785249: {"jsonrpc":"2.0","method":"updateOrderbook","params":{"ask":[{"price":"0.00000065973","size":"15231450"},{"price":"0.00000094570","size":"2769410"}],"bid":[],"sequence":10532314,"timestamp":"2021-07-15T03:00:27.198Z","symbol":"SCBTC"}}
1626318027.2785652: {"jsonrpc":"2.0","method":"updateOrderbook","params":{"ask":[],"bid":[{"price":"0.00054527","size":"0"},{"price":"0.00054526","size":"5.18"}],"sequence":19513120,"timestamp":"2021-07-15T03:00:27.220Z","symbol":"UNIBTC"}}
1626318027.35327: {"jsonrpc":"2.0","method":"updateOrderbook","params":{"ask":[{"price":"0.615770","size":"1331.7"},{"price":"0.615777","size":"0"},{"price":"0.615885","size":"10633.1"},{"price":"0.616848","size":"0"},{"price":"0.616911","size":"5500.0"},{"price":"0.662655","size":"399090.6"}],"bid":[],"sequence":20584125,"timestamp":"2021-07-15T03:00:27.312Z","symbol":"XRPUSDT"}}
1626318027.381813: {"jsonrpc":"2.0","method":"updateOrderbook","params":{"ask":[{"price":"0.00000065973","size":"15231470"},{"price":"0.00000094570","size":"2769430"}],"bid":[],"sequence":10532315,"timestamp":"2021-07-15T03:00:27.332Z","symbol":"SCBTC"}}
1626318027.381852: {"jsonrpc":"2.0","method":"updateOrderbook","params":{"ask":[{"price":"0.00054551","size":"0"},{"price":"0.00054553","size":"4.33"},{"price":"0.00054571","size":"0"},{"price":"0.00054579","size":"10.47"},{"price":"0.00054621","size":"66.76"},{"price":"0.00054633","size":"77.40"},{"price":"0.00054662","size":"333.84"},{"price":"0.00054690","size":"0"},{"price":"0.00058871","size":"2343.84"},{"price":"0.00060290","size":"0"},{"price":"0.00078164","size":"3484.36"},{"price":"0.00078772","size":"0"}],"bid":[{"price":"0.00054530","size":"5.18"},{"price":"0.00054526","size":"0"},{"price":"0.00054467","size":"18.58"},{"price":"0.00054462","size":"69.23"},{"price":"0.00054451","size":"72.79"},{"price":"0.00054450","size":"0"},{"price":"0.00054447","size":"0"},{"price":"0.00054431","size":"0"},{"price":"0.00053050","size":"443.28"}],"sequence":19513121,"timestamp":"2021-07-15T03:00:27.332Z","symbol":"UNIBTC"}}
1626318027.453983: {"jsonrpc":"2.0","method":"updateOrderbook","params":{"ask":[{"price":"0.662655","size":"399090.8"}],"bid":[{"price":"0.615594","size":"2955.8"},{"price":"0.615561","size":"0"}],"sequence":20584126,"timestamp":"2021-07-15T03:00:27.390Z","symbol":"XRPUSDT"}}
1626318027.4653518: {"jsonrpc":"2.0","method":"updateOrderbook","params":{"ask":[{"price":"0.00000065973","size":"15231480"},{"price":"0.00000094570","size":"2769440"}],"bid":[],"sequence":10532316,"timestamp":"2021-07-15T03:00:27.438Z","symbol":"SCBTC"}}
1626318027.475969: {"jsonrpc":"2.0","method":"updateOrderbook","params":{"ask":[{"price":"0.00054553","size":"0"},{"price":"0.00054555","size":"4.33"},{"price":"0.00054593","size":"0"},{"price":"0.00054603","size":"16.70"},{"price":"0.00058871","size":"0"},{"price":"0.00059115","size":"2343.84"},{"price":"0.00078164","size":"0"},{"price":"0.00078270","size":"3484.36"}],"bid":[],"sequence":19513122,"timestamp":"2021-07-15T03:00:27.422Z","symbol":"UNIBTC"}}
1626318027.555207: {"jsonrpc":"2.0","method":"updateOrderbook","params":{"ask":[{"price":"0.662655","size":"399091.1"}],"bid":[],"sequence":20584127,"timestamp":"2021-07-15T03:00:27.492Z","symbol":"XRPUSDT"}}
1626318027.570261: {"jsonrpc":"2.0","method":"updateOrderbook","params":{"ask":[{"price":"0.00000065973","size":"15231500"},{"price":"0.00000094570","size":"2769460"}],"bid":[],"sequence":10532317,"timestamp":"2021-07-15T03:00:27.534Z","symbol":"SCBTC"}}
1626318027.5703082: {"jsonrpc":"2.0","method":"updateOrderbook","params":{"ask":[{"price":"0.00054555","size":"0"},{"price":"0.00054561","size":"4.33"},{"price":"0.00054621","size":"0"},{"price":"0.00054645","size":"66.76"},{"price":"0.00059115","size":"0"},{"price":"0.00059359","size":"2343.84"},{"price":"0.00068214","size":"1054.50"},{"price":"0.00069040","size":"0"},{"price":"0.00078270","size":"0"},{"price":"0.00078382","size":"3484.36"}],"bid":[{"price":"0.00054533","size":"5.18"},{"price":"0.00054530","size":"0"},{"price":"0.00053422","size":"0"},{"price":"0.00053290","size":"2974.71"}],"sequence":19513123,"timestamp":"2021-07-15T03:00:27.530Z","symbol":"UNIBTC"}}
1626318027.6659122: {"jsonrpc":"2.0","method":"updateOrderbook","params":{"ask":[],"bid":[{"price":"12.097","size":"0"}],"sequence":2190708,"timestamp":"2021-07-15T03:00:27.571Z","symbol":"SPIUSD"}}
1626318027.6659682: {"jsonrpc":"2.0","method":"updateOrderbook","params":{"ask":[{"price":"0.662655","size":"399091.4"}],"bid":[],"sequence":20584128,"timestamp":"2021-07-15T03:00:27.596Z","symbol":"XRPUSDT"}}
1626318027.673723: {"jsonrpc":"2.0","method":"updateOrderbook","params":{"ask":[{"price":"0.00000065973","size":"15231510"},{"price":"0.00000094570","size":"2769470"}],"bid":[],"sequence":10532318,"timestamp":"2021-07-15T03:00:27.641Z","symbol":"SCBTC"}}
1626318027.673783: {"jsonrpc":"2.0","method":"updateOrderbook","params":{"ask":[{"price":"0.00054579","size":"0"},{"price":"0.00054587","size":"10.47"},{"price":"0.00054607","size":"18.88"},{"price":"0.00054615","size":"0"},{"price":"0.00054621","size":"66.20"},{"price":"0.00054625","size":"0"},{"price":"0.00054649","size":"217.82"},{"price":"0.00054664","size":"296.51"}],"bid":[{"price":"0.00054537","size":"5.18"},{"price":"0.00054533","size":"0"},{"price":"0.00054512","size":"9.62"},{"price":"0.00054500","size":"0"}],"sequence":19513124,"timestamp":"2021-07-15T03:00:27.606Z","symbol":"UNIBTC"}}
1626318027.749162: {"jsonrpc":"2.0","method":"updateOrderbook","params":{"ask":[],"bid":[{"price":"12.099","size":"5.8757"},{"price":"12.098","size":"0"},{"price":"12.060","size":"6.6335"}],"sequence":2190709,"timestamp":"2021-07-15T03:00:27.668Z","symbol":"SPIUSD"}}
1626318027.754142: {"jsonrpc":"2.0","method":"updateOrderbook","params":{"ask":[{"price":"0.643665","size":"0"},{"price":"0.645373","size":"347706.3"},{"price":"0.662655","size":"399091.8"}],"bid":[],"sequence":20584129,"timestamp":"2021-07-15T03:00:27.719Z","symbol":"XRPUSDT"}}
1626318027.8473861: {"jsonrpc":"2.0","method":"updateOrderbook","params":{"ask":[],"bid":[{"price":"12.100","size":"6.6986"},{"price":"12.060","size":"0"}],"sequence":2190710,"timestamp":"2021-07-15T03:00:27.769Z","symbol":"SPIUSD"}}
1626318027.864373: {"jsonrpc":"2.0","method":"updateOrderbook","params":{"ask":[{"price":"0.662655","size":"399092.1"}],"bid":[{"price":"0.615703","size":"0"},{"price":"0.615693","size":"1591.6"}],"sequence":20584130,"timestamp":"2021-07-15T03:00:27.832Z","symbol":"XRPUSDT"}}
1626318027.8706088: {"jsonrpc":"2.0","method":"updateOrderbook","params":{"ask":[{"price":"0.00000065973","size":"15231530"},{"price":"0.00000094570","size":"2769490"}],"bid":[],"sequence":10532319,"timestamp":"2021-07-15T03:00:27.747Z","symbol":"SCBTC"}}
1626318027.870667: {"jsonrpc":"2.0","method":"updateOrderbook","params":{"ask":[{"price":"0.00054592","size":"16.70"},{"price":"0.00054603","size":"0"},{"price":"0.00054712","size":"250.69"},{"price":"0.00054745","size":"528.37"},{"price":"0.00054747","size":"0"},{"price":"0.00054779","size":"0"},{"price":"0.00054794","size":"0"},{"price":"0.00054825","size":"170.00"},{"price":"0.00055013","size":"3677.57"},{"price":"0.00055086","size":"0"}],"bid":[],"sequence":19513125,"timestamp":"2021-07-15T03:00:27.834Z","symbol":"UNIBTC"}}
1626318027.959111: {"jsonrpc":"2.0","method":"updateOrderbook","params":{"ask":[{"price":"0.662655","size":"399092.4"}],"bid":[],"sequence":20584131,"timestamp":"2021-07-15T03:00:27.930Z","symbol":"XRPUSDT"}}
1626318027.9665642: {"jsonrpc":"2.0","method":"updateOrderbook","params":{"ask":[{"price":"0.00000065973","size":"15231550"},{"price":"0.00000094570","size":"2769500"}],"bid":[],"sequence":10532320,"timestamp":"2021-07-15T03:00:27.851Z","symbol":"SCBTC"}}
1626318027.9666219: {"jsonrpc":"2.0","method":"updateOrderbook","params":{"ask":[],"bid":[{"price":"0.00054413","size":"1.17"},{"price":"0.00054401","size":"0"},{"price":"0.00053377","size":"2974.71"},{"price":"0.00053290","size":"0"}],"sequence":19513126,"timestamp":"2021-07-15T03:00:27.887Z","symbol":"UNIBTC"}}
1626318028.05425: {"jsonrpc":"2.0","method":"updateOrderbook","params":{"ask":[{"price":"0.662655","size":"399092.6"}],"bid":[],"sequence":20584132,"timestamp":"2021-07-15T03:00:28.011Z","symbol":"XRPUSDT"}}
1626318028.076106: {"jsonrpc":"2.0","method":"updateOrderbook","params":{"ask":[{"price":"0.00000065973","size":"15231560"},{"price":"0.00000094570","size":"2769520"}],"bid":[],"sequence":10532321,"timestamp":"2021-07-15T03:00:27.956Z","symbol":"SCBTC"}}
1626318028.076163: {"jsonrpc":"2.0","method":"updateOrderbook","params":{"ask":[{"price":"0.00054862","size":"658.12"},{"price":"0.00055061","size":"0"}],"bid":[{"price":"0.00054345","size":"1356.90"},{"price":"0.00054279","size":"0"},{"price":"0.00053377","size":"0"},{"price":"0.00053298","size":"2974.71"}],"sequence":19513127,"timestamp":"2021-07-15T03:00:28.036Z","symbol":"UNIBTC"}}
1626318028.154424: {"jsonrpc":"2.0","method":"updateOrderbook","params":{"ask":[{"price":"0.662655","size":"399092.9"}],"bid":[],"sequence":20584133,"timestamp":"2021-07-15T03:00:28.110Z","symbol":"XRPUSDT"}}
1626318028.172729: {"jsonrpc":"2.0","method":"updateOrderbook","params":{"ask":[{"price":"0.00000065973","size":"15231580"},{"price":"0.00000094570","size":"2769530"}],"bid":[],"sequence":10532322,"timestamp":"2021-07-15T03:00:28.060Z","symbol":"SCBTC"}}
1626318028.172789: {"jsonrpc":"2.0","method":"updateOrderbook","params":{"ask":[],"bid":[{"price":"0.00054487","size":"18.61"},{"price":"0.00054475","size":"0"},{"price":"0.00054312","size":"634.39"},{"price":"0.00054229","size":"0"}],"sequence":19513128,"timestamp":"2021-07-15T03:00:28.141Z","symbol":"UNIBTC"}}
1626318028.2474592: {"jsonrpc":"2.0","method":"updateOrderbook","params":{"ask":[],"bid":[{"price":"12.099","size":"0"}],"sequence":2190711,"timestamp":"2021-07-15T03:00:28.234Z","symbol":"SPIUSD"}}
1626318028.2737129: {"jsonrpc":"2.0","method":"updateOrderbook","params":{"ask":[{"price":"0.662655","size":"399093.1"}],"bid":[{"price":"0.615698","size":"1591.6"},{"price":"0.615693","size":"0"}],"sequence":20584134,"timestamp":"2021-07-15T03:00:28.170Z","symbol":"XRPUSDT"}}
1626318028.273771: {"jsonrpc":"2.0","method":"updateOrderbook","params":{"ask":[{"price":"0.00000065973","size":"15231590"},{"price":"0.00000094570","size":"2769550"}],"bid":[],"sequence":10532323,"timestamp":"2021-07-15T03:00:28.165Z","symbol":"SCBTC"}}
1626318028.2737951: {"jsonrpc":"2.0","method":"updateOrderbook","params":{"ask":[{"price":"0.00054624","size":"66.76"},{"price":"0.00054645","size":"0"}],"bid":[{"price":"0.00054537","size":"0"},{"price":"0.00054535","size":"5.18"}],"sequence":19513129,"timestamp":"2021-07-15T03:00:28.224Z","symbol":"UNIBTC"}}
1626318028.37119: {"jsonrpc":"2.0","method":"updateOrderbook","params":{"ask":[],"bid":[{"price":"12.101","size":"5.8747"},{"price":"12.100","size":"0"},{"price":"12.060","size":"6.7637"}],"sequence":2190712,"timestamp":"2021-07-15T03:00:28.310Z","symbol":"SPIUSD"}}
1626318028.3713138: {"jsonrpc":"2.0","method":"updateOrderbook","params":{"ask":[{"price":"0.616419","size":"0"},{"price":"0.616530","size":"508.2"},{"price":"0.662655","size":"399093.4"}],"bid":[],"sequence":20584135,"timestamp":"2021-07-15T03:00:28.278Z","symbol":"XRPUSDT"}}
1626318028.3825998: {"jsonrpc":"2.0","method":"updateOrderbook","params":{"ask":[{"price":"0.00000065973","size":"15231610"},{"price":"0.00000094570","size":"2769560"}],"bid":[],"sequence":10532324,"timestamp":"2021-07-15T03:00:28.277Z","symbol":"SCBTC"}}
1626318028.382659: {"jsonrpc":"2.0","method":"updateOrderbook","params":{"ask":[{"price":"0.00054624","size":"0"},{"price":"0.00054646","size":"66.76"},{"price":"0.00054755","size":"331.40"},{"price":"0.00054992","size":"433.80"},{"price":"0.00055028","size":"0"},{"price":"0.00055263","size":"0"}],"bid":[{"price":"0.00054535","size":"0"},{"price":"0.00054531","size":"5.18"}],"sequence":19513130,"timestamp":"2021-07-15T03:00:28.320Z","symbol":"UNIBTC"}}
1626318028.45155: {"jsonrpc":"2.0","method":"updateOrderbook","params":{"ask":[],"bid":[{"price":"12.102","size":"6.8288"},{"price":"12.060","size":"0"}],"sequence":2190713,"timestamp":"2021-07-15T03:00:28.374Z","symbol":"SPIUSD"}}
1626318028.463657: {"jsonrpc":"2.0","method":"updateOrderbook","params":{"ask":[{"price":"0.662655","size":"399093.7"}],"bid":[],"sequence":20584136,"timestamp":"2021-07-15T03:00:28.387Z","symbol":"XRPUSDT"}}
1626318028.4824488: {"jsonrpc":"2.0","method":"updateOrderbook","params":{"ask":[{"price":"0.00000065973","size":"15231630"},{"price":"0.00000094570","size":"2769580"}],"bid":[],"sequence":10532325,"timestamp":"2021-07-15T03:00:28.382Z","symbol":"SCBTC"}}
1626318028.482506: {"jsonrpc":"2.0","method":"updateOrderbook","params":{"ask":[{"price":"0.00054556","size":"4.33"},{"price":"0.00054561","size":"0"}],"bid":[],"sequence":19513131,"timestamp":"2021-07-15T03:00:28.391Z","symbol":"UNIBTC"}}
1626318028.552223: {"jsonrpc":"2.0","method":"updateOrderbook","params":{"ask":[{"price":"0.615770","size":"0"},{"price":"0.615772","size":"1331.7"},{"price":"0.662655","size":"399094.1"}],"bid":[{"price":"0.615704","size":"1591.6"},{"price":"0.615698","size":"0"}],"sequence":20584137,"timestamp":"2021-07-15T03:00:28.524Z","symbol":"XRPUSDT"}}
1626318028.5807161: {"jsonrpc":"2.0","method":"updateOrderbook","params":{"ask":[{"price":"0.00000036716","size":"25530"},{"price":"0.00000036726","size":"0"},{"price":"0.00000065973","size":"15231650"},{"price":"0.00000094570","size":"2769600"}],"bid":[],"sequence":10532326,"timestamp":"2021-07-15T03:00:28.526Z","symbol":"SCBTC"}}
1626318028.580801: {"jsonrpc":"2.0","method":"updateOrderbook","params":{"ask":[{"price":"0.00056035","size":"2539.46"},{"price":"0.00057461","size":"0"}],"bid":[{"price":"0.00054512","size":"0"},{"price":"0.00054505","size":"9.62"}],"sequence":19513132,"timestamp":"2021-07-15T03:00:28.541Z","symbol":"UNIBTC"}}
1626318028.683191: {"jsonrpc":"2.0","method":"updateOrderbook","params":{"ask":[{"price":"0.615772","size":"0"},{"price":"0.615778","size":"1331.7"},{"price":"0.615885","size":"0"},{"price":"0.616137","size":"10633.0"},{"price":"0.662655","size":"399094.4"}],"bid":[{"price":"0.615704","size":"0"},{"price":"0.615686","size":"1591.6"}],"sequence":20584138,"timestamp":"2021-07-15T03:00:28.630Z","symbol":"XRPUSDT"}}
1626318028.683321: {"jsonrpc":"2.0","method":"updateOrderbook","params":{"ask":[{"price":"0.00000036716","size":"0"},{"price":"0.00000036726","size":"25530"},{"price":"0.00000065973","size":"15231660"},{"price":"0.00000089245","size":"0"},{"price":"0.00000089324","size":"2001500"},{"price":"0.00000094570","size":"2769610"}],"bid":[],"sequence":10532327,"timestamp":"2021-07-15T03:00:28.625Z","symbol":"SCBTC"}}
1626318028.683386: {"jsonrpc":"2.0","method":"updateOrderbook","params":{"ask":[{"price":"0.00054556","size":"0"},{"price":"0.00054559","size":"4.33"},{"price":"0.00054607","size":"85.08"},{"price":"0.00054620","size":"66.76"},{"price":"0.00054621","size":"0"},{"price":"0.00054646","size":"0"},{"price":"0.00054777","size":"86.00"},{"price":"0.00054825","size":"84.00"}],"bid":[],"sequence":19513133,"timestamp":"2021-07-15T03:00:28.641Z","symbol":"UNIBTC"}}
1626318028.763904: {"jsonrpc":"2.0","method":"updateOrderbook","params":{"ask":[{"price":"0.616137","size":"10633.1"},{"price":"0.662655","size":"399094.7"}],"bid":[],"sequence":20584139,"timestamp":"2021-07-15T03:00:28.732Z","symbol":"XRPUSDT"}}
1626318028.7911701: {"jsonrpc":"2.0","method":"updateOrderbook","params":{"ask":[{"price":"0.00000065973","size":"15231680"},{"price":"0.00000094570","size":"2769630"},{"price":"0.00000161010","size":"0"},{"price":"0.00000161321","size":"4634410"},{"price":"0.00000416349","size":"0"},{"price":"0.00000419436","size":"7466230"}],"bid":[],"sequence":10532328,"timestamp":"2021-07-15T03:00:28.732Z","symbol":"SCBTC"}}
1626318028.7911942: {"jsonrpc":"2.0","method":"updateOrderbook","params":{"ask":[{"price":"0.00054559","size":"0"},{"price":"0.00054561","size":"4.33"},{"price":"0.00054607","size":"18.88"},{"price":"0.00054620","size":"66.20"},{"price":"0.00054662","size":"400.60"},{"price":"0.00054777","size":"0"},{"price":"0.00054825","size":"170.00"},{"price":"0.00059359","size":"0"},{"price":"0.00059528","size":"2343.84"}],"bid":[{"price":"0.00054533","size":"5.18"},{"price":"0.00054531","size":"0"}],"sequence":19513134,"timestamp":"2021-07-15T03:00:28.705Z","symbol":"UNIBTC"}}
1626318028.874516: {"jsonrpc":"2.0","method":"updateOrderbook","params":{"ask":[{"price":"0.615885","size":"10633.3"},{"price":"0.616137","size":"0"},{"price":"0.662655","size":"399095.0"}],"bid":[],"sequence":20584140,"timestamp":"2021-07-15T03:00:28.832Z","symbol":"XRPUSDT"}}
1626318028.874578: {"jsonrpc":"2.0","method":"updateOrderbook","params":{"ask":[{"price":"0.00000065973","size":"15231690"},{"price":"0.00000094570","size":"2769640"}],"bid":[],"sequence":10532329,"timestamp":"2021-07-15T03:00:28.837Z","symbol":"SCBTC"}}
1626318028.874601: {"jsonrpc":"2.0","method":"updateOrderbook","params":{"ask":[],"bid":[{"price":"0.00054535","size":"5.18"},{"price":"0.00054533","size":"0"}],"sequence":19513135,"timestamp":"2021-07-15T03:00:28.774Z","symbol":"UNIBTC"}}
1626318028.9585621: {"jsonrpc":"2.0","method":"updateOrderbook","params":{"ask":[{"price":"0.615774","size":"1331.7"},{"price":"0.615778","size":"0"},{"price":"0.643805","size":"347706.3"},{"price":"0.645373","size":"0"},{"price":"0.662655","size":"399095.3"}],"bid":[{"price":"0.615081","size":"6397.5"}],"sequence":20584141,"timestamp":"2021-07-15T03:00:28.937Z","symbol":"XRPUSDT"}}
1626318028.958692: {"jsonrpc":"2.0","method":"updateOrderbook","params":{"ask":[{"price":"0.00000065973","size":"15231710"},{"price":"0.00000094570","size":"2769660"}],"bid":[],"sequence":10532330,"timestamp":"2021-07-15T03:00:28.942Z","symbol":"SCBTC"}}
1626318028.971647: {"jsonrpc":"2.0","method":"updateOrderbook","params":{"ask":[{"price":"0.00054559","size":"4.33"},{"price":"0.00054561","size":"0"},{"price":"0.00054622","size":"77.40"},{"price":"0.00054633","size":"0"},{"price":"0.00055615","size":"881.76"},{"price":"0.00060692","size":"0"}],"bid":[{"price":"0.00054535","size":"0"},{"price":"0.00054533","size":"5.18"},{"price":"0.00054413","size":"0"},{"price":"0.00054410","size":"1.17"}],"sequence":19513136,"timestamp":"2021-07-15T03:00:28.913Z","symbol":"UNIBTC"}}
1626318029.048136: {"jsonrpc":"2.0","method":"updateOrderbook","params":{"ask":[],"bid":[{"price":"12.101","size":"0"}],"sequence":2190714,"timestamp":"2021-07-15T03:00:28.987Z","symbol":"SPIUSD"}}
1626318029.0568771: {"jsonrpc":"2.0","method":"updateOrderbook","params":{"ask":[{"price":"0.662655","size":"399095.4"}],"bid":[{"price":"0.615691","size":"1591.6"},{"price":"0.615686","size":"0"}],"sequence":20584142,"timestamp":"2021-07-15T03:00:28.998Z","symbol":"XRPUSDT"}}
1626318029.080744: {"jsonrpc":"2.0","method":"updateOrderbook","params":{"ask":[{"price":"0.00054607","size":"0"},{"price":"0.00054620","size":"85.08"},{"price":"0.00054622","size":"0"},{"price":"0.00054638","size":"77.40"}],"bid":[{"price":"0.00054487","size":"0"},{"price":"0.00054476","size":"36.95"},{"price":"0.00054462","size":"0"},{"price":"0.00054451","size":"142.02"}],"sequence":19513137,"timestamp":"2021-07-15T03:00:29.033Z","symbol":"UNIBTC"}}
1626318029.152579: {"jsonrpc":"2.0","method":"updateOrderbook","params":{"ask":[],"bid":[{"price":"12.103","size":"12.8327"},{"price":"12.102","size":"0"}],"sequence":2190715,"timestamp":"2021-07-15T03:00:29.102Z","symbol":"SPIUSD"}}
1626318029.1603122: {"jsonrpc":"2.0","method":"updateOrderbook","params":{"ask":[{"price":"0.662655","size":"399095.7"}],"bid":[],"sequence":20584143,"timestamp":"2021-07-15T03:00:29.085Z","symbol":"XRPUSDT"}}
1626318029.188948: {"jsonrpc":"2.0","method":"updateOrderbook","params":{"ask":[{"price":"0.00000065973","size":"15231730"},{"price":"0.00000094570","size":"2769670"}],"bid":[],"sequence":10532331,"timestamp":"2021-07-15T03:00:29.047Z","symbol":"SCBTC"}}
1626318029.1890078: {"jsonrpc":"2.0","method":"updateOrderbook","params":{"ask":[{"price":"0.00054777","size":"86.00"},{"price":"0.00054825","size":"84.00"}],"bid":[],"sequence":19513138,"timestamp":"2021-07-15T03:00:29.095Z","symbol":"UNIBTC"}}
1626318029.277013: {"jsonrpc":"2.0","method":"updateOrderbook","params":{"ask":[{"price":"0.615885","size":"10633.2"},{"price":"0.629354","size":"129038.8"},{"price":"0.632729","size":"0"},{"price":"0.653889","size":"181214.3"},{"price":"0.656715","size":"0"},{"price":"0.662655","size":"399096.0"}],"bid":[],"sequence":20584144,"timestamp":"2021-07-15T03:00:29.206Z","symbol":"XRPUSDT"}}
1626318029.277075: {"jsonrpc":"2.0","method":"updateOrderbook","params":{"ask":[{"price":"0.00000065973","size":"15231740"},{"price":"0.00000094570","size":"2769690"}],"bid":[],"sequence":10532332,"timestamp":"2021-07-15T03:00:29.157Z","symbol":"SCBTC"}}
1626318029.2771: {"jsonrpc":"2.0","method":"updateOrderbook","params":{"ask":[{"price":"0.00054625","size":"66.76"},{"price":"0.00054662","size":"333.84"},{"price":"0.00055054","size":"662.81"},{"price":"0.00055449","size":"0"}],"bid":[],"sequence":19513139,"timestamp":"2021-07-15T03:00:29.200Z","symbol":"UNIBTC"}}
1626318029.367527: {"jsonrpc":"2.0","method":"updateOrderbook","params":{"ask":[{"price":"0.662655","size":"399096.3"}],"bid":[{"price":"0.615696","size":"1591.6"},{"price":"0.615691","size":"0"}],"sequence":20584145,"timestamp":"2021-07-15T03:00:29.315Z","symbol":"XRPUSDT"}}
1626318029.376417: {"jsonrpc":"2.0","method":"updateOrderbook","params":{"ask":[{"price":"0.00000065973","size":"15231760"},{"price":"0.00000094570","size":"2769700"}],"bid":[],"sequence":10532333,"timestamp":"2021-07-15T03:00:29.267Z","symbol":"SCBTC"}}
1626318029.3836339: {"jsonrpc":"2.0","method":"updateOrderbook","params":{"ask":[{"price":"0.00054555","size":"4.33"},{"price":"0.00054559","size":"0"},{"price":"0.00067877","size":"1125.76"},{"price":"0.00079071","size":"0"}],"bid":[{"price":"0.00054533","size":"0"},{"price":"0.00054531","size":"5.18"},{"price":"0.00054476","size":"18.34"},{"price":"0.00054464","size":"18.61"}],"sequence":19513140,"timestamp":"2021-07-15T03:00:29.341Z","symbol":"UNIBTC"}}
1626318029.383678: {"jsonrpc":"2.0","method":"updateOrderbook","params":{"ask":[{"price":"0.0004397","size":"47.197"},{"price":"0.0004398","size":"0"}],"bid":[],"sequence":2198427,"timestamp":"2021-07-15T03:00:29.340Z","symbol":"NUTBTC"}}
1626318029.477153: {"jsonrpc":"2.0","method":"updateOrderbook","params":{"ask":[{"price":"0.662655","size":"399096.6"}],"bid":[],"sequence":20584146,"timestamp":"2021-07-15T03:00:29.418Z","symbol":"XRPUSDT"}}
1626318029.477209: {"jsonrpc":"2.0","method":"updateOrderbook","params":{"ask":[{"price":"0.00000065973","size":"15231780"},{"price":"0.00000094570","size":"2769740"}],"bid":[],"sequence":10532334,"timestamp":"2021-07-15T03:00:29.441Z","symbol":"SCBTC"}}
1626318029.477233: {"jsonrpc":"2.0","method":"updateOrderbook","params":{"ask":[{"price":"0.00054555","size":"0"},{"price":"0.00054558","size":"4.33"}],"bid":[],"sequence":19513141,"timestamp":"2021-07-15T03:00:29.430Z","symbol":"UNIBTC"}}
1626318029.5607748: {"jsonrpc":"2.0","method":"updateOrderbook","params":{"ask":[{"price":"0.662655","size":"399096.9"}],"bid":[],"sequence":20584147,"timestamp":"2021-07-15T03:00:29.520Z","symbol":"XRPUSDT"}}
1626318029.565005: {"jsonrpc":"2.0","method":"updateOrderbook","params":{"ask":[{"price":"0.00000065973","size":"15231800"},{"price":"0.00000094570","size":"2769750"}],"bid":[],"sequence":10532335,"timestamp":"2021-07-15T03:00:29.527Z","symbol":"SCBTC"}}
1626318029.565046: {"jsonrpc":"2.0","method":"updateOrderbook","params":{"ask":[{"price":"0.00054556","size":"4.33"},{"price":"0.00054558","size":"0"},{"price":"0.00054610","size":"18.88"},{"price":"0.00054620","size":"143.60"},{"price":"0.00054638","size":"0"},{"price":"0.00054819","size":"658.12"},{"price":"0.00054862","size":"0"},{"price":"0.00055066","size":"843.90"},{"price":"0.00055112","size":"0"}],"bid":[{"price":"0.00054489","size":"0"},{"price":"0.00054471","size":"18.03"}],"sequence":19513142,"timestamp":"2021-07-15T03:00:29.533Z","symbol":"UNIBTC"}}
1626318029.649494: {"jsonrpc":"2.0","method":"updateOrderbook","params":{"ask":[{"price":"0.615881","size":"3215.6"},{"price":"0.615886","size":"0"},{"price":"0.616151","size":"5554.2"},{"price":"0.616183","size":"0"},{"price":"0.616283","size":"6528.7"},{"price":"0.616298","size":"0"},{"price":"0.662655","size":"399097.2"}],"bid":[{"price":"0.615696","size":"1591.5"},{"price":"0.615594","size":"0"},{"price":"0.615587","size":"2955.7"},{"price":"0.615317","size":"5489.3"},{"price":"0.615254","size":"0"},{"price":"0.615253","size":"0"},{"price":"0.615195","size":"1337.0"},{"price":"0.615181","size":"6463.7"},{"price":"0.614984","size":"0"}],"sequence":20584148,"timestamp":"2021-07-15T03:00:29.621Z","symbol":"XRPUSDT"}}
1626318029.685314: {"jsonrpc":"2.0","method":"updateOrderbook","params":{"ask":[{"price":"0.00000065973","size":"15231810"},{"price":"0.00000094570","size":"2769770"}],"bid":[],"sequence":10532336,"timestamp":"2021-07-15T03:00:29.636Z","symbol":"SCBTC"}}
1626318029.7765021: {"jsonrpc":"2.0","method":"updateOrderbook","params":{"ask":[{"price":"0.616839","size":"5500.0"},{"price":"0.616911","size":"0"},{"price":"0.629354","size":"0"},{"price":"0.632203","size":"129038.8"},{"price":"0.653889","size":"0"},{"price":"0.656260","size":"181214.3"},{"price":"0.662655","size":"399097.5"}],"bid":[],"sequence":20584149,"timestamp":"2021-07-15T03:00:29.730Z","symbol":"XRPUSDT"}}
1626318029.77657: {"jsonrpc":"2.0","method":"updateOrderbook","params":{"ask":[{"price":"0.00000065973","size":"15231830"}],"bid":[],"sequence":10532337,"timestamp":"2021-07-15T03:00:29.740Z","symbol":"SCBTC"}}
1626318029.776593: {"jsonrpc":"2.0","method":"updateOrderbook","params":{"ask":[{"price":"0.00083080","size":"1585.64"},{"price":"0.00083984","size":"0"}],"bid":[],"sequence":19513143,"timestamp":"2021-07-15T03:00:29.721Z","symbol":"UNIBTC"}}
1626318029.8735518: {"jsonrpc":"2.0","method":"updateOrderbook","params":{"ask":[{"price":"0.662655","size":"399097.8"}],"bid":[],"sequence":20584150,"timestamp":"2021-07-15T03:00:29.834Z","symbol":"XRPUSDT"}}
1626318029.8736079: {"jsonrpc":"2.0","method":"updateOrderbook","params":{"ask":[{"price":"0.00000094570","size":"2769790"}],"bid":[],"sequence":10532338,"timestamp":"2021-07-15T03:00:29.749Z","symbol":"SCBTC"}}
1626318029.873632: {"jsonrpc":"2.0","method":"updateOrderbook","params":{"ask":[],"bid":[{"price":"0.00054531","size":"0"},{"price":"0.00054530","size":"5.18"},{"price":"0.00054477","size":"18.61"},{"price":"0.00054464","size":"0"}],"sequence":19513144,"timestamp":"2021-07-15T03:00:29.789Z","symbol":"UNIBTC"}}
1626318029.8737159: {"jsonrpc":"2.0","method":"updateOrderbook","params":{"ask":[{"price":"0.0004397","size":"0"},{"price":"0.0004398","size":"47.197"}],"bid":[],"sequence":2198428,"timestamp":"2021-07-15T03:00:29.837Z","symbol":"NUTBTC"}}
1626318030.005263: {"jsonrpc":"2.0","method":"updateOrderbook","params":{"ask":[{"price":"0.615885","size":"0"},{"price":"0.616383","size":"160.9"},{"price":"0.616410","size":"0"},{"price":"0.662655","size":"399098.1"}],"bid":[{"price":"0.615707","size":"0"},{"price":"0.615703","size":"11000.0"},{"price":"0.615696","size":"0"},{"price":"0.615694","size":"1591.5"}],"sequence":20584151,"timestamp":"2021-07-15T03:00:29.938Z","symbol":"XRPUSDT"}}
1626318030.005311: {"jsonrpc":"2.0","method":"updateOrderbook","params":{"ask":[{"price":"0.00000037368","size":"0"},{"price":"0.00000037408","size":"661850"},{"price":"0.00000044263","size":"0"},{"price":"0.00000044325","size":"1381850"},{"price":"0.00000065973","size":"15231860"},{"price":"0.00000089324","size":"0"},{"price":"0.00000089465","size":"2001500"},{"price":"0.00000094570","size":"2769820"},{"price":"0.00000124621","size":"0"},{"price":"0.00000124701","size":"2705250"}],"bid":[],"sequence":10532339,"timestamp":"2021-07-15T03:00:29.910Z","symbol":"SCBTC"}}
1626318030.005352: {"jsonrpc":"2.0","method":"updateOrderbook","params":{"ask":[],"bid":[{"price":"0.00054531","size":"5.18"},{"price":"0.00054530","size":"0"},{"price":"0.00054481","size":"18.03"},{"price":"0.00054471","size":"0"},{"price":"0.00054466","size":"69.23"},{"price":"0.00054451","size":"72.79"}],"sequence":19513145,"timestamp":"2021-07-15T03:00:29.923Z","symbol":"UNIBTC"}}
1626318030.072584: {"jsonrpc":"2.0","method":"updateOrderbook","params":{"ask":[{"price":"0.616137","size":"10632.8"},{"price":"0.662655","size":"399098.4"}],"bid":[{"price":"0.615196","size":"1337.0"},{"price":"0.615195","size":"0"}],"sequence":20584152,"timestamp":"2021-07-15T03:00:30.041Z","symbol":"XRPUSDT"}}
1626318030.0726469: {"jsonrpc":"2.0","method":"updateOrderbook","params":{"ask":[{"price":"0.00000065973","size":"15231870"},{"price":"0.00000094570","size":"2769840"}],"bid":[],"sequence":10532340,"timestamp":"2021-07-15T03:00:30.015Z","symbol":"SCBTC"}}
1626318030.171618: {"jsonrpc":"2.0","method":"updateOrderbook","params":{"ask":[{"price":"0.615880","size":"10632.7"},{"price":"0.616137","size":"0"},{"price":"0.662655","size":"399098.7"}],"bid":[{"price":"0.615318","size":"1337.0"},{"price":"0.615196","size":"0"}],"sequence":20584153,"timestamp":"2021-07-15T03:00:30.138Z","symbol":"XRPUSDT"}}
1626318030.171679: {"jsonrpc":"2.0","method":"updateOrderbook","params":{"ask":[{"price":"0.00000065973","size":"15231890"},{"price":"0.00000094570","size":"2769860"}],"bid":[],"sequence":10532341,"timestamp":"2021-07-15T03:00:30.123Z","symbol":"SCBTC"}}
1626318030.171704: {"jsonrpc":"2.0","method":"updateOrderbook","params":{"ask":[{"price":"0.00054556","size":"0"},{"price":"0.00054559","size":"4.33"}],"bid":[{"price":"0.00054531","size":"0"},{"price":"0.00054526","size":"5.18"}],"sequence":19513146,"timestamp":"2021-07-15T03:00:30.123Z","symbol":"UNIBTC"}}
1626318030.295435: {"jsonrpc":"2.0","method":"updateOrderbook","params":{"ask":[{"price":"0.615880","size":"0"},{"price":"0.616137","size":"10632.2"}],"bid":[{"price":"0.615318","size":"0"},{"price":"0.615196","size":"1337.0"}],"sequence":20584154,"timestamp":"2021-07-15T03:00:30.156Z","symbol":"XRPUSDT"}}
1626318030.2955022: {"jsonrpc":"2.0","method":"updateOrderbook","params":{"ask":[{"price":"0.00000065973","size":"15231900"},{"price":"0.00000094570","size":"2769880"}],"bid":[{"price":"0.00000036495","size":"0"},{"price":"0.00000036482","size":"110390"},{"price":"0.00000032529","size":"0"},{"price":"0.00000032212","size":"1993120"},{"price":"0.00000004684","size":"0"},{"price":"0.00000004424","size":"2752080"}],"sequence":10532342,"timestamp":"2021-07-15T03:00:30.238Z","symbol":"SCBTC"}}
1626318030.295537: {"jsonrpc":"2.0","method":"updateOrderbook","params":{"ask":[{"price":"0.00054551","size":"4.33"},{"price":"0.00054559","size":"0"}],"bid":[],"sequence":19513147,"timestamp":"2021-07-15T03:00:30.226Z","symbol":"UNIBTC"}}
1626318030.352164: {"jsonrpc":"2.0","method":"updateOrderbook","params":{"ask":[{"price":"0.662655","size":"399099.1"}],"bid":[],"sequence":20584155,"timestamp":"2021-07-15T03:00:30.277Z","symbol":"XRPUSDT"}}
1626318030.374918: {"jsonrpc":"2.0","method":"updateOrderbook","params":{"ask":[{"price":"0.00000037357","size":"661850"},{"price":"0.00000037408","size":"0"},{"price":"0.00000065973","size":"15231920"},{"price":"0.00000094570","size":"2769900"},{"price":"0.00000124640","size":"2705250"},{"price":"0.00000124701","size":"0"}],"bid":[{"price":"0.00000036496","size":"0"},{"price":"0.00000036483","size":"1000"}],"sequence":10532343,"timestamp":"2021-07-15T03:00:30.333Z","symbol":"SCBTC"}}
1626318030.374951: {"jsonrpc":"2.0","method":"updateOrderbook","params":{"ask":[{"price":"0.00054575","size":"10.47"},{"price":"0.00054587","size":"0"}],"bid":[],"sequence":19513148,"timestamp":"2021-07-15T03:00:30.302Z","symbol":"UNIBTC"}}
1626318030.471354: {"jsonrpc":"2.0","method":"updateOrderbook","params":{"ask":[{"price":"0.615880","size":"10632.6"},{"price":"0.616137","size":"0"},{"price":"0.662655","size":"399099.5"}],"bid":[{"price":"0.615196","size":"0"},{"price":"0.615195","size":"1337.0"},{"price":"0.610018","size":"0"},{"price":"0.609918","size":"491.8"}],"sequence":20584156,"timestamp":"2021-07-15T03:00:30.414Z","symbol":"XRPUSDT"}}
1626318030.4714172: {"jsonrpc":"2.0","method":"updateOrderbook","params":{"ask":[{"price":"0.00000065973","size":"15231930"},{"price":"0.00000094570","size":"2769920"}],"bid":[],"sequence":10532344,"timestamp":"2021-07-15T03:00:30.441Z","symbol":"SCBTC"}}
1626318030.471444: {"jsonrpc":"2.0","method":"updateOrderbook","params":{"ask":[{"price":"0.00055615","size":"0"},{"price":"0.00056925","size":"881.76"},{"price":"0.00067877","size":"0"},{"price":"0.00073715","size":"1125.76"},{"price":"0.00083080","size":"0"},{"price":"0.00083870","size":"1585.64"}],"bid":[],"sequence":19513149,"timestamp":"2021-07-15T03:00:30.400Z","symbol":"UNIBTC"}}
1626318030.560895: {"jsonrpc":"2.0","method":"updateOrderbook","params":{"ask":[{"price":"0.616382","size":"160.9"},{"price":"0.616383","size":"0"},{"price":"0.662655","size":"399099.8"},{"price":"0.701792","size":"228479.7"}],"bid":[{"price":"0.615703","size":"0"},{"price":"0.615698","size":"11000.0"},{"price":"0.615694","size":"0"},{"price":"0.615646","size":"1591.5"},{"price":"0.615587","size":"0"},{"price":"0.615541","size":"2955.7"}],"sequence":20584157,"timestamp":"2021-07-15T03:00:30.529Z","symbol":"XRPUSDT"}}
1626318030.578123: {"jsonrpc":"2.0","method":"updateOrderbook","params":{"ask":[{"price":"0.00000065973","size":"15231950"},{"price":"0.00000094570","size":"2769930"}],"bid":[],"sequence":10532345,"timestamp":"2021-07-15T03:00:30.526Z","symbol":"SCBTC"}}
1626318030.653663: {"jsonrpc":"2.0","method":"updateOrderbook","params":{"ask":[{"price":"0.616722","size":"9601.1"},{"price":"0.617137","size":"0"},{"price":"0.662655","size":"399100.1"}],"bid":[{"price":"0.615646","size":"0"},{"price":"0.615619","size":"1591.5"}],"sequence":20584158,"timestamp":"2021-07-15T03:00:30.615Z","symbol":"XRPUSDT"}}
1626318030.67238: {"jsonrpc":"2.0","method":"updateOrderbook","params":{"ask":[{"price":"0.00000065973","size":"15231960"},{"price":"0.00000094570","size":"2769950"}],"bid":[],"sequence":10532346,"timestamp":"2021-07-15T03:00:30.631Z","symbol":"SCBTC"}}
1626318030.673996: {"jsonrpc":"2.0","method":"updateOrderbook","params":{"ask":[{"price":"0.00054549","size":"4.33"},{"price":"0.00054551","size":"0"},{"price":"0.00054580","size":"16.70"},{"price":"0.00054592","size":"0"},{"price":"0.00054594","size":"66.20"},{"price":"0.00054620","size":"77.40"},{"price":"0.00055054","size":"0"},{"price":"0.00055196","size":"662.81"},{"price":"0.00058544","size":"2343.84"},{"price":"0.00059528","size":"0"},{"price":"0.00078017","size":"3484.36"},{"price":"0.00078382","size":"0"}],"bid":[{"price":"0.00054526","size":"0"},{"price":"0.00054525","size":"5.18"}],"sequence":19513150,"timestamp":"2021-07-15T03:00:30.624Z","symbol":"UNIBTC"}}
1626318030.768399: {"jsonrpc":"2.0","method":"updateOrderbook","params":{"ask":[{"price":"0.615880","size":"0"},{"price":"0.616137","size":"10632.5"},{"price":"0.662655","size":"399100.4"}],"bid":[{"price":"0.615619","size":"0"},{"price":"0.615613","size":"1591.5"},{"price":"0.615541","size":"0"},{"price":"0.615508","size":"2955.7"}],"sequence":20584159,"timestamp":"2021-07-15T03:00:30.725Z","symbol":"XRPUSDT"}}
1626318030.768437: {"jsonrpc":"2.0","method":"updateOrderbook","params":{"ask":[{"price":"0.00000065973","size":"15231980"},{"price":"0.00000094570","size":"2769970"}],"bid":[],"sequence":10532347,"timestamp":"2021-07-15T03:00:30.736Z","symbol":"SCBTC"}}
1626318030.853893: {"jsonrpc":"2.0","method":"updateOrderbook","params":{"ask":[{"price":"0.662655","size":"399100.7"},{"price":"0.802748","size":"0"},{"price":"0.803952","size":"0"},{"price":"0.805157","size":"0"},{"price":"0.806361","size":"0"},{"price":"0.807565","size":"0"},{"price":"0.808769","size":"0"},{"price":"0.809973","size":"0"},{"price":"0.811177","size":"0"},{"price":"0.812381","size":"0"},{"price":"0.813585","size":"0"}],"bid":[{"price":"0.609049","size":"0"},{"price":"0.595517","size":"0"},{"price":"0.581984","size":"0"},{"price":"0.568451","size":"0"},{"price":"0.554919","size":"0"}],"sequence":20584160,"timestamp":"2021-07-15T03:00:30.823Z","symbol":"XRPUSDT"}}
1626318030.869235: {"jsonrpc":"2.0","method":"updateOrderbook","params":{"ask":[{"price":"0.00000065973","size":"15231990"},{"price":"0.00000094570","size":"2769990"}],"bid":[],"sequence":10532348,"timestamp":"2021-07-15T03:00:30.842Z","symbol":"SCBTC"}}
1626318030.956927: {"jsonrpc":"2.0","method":"updateOrderbook","params":{"ask":[{"price":"0.662655","size":"399101.0"}],"bid":[],"sequence":20584161,"timestamp":"2021-07-15T03:00:30.926Z","symbol":"XRPUSDT"}}
1626318030.9678478: {"jsonrpc":"2.0","method":"updateOrderbook","params":{"ask":[{"price":"0.00000065973","size":"15232000"}],"bid":[],"sequence":10532349,"timestamp":"2021-07-15T03:00:30.845Z","symbol":"SCBTC"}}
1626318030.9678879: {"jsonrpc":"2.0","method":"updateOrderbook","params":{"ask":[{"price":"0.00054607","size":"199.63"},{"price":"0.00054617","size":"296.51"},{"price":"0.00054649","size":"18.19"},{"price":"0.00054664","size":"0"},{"price":"0.00055750","size":"2539.46"},{"price":"0.00056035","size":"0"}],"bid":[{"price":"0.00054410","size":"0"},{"price":"0.00054396","size":"1.17"}],"sequence":19513151,"timestamp":"2021-07-15T03:00:30.923Z","symbol":"UNIBTC"}}
1626318031.061283: {"jsonrpc":"2.0","method":"updateOrderbook","params":{"ask":[{"price":"0.616746","size":"0"},{"price":"0.617115","size":"0"},{"price":"0.617189","size":"6433.6"},{"price":"0.617506","size":"0"},{"price":"0.617559","size":"4276.9"},{"price":"0.617928","size":"12316.2"},{"price":"0.662655","size":"399101.3"}],"bid":[],"sequence":20584162,"timestamp":"2021-07-15T03:00:31.027Z","symbol":"XRPUSDT"}}
1626318031.0724669: {"jsonrpc":"2.0","method":"updateOrderbook","params":{"ask":[{"price":"0.00000065973","size":"15232010"},{"price":"0.00000094570","size":"2770010"}],"bid":[],"sequence":10532350,"timestamp":"2021-07-15T03:00:30.950Z","symbol":"SCBTC"}}
1626318031.072507: {"jsonrpc":"2.0","method":"updateOrderbook","params":{"ask":[{"price":"0.00054625","size":"0"},{"price":"0.00054638","size":"66.76"},{"price":"0.00054818","size":"84.00"},{"price":"0.00054825","size":"0"},{"price":"0.00058544","size":"0"},{"price":"0.00058953","size":"2343.84"},{"price":"0.00078017","size":"0"},{"price":"0.00078201","size":"3484.36"}],"bid":[{"price":"0.00054525","size":"0"},{"price":"0.00054523","size":"5.18"},{"price":"0.00054505","size":"0"},{"price":"0.00054497","size":"9.62"}],"sequence":19513152,"timestamp":"2021-07-15T03:00:31.019Z","symbol":"UNIBTC"}}
1626318031.1692789: {"jsonrpc":"2.0","method":"updateOrderbook","params":{"ask":[{"price":"0.615774","size":"0"},{"price":"0.615800","size":"1331.7"},{"price":"0.662655","size":"399101.6"},{"price":"0.701792","size":"0"}],"bid":[{"price":"0.615318","size":"6394.5"},{"price":"0.615081","size":"0"},{"price":"0.614734","size":"0"},{"price":"0.614645","size":"6216.0"},{"price":"0.614356","size":"0"},{"price":"0.614249","size":"3391.2"},{"price":"0.610018","size":"491.7"},{"price":"0.609918","size":"0"}],"sequence":20584163,"timestamp":"2021-07-15T03:00:31.137Z","symbol":"XRPUSDT"}}
1626318031.169416: {"jsonrpc":"2.0","method":"updateOrderbook","params":{"ask":[{"price":"0.00000065973","size":"15232030"},{"price":"0.00000094570","size":"0"},{"price":"0.00000094571","size":"2770030"}],"bid":[],"sequence":10532351,"timestamp":"2021-07-15T03:00:31.055Z","symbol":"SCBTC"}}
1626318031.1733298: {"jsonrpc":"2.0","method":"updateOrderbook","params":{"ask":[{"price":"0.00054549","size":"0"},{"price":"0.00054559","size":"4.33"},{"price":"0.00054575","size":"0"},{"price":"0.00054585","size":"10.47"},{"price":"0.00054637","size":"201.47"},{"price":"0.00054654","size":"0"}],"bid":[{"price":"0.00054524","size":"5.18"},{"price":"0.00054523","size":"0"}],"sequence":19513153,"timestamp":"2021-07-15T03:00:31.125Z","symbol":"UNIBTC"}}
1626318031.249354: {"jsonrpc":"2.0","method":"updateOrderbook","params":{"ask":[{"price":"0.615800","size":"0"},{"price":"0.615848","size":"1331.7"},{"price":"0.615881","size":"0"},{"price":"0.615955","size":"3215.6"},{"price":"0.616411","size":"0"},{"price":"0.616515","size":"0"},{"price":"0.616534","size":"503.2"},{"price":"0.616547","size":"0"},{"price":"0.616641","size":"0"},{"price":"0.616675","size":"5468.7"},{"price":"0.616839","size":"7289.7"},{"price":"0.616887","size":"2193.4"},{"price":"0.616904","size":"5500.0"},{"price":"0.617188","size":"0"},{"price":"0.617300","size":"7700.0"},{"price":"0.618246","size":"0"},{"price":"0.619259","size":"49654.6"},{"price":"0.619643","size":"0"},{"price":"0.620850","size":"63061.3"},{"price":"0.623969","size":"0"},{"price":"0.625253","size":"124095.9"},{"price":"0.632203","size":"0"},{"price":"0.633625","size":"129038.8"},{"price":"0.643805","size":"0"},{"price":"0.645321","size":"347706.3"},{"price":"0.656260","size":"0"},{"price":"0.657498","size":"181214.3"},{"price":"0.662655","size":"399101.9"}],"bid":[{"price":"0.615727","size":"1591.5"},{"price":"0.615639","size":"2955.7"},{"price":"0.615613","size":"0"},{"price":"0.615508","size":"0"},{"price":"0.615319","size":"1337.0"},{"price":"0.615318","size":"0"},{"price":"0.615195","size":"0"},{"price":"0.615182","size":"6394.1"}],"sequence":20584164,"timestamp":"2021-07-15T03:00:31.242Z","symbol":"XRPUSDT"}}
1626318031.264626: {"jsonrpc":"2.0","method":"updateOrderbook","params":{"ask":[{"price":"0.00000065973","size":"15232040"},{"price":"0.00000094571","size":"2770050"}],"bid":[],"sequence":10532352,"timestamp":"2021-07-15T03:00:31.160Z","symbol":"SCBTC"}}
1626318031.264645: {"jsonrpc":"2.0","method":"updateOrderbook","params":{"ask":[{"price":"0.00054551","size":"4.33"},{"price":"0.00054559","size":"0"},{"price":"0.00054580","size":"0"},{"price":"0.00054594","size":"0"},{"price":"0.00054603","size":"16.70"},{"price":"0.00054607","size":"0"},{"price":"0.00054617","size":"0"},{"price":"0.00054631","size":"66.20"},{"price":"0.00054644","size":"199.63"},{"price":"0.00054663","size":"296.51"}],"bid":[{"price":"0.00054525","size":"5.18"},{"price":"0.00054524","size":"0"}],"sequence":19513154,"timestamp":"2021-07-15T03:00:31.243Z","symbol":"UNIBTC"}}
1626318031.368602: {"jsonrpc":"2.0","method":"updateOrderbook","params":{"ask":[{"price":"0.615848","size":"0"},{"price":"0.615870","size":"1331.7"},{"price":"0.616239","size":"0"},{"price":"0.616418","size":"495.8"},{"price":"0.622891","size":"0"},{"price":"0.625541","size":"272131.6"},{"price":"0.645321","size":"0"},{"price":"0.647695","size":"347706.3"},{"price":"0.662655","size":"399102.1"}],"bid":[{"price":"0.615760","size":"1591.5"},{"price":"0.615727","size":"0"},{"price":"0.614661","size":"7411.2"},{"price":"0.614575","size":"1800.0"},{"price":"0.614423","size":"5500.0"},{"price":"0.614378","size":"0"},{"price":"0.614375","size":"0"},{"price":"0.614316","size":"0"},{"price":"0.614061","size":"7700.0"},{"price":"0.613967","size":"0"}],"sequence":20584165,"timestamp":"2021-07-15T03:00:31.342Z","symbol":"XRPUSDT"}}
1626318031.368769: {"jsonrpc":"2.0","method":"updateOrderbook","params":{"ask":[{"price":"0.00000065973","size":"15232060"},{"price":"0.00000094571","size":"2770070"}],"bid":[],"sequence":10532353,"timestamp":"2021-07-15T03:00:31.274Z","symbol":"SCBTC"}}
1626318031.3687942: {"jsonrpc":"2.0","method":"updateOrderbook","params":{"ask":[{"price":"0.00054576","size":"10.47"},{"price":"0.00054585","size":"0"}],"bid":[],"sequence":19513155,"timestamp":"2021-07-15T03:00:31.311Z","symbol":"UNIBTC"}}
1626318031.455443: {"jsonrpc":"2.0","method":"updateOrderbook","params":{"ask":[{"price":"0.615870","size":"0"},{"price":"0.615875","size":"1331.7"},{"price":"0.616382","size":"0"},{"price":"0.616383","size":"160.9"},{"price":"0.616904","size":"0"},{"price":"0.616987","size":"5500.0"},{"price":"0.662655","size":"399102.3"}],"bid":[{"price":"0.615789","size":"1591.5"},{"price":"0.615760","size":"0"},{"price":"0.615685","size":"2955.7"},{"price":"0.615639","size":"0"}],"sequence":20584166,"timestamp":"2021-07-15T03:00:31.442Z","symbol":"XRPUSDT"}}
1626318031.469304: {"jsonrpc":"2.0","method":"updateOrderbook","params":{"ask":[{"price":"0.00000065973","size":"15232080"},{"price":"0.00000094571","size":"2770090"}],"bid":[],"sequence":10532354,"timestamp":"2021-07-15T03:00:31.379Z","symbol":"SCBTC"}}
1626318031.5543292: {"jsonrpc":"2.0","method":"updateOrderbook","params":{"ask":[{"price":"0.615874","size":"1331.7"},{"price":"0.615875","size":"0"},{"price":"0.615955","size":"0"},{"price":"0.615982","size":"3215.6"},{"price":"0.616534","size":"0"},{"price":"0.616773","size":"503.2"},{"price":"0.662655","size":"399102.5"}],"bid":[{"price":"0.606754","size":"165690.2"},{"price":"0.605370","size":"0"},{"price":"0.584700","size":"10.2"},{"price":"0.581616","size":"195374.1"}],"sequence":20584167,"timestamp":"2021-07-15T03:00:31.542Z","symbol":"XRPUSDT"}}
1626318031.577652: {"jsonrpc":"2.0","method":"updateOrderbook","params":{"ask":[{"price":"0.00000065973","size":"15232100"},{"price":"0.00000094571","size":"2770120"}],"bid":[],"sequence":10532355,"timestamp":"2021-07-15T03:00:31.527Z","symbol":"SCBTC"}}
1626318031.5776708: {"jsonrpc":"2.0","method":"updateOrderbook","params":{"ask":[{"price":"0.00054551","size":"0"},{"price":"0.00054557","size":"4.33"},{"price":"0.00054579","size":"16.70"},{"price":"0.00054593","size":"66.20"},{"price":"0.00054603","size":"0"},{"price":"0.00054631","size":"0"}],"bid":[{"price":"0.00054526","size":"5.18"},{"price":"0.00054525","size":"0"}],"sequence":19513156,"timestamp":"2021-07-15T03:00:31.532Z","symbol":"UNIBTC"}}
1626318031.647475: {"jsonrpc":"2.0","method":"updateOrderbook","params":{"ask":[{"price":"10000.000","size":"0.0012"}],"bid":[{"price":"0.010","size":"1000.0012"}],"sequence":2190716,"timestamp":"2021-07-15T03:00:31.593Z","symbol":"SPIUSD"}}
1626318031.664532: {"jsonrpc":"2.0","method":"updateOrderbook","params":{"ask":[{"price":"0.615874","size":"0"},{"price":"0.615875","size":"1331.7"},{"price":"0.616722","size":"0"},{"price":"0.616888","size":"5500.0"},{"price":"0.616987","size":"0"},{"price":"0.617126","size":"9601.1"},{"price":"0.617205","size":"7700.0"},{"price":"0.617300","size":"0"},{"price":"0.618549","size":"0"},{"price":"0.619460","size":"68872.3"},{"price":"0.633625","size":"0"},{"price":"0.635140","size":"129038.8"},{"price":"0.657498","size":"0"},{"price":"0.658817","size":"181214.3"},{"price":"0.662655","size":"399102.8"}],"bid":[{"price":"0.615789","size":"0"},{"price":"0.615772","size":"1591.5"},{"price":"0.615063","size":"538.8"},{"price":"0.614927","size":"0"},{"price":"0.614423","size":"0"},{"price":"0.614340","size":"5500.0"}],"sequence":20584168,"timestamp":"2021-07-15T03:00:31.627Z","symbol":"XRPUSDT"}}
1626318031.6750772: {"jsonrpc":"2.0","method":"updateOrderbook","params":{"ask":[{"price":"0.00000065973","size":"15232110"},{"price":"0.00000094571","size":"2770140"}],"bid":[],"sequence":10532356,"timestamp":"2021-07-15T03:00:31.633Z","symbol":"SCBTC"}}
1626318031.677218: {"jsonrpc":"2.0","method":"updateOrderbook","params":{"ask":[{"price":"0.00054593","size":"0"},{"price":"0.00054612","size":"66.20"},{"price":"0.00055066","size":"0"},{"price":"0.00055110","size":"843.90"},{"price":"0.00055750","size":"0"},{"price":"0.00055851","size":"2539.46"}],"bid":[{"price":"0.00054526","size":"0"},{"price":"0.00054525","size":"5.18"},{"price":"0.00054507","size":"9.62"},{"price":"0.00054497","size":"0"},{"price":"0.00054455","size":"199.39"},{"price":"0.00054438","size":"0"}],"sequence":19513157,"timestamp":"2021-07-15T03:00:31.640Z","symbol":"UNIBTC"}}
1626318031.771159: {"jsonrpc":"2.0","method":"updateOrderbook","params":{"ask":[{"price":"0.615844","size":"1331.7"},{"price":"0.615875","size":"0"},{"price":"0.616383","size":"0"},{"price":"0.616417","size":"160.9"},{"price":"0.662655","size":"399103.0"},{"price":"0.671037","size":"0"},{"price":"0.679721","size":"229002.7"},{"price":"0.847046","size":"0"},{"price":"0.857446","size":"324970.5"}],"bid":[{"price":"0.615772","size":"0"},{"price":"0.615742","size":"1591.5"},{"price":"0.615685","size":"0"},{"price":"0.615654","size":"2955.7"},{"price":"0.614575","size":"0"},{"price":"0.614504","size":"1800.0"},{"price":"0.606754","size":"0"},{"price":"0.605348","size":"165690.2"}],"sequence":20584169,"timestamp":"2021-07-15T03:00:31.741Z","symbol":"XRPUSDT"}}
1626318031.771256: {"jsonrpc":"2.0","method":"updateOrderbook","params":{"ask":[{"price":"0.00000065973","size":"15232130"},{"price":"0.00000094571","size":"2770160"}],"bid":[],"sequence":10532357,"timestamp":"2021-07-15T03:00:31.738Z","symbol":"SCBTC"}}
1626318031.771272: {"jsonrpc":"2.0","method":"updateOrderbook","params":{"ask":[{"price":"0.00054550","size":"4.33"},{"price":"0.00054557","size":"0"},{"price":"0.00054797","size":"1302.32"},{"price":"0.00054949","size":"0"},{"price":"0.00055196","size":"0"},{"price":"0.00055287","size":"662.81"}],"bid":[{"price":"0.00054507","size":"0"},{"price":"0.00054499","size":"9.62"}],"sequence":19513158,"timestamp":"2021-07-15T03:00:31.720Z","symbol":"UNIBTC"}}
1626318031.873146: {"jsonrpc":"2.0","method":"updateOrderbook","params":{"ask":[{"price":"0.615831","size":"1331.7"},{"price":"0.615844","size":"0"},{"price":"0.615942","size":"10631.4"},{"price":"0.615943","size":"3215.6"},{"price":"0.615982","size":"0"},{"price":"0.616137","size":"0"},{"price":"0.662655","size":"399103.2"}],"bid":[{"price":"0.615746","size":"1591.5"},{"price":"0.615742","size":"0"}],"sequence":20584170,"timestamp":"2021-07-15T03:00:31.790Z","symbol":"XRPUSDT"}}
1626318031.873281: {"jsonrpc":"2.0","method":"updateOrderbook","params":{"ask":[{"price":"0.00000065973","size":"15232140"},{"price":"0.00000094571","size":"2770170"}],"bid":[],"sequence":10532358,"timestamp":"2021-07-15T03:00:31.824Z","symbol":"SCBTC"}}
1626318031.873306: {"jsonrpc":"2.0","method":"updateOrderbook","params":{"ask":[{"price":"0.00054550","size":"0"},{"price":"0.00054554","size":"4.33"},{"price":"0.00054607","size":"199.63"},{"price":"0.00054617","size":"296.51"},{"price":"0.00054644","size":"0"},{"price":"0.00054663","size":"0"},{"price":"0.00054797","size":"0"},{"price":"0.00054853","size":"1302.32"}],"bid":[{"price":"0.00054528","size":"5.18"},{"price":"0.00054525","size":"0"}],"sequence":19513159,"timestamp":"2021-07-15T03:00:31.818Z","symbol":"UNIBTC"}}
1626318031.970908: {"jsonrpc":"2.0","method":"updateOrderbook","params":{"ask":[{"price":"0.615828","size":"1331.7"},{"price":"0.615831","size":"0"},{"price":"0.615942","size":"0"},{"price":"0.616137","size":"10631.5"},{"price":"0.662655","size":"399103.5"},{"price":"0.679721","size":"0"},{"price":"0.684350","size":"229002.7"},{"price":"0.857446","size":"0"},{"price":"0.862547","size":"324970.5"}],"bid":[{"price":"0.614504","size":"0"},{"price":"0.614436","size":"1800.0"},{"price":"0.581616","size":"0"},{"price":"0.579277","size":"195374.1"}],"sequence":20584171,"timestamp":"2021-07-15T03:00:31.922Z","symbol":"XRPUSDT"}}
1626318031.971047: {"jsonrpc":"2.0","method":"updateOrderbook","params":{"ask":[{"price":"0.00000065973","size":"15232160"},{"price":"0.00000094571","size":"2770190"}],"bid":[{"price":"0.00000034658","size":"4600"},{"price":"0.00000034622","size":"230000"}],"sequence":10532359,"timestamp":"2021-07-15T03:00:31.929Z","symbol":"SCBTC"}}
1626318031.971064: {"jsonrpc":"2.0","method":"updateOrderbook","params":{"ask":[{"price":"0.00054554","size":"0"},{"price":"0.00054557","size":"4.33"},{"price":"0.00054576","size":"0"},{"price":"0.00054584","size":"10.47"},{"price":"0.00054607","size":"0"},{"price":"0.00054617","size":"0"},{"price":"0.00054642","size":"199.63"},{"price":"0.00054661","size":"296.51"},{"price":"0.00054777","size":"0"},{"price":"0.00054818","size":"170.00"},{"price":"0.00054853","size":"0"},{"price":"0.00054917","size":"1302.32"}],"bid":[{"price":"0.00054531","size":"5.18"},{"price":"0.00054528","size":"0"},{"price":"0.00053478","size":"2974.71"},{"price":"0.00053298","size":"0"}],"sequence":19513160,"timestamp":"2021-07-15T03:00:31.924Z","symbol":"UNIBTC"}}
1626318032.056236: {"jsonrpc":"2.0","method":"updateOrderbook","params":{"ask":[{"price":"0.615942","size":"10631.5"},{"price":"0.616137","size":"0"},{"price":"0.662655","size":"399103.8"}],"bid":[{"price":"0.615748","size":"1591.5"},{"price":"0.615746","size":"0"},{"price":"0.579277","size":"0"},{"price":"0.576918","size":"195374.1"}],"sequence":20584172,"timestamp":"2021-07-15T03:00:32.031Z","symbol":"XRPUSDT"}}
1626318032.072883: {"jsonrpc":"2.0","method":"updateOrderbook","params":{"ask":[{"price":"0.00000065973","size":"15232170"},{"price":"0.00000094571","size":"2770210"}],"bid":[{"price":"0.00000034658","size":"234600"},{"price":"0.00000034622","size":"0"}],"sequence":10532360,"timestamp":"2021-07-15T03:00:32.023Z","symbol":"SCBTC"}}
1626318032.0729249: {"jsonrpc":"2.0","method":"updateOrderbook","params":{"ask":[{"price":"0.00054555","size":"4.33"},{"price":"0.00054557","size":"0"},{"price":"0.00054579","size":"0"},{"price":"0.00054612","size":"0"},{"price":"0.00054618","size":"16.70"},{"price":"0.00054624","size":"66.76"},{"price":"0.00054631","size":"66.20"},{"price":"0.00054637","size":"0"},{"price":"0.00054638","size":"0"},{"price":"0.00054657","size":"201.47"}],"bid":[{"price":"0.00054531","size":"0"},{"price":"0.00054530","size":"5.18"},{"price":"0.00053050","size":"0.79"}],"sequence":19513161,"timestamp":"2021-07-15T03:00:32.036Z","symbol":"UNIBTC"}}
1626318032.155334: {"jsonrpc":"2.0","method":"updateOrderbook","params":{"ask":[{"price":"0.662655","size":"399103.9"}],"bid":[],"sequence":20584173,"timestamp":"2021-07-15T03:00:32.087Z","symbol":"XRPUSDT"}}
1626318032.165807: {"jsonrpc":"2.0","method":"updateOrderbook","params":{"ask":[{"price":"0.00000065973","size":"15232190"},{"price":"0.00000094571","size":"2770230"}],"bid":[],"sequence":10532361,"timestamp":"2021-07-15T03:00:32.128Z","symbol":"SCBTC"}}
1626318032.170584: {"jsonrpc":"2.0","method":"updateOrderbook","params":{"ask":[{"price":"0.00054551","size":"4.33"},{"price":"0.00054555","size":"0"}],"bid":[{"price":"0.00054530","size":"0"},{"price":"0.00054528","size":"5.18"},{"price":"0.00053050","size":"0"}],"sequence":19513162,"timestamp":"2021-07-15T03:00:32.123Z","symbol":"UNIBTC"}}
1626318032.2594829: {"jsonrpc":"2.0","method":"updateOrderbook","params":{"ask":[{"price":"0.615825","size":"1331.7"},{"price":"0.615828","size":"0"},{"price":"0.662655","size":"399104.3"}],"bid":[{"price":"0.615748","size":"0"},{"price":"0.615738","size":"1591.5"}],"sequence":20584174,"timestamp":"2021-07-15T03:00:32.241Z","symbol":"XRPUSDT"}}
1626318032.267669: {"jsonrpc":"2.0","method":"updateOrderbook","params":{"ask":[{"price":"0.00000065973","size":"15232200"},{"price":"0.00000094571","size":"2770240"}],"bid":[],"sequence":10532362,"timestamp":"2021-07-15T03:00:32.196Z","symbol":"SCBTC"}}
1626318032.271039: {"jsonrpc":"2.0","method":"updateOrderbook","params":{"ask":[{"price":"0.00054777","size":"86.00"},{"price":"0.00054818","size":"84.00"}],"bid":[{"price":"0.00054528","size":"0"},{"price":"0.00054527","size":"5.18"},{"price":"0.00052694","size":"445.48"}],"sequence":19513163,"timestamp":"2021-07-15T03:00:32.221Z","symbol":"UNIBTC"}}
1626318032.380552: {"jsonrpc":"2.0","method":"updateOrderbook","params":{"ask":[{"price":"0.662655","size":"399104.5"}],"bid":[{"price":"0.576918","size":"0"},{"price":"0.574270","size":"195374.1"}],"sequence":20584175,"timestamp":"2021-07-15T03:00:32.326Z","symbol":"XRPUSDT"}}
1626318032.380592: {"jsonrpc":"2.0","method":"updateOrderbook","params":{"ask":[{"price":"0.00000065973","size":"15232210"},{"price":"0.00000094571","size":"2770260"}],"bid":[],"sequence":10532363,"timestamp":"2021-07-15T03:00:32.308Z","symbol":"SCBTC"}}
1626318032.380607: {"jsonrpc":"2.0","method":"updateOrderbook","params":{"ask":[{"price":"0.00054547","size":"4.33"},{"price":"0.00054551","size":"0"},{"price":"0.00054572","size":"10.47"},{"price":"0.00054584","size":"0"},{"price":"0.00054587","size":"16.70"},{"price":"0.00054601","size":"66.20"},{"price":"0.00054618","size":"0"},{"price":"0.00054631","size":"0"}],"bid":[],"sequence":19513164,"timestamp":"2021-07-15T03:00:32.328Z","symbol":"UNIBTC"}}
1626318032.463087: {"jsonrpc":"2.0","method":"updateOrderbook","params":{"ask":[{"price":"0.615818","size":"1331.7"},{"price":"0.615825","size":"0"},{"price":"0.662655","size":"399104.7"}],"bid":[],"sequence":20584176,"timestamp":"2021-07-15T03:00:32.399Z","symbol":"XRPUSDT"}}
1626318032.463132: {"jsonrpc":"2.0","method":"updateOrderbook","params":{"ask":[{"price":"0.00000065973","size":"15232230"},{"price":"0.00000094571","size":"2770280"},{"price":"0.00000095824","size":"2754880"},{"price":"0.00000095882","size":"0"}],"bid":[],"sequence":10532364,"timestamp":"2021-07-15T03:00:32.404Z","symbol":"SCBTC"}}
1626318032.463147: {"jsonrpc":"2.0","method":"updateOrderbook","params":{"ask":[{"price":"0.00054547","size":"0"},{"price":"0.00054552","size":"4.33"}],"bid":[{"price":"0.00054528","size":"5.18"},{"price":"0.00054527","size":"0"}],"sequence":19513165,"timestamp":"2021-07-15T03:00:32.424Z","symbol":"UNIBTC"}}
1626318032.5701702: {"jsonrpc":"2.0","method":"updateOrderbook","params":{"ask":[{"price":"0.662655","size":"399105.0"}],"bid":[],"sequence":20584177,"timestamp":"2021-07-15T03:00:32.502Z","symbol":"XRPUSDT"}}
1626318032.570226: {"jsonrpc":"2.0","method":"updateOrderbook","params":{"ask":[{"price":"0.00000037314","size":"661850"},{"price":"0.00000037357","size":"0"},{"price":"0.00000044040","size":"1381850"},{"price":"0.00000044325","size":"0"},{"price":"0.00000065973","size":"15232250"},{"price":"0.00000094571","size":"2770300"}],"bid":[],"sequence":10532365,"timestamp":"2021-07-15T03:00:32.521Z","symbol":"SCBTC"}}
1626318032.5702558: {"jsonrpc":"2.0","method":"updateOrderbook","params":{"ask":[{"price":"0.00054550","size":"4.33"},{"price":"0.00054552","size":"0"},{"price":"0.00054587","size":"0"},{"price":"0.00054601","size":"0"},{"price":"0.00054603","size":"16.70"},{"price":"0.00054614","size":"66.20"},{"price":"0.00054915","size":"433.80"},{"price":"0.00054992","size":"0"}],"bid":[{"price":"0.00052694","size":"0"}],"sequence":19513166,"timestamp":"2021-07-15T03:00:32.522Z","symbol":"UNIBTC"}}
1626318032.680046: {"jsonrpc":"2.0","method":"updateOrderbook","params":{"ask":[{"price":"0.615800","size":"11000.0"},{"price":"0.615810","size":"1331.7"},{"price":"0.615818","size":"0"},{"price":"0.616417","size":"0"},{"price":"0.616479","size":"160.9"},{"price":"0.662655","size":"399105.3"}],"bid":[{"price":"0.615738","size":"0"},{"price":"0.615726","size":"1591.5"},{"price":"0.615654","size":"0"},{"price":"0.615619","size":"2955.7"},{"price":"0.615319","size":"0"},{"price":"0.615195","size":"1337.0"}],"sequence":20584178,"timestamp":"2021-07-15T03:00:32.627Z","symbol":"XRPUSDT"}}
1626318032.680186: {"jsonrpc":"2.0","method":"updateOrderbook","params":{"ask":[{"price":"0.00000065973","size":"15232260"},{"price":"0.00000094571","size":"2770320"}],"bid":[],"sequence":10532366,"timestamp":"2021-07-15T03:00:32.629Z","symbol":"SCBTC"}}
1626318032.680722: {"jsonrpc":"2.0","method":"updateOrderbook","params":{"ask":[{"price":"0.00054613","size":"199.63"},{"price":"0.00054623","size":"296.51"},{"price":"0.00054642","size":"0"},{"price":"0.00054661","size":"0"}],"bid":[{"price":"0.00054529","size":"5.18"},{"price":"0.00054528","size":"0"},{"price":"0.00053050","size":"442.49"}],"sequence":19513167,"timestamp":"2021-07-15T03:00:32.586Z","symbol":"UNIBTC"}}
1626318032.754836: {"jsonrpc":"2.0","method":"updateOrderbook","params":{"ask":[{"price":"0.615800","size":"0"},{"price":"0.615806","size":"1331.7"},{"price":"0.615810","size":"0"},{"price":"0.616417","size":"160.9"},{"price":"0.616479","size":"0"},{"price":"0.616552","size":"503.2"},{"price":"0.616773","size":"0"},{"price":"0.616951","size":"12967.5"},{"price":"0.617377","size":"0"},{"price":"0.618514","size":"68872.3"},{"price":"0.619460","size":"0"},{"price":"0.662655","size":"399105.6"},{"price":"0.702158","size":"228479.7"}],"bid":[{"price":"0.615726","size":"0"},{"price":"0.615660","size":"1591.5"},{"price":"0.615619","size":"0"},{"price":"0.615571","size":"2955.7"},{"price":"0.615339","size":"1337.0"},{"price":"0.615195","size":"0"}],"sequence":20584179,"timestamp":"2021-07-15T03:00:32.734Z","symbol":"XRPUSDT"}}
1626318032.768428: {"jsonrpc":"2.0","method":"updateOrderbook","params":{"ask":[{"price":"0.00000065973","size":"15232280"},{"price":"0.00000094571","size":"2770340"}],"bid":[],"sequence":10532367,"timestamp":"2021-07-15T03:00:32.734Z","symbol":"SCBTC"}}
1626318032.772165: {"jsonrpc":"2.0","method":"updateOrderbook","params":{"ask":[{"price":"0.00054651","size":"218.82"},{"price":"0.00054681","size":"0"}],"bid":[{"price":"0.00054529","size":"0"},{"price":"0.00054525","size":"5.18"}],"sequence":19513168,"timestamp":"2021-07-15T03:00:32.718Z","symbol":"UNIBTC"}}
1626318032.856093: {"jsonrpc":"2.0","method":"updateOrderbook","params":{"ask":[{"price":"0.615776","size":"12331.7"},{"price":"0.615806","size":"0"},{"price":"0.616265","size":"495.8"},{"price":"0.616418","size":"0"},{"price":"0.616480","size":"0"},{"price":"0.662655","size":"399105.9"}],"bid":[{"price":"0.615698","size":"0"},{"price":"0.615660","size":"0"},{"price":"0.615652","size":"1591.5"},{"price":"0.615339","size":"0"},{"price":"0.615195","size":"1337.0"},{"price":"0.614340","size":"0"},{"price":"0.614277","size":"5500.0"}],"sequence":20584180,"timestamp":"2021-07-15T03:00:32.840Z","symbol":"XRPUSDT"}}
1626318032.893327: {"jsonrpc":"2.0","method":"updateOrderbook","params":{"ask":[{"price":"0.00000065973","size":"15232290"},{"price":"0.00000094571","size":"2770360"}],"bid":[],"sequence":10532368,"timestamp":"2021-07-15T03:00:32.839Z","symbol":"SCBTC"}}
1626318032.893385: {"jsonrpc":"2.0","method":"updateOrderbook","params":{"ask":[{"price":"0.00054548","size":"4.33"},{"price":"0.00054550","size":"0"},{"price":"0.00054586","size":"16.70"},{"price":"0.00054599","size":"66.20"},{"price":"0.00054603","size":"0"},{"price":"0.00054614","size":"0"}],"bid":[{"price":"0.00054486","size":"18.61"},{"price":"0.00054477","size":"0"}],"sequence":19513169,"timestamp":"2021-07-15T03:00:32.785Z","symbol":"UNIBTC"}}
1626318032.954602: {"jsonrpc":"2.0","method":"updateOrderbook","params":{"ask":[{"price":"0.615776","size":"11000.0"},{"price":"0.615824","size":"1331.7"},{"price":"0.616282","size":"10633.0"},{"price":"0.616816","size":"5500.0"},{"price":"0.616888","size":"0"},{"price":"0.617102","size":"7700.0"},{"price":"0.617205","size":"0"},{"price":"0.662655","size":"399106.2"},{"price":"0.702158","size":"0"}],"bid":[{"price":"0.615698","size":"1591.5"},{"price":"0.615652","size":"0"},{"price":"0.615571","size":"0"},{"price":"0.615535","size":"2955.7"},{"price":"0.615063","size":"0"},{"price":"0.614883","size":"538.8"}],"sequence":20584181,"timestamp":"2021-07-15T03:00:32.937Z","symbol":"XRPUSDT"}}
1626318032.994666: {"jsonrpc":"2.0","method":"updateOrderbook","params":{"ask":[{"price":"0.00000036726","size":"0"},{"price":"0.00000036737","size":"0"},{"price":"0.00000036748","size":"0"},{"price":"0.00000036761","size":"25530"},{"price":"0.00000036784","size":"0"},{"price":"0.00000036826","size":"101590"},{"price":"0.00000036877","size":"255050"},{"price":"0.00000036909","size":"408320"},{"price":"0.00000036910","size":"0"},{"price":"0.00000037314","size":"0"},{"price":"0.00000037986","size":"603920"},{"price":"0.00000041211","size":"666450"},{"price":"0.00000041356","size":"0"},{"price":"0.00000042829","size":"1016210"},{"price":"0.00000044040","size":"0"},{"price":"0.00000060970","size":"1381850"},{"price":"0.00000065973","size":"15232310"},{"price":"0.00000089465","size":"0"},{"price":"0.00000094571","size":"2770370"},{"price":"0.00000106078","size":"2001500"},{"price":"0.00000124640","size":"0"},{"price":"0.00000131433","size":"2705250"},{"price":"0.00000146968","size":"0"},{"price":"0.00000148900","size":"3222000"},{"price":"0.00000161321","size":"0"},{"price":"0.00000167169","size":"4634410"},{"price":"0.00000419436","size":"0"},{"price":"0.00000462426","size":"7466230"}],"bid":[{"price":"0.00000036428","size":"0"},{"price":"0.00000036411","size":"0"},{"price":"0.00000036388","size":"284390"},{"price":"0.00000036356","size":"0"},{"price":"0.00000036342","size":"384900"},{"price":"0.00000036330","size":"586390"},{"price":"0.00000036265","size":"0"},{"price":"0.00000036210","size":"1248220"},{"price":"0.00000032212","size":"0"},{"price":"0.00000023946","size":"1993120"},{"price":"0.00000004424","size":"0"},{"price":"0.00000000735","size":"2752080"}],"sequence":10532369,"timestamp":"2021-07-15T03:00:32.933Z","symbol":"SCBTC"}}
1626318032.994829: {"jsonrpc":"2.0","method":"updateOrderbook","params":{"ask":[{"price":"0.00054548","size":"0"},{"price":"0.00054550","size":"4.33"},{"price":"0.00054633","size":"333.84"},{"price":"0.00054647","size":"440.89"},{"price":"0.00054662","size":"0"},{"price":"0.00054689","size":"0"}],"bid":[{"price":"0.00053050","size":"443.28"}],"sequence":19513170,"timestamp":"2021-07-15T03:00:32.920Z","symbol":"UNIBTC"}}
1626318033.081207: {"jsonrpc":"2.0","method":"updateOrderbook","params":{"ask":[{"price":"0.615776","size":"0"},{"price":"0.615801","size":"11000.0"},{"price":"0.615824","size":"0"},{"price":"0.615830","size":"1331.7"},{"price":"0.616282","size":"0"},{"price":"0.616384","size":"0"},{"price":"0.616417","size":"0"},{"price":"0.616479","size":"160.9"},{"price":"0.616480","size":"10632.0"},{"price":"0.616562","size":"2020.2"},{"price":"0.646107","size":"347706.3"},{"price":"0.647695","size":"0"},{"price":"0.662655","size":"399106.5"}],"bid":[{"price":"0.615713","size":"1591.5"},{"price":"0.615698","size":"0"},{"price":"0.615608","size":"2955.7"},{"price":"0.615535","size":"0"}],"sequence":20584182,"timestamp":"2021-07-15T03:00:33.042Z","symbol":"XRPUSDT"}}
1626318033.081236: {"jsonrpc":"2.0","method":"updateOrderbook","params":{"ask":[{"price":"0.00000065973","size":"15232320"},{"price":"0.00000094571","size":"2770380"}],"bid":[{"price":"0.00000036535","size":"1000"},{"price":"0.00000036483","size":"0"}],"sequence":10532370,"timestamp":"2021-07-15T03:00:32.994Z","symbol":"SCBTC"}}
1626318033.081253: {"jsonrpc":"2.0","method":"updateOrderbook","params":{"ask":[{"price":"0.00054550","size":"0"},{"price":"0.00054556","size":"4.33"},{"price":"0.00054572","size":"0"},{"price":"0.00054582","size":"10.47"},{"price":"0.00054594","size":"17.11"},{"price":"0.00054616","size":"0"},{"price":"0.00054647","size":"0"},{"price":"0.00054684","size":"440.89"},{"price":"0.00055429","size":"881.76"},{"price":"0.00056925","size":"0"}],"bid":[{"price":"0.00054528","size":"5.18"},{"price":"0.00054525","size":"0"}],"sequence":19513171,"timestamp":"2021-07-15T03:00:33.027Z","symbol":"UNIBTC"}}
1626318033.155624: {"jsonrpc":"2.0","method":"updateOrderbook","params":{"ask":[{"price":"0.615801","size":"0"},{"price":"0.615830","size":"0"},{"price":"0.615853","size":"1331.7"},{"price":"0.624064","size":"272131.6"},{"price":"0.625541","size":"0"},{"price":"0.662655","size":"399106.7"}],"bid":[{"price":"0.615743","size":"11000.0"},{"price":"0.615713","size":"0"},{"price":"0.615696","size":"1591.5"},{"price":"0.615318","size":"1337.0"},{"price":"0.615195","size":"0"},{"price":"0.614436","size":"0"},{"price":"0.614368","size":"1800.0"}],"sequence":20584183,"timestamp":"2021-07-15T03:00:33.133Z","symbol":"XRPUSDT"}}
1626318033.1710348: {"jsonrpc":"2.0","method":"updateOrderbook","params":{"ask":[{"price":"0.00000065973","size":"15232330"},{"price":"0.00000094571","size":"2770400"}],"bid":[],"sequence":10532371,"timestamp":"2021-07-15T03:00:33.101Z","symbol":"SCBTC"}}
1626318033.1733289: {"jsonrpc":"2.0","method":"updateOrderbook","params":{"ask":[{"price":"0.00054613","size":"0"},{"price":"0.00054623","size":"0"},{"price":"0.00054633","size":"0"},{"price":"0.00054637","size":"201.47"},{"price":"0.00054639","size":"217.72"},{"price":"0.00054657","size":"0"},{"price":"0.00054661","size":"296.51"},{"price":"0.00054685","size":"333.84"},{"price":"0.00055063","size":"843.90"},{"price":"0.00055110","size":"0"}],"bid":[{"price":"0.00054528","size":"0"},{"price":"0.00054526","size":"5.18"},{"price":"0.00053478","size":"0"},{"price":"0.00053387","size":"2974.71"}],"sequence":19513172,"timestamp":"2021-07-15T03:00:33.143Z","symbol":"UNIBTC"}}
1626318033.260042: {"jsonrpc":"2.0","method":"updateOrderbook","params":{"ask":[{"price":"0.615819","size":"11000.0"},{"price":"0.615841","size":"1331.7"},{"price":"0.615853","size":"0"},{"price":"0.633757","size":"129038.8"},{"price":"0.635140","size":"0"},{"price":"0.657613","size":"181214.3"},{"price":"0.658817","size":"0"},{"price":"0.662655","size":"399107.0"}],"bid":[{"price":"0.615709","size":"1591.5"},{"price":"0.615696","size":"0"},{"price":"0.615318","size":"0"},{"price":"0.615195","size":"1337.0"},{"price":"0.606732","size":"165690.2"},{"price":"0.605348","size":"0"}],"sequence":20584184,"timestamp":"2021-07-15T03:00:33.228Z","symbol":"XRPUSDT"}}
1626318033.271944: {"jsonrpc":"2.0","method":"updateOrderbook","params":{"ask":[{"price":"0.00000065973","size":"15232350"},{"price":"0.00000094571","size":"2770420"}],"bid":[],"sequence":10532372,"timestamp":"2021-07-15T03:00:33.194Z","symbol":"SCBTC"}}
1626318033.278164: {"jsonrpc":"2.0","method":"updateOrderbook","params":{"ask":[{"price":"0.00054551","size":"4.33"},{"price":"0.00054556","size":"0"},{"price":"0.00054586","size":"0"},{"price":"0.00054596","size":"16.70"},{"price":"0.00054599","size":"0"},{"price":"0.00054610","size":"85.08"}],"bid":[],"sequence":19513173,"timestamp":"2021-07-15T03:00:33.181Z","symbol":"UNIBTC"}}
1626318033.367458: {"jsonrpc":"2.0","method":"updateOrderbook","params":{"ask":[{"price":"0.615819","size":"0"},{"price":"0.615838","size":"1331.7"},{"price":"0.615841","size":"0"},{"price":"0.662655","size":"399107.2"}],"bid":[{"price":"0.615743","size":"0"},{"price":"0.615731","size":"11000.0"},{"price":"0.615719","size":"1591.5"},{"price":"0.615709","size":"0"}],"sequence":20584185,"timestamp":"2021-07-15T03:00:33.318Z","symbol":"XRPUSDT"}}
1626318033.3675892: {"jsonrpc":"2.0","method":"updateOrderbook","params":{"ask":[{"price":"0.00000065973","size":"15232360"},{"price":"0.00000094571","size":"2770440"}],"bid":[],"sequence":10532373,"timestamp":"2021-07-15T03:00:33.303Z","symbol":"SCBTC"}}
1626318033.367614: {"jsonrpc":"2.0","method":"updateOrderbook","params":{"ask":[],"bid":[{"price":"0.00054529","size":"5.18"},{"price":"0.00054526","size":"0"}],"sequence":19513174,"timestamp":"2021-07-15T03:00:33.282Z","symbol":"UNIBTC"}}
1626318033.466126: {"jsonrpc":"2.0","method":"updateOrderbook","params":{"ask":[{"price":"0.662655","size":"399107.5"}],"bid":[{"price":"0.615719","size":"0"},{"price":"0.615688","size":"1591.5"},{"price":"0.606732","size":"0"},{"price":"0.605158","size":"165690.2"}],"sequence":20584186,"timestamp":"2021-07-15T03:00:33.420Z","symbol":"XRPUSDT"}}
1626318033.466472: {"jsonrpc":"2.0","method":"updateOrderbook","params":{"ask":[{"price":"0.00000065973","size":"15232380"},{"price":"0.00000094571","size":"2770460"}],"bid":[],"sequence":10532374,"timestamp":"2021-07-15T03:00:33.410Z","symbol":"SCBTC"}}
1626318033.586237: {"jsonrpc":"2.0","method":"updateOrderbook","params":{"ask":[{"price":"0.615811","size":"1331.7"},{"price":"0.615838","size":"0"},{"price":"0.616387","size":"160.9"},{"price":"0.616388","size":"2020.2"},{"price":"0.616479","size":"0"},{"price":"0.616562","size":"0"},{"price":"0.617102","size":"0"},{"price":"0.617196","size":"7700.0"},{"price":"0.662655","size":"399107.7"}],"bid":[{"price":"0.614061","size":"0"},{"price":"0.613962","size":"7700.0"}],"sequence":20584187,"timestamp":"2021-07-15T03:00:33.519Z","symbol":"XRPUSDT"}}
1626318033.586375: {"jsonrpc":"2.0","method":"updateOrderbook","params":{"ask":[{"price":"0.00000065973","size":"15232390"},{"price":"0.00000094571","size":"2770480"}],"bid":[],"sequence":10532375,"timestamp":"2021-07-15T03:00:33.516Z","symbol":"SCBTC"}}
1626318033.5864: {"jsonrpc":"2.0","method":"updateOrderbook","params":{"ask":[{"price":"0.00054624","size":"0"},{"price":"0.00054638","size":"66.76"},{"price":"0.00054843","size":"1302.32"},{"price":"0.00054917","size":"0"},{"price":"0.00058935","size":"2343.84"},{"price":"0.00058953","size":"0"},{"price":"0.00062612","size":"1125.76"},{"price":"0.00073715","size":"0"},{"price":"0.00078195","size":"3484.36"},{"price":"0.00078201","size":"0"},{"price":"0.00081742","size":"1585.64"},{"price":"0.00083870","size":"0"}],"bid":[],"sequence":19513175,"timestamp":"2021-07-15T03:00:33.530Z","symbol":"UNIBTC"}}
1626318033.6629179: {"jsonrpc":"2.0","method":"updateOrderbook","params":{"ask":[{"price":"0.615790","size":"1331.7"},{"price":"0.615811","size":"0"},{"price":"0.615888","size":"3215.6"},{"price":"0.615943","size":"0"},{"price":"0.616906","size":"6433.6"},{"price":"0.617189","size":"0"},{"price":"0.662655","size":"399108.0"}],"bid":[{"price":"0.615688","size":"0"},{"price":"0.615682","size":"1591.5"},{"price":"0.615608","size":"0"},{"price":"0.615576","size":"2955.7"}],"sequence":20584188,"timestamp":"2021-07-15T03:00:33.628Z","symbol":"XRPUSDT"}}
1626318033.663063: {"jsonrpc":"2.0","method":"updateOrderbook","params":{"ask":[{"price":"0.00000065973","size":"15232410"},{"price":"0.00000094571","size":"2770490"}],"bid":[],"sequence":10532376,"timestamp":"2021-07-15T03:00:33.621Z","symbol":"SCBTC"}}
1626318033.663079: {"jsonrpc":"2.0","method":"updateOrderbook","params":{"ask":[{"price":"0.00054777","size":"0"},{"price":"0.00054818","size":"170.00"}],"bid":[{"price":"0.00054529","size":"0"},{"price":"0.00054526","size":"5.18"}],"sequence":19513176,"timestamp":"2021-07-15T03:00:33.627Z","symbol":"UNIBTC"}}
1626318033.7673972: {"jsonrpc":"2.0","method":"updateOrderbook","params":{"ask":[{"price":"0.662655","size":"399108.2"}],"bid":[{"price":"0.614890","size":"6216.0"},{"price":"0.614645","size":"0"},{"price":"0.614474","size":"3391.2"},{"price":"0.614249","size":"0"},{"price":"0.614071","size":"13252.5"},{"price":"0.613909","size":"0"}],"sequence":20584189,"timestamp":"2021-07-15T03:00:33.698Z","symbol":"XRPUSDT"}}
1626318033.768845: {"jsonrpc":"2.0","method":"updateOrderbook","params":{"ask":[{"price":"0.00000065973","size":"15232420"},{"price":"0.00000094571","size":"2770510"}],"bid":[],"sequence":10532377,"timestamp":"2021-07-15T03:00:33.727Z","symbol":"SCBTC"}}
1626318033.7689018: {"jsonrpc":"2.0","method":"updateOrderbook","params":{"ask":[{"price":"0.00054551","size":"0"},{"price":"0.00054553","size":"4.33"}],"bid":[{"price":"0.00054527","size":"5.18"},{"price":"0.00054526","size":"0"}],"sequence":19513177,"timestamp":"2021-07-15T03:00:33.740Z","symbol":"UNIBTC"}}
1626318033.85979: {"jsonrpc":"2.0","method":"updateOrderbook","params":{"ask":[{"price":"0.662655","size":"399108.5"}],"bid":[{"price":"0.615690","size":"1596.4"},{"price":"0.615682","size":"0"}],"sequence":20584190,"timestamp":"2021-07-15T03:00:33.824Z","symbol":"XRPUSDT"}}
1626318033.873527: {"jsonrpc":"2.0","method":"updateOrderbook","params":{"ask":[{"price":"0.00000065973","size":"15232440"},{"price":"0.00000094571","size":"2770530"}],"bid":[],"sequence":10532378,"timestamp":"2021-07-15T03:00:33.831Z","symbol":"SCBTC"}}
1626318033.873587: {"jsonrpc":"2.0","method":"updateOrderbook","params":{"ask":[{"price":"0.00054553","size":"0"},{"price":"0.00054558","size":"4.33"},{"price":"0.00054616","size":"199.63"},{"price":"0.00054626","size":"296.51"},{"price":"0.00054639","size":"18.09"},{"price":"0.00054661","size":"0"}],"bid":[{"price":"0.00054530","size":"5.18"},{"price":"0.00054527","size":"0"}],"sequence":19513178,"timestamp":"2021-07-15T03:00:33.816Z","symbol":"UNIBTC"}}
1626318033.9534678: {"jsonrpc":"2.0","method":"updateOrderbook","params":{"ask":[{"price":"0.615760","size":"11000.0"},{"price":"0.615790","size":"0"},{"price":"0.615795","size":"1331.7"},{"price":"0.662655","size":"399108.7"}],"bid":[{"price":"0.615731","size":"0"},{"price":"0.615690","size":"4.9"},{"price":"0.615609","size":"1591.5"},{"price":"0.615576","size":"0"},{"price":"0.615511","size":"2955.7"}],"sequence":20584191,"timestamp":"2021-07-15T03:00:33.895Z","symbol":"XRPUSDT"}}
1626318033.9609358: {"jsonrpc":"2.0","method":"updateOrderbook","params":{"ask":[{"price":"0.00000065973","size":"15232450"},{"price":"0.00000094571","size":"2770550"}],"bid":[],"sequence":10532379,"timestamp":"2021-07-15T03:00:33.937Z","symbol":"SCBTC"}}
1626318033.960958: {"jsonrpc":"2.0","method":"updateOrderbook","params":{"ask":[{"price":"0.00054596","size":"0"},{"price":"0.00054609","size":"16.70"},{"price":"0.00054610","size":"18.88"},{"price":"0.00054616","size":"0"},{"price":"0.00054626","size":"0"},{"price":"0.00054630","size":"66.20"},{"price":"0.00054643","size":"199.63"},{"price":"0.00054662","size":"296.51"},{"price":"0.00054843","size":"0"},{"price":"0.00054920","size":"1302.32"}],"bid":[{"price":"0.00054509","size":"9.62"},{"price":"0.00054499","size":"0"}],"sequence":19513179,"timestamp":"2021-07-15T03:00:33.918Z","symbol":"UNIBTC"}}
1626318034.0687811: {"jsonrpc":"2.0","method":"updateOrderbook","params":{"ask":[{"price":"0.662655","size":"399109.1"}],"bid":[{"price":"0.615679","size":"1591.5"},{"price":"0.615609","size":"0"}],"sequence":20584192,"timestamp":"2021-07-15T03:00:34.024Z","symbol":"XRPUSDT"}}
1626318034.068816: {"jsonrpc":"2.0","method":"updateOrderbook","params":{"ask":[{"price":"0.00000065973","size":"15232470"},{"price":"0.00000094571","size":"2770570"}],"bid":[],"sequence":10532380,"timestamp":"2021-07-15T03:00:34.043Z","symbol":"SCBTC"}}
1626318034.151662: {"jsonrpc":"2.0","method":"updateOrderbook","params":{"ask":[{"price":"0.617284","size":"4276.9"},{"price":"0.617559","size":"0"},{"price":"0.617687","size":"12316.2"},{"price":"0.617928","size":"0"},{"price":"0.662655","size":"399109.3"}],"bid":[],"sequence":20584193,"timestamp":"2021-07-15T03:00:34.090Z","symbol":"XRPUSDT"}}
1626318034.163232: {"jsonrpc":"2.0","method":"updateOrderbook","params":{"ask":[{"price":"0.00054556","size":"4.33"},{"price":"0.00054558","size":"0"},{"price":"0.00055063","size":"0"},{"price":"0.00055110","size":"843.90"}],"bid":[{"price":"0.00054530","size":"0"},{"price":"0.00054528","size":"5.18"}],"sequence":19513180,"timestamp":"2021-07-15T03:00:34.120Z","symbol":"UNIBTC"}}
1626318034.250763: {"jsonrpc":"2.0","method":"updateOrderbook","params":{"ask":[],"bid":[{"price":"12.104","size":"5.7265"},{"price":"12.103","size":"5.8737"}],"sequence":2190717,"timestamp":"2021-07-15T03:00:34.206Z","symbol":"SPIUSD"}}
1626318034.25085: {"jsonrpc":"2.0","method":"updateOrderbook","params":{"ask":[{"price":"0.618282","size":"49654.6"},{"price":"0.619259","size":"0"},{"price":"0.623770","size":"124095.9"},{"price":"0.625253","size":"0"},{"price":"0.662655","size":"399109.7"}],"bid":[{"price":"0.615575","size":"2955.7"},{"price":"0.615511","size":"0"}],"sequence":20584194,"timestamp":"2021-07-15T03:00:34.238Z","symbol":"XRPUSDT"}}
1626318034.260673: {"jsonrpc":"2.0","method":"updateOrderbook","params":{"ask":[{"price":"0.00000065973","size":"15232480"},{"price":"0.00000094571","size":"2770590"}],"bid":[],"sequence":10532381,"timestamp":"2021-07-15T03:00:34.147Z","symbol":"SCBTC"}}
1626318034.260691: {"jsonrpc":"2.0","method":"updateOrderbook","params":{"ask":[{"price":"0.00054591","size":"16.70"},{"price":"0.00054605","size":"66.20"},{"price":"0.00054609","size":"0"},{"price":"0.00054630","size":"0"},{"price":"0.00054915","size":"0"},{"price":"0.00054992","size":"433.80"}],"bid":[{"price":"0.00054530","size":"5.18"},{"price":"0.00054528","size":"0"}],"sequence":19513181,"timestamp":"2021-07-15T03:00:34.172Z","symbol":"UNIBTC"}}
1626318034.369005: {"jsonrpc":"2.0","method":"updateOrderbook","params":{"ask":[{"price":"0.615760","size":"0"},{"price":"0.615786","size":"1331.7"},{"price":"0.615795","size":"0"},{"price":"0.662655","size":"399109.9"}],"bid":[{"price":"0.615720","size":"11000.0"},{"price":"0.615679","size":"0"},{"price":"0.615673","size":"1591.5"}],"sequence":20584195,"timestamp":"2021-07-15T03:00:34.297Z","symbol":"XRPUSDT"}}
1626318034.369133: {"jsonrpc":"2.0","method":"updateOrderbook","params":{"ask":[{"price":"0.00000065973","size":"15232500"},{"price":"0.00000094571","size":"2770610"}],"bid":[],"sequence":10532382,"timestamp":"2021-07-15T03:00:34.257Z","symbol":"SCBTC"}}
1626318034.371739: {"jsonrpc":"2.0","method":"updateOrderbook","params":{"ask":[{"price":"0.00055054","size":"662.81"},{"price":"0.00055287","size":"0"}],"bid":[{"price":"0.00054530","size":"0"},{"price":"0.00054529","size":"5.18"},{"price":"0.00054490","size":"18.03"},{"price":"0.00054481","size":"0"}],"sequence":19513182,"timestamp":"2021-07-15T03:00:34.327Z","symbol":"UNIBTC"}}
1626318034.449234: {"jsonrpc":"2.0","method":"updateOrderbook","params":{"ask":[],"bid":[{"price":"12.103","size":"0"}],"sequence":2190718,"timestamp":"2021-07-15T03:00:34.437Z","symbol":"SPIUSD"}}
1626318034.473681: {"jsonrpc":"2.0","method":"updateOrderbook","params":{"ask":[{"price":"0.615785","size":"1331.7"},{"price":"0.615786","size":"0"},{"price":"0.662655","size":"399110.3"}],"bid":[{"price":"0.615686","size":"1591.5"},{"price":"0.615673","size":"0"},{"price":"0.615575","size":"0"},{"price":"0.615540","size":"2955.7"},{"price":"0.577301","size":"195374.1"},{"price":"0.574270","size":"0"}],"sequence":20584196,"timestamp":"2021-07-15T03:00:34.442Z","symbol":"XRPUSDT"}}
1626318034.473817: {"jsonrpc":"2.0","method":"updateOrderbook","params":{"ask":[{"price":"0.00000036725","size":"25530"},{"price":"0.00000036737","size":"101590"},{"price":"0.00000036761","size":"0"},{"price":"0.00000036826","size":"0"},{"price":"0.00000065973","size":"15232520"},{"price":"0.00000094571","size":"2770630"}],"bid":[],"sequence":10532383,"timestamp":"2021-07-15T03:00:34.373Z","symbol":"SCBTC"}}
1626318034.4738839: {"jsonrpc":"2.0","method":"updateOrderbook","params":{"ask":[{"price":"0.00054591","size":"0"},{"price":"0.00054603","size":"16.70"},{"price":"0.00054605","size":"0"},{"price":"0.00054619","size":"66.20"}],"bid":[{"price":"0.00054529","size":"0"},{"price":"0.00054527","size":"5.18"}],"sequence":19513183,"timestamp":"2021-07-15T03:00:34.369Z","symbol":"UNIBTC"}}
1626318034.563148: {"jsonrpc":"2.0","method":"updateOrderbook","params":{"ask":[],"bid":[{"price":"12.105","size":"5.8728"},{"price":"12.104","size":"0"},{"price":"12.060","size":"5.7399"}],"sequence":2190719,"timestamp":"2021-07-15T03:00:34.498Z","symbol":"SPIUSD"}}
1626318034.563272: {"jsonrpc":"2.0","method":"updateOrderbook","params":{"ask":[{"price":"0.615942","size":"0"},{"price":"0.616137","size":"10632.9"},{"price":"0.662655","size":"399110.5"}],"bid":[{"price":"0.615686","size":"0"},{"price":"0.615646","size":"1591.5"},{"price":"0.615318","size":"1337.0"},{"price":"0.615195","size":"0"},{"price":"0.614438","size":"1800.0"},{"price":"0.614368","size":"0"},{"price":"0.614346","size":"5500.0"},{"price":"0.614277","size":"0"},{"price":"0.614063","size":"7700.0"},{"price":"0.613962","size":"0"}],"sequence":20584197,"timestamp":"2021-07-15T03:00:34.508Z","symbol":"XRPUSDT"}}
1626318034.568924: {"jsonrpc":"2.0","method":"updateOrderbook","params":{"ask":[{"price":"0.00000065973","size":"15232540"},{"price":"0.00000094571","size":"2770650"}],"bid":[{"price":"0.00000036535","size":"0"},{"price":"0.00000036483","size":"1000"},{"price":"0.00000036426","size":"284390"},{"price":"0.00000036411","size":"384900"},{"price":"0.00000036388","size":"0"},{"price":"0.00000036342","size":"0"}],"sequence":10532384,"timestamp":"2021-07-15T03:00:34.508Z","symbol":"SCBTC"}}
1626318034.568971: {"jsonrpc":"2.0","method":"updateOrderbook","params":{"ask":[{"price":"0.00054556","size":"0"},{"price":"0.00054568","size":"4.33"},{"price":"0.00054582","size":"0"},{"price":"0.00054593","size":"10.47"},{"price":"0.00054620","size":"199.63"},{"price":"0.00054630","size":"296.51"},{"price":"0.00054635","size":"77.40"},{"price":"0.00054637","size":"0"},{"price":"0.00054638","size":"0"},{"price":"0.00054643","size":"0"},{"price":"0.00054662","size":"0"},{"price":"0.00054663","size":"201.47"},{"price":"0.00054666","size":"66.76"},{"price":"0.00055851","size":"0"},{"price":"0.00056018","size":"2539.46"},{"price":"0.00058935","size":"0"},{"price":"0.00059258","size":"2343.84"},{"price":"0.00078195","size":"0"},{"price":"0.00078338","size":"3484.36"}],"bid":[{"price":"0.00054532","size":"5.18"},{"price":"0.00054527","size":"0"},{"price":"0.00054478","size":"69.23"},{"price":"0.00054466","size":"0"},{"price":"0.00053467","size":"2974.71"},{"price":"0.00053387","size":"0"}],"sequence":19513184,"timestamp":"2021-07-15T03:00:34.534Z","symbol":"UNIBTC"}}
1626318034.655338: {"jsonrpc":"2.0","method":"updateOrderbook","params":{"ask":[],"bid":[{"price":"12.106","size":"5.7533"},{"price":"12.060","size":"0"}],"sequence":2190720,"timestamp":"2021-07-15T03:00:34.568Z","symbol":"SPIUSD"}}
1626318034.6553888: {"jsonrpc":"2.0","method":"updateOrderbook","params":{"ask":[{"price":"0.615779","size":"1331.6"},{"price":"0.615785","size":"0"},{"price":"0.615888","size":"0"},{"price":"0.615892","size":"10632.8"},{"price":"0.615893","size":"3215.5"},{"price":"0.616137","size":"0"},{"price":"0.616142","size":"5554.1"},{"price":"0.616151","size":"0"},{"price":"0.616263","size":"6528.5"},{"price":"0.616283","size":"0"},{"price":"0.616816","size":"0"},{"price":"0.616879","size":"5500.0"},{"price":"0.662655","size":"399110.7"}],"bid":[{"price":"0.615658","size":"1591.5"},{"price":"0.615646","size":"0"},{"price":"0.615318","size":"0"},{"price":"0.615317","size":"0"},{"price":"0.615293","size":"1337.0"},{"price":"0.615292","size":"5489.1"},{"price":"0.615181","size":"0"},{"price":"0.615170","size":"6463.5"}],"sequence":20584198,"timestamp":"2021-07-15T03:00:34.596Z","symbol":"XRPUSDT"}}
1626318034.6731038: {"jsonrpc":"2.0","method":"updateOrderbook","params":{"ask":[{"price":"0.00000065973","size":"15232550"},{"price":"0.00000094571","size":"2770670"}],"bid":[],"sequence":10532385,"timestamp":"2021-07-15T03:00:34.618Z","symbol":"SCBTC"}}
1626318034.673163: {"jsonrpc":"2.0","method":"updateOrderbook","params":{"ask":[{"price":"0.00054567","size":"4.33"},{"price":"0.00054568","size":"0"},{"price":"0.00054620","size":"0"},{"price":"0.00054630","size":"0"},{"price":"0.00054639","size":"0"},{"price":"0.00054650","size":"199.63"},{"price":"0.00054658","size":"18.08"},{"price":"0.00054671","size":"296.51"},{"price":"0.00054684","size":"0"},{"price":"0.00054720","size":"440.89"},{"price":"0.00054778","size":"0"},{"price":"0.00054826","size":"5223.74"}],"bid":[{"price":"0.00054540","size":"5.18"},{"price":"0.00054532","size":"0"}],"sequence":19513185,"timestamp":"2021-07-15T03:00:34.641Z","symbol":"UNIBTC"}}
1626318034.762557: {"jsonrpc":"2.0","method":"updateOrderbook","params":{"ask":[{"price":"0.615892","size":"0"},{"price":"0.616137","size":"10632.6"},{"price":"0.644533","size":"347706.3"},{"price":"0.646107","size":"0"},{"price":"0.662655","size":"399111.0"}],"bid":[{"price":"0.615116","size":"538.8"},{"price":"0.614883","size":"0"},{"price":"0.614346","size":"0"},{"price":"0.614284","size":"5500.0"}],"sequence":20584199,"timestamp":"2021-07-15T03:00:34.712Z","symbol":"XRPUSDT"}}
1626318034.766686: {"jsonrpc":"2.0","method":"updateOrderbook","params":{"ask":[{"price":"0.00000065973","size":"15232570"},{"price":"0.00000094571","size":"2770690"}],"bid":[],"sequence":10532386,"timestamp":"2021-07-15T03:00:34.723Z","symbol":"SCBTC"}}
1626318034.766728: {"jsonrpc":"2.0","method":"updateOrderbook","params":{"ask":[{"price":"0.00054567","size":"0"},{"price":"0.00054571","size":"4.33"},{"price":"0.00054594","size":"0"},{"price":"0.00054604","size":"17.11"},{"price":"0.00054611","size":"0"},{"price":"0.00054625","size":"16.96"},{"price":"0.00054819","size":"0"},{"price":"0.00054923","size":"658.12"},{"price":"0.00056018","size":"0"},{"price":"0.00056284","size":"2539.46"}],"bid":[{"price":"0.00054542","size":"5.18"},{"price":"0.00054540","size":"0"},{"price":"0.00054395","size":"650.72"},{"price":"0.00054368","size":"482.00"}],"sequence":19513186,"timestamp":"2021-07-15T03:00:34.731Z","symbol":"UNIBTC"}}
1626318034.8731: {"jsonrpc":"2.0","method":"updateOrderbook","params":{"ask":[{"price":"0.615892","size":"10632.5"},{"price":"0.616137","size":"0"},{"price":"0.662655","size":"399111.3"}],"bid":[],"sequence":20584200,"timestamp":"2021-07-15T03:00:34.793Z","symbol":"XRPUSDT"}}
1626318034.873164: {"jsonrpc":"2.0","method":"updateOrderbook","params":{"ask":[{"price":"0.00000036748","size":"255050"},{"price":"0.00000036787","size":"408320"},{"price":"0.00000036877","size":"0"},{"price":"0.00000036909","size":"0"},{"price":"0.00000065973","size":"15232580"},{"price":"0.00000094571","size":"2770710"}],"bid":[],"sequence":10532387,"timestamp":"2021-07-15T03:00:34.833Z","symbol":"SCBTC"}}
1626318034.8731918: {"jsonrpc":"2.0","method":"updateOrderbook","params":{"ask":[{"price":"0.00054571","size":"0"},{"price":"0.00054577","size":"4.33"},{"price":"0.00054593","size":"0"},{"price":"0.00054601","size":"10.47"},{"price":"0.00054604","size":"0"},{"price":"0.00054615","size":"17.11"},{"price":"0.00054692","size":"0"},{"price":"0.00054715","size":"193.61"},{"price":"0.00059258","size":"0"},{"price":"0.00059866","size":"2343.84"},{"price":"0.00078338","size":"0"},{"price":"0.00078605","size":"3484.36"}],"bid":[{"price":"0.00054545","size":"5.18"},{"price":"0.00054542","size":"0"},{"price":"0.00054523","size":"9.62"},{"price":"0.00054509","size":"0"},{"price":"0.00053467","size":"0"},{"price":"0.00053289","size":"2974.71"}],"sequence":19513187,"timestamp":"2021-07-15T03:00:34.819Z","symbol":"UNIBTC"}}
1626318034.956405: {"jsonrpc":"2.0","method":"updateOrderbook","params":{"ask":[{"price":"0.618240","size":"22946.4"},{"price":"0.619032","size":"0"},{"price":"0.662655","size":"399111.5"},{"price":"0.671039","size":"229002.7"},{"price":"0.684350","size":"0"},{"price":"0.847048","size":"324970.5"},{"price":"0.862547","size":"0"}],"bid":[],"sequence":20584201,"timestamp":"2021-07-15T03:00:34.941Z","symbol":"XRPUSDT"}}
1626318034.994564: {"jsonrpc":"2.0","method":"updateOrderbook","params":{"ask":[{"price":"0.00000065973","size":"0"},{"price":"0.00000065974","size":"15232600"},{"price":"0.00000094571","size":"2770730"}],"bid":[],"sequence":10532388,"timestamp":"2021-07-15T03:00:34.938Z","symbol":"SCBTC"}}
1626318034.994582: {"jsonrpc":"2.0","method":"updateOrderbook","params":{"ask":[{"price":"0.00054577","size":"0"},{"price":"0.00054582","size":"4.33"},{"price":"0.00054601","size":"0"},{"price":"0.00054603","size":"0"},{"price":"0.00054609","size":"10.47"},{"price":"0.00054615","size":"0"},{"price":"0.00054619","size":"0"},{"price":"0.00054624","size":"16.70"},{"price":"0.00054625","size":"34.07"},{"price":"0.00054635","size":"0"},{"price":"0.00054637","size":"66.20"},{"price":"0.00054647","size":"77.40"},{"price":"0.00054651","size":"0"},{"price":"0.00054673","size":"0"},{"price":"0.00054678","size":"218.78"},{"price":"0.00054694","size":"276.50"},{"price":"0.00054725","size":"0"},{"price":"0.00054736","size":"0"},{"price":"0.00054766","size":"0"},{"price":"0.00054777","size":"291.41"},{"price":"0.00054825","size":"375.71"},{"price":"0.00054879","size":"484.13"},{"price":"0.00054922","size":"0"},{"price":"0.00055059","size":"805.27"},{"price":"0.00055097","size":"0"},{"price":"0.00055157","size":"1244.50"},{"price":"0.00055241","size":"0"},{"price":"0.00055429","size":"0"},{"price":"0.00055557","size":"881.76"},{"price":"0.00056166","size":"1757.02"},{"price":"0.00059866","size":"0"},{"price":"0.00062612","size":"0"},{"price":"0.00066197","size":"2343.84"},{"price":"0.00067260","size":"1125.76"},{"price":"0.00078605","size":"0"},{"price":"0.00080159","size":"3484.36"},{"price":"0.00081742","size":"0"},{"price":"0.00082961","size":"1585.64"}],"bid":[{"price":"0.00054550","size":"5.18"},{"price":"0.00054545","size":"0"},{"price":"0.00054500","size":"18.03"},{"price":"0.00054490","size":"0"},{"price":"0.00054445","size":"177.91"},{"price":"0.00054409","size":"0"}],"sequence":19513188,"timestamp":"2021-07-15T03:00:34.942Z","symbol":"UNIBTC"}}
1626318035.0658429: {"jsonrpc":"2.0","method":"updateOrderbook","params":{"ask":[{"price":"0.662655","size":"399111.7"}],"bid":[],"sequence":20584202,"timestamp":"2021-07-15T03:00:34.947Z","symbol":"XRPUSDT"}}
1626318035.067903: {"jsonrpc":"2.0","method":"updateOrderbook","params":{"ask":[{"price":"0.00054647","size":"0"},{"price":"0.00054666","size":"144.16"},{"price":"0.00054715","size":"0"},{"price":"0.00054734","size":"193.61"},{"price":"0.00056166","size":"0"},{"price":"0.00056230","size":"1757.02"},{"price":"0.00066197","size":"0"},{"price":"0.00066759","size":"2343.84"}],"bid":[{"price":"0.00054489","size":"80.24"},{"price":"0.00054464","size":"17.87"},{"price":"0.00054457","size":"0"},{"price":"0.00054429","size":"0"},{"price":"0.00053289","size":"0"},{"price":"0.00053181","size":"2974.71"}],"sequence":19513189,"timestamp":"2021-07-15T03:00:35.038Z","symbol":"UNIBTC"}}
1626318035.1671581: {"jsonrpc":"2.0","method":"updateOrderbook","params":{"ask":[{"price":"0.662655","size":"399112.0"}],"bid":[],"sequence":20584203,"timestamp":"2021-07-15T03:00:35.052Z","symbol":"XRPUSDT"}}
1626318035.171573: {"jsonrpc":"2.0","method":"updateOrderbook","params":{"ask":[{"price":"0.00000065974","size":"15232620"},{"price":"0.00000094571","size":"2770750"}],"bid":[],"sequence":10532389,"timestamp":"2021-07-15T03:00:35.044Z","symbol":"SCBTC"}}
1626318035.1716118: {"jsonrpc":"2.0","method":"updateOrderbook","params":{"ask":[{"price":"0.00054582","size":"0"},{"price":"0.00054590","size":"4.33"},{"price":"0.00054610","size":"0"},{"price":"0.00054625","size":"17.11"},{"price":"0.00054644","size":"16.96"},{"price":"0.00054649","size":"0"},{"price":"0.00054650","size":"218.51"},{"price":"0.00054663","size":"219.66"},{"price":"0.00054666","size":"77.40"},{"price":"0.00054685","size":"400.60"}],"bid":[{"price":"0.00054550","size":"0"},{"price":"0.00054546","size":"5.18"}],"sequence":19513190,"timestamp":"2021-07-15T03:00:35.135Z","symbol":"UNIBTC"}}
1626318035.268756: {"jsonrpc":"2.0","method":"updateOrderbook","params":{"ask":[],"bid":[{"price":"12.107","size":"5.8718"},{"price":"12.105","size":"0"}],"sequence":2190721,"timestamp":"2021-07-15T03:00:35.229Z","symbol":"SPIUSD"}}
1626318035.268885: {"jsonrpc":"2.0","method":"updateOrderbook","params":{"ask":[{"price":"0.662655","size":"399112.4"}],"bid":[{"price":"0.615667","size":"1591.5"},{"price":"0.615658","size":"0"}],"sequence":20584204,"timestamp":"2021-07-15T03:00:35.202Z","symbol":"XRPUSDT"}}
1626318035.2689111: {"jsonrpc":"2.0","method":"updateOrderbook","params":{"ask":[{"price":"0.00000065974","size":"15232630"},{"price":"0.00000094571","size":"2770770"}],"bid":[],"sequence":10532390,"timestamp":"2021-07-15T03:00:35.149Z","symbol":"SCBTC"}}
1626318035.26893: {"jsonrpc":"2.0","method":"updateOrderbook","params":{"ask":[{"price":"0.00054590","size":"0"},{"price":"0.00054592","size":"4.33"},{"price":"0.00054609","size":"0"},{"price":"0.00054618","size":"10.47"}],"bid":[{"price":"0.00054550","size":"5.18"},{"price":"0.00054546","size":"0"},{"price":"0.00054498","size":"18.61"},{"price":"0.00054486","size":"0"},{"price":"0.00054336","size":"929.35"},{"price":"0.00054312","size":"0"},{"price":"0.00054270","size":"0"},{"price":"0.00054263","size":"634.39"},{"price":"0.00053181","size":"0"},{"price":"0.00052751","size":"2974.71"}],"sequence":19513191,"timestamp":"2021-07-15T03:00:35.231Z","symbol":"UNIBTC"}}
1626318035.3891451: {"jsonrpc":"2.0","method":"updateOrderbook","params":{"ask":[],"bid":[{"price":"12.108","size":"5.7667"},{"price":"12.106","size":"0"}],"sequence":2190722,"timestamp":"2021-07-15T03:00:35.304Z","symbol":"SPIUSD"}}
1626318035.389271: {"jsonrpc":"2.0","method":"updateOrderbook","params":{"ask":[{"price":"0.662655","size":"399112.6"}],"bid":[],"sequence":20584205,"timestamp":"2021-07-15T03:00:35.277Z","symbol":"XRPUSDT"}}
1626318035.3892941: {"jsonrpc":"2.0","method":"updateOrderbook","params":{"ask":[{"price":"0.00000065974","size":"15232650"},{"price":"0.00000094571","size":"2770790"}],"bid":[],"sequence":10532391,"timestamp":"2021-07-15T03:00:35.264Z","symbol":"SCBTC"}}
1626318035.389313: {"jsonrpc":"2.0","method":"updateOrderbook","params":{"ask":[{"price":"0.00054592","size":"0"},{"price":"0.00054597","size":"4.33"},{"price":"0.00054671","size":"0"},{"price":"0.00054685","size":"66.76"},{"price":"0.00054694","size":"573.01"},{"price":"0.00054720","size":"0"},{"price":"0.00054725","size":"333.84"},{"price":"0.00054738","size":"0"},{"price":"0.00054764","size":"440.89"},{"price":"0.00054826","size":"4926.48"},{"price":"0.00054910","size":"963.50"},{"price":"0.00054920","size":"0"},{"price":"0.00055005","size":"1302.32"}],"bid":[{"price":"0.00054553","size":"5.18"},{"price":"0.00054550","size":"0"},{"price":"0.00054509","size":"18.03"},{"price":"0.00054500","size":"0"},{"price":"0.00054474","size":"196.86"},{"price":"0.00054436","size":"0"}],"sequence":19513192,"timestamp":"2021-07-15T03:00:35.341Z","symbol":"UNIBTC"}}
1626318035.4666922: {"jsonrpc":"2.0","method":"updateOrderbook","params":{"ask":[{"price":"0.615765","size":"11000.0"},{"price":"0.662655","size":"399112.9"},{"price":"0.701117","size":"228479.7"}],"bid":[{"price":"0.615720","size":"0"},{"price":"0.615293","size":"0"},{"price":"0.615195","size":"1337.0"}],"sequence":20584206,"timestamp":"2021-07-15T03:00:35.412Z","symbol":"XRPUSDT"}}
1626318035.46678: {"jsonrpc":"2.0","method":"updateOrderbook","params":{"ask":[{"price":"0.00000036911","size":"603920"},{"price":"0.00000037466","size":"661850"},{"price":"0.00000037986","size":"0"},{"price":"0.00000041211","size":"4600"},{"price":"0.00000065974","size":"15232670"},{"price":"0.00000094571","size":"2770820"}],"bid":[{"price":"0.00000036265","size":"1248220"},{"price":"0.00000036210","size":"0"}],"sequence":10532392,"timestamp":"2021-07-15T03:00:35.439Z","symbol":"SCBTC"}}
1626318035.4668002: {"jsonrpc":"2.0","method":"updateOrderbook","params":{"ask":[{"price":"0.00054594","size":"4.33"},{"price":"0.00054597","size":"0"},{"price":"0.00054755","size":"0"},{"price":"0.00054826","size":"997.64"},{"price":"0.00054873","size":"4260.24"}],"bid":[{"price":"0.00054553","size":"0"},{"price":"0.00054547","size":"5.18"},{"price":"0.00054432","size":"269.93"},{"price":"0.00054395","size":"380.79"},{"price":"0.00054263","size":"0"},{"price":"0.00054222","size":"634.39"},{"price":"0.00052751","size":"0"},{"price":"0.00052358","size":"2974.71"}],"sequence":19513193,"timestamp":"2021-07-15T03:00:35.441Z","symbol":"UNIBTC"}}
1626318035.5665128: {"jsonrpc":"2.0","method":"updateOrderbook","params":{"ask":[{"price":"0.615772","size":"1331.6"},{"price":"0.615779","size":"0"},{"price":"0.662655","size":"399113.3"}],"bid":[{"price":"0.615569","size":"2955.7"},{"price":"0.615540","size":"0"}],"sequence":20584207,"timestamp":"2021-07-15T03:00:35.543Z","symbol":"XRPUSDT"}}
1626318035.5707672: {"jsonrpc":"2.0","method":"updateOrderbook","params":{"ask":[{"price":"0.00000065974","size":"15232690"},{"price":"0.00000094571","size":"2770830"}],"bid":[],"sequence":10532393,"timestamp":"2021-07-15T03:00:35.528Z","symbol":"SCBTC"}}
1626318035.570807: {"jsonrpc":"2.0","method":"updateOrderbook","params":{"ask":[{"price":"0.00054658","size":"0"},{"price":"0.00054690","size":"18.08"}],"bid":[{"price":"0.00054320","size":"1215.25"},{"price":"0.00054209","size":"0"},{"price":"0.00052358","size":"0"},{"price":"0.00052259","size":"2974.71"}],"sequence":19513194,"timestamp":"2021-07-15T03:00:35.538Z","symbol":"UNIBTC"}}
1626318035.668898: {"jsonrpc":"2.0","method":"updateOrderbook","params":{"ask":[{"price":"0.615765","size":"0"},{"price":"0.615772","size":"0"},{"price":"0.615780","size":"1331.6"},{"price":"0.662655","size":"399113.6"}],"bid":[{"price":"0.615709","size":"11000.0"},{"price":"0.615667","size":"0"},{"price":"0.615657","size":"1591.5"},{"price":"0.615293","size":"1337.0"},{"price":"0.615195","size":"0"}],"sequence":20584208,"timestamp":"2021-07-15T03:00:35.641Z","symbol":"XRPUSDT"}}
1626318035.671596: {"jsonrpc":"2.0","method":"updateOrderbook","params":{"ask":[{"price":"0.00000037466","size":"0"},{"price":"0.00000037510","size":"661850"},{"price":"0.00000065974","size":"15232700"},{"price":"0.00000094571","size":"2770850"}],"bid":[{"price":"0.00000036497","size":"110390"},{"price":"0.00000036482","size":"0"}],"sequence":10532394,"timestamp":"2021-07-15T03:00:35.614Z","symbol":"SCBTC"}}
1626318035.671654: {"jsonrpc":"2.0","method":"updateOrderbook","params":{"ask":[{"price":"0.00054588","size":"4.33"},{"price":"0.00054594","size":"0"}],"bid":[{"price":"0.00054534","size":"18.34"},{"price":"0.00054514","size":"18.61"},{"price":"0.00054498","size":"0"},{"price":"0.00054476","size":"0"},{"price":"0.00054441","size":"239.72"},{"price":"0.00054390","size":"0"},{"price":"0.00054388","size":"346.03"},{"price":"0.00054345","size":"1010.75"},{"price":"0.00052259","size":"0"},{"price":"0.00052065","size":"2974.71"}],"sequence":19513195,"timestamp":"2021-07-15T03:00:35.614Z","symbol":"UNIBTC"}}
1626318035.758513: {"jsonrpc":"2.0","method":"updateOrderbook","params":{"ask":[{"price":"0.662655","size":"399113.7"}],"bid":[],"sequence":20584209,"timestamp":"2021-07-15T03:00:35.683Z","symbol":"XRPUSDT"}}
1626318035.773052: {"jsonrpc":"2.0","method":"updateOrderbook","params":{"ask":[{"price":"0.00000065974","size":"15232720"},{"price":"0.00000094571","size":"2770870"}],"bid":[{"price":"0.00000036498","size":"1000"},{"price":"0.00000036483","size":"0"}],"sequence":10532395,"timestamp":"2021-07-15T03:00:35.720Z","symbol":"SCBTC"}}
1626318035.773082: {"jsonrpc":"2.0","method":"updateOrderbook","params":{"ask":[{"price":"0.00054712","size":"0"},{"price":"0.00054756","size":"250.69"}],"bid":[],"sequence":19513196,"timestamp":"2021-07-15T03:00:35.668Z","symbol":"UNIBTC"}}
1626318035.867004: {"jsonrpc":"2.0","method":"updateOrderbook","params":{"ask":[{"price":"0.662655","size":"399114.0"}],"bid":[],"sequence":20584210,"timestamp":"2021-07-15T03:00:35.783Z","symbol":"XRPUSDT"}}
1626318035.867059: {"jsonrpc":"2.0","method":"updateOrderbook","params":{"ask":[{"price":"0.00000041405","size":"1016210"},{"price":"0.00000042829","size":"0"},{"price":"0.00000044445","size":"10293110"},{"price":"0.00000060970","size":"0"},{"price":"0.00000065974","size":"15232730"},{"price":"0.00000094571","size":"2770890"}],"bid":[{"price":"0.00000034003","size":"0"}],"sequence":10532396,"timestamp":"2021-07-15T03:00:35.838Z","symbol":"SCBTC"}}
1626318035.873815: {"jsonrpc":"2.0","method":"updateOrderbook","params":{"ask":[{"price":"0.00054586","size":"4.33"},{"price":"0.00054588","size":"0"},{"price":"0.00054610","size":"10.47"},{"price":"0.00054613","size":"16.70"},{"price":"0.00054618","size":"0"},{"price":"0.00054624","size":"0"},{"price":"0.00054867","size":"0"},{"price":"0.00054910","size":"1550.86"},{"price":"0.00055054","size":"0"},{"price":"0.00055288","size":"662.81"},{"price":"0.00055557","size":"0"},{"price":"0.00057411","size":"881.76"},{"price":"0.00066759","size":"0"},{"price":"0.00067076","size":"2343.84"},{"price":"0.00067260","size":"0"},{"price":"0.00075423","size":"1125.76"},{"price":"0.00080159","size":"0"},{"price":"0.00080246","size":"3484.36"},{"price":"0.00082961","size":"0"},{"price":"0.00084103","size":"1585.64"}],"bid":[{"price":"0.00054549","size":"5.18"},{"price":"0.00054547","size":"0"}],"sequence":19513197,"timestamp":"2021-07-15T03:00:35.809Z","symbol":"UNIBTC"}}
1626318035.950332: {"jsonrpc":"2.0","method":"updateOrderbook","params":{"ask":[],"bid":[{"price":"12.107","size":"0"}],"sequence":2190723,"timestamp":"2021-07-15T03:00:35.888Z","symbol":"SPIUSD"}}
1626318035.954813: {"jsonrpc":"2.0","method":"updateOrderbook","params":{"ask":[{"price":"0.615780","size":"0"},{"price":"0.615788","size":"1331.6"},{"price":"0.662655","size":"399114.4"}],"bid":[{"price":"0.615663","size":"1591.5"},{"price":"0.615657","size":"0"}],"sequence":20584211,"timestamp":"2021-07-15T03:00:35.937Z","symbol":"XRPUSDT"}}
1626318035.977615: {"jsonrpc":"2.0","method":"updateOrderbook","params":{"ask":[{"price":"0.00000036816","size":"0"},{"price":"0.00000036828","size":"26770"},{"price":"0.00000043091","size":"0"},{"price":"0.00000043194","size":"522810"},{"price":"0.00000044445","size":"8911260"},{"price":"0.00000044488","size":"1381850"},{"price":"0.00000054523","size":"0"},{"price":"0.00000054577","size":"757990"},{"price":"0.00000065974","size":"15232750"},{"price":"0.00000078071","size":"0"},{"price":"0.00000078139","size":"2003810"},{"price":"0.00000094571","size":"2770910"},{"price":"0.00000095824","size":"0"},{"price":"0.00000095882","size":"2754880"},{"price":"0.00000284543","size":"0"},{"price":"0.00000284830","size":"4472830"}],"bid":[{"price":"0.00000034004","size":"0"},{"price":"0.00000033944","size":"234600"},{"price":"0.00000032343","size":"1993120"},{"price":"0.00000023946","size":"0"},{"price":"0.00000004529","size":"2752080"},{"price":"0.00000000735","size":"0"}],"sequence":10532397,"timestamp":"2021-07-15T03:00:35.929Z","symbol":"SCBTC"}}
1626318035.977692: {"jsonrpc":"2.0","method":"updateOrderbook","params":{"ask":[],"bid":[{"price":"0.00054551","size":"5.18"},{"price":"0.00054549","size":"0"},{"price":"0.00054506","size":"18.58"},{"price":"0.00054503","size":"69.23"},{"price":"0.00054490","size":"72.79"},{"price":"0.00054478","size":"0"},{"price":"0.00054467","size":"0"},{"price":"0.00054451","size":"0"}],"sequence":19513198,"timestamp":"2021-07-15T03:00:35.912Z","symbol":"UNIBTC"}}
1626318036.05377: {"jsonrpc":"2.0","method":"updateOrderbook","params":{"ask":[],"bid":[{"price":"12.109","size":"5.8708"},{"price":"12.108","size":"0"},{"price":"12.060","size":"5.7745"}],"sequence":2190724,"timestamp":"2021-07-15T03:00:35.972Z","symbol":"SPIUSD"}}
1626318036.0538208: {"jsonrpc":"2.0","method":"updateOrderbook","params":{"ask":[{"price":"0.620782","size":"0"},{"price":"0.620879","size":"483.1"},{"price":"0.662655","size":"399114.6"}],"bid":[],"sequence":20584212,"timestamp":"2021-07-15T03:00:36.007Z","symbol":"XRPUSDT"}}
1626318036.0732899: {"jsonrpc":"2.0","method":"updateOrderbook","params":{"ask":[{"price":"0.00000065974","size":"15232760"},{"price":"0.00000094571","size":"2770930"}],"bid":[],"sequence":10532398,"timestamp":"2021-07-15T03:00:36.039Z","symbol":"SCBTC"}}
1626318036.073306: {"jsonrpc":"2.0","method":"updateOrderbook","params":{"ask":[{"price":"0.00054840","size":"658.12"},{"price":"0.00054923","size":"0"}],"bid":[{"price":"0.00054474","size":"0"},{"price":"0.00054453","size":"196.86"}],"sequence":19513199,"timestamp":"2021-07-15T03:00:35.969Z","symbol":"UNIBTC"}}
1626318036.151351: {"jsonrpc":"2.0","method":"updateOrderbook","params":{"ask":[],"bid":[{"price":"12.110","size":"5.7773"},{"price":"12.060","size":"0"}],"sequence":2190725,"timestamp":"2021-07-15T03:00:36.090Z","symbol":"SPIUSD"}}
1626318036.1573539: {"jsonrpc":"2.0","method":"updateOrderbook","params":{"ask":[{"price":"0.615892","size":"0"},{"price":"0.616137","size":"10632.6"},{"price":"0.662655","size":"399115.0"}],"bid":[{"price":"0.615671","size":"1591.5"},{"price":"0.615663","size":"0"}],"sequence":20584213,"timestamp":"2021-07-15T03:00:36.128Z","symbol":"XRPUSDT"}}
1626318036.164224: {"jsonrpc":"2.0","method":"updateOrderbook","params":{"ask":[{"price":"0.00000065974","size":"15232780"},{"price":"0.00000094571","size":"2770940"}],"bid":[],"sequence":10532399,"timestamp":"2021-07-15T03:00:36.144Z","symbol":"SCBTC"}}
1626318036.164247: {"jsonrpc":"2.0","method":"updateOrderbook","params":{"ask":[{"price":"0.00054646","size":"296.51"},{"price":"0.00054694","size":"276.50"}],"bid":[{"price":"0.00054267","size":"1587.01"},{"price":"0.00054166","size":"0"}],"sequence":19513200,"timestamp":"2021-07-15T03:00:36.064Z","symbol":"UNIBTC"}}
1626318036.277338: {"jsonrpc":"2.0","method":"updateOrderbook","params":{"ask":[{"price":"0.662655","size":"399115.1"}],"bid":[{"price":"0.614367","size":"5500.0"},{"price":"0.614284","size":"0"}],"sequence":20584214,"timestamp":"2021-07-15T03:00:36.185Z","symbol":"XRPUSDT"}}
1626318036.277364: {"jsonrpc":"2.0","method":"updateOrderbook","params":{"ask":[{"price":"0.00000094571","size":"2770950"}],"bid":[],"sequence":10532400,"timestamp":"2021-07-15T03:00:36.149Z","symbol":"SCBTC"}}
1626318036.277372: {"jsonrpc":"2.0","method":"updateOrderbook","params":{"ask":[],"bid":[{"price":"0.00054552","size":"5.18"},{"price":"0.00054551","size":"0"}],"sequence":19513201,"timestamp":"2021-07-15T03:00:36.238Z","symbol":"UNIBTC"}}
1626318036.3584561: {"jsonrpc":"2.0","method":"updateOrderbook","params":{"ask":[{"price":"0.615788","size":"0"},{"price":"0.615797","size":"1331.6"},{"price":"0.616906","size":"0"},{"price":"0.616976","size":"6433.6"},{"price":"0.617284","size":"0"},{"price":"0.617459","size":"4276.9"},{"price":"0.617687","size":"0"},{"price":"0.617880","size":"12316.2"},{"price":"0.627015","size":"129038.8"},{"price":"0.633757","size":"0"},{"price":"0.644533","size":"0"},{"price":"0.646630","size":"347706.3"},{"price":"0.651679","size":"181214.3"},{"price":"0.657613","size":"0"},{"price":"0.662655","size":"399115.4"}],"bid":[],"sequence":20584215,"timestamp":"2021-07-15T03:00:36.287Z","symbol":"XRPUSDT"}}
1626318036.370998: {"jsonrpc":"2.0","method":"updateOrderbook","params":{"ask":[{"price":"0.00000065974","size":"15232810"},{"price":"0.00000090036","size":"2001500"},{"price":"0.00000094571","size":"2770980"},{"price":"0.00000106078","size":"0"},{"price":"0.00000124824","size":"2705250"},{"price":"0.00000131433","size":"0"}],"bid":[],"sequence":10532401,"timestamp":"2021-07-15T03:00:36.343Z","symbol":"SCBTC"}}
1626318036.371041: {"jsonrpc":"2.0","method":"updateOrderbook","params":{"ask":[{"price":"0.00054586","size":"0"},{"price":"0.00054588","size":"4.33"},{"price":"0.00054646","size":"0"},{"price":"0.00054690","size":"314.59"},{"price":"0.00054826","size":"666.24"},{"price":"0.00054961","size":"331.40"},{"price":"0.00054992","size":"0"},{"price":"0.00055057","size":"433.80"},{"price":"0.00055288","size":"0"},{"price":"0.00055404","size":"662.81"},{"price":"0.00057411","size":"0"},{"price":"0.00060060","size":"881.76"},{"price":"0.00075423","size":"0"},{"price":"0.00078640","size":"1125.76"},{"price":"0.00084103","size":"0"}],"bid":[{"price":"0.00054555","size":"5.18"},{"price":"0.00054552","size":"0"}],"sequence":19513202,"timestamp":"2021-07-15T03:00:36.329Z","symbol":"UNIBTC"}}
1626318036.470887: {"jsonrpc":"2.0","method":"updateOrderbook","params":{"ask":[{"price":"0.615797","size":"0"},{"price":"0.615859","size":"1331.6"},{"price":"0.615893","size":"0"},{"price":"0.615956","size":"3215.5"},{"price":"0.619854","size":"64176.0"},{"price":"0.620909","size":"0"},{"price":"0.627015","size":"0"},{"price":"0.629095","size":"129038.8"},{"price":"0.651679","size":"0"},{"price":"0.653682","size":"181214.3"},{"price":"0.662655","size":"399115.8"},{"price":"0.701117","size":"0"}],"bid":[{"price":"0.615737","size":"1591.5"},{"price":"0.615671","size":"0"},{"price":"0.615339","size":"1337.0"},{"price":"0.615293","size":"0"}],"sequence":20584216,"timestamp":"2021-07-15T03:00:36.429Z","symbol":"XRPUSDT"}}
1626318036.471029: {"jsonrpc":"2.0","method":"updateOrderbook","params":{"ask":[{"price":"0.00000065974","size":"15232820"},{"price":"0.00000094571","size":"2770990"},{"price":"0.00000096947","size":"3422070"},{"price":"0.00000097026","size":"0"}],"bid":[{"price":"0.00000036497","size":"0"},{"price":"0.00000036485","size":"110390"},{"price":"0.00000032343","size":"0"},{"price":"0.00000032019","size":"1993120"},{"price":"0.00000004529","size":"0"},{"price":"0.00000004273","size":"2752080"}],"sequence":10532402,"timestamp":"2021-07-15T03:00:36.399Z","symbol":"SCBTC"}}
1626318036.471061: {"jsonrpc":"2.0","method":"updateOrderbook","params":{"ask":[{"price":"0.00054661","size":"66.76"},{"price":"0.00054685","size":"0"}],"bid":[{"price":"0.00054555","size":"0"},{"price":"0.00054550","size":"5.18"},{"price":"0.00052065","size":"0"},{"price":"0.00051929","size":"2974.71"}],"sequence":19513203,"timestamp":"2021-07-15T03:00:36.441Z","symbol":"UNIBTC"}}
