1626318013.596535: {"jsonrpc":"2.0","method":"snapshotOrderbook","params":{"ask":[{"price":"0.002350","size":"10500.0"},{"price":"0.002368","size":"2.2"},{"price":"0.002377","size":"0.1"},{"price":"0.002379","size":"75412.0"},{"price":"0.002381","size":"7.7"},{"price":"0.002388","size":"4.0"},{"price":"0.002394","size":"1.9"},{"price":"0.002395","size":"2.4"},{"price":"0.002398","size":"1.6"},{"price":"0.002399","size":"0.5"},{"price":"0.002400","size":"2.4"},{"price":"0.002410","size":"1.2"},{"price":"0.002411","size":"1.8"},{"price":"0.002415","size":"107528.0"},{"price":"0.002437","size":"0.1"},{"price":"0.002448","size":"142992.0"},{"price":"0.002472","size":"0.4"},{"price":"0.002475","size":"0.3"},{"price":"0.002476","size":"2.4"},{"price":"0.002484","size":"158007.0"},{"price":"0.002505","size":"148735.0"},{"price":"0.002506","size":"5.8"},{"price":"0.002528","size":"6.0"},{"price":"0.002540","size":"138343.0"},{"price":"0.002552","size":"5.9"},{"price":"0.002575","size":"129277.0"},{"price":"0.002582","size":"14.7"},{"price":"0.002605","size":"3.0"},{"price":"0.002611","size":"125314.0"},{"price":"0.002636","size":"14.9"},{"price":"0.002647","size":"118292.0"},{"price":"0.002649","size":"1.2"},{"price":"0.002652","size":"0.6"},{"price":"0.002654","size":"0.7"},{"price":"0.002655","size":"0.6"},{"price":"0.002660","size":"2.1"},{"price":"0.002662","size":"2.3"},{"price":"0.002667","size":"1.3"},{"price":"0.002668","size":"1.5"},{"price":"0.002670","size":"5.9"},{"price":"0.002673","size":"1.4"},{"price":"0.002691","size":"1.2"},{"price":"0.002705","size":"11.7"},{"price":"0.002714","size":"113803.0"},{"price":"0.002719","size":"13000.0"},{"price":"0.002737","size":"8.8"},{"price":"0.002744","size":"1.1"},{"price":"0.002758","size":"1.2"},{"price":"0.002768","size":"2.0"},{"price":"0.002769","size":"2.0"},{"price":"0.002770","size":"2.1"},{"price":"0.002779","size":"16117.0"},{"price":"0.002781","size":"17.5"},{"price":"0.002785","size":"112310.0"},{"price":"0.002801","size":"1.7"},{"price":"0.002805","size":"1.5"},{"price":"0.002808","size":"0.9"},{"price":"0.002813","size":"0.9"},{"price":"0.002815","size":"1.4"},{"price":"0.002816","size":"0.9"},{"price":"0.002817","size":"0.5"},{"price":"0.002818","size":"0.1"},{"price":"0.002822","size":"0.8"},{"price":"0.002828","size":"0.3"},{"price":"0.002831","size":"15.2"},{"price":"0.002845","size":"0.3"},{"price":"0.002862","size":"111635.0"},{"price":"0.002900","size":"20.5"},{"price":"0.002920","size":"110394.0"},{"price":"0.002947","size":"8000.0"},{"price":"0.002973","size":"20.5"},{"price":"0.002980","size":"734.8"},{"price":"0.003007","size":"104608.0"},{"price":"0.003009","size":"41.0"},{"price":"0.003084","size":"20.5"},{"price":"0.003100","size":"97965.0"},{"price":"0.003133","size":"61.5"},{"price":"0.003199","size":"95642.0"},{"price":"0.003217","size":"61.5"},{"price":"0.003304","size":"93589.0"},{"price":"0.003328","size":"82.0"},{"price":"0.003387","size":"9000.0"},{"price":"0.003416","size":"91455.0"},{"price":"0.003443","size":"61.5"},{"price":"0.003535","size":"87866.0"},{"price":"0.003562","size":"41.0"},{"price":"0.003614","size":"20.5"},{"price":"0.003647","size":"7500.0"},{"price":"0.003662","size":"86245.0"},{"price":"0.003684","size":"41.0"},{"price":"0.003687","size":"7500.0"},{"price":"0.003700","size":"43636.9"},{"price":"0.003701","size":"2.0"},{"price":"0.003772","size":"9.0"},{"price":"0.003800","size":"18.0"},{"price":"0.003854","size":"35.9"},{"price":"0.003906","size":"9.0"},{"price":"0.003951","size":"31.4"},{"price":"0.004001","size":"27.0"},{"price":"0.004095","size":"49.3"},{"price":"0.004165","size":"34.0"},{"price":"0.004193","size":"3232.1"},{"price":"0.004223","size":"9.4"},{"price":"0.004276","size":"52.0"},{"price":"0.004300","size":"1393.3"},{"price":"0.004355","size":"29.4"},{"price":"0.004429","size":"29.5"},{"price":"0.004439","size":"2495.0"},{"price":"0.004500","size":"450.0"},{"price":"0.004510","size":"22.2"},{"price":"0.004580","size":"52.5"},{"price":"0.004693","size":"29.0"},{"price":"0.004740","size":"150.8"},{"price":"0.004765","size":"14.7"},{"price":"0.004849","size":"78.3"},{"price":"0.004927","size":"17.0"},{"price":"0.005025","size":"45.3"},{"price":"0.005099","size":"1321.6"},{"price":"0.005100","size":"13500.0"},{"price":"0.005117","size":"16.7"},{"price":"0.005192","size":"26.5"},{"price":"0.005270","size":"44.1"},{"price":"0.005391","size":"27.6"},{"price":"0.005498","size":"39.3"},{"price":"0.005648","size":"70.1"},{"price":"0.005808","size":"22.7"},{"price":"0.005870","size":"3274.0"},{"price":"0.005917","size":"38.2"},{"price":"0.006000","size":"54750.0"},{"price":"0.006016","size":"52.1"},{"price":"0.006150","size":"3274.0"},{"price":"0.006164","size":"32.1"},{"price":"0.006305","size":"50.5"},{"price":"0.006445","size":"12.7"},{"price":"0.006500","size":"499.0"},{"price":"0.006576","size":"52.8"},{"price":"0.006750","size":"39.3"},{"price":"0.006922","size":"62.1"},{"price":"0.007114","size":"95.4"},{"price":"0.007209","size":"0.1"},{"price":"0.007466","size":"62.8"},{"price":"0.007646","size":"52.6"},{"price":"0.007854","size":"3880.2"},{"price":"0.007887","size":"38.8"},{"price":"0.008000","size":"646.0"},{"price":"0.008041","size":"31.9"},{"price":"0.008200","size":"249.0"},{"price":"0.008205","size":"56.6"},{"price":"0.008300","size":"20000.0"},{"price":"0.008387","size":"13.5"},{"price":"0.008565","size":"68.1"},{"price":"0.008600","size":"7800.0"},{"price":"0.008900","size":"200.0"},{"price":"0.008917","size":"73.5"},{"price":"0.009000","size":"50.0"},{"price":"0.009193","size":"60.9"},{"price":"0.009209","size":"0.1"},{"price":"0.009400","size":"1400.0"},{"price":"0.009419","size":"50.6"},{"price":"0.009632","size":"13.5"},{"price":"0.009824","size":"39.5"},{"price":"0.009942","size":"3.6"},{"price":"0.010010","size":"5295.0"},{"price":"0.010040","size":"32.1"},{"price":"0.010100","size":"1.0"},{"price":"0.010200","size":"1.0"},{"price":"0.010249","size":"63.1"},{"price":"0.010300","size":"1.0"},{"price":"0.010501","size":"1.0"},{"price":"0.010601","size":"1.0"},{"price":"0.010699","size":"80.7"},{"price":"0.010701","size":"1.0"},{"price":"0.010801","size":"1.0"},{"price":"0.010901","size":"1.0"},{"price":"0.011000","size":"200.0"},{"price":"0.011001","size":"1.0"},{"price":"0.011101","size":"1.0"},{"price":"0.011111","size":"76.7"},{"price":"0.011201","size":"1.0"},{"price":"0.011301","size":"1.0"},{"price":"0.011357","size":"101651.1"},{"price":"0.011401","size":"1.0"},{"price":"0.011482","size":"28.2"},{"price":"0.011501","size":"1.0"},{"price":"0.011600","size":"109.0"},{"price":"0.011601","size":"1.0"},{"price":"0.011701","size":"1.0"},{"price":"0.011757","size":"40.8"},{"price":"0.011800","size":"100.0"},{"price":"0.011801","size":"1.0"},{"price":"0.011901","size":"1.0"},{"price":"0.012000","size":"1500.0"},{"price":"0.012001","size":"1.0"},{"price":"0.012053","size":"55.6"},{"price":"0.012057","size":"133.3"},{"price":"0.012101","size":"1.0"},{"price":"0.012200","size":"100.0"},{"price":"0.012201","size":"1.0"},{"price":"0.012443","size":"80.8"},{"price":"0.012500","size":"100.0"},{"price":"0.012767","size":"10.0"},{"price":"0.012936","size":"66.6"},{"price":"0.013000","size":"19655.3"},{"price":"0.013134","size":"123.9"},{"price":"0.013200","size":"100.0"},{"price":"0.013209","size":"0.1"},{"price":"0.013454","size":"80.6"},{"price":"0.013600","size":"100.0"},{"price":"0.013800","size":"100.0"},{"price":"0.014000","size":"195625.3"},{"price":"0.014006","size":"41.2"},{"price":"0.014200","size":"100.0"},{"price":"0.014286","size":"123.9"},{"price":"0.014398","size":"80.3"},{"price":"0.014500","size":"100.0"},{"price":"0.014994","size":"3.7"},{"price":"0.015000","size":"2848.0"},{"price":"0.015273","size":"130.7"},{"price":"0.015438","size":"124.0"},{"price":"0.015996","size":"65.9"},{"price":"0.016590","size":"123.9"},{"price":"0.016635","size":"107.8"},{"price":"0.017407","size":"20.9"},{"price":"0.017742","size":"123.9"},{"price":"0.018000","size":"80000.0"},{"price":"0.018139","size":"157.5"},{"price":"0.018894","size":"124.0"},{"price":"0.019211","size":"100.5"},{"price":"0.020000","size":"5445.0"},{"price":"0.020046","size":"127.5"},{"price":"0.020224","size":"49.9"},{"price":"0.021000","size":"1000.0"},{"price":"0.021176","size":"91.6"},{"price":"0.021198","size":"123.9"},{"price":"0.021700","size":"1800.0"},{"price":"0.022350","size":"124.0"},{"price":"0.022519","size":"216.8"},{"price":"0.023000","size":"2734.8"},{"price":"0.023502","size":"123.9"},{"price":"0.023998","size":"62.3"},{"price":"0.024654","size":"123.9"},{"price":"0.024800","size":"33276.5"},{"price":"0.025098","size":"3.6"},{"price":"0.025202","size":"81.1"},{"price":"0.025343","size":"61739.4"},{"price":"0.025806","size":"124.0"},{"price":"0.026785","size":"129.3"},{"price":"0.026958","size":"123.9"},{"price":"0.027749","size":"10.8"},{"price":"0.027943","size":"49.3"},{"price":"0.028000","size":"800.0"},{"price":"0.028110","size":"123.9"},{"price":"0.029000","size":"50000.0"},{"price":"0.029073","size":"136.7"},{"price":"0.029262","size":"124.0"},{"price":"0.029999","size":"11790.9"},{"price":"0.030000","size":"30363.5"},{"price":"0.030150","size":"3.7"},{"price":"0.030414","size":"123.9"},{"price":"0.030861","size":"143.6"},{"price":"0.031567","size":"123.9"},{"price":"0.032425","size":"46.8"},{"price":"0.032719","size":"124.0"},{"price":"0.033000","size":"250.0"},{"price":"0.033871","size":"123.9"},{"price":"0.034000","size":"48457.9"},{"price":"0.034019","size":"122.8"},{"price":"0.035023","size":"123.9"},{"price":"0.035202","size":"3.6"},{"price":"0.035910","size":"3253.6"},{"price":"0.036175","size":"124.0"},{"price":"0.036372","size":"118.0"},{"price":"0.037327","size":"123.9"},{"price":"0.038000","size":"3000.0"},{"price":"0.038479","size":"123.9"},{"price":"0.038661","size":"63.8"},{"price":"0.039000","size":"2135.1"},{"price":"0.039500","size":"3096.0"},{"price":"0.039631","size":"124.0"},{"price":"0.040000","size":"81671.2"},{"price":"0.040255","size":"3.6"},{"price":"0.040758","size":"126.4"},{"price":"0.040783","size":"123.9"},{"price":"0.041450","size":"3836.6"},{"price":"0.041935","size":"123.9"},{"price":"0.042998","size":"270.0"},{"price":"0.043087","size":"124.0"},{"price":"0.043347","size":"79.9"},{"price":"0.044000","size":"20000.0"},{"price":"0.044239","size":"123.9"},{"price":"0.044900","size":"23734.0"},{"price":"0.045000","size":"1000.0"},{"price":"0.045237","size":"405.7"},{"price":"0.045307","size":"3.7"},{"price":"0.045391","size":"123.9"},{"price":"0.045500","size":"30000.0"},{"price":"0.046353","size":"126.6"},{"price":"0.046397","size":"30000.0"},{"price":"0.046543","size":"124.0"},{"price":"0.046700","size":"200000.0"},{"price":"0.047163","size":"3.4"},{"price":"0.047695","size":"123.9"},{"price":"0.048000","size":"19718.0"},{"price":"0.048100","size":"15084.0"},{"price":"0.048200","size":"10000.0"},{"price":"0.048300","size":"10000.0"},{"price":"0.048400","size":"10000.0"},{"price":"0.048500","size":"10000.0"},{"price":"0.048600","size":"10000.0"},{"price":"0.048700","size":"10000.0"},{"price":"0.048847","size":"123.9"},{"price":"0.049000","size":"10000.0"},{"price":"0.049100","size":"10000.0"},{"price":"0.049200","size":"10000.0"},{"price":"0.049300","size":"10000.0"},{"price":"0.049400","size":"10000.0"},{"price":"0.049500","size":"10000.0"},{"price":"0.049600","size":"10000.0"},{"price":"0.049700","size":"10000.0"},{"price":"0.049703","size":"23165.0"},{"price":"0.049800","size":"10000.0"},{"price":"0.050000","size":"11239.9"},{"price":"0.050180","size":"91.9"},{"price":"0.050359","size":"3.6"},{"price":"0.051000","size":"10000.0"},{"price":"0.052000","size":"10000.0"},{"price":"0.052973","size":"51.2"},{"price":"0.053000","size":"10000.0"},{"price":"0.054000","size":"10000.0"},{"price":"0.055000","size":"11000.0"},{"price":"0.055411","size":"3.6"},{"price":"0.056000","size":"10000.0"},{"price":"0.056265","size":"93.2"},{"price":"0.057000","size":"10000.0"},{"price":"0.057193","size":"3.4"},{"price":"0.058000","size":"10000.0"},{"price":"0.059000","size":"10000.0"},{"price":"0.060000","size":"31194.6"},{"price":"0.060463","size":"3.7"},{"price":"0.060493","size":"89.2"},{"price":"0.061000","size":"10000.0"},{"price":"0.062000","size":"10000.0"},{"price":"0.063000","size":"10000.0"},{"price":"0.064000","size":"10000.0"},{"price":"0.065000","size":"12000.0"},{"price":"0.065515","size":"3.6"},{"price":"0.066000","size":"10000.0"},{"price":"0.066895","size":"56.5"},{"price":"0.067000","size":"10000.0"},{"price":"0.067215","size":"95276.8"},{"price":"0.067223","size":"3.3"},{"price":"0.068000","size":"10000.0"},{"price":"0.070000","size":"10000.0"},{"price":"0.070567","size":"3.6"},{"price":"0.071102","size":"4.4"},{"price":"0.071390","size":"4.8"},{"price":"0.073073","size":"4.5"},{"price":"0.073471","size":"4.9"},{"price":"0.075000","size":"5000.0"},{"price":"0.075062","size":"4.4"},{"price":"0.075574","size":"4.8"},{"price":"0.075620","size":"3.7"},{"price":"0.077069","size":"4.4"},{"price":"0.077253","size":"3.4"},{"price":"0.077699","size":"4.9"},{"price":"0.079093","size":"4.5"},{"price":"0.080000","size":"20187.0"},{"price":"0.080672","size":"3.6"},{"price":"0.081135","size":"4.4"},{"price":"0.081270","size":"4.8"},{"price":"0.082002","size":"368.7"},{"price":"0.082011","size":"4.9"},{"price":"0.082826","size":"2.3"},{"price":"0.083006","size":"3.6"},{"price":"0.085000","size":"1899.0"},{"price":"0.085724","size":"3.6"},{"price":"0.085967","size":"4.5"},{"price":"0.086138","size":"3.7"},{"price":"0.087283","size":"3.4"},{"price":"0.088132","size":"9.8"},{"price":"0.090000","size":"5000.0"},{"price":"0.090452","size":"5.9"},{"price":"0.090776","size":"3.7"},{"price":"0.095000","size":"3000.0"},{"price":"0.095828","size":"3.6"},{"price":"0.097312","size":"3.4"},{"price":"0.100000","size":"55494.4"},{"price":"0.100880","size":"3.6"},{"price":"0.105000","size":"250.0"},{"price":"0.105932","size":"3.7"},{"price":"0.107342","size":"3.4"},{"price":"0.109999","size":"20000.0"},{"price":"0.110000","size":"26567.7"},{"price":"0.110985","size":"3.6"},{"price":"0.116037","size":"3.6"},{"price":"0.117372","size":"3.3"},{"price":"0.120000","size":"20000.0"},{"price":"0.121089","size":"3.7"},{"price":"0.126141","size":"3.6"},{"price":"0.127402","size":"3.4"},{"price":"0.131193","size":"3.6"},{"price":"0.131400","size":"50000.0"},{"price":"0.136200","size":"50000.0"},{"price":"0.136245","size":"3.7"},{"price":"0.137432","size":"3.4"},{"price":"0.140000","size":"7016.0"},{"price":"0.141297","size":"3.6"},{"price":"0.146350","size":"3.6"},{"price":"0.147462","size":"3.4"},{"price":"0.150000","size":"50000.0"},{"price":"0.151402","size":"3.7"},{"price":"0.156454","size":"3.6"},{"price":"0.157492","size":"3.4"},{"price":"0.160000","size":"10100.0"},{"price":"0.161506","size":"3.6"},{"price":"0.166558","size":"3.7"},{"price":"0.167521","size":"3.3"},{"price":"0.171610","size":"3.6"},{"price":"0.176662","size":"3.6"},{"price":"0.177551","size":"3.4"},{"price":"0.180000","size":"4935.0"},{"price":"0.181715","size":"3.7"},{"price":"0.186767","size":"3.6"},{"price":"0.187581","size":"3.4"},{"price":"0.191819","size":"3.6"},{"price":"0.196871","size":"3.7"},{"price":"0.197611","size":"3.4"},{"price":"0.200000","size":"1119.9"},{"price":"0.201923","size":"3.6"},{"price":"0.206975","size":"3.6"},{"price":"0.207641","size":"28914.8"},{"price":"0.212027","size":"3.7"},{"price":"0.217080","size":"3.6"},{"price":"0.217671","size":"3.3"},{"price":"0.222132","size":"3.6"},{"price":"0.227184","size":"3.7"},{"price":"0.227701","size":"3.4"},{"price":"0.230000","size":"5366.0"},{"price":"0.232236","size":"3.6"},{"price":"0.233100","size":"813.7"},{"price":"0.236200","size":"50000.0"},{"price":"0.237288","size":"3.6"},{"price":"0.237730","size":"3.4"},{"price":"0.242340","size":"3.7"},{"price":"0.247392","size":"3.6"},{"price":"0.247760","size":"3.4"},{"price":"0.250000","size":"23165.0"},{"price":"0.252445","size":"3.6"},{"price":"0.257497","size":"3.7"},{"price":"0.257790","size":"3.4"},{"price":"0.262549","size":"3.6"},{"price":"0.262620","size":"84357.0"},{"price":"0.267601","size":"3.6"},{"price":"0.267820","size":"3.3"},{"price":"0.272653","size":"3.7"},{"price":"0.277705","size":"3.6"},{"price":"0.277850","size":"3.4"},{"price":"0.280000","size":"58545.0"},{"price":"0.282757","size":"3.6"},{"price":"0.287810","size":"3.7"},{"price":"0.287880","size":"3.4"},{"price":"0.292862","size":"3.6"},{"price":"0.297910","size":"3.4"},{"price":"0.297914","size":"3.6"},{"price":"0.302966","size":"3.7"},{"price":"0.307939","size":"3.4"},{"price":"0.308018","size":"3.6"},{"price":"0.313070","size":"3.6"},{"price":"0.317969","size":"3.3"},{"price":"0.318122","size":"3.7"},{"price":"0.323175","size":"3.6"},{"price":"0.327999","size":"3.4"},{"price":"0.328227","size":"3.6"},{"price":"0.330000","size":"2817.0"},{"price":"0.333279","size":"3.7"},{"price":"0.338029","size":"3.4"},{"price":"0.338331","size":"3.6"},{"price":"0.340000","size":"24345.8"},{"price":"0.343383","size":"3.6"},{"price":"0.348059","size":"3.4"},{"price":"0.348435","size":"3.7"},{"price":"0.353487","size":"3.6"},{"price":"0.358089","size":"3.4"},{"price":"0.358540","size":"3.6"},{"price":"0.363592","size":"3.7"},{"price":"0.368119","size":"3.3"},{"price":"0.368644","size":"3.6"},{"price":"0.373696","size":"3.6"},{"price":"0.378148","size":"3.4"},{"price":"0.378748","size":"3.7"},{"price":"0.380000","size":"2781.0"},{"price":"0.383800","size":"3.6"},{"price":"0.388178","size":"3.4"},{"price":"0.388852","size":"3.6"},{"price":"0.393905","size":"3.7"},{"price":"0.398208","size":"3.4"},{"price":"0.398957","size":"3.6"},{"price":"0.404009","size":"3.6"},{"price":"0.408238","size":"3.4"},{"price":"0.409061","size":"3.7"},{"price":"0.414113","size":"3.6"},{"price":"0.418268","size":"3.3"},{"price":"0.419165","size":"3.6"},{"price":"0.420000","size":"2219.0"},{"price":"0.424217","size":"3.7"},{"price":"0.428298","size":"3.4"},{"price":"0.429270","size":"3.6"},{"price":"0.434322","size":"3.6"},{"price":"0.438328","size":"3.4"},{"price":"0.439374","size":"3.7"},{"price":"0.444426","size":"3.6"},{"price":"0.448357","size":"3.4"},{"price":"0.449478","size":"3.6"},{"price":"0.450000","size":"1917.0"},{"price":"0.454530","size":"3.7"},{"price":"0.458387","size":"3.4"},{"price":"0.459582","size":"3.6"},{"price":"0.464635","size":"3.6"},{"price":"0.468417","size":"3.3"},{"price":"0.469687","size":"3.7"},{"price":"0.474739","size":"3.6"},{"price":"0.478447","size":"3.4"},{"price":"0.479791","size":"3.6"},{"price":"0.480000","size":"2517.0"},{"price":"0.484843","size":"3.7"},{"price":"0.488477","size":"3.4"},{"price":"0.489895","size":"3.6"},{"price":"0.494947","size":"3.6"},{"price":"0.498507","size":"3.4"},{"price":"0.500000","size":"3.3"},{"price":"0.508537","size":"3.4"},{"price":"0.518566","size":"3.3"},{"price":"0.520000","size":"2191.0"},{"price":"0.528596","size":"3.4"},{"price":"0.538626","size":"3.4"},{"price":"0.548656","size":"3.4"},{"price":"0.558686","size":"3.4"},{"price":"0.560000","size":"1759.0"},{"price":"0.568716","size":"3.3"},{"price":"0.578746","size":"3.4"},{"price":"0.588775","size":"3.4"},{"price":"0.590000","size":"1481.0"},{"price":"0.598805","size":"3.4"},{"price":"0.600000","size":"50000.0"},{"price":"0.608835","size":"3.4"},{"price":"0.618865","size":"3.3"},{"price":"0.628895","size":"3.4"},{"price":"0.630000","size":"2211.0"},{"price":"0.638925","size":"3.4"},{"price":"0.648955","size":"3.4"},{"price":"0.658984","size":"3.4"},{"price":"0.669014","size":"3.3"},{"price":"0.679044","size":"3.4"},{"price":"0.680000","size":"2087.0"},{"price":"0.689074","size":"3.4"},{"price":"0.699104","size":"3.4"},{"price":"0.709134","size":"3.4"},{"price":"0.719164","size":"3.3"},{"price":"0.720000","size":"1071.0"},{"price":"0.729193","size":"3.4"},{"price":"0.739223","size":"3.4"},{"price":"0.749253","size":"3.4"},{"price":"0.750000","size":"23231.8"},{"price":"0.759283","size":"3.4"},{"price":"0.769313","size":"3.3"},{"price":"0.779343","size":"3.4"},{"price":"0.780000","size":"27648.5"},{"price":"0.789373","size":"3.4"},{"price":"0.799402","size":"3.4"},{"price":"0.809432","size":"3.4"},{"price":"0.819462","size":"3.3"},{"price":"0.820000","size":"1181.0"},{"price":"0.829492","size":"3.4"},{"price":"0.839522","size":"3.4"},{"price":"0.849552","size":"3.4"},{"price":"0.859582","size":"3.4"},{"price":"0.869611","size":"3.3"},{"price":"0.879641","size":"3.4"},{"price":"0.880000","size":"2078.0"},{"price":"0.889671","size":"3.4"},{"price":"0.899701","size":"3.4"},{"price":"0.909731","size":"3.4"},{"price":"0.919761","size":"3.3"},{"price":"0.920000","size":"958.0"},{"price":"0.929791","size":"3.4"},{"price":"0.939820","size":"3.4"},{"price":"0.949850","size":"3.4"},{"price":"0.959880","size":"3.4"},{"price":"0.969910","size":"3.3"},{"price":"0.979940","size":"3.4"},{"price":"0.989970","size":"3.4"},{"price":"1.000000","size":"37646.3"},{"price":"1.004091","size":"1201.3"},{"price":"1.400000","size":"47550.0"},{"price":"2.331000","size":"1000.0"},{"price":"3.000000","size":"9900.0"},{"price":"5.000000","size":"3211.0"},{"price":"10.000000","size":"4490.0"},{"price":"100.000000","size":"0.8"},{"price":"200.000000","size":"0.6"},{"price":"250.000000","size":"0.6"},{"price":"500.000000","size":"1.6"},{"price":"600.000000","size":"0.7"}],"bid":[{"price":"0.002338","size":"10500.0"},{"price":"0.002313","size":"75412.0"},{"price":"0.002306","size":"1.8"},{"price":"0.002290","size":"1.1"},{"price":"0.002274","size":"18792.1"},{"price":"0.002273","size":"107528.0"},{"price":"0.002272","size":"0.3"},{"price":"0.002271","size":"4.2"},{"price":"0.002264","size":"0.6"},{"price":"0.002262","size":"2.2"},{"price":"0.002261","size":"0.7"},{"price":"0.002260","size":"2.7"},{"price":"0.002259","size":"0.4"},{"price":"0.002258","size":"0.8"},{"price":"0.002257","size":"0.5"},{"price":"0.002255","size":"2.3"},{"price":"0.002254","size":"1.3"},{"price":"0.002253","size":"3.2"},{"price":"0.002252","size":"2.4"},{"price":"0.002251","size":"0.6"},{"price":"0.002250","size":"0.5"},{"price":"0.002248","size":"0.4"},{"price":"0.002247","size":"0.1"},{"price":"0.002241","size":"0.4"},{"price":"0.002240","size":"0.2"},{"price":"0.002239","size":"2.7"},{"price":"0.002238","size":"142992.0"},{"price":"0.002237","size":"0.1"},{"price":"0.002235","size":"1.2"},{"price":"0.002234","size":"0.6"},{"price":"0.002233","size":"2.3"},{"price":"0.002232","size":"0.7"},{"price":"0.002231","size":"2.1"},{"price":"0.002230","size":"1.9"},{"price":"0.002229","size":"0.7"},{"price":"0.002226","size":"0.5"},{"price":"0.002224","size":"0.1"},{"price":"0.002223","size":"0.4"},{"price":"0.002222","size":"2.7"},{"price":"0.002221","size":"2.1"},{"price":"0.002212","size":"49665.2"},{"price":"0.002198","size":"0.2"},{"price":"0.002196","size":"0.4"},{"price":"0.002194","size":"0.2"},{"price":"0.002191","size":"0.1"},{"price":"0.002190","size":"0.1"},{"price":"0.002189","size":"0.2"},{"price":"0.002183","size":"0.3"},{"price":"0.002171","size":"0.3"},{"price":"0.002157","size":"0.1"},{"price":"0.002156","size":"0.1"},{"price":"0.002100","size":"55099.1"},{"price":"0.002073","size":"1.7"},{"price":"0.002070","size":"2.0"},{"price":"0.002066","size":"4.3"},{"price":"0.002065","size":"1.3"},{"price":"0.002054","size":"0.6"},{"price":"0.002053","size":"2.2"},{"price":"0.002052","size":"4.0"},{"price":"0.002047","size":"0.2"},{"price":"0.002046","size":"0.5"},{"price":"0.002045","size":"22.7"},{"price":"0.002041","size":"0.2"},{"price":"0.002040","size":"0.8"},{"price":"0.002022","size":"0.7"},{"price":"0.002021","size":"1.4"},{"price":"0.002020","size":"1.7"},{"price":"0.002019","size":"0.2"},{"price":"0.002018","size":"1.2"},{"price":"0.002017","size":"0.2"},{"price":"0.002010","size":"1.0"},{"price":"0.002006","size":"0.4"},{"price":"0.002004","size":"2.1"},{"price":"0.002003","size":"0.3"},{"price":"0.001996","size":"0.3"},{"price":"0.001953","size":"0.4"},{"price":"0.001950","size":"0.4"},{"price":"0.001800","size":"19175.8"},{"price":"0.001338","size":"30736.9"},{"price":"0.001251","size":"2508.3"},{"price":"0.001218","size":"8.2"},{"price":"0.001048","size":"4638.7"},{"price":"0.000961","size":"151.5"},{"price":"0.000879","size":"151.5"},{"price":"0.000796","size":"151.5"},{"price":"0.000755","size":"151.5"},{"price":"0.000713","size":"151.5"},{"price":"0.000672","size":"151.5"},{"price":"0.000631","size":"151.5"},{"price":"0.000589","size":"151.5"},{"price":"0.000548","size":"151.6"},{"price":"0.000507","size":"151.5"},{"price":"0.000465","size":"151.5"},{"price":"0.000424","size":"151.5"},{"price":"0.000383","size":"151.5"},{"price":"0.000341","size":"151.5"},{"price":"0.000300","size":"151.5"},{"price":"0.000259","size":"151.6"},{"price":"0.000218","size":"344036.6"},{"price":"0.000217","size":"151.5"},{"price":"0.000176","size":"151.5"},{"price":"0.000135","size":"151.5"},{"price":"0.000107","size":"25000.0"},{"price":"0.000100","size":"24306.6"},{"price":"0.000093","size":"10904.1"},{"price":"0.000075","size":"13333.3"},{"price":"0.000065","size":"15384.6"},{"price":"0.000055","size":"18181.8"},{"price":"0.000052","size":"65845.3"},{"price":"0.000038","size":"7184.7"},{"price":"0.000037","size":"7184.7"},{"price":"0.000036","size":"7184.6"},{"price":"0.000035","size":"7184.7"},{"price":"0.000034","size":"7184.7"},{"price":"0.000033","size":"7184.6"},{"price":"0.000032","size":"38434.7"},{"price":"0.000031","size":"7184.7"},{"price":"0.000030","size":"7184.6"},{"price":"0.000029","size":"7184.7"},{"price":"0.000028","size":"7184.7"},{"price":"0.000027","size":"9830.0"},{"price":"0.000026","size":"12475.6"},{"price":"0.000025","size":"15121.0"},{"price":"0.000024","size":"17766.4"},{"price":"0.000023","size":"26454.4"},{"price":"0.000022","size":"61327.1"},{"price":"0.000021","size":"18518.0"},{"price":"0.000020","size":"21163.5"},{"price":"0.000019","size":"23808.9"},{"price":"0.000018","size":"26454.3"},{"price":"0.000017","size":"29099.8"},{"price":"0.000016","size":"852917.6"},{"price":"0.000015","size":"34390.6"},{"price":"0.000014","size":"99071.0"},{"price":"0.000012","size":"83333.3"},{"price":"0.000010","size":"151.5"},{"price":"0.000009","size":"1023795.3"},{"price":"0.000008","size":"625000.0"},{"price":"0.000007","size":"1690960.0"},{"price":"0.000006","size":"250000.0"},{"price":"0.000005","size":"200000.0"},{"price":"0.000003","size":"3455309.1"},{"price":"0.000002","size":"3974718.0"},{"price":"0.000001","size":"11332641.5"}],"sequence":82320,"timestamp":"2021-07-15T01:23:26.850Z","symbol":"HUBUSD"}}
1626318013.596787: {"jsonrpc":"2.0","method":"snapshotOrderbook","params":{"ask":[{"price":"0.0001138","size":"0.001"},{"price":"0.0001152","size":"0.015"},{"price":"0.0001561","size":"0.154"},{"price":"0.0001799","size":"2.346"},{"price":"0.0002076","size":"4.279"},{"price":"0.0002200","size":"0.181"},{"price":"0.0002400","size":"0.166"},{"price":"0.0002424","size":"1.953"},{"price":"0.0002573","size":"3.766"},{"price":"0.0002574","size":"3.176"},{"price":"0.0002600","size":"0.153"},{"price":"0.0002800","size":"0.142"},{"price":"0.0002876","size":"9.900"},{"price":"0.0003000","size":"0.233"},{"price":"0.0003200","size":"0.125"},{"price":"0.0003400","size":"0.117"},{"price":"0.0003600","size":"0.111"},{"price":"0.0003800","size":"0.105"},{"price":"0.0004000","size":"0.300"},{"price":"0.0004200","size":"0.080"},{"price":"0.0004396","size":"47.197"},{"price":"0.0004500","size":"0.080"},{"price":"0.0004536","size":"0.261"},{"price":"0.0004800","size":"0.040"},{"price":"0.0005000","size":"0.100"},{"price":"0.0005097","size":"0.158"},{"price":"0.0005100","size":"0.047"},{"price":"0.0005500","size":"0.040"},{"price":"0.0005700","size":"0.068"},{"price":"0.0006000","size":"0.407"},{"price":"0.0006321","size":"0.490"},{"price":"0.0006600","size":"0.312"},{"price":"0.0006970","size":"3.608"},{"price":"0.0007000","size":"0.100"},{"price":"0.0007400","size":"0.209"},{"price":"0.0008000","size":"0.232"},{"price":"0.0008500","size":"0.174"},{"price":"0.0009200","size":"0.169"},{"price":"0.0010000","size":"0.180"},{"price":"0.0010800","size":"0.138"},{"price":"0.0011600","size":"0.417"},{"price":"0.0013500","size":"0.410"},{"price":"0.0016000","size":"0.291"},{"price":"0.0020000","size":"0.276"},{"price":"0.0026000","size":"0.174"},{"price":"0.0036000","size":"0.299"},{"price":"0.0500000","size":"0.839"},{"price":"0.2000000","size":"0.015"},{"price":"0.6000000","size":"0.100"},{"price":"0.8659200","size":"0.105"},{"price":"1.5557466","size":"0.001"},{"price":"7.5557466","size":"0.001"},{"price":"13.5557466","size":"0.001"},{"price":"27.5557466","size":"0.001"},{"price":"77.5557466","size":"0.001"},{"price":"133.5557466","size":"0.001"},{"price":"400.0000000","size":"0.001"},{"price":"433.5557466","size":"0.001"},{"price":"833.5557466","size":"0.001"},{"price":"1233.5557466","size":"0.001"},{"price":"4233.5557466","size":"0.001"},{"price":"8233.5557466","size":"0.001"},{"price":"13233.5557466","size":"0.001"},{"price":"43233.5557466","size":"0.001"},{"price":"83233.5557466","size":"0.001"},{"price":"123233.5557466","size":"0.001"},{"price":"423233.5557466","size":"0.001"},{"price":"823233.5557466","size":"0.001"},{"price":"1323233.5557466","size":"0.001"}],"bid":[{"price":"0.0001013","size":"85.237"},{"price":"0.0001012","size":"2.999"},{"price":"0.0001007","size":"0.001"},{"price":"0.0001000","size":"9.821"},{"price":"0.0000950","size":"0.263"},{"price":"0.0000900","size":"0.288"},{"price":"0.0000850","size":"0.320"},{"price":"0.0000800","size":"0.250"},{"price":"0.0000787","size":"39.275"},{"price":"0.0000760","size":"0.263"},{"price":"0.0000730","size":"0.273"},{"price":"0.0000707","size":"1.428"},{"price":"0.0000700","size":"0.285"},{"price":"0.0000675","size":"0.296"},{"price":"0.0000650","size":"0.307"},{"price":"0.0000625","size":"0.320"},{"price":"0.0000600","size":"0.333"},{"price":"0.0000580","size":"0.344"},{"price":"0.0000560","size":"0.357"},{"price":"0.0000540","size":"0.370"},{"price":"0.0000520","size":"0.384"},{"price":"0.0000500","size":"0.400"},{"price":"0.0000142","size":"7.112"},{"price":"0.0000037","size":"0.193"},{"price":"0.0000036","size":"0.194"},{"price":"0.0000035","size":"0.195"},{"price":"0.0000034","size":"0.194"},{"price":"0.0000033","size":"0.195"},{"price":"0.0000032","size":"0.194"},{"price":"0.0000031","size":"0.195"},{"price":"0.0000030","size":"0.194"},{"price":"0.0000029","size":"0.195"},{"price":"0.0000028","size":"0.194"},{"price":"0.0000027","size":"0.195"},{"price":"0.0000026","size":"0.194"},{"price":"0.0000025","size":"0.195"},{"price":"0.0000024","size":"0.388"},{"price":"0.0000023","size":"0.390"},{"price":"0.0000022","size":"0.388"},{"price":"0.0000021","size":"0.390"},{"price":"0.0000020","size":"0.388"},{"price":"0.0000019","size":"526.705"},{"price":"0.0000018","size":"0.388"},{"price":"0.0000017","size":"0.390"},{"price":"0.0000016","size":"0.388"},{"price":"0.0000015","size":"0.390"},{"price":"0.0000014","size":"0.388"},{"price":"0.0000013","size":"0.390"},{"price":"0.0000012","size":"0.388"},{"price":"0.0000011","size":"0.390"},{"price":"0.0000010","size":"0.388"},{"price":"0.0000009","size":"0.390"},{"price":"0.0000008","size":"0.388"},{"price":"0.0000007","size":"144.675"},{"price":"0.0000006","size":"0.388"},{"price":"0.0000005","size":"0.390"},{"price":"0.0000004","size":"0.388"},{"price":"0.0000003","size":"0.390"},{"price":"0.0000002","size":"0.776"}],"sequence":2198419,"timestamp":"2021-07-15T03:00:12.534Z","symbol":"NUTBTC"}}
1626318013.5968902: {"jsonrpc":"2.0","method":"updateOrderbook","params":{"ask":[{"price":"0.662654","size":"399047.6"}],"bid":[{"price":"0.615539","size":"1591.6"},{"price":"0.615525","size":"0"},{"price":"0.609523","size":"0"},{"price":"0.608435","size":"231424.6"}],"sequence":20583984,"timestamp":"2021-07-15T03:00:13.080Z","symbol":"XRPUSDT"}}
1626318013.596898: {"jsonrpc":"2.0","method":"updateOrderbook","params":{"ask":[{"price":"0.00000038300","size":"0"},{"price":"0.00000038373","size":"603920"},{"price":"0.00000042878","size":"0"},{"price":"0.00000042942","size":"1016210"},{"price":"0.00000062098","size":"0"},{"price":"0.00000062424","size":"1381850"},{"price":"0.00000107023","size":"0"},{"price":"0.00000107297","size":"2001500"},{"price":"0.00000131756","size":"0"},{"price":"0.00000131849","size":"2705250"},{"price":"0.00000148899","size":"0"},{"price":"0.00000148986","size":"3222000"},{"price":"0.00000167166","size":"0"},{"price":"0.00000167362","size":"4634410"},{"price":"0.00000468263","size":"0"},{"price":"0.00000469246","size":"7466230"}],"bid":[{"price":"0.00000034622","size":"0"},{"price":"0.00000034002","size":"230000"}],"sequence":10532183,"timestamp":"2021-07-15T03:00:13.100Z","symbol":"SCBTC"}}
1626318013.596909: {"jsonrpc":"2.0","method":"updateOrderbook","params":{"ask":[{"price":"0.00054624","size":"0"},{"price":"0.00054630","size":"4.33"},{"price":"0.00054661","size":"16.70"},{"price":"0.00054674","size":"0"},{"price":"0.00054694","size":"296.51"},{"price":"0.00054705","size":"144.16"},{"price":"0.00054721","size":"0"},{"price":"0.00054750","size":"0"},{"price":"0.00054872","size":"658.12"},{"price":"0.00054913","size":"0"},{"price":"0.00055303","size":"0"},{"price":"0.00055364","size":"1811.87"},{"price":"0.00056145","size":"0"},{"price":"0.00056463","size":"0"},{"price":"0.00056541","size":"2539.46"},{"price":"0.00056633","size":"1757.02"},{"price":"0.00069110","size":"0"},{"price":"0.00070823","size":"2343.84"},{"price":"0.00080525","size":"0"},{"price":"0.00080803","size":"3484.36"}],"bid":[{"price":"0.00054585","size":"0"},{"price":"0.00054583","size":"5.18"},{"price":"0.00054578","size":"0"},{"price":"0.00054574","size":"9.62"},{"price":"0.00054515","size":"0"},{"price":"0.00054493","size":"275.31"},{"price":"0.00054455","size":"733.95"},{"price":"0.00054443","size":"0"},{"price":"0.00054407","size":"482.00"},{"price":"0.00054396","size":"0"},{"price":"0.00054346","size":"679.54"},{"price":"0.00054295","size":"0"},{"price":"0.00054246","size":"929.35"}],"sequence":19512985,"timestamp":"2021-07-15T03:00:13.118Z","symbol":"UNIBTC"}}
1626318013.5969348: {"jsonrpc":"2.0","method":"updateOrderbook","params":{"ask":[{"price":"0.616078","size":"495.8"},{"price":"0.616286","size":"2136.6"},{"price":"0.616361","size":"0"},{"price":"0.616498","size":"0"},{"price":"0.662654","size":"399048.1"}],"bid":[{"price":"0.615544","size":"1591.6"},{"price":"0.615539","size":"0"},{"price":"0.603923","size":"91768.8"},{"price":"0.591463","size":"0"}],"sequence":20583985,"timestamp":"2021-07-15T03:00:13.220Z","symbol":"XRPUSDT"}}
1626318013.5969431: {"jsonrpc":"2.0","method":"updateOrderbook","params":{"ask":[{"price":"0.00000065973","size":"15229610"}],"bid":[],"sequence":10532184,"timestamp":"2021-07-15T03:00:13.224Z","symbol":"SCBTC"}}
1626318013.596949: {"jsonrpc":"2.0","method":"updateOrderbook","params":{"ask":[{"price":"0.00054622","size":"4.33"},{"price":"0.00054630","size":"0"},{"price":"0.00054666","size":"66.20"},{"price":"0.00054685","size":"0"},{"price":"0.00054694","size":"0"},{"price":"0.00054711","size":"201.47"},{"price":"0.00054727","size":"18.19"},{"price":"0.00054737","size":"296.51"},{"price":"0.00054743","size":"72.32"},{"price":"0.00054863","size":"0"},{"price":"0.00054977","size":"433.80"},{"price":"0.00055050","size":"0"},{"price":"0.00055297","size":"662.81"},{"price":"0.00055873","size":"0"},{"price":"0.00057775","size":"881.76"},{"price":"0.00074880","size":"0"},{"price":"0.00076428","size":"1125.76"},{"price":"0.00084018","size":"0"}],"bid":[{"price":"0.00054583","size":"0"},{"price":"0.00054579","size":"5.18"},{"price":"0.00054574","size":"0"},{"price":"0.00054569","size":"27.94"},{"price":"0.00053120","size":"0"}],"sequence":19512986,"timestamp":"2021-07-15T03:00:13.241Z","symbol":"UNIBTC"}}
1626318013.596972: {"jsonrpc":"2.0","method":"updateOrderbook","params":{"ask":[],"bid":[{"price":"12.063","size":"5.8932"},{"price":"12.061","size":"0"}],"sequence":2190655,"timestamp":"2021-07-15T03:00:13.340Z","symbol":"SPIUSD"}}
1626318013.596988: {"jsonrpc":"2.0","method":"updateOrderbook","params":{"ask":[{"price":"0.615885","size":"10637.3"},{"price":"0.617403","size":"12316.2"},{"price":"0.617485","size":"0"},{"price":"0.662654","size":"399048.4"}],"bid":[{"price":"0.615544","size":"0"},{"price":"0.615543","size":"1591.6"},{"price":"0.578683","size":"0"},{"price":"0.575457","size":"195374.1"}],"sequence":20583986,"timestamp":"2021-07-15T03:00:13.337Z","symbol":"XRPUSDT"}}
1626318013.596996: {"jsonrpc":"2.0","method":"updateOrderbook","params":{"ask":[{"price":"0.00000094558","size":"2753570"},{"price":"0.00000094561","size":"0"}],"bid":[],"sequence":10532185,"timestamp":"2021-07-15T03:00:13.272Z","symbol":"SCBTC"}}
1626318013.597002: {"jsonrpc":"2.0","method":"updateOrderbook","params":{"ask":[{"price":"0.00054618","size":"4.33"},{"price":"0.00054622","size":"0"},{"price":"0.00054625","size":"10.47"},{"price":"0.00054635","size":"0"},{"price":"0.00054672","size":"16.96"},{"price":"0.00054691","size":"0"},{"price":"0.00056559","size":"1757.02"},{"price":"0.00056633","size":"0"},{"price":"0.00080659","size":"3484.36"},{"price":"0.00080803","size":"0"}],"bid":[{"price":"0.00054579","size":"0"},{"price":"0.00054573","size":"5.18"},{"price":"0.00054569","size":"18.32"},{"price":"0.00054564","size":"9.62"},{"price":"0.00054556","size":"0"},{"price":"0.00054548","size":"0"},{"price":"0.00054542","size":"0"},{"price":"0.00054537","size":"18.03"},{"price":"0.00054531","size":"17.87"},{"price":"0.00054525","size":"69.23"},{"price":"0.00054507","size":"0"},{"price":"0.00054479","size":"239.54"},{"price":"0.00054445","size":"0"},{"price":"0.00054405","size":"468.52"},{"price":"0.00054267","size":"0"},{"price":"0.00054192","size":"634.39"},{"price":"0.00053050","size":"442.49"},{"price":"0.00052241","size":"0"},{"price":"0.00051743","size":"2974.71"}],"sequence":19512987,"timestamp":"2021-07-15T03:00:13.313Z","symbol":"UNIBTC"}}
1626318013.597025: {"jsonrpc":"2.0","method":"updateOrderbook","params":{"ask":[{"price":"0.662654","size":"399048.6"}],"bid":[{"price":"0.613589","size":"0"},{"price":"0.613490","size":"0"},{"price":"0.612944","size":"514.4"},{"price":"0.612834","size":"0"},{"price":"0.612818","size":"2256.2"},{"price":"0.611745","size":"9414.1"},{"price":"0.575457","size":"0"},{"price":"0.573251","size":"195374.1"}],"sequence":20583987,"timestamp":"2021-07-15T03:00:13.405Z","symbol":"XRPUSDT"}}
1626318013.597034: {"jsonrpc":"2.0","method":"updateOrderbook","params":{"ask":[],"bid":[{"price":"0.00000034677","size":"0"},{"price":"0.00000034622","size":"230000"}],"sequence":10532186,"timestamp":"2021-07-15T03:00:13.409Z","symbol":"SCBTC"}}
1626318013.5970402: {"jsonrpc":"2.0","method":"updateOrderbook","params":{"ask":[{"price":"0.00054675","size":"199.63"},{"price":"0.00054697","size":"333.84"},{"price":"0.00054723","size":"0"},{"price":"0.00054727","size":"459.08"},{"price":"0.00054767","size":"218.43"},{"price":"0.00054786","size":"0"},{"price":"0.00054855","size":"86.00"},{"price":"0.00054856","size":"0"},{"price":"0.00054872","size":"0"},{"price":"0.00054949","size":"658.12"},{"price":"0.00056541","size":"0"},{"price":"0.00056892","size":"2539.46"},{"price":"0.00083297","size":"1585.64"}],"bid":[{"price":"0.00054569","size":"0"},{"price":"0.00054559","size":"18.32"},{"price":"0.00054557","size":"0"},{"price":"0.00054539","size":"0"},{"price":"0.00054529","size":"18.58"},{"price":"0.00054519","size":"0"},{"price":"0.00054513","size":"269.65"},{"price":"0.00054490","size":"177.91"},{"price":"0.00054450","size":"0"},{"price":"0.00054416","size":"345.77"},{"price":"0.00054405","size":"0"},{"price":"0.00054397","size":"0"},{"price":"0.00054361","size":"468.52"},{"price":"0.00054348","size":"1046.48"},{"price":"0.00051743","size":"0"},{"price":"0.00051518","size":"2974.71"}],"sequence":19512988,"timestamp":"2021-07-15T03:00:13.427Z","symbol":"UNIBTC"}}
1626318013.5970528: {"jsonrpc":"2.0","method":"updateOrderbook","params":{"ask":[{"price":"0.615885","size":"0"},{"price":"0.616137","size":"10636.9"},{"price":"0.662654","size":"399049.0"}],"bid":[],"sequence":20583988,"timestamp":"2021-07-15T03:00:13.534Z","symbol":"XRPUSDT"}}
1626318013.597059: {"jsonrpc":"2.0","method":"updateOrderbook","params":{"ask":[{"price":"0.00000065973","size":"15229620"}],"bid":[],"sequence":10532187,"timestamp":"2021-07-15T03:00:13.519Z","symbol":"SCBTC"}}
1626318013.597064: {"jsonrpc":"2.0","method":"updateOrderbook","params":{"ask":[{"price":"0.00054614","size":"4.33"},{"price":"0.00054618","size":"0"},{"price":"0.00054691","size":"66.76"},{"price":"0.00054705","size":"77.40"}],"bid":[{"price":"0.00054353","size":"0"},{"price":"0.00054305","size":"170.00"}],"sequence":19512989,"timestamp":"2021-07-15T03:00:13.527Z","symbol":"UNIBTC"}}
1626318013.664347: {"jsonrpc":"2.0","method":"updateOrderbook","params":{"ask":[{"price":"0.615885","size":"10636.8"},{"price":"0.616137","size":"0"},{"price":"0.662654","size":"399049.3"}],"bid":[{"price":"0.615548","size":"1591.6"},{"price":"0.615543","size":"0"},{"price":"0.603923","size":"0"},{"price":"0.602219","size":"91768.8"}],"sequence":20583989,"timestamp":"2021-07-15T03:00:13.627Z","symbol":"XRPUSDT"}}
1626318013.6785321: {"jsonrpc":"2.0","method":"updateOrderbook","params":{"ask":[],"bid":[{"price":"0.00000034658","size":"234600"},{"price":"0.00000034622","size":"0"}],"sequence":10532188,"timestamp":"2021-07-15T03:00:13.550Z","symbol":"SCBTC"}}
1626318013.678574: {"jsonrpc":"2.0","method":"updateOrderbook","params":{"ask":[{"price":"0.00054611","size":"4.33"},{"price":"0.00054614","size":"0"},{"price":"0.00054727","size":"18.19"},{"price":"0.00054763","size":"440.89"},{"price":"0.00054817","size":"86.00"},{"price":"0.00054823","size":"84.00"},{"price":"0.00054855","size":"0"},{"price":"0.00054873","size":"0"}],"bid":[{"price":"0.00054575","size":"5.18"},{"price":"0.00054573","size":"0"},{"price":"0.00054559","size":"0"},{"price":"0.00054549","size":"18.32"},{"price":"0.00054525","size":"0"},{"price":"0.00054509","size":"69.23"},{"price":"0.00053050","size":"443.28"}],"sequence":19512990,"timestamp":"2021-07-15T03:00:13.640Z","symbol":"UNIBTC"}}
1626318013.7590752: {"jsonrpc":"2.0","method":"updateOrderbook","params":{"ask":[{"price":"0.662654","size":"399049.7"}],"bid":[{"price":"0.615552","size":"1591.6"},{"price":"0.615548","size":"0"},{"price":"0.612957","size":"0"},{"price":"0.611736","size":"7330.7"}],"sequence":20583990,"timestamp":"2021-07-15T03:00:13.740Z","symbol":"XRPUSDT"}}
1626318013.774815: {"jsonrpc":"2.0","method":"updateOrderbook","params":{"ask":[{"price":"0.00054678","size":"18.88"},{"price":"0.00054687","size":"0"},{"price":"0.00054694","size":"77.40"},{"price":"0.00054705","size":"0"},{"price":"0.00054823","size":"0"},{"price":"0.00054869","size":"84.00"}],"bid":[{"price":"0.00054575","size":"0"},{"price":"0.00054570","size":"5.18"},{"price":"0.00054564","size":"0"},{"price":"0.00054559","size":"9.62"},{"price":"0.00054536","size":"0"},{"price":"0.00054513","size":"72.79"},{"price":"0.00054505","size":"21.05"},{"price":"0.00054493","size":"0"},{"price":"0.00054485","size":"196.86"},{"price":"0.00054479","size":"0"},{"price":"0.00054466","size":"275.31"},{"price":"0.00054457","size":"239.57"},{"price":"0.00054343","size":"0"},{"price":"0.00054305","size":"86.00"},{"price":"0.00054285","size":"977.96"},{"price":"0.00054247","size":"84.00"}],"sequence":19512991,"timestamp":"2021-07-15T03:00:13.717Z","symbol":"UNIBTC"}}
1626318013.8568041: {"jsonrpc":"2.0","method":"updateOrderbook","params":{"ask":[{"price":"0.615756","size":"0"},{"price":"0.616324","size":"0"},{"price":"0.616382","size":"160.9"},{"price":"0.662654","size":"399050.0"}],"bid":[{"price":"0.615695","size":"11000.0"},{"price":"0.615574","size":"1591.6"},{"price":"0.615552","size":"0"}],"sequence":20583991,"timestamp":"2021-07-15T03:00:13.841Z","symbol":"XRPUSDT"}}
1626318013.875687: {"jsonrpc":"2.0","method":"updateOrderbook","params":{"ask":[{"price":"0.00000065973","size":"15229630"}],"bid":[],"sequence":10532189,"timestamp":"2021-07-15T03:00:13.760Z","symbol":"SCBTC"}}
1626318013.8757179: {"jsonrpc":"2.0","method":"updateOrderbook","params":{"ask":[{"price":"0.00054686","size":"296.51"},{"price":"0.00054737","size":"0"}],"bid":[{"price":"0.00054572","size":"5.18"},{"price":"0.00054570","size":"0"},{"price":"0.00054483","size":"0"},{"price":"0.00054455","size":"623.09"},{"price":"0.00054423","size":"380.79"},{"price":"0.00054346","size":"0"},{"price":"0.00054304","size":"880.17"},{"price":"0.00054286","size":"84.00"},{"price":"0.00054254","size":"634.39"},{"price":"0.00054247","size":"0"},{"price":"0.00054192","size":"0"}],"sequence":19512992,"timestamp":"2021-07-15T03:00:13.818Z","symbol":"UNIBTC"}}
1626318013.954717: {"jsonrpc":"2.0","method":"updateOrderbook","params":{"ask":[{"price":"0.615749","size":"1331.7"},{"price":"0.615763","size":"0"},{"price":"0.615885","size":"0"},{"price":"0.616137","size":"10636.6"},{"price":"0.616383","size":"0"},{"price":"0.616507","size":"10636.4"},{"price":"0.616508","size":"8521.8"},{"price":"0.662654","size":"399050.3"}],"bid":[{"price":"0.615695","size":"0"},{"price":"0.615693","size":"11000.0"}],"sequence":20583992,"timestamp":"2021-07-15T03:00:13.936Z","symbol":"XRPUSDT"}}
1626318013.962976: {"jsonrpc":"2.0","method":"updateOrderbook","params":{"ask":[{"price":"0.00000042897","size":"1016210"},{"price":"0.00000042915","size":"0"},{"price":"0.00000042942","size":"0"},{"price":"0.00000043223","size":"522810"},{"price":"0.00000054429","size":"0"},{"price":"0.00000054592","size":"757990"},{"price":"0.00000077953","size":"0"},{"price":"0.00000078158","size":"2003810"},{"price":"0.00000284046","size":"0"},{"price":"0.00000284910","size":"4472830"}],"bid":[],"sequence":10532190,"timestamp":"2021-07-15T03:00:13.940Z","symbol":"SCBTC"}}
1626318013.96301: {"jsonrpc":"2.0","method":"updateOrderbook","params":{"ask":[{"price":"0.00054608","size":"4.33"},{"price":"0.00054611","size":"0"},{"price":"0.00054658","size":"16.96"},{"price":"0.00054672","size":"0"}],"bid":[{"price":"0.00054574","size":"5.18"},{"price":"0.00054572","size":"0"},{"price":"0.00054555","size":"0"},{"price":"0.00054523","size":"18.61"}],"sequence":19512993,"timestamp":"2021-07-15T03:00:13.891Z","symbol":"UNIBTC"}}
1626318014.053631: {"jsonrpc":"2.0","method":"updateOrderbook","params":{"ask":[{"price":"0.615747","size":"11000.0"},{"price":"0.616285","size":"160.9"},{"price":"0.616382","size":"0"},{"price":"0.618219","size":"128852.0"},{"price":"0.619332","size":"0"},{"price":"0.662654","size":"399050.6"}],"bid":[{"price":"0.615693","size":"0"},{"price":"0.615413","size":"2843.9"},{"price":"0.615339","size":"0"}],"sequence":20583993,"timestamp":"2021-07-15T03:00:14.035Z","symbol":"XRPUSDT"}}
1626318014.075145: {"jsonrpc":"2.0","method":"updateOrderbook","params":{"ask":[{"price":"0.00054876","size":"4260.27"},{"price":"0.00054942","size":"0"}],"bid":[],"sequence":19512994,"timestamp":"2021-07-15T03:00:13.974Z","symbol":"UNIBTC"}}
1626318014.163359: {"jsonrpc":"2.0","method":"updateOrderbook","params":{"ask":[{"price":"0.662654","size":"399050.8"}],"bid":[{"price":"0.615574","size":"0"},{"price":"0.615569","size":"1591.6"}],"sequence":20583994,"timestamp":"2021-07-15T03:00:14.101Z","symbol":"XRPUSDT"}}
1626318014.180374: {"jsonrpc":"2.0","method":"updateOrderbook","params":{"ask":[{"price":"0.00000065973","size":"15229640"}],"bid":[],"sequence":10532191,"timestamp":"2021-07-15T03:00:14.045Z","symbol":"SCBTC"}}
1626318014.180403: {"jsonrpc":"2.0","method":"updateOrderbook","params":{"ask":[{"price":"0.00054608","size":"0"},{"price":"0.00054613","size":"4.33"},{"price":"0.00054817","size":"0"},{"price":"0.00054823","size":"86.00"},{"price":"0.00054949","size":"0"},{"price":"0.00055031","size":"658.12"},{"price":"0.00056892","size":"0"},{"price":"0.00057102","size":"2539.46"}],"bid":[{"price":"0.00054576","size":"5.18"},{"price":"0.00054574","size":"0"}],"sequence":19512995,"timestamp":"2021-07-15T03:00:14.140Z","symbol":"UNIBTC"}}
1626318014.25681: {"jsonrpc":"2.0","method":"updateOrderbook","params":{"ask":[],"bid":[{"price":"12.064","size":"7.2207"},{"price":"12.062","size":"0"}],"sequence":2190656,"timestamp":"2021-07-15T03:00:14.202Z","symbol":"SPIUSD"}}
1626318014.284022: {"jsonrpc":"2.0","method":"updateOrderbook","params":{"ask":[{"price":"0.662654","size":"399051.1"}],"bid":[],"sequence":20583995,"timestamp":"2021-07-15T03:00:14.193Z","symbol":"XRPUSDT"}}
1626318014.288084: {"jsonrpc":"2.0","method":"updateOrderbook","params":{"ask":[{"price":"0.00000038373","size":"0"},{"price":"0.00000038575","size":"603920"},{"price":"0.00000041210","size":"0"},{"price":"0.00000041276","size":"661850"},{"price":"0.00000042897","size":"0"},{"price":"0.00000042978","size":"1016210"},{"price":"0.00000062424","size":"0"},{"price":"0.00000063201","size":"1381850"},{"price":"0.00000107297","size":"0"},{"price":"0.00000107948","size":"2001500"},{"price":"0.00000131849","size":"0"},{"price":"0.00000132071","size":"2705250"},{"price":"0.00000167362","size":"0"},{"price":"0.00000167678","size":"4634410"},{"price":"0.00000469246","size":"0"},{"price":"0.00000472388","size":"7466230"}],"bid":[],"sequence":10532192,"timestamp":"2021-07-15T03:00:14.210Z","symbol":"SCBTC"}}
1626318014.2881348: {"jsonrpc":"2.0","method":"updateOrderbook","params":{"ask":[{"price":"0.00054607","size":"4.33"},{"price":"0.00054613","size":"0"},{"price":"0.00054638","size":"16.70"},{"price":"0.00054652","size":"66.20"},{"price":"0.00054661","size":"0"},{"price":"0.00054666","size":"0"},{"price":"0.00054675","size":"0"},{"price":"0.00054686","size":"0"},{"price":"0.00054697","size":"0"},{"price":"0.00054698","size":"199.63"},{"price":"0.00054715","size":"296.51"},{"price":"0.00054743","size":"406.16"},{"price":"0.00054823","size":"0"},{"price":"0.00054869","size":"170.00"},{"price":"0.00054940","size":"0"},{"price":"0.00055008","size":"1302.32"}],"bid":[{"price":"0.00054454","size":"0"},{"price":"0.00054417","size":"1.17"},{"price":"0.00054303","size":"634.39"},{"price":"0.00054254","size":"0"}],"sequence":19512996,"timestamp":"2021-07-15T03:00:14.237Z","symbol":"UNIBTC"}}
1626318014.351983: {"jsonrpc":"2.0","method":"updateOrderbook","params":{"ask":[{"price":"0.615885","size":"10635.9"},{"price":"0.616137","size":"0"},{"price":"0.617403","size":"0"},{"price":"0.617484","size":"12316.2"},{"price":"0.662654","size":"399051.5"}],"bid":[{"price":"0.615574","size":"1591.6"},{"price":"0.615569","size":"0"},{"price":"0.615202","size":"0"},{"price":"0.614839","size":"2800.0"}],"sequence":20583996,"timestamp":"2021-07-15T03:00:14.326Z","symbol":"XRPUSDT"}}
1626318014.3815339: {"jsonrpc":"2.0","method":"updateOrderbook","params":{"ask":[{"price":"0.00000065973","size":"15229650"}],"bid":[],"sequence":10532193,"timestamp":"2021-07-15T03:00:14.317Z","symbol":"SCBTC"}}
1626318014.3815649: {"jsonrpc":"2.0","method":"updateOrderbook","params":{"ask":[{"price":"0.00054616","size":"10.47"},{"price":"0.00054625","size":"0"},{"price":"0.00054823","size":"86.00"},{"price":"0.00054869","size":"84.00"}],"bid":[{"price":"0.00054576","size":"0"},{"price":"0.00054572","size":"5.18"},{"price":"0.00054414","size":"468.52"},{"price":"0.00054361","size":"0"}],"sequence":19512997,"timestamp":"2021-07-15T03:00:14.314Z","symbol":"UNIBTC"}}
1626318014.38162: {"jsonrpc":"2.0","method":"updateOrderbook","params":{"ask":[{"price":"0.0004396","size":"0"},{"price":"0.0004397","size":"47.197"}],"bid":[],"sequence":2198420,"timestamp":"2021-07-15T03:00:14.270Z","symbol":"NUTBTC"}}
1626318014.472335: {"jsonrpc":"2.0","method":"updateOrderbook","params":{"ask":[{"price":"0.616301","size":"10636.2"},{"price":"0.616507","size":"0"},{"price":"0.616604","size":"8706.8"},{"price":"0.616916","size":"0"},{"price":"0.619997","size":"177540.1"},{"price":"0.621253","size":"0"},{"price":"0.662654","size":"399051.8"}],"bid":[{"price":"0.612578","size":"7330.7"},{"price":"0.611736","size":"0"}],"sequence":20583997,"timestamp":"2021-07-15T03:00:14.439Z","symbol":"XRPUSDT"}}
1626318014.474408: {"jsonrpc":"2.0","method":"updateOrderbook","params":{"ask":[],"bid":[{"price":"0.00000036356","size":"586390"},{"price":"0.00000036330","size":"0"}],"sequence":10532194,"timestamp":"2021-07-15T03:00:14.385Z","symbol":"SCBTC"}}
1626318014.474453: {"jsonrpc":"2.0","method":"updateOrderbook","params":{"ask":[{"price":"0.00054601","size":"4.33"},{"price":"0.00054607","size":"0"},{"price":"0.00054666","size":"18.19"},{"price":"0.00054682","size":"149.72"},{"price":"0.00054694","size":"0"},{"price":"0.00054727","size":"0"},{"price":"0.00054743","size":"333.84"},{"price":"0.00054780","size":"528.37"},{"price":"0.00054792","size":"0"}],"bid":[{"price":"0.00054572","size":"0"},{"price":"0.00054569","size":"5.18"},{"price":"0.00054537","size":"0"},{"price":"0.00054532","size":"0"},{"price":"0.00054524","size":"18.03"},{"price":"0.00054501","size":"80.24"}],"sequence":19512998,"timestamp":"2021-07-15T03:00:14.423Z","symbol":"UNIBTC"}}
1626318014.563828: {"jsonrpc":"2.0","method":"updateOrderbook","params":{"ask":[{"price":"0.617185","size":"20127.1"},{"price":"0.617707","size":"0"},{"price":"0.662654","size":"399052.0"}],"bid":[{"price":"0.615581","size":"1591.6"},{"price":"0.615574","size":"0"},{"price":"0.615445","size":"2955.9"},{"price":"0.615411","size":"0"},{"price":"0.591781","size":"4.3"}],"sequence":20583998,"timestamp":"2021-07-15T03:00:14.499Z","symbol":"XRPUSDT"}}
1626318014.575995: {"jsonrpc":"2.0","method":"updateOrderbook","params":{"ask":[{"price":"0.00000065973","size":"15229660"}],"bid":[],"sequence":10532195,"timestamp":"2021-07-15T03:00:14.521Z","symbol":"SCBTC"}}
1626318014.66364: {"jsonrpc":"2.0","method":"updateOrderbook","params":{"ask":[{"price":"0.616183","size":"5554.4"},{"price":"0.616186","size":"0"},{"price":"0.616322","size":"8521.0"},{"price":"0.616323","size":"6528.9"},{"price":"0.616325","size":"0"},{"price":"0.616508","size":"0"},{"price":"0.622068","size":"272131.6"},{"price":"0.626787","size":"0"},{"price":"0.641445","size":"347706.3"},{"price":"0.650427","size":"0"},{"price":"0.662654","size":"399052.4"}],"bid":[{"price":"0.615445","size":"2955.8"},{"price":"0.615098","size":"0"},{"price":"0.614984","size":"6463.9"},{"price":"0.590893","size":"4.3"}],"sequence":20583999,"timestamp":"2021-07-15T03:00:14.618Z","symbol":"XRPUSDT"}}
1626318014.683816: {"jsonrpc":"2.0","method":"updateOrderbook","params":{"ask":[{"price":"0.00000036792","size":"25530"},{"price":"0.00000036803","size":"0"}],"bid":[],"sequence":10532196,"timestamp":"2021-07-15T03:00:14.631Z","symbol":"SCBTC"}}
1626318014.683944: {"jsonrpc":"2.0","method":"updateOrderbook","params":{"ask":[{"price":"0.00054716","size":"276.50"},{"price":"0.00054737","size":"193.61"},{"price":"0.00054739","size":"0"},{"price":"0.00054768","size":"346.36"},{"price":"0.00057775","size":"0"},{"price":"0.00058185","size":"881.76"},{"price":"0.00076428","size":"0"},{"price":"0.00077082","size":"1125.76"},{"price":"0.00083297","size":"0"}],"bid":[],"sequence":19512999,"timestamp":"2021-07-15T03:00:14.638Z","symbol":"UNIBTC"}}
1626318014.7535958: {"jsonrpc":"2.0","method":"updateOrderbook","params":{"ask":[{"price":"0.641445","size":"0"},{"price":"0.643719","size":"347706.3"},{"price":"0.662654","size":"399052.7"}],"bid":[{"price":"0.613967","size":"7700.0"},{"price":"0.613871","size":"0"},{"price":"0.590005","size":"4.3"}],"sequence":20584000,"timestamp":"2021-07-15T03:00:14.740Z","symbol":"XRPUSDT"}}
1626318014.7733681: {"jsonrpc":"2.0","method":"updateOrderbook","params":{"ask":[{"price":"0.00054650","size":"18.88"},{"price":"0.00054678","size":"0"},{"price":"0.00054795","size":"291.41"},{"price":"0.00054818","size":"0"}],"bid":[],"sequence":19513000,"timestamp":"2021-07-15T03:00:14.704Z","symbol":"UNIBTC"}}
1626318014.851541: {"jsonrpc":"2.0","method":"updateOrderbook","params":{"ask":[{"price":"0.662654","size":"399052.9"}],"bid":[],"sequence":20584001,"timestamp":"2021-07-15T03:00:14.786Z","symbol":"XRPUSDT"}}
1626318014.871448: {"jsonrpc":"2.0","method":"updateOrderbook","params":{"ask":[{"price":"0.00000036891","size":"0"},{"price":"0.00000036912","size":"417100"},{"price":"0.00000065973","size":"15229670"}],"bid":[{"price":"0.00000036265","size":"1248220"},{"price":"0.00000035478","size":"0"}],"sequence":10532197,"timestamp":"2021-07-15T03:00:14.826Z","symbol":"SCBTC"}}
1626318014.87149: {"jsonrpc":"2.0","method":"updateOrderbook","params":{"ask":[{"price":"0.00054601","size":"0"},{"price":"0.00054608","size":"4.33"},{"price":"0.00054653","size":"199.63"},{"price":"0.00054664","size":"296.51"},{"price":"0.00054665","size":"77.40"},{"price":"0.00054682","size":"72.32"},{"price":"0.00054698","size":"0"},{"price":"0.00054715","size":"0"},{"price":"0.00054823","size":"0"},{"price":"0.00054869","size":"170.00"}],"bid":[],"sequence":19513001,"timestamp":"2021-07-15T03:00:14.831Z","symbol":"UNIBTC"}}
1626318014.962157: {"jsonrpc":"2.0","method":"updateOrderbook","params":{"ask":[{"price":"0.616682","size":"6433.6"},{"price":"0.616738","size":"0"},{"price":"0.624510","size":"129038.8"},{"price":"0.630946","size":"0"},{"price":"0.648218","size":"181214.3"},{"price":"0.655189","size":"0"},{"price":"0.662654","size":"399053.4"}],"bid":[{"price":"0.615586","size":"1591.6"},{"price":"0.615581","size":"0"},{"price":"0.589118","size":"4.3"}],"sequence":20584002,"timestamp":"2021-07-15T03:00:14.940Z","symbol":"XRPUSDT"}}
1626318014.962222: {"jsonrpc":"2.0","method":"updateOrderbook","params":{"ask":[],"bid":[{"price":"0.00000036540","size":"110390"},{"price":"0.00000036528","size":"0"}],"sequence":10532198,"timestamp":"2021-07-15T03:00:14.875Z","symbol":"SCBTC"}}
1626318015.155329: {"jsonrpc":"2.0","method":"updateOrderbook","params":{"ask":[{"price":"0.00054616","size":"0"},{"price":"0.00054624","size":"10.47"},{"price":"0.00054653","size":"0"},{"price":"0.00054664","size":"0"},{"price":"0.00054693","size":"199.63"},{"price":"0.00054711","size":"497.98"},{"price":"0.00054718","size":"169.84"},{"price":"0.00054763","size":"691.58"},{"price":"0.00054769","size":"0"},{"price":"0.00054803","size":"0"}],"bid":[{"price":"0.00054575","size":"5.18"},{"price":"0.00054569","size":"0"}],"sequence":19513002,"timestamp":"2021-07-15T03:00:14.929Z","symbol":"UNIBTC"}}
1626318015.155391: {"jsonrpc":"2.0","method":"updateOrderbook","params":{"ask":[{"price":"0.662654","size":"399053.5"}],"bid":[{"price":"0.588230","size":"4.3"}],"sequence":20584003,"timestamp":"2021-07-15T03:00:14.980Z","symbol":"XRPUSDT"}}
1626318015.155405: {"jsonrpc":"2.0","method":"updateOrderbook","params":{"ask":[{"price":"0.00054608","size":"0"},{"price":"0.00054610","size":"4.33"},{"price":"0.00054638","size":"0"},{"price":"0.00054652","size":"0"},{"price":"0.00054659","size":"16.70"},{"price":"0.00054670","size":"66.20"},{"price":"0.00054688","size":"201.47"},{"price":"0.00054711","size":"296.51"},{"price":"0.00068731","size":"2343.84"},{"price":"0.00070823","size":"0"},{"price":"0.00083296","size":"1585.64"}],"bid":[{"price":"0.00054578","size":"5.18"},{"price":"0.00054575","size":"0"},{"price":"0.00054529","size":"0"},{"price":"0.00054513","size":"0"},{"price":"0.00054506","size":"18.58"},{"price":"0.00054490","size":"250.70"},{"price":"0.00054446","size":"0"},{"price":"0.00054398","size":"331.21"}],"sequence":19513003,"timestamp":"2021-07-15T03:00:15.032Z","symbol":"UNIBTC"}}
1626318015.222827: {"jsonrpc":"2.0","method":"updateOrderbook","params":{"ask":[{"price":"0.662654","size":"399053.9"}],"bid":[],"sequence":20584004,"timestamp":"2021-07-15T03:00:15.119Z","symbol":"XRPUSDT"}}
1626318015.2228858: {"jsonrpc":"2.0","method":"updateOrderbook","params":{"ask":[{"price":"0.00000065973","size":"15229680"}],"bid":[{"price":"0.00000036540","size":"0"},{"price":"0.00000036528","size":"110390"}],"sequence":10532199,"timestamp":"2021-07-15T03:00:15.127Z","symbol":"SCBTC"}}
1626318015.222913: {"jsonrpc":"2.0","method":"updateOrderbook","params":{"ask":[{"price":"0.00054608","size":"4.33"},{"price":"0.00054610","size":"0"},{"price":"0.00054706","size":"333.84"},{"price":"0.00054731","size":"440.89"},{"price":"0.00054743","size":"0"},{"price":"0.00054763","size":"250.69"},{"price":"0.00054780","size":"0"},{"price":"0.00054814","size":"528.37"}],"bid":[{"price":"0.00054582","size":"5.18"},{"price":"0.00054578","size":"0"}],"sequence":19513004,"timestamp":"2021-07-15T03:00:15.136Z","symbol":"UNIBTC"}}
1626318015.223007: {"jsonrpc":"2.0","method":"updateOrderbook","params":{"ask":[],"bid":[{"price":"0.0000788","size":"39.275"},{"price":"0.0000787","size":"0"}],"sequence":2198421,"timestamp":"2021-07-15T03:00:15.049Z","symbol":"NUTBTC"}}
1626318015.311521: {"jsonrpc":"2.0","method":"updateOrderbook","params":{"ask":[{"price":"0.662654","size":"399054.1"}],"bid":[],"sequence":20584005,"timestamp":"2021-07-15T03:00:15.189Z","symbol":"XRPUSDT"}}
1626318015.311557: {"jsonrpc":"2.0","method":"updateOrderbook","params":{"ask":[],"bid":[{"price":"0.00054568","size":"9.62"},{"price":"0.00054559","size":"0"},{"price":"0.00054376","size":"679.54"},{"price":"0.00054353","size":"634.39"},{"price":"0.00054317","size":"929.35"},{"price":"0.00054304","size":"200.63"},{"price":"0.00054303","size":"0"},{"price":"0.00054246","size":"0"},{"price":"0.00052741","size":"2974.71"},{"price":"0.00051518","size":"0"}],"sequence":19513005,"timestamp":"2021-07-15T03:00:15.209Z","symbol":"UNIBTC"}}
1626318015.35478: {"jsonrpc":"2.0","method":"updateOrderbook","params":{"ask":[{"price":"0.617338","size":"5288.2"},{"price":"0.617777","size":"10926.9"},{"price":"0.617914","size":"0"},{"price":"0.618316","size":"0"},{"price":"0.662654","size":"399054.6"},{"price":"0.696287","size":"228479.7"},{"price":"0.703285","size":"0"}],"bid":[{"price":"0.587342","size":"4.3"}],"sequence":20584006,"timestamp":"2021-07-15T03:00:15.340Z","symbol":"XRPUSDT"}}
1626318015.3831239: {"jsonrpc":"2.0","method":"updateOrderbook","params":{"ask":[{"price":"0.00000065973","size":"15229690"}],"bid":[{"price":"0.00000024464","size":"1993120"},{"price":"0.00000011544","size":"0"},{"price":"0.00000000857","size":"2752080"}],"sequence":10532200,"timestamp":"2021-07-15T03:00:15.332Z","symbol":"SCBTC"}}
1626318015.3831658: {"jsonrpc":"2.0","method":"updateOrderbook","params":{"ask":[{"price":"0.00054643","size":"16.70"},{"price":"0.00054657","size":"66.20"},{"price":"0.00054659","size":"0"},{"price":"0.00054670","size":"0"},{"price":"0.00054823","size":"86.00"},{"price":"0.00054869","size":"84.00"}],"bid":[{"price":"0.00054582","size":"0"},{"price":"0.00054581","size":"5.18"}],"sequence":19513006,"timestamp":"2021-07-15T03:00:15.333Z","symbol":"UNIBTC"}}
1626318015.4462879: {"jsonrpc":"2.0","method":"updateOrderbook","params":{"ask":[],"bid":[{"price":"12.065","size":"11.9192"},{"price":"12.064","size":"0"},{"price":"12.063","size":"0"}],"sequence":2190657,"timestamp":"2021-07-15T03:00:15.434Z","symbol":"SPIUSD"}}
1626318015.4615119: {"jsonrpc":"2.0","method":"updateOrderbook","params":{"ask":[{"price":"0.624510","size":"0"},{"price":"0.627039","size":"129038.8"},{"price":"0.648218","size":"0"},{"price":"0.651700","size":"181214.3"},{"price":"0.662654","size":"399054.9"},{"price":"0.667764","size":"0"},{"price":"0.672296","size":"229002.7"},{"price":"0.696287","size":"0"},{"price":"0.701424","size":"228479.7"},{"price":"0.842694","size":"0"},{"price":"0.848572","size":"324970.5"}],"bid":[],"sequence":20584007,"timestamp":"2021-07-15T03:00:15.441Z","symbol":"XRPUSDT"}}
1626318015.475818: {"jsonrpc":"2.0","method":"updateOrderbook","params":{"ask":[{"price":"0.00054606","size":"4.33"},{"price":"0.00054608","size":"0"}],"bid":[{"price":"0.00054581","size":"0"},{"price":"0.00054577","size":"5.18"},{"price":"0.00054568","size":"0"},{"price":"0.00054563","size":"9.62"},{"price":"0.00054553","size":"18.03"},{"price":"0.00054524","size":"0"},{"price":"0.00054516","size":"80.24"},{"price":"0.00054501","size":"0"}],"sequence":19513007,"timestamp":"2021-07-15T03:00:15.440Z","symbol":"UNIBTC"}}
1626318015.5530229: {"jsonrpc":"2.0","method":"updateOrderbook","params":{"ask":[{"price":"0.662654","size":"399055.0"}],"bid":[{"price":"0.615594","size":"1591.6"},{"price":"0.615586","size":"0"},{"price":"0.586455","size":"4.3"}],"sequence":20584008,"timestamp":"2021-07-15T03:00:15.539Z","symbol":"XRPUSDT"}}
1626318015.563636: {"jsonrpc":"2.0","method":"updateOrderbook","params":{"ask":[{"price":"0.00054602","size":"4.33"},{"price":"0.00054606","size":"0"},{"price":"0.00054776","size":"528.37"},{"price":"0.00054814","size":"0"},{"price":"0.00056173","size":"1757.02"},{"price":"0.00056559","size":"0"}],"bid":[],"sequence":19513008,"timestamp":"2021-07-15T03:00:15.531Z","symbol":"UNIBTC"}}
1626318015.663262: {"jsonrpc":"2.0","method":"updateOrderbook","params":{"ask":[{"price":"0.662654","size":"399055.3"}],"bid":[{"price":"0.585567","size":"4.3"}],"sequence":20584009,"timestamp":"2021-07-15T03:00:15.567Z","symbol":"XRPUSDT"}}
1626318015.665617: {"jsonrpc":"2.0","method":"updateOrderbook","params":{"ask":[{"price":"0.00000065973","size":"15229700"}],"bid":[],"sequence":10532201,"timestamp":"2021-07-15T03:00:15.621Z","symbol":"SCBTC"}}
1626318015.66973: {"jsonrpc":"2.0","method":"updateOrderbook","params":{"ask":[{"price":"0.00054602","size":"0"},{"price":"0.00054609","size":"4.33"},{"price":"0.00054624","size":"0"},{"price":"0.00054626","size":"10.47"},{"price":"0.00054658","size":"216.59"},{"price":"0.00054669","size":"296.51"},{"price":"0.00054693","size":"0"},{"price":"0.00054696","size":"276.50"},{"price":"0.00054711","size":"0"},{"price":"0.00054716","size":"0"}],"bid":[{"price":"0.00054578","size":"5.18"},{"price":"0.00054577","size":"0"}],"sequence":19513009,"timestamp":"2021-07-15T03:00:15.622Z","symbol":"UNIBTC"}}
1626318015.758689: {"jsonrpc":"2.0","method":"updateOrderbook","params":{"ask":[{"price":"0.662654","size":"399055.7"}],"bid":[{"price":"0.584679","size":"4.3"}],"sequence":20584010,"timestamp":"2021-07-15T03:00:15.685Z","symbol":"XRPUSDT"}}
1626318015.758698: {"jsonrpc":"2.0","method":"updateOrderbook","params":{"ask":[],"bid":[{"price":"0.00000034658","size":"4600"},{"price":"0.00000034622","size":"230000"}],"sequence":10532202,"timestamp":"2021-07-15T03:00:15.719Z","symbol":"SCBTC"}}
1626318015.759727: {"jsonrpc":"2.0","method":"updateOrderbook","params":{"ask":[{"price":"0.00054609","size":"0"},{"price":"0.00054611","size":"4.33"},{"price":"0.00054658","size":"16.96"},{"price":"0.00054669","size":"0"},{"price":"0.00054693","size":"199.63"},{"price":"0.00054711","size":"296.51"}],"bid":[{"price":"0.00054585","size":"5.18"},{"price":"0.00054578","size":"0"},{"price":"0.00054571","size":"9.62"},{"price":"0.00054563","size":"0"}],"sequence":19513010,"timestamp":"2021-07-15T03:00:15.738Z","symbol":"UNIBTC"}}
1626318015.865955: {"jsonrpc":"2.0","method":"updateOrderbook","params":{"ask":[{"price":"0.662654","size":"399056.0"}],"bid":[{"price":"0.583792","size":"4.3"}],"sequence":20584011,"timestamp":"2021-07-15T03:00:15.791Z","symbol":"XRPUSDT"}}
1626318015.8660119: {"jsonrpc":"2.0","method":"updateOrderbook","params":{"ask":[{"price":"0.00054609","size":"4.33"},{"price":"0.00054611","size":"0"},{"price":"0.00054733","size":"346.36"},{"price":"0.00054768","size":"0"},{"price":"0.00055279","size":"1811.87"},{"price":"0.00055364","size":"0"},{"price":"0.00080159","size":"3484.36"},{"price":"0.00080659","size":"0"}],"bid":[{"price":"0.00054585","size":"0"},{"price":"0.00054583","size":"5.18"}],"sequence":19513011,"timestamp":"2021-07-15T03:00:15.829Z","symbol":"UNIBTC"}}
1626318015.979597: {"jsonrpc":"2.0","method":"updateOrderbook","params":{"ask":[{"price":"0.662654","size":"399056.3"}],"bid":[],"sequence":20584012,"timestamp":"2021-07-15T03:00:15.894Z","symbol":"XRPUSDT"}}
1626318015.9796538: {"jsonrpc":"2.0","method":"updateOrderbook","params":{"ask":[{"price":"0.00000036833","size":"101590"},{"price":"0.00000036837","size":"0"},{"price":"0.00000065973","size":"15229710"}],"bid":[{"price":"0.00000024464","size":"0"},{"price":"0.00000024410","size":"1993120"}],"sequence":10532203,"timestamp":"2021-07-15T03:00:15.915Z","symbol":"SCBTC"}}
1626318015.9796832: {"jsonrpc":"2.0","method":"updateOrderbook","params":{"ask":[{"price":"0.00054609","size":"0"},{"price":"0.00054611","size":"4.33"},{"price":"0.00054625","size":"10.47"},{"price":"0.00054626","size":"0"}],"bid":[{"price":"0.00054583","size":"0"},{"price":"0.00054582","size":"5.18"},{"price":"0.00054571","size":"0"},{"price":"0.00054565","size":"9.62"},{"price":"0.00054290","size":"0"},{"price":"0.00054219","size":"967.17"}],"sequence":19513012,"timestamp":"2021-07-15T03:00:15.934Z","symbol":"UNIBTC"}}
1626318016.07487: {"jsonrpc":"2.0","method":"updateOrderbook","params":{"ask":[{"price":"0.662654","size":"399056.7"}],"bid":[{"price":"0.615599","size":"1591.6"},{"price":"0.615594","size":"0"},{"price":"0.576549","size":"195374.1"},{"price":"0.573251","size":"0"}],"sequence":20584013,"timestamp":"2021-07-15T03:00:16.032Z","symbol":"XRPUSDT"}}
1626318016.07493: {"jsonrpc":"2.0","method":"updateOrderbook","params":{"ask":[],"bid":[{"price":"0.00000024410","size":"0"},{"price":"0.00000023898","size":"1993120"},{"price":"0.00000000857","size":"0"},{"price":"0.00000000723","size":"2752080"}],"sequence":10532204,"timestamp":"2021-07-15T03:00:15.993Z","symbol":"SCBTC"}}
1626318016.076319: {"jsonrpc":"2.0","method":"updateOrderbook","params":{"ask":[{"price":"0.00054607","size":"4.33"},{"price":"0.00054611","size":"0"}],"bid":[],"sequence":19513013,"timestamp":"2021-07-15T03:00:16.039Z","symbol":"UNIBTC"}}
1626318016.159214: {"jsonrpc":"2.0","method":"updateOrderbook","params":{"ask":[{"price":"0.641894","size":"347706.3"},{"price":"0.643719","size":"0"},{"price":"0.662654","size":"399056.9"}],"bid":[],"sequence":20584014,"timestamp":"2021-07-15T03:00:16.084Z","symbol":"XRPUSDT"}}
1626318016.17818: {"jsonrpc":"2.0","method":"updateOrderbook","params":{"ask":[{"price":"0.00000065973","size":"15229720"}],"bid":[],"sequence":10532205,"timestamp":"2021-07-15T03:00:16.100Z","symbol":"SCBTC"}}
1626318016.178242: {"jsonrpc":"2.0","method":"updateOrderbook","params":{"ask":[{"price":"0.00054605","size":"4.33"},{"price":"0.00054607","size":"0"}],"bid":[{"price":"0.00054583","size":"5.18"},{"price":"0.00054582","size":"0"}],"sequence":19513014,"timestamp":"2021-07-15T03:00:16.134Z","symbol":"UNIBTC"}}
1626318016.2617228: {"jsonrpc":"2.0","method":"updateOrderbook","params":{"ask":[{"price":"0.662654","size":"399057.2"}],"bid":[],"sequence":20584015,"timestamp":"2021-07-15T03:00:16.186Z","symbol":"XRPUSDT"}}
1626318016.2741299: {"jsonrpc":"2.0","method":"updateOrderbook","params":{"ask":[{"price":"0.00000036877","size":"255050"},{"price":"0.00000036897","size":"0"},{"price":"0.00000043223","size":"0"},{"price":"0.00000043635","size":"522810"},{"price":"0.00000054592","size":"0"},{"price":"0.00000054811","size":"757990"},{"price":"0.00000078158","size":"0"},{"price":"0.00000078433","size":"2003810"},{"price":"0.00000095829","size":"0"},{"price":"0.00000095888","size":"2754880"},{"price":"0.00000096953","size":"0"},{"price":"0.00000097026","size":"3422070"},{"price":"0.00000284910","size":"0"},{"price":"0.00000286068","size":"4472830"}],"bid":[{"price":"0.00000036564","size":"0"},{"price":"0.00000036528","size":"0"},{"price":"0.00000036520","size":"28670"},{"price":"0.00000036503","size":"110390"},{"price":"0.00000036434","size":"0"},{"price":"0.00000036392","size":"284390"},{"price":"0.00000034658","size":"234600"},{"price":"0.00000034622","size":"0"},{"price":"0.00000023898","size":"0"},{"price":"0.00000022599","size":"1993120"},{"price":"0.00000000723","size":"0"},{"price":"0.00000000436","size":"2752080"}],"sequence":10532206,"timestamp":"2021-07-15T03:00:16.218Z","symbol":"SCBTC"}}
1626318016.279635: {"jsonrpc":"2.0","method":"updateOrderbook","params":{"ask":[{"price":"0.00054619","size":"10.47"},{"price":"0.00054625","size":"0"}],"bid":[],"sequence":19513015,"timestamp":"2021-07-15T03:00:16.187Z","symbol":"UNIBTC"}}
1626318016.369403: {"jsonrpc":"2.0","method":"updateOrderbook","params":{"ask":[{"price":"0.662654","size":"399057.5"}],"bid":[],"sequence":20584016,"timestamp":"2021-07-15T03:00:16.277Z","symbol":"XRPUSDT"}}
1626318016.369427: {"jsonrpc":"2.0","method":"updateOrderbook","params":{"ask":[{"price":"0.00000038125","size":"603920"},{"price":"0.00000038575","size":"0"},{"price":"0.00000041214","size":"661850"},{"price":"0.00000041276","size":"0"},{"price":"0.00000094558","size":"0"},{"price":"0.00000094569","size":"2767750"}],"bid":[{"price":"0.00000036565","size":"0"},{"price":"0.00000036521","size":"1000"}],"sequence":10532207,"timestamp":"2021-07-15T03:00:16.310Z","symbol":"SCBTC"}}
1626318016.369476: {"jsonrpc":"2.0","method":"updateOrderbook","params":{"ask":[{"price":"0.00054632","size":"16.70"},{"price":"0.00054643","size":"0"},{"price":"0.00055683","size":"2539.46"},{"price":"0.00057102","size":"0"}],"bid":[{"price":"0.00054286","size":"0"},{"price":"0.00054234","size":"84.00"}],"sequence":19513016,"timestamp":"2021-07-15T03:00:16.335Z","symbol":"UNIBTC"}}
1626318016.472053: {"jsonrpc":"2.0","method":"updateOrderbook","params":{"ask":[{"price":"0.662654","size":"399057.8"}],"bid":[{"price":"0.615603","size":"1591.6"},{"price":"0.615599","size":"0"}],"sequence":20584017,"timestamp":"2021-07-15T03:00:16.393Z","symbol":"XRPUSDT"}}
1626318016.472111: {"jsonrpc":"2.0","method":"updateOrderbook","params":{"ask":[{"price":"0.00000065973","size":"15229750"},{"price":"0.00000094569","size":"2767780"}],"bid":[],"sequence":10532208,"timestamp":"2021-07-15T03:00:16.422Z","symbol":"SCBTC"}}
1626318016.472136: {"jsonrpc":"2.0","method":"updateOrderbook","params":{"ask":[{"price":"0.00054605","size":"0"},{"price":"0.00054608","size":"4.33"}],"bid":[{"price":"0.00054585","size":"5.18"},{"price":"0.00054583","size":"0"}],"sequence":19513017,"timestamp":"2021-07-15T03:00:16.435Z","symbol":"UNIBTC"}}
1626318016.47222: {"jsonrpc":"2.0","method":"updateOrderbook","params":{"ask":[{"price":"0.0004396","size":"47.197"},{"price":"0.0004397","size":"0"}],"bid":[],"sequence":2198422,"timestamp":"2021-07-15T03:00:16.438Z","symbol":"NUTBTC"}}
1626318016.579276: {"jsonrpc":"2.0","method":"updateOrderbook","params":{"ask":[{"price":"0.662654","size":"399058.2"}],"bid":[{"price":"0.610484","size":"91768.8"},{"price":"0.602219","size":"0"}],"sequence":20584018,"timestamp":"2021-07-15T03:00:16.497Z","symbol":"XRPUSDT"}}
1626318016.579335: {"jsonrpc":"2.0","method":"updateOrderbook","params":{"ask":[{"price":"0.00000065973","size":"15229770"},{"price":"0.00000094569","size":"2767800"}],"bid":[],"sequence":10532209,"timestamp":"2021-07-15T03:00:16.527Z","symbol":"SCBTC"}}
1626318016.579359: {"jsonrpc":"2.0","method":"updateOrderbook","params":{"ask":[{"price":"0.00055065","size":"805.27"},{"price":"0.00055135","size":"0"}],"bid":[{"price":"0.00054586","size":"5.18"},{"price":"0.00054585","size":"0"}],"sequence":19513018,"timestamp":"2021-07-15T03:00:16.532Z","symbol":"UNIBTC"}}
1626318016.6560042: {"jsonrpc":"2.0","method":"updateOrderbook","params":{"ask":[{"price":"10000.000","size":"0.0011"}],"bid":[{"price":"0.010","size":"1000.0011"}],"sequence":2190658,"timestamp":"2021-07-15T03:00:16.554Z","symbol":"SPIUSD"}}
1626318016.656061: {"jsonrpc":"2.0","method":"updateOrderbook","params":{"ask":[{"price":"0.662654","size":"399058.4"}],"bid":[{"price":"0.615139","size":"0"},{"price":"0.614980","size":"13468.6"}],"sequence":20584019,"timestamp":"2021-07-15T03:00:16.564Z","symbol":"XRPUSDT"}}
1626318016.6675699: {"jsonrpc":"2.0","method":"updateOrderbook","params":{"ask":[{"price":"0.00000036726","size":"25530"},{"price":"0.00000036792","size":"0"},{"price":"0.00000065973","size":"15229790"},{"price":"0.00000094569","size":"2767820"}],"bid":[],"sequence":10532210,"timestamp":"2021-07-15T03:00:16.632Z","symbol":"SCBTC"}}
1626318016.667659: {"jsonrpc":"2.0","method":"updateOrderbook","params":{"ask":[{"price":"0.00055060","size":"843.90"},{"price":"0.00055113","size":"0"}],"bid":[{"price":"0.00054571","size":"9.62"},{"price":"0.00054565","size":"0"}],"sequence":19513019,"timestamp":"2021-07-15T03:00:16.606Z","symbol":"UNIBTC"}}
1626318016.746583: {"jsonrpc":"2.0","method":"updateOrderbook","params":{"ask":[],"bid":[{"price":"12.066","size":"5.7269"},{"price":"12.065","size":"5.8922"}],"sequence":2190659,"timestamp":"2021-07-15T03:00:16.702Z","symbol":"SPIUSD"}}
1626318016.7542021: {"jsonrpc":"2.0","method":"updateOrderbook","params":{"ask":[{"price":"0.662654","size":"399058.8"}],"bid":[{"price":"0.614838","size":"0"},{"price":"0.614758","size":"44970.5"}],"sequence":20584020,"timestamp":"2021-07-15T03:00:16.711Z","symbol":"XRPUSDT"}}
1626318016.7762518: {"jsonrpc":"2.0","method":"updateOrderbook","params":{"ask":[{"price":"0.00000065973","size":"15229800"},{"price":"0.00000094569","size":"2767840"}],"bid":[{"price":"0.00000036521","size":"0"},{"price":"0.00000036504","size":"1000"}],"sequence":10532211,"timestamp":"2021-07-15T03:00:16.703Z","symbol":"SCBTC"}}
1626318016.77634: {"jsonrpc":"2.0","method":"updateOrderbook","params":{"ask":[],"bid":[{"price":"0.00054586","size":"0"},{"price":"0.00054585","size":"5.18"},{"price":"0.00054286","size":"84.00"},{"price":"0.00054234","size":"0"}],"sequence":19513020,"timestamp":"2021-07-15T03:00:16.739Z","symbol":"UNIBTC"}}
1626318016.8529642: {"jsonrpc":"2.0","method":"updateOrderbook","params":{"ask":[{"price":"0.662654","size":"399059.1"}],"bid":[{"price":"0.615608","size":"1591.6"},{"price":"0.615603","size":"0"}],"sequence":20584021,"timestamp":"2021-07-15T03:00:16.800Z","symbol":"XRPUSDT"}}
1626318016.875063: {"jsonrpc":"2.0","method":"updateOrderbook","params":{"ask":[{"price":"0.00000041218","size":"1016210"},{"price":"0.00000042978","size":"0"},{"price":"0.00000043922","size":"1381850"},{"price":"0.00000063201","size":"0"},{"price":"0.00000065973","size":"15229830"},{"price":"0.00000094569","size":"2767870"}],"bid":[{"price":"0.00000034658","size":"4600"},{"price":"0.00000034622","size":"230000"}],"sequence":10532212,"timestamp":"2021-07-15T03:00:16.823Z","symbol":"SCBTC"}}
1626318016.875108: {"jsonrpc":"2.0","method":"updateOrderbook","params":{"ask":[{"price":"0.00054803","size":"658.12"},{"price":"0.00055031","size":"0"}],"bid":[{"price":"0.00054286","size":"0"},{"price":"0.00054234","size":"84.00"}],"sequence":19513021,"timestamp":"2021-07-15T03:00:16.828Z","symbol":"UNIBTC"}}
1626318016.952254: {"jsonrpc":"2.0","method":"updateOrderbook","params":{"ask":[{"price":"0.616627","size":"6433.6"},{"price":"0.616682","size":"0"},{"price":"0.662654","size":"399059.4"}],"bid":[{"price":"0.615479","size":"2955.8"},{"price":"0.615445","size":"0"}],"sequence":20584022,"timestamp":"2021-07-15T03:00:16.914Z","symbol":"XRPUSDT"}}
1626318016.962888: {"jsonrpc":"2.0","method":"updateOrderbook","params":{"ask":[{"price":"0.00000065973","size":"15229850"},{"price":"0.00000094569","size":"2767890"}],"bid":[],"sequence":10532213,"timestamp":"2021-07-15T03:00:16.930Z","symbol":"SCBTC"}}
1626318016.962928: {"jsonrpc":"2.0","method":"updateOrderbook","params":{"ask":[{"price":"0.00054606","size":"4.33"},{"price":"0.00054608","size":"0"}],"bid":[{"price":"0.00054585","size":"0"},{"price":"0.00054581","size":"5.18"},{"price":"0.00054571","size":"0"},{"price":"0.00054566","size":"9.62"},{"price":"0.00054286","size":"84.00"},{"price":"0.00054234","size":"0"}],"sequence":19513022,"timestamp":"2021-07-15T03:00:16.942Z","symbol":"UNIBTC"}}
1626318017.054125: {"jsonrpc":"2.0","method":"updateOrderbook","params":{"ask":[],"bid":[{"price":"12.067","size":"5.8913"},{"price":"12.065","size":"0"}],"sequence":2190660,"timestamp":"2021-07-15T03:00:17.024Z","symbol":"SPIUSD"}}
1626318017.0586638: {"jsonrpc":"2.0","method":"updateOrderbook","params":{"ask":[{"price":"0.662654","size":"399059.8"},{"price":"0.701424","size":"0"},{"price":"0.703123","size":"228479.7"}],"bid":[{"price":"0.615646","size":"1591.6"},{"price":"0.615608","size":"0"}],"sequence":20584023,"timestamp":"2021-07-15T03:00:17.023Z","symbol":"XRPUSDT"}}
1626318017.068245: {"jsonrpc":"2.0","method":"updateOrderbook","params":{"ask":[{"price":"0.00000065973","size":"15229870"},{"price":"0.00000094569","size":"2767910"}],"bid":[],"sequence":10532214,"timestamp":"2021-07-15T03:00:17.036Z","symbol":"SCBTC"}}
1626318017.07279: {"jsonrpc":"2.0","method":"updateOrderbook","params":{"ask":[{"price":"0.00054604","size":"4.33"},{"price":"0.00054606","size":"0"},{"price":"0.00054851","size":"433.80"},{"price":"0.00054977","size":"0"}],"bid":[{"price":"0.00054292","size":"914.50"},{"price":"0.00054203","size":"0"}],"sequence":19513023,"timestamp":"2021-07-15T03:00:17.034Z","symbol":"UNIBTC"}}
1626318017.072885: {"jsonrpc":"2.0","method":"updateOrderbook","params":{"ask":[{"price":"0.0004396","size":"0"},{"price":"0.0004397","size":"47.197"}],"bid":[],"sequence":2198423,"timestamp":"2021-07-15T03:00:16.980Z","symbol":"NUTBTC"}}
1626318017.146901: {"jsonrpc":"2.0","method":"updateOrderbook","params":{"ask":[],"bid":[{"price":"12.068","size":"5.7295"},{"price":"12.066","size":"0"}],"sequence":2190661,"timestamp":"2021-07-15T03:00:17.084Z","symbol":"SPIUSD"}}
1626318017.1579368: {"jsonrpc":"2.0","method":"updateOrderbook","params":{"ask":[{"price":"0.627039","size":"0"},{"price":"0.628174","size":"129038.8"},{"price":"0.651700","size":"0"},{"price":"0.652912","size":"181214.3"},{"price":"0.662654","size":"399060.0"},{"price":"0.703123","size":"0"}],"bid":[{"price":"0.615646","size":"0"},{"price":"0.615641","size":"1591.6"},{"price":"0.615513","size":"2955.8"},{"price":"0.615479","size":"0"}],"sequence":20584024,"timestamp":"2021-07-15T03:00:17.099Z","symbol":"XRPUSDT"}}
1626318017.175952: {"jsonrpc":"2.0","method":"updateOrderbook","params":{"ask":[{"price":"0.00000065973","size":"15229890"},{"price":"0.00000094569","size":"2767940"}],"bid":[],"sequence":10532215,"timestamp":"2021-07-15T03:00:17.141Z","symbol":"SCBTC"}}
1626318017.175971: {"jsonrpc":"2.0","method":"updateOrderbook","params":{"ask":[{"price":"0.00054602","size":"4.33"},{"price":"0.00054604","size":"0"},{"price":"0.00065925","size":"2343.84"},{"price":"0.00068731","size":"0"}],"bid":[{"price":"0.00054581","size":"0"},{"price":"0.00054579","size":"5.18"},{"price":"0.00054286","size":"0"},{"price":"0.00054234","size":"84.00"}],"sequence":19513024,"timestamp":"2021-07-15T03:00:17.135Z","symbol":"UNIBTC"}}
1626318017.26294: {"jsonrpc":"2.0","method":"updateOrderbook","params":{"ask":[{"price":"0.615742","size":"1331.7"},{"price":"0.615749","size":"0"},{"price":"0.641894","size":"0"},{"price":"0.643681","size":"347706.3"},{"price":"0.662654","size":"399060.3"}],"bid":[{"price":"0.615651","size":"1591.6"},{"price":"0.615641","size":"0"}],"sequence":20584025,"timestamp":"2021-07-15T03:00:17.206Z","symbol":"XRPUSDT"}}
1626318017.267212: {"jsonrpc":"2.0","method":"updateOrderbook","params":{"ask":[{"price":"0.00000043863","size":"1381850"},{"price":"0.00000043922","size":"0"},{"price":"0.00000065973","size":"15229910"},{"price":"0.00000094569","size":"2767960"}],"bid":[],"sequence":10532216,"timestamp":"2021-07-15T03:00:17.219Z","symbol":"SCBTC"}}
1626318017.267253: {"jsonrpc":"2.0","method":"updateOrderbook","params":{"ask":[{"price":"0.00054598","size":"4.33"},{"price":"0.00054602","size":"0"},{"price":"0.00054642","size":"66.20"},{"price":"0.00054657","size":"0"}],"bid":[{"price":"0.00053567","size":"2974.71"},{"price":"0.00052741","size":"0"}],"sequence":19513025,"timestamp":"2021-07-15T03:00:17.210Z","symbol":"UNIBTC"}}
1626318017.34932: {"jsonrpc":"2.0","method":"updateOrderbook","params":{"ask":[{"price":"0.662654","size":"399060.6"}],"bid":[],"sequence":20584026,"timestamp":"2021-07-15T03:00:17.279Z","symbol":"XRPUSDT"}}
1626318017.363345: {"jsonrpc":"2.0","method":"updateOrderbook","params":{"ask":[{"price":"0.00000036888","size":"417100"},{"price":"0.00000036912","size":"0"},{"price":"0.00000065973","size":"15229930"},{"price":"0.00000087979","size":"2001500"},{"price":"0.00000094569","size":"2767980"},{"price":"0.00000107948","size":"0"},{"price":"0.00000124326","size":"2705250"},{"price":"0.00000132071","size":"0"}],"bid":[{"price":"0.00000036534","size":"28670"},{"price":"0.00000036520","size":"0"},{"price":"0.00000036514","size":"110390"},{"price":"0.00000036503","size":"0"}],"sequence":10532217,"timestamp":"2021-07-15T03:00:17.322Z","symbol":"SCBTC"}}
1626318017.3702981: {"jsonrpc":"2.0","method":"updateOrderbook","params":{"ask":[{"price":"0.00054738","size":"666.24"},{"price":"0.00054773","size":"963.50"},{"price":"0.00054785","size":"0"},{"price":"0.00054824","size":"0"},{"price":"0.00054841","size":"375.71"},{"price":"0.00054870","size":"0"}],"bid":[],"sequence":19513026,"timestamp":"2021-07-15T03:00:17.317Z","symbol":"UNIBTC"}}
1626318017.455403: {"jsonrpc":"2.0","method":"updateOrderbook","params":{"ask":[{"price":"0.662654","size":"399060.9"}],"bid":[],"sequence":20584027,"timestamp":"2021-07-15T03:00:17.385Z","symbol":"XRPUSDT"}}
1626318017.469038: {"jsonrpc":"2.0","method":"updateOrderbook","params":{"ask":[{"price":"0.00000065973","size":"15229950"},{"price":"0.00000094569","size":"2767990"}],"bid":[],"sequence":10532218,"timestamp":"2021-07-15T03:00:17.427Z","symbol":"SCBTC"}}
1626318017.469097: {"jsonrpc":"2.0","method":"updateOrderbook","params":{"ask":[{"price":"0.00054613","size":"10.47"},{"price":"0.00054619","size":"0"}],"bid":[],"sequence":19513027,"timestamp":"2021-07-15T03:00:17.394Z","symbol":"UNIBTC"}}
1626318017.5525289: {"jsonrpc":"2.0","method":"updateOrderbook","params":{"ask":[{"price":"0.662654","size":"399061.2"}],"bid":[],"sequence":20584028,"timestamp":"2021-07-15T03:00:17.485Z","symbol":"XRPUSDT"}}
1626318017.5640588: {"jsonrpc":"2.0","method":"updateOrderbook","params":{"ask":[{"price":"0.00000043863","size":"0"},{"price":"0.00000043994","size":"1381850"},{"price":"0.00000065973","size":"15229960"},{"price":"0.00000087979","size":"0"},{"price":"0.00000088323","size":"2001500"},{"price":"0.00000094569","size":"2768000"},{"price":"0.00000124326","size":"0"},{"price":"0.00000124431","size":"2705250"}],"bid":[{"price":"0.00000034658","size":"234600"},{"price":"0.00000034622","size":"0"}],"sequence":10532219,"timestamp":"2021-07-15T03:00:17.496Z","symbol":"SCBTC"}}
1626318017.570842: {"jsonrpc":"2.0","method":"updateOrderbook","params":{"ask":[{"price":"0.00054653","size":"199.63"},{"price":"0.00054664","size":"296.51"},{"price":"0.00054693","size":"0"},{"price":"0.00054711","size":"0"},{"price":"0.00055048","size":"662.81"},{"price":"0.00055297","size":"0"},{"price":"0.00055868","size":"881.76"},{"price":"0.00058185","size":"0"}],"bid":[],"sequence":19513028,"timestamp":"2021-07-15T03:00:17.493Z","symbol":"UNIBTC"}}
1626318017.6560462: {"jsonrpc":"2.0","method":"updateOrderbook","params":{"ask":[{"price":"0.662654","size":"399061.5"}],"bid":[{"price":"0.615656","size":"1591.6"},{"price":"0.615651","size":"0"}],"sequence":20584029,"timestamp":"2021-07-15T03:00:17.601Z","symbol":"XRPUSDT"}}
1626318017.672153: {"jsonrpc":"2.0","method":"updateOrderbook","params":{"ask":[{"price":"0.00000036737","size":"101590"},{"price":"0.00000036833","size":"0"},{"price":"0.00000065973","size":"15229970"},{"price":"0.00000094569","size":"2768020"}],"bid":[],"sequence":10532220,"timestamp":"2021-07-15T03:00:17.590Z","symbol":"SCBTC"}}
1626318017.672212: {"jsonrpc":"2.0","method":"updateOrderbook","params":{"ask":[{"price":"0.00054655","size":"18.08"},{"price":"0.00054676","size":"0"},{"price":"0.00054823","size":"1388.32"},{"price":"0.00055008","size":"0"}],"bid":[{"price":"0.00054580","size":"5.18"},{"price":"0.00054579","size":"0"}],"sequence":19513029,"timestamp":"2021-07-15T03:00:17.573Z","symbol":"UNIBTC"}}
1626318017.747825: {"jsonrpc":"2.0","method":"updateOrderbook","params":{"ask":[],"bid":[{"price":"12.067","size":"0"}],"sequence":2190662,"timestamp":"2021-07-15T03:00:17.722Z","symbol":"SPIUSD"}}
1626318017.753335: {"jsonrpc":"2.0","method":"updateOrderbook","params":{"ask":[{"price":"0.662654","size":"399061.9"}],"bid":[],"sequence":20584030,"timestamp":"2021-07-15T03:00:17.704Z","symbol":"XRPUSDT"}}
1626318017.7703948: {"jsonrpc":"2.0","method":"updateOrderbook","params":{"ask":[{"price":"0.00000065973","size":"15229990"},{"price":"0.00000094569","size":"2768030"}],"bid":[],"sequence":10532221,"timestamp":"2021-07-15T03:00:17.696Z","symbol":"SCBTC"}}
1626318017.770454: {"jsonrpc":"2.0","method":"updateOrderbook","params":{"ask":[{"price":"0.00054597","size":"4.33"},{"price":"0.00054598","size":"0"}],"bid":[],"sequence":19513030,"timestamp":"2021-07-15T03:00:17.728Z","symbol":"UNIBTC"}}
1626318017.8440168: {"jsonrpc":"2.0","method":"updateOrderbook","params":{"ask":[],"bid":[{"price":"12.069","size":"5.8903"},{"price":"12.068","size":"0"},{"price":"12.060","size":"5.7321"}],"sequence":2190663,"timestamp":"2021-07-15T03:00:17.826Z","symbol":"SPIUSD"}}
1626318017.8499022: {"jsonrpc":"2.0","method":"updateOrderbook","params":{"ask":[{"price":"0.662654","size":"399062.2"}],"bid":[],"sequence":20584031,"timestamp":"2021-07-15T03:00:17.809Z","symbol":"XRPUSDT"}}
1626318017.861747: {"jsonrpc":"2.0","method":"updateOrderbook","params":{"ask":[{"price":"0.00000065973","size":"15230000"},{"price":"0.00000094569","size":"2768050"},{"price":"0.00000146767","size":"3222000"},{"price":"0.00000148986","size":"0"},{"price":"0.00000159009","size":"4634410"},{"price":"0.00000167678","size":"0"}],"bid":[{"price":"0.00000036515","size":"1000"},{"price":"0.00000036504","size":"0"},{"price":"0.00000036454","size":"284390"},{"price":"0.00000036392","size":"0"}],"sequence":10532222,"timestamp":"2021-07-15T03:00:17.789Z","symbol":"SCBTC"}}
1626318017.861814: {"jsonrpc":"2.0","method":"updateOrderbook","params":{"ask":[{"price":"0.00054822","size":"84.00"},{"price":"0.00054869","size":"0"}],"bid":[],"sequence":19513031,"timestamp":"2021-07-15T03:00:17.836Z","symbol":"UNIBTC"}}
1626318017.946831: {"jsonrpc":"2.0","method":"updateOrderbook","params":{"ask":[],"bid":[{"price":"12.070","size":"5.7347"},{"price":"12.060","size":"0"}],"sequence":2190664,"timestamp":"2021-07-15T03:00:17.867Z","symbol":"SPIUSD"}}
1626318017.966229: {"jsonrpc":"2.0","method":"updateOrderbook","params":{"ask":[{"price":"0.662654","size":"399062.4"}],"bid":[],"sequence":20584032,"timestamp":"2021-07-15T03:00:17.894Z","symbol":"XRPUSDT"}}
1626318017.9662678: {"jsonrpc":"2.0","method":"updateOrderbook","params":{"ask":[{"price":"0.00000065973","size":"15230020"},{"price":"0.00000094569","size":"2768060"}],"bid":[{"price":"0.00000034658","size":"4600"},{"price":"0.00000034622","size":"230000"}],"sequence":10532223,"timestamp":"2021-07-15T03:00:17.872Z","symbol":"SCBTC"}}
1626318017.9662862: {"jsonrpc":"2.0","method":"updateOrderbook","params":{"ask":[{"price":"0.00054593","size":"4.33"},{"price":"0.00054597","size":"0"}],"bid":[{"price":"0.00054580","size":"0"},{"price":"0.00054576","size":"5.18"},{"price":"0.00054566","size":"0"},{"price":"0.00054559","size":"9.62"},{"price":"0.00054417","size":"0"},{"price":"0.00054408","size":"1.17"}],"sequence":19513032,"timestamp":"2021-07-15T03:00:17.937Z","symbol":"UNIBTC"}}
1626318018.0813131: {"jsonrpc":"2.0","method":"updateOrderbook","params":{"ask":[{"price":"0.662654","size":"399062.8"},{"price":"0.702918","size":"228479.7"}],"bid":[],"sequence":20584033,"timestamp":"2021-07-15T03:00:18.006Z","symbol":"XRPUSDT"}}
1626318018.081354: {"jsonrpc":"2.0","method":"updateOrderbook","params":{"ask":[{"price":"0.00000041218","size":"0"},{"price":"0.00000041336","size":"1016210"},{"price":"0.00000043994","size":"0"},{"price":"0.00000044175","size":"1381850"},{"price":"0.00000065973","size":"15230040"},{"price":"0.00000088323","size":"0"},{"price":"0.00000088939","size":"2001500"},{"price":"0.00000094569","size":"2768080"},{"price":"0.00000124431","size":"0"},{"price":"0.00000124589","size":"2705250"},{"price":"0.00000146767","size":"0"},{"price":"0.00000146941","size":"3222000"},{"price":"0.00000159009","size":"0"},{"price":"0.00000161545","size":"4634410"}],"bid":[],"sequence":10532224,"timestamp":"2021-07-15T03:00:18.012Z","symbol":"SCBTC"}}
1626318018.081378: {"jsonrpc":"2.0","method":"updateOrderbook","params":{"ask":[{"price":"0.00068955","size":"1125.76"},{"price":"0.00077082","size":"0"}],"bid":[{"price":"0.00054286","size":"84.00"},{"price":"0.00054234","size":"0"}],"sequence":19513033,"timestamp":"2021-07-15T03:00:18.031Z","symbol":"UNIBTC"}}
1626318018.1663418: {"jsonrpc":"2.0","method":"updateOrderbook","params":{"ask":[{"price":"0.662654","size":"399063.0"},{"price":"0.702918","size":"0"}],"bid":[],"sequence":20584034,"timestamp":"2021-07-15T03:00:18.075Z","symbol":"XRPUSDT"}}
1626318018.1664: {"jsonrpc":"2.0","method":"updateOrderbook","params":{"ask":[{"price":"0.00000036748","size":"255050"},{"price":"0.00000036784","size":"408320"},{"price":"0.00000036877","size":"0"},{"price":"0.00000036909","size":"0"},{"price":"0.00000065973","size":"15230060"},{"price":"0.00000088939","size":"0"},{"price":"0.00000089027","size":"2001500"},{"price":"0.00000094569","size":"2768090"}],"bid":[{"price":"0.00000036411","size":"384900"},{"price":"0.00000036354","size":"0"}],"sequence":10532225,"timestamp":"2021-07-15T03:00:18.139Z","symbol":"SCBTC"}}
1626318018.1664371: {"jsonrpc":"2.0","method":"updateOrderbook","params":{"ask":[],"bid":[{"price":"0.00054576","size":"0"},{"price":"0.00054575","size":"5.18"}],"sequence":19513034,"timestamp":"2021-07-15T03:00:18.120Z","symbol":"UNIBTC"}}
1626318018.255299: {"jsonrpc":"2.0","method":"updateOrderbook","params":{"ask":[{"price":"0.641909","size":"347706.3"},{"price":"0.643681","size":"0"},{"price":"0.662654","size":"399063.4"}],"bid":[],"sequence":20584035,"timestamp":"2021-07-15T03:00:18.210Z","symbol":"XRPUSDT"}}
1626318018.2734022: {"jsonrpc":"2.0","method":"updateOrderbook","params":{"ask":[{"price":"0.00000043202","size":"522810"},{"price":"0.00000043635","size":"0"},{"price":"0.00000054581","size":"757990"},{"price":"0.00000054811","size":"0"},{"price":"0.00000065973","size":"15230070"},{"price":"0.00000094569","size":"2768110"}],"bid":[{"price":"0.00000034658","size":"234600"},{"price":"0.00000034622","size":"0"}],"sequence":10532226,"timestamp":"2021-07-15T03:00:18.230Z","symbol":"SCBTC"}}
1626318018.2734668: {"jsonrpc":"2.0","method":"updateOrderbook","params":{"ask":[{"price":"0.00054593","size":"0"},{"price":"0.00054594","size":"4.33"},{"price":"0.00054621","size":"16.70"},{"price":"0.00054632","size":"0"}],"bid":[],"sequence":19513035,"timestamp":"2021-07-15T03:00:18.203Z","symbol":"UNIBTC"}}
1626318018.4094641: {"jsonrpc":"2.0","method":"updateOrderbook","params":{"ask":[{"price":"0.662654","size":"399063.6"}],"bid":[],"sequence":20584036,"timestamp":"2021-07-15T03:00:18.277Z","symbol":"XRPUSDT"}}
1626318018.4095209: {"jsonrpc":"2.0","method":"updateOrderbook","params":{"ask":[{"price":"0.00000041336","size":"0"},{"price":"0.00000041390","size":"1016210"},{"price":"0.00000044175","size":"0"},{"price":"0.00000044361","size":"1381850"},{"price":"0.00000065973","size":"15230080"},{"price":"0.00000089027","size":"0"},{"price":"0.00000089590","size":"2001500"},{"price":"0.00000094569","size":"2768120"},{"price":"0.00000124589","size":"0"},{"price":"0.00000124728","size":"2705250"},{"price":"0.00000146941","size":"0"},{"price":"0.00000147053","size":"3222000"},{"price":"0.00000384260","size":"7466230"},{"price":"0.00000472388","size":"0"}],"bid":[{"price":"0.00000034658","size":"4600"},{"price":"0.00000034622","size":"230000"}],"sequence":10532227,"timestamp":"2021-07-15T03:00:18.305Z","symbol":"SCBTC"}}
1626318018.40956: {"jsonrpc":"2.0","method":"updateOrderbook","params":{"ask":[{"price":"0.00054772","size":"331.40"},{"price":"0.00054811","size":"0"}],"bid":[{"price":"0.00054286","size":"0"},{"price":"0.00054234","size":"84.00"}],"sequence":19513036,"timestamp":"2021-07-15T03:00:18.327Z","symbol":"UNIBTC"}}
1626318018.467335: {"jsonrpc":"2.0","method":"updateOrderbook","params":{"ask":[{"price":"0.662654","size":"399064.0"}],"bid":[{"price":"0.581347","size":"195374.1"},{"price":"0.576549","size":"0"}],"sequence":20584037,"timestamp":"2021-07-15T03:00:18.408Z","symbol":"XRPUSDT"}}
1626318018.4704762: {"jsonrpc":"2.0","method":"updateOrderbook","params":{"ask":[{"price":"0.00000065973","size":"15230100"},{"price":"0.00000094569","size":"2768140"},{"price":"0.00000095828","size":"2754880"},{"price":"0.00000095888","size":"0"}],"bid":[],"sequence":10532228,"timestamp":"2021-07-15T03:00:18.404Z","symbol":"SCBTC"}}
1626318018.555816: {"jsonrpc":"2.0","method":"updateOrderbook","params":{"ask":[{"price":"0.662654","size":"399064.3"}],"bid":[],"sequence":20584038,"timestamp":"2021-07-15T03:00:18.511Z","symbol":"XRPUSDT"}}
1626318018.5744529: {"jsonrpc":"2.0","method":"updateOrderbook","params":{"ask":[{"price":"0.00000065973","size":"15230120"},{"price":"0.00000094569","size":"2768150"}],"bid":[],"sequence":10532229,"timestamp":"2021-07-15T03:00:18.515Z","symbol":"SCBTC"}}
1626318018.574513: {"jsonrpc":"2.0","method":"updateOrderbook","params":{"ask":[],"bid":[{"price":"0.00054576","size":"5.18"},{"price":"0.00054575","size":"0"},{"price":"0.00054486","size":"0"},{"price":"0.00054460","size":"261.13"},{"price":"0.00054292","size":"0"},{"price":"0.00054241","size":"914.50"},{"price":"0.00053567","size":"0"},{"price":"0.00053397","size":"2974.71"}],"sequence":19513037,"timestamp":"2021-07-15T03:00:18.531Z","symbol":"UNIBTC"}}
1626318018.6654139: {"jsonrpc":"2.0","method":"updateOrderbook","params":{"ask":[{"price":"0.662654","size":"399064.6"},{"price":"0.702918","size":"228479.7"}],"bid":[{"price":"0.615238","size":"0"},{"price":"0.615195","size":"1337.0"},{"price":"0.614682","size":"0"},{"price":"0.614441","size":"1950.1"}],"sequence":20584039,"timestamp":"2021-07-15T03:00:18.593Z","symbol":"XRPUSDT"}}
1626318018.669989: {"jsonrpc":"2.0","method":"updateOrderbook","params":{"ask":[{"price":"0.00000036910","size":"603920"},{"price":"0.00000037415","size":"661850"},{"price":"0.00000038125","size":"0"},{"price":"0.00000041214","size":"0"},{"price":"0.00000065973","size":"15230130"},{"price":"0.00000094569","size":"2768170"}],"bid":[],"sequence":10532230,"timestamp":"2021-07-15T03:00:18.620Z","symbol":"SCBTC"}}
1626318018.670033: {"jsonrpc":"2.0","method":"updateOrderbook","params":{"ask":[{"price":"0.00054590","size":"4.33"},{"price":"0.00054594","size":"0"},{"price":"0.00054654","size":"77.40"},{"price":"0.00054665","size":"0"},{"price":"0.00054671","size":"201.47"},{"price":"0.00054688","size":"0"}],"bid":[{"price":"0.00054576","size":"0"},{"price":"0.00054567","size":"5.18"},{"price":"0.00054559","size":"0"},{"price":"0.00054553","size":"0"},{"price":"0.00054548","size":"9.62"},{"price":"0.00054533","size":"18.03"},{"price":"0.00054531","size":"0"},{"price":"0.00054508","size":"17.87"}],"sequence":19513038,"timestamp":"2021-07-15T03:00:18.624Z","symbol":"UNIBTC"}}
1626318018.7751071: {"jsonrpc":"2.0","method":"updateOrderbook","params":{"ask":[{"price":"0.662654","size":"399064.9"}],"bid":[],"sequence":20584040,"timestamp":"2021-07-15T03:00:18.686Z","symbol":"XRPUSDT"}}
1626318018.775163: {"jsonrpc":"2.0","method":"updateOrderbook","params":{"ask":[{"price":"0.00000065973","size":"15230150"},{"price":"0.00000094569","size":"2768180"}],"bid":[],"sequence":10532231,"timestamp":"2021-07-15T03:00:18.732Z","symbol":"SCBTC"}}
1626318018.775189: {"jsonrpc":"2.0","method":"updateOrderbook","params":{"ask":[{"price":"0.00054586","size":"4.33"},{"price":"0.00054590","size":"0"},{"price":"0.00054768","size":"291.41"},{"price":"0.00054795","size":"0"},{"price":"0.00055097","size":"1244.50"},{"price":"0.00055157","size":"0"}],"bid":[{"price":"0.00054567","size":"0"},{"price":"0.00054566","size":"5.18"}],"sequence":19513039,"timestamp":"2021-07-15T03:00:18.741Z","symbol":"UNIBTC"}}
1626318018.869097: {"jsonrpc":"2.0","method":"updateOrderbook","params":{"ask":[{"price":"0.662654","size":"399065.2"}],"bid":[],"sequence":20584041,"timestamp":"2021-07-15T03:00:18.790Z","symbol":"XRPUSDT"}}
1626318018.8691142: {"jsonrpc":"2.0","method":"updateOrderbook","params":{"ask":[{"price":"0.00000065973","size":"15230170"},{"price":"0.00000094569","size":"2768200"}],"bid":[],"sequence":10532232,"timestamp":"2021-07-15T03:00:18.839Z","symbol":"SCBTC"}}
1626318018.8691258: {"jsonrpc":"2.0","method":"updateOrderbook","params":{"ask":[{"price":"0.00054602","size":"10.47"},{"price":"0.00054613","size":"0"},{"price":"0.00054664","size":"363.27"},{"price":"0.00054691","size":"0"},{"price":"0.00054716","size":"193.61"},{"price":"0.00054737","size":"0"}],"bid":[{"price":"0.00054466","size":"0"},{"price":"0.00054435","size":"275.31"}],"sequence":19513040,"timestamp":"2021-07-15T03:00:18.798Z","symbol":"UNIBTC"}}
1626318018.966539: {"jsonrpc":"2.0","method":"updateOrderbook","params":{"ask":[{"price":"0.662654","size":"399065.6"}],"bid":[{"price":"0.615662","size":"1591.6"},{"price":"0.615656","size":"0"}],"sequence":20584042,"timestamp":"2021-07-15T03:00:18.921Z","symbol":"XRPUSDT"}}
1626318018.966559: {"jsonrpc":"2.0","method":"updateOrderbook","params":{"ask":[{"price":"0.00000037415","size":"0"},{"price":"0.00000037470","size":"661850"},{"price":"0.00000044361","size":"0"},{"price":"0.00000044405","size":"1381850"},{"price":"0.00000065973","size":"15230180"},{"price":"0.00000089590","size":"0"},{"price":"0.00000089742","size":"2001500"},{"price":"0.00000094569","size":"2768210"},{"price":"0.00000384260","size":"0"},{"price":"0.00000384793","size":"7466230"}],"bid":[],"sequence":10532233,"timestamp":"2021-07-15T03:00:18.925Z","symbol":"SCBTC"}}
1626318018.9665768: {"jsonrpc":"2.0","method":"updateOrderbook","params":{"ask":[{"price":"0.00054584","size":"4.33"},{"price":"0.00054586","size":"0"},{"price":"0.00054803","size":"0"},{"price":"0.00054870","size":"658.12"},{"price":"0.00055060","size":"0"},{"price":"0.00055133","size":"843.90"},{"price":"0.00055683","size":"0"},{"price":"0.00056011","size":"2539.46"}],"bid":[{"price":"0.00054566","size":"0"},{"price":"0.00054565","size":"5.18"},{"price":"0.00054549","size":"0"},{"price":"0.00054537","size":"18.33"},{"price":"0.00054516","size":"0"},{"price":"0.00054495","size":"80.24"},{"price":"0.00054485","size":"0"},{"price":"0.00054447","size":"196.86"}],"sequence":19513041,"timestamp":"2021-07-15T03:00:18.917Z","symbol":"UNIBTC"}}
1626318019.056648: {"jsonrpc":"2.0","method":"updateOrderbook","params":{"ask":[{"price":"0.615747","size":"0"},{"price":"0.616285","size":"0"},{"price":"0.616410","size":"160.9"},{"price":"0.616627","size":"0"},{"price":"0.616896","size":"6433.6"},{"price":"0.617115","size":"0"},{"price":"0.617484","size":"0"},{"price":"0.617536","size":"4276.9"},{"price":"0.617909","size":"12316.2"},{"price":"0.662654","size":"399065.9"}],"bid":[{"price":"0.615715","size":"11000.0"},{"price":"0.615238","size":"1337.0"},{"price":"0.615195","size":"0"}],"sequence":20584043,"timestamp":"2021-07-15T03:00:19.012Z","symbol":"XRPUSDT"}}
1626318019.0698838: {"jsonrpc":"2.0","method":"updateOrderbook","params":{"ask":[{"price":"0.00000065973","size":"15230200"},{"price":"0.00000094569","size":"2768230"}],"bid":[],"sequence":10532234,"timestamp":"2021-07-15T03:00:19.033Z","symbol":"SCBTC"}}
1626318019.0699022: {"jsonrpc":"2.0","method":"updateOrderbook","params":{"ask":[{"price":"0.00054629","size":"66.20"},{"price":"0.00054642","size":"0"},{"price":"0.00054780","size":"375.71"},{"price":"0.00054802","size":"484.13"},{"price":"0.00054841","size":"0"},{"price":"0.00054870","size":"0"},{"price":"0.00054874","size":"0"},{"price":"0.00054918","size":"658.12"},{"price":"0.00055279","size":"0"},{"price":"0.00055346","size":"1811.87"},{"price":"0.00056011","size":"0"},{"price":"0.00056209","size":"2539.46"}],"bid":[],"sequence":19513042,"timestamp":"2021-07-15T03:00:19.041Z","symbol":"UNIBTC"}}
1626318019.1523368: {"jsonrpc":"2.0","method":"updateOrderbook","params":{"ask":[{"price":"0.615742","size":"0"},{"price":"0.615756","size":"1331.7"},{"price":"0.617074","size":"0"},{"price":"0.617188","size":"7700.0"},{"price":"0.622068","size":"0"},{"price":"0.626104","size":"272131.6"},{"price":"0.641909","size":"0"},{"price":"0.648232","size":"347706.3"},{"price":"0.657744","size":"0"},{"price":"0.659380","size":"485414.3"},{"price":"0.662654","size":"399066.2"},{"price":"0.666845","size":"229002.7"},{"price":"0.672296","size":"0"},{"price":"0.841249","size":"324970.5"},{"price":"0.848572","size":"0"}],"bid":[{"price":"0.615715","size":"0"},{"price":"0.615700","size":"11000.0"},{"price":"0.615688","size":"1591.6"},{"price":"0.615662","size":"0"}],"sequence":20584044,"timestamp":"2021-07-15T03:00:19.132Z","symbol":"XRPUSDT"}}
1626318019.1653152: {"jsonrpc":"2.0","method":"updateOrderbook","params":{"ask":[{"price":"0.00000065973","size":"15230210"},{"price":"0.00000094569","size":"2768240"}],"bid":[{"price":"0.00000034658","size":"234600"},{"price":"0.00000034622","size":"0"}],"sequence":10532235,"timestamp":"2021-07-15T03:00:19.140Z","symbol":"SCBTC"}}
1626318019.255481: {"jsonrpc":"2.0","method":"updateOrderbook","params":{"ask":[{"price":"0.615756","size":"0"},{"price":"0.615779","size":"1331.7"},{"price":"0.616078","size":"0"},{"price":"0.616239","size":"495.8"},{"price":"0.616286","size":"0"},{"price":"0.616419","size":"508.4"},{"price":"0.616488","size":"2136.6"},{"price":"0.616533","size":"0"},{"price":"0.616685","size":"0"},{"price":"0.616785","size":"1800.0"},{"price":"0.616809","size":"0"},{"price":"0.616923","size":"5500.0"},{"price":"0.617107","size":"523.2"},{"price":"0.617168","size":"2281.9"},{"price":"0.617424","size":"0"},{"price":"0.617504","size":"7145.7"},{"price":"0.617562","size":"0"},{"price":"0.618034","size":"0"},{"price":"0.628174","size":"0"},{"price":"0.629622","size":"129038.8"},{"price":"0.652912","size":"0"},{"price":"0.654112","size":"181214.3"},{"price":"0.662654","size":"399066.5"},{"price":"0.702918","size":"0"}],"bid":[{"price":"0.615688","size":"0"},{"price":"0.615685","size":"1591.6"},{"price":"0.615561","size":"2955.8"},{"price":"0.615513","size":"0"}],"sequence":20584045,"timestamp":"2021-07-15T03:00:19.242Z","symbol":"XRPUSDT"}}
1626318019.283123: {"jsonrpc":"2.0","method":"updateOrderbook","params":{"ask":[{"price":"0.00000065973","size":"15230220"},{"price":"0.00000094569","size":"2768250"}],"bid":[],"sequence":10532236,"timestamp":"2021-07-15T03:00:19.193Z","symbol":"SCBTC"}}
1626318019.360318: {"jsonrpc":"2.0","method":"updateOrderbook","params":{"ask":[{"price":"0.615767","size":"1331.7"},{"price":"0.615779","size":"0"},{"price":"0.662654","size":"399066.7"}],"bid":[{"price":"0.615701","size":"11000.0"},{"price":"0.615700","size":"0"},{"price":"0.615690","size":"1596.5"},{"price":"0.615685","size":"0"}],"sequence":20584046,"timestamp":"2021-07-15T03:00:19.304Z","symbol":"XRPUSDT"}}
1626318019.3722591: {"jsonrpc":"2.0","method":"updateOrderbook","params":{"ask":[{"price":"0.00000065973","size":"15230230"},{"price":"0.00000077938","size":"2003810"},{"price":"0.00000078433","size":"0"},{"price":"0.00000094569","size":"2768260"}],"bid":[{"price":"0.00000034658","size":"4600"},{"price":"0.00000034622","size":"230000"}],"sequence":10532237,"timestamp":"2021-07-15T03:00:19.258Z","symbol":"SCBTC"}}
1626318019.372303: {"jsonrpc":"2.0","method":"updateOrderbook","params":{"ask":[],"bid":[{"price":"0.00054566","size":"5.18"},{"price":"0.00054565","size":"0"},{"price":"0.00054480","size":"261.13"},{"price":"0.00054460","size":"0"}],"sequence":19513043,"timestamp":"2021-07-15T03:00:19.289Z","symbol":"UNIBTC"}}
1626318019.4720562: {"jsonrpc":"2.0","method":"updateOrderbook","params":{"ask":[{"price":"0.615759","size":"11000.0"},{"price":"0.615764","size":"1331.7"},{"price":"0.615767","size":"0"},{"price":"0.616300","size":"160.9"},{"price":"0.616410","size":"0"},{"price":"0.624269","size":"272131.6"},{"price":"0.626104","size":"0"},{"price":"0.629622","size":"0"},{"price":"0.631987","size":"129038.8"},{"price":"0.654112","size":"0"},{"price":"0.656074","size":"181214.3"},{"price":"0.662654","size":"399067.0"}],"bid":[{"price":"0.615701","size":"0"}],"sequence":20584047,"timestamp":"2021-07-15T03:00:19.394Z","symbol":"XRPUSDT"}}
1626318019.472197: {"jsonrpc":"2.0","method":"updateOrderbook","params":{"ask":[{"price":"0.00000065973","size":"15230250"},{"price":"0.00000094569","size":"2768270"}],"bid":[{"price":"0.00000032828","size":"1993120"},{"price":"0.00000022599","size":"0"},{"price":"0.00000004908","size":"2752080"},{"price":"0.00000000436","size":"0"}],"sequence":10532238,"timestamp":"2021-07-15T03:00:19.358Z","symbol":"SCBTC"}}
1626318019.47421: {"jsonrpc":"2.0","method":"updateOrderbook","params":{"ask":[{"price":"0.00054867","size":"587.36"},{"price":"0.00054922","size":"805.27"},{"price":"0.00054947","size":"0"},{"price":"0.00055065","size":"0"}],"bid":[],"sequence":19513044,"timestamp":"2021-07-15T03:00:19.392Z","symbol":"UNIBTC"}}
1626318019.5639591: {"jsonrpc":"2.0","method":"updateOrderbook","params":{"ask":[{"price":"0.615764","size":"0"},{"price":"0.615767","size":"1331.7"},{"price":"0.616853","size":"5500.0"},{"price":"0.616923","size":"0"},{"price":"0.662654","size":"399067.4"}],"bid":[],"sequence":20584048,"timestamp":"2021-07-15T03:00:19.531Z","symbol":"XRPUSDT"}}
1626318019.569176: {"jsonrpc":"2.0","method":"updateOrderbook","params":{"ask":[{"price":"0.00000065973","size":"15230270"},{"price":"0.00000089742","size":"0"},{"price":"0.00000089834","size":"2001500"},{"price":"0.00000094569","size":"2768300"},{"price":"0.00000384793","size":"0"},{"price":"0.00000384932","size":"7466230"}],"bid":[],"sequence":10532239,"timestamp":"2021-07-15T03:00:19.527Z","symbol":"SCBTC"}}
1626318019.569219: {"jsonrpc":"2.0","method":"updateOrderbook","params":{"ask":[{"price":"0.00054584","size":"0"},{"price":"0.00054586","size":"4.33"}],"bid":[{"price":"0.00054566","size":"0"},{"price":"0.00054564","size":"5.18"}],"sequence":19513045,"timestamp":"2021-07-15T03:00:19.512Z","symbol":"UNIBTC"}}
1626318019.664726: {"jsonrpc":"2.0","method":"updateOrderbook","params":{"ask":[{"price":"0.616323","size":"0"},{"price":"0.616354","size":"6528.8"},{"price":"0.662654","size":"399067.7"}],"bid":[{"price":"0.615253","size":"5489.4"},{"price":"0.615238","size":"0"},{"price":"0.615237","size":"0"},{"price":"0.615195","size":"1337.0"}],"sequence":20584049,"timestamp":"2021-07-15T03:00:19.619Z","symbol":"XRPUSDT"}}
1626318019.6997252: {"jsonrpc":"2.0","method":"updateOrderbook","params":{"ask":[{"price":"0.00000037470","size":"0"},{"price":"0.00000037542","size":"661850"},{"price":"0.00000044405","size":"0"},{"price":"0.00000044539","size":"1381850"},{"price":"0.00000065973","size":"15230280"},{"price":"0.00000089834","size":"0"},{"price":"0.00000090214","size":"2001500"},{"price":"0.00000094569","size":"2768310"},{"price":"0.00000124728","size":"0"},{"price":"0.00000124862","size":"2705250"},{"price":"0.00000147053","size":"0"},{"price":"0.00000147160","size":"3222000"},{"price":"0.00000384932","size":"0"},{"price":"0.00000385651","size":"7466230"}],"bid":[],"sequence":10532240,"timestamp":"2021-07-15T03:00:19.600Z","symbol":"SCBTC"}}
1626318019.699796: {"jsonrpc":"2.0","method":"updateOrderbook","params":{"ask":[{"price":"0.00054584","size":"4.33"},{"price":"0.00054586","size":"0"}],"bid":[{"price":"0.00054533","size":"0"},{"price":"0.00054495","size":"0"},{"price":"0.00054494","size":"18.03"},{"price":"0.00054458","size":"80.24"},{"price":"0.00054317","size":"0"},{"price":"0.00054267","size":"929.35"}],"sequence":19513046,"timestamp":"2021-07-15T03:00:19.590Z","symbol":"UNIBTC"}}
1626318019.782551: {"jsonrpc":"2.0","method":"updateOrderbook","params":{"ask":[],"bid":[{"price":"12.069","size":"0"}],"sequence":2190665,"timestamp":"2021-07-15T03:00:19.702Z","symbol":"SPIUSD"}}
1626318019.782589: {"jsonrpc":"2.0","method":"updateOrderbook","params":{"ask":[{"price":"0.662654","size":"399068.0"}],"bid":[],"sequence":20584050,"timestamp":"2021-07-15T03:00:19.722Z","symbol":"XRPUSDT"}}
1626318019.784802: {"jsonrpc":"2.0","method":"updateOrderbook","params":{"ask":[{"price":"0.00000065973","size":"15230300"},{"price":"0.00000094569","size":"2768320"},{"price":"0.00000273316","size":"4472830"},{"price":"0.00000286068","size":"0"}],"bid":[],"sequence":10532241,"timestamp":"2021-07-15T03:00:19.711Z","symbol":"SCBTC"}}
1626318019.784844: {"jsonrpc":"2.0","method":"updateOrderbook","params":{"ask":[{"price":"0.00055241","size":"1757.02"},{"price":"0.00056173","size":"0"}],"bid":[{"price":"0.00054564","size":"0"},{"price":"0.00054562","size":"5.18"},{"price":"0.00054548","size":"0"},{"price":"0.00054541","size":"9.62"}],"sequence":19513047,"timestamp":"2021-07-15T03:00:19.699Z","symbol":"UNIBTC"}}
1626318019.857255: {"jsonrpc":"2.0","method":"updateOrderbook","params":{"ask":[],"bid":[{"price":"12.071","size":"5.8893"},{"price":"12.070","size":"0"},{"price":"12.060","size":"5.7381"}],"sequence":2190666,"timestamp":"2021-07-15T03:00:19.773Z","symbol":"SPIUSD"}}
1626318019.889198: {"jsonrpc":"2.0","method":"updateOrderbook","params":{"ask":[{"price":"0.615764","size":"1331.7"},{"price":"0.615767","size":"0"},{"price":"0.662654","size":"399068.1"}],"bid":[],"sequence":20584051,"timestamp":"2021-07-15T03:00:19.768Z","symbol":"XRPUSDT"}}
1626318019.9613178: {"jsonrpc":"2.0","method":"updateOrderbook","params":{"ask":[{"price":"0.00000065973","size":"15230320"},{"price":"0.00000094569","size":"2768340"}],"bid":[],"sequence":10532242,"timestamp":"2021-07-15T03:00:19.815Z","symbol":"SCBTC"}}
1626318019.986122: {"jsonrpc":"2.0","method":"updateOrderbook","params":{"ask":[{"price":"0.00054582","size":"4.33"},{"price":"0.00054584","size":"0"}],"bid":[{"price":"0.00054562","size":"0"},{"price":"0.00054558","size":"5.18"},{"price":"0.00054511","size":"0"},{"price":"0.00054508","size":"0"},{"price":"0.00054505","size":"0"},{"price":"0.00054484","size":"17.87"},{"price":"0.00054480","size":"199.39"},{"price":"0.00054460","size":"21.05"},{"price":"0.00054457","size":"500.70"},{"price":"0.00054241","size":"0"},{"price":"0.00054226","size":"914.50"},{"price":"0.00053397","size":"0"},{"price":"0.00053242","size":"2974.71"}],"sequence":19513048,"timestamp":"2021-07-15T03:00:19.825Z","symbol":"UNIBTC"}}
1626318019.99383: {"jsonrpc":"2.0","method":"updateOrderbook","params":{"ask":[],"bid":[{"price":"12.072","size":"5.7415"},{"price":"12.060","size":"0"}],"sequence":2190667,"timestamp":"2021-07-15T03:00:19.870Z","symbol":"SPIUSD"}}
1626318020.016893: {"jsonrpc":"2.0","method":"updateOrderbook","params":{"ask":[{"price":"0.662654","size":"399068.5"}],"bid":[],"sequence":20584052,"timestamp":"2021-07-15T03:00:19.876Z","symbol":"XRPUSDT"}}
1626318020.053919: {"jsonrpc":"2.0","method":"updateOrderbook","params":{"ask":[{"price":"0.00000065973","size":"15230330"},{"price":"0.00000094569","size":"2768350"},{"price":"0.00000273316","size":"0"},{"price":"0.00000283983","size":"4472830"}],"bid":[{"price":"0.00000036534","size":"0"},{"price":"0.00000036526","size":"28670"},{"price":"0.00000036514","size":"0"},{"price":"0.00000036504","size":"110390"},{"price":"0.00000032828","size":"0"},{"price":"0.00000032029","size":"1993120"},{"price":"0.00000004908","size":"0"},{"price":"0.00000004259","size":"2752080"}],"sequence":10532243,"timestamp":"2021-07-15T03:00:19.907Z","symbol":"SCBTC"}}
1626318020.053974: {"jsonrpc":"2.0","method":"updateOrderbook","params":{"ask":[{"price":"0.00056209","size":"0"},{"price":"0.00056345","size":"2539.46"},{"price":"0.00059460","size":"2343.84"},{"price":"0.00065925","size":"0"},{"price":"0.00078428","size":"3484.36"},{"price":"0.00080159","size":"0"}],"bid":[{"price":"0.00054558","size":"0"},{"price":"0.00054557","size":"5.18"},{"price":"0.00054226","size":"0"},{"price":"0.00054173","size":"914.50"},{"price":"0.00053242","size":"0"},{"price":"0.00052895","size":"2974.71"}],"sequence":19513049,"timestamp":"2021-07-15T03:00:19.937Z","symbol":"UNIBTC"}}
1626318020.075319: {"jsonrpc":"2.0","method":"updateOrderbook","params":{"ask":[{"price":"0.662654","size":"399068.8"}],"bid":[],"sequence":20584053,"timestamp":"2021-07-15T03:00:19.993Z","symbol":"XRPUSDT"}}
1626318020.112704: {"jsonrpc":"2.0","method":"updateOrderbook","params":{"ask":[{"price":"0.00000065973","size":"15230350"},{"price":"0.00000094569","size":"2768370"}],"bid":[{"price":"0.00000036515","size":"0"},{"price":"0.00000036505","size":"1000"}],"sequence":10532244,"timestamp":"2021-07-15T03:00:20.003Z","symbol":"SCBTC"}}
1626318020.1127648: {"jsonrpc":"2.0","method":"updateOrderbook","params":{"ask":[{"price":"0.00054918","size":"0"},{"price":"0.00054961","size":"658.12"},{"price":"0.00056345","size":"0"},{"price":"0.00056453","size":"2539.46"}],"bid":[{"price":"0.00054558","size":"5.18"},{"price":"0.00054557","size":"0"},{"price":"0.00054537","size":"0"},{"price":"0.00054527","size":"18.33"}],"sequence":19513050,"timestamp":"2021-07-15T03:00:20.013Z","symbol":"UNIBTC"}}
1626318020.184979: {"jsonrpc":"2.0","method":"updateOrderbook","params":{"ask":[],"bid":[{"price":"12.073","size":"5.8883"},{"price":"12.071","size":"0"}],"sequence":2190668,"timestamp":"2021-07-15T03:00:20.122Z","symbol":"SPIUSD"}}
1626318020.1851032: {"jsonrpc":"2.0","method":"updateOrderbook","params":{"ask":[{"price":"0.662654","size":"399069.3"}],"bid":[{"price":"0.615691","size":"11000.0"}],"sequence":20584054,"timestamp":"2021-07-15T03:00:20.141Z","symbol":"XRPUSDT"}}
1626318020.185142: {"jsonrpc":"2.0","method":"updateOrderbook","params":{"ask":[{"price":"0.00000065973","size":"15230370"},{"price":"0.00000094569","size":"0"},{"price":"0.00000094570","size":"2768390"}],"bid":[],"sequence":10532245,"timestamp":"2021-07-15T03:00:20.114Z","symbol":"SCBTC"}}
1626318020.185157: {"jsonrpc":"2.0","method":"updateOrderbook","params":{"ask":[{"price":"0.00054580","size":"4.33"},{"price":"0.00054582","size":"0"},{"price":"0.00054609","size":"16.70"},{"price":"0.00054621","size":"0"},{"price":"0.00054641","size":"18.88"},{"price":"0.00054650","size":"0"},{"price":"0.00056453","size":"0"},{"price":"0.00056934","size":"2539.46"}],"bid":[{"price":"0.00054558","size":"0"},{"price":"0.00054553","size":"5.18"},{"price":"0.00054541","size":"0"},{"price":"0.00054534","size":"9.62"},{"price":"0.00054509","size":"0"},{"price":"0.00054480","size":"268.62"},{"price":"0.00054220","size":"914.50"},{"price":"0.00054173","size":"0"}],"sequence":19513051,"timestamp":"2021-07-15T03:00:20.138Z","symbol":"UNIBTC"}}
1626318020.249699: {"jsonrpc":"2.0","method":"updateOrderbook","params":{"ask":[],"bid":[{"price":"12.074","size":"5.7479"},{"price":"12.072","size":"0"}],"sequence":2190669,"timestamp":"2021-07-15T03:00:20.207Z","symbol":"SPIUSD"}}
1626318020.300006: {"jsonrpc":"2.0","method":"updateOrderbook","params":{"ask":[{"price":"0.615752","size":"11000.0"},{"price":"0.615759","size":"0"},{"price":"0.662654","size":"399069.4"},{"price":"0.702918","size":"228479.7"}],"bid":[{"price":"0.615691","size":"0"},{"price":"0.615690","size":"4.9"},{"price":"0.615685","size":"1591.6"}],"sequence":20584055,"timestamp":"2021-07-15T03:00:20.176Z","symbol":"XRPUSDT"}}
1626318020.300137: {"jsonrpc":"2.0","method":"updateOrderbook","params":{"ask":[{"price":"0.00000065973","size":"15230380"},{"price":"0.00000094570","size":"2768410"}],"bid":[],"sequence":10532246,"timestamp":"2021-07-15T03:00:20.196Z","symbol":"SCBTC"}}
1626318020.300162: {"jsonrpc":"2.0","method":"updateOrderbook","params":{"ask":[{"price":"0.00054578","size":"4.33"},{"price":"0.00054580","size":"0"}],"bid":[{"price":"0.00054553","size":"0"},{"price":"0.00054552","size":"5.18"},{"price":"0.00054490","size":"72.79"},{"price":"0.00054457","size":"261.13"},{"price":"0.00054455","size":"353.16"},{"price":"0.00054434","size":"417.56"},{"price":"0.00054416","size":"0"},{"price":"0.00054398","size":"0"},{"price":"0.00054382","size":"345.92"},{"price":"0.00054349","size":"269.93"},{"price":"0.00054321","size":"331.21"},{"price":"0.00054220","size":"0"},{"price":"0.00054175","size":"914.50"},{"price":"0.00053050","size":"0"},{"price":"0.00052999","size":"2974.71"},{"price":"0.00052895","size":"0"}],"sequence":19513052,"timestamp":"2021-07-15T03:00:20.241Z","symbol":"UNIBTC"}}
1626318020.383853: {"jsonrpc":"2.0","method":"updateOrderbook","params":{"ask":[{"price":"0.615752","size":"0"},{"price":"0.662654","size":"399069.8"}],"bid":[{"price":"0.615690","size":"11004.9"},{"price":"0.615254","size":"1337.0"},{"price":"0.615195","size":"0"}],"sequence":20584056,"timestamp":"2021-07-15T03:00:20.305Z","symbol":"XRPUSDT"}}
1626318020.3839612: {"jsonrpc":"2.0","method":"updateOrderbook","params":{"ask":[{"price":"0.00000065973","size":"15230400"},{"price":"0.00000094570","size":"2768430"}],"bid":[],"sequence":10532247,"timestamp":"2021-07-15T03:00:20.302Z","symbol":"SCBTC"}}
1626318020.383986: {"jsonrpc":"2.0","method":"updateOrderbook","params":{"ask":[],"bid":[{"price":"0.00054554","size":"5.18"},{"price":"0.00054552","size":"0"},{"price":"0.00054515","size":"18.03"},{"price":"0.00054496","size":"80.24"},{"price":"0.00054494","size":"0"},{"price":"0.00054458","size":"0"},{"price":"0.00052896","size":"443.78"}],"sequence":19513053,"timestamp":"2021-07-15T03:00:20.310Z","symbol":"UNIBTC"}}
1626318020.453094: {"jsonrpc":"2.0","method":"updateOrderbook","params":{"ask":[{"price":"0.615739","size":"11000.0"},{"price":"0.662654","size":"399070.1"}],"bid":[{"price":"0.615690","size":"4.9"},{"price":"0.615254","size":"0"},{"price":"0.615195","size":"1337.0"}],"sequence":20584057,"timestamp":"2021-07-15T03:00:20.410Z","symbol":"XRPUSDT"}}
1626318020.472499: {"jsonrpc":"2.0","method":"updateOrderbook","params":{"ask":[{"price":"0.00000042892","size":"522810"},{"price":"0.00000043202","size":"0"},{"price":"0.00000054417","size":"757990"},{"price":"0.00000054581","size":"0"},{"price":"0.00000065973","size":"15230420"},{"price":"0.00000094570","size":"2768450"},{"price":"0.00000124775","size":"2705250"},{"price":"0.00000124862","size":"0"},{"price":"0.00000147091","size":"3222000"},{"price":"0.00000147160","size":"0"}],"bid":[{"price":"0.00000035817","size":"0"}],"sequence":10532248,"timestamp":"2021-07-15T03:00:20.396Z","symbol":"SCBTC"}}
1626318020.472545: {"jsonrpc":"2.0","method":"updateOrderbook","params":{"ask":[{"price":"0.00054688","size":"169.84"},{"price":"0.00054718","size":"0"},{"price":"0.00054719","size":"250.69"},{"price":"0.00054763","size":"0"}],"bid":[],"sequence":19513054,"timestamp":"2021-07-15T03:00:20.362Z","symbol":"UNIBTC"}}
1626318020.555787: {"jsonrpc":"2.0","method":"updateOrderbook","params":{"ask":[{"price":"0.662654","size":"399070.2"}],"bid":[],"sequence":20584058,"timestamp":"2021-07-15T03:00:20.457Z","symbol":"XRPUSDT"}}
1626318020.5642729: {"jsonrpc":"2.0","method":"updateOrderbook","params":{"ask":[{"price":"0.00000065973","size":"15230440"},{"price":"0.00000094570","size":"2768470"}],"bid":[],"sequence":10532249,"timestamp":"2021-07-15T03:00:20.503Z","symbol":"SCBTC"}}
1626318020.564312: {"jsonrpc":"2.0","method":"updateOrderbook","params":{"ask":[{"price":"0.00054578","size":"0"},{"price":"0.00054581","size":"4.33"},{"price":"0.00054618","size":"66.20"},{"price":"0.00054629","size":"199.63"},{"price":"0.00054639","size":"296.51"},{"price":"0.00054653","size":"0"},{"price":"0.00054664","size":"66.76"},{"price":"0.00059460","size":"0"},{"price":"0.00060103","size":"2343.84"},{"price":"0.00078428","size":"0"},{"price":"0.00078698","size":"3484.36"}],"bid":[{"price":"0.00054554","size":"0"},{"price":"0.00054552","size":"5.18"},{"price":"0.00052896","size":"0"}],"sequence":19513055,"timestamp":"2021-07-15T03:00:20.530Z","symbol":"UNIBTC"}}
1626318020.671561: {"jsonrpc":"2.0","method":"updateOrderbook","params":{"ask":[],"bid":[{"price":"12.075","size":"5.8874"},{"price":"12.073","size":"0"}],"sequence":2190670,"timestamp":"2021-07-15T03:00:20.620Z","symbol":"SPIUSD"}}
1626318020.70717: {"jsonrpc":"2.0","method":"updateOrderbook","params":{"ask":[{"price":"0.662654","size":"399070.6"}],"bid":[],"sequence":20584059,"timestamp":"2021-07-15T03:00:20.564Z","symbol":"XRPUSDT"}}
1626318020.7072299: {"jsonrpc":"2.0","method":"updateOrderbook","params":{"ask":[{"price":"0.00000065973","size":"15230460"},{"price":"0.00000094570","size":"2768480"}],"bid":[{"price":"0.00000035843","size":"9990"}],"sequence":10532250,"timestamp":"2021-07-15T03:00:20.592Z","symbol":"SCBTC"}}
1626318020.707256: {"jsonrpc":"2.0","method":"updateOrderbook","params":{"ask":[{"price":"0.00055656","size":"0"}],"bid":[{"price":"0.00054555","size":"5.18"},{"price":"0.00054552","size":"0"},{"price":"0.00053050","size":"442.49"}],"sequence":19513056,"timestamp":"2021-07-15T03:00:20.639Z","symbol":"UNIBTC"}}
1626318020.770087: {"jsonrpc":"2.0","method":"updateOrderbook","params":{"ask":[],"bid":[{"price":"12.076","size":"5.7543"},{"price":"12.074","size":"0"}],"sequence":2190671,"timestamp":"2021-07-15T03:00:20.683Z","symbol":"SPIUSD"}}
1626318020.7701912: {"jsonrpc":"2.0","method":"updateOrderbook","params":{"ask":[{"price":"0.662654","size":"399070.9"}],"bid":[],"sequence":20584060,"timestamp":"2021-07-15T03:00:20.667Z","symbol":"XRPUSDT"}}
1626318020.782144: {"jsonrpc":"2.0","method":"updateOrderbook","params":{"ask":[{"price":"0.00000065973","size":"15230480"},{"price":"0.00000094570","size":"2768500"}],"bid":[],"sequence":10532251,"timestamp":"2021-07-15T03:00:20.702Z","symbol":"SCBTC"}}
1626318020.782203: {"jsonrpc":"2.0","method":"updateOrderbook","params":{"ask":[],"bid":[{"price":"0.00054556","size":"5.18"},{"price":"0.00054555","size":"0"}],"sequence":19513057,"timestamp":"2021-07-15T03:00:20.669Z","symbol":"UNIBTC"}}
1626318020.8939688: {"jsonrpc":"2.0","method":"updateOrderbook","params":{"ask":[{"price":"0.662654","size":"399071.3"}],"bid":[],"sequence":20584061,"timestamp":"2021-07-15T03:00:20.804Z","symbol":"XRPUSDT"}}
1626318020.894031: {"jsonrpc":"2.0","method":"updateOrderbook","params":{"ask":[{"price":"0.00000065973","size":"15230500"},{"price":"0.00000094570","size":"2768530"}],"bid":[],"sequence":10532252,"timestamp":"2021-07-15T03:00:20.812Z","symbol":"SCBTC"}}
1626318020.8940558: {"jsonrpc":"2.0","method":"updateOrderbook","params":{"ask":[],"bid":[{"price":"0.00053050","size":"443.28"}],"sequence":19513058,"timestamp":"2021-07-15T03:00:20.840Z","symbol":"UNIBTC"}}
1626318020.990858: {"jsonrpc":"2.0","method":"updateOrderbook","params":{"ask":[{"price":"0.639732","size":"1.2"},{"price":"0.662654","size":"399071.6"}],"bid":[],"sequence":20584062,"timestamp":"2021-07-15T03:00:20.939Z","symbol":"XRPUSDT"}}
1626318020.990918: {"jsonrpc":"2.0","method":"updateOrderbook","params":{"ask":[{"price":"0.00000065973","size":"15230520"},{"price":"0.00000094570","size":"2768550"}],"bid":[],"sequence":10532253,"timestamp":"2021-07-15T03:00:20.918Z","symbol":"SCBTC"}}
1626318020.990942: {"jsonrpc":"2.0","method":"updateOrderbook","params":{"ask":[{"price":"0.00054577","size":"4.33"},{"price":"0.00054581","size":"0"}],"bid":[{"price":"0.00054556","size":"0"},{"price":"0.00054555","size":"5.18"},{"price":"0.00054523","size":"0"},{"price":"0.00054501","size":"18.61"}],"sequence":19513059,"timestamp":"2021-07-15T03:00:20.937Z","symbol":"UNIBTC"}}
1626318021.1989272: {"jsonrpc":"2.0","method":"updateOrderbook","params":{"ask":[{"price":"0.662654","size":"399072.0"}],"bid":[],"sequence":20584063,"timestamp":"2021-07-15T03:00:21.028Z","symbol":"XRPUSDT"}}
1626318021.198972: {"jsonrpc":"2.0","method":"updateOrderbook","params":{"ask":[{"price":"0.00000065973","size":"15230540"},{"price":"0.00000094570","size":"2768570"}],"bid":[],"sequence":10532254,"timestamp":"2021-07-15T03:00:21.027Z","symbol":"SCBTC"}}
1626318021.199003: {"jsonrpc":"2.0","method":"updateOrderbook","params":{"ask":[],"bid":[{"price":"0.00052999","size":"0"},{"price":"0.00052836","size":"2974.71"}],"sequence":19513060,"timestamp":"2021-07-15T03:00:21.031Z","symbol":"UNIBTC"}}
1626318021.242989: {"jsonrpc":"2.0","method":"updateOrderbook","params":{"ask":[],"bid":[{"price":"12.075","size":"0"}],"sequence":2190672,"timestamp":"2021-07-15T03:00:21.127Z","symbol":"SPIUSD"}}
1626318021.243037: {"jsonrpc":"2.0","method":"updateOrderbook","params":{"ask":[{"price":"0.635952","size":"1.2"},{"price":"0.662654","size":"399072.1"}],"bid":[],"sequence":20584064,"timestamp":"2021-07-15T03:00:21.071Z","symbol":"XRPUSDT"}}
1626318021.243062: {"jsonrpc":"2.0","method":"updateOrderbook","params":{"ask":[{"price":"0.00000065973","size":"15230560"},{"price":"0.00000094570","size":"2768590"}],"bid":[],"sequence":10532255,"timestamp":"2021-07-15T03:00:21.137Z","symbol":"SCBTC"}}
1626318021.250416: {"jsonrpc":"2.0","method":"updateOrderbook","params":{"ask":[],"bid":[{"price":"12.077","size":"5.8864"}],"sequence":2190673,"timestamp":"2021-07-15T03:00:21.181Z","symbol":"SPIUSD"}}
1626318021.285562: {"jsonrpc":"2.0","method":"updateOrderbook","params":{"ask":[{"price":"0.632172","size":"1.2"},{"price":"0.662654","size":"399072.5"}],"bid":[],"sequence":20584065,"timestamp":"2021-07-15T03:00:21.213Z","symbol":"XRPUSDT"}}
1626318021.285619: {"jsonrpc":"2.0","method":"updateOrderbook","params":{"ask":[{"price":"0.00000065973","size":"15230570"},{"price":"0.00000094560","size":"2756060"},{"price":"0.00000094570","size":"0"}],"bid":[{"price":"0.00000036564","size":"28670"},{"price":"0.00000036526","size":"0"},{"price":"0.00000036525","size":"110390"},{"price":"0.00000036504","size":"0"}],"sequence":10532256,"timestamp":"2021-07-15T03:00:21.198Z","symbol":"SCBTC"}}
1626318021.2857149: {"jsonrpc":"2.0","method":"updateOrderbook","params":{"ask":[],"bid":[{"price":"0.00054556","size":"5.18"},{"price":"0.00054555","size":"0"}],"sequence":19513061,"timestamp":"2021-07-15T03:00:21.217Z","symbol":"UNIBTC"}}
1626318021.3564959: {"jsonrpc":"2.0","method":"updateOrderbook","params":{"ask":[],"bid":[{"price":"12.076","size":"0"},{"price":"12.060","size":"5.7607"}],"sequence":2190674,"timestamp":"2021-07-15T03:00:21.272Z","symbol":"SPIUSD"}}
1626318021.365014: {"jsonrpc":"2.0","method":"updateOrderbook","params":{"ask":[{"price":"0.628392","size":"1.2"},{"price":"0.662654","size":"399072.9"}],"bid":[],"sequence":20584066,"timestamp":"2021-07-15T03:00:21.336Z","symbol":"XRPUSDT"}}
1626318021.390333: {"jsonrpc":"2.0","method":"updateOrderbook","params":{"ask":[{"price":"0.00000147008","size":"3222000"},{"price":"0.00000147091","size":"0"}],"bid":[{"price":"0.00000036526","size":"1000"},{"price":"0.00000036505","size":"0"},{"price":"0.00000034658","size":"234600"},{"price":"0.00000034622","size":"0"}],"sequence":10532257,"timestamp":"2021-07-15T03:00:21.339Z","symbol":"SCBTC"}}
1626318021.390395: {"jsonrpc":"2.0","method":"updateOrderbook","params":{"ask":[{"price":"0.00054649","size":"18.19"},{"price":"0.00054665","size":"72.32"},{"price":"0.00054666","size":"0"},{"price":"0.00054682","size":"0"},{"price":"0.00055868","size":"0"},{"price":"0.00057237","size":"881.76"},{"price":"0.00068955","size":"0"},{"price":"0.00074841","size":"1125.76"},{"price":"0.00083296","size":"0"},{"price":"0.00084011","size":"1585.64"}],"bid":[{"price":"0.00053050","size":"0.79"}],"sequence":19513062,"timestamp":"2021-07-15T03:00:21.315Z","symbol":"UNIBTC"}}
1626318021.457244: {"jsonrpc":"2.0","method":"updateOrderbook","params":{"ask":[],"bid":[{"price":"12.078","size":"5.7671"},{"price":"12.060","size":"0"}],"sequence":2190675,"timestamp":"2021-07-15T03:00:21.350Z","symbol":"SPIUSD"}}
1626318021.457355: {"jsonrpc":"2.0","method":"updateOrderbook","params":{"ask":[{"price":"0.662654","size":"399073.2"}],"bid":[],"sequence":20584067,"timestamp":"2021-07-15T03:00:21.430Z","symbol":"XRPUSDT"}}
1626318021.501098: {"jsonrpc":"2.0","method":"updateOrderbook","params":{"ask":[],"bid":[{"price":"0.00054556","size":"0"},{"price":"0.00054555","size":"5.18"},{"price":"0.00053050","size":"0"},{"price":"0.00052837","size":"444.27"}],"sequence":19513063,"timestamp":"2021-07-15T03:00:21.431Z","symbol":"UNIBTC"}}
1626318021.594211: {"jsonrpc":"2.0","method":"updateOrderbook","params":{"ask":[{"price":"0.624613","size":"1.2"},{"price":"0.662654","size":"399073.3"}],"bid":[],"sequence":20584068,"timestamp":"2021-07-15T03:00:21.466Z","symbol":"XRPUSDT"}}
1626318021.594269: {"jsonrpc":"2.0","method":"updateOrderbook","params":{"ask":[{"price":"0.00000065973","size":"15230580"}],"bid":[],"sequence":10532258,"timestamp":"2021-07-15T03:00:21.443Z","symbol":"SCBTC"}}
1626318021.594294: {"jsonrpc":"2.0","method":"updateOrderbook","params":{"ask":[{"price":"0.00054577","size":"0"},{"price":"0.00054582","size":"4.33"}],"bid":[],"sequence":19513064,"timestamp":"2021-07-15T03:00:21.520Z","symbol":"UNIBTC"}}
1626318021.657002: {"jsonrpc":"2.0","method":"updateOrderbook","params":{"ask":[{"price":"10000.000","size":"0.0012"}],"bid":[{"price":"0.010","size":"1000.0012"}],"sequence":2190676,"timestamp":"2021-07-15T03:00:21.590Z","symbol":"SPIUSD"}}
1626318021.657059: {"jsonrpc":"2.0","method":"updateOrderbook","params":{"ask":[{"price":"0.627159","size":"129038.8"},{"price":"0.631987","size":"0"},{"price":"0.651855","size":"181214.3"},{"price":"0.656074","size":"0"},{"price":"0.662654","size":"399073.7"}],"bid":[],"sequence":20584069,"timestamp":"2021-07-15T03:00:21.590Z","symbol":"XRPUSDT"}}
1626318021.692557: {"jsonrpc":"2.0","method":"updateOrderbook","params":{"ask":[{"price":"0.00054580","size":"4.33"},{"price":"0.00054582","size":"0"},{"price":"0.00054648","size":"16.96"},{"price":"0.00054658","size":"0"}],"bid":[{"price":"0.00054557","size":"5.18"},{"price":"0.00054555","size":"0"},{"price":"0.00054470","size":"196.86"},{"price":"0.00054447","size":"0"},{"price":"0.00052968","size":"2974.71"},{"price":"0.00052836","size":"0"}],"sequence":19513065,"timestamp":"2021-07-15T03:00:21.640Z","symbol":"UNIBTC"}}
1626318021.8225899: {"jsonrpc":"2.0","method":"updateOrderbook","params":{"ask":[{"price":"0.645449","size":"347706.3"},{"price":"0.648232","size":"0"},{"price":"0.662654","size":"399074.0"}],"bid":[],"sequence":20584070,"timestamp":"2021-07-15T03:00:21.692Z","symbol":"XRPUSDT"}}
1626318021.8268101: {"jsonrpc":"2.0","method":"updateOrderbook","params":{"ask":[{"price":"0.00000065973","size":"15230590"}],"bid":[],"sequence":10532259,"timestamp":"2021-07-15T03:00:21.721Z","symbol":"SCBTC"}}
1626318021.8268852: {"jsonrpc":"2.0","method":"updateOrderbook","params":{"ask":[],"bid":[{"price":"0.00052837","size":"445.07"}],"sequence":19513066,"timestamp":"2021-07-15T03:00:21.650Z","symbol":"UNIBTC"}}
1626318021.864297: {"jsonrpc":"2.0","method":"updateOrderbook","params":{"ask":[{"price":"0.616746","size":"6433.6"},{"price":"0.616896","size":"0"},{"price":"0.617115","size":"4276.9"},{"price":"0.617506","size":"12316.2"},{"price":"0.617536","size":"0"},{"price":"0.617909","size":"0"},{"price":"0.662654","size":"399074.2"}],"bid":[],"sequence":20584071,"timestamp":"2021-07-15T03:00:21.763Z","symbol":"XRPUSDT"}}
1626318021.87608: {"jsonrpc":"2.0","method":"updateOrderbook","params":{"ask":[{"price":"0.00000094560","size":"0"},{"price":"0.00000094570","size":"2768580"},{"price":"0.00000159405","size":"4634410"},{"price":"0.00000161545","size":"0"}],"bid":[{"price":"0.00000036564","size":"0"},{"price":"0.00000036525","size":"28670"},{"price":"0.00000036504","size":"110390"},{"price":"0.00000034658","size":"4600"},{"price":"0.00000034622","size":"230000"}],"sequence":10532260,"timestamp":"2021-07-15T03:00:21.813Z","symbol":"SCBTC"}}
1626318021.8764002: {"jsonrpc":"2.0","method":"updateOrderbook","params":{"ask":[{"price":"0.00054670","size":"333.84"},{"price":"0.00054701","size":"346.36"},{"price":"0.00054706","size":"0"},{"price":"0.00054733","size":"0"},{"price":"0.00054742","size":"528.37"},{"price":"0.00054776","size":"0"},{"price":"0.00055281","size":"1811.87"},{"price":"0.00055346","size":"0"}],"bid":[],"sequence":19513067,"timestamp":"2021-07-15T03:00:21.830Z","symbol":"UNIBTC"}}
1626318021.955285: {"jsonrpc":"2.0","method":"updateOrderbook","params":{"ask":[],"bid":[{"price":"12.077","size":"0"}],"sequence":2190677,"timestamp":"2021-07-15T03:00:21.920Z","symbol":"SPIUSD"}}
1626318021.955341: {"jsonrpc":"2.0","method":"updateOrderbook","params":{"ask":[{"price":"0.627159","size":"0"},{"price":"0.629647","size":"129038.8"},{"price":"0.651855","size":"0"},{"price":"0.654131","size":"181214.3"},{"price":"0.662654","size":"399074.6"},{"price":"0.702918","size":"0"}],"bid":[{"price":"0.614734","size":"6216.0"},{"price":"0.614601","size":"0"},{"price":"0.614356","size":"3391.2"},{"price":"0.614231","size":"0"}],"sequence":20584072,"timestamp":"2021-07-15T03:00:21.881Z","symbol":"XRPUSDT"}}
1626318021.982379: {"jsonrpc":"2.0","method":"updateOrderbook","params":{"ask":[{"price":"0.00000037386","size":"3970500"},{"price":"0.00000037542","size":"0"},{"price":"0.00000065973","size":"15230610"},{"price":"0.00000094570","size":"2768600"},{"price":"0.00000124704","size":"2705250"},{"price":"0.00000124775","size":"0"}],"bid":[{"price":"0.00000036526","size":"0"},{"price":"0.00000036505","size":"1000"}],"sequence":10532261,"timestamp":"2021-07-15T03:00:21.913Z","symbol":"SCBTC"}}
1626318021.982445: {"jsonrpc":"2.0","method":"updateOrderbook","params":{"ask":[{"price":"0.00054578","size":"4.33"},{"price":"0.00054580","size":"0"}],"bid":[{"price":"0.00054558","size":"5.18"},{"price":"0.00054557","size":"0"},{"price":"0.00054416","size":"269.93"},{"price":"0.00054349","size":"0"},{"price":"0.00054255","size":"914.50"},{"price":"0.00054175","size":"0"},{"price":"0.00052837","size":"0.80"}],"sequence":19513068,"timestamp":"2021-07-15T03:00:21.940Z","symbol":"UNIBTC"}}
1626318022.04728: {"jsonrpc":"2.0","method":"updateOrderbook","params":{"ask":[],"bid":[{"price":"12.079","size":"5.8854"},{"price":"12.078","size":"0"},{"price":"12.060","size":"5.7735"}],"sequence":2190678,"timestamp":"2021-07-15T03:00:21.975Z","symbol":"SPIUSD"}}
1626318022.055527: {"jsonrpc":"2.0","method":"updateOrderbook","params":{"ask":[{"price":"0.662654","size":"399074.9"},{"price":"0.701643","size":"228479.7"}],"bid":[],"sequence":20584073,"timestamp":"2021-07-15T03:00:21.988Z","symbol":"XRPUSDT"}}
1626318022.0774279: {"jsonrpc":"2.0","method":"updateOrderbook","params":{"ask":[{"price":"0.00000036888","size":"0"},{"price":"0.00000036908","size":"417100"},{"price":"0.00000042892","size":"0"},{"price":"0.00000043201","size":"522810"},{"price":"0.00000054417","size":"0"},{"price":"0.00000054581","size":"757990"},{"price":"0.00000065973","size":"15230630"},{"price":"0.00000077938","size":"0"},{"price":"0.00000078144","size":"2003810"},{"price":"0.00000094570","size":"2768620"},{"price":"0.00000283983","size":"0"},{"price":"0.00000284851","size":"4472830"}],"bid":[{"price":"0.00000034658","size":"234600"},{"price":"0.00000034622","size":"0"}],"sequence":10532262,"timestamp":"2021-07-15T03:00:22.000Z","symbol":"SCBTC"}}
1626318022.077461: {"jsonrpc":"2.0","method":"updateOrderbook","params":{"ask":[{"price":"0.00054632","size":"18.88"},{"price":"0.00054641","size":"0"},{"price":"0.00054643","size":"77.40"},{"price":"0.00054654","size":"0"},{"price":"0.00055621","size":"2539.46"},{"price":"0.00056934","size":"0"}],"bid":[{"price":"0.00054558","size":"0"},{"price":"0.00054557","size":"5.18"},{"price":"0.00053050","size":"442.49"},{"price":"0.00052837","size":"0"}],"sequence":19513069,"timestamp":"2021-07-15T03:00:22.037Z","symbol":"UNIBTC"}}
1626318022.147396: {"jsonrpc":"2.0","method":"updateOrderbook","params":{"ask":[],"bid":[{"price":"12.080","size":"5.7799"},{"price":"12.060","size":"0"}],"sequence":2190679,"timestamp":"2021-07-15T03:00:22.075Z","symbol":"SPIUSD"}}
1626318022.157311: {"jsonrpc":"2.0","method":"updateOrderbook","params":{"ask":[{"price":"0.616299","size":"160.9"},{"price":"0.616300","size":"0"},{"price":"0.662654","size":"399075.3"}],"bid":[{"price":"0.615413","size":"0"},{"price":"0.615339","size":"2848.3"},{"price":"0.609918","size":"0"},{"price":"0.609817","size":"491.9"},{"price":"0.584700","size":"195384.3"},{"price":"0.581347","size":"0"}],"sequence":20584074,"timestamp":"2021-07-15T03:00:22.122Z","symbol":"XRPUSDT"}}
1626318022.1820328: {"jsonrpc":"2.0","method":"updateOrderbook","params":{"ask":[{"price":"0.00000065973","size":"15230650"},{"price":"0.00000094570","size":"2768640"}],"bid":[{"price":"0.00000034658","size":"4600"},{"price":"0.00000034622","size":"230000"}],"sequence":10532263,"timestamp":"2021-07-15T03:00:22.106Z","symbol":"SCBTC"}}
1626318022.182077: {"jsonrpc":"2.0","method":"updateOrderbook","params":{"ask":[],"bid":[{"price":"0.00054558","size":"5.18"},{"price":"0.00054557","size":"0"}],"sequence":19513070,"timestamp":"2021-07-15T03:00:22.130Z","symbol":"UNIBTC"}}
1626318022.1821282: {"jsonrpc":"2.0","method":"updateOrderbook","params":{"ask":[{"price":"0.0004397","size":"0"},{"price":"0.0004398","size":"47.197"}],"bid":[],"sequence":2198424,"timestamp":"2021-07-15T03:00:22.079Z","symbol":"NUTBTC"}}
1626318022.273707: {"jsonrpc":"2.0","method":"updateOrderbook","params":{"ask":[{"price":"0.662654","size":"399075.5"}],"bid":[{"price":"0.615685","size":"0"},{"price":"0.615679","size":"1591.6"}],"sequence":20584075,"timestamp":"2021-07-15T03:00:22.201Z","symbol":"XRPUSDT"}}
1626318022.282727: {"jsonrpc":"2.0","method":"updateOrderbook","params":{"ask":[{"price":"0.00000065973","size":"15230660"},{"price":"0.00000094570","size":"2768660"}],"bid":[],"sequence":10532264,"timestamp":"2021-07-15T03:00:22.199Z","symbol":"SCBTC"}}
1626318022.2827861: {"jsonrpc":"2.0","method":"updateOrderbook","params":{"ask":[{"price":"0.00054575","size":"4.33"},{"price":"0.00054578","size":"0"}],"bid":[{"price":"0.00054558","size":"0"},{"price":"0.00054553","size":"5.18"}],"sequence":19513071,"timestamp":"2021-07-15T03:00:22.235Z","symbol":"UNIBTC"}}
1626318022.3577468: {"jsonrpc":"2.0","method":"updateOrderbook","params":{"ask":[{"price":"0.662654","size":"399075.8"}],"bid":[{"price":"0.615679","size":"0"},{"price":"0.615674","size":"1591.6"}],"sequence":20584076,"timestamp":"2021-07-15T03:00:22.277Z","symbol":"XRPUSDT"}}
1626318022.3794382: {"jsonrpc":"2.0","method":"updateOrderbook","params":{"ask":[{"price":"0.00000065973","size":"15230690"},{"price":"0.00000094570","size":"2768680"}],"bid":[{"price":"0.00000036454","size":"0"},{"price":"0.00000036428","size":"284390"},{"price":"0.00000034658","size":"234600"},{"price":"0.00000034622","size":"0"}],"sequence":10532265,"timestamp":"2021-07-15T03:00:22.318Z","symbol":"SCBTC"}}
1626318022.379505: {"jsonrpc":"2.0","method":"updateOrderbook","params":{"ask":[{"price":"0.00054571","size":"4.33"},{"price":"0.00054575","size":"0"}],"bid":[{"price":"0.00053050","size":"443.28"}],"sequence":19513072,"timestamp":"2021-07-15T03:00:22.307Z","symbol":"UNIBTC"}}
1626318022.4460359: {"jsonrpc":"2.0","method":"updateOrderbook","params":{"ask":[],"bid":[{"price":"12.079","size":"0"}],"sequence":2190680,"timestamp":"2021-07-15T03:00:22.405Z","symbol":"SPIUSD"}}
1626318022.482923: {"jsonrpc":"2.0","method":"updateOrderbook","params":{"ask":[{"price":"0.662654","size":"399076.2"}],"bid":[],"sequence":20584077,"timestamp":"2021-07-15T03:00:22.419Z","symbol":"XRPUSDT"}}
1626318022.4829812: {"jsonrpc":"2.0","method":"updateOrderbook","params":{"ask":[{"price":"0.00000043201","size":"0"},{"price":"0.00000043635","size":"522810"},{"price":"0.00000044087","size":"1381850"},{"price":"0.00000044539","size":"0"},{"price":"0.00000054581","size":"0"},{"price":"0.00000054811","size":"757990"},{"price":"0.00000065973","size":"15230710"},{"price":"0.00000078144","size":"0"},{"price":"0.00000078433","size":"2003810"},{"price":"0.00000094570","size":"2768700"},{"price":"0.00000095828","size":"0"},{"price":"0.00000095888","size":"2754880"},{"price":"0.00000284851","size":"0"},{"price":"0.00000286067","size":"4472830"}],"bid":[{"price":"0.00000036504","size":"0"},{"price":"0.00000036492","size":"110390"},{"price":"0.00000034658","size":"4600"},{"price":"0.00000034622","size":"230000"}],"sequence":10532266,"timestamp":"2021-07-15T03:00:22.441Z","symbol":"SCBTC"}}
1626318022.483022: {"jsonrpc":"2.0","method":"updateOrderbook","params":{"ask":[{"price":"0.00054570","size":"4.33"},{"price":"0.00054571","size":"0"},{"price":"0.00054591","size":"10.47"},{"price":"0.00054602","size":"0"}],"bid":[{"price":"0.00054553","size":"0"},{"price":"0.00054552","size":"5.18"},{"price":"0.00054366","size":"331.21"},{"price":"0.00054321","size":"0"}],"sequence":19513073,"timestamp":"2021-07-15T03:00:22.396Z","symbol":"UNIBTC"}}
1626318022.552046: {"jsonrpc":"2.0","method":"updateOrderbook","params":{"ask":[],"bid":[{"price":"12.080","size":"0"},{"price":"12.060","size":"5.7863"}],"sequence":2190681,"timestamp":"2021-07-15T03:00:22.478Z","symbol":"SPIUSD"}}
1626318022.589133: {"jsonrpc":"2.0","method":"updateOrderbook","params":{"ask":[{"price":"0.662654","size":"399076.4"}],"bid":[],"sequence":20584078,"timestamp":"2021-07-15T03:00:22.484Z","symbol":"XRPUSDT"}}
1626318022.589172: {"jsonrpc":"2.0","method":"updateOrderbook","params":{"ask":[{"price":"0.00000044087","size":"0"},{"price":"0.00000044130","size":"1381850"},{"price":"0.00000065973","size":"15230720"},{"price":"0.00000094570","size":"2768720"}],"bid":[{"price":"0.00000036505","size":"0"},{"price":"0.00000036493","size":"1000"}],"sequence":10532267,"timestamp":"2021-07-15T03:00:22.522Z","symbol":"SCBTC"}}
1626318022.655696: {"jsonrpc":"2.0","method":"updateOrderbook","params":{"ask":[{"price":"0.616853","size":"0"},{"price":"0.616917","size":"5500.0"},{"price":"0.662654","size":"399076.8"}],"bid":[{"price":"0.615679","size":"1591.6"},{"price":"0.615674","size":"0"}],"sequence":20584079,"timestamp":"2021-07-15T03:00:22.631Z","symbol":"XRPUSDT"}}
1626318022.671586: {"jsonrpc":"2.0","method":"updateOrderbook","params":{"ask":[{"price":"0.00000065973","size":"15230750"},{"price":"0.00000094570","size":"2768740"}],"bid":[{"price":"0.00000036493","size":"0"},{"price":"0.00000036492","size":"0"},{"price":"0.00000036482","size":"110390"},{"price":"0.00000034658","size":"234600"},{"price":"0.00000034622","size":"0"}],"sequence":10532268,"timestamp":"2021-07-15T03:00:22.640Z","symbol":"SCBTC"}}
1626318022.671631: {"jsonrpc":"2.0","method":"updateOrderbook","params":{"ask":[{"price":"0.00059499","size":"2343.84"},{"price":"0.00060103","size":"0"},{"price":"0.00078446","size":"3484.36"},{"price":"0.00078698","size":"0"}],"bid":[],"sequence":19513074,"timestamp":"2021-07-15T03:00:22.608Z","symbol":"UNIBTC"}}
1626318022.7458282: {"jsonrpc":"2.0","method":"updateOrderbook","params":{"ask":[],"bid":[{"price":"12.081","size":"5.8844"}],"sequence":2190682,"timestamp":"2021-07-15T03:00:22.653Z","symbol":"SPIUSD"}}
1626318022.752695: {"jsonrpc":"2.0","method":"updateOrderbook","params":{"ask":[{"price":"0.615739","size":"0"},{"price":"0.615754","size":"11000.0"},{"price":"0.615764","size":"0"},{"price":"0.615773","size":"1331.7"},{"price":"0.662654","size":"399077.1"}],"bid":[{"price":"0.615700","size":"1591.6"},{"price":"0.615679","size":"0"},{"price":"0.614316","size":"5500.0"},{"price":"0.614241","size":"1768.2"}],"sequence":20584080,"timestamp":"2021-07-15T03:00:22.730Z","symbol":"XRPUSDT"}}
1626318022.7785459: {"jsonrpc":"2.0","method":"updateOrderbook","params":{"ask":[{"price":"0.00000036719","size":"25530"},{"price":"0.00000036726","size":"0"},{"price":"0.00000065973","size":"15230760"},{"price":"0.00000094570","size":"2768760"}],"bid":[{"price":"0.00000036483","size":"1000"}],"sequence":10532269,"timestamp":"2021-07-15T03:00:22.717Z","symbol":"SCBTC"}}
1626318022.778694: {"jsonrpc":"2.0","method":"updateOrderbook","params":{"ask":[{"price":"0.00054616","size":"17.10"},{"price":"0.00054681","size":"218.69"},{"price":"0.00054689","size":"0"},{"price":"0.00054730","size":"373.82"},{"price":"0.00054767","size":"0"},{"price":"0.00054806","size":"0"},{"price":"0.00055087","size":"843.90"},{"price":"0.00055133","size":"0"},{"price":"0.00055621","size":"0"},{"price":"0.00055730","size":"2539.46"}],"bid":[],"sequence":19513075,"timestamp":"2021-07-15T03:00:22.654Z","symbol":"UNIBTC"}}
1626318022.851797: {"jsonrpc":"2.0","method":"updateOrderbook","params":{"ask":[],"bid":[{"price":"12.082","size":"5.7927"},{"price":"12.060","size":"0"}],"sequence":2190683,"timestamp":"2021-07-15T03:00:22.766Z","symbol":"SPIUSD"}}
1626318022.851837: {"jsonrpc":"2.0","method":"updateOrderbook","params":{"ask":[{"price":"0.615773","size":"0"},{"price":"0.615776","size":"1331.7"},{"price":"0.662654","size":"399077.4"}],"bid":[{"price":"0.615700","size":"0"},{"price":"0.615685","size":"1591.6"},{"price":"0.610018","size":"491.7"},{"price":"0.609817","size":"0"}],"sequence":20584081,"timestamp":"2021-07-15T03:00:22.820Z","symbol":"XRPUSDT"}}
1626318022.870295: {"jsonrpc":"2.0","method":"updateOrderbook","params":{"ask":[{"price":"0.00000065973","size":"15230780"},{"price":"0.00000094570","size":"2768780"}],"bid":[{"price":"0.00000036265","size":"0"},{"price":"0.00000036202","size":"1248220"},{"price":"0.00000034658","size":"4600"},{"price":"0.00000034622","size":"230000"},{"price":"0.00000032029","size":"0"},{"price":"0.00000023134","size":"1993120"},{"price":"0.00000004259","size":"0"},{"price":"0.00000000546","size":"2752080"}],"sequence":10532270,"timestamp":"2021-07-15T03:00:22.811Z","symbol":"SCBTC"}}
1626318022.870323: {"jsonrpc":"2.0","method":"updateOrderbook","params":{"ask":[{"price":"0.00054570","size":"0"},{"price":"0.00054571","size":"4.33"},{"price":"0.00054800","size":"658.12"},{"price":"0.00054961","size":"0"},{"price":"0.00059499","size":"0"},{"price":"0.00059880","size":"2343.84"},{"price":"0.00078446","size":"0"},{"price":"0.00078612","size":"3484.36"}],"bid":[],"sequence":19513076,"timestamp":"2021-07-15T03:00:22.829Z","symbol":"UNIBTC"}}
1626318022.958556: {"jsonrpc":"2.0","method":"updateOrderbook","params":{"ask":[{"price":"0.615768","size":"1331.7"},{"price":"0.615776","size":"0"},{"price":"0.662654","size":"399077.7"}],"bid":[{"price":"0.615685","size":"0"},{"price":"0.615675","size":"1591.6"}],"sequence":20584082,"timestamp":"2021-07-15T03:00:22.909Z","symbol":"XRPUSDT"}}
1626318022.9712949: {"jsonrpc":"2.0","method":"updateOrderbook","params":{"ask":[{"price":"0.00000065973","size":"15230800"},{"price":"0.00000088533","size":"2001500"},{"price":"0.00000090214","size":"0"},{"price":"0.00000094570","size":"2768800"}],"bid":[{"price":"0.00000036534","size":"28670"},{"price":"0.00000036525","size":"0"}],"sequence":10532271,"timestamp":"2021-07-15T03:00:22.918Z","symbol":"SCBTC"}}
1626318022.979106: {"jsonrpc":"2.0","method":"updateOrderbook","params":{"ask":[{"price":"0.00054569","size":"4.33"},{"price":"0.00054571","size":"0"}],"bid":[{"price":"0.00054552","size":"0"},{"price":"0.00054551","size":"5.18"},{"price":"0.00054527","size":"0"},{"price":"0.00054517","size":"18.33"},{"price":"0.00054255","size":"0"},{"price":"0.00054195","size":"914.50"}],"sequence":19513077,"timestamp":"2021-07-15T03:00:22.935Z","symbol":"UNIBTC"}}
1626318023.05729: {"jsonrpc":"2.0","method":"updateOrderbook","params":{"ask":[{"price":"0.662654","size":"399078.0"}],"bid":[],"sequence":20584083,"timestamp":"2021-07-15T03:00:23.014Z","symbol":"XRPUSDT"}}
1626318023.0860548: {"jsonrpc":"2.0","method":"updateOrderbook","params":{"ask":[{"price":"0.00000065973","size":"15230810"},{"price":"0.00000088533","size":"0"},{"price":"0.00000088679","size":"2001500"},{"price":"0.00000094570","size":"2768810"}],"bid":[{"price":"0.00000034658","size":"234600"},{"price":"0.00000034622","size":"0"}],"sequence":10532272,"timestamp":"2021-07-15T03:00:23.020Z","symbol":"SCBTC"}}
1626318023.08609: {"jsonrpc":"2.0","method":"updateOrderbook","params":{"ask":[{"price":"0.00054566","size":"4.33"},{"price":"0.00054569","size":"0"}],"bid":[{"price":"0.00054551","size":"0"},{"price":"0.00054549","size":"5.18"},{"price":"0.00054534","size":"0"},{"price":"0.00054528","size":"9.62"},{"price":"0.00054455","size":"0"},{"price":"0.00054423","size":"733.95"},{"price":"0.00054414","size":"0"},{"price":"0.00054382","size":"814.44"},{"price":"0.00052968","size":"0"},{"price":"0.00052929","size":"2974.71"}],"sequence":19513078,"timestamp":"2021-07-15T03:00:22.995Z","symbol":"UNIBTC"}}
1626318023.1715572: {"jsonrpc":"2.0","method":"updateOrderbook","params":{"ask":[{"price":"0.662654","size":"399078.3"}],"bid":[],"sequence":20584084,"timestamp":"2021-07-15T03:00:23.133Z","symbol":"XRPUSDT"}}
1626318023.178344: {"jsonrpc":"2.0","method":"updateOrderbook","params":{"ask":[{"price":"0.00000065973","size":"15230830"},{"price":"0.00000094570","size":"2768830"}],"bid":[],"sequence":10532273,"timestamp":"2021-07-15T03:00:23.132Z","symbol":"SCBTC"}}
1626318023.1783638: {"jsonrpc":"2.0","method":"updateOrderbook","params":{"ask":[{"price":"0.00054635","size":"16.96"},{"price":"0.00054648","size":"0"}],"bid":[{"price":"0.00054549","size":"0"},{"price":"0.00054546","size":"5.18"},{"price":"0.00054423","size":"353.16"},{"price":"0.00054407","size":"0"},{"price":"0.00054395","size":"380.79"},{"price":"0.00054369","size":"482.00"},{"price":"0.00054305","size":"0"},{"price":"0.00054268","size":"86.00"},{"price":"0.00053050","size":"0.79"}],"sequence":19513079,"timestamp":"2021-07-15T03:00:23.132Z","symbol":"UNIBTC"}}
1626318023.24979: {"jsonrpc":"2.0","method":"updateOrderbook","params":{"ask":[],"bid":[{"price":"12.081","size":"0"}],"sequence":2190684,"timestamp":"2021-07-15T03:00:23.201Z","symbol":"SPIUSD"}}
1626318023.2594528: {"jsonrpc":"2.0","method":"updateOrderbook","params":{"ask":[{"price":"0.615764","size":"1331.7"},{"price":"0.615768","size":"0"},{"price":"0.616846","size":"5500.0"},{"price":"0.616917","size":"0"},{"price":"0.662654","size":"399078.4"}],"bid":[{"price":"0.615681","size":"1591.6"},{"price":"0.615675","size":"0"}],"sequence":20584085,"timestamp":"2021-07-15T03:00:23.159Z","symbol":"XRPUSDT"}}
1626318023.279636: {"jsonrpc":"2.0","method":"updateOrderbook","params":{"ask":[{"price":"0.00000036719","size":"0"},{"price":"0.00000036726","size":"25530"},{"price":"0.00000041341","size":"1016210"},{"price":"0.00000041390","size":"0"},{"price":"0.00000044130","size":"0"},{"price":"0.00000044188","size":"1381850"},{"price":"0.00000065973","size":"15230840"},{"price":"0.00000088679","size":"0"},{"price":"0.00000088985","size":"2001500"},{"price":"0.00000094570","size":"2768840"}],"bid":[],"sequence":10532274,"timestamp":"2021-07-15T03:00:23.189Z","symbol":"SCBTC"}}
1626318023.2796779: {"jsonrpc":"2.0","method":"updateOrderbook","params":{"ask":[{"price":"0.00054564","size":"4.33"},{"price":"0.00054566","size":"0"},{"price":"0.00055082","size":"3878.47"},{"price":"0.00055158","size":"4111.40"},{"price":"0.00055196","size":"0"},{"price":"0.00055237","size":"4023.92"},{"price":"0.00055268","size":"0"},{"price":"0.00055312","size":"4002.23"},{"price":"0.00055363","size":"0"},{"price":"0.00055440","size":"0"},{"price":"0.00059880","size":"0"},{"price":"0.00060290","size":"2343.84"},{"price":"0.00078612","size":"0"},{"price":"0.00078772","size":"3484.36"}],"bid":[{"price":"0.00054517","size":"0"},{"price":"0.00054507","size":"18.33"},{"price":"0.00054501","size":"0"},{"price":"0.00054492","size":"18.61"},{"price":"0.00054470","size":"0"},{"price":"0.00054453","size":"196.86"},{"price":"0.00053050","size":"0"},{"price":"0.00052969","size":"443.17"}],"sequence":19513080,"timestamp":"2021-07-15T03:00:23.234Z","symbol":"UNIBTC"}}
1626318023.344838: {"jsonrpc":"2.0","method":"updateOrderbook","params":{"ask":[],"bid":[{"price":"12.083","size":"5.8835"},{"price":"12.082","size":"0"},{"price":"12.060","size":"5.8119"}],"sequence":2190685,"timestamp":"2021-07-15T03:00:23.279Z","symbol":"SPIUSD"}}
1626318023.3498838: {"jsonrpc":"2.0","method":"updateOrderbook","params":{"ask":[{"price":"0.662654","size":"399078.9"}],"bid":[],"sequence":20584086,"timestamp":"2021-07-15T03:00:23.312Z","symbol":"XRPUSDT"}}
1626318023.3653052: {"jsonrpc":"2.0","method":"updateOrderbook","params":{"ask":[{"price":"0.00000065973","size":"15230860"},{"price":"0.00000094570","size":"2768850"}],"bid":[],"sequence":10532275,"timestamp":"2021-07-15T03:00:23.300Z","symbol":"SCBTC"}}
1626318023.3654149: {"jsonrpc":"2.0","method":"updateOrderbook","params":{"ask":[{"price":"0.00054592","size":"16.70"},{"price":"0.00054606","size":"66.20"},{"price":"0.00054609","size":"0"},{"price":"0.00054618","size":"0"}],"bid":[{"price":"0.00054506","size":"0"},{"price":"0.00054490","size":"0"},{"price":"0.00054489","size":"18.58"},{"price":"0.00054473","size":"72.79"},{"price":"0.00054457","size":"0"},{"price":"0.00054426","size":"261.13"},{"price":"0.00054353","size":"0"},{"price":"0.00054350","size":"0"},{"price":"0.00054304","size":"0"},{"price":"0.00054292","size":"634.39"},{"price":"0.00054283","size":"1.47"},{"price":"0.00054243","size":"200.63"},{"price":"0.00054233","size":"0"},{"price":"0.00054149","size":"1015.38"},{"price":"0.00052929","size":"0"},{"price":"0.00052792","size":"2974.71"}],"sequence":19513081,"timestamp":"2021-07-15T03:00:23.338Z","symbol":"UNIBTC"}}
1626318023.447464: {"jsonrpc":"2.0","method":"updateOrderbook","params":{"ask":[],"bid":[{"price":"12.084","size":"5.8311"},{"price":"12.060","size":"0"}],"sequence":2190686,"timestamp":"2021-07-15T03:00:23.370Z","symbol":"SPIUSD"}}
1626318023.460812: {"jsonrpc":"2.0","method":"updateOrderbook","params":{"ask":[{"price":"0.662654","size":"399079.3"},{"price":"0.663943","size":"229002.7"},{"price":"0.666845","size":"0"},{"price":"0.836239","size":"324970.5"},{"price":"0.841249","size":"0"}],"bid":[],"sequence":20584087,"timestamp":"2021-07-15T03:00:23.438Z","symbol":"XRPUSDT"}}
1626318023.468456: {"jsonrpc":"2.0","method":"updateOrderbook","params":{"ask":[{"price":"0.00000065973","size":"15230870"},{"price":"0.00000094570","size":"2768870"},{"price":"0.00000095822","size":"2754880"},{"price":"0.00000095888","size":"0"}],"bid":[],"sequence":10532276,"timestamp":"2021-07-15T03:00:23.406Z","symbol":"SCBTC"}}
1626318023.468516: {"jsonrpc":"2.0","method":"updateOrderbook","params":{"ask":[],"bid":[{"price":"0.00054547","size":"5.18"},{"price":"0.00054546","size":"0"},{"price":"0.00052792","size":"0"},{"price":"0.00052657","size":"2974.71"}],"sequence":19513082,"timestamp":"2021-07-15T03:00:23.382Z","symbol":"UNIBTC"}}
1626318023.552083: {"jsonrpc":"2.0","method":"updateOrderbook","params":{"ask":[{"price":"0.662654","size":"399079.6"}],"bid":[],"sequence":20584088,"timestamp":"2021-07-15T03:00:23.541Z","symbol":"XRPUSDT"}}
1626318023.5657039: {"jsonrpc":"2.0","method":"updateOrderbook","params":{"ask":[{"price":"0.00000065973","size":"15230890"},{"price":"0.00000094570","size":"2768880"}],"bid":[],"sequence":10532277,"timestamp":"2021-07-15T03:00:23.512Z","symbol":"SCBTC"}}
1626318023.5717041: {"jsonrpc":"2.0","method":"updateOrderbook","params":{"ask":[{"price":"0.00054562","size":"4.33"},{"price":"0.00054564","size":"0"},{"price":"0.00054654","size":"201.47"},{"price":"0.00054671","size":"0"},{"price":"0.00054779","size":"86.00"},{"price":"0.00054823","size":"1302.32"}],"bid":[{"price":"0.00054547","size":"0"},{"price":"0.00054543","size":"5.18"},{"price":"0.00054528","size":"0"},{"price":"0.00054521","size":"9.62"},{"price":"0.00052969","size":"0"},{"price":"0.00052788","size":"2974.71"},{"price":"0.00052657","size":"0"}],"sequence":19513083,"timestamp":"2021-07-15T03:00:23.540Z","symbol":"UNIBTC"}}
1626318023.657692: {"jsonrpc":"2.0","method":"updateOrderbook","params":{"ask":[{"price":"0.662654","size":"399079.7"}],"bid":[],"sequence":20584089,"timestamp":"2021-07-15T03:00:23.570Z","symbol":"XRPUSDT"}}
1626318023.6679301: {"jsonrpc":"2.0","method":"updateOrderbook","params":{"ask":[{"price":"0.00000065973","size":"15230900"},{"price":"0.00000094570","size":"2768890"}],"bid":[],"sequence":10532278,"timestamp":"2021-07-15T03:00:23.590Z","symbol":"SCBTC"}}
1626318023.667974: {"jsonrpc":"2.0","method":"updateOrderbook","params":{"ask":[{"price":"0.00054562","size":"0"},{"price":"0.00054565","size":"4.33"},{"price":"0.00054592","size":"0"},{"price":"0.00054606","size":"0"},{"price":"0.00054621","size":"16.70"},{"price":"0.00054629","size":"0"},{"price":"0.00054639","size":"0"},{"price":"0.00054642","size":"66.20"},{"price":"0.00054666","size":"199.63"},{"price":"0.00054670","size":"0"},{"price":"0.00054684","size":"296.51"},{"price":"0.00054707","size":"333.84"}],"bid":[{"price":"0.00054547","size":"5.18"},{"price":"0.00054543","size":"0"},{"price":"0.00052910","size":"443.66"}],"sequence":19513084,"timestamp":"2021-07-15T03:00:23.632Z","symbol":"UNIBTC"}}
1626318023.764384: {"jsonrpc":"2.0","method":"updateOrderbook","params":{"ask":[{"price":"0.662654","size":"399080.1"}],"bid":[],"sequence":20584090,"timestamp":"2021-07-15T03:00:23.738Z","symbol":"XRPUSDT"}}
1626318023.772853: {"jsonrpc":"2.0","method":"updateOrderbook","params":{"ask":[{"price":"0.00000065973","size":"15230920"},{"price":"0.00000094570","size":"2768910"}],"bid":[],"sequence":10532279,"timestamp":"2021-07-15T03:00:23.696Z","symbol":"SCBTC"}}
1626318023.772911: {"jsonrpc":"2.0","method":"updateOrderbook","params":{"ask":[{"price":"0.00054565","size":"0"},{"price":"0.00054568","size":"4.33"}],"bid":[],"sequence":19513085,"timestamp":"2021-07-15T03:00:23.718Z","symbol":"UNIBTC"}}
1626318023.845557: {"jsonrpc":"2.0","method":"updateOrderbook","params":{"ask":[],"bid":[{"price":"12.083","size":"0"}],"sequence":2190687,"timestamp":"2021-07-15T03:00:23.783Z","symbol":"SPIUSD"}}
1626318023.85454: {"jsonrpc":"2.0","method":"updateOrderbook","params":{"ask":[{"price":"0.616846","size":"0"},{"price":"0.616910","size":"5500.0"},{"price":"0.662654","size":"399080.3"}],"bid":[],"sequence":20584091,"timestamp":"2021-07-15T03:00:23.770Z","symbol":"XRPUSDT"}}
1626318023.868036: {"jsonrpc":"2.0","method":"updateOrderbook","params":{"ask":[{"price":"0.00000065973","size":"15230940"},{"price":"0.00000094570","size":"2768930"}],"bid":[{"price":"0.00000034002","size":"0"},{"price":"0.00000034001","size":"0"},{"price":"0.00000033944","size":"234600"}],"sequence":10532280,"timestamp":"2021-07-15T03:00:23.838Z","symbol":"SCBTC"}}
1626318023.868085: {"jsonrpc":"2.0","method":"updateOrderbook","params":{"ask":[{"price":"0.00054621","size":"35.58"},{"price":"0.00054632","size":"0"},{"price":"0.00054823","size":"0"},{"price":"0.00054894","size":"1302.32"}],"bid":[{"price":"0.00054549","size":"5.18"},{"price":"0.00054547","size":"0"},{"price":"0.00054527","size":"9.62"},{"price":"0.00054521","size":"0"},{"price":"0.00052910","size":"0"},{"price":"0.00052788","size":"0"},{"price":"0.00052486","size":"2974.71"}],"sequence":19513086,"timestamp":"2021-07-15T03:00:23.815Z","symbol":"UNIBTC"}}
1626318023.94646: {"jsonrpc":"2.0","method":"updateOrderbook","params":{"ask":[],"bid":[{"price":"12.085","size":"5.8825"},{"price":"12.084","size":"0"},{"price":"12.060","size":"5.8503"}],"sequence":2190688,"timestamp":"2021-07-15T03:00:23.866Z","symbol":"SPIUSD"}}
1626318023.972667: {"jsonrpc":"2.0","method":"updateOrderbook","params":{"ask":[{"price":"0.662654","size":"399080.6"}],"bid":[],"sequence":20584092,"timestamp":"2021-07-15T03:00:23.872Z","symbol":"XRPUSDT"}}
1626318023.9727209: {"jsonrpc":"2.0","method":"updateOrderbook","params":{"ask":[{"price":"0.00000094570","size":"2768940"},{"price":"0.00000146884","size":"3222000"},{"price":"0.00000147008","size":"0"}],"bid":[],"sequence":10532281,"timestamp":"2021-07-15T03:00:23.942Z","symbol":"SCBTC"}}
1626318023.972748: {"jsonrpc":"2.0","method":"updateOrderbook","params":{"ask":[{"price":"0.00054567","size":"4.33"},{"price":"0.00054568","size":"0"},{"price":"0.00054597","size":"16.70"},{"price":"0.00054610","size":"66.20"},{"price":"0.00054621","size":"18.88"},{"price":"0.00054642","size":"0"},{"price":"0.00055042","size":"843.90"},{"price":"0.00055087","size":"0"}],"bid":[{"price":"0.00054434","size":"177.91"},{"price":"0.00054412","size":"239.70"},{"price":"0.00054408","size":"0"},{"price":"0.00054396","size":"1.17"},{"price":"0.00052789","size":"444.68"}],"sequence":19513087,"timestamp":"2021-07-15T03:00:23.940Z","symbol":"UNIBTC"}}
1626318024.0477471: {"jsonrpc":"2.0","method":"updateOrderbook","params":{"ask":[],"bid":[{"price":"12.086","size":"5.8695"},{"price":"12.060","size":"0"}],"sequence":2190689,"timestamp":"2021-07-15T03:00:23.971Z","symbol":"SPIUSD"}}
1626318024.0793579: {"jsonrpc":"2.0","method":"updateOrderbook","params":{"ask":[{"price":"0.662654","size":"399080.9"}],"bid":[],"sequence":20584093,"timestamp":"2021-07-15T03:00:23.975Z","symbol":"XRPUSDT"}}
1626318024.079415: {"jsonrpc":"2.0","method":"updateOrderbook","params":{"ask":[{"price":"0.00000065973","size":"15230950"},{"price":"0.00000380755","size":"7466230"},{"price":"0.00000385651","size":"0"}],"bid":[],"sequence":10532282,"timestamp":"2021-07-15T03:00:23.946Z","symbol":"SCBTC"}}
1626318024.0794408: {"jsonrpc":"2.0","method":"updateOrderbook","params":{"ask":[{"price":"0.00054566","size":"4.33"},{"price":"0.00054567","size":"0"}],"bid":[{"price":"0.00054549","size":"0"},{"price":"0.00054548","size":"5.18"}],"sequence":19513088,"timestamp":"2021-07-15T03:00:24.018Z","symbol":"UNIBTC"}}
1626318024.16463: {"jsonrpc":"2.0","method":"updateOrderbook","params":{"ask":[{"price":"0.627206","size":"129038.8"},{"price":"0.629647","size":"0"},{"price":"0.643665","size":"347706.3"},{"price":"0.645449","size":"0"},{"price":"0.651907","size":"181214.3"},{"price":"0.654131","size":"0"},{"price":"0.657746","size":"485414.3"},{"price":"0.659380","size":"0"},{"price":"0.662654","size":"399081.3"}],"bid":[],"sequence":20584094,"timestamp":"2021-07-15T03:00:24.098Z","symbol":"XRPUSDT"}}
1626318024.1734028: {"jsonrpc":"2.0","method":"updateOrderbook","params":{"ask":[{"price":"0.00000065973","size":"15230980"},{"price":"0.00000094570","size":"2768970"}],"bid":[{"price":"0.00000034658","size":"4600"},{"price":"0.00000034622","size":"230000"}],"sequence":10532283,"timestamp":"2021-07-15T03:00:24.094Z","symbol":"SCBTC"}}
1626318024.173471: {"jsonrpc":"2.0","method":"updateOrderbook","params":{"ask":[{"price":"0.00054565","size":"4.33"},{"price":"0.00054566","size":"0"},{"price":"0.00054631","size":"77.40"},{"price":"0.00054643","size":"0"},{"price":"0.00054645","size":"66.76"},{"price":"0.00054664","size":"0"}],"bid":[{"price":"0.00052789","size":"0"}],"sequence":19513089,"timestamp":"2021-07-15T03:00:24.105Z","symbol":"UNIBTC"}}
1626318024.173562: {"jsonrpc":"2.0","method":"updateOrderbook","params":{"ask":[{"price":"0.0004397","size":"47.197"},{"price":"0.0004398","size":"0"}],"bid":[],"sequence":2198425,"timestamp":"2021-07-15T03:00:24.099Z","symbol":"NUTBTC"}}
1626318024.254015: {"jsonrpc":"2.0","method":"updateOrderbook","params":{"ask":[{"price":"0.662654","size":"399081.5"}],"bid":[{"price":"0.610018","size":"0"},{"price":"0.609918","size":"491.8"}],"sequence":20584095,"timestamp":"2021-07-15T03:00:24.192Z","symbol":"XRPUSDT"}}
1626318024.26733: {"jsonrpc":"2.0","method":"updateOrderbook","params":{"ask":[{"price":"0.00000041289","size":"1016210"},{"price":"0.00000041341","size":"0"},{"price":"0.00000065973","size":"15230990"},{"price":"0.00000094570","size":"2768980"},{"price":"0.00000380755","size":"0"},{"price":"0.00000381291","size":"7466230"}],"bid":[],"sequence":10532284,"timestamp":"2021-07-15T03:00:24.202Z","symbol":"SCBTC"}}
1626318024.267355: {"jsonrpc":"2.0","method":"updateOrderbook","params":{"ask":[{"price":"0.00054563","size":"4.33"},{"price":"0.00054565","size":"0"},{"price":"0.00054581","size":"10.47"},{"price":"0.00054591","size":"0"},{"price":"0.00054612","size":"199.63"},{"price":"0.00054622","size":"296.51"},{"price":"0.00054666","size":"0"},{"price":"0.00054684","size":"0"},{"price":"0.00054913","size":"3933.58"},{"price":"0.00054982","size":"0"}],"bid":[{"price":"0.00054548","size":"0"},{"price":"0.00054545","size":"5.18"},{"price":"0.00054435","size":"0"},{"price":"0.00054412","size":"515.01"},{"price":"0.00052694","size":"445.48"}],"sequence":19513090,"timestamp":"2021-07-15T03:00:24.224Z","symbol":"UNIBTC"}}
1626318024.349917: {"jsonrpc":"2.0","method":"updateOrderbook","params":{"ask":[{"price":"0.0000013617","size":"111546"},{"price":"0.0000013623","size":"0"},{"price":"0.0000013676","size":"0"},{"price":"0.0000013687","size":"210934"},{"price":"0.0000013838","size":"0"},{"price":"0.0000013851","size":"259015"},{"price":"0.0000014016","size":"0"},{"price":"0.0000014021","size":"368558"},{"price":"0.0000014222","size":"0"},{"price":"0.0000014243","size":"481455"},{"price":"0.0000015022","size":"724406"},{"price":"0.0000015029","size":"0"},{"price":"0.0000016641","size":"982126"},{"price":"0.0000016648","size":"0"},{"price":"0.0000017873","size":"0"},{"price":"0.0000017890","size":"1389932"}],"bid":[],"sequence":495980,"timestamp":"2021-07-15T03:00:24.282Z","symbol":"STPTBTC"}}
1626318024.349967: {"jsonrpc":"2.0","method":"updateOrderbook","params":{"ask":[],"bid":[{"price":"12.085","size":"0"}],"sequence":2190690,"timestamp":"2021-07-15T03:00:24.296Z","symbol":"SPIUSD"}}
1626318024.3522692: {"jsonrpc":"2.0","method":"updateOrderbook","params":{"ask":[{"price":"0.662654","size":"399081.8"}],"bid":[],"sequence":20584096,"timestamp":"2021-07-15T03:00:24.277Z","symbol":"XRPUSDT"}}
1626318024.38328: {"jsonrpc":"2.0","method":"updateOrderbook","params":{"ask":[{"price":"0.00000065973","size":"15231010"},{"price":"0.00000094570","size":"2769000"}],"bid":[],"sequence":10532285,"timestamp":"2021-07-15T03:00:24.308Z","symbol":"SCBTC"}}
1626318024.383339: {"jsonrpc":"2.0","method":"updateOrderbook","params":{"ask":[{"price":"0.00054826","size":"4260.24"},{"price":"0.00054876","size":"0"}],"bid":[{"price":"0.00054546","size":"5.18"},{"price":"0.00054545","size":"0"},{"price":"0.00054376","size":"0"},{"price":"0.00054348","size":"0"},{"price":"0.00054333","size":"679.54"},{"price":"0.00054302","size":"1046.45"}],"sequence":19513091,"timestamp":"2021-07-15T03:00:24.322Z","symbol":"UNIBTC"}}
1626318024.383455: {"jsonrpc":"2.0","method":"updateOrderbook","params":{"ask":[{"price":"0.0004397","size":"0"},{"price":"0.0004398","size":"47.197"}],"bid":[],"sequence":2198426,"timestamp":"2021-07-15T03:00:24.331Z","symbol":"NUTBTC"}}
1626318024.4496372: {"jsonrpc":"2.0","method":"updateOrderbook","params":{"ask":[],"bid":[{"price":"12.087","size":"5.8815"},{"price":"12.086","size":"0"},{"price":"12.060","size":"5.8930"}],"sequence":2190691,"timestamp":"2021-07-15T03:00:24.398Z","symbol":"SPIUSD"}}
1626318024.4531882: {"jsonrpc":"2.0","method":"updateOrderbook","params":{"ask":[{"price":"0.662654","size":"0"},{"price":"0.662655","size":"399082.1"}],"bid":[],"sequence":20584097,"timestamp":"2021-07-15T03:00:24.384Z","symbol":"XRPUSDT"}}
1626318024.47924: {"jsonrpc":"2.0","method":"updateOrderbook","params":{"ask":[{"price":"0.00000037254","size":"661850"},{"price":"0.00000037386","size":"3308650"},{"price":"0.00000040717","size":"522810"},{"price":"0.00000043635","size":"0"},{"price":"0.00000052883","size":"757990"},{"price":"0.00000054811","size":"0"},{"price":"0.00000065973","size":"15231030"},{"price":"0.00000094570","size":"2769010"},{"price":"0.00000159405","size":"0"},{"price":"0.00000161010","size":"4634410"},{"price":"0.00000381291","size":"0"},{"price":"0.00000416349","size":"7466230"}],"bid":[{"price":"0.00000034658","size":"234600"},{"price":"0.00000034622","size":"0"}],"sequence":10532286,"timestamp":"2021-07-15T03:00:24.436Z","symbol":"SCBTC"}}
1626318024.479279: {"jsonrpc":"2.0","method":"updateOrderbook","params":{"ask":[],"bid":[{"price":"0.00054507","size":"0"},{"price":"0.00054497","size":"18.34"},{"price":"0.00054292","size":"0"},{"price":"0.00054281","size":"634.39"},{"price":"0.00052694","size":"446.28"},{"price":"0.00052486","size":"0"},{"price":"0.00052288","size":"2974.71"}],"sequence":19513092,"timestamp":"2021-07-15T03:00:24.439Z","symbol":"UNIBTC"}}
1626318024.546707: {"jsonrpc":"2.0","method":"updateOrderbook","params":{"ask":[],"bid":[{"price":"12.088","size":"5.9165"},{"price":"12.060","size":"0"}],"sequence":2190692,"timestamp":"2021-07-15T03:00:24.469Z","symbol":"SPIUSD"}}
1626318024.563597: {"jsonrpc":"2.0","method":"updateOrderbook","params":{"ask":[{"price":"0.662655","size":"399082.4"}],"bid":[],"sequence":20584098,"timestamp":"2021-07-15T03:00:24.490Z","symbol":"XRPUSDT"}}
1626318024.575747: {"jsonrpc":"2.0","method":"updateOrderbook","params":{"ask":[{"price":"0.00000065973","size":"15231040"},{"price":"0.00000094570","size":"2769030"}],"bid":[],"sequence":10532287,"timestamp":"2021-07-15T03:00:24.532Z","symbol":"SCBTC"}}
1626318024.5774999: {"jsonrpc":"2.0","method":"updateOrderbook","params":{"ask":[{"price":"0.00054663","size":"333.84"},{"price":"0.00054707","size":"0"}],"bid":[{"price":"0.00054480","size":"69.23"},{"price":"0.00054457","size":"199.39"}],"sequence":19513093,"timestamp":"2021-07-15T03:00:24.540Z","symbol":"UNIBTC"}}
1626318024.6703072: {"jsonrpc":"2.0","method":"updateOrderbook","params":{"ask":[{"price":"0.615764","size":"0"},{"price":"0.615771","size":"1331.7"},{"price":"0.616298","size":"6528.9"},{"price":"0.616354","size":"0"},{"price":"0.662655","size":"399082.9"}],"bid":[{"price":"0.615696","size":"1591.6"},{"price":"0.615681","size":"0"}],"sequence":20584099,"timestamp":"2021-07-15T03:00:24.632Z","symbol":"XRPUSDT"}}
1626318024.679009: {"jsonrpc":"2.0","method":"updateOrderbook","params":{"ask":[{"price":"0.00000037254","size":"0"},{"price":"0.00000037334","size":"661850"},{"price":"0.00000065973","size":"15231060"},{"price":"0.00000094570","size":"2769040"}],"bid":[],"sequence":10532288,"timestamp":"2021-07-15T03:00:24.627Z","symbol":"SCBTC"}}
1626318024.679071: {"jsonrpc":"2.0","method":"updateOrderbook","params":{"ask":[{"price":"0.00054639","size":"18.09"},{"price":"0.00054655","size":"0"}],"bid":[],"sequence":19513094,"timestamp":"2021-07-15T03:00:24.576Z","symbol":"UNIBTC"}}
1626318024.750531: {"jsonrpc":"2.0","method":"updateOrderbook","params":{"ask":[{"price":"0.615767","size":"1331.7"},{"price":"0.615771","size":"0"},{"price":"0.662655","size":"399083.2"}],"bid":[{"price":"0.615696","size":"0"},{"price":"0.615686","size":"1591.6"}],"sequence":20584100,"timestamp":"2021-07-15T03:00:24.739Z","symbol":"XRPUSDT"}}
1626318024.77438: {"jsonrpc":"2.0","method":"updateOrderbook","params":{"ask":[{"price":"0.00000065973","size":"15231070"},{"price":"0.00000094570","size":"2769060"}],"bid":[{"price":"0.00000036507","size":"110390"},{"price":"0.00000036482","size":"0"}],"sequence":10532289,"timestamp":"2021-07-15T03:00:24.737Z","symbol":"SCBTC"}}
1626318024.774422: {"jsonrpc":"2.0","method":"updateOrderbook","params":{"ask":[{"price":"0.00054561","size":"4.33"},{"price":"0.00054563","size":"0"},{"price":"0.00054779","size":"170.00"},{"price":"0.00054822","size":"0"},{"price":"0.00055042","size":"0"},{"price":"0.00055112","size":"843.90"},{"price":"0.00055730","size":"0"},{"price":"0.00055901","size":"2539.46"}],"bid":[{"price":"0.00054546","size":"0"},{"price":"0.00054529","size":"5.18"},{"price":"0.00054527","size":"0"},{"price":"0.00054512","size":"9.62"},{"price":"0.00054484","size":"0"},{"price":"0.00054457","size":"217.26"}],"sequence":19513095,"timestamp":"2021-07-15T03:00:24.740Z","symbol":"UNIBTC"}}
1626318024.851365: {"jsonrpc":"2.0","method":"updateOrderbook","params":{"ask":[],"bid":[{"price":"12.087","size":"0"}],"sequence":2190693,"timestamp":"2021-07-15T03:00:24.819Z","symbol":"SPIUSD"}}
1626318024.8727648: {"jsonrpc":"2.0","method":"updateOrderbook","params":{"ask":[{"price":"0.00000065973","size":"15231090"},{"price":"0.00000094570","size":"2769070"}],"bid":[{"price":"0.00000036508","size":"1000"},{"price":"0.00000036483","size":"0"}],"sequence":10532290,"timestamp":"2021-07-15T03:00:24.813Z","symbol":"SCBTC"}}
1626318024.876035: {"jsonrpc":"2.0","method":"updateOrderbook","params":{"ask":[{"price":"0.00054552","size":"4.33"},{"price":"0.00054561","size":"0"},{"price":"0.00054689","size":"440.89"},{"price":"0.00054731","size":"0"},{"price":"0.00054766","size":"484.13"},{"price":"0.00054802","size":"0"},{"price":"0.00055901","size":"0"},{"price":"0.00055992","size":"2539.46"}],"bid":[{"price":"0.00054529","size":"0"},{"price":"0.00054517","size":"5.18"},{"price":"0.00054515","size":"0"},{"price":"0.00054512","size":"0"},{"price":"0.00054497","size":"9.62"},{"price":"0.00054496","size":"0"},{"price":"0.00054489","size":"0"},{"price":"0.00054486","size":"36.37"},{"price":"0.00054473","size":"0"},{"price":"0.00054467","size":"18.58"},{"price":"0.00054460","size":"0"},{"price":"0.00054457","size":"98.11"},{"price":"0.00054453","size":"0"},{"price":"0.00054451","size":"72.79"},{"price":"0.00054438","size":"199.39"},{"price":"0.00054436","size":"196.86"},{"price":"0.00054423","size":"0"},{"price":"0.00054411","size":"21.05"},{"price":"0.00054393","size":"353.16"},{"price":"0.00054335","size":"634.39"},{"price":"0.00054281","size":"0"}],"sequence":19513096,"timestamp":"2021-07-15T03:00:24.834Z","symbol":"UNIBTC"}}
1626318024.948452: {"jsonrpc":"2.0","method":"updateOrderbook","params":{"ask":[],"bid":[{"price":"12.089","size":"5.8806"},{"price":"12.088","size":"0"},{"price":"12.060","size":"5.9817"}],"sequence":2190694,"timestamp":"2021-07-15T03:00:24.894Z","symbol":"SPIUSD"}}
1626318025.0064151: {"jsonrpc":"2.0","method":"updateOrderbook","params":{"ask":[{"price":"0.662655","size":"399083.7"}],"bid":[],"sequence":20584101,"timestamp":"2021-07-15T03:00:24.895Z","symbol":"XRPUSDT"}}
1626318025.00647: {"jsonrpc":"2.0","method":"updateOrderbook","params":{"ask":[{"price":"0.00000040717","size":"0"},{"price":"0.00000042892","size":"522810"},{"price":"0.00000052883","size":"0"},{"price":"0.00000054417","size":"757990"},{"price":"0.00000065973","size":"15231100"},{"price":"0.00000094570","size":"2769080"}],"bid":[{"price":"0.00000036507","size":"0"},{"price":"0.00000036495","size":"110390"}],"sequence":10532291,"timestamp":"2021-07-15T03:00:24.903Z","symbol":"SCBTC"}}
1626318025.0065029: {"jsonrpc":"2.0","method":"updateOrderbook","params":{"ask":[{"price":"0.00054543","size":"4.33"},{"price":"0.00054552","size":"0"},{"price":"0.00054566","size":"10.47"},{"price":"0.00054581","size":"0"},{"price":"0.00054621","size":"85.64"},{"price":"0.00054645","size":"0"},{"price":"0.00054800","size":"0"},{"price":"0.00054867","size":"1245.48"},{"price":"0.00055992","size":"0"},{"price":"0.00056289","size":"2539.46"}],"bid":[{"price":"0.00054517","size":"0"},{"price":"0.00054511","size":"5.18"},{"price":"0.00054497","size":"0"},{"price":"0.00054490","size":"9.62"},{"price":"0.00054486","size":"18.34"},{"price":"0.00054480","size":"0"},{"price":"0.00054472","size":"18.03"},{"price":"0.00054450","size":"69.23"}],"sequence":19513097,"timestamp":"2021-07-15T03:00:24.941Z","symbol":"UNIBTC"}}
1626318025.046565: {"jsonrpc":"2.0","method":"updateOrderbook","params":{"ask":[],"bid":[{"price":"12.090","size":"6.0469"},{"price":"12.060","size":"0"}],"sequence":2190695,"timestamp":"2021-07-15T03:00:25.010Z","symbol":"SPIUSD"}}
1626318025.056051: {"jsonrpc":"2.0","method":"updateOrderbook","params":{"ask":[{"price":"0.615754","size":"0"},{"price":"0.662655","size":"399084.0"}],"bid":[{"price":"0.615254","size":"1337.0"},{"price":"0.615195","size":"0"}],"sequence":20584102,"timestamp":"2021-07-15T03:00:25.016Z","symbol":"XRPUSDT"}}
1626318025.07718: {"jsonrpc":"2.0","method":"updateOrderbook","params":{"ask":[{"price":"0.00000042892","size":"0"},{"price":"0.00000043201","size":"522810"},{"price":"0.00000054417","size":"0"},{"price":"0.00000054581","size":"757990"},{"price":"0.00000065973","size":"15231120"},{"price":"0.00000094570","size":"2769100"},{"price":"0.00000095822","size":"0"},{"price":"0.00000095882","size":"2754880"}],"bid":[{"price":"0.00000036508","size":"0"},{"price":"0.00000036496","size":"1000"}],"sequence":10532292,"timestamp":"2021-07-15T03:00:25.025Z","symbol":"SCBTC"}}
1626318025.077227: {"jsonrpc":"2.0","method":"updateOrderbook","params":{"ask":[{"price":"0.00054543","size":"0"},{"price":"0.00054546","size":"4.33"},{"price":"0.00054621","size":"18.88"},{"price":"0.00054640","size":"66.76"},{"price":"0.00054693","size":"193.61"},{"price":"0.00054716","size":"0"},{"price":"0.00054727","size":"963.50"},{"price":"0.00054773","size":"0"},{"price":"0.00055281","size":"0"},{"price":"0.00055340","size":"1811.87"}],"bid":[{"price":"0.00054511","size":"0"},{"price":"0.00054500","size":"5.18"},{"price":"0.00054490","size":"0"},{"price":"0.00054481","size":"9.62"},{"price":"0.00054457","size":"80.24"},{"price":"0.00054429","size":"17.87"},{"price":"0.00054382","size":"0"},{"price":"0.00054346","size":"468.52"},{"price":"0.00054345","size":"346.15"},{"price":"0.00054335","size":"0"},{"price":"0.00054333","size":"0"},{"price":"0.00054281","size":"679.54"},{"price":"0.00054267","size":"0"},{"price":"0.00054250","size":"634.39"},{"price":"0.00054221","size":"929.35"}],"sequence":19513098,"timestamp":"2021-07-15T03:00:25.018Z","symbol":"UNIBTC"}}
1626318025.1605911: {"jsonrpc":"2.0","method":"updateOrderbook","params":{"ask":[{"price":"0.615767","size":"0"},{"price":"0.615778","size":"1331.7"},{"price":"0.616297","size":"160.9"},{"price":"0.616299","size":"0"},{"price":"0.662624","size":"11000.0"},{"price":"0.662655","size":"399084.4"}],"bid":[{"price":"0.615707","size":"11000.0"},{"price":"0.615686","size":"0"},{"price":"0.615677","size":"1591.6"}],"sequence":20584103,"timestamp":"2021-07-15T03:00:25.141Z","symbol":"XRPUSDT"}}
1626318025.175946: {"jsonrpc":"2.0","method":"updateOrderbook","params":{"ask":[{"price":"0.00000065973","size":"15231140"},{"price":"0.00000094570","size":"2769110"}],"bid":[],"sequence":10532293,"timestamp":"2021-07-15T03:00:25.138Z","symbol":"SCBTC"}}
1626318025.1759648: {"jsonrpc":"2.0","method":"updateOrderbook","params":{"ask":[{"price":"0.00054567","size":"16.70"},{"price":"0.00054581","size":"66.20"},{"price":"0.00054597","size":"0"},{"price":"0.00054610","size":"0"},{"price":"0.00054616","size":"34.06"},{"price":"0.00054619","size":"77.40"},{"price":"0.00054631","size":"0"},{"price":"0.00054635","size":"0"},{"price":"0.00054673","size":"276.50"},{"price":"0.00054696","size":"0"},{"price":"0.00054867","size":"587.36"},{"price":"0.00054919","size":"658.12"},{"price":"0.00056289","size":"0"},{"price":"0.00056714","size":"2539.46"}],"bid":[{"price":"0.00054426","size":"0"},{"price":"0.00054412","size":"275.31"},{"price":"0.00054400","size":"261.13"},{"price":"0.00054393","size":"0"},{"price":"0.00054390","size":"239.81"},{"price":"0.00054360","size":"353.16"},{"price":"0.00054346","size":"0"},{"price":"0.00054296","size":"468.52"},{"price":"0.00054285","size":"0"},{"price":"0.00054250","size":"0"},{"price":"0.00054226","size":"977.91"},{"price":"0.00054185","size":"634.39"},{"price":"0.00054179","size":"0"},{"price":"0.00054080","size":"986.13"},{"price":"0.00052288","size":"0"},{"price":"0.00051951","size":"2974.71"}],"sequence":19513099,"timestamp":"2021-07-15T03:00:25.127Z","symbol":"UNIBTC"}}
1626318025.2623098: {"jsonrpc":"2.0","method":"updateOrderbook","params":{"ask":[{"price":"0.615765","size":"1331.7"},{"price":"0.615778","size":"0"},{"price":"0.662655","size":"399084.6"}],"bid":[{"price":"0.615677","size":"0"},{"price":"0.615661","size":"1591.6"}],"sequence":20584104,"timestamp":"2021-07-15T03:00:25.208Z","symbol":"XRPUSDT"}}
1626318025.267713: {"jsonrpc":"2.0","method":"updateOrderbook","params":{"ask":[{"price":"0.00000094570","size":"2769120"}],"bid":[],"sequence":10532294,"timestamp":"2021-07-15T03:00:25.146Z","symbol":"SCBTC"}}
1626318025.267752: {"jsonrpc":"2.0","method":"updateOrderbook","params":{"ask":[{"price":"0.00054539","size":"4.33"},{"price":"0.00054546","size":"0"},{"price":"0.00054607","size":"18.88"},{"price":"0.00054621","size":"0"},{"price":"0.00054867","size":"1245.48"},{"price":"0.00054919","size":"0"}],"bid":[{"price":"0.00054503","size":"5.18"},{"price":"0.00054500","size":"0"},{"price":"0.00054369","size":"0"},{"price":"0.00054327","size":"482.00"},{"price":"0.00051951","size":"0"},{"price":"0.00051486","size":"2974.71"}],"sequence":19513100,"timestamp":"2021-07-15T03:00:25.222Z","symbol":"UNIBTC"}}
1626318025.354804: {"jsonrpc":"2.0","method":"updateOrderbook","params":{"ask":[{"price":"0.662655","size":"399085.0"}],"bid":[{"price":"0.615080","size":"13468.6"},{"price":"0.614980","size":"0"}],"sequence":20584105,"timestamp":"2021-07-15T03:00:25.338Z","symbol":"XRPUSDT"}}
1626318025.3798258: {"jsonrpc":"2.0","method":"updateOrderbook","params":{"ask":[{"price":"0.00000065973","size":"15231170"},{"price":"0.00000094570","size":"2769140"}],"bid":[{"price":"0.00000034003","size":"14700"}],"sequence":10532295,"timestamp":"2021-07-15T03:00:25.338Z","symbol":"SCBTC"}}
1626318025.3798678: {"jsonrpc":"2.0","method":"updateOrderbook","params":{"ask":[],"bid":[{"price":"0.00054467","size":"0"},{"price":"0.00054451","size":"0"},{"price":"0.00054447","size":"18.58"},{"price":"0.00054434","size":"0"},{"price":"0.00054431","size":"72.79"},{"price":"0.00054416","size":"0"},{"price":"0.00054409","size":"177.91"},{"price":"0.00054367","size":"269.93"},{"price":"0.00054366","size":"0"},{"price":"0.00054279","size":"331.21"},{"price":"0.00054006","size":"0"},{"price":"0.00053899","size":"1151.25"}],"sequence":19513101,"timestamp":"2021-07-15T03:00:25.311Z","symbol":"UNIBTC"}}
1626318025.4450638: {"jsonrpc":"2.0","method":"updateOrderbook","params":{"ask":[],"bid":[{"price":"12.089","size":"0"}],"sequence":2190696,"timestamp":"2021-07-15T03:00:25.376Z","symbol":"SPIUSD"}}
1626318025.4848242: {"jsonrpc":"2.0","method":"updateOrderbook","params":{"ask":[{"price":"0.662655","size":"399085.1"}],"bid":[{"price":"0.615669","size":"1591.6"},{"price":"0.615661","size":"0"}],"sequence":20584106,"timestamp":"2021-07-15T03:00:25.401Z","symbol":"XRPUSDT"}}
1626318025.484885: {"jsonrpc":"2.0","method":"updateOrderbook","params":{"ask":[{"price":"0.00000094570","size":"2769150"}],"bid":[{"price":"0.00000034004","size":"230000"},{"price":"0.00000033944","size":"4600"}],"sequence":10532296,"timestamp":"2021-07-15T03:00:25.355Z","symbol":"SCBTC"}}
1626318025.4849112: {"jsonrpc":"2.0","method":"updateOrderbook","params":{"ask":[{"price":"0.00054539","size":"0"},{"price":"0.00054554","size":"4.33"},{"price":"0.00054566","size":"0"},{"price":"0.00054578","size":"10.47"},{"price":"0.00054588","size":"199.63"},{"price":"0.00054598","size":"296.51"},{"price":"0.00054612","size":"0"},{"price":"0.00054622","size":"0"},{"price":"0.00054637","size":"201.47"},{"price":"0.00054654","size":"0"},{"price":"0.00054725","size":"291.41"},{"price":"0.00054768","size":"0"}],"bid":[{"price":"0.00054503","size":"0"},{"price":"0.00054502","size":"5.18"},{"price":"0.00054486","size":"0"},{"price":"0.00054476","size":"18.34"},{"price":"0.00054395","size":"0"},{"price":"0.00054368","size":"380.79"}],"sequence":19513102,"timestamp":"2021-07-15T03:00:25.419Z","symbol":"UNIBTC"}}
1626318025.5460968: {"jsonrpc":"2.0","method":"updateOrderbook","params":{"ask":[],"bid":[{"price":"12.091","size":"5.8796"},{"price":"12.090","size":"0"},{"price":"12.060","size":"6.1121"}],"sequence":2190697,"timestamp":"2021-07-15T03:00:25.470Z","symbol":"SPIUSD"}}
1626318025.566559: {"jsonrpc":"2.0","method":"updateOrderbook","params":{"ask":[{"price":"0.616848","size":"5500.0"},{"price":"0.616910","size":"0"},{"price":"0.627206","size":"0"},{"price":"0.629667","size":"129038.8"},{"price":"0.651907","size":"0"},{"price":"0.654145","size":"181214.3"},{"price":"0.662655","size":"399085.5"},{"price":"0.701643","size":"0"},{"price":"0.701808","size":"228479.7"}],"bid":[{"price":"0.615669","size":"0"},{"price":"0.615664","size":"1591.6"}],"sequence":20584107,"timestamp":"2021-07-15T03:00:25.537Z","symbol":"XRPUSDT"}}
1626318025.573165: {"jsonrpc":"2.0","method":"updateOrderbook","params":{"ask":[{"price":"0.00000065973","size":"15231190"},{"price":"0.00000078071","size":"2003810"},{"price":"0.00000078433","size":"0"},{"price":"0.00000094570","size":"2769160"},{"price":"0.00000124479","size":"2705250"},{"price":"0.00000124704","size":"0"}],"bid":[],"sequence":10532297,"timestamp":"2021-07-15T03:00:25.469Z","symbol":"SCBTC"}}
1626318025.573233: {"jsonrpc":"2.0","method":"updateOrderbook","params":{"ask":[{"price":"0.00054542","size":"4.33"},{"price":"0.00054554","size":"0"},{"price":"0.00054567","size":"0"},{"price":"0.00054581","size":"0"},{"price":"0.00054585","size":"16.70"},{"price":"0.00054588","size":"0"},{"price":"0.00054598","size":"0"},{"price":"0.00054602","size":"66.20"},{"price":"0.00054638","size":"199.63"},{"price":"0.00054661","size":"296.51"},{"price":"0.00054727","size":"0"},{"price":"0.00054778","size":"963.50"}],"bid":[{"price":"0.00054509","size":"5.18"},{"price":"0.00054502","size":"0"}],"sequence":19513103,"timestamp":"2021-07-15T03:00:25.530Z","symbol":"UNIBTC"}}
1626318025.649518: {"jsonrpc":"2.0","method":"updateOrderbook","params":{"ask":[],"bid":[{"price":"12.092","size":"6.1773"},{"price":"12.060","size":"0"}],"sequence":2190698,"timestamp":"2021-07-15T03:00:25.573Z","symbol":"SPIUSD"}}
1626318025.671492: {"jsonrpc":"2.0","method":"updateOrderbook","params":{"ask":[{"price":"0.662655","size":"399085.6"}],"bid":[{"price":"0.615678","size":"1591.6"},{"price":"0.615664","size":"0"}],"sequence":20584108,"timestamp":"2021-07-15T03:00:25.561Z","symbol":"XRPUSDT"}}
1626318025.671552: {"jsonrpc":"2.0","method":"updateOrderbook","params":{"ask":[{"price":"0.00000065973","size":"15231200"},{"price":"0.00000094570","size":"2769180"}],"bid":[{"price":"0.00000036265","size":"1248220"},{"price":"0.00000036202","size":"0"}],"sequence":10532298,"timestamp":"2021-07-15T03:00:25.578Z","symbol":"SCBTC"}}
1626318025.6715782: {"jsonrpc":"2.0","method":"updateOrderbook","params":{"ask":[{"price":"0.00054536","size":"4.33"},{"price":"0.00054542","size":"0"},{"price":"0.00054562","size":"10.47"},{"price":"0.00054578","size":"0"},{"price":"0.00054597","size":"16.96"},{"price":"0.00054616","size":"17.10"}],"bid":[{"price":"0.00054509","size":"0"},{"price":"0.00054499","size":"5.18"},{"price":"0.00054492","size":"0"},{"price":"0.00054481","size":"0"},{"price":"0.00054473","size":"9.62"},{"price":"0.00054462","size":"18.61"},{"price":"0.00054327","size":"0"},{"price":"0.00054281","size":"0"},{"price":"0.00054279","size":"813.21"},{"price":"0.00054234","size":"763.54"}],"sequence":19513104,"timestamp":"2021-07-15T03:00:25.641Z","symbol":"UNIBTC"}}
1626318025.750261: {"jsonrpc":"2.0","method":"updateOrderbook","params":{"ask":[{"price":"0.662655","size":"399085.9"}],"bid":[],"sequence":20584109,"timestamp":"2021-07-15T03:00:25.665Z","symbol":"XRPUSDT"}}
1626318025.771737: {"jsonrpc":"2.0","method":"updateOrderbook","params":{"ask":[{"price":"0.00000065973","size":"15231220"},{"price":"0.00000094570","size":"2769190"}],"bid":[],"sequence":10532299,"timestamp":"2021-07-15T03:00:25.683Z","symbol":"SCBTC"}}
1626318025.771754: {"jsonrpc":"2.0","method":"updateOrderbook","params":{"ask":[{"price":"0.00054536","size":"0"},{"price":"0.00054545","size":"4.33"},{"price":"0.00054736","size":"375.71"},{"price":"0.00054780","size":"0"}],"bid":[{"price":"0.00054503","size":"5.18"},{"price":"0.00054499","size":"0"},{"price":"0.00054231","size":"0"},{"price":"0.00054166","size":"1587.01"}],"sequence":19513105,"timestamp":"2021-07-15T03:00:25.715Z","symbol":"UNIBTC"}}
1626318025.869924: {"jsonrpc":"2.0","method":"updateOrderbook","params":{"ask":[{"price":"0.662655","size":"399086.3"}],"bid":[],"sequence":20584110,"timestamp":"2021-07-15T03:00:25.805Z","symbol":"XRPUSDT"}}
1626318025.8699331: {"jsonrpc":"2.0","method":"updateOrderbook","params":{"ask":[{"price":"0.00000065973","size":"15231230"},{"price":"0.00000094570","size":"2769210"}],"bid":[],"sequence":10532300,"timestamp":"2021-07-15T03:00:25.787Z","symbol":"SCBTC"}}
1626318025.86994: {"jsonrpc":"2.0","method":"updateOrderbook","params":{"ask":[{"price":"0.00054542","size":"4.33"},{"price":"0.00054545","size":"0"},{"price":"0.00054562","size":"0"},{"price":"0.00054570","size":"10.47"},{"price":"0.00054574","size":"16.70"},{"price":"0.00054585","size":"66.20"},{"price":"0.00054602","size":"0"}],"bid":[{"price":"0.00054511","size":"5.18"},{"price":"0.00054503","size":"0"},{"price":"0.00054490","size":"9.62"},{"price":"0.00054473","size":"0"}],"sequence":19513106,"timestamp":"2021-07-15T03:00:25.835Z","symbol":"UNIBTC"}}
1626318025.9475908: {"jsonrpc":"2.0","method":"updateOrderbook","params":{"ask":[],"bid":[{"price":"12.091","size":"0"}],"sequence":2190699,"timestamp":"2021-07-15T03:00:25.927Z","symbol":"SPIUSD"}}
1626318025.95507: {"jsonrpc":"2.0","method":"updateOrderbook","params":{"ask":[{"price":"0.616297","size":"0"},{"price":"0.616410","size":"160.9"},{"price":"0.622891","size":"272131.6"},{"price":"0.624269","size":"0"},{"price":"0.662655","size":"399086.7"}],"bid":[{"price":"0.615097","size":"0"},{"price":"0.615081","size":"15950.8"}],"sequence":20584111,"timestamp":"2021-07-15T03:00:25.938Z","symbol":"XRPUSDT"}}
1626318025.974383: {"jsonrpc":"2.0","method":"updateOrderbook","params":{"ask":[{"price":"0.00000065973","size":"15231250"},{"price":"0.00000094570","size":"2769220"},{"price":"0.00000124479","size":"0"},{"price":"0.00000124541","size":"2705250"},{"price":"0.00000284543","size":"4472830"},{"price":"0.00000286067","size":"0"}],"bid":[],"sequence":10532301,"timestamp":"2021-07-15T03:00:25.904Z","symbol":"SCBTC"}}
1626318025.974397: {"jsonrpc":"2.0","method":"updateOrderbook","params":{"ask":[{"price":"0.00054542","size":"0"},{"price":"0.00054556","size":"4.33"},{"price":"0.00054570","size":"0"},{"price":"0.00054581","size":"10.47"},{"price":"0.00054742","size":"0"},{"price":"0.00054772","size":"0"},{"price":"0.00054794","size":"528.37"},{"price":"0.00054830","size":"331.40"},{"price":"0.00054851","size":"0"},{"price":"0.00054867","size":"587.36"},{"price":"0.00054903","size":"433.80"},{"price":"0.00055048","size":"0"},{"price":"0.00055061","size":"658.12"},{"price":"0.00055205","size":"662.81"},{"price":"0.00055340","size":"0"},{"price":"0.00055404","size":"1811.87"},{"price":"0.00056714","size":"0"},{"price":"0.00057165","size":"2539.46"}],"bid":[{"price":"0.00054516","size":"5.18"},{"price":"0.00054511","size":"0"},{"price":"0.00054401","size":"1.17"},{"price":"0.00054396","size":"0"}],"sequence":19513107,"timestamp":"2021-07-15T03:00:25.935Z","symbol":"UNIBTC"}}
1626318026.044889: {"jsonrpc":"2.0","method":"updateOrderbook","params":{"ask":[],"bid":[{"price":"12.093","size":"5.8786"},{"price":"12.092","size":"0"},{"price":"12.060","size":"6.2425"}],"sequence":2190700,"timestamp":"2021-07-15T03:00:26.001Z","symbol":"SPIUSD"}}
1626318026.054008: {"jsonrpc":"2.0","method":"updateOrderbook","params":{"ask":[{"price":"0.615885","size":"10632.9"},{"price":"0.662655","size":"399087.0"}],"bid":[{"price":"0.615678","size":"0"},{"price":"0.615673","size":"1591.6"},{"price":"0.615255","size":"1337.0"},{"price":"0.615254","size":"0"},{"price":"0.610018","size":"491.7"},{"price":"0.609928","size":"0"},{"price":"0.609918","size":"0"},{"price":"0.608987","size":"245838.0"}],"sequence":20584112,"timestamp":"2021-07-15T03:00:26.039Z","symbol":"XRPUSDT"}}
1626318026.0750358: {"jsonrpc":"2.0","method":"updateOrderbook","params":{"ask":[{"price":"0.00000065973","size":"15231270"},{"price":"0.00000094570","size":"2769240"}],"bid":[{"price":"0.00000032529","size":"1993120"},{"price":"0.00000023134","size":"0"},{"price":"0.00000004684","size":"2752080"},{"price":"0.00000000546","size":"0"}],"sequence":10532302,"timestamp":"2021-07-15T03:00:26.015Z","symbol":"SCBTC"}}
1626318026.0751: {"jsonrpc":"2.0","method":"updateOrderbook","params":{"ask":[{"price":"0.00054549","size":"4.33"},{"price":"0.00054556","size":"0"},{"price":"0.00054574","size":"0"},{"price":"0.00054585","size":"0"},{"price":"0.00054609","size":"66.76"},{"price":"0.00054625","size":"16.70"},{"price":"0.00054639","size":"84.29"},{"price":"0.00054640","size":"0"},{"price":"0.00054779","size":"86.00"},{"price":"0.00054825","size":"84.00"}],"bid":[{"price":"0.00054525","size":"5.18"},{"price":"0.00054516","size":"0"},{"price":"0.00054500","size":"9.62"},{"price":"0.00054490","size":"0"}],"sequence":19513108,"timestamp":"2021-07-15T03:00:26.028Z","symbol":"UNIBTC"}}
1626318026.1574929: {"jsonrpc":"2.0","method":"updateOrderbook","params":{"ask":[],"bid":[{"price":"12.094","size":"6.3077"},{"price":"12.060","size":"0"}],"sequence":2190701,"timestamp":"2021-07-15T03:00:26.070Z","symbol":"SPIUSD"}}
1626318026.160225: {"jsonrpc":"2.0","method":"updateOrderbook","params":{"ask":[{"price":"0.615885","size":"0"},{"price":"0.616137","size":"10632.2"},{"price":"0.616301","size":"0"},{"price":"0.616322","size":"0"},{"price":"0.616480","size":"10632.3"},{"price":"0.616481","size":"8515.0"},{"price":"0.629667","size":"0"},{"price":"0.632729","size":"129038.8"},{"price":"0.654145","size":"0"},{"price":"0.656715","size":"181214.3"},{"price":"0.662655","size":"399087.3"},{"price":"0.701808","size":"0"}],"bid":[{"price":"0.615685","size":"1591.6"},{"price":"0.615673","size":"0"},{"price":"0.615339","size":"0"},{"price":"0.615255","size":"0"},{"price":"0.615254","size":"1337.0"}],"sequence":20584113,"timestamp":"2021-07-15T03:00:26.137Z","symbol":"XRPUSDT"}}
1626318026.168173: {"jsonrpc":"2.0","method":"updateOrderbook","params":{"ask":[{"price":"0.00000036816","size":"26770"},{"price":"0.00000036828","size":"0"},{"price":"0.00000065973","size":"15231290"},{"price":"0.00000094570","size":"2769260"}],"bid":[],"sequence":10532303,"timestamp":"2021-07-15T03:00:26.131Z","symbol":"SCBTC"}}
1626318026.1683671: {"jsonrpc":"2.0","method":"updateOrderbook","params":{"ask":[{"price":"0.00054549","size":"0"},{"price":"0.00054551","size":"4.33"},{"price":"0.00054609","size":"0"},{"price":"0.00054637","size":"0"},{"price":"0.00054639","size":"151.05"},{"price":"0.00054654","size":"201.47"},{"price":"0.00054719","size":"0"},{"price":"0.00054747","size":"250.69"},{"price":"0.00054830","size":"0"},{"price":"0.00054903","size":"0"},{"price":"0.00055028","size":"331.40"},{"price":"0.00055205","size":"0"},{"price":"0.00055263","size":"433.80"},{"price":"0.00055449","size":"662.81"},{"price":"0.00057237","size":"0"},{"price":"0.00060692","size":"881.76"},{"price":"0.00074841","size":"0"},{"price":"0.00079071","size":"1125.76"},{"price":"0.00084011","size":"0"}],"bid":[{"price":"0.00054526","size":"5.18"},{"price":"0.00054525","size":"0"},{"price":"0.00054491","size":"18.03"},{"price":"0.00054472","size":"0"}],"sequence":19513109,"timestamp":"2021-07-15T03:00:26.137Z","symbol":"UNIBTC"}}
1626318026.2522838: {"jsonrpc":"2.0","method":"updateOrderbook","params":{"ask":[{"price":"0.662655","size":"399087.4"}],"bid":[{"price":"0.615562","size":"2839.8"}],"sequence":20584114,"timestamp":"2021-07-15T03:00:26.192Z","symbol":"XRPUSDT"}}
1626318026.2622879: {"jsonrpc":"2.0","method":"updateOrderbook","params":{"ask":[{"price":"0.00000065973","size":"15231300"}],"bid":[],"sequence":10532304,"timestamp":"2021-07-15T03:00:26.239Z","symbol":"SCBTC"}}
1626318026.262312: {"jsonrpc":"2.0","method":"updateOrderbook","params":{"ask":[{"price":"0.00054551","size":"0"},{"price":"0.00054562","size":"4.33"},{"price":"0.00054597","size":"0"},{"price":"0.00054639","size":"84.29"},{"price":"0.00054650","size":"16.96"},{"price":"0.00054679","size":"66.76"},{"price":"0.00054693","size":"0"},{"price":"0.00054712","size":"193.61"}],"bid":[{"price":"0.00054526","size":"0"},{"price":"0.00054523","size":"5.18"},{"price":"0.00054491","size":"0"},{"price":"0.00054476","size":"36.37"}],"sequence":19513110,"timestamp":"2021-07-15T03:00:26.218Z","symbol":"UNIBTC"}}
