1618677528.065807: {"jsonrpc":"2.0","method":"updateOrderbook","params":{"ask":[{"price":"6.01602","size":"1.00"},{"price":"6.01668","size":"0"}],"bid":[{"price":"3.41177","size":"0"},{"price":"3.41139","size":"1.00"}],"sequence":7132788,"timestamp":"2021-04-17T16:38:47.939Z","symbol":"DODOUSD"}}
1618677528.065949: {"jsonrpc":"2.0","method":"updateOrderbook","params":{"ask":[{"price":"0.00007622","size":"0"},{"price":"0.00007625","size":"1735.87"}],"bid":[],"sequence":5856055,"timestamp":"2021-04-17T16:38:47.938Z","symbol":"DODOBTC"}}
1618677528.08267: {"jsonrpc":"2.0","method":"updateOrderbook","params":{"ask":[{"price":"0.001361374","size":"48908"},{"price":"0.001362058","size":"0"},{"price":"0.001371622","size":"0"},{"price":"0.001372031","size":"52376"},{"price":"0.001376982","size":"0"},{"price":"0.001377662","size":"54864"},{"price":"0.001381781","size":"0"},{"price":"0.001382438","size":"49557"},{"price":"0.001386334","size":"0"},{"price":"0.001387002","size":"49184"}],"bid":[{"price":"0.001255675","size":"39175"},{"price":"0.001255269","size":"0"},{"price":"0.001225601","size":"37554"},{"price":"0.001225324","size":"0"}],"sequence":5053533,"timestamp":"2021-04-17T16:38:48.011Z","symbol":"ADABCH"}}
1618677528.1577501: {"jsonrpc":"2.0","method":"updateOrderbook","params":{"ask":[{"price":"0.00015798","size":"290.61"},{"price":"0.00015808","size":"0"},{"price":"0.00015812","size":"370.08"},{"price":"0.00015814","size":"0"},{"price":"0.00015818","size":"500.06"},{"price":"0.00015824","size":"0"},{"price":"0.00016750","size":"0"},{"price":"0.00016755","size":"4264.85"}],"bid":[{"price":"0.00015766","size":"0"},{"price":"0.00015765","size":"67.05"},{"price":"0.00015763","size":"0"},{"price":"0.00015758","size":"446.65"},{"price":"0.00015757","size":"189.73"},{"price":"0.00015752","size":"603.34"},{"price":"0.00015738","size":"587.38"},{"price":"0.00015731","size":"670.43"},{"price":"0.00015727","size":"0"},{"price":"0.00015725","size":"1394.00"},{"price":"0.00015717","size":"110.32"},{"price":"0.00015708","size":"0"},{"price":"0.00015692","size":"1821.71"},{"price":"0.00015650","size":"0"},{"price":"0.00015642","size":"2504.10"}],"sequence":18307794,"timestamp":"2021-04-17T16:38:48.125Z","symbol":"OMGBTC"}}
1618677528.158257: {"jsonrpc":"2.0","method":"updateOrderbook","params":{"ask":[{"price":"4.71907","size":"15561.71"},{"price":"4.72171","size":"0"},{"price":"4.78717","size":"21772.25"},{"price":"4.79004","size":"0"},{"price":"6.01602","size":"0"},{"price":"6.01668","size":"1.00"}],"bid":[{"price":"4.54103","size":"0"},{"price":"4.53835","size":"902.75"},{"price":"4.53311","size":"0"},{"price":"4.53084","size":"1196.81"},{"price":"4.52654","size":"0"},{"price":"4.52512","size":"1626.22"},{"price":"4.52045","size":"0"},{"price":"4.51924","size":"2203.89"},{"price":"4.51328","size":"0"},{"price":"4.51067","size":"2740.00"},{"price":"4.49463","size":"0"},{"price":"4.49269","size":"4091.22"},{"price":"4.48659","size":"0"},{"price":"4.48467","size":"1661.53"},{"price":"3.41177","size":"1.00"},{"price":"3.41139","size":"0"}],"sequence":7132789,"timestamp":"2021-04-17T16:38:48.068Z","symbol":"DODOUSD"}}
1618677528.264946: {"jsonrpc":"2.0","method":"updateOrderbook","params":{"ask":[{"price":"0.00015807","size":"0"},{"price":"0.00015809","size":"42.78"}],"bid":[{"price":"0.00015767","size":"0"},{"price":"0.00015766","size":"9.55"},{"price":"0.00015717","size":"0"},{"price":"0.00015708","size":"110.32"}],"sequence":18307795,"timestamp":"2021-04-17T16:38:48.162Z","symbol":"OMGBTC"}}
1618677528.265176: {"jsonrpc":"2.0","method":"updateOrderbook","params":{"ask":[{"price":"6.01602","size":"1.00"},{"price":"6.01668","size":"0"}],"bid":[{"price":"3.41177","size":"0"},{"price":"3.41139","size":"1.00"}],"sequence":7132790,"timestamp":"2021-04-17T16:38:48.134Z","symbol":"DODOUSD"}}
1618677528.378987: {"jsonrpc":"2.0","method":"updateOrderbook","params":{"ask":[{"price":"0.00015798","size":"0"},{"price":"0.00015808","size":"290.61"},{"price":"0.00015813","size":"245.28"},{"price":"0.00015815","size":"0"},{"price":"0.00015818","size":"0"},{"price":"0.00015824","size":"500.06"},{"price":"0.00015825","size":"162.38"},{"price":"0.00015829","size":"1129.39"},{"price":"0.00015830","size":"234.96"},{"price":"0.00015837","size":"0"},{"price":"0.00015842","size":"1272.79"},{"price":"0.00015865","size":"0"},{"price":"0.00015869","size":"1774.39"},{"price":"0.00015897","size":"2128.07"},{"price":"0.00015901","size":"0"},{"price":"0.00015920","size":"3008.25"},{"price":"0.00015946","size":"0"},{"price":"0.00015969","size":"4402.08"},{"price":"0.00015986","size":"0"},{"price":"0.00016077","size":"5617.94"}],"bid":[{"price":"0.00015765","size":"0"},{"price":"0.00015764","size":"67.05"},{"price":"0.00015738","size":"0"},{"price":"0.00015731","size":"587.38"},{"price":"0.00015726","size":"670.43"}],"sequence":18307796,"timestamp":"2021-04-17T16:38:48.304Z","symbol":"OMGBTC"}}
1618677528.3795562: {"jsonrpc":"2.0","method":"updateOrderbook","params":{"ask":[{"price":"6.01602","size":"0"},{"price":"6.01668","size":"1.00"}],"bid":[{"price":"3.41177","size":"1.00"},{"price":"3.41139","size":"0"}],"sequence":7132791,"timestamp":"2021-04-17T16:38:48.245Z","symbol":"DODOUSD"}}
1618677528.379681: {"jsonrpc":"2.0","method":"updateOrderbook","params":{"ask":[{"price":"0.00007881","size":"7232.62"},{"price":"0.00007891","size":"0"},{"price":"0.00007947","size":"6941.62"},{"price":"0.00007955","size":"0"},{"price":"0.00008003","size":"8110.14"},{"price":"0.00008010","size":"0"},{"price":"0.00008046","size":"7519.42"},{"price":"0.00008052","size":"0"},{"price":"0.00008084","size":"7976.53"},{"price":"0.00008089","size":"0"},{"price":"0.00008114","size":"7673.85"},{"price":"0.00008118","size":"0"},{"price":"0.00008138","size":"7109.71"},{"price":"0.00008142","size":"0"}],"bid":[],"sequence":5856056,"timestamp":"2021-04-17T16:38:48.278Z","symbol":"DODOBTC"}}
1618677528.379821: {"jsonrpc":"2.0","method":"updateOrderbook","params":{"ask":[],"bid":[{"price":"0.001310901","size":"520"},{"price":"0.001310504","size":"0"}],"sequence":5053534,"timestamp":"2021-04-17T16:38:48.319Z","symbol":"ADABCH"}}
1618677528.454526: {"jsonrpc":"2.0","method":"updateOrderbook","params":{"ask":[{"price":"0.00015809","size":"0"},{"price":"0.00015815","size":"42.78"}],"bid":[{"price":"0.00015766","size":"0"},{"price":"0.00015765","size":"9.55"}],"sequence":18307797,"timestamp":"2021-04-17T16:38:48.360Z","symbol":"OMGBTC"}}
1618677528.454839: {"jsonrpc":"2.0","method":"updateOrderbook","params":{"ask":[{"price":"6.01602","size":"1.00"},{"price":"6.01668","size":"0"}],"bid":[{"price":"3.41177","size":"0"},{"price":"3.41139","size":"1.00"}],"sequence":7132792,"timestamp":"2021-04-17T16:38:48.331Z","symbol":"DODOUSD"}}
1618677528.4617758: {"jsonrpc":"2.0","method":"updateOrderbook","params":{"ask":[{"price":"0.00012947","size":"3.00"},{"price":"0.00012948","size":"0"}],"bid":[],"sequence":5856057,"timestamp":"2021-04-17T16:38:48.409Z","symbol":"DODOBTC"}}
1618677528.4674509: {"jsonrpc":"2.0","method":"updateOrderbook","params":{"ask":[],"bid":[{"price":"0.00025436","size":"0"},{"price":"0.00025427","size":"1180.6"},{"price":"0.00025410","size":"2900.0"},{"price":"0.00025377","size":"3000.0"},{"price":"0.00025376","size":"0"},{"price":"0.00025362","size":"7870.9"},{"price":"0.00025336","size":"0.3"},{"price":"0.00025309","size":"0"}],"sequence":9316146,"timestamp":"2021-04-17T16:38:48.398Z","symbol":"XLMETH"}}
1618677528.5604181: {"jsonrpc":"2.0","method":"updateOrderbook","params":{"ask":[{"price":"0.00015944","size":"984.17"}],"bid":[{"price":"0.00015755","size":"58.80"},{"price":"0.00015750","size":"648.50"},{"price":"0.00015731","size":"0"},{"price":"0.00015695","size":"587.38"},{"price":"0.00015680","size":"225.06"},{"price":"0.00015676","size":"523.16"},{"price":"0.00015654","size":"0"},{"price":"0.00015645","size":"768.35"}],"sequence":18307798,"timestamp":"2021-04-17T16:38:48.429Z","symbol":"OMGBTC"}}
1618677528.5607092: {"jsonrpc":"2.0","method":"updateOrderbook","params":{"ask":[{"price":"4.65777","size":"10836.10"},{"price":"4.66059","size":"0"}],"bid":[],"sequence":7132793,"timestamp":"2021-04-17T16:38:48.494Z","symbol":"DODOUSD"}}
1618677528.5694468: {"jsonrpc":"2.0","method":"updateOrderbook","params":{"ask":[{"price":"0.00025479","size":"2900.0"},{"price":"0.00025499","size":"3000.0"},{"price":"0.00025574","size":"10000.0"},{"price":"0.00025586","size":"0"}],"bid":[{"price":"0.00025377","size":"0"},{"price":"0.00025362","size":"0"},{"price":"0.00025355","size":"3000.0"},{"price":"0.00025354","size":"7870.9"}],"sequence":9316147,"timestamp":"2021-04-17T16:38:48.481Z","symbol":"XLMETH"}}
1618677528.653837: {"jsonrpc":"2.0","method":"updateOrderbook","params":{"ask":[{"price":"0.00015807","size":"42.78"},{"price":"0.00015815","size":"0"}],"bid":[],"sequence":18307799,"timestamp":"2021-04-17T16:38:48.578Z","symbol":"OMGBTC"}}
1618677528.654119: {"jsonrpc":"2.0","method":"updateOrderbook","params":{"ask":[{"price":"6.01536","size":"1.00"},{"price":"6.01602","size":"0"}],"bid":[{"price":"3.41139","size":"0"},{"price":"3.41102","size":"1.00"}],"sequence":7132794,"timestamp":"2021-04-17T16:38:48.537Z","symbol":"DODOUSD"}}
1618677528.662004: {"jsonrpc":"2.0","method":"updateOrderbook","params":{"ask":[{"price":"0.00007661","size":"7907.07"},{"price":"0.00007669","size":"0"},{"price":"0.00007736","size":"7289.28"},{"price":"0.00007746","size":"0"},{"price":"0.00007815","size":"7949.10"},{"price":"0.00007826","size":"0"}],"bid":[],"sequence":5856058,"timestamp":"2021-04-17T16:38:48.566Z","symbol":"DODOBTC"}}
1618677528.767039: {"jsonrpc":"2.0","method":"updateOrderbook","params":{"ask":[{"price":"0.00015809","size":"72.33"},{"price":"0.00015810","size":"0"}],"bid":[{"price":"0.00015701","size":"587.38"},{"price":"0.00015695","size":"0"}],"sequence":18307800,"timestamp":"2021-04-17T16:38:48.639Z","symbol":"OMGBTC"}}
1618677528.7672908: {"jsonrpc":"2.0","method":"updateOrderbook","params":{"ask":[{"price":"6.01536","size":"0"},{"price":"6.01602","size":"1.00"}],"bid":[{"price":"3.41139","size":"1.00"},{"price":"3.41102","size":"0"}],"sequence":7132795,"timestamp":"2021-04-17T16:38:48.640Z","symbol":"DODOUSD"}}
1618677528.8508: {"jsonrpc":"2.0","method":"updateOrderbook","params":{"ask":[{"price":"6.01536","size":"1.00"},{"price":"6.01602","size":"0"}],"bid":[{"price":"3.41139","size":"0"},{"price":"3.41102","size":"1.00"}],"sequence":7132796,"timestamp":"2021-04-17T16:38:48.730Z","symbol":"DODOUSD"}}
1618677528.875252: {"jsonrpc":"2.0","method":"updateOrderbook","params":{"ask":[],"bid":[{"price":"0.00025409","size":"0"},{"price":"0.00025401","size":"3935.4"},{"price":"0.00025335","size":"0"},{"price":"0.00025323","size":"10000.0"}],"sequence":9316148,"timestamp":"2021-04-17T16:38:48.795Z","symbol":"XLMETH"}}
1618677528.954001: {"jsonrpc":"2.0","method":"updateOrderbook","params":{"ask":[{"price":"0.00015816","size":"795.80"},{"price":"0.00015819","size":"929.39"},{"price":"0.00015820","size":"0"},{"price":"0.00015821","size":"0"},{"price":"0.00015825","size":"0"},{"price":"0.00015829","size":"200.00"},{"price":"0.00015830","size":"0"},{"price":"0.00015880","size":"149.45"},{"price":"0.00015899","size":"0"},{"price":"0.00015902","size":"633.98"},{"price":"0.00015906","size":"0"},{"price":"0.00015925","size":"625.43"},{"price":"0.00015930","size":"234.96"},{"price":"0.00015935","size":"280.67"},{"price":"0.00015985","size":"0"},{"price":"0.00016020","size":"1828.03"}],"bid":[],"sequence":18307801,"timestamp":"2021-04-17T16:38:48.920Z","symbol":"OMGBTC"}}
1618677528.961051: {"jsonrpc":"2.0","method":"updateOrderbook","params":{"ask":[{"price":"0.00012947","size":"0"},{"price":"0.00012948","size":"3.00"}],"bid":[],"sequence":5856059,"timestamp":"2021-04-17T16:38:48.886Z","symbol":"DODOBTC"}}
1618677528.97587: {"jsonrpc":"2.0","method":"updateOrderbook","params":{"ask":[{"price":"0.00025479","size":"5900.0"},{"price":"0.00025499","size":"0"}],"bid":[{"price":"0.00024318","size":"27210.7"}],"sequence":9316149,"timestamp":"2021-04-17T16:38:48.898Z","symbol":"XLMETH"}}
1618677529.075934: {"jsonrpc":"2.0","method":"updateOrderbook","params":{"ask":[],"bid":[{"price":"4.53295","size":"1196.81"},{"price":"4.53124","size":"1626.22"},{"price":"4.53084","size":"0"},{"price":"4.52512","size":"0"},{"price":"4.52484","size":"2203.89"},{"price":"4.51924","size":"0"},{"price":"4.51765","size":"2740.00"},{"price":"4.51067","size":"0"},{"price":"4.50458","size":"4091.22"},{"price":"4.49269","size":"0"},{"price":"4.48629","size":"1661.53"},{"price":"4.48467","size":"0"}],"sequence":7132797,"timestamp":"2021-04-17T16:38:48.965Z","symbol":"DODOUSD"}}
1618677529.076254: {"jsonrpc":"2.0","method":"updateOrderbook","params":{"ask":[],"bid":[{"price":"0.00007489","size":"0"},{"price":"0.00007486","size":"1739.52"}],"sequence":5856060,"timestamp":"2021-04-17T16:38:48.969Z","symbol":"DODOBTC"}}
1618677529.1574929: {"jsonrpc":"2.0","method":"updateOrderbook","params":{"ask":[{"price":"0.00015934","size":"2.45"},{"price":"0.00015939","size":"0"}],"bid":[{"price":"0.00015632","size":"0"},{"price":"0.00015627","size":"0.01"}],"sequence":18307802,"timestamp":"2021-04-17T16:38:49.123Z","symbol":"OMGBTC"}}
1618677529.157749: {"jsonrpc":"2.0","method":"updateOrderbook","params":{"ask":[{"price":"6.01536","size":"0"},{"price":"6.01602","size":"1.00"}],"bid":[{"price":"3.41139","size":"1.00"},{"price":"3.41102","size":"0"}],"sequence":7132798,"timestamp":"2021-04-17T16:38:49.109Z","symbol":"DODOUSD"}}
1618677529.161649: {"jsonrpc":"2.0","method":"updateOrderbook","params":{"ask":[{"price":"0.00012947","size":"3.00"},{"price":"0.00012948","size":"0"}],"bid":[],"sequence":5856061,"timestamp":"2021-04-17T16:38:49.089Z","symbol":"DODOBTC"}}
1618677529.174477: {"jsonrpc":"2.0","method":"updateOrderbook","params":{"ask":[],"bid":[{"price":"0.00024318","size":"0"}],"sequence":9316150,"timestamp":"2021-04-17T16:38:49.099Z","symbol":"XLMETH"}}
1618677529.263586: {"jsonrpc":"2.0","method":"updateOrderbook","params":{"ask":[{"price":"0.00015826","size":"1272.79"},{"price":"0.00015837","size":"1774.39"},{"price":"0.00015842","size":"0"},{"price":"0.00015869","size":"0"}],"bid":[{"price":"0.00015764","size":"0"},{"price":"0.00015763","size":"67.05"}],"sequence":18307803,"timestamp":"2021-04-17T16:38:49.212Z","symbol":"OMGBTC"}}
1618677529.364574: {"jsonrpc":"2.0","method":"updateOrderbook","params":{"ask":[],"bid":[{"price":"4.53886","size":"902.75"},{"price":"4.53835","size":"0"}],"sequence":7132799,"timestamp":"2021-04-17T16:38:49.266Z","symbol":"DODOUSD"}}
1618677529.3647208: {"jsonrpc":"2.0","method":"updateOrderbook","params":{"ask":[],"bid":[{"price":"0.00015765","size":"0"},{"price":"0.00015764","size":"9.55"},{"price":"0.00015749","size":"0"},{"price":"0.00015734","size":"963.02"},{"price":"0.00015725","size":"0"},{"price":"0.00015711","size":"1394.00"},{"price":"0.00015692","size":"0"},{"price":"0.00015668","size":"1821.71"},{"price":"0.00015631","size":"0"},{"price":"0.00015623","size":"3145.03"},{"price":"0.00015573","size":"0"},{"price":"0.00015539","size":"5478.09"}],"sequence":18307804,"timestamp":"2021-04-17T16:38:49.319Z","symbol":"OMGBTC"}}
1618677529.454746: {"jsonrpc":"2.0","method":"updateOrderbook","params":{"ask":[],"bid":[{"price":"0.00015764","size":"0"},{"price":"0.00015746","size":"9.55"}],"sequence":18307805,"timestamp":"2021-04-17T16:38:49.374Z","symbol":"OMGBTC"}}
1618677529.465271: {"jsonrpc":"2.0","method":"updateOrderbook","params":{"ask":[{"price":"0.00025573","size":"8.4"},{"price":"0.00025585","size":"0"}],"bid":[{"price":"0.00025336","size":"0"},{"price":"0.00025324","size":"0.3"}],"sequence":9316151,"timestamp":"2021-04-17T16:38:49.419Z","symbol":"XLMETH"}}
1618677529.556294: {"jsonrpc":"2.0","method":"updateOrderbook","params":{"ask":[{"price":"0.00015823","size":"0"},{"price":"0.00015827","size":"429.72"},{"price":"0.00015840","size":"63.42"},{"price":"0.00015843","size":"528.19"},{"price":"0.00015860","size":"0"},{"price":"0.00015866","size":"2284.40"},{"price":"0.00015868","size":"551.24"},{"price":"0.00015897","size":"0"},{"price":"0.00015901","size":"3008.25"},{"price":"0.00015902","size":"0"},{"price":"0.00015908","size":"633.98"},{"price":"0.00015920","size":"0"},{"price":"0.00015944","size":"466.51"},{"price":"0.00018166","size":"2362.68"},{"price":"0.00018206","size":"0"}],"bid":[{"price":"0.00015574","size":"0"},{"price":"0.00015560","size":"185.32"}],"sequence":18307806,"timestamp":"2021-04-17T16:38:49.515Z","symbol":"OMGBTC"}}
1618677529.564831: {"jsonrpc":"2.0","method":"updateOrderbook","params":{"ask":[{"price":"6.01602","size":"0"},{"price":"6.01668","size":"1.00"}],"bid":[{"price":"4.54761","size":"570.65"},{"price":"4.54440","size":"0"},{"price":"4.54154","size":"902.75"},{"price":"4.53886","size":"0"},{"price":"4.52616","size":"2203.89"},{"price":"4.52484","size":"0"},{"price":"4.50631","size":"4091.22"},{"price":"4.50458","size":"0"},{"price":"3.41177","size":"1.00"},{"price":"3.41139","size":"0"}],"sequence":7132800,"timestamp":"2021-04-17T16:38:49.470Z","symbol":"DODOUSD"}}
1618677529.658615: {"jsonrpc":"2.0","method":"updateOrderbook","params":{"ask":[{"price":"0.00015929","size":"2.45"},{"price":"0.00015934","size":"0"}],"bid":[],"sequence":18307807,"timestamp":"2021-04-17T16:38:49.598Z","symbol":"OMGBTC"}}
1618677529.6588302: {"jsonrpc":"2.0","method":"updateOrderbook","params":{"ask":[],"bid":[{"price":"4.54761","size":"0"},{"price":"4.54681","size":"570.65"},{"price":"4.54154","size":"0"},{"price":"4.53768","size":"902.75"},{"price":"4.53295","size":"0"},{"price":"4.53124","size":"0"},{"price":"4.53048","size":"1196.81"},{"price":"4.52616","size":"0"},{"price":"4.52491","size":"1626.22"},{"price":"4.51905","size":"2203.89"},{"price":"4.51765","size":"0"},{"price":"4.51023","size":"2740.00"},{"price":"4.50631","size":"0"},{"price":"4.49240","size":"4091.22"},{"price":"4.48629","size":"0"},{"price":"4.48442","size":"1661.53"}],"sequence":7132801,"timestamp":"2021-04-17T16:38:49.564Z","symbol":"DODOUSD"}}
1618677529.668222: {"jsonrpc":"2.0","method":"updateOrderbook","params":{"ask":[],"bid":[{"price":"0.00007457","size":"0"},{"price":"0.00007454","size":"2671.65"}],"sequence":5856062,"timestamp":"2021-04-17T16:38:49.569Z","symbol":"DODOBTC"}}
1618677529.674585: {"jsonrpc":"2.0","method":"updateOrderbook","params":{"ask":[],"bid":[{"price":"0.00025427","size":"0"},{"price":"0.00025417","size":"1180.6"}],"sequence":9316152,"timestamp":"2021-04-17T16:38:49.575Z","symbol":"XLMETH"}}
1618677529.757515: {"jsonrpc":"2.0","method":"updateOrderbook","params":{"ask":[{"price":"6.01602","size":"1.00"},{"price":"6.01668","size":"0"}],"bid":[{"price":"3.41177","size":"0"},{"price":"3.41139","size":"1.00"}],"sequence":7132802,"timestamp":"2021-04-17T16:38:49.643Z","symbol":"DODOUSD"}}
1618677529.771143: {"jsonrpc":"2.0","method":"updateOrderbook","params":{"ask":[{"price":"0.001366858","size":"0"},{"price":"0.001367472","size":"53224"},{"price":"0.001372031","size":"0"},{"price":"0.001372531","size":"52392"},{"price":"0.001377662","size":"0"},{"price":"0.001378142","size":"54881"},{"price":"0.001382438","size":"0"},{"price":"0.001382978","size":"49572"},{"price":"0.001387002","size":"0"},{"price":"0.001387530","size":"49199"}],"bid":[{"price":"0.001310901","size":"0"},{"price":"0.001310446","size":"520"},{"price":"0.001309089","size":"0"},{"price":"0.001308684","size":"1735"}],"sequence":5053535,"timestamp":"2021-04-17T16:38:49.703Z","symbol":"ADABCH"}}
1618677529.771602: {"jsonrpc":"2.0","method":"updateOrderbook","params":{"ask":[{"price":"0.00025479","size":"2900.0"},{"price":"0.00025499","size":"3000.0"}],"bid":[],"sequence":9316153,"timestamp":"2021-04-17T16:38:49.644Z","symbol":"XLMETH"}}
1618677529.858291: {"jsonrpc":"2.0","method":"updateOrderbook","params":{"ask":[{"price":"0.00015949","size":"4910.46"},{"price":"0.00015969","size":"0"},{"price":"0.00015988","size":"6718.35"},{"price":"0.00016077","size":"0"}],"bid":[{"price":"0.00015764","size":"67.05"},{"price":"0.00015763","size":"0"}],"sequence":18307808,"timestamp":"2021-04-17T16:38:49.822Z","symbol":"OMGBTC"}}
1618677529.85862: {"jsonrpc":"2.0","method":"updateOrderbook","params":{"ask":[{"price":"6.01602","size":"0"},{"price":"6.34843","size":"1.00"}],"bid":[{"price":"3.41139","size":"0"},{"price":"3.07898","size":"1.00"}],"sequence":7132803,"timestamp":"2021-04-17T16:38:49.765Z","symbol":"DODOUSD"}}
1618677529.868212: {"jsonrpc":"2.0","method":"updateOrderbook","params":{"ask":[{"price":"0.00012947","size":"0"},{"price":"0.00012948","size":"3.00"}],"bid":[],"sequence":5856063,"timestamp":"2021-04-17T16:38:49.770Z","symbol":"DODOBTC"}}
1618677529.886961: {"jsonrpc":"2.0","method":"updateOrderbook","params":{"ask":[{"price":"0.00025481","size":"3000.0"},{"price":"0.00025482","size":"3935.4"},{"price":"0.00025499","size":"0"},{"price":"0.00025500","size":"0"}],"bid":[],"sequence":9316154,"timestamp":"2021-04-17T16:38:49.756Z","symbol":"XLMETH"}}
1618677529.9589372: {"jsonrpc":"2.0","method":"updateOrderbook","params":{"ask":[],"bid":[{"price":"0.00015753","size":"549.15"},{"price":"0.00015750","size":"200.00"},{"price":"0.00015718","size":"587.38"},{"price":"0.00015701","size":"0"}],"sequence":18307809,"timestamp":"2021-04-17T16:38:49.915Z","symbol":"OMGBTC"}}
1618677529.9708512: {"jsonrpc":"2.0","method":"updateOrderbook","params":{"ask":[{"price":"0.00025481","size":"0"},{"price":"0.00025534","size":"3000.0"}],"bid":[],"sequence":9316155,"timestamp":"2021-04-17T16:38:49.883Z","symbol":"XLMETH"}}
1618677529.971067: {"jsonrpc":"2.0","method":"updateOrderbook","params":{"ask":[],"bid":[{"price":"0.0150775","size":"784.64"},{"price":"0.0150032","size":"0"}],"sequence":6928585,"timestamp":"2021-04-17T16:38:49.843Z","symbol":"ETCETH"}}
1618677530.077916: {"jsonrpc":"2.0","method":"updateOrderbook","params":{"ask":[],"bid":[{"price":"0.00015756","size":"642.53"},{"price":"0.00015752","size":"963.03"},{"price":"0.00015734","size":"0"}],"sequence":18307810,"timestamp":"2021-04-17T16:38:49.971Z","symbol":"OMGBTC"}}
1618677530.078136: {"jsonrpc":"2.0","method":"updateOrderbook","params":{"ask":[{"price":"0.001336082","size":"0"},{"price":"0.001336510","size":"52325"},{"price":"0.001341720","size":"0"},{"price":"0.001342130","size":"56233"},{"price":"0.001348119","size":"0"},{"price":"0.001348616","size":"57535"},{"price":"0.001355350","size":"0"},{"price":"0.001356702","size":"58712"},{"price":"0.001361374","size":"0"},{"price":"0.001362620","size":"48908"},{"price":"0.001367472","size":"0"},{"price":"0.001368154","size":"53172"},{"price":"0.001372531","size":"0"},{"price":"0.001373054","size":"52341"},{"price":"0.001378142","size":"0"},{"price":"0.001378536","size":"54827"},{"price":"0.001387530","size":"0"},{"price":"0.001387948","size":"49151"}],"bid":[{"price":"0.001243446","size":"40326"},{"price":"0.001242799","size":"0"},{"price":"0.001236672","size":"44200"},{"price":"0.001236048","size":"0"},{"price":"0.001230827","size":"40497"},{"price":"0.001230161","size":"0"}],"sequence":5053536,"timestamp":"2021-04-17T16:38:50.016Z","symbol":"ADABCH"}}
1618677530.0853791: {"jsonrpc":"2.0","method":"updateOrderbook","params":{"ask":[],"bid":[{"price":"0.0144094","size":"1198.46"},{"price":"0.0143499","size":"0"},{"price":"0.0138433","size":"2142.40"},{"price":"0.0138141","size":"0"}],"sequence":6928586,"timestamp":"2021-04-17T16:38:49.943Z","symbol":"ETCETH"}}
1618677530.167103: {"jsonrpc":"2.0","method":"updateOrderbook","params":{"ask":[],"bid":[{"price":"0.00002285","size":"3.00"},{"price":"0.00002284","size":"0"}],"sequence":5856064,"timestamp":"2021-04-17T16:38:50.080Z","symbol":"DODOBTC"}}
1618677530.1710699: {"jsonrpc":"2.0","method":"updateOrderbook","params":{"ask":[{"price":"0.001382978","size":"0"},{"price":"0.001383374","size":"49524"}],"bid":[],"sequence":5053537,"timestamp":"2021-04-17T16:38:50.050Z","symbol":"ADABCH"}}
1618677530.175957: {"jsonrpc":"2.0","method":"updateOrderbook","params":{"ask":[],"bid":[{"price":"0.00025402","size":"3000.0"},{"price":"0.00025355","size":"0"}],"sequence":9316156,"timestamp":"2021-04-17T16:38:50.059Z","symbol":"XLMETH"}}
1618677530.261467: {"jsonrpc":"2.0","method":"updateOrderbook","params":{"ask":[{"price":"0.00015926","size":"2.45"},{"price":"0.00015929","size":"0"}],"bid":[{"price":"0.00015627","size":"0"},{"price":"0.00015625","size":"0.01"},{"price":"0.00014906","size":"1268.71"},{"price":"0.00014901","size":"0"}],"sequence":18307811,"timestamp":"2021-04-17T16:38:50.181Z","symbol":"OMGBTC"}}
1618677530.275638: {"jsonrpc":"2.0","method":"updateOrderbook","params":{"ask":[],"bid":[{"price":"0.00025402","size":"0"},{"price":"0.00025355","size":"3000.0"}],"sequence":9316157,"timestamp":"2021-04-17T16:38:50.160Z","symbol":"XLMETH"}}
1618677530.361388: {"jsonrpc":"2.0","method":"updateOrderbook","params":{"ask":[],"bid":[{"price":"0.00015734","size":"1394.00"},{"price":"0.00015711","size":"0"},{"price":"0.00015702","size":"1821.71"},{"price":"0.00015668","size":"0"}],"sequence":18307812,"timestamp":"2021-04-17T16:38:50.290Z","symbol":"OMGBTC"}}
1618677530.3616269: {"jsonrpc":"2.0","method":"updateOrderbook","params":{"ask":[{"price":"6.34843","size":"0"},{"price":"6.34913","size":"1.00"}],"bid":[{"price":"3.07932","size":"1.00"},{"price":"3.07898","size":"0"}],"sequence":7132804,"timestamp":"2021-04-17T16:38:50.259Z","symbol":"DODOUSD"}}
1618677530.4005702: {"jsonrpc":"2.0","method":"updateOrderbook","params":{"ask":[{"price":"0.00025482","size":"0"},{"price":"0.00025492","size":"3935.4"}],"bid":[{"price":"0.00025402","size":"3000.0"},{"price":"0.00025355","size":"0"}],"sequence":9316158,"timestamp":"2021-04-17T16:38:50.274Z","symbol":"XLMETH"}}
1618677530.400823: {"jsonrpc":"2.0","method":"updateOrderbook","params":{"ask":[{"price":"0.0167587","size":"0"},{"price":"0.0167636","size":"784.64"}],"bid":[],"sequence":6928587,"timestamp":"2021-04-17T16:38:50.270Z","symbol":"ETCETH"}}
1618677530.4521952: {"jsonrpc":"2.0","method":"updateOrderbook","params":{"ask":[],"bid":[{"price":"0.00401","size":"2300.00"},{"price":"0.00251","size":"0"}],"sequence":4905794,"timestamp":"2021-04-17T16:38:50.334Z","symbol":"HEDGUSD"}}
1618677530.458674: {"jsonrpc":"2.0","method":"updateOrderbook","params":{"ask":[],"bid":[{"price":"0.00015765","size":"9.55"},{"price":"0.00015746","size":"0"}],"sequence":18307813,"timestamp":"2021-04-17T16:38:50.415Z","symbol":"OMGBTC"}}
1618677530.4589498: {"jsonrpc":"2.0","method":"updateOrderbook","params":{"ask":[{"price":"6.34843","size":"1.00"},{"price":"6.34913","size":"0"}],"bid":[{"price":"3.07932","size":"0"},{"price":"3.07898","size":"1.00"}],"sequence":7132805,"timestamp":"2021-04-17T16:38:50.406Z","symbol":"DODOUSD"}}
1618677530.477089: {"jsonrpc":"2.0","method":"updateOrderbook","params":{"ask":[{"price":"0.001331783","size":"0"},{"price":"0.001332223","size":"56575"}],"bid":[],"sequence":5053538,"timestamp":"2021-04-17T16:38:50.386Z","symbol":"ADABCH"}}
1618677530.484048: {"jsonrpc":"2.0","method":"updateOrderbook","params":{"ask":[{"price":"0.00025491","size":"3000.0"},{"price":"0.00025534","size":"0"}],"bid":[],"sequence":9316159,"timestamp":"2021-04-17T16:38:50.364Z","symbol":"XLMETH"}}
1618677530.57853: {"jsonrpc":"2.0","method":"updateOrderbook","params":{"ask":[{"price":"0.00015837","size":"0"},{"price":"0.00015843","size":"2302.58"},{"price":"0.00015866","size":"156.33"},{"price":"0.00015878","size":"2128.07"},{"price":"0.00015927","size":"0"},{"price":"0.00015944","size":"984.17"}],"bid":[{"price":"0.00015737","size":"587.38"},{"price":"0.00015718","size":"0"},{"price":"0.00015680","size":"748.22"},{"price":"0.00015676","size":"0"},{"price":"0.00015675","size":"162.11"},{"price":"0.00015662","size":"265.47"}],"sequence":18307814,"timestamp":"2021-04-17T16:38:50.521Z","symbol":"OMGBTC"}}
1618677530.578864: {"jsonrpc":"2.0","method":"updateOrderbook","params":{"ask":[{"price":"4.87623","size":"28569.63"},{"price":"4.87989","size":"0"}],"bid":[],"sequence":7132806,"timestamp":"2021-04-17T16:38:50.440Z","symbol":"DODOUSD"}}
1618677530.5917451: {"jsonrpc":"2.0","method":"updateOrderbook","params":{"ask":[],"bid":[{"price":"0.001299124","size":"0"},{"price":"0.001298719","size":"39208"},{"price":"0.001294480","size":"0"},{"price":"0.001294079","size":"40483"}],"sequence":5053539,"timestamp":"2021-04-17T16:38:50.491Z","symbol":"ADABCH"}}
1618677530.591986: {"jsonrpc":"2.0","method":"updateOrderbook","params":{"ask":[{"price":"0.00025573","size":"0"},{"price":"0.00025589","size":"8.4"}],"bid":[],"sequence":9316160,"timestamp":"2021-04-17T16:38:50.460Z","symbol":"XLMETH"}}
1618677530.671239: {"jsonrpc":"2.0","method":"updateOrderbook","params":{"ask":[{"price":"0.00015927","size":"830.99"},{"price":"0.00015944","size":"466.51"}],"bid":[{"price":"0.00015663","size":"768.35"},{"price":"0.00015651","size":"1152.34"},{"price":"0.00015646","size":"1254.62"},{"price":"0.00015645","size":"0"},{"price":"0.00015640","size":"1044.89"},{"price":"0.00015636","size":"428.23"},{"price":"0.00015635","size":"732.55"},{"price":"0.00015631","size":"3145.03"},{"price":"0.00015629","size":"931.13"},{"price":"0.00015626","size":"0"},{"price":"0.00015624","size":"1417.83"},{"price":"0.00015623","size":"0"},{"price":"0.00015620","size":"0"},{"price":"0.00015618","size":"564.59"},{"price":"0.00015617","size":"0"},{"price":"0.00015613","size":"613.58"},{"price":"0.00015611","size":"0"},{"price":"0.00015607","size":"1589.25"},{"price":"0.00015606","size":"0"},{"price":"0.00015602","size":"1149.96"},{"price":"0.00015600","size":"0"},{"price":"0.00015595","size":"0"},{"price":"0.00015589","size":"0"},{"price":"0.00015584","size":"0"}],"sequence":18307815,"timestamp":"2021-04-17T16:38:50.609Z","symbol":"OMGBTC"}}
1618677530.671723: {"jsonrpc":"2.0","method":"updateOrderbook","params":{"ask":[{"price":"6.34843","size":"0"},{"price":"6.34913","size":"1.00"}],"bid":[{"price":"3.07932","size":"1.00"},{"price":"3.07898","size":"0"}],"sequence":7132807,"timestamp":"2021-04-17T16:38:50.572Z","symbol":"DODOUSD"}}
1618677530.7567518: {"jsonrpc":"2.0","method":"updateOrderbook","params":{"ask":[{"price":"0.00015823","size":"429.72"},{"price":"0.00015827","size":"0"},{"price":"0.00015840","size":"591.61"},{"price":"0.00015843","size":"1774.39"},{"price":"0.00015860","size":"551.24"},{"price":"0.00015868","size":"0"},{"price":"0.00015924","size":"2.45"},{"price":"0.00015926","size":"0"}],"bid":[{"price":"0.00015753","size":"100.65"},{"price":"0.00015750","size":"648.50"},{"price":"0.00015737","size":"0"},{"price":"0.00015701","size":"587.38"},{"price":"0.00015680","size":"225.06"},{"price":"0.00015676","size":"523.16"},{"price":"0.00015663","size":"0"},{"price":"0.00015659","size":"768.35"},{"price":"0.00015625","size":"0"},{"price":"0.00015624","size":"1417.84"}],"sequence":18307816,"timestamp":"2021-04-17T16:38:50.682Z","symbol":"OMGBTC"}}
1618677530.7571359: {"jsonrpc":"2.0","method":"updateOrderbook","params":{"ask":[{"price":"6.34843","size":"1.00"},{"price":"6.34913","size":"0"}],"bid":[{"price":"3.07932","size":"0"},{"price":"3.07898","size":"1.00"}],"sequence":7132808,"timestamp":"2021-04-17T16:38:50.651Z","symbol":"DODOUSD"}}
1618677530.7769332: {"jsonrpc":"2.0","method":"updateOrderbook","params":{"ask":[],"bid":[{"price":"0.00025402","size":"0"},{"price":"0.00025355","size":"3000.0"}],"sequence":9316161,"timestamp":"2021-04-17T16:38:50.693Z","symbol":"XLMETH"}}
1618677530.777142: {"jsonrpc":"2.0","method":"updateOrderbook","params":{"ask":[],"bid":[{"price":"0.0162571","size":"0"}],"sequence":6928588,"timestamp":"2021-04-17T16:38:50.691Z","symbol":"ETCETH"}}
1618677530.877656: {"jsonrpc":"2.0","method":"updateOrderbook","params":{"ask":[{"price":"0.00025971","size":"0"},{"price":"0.00025979","size":"58223.1"}],"bid":[],"sequence":9316162,"timestamp":"2021-04-17T16:38:50.732Z","symbol":"XLMETH"}}
1618677530.981929: {"jsonrpc":"2.0","method":"updateOrderbook","params":{"ask":[],"bid":[{"price":"0.0150775","size":"0"},{"price":"0.0149978","size":"784.52"},{"price":"0.0144094","size":"0"},{"price":"0.0143438","size":"1198.28"},{"price":"0.0138433","size":"0"},{"price":"0.0138143","size":"2142.07"}],"sequence":6928589,"timestamp":"2021-04-17T16:38:50.919Z","symbol":"ETCETH"}}
1618677531.0590231: {"jsonrpc":"2.0","method":"updateOrderbook","params":{"ask":[],"bid":[{"price":"0.00015569","size":"5478.09"},{"price":"0.00015539","size":"0"},{"price":"0.00014757","size":"4996.98"},{"price":"0.00014749","size":"0"},{"price":"0.00014694","size":"5680.46"},{"price":"0.00014687","size":"0"}],"sequence":18307817,"timestamp":"2021-04-17T16:38:50.987Z","symbol":"OMGBTC"}}
1618677531.063812: {"jsonrpc":"2.0","method":"updateOrderbook","params":{"ask":[],"bid":[{"price":"4.19769","size":"133.58"},{"price":"4.19247","size":"0"},{"price":"3.22490","size":"175.03"},{"price":"3.20805","size":"0"}],"sequence":7132809,"timestamp":"2021-04-17T16:38:50.990Z","symbol":"DODOUSD"}}
1618677531.068544: {"jsonrpc":"2.0","method":"updateOrderbook","params":{"ask":[],"bid":[{"price":"0.00006374","size":"20862.26"},{"price":"0.00006370","size":"0"}],"sequence":5856065,"timestamp":"2021-04-17T16:38:50.989Z","symbol":"DODOBTC"}}
1618677531.0836558: {"jsonrpc":"2.0","method":"updateOrderbook","params":{"ask":[{"price":"0.001336510","size":"0"},{"price":"0.001337050","size":"52325"},{"price":"0.001342130","size":"0"},{"price":"0.001342755","size":"56233"}],"bid":[],"sequence":5053540,"timestamp":"2021-04-17T16:38:50.951Z","symbol":"ADABCH"}}
1618677531.155267: {"jsonrpc":"2.0","method":"updateOrderbook","params":{"ask":[],"bid":[{"price":"0.00015764","size":"0"},{"price":"0.00015762","size":"227.96"},{"price":"0.00015756","size":"39.20"},{"price":"0.00015752","size":"603.34"},{"price":"0.00015734","size":"0"},{"price":"0.00015729","size":"963.02"},{"price":"0.00015706","size":"1394.00"},{"price":"0.00015702","size":"0"},{"price":"0.00015663","size":"1821.71"},{"price":"0.00015631","size":"0"},{"price":"0.00015621","size":"3145.03"},{"price":"0.00015569","size":"0"},{"price":"0.00015527","size":"5478.09"}],"sequence":18307818,"timestamp":"2021-04-17T16:38:51.117Z","symbol":"OMGBTC"}}
1618677531.191951: {"jsonrpc":"2.0","method":"updateOrderbook","params":{"ask":[{"price":"0.00025461","size":"1180.6"},{"price":"0.00025479","size":"0"},{"price":"0.00025480","size":"0"},{"price":"0.00025491","size":"5900.0"}],"bid":[{"price":"0.00025402","size":"3000.0"},{"price":"0.00025355","size":"0"}],"sequence":9316163,"timestamp":"2021-04-17T16:38:51.121Z","symbol":"XLMETH"}}
1618677531.192287: {"jsonrpc":"2.0","method":"updateOrderbook","params":{"ask":[],"bid":[{"price":"0.0162941","size":"15.69"},{"price":"0.0162889","size":"0"}],"sequence":6928590,"timestamp":"2021-04-17T16:38:51.035Z","symbol":"ETCETH"}}
1618677531.266736: {"jsonrpc":"2.0","method":"updateOrderbook","params":{"ask":[],"bid":[{"price":"0.00015765","size":"0"},{"price":"0.00015746","size":"9.55"},{"price":"0.00015624","size":"1417.83"},{"price":"0.00015619","size":"0.01"},{"price":"0.00014778","size":"5673.63"},{"price":"0.00014772","size":"0"},{"price":"0.00014740","size":"5432.14"},{"price":"0.00014733","size":"0"},{"price":"0.00014671","size":"5096.45"},{"price":"0.00014665","size":"0"}],"sequence":18307819,"timestamp":"2021-04-17T16:38:51.200Z","symbol":"OMGBTC"}}
1618677531.2671108: {"jsonrpc":"2.0","method":"updateOrderbook","params":{"ask":[{"price":"5.56985","size":"48.76"},{"price":"5.57225","size":"0"}],"bid":[],"sequence":7132810,"timestamp":"2021-04-17T16:38:51.201Z","symbol":"DODOUSD"}}
1618677531.270143: {"jsonrpc":"2.0","method":"updateOrderbook","params":{"ask":[{"price":"0.00012948","size":"0"},{"price":"0.00012949","size":"3.00"}],"bid":[],"sequence":5856066,"timestamp":"2021-04-17T16:38:51.155Z","symbol":"DODOBTC"}}
1618677531.2818072: {"jsonrpc":"2.0","method":"updateOrderbook","params":{"ask":[{"price":"0.001332223","size":"0"},{"price":"0.001332620","size":"56575"},{"price":"0.001348616","size":"0"},{"price":"0.001349012","size":"57535"},{"price":"0.001356702","size":"0"},{"price":"0.001357153","size":"58712"}],"bid":[],"sequence":5053541,"timestamp":"2021-04-17T16:38:51.202Z","symbol":"ADABCH"}}
1618677531.354511: {"jsonrpc":"2.0","method":"updateOrderbook","params":{"ask":[{"price":"0.00015821","size":"149.45"},{"price":"0.00015825","size":"162.38"},{"price":"0.00015880","size":"0"},{"price":"0.00015904","size":"633.98"},{"price":"0.00015908","size":"0"},{"price":"0.00015925","size":"463.05"}],"bid":[{"price":"0.00015762","size":"160.91"},{"price":"0.00015761","size":"67.05"}],"sequence":18307820,"timestamp":"2021-04-17T16:38:51.304Z","symbol":"OMGBTC"}}
1618677531.3590488: {"jsonrpc":"2.0","method":"updateOrderbook","params":{"ask":[{"price":"4.65454","size":"10836.10"},{"price":"4.65777","size":"0"}],"bid":[],"sequence":7132811,"timestamp":"2021-04-17T16:38:51.272Z","symbol":"DODOUSD"}}
1618677531.3669162: {"jsonrpc":"2.0","method":"updateOrderbook","params":{"ask":[{"price":"0.001378536","size":"0"},{"price":"0.001379052","size":"54827"},{"price":"0.001383374","size":"0"},{"price":"0.001383894","size":"49524"},{"price":"0.001387948","size":"0"},{"price":"0.001388535","size":"49151"}],"bid":[],"sequence":5053542,"timestamp":"2021-04-17T16:38:51.234Z","symbol":"ADABCH"}}
1618677531.455122: {"jsonrpc":"2.0","method":"updateOrderbook","params":{"ask":[{"price":"0.00016843","size":"0"},{"price":"0.00016848","size":"4534.68"}],"bid":[],"sequence":18307821,"timestamp":"2021-04-17T16:38:51.385Z","symbol":"OMGBTC"}}
1618677531.476544: {"jsonrpc":"2.0","method":"updateOrderbook","params":{"ask":[],"bid":[{"price":"0.0149978","size":"0"},{"price":"0.0149921","size":"784.52"}],"sequence":6928591,"timestamp":"2021-04-17T16:38:51.411Z","symbol":"ETCETH"}}
1618677531.557048: {"jsonrpc":"2.0","method":"updateOrderbook","params":{"ask":[{"price":"0.00015944","size":"984.17"}],"bid":[{"price":"0.00015686","size":"0"},{"price":"0.00015681","size":"477.14"}],"sequence":18307822,"timestamp":"2021-04-17T16:38:51.507Z","symbol":"OMGBTC"}}
1618677531.557274: {"jsonrpc":"2.0","method":"updateOrderbook","params":{"ask":[{"price":"6.34495","size":"1.00"},{"price":"6.34843","size":"0"}],"bid":[{"price":"4.54681","size":"0"},{"price":"4.53768","size":"570.65"},{"price":"4.53295","size":"902.75"},{"price":"4.53048","size":"0"},{"price":"4.52791","size":"1196.81"},{"price":"4.52491","size":"0"},{"price":"4.52254","size":"1626.22"},{"price":"4.51905","size":"0"},{"price":"4.51738","size":"2203.89"},{"price":"4.51023","size":"0"},{"price":"4.50593","size":"2740.00"},{"price":"4.49240","size":"0"},{"price":"4.48933","size":"4091.22"},{"price":"4.48442","size":"0"},{"price":"4.48112","size":"1661.53"},{"price":"3.07898","size":"0"},{"price":"3.07729","size":"1.00"}],"sequence":7132812,"timestamp":"2021-04-17T16:38:51.503Z","symbol":"DODOUSD"}}
1618677531.582922: {"jsonrpc":"2.0","method":"updateOrderbook","params":{"ask":[{"price":"0.00025527","size":"7870.9"},{"price":"0.00025535","size":"0"},{"price":"0.00026033","size":"0"},{"price":"0.00026041","size":"53911.7"}],"bid":[],"sequence":9316164,"timestamp":"2021-04-17T16:38:51.509Z","symbol":"XLMETH"}}
1618677531.664254: {"jsonrpc":"2.0","method":"updateOrderbook","params":{"ask":[{"price":"0.00015921","size":"2.45"},{"price":"0.00015924","size":"0"}],"bid":[{"price":"0.00015686","size":"477.14"},{"price":"0.00015681","size":"0"}],"sequence":18307823,"timestamp":"2021-04-17T16:38:51.606Z","symbol":"OMGBTC"}}
1618677531.6645: {"jsonrpc":"2.0","method":"updateOrderbook","params":{"ask":[],"bid":[{"price":"4.54281","size":"570.65"},{"price":"4.53768","size":"0"},{"price":"4.53450","size":"902.75"},{"price":"4.53295","size":"0"},{"price":"4.52915","size":"1196.81"},{"price":"4.52791","size":"0"},{"price":"4.52360","size":"1626.22"},{"price":"4.52254","size":"0"},{"price":"4.50768","size":"2740.00"},{"price":"4.50593","size":"0"},{"price":"4.49083","size":"4091.22"},{"price":"4.48933","size":"0"},{"price":"4.48279","size":"1661.53"},{"price":"4.48112","size":"0"}],"sequence":7132813,"timestamp":"2021-04-17T16:38:51.539Z","symbol":"DODOUSD"}}
1618677531.677021: {"jsonrpc":"2.0","method":"updateOrderbook","params":{"ask":[],"bid":[{"price":"0.00007516","size":"0"},{"price":"0.00007506","size":"133.67"},{"price":"0.00007486","size":"3.65"},{"price":"0.00007481","size":"1736.57"},{"price":"0.00007454","size":"0"},{"price":"0.00007449","size":"2671.65"}],"sequence":5856067,"timestamp":"2021-04-17T16:38:51.602Z","symbol":"DODOBTC"}}
1618677531.677278: {"jsonrpc":"2.0","method":"updateOrderbook","params":{"ask":[{"price":"0.001362620","size":"0"},{"price":"0.001363090","size":"48908"},{"price":"0.001368154","size":"0"},{"price":"0.001368603","size":"53172"},{"price":"0.001373054","size":"0"},{"price":"0.001373532","size":"52341"}],"bid":[],"sequence":5053543,"timestamp":"2021-04-17T16:38:51.597Z","symbol":"ADABCH"}}
1618677531.7652638: {"jsonrpc":"2.0","method":"updateOrderbook","params":{"ask":[{"price":"0.00015907","size":"608.03"},{"price":"0.00015930","size":"0"}],"bid":[{"price":"0.00015762","size":"227.96"},{"price":"0.00015761","size":"0"},{"price":"0.00015755","size":"662.13"},{"price":"0.00015752","size":"0.01"},{"price":"0.00015751","size":"963.02"},{"price":"0.00015729","size":"0"},{"price":"0.00015686","size":"0"},{"price":"0.00015681","size":"477.14"}],"sequence":18307824,"timestamp":"2021-04-17T16:38:51.713Z","symbol":"OMGBTC"}}
1618677531.765567: {"jsonrpc":"2.0","method":"updateOrderbook","params":{"ask":[{"price":"6.34425","size":"1.00"},{"price":"6.34495","size":"0"}],"bid":[{"price":"4.54281","size":"0"},{"price":"4.54247","size":"570.65"},{"price":"4.52915","size":"0"},{"price":"4.52454","size":"1196.81"},{"price":"4.52360","size":"0"},{"price":"4.51835","size":"1626.22"},{"price":"4.51738","size":"0"},{"price":"4.50768","size":"0"},{"price":"4.50242","size":"2203.89"},{"price":"4.49083","size":"0"},{"price":"4.48809","size":"2740.00"},{"price":"4.48279","size":"0"},{"price":"4.47736","size":"4091.22"},{"price":"4.46349","size":"1661.53"},{"price":"3.07729","size":"0"},{"price":"3.07695","size":"1.00"}],"sequence":7132814,"timestamp":"2021-04-17T16:38:51.704Z","symbol":"DODOUSD"}}
1618677531.765812: {"jsonrpc":"2.0","method":"updateOrderbook","params":{"ask":[],"bid":[{"price":"0.00007486","size":"0"},{"price":"0.00007481","size":"0"},{"price":"0.00007474","size":"1731.94"},{"price":"0.00007449","size":"0"},{"price":"0.00007432","size":"2664.53"},{"price":"0.00006974","size":"0"},{"price":"0.00006968","size":"18465.30"}],"sequence":5856068,"timestamp":"2021-04-17T16:38:51.713Z","symbol":"DODOBTC"}}
1618677531.7768772: {"jsonrpc":"2.0","method":"updateOrderbook","params":{"ask":[{"price":"0.001349012","size":"0"},{"price":"0.001349426","size":"57535"}],"bid":[{"price":"0.001286944","size":"0"},{"price":"0.001286342","size":"37612"},{"price":"0.001277373","size":"0"},{"price":"0.001276963","size":"39117"},{"price":"0.001268567","size":"0"},{"price":"0.001267916","size":"44239"},{"price":"0.001261474","size":"0"},{"price":"0.001261029","size":"37938"},{"price":"0.001255675","size":"0"},{"price":"0.001255031","size":"39175"},{"price":"0.001243446","size":"0"},{"price":"0.001242900","size":"40326"},{"price":"0.001236672","size":"0"},{"price":"0.001236184","size":"44200"},{"price":"0.001230827","size":"0"},{"price":"0.001230384","size":"40497"}],"sequence":5053544,"timestamp":"2021-04-17T16:38:51.693Z","symbol":"ADABCH"}}
1618677531.857476: {"jsonrpc":"2.0","method":"updateOrderbook","params":{"ask":[],"bid":[{"price":"0.00015763","size":"9.55"},{"price":"0.00015746","size":"0"}],"sequence":18307825,"timestamp":"2021-04-17T16:38:51.818Z","symbol":"OMGBTC"}}
1618677531.857762: {"jsonrpc":"2.0","method":"updateOrderbook","params":{"ask":[{"price":"4.65454","size":"0"},{"price":"4.66236","size":"10836.10"}],"bid":[{"price":"4.50932","size":"2203.89"},{"price":"4.50242","size":"0"},{"price":"4.49377","size":"2740.00"},{"price":"4.48809","size":"0"},{"price":"4.48508","size":"4091.22"},{"price":"4.47736","size":"0"},{"price":"4.19769","size":"0"},{"price":"4.19479","size":"133.22"},{"price":"3.22490","size":"0"},{"price":"3.20857","size":"175.39"}],"sequence":7132815,"timestamp":"2021-04-17T16:38:51.782Z","symbol":"DODOUSD"}}
1618677531.864815: {"jsonrpc":"2.0","method":"updateOrderbook","params":{"ask":[{"price":"0.00007661","size":"0"},{"price":"0.00007664","size":"7907.91"}],"bid":[{"price":"0.00007475","size":"3.66"}],"sequence":5856069,"timestamp":"2021-04-17T16:38:51.811Z","symbol":"DODOBTC"}}
1618677531.879093: {"jsonrpc":"2.0","method":"updateOrderbook","params":{"ask":[{"price":"0.00025491","size":"2900.0"},{"price":"0.00025526","size":"3000.0"}],"bid":[],"sequence":9316165,"timestamp":"2021-04-17T16:38:51.745Z","symbol":"XLMETH"}}
1618677531.879296: {"jsonrpc":"2.0","method":"updateOrderbook","params":{"ask":[],"bid":[{"price":"0.0162941","size":"0"},{"price":"0.0162601","size":"15.69"},{"price":"0.0149921","size":"0"},{"price":"0.0149159","size":"784.52"},{"price":"0.0143438","size":"0"},{"price":"0.0142867","size":"1198.28"},{"price":"0.0138143","size":"0"},{"price":"0.0137877","size":"2142.07"},{"price":"0.0135645","size":"0"},{"price":"0.0135477","size":"3131.66"}],"sequence":6928592,"timestamp":"2021-04-17T16:38:51.813Z","symbol":"ETCETH"}}
1618677531.9611058: {"jsonrpc":"2.0","method":"updateOrderbook","params":{"ask":[{"price":"0.00015808","size":"362.94"},{"price":"0.00015809","size":"0"}],"bid":[{"price":"0.00015754","size":"448.50"},{"price":"0.00015750","size":"200.00"},{"price":"0.00015733","size":"670.43"},{"price":"0.00015726","size":"0"},{"price":"0.00015719","size":"587.38"},{"price":"0.00015718","size":"110.32"},{"price":"0.00015714","size":"91.76"},{"price":"0.00015708","size":"0"},{"price":"0.00015704","size":"0"},{"price":"0.00015701","size":"0"},{"price":"0.00015691","size":"478.83"},{"price":"0.00015681","size":"0"}],"sequence":18307826,"timestamp":"2021-04-17T16:38:51.909Z","symbol":"OMGBTC"}}
1618677531.979865: {"jsonrpc":"2.0","method":"updateOrderbook","params":{"ask":[{"price":"0.00025491","size":"5900.0"},{"price":"0.00025526","size":"0"}],"bid":[],"sequence":9316166,"timestamp":"2021-04-17T16:38:51.839Z","symbol":"XLMETH"}}
1618677532.067678: {"jsonrpc":"2.0","method":"updateOrderbook","params":{"ask":[],"bid":[{"price":"0.00015734","size":"1394.00"},{"price":"0.00015706","size":"0"},{"price":"0.00015701","size":"1821.71"},{"price":"0.00015663","size":"0"}],"sequence":18307827,"timestamp":"2021-04-17T16:38:52.015Z","symbol":"OMGBTC"}}
1618677532.0679529: {"jsonrpc":"2.0","method":"updateOrderbook","params":{"ask":[],"bid":[{"price":"4.51921","size":"1626.22"},{"price":"4.51835","size":"0"},{"price":"4.51169","size":"2203.89"},{"price":"4.50932","size":"0"},{"price":"4.49594","size":"2740.00"},{"price":"4.49377","size":"0"}],"sequence":7132816,"timestamp":"2021-04-17T16:38:51.972Z","symbol":"DODOUSD"}}
1618677532.0794308: {"jsonrpc":"2.0","method":"updateOrderbook","params":{"ask":[],"bid":[{"price":"0.0142867","size":"0"},{"price":"0.0142770","size":"1198.28"}],"sequence":6928593,"timestamp":"2021-04-17T16:38:52.008Z","symbol":"ETCETH"}}
1618677532.16691: {"jsonrpc":"2.0","method":"updateOrderbook","params":{"ask":[],"bid":[{"price":"0.0149159","size":"0"},{"price":"0.0149090","size":"784.52"}],"sequence":6928594,"timestamp":"2021-04-17T16:38:52.125Z","symbol":"ETCETH"}}
1618677532.352004: {"jsonrpc":"2.0","method":"updateOrderbook","params":{"ask":[{"price":"0.00015836","size":"1774.39"},{"price":"0.00015843","size":"0"}],"bid":[{"price":"0.00015650","size":"2504.10"},{"price":"0.00015642","size":"0"},{"price":"0.00015631","size":"3145.03"},{"price":"0.00015621","size":"0"}],"sequence":18307828,"timestamp":"2021-04-17T16:38:52.309Z","symbol":"OMGBTC"}}
1618677532.36814: {"jsonrpc":"2.0","method":"updateOrderbook","params":{"ask":[{"price":"0.00025461","size":"0"},{"price":"0.00025469","size":"1180.6"}],"bid":[],"sequence":9316167,"timestamp":"2021-04-17T16:38:52.257Z","symbol":"XLMETH"}}
1618677532.468432: {"jsonrpc":"2.0","method":"updateOrderbook","params":{"ask":[{"price":"0.00016770","size":"0"},{"price":"0.00016775","size":"4211.26"},{"price":"0.00016821","size":"0"},{"price":"0.00016826","size":"4260.55"},{"price":"0.00016832","size":"0"},{"price":"0.00016837","size":"3918.86"}],"bid":[],"sequence":18307829,"timestamp":"2021-04-17T16:38:52.392Z","symbol":"OMGBTC"}}
1618677532.468699: {"jsonrpc":"2.0","method":"updateOrderbook","params":{"ask":[],"bid":[{"price":"4.53450","size":"0"},{"price":"4.53083","size":"902.75"},{"price":"4.52454","size":"0"},{"price":"4.52248","size":"1196.81"},{"price":"4.51921","size":"0"},{"price":"4.51764","size":"1626.22"},{"price":"4.51169","size":"0"},{"price":"4.50936","size":"2203.89"},{"price":"4.49594","size":"0"},{"price":"4.49379","size":"2740.00"}],"sequence":7132817,"timestamp":"2021-04-17T16:38:52.375Z","symbol":"DODOUSD"}}
1618677532.573706: {"jsonrpc":"2.0","method":"updateOrderbook","params":{"ask":[{"price":"0.00015890","size":"861.52"},{"price":"0.00015904","size":"0"},{"price":"0.00016895","size":"0"},{"price":"0.00016900","size":"4174.69"}],"bid":[],"sequence":18307830,"timestamp":"2021-04-17T16:38:52.519Z","symbol":"OMGBTC"}}
1618677532.573953: {"jsonrpc":"2.0","method":"updateOrderbook","params":{"ask":[{"price":"4.60614","size":"0"},{"price":"4.60928","size":"8443.15"},{"price":"4.66236","size":"0"},{"price":"4.66529","size":"10836.10"},{"price":"4.71907","size":"0"},{"price":"4.72318","size":"15561.71"},{"price":"4.78717","size":"0"},{"price":"4.79156","size":"21772.25"},{"price":"4.87623","size":"0"},{"price":"4.88091","size":"28569.63"},{"price":"6.34286","size":"1.00"},{"price":"6.34425","size":"0"}],"bid":[{"price":"4.54247","size":"0"},{"price":"4.53681","size":"570.65"},{"price":"4.53083","size":"0"},{"price":"4.52656","size":"902.75"},{"price":"4.51243","size":"2203.89"},{"price":"4.50936","size":"0"},{"price":"4.50115","size":"2740.00"},{"price":"4.49379","size":"0"},{"price":"4.48795","size":"4091.22"},{"price":"4.48508","size":"0"},{"price":"3.07695","size":"0"},{"price":"3.07628","size":"1.00"}],"sequence":7132818,"timestamp":"2021-04-17T16:38:52.518Z","symbol":"DODOUSD"}}
1618677532.5747762: {"jsonrpc":"2.0","method":"updateOrderbook","params":{"ask":[{"price":"0.00007664","size":"0"},{"price":"0.00007667","size":"7907.91"},{"price":"0.00007736","size":"0"},{"price":"0.00007743","size":"7290.06"},{"price":"0.00007815","size":"0"},{"price":"0.00007822","size":"7949.94"},{"price":"0.00007881","size":"0"},{"price":"0.00007886","size":"7233.39"},{"price":"0.00007947","size":"0"},{"price":"0.00007952","size":"6942.36"},{"price":"0.00008003","size":"0"},{"price":"0.00008007","size":"8111.00"},{"price":"0.00008046","size":"0"},{"price":"0.00008050","size":"7520.22"},{"price":"0.00008084","size":"0"},{"price":"0.00008087","size":"7977.38"},{"price":"0.00008114","size":"0"},{"price":"0.00008117","size":"7674.66"},{"price":"0.00008138","size":"0"},{"price":"0.00008141","size":"7110.46"}],"bid":[{"price":"0.00007525","size":"0.05"}],"sequence":5856070,"timestamp":"2021-04-17T16:38:52.493Z","symbol":"DODOBTC"}}
1618677532.6562612: {"jsonrpc":"2.0","method":"updateOrderbook","params":{"ask":[{"price":"0.00015840","size":"528.19"},{"price":"0.00015845","size":"63.43"}],"bid":[{"price":"0.00015753","size":"0"},{"price":"0.00015750","size":"300.65"},{"price":"0.00015745","size":"0"},{"price":"0.00015738","size":"780.80"},{"price":"0.00015733","size":"0"},{"price":"0.00015721","size":"670.43"},{"price":"0.00015718","size":"0"},{"price":"0.00015714","size":"0"},{"price":"0.00015708","size":"110.32"},{"price":"0.00015704","size":"91.76"},{"price":"0.00015685","size":"0"},{"price":"0.00015680","size":"0"},{"price":"0.00015675","size":"433.72"},{"price":"0.00015662","size":"0"},{"price":"0.00015660","size":"225.06"},{"price":"0.00015657","size":"0"},{"price":"0.00015646","size":"1520.09"},{"price":"0.00015641","size":"859.56"},{"price":"0.00014820","size":"4839.16"},{"price":"0.00014815","size":"0"}],"sequence":18307831,"timestamp":"2021-04-17T16:38:52.625Z","symbol":"OMGBTC"}}
1618677532.657069: {"jsonrpc":"2.0","method":"updateOrderbook","params":{"ask":[],"bid":[{"price":"4.53819","size":"570.65"},{"price":"4.53681","size":"0"},{"price":"4.53072","size":"902.75"},{"price":"4.52656","size":"0"},{"price":"4.51852","size":"1626.22"},{"price":"4.51764","size":"0"},{"price":"4.50312","size":"2740.00"},{"price":"4.50115","size":"0"}],"sequence":7132819,"timestamp":"2021-04-17T16:38:52.573Z","symbol":"DODOUSD"}}
1618677532.73221: {"jsonrpc":"2.0","method":"updateOrderbook","params":{"ask":[{"price":"0.00007618","size":"0"},{"price":"0.00007621","size":"133.22"}],"bid":[{"price":"0.00007525","size":"0"}],"sequence":5856071,"timestamp":"2021-04-17T16:38:52.577Z","symbol":"DODOBTC"}}
1618677532.732502: {"jsonrpc":"2.0","method":"updateOrderbook","params":{"ask":[{"price":"0.0168133","size":"0"}],"bid":[],"sequence":6928595,"timestamp":"2021-04-17T16:38:52.582Z","symbol":"ETCETH"}}
1618677532.760004: {"jsonrpc":"2.0","method":"updateOrderbook","params":{"ask":[{"price":"0.00016785","size":"0"},{"price":"0.00016790","size":"3937.00"},{"price":"0.00016798","size":"0"},{"price":"0.00016803","size":"4090.61"},{"price":"0.00016810","size":"0"},{"price":"0.00016815","size":"4147.65"},{"price":"0.00016868","size":"0"},{"price":"0.00016873","size":"4229.18"}],"bid":[{"price":"0.00015754","size":"0"},{"price":"0.00015750","size":"749.15"},{"price":"0.00015719","size":"0"},{"price":"0.00015707","size":"587.38"},{"price":"0.00015691","size":"1.69"},{"price":"0.00015688","size":"628.44"},{"price":"0.00015570","size":"5478.09"},{"price":"0.00015527","size":"0"}],"sequence":18307832,"timestamp":"2021-04-17T16:38:52.662Z","symbol":"OMGBTC"}}
1618677532.760383: {"jsonrpc":"2.0","method":"updateOrderbook","params":{"ask":[{"price":"4.87723","size":"28569.63"},{"price":"4.88091","size":"0"}],"bid":[],"sequence":7132820,"timestamp":"2021-04-17T16:38:52.691Z","symbol":"DODOUSD"}}
1618677532.772589: {"jsonrpc":"2.0","method":"updateOrderbook","params":{"ask":[{"price":"0.00007628","size":"0"},{"price":"0.00007631","size":"2685.40"}],"bid":[],"sequence":5856072,"timestamp":"2021-04-17T16:38:52.661Z","symbol":"DODOBTC"}}
1618677532.773258: {"jsonrpc":"2.0","method":"updateOrderbook","params":{"ask":[],"bid":[{"price":"0.001311223","size":"520"},{"price":"0.001310446","size":"0"}],"sequence":5053545,"timestamp":"2021-04-17T16:38:52.720Z","symbol":"ADABCH"}}
1618677532.858101: {"jsonrpc":"2.0","method":"updateOrderbook","params":{"ask":[],"bid":[{"price":"4.48175","size":"1661.53"},{"price":"4.46349","size":"0"}],"sequence":7132821,"timestamp":"2021-04-17T16:38:52.766Z","symbol":"DODOUSD"}}
1618677532.8720498: {"jsonrpc":"2.0","method":"updateOrderbook","params":{"ask":[],"bid":[{"price":"0.00025428","size":"1180.6"},{"price":"0.00025417","size":"0"}],"sequence":9316168,"timestamp":"2021-04-17T16:38:52.823Z","symbol":"XLMETH"}}
1618677533.0013142: {"jsonrpc":"2.0","method":"updateOrderbook","params":{"ask":[],"bid":[{"price":"0.001309183","size":"1735"},{"price":"0.001308684","size":"0"}],"sequence":5053546,"timestamp":"2021-04-17T16:38:52.872Z","symbol":"ADABCH"}}
1618677533.069022: {"jsonrpc":"2.0","method":"updateOrderbook","params":{"ask":[{"price":"0.00015808","size":"290.61"},{"price":"0.00015809","size":"72.33"}],"bid":[],"sequence":18307833,"timestamp":"2021-04-17T16:38:52.932Z","symbol":"OMGBTC"}}
1618677533.091409: {"jsonrpc":"2.0","method":"updateOrderbook","params":{"ask":[],"bid":[{"price":"0.00024204","size":"85076.4"},{"price":"0.00024192","size":"0"}],"sequence":9316169,"timestamp":"2021-04-17T16:38:52.954Z","symbol":"XLMETH"}}
1618677533.155385: {"jsonrpc":"2.0","method":"updateOrderbook","params":{"ask":[],"bid":[{"price":"0.00015560","size":"0"}],"sequence":18307834,"timestamp":"2021-04-17T16:38:53.055Z","symbol":"OMGBTC"}}
1618677533.155571: {"jsonrpc":"2.0","method":"updateOrderbook","params":{"ask":[],"bid":[{"price":"4.53072","size":"0"},{"price":"4.52983","size":"902.75"}],"sequence":7132822,"timestamp":"2021-04-17T16:38:53.071Z","symbol":"DODOUSD"}}
1618677533.271831: {"jsonrpc":"2.0","method":"updateOrderbook","params":{"ask":[],"bid":[{"price":"0.00015710","size":"587.38"},{"price":"0.00015707","size":"0"},{"price":"0.00015691","size":"478.83"},{"price":"0.00015688","size":"151.30"},{"price":"0.00015571","size":"185.19"}],"sequence":18307835,"timestamp":"2021-04-17T16:38:53.211Z","symbol":"OMGBTC"}}
1618677533.2720718: {"jsonrpc":"2.0","method":"updateOrderbook","params":{"ask":[],"bid":[{"price":"4.53896","size":"570.65"},{"price":"4.53819","size":"0"},{"price":"4.53130","size":"902.75"},{"price":"4.52983","size":"0"}],"sequence":7132823,"timestamp":"2021-04-17T16:38:53.186Z","symbol":"DODOUSD"}}
1618677533.29032: {"jsonrpc":"2.0","method":"updateOrderbook","params":{"ask":[{"price":"0.00025491","size":"2900.0"},{"price":"0.00025526","size":"3000.0"}],"bid":[{"price":"0.00024350","size":"80208.3"},{"price":"0.00024339","size":"0"},{"price":"0.00023664","size":"81067.3"},{"price":"0.00023656","size":"0"}],"sequence":9316170,"timestamp":"2021-04-17T16:38:53.202Z","symbol":"XLMETH"}}
1618677533.362775: {"jsonrpc":"2.0","method":"updateOrderbook","params":{"ask":[],"bid":[{"price":"0.00015712","size":"587.38"},{"price":"0.00015710","size":"0"},{"price":"0.00015694","size":"477.14"},{"price":"0.00015691","size":"1.69"},{"price":"0.00015686","size":"523.16"},{"price":"0.00015676","size":"0"},{"price":"0.00015663","size":"768.35"},{"price":"0.00015659","size":"0"}],"sequence":18307836,"timestamp":"2021-04-17T16:38:53.253Z","symbol":"OMGBTC"}}
1618677533.3629708: {"jsonrpc":"2.0","method":"updateOrderbook","params":{"ask":[],"bid":[{"price":"4.53465","size":"902.75"},{"price":"4.53130","size":"0"},{"price":"4.52535","size":"1196.81"},{"price":"4.52248","size":"0"},{"price":"4.51978","size":"1626.22"},{"price":"4.51852","size":"0"},{"price":"4.51419","size":"2203.89"},{"price":"4.51243","size":"0"},{"price":"4.50649","size":"2740.00"},{"price":"4.50312","size":"0"},{"price":"4.48989","size":"4091.22"},{"price":"4.48795","size":"0"},{"price":"4.13393","size":"28557.19"},{"price":"4.12947","size":"0"}],"sequence":7132824,"timestamp":"2021-04-17T16:38:53.287Z","symbol":"DODOUSD"}}
1618677533.3631449: {"jsonrpc":"2.0","method":"updateOrderbook","params":{"ask":[],"bid":[{"price":"0.00006891","size":"0"},{"price":"0.00006869","size":"19429.54"},{"price":"0.00006836","size":"0"},{"price":"0.00006802","size":"20437.13"},{"price":"0.00006792","size":"0"},{"price":"0.00006720","size":"20314.25"},{"price":"0.00006717","size":"0"},{"price":"0.00006600","size":"0"},{"price":"0.00006580","size":"20658.51"},{"price":"0.00006485","size":"0"},{"price":"0.00006451","size":"19098.86"},{"price":"0.00006374","size":"0"},{"price":"0.00006344","size":"18768.53"},{"price":"0.00006236","size":"0"},{"price":"0.00006192","size":"20863.23"},{"price":"0.00006089","size":"0"},{"price":"0.00006044","size":"19597.27"},{"price":"0.00005874","size":"20242.26"}],"sequence":5856073,"timestamp":"2021-04-17T16:38:53.309Z","symbol":"DODOBTC"}}
1618677533.4650922: {"jsonrpc":"2.0","method":"updateOrderbook","params":{"ask":[],"bid":[{"price":"0.00015686","size":"0"},{"price":"0.00015678","size":"523.16"}],"sequence":18307837,"timestamp":"2021-04-17T16:38:53.406Z","symbol":"OMGBTC"}}
1618677533.483374: {"jsonrpc":"2.0","method":"updateOrderbook","params":{"ask":[],"bid":[{"price":"0.000000045","size":"50631.6"},{"price":"0.000000044","size":"10.0"}],"sequence":651386,"timestamp":"2021-04-17T16:38:53.419Z","symbol":"HUBBTC"}}
1618677533.557209: {"jsonrpc":"2.0","method":"updateOrderbook","params":{"ask":[{"price":"0.00015863","size":"2128.07"},{"price":"0.00015878","size":"0"}],"bid":[{"price":"0.00014619","size":"4864.97"},{"price":"0.00014613","size":"0"}],"sequence":18307838,"timestamp":"2021-04-17T16:38:53.512Z","symbol":"OMGBTC"}}
1618677533.569899: {"jsonrpc":"2.0","method":"updateOrderbook","params":{"ask":[],"bid":[{"price":"0.00007525","size":"0.05"}],"sequence":5856074,"timestamp":"2021-04-17T16:38:53.480Z","symbol":"DODOBTC"}}
1618677533.5822349: {"jsonrpc":"2.0","method":"updateOrderbook","params":{"ask":[{"price":"0.00025491","size":"5900.0"},{"price":"0.00025526","size":"0"}],"bid":[],"sequence":9316171,"timestamp":"2021-04-17T16:38:53.521Z","symbol":"XLMETH"}}
1618677533.582442: {"jsonrpc":"2.0","method":"updateOrderbook","params":{"ask":[{"price":"0.0169774","size":"0"},{"price":"0.0169940","size":"3131.66"}],"bid":[],"sequence":6928596,"timestamp":"2021-04-17T16:38:53.473Z","symbol":"ETCETH"}}
1618677533.668256: {"jsonrpc":"2.0","method":"updateOrderbook","params":{"ask":[],"bid":[{"price":"0.00015712","size":"0"},{"price":"0.00015708","size":"697.70"},{"price":"0.00015663","size":"0"},{"price":"0.00015659","size":"768.35"}],"sequence":18307839,"timestamp":"2021-04-17T16:38:53.541Z","symbol":"OMGBTC"}}
1618677533.668396: {"jsonrpc":"2.0","method":"updateOrderbook","params":{"ask":[{"price":"4.60441","size":"8443.15"},{"price":"4.60928","size":"0"},{"price":"4.65251","size":"10836.10"},{"price":"4.66529","size":"0"}],"bid":[],"sequence":7132825,"timestamp":"2021-04-17T16:38:53.569Z","symbol":"DODOUSD"}}
1618677533.678411: {"jsonrpc":"2.0","method":"updateOrderbook","params":{"ask":[],"bid":[{"price":"0.00007525","size":"0"}],"sequence":5856075,"timestamp":"2021-04-17T16:38:53.609Z","symbol":"DODOBTC"}}
1618677533.694442: {"jsonrpc":"2.0","method":"updateOrderbook","params":{"ask":[{"price":"0.00026575","size":"0"}],"bid":[],"sequence":9316172,"timestamp":"2021-04-17T16:38:53.604Z","symbol":"XLMETH"}}
1618677533.7646542: {"jsonrpc":"2.0","method":"updateOrderbook","params":{"ask":[],"bid":[{"price":"0.00015753","size":"100.65"},{"price":"0.00015751","size":"0"},{"price":"0.00015750","size":"648.50"},{"price":"0.00015744","size":"780.80"},{"price":"0.00015738","size":"0"},{"price":"0.00015735","size":"963.02"},{"price":"0.00015734","size":"0"},{"price":"0.00015733","size":"670.43"},{"price":"0.00015721","size":"0"},{"price":"0.00015718","size":"110.32"},{"price":"0.00015714","size":"91.76"},{"price":"0.00015712","size":"1394.00"},{"price":"0.00015708","size":"587.38"},{"price":"0.00015704","size":"0"},{"price":"0.00015701","size":"0"},{"price":"0.00015672","size":"1821.71"},{"price":"0.00015650","size":"0"},{"price":"0.00015635","size":"3236.65"},{"price":"0.00015570","size":"0"},{"price":"0.00015544","size":"5478.09"}],"sequence":18307840,"timestamp":"2021-04-17T16:38:53.715Z","symbol":"OMGBTC"}}
1618677533.764929: {"jsonrpc":"2.0","method":"updateOrderbook","params":{"ask":[{"price":"6.34216","size":"1.00"},{"price":"6.34286","size":"0"}],"bid":[{"price":"3.07628","size":"0"},{"price":"3.07594","size":"1.00"}],"sequence":7132826,"timestamp":"2021-04-17T16:38:53.721Z","symbol":"DODOUSD"}}
1618677533.864903: {"jsonrpc":"2.0","method":"updateOrderbook","params":{"ask":[],"bid":[{"price":"0.00015763","size":"0"},{"price":"0.00015753","size":"549.15"},{"price":"0.00015750","size":"200.00"},{"price":"0.00015745","size":"9.55"},{"price":"0.00015723","size":"587.38"},{"price":"0.00015708","size":"0"},{"price":"0.00015697","size":"477.14"},{"price":"0.00015694","size":"0"},{"price":"0.00015681","size":"523.16"},{"price":"0.00015678","size":"0"}],"sequence":18307841,"timestamp":"2021-04-17T16:38:53.813Z","symbol":"OMGBTC"}}
1618677533.8652759: {"jsonrpc":"2.0","method":"updateOrderbook","params":{"ask":[{"price":"6.24634","size":"1.00"},{"price":"6.34216","size":"0"}],"bid":[{"price":"3.17176","size":"1.00"},{"price":"3.07594","size":"0"}],"sequence":7132827,"timestamp":"2021-04-17T16:38:53.769Z","symbol":"DODOUSD"}}
1618677533.8785331: {"jsonrpc":"2.0","method":"updateOrderbook","params":{"ask":[{"price":"0.00026139","size":"0"},{"price":"0.00026148","size":"59967.0"},{"price":"0.00026252","size":"80.0"},{"price":"0.00026260","size":"63872.9"},{"price":"0.00026575","size":"10047.3"}],"bid":[],"sequence":9316173,"timestamp":"2021-04-17T16:38:53.798Z","symbol":"XLMETH"}}
1618677533.969433: {"jsonrpc":"2.0","method":"updateOrderbook","params":{"ask":[],"bid":[{"price":"0.00015763","size":"9.55"},{"price":"0.00015745","size":"0"}],"sequence":18307842,"timestamp":"2021-04-17T16:38:53.867Z","symbol":"OMGBTC"}}
1618677533.977823: {"jsonrpc":"2.0","method":"updateOrderbook","params":{"ask":[],"bid":[{"price":"0.001294542","size":"40483"},{"price":"0.001294079","size":"0"}],"sequence":5053547,"timestamp":"2021-04-17T16:38:53.850Z","symbol":"ADABCH"}}
1618677534.066425: {"jsonrpc":"2.0","method":"updateOrderbook","params":{"ask":[],"bid":[{"price":"0.00015755","size":"1110.63"},{"price":"0.00015753","size":"100.65"},{"price":"0.00015739","size":"587.38"},{"price":"0.00015723","size":"0"},{"price":"0.00015688","size":"674.46"},{"price":"0.00015681","size":"0"},{"price":"0.00015663","size":"768.35"},{"price":"0.00015659","size":"0"},{"price":"0.00015571","size":"0"}],"sequence":18307843,"timestamp":"2021-04-17T16:38:54.011Z","symbol":"OMGBTC"}}
1618677534.066714: {"jsonrpc":"2.0","method":"updateOrderbook","params":{"ask":[{"price":"6.24566","size":"1.00"},{"price":"6.24634","size":"0"}],"bid":[{"price":"4.53896","size":"0"},{"price":"4.53843","size":"570.65"},{"price":"3.17176","size":"0"},{"price":"3.17141","size":"1.00"}],"sequence":7132828,"timestamp":"2021-04-17T16:38:54.012Z","symbol":"DODOUSD"}}
1618677534.1568818: {"jsonrpc":"2.0","method":"updateOrderbook","params":{"ask":[{"price":"0.00016755","size":"0"},{"price":"0.00016760","size":"4264.81"}],"bid":[{"price":"0.00015560","size":"185.32"}],"sequence":18307844,"timestamp":"2021-04-17T16:38:54.074Z","symbol":"OMGBTC"}}
1618677534.1629992: {"jsonrpc":"2.0","method":"updateOrderbook","params":{"ask":[{"price":"4.71633","size":"15561.71"},{"price":"4.72318","size":"0"},{"price":"4.78418","size":"21772.25"},{"price":"4.79156","size":"0"}],"bid":[{"price":"4.53939","size":"570.65"},{"price":"4.53843","size":"0"}],"sequence":7132829,"timestamp":"2021-04-17T16:38:54.101Z","symbol":"DODOUSD"}}
1618677534.180048: {"jsonrpc":"2.0","method":"updateOrderbook","params":{"ask":[{"price":"0.0167657","size":"134.07"}],"bid":[],"sequence":6928597,"timestamp":"2021-04-17T16:38:54.088Z","symbol":"ETCETH"}}
1618677534.272941: {"jsonrpc":"2.0","method":"updateOrderbook","params":{"ask":[{"price":"6.24566","size":"0"},{"price":"6.24634","size":"1.00"}],"bid":[{"price":"4.52924","size":"0"},{"price":"4.48175","size":"0"},{"price":"4.47831","size":"1661.53"},{"price":"3.17176","size":"1.00"},{"price":"3.17141","size":"0"}],"sequence":7132830,"timestamp":"2021-04-17T16:38:54.171Z","symbol":"DODOUSD"}}
1618677534.3631518: {"jsonrpc":"2.0","method":"updateOrderbook","params":{"ask":[{"price":"0.00017717","size":"2362.68"},{"price":"0.00018166","size":"0"}],"bid":[],"sequence":18307845,"timestamp":"2021-04-17T16:38:54.244Z","symbol":"OMGBTC"}}
1618677534.3633652: {"jsonrpc":"2.0","method":"updateOrderbook","params":{"ask":[{"price":"6.24566","size":"1.00"},{"price":"6.24634","size":"0"}],"bid":[{"price":"4.52426","size":"2.63"},{"price":"3.17176","size":"0"},{"price":"3.17141","size":"1.00"}],"sequence":7132831,"timestamp":"2021-04-17T16:38:54.247Z","symbol":"DODOUSD"}}
1618677534.454958: {"jsonrpc":"2.0","method":"updateOrderbook","params":{"ask":[],"bid":[{"price":"0.00015763","size":"76.60"},{"price":"0.00015762","size":"160.91"},{"price":"0.00015752","size":"963.03"},{"price":"0.00015735","size":"0"}],"sequence":18307846,"timestamp":"2021-04-17T16:38:54.354Z","symbol":"OMGBTC"}}
1618677534.4775: {"jsonrpc":"2.0","method":"updateOrderbook","params":{"ask":[{"price":"0.00026373","size":"0"},{"price":"0.00026381","size":"62819.0"}],"bid":[],"sequence":9316174,"timestamp":"2021-04-17T16:38:54.382Z","symbol":"XLMETH"}}
1618677534.558641: {"jsonrpc":"2.0","method":"updateOrderbook","params":{"ask":[{"price":"0.00015863","size":"0"},{"price":"0.00015875","size":"2128.07"}],"bid":[],"sequence":18307847,"timestamp":"2021-04-17T16:38:54.459Z","symbol":"OMGBTC"}}
1618677534.559786: {"jsonrpc":"2.0","method":"updateOrderbook","params":{"ask":[{"price":"6.24566","size":"0"},{"price":"6.24634","size":"1.00"}],"bid":[{"price":"4.54305","size":"570.65"},{"price":"4.53939","size":"0"},{"price":"4.53577","size":"902.75"},{"price":"4.53465","size":"0"},{"price":"4.52892","size":"1196.81"},{"price":"4.52535","size":"0"},{"price":"4.52066","size":"1626.22"},{"price":"4.51978","size":"0"},{"price":"4.50894","size":"2740.00"},{"price":"4.50649","size":"0"},{"price":"3.17176","size":"1.00"},{"price":"3.17141","size":"0"}],"sequence":7132832,"timestamp":"2021-04-17T16:38:54.509Z","symbol":"DODOUSD"}}
1618677534.566129: {"jsonrpc":"2.0","method":"updateOrderbook","params":{"ask":[],"bid":[{"price":"0.00007525","size":"0.05"}],"sequence":5856076,"timestamp":"2021-04-17T16:38:54.486Z","symbol":"DODOBTC"}}
1618677534.576868: {"jsonrpc":"2.0","method":"updateOrderbook","params":{"ask":[{"price":"0.00025491","size":"2900.0"},{"price":"0.00025526","size":"3000.0"}],"bid":[],"sequence":9316175,"timestamp":"2021-04-17T16:38:54.456Z","symbol":"XLMETH"}}
1618677534.6793559: {"jsonrpc":"2.0","method":"updateOrderbook","params":{"ask":[{"price":"4.65251","size":"0"},{"price":"4.65626","size":"10836.10"}],"bid":[{"price":"4.54305","size":"0"},{"price":"4.54223","size":"570.65"},{"price":"4.52892","size":"0"},{"price":"4.52790","size":"1196.81"}],"sequence":7132833,"timestamp":"2021-04-17T16:38:54.574Z","symbol":"DODOUSD"}}
1618677534.679623: {"jsonrpc":"2.0","method":"updateOrderbook","params":{"ask":[],"bid":[{"price":"0.00007525","size":"0"}],"sequence":5856077,"timestamp":"2021-04-17T16:38:54.556Z","symbol":"DODOBTC"}}
1618677534.679774: {"jsonrpc":"2.0","method":"updateOrderbook","params":{"ask":[{"price":"0.00025491","size":"5900.0"},{"price":"0.00025526","size":"0"}],"bid":[],"sequence":9316176,"timestamp":"2021-04-17T16:38:54.593Z","symbol":"XLMETH"}}
1618677534.7628531: {"jsonrpc":"2.0","method":"updateOrderbook","params":{"ask":[],"bid":[{"price":"0.00015739","size":"0"},{"price":"0.00015735","size":"1394.00"},{"price":"0.00015723","size":"587.38"},{"price":"0.00015712","size":"0"},{"price":"0.00015704","size":"1821.71"},{"price":"0.00015688","size":"151.30"},{"price":"0.00015681","size":"523.16"},{"price":"0.00015672","size":"0"}],"sequence":18307848,"timestamp":"2021-04-17T16:38:54.642Z","symbol":"OMGBTC"}}
1618677534.763136: {"jsonrpc":"2.0","method":"updateOrderbook","params":{"ask":[{"price":"4.71633","size":"0"},{"price":"4.71913","size":"15561.71"},{"price":"4.78418","size":"0"},{"price":"4.78723","size":"21772.25"}],"bid":[],"sequence":7132834,"timestamp":"2021-04-17T16:38:54.670Z","symbol":"DODOUSD"}}
1618677534.782613: {"jsonrpc":"2.0","method":"updateOrderbook","params":{"ask":[{"price":"0.001354989","size":"58712"},{"price":"0.001357153","size":"0"},{"price":"0.001361030","size":"48908"},{"price":"0.001363090","size":"0"},{"price":"0.001366700","size":"53172"},{"price":"0.001368603","size":"0"},{"price":"0.001371697","size":"52341"},{"price":"0.001373532","size":"0"},{"price":"0.001377207","size":"54827"},{"price":"0.001379052","size":"0"},{"price":"0.001381989","size":"49524"},{"price":"0.001383894","size":"0"},{"price":"0.001386528","size":"49151"},{"price":"0.001388535","size":"0"}],"bid":[{"price":"0.001277380","size":"39117"},{"price":"0.001276963","size":"0"},{"price":"0.001268384","size":"44239"},{"price":"0.001267916","size":"0"}],"sequence":5053548,"timestamp":"2021-04-17T16:38:54.699Z","symbol":"ADABCH"}}
1618677534.782885: {"jsonrpc":"2.0","method":"updateOrderbook","params":{"ask":[{"price":"0.00025749","size":"0"},{"price":"0.00025757","size":"58571.2"},{"price":"0.00026575","size":"0"}],"bid":[],"sequence":9316177,"timestamp":"2021-04-17T16:38:54.697Z","symbol":"XLMETH"}}
1618677534.8613389: {"jsonrpc":"2.0","method":"updateOrderbook","params":{"ask":[],"bid":[{"price":"0.00015726","size":"110.32"},{"price":"0.00015718","size":"0"},{"price":"0.00015655","size":"325.79"},{"price":"0.00015641","size":"533.77"}],"sequence":18307849,"timestamp":"2021-04-17T16:38:54.789Z","symbol":"OMGBTC"}}
1618677534.861572: {"jsonrpc":"2.0","method":"updateOrderbook","params":{"ask":[],"bid":[{"price":"4.20035","size":"133.22"},{"price":"4.19479","size":"0"},{"price":"3.22548","size":"175.39"},{"price":"3.20857","size":"0"}],"sequence":7132835,"timestamp":"2021-04-17T16:38:54.777Z","symbol":"DODOUSD"}}
1618677534.863151: {"jsonrpc":"2.0","method":"updateOrderbook","params":{"ask":[],"bid":[{"price":"0.00007450","size":"2664.53"},{"price":"0.00007432","size":"0"},{"price":"0.00006972","size":"18465.30"},{"price":"0.00006968","size":"0"}],"sequence":5856078,"timestamp":"2021-04-17T16:38:54.797Z","symbol":"DODOBTC"}}
1618677534.958832: {"jsonrpc":"2.0","method":"updateOrderbook","params":{"ask":[{"price":"4.65626","size":"0"},{"price":"4.65919","size":"10836.10"}],"bid":[],"sequence":7132836,"timestamp":"2021-04-17T16:38:54.866Z","symbol":"DODOUSD"}}
1618677534.9713101: {"jsonrpc":"2.0","method":"updateOrderbook","params":{"ask":[{"price":"0.001336155","size":"52325"},{"price":"0.001337050","size":"0"},{"price":"0.001341467","size":"56233"},{"price":"0.001342755","size":"0"},{"price":"0.001347803","size":"57535"},{"price":"0.001349426","size":"0"}],"bid":[],"sequence":5053549,"timestamp":"2021-04-17T16:38:54.901Z","symbol":"ADABCH"}}
1618677534.9715672: {"jsonrpc":"2.0","method":"updateOrderbook","params":{"ask":[{"price":"0.00026575","size":"10050.2"}],"bid":[{"price":"0.00024099","size":"85748.6"},{"price":"0.00024089","size":"0"}],"sequence":9316178,"timestamp":"2021-04-17T16:38:54.879Z","symbol":"XLMETH"}}
1618677535.0693882: {"jsonrpc":"2.0","method":"updateOrderbook","params":{"ask":[],"bid":[{"price":"0.00015649","size":"2504.10"},{"price":"0.00015635","size":"732.55"}],"sequence":18307850,"timestamp":"2021-04-17T16:38:54.991Z","symbol":"OMGBTC"}}
1618677535.069589: {"jsonrpc":"2.0","method":"updateOrderbook","params":{"ask":[{"price":"6.24634","size":"0"},{"price":"6.24840","size":"1.00"}],"bid":[{"price":"4.54423","size":"570.65"},{"price":"4.54223","size":"0"},{"price":"4.53832","size":"902.75"},{"price":"4.53577","size":"0"},{"price":"4.53341","size":"1196.81"},{"price":"4.52790","size":"0"},{"price":"4.52267","size":"1626.22"},{"price":"4.52066","size":"0"},{"price":"4.51665","size":"2203.89"},{"price":"4.51419","size":"0"},{"price":"4.51066","size":"2740.00"},{"price":"4.50894","size":"0"},{"price":"4.49387","size":"4091.22"},{"price":"4.48989","size":"0"},{"price":"3.17280","size":"1.00"},{"price":"3.17176","size":"0"}],"sequence":7132837,"timestamp":"2021-04-17T16:38:54.978Z","symbol":"DODOUSD"}}
1618677535.0699: {"jsonrpc":"2.0","method":"updateOrderbook","params":{"ask":[{"price":"0.001319841","size":"0"},{"price":"0.001320252","size":"4338"}],"bid":[],"sequence":5053550,"timestamp":"2021-04-17T16:38:54.932Z","symbol":"ADABCH"}}
1618677535.1548622: {"jsonrpc":"2.0","method":"updateOrderbook","params":{"ask":[{"price":"0.00015834","size":"200.00"},{"price":"0.00015837","size":"550.49"},{"price":"0.00015866","size":"0"},{"price":"0.00015876","size":"156.33"}],"bid":[{"price":"0.00015632","size":"724.18"},{"price":"0.00015612","size":"0"},{"price":"0.00014654","size":"4795.86"},{"price":"0.00014648","size":"0"}],"sequence":18307851,"timestamp":"2021-04-17T16:38:55.058Z","symbol":"OMGBTC"}}
1618677535.266858: {"jsonrpc":"2.0","method":"updateOrderbook","params":{"ask":[{"price":"0.00016726","size":"0"},{"price":"0.00016731","size":"4405.72"}],"bid":[],"sequence":18307852,"timestamp":"2021-04-17T16:38:55.219Z","symbol":"OMGBTC"}}
1618677535.267076: {"jsonrpc":"2.0","method":"updateOrderbook","params":{"ask":[{"price":"6.24840","size":"0"},{"price":"6.24909","size":"1.00"}],"bid":[{"price":"3.17315","size":"1.00"},{"price":"3.17280","size":"0"}],"sequence":7132838,"timestamp":"2021-04-17T16:38:55.183Z","symbol":"DODOUSD"}}
1618677535.360576: {"jsonrpc":"2.0","method":"updateOrderbook","params":{"ask":[{"price":"0.00016646","size":"0"},{"price":"0.00016651","size":"1268.79"}],"bid":[{"price":"0.00015685","size":"271.61"},{"price":"0.00015681","size":"0"},{"price":"0.00015680","size":"225.06"},{"price":"0.00015676","size":"523.16"},{"price":"0.00015675","size":"162.11"},{"price":"0.00015670","size":"491.83"},{"price":"0.00015660","size":"0"},{"price":"0.00015646","size":"1254.62"},{"price":"0.00015572","size":"5478.09"},{"price":"0.00015544","size":"0"}],"sequence":18307853,"timestamp":"2021-04-17T16:38:55.324Z","symbol":"OMGBTC"}}
1618677535.360901: {"jsonrpc":"2.0","method":"updateOrderbook","params":{"ask":[{"price":"6.24840","size":"1.00"},{"price":"6.24909","size":"0"}],"bid":[{"price":"3.17315","size":"0"},{"price":"3.17280","size":"1.00"}],"sequence":7132839,"timestamp":"2021-04-17T16:38:55.284Z","symbol":"DODOUSD"}}
1618677535.458427: {"jsonrpc":"2.0","method":"updateOrderbook","params":{"ask":[],"bid":[{"price":"0.00015560","size":"0"}],"sequence":18307854,"timestamp":"2021-04-17T16:38:55.413Z","symbol":"OMGBTC"}}
1618677535.458612: {"jsonrpc":"2.0","method":"updateOrderbook","params":{"ask":[],"bid":[{"price":"4.52353","size":"1626.22"},{"price":"4.52267","size":"0"},{"price":"4.20035","size":"0"},{"price":"4.19414","size":"133.22"},{"price":"3.22548","size":"0"},{"price":"3.20798","size":"175.39"}],"sequence":7132840,"timestamp":"2021-04-17T16:38:55.410Z","symbol":"DODOUSD"}}
1618677535.466617: {"jsonrpc":"2.0","method":"updateOrderbook","params":{"ask":[],"bid":[{"price":"0.00007486","size":"3.65"},{"price":"0.00007475","size":"0"}],"sequence":5856079,"timestamp":"2021-04-17T16:38:55.412Z","symbol":"DODOBTC"}}
1618677535.4949582: {"jsonrpc":"2.0","method":"updateOrderbook","params":{"ask":[{"price":"0.001315836","size":"0"},{"price":"0.001316344","size":"520"}],"bid":[],"sequence":5053551,"timestamp":"2021-04-17T16:38:55.370Z","symbol":"ADABCH"}}
1618677535.4952419: {"jsonrpc":"2.0","method":"updateOrderbook","params":{"ask":[{"price":"0.00025912","size":"0"},{"price":"0.00025920","size":"57658.1"},{"price":"0.00026746","size":"0"},{"price":"0.00026754","size":"56304.9"}],"bid":[],"sequence":9316179,"timestamp":"2021-04-17T16:38:55.366Z","symbol":"XLMETH"}}
1618677535.561238: {"jsonrpc":"2.0","method":"updateOrderbook","params":{"ask":[{"price":"0.00015823","size":"0"},{"price":"0.00015833","size":"429.72"},{"price":"0.00015840","size":"0"},{"price":"0.00015843","size":"528.19"},{"price":"0.00015860","size":"0"},{"price":"0.00015873","size":"551.24"},{"price":"0.00015890","size":"227.54"},{"price":"0.00015903","size":"633.98"},{"price":"0.00015944","size":"466.51"}],"bid":[{"price":"0.00015763","size":"9.55"},{"price":"0.00015762","size":"227.96"},{"price":"0.00015757","size":"638.23"},{"price":"0.00015755","size":"662.13"},{"price":"0.00015752","size":"0.01"},{"price":"0.00015739","size":"587.38"},{"price":"0.00015735","size":"963.02"},{"price":"0.00015723","size":"0"},{"price":"0.00015710","size":"1394.00"},{"price":"0.00015704","size":"0"},{"price":"0.00015682","size":"523.16"},{"price":"0.00015676","size":"0"},{"price":"0.00015667","size":"1821.71"},{"price":"0.00015649","size":"0"},{"price":"0.00015635","size":"3236.65"},{"price":"0.00015631","size":"0"},{"price":"0.00015622","size":"4175.00"},{"price":"0.00015573","size":"185.17"},{"price":"0.00015572","size":"0"},{"price":"0.00015535","size":"5478.09"}],"sequence":18307855,"timestamp":"2021-04-17T16:38:55.519Z","symbol":"OMGBTC"}}
1618677535.5681448: {"jsonrpc":"2.0","method":"updateOrderbook","params":{"ask":[],"bid":[{"price":"0.00007525","size":"0.05"},{"price":"0.00007524","size":"0"}],"sequence":5856080,"timestamp":"2021-04-17T16:38:55.465Z","symbol":"DODOBTC"}}
1618677535.578219: {"jsonrpc":"2.0","method":"updateOrderbook","params":{"ask":[{"price":"0.001317432","size":"0"},{"price":"0.001317828","size":"1735"}],"bid":[],"sequence":5053552,"timestamp":"2021-04-17T16:38:55.477Z","symbol":"ADABCH"}}
1618677535.57843: {"jsonrpc":"2.0","method":"updateOrderbook","params":{"ask":[{"price":"0.00025491","size":"2900.0"},{"price":"0.00025526","size":"3000.0"},{"price":"0.00025839","size":"0"},{"price":"0.00025847","size":"56902.7"},{"price":"0.00026481","size":"0"},{"price":"0.00026489","size":"63543.2"},{"price":"0.00026576","size":"0"},{"price":"0.00026584","size":"60813.9"},{"price":"0.00026668","size":"0"},{"price":"0.00026676","size":"64506.9"}],"bid":[],"sequence":9316180,"timestamp":"2021-04-17T16:38:55.491Z","symbol":"XLMETH"}}
1618677535.578646: {"jsonrpc":"2.0","method":"updateOrderbook","params":{"ask":[{"price":"0.0167658","size":"0"}],"bid":[],"sequence":6928598,"timestamp":"2021-04-17T16:38:55.524Z","symbol":"ETCETH"}}
1618677535.6629171: {"jsonrpc":"2.0","method":"updateOrderbook","params":{"ask":[],"bid":[{"price":"0.00015763","size":"0"},{"price":"0.00015748","size":"9.55"}],"sequence":18307856,"timestamp":"2021-04-17T16:38:55.578Z","symbol":"OMGBTC"}}
1618677535.663197: {"jsonrpc":"2.0","method":"updateOrderbook","params":{"ask":[{"price":"6.24840","size":"0"},{"price":"6.24909","size":"1.00"}],"bid":[{"price":"3.17315","size":"1.00"},{"price":"3.17280","size":"0"}],"sequence":7132841,"timestamp":"2021-04-17T16:38:55.619Z","symbol":"DODOUSD"}}
1618677535.678306: {"jsonrpc":"2.0","method":"updateOrderbook","params":{"ask":[{"price":"0.00025491","size":"5900.0"},{"price":"0.00025526","size":"0"}],"bid":[],"sequence":9316181,"timestamp":"2021-04-17T16:38:55.601Z","symbol":"XLMETH"}}
1618677535.755542: {"jsonrpc":"2.0","method":"updateOrderbook","params":{"ask":[],"bid":[{"price":"0.00014727","size":"5414.61"},{"price":"0.00014721","size":"0"}],"sequence":18307857,"timestamp":"2021-04-17T16:38:55.637Z","symbol":"OMGBTC"}}
1618677535.7557561: {"jsonrpc":"2.0","method":"updateOrderbook","params":{"ask":[{"price":"5.56743","size":"48.76"},{"price":"5.56985","size":"0"},{"price":"6.24772","size":"1.00"},{"price":"6.24909","size":"0"}],"bid":[{"price":"4.54423","size":"0"},{"price":"4.54158","size":"570.65"},{"price":"4.53832","size":"0"},{"price":"4.53651","size":"902.75"},{"price":"4.53341","size":"0"},{"price":"4.53137","size":"1196.81"},{"price":"4.52353","size":"0"},{"price":"4.52120","size":"1626.22"},{"price":"4.51665","size":"0"},{"price":"4.51536","size":"2203.89"},{"price":"4.49387","size":"0"},{"price":"4.49227","size":"4091.22"},{"price":"3.17315","size":"0"},{"price":"3.17246","size":"1.00"}],"sequence":7132842,"timestamp":"2021-04-17T16:38:55.721Z","symbol":"DODOUSD"}}
1618677535.767945: {"jsonrpc":"2.0","method":"updateOrderbook","params":{"ask":[],"bid":[{"price":"0.00007517","size":"133.22"},{"price":"0.00007506","size":"0"},{"price":"0.00007487","size":"1731.94"},{"price":"0.00007474","size":"0"}],"sequence":5856081,"timestamp":"2021-04-17T16:38:55.637Z","symbol":"DODOBTC"}}
1618677535.774293: {"jsonrpc":"2.0","method":"updateOrderbook","params":{"ask":[{"price":"0.001316344","size":"0"},{"price":"0.001316795","size":"520"},{"price":"0.001317828","size":"0"},{"price":"0.001318270","size":"1735"},{"price":"0.001320252","size":"0"},{"price":"0.001320650","size":"4338"},{"price":"0.001327481","size":"0"},{"price":"0.001327933","size":"51644"},{"price":"0.001381989","size":"0"},{"price":"0.001382396","size":"49524"},{"price":"0.001386528","size":"0"},{"price":"0.001386944","size":"49151"}],"bid":[],"sequence":5053553,"timestamp":"2021-04-17T16:38:55.721Z","symbol":"ADABCH"}}
1618677535.856025: {"jsonrpc":"2.0","method":"updateOrderbook","params":{"ask":[{"price":"0.00015863","size":"2128.07"},{"price":"0.00015875","size":"0"}],"bid":[{"price":"0.00015573","size":"0"}],"sequence":18307858,"timestamp":"2021-04-17T16:38:55.782Z","symbol":"OMGBTC"}}
1618677535.856166: {"jsonrpc":"2.0","method":"updateOrderbook","params":{"ask":[],"bid":[{"price":"4.54158","size":"0"},{"price":"4.54050","size":"570.65"},{"price":"4.53137","size":"0"},{"price":"4.53053","size":"1196.81"}],"sequence":7132843,"timestamp":"2021-04-17T16:38:55.822Z","symbol":"DODOUSD"}}
1618677535.8651378: {"jsonrpc":"2.0","method":"updateOrderbook","params":{"ask":[{"price":"0.00007883","size":"7232.53"},{"price":"0.00007886","size":"0"},{"price":"0.00007949","size":"6941.54"},{"price":"0.00007952","size":"0"}],"bid":[],"sequence":5856082,"timestamp":"2021-04-17T16:38:55.789Z","symbol":"DODOBTC"}}
1618677535.8710332: {"jsonrpc":"2.0","method":"updateOrderbook","params":{"ask":[{"price":"0.001336155","size":"0"},{"price":"0.001336848","size":"52325"},{"price":"0.001341467","size":"0"},{"price":"0.001342031","size":"56233"},{"price":"0.001371697","size":"0"},{"price":"0.001372142","size":"52341"},{"price":"0.001377207","size":"0"},{"price":"0.001377614","size":"54827"}],"bid":[],"sequence":5053554,"timestamp":"2021-04-17T16:38:55.825Z","symbol":"ADABCH"}}
1618677535.95359: {"jsonrpc":"2.0","method":"updateOrderbook","params":{"ask":[{"price":"0.00015945","size":"517.66"}],"bid":[{"price":"0.00015763","size":"67.05"},{"price":"0.00015762","size":"160.91"},{"price":"0.00015757","size":"189.73"},{"price":"0.00015755","size":"1110.63"},{"price":"0.00015739","size":"0"},{"price":"0.00015723","size":"587.38"},{"price":"0.00015708","size":"155.75"},{"price":"0.00015699","size":"0"},{"price":"0.00015682","size":"0"},{"price":"0.00015676","size":"523.16"},{"price":"0.00015560","size":"185.32"}],"sequence":18307859,"timestamp":"2021-04-17T16:38:55.917Z","symbol":"OMGBTC"}}
1618677535.9539871: {"jsonrpc":"2.0","method":"updateOrderbook","params":{"ask":[],"bid":[{"price":"4.54158","size":"570.65"},{"price":"4.54050","size":"0"},{"price":"4.53137","size":"1196.81"},{"price":"4.53053","size":"0"},{"price":"4.48004","size":"1661.53"},{"price":"4.47831","size":"0"}],"sequence":7132844,"timestamp":"2021-04-17T16:38:55.911Z","symbol":"DODOUSD"}}
1618677535.959928: {"jsonrpc":"2.0","method":"updateOrderbook","params":{"ask":[],"bid":[{"price":"0.00007517","size":"0"},{"price":"0.00007513","size":"133.56"},{"price":"0.00007487","size":"0"},{"price":"0.00007484","size":"1736.34"}],"sequence":5856083,"timestamp":"2021-04-17T16:38:55.850Z","symbol":"DODOBTC"}}
1618677535.968261: {"jsonrpc":"2.0","method":"updateOrderbook","params":{"ask":[{"price":"0.001327933","size":"0"},{"price":"0.001328355","size":"51644"},{"price":"0.001332620","size":"0"},{"price":"0.001333111","size":"56575"},{"price":"0.001347803","size":"0"},{"price":"0.001348318","size":"57535"},{"price":"0.001354989","size":"0"},{"price":"0.001355594","size":"58712"},{"price":"0.001361030","size":"0"},{"price":"0.001361675","size":"48908"},{"price":"0.001366700","size":"0"},{"price":"0.001367327","size":"53172"},{"price":"0.001382396","size":"0"},{"price":"0.001382800","size":"49524"},{"price":"0.001386944","size":"0"},{"price":"0.001387340","size":"49151"}],"bid":[],"sequence":5053555,"timestamp":"2021-04-17T16:38:55.854Z","symbol":"ADABCH"}}
1618677536.059934: {"jsonrpc":"2.0","method":"updateOrderbook","params":{"ask":[],"bid":[{"price":"0.00015764","size":"9.55"},{"price":"0.00015748","size":"0"}],"sequence":18307860,"timestamp":"2021-04-17T16:38:55.978Z","symbol":"OMGBTC"}}
1618677536.07664: {"jsonrpc":"2.0","method":"updateOrderbook","params":{"ask":[],"bid":[{"price":"0.00024017","size":"84667.4"},{"price":"0.00024008","size":"0"},{"price":"0.00023952","size":"75814.7"},{"price":"0.00023944","size":"0"},{"price":"0.00023896","size":"75673.3"},{"price":"0.00023888","size":"0"},{"price":"0.00023848","size":"71128.4"},{"price":"0.00023840","size":"0"},{"price":"0.00023801","size":"73259.1"},{"price":"0.00023792","size":"0"}],"sequence":9316182,"timestamp":"2021-04-17T16:38:55.967Z","symbol":"XLMETH"}}
1618677536.0768452: {"jsonrpc":"2.0","method":"updateOrderbook","params":{"ask":[],"bid":[{"price":"0.0162602","size":"48.68"}],"sequence":6928599,"timestamp":"2021-04-17T16:38:55.981Z","symbol":"ETCETH"}}
1618677536.2510731: {"jsonrpc":"2.0","method":"updateOrderbook","params":{"ask":[],"bid":[{"price":"0.00015752","size":"963.03"},{"price":"0.00015735","size":"0"}],"sequence":18307861,"timestamp":"2021-04-17T16:38:56.136Z","symbol":"OMGBTC"}}
1618677536.255923: {"jsonrpc":"2.0","method":"updateOrderbook","params":{"ask":[{"price":"6.24772","size":"0"},{"price":"6.24840","size":"1.00"}],"bid":[{"price":"3.17280","size":"1.00"},{"price":"3.17246","size":"0"}],"sequence":7132845,"timestamp":"2021-04-17T16:38:56.158Z","symbol":"DODOUSD"}}
1618677536.367052: {"jsonrpc":"2.0","method":"updateOrderbook","params":{"ask":[{"price":"6.24772","size":"1.00"},{"price":"6.24840","size":"0"}],"bid":[{"price":"3.17280","size":"0"},{"price":"3.17246","size":"1.00"}],"sequence":7132846,"timestamp":"2021-04-17T16:38:56.263Z","symbol":"DODOUSD"}}
1618677536.552004: {"jsonrpc":"2.0","method":"updateOrderbook","params":{"ask":[{"price":"0.00015827","size":"429.72"},{"price":"0.00015833","size":"0"},{"price":"0.00015866","size":"551.24"},{"price":"0.00015873","size":"0"},{"price":"0.00015944","size":"984.17"},{"price":"0.00015945","size":"0"}],"bid":[{"price":"0.00015734","size":"1394.00"},{"price":"0.00015710","size":"0"},{"price":"0.00015699","size":"1821.71"},{"price":"0.00015667","size":"0"}],"sequence":18307862,"timestamp":"2021-04-17T16:38:56.517Z","symbol":"OMGBTC"}}
1618677536.567225: {"jsonrpc":"2.0","method":"updateOrderbook","params":{"ask":[],"bid":[{"price":"0.001226026","size":"37521"},{"price":"0.001225601","size":"0"}],"sequence":5053556,"timestamp":"2021-04-17T16:38:56.463Z","symbol":"ADABCH"}}
1618677536.65393: {"jsonrpc":"2.0","method":"updateOrderbook","params":{"ask":[{"price":"0.00015824","size":"929.78"},{"price":"0.00015827","size":"0"},{"price":"0.00015838","size":"528.19"},{"price":"0.00015843","size":"0"},{"price":"0.00015855","size":"551.24"},{"price":"0.00015866","size":"0"}],"bid":[],"sequence":18307863,"timestamp":"2021-04-17T16:38:56.534Z","symbol":"OMGBTC"}}
1618677536.658495: {"jsonrpc":"2.0","method":"updateOrderbook","params":{"ask":[{"price":"0.00007664","size":"7906.82"},{"price":"0.00007667","size":"0"},{"price":"0.00007740","size":"7289.06"},{"price":"0.00007743","size":"0"},{"price":"0.00007818","size":"7948.85"},{"price":"0.00007822","size":"0"}],"bid":[],"sequence":5856084,"timestamp":"2021-04-17T16:38:56.590Z","symbol":"DODOBTC"}}
1618677536.666927: {"jsonrpc":"2.0","method":"updateOrderbook","params":{"ask":[{"price":"0.00026575","size":"0"}],"bid":[],"sequence":9316183,"timestamp":"2021-04-17T16:38:56.573Z","symbol":"XLMETH"}}
1618677536.7547252: {"jsonrpc":"2.0","method":"updateOrderbook","params":{"ask":[{"price":"0.00015863","size":"0"},{"price":"0.00015871","size":"2128.07"}],"bid":[{"price":"0.00015631","size":"3145.03"},{"price":"0.00015622","size":"1029.97"}],"sequence":18307864,"timestamp":"2021-04-17T16:38:56.726Z","symbol":"OMGBTC"}}
1618677536.75901: {"jsonrpc":"2.0","method":"updateOrderbook","params":{"ask":[],"bid":[{"price":"4.19414","size":"0"},{"price":"4.08262","size":"133.61"},{"price":"3.20798","size":"0"},{"price":"2.59182","size":"175.00"}],"sequence":7132847,"timestamp":"2021-04-17T16:38:56.720Z","symbol":"DODOUSD"}}
1618677536.760733: {"jsonrpc":"2.0","method":"updateOrderbook","params":{"ask":[],"bid":[{"price":"0.00006892","size":"0"}],"sequence":5856085,"timestamp":"2021-04-17T16:38:56.710Z","symbol":"DODOBTC"}}
1618677536.7769332: {"jsonrpc":"2.0","method":"updateOrderbook","params":{"ask":[{"price":"0.00026583","size":"10052.9"}],"bid":[],"sequence":9316184,"timestamp":"2021-04-17T16:38:56.708Z","symbol":"XLMETH"}}
1618677536.864838: {"jsonrpc":"2.0","method":"updateOrderbook","params":{"ask":[],"bid":[{"price":"0.00015648","size":"2504.10"},{"price":"0.00015635","size":"732.55"}],"sequence":18307865,"timestamp":"2021-04-17T16:38:56.726Z","symbol":"OMGBTC"}}
1618677536.9590552: {"jsonrpc":"2.0","method":"updateOrderbook","params":{"ask":[{"price":"0.00015824","size":"500.06"},{"price":"0.00015827","size":"429.72"},{"price":"0.00015838","size":"0"},{"price":"0.00015841","size":"528.19"},{"price":"0.00015855","size":"0"},{"price":"0.00015860","size":"551.24"}],"bid":[],"sequence":18307866,"timestamp":"2021-04-17T16:38:56.839Z","symbol":"OMGBTC"}}
1618677537.1103349: {"jsonrpc":"2.0","method":"updateOrderbook","params":{"ask":[],"bid":[{"price":"0.00015734","size":"0"},{"price":"0.00015724","size":"1394.00"},{"price":"0.00015699","size":"0"},{"price":"0.00015689","size":"2130.40"},{"price":"0.00015648","size":"0"},{"price":"0.00015639","size":"2504.10"},{"price":"0.00015563","size":"5478.09"},{"price":"0.00015535","size":"0"}],"sequence":18307867,"timestamp":"2021-04-17T16:38:57.018Z","symbol":"OMGBTC"}}
1618677537.110621: {"jsonrpc":"2.0","method":"updateOrderbook","params":{"ask":[],"bid":[{"price":"4.54308","size":"570.65"},{"price":"4.54158","size":"0"},{"price":"4.53682","size":"902.75"},{"price":"4.53651","size":"0"},{"price":"4.53245","size":"1196.81"},{"price":"4.53137","size":"0"},{"price":"4.52199","size":"1626.22"},{"price":"4.52120","size":"0"},{"price":"4.51644","size":"2203.89"},{"price":"4.51536","size":"0"}],"sequence":7132848,"timestamp":"2021-04-17T16:38:56.946Z","symbol":"DODOUSD"}}
1618677537.110821: {"jsonrpc":"2.0","method":"updateOrderbook","params":{"ask":[],"bid":[{"price":"0.00007513","size":"0"},{"price":"0.00007509","size":"133.61"}],"sequence":5856086,"timestamp":"2021-04-17T16:38:56.949Z","symbol":"DODOBTC"}}
1618677537.1108859: {"jsonrpc":"2.0","method":"updateOrderbook","params":{"ask":[{"price":"0.0167635","size":"72.92"}],"bid":[],"sequence":6928600,"timestamp":"2021-04-17T16:38:57.024Z","symbol":"ETCETH"}}
1618677537.15627: {"jsonrpc":"2.0","method":"updateOrderbook","params":{"ask":[{"price":"0.00015824","size":"0"},{"price":"0.00015827","size":"929.78"},{"price":"0.00015837","size":"0"},{"price":"0.00015840","size":"550.49"},{"price":"0.00015856","size":"0"},{"price":"0.00015861","size":"0"},{"price":"0.00015864","size":"112.89"},{"price":"0.00015871","size":"2277.66"}],"bid":[{"price":"0.00015752","size":"0.01"},{"price":"0.00015734","size":"963.02"},{"price":"0.00015724","size":"0"},{"price":"0.00015709","size":"1394.00"},{"price":"0.00015689","size":"308.69"},{"price":"0.00015665","size":"2100.06"},{"price":"0.00015631","size":"0"},{"price":"0.00015622","size":"4175.00"},{"price":"0.00015583","size":"2391.01"},{"price":"0.00015563","size":"0"},{"price":"0.00015551","size":"0"},{"price":"0.00015532","size":"5478.09"}],"sequence":18307868,"timestamp":"2021-04-17T16:38:57.087Z","symbol":"OMGBTC"}}
1618677537.1566799: {"jsonrpc":"2.0","method":"updateOrderbook","params":{"ask":[{"price":"6.24772","size":"0"},{"price":"6.24840","size":"1.00"}],"bid":[{"price":"4.54366","size":"570.65"},{"price":"4.54308","size":"0"},{"price":"4.53730","size":"902.75"},{"price":"4.53682","size":"0"},{"price":"4.49403","size":"4091.22"},{"price":"4.49227","size":"0"},{"price":"3.17280","size":"1.00"},{"price":"3.17246","size":"0"}],"sequence":7132849,"timestamp":"2021-04-17T16:38:57.097Z","symbol":"DODOUSD"}}
1618677537.262481: {"jsonrpc":"2.0","method":"updateOrderbook","params":{"ask":[{"price":"0.00015836","size":"0"},{"price":"0.00015842","size":"1774.39"}],"bid":[],"sequence":18307869,"timestamp":"2021-04-17T16:38:57.215Z","symbol":"OMGBTC"}}
1618677537.2627048: {"jsonrpc":"2.0","method":"updateOrderbook","params":{"ask":[{"price":"6.24840","size":"0"},{"price":"6.24909","size":"1.00"}],"bid":[{"price":"3.17315","size":"1.00"},{"price":"3.17280","size":"0"}],"sequence":7132850,"timestamp":"2021-04-17T16:38:57.156Z","symbol":"DODOUSD"}}
1618677537.357035: {"jsonrpc":"2.0","method":"updateOrderbook","params":{"ask":[{"price":"0.00015829","size":"0"},{"price":"0.00015839","size":"200.00"},{"price":"0.00015871","size":"149.59"},{"price":"0.00015896","size":"2128.07"},{"price":"0.00015949","size":"508.38"},{"price":"0.00015968","size":"7027.30"},{"price":"0.00015988","size":"1100.41"},{"price":"0.00016019","size":"5617.94"}],"bid":[],"sequence":18307870,"timestamp":"2021-04-17T16:38:57.318Z","symbol":"OMGBTC"}}
1618677537.452735: {"jsonrpc":"2.0","method":"updateOrderbook","params":{"ask":[],"bid":[{"price":"0.00015767","size":"67.05"},{"price":"0.00015763","size":"246.65"},{"price":"0.00015758","size":"200.00"}],"sequence":18307871,"timestamp":"2021-04-17T16:38:57.356Z","symbol":"OMGBTC"}}
1618677537.476116: {"jsonrpc":"2.0","method":"updateOrderbook","params":{"ask":[{"price":"0.00025491","size":"2900.0"},{"price":"0.00025526","size":"3000.0"}],"bid":[],"sequence":9316185,"timestamp":"2021-04-17T16:38:57.423Z","symbol":"XLMETH"}}
1618677537.5566368: {"jsonrpc":"2.0","method":"updateOrderbook","params":{"ask":[{"price":"0.00015887","size":"2128.07"},{"price":"0.00015896","size":"0"},{"price":"0.00017859","size":"0"},{"price":"0.00017868","size":"10422.63"}],"bid":[{"price":"0.00015764","size":"0"},{"price":"0.00015748","size":"9.55"}],"sequence":18307872,"timestamp":"2021-04-17T16:38:57.504Z","symbol":"OMGBTC"}}
1618677537.5641441: {"jsonrpc":"2.0","method":"updateOrderbook","params":{"ask":[{"price":"0.00025491","size":"5900.0"},{"price":"0.00025526","size":"0"}],"bid":[],"sequence":9316186,"timestamp":"2021-04-17T16:38:57.429Z","symbol":"XLMETH"}}
1618677537.65519: {"jsonrpc":"2.0","method":"updateOrderbook","params":{"ask":[{"price":"0.00015890","size":"861.52"},{"price":"0.00015903","size":"0"}],"bid":[{"price":"0.00015623","size":"0.01"},{"price":"0.00015619","size":"0"}],"sequence":18307873,"timestamp":"2021-04-17T16:38:57.604Z","symbol":"OMGBTC"}}
1618677537.762243: {"jsonrpc":"2.0","method":"updateOrderbook","params":{"ask":[{"price":"0.00015921","size":"0"},{"price":"0.00015924","size":"2.45"}],"bid":[{"price":"0.00015749","size":"963.02"},{"price":"0.00015734","size":"0"}],"sequence":18307874,"timestamp":"2021-04-17T16:38:57.725Z","symbol":"OMGBTC"}}
1618677537.7624161: {"jsonrpc":"2.0","method":"updateOrderbook","params":{"ask":[{"price":"6.24840","size":"1.00"},{"price":"6.24909","size":"0"}],"bid":[{"price":"4.53245","size":"0"},{"price":"4.53074","size":"1196.81"},{"price":"4.52199","size":"0"},{"price":"4.52109","size":"1626.22"},{"price":"4.49403","size":"0"},{"price":"4.49223","size":"4091.22"},{"price":"3.17315","size":"0"},{"price":"3.17280","size":"1.00"}],"sequence":7132851,"timestamp":"2021-04-17T16:38:57.668Z","symbol":"DODOUSD"}}
1618677537.766191: {"jsonrpc":"2.0","method":"updateOrderbook","params":{"ask":[],"bid":[{"price":"0.001309860","size":"1735"},{"price":"0.001309183","size":"0"},{"price":"0.001306478","size":"4338"},{"price":"0.001305482","size":"0"},{"price":"0.001299584","size":"39208"},{"price":"0.001298719","size":"0"}],"sequence":5053557,"timestamp":"2021-04-17T16:38:57.637Z","symbol":"ADABCH"}}
1618677537.85312: {"jsonrpc":"2.0","method":"updateOrderbook","params":{"ask":[{"price":"0.00015835","size":"200.00"},{"price":"0.00015836","size":"550.49"},{"price":"0.00015839","size":"0"},{"price":"0.00015840","size":"0"},{"price":"0.00015856","size":"112.89"},{"price":"0.00015864","size":"0"}],"bid":[{"price":"0.00015748","size":"0"},{"price":"0.00015745","size":"9.55"}],"sequence":18307875,"timestamp":"2021-04-17T16:38:57.798Z","symbol":"OMGBTC"}}
1618677537.853423: {"jsonrpc":"2.0","method":"updateOrderbook","params":{"ask":[{"price":"5.94383","size":"1.00"},{"price":"6.24840","size":"0"}],"bid":[{"price":"4.54404","size":"570.65"},{"price":"4.54366","size":"0"},{"price":"4.54061","size":"902.75"},{"price":"4.53730","size":"0"},{"price":"4.53364","size":"1196.81"},{"price":"4.53074","size":"0"},{"price":"4.52331","size":"1626.22"},{"price":"4.52109","size":"0"},{"price":"4.49402","size":"4091.22"},{"price":"4.49223","size":"0"},{"price":"3.47738","size":"1.00"},{"price":"3.17280","size":"0"}],"sequence":7132852,"timestamp":"2021-04-17T16:38:57.814Z","symbol":"DODOUSD"}}
1618677537.860497: {"jsonrpc":"2.0","method":"updateOrderbook","params":{"ask":[],"bid":[{"price":"0.00007455","size":"2672.36"},{"price":"0.00007450","size":"0"}],"sequence":5856087,"timestamp":"2021-04-17T16:38:57.808Z","symbol":"DODOBTC"}}
1618677537.955675: {"jsonrpc":"2.0","method":"updateOrderbook","params":{"ask":[{"price":"4.60441","size":"0"},{"price":"4.60993","size":"8443.15"},{"price":"4.65919","size":"0"},{"price":"4.66696","size":"10836.10"},{"price":"4.71913","size":"0"},{"price":"4.72403","size":"15561.71"},{"price":"4.78723","size":"0"},{"price":"4.79251","size":"21772.25"},{"price":"4.87723","size":"0"},{"price":"4.88172","size":"28569.63"}],"bid":[],"sequence":7132853,"timestamp":"2021-04-17T16:38:57.872Z","symbol":"DODOUSD"}}
1618677537.95598: {"jsonrpc":"2.0","method":"updateOrderbook","params":{"ask":[{"price":"0.00007664","size":"0"},{"price":"0.00007669","size":"7906.82"},{"price":"0.00007740","size":"0"},{"price":"0.00007745","size":"7289.06"},{"price":"0.00007818","size":"0"},{"price":"0.00007825","size":"7948.85"},{"price":"0.00007883","size":"0"},{"price":"0.00007889","size":"7232.40"},{"price":"0.00007949","size":"0"},{"price":"0.00007954","size":"6941.41"},{"price":"0.00008007","size":"0"},{"price":"0.00008010","size":"8109.89"},{"price":"0.00008087","size":"0"},{"price":"0.00008090","size":"7976.28"}],"bid":[],"sequence":5856088,"timestamp":"2021-04-17T16:38:57.877Z","symbol":"DODOBTC"}}
1618677537.9605691: {"jsonrpc":"2.0","method":"updateOrderbook","params":{"ask":[],"bid":[{"price":"0.001287341","size":"37612"},{"price":"0.001286342","size":"0"},{"price":"0.001277915","size":"39117"},{"price":"0.001277380","size":"0"},{"price":"0.001269072","size":"44239"},{"price":"0.001268384","size":"0"},{"price":"0.001262113","size":"37938"},{"price":"0.001261029","size":"0"},{"price":"0.001255960","size":"39175"},{"price":"0.001255031","size":"0"},{"price":"0.001250467","size":"39768"},{"price":"0.001249874","size":"0"},{"price":"0.001226026","size":"0"},{"price":"0.001225627","size":"37564"}],"sequence":5053558,"timestamp":"2021-04-17T16:38:57.893Z","symbol":"ADABCH"}}
1618677538.0526981: {"jsonrpc":"2.0","method":"updateOrderbook","params":{"ask":[],"bid":[{"price":"0.00015739","size":"1394.00"},{"price":"0.00015709","size":"0"},{"price":"0.00015705","size":"1821.71"},{"price":"0.00015665","size":"278.35"}],"sequence":18307876,"timestamp":"2021-04-17T16:38:58.008Z","symbol":"OMGBTC"}}
1618677538.052943: {"jsonrpc":"2.0","method":"updateOrderbook","params":{"ask":[{"price":"5.94318","size":"1.00"},{"price":"5.94383","size":"0"}],"bid":[{"price":"4.53445","size":"1196.81"},{"price":"4.53364","size":"0"},{"price":"4.52488","size":"1626.22"},{"price":"4.52331","size":"0"},{"price":"4.49566","size":"4091.22"},{"price":"4.49402","size":"0"},{"price":"3.47738","size":"0"},{"price":"3.47700","size":"1.00"}],"sequence":7132854,"timestamp":"2021-04-17T16:38:57.965Z","symbol":"DODOUSD"}}
1618677538.064728: {"jsonrpc":"2.0","method":"updateOrderbook","params":{"ask":[{"price":"0.001372142","size":"0"},{"price":"0.001372558","size":"52341"},{"price":"0.001377614","size":"0"},{"price":"0.001378040","size":"54827"}],"bid":[{"price":"0.001243606","size":"40326"},{"price":"0.001242900","size":"0"}],"sequence":5053559,"timestamp":"2021-04-17T16:38:57.943Z","symbol":"ADABCH"}}
1618677538.161355: {"jsonrpc":"2.0","method":"updateOrderbook","params":{"ask":[{"price":"0.00015826","size":"1472.79"},{"price":"0.00015835","size":"0"}],"bid":[{"price":"0.00015759","size":"9.55"},{"price":"0.00015745","size":"0"}],"sequence":18307877,"timestamp":"2021-04-17T16:38:58.080Z","symbol":"OMGBTC"}}
1618677538.161591: {"jsonrpc":"2.0","method":"updateOrderbook","params":{"ask":[],"bid":[{"price":"4.53445","size":"0"},{"price":"4.53364","size":"1196.81"},{"price":"4.52488","size":"0"},{"price":"4.52320","size":"1626.22"}],"sequence":7132855,"timestamp":"2021-04-17T16:38:58.069Z","symbol":"DODOUSD"}}
1618677538.17258: {"jsonrpc":"2.0","method":"updateOrderbook","params":{"ask":[],"bid":[{"price":"0.0162601","size":"0"},{"price":"0.0162546","size":"15.69"}],"sequence":6928601,"timestamp":"2021-04-17T16:38:58.080Z","symbol":"ETCETH"}}
1618677538.256671: {"jsonrpc":"2.0","method":"updateOrderbook","params":{"ask":[{"price":"5.94318","size":"0"},{"price":"5.94383","size":"1.00"}],"bid":[{"price":"3.47738","size":"1.00"},{"price":"3.47700","size":"0"}],"sequence":7132856,"timestamp":"2021-04-17T16:38:58.151Z","symbol":"DODOUSD"}}
1618677538.2662568: {"jsonrpc":"2.0","method":"updateOrderbook","params":{"ask":[],"bid":[{"price":"0.00006870","size":"145.56"}],"sequence":5856089,"timestamp":"2021-04-17T16:38:58.210Z","symbol":"DODOBTC"}}
1618677538.27524: {"jsonrpc":"2.0","method":"updateOrderbook","params":{"ask":[],"bid":[{"price":"0.00024017","size":"0"},{"price":"0.00024009","size":"84667.4"}],"sequence":9316187,"timestamp":"2021-04-17T16:38:58.178Z","symbol":"XLMETH"}}
1618677538.3565598: {"jsonrpc":"2.0","method":"updateOrderbook","params":{"ask":[],"bid":[{"price":"4.54061","size":"0"},{"price":"4.54006","size":"902.75"},{"price":"4.49566","size":"0"},{"price":"4.49385","size":"4091.22"}],"sequence":7132857,"timestamp":"2021-04-17T16:38:58.286Z","symbol":"DODOUSD"}}
1618677538.455914: {"jsonrpc":"2.0","method":"updateOrderbook","params":{"ask":[{"price":"0.00015809","size":"0"},{"price":"0.00015810","size":"72.33"},{"price":"0.00015813","size":"0"},{"price":"0.00015815","size":"245.28"},{"price":"0.00015816","size":"103.39"},{"price":"0.00015819","size":"0"},{"price":"0.00015824","size":"692.41"},{"price":"0.00015826","size":"200.00"},{"price":"0.00015831","size":"929.39"},{"price":"0.00015842","size":"0"},{"price":"0.00015846","size":"1272.79"},{"price":"0.00015887","size":"0"},{"price":"0.00015888","size":"1774.39"},{"price":"0.00015897","size":"2128.07"},{"price":"0.00015901","size":"0"},{"price":"0.00015923","size":"3008.25"},{"price":"0.00016019","size":"0"},{"price":"0.00016096","size":"5617.94"}],"bid":[{"price":"0.00015749","size":"0"},{"price":"0.00015739","size":"963.02"},{"price":"0.00015713","size":"1394.00"},{"price":"0.00015705","size":"0"},{"price":"0.00015671","size":"1821.71"},{"price":"0.00015639","size":"0"},{"price":"0.00015635","size":"3236.65"},{"price":"0.00015631","size":"3145.03"},{"price":"0.00015622","size":"1029.97"},{"price":"0.00015544","size":"5478.09"},{"price":"0.00015532","size":"0"}],"sequence":18307878,"timestamp":"2021-04-17T16:38:58.362Z","symbol":"OMGBTC"}}
1618677538.456447: {"jsonrpc":"2.0","method":"updateOrderbook","params":{"ask":[],"bid":[{"price":"4.54061","size":"902.75"},{"price":"4.54006","size":"0"}],"sequence":7132858,"timestamp":"2021-04-17T16:38:58.356Z","symbol":"DODOUSD"}}
1618677538.4695392: {"jsonrpc":"2.0","method":"updateOrderbook","params":{"ask":[],"bid":[{"price":"0.00025428","size":"0"},{"price":"0.00025419","size":"1180.6"}],"sequence":9316188,"timestamp":"2021-04-17T16:38:58.340Z","symbol":"XLMETH"}}
1618677538.554883: {"jsonrpc":"2.0","method":"updateOrderbook","params":{"ask":[],"bid":[{"price":"0.00015768","size":"9.55"},{"price":"0.00015759","size":"0"}],"sequence":18307879,"timestamp":"2021-04-17T16:38:58.456Z","symbol":"OMGBTC"}}
1618677538.555181: {"jsonrpc":"2.0","method":"updateOrderbook","params":{"ask":[{"price":"5.94318","size":"1.00"},{"price":"5.94383","size":"0"}],"bid":[{"price":"3.47738","size":"0"},{"price":"3.47700","size":"1.00"}],"sequence":7132859,"timestamp":"2021-04-17T16:38:58.439Z","symbol":"DODOUSD"}}
1618677538.569272: {"jsonrpc":"2.0","method":"updateOrderbook","params":{"ask":[],"bid":[{"price":"0.00007526","size":"0.05"}],"sequence":5856090,"timestamp":"2021-04-17T16:38:58.472Z","symbol":"DODOBTC"}}
1618677538.6515698: {"jsonrpc":"2.0","method":"updateOrderbook","params":{"ask":[{"price":"0.00015922","size":"737.36"},{"price":"0.00015924","size":"0"}],"bid":[],"sequence":18307880,"timestamp":"2021-04-17T16:38:58.602Z","symbol":"OMGBTC"}}
1618677538.660091: {"jsonrpc":"2.0","method":"updateOrderbook","params":{"ask":[],"bid":[{"price":"0.00007526","size":"0"}],"sequence":5856091,"timestamp":"2021-04-17T16:38:58.605Z","symbol":"DODOBTC"}}
1618677538.754165: {"jsonrpc":"2.0","method":"updateOrderbook","params":{"ask":[],"bid":[{"price":"0.00015768","size":"76.60"},{"price":"0.00015767","size":"0"}],"sequence":18307881,"timestamp":"2021-04-17T16:38:58.707Z","symbol":"OMGBTC"}}
1618677538.854541: {"jsonrpc":"2.0","method":"updateOrderbook","params":{"ask":[{"price":"0.00015861","size":"149.59"},{"price":"0.00015871","size":"0"}],"bid":[{"price":"0.00015768","size":"67.05"},{"price":"0.00015764","size":"9.55"}],"sequence":18307882,"timestamp":"2021-04-17T16:38:58.781Z","symbol":"OMGBTC"}}
1618677538.8547788: {"jsonrpc":"2.0","method":"updateOrderbook","params":{"ask":[],"bid":[{"price":"4.48176","size":"1661.53"},{"price":"4.48004","size":"0"}],"sequence":7132860,"timestamp":"2021-04-17T16:38:58.767Z","symbol":"DODOUSD"}}
1618677538.8630002: {"jsonrpc":"2.0","method":"updateOrderbook","params":{"ask":[],"bid":[{"price":"0.00023952","size":"0"},{"price":"0.00023944","size":"75814.7"}],"sequence":9316189,"timestamp":"2021-04-17T16:38:58.770Z","symbol":"XLMETH"}}
1618677538.9695628: {"jsonrpc":"2.0","method":"updateOrderbook","params":{"ask":[{"price":"0.0167587","size":"784.64"},{"price":"0.0167636","size":"0"}],"bid":[],"sequence":6928602,"timestamp":"2021-04-17T16:38:58.920Z","symbol":"ETCETH"}}
1618677539.05711: {"jsonrpc":"2.0","method":"updateOrderbook","params":{"ask":[{"price":"0.00015825","size":"1091.77"},{"price":"0.00015831","size":"0"}],"bid":[{"price":"0.00015761","size":"603.33"},{"price":"0.00015756","size":"1002.22"},{"price":"0.00015755","size":"507.30"},{"price":"0.00015739","size":"0"}],"sequence":18307883,"timestamp":"2021-04-17T16:38:58.988Z","symbol":"OMGBTC"}}
1618677539.076559: {"jsonrpc":"2.0","method":"updateOrderbook","params":{"ask":[{"price":"0.001342031","size":"0"},{"price":"0.001342437","size":"56233"}],"bid":[],"sequence":5053560,"timestamp":"2021-04-17T16:38:58.945Z","symbol":"ADABCH"}}
1618677539.152478: {"jsonrpc":"2.0","method":"updateOrderbook","params":{"ask":[{"price":"0.00015807","size":"0"},{"price":"0.00015820","size":"42.78"},{"price":"0.00015922","size":"734.91"},{"price":"0.00015924","size":"2.45"}],"bid":[{"price":"0.00015769","size":"9.55"},{"price":"0.00015764","size":"0"}],"sequence":18307884,"timestamp":"2021-04-17T16:38:59.122Z","symbol":"OMGBTC"}}
1618677539.152817: {"jsonrpc":"2.0","method":"updateOrderbook","params":{"ask":[],"bid":[{"price":"4.08262","size":"0"},{"price":"3.86522","size":"133.61"},{"price":"2.59182","size":"0"},{"price":"1.96285","size":"175.00"}],"sequence":7132861,"timestamp":"2021-04-17T16:38:59.080Z","symbol":"DODOUSD"}}
1618677539.159599: {"jsonrpc":"2.0","method":"updateOrderbook","params":{"ask":[],"bid":[{"price":"0.00006371","size":"0"}],"sequence":5856092,"timestamp":"2021-04-17T16:38:59.073Z","symbol":"DODOBTC"}}
1618677539.25506: {"jsonrpc":"2.0","method":"updateOrderbook","params":{"ask":[{"price":"5.94253","size":"1.00"},{"price":"5.94318","size":"0"}],"bid":[{"price":"3.47700","size":"0"},{"price":"3.47661","size":"1.00"}],"sequence":7132862,"timestamp":"2021-04-17T16:38:59.140Z","symbol":"DODOUSD"}}
1618677539.3531919: {"jsonrpc":"2.0","method":"updateOrderbook","params":{"ask":[{"price":"4.66379","size":"10836.10"},{"price":"4.66696","size":"0"},{"price":"5.94253","size":"0"},{"price":"5.94318","size":"1.00"}],"bid":[{"price":"3.47700","size":"1.00"},{"price":"3.47661","size":"0"}],"sequence":7132863,"timestamp":"2021-04-17T16:38:59.273Z","symbol":"DODOUSD"}}
1618677539.452228: {"jsonrpc":"2.0","method":"updateOrderbook","params":{"ask":[{"price":"0.00015829","size":"1272.79"},{"price":"0.00015841","size":"2302.58"},{"price":"0.00015846","size":"0"},{"price":"0.00015888","size":"0"}],"bid":[{"price":"0.00015768","size":"0"},{"price":"0.00015766","size":"67.05"},{"price":"0.00015761","size":"0"},{"price":"0.00015756","size":"39.20"},{"price":"0.00015754","size":"603.33"},{"price":"0.00015734","size":"963.02"},{"price":"0.00015713","size":"0"},{"price":"0.00015709","size":"1394.00"},{"price":"0.00015671","size":"0"},{"price":"0.00015666","size":"1821.71"},{"price":"0.00015631","size":"0"},{"price":"0.00015622","size":"4175.00"}],"sequence":18307885,"timestamp":"2021-04-17T16:38:59.399Z","symbol":"OMGBTC"}}
1618677539.452599: {"jsonrpc":"2.0","method":"updateOrderbook","params":{"ask":[{"price":"5.94253","size":"1.00"},{"price":"5.94318","size":"0"}],"bid":[{"price":"3.47700","size":"0"},{"price":"3.47661","size":"1.00"}],"sequence":7132864,"timestamp":"2021-04-17T16:38:59.341Z","symbol":"DODOUSD"}}
1618677539.551832: {"jsonrpc":"2.0","method":"updateOrderbook","params":{"ask":[{"price":"0.00015807","size":"42.78"},{"price":"0.00015820","size":"0"}],"bid":[{"price":"0.00015769","size":"0"},{"price":"0.00015759","size":"9.55"}],"sequence":18307886,"timestamp":"2021-04-17T16:38:59.475Z","symbol":"OMGBTC"}}
1618677539.561125: {"jsonrpc":"2.0","method":"updateOrderbook","params":{"ask":[],"bid":[{"price":"0.00007526","size":"0.05"}],"sequence":5856093,"timestamp":"2021-04-17T16:38:59.485Z","symbol":"DODOBTC"}}
1618677539.659081: {"jsonrpc":"2.0","method":"updateOrderbook","params":{"ask":[{"price":"0.00015879","size":"2128.07"},{"price":"0.00015897","size":"0"},{"price":"0.00015901","size":"3008.25"},{"price":"0.00015923","size":"0"}],"bid":[],"sequence":18307887,"timestamp":"2021-04-17T16:38:59.582Z","symbol":"OMGBTC"}}
1618677539.6628768: {"jsonrpc":"2.0","method":"updateOrderbook","params":{"ask":[],"bid":[{"price":"0.00007526","size":"0"}],"sequence":5856094,"timestamp":"2021-04-17T16:38:59.602Z","symbol":"DODOBTC"}}
1618677540.023641: {"jsonrpc":"2.0","method":"updateOrderbook","params":{"ask":[{"price":"0.00015949","size":"4910.46"},{"price":"0.00015968","size":"2625.22"},{"price":"0.00015988","size":"6718.35"},{"price":"0.00016096","size":"0"}],"bid":[],"sequence":18307888,"timestamp":"2021-04-17T16:38:59.901Z","symbol":"OMGBTC"}}
1618677540.079364: {"jsonrpc":"2.0","method":"updateOrderbook","params":{"ask":[],"bid":[{"price":"0.00007517","size":"133.61"},{"price":"0.00007509","size":"0"},{"price":"0.00007487","size":"1737.03"},{"price":"0.00007484","size":"0"}],"sequence":5856095,"timestamp":"2021-04-17T16:38:59.963Z","symbol":"DODOBTC"}}
1618677540.330152: {"jsonrpc":"2.0","method":"updateOrderbook","params":{"ask":[],"bid":[{"price":"0.00015749","size":"963.02"},{"price":"0.00015734","size":"0"}],"sequence":18307889,"timestamp":"2021-04-17T16:39:00.119Z","symbol":"OMGBTC"}}
1618677540.441032: {"jsonrpc":"2.0","method":"updateOrderbook","params":{"ask":[{"price":"0.001320219","size":"4338"},{"price":"0.001320650","size":"0"},{"price":"0.001327874","size":"51644"},{"price":"0.001328355","size":"0"}],"bid":[],"sequence":5053561,"timestamp":"2021-04-17T16:39:00.290Z","symbol":"ADABCH"}}
1618677540.441267: {"jsonrpc":"2.0","method":"updateOrderbook","params":{"ask":[],"bid":[{"price":"0.0162609","size":"15.69"},{"price":"0.0162546","size":"0"}],"sequence":6928603,"timestamp":"2021-04-17T16:39:00.246Z","symbol":"ETCETH"}}
1618677540.454211: {"jsonrpc":"2.0","method":"updateOrderbook","params":{"ask":[],"bid":[{"price":"0.00015767","size":"9.55"},{"price":"0.00015759","size":"0"},{"price":"0.00015734","size":"1394.00"},{"price":"0.00015709","size":"0"},{"price":"0.00015700","size":"1821.71"},{"price":"0.00015666","size":"0"}],"sequence":18307890,"timestamp":"2021-04-17T16:39:00.334Z","symbol":"OMGBTC"}}
1618677540.561238: {"jsonrpc":"2.0","method":"updateOrderbook","params":{"ask":[{"price":"0.00015938","size":"890.55"},{"price":"0.00015944","size":"466.51"}],"bid":[],"sequence":18307891,"timestamp":"2021-04-17T16:39:00.441Z","symbol":"OMGBTC"}}
1618677540.654458: {"jsonrpc":"2.0","method":"updateOrderbook","params":{"ask":[],"bid":[{"price":"3.86522","size":"0"},{"price":"3.84720","size":"133.56"},{"price":"1.96285","size":"0"},{"price":"1.94581","size":"175.05"}],"sequence":7132865,"timestamp":"2021-04-17T16:39:00.567Z","symbol":"DODOUSD"}}
1618677540.6603289: {"jsonrpc":"2.0","method":"updateOrderbook","params":{"ask":[],"bid":[{"price":"0.00007486","size":"0"},{"price":"0.00006345","size":"315.20"}],"sequence":5856096,"timestamp":"2021-04-17T16:39:00.575Z","symbol":"DODOBTC"}}
1618677540.667091: {"jsonrpc":"2.0","method":"updateOrderbook","params":{"ask":[],"bid":[{"price":"0.001243606","size":"0"},{"price":"0.001243047","size":"40326"}],"sequence":5053562,"timestamp":"2021-04-17T16:39:00.558Z","symbol":"ADABCH"}}
1618677540.755988: {"jsonrpc":"2.0","method":"updateOrderbook","params":{"ask":[],"bid":[{"price":"0.00015648","size":"2504.10"},{"price":"0.00015635","size":"732.55"},{"price":"0.00015631","size":"3145.03"},{"price":"0.00015622","size":"1029.97"}],"sequence":18307892,"timestamp":"2021-04-17T16:39:00.645Z","symbol":"OMGBTC"}}
1618677540.76263: {"jsonrpc":"2.0","method":"updateOrderbook","params":{"ask":[],"bid":[{"price":"0.00007475","size":"3.66"}],"sequence":5856097,"timestamp":"2021-04-17T16:39:00.636Z","symbol":"DODOBTC"}}
1618677540.962909: {"jsonrpc":"2.0","method":"updateOrderbook","params":{"ask":[{"price":"0.00015938","size":"0"},{"price":"0.00015944","size":"984.17"}],"bid":[],"sequence":18307893,"timestamp":"2021-04-17T16:39:00.850Z","symbol":"OMGBTC"}}
1618677540.97611: {"jsonrpc":"2.0","method":"updateOrderbook","params":{"ask":[],"bid":[{"price":"0.001295280","size":"40483"},{"price":"0.001294542","size":"0"}],"sequence":5053563,"timestamp":"2021-04-17T16:39:00.897Z","symbol":"ADABCH"}}
1618677541.0545979: {"jsonrpc":"2.0","method":"updateOrderbook","params":{"ask":[],"bid":[{"price":"0.00015571","size":"5478.09"},{"price":"0.00015544","size":"0"}],"sequence":18307894,"timestamp":"2021-04-17T16:39:00.957Z","symbol":"OMGBTC"}}
1618677541.180299: {"jsonrpc":"2.0","method":"updateOrderbook","params":{"ask":[{"price":"0.00015825","size":"1521.49"},{"price":"0.00015827","size":"500.06"},{"price":"0.00015857","size":"551.24"},{"price":"0.00015860","size":"0"},{"price":"0.00015921","size":"2.45"},{"price":"0.00015924","size":"0"}],"bid":[{"price":"0.00015723","size":"0"},{"price":"0.00015718","size":"587.38"},{"price":"0.00015697","size":"0"},{"price":"0.00015694","size":"477.14"},{"price":"0.00015623","size":"0"},{"price":"0.00015619","size":"0.01"}],"sequence":18307895,"timestamp":"2021-04-17T16:39:01.122Z","symbol":"OMGBTC"}}
1618677541.180639: {"jsonrpc":"2.0","method":"updateOrderbook","params":{"ask":[{"price":"0.001371884","size":"52341"},{"price":"0.001372558","size":"0"},{"price":"0.001377476","size":"54827"},{"price":"0.001378040","size":"0"},{"price":"0.001382312","size":"49524"},{"price":"0.001382800","size":"0"}],"bid":[],"sequence":5053564,"timestamp":"2021-04-17T16:39:01.070Z","symbol":"ADABCH"}}
1618677541.354847: {"jsonrpc":"2.0","method":"updateOrderbook","params":{"ask":[{"price":"0.00015879","size":"0"},{"price":"0.00015887","size":"2128.07"},{"price":"0.00015949","size":"508.38"},{"price":"0.00015968","size":"7027.30"},{"price":"0.00015988","size":"1100.41"},{"price":"0.00016015","size":"5617.94"}],"bid":[{"price":"0.00015560","size":"0"}],"sequence":18307896,"timestamp":"2021-04-17T16:39:01.299Z","symbol":"OMGBTC"}}
1618677541.367114: {"jsonrpc":"2.0","method":"updateOrderbook","params":{"ask":[{"price":"0.00025562","size":"10000.0"},{"price":"0.00025574","size":"0"}],"bid":[],"sequence":9316190,"timestamp":"2021-04-17T16:39:01.240Z","symbol":"XLMETH"}}
1618677541.456681: {"jsonrpc":"2.0","method":"updateOrderbook","params":{"ask":[],"bid":[{"price":"0.00015749","size":"0"},{"price":"0.00015737","size":"963.02"},{"price":"0.00015734","size":"0"},{"price":"0.00015712","size":"1394.00"},{"price":"0.00015700","size":"0"},{"price":"0.00015669","size":"2267.09"},{"price":"0.00015648","size":"0"},{"price":"0.00015635","size":"3236.65"},{"price":"0.00015631","size":"0"},{"price":"0.00015623","size":"3145.03"},{"price":"0.00015572","size":"185.18"},{"price":"0.00015571","size":"0"},{"price":"0.00015540","size":"5478.09"}],"sequence":18307897,"timestamp":"2021-04-17T16:39:01.390Z","symbol":"OMGBTC"}}
1618677541.467317: {"jsonrpc":"2.0","method":"updateOrderbook","params":{"ask":[{"price":"0.001336425","size":"52325"},{"price":"0.001336848","size":"0"},{"price":"0.001366786","size":"53172"},{"price":"0.001367327","size":"0"}],"bid":[],"sequence":5053565,"timestamp":"2021-04-17T16:39:01.375Z","symbol":"ADABCH"}}
1618677541.4675531: {"jsonrpc":"2.0","method":"updateOrderbook","params":{"ask":[],"bid":[{"price":"0.0162602","size":"0"}],"sequence":6928604,"timestamp":"2021-04-17T16:39:01.411Z","symbol":"ETCETH"}}
1618677541.5627809: {"jsonrpc":"2.0","method":"updateOrderbook","params":{"ask":[{"price":"0.00015822","size":"429.72"},{"price":"0.00015825","size":"1091.77"},{"price":"0.00015837","size":"528.19"},{"price":"0.00015841","size":"1774.39"},{"price":"0.00015938","size":"890.55"},{"price":"0.00015944","size":"466.51"},{"price":"0.00015984","size":"1828.03"},{"price":"0.00016020","size":"0"}],"bid":[{"price":"0.00015767","size":"0"},{"price":"0.00015759","size":"9.55"}],"sequence":18307898,"timestamp":"2021-04-17T16:39:01.520Z","symbol":"OMGBTC"}}
1618677541.563179: {"jsonrpc":"2.0","method":"updateOrderbook","params":{"ask":[],"bid":[{"price":"4.54061","size":"0"},{"price":"4.54005","size":"902.75"}],"sequence":7132866,"timestamp":"2021-04-17T16:39:01.435Z","symbol":"DODOUSD"}}
1618677541.662485: {"jsonrpc":"2.0","method":"updateOrderbook","params":{"ask":[{"price":"0.00015822","size":"0"},{"price":"0.00015824","size":"1122.13"},{"price":"0.00015938","size":"0"},{"price":"0.00015944","size":"984.17"}],"bid":[],"sequence":18307899,"timestamp":"2021-04-17T16:39:01.555Z","symbol":"OMGBTC"}}
1618677541.679253: {"jsonrpc":"2.0","method":"updateOrderbook","params":{"ask":[],"bid":[{"price":"0.0162610","size":"48.68"}],"sequence":6928605,"timestamp":"2021-04-17T16:39:01.528Z","symbol":"ETCETH"}}
1618677541.76619: {"jsonrpc":"2.0","method":"updateOrderbook","params":{"ask":[{"price":"0.001315926","size":"520"},{"price":"0.001316795","size":"0"}],"bid":[],"sequence":5053566,"timestamp":"2021-04-17T16:39:01.669Z","symbol":"ADABCH"}}
1618677541.856972: {"jsonrpc":"2.0","method":"updateOrderbook","params":{"ask":[],"bid":[{"price":"0.00015767","size":"67.05"},{"price":"0.00015766","size":"0"},{"price":"0.00015741","size":"587.38"},{"price":"0.00015718","size":"0"},{"price":"0.00015705","size":"477.14"},{"price":"0.00015694","size":"0"},{"price":"0.00015572","size":"0"}],"sequence":18307900,"timestamp":"2021-04-17T16:39:01.752Z","symbol":"OMGBTC"}}
1618677541.857316: {"jsonrpc":"2.0","method":"updateOrderbook","params":{"ask":[{"price":"5.94253","size":"0"},{"price":"6.31924","size":"1.00"}],"bid":[{"price":"4.53364","size":"0"},{"price":"4.53302","size":"1196.81"},{"price":"3.47661","size":"0"},{"price":"3.09990","size":"1.00"}],"sequence":7132867,"timestamp":"2021-04-17T16:39:01.771Z","symbol":"DODOUSD"}}
1618677541.881189: {"jsonrpc":"2.0","method":"updateOrderbook","params":{"ask":[{"price":"0.001317396","size":"1735"},{"price":"0.001318270","size":"0"}],"bid":[],"sequence":5053567,"timestamp":"2021-04-17T16:39:01.796Z","symbol":"ADABCH"}}
1618677541.881394: {"jsonrpc":"2.0","method":"updateOrderbook","params":{"ask":[{"price":"0.00026583","size":"0"}],"bid":[],"sequence":9316191,"timestamp":"2021-04-17T16:39:01.752Z","symbol":"XLMETH"}}
1618677541.958771: {"jsonrpc":"2.0","method":"updateOrderbook","params":{"ask":[],"bid":[{"price":"0.00015560","size":"185.32"}],"sequence":18307901,"timestamp":"2021-04-17T16:39:01.829Z","symbol":"OMGBTC"}}
1618677541.967715: {"jsonrpc":"2.0","method":"updateOrderbook","params":{"ask":[{"price":"0.00026583","size":"10050.2"}],"bid":[],"sequence":9316192,"timestamp":"2021-04-17T16:39:01.909Z","symbol":"XLMETH"}}
1618677542.074336: {"jsonrpc":"2.0","method":"updateOrderbook","params":{"ask":[],"bid":[{"price":"0.001269072","size":"0"},{"price":"0.001268638","size":"44239"},{"price":"0.001262113","size":"0"},{"price":"0.001261459","size":"37938"},{"price":"0.001255960","size":"0"},{"price":"0.001255197","size":"39175"},{"price":"0.001250467","size":"0"},{"price":"0.001248851","size":"39768"},{"price":"0.001243047","size":"0"},{"price":"0.001241544","size":"40326"},{"price":"0.001236184","size":"0"},{"price":"0.001234754","size":"44200"},{"price":"0.001230384","size":"0"},{"price":"0.001229091","size":"40497"},{"price":"0.001225627","size":"0"},{"price":"0.001224436","size":"37521"}],"sequence":5053568,"timestamp":"2021-04-17T16:39:01.930Z","symbol":"ADABCH"}}
1618677542.161209: {"jsonrpc":"2.0","method":"updateOrderbook","params":{"ask":[{"price":"0.00015821","size":"841.86"},{"price":"0.00015824","size":"429.72"}],"bid":[{"price":"0.00015760","size":"603.33"},{"price":"0.00015756","size":"1002.22"},{"price":"0.00015754","size":"0"},{"price":"0.00015737","size":"0"}],"sequence":18307902,"timestamp":"2021-04-17T16:39:02.094Z","symbol":"OMGBTC"}}
1618677542.161469: {"jsonrpc":"2.0","method":"updateOrderbook","params":{"ask":[{"price":"6.31924","size":"0"},{"price":"6.31993","size":"1.00"}],"bid":[{"price":"3.10024","size":"1.00"},{"price":"3.09990","size":"0"}],"sequence":7132868,"timestamp":"2021-04-17T16:39:02.115Z","symbol":"DODOUSD"}}
1618677542.167124: {"jsonrpc":"2.0","method":"updateOrderbook","params":{"ask":[{"price":"0.001341694","size":"56233"},{"price":"0.001342437","size":"0"},{"price":"0.001386615","size":"49151"},{"price":"0.001387340","size":"0"}],"bid":[],"sequence":5053569,"timestamp":"2021-04-17T16:39:02.060Z","symbol":"ADABCH"}}
1618677542.26565: {"jsonrpc":"2.0","method":"updateOrderbook","params":{"ask":[],"bid":[{"price":"0.00015768","size":"9.55"},{"price":"0.00015759","size":"0"}],"sequence":18307903,"timestamp":"2021-04-17T16:39:02.160Z","symbol":"OMGBTC"}}
1618677542.265926: {"jsonrpc":"2.0","method":"updateOrderbook","params":{"ask":[{"price":"6.31924","size":"1.00"},{"price":"6.31993","size":"0"}],"bid":[{"price":"3.10024","size":"0"},{"price":"3.09990","size":"1.00"}],"sequence":7132869,"timestamp":"2021-04-17T16:39:02.203Z","symbol":"DODOUSD"}}
1618677542.266075: {"jsonrpc":"2.0","method":"updateOrderbook","params":{"ask":[],"bid":[{"price":"0.001309860","size":"0"},{"price":"0.001309411","size":"1735"}],"sequence":5053570,"timestamp":"2021-04-17T16:39:02.199Z","symbol":"ADABCH"}}
1618677542.357188: {"jsonrpc":"2.0","method":"updateOrderbook","params":{"ask":[{"price":"0.00007666","size":"7906.97"},{"price":"0.00007669","size":"0"}],"bid":[],"sequence":5856098,"timestamp":"2021-04-17T16:39:02.281Z","symbol":"DODOBTC"}}
1618677542.367862: {"jsonrpc":"2.0","method":"updateOrderbook","params":{"ask":[{"price":"0.0167587","size":"0"},{"price":"0.0167637","size":"784.46"}],"bid":[],"sequence":6928606,"timestamp":"2021-04-17T16:39:02.277Z","symbol":"ETCETH"}}
1618677542.457983: {"jsonrpc":"2.0","method":"updateOrderbook","params":{"ask":[],"bid":[{"price":"0.00015748","size":"780.80"},{"price":"0.00015744","size":"0"},{"price":"0.00015738","size":"1394.00"},{"price":"0.00015737","size":"670.43"},{"price":"0.00015733","size":"0"},{"price":"0.00015724","size":"91.76"},{"price":"0.00015714","size":"0"},{"price":"0.00015712","size":"0"},{"price":"0.00015705","size":"2298.85"},{"price":"0.00015669","size":"445.38"},{"price":"0.00015652","size":"428.23"},{"price":"0.00015636","size":"0"}],"sequence":18307904,"timestamp":"2021-04-17T16:39:02.344Z","symbol":"OMGBTC"}}
1618677542.5629041: {"jsonrpc":"2.0","method":"updateOrderbook","params":{"ask":[{"price":"0.00015807","size":"0"},{"price":"0.00015814","size":"42.78"}],"bid":[],"sequence":18307905,"timestamp":"2021-04-17T16:39:02.465Z","symbol":"OMGBTC"}}
1618677542.653789: {"jsonrpc":"2.0","method":"updateOrderbook","params":{"ask":[{"price":"0.00015821","size":"692.41"},{"price":"0.00015825","size":"929.39"},{"price":"0.00015865","size":"2128.07"},{"price":"0.00015880","size":"149.45"},{"price":"0.00015884","size":"633.98"},{"price":"0.00015887","size":"0"},{"price":"0.00015890","size":"227.54"},{"price":"0.00015907","size":"373.07"},{"price":"0.00015926","size":"162.38"},{"price":"0.00015930","size":"234.96"},{"price":"0.00015984","size":"0"},{"price":"0.00016020","size":"1828.03"},{"price":"0.00017717","size":"0"},{"price":"0.00018167","size":"2362.68"}],"bid":[{"price":"0.00015767","size":"0"},{"price":"0.00015765","size":"67.05"},{"price":"0.00015763","size":"0"},{"price":"0.00015760","size":"0"},{"price":"0.00015757","size":"436.38"},{"price":"0.00015756","size":"39.20"},{"price":"0.00015750","size":"803.33"},{"price":"0.00015741","size":"0"},{"price":"0.00015738","size":"0"},{"price":"0.00015737","size":"0"},{"price":"0.00015733","size":"670.43"},{"price":"0.00015726","size":"1073.34"},{"price":"0.00015724","size":"0"},{"price":"0.00015722","size":"587.38"},{"price":"0.00015714","size":"91.76"},{"price":"0.00015705","size":"0"},{"price":"0.00015701","size":"1394.00"},{"price":"0.00015683","size":"477.14"},{"price":"0.00015663","size":"0"},{"price":"0.00015659","size":"1821.71"},{"price":"0.00015658","size":"768.35"},{"price":"0.00015623","size":"0"},{"price":"0.00015619","size":"3145.04"},{"price":"0.00015540","size":"0"},{"price":"0.00015515","size":"5478.09"}],"sequence":18307906,"timestamp":"2021-04-17T16:39:02.625Z","symbol":"OMGBTC"}}
1618677542.664586: {"jsonrpc":"2.0","method":"updateOrderbook","params":{"ask":[],"bid":[],"sequence":9316193,"timestamp":"2021-04-17T16:39:02.593Z","symbol":"XLMETH"}}
1618677542.758883: {"jsonrpc":"2.0","method":"updateOrderbook","params":{"ask":[{"price":"0.00015807","size":"42.78"},{"price":"0.00015814","size":"0"},{"price":"0.00015865","size":"0"},{"price":"0.00015875","size":"2128.07"}],"bid":[{"price":"0.00015768","size":"0"},{"price":"0.00015766","size":"9.55"},{"price":"0.00015759","size":"246.65"},{"price":"0.00015757","size":"189.73"}],"sequence":18307907,"timestamp":"2021-04-17T16:39:02.661Z","symbol":"OMGBTC"}}
1618677542.7592478: {"jsonrpc":"2.0","method":"updateOrderbook","params":{"ask":[],"bid":[{"price":"4.54005","size":"0"},{"price":"4.53917","size":"902.75"},{"price":"4.53302","size":"0"},{"price":"4.53059","size":"1196.81"},{"price":"4.52320","size":"0"},{"price":"4.52118","size":"1626.22"},{"price":"4.51644","size":"0"},{"price":"4.51537","size":"2203.89"},{"price":"4.49385","size":"0"},{"price":"4.49178","size":"4091.22"},{"price":"4.48176","size":"0"},{"price":"4.47916","size":"1661.53"}],"sequence":7132870,"timestamp":"2021-04-17T16:39:02.672Z","symbol":"DODOUSD"}}
1618677542.764082: {"jsonrpc":"2.0","method":"updateOrderbook","params":{"ask":[],"bid":[{"price":"0.00007487","size":"0"},{"price":"0.00007484","size":"1736.34"}],"sequence":5856099,"timestamp":"2021-04-17T16:39:02.678Z","symbol":"DODOBTC"}}
1618677542.768354: {"jsonrpc":"2.0","method":"updateOrderbook","params":{"ask":[],"bid":[{"price":"0.00025402","size":"0"},{"price":"0.00025355","size":"3000.0"}],"sequence":9316194,"timestamp":"2021-04-17T16:39:02.670Z","symbol":"XLMETH"}}
1618677542.8492632: {"jsonrpc":"2.0","method":"updateOrderbook","params":{"ask":[{"price":"0.00015953","size":"4402.08"},{"price":"0.00015968","size":"2625.22"},{"price":"0.00015990","size":"5617.94"},{"price":"0.00016015","size":"0"}],"bid":[{"price":"0.00015765","size":"0"},{"price":"0.00015763","size":"67.05"},{"price":"0.00015759","size":"0"},{"price":"0.00015757","size":"436.38"}],"sequence":18307908,"timestamp":"2021-04-17T16:39:02.822Z","symbol":"OMGBTC"}}
1618677542.8841212: {"jsonrpc":"2.0","method":"updateOrderbook","params":{"ask":[],"bid":[{"price":"0.00025402","size":"3000.0"},{"price":"0.00025355","size":"0"}],"sequence":9316195,"timestamp":"2021-04-17T16:39:02.728Z","symbol":"XLMETH"}}
