1639350346.467103: {"jsonrpc":"2.0","method":"channelMessage","params":{"channel":"lightning_board_snapshot_XLM_JPY","message":{"mid_price":31.53,"bids":[{"price":31.49,"size":3979.0},{"price":31.485,"size":2854.18},{"price":31.468,"size":3736.0},{"price":31.456,"size":11880.0},{"price":31.428,"size":8000.0},{"price":31.421,"size":967.9},{"price":31.406,"size":29746.0},{"price":31.4,"size":5.095541},{"price":31.39,"size":905.6},{"price":31.337,"size":8000.0},{"price":31.309,"size":295826.89},{"price":31.3,"size":5.111821},{"price":31.256,"size":749.85},{"price":31.2,"size":5.128205},{"price":31.123,"size":192.79},{"price":31.117,"size":90.7},{"price":31.1,"size":5.144694},{"price":31.098,"size":120.9},{"price":31.068,"size":123727.0},{"price":31.045,"size":10.0},{"price":31.02,"size":59219.0},{"price":31.0,"size":31497.5846143},{"price":30.973,"size":108.5},{"price":30.9,"size":30.0},{"price":30.841,"size":107.1},{"price":30.8,"size":4040.0},{"price":30.776,"size":29819.0},{"price":30.7,"size":20.0},{"price":30.623,"size":113.2},{"price":30.622,"size":30308.0},{"price":30.61,"size":300.0},{"price":30.6,"size":40.0},{"price":30.526,"size":113.4},{"price":30.502,"size":116.3},{"price":30.5,"size":20610.425295},{"price":30.4,"size":40.0},{"price":30.395,"size":197.41},{"price":30.3,"size":20.0},{"price":30.297,"size":115.8},{"price":30.266,"size":0.7},{"price":30.2,"size":65.99337},{"price":30.145,"size":31034.0},{"price":30.1,"size":20.0},{"price":30.096,"size":0.7},{"price":30.015,"size":200.0},{"price":30.01,"size":2002.0},{"price":30.0,"size":3179.5263666},{"price":29.911,"size":1.0},{"price":29.9,"size":5020.0},{"price":29.888,"size":1000.0},{"price":29.8,"size":11030.0},{"price":29.79,"size":14358.2410204},{"price":29.74,"size":300.0},{"price":29.7,"size":41.838},{"price":29.6,"size":30.0},{"price":29.548,"size":200.0},{"price":29.5,"size":31075.6279661},{"price":29.4,"size":21.9588},{"price":29.301,"size":10.0},{"price":29.3,"size":7027.04},{"price":29.215,"size":100.0},{"price":29.2,"size":10.0},{"price":29.11,"size":8.0},{"price":29.1,"size":5958.5082168},{"price":29.038,"size":206.63},{"price":29.03,"size":550.0},{"price":29.01,"size":2000.0},{"price":29.008,"size":1.1095801},{"price":29.0,"size":21688.199987},{"price":28.999,"size":0.73},{"price":28.98,"size":30.0},{"price":28.9,"size":10.0},{"price":28.896,"size":10.0},{"price":28.895,"size":2000.0},{"price":28.888,"size":1100.0},{"price":28.88,"size":150.0},{"price":28.8,"size":5032.208},{"price":28.75,"size":2000.0},{"price":28.7,"size":2310.0},{"price":28.66,"size":150.0},{"price":28.624,"size":69.903},{"price":28.61,"size":7790.0},{"price":28.6,"size":16220.0},{"price":28.55,"size":5000.0},{"price":28.506,"size":29000.0},{"price":28.5,"size":15764.3365},{"price":28.484,"size":2000.0},{"price":28.48,"size":1000.0},{"price":28.4,"size":10.0},{"price":28.342,"size":211.7},{"price":28.33,"size":150.0},{"price":28.3,"size":7127.0},{"price":28.22,"size":260.0},{"price":28.2,"size":5032.4677},{"price":28.167,"size":2000.0},{"price":28.14,"size":0.355366},{"price":28.111,"size":401.0},{"price":28.1,"size":20110.0},{"price":28.031,"size":0.76},{"price":28.017,"size":0.76},{"price":28.01,"size":2000.0},{"price":28.0,"size":95929.3687536},{"price":27.949,"size":200.0},{"price":27.9,"size":112.6018},{"price":27.895,"size":2000.0},{"price":27.888,"size":1100.0},{"price":27.88,"size":508.68},{"price":27.8,"size":10.0},{"price":27.743,"size":2000.0},{"price":27.734,"size":120.0},{"price":27.66,"size":150.0},{"price":27.64,"size":40.0},{"price":27.6,"size":322.7388},{"price":27.5,"size":10657.0},{"price":27.407,"size":500.0},{"price":27.4,"size":1812.0},{"price":27.33,"size":150.0},{"price":27.3,"size":5092.8788},{"price":27.272,"size":1.098},{"price":27.2,"size":10.0},{"price":27.167,"size":2000.0},{"price":27.111,"size":300.0},{"price":27.11,"size":1000.0},{"price":27.1,"size":39854.2804428},{"price":27.01,"size":2000.0},{"price":27.0,"size":53444.0469},{"price":26.905,"size":400.0},{"price":26.9,"size":900.0},{"price":26.895,"size":2000.0},{"price":26.888,"size":100.0},{"price":26.88,"size":150.0},{"price":26.831,"size":1000.0},{"price":26.8,"size":1500.0},{"price":26.752,"size":50.0},{"price":26.7,"size":1646.1682},{"price":26.666,"size":10000.0},{"price":26.66,"size":150.0},{"price":26.6,"size":100.0},{"price":26.588,"size":3000.0},{"price":26.568,"size":100.0},{"price":26.5,"size":64982.490566},{"price":26.494,"size":177.2597},{"price":26.42,"size":800.0},{"price":26.4,"size":403.3178},{"price":26.33,"size":150.0},{"price":26.31,"size":100.0},{"price":26.3,"size":3100.0},{"price":26.262,"size":750.0},{"price":26.167,"size":1000.0},{"price":26.111,"size":300.0},{"price":26.11,"size":1000.0},{"price":26.1,"size":20013.4709},{"price":26.062,"size":76.74},{"price":26.0,"size":54460.2769229},{"price":25.9,"size":100.0},{"price":25.88,"size":300.0},{"price":25.841,"size":773.0},{"price":25.8,"size":463.6275},{"price":25.776,"size":0.83},{"price":25.678,"size":7.0},{"price":25.66,"size":150.0},{"price":25.6,"size":100.0},{"price":25.588,"size":2000.0},{"price":25.56,"size":400.0},{"price":25.555,"size":391.0},{"price":25.506,"size":1000.0},{"price":25.5,"size":6423.8878},{"price":25.4,"size":5000.0},{"price":25.33,"size":150.0},{"price":25.3,"size":5200.0},{"price":25.26,"size":1500.0},{"price":25.25,"size":40.0},{"price":25.222,"size":410.0},{"price":25.2,"size":13.952},{"price":25.19,"size":25.0},{"price":25.111,"size":300.0},{"price":25.11,"size":2000.0},{"price":25.1,"size":20100.0},{"price":25.08,"size":400.0},{"price":25.011,"size":2000.0},{"price":25.01,"size":3433.0},{"price":25.0,"size":128164.3},{"price":24.9,"size":214.1201},{"price":24.891,"size":80.389},{"price":24.8,"size":2500.0},{"price":24.793,"size":1.208},{"price":24.745,"size":2000.0},{"price":24.743,"size":2000.0},{"price":24.667,"size":30.0},{"price":24.666,"size":10150.0},{"price":24.6,"size":14.2923},{"price":24.5,"size":22820.0},{"price":24.456,"size":50.0},{"price":24.3,"size":19119.4687},{"price":24.1,"size":1411.5},{"price":24.0,"size":77501.0},{"price":23.814,"size":2000.0},{"price":23.666,"size":10000.0},{"price":23.6,"size":4300.0},{"price":23.5,"size":3020.0},{"price":23.45,"size":100.0},{"price":23.4,"size":522.0},{"price":23.3,"size":3000.0},{"price":23.257,"size":859.0},{"price":23.25,"size":5000.0},{"price":23.2,"size":100.0},{"price":23.02,"size":3000.0},{"price":23.0,"size":66449.0},{"price":22.666,"size":10000.0},{"price":22.5,"size":8020.0},{"price":22.3,"size":3000.0},{"price":22.05,"size":5000.0},{"price":22.0,"size":3640.090909},{"price":21.828,"size":300.0},{"price":21.655,"size":500.0},{"price":21.644,"size":92.447},{"price":21.57,"size":5000.0},{"price":21.5,"size":70.0},{"price":21.49,"size":301.0},{"price":21.3,"size":3000.0},{"price":21.0,"size":7870.0},{"price":20.98,"size":3000.0},{"price":20.568,"size":200.0},{"price":20.5,"size":20.0},{"price":20.44,"size":0.1},{"price":20.3,"size":3000.0},{"price":20.0,"size":30616.1},{"price":19.895,"size":55.0},{"price":19.57,"size":5000.0},{"price":19.0,"size":1711.0},{"price":18.5,"size":20.0},{"price":18.3,"size":6000.0},{"price":18.0,"size":10240.0},{"price":17.58,"size":5000.0},{"price":17.1,"size":1000.0},{"price":17.0,"size":5010.0},{"price":16.8,"size":30.0},{"price":16.0,"size":1110.0},{"price":15.0,"size":200.0}],"asks":[{"price":31.57,"size":750.95},{"price":31.579,"size":975.2},{"price":31.583,"size":3783.0},{"price":31.592,"size":11880.0},{"price":31.594,"size":3736.0},{"price":31.615,"size":8000.0},{"price":31.623,"size":607.9},{"price":31.628,"size":29746.0},{"price":31.715,"size":8000.0},{"price":31.728,"size":717.1},{"price":31.73,"size":303740.0},{"price":31.746,"size":119.01},{"price":31.85,"size":137.0},{"price":31.886,"size":92.83},{"price":31.9,"size":30000.0},{"price":31.916,"size":119.43},{"price":31.918,"size":73495.0},{"price":31.947,"size":187.82},{"price":31.948,"size":31.3011112},{"price":31.95,"size":20000.0},{"price":32.0,"size":1397.0},{"price":32.036,"size":122.0},{"price":32.1,"size":5.140187},{"price":32.125,"size":8.0},{"price":32.193,"size":118.9},{"price":32.2,"size":5.124224},{"price":32.215,"size":98.5},{"price":32.25,"size":20008.0},{"price":32.282,"size":619.538},{"price":32.3,"size":4005.10836},{"price":32.375,"size":8.0},{"price":32.4,"size":379.092593},{"price":32.414,"size":100.0},{"price":32.47,"size":200.0},{"price":32.5,"size":1323.9384624},{"price":32.571,"size":118.53},{"price":32.6,"size":304.04908},{"price":32.625,"size":8.0},{"price":32.7,"size":4.036698},{"price":32.71,"size":12488.0},{"price":32.75,"size":8.0},{"price":32.8,"size":4.024391},{"price":32.822,"size":100.0},{"price":32.875,"size":8.0},{"price":32.9,"size":4.012159},{"price":32.98,"size":149.61},{"price":33.0,"size":9178.468362},{"price":33.015,"size":5000.0},{"price":33.1,"size":14.108762},{"price":33.125,"size":8.0},{"price":33.2,"size":2304.096386},{"price":33.25,"size":8.0},{"price":33.253,"size":150.0},{"price":33.3,"size":6104.084085},{"price":33.33,"size":3994.0},{"price":33.37,"size":10000.0},{"price":33.375,"size":8.0},{"price":33.4,"size":4.071857},{"price":33.5,"size":1811.059702},{"price":33.545,"size":29.8105828},{"price":33.6,"size":4.04762},{"price":33.625,"size":8.0},{"price":33.7,"size":4.035609},{"price":33.75,"size":8.0},{"price":33.79,"size":0.2071618},{"price":33.8,"size":4.023669},{"price":33.875,"size":8.0},{"price":33.9,"size":13204.0118},{"price":33.968,"size":98.5},{"price":34.0,"size":3772.5},{"price":34.1,"size":1.026393},{"price":34.125,"size":8.0},{"price":34.2,"size":1.023392},{"price":34.25,"size":8.0},{"price":34.26,"size":400.0},{"price":34.3,"size":1.020409},{"price":34.375,"size":8.0},{"price":34.4,"size":74696.017442},{"price":34.5,"size":24697.014493},{"price":34.6,"size":1.011561},{"price":34.625,"size":8.0},{"price":34.7,"size":1.008646},{"price":34.75,"size":8.0},{"price":34.8,"size":1.005748},{"price":34.807,"size":100.0},{"price":34.875,"size":8.0},{"price":34.88,"size":49.87},{"price":34.9,"size":17983.002866},{"price":35.0,"size":54349.1174446},{"price":35.026,"size":242.9005511},{"price":35.094,"size":1555.0},{"price":35.1,"size":1.025642},{"price":35.111,"size":1000.0},{"price":35.125,"size":8.0},{"price":35.18,"size":6.283},{"price":35.2,"size":16.022728},{"price":35.222,"size":28.3910313},{"price":35.25,"size":8.0},{"price":35.3,"size":1.019831},{"price":35.312,"size":3271.4},{"price":35.333,"size":1000.0},{"price":35.375,"size":8.0},{"price":35.4,"size":1.01695},{"price":35.5,"size":15329.014085},{"price":35.53,"size":149.64},{"price":35.6,"size":1.011236},{"price":35.625,"size":8.0},{"price":35.7,"size":1.008404},{"price":35.75,"size":8.0},{"price":35.8,"size":1.005587},{"price":35.821,"size":9982.0},{"price":35.875,"size":8.0},{"price":35.888,"size":992.0},{"price":35.9,"size":501.002786},{"price":36.0,"size":18856.5},{"price":36.01,"size":126570.0},{"price":36.125,"size":8.0},{"price":36.2,"size":1000.0},{"price":36.25,"size":8.0},{"price":36.3,"size":1.096},{"price":36.375,"size":8.0},{"price":36.5,"size":1878.0},{"price":36.59,"size":190.0},{"price":36.625,"size":8.0},{"price":36.711,"size":284.58},{"price":36.75,"size":8.0},{"price":36.875,"size":8.0},{"price":36.92,"size":500.0},{"price":36.984,"size":27.0390774},{"price":37.0,"size":2479.4897541},{"price":37.1,"size":9950.0},{"price":37.125,"size":8.0},{"price":37.2,"size":49.0},{"price":37.25,"size":8.0},{"price":37.301,"size":9.85},{"price":37.314,"size":75.0296917},{"price":37.375,"size":8.0},{"price":37.388,"size":98.5},{"price":37.4,"size":12000.0},{"price":37.5,"size":11899.0},{"price":37.6,"size":4000.0},{"price":37.625,"size":8.0},{"price":37.75,"size":8.0},{"price":37.8,"size":1000.0},{"price":37.856,"size":60.786},{"price":37.875,"size":8.0},{"price":38.0,"size":5060.560063},{"price":38.1,"size":8223.7864549},{"price":38.125,"size":8.0},{"price":38.2,"size":8223.7864549},{"price":38.25,"size":8.0},{"price":38.28,"size":1244.0},{"price":38.3,"size":8223.7864549},{"price":38.375,"size":8.0},{"price":38.4,"size":17756.31544},{"price":38.41,"size":5.0},{"price":38.5,"size":29713.7864549},{"price":38.6,"size":8223.7864549},{"price":38.625,"size":8.0},{"price":38.7,"size":8223.7864549},{"price":38.75,"size":8.0},{"price":38.8,"size":12884.9279845},{"price":38.833,"size":25.7515022},{"price":38.875,"size":8.0},{"price":38.9,"size":8223.7864549},{"price":39.0,"size":35349.0023061},{"price":39.05,"size":1076.76},{"price":39.1,"size":8223.7864549},{"price":39.12,"size":500.0},{"price":39.125,"size":8.0},{"price":39.14,"size":500.0},{"price":39.17,"size":500.0},{"price":39.2,"size":8223.7864549},{"price":39.22,"size":500.0},{"price":39.24,"size":500.0},{"price":39.25,"size":8.0},{"price":39.27,"size":500.0},{"price":39.3,"size":7762.1354514},{"price":39.32,"size":500.0},{"price":39.34,"size":500.0},{"price":39.37,"size":500.0},{"price":39.375,"size":8.0},{"price":39.41,"size":5.0},{"price":39.42,"size":500.0},{"price":39.44,"size":500.0},{"price":39.45,"size":100.0},{"price":39.47,"size":500.0},{"price":39.49,"size":300.0},{"price":39.5,"size":13910.0},{"price":39.52,"size":500.0},{"price":39.53,"size":500.0},{"price":39.54,"size":500.0},{"price":39.55,"size":500.0},{"price":39.555,"size":779.6061182},{"price":39.57,"size":500.0},{"price":39.6,"size":500.0},{"price":39.62,"size":500.0},{"price":39.625,"size":8.0},{"price":39.63,"size":500.0},{"price":39.64,"size":500.0},{"price":39.65,"size":500.0},{"price":39.666,"size":500.0},{"price":39.67,"size":500.0},{"price":39.7,"size":600.0},{"price":39.72,"size":500.0},{"price":39.73,"size":500.0},{"price":39.74,"size":500.0},{"price":39.75,"size":508.0},{"price":39.77,"size":500.0},{"price":39.777,"size":500.0},{"price":39.8,"size":9901.628345},{"price":39.82,"size":500.0},{"price":39.83,"size":500.0},{"price":39.84,"size":500.0},{"price":39.85,"size":500.0},{"price":39.87,"size":500.0},{"price":39.875,"size":8.0},{"price":39.888,"size":500.0},{"price":39.9,"size":500.0},{"price":39.92,"size":500.0},{"price":39.93,"size":501.0},{"price":39.94,"size":500.0},{"price":39.95,"size":500.0},{"price":39.97,"size":500.0},{"price":39.989,"size":1995.0},{"price":39.996,"size":1990.0},{"price":39.999,"size":500.0},{"price":40.0,"size":86596.9346262},{"price":40.039,"size":100.0},{"price":40.05,"size":500.0},{"price":40.1,"size":510.0},{"price":40.125,"size":8.0},{"price":40.15,"size":500.0},{"price":40.2,"size":600.0},{"price":40.25,"size":508.0},{"price":40.253,"size":0.947035},{"price":40.3,"size":500.0},{"price":40.32,"size":35.0},{"price":40.35,"size":500.0},{"price":40.375,"size":8.0},{"price":40.4,"size":500.0},{"price":40.45,"size":500.0},{"price":40.5,"size":1908.0},{"price":40.55,"size":500.0},{"price":40.6,"size":500.0},{"price":40.625,"size":8.0},{"price":40.65,"size":500.0},{"price":40.7,"size":10500.0},{"price":40.72,"size":4696.5529785},{"price":40.75,"size":508.0},{"price":40.774,"size":24.5252402},{"price":40.8,"size":500.0},{"price":40.83,"size":98.5},{"price":40.85,"size":500.0},{"price":40.875,"size":8.0},{"price":40.9,"size":500.0},{"price":40.95,"size":500.0},{"price":41.0,"size":4642.2},{"price":41.1,"size":1036.935},{"price":41.125,"size":8.0},{"price":41.15,"size":50300.0},{"price":41.2,"size":151.019418},{"price":41.25,"size":8.0},{"price":41.3,"size":1.01695},{"price":41.375,"size":8.0},{"price":41.4,"size":20001.014493},{"price":41.5,"size":42091.832049},{"price":41.6,"size":21.009616},{"price":41.622,"size":22000.0},{"price":41.625,"size":8.0},{"price":41.666,"size":2000.0},{"price":41.7,"size":1.007195},{"price":41.75,"size":8.0},{"price":41.79,"size":15.0},{"price":41.8,"size":1.004785},{"price":41.833,"size":200.0},{"price":41.875,"size":8.0},{"price":41.88,"size":1398.0},{"price":41.9,"size":1.002387},{"price":42.0,"size":15853.5},{"price":42.1,"size":1.021378},{"price":42.125,"size":8.0},{"price":42.18,"size":300.0},{"price":42.2,"size":101.018958},{"price":42.25,"size":8.0},{"price":42.3,"size":1.016549},{"price":42.31,"size":40.0},{"price":42.375,"size":8.0},{"price":42.4,"size":1.014151},{"price":42.485,"size":100.0},{"price":42.5,"size":5646.011765},{"price":42.6,"size":101.00939},{"price":42.625,"size":8.0},{"price":42.666,"size":2000.0},{"price":42.7,"size":1.007026},{"price":42.75,"size":8.0},{"price":42.8,"size":1001.004673},{"price":42.813,"size":23.3573716},{"price":42.875,"size":8.0},{"price":42.9,"size":612.002332}]}}}
1639350346.484192: {"jsonrpc":"2.0","method":"channelMessage","params":{"channel":"lightning_board_FX_BTC_JPY","message":{"mid_price":5864396.0,"bids":[{"price":5861467.0,"size":0.0},{"price":5862345.0,"size":0.0},{"price":5861070.0,"size":0.0},{"price":5857844.0,"size":0.0},{"price":5860717.0,"size":0.0},{"price":5860979.0,"size":0.0},{"price":5861081.0,"size":0.0},{"price":5861461.0,"size":0.0},{"price":5862717.0,"size":0.0},{"price":5862709.0,"size":0.1346},{"price":5862576.0,"size":0.02435637}],"asks":[{"price":5866308.0,"size":0.1894},{"price":5891606.0,"size":0.0},{"price":5867059.0,"size":0.02},{"price":5870434.0,"size":0.02913836},{"price":5867650.0,"size":0.02},{"price":5867934.0,"size":0.0}]}}}
1639350346.518423: {"jsonrpc":"2.0","method":"channelMessage","params":{"channel":"lightning_board_ETH_JPY","message":{"mid_price":471837.0,"bids":[{"price":471732.0,"size":0.0},{"price":471123.0,"size":0.0},{"price":471675.0,"size":0.064},{"price":471674.0,"size":0.0}],"asks":[{"price":472383.0,"size":0.864},{"price":472860.0,"size":0.0}]}}}
1639350346.5997682: {"jsonrpc":"2.0","method":"channelMessage","params":{"channel":"lightning_ticker_FX_BTC_JPY","message":{"product_code":"FX_BTC_JPY","state":"RUNNING","timestamp":"2021-12-12T23:05:46.4184903Z","tick_id":127091783,"best_bid":5863163.0,"best_ask":5865630.0,"best_bid_size":0.03,"best_ask_size":0.01,"total_bid_depth":231.902902190000,"total_ask_depth":294.528077830000,"market_bid_size":0.0,"market_ask_size":0.0,"ltp":5864791.0,"volume":4227.702096850000,"volume_by_product":4227.702096850000}}}
1639350346.6061592: {"jsonrpc":"2.0","method":"channelMessage","params":{"channel":"lightning_board_FX_BTC_JPY","message":{"mid_price":5864396.0,"bids":[{"price":5841212.0,"size":0.02},{"price":5863051.0,"size":0.01},{"price":5860729.0,"size":0.01}],"asks":[{"price":5868740.0,"size":0.0},{"price":5867047.0,"size":0.0},{"price":5867138.0,"size":0.0},{"price":5866570.0,"size":0.0},{"price":5866747.0,"size":0.0},{"price":5866314.0,"size":0.0}]}}}
1639350346.632055: {"jsonrpc":"2.0","method":"channelMessage","params":{"channel":"lightning_ticker_ETH_JPY","message":{"product_code":"ETH_JPY","state":"RUNNING","timestamp":"2021-12-12T23:05:46.5348626Z","tick_id":26934633,"best_bid":471675.0,"best_ask":472000.0,"best_bid_size":0.064,"best_ask_size":0.770000,"total_bid_depth":3320.357417900000,"total_ask_depth":4431.97557320,"market_bid_size":0.0,"market_ask_size":0.0,"ltp":471722.0,"volume":10833.320505500000,"volume_by_product":10833.320505500000}}}
1639350346.6396182: {"jsonrpc":"2.0","method":"channelMessage","params":{"channel":"lightning_board_ETH_JPY","message":{"mid_price":471837.0,"bids":[],"asks":[{"price":473945.0,"size":0.57}]}}}
1639350346.645725: {"jsonrpc":"2.0","method":"channelMessage","params":{"channel":"lightning_board_BTC_EUR","message":{"mid_price":44470.42,"bids":[],"asks":[{"price":44616.51,"size":0.13}]}}}
1639350346.72168: {"jsonrpc":"2.0","method":"channelMessage","params":{"channel":"lightning_board_FX_BTC_JPY","message":{"mid_price":5864396.0,"bids":[{"price":5862576.0,"size":0.04867766},{"price":5863103.0,"size":0.01},{"price":5859036.0,"size":0.05},{"price":5826806.0,"size":0.01},{"price":5862027.0,"size":0.1},{"price":5862385.0,"size":0.1348},{"price":5862420.0,"size":0.05}],"asks":[{"price":5866207.0,"size":0.02}]}}}
1639350346.752415: {"jsonrpc":"2.0","method":"channelMessage","params":{"channel":"lightning_ticker_XLM_JPY","message":{"product_code":"XLM_JPY","state":"RUNNING","timestamp":"2021-12-12T23:05:46.653508Z","tick_id":8300585,"best_bid":31.49,"best_ask":31.57,"best_bid_size":3979.0,"best_ask_size":750.95,"total_bid_depth":1852668.85493760,"total_ask_depth":2114360.197473400000,"market_bid_size":0.0,"market_ask_size":0.0,"ltp":31.471,"volume":1471420.073424000000,"volume_by_product":1471420.073424000000}}}
1639350346.756043: {"jsonrpc":"2.0","method":"channelMessage","params":{"channel":"lightning_board_XLM_JPY","message":{"mid_price":31.53,"bids":[{"price":31.485,"size":0.0}],"asks":[]}}}
1639350346.77483: {"jsonrpc":"2.0","method":"channelMessage","params":{"channel":"lightning_board_ETH_JPY","message":{"mid_price":471837.0,"bids":[{"price":471200.0,"size":0.0}],"asks":[]}}}
1639350346.83635: {"jsonrpc":"2.0","method":"channelMessage","params":{"channel":"lightning_board_FX_BTC_JPY","message":{"mid_price":5864396.0,"bids":[{"price":5862708.0,"size":0.0},{"price":5862709.0,"size":0.0},{"price":5862022.0,"size":0.12}],"asks":[{"price":5868731.0,"size":0.0},{"price":5866308.0,"size":0.0},{"price":5868097.0,"size":0.1},{"price":5951720.0,"size":0.0},{"price":5867199.0,"size":0.02},{"price":5867276.0,"size":0.05}]}}}
1639350346.876888: {"jsonrpc":"2.0","method":"channelMessage","params":{"channel":"lightning_board_XLM_JPY","message":{"mid_price":31.53,"bids":[{"price":31.491,"size":2403.2}],"asks":[]}}}
1639350346.946829: {"jsonrpc":"2.0","method":"channelMessage","params":{"channel":"lightning_board_FX_BTC_JPY","message":{"mid_price":5864396.0,"bids":[{"price":5828264.0,"size":0.06},{"price":5862713.0,"size":0.01},{"price":5859203.0,"size":0.1},{"price":5861663.0,"size":0.05},{"price":5855845.0,"size":0.0}],"asks":[{"price":5870238.0,"size":0.02933836},{"price":5868092.0,"size":0.12},{"price":7013445.0,"size":0.0},{"price":5869087.0,"size":0.05},{"price":5867058.0,"size":0.02},{"price":5866206.0,"size":0.1848},{"price":5892157.0,"size":0.0}]}}}
1639350346.992778: {"jsonrpc":"2.0","method":"channelMessage","params":{"channel":"lightning_board_snapshot_FX_BTC_JPY","message":{"mid_price":5864396.0,"bids":[{"price":5863163.0,"size":0.03},{"price":5863103.0,"size":0.01},{"price":5863051.0,"size":0.01},{"price":5863033.0,"size":0.02290718},{"price":5862820.0,"size":0.01},{"price":5862713.0,"size":0.01},{"price":5862576.0,"size":0.04867766},{"price":5862570.0,"size":0.02},{"price":5862567.0,"size":0.23172252},{"price":5862513.0,"size":0.03},{"price":5862420.0,"size":0.05},{"price":5862385.0,"size":0.1348},{"price":5862384.0,"size":0.04644039},{"price":5862344.0,"size":0.04},{"price":5862343.0,"size":0.2},{"price":5862333.0,"size":0.0493381},{"price":5862266.0,"size":0.02},{"price":5862041.0,"size":0.2},{"price":5862040.0,"size":0.2},{"price":5862027.0,"size":0.1},{"price":5862022.0,"size":0.12},{"price":5861761.0,"size":0.05},{"price":5861748.0,"size":0.011},{"price":5861663.0,"size":0.05},{"price":5861560.0,"size":0.05},{"price":5861519.0,"size":0.05},{"price":5861411.0,"size":0.2},{"price":5861152.0,"size":0.05},{"price":5860887.0,"size":0.04},{"price":5860750.0,"size":0.02},{"price":5860729.0,"size":0.01},{"price":5860579.0,"size":0.01},{"price":5860575.0,"size":0.1},{"price":5860148.0,"size":0.01},{"price":5859959.0,"size":0.01},{"price":5859362.0,"size":0.02},{"price":5859268.0,"size":0.03},{"price":5859264.0,"size":0.02},{"price":5859239.0,"size":0.1},{"price":5859203.0,"size":0.1},{"price":5859046.0,"size":0.255},{"price":5859036.0,"size":0.05},{"price":5859002.0,"size":0.032},{"price":5858532.0,"size":0.01},{"price":5858034.0,"size":0.02675347},{"price":5858025.0,"size":0.01},{"price":5858020.0,"size":0.02675395},{"price":5858010.0,"size":0.01},{"price":5857995.0,"size":0.02675389},{"price":5857984.0,"size":0.2},{"price":5857861.0,"size":0.109},{"price":5857614.0,"size":0.1},{"price":5857564.0,"size":0.2},{"price":5857563.0,"size":0.02},{"price":5857263.0,"size":0.026},{"price":5856882.0,"size":0.029},{"price":5856251.0,"size":0.01},{"price":5856211.0,"size":0.1},{"price":5855864.0,"size":0.0267539},{"price":5855851.0,"size":0.02675395},{"price":5855808.0,"size":0.2},{"price":5855805.0,"size":0.2},{"price":5855577.0,"size":0.01},{"price":5855148.0,"size":0.1},{"price":5855145.0,"size":0.1},{"price":5854446.0,"size":0.09950742},{"price":5854281.0,"size":0.04},{"price":5854070.0,"size":0.14},{"price":5853722.0,"size":0.058},{"price":5853607.0,"size":0.1},{"price":5853534.0,"size":0.47773664},{"price":5853431.0,"size":0.04},{"price":5853321.0,"size":0.025},{"price":5853250.0,"size":0.04},{"price":5853170.0,"size":0.02},{"price":5853121.0,"size":0.08},{"price":5852997.0,"size":0.01},{"price":5852947.0,"size":0.5},{"price":5852917.0,"size":0.01},{"price":5852877.0,"size":0.04},{"price":5852790.0,"size":0.04},{"price":5852760.0,"size":0.252},{"price":5852645.0,"size":0.05},{"price":5852632.0,"size":0.01},{"price":5852338.0,"size":0.01},{"price":5852291.0,"size":0.01},{"price":5852203.0,"size":0.477},{"price":5851958.0,"size":0.03},{"price":5851571.0,"size":0.01},{"price":5851295.0,"size":0.1},{"price":5851233.0,"size":0.2},{"price":5850774.0,"size":0.05},{"price":5850751.0,"size":0.292},{"price":5850693.0,"size":0.04},{"price":5850673.0,"size":0.01},{"price":5850492.0,"size":0.3},{"price":5850016.0,"size":0.02},{"price":5849903.0,"size":0.02},{"price":5848716.0,"size":0.01},{"price":5848456.0,"size":0.02},{"price":5848392.0,"size":0.01},{"price":5848347.0,"size":0.01},{"price":5847901.0,"size":0.02},{"price":5847844.0,"size":0.05},{"price":5847732.0,"size":0.01},{"price":5847571.0,"size":0.01},{"price":5847303.0,"size":0.12},{"price":5846500.0,"size":0.02},{"price":5846007.0,"size":0.1},{"price":5845785.0,"size":0.02},{"price":5845541.0,"size":0.12},{"price":5845407.0,"size":0.01},{"price":5845403.0,"size":0.02},{"price":5845367.0,"size":0.02},{"price":5845230.0,"size":0.02},{"price":5845000.0,"size":0.05},{"price":5844928.0,"size":0.02},{"price":5844914.0,"size":0.05},{"price":5843860.0,"size":0.04},{"price":5843576.0,"size":0.029},{"price":5843040.0,"size":0.05},{"price":5841212.0,"size":0.02},{"price":5841009.0,"size":0.03},{"price":5840987.0,"size":0.1},{"price":5840909.0,"size":0.02},{"price":5840806.0,"size":0.01},{"price":5840794.0,"size":0.02},{"price":5840706.0,"size":1.183},{"price":5840129.0,"size":0.01},{"price":5838420.0,"size":0.01},{"price":5837453.0,"size":0.029},{"price":5837200.0,"size":0.01},{"price":5836317.0,"size":0.04},{"price":5835949.0,"size":0.04},{"price":5834878.0,"size":0.04},{"price":5833832.0,"size":0.01},{"price":5833806.0,"size":0.01},{"price":5833715.0,"size":0.01},{"price":5832750.0,"size":0.01},{"price":5832211.0,"size":0.08},{"price":5831082.0,"size":0.01},{"price":5830423.0,"size":0.02},{"price":5830300.0,"size":0.02},{"price":5828264.0,"size":0.06},{"price":5828190.0,"size":0.01},{"price":5827582.0,"size":0.08},{"price":5827500.0,"size":0.01},{"price":5827441.0,"size":0.02},{"price":5826882.0,"size":0.029},{"price":5826806.0,"size":0.01},{"price":5826000.0,"size":0.05},{"price":5825845.0,"size":0.03},{"price":5825000.0,"size":0.01},{"price":5824694.0,"size":0.01},{"price":5822172.0,"size":6.043},{"price":5821506.0,"size":0.04},{"price":5820555.0,"size":0.0125},{"price":5820000.0,"size":0.021},{"price":5818271.0,"size":0.08},{"price":5817493.0,"size":0.01},{"price":5817263.0,"size":0.026},{"price":5816415.0,"size":0.05},{"price":5815888.0,"size":0.015},{"price":5815000.0,"size":0.02},{"price":5813000.0,"size":0.01},{"price":5812404.0,"size":0.1},{"price":5812383.0,"size":0.1},{"price":5812099.0,"size":0.01},{"price":5810555.0,"size":0.01},{"price":5810115.0,"size":0.01},{"price":5810000.0,"size":0.01},{"price":5809775.0,"size":0.55},{"price":5808888.0,"size":0.021},{"price":5808532.0,"size":0.01},{"price":5808251.0,"size":1.5},{"price":5807825.0,"size":0.01},{"price":5806643.0,"size":0.01},{"price":5806493.0,"size":0.01},{"price":5805600.0,"size":0.03573532},{"price":5805555.0,"size":0.0125},{"price":5805000.0,"size":0.06},{"price":5804817.0,"size":0.02},{"price":5803666.0,"size":0.01},{"price":5802985.0,"size":0.01},{"price":5802094.0,"size":0.01},{"price":5801000.0,"size":0.2},{"price":5800577.0,"size":0.02},{"price":5800541.0,"size":0.2},{"price":5800134.0,"size":0.02},{"price":5800000.0,"size":0.58},{"price":5799987.0,"size":0.02},{"price":5797000.0,"size":0.03},{"price":5795600.0,"size":0.05},{"price":5794167.0,"size":0.01},{"price":5791786.0,"size":0.01},{"price":5790441.0,"size":0.02},{"price":5790000.0,"size":0.01},{"price":5789008.0,"size":0.1},{"price":5789000.0,"size":0.30334734},{"price":5788910.0,"size":3.597},{"price":5788888.0,"size":0.1},{"price":5787938.0,"size":0.01},{"price":5787489.0,"size":0.04},{"price":5787383.0,"size":0.1},{"price":5786910.0,"size":0.2},{"price":5786316.0,"size":0.01},{"price":5786173.0,"size":0.08},{"price":5785600.0,"size":0.05},{"price":5785000.0,"size":0.01},{"price":5782552.0,"size":0.03},{"price":5781103.0,"size":0.01},{"price":5781082.0,"size":0.01},{"price":5780088.0,"size":0.01},{"price":5780000.0,"size":0.62},{"price":5778256.0,"size":0.08},{"price":5778000.0,"size":0.01},{"price":5777911.0,"size":0.012},{"price":5775600.0,"size":0.05},{"price":5772041.0,"size":0.01},{"price":5770790.0,"size":0.1},{"price":5770474.0,"size":0.01},{"price":5770358.0,"size":1.0},{"price":5770000.0,"size":0.2},{"price":5766882.0,"size":0.058},{"price":5765600.0,"size":0.05},{"price":5765062.0,"size":0.01},{"price":5763400.0,"size":0.01},{"price":5762832.0,"size":0.01},{"price":5762383.0,"size":0.1},{"price":5761555.0,"size":0.02},{"price":5761000.0,"size":0.2},{"price":5760807.0,"size":0.15},{"price":5760000.0,"size":0.12},{"price":5759658.0,"size":0.01},{"price":5758888.0,"size":0.301},{"price":5758715.0,"size":0.01},{"price":5758000.0,"size":0.03},{"price":5757263.0,"size":0.052},{"price":5755600.0,"size":0.05},{"price":5755555.0,"size":0.025},{"price":5753726.0,"size":0.01},{"price":5752455.0,"size":3.589},{"price":5752323.0,"size":0.01},{"price":5752321.0,"size":0.1},{"price":5751800.0,"size":0.01},{"price":5751643.0,"size":0.01},{"price":5750000.0,"size":0.32},{"price":5747829.0,"size":0.5},{"price":5747500.0,"size":0.1},{"price":5747499.0,"size":0.01},{"price":5745600.0,"size":0.05},{"price":5744759.0,"size":0.5},{"price":5743022.0,"size":0.01},{"price":5741499.0,"size":0.01},{"price":5740000.0,"size":0.52},{"price":5737499.0,"size":0.01},{"price":5735600.0,"size":0.05},{"price":5732750.0,"size":0.025},{"price":5731731.0,"size":0.01},{"price":5731653.0,"size":0.5},{"price":5731499.0,"size":0.01},{"price":5731232.0,"size":0.05},{"price":5728000.0,"size":1.0},{"price":5727499.0,"size":0.01},{"price":5725600.0,"size":0.05},{"price":5725441.0,"size":0.04},{"price":5725150.0,"size":0.01},{"price":5725101.0,"size":0.1},{"price":5725000.0,"size":0.04},{"price":5724000.0,"size":0.03},{"price":5723654.0,"size":0.012},{"price":5721499.0,"size":0.01},{"price":5721000.0,"size":0.2},{"price":5720009.0,"size":0.01},{"price":5720000.0,"size":0.02},{"price":5715600.0,"size":0.05},{"price":5715000.0,"size":0.03},{"price":5711653.0,"size":0.5},{"price":5708532.0,"size":0.02},{"price":5708450.0,"size":1.191},{"price":5705600.0,"size":0.05},{"price":5705555.0,"size":0.025},{"price":5704543.0,"size":2.341},{"price":5702883.0,"size":0.01},{"price":5700000.0,"size":0.985},{"price":5693739.0,"size":0.1},{"price":5692856.0,"size":0.01},{"price":5690585.0,"size":0.01},{"price":5690000.0,"size":0.06},{"price":5686666.0,"size":0.03},{"price":5686049.0,"size":0.1},{"price":5683737.0,"size":0.01},{"price":5682000.0,"size":0.2},{"price":5681000.0,"size":0.2},{"price":5680800.0,"size":0.01},{"price":5680000.0,"size":1.05},{"price":5679812.0,"size":0.01},{"price":5679051.0,"size":0.1},{"price":5678504.0,"size":0.5},{"price":5678000.0,"size":0.01}],"asks":[{"price":5865630.0,"size":0.01},{"price":5866206.0,"size":0.1848},{"price":5866207.0,"size":0.02},{"price":5866944.0,"size":0.2},{"price":5866945.0,"size":0.02},{"price":5866966.0,"size":0.2},{"price":5866967.0,"size":0.2},{"price":5866992.0,"size":0.01},{"price":5867011.0,"size":0.01},{"price":5867048.0,"size":0.01},{"price":5867058.0,"size":0.02},{"price":5867059.0,"size":0.02},{"price":5867069.0,"size":0.011},{"price":5867156.0,"size":0.05},{"price":5867199.0,"size":0.02},{"price":5867200.0,"size":0.01},{"price":5867276.0,"size":0.05},{"price":5867345.0,"size":0.01},{"price":5867472.0,"size":0.04964016},{"price":5867550.0,"size":0.01},{"price":5867589.0,"size":0.05},{"price":5867650.0,"size":0.02},{"price":5867668.0,"size":0.011},{"price":5867858.0,"size":0.05},{"price":5868092.0,"size":0.12},{"price":5868097.0,"size":0.1},{"price":5868951.0,"size":0.1},{"price":5868974.0,"size":0.08558488},{"price":5869087.0,"size":0.05},{"price":5869110.0,"size":0.01},{"price":5869149.0,"size":0.02},{"price":5869325.0,"size":0.255},{"price":5869591.0,"size":0.025},{"price":5869665.0,"size":0.02},{"price":5869879.0,"size":0.02913836},{"price":5869989.0,"size":0.06},{"price":5869997.0,"size":0.01},{"price":5870031.0,"size":0.5},{"price":5870238.0,"size":0.02933836},{"price":5870434.0,"size":0.02913836},{"price":5870648.0,"size":0.1},{"price":5870739.0,"size":0.01},{"price":5871849.0,"size":0.477},{"price":5872491.0,"size":0.02},{"price":5872509.0,"size":0.1},{"price":5872800.0,"size":0.01},{"price":5873075.0,"size":0.04},{"price":5873654.0,"size":0.01},{"price":5874100.0,"size":0.01},{"price":5874888.0,"size":0.01},{"price":5874951.0,"size":0.04},{"price":5874972.0,"size":0.1},{"price":5875000.0,"size":0.01},{"price":5875180.0,"size":0.05},{"price":5875484.0,"size":0.01},{"price":5875845.0,"size":0.058},{"price":5876000.0,"size":0.11},{"price":5876337.0,"size":0.1},{"price":5876450.0,"size":0.01},{"price":5876629.0,"size":0.133},{"price":5876840.0,"size":0.05},{"price":5877263.0,"size":0.02},{"price":5878113.0,"size":0.05},{"price":5878230.0,"size":0.02},{"price":5879980.0,"size":0.0125},{"price":5880000.0,"size":0.1},{"price":5880200.0,"size":0.02},{"price":5880558.0,"size":0.02675347},{"price":5880572.0,"size":0.02675395},{"price":5880582.0,"size":0.01},{"price":5880615.0,"size":0.01},{"price":5880630.0,"size":0.02675389},{"price":5880670.0,"size":0.03},{"price":5880700.0,"size":0.02},{"price":5880738.0,"size":0.04},{"price":5880770.0,"size":0.02},{"price":5880973.0,"size":1.183},{"price":5881046.0,"size":0.05},{"price":5881250.0,"size":0.01},{"price":5881462.0,"size":0.01},{"price":5881586.0,"size":0.04},{"price":5882441.0,"size":0.01},{"price":5883343.0,"size":0.01},{"price":5883526.0,"size":0.02},{"price":5883999.0,"size":0.01},{"price":5884885.0,"size":0.04},{"price":5887547.0,"size":0.5},{"price":5887700.0,"size":0.02},{"price":5887824.0,"size":0.01},{"price":5889450.0,"size":0.01},{"price":5889599.0,"size":0.01},{"price":5889900.0,"size":0.0125},{"price":5890000.0,"size":0.15},{"price":5891040.0,"size":0.04},{"price":5892123.0,"size":0.01},{"price":5892138.0,"size":0.0267539},{"price":5892151.0,"size":0.02675395},{"price":5892205.0,"size":0.29719466},{"price":5892319.0,"size":0.03},{"price":5892950.0,"size":0.01},{"price":5893134.0,"size":0.04},{"price":5894000.0,"size":0.01},{"price":5894980.0,"size":0.0125},{"price":5895585.0,"size":0.02},{"price":5896416.0,"size":0.01},{"price":5898188.0,"size":0.01},{"price":5899423.0,"size":0.11},{"price":5899480.0,"size":0.0125},{"price":5899999.0,"size":0.035},{"price":5900000.0,"size":1.21},{"price":5901198.0,"size":0.172},{"price":5902155.0,"size":0.02},{"price":5902930.0,"size":0.01},{"price":5903265.0,"size":0.01},{"price":5903336.0,"size":0.01},{"price":5903373.0,"size":0.01},{"price":5903500.0,"size":0.01},{"price":5904359.0,"size":0.02},{"price":5905400.0,"size":0.01},{"price":5905522.0,"size":5.959},{"price":5905821.0,"size":0.02},{"price":5906150.0,"size":0.02},{"price":5907198.0,"size":0.08},{"price":5907359.0,"size":0.02},{"price":5908042.0,"size":0.02},{"price":5909394.0,"size":0.01},{"price":5909719.0,"size":0.02},{"price":5910243.0,"size":0.02},{"price":5910373.0,"size":0.01},{"price":5910844.0,"size":0.01},{"price":5910977.0,"size":0.01},{"price":5914900.0,"size":0.01},{"price":5915167.0,"size":0.01},{"price":5915687.0,"size":0.02},{"price":5915900.0,"size":0.01},{"price":5917850.0,"size":0.02},{"price":5918578.0,"size":0.01},{"price":5918900.0,"size":0.17},{"price":5919157.0,"size":0.05},{"price":5919800.0,"size":0.05},{"price":5920000.0,"size":0.08},{"price":5920100.0,"size":0.01},{"price":5920243.0,"size":0.02},{"price":5920365.0,"size":0.01},{"price":5920406.0,"size":0.01},{"price":5920528.0,"size":0.01},{"price":5921313.0,"size":0.01},{"price":5922222.0,"size":0.23},{"price":5922561.0,"size":0.02},{"price":5923164.0,"size":0.02},{"price":5923250.0,"size":0.02},{"price":5923314.0,"size":0.01},{"price":5923655.0,"size":0.1},{"price":5923670.0,"size":0.02},{"price":5924075.0,"size":3.0},{"price":5924482.0,"size":0.01},{"price":5924500.0,"size":0.2},{"price":5925000.0,"size":0.01},{"price":5925365.0,"size":0.01},{"price":5926888.0,"size":0.02},{"price":5927164.0,"size":0.02},{"price":5927250.0,"size":0.01},{"price":5929800.0,"size":0.05},{"price":5930000.0,"size":0.87},{"price":5930087.0,"size":0.01},{"price":5930314.0,"size":0.01},{"price":5930497.0,"size":0.01},{"price":5930643.0,"size":0.02},{"price":5931365.0,"size":0.01},{"price":5932450.0,"size":0.02},{"price":5933273.0,"size":0.01},{"price":5934563.0,"size":0.1},{"price":5935160.0,"size":0.01},{"price":5935314.0,"size":0.01},{"price":5935843.0,"size":0.02},{"price":5936000.0,"size":0.05},{"price":5936203.0,"size":3.538},{"price":5936481.0,"size":0.01},{"price":5936699.0,"size":0.01},{"price":5936800.0,"size":0.02},{"price":5936840.0,"size":0.1},{"price":5939365.0,"size":0.01},{"price":5939514.0,"size":3.613},{"price":5939780.0,"size":0.0125},{"price":5939800.0,"size":0.05},{"price":5940000.0,"size":0.01},{"price":5940497.0,"size":0.01},{"price":5940800.0,"size":0.03},{"price":5941000.0,"size":0.2},{"price":5941442.0,"size":0.01},{"price":5942373.0,"size":0.01},{"price":5943800.0,"size":0.1},{"price":5944400.0,"size":0.01},{"price":5944500.0,"size":0.2},{"price":5944700.0,"size":0.01},{"price":5944800.0,"size":0.0125},{"price":5944818.0,"size":0.01},{"price":5945000.0,"size":0.2},{"price":5945948.0,"size":1.0},{"price":5948180.0,"size":0.08},{"price":5948450.0,"size":0.02},{"price":5948719.0,"size":0.2},{"price":5949373.0,"size":0.01},{"price":5949780.0,"size":0.0125},{"price":5949800.0,"size":0.05},{"price":5949998.0,"size":0.01},{"price":5950000.0,"size":1.0},{"price":5950497.0,"size":0.01},{"price":5950752.0,"size":0.02},{"price":5950800.0,"size":0.15},{"price":5952500.0,"size":0.03},{"price":5954350.0,"size":0.01},{"price":5954503.0,"size":2.343},{"price":5955555.0,"size":0.05},{"price":5955752.0,"size":0.02},{"price":5955929.0,"size":0.01},{"price":5956888.0,"size":0.05},{"price":5957800.0,"size":0.1},{"price":5958373.0,"size":0.01},{"price":5958507.0,"size":0.03},{"price":5959050.0,"size":0.02},{"price":5959800.0,"size":0.05},{"price":5960000.0,"size":0.6},{"price":5960752.0,"size":0.02},{"price":5963000.0,"size":0.01},{"price":5963523.0,"size":0.01},{"price":5964500.0,"size":0.2},{"price":5965203.0,"size":0.01},{"price":5965511.0,"size":0.02},{"price":5965948.0,"size":1.0},{"price":5969750.0,"size":0.03},{"price":5969800.0,"size":0.05},{"price":5970000.0,"size":0.38},{"price":5970164.0,"size":0.02},{"price":5970752.0,"size":0.02},{"price":5974200.0,"size":0.1},{"price":5975800.0,"size":0.01},{"price":5976092.0,"size":0.01},{"price":5976766.0,"size":0.32},{"price":5976800.0,"size":0.1},{"price":5977049.0,"size":0.2},{"price":5977164.0,"size":0.02},{"price":5977176.0,"size":0.1},{"price":5977777.0,"size":0.01},{"price":5978000.0,"size":0.02},{"price":5978719.0,"size":0.2},{"price":5978975.0,"size":0.5},{"price":5979135.0,"size":0.1},{"price":5979800.0,"size":0.05},{"price":5979838.0,"size":0.06},{"price":5980000.0,"size":1.021},{"price":5980125.0,"size":0.01},{"price":5980752.0,"size":0.02},{"price":5981000.0,"size":0.2},{"price":5983443.0,"size":0.05},{"price":5984500.0,"size":0.2},{"price":5985192.0,"size":0.01},{"price":5985425.0,"size":0.5},{"price":5985434.0,"size":0.1},{"price":5985750.0,"size":0.02},{"price":5985842.0,"size":0.01},{"price":5985948.0,"size":1.0},{"price":5988632.0,"size":0.01},{"price":5989750.0,"size":0.03},{"price":5989800.0,"size":0.05},{"price":5989809.0,"size":1.0},{"price":5989870.0,"size":0.15},{"price":5989906.0,"size":0.5},{"price":5990000.0,"size":0.4},{"price":5990752.0,"size":0.02},{"price":5990999.0,"size":0.01},{"price":5993000.0,"size":0.01},{"price":5993999.0,"size":0.24123375},{"price":5994000.0,"size":40.0},{"price":5994255.0,"size":0.01},{"price":5994400.0,"size":0.01},{"price":5994573.0,"size":0.01},{"price":5994643.0,"size":0.3},{"price":5995200.0,"size":0.02},{"price":5996000.0,"size":0.01},{"price":5996599.0,"size":0.48225832},{"price":5996600.0,"size":70.0},{"price":5996659.0,"size":0.24112674},{"price":5996660.0,"size":25.0},{"price":5999983.0,"size":0.01},{"price":5999999.0,"size":0.01},{"price":6000000.0,"size":4.995},{"price":6000298.0,"size":0.17},{"price":6000500.0,"size":0.01},{"price":6000752.0,"size":0.02},{"price":6003000.0,"size":0.1},{"price":6003265.0,"size":0.01},{"price":6004200.0,"size":0.02},{"price":6004500.0,"size":0.2},{"price":6005450.0,"size":0.01},{"price":6005511.0,"size":0.01},{"price":6008000.0,"size":0.01},{"price":6008027.0,"size":0.25},{"price":6008284.0,"size":0.084},{"price":6010000.0,"size":0.05}]}}}
1639350347.009005: {"jsonrpc":"2.0","method":"channelMessage","params":{"channel":"lightning_board_ETH_JPY","message":{"mid_price":471837.0,"bids":[{"price":471250.0,"size":14.99995}],"asks":[]}}}
1639350347.027595: {"jsonrpc":"2.0","method":"channelMessage","params":{"channel":"lightning_board_snapshot_BTCJPY17DEC2021","message":{"mid_price":5701213.0,"bids":[{"price":5349532.0,"size":15.6},{"price":5391567.0,"size":6.6},{"price":5442047.0,"size":5.01},{"price":5454556.0,"size":4.0},{"price":5510756.0,"size":4.9},{"price":5575932.0,"size":3.9},{"price":5586201.0,"size":3.0},{"price":5598443.0,"size":3.02},{"price":5619882.0,"size":2.0},{"price":5629303.0,"size":1.8},{"price":5648347.0,"size":0.76},{"price":5653790.0,"size":0.7},{"price":5661414.0,"size":0.6},{"price":5674739.0,"size":0.26},{"price":5677741.0,"size":1.0},{"price":5677751.0,"size":0.01},{"price":5686175.0,"size":0.2},{"price":5691316.0,"size":0.01}],"asks":[{"price":5711111.0,"size":0.01},{"price":5713220.0,"size":0.15},{"price":5713319.0,"size":0.2},{"price":5714075.0,"size":0.58},{"price":5715427.0,"size":0.3},{"price":5716898.0,"size":0.6},{"price":5718589.0,"size":1.0},{"price":5732566.0,"size":1.0},{"price":5734417.0,"size":1.8},{"price":5746044.0,"size":1.9},{"price":5766647.0,"size":3.0},{"price":5796786.0,"size":2.4},{"price":5829125.0,"size":3.0},{"price":5852911.0,"size":5.0},{"price":5879283.0,"size":4.8},{"price":5920799.0,"size":5.0},{"price":5944842.0,"size":9.3},{"price":5986556.0,"size":12.75},{"price":6536736.0,"size":0.5},{"price":6600822.0,"size":1.0},{"price":6728993.0,"size":3.0},{"price":6857165.0,"size":5.0}]}}}
1639350347.030823: {"jsonrpc":"2.0","method":"channelMessage","params":{"channel":"lightning_board_snapshot_BTCJPY24DEC2021","message":{"mid_price":5700879.0,"bids":[{"price":5073146.0,"size":5.0},{"price":5182246.0,"size":3.0},{"price":5291346.0,"size":1.0},{"price":5468270.0,"size":5.21},{"price":5502844.0,"size":4.0},{"price":5557220.0,"size":3.0},{"price":5583530.0,"size":3.7},{"price":5603205.0,"size":2.3},{"price":5623006.0,"size":1.92},{"price":5659178.0,"size":2.0},{"price":5661869.0,"size":1.3},{"price":5677658.0,"size":1.0},{"price":5680273.0,"size":0.7},{"price":5683047.0,"size":0.5},{"price":5683544.0,"size":0.75}],"asks":[{"price":5718215.0,"size":0.19},{"price":5721381.0,"size":0.41},{"price":5722463.0,"size":1.0},{"price":5723492.0,"size":1.0},{"price":5725066.0,"size":1.09},{"price":5727746.0,"size":0.51},{"price":5730420.0,"size":1.0},{"price":5743558.0,"size":2.0},{"price":5749238.0,"size":2.0},{"price":5771552.0,"size":1.91},{"price":5794015.0,"size":2.8},{"price":5820325.0,"size":2.77},{"price":5832425.0,"size":3.71},{"price":5836846.0,"size":5.0},{"price":5867046.0,"size":4.9}]}}}
1639350347.083244: {"jsonrpc":"2.0","method":"channelMessage","params":{"channel":"lightning_board_FX_BTC_JPY","message":{"mid_price":5864396.0,"bids":[{"price":5862513.0,"size":0.0}],"asks":[{"price":5870240.0,"size":0.02933836},{"price":5867148.0,"size":0.04946442},{"price":5869149.0,"size":0.0},{"price":5869879.0,"size":0.0},{"price":5892114.0,"size":0.02679844}]}}}
1639350347.135905: {"jsonrpc":"2.0","method":"channelMessage","params":{"channel":"lightning_board_ETH_JPY","message":{"mid_price":471837.0,"bids":[],"asks":[{"price":472384.0,"size":0.0},{"price":473945.0,"size":0.0}]}}}
1639350347.2072709: {"jsonrpc":"2.0","method":"channelMessage","params":{"channel":"lightning_ticker_FX_BTC_JPY","message":{"product_code":"FX_BTC_JPY","state":"RUNNING","timestamp":"2021-12-12T23:05:47.1193771Z","tick_id":127091821,"best_bid":5863163.0,"best_ask":5865630.0,"best_bid_size":0.03,"best_ask_size":0.01,"total_bid_depth":232.312623480000,"total_ask_depth":292.895406280000,"market_bid_size":0.0,"market_ask_size":0.0,"ltp":5864791.0,"volume":4227.702096850000,"volume_by_product":4227.702096850000}}}
1639350347.212439: {"jsonrpc":"2.0","method":"channelMessage","params":{"channel":"lightning_board_FX_BTC_JPY","message":{"mid_price":5864396.0,"bids":[{"price":5855873.0,"size":0.02679844},{"price":5862385.0,"size":0.0}],"asks":[{"price":5869477.0,"size":0.02}]}}}
1639350347.2504: {"jsonrpc":"2.0","method":"channelMessage","params":{"channel":"lightning_ticker_ETH_JPY","message":{"product_code":"ETH_JPY","state":"RUNNING","timestamp":"2021-12-12T23:05:47.092205Z","tick_id":26934638,"best_bid":471736.0,"best_ask":472000.0,"best_bid_size":0.62,"best_ask_size":0.770000,"total_bid_depth":3291.977367900000,"total_ask_depth":4426.39257320,"market_bid_size":0.0,"market_ask_size":0.0,"ltp":471722.0,"volume":10833.320505500000,"volume_by_product":10833.320505500000}}}
1639350347.255363: {"jsonrpc":"2.0","method":"channelMessage","params":{"channel":"lightning_board_ETH_JPY","message":{"mid_price":471868.0,"bids":[{"price":471736.0,"size":0.62}],"asks":[]}}}
1639350347.329816: {"jsonrpc":"2.0","method":"channelMessage","params":{"channel":"lightning_board_FX_BTC_JPY","message":{"mid_price":5864396.0,"bids":[],"asks":[{"price":5870434.0,"size":0.0}]}}}
1639350347.366207: {"jsonrpc":"2.0","method":"channelMessage","params":{"channel":"lightning_board_ETH_JPY","message":{"mid_price":471868.0,"bids":[{"price":471148.0,"size":0.0}],"asks":[{"price":472105.0,"size":0.0}]}}}
1639350347.449258: {"jsonrpc":"2.0","method":"channelMessage","params":{"channel":"lightning_board_FX_BTC_JPY","message":{"mid_price":5864654.0,"bids":[{"price":5855851.0,"size":0.0},{"price":5863163.0,"size":0.0},{"price":5859203.0,"size":0.0},{"price":5862384.0,"size":0.0},{"price":5860575.0,"size":0.0},{"price":5862876.0,"size":0.01},{"price":5861761.0,"size":0.0},{"price":5862333.0,"size":0.0},{"price":5861560.0,"size":0.0},{"price":5859242.0,"size":0.02933836}],"asks":[{"price":5892151.0,"size":0.0},{"price":5891606.0,"size":0.06},{"price":5870648.0,"size":0.0},{"price":5865630.0,"size":0.0},{"price":5866992.0,"size":0.0}]}}}
1639350347.4690719: {"jsonrpc":"2.0","method":"channelMessage","params":{"channel":"lightning_board_ETH_JPY","message":{"mid_price":471868.0,"bids":[{"price":471144.0,"size":0.0},{"price":471675.0,"size":0.814}],"asks":[{"price":473083.0,"size":0.0},{"price":472751.0,"size":6.08}]}}}
1639350347.586983: {"jsonrpc":"2.0","method":"channelMessage","params":{"channel":"lightning_board_ETH_JPY","message":{"mid_price":471868.0,"bids":[{"price":471250.0,"size":0.0}],"asks":[{"price":472383.0,"size":0.0},{"price":472638.0,"size":2.048}]}}}
1639350347.6046689: {"jsonrpc":"2.0","method":"channelMessage","params":{"channel":"lightning_board_FX_BTC_JPY","message":{"mid_price":5864827.0,"bids":[{"price":5862344.0,"size":0.0},{"price":5862714.0,"size":0.1751},{"price":5862567.0,"size":0.0},{"price":5859274.0,"size":0.02675395},{"price":5860579.0,"size":0.0},{"price":5863447.0,"size":0.04644039},{"price":5858002.0,"size":0.1},{"price":5859268.0,"size":0.0},{"price":5861152.0,"size":0.0},{"price":5863164.0,"size":0.04},{"price":5857995.0,"size":0.0},{"price":5859582.0,"size":0.02933836},{"price":5861519.0,"size":0.0},{"price":5862420.0,"size":0.0}],"asks":[{"price":5867048.0,"size":0.0},{"price":5867156.0,"size":0.0},{"price":5867011.0,"size":0.0},{"price":5892108.0,"size":0.02675395},{"price":5880379.0,"size":0.02},{"price":5866206.0,"size":0.0},{"price":5869989.0,"size":0.0},{"price":5952511.0,"size":0.7},{"price":5880630.0,"size":0.0}]}}}
1639350347.608033: {"jsonrpc":"2.0","method":"channelMessage","params":{"channel":"lightning_ticker_BTC_USD","message":{"product_code":"BTC_USD","state":"RUNNING","timestamp":"2021-12-12T23:05:47.4820985Z","tick_id":17933022,"best_bid":50274.28,"best_ask":50296.90,"best_bid_size":1.0,"best_ask_size":0.09,"total_bid_depth":30.26365669,"total_ask_depth":22.39281796,"market_bid_size":0.0,"market_ask_size":0.0,"ltp":50278.04,"volume":250.100018300000,"volume_by_product":250.100018300000}}}
1639350347.613271: {"jsonrpc":"2.0","method":"channelMessage","params":{"channel":"lightning_board_BTC_USD","message":{"mid_price":50285.59,"bids":[{"price":49845.9,"size":0.0}],"asks":[{"price":50687.48,"size":0.0},{"price":51009.3,"size":0.0}]}}}
1639350347.634271: {"jsonrpc":"2.0","method":"channelMessage","params":{"channel":"lightning_executions_FX_BTC_JPY","message":[{"id":2284079871,"side":"BUY","price":5866207.0,"size":0.02,"exec_date":"2021-12-12T23:05:47.516381Z","buy_child_order_acceptance_id":"JRF20211212-230547-202738","sell_child_order_acceptance_id":"JRF20211212-230546-210160"}]}}
1639350347.6570299: {"jsonrpc":"2.0","method":"channelMessage","params":{"channel":"lightning_executions_FX_BTC_JPY","message":[{"id":2284079872,"side":"BUY","price":5866944.0,"size":0.04,"exec_date":"2021-12-12T23:05:47.516381Z","buy_child_order_acceptance_id":"JRF20211212-230547-207926","sell_child_order_acceptance_id":"JRF20211212-230540-209458"}]}}
1639350347.710128: {"jsonrpc":"2.0","method":"channelMessage","params":{"channel":"lightning_ticker_FX_BTC_JPY","message":{"product_code":"FX_BTC_JPY","state":"RUNNING","timestamp":"2021-12-12T23:05:47.5499198Z","tick_id":127091877,"best_bid":5863901.0,"best_ask":5866944.0,"best_bid_size":0.03,"best_ask_size":0.16000000,"total_bid_depth":231.641240150000,"total_ask_depth":292.975073870000,"market_bid_size":0.0,"market_ask_size":0.0,"ltp":5866944.0,"volume":4227.762096850000,"volume_by_product":4227.762096850000}}}
1639350347.716398: {"jsonrpc":"2.0","method":"channelMessage","params":{"channel":"lightning_board_FX_BTC_JPY","message":{"mid_price":5865422.0,"bids":[{"price":5863033.0,"size":0.0},{"price":5863103.0,"size":0.0},{"price":5862820.0,"size":0.0},{"price":5863286.0,"size":0.02},{"price":5859242.0,"size":0.0},{"price":5862714.0,"size":0.0},{"price":5812806.0,"size":0.01},{"price":5862713.0,"size":0.0},{"price":5863039.0,"size":0.01},{"price":5863901.0,"size":0.03}],"asks":[{"price":5869161.0,"size":0.01},{"price":5867472.0,"size":0.0},{"price":5875484.0,"size":0.0},{"price":5867589.0,"size":0.0},{"price":5867276.0,"size":0.0},{"price":5866207.0,"size":0.0},{"price":5866944.0,"size":0.16}]}}}
1639350347.7574809: {"jsonrpc":"2.0","method":"channelMessage","params":{"channel":"lightning_board_BTC_USD","message":{"mid_price":50285.59,"bids":[{"price":49760.48,"size":0.0},{"price":49680.02,"size":0.0},{"price":49882.9,"size":0.0},{"price":49805.67,"size":0.0}],"asks":[{"price":51087.97,"size":0.0},{"price":50771.22,"size":0.0},{"price":50886.83,"size":0.0}]}}}
1639350347.762812: {"jsonrpc":"2.0","method":"channelMessage","params":{"channel":"lightning_ticker_ETH_JPY","message":{"product_code":"ETH_JPY","state":"RUNNING","timestamp":"2021-12-12T23:05:47.6421309Z","tick_id":26934655,"best_bid":471736.0,"best_ask":472000.0,"best_bid_size":0.62,"best_ask_size":0.020000,"total_bid_depth":3276.227417900000,"total_ask_depth":4461.82657320,"market_bid_size":0.0,"market_ask_size":0.0,"ltp":471722.0,"volume":10833.320505500000,"volume_by_product":10833.320505500000}}}
1639350347.771765: {"jsonrpc":"2.0","method":"channelMessage","params":{"channel":"lightning_board_ETH_JPY","message":{"mid_price":471868.0,"bids":[],"asks":[{"price":472952.0,"size":44.0},{"price":472000.0,"size":0.02},{"price":472939.0,"size":0.0},{"price":472016.0,"size":0.0},{"price":472024.0,"size":0.0},{"price":472038.0,"size":0.0},{"price":472037.0,"size":0.0},{"price":472020.0,"size":0.75}]}}}
1639350347.772867: {"jsonrpc":"2.0","method":"channelMessage","params":{"channel":"lightning_ticker_BTC_EUR","message":{"product_code":"BTC_EUR","state":"RUNNING","timestamp":"2021-12-12T23:05:47.5160289Z","tick_id":7240258,"best_bid":44461.19,"best_ask":44479.65,"best_bid_size":0.00118145,"best_ask_size":0.01,"total_bid_depth":14.75728901,"total_ask_depth":13.86946467,"market_bid_size":0.0,"market_ask_size":0.0,"ltp":44461.2,"volume":43.951523900000,"volume_by_product":43.951523900000}}}
1639350347.781363: {"jsonrpc":"2.0","method":"channelMessage","params":{"channel":"lightning_board_BTC_EUR","message":{"mid_price":44470.42,"bids":[],"asks":[{"price":44590.97,"size":0.0}]}}}
1639350347.7847848: {"jsonrpc":"2.0","method":"channelMessage","params":{"channel":"lightning_ticker_XRP_JPY","message":{"product_code":"XRP_JPY","state":"RUNNING","timestamp":"2021-12-12T23:05:47.5913483Z","tick_id":12284649,"best_bid":95.98,"best_ask":96.13,"best_bid_size":620.28,"best_ask_size":49.479871,"total_bid_depth":1523951.86922300,"total_ask_depth":2319852.552871000000,"market_bid_size":0.0,"market_ask_size":0.0,"ltp":95.96,"volume":1653279.685708000000,"volume_by_product":1653279.685708000000}}}
1639350347.792099: {"jsonrpc":"2.0","method":"channelMessage","params":{"channel":"lightning_board_XRP_JPY","message":{"mid_price":96.05,"bids":[],"asks":[{"price":96.16,"size":0.0}]}}}
1639350347.8680089: {"jsonrpc":"2.0","method":"channelMessage","params":{"channel":"lightning_board_FX_BTC_JPY","message":{"mid_price":5865705.0,"bids":[{"price":5862587.0,"size":0.02675389},{"price":5863052.0,"size":0.1354},{"price":5863051.0,"size":0.0},{"price":5859264.0,"size":0.0},{"price":5863168.0,"size":0.05},{"price":5863103.0,"size":0.02},{"price":5863039.0,"size":0.03432111},{"price":5863547.0,"size":0.01},{"price":5862027.0,"size":0.0},{"price":5862022.0,"size":0.0},{"price":5859036.0,"size":0.0},{"price":5861663.0,"size":0.0},{"price":5863397.0,"size":0.0493381},{"price":5864468.0,"size":0.01},{"price":5864320.0,"size":0.23169577},{"price":5863014.0,"size":0.01},{"price":5862968.0,"size":0.05}],"asks":[{"price":5866967.0,"size":0.0},{"price":5867069.0,"size":0.0},{"price":5866943.0,"size":0.15},{"price":5867858.0,"size":0.0},{"price":5866945.0,"size":0.0},{"price":5869325.0,"size":0.0},{"price":5866966.0,"size":0.0},{"price":5869510.0,"size":0.01},{"price":5869240.0,"size":0.01},{"price":5892103.0,"size":0.02675389},{"price":5870031.0,"size":0.0},{"price":5867857.0,"size":0.04},{"price":5870240.0,"size":0.0}]}}}
1639350347.9119449: {"jsonrpc":"2.0","method":"channelMessage","params":{"channel":"lightning_board_ETH_JPY","message":{"mid_price":471916.0,"bids":[{"price":471833.0,"size":0.65}],"asks":[{"price":472020.0,"size":0.0},{"price":474051.0,"size":0.0}]}}}
1639350347.923882: {"jsonrpc":"2.0","method":"channelMessage","params":{"channel":"lightning_board_BTC_USD","message":{"mid_price":50285.59,"bids":[{"price":49484.38,"size":0.0},{"price":49725.21,"size":0.0}],"asks":[{"price":50730.98,"size":0.0},{"price":50851.68,"size":0.0},{"price":50306.35,"size":0.0}]}}}
1639350347.9739342: {"jsonrpc":"2.0","method":"channelMessage","params":{"channel":"lightning_board_FX_BTC_JPY","message":{"mid_price":5865867.0,"bids":[{"price":5864791.0,"size":0.02},{"price":5863052.0,"size":0.2354},{"price":5864364.0,"size":0.02289383},{"price":5863118.0,"size":0.05},{"price":5863164.0,"size":0.0},{"price":5863784.0,"size":0.01},{"price":5863585.0,"size":0.01},{"price":5848347.0,"size":0.02},{"price":5863448.0,"size":0.2},{"price":5863447.0,"size":0.0}],"asks":[{"price":5868097.0,"size":0.0},{"price":5867148.0,"size":0.0},{"price":5868092.0,"size":0.0},{"price":5869087.0,"size":0.0},{"price":5868897.0,"size":0.05},{"price":5866944.0,"size":0.0},{"price":5870238.0,"size":0.0},{"price":5867345.0,"size":0.0},{"price":5867199.0,"size":0.0}]}}}
1639350348.075955: {"jsonrpc":"2.0","method":"channelMessage","params":{"channel":"lightning_board_ETH_JPY","message":{"mid_price":471916.0,"bids":[],"asks":[{"price":473843.0,"size":6.0}]}}}
1639350348.091634: {"jsonrpc":"2.0","method":"channelMessage","params":{"channel":"lightning_board_FX_BTC_JPY","message":{"mid_price":5865867.0,"bids":[{"price":5863052.0,"size":0.1},{"price":5863902.0,"size":0.1353},{"price":5864320.0,"size":0.0},{"price":5863397.0,"size":0.0},{"price":5863600.0,"size":0.12},{"price":5863967.0,"size":0.05},{"price":5864468.0,"size":0.0},{"price":5863303.0,"size":0.05},{"price":5860657.0,"size":0.05},{"price":5864364.0,"size":0.0},{"price":5863687.0,"size":0.1},{"price":5863701.0,"size":0.05}],"asks":[{"price":5869040.0,"size":0.04964016},{"price":5869509.0,"size":0.05},{"price":5869422.0,"size":0.011},{"price":5867857.0,"size":0.0},{"price":5867058.0,"size":0.0}]}}}
1639350348.091855: {"jsonrpc":"2.0","method":"channelMessage","params":{"channel":"lightning_board_BTC_USD","message":{"mid_price":50285.59,"bids":[],"asks":[{"price":50811.45,"size":0.0}]}}}
1639350348.105124: {"jsonrpc":"2.0","method":"channelMessage","params":{"channel":"lightning_executions_FX_BTC_JPY","message":[{"id":2284079873,"side":"BUY","price":5866943.0,"size":0.15,"exec_date":"2021-12-12T23:05:47.9323008Z","buy_child_order_acceptance_id":"JRF20211212-230547-200348","sell_child_order_acceptance_id":"JRF20211212-230547-086984"}]}}
1639350348.2021172: {"jsonrpc":"2.0","method":"channelMessage","params":{"channel":"lightning_board_ETH_JPY","message":{"mid_price":471916.0,"bids":[{"price":471252.0,"size":44.0}],"asks":[{"price":472088.0,"size":0.0},{"price":472094.0,"size":0.0},{"price":472638.0,"size":3.648}]}}}
1639350348.202256: {"jsonrpc":"2.0","method":"channelMessage","params":{"channel":"lightning_board_FX_BTC_JPY","message":{"mid_price":5865925.0,"bids":[{"price":5863902.0,"size":0.0},{"price":5857861.0,"size":0.0}],"asks":[{"price":5866943.0,"size":0.0},{"price":5870284.0,"size":0.05},{"price":5869798.0,"size":0.01},{"price":5869008.0,"size":0.04946442},{"price":5869975.0,"size":0.12},{"price":5873237.0,"size":0.5},{"price":5870977.0,"size":0.05},{"price":5870062.0,"size":0.1}]}}}
1639350348.204886: {"jsonrpc":"2.0","method":"channelMessage","params":{"channel":"lightning_ticker_BTC_USD","message":{"product_code":"BTC_USD","state":"RUNNING","timestamp":"2021-12-12T23:05:48.0759991Z","tick_id":17933039,"best_bid":50278.93,"best_ask":50296.90,"best_bid_size":0.6003,"best_ask_size":0.09,"total_bid_depth":25.39335669,"total_ask_depth":17.43281796,"market_bid_size":0.0,"market_ask_size":0.0,"ltp":50278.04,"volume":250.100018300000,"volume_by_product":250.100018300000}}}
1639350348.208708: {"jsonrpc":"2.0","method":"channelMessage","params":{"channel":"lightning_board_BTC_USD","message":{"mid_price":50287.91,"bids":[{"price":49564.85,"size":0.0},{"price":50245.68,"size":0.0},{"price":50253.22,"size":0.0},{"price":50278.93,"size":0.6003}],"asks":[]}}}
1639350348.236862: {"jsonrpc":"2.0","method":"channelMessage","params":{"channel":"lightning_board_XRP_JPY","message":{"mid_price":96.05,"bids":[{"price":95.9,"size":10625.0},{"price":95.84,"size":10819.0}],"asks":[{"price":96.15,"size":0.0},{"price":96.31,"size":0.0}]}}}
1639350348.276034: {"jsonrpc":"2.0","method":"channelMessage","params":{"channel":"lightning_executions_ETH_JPY","message":[{"id":2284078768,"side":"BUY","price":472000.0,"size":0.02,"exec_date":"2021-12-12T23:05:48.1776075Z","buy_child_order_acceptance_id":"JRF20211212-230547-210161","sell_child_order_acceptance_id":"JRF20211212-230254-032186"}]}}
1639350348.310545: {"jsonrpc":"2.0","method":"channelMessage","params":{"channel":"lightning_ticker_FX_BTC_JPY","message":{"product_code":"FX_BTC_JPY","state":"RUNNING","timestamp":"2021-12-12T23:05:48.1831929Z","tick_id":127091972,"best_bid":5866477.0,"best_ask":5867059.0,"best_bid_size":0.02,"best_ask_size":0.02,"total_bid_depth":232.382423590000,"total_ask_depth":292.407467920000,"market_bid_size":0.0,"market_ask_size":0.0,"ltp":5866943.0,"volume":4227.912096850000,"volume_by_product":4227.912096850000}}}
1639350348.3182: {"jsonrpc":"2.0","method":"channelMessage","params":{"channel":"lightning_board_FX_BTC_JPY","message":{"mid_price":5866768.0,"bids":[{"price":5863490.0,"size":0.109},{"price":5853722.0,"size":0.0},{"price":5864321.0,"size":0.15},{"price":5859046.0,"size":0.0},{"price":5865023.0,"size":0.23167298},{"price":5866477.0,"size":0.02},{"price":5862716.0,"size":0.03},{"price":5865007.0,"size":0.025},{"price":5860729.0,"size":0.0},{"price":5865000.0,"size":0.02287585},{"price":5865924.0,"size":0.01}],"asks":[{"price":5869180.0,"size":0.05},{"price":5868950.0,"size":0.0},{"price":5871127.0,"size":0.109},{"price":5875845.0,"size":0.0},{"price":5872130.0,"size":0.05867672},{"price":5867954.0,"size":0.01}]}}}
1639350348.3469849: {"jsonrpc":"2.0","method":"channelMessage","params":{"channel":"lightning_board_BTC_USD","message":{"mid_price":50291.68,"bids":[{"price":50286.47,"size":0.6003}],"asks":[{"price":50338.35,"size":0.6003},{"price":50345.9,"size":0.6003},{"price":50323.56,"size":0.0}]}}}
1639350348.3628922: {"jsonrpc":"2.0","method":"channelMessage","params":{"channel":"lightning_ticker_ETH_JPY","message":{"product_code":"ETH_JPY","state":"RUNNING","timestamp":"2021-12-12T23:05:48.2455298Z","tick_id":26934668,"best_bid":471910.0,"best_ask":472200.0,"best_bid_size":0.58,"best_ask_size":0.02,"total_bid_depth":3321.393417900000,"total_ask_depth":4472.28957320,"market_bid_size":0.0,"market_ask_size":0.0,"ltp":472000.0,"volume":10833.340505500000,"volume_by_product":10833.340505500000}}}
1639350348.370194: {"jsonrpc":"2.0","method":"channelMessage","params":{"channel":"lightning_board_ETH_JPY","message":{"mid_price":472055.0,"bids":[{"price":471675.0,"size":0.75},{"price":471910.0,"size":0.58}],"asks":[{"price":474216.0,"size":0.69},{"price":472000.0,"size":0.0},{"price":472489.0,"size":5.013}]}}}
1639350348.441281: {"jsonrpc":"2.0","method":"channelMessage","params":{"channel":"lightning_board_FX_BTC_JPY","message":{"mid_price":5866768.0,"bids":[{"price":5861860.0,"size":0.01},{"price":5853642.0,"size":0.057},{"price":5848456.0,"size":0.0},{"price":5865147.0,"size":0.03},{"price":5860148.0,"size":0.0},{"price":5865023.0,"size":0.0},{"price":5858002.0,"size":0.0},{"price":5855145.0,"size":0.0},{"price":5855148.0,"size":0.0},{"price":5860247.0,"size":0.255},{"price":5864792.0,"size":0.15},{"price":5858010.0,"size":0.0}],"asks":[{"price":5878230.0,"size":0.0},{"price":5876039.0,"size":0.057},{"price":5871488.0,"size":0.255},{"price":5871127.0,"size":0.0},{"price":5874944.0,"size":0.06}]}}}
1639350348.457459: {"jsonrpc":"2.0","method":"channelMessage","params":{"channel":"lightning_executions_BTC_USD","message":[{"id":2284078769,"side":"BUY","price":50296.9,"size":0.09,"exec_date":"2021-12-12T23:05:48.3473487Z","buy_child_order_acceptance_id":"JRF20211212-230548-223109","sell_child_order_acceptance_id":"JRF20211212-230545-709202"}]}}
1639350348.49476: {"jsonrpc":"2.0","method":"channelMessage","params":{"channel":"lightning_board_ETH_JPY","message":{"mid_price":472149.0,"bids":[{"price":471156.0,"size":0.0},{"price":471379.0,"size":0.75},{"price":472099.0,"size":1.52}],"asks":[{"price":472638.0,"size":1.6}]}}}
1639350348.497951: {"jsonrpc":"2.0","method":"channelMessage","params":{"channel":"lightning_ticker_XRP_JPY","message":{"product_code":"XRP_JPY","state":"RUNNING","timestamp":"2021-12-12T23:05:48.2793303Z","tick_id":12284654,"best_bid":95.98,"best_ask":96.13,"best_bid_size":620.28,"best_ask_size":49.479871,"total_bid_depth":1534733.26184100,"total_ask_depth":2319203.089719000000,"market_bid_size":0.0,"market_ask_size":0.0,"ltp":95.96,"volume":1653279.685708000000,"volume_by_product":1653279.685708000000}}}
1639350348.501591: {"jsonrpc":"2.0","method":"channelMessage","params":{"channel":"lightning_board_XRP_JPY","message":{"mid_price":96.05,"bids":[{"price":95.88,"size":693.631618}],"asks":[]}}}
1639350348.506001: {"jsonrpc":"2.0","method":"channelMessage","params":{"channel":"lightning_ticker_BTC_EUR","message":{"product_code":"BTC_EUR","state":"RUNNING","timestamp":"2021-12-12T23:05:48.3304246Z","tick_id":7240260,"best_bid":44461.19,"best_ask":44479.65,"best_bid_size":0.00118145,"best_ask_size":0.01,"total_bid_depth":14.39728901,"total_ask_depth":13.86946467,"market_bid_size":0.0,"market_ask_size":0.0,"ltp":44461.2,"volume":43.951523900000,"volume_by_product":43.951523900000}}}
1639350348.510435: {"jsonrpc":"2.0","method":"channelMessage","params":{"channel":"lightning_board_BTC_EUR","message":{"mid_price":44470.42,"bids":[{"price":44239.14,"size":0.0},{"price":44325.79,"size":0.0}],"asks":[]}}}
1639350348.5271602: {"jsonrpc":"2.0","method":"channelMessage","params":{"channel":"lightning_board_BTC_USD","message":{"mid_price":50301.65,"bids":[],"asks":[{"price":50296.9,"size":0.0}]}}}
1639350348.5505102: {"jsonrpc":"2.0","method":"channelMessage","params":{"channel":"lightning_board_FX_BTC_JPY","message":{"mid_price":5866768.0,"bids":[{"price":5863168.0,"size":0.0},{"price":5859239.0,"size":0.0},{"price":5864321.0,"size":0.0},{"price":5859582.0,"size":0.0},{"price":5862347.0,"size":0.02}],"asks":[{"price":5880615.0,"size":0.0},{"price":5868974.0,"size":0.0}]}}}
1639350348.589819: {"jsonrpc":"2.0","method":"channelMessage","params":{"channel":"lightning_executions_FX_BTC_JPY","message":[{"id":2284079874,"side":"BUY","price":5867059.0,"size":0.02,"exec_date":"2021-12-12T23:05:48.4828723Z","buy_child_order_acceptance_id":"JRF20211212-230548-196571","sell_child_order_acceptance_id":"JRF20211212-230546-213237"}]}}
1639350348.652988: {"jsonrpc":"2.0","method":"channelMessage","params":{"channel":"lightning_board_ETH_JPY","message":{"mid_price":472149.0,"bids":[{"price":471676.0,"size":0.0},{"price":469207.0,"size":0.0},{"price":470631.0,"size":0.0}],"asks":[{"price":472233.0,"size":0.75},{"price":472599.0,"size":0.1}]}}}
1639350348.667593: {"jsonrpc":"2.0","method":"channelMessage","params":{"channel":"lightning_board_BTC_EUR","message":{"mid_price":44470.42,"bids":[],"asks":[{"price":44701.57,"size":0.0},{"price":44616.51,"size":0.0},{"price":44531.7,"size":0.0}]}}}
1639350348.685518: {"jsonrpc":"2.0","method":"channelMessage","params":{"channel":"lightning_board_BTC_USD","message":{"mid_price":50301.65,"bids":[{"price":49833.04,"size":0.45},{"price":49913.55,"size":0.18}],"asks":[{"price":50799.12,"size":0.45},{"price":50718.62,"size":0.18},{"price":50758.87,"size":0.27}]}}}
1639350348.719916: {"jsonrpc":"2.0","method":"channelMessage","params":{"channel":"lightning_board_FX_BTC_JPY","message":{"mid_price":5867133.0,"bids":[{"price":5863585.0,"size":0.0},{"price":5861436.0,"size":0.02933836},{"price":5859002.0,"size":0.0},{"price":5862876.0,"size":0.0},{"price":5862576.0,"size":0.0},{"price":5855864.0,"size":0.0},{"price":5864792.0,"size":0.0},{"price":5865170.0,"size":0.02},{"price":5863967.0,"size":0.0},{"price":5856211.0,"size":0.0},{"price":5862968.0,"size":0.0},{"price":5863052.0,"size":0.0},{"price":5863600.0,"size":0.0},{"price":5863701.0,"size":0.0},{"price":5851059.0,"size":0.02},{"price":5865256.0,"size":0.0493381},{"price":5863769.0,"size":0.01},{"price":5858049.0,"size":0.01},{"price":5860657.0,"size":0.0},{"price":5863118.0,"size":0.0},{"price":5863687.0,"size":0.0},{"price":5867066.0,"size":0.02},{"price":5863303.0,"size":0.0},{"price":5861374.0,"size":0.1},{"price":5865039.0,"size":0.23164999},{"price":5865000.0,"size":0.0},{"price":5798806.0,"size":0.01}],"asks":[{"price":5868951.0,"size":0.0},{"price":5868897.0,"size":0.0},{"price":5869477.0,"size":0.0},{"price":5873075.0,"size":0.0},{"price":5867059.0,"size":0.0},{"price":5895570.0,"size":0.01},{"price":5892138.0,"size":0.0},{"price":5867954.0,"size":0.0},{"price":5869040.0,"size":0.0},{"price":5870284.0,"size":0.0}]}}}
1639350348.725099: {"jsonrpc":"2.0","method":"channelMessage","params":{"channel":"lightning_executions_FX_BTC_JPY","message":[{"id":2284079875,"side":"BUY","price":5867200.0,"size":0.01,"exec_date":"2021-12-12T23:05:48.5667996Z","buy_child_order_acceptance_id":"JRF20211212-230548-199001","sell_child_order_acceptance_id":"JRF20211212-230544-208817"},{"id":2284079876,"side":"BUY","price":5867550.0,"size":0.01,"exec_date":"2021-12-12T23:05:48.5667996Z","buy_child_order_acceptance_id":"JRF20211212-230548-199001","sell_child_order_acceptance_id":"JRF20211212-230423-124715"}]}}
1639350348.815974: {"jsonrpc":"2.0","method":"channelMessage","params":{"channel":"lightning_board_BTC_EUR","message":{"mid_price":44470.42,"bids":[],"asks":[{"price":44491.31,"size":0.0}]}}}
1639350348.8264441: {"jsonrpc":"2.0","method":"channelMessage","params":{"channel":"lightning_board_ETH_JPY","message":{"mid_price":472149.0,"bids":[{"price":471833.0,"size":1.4},{"price":471660.0,"size":14.99995},{"price":471834.0,"size":0.96}],"asks":[{"price":472233.0,"size":0.0},{"price":472638.0,"size":2.208},{"price":474216.0,"size":0.0},{"price":472721.0,"size":0.0},{"price":472599.0,"size":0.0}]}}}
1639350348.834819: {"jsonrpc":"2.0","method":"channelMessage","params":{"channel":"lightning_board_XRP_JPY","message":{"mid_price":96.05,"bids":[],"asks":[{"price":96.28,"size":0.0},{"price":96.2,"size":310.12},{"price":96.21,"size":0.0}]}}}
1639350348.8619251: {"jsonrpc":"2.0","method":"channelMessage","params":{"channel":"lightning_executions_ETH_JPY","message":[{"id":2284078770,"side":"BUY","price":472200.0,"size":0.02,"exec_date":"2021-12-12T23:05:48.754812Z","buy_child_order_acceptance_id":"JRF20211212-230548-123403","sell_child_order_acceptance_id":"JRF20211212-230249-055914"}]}}
1639350348.9341: {"jsonrpc":"2.0","method":"channelMessage","params":{"channel":"lightning_ticker_FX_BTC_JPY","message":{"product_code":"FX_BTC_JPY","state":"RUNNING","timestamp":"2021-12-12T23:05:48.5667996Z","tick_id":127092043,"best_bid":5867066.0,"best_ask":5867200.0,"best_bid_size":0.02,"best_ask_size":0.01,"total_bid_depth":231.539871680000,"total_ask_depth":291.679024560000,"market_bid_size":0.0,"market_ask_size":0.0,"ltp":5867059.0,"volume":4227.932096850000,"volume_by_product":4227.932096850000}}}
1639350348.942507: {"jsonrpc":"2.0","method":"channelMessage","params":{"channel":"lightning_board_FX_BTC_JPY","message":{"mid_price":5867133.0,"bids":[{"price":5865033.0,"size":0.01},{"price":5865360.0,"size":0.04644039}],"asks":[{"price":5869975.0,"size":0.0},{"price":5869180.0,"size":0.0},{"price":5870977.0,"size":0.0},{"price":5872509.0,"size":0.0},{"price":5869509.0,"size":0.0},{"price":5870062.0,"size":0.0},{"price":5869008.0,"size":0.0}]}}}
1639350348.942702: {"jsonrpc":"2.0","method":"channelMessage","params":{"channel":"lightning_board_XRP_JPY","message":{"mid_price":96.05,"bids":[{"price":95.93,"size":10820.0},{"price":95.42,"size":0.0},{"price":95.81,"size":0.0}],"asks":[{"price":96.35,"size":339.239969},{"price":96.23,"size":0.0}]}}}
1639350348.956398: {"jsonrpc":"2.0","method":"channelMessage","params":{"channel":"lightning_ticker_ETH_JPY","message":{"product_code":"ETH_JPY","state":"RUNNING","timestamp":"2021-12-12T23:05:48.8444877Z","tick_id":26934688,"best_bid":472099.0,"best_ask":472252.0,"best_bid_size":1.52,"best_ask_size":0.01,"total_bid_depth":3327.253367900000,"total_ask_depth":4464.13957320,"market_bid_size":0.0,"market_ask_size":0.0,"ltp":472200.0,"volume":10833.360505500000,"volume_by_product":10833.360505500000}}}
1639350348.961526: {"jsonrpc":"2.0","method":"channelMessage","params":{"channel":"lightning_board_ETH_JPY","message":{"mid_price":472175.0,"bids":[{"price":471676.0,"size":1.0}],"asks":[{"price":472200.0,"size":0.0}]}}}
1639350348.966675: {"jsonrpc":"2.0","method":"channelMessage","params":{"channel":"lightning_ticker_XLM_JPY","message":{"product_code":"XLM_JPY","state":"RUNNING","timestamp":"2021-12-12T23:05:48.7717429Z","tick_id":8300587,"best_bid":31.491,"best_ask":31.57,"best_bid_size":2403.2,"best_ask_size":750.95,"total_bid_depth":1855072.05493760,"total_ask_depth":2110577.197473400000,"market_bid_size":0.0,"market_ask_size":0.0,"ltp":31.471,"volume":1471420.073424000000,"volume_by_product":1471420.073424000000}}}
1639350348.970977: {"jsonrpc":"2.0","method":"channelMessage","params":{"channel":"lightning_board_XLM_JPY","message":{"mid_price":31.53,"bids":[],"asks":[{"price":31.583,"size":0.0}]}}}
1639350349.232768: {"jsonrpc":"2.0","method":"channelMessage","params":{"channel":"lightning_executions_FX_BTC_JPY","message":[{"id":2284079877,"side":"BUY","price":5867650.0,"size":0.02,"exec_date":"2021-12-12T23:05:48.5836497Z","buy_child_order_acceptance_id":"JRF20211212-230548-068891","sell_child_order_acceptance_id":"JRF20211212-230546-199993"},{"id":2284079878,"side":"BUY","price":5867668.0,"size":0.011,"exec_date":"2021-12-12T23:05:48.5836497Z","buy_child_order_acceptance_id":"JRF20211212-230548-068891","sell_child_order_acceptance_id":"JRF20211212-230543-200339"},{"id":2284079879,"side":"BUY","price":5869110.0,"size":0.01,"exec_date":"2021-12-12T23:05:48.5836497Z","buy_child_order_acceptance_id":"JRF20211212-230548-068891","sell_child_order_acceptance_id":"JRF20211212-230252-992488"},{"id":2284079880,"side":"BUY","price":5869161.0,"size":0.01,"exec_date":"2021-12-12T23:05:48.5836497Z","buy_child_order_acceptance_id":"JRF20211212-230548-068891","sell_child_order_acceptance_id":"JRF20211212-230547-224263"},{"id":2284079881,"side":"BUY","price":5869240.0,"size":0.009,"exec_date":"2021-12-12T23:05:48.5836497Z","buy_child_order_acceptance_id":"JRF20211212-230548-068891","sell_child_order_acceptance_id":"JRF20211212-230547-086985"},{"id":2284079882,"side":"BUY","price":5869240.0,"size":0.001,"exec_date":"2021-12-12T23:05:48.6004153Z","buy_child_order_acceptance_id":"JRF20211212-230548-220168","sell_child_order_acceptance_id":"JRF20211212-230547-086985"},{"id":2284079883,"side":"BUY","price":5869422.0,"size":0.011,"exec_date":"2021-12-12T23:05:48.6004153Z","buy_child_order_acceptance_id":"JRF20211212-230548-220168","sell_child_order_acceptance_id":"JRF20211212-230547-219076"},{"id":2284079884,"side":"BUY","price":5869510.0,"size":0.008,"exec_date":"2021-12-12T23:05:48.6004153Z","buy_child_order_acceptance_id":"JRF20211212-230548-220168","sell_child_order_acceptance_id":"JRF20211212-230547-205605"}]}}
1639350349.240154: {"jsonrpc":"2.0","method":"channelMessage","params":{"channel":"lightning_board_FX_BTC_JPY","message":{"mid_price":5867358.0,"bids":[{"price":5865696.0,"size":0.01},{"price":5865148.0,"size":0.15}],"asks":[{"price":5867200.0,"size":0.0},{"price":5867550.0,"size":0.0}]}}}
1639350349.292695: {"jsonrpc":"2.0","method":"channelMessage","params":{"channel":"lightning_board_ETH_JPY","message":{"mid_price":472175.0,"bids":[{"price":470249.0,"size":6.0}],"asks":[{"price":472489.0,"size":0.0}]}}}
1639350349.295722: {"jsonrpc":"2.0","method":"channelMessage","params":{"channel":"lightning_ticker_XRP_JPY","message":{"product_code":"XRP_JPY","state":"RUNNING","timestamp":"2021-12-12T23:05:48.8634874Z","tick_id":12284663,"best_bid":95.97,"best_ask":96.13,"best_bid_size":17012.54584,"best_ask_size":49.479871,"total_bid_depth":1525352.98184100,"total_ask_depth":2294665.449688000000,"market_bid_size":0.0,"market_ask_size":0.0,"ltp":95.96,"volume":1653279.685708000000,"volume_by_product":1653279.685708000000}}}
1639350349.3007512: {"jsonrpc":"2.0","method":"channelMessage","params":{"channel":"lightning_board_XRP_JPY","message":{"mid_price":96.05,"bids":[{"price":95.98,"size":0.0}],"asks":[]}}}
1639350349.305519: {"jsonrpc":"2.0","method":"channelMessage","params":{"channel":"lightning_executions_FX_BTC_JPY","message":[{"id":2284079885,"side":"BUY","price":5869510.0,"size":0.002,"exec_date":"2021-12-12T23:05:48.7185271Z","buy_child_order_acceptance_id":"JRF20211212-230548-200352","sell_child_order_acceptance_id":"JRF20211212-230547-205605"},{"id":2284079886,"side":"BUY","price":5869591.0,"size":0.008,"exec_date":"2021-12-12T23:05:48.7185271Z","buy_child_order_acceptance_id":"JRF20211212-230548-200352","sell_child_order_acceptance_id":"JRF20211212-230500-205477"},{"id":2284079887,"side":"BUY","price":5869591.0,"size":0.017,"exec_date":"2021-12-12T23:05:48.7690727Z","buy_child_order_acceptance_id":"JRF20211212-230548-218948","sell_child_order_acceptance_id":"JRF20211212-230500-205477"},{"id":2284079888,"side":"BUY","price":5869665.0,"size":0.013,"exec_date":"2021-12-12T23:05:48.7690727Z","buy_child_order_acceptance_id":"JRF20211212-230548-218948","sell_child_order_acceptance_id":"JRF20211212-230543-216289"}]}}
1639350349.308073: {"jsonrpc":"2.0","method":"channelMessage","params":{"channel":"lightning_ticker_BTC_EUR","message":{"product_code":"BTC_EUR","state":"RUNNING","timestamp":"2021-12-12T23:05:49.1630509Z","tick_id":7240265,"best_bid":44461.19,"best_ask":44479.65,"best_bid_size":0.00118145,"best_ask_size":0.01,"total_bid_depth":14.57728901,"total_ask_depth":12.55678467,"market_bid_size":0.0,"market_ask_size":0.0,"ltp":44461.2,"volume":43.951523900000,"volume_by_product":43.951523900000}}}
1639350349.311887: {"jsonrpc":"2.0","method":"channelMessage","params":{"channel":"lightning_board_BTC_EUR","message":{"mid_price":44470.42,"bids":[{"price":44261.31,"size":0.18}],"asks":[]}}}
1639350349.332093: {"jsonrpc":"2.0","method":"channelMessage","params":{"channel":"lightning_executions_ETH_JPY","message":[{"id":2284078772,"side":"BUY","price":472252.0,"size":0.01,"exec_date":"2021-12-12T23:05:49.2141194Z","buy_child_order_acceptance_id":"JRF20211212-230548-123405","sell_child_order_acceptance_id":"JRF20211212-225358-205243"}]}}
1639350349.437814: {"jsonrpc":"2.0","method":"channelMessage","params":{"channel":"lightning_board_FX_BTC_JPY","message":{"mid_price":5868867.0,"bids":[{"price":5866477.0,"size":0.04},{"price":5865696.0,"size":0.0},{"price":5865901.0,"size":0.05},{"price":5867066.0,"size":0.0},{"price":5866478.0,"size":0.0},{"price":5863714.0,"size":0.0267539},{"price":5863559.0,"size":0.02},{"price":5867650.0,"size":0.02},{"price":5867564.0,"size":0.02},{"price":5857188.0,"size":0.1},{"price":5865930.0,"size":0.02435637},{"price":5866507.0,"size":0.01},{"price":5865039.0,"size":0.0},{"price":5868070.0,"size":0.021},{"price":5862811.0,"size":0.032},{"price":5859991.0,"size":0.1},{"price":5863547.0,"size":0.02},{"price":5858020.0,"size":0.0},{"price":5865850.0,"size":0.05},{"price":5865510.0,"size":0.05},{"price":5865256.0,"size":0.0},{"price":5853607.0,"size":0.0},{"price":5865148.0,"size":0.0},{"price":5865033.0,"size":0.0},{"price":5866932.0,"size":0.0228625},{"price":5863901.0,"size":0.0},{"price":5851295.0,"size":0.0},{"price":5865360.0,"size":0.0},{"price":5864638.0,"size":0.02},{"price":5848347.0,"size":0.03},{"price":5866757.0,"size":0.05}],"asks":[{"price":5867650.0,"size":0.0},{"price":5867668.0,"size":0.0},{"price":5869110.0,"size":0.0},{"price":5869161.0,"size":0.0},{"price":5869240.0,"size":0.0},{"price":5876616.0,"size":0.04},{"price":5872130.0,"size":0.0},{"price":5869422.0,"size":0.0},{"price":5869510.0,"size":0.0},{"price":5878230.0,"size":0.02},{"price":5871488.0,"size":0.0},{"price":5869591.0,"size":0.0},{"price":5872112.0,"size":0.05},{"price":5880572.0,"size":0.0},{"price":5871487.0,"size":0.02},{"price":5872987.0,"size":0.08558488},{"price":5869665.0,"size":0.007},{"price":5874972.0,"size":0.0},{"price":5873237.0,"size":0.0},{"price":5876582.0,"size":0.1},{"price":5871848.0,"size":0.02},{"price":5872207.0,"size":0.05},{"price":5896406.0,"size":0.02675395},{"price":5872185.0,"size":0.05}]}}}
1639350349.438795: {"jsonrpc":"2.0","method":"channelMessage","params":{"channel":"lightning_ticker_BTCJPY17DEC2021","message":{"product_code":"BTCJPY17DEC2021","state":"RUNNING","timestamp":"2021-12-12T23:05:48.7185271Z","tick_id":115147,"best_bid":5693424.0,"best_ask":5711111.0,"best_bid_size":0.02,"best_ask_size":0.01,"total_bid_depth":53.39,"total_ask_depth":62.29,"market_bid_size":0.0,"market_ask_size":0.0,"ltp":5637555.0,"volume":1.034,"volume_by_product":1.034}}}
1639350349.443615: {"jsonrpc":"2.0","method":"channelMessage","params":{"channel":"lightning_board_BTCJPY17DEC2021","message":{"mid_price":5702267.0,"bids":[{"price":5693424.0,"size":0.02}],"asks":[]}}}
1639350349.449208: {"jsonrpc":"2.0","method":"channelMessage","params":{"channel":"lightning_board_BTC_EUR","message":{"mid_price":44470.42,"bids":[{"price":44348.07,"size":0.18}],"asks":[{"price":44721.1,"size":0.18}]}}}
1639350349.4506009: {"jsonrpc":"2.0","method":"channelMessage","params":{"channel":"lightning_ticker_BTCJPY24DEC2021","message":{"product_code":"BTCJPY24DEC2021","state":"RUNNING","timestamp":"2021-12-12T23:05:49.1802677Z","tick_id":30318,"best_bid":5688641.0,"best_ask":5718215.0,"best_bid_size":0.3,"best_ask_size":0.19,"total_bid_depth":35.68,"total_ask_depth":30.29,"market_bid_size":0.0,"market_ask_size":0.0,"ltp":5481691.0,"volume":0.00,"volume_by_product":0.00}}}
1639350349.456059: {"jsonrpc":"2.0","method":"channelMessage","params":{"channel":"lightning_board_BTCJPY24DEC2021","message":{"mid_price":5703428.0,"bids":[{"price":5688641.0,"size":0.3}],"asks":[]}}}
1639350349.461501: {"jsonrpc":"2.0","method":"channelMessage","params":{"channel":"lightning_board_XRP_JPY","message":{"mid_price":96.05,"bids":[{"price":95.97,"size":27616.54584},{"price":95.84,"size":0.0}],"asks":[{"price":96.24,"size":0.0},{"price":96.39,"size":9000.0}]}}}
1639350349.466027: {"jsonrpc":"2.0","method":"channelMessage","params":{"channel":"lightning_ticker_ETH_JPY","message":{"product_code":"ETH_JPY","state":"RUNNING","timestamp":"2021-12-12T23:05:49.31086Z","tick_id":26934695,"best_bid":472258.0,"best_ask":472400.0,"best_bid_size":0.77,"best_ask_size":0.02,"total_bid_depth":3334.023367900000,"total_ask_depth":4414.10657320,"market_bid_size":0.0,"market_ask_size":0.0,"ltp":472252.0,"volume":10833.370505500000,"volume_by_product":10833.370505500000}}}
1639350349.471395: {"jsonrpc":"2.0","method":"channelMessage","params":{"channel":"lightning_board_ETH_JPY","message":{"mid_price":472329.0,"bids":[{"price":472258.0,"size":0.77}],"asks":[{"price":472252.0,"size":0.0},{"price":474467.0,"size":0.59},{"price":472638.0,"size":0.608},{"price":472952.0,"size":0.0}]}}}
1639350349.475893: {"jsonrpc":"2.0","method":"channelMessage","params":{"channel":"lightning_ticker_XLM_JPY","message":{"product_code":"XLM_JPY","state":"RUNNING","timestamp":"2021-12-12T23:05:49.31086Z","tick_id":8300591,"best_bid":31.506,"best_ask":31.57,"best_bid_size":4018.0,"best_ask_size":750.95,"total_bid_depth":1859090.05493760,"total_ask_depth":2098697.197473400000,"market_bid_size":0.0,"market_ask_size":0.0,"ltp":31.471,"volume":1471420.073424000000,"volume_by_product":1471420.073424000000}}}
1639350349.481087: {"jsonrpc":"2.0","method":"channelMessage","params":{"channel":"lightning_board_XLM_JPY","message":{"mid_price":31.538,"bids":[{"price":31.456,"size":0.0},{"price":31.506,"size":4018.0},{"price":31.427,"size":11880.0}],"asks":[{"price":31.592,"size":0.0}]}}}
1639350349.4946291: {"jsonrpc":"2.0","method":"channelMessage","params":{"channel":"lightning_ticker_MONA_JPY","message":{"product_code":"MONA_JPY","state":"RUNNING","timestamp":"2021-12-12T23:05:49.2909642Z","tick_id":1298064,"best_bid":165.021,"best_ask":166.998,"best_bid_size":98.0,"best_ask_size":0.80479767,"total_bid_depth":104378.54458855,"total_ask_depth":165292.58885022,"market_bid_size":0.0,"market_ask_size":0.0,"ltp":166.0,"volume":9933.778937320000,"volume_by_product":9933.778937320000}}}
1639350349.500905: {"jsonrpc":"2.0","method":"channelMessage","params":{"channel":"lightning_board_MONA_JPY","message":{"mid_price":166.009,"bids":[],"asks":[{"price":167.999,"size":0.0}]}}}
1639350349.5531971: {"jsonrpc":"2.0","method":"channelMessage","params":{"channel":"lightning_executions_FX_BTC_JPY","message":[{"id":2284079889,"side":"BUY","price":5869665.0,"size":0.007,"exec_date":"2021-12-12T23:05:49.4331321Z","buy_child_order_acceptance_id":"JRF20211212-230549-208836","sell_child_order_acceptance_id":"JRF20211212-230543-216289"}]}}
1639350349.600806: {"jsonrpc":"2.0","method":"channelMessage","params":{"channel":"lightning_executions_FX_BTC_JPY","message":[{"id":2284079890,"side":"BUY","price":5869798.0,"size":0.01,"exec_date":"2021-12-12T23:05:49.4499691Z","buy_child_order_acceptance_id":"JRF20211212-230549-205612","sell_child_order_acceptance_id":"JRF20211212-230547-202740"},{"id":2284079891,"side":"BUY","price":5869997.0,"size":0.01,"exec_date":"2021-12-12T23:05:49.4499691Z","buy_child_order_acceptance_id":"JRF20211212-230549-122301","sell_child_order_acceptance_id":"JRF20211212-230500-180955"}]}}
1639350349.6145668: {"jsonrpc":"2.0","method":"channelMessage","params":{"channel":"lightning_ticker_FX_BTC_JPY","message":{"product_code":"FX_BTC_JPY","state":"RUNNING","timestamp":"2021-12-12T23:05:49.3150581Z","tick_id":127092153,"best_bid":5869078.0,"best_ask":5869665.0,"best_bid_size":0.01946442,"best_ask_size":0.007,"total_bid_depth":231.520681370000,"total_ask_depth":291.430397570000,"market_bid_size":0.0,"market_ask_size":0.0,"ltp":5869665.0,"volume":4228.072096850000,"volume_by_product":4228.072096850000}}}
1639350349.621331: {"jsonrpc":"2.0","method":"channelMessage","params":{"channel":"lightning_board_FX_BTC_JPY","message":{"mid_price":5869371.0,"bids":[{"price":5867790.0,"size":0.01},{"price":5867067.0,"size":0.2},{"price":5863501.0,"size":0.05},{"price":5863630.0,"size":0.1},{"price":5866478.0,"size":0.0},{"price":5863784.0,"size":0.0},{"price":5866113.0,"size":0.05},{"price":5866340.0,"size":0.12},{"price":5867078.0,"size":0.03},{"price":5853534.0,"size":0.0},{"price":5858059.0,"size":0.02675395},{"price":5869078.0,"size":0.01946442},{"price":5865930.0,"size":0.04867766},{"price":5858860.0,"size":0.1},{"price":5858025.0,"size":0.0},{"price":5862570.0,"size":0.0},{"price":5864648.0,"size":0.02},{"price":5862266.0,"size":0.0},{"price":5867883.0,"size":0.06},{"price":5867200.0,"size":0.01},{"price":5866483.0,"size":0.0729698},{"price":5867963.0,"size":0.01},{"price":5868136.0,"size":0.05},{"price":5852947.0,"size":0.0},{"price":5858064.0,"size":0.01},{"price":5867964.0,"size":0.01},{"price":5858034.0,"size":0.0},{"price":5861748.0,"size":0.0},{"price":5857614.0,"size":0.0},{"price":5866226.0,"size":0.1},{"price":5864791.0,"size":0.0},{"price":5867700.0,"size":0.01},{"price":5865853.0,"size":0.05}],"asks":[{"price":5892123.0,"size":0.0},{"price":5895572.0,"size":0.0267539},{"price":5874005.0,"size":0.05},{"price":5873323.0,"size":0.05},{"price":5872935.0,"size":0.12},{"price":5872066.0,"size":0.04946442},{"price":5896401.0,"size":0.01},{"price":5873658.0,"size":0.1},{"price":5880558.0,"size":0.0}]}}}
1639350349.622087: {"jsonrpc":"2.0","method":"channelMessage","params":{"channel":"lightning_board_BTC_EUR","message":{"mid_price":44470.42,"bids":[],"asks":[{"price":44637.28,"size":0.13}]}}}
1639350349.632722: {"jsonrpc":"2.0","method":"channelMessage","params":{"channel":"lightning_board_XLM_JPY","message":{"mid_price":31.538,"bids":[{"price":31.468,"size":0.0}],"asks":[{"price":31.624,"size":11880.0}]}}}
1639350349.6422558: {"jsonrpc":"2.0","method":"channelMessage","params":{"channel":"lightning_board_XRP_JPY","message":{"mid_price":96.05,"bids":[{"price":95.69,"size":9000.0}],"asks":[{"price":96.33,"size":24663.0}]}}}
1639350349.654758: {"jsonrpc":"2.0","method":"channelMessage","params":{"channel":"lightning_board_ETH_JPY","message":{"mid_price":472337.0,"bids":[{"price":472274.0,"size":1.1037908},{"price":472069.0,"size":0.57}],"asks":[{"price":472902.0,"size":0.0}]}}}
1639350349.758241: {"jsonrpc":"2.0","method":"channelMessage","params":{"channel":"lightning_board_FX_BTC_JPY","message":{"mid_price":5870296.0,"bids":[{"price":5867564.0,"size":0.0},{"price":5863473.0,"size":0.02},{"price":5867650.0,"size":0.0},{"price":5866483.0,"size":0.0829698},{"price":5867200.0,"size":0.03},{"price":5869404.0,"size":0.01},{"price":5867497.0,"size":0.01},{"price":5869924.0,"size":0.06653558},{"price":5865901.0,"size":0.0},{"price":5865850.0,"size":0.0},{"price":5865510.0,"size":0.0},{"price":5866480.0,"size":0.02},{"price":5866340.0,"size":0.0},{"price":5861705.0,"size":0.47773664},{"price":5856966.0,"size":0.1},{"price":5861436.0,"size":0.0},{"price":5865924.0,"size":0.0},{"price":5859613.0,"size":0.1},{"price":5505878.0,"size":0.0}],"asks":[{"price":5869665.0,"size":0.0},{"price":5873589.0,"size":0.1},{"price":5896402.0,"size":0.02678456},{"price":5870669.0,"size":0.02},{"price":5871647.0,"size":0.01},{"price":5897723.0,"size":0.01},{"price":5873654.0,"size":0.0},{"price":5869798.0,"size":0.0},{"price":5869997.0,"size":0.0},{"price":5873741.0,"size":0.04964016},{"price":5873776.0,"size":0.02},{"price":5872112.0,"size":0.0},{"price":5872491.0,"size":0.0}]}}}
1639350349.785504: {"jsonrpc":"2.0","method":"channelMessage","params":{"channel":"lightning_ticker_BTC_USD","message":{"product_code":"BTC_USD","state":"RUNNING","timestamp":"2021-12-12T23:05:49.5524941Z","tick_id":17933057,"best_bid":50286.47,"best_ask":50316.83,"best_bid_size":0.6003,"best_ask_size":0.01,"total_bid_depth":25.99365669,"total_ask_depth":17.34281796,"market_bid_size":0.0,"market_ask_size":0.0,"ltp":50296.90,"volume":250.190018300000,"volume_by_product":250.190018300000}}}
1639350349.790161: {"jsonrpc":"2.0","method":"channelMessage","params":{"channel":"lightning_board_BTC_USD","message":{"mid_price":50301.65,"bids":[{"price":49873.3,"size":0.0},{"price":49833.04,"size":0.0},{"price":49913.55,"size":0.0}],"asks":[{"price":50338.35,"size":0.0},{"price":50718.62,"size":0.0},{"price":50799.12,"size":0.0},{"price":50758.87,"size":0.0}]}}}
1639350349.811291: {"jsonrpc":"2.0","method":"channelMessage","params":{"channel":"lightning_board_ETH_JPY","message":{"mid_price":472337.0,"bids":[{"price":471516.0,"size":0.0},{"price":471171.0,"size":0.0}],"asks":[{"price":473649.0,"size":14.83}]}}}
1639350349.827997: {"jsonrpc":"2.0","method":"channelMessage","params":{"channel":"lightning_ticker_BTC_EUR","message":{"product_code":"BTC_EUR","state":"RUNNING","timestamp":"2021-12-12T23:05:49.6205084Z","tick_id":7240269,"best_bid":44461.19,"best_ask":44479.65,"best_bid_size":0.00118145,"best_ask_size":0.01,"total_bid_depth":14.75728901,"total_ask_depth":12.68678467,"market_bid_size":0.0,"market_ask_size":0.0,"ltp":44461.2,"volume":43.951523900000,"volume_by_product":43.951523900000}}}
1639350349.833212: {"jsonrpc":"2.0","method":"channelMessage","params":{"channel":"lightning_board_BTC_EUR","message":{"mid_price":44470.42,"bids":[],"asks":[{"price":44721.1,"size":0.0}]}}}
1639350349.838469: {"jsonrpc":"2.0","method":"channelMessage","params":{"channel":"lightning_ticker_XRP_JPY","message":{"product_code":"XRP_JPY","state":"RUNNING","timestamp":"2021-12-12T23:05:49.6205084Z","tick_id":12284670,"best_bid":95.97,"best_ask":96.13,"best_bid_size":27616.54584,"best_ask_size":49.479871,"total_bid_depth":1523774.98184100,"total_ask_depth":2304689.449688000000,"market_bid_size":0.0,"market_ask_size":0.0,"ltp":95.96,"volume":1653279.685708000000,"volume_by_product":1653279.685708000000}}}
1639350349.844985: {"jsonrpc":"2.0","method":"channelMessage","params":{"channel":"lightning_board_XRP_JPY","message":{"mid_price":96.05,"bids":[{"price":95.87,"size":0.0}],"asks":[]}}}
1639350349.855198: {"jsonrpc":"2.0","method":"channelMessage","params":{"channel":"lightning_board_XLM_JPY","message":{"mid_price":31.538,"bids":[],"asks":[{"price":31.591,"size":751.0}]}}}
1639350349.870964: {"jsonrpc":"2.0","method":"channelMessage","params":{"channel":"lightning_board_FX_BTC_JPY","message":{"mid_price":5870296.0,"bids":[{"price":5863503.0,"size":0.1},{"price":5866932.0,"size":0.0},{"price":5868900.0,"size":0.0},{"price":5859959.0,"size":0.0},{"price":5864243.0,"size":0.02911856},{"price":5861374.0,"size":0.0},{"price":5867650.0,"size":0.0},{"price":5862002.0,"size":0.1},{"price":5868071.0,"size":0.35},{"price":5867709.0,"size":0.022},{"price":5868423.0,"size":0.2316171},{"price":5867582.0,"size":0.01},{"price":5863501.0,"size":0.0},{"price":5869724.0,"size":0.02},{"price":5865147.0,"size":0.0},{"price":5866113.0,"size":0.0},{"price":5863547.0,"size":0.03},{"price":5868537.0,"size":0.03},{"price":5866757.0,"size":0.0},{"price":5784806.0,"size":0.02},{"price":5866477.0,"size":0.02},{"price":5867200.0,"size":0.01},{"price":5863039.0,"size":0.02432111},{"price":5868070.0,"size":0.02},{"price":5865007.0,"size":0.0},{"price":5863630.0,"size":0.0},{"price":5862811.0,"size":0.0},{"price":5865170.0,"size":0.0},{"price":5858063.0,"size":0.02678456},{"price":5866226.0,"size":0.0},{"price":5869423.0,"size":0.04644039},{"price":5868300.0,"size":0.01},{"price":5869078.0,"size":0.0},{"price":5857188.0,"size":0.0},{"price":5863286.0,"size":0.0},{"price":5865853.0,"size":0.0},{"price":5868428.0,"size":0.05}],"asks":[{"price":5872935.0,"size":0.0},{"price":5878121.0,"size":0.5},{"price":5880798.0,"size":0.1},{"price":5874350.0,"size":0.01},{"price":5876616.0,"size":0.0},{"price":5874005.0,"size":0.0},{"price":5874064.0,"size":0.01},{"price":5872066.0,"size":0.0},{"price":5872185.0,"size":0.0},{"price":5871647.0,"size":0.0},{"price":5871426.0,"size":0.01},{"price":5873323.0,"size":0.0},{"price":5873589.0,"size":0.0},{"price":5874937.0,"size":0.01},{"price":5872207.0,"size":0.0}]}}}
1639350349.959187: {"jsonrpc":"2.0","method":"channelMessage","params":{"channel":"lightning_executions_FX_BTC_JPY","message":[{"id":2284079892,"side":"BUY","price":5870638.0,"size":0.02,"exec_date":"2021-12-12T23:05:49.7355011Z","buy_child_order_acceptance_id":"JRF20211212-230549-202751","sell_child_order_acceptance_id":"JRF20211212-230549-086998"},{"id":2284079893,"side":"BUY","price":5870669.0,"size":0.02,"exec_date":"2021-12-12T23:05:49.7355011Z","buy_child_order_acceptance_id":"JRF20211212-230549-202751","sell_child_order_acceptance_id":"JRF20211212-230549-210170"},{"id":2284079894,"side":"BUY","price":5870739.0,"size":0.01,"exec_date":"2021-12-12T23:05:49.7355011Z","buy_child_order_acceptance_id":"JRF20211212-230549-202751","sell_child_order_acceptance_id":"JRF20211212-230459-001728"},{"id":2284079895,"side":"BUY","price":5871426.0,"size":0.01,"exec_date":"2021-12-12T23:05:49.7355011Z","buy_child_order_acceptance_id":"JRF20211212-230549-202751","sell_child_order_acceptance_id":"JRF20211212-230549-205614"},{"id":2284079896,"side":"BUY","price":5871487.0,"size":0.02,"exec_date":"2021-12-12T23:05:49.7355011Z","buy_child_order_acceptance_id":"JRF20211212-230549-202751","sell_child_order_acceptance_id":"JRF20211212-230548-002396"},{"id":2284079897,"side":"BUY","price":5871848.0,"size":0.02,"exec_date":"2021-12-12T23:05:49.7355011Z","buy_child_order_acceptance_id":"JRF20211212-230549-202751","sell_child_order_acceptance_id":"JRF20211212-230548-083290"},{"id":2284079898,"side":"BUY","price":5871849.0,"size":0.07,"exec_date":"2021-12-12T23:05:49.7355011Z","buy_child_order_acceptance_id":"JRF20211212-230549-202751","sell_child_order_acceptance_id":"JRF20211212-230533-180998"}]}}
1639350349.9593332: {"jsonrpc":"2.0","method":"channelMessage","params":{"channel":"lightning_executions_XRP_JPY","message":[{"id":2284078776,"side":"BUY","price":96.13,"size":49.479871,"exec_date":"2021-12-12T23:05:49.8552826Z","buy_child_order_acceptance_id":"JRF20211212-230549-199006","sell_child_order_acceptance_id":"JRF20211212-223856-208315"}]}}
1639350349.97722: {"jsonrpc":"2.0","method":"channelMessage","params":{"channel":"lightning_board_FX_BTC_JPY","message":{"mid_price":5870281.0,"bids":[{"price":5864243.0,"size":0.0},{"price":5863039.0,"size":0.0},{"price":5863014.0,"size":0.0},{"price":5845403.0,"size":0.0}],"asks":[{"price":5872987.0,"size":0.0},{"price":5870638.0,"size":0.02}]}}}
1639350349.979469: {"jsonrpc":"2.0","method":"channelMessage","params":{"channel":"lightning_board_XRP_JPY","message":{"mid_price":96.07,"bids":[{"price":96.01,"size":10268.0},{"price":95.83,"size":0.0}],"asks":[{"price":96.29,"size":1705.66},{"price":96.43,"size":0.0},{"price":96.33,"size":10953.0}]}}}
1639350350.0064871: {"jsonrpc":"2.0","method":"channelMessage","params":{"channel":"lightning_board_BTC_EUR","message":{"mid_price":44470.42,"bids":[{"price":44443.58,"size":0.50134},{"price":44356.59,"size":0.0}],"asks":[{"price":44573.1,"size":0.50134},{"price":44546.37,"size":0.50134}]}}}
1639350350.016103: {"jsonrpc":"2.0","method":"channelMessage","params":{"channel":"lightning_board_BTC_USD","message":{"mid_price":50301.65,"bids":[],"asks":[{"price":50345.9,"size":0.0}]}}}
1639350350.021316: {"jsonrpc":"2.0","method":"channelMessage","params":{"channel":"lightning_ticker_ETH_JPY","message":{"product_code":"ETH_JPY","state":"RUNNING","timestamp":"2021-12-12T23:05:49.8422843Z","tick_id":26934705,"best_bid":472274.0,"best_ask":472400.0,"best_bid_size":1.1037908,"best_ask_size":0.02,"total_bid_depth":3289.617158700000,"total_ask_depth":4414.85657320,"market_bid_size":0.0,"market_ask_size":0.0,"ltp":472252.0,"volume":10833.370505500000,"volume_by_product":10833.370505500000}}}
1639350350.029402: {"jsonrpc":"2.0","method":"channelMessage","params":{"channel":"lightning_board_ETH_JPY","message":{"mid_price":472337.0,"bids":[{"price":471379.0,"size":0.0},{"price":471252.0,"size":0.0}],"asks":[{"price":472483.0,"size":0.75}]}}}
1639350350.1345978: {"jsonrpc":"2.0","method":"channelMessage","params":{"channel":"lightning_ticker_FX_BTC_JPY","message":{"product_code":"FX_BTC_JPY","state":"RUNNING","timestamp":"2021-12-12T23:05:49.9324247Z","tick_id":127092290,"best_bid":5869724.0,"best_ask":5871849.0,"best_bid_size":0.02,"best_ask_size":0.407,"total_bid_depth":232.624807100000,"total_ask_depth":291.218334390000,"market_bid_size":0.0,"market_ask_size":0.0,"ltp":5871849.0,"volume":4228.269096850000,"volume_by_product":4228.269096850000}}}
1639350350.13891: {"jsonrpc":"2.0","method":"channelMessage","params":{"channel":"lightning_board_FX_BTC_JPY","message":{"mid_price":5870786.0,"bids":[{"price":5865259.0,"size":0.02911856},{"price":5868626.0,"size":0.1},{"price":5868423.0,"size":0.0},{"price":5867700.0,"size":0.02},{"price":5868271.0,"size":0.05},{"price":5869416.0,"size":0.02283041},{"price":5868998.0,"size":0.01},{"price":5868142.0,"size":0.01},{"price":5869924.0,"size":0.0},{"price":5869079.0,"size":0.0},{"price":5868995.0,"size":0.05},{"price":5850774.0,"size":0.0},{"price":5847844.0,"size":0.0},{"price":5844914.0,"size":0.0},{"price":5866507.0,"size":0.0},{"price":5835949.0,"size":0.0},{"price":5869663.0,"size":0.05},{"price":5869307.0,"size":0.01},{"price":5868835.0,"size":0.05},{"price":5868828.0,"size":0.1},{"price":5863503.0,"size":0.0},{"price":5861119.0,"size":0.5},{"price":5869202.0,"size":0.12},{"price":5855873.0,"size":0.0}],"asks":[{"price":5870638.0,"size":0.0},{"price":5870669.0,"size":0.0},{"price":5870739.0,"size":0.0},{"price":5871426.0,"size":0.0},{"price":5871487.0,"size":0.0},{"price":5871848.0,"size":0.0},{"price":5871849.0,"size":0.407},{"price":5873741.0,"size":0.0},{"price":5881462.0,"size":0.0},{"price":5893134.0,"size":0.0},{"price":5875180.0,"size":0.0},{"price":5878113.0,"size":0.0},{"price":5881046.0,"size":0.0},{"price":5875072.0,"size":0.05},{"price":5892114.0,"size":0.0}]}}}
1639350350.150248: {"jsonrpc":"2.0","method":"channelMessage","params":{"channel":"lightning_board_XRP_JPY","message":{"mid_price":96.1,"bids":[{"price":95.9,"size":0.0}],"asks":[{"price":96.13,"size":0.0},{"price":96.34,"size":5540.0},{"price":96.39,"size":0.0},{"price":96.35,"size":0.0}]}}}
1639350350.168729: {"jsonrpc":"2.0","method":"channelMessage","params":{"channel":"lightning_ticker_XLM_JPY","message":{"product_code":"XLM_JPY","state":"RUNNING","timestamp":"2021-12-12T23:05:49.9455527Z","tick_id":8300596,"best_bid":31.506,"best_ask":31.57,"best_bid_size":4018.0,"best_ask_size":750.95,"total_bid_depth":1855354.05493760,"total_ask_depth":2111609.197473400000,"market_bid_size":0.0,"market_ask_size":0.0,"ltp":31.471,"volume":1471420.073424000000,"volume_by_product":1471420.073424000000}}}
1639350350.172357: {"jsonrpc":"2.0","method":"channelMessage","params":{"channel":"lightning_board_XLM_JPY","message":{"mid_price":31.538,"bids":[],"asks":[{"price":31.594,"size":0.0},{"price":31.62,"size":4017.0}]}}}
1639350350.184726: {"jsonrpc":"2.0","method":"channelMessage","params":{"channel":"lightning_board_ETH_JPY","message":{"mid_price":472337.0,"bids":[{"price":472099.0,"size":2.27},{"price":471660.0,"size":0.0},{"price":472258.0,"size":0.0},{"price":472211.0,"size":0.67}],"asks":[{"price":474467.0,"size":0.0}]}}}
1639350350.198407: {"jsonrpc":"2.0","method":"channelMessage","params":{"channel":"lightning_board_BTC_EUR","message":{"mid_price":44470.42,"bids":[{"price":44348.07,"size":0.0},{"price":44261.31,"size":0.0},{"price":43711.83,"size":0.0}],"asks":[{"price":44637.28,"size":0.0},{"price":44736.28,"size":0.18},{"price":44630.06,"size":0.056},{"price":44518.0,"size":0.0}]}}}
1639350350.240591: {"jsonrpc":"2.0","method":"channelMessage","params":{"channel":"lightning_board_FX_BTC_JPY","message":{"mid_price":5871692.0,"bids":[{"price":5868136.0,"size":0.0},{"price":5867883.0,"size":0.0},{"price":5870583.0,"size":0.05},{"price":5869416.0,"size":0.0},{"price":5865229.0,"size":0.02911856},{"price":5860887.0,"size":0.0},{"price":5868071.0,"size":0.2},{"price":5866496.0,"size":0.05},{"price":5864057.0,"size":0.02911856},{"price":5869925.0,"size":0.2},{"price":5863568.0,"size":0.02679844},{"price":5871535.0,"size":0.02},{"price":5848477.0,"size":0.05},{"price":5868538.0,"size":0.15},{"price":5848347.0,"size":0.04},{"price":5869997.0,"size":0.02}],"asks":[{"price":5875831.0,"size":0.05},{"price":5874620.0,"size":0.04946442},{"price":5875311.0,"size":0.12},{"price":5883526.0,"size":0.0},{"price":5874951.0,"size":0.0},{"price":5875164.0,"size":0.05},{"price":5875270.0,"size":0.05},{"price":5875077.0,"size":0.01},{"price":5899414.0,"size":0.02679844},{"price":5874936.0,"size":0.1}]}}}
1639350350.322607: {"jsonrpc":"2.0","method":"channelMessage","params":{"channel":"lightning_board_XRP_JPY","message":{"mid_price":96.1,"bids":[{"price":95.93,"size":11336.893},{"price":95.88,"size":0.0}],"asks":[{"price":96.5,"size":0.0}]}}}
1639350350.3494809: {"jsonrpc":"2.0","method":"channelMessage","params":{"channel":"lightning_board_ETH_JPY","message":{"mid_price":472337.0,"bids":[{"price":471614.0,"size":0.75}],"asks":[]}}}
1639350350.3838289: {"jsonrpc":"2.0","method":"channelMessage","params":{"channel":"lightning_board_FX_BTC_JPY","message":{"mid_price":5871216.0,"bids":[{"price":5868538.0,"size":0.0},{"price":5869241.0,"size":0.05},{"price":5871535.0,"size":0.0},{"price":5867964.0,"size":0.0},{"price":5869902.0,"size":0.23156092},{"price":5869424.0,"size":0.15},{"price":5867078.0,"size":0.0},{"price":5869729.0,"size":0.01},{"price":5869857.0,"size":0.03},{"price":5867700.0,"size":0.01}],"asks":[{"price":5876525.0,"size":0.05},{"price":5890463.0,"size":0.02},{"price":5886824.0,"size":0.05},{"price":5875318.0,"size":0.04964016}]}}}
1639350350.5113358: {"jsonrpc":"2.0","method":"channelMessage","params":{"channel":"lightning_board_FX_BTC_JPY","message":{"mid_price":5871216.0,"bids":[{"price":5869883.0,"size":0.02281047},{"price":5869830.0,"size":0.01},{"price":5852293.0,"size":0.02},{"price":5863559.0,"size":0.0},{"price":5869669.0,"size":0.02432111},{"price":5869424.0,"size":0.0},{"price":5859274.0,"size":0.0}],"asks":[{"price":5876955.0,"size":0.02911856},{"price":5892108.0,"size":0.0}]}}}
1639350350.556884: {"jsonrpc":"2.0","method":"channelMessage","params":{"channel":"lightning_ticker_XRP_JPY","message":{"product_code":"XRP_JPY","state":"RUNNING","timestamp":"2021-12-12T23:05:50.3851933Z","tick_id":12284685,"best_bid":96.01,"best_ask":96.29,"best_bid_size":10268.0,"best_ask_size":1705.66,"total_bid_depth":1514241.24322300,"total_ask_depth":2149860.269848000000,"market_bid_size":0.0,"market_ask_size":0.0,"ltp":96.13,"volume":1653329.165579000000,"volume_by_product":1653329.165579000000}}}
1639350350.566261: {"jsonrpc":"2.0","method":"channelMessage","params":{"channel":"lightning_board_XRP_JPY","message":{"mid_price":96.15,"bids":[],"asks":[{"price":96.4,"size":9584.0},{"price":96.2,"size":0.0}]}}}
1639350350.576684: {"jsonrpc":"2.0","method":"channelMessage","params":{"channel":"lightning_board_XLM_JPY","message":{"mid_price":31.542,"bids":[{"price":31.491,"size":0.0}],"asks":[{"price":31.57,"size":0.0}]}}}
1639350350.582977: {"jsonrpc":"2.0","method":"channelMessage","params":{"channel":"lightning_ticker_ETH_JPY","message":{"product_code":"ETH_JPY","state":"RUNNING","timestamp":"2021-12-12T23:05:50.3851933Z","tick_id":26934713,"best_bid":472211.0,"best_ask":472400.0,"best_bid_size":0.67,"best_ask_size":0.02,"total_bid_depth":3273.533417900000,"total_ask_depth":4414.26657320,"market_bid_size":0.0,"market_ask_size":0.0,"ltp":472252.0,"volume":10833.370505500000,"volume_by_product":10833.370505500000}}}
1639350350.591685: {"jsonrpc":"2.0","method":"channelMessage","params":{"channel":"lightning_board_ETH_JPY","message":{"mid_price":472305.0,"bids":[{"price":472274.0,"size":0.0}],"asks":[]}}}
1639350350.595548: {"jsonrpc":"2.0","method":"channelMessage","params":{"channel":"lightning_ticker_BTC_USD","message":{"product_code":"BTC_USD","state":"RUNNING","timestamp":"2021-12-12T23:05:50.4424133Z","tick_id":17933062,"best_bid":50286.47,"best_ask":50316.83,"best_bid_size":0.6003,"best_ask_size":0.01,"total_bid_depth":26.44365669,"total_ask_depth":17.37251796,"market_bid_size":0.0,"market_ask_size":0.0,"ltp":50296.90,"volume":250.190018300000,"volume_by_product":250.190018300000}}}
1639350350.600826: {"jsonrpc":"2.0","method":"channelMessage","params":{"channel":"lightning_board_BTC_USD","message":{"mid_price":50301.65,"bids":[{"price":49918.42,"size":0.27},{"price":49958.71,"size":0.18}],"asks":[{"price":50764.5,"size":0.18},{"price":50845.08,"size":0.45}]}}}
1639350350.6205812: {"jsonrpc":"2.0","method":"channelMessage","params":{"channel":"lightning_board_FX_BTC_JPY","message":{"mid_price":5871668.0,"bids":[{"price":5871487.0,"size":0.06},{"price":5869725.0,"size":0.15},{"price":5869999.0,"size":0.025},{"price":5851409.0,"size":0.05},{"price":5868101.0,"size":0.02},{"price":5869830.0,"size":0.0},{"price":5865495.0,"size":0.04},{"price":5842828.0,"size":0.04},{"price":5862308.0,"size":0.1},{"price":5870449.0,"size":0.02},{"price":5855805.0,"size":0.0},{"price":5867497.0,"size":0.0}],"asks":[{"price":5900084.0,"size":0.04},{"price":5876805.0,"size":0.02911856}]}}}
1639350350.696676: {"jsonrpc":"2.0","method":"channelMessage","params":{"channel":"lightning_board_XRP_JPY","message":{"mid_price":96.24,"bids":[{"price":96.2,"size":359.599871}],"asks":[{"price":117.7,"size":500.0},{"price":96.49,"size":13710.0},{"price":96.75,"size":139250.0}]}}}
1639350350.716738: {"jsonrpc":"2.0","method":"channelMessage","params":{"channel":"lightning_board_BTC_USD","message":{"mid_price":50301.65,"bids":[{"price":49878.13,"size":0.45}],"asks":[{"price":50335.52,"size":1.0},{"price":50804.79,"size":0.27}]}}}
1639350350.721898: {"jsonrpc":"2.0","method":"channelMessage","params":{"channel":"lightning_ticker_BTC_EUR","message":{"product_code":"BTC_EUR","state":"RUNNING","timestamp":"2021-12-12T23:05:50.5777196Z","tick_id":7240285,"best_bid":44461.19,"best_ask":44479.65,"best_bid_size":0.00118145,"best_ask_size":0.01,"total_bid_depth":14.74728901,"total_ask_depth":13.76712467,"market_bid_size":0.0,"market_ask_size":0.0,"ltp":44461.2,"volume":43.951523900000,"volume_by_product":43.951523900000}}}
1639350350.727205: {"jsonrpc":"2.0","method":"channelMessage","params":{"channel":"lightning_board_BTC_EUR","message":{"mid_price":44470.42,"bids":[{"price":44274.46,"size":0.18},{"price":44361.25,"size":0.18}],"asks":[{"price":44650.9,"size":0.13},{"price":44630.06,"size":0.0},{"price":45427.26,"size":0.399}]}}}
1639350350.729316: {"jsonrpc":"2.0","method":"channelMessage","params":{"channel":"lightning_executions_BTC_USD","message":[{"id":2284078781,"side":"BUY","price":50316.83,"size":0.01,"exec_date":"2021-12-12T23:05:50.594638Z","buy_child_order_acceptance_id":"JRF20211212-230549-209479","sell_child_order_acceptance_id":"JRF20211212-230350-707600"}]}}
1639350350.743009: {"jsonrpc":"2.0","method":"channelMessage","params":{"channel":"lightning_board_ETH_JPY","message":{"mid_price":472375.0,"bids":[{"price":472350.0,"size":0.58}],"asks":[]}}}
1639350350.746908: {"jsonrpc":"2.0","method":"channelMessage","params":{"channel":"lightning_ticker_FX_BTC_JPY","message":{"product_code":"FX_BTC_JPY","state":"RUNNING","timestamp":"2021-12-12T23:05:50.6484916Z","tick_id":127092366,"best_bid":5870583.0,"best_ask":5871849.0,"best_bid_size":0.0500,"best_ask_size":0.407,"total_bid_depth":233.433967300000,"total_ask_depth":292.070440520000,"market_bid_size":0.0,"market_ask_size":0.0,"ltp":5871849.0,"volume":4228.269096850000,"volume_by_product":4228.269096850000}}}
1639350350.761973: {"jsonrpc":"2.0","method":"channelMessage","params":{"channel":"lightning_board_FX_BTC_JPY","message":{"mid_price":5871216.0,"bids":[{"price":5863574.0,"size":0.02677039},{"price":5866492.0,"size":0.1},{"price":5862587.0,"size":0.0},{"price":5871487.0,"size":0.0},{"price":5863547.0,"size":0.02},{"price":5854341.0,"size":0.05}],"asks":[{"price":5883888.0,"size":0.05},{"price":5899408.0,"size":0.02677039},{"price":5892103.0,"size":0.0},{"price":5878246.0,"size":0.04},{"price":5876153.0,"size":0.08558488},{"price":5873271.0,"size":0.01},{"price":5877746.0,"size":0.02911856}]}}}
1639350350.8540092: {"jsonrpc":"2.0","method":"channelMessage","params":{"channel":"lightning_board_BTC_USD","message":{"mid_price":50320.68,"bids":[{"price":50263.53,"size":0.0},{"price":50286.47,"size":0.0},{"price":50316.82,"size":1.2006},{"price":50278.93,"size":0.0},{"price":50316.23,"size":0.6003}],"asks":[{"price":50316.83,"size":0.0},{"price":50384.43,"size":0.6003},{"price":50376.87,"size":0.6003}]}}}
1639350350.8779159: {"jsonrpc":"2.0","method":"channelMessage","params":{"channel":"lightning_board_ETH_JPY","message":{"mid_price":472375.0,"bids":[{"price":471736.0,"size":0.0}],"asks":[{"price":472483.0,"size":0.0}]}}}
1639350350.887747: {"jsonrpc":"2.0","method":"channelMessage","params":{"channel":"lightning_board_XRP_JPY","message":{"mid_price":96.24,"bids":[{"price":95.93,"size":10820.0},{"price":95.98,"size":4652.1}],"asks":[{"price":96.32,"size":465.21}]}}}
1639350350.936235: {"jsonrpc":"2.0","method":"channelMessage","params":{"channel":"lightning_board_FX_BTC_JPY","message":{"mid_price":5871216.0,"bids":[{"price":5519412.0,"size":0.01},{"price":5869724.0,"size":0.0},{"price":5863579.0,"size":0.02675389},{"price":5865930.0,"size":0.02432129},{"price":5869725.0,"size":0.0},{"price":5836317.0,"size":0.0},{"price":5867700.0,"size":0.0},{"price":5869404.0,"size":0.0},{"price":5869424.0,"size":0.15},{"price":5851059.0,"size":0.0}],"asks":[{"price":5899403.0,"size":0.02675389},{"price":5872000.0,"size":0.22},{"price":5877713.0,"size":0.02911856},{"price":5880952.0,"size":0.05}]}}}
1639350351.010365: {"jsonrpc":"2.0","method":"channelMessage","params":{"channel":"lightning_executions_ETH_JPY","message":[{"id":2284078784,"side":"BUY","price":472400.0,"size":0.02,"exec_date":"2021-12-12T23:05:50.8912618Z","buy_child_order_acceptance_id":"JRF20211212-230550-211434","sell_child_order_acceptance_id":"JRF20211212-214408-078132"},{"id":2284078785,"side":"BUY","price":472500.0,"size":0.01,"exec_date":"2021-12-12T23:05:50.8912618Z","buy_child_order_acceptance_id":"JRF20211212-230550-211434","sell_child_order_acceptance_id":"JRF20211212-215759-085706"},{"id":2284078786,"side":"BUY","price":472600.0,"size":0.02,"exec_date":"2021-12-12T23:05:50.8912618Z","buy_child_order_acceptance_id":"JRF20211212-230550-211434","sell_child_order_acceptance_id":"JRF20211212-214403-092077"},{"id":2284078787,"side":"BUY","price":472638.0,"size":0.608,"exec_date":"2021-12-12T23:05:50.8912618Z","buy_child_order_acceptance_id":"JRF20211212-230550-211434","sell_child_order_acceptance_id":"JRF20211212-230548-216297"},{"id":2284078788,"side":"BUY","price":472639.0,"size":0.342,"exec_date":"2021-12-12T23:05:50.8912618Z","buy_child_order_acceptance_id":"JRF20211212-230550-211434","sell_child_order_acceptance_id":"JRF20211212-213125-014823"}]}}
1639350351.0105011: {"jsonrpc":"2.0","method":"channelMessage","params":{"channel":"lightning_board_XRP_JPY","message":{"mid_price":96.24,"bids":[{"price":95.97,"size":28310.553601}],"asks":[{"price":96.39,"size":338.98227}]}}}
1639350351.028218: {"jsonrpc":"2.0","method":"channelMessage","params":{"channel":"lightning_board_BTC_USD","message":{"mid_price":50320.68,"bids":[],"asks":[{"price":50391.98,"size":0.6003}]}}}
1639350351.043912: {"jsonrpc":"2.0","method":"channelMessage","params":{"channel":"lightning_board_ETH_JPY","message":{"mid_price":472375.0,"bids":[{"price":471529.0,"size":0.0},{"price":472275.0,"size":0.096},{"price":471615.0,"size":0.0},{"price":471833.0,"size":0.65},{"price":471596.0,"size":0.0},{"price":471614.0,"size":0.0},{"price":472111.0,"size":5.013},{"price":472099.0,"size":1.52},{"price":471675.0,"size":0.0}],"asks":[{"price":472703.0,"size":5.013},{"price":474686.0,"size":0.67}]}}}
1639350351.057079: {"jsonrpc":"2.0","method":"channelMessage","params":{"channel":"lightning_board_BTC_EUR","message":{"mid_price":44470.42,"bids":[{"price":44274.46,"size":0.0},{"price":44361.25,"size":0.0}],"asks":[{"price":44650.9,"size":0.0},{"price":44736.28,"size":0.0}]}}}
1639350351.0607018: {"jsonrpc":"2.0","method":"channelMessage","params":{"channel":"lightning_board_FX_BTC_JPY","message":{"mid_price":5871216.0,"bids":[],"asks":[{"price":5878230.0,"size":0.0}]}}}
1639350351.107681: {"jsonrpc":"2.0","method":"channelMessage","params":{"channel":"lightning_executions_ETH_JPY","message":[{"id":2284078789,"side":"SELL","price":472350.0,"size":0.01,"exec_date":"2021-12-12T23:05:51.0098781Z","buy_child_order_acceptance_id":"JRF20211212-230549-206919","sell_child_order_acceptance_id":"JRF20211212-230550-698175"}]}}
1639350351.157984: {"jsonrpc":"2.0","method":"channelMessage","params":{"channel":"lightning_ticker_ETH_JPY","message":{"product_code":"ETH_JPY","state":"RUNNING","timestamp":"2021-12-12T23:05:51.0098781Z","tick_id":26934749,"best_bid":472350.0,"best_ask":472639.0,"best_bid_size":0.57,"best_ask_size":0.158,"total_bid_depth":3285.159367900000,"total_ask_depth":4418.84957320,"market_bid_size":0.0,"market_ask_size":0.0,"ltp":472350.0,"volume":10834.380505500000,"volume_by_product":10834.380505500000}}}
1639350351.1632588: {"jsonrpc":"2.0","method":"channelMessage","params":{"channel":"lightning_board_ETH_JPY","message":{"mid_price":472494.0,"bids":[{"price":469644.0,"size":0.0},{"price":471026.0,"size":0.7},{"price":471870.0,"size":14.99995},{"price":469336.0,"size":0.0},{"price":470589.0,"size":1.0},{"price":468098.0,"size":0.0},{"price":469716.0,"size":1.0},{"price":467075.0,"size":0.0},{"price":469279.0,"size":0.1},{"price":469913.0,"size":0.0},{"price":470363.0,"size":0.01},{"price":472350.0,"size":0.57}],"asks":[{"price":472400.0,"size":0.0},{"price":472500.0,"size":0.0},{"price":472600.0,"size":0.0},{"price":472638.0,"size":0.0},{"price":472639.0,"size":0.158},{"price":472642.0,"size":0.75},{"price":472822.0,"size":0.0},{"price":474085.0,"size":0.6},{"price":473163.0,"size":0.0},{"price":475395.0,"size":0.06}]}}}
1639350351.1665869: {"jsonrpc":"2.0","method":"channelMessage","params":{"channel":"lightning_ticker_BTC_USD","message":{"product_code":"BTC_USD","state":"RUNNING","timestamp":"2021-12-12T23:05:50.9082126Z","tick_id":17933076,"best_bid":50316.82,"best_ask":50324.55,"best_bid_size":1.2006,"best_ask_size":0.1,"total_bid_depth":26.89365669,"total_ask_depth":19.43341796,"market_bid_size":0.0,"market_ask_size":0.0,"ltp":50316.83,"volume":250.200018300000,"volume_by_product":250.200018300000}}}
1639350351.174919: {"jsonrpc":"2.0","method":"channelMessage","params":{"channel":"lightning_board_BTC_USD","message":{"mid_price":50320.68,"bids":[],"asks":[{"price":50335.52,"size":0.0}]}}}
1639350351.191655: {"jsonrpc":"2.0","method":"channelMessage","params":{"channel":"lightning_board_FX_BTC_JPY","message":{"mid_price":5871278.0,"bids":[{"price":5862716.0,"size":0.0},{"price":5868537.0,"size":0.0},{"price":5849903.0,"size":0.0},{"price":5866635.0,"size":0.1},{"price":5869424.0,"size":0.0},{"price":5870708.0,"size":0.09227786},{"price":5862347.0,"size":0.0},{"price":5865930.0,"size":0.0},{"price":5870509.0,"size":0.01},{"price":5869725.0,"size":0.15}],"asks":[{"price":5874944.0,"size":0.0},{"price":7013445.0,"size":1.35793597},{"price":5877263.0,"size":0.0}]}}}
1639350351.257635: {"jsonrpc":"2.0","method":"channelMessage","params":{"channel":"lightning_executions_FX_BTC_JPY","message":[{"id":2284079899,"side":"BUY","price":5871849.0,"size":0.01,"exec_date":"2021-12-12T23:05:51.1351236Z","buy_child_order_acceptance_id":"JRF20211212-230550-180029","sell_child_order_acceptance_id":"JRF20211212-230533-180998"}]}}
1639350351.28306: {"jsonrpc":"2.0","method":"channelMessage","params":{"channel":"lightning_board_ETH_JPY","message":{"mid_price":472570.0,"bids":[{"price":471870.0,"size":0.0},{"price":472069.0,"size":0.0},{"price":471834.0,"size":0.0},{"price":471833.0,"size":0.0},{"price":471910.0,"size":0.0},{"price":472501.0,"size":0.930049}],"asks":[{"price":472999.0,"size":0.928}]}}}
1639350351.298851: {"jsonrpc":"2.0","method":"channelMessage","params":{"channel":"lightning_ticker_FX_BTC_JPY","message":{"product_code":"FX_BTC_JPY","state":"RUNNING","timestamp":"2021-12-12T23:05:51.1351236Z","tick_id":127092402,"best_bid":5870937.0,"best_ask":5871849.0,"best_bid_size":0.01,"best_ask_size":0.397,"total_bid_depth":233.361763160000,"total_ask_depth":293.604248940000,"market_bid_size":0.0,"market_ask_size":0.0,"ltp":5871849.0,"volume":4228.279096850000,"volume_by_product":4228.279096850000}}}
1639350351.298956: {"jsonrpc":"2.0","method":"channelMessage","params":{"channel":"lightning_ticker_XRP_JPY","message":{"product_code":"XRP_JPY","state":"RUNNING","timestamp":"2021-12-12T23:05:51.1116423Z","tick_id":12284700,"best_bid":96.01,"best_ask":96.3,"best_bid_size":10268.0,"best_ask_size":1352.250000,"total_bid_depth":1518383.39030100,"total_ask_depth":2290581.819848000000,"market_bid_size":0.0,"market_ask_size":0.0,"ltp":96.13,"volume":1653329.165579000000,"volume_by_product":1653329.165579000000}}}
1639350351.3009338: {"jsonrpc":"2.0","method":"channelMessage","params":{"channel":"lightning_board_FX_BTC_JPY","message":{"mid_price":5871393.0,"bids":[{"price":5865259.0,"size":0.0},{"price":5763806.0,"size":0.02},{"price":5867963.0,"size":0.0},{"price":5866483.0,"size":0.05864869},{"price":5870937.0,"size":0.01},{"price":5865229.0,"size":0.0}],"asks":[{"price":5891040.0,"size":0.0},{"price":5871849.0,"size":0.397}]}}}
1639350351.308504: {"jsonrpc":"2.0","method":"channelMessage","params":{"channel":"lightning_board_XRP_JPY","message":{"mid_price":96.15,"bids":[{"price":95.97,"size":27616.54584},{"price":96.2,"size":0.0},{"price":95.89,"size":6.940078}],"asks":[{"price":96.29,"size":0.0},{"price":96.39,"size":0.0},{"price":96.33,"size":0.0}]}}}
1639350351.3132339: {"jsonrpc":"2.0","method":"channelMessage","params":{"channel":"lightning_ticker_BTC_EUR","message":{"product_code":"BTC_EUR","state":"RUNNING","timestamp":"2021-12-12T23:05:51.1796332Z","tick_id":7240293,"best_bid":44461.19,"best_ask":44479.65,"best_bid_size":0.00118145,"best_ask_size":0.01,"total_bid_depth":14.74728901,"total_ask_depth":13.76712467,"market_bid_size":0.0,"market_ask_size":0.0,"ltp":44461.2,"volume":43.951523900000,"volume_by_product":43.951523900000}}}
1639350351.318173: {"jsonrpc":"2.0","method":"channelMessage","params":{"channel":"lightning_board_BTC_EUR","message":{"mid_price":44470.42,"bids":[{"price":44286.43,"size":0.18},{"price":44369.75,"size":0.18}],"asks":[{"price":44659.11,"size":0.13},{"price":44745.91,"size":0.18}]}}}
1639350351.322892: {"jsonrpc":"2.0","method":"channelMessage","params":{"channel":"lightning_ticker_XLM_JPY","message":{"product_code":"XLM_JPY","state":"RUNNING","timestamp":"2021-12-12T23:05:51.0946999Z","tick_id":8300599,"best_bid":31.506,"best_ask":31.579,"best_bid_size":4018.0,"best_ask_size":975.2,"total_bid_depth":1848971.85493760,"total_ask_depth":2110858.247473400000,"market_bid_size":0.0,"market_ask_size":0.0,"ltp":31.471,"volume":1471420.073424000000,"volume_by_product":1471420.073424000000}}}
1639350351.326068: {"jsonrpc":"2.0","method":"channelMessage","params":{"channel":"lightning_board_XLM_JPY","message":{"mid_price":31.542,"bids":[{"price":31.49,"size":0.0}],"asks":[]}}}
1639350351.33861: {"jsonrpc":"2.0","method":"channelMessage","params":{"channel":"lightning_board_BTC_USD","message":{"mid_price":50320.68,"bids":[{"price":49757.26,"size":0.9},{"price":49797.55,"size":1.115}],"asks":[{"price":50925.66,"size":1.125},{"price":50885.37,"size":0.675}]}}}
1639350351.407361: {"jsonrpc":"2.0","method":"channelMessage","params":{"channel":"lightning_board_FX_BTC_JPY","message":{"mid_price":5871393.0,"bids":[{"price":5851059.0,"size":0.02},{"price":5869725.0,"size":0.0},{"price":5866483.0,"size":0.03432129},{"price":5869925.0,"size":0.0}],"asks":[{"price":5886206.0,"size":0.02}]}}}
1639350351.4111428: {"jsonrpc":"2.0","method":"channelMessage","params":{"channel":"lightning_board_snapshot_BCH_BTC","message":{"mid_price":0.00921,"bids":[{"price":0.006,"size":2.0},{"price":0.0073,"size":0.1},{"price":0.0074,"size":0.1},{"price":0.0075,"size":0.1},{"price":0.00756,"size":0.29502},{"price":0.0076,"size":0.1},{"price":0.0077,"size":0.1},{"price":0.00775,"size":0.1},{"price":0.0078,"size":0.1},{"price":0.0079,"size":0.1},{"price":0.008,"size":0.1},{"price":0.0081,"size":0.1},{"price":0.00811,"size":10.0},{"price":0.0082,"size":0.1},{"price":0.0083,"size":0.1},{"price":0.0084,"size":0.0214},{"price":0.00844,"size":0.75},{"price":0.0085,"size":0.01},{"price":0.00852,"size":0.01},{"price":0.00853,"size":20.0},{"price":0.00854,"size":0.01},{"price":0.00856,"size":0.01},{"price":0.00858,"size":0.01},{"price":0.0086,"size":0.01},{"price":0.00862,"size":0.01},{"price":0.00864,"size":0.01},{"price":0.00866,"size":0.01},{"price":0.00868,"size":0.01},{"price":0.0087,"size":0.01},{"price":0.00872,"size":0.01},{"price":0.00874,"size":0.01},{"price":0.00876,"size":0.01},{"price":0.00878,"size":0.01},{"price":0.0088,"size":0.01},{"price":0.00882,"size":0.01},{"price":0.00884,"size":0.01},{"price":0.00885,"size":0.026},{"price":0.00886,"size":0.01},{"price":0.00888,"size":10.01},{"price":0.0089,"size":0.11},{"price":0.00892,"size":0.01},{"price":0.00894,"size":0.01},{"price":0.00896,"size":0.01},{"price":0.00898,"size":2.51},{"price":0.009,"size":0.23},{"price":0.00905,"size":0.1},{"price":0.00907,"size":17.918142},{"price":0.00908,"size":8.7},{"price":0.00912,"size":10.3},{"price":0.00916,"size":25.1},{"price":0.00918,"size":2.4},{"price":0.00919,"size":0.9}],"asks":[{"price":0.00923,"size":0.9},{"price":0.00924,"size":2.4},{"price":0.00928,"size":25.7},{"price":0.00936,"size":1.1},{"price":0.00963,"size":0.1},{"price":0.0097,"size":0.96510871},{"price":0.00975,"size":0.01},{"price":0.00976,"size":0.051},{"price":0.0098,"size":1.0},{"price":0.00984,"size":5.0},{"price":0.00985,"size":0.01},{"price":0.0099,"size":0.01},{"price":0.00994,"size":0.05},{"price":0.00995,"size":0.01},{"price":0.01,"size":0.21},{"price":0.01005,"size":0.21},{"price":0.0101,"size":0.21},{"price":0.01015,"size":2.8626601},{"price":0.0102,"size":0.21},{"price":0.01025,"size":0.21},{"price":0.0103,"size":0.21},{"price":0.01035,"size":0.21},{"price":0.01036,"size":0.1},{"price":0.01037,"size":0.1},{"price":0.0104,"size":0.21},{"price":0.01045,"size":0.21},{"price":0.0105,"size":0.21},{"price":0.01055,"size":0.01},{"price":0.0106,"size":0.21},{"price":0.01065,"size":0.01},{"price":0.0107,"size":0.21},{"price":0.01074,"size":0.1},{"price":0.01075,"size":0.01},{"price":0.0108,"size":4.855},{"price":0.01083,"size":0.1},{"price":0.01085,"size":0.01},{"price":0.01088,"size":0.01},{"price":0.0109,"size":0.31},{"price":0.01095,"size":0.01},{"price":0.011,"size":0.22},{"price":0.01105,"size":0.01},{"price":0.0111,"size":0.02},{"price":0.01115,"size":0.01},{"price":0.0112,"size":0.21},{"price":0.0114,"size":0.2},{"price":0.0115,"size":0.2},{"price":0.01156,"size":0.18952},{"price":0.0116,"size":0.2},{"price":0.0118,"size":0.2},{"price":0.012,"size":0.51},{"price":0.0121,"size":0.2},{"price":0.01243,"size":7.56559535},{"price":0.0125,"size":0.5},{"price":0.013,"size":0.51},{"price":0.0135,"size":0.5},{"price":0.014,"size":0.51},{"price":0.01413,"size":3.7},{"price":0.0145,"size":0.5},{"price":0.015,"size":1.14459141},{"price":0.0151,"size":2.0},{"price":0.0155,"size":0.5},{"price":0.016,"size":0.5},{"price":0.0165,"size":0.5},{"price":0.017,"size":0.5},{"price":0.0175,"size":0.5},{"price":0.018,"size":0.51},{"price":0.0185,"size":0.5},{"price":0.01891,"size":0.01},{"price":0.019,"size":0.51},{"price":0.01918,"size":9.96007985},{"price":0.0195,"size":0.5},{"price":0.02,"size":3.68802395}]}}}
1639350351.4120839: {"jsonrpc":"2.0","method":"channelMessage","params":{"channel":"lightning_executions_FX_BTC_JPY","message":[{"id":2284079900,"side":"SELL","price":5870937.0,"size":0.01,"exec_date":"2021-12-12T23:05:51.2810999Z","buy_child_order_acceptance_id":"JRF20211212-230550-001820","sell_child_order_acceptance_id":"JRF20211212-230551-206925"},{"id":2284079901,"side":"SELL","price":5870708.0,"size":0.04,"exec_date":"2021-12-12T23:05:51.2810999Z","buy_child_order_acceptance_id":"JRF20211212-230550-207940","sell_child_order_acceptance_id":"JRF20211212-230551-206925"}]}}
1639350351.421616: {"jsonrpc":"2.0","method":"channelMessage","params":{"channel":"lightning_board_snapshot_BTC_USD","message":{"mid_price":50320.68,"bids":[{"price":30000.0,"size":0.002},{"price":35000.0,"size":0.05},{"price":38000.0,"size":0.1},{"price":40000.0,"size":0.13},{"price":41000.0,"size":0.103},{"price":41250.0,"size":0.003},{"price":41500.0,"size":0.003},{"price":42000.0,"size":0.04},{"price":44000.0,"size":0.01},{"price":44500.0,"size":0.01},{"price":45000.0,"size":0.033},{"price":45500.0,"size":0.01},{"price":46000.0,"size":0.01},{"price":46500.0,"size":0.01},{"price":46725.0,"size":0.10050619},{"price":47237.86,"size":0.89},{"price":47273.37,"size":0.76},{"price":47292.29,"size":1.03},{"price":47311.21,"size":1.19},{"price":48409.37,"size":0.45},{"price":48558.85,"size":1.1},{"price":48707.54,"size":1.0},{"price":48760.6,"size":0.675},{"price":49436.21,"size":0.98},{"price":49470.84,"size":0.78},{"price":49537.48,"size":0.95},{"price":49545.47,"size":0.45},{"price":49557.3,"size":0.96},{"price":49580.78,"size":0.45},{"price":49613.78,"size":1.0},{"price":49651.32,"size":1.0},{"price":49736.04,"size":0.95},{"price":49757.26,"size":0.9},{"price":49778.08,"size":0.84},{"price":49797.55,"size":1.115},{"price":49822.07,"size":1.26},{"price":49837.84,"size":0.675},{"price":49844.95,"size":0.18},{"price":49878.13,"size":0.45},{"price":49879.71,"size":0.27},{"price":49918.42,"size":0.27},{"price":49937.96,"size":1.0},{"price":49958.71,"size":0.18},{"price":50065.72,"size":1.0},{"price":50120.61,"size":0.01},{"price":50165.39,"size":1.29},{"price":50211.42,"size":0.11},{"price":50226.78,"size":0.57},{"price":50229.86,"size":1.0},{"price":50239.86,"size":0.01},{"price":50242.43,"size":0.05096228},{"price":50242.45,"size":0.01398398},{"price":50242.46,"size":0.04566142},{"price":50244.89,"size":0.01},{"price":50244.91,"size":0.15066957},{"price":50244.92,"size":0.04197325},{"price":50274.27,"size":0.11},{"price":50274.28,"size":1.0},{"price":50316.23,"size":0.6003},{"price":50316.82,"size":1.2006}],"asks":[{"price":50324.55,"size":0.1},{"price":50373.38,"size":0.07225738},{"price":50376.87,"size":0.6003},{"price":50384.43,"size":0.6003},{"price":50391.98,"size":0.6003},{"price":50413.75,"size":0.5},{"price":50439.81,"size":0.04234589},{"price":50439.82,"size":0.07359133},{"price":50439.84,"size":1.0},{"price":50464.12,"size":1.0},{"price":50514.48,"size":1.0},{"price":50538.23,"size":1.3},{"price":50568.33,"size":2.0},{"price":50623.32,"size":0.01},{"price":50654.37,"size":0.88},{"price":50764.5,"size":0.18},{"price":50804.79,"size":0.27},{"price":50818.97,"size":0.8},{"price":50845.08,"size":0.45},{"price":50885.37,"size":0.675},{"price":50925.66,"size":1.125},{"price":50965.95,"size":0.9},{"price":50977.57,"size":0.9},{"price":51248.54,"size":1.1},{"price":51267.89,"size":0.54},{"price":51372.57,"size":0.9},{"price":51394.06,"size":0.79},{"price":51500.0,"size":0.2},{"price":51644.76,"size":0.8},{"price":52000.0,"size":0.03858975},{"price":52191.68,"size":0.892},{"price":54425.0,"size":0.001},{"price":68000.0,"size":1.09211295},{"price":75000.0,"size":0.70062066}]}}}
1639350351.424331: {"jsonrpc":"2.0","method":"channelMessage","params":{"channel":"lightning_board_snapshot_BTC_EUR","message":{"mid_price":44470.42,"bids":[{"price":27675.2,"size":0.353},{"price":30056.0,"size":0.1},{"price":32312.0,"size":0.062},{"price":35005.0,"size":0.25},{"price":35403.0,"size":0.0565},{"price":38300.0,"size":0.002},{"price":38400.0,"size":0.002},{"price":38500.0,"size":0.002},{"price":38600.0,"size":0.002},{"price":38700.0,"size":0.002},{"price":38800.0,"size":0.002},{"price":38824.29,"size":0.77},{"price":38900.0,"size":0.002},{"price":38981.11,"size":0.0754},{"price":39000.0,"size":0.002},{"price":39001.0,"size":0.2},{"price":39100.0,"size":0.002},{"price":39200.0,"size":0.002},{"price":39300.0,"size":0.002},{"price":39400.0,"size":0.002},{"price":39500.0,"size":0.002},{"price":39600.0,"size":0.002},{"price":39700.0,"size":0.002},{"price":39741.94,"size":1.02},{"price":39800.0,"size":0.002},{"price":39900.0,"size":0.002},{"price":40000.0,"size":0.002},{"price":40100.0,"size":0.002},{"price":40200.0,"size":0.002},{"price":40300.0,"size":0.002},{"price":40400.0,"size":0.004},{"price":40500.0,"size":0.002},{"price":40600.0,"size":0.002},{"price":40688.3,"size":0.7},{"price":40700.0,"size":0.002},{"price":40800.0,"size":0.004},{"price":40900.0,"size":0.002},{"price":40955.0,"size":0.03},{"price":40972.0,"size":0.03},{"price":40981.11,"size":0.03},{"price":41000.0,"size":0.002},{"price":41001.0,"size":0.1},{"price":41100.0,"size":0.002},{"price":41125.0,"size":0.03},{"price":41200.0,"size":0.002},{"price":41300.0,"size":0.002},{"price":41336.84,"size":0.9},{"price":41400.0,"size":0.002},{"price":41500.0,"size":0.002},{"price":41505.0,"size":0.05},{"price":41600.0,"size":0.002},{"price":41700.0,"size":0.002},{"price":41800.0,"size":0.004},{"price":41900.0,"size":0.002},{"price":41949.83,"size":1.2},{"price":42000.0,"size":0.002},{"price":42100.0,"size":0.002},{"price":42200.0,"size":0.002},{"price":42300.0,"size":0.002},{"price":42400.0,"size":0.002},{"price":42500.0,"size":0.002},{"price":42600.0,"size":0.002},{"price":42700.0,"size":0.001},{"price":42786.32,"size":0.18},{"price":42800.0,"size":0.001},{"price":42861.18,"size":1.8},{"price":42900.0,"size":0.001},{"price":43000.0,"size":0.001},{"price":43091.16,"size":1.4},{"price":43100.0,"size":0.001},{"price":43113.73,"size":0.18},{"price":43200.0,"size":0.001},{"price":43300.0,"size":0.001},{"price":43400.0,"size":0.001},{"price":43500.0,"size":0.001},{"price":43558.56,"size":0.8},{"price":43600.0,"size":0.001},{"price":43711.82,"size":1.0},{"price":43904.41,"size":0.18},{"price":44149.97,"size":0.01},{"price":44221.6,"size":0.00107479},{"price":44239.98,"size":0.01},{"price":44248.15,"size":0.00110903},{"price":44274.69,"size":0.00131169},{"price":44286.43,"size":0.18},{"price":44300.53,"size":0.18},{"price":44301.29,"size":0.00115867},{"price":44327.9,"size":0.00117149},{"price":44327.91,"size":0.3005332},{"price":44349.49,"size":0.3},{"price":44354.5,"size":0.00118117},{"price":44354.87,"size":0.18},{"price":44369.75,"size":0.18},{"price":44381.14,"size":0.00130283},{"price":44383.66,"size":0.50134},{"price":44401.54,"size":0.01},{"price":44405.1,"size":0.1},{"price":44407.34,"size":0.50134},{"price":44407.75,"size":0.00121377},{"price":44417.1,"size":0.01},{"price":44420.67,"size":0.15},{"price":44432.66,"size":0.02},{"price":44434.52,"size":0.00113092},{"price":44443.58,"size":0.50134},{"price":44461.19,"size":0.00118145}],"asks":[{"price":44479.65,"size":0.01},{"price":44514.08,"size":0.1},{"price":44514.55,"size":0.0010134},{"price":44529.65,"size":0.1},{"price":44541.28,"size":0.00100978},{"price":44546.37,"size":0.50134},{"price":44568.0,"size":0.00107131},{"price":44568.32,"size":0.1},{"price":44573.1,"size":0.50134},{"price":44576.35,"size":0.1574203},{"price":44576.36,"size":0.01},{"price":44583.9,"size":0.01},{"price":44594.58,"size":0.01},{"price":44594.74,"size":0.00110449},{"price":44621.5,"size":0.00118707},{"price":44648.27,"size":0.00115137},{"price":44659.11,"size":0.13},{"price":44661.02,"size":0.19},{"price":44675.06,"size":0.00123005},{"price":44701.87,"size":0.00100114},{"price":44728.69,"size":0.00125068},{"price":44745.91,"size":0.18},{"price":44755.53,"size":0.00100508},{"price":44768.15,"size":0.1},{"price":44863.71,"size":0.74},{"price":44953.12,"size":1.0},{"price":45000.0,"size":0.001},{"price":45200.0,"size":0.001},{"price":45400.0,"size":0.001},{"price":45427.26,"size":0.399},{"price":45427.27,"size":1.1},{"price":45573.78,"size":1.2},{"price":45600.0,"size":0.001},{"price":45800.0,"size":0.001},{"price":45914.15,"size":1.5},{"price":46000.0,"size":0.001},{"price":46200.0,"size":0.001},{"price":46400.0,"size":0.001},{"price":46600.0,"size":0.001},{"price":46777.42,"size":0.94},{"price":46800.0,"size":0.001},{"price":47000.0,"size":1.001},{"price":47200.0,"size":0.001},{"price":47400.0,"size":0.001},{"price":47498.64,"size":0.73},{"price":47600.0,"size":0.001},{"price":47800.0,"size":0.001},{"price":47883.35,"size":0.9},{"price":48000.0,"size":0.001},{"price":48200.0,"size":0.001},{"price":48400.0,"size":0.001},{"price":48600.0,"size":0.001},{"price":48800.0,"size":0.001},{"price":49000.0,"size":0.001},{"price":49073.85,"size":1.09},{"price":49200.0,"size":0.001},{"price":49400.0,"size":0.001},{"price":49600.0,"size":0.001},{"price":49800.0,"size":0.001},{"price":50000.0,"size":0.001},{"price":50157.03,"size":0.98},{"price":50200.0,"size":0.001},{"price":50400.0,"size":0.001},{"price":50600.0,"size":0.001},{"price":50800.0,"size":0.001},{"price":51000.0,"size":0.001},{"price":51200.0,"size":0.002},{"price":51400.0,"size":0.001},{"price":51600.0,"size":0.001},{"price":51800.0,"size":0.001},{"price":52000.0,"size":0.001},{"price":52200.0,"size":0.001},{"price":52400.0,"size":0.001},{"price":52600.0,"size":0.001},{"price":52800.0,"size":0.001},{"price":53000.0,"size":0.001},{"price":53200.0,"size":0.001},{"price":53400.0,"size":0.001},{"price":53600.0,"size":0.001},{"price":53800.0,"size":0.001},{"price":54000.0,"size":0.001},{"price":54200.0,"size":0.001},{"price":54400.0,"size":0.001},{"price":54600.0,"size":0.001},{"price":54800.0,"size":0.001},{"price":55000.0,"size":0.001},{"price":55200.0,"size":0.001},{"price":55400.0,"size":0.001},{"price":55600.0,"size":0.001},{"price":55800.0,"size":0.001},{"price":56000.0,"size":0.001},{"price":56200.0,"size":0.001},{"price":56400.0,"size":0.001},{"price":56600.0,"size":0.001},{"price":56800.0,"size":0.001},{"price":57000.0,"size":0.001},{"price":57200.0,"size":0.001},{"price":57400.0,"size":0.001},{"price":57600.0,"size":0.001},{"price":57800.0,"size":0.001},{"price":59400.0,"size":0.001},{"price":59600.0,"size":0.001},{"price":59800.0,"size":0.001},{"price":60000.0,"size":0.002},{"price":63000.0,"size":0.001},{"price":67200.0,"size":0.001},{"price":67400.0,"size":0.001},{"price":67600.0,"size":0.001},{"price":67800.0,"size":0.001},{"price":68000.0,"size":0.001}]}}}
1639350351.447375: {"jsonrpc":"2.0","method":"channelMessage","params":{"channel":"lightning_board_snapshot_ETH_JPY","message":{"mid_price":472570.0,"bids":[{"price":472501.0,"size":0.930049},{"price":472275.0,"size":0.096},{"price":472211.0,"size":0.67},{"price":472111.0,"size":5.013},{"price":472099.0,"size":1.52},{"price":471676.0,"size":1.0},{"price":471026.0,"size":0.7},{"price":470988.0,"size":0.01},{"price":470813.0,"size":0.7},{"price":470589.0,"size":1.0},{"price":470363.0,"size":0.01},{"price":470249.0,"size":6.0},{"price":469833.0,"size":6.08},{"price":469716.0,"size":1.0},{"price":469522.0,"size":2.1},{"price":469399.0,"size":14.83},{"price":469356.0,"size":1.0},{"price":469279.0,"size":0.1},{"price":469020.0,"size":0.8},{"price":468944.0,"size":0.1},{"price":468222.0,"size":119.3},{"price":468017.0,"size":0.99},{"price":468007.0,"size":1.0},{"price":468000.0,"size":1.9},{"price":467941.0,"size":0.05},{"price":467700.0,"size":0.01},{"price":467585.0,"size":0.07},{"price":467526.0,"size":0.01},{"price":467252.0,"size":2.385},{"price":467074.0,"size":0.43},{"price":467004.0,"size":0.1},{"price":467000.0,"size":0.783},{"price":466501.0,"size":8.0},{"price":466260.0,"size":5.26},{"price":466228.0,"size":0.129},{"price":466100.0,"size":4.33},{"price":466000.0,"size":0.02},{"price":465720.0,"size":2.044312},{"price":465700.0,"size":0.5},{"price":465591.0,"size":58.73},{"price":465555.0,"size":0.7},{"price":465500.0,"size":0.5},{"price":465250.0,"size":0.5},{"price":465181.0,"size":1.33},{"price":465123.0,"size":0.1},{"price":465000.0,"size":9.458},{"price":464979.0,"size":0.01},{"price":464228.0,"size":0.129},{"price":464000.0,"size":0.0202},{"price":463230.0,"size":30.35},{"price":462990.0,"size":0.4},{"price":462500.0,"size":0.51},{"price":462228.0,"size":0.13},{"price":462000.0,"size":0.51},{"price":461000.0,"size":0.51},{"price":460946.0,"size":14.99},{"price":460742.0,"size":0.01},{"price":460724.0,"size":0.01},{"price":460563.0,"size":1.9},{"price":460321.0,"size":0.95},{"price":460250.0,"size":0.5},{"price":460228.0,"size":0.13},{"price":460123.0,"size":0.21},{"price":460111.0,"size":0.1},{"price":460106.0,"size":1.0},{"price":460010.0,"size":0.012},{"price":460000.0,"size":8.686101},{"price":459855.0,"size":0.2},{"price":459740.0,"size":62.247},{"price":459000.0,"size":32.5202},{"price":458819.0,"size":0.89},{"price":458545.0,"size":0.1},{"price":458500.0,"size":0.05},{"price":458228.0,"size":0.131},{"price":458151.0,"size":0.01},{"price":458090.0,"size":1.0},{"price":458000.0,"size":13.06},{"price":457976.0,"size":0.1},{"price":457777.0,"size":0.1},{"price":457500.0,"size":0.51},{"price":457136.0,"size":0.013},{"price":457000.0,"size":4.74},{"price":456870.0,"size":0.01},{"price":456500.0,"size":0.5},{"price":456253.0,"size":0.1},{"price":456243.0,"size":15.44},{"price":456228.0,"size":0.132},{"price":456213.0,"size":0.5},{"price":456100.0,"size":0.030696},{"price":456000.0,"size":1.7907},{"price":455968.0,"size":0.1},{"price":455777.0,"size":0.04},{"price":455507.0,"size":0.01},{"price":455500.0,"size":0.61},{"price":455438.0,"size":0.01},{"price":455250.0,"size":0.5},{"price":455111.0,"size":0.1},{"price":455044.0,"size":0.386},{"price":455000.0,"size":6.0746},{"price":454947.0,"size":1.1},{"price":454900.0,"size":0.05},{"price":454600.0,"size":0.11},{"price":454500.0,"size":0.238},{"price":454485.0,"size":0.01},{"price":454228.0,"size":0.132},{"price":454000.0,"size":15.191629},{"price":453865.0,"size":1.0},{"price":453750.0,"size":0.5},{"price":453610.0,"size":0.1},{"price":453601.0,"size":0.99},{"price":453500.0,"size":0.4},{"price":453492.0,"size":0.14},{"price":453112.0,"size":0.01},{"price":453006.0,"size":0.3},{"price":453003.0,"size":3.640905},{"price":453001.0,"size":8.0},{"price":453000.0,"size":3.4605},{"price":452787.0,"size":0.6747411},{"price":452500.0,"size":0.1204972},{"price":452369.0,"size":0.5},{"price":452244.0,"size":0.030957},{"price":452228.0,"size":0.133},{"price":452112.0,"size":0.01},{"price":452111.0,"size":0.01},{"price":452100.0,"size":0.07},{"price":452000.0,"size":1.854607},{"price":451880.0,"size":0.1},{"price":451820.0,"size":0.3},{"price":451800.0,"size":0.07},{"price":451600.0,"size":1.05},{"price":451555.0,"size":6.0},{"price":451539.0,"size":14.75},{"price":451500.0,"size":0.11},{"price":451250.0,"size":0.11},{"price":451200.0,"size":0.07},{"price":451176.0,"size":0.01},{"price":451111.0,"size":5.01},{"price":451001.0,"size":0.7},{"price":451000.0,"size":0.71},{"price":450900.0,"size":0.1},{"price":450740.0,"size":4.0},{"price":450600.0,"size":0.1},{"price":450500.0,"size":0.02},{"price":450300.0,"size":0.1},{"price":450250.0,"size":0.5},{"price":450228.0,"size":0.133},{"price":450210.0,"size":0.31},{"price":450111.0,"size":0.55},{"price":450106.0,"size":1.0},{"price":450038.0,"size":0.01},{"price":450020.0,"size":5.0},{"price":450010.0,"size":0.4340547},{"price":450008.0,"size":0.05},{"price":450002.0,"size":0.125},{"price":450001.0,"size":0.62697},{"price":450000.0,"size":40.3350369},{"price":449990.0,"size":0.45},{"price":449700.0,"size":0.1},{"price":449580.0,"size":0.1},{"price":449400.0,"size":1.11},{"price":449111.0,"size":0.02},{"price":449100.0,"size":0.1},{"price":449000.0,"size":0.32},{"price":448980.0,"size":0.1},{"price":448900.0,"size":0.5},{"price":448888.0,"size":0.2005},{"price":448800.0,"size":0.1},{"price":448587.0,"size":0.1},{"price":448565.0,"size":0.05},{"price":448500.0,"size":0.15},{"price":448300.0,"size":0.03},{"price":448230.0,"size":0.2},{"price":448228.0,"size":0.134},{"price":448222.0,"size":5.0},{"price":448200.0,"size":0.1},{"price":448111.0,"size":0.01},{"price":448001.0,"size":0.015},{"price":448000.0,"size":11.4566045},{"price":447800.0,"size":0.23},{"price":447700.0,"size":0.031},{"price":447576.0,"size":0.01},{"price":447502.0,"size":0.125},{"price":447500.0,"size":0.03},{"price":447252.0,"size":1.1},{"price":447136.0,"size":0.013},{"price":447111.0,"size":0.01},{"price":447000.0,"size":1.46},{"price":446836.0,"size":14.76},{"price":446543.0,"size":0.53},{"price":446500.0,"size":2.17},{"price":446489.0,"size":1.0},{"price":446400.0,"size":0.3},{"price":446397.0,"size":0.01},{"price":446228.0,"size":0.134},{"price":446111.0,"size":0.04},{"price":446000.0,"size":2.870067},{"price":445973.0,"size":0.1121121},{"price":445900.0,"size":0.01},{"price":445885.0,"size":0.02},{"price":445858.0,"size":0.01},{"price":445700.0,"size":0.01},{"price":445670.0,"size":0.2},{"price":445555.0,"size":1.0},{"price":445525.0,"size":0.012134},{"price":445500.0,"size":1.285},{"price":445451.0,"size":1.0},{"price":445188.0,"size":0.3},{"price":445111.0,"size":0.12},{"price":445088.0,"size":0.2},{"price":445011.0,"size":0.3},{"price":445008.0,"size":0.01},{"price":445002.0,"size":0.125},{"price":445001.0,"size":0.03},{"price":445000.0,"size":9.6017349},{"price":444924.0,"size":0.01},{"price":444900.0,"size":0.06743},{"price":444502.0,"size":0.01},{"price":444500.0,"size":0.25},{"price":444444.0,"size":1.21},{"price":444400.0,"size":0.01},{"price":444309.0,"size":0.01},{"price":444228.0,"size":0.135},{"price":444111.0,"size":0.01},{"price":444050.0,"size":0.017},{"price":444023.0,"size":0.01},{"price":444000.0,"size":7.020865},{"price":443944.0,"size":0.01},{"price":443739.0,"size":1.0},{"price":443502.0,"size":0.01},{"price":443500.0,"size":0.043822},{"price":443400.0,"size":1.0},{"price":443300.0,"size":0.01},{"price":443111.0,"size":0.01},{"price":443002.0,"size":1.0},{"price":443000.0,"size":0.50436},{"price":442921.0,"size":0.01},{"price":442844.0,"size":0.11},{"price":442502.0,"size":0.135},{"price":442500.0,"size":0.05},{"price":442450.0,"size":0.03},{"price":442350.0,"size":0.6},{"price":442258.0,"size":6.0},{"price":442228.0,"size":0.136},{"price":442111.0,"size":0.01},{"price":442000.0,"size":2.3356125},{"price":441888.0,"size":0.1},{"price":441502.0,"size":0.01},{"price":441410.0,"size":1.0},{"price":441249.0,"size":0.01},{"price":441200.0,"size":5.0},{"price":441111.0,"size":1.01},{"price":441100.0,"size":0.3},{"price":441008.0,"size":0.1},{"price":441000.0,"size":22.025},{"price":440888.0,"size":0.2},{"price":440700.0,"size":2.0},{"price":440666.0,"size":0.5},{"price":440603.0,"size":0.01},{"price":440600.0,"size":0.01},{"price":440500.0,"size":0.029},{"price":440228.0,"size":0.136},{"price":440212.0,"size":0.11356},{"price":440139.0,"size":0.2},{"price":440111.0,"size":0.13},{"price":440099.0,"size":0.01},{"price":440088.0,"size":0.3},{"price":440070.0,"size":0.01},{"price":440050.0,"size":0.2},{"price":440010.0,"size":0.01},{"price":440008.0,"size":0.1},{"price":440002.0,"size":0.125},{"price":440001.0,"size":0.1},{"price":440000.0,"size":40.446149},{"price":439999.0,"size":0.1},{"price":439807.0,"size":0.01},{"price":439800.0,"size":0.1},{"price":439500.0,"size":0.05},{"price":439495.0,"size":0.505125},{"price":439157.0,"size":0.10025},{"price":439115.0,"size":1.0},{"price":439111.0,"size":0.03},{"price":439100.0,"size":0.642},{"price":439000.0,"size":8.28319},{"price":438845.0,"size":1.0},{"price":438666.0,"size":0.5},{"price":438598.0,"size":0.01},{"price":438575.0,"size":0.1},{"price":438500.0,"size":0.05},{"price":438456.0,"size":0.01},{"price":438357.0,"size":0.01},{"price":438257.0,"size":0.05},{"price":438228.0,"size":0.137},{"price":438112.0,"size":0.01},{"price":438111.0,"size":0.03},{"price":438000.0,"size":22.1920639},{"price":437999.0,"size":0.36},{"price":437900.0,"size":0.1},{"price":437800.0,"size":0.168},{"price":437703.0,"size":1.0},{"price":437698.0,"size":0.06}],"asks":[{"price":472639.0,"size":0.158},{"price":472642.0,"size":0.75},{"price":472696.0,"size":4.202},{"price":472703.0,"size":5.013},{"price":472751.0,"size":6.08},{"price":472752.0,"size":0.01},{"price":472800.0,"size":0.02},{"price":472900.0,"size":0.013},{"price":472999.0,"size":0.928},{"price":473000.0,"size":0.33},{"price":473038.0,"size":1.01},{"price":473050.0,"size":0.010613},{"price":473200.0,"size":0.02},{"price":473212.0,"size":0.029586},{"price":473252.0,"size":0.01},{"price":473256.0,"size":44.0},{"price":473300.0,"size":0.11},{"price":473347.0,"size":6.0},{"price":473400.0,"size":0.53},{"price":473473.0,"size":0.2},{"price":473500.0,"size":0.01},{"price":473550.0,"size":0.1050705},{"price":473599.0,"size":0.3005},{"price":473600.0,"size":1.03},{"price":473649.0,"size":14.83},{"price":473700.0,"size":0.01},{"price":473718.0,"size":0.5},{"price":473752.0,"size":0.01},{"price":473772.0,"size":0.0146843},{"price":473800.0,"size":0.03},{"price":473843.0,"size":6.0},{"price":473900.0,"size":0.01},{"price":473960.0,"size":117.31},{"price":473968.0,"size":0.09},{"price":473997.0,"size":0.01},{"price":474000.0,"size":1.2201},{"price":474085.0,"size":0.6},{"price":474100.0,"size":0.01},{"price":474200.0,"size":0.03},{"price":474300.0,"size":0.01},{"price":474400.0,"size":0.05},{"price":474450.0,"size":0.5},{"price":474480.0,"size":0.7},{"price":474500.0,"size":0.02},{"price":474535.0,"size":0.15},{"price":474558.0,"size":0.02},{"price":474600.0,"size":0.03},{"price":474650.0,"size":0.5},{"price":474656.0,"size":0.01},{"price":474686.0,"size":0.67},{"price":474700.0,"size":0.01},{"price":474800.0,"size":0.03},{"price":474882.0,"size":0.12},{"price":474888.0,"size":0.1},{"price":474900.0,"size":0.01},{"price":474950.0,"size":0.5},{"price":474997.0,"size":0.21},{"price":475000.0,"size":12.0154268},{"price":475123.0,"size":0.66},{"price":475395.0,"size":0.06},{"price":475436.0,"size":0.07},{"price":475457.0,"size":1.0},{"price":475555.0,"size":0.05},{"price":475750.0,"size":0.01},{"price":475880.0,"size":3.0},{"price":475899.0,"size":0.027},{"price":475997.0,"size":0.01},{"price":476000.0,"size":2.2872},{"price":476434.0,"size":1.9626441},{"price":476468.0,"size":0.07},{"price":476600.0,"size":0.1},{"price":476678.0,"size":0.011},{"price":476750.0,"size":0.02},{"price":476800.0,"size":0.1},{"price":476880.0,"size":2.0},{"price":476882.0,"size":0.12},{"price":476997.0,"size":0.51},{"price":477000.0,"size":1.4196},{"price":477011.0,"size":58.97},{"price":477098.0,"size":0.01},{"price":477136.0,"size":0.013},{"price":477179.0,"size":0.07},{"price":477343.0,"size":0.01},{"price":477500.0,"size":0.02},{"price":477777.0,"size":1.0498702},{"price":477880.0,"size":2.0},{"price":477997.0,"size":0.01},{"price":478000.0,"size":2.2186},{"price":478092.0,"size":0.01},{"price":478200.0,"size":0.25},{"price":478343.0,"size":0.01},{"price":478600.0,"size":0.4},{"price":478750.0,"size":0.01},{"price":478800.0,"size":12.1},{"price":478882.0,"size":0.12},{"price":478888.0,"size":9.99},{"price":478900.0,"size":1.5},{"price":478997.0,"size":0.01},{"price":479000.0,"size":1.9},{"price":479198.0,"size":0.01},{"price":479343.0,"size":0.01},{"price":479500.0,"size":51.0976115},{"price":479650.0,"size":0.5},{"price":479750.0,"size":0.02},{"price":479800.0,"size":0.2},{"price":479827.0,"size":29.93},{"price":479837.0,"size":0.01},{"price":479880.0,"size":2.0},{"price":479888.0,"size":0.1},{"price":479996.0,"size":0.2},{"price":479997.0,"size":0.01},{"price":479999.0,"size":0.496919},{"price":480000.0,"size":25.898},{"price":480021.0,"size":10.025},{"price":480038.0,"size":0.02},{"price":480113.0,"size":0.01},{"price":480200.0,"size":0.2},{"price":480250.0,"size":5.0},{"price":480343.0,"size":0.01},{"price":480447.0,"size":4.0},{"price":480480.0,"size":1.0},{"price":480500.0,"size":0.81},{"price":480527.0,"size":0.1},{"price":480680.0,"size":0.4},{"price":480700.0,"size":0.03},{"price":480750.0,"size":0.02},{"price":480800.0,"size":0.1},{"price":480882.0,"size":0.12},{"price":480899.0,"size":0.02},{"price":480990.0,"size":0.013},{"price":480997.0,"size":0.02},{"price":481000.0,"size":5.574676},{"price":481126.0,"size":0.5},{"price":481140.0,"size":0.01},{"price":481200.0,"size":1.0815},{"price":481234.0,"size":0.66},{"price":481239.0,"size":0.1499476},{"price":481351.0,"size":0.011},{"price":481456.0,"size":0.2},{"price":481480.0,"size":1.0},{"price":481500.0,"size":0.5},{"price":481800.0,"size":0.1},{"price":481997.0,"size":0.01},{"price":482000.0,"size":4.669},{"price":482162.0,"size":0.01},{"price":482187.0,"size":15.37},{"price":482222.0,"size":0.4},{"price":482400.0,"size":1.49},{"price":482480.0,"size":1.0},{"price":482500.0,"size":0.01},{"price":482531.0,"size":10.0},{"price":482572.0,"size":0.2},{"price":482750.0,"size":0.02},{"price":482800.0,"size":0.11},{"price":482882.0,"size":0.12},{"price":482997.0,"size":0.01},{"price":483000.0,"size":7.3},{"price":483203.0,"size":5.1},{"price":483300.0,"size":0.5},{"price":483333.0,"size":0.01},{"price":483480.0,"size":1.0},{"price":483500.0,"size":0.01},{"price":483645.0,"size":0.01},{"price":483800.0,"size":0.1},{"price":483997.0,"size":0.01},{"price":484000.0,"size":4.84},{"price":484450.0,"size":0.3},{"price":484480.0,"size":3.0},{"price":484487.0,"size":0.01},{"price":484721.0,"size":0.11},{"price":484800.0,"size":0.2},{"price":484882.0,"size":0.12},{"price":484888.0,"size":0.1},{"price":484901.0,"size":20.0},{"price":484997.0,"size":0.02},{"price":485000.0,"size":33.6485951},{"price":485113.0,"size":0.01},{"price":485322.0,"size":0.0997403},{"price":485480.0,"size":1.0},{"price":485631.0,"size":0.01},{"price":485675.0,"size":0.01},{"price":485678.0,"size":0.5},{"price":485680.0,"size":0.14},{"price":485750.0,"size":0.01},{"price":485800.0,"size":0.1},{"price":485880.0,"size":5.0},{"price":485983.0,"size":20.0},{"price":485997.0,"size":0.01},{"price":486000.0,"size":5.6921733},{"price":486024.0,"size":0.011},{"price":486373.0,"size":0.01},{"price":486438.0,"size":14.75},{"price":486446.0,"size":0.1},{"price":486480.0,"size":1.0},{"price":486500.0,"size":0.01},{"price":486544.0,"size":0.05},{"price":486786.0,"size":0.01},{"price":486800.0,"size":0.1},{"price":486882.0,"size":0.12},{"price":486900.0,"size":0.06},{"price":486901.0,"size":20.0},{"price":486997.0,"size":0.01},{"price":487000.0,"size":2.2},{"price":487136.0,"size":0.013},{"price":487480.0,"size":1.0},{"price":487500.0,"size":0.01},{"price":487600.0,"size":0.05},{"price":487786.0,"size":0.01},{"price":487800.0,"size":1.0},{"price":487950.0,"size":0.04},{"price":487997.0,"size":0.01},{"price":488000.0,"size":0.893282},{"price":488465.0,"size":0.05},{"price":488480.0,"size":1.0},{"price":488600.0,"size":0.5},{"price":488786.0,"size":0.01},{"price":488800.0,"size":0.1},{"price":488880.0,"size":5.0},{"price":488882.0,"size":0.12},{"price":488888.0,"size":11.4321},{"price":488997.0,"size":0.01},{"price":489000.0,"size":18.7607},{"price":489463.0,"size":0.1},{"price":489480.0,"size":1.0},{"price":489500.0,"size":0.01},{"price":489600.0,"size":0.14},{"price":489650.0,"size":0.5},{"price":489786.0,"size":0.01},{"price":489788.0,"size":0.1},{"price":489800.0,"size":0.8},{"price":489840.0,"size":0.01},{"price":489900.0,"size":1.0},{"price":489997.0,"size":0.01},{"price":489999.0,"size":0.1},{"price":490000.0,"size":35.129675},{"price":490001.0,"size":0.2},{"price":490300.0,"size":0.01},{"price":490480.0,"size":1.0},{"price":490698.0,"size":0.011},{"price":490786.0,"size":0.01},{"price":490800.0,"size":0.1},{"price":490882.0,"size":0.12},{"price":490997.0,"size":0.01},{"price":491000.0,"size":8.65},{"price":491160.0,"size":14.78},{"price":491300.0,"size":0.04},{"price":491480.0,"size":1.0},{"price":491786.0,"size":0.01},{"price":491800.0,"size":0.3},{"price":491882.0,"size":0.01},{"price":491997.0,"size":0.01},{"price":491999.0,"size":0.12},{"price":492000.0,"size":2.0017},{"price":492445.0,"size":0.01},{"price":492480.0,"size":1.0},{"price":492500.0,"size":1.05},{"price":492786.0,"size":0.01},{"price":492800.0,"size":0.6},{"price":492882.0,"size":0.12},{"price":492997.0,"size":0.01},{"price":493000.0,"size":9.9},{"price":493341.0,"size":0.1},{"price":493433.0,"size":0.01},{"price":493480.0,"size":1.0},{"price":493493.0,"size":0.2},{"price":493500.0,"size":0.02},{"price":493630.0,"size":0.15},{"price":493786.0,"size":0.01},{"price":493800.0,"size":0.1},{"price":493997.0,"size":0.01},{"price":494000.0,"size":2.43},{"price":494480.0,"size":1.0},{"price":494500.0,"size":0.17},{"price":494882.0,"size":0.12},{"price":494997.0,"size":0.01},{"price":494998.0,"size":0.9581203},{"price":495000.0,"size":47.963267},{"price":495480.0,"size":1.0},{"price":495500.0,"size":0.03},{"price":495572.0,"size":0.01},{"price":495700.0,"size":0.10027},{"price":495883.0,"size":15.33},{"price":495960.0,"size":0.01},{"price":495997.0,"size":0.01},{"price":496000.0,"size":3.439},{"price":496012.0,"size":0.98},{"price":496044.0,"size":0.01},{"price":496300.0,"size":0.01},{"price":496480.0,"size":1.0},{"price":496500.0,"size":0.02},{"price":496600.0,"size":0.04},{"price":496696.0,"size":0.01},{"price":496711.0,"size":0.102},{"price":496882.0,"size":0.12},{"price":496997.0,"size":0.01},{"price":496999.0,"size":0.12},{"price":497000.0,"size":1.01},{"price":497100.0,"size":0.281},{"price":497114.0,"size":0.016908},{"price":497136.0,"size":0.013}]}}}
1639350351.449146: {"jsonrpc":"2.0","method":"channelMessage","params":{"channel":"lightning_board_snapshot_XRP_JPY","message":{"mid_price":96.18,"bids":[{"price":96.06,"size":10149.0},{"price":96.01,"size":10268.0},{"price":95.98,"size":4652.1},{"price":95.97,"size":27616.54584},{"price":95.89,"size":6.940078},{"price":95.73,"size":5540.0},{"price":95.69,"size":9000.0},{"price":95.6,"size":5070.0},{"price":95.57,"size":13710.0},{"price":95.5,"size":82.934},{"price":95.4,"size":70.0},{"price":95.36,"size":137270.0},{"price":95.3,"size":5070.0},{"price":95.2,"size":70.0},{"price":95.16,"size":473.0},{"price":95.1,"size":70.0},{"price":95.0,"size":1954.1},{"price":94.9,"size":70.0},{"price":94.8,"size":1889.0},{"price":94.78,"size":53820.0},{"price":94.7,"size":70.0},{"price":94.6,"size":1570.0},{"price":94.5,"size":1072.0},{"price":94.42,"size":13530.0},{"price":94.4,"size":70.0},{"price":94.3,"size":70.0},{"price":94.2,"size":70.0},{"price":94.17,"size":27230.0},{"price":94.1,"size":70.0},{"price":94.0,"size":1677.0},{"price":93.99,"size":15.859},{"price":93.9,"size":70.0},{"price":93.8,"size":80.0},{"price":93.7,"size":70.0},{"price":93.6,"size":70.0},{"price":93.5,"size":74.0},{"price":93.45,"size":70.0},{"price":93.4,"size":87.0},{"price":93.32,"size":5.0},{"price":93.3,"size":70.0},{"price":93.2,"size":70.0},{"price":93.18,"size":3938.63},{"price":93.12,"size":40.0},{"price":93.1,"size":70.0},{"price":93.0,"size":13631.301075},{"price":92.97,"size":13470.0},{"price":92.9,"size":70.0},{"price":92.8,"size":70.0},{"price":92.7,"size":70.0},{"price":92.6,"size":70.0},{"price":92.51,"size":0.2},{"price":92.5,"size":899.0},{"price":92.49,"size":0.11},{"price":92.41,"size":0.2},{"price":92.4,"size":500.0},{"price":92.31,"size":0.2},{"price":92.3,"size":70.0},{"price":92.21,"size":0.2},{"price":92.2,"size":70.0},{"price":92.11,"size":0.2},{"price":92.1,"size":81.4},{"price":92.01,"size":0.2},{"price":92.0,"size":5724.043395},{"price":91.95,"size":0.495},{"price":91.92,"size":100.0},{"price":91.91,"size":0.2},{"price":91.9,"size":70.0},{"price":91.81,"size":0.2},{"price":91.8,"size":2757.0},{"price":91.7,"size":70.0},{"price":91.6,"size":70.0},{"price":91.53,"size":13740.0},{"price":91.5,"size":110.0},{"price":91.4,"size":70.0},{"price":91.3,"size":70.0},{"price":91.2,"size":70.0},{"price":91.1,"size":70.0},{"price":91.0,"size":6164.681318},{"price":90.98,"size":1000.0},{"price":90.92,"size":100.0},{"price":90.9,"size":70.0},{"price":90.8,"size":102.0},{"price":90.7,"size":70.0},{"price":90.6,"size":70.0},{"price":90.53,"size":100.0},{"price":90.5,"size":610.0},{"price":90.4,"size":70.0},{"price":90.3,"size":89.2},{"price":90.2,"size":70.0},{"price":90.19,"size":27.0},{"price":90.1,"size":240.0},{"price":90.01,"size":600.0},{"price":90.0,"size":19541.055555},{"price":89.99,"size":10.0},{"price":89.92,"size":100.0},{"price":89.9,"size":55.0},{"price":89.75,"size":100.0},{"price":89.7,"size":60.0},{"price":89.6,"size":1000.0},{"price":89.5,"size":4570.0},{"price":89.41,"size":500.0},{"price":89.3,"size":100.0},{"price":89.19,"size":300.0},{"price":89.15,"size":207.7},{"price":89.12,"size":2.0},{"price":89.1,"size":50.0},{"price":89.02,"size":300.51},{"price":89.01,"size":1000.0},{"price":89.0,"size":8203.861797},{"price":88.9,"size":405.0},{"price":88.84,"size":60.0},{"price":88.82,"size":112.589},{"price":88.7,"size":22.6},{"price":88.69,"size":1000.0},{"price":88.55,"size":420.0},{"price":88.5,"size":3081.0},{"price":88.29,"size":150.0},{"price":88.15,"size":2500.0},{"price":88.11,"size":156.0},{"price":88.1,"size":50.0},{"price":88.01,"size":1100.0},{"price":88.0,"size":26751.62},{"price":87.9,"size":1105.0},{"price":87.86,"size":500.0},{"price":87.68,"size":400.0},{"price":87.5,"size":4345.0},{"price":87.33,"size":1150.0},{"price":87.2,"size":103.165137},{"price":87.1,"size":50.0},{"price":87.01,"size":1000.0},{"price":87.0,"size":11316.3},{"price":86.95,"size":9200.0},{"price":86.9,"size":105.52},{"price":86.8,"size":200.0},{"price":86.57,"size":10.0},{"price":86.53,"size":1000.0},{"price":86.5,"size":1320.0},{"price":86.4,"size":10.0},{"price":86.17,"size":10.0},{"price":86.16,"size":1000.0},{"price":86.1,"size":3050.0},{"price":86.0,"size":19585.68},{"price":85.91,"size":120.0},{"price":85.9,"size":705.0},{"price":85.88,"size":25.0},{"price":85.69,"size":1000.0},{"price":85.61,"size":50.0},{"price":85.6,"size":1000.0},{"price":85.5,"size":160.0},{"price":85.35,"size":150.0},{"price":85.3,"size":1000.0},{"price":85.29,"size":126.0},{"price":85.25,"size":16550.604105},{"price":85.23,"size":1000.0},{"price":85.2,"size":50.0},{"price":85.11,"size":0.53},{"price":85.1,"size":3950.0},{"price":85.08,"size":10.0},{"price":85.04,"size":25.0},{"price":85.01,"size":600.0},{"price":85.0,"size":75986.705814},{"price":84.89,"size":500.0},{"price":84.85,"size":100.0},{"price":84.83,"size":100.0},{"price":84.82,"size":100.0},{"price":84.81,"size":5.0},{"price":84.72,"size":0.54},{"price":84.7,"size":100.0},{"price":84.6,"size":500.0},{"price":84.54,"size":11.0},{"price":84.5,"size":80.5},{"price":84.28,"size":0.35},{"price":84.12,"size":30.0},{"price":84.1,"size":150.0},{"price":84.0,"size":8231.095108},{"price":83.99,"size":100.0},{"price":83.97,"size":2002.5},{"price":83.85,"size":100.0},{"price":83.5,"size":282.0},{"price":83.33,"size":5.0},{"price":83.3,"size":1000.0},{"price":83.25,"size":300.0},{"price":83.1,"size":2456.7387},{"price":83.0,"size":12219.2},{"price":82.95,"size":100.0},{"price":82.92,"size":10000.0},{"price":82.91,"size":100.0},{"price":82.89,"size":67.0},{"price":82.79,"size":150.0},{"price":82.74,"size":2000.0},{"price":82.62,"size":10000.0},{"price":82.6,"size":1000.0},{"price":82.5,"size":13075.078787},{"price":82.22,"size":11000.0},{"price":82.15,"size":51.0},{"price":82.1,"size":50.0},{"price":82.0,"size":30925.1365},{"price":81.88,"size":30.0},{"price":81.85,"size":100.0},{"price":81.78,"size":0.7},{"price":81.65,"size":65.0},{"price":81.6,"size":1000.0},{"price":81.5,"size":1100.0},{"price":81.4,"size":5000.0},{"price":81.37,"size":24.5912},{"price":81.3,"size":6410.0},{"price":81.2,"size":2281.527},{"price":81.1,"size":550.0},{"price":81.03,"size":1000.0},{"price":81.0,"size":22360.909},{"price":80.99,"size":12.4},{"price":80.96,"size":10.0},{"price":80.95,"size":4000.0},{"price":80.94,"size":125.0},{"price":80.9,"size":911.0},{"price":80.88,"size":50.0},{"price":80.75,"size":100.0},{"price":80.73,"size":1000.0},{"price":80.72,"size":100.0},{"price":80.69,"size":10000.0},{"price":80.6,"size":1152.0},{"price":80.52,"size":500.0},{"price":80.5,"size":4230.0},{"price":80.44,"size":200.0},{"price":80.4,"size":271.0},{"price":80.19,"size":500.0},{"price":80.12,"size":200.0},{"price":80.1,"size":6636.0},{"price":80.09,"size":1000.0},{"price":80.02,"size":3620.0},{"price":80.0,"size":110476.075},{"price":79.9,"size":1500.0},{"price":79.86,"size":100.0},{"price":79.8,"size":3000.0},{"price":79.78,"size":30.0},{"price":79.72,"size":100.0},{"price":79.7,"size":30.0},{"price":79.6,"size":252.0},{"price":79.58,"size":1.0},{"price":79.5,"size":5150.0},{"price":79.4,"size":20.0},{"price":79.2,"size":2000.0},{"price":79.11,"size":150.0},{"price":79.1,"size":325.0},{"price":79.0,"size":4798.42},{"price":78.9,"size":20.0},{"price":78.8,"size":1010.0},{"price":78.72,"size":100.0},{"price":78.5,"size":3000.0},{"price":78.35,"size":50.0},{"price":78.21,"size":255.0},{"price":78.2,"size":8602.11},{"price":78.1,"size":690.0},{"price":78.0,"size":14272.980769},{"price":77.88,"size":1.3},{"price":77.77,"size":890.0},{"price":77.72,"size":100.0},{"price":77.7,"size":400.0},{"price":77.5,"size":3150.0},{"price":77.27,"size":100.0},{"price":77.1,"size":50.0},{"price":77.0,"size":11349.08},{"price":76.8,"size":1500.0},{"price":76.72,"size":100.0},{"price":76.63,"size":655.0},{"price":76.6,"size":500.0},{"price":76.53,"size":190.0},{"price":76.5,"size":3000.0},{"price":76.11,"size":5000.0},{"price":76.1,"size":2050.0},{"price":76.0,"size":6777.42},{"price":75.91,"size":1000.0},{"price":75.88,"size":50.0},{"price":75.79,"size":50.0},{"price":75.78,"size":1.4},{"price":75.72,"size":100.0},{"price":75.6,"size":500.0},{"price":75.52,"size":3000.0},{"price":75.5,"size":7500.0},{"price":75.3,"size":441.0},{"price":75.1,"size":50.0},{"price":75.01,"size":10.0},{"price":75.0,"size":17050.30333},{"price":74.74,"size":5000.0},{"price":74.54,"size":49.0},{"price":74.5,"size":3000.0},{"price":74.4,"size":5000.0},{"price":74.1,"size":50.0},{"price":74.0,"size":418.03},{"price":73.84,"size":30.0},{"price":73.5,"size":3000.0},{"price":73.39,"size":100.0},{"price":73.1,"size":785.0},{"price":73.0,"size":1778.4},{"price":72.9,"size":1.109},{"price":72.5,"size":3000.0},{"price":72.1,"size":50.0},{"price":72.0,"size":11526.78},{"price":71.68,"size":27.901},{"price":71.58,"size":200.0}],"asks":[{"price":96.3,"size":1352.25},{"price":96.32,"size":465.21},{"price":96.34,"size":5540.0},{"price":96.4,"size":9584.0},{"price":96.45,"size":27.65},{"price":96.49,"size":13710.0},{"price":96.6,"size":4000.0},{"price":96.7,"size":4070.0},{"price":96.75,"size":139250.0},{"price":96.8,"size":70.0},{"price":96.9,"size":70.0},{"price":96.99,"size":26630.0},{"price":97.0,"size":4451.0},{"price":97.1,"size":70.0},{"price":97.14,"size":5000.0},{"price":97.19,"size":8000.0},{"price":97.2,"size":1070.0},{"price":97.21,"size":5000.0},{"price":97.24,"size":5000.0},{"price":97.3,"size":70.0},{"price":97.34,"size":5000.0},{"price":97.4,"size":70.0},{"price":97.5,"size":1552.1},{"price":97.6,"size":70.0},{"price":97.7,"size":70.0},{"price":97.8,"size":70.0},{"price":97.9,"size":140.0},{"price":98.0,"size":2076.1},{"price":98.1,"size":70.0},{"price":98.2,"size":71.0},{"price":98.25,"size":4.0},{"price":98.3,"size":370.0},{"price":98.4,"size":70.0},{"price":98.48,"size":491.120224},{"price":98.5,"size":6077.1},{"price":98.55,"size":11000.0},{"price":98.7,"size":70.0},{"price":98.75,"size":4.0},{"price":98.8,"size":70.0},{"price":99.0,"size":8878.0},{"price":99.1,"size":70.0},{"price":99.13,"size":30.0},{"price":99.2,"size":70.0},{"price":99.24,"size":500.0},{"price":99.25,"size":4.0},{"price":99.3,"size":70.0},{"price":99.38,"size":14.104},{"price":99.4,"size":80.0},{"price":99.5,"size":4276.0},{"price":99.6,"size":70.0},{"price":99.7,"size":70.0},{"price":99.75,"size":4.0},{"price":99.8,"size":70.0},{"price":99.9,"size":70.0},{"price":99.99,"size":2994.0},{"price":100.0,"size":24347.2616},{"price":100.1,"size":70.0},{"price":100.2,"size":70.0},{"price":100.25,"size":4.0},{"price":100.3,"size":70.0},{"price":100.4,"size":70.0},{"price":100.5,"size":1311.0},{"price":100.6,"size":70.0},{"price":100.7,"size":70.0},{"price":100.75,"size":4.0},{"price":100.8,"size":70.0},{"price":100.9,"size":70.0},{"price":100.99,"size":499.0},{"price":101.0,"size":3108.0},{"price":101.1,"size":70.0},{"price":101.2,"size":70.0},{"price":101.25,"size":4.0},{"price":101.3,"size":70.0},{"price":101.4,"size":70.0},{"price":101.5,"size":77.0},{"price":101.6,"size":70.0},{"price":101.7,"size":70.0},{"price":101.75,"size":4.0},{"price":101.8,"size":70.0},{"price":101.89,"size":5000.0},{"price":101.9,"size":70.0},{"price":102.0,"size":5454.5},{"price":102.1,"size":70.0},{"price":102.2,"size":70.0},{"price":102.25,"size":4.0},{"price":102.3,"size":70.0},{"price":102.4,"size":70.0},{"price":102.5,"size":76.0},{"price":102.6,"size":70.0},{"price":102.7,"size":70.0},{"price":102.75,"size":4.0},{"price":102.8,"size":70.0},{"price":102.84,"size":194.472},{"price":102.9,"size":70.0},{"price":103.0,"size":100817.0},{"price":103.1,"size":70.0},{"price":103.2,"size":90.0},{"price":103.25,"size":4.0},{"price":103.28,"size":100.0},{"price":103.3,"size":660.7},{"price":103.4,"size":70.0},{"price":103.5,"size":106.0},{"price":103.6,"size":70.0},{"price":103.7,"size":100.0},{"price":103.75,"size":4.0},{"price":103.8,"size":70.0},{"price":103.9,"size":70.0},{"price":103.99,"size":499.0},{"price":104.0,"size":5010.0},{"price":104.09,"size":100.0},{"price":104.1,"size":100.0},{"price":104.13,"size":99.7},{"price":104.2,"size":400.0},{"price":104.25,"size":4.0},{"price":104.3,"size":100.0},{"price":104.4,"size":100.0},{"price":104.5,"size":9951.5},{"price":104.6,"size":800.0},{"price":104.61,"size":150.0},{"price":104.7,"size":100.0},{"price":104.75,"size":4.0},{"price":104.8,"size":99.8},{"price":104.9,"size":100.0},{"price":104.96,"size":1000.0},{"price":104.97,"size":1500.0},{"price":105.0,"size":28525.4381},{"price":105.02,"size":5652.0},{"price":105.1,"size":110.0},{"price":105.2,"size":100.0},{"price":105.25,"size":4.0},{"price":105.3,"size":100.0},{"price":105.31,"size":9.85},{"price":105.4,"size":100.0},{"price":105.46,"size":3795.0},{"price":105.5,"size":4700.7},{"price":105.55,"size":100.1},{"price":105.6,"size":100.0},{"price":105.7,"size":100.0},{"price":105.75,"size":4.0},{"price":105.78,"size":100.0},{"price":105.8,"size":2110.000001},{"price":105.98,"size":13000.0},{"price":105.99,"size":499.0},{"price":106.0,"size":12467.0},{"price":106.12,"size":9.8},{"price":106.25,"size":4.0},{"price":106.3,"size":11000.0},{"price":106.33,"size":49.2},{"price":106.5,"size":6.0},{"price":106.75,"size":4.0},{"price":107.0,"size":2167.0},{"price":107.25,"size":4.0},{"price":107.27,"size":100.0},{"price":107.5,"size":6.0},{"price":107.61,"size":21.3836},{"price":107.75,"size":4.0},{"price":108.0,"size":6991.67948},{"price":108.01,"size":6.491},{"price":108.2,"size":100.0},{"price":108.25,"size":4.0},{"price":108.5,"size":6.0},{"price":108.75,"size":4.0},{"price":108.96,"size":1389.050949},{"price":109.0,"size":3091.0},{"price":109.09,"size":1.0},{"price":109.1,"size":80.0},{"price":109.25,"size":4.0},{"price":109.5,"size":7.0},{"price":109.75,"size":4.0},{"price":109.9,"size":10.0},{"price":109.98,"size":29.0},{"price":110.0,"size":12253.7},{"price":110.11,"size":156.0},{"price":110.25,"size":4.0},{"price":110.5,"size":182.0},{"price":110.56,"size":218.95096},{"price":110.75,"size":4.0},{"price":110.99,"size":998.0},{"price":111.0,"size":3085.0},{"price":111.1,"size":5000.0},{"price":111.25,"size":4.0},{"price":111.5,"size":4.0},{"price":111.75,"size":4.0},{"price":112.0,"size":1720.892764},{"price":112.2,"size":49.2},{"price":112.25,"size":4.0},{"price":112.5,"size":1104.0},{"price":112.75,"size":4.0},{"price":112.8,"size":400.0},{"price":112.82,"size":49.2},{"price":112.9,"size":1000.0},{"price":113.0,"size":1774.0},{"price":113.25,"size":4.0},{"price":113.3,"size":699.0},{"price":113.5,"size":4.0},{"price":113.54,"size":17900.0},{"price":113.71,"size":49.2},{"price":113.75,"size":4.0},{"price":113.8,"size":100.0},{"price":114.0,"size":10698.410537},{"price":114.25,"size":4.0},{"price":114.4,"size":55.0},{"price":114.5,"size":104.0},{"price":114.75,"size":4.0},{"price":114.8,"size":1612.07},{"price":114.93,"size":49.2},{"price":115.0,"size":9176.5},{"price":115.05,"size":497.0009},{"price":115.1,"size":579.76036},{"price":115.15,"size":500.0},{"price":115.2,"size":3010.0},{"price":115.25,"size":504.0},{"price":115.3,"size":800.0},{"price":115.35,"size":500.0},{"price":115.4,"size":500.0},{"price":115.45,"size":500.0},{"price":115.5,"size":3404.0},{"price":115.6,"size":800.0},{"price":115.63,"size":49.2},{"price":115.7,"size":500.0},{"price":115.75,"size":4.0},{"price":115.78,"size":155.0},{"price":115.8,"size":500.0},{"price":115.87,"size":1000.0},{"price":115.9,"size":500.0},{"price":116.0,"size":3244.645},{"price":116.1,"size":500.0},{"price":116.11,"size":500.0},{"price":116.14,"size":500.0},{"price":116.15,"size":500.0},{"price":116.18,"size":500.0},{"price":116.2,"size":500.0},{"price":116.21,"size":500.0},{"price":116.24,"size":500.0},{"price":116.25,"size":504.0},{"price":116.28,"size":500.0},{"price":116.29,"size":500.0},{"price":116.3,"size":3827.0},{"price":116.31,"size":500.0},{"price":116.34,"size":500.0},{"price":116.35,"size":500.0},{"price":116.4,"size":500.0},{"price":116.44,"size":500.0},{"price":116.47,"size":1000.0},{"price":116.5,"size":606.0},{"price":116.54,"size":500.0},{"price":116.6,"size":500.0},{"price":116.64,"size":500.0},{"price":116.7,"size":501.0},{"price":116.74,"size":500.0},{"price":116.75,"size":4.0},{"price":116.8,"size":500.0},{"price":116.84,"size":500.0},{"price":116.88,"size":29.5},{"price":116.9,"size":500.0},{"price":116.94,"size":500.0},{"price":117.0,"size":2740.0},{"price":117.1,"size":500.0},{"price":117.2,"size":1505.0},{"price":117.25,"size":4.0},{"price":117.3,"size":34865.0},{"price":117.33,"size":29.5},{"price":117.4,"size":500.0},{"price":117.5,"size":966.0},{"price":117.6,"size":500.0},{"price":117.7,"size":500.0},{"price":117.75,"size":4.0},{"price":117.8,"size":500.0},{"price":117.9,"size":500.0},{"price":118.0,"size":4151.4},{"price":118.1,"size":500.0},{"price":118.12,"size":500.0},{"price":118.2,"size":500.0},{"price":118.22,"size":500.0},{"price":118.25,"size":4.0},{"price":118.3,"size":500.0},{"price":118.32,"size":500.0},{"price":118.4,"size":500.0},{"price":118.42,"size":500.0},{"price":118.5,"size":651.0},{"price":118.52,"size":500.0},{"price":118.6,"size":500.0},{"price":118.62,"size":500.0},{"price":118.7,"size":500.0},{"price":118.72,"size":750.0},{"price":118.75,"size":4.0},{"price":118.8,"size":500.0},{"price":118.82,"size":500.0},{"price":118.9,"size":820.0},{"price":118.92,"size":500.0},{"price":119.0,"size":11856.0},{"price":119.2,"size":2600.0},{"price":119.25,"size":4.0},{"price":119.48,"size":50.0},{"price":119.49,"size":654.5},{"price":119.5,"size":6.0},{"price":119.55,"size":90.0},{"price":119.75,"size":4.0},{"price":119.8,"size":100.0},{"price":119.88,"size":1288.0}]}}}
1639350351.456844: {"jsonrpc":"2.0","method":"channelMessage","params":{"channel":"lightning_board_XLM_JPY","message":{"mid_price":31.543,"bids":[{"price":31.506,"size":0.0},{"price":31.507,"size":4354.35}],"asks":[{"price":31.629,"size":3589.0},{"price":31.614,"size":1201.2}]}}}
1639350351.463236: {"jsonrpc":"2.0","method":"channelMessage","params":{"channel":"lightning_board_snapshot_MONA_JPY","message":{"mid_price":166.009,"bids":[{"price":83.5,"size":10.0},{"price":84.0,"size":10.0},{"price":84.1,"size":10.0},{"price":84.3,"size":10.0},{"price":84.5,"size":10.0},{"price":90.0,"size":100.0},{"price":93.572,"size":21.3836},{"price":94.4,"size":10.0},{"price":100.0,"size":733.94},{"price":101.0,"size":80.0},{"price":104.0,"size":60.0},{"price":105.0,"size":10.0},{"price":107.61,"size":18.5945},{"price":108.11,"size":10.0},{"price":110.0,"size":5.0},{"price":112.011,"size":30.0},{"price":120.0,"size":51.1},{"price":121.0,"size":150.0},{"price":123.75,"size":16.1691},{"price":125.0,"size":573.0},{"price":125.911,"size":30.0},{"price":126.27,"size":100.0},{"price":127.0,"size":150.0},{"price":128.0,"size":800.0},{"price":130.0,"size":1468.2},{"price":130.1,"size":5.0},{"price":131.0,"size":150.0},{"price":132.0,"size":321.0},{"price":135.0,"size":150.0},{"price":137.0,"size":350.0},{"price":139.0,"size":40.0},{"price":139.6,"size":10.0},{"price":139.811,"size":30.0},{"price":140.0,"size":2846.1},{"price":140.183,"size":28.535},{"price":141.1,"size":2510.0},{"price":141.4,"size":10.0},{"price":142.311,"size":14.0601},{"price":142.537,"size":140.0},{"price":145.0,"size":10.0},{"price":146.0,"size":20.0},{"price":146.1,"size":2000.0},{"price":147.0,"size":370.85714285},{"price":148.0,"size":769.0},{"price":149.0,"size":9.0},{"price":149.3,"size":50.0},{"price":149.36,"size":14.2},{"price":149.4,"size":24.18684765},{"price":149.8,"size":120.0},{"price":149.9,"size":50.0},{"price":150.0,"size":1582.63333},{"price":151.0,"size":258.1},{"price":151.1,"size":2000.0},{"price":152.0,"size":28.1},{"price":153.0,"size":458.1},{"price":153.65,"size":10.0},{"price":153.772,"size":2446.0},{"price":154.0,"size":8.1},{"price":154.524,"size":1.0014},{"price":155.0,"size":3925.10450676},{"price":155.06,"size":2489.0},{"price":155.2,"size":50.0},{"price":155.3,"size":4000.0},{"price":155.311,"size":69.51},{"price":156.0,"size":578.3},{"price":156.1,"size":1500.0},{"price":156.4,"size":10.0},{"price":157.0,"size":99.1},{"price":158.0,"size":221.1},{"price":158.375,"size":126.0},{"price":158.5,"size":30.0},{"price":158.628,"size":2472.0},{"price":158.879,"size":1000.0},{"price":159.0,"size":552.158},{"price":160.0,"size":5968.3525},{"price":160.039,"size":11.0},{"price":160.5,"size":10.0},{"price":160.545,"size":50.0},{"price":160.577,"size":4923.0},{"price":160.639,"size":30.0},{"price":161.0,"size":1460.2},{"price":161.1,"size":8461.71687854},{"price":161.2,"size":5.0},{"price":161.245,"size":2400.0},{"price":161.392,"size":9754.0},{"price":161.4,"size":5.0},{"price":161.6,"size":5.0},{"price":161.8,"size":683.0},{"price":162.0,"size":305.24691358},{"price":162.2,"size":5.0},{"price":162.207,"size":25175.0},{"price":162.4,"size":5.0},{"price":162.6,"size":5.0},{"price":162.8,"size":5.0},{"price":162.835,"size":2506.0},{"price":162.901,"size":964.0},{"price":163.0,"size":977.73337133},{"price":163.001,"size":10.0},{"price":163.14,"size":6.0},{"price":163.2,"size":5.0},{"price":163.4,"size":5.0},{"price":163.6,"size":5.0},{"price":163.8,"size":5.0},{"price":163.86,"size":1000.0},{"price":164.0,"size":399.5068536},{"price":164.02,"size":0.1},{"price":165.0,"size":206.93939393},{"price":165.002,"size":0.11515011},{"price":165.02,"size":500.0000002},{"price":165.021,"size":98.0}],"asks":[{"price":166.998,"size":0.80479767},{"price":166.999,"size":98.0},{"price":167.0,"size":161.0},{"price":167.5,"size":4.09152951},{"price":167.784,"size":23.841},{"price":168.0,"size":311.5},{"price":168.49,"size":83.3},{"price":168.839,"size":1000.0},{"price":169.0,"size":307.99},{"price":170.0,"size":315.0},{"price":170.2,"size":5.0},{"price":170.4,"size":5.0},{"price":170.6,"size":5.0},{"price":170.8,"size":5.0},{"price":170.999,"size":100.0},{"price":171.0,"size":415.0},{"price":171.2,"size":5.0},{"price":171.4,"size":5.0},{"price":171.6,"size":5.0},{"price":171.8,"size":5.0},{"price":171.999,"size":53.9},{"price":172.0,"size":515.0},{"price":172.2,"size":5.0},{"price":172.4,"size":5.0},{"price":172.6,"size":5.0},{"price":172.8,"size":5.0},{"price":173.0,"size":446.92},{"price":173.2,"size":5.0},{"price":173.4,"size":5.0},{"price":173.6,"size":5.0},{"price":173.8,"size":5.0},{"price":173.82,"size":1000.0},{"price":173.997,"size":7589.25902325},{"price":174.0,"size":1562.23062369},{"price":174.1,"size":199.7},{"price":174.2,"size":5.0},{"price":174.4,"size":5.0},{"price":174.6,"size":5.0},{"price":174.8,"size":5.0},{"price":174.9,"size":99.74},{"price":174.99,"size":730.0},{"price":175.0,"size":617.0},{"price":175.2,"size":5.0},{"price":175.4,"size":5.0},{"price":175.584,"size":4.9},{"price":175.6,"size":5.0},{"price":175.8,"size":5.0},{"price":176.0,"size":2532.5},{"price":176.2,"size":5.0},{"price":176.4,"size":5.0},{"price":176.6,"size":5.0},{"price":176.607,"size":4.9},{"price":176.8,"size":5.0},{"price":177.0,"size":365.0},{"price":177.2,"size":5.0},{"price":177.4,"size":5.0},{"price":177.6,"size":5.0},{"price":177.8,"size":5.0},{"price":178.0,"size":126.5},{"price":178.2,"size":5.0},{"price":178.4,"size":5.0},{"price":178.5,"size":2.238},{"price":178.6,"size":5.0},{"price":178.8,"size":5.0},{"price":179.0,"size":465.0},{"price":179.2,"size":5.0},{"price":179.4,"size":5.0},{"price":179.6,"size":5.0},{"price":179.7,"size":124.2},{"price":179.8,"size":5.0},{"price":180.0,"size":21159.143985},{"price":180.2,"size":5.0},{"price":180.4,"size":5.0},{"price":180.6,"size":5.0},{"price":180.8,"size":5.0},{"price":181.0,"size":165.0},{"price":181.2,"size":5.0},{"price":181.4,"size":5.0},{"price":181.6,"size":5.0},{"price":181.8,"size":5.0},{"price":182.0,"size":65.0},{"price":182.2,"size":5.0},{"price":182.4,"size":5.0},{"price":182.6,"size":5.0},{"price":182.8,"size":5.0},{"price":183.0,"size":365.0},{"price":183.2,"size":5.0},{"price":183.4,"size":5.0},{"price":183.6,"size":5.0},{"price":183.8,"size":5.0},{"price":184.0,"size":65.0},{"price":184.2,"size":5.0},{"price":184.4,"size":5.0},{"price":184.6,"size":5.0},{"price":184.8,"size":5.0},{"price":185.0,"size":1624.85618696},{"price":185.01,"size":5.87639265},{"price":185.2,"size":5.0},{"price":185.4,"size":5.0},{"price":185.6,"size":5.0},{"price":185.8,"size":5.0},{"price":186.0,"size":306.5},{"price":186.8,"size":5.0},{"price":187.0,"size":415.0},{"price":187.2,"size":5.0},{"price":187.4,"size":5.0},{"price":187.425,"size":1.0},{"price":187.6,"size":5.0},{"price":187.8,"size":5.0},{"price":188.0,"size":315.0},{"price":188.2,"size":5.0},{"price":188.211,"size":12.2262},{"price":188.4,"size":5.0},{"price":188.6,"size":5.0},{"price":188.8,"size":5.0},{"price":188.999,"size":50.0},{"price":189.0,"size":3582.0},{"price":189.2,"size":5.0},{"price":189.4,"size":5.0},{"price":189.6,"size":5.0},{"price":189.8,"size":5.0},{"price":189.999,"size":50.0},{"price":190.0,"size":674.96230901},{"price":190.2,"size":5.0},{"price":190.4,"size":5.0},{"price":190.6,"size":5.0},{"price":190.8,"size":5.0},{"price":190.999,"size":19.0},{"price":191.0,"size":415.0},{"price":191.113,"size":9.99},{"price":191.2,"size":5.0},{"price":191.4,"size":5.0},{"price":191.6,"size":5.0},{"price":191.8,"size":5.0},{"price":191.999,"size":50.0},{"price":192.0,"size":815.0},{"price":192.2,"size":5.0},{"price":192.4,"size":5.0},{"price":192.6,"size":5.0},{"price":192.747,"size":20.0},{"price":192.8,"size":5.0},{"price":192.999,"size":50.0},{"price":193.0,"size":465.75789053},{"price":193.2,"size":5.0},{"price":193.4,"size":5.0},{"price":193.6,"size":5.0},{"price":193.8,"size":5.0},{"price":193.999,"size":50.0},{"price":194.0,"size":325.5},{"price":194.2,"size":5.0},{"price":194.4,"size":5.0},{"price":194.6,"size":5.0},{"price":194.8,"size":5.0},{"price":194.999,"size":50.0},{"price":195.0,"size":1386.2},{"price":195.2,"size":5.0},{"price":195.4,"size":5.0},{"price":195.6,"size":5.0},{"price":195.8,"size":5.0},{"price":195.999,"size":50.0},{"price":196.0,"size":315.0},{"price":196.2,"size":5.0},{"price":196.4,"size":5.0},{"price":196.6,"size":5.0},{"price":196.8,"size":6.01474},{"price":196.999,"size":50.0},{"price":197.0,"size":1934.64296797},{"price":197.2,"size":5.0},{"price":197.4,"size":5.0},{"price":197.6,"size":5.0},{"price":197.8,"size":5.0},{"price":198.0,"size":516.6},{"price":199.0,"size":2042.88},{"price":199.2,"size":5.0},{"price":199.4,"size":5.0},{"price":199.5,"size":497.0},{"price":199.6,"size":5.0},{"price":199.8,"size":5.0},{"price":200.0,"size":1667.42438504},{"price":200.109,"size":4.9},{"price":200.2,"size":5.0},{"price":200.4,"size":5.0},{"price":200.8,"size":5.0},{"price":200.897,"size":50.0},{"price":201.0,"size":280.2},{"price":201.2,"size":5.0},{"price":201.4,"size":5.0},{"price":201.6,"size":5.0},{"price":201.8,"size":5.0},{"price":202.0,"size":325.2},{"price":202.2,"size":5.0},{"price":202.4,"size":5.0},{"price":202.6,"size":5.0},{"price":202.8,"size":5.0},{"price":203.0,"size":115.2},{"price":203.2,"size":5.0},{"price":203.6,"size":20.0},{"price":203.66,"size":270.0},{"price":204.0,"size":359.50071915},{"price":204.8,"size":8156.68824317},{"price":205.0,"size":33869.616},{"price":205.275,"size":200.0},{"price":206.0,"size":348.5607011},{"price":206.8,"size":10.0},{"price":207.0,"size":130.91515376},{"price":208.0,"size":329.2},{"price":209.0,"size":169.2},{"price":209.811,"size":26.5101},{"price":210.0,"size":5122.1978011},{"price":210.03,"size":994.0},{"price":211.0,"size":2270.42259506},{"price":211.167,"size":226.0},{"price":211.7,"size":10.0},{"price":212.0,"size":570.2},{"price":212.134,"size":0.985},{"price":213.0,"size":207.52986169},{"price":214.0,"size":3288.55795542},{"price":214.8,"size":1000.0},{"price":215.0,"size":1753.04052022},{"price":215.1,"size":299.28079113},{"price":216.0,"size":2265.1},{"price":216.3,"size":50.0},{"price":216.444,"size":10.6314},{"price":216.972,"size":1.0},{"price":216.998,"size":100.0},{"price":217.0,"size":1983.1},{"price":217.5,"size":5.0},{"price":218.0,"size":461.6},{"price":218.4,"size":5.0},{"price":219.0,"size":360.1},{"price":220.0,"size":9229.57604492},{"price":221.0,"size":33.1},{"price":222.0,"size":514.82664685},{"price":222.2,"size":45.0},{"price":222.222,"size":150.0},{"price":222.5,"size":5.0},{"price":223.0,"size":735.77279265},{"price":224.0,"size":135.1},{"price":224.01,"size":500.0},{"price":225.0,"size":3214.4},{"price":225.009,"size":300.0},{"price":225.17,"size":50.0},{"price":226.0,"size":114.1},{"price":226.8,"size":15.0},{"price":227.0,"size":50.1},{"price":227.5,"size":5.0},{"price":228.0,"size":43.1},{"price":229.0,"size":50.1},{"price":229.8,"size":10.0},{"price":230.0,"size":1975.239331},{"price":230.1,"size":110.0},{"price":231.86,"size":2.26},{"price":235.0,"size":317.0},{"price":235.4,"size":43.35581731},{"price":237.0,"size":6.0},{"price":239.0,"size":2998.0},{"price":239.899,"size":15.0},{"price":240.0,"size":999.4},{"price":240.1,"size":290.0},{"price":245.0,"size":605.0},{"price":245.009,"size":300.0},{"price":248.0,"size":219.0},{"price":248.911,"size":9.2447},{"price":250.0,"size":4097.79714313},{"price":253.0,"size":5.0},{"price":255.0,"size":205.0},{"price":257.0,"size":50.0},{"price":260.0,"size":220.5},{"price":264.0,"size":200.0},{"price":265.0,"size":5.0},{"price":268.0,"size":100.0},{"price":270.0,"size":573.56},{"price":273.0,"size":199.5},{"price":275.0,"size":27.0},{"price":279.0,"size":200.0},{"price":280.0,"size":1310.8},{"price":285.0,"size":5.0},{"price":286.25,"size":8.0389},{"price":289.91,"size":1.59648246},{"price":290.0,"size":110.7},{"price":292.0,"size":42.5},{"price":295.0,"size":10.1},{"price":298.0,"size":200.0},{"price":299.0,"size":200.0},{"price":300.0,"size":1637.62059002},{"price":301.0,"size":58.22738048},{"price":302.0,"size":30.0},{"price":305.0,"size":5.1},{"price":310.0,"size":1105.9},{"price":312.0,"size":6.0},{"price":315.0,"size":22.0},{"price":317.0,"size":5.0},{"price":320.0,"size":110.1},{"price":321.0,"size":100.0},{"price":325.0,"size":5.0},{"price":329.19,"size":6.9903},{"price":330.0,"size":604.0},{"price":332.0,"size":190.0},{"price":335.0,"size":5.0},{"price":338.0,"size":32.68899798},{"price":340.0,"size":58.5},{"price":341.0,"size":34.69794721},{"price":342.0,"size":1000.0},{"price":350.0,"size":1631.8225},{"price":360.0,"size":0.2},{"price":370.0,"size":20.0},{"price":380.0,"size":358.2},{"price":397.0,"size":1841.88271694},{"price":400.0,"size":103.81018981},{"price":435.0,"size":336.55349638}]}}}
