1639350336.121011: {"jsonrpc":"2.0","method":"channelMessage","params":{"channel":"lightning_board_snapshot_ETH_JPY","message":{"mid_price":471707.0,"bids":[{"price":471614.0,"size":0.63},{"price":471516.0,"size":0.58},{"price":471480.0,"size":0.62},{"price":471379.0,"size":1.37},{"price":471316.0,"size":14.99995},{"price":471281.0,"size":0.768},{"price":471280.0,"size":0.68},{"price":471277.0,"size":5.013},{"price":471171.0,"size":0.75},{"price":471156.0,"size":0.75},{"price":471148.0,"size":0.75},{"price":471144.0,"size":0.75},{"price":471123.0,"size":0.75},{"price":471104.0,"size":0.75},{"price":471103.0,"size":0.75},{"price":471094.0,"size":0.75},{"price":471077.0,"size":0.75},{"price":471000.0,"size":0.75},{"price":470655.0,"size":1.0},{"price":470631.0,"size":6.0},{"price":469927.0,"size":0.3},{"price":469833.0,"size":6.08},{"price":469752.0,"size":1.0},{"price":469644.0,"size":0.01},{"price":469614.0,"size":0.18},{"price":469399.0,"size":14.83},{"price":469356.0,"size":1.0},{"price":469336.0,"size":0.7},{"price":469207.0,"size":6.0},{"price":469020.0,"size":0.8},{"price":468944.0,"size":0.1},{"price":468222.0,"size":119.3},{"price":468098.0,"size":0.7},{"price":468017.0,"size":0.99},{"price":468007.0,"size":1.0},{"price":468000.0,"size":1.9},{"price":467941.0,"size":0.05},{"price":467700.0,"size":0.01},{"price":467585.0,"size":0.07},{"price":467526.0,"size":0.01},{"price":467252.0,"size":2.385},{"price":467075.0,"size":0.1},{"price":467074.0,"size":0.43},{"price":467004.0,"size":0.1},{"price":467000.0,"size":0.783},{"price":466501.0,"size":8.0},{"price":466260.0,"size":5.26},{"price":466228.0,"size":0.129},{"price":466100.0,"size":4.33},{"price":466000.0,"size":0.02},{"price":465720.0,"size":2.044312},{"price":465700.0,"size":0.5},{"price":465591.0,"size":58.73},{"price":465555.0,"size":0.7},{"price":465500.0,"size":0.5},{"price":465250.0,"size":0.5},{"price":465181.0,"size":1.33},{"price":465123.0,"size":0.1},{"price":465000.0,"size":9.458},{"price":464979.0,"size":0.01},{"price":464228.0,"size":0.129},{"price":464000.0,"size":0.0202},{"price":463230.0,"size":30.35},{"price":462990.0,"size":0.4},{"price":462500.0,"size":0.51},{"price":462228.0,"size":0.13},{"price":462000.0,"size":0.51},{"price":461000.0,"size":0.51},{"price":460946.0,"size":14.99},{"price":460742.0,"size":0.01},{"price":460724.0,"size":0.01},{"price":460563.0,"size":1.9},{"price":460321.0,"size":0.95},{"price":460250.0,"size":0.5},{"price":460228.0,"size":0.13},{"price":460123.0,"size":0.21},{"price":460111.0,"size":0.1},{"price":460106.0,"size":1.0},{"price":460010.0,"size":0.012},{"price":460000.0,"size":8.686101},{"price":459855.0,"size":0.2},{"price":459740.0,"size":62.247},{"price":459000.0,"size":32.5202},{"price":458819.0,"size":0.89},{"price":458545.0,"size":0.1},{"price":458500.0,"size":0.05},{"price":458228.0,"size":0.131},{"price":458151.0,"size":0.01},{"price":458090.0,"size":1.0},{"price":458000.0,"size":13.06},{"price":457976.0,"size":0.1},{"price":457777.0,"size":0.1},{"price":457500.0,"size":0.51},{"price":457136.0,"size":0.013},{"price":457000.0,"size":4.74},{"price":456870.0,"size":0.01},{"price":456500.0,"size":0.5},{"price":456253.0,"size":0.1},{"price":456243.0,"size":15.44},{"price":456228.0,"size":0.132},{"price":456213.0,"size":0.5},{"price":456100.0,"size":0.030696},{"price":456000.0,"size":1.7907},{"price":455968.0,"size":0.1},{"price":455777.0,"size":0.04},{"price":455507.0,"size":0.01},{"price":455500.0,"size":0.61},{"price":455438.0,"size":0.01},{"price":455250.0,"size":0.5},{"price":455111.0,"size":0.1},{"price":455044.0,"size":0.386},{"price":455000.0,"size":6.0746},{"price":454947.0,"size":1.1},{"price":454900.0,"size":0.05},{"price":454600.0,"size":0.11},{"price":454500.0,"size":0.238},{"price":454485.0,"size":0.01},{"price":454228.0,"size":0.132},{"price":454000.0,"size":15.191629},{"price":453865.0,"size":1.0},{"price":453750.0,"size":0.5},{"price":453610.0,"size":0.1},{"price":453601.0,"size":0.99},{"price":453500.0,"size":0.4},{"price":453492.0,"size":0.14},{"price":453112.0,"size":0.01},{"price":453006.0,"size":0.3},{"price":453003.0,"size":3.640905},{"price":453001.0,"size":8.0},{"price":453000.0,"size":3.4605},{"price":452787.0,"size":0.6747411},{"price":452500.0,"size":0.1204972},{"price":452369.0,"size":0.5},{"price":452244.0,"size":0.030957},{"price":452228.0,"size":0.133},{"price":452112.0,"size":0.01},{"price":452111.0,"size":0.01},{"price":452100.0,"size":0.07},{"price":452000.0,"size":1.854607},{"price":451880.0,"size":0.1},{"price":451820.0,"size":0.3},{"price":451800.0,"size":0.07},{"price":451600.0,"size":1.05},{"price":451555.0,"size":6.0},{"price":451539.0,"size":14.75},{"price":451500.0,"size":0.11},{"price":451250.0,"size":0.11},{"price":451200.0,"size":0.07},{"price":451176.0,"size":0.01},{"price":451111.0,"size":5.01},{"price":451001.0,"size":0.7},{"price":451000.0,"size":0.71},{"price":450900.0,"size":0.1},{"price":450740.0,"size":4.0},{"price":450600.0,"size":0.1},{"price":450500.0,"size":0.02},{"price":450300.0,"size":0.1},{"price":450250.0,"size":0.5},{"price":450228.0,"size":0.133},{"price":450210.0,"size":0.31},{"price":450111.0,"size":0.55},{"price":450106.0,"size":1.0},{"price":450038.0,"size":0.01},{"price":450020.0,"size":5.0},{"price":450010.0,"size":0.4340547},{"price":450008.0,"size":0.05},{"price":450002.0,"size":0.125},{"price":450001.0,"size":0.62697},{"price":450000.0,"size":40.3350369},{"price":449990.0,"size":0.45},{"price":449700.0,"size":0.1},{"price":449580.0,"size":0.1},{"price":449400.0,"size":1.11},{"price":449111.0,"size":0.02},{"price":449100.0,"size":0.1},{"price":449000.0,"size":0.32},{"price":448980.0,"size":0.1},{"price":448900.0,"size":0.5},{"price":448888.0,"size":0.2005},{"price":448800.0,"size":0.1},{"price":448587.0,"size":0.1},{"price":448565.0,"size":0.05},{"price":448500.0,"size":0.15},{"price":448300.0,"size":0.03},{"price":448230.0,"size":0.2},{"price":448228.0,"size":0.134},{"price":448222.0,"size":5.0},{"price":448200.0,"size":0.1},{"price":448111.0,"size":0.01},{"price":448001.0,"size":0.015},{"price":448000.0,"size":11.4566045},{"price":447800.0,"size":0.23},{"price":447700.0,"size":0.031},{"price":447576.0,"size":0.01},{"price":447502.0,"size":0.125},{"price":447500.0,"size":0.03},{"price":447252.0,"size":1.1},{"price":447136.0,"size":0.013},{"price":447111.0,"size":0.01},{"price":447000.0,"size":1.46},{"price":446836.0,"size":14.76},{"price":446543.0,"size":0.53},{"price":446500.0,"size":2.17},{"price":446489.0,"size":1.0},{"price":446400.0,"size":0.3},{"price":446397.0,"size":0.01},{"price":446228.0,"size":0.134},{"price":446111.0,"size":0.04},{"price":446000.0,"size":2.870067},{"price":445973.0,"size":0.1121121},{"price":445900.0,"size":0.01},{"price":445885.0,"size":0.02},{"price":445858.0,"size":0.01},{"price":445700.0,"size":0.01},{"price":445670.0,"size":0.2},{"price":445555.0,"size":1.0},{"price":445525.0,"size":0.012134},{"price":445500.0,"size":1.285},{"price":445451.0,"size":1.0},{"price":445188.0,"size":0.3},{"price":445111.0,"size":0.12},{"price":445088.0,"size":0.2},{"price":445011.0,"size":0.3},{"price":445008.0,"size":0.01},{"price":445002.0,"size":0.125},{"price":445001.0,"size":0.03},{"price":445000.0,"size":9.6017349},{"price":444924.0,"size":0.01},{"price":444900.0,"size":0.06743},{"price":444502.0,"size":0.01},{"price":444500.0,"size":0.25},{"price":444444.0,"size":1.21},{"price":444400.0,"size":0.01},{"price":444309.0,"size":0.01},{"price":444228.0,"size":0.135},{"price":444111.0,"size":0.01},{"price":444050.0,"size":0.017},{"price":444023.0,"size":0.01},{"price":444000.0,"size":7.020865},{"price":443944.0,"size":0.01},{"price":443739.0,"size":1.0},{"price":443502.0,"size":0.01},{"price":443500.0,"size":0.043822},{"price":443400.0,"size":1.0},{"price":443300.0,"size":0.01},{"price":443111.0,"size":0.01},{"price":443002.0,"size":1.0},{"price":443000.0,"size":0.50436},{"price":442921.0,"size":0.01},{"price":442844.0,"size":0.11},{"price":442502.0,"size":0.135},{"price":442500.0,"size":0.05},{"price":442450.0,"size":0.03},{"price":442350.0,"size":0.6},{"price":442258.0,"size":6.0},{"price":442228.0,"size":0.136},{"price":442111.0,"size":0.01},{"price":442000.0,"size":2.3356125},{"price":441888.0,"size":0.1},{"price":441502.0,"size":0.01},{"price":441410.0,"size":1.0},{"price":441249.0,"size":0.01},{"price":441200.0,"size":5.0},{"price":441111.0,"size":1.01},{"price":441100.0,"size":0.3},{"price":441008.0,"size":0.1},{"price":441000.0,"size":22.025},{"price":440888.0,"size":0.2},{"price":440700.0,"size":2.0},{"price":440666.0,"size":0.5},{"price":440603.0,"size":0.01},{"price":440600.0,"size":0.01},{"price":440500.0,"size":0.029},{"price":440228.0,"size":0.136},{"price":440212.0,"size":0.11356},{"price":440139.0,"size":0.2},{"price":440111.0,"size":0.13},{"price":440099.0,"size":0.01},{"price":440088.0,"size":0.3},{"price":440070.0,"size":0.01},{"price":440050.0,"size":0.2},{"price":440010.0,"size":0.01},{"price":440008.0,"size":0.1},{"price":440002.0,"size":0.125},{"price":440001.0,"size":0.1},{"price":440000.0,"size":40.446149},{"price":439999.0,"size":0.1},{"price":439807.0,"size":0.01},{"price":439800.0,"size":0.1},{"price":439500.0,"size":0.05},{"price":439495.0,"size":0.505125},{"price":439157.0,"size":0.10025},{"price":439115.0,"size":1.0},{"price":439111.0,"size":0.03},{"price":439100.0,"size":0.642},{"price":439000.0,"size":8.28319},{"price":438845.0,"size":1.0},{"price":438666.0,"size":0.5},{"price":438598.0,"size":0.01},{"price":438575.0,"size":0.1}],"asks":[{"price":471800.0,"size":0.02},{"price":471940.0,"size":0.75},{"price":472000.0,"size":0.02},{"price":472200.0,"size":0.02},{"price":472252.0,"size":0.01},{"price":472322.0,"size":1.984},{"price":472323.0,"size":6.0},{"price":472400.0,"size":0.02},{"price":472493.0,"size":44.0},{"price":472500.0,"size":0.01},{"price":472527.0,"size":6.08},{"price":472600.0,"size":0.02},{"price":472639.0,"size":0.51},{"price":472696.0,"size":4.202},{"price":472728.0,"size":0.6},{"price":472752.0,"size":0.01},{"price":472800.0,"size":0.02},{"price":472822.0,"size":0.7},{"price":472900.0,"size":0.013},{"price":472902.0,"size":14.83},{"price":472939.0,"size":6.0},{"price":473000.0,"size":0.33},{"price":473038.0,"size":1.01},{"price":473050.0,"size":0.010613},{"price":473163.0,"size":0.06},{"price":473200.0,"size":0.02},{"price":473212.0,"size":0.029586},{"price":473252.0,"size":0.01},{"price":473300.0,"size":0.11},{"price":473400.0,"size":0.53},{"price":473473.0,"size":0.2},{"price":473500.0,"size":0.01},{"price":473550.0,"size":0.1050705},{"price":473599.0,"size":0.3005},{"price":473600.0,"size":1.03},{"price":473700.0,"size":0.01},{"price":473718.0,"size":0.5},{"price":473752.0,"size":0.01},{"price":473772.0,"size":0.0146843},{"price":473800.0,"size":0.03},{"price":473900.0,"size":0.01},{"price":473960.0,"size":117.31},{"price":473968.0,"size":0.09},{"price":473997.0,"size":0.01},{"price":474000.0,"size":1.2201},{"price":474100.0,"size":0.01},{"price":474200.0,"size":0.03},{"price":474300.0,"size":0.01},{"price":474400.0,"size":0.05},{"price":474450.0,"size":0.5},{"price":474500.0,"size":0.02},{"price":474535.0,"size":0.15},{"price":474558.0,"size":0.02},{"price":474600.0,"size":0.03},{"price":474650.0,"size":0.5},{"price":474656.0,"size":0.01},{"price":474700.0,"size":0.01},{"price":474800.0,"size":0.03},{"price":474882.0,"size":0.12},{"price":474888.0,"size":0.1},{"price":474900.0,"size":0.01},{"price":474950.0,"size":0.5},{"price":474997.0,"size":0.21},{"price":475000.0,"size":12.0154268},{"price":475123.0,"size":0.66},{"price":475436.0,"size":0.07},{"price":475457.0,"size":1.0},{"price":475555.0,"size":0.05},{"price":475750.0,"size":0.01},{"price":475836.0,"size":29.93},{"price":475880.0,"size":3.0},{"price":475899.0,"size":0.027},{"price":475997.0,"size":0.01},{"price":476000.0,"size":2.2872},{"price":476434.0,"size":1.9626441},{"price":476468.0,"size":0.07},{"price":476600.0,"size":0.1},{"price":476678.0,"size":0.011},{"price":476750.0,"size":0.02},{"price":476800.0,"size":0.1},{"price":476880.0,"size":2.0},{"price":476882.0,"size":0.12},{"price":476997.0,"size":0.51},{"price":477000.0,"size":1.4196},{"price":477011.0,"size":58.97},{"price":477037.0,"size":15.37},{"price":477098.0,"size":0.01},{"price":477136.0,"size":0.013},{"price":477179.0,"size":0.07},{"price":477343.0,"size":0.01},{"price":477500.0,"size":0.02},{"price":477777.0,"size":1.0498702},{"price":477880.0,"size":2.0},{"price":477997.0,"size":0.01},{"price":478000.0,"size":2.2186},{"price":478092.0,"size":0.01},{"price":478200.0,"size":0.25},{"price":478343.0,"size":0.01},{"price":478600.0,"size":0.4},{"price":478750.0,"size":0.01},{"price":478800.0,"size":12.1},{"price":478882.0,"size":0.12},{"price":478888.0,"size":9.99},{"price":478900.0,"size":1.5},{"price":478997.0,"size":0.01},{"price":479000.0,"size":1.9},{"price":479198.0,"size":0.01},{"price":479343.0,"size":0.01},{"price":479500.0,"size":51.0976115},{"price":479650.0,"size":0.5},{"price":479750.0,"size":0.02},{"price":479800.0,"size":0.2},{"price":479837.0,"size":0.01},{"price":479880.0,"size":2.0},{"price":479888.0,"size":0.1},{"price":479996.0,"size":0.2},{"price":479997.0,"size":0.01},{"price":479999.0,"size":0.496919},{"price":480000.0,"size":25.898},{"price":480021.0,"size":10.025},{"price":480038.0,"size":0.02},{"price":480113.0,"size":0.01},{"price":480200.0,"size":0.2},{"price":480250.0,"size":5.0},{"price":480343.0,"size":0.01},{"price":480447.0,"size":4.0},{"price":480480.0,"size":1.0},{"price":480500.0,"size":0.81},{"price":480527.0,"size":0.1},{"price":480680.0,"size":0.4},{"price":480700.0,"size":0.03},{"price":480750.0,"size":0.02},{"price":480800.0,"size":0.1},{"price":480882.0,"size":0.12},{"price":480899.0,"size":0.02},{"price":480990.0,"size":0.013},{"price":480997.0,"size":0.02},{"price":481000.0,"size":5.574676},{"price":481126.0,"size":0.5},{"price":481140.0,"size":0.01},{"price":481200.0,"size":1.0815},{"price":481234.0,"size":0.66},{"price":481239.0,"size":0.1499476},{"price":481351.0,"size":0.011},{"price":481456.0,"size":0.2},{"price":481480.0,"size":1.0},{"price":481500.0,"size":0.5},{"price":481800.0,"size":0.1},{"price":481997.0,"size":0.01},{"price":482000.0,"size":4.669},{"price":482162.0,"size":0.01},{"price":482222.0,"size":0.4},{"price":482400.0,"size":1.49},{"price":482480.0,"size":1.0},{"price":482500.0,"size":0.01},{"price":482531.0,"size":10.0},{"price":482572.0,"size":0.2},{"price":482750.0,"size":0.02},{"price":482800.0,"size":0.11},{"price":482882.0,"size":0.12},{"price":482997.0,"size":0.01},{"price":483000.0,"size":7.3},{"price":483203.0,"size":5.1},{"price":483300.0,"size":0.5},{"price":483333.0,"size":0.01},{"price":483480.0,"size":1.0},{"price":483500.0,"size":0.01},{"price":483645.0,"size":0.01},{"price":483800.0,"size":0.1},{"price":483997.0,"size":0.01},{"price":484000.0,"size":4.84},{"price":484450.0,"size":0.3},{"price":484480.0,"size":3.0},{"price":484487.0,"size":0.01},{"price":484721.0,"size":0.11},{"price":484800.0,"size":0.2},{"price":484882.0,"size":0.12},{"price":484888.0,"size":0.1},{"price":484901.0,"size":20.0},{"price":484997.0,"size":0.02},{"price":485000.0,"size":33.6485951},{"price":485113.0,"size":0.01},{"price":485322.0,"size":0.0997403},{"price":485480.0,"size":1.0},{"price":485631.0,"size":0.01},{"price":485675.0,"size":0.01},{"price":485678.0,"size":0.5},{"price":485680.0,"size":0.14},{"price":485750.0,"size":0.01},{"price":485800.0,"size":0.1},{"price":485880.0,"size":5.0},{"price":485983.0,"size":20.0},{"price":485997.0,"size":0.01},{"price":486000.0,"size":5.6921733},{"price":486024.0,"size":0.011},{"price":486373.0,"size":0.01},{"price":486438.0,"size":14.75},{"price":486446.0,"size":0.1},{"price":486480.0,"size":1.0},{"price":486500.0,"size":0.01},{"price":486544.0,"size":0.05},{"price":486786.0,"size":0.01},{"price":486800.0,"size":0.1},{"price":486882.0,"size":0.12},{"price":486900.0,"size":0.06},{"price":486901.0,"size":20.0},{"price":486997.0,"size":0.01},{"price":487000.0,"size":2.2},{"price":487136.0,"size":0.013},{"price":487480.0,"size":1.0},{"price":487500.0,"size":0.01},{"price":487600.0,"size":0.05},{"price":487786.0,"size":0.01},{"price":487800.0,"size":1.0},{"price":487950.0,"size":0.04},{"price":487997.0,"size":0.01},{"price":488000.0,"size":0.893282},{"price":488465.0,"size":0.05},{"price":488480.0,"size":1.0},{"price":488600.0,"size":0.5},{"price":488786.0,"size":0.01},{"price":488800.0,"size":0.1},{"price":488880.0,"size":5.0},{"price":488882.0,"size":0.12},{"price":488888.0,"size":11.4321},{"price":488997.0,"size":0.01},{"price":489000.0,"size":18.7607},{"price":489463.0,"size":0.1},{"price":489480.0,"size":1.0},{"price":489500.0,"size":0.01},{"price":489600.0,"size":0.14},{"price":489650.0,"size":0.5},{"price":489786.0,"size":0.01},{"price":489788.0,"size":0.1},{"price":489800.0,"size":0.8},{"price":489840.0,"size":0.01},{"price":489900.0,"size":1.0},{"price":489997.0,"size":0.01},{"price":489999.0,"size":0.1},{"price":490000.0,"size":35.129675},{"price":490001.0,"size":0.2},{"price":490300.0,"size":0.01},{"price":490480.0,"size":1.0},{"price":490698.0,"size":0.011},{"price":490786.0,"size":0.01},{"price":490800.0,"size":0.1},{"price":490882.0,"size":0.12},{"price":490997.0,"size":0.01},{"price":491000.0,"size":8.65},{"price":491160.0,"size":14.78},{"price":491300.0,"size":0.04},{"price":491480.0,"size":1.0},{"price":491786.0,"size":0.01},{"price":491800.0,"size":0.3},{"price":491882.0,"size":0.01},{"price":491997.0,"size":0.01},{"price":491999.0,"size":0.12},{"price":492000.0,"size":2.0017},{"price":492445.0,"size":0.01},{"price":492480.0,"size":1.0},{"price":492500.0,"size":1.05},{"price":492786.0,"size":0.01},{"price":492800.0,"size":0.6},{"price":492882.0,"size":0.12},{"price":492997.0,"size":0.01},{"price":493000.0,"size":9.9},{"price":493341.0,"size":0.1},{"price":493433.0,"size":0.01},{"price":493480.0,"size":1.0},{"price":493493.0,"size":0.2},{"price":493500.0,"size":0.02},{"price":493630.0,"size":0.15},{"price":493786.0,"size":0.01},{"price":493800.0,"size":0.1},{"price":493997.0,"size":0.01},{"price":494000.0,"size":2.43},{"price":494480.0,"size":1.0},{"price":494500.0,"size":0.17},{"price":494882.0,"size":0.12},{"price":494997.0,"size":0.01},{"price":494998.0,"size":0.9581203},{"price":495000.0,"size":47.963267},{"price":495480.0,"size":1.0},{"price":495500.0,"size":0.03},{"price":495572.0,"size":0.01},{"price":495700.0,"size":0.10027},{"price":495883.0,"size":15.33},{"price":495960.0,"size":0.01},{"price":495997.0,"size":0.01},{"price":496000.0,"size":3.439},{"price":496012.0,"size":0.98},{"price":496044.0,"size":0.01},{"price":496300.0,"size":0.01},{"price":496480.0,"size":1.0},{"price":496500.0,"size":0.02},{"price":496600.0,"size":0.04},{"price":496696.0,"size":0.01},{"price":496711.0,"size":0.102},{"price":496882.0,"size":0.12},{"price":496997.0,"size":0.01}]}}}
1639350336.128722: {"jsonrpc":"2.0","method":"channelMessage","params":{"channel":"lightning_board_snapshot_XRP_JPY","message":{"mid_price":96.01,"bids":[{"price":95.95,"size":17012.54584},{"price":95.87,"size":10363.0},{"price":95.85,"size":2326.5},{"price":95.84,"size":10819.0},{"price":95.81,"size":10580.0},{"price":95.78,"size":10770.776},{"price":95.71,"size":9000.0},{"price":95.68,"size":5540.0},{"price":95.6,"size":5070.0},{"price":95.57,"size":13710.0},{"price":95.5,"size":82.934},{"price":95.42,"size":9000.0},{"price":95.4,"size":70.0},{"price":95.36,"size":137270.0},{"price":95.3,"size":5070.0},{"price":95.2,"size":70.0},{"price":95.16,"size":473.0},{"price":95.1,"size":70.0},{"price":95.0,"size":1954.1},{"price":94.9,"size":70.0},{"price":94.8,"size":1889.0},{"price":94.78,"size":53820.0},{"price":94.7,"size":70.0},{"price":94.6,"size":1570.0},{"price":94.5,"size":1072.0},{"price":94.42,"size":13530.0},{"price":94.4,"size":70.0},{"price":94.3,"size":70.0},{"price":94.2,"size":70.0},{"price":94.17,"size":27230.0},{"price":94.1,"size":70.0},{"price":94.0,"size":1677.0},{"price":93.99,"size":15.859},{"price":93.9,"size":70.0},{"price":93.8,"size":80.0},{"price":93.7,"size":70.0},{"price":93.6,"size":70.0},{"price":93.5,"size":74.0},{"price":93.45,"size":70.0},{"price":93.4,"size":87.0},{"price":93.32,"size":5.0},{"price":93.3,"size":70.0},{"price":93.2,"size":70.0},{"price":93.18,"size":3938.63},{"price":93.12,"size":40.0},{"price":93.1,"size":70.0},{"price":93.0,"size":13631.301075},{"price":92.97,"size":13470.0},{"price":92.9,"size":70.0},{"price":92.8,"size":70.0},{"price":92.7,"size":70.0},{"price":92.6,"size":70.0},{"price":92.51,"size":0.2},{"price":92.5,"size":899.0},{"price":92.49,"size":0.11},{"price":92.41,"size":0.2},{"price":92.4,"size":500.0},{"price":92.31,"size":0.2},{"price":92.3,"size":70.0},{"price":92.21,"size":0.2},{"price":92.2,"size":70.0},{"price":92.11,"size":0.2},{"price":92.1,"size":81.4},{"price":92.01,"size":0.2},{"price":92.0,"size":5724.043395},{"price":91.95,"size":0.495},{"price":91.92,"size":100.0},{"price":91.91,"size":0.2},{"price":91.9,"size":70.0},{"price":91.81,"size":0.2},{"price":91.8,"size":2757.0},{"price":91.7,"size":70.0},{"price":91.6,"size":70.0},{"price":91.53,"size":13740.0},{"price":91.5,"size":110.0},{"price":91.4,"size":70.0},{"price":91.3,"size":70.0},{"price":91.2,"size":70.0},{"price":91.1,"size":70.0},{"price":91.0,"size":6164.681318},{"price":90.98,"size":1000.0},{"price":90.92,"size":100.0},{"price":90.9,"size":70.0},{"price":90.8,"size":102.0},{"price":90.7,"size":70.0},{"price":90.6,"size":70.0},{"price":90.53,"size":100.0},{"price":90.5,"size":610.0},{"price":90.4,"size":70.0},{"price":90.3,"size":89.2},{"price":90.2,"size":70.0},{"price":90.19,"size":27.0},{"price":90.1,"size":240.0},{"price":90.01,"size":600.0},{"price":90.0,"size":19541.055555},{"price":89.99,"size":10.0},{"price":89.92,"size":100.0},{"price":89.9,"size":55.0},{"price":89.75,"size":100.0},{"price":89.7,"size":60.0},{"price":89.6,"size":1000.0},{"price":89.5,"size":4570.0},{"price":89.41,"size":500.0},{"price":89.3,"size":100.0},{"price":89.19,"size":300.0},{"price":89.15,"size":207.7},{"price":89.12,"size":2.0},{"price":89.1,"size":50.0},{"price":89.02,"size":300.51},{"price":89.01,"size":1000.0},{"price":89.0,"size":8203.861797},{"price":88.9,"size":405.0},{"price":88.84,"size":60.0},{"price":88.82,"size":112.589},{"price":88.7,"size":22.6},{"price":88.69,"size":1000.0},{"price":88.55,"size":420.0},{"price":88.5,"size":3081.0},{"price":88.29,"size":150.0},{"price":88.15,"size":2500.0},{"price":88.11,"size":156.0},{"price":88.1,"size":50.0},{"price":88.01,"size":1100.0},{"price":88.0,"size":26751.62},{"price":87.9,"size":1105.0},{"price":87.86,"size":500.0},{"price":87.68,"size":400.0},{"price":87.5,"size":4345.0},{"price":87.33,"size":1150.0},{"price":87.2,"size":103.165137},{"price":87.1,"size":50.0},{"price":87.01,"size":1000.0},{"price":87.0,"size":11316.3},{"price":86.95,"size":9200.0},{"price":86.9,"size":105.52},{"price":86.8,"size":200.0},{"price":86.57,"size":10.0},{"price":86.53,"size":1000.0},{"price":86.5,"size":1320.0},{"price":86.4,"size":10.0},{"price":86.17,"size":10.0},{"price":86.16,"size":1000.0},{"price":86.1,"size":3050.0},{"price":86.0,"size":19585.68},{"price":85.91,"size":120.0},{"price":85.9,"size":705.0},{"price":85.88,"size":25.0},{"price":85.69,"size":1000.0},{"price":85.61,"size":50.0},{"price":85.6,"size":1000.0},{"price":85.5,"size":160.0},{"price":85.35,"size":150.0},{"price":85.3,"size":1000.0},{"price":85.29,"size":126.0},{"price":85.25,"size":16550.604105},{"price":85.23,"size":1000.0},{"price":85.2,"size":50.0},{"price":85.11,"size":0.53},{"price":85.1,"size":3950.0},{"price":85.08,"size":10.0},{"price":85.04,"size":25.0},{"price":85.01,"size":600.0},{"price":85.0,"size":75986.705814},{"price":84.89,"size":500.0},{"price":84.85,"size":100.0},{"price":84.83,"size":100.0},{"price":84.82,"size":100.0},{"price":84.81,"size":5.0},{"price":84.72,"size":0.54},{"price":84.7,"size":100.0},{"price":84.6,"size":500.0},{"price":84.54,"size":11.0},{"price":84.5,"size":80.5},{"price":84.28,"size":0.35},{"price":84.12,"size":30.0},{"price":84.1,"size":150.0},{"price":84.0,"size":8231.095108},{"price":83.99,"size":100.0},{"price":83.97,"size":2002.5},{"price":83.85,"size":100.0},{"price":83.5,"size":282.0},{"price":83.33,"size":5.0},{"price":83.3,"size":1000.0},{"price":83.25,"size":300.0},{"price":83.1,"size":2456.7387},{"price":83.0,"size":12219.2},{"price":82.95,"size":100.0},{"price":82.92,"size":10000.0},{"price":82.91,"size":100.0},{"price":82.89,"size":67.0},{"price":82.79,"size":150.0},{"price":82.74,"size":2000.0},{"price":82.62,"size":10000.0},{"price":82.6,"size":1000.0},{"price":82.5,"size":13075.078787},{"price":82.22,"size":11000.0},{"price":82.15,"size":51.0},{"price":82.1,"size":50.0},{"price":82.0,"size":30925.1365},{"price":81.88,"size":30.0},{"price":81.85,"size":100.0},{"price":81.78,"size":0.7},{"price":81.65,"size":65.0},{"price":81.6,"size":1000.0},{"price":81.5,"size":1100.0},{"price":81.4,"size":5000.0},{"price":81.37,"size":24.5912},{"price":81.3,"size":6410.0},{"price":81.2,"size":2281.527},{"price":81.1,"size":550.0},{"price":81.03,"size":1000.0},{"price":81.0,"size":22360.909},{"price":80.99,"size":12.4},{"price":80.96,"size":10.0},{"price":80.95,"size":4000.0},{"price":80.94,"size":125.0},{"price":80.9,"size":911.0},{"price":80.88,"size":50.0},{"price":80.75,"size":100.0},{"price":80.73,"size":1000.0},{"price":80.72,"size":100.0},{"price":80.69,"size":10000.0},{"price":80.6,"size":1152.0},{"price":80.52,"size":500.0},{"price":80.5,"size":4230.0},{"price":80.44,"size":200.0},{"price":80.4,"size":271.0},{"price":80.19,"size":500.0},{"price":80.12,"size":200.0},{"price":80.1,"size":6636.0},{"price":80.09,"size":1000.0},{"price":80.02,"size":3620.0},{"price":80.0,"size":110476.075},{"price":79.9,"size":1500.0},{"price":79.86,"size":100.0},{"price":79.8,"size":3000.0},{"price":79.78,"size":30.0},{"price":79.72,"size":100.0},{"price":79.7,"size":30.0},{"price":79.6,"size":252.0},{"price":79.58,"size":1.0},{"price":79.5,"size":5150.0},{"price":79.4,"size":20.0},{"price":79.2,"size":2000.0},{"price":79.11,"size":150.0},{"price":79.1,"size":325.0},{"price":79.0,"size":4798.42},{"price":78.9,"size":20.0},{"price":78.8,"size":1010.0},{"price":78.72,"size":100.0},{"price":78.5,"size":3000.0},{"price":78.35,"size":50.0},{"price":78.21,"size":255.0},{"price":78.2,"size":8602.11},{"price":78.1,"size":690.0},{"price":78.0,"size":14272.980769},{"price":77.88,"size":1.3},{"price":77.77,"size":890.0},{"price":77.72,"size":100.0},{"price":77.7,"size":400.0},{"price":77.5,"size":3150.0},{"price":77.27,"size":100.0},{"price":77.1,"size":50.0},{"price":77.0,"size":11349.08},{"price":76.8,"size":1500.0},{"price":76.72,"size":100.0},{"price":76.63,"size":655.0},{"price":76.6,"size":500.0},{"price":76.53,"size":190.0},{"price":76.5,"size":3000.0},{"price":76.11,"size":5000.0},{"price":76.1,"size":2050.0},{"price":76.0,"size":6777.42},{"price":75.91,"size":1000.0},{"price":75.88,"size":50.0},{"price":75.79,"size":50.0},{"price":75.78,"size":1.4},{"price":75.72,"size":100.0},{"price":75.6,"size":500.0},{"price":75.52,"size":3000.0},{"price":75.5,"size":7500.0},{"price":75.3,"size":441.0},{"price":75.1,"size":50.0},{"price":75.01,"size":10.0},{"price":75.0,"size":17050.30333},{"price":74.74,"size":5000.0},{"price":74.54,"size":49.0},{"price":74.5,"size":3000.0},{"price":74.4,"size":5000.0},{"price":74.1,"size":50.0},{"price":74.0,"size":418.03},{"price":73.84,"size":30.0},{"price":73.5,"size":3000.0},{"price":73.39,"size":100.0},{"price":73.1,"size":785.0},{"price":73.0,"size":1778.4},{"price":72.9,"size":1.109},{"price":72.5,"size":3000.0},{"price":72.1,"size":50.0},{"price":72.0,"size":11526.78}],"asks":[{"price":96.08,"size":620.32},{"price":96.13,"size":49.479871},{"price":96.18,"size":10863.0},{"price":96.21,"size":339.420653},{"price":96.23,"size":5540.0},{"price":96.24,"size":9929.0},{"price":96.3,"size":1352.25},{"price":96.33,"size":13710.0},{"price":96.43,"size":139250.0},{"price":96.45,"size":27.65},{"price":96.5,"size":9000.0},{"price":96.6,"size":4000.0},{"price":96.7,"size":4070.0},{"price":96.8,"size":70.0},{"price":96.9,"size":70.0},{"price":96.99,"size":26630.0},{"price":97.0,"size":4451.0},{"price":97.1,"size":70.0},{"price":97.14,"size":5000.0},{"price":97.19,"size":8000.0},{"price":97.2,"size":1070.0},{"price":97.21,"size":5000.0},{"price":97.24,"size":5000.0},{"price":97.3,"size":70.0},{"price":97.34,"size":5000.0},{"price":97.4,"size":70.0},{"price":97.5,"size":1552.1},{"price":97.6,"size":70.0},{"price":97.7,"size":70.0},{"price":97.8,"size":70.0},{"price":97.9,"size":140.0},{"price":98.0,"size":2076.1},{"price":98.1,"size":70.0},{"price":98.2,"size":71.0},{"price":98.25,"size":4.0},{"price":98.3,"size":370.0},{"price":98.4,"size":70.0},{"price":98.48,"size":491.120224},{"price":98.5,"size":6077.1},{"price":98.55,"size":11000.0},{"price":98.7,"size":70.0},{"price":98.75,"size":4.0},{"price":98.8,"size":70.0},{"price":99.0,"size":8878.0},{"price":99.1,"size":70.0},{"price":99.13,"size":30.0},{"price":99.2,"size":70.0},{"price":99.24,"size":500.0},{"price":99.25,"size":4.0},{"price":99.3,"size":70.0},{"price":99.38,"size":14.104},{"price":99.4,"size":80.0},{"price":99.5,"size":4276.0},{"price":99.6,"size":70.0},{"price":99.7,"size":70.0},{"price":99.75,"size":4.0},{"price":99.8,"size":70.0},{"price":99.9,"size":70.0},{"price":99.99,"size":2994.0},{"price":100.0,"size":24347.2616},{"price":100.1,"size":70.0},{"price":100.2,"size":70.0},{"price":100.25,"size":4.0},{"price":100.3,"size":70.0},{"price":100.4,"size":70.0},{"price":100.5,"size":1311.0},{"price":100.6,"size":70.0},{"price":100.7,"size":70.0},{"price":100.75,"size":4.0},{"price":100.8,"size":70.0},{"price":100.9,"size":70.0},{"price":100.99,"size":499.0},{"price":101.0,"size":3108.0},{"price":101.1,"size":70.0},{"price":101.2,"size":70.0},{"price":101.25,"size":4.0},{"price":101.3,"size":70.0},{"price":101.4,"size":70.0},{"price":101.5,"size":77.0},{"price":101.6,"size":70.0},{"price":101.7,"size":70.0},{"price":101.75,"size":4.0},{"price":101.8,"size":70.0},{"price":101.89,"size":5000.0},{"price":101.9,"size":70.0},{"price":102.0,"size":5454.5},{"price":102.1,"size":70.0},{"price":102.2,"size":70.0},{"price":102.25,"size":4.0},{"price":102.3,"size":70.0},{"price":102.4,"size":70.0},{"price":102.5,"size":76.0},{"price":102.6,"size":70.0},{"price":102.7,"size":70.0},{"price":102.75,"size":4.0},{"price":102.8,"size":70.0},{"price":102.84,"size":194.472},{"price":102.9,"size":70.0},{"price":103.0,"size":100817.0},{"price":103.1,"size":70.0},{"price":103.2,"size":90.0},{"price":103.25,"size":4.0},{"price":103.28,"size":100.0},{"price":103.3,"size":660.7},{"price":103.4,"size":70.0},{"price":103.5,"size":106.0},{"price":103.6,"size":70.0},{"price":103.7,"size":100.0},{"price":103.75,"size":4.0},{"price":103.8,"size":70.0},{"price":103.9,"size":70.0},{"price":103.99,"size":499.0},{"price":104.0,"size":5010.0},{"price":104.09,"size":100.0},{"price":104.1,"size":100.0},{"price":104.13,"size":99.7},{"price":104.2,"size":400.0},{"price":104.25,"size":4.0},{"price":104.3,"size":100.0},{"price":104.4,"size":100.0},{"price":104.5,"size":9951.5},{"price":104.6,"size":800.0},{"price":104.61,"size":150.0},{"price":104.7,"size":100.0},{"price":104.75,"size":4.0},{"price":104.8,"size":99.8},{"price":104.9,"size":100.0},{"price":104.96,"size":1000.0},{"price":104.97,"size":1500.0},{"price":105.0,"size":28525.4381},{"price":105.02,"size":5652.0},{"price":105.1,"size":110.0},{"price":105.2,"size":100.0},{"price":105.25,"size":4.0},{"price":105.3,"size":100.0},{"price":105.31,"size":9.85},{"price":105.4,"size":100.0},{"price":105.46,"size":3795.0},{"price":105.5,"size":4700.7},{"price":105.55,"size":100.1},{"price":105.6,"size":100.0},{"price":105.7,"size":100.0},{"price":105.75,"size":4.0},{"price":105.78,"size":100.0},{"price":105.8,"size":2110.000001},{"price":105.98,"size":13000.0},{"price":105.99,"size":499.0},{"price":106.0,"size":12467.0},{"price":106.12,"size":9.8},{"price":106.25,"size":4.0},{"price":106.3,"size":11000.0},{"price":106.33,"size":49.2},{"price":106.5,"size":6.0},{"price":106.75,"size":4.0},{"price":107.0,"size":2167.0},{"price":107.25,"size":4.0},{"price":107.27,"size":100.0},{"price":107.5,"size":6.0},{"price":107.61,"size":21.3836},{"price":107.75,"size":4.0},{"price":108.0,"size":6991.67948},{"price":108.01,"size":6.491},{"price":108.2,"size":100.0},{"price":108.25,"size":4.0},{"price":108.5,"size":6.0},{"price":108.75,"size":4.0},{"price":108.96,"size":1389.050949},{"price":109.0,"size":3091.0},{"price":109.09,"size":1.0},{"price":109.1,"size":80.0},{"price":109.25,"size":4.0},{"price":109.5,"size":7.0},{"price":109.75,"size":4.0},{"price":109.9,"size":10.0},{"price":109.98,"size":29.0},{"price":110.0,"size":12253.7},{"price":110.11,"size":156.0},{"price":110.25,"size":4.0},{"price":110.5,"size":182.0},{"price":110.56,"size":218.95096},{"price":110.75,"size":4.0},{"price":110.99,"size":998.0},{"price":111.0,"size":3085.0},{"price":111.1,"size":5000.0},{"price":111.25,"size":4.0},{"price":111.5,"size":4.0},{"price":111.75,"size":4.0},{"price":112.0,"size":1720.892764},{"price":112.2,"size":49.2},{"price":112.25,"size":4.0},{"price":112.5,"size":1104.0},{"price":112.75,"size":4.0},{"price":112.8,"size":400.0},{"price":112.82,"size":49.2},{"price":112.9,"size":1000.0},{"price":113.0,"size":1774.0},{"price":113.25,"size":4.0},{"price":113.3,"size":699.0},{"price":113.5,"size":4.0},{"price":113.54,"size":17900.0},{"price":113.71,"size":49.2},{"price":113.75,"size":4.0},{"price":113.8,"size":100.0},{"price":114.0,"size":10698.410537},{"price":114.25,"size":4.0},{"price":114.4,"size":55.0},{"price":114.5,"size":104.0},{"price":114.75,"size":4.0},{"price":114.8,"size":1612.07},{"price":114.93,"size":49.2},{"price":115.0,"size":9176.5},{"price":115.05,"size":497.0009},{"price":115.1,"size":579.76036},{"price":115.15,"size":500.0},{"price":115.2,"size":3010.0},{"price":115.25,"size":504.0},{"price":115.3,"size":800.0},{"price":115.35,"size":500.0},{"price":115.4,"size":500.0},{"price":115.45,"size":500.0},{"price":115.5,"size":3404.0},{"price":115.6,"size":800.0},{"price":115.63,"size":49.2},{"price":115.7,"size":500.0},{"price":115.75,"size":4.0},{"price":115.78,"size":155.0},{"price":115.8,"size":500.0},{"price":115.87,"size":1000.0},{"price":115.9,"size":500.0},{"price":116.0,"size":3244.645},{"price":116.1,"size":500.0},{"price":116.11,"size":500.0},{"price":116.14,"size":500.0},{"price":116.15,"size":500.0},{"price":116.18,"size":500.0},{"price":116.2,"size":500.0},{"price":116.21,"size":500.0},{"price":116.24,"size":500.0},{"price":116.25,"size":504.0},{"price":116.28,"size":500.0},{"price":116.29,"size":500.0},{"price":116.3,"size":3827.0},{"price":116.31,"size":500.0},{"price":116.34,"size":500.0},{"price":116.35,"size":500.0},{"price":116.4,"size":500.0},{"price":116.44,"size":500.0},{"price":116.47,"size":1000.0},{"price":116.5,"size":606.0},{"price":116.54,"size":500.0},{"price":116.6,"size":500.0},{"price":116.64,"size":500.0},{"price":116.7,"size":501.0},{"price":116.74,"size":500.0},{"price":116.75,"size":4.0},{"price":116.8,"size":500.0},{"price":116.84,"size":500.0},{"price":116.88,"size":29.5},{"price":116.9,"size":500.0},{"price":116.94,"size":500.0},{"price":117.0,"size":2740.0},{"price":117.1,"size":500.0},{"price":117.2,"size":1505.0},{"price":117.25,"size":4.0},{"price":117.3,"size":34865.0},{"price":117.33,"size":29.5},{"price":117.4,"size":500.0},{"price":117.5,"size":966.0},{"price":117.6,"size":500.0},{"price":117.7,"size":545.0},{"price":117.75,"size":4.0},{"price":117.8,"size":500.0},{"price":117.9,"size":500.0},{"price":118.0,"size":4151.4},{"price":118.1,"size":500.0},{"price":118.12,"size":500.0},{"price":118.2,"size":500.0},{"price":118.22,"size":500.0},{"price":118.25,"size":4.0},{"price":118.3,"size":500.0},{"price":118.32,"size":500.0},{"price":118.4,"size":500.0},{"price":118.42,"size":500.0},{"price":118.5,"size":651.0},{"price":118.52,"size":500.0},{"price":118.6,"size":500.0},{"price":118.62,"size":500.0},{"price":118.7,"size":500.0},{"price":118.72,"size":750.0},{"price":118.75,"size":4.0},{"price":118.8,"size":500.0},{"price":118.82,"size":500.0},{"price":118.9,"size":820.0},{"price":118.92,"size":500.0},{"price":119.0,"size":11856.0},{"price":119.2,"size":2600.0},{"price":119.25,"size":4.0},{"price":119.48,"size":50.0},{"price":119.49,"size":654.5},{"price":119.5,"size":6.0}]}}}
1639350336.131001: {"jsonrpc":"2.0","method":"channelMessage","params":{"channel":"lightning_board_snapshot_MONA_JPY","message":{"mid_price":166.009,"bids":[{"price":83.5,"size":10.0},{"price":84.0,"size":10.0},{"price":84.1,"size":10.0},{"price":84.3,"size":10.0},{"price":84.5,"size":10.0},{"price":90.0,"size":100.0},{"price":93.572,"size":21.3836},{"price":94.4,"size":10.0},{"price":100.0,"size":733.94},{"price":101.0,"size":80.0},{"price":104.0,"size":60.0},{"price":105.0,"size":10.0},{"price":107.61,"size":18.5945},{"price":108.11,"size":10.0},{"price":110.0,"size":5.0},{"price":112.011,"size":30.0},{"price":120.0,"size":51.1},{"price":121.0,"size":150.0},{"price":123.75,"size":16.1691},{"price":125.0,"size":573.0},{"price":125.911,"size":30.0},{"price":126.27,"size":100.0},{"price":127.0,"size":150.0},{"price":128.0,"size":800.0},{"price":130.0,"size":1468.2},{"price":130.1,"size":5.0},{"price":131.0,"size":150.0},{"price":132.0,"size":321.0},{"price":135.0,"size":150.0},{"price":137.0,"size":350.0},{"price":139.0,"size":40.0},{"price":139.6,"size":10.0},{"price":139.811,"size":30.0},{"price":140.0,"size":2846.1},{"price":140.183,"size":28.535},{"price":141.1,"size":2510.0},{"price":141.4,"size":10.0},{"price":142.311,"size":14.0601},{"price":142.537,"size":140.0},{"price":145.0,"size":10.0},{"price":146.0,"size":20.0},{"price":146.1,"size":2000.0},{"price":147.0,"size":370.85714285},{"price":148.0,"size":769.0},{"price":149.0,"size":9.0},{"price":149.3,"size":50.0},{"price":149.36,"size":14.2},{"price":149.4,"size":24.18684765},{"price":149.8,"size":120.0},{"price":149.9,"size":50.0},{"price":150.0,"size":1582.63333},{"price":151.0,"size":258.1},{"price":151.1,"size":2000.0},{"price":152.0,"size":28.1},{"price":153.0,"size":458.1},{"price":153.65,"size":10.0},{"price":153.772,"size":2446.0},{"price":154.0,"size":8.1},{"price":154.524,"size":1.0014},{"price":155.0,"size":3925.10450676},{"price":155.06,"size":2489.0},{"price":155.2,"size":50.0},{"price":155.3,"size":4000.0},{"price":155.311,"size":69.51},{"price":156.0,"size":578.3},{"price":156.1,"size":1500.0},{"price":156.4,"size":10.0},{"price":157.0,"size":99.1},{"price":158.0,"size":221.1},{"price":158.375,"size":126.0},{"price":158.5,"size":30.0},{"price":158.628,"size":2472.0},{"price":158.879,"size":1000.0},{"price":159.0,"size":552.158},{"price":160.0,"size":5968.3525},{"price":160.039,"size":11.0},{"price":160.5,"size":10.0},{"price":160.545,"size":50.0},{"price":160.577,"size":4923.0},{"price":160.639,"size":30.0},{"price":161.0,"size":1460.2},{"price":161.1,"size":8461.71687854},{"price":161.2,"size":5.0},{"price":161.245,"size":2400.0},{"price":161.392,"size":9754.0},{"price":161.4,"size":5.0},{"price":161.6,"size":5.0},{"price":161.8,"size":683.0},{"price":162.0,"size":305.24691358},{"price":162.2,"size":5.0},{"price":162.207,"size":25175.0},{"price":162.4,"size":5.0},{"price":162.6,"size":5.0},{"price":162.8,"size":5.0},{"price":162.835,"size":2506.0},{"price":162.901,"size":964.0},{"price":163.0,"size":977.73337133},{"price":163.001,"size":10.0},{"price":163.14,"size":6.0},{"price":163.2,"size":5.0},{"price":163.4,"size":5.0},{"price":163.6,"size":5.0},{"price":163.8,"size":5.0},{"price":163.86,"size":1000.0},{"price":164.0,"size":399.5068536},{"price":164.02,"size":0.1},{"price":165.0,"size":206.93939393},{"price":165.002,"size":0.11515011},{"price":165.02,"size":500.0000002},{"price":165.021,"size":98.0}],"asks":[{"price":166.998,"size":0.80479767},{"price":166.999,"size":98.0},{"price":167.0,"size":161.0},{"price":167.5,"size":4.09152951},{"price":167.656,"size":566.0},{"price":167.784,"size":23.841},{"price":168.0,"size":311.5},{"price":168.179,"size":22.0},{"price":168.49,"size":83.3},{"price":168.839,"size":1000.0},{"price":169.0,"size":307.99},{"price":170.0,"size":315.0},{"price":170.2,"size":5.0},{"price":170.4,"size":5.0},{"price":170.6,"size":5.0},{"price":170.8,"size":5.0},{"price":170.999,"size":100.0},{"price":171.0,"size":415.0},{"price":171.2,"size":5.0},{"price":171.4,"size":5.0},{"price":171.6,"size":5.0},{"price":171.8,"size":5.0},{"price":171.999,"size":53.9},{"price":172.0,"size":515.0},{"price":172.2,"size":5.0},{"price":172.4,"size":5.0},{"price":172.6,"size":5.0},{"price":172.8,"size":5.0},{"price":173.0,"size":446.92},{"price":173.2,"size":5.0},{"price":173.4,"size":5.0},{"price":173.6,"size":5.0},{"price":173.8,"size":5.0},{"price":173.82,"size":1000.0},{"price":173.997,"size":7589.25902325},{"price":174.0,"size":1562.23062369},{"price":174.1,"size":199.7},{"price":174.2,"size":5.0},{"price":174.4,"size":5.0},{"price":174.6,"size":5.0},{"price":174.8,"size":5.0},{"price":174.9,"size":99.74},{"price":174.99,"size":730.0},{"price":175.0,"size":617.0},{"price":175.2,"size":5.0},{"price":175.4,"size":5.0},{"price":175.584,"size":4.9},{"price":175.6,"size":5.0},{"price":175.8,"size":5.0},{"price":176.0,"size":2532.5},{"price":176.2,"size":5.0},{"price":176.4,"size":5.0},{"price":176.6,"size":5.0},{"price":176.607,"size":4.9},{"price":176.8,"size":5.0},{"price":177.0,"size":365.0},{"price":177.2,"size":5.0},{"price":177.4,"size":5.0},{"price":177.6,"size":5.0},{"price":177.8,"size":5.0},{"price":178.0,"size":126.5},{"price":178.2,"size":5.0},{"price":178.4,"size":5.0},{"price":178.5,"size":2.238},{"price":178.6,"size":5.0},{"price":178.8,"size":5.0},{"price":179.0,"size":465.0},{"price":179.2,"size":5.0},{"price":179.4,"size":5.0},{"price":179.6,"size":5.0},{"price":179.7,"size":124.2},{"price":179.8,"size":5.0},{"price":180.0,"size":21159.143985},{"price":180.2,"size":5.0},{"price":180.4,"size":5.0},{"price":180.6,"size":5.0},{"price":180.8,"size":5.0},{"price":181.0,"size":165.0},{"price":181.2,"size":5.0},{"price":181.4,"size":5.0},{"price":181.6,"size":5.0},{"price":181.8,"size":5.0},{"price":182.0,"size":65.0},{"price":182.2,"size":5.0},{"price":182.4,"size":5.0},{"price":182.6,"size":5.0},{"price":182.8,"size":5.0},{"price":183.0,"size":365.0},{"price":183.2,"size":5.0},{"price":183.4,"size":5.0},{"price":183.6,"size":5.0},{"price":183.8,"size":5.0},{"price":184.0,"size":65.0},{"price":184.2,"size":5.0},{"price":184.4,"size":5.0},{"price":184.6,"size":5.0},{"price":184.8,"size":5.0},{"price":185.0,"size":1624.85618696},{"price":185.01,"size":5.87639265},{"price":185.2,"size":5.0},{"price":185.4,"size":5.0},{"price":185.6,"size":5.0},{"price":185.8,"size":5.0},{"price":186.0,"size":306.5},{"price":186.8,"size":5.0},{"price":187.0,"size":415.0},{"price":187.2,"size":5.0},{"price":187.4,"size":5.0},{"price":187.425,"size":1.0},{"price":187.6,"size":5.0},{"price":187.8,"size":5.0},{"price":188.0,"size":315.0},{"price":188.2,"size":5.0},{"price":188.211,"size":12.2262},{"price":188.4,"size":5.0},{"price":188.6,"size":5.0},{"price":188.8,"size":5.0},{"price":188.999,"size":50.0},{"price":189.0,"size":3582.0},{"price":189.2,"size":5.0},{"price":189.4,"size":5.0},{"price":189.6,"size":5.0},{"price":189.8,"size":5.0},{"price":189.999,"size":50.0},{"price":190.0,"size":674.96230901},{"price":190.2,"size":5.0},{"price":190.4,"size":5.0},{"price":190.6,"size":5.0},{"price":190.8,"size":5.0},{"price":190.999,"size":19.0},{"price":191.0,"size":415.0},{"price":191.113,"size":9.99},{"price":191.2,"size":5.0},{"price":191.4,"size":5.0},{"price":191.6,"size":5.0},{"price":191.8,"size":5.0},{"price":191.999,"size":50.0},{"price":192.0,"size":815.0},{"price":192.2,"size":5.0},{"price":192.4,"size":5.0},{"price":192.6,"size":5.0},{"price":192.747,"size":20.0},{"price":192.8,"size":5.0},{"price":192.999,"size":50.0},{"price":193.0,"size":465.75789053},{"price":193.2,"size":5.0},{"price":193.4,"size":5.0},{"price":193.6,"size":5.0},{"price":193.8,"size":5.0},{"price":193.999,"size":50.0},{"price":194.0,"size":325.5},{"price":194.2,"size":5.0},{"price":194.4,"size":5.0},{"price":194.6,"size":5.0},{"price":194.8,"size":5.0},{"price":194.999,"size":50.0},{"price":195.0,"size":1386.2},{"price":195.2,"size":5.0},{"price":195.4,"size":5.0},{"price":195.6,"size":5.0},{"price":195.8,"size":5.0},{"price":195.999,"size":50.0},{"price":196.0,"size":315.0},{"price":196.2,"size":5.0},{"price":196.4,"size":5.0},{"price":196.6,"size":5.0},{"price":196.8,"size":6.01474},{"price":196.999,"size":50.0},{"price":197.0,"size":1934.64296797},{"price":197.2,"size":5.0},{"price":197.4,"size":5.0},{"price":197.6,"size":5.0},{"price":197.8,"size":5.0},{"price":198.0,"size":516.6},{"price":199.0,"size":2042.88},{"price":199.2,"size":5.0},{"price":199.4,"size":5.0},{"price":199.5,"size":497.0},{"price":199.6,"size":5.0},{"price":199.8,"size":5.0},{"price":200.0,"size":1667.42438504},{"price":200.109,"size":4.9},{"price":200.2,"size":5.0},{"price":200.4,"size":5.0},{"price":200.8,"size":5.0},{"price":200.897,"size":50.0},{"price":201.0,"size":280.2},{"price":201.2,"size":5.0},{"price":201.4,"size":5.0},{"price":201.6,"size":5.0},{"price":201.8,"size":5.0},{"price":202.0,"size":325.2},{"price":202.2,"size":5.0},{"price":202.4,"size":5.0},{"price":202.6,"size":5.0},{"price":202.8,"size":5.0},{"price":203.0,"size":115.2},{"price":203.2,"size":5.0},{"price":203.6,"size":20.0},{"price":203.66,"size":270.0},{"price":204.0,"size":359.50071915},{"price":204.8,"size":8156.68824317},{"price":205.0,"size":33869.616},{"price":205.275,"size":200.0},{"price":206.0,"size":348.5607011},{"price":206.8,"size":10.0},{"price":207.0,"size":130.91515376},{"price":208.0,"size":329.2},{"price":209.0,"size":169.2},{"price":209.811,"size":26.5101},{"price":210.0,"size":5122.1978011},{"price":210.03,"size":994.0},{"price":211.0,"size":2270.42259506},{"price":211.167,"size":226.0},{"price":211.7,"size":10.0},{"price":212.0,"size":570.2},{"price":212.134,"size":0.985},{"price":213.0,"size":207.52986169},{"price":214.0,"size":3288.55795542},{"price":214.8,"size":1000.0},{"price":215.0,"size":1753.04052022},{"price":215.1,"size":299.28079113},{"price":216.0,"size":2265.1},{"price":216.3,"size":50.0},{"price":216.444,"size":10.6314},{"price":216.972,"size":1.0},{"price":216.998,"size":100.0},{"price":217.0,"size":1983.1},{"price":217.5,"size":5.0},{"price":218.0,"size":461.6},{"price":218.4,"size":5.0},{"price":219.0,"size":360.1},{"price":220.0,"size":9229.57604492},{"price":221.0,"size":33.1},{"price":222.0,"size":514.82664685},{"price":222.2,"size":45.0},{"price":222.222,"size":150.0},{"price":222.5,"size":5.0},{"price":223.0,"size":735.77279265},{"price":224.0,"size":135.1},{"price":224.01,"size":500.0},{"price":225.0,"size":3214.4},{"price":225.009,"size":300.0},{"price":225.17,"size":50.0},{"price":226.0,"size":114.1},{"price":226.8,"size":15.0},{"price":227.0,"size":50.1},{"price":227.5,"size":5.0},{"price":228.0,"size":43.1},{"price":229.0,"size":50.1},{"price":229.8,"size":10.0},{"price":230.0,"size":1975.239331},{"price":230.1,"size":110.0},{"price":231.86,"size":2.26},{"price":235.0,"size":317.0},{"price":235.4,"size":43.35581731},{"price":237.0,"size":6.0},{"price":239.0,"size":2998.0},{"price":239.899,"size":15.0},{"price":240.0,"size":999.4},{"price":240.1,"size":290.0},{"price":245.0,"size":605.0},{"price":245.009,"size":300.0},{"price":248.0,"size":219.0},{"price":248.911,"size":9.2447},{"price":250.0,"size":4097.79714313},{"price":253.0,"size":5.0},{"price":255.0,"size":205.0},{"price":257.0,"size":50.0},{"price":260.0,"size":220.5},{"price":264.0,"size":200.0},{"price":265.0,"size":5.0},{"price":268.0,"size":100.0},{"price":270.0,"size":573.56},{"price":273.0,"size":199.5},{"price":275.0,"size":27.0},{"price":279.0,"size":200.0},{"price":280.0,"size":1310.8},{"price":285.0,"size":5.0},{"price":286.25,"size":8.0389},{"price":289.91,"size":1.59648246},{"price":290.0,"size":110.7},{"price":292.0,"size":42.5},{"price":295.0,"size":10.1},{"price":298.0,"size":200.0},{"price":299.0,"size":200.0},{"price":300.0,"size":1637.62059002},{"price":301.0,"size":58.22738048},{"price":302.0,"size":30.0},{"price":305.0,"size":5.1},{"price":310.0,"size":1105.9},{"price":312.0,"size":6.0},{"price":315.0,"size":22.0},{"price":317.0,"size":5.0},{"price":320.0,"size":110.1},{"price":321.0,"size":100.0},{"price":325.0,"size":5.0},{"price":329.19,"size":6.9903},{"price":330.0,"size":604.0},{"price":332.0,"size":190.0},{"price":335.0,"size":5.0},{"price":338.0,"size":32.68899798},{"price":340.0,"size":58.5},{"price":341.0,"size":34.69794721},{"price":342.0,"size":1000.0},{"price":350.0,"size":1631.8225},{"price":360.0,"size":0.2},{"price":370.0,"size":20.0},{"price":380.0,"size":358.2},{"price":397.0,"size":1841.88271694},{"price":400.0,"size":103.81018981},{"price":435.0,"size":336.55349638}]}}}
1639350336.141411: {"jsonrpc":"2.0","method":"channelMessage","params":{"channel":"lightning_board_FX_BTC_JPY","message":{"mid_price":5863314.0,"bids":[{"price":5855830.0,"size":0.0},{"price":5862041.0,"size":0.39},{"price":5858294.0,"size":0.01},{"price":5861452.0,"size":0.02}],"asks":[{"price":5865903.0,"size":0.0},{"price":5887515.0,"size":0.0},{"price":5866796.0,"size":0.0},{"price":5870421.0,"size":0.5},{"price":5864000.0,"size":0.17675395}]}}}
1639350336.1415942: {"jsonrpc":"2.0","method":"channelMessage","params":{"channel":"lightning_board_BTC_USD","message":{"mid_price":50268.27,"bids":[],"asks":[{"price":51011.75,"size":0.41},{"price":51092.21,"size":0.54}]}}}
1639350336.154336: {"jsonrpc":"2.0","method":"channelMessage","params":{"channel":"lightning_board_snapshot_XLM_JPY","message":{"mid_price":31.52,"bids":[{"price":31.484,"size":3739.0},{"price":31.478,"size":2554.08},{"price":31.477,"size":3819.0},{"price":31.468,"size":3736.0},{"price":31.456,"size":11880.0},{"price":31.452,"size":3866.0},{"price":31.428,"size":8000.0},{"price":31.421,"size":967.9},{"price":31.406,"size":29746.0},{"price":31.4,"size":5.095541},{"price":31.39,"size":905.6},{"price":31.337,"size":8000.0},{"price":31.309,"size":295826.89},{"price":31.3,"size":5.111821},{"price":31.256,"size":749.85},{"price":31.2,"size":5.128205},{"price":31.123,"size":192.79},{"price":31.117,"size":90.7},{"price":31.1,"size":5.144694},{"price":31.098,"size":120.9},{"price":31.068,"size":123727.0},{"price":31.045,"size":10.0},{"price":31.02,"size":59219.0},{"price":31.0,"size":31497.5846143},{"price":30.973,"size":108.5},{"price":30.9,"size":30.0},{"price":30.841,"size":107.1},{"price":30.8,"size":4040.0},{"price":30.776,"size":29819.0},{"price":30.7,"size":20.0},{"price":30.623,"size":113.2},{"price":30.622,"size":30308.0},{"price":30.61,"size":300.0},{"price":30.6,"size":40.0},{"price":30.526,"size":113.4},{"price":30.502,"size":116.3},{"price":30.5,"size":20610.425295},{"price":30.4,"size":40.0},{"price":30.395,"size":197.41},{"price":30.3,"size":20.0},{"price":30.297,"size":115.8},{"price":30.266,"size":0.7},{"price":30.2,"size":65.99337},{"price":30.145,"size":31034.0},{"price":30.1,"size":20.0},{"price":30.096,"size":0.7},{"price":30.015,"size":200.0},{"price":30.01,"size":2002.0},{"price":30.0,"size":3179.5263666},{"price":29.911,"size":1.0},{"price":29.9,"size":5020.0},{"price":29.888,"size":1000.0},{"price":29.8,"size":11030.0},{"price":29.79,"size":14358.2410204},{"price":29.74,"size":300.0},{"price":29.7,"size":41.838},{"price":29.6,"size":30.0},{"price":29.548,"size":200.0},{"price":29.5,"size":31075.6279661},{"price":29.4,"size":21.9588},{"price":29.301,"size":10.0},{"price":29.3,"size":7027.04},{"price":29.215,"size":100.0},{"price":29.2,"size":10.0},{"price":29.11,"size":8.0},{"price":29.1,"size":5958.5082168},{"price":29.038,"size":206.63},{"price":29.03,"size":550.0},{"price":29.01,"size":2000.0},{"price":29.008,"size":1.1095801},{"price":29.0,"size":21688.199987},{"price":28.999,"size":0.73},{"price":28.98,"size":30.0},{"price":28.9,"size":10.0},{"price":28.896,"size":10.0},{"price":28.895,"size":2000.0},{"price":28.888,"size":1100.0},{"price":28.88,"size":150.0},{"price":28.8,"size":5032.208},{"price":28.75,"size":2000.0},{"price":28.7,"size":2310.0},{"price":28.66,"size":150.0},{"price":28.624,"size":69.903},{"price":28.61,"size":7790.0},{"price":28.6,"size":16220.0},{"price":28.55,"size":5000.0},{"price":28.506,"size":29000.0},{"price":28.5,"size":15764.3365},{"price":28.484,"size":2000.0},{"price":28.48,"size":1000.0},{"price":28.4,"size":10.0},{"price":28.342,"size":211.7},{"price":28.33,"size":150.0},{"price":28.3,"size":7127.0},{"price":28.22,"size":260.0},{"price":28.2,"size":5032.4677},{"price":28.167,"size":2000.0},{"price":28.14,"size":0.355366},{"price":28.111,"size":401.0},{"price":28.1,"size":20110.0},{"price":28.031,"size":0.76},{"price":28.017,"size":0.76},{"price":28.01,"size":2000.0},{"price":28.0,"size":95929.3687536},{"price":27.949,"size":200.0},{"price":27.9,"size":112.6018},{"price":27.895,"size":2000.0},{"price":27.888,"size":1100.0},{"price":27.88,"size":508.68},{"price":27.8,"size":10.0},{"price":27.743,"size":2000.0},{"price":27.734,"size":120.0},{"price":27.66,"size":150.0},{"price":27.64,"size":40.0},{"price":27.6,"size":322.7388},{"price":27.5,"size":10657.0},{"price":27.407,"size":500.0},{"price":27.4,"size":1812.0},{"price":27.33,"size":150.0},{"price":27.3,"size":5092.8788},{"price":27.272,"size":1.098},{"price":27.2,"size":10.0},{"price":27.167,"size":2000.0},{"price":27.111,"size":300.0},{"price":27.11,"size":1000.0},{"price":27.1,"size":39854.2804428},{"price":27.01,"size":2000.0},{"price":27.0,"size":53444.0469},{"price":26.905,"size":400.0},{"price":26.9,"size":900.0},{"price":26.895,"size":2000.0},{"price":26.888,"size":100.0},{"price":26.88,"size":150.0},{"price":26.831,"size":1000.0},{"price":26.8,"size":1500.0},{"price":26.752,"size":50.0},{"price":26.7,"size":1646.1682},{"price":26.666,"size":10000.0},{"price":26.66,"size":150.0},{"price":26.6,"size":100.0},{"price":26.588,"size":3000.0},{"price":26.568,"size":100.0},{"price":26.5,"size":64982.490566},{"price":26.494,"size":177.2597},{"price":26.42,"size":800.0},{"price":26.4,"size":403.3178},{"price":26.33,"size":150.0},{"price":26.31,"size":100.0},{"price":26.3,"size":3100.0},{"price":26.262,"size":750.0},{"price":26.167,"size":1000.0},{"price":26.111,"size":300.0},{"price":26.11,"size":1000.0},{"price":26.1,"size":20013.4709},{"price":26.062,"size":76.74},{"price":26.0,"size":54460.2769229},{"price":25.9,"size":100.0},{"price":25.88,"size":300.0},{"price":25.841,"size":773.0},{"price":25.8,"size":463.6275},{"price":25.776,"size":0.83},{"price":25.678,"size":7.0},{"price":25.66,"size":150.0},{"price":25.6,"size":100.0},{"price":25.588,"size":2000.0},{"price":25.56,"size":400.0},{"price":25.555,"size":391.0},{"price":25.506,"size":1000.0},{"price":25.5,"size":6423.8878},{"price":25.4,"size":5000.0},{"price":25.33,"size":150.0},{"price":25.3,"size":5200.0},{"price":25.26,"size":1500.0},{"price":25.25,"size":40.0},{"price":25.222,"size":410.0},{"price":25.2,"size":13.952},{"price":25.19,"size":25.0},{"price":25.111,"size":300.0},{"price":25.11,"size":2000.0},{"price":25.1,"size":20100.0},{"price":25.08,"size":400.0},{"price":25.011,"size":2000.0},{"price":25.01,"size":3433.0},{"price":25.0,"size":128164.3},{"price":24.9,"size":214.1201},{"price":24.891,"size":80.389},{"price":24.8,"size":2500.0},{"price":24.793,"size":1.208},{"price":24.745,"size":2000.0},{"price":24.743,"size":2000.0},{"price":24.667,"size":30.0},{"price":24.666,"size":10150.0},{"price":24.6,"size":14.2923},{"price":24.5,"size":22820.0},{"price":24.456,"size":50.0},{"price":24.3,"size":19119.4687},{"price":24.1,"size":1411.5},{"price":24.0,"size":77501.0},{"price":23.814,"size":2000.0},{"price":23.666,"size":10000.0},{"price":23.6,"size":4300.0},{"price":23.5,"size":3020.0},{"price":23.45,"size":100.0},{"price":23.4,"size":522.0},{"price":23.3,"size":3000.0},{"price":23.257,"size":859.0},{"price":23.25,"size":5000.0},{"price":23.2,"size":100.0},{"price":23.02,"size":3000.0},{"price":23.0,"size":66449.0},{"price":22.666,"size":10000.0},{"price":22.5,"size":8020.0},{"price":22.3,"size":3000.0},{"price":22.05,"size":5000.0},{"price":22.0,"size":3640.090909},{"price":21.828,"size":300.0},{"price":21.655,"size":500.0},{"price":21.644,"size":92.447},{"price":21.57,"size":5000.0},{"price":21.5,"size":70.0},{"price":21.49,"size":301.0},{"price":21.3,"size":3000.0},{"price":21.0,"size":7870.0},{"price":20.98,"size":3000.0},{"price":20.568,"size":200.0},{"price":20.5,"size":20.0},{"price":20.44,"size":0.1},{"price":20.3,"size":3000.0},{"price":20.0,"size":30616.1},{"price":19.895,"size":55.0},{"price":19.57,"size":5000.0},{"price":19.0,"size":1711.0},{"price":18.5,"size":20.0},{"price":18.3,"size":6000.0},{"price":18.0,"size":10240.0},{"price":17.58,"size":5000.0},{"price":17.1,"size":1000.0},{"price":17.0,"size":5010.0},{"price":16.8,"size":30.0},{"price":16.0,"size":1110.0},{"price":15.0,"size":200.0}],"asks":[{"price":31.556,"size":150.24},{"price":31.557,"size":978.2},{"price":31.572,"size":3938.0},{"price":31.579,"size":975.2},{"price":31.583,"size":3783.0},{"price":31.592,"size":11880.0},{"price":31.594,"size":3736.0},{"price":31.615,"size":8000.0},{"price":31.623,"size":607.9},{"price":31.628,"size":29746.0},{"price":31.715,"size":8000.0},{"price":31.728,"size":717.1},{"price":31.73,"size":303740.0},{"price":31.746,"size":119.01},{"price":31.85,"size":137.0},{"price":31.886,"size":92.83},{"price":31.9,"size":30000.0},{"price":31.916,"size":119.43},{"price":31.918,"size":73495.0},{"price":31.947,"size":187.82},{"price":31.948,"size":31.3011112},{"price":31.95,"size":20000.0},{"price":32.0,"size":1397.0},{"price":32.036,"size":122.0},{"price":32.1,"size":5.140187},{"price":32.125,"size":8.0},{"price":32.193,"size":118.9},{"price":32.2,"size":5.124224},{"price":32.215,"size":98.5},{"price":32.25,"size":20008.0},{"price":32.282,"size":619.538},{"price":32.3,"size":4005.10836},{"price":32.375,"size":8.0},{"price":32.4,"size":379.092593},{"price":32.414,"size":100.0},{"price":32.47,"size":200.0},{"price":32.5,"size":1323.9384624},{"price":32.571,"size":118.53},{"price":32.6,"size":304.04908},{"price":32.625,"size":8.0},{"price":32.7,"size":4.036698},{"price":32.71,"size":12488.0},{"price":32.75,"size":8.0},{"price":32.8,"size":4.024391},{"price":32.822,"size":100.0},{"price":32.875,"size":8.0},{"price":32.9,"size":4.012159},{"price":32.98,"size":149.61},{"price":33.0,"size":9178.468362},{"price":33.015,"size":5000.0},{"price":33.1,"size":14.108762},{"price":33.125,"size":8.0},{"price":33.2,"size":2304.096386},{"price":33.25,"size":8.0},{"price":33.253,"size":150.0},{"price":33.3,"size":6104.084085},{"price":33.33,"size":3994.0},{"price":33.37,"size":10000.0},{"price":33.375,"size":8.0},{"price":33.4,"size":4.071857},{"price":33.5,"size":1811.059702},{"price":33.545,"size":29.8105828},{"price":33.6,"size":4.04762},{"price":33.625,"size":8.0},{"price":33.7,"size":4.035609},{"price":33.75,"size":8.0},{"price":33.79,"size":0.2071618},{"price":33.8,"size":4.023669},{"price":33.875,"size":8.0},{"price":33.9,"size":13204.0118},{"price":33.968,"size":98.5},{"price":34.0,"size":3772.5},{"price":34.1,"size":1.026393},{"price":34.125,"size":8.0},{"price":34.2,"size":1.023392},{"price":34.25,"size":8.0},{"price":34.26,"size":400.0},{"price":34.3,"size":1.020409},{"price":34.375,"size":8.0},{"price":34.4,"size":74696.017442},{"price":34.5,"size":24697.014493},{"price":34.6,"size":1.011561},{"price":34.625,"size":8.0},{"price":34.7,"size":1.008646},{"price":34.75,"size":8.0},{"price":34.8,"size":1.005748},{"price":34.807,"size":100.0},{"price":34.875,"size":8.0},{"price":34.88,"size":49.87},{"price":34.9,"size":17983.002866},{"price":35.0,"size":54349.1174446},{"price":35.026,"size":242.9005511},{"price":35.094,"size":1555.0},{"price":35.1,"size":1.025642},{"price":35.111,"size":1000.0},{"price":35.125,"size":8.0},{"price":35.18,"size":6.283},{"price":35.2,"size":16.022728},{"price":35.222,"size":28.3910313},{"price":35.25,"size":8.0},{"price":35.3,"size":1.019831},{"price":35.312,"size":3271.4},{"price":35.333,"size":1000.0},{"price":35.375,"size":8.0},{"price":35.4,"size":1.01695},{"price":35.5,"size":15329.014085},{"price":35.53,"size":149.64},{"price":35.6,"size":1.011236},{"price":35.625,"size":8.0},{"price":35.7,"size":1.008404},{"price":35.75,"size":8.0},{"price":35.8,"size":1.005587},{"price":35.821,"size":9982.0},{"price":35.875,"size":8.0},{"price":35.888,"size":992.0},{"price":35.9,"size":501.002786},{"price":36.0,"size":18856.5},{"price":36.01,"size":126570.0},{"price":36.125,"size":8.0},{"price":36.2,"size":1000.0},{"price":36.25,"size":8.0},{"price":36.3,"size":1.096},{"price":36.375,"size":8.0},{"price":36.5,"size":1878.0},{"price":36.59,"size":190.0},{"price":36.625,"size":8.0},{"price":36.711,"size":284.58},{"price":36.75,"size":8.0},{"price":36.875,"size":8.0},{"price":36.92,"size":500.0},{"price":36.984,"size":27.0390774},{"price":37.0,"size":2479.4897541},{"price":37.1,"size":9950.0},{"price":37.125,"size":8.0},{"price":37.2,"size":49.0},{"price":37.25,"size":8.0},{"price":37.301,"size":9.85},{"price":37.314,"size":75.0296917},{"price":37.375,"size":8.0},{"price":37.388,"size":98.5},{"price":37.4,"size":12000.0},{"price":37.5,"size":11899.0},{"price":37.6,"size":4000.0},{"price":37.625,"size":8.0},{"price":37.75,"size":8.0},{"price":37.8,"size":1000.0},{"price":37.856,"size":60.786},{"price":37.875,"size":8.0},{"price":38.0,"size":5060.560063},{"price":38.1,"size":8223.7864549},{"price":38.125,"size":8.0},{"price":38.2,"size":8223.7864549},{"price":38.25,"size":8.0},{"price":38.28,"size":1244.0},{"price":38.3,"size":8223.7864549},{"price":38.375,"size":8.0},{"price":38.4,"size":17756.31544},{"price":38.41,"size":5.0},{"price":38.5,"size":29713.7864549},{"price":38.6,"size":8223.7864549},{"price":38.625,"size":8.0},{"price":38.7,"size":8223.7864549},{"price":38.75,"size":8.0},{"price":38.8,"size":12884.9279845},{"price":38.833,"size":25.7515022},{"price":38.875,"size":8.0},{"price":38.9,"size":8223.7864549},{"price":39.0,"size":35349.0023061},{"price":39.05,"size":1076.76},{"price":39.1,"size":8223.7864549},{"price":39.12,"size":500.0},{"price":39.125,"size":8.0},{"price":39.14,"size":500.0},{"price":39.17,"size":500.0},{"price":39.2,"size":8223.7864549},{"price":39.22,"size":500.0},{"price":39.24,"size":500.0},{"price":39.25,"size":8.0},{"price":39.27,"size":500.0},{"price":39.3,"size":7762.1354514},{"price":39.32,"size":500.0},{"price":39.34,"size":500.0},{"price":39.37,"size":500.0},{"price":39.375,"size":8.0},{"price":39.41,"size":5.0},{"price":39.42,"size":500.0},{"price":39.44,"size":500.0},{"price":39.45,"size":100.0},{"price":39.47,"size":500.0},{"price":39.49,"size":300.0},{"price":39.5,"size":13910.0},{"price":39.52,"size":500.0},{"price":39.53,"size":500.0},{"price":39.54,"size":500.0},{"price":39.55,"size":500.0},{"price":39.555,"size":779.6061182},{"price":39.57,"size":500.0},{"price":39.6,"size":500.0},{"price":39.62,"size":500.0},{"price":39.625,"size":8.0},{"price":39.63,"size":500.0},{"price":39.64,"size":500.0},{"price":39.65,"size":500.0},{"price":39.666,"size":500.0},{"price":39.67,"size":500.0},{"price":39.7,"size":600.0},{"price":39.72,"size":500.0},{"price":39.73,"size":500.0},{"price":39.74,"size":500.0},{"price":39.75,"size":508.0},{"price":39.77,"size":500.0},{"price":39.777,"size":500.0},{"price":39.8,"size":9901.628345},{"price":39.82,"size":500.0},{"price":39.83,"size":500.0},{"price":39.84,"size":500.0},{"price":39.85,"size":500.0},{"price":39.87,"size":500.0},{"price":39.875,"size":8.0},{"price":39.888,"size":500.0},{"price":39.9,"size":500.0},{"price":39.92,"size":500.0},{"price":39.93,"size":501.0},{"price":39.94,"size":500.0},{"price":39.95,"size":500.0},{"price":39.97,"size":500.0},{"price":39.989,"size":1995.0},{"price":39.996,"size":1990.0},{"price":39.999,"size":500.0},{"price":40.0,"size":86596.9346262},{"price":40.039,"size":100.0},{"price":40.05,"size":500.0},{"price":40.1,"size":510.0},{"price":40.125,"size":8.0},{"price":40.15,"size":500.0},{"price":40.2,"size":600.0},{"price":40.25,"size":508.0},{"price":40.253,"size":0.947035},{"price":40.3,"size":500.0},{"price":40.32,"size":35.0},{"price":40.35,"size":500.0},{"price":40.375,"size":8.0},{"price":40.4,"size":500.0},{"price":40.45,"size":500.0},{"price":40.5,"size":1908.0},{"price":40.55,"size":500.0},{"price":40.6,"size":500.0},{"price":40.625,"size":8.0},{"price":40.65,"size":500.0},{"price":40.7,"size":10500.0},{"price":40.72,"size":4696.5529785},{"price":40.75,"size":508.0},{"price":40.774,"size":24.5252402},{"price":40.8,"size":500.0},{"price":40.83,"size":98.5},{"price":40.85,"size":500.0},{"price":40.875,"size":8.0},{"price":40.9,"size":500.0},{"price":40.95,"size":500.0},{"price":41.0,"size":4642.2},{"price":41.1,"size":1036.935},{"price":41.125,"size":8.0},{"price":41.15,"size":50300.0},{"price":41.2,"size":151.019418},{"price":41.25,"size":8.0},{"price":41.3,"size":1.01695},{"price":41.375,"size":8.0},{"price":41.4,"size":20001.014493},{"price":41.5,"size":42091.832049},{"price":41.6,"size":21.009616},{"price":41.622,"size":22000.0},{"price":41.625,"size":8.0},{"price":41.666,"size":2000.0},{"price":41.7,"size":1.007195},{"price":41.75,"size":8.0},{"price":41.79,"size":15.0},{"price":41.8,"size":1.004785},{"price":41.833,"size":200.0},{"price":41.875,"size":8.0},{"price":41.88,"size":1398.0},{"price":41.9,"size":1.002387},{"price":42.0,"size":15853.5},{"price":42.1,"size":1.021378},{"price":42.125,"size":8.0},{"price":42.18,"size":300.0},{"price":42.2,"size":101.018958},{"price":42.25,"size":8.0},{"price":42.3,"size":1.016549},{"price":42.31,"size":40.0},{"price":42.375,"size":8.0},{"price":42.4,"size":1.014151},{"price":42.485,"size":100.0},{"price":42.5,"size":5646.011765},{"price":42.6,"size":101.00939},{"price":42.625,"size":8.0},{"price":42.666,"size":2000.0},{"price":42.7,"size":1.007026},{"price":42.75,"size":8.0},{"price":42.8,"size":1001.004673},{"price":42.813,"size":23.3573716}]}}}
1639350336.160007: {"jsonrpc":"2.0","method":"channelMessage","params":{"channel":"lightning_ticker_BTC_EUR","message":{"product_code":"BTC_EUR","state":"RUNNING","timestamp":"2021-12-12T23:05:35.9421098Z","tick_id":7240211,"best_bid":44461.19,"best_ask":44471.91,"best_bid_size":0.00118145,"best_ask_size":0.50134,"total_bid_depth":14.75728901,"total_ask_depth":13.17812467,"market_bid_size":0.0,"market_ask_size":0.0,"ltp":44461.2,"volume":43.951523900000,"volume_by_product":43.951523900000}}}
1639350336.160084: {"jsonrpc":"2.0","method":"channelMessage","params":{"channel":"lightning_executions_FX_BTC_JPY","message":[{"id":2284079831,"side":"BUY","price":5864000.0,"size":0.04,"exec_date":"2021-12-12T23:05:35.935753Z","buy_child_order_acceptance_id":"JRF20211212-230535-205572","sell_child_order_acceptance_id":"JRF20211212-230532-084217"},{"id":2284079832,"side":"BUY","price":5864000.0,"size":0.01,"exec_date":"2021-12-12T23:05:35.935753Z","buy_child_order_acceptance_id":"JRF20211212-230535-219045","sell_child_order_acceptance_id":"JRF20211212-230532-084217"},{"id":2284079833,"side":"BUY","price":5864000.0,"size":0.12675395,"exec_date":"2021-12-12T23:05:35.9525747Z","buy_child_order_acceptance_id":"JRF20211212-230535-200318","sell_child_order_acceptance_id":"JRF20211212-230532-084217"}]}}
1639350336.169302: {"jsonrpc":"2.0","method":"channelMessage","params":{"channel":"lightning_board_BTC_EUR","message":{"mid_price":44466.55,"bids":[],"asks":[{"price":44597.89,"size":0.13},{"price":44676.17,"size":0.0}]}}}
1639350336.1735868: {"jsonrpc":"2.0","method":"channelMessage","params":{"channel":"lightning_ticker_ETH_JPY","message":{"product_code":"ETH_JPY","state":"RUNNING","timestamp":"2021-12-12T23:05:35.9759249Z","tick_id":26934510,"best_bid":471614.0,"best_ask":471800.0,"best_bid_size":0.63,"best_ask_size":0.02,"total_bid_depth":3295.061367900000,"total_ask_depth":4465.62257320,"market_bid_size":0.0,"market_ask_size":0.0,"ltp":471501.000000,"volume":10833.500505500000,"volume_by_product":10833.500505500000}}}
1639350336.1803808: {"jsonrpc":"2.0","method":"channelMessage","params":{"channel":"lightning_board_ETH_JPY","message":{"mid_price":471707.0,"bids":[{"price":471033.0,"size":0.0},{"price":471614.0,"size":0.63},{"price":471171.0,"size":0.75}],"asks":[{"price":473843.0,"size":0.0}]}}}
1639350336.1887538: {"jsonrpc":"2.0","method":"channelMessage","params":{"channel":"lightning_board_XRP_JPY","message":{"mid_price":96.01,"bids":[],"asks":[{"price":96.24,"size":9929.0},{"price":96.19,"size":0.0}]}}}
1639350336.1992059: {"jsonrpc":"2.0","method":"channelMessage","params":{"channel":"lightning_board_XLM_JPY","message":{"mid_price":31.52,"bids":[],"asks":[{"price":31.555,"size":0.0}]}}}
1639350336.301017: {"jsonrpc":"2.0","method":"channelMessage","params":{"channel":"lightning_board_FX_BTC_JPY","message":{"mid_price":5863505.0,"bids":[{"price":5861714.0,"size":0.06644039},{"price":5861169.0,"size":0.05},{"price":5858848.0,"size":0.0},{"price":5860748.0,"size":0.05},{"price":5860769.0,"size":0.12},{"price":5860545.0,"size":0.02},{"price":5859976.0,"size":0.05},{"price":5862041.0,"size":0.35},{"price":5860800.0,"size":0.0},{"price":5855832.0,"size":0.0},{"price":5856882.0,"size":0.029},{"price":5862805.0,"size":0.09394516},{"price":5853729.0,"size":0.0},{"price":5862791.0,"size":0.23173743},{"price":5860908.0,"size":0.0},{"price":5860978.0,"size":0.02},{"price":5862629.0,"size":0.04},{"price":5862045.0,"size":0.0},{"price":5860328.0,"size":0.011},{"price":5854678.0,"size":0.0},{"price":5855872.0,"size":0.0267539},{"price":5860526.0,"size":0.1},{"price":5862101.0,"size":0.01},{"price":5860636.0,"size":0.05},{"price":5855874.0,"size":0.01},{"price":5860977.0,"size":0.0},{"price":5857765.0,"size":0.05},{"price":5862819.0,"size":0.03},{"price":5860445.0,"size":0.0},{"price":5855768.0,"size":0.0},{"price":5858127.0,"size":0.0}],"asks":[{"price":5864000.0,"size":0.0},{"price":5864707.0,"size":0.0},{"price":5887513.0,"size":0.0},{"price":5866002.0,"size":0.0},{"price":5866817.0,"size":0.05},{"price":5865372.0,"size":0.0},{"price":5866260.0,"size":0.04946442},{"price":5892192.0,"size":0.0267539},{"price":5867277.0,"size":0.05},{"price":5892190.0,"size":0.01}]}}}
1639350336.3125608: {"jsonrpc":"2.0","method":"channelMessage","params":{"channel":"lightning_ticker_XRP_JPY","message":{"product_code":"XRP_JPY","state":"RUNNING","timestamp":"2021-12-12T23:05:36.1973342Z","tick_id":12284608,"best_bid":95.95,"best_ask":96.08,"best_bid_size":17012.54584,"best_ask_size":620.32,"total_bid_depth":1535891.62622300,"total_ask_depth":2311468.830372000000,"market_bid_size":0.0,"market_ask_size":0.0,"ltp":95.96,"volume":1653279.685708000000,"volume_by_product":1653279.685708000000}}}
1639350336.316757: {"jsonrpc":"2.0","method":"channelMessage","params":{"channel":"lightning_board_XRP_JPY","message":{"mid_price":96.01,"bids":[],"asks":[{"price":96.21,"size":0.0},{"price":96.26,"size":339.420653}]}}}
1639350336.347967: {"jsonrpc":"2.0","method":"channelMessage","params":{"channel":"lightning_board_BTC_EUR","message":{"mid_price":44466.55,"bids":[{"price":44220.02,"size":0.0},{"price":44308.94,"size":0.0}],"asks":[{"price":44597.89,"size":0.0}]}}}
1639350336.3501382: {"jsonrpc":"2.0","method":"channelMessage","params":{"channel":"lightning_board_ETH_JPY","message":{"mid_price":471707.0,"bids":[],"asks":[{"price":473941.0,"size":0.61},{"price":472322.0,"size":2.752}]}}}
1639350336.354941: {"jsonrpc":"2.0","method":"channelMessage","params":{"channel":"lightning_ticker_BTC_USD","message":{"product_code":"BTC_USD","state":"RUNNING","timestamp":"2021-12-12T23:05:36.1973342Z","tick_id":17932855,"best_bid":50244.91,"best_ask":50316.83,"best_bid_size":0.14403190,"best_ask_size":0.01,"total_bid_depth":27.90004577,"total_ask_depth":18.57155541,"market_bid_size":0.0,"market_ask_size":0.0,"ltp":50278.04,"volume":250.100018300000,"volume_by_product":250.100018300000}}}
1639350336.3584461: {"jsonrpc":"2.0","method":"channelMessage","params":{"channel":"lightning_board_BTC_USD","message":{"mid_price":50280.87,"bids":[],"asks":[{"price":50291.63,"size":0.0}]}}}
1639350336.409462: {"jsonrpc":"2.0","method":"channelMessage","params":{"channel":"lightning_ticker_FX_BTC_JPY","message":{"product_code":"FX_BTC_JPY","state":"RUNNING","timestamp":"2021-12-12T23:05:36.2468255Z","tick_id":127090784,"best_bid":5863324.0,"best_ask":5864192.0,"best_bid_size":0.01,"best_ask_size":0.02,"total_bid_depth":230.680554930000,"total_ask_depth":293.794948140000,"market_bid_size":0.0,"market_ask_size":0.0,"ltp":5864000.0,"volume":4227.059644050000,"volume_by_product":4227.059644050000}}}
1639350336.414049: {"jsonrpc":"2.0","method":"channelMessage","params":{"channel":"lightning_board_FX_BTC_JPY","message":{"mid_price":5863758.0,"bids":[{"price":5861541.0,"size":0.01},{"price":5858126.0,"size":0.0},{"price":5863324.0,"size":0.01},{"price":5861959.0,"size":0.0493381},{"price":5860363.0,"size":0.05},{"price":5858331.0,"size":0.255},{"price":5858313.0,"size":0.1}],"asks":[{"price":5867000.0,"size":0.04964016},{"price":5868261.0,"size":0.05},{"price":5866890.0,"size":0.1},{"price":5866839.0,"size":0.12},{"price":5868297.0,"size":0.255}]}}}
1639350336.468653: {"jsonrpc":"2.0","method":"channelMessage","params":{"channel":"lightning_board_XRP_JPY","message":{"mid_price":96.04,"bids":[{"price":95.96,"size":775.5}],"asks":[{"price":96.08,"size":0.0}]}}}
1639350336.480201: {"jsonrpc":"2.0","method":"channelMessage","params":{"channel":"lightning_board_ETH_JPY","message":{"mid_price":471707.0,"bids":[{"price":471517.0,"size":0.832}],"asks":[]}}}
1639350336.521899: {"jsonrpc":"2.0","method":"channelMessage","params":{"channel":"lightning_executions_FX_BTC_JPY","message":[{"id":2284079834,"side":"BUY","price":5864192.0,"size":0.02,"exec_date":"2021-12-12T23:05:36.3976377Z","buy_child_order_acceptance_id":"JRF20211212-230536-124881","sell_child_order_acceptance_id":"JRF20211212-230535-217274"}]}}
1639350336.530352: {"jsonrpc":"2.0","method":"channelMessage","params":{"channel":"lightning_board_FX_BTC_JPY","message":{"mid_price":5863843.0,"bids":[{"price":5863495.0,"size":0.02},{"price":5659138.0,"size":0.02},{"price":5856212.0,"size":0.0},{"price":5862041.0,"size":0.2},{"price":5824800.0,"size":0.0}],"asks":[{"price":5866246.0,"size":0.0},{"price":5867405.0,"size":0.05},{"price":5865910.0,"size":0.0},{"price":5866141.0,"size":0.0},{"price":5870284.0,"size":0.0},{"price":5879777.0,"size":0.0}]}}}
1639350336.549131: {"jsonrpc":"2.0","method":"channelMessage","params":{"channel":"lightning_executions_FX_BTC_JPY","message":[{"id":2284079835,"side":"BUY","price":5865941.0,"size":0.02,"exec_date":"2021-12-12T23:05:36.4144296Z","buy_child_order_acceptance_id":"JRF20211212-230536-204603","sell_child_order_acceptance_id":"JRF20211212-230524-207878"}]}}
1639350336.6517959: {"jsonrpc":"2.0","method":"channelMessage","params":{"channel":"lightning_board_FX_BTC_JPY","message":{"mid_price":5865090.0,"bids":[{"price":5861959.0,"size":0.0},{"price":5861714.0,"size":0.0},{"price":5852431.0,"size":0.0},{"price":5852438.0,"size":0.0},{"price":5855844.0,"size":0.0},{"price":5861541.0,"size":0.0},{"price":5862805.0,"size":0.0},{"price":5859459.0,"size":0.02767346},{"price":5862873.0,"size":0.02},{"price":5862887.0,"size":0.02},{"price":5862629.0,"size":0.0},{"price":5864422.0,"size":0.01},{"price":5852463.0,"size":0.0},{"price":5859976.0,"size":0.0},{"price":5861169.0,"size":0.0},{"price":5862791.0,"size":0.0}],"asks":[{"price":5864192.0,"size":0.0},{"price":5865941.0,"size":0.08},{"price":5875972.0,"size":0.0},{"price":5951720.0,"size":0.7},{"price":5865759.0,"size":0.01},{"price":5866234.0,"size":0.0},{"price":5866258.0,"size":0.0}]}}}
1639350336.787828: {"jsonrpc":"2.0","method":"channelMessage","params":{"channel":"lightning_board_FX_BTC_JPY","message":{"mid_price":5865090.0,"bids":[{"price":5860750.0,"size":0.02},{"price":5859281.0,"size":0.0},{"price":5855840.0,"size":0.0},{"price":5859002.0,"size":0.032},{"price":5859236.0,"size":0.0},{"price":5858313.0,"size":0.0},{"price":5849402.0,"size":0.0},{"price":5832244.0,"size":0.0},{"price":5860526.0,"size":0.0},{"price":5862819.0,"size":0.0},{"price":5864010.0,"size":0.02},{"price":5860769.0,"size":0.0},{"price":5860636.0,"size":0.0},{"price":5862630.0,"size":0.15},{"price":5858341.0,"size":0.02675395},{"price":5861533.0,"size":0.02},{"price":5843860.0,"size":0.03},{"price":5860748.0,"size":0.0},{"price":5863496.0,"size":0.2},{"price":5856510.0,"size":0.0},{"price":5857765.0,"size":0.0}],"asks":[{"price":5866260.0,"size":0.0},{"price":5867277.0,"size":0.0},{"price":5866799.0,"size":0.0},{"price":5868175.0,"size":0.0},{"price":5866726.0,"size":0.02},{"price":5879962.0,"size":0.0},{"price":5873075.0,"size":0.04},{"price":5870470.0,"size":0.0},{"price":5875527.0,"size":0.0},{"price":5866890.0,"size":0.0},{"price":5867000.0,"size":0.0},{"price":5866839.0,"size":0.0}]}}}
1639350336.8703942: {"jsonrpc":"2.0","method":"channelMessage","params":{"channel":"lightning_ticker_XRP_JPY","message":{"product_code":"XRP_JPY","state":"RUNNING","timestamp":"2021-12-12T23:05:36.7921637Z","tick_id":12284611,"best_bid":95.96,"best_ask":96.13,"best_bid_size":775.5,"best_ask_size":49.479871,"total_bid_depth":1536667.12622300,"total_ask_depth":2312089.310372000000,"market_bid_size":0.0,"market_ask_size":0.0,"ltp":95.96,"volume":1653279.685708000000,"volume_by_product":1653279.685708000000}}}
1639350336.8740401: {"jsonrpc":"2.0","method":"channelMessage","params":{"channel":"lightning_board_XRP_JPY","message":{"mid_price":96.04,"bids":[],"asks":[{"price":96.17,"size":1240.8}]}}}
1639350336.9046881: {"jsonrpc":"2.0","method":"channelMessage","params":{"channel":"lightning_board_FX_BTC_JPY","message":{"mid_price":5865090.0,"bids":[{"price":5862630.0,"size":0.0},{"price":5864202.0,"size":0.02},{"price":5855883.0,"size":0.02675298},{"price":5858345.0,"size":0.02675347},{"price":5863945.0,"size":0.23169438}],"asks":[{"price":5892180.0,"size":0.02675395},{"price":5868749.0,"size":0.0},{"price":5879933.0,"size":0.02675347},{"price":5892181.0,"size":0.02675298}]}}}
1639350336.9829519: {"jsonrpc":"2.0","method":"channelMessage","params":{"channel":"lightning_board_snapshot_FX_BTC_JPY","message":{"mid_price":5865090.0,"bids":[{"price":5864422.0,"size":0.01},{"price":5864204.0,"size":0.02},{"price":5864202.0,"size":0.02},{"price":5864010.0,"size":0.02},{"price":5863968.0,"size":0.09392864},{"price":5863945.0,"size":0.23169438},{"price":5863496.0,"size":0.2},{"price":5863324.0,"size":0.01},{"price":5863230.0,"size":0.03},{"price":5862887.0,"size":0.02},{"price":5862873.0,"size":0.02},{"price":5862628.0,"size":0.01},{"price":5862179.0,"size":0.025},{"price":5862105.0,"size":0.03},{"price":5862101.0,"size":0.01},{"price":5862041.0,"size":0.2},{"price":5862040.0,"size":0.2},{"price":5861533.0,"size":0.02},{"price":5861452.0,"size":0.02},{"price":5861451.0,"size":0.01},{"price":5861411.0,"size":0.2},{"price":5860978.0,"size":0.02},{"price":5860750.0,"size":0.02},{"price":5860545.0,"size":0.02},{"price":5860363.0,"size":0.05},{"price":5860328.0,"size":0.011},{"price":5860300.0,"size":0.01},{"price":5860194.0,"size":0.01},{"price":5860075.0,"size":0.02},{"price":5859459.0,"size":0.02767346},{"price":5859147.0,"size":0.01},{"price":5859060.0,"size":0.02},{"price":5859002.0,"size":0.032},{"price":5858863.0,"size":0.02},{"price":5858861.0,"size":0.025},{"price":5858532.0,"size":0.01},{"price":5858345.0,"size":0.02675347},{"price":5858341.0,"size":0.02675395},{"price":5858331.0,"size":0.255},{"price":5858294.0,"size":0.01},{"price":5858210.0,"size":0.04},{"price":5857990.0,"size":0.02},{"price":5857987.0,"size":0.03},{"price":5857984.0,"size":0.2},{"price":5857564.0,"size":0.2},{"price":5857563.0,"size":0.02},{"price":5857263.0,"size":0.026},{"price":5857138.0,"size":0.04},{"price":5856882.0,"size":0.029},{"price":5856474.0,"size":0.04},{"price":5856211.0,"size":0.1},{"price":5855883.0,"size":0.02675298},{"price":5855874.0,"size":0.01},{"price":5855872.0,"size":0.0267539},{"price":5855859.0,"size":0.01},{"price":5855855.0,"size":0.02675389},{"price":5855850.0,"size":0.02675395},{"price":5855808.0,"size":0.2},{"price":5855805.0,"size":0.2},{"price":5855804.0,"size":0.02},{"price":5855577.0,"size":0.01},{"price":5855380.0,"size":0.109},{"price":5854446.0,"size":0.09950742},{"price":5854281.0,"size":0.04},{"price":5854070.0,"size":0.14},{"price":5853607.0,"size":0.1},{"price":5853566.0,"size":0.02760291},{"price":5853534.0,"size":0.47773664},{"price":5853431.0,"size":0.04},{"price":5853321.0,"size":0.025},{"price":5853290.0,"size":0.01},{"price":5853250.0,"size":0.04},{"price":5853170.0,"size":0.02},{"price":5853121.0,"size":0.08},{"price":5852997.0,"size":0.01},{"price":5852983.0,"size":0.05},{"price":5852947.0,"size":0.5},{"price":5852917.0,"size":0.01},{"price":5852877.0,"size":0.04},{"price":5852790.0,"size":0.04},{"price":5852760.0,"size":0.252},{"price":5852632.0,"size":0.01},{"price":5852338.0,"size":0.01},{"price":5852291.0,"size":0.01},{"price":5852203.0,"size":0.477},{"price":5851958.0,"size":0.03},{"price":5851571.0,"size":0.01},{"price":5851233.0,"size":0.2},{"price":5851079.0,"size":0.05},{"price":5850751.0,"size":0.292},{"price":5850693.0,"size":0.04},{"price":5850673.0,"size":0.01},{"price":5850492.0,"size":0.3},{"price":5850052.0,"size":0.05},{"price":5850016.0,"size":0.02},{"price":5849194.0,"size":0.058},{"price":5848716.0,"size":0.01},{"price":5848456.0,"size":0.02},{"price":5848392.0,"size":0.01},{"price":5847901.0,"size":0.02},{"price":5847732.0,"size":0.01},{"price":5847571.0,"size":0.01},{"price":5847473.0,"size":0.05},{"price":5847363.0,"size":0.01},{"price":5847303.0,"size":0.12},{"price":5847121.0,"size":0.05},{"price":5847015.0,"size":0.02},{"price":5846500.0,"size":0.02},{"price":5846007.0,"size":0.1},{"price":5845785.0,"size":0.02},{"price":5845541.0,"size":0.12},{"price":5845407.0,"size":0.01},{"price":5845367.0,"size":0.02},{"price":5845230.0,"size":0.02},{"price":5845000.0,"size":0.05},{"price":5844928.0,"size":0.02},{"price":5843860.0,"size":0.03},{"price":5843040.0,"size":0.05},{"price":5841495.0,"size":0.02},{"price":5841009.0,"size":0.03},{"price":5840987.0,"size":0.1},{"price":5840909.0,"size":0.02},{"price":5840875.0,"size":0.029},{"price":5840794.0,"size":0.02},{"price":5840706.0,"size":1.183},{"price":5840363.0,"size":0.01},{"price":5840129.0,"size":0.01},{"price":5838420.0,"size":0.01},{"price":5837200.0,"size":0.01},{"price":5834878.0,"size":0.04},{"price":5834752.0,"size":0.029},{"price":5834599.0,"size":0.04},{"price":5833832.0,"size":0.01},{"price":5833715.0,"size":0.01},{"price":5833363.0,"size":0.01},{"price":5832750.0,"size":0.01},{"price":5832211.0,"size":0.08},{"price":5831082.0,"size":0.01},{"price":5830423.0,"size":0.02},{"price":5830300.0,"size":0.02},{"price":5828264.0,"size":0.06},{"price":5828190.0,"size":0.01},{"price":5827582.0,"size":0.08},{"price":5827500.0,"size":0.01},{"price":5827441.0,"size":0.02},{"price":5826000.0,"size":0.05},{"price":5825845.0,"size":0.03},{"price":5825000.0,"size":0.01},{"price":5824694.0,"size":0.01},{"price":5822172.0,"size":6.043},{"price":5821506.0,"size":0.04},{"price":5820555.0,"size":0.0125},{"price":5820000.0,"size":0.021},{"price":5819363.0,"size":0.01},{"price":5818271.0,"size":0.08},{"price":5817493.0,"size":0.01},{"price":5817263.0,"size":0.026},{"price":5816415.0,"size":0.05},{"price":5815888.0,"size":0.015},{"price":5815000.0,"size":0.02},{"price":5813693.0,"size":0.01},{"price":5813000.0,"size":0.01},{"price":5812404.0,"size":0.1},{"price":5812383.0,"size":0.1},{"price":5812099.0,"size":0.01},{"price":5810555.0,"size":0.01},{"price":5810115.0,"size":0.01},{"price":5810000.0,"size":0.01},{"price":5809775.0,"size":0.55},{"price":5808888.0,"size":0.021},{"price":5808532.0,"size":0.01},{"price":5808251.0,"size":1.5},{"price":5807825.0,"size":0.01},{"price":5806643.0,"size":0.01},{"price":5806493.0,"size":0.01},{"price":5805600.0,"size":0.03573532},{"price":5805555.0,"size":0.0125},{"price":5805363.0,"size":0.01},{"price":5805000.0,"size":0.06},{"price":5804817.0,"size":0.02},{"price":5803666.0,"size":0.01},{"price":5802985.0,"size":0.01},{"price":5802094.0,"size":0.01},{"price":5801000.0,"size":0.2},{"price":5800577.0,"size":0.02},{"price":5800541.0,"size":0.2},{"price":5800134.0,"size":0.02},{"price":5800000.0,"size":0.58},{"price":5799987.0,"size":0.02},{"price":5797000.0,"size":0.03},{"price":5795600.0,"size":0.05},{"price":5794167.0,"size":0.01},{"price":5791786.0,"size":0.01},{"price":5791363.0,"size":0.02},{"price":5790441.0,"size":0.02},{"price":5790000.0,"size":0.01},{"price":5789008.0,"size":0.1},{"price":5789000.0,"size":0.30334734},{"price":5788910.0,"size":3.597},{"price":5788888.0,"size":0.1},{"price":5787938.0,"size":0.01},{"price":5787489.0,"size":0.04},{"price":5787383.0,"size":0.1},{"price":5786910.0,"size":0.2},{"price":5786316.0,"size":0.01},{"price":5786173.0,"size":0.08},{"price":5785600.0,"size":0.05},{"price":5785000.0,"size":0.01},{"price":5782552.0,"size":0.03},{"price":5781103.0,"size":0.01},{"price":5781082.0,"size":0.01},{"price":5780088.0,"size":0.01},{"price":5780000.0,"size":0.62},{"price":5778256.0,"size":0.08},{"price":5778000.0,"size":0.01},{"price":5777911.0,"size":0.012},{"price":5775600.0,"size":0.05},{"price":5772041.0,"size":0.01},{"price":5770790.0,"size":0.1},{"price":5770474.0,"size":0.01},{"price":5770363.0,"size":0.02},{"price":5770358.0,"size":1.0},{"price":5770000.0,"size":0.2},{"price":5765600.0,"size":0.05},{"price":5765062.0,"size":0.01},{"price":5763400.0,"size":0.01},{"price":5762832.0,"size":0.01},{"price":5762383.0,"size":0.1},{"price":5761555.0,"size":0.02},{"price":5761000.0,"size":0.2},{"price":5760807.0,"size":0.15},{"price":5760000.0,"size":0.12},{"price":5759658.0,"size":0.01},{"price":5758888.0,"size":0.301},{"price":5758715.0,"size":0.01},{"price":5758000.0,"size":0.03},{"price":5757263.0,"size":0.052},{"price":5755600.0,"size":0.05},{"price":5755555.0,"size":0.025},{"price":5753726.0,"size":0.01},{"price":5752455.0,"size":3.589},{"price":5752323.0,"size":0.01},{"price":5752321.0,"size":0.1},{"price":5751800.0,"size":0.01},{"price":5751643.0,"size":0.01},{"price":5750000.0,"size":0.32},{"price":5747500.0,"size":0.1},{"price":5747499.0,"size":0.01},{"price":5745600.0,"size":0.05},{"price":5744759.0,"size":0.5},{"price":5743022.0,"size":0.01},{"price":5742907.0,"size":0.5},{"price":5742363.0,"size":0.02},{"price":5741499.0,"size":0.01},{"price":5740000.0,"size":0.52},{"price":5737499.0,"size":0.01},{"price":5735600.0,"size":0.05},{"price":5732750.0,"size":0.025},{"price":5731731.0,"size":0.01},{"price":5731653.0,"size":0.5},{"price":5731499.0,"size":0.01},{"price":5731232.0,"size":0.05},{"price":5728000.0,"size":1.0},{"price":5727499.0,"size":0.01},{"price":5725600.0,"size":0.05},{"price":5725441.0,"size":0.04},{"price":5725150.0,"size":0.01},{"price":5725101.0,"size":0.1},{"price":5725000.0,"size":0.04},{"price":5724000.0,"size":0.03},{"price":5723654.0,"size":0.012},{"price":5721499.0,"size":0.01},{"price":5721000.0,"size":0.2},{"price":5720009.0,"size":0.01},{"price":5720000.0,"size":0.02},{"price":5715600.0,"size":0.05},{"price":5715000.0,"size":0.03},{"price":5711653.0,"size":0.5},{"price":5708532.0,"size":0.02},{"price":5708450.0,"size":1.191},{"price":5707363.0,"size":0.04},{"price":5705600.0,"size":0.05},{"price":5705555.0,"size":0.025},{"price":5704543.0,"size":2.341},{"price":5702883.0,"size":0.01},{"price":5700000.0,"size":0.985},{"price":5693739.0,"size":0.1},{"price":5692856.0,"size":0.01},{"price":5690585.0,"size":0.01},{"price":5690000.0,"size":0.06},{"price":5686666.0,"size":0.03},{"price":5686049.0,"size":0.1},{"price":5683737.0,"size":0.01},{"price":5682000.0,"size":0.2},{"price":5681000.0,"size":0.2},{"price":5680800.0,"size":0.01},{"price":5680000.0,"size":1.05},{"price":5679812.0,"size":0.01},{"price":5679051.0,"size":0.1},{"price":5678504.0,"size":0.5}],"asks":[{"price":5865759.0,"size":0.01},{"price":5865941.0,"size":0.08},{"price":5865990.0,"size":0.01},{"price":5866726.0,"size":0.02},{"price":5866968.0,"size":0.01},{"price":5867038.0,"size":0.01},{"price":5867405.0,"size":0.05},{"price":5867550.0,"size":0.01},{"price":5868297.0,"size":0.255},{"price":5868514.0,"size":0.02},{"price":5869110.0,"size":0.01},{"price":5869432.0,"size":0.02767346},{"price":5869433.0,"size":0.02767346},{"price":5869591.0,"size":0.025},{"price":5869997.0,"size":0.01},{"price":5870010.0,"size":0.02},{"price":5870281.0,"size":0.06},{"price":5870421.0,"size":0.5},{"price":5870625.0,"size":0.058},{"price":5870739.0,"size":0.01},{"price":5870784.0,"size":0.04},{"price":5871448.0,"size":0.02846307},{"price":5871489.0,"size":0.05},{"price":5871849.0,"size":0.477},{"price":5872800.0,"size":0.01},{"price":5873075.0,"size":0.04},{"price":5873315.0,"size":0.1},{"price":5874100.0,"size":0.01},{"price":5874350.0,"size":0.05},{"price":5874362.0,"size":0.02},{"price":5874888.0,"size":0.01},{"price":5875000.0,"size":0.01},{"price":5875773.0,"size":0.02},{"price":5876000.0,"size":0.11},{"price":5876337.0,"size":0.1},{"price":5876450.0,"size":0.01},{"price":5876629.0,"size":0.133},{"price":5876840.0,"size":0.05},{"price":5877283.0,"size":0.05},{"price":5879591.0,"size":0.02},{"price":5879933.0,"size":0.02675347},{"price":5879947.0,"size":0.01},{"price":5879951.0,"size":0.02675389},{"price":5879980.0,"size":0.0125},{"price":5880000.0,"size":0.1},{"price":5880200.0,"size":0.02},{"price":5880215.0,"size":0.05},{"price":5880582.0,"size":0.01},{"price":5880670.0,"size":0.03},{"price":5880700.0,"size":0.02},{"price":5880738.0,"size":0.04},{"price":5880770.0,"size":0.02},{"price":5880973.0,"size":1.183},{"price":5881250.0,"size":0.01},{"price":5881462.0,"size":0.01},{"price":5881586.0,"size":0.04},{"price":5882441.0,"size":0.01},{"price":5883343.0,"size":0.01},{"price":5883999.0,"size":0.01},{"price":5884885.0,"size":0.04},{"price":5887547.0,"size":0.5},{"price":5887700.0,"size":0.02},{"price":5887824.0,"size":0.01},{"price":5889305.0,"size":0.04},{"price":5889599.0,"size":0.01},{"price":5889900.0,"size":0.0125},{"price":5890000.0,"size":0.15},{"price":5891600.0,"size":0.02675395},{"price":5891606.0,"size":0.06},{"price":5892180.0,"size":0.02675395},{"price":5892181.0,"size":0.02675298},{"price":5892190.0,"size":0.01},{"price":5892192.0,"size":0.0267539},{"price":5892205.0,"size":0.29719466},{"price":5892319.0,"size":0.03},{"price":5892950.0,"size":0.01},{"price":5894000.0,"size":0.01},{"price":5894980.0,"size":0.0125},{"price":5895585.0,"size":0.02},{"price":5896416.0,"size":0.01},{"price":5898188.0,"size":0.01},{"price":5899423.0,"size":0.11},{"price":5899480.0,"size":0.0125},{"price":5899999.0,"size":0.035},{"price":5900000.0,"size":1.21},{"price":5901198.0,"size":0.172},{"price":5901600.0,"size":0.01},{"price":5902155.0,"size":0.02},{"price":5902930.0,"size":0.01},{"price":5903265.0,"size":0.01},{"price":5903336.0,"size":0.01},{"price":5903373.0,"size":0.01},{"price":5903500.0,"size":0.01},{"price":5904359.0,"size":0.02},{"price":5905400.0,"size":0.01},{"price":5905522.0,"size":5.959},{"price":5905821.0,"size":0.02},{"price":5906150.0,"size":0.02},{"price":5907198.0,"size":0.08},{"price":5907359.0,"size":0.02},{"price":5908042.0,"size":0.02},{"price":5909394.0,"size":0.01},{"price":5909719.0,"size":0.02},{"price":5910243.0,"size":0.02},{"price":5910373.0,"size":0.01},{"price":5910844.0,"size":0.01},{"price":5910977.0,"size":0.01},{"price":5914900.0,"size":0.01},{"price":5915167.0,"size":0.01},{"price":5915687.0,"size":0.02},{"price":5915900.0,"size":0.01},{"price":5917850.0,"size":0.02},{"price":5918578.0,"size":0.01},{"price":5918900.0,"size":0.17},{"price":5919157.0,"size":0.05},{"price":5919800.0,"size":0.05},{"price":5920000.0,"size":0.03},{"price":5920100.0,"size":0.01},{"price":5920243.0,"size":0.02},{"price":5920365.0,"size":0.01},{"price":5920406.0,"size":0.01},{"price":5920528.0,"size":0.01},{"price":5921313.0,"size":0.01},{"price":5922222.0,"size":0.23},{"price":5922561.0,"size":0.02},{"price":5923164.0,"size":0.02},{"price":5923250.0,"size":0.02},{"price":5923314.0,"size":0.01},{"price":5923655.0,"size":0.1},{"price":5923670.0,"size":0.02},{"price":5924075.0,"size":3.0},{"price":5924482.0,"size":0.01},{"price":5924500.0,"size":0.2},{"price":5925000.0,"size":0.01},{"price":5925365.0,"size":0.01},{"price":5926888.0,"size":0.02},{"price":5927164.0,"size":0.02},{"price":5927250.0,"size":0.01},{"price":5929800.0,"size":0.05},{"price":5930000.0,"size":0.87},{"price":5930087.0,"size":0.01},{"price":5930314.0,"size":0.01},{"price":5930497.0,"size":0.01},{"price":5930643.0,"size":0.02},{"price":5931365.0,"size":0.01},{"price":5932450.0,"size":0.02},{"price":5933273.0,"size":0.01},{"price":5934563.0,"size":0.1},{"price":5935160.0,"size":0.01},{"price":5935314.0,"size":0.01},{"price":5935843.0,"size":0.02},{"price":5936000.0,"size":0.05},{"price":5936203.0,"size":3.538},{"price":5936481.0,"size":0.01},{"price":5936699.0,"size":0.01},{"price":5936800.0,"size":0.02},{"price":5936840.0,"size":0.1},{"price":5939365.0,"size":0.01},{"price":5939514.0,"size":3.613},{"price":5939780.0,"size":0.0125},{"price":5939800.0,"size":0.05},{"price":5940000.0,"size":0.01},{"price":5940497.0,"size":0.01},{"price":5940800.0,"size":0.03},{"price":5941000.0,"size":0.2},{"price":5941442.0,"size":0.01},{"price":5942373.0,"size":0.01},{"price":5943800.0,"size":0.1},{"price":5944400.0,"size":0.01},{"price":5944500.0,"size":0.2},{"price":5944700.0,"size":0.01},{"price":5944800.0,"size":0.0125},{"price":5944818.0,"size":0.01},{"price":5945000.0,"size":0.2},{"price":5945948.0,"size":1.0},{"price":5948180.0,"size":0.08},{"price":5948450.0,"size":0.02},{"price":5948719.0,"size":0.2},{"price":5949373.0,"size":0.01},{"price":5949780.0,"size":0.0125},{"price":5949800.0,"size":0.05},{"price":5949998.0,"size":0.01},{"price":5950000.0,"size":1.0},{"price":5950497.0,"size":0.01},{"price":5950752.0,"size":0.02},{"price":5950800.0,"size":0.15},{"price":5951720.0,"size":0.7},{"price":5952500.0,"size":0.03},{"price":5954350.0,"size":0.01},{"price":5954503.0,"size":2.343},{"price":5955555.0,"size":0.05},{"price":5955752.0,"size":0.02},{"price":5955929.0,"size":0.01},{"price":5956888.0,"size":0.05},{"price":5957800.0,"size":0.1},{"price":5958373.0,"size":0.01},{"price":5958507.0,"size":0.03},{"price":5959050.0,"size":0.02},{"price":5959800.0,"size":0.05},{"price":5960000.0,"size":0.6},{"price":5960752.0,"size":0.02},{"price":5963000.0,"size":0.01},{"price":5963523.0,"size":0.01},{"price":5964500.0,"size":0.2},{"price":5965203.0,"size":0.01},{"price":5965511.0,"size":0.02},{"price":5965948.0,"size":1.0},{"price":5969750.0,"size":0.03},{"price":5969800.0,"size":0.05},{"price":5970000.0,"size":0.38},{"price":5970164.0,"size":0.02},{"price":5970752.0,"size":0.02},{"price":5974200.0,"size":0.1},{"price":5975800.0,"size":0.01},{"price":5976092.0,"size":0.01},{"price":5976766.0,"size":0.32},{"price":5976800.0,"size":0.1},{"price":5977049.0,"size":0.2},{"price":5977164.0,"size":0.02},{"price":5977176.0,"size":0.1},{"price":5977777.0,"size":0.01},{"price":5978000.0,"size":0.02},{"price":5978719.0,"size":0.2},{"price":5978975.0,"size":0.5},{"price":5979135.0,"size":0.1},{"price":5979800.0,"size":0.05},{"price":5979838.0,"size":0.06},{"price":5980000.0,"size":1.021},{"price":5980125.0,"size":0.01},{"price":5980752.0,"size":0.02},{"price":5981000.0,"size":0.2},{"price":5983443.0,"size":0.05},{"price":5984500.0,"size":0.2},{"price":5985192.0,"size":0.01},{"price":5985425.0,"size":0.5},{"price":5985434.0,"size":0.1},{"price":5985750.0,"size":0.02},{"price":5985842.0,"size":0.01},{"price":5985948.0,"size":1.0},{"price":5988632.0,"size":0.01},{"price":5989750.0,"size":0.03},{"price":5989800.0,"size":0.05},{"price":5989809.0,"size":1.0},{"price":5989870.0,"size":0.15},{"price":5989906.0,"size":0.5},{"price":5990000.0,"size":0.4},{"price":5990752.0,"size":0.02},{"price":5990999.0,"size":0.01},{"price":5993000.0,"size":0.01},{"price":5993999.0,"size":0.24123375},{"price":5994000.0,"size":40.0},{"price":5994255.0,"size":0.01},{"price":5994400.0,"size":0.01},{"price":5994573.0,"size":0.01},{"price":5994643.0,"size":0.3},{"price":5995200.0,"size":0.02},{"price":5996000.0,"size":0.01},{"price":5996599.0,"size":0.48225832},{"price":5996600.0,"size":70.0},{"price":5996659.0,"size":0.24112674},{"price":5996660.0,"size":25.0},{"price":5999983.0,"size":0.01},{"price":5999999.0,"size":0.01},{"price":6000000.0,"size":4.995},{"price":6000298.0,"size":0.17},{"price":6000500.0,"size":0.01},{"price":6000752.0,"size":0.02},{"price":6003000.0,"size":0.1},{"price":6003265.0,"size":0.01},{"price":6004200.0,"size":0.02},{"price":6004500.0,"size":0.2},{"price":6005450.0,"size":0.01},{"price":6005511.0,"size":0.01},{"price":6008000.0,"size":0.01},{"price":6008027.0,"size":0.25},{"price":6008284.0,"size":0.084},{"price":6010000.0,"size":0.05},{"price":6010039.0,"size":0.2},{"price":6015420.0,"size":0.01},{"price":6015500.0,"size":0.01},{"price":6016594.0,"size":0.01},{"price":6017230.0,"size":0.01},{"price":6018888.0,"size":0.02},{"price":6020000.0,"size":0.13},{"price":6020750.0,"size":0.02},{"price":6021000.0,"size":0.2},{"price":6021130.0,"size":0.01},{"price":6022000.0,"size":0.01},{"price":6023000.0,"size":0.01},{"price":6023211.0,"size":0.18},{"price":6024386.0,"size":0.01},{"price":6024500.0,"size":0.2},{"price":6025000.0,"size":0.025},{"price":6025706.0,"size":0.01},{"price":6028425.0,"size":0.34},{"price":6030000.0,"size":0.01},{"price":6030500.0,"size":0.01},{"price":6031629.0,"size":0.03},{"price":6036000.0,"size":0.2},{"price":6037443.0,"size":0.05}]}}}
1639350336.996595: {"jsonrpc":"2.0","method":"channelMessage","params":{"channel":"lightning_board_XRP_JPY","message":{"mid_price":96.04,"bids":[{"price":95.85,"size":0.0}],"asks":[{"price":122.8,"size":0.0},{"price":96.28,"size":9000.0}]}}}
1639350337.003148: {"jsonrpc":"2.0","method":"channelMessage","params":{"channel":"lightning_ticker_BTC_EUR","message":{"product_code":"BTC_EUR","state":"RUNNING","timestamp":"2021-12-12T23:05:36.8120432Z","tick_id":7240215,"best_bid":44461.19,"best_ask":44471.91,"best_bid_size":0.00118145,"best_ask_size":0.50134,"total_bid_depth":14.39728901,"total_ask_depth":13.22812467,"market_bid_size":0.0,"market_ask_size":0.0,"ltp":44461.2,"volume":43.951523900000,"volume_by_product":43.951523900000}}}
1639350337.012379: {"jsonrpc":"2.0","method":"channelMessage","params":{"channel":"lightning_ticker_FX_BTC_JPY","message":{"product_code":"FX_BTC_JPY","state":"RUNNING","timestamp":"2021-12-12T23:05:36.8367351Z","tick_id":127090875,"best_bid":5864422.0,"best_ask":5865759.0,"best_bid_size":0.01,"best_ask_size":0.01,"total_bid_depth":229.759391560000,"total_ask_depth":293.177802240000,"market_bid_size":0.0,"market_ask_size":0.0,"ltp":5865941.0,"volume":4227.099644050000,"volume_by_product":4227.099644050000}}}
1639350337.015508: {"jsonrpc":"2.0","method":"channelMessage","params":{"channel":"lightning_board_BTC_EUR","message":{"mid_price":44466.55,"bids":[],"asks":[{"price":44695.8,"size":0.18}]}}}
1639350337.028704: {"jsonrpc":"2.0","method":"channelMessage","params":{"channel":"lightning_board_FX_BTC_JPY","message":{"mid_price":5865090.0,"bids":[{"price":5863495.0,"size":0.0},{"price":5853607.0,"size":0.1},{"price":5863230.0,"size":0.03},{"price":5863968.0,"size":0.09392864},{"price":5856211.0,"size":0.1},{"price":5864204.0,"size":0.02}],"asks":[{"price":5866817.0,"size":0.0},{"price":5868261.0,"size":0.0},{"price":5870010.0,"size":0.02},{"price":5871448.0,"size":0.02846307},{"price":5868514.0,"size":0.02},{"price":5868493.0,"size":0.0}]}}}
1639350337.044615: {"jsonrpc":"2.0","method":"channelMessage","params":{"channel":"lightning_board_snapshot_BTCJPY17DEC2021","message":{"mid_price":5701213.0,"bids":[{"price":5349532.0,"size":15.6},{"price":5391567.0,"size":6.6},{"price":5442047.0,"size":5.01},{"price":5454556.0,"size":4.0},{"price":5510756.0,"size":4.9},{"price":5575932.0,"size":3.9},{"price":5586201.0,"size":3.0},{"price":5598443.0,"size":3.02},{"price":5619882.0,"size":2.0},{"price":5629303.0,"size":1.8},{"price":5648347.0,"size":0.76},{"price":5653790.0,"size":0.7},{"price":5661414.0,"size":0.6},{"price":5674739.0,"size":0.26},{"price":5677741.0,"size":1.0},{"price":5677751.0,"size":0.01},{"price":5686175.0,"size":0.2},{"price":5691316.0,"size":0.01}],"asks":[{"price":5711111.0,"size":0.01},{"price":5713220.0,"size":0.15},{"price":5713319.0,"size":0.2},{"price":5714075.0,"size":0.58},{"price":5715427.0,"size":0.3},{"price":5716898.0,"size":0.6},{"price":5718589.0,"size":1.0},{"price":5732566.0,"size":1.0},{"price":5734417.0,"size":1.8},{"price":5746044.0,"size":1.9},{"price":5766647.0,"size":3.0},{"price":5796786.0,"size":2.4},{"price":5829125.0,"size":3.0},{"price":5852911.0,"size":5.0},{"price":5879283.0,"size":4.8},{"price":5920799.0,"size":5.0},{"price":5944842.0,"size":9.3},{"price":5986556.0,"size":12.75},{"price":6536736.0,"size":0.5},{"price":6600822.0,"size":1.0},{"price":6728993.0,"size":3.0},{"price":6857165.0,"size":5.0}]}}}
1639350337.0457149: {"jsonrpc":"2.0","method":"channelMessage","params":{"channel":"lightning_ticker_ETH_JPY","message":{"product_code":"ETH_JPY","state":"RUNNING","timestamp":"2021-12-12T23:05:36.8499988Z","tick_id":26934520,"best_bid":471614.0,"best_ask":471800.0,"best_bid_size":0.63,"best_ask_size":0.02,"total_bid_depth":3281.125417900000,"total_ask_depth":4457.65657320,"market_bid_size":0.0,"market_ask_size":0.0,"ltp":471501.000000,"volume":10833.500505500000,"volume_by_product":10833.500505500000}}}
1639350337.049081: {"jsonrpc":"2.0","method":"channelMessage","params":{"channel":"lightning_board_snapshot_BTCJPY24DEC2021","message":{"mid_price":5700879.0,"bids":[{"price":5073146.0,"size":5.0},{"price":5182246.0,"size":3.0},{"price":5291346.0,"size":1.0},{"price":5468270.0,"size":5.21},{"price":5502844.0,"size":4.0},{"price":5557220.0,"size":3.0},{"price":5583530.0,"size":3.7},{"price":5603205.0,"size":2.3},{"price":5623006.0,"size":1.92},{"price":5659178.0,"size":2.0},{"price":5661869.0,"size":1.3},{"price":5677658.0,"size":1.0},{"price":5680273.0,"size":0.7},{"price":5683047.0,"size":0.5},{"price":5683544.0,"size":0.75}],"asks":[{"price":5718215.0,"size":0.19},{"price":5721381.0,"size":0.41},{"price":5722463.0,"size":1.0},{"price":5723492.0,"size":1.0},{"price":5725066.0,"size":1.09},{"price":5727746.0,"size":0.51},{"price":5730420.0,"size":1.0},{"price":5743558.0,"size":2.0},{"price":5749238.0,"size":2.0},{"price":5771552.0,"size":1.91},{"price":5794015.0,"size":2.8},{"price":5820325.0,"size":2.77},{"price":5832425.0,"size":3.71},{"price":5836846.0,"size":5.0},{"price":5867046.0,"size":4.9}]}}}
1639350337.0523992: {"jsonrpc":"2.0","method":"channelMessage","params":{"channel":"lightning_board_ETH_JPY","message":{"mid_price":471707.0,"bids":[{"price":471317.0,"size":1.0},{"price":471281.0,"size":0.0},{"price":471316.0,"size":0.0}],"asks":[{"price":471940.0,"size":0.0},{"price":472323.0,"size":0.0},{"price":472322.0,"size":0.768},{"price":473941.0,"size":0.0}]}}}
1639350337.058738: {"jsonrpc":"2.0","method":"channelMessage","params":{"channel":"lightning_ticker_BTC_USD","message":{"product_code":"BTC_USD","state":"RUNNING","timestamp":"2021-12-12T23:05:36.8730487Z","tick_id":17932860,"best_bid":50265.78,"best_ask":50316.83,"best_bid_size":0.6003,"best_ask_size":0.01,"total_bid_depth":27.29974577,"total_ask_depth":19.77215541,"market_bid_size":0.0,"market_ask_size":0.0,"ltp":50278.04,"volume":250.100018300000,"volume_by_product":250.100018300000}}}
1639350337.065399: {"jsonrpc":"2.0","method":"channelMessage","params":{"channel":"lightning_board_BTC_USD","message":{"mid_price":50291.3,"bids":[{"price":50216.06,"size":0.0},{"price":50223.59,"size":0.0},{"price":50265.78,"size":0.6003}],"asks":[{"price":50318.6,"size":0.6003},{"price":50326.15,"size":0.6003}]}}}
1639350337.0828428: {"jsonrpc":"2.0","method":"channelMessage","params":{"channel":"lightning_executions_ETH_JPY","message":[{"id":2284078764,"side":"BUY","price":471800.0,"size":0.02,"exec_date":"2021-12-12T23:05:36.9869304Z","buy_child_order_acceptance_id":"JRF20211212-230536-156822","sell_child_order_acceptance_id":"JRF20211212-230312-093056"}]}}
1639350337.149737: {"jsonrpc":"2.0","method":"channelMessage","params":{"channel":"lightning_board_FX_BTC_JPY","message":{"mid_price":5865090.0,"bids":[{"price":5857564.0,"size":0.3},{"price":5863496.0,"size":0.35},{"price":5861704.0,"size":0.05},{"price":5826882.0,"size":0.029},{"price":5863495.0,"size":0.02},{"price":5862707.0,"size":0.05},{"price":5864204.0,"size":0.0},{"price":5862394.0,"size":0.02},{"price":5862405.0,"size":0.17},{"price":5862105.0,"size":0.0},{"price":5861451.0,"size":0.0},{"price":5861818.0,"size":0.02},{"price":5851295.0,"size":0.1},{"price":5863257.0,"size":0.06644039},{"price":5862893.0,"size":0.01}],"asks":[{"price":5871448.0,"size":0.05692614},{"price":5872509.0,"size":0.1},{"price":5868811.0,"size":0.05},{"price":5867798.0,"size":0.04946442},{"price":5889450.0,"size":0.01},{"price":5874972.0,"size":0.1},{"price":5868476.0,"size":0.12}]}}}
1639350337.173768: {"jsonrpc":"2.0","method":"channelMessage","params":{"channel":"lightning_board_BTC_USD","message":{"mid_price":50295.07,"bids":[{"price":49852.51,"size":0.27},{"price":49812.28,"size":0.45},{"price":49892.75,"size":0.18},{"price":49724.37,"size":0.0},{"price":50273.32,"size":0.6003}],"asks":[{"price":50697.48,"size":0.18},{"price":50737.72,"size":0.27},{"price":50777.95,"size":0.45},{"price":50850.83,"size":0.0},{"price":51092.21,"size":0.0}]}}}
1639350337.2116811: {"jsonrpc":"2.0","method":"channelMessage","params":{"channel":"lightning_board_BTC_EUR","message":{"mid_price":44481.84,"bids":[{"price":44337.68,"size":0.0},{"price":44236.98,"size":0.18},{"price":44407.34,"size":0.50134},{"price":44323.52,"size":0.18}],"asks":[{"price":44531.7,"size":0.50134},{"price":44471.91,"size":0.0}]}}}
1639350337.223436: {"jsonrpc":"2.0","method":"channelMessage","params":{"channel":"lightning_board_XRP_JPY","message":{"mid_price":96.04,"bids":[{"price":95.78,"size":10434.0},{"price":95.84,"size":11356.239}],"asks":[{"price":96.26,"size":0.0}]}}}
1639350337.2292008: {"jsonrpc":"2.0","method":"channelMessage","params":{"channel":"lightning_ticker_XLM_JPY","message":{"product_code":"XLM_JPY","state":"RUNNING","timestamp":"2021-12-12T23:05:36.9407058Z","tick_id":8300559,"best_bid":31.484,"best_ask":31.556,"best_bid_size":3739.0,"best_ask_size":150.24,"total_bid_depth":1862667.93493760,"total_ask_depth":2114737.687473400000,"market_bid_size":0.0,"market_ask_size":0.0,"ltp":31.471,"volume":1471420.073424000000,"volume_by_product":1471420.073424000000}}}
1639350337.2299259: {"jsonrpc":"2.0","method":"channelMessage","params":{"channel":"lightning_board_XLM_JPY","message":{"mid_price":31.52,"bids":[],"asks":[{"price":31.572,"size":0.0}]}}}
1639350337.2418401: {"jsonrpc":"2.0","method":"channelMessage","params":{"channel":"lightning_board_ETH_JPY","message":{"mid_price":471807.0,"bids":[{"price":470655.0,"size":0.0},{"price":471614.0,"size":1.38}],"asks":[{"price":472088.0,"size":0.75},{"price":471800.0,"size":0.0}]}}}
1639350337.280548: {"jsonrpc":"2.0","method":"channelMessage","params":{"channel":"lightning_board_FX_BTC_JPY","message":{"mid_price":5865090.0,"bids":[{"price":5855145.0,"size":0.1},{"price":5855148.0,"size":0.1},{"price":5859239.0,"size":0.1},{"price":5862320.0,"size":0.05},{"price":5864397.0,"size":0.03},{"price":5859306.0,"size":0.05},{"price":5862101.0,"size":0.0}],"asks":[{"price":5868476.0,"size":0.17},{"price":5869432.0,"size":0.0}]}}}
1639350337.360008: {"jsonrpc":"2.0","method":"channelMessage","params":{"channel":"lightning_board_BTC_USD","message":{"mid_price":50285.15,"bids":[],"asks":[{"price":50311.05,"size":0.0},{"price":51011.75,"size":0.0},{"price":50296.99,"size":1.0}]}}}
1639350337.381651: {"jsonrpc":"2.0","method":"channelMessage","params":{"channel":"lightning_board_ETH_JPY","message":{"mid_price":471807.0,"bids":[{"price":470880.0,"size":44.0}],"asks":[{"price":472527.0,"size":0.0},{"price":472360.0,"size":5.013},{"price":473083.0,"size":6.08},{"price":472493.0,"size":0.0}]}}}
1639350337.396992: {"jsonrpc":"2.0","method":"channelMessage","params":{"channel":"lightning_board_XLM_JPY","message":{"mid_price":31.521,"bids":[{"price":31.478,"size":0.0},{"price":31.485,"size":2553.74}],"asks":[{"price":31.556,"size":0.0}]}}}
1639350337.399605: {"jsonrpc":"2.0","method":"channelMessage","params":{"channel":"lightning_board_FX_BTC_JPY","message":{"mid_price":5865090.0,"bids":[{"price":5861452.0,"size":0.0},{"price":5864304.0,"size":0.01}],"asks":[{"price":5868951.0,"size":0.1},{"price":5869019.0,"size":0.02},{"price":5868974.0,"size":0.08558488},{"price":5867162.0,"size":0.011},{"price":5868391.0,"size":0.04964016},{"price":5869498.0,"size":0.05},{"price":5869433.0,"size":0.0}]}}}
1639350337.415275: {"jsonrpc":"2.0","method":"channelMessage","params":{"channel":"lightning_board_BTC_EUR","message":{"mid_price":44470.42,"bids":[{"price":43711.83,"size":0.0}],"asks":[{"price":44612.57,"size":0.13},{"price":44479.65,"size":0.01},{"price":44695.8,"size":0.0}]}}}
1639350337.4219332: {"jsonrpc":"2.0","method":"channelMessage","params":{"channel":"lightning_ticker_XRP_JPY","message":{"product_code":"XRP_JPY","state":"RUNNING","timestamp":"2021-12-12T23:05:37.2416335Z","tick_id":12284621,"best_bid":95.96,"best_ask":96.13,"best_bid_size":775.5,"best_ask_size":49.479871,"total_bid_depth":1525804.08922300,"total_ask_depth":2320999.181293000000,"market_bid_size":0.0,"market_ask_size":0.0,"ltp":95.96,"volume":1653279.685708000000,"volume_by_product":1653279.685708000000}}}
1639350337.42666: {"jsonrpc":"2.0","method":"channelMessage","params":{"channel":"lightning_board_XRP_JPY","message":{"mid_price":96.04,"bids":[{"price":95.9,"size":10697.0},{"price":95.78,"size":0.0},{"price":95.71,"size":0.0}],"asks":[{"price":96.26,"size":339.291574}]}}}
1639350337.4330828: {"jsonrpc":"2.0","method":"channelMessage","params":{"channel":"lightning_ticker_MONA_JPY","message":{"product_code":"MONA_JPY","state":"RUNNING","timestamp":"2021-12-12T23:05:37.2416335Z","tick_id":1298060,"best_bid":165.021,"best_ask":166.998,"best_bid_size":98.0,"best_ask_size":0.80479767,"total_bid_depth":104378.54458855,"total_ask_depth":165869.58885022,"market_bid_size":0.0,"market_ask_size":0.0,"ltp":166.0,"volume":9933.778937320000,"volume_by_product":9933.778937320000}}}
1639350337.4355671: {"jsonrpc":"2.0","method":"channelMessage","params":{"channel":"lightning_board_MONA_JPY","message":{"mid_price":166.009,"bids":[],"asks":[{"price":168.179,"size":11.0}]}}}
1639350337.517845: {"jsonrpc":"2.0","method":"channelMessage","params":{"channel":"lightning_board_FX_BTC_JPY","message":{"mid_price":5865090.0,"bids":[{"price":5862179.0,"size":0.0},{"price":5862117.0,"size":0.1},{"price":5863206.0,"size":0.0493381},{"price":5857987.0,"size":0.0},{"price":5860978.0,"size":0.0},{"price":5401538.0,"size":0.04}],"asks":[{"price":5870281.0,"size":0.0}]}}}
1639350337.547634: {"jsonrpc":"2.0","method":"channelMessage","params":{"channel":"lightning_board_ETH_JPY","message":{"mid_price":471860.0,"bids":[{"price":471721.0,"size":0.65},{"price":470878.0,"size":14.99995},{"price":471615.0,"size":0.928},{"price":471280.0,"size":0.0}],"asks":[{"price":474051.0,"size":0.57},{"price":472094.0,"size":0.75}]}}}
1639350337.564064: {"jsonrpc":"2.0","method":"channelMessage","params":{"channel":"lightning_board_BTC_USD","message":{"mid_price":50285.15,"bids":[{"price":49737.39,"size":1.115},{"price":49697.15,"size":0.9},{"price":49777.63,"size":0.675},{"price":50244.9,"size":0.0}],"asks":[{"price":50823.89,"size":0.675},{"price":50904.37,"size":0.9},{"price":50864.13,"size":1.125}]}}}
1639350337.573476: {"jsonrpc":"2.0","method":"channelMessage","params":{"channel":"lightning_board_XRP_JPY","message":{"mid_price":96.04,"bids":[{"price":95.83,"size":9000.0}],"asks":[{"price":96.17,"size":465.24}]}}}
1639350337.579202: {"jsonrpc":"2.0","method":"channelMessage","params":{"channel":"lightning_ticker_BTC_EUR","message":{"product_code":"BTC_EUR","state":"RUNNING","timestamp":"2021-12-12T23:05:37.4110793Z","tick_id":7240228,"best_bid":44461.19,"best_ask":44479.65,"best_bid_size":0.00118145,"best_ask_size":0.01,"total_bid_depth":14.56728901,"total_ask_depth":13.45712467,"market_bid_size":0.0,"market_ask_size":0.0,"ltp":44461.2,"volume":43.951523900000,"volume_by_product":43.951523900000}}}
1639350337.586793: {"jsonrpc":"2.0","method":"channelMessage","params":{"channel":"lightning_board_BTC_EUR","message":{"mid_price":44470.42,"bids":[{"price":44323.52,"size":0.0}],"asks":[{"price":45427.26,"size":0.399},{"price":44612.57,"size":0.0}]}}}
1639350337.630518: {"jsonrpc":"2.0","method":"channelMessage","params":{"channel":"lightning_ticker_FX_BTC_JPY","message":{"product_code":"FX_BTC_JPY","state":"RUNNING","timestamp":"2021-12-12T23:05:37.4492563Z","tick_id":127090927,"best_bid":5864422.0,"best_ask":5865759.0,"best_bid_size":0.01,"best_ask_size":0.01,"total_bid_depth":230.999170050000,"total_ask_depth":293.986607850000,"market_bid_size":0.0,"market_ask_size":0.0,"ltp":5865941.0,"volume":4227.099644050000,"volume_by_product":4227.099644050000}}}
1639350337.639487: {"jsonrpc":"2.0","method":"channelMessage","params":{"channel":"lightning_board_FX_BTC_JPY","message":{"mid_price":5865090.0,"bids":[{"price":5863324.0,"size":0.0},{"price":5841495.0,"size":0.0},{"price":5863032.0,"size":0.02}],"asks":[{"price":5868187.0,"size":0.1}]}}}
1639350337.678245: {"jsonrpc":"2.0","method":"channelMessage","params":{"channel":"lightning_ticker_BTC_USD","message":{"product_code":"BTC_USD","state":"RUNNING","timestamp":"2021-12-12T23:05:37.546757Z","tick_id":17932885,"best_bid":50273.32,"best_ask":50296.99,"best_bid_size":0.6003,"best_ask_size":1.0,"total_bid_depth":29.42365669,"total_ask_depth":22.44300412,"market_bid_size":0.0,"market_ask_size":0.0,"ltp":50278.04,"volume":250.100018300000,"volume_by_product":250.100018300000}}}
1639350337.6824498: {"jsonrpc":"2.0","method":"channelMessage","params":{"channel":"lightning_board_BTC_USD","message":{"mid_price":50285.15,"bids":[{"price":50244.92,"size":0.04197325},{"price":50244.91,"size":0.15066957}],"asks":[{"price":50373.38,"size":0.07225738},{"price":50439.82,"size":0.07359133}]}}}
1639350337.6937358: {"jsonrpc":"2.0","method":"channelMessage","params":{"channel":"lightning_ticker_ETH_JPY","message":{"product_code":"ETH_JPY","state":"RUNNING","timestamp":"2021-12-12T23:05:37.546757Z","tick_id":26934537,"best_bid":471721.0,"best_ask":472000.0,"best_bid_size":0.65,"best_ask_size":0.02,"total_bid_depth":3339.941367900000,"total_ask_depth":4426.71957320,"market_bid_size":0.0,"market_ask_size":0.0,"ltp":471800.0,"volume":10833.520505500000,"volume_by_product":10833.520505500000}}}
1639350337.699156: {"jsonrpc":"2.0","method":"channelMessage","params":{"channel":"lightning_board_ETH_JPY","message":{"mid_price":471860.0,"bids":[{"price":471517.0,"size":0.0}],"asks":[{"price":472721.0,"size":6.0}]}}}
1639350337.75025: {"jsonrpc":"2.0","method":"channelMessage","params":{"channel":"lightning_board_FX_BTC_JPY","message":{"mid_price":5865409.0,"bids":[{"price":5858863.0,"size":0.0},{"price":5857990.0,"size":0.0},{"price":5855380.0,"size":0.0},{"price":5865059.0,"size":0.01}],"asks":[{"price":5866421.0,"size":0.01},{"price":5872676.0,"size":0.02846307},{"price":5879591.0,"size":0.0}]}}}
1639350337.830514: {"jsonrpc":"2.0","method":"channelMessage","params":{"channel":"lightning_board_XRP_JPY","message":{"mid_price":96.04,"bids":[],"asks":[{"price":96.17,"size":0.0}]}}}
1639350337.849178: {"jsonrpc":"2.0","method":"channelMessage","params":{"channel":"lightning_executions_FX_BTC_JPY","message":[{"id":2284079836,"side":"BUY","price":5865759.0,"size":0.01,"exec_date":"2021-12-12T23:05:37.7289105Z","buy_child_order_acceptance_id":"JRF20211212-230537-218912","sell_child_order_acceptance_id":"JRF20211212-230536-156821"}]}}
1639350337.911975: {"jsonrpc":"2.0","method":"channelMessage","params":{"channel":"lightning_board_FX_BTC_JPY","message":{"mid_price":5865829.0,"bids":[{"price":5863968.0,"size":0.0},{"price":5863945.0,"size":0.0},{"price":5860726.0,"size":0.109},{"price":5847473.0,"size":0.0},{"price":5397473.0,"size":0.0},{"price":4897473.0,"size":0.0},{"price":4097473.0,"size":0.0},{"price":5865717.0,"size":0.01},{"price":5863257.0,"size":0.0},{"price":5861704.0,"size":0.0},{"price":5863206.0,"size":0.0},{"price":5860363.0,"size":0.0},{"price":5863496.0,"size":0.2},{"price":5864400.0,"size":0.02},{"price":5849194.0,"size":0.0}],"asks":[{"price":5865759.0,"size":0.0},{"price":5868362.0,"size":0.0},{"price":5870625.0,"size":0.0}]}}}
1639350337.954966: {"jsonrpc":"2.0","method":"channelMessage","params":{"channel":"lightning_ticker_XLM_JPY","message":{"product_code":"XLM_JPY","state":"RUNNING","timestamp":"2021-12-12T23:05:37.7162871Z","tick_id":8300563,"best_bid":31.485,"best_ask":31.557,"best_bid_size":2553.74,"best_ask_size":978.2,"total_bid_depth":1862667.59493760,"total_ask_depth":2115939.427473400000,"market_bid_size":0.0,"market_ask_size":0.0,"ltp":31.471,"volume":1471420.073424000000,"volume_by_product":1471420.073424000000}}}
1639350337.960187: {"jsonrpc":"2.0","method":"channelMessage","params":{"channel":"lightning_board_XLM_JPY","message":{"mid_price":31.521,"bids":[],"asks":[{"price":31.578,"size":1351.98}]}}}
1639350337.970769: {"jsonrpc":"2.0","method":"channelMessage","params":{"channel":"lightning_board_BTC_USD","message":{"mid_price":50295.07,"bids":[],"asks":[{"price":50296.99,"size":0.0}]}}}
1639350337.992587: {"jsonrpc":"2.0","method":"channelMessage","params":{"channel":"lightning_board_ETH_JPY","message":{"mid_price":471860.0,"bids":[{"price":470878.0,"size":0.0}],"asks":[]}}}
1639350337.9961002: {"jsonrpc":"2.0","method":"channelMessage","params":{"channel":"lightning_ticker_XRP_JPY","message":{"product_code":"XRP_JPY","state":"RUNNING","timestamp":"2021-12-12T23:05:37.8202002Z","tick_id":12284626,"best_bid":95.96,"best_ask":96.13,"best_bid_size":775.5,"best_ask_size":49.479871,"total_bid_depth":1534804.08922300,"total_ask_depth":2308895.381293000000,"market_bid_size":0.0,"market_ask_size":0.0,"ltp":95.96,"volume":1653279.685708000000,"volume_by_product":1653279.685708000000}}}
1639350337.9989388: {"jsonrpc":"2.0","method":"channelMessage","params":{"channel":"lightning_board_XRP_JPY","message":{"mid_price":96.04,"bids":[],"asks":[{"price":96.18,"size":0.0}]}}}
1639350338.009282: {"jsonrpc":"2.0","method":"channelMessage","params":{"channel":"lightning_board_BTC_EUR","message":{"mid_price":44470.42,"bids":[{"price":44331.57,"size":0.18}],"asks":[]}}}
1639350338.037598: {"jsonrpc":"2.0","method":"channelMessage","params":{"channel":"lightning_board_FX_BTC_JPY","message":{"mid_price":5865829.0,"bids":[{"price":5859459.0,"size":0.0},{"price":5862707.0,"size":0.0},{"price":5766882.0,"size":0.058},{"price":5848456.0,"size":0.0},{"price":5852602.0,"size":0.058},{"price":5858294.0,"size":0.0},{"price":5845403.0,"size":0.02},{"price":5863230.0,"size":0.0}],"asks":[{"price":5867798.0,"size":0.0},{"price":5883526.0,"size":0.02},{"price":5867405.0,"size":0.0},{"price":5872675.0,"size":0.02846307},{"price":5868811.0,"size":0.0},{"price":5866726.0,"size":0.0},{"price":5875773.0,"size":0.0},{"price":5874448.0,"size":0.058}]}}}
1639350338.124884: {"jsonrpc":"2.0","method":"channelMessage","params":{"channel":"lightning_board_ETH_JPY","message":{"mid_price":471860.0,"bids":[],"asks":[{"price":477037.0,"size":0.0},{"price":475836.0,"size":0.0}]}}}
1639350338.133099: {"jsonrpc":"2.0","method":"channelMessage","params":{"channel":"lightning_board_BTC_USD","message":{"mid_price":50295.07,"bids":[],"asks":[{"price":51105.93,"size":0.54}]}}}
1639350338.177461: {"jsonrpc":"2.0","method":"channelMessage","params":{"channel":"lightning_ticker_FX_BTC_JPY","message":{"product_code":"FX_BTC_JPY","state":"RUNNING","timestamp":"2021-12-12T23:05:38.0469207Z","tick_id":127090983,"best_bid":5865717.0,"best_ask":5865941.0,"best_bid_size":0.01,"best_ask_size":0.08000000,"total_bid_depth":229.862000520000,"total_ask_depth":293.634069570000,"market_bid_size":0.0,"market_ask_size":0.0,"ltp":5865759.0,"volume":4227.109644050000,"volume_by_product":4227.109644050000}}}
1639350338.1842408: {"jsonrpc":"2.0","method":"channelMessage","params":{"channel":"lightning_board_FX_BTC_JPY","message":{"mid_price":5865829.0,"bids":[{"price":5862117.0,"size":0.0},{"price":5859306.0,"size":0.0},{"price":5862405.0,"size":0.0},{"price":5862320.0,"size":0.0},{"price":5864397.0,"size":0.0},{"price":5860545.0,"size":0.0},{"price":5864498.0,"size":0.09390544},{"price":5863946.0,"size":0.15}],"asks":[{"price":5873315.0,"size":0.0},{"price":5866421.0,"size":0.0},{"price":5868187.0,"size":0.0},{"price":5893134.0,"size":0.04},{"price":5869498.0,"size":0.0}]}}}
1639350338.217856: {"jsonrpc":"2.0","method":"channelMessage","params":{"channel":"lightning_executions_FX_BTC_JPY","message":[{"id":2284079837,"side":"BUY","price":5865941.0,"size":0.08,"exec_date":"2021-12-12T23:05:38.0637041Z","buy_child_order_acceptance_id":"JRF20211212-230537-217284","sell_child_order_acceptance_id":"JRF20211212-230524-207878"},{"id":2284079838,"side":"BUY","price":5865990.0,"size":0.01,"exec_date":"2021-12-12T23:05:38.0637041Z","buy_child_order_acceptance_id":"JRF20211212-230537-199980","sell_child_order_acceptance_id":"JRF20211212-230534-212586"}]}}
1639350338.2281191: {"jsonrpc":"2.0","method":"channelMessage","params":{"channel":"lightning_ticker_ETH_JPY","message":{"product_code":"ETH_JPY","state":"RUNNING","timestamp":"2021-12-12T23:05:38.113394Z","tick_id":26934542,"best_bid":471721.0,"best_ask":472000.0,"best_bid_size":0.65,"best_ask_size":0.02,"total_bid_depth":3339.941367900000,"total_ask_depth":4396.78957320,"market_bid_size":0.0,"market_ask_size":0.0,"ltp":471800.0,"volume":10833.520505500000,"volume_by_product":10833.520505500000}}}
1639350338.2358289: {"jsonrpc":"2.0","method":"channelMessage","params":{"channel":"lightning_board_ETH_JPY","message":{"mid_price":471860.0,"bids":[{"price":471380.0,"size":14.99995}],"asks":[{"price":482187.0,"size":15.37}]}}}
1639350338.367399: {"jsonrpc":"2.0","method":"channelMessage","params":{"channel":"lightning_board_ETH_JPY","message":{"mid_price":471860.0,"bids":[],"asks":[{"price":479827.0,"size":29.93},{"price":472322.0,"size":0.0},{"price":472638.0,"size":1.536}]}}}
1639350338.373871: {"jsonrpc":"2.0","method":"channelMessage","params":{"channel":"lightning_board_FX_BTC_JPY","message":{"mid_price":5866347.0,"bids":[{"price":5862113.0,"size":0.03},{"price":5862731.0,"size":0.05},{"price":5855850.0,"size":0.0},{"price":5864510.0,"size":0.23167942},{"price":5862800.0,"size":0.05},{"price":5864010.0,"size":0.0},{"price":5863760.0,"size":0.05},{"price":5861217.0,"size":0.05692614},{"price":5864202.0,"size":0.0},{"price":5864543.0,"size":0.06644039},{"price":5848456.0,"size":0.02},{"price":5863946.0,"size":0.0},{"price":5863497.0,"size":0.02},{"price":5864011.0,"size":0.02},{"price":5855859.0,"size":0.0},{"price":5855855.0,"size":0.0},{"price":5858351.0,"size":0.02675395},{"price":5852983.0,"size":0.0},{"price":5850052.0,"size":0.0},{"price":5847121.0,"size":0.0},{"price":5857564.0,"size":0.2},{"price":5860075.0,"size":0.0},{"price":5865727.0,"size":0.03},{"price":5857614.0,"size":0.1},{"price":5860597.0,"size":0.05}],"asks":[{"price":5868476.0,"size":0.0},{"price":5868391.0,"size":0.0},{"price":5865941.0,"size":0.0},{"price":5865990.0,"size":0.0},{"price":5891600.0,"size":0.0},{"price":5869538.0,"size":0.05},{"price":5871841.0,"size":0.06},{"price":5879947.0,"size":0.0},{"price":5869007.0,"size":0.04946442},{"price":5879951.0,"size":0.0},{"price":5870077.0,"size":0.05},{"price":5870010.0,"size":0.0},{"price":5870421.0,"size":0.0},{"price":5874350.0,"size":0.0},{"price":5877283.0,"size":0.0},{"price":5880215.0,"size":0.0},{"price":5894974.0,"size":0.02675395}]}}}
1639350338.3805408: {"jsonrpc":"2.0","method":"channelMessage","params":{"channel":"lightning_board_XRP_JPY","message":{"mid_price":96.04,"bids":[],"asks":[{"price":96.22,"size":1550.8}]}}}
1639350338.505216: {"jsonrpc":"2.0","method":"channelMessage","params":{"channel":"lightning_board_ETH_JPY","message":{"mid_price":471861.0,"bids":[{"price":471722.0,"size":0.576},{"price":471077.0,"size":0.0},{"price":471000.0,"size":0.0}],"asks":[]}}}
1639350338.5206652: {"jsonrpc":"2.0","method":"channelMessage","params":{"channel":"lightning_ticker_BTC_EUR","message":{"product_code":"BTC_EUR","state":"RUNNING","timestamp":"2021-12-12T23:05:38.3012252Z","tick_id":7240230,"best_bid":44461.19,"best_ask":44479.65,"best_bid_size":0.00118145,"best_ask_size":0.01,"total_bid_depth":14.74728901,"total_ask_depth":13.51312467,"market_bid_size":0.0,"market_ask_size":0.0,"ltp":44461.2,"volume":43.951523900000,"volume_by_product":43.951523900000}}}
1639350338.5241191: {"jsonrpc":"2.0","method":"channelMessage","params":{"channel":"lightning_board_FX_BTC_JPY","message":{"mid_price":5866741.0,"bids":[{"price":5866514.0,"size":0.01},{"price":5863426.0,"size":0.1},{"price":5862893.0,"size":0.0},{"price":5864498.0,"size":0.0},{"price":5864270.0,"size":0.02},{"price":5864401.0,"size":0.15},{"price":5865931.0,"size":0.01},{"price":5862628.0,"size":0.0},{"price":5864598.0,"size":0.0493381},{"price":5860938.0,"size":0.1},{"price":5864510.0,"size":0.0},{"price":5861818.0,"size":0.0},{"price":5863832.0,"size":0.05},{"price":5858356.0,"size":0.02675389},{"price":5865718.0,"size":0.2},{"price":4886338.0,"size":0.08},{"price":5863171.0,"size":0.01},{"price":5843860.0,"size":0.04},{"price":5864504.0,"size":0.04867766},{"price":5863622.0,"size":0.05},{"price":5864422.0,"size":0.0},{"price":5853566.0,"size":0.0},{"price":5861082.0,"size":0.02},{"price":5858347.0,"size":0.02}],"asks":[{"price":5867162.0,"size":0.0},{"price":5894965.0,"size":0.01},{"price":5894969.0,"size":0.02675389},{"price":5869603.0,"size":0.1},{"price":5870876.0,"size":0.05},{"price":5873698.0,"size":0.5}]}}}
1639350338.5315871: {"jsonrpc":"2.0","method":"channelMessage","params":{"channel":"lightning_board_BTC_EUR","message":{"mid_price":44470.42,"bids":[],"asks":[{"price":44590.97,"size":0.056}]}}}
1639350338.546429: {"jsonrpc":"2.0","method":"channelMessage","params":{"channel":"lightning_ticker_BTC_USD","message":{"product_code":"BTC_USD","state":"RUNNING","timestamp":"2021-12-12T23:05:38.4029875Z","tick_id":17932897,"best_bid":50273.32,"best_ask":50316.83,"best_bid_size":0.6003,"best_ask_size":0.01,"total_bid_depth":27.57365669,"total_ask_depth":20.89270412,"market_bid_size":0.0,"market_ask_size":0.0,"ltp":50278.04,"volume":250.100018300000,"volume_by_product":250.100018300000}}}
1639350338.551968: {"jsonrpc":"2.0","method":"channelMessage","params":{"channel":"lightning_board_BTC_USD","message":{"mid_price":50295.07,"bids":[{"price":49812.28,"size":0.0},{"price":49892.75,"size":0.0},{"price":49563.45,"size":0.0},{"price":49482.99,"size":0.0},{"price":49852.51,"size":0.0}],"asks":[{"price":51025.45,"size":0.41},{"price":50318.6,"size":0.0},{"price":50777.95,"size":0.0},{"price":50697.48,"size":0.0},{"price":50737.72,"size":0.0}]}}}
1639350338.6081102: {"jsonrpc":"2.0","method":"channelMessage","params":{"channel":"lightning_ticker_XLM_JPY","message":{"product_code":"XLM_JPY","state":"RUNNING","timestamp":"2021-12-12T23:05:38.3870614Z","tick_id":8300564,"best_bid":31.485,"best_ask":31.557,"best_bid_size":2553.74,"best_ask_size":978.2,"total_bid_depth":1858801.59493760,"total_ask_depth":2115939.427473400000,"market_bid_size":0.0,"market_ask_size":0.0,"ltp":31.471,"volume":1471420.073424000000,"volume_by_product":1471420.073424000000}}}
1639350338.6128: {"jsonrpc":"2.0","method":"channelMessage","params":{"channel":"lightning_board_XLM_JPY","message":{"mid_price":31.521,"bids":[{"price":31.452,"size":0.0}],"asks":[]}}}
1639350338.6171362: {"jsonrpc":"2.0","method":"channelMessage","params":{"channel":"lightning_ticker_XRP_JPY","message":{"product_code":"XRP_JPY","state":"RUNNING","timestamp":"2021-12-12T23:05:38.3870614Z","tick_id":12284628,"best_bid":95.96,"best_ask":96.13,"best_bid_size":775.5,"best_ask_size":49.479871,"total_bid_depth":1529264.08922300,"total_ask_depth":2310446.181293000000,"market_bid_size":0.0,"market_ask_size":0.0,"ltp":95.96,"volume":1653279.685708000000,"volume_by_product":1653279.685708000000}}}
1639350338.620695: {"jsonrpc":"2.0","method":"channelMessage","params":{"channel":"lightning_board_XRP_JPY","message":{"mid_price":96.04,"bids":[{"price":95.68,"size":0.0}],"asks":[]}}}
1639350338.640736: {"jsonrpc":"2.0","method":"channelMessage","params":{"channel":"lightning_board_FX_BTC_JPY","message":{"mid_price":5866741.0,"bids":[{"price":5863032.0,"size":0.0},{"price":5860418.0,"size":0.02852248},{"price":5835949.0,"size":0.04},{"price":5863745.0,"size":0.12},{"price":5864468.0,"size":0.02}],"asks":[{"price":5870086.0,"size":0.05},{"price":5889305.0,"size":0.0},{"price":5869877.0,"size":0.04964016}]}}}
1639350338.730428: {"jsonrpc":"2.0","method":"channelMessage","params":{"channel":"lightning_board_XLM_JPY","message":{"mid_price":31.525,"bids":[{"price":31.493,"size":3757.0}],"asks":[]}}}
1639350338.739698: {"jsonrpc":"2.0","method":"channelMessage","params":{"channel":"lightning_board_BTC_EUR","message":{"mid_price":44470.42,"bids":[{"price":44236.98,"size":0.0}],"asks":[{"price":44707.41,"size":0.18}]}}}
1639350338.753543: {"jsonrpc":"2.0","method":"channelMessage","params":{"channel":"lightning_ticker_FX_BTC_JPY","message":{"product_code":"FX_BTC_JPY","state":"RUNNING","timestamp":"2021-12-12T23:05:38.5730279Z","tick_id":127091075,"best_bid":5866514.0,"best_ask":5866968.0,"best_bid_size":0.01,"best_ask_size":0.01,"total_bid_depth":231.205954860000,"total_ask_depth":293.662533990000,"market_bid_size":0.0,"market_ask_size":0.0,"ltp":5865990.0,"volume":4227.199644050000,"volume_by_product":4227.199644050000}}}
1639350338.753648: {"jsonrpc":"2.0","method":"channelMessage","params":{"channel":"lightning_ticker_ETH_JPY","message":{"product_code":"ETH_JPY","state":"RUNNING","timestamp":"2021-12-12T23:05:38.5589527Z","tick_id":26934550,"best_bid":471722.0,"best_ask":472000.0,"best_bid_size":0.576,"best_ask_size":0.02,"total_bid_depth":3295.017367900000,"total_ask_depth":4428.23757320,"market_bid_size":0.0,"market_ask_size":0.0,"ltp":471800.0,"volume":10833.520505500000,"volume_by_product":10833.520505500000}}}
1639350338.755688: {"jsonrpc":"2.0","method":"channelMessage","params":{"channel":"lightning_board_FX_BTC_JPY","message":{"mid_price":5866741.0,"bids":[{"price":5865403.0,"size":0.09389884},{"price":5847015.0,"size":0.0},{"price":5862887.0,"size":0.0},{"price":5865405.0,"size":0.23165908},{"price":5864058.0,"size":0.01},{"price":5862873.0,"size":0.0},{"price":5844914.0,"size":0.05}],"asks":[{"price":5869999.0,"size":0.12},{"price":5874362.0,"size":0.0}]}}}
1639350338.7619: {"jsonrpc":"2.0","method":"channelMessage","params":{"channel":"lightning_board_ETH_JPY","message":{"mid_price":471861.0,"bids":[{"price":470880.0,"size":0.0}],"asks":[{"price":472154.0,"size":0.75}]}}}
1639350338.877238: {"jsonrpc":"2.0","method":"channelMessage","params":{"channel":"lightning_board_FX_BTC_JPY","message":{"mid_price":5866741.0,"bids":[{"price":5834599.0,"size":0.0},{"price":5855804.0,"size":0.0},{"price":5860402.0,"size":0.02852248},{"price":5865728.0,"size":0.1542}],"asks":[{"price":5877672.0,"size":0.02},{"price":5881046.0,"size":0.05},{"price":5879827.0,"size":0.02}]}}}
1639350338.979079: {"jsonrpc":"2.0","method":"channelMessage","params":{"channel":"lightning_board_FX_BTC_JPY","message":{"mid_price":5866741.0,"bids":[{"price":5864304.0,"size":0.0},{"price":5676882.0,"size":0.116},{"price":5865728.0,"size":0.0},{"price":5858360.0,"size":0.01},{"price":5847844.0,"size":0.05},{"price":5864401.0,"size":0.0},{"price":5863719.0,"size":0.02}],"asks":[{"price":5879294.0,"size":0.02}]}}}
1639350338.985413: {"jsonrpc":"2.0","method":"channelMessage","params":{"channel":"lightning_executions_FX_BTC_JPY","message":[{"id":2284079839,"side":"SELL","price":5866514.0,"size":0.01,"exec_date":"2021-12-12T23:05:38.8755051Z","buy_child_order_acceptance_id":"JRF20211212-230538-077039","sell_child_order_acceptance_id":"JRF20211212-230538-214528"}]}}
1639350339.088248: {"jsonrpc":"2.0","method":"channelMessage","params":{"channel":"lightning_board_FX_BTC_JPY","message":{"mid_price":5866449.0,"bids":[{"price":5862266.0,"size":0.02},{"price":5866514.0,"size":0.0}],"asks":[]}}}
1639350339.171286: {"jsonrpc":"2.0","method":"channelMessage","params":{"channel":"lightning_executions_FX_BTC_JPY","message":[{"id":2284079840,"side":"SELL","price":5865931.0,"size":0.01,"exec_date":"2021-12-12T23:05:39.0371271Z","buy_child_order_acceptance_id":"JRF20211212-230538-124888","sell_child_order_acceptance_id":"JRF20211212-230538-081771"},{"id":2284079841,"side":"SELL","price":5865727.0,"size":0.01,"exec_date":"2021-12-12T23:05:39.0371271Z","buy_child_order_acceptance_id":"JRF20211212-230538-212594","sell_child_order_acceptance_id":"JRF20211212-230538-001807"}]}}
1639350339.191305: {"jsonrpc":"2.0","method":"channelMessage","params":{"channel":"lightning_board_FX_BTC_JPY","message":{"mid_price":5866347.0,"bids":[{"price":5865717.0,"size":0.0},{"price":5864599.0,"size":0.1514},{"price":5855872.0,"size":0.0},{"price":5859378.0,"size":0.1},{"price":5863633.0,"size":0.1},{"price":5865931.0,"size":0.0},{"price":5865727.0,"size":0.02}],"asks":[{"price":5867903.0,"size":0.01},{"price":5892192.0,"size":0.0},{"price":5878113.0,"size":0.05},{"price":5872491.0,"size":0.02},{"price":5870199.0,"size":0.01},{"price":5868296.0,"size":0.1523}]}}}
1639350339.293501: {"jsonrpc":"2.0","method":"channelMessage","params":{"channel":"lightning_ticker_FX_BTC_JPY","message":{"product_code":"FX_BTC_JPY","state":"RUNNING","timestamp":"2021-12-12T23:05:39.1772253Z","tick_id":127091109,"best_bid":5865727.0,"best_ask":5865800.0,"best_bid_size":0.02,"best_ask_size":0.01,"total_bid_depth":231.530877340000,"total_ask_depth":294.024833990000,"market_bid_size":0.0,"market_ask_size":0.0,"ltp":5865727.0,"volume":4227.229644050000,"volume_by_product":4227.229644050000}}}
1639350339.29667: {"jsonrpc":"2.0","method":"channelMessage","params":{"channel":"lightning_board_FX_BTC_JPY","message":{"mid_price":5865763.0,"bids":[{"price":5860328.0,"size":0.0},{"price":5858373.0,"size":0.0267539}],"asks":[{"price":5865800.0,"size":0.01},{"price":5895572.0,"size":0.0267539}]}}}
1639350339.311241: {"jsonrpc":"2.0","method":"channelMessage","params":{"channel":"lightning_executions_FX_BTC_JPY","message":[{"id":2284079842,"side":"SELL","price":5865727.0,"size":0.01,"exec_date":"2021-12-12T23:05:39.1772253Z","buy_child_order_acceptance_id":"JRF20211212-230538-212594","sell_child_order_acceptance_id":"JRF20211212-230539-180012"},{"id":2284079843,"side":"SELL","price":5865727.0,"size":0.01,"exec_date":"2021-12-12T23:05:39.1802237Z","buy_child_order_acceptance_id":"JRF20211212-230538-212594","sell_child_order_acceptance_id":"JRF20211212-230539-118625"}]}}
1639350339.369909: {"jsonrpc":"2.0","method":"channelMessage","params":{"channel":"lightning_executions_FX_BTC_JPY","message":[{"id":2284079844,"side":"BUY","price":5865800.0,"size":0.01,"exec_date":"2021-12-12T23:05:39.1812271Z","buy_child_order_acceptance_id":"JRF20211212-230538-180011","sell_child_order_acceptance_id":"JRF20211212-230538-161212"},{"id":2284079845,"side":"SELL","price":5865718.0,"size":0.01,"exec_date":"2021-12-12T23:05:39.1842255Z","buy_child_order_acceptance_id":"JRF20211212-230538-208795","sell_child_order_acceptance_id":"JRF20211212-230538-081770"}]}}
1639350339.4301178: {"jsonrpc":"2.0","method":"channelMessage","params":{"channel":"lightning_board_FX_BTC_JPY","message":{"mid_price":5866343.0,"bids":[{"price":5865727.0,"size":0.0},{"price":5850774.0,"size":0.05},{"price":5858210.0,"size":0.0},{"price":5865718.0,"size":0.19},{"price":5855874.0,"size":0.0},{"price":5859147.0,"size":0.0},{"price":5862627.0,"size":0.01}],"asks":[{"price":5865800.0,"size":0.0},{"price":5868261.0,"size":0.011},{"price":5892190.0,"size":0.0},{"price":5871448.0,"size":0.02846307},{"price":5875180.0,"size":0.05}]}}}
1639350339.548464: {"jsonrpc":"2.0","method":"channelMessage","params":{"channel":"lightning_board_FX_BTC_JPY","message":{"mid_price":5866347.0,"bids":[{"price":5864474.0,"size":0.01},{"price":3855938.0,"size":0.16},{"price":5865718.0,"size":0.0},{"price":5865727.0,"size":0.02},{"price":5863497.0,"size":0.0},{"price":5864011.0,"size":0.0},{"price":5858375.0,"size":0.01},{"price":5863347.0,"size":0.011}],"asks":[{"price":5866967.0,"size":0.2},{"price":5871448.0,"size":0.0},{"price":5895570.0,"size":0.01}]}}}
1639350339.6220858: {"jsonrpc":"2.0","method":"channelMessage","params":{"channel":"lightning_executions_FX_BTC_JPY","message":[{"id":2284079846,"side":"SELL","price":5865727.0,"size":0.02,"exec_date":"2021-12-12T23:05:39.4983389Z","buy_child_order_acceptance_id":"JRF20211212-230539-220149","sell_child_order_acceptance_id":"JRF20211212-230539-217289"}]}}
1639350339.665897: {"jsonrpc":"2.0","method":"channelMessage","params":{"channel":"lightning_board_FX_BTC_JPY","message":{"mid_price":5866790.0,"bids":[{"price":5813693.0,"size":0.0},{"price":5865727.0,"size":0.02},{"price":5865059.0,"size":0.0},{"price":5861533.0,"size":0.0},{"price":5866614.0,"size":0.02},{"price":5863913.0,"size":0.05},{"price":5857138.0,"size":0.0},{"price":5865728.0,"size":0.2}],"asks":[{"price":5901600.0,"size":0.0},{"price":5868514.0,"size":0.0},{"price":5870784.0,"size":0.0}]}}}
1639350339.784616: {"jsonrpc":"2.0","method":"channelMessage","params":{"channel":"lightning_board_FX_BTC_JPY","message":{"mid_price":5866790.0,"bids":[{"price":5861082.0,"size":0.0},{"price":5851924.0,"size":0.02},{"price":5858341.0,"size":0.0},{"price":5858345.0,"size":0.0},{"price":5860194.0,"size":0.0},{"price":5863309.0,"size":0.01}],"asks":[{"price":5872675.0,"size":0.0},{"price":5869073.0,"size":0.05},{"price":5892180.0,"size":0.0},{"price":5879933.0,"size":0.0},{"price":5893075.0,"size":0.04},{"price":5879730.0,"size":0.02},{"price":5895560.0,"size":0.02675395}]}}}
1639350339.898546: {"jsonrpc":"2.0","method":"channelMessage","params":{"channel":"lightning_ticker_FX_BTC_JPY","message":{"product_code":"FX_BTC_JPY","state":"RUNNING","timestamp":"2021-12-12T23:05:39.698427Z","tick_id":127091160,"best_bid":5866614.0,"best_ask":5866967.000000,"best_bid_size":0.02,"best_ask_size":0.200000,"total_bid_depth":231.819123870000,"total_ask_depth":294.203691310000,"market_bid_size":0.0,"market_ask_size":0.0,"ltp":5865727.0,"volume":4227.279644050000,"volume_by_product":4227.279644050000}}}
1639350339.90055: {"jsonrpc":"2.0","method":"channelMessage","params":{"channel":"lightning_board_FX_BTC_JPY","message":{"mid_price":5866790.0,"bids":[{"price":5496882.0,"size":0.174},{"price":5858385.0,"size":0.02675395}],"asks":[]}}}
1639350339.9318788: {"jsonrpc":"2.0","method":"channelMessage","params":{"channel":"lightning_executions_FX_BTC_JPY","message":[{"id":2284079847,"side":"SELL","price":5866614.0,"size":0.02,"exec_date":"2021-12-12T23:05:39.8167203Z","buy_child_order_acceptance_id":"JRF20211212-230539-211413","sell_child_order_acceptance_id":"JRF20211212-230539-122278"}]}}
1639350340.017098: {"jsonrpc":"2.0","method":"channelMessage","params":{"channel":"lightning_board_FX_BTC_JPY","message":{"mid_price":5866347.0,"bids":[{"price":5861074.0,"size":0.02},{"price":5838334.0,"size":0.04},{"price":5858389.0,"size":0.02675347},{"price":5866614.0,"size":0.0},{"price":5860887.0,"size":0.04},{"price":5864144.0,"size":0.02},{"price":5862394.0,"size":0.0}],"asks":[{"price":5866966.0,"size":0.2},{"price":5895556.0,"size":0.02675347},{"price":5872676.0,"size":0.0},{"price":5869019.0,"size":0.0}]}}}
1639350340.222425: {"jsonrpc":"2.0","method":"channelMessage","params":{"channel":"lightning_board_FX_BTC_JPY","message":{"mid_price":5866336.0,"bids":[{"price":5863388.0,"size":0.01}],"asks":[{"price":5874951.0,"size":0.04},{"price":5870668.0,"size":0.02},{"price":5866945.0,"size":0.011}]}}}
1639350340.365261: {"jsonrpc":"2.0","method":"channelMessage","params":{"channel":"lightning_board_FX_BTC_JPY","message":{"mid_price":5866336.0,"bids":[{"price":5853290.0,"size":0.0},{"price":5855883.0,"size":0.0},{"price":5859060.0,"size":0.0},{"price":5863786.0,"size":0.02},{"price":5865728.0,"size":0.0},{"price":5858398.0,"size":0.02675298},{"price":5864059.0,"size":0.02}],"asks":[{"price":5867038.0,"size":0.0},{"price":5868296.0,"size":0.0},{"price":5892181.0,"size":0.0},{"price":5867902.0,"size":0.1706},{"price":5866968.0,"size":0.0},{"price":5895547.0,"size":0.02675298}]}}}
1639350340.4786172: {"jsonrpc":"2.0","method":"channelMessage","params":{"channel":"lightning_ticker_FX_BTC_JPY","message":{"product_code":"FX_BTC_JPY","state":"RUNNING","timestamp":"2021-12-12T23:05:40.2637386Z","tick_id":127091190,"best_bid":5865727.0,"best_ask":5866945.0,"best_bid_size":0.02,"best_ask_size":0.011,"total_bid_depth":231.755877340000,"total_ask_depth":294.461281710000,"market_bid_size":0.0,"market_ask_size":0.0,"ltp":5866614.0,"volume":4227.299644050000,"volume_by_product":4227.299644050000}}}
1639350340.479847: {"jsonrpc":"2.0","method":"channelMessage","params":{"channel":"lightning_board_FX_BTC_JPY","message":{"mid_price":5866336.0,"bids":[{"price":5859959.0,"size":0.01}],"asks":[{"price":5873654.0,"size":0.01}]}}}
1639350340.5929222: {"jsonrpc":"2.0","method":"channelMessage","params":{"channel":"lightning_executions_FX_BTC_JPY","message":[{"id":2284079848,"side":"SELL","price":5865727.0,"size":0.02,"exec_date":"2021-12-12T23:05:40.4806186Z","buy_child_order_acceptance_id":"JRF20211212-230539-203089","sell_child_order_acceptance_id":"JRF20211212-230540-204613"}]}}
1639350340.603798: {"jsonrpc":"2.0","method":"channelMessage","params":{"channel":"lightning_board_FX_BTC_JPY","message":{"mid_price":5866336.0,"bids":[{"price":5864599.0,"size":0.0},{"price":5847363.0,"size":0.0},{"price":5840363.0,"size":0.0},{"price":5833363.0,"size":0.0},{"price":5819363.0,"size":0.0},{"price":5805363.0,"size":0.0},{"price":5791363.0,"size":0.0},{"price":5770363.0,"size":0.0},{"price":5742363.0,"size":0.0},{"price":5707363.0,"size":0.0},{"price":5672363.0,"size":0.0},{"price":5630363.0,"size":0.0},{"price":5581363.0,"size":0.0},{"price":5532363.0,"size":0.0},{"price":5469363.0,"size":0.0},{"price":5406363.0,"size":0.0},{"price":5343363.0,"size":0.0},{"price":5863914.0,"size":0.02},{"price":5864504.0,"size":0.0},{"price":5864271.0,"size":0.131},{"price":5863495.0,"size":0.0},{"price":5863496.0,"size":0.0},{"price":5863760.0,"size":0.0},{"price":5864598.0,"size":0.0}],"asks":[{"price":5867549.0,"size":0.04},{"price":5870224.0,"size":0.01},{"price":5869420.0,"size":0.02},{"price":5868261.0,"size":0.0}]}}}
1639350340.684893: {"jsonrpc":"2.0","method":"channelMessage","params":{"channel":"lightning_executions_FX_BTC_JPY","message":[{"id":2284079849,"side":"SELL","price":5865403.0,"size":0.02034737,"exec_date":"2021-12-12T23:05:40.5656398Z","buy_child_order_acceptance_id":"JRF20211212-230538-124891","sell_child_order_acceptance_id":"JRF20211212-230540-210137"},{"id":2284079850,"side":"SELL","price":5865403.0,"size":0.05067543,"exec_date":"2021-12-12T23:05:40.5656398Z","buy_child_order_acceptance_id":"JRF20211212-230538-124891","sell_child_order_acceptance_id":"JRF20211212-230540-218917"}]}}
1639350340.7381618: {"jsonrpc":"2.0","method":"channelMessage","params":{"channel":"lightning_board_FX_BTC_JPY","message":{"mid_price":5865404.0,"bids":[{"price":5862800.0,"size":0.0},{"price":5863622.0,"size":0.0},{"price":5863832.0,"size":0.0},{"price":5864271.0,"size":0.0},{"price":5865727.0,"size":0.0},{"price":5864474.0,"size":0.0},{"price":5860597.0,"size":0.0},{"price":5865405.0,"size":0.0},{"price":5860938.0,"size":0.0},{"price":5863745.0,"size":0.0},{"price":5864543.0,"size":0.0},{"price":5863426.0,"size":0.0},{"price":5863913.0,"size":0.0},{"price":5860726.0,"size":0.0},{"price":5863497.0,"size":0.04},{"price":5865403.0,"size":0.02287604},{"price":5861217.0,"size":0.02846307}],"asks":[{"price":5867549.0,"size":0.0},{"price":5867902.0,"size":0.0},{"price":5875484.0,"size":0.01},{"price":5869007.0,"size":0.0},{"price":5865818.0,"size":0.01},{"price":5870077.0,"size":0.0},{"price":5871868.0,"size":0.02852248},{"price":5869877.0,"size":0.0},{"price":5870876.0,"size":0.0},{"price":5865405.0,"size":0.04480675},{"price":5869999.0,"size":0.0},{"price":5865618.0,"size":0.02},{"price":5869603.0,"size":0.0},{"price":5869073.0,"size":0.0},{"price":5866944.0,"size":0.04}]}}}
1639350340.939432: {"jsonrpc":"2.0","method":"channelMessage","params":{"channel":"lightning_board_FX_BTC_JPY","message":{"mid_price":5864936.0,"bids":[{"price":5865403.0,"size":0.0},{"price":5136882.0,"size":0.29},{"price":5862731.0,"size":0.0},{"price":5863576.0,"size":0.0493381},{"price":5863625.0,"size":0.06644039},{"price":5862390.0,"size":0.05},{"price":5863633.0,"size":0.0},{"price":5862113.0,"size":0.0},{"price":5859378.0,"size":0.0},{"price":5859683.0,"size":0.05},{"price":5863043.0,"size":0.05},{"price":5848456.0,"size":0.0}],"asks":[{"price":5866965.0,"size":0.1656},{"price":5866924.0,"size":0.02},{"price":5870086.0,"size":0.0},{"price":5865405.0,"size":0.03619673},{"price":5866614.0,"size":0.02},{"price":5866945.0,"size":0.031},{"price":5869538.0,"size":0.0},{"price":5869613.0,"size":0.1},{"price":5871841.0,"size":0.0},{"price":5867284.0,"size":0.011},{"price":5877672.0,"size":0.0},{"price":5867315.0,"size":0.04946442}]}}}
1639350341.0483751: {"jsonrpc":"2.0","method":"channelMessage","params":{"channel":"lightning_ticker_FX_BTC_JPY","message":{"product_code":"FX_BTC_JPY","state":"RUNNING","timestamp":"2021-12-12T23:05:40.8366969Z","tick_id":127091291,"best_bid":5864468.0,"best_ask":5865818.0,"best_bid_size":0.02,"best_ask_size":0.01,"total_bid_depth":230.172778690000,"total_ask_depth":294.407641550000,"market_bid_size":0.0,"market_ask_size":0.0,"ltp":5865403.0,"volume":4227.390666850000,"volume_by_product":4227.390666850000}}}
1639350341.053548: {"jsonrpc":"2.0","method":"channelMessage","params":{"channel":"lightning_board_FX_BTC_JPY","message":{"mid_price":5865143.0,"bids":[{"price":5863623.0,"size":0.0},{"price":5862264.0,"size":0.05},{"price":5862134.0,"size":0.12},{"price":5862529.0,"size":0.05},{"price":5862043.0,"size":0.1}],"asks":[{"price":5867903.0,"size":0.0},{"price":5871868.0,"size":0.0},{"price":5866956.0,"size":0.011},{"price":5866944.0,"size":0.24},{"price":5865618.0,"size":0.0},{"price":5869453.0,"size":0.05},{"price":5868752.0,"size":0.05},{"price":5865405.0,"size":0.0}]}}}
1639350341.145409: {"jsonrpc":"2.0","method":"channelMessage","params":{"channel":"lightning_executions_FX_BTC_JPY","message":[{"id":2284079851,"side":"SELL","price":5864468.0,"size":0.02,"exec_date":"2021-12-12T23:05:41.0009905Z","buy_child_order_acceptance_id":"JRF20211212-230538-217287","sell_child_order_acceptance_id":"JRF20211212-230540-086969"}]}}
1639350341.1849291: {"jsonrpc":"2.0","method":"channelMessage","params":{"channel":"lightning_board_FX_BTC_JPY","message":{"mid_price":5864748.0,"bids":[{"price":5862732.0,"size":0.0},{"price":5862069.0,"size":0.05},{"price":5862064.0,"size":0.1},{"price":5861430.0,"size":0.05},{"price":5861074.0,"size":0.0},{"price":5858347.0,"size":0.0},{"price":5852602.0,"size":0.0},{"price":5864468.0,"size":0.0},{"price":5852009.0,"size":0.02}],"asks":[{"price":5870952.0,"size":0.02860168},{"price":5867385.0,"size":0.05},{"price":5867134.0,"size":0.02233224},{"price":5867975.0,"size":0.04964016},{"price":5872138.0,"size":0.1},{"price":5868113.0,"size":0.1},{"price":5868204.0,"size":0.12},{"price":5867127.0,"size":0.15101835},{"price":5874448.0,"size":0.0},{"price":5865096.0,"size":0.02287604},{"price":5868139.0,"size":0.05},{"price":5868248.0,"size":0.05},{"price":5866965.0,"size":0.0}]}}}
1639350341.29647: {"jsonrpc":"2.0","method":"channelMessage","params":{"channel":"lightning_board_FX_BTC_JPY","message":{"mid_price":5864714.0,"bids":[{"price":5863497.0,"size":0.0},{"price":5858351.0,"size":0.0},{"price":5864400.0,"size":0.0}],"asks":[{"price":5866944.0,"size":0.2},{"price":5865159.0,"size":0.01},{"price":5865096.0,"size":0.0},{"price":5866945.0,"size":0.02},{"price":5894974.0,"size":0.0}]}}}
1639350341.338088: {"jsonrpc":"2.0","method":"channelMessage","params":{"channel":"lightning_ticker_ETH_JPY","message":{"product_code":"ETH_JPY","state":"RUNNING","timestamp":"2021-12-12T23:05:41.2332243Z","tick_id":26934551,"best_bid":471722.0,"best_ask":472000.0,"best_bid_size":0.576,"best_ask_size":0.02,"total_bid_depth":3295.767367900000,"total_ask_depth":4428.23757320,"market_bid_size":0.0,"market_ask_size":0.0,"ltp":471800.0,"volume":10833.520505500000,"volume_by_product":10833.520505500000}}}
1639350341.338191: {"jsonrpc":"2.0","method":"channelMessage","params":{"channel":"lightning_board_ETH_JPY","message":{"mid_price":471861.0,"bids":[{"price":471721.0,"size":1.4}],"asks":[]}}}
1639350341.447551: {"jsonrpc":"2.0","method":"channelMessage","params":{"channel":"lightning_executions_FX_BTC_JPY","message":[{"id":2284079852,"side":"SELL","price":5864270.0,"size":0.02,"exec_date":"2021-12-12T23:05:41.1842852Z","buy_child_order_acceptance_id":"JRF20211212-230538-196545","sell_child_order_acceptance_id":"JRF20211212-230540-207911"},{"id":2284079853,"side":"SELL","price":5864144.0,"size":0.02,"exec_date":"2021-12-12T23:05:41.1842852Z","buy_child_order_acceptance_id":"JRF20211212-230539-122277","sell_child_order_acceptance_id":"JRF20211212-230540-207911"},{"id":2284079854,"side":"SELL","price":5864059.0,"size":0.02,"exec_date":"2021-12-12T23:05:41.1842852Z","buy_child_order_acceptance_id":"JRF20211212-230540-001808","sell_child_order_acceptance_id":"JRF20211212-230540-207911"},{"id":2284079855,"side":"SELL","price":5864058.0,"size":0.01,"exec_date":"2021-12-12T23:05:41.1842852Z","buy_child_order_acceptance_id":"JRF20211212-230538-217286","sell_child_order_acceptance_id":"JRF20211212-230540-207911"},{"id":2284079856,"side":"SELL","price":5863914.0,"size":0.02,"exec_date":"2021-12-12T23:05:41.1842852Z","buy_child_order_acceptance_id":"JRF20211212-230540-118626","sell_child_order_acceptance_id":"JRF20211212-230540-207911"},{"id":2284079857,"side":"SELL","price":5863786.0,"size":0.02,"exec_date":"2021-12-12T23:05:41.1892733Z","buy_child_order_acceptance_id":"JRF20211212-230539-219059","sell_child_order_acceptance_id":"JRF20211212-230540-220152"}]}}
1639350341.483283: {"jsonrpc":"2.0","method":"channelMessage","params":{"channel":"lightning_board_FX_BTC_JPY","message":{"mid_price":5864439.0,"bids":[{"price":5864270.0,"size":0.0},{"price":5864144.0,"size":0.0},{"price":5864059.0,"size":0.0},{"price":5864058.0,"size":0.0},{"price":5863914.0,"size":0.0},{"price":5853722.0,"size":0.058},{"price":5860300.0,"size":0.0},{"price":5863786.0,"size":0.0}],"asks":[]}}}
1639350341.5114272: {"jsonrpc":"2.0","method":"channelMessage","params":{"channel":"lightning_executions_FX_BTC_JPY","message":[{"id":2284079858,"side":"SELL","price":5863719.0,"size":0.02,"exec_date":"2021-12-12T23:05:41.1912926Z","buy_child_order_acceptance_id":"JRF20211212-230538-203085","sell_child_order_acceptance_id":"JRF20211212-230540-219063"},{"id":2284079859,"side":"SELL","price":5863625.0,"size":0.02,"exec_date":"2021-12-12T23:05:41.1912926Z","buy_child_order_acceptance_id":"JRF20211212-230540-218920","sell_child_order_acceptance_id":"JRF20211212-230540-219063"}]}}
1639350341.581027: {"jsonrpc":"2.0","method":"channelMessage","params":{"channel":"lightning_board_snapshot_BCH_BTC","message":{"mid_price":0.00921,"bids":[{"price":0.006,"size":2.0},{"price":0.0073,"size":0.1},{"price":0.0074,"size":0.1},{"price":0.0075,"size":0.1},{"price":0.00756,"size":0.29502},{"price":0.0076,"size":0.1},{"price":0.0077,"size":0.1},{"price":0.00775,"size":0.1},{"price":0.0078,"size":0.1},{"price":0.0079,"size":0.1},{"price":0.008,"size":0.1},{"price":0.0081,"size":0.1},{"price":0.00811,"size":10.0},{"price":0.0082,"size":0.1},{"price":0.0083,"size":0.1},{"price":0.0084,"size":0.0214},{"price":0.00844,"size":0.75},{"price":0.0085,"size":0.01},{"price":0.00852,"size":0.01},{"price":0.00853,"size":20.0},{"price":0.00854,"size":0.01},{"price":0.00856,"size":0.01},{"price":0.00858,"size":0.01},{"price":0.0086,"size":0.01},{"price":0.00862,"size":0.01},{"price":0.00864,"size":0.01},{"price":0.00866,"size":0.01},{"price":0.00868,"size":0.01},{"price":0.0087,"size":0.01},{"price":0.00872,"size":0.01},{"price":0.00874,"size":0.01},{"price":0.00876,"size":0.01},{"price":0.00878,"size":0.01},{"price":0.0088,"size":0.01},{"price":0.00882,"size":0.01},{"price":0.00884,"size":0.01},{"price":0.00885,"size":0.026},{"price":0.00886,"size":0.01},{"price":0.00888,"size":10.01},{"price":0.0089,"size":0.11},{"price":0.00892,"size":0.01},{"price":0.00894,"size":0.01},{"price":0.00896,"size":0.01},{"price":0.00898,"size":2.51},{"price":0.009,"size":0.23},{"price":0.00905,"size":0.1},{"price":0.00907,"size":17.918142},{"price":0.00908,"size":8.7},{"price":0.00912,"size":10.3},{"price":0.00916,"size":25.1},{"price":0.00918,"size":2.4},{"price":0.00919,"size":0.9}],"asks":[{"price":0.00923,"size":0.9},{"price":0.00924,"size":2.4},{"price":0.00928,"size":25.7},{"price":0.00936,"size":1.1},{"price":0.00963,"size":0.1},{"price":0.0097,"size":0.96510871},{"price":0.00975,"size":0.01},{"price":0.00976,"size":0.051},{"price":0.0098,"size":1.0},{"price":0.00984,"size":5.0},{"price":0.00985,"size":0.01},{"price":0.0099,"size":0.01},{"price":0.00994,"size":0.05},{"price":0.00995,"size":0.01},{"price":0.01,"size":0.21},{"price":0.01005,"size":0.21},{"price":0.0101,"size":0.21},{"price":0.01015,"size":2.8626601},{"price":0.0102,"size":0.21},{"price":0.01025,"size":0.21},{"price":0.0103,"size":0.21},{"price":0.01035,"size":0.21},{"price":0.01036,"size":0.1},{"price":0.01037,"size":0.1},{"price":0.0104,"size":0.21},{"price":0.01045,"size":0.21},{"price":0.0105,"size":0.21},{"price":0.01055,"size":0.01},{"price":0.0106,"size":0.21},{"price":0.01065,"size":0.01},{"price":0.0107,"size":0.21},{"price":0.01074,"size":0.1},{"price":0.01075,"size":0.01},{"price":0.0108,"size":4.855},{"price":0.01083,"size":0.1},{"price":0.01085,"size":0.01},{"price":0.01088,"size":0.01},{"price":0.0109,"size":0.31},{"price":0.01095,"size":0.01},{"price":0.011,"size":0.22},{"price":0.01105,"size":0.01},{"price":0.0111,"size":0.02},{"price":0.01115,"size":0.01},{"price":0.0112,"size":0.21},{"price":0.0114,"size":0.2},{"price":0.0115,"size":0.2},{"price":0.01156,"size":0.18952},{"price":0.0116,"size":0.2},{"price":0.0118,"size":0.2},{"price":0.012,"size":0.51},{"price":0.0121,"size":0.2},{"price":0.01243,"size":7.56559535},{"price":0.0125,"size":0.5},{"price":0.013,"size":0.51},{"price":0.0135,"size":0.5},{"price":0.014,"size":0.51},{"price":0.01413,"size":3.7},{"price":0.0145,"size":0.5},{"price":0.015,"size":1.14459141},{"price":0.0151,"size":2.0},{"price":0.0155,"size":0.5},{"price":0.016,"size":0.5},{"price":0.0165,"size":0.5},{"price":0.017,"size":0.5},{"price":0.0175,"size":0.5},{"price":0.018,"size":0.51},{"price":0.0185,"size":0.5},{"price":0.01891,"size":0.01},{"price":0.019,"size":0.51},{"price":0.01918,"size":9.96007985},{"price":0.0195,"size":0.5},{"price":0.02,"size":3.68802395}]}}}
1639350341.5816362: {"jsonrpc":"2.0","method":"channelMessage","params":{"channel":"lightning_board_snapshot_BTC_USD","message":{"mid_price":50295.07,"bids":[{"price":30000.0,"size":0.002},{"price":35000.0,"size":0.05},{"price":38000.0,"size":0.1},{"price":40000.0,"size":0.13},{"price":41000.0,"size":0.103},{"price":41250.0,"size":0.003},{"price":41500.0,"size":0.003},{"price":42000.0,"size":0.04},{"price":44000.0,"size":0.01},{"price":44500.0,"size":0.01},{"price":45000.0,"size":0.033},{"price":45500.0,"size":0.01},{"price":46000.0,"size":0.01},{"price":46500.0,"size":0.01},{"price":46725.0,"size":0.10050619},{"price":47237.86,"size":0.89},{"price":47273.37,"size":0.76},{"price":47292.29,"size":1.03},{"price":47311.21,"size":1.19},{"price":48409.37,"size":0.45},{"price":48558.85,"size":1.1},{"price":48707.54,"size":1.0},{"price":48760.6,"size":0.675},{"price":49436.21,"size":0.98},{"price":49470.84,"size":0.78},{"price":49537.48,"size":0.95},{"price":49545.47,"size":0.45},{"price":49557.3,"size":0.96},{"price":49580.78,"size":0.45},{"price":49613.78,"size":1.0},{"price":49651.32,"size":1.0},{"price":49697.15,"size":0.9},{"price":49736.04,"size":0.95},{"price":49737.39,"size":1.115},{"price":49777.63,"size":0.675},{"price":49778.08,"size":0.84},{"price":49822.07,"size":1.26},{"price":49844.95,"size":0.18},{"price":49879.71,"size":0.27},{"price":49937.96,"size":1.0},{"price":50065.72,"size":1.0},{"price":50120.61,"size":0.01},{"price":50165.39,"size":1.29},{"price":50211.42,"size":0.11},{"price":50226.78,"size":0.57},{"price":50229.86,"size":1.0},{"price":50239.86,"size":0.01},{"price":50241.82,"size":0.6003},{"price":50242.43,"size":0.05096228},{"price":50242.45,"size":0.01398398},{"price":50242.46,"size":0.04566142},{"price":50244.89,"size":0.01},{"price":50244.91,"size":0.15066957},{"price":50244.92,"size":0.04197325},{"price":50265.78,"size":0.6003},{"price":50273.32,"size":0.6003}],"asks":[{"price":50316.83,"size":0.01},{"price":50326.15,"size":0.6003},{"price":50373.38,"size":0.07225738},{"price":50373.39,"size":0.02414146},{"price":50413.75,"size":0.5},{"price":50439.82,"size":0.07359133},{"price":50439.83,"size":0.01809059},{"price":50439.84,"size":1.0},{"price":50464.12,"size":1.0},{"price":50514.48,"size":1.0},{"price":50538.23,"size":1.3},{"price":50568.33,"size":2.0},{"price":50623.32,"size":0.01},{"price":50654.37,"size":0.88},{"price":50818.97,"size":0.8},{"price":50823.89,"size":0.675},{"price":50864.13,"size":1.125},{"price":50904.37,"size":0.9},{"price":50977.57,"size":0.9},{"price":51025.45,"size":0.41},{"price":51105.93,"size":0.54},{"price":51248.54,"size":1.1},{"price":51267.89,"size":0.54},{"price":51372.57,"size":0.9},{"price":51394.06,"size":0.79},{"price":51500.0,"size":0.2},{"price":51644.76,"size":0.8},{"price":52000.0,"size":0.03858975},{"price":52191.68,"size":0.892},{"price":54425.0,"size":0.001},{"price":68000.0,"size":1.09211295},{"price":75000.0,"size":0.70062066}]}}}
1639350341.583231: {"jsonrpc":"2.0","method":"channelMessage","params":{"channel":"lightning_ticker_FX_BTC_JPY","message":{"product_code":"FX_BTC_JPY","state":"RUNNING","timestamp":"2021-12-12T23:05:41.3825542Z","tick_id":127091374,"best_bid":5863388.0,"best_ask":5865025.0,"best_bid_size":0.01,"best_ask_size":0.025,"total_bid_depth":229.747446310000,"total_ask_depth":294.128728280000,"market_bid_size":0.0,"market_ask_size":0.0,"ltp":5863625.0,"volume":4227.560666850000,"volume_by_product":4227.560666850000}}}
1639350341.5897229: {"jsonrpc":"2.0","method":"channelMessage","params":{"channel":"lightning_board_snapshot_BTC_EUR","message":{"mid_price":44470.42,"bids":[{"price":27675.2,"size":0.353},{"price":30056.0,"size":0.1},{"price":32312.0,"size":0.062},{"price":35005.0,"size":0.25},{"price":35403.0,"size":0.0565},{"price":38300.0,"size":0.002},{"price":38400.0,"size":0.002},{"price":38500.0,"size":0.002},{"price":38600.0,"size":0.002},{"price":38700.0,"size":0.002},{"price":38800.0,"size":0.002},{"price":38824.29,"size":0.77},{"price":38900.0,"size":0.002},{"price":38981.11,"size":0.0754},{"price":39000.0,"size":0.002},{"price":39001.0,"size":0.2},{"price":39100.0,"size":0.002},{"price":39200.0,"size":0.002},{"price":39300.0,"size":0.002},{"price":39400.0,"size":0.002},{"price":39500.0,"size":0.002},{"price":39600.0,"size":0.002},{"price":39700.0,"size":0.002},{"price":39741.94,"size":1.02},{"price":39800.0,"size":0.002},{"price":39900.0,"size":0.002},{"price":40000.0,"size":0.002},{"price":40100.0,"size":0.002},{"price":40200.0,"size":0.002},{"price":40300.0,"size":0.002},{"price":40400.0,"size":0.004},{"price":40500.0,"size":0.002},{"price":40600.0,"size":0.002},{"price":40688.3,"size":0.7},{"price":40700.0,"size":0.002},{"price":40800.0,"size":0.004},{"price":40900.0,"size":0.002},{"price":40955.0,"size":0.03},{"price":40972.0,"size":0.03},{"price":40981.11,"size":0.03},{"price":41000.0,"size":0.002},{"price":41001.0,"size":0.1},{"price":41100.0,"size":0.002},{"price":41125.0,"size":0.03},{"price":41200.0,"size":0.002},{"price":41300.0,"size":0.002},{"price":41336.84,"size":0.9},{"price":41400.0,"size":0.002},{"price":41500.0,"size":0.002},{"price":41505.0,"size":0.05},{"price":41600.0,"size":0.002},{"price":41700.0,"size":0.002},{"price":41800.0,"size":0.004},{"price":41900.0,"size":0.002},{"price":41949.83,"size":1.2},{"price":42000.0,"size":0.002},{"price":42100.0,"size":0.002},{"price":42200.0,"size":0.002},{"price":42300.0,"size":0.002},{"price":42400.0,"size":0.002},{"price":42500.0,"size":0.002},{"price":42600.0,"size":0.002},{"price":42700.0,"size":0.001},{"price":42786.32,"size":0.18},{"price":42800.0,"size":0.001},{"price":42861.18,"size":1.8},{"price":42900.0,"size":0.001},{"price":43000.0,"size":0.001},{"price":43091.16,"size":1.4},{"price":43100.0,"size":0.001},{"price":43113.73,"size":0.18},{"price":43200.0,"size":0.001},{"price":43300.0,"size":0.001},{"price":43400.0,"size":0.001},{"price":43500.0,"size":0.001},{"price":43558.56,"size":0.8},{"price":43600.0,"size":0.001},{"price":43711.82,"size":1.0},{"price":43904.41,"size":0.18},{"price":44149.97,"size":0.01},{"price":44221.6,"size":0.00107479},{"price":44239.98,"size":0.01},{"price":44248.15,"size":0.00110903},{"price":44274.69,"size":0.00131169},{"price":44300.53,"size":0.18},{"price":44301.29,"size":0.00115867},{"price":44327.9,"size":0.00117149},{"price":44327.91,"size":0.3005332},{"price":44331.57,"size":0.18},{"price":44349.49,"size":0.3},{"price":44354.5,"size":0.00118117},{"price":44354.87,"size":0.18},{"price":44364.3,"size":0.50134},{"price":44381.14,"size":0.00130283},{"price":44383.66,"size":0.50134},{"price":44401.54,"size":0.01},{"price":44405.1,"size":0.1},{"price":44407.34,"size":0.50134},{"price":44407.75,"size":0.00121377},{"price":44417.1,"size":0.01},{"price":44420.67,"size":0.15},{"price":44432.66,"size":0.02},{"price":44434.52,"size":0.00113092},{"price":44461.19,"size":0.00118145}],"asks":[{"price":44479.65,"size":0.01},{"price":44502.49,"size":0.50134},{"price":44514.08,"size":0.1},{"price":44514.55,"size":0.0010134},{"price":44529.65,"size":0.1},{"price":44531.7,"size":0.50134},{"price":44541.28,"size":0.00100978},{"price":44568.0,"size":0.00107131},{"price":44568.32,"size":0.1},{"price":44576.35,"size":0.1574203},{"price":44576.36,"size":0.01},{"price":44583.9,"size":0.01},{"price":44590.97,"size":0.056},{"price":44594.58,"size":0.01},{"price":44594.74,"size":0.00110449},{"price":44621.5,"size":0.00118707},{"price":44648.27,"size":0.00115137},{"price":44661.02,"size":0.19},{"price":44675.06,"size":0.00123005},{"price":44701.87,"size":0.00100114},{"price":44707.41,"size":0.18},{"price":44728.69,"size":0.00125068},{"price":44755.53,"size":0.00100508},{"price":44768.15,"size":0.1},{"price":44863.71,"size":0.74},{"price":44953.12,"size":1.0},{"price":45000.0,"size":0.001},{"price":45200.0,"size":0.001},{"price":45400.0,"size":0.001},{"price":45427.26,"size":0.399},{"price":45427.27,"size":1.1},{"price":45573.78,"size":1.2},{"price":45600.0,"size":0.001},{"price":45800.0,"size":0.001},{"price":45914.15,"size":1.5},{"price":46000.0,"size":0.001},{"price":46200.0,"size":0.001},{"price":46400.0,"size":0.001},{"price":46600.0,"size":0.001},{"price":46777.42,"size":0.94},{"price":46800.0,"size":0.001},{"price":47000.0,"size":1.001},{"price":47200.0,"size":0.001},{"price":47400.0,"size":0.001},{"price":47498.64,"size":0.73},{"price":47600.0,"size":0.001},{"price":47800.0,"size":0.001},{"price":47883.35,"size":0.9},{"price":48000.0,"size":0.001},{"price":48200.0,"size":0.001},{"price":48400.0,"size":0.001},{"price":48600.0,"size":0.001},{"price":48800.0,"size":0.001},{"price":49000.0,"size":0.001},{"price":49073.85,"size":1.09},{"price":49200.0,"size":0.001},{"price":49400.0,"size":0.001},{"price":49600.0,"size":0.001},{"price":49800.0,"size":0.001},{"price":50000.0,"size":0.001},{"price":50157.03,"size":0.98},{"price":50200.0,"size":0.001},{"price":50400.0,"size":0.001},{"price":50600.0,"size":0.001},{"price":50800.0,"size":0.001},{"price":51000.0,"size":0.001},{"price":51200.0,"size":0.002},{"price":51400.0,"size":0.001},{"price":51600.0,"size":0.001},{"price":51800.0,"size":0.001},{"price":52000.0,"size":0.001},{"price":52200.0,"size":0.001},{"price":52400.0,"size":0.001},{"price":52600.0,"size":0.001},{"price":52800.0,"size":0.001},{"price":53000.0,"size":0.001},{"price":53200.0,"size":0.001},{"price":53400.0,"size":0.001},{"price":53600.0,"size":0.001},{"price":53800.0,"size":0.001},{"price":54000.0,"size":0.001},{"price":54200.0,"size":0.001},{"price":54400.0,"size":0.001},{"price":54600.0,"size":0.001},{"price":54800.0,"size":0.001},{"price":55000.0,"size":0.001},{"price":55200.0,"size":0.001},{"price":55400.0,"size":0.001},{"price":55600.0,"size":0.001},{"price":55800.0,"size":0.001},{"price":56000.0,"size":0.001},{"price":56200.0,"size":0.001},{"price":56400.0,"size":0.001},{"price":56600.0,"size":0.001},{"price":56800.0,"size":0.001},{"price":57000.0,"size":0.001},{"price":57200.0,"size":0.001},{"price":57400.0,"size":0.001},{"price":57600.0,"size":0.001},{"price":57800.0,"size":0.001},{"price":59400.0,"size":0.001},{"price":59600.0,"size":0.001},{"price":59800.0,"size":0.001},{"price":60000.0,"size":0.002},{"price":63000.0,"size":0.001},{"price":67200.0,"size":0.001},{"price":67400.0,"size":0.001},{"price":67600.0,"size":0.001},{"price":67800.0,"size":0.001},{"price":68000.0,"size":0.001}]}}}
1639350341.59424: {"jsonrpc":"2.0","method":"channelMessage","params":{"channel":"lightning_board_FX_BTC_JPY","message":{"mid_price":5864206.0,"bids":[{"price":5863719.0,"size":0.0},{"price":5863625.0,"size":0.0},{"price":5862391.0,"size":0.1872},{"price":5862627.0,"size":0.0},{"price":5858404.0,"size":0.02675395},{"price":5861930.0,"size":0.01},{"price":5858356.0,"size":0.0},{"price":5862137.0,"size":0.01},{"price":5862264.0,"size":0.0},{"price":5863043.0,"size":0.0},{"price":5863576.0,"size":0.0},{"price":5862529.0,"size":0.0},{"price":5862134.0,"size":0.0},{"price":5862390.0,"size":0.0},{"price":5862069.0,"size":0.0},{"price":5862043.0,"size":0.0},{"price":5858402.0,"size":0.03}],"asks":[{"price":5869185.0,"size":0.02},{"price":5867127.0,"size":0.0},{"price":5866924.0,"size":0.0},{"price":5873698.0,"size":0.0},{"price":5870884.0,"size":0.02860168},{"price":5867134.0,"size":0.0},{"price":5866613.0,"size":0.1931},{"price":5865817.0,"size":0.0},{"price":5865219.0,"size":0.01},{"price":5872059.0,"size":0.02860168},{"price":5865402.0,"size":0.02},{"price":5893994.0,"size":0.02675395},{"price":5875845.0,"size":0.058},{"price":5878429.0,"size":0.02},{"price":5867956.0,"size":0.01},{"price":5865095.0,"size":0.04},{"price":5894969.0,"size":0.0},{"price":5869613.0,"size":0.0},{"price":5865025.0,"size":0.025},{"price":5867975.0,"size":0.0},{"price":5868752.0,"size":0.0},{"price":5868204.0,"size":0.0},{"price":5867315.0,"size":0.0},{"price":5868113.0,"size":0.0}]}}}
1639350341.6051252: {"jsonrpc":"2.0","method":"channelMessage","params":{"channel":"lightning_board_snapshot_ETH_JPY","message":{"mid_price":471861.0,"bids":[{"price":471722.0,"size":0.576},{"price":471721.0,"size":1.4},{"price":471615.0,"size":0.928},{"price":471614.0,"size":1.38},{"price":471516.0,"size":0.58},{"price":471480.0,"size":0.62},{"price":471380.0,"size":14.99995},{"price":471379.0,"size":1.37},{"price":471317.0,"size":1.0},{"price":471277.0,"size":5.013},{"price":471171.0,"size":0.75},{"price":471156.0,"size":0.75},{"price":471148.0,"size":0.75},{"price":471144.0,"size":0.75},{"price":471123.0,"size":0.75},{"price":471104.0,"size":0.75},{"price":471103.0,"size":0.75},{"price":471094.0,"size":0.75},{"price":470631.0,"size":6.0},{"price":469927.0,"size":0.3},{"price":469833.0,"size":6.08},{"price":469752.0,"size":1.0},{"price":469644.0,"size":0.01},{"price":469614.0,"size":0.18},{"price":469399.0,"size":14.83},{"price":469356.0,"size":1.0},{"price":469336.0,"size":0.7},{"price":469207.0,"size":6.0},{"price":469020.0,"size":0.8},{"price":468944.0,"size":0.1},{"price":468222.0,"size":119.3},{"price":468098.0,"size":0.7},{"price":468017.0,"size":0.99},{"price":468007.0,"size":1.0},{"price":468000.0,"size":1.9},{"price":467941.0,"size":0.05},{"price":467700.0,"size":0.01},{"price":467585.0,"size":0.07},{"price":467526.0,"size":0.01},{"price":467252.0,"size":2.385},{"price":467075.0,"size":0.1},{"price":467074.0,"size":0.43},{"price":467004.0,"size":0.1},{"price":467000.0,"size":0.783},{"price":466501.0,"size":8.0},{"price":466260.0,"size":5.26},{"price":466228.0,"size":0.129},{"price":466100.0,"size":4.33},{"price":466000.0,"size":0.02},{"price":465720.0,"size":2.044312},{"price":465700.0,"size":0.5},{"price":465591.0,"size":58.73},{"price":465555.0,"size":0.7},{"price":465500.0,"size":0.5},{"price":465250.0,"size":0.5},{"price":465181.0,"size":1.33},{"price":465123.0,"size":0.1},{"price":465000.0,"size":9.458},{"price":464979.0,"size":0.01},{"price":464228.0,"size":0.129},{"price":464000.0,"size":0.0202},{"price":463230.0,"size":30.35},{"price":462990.0,"size":0.4},{"price":462500.0,"size":0.51},{"price":462228.0,"size":0.13},{"price":462000.0,"size":0.51},{"price":461000.0,"size":0.51},{"price":460946.0,"size":14.99},{"price":460742.0,"size":0.01},{"price":460724.0,"size":0.01},{"price":460563.0,"size":1.9},{"price":460321.0,"size":0.95},{"price":460250.0,"size":0.5},{"price":460228.0,"size":0.13},{"price":460123.0,"size":0.21},{"price":460111.0,"size":0.1},{"price":460106.0,"size":1.0},{"price":460010.0,"size":0.012},{"price":460000.0,"size":8.686101},{"price":459855.0,"size":0.2},{"price":459740.0,"size":62.247},{"price":459000.0,"size":32.5202},{"price":458819.0,"size":0.89},{"price":458545.0,"size":0.1},{"price":458500.0,"size":0.05},{"price":458228.0,"size":0.131},{"price":458151.0,"size":0.01},{"price":458090.0,"size":1.0},{"price":458000.0,"size":13.06},{"price":457976.0,"size":0.1},{"price":457777.0,"size":0.1},{"price":457500.0,"size":0.51},{"price":457136.0,"size":0.013},{"price":457000.0,"size":4.74},{"price":456870.0,"size":0.01},{"price":456500.0,"size":0.5},{"price":456253.0,"size":0.1},{"price":456243.0,"size":15.44},{"price":456228.0,"size":0.132},{"price":456213.0,"size":0.5},{"price":456100.0,"size":0.030696},{"price":456000.0,"size":1.7907},{"price":455968.0,"size":0.1},{"price":455777.0,"size":0.04},{"price":455507.0,"size":0.01},{"price":455500.0,"size":0.61},{"price":455438.0,"size":0.01},{"price":455250.0,"size":0.5},{"price":455111.0,"size":0.1},{"price":455044.0,"size":0.386},{"price":455000.0,"size":6.0746},{"price":454947.0,"size":1.1},{"price":454900.0,"size":0.05},{"price":454600.0,"size":0.11},{"price":454500.0,"size":0.238},{"price":454485.0,"size":0.01},{"price":454228.0,"size":0.132},{"price":454000.0,"size":15.191629},{"price":453865.0,"size":1.0},{"price":453750.0,"size":0.5},{"price":453610.0,"size":0.1},{"price":453601.0,"size":0.99},{"price":453500.0,"size":0.4},{"price":453492.0,"size":0.14},{"price":453112.0,"size":0.01},{"price":453006.0,"size":0.3},{"price":453003.0,"size":3.640905},{"price":453001.0,"size":8.0},{"price":453000.0,"size":3.4605},{"price":452787.0,"size":0.6747411},{"price":452500.0,"size":0.1204972},{"price":452369.0,"size":0.5},{"price":452244.0,"size":0.030957},{"price":452228.0,"size":0.133},{"price":452112.0,"size":0.01},{"price":452111.0,"size":0.01},{"price":452100.0,"size":0.07},{"price":452000.0,"size":1.854607},{"price":451880.0,"size":0.1},{"price":451820.0,"size":0.3},{"price":451800.0,"size":0.07},{"price":451600.0,"size":1.05},{"price":451555.0,"size":6.0},{"price":451539.0,"size":14.75},{"price":451500.0,"size":0.11},{"price":451250.0,"size":0.11},{"price":451200.0,"size":0.07},{"price":451176.0,"size":0.01},{"price":451111.0,"size":5.01},{"price":451001.0,"size":0.7},{"price":451000.0,"size":0.71},{"price":450900.0,"size":0.1},{"price":450740.0,"size":4.0},{"price":450600.0,"size":0.1},{"price":450500.0,"size":0.02},{"price":450300.0,"size":0.1},{"price":450250.0,"size":0.5},{"price":450228.0,"size":0.133},{"price":450210.0,"size":0.31},{"price":450111.0,"size":0.55},{"price":450106.0,"size":1.0},{"price":450038.0,"size":0.01},{"price":450020.0,"size":5.0},{"price":450010.0,"size":0.4340547},{"price":450008.0,"size":0.05},{"price":450002.0,"size":0.125},{"price":450001.0,"size":0.62697},{"price":450000.0,"size":40.3350369},{"price":449990.0,"size":0.45},{"price":449700.0,"size":0.1},{"price":449580.0,"size":0.1},{"price":449400.0,"size":1.11},{"price":449111.0,"size":0.02},{"price":449100.0,"size":0.1},{"price":449000.0,"size":0.32},{"price":448980.0,"size":0.1},{"price":448900.0,"size":0.5},{"price":448888.0,"size":0.2005},{"price":448800.0,"size":0.1},{"price":448587.0,"size":0.1},{"price":448565.0,"size":0.05},{"price":448500.0,"size":0.15},{"price":448300.0,"size":0.03},{"price":448230.0,"size":0.2},{"price":448228.0,"size":0.134},{"price":448222.0,"size":5.0},{"price":448200.0,"size":0.1},{"price":448111.0,"size":0.01},{"price":448001.0,"size":0.015},{"price":448000.0,"size":11.4566045},{"price":447800.0,"size":0.23},{"price":447700.0,"size":0.031},{"price":447576.0,"size":0.01},{"price":447502.0,"size":0.125},{"price":447500.0,"size":0.03},{"price":447252.0,"size":1.1},{"price":447136.0,"size":0.013},{"price":447111.0,"size":0.01},{"price":447000.0,"size":1.46},{"price":446836.0,"size":14.76},{"price":446543.0,"size":0.53},{"price":446500.0,"size":2.17},{"price":446489.0,"size":1.0},{"price":446400.0,"size":0.3},{"price":446397.0,"size":0.01},{"price":446228.0,"size":0.134},{"price":446111.0,"size":0.04},{"price":446000.0,"size":2.870067},{"price":445973.0,"size":0.1121121},{"price":445900.0,"size":0.01},{"price":445885.0,"size":0.02},{"price":445858.0,"size":0.01},{"price":445700.0,"size":0.01},{"price":445670.0,"size":0.2},{"price":445555.0,"size":1.0},{"price":445525.0,"size":0.012134},{"price":445500.0,"size":1.285},{"price":445451.0,"size":1.0},{"price":445188.0,"size":0.3},{"price":445111.0,"size":0.12},{"price":445088.0,"size":0.2},{"price":445011.0,"size":0.3},{"price":445008.0,"size":0.01},{"price":445002.0,"size":0.125},{"price":445001.0,"size":0.03},{"price":445000.0,"size":9.6017349},{"price":444924.0,"size":0.01},{"price":444900.0,"size":0.06743},{"price":444502.0,"size":0.01},{"price":444500.0,"size":0.25},{"price":444444.0,"size":1.21},{"price":444400.0,"size":0.01},{"price":444309.0,"size":0.01},{"price":444228.0,"size":0.135},{"price":444111.0,"size":0.01},{"price":444050.0,"size":0.017},{"price":444023.0,"size":0.01},{"price":444000.0,"size":7.020865},{"price":443944.0,"size":0.01},{"price":443739.0,"size":1.0},{"price":443502.0,"size":0.01},{"price":443500.0,"size":0.043822},{"price":443400.0,"size":1.0},{"price":443300.0,"size":0.01},{"price":443111.0,"size":0.01},{"price":443002.0,"size":1.0},{"price":443000.0,"size":0.50436},{"price":442921.0,"size":0.01},{"price":442844.0,"size":0.11},{"price":442502.0,"size":0.135},{"price":442500.0,"size":0.05},{"price":442450.0,"size":0.03},{"price":442350.0,"size":0.6},{"price":442258.0,"size":6.0},{"price":442228.0,"size":0.136},{"price":442111.0,"size":0.01},{"price":442000.0,"size":2.3356125},{"price":441888.0,"size":0.1},{"price":441502.0,"size":0.01},{"price":441410.0,"size":1.0},{"price":441249.0,"size":0.01},{"price":441200.0,"size":5.0},{"price":441111.0,"size":1.01},{"price":441100.0,"size":0.3},{"price":441008.0,"size":0.1},{"price":441000.0,"size":22.025},{"price":440888.0,"size":0.2},{"price":440700.0,"size":2.0},{"price":440666.0,"size":0.5},{"price":440603.0,"size":0.01},{"price":440600.0,"size":0.01},{"price":440500.0,"size":0.029},{"price":440228.0,"size":0.136},{"price":440212.0,"size":0.11356},{"price":440139.0,"size":0.2},{"price":440111.0,"size":0.13},{"price":440099.0,"size":0.01},{"price":440088.0,"size":0.3},{"price":440070.0,"size":0.01},{"price":440050.0,"size":0.2},{"price":440010.0,"size":0.01},{"price":440008.0,"size":0.1},{"price":440002.0,"size":0.125},{"price":440001.0,"size":0.1},{"price":440000.0,"size":40.446149},{"price":439999.0,"size":0.1},{"price":439807.0,"size":0.01},{"price":439800.0,"size":0.1},{"price":439500.0,"size":0.05},{"price":439495.0,"size":0.505125},{"price":439157.0,"size":0.10025},{"price":439115.0,"size":1.0},{"price":439111.0,"size":0.03},{"price":439100.0,"size":0.642},{"price":439000.0,"size":8.28319},{"price":438845.0,"size":1.0},{"price":438666.0,"size":0.5},{"price":438598.0,"size":0.01},{"price":438575.0,"size":0.1},{"price":438500.0,"size":0.05}],"asks":[{"price":472000.0,"size":0.02},{"price":472088.0,"size":0.75},{"price":472094.0,"size":0.75},{"price":472154.0,"size":0.75},{"price":472200.0,"size":0.02},{"price":472252.0,"size":0.01},{"price":472360.0,"size":5.013},{"price":472400.0,"size":0.02},{"price":472500.0,"size":0.01},{"price":472600.0,"size":0.02},{"price":472638.0,"size":1.536},{"price":472639.0,"size":0.51},{"price":472696.0,"size":4.202},{"price":472721.0,"size":6.0},{"price":472728.0,"size":0.6},{"price":472752.0,"size":0.01},{"price":472800.0,"size":0.02},{"price":472822.0,"size":0.7},{"price":472900.0,"size":0.013},{"price":472902.0,"size":14.83},{"price":472939.0,"size":6.0},{"price":473000.0,"size":0.33},{"price":473038.0,"size":1.01},{"price":473050.0,"size":0.010613},{"price":473083.0,"size":6.08},{"price":473163.0,"size":0.06},{"price":473200.0,"size":0.02},{"price":473212.0,"size":0.029586},{"price":473252.0,"size":0.01},{"price":473300.0,"size":0.11},{"price":473400.0,"size":0.53},{"price":473473.0,"size":0.2},{"price":473500.0,"size":0.01},{"price":473550.0,"size":0.1050705},{"price":473599.0,"size":0.3005},{"price":473600.0,"size":1.03},{"price":473700.0,"size":0.01},{"price":473718.0,"size":0.5},{"price":473752.0,"size":0.01},{"price":473772.0,"size":0.0146843},{"price":473800.0,"size":0.03},{"price":473900.0,"size":0.01},{"price":473960.0,"size":117.31},{"price":473968.0,"size":0.09},{"price":473997.0,"size":0.01},{"price":474000.0,"size":1.2201},{"price":474051.0,"size":0.57},{"price":474100.0,"size":0.01},{"price":474200.0,"size":0.03},{"price":474300.0,"size":0.01},{"price":474400.0,"size":0.05},{"price":474450.0,"size":0.5},{"price":474500.0,"size":0.02},{"price":474535.0,"size":0.15},{"price":474558.0,"size":0.02},{"price":474600.0,"size":0.03},{"price":474650.0,"size":0.5},{"price":474656.0,"size":0.01},{"price":474700.0,"size":0.01},{"price":474800.0,"size":0.03},{"price":474882.0,"size":0.12},{"price":474888.0,"size":0.1},{"price":474900.0,"size":0.01},{"price":474950.0,"size":0.5},{"price":474997.0,"size":0.21},{"price":475000.0,"size":12.0154268},{"price":475123.0,"size":0.66},{"price":475436.0,"size":0.07},{"price":475457.0,"size":1.0},{"price":475555.0,"size":0.05},{"price":475750.0,"size":0.01},{"price":475880.0,"size":3.0},{"price":475899.0,"size":0.027},{"price":475997.0,"size":0.01},{"price":476000.0,"size":2.2872},{"price":476434.0,"size":1.9626441},{"price":476468.0,"size":0.07},{"price":476600.0,"size":0.1},{"price":476678.0,"size":0.011},{"price":476750.0,"size":0.02},{"price":476800.0,"size":0.1},{"price":476880.0,"size":2.0},{"price":476882.0,"size":0.12},{"price":476997.0,"size":0.51},{"price":477000.0,"size":1.4196},{"price":477011.0,"size":58.97},{"price":477098.0,"size":0.01},{"price":477136.0,"size":0.013},{"price":477179.0,"size":0.07},{"price":477343.0,"size":0.01},{"price":477500.0,"size":0.02},{"price":477777.0,"size":1.0498702},{"price":477880.0,"size":2.0},{"price":477997.0,"size":0.01},{"price":478000.0,"size":2.2186},{"price":478092.0,"size":0.01},{"price":478200.0,"size":0.25},{"price":478343.0,"size":0.01},{"price":478600.0,"size":0.4},{"price":478750.0,"size":0.01},{"price":478800.0,"size":12.1},{"price":478882.0,"size":0.12},{"price":478888.0,"size":9.99},{"price":478900.0,"size":1.5},{"price":478997.0,"size":0.01},{"price":479000.0,"size":1.9},{"price":479198.0,"size":0.01},{"price":479343.0,"size":0.01},{"price":479500.0,"size":51.0976115},{"price":479650.0,"size":0.5},{"price":479750.0,"size":0.02},{"price":479800.0,"size":0.2},{"price":479827.0,"size":29.93},{"price":479837.0,"size":0.01},{"price":479880.0,"size":2.0},{"price":479888.0,"size":0.1},{"price":479996.0,"size":0.2},{"price":479997.0,"size":0.01},{"price":479999.0,"size":0.496919},{"price":480000.0,"size":25.898},{"price":480021.0,"size":10.025},{"price":480038.0,"size":0.02},{"price":480113.0,"size":0.01},{"price":480200.0,"size":0.2},{"price":480250.0,"size":5.0},{"price":480343.0,"size":0.01},{"price":480447.0,"size":4.0},{"price":480480.0,"size":1.0},{"price":480500.0,"size":0.81},{"price":480527.0,"size":0.1},{"price":480680.0,"size":0.4},{"price":480700.0,"size":0.03},{"price":480750.0,"size":0.02},{"price":480800.0,"size":0.1},{"price":480882.0,"size":0.12},{"price":480899.0,"size":0.02},{"price":480990.0,"size":0.013},{"price":480997.0,"size":0.02},{"price":481000.0,"size":5.574676},{"price":481126.0,"size":0.5},{"price":481140.0,"size":0.01},{"price":481200.0,"size":1.0815},{"price":481234.0,"size":0.66},{"price":481239.0,"size":0.1499476},{"price":481351.0,"size":0.011},{"price":481456.0,"size":0.2},{"price":481480.0,"size":1.0},{"price":481500.0,"size":0.5},{"price":481800.0,"size":0.1},{"price":481997.0,"size":0.01},{"price":482000.0,"size":4.669},{"price":482162.0,"size":0.01},{"price":482187.0,"size":15.37},{"price":482222.0,"size":0.4},{"price":482400.0,"size":1.49},{"price":482480.0,"size":1.0},{"price":482500.0,"size":0.01},{"price":482531.0,"size":10.0},{"price":482572.0,"size":0.2},{"price":482750.0,"size":0.02},{"price":482800.0,"size":0.11},{"price":482882.0,"size":0.12},{"price":482997.0,"size":0.01},{"price":483000.0,"size":7.3},{"price":483203.0,"size":5.1},{"price":483300.0,"size":0.5},{"price":483333.0,"size":0.01},{"price":483480.0,"size":1.0},{"price":483500.0,"size":0.01},{"price":483645.0,"size":0.01},{"price":483800.0,"size":0.1},{"price":483997.0,"size":0.01},{"price":484000.0,"size":4.84},{"price":484450.0,"size":0.3},{"price":484480.0,"size":3.0},{"price":484487.0,"size":0.01},{"price":484721.0,"size":0.11},{"price":484800.0,"size":0.2},{"price":484882.0,"size":0.12},{"price":484888.0,"size":0.1},{"price":484901.0,"size":20.0},{"price":484997.0,"size":0.02},{"price":485000.0,"size":33.6485951},{"price":485113.0,"size":0.01},{"price":485322.0,"size":0.0997403},{"price":485480.0,"size":1.0},{"price":485631.0,"size":0.01},{"price":485675.0,"size":0.01},{"price":485678.0,"size":0.5},{"price":485680.0,"size":0.14},{"price":485750.0,"size":0.01},{"price":485800.0,"size":0.1},{"price":485880.0,"size":5.0},{"price":485983.0,"size":20.0},{"price":485997.0,"size":0.01},{"price":486000.0,"size":5.6921733},{"price":486024.0,"size":0.011},{"price":486373.0,"size":0.01},{"price":486438.0,"size":14.75},{"price":486446.0,"size":0.1},{"price":486480.0,"size":1.0},{"price":486500.0,"size":0.01},{"price":486544.0,"size":0.05},{"price":486786.0,"size":0.01},{"price":486800.0,"size":0.1},{"price":486882.0,"size":0.12},{"price":486900.0,"size":0.06},{"price":486901.0,"size":20.0},{"price":486997.0,"size":0.01},{"price":487000.0,"size":2.2},{"price":487136.0,"size":0.013},{"price":487480.0,"size":1.0},{"price":487500.0,"size":0.01},{"price":487600.0,"size":0.05},{"price":487786.0,"size":0.01},{"price":487800.0,"size":1.0},{"price":487950.0,"size":0.04},{"price":487997.0,"size":0.01},{"price":488000.0,"size":0.893282},{"price":488465.0,"size":0.05},{"price":488480.0,"size":1.0},{"price":488600.0,"size":0.5},{"price":488786.0,"size":0.01},{"price":488800.0,"size":0.1},{"price":488880.0,"size":5.0},{"price":488882.0,"size":0.12},{"price":488888.0,"size":11.4321},{"price":488997.0,"size":0.01},{"price":489000.0,"size":18.7607},{"price":489463.0,"size":0.1},{"price":489480.0,"size":1.0},{"price":489500.0,"size":0.01},{"price":489600.0,"size":0.14},{"price":489650.0,"size":0.5},{"price":489786.0,"size":0.01},{"price":489788.0,"size":0.1},{"price":489800.0,"size":0.8},{"price":489840.0,"size":0.01},{"price":489900.0,"size":1.0},{"price":489997.0,"size":0.01},{"price":489999.0,"size":0.1},{"price":490000.0,"size":35.129675},{"price":490001.0,"size":0.2},{"price":490300.0,"size":0.01},{"price":490480.0,"size":1.0},{"price":490698.0,"size":0.011},{"price":490786.0,"size":0.01},{"price":490800.0,"size":0.1},{"price":490882.0,"size":0.12},{"price":490997.0,"size":0.01},{"price":491000.0,"size":8.65},{"price":491160.0,"size":14.78},{"price":491300.0,"size":0.04},{"price":491480.0,"size":1.0},{"price":491786.0,"size":0.01},{"price":491800.0,"size":0.3},{"price":491882.0,"size":0.01},{"price":491997.0,"size":0.01},{"price":491999.0,"size":0.12},{"price":492000.0,"size":2.0017},{"price":492445.0,"size":0.01},{"price":492480.0,"size":1.0},{"price":492500.0,"size":1.05},{"price":492786.0,"size":0.01},{"price":492800.0,"size":0.6},{"price":492882.0,"size":0.12},{"price":492997.0,"size":0.01},{"price":493000.0,"size":9.9},{"price":493341.0,"size":0.1},{"price":493433.0,"size":0.01},{"price":493480.0,"size":1.0},{"price":493493.0,"size":0.2},{"price":493500.0,"size":0.02},{"price":493630.0,"size":0.15},{"price":493786.0,"size":0.01},{"price":493800.0,"size":0.1},{"price":493997.0,"size":0.01},{"price":494000.0,"size":2.43},{"price":494480.0,"size":1.0},{"price":494500.0,"size":0.17},{"price":494882.0,"size":0.12},{"price":494997.0,"size":0.01},{"price":494998.0,"size":0.9581203},{"price":495000.0,"size":47.963267},{"price":495480.0,"size":1.0},{"price":495500.0,"size":0.03},{"price":495572.0,"size":0.01},{"price":495700.0,"size":0.10027},{"price":495883.0,"size":15.33},{"price":495960.0,"size":0.01},{"price":495997.0,"size":0.01},{"price":496000.0,"size":3.439},{"price":496012.0,"size":0.98},{"price":496044.0,"size":0.01},{"price":496300.0,"size":0.01},{"price":496480.0,"size":1.0},{"price":496500.0,"size":0.02},{"price":496600.0,"size":0.04},{"price":496696.0,"size":0.01},{"price":496711.0,"size":0.102}]}}}
