1639350341.613676: {"jsonrpc":"2.0","method":"channelMessage","params":{"channel":"lightning_board_snapshot_XRP_JPY","message":{"mid_price":96.04,"bids":[{"price":95.96,"size":775.5},{"price":95.95,"size":17012.54584},{"price":95.9,"size":10697.0},{"price":95.87,"size":10363.0},{"price":95.84,"size":11356.239},{"price":95.83,"size":9000.0},{"price":95.81,"size":10580.0},{"price":95.6,"size":5070.0},{"price":95.57,"size":13710.0},{"price":95.5,"size":82.934},{"price":95.42,"size":9000.0},{"price":95.4,"size":70.0},{"price":95.36,"size":137270.0},{"price":95.3,"size":5070.0},{"price":95.2,"size":70.0},{"price":95.16,"size":473.0},{"price":95.1,"size":70.0},{"price":95.0,"size":1954.1},{"price":94.9,"size":70.0},{"price":94.8,"size":1889.0},{"price":94.78,"size":53820.0},{"price":94.7,"size":70.0},{"price":94.6,"size":1570.0},{"price":94.5,"size":1072.0},{"price":94.42,"size":13530.0},{"price":94.4,"size":70.0},{"price":94.3,"size":70.0},{"price":94.2,"size":70.0},{"price":94.17,"size":27230.0},{"price":94.1,"size":70.0},{"price":94.0,"size":1677.0},{"price":93.99,"size":15.859},{"price":93.9,"size":70.0},{"price":93.8,"size":80.0},{"price":93.7,"size":70.0},{"price":93.6,"size":70.0},{"price":93.5,"size":74.0},{"price":93.45,"size":70.0},{"price":93.4,"size":87.0},{"price":93.32,"size":5.0},{"price":93.3,"size":70.0},{"price":93.2,"size":70.0},{"price":93.18,"size":3938.63},{"price":93.12,"size":40.0},{"price":93.1,"size":70.0},{"price":93.0,"size":13631.301075},{"price":92.97,"size":13470.0},{"price":92.9,"size":70.0},{"price":92.8,"size":70.0},{"price":92.7,"size":70.0},{"price":92.6,"size":70.0},{"price":92.51,"size":0.2},{"price":92.5,"size":899.0},{"price":92.49,"size":0.11},{"price":92.41,"size":0.2},{"price":92.4,"size":500.0},{"price":92.31,"size":0.2},{"price":92.3,"size":70.0},{"price":92.21,"size":0.2},{"price":92.2,"size":70.0},{"price":92.11,"size":0.2},{"price":92.1,"size":81.4},{"price":92.01,"size":0.2},{"price":92.0,"size":5724.043395},{"price":91.95,"size":0.495},{"price":91.92,"size":100.0},{"price":91.91,"size":0.2},{"price":91.9,"size":70.0},{"price":91.81,"size":0.2},{"price":91.8,"size":2757.0},{"price":91.7,"size":70.0},{"price":91.6,"size":70.0},{"price":91.53,"size":13740.0},{"price":91.5,"size":110.0},{"price":91.4,"size":70.0},{"price":91.3,"size":70.0},{"price":91.2,"size":70.0},{"price":91.1,"size":70.0},{"price":91.0,"size":6164.681318},{"price":90.98,"size":1000.0},{"price":90.92,"size":100.0},{"price":90.9,"size":70.0},{"price":90.8,"size":102.0},{"price":90.7,"size":70.0},{"price":90.6,"size":70.0},{"price":90.53,"size":100.0},{"price":90.5,"size":610.0},{"price":90.4,"size":70.0},{"price":90.3,"size":89.2},{"price":90.2,"size":70.0},{"price":90.19,"size":27.0},{"price":90.1,"size":240.0},{"price":90.01,"size":600.0},{"price":90.0,"size":19541.055555},{"price":89.99,"size":10.0},{"price":89.92,"size":100.0},{"price":89.9,"size":55.0},{"price":89.75,"size":100.0},{"price":89.7,"size":60.0},{"price":89.6,"size":1000.0},{"price":89.5,"size":4570.0},{"price":89.41,"size":500.0},{"price":89.3,"size":100.0},{"price":89.19,"size":300.0},{"price":89.15,"size":207.7},{"price":89.12,"size":2.0},{"price":89.1,"size":50.0},{"price":89.02,"size":300.51},{"price":89.01,"size":1000.0},{"price":89.0,"size":8203.861797},{"price":88.9,"size":405.0},{"price":88.84,"size":60.0},{"price":88.82,"size":112.589},{"price":88.7,"size":22.6},{"price":88.69,"size":1000.0},{"price":88.55,"size":420.0},{"price":88.5,"size":3081.0},{"price":88.29,"size":150.0},{"price":88.15,"size":2500.0},{"price":88.11,"size":156.0},{"price":88.1,"size":50.0},{"price":88.01,"size":1100.0},{"price":88.0,"size":26751.62},{"price":87.9,"size":1105.0},{"price":87.86,"size":500.0},{"price":87.68,"size":400.0},{"price":87.5,"size":4345.0},{"price":87.33,"size":1150.0},{"price":87.2,"size":103.165137},{"price":87.1,"size":50.0},{"price":87.01,"size":1000.0},{"price":87.0,"size":11316.3},{"price":86.95,"size":9200.0},{"price":86.9,"size":105.52},{"price":86.8,"size":200.0},{"price":86.57,"size":10.0},{"price":86.53,"size":1000.0},{"price":86.5,"size":1320.0},{"price":86.4,"size":10.0},{"price":86.17,"size":10.0},{"price":86.16,"size":1000.0},{"price":86.1,"size":3050.0},{"price":86.0,"size":19585.68},{"price":85.91,"size":120.0},{"price":85.9,"size":705.0},{"price":85.88,"size":25.0},{"price":85.69,"size":1000.0},{"price":85.61,"size":50.0},{"price":85.6,"size":1000.0},{"price":85.5,"size":160.0},{"price":85.35,"size":150.0},{"price":85.3,"size":1000.0},{"price":85.29,"size":126.0},{"price":85.25,"size":16550.604105},{"price":85.23,"size":1000.0},{"price":85.2,"size":50.0},{"price":85.11,"size":0.53},{"price":85.1,"size":3950.0},{"price":85.08,"size":10.0},{"price":85.04,"size":25.0},{"price":85.01,"size":600.0},{"price":85.0,"size":75986.705814},{"price":84.89,"size":500.0},{"price":84.85,"size":100.0},{"price":84.83,"size":100.0},{"price":84.82,"size":100.0},{"price":84.81,"size":5.0},{"price":84.72,"size":0.54},{"price":84.7,"size":100.0},{"price":84.6,"size":500.0},{"price":84.54,"size":11.0},{"price":84.5,"size":80.5},{"price":84.28,"size":0.35},{"price":84.12,"size":30.0},{"price":84.1,"size":150.0},{"price":84.0,"size":8231.095108},{"price":83.99,"size":100.0},{"price":83.97,"size":2002.5},{"price":83.85,"size":100.0},{"price":83.5,"size":282.0},{"price":83.33,"size":5.0},{"price":83.3,"size":1000.0},{"price":83.25,"size":300.0},{"price":83.1,"size":2456.7387},{"price":83.0,"size":12219.2},{"price":82.95,"size":100.0},{"price":82.92,"size":10000.0},{"price":82.91,"size":100.0},{"price":82.89,"size":67.0},{"price":82.79,"size":150.0},{"price":82.74,"size":2000.0},{"price":82.62,"size":10000.0},{"price":82.6,"size":1000.0},{"price":82.5,"size":13075.078787},{"price":82.22,"size":11000.0},{"price":82.15,"size":51.0},{"price":82.1,"size":50.0},{"price":82.0,"size":30925.1365},{"price":81.88,"size":30.0},{"price":81.85,"size":100.0},{"price":81.78,"size":0.7},{"price":81.65,"size":65.0},{"price":81.6,"size":1000.0},{"price":81.5,"size":1100.0},{"price":81.4,"size":5000.0},{"price":81.37,"size":24.5912},{"price":81.3,"size":6410.0},{"price":81.2,"size":2281.527},{"price":81.1,"size":550.0},{"price":81.03,"size":1000.0},{"price":81.0,"size":22360.909},{"price":80.99,"size":12.4},{"price":80.96,"size":10.0},{"price":80.95,"size":4000.0},{"price":80.94,"size":125.0},{"price":80.9,"size":911.0},{"price":80.88,"size":50.0},{"price":80.75,"size":100.0},{"price":80.73,"size":1000.0},{"price":80.72,"size":100.0},{"price":80.69,"size":10000.0},{"price":80.6,"size":1152.0},{"price":80.52,"size":500.0},{"price":80.5,"size":4230.0},{"price":80.44,"size":200.0},{"price":80.4,"size":271.0},{"price":80.19,"size":500.0},{"price":80.12,"size":200.0},{"price":80.1,"size":6636.0},{"price":80.09,"size":1000.0},{"price":80.02,"size":3620.0},{"price":80.0,"size":110476.075},{"price":79.9,"size":1500.0},{"price":79.86,"size":100.0},{"price":79.8,"size":3000.0},{"price":79.78,"size":30.0},{"price":79.72,"size":100.0},{"price":79.7,"size":30.0},{"price":79.6,"size":252.0},{"price":79.58,"size":1.0},{"price":79.5,"size":5150.0},{"price":79.4,"size":20.0},{"price":79.2,"size":2000.0},{"price":79.11,"size":150.0},{"price":79.1,"size":325.0},{"price":79.0,"size":4798.42},{"price":78.9,"size":20.0},{"price":78.8,"size":1010.0},{"price":78.72,"size":100.0},{"price":78.5,"size":3000.0},{"price":78.35,"size":50.0},{"price":78.21,"size":255.0},{"price":78.2,"size":8602.11},{"price":78.1,"size":690.0},{"price":78.0,"size":14272.980769},{"price":77.88,"size":1.3},{"price":77.77,"size":890.0},{"price":77.72,"size":100.0},{"price":77.7,"size":400.0},{"price":77.5,"size":3150.0},{"price":77.27,"size":100.0},{"price":77.1,"size":50.0},{"price":77.0,"size":11349.08},{"price":76.8,"size":1500.0},{"price":76.72,"size":100.0},{"price":76.63,"size":655.0},{"price":76.6,"size":500.0},{"price":76.53,"size":190.0},{"price":76.5,"size":3000.0},{"price":76.11,"size":5000.0},{"price":76.1,"size":2050.0},{"price":76.0,"size":6777.42},{"price":75.91,"size":1000.0},{"price":75.88,"size":50.0},{"price":75.79,"size":50.0},{"price":75.78,"size":1.4},{"price":75.72,"size":100.0},{"price":75.6,"size":500.0},{"price":75.52,"size":3000.0},{"price":75.5,"size":7500.0},{"price":75.3,"size":441.0},{"price":75.1,"size":50.0},{"price":75.01,"size":10.0},{"price":75.0,"size":17050.30333},{"price":74.74,"size":5000.0},{"price":74.54,"size":49.0},{"price":74.5,"size":3000.0},{"price":74.4,"size":5000.0},{"price":74.1,"size":50.0},{"price":74.0,"size":418.03},{"price":73.84,"size":30.0},{"price":73.5,"size":3000.0},{"price":73.39,"size":100.0},{"price":73.1,"size":785.0},{"price":73.0,"size":1778.4},{"price":72.9,"size":1.109},{"price":72.5,"size":3000.0},{"price":72.1,"size":50.0},{"price":72.0,"size":11526.78},{"price":71.68,"size":27.901}],"asks":[{"price":96.13,"size":49.479871},{"price":96.22,"size":1550.8},{"price":96.23,"size":5540.0},{"price":96.24,"size":9929.0},{"price":96.26,"size":339.291574},{"price":96.28,"size":9000.0},{"price":96.3,"size":1352.25},{"price":96.33,"size":13710.0},{"price":96.43,"size":139250.0},{"price":96.45,"size":27.65},{"price":96.5,"size":9000.0},{"price":96.6,"size":4000.0},{"price":96.7,"size":4070.0},{"price":96.8,"size":70.0},{"price":96.9,"size":70.0},{"price":96.99,"size":26630.0},{"price":97.0,"size":4451.0},{"price":97.1,"size":70.0},{"price":97.14,"size":5000.0},{"price":97.19,"size":8000.0},{"price":97.2,"size":1070.0},{"price":97.21,"size":5000.0},{"price":97.24,"size":5000.0},{"price":97.3,"size":70.0},{"price":97.34,"size":5000.0},{"price":97.4,"size":70.0},{"price":97.5,"size":1552.1},{"price":97.6,"size":70.0},{"price":97.7,"size":70.0},{"price":97.8,"size":70.0},{"price":97.9,"size":140.0},{"price":98.0,"size":2076.1},{"price":98.1,"size":70.0},{"price":98.2,"size":71.0},{"price":98.25,"size":4.0},{"price":98.3,"size":370.0},{"price":98.4,"size":70.0},{"price":98.48,"size":491.120224},{"price":98.5,"size":6077.1},{"price":98.55,"size":11000.0},{"price":98.7,"size":70.0},{"price":98.75,"size":4.0},{"price":98.8,"size":70.0},{"price":99.0,"size":8878.0},{"price":99.1,"size":70.0},{"price":99.13,"size":30.0},{"price":99.2,"size":70.0},{"price":99.24,"size":500.0},{"price":99.25,"size":4.0},{"price":99.3,"size":70.0},{"price":99.38,"size":14.104},{"price":99.4,"size":80.0},{"price":99.5,"size":4276.0},{"price":99.6,"size":70.0},{"price":99.7,"size":70.0},{"price":99.75,"size":4.0},{"price":99.8,"size":70.0},{"price":99.9,"size":70.0},{"price":99.99,"size":2994.0},{"price":100.0,"size":24347.2616},{"price":100.1,"size":70.0},{"price":100.2,"size":70.0},{"price":100.25,"size":4.0},{"price":100.3,"size":70.0},{"price":100.4,"size":70.0},{"price":100.5,"size":1311.0},{"price":100.6,"size":70.0},{"price":100.7,"size":70.0},{"price":100.75,"size":4.0},{"price":100.8,"size":70.0},{"price":100.9,"size":70.0},{"price":100.99,"size":499.0},{"price":101.0,"size":3108.0},{"price":101.1,"size":70.0},{"price":101.2,"size":70.0},{"price":101.25,"size":4.0},{"price":101.3,"size":70.0},{"price":101.4,"size":70.0},{"price":101.5,"size":77.0},{"price":101.6,"size":70.0},{"price":101.7,"size":70.0},{"price":101.75,"size":4.0},{"price":101.8,"size":70.0},{"price":101.89,"size":5000.0},{"price":101.9,"size":70.0},{"price":102.0,"size":5454.5},{"price":102.1,"size":70.0},{"price":102.2,"size":70.0},{"price":102.25,"size":4.0},{"price":102.3,"size":70.0},{"price":102.4,"size":70.0},{"price":102.5,"size":76.0},{"price":102.6,"size":70.0},{"price":102.7,"size":70.0},{"price":102.75,"size":4.0},{"price":102.8,"size":70.0},{"price":102.84,"size":194.472},{"price":102.9,"size":70.0},{"price":103.0,"size":100817.0},{"price":103.1,"size":70.0},{"price":103.2,"size":90.0},{"price":103.25,"size":4.0},{"price":103.28,"size":100.0},{"price":103.3,"size":660.7},{"price":103.4,"size":70.0},{"price":103.5,"size":106.0},{"price":103.6,"size":70.0},{"price":103.7,"size":100.0},{"price":103.75,"size":4.0},{"price":103.8,"size":70.0},{"price":103.9,"size":70.0},{"price":103.99,"size":499.0},{"price":104.0,"size":5010.0},{"price":104.09,"size":100.0},{"price":104.1,"size":100.0},{"price":104.13,"size":99.7},{"price":104.2,"size":400.0},{"price":104.25,"size":4.0},{"price":104.3,"size":100.0},{"price":104.4,"size":100.0},{"price":104.5,"size":9951.5},{"price":104.6,"size":800.0},{"price":104.61,"size":150.0},{"price":104.7,"size":100.0},{"price":104.75,"size":4.0},{"price":104.8,"size":99.8},{"price":104.9,"size":100.0},{"price":104.96,"size":1000.0},{"price":104.97,"size":1500.0},{"price":105.0,"size":28525.4381},{"price":105.02,"size":5652.0},{"price":105.1,"size":110.0},{"price":105.2,"size":100.0},{"price":105.25,"size":4.0},{"price":105.3,"size":100.0},{"price":105.31,"size":9.85},{"price":105.4,"size":100.0},{"price":105.46,"size":3795.0},{"price":105.5,"size":4700.7},{"price":105.55,"size":100.1},{"price":105.6,"size":100.0},{"price":105.7,"size":100.0},{"price":105.75,"size":4.0},{"price":105.78,"size":100.0},{"price":105.8,"size":2110.000001},{"price":105.98,"size":13000.0},{"price":105.99,"size":499.0},{"price":106.0,"size":12467.0},{"price":106.12,"size":9.8},{"price":106.25,"size":4.0},{"price":106.3,"size":11000.0},{"price":106.33,"size":49.2},{"price":106.5,"size":6.0},{"price":106.75,"size":4.0},{"price":107.0,"size":2167.0},{"price":107.25,"size":4.0},{"price":107.27,"size":100.0},{"price":107.5,"size":6.0},{"price":107.61,"size":21.3836},{"price":107.75,"size":4.0},{"price":108.0,"size":6991.67948},{"price":108.01,"size":6.491},{"price":108.2,"size":100.0},{"price":108.25,"size":4.0},{"price":108.5,"size":6.0},{"price":108.75,"size":4.0},{"price":108.96,"size":1389.050949},{"price":109.0,"size":3091.0},{"price":109.09,"size":1.0},{"price":109.1,"size":80.0},{"price":109.25,"size":4.0},{"price":109.5,"size":7.0},{"price":109.75,"size":4.0},{"price":109.9,"size":10.0},{"price":109.98,"size":29.0},{"price":110.0,"size":12253.7},{"price":110.11,"size":156.0},{"price":110.25,"size":4.0},{"price":110.5,"size":182.0},{"price":110.56,"size":218.95096},{"price":110.75,"size":4.0},{"price":110.99,"size":998.0},{"price":111.0,"size":3085.0},{"price":111.1,"size":5000.0},{"price":111.25,"size":4.0},{"price":111.5,"size":4.0},{"price":111.75,"size":4.0},{"price":112.0,"size":1720.892764},{"price":112.2,"size":49.2},{"price":112.25,"size":4.0},{"price":112.5,"size":1104.0},{"price":112.75,"size":4.0},{"price":112.8,"size":400.0},{"price":112.82,"size":49.2},{"price":112.9,"size":1000.0},{"price":113.0,"size":1774.0},{"price":113.25,"size":4.0},{"price":113.3,"size":699.0},{"price":113.5,"size":4.0},{"price":113.54,"size":17900.0},{"price":113.71,"size":49.2},{"price":113.75,"size":4.0},{"price":113.8,"size":100.0},{"price":114.0,"size":10698.410537},{"price":114.25,"size":4.0},{"price":114.4,"size":55.0},{"price":114.5,"size":104.0},{"price":114.75,"size":4.0},{"price":114.8,"size":1612.07},{"price":114.93,"size":49.2},{"price":115.0,"size":9176.5},{"price":115.05,"size":497.0009},{"price":115.1,"size":579.76036},{"price":115.15,"size":500.0},{"price":115.2,"size":3010.0},{"price":115.25,"size":504.0},{"price":115.3,"size":800.0},{"price":115.35,"size":500.0},{"price":115.4,"size":500.0},{"price":115.45,"size":500.0},{"price":115.5,"size":3404.0},{"price":115.6,"size":800.0},{"price":115.63,"size":49.2},{"price":115.7,"size":500.0},{"price":115.75,"size":4.0},{"price":115.78,"size":155.0},{"price":115.8,"size":500.0},{"price":115.87,"size":1000.0},{"price":115.9,"size":500.0},{"price":116.0,"size":3244.645},{"price":116.1,"size":500.0},{"price":116.11,"size":500.0},{"price":116.14,"size":500.0},{"price":116.15,"size":500.0},{"price":116.18,"size":500.0},{"price":116.2,"size":500.0},{"price":116.21,"size":500.0},{"price":116.24,"size":500.0},{"price":116.25,"size":504.0},{"price":116.28,"size":500.0},{"price":116.29,"size":500.0},{"price":116.3,"size":3827.0},{"price":116.31,"size":500.0},{"price":116.34,"size":500.0},{"price":116.35,"size":500.0},{"price":116.4,"size":500.0},{"price":116.44,"size":500.0},{"price":116.47,"size":1000.0},{"price":116.5,"size":606.0},{"price":116.54,"size":500.0},{"price":116.6,"size":500.0},{"price":116.64,"size":500.0},{"price":116.7,"size":501.0},{"price":116.74,"size":500.0},{"price":116.75,"size":4.0},{"price":116.8,"size":500.0},{"price":116.84,"size":500.0},{"price":116.88,"size":29.5},{"price":116.9,"size":500.0},{"price":116.94,"size":500.0},{"price":117.0,"size":2740.0},{"price":117.1,"size":500.0},{"price":117.2,"size":1505.0},{"price":117.25,"size":4.0},{"price":117.3,"size":34865.0},{"price":117.33,"size":29.5},{"price":117.4,"size":500.0},{"price":117.5,"size":966.0},{"price":117.6,"size":500.0},{"price":117.7,"size":545.0},{"price":117.75,"size":4.0},{"price":117.8,"size":500.0},{"price":117.9,"size":500.0},{"price":118.0,"size":4151.4},{"price":118.1,"size":500.0},{"price":118.12,"size":500.0},{"price":118.2,"size":500.0},{"price":118.22,"size":500.0},{"price":118.25,"size":4.0},{"price":118.3,"size":500.0},{"price":118.32,"size":500.0},{"price":118.4,"size":500.0},{"price":118.42,"size":500.0},{"price":118.5,"size":651.0},{"price":118.52,"size":500.0},{"price":118.6,"size":500.0},{"price":118.62,"size":500.0},{"price":118.7,"size":500.0},{"price":118.72,"size":750.0},{"price":118.75,"size":4.0},{"price":118.8,"size":500.0},{"price":118.82,"size":500.0},{"price":118.9,"size":820.0},{"price":118.92,"size":500.0},{"price":119.0,"size":11856.0},{"price":119.2,"size":2600.0},{"price":119.25,"size":4.0},{"price":119.48,"size":50.0},{"price":119.49,"size":654.5},{"price":119.5,"size":6.0}]}}}
1639350341.6219342: {"jsonrpc":"2.0","method":"channelMessage","params":{"channel":"lightning_board_snapshot_MONA_JPY","message":{"mid_price":166.009,"bids":[{"price":83.5,"size":10.0},{"price":84.0,"size":10.0},{"price":84.1,"size":10.0},{"price":84.3,"size":10.0},{"price":84.5,"size":10.0},{"price":90.0,"size":100.0},{"price":93.572,"size":21.3836},{"price":94.4,"size":10.0},{"price":100.0,"size":733.94},{"price":101.0,"size":80.0},{"price":104.0,"size":60.0},{"price":105.0,"size":10.0},{"price":107.61,"size":18.5945},{"price":108.11,"size":10.0},{"price":110.0,"size":5.0},{"price":112.011,"size":30.0},{"price":120.0,"size":51.1},{"price":121.0,"size":150.0},{"price":123.75,"size":16.1691},{"price":125.0,"size":573.0},{"price":125.911,"size":30.0},{"price":126.27,"size":100.0},{"price":127.0,"size":150.0},{"price":128.0,"size":800.0},{"price":130.0,"size":1468.2},{"price":130.1,"size":5.0},{"price":131.0,"size":150.0},{"price":132.0,"size":321.0},{"price":135.0,"size":150.0},{"price":137.0,"size":350.0},{"price":139.0,"size":40.0},{"price":139.6,"size":10.0},{"price":139.811,"size":30.0},{"price":140.0,"size":2846.1},{"price":140.183,"size":28.535},{"price":141.1,"size":2510.0},{"price":141.4,"size":10.0},{"price":142.311,"size":14.0601},{"price":142.537,"size":140.0},{"price":145.0,"size":10.0},{"price":146.0,"size":20.0},{"price":146.1,"size":2000.0},{"price":147.0,"size":370.85714285},{"price":148.0,"size":769.0},{"price":149.0,"size":9.0},{"price":149.3,"size":50.0},{"price":149.36,"size":14.2},{"price":149.4,"size":24.18684765},{"price":149.8,"size":120.0},{"price":149.9,"size":50.0},{"price":150.0,"size":1582.63333},{"price":151.0,"size":258.1},{"price":151.1,"size":2000.0},{"price":152.0,"size":28.1},{"price":153.0,"size":458.1},{"price":153.65,"size":10.0},{"price":153.772,"size":2446.0},{"price":154.0,"size":8.1},{"price":154.524,"size":1.0014},{"price":155.0,"size":3925.10450676},{"price":155.06,"size":2489.0},{"price":155.2,"size":50.0},{"price":155.3,"size":4000.0},{"price":155.311,"size":69.51},{"price":156.0,"size":578.3},{"price":156.1,"size":1500.0},{"price":156.4,"size":10.0},{"price":157.0,"size":99.1},{"price":158.0,"size":221.1},{"price":158.375,"size":126.0},{"price":158.5,"size":30.0},{"price":158.628,"size":2472.0},{"price":158.879,"size":1000.0},{"price":159.0,"size":552.158},{"price":160.0,"size":5968.3525},{"price":160.039,"size":11.0},{"price":160.5,"size":10.0},{"price":160.545,"size":50.0},{"price":160.577,"size":4923.0},{"price":160.639,"size":30.0},{"price":161.0,"size":1460.2},{"price":161.1,"size":8461.71687854},{"price":161.2,"size":5.0},{"price":161.245,"size":2400.0},{"price":161.392,"size":9754.0},{"price":161.4,"size":5.0},{"price":161.6,"size":5.0},{"price":161.8,"size":683.0},{"price":162.0,"size":305.24691358},{"price":162.2,"size":5.0},{"price":162.207,"size":25175.0},{"price":162.4,"size":5.0},{"price":162.6,"size":5.0},{"price":162.8,"size":5.0},{"price":162.835,"size":2506.0},{"price":162.901,"size":964.0},{"price":163.0,"size":977.73337133},{"price":163.001,"size":10.0},{"price":163.14,"size":6.0},{"price":163.2,"size":5.0},{"price":163.4,"size":5.0},{"price":163.6,"size":5.0},{"price":163.8,"size":5.0},{"price":163.86,"size":1000.0},{"price":164.0,"size":399.5068536},{"price":164.02,"size":0.1},{"price":165.0,"size":206.93939393},{"price":165.002,"size":0.11515011},{"price":165.02,"size":500.0000002},{"price":165.021,"size":98.0}],"asks":[{"price":166.998,"size":0.80479767},{"price":166.999,"size":98.0},{"price":167.0,"size":161.0},{"price":167.5,"size":4.09152951},{"price":167.656,"size":566.0},{"price":167.784,"size":23.841},{"price":168.0,"size":311.5},{"price":168.179,"size":11.0},{"price":168.49,"size":83.3},{"price":168.839,"size":1000.0},{"price":169.0,"size":307.99},{"price":170.0,"size":315.0},{"price":170.2,"size":5.0},{"price":170.4,"size":5.0},{"price":170.6,"size":5.0},{"price":170.8,"size":5.0},{"price":170.999,"size":100.0},{"price":171.0,"size":415.0},{"price":171.2,"size":5.0},{"price":171.4,"size":5.0},{"price":171.6,"size":5.0},{"price":171.8,"size":5.0},{"price":171.999,"size":53.9},{"price":172.0,"size":515.0},{"price":172.2,"size":5.0},{"price":172.4,"size":5.0},{"price":172.6,"size":5.0},{"price":172.8,"size":5.0},{"price":173.0,"size":446.92},{"price":173.2,"size":5.0},{"price":173.4,"size":5.0},{"price":173.6,"size":5.0},{"price":173.8,"size":5.0},{"price":173.82,"size":1000.0},{"price":173.997,"size":7589.25902325},{"price":174.0,"size":1562.23062369},{"price":174.1,"size":199.7},{"price":174.2,"size":5.0},{"price":174.4,"size":5.0},{"price":174.6,"size":5.0},{"price":174.8,"size":5.0},{"price":174.9,"size":99.74},{"price":174.99,"size":730.0},{"price":175.0,"size":617.0},{"price":175.2,"size":5.0},{"price":175.4,"size":5.0},{"price":175.584,"size":4.9},{"price":175.6,"size":5.0},{"price":175.8,"size":5.0},{"price":176.0,"size":2532.5},{"price":176.2,"size":5.0},{"price":176.4,"size":5.0},{"price":176.6,"size":5.0},{"price":176.607,"size":4.9},{"price":176.8,"size":5.0},{"price":177.0,"size":365.0},{"price":177.2,"size":5.0},{"price":177.4,"size":5.0},{"price":177.6,"size":5.0},{"price":177.8,"size":5.0},{"price":178.0,"size":126.5},{"price":178.2,"size":5.0},{"price":178.4,"size":5.0},{"price":178.5,"size":2.238},{"price":178.6,"size":5.0},{"price":178.8,"size":5.0},{"price":179.0,"size":465.0},{"price":179.2,"size":5.0},{"price":179.4,"size":5.0},{"price":179.6,"size":5.0},{"price":179.7,"size":124.2},{"price":179.8,"size":5.0},{"price":180.0,"size":21159.143985},{"price":180.2,"size":5.0},{"price":180.4,"size":5.0},{"price":180.6,"size":5.0},{"price":180.8,"size":5.0},{"price":181.0,"size":165.0},{"price":181.2,"size":5.0},{"price":181.4,"size":5.0},{"price":181.6,"size":5.0},{"price":181.8,"size":5.0},{"price":182.0,"size":65.0},{"price":182.2,"size":5.0},{"price":182.4,"size":5.0},{"price":182.6,"size":5.0},{"price":182.8,"size":5.0},{"price":183.0,"size":365.0},{"price":183.2,"size":5.0},{"price":183.4,"size":5.0},{"price":183.6,"size":5.0},{"price":183.8,"size":5.0},{"price":184.0,"size":65.0},{"price":184.2,"size":5.0},{"price":184.4,"size":5.0},{"price":184.6,"size":5.0},{"price":184.8,"size":5.0},{"price":185.0,"size":1624.85618696},{"price":185.01,"size":5.87639265},{"price":185.2,"size":5.0},{"price":185.4,"size":5.0},{"price":185.6,"size":5.0},{"price":185.8,"size":5.0},{"price":186.0,"size":306.5},{"price":186.8,"size":5.0},{"price":187.0,"size":415.0},{"price":187.2,"size":5.0},{"price":187.4,"size":5.0},{"price":187.425,"size":1.0},{"price":187.6,"size":5.0},{"price":187.8,"size":5.0},{"price":188.0,"size":315.0},{"price":188.2,"size":5.0},{"price":188.211,"size":12.2262},{"price":188.4,"size":5.0},{"price":188.6,"size":5.0},{"price":188.8,"size":5.0},{"price":188.999,"size":50.0},{"price":189.0,"size":3582.0},{"price":189.2,"size":5.0},{"price":189.4,"size":5.0},{"price":189.6,"size":5.0},{"price":189.8,"size":5.0},{"price":189.999,"size":50.0},{"price":190.0,"size":674.96230901},{"price":190.2,"size":5.0},{"price":190.4,"size":5.0},{"price":190.6,"size":5.0},{"price":190.8,"size":5.0},{"price":190.999,"size":19.0},{"price":191.0,"size":415.0},{"price":191.113,"size":9.99},{"price":191.2,"size":5.0},{"price":191.4,"size":5.0},{"price":191.6,"size":5.0},{"price":191.8,"size":5.0},{"price":191.999,"size":50.0},{"price":192.0,"size":815.0},{"price":192.2,"size":5.0},{"price":192.4,"size":5.0},{"price":192.6,"size":5.0},{"price":192.747,"size":20.0},{"price":192.8,"size":5.0},{"price":192.999,"size":50.0},{"price":193.0,"size":465.75789053},{"price":193.2,"size":5.0},{"price":193.4,"size":5.0},{"price":193.6,"size":5.0},{"price":193.8,"size":5.0},{"price":193.999,"size":50.0},{"price":194.0,"size":325.5},{"price":194.2,"size":5.0},{"price":194.4,"size":5.0},{"price":194.6,"size":5.0},{"price":194.8,"size":5.0},{"price":194.999,"size":50.0},{"price":195.0,"size":1386.2},{"price":195.2,"size":5.0},{"price":195.4,"size":5.0},{"price":195.6,"size":5.0},{"price":195.8,"size":5.0},{"price":195.999,"size":50.0},{"price":196.0,"size":315.0},{"price":196.2,"size":5.0},{"price":196.4,"size":5.0},{"price":196.6,"size":5.0},{"price":196.8,"size":6.01474},{"price":196.999,"size":50.0},{"price":197.0,"size":1934.64296797},{"price":197.2,"size":5.0},{"price":197.4,"size":5.0},{"price":197.6,"size":5.0},{"price":197.8,"size":5.0},{"price":198.0,"size":516.6},{"price":199.0,"size":2042.88},{"price":199.2,"size":5.0},{"price":199.4,"size":5.0},{"price":199.5,"size":497.0},{"price":199.6,"size":5.0},{"price":199.8,"size":5.0},{"price":200.0,"size":1667.42438504},{"price":200.109,"size":4.9},{"price":200.2,"size":5.0},{"price":200.4,"size":5.0},{"price":200.8,"size":5.0},{"price":200.897,"size":50.0},{"price":201.0,"size":280.2},{"price":201.2,"size":5.0},{"price":201.4,"size":5.0},{"price":201.6,"size":5.0},{"price":201.8,"size":5.0},{"price":202.0,"size":325.2},{"price":202.2,"size":5.0},{"price":202.4,"size":5.0},{"price":202.6,"size":5.0},{"price":202.8,"size":5.0},{"price":203.0,"size":115.2},{"price":203.2,"size":5.0},{"price":203.6,"size":20.0},{"price":203.66,"size":270.0},{"price":204.0,"size":359.50071915},{"price":204.8,"size":8156.68824317},{"price":205.0,"size":33869.616},{"price":205.275,"size":200.0},{"price":206.0,"size":348.5607011},{"price":206.8,"size":10.0},{"price":207.0,"size":130.91515376},{"price":208.0,"size":329.2},{"price":209.0,"size":169.2},{"price":209.811,"size":26.5101},{"price":210.0,"size":5122.1978011},{"price":210.03,"size":994.0},{"price":211.0,"size":2270.42259506},{"price":211.167,"size":226.0},{"price":211.7,"size":10.0},{"price":212.0,"size":570.2},{"price":212.134,"size":0.985},{"price":213.0,"size":207.52986169},{"price":214.0,"size":3288.55795542},{"price":214.8,"size":1000.0},{"price":215.0,"size":1753.04052022},{"price":215.1,"size":299.28079113},{"price":216.0,"size":2265.1},{"price":216.3,"size":50.0},{"price":216.444,"size":10.6314},{"price":216.972,"size":1.0},{"price":216.998,"size":100.0},{"price":217.0,"size":1983.1},{"price":217.5,"size":5.0},{"price":218.0,"size":461.6},{"price":218.4,"size":5.0},{"price":219.0,"size":360.1},{"price":220.0,"size":9229.57604492},{"price":221.0,"size":33.1},{"price":222.0,"size":514.82664685},{"price":222.2,"size":45.0},{"price":222.222,"size":150.0},{"price":222.5,"size":5.0},{"price":223.0,"size":735.77279265},{"price":224.0,"size":135.1},{"price":224.01,"size":500.0},{"price":225.0,"size":3214.4},{"price":225.009,"size":300.0},{"price":225.17,"size":50.0},{"price":226.0,"size":114.1},{"price":226.8,"size":15.0},{"price":227.0,"size":50.1},{"price":227.5,"size":5.0},{"price":228.0,"size":43.1},{"price":229.0,"size":50.1},{"price":229.8,"size":10.0},{"price":230.0,"size":1975.239331},{"price":230.1,"size":110.0},{"price":231.86,"size":2.26},{"price":235.0,"size":317.0},{"price":235.4,"size":43.35581731},{"price":237.0,"size":6.0},{"price":239.0,"size":2998.0},{"price":239.899,"size":15.0},{"price":240.0,"size":999.4},{"price":240.1,"size":290.0},{"price":245.0,"size":605.0},{"price":245.009,"size":300.0},{"price":248.0,"size":219.0},{"price":248.911,"size":9.2447},{"price":250.0,"size":4097.79714313},{"price":253.0,"size":5.0},{"price":255.0,"size":205.0},{"price":257.0,"size":50.0},{"price":260.0,"size":220.5},{"price":264.0,"size":200.0},{"price":265.0,"size":5.0},{"price":268.0,"size":100.0},{"price":270.0,"size":573.56},{"price":273.0,"size":199.5},{"price":275.0,"size":27.0},{"price":279.0,"size":200.0},{"price":280.0,"size":1310.8},{"price":285.0,"size":5.0},{"price":286.25,"size":8.0389},{"price":289.91,"size":1.59648246},{"price":290.0,"size":110.7},{"price":292.0,"size":42.5},{"price":295.0,"size":10.1},{"price":298.0,"size":200.0},{"price":299.0,"size":200.0},{"price":300.0,"size":1637.62059002},{"price":301.0,"size":58.22738048},{"price":302.0,"size":30.0},{"price":305.0,"size":5.1},{"price":310.0,"size":1105.9},{"price":312.0,"size":6.0},{"price":315.0,"size":22.0},{"price":317.0,"size":5.0},{"price":320.0,"size":110.1},{"price":321.0,"size":100.0},{"price":325.0,"size":5.0},{"price":329.19,"size":6.9903},{"price":330.0,"size":604.0},{"price":332.0,"size":190.0},{"price":335.0,"size":5.0},{"price":338.0,"size":32.68899798},{"price":340.0,"size":58.5},{"price":341.0,"size":34.69794721},{"price":342.0,"size":1000.0},{"price":350.0,"size":1631.8225},{"price":360.0,"size":0.2},{"price":370.0,"size":20.0},{"price":380.0,"size":358.2},{"price":397.0,"size":1841.88271694},{"price":400.0,"size":103.81018981},{"price":435.0,"size":336.55349638}]}}}
1639350341.640578: {"jsonrpc":"2.0","method":"channelMessage","params":{"channel":"lightning_board_snapshot_XLM_JPY","message":{"mid_price":31.525,"bids":[{"price":31.493,"size":3757.0},{"price":31.485,"size":2553.74},{"price":31.484,"size":3739.0},{"price":31.477,"size":3819.0},{"price":31.468,"size":3736.0},{"price":31.456,"size":11880.0},{"price":31.428,"size":8000.0},{"price":31.421,"size":967.9},{"price":31.406,"size":29746.0},{"price":31.4,"size":5.095541},{"price":31.39,"size":905.6},{"price":31.337,"size":8000.0},{"price":31.309,"size":295826.89},{"price":31.3,"size":5.111821},{"price":31.256,"size":749.85},{"price":31.2,"size":5.128205},{"price":31.123,"size":192.79},{"price":31.117,"size":90.7},{"price":31.1,"size":5.144694},{"price":31.098,"size":120.9},{"price":31.068,"size":123727.0},{"price":31.045,"size":10.0},{"price":31.02,"size":59219.0},{"price":31.0,"size":31497.5846143},{"price":30.973,"size":108.5},{"price":30.9,"size":30.0},{"price":30.841,"size":107.1},{"price":30.8,"size":4040.0},{"price":30.776,"size":29819.0},{"price":30.7,"size":20.0},{"price":30.623,"size":113.2},{"price":30.622,"size":30308.0},{"price":30.61,"size":300.0},{"price":30.6,"size":40.0},{"price":30.526,"size":113.4},{"price":30.502,"size":116.3},{"price":30.5,"size":20610.425295},{"price":30.4,"size":40.0},{"price":30.395,"size":197.41},{"price":30.3,"size":20.0},{"price":30.297,"size":115.8},{"price":30.266,"size":0.7},{"price":30.2,"size":65.99337},{"price":30.145,"size":31034.0},{"price":30.1,"size":20.0},{"price":30.096,"size":0.7},{"price":30.015,"size":200.0},{"price":30.01,"size":2002.0},{"price":30.0,"size":3179.5263666},{"price":29.911,"size":1.0},{"price":29.9,"size":5020.0},{"price":29.888,"size":1000.0},{"price":29.8,"size":11030.0},{"price":29.79,"size":14358.2410204},{"price":29.74,"size":300.0},{"price":29.7,"size":41.838},{"price":29.6,"size":30.0},{"price":29.548,"size":200.0},{"price":29.5,"size":31075.6279661},{"price":29.4,"size":21.9588},{"price":29.301,"size":10.0},{"price":29.3,"size":7027.04},{"price":29.215,"size":100.0},{"price":29.2,"size":10.0},{"price":29.11,"size":8.0},{"price":29.1,"size":5958.5082168},{"price":29.038,"size":206.63},{"price":29.03,"size":550.0},{"price":29.01,"size":2000.0},{"price":29.008,"size":1.1095801},{"price":29.0,"size":21688.199987},{"price":28.999,"size":0.73},{"price":28.98,"size":30.0},{"price":28.9,"size":10.0},{"price":28.896,"size":10.0},{"price":28.895,"size":2000.0},{"price":28.888,"size":1100.0},{"price":28.88,"size":150.0},{"price":28.8,"size":5032.208},{"price":28.75,"size":2000.0},{"price":28.7,"size":2310.0},{"price":28.66,"size":150.0},{"price":28.624,"size":69.903},{"price":28.61,"size":7790.0},{"price":28.6,"size":16220.0},{"price":28.55,"size":5000.0},{"price":28.506,"size":29000.0},{"price":28.5,"size":15764.3365},{"price":28.484,"size":2000.0},{"price":28.48,"size":1000.0},{"price":28.4,"size":10.0},{"price":28.342,"size":211.7},{"price":28.33,"size":150.0},{"price":28.3,"size":7127.0},{"price":28.22,"size":260.0},{"price":28.2,"size":5032.4677},{"price":28.167,"size":2000.0},{"price":28.14,"size":0.355366},{"price":28.111,"size":401.0},{"price":28.1,"size":20110.0},{"price":28.031,"size":0.76},{"price":28.017,"size":0.76},{"price":28.01,"size":2000.0},{"price":28.0,"size":95929.3687536},{"price":27.949,"size":200.0},{"price":27.9,"size":112.6018},{"price":27.895,"size":2000.0},{"price":27.888,"size":1100.0},{"price":27.88,"size":508.68},{"price":27.8,"size":10.0},{"price":27.743,"size":2000.0},{"price":27.734,"size":120.0},{"price":27.66,"size":150.0},{"price":27.64,"size":40.0},{"price":27.6,"size":322.7388},{"price":27.5,"size":10657.0},{"price":27.407,"size":500.0},{"price":27.4,"size":1812.0},{"price":27.33,"size":150.0},{"price":27.3,"size":5092.8788},{"price":27.272,"size":1.098},{"price":27.2,"size":10.0},{"price":27.167,"size":2000.0},{"price":27.111,"size":300.0},{"price":27.11,"size":1000.0},{"price":27.1,"size":39854.2804428},{"price":27.01,"size":2000.0},{"price":27.0,"size":53444.0469},{"price":26.905,"size":400.0},{"price":26.9,"size":900.0},{"price":26.895,"size":2000.0},{"price":26.888,"size":100.0},{"price":26.88,"size":150.0},{"price":26.831,"size":1000.0},{"price":26.8,"size":1500.0},{"price":26.752,"size":50.0},{"price":26.7,"size":1646.1682},{"price":26.666,"size":10000.0},{"price":26.66,"size":150.0},{"price":26.6,"size":100.0},{"price":26.588,"size":3000.0},{"price":26.568,"size":100.0},{"price":26.5,"size":64982.490566},{"price":26.494,"size":177.2597},{"price":26.42,"size":800.0},{"price":26.4,"size":403.3178},{"price":26.33,"size":150.0},{"price":26.31,"size":100.0},{"price":26.3,"size":3100.0},{"price":26.262,"size":750.0},{"price":26.167,"size":1000.0},{"price":26.111,"size":300.0},{"price":26.11,"size":1000.0},{"price":26.1,"size":20013.4709},{"price":26.062,"size":76.74},{"price":26.0,"size":54460.2769229},{"price":25.9,"size":100.0},{"price":25.88,"size":300.0},{"price":25.841,"size":773.0},{"price":25.8,"size":463.6275},{"price":25.776,"size":0.83},{"price":25.678,"size":7.0},{"price":25.66,"size":150.0},{"price":25.6,"size":100.0},{"price":25.588,"size":2000.0},{"price":25.56,"size":400.0},{"price":25.555,"size":391.0},{"price":25.506,"size":1000.0},{"price":25.5,"size":6423.8878},{"price":25.4,"size":5000.0},{"price":25.33,"size":150.0},{"price":25.3,"size":5200.0},{"price":25.26,"size":1500.0},{"price":25.25,"size":40.0},{"price":25.222,"size":410.0},{"price":25.2,"size":13.952},{"price":25.19,"size":25.0},{"price":25.111,"size":300.0},{"price":25.11,"size":2000.0},{"price":25.1,"size":20100.0},{"price":25.08,"size":400.0},{"price":25.011,"size":2000.0},{"price":25.01,"size":3433.0},{"price":25.0,"size":128164.3},{"price":24.9,"size":214.1201},{"price":24.891,"size":80.389},{"price":24.8,"size":2500.0},{"price":24.793,"size":1.208},{"price":24.745,"size":2000.0},{"price":24.743,"size":2000.0},{"price":24.667,"size":30.0},{"price":24.666,"size":10150.0},{"price":24.6,"size":14.2923},{"price":24.5,"size":22820.0},{"price":24.456,"size":50.0},{"price":24.3,"size":19119.4687},{"price":24.1,"size":1411.5},{"price":24.0,"size":77501.0},{"price":23.814,"size":2000.0},{"price":23.666,"size":10000.0},{"price":23.6,"size":4300.0},{"price":23.5,"size":3020.0},{"price":23.45,"size":100.0},{"price":23.4,"size":522.0},{"price":23.3,"size":3000.0},{"price":23.257,"size":859.0},{"price":23.25,"size":5000.0},{"price":23.2,"size":100.0},{"price":23.02,"size":3000.0},{"price":23.0,"size":66449.0},{"price":22.666,"size":10000.0},{"price":22.5,"size":8020.0},{"price":22.3,"size":3000.0},{"price":22.05,"size":5000.0},{"price":22.0,"size":3640.090909},{"price":21.828,"size":300.0},{"price":21.655,"size":500.0},{"price":21.644,"size":92.447},{"price":21.57,"size":5000.0},{"price":21.5,"size":70.0},{"price":21.49,"size":301.0},{"price":21.3,"size":3000.0},{"price":21.0,"size":7870.0},{"price":20.98,"size":3000.0},{"price":20.568,"size":200.0},{"price":20.5,"size":20.0},{"price":20.44,"size":0.1},{"price":20.3,"size":3000.0},{"price":20.0,"size":30616.1},{"price":19.895,"size":55.0},{"price":19.57,"size":5000.0},{"price":19.0,"size":1711.0},{"price":18.5,"size":20.0},{"price":18.3,"size":6000.0},{"price":18.0,"size":10240.0},{"price":17.58,"size":5000.0},{"price":17.1,"size":1000.0},{"price":17.0,"size":5010.0},{"price":16.8,"size":30.0},{"price":16.0,"size":1110.0},{"price":15.0,"size":200.0}],"asks":[{"price":31.557,"size":978.2},{"price":31.578,"size":1351.98},{"price":31.579,"size":975.2},{"price":31.583,"size":3783.0},{"price":31.592,"size":11880.0},{"price":31.594,"size":3736.0},{"price":31.615,"size":8000.0},{"price":31.623,"size":607.9},{"price":31.628,"size":29746.0},{"price":31.715,"size":8000.0},{"price":31.728,"size":717.1},{"price":31.73,"size":303740.0},{"price":31.746,"size":119.01},{"price":31.85,"size":137.0},{"price":31.886,"size":92.83},{"price":31.9,"size":30000.0},{"price":31.916,"size":119.43},{"price":31.918,"size":73495.0},{"price":31.947,"size":187.82},{"price":31.948,"size":31.3011112},{"price":31.95,"size":20000.0},{"price":32.0,"size":1397.0},{"price":32.036,"size":122.0},{"price":32.1,"size":5.140187},{"price":32.125,"size":8.0},{"price":32.193,"size":118.9},{"price":32.2,"size":5.124224},{"price":32.215,"size":98.5},{"price":32.25,"size":20008.0},{"price":32.282,"size":619.538},{"price":32.3,"size":4005.10836},{"price":32.375,"size":8.0},{"price":32.4,"size":379.092593},{"price":32.414,"size":100.0},{"price":32.47,"size":200.0},{"price":32.5,"size":1323.9384624},{"price":32.571,"size":118.53},{"price":32.6,"size":304.04908},{"price":32.625,"size":8.0},{"price":32.7,"size":4.036698},{"price":32.71,"size":12488.0},{"price":32.75,"size":8.0},{"price":32.8,"size":4.024391},{"price":32.822,"size":100.0},{"price":32.875,"size":8.0},{"price":32.9,"size":4.012159},{"price":32.98,"size":149.61},{"price":33.0,"size":9178.468362},{"price":33.015,"size":5000.0},{"price":33.1,"size":14.108762},{"price":33.125,"size":8.0},{"price":33.2,"size":2304.096386},{"price":33.25,"size":8.0},{"price":33.253,"size":150.0},{"price":33.3,"size":6104.084085},{"price":33.33,"size":3994.0},{"price":33.37,"size":10000.0},{"price":33.375,"size":8.0},{"price":33.4,"size":4.071857},{"price":33.5,"size":1811.059702},{"price":33.545,"size":29.8105828},{"price":33.6,"size":4.04762},{"price":33.625,"size":8.0},{"price":33.7,"size":4.035609},{"price":33.75,"size":8.0},{"price":33.79,"size":0.2071618},{"price":33.8,"size":4.023669},{"price":33.875,"size":8.0},{"price":33.9,"size":13204.0118},{"price":33.968,"size":98.5},{"price":34.0,"size":3772.5},{"price":34.1,"size":1.026393},{"price":34.125,"size":8.0},{"price":34.2,"size":1.023392},{"price":34.25,"size":8.0},{"price":34.26,"size":400.0},{"price":34.3,"size":1.020409},{"price":34.375,"size":8.0},{"price":34.4,"size":74696.017442},{"price":34.5,"size":24697.014493},{"price":34.6,"size":1.011561},{"price":34.625,"size":8.0},{"price":34.7,"size":1.008646},{"price":34.75,"size":8.0},{"price":34.8,"size":1.005748},{"price":34.807,"size":100.0},{"price":34.875,"size":8.0},{"price":34.88,"size":49.87},{"price":34.9,"size":17983.002866},{"price":35.0,"size":54349.1174446},{"price":35.026,"size":242.9005511},{"price":35.094,"size":1555.0},{"price":35.1,"size":1.025642},{"price":35.111,"size":1000.0},{"price":35.125,"size":8.0},{"price":35.18,"size":6.283},{"price":35.2,"size":16.022728},{"price":35.222,"size":28.3910313},{"price":35.25,"size":8.0},{"price":35.3,"size":1.019831},{"price":35.312,"size":3271.4},{"price":35.333,"size":1000.0},{"price":35.375,"size":8.0},{"price":35.4,"size":1.01695},{"price":35.5,"size":15329.014085},{"price":35.53,"size":149.64},{"price":35.6,"size":1.011236},{"price":35.625,"size":8.0},{"price":35.7,"size":1.008404},{"price":35.75,"size":8.0},{"price":35.8,"size":1.005587},{"price":35.821,"size":9982.0},{"price":35.875,"size":8.0},{"price":35.888,"size":992.0},{"price":35.9,"size":501.002786},{"price":36.0,"size":18856.5},{"price":36.01,"size":126570.0},{"price":36.125,"size":8.0},{"price":36.2,"size":1000.0},{"price":36.25,"size":8.0},{"price":36.3,"size":1.096},{"price":36.375,"size":8.0},{"price":36.5,"size":1878.0},{"price":36.59,"size":190.0},{"price":36.625,"size":8.0},{"price":36.711,"size":284.58},{"price":36.75,"size":8.0},{"price":36.875,"size":8.0},{"price":36.92,"size":500.0},{"price":36.984,"size":27.0390774},{"price":37.0,"size":2479.4897541},{"price":37.1,"size":9950.0},{"price":37.125,"size":8.0},{"price":37.2,"size":49.0},{"price":37.25,"size":8.0},{"price":37.301,"size":9.85},{"price":37.314,"size":75.0296917},{"price":37.375,"size":8.0},{"price":37.388,"size":98.5},{"price":37.4,"size":12000.0},{"price":37.5,"size":11899.0},{"price":37.6,"size":4000.0},{"price":37.625,"size":8.0},{"price":37.75,"size":8.0},{"price":37.8,"size":1000.0},{"price":37.856,"size":60.786},{"price":37.875,"size":8.0},{"price":38.0,"size":5060.560063},{"price":38.1,"size":8223.7864549},{"price":38.125,"size":8.0},{"price":38.2,"size":8223.7864549},{"price":38.25,"size":8.0},{"price":38.28,"size":1244.0},{"price":38.3,"size":8223.7864549},{"price":38.375,"size":8.0},{"price":38.4,"size":17756.31544},{"price":38.41,"size":5.0},{"price":38.5,"size":29713.7864549},{"price":38.6,"size":8223.7864549},{"price":38.625,"size":8.0},{"price":38.7,"size":8223.7864549},{"price":38.75,"size":8.0},{"price":38.8,"size":12884.9279845},{"price":38.833,"size":25.7515022},{"price":38.875,"size":8.0},{"price":38.9,"size":8223.7864549},{"price":39.0,"size":35349.0023061},{"price":39.05,"size":1076.76},{"price":39.1,"size":8223.7864549},{"price":39.12,"size":500.0},{"price":39.125,"size":8.0},{"price":39.14,"size":500.0},{"price":39.17,"size":500.0},{"price":39.2,"size":8223.7864549},{"price":39.22,"size":500.0},{"price":39.24,"size":500.0},{"price":39.25,"size":8.0},{"price":39.27,"size":500.0},{"price":39.3,"size":7762.1354514},{"price":39.32,"size":500.0},{"price":39.34,"size":500.0},{"price":39.37,"size":500.0},{"price":39.375,"size":8.0},{"price":39.41,"size":5.0},{"price":39.42,"size":500.0},{"price":39.44,"size":500.0},{"price":39.45,"size":100.0},{"price":39.47,"size":500.0},{"price":39.49,"size":300.0},{"price":39.5,"size":13910.0},{"price":39.52,"size":500.0},{"price":39.53,"size":500.0},{"price":39.54,"size":500.0},{"price":39.55,"size":500.0},{"price":39.555,"size":779.6061182},{"price":39.57,"size":500.0},{"price":39.6,"size":500.0},{"price":39.62,"size":500.0},{"price":39.625,"size":8.0},{"price":39.63,"size":500.0},{"price":39.64,"size":500.0},{"price":39.65,"size":500.0},{"price":39.666,"size":500.0},{"price":39.67,"size":500.0},{"price":39.7,"size":600.0},{"price":39.72,"size":500.0},{"price":39.73,"size":500.0},{"price":39.74,"size":500.0},{"price":39.75,"size":508.0},{"price":39.77,"size":500.0},{"price":39.777,"size":500.0},{"price":39.8,"size":9901.628345},{"price":39.82,"size":500.0},{"price":39.83,"size":500.0},{"price":39.84,"size":500.0},{"price":39.85,"size":500.0},{"price":39.87,"size":500.0},{"price":39.875,"size":8.0},{"price":39.888,"size":500.0},{"price":39.9,"size":500.0},{"price":39.92,"size":500.0},{"price":39.93,"size":501.0},{"price":39.94,"size":500.0},{"price":39.95,"size":500.0},{"price":39.97,"size":500.0},{"price":39.989,"size":1995.0},{"price":39.996,"size":1990.0},{"price":39.999,"size":500.0},{"price":40.0,"size":86596.9346262},{"price":40.039,"size":100.0},{"price":40.05,"size":500.0},{"price":40.1,"size":510.0},{"price":40.125,"size":8.0},{"price":40.15,"size":500.0},{"price":40.2,"size":600.0},{"price":40.25,"size":508.0},{"price":40.253,"size":0.947035},{"price":40.3,"size":500.0},{"price":40.32,"size":35.0},{"price":40.35,"size":500.0},{"price":40.375,"size":8.0},{"price":40.4,"size":500.0},{"price":40.45,"size":500.0},{"price":40.5,"size":1908.0},{"price":40.55,"size":500.0},{"price":40.6,"size":500.0},{"price":40.625,"size":8.0},{"price":40.65,"size":500.0},{"price":40.7,"size":10500.0},{"price":40.72,"size":4696.5529785},{"price":40.75,"size":508.0},{"price":40.774,"size":24.5252402},{"price":40.8,"size":500.0},{"price":40.83,"size":98.5},{"price":40.85,"size":500.0},{"price":40.875,"size":8.0},{"price":40.9,"size":500.0},{"price":40.95,"size":500.0},{"price":41.0,"size":4642.2},{"price":41.1,"size":1036.935},{"price":41.125,"size":8.0},{"price":41.15,"size":50300.0},{"price":41.2,"size":151.019418},{"price":41.25,"size":8.0},{"price":41.3,"size":1.01695},{"price":41.375,"size":8.0},{"price":41.4,"size":20001.014493},{"price":41.5,"size":42091.832049},{"price":41.6,"size":21.009616},{"price":41.622,"size":22000.0},{"price":41.625,"size":8.0},{"price":41.666,"size":2000.0},{"price":41.7,"size":1.007195},{"price":41.75,"size":8.0},{"price":41.79,"size":15.0},{"price":41.8,"size":1.004785},{"price":41.833,"size":200.0},{"price":41.875,"size":8.0},{"price":41.88,"size":1398.0},{"price":41.9,"size":1.002387},{"price":42.0,"size":15853.5},{"price":42.1,"size":1.021378},{"price":42.125,"size":8.0},{"price":42.18,"size":300.0},{"price":42.2,"size":101.018958},{"price":42.25,"size":8.0},{"price":42.3,"size":1.016549},{"price":42.31,"size":40.0},{"price":42.375,"size":8.0},{"price":42.4,"size":1.014151},{"price":42.485,"size":100.0},{"price":42.5,"size":5646.011765},{"price":42.6,"size":101.00939},{"price":42.625,"size":8.0},{"price":42.666,"size":2000.0},{"price":42.7,"size":1.007026},{"price":42.75,"size":8.0},{"price":42.8,"size":1001.004673},{"price":42.813,"size":23.3573716},{"price":42.875,"size":8.0}]}}}
1639350341.7020311: {"jsonrpc":"2.0","method":"channelMessage","params":{"channel":"lightning_board_FX_BTC_JPY","message":{"mid_price":5864206.0,"bids":[{"price":5858409.0,"size":0.02675389},{"price":5861718.0,"size":0.02}],"asks":[{"price":5867385.0,"size":0.0},{"price":5868139.0,"size":0.0},{"price":5870884.0,"size":0.0},{"price":5870952.0,"size":0.0},{"price":5892194.0,"size":0.02675389},{"price":5871845.0,"size":0.06},{"price":5865158.0,"size":0.2}]}}}
1639350341.773046: {"jsonrpc":"2.0","method":"channelMessage","params":{"channel":"lightning_board_ETH_JPY","message":{"mid_price":471861.0,"bids":[{"price":471380.0,"size":0.0},{"price":471615.0,"size":0.0},{"price":471277.0,"size":0.0}],"asks":[{"price":472951.0,"size":44.0}]}}}
1639350341.7733068: {"jsonrpc":"2.0","method":"channelMessage","params":{"channel":"lightning_ticker_MONA_JPY","message":{"product_code":"MONA_JPY","state":"RUNNING","timestamp":"2021-12-12T23:05:41.3015371Z","tick_id":1298061,"best_bid":165.021,"best_ask":166.998,"best_bid_size":98.0,"best_ask_size":0.80479767,"total_bid_depth":104378.54458855,"total_ask_depth":165858.58885022,"market_bid_size":0.0,"market_ask_size":0.0,"ltp":166.0,"volume":9933.778937320000,"volume_by_product":9933.778937320000}}}
1639350341.773663: {"jsonrpc":"2.0","method":"channelMessage","params":{"channel":"lightning_board_MONA_JPY","message":{"mid_price":166.009,"bids":[],"asks":[{"price":168.179,"size":0.0}]}}}
1639350341.780352: {"jsonrpc":"2.0","method":"channelMessage","params":{"channel":"lightning_executions_FX_BTC_JPY","message":[{"id":2284079860,"side":"SELL","price":5863388.0,"size":0.01,"exec_date":"2021-12-12T23:05:41.6849208Z","buy_child_order_acceptance_id":"JRF20211212-230539-214530","sell_child_order_acceptance_id":"JRF20211212-230541-123393"},{"id":2284079861,"side":"SELL","price":5863347.0,"size":0.01,"exec_date":"2021-12-12T23:05:41.6849208Z","buy_child_order_acceptance_id":"JRF20211212-230539-086965","sell_child_order_acceptance_id":"JRF20211212-230541-123393"}]}}
1639350341.780457: {"jsonrpc":"2.0","method":"channelMessage","params":{"channel":"lightning_ticker_XRP_JPY","message":{"product_code":"XRP_JPY","state":"RUNNING","timestamp":"2021-12-12T23:05:41.437707Z","tick_id":12284630,"best_bid":95.96,"best_ask":96.13,"best_bid_size":775.5,"best_ask_size":49.479871,"total_bid_depth":1534804.08922300,"total_ask_depth":2321093.181293000000,"market_bid_size":0.0,"market_ask_size":0.0,"ltp":95.96,"volume":1653279.685708000000,"volume_by_product":1653279.685708000000}}}
1639350341.7896981: {"jsonrpc":"2.0","method":"channelMessage","params":{"channel":"lightning_board_XRP_JPY","message":{"mid_price":96.04,"bids":[{"price":95.73,"size":5540.0}],"asks":[{"price":96.21,"size":10647.0}]}}}
1639350341.7949061: {"jsonrpc":"2.0","method":"channelMessage","params":{"channel":"lightning_ticker_BTC_USD","message":{"product_code":"BTC_USD","state":"RUNNING","timestamp":"2021-12-12T23:05:41.5392349Z","tick_id":17932906,"best_bid":50293.1,"best_ask":50316.83,"best_bid_size":0.6003,"best_ask_size":0.01,"total_bid_depth":28.02365669,"total_ask_depth":22.16916266,"market_bid_size":0.0,"market_ask_size":0.0,"ltp":50278.04,"volume":250.100018300000,"volume_by_product":250.100018300000}}}
1639350341.8032079: {"jsonrpc":"2.0","method":"channelMessage","params":{"channel":"lightning_board_BTC_USD","message":{"mid_price":50304.96,"bids":[{"price":50265.78,"size":0.0},{"price":50241.82,"size":0.0},{"price":50293.1,"size":0.6003},{"price":50278.01,"size":0.6003},{"price":49823.71,"size":0.45}],"asks":[{"price":50338.4,"size":0.6003},{"price":50345.95,"size":0.6003},{"price":50373.39,"size":0.0},{"price":50324.55,"size":0.1}]}}}
1639350341.820967: {"jsonrpc":"2.0","method":"channelMessage","params":{"channel":"lightning_board_FX_BTC_JPY","message":{"mid_price":5864186.0,"bids":[{"price":4416882.0,"size":0.522},{"price":5862292.0,"size":0.0493381},{"price":5861217.0,"size":0.0},{"price":5861430.0,"size":0.0},{"price":5862731.0,"size":0.02289772},{"price":5863388.0,"size":0.0},{"price":5863347.0,"size":0.001},{"price":5860759.0,"size":0.05}],"asks":[{"price":5870031.0,"size":0.5},{"price":5866613.0,"size":0.0},{"price":5867069.0,"size":0.011}]}}}
1639350341.823091: {"jsonrpc":"2.0","method":"channelMessage","params":{"channel":"lightning_ticker_BTC_EUR","message":{"product_code":"BTC_EUR","state":"RUNNING","timestamp":"2021-12-12T23:05:41.5731924Z","tick_id":7240237,"best_bid":44461.19,"best_ask":44479.65,"best_bid_size":0.00118145,"best_ask_size":0.01,"total_bid_depth":14.74728901,"total_ask_depth":14.32446467,"market_bid_size":0.0,"market_ask_size":0.0,"ltp":44461.2,"volume":43.951523900000,"volume_by_product":43.951523900000}}}
1639350341.832582: {"jsonrpc":"2.0","method":"channelMessage","params":{"channel":"lightning_board_BTC_EUR","message":{"mid_price":44470.42,"bids":[{"price":44364.3,"size":0.0},{"price":44423.83,"size":0.50134},{"price":44249.83,"size":0.18}],"asks":[{"price":44625.8,"size":0.13},{"price":44557.9,"size":0.50134}]}}}
1639350341.852056: {"jsonrpc":"2.0","method":"channelMessage","params":{"channel":"lightning_ticker_XLM_JPY","message":{"product_code":"XLM_JPY","state":"RUNNING","timestamp":"2021-12-12T23:05:41.5054691Z","tick_id":8300567,"best_bid":31.493,"best_ask":31.557,"best_bid_size":3757.0,"best_ask_size":978.2,"total_bid_depth":1862558.59493760,"total_ask_depth":2115488.767473400000,"market_bid_size":0.0,"market_ask_size":0.0,"ltp":31.471,"volume":1471420.073424000000,"volume_by_product":1471420.073424000000}}}
1639350341.864848: {"jsonrpc":"2.0","method":"channelMessage","params":{"channel":"lightning_board_XLM_JPY","message":{"mid_price":31.525,"bids":[],"asks":[{"price":31.578,"size":901.32}]}}}
1639350341.871115: {"jsonrpc":"2.0","method":"channelMessage","params":{"channel":"lightning_executions_ETH_JPY","message":[{"id":2284078765,"side":"SELL","price":471722.0,"size":0.01,"exec_date":"2021-12-12T23:05:41.7600774Z","buy_child_order_acceptance_id":"JRF20211212-230538-223079","sell_child_order_acceptance_id":"JRF20211212-230539-697375"}]}}
1639350341.945824: {"jsonrpc":"2.0","method":"channelMessage","params":{"channel":"lightning_board_FX_BTC_JPY","message":{"mid_price":5864186.0,"bids":[{"price":5862693.0,"size":0.23170144},{"price":5861110.0,"size":0.05},{"price":5858360.0,"size":0.0},{"price":5858742.0,"size":0.02860168},{"price":5861723.0,"size":0.05},{"price":5858402.0,"size":0.05},{"price":5860979.0,"size":0.1},{"price":5861461.0,"size":0.05},{"price":5861070.0,"size":0.12}],"asks":[{"price":5865401.0,"size":0.1483},{"price":5868248.0,"size":0.0},{"price":5867345.0,"size":0.01},{"price":5894965.0,"size":0.0},{"price":5866373.0,"size":0.04946442}]}}}
1639350341.97776: {"jsonrpc":"2.0","method":"channelMessage","params":{"channel":"lightning_board_snapshot_FX_BTC_JPY","message":{"mid_price":5864185.0,"bids":[{"price":5863347.0,"size":0.001},{"price":5863309.0,"size":0.01},{"price":5863171.0,"size":0.01},{"price":5862731.0,"size":0.02289772},{"price":5862693.0,"size":0.23170144},{"price":5862391.0,"size":0.1872},{"price":5862292.0,"size":0.0493381},{"price":5862266.0,"size":0.02},{"price":5862137.0,"size":0.01},{"price":5862064.0,"size":0.1},{"price":5862041.0,"size":0.2},{"price":5862040.0,"size":0.2},{"price":5861930.0,"size":0.01},{"price":5861723.0,"size":0.05},{"price":5861718.0,"size":0.02},{"price":5861461.0,"size":0.05},{"price":5861411.0,"size":0.2},{"price":5861110.0,"size":0.05},{"price":5861070.0,"size":0.12},{"price":5860979.0,"size":0.1},{"price":5860887.0,"size":0.04},{"price":5860759.0,"size":0.05},{"price":5860750.0,"size":0.02},{"price":5860418.0,"size":0.02852248},{"price":5860402.0,"size":0.02852248},{"price":5859959.0,"size":0.01},{"price":5859683.0,"size":0.05},{"price":5859239.0,"size":0.1},{"price":5859002.0,"size":0.032},{"price":5858861.0,"size":0.025},{"price":5858742.0,"size":0.02860168},{"price":5858532.0,"size":0.01},{"price":5858409.0,"size":0.02675389},{"price":5858404.0,"size":0.02675395},{"price":5858402.0,"size":0.05},{"price":5858398.0,"size":0.02675298},{"price":5858389.0,"size":0.02675347},{"price":5858385.0,"size":0.02675395},{"price":5858375.0,"size":0.01},{"price":5858373.0,"size":0.0267539},{"price":5858331.0,"size":0.255},{"price":5857984.0,"size":0.2},{"price":5857614.0,"size":0.1},{"price":5857564.0,"size":0.2},{"price":5857563.0,"size":0.02},{"price":5857263.0,"size":0.026},{"price":5856882.0,"size":0.029},{"price":5856474.0,"size":0.04},{"price":5856211.0,"size":0.1},{"price":5855808.0,"size":0.2},{"price":5855805.0,"size":0.2},{"price":5855577.0,"size":0.01},{"price":5855148.0,"size":0.1},{"price":5855145.0,"size":0.1},{"price":5854446.0,"size":0.09950742},{"price":5854281.0,"size":0.04},{"price":5854070.0,"size":0.14},{"price":5853722.0,"size":0.058},{"price":5853607.0,"size":0.1},{"price":5853534.0,"size":0.47773664},{"price":5853431.0,"size":0.04},{"price":5853321.0,"size":0.025},{"price":5853250.0,"size":0.04},{"price":5853170.0,"size":0.02},{"price":5853121.0,"size":0.08},{"price":5852997.0,"size":0.01},{"price":5852947.0,"size":0.5},{"price":5852917.0,"size":0.01},{"price":5852877.0,"size":0.04},{"price":5852790.0,"size":0.04},{"price":5852760.0,"size":0.252},{"price":5852632.0,"size":0.01},{"price":5852338.0,"size":0.01},{"price":5852291.0,"size":0.01},{"price":5852203.0,"size":0.477},{"price":5852009.0,"size":0.02},{"price":5851958.0,"size":0.03},{"price":5851924.0,"size":0.02},{"price":5851571.0,"size":0.01},{"price":5851295.0,"size":0.1},{"price":5851233.0,"size":0.2},{"price":5851079.0,"size":0.05},{"price":5850774.0,"size":0.05},{"price":5850751.0,"size":0.292},{"price":5850693.0,"size":0.04},{"price":5850673.0,"size":0.01},{"price":5850492.0,"size":0.3},{"price":5850016.0,"size":0.02},{"price":5848716.0,"size":0.01},{"price":5848392.0,"size":0.01},{"price":5847901.0,"size":0.02},{"price":5847844.0,"size":0.05},{"price":5847732.0,"size":0.01},{"price":5847571.0,"size":0.01},{"price":5847303.0,"size":0.12},{"price":5846500.0,"size":0.02},{"price":5846007.0,"size":0.1},{"price":5845785.0,"size":0.02},{"price":5845541.0,"size":0.12},{"price":5845407.0,"size":0.01},{"price":5845403.0,"size":0.02},{"price":5845367.0,"size":0.02},{"price":5845230.0,"size":0.02},{"price":5845000.0,"size":0.05},{"price":5844928.0,"size":0.02},{"price":5844914.0,"size":0.05},{"price":5843860.0,"size":0.04},{"price":5843040.0,"size":0.05},{"price":5841009.0,"size":0.03},{"price":5840987.0,"size":0.1},{"price":5840909.0,"size":0.02},{"price":5840875.0,"size":0.029},{"price":5840794.0,"size":0.02},{"price":5840706.0,"size":1.183},{"price":5840129.0,"size":0.01},{"price":5838420.0,"size":0.01},{"price":5838334.0,"size":0.04},{"price":5837200.0,"size":0.01},{"price":5835949.0,"size":0.04},{"price":5834878.0,"size":0.04},{"price":5834752.0,"size":0.029},{"price":5833832.0,"size":0.01},{"price":5833715.0,"size":0.01},{"price":5832750.0,"size":0.01},{"price":5832211.0,"size":0.08},{"price":5831082.0,"size":0.01},{"price":5830423.0,"size":0.02},{"price":5830300.0,"size":0.02},{"price":5828264.0,"size":0.06},{"price":5828190.0,"size":0.01},{"price":5827582.0,"size":0.08},{"price":5827500.0,"size":0.01},{"price":5827441.0,"size":0.02},{"price":5826882.0,"size":0.029},{"price":5826000.0,"size":0.05},{"price":5825845.0,"size":0.03},{"price":5825000.0,"size":0.01},{"price":5824694.0,"size":0.01},{"price":5822172.0,"size":6.043},{"price":5821506.0,"size":0.04},{"price":5820555.0,"size":0.0125},{"price":5820000.0,"size":0.021},{"price":5818271.0,"size":0.08},{"price":5817493.0,"size":0.01},{"price":5817263.0,"size":0.026},{"price":5816415.0,"size":0.05},{"price":5815888.0,"size":0.015},{"price":5815000.0,"size":0.02},{"price":5813000.0,"size":0.01},{"price":5812404.0,"size":0.1},{"price":5812383.0,"size":0.1},{"price":5812099.0,"size":0.01},{"price":5810555.0,"size":0.01},{"price":5810115.0,"size":0.01},{"price":5810000.0,"size":0.01},{"price":5809775.0,"size":0.55},{"price":5808888.0,"size":0.021},{"price":5808532.0,"size":0.01},{"price":5808251.0,"size":1.5},{"price":5807825.0,"size":0.01},{"price":5806643.0,"size":0.01},{"price":5806493.0,"size":0.01},{"price":5805600.0,"size":0.03573532},{"price":5805555.0,"size":0.0125},{"price":5805000.0,"size":0.06},{"price":5804817.0,"size":0.02},{"price":5803666.0,"size":0.01},{"price":5802985.0,"size":0.01},{"price":5802094.0,"size":0.01},{"price":5801000.0,"size":0.2},{"price":5800577.0,"size":0.02},{"price":5800541.0,"size":0.2},{"price":5800134.0,"size":0.02},{"price":5800000.0,"size":0.58},{"price":5799987.0,"size":0.02},{"price":5797000.0,"size":0.03},{"price":5795600.0,"size":0.05},{"price":5794167.0,"size":0.01},{"price":5791786.0,"size":0.01},{"price":5790441.0,"size":0.02},{"price":5790000.0,"size":0.01},{"price":5789008.0,"size":0.1},{"price":5789000.0,"size":0.30334734},{"price":5788910.0,"size":3.597},{"price":5788888.0,"size":0.1},{"price":5787938.0,"size":0.01},{"price":5787489.0,"size":0.04},{"price":5787383.0,"size":0.1},{"price":5786910.0,"size":0.2},{"price":5786316.0,"size":0.01},{"price":5786173.0,"size":0.08},{"price":5785600.0,"size":0.05},{"price":5785000.0,"size":0.01},{"price":5782552.0,"size":0.03},{"price":5781103.0,"size":0.01},{"price":5781082.0,"size":0.01},{"price":5780088.0,"size":0.01},{"price":5780000.0,"size":0.62},{"price":5778256.0,"size":0.08},{"price":5778000.0,"size":0.01},{"price":5777911.0,"size":0.012},{"price":5775600.0,"size":0.05},{"price":5772041.0,"size":0.01},{"price":5770790.0,"size":0.1},{"price":5770474.0,"size":0.01},{"price":5770358.0,"size":1.0},{"price":5770000.0,"size":0.2},{"price":5766882.0,"size":0.058},{"price":5765600.0,"size":0.05},{"price":5765062.0,"size":0.01},{"price":5763400.0,"size":0.01},{"price":5762832.0,"size":0.01},{"price":5762383.0,"size":0.1},{"price":5761555.0,"size":0.02},{"price":5761000.0,"size":0.2},{"price":5760807.0,"size":0.15},{"price":5760000.0,"size":0.12},{"price":5759658.0,"size":0.01},{"price":5758888.0,"size":0.301},{"price":5758715.0,"size":0.01},{"price":5758000.0,"size":0.03},{"price":5757263.0,"size":0.052},{"price":5755600.0,"size":0.05},{"price":5755555.0,"size":0.025},{"price":5753726.0,"size":0.01},{"price":5752455.0,"size":3.589},{"price":5752323.0,"size":0.01},{"price":5752321.0,"size":0.1},{"price":5751800.0,"size":0.01},{"price":5751643.0,"size":0.01},{"price":5750000.0,"size":0.32},{"price":5747500.0,"size":0.1},{"price":5747499.0,"size":0.01},{"price":5745600.0,"size":0.05},{"price":5744759.0,"size":0.5},{"price":5743022.0,"size":0.01},{"price":5742907.0,"size":0.5},{"price":5741499.0,"size":0.01},{"price":5740000.0,"size":0.52},{"price":5737499.0,"size":0.01},{"price":5735600.0,"size":0.05},{"price":5732750.0,"size":0.025},{"price":5731731.0,"size":0.01},{"price":5731653.0,"size":0.5},{"price":5731499.0,"size":0.01},{"price":5731232.0,"size":0.05},{"price":5728000.0,"size":1.0},{"price":5727499.0,"size":0.01},{"price":5725600.0,"size":0.05},{"price":5725441.0,"size":0.04},{"price":5725150.0,"size":0.01},{"price":5725101.0,"size":0.1},{"price":5725000.0,"size":0.04},{"price":5724000.0,"size":0.03},{"price":5723654.0,"size":0.012},{"price":5721499.0,"size":0.01},{"price":5721000.0,"size":0.2},{"price":5720009.0,"size":0.01},{"price":5720000.0,"size":0.02},{"price":5715600.0,"size":0.05},{"price":5715000.0,"size":0.03},{"price":5711653.0,"size":0.5},{"price":5708532.0,"size":0.02},{"price":5708450.0,"size":1.191},{"price":5705600.0,"size":0.05},{"price":5705555.0,"size":0.025},{"price":5704543.0,"size":2.341},{"price":5702883.0,"size":0.01},{"price":5700000.0,"size":0.985},{"price":5693739.0,"size":0.1},{"price":5692856.0,"size":0.01},{"price":5690585.0,"size":0.01},{"price":5690000.0,"size":0.06},{"price":5686666.0,"size":0.03},{"price":5686049.0,"size":0.1},{"price":5683737.0,"size":0.01},{"price":5682000.0,"size":0.2},{"price":5681000.0,"size":0.2},{"price":5680800.0,"size":0.01},{"price":5680000.0,"size":1.05},{"price":5679812.0,"size":0.01},{"price":5679051.0,"size":0.1},{"price":5678504.0,"size":0.5},{"price":5678000.0,"size":0.01},{"price":5677000.0,"size":0.01},{"price":5676890.0,"size":0.06},{"price":5676882.0,"size":0.116},{"price":5676611.0,"size":0.1},{"price":5676000.0,"size":0.5},{"price":5675811.0,"size":0.01},{"price":5675000.0,"size":0.01},{"price":5674640.0,"size":0.01},{"price":5674252.0,"size":0.015},{"price":5672125.0,"size":0.01},{"price":5672077.0,"size":0.065},{"price":5671653.0,"size":1.0},{"price":5669760.0,"size":0.01},{"price":5668000.0,"size":0.01},{"price":5666666.0,"size":0.01},{"price":5666664.0,"size":0.05}],"asks":[{"price":5865024.0,"size":0.2},{"price":5865025.0,"size":0.025},{"price":5865095.0,"size":0.04},{"price":5865158.0,"size":0.2},{"price":5865159.0,"size":0.01},{"price":5865219.0,"size":0.01},{"price":5865401.0,"size":0.1483},{"price":5865402.0,"size":0.02},{"price":5865818.0,"size":0.01},{"price":5866373.0,"size":0.04946442},{"price":5866614.0,"size":0.02},{"price":5866944.0,"size":0.2},{"price":5866945.0,"size":0.02},{"price":5866956.0,"size":0.011},{"price":5866966.0,"size":0.2},{"price":5866967.0,"size":0.2},{"price":5867069.0,"size":0.011},{"price":5867284.0,"size":0.011},{"price":5867345.0,"size":0.01},{"price":5867550.0,"size":0.01},{"price":5867842.0,"size":0.05},{"price":5867956.0,"size":0.01},{"price":5868297.0,"size":0.255},{"price":5868951.0,"size":0.1},{"price":5868974.0,"size":0.08558488},{"price":5869110.0,"size":0.01},{"price":5869185.0,"size":0.02},{"price":5869420.0,"size":0.02},{"price":5869453.0,"size":0.05},{"price":5869591.0,"size":0.025},{"price":5869997.0,"size":0.01},{"price":5870031.0,"size":0.5},{"price":5870199.0,"size":0.01},{"price":5870224.0,"size":0.01},{"price":5870668.0,"size":0.02},{"price":5870739.0,"size":0.01},{"price":5871489.0,"size":0.05},{"price":5871845.0,"size":0.06},{"price":5871849.0,"size":0.477},{"price":5872059.0,"size":0.02860168},{"price":5872138.0,"size":0.1},{"price":5872491.0,"size":0.02},{"price":5872509.0,"size":0.1},{"price":5872800.0,"size":0.01},{"price":5873075.0,"size":0.04},{"price":5873654.0,"size":0.01},{"price":5874100.0,"size":0.01},{"price":5874888.0,"size":0.01},{"price":5874951.0,"size":0.04},{"price":5874972.0,"size":0.1},{"price":5875000.0,"size":0.01},{"price":5875180.0,"size":0.05},{"price":5875484.0,"size":0.01},{"price":5875845.0,"size":0.058},{"price":5876000.0,"size":0.11},{"price":5876337.0,"size":0.1},{"price":5876450.0,"size":0.01},{"price":5876629.0,"size":0.133},{"price":5876840.0,"size":0.05},{"price":5878113.0,"size":0.05},{"price":5878429.0,"size":0.02},{"price":5879294.0,"size":0.02},{"price":5879730.0,"size":0.02},{"price":5879827.0,"size":0.02},{"price":5879980.0,"size":0.0125},{"price":5880000.0,"size":0.1},{"price":5880200.0,"size":0.02},{"price":5880582.0,"size":0.01},{"price":5880670.0,"size":0.03},{"price":5880700.0,"size":0.02},{"price":5880738.0,"size":0.04},{"price":5880770.0,"size":0.02},{"price":5880973.0,"size":1.183},{"price":5881046.0,"size":0.05},{"price":5881250.0,"size":0.01},{"price":5881462.0,"size":0.01},{"price":5881586.0,"size":0.04},{"price":5882441.0,"size":0.01},{"price":5883343.0,"size":0.01},{"price":5883526.0,"size":0.02},{"price":5883999.0,"size":0.01},{"price":5884885.0,"size":0.04},{"price":5887547.0,"size":0.5},{"price":5887700.0,"size":0.02},{"price":5887824.0,"size":0.01},{"price":5889450.0,"size":0.01},{"price":5889599.0,"size":0.01},{"price":5889900.0,"size":0.0125},{"price":5890000.0,"size":0.15},{"price":5891606.0,"size":0.06},{"price":5892194.0,"size":0.02675389},{"price":5892205.0,"size":0.29719466},{"price":5892319.0,"size":0.03},{"price":5892950.0,"size":0.01},{"price":5893075.0,"size":0.04},{"price":5893134.0,"size":0.04},{"price":5893994.0,"size":0.02675395},{"price":5894000.0,"size":0.01},{"price":5894980.0,"size":0.0125},{"price":5895547.0,"size":0.02675298},{"price":5895556.0,"size":0.02675347},{"price":5895560.0,"size":0.02675395},{"price":5895570.0,"size":0.01},{"price":5895572.0,"size":0.0267539},{"price":5895585.0,"size":0.02},{"price":5896416.0,"size":0.01},{"price":5898188.0,"size":0.01},{"price":5899423.0,"size":0.11},{"price":5899480.0,"size":0.0125},{"price":5899999.0,"size":0.035},{"price":5900000.0,"size":1.21},{"price":5901198.0,"size":0.172},{"price":5902155.0,"size":0.02},{"price":5902930.0,"size":0.01},{"price":5903265.0,"size":0.01},{"price":5903336.0,"size":0.01},{"price":5903373.0,"size":0.01},{"price":5903500.0,"size":0.01},{"price":5904359.0,"size":0.02},{"price":5905400.0,"size":0.01},{"price":5905522.0,"size":5.959},{"price":5905821.0,"size":0.02},{"price":5906150.0,"size":0.02},{"price":5907198.0,"size":0.08},{"price":5907359.0,"size":0.02},{"price":5908042.0,"size":0.02},{"price":5909394.0,"size":0.01},{"price":5909719.0,"size":0.02},{"price":5910243.0,"size":0.02},{"price":5910373.0,"size":0.01},{"price":5910844.0,"size":0.01},{"price":5910977.0,"size":0.01},{"price":5914900.0,"size":0.01},{"price":5915167.0,"size":0.01},{"price":5915687.0,"size":0.02},{"price":5915900.0,"size":0.01},{"price":5917850.0,"size":0.02},{"price":5918578.0,"size":0.01},{"price":5918900.0,"size":0.17},{"price":5919157.0,"size":0.05},{"price":5919800.0,"size":0.05},{"price":5920000.0,"size":0.03},{"price":5920100.0,"size":0.01},{"price":5920243.0,"size":0.02},{"price":5920365.0,"size":0.01},{"price":5920406.0,"size":0.01},{"price":5920528.0,"size":0.01},{"price":5921313.0,"size":0.01},{"price":5922222.0,"size":0.23},{"price":5922561.0,"size":0.02},{"price":5923164.0,"size":0.02},{"price":5923250.0,"size":0.02},{"price":5923314.0,"size":0.01},{"price":5923655.0,"size":0.1},{"price":5923670.0,"size":0.02},{"price":5924075.0,"size":3.0},{"price":5924482.0,"size":0.01},{"price":5924500.0,"size":0.2},{"price":5925000.0,"size":0.01},{"price":5925365.0,"size":0.01},{"price":5926888.0,"size":0.02},{"price":5927164.0,"size":0.02},{"price":5927250.0,"size":0.01},{"price":5929800.0,"size":0.05},{"price":5930000.0,"size":0.87},{"price":5930087.0,"size":0.01},{"price":5930314.0,"size":0.01},{"price":5930497.0,"size":0.01},{"price":5930643.0,"size":0.02},{"price":5931365.0,"size":0.01},{"price":5932450.0,"size":0.02},{"price":5933273.0,"size":0.01},{"price":5934563.0,"size":0.1},{"price":5935160.0,"size":0.01},{"price":5935314.0,"size":0.01},{"price":5935843.0,"size":0.02},{"price":5936000.0,"size":0.05},{"price":5936203.0,"size":3.538},{"price":5936481.0,"size":0.01},{"price":5936699.0,"size":0.01},{"price":5936800.0,"size":0.02},{"price":5936840.0,"size":0.1},{"price":5939365.0,"size":0.01},{"price":5939514.0,"size":3.613},{"price":5939780.0,"size":0.0125},{"price":5939800.0,"size":0.05},{"price":5940000.0,"size":0.01},{"price":5940497.0,"size":0.01},{"price":5940800.0,"size":0.03},{"price":5941000.0,"size":0.2},{"price":5941442.0,"size":0.01},{"price":5942373.0,"size":0.01},{"price":5943800.0,"size":0.1},{"price":5944400.0,"size":0.01},{"price":5944500.0,"size":0.2},{"price":5944700.0,"size":0.01},{"price":5944800.0,"size":0.0125},{"price":5944818.0,"size":0.01},{"price":5945000.0,"size":0.2},{"price":5945948.0,"size":1.0},{"price":5948180.0,"size":0.08},{"price":5948450.0,"size":0.02},{"price":5948719.0,"size":0.2},{"price":5949373.0,"size":0.01},{"price":5949780.0,"size":0.0125},{"price":5949800.0,"size":0.05},{"price":5949998.0,"size":0.01},{"price":5950000.0,"size":1.0},{"price":5950497.0,"size":0.01},{"price":5950752.0,"size":0.02},{"price":5950800.0,"size":0.15},{"price":5951720.0,"size":0.7},{"price":5952500.0,"size":0.03},{"price":5954350.0,"size":0.01},{"price":5954503.0,"size":2.343},{"price":5955555.0,"size":0.05},{"price":5955752.0,"size":0.02},{"price":5955929.0,"size":0.01},{"price":5956888.0,"size":0.05},{"price":5957800.0,"size":0.1},{"price":5958373.0,"size":0.01},{"price":5958507.0,"size":0.03},{"price":5959050.0,"size":0.02},{"price":5959800.0,"size":0.05},{"price":5960000.0,"size":0.6},{"price":5960752.0,"size":0.02},{"price":5963000.0,"size":0.01},{"price":5963523.0,"size":0.01},{"price":5964500.0,"size":0.2},{"price":5965203.0,"size":0.01},{"price":5965511.0,"size":0.02},{"price":5965948.0,"size":1.0},{"price":5969750.0,"size":0.03},{"price":5969800.0,"size":0.05},{"price":5970000.0,"size":0.38},{"price":5970164.0,"size":0.02},{"price":5970752.0,"size":0.02},{"price":5974200.0,"size":0.1},{"price":5975800.0,"size":0.01},{"price":5976092.0,"size":0.01},{"price":5976766.0,"size":0.32},{"price":5976800.0,"size":0.1},{"price":5977049.0,"size":0.2},{"price":5977164.0,"size":0.02},{"price":5977176.0,"size":0.1},{"price":5977777.0,"size":0.01},{"price":5978000.0,"size":0.02},{"price":5978719.0,"size":0.2},{"price":5978975.0,"size":0.5},{"price":5979135.0,"size":0.1},{"price":5979800.0,"size":0.05},{"price":5979838.0,"size":0.06},{"price":5980000.0,"size":1.021},{"price":5980125.0,"size":0.01},{"price":5980752.0,"size":0.02},{"price":5981000.0,"size":0.2},{"price":5983443.0,"size":0.05},{"price":5984500.0,"size":0.2},{"price":5985192.0,"size":0.01},{"price":5985425.0,"size":0.5},{"price":5985434.0,"size":0.1},{"price":5985750.0,"size":0.02},{"price":5985842.0,"size":0.01},{"price":5985948.0,"size":1.0},{"price":5988632.0,"size":0.01},{"price":5989750.0,"size":0.03},{"price":5989800.0,"size":0.05},{"price":5989809.0,"size":1.0},{"price":5989870.0,"size":0.15},{"price":5989906.0,"size":0.5},{"price":5990000.0,"size":0.4},{"price":5990752.0,"size":0.02},{"price":5990999.0,"size":0.01},{"price":5993000.0,"size":0.01},{"price":5993999.0,"size":0.24123375},{"price":5994000.0,"size":40.0},{"price":5994255.0,"size":0.01},{"price":5994400.0,"size":0.01},{"price":5994573.0,"size":0.01},{"price":5994643.0,"size":0.3},{"price":5995200.0,"size":0.02},{"price":5996000.0,"size":0.01},{"price":5996599.0,"size":0.48225832},{"price":5996600.0,"size":70.0},{"price":5996659.0,"size":0.24112674},{"price":5996660.0,"size":25.0},{"price":5999983.0,"size":0.01},{"price":5999999.0,"size":0.01},{"price":6000000.0,"size":4.995},{"price":6000298.0,"size":0.17},{"price":6000500.0,"size":0.01},{"price":6000752.0,"size":0.02},{"price":6003000.0,"size":0.1},{"price":6003265.0,"size":0.01},{"price":6004200.0,"size":0.02},{"price":6004500.0,"size":0.2},{"price":6005450.0,"size":0.01},{"price":6005511.0,"size":0.01},{"price":6008000.0,"size":0.01},{"price":6008027.0,"size":0.25}]}}}
1639350342.0046332: {"jsonrpc":"2.0","method":"channelMessage","params":{"channel":"lightning_board_BTC_USD","message":{"mid_price":50304.96,"bids":[{"price":49863.95,"size":0.27},{"price":49904.2,"size":0.18},{"price":49582.23,"size":0.41},{"price":50273.33,"size":1.0}],"asks":[{"price":50789.6,"size":0.45},{"price":50709.11,"size":0.18},{"price":50439.83,"size":0.0},{"price":50749.36,"size":0.27},{"price":50327.24,"size":1.0}]}}}
1639350342.007275: {"jsonrpc":"2.0","method":"channelMessage","params":{"channel":"lightning_board_snapshot_BTCJPY17DEC2021","message":{"mid_price":5701213.0,"bids":[{"price":5349532.0,"size":15.6},{"price":5391567.0,"size":6.6},{"price":5442047.0,"size":5.01},{"price":5454556.0,"size":4.0},{"price":5510756.0,"size":4.9},{"price":5575932.0,"size":3.9},{"price":5586201.0,"size":3.0},{"price":5598443.0,"size":3.02},{"price":5619882.0,"size":2.0},{"price":5629303.0,"size":1.8},{"price":5648347.0,"size":0.76},{"price":5653790.0,"size":0.7},{"price":5661414.0,"size":0.6},{"price":5674739.0,"size":0.26},{"price":5677741.0,"size":1.0},{"price":5677751.0,"size":0.01},{"price":5686175.0,"size":0.2},{"price":5691316.0,"size":0.01}],"asks":[{"price":5711111.0,"size":0.01},{"price":5713220.0,"size":0.15},{"price":5713319.0,"size":0.2},{"price":5714075.0,"size":0.58},{"price":5715427.0,"size":0.3},{"price":5716898.0,"size":0.6},{"price":5718589.0,"size":1.0},{"price":5732566.0,"size":1.0},{"price":5734417.0,"size":1.8},{"price":5746044.0,"size":1.9},{"price":5766647.0,"size":3.0},{"price":5796786.0,"size":2.4},{"price":5829125.0,"size":3.0},{"price":5852911.0,"size":5.0},{"price":5879283.0,"size":4.8},{"price":5920799.0,"size":5.0},{"price":5944842.0,"size":9.3},{"price":5986556.0,"size":12.75},{"price":6536736.0,"size":0.5},{"price":6600822.0,"size":1.0},{"price":6728993.0,"size":3.0},{"price":6857165.0,"size":5.0}]}}}
1639350342.0093582: {"jsonrpc":"2.0","method":"channelMessage","params":{"channel":"lightning_board_snapshot_BTCJPY24DEC2021","message":{"mid_price":5700879.0,"bids":[{"price":5073146.0,"size":5.0},{"price":5182246.0,"size":3.0},{"price":5291346.0,"size":1.0},{"price":5468270.0,"size":5.21},{"price":5502844.0,"size":4.0},{"price":5557220.0,"size":3.0},{"price":5583530.0,"size":3.7},{"price":5603205.0,"size":2.3},{"price":5623006.0,"size":1.92},{"price":5659178.0,"size":2.0},{"price":5661869.0,"size":1.3},{"price":5677658.0,"size":1.0},{"price":5680273.0,"size":0.7},{"price":5683047.0,"size":0.5},{"price":5683544.0,"size":0.75}],"asks":[{"price":5718215.0,"size":0.19},{"price":5721381.0,"size":0.41},{"price":5722463.0,"size":1.0},{"price":5723492.0,"size":1.0},{"price":5725066.0,"size":1.09},{"price":5727746.0,"size":0.51},{"price":5730420.0,"size":1.0},{"price":5743558.0,"size":2.0},{"price":5749238.0,"size":2.0},{"price":5771552.0,"size":1.91},{"price":5794015.0,"size":2.8},{"price":5820325.0,"size":2.77},{"price":5832425.0,"size":3.71},{"price":5836846.0,"size":5.0},{"price":5867046.0,"size":4.9}]}}}
1639350342.0116448: {"jsonrpc":"2.0","method":"channelMessage","params":{"channel":"lightning_ticker_ETH_JPY","message":{"product_code":"ETH_JPY","state":"RUNNING","timestamp":"2021-12-12T23:05:41.8217078Z","tick_id":26934571,"best_bid":471722.0,"best_ask":472000.0,"best_bid_size":1.316000,"best_ask_size":0.02,"total_bid_depth":3273.516417900000,"total_ask_depth":4468.07457320,"market_bid_size":0.0,"market_ask_size":0.0,"ltp":471722.0,"volume":10833.530505500000,"volume_by_product":10833.530505500000}}}
1639350342.0181298: {"jsonrpc":"2.0","method":"channelMessage","params":{"channel":"lightning_board_ETH_JPY","message":{"mid_price":471861.0,"bids":[{"price":471626.0,"size":0.0},{"price":469927.0,"size":0.0},{"price":470988.0,"size":0.01},{"price":469752.0,"size":0.0},{"price":470813.0,"size":0.7},{"price":469614.0,"size":0.0},{"price":469913.0,"size":0.22},{"price":471722.0,"size":1.316},{"price":471094.0,"size":0.0},{"price":471103.0,"size":0.0}],"asks":[{"price":472728.0,"size":0.0},{"price":474480.0,"size":0.7},{"price":472128.0,"size":0.75},{"price":472360.0,"size":0.0}]}}}
1639350342.0413282: {"jsonrpc":"2.0","method":"channelMessage","params":{"channel":"lightning_board_XRP_JPY","message":{"mid_price":96.05,"bids":[{"price":95.95,"size":0.0},{"price":95.97,"size":17012.54584}],"asks":[]}}}
1639350342.055638: {"jsonrpc":"2.0","method":"channelMessage","params":{"channel":"lightning_board_FX_BTC_JPY","message":{"mid_price":5864185.0,"bids":[],"asks":[{"price":5867842.0,"size":0.05},{"price":5865024.0,"size":0.2}]}}}
1639350342.166731: {"jsonrpc":"2.0","method":"channelMessage","params":{"channel":"lightning_ticker_FX_BTC_JPY","message":{"product_code":"FX_BTC_JPY","state":"RUNNING","timestamp":"2021-12-12T23:05:42.0357414Z","tick_id":127091436,"best_bid":5863347.0,"best_ask":5864793.0,"best_bid_size":0.001,"best_ask_size":0.01,"total_bid_depth":230.820585750000,"total_ask_depth":294.995724910000,"market_bid_size":0.0,"market_ask_size":0.0,"ltp":5863347.0,"volume":4227.580666850000,"volume_by_product":4227.580666850000}}}
1639350342.168868: {"jsonrpc":"2.0","method":"channelMessage","params":{"channel":"lightning_board_FX_BTC_JPY","message":{"mid_price":5864070.0,"bids":[{"price":5858424.0,"size":0.01},{"price":5861723.0,"size":0.0},{"price":5862292.0,"size":0.0},{"price":5861110.0,"size":0.0},{"price":5862064.0,"size":0.0},{"price":5861061.0,"size":0.05},{"price":5862391.0,"size":0.0},{"price":5858726.0,"size":0.02860168},{"price":5860393.0,"size":0.05},{"price":5858373.0,"size":0.0},{"price":5862065.0,"size":0.135},{"price":5862137.0,"size":0.0},{"price":5861724.0,"size":0.04}],"asks":[{"price":5866314.0,"size":0.05},{"price":5867138.0,"size":0.12},{"price":5865555.0,"size":0.01},{"price":5867047.0,"size":0.1},{"price":5864793.0,"size":0.01},{"price":5867284.0,"size":0.0},{"price":5872138.0,"size":0.0},{"price":5867842.0,"size":0.0},{"price":5866373.0,"size":0.0},{"price":5895572.0,"size":0.0},{"price":5866956.0,"size":0.0},{"price":5866614.0,"size":0.0}]}}}
1639350342.190071: {"jsonrpc":"2.0","method":"channelMessage","params":{"channel":"lightning_board_BTC_USD","message":{"mid_price":50297.42,"bids":[{"price":49501.78,"size":0.0},{"price":50293.1,"size":0.0},{"price":49904.2,"size":0.0},{"price":49863.95,"size":0.0},{"price":49823.71,"size":0.0},{"price":49582.23,"size":0.0},{"price":49697.15,"size":0.0},{"price":49737.39,"size":0.0},{"price":49777.63,"size":0.0}],"asks":[{"price":50326.15,"size":0.0},{"price":50749.36,"size":0.0},{"price":50709.11,"size":0.0},{"price":50789.6,"size":0.0},{"price":50904.37,"size":0.0},{"price":50823.89,"size":0.0},{"price":50864.13,"size":0.0},{"price":51105.93,"size":0.0}]}}}
1639350342.210324: {"jsonrpc":"2.0","method":"channelMessage","params":{"channel":"lightning_board_ETH_JPY","message":{"mid_price":471861.0,"bids":[{"price":471722.0,"size":0.566},{"price":471721.0,"size":0.0},{"price":471664.0,"size":1.0},{"price":471317.0,"size":0.0},{"price":471480.0,"size":0.0},{"price":471314.0,"size":44.0}],"asks":[{"price":472105.0,"size":0.75},{"price":473878.0,"size":0.62}]}}}
1639350342.219288: {"jsonrpc":"2.0","method":"channelMessage","params":{"channel":"lightning_board_XLM_JPY","message":{"mid_price":31.525,"bids":[{"price":31.485,"size":0.0},{"price":31.494,"size":2403.04},{"price":31.493,"size":0.0}],"asks":[{"price":31.578,"size":0.0},{"price":31.577,"size":901.14}]}}}
1639350342.228147: {"jsonrpc":"2.0","method":"channelMessage","params":{"channel":"lightning_board_BTC_EUR","message":{"mid_price":44470.42,"bids":[{"price":44423.83,"size":0.0}],"asks":[{"price":44502.49,"size":0.0}]}}}
1639350342.238285: {"jsonrpc":"2.0","method":"channelMessage","params":{"channel":"lightning_board_XRP_JPY","message":{"mid_price":96.05,"bids":[{"price":95.9,"size":0.0}],"asks":[{"price":96.16,"size":10112.0}]}}}
1639350342.278635: {"jsonrpc":"2.0","method":"channelMessage","params":{"channel":"lightning_board_FX_BTC_JPY","message":{"mid_price":5864070.0,"bids":[{"price":5862065.0,"size":0.0},{"price":5862693.0,"size":0.0},{"price":5858331.0,"size":0.0},{"price":5861724.0,"size":0.1804}],"asks":[{"price":5868297.0,"size":0.0},{"price":5866498.0,"size":0.05}]}}}
1639350342.3674061: {"jsonrpc":"2.0","method":"channelMessage","params":{"channel":"lightning_ticker_XLM_JPY","message":{"product_code":"XLM_JPY","state":"RUNNING","timestamp":"2021-12-12T23:05:42.1232414Z","tick_id":8300573,"best_bid":31.494,"best_ask":31.557,"best_bid_size":2403.04,"best_ask_size":978.2,"total_bid_depth":1858650.89493760,"total_ask_depth":2119427.587473400000,"market_bid_size":0.0,"market_ask_size":0.0,"ltp":31.471,"volume":1471420.073424000000,"volume_by_product":1471420.073424000000}}}
1639350342.373557: {"jsonrpc":"2.0","method":"channelMessage","params":{"channel":"lightning_board_XLM_JPY","message":{"mid_price":31.525,"bids":[],"asks":[{"price":31.571,"size":3939.0}]}}}
1639350342.377878: {"jsonrpc":"2.0","method":"channelMessage","params":{"channel":"lightning_ticker_BTC_USD","message":{"product_code":"BTC_USD","state":"RUNNING","timestamp":"2021-12-12T23:05:42.2761565Z","tick_id":17932941,"best_bid":50278.01,"best_ask":50316.83,"best_bid_size":0.6003,"best_ask_size":0.01,"total_bid_depth":27.97335669,"total_ask_depth":20.43577207,"market_bid_size":0.0,"market_ask_size":0.0,"ltp":50278.04,"volume":250.100018300000,"volume_by_product":250.100018300000}}}
1639350342.382091: {"jsonrpc":"2.0","method":"channelMessage","params":{"channel":"lightning_board_BTC_USD","message":{"mid_price":50297.42,"bids":[{"price":49887.06,"size":0.18},{"price":49846.83,"size":0.27},{"price":49766.37,"size":0.675},{"price":49726.14,"size":1.115},{"price":49806.6,"size":0.45}],"asks":[{"price":50691.7,"size":0.18},{"price":50731.93,"size":0.27},{"price":50812.4,"size":0.675}]}}}
1639350342.386245: {"jsonrpc":"2.0","method":"channelMessage","params":{"channel":"lightning_ticker_BTC_EUR","message":{"product_code":"BTC_EUR","state":"RUNNING","timestamp":"2021-12-12T23:05:42.242097Z","tick_id":7240245,"best_bid":44461.19,"best_ask":44479.65,"best_bid_size":0.00118145,"best_ask_size":0.01,"total_bid_depth":14.56728901,"total_ask_depth":14.19446467,"market_bid_size":0.0,"market_ask_size":0.0,"ltp":44461.2,"volume":43.951523900000,"volume_by_product":43.951523900000}}}
1639350342.391527: {"jsonrpc":"2.0","method":"channelMessage","params":{"channel":"lightning_board_BTC_EUR","message":{"mid_price":44470.42,"bids":[{"price":44249.83,"size":0.0},{"price":44356.59,"size":0.50134}],"asks":[{"price":44625.8,"size":0.0},{"price":44491.31,"size":0.50134},{"price":44518.0,"size":0.50134},{"price":44557.9,"size":0.0}]}}}
1639350342.3994188: {"jsonrpc":"2.0","method":"channelMessage","params":{"channel":"lightning_board_FX_BTC_JPY","message":{"mid_price":5864070.0,"bids":[{"price":5855821.0,"size":0.0267539}],"asks":[]}}}
1639350342.4866612: {"jsonrpc":"2.0","method":"channelMessage","params":{"channel":"lightning_executions_FX_BTC_JPY","message":[{"id":2284079862,"side":"SELL","price":5863347.0,"size":0.001,"exec_date":"2021-12-12T23:05:42.1939939Z","buy_child_order_acceptance_id":"JRF20211212-230539-086965","sell_child_order_acceptance_id":"JRF20211212-230542-224249"},{"id":2284079863,"side":"SELL","price":5863309.0,"size":0.009,"exec_date":"2021-12-12T23:05:42.1939939Z","buy_child_order_acceptance_id":"JRF20211212-230539-212596","sell_child_order_acceptance_id":"JRF20211212-230542-224249"},{"id":2284079864,"side":"SELL","price":5863309.0,"size":0.001,"exec_date":"2021-12-12T23:05:42.1960008Z","buy_child_order_acceptance_id":"JRF20211212-230539-212596","sell_child_order_acceptance_id":"JRF20211212-230542-124904"},{"id":2284079865,"side":"SELL","price":5863171.0,"size":0.01,"exec_date":"2021-12-12T23:05:42.1960008Z","buy_child_order_acceptance_id":"JRF20211212-230538-124889","sell_child_order_acceptance_id":"JRF20211212-230542-124904"}]}}
1639350342.580899: {"jsonrpc":"2.0","method":"channelMessage","params":{"channel":"lightning_board_BTC_USD","message":{"mid_price":50297.42,"bids":[],"asks":[{"price":50852.63,"size":1.125},{"price":50772.17,"size":0.45}]}}}
1639350342.588337: {"jsonrpc":"2.0","method":"channelMessage","params":{"channel":"lightning_board_FX_BTC_JPY","message":{"mid_price":5863640.0,"bids":[{"price":5863347.0,"size":0.02},{"price":5863309.0,"size":0.0},{"price":5863171.0,"size":0.0},{"price":5860402.0,"size":0.0},{"price":5862342.0,"size":0.04644039},{"price":5860418.0,"size":0.0},{"price":5859683.0,"size":0.0},{"price":5860579.0,"size":0.01},{"price":5862731.0,"size":0.0}],"asks":[{"price":5892181.0,"size":0.0267539},{"price":5863934.0,"size":0.011},{"price":5864603.0,"size":0.011},{"price":5869325.0,"size":0.255},{"price":5866497.0,"size":0.05},{"price":5869453.0,"size":0.0},{"price":5865023.0,"size":0.1534},{"price":5866826.0,"size":0.04964016},{"price":5880655.0,"size":0.01},{"price":5866313.0,"size":0.02}]}}}
1639350342.622738: {"jsonrpc":"2.0","method":"channelMessage","params":{"channel":"lightning_ticker_MONA_JPY","message":{"product_code":"MONA_JPY","state":"RUNNING","timestamp":"2021-12-12T23:05:42.3101252Z","tick_id":1298062,"best_bid":165.021,"best_ask":166.998,"best_bid_size":98.0,"best_ask_size":0.80479767,"total_bid_depth":104378.54458855,"total_ask_depth":165292.58885022,"market_bid_size":0.0,"market_ask_size":0.0,"ltp":166.0,"volume":9933.778937320000,"volume_by_product":9933.778937320000}}}
1639350342.622845: {"jsonrpc":"2.0","method":"channelMessage","params":{"channel":"lightning_board_MONA_JPY","message":{"mid_price":166.009,"bids":[],"asks":[{"price":167.656,"size":0.0}]}}}
1639350342.6229272: {"jsonrpc":"2.0","method":"channelMessage","params":{"channel":"lightning_board_BTC_EUR","message":{"mid_price":44470.42,"bids":[{"price":44239.14,"size":0.18},{"price":44331.57,"size":0.0}],"asks":[{"price":44614.95,"size":0.13},{"price":44707.41,"size":0.0}]}}}
1639350342.626292: {"jsonrpc":"2.0","method":"channelMessage","params":{"channel":"lightning_ticker_ETH_JPY","message":{"product_code":"ETH_JPY","state":"RUNNING","timestamp":"2021-12-12T23:05:42.3271449Z","tick_id":26934582,"best_bid":471722.0,"best_ask":472000.0,"best_bid_size":0.566000,"best_ask_size":0.02,"total_bid_depth":3315.496417900000,"total_ask_depth":4470.19457320,"market_bid_size":0.0,"market_ask_size":0.0,"ltp":471722.0,"volume":10833.530505500000,"volume_by_product":10833.530505500000}}}
1639350342.631228: {"jsonrpc":"2.0","method":"channelMessage","params":{"channel":"lightning_board_ETH_JPY","message":{"mid_price":471861.0,"bids":[{"price":471673.0,"size":0.75}],"asks":[{"price":472016.0,"size":0.75}]}}}
1639350342.6924832: {"jsonrpc":"2.0","method":"channelMessage","params":{"channel":"lightning_ticker_FX_BTC_JPY","message":{"product_code":"FX_BTC_JPY","state":"RUNNING","timestamp":"2021-12-12T23:05:42.5314048Z","tick_id":127091472,"best_bid":5863347.0,"best_ask":5863934.0,"best_bid_size":0.02,"best_ask_size":0.011,"total_bid_depth":230.910332560000,"total_ask_depth":295.229218970000,"market_bid_size":0.0,"market_ask_size":0.0,"ltp":5863171.0,"volume":4227.601666850000,"volume_by_product":4227.601666850000}}}
1639350342.698477: {"jsonrpc":"2.0","method":"channelMessage","params":{"channel":"lightning_board_FX_BTC_JPY","message":{"mid_price":5863640.0,"bids":[{"price":5861718.0,"size":0.0},{"price":5858726.0,"size":0.0},{"price":5858742.0,"size":0.0},{"price":3696882.0,"size":0.696}],"asks":[{"price":5864928.0,"size":0.02},{"price":5867048.0,"size":0.01},{"price":5865401.0,"size":0.0},{"price":5866313.0,"size":0.04}]}}}
1639350342.777641: {"jsonrpc":"2.0","method":"channelMessage","params":{"channel":"lightning_executions_FX_BTC_JPY","message":[{"id":2284079866,"side":"SELL","price":5863347.0,"size":0.02,"exec_date":"2021-12-12T23:05:42.6802894Z","buy_child_order_acceptance_id":"JRF20211212-230542-212606","sell_child_order_acceptance_id":"JRF20211212-230542-214534"}]}}
1639350342.806697: {"jsonrpc":"2.0","method":"channelMessage","params":{"channel":"lightning_board_FX_BTC_JPY","message":{"mid_price":5863640.0,"bids":[{"price":5861723.0,"size":0.0493381},{"price":5858375.0,"size":0.0},{"price":5858385.0,"size":0.0},{"price":5860148.0,"size":0.01},{"price":5857844.0,"size":0.05},{"price":5859046.0,"size":0.255}],"asks":[{"price":5864792.0,"size":0.2},{"price":5895570.0,"size":0.0},{"price":5895560.0,"size":0.0},{"price":5869185.0,"size":0.0},{"price":5866992.0,"size":0.01},{"price":5865630.0,"size":0.15103841}]}}}
1639350342.874455: {"jsonrpc":"2.0","method":"channelMessage","params":{"channel":"lightning_ticker_XLM_JPY","message":{"product_code":"XLM_JPY","state":"RUNNING","timestamp":"2021-12-12T23:05:42.4455879Z","tick_id":8300574,"best_bid":31.494,"best_ask":31.571,"best_bid_size":2403.04,"best_ask_size":3939.0,"total_bid_depth":1858650.89493760,"total_ask_depth":2118449.387473400000,"market_bid_size":0.0,"market_ask_size":0.0,"ltp":31.471,"volume":1471420.073424000000,"volume_by_product":1471420.073424000000}}}
1639350342.8796659: {"jsonrpc":"2.0","method":"channelMessage","params":{"channel":"lightning_board_XLM_JPY","message":{"mid_price":31.532,"bids":[],"asks":[{"price":31.557,"size":0.0}]}}}
1639350342.888045: {"jsonrpc":"2.0","method":"channelMessage","params":{"channel":"lightning_board_ETH_JPY","message":{"mid_price":471861.0,"bids":[{"price":471445.0,"size":14.99995},{"price":471664.0,"size":0.0},{"price":469522.0,"size":2.1}],"asks":[]}}}
1639350342.894318: {"jsonrpc":"2.0","method":"channelMessage","params":{"channel":"lightning_ticker_BTC_USD","message":{"product_code":"BTC_USD","state":"RUNNING","timestamp":"2021-12-12T23:05:42.563862Z","tick_id":17932954,"best_bid":50273.33,"best_ask":50301.14,"best_bid_size":1.0,"best_ask_size":0.6003,"total_bid_depth":28.68305669,"total_ask_depth":24.09341796,"market_bid_size":0.0,"market_ask_size":0.0,"ltp":50278.04,"volume":250.100018300000,"volume_by_product":250.100018300000}}}
1639350342.898571: {"jsonrpc":"2.0","method":"channelMessage","params":{"channel":"lightning_board_BTC_USD","message":{"mid_price":50287.23,"bids":[{"price":49685.54,"size":0.9},{"price":49564.85,"size":0.41},{"price":50273.32,"size":0.0},{"price":50278.01,"size":0.0},{"price":50245.68,"size":0.6003}],"asks":[{"price":50439.81,"size":0.04234589},{"price":50892.49,"size":0.9},{"price":51093.64,"size":0.54},{"price":50345.95,"size":0.0},{"price":50301.14,"size":0.6003},{"price":50308.69,"size":0.6003}]}}}
1639350342.917282: {"jsonrpc":"2.0","method":"channelMessage","params":{"channel":"lightning_board_FX_BTC_JPY","message":{"mid_price":5863138.0,"bids":[{"price":5863347.0,"size":0.0},{"price":5858389.0,"size":0.0},{"price":5860558.0,"size":0.05},{"price":5851924.0,"size":0.0},{"price":5838334.0,"size":0.0},{"price":5861143.0,"size":0.05},{"price":5855831.0,"size":0.02675395},{"price":5857893.0,"size":0.02913836},{"price":5859260.0,"size":0.011}],"asks":[{"price":5867934.0,"size":0.05},{"price":5895556.0,"size":0.0},{"price":5867750.0,"size":0.1},{"price":5879294.0,"size":0.0},{"price":5893075.0,"size":0.0},{"price":5892171.0,"size":0.02675395},{"price":5892166.0,"size":0.01},{"price":5865025.0,"size":0.0}]}}}
1639350343.031729: {"jsonrpc":"2.0","method":"channelMessage","params":{"channel":"lightning_board_BTC_USD","message":{"mid_price":50287.23,"bids":[{"price":50253.22,"size":0.6003},{"price":50260.76,"size":0.0},{"price":49484.38,"size":0.54}],"asks":[{"price":51025.45,"size":0.0},{"price":51009.3,"size":0.41}]}}}
1639350343.038378: {"jsonrpc":"2.0","method":"channelMessage","params":{"channel":"lightning_board_FX_BTC_JPY","message":{"mid_price":5863138.0,"bids":[{"price":5857893.0,"size":0.05827672},{"price":5857861.0,"size":0.109},{"price":5852645.0,"size":0.05}],"asks":[{"price":5867881.0,"size":0.02},{"price":5867272.0,"size":0.05},{"price":5865806.0,"size":0.04946442},{"price":5870668.0,"size":0.0},{"price":5865495.0,"size":0.109},{"price":5880641.0,"size":0.02675347}]}}}
1639350343.047455: {"jsonrpc":"2.0","method":"channelMessage","params":{"channel":"lightning_ticker_BTC_EUR","message":{"product_code":"BTC_EUR","state":"RUNNING","timestamp":"2021-12-12T23:05:42.6145746Z","tick_id":7240251,"best_bid":44461.19,"best_ask":44479.65,"best_bid_size":0.00118145,"best_ask_size":0.01,"total_bid_depth":14.74728901,"total_ask_depth":14.32446467,"market_bid_size":0.0,"market_ask_size":0.0,"ltp":44461.2,"volume":43.951523900000,"volume_by_product":43.951523900000}}}
1639350343.05168: {"jsonrpc":"2.0","method":"channelMessage","params":{"channel":"lightning_board_BTC_EUR","message":{"mid_price":44470.42,"bids":[{"price":44325.79,"size":0.18}],"asks":[{"price":44701.57,"size":0.18}]}}}
1639350343.061847: {"jsonrpc":"2.0","method":"channelMessage","params":{"channel":"lightning_board_ETH_JPY","message":{"mid_price":471861.0,"bids":[{"price":471605.0,"size":0.0},{"price":471314.0,"size":0.0},{"price":471689.0,"size":0.75},{"price":471445.0,"size":0.0},{"price":471615.0,"size":0.32},{"price":471722.0,"size":0.0},{"price":471723.0,"size":14.99995}],"asks":[{"price":472384.0,"size":5.013},{"price":472037.0,"size":0.75},{"price":472638.0,"size":0.0},{"price":472951.0,"size":0.0}]}}}
1639350343.065231: {"jsonrpc":"2.0","method":"channelMessage","params":{"channel":"lightning_ticker_XRP_JPY","message":{"product_code":"XRP_JPY","state":"RUNNING","timestamp":"2021-12-12T23:05:42.767675Z","tick_id":12284638,"best_bid":95.98,"best_ask":96.13,"best_bid_size":620.28,"best_ask_size":49.479871,"total_bid_depth":1523951.86922300,"total_ask_depth":2331205.081293000000,"market_bid_size":0.0,"market_ask_size":0.0,"ltp":95.96,"volume":1653279.685708000000,"volume_by_product":1653279.685708000000}}}
1639350343.0692182: {"jsonrpc":"2.0","method":"channelMessage","params":{"channel":"lightning_board_XRP_JPY","message":{"mid_price":96.05,"bids":[{"price":95.96,"size":0.0},{"price":95.98,"size":620.28}],"asks":[{"price":96.2,"size":1550.7},{"price":96.22,"size":0.0}]}}}
1639350343.142494: {"jsonrpc":"2.0","method":"channelMessage","params":{"channel":"lightning_executions_FX_BTC_JPY","message":[{"id":2284079867,"side":"BUY","price":5863934.0,"size":0.011,"exec_date":"2021-12-12T23:05:42.9654165Z","buy_child_order_acceptance_id":"JRF20211212-230542-084218","sell_child_order_acceptance_id":"JRF20211212-230542-077041"},{"id":2284079868,"side":"BUY","price":5864603.0,"size":0.011,"exec_date":"2021-12-12T23:05:42.9654165Z","buy_child_order_acceptance_id":"JRF20211212-230542-084218","sell_child_order_acceptance_id":"JRF20211212-230542-164439"},{"id":2284079869,"side":"BUY","price":5864792.0,"size":0.078,"exec_date":"2021-12-12T23:05:42.9654165Z","buy_child_order_acceptance_id":"JRF20211212-230542-084218","sell_child_order_acceptance_id":"JRF20211212-230542-203094"}]}}
1639350343.149885: {"jsonrpc":"2.0","method":"channelMessage","params":{"channel":"lightning_board_FX_BTC_JPY","message":{"mid_price":5863138.0,"bids":[{"price":5861467.0,"size":0.01}],"asks":[{"price":5865641.0,"size":0.02238173},{"price":5865495.0,"size":0.0}]}}}
1639350343.2204502: {"jsonrpc":"2.0","method":"channelMessage","params":{"channel":"lightning_board_XLM_JPY","message":{"mid_price":31.527,"bids":[{"price":31.485,"size":1802.28},{"price":31.494,"size":0.0}],"asks":[{"price":31.57,"size":750.95},{"price":31.577,"size":0.0}]}}}
1639350343.22996: {"jsonrpc":"2.0","method":"channelMessage","params":{"channel":"lightning_board_BTC_USD","message":{"mid_price":50287.23,"bids":[{"price":49887.06,"size":0.0}],"asks":[{"price":50691.7,"size":0.0}]}}}
1639350343.239251: {"jsonrpc":"2.0","method":"channelMessage","params":{"channel":"lightning_board_XRP_JPY","message":{"mid_price":96.05,"bids":[],"asks":[{"price":96.26,"size":0.0},{"price":96.31,"size":339.291574}]}}}
1639350343.246977: {"jsonrpc":"2.0","method":"channelMessage","params":{"channel":"lightning_ticker_FX_BTC_JPY","message":{"product_code":"FX_BTC_JPY","state":"RUNNING","timestamp":"2021-12-12T23:05:43.1163Z","tick_id":127091530,"best_bid":5862342.0,"best_ask":5864792.000000,"best_bid_size":0.04644039,"best_ask_size":0.122000,"total_bid_depth":231.672485740000,"total_ask_depth":295.747103530000,"market_bid_size":0.0,"market_ask_size":0.0,"ltp":5864792.000000,"volume":4227.692096850000,"volume_by_product":4227.692096850000}}}
1639350343.249664: {"jsonrpc":"2.0","method":"channelMessage","params":{"channel":"lightning_board_FX_BTC_JPY","message":{"mid_price":5863567.0,"bids":[{"price":5862042.0,"size":0.1308},{"price":5860575.0,"size":0.1},{"price":5855836.0,"size":0.01},{"price":5861724.0,"size":0.04},{"price":5855835.0,"size":0.02675347},{"price":5849903.0,"size":0.02},{"price":5856686.0,"size":0.02913836}],"asks":[{"price":5870648.0,"size":0.1},{"price":5863934.0,"size":0.0},{"price":5864603.0,"size":0.0},{"price":5864792.0,"size":0.122},{"price":5864793.0,"size":0.0},{"price":5877263.0,"size":0.02},{"price":5865818.0,"size":0.0},{"price":5869420.0,"size":0.0},{"price":5866668.0,"size":0.02},{"price":5870199.0,"size":0.0}]}}}
1639350343.355329: {"jsonrpc":"2.0","method":"channelMessage","params":{"channel":"lightning_board_BTC_USD","message":{"mid_price":50277.18,"bids":[{"price":50273.33,"size":0.0}],"asks":[{"price":50327.24,"size":0.0}]}}}
1639350343.368282: {"jsonrpc":"2.0","method":"channelMessage","params":{"channel":"lightning_board_FX_BTC_JPY","message":{"mid_price":5863567.0,"bids":[{"price":5856686.0,"size":0.05827672},{"price":5862042.0,"size":0.0},{"price":5861930.0,"size":0.0},{"price":5862343.0,"size":0.2},{"price":5862280.0,"size":0.01},{"price":5861725.0,"size":0.1293},{"price":5848347.0,"size":0.01}],"asks":[{"price":5865159.0,"size":0.0},{"price":5891040.0,"size":0.04},{"price":5865218.0,"size":0.04}]}}}
1639350343.486806: {"jsonrpc":"2.0","method":"channelMessage","params":{"channel":"lightning_ticker_ETH_JPY","message":{"product_code":"ETH_JPY","state":"RUNNING","timestamp":"2021-12-12T23:05:43.3778278Z","tick_id":26934598,"best_bid":471723.0,"best_ask":472000.0,"best_bid_size":14.99995,"best_ask_size":0.02,"total_bid_depth":3288.100367900000,"total_ask_depth":4431.44557320,"market_bid_size":0.0,"market_ask_size":0.0,"ltp":471722.0,"volume":10833.530505500000,"volume_by_product":10833.530505500000}}}
1639350343.4931939: {"jsonrpc":"2.0","method":"channelMessage","params":{"channel":"lightning_board_FX_BTC_JPY","message":{"mid_price":5863368.0,"bids":[{"price":5858398.0,"size":0.0},{"price":5862313.0,"size":0.01}],"asks":[{"price":5864472.0,"size":0.02},{"price":5864394.0,"size":0.01},{"price":5895547.0,"size":0.0}]}}}
1639350343.493351: {"jsonrpc":"2.0","method":"channelMessage","params":{"channel":"lightning_board_ETH_JPY","message":{"mid_price":471861.0,"bids":[],"asks":[{"price":472383.0,"size":1.024}]}}}
1639350343.508694: {"jsonrpc":"2.0","method":"channelMessage","params":{"channel":"lightning_board_XRP_JPY","message":{"mid_price":96.05,"bids":[],"asks":[{"price":96.2,"size":0.0}]}}}
1639350343.610934: {"jsonrpc":"2.0","method":"channelMessage","params":{"channel":"lightning_ticker_XRP_JPY","message":{"product_code":"XRP_JPY","state":"RUNNING","timestamp":"2021-12-12T23:05:43.3778278Z","tick_id":12284642,"best_bid":95.98,"best_ask":96.13,"best_bid_size":620.28,"best_ask_size":49.479871,"total_bid_depth":1523951.86922300,"total_ask_depth":2329964.501293000000,"market_bid_size":0.0,"market_ask_size":0.0,"ltp":95.96,"volume":1653279.685708000000,"volume_by_product":1653279.685708000000}}}
1639350343.6190279: {"jsonrpc":"2.0","method":"channelMessage","params":{"channel":"lightning_board_XRP_JPY","message":{"mid_price":96.05,"bids":[],"asks":[{"price":96.15,"size":310.12}]}}}
1639350343.621176: {"jsonrpc":"2.0","method":"channelMessage","params":{"channel":"lightning_board_FX_BTC_JPY","message":{"mid_price":5863368.0,"bids":[{"price":5836317.0,"size":0.04},{"price":5857893.0,"size":0.0},{"price":5855845.0,"size":0.02679844},{"price":5861725.0,"size":0.0},{"price":5852009.0,"size":0.0}],"asks":[{"price":5864928.0,"size":0.0},{"price":5878429.0,"size":0.0},{"price":5867011.0,"size":0.01},{"price":5866309.0,"size":0.02}]}}}
1639350343.6316218: {"jsonrpc":"2.0","method":"channelMessage","params":{"channel":"lightning_board_ETH_JPY","message":{"mid_price":471844.0,"bids":[{"price":471723.0,"size":0.0}],"asks":[{"price":472024.0,"size":0.75}]}}}
1639350343.636411: {"jsonrpc":"2.0","method":"channelMessage","params":{"channel":"lightning_ticker_BTC_USD","message":{"product_code":"BTC_USD","state":"RUNNING","timestamp":"2021-12-12T23:05:43.4954303Z","tick_id":17932966,"best_bid":50253.22,"best_ask":50301.14,"best_bid_size":0.6003,"best_ask_size":0.6003,"total_bid_depth":28.82335669,"total_ask_depth":23.09341796,"market_bid_size":0.0,"market_ask_size":0.0,"ltp":50278.04,"volume":250.100018300000,"volume_by_product":250.100018300000}}}
1639350343.6406138: {"jsonrpc":"2.0","method":"channelMessage","params":{"channel":"lightning_board_BTC_USD","message":{"mid_price":50277.18,"bids":[{"price":49882.9,"size":0.18}],"asks":[{"price":50687.48,"size":0.18}]}}}
1639350343.644892: {"jsonrpc":"2.0","method":"channelMessage","params":{"channel":"lightning_ticker_BTC_EUR","message":{"product_code":"BTC_EUR","state":"RUNNING","timestamp":"2021-12-12T23:05:43.4965285Z","tick_id":7240252,"best_bid":44461.19,"best_ask":44479.65,"best_bid_size":0.00118145,"best_ask_size":0.01,"total_bid_depth":14.75728901,"total_ask_depth":14.32446467,"market_bid_size":0.0,"market_ask_size":0.0,"ltp":44461.2,"volume":43.951523900000,"volume_by_product":43.951523900000}}}
1639350343.649014: {"jsonrpc":"2.0","method":"channelMessage","params":{"channel":"lightning_board_BTC_EUR","message":{"mid_price":44470.42,"bids":[{"price":43711.83,"size":0.01}],"asks":[]}}}
1639350343.735242: {"jsonrpc":"2.0","method":"channelMessage","params":{"channel":"lightning_board_FX_BTC_JPY","message":{"mid_price":5863368.0,"bids":[{"price":5862042.0,"size":0.1333},{"price":5742907.0,"size":0.0}],"asks":[{"price":5865095.0,"size":0.0},{"price":5865723.0,"size":0.02},{"price":5867668.0,"size":0.011},{"price":5866313.0,"size":0.02}]}}}
1639350343.819268: {"jsonrpc":"2.0","method":"channelMessage","params":{"channel":"lightning_board_BTC_EUR","message":{"mid_price":44470.42,"bids":[],"asks":[{"price":44614.95,"size":0.0}]}}}
1639350343.835346: {"jsonrpc":"2.0","method":"channelMessage","params":{"channel":"lightning_ticker_FX_BTC_JPY","message":{"product_code":"FX_BTC_JPY","state":"RUNNING","timestamp":"2021-12-12T23:05:43.6989519Z","tick_id":127091569,"best_bid":5862445.0,"best_ask":5864393.0,"best_bid_size":0.01,"best_ask_size":0.04,"total_bid_depth":231.380654480000,"total_ask_depth":295.791350550000,"market_bid_size":0.0,"market_ask_size":0.0,"ltp":5864792.000000,"volume":4227.682096850000,"volume_by_product":4227.682096850000}}}
1639350343.842528: {"jsonrpc":"2.0","method":"channelMessage","params":{"channel":"lightning_board_FX_BTC_JPY","message":{"mid_price":5863419.0,"bids":[{"price":5856686.0,"size":0.02913836},{"price":5862042.0,"size":0.0},{"price":5862445.0,"size":0.01},{"price":5861726.0,"size":0.1372},{"price":5860717.0,"size":0.01}],"asks":[{"price":5864393.0,"size":0.04},{"price":5865219.0,"size":0.0},{"price":5866313.0,"size":0.0}]}}}
1639350343.937206: {"jsonrpc":"2.0","method":"channelMessage","params":{"channel":"lightning_board_BTC_USD","message":{"mid_price":50287.24,"bids":[{"price":50273.34,"size":1.0}],"asks":[]}}}
1639350343.948371: {"jsonrpc":"2.0","method":"channelMessage","params":{"channel":"lightning_board_ETH_JPY","message":{"mid_price":471836.0,"bids":[{"price":470905.0,"size":14.99995},{"price":471689.0,"size":0.0}],"asks":[]}}}
1639350343.956301: {"jsonrpc":"2.0","method":"channelMessage","params":{"channel":"lightning_board_FX_BTC_JPY","message":{"mid_price":5863419.0,"bids":[{"price":5848456.0,"size":0.02},{"price":5402645.0,"size":0.05}],"asks":[{"price":5865023.0,"size":0.0},{"price":5865641.0,"size":0.0}]}}}
1639350343.959479: {"jsonrpc":"2.0","method":"channelMessage","params":{"channel":"lightning_board_BTC_EUR","message":{"mid_price":44470.42,"bids":[],"asks":[{"price":45427.26,"size":0.0}]}}}
1639350344.072748: {"jsonrpc":"2.0","method":"channelMessage","params":{"channel":"lightning_board_FX_BTC_JPY","message":{"mid_price":5863368.0,"bids":[{"price":5861724.0,"size":0.0},{"price":5861450.0,"size":0.01},{"price":5859362.0,"size":0.02},{"price":5862445.0,"size":0.0},{"price":5861144.0,"size":0.04}],"asks":[{"price":5864864.0,"size":0.01},{"price":5878230.0,"size":0.02},{"price":5865630.0,"size":0.0},{"price":5864471.0,"size":0.1477},{"price":5868932.0,"size":0.02913836},{"price":5892157.0,"size":0.02679844}]}}}
1639350344.07903: {"jsonrpc":"2.0","method":"channelMessage","params":{"channel":"lightning_board_BTC_USD","message":{"mid_price":50287.24,"bids":[{"price":49846.83,"size":0.0},{"price":49806.6,"size":0.0}],"asks":[{"price":50731.93,"size":0.0},{"price":50772.17,"size":0.0},{"price":50306.35,"size":1.0}]}}}
1639350344.0858219: {"jsonrpc":"2.0","method":"channelMessage","params":{"channel":"lightning_ticker_ETH_JPY","message":{"product_code":"ETH_JPY","state":"RUNNING","timestamp":"2021-12-12T23:05:43.8910876Z","tick_id":26934603,"best_bid":471673.000000,"best_ask":472000.0,"best_bid_size":0.750000,"best_ask_size":0.02,"total_bid_depth":3331.350367900000,"total_ask_depth":4432.19557320,"market_bid_size":0.0,"market_ask_size":0.0,"ltp":471722.0,"volume":10833.530505500000,"volume_by_product":10833.530505500000}}}
1639350344.089841: {"jsonrpc":"2.0","method":"channelMessage","params":{"channel":"lightning_board_ETH_JPY","message":{"mid_price":471836.0,"bids":[{"price":471200.0,"size":44.0}],"asks":[]}}}
1639350344.1822872: {"jsonrpc":"2.0","method":"channelMessage","params":{"channel":"lightning_board_FX_BTC_JPY","message":{"mid_price":5863368.0,"bids":[{"price":5861726.0,"size":0.0},{"price":5861144.0,"size":0.08},{"price":5861412.0,"size":0.1334},{"price":5858402.0,"size":0.02},{"price":5856686.0,"size":0.0}],"asks":[{"price":5867881.0,"size":0.0},{"price":5869665.0,"size":0.02},{"price":5871845.0,"size":0.0}]}}}
1639350344.192118: {"jsonrpc":"2.0","method":"channelMessage","params":{"channel":"lightning_ticker_BTC_USD","message":{"product_code":"BTC_USD","state":"RUNNING","timestamp":"2021-12-12T23:05:44.0258097Z","tick_id":17932981,"best_bid":50253.22,"best_ask":50301.14,"best_bid_size":0.6003,"best_ask_size":0.6003,"total_bid_depth":26.68865669,"total_ask_depth":21.03341796,"market_bid_size":0.0,"market_ask_size":0.0,"ltp":50278.04,"volume":250.100018300000,"volume_by_product":250.100018300000}}}
1639350344.1963441: {"jsonrpc":"2.0","method":"channelMessage","params":{"channel":"lightning_board_BTC_USD","message":{"mid_price":50277.18,"bids":[{"price":49685.54,"size":0.0},{"price":49726.14,"size":0.0},{"price":50239.61,"size":0.6003},{"price":50273.34,"size":0.0}],"asks":[{"price":50852.63,"size":0.0},{"price":51093.64,"size":0.0},{"price":50812.4,"size":0.0},{"price":50338.4,"size":0.0},{"price":50313.58,"size":0.6003}]}}}
1639350344.208889: {"jsonrpc":"2.0","method":"channelMessage","params":{"channel":"lightning_ticker_BTC_EUR","message":{"product_code":"BTC_EUR","state":"RUNNING","timestamp":"2021-12-12T23:05:44.0439591Z","tick_id":7240255,"best_bid":44461.19,"best_ask":44479.65,"best_bid_size":0.00118145,"best_ask_size":0.01,"total_bid_depth":14.75728901,"total_ask_depth":13.92546467,"market_bid_size":0.0,"market_ask_size":0.0,"ltp":44461.2,"volume":43.951523900000,"volume_by_product":43.951523900000}}}
1639350344.217162: {"jsonrpc":"2.0","method":"channelMessage","params":{"channel":"lightning_board_BTC_EUR","message":{"mid_price":44470.42,"bids":[],"asks":[{"price":44607.62,"size":0.13}]}}}
1639350344.3068311: {"jsonrpc":"2.0","method":"channelMessage","params":{"channel":"lightning_board_FX_BTC_JPY","message":{"mid_price":5863368.0,"bids":[{"price":5858404.0,"size":0.0}],"asks":[{"price":5865051.0,"size":0.02239542},{"price":5879730.0,"size":0.0},{"price":5879827.0,"size":0.0},{"price":5893994.0,"size":0.0},{"price":5872059.0,"size":0.0},{"price":5865022.0,"size":0.15104779},{"price":5920000.0,"size":0.08}]}}}
1639350344.3327942: {"jsonrpc":"2.0","method":"channelMessage","params":{"channel":"lightning_board_BTC_USD","message":{"mid_price":50277.18,"bids":[{"price":49766.37,"size":0.0}],"asks":[{"price":50892.49,"size":0.0}]}}}
1639350344.356559: {"jsonrpc":"2.0","method":"channelMessage","params":{"channel":"lightning_board_ETH_JPY","message":{"mid_price":471836.0,"bids":[{"price":471529.0,"size":5.013}],"asks":[]}}}
1639350344.406705: {"jsonrpc":"2.0","method":"channelMessage","params":{"channel":"lightning_ticker_FX_BTC_JPY","message":{"product_code":"FX_BTC_JPY","state":"RUNNING","timestamp":"2021-12-12T23:05:44.2405258Z","tick_id":127091603,"best_bid":5862343.000000,"best_ask":5864393.0,"best_bid_size":0.200000,"best_ask_size":0.04,"total_bid_depth":231.422716120000,"total_ask_depth":295.793008740000,"market_bid_size":0.0,"market_ask_size":0.0,"ltp":5864792.000000,"volume":4227.682096850000,"volume_by_product":4227.682096850000}}}
1639350344.408742: {"jsonrpc":"2.0","method":"channelMessage","params":{"channel":"lightning_board_FX_BTC_JPY","message":{"mid_price":5863368.0,"bids":[{"price":5855851.0,"size":0.02675395},{"price":5858861.0,"size":0.0}],"asks":[{"price":5892151.0,"size":0.02675395}]}}}
1639350344.4771042: {"jsonrpc":"2.0","method":"channelMessage","params":{"channel":"lightning_board_BTC_USD","message":{"mid_price":50277.18,"bids":[],"asks":[{"price":50762.81,"size":0.45}]}}}
1639350344.485798: {"jsonrpc":"2.0","method":"channelMessage","params":{"channel":"lightning_board_ETH_JPY","message":{"mid_price":471836.0,"bids":[{"price":471104.0,"size":0.0}],"asks":[{"price":472154.0,"size":0.0},{"price":472860.0,"size":44.0}]}}}
1639350344.52087: {"jsonrpc":"2.0","method":"channelMessage","params":{"channel":"lightning_board_FX_BTC_JPY","message":{"mid_price":5863419.0,"bids":[{"price":5862445.0,"size":0.01},{"price":5858402.0,"size":0.0},{"price":5856474.0,"size":0.02},{"price":5858409.0,"size":0.0}],"asks":[{"price":5865555.0,"size":0.0},{"price":5867956.0,"size":0.0},{"price":5864394.0,"size":0.0},{"price":5864471.0,"size":0.0},{"price":5870224.0,"size":0.0},{"price":5868932.0,"size":0.0},{"price":5892194.0,"size":0.0}]}}}
1639350344.583185: {"jsonrpc":"2.0","method":"channelMessage","params":{"channel":"lightning_board_ETH_JPY","message":{"mid_price":471807.0,"bids":[{"price":471673.0,"size":0.0}],"asks":[{"price":472000.0,"size":0.77}]}}}
1639350344.594624: {"jsonrpc":"2.0","method":"channelMessage","params":{"channel":"lightning_board_BTC_USD","message":{"mid_price":50277.18,"bids":[{"price":49837.65,"size":0.27},{"price":49716.97,"size":1.115},{"price":49797.42,"size":0.45}],"asks":[{"price":50843.26,"size":1.125}]}}}
1639350344.648308: {"jsonrpc":"2.0","method":"channelMessage","params":{"channel":"lightning_board_FX_BTC_JPY","message":{"mid_price":5863419.0,"bids":[{"price":5862313.0,"size":0.0},{"price":5856474.0,"size":0.0},{"price":5862280.0,"size":0.0},{"price":5857995.0,"size":0.02675389}],"asks":[{"price":5868047.0,"size":0.02913836},{"price":5864791.0,"size":0.1614},{"price":5866899.0,"size":0.02},{"price":5880630.0,"size":0.02675389}]}}}
1639350344.695273: {"jsonrpc":"2.0","method":"channelMessage","params":{"channel":"lightning_ticker_BTC_USD","message":{"product_code":"BTC_USD","state":"RUNNING","timestamp":"2021-12-12T23:05:44.5989978Z","tick_id":17932992,"best_bid":50274.27,"best_ask":50301.14,"best_bid_size":0.11,"best_ask_size":0.6003,"total_bid_depth":28.95865669,"total_ask_depth":22.65341796,"market_bid_size":0.0,"market_ask_size":0.0,"ltp":50278.04,"volume":250.100018300000,"volume_by_product":250.100018300000}}}
1639350344.700644: {"jsonrpc":"2.0","method":"channelMessage","params":{"channel":"lightning_board_BTC_USD","message":{"mid_price":50287.7,"bids":[{"price":50274.27,"size":0.11},{"price":50273.35,"size":1.0}],"asks":[{"price":50722.59,"size":0.27},{"price":50803.03,"size":0.675}]}}}
1639350344.704929: {"jsonrpc":"2.0","method":"channelMessage","params":{"channel":"lightning_ticker_ETH_JPY","message":{"product_code":"ETH_JPY","state":"RUNNING","timestamp":"2021-12-12T23:05:44.5989978Z","tick_id":26934613,"best_bid":471615.0,"best_ask":472000.0,"best_bid_size":0.096,"best_ask_size":0.770000,"total_bid_depth":3320.389417900000,"total_ask_depth":4476.19557320,"market_bid_size":0.0,"market_ask_size":0.0,"ltp":471722.0,"volume":10833.320505500000,"volume_by_product":10833.320505500000}}}
1639350344.710259: {"jsonrpc":"2.0","method":"channelMessage","params":{"channel":"lightning_board_ETH_JPY","message":{"mid_price":471807.0,"bids":[{"price":471596.0,"size":0.75},{"price":470905.0,"size":0.0},{"price":471615.0,"size":0.096}],"asks":[]}}}
1639350344.7241862: {"jsonrpc":"2.0","method":"channelMessage","params":{"channel":"lightning_ticker_XRP_JPY","message":{"product_code":"XRP_JPY","state":"RUNNING","timestamp":"2021-12-12T23:05:44.5989978Z","tick_id":12284643,"best_bid":95.98,"best_ask":96.13,"best_bid_size":620.28,"best_ask_size":49.479871,"total_bid_depth":1523951.86922300,"total_ask_depth":2329625.209719000000,"market_bid_size":0.0,"market_ask_size":0.0,"ltp":95.96,"volume":1653279.685708000000,"volume_by_product":1653279.685708000000}}}
1639350344.730421: {"jsonrpc":"2.0","method":"channelMessage","params":{"channel":"lightning_board_XRP_JPY","message":{"mid_price":96.05,"bids":[],"asks":[{"price":96.31,"size":0.0}]}}}
1639350344.7650728: {"jsonrpc":"2.0","method":"channelMessage","params":{"channel":"lightning_board_FX_BTC_JPY","message":{"mid_price":5863419.0,"bids":[],"asks":[{"price":5865554.0,"size":0.02},{"price":5867200.0,"size":0.01}]}}}
1639350344.837064: {"jsonrpc":"2.0","method":"channelMessage","params":{"channel":"lightning_board_ETH_JPY","message":{"mid_price":471807.0,"bids":[{"price":471530.0,"size":1.0}],"asks":[]}}}
1639350344.881569: {"jsonrpc":"2.0","method":"channelMessage","params":{"channel":"lightning_board_FX_BTC_JPY","message":{"mid_price":5863368.0,"bids":[{"price":5862445.0,"size":0.0},{"price":5853722.0,"size":0.0}],"asks":[{"price":5864625.0,"size":0.03},{"price":5867750.0,"size":0.0},{"price":5865401.0,"size":0.02},{"price":5875845.0,"size":0.0},{"price":5867868.0,"size":0.02913836}]}}}
1639350344.959486: {"jsonrpc":"2.0","method":"channelMessage","params":{"channel":"lightning_board_XRP_JPY","message":{"mid_price":96.05,"bids":[],"asks":[{"price":96.26,"size":339.343152}]}}}
1639350344.9805398: {"jsonrpc":"2.0","method":"channelMessage","params":{"channel":"lightning_ticker_FX_BTC_JPY","message":{"product_code":"FX_BTC_JPY","state":"RUNNING","timestamp":"2021-12-12T23:05:44.8312426Z","tick_id":127091637,"best_bid":5862343.000000,"best_ask":5864393.0,"best_bid_size":0.200000,"best_ask_size":0.04,"total_bid_depth":231.522716120000,"total_ask_depth":295.746985460000,"market_bid_size":0.0,"market_ask_size":0.0,"ltp":5864792.000000,"volume":4227.682096850000,"volume_by_product":4227.682096850000}}}
1639350344.982683: {"jsonrpc":"2.0","method":"channelMessage","params":{"channel":"lightning_board_FX_BTC_JPY","message":{"mid_price":5863368.0,"bids":[{"price":5859268.0,"size":0.03},{"price":4902645.0,"size":0.05},{"price":5857558.0,"size":0.1},{"price":5853722.0,"size":0.058}],"asks":[{"price":5864472.0,"size":0.0},{"price":5869044.0,"size":0.02913836}]}}}
1639350345.077089: {"jsonrpc":"2.0","method":"channelMessage","params":{"channel":"lightning_board_BTC_USD","message":{"mid_price":50287.7,"bids":[{"price":50273.35,"size":0.0}],"asks":[]}}}
1639350345.096846: {"jsonrpc":"2.0","method":"channelMessage","params":{"channel":"lightning_board_ETH_JPY","message":{"mid_price":471807.0,"bids":[{"price":471530.0,"size":0.0}],"asks":[]}}}
1639350345.1020422: {"jsonrpc":"2.0","method":"channelMessage","params":{"channel":"lightning_ticker_MONA_JPY","message":{"product_code":"MONA_JPY","state":"RUNNING","timestamp":"2021-12-12T23:05:44.9746003Z","tick_id":1298063,"best_bid":165.021,"best_ask":166.998,"best_bid_size":98.0,"best_ask_size":0.80479767,"total_bid_depth":104378.54458855,"total_ask_depth":165858.58885022,"market_bid_size":0.0,"market_ask_size":0.0,"ltp":166.0,"volume":9933.778937320000,"volume_by_product":9933.778937320000}}}
1639350345.106875: {"jsonrpc":"2.0","method":"channelMessage","params":{"channel":"lightning_board_MONA_JPY","message":{"mid_price":166.009,"bids":[],"asks":[{"price":167.999,"size":566.0}]}}}
1639350345.134642: {"jsonrpc":"2.0","method":"channelMessage","params":{"channel":"lightning_board_FX_BTC_JPY","message":{"mid_price":5863368.0,"bids":[],"asks":[{"price":5869989.0,"size":0.06},{"price":5864617.0,"size":0.01},{"price":5875845.0,"size":0.058},{"price":5869043.0,"size":0.02913836}]}}}
1639350345.221858: {"jsonrpc":"2.0","method":"channelMessage","params":{"channel":"lightning_board_XRP_JPY","message":{"mid_price":96.05,"bids":[],"asks":[{"price":96.26,"size":0.0}]}}}
1639350345.2577002: {"jsonrpc":"2.0","method":"channelMessage","params":{"channel":"lightning_board_FX_BTC_JPY","message":{"mid_price":5863419.0,"bids":[{"price":5862445.0,"size":0.01},{"price":5859264.0,"size":0.02}],"asks":[]}}}
1639350345.338193: {"jsonrpc":"2.0","method":"channelMessage","params":{"channel":"lightning_ticker_XRP_JPY","message":{"product_code":"XRP_JPY","state":"RUNNING","timestamp":"2021-12-12T23:05:45.1780319Z","tick_id":12284646,"best_bid":95.98,"best_ask":96.13,"best_bid_size":620.28,"best_ask_size":49.479871,"total_bid_depth":1523951.86922300,"total_ask_depth":2329964.552871000000,"market_bid_size":0.0,"market_ask_size":0.0,"ltp":95.96,"volume":1653279.685708000000,"volume_by_product":1653279.685708000000}}}
1639350345.341345: {"jsonrpc":"2.0","method":"channelMessage","params":{"channel":"lightning_board_XRP_JPY","message":{"mid_price":96.05,"bids":[],"asks":[{"price":96.3,"size":1691.593152}]}}}
1639350345.347651: {"jsonrpc":"2.0","method":"channelMessage","params":{"channel":"lightning_ticker_BTC_USD","message":{"product_code":"BTC_USD","state":"RUNNING","timestamp":"2021-12-12T23:05:45.2120111Z","tick_id":17932994,"best_bid":50274.27,"best_ask":50301.14,"best_bid_size":0.11,"best_ask_size":0.6003,"total_bid_depth":28.63365669,"total_ask_depth":22.65341796,"market_bid_size":0.0,"market_ask_size":0.0,"ltp":50278.04,"volume":250.100018300000,"volume_by_product":250.100018300000}}}
1639350345.3518689: {"jsonrpc":"2.0","method":"channelMessage","params":{"channel":"lightning_board_BTC_USD","message":{"mid_price":50287.7,"bids":[{"price":49760.48,"size":0.675}],"asks":[]}}}
1639350345.3793201: {"jsonrpc":"2.0","method":"channelMessage","params":{"channel":"lightning_board_FX_BTC_JPY","message":{"mid_price":5863419.0,"bids":[{"price":5834752.0,"size":0.0},{"price":5855821.0,"size":0.0},{"price":5861412.0,"size":0.0},{"price":5840875.0,"size":0.0},{"price":5861724.0,"size":0.135}],"asks":[{"price":5892181.0,"size":0.0},{"price":5865402.0,"size":0.0},{"price":5864791.0,"size":0.0}]}}}
1639350345.4650838: {"jsonrpc":"2.0","method":"channelMessage","params":{"channel":"lightning_board_BTC_USD","message":{"mid_price":50287.7,"bids":[{"price":49680.02,"size":0.9},{"price":49797.42,"size":0.0},{"price":49837.65,"size":0.0},{"price":49716.97,"size":0.0}],"asks":[{"price":50886.83,"size":0.9},{"price":51087.97,"size":0.54},{"price":50722.59,"size":0.0},{"price":50803.03,"size":0.0},{"price":50762.81,"size":0.0}]}}}
1639350345.483932: {"jsonrpc":"2.0","method":"channelMessage","params":{"channel":"lightning_ticker_ETH_JPY","message":{"product_code":"ETH_JPY","state":"RUNNING","timestamp":"2021-12-12T23:05:45.3476595Z","tick_id":26934618,"best_bid":471615.0,"best_ask":472000.0,"best_bid_size":0.096,"best_ask_size":0.770000,"total_bid_depth":3335.389367900000,"total_ask_depth":4474.82557320,"market_bid_size":0.0,"market_ask_size":0.0,"ltp":471722.0,"volume":10833.320505500000,"volume_by_product":10833.320505500000}}}
1639350345.491254: {"jsonrpc":"2.0","method":"channelMessage","params":{"channel":"lightning_board_ETH_JPY","message":{"mid_price":471807.0,"bids":[{"price":470832.0,"size":14.99995}],"asks":[{"price":473878.0,"size":0.0},{"price":472128.0,"size":0.0}]}}}
1639350345.4955049: {"jsonrpc":"2.0","method":"channelMessage","params":{"channel":"lightning_ticker_XLM_JPY","message":{"product_code":"XLM_JPY","state":"RUNNING","timestamp":"2021-12-12T23:05:45.3476595Z","tick_id":8300579,"best_bid":31.484,"best_ask":31.57,"best_bid_size":3739.0,"best_ask_size":750.95,"total_bid_depth":1856247.85493760,"total_ask_depth":2118299.197473400000,"market_bid_size":0.0,"market_ask_size":0.0,"ltp":31.471,"volume":1471420.073424000000,"volume_by_product":1471420.073424000000}}}
1639350345.499698: {"jsonrpc":"2.0","method":"channelMessage","params":{"channel":"lightning_board_XLM_JPY","message":{"mid_price":31.527,"bids":[{"price":31.485,"size":0.0}],"asks":[]}}}
1639350345.5288: {"jsonrpc":"2.0","method":"channelMessage","params":{"channel":"lightning_ticker_FX_BTC_JPY","message":{"product_code":"FX_BTC_JPY","state":"RUNNING","timestamp":"2021-12-12T23:05:45.3471455Z","tick_id":127091678,"best_bid":5862717.0,"best_ask":5864625.0,"best_bid_size":0.01,"best_ask_size":0.03,"total_bid_depth":231.260616120000,"total_ask_depth":295.460502090000,"market_bid_size":0.0,"market_ask_size":0.0,"ltp":5864792.000000,"volume":4227.682096850000,"volume_by_product":4227.682096850000}}}
1639350345.532342: {"jsonrpc":"2.0","method":"channelMessage","params":{"channel":"lightning_board_FX_BTC_JPY","message":{"mid_price":5863671.0,"bids":[{"price":5861450.0,"size":0.0},{"price":5857558.0,"size":0.0},{"price":5858424.0,"size":0.0},{"price":5862708.0,"size":0.01},{"price":5862717.0,"size":0.01},{"price":5860759.0,"size":0.0},{"price":5861724.0,"size":0.0},{"price":5860393.0,"size":0.0},{"price":5855864.0,"size":0.0267539},{"price":5861144.0,"size":0.0},{"price":5837453.0,"size":0.029},{"price":5862344.0,"size":0.1303},{"price":5862445.0,"size":0.0},{"price":5862513.0,"size":0.03}],"asks":[{"price":5864864.0,"size":0.0},{"price":5865022.0,"size":0.0},{"price":5892138.0,"size":0.0267539},{"price":5880655.0,"size":0.0},{"price":5867868.0,"size":0.0},{"price":5864617.0,"size":0.0},{"price":5864393.0,"size":0.0},{"price":5865051.0,"size":0.0},{"price":5865218.0,"size":0.0},{"price":5866826.0,"size":0.0},{"price":5865400.0,"size":0.15},{"price":5866498.0,"size":0.0}]}}}
1639350345.636471: {"jsonrpc":"2.0","method":"channelMessage","params":{"channel":"lightning_board_BTC_USD","message":{"mid_price":50287.71,"bids":[{"price":50274.28,"size":1.0}],"asks":[{"price":50843.26,"size":0.0}]}}}
1639350345.652074: {"jsonrpc":"2.0","method":"channelMessage","params":{"channel":"lightning_board_FX_BTC_JPY","message":{"mid_price":5863671.0,"bids":[{"price":5862344.0,"size":0.04},{"price":5858010.0,"size":0.01},{"price":5843576.0,"size":0.029},{"price":5856251.0,"size":0.01},{"price":5861723.0,"size":0.0},{"price":5840806.0,"size":0.01},{"price":5862342.0,"size":0.0},{"price":5862567.0,"size":0.23172252},{"price":5862042.0,"size":0.1382},{"price":5861152.0,"size":0.05},{"price":5861560.0,"size":0.05}],"asks":[{"price":5880615.0,"size":0.01},{"price":5865723.0,"size":0.0},{"price":5864791.0,"size":0.02},{"price":5868047.0,"size":0.0},{"price":5866747.0,"size":0.02}]}}}
1639350345.662703: {"jsonrpc":"2.0","method":"channelMessage","params":{"channel":"lightning_board_ETH_JPY","message":{"mid_price":471807.0,"bids":[{"price":471615.0,"size":0.846},{"price":470832.0,"size":0.0}],"asks":[{"price":472038.0,"size":0.75}]}}}
1639350345.778801: {"jsonrpc":"2.0","method":"channelMessage","params":{"channel":"lightning_board_ETH_JPY","message":{"mid_price":471807.0,"bids":[],"asks":[{"price":472639.0,"size":0.5}]}}}
1639350345.784003: {"jsonrpc":"2.0","method":"channelMessage","params":{"channel":"lightning_board_FX_BTC_JPY","message":{"mid_price":5863671.0,"bids":[{"price":5747829.0,"size":0.5},{"price":5860558.0,"size":0.0},{"price":5861143.0,"size":0.0},{"price":5861061.0,"size":0.0},{"price":5862546.0,"size":0.02291215},{"price":5862333.0,"size":0.0493381}],"asks":[{"price":5868740.0,"size":0.02913836},{"price":5865806.0,"size":0.0},{"price":5867472.0,"size":0.04964016},{"price":5865554.0,"size":0.0},{"price":5867156.0,"size":0.05},{"price":5866497.0,"size":0.0}]}}}
1639350345.786141: {"jsonrpc":"2.0","method":"channelMessage","params":{"channel":"lightning_board_XRP_JPY","message":{"mid_price":96.05,"bids":[],"asks":[{"price":96.3,"size":1352.25},{"price":96.31,"size":339.343152}]}}}
1639350345.796907: {"jsonrpc":"2.0","method":"channelMessage","params":{"channel":"lightning_board_XLM_JPY","message":{"mid_price":31.519,"bids":[{"price":31.484,"size":0.0},{"price":31.477,"size":0.0}],"asks":[]}}}
1639350345.89023: {"jsonrpc":"2.0","method":"channelMessage","params":{"channel":"lightning_ticker_BTC_USD","message":{"product_code":"BTC_USD","state":"RUNNING","timestamp":"2021-12-12T23:05:45.7240602Z","tick_id":17933008,"best_bid":50274.28,"best_ask":50301.14,"best_bid_size":1.0,"best_ask_size":0.6003,"total_bid_depth":29.14865669,"total_ask_depth":22.51841796,"market_bid_size":0.0,"market_ask_size":0.0,"ltp":50278.04,"volume":250.100018300000,"volume_by_product":250.100018300000}}}
1639350345.894444: {"jsonrpc":"2.0","method":"channelMessage","params":{"channel":"lightning_board_BTC_USD","message":{"mid_price":50287.71,"bids":[{"price":49805.67,"size":0.45}],"asks":[{"price":50811.45,"size":0.675},{"price":50730.98,"size":0.27}]}}}
1639350345.909707: {"jsonrpc":"2.0","method":"channelMessage","params":{"channel":"lightning_board_ETH_JPY","message":{"mid_price":471807.0,"bids":[{"price":471615.0,"size":0.75}],"asks":[]}}}
1639350345.920969: {"jsonrpc":"2.0","method":"channelMessage","params":{"channel":"lightning_board_FX_BTC_JPY","message":{"mid_price":5863754.0,"bids":[{"price":5855831.0,"size":0.0},{"price":5862384.0,"size":0.04644039},{"price":5858020.0,"size":0.02675395},{"price":4102645.0,"size":0.06}],"asks":[{"price":5867272.0,"size":0.0},{"price":5864625.0,"size":0.0},{"price":5892171.0,"size":0.0},{"price":5866899.0,"size":0.0},{"price":5868731.0,"size":0.02913836},{"price":5865158.0,"size":0.0},{"price":5880572.0,"size":0.02675395},{"price":5866668.0,"size":0.0},{"price":5865401.0,"size":0.0}]}}}
1639350346.021884: {"jsonrpc":"2.0","method":"channelMessage","params":{"channel":"lightning_ticker_ETH_JPY","message":{"product_code":"ETH_JPY","state":"RUNNING","timestamp":"2021-12-12T23:05:45.828732Z","tick_id":26934624,"best_bid":471674.0,"best_ask":472000.0,"best_bid_size":14.99995,"best_ask_size":0.770000,"total_bid_depth":3336.043367900000,"total_ask_depth":4475.56557320,"market_bid_size":0.0,"market_ask_size":0.0,"ltp":471722.0,"volume":10833.320505500000,"volume_by_product":10833.320505500000}}}
1639350346.0265448: {"jsonrpc":"2.0","method":"channelMessage","params":{"channel":"lightning_board_ETH_JPY","message":{"mid_price":471837.0,"bids":[{"price":471674.0,"size":14.99995}],"asks":[]}}}
1639350346.0299132: {"jsonrpc":"2.0","method":"channelMessage","params":{"channel":"lightning_ticker_FX_BTC_JPY","message":{"product_code":"FX_BTC_JPY","state":"RUNNING","timestamp":"2021-12-12T23:05:45.833413Z","tick_id":127091729,"best_bid":5862717.0,"best_ask":5864791.0,"best_bid_size":0.01,"best_ask_size":0.02,"total_bid_depth":232.082950790000,"total_ask_depth":294.678677830000,"market_bid_size":0.0,"market_ask_size":0.0,"ltp":5864792.000000,"volume":4227.682096850000,"volume_by_product":4227.682096850000}}}
1639350346.039453: {"jsonrpc":"2.0","method":"channelMessage","params":{"channel":"lightning_board_FX_BTC_JPY","message":{"mid_price":5863754.0,"bids":[{"price":5861081.0,"size":0.05},{"price":5859260.0,"size":0.0},{"price":5862042.0,"size":0.0},{"price":5861519.0,"size":0.05}],"asks":[{"price":5864792.0,"size":0.0},{"price":5865400.0,"size":0.0},{"price":5865024.0,"size":0.0},{"price":5869149.0,"size":0.02},{"price":5869043.0,"size":0.0}]}}}
1639350346.054045: {"jsonrpc":"2.0","method":"channelMessage","params":{"channel":"lightning_ticker_XLM_JPY","message":{"product_code":"XLM_JPY","state":"RUNNING","timestamp":"2021-12-12T23:05:45.9078079Z","tick_id":8300583,"best_bid":31.485,"best_ask":31.57,"best_bid_size":2854.18,"best_ask_size":750.95,"total_bid_depth":1851544.03493760,"total_ask_depth":2114360.197473400000,"market_bid_size":0.0,"market_ask_size":0.0,"ltp":31.471,"volume":1471420.073424000000,"volume_by_product":1471420.073424000000}}}
1639350346.055203: {"jsonrpc":"2.0","method":"channelMessage","params":{"channel":"lightning_board_XLM_JPY","message":{"mid_price":31.527,"bids":[{"price":31.485,"size":2854.18}],"asks":[{"price":31.571,"size":0.0}]}}}
1639350346.0629241: {"jsonrpc":"2.0","method":"channelMessage","params":{"channel":"lightning_board_BTC_USD","message":{"mid_price":50285.59,"bids":[{"price":49845.9,"size":0.27},{"price":49725.21,"size":1.115}],"asks":[{"price":50851.68,"size":1.125},{"price":50771.22,"size":0.45},{"price":50313.58,"size":0.0},{"price":50296.9,"size":0.09}]}}}
1639350346.183553: {"jsonrpc":"2.0","method":"channelMessage","params":{"channel":"lightning_board_FX_BTC_JPY","message":{"mid_price":5863754.0,"bids":[{"price":5862345.0,"size":0.1353},{"price":5855836.0,"size":0.0},{"price":5828264.0,"size":0.0},{"price":5862570.0,"size":0.02},{"price":5862546.0,"size":0.0},{"price":5855835.0,"size":0.0},{"price":5858025.0,"size":0.01},{"price":5851079.0,"size":0.0}],"asks":[{"price":5892166.0,"size":0.0},{"price":5865630.0,"size":0.01},{"price":5867589.0,"size":0.05},{"price":5880641.0,"size":0.0},{"price":5866570.0,"size":0.04946442},{"price":5866309.0,"size":0.0},{"price":5892123.0,"size":0.01},{"price":5869044.0,"size":0.0}]}}}
1639350346.183775: {"jsonrpc":"2.0","method":"channelMessage","params":{"channel":"lightning_board_XLM_JPY","message":{"mid_price":31.53,"bids":[{"price":31.49,"size":3979.0}],"asks":[]}}}
1639350346.211029: {"jsonrpc":"2.0","method":"channelMessage","params":{"channel":"lightning_board_BTC_USD","message":{"mid_price":50285.59,"bids":[{"price":50239.61,"size":0.0}],"asks":[]}}}
1639350346.305722: {"jsonrpc":"2.0","method":"channelMessage","params":{"channel":"lightning_executions_FX_BTC_JPY","message":[{"id":2284079870,"side":"BUY","price":5864791.0,"size":0.02,"exec_date":"2021-12-12T23:05:46.1666815Z","buy_child_order_acceptance_id":"JRF20211212-230546-175260","sell_child_order_acceptance_id":"JRF20211212-230545-202734"}]}}
1639350346.357184: {"jsonrpc":"2.0","method":"channelMessage","params":{"channel":"lightning_board_BTC_USD","message":{"mid_price":50285.59,"bids":[{"price":50263.53,"size":0.6003}],"asks":[{"price":50301.14,"size":0.0},{"price":50323.56,"size":0.6003},{"price":50308.69,"size":0.0}]}}}
1639350346.362566: {"jsonrpc":"2.0","method":"channelMessage","params":{"channel":"lightning_ticker_BTC_EUR","message":{"product_code":"BTC_EUR","state":"RUNNING","timestamp":"2021-12-12T23:05:46.2131311Z","tick_id":7240256,"best_bid":44461.19,"best_ask":44479.65,"best_bid_size":0.00118145,"best_ask_size":0.01,"total_bid_depth":14.75728901,"total_ask_depth":13.79546467,"market_bid_size":0.0,"market_ask_size":0.0,"ltp":44461.2,"volume":43.951523900000,"volume_by_product":43.951523900000}}}
1639350346.36786: {"jsonrpc":"2.0","method":"channelMessage","params":{"channel":"lightning_board_BTC_EUR","message":{"mid_price":44470.42,"bids":[],"asks":[{"price":44607.62,"size":0.0}]}}}
1639350346.3770518: {"jsonrpc":"2.0","method":"channelMessage","params":{"channel":"lightning_board_FX_BTC_JPY","message":{"mid_price":5864396.0,"bids":[{"price":5861761.0,"size":0.05},{"price":5863163.0,"size":0.03},{"price":5862820.0,"size":0.01},{"price":5858034.0,"size":0.02675347},{"price":5863033.0,"size":0.02290718},{"price":5833806.0,"size":0.01},{"price":5861748.0,"size":0.011}],"asks":[{"price":5871489.0,"size":0.0},{"price":5880558.0,"size":0.02675347},{"price":5864791.0,"size":0.0},{"price":5869879.0,"size":0.02913836},{"price":5867858.0,"size":0.05}]}}}
1639350346.392917: {"jsonrpc":"2.0","method":"channelMessage","params":{"channel":"lightning_board_ETH_JPY","message":{"mid_price":471837.0,"bids":[],"asks":[{"price":472383.0,"size":0.0}]}}}
1639350346.398772: {"jsonrpc":"2.0","method":"channelMessage","params":{"channel":"lightning_board_snapshot_BCH_BTC","message":{"mid_price":0.00921,"bids":[{"price":0.006,"size":2.0},{"price":0.0073,"size":0.1},{"price":0.0074,"size":0.1},{"price":0.0075,"size":0.1},{"price":0.00756,"size":0.29502},{"price":0.0076,"size":0.1},{"price":0.0077,"size":0.1},{"price":0.00775,"size":0.1},{"price":0.0078,"size":0.1},{"price":0.0079,"size":0.1},{"price":0.008,"size":0.1},{"price":0.0081,"size":0.1},{"price":0.00811,"size":10.0},{"price":0.0082,"size":0.1},{"price":0.0083,"size":0.1},{"price":0.0084,"size":0.0214},{"price":0.00844,"size":0.75},{"price":0.0085,"size":0.01},{"price":0.00852,"size":0.01},{"price":0.00853,"size":20.0},{"price":0.00854,"size":0.01},{"price":0.00856,"size":0.01},{"price":0.00858,"size":0.01},{"price":0.0086,"size":0.01},{"price":0.00862,"size":0.01},{"price":0.00864,"size":0.01},{"price":0.00866,"size":0.01},{"price":0.00868,"size":0.01},{"price":0.0087,"size":0.01},{"price":0.00872,"size":0.01},{"price":0.00874,"size":0.01},{"price":0.00876,"size":0.01},{"price":0.00878,"size":0.01},{"price":0.0088,"size":0.01},{"price":0.00882,"size":0.01},{"price":0.00884,"size":0.01},{"price":0.00885,"size":0.026},{"price":0.00886,"size":0.01},{"price":0.00888,"size":10.01},{"price":0.0089,"size":0.11},{"price":0.00892,"size":0.01},{"price":0.00894,"size":0.01},{"price":0.00896,"size":0.01},{"price":0.00898,"size":2.51},{"price":0.009,"size":0.23},{"price":0.00905,"size":0.1},{"price":0.00907,"size":17.918142},{"price":0.00908,"size":8.7},{"price":0.00912,"size":10.3},{"price":0.00916,"size":25.1},{"price":0.00918,"size":2.4},{"price":0.00919,"size":0.9}],"asks":[{"price":0.00923,"size":0.9},{"price":0.00924,"size":2.4},{"price":0.00928,"size":25.7},{"price":0.00936,"size":1.1},{"price":0.00963,"size":0.1},{"price":0.0097,"size":0.96510871},{"price":0.00975,"size":0.01},{"price":0.00976,"size":0.051},{"price":0.0098,"size":1.0},{"price":0.00984,"size":5.0},{"price":0.00985,"size":0.01},{"price":0.0099,"size":0.01},{"price":0.00994,"size":0.05},{"price":0.00995,"size":0.01},{"price":0.01,"size":0.21},{"price":0.01005,"size":0.21},{"price":0.0101,"size":0.21},{"price":0.01015,"size":2.8626601},{"price":0.0102,"size":0.21},{"price":0.01025,"size":0.21},{"price":0.0103,"size":0.21},{"price":0.01035,"size":0.21},{"price":0.01036,"size":0.1},{"price":0.01037,"size":0.1},{"price":0.0104,"size":0.21},{"price":0.01045,"size":0.21},{"price":0.0105,"size":0.21},{"price":0.01055,"size":0.01},{"price":0.0106,"size":0.21},{"price":0.01065,"size":0.01},{"price":0.0107,"size":0.21},{"price":0.01074,"size":0.1},{"price":0.01075,"size":0.01},{"price":0.0108,"size":4.855},{"price":0.01083,"size":0.1},{"price":0.01085,"size":0.01},{"price":0.01088,"size":0.01},{"price":0.0109,"size":0.31},{"price":0.01095,"size":0.01},{"price":0.011,"size":0.22},{"price":0.01105,"size":0.01},{"price":0.0111,"size":0.02},{"price":0.01115,"size":0.01},{"price":0.0112,"size":0.21},{"price":0.0114,"size":0.2},{"price":0.0115,"size":0.2},{"price":0.01156,"size":0.18952},{"price":0.0116,"size":0.2},{"price":0.0118,"size":0.2},{"price":0.012,"size":0.51},{"price":0.0121,"size":0.2},{"price":0.01243,"size":7.56559535},{"price":0.0125,"size":0.5},{"price":0.013,"size":0.51},{"price":0.0135,"size":0.5},{"price":0.014,"size":0.51},{"price":0.01413,"size":3.7},{"price":0.0145,"size":0.5},{"price":0.015,"size":1.14459141},{"price":0.0151,"size":2.0},{"price":0.0155,"size":0.5},{"price":0.016,"size":0.5},{"price":0.0165,"size":0.5},{"price":0.017,"size":0.5},{"price":0.0175,"size":0.5},{"price":0.018,"size":0.51},{"price":0.0185,"size":0.5},{"price":0.01891,"size":0.01},{"price":0.019,"size":0.51},{"price":0.01918,"size":9.96007985},{"price":0.0195,"size":0.5},{"price":0.02,"size":3.68802395}]}}}
1639350346.403201: {"jsonrpc":"2.0","method":"channelMessage","params":{"channel":"lightning_board_snapshot_BTC_USD","message":{"mid_price":50285.59,"bids":[{"price":30000.0,"size":0.002},{"price":35000.0,"size":0.05},{"price":38000.0,"size":0.1},{"price":40000.0,"size":0.13},{"price":41000.0,"size":0.103},{"price":41250.0,"size":0.003},{"price":41500.0,"size":0.003},{"price":42000.0,"size":0.04},{"price":44000.0,"size":0.01},{"price":44500.0,"size":0.01},{"price":45000.0,"size":0.033},{"price":45500.0,"size":0.01},{"price":46000.0,"size":0.01},{"price":46500.0,"size":0.01},{"price":46725.0,"size":0.10050619},{"price":47237.86,"size":0.89},{"price":47273.37,"size":0.76},{"price":47292.29,"size":1.03},{"price":47311.21,"size":1.19},{"price":48409.37,"size":0.45},{"price":48558.85,"size":1.1},{"price":48707.54,"size":1.0},{"price":48760.6,"size":0.675},{"price":49436.21,"size":0.98},{"price":49470.84,"size":0.78},{"price":49484.38,"size":0.54},{"price":49537.48,"size":0.95},{"price":49545.47,"size":0.45},{"price":49557.3,"size":0.96},{"price":49564.85,"size":0.41},{"price":49580.78,"size":0.45},{"price":49613.78,"size":1.0},{"price":49651.32,"size":1.0},{"price":49680.02,"size":0.9},{"price":49725.21,"size":1.115},{"price":49736.04,"size":0.95},{"price":49760.48,"size":0.675},{"price":49778.08,"size":0.84},{"price":49805.67,"size":0.45},{"price":49822.07,"size":1.26},{"price":49844.95,"size":0.18},{"price":49845.9,"size":0.27},{"price":49879.71,"size":0.27},{"price":49882.9,"size":0.18},{"price":49937.96,"size":1.0},{"price":50065.72,"size":1.0},{"price":50120.61,"size":0.01},{"price":50165.39,"size":1.29},{"price":50211.42,"size":0.11},{"price":50226.78,"size":0.57},{"price":50229.86,"size":1.0},{"price":50239.86,"size":0.01},{"price":50242.43,"size":0.05096228},{"price":50242.45,"size":0.01398398},{"price":50242.46,"size":0.04566142},{"price":50244.89,"size":0.01},{"price":50244.91,"size":0.15066957},{"price":50244.92,"size":0.04197325},{"price":50245.68,"size":0.6003},{"price":50253.22,"size":0.6003},{"price":50263.53,"size":0.6003},{"price":50274.27,"size":0.11},{"price":50274.28,"size":1.0}],"asks":[{"price":50296.9,"size":0.09},{"price":50306.35,"size":1.0},{"price":50316.83,"size":0.01},{"price":50323.56,"size":0.6003},{"price":50324.55,"size":0.1},{"price":50373.38,"size":0.07225738},{"price":50413.75,"size":0.5},{"price":50439.81,"size":0.04234589},{"price":50439.82,"size":0.07359133},{"price":50439.84,"size":1.0},{"price":50464.12,"size":1.0},{"price":50514.48,"size":1.0},{"price":50538.23,"size":1.3},{"price":50568.33,"size":2.0},{"price":50623.32,"size":0.01},{"price":50654.37,"size":0.88},{"price":50687.48,"size":0.18},{"price":50730.98,"size":0.27},{"price":50771.22,"size":0.45},{"price":50811.45,"size":0.675},{"price":50818.97,"size":0.8},{"price":50851.68,"size":1.125},{"price":50886.83,"size":0.9},{"price":50977.57,"size":0.9},{"price":51009.3,"size":0.41},{"price":51087.97,"size":0.54},{"price":51248.54,"size":1.1},{"price":51267.89,"size":0.54},{"price":51372.57,"size":0.9},{"price":51394.06,"size":0.79},{"price":51500.0,"size":0.2},{"price":51644.76,"size":0.8},{"price":52000.0,"size":0.03858975},{"price":52191.68,"size":0.892},{"price":54425.0,"size":0.001},{"price":68000.0,"size":1.09211295},{"price":75000.0,"size":0.70062066}]}}}
1639350346.409994: {"jsonrpc":"2.0","method":"channelMessage","params":{"channel":"lightning_board_snapshot_BTC_EUR","message":{"mid_price":44470.42,"bids":[{"price":27675.2,"size":0.353},{"price":30056.0,"size":0.1},{"price":32312.0,"size":0.062},{"price":35005.0,"size":0.25},{"price":35403.0,"size":0.0565},{"price":38300.0,"size":0.002},{"price":38400.0,"size":0.002},{"price":38500.0,"size":0.002},{"price":38600.0,"size":0.002},{"price":38700.0,"size":0.002},{"price":38800.0,"size":0.002},{"price":38824.29,"size":0.77},{"price":38900.0,"size":0.002},{"price":38981.11,"size":0.0754},{"price":39000.0,"size":0.002},{"price":39001.0,"size":0.2},{"price":39100.0,"size":0.002},{"price":39200.0,"size":0.002},{"price":39300.0,"size":0.002},{"price":39400.0,"size":0.002},{"price":39500.0,"size":0.002},{"price":39600.0,"size":0.002},{"price":39700.0,"size":0.002},{"price":39741.94,"size":1.02},{"price":39800.0,"size":0.002},{"price":39900.0,"size":0.002},{"price":40000.0,"size":0.002},{"price":40100.0,"size":0.002},{"price":40200.0,"size":0.002},{"price":40300.0,"size":0.002},{"price":40400.0,"size":0.004},{"price":40500.0,"size":0.002},{"price":40600.0,"size":0.002},{"price":40688.3,"size":0.7},{"price":40700.0,"size":0.002},{"price":40800.0,"size":0.004},{"price":40900.0,"size":0.002},{"price":40955.0,"size":0.03},{"price":40972.0,"size":0.03},{"price":40981.11,"size":0.03},{"price":41000.0,"size":0.002},{"price":41001.0,"size":0.1},{"price":41100.0,"size":0.002},{"price":41125.0,"size":0.03},{"price":41200.0,"size":0.002},{"price":41300.0,"size":0.002},{"price":41336.84,"size":0.9},{"price":41400.0,"size":0.002},{"price":41500.0,"size":0.002},{"price":41505.0,"size":0.05},{"price":41600.0,"size":0.002},{"price":41700.0,"size":0.002},{"price":41800.0,"size":0.004},{"price":41900.0,"size":0.002},{"price":41949.83,"size":1.2},{"price":42000.0,"size":0.002},{"price":42100.0,"size":0.002},{"price":42200.0,"size":0.002},{"price":42300.0,"size":0.002},{"price":42400.0,"size":0.002},{"price":42500.0,"size":0.002},{"price":42600.0,"size":0.002},{"price":42700.0,"size":0.001},{"price":42786.32,"size":0.18},{"price":42800.0,"size":0.001},{"price":42861.18,"size":1.8},{"price":42900.0,"size":0.001},{"price":43000.0,"size":0.001},{"price":43091.16,"size":1.4},{"price":43100.0,"size":0.001},{"price":43113.73,"size":0.18},{"price":43200.0,"size":0.001},{"price":43300.0,"size":0.001},{"price":43400.0,"size":0.001},{"price":43500.0,"size":0.001},{"price":43558.56,"size":0.8},{"price":43600.0,"size":0.001},{"price":43711.82,"size":1.0},{"price":43711.83,"size":0.01},{"price":43904.41,"size":0.18},{"price":44149.97,"size":0.01},{"price":44221.6,"size":0.00107479},{"price":44239.14,"size":0.18},{"price":44239.98,"size":0.01},{"price":44248.15,"size":0.00110903},{"price":44274.69,"size":0.00131169},{"price":44300.53,"size":0.18},{"price":44301.29,"size":0.00115867},{"price":44325.79,"size":0.18},{"price":44327.9,"size":0.00117149},{"price":44327.91,"size":0.3005332},{"price":44349.49,"size":0.3},{"price":44354.5,"size":0.00118117},{"price":44354.87,"size":0.18},{"price":44356.59,"size":0.50134},{"price":44381.14,"size":0.00130283},{"price":44383.66,"size":0.50134},{"price":44401.54,"size":0.01},{"price":44405.1,"size":0.1},{"price":44407.34,"size":0.50134},{"price":44407.75,"size":0.00121377},{"price":44417.1,"size":0.01},{"price":44420.67,"size":0.15},{"price":44432.66,"size":0.02},{"price":44434.52,"size":0.00113092},{"price":44461.19,"size":0.00118145}],"asks":[{"price":44479.65,"size":0.01},{"price":44491.31,"size":0.50134},{"price":44514.08,"size":0.1},{"price":44514.55,"size":0.0010134},{"price":44518.0,"size":0.50134},{"price":44529.65,"size":0.1},{"price":44531.7,"size":0.50134},{"price":44541.28,"size":0.00100978},{"price":44568.0,"size":0.00107131},{"price":44568.32,"size":0.1},{"price":44576.35,"size":0.1574203},{"price":44576.36,"size":0.01},{"price":44583.9,"size":0.01},{"price":44590.97,"size":0.056},{"price":44594.58,"size":0.01},{"price":44594.74,"size":0.00110449},{"price":44621.5,"size":0.00118707},{"price":44648.27,"size":0.00115137},{"price":44661.02,"size":0.19},{"price":44675.06,"size":0.00123005},{"price":44701.57,"size":0.18},{"price":44701.87,"size":0.00100114},{"price":44728.69,"size":0.00125068},{"price":44755.53,"size":0.00100508},{"price":44768.15,"size":0.1},{"price":44863.71,"size":0.74},{"price":44953.12,"size":1.0},{"price":45000.0,"size":0.001},{"price":45200.0,"size":0.001},{"price":45400.0,"size":0.001},{"price":45427.27,"size":1.1},{"price":45573.78,"size":1.2},{"price":45600.0,"size":0.001},{"price":45800.0,"size":0.001},{"price":45914.15,"size":1.5},{"price":46000.0,"size":0.001},{"price":46200.0,"size":0.001},{"price":46400.0,"size":0.001},{"price":46600.0,"size":0.001},{"price":46777.42,"size":0.94},{"price":46800.0,"size":0.001},{"price":47000.0,"size":1.001},{"price":47200.0,"size":0.001},{"price":47400.0,"size":0.001},{"price":47498.64,"size":0.73},{"price":47600.0,"size":0.001},{"price":47800.0,"size":0.001},{"price":47883.35,"size":0.9},{"price":48000.0,"size":0.001},{"price":48200.0,"size":0.001},{"price":48400.0,"size":0.001},{"price":48600.0,"size":0.001},{"price":48800.0,"size":0.001},{"price":49000.0,"size":0.001},{"price":49073.85,"size":1.09},{"price":49200.0,"size":0.001},{"price":49400.0,"size":0.001},{"price":49600.0,"size":0.001},{"price":49800.0,"size":0.001},{"price":50000.0,"size":0.001},{"price":50157.03,"size":0.98},{"price":50200.0,"size":0.001},{"price":50400.0,"size":0.001},{"price":50600.0,"size":0.001},{"price":50800.0,"size":0.001},{"price":51000.0,"size":0.001},{"price":51200.0,"size":0.002},{"price":51400.0,"size":0.001},{"price":51600.0,"size":0.001},{"price":51800.0,"size":0.001},{"price":52000.0,"size":0.001},{"price":52200.0,"size":0.001},{"price":52400.0,"size":0.001},{"price":52600.0,"size":0.001},{"price":52800.0,"size":0.001},{"price":53000.0,"size":0.001},{"price":53200.0,"size":0.001},{"price":53400.0,"size":0.001},{"price":53600.0,"size":0.001},{"price":53800.0,"size":0.001},{"price":54000.0,"size":0.001},{"price":54200.0,"size":0.001},{"price":54400.0,"size":0.001},{"price":54600.0,"size":0.001},{"price":54800.0,"size":0.001},{"price":55000.0,"size":0.001},{"price":55200.0,"size":0.001},{"price":55400.0,"size":0.001},{"price":55600.0,"size":0.001},{"price":55800.0,"size":0.001},{"price":56000.0,"size":0.001},{"price":56200.0,"size":0.001},{"price":56400.0,"size":0.001},{"price":56600.0,"size":0.001},{"price":56800.0,"size":0.001},{"price":57000.0,"size":0.001},{"price":57200.0,"size":0.001},{"price":57400.0,"size":0.001},{"price":57600.0,"size":0.001},{"price":57800.0,"size":0.001},{"price":59400.0,"size":0.001},{"price":59600.0,"size":0.001},{"price":59800.0,"size":0.001},{"price":60000.0,"size":0.002},{"price":63000.0,"size":0.001},{"price":67200.0,"size":0.001},{"price":67400.0,"size":0.001},{"price":67600.0,"size":0.001},{"price":67800.0,"size":0.001},{"price":68000.0,"size":0.001}]}}}
1639350346.42447: {"jsonrpc":"2.0","method":"channelMessage","params":{"channel":"lightning_board_snapshot_ETH_JPY","message":{"mid_price":471866.0,"bids":[{"price":471732.0,"size":0.67},{"price":471674.0,"size":14.99995},{"price":471615.0,"size":0.75},{"price":471614.0,"size":1.38},{"price":471596.0,"size":0.75},{"price":471529.0,"size":5.013},{"price":471516.0,"size":0.58},{"price":471379.0,"size":1.37},{"price":471200.0,"size":44.0},{"price":471171.0,"size":0.75},{"price":471156.0,"size":0.75},{"price":471148.0,"size":0.75},{"price":471144.0,"size":0.75},{"price":471123.0,"size":0.75},{"price":470988.0,"size":0.01},{"price":470813.0,"size":0.7},{"price":470631.0,"size":6.0},{"price":469913.0,"size":0.22},{"price":469833.0,"size":6.08},{"price":469644.0,"size":0.01},{"price":469522.0,"size":2.1},{"price":469399.0,"size":14.83},{"price":469356.0,"size":1.0},{"price":469336.0,"size":0.7},{"price":469207.0,"size":6.0},{"price":469020.0,"size":0.8},{"price":468944.0,"size":0.1},{"price":468222.0,"size":119.3},{"price":468098.0,"size":0.7},{"price":468017.0,"size":0.99},{"price":468007.0,"size":1.0},{"price":468000.0,"size":1.9},{"price":467941.0,"size":0.05},{"price":467700.0,"size":0.01},{"price":467585.0,"size":0.07},{"price":467526.0,"size":0.01},{"price":467252.0,"size":2.385},{"price":467075.0,"size":0.1},{"price":467074.0,"size":0.43},{"price":467004.0,"size":0.1},{"price":467000.0,"size":0.783},{"price":466501.0,"size":8.0},{"price":466260.0,"size":5.26},{"price":466228.0,"size":0.129},{"price":466100.0,"size":4.33},{"price":466000.0,"size":0.02},{"price":465720.0,"size":2.044312},{"price":465700.0,"size":0.5},{"price":465591.0,"size":58.73},{"price":465555.0,"size":0.7},{"price":465500.0,"size":0.5},{"price":465250.0,"size":0.5},{"price":465181.0,"size":1.33},{"price":465123.0,"size":0.1},{"price":465000.0,"size":9.458},{"price":464979.0,"size":0.01},{"price":464228.0,"size":0.129},{"price":464000.0,"size":0.0202},{"price":463230.0,"size":30.35},{"price":462990.0,"size":0.4},{"price":462500.0,"size":0.51},{"price":462228.0,"size":0.13},{"price":462000.0,"size":0.51},{"price":461000.0,"size":0.51},{"price":460946.0,"size":14.99},{"price":460742.0,"size":0.01},{"price":460724.0,"size":0.01},{"price":460563.0,"size":1.9},{"price":460321.0,"size":0.95},{"price":460250.0,"size":0.5},{"price":460228.0,"size":0.13},{"price":460123.0,"size":0.21},{"price":460111.0,"size":0.1},{"price":460106.0,"size":1.0},{"price":460010.0,"size":0.012},{"price":460000.0,"size":8.686101},{"price":459855.0,"size":0.2},{"price":459740.0,"size":62.247},{"price":459000.0,"size":32.5202},{"price":458819.0,"size":0.89},{"price":458545.0,"size":0.1},{"price":458500.0,"size":0.05},{"price":458228.0,"size":0.131},{"price":458151.0,"size":0.01},{"price":458090.0,"size":1.0},{"price":458000.0,"size":13.06},{"price":457976.0,"size":0.1},{"price":457777.0,"size":0.1},{"price":457500.0,"size":0.51},{"price":457136.0,"size":0.013},{"price":457000.0,"size":4.74},{"price":456870.0,"size":0.01},{"price":456500.0,"size":0.5},{"price":456253.0,"size":0.1},{"price":456243.0,"size":15.44},{"price":456228.0,"size":0.132},{"price":456213.0,"size":0.5},{"price":456100.0,"size":0.030696},{"price":456000.0,"size":1.7907},{"price":455968.0,"size":0.1},{"price":455777.0,"size":0.04},{"price":455507.0,"size":0.01},{"price":455500.0,"size":0.61},{"price":455438.0,"size":0.01},{"price":455250.0,"size":0.5},{"price":455111.0,"size":0.1},{"price":455044.0,"size":0.386},{"price":455000.0,"size":6.0746},{"price":454947.0,"size":1.1},{"price":454900.0,"size":0.05},{"price":454600.0,"size":0.11},{"price":454500.0,"size":0.238},{"price":454485.0,"size":0.01},{"price":454228.0,"size":0.132},{"price":454000.0,"size":15.191629},{"price":453865.0,"size":1.0},{"price":453750.0,"size":0.5},{"price":453610.0,"size":0.1},{"price":453601.0,"size":0.99},{"price":453500.0,"size":0.4},{"price":453492.0,"size":0.14},{"price":453112.0,"size":0.01},{"price":453006.0,"size":0.3},{"price":453003.0,"size":3.640905},{"price":453001.0,"size":8.0},{"price":453000.0,"size":3.4605},{"price":452787.0,"size":0.6747411},{"price":452500.0,"size":0.1204972},{"price":452369.0,"size":0.5},{"price":452244.0,"size":0.030957},{"price":452228.0,"size":0.133},{"price":452112.0,"size":0.01},{"price":452111.0,"size":0.01},{"price":452100.0,"size":0.07},{"price":452000.0,"size":1.854607},{"price":451880.0,"size":0.1},{"price":451820.0,"size":0.3},{"price":451800.0,"size":0.07},{"price":451600.0,"size":1.05},{"price":451555.0,"size":6.0},{"price":451539.0,"size":14.75},{"price":451500.0,"size":0.11},{"price":451250.0,"size":0.11},{"price":451200.0,"size":0.07},{"price":451176.0,"size":0.01},{"price":451111.0,"size":5.01},{"price":451001.0,"size":0.7},{"price":451000.0,"size":0.71},{"price":450900.0,"size":0.1},{"price":450740.0,"size":4.0},{"price":450600.0,"size":0.1},{"price":450500.0,"size":0.02},{"price":450300.0,"size":0.1},{"price":450250.0,"size":0.5},{"price":450228.0,"size":0.133},{"price":450210.0,"size":0.31},{"price":450111.0,"size":0.55},{"price":450106.0,"size":1.0},{"price":450038.0,"size":0.01},{"price":450020.0,"size":5.0},{"price":450010.0,"size":0.4340547},{"price":450008.0,"size":0.05},{"price":450002.0,"size":0.125},{"price":450001.0,"size":0.62697},{"price":450000.0,"size":40.3350369},{"price":449990.0,"size":0.45},{"price":449700.0,"size":0.1},{"price":449580.0,"size":0.1},{"price":449400.0,"size":1.11},{"price":449111.0,"size":0.02},{"price":449100.0,"size":0.1},{"price":449000.0,"size":0.32},{"price":448980.0,"size":0.1},{"price":448900.0,"size":0.5},{"price":448888.0,"size":0.2005},{"price":448800.0,"size":0.1},{"price":448587.0,"size":0.1},{"price":448565.0,"size":0.05},{"price":448500.0,"size":0.15},{"price":448300.0,"size":0.03},{"price":448230.0,"size":0.2},{"price":448228.0,"size":0.134},{"price":448222.0,"size":5.0},{"price":448200.0,"size":0.1},{"price":448111.0,"size":0.01},{"price":448001.0,"size":0.015},{"price":448000.0,"size":11.4566045},{"price":447800.0,"size":0.23},{"price":447700.0,"size":0.031},{"price":447576.0,"size":0.01},{"price":447502.0,"size":0.125},{"price":447500.0,"size":0.03},{"price":447252.0,"size":1.1},{"price":447136.0,"size":0.013},{"price":447111.0,"size":0.01},{"price":447000.0,"size":1.46},{"price":446836.0,"size":14.76},{"price":446543.0,"size":0.53},{"price":446500.0,"size":2.17},{"price":446489.0,"size":1.0},{"price":446400.0,"size":0.3},{"price":446397.0,"size":0.01},{"price":446228.0,"size":0.134},{"price":446111.0,"size":0.04},{"price":446000.0,"size":2.870067},{"price":445973.0,"size":0.1121121},{"price":445900.0,"size":0.01},{"price":445885.0,"size":0.02},{"price":445858.0,"size":0.01},{"price":445700.0,"size":0.01},{"price":445670.0,"size":0.2},{"price":445555.0,"size":1.0},{"price":445525.0,"size":0.012134},{"price":445500.0,"size":1.285},{"price":445451.0,"size":1.0},{"price":445188.0,"size":0.3},{"price":445111.0,"size":0.12},{"price":445088.0,"size":0.2},{"price":445011.0,"size":0.3},{"price":445008.0,"size":0.01},{"price":445002.0,"size":0.125},{"price":445001.0,"size":0.03},{"price":445000.0,"size":9.6017349},{"price":444924.0,"size":0.01},{"price":444900.0,"size":0.06743},{"price":444502.0,"size":0.01},{"price":444500.0,"size":0.25},{"price":444444.0,"size":1.21},{"price":444400.0,"size":0.01},{"price":444309.0,"size":0.01},{"price":444228.0,"size":0.135},{"price":444111.0,"size":0.01},{"price":444050.0,"size":0.017},{"price":444023.0,"size":0.01},{"price":444000.0,"size":7.020865},{"price":443944.0,"size":0.01},{"price":443739.0,"size":1.0},{"price":443502.0,"size":0.01},{"price":443500.0,"size":0.043822},{"price":443400.0,"size":1.0},{"price":443300.0,"size":0.01},{"price":443111.0,"size":0.01},{"price":443002.0,"size":1.0},{"price":443000.0,"size":0.50436},{"price":442921.0,"size":0.01},{"price":442844.0,"size":0.11},{"price":442502.0,"size":0.135},{"price":442500.0,"size":0.05},{"price":442450.0,"size":0.03},{"price":442350.0,"size":0.6},{"price":442258.0,"size":6.0},{"price":442228.0,"size":0.136},{"price":442111.0,"size":0.01},{"price":442000.0,"size":2.3356125},{"price":441888.0,"size":0.1},{"price":441502.0,"size":0.01},{"price":441410.0,"size":1.0},{"price":441249.0,"size":0.01},{"price":441200.0,"size":5.0},{"price":441111.0,"size":1.01},{"price":441100.0,"size":0.3},{"price":441008.0,"size":0.1},{"price":441000.0,"size":22.025},{"price":440888.0,"size":0.2},{"price":440700.0,"size":2.0},{"price":440666.0,"size":0.5},{"price":440603.0,"size":0.01},{"price":440600.0,"size":0.01},{"price":440500.0,"size":0.029},{"price":440228.0,"size":0.136},{"price":440212.0,"size":0.11356},{"price":440139.0,"size":0.2},{"price":440111.0,"size":0.13},{"price":440099.0,"size":0.01},{"price":440088.0,"size":0.3},{"price":440070.0,"size":0.01},{"price":440050.0,"size":0.2},{"price":440010.0,"size":0.01},{"price":440008.0,"size":0.1},{"price":440002.0,"size":0.125},{"price":440001.0,"size":0.1},{"price":440000.0,"size":40.446149},{"price":439999.0,"size":0.1},{"price":439807.0,"size":0.01},{"price":439800.0,"size":0.1},{"price":439500.0,"size":0.05},{"price":439495.0,"size":0.505125},{"price":439157.0,"size":0.10025},{"price":439115.0,"size":1.0},{"price":439111.0,"size":0.03},{"price":439100.0,"size":0.642},{"price":439000.0,"size":8.28319},{"price":438845.0,"size":1.0},{"price":438666.0,"size":0.5},{"price":438598.0,"size":0.01},{"price":438575.0,"size":0.1},{"price":438500.0,"size":0.05},{"price":438456.0,"size":0.01},{"price":438357.0,"size":0.01},{"price":438257.0,"size":0.05}],"asks":[{"price":472000.0,"size":0.77},{"price":472016.0,"size":0.75},{"price":472024.0,"size":0.75},{"price":472037.0,"size":0.75},{"price":472038.0,"size":0.75},{"price":472088.0,"size":0.75},{"price":472094.0,"size":0.75},{"price":472105.0,"size":0.75},{"price":472200.0,"size":0.02},{"price":472252.0,"size":0.01},{"price":472384.0,"size":5.013},{"price":472400.0,"size":0.02},{"price":472500.0,"size":0.01},{"price":472600.0,"size":0.02},{"price":472639.0,"size":0.5},{"price":472696.0,"size":4.202},{"price":472721.0,"size":6.0},{"price":472752.0,"size":0.01},{"price":472800.0,"size":0.02},{"price":472822.0,"size":0.7},{"price":472860.0,"size":44.0},{"price":472900.0,"size":0.013},{"price":472902.0,"size":14.83},{"price":472939.0,"size":6.0},{"price":473000.0,"size":0.33},{"price":473038.0,"size":1.01},{"price":473050.0,"size":0.010613},{"price":473083.0,"size":6.08},{"price":473163.0,"size":0.06},{"price":473200.0,"size":0.02},{"price":473212.0,"size":0.029586},{"price":473252.0,"size":0.01},{"price":473300.0,"size":0.11},{"price":473400.0,"size":0.53},{"price":473473.0,"size":0.2},{"price":473500.0,"size":0.01},{"price":473550.0,"size":0.1050705},{"price":473599.0,"size":0.3005},{"price":473600.0,"size":1.03},{"price":473700.0,"size":0.01},{"price":473718.0,"size":0.5},{"price":473752.0,"size":0.01},{"price":473772.0,"size":0.0146843},{"price":473800.0,"size":0.03},{"price":473900.0,"size":0.01},{"price":473960.0,"size":117.31},{"price":473968.0,"size":0.09},{"price":473997.0,"size":0.01},{"price":474000.0,"size":1.2201},{"price":474051.0,"size":0.57},{"price":474100.0,"size":0.01},{"price":474200.0,"size":0.03},{"price":474300.0,"size":0.01},{"price":474400.0,"size":0.05},{"price":474450.0,"size":0.5},{"price":474480.0,"size":0.7},{"price":474500.0,"size":0.02},{"price":474535.0,"size":0.15},{"price":474558.0,"size":0.02},{"price":474600.0,"size":0.03},{"price":474650.0,"size":0.5},{"price":474656.0,"size":0.01},{"price":474700.0,"size":0.01},{"price":474800.0,"size":0.03},{"price":474882.0,"size":0.12},{"price":474888.0,"size":0.1},{"price":474900.0,"size":0.01},{"price":474950.0,"size":0.5},{"price":474997.0,"size":0.21},{"price":475000.0,"size":12.0154268},{"price":475123.0,"size":0.66},{"price":475436.0,"size":0.07},{"price":475457.0,"size":1.0},{"price":475555.0,"size":0.05},{"price":475750.0,"size":0.01},{"price":475880.0,"size":3.0},{"price":475899.0,"size":0.027},{"price":475997.0,"size":0.01},{"price":476000.0,"size":2.2872},{"price":476434.0,"size":1.9626441},{"price":476468.0,"size":0.07},{"price":476600.0,"size":0.1},{"price":476678.0,"size":0.011},{"price":476750.0,"size":0.02},{"price":476800.0,"size":0.1},{"price":476880.0,"size":2.0},{"price":476882.0,"size":0.12},{"price":476997.0,"size":0.51},{"price":477000.0,"size":1.4196},{"price":477011.0,"size":58.97},{"price":477098.0,"size":0.01},{"price":477136.0,"size":0.013},{"price":477179.0,"size":0.07},{"price":477343.0,"size":0.01},{"price":477500.0,"size":0.02},{"price":477777.0,"size":1.0498702},{"price":477880.0,"size":2.0},{"price":477997.0,"size":0.01},{"price":478000.0,"size":2.2186},{"price":478092.0,"size":0.01},{"price":478200.0,"size":0.25},{"price":478343.0,"size":0.01},{"price":478600.0,"size":0.4},{"price":478750.0,"size":0.01},{"price":478800.0,"size":12.1},{"price":478882.0,"size":0.12},{"price":478888.0,"size":9.99},{"price":478900.0,"size":1.5},{"price":478997.0,"size":0.01},{"price":479000.0,"size":1.9},{"price":479198.0,"size":0.01},{"price":479343.0,"size":0.01},{"price":479500.0,"size":51.0976115},{"price":479650.0,"size":0.5},{"price":479750.0,"size":0.02},{"price":479800.0,"size":0.2},{"price":479827.0,"size":29.93},{"price":479837.0,"size":0.01},{"price":479880.0,"size":2.0},{"price":479888.0,"size":0.1},{"price":479996.0,"size":0.2},{"price":479997.0,"size":0.01},{"price":479999.0,"size":0.496919},{"price":480000.0,"size":25.898},{"price":480021.0,"size":10.025},{"price":480038.0,"size":0.02},{"price":480113.0,"size":0.01},{"price":480200.0,"size":0.2},{"price":480250.0,"size":5.0},{"price":480343.0,"size":0.01},{"price":480447.0,"size":4.0},{"price":480480.0,"size":1.0},{"price":480500.0,"size":0.81},{"price":480527.0,"size":0.1},{"price":480680.0,"size":0.4},{"price":480700.0,"size":0.03},{"price":480750.0,"size":0.02},{"price":480800.0,"size":0.1},{"price":480882.0,"size":0.12},{"price":480899.0,"size":0.02},{"price":480990.0,"size":0.013},{"price":480997.0,"size":0.02},{"price":481000.0,"size":5.574676},{"price":481126.0,"size":0.5},{"price":481140.0,"size":0.01},{"price":481200.0,"size":1.0815},{"price":481234.0,"size":0.66},{"price":481239.0,"size":0.1499476},{"price":481351.0,"size":0.011},{"price":481456.0,"size":0.2},{"price":481480.0,"size":1.0},{"price":481500.0,"size":0.5},{"price":481800.0,"size":0.1},{"price":481997.0,"size":0.01},{"price":482000.0,"size":4.669},{"price":482162.0,"size":0.01},{"price":482187.0,"size":15.37},{"price":482222.0,"size":0.4},{"price":482400.0,"size":1.49},{"price":482480.0,"size":1.0},{"price":482500.0,"size":0.01},{"price":482531.0,"size":10.0},{"price":482572.0,"size":0.2},{"price":482750.0,"size":0.02},{"price":482800.0,"size":0.11},{"price":482882.0,"size":0.12},{"price":482997.0,"size":0.01},{"price":483000.0,"size":7.3},{"price":483203.0,"size":5.1},{"price":483300.0,"size":0.5},{"price":483333.0,"size":0.01},{"price":483480.0,"size":1.0},{"price":483500.0,"size":0.01},{"price":483645.0,"size":0.01},{"price":483800.0,"size":0.1},{"price":483997.0,"size":0.01},{"price":484000.0,"size":4.84},{"price":484450.0,"size":0.3},{"price":484480.0,"size":3.0},{"price":484487.0,"size":0.01},{"price":484721.0,"size":0.11},{"price":484800.0,"size":0.2},{"price":484882.0,"size":0.12},{"price":484888.0,"size":0.1},{"price":484901.0,"size":20.0},{"price":484997.0,"size":0.02},{"price":485000.0,"size":33.6485951},{"price":485113.0,"size":0.01},{"price":485322.0,"size":0.0997403},{"price":485480.0,"size":1.0},{"price":485631.0,"size":0.01},{"price":485675.0,"size":0.01},{"price":485678.0,"size":0.5},{"price":485680.0,"size":0.14},{"price":485750.0,"size":0.01},{"price":485800.0,"size":0.1},{"price":485880.0,"size":5.0},{"price":485983.0,"size":20.0},{"price":485997.0,"size":0.01},{"price":486000.0,"size":5.6921733},{"price":486024.0,"size":0.011},{"price":486373.0,"size":0.01},{"price":486438.0,"size":14.75},{"price":486446.0,"size":0.1},{"price":486480.0,"size":1.0},{"price":486500.0,"size":0.01},{"price":486544.0,"size":0.05},{"price":486786.0,"size":0.01},{"price":486800.0,"size":0.1},{"price":486882.0,"size":0.12},{"price":486900.0,"size":0.06},{"price":486901.0,"size":20.0},{"price":486997.0,"size":0.01},{"price":487000.0,"size":2.2},{"price":487136.0,"size":0.013},{"price":487480.0,"size":1.0},{"price":487500.0,"size":0.01},{"price":487600.0,"size":0.05},{"price":487786.0,"size":0.01},{"price":487800.0,"size":1.0},{"price":487950.0,"size":0.04},{"price":487997.0,"size":0.01},{"price":488000.0,"size":0.893282},{"price":488465.0,"size":0.05},{"price":488480.0,"size":1.0},{"price":488600.0,"size":0.5},{"price":488786.0,"size":0.01},{"price":488800.0,"size":0.1},{"price":488880.0,"size":5.0},{"price":488882.0,"size":0.12},{"price":488888.0,"size":11.4321},{"price":488997.0,"size":0.01},{"price":489000.0,"size":18.7607},{"price":489463.0,"size":0.1},{"price":489480.0,"size":1.0},{"price":489500.0,"size":0.01},{"price":489600.0,"size":0.14},{"price":489650.0,"size":0.5},{"price":489786.0,"size":0.01},{"price":489788.0,"size":0.1},{"price":489800.0,"size":0.8},{"price":489840.0,"size":0.01},{"price":489900.0,"size":1.0},{"price":489997.0,"size":0.01},{"price":489999.0,"size":0.1},{"price":490000.0,"size":35.129675},{"price":490001.0,"size":0.2},{"price":490300.0,"size":0.01},{"price":490480.0,"size":1.0},{"price":490698.0,"size":0.011},{"price":490786.0,"size":0.01},{"price":490800.0,"size":0.1},{"price":490882.0,"size":0.12},{"price":490997.0,"size":0.01},{"price":491000.0,"size":8.65},{"price":491160.0,"size":14.78},{"price":491300.0,"size":0.04},{"price":491480.0,"size":1.0},{"price":491786.0,"size":0.01},{"price":491800.0,"size":0.3},{"price":491882.0,"size":0.01},{"price":491997.0,"size":0.01},{"price":491999.0,"size":0.12},{"price":492000.0,"size":2.0017},{"price":492445.0,"size":0.01},{"price":492480.0,"size":1.0},{"price":492500.0,"size":1.05},{"price":492786.0,"size":0.01},{"price":492800.0,"size":0.6},{"price":492882.0,"size":0.12},{"price":492997.0,"size":0.01},{"price":493000.0,"size":9.9},{"price":493341.0,"size":0.1},{"price":493433.0,"size":0.01},{"price":493480.0,"size":1.0},{"price":493493.0,"size":0.2},{"price":493500.0,"size":0.02},{"price":493630.0,"size":0.15},{"price":493786.0,"size":0.01},{"price":493800.0,"size":0.1},{"price":493997.0,"size":0.01},{"price":494000.0,"size":2.43},{"price":494480.0,"size":1.0},{"price":494500.0,"size":0.17},{"price":494882.0,"size":0.12},{"price":494997.0,"size":0.01},{"price":494998.0,"size":0.9581203},{"price":495000.0,"size":47.963267},{"price":495480.0,"size":1.0},{"price":495500.0,"size":0.03},{"price":495572.0,"size":0.01},{"price":495700.0,"size":0.10027},{"price":495883.0,"size":15.33},{"price":495960.0,"size":0.01},{"price":495997.0,"size":0.01},{"price":496000.0,"size":3.439},{"price":496012.0,"size":0.98},{"price":496044.0,"size":0.01},{"price":496300.0,"size":0.01},{"price":496480.0,"size":1.0}]}}}
1639350346.4327521: {"jsonrpc":"2.0","method":"channelMessage","params":{"channel":"lightning_board_snapshot_XRP_JPY","message":{"mid_price":96.05,"bids":[{"price":95.98,"size":620.28},{"price":95.97,"size":17012.54584},{"price":95.87,"size":10363.0},{"price":95.84,"size":11356.239},{"price":95.83,"size":9000.0},{"price":95.81,"size":10580.0},{"price":95.73,"size":5540.0},{"price":95.6,"size":5070.0},{"price":95.57,"size":13710.0},{"price":95.5,"size":82.934},{"price":95.42,"size":9000.0},{"price":95.4,"size":70.0},{"price":95.36,"size":137270.0},{"price":95.3,"size":5070.0},{"price":95.2,"size":70.0},{"price":95.16,"size":473.0},{"price":95.1,"size":70.0},{"price":95.0,"size":1954.1},{"price":94.9,"size":70.0},{"price":94.8,"size":1889.0},{"price":94.78,"size":53820.0},{"price":94.7,"size":70.0},{"price":94.6,"size":1570.0},{"price":94.5,"size":1072.0},{"price":94.42,"size":13530.0},{"price":94.4,"size":70.0},{"price":94.3,"size":70.0},{"price":94.2,"size":70.0},{"price":94.17,"size":27230.0},{"price":94.1,"size":70.0},{"price":94.0,"size":1677.0},{"price":93.99,"size":15.859},{"price":93.9,"size":70.0},{"price":93.8,"size":80.0},{"price":93.7,"size":70.0},{"price":93.6,"size":70.0},{"price":93.5,"size":74.0},{"price":93.45,"size":70.0},{"price":93.4,"size":87.0},{"price":93.32,"size":5.0},{"price":93.3,"size":70.0},{"price":93.2,"size":70.0},{"price":93.18,"size":3938.63},{"price":93.12,"size":40.0},{"price":93.1,"size":70.0},{"price":93.0,"size":13631.301075},{"price":92.97,"size":13470.0},{"price":92.9,"size":70.0},{"price":92.8,"size":70.0},{"price":92.7,"size":70.0},{"price":92.6,"size":70.0},{"price":92.51,"size":0.2},{"price":92.5,"size":899.0},{"price":92.49,"size":0.11},{"price":92.41,"size":0.2},{"price":92.4,"size":500.0},{"price":92.31,"size":0.2},{"price":92.3,"size":70.0},{"price":92.21,"size":0.2},{"price":92.2,"size":70.0},{"price":92.11,"size":0.2},{"price":92.1,"size":81.4},{"price":92.01,"size":0.2},{"price":92.0,"size":5724.043395},{"price":91.95,"size":0.495},{"price":91.92,"size":100.0},{"price":91.91,"size":0.2},{"price":91.9,"size":70.0},{"price":91.81,"size":0.2},{"price":91.8,"size":2757.0},{"price":91.7,"size":70.0},{"price":91.6,"size":70.0},{"price":91.53,"size":13740.0},{"price":91.5,"size":110.0},{"price":91.4,"size":70.0},{"price":91.3,"size":70.0},{"price":91.2,"size":70.0},{"price":91.1,"size":70.0},{"price":91.0,"size":6164.681318},{"price":90.98,"size":1000.0},{"price":90.92,"size":100.0},{"price":90.9,"size":70.0},{"price":90.8,"size":102.0},{"price":90.7,"size":70.0},{"price":90.6,"size":70.0},{"price":90.53,"size":100.0},{"price":90.5,"size":610.0},{"price":90.4,"size":70.0},{"price":90.3,"size":89.2},{"price":90.2,"size":70.0},{"price":90.19,"size":27.0},{"price":90.1,"size":240.0},{"price":90.01,"size":600.0},{"price":90.0,"size":19541.055555},{"price":89.99,"size":10.0},{"price":89.92,"size":100.0},{"price":89.9,"size":55.0},{"price":89.75,"size":100.0},{"price":89.7,"size":60.0},{"price":89.6,"size":1000.0},{"price":89.5,"size":4570.0},{"price":89.41,"size":500.0},{"price":89.3,"size":100.0},{"price":89.19,"size":300.0},{"price":89.15,"size":207.7},{"price":89.12,"size":2.0},{"price":89.1,"size":50.0},{"price":89.02,"size":300.51},{"price":89.01,"size":1000.0},{"price":89.0,"size":8203.861797},{"price":88.9,"size":405.0},{"price":88.84,"size":60.0},{"price":88.82,"size":112.589},{"price":88.7,"size":22.6},{"price":88.69,"size":1000.0},{"price":88.55,"size":420.0},{"price":88.5,"size":3081.0},{"price":88.29,"size":150.0},{"price":88.15,"size":2500.0},{"price":88.11,"size":156.0},{"price":88.1,"size":50.0},{"price":88.01,"size":1100.0},{"price":88.0,"size":26751.62},{"price":87.9,"size":1105.0},{"price":87.86,"size":500.0},{"price":87.68,"size":400.0},{"price":87.5,"size":4345.0},{"price":87.33,"size":1150.0},{"price":87.2,"size":103.165137},{"price":87.1,"size":50.0},{"price":87.01,"size":1000.0},{"price":87.0,"size":11316.3},{"price":86.95,"size":9200.0},{"price":86.9,"size":105.52},{"price":86.8,"size":200.0},{"price":86.57,"size":10.0},{"price":86.53,"size":1000.0},{"price":86.5,"size":1320.0},{"price":86.4,"size":10.0},{"price":86.17,"size":10.0},{"price":86.16,"size":1000.0},{"price":86.1,"size":3050.0},{"price":86.0,"size":19585.68},{"price":85.91,"size":120.0},{"price":85.9,"size":705.0},{"price":85.88,"size":25.0},{"price":85.69,"size":1000.0},{"price":85.61,"size":50.0},{"price":85.6,"size":1000.0},{"price":85.5,"size":160.0},{"price":85.35,"size":150.0},{"price":85.3,"size":1000.0},{"price":85.29,"size":126.0},{"price":85.25,"size":16550.604105},{"price":85.23,"size":1000.0},{"price":85.2,"size":50.0},{"price":85.11,"size":0.53},{"price":85.1,"size":3950.0},{"price":85.08,"size":10.0},{"price":85.04,"size":25.0},{"price":85.01,"size":600.0},{"price":85.0,"size":75986.705814},{"price":84.89,"size":500.0},{"price":84.85,"size":100.0},{"price":84.83,"size":100.0},{"price":84.82,"size":100.0},{"price":84.81,"size":5.0},{"price":84.72,"size":0.54},{"price":84.7,"size":100.0},{"price":84.6,"size":500.0},{"price":84.54,"size":11.0},{"price":84.5,"size":80.5},{"price":84.28,"size":0.35},{"price":84.12,"size":30.0},{"price":84.1,"size":150.0},{"price":84.0,"size":8231.095108},{"price":83.99,"size":100.0},{"price":83.97,"size":2002.5},{"price":83.85,"size":100.0},{"price":83.5,"size":282.0},{"price":83.33,"size":5.0},{"price":83.3,"size":1000.0},{"price":83.25,"size":300.0},{"price":83.1,"size":2456.7387},{"price":83.0,"size":12219.2},{"price":82.95,"size":100.0},{"price":82.92,"size":10000.0},{"price":82.91,"size":100.0},{"price":82.89,"size":67.0},{"price":82.79,"size":150.0},{"price":82.74,"size":2000.0},{"price":82.62,"size":10000.0},{"price":82.6,"size":1000.0},{"price":82.5,"size":13075.078787},{"price":82.22,"size":11000.0},{"price":82.15,"size":51.0},{"price":82.1,"size":50.0},{"price":82.0,"size":30925.1365},{"price":81.88,"size":30.0},{"price":81.85,"size":100.0},{"price":81.78,"size":0.7},{"price":81.65,"size":65.0},{"price":81.6,"size":1000.0},{"price":81.5,"size":1100.0},{"price":81.4,"size":5000.0},{"price":81.37,"size":24.5912},{"price":81.3,"size":6410.0},{"price":81.2,"size":2281.527},{"price":81.1,"size":550.0},{"price":81.03,"size":1000.0},{"price":81.0,"size":22360.909},{"price":80.99,"size":12.4},{"price":80.96,"size":10.0},{"price":80.95,"size":4000.0},{"price":80.94,"size":125.0},{"price":80.9,"size":911.0},{"price":80.88,"size":50.0},{"price":80.75,"size":100.0},{"price":80.73,"size":1000.0},{"price":80.72,"size":100.0},{"price":80.69,"size":10000.0},{"price":80.6,"size":1152.0},{"price":80.52,"size":500.0},{"price":80.5,"size":4230.0},{"price":80.44,"size":200.0},{"price":80.4,"size":271.0},{"price":80.19,"size":500.0},{"price":80.12,"size":200.0},{"price":80.1,"size":6636.0},{"price":80.09,"size":1000.0},{"price":80.02,"size":3620.0},{"price":80.0,"size":110476.075},{"price":79.9,"size":1500.0},{"price":79.86,"size":100.0},{"price":79.8,"size":3000.0},{"price":79.78,"size":30.0},{"price":79.72,"size":100.0},{"price":79.7,"size":30.0},{"price":79.6,"size":252.0},{"price":79.58,"size":1.0},{"price":79.5,"size":5150.0},{"price":79.4,"size":20.0},{"price":79.2,"size":2000.0},{"price":79.11,"size":150.0},{"price":79.1,"size":325.0},{"price":79.0,"size":4798.42},{"price":78.9,"size":20.0},{"price":78.8,"size":1010.0},{"price":78.72,"size":100.0},{"price":78.5,"size":3000.0},{"price":78.35,"size":50.0},{"price":78.21,"size":255.0},{"price":78.2,"size":8602.11},{"price":78.1,"size":690.0},{"price":78.0,"size":14272.980769},{"price":77.88,"size":1.3},{"price":77.77,"size":890.0},{"price":77.72,"size":100.0},{"price":77.7,"size":400.0},{"price":77.5,"size":3150.0},{"price":77.27,"size":100.0},{"price":77.1,"size":50.0},{"price":77.0,"size":11349.08},{"price":76.8,"size":1500.0},{"price":76.72,"size":100.0},{"price":76.63,"size":655.0},{"price":76.6,"size":500.0},{"price":76.53,"size":190.0},{"price":76.5,"size":3000.0},{"price":76.11,"size":5000.0},{"price":76.1,"size":2050.0},{"price":76.0,"size":6777.42},{"price":75.91,"size":1000.0},{"price":75.88,"size":50.0},{"price":75.79,"size":50.0},{"price":75.78,"size":1.4},{"price":75.72,"size":100.0},{"price":75.6,"size":500.0},{"price":75.52,"size":3000.0},{"price":75.5,"size":7500.0},{"price":75.3,"size":441.0},{"price":75.1,"size":50.0},{"price":75.01,"size":10.0},{"price":75.0,"size":17050.30333},{"price":74.74,"size":5000.0},{"price":74.54,"size":49.0},{"price":74.5,"size":3000.0},{"price":74.4,"size":5000.0},{"price":74.1,"size":50.0},{"price":74.0,"size":418.03},{"price":73.84,"size":30.0},{"price":73.5,"size":3000.0},{"price":73.39,"size":100.0},{"price":73.1,"size":785.0},{"price":73.0,"size":1778.4},{"price":72.9,"size":1.109},{"price":72.5,"size":3000.0},{"price":72.1,"size":50.0},{"price":72.0,"size":11526.78},{"price":71.68,"size":27.901}],"asks":[{"price":96.13,"size":49.479871},{"price":96.15,"size":310.12},{"price":96.16,"size":10112.0},{"price":96.21,"size":10647.0},{"price":96.23,"size":5540.0},{"price":96.24,"size":9929.0},{"price":96.28,"size":9000.0},{"price":96.3,"size":1352.25},{"price":96.31,"size":339.343152},{"price":96.33,"size":13710.0},{"price":96.43,"size":139250.0},{"price":96.45,"size":27.65},{"price":96.5,"size":9000.0},{"price":96.6,"size":4000.0},{"price":96.7,"size":4070.0},{"price":96.8,"size":70.0},{"price":96.9,"size":70.0},{"price":96.99,"size":26630.0},{"price":97.0,"size":4451.0},{"price":97.1,"size":70.0},{"price":97.14,"size":5000.0},{"price":97.19,"size":8000.0},{"price":97.2,"size":1070.0},{"price":97.21,"size":5000.0},{"price":97.24,"size":5000.0},{"price":97.3,"size":70.0},{"price":97.34,"size":5000.0},{"price":97.4,"size":70.0},{"price":97.5,"size":1552.1},{"price":97.6,"size":70.0},{"price":97.7,"size":70.0},{"price":97.8,"size":70.0},{"price":97.9,"size":140.0},{"price":98.0,"size":2076.1},{"price":98.1,"size":70.0},{"price":98.2,"size":71.0},{"price":98.25,"size":4.0},{"price":98.3,"size":370.0},{"price":98.4,"size":70.0},{"price":98.48,"size":491.120224},{"price":98.5,"size":6077.1},{"price":98.55,"size":11000.0},{"price":98.7,"size":70.0},{"price":98.75,"size":4.0},{"price":98.8,"size":70.0},{"price":99.0,"size":8878.0},{"price":99.1,"size":70.0},{"price":99.13,"size":30.0},{"price":99.2,"size":70.0},{"price":99.24,"size":500.0},{"price":99.25,"size":4.0},{"price":99.3,"size":70.0},{"price":99.38,"size":14.104},{"price":99.4,"size":80.0},{"price":99.5,"size":4276.0},{"price":99.6,"size":70.0},{"price":99.7,"size":70.0},{"price":99.75,"size":4.0},{"price":99.8,"size":70.0},{"price":99.9,"size":70.0},{"price":99.99,"size":2994.0},{"price":100.0,"size":24347.2616},{"price":100.1,"size":70.0},{"price":100.2,"size":70.0},{"price":100.25,"size":4.0},{"price":100.3,"size":70.0},{"price":100.4,"size":70.0},{"price":100.5,"size":1311.0},{"price":100.6,"size":70.0},{"price":100.7,"size":70.0},{"price":100.75,"size":4.0},{"price":100.8,"size":70.0},{"price":100.9,"size":70.0},{"price":100.99,"size":499.0},{"price":101.0,"size":3108.0},{"price":101.1,"size":70.0},{"price":101.2,"size":70.0},{"price":101.25,"size":4.0},{"price":101.3,"size":70.0},{"price":101.4,"size":70.0},{"price":101.5,"size":77.0},{"price":101.6,"size":70.0},{"price":101.7,"size":70.0},{"price":101.75,"size":4.0},{"price":101.8,"size":70.0},{"price":101.89,"size":5000.0},{"price":101.9,"size":70.0},{"price":102.0,"size":5454.5},{"price":102.1,"size":70.0},{"price":102.2,"size":70.0},{"price":102.25,"size":4.0},{"price":102.3,"size":70.0},{"price":102.4,"size":70.0},{"price":102.5,"size":76.0},{"price":102.6,"size":70.0},{"price":102.7,"size":70.0},{"price":102.75,"size":4.0},{"price":102.8,"size":70.0},{"price":102.84,"size":194.472},{"price":102.9,"size":70.0},{"price":103.0,"size":100817.0},{"price":103.1,"size":70.0},{"price":103.2,"size":90.0},{"price":103.25,"size":4.0},{"price":103.28,"size":100.0},{"price":103.3,"size":660.7},{"price":103.4,"size":70.0},{"price":103.5,"size":106.0},{"price":103.6,"size":70.0},{"price":103.7,"size":100.0},{"price":103.75,"size":4.0},{"price":103.8,"size":70.0},{"price":103.9,"size":70.0},{"price":103.99,"size":499.0},{"price":104.0,"size":5010.0},{"price":104.09,"size":100.0},{"price":104.1,"size":100.0},{"price":104.13,"size":99.7},{"price":104.2,"size":400.0},{"price":104.25,"size":4.0},{"price":104.3,"size":100.0},{"price":104.4,"size":100.0},{"price":104.5,"size":9951.5},{"price":104.6,"size":800.0},{"price":104.61,"size":150.0},{"price":104.7,"size":100.0},{"price":104.75,"size":4.0},{"price":104.8,"size":99.8},{"price":104.9,"size":100.0},{"price":104.96,"size":1000.0},{"price":104.97,"size":1500.0},{"price":105.0,"size":28525.4381},{"price":105.02,"size":5652.0},{"price":105.1,"size":110.0},{"price":105.2,"size":100.0},{"price":105.25,"size":4.0},{"price":105.3,"size":100.0},{"price":105.31,"size":9.85},{"price":105.4,"size":100.0},{"price":105.46,"size":3795.0},{"price":105.5,"size":4700.7},{"price":105.55,"size":100.1},{"price":105.6,"size":100.0},{"price":105.7,"size":100.0},{"price":105.75,"size":4.0},{"price":105.78,"size":100.0},{"price":105.8,"size":2110.000001},{"price":105.98,"size":13000.0},{"price":105.99,"size":499.0},{"price":106.0,"size":12467.0},{"price":106.12,"size":9.8},{"price":106.25,"size":4.0},{"price":106.3,"size":11000.0},{"price":106.33,"size":49.2},{"price":106.5,"size":6.0},{"price":106.75,"size":4.0},{"price":107.0,"size":2167.0},{"price":107.25,"size":4.0},{"price":107.27,"size":100.0},{"price":107.5,"size":6.0},{"price":107.61,"size":21.3836},{"price":107.75,"size":4.0},{"price":108.0,"size":6991.67948},{"price":108.01,"size":6.491},{"price":108.2,"size":100.0},{"price":108.25,"size":4.0},{"price":108.5,"size":6.0},{"price":108.75,"size":4.0},{"price":108.96,"size":1389.050949},{"price":109.0,"size":3091.0},{"price":109.09,"size":1.0},{"price":109.1,"size":80.0},{"price":109.25,"size":4.0},{"price":109.5,"size":7.0},{"price":109.75,"size":4.0},{"price":109.9,"size":10.0},{"price":109.98,"size":29.0},{"price":110.0,"size":12253.7},{"price":110.11,"size":156.0},{"price":110.25,"size":4.0},{"price":110.5,"size":182.0},{"price":110.56,"size":218.95096},{"price":110.75,"size":4.0},{"price":110.99,"size":998.0},{"price":111.0,"size":3085.0},{"price":111.1,"size":5000.0},{"price":111.25,"size":4.0},{"price":111.5,"size":4.0},{"price":111.75,"size":4.0},{"price":112.0,"size":1720.892764},{"price":112.2,"size":49.2},{"price":112.25,"size":4.0},{"price":112.5,"size":1104.0},{"price":112.75,"size":4.0},{"price":112.8,"size":400.0},{"price":112.82,"size":49.2},{"price":112.9,"size":1000.0},{"price":113.0,"size":1774.0},{"price":113.25,"size":4.0},{"price":113.3,"size":699.0},{"price":113.5,"size":4.0},{"price":113.54,"size":17900.0},{"price":113.71,"size":49.2},{"price":113.75,"size":4.0},{"price":113.8,"size":100.0},{"price":114.0,"size":10698.410537},{"price":114.25,"size":4.0},{"price":114.4,"size":55.0},{"price":114.5,"size":104.0},{"price":114.75,"size":4.0},{"price":114.8,"size":1612.07},{"price":114.93,"size":49.2},{"price":115.0,"size":9176.5},{"price":115.05,"size":497.0009},{"price":115.1,"size":579.76036},{"price":115.15,"size":500.0},{"price":115.2,"size":3010.0},{"price":115.25,"size":504.0},{"price":115.3,"size":800.0},{"price":115.35,"size":500.0},{"price":115.4,"size":500.0},{"price":115.45,"size":500.0},{"price":115.5,"size":3404.0},{"price":115.6,"size":800.0},{"price":115.63,"size":49.2},{"price":115.7,"size":500.0},{"price":115.75,"size":4.0},{"price":115.78,"size":155.0},{"price":115.8,"size":500.0},{"price":115.87,"size":1000.0},{"price":115.9,"size":500.0},{"price":116.0,"size":3244.645},{"price":116.1,"size":500.0},{"price":116.11,"size":500.0},{"price":116.14,"size":500.0},{"price":116.15,"size":500.0},{"price":116.18,"size":500.0},{"price":116.2,"size":500.0},{"price":116.21,"size":500.0},{"price":116.24,"size":500.0},{"price":116.25,"size":504.0},{"price":116.28,"size":500.0},{"price":116.29,"size":500.0},{"price":116.3,"size":3827.0},{"price":116.31,"size":500.0},{"price":116.34,"size":500.0},{"price":116.35,"size":500.0},{"price":116.4,"size":500.0},{"price":116.44,"size":500.0},{"price":116.47,"size":1000.0},{"price":116.5,"size":606.0},{"price":116.54,"size":500.0},{"price":116.6,"size":500.0},{"price":116.64,"size":500.0},{"price":116.7,"size":501.0},{"price":116.74,"size":500.0},{"price":116.75,"size":4.0},{"price":116.8,"size":500.0},{"price":116.84,"size":500.0},{"price":116.88,"size":29.5},{"price":116.9,"size":500.0},{"price":116.94,"size":500.0},{"price":117.0,"size":2740.0},{"price":117.1,"size":500.0},{"price":117.2,"size":1505.0},{"price":117.25,"size":4.0},{"price":117.3,"size":34865.0},{"price":117.33,"size":29.5},{"price":117.4,"size":500.0},{"price":117.5,"size":966.0},{"price":117.6,"size":500.0},{"price":117.7,"size":545.0},{"price":117.75,"size":4.0},{"price":117.8,"size":500.0},{"price":117.9,"size":500.0},{"price":118.0,"size":4151.4},{"price":118.1,"size":500.0},{"price":118.12,"size":500.0},{"price":118.2,"size":500.0},{"price":118.22,"size":500.0},{"price":118.25,"size":4.0},{"price":118.3,"size":500.0},{"price":118.32,"size":500.0},{"price":118.4,"size":500.0},{"price":118.42,"size":500.0},{"price":118.5,"size":651.0},{"price":118.52,"size":500.0},{"price":118.6,"size":500.0},{"price":118.62,"size":500.0},{"price":118.7,"size":500.0},{"price":118.72,"size":750.0},{"price":118.75,"size":4.0},{"price":118.8,"size":500.0},{"price":118.82,"size":500.0},{"price":118.9,"size":820.0},{"price":118.92,"size":500.0},{"price":119.0,"size":11856.0},{"price":119.2,"size":2600.0},{"price":119.25,"size":4.0},{"price":119.48,"size":50.0}]}}}
1639350346.463944: {"jsonrpc":"2.0","method":"channelMessage","params":{"channel":"lightning_board_snapshot_MONA_JPY","message":{"mid_price":166.009,"bids":[{"price":83.5,"size":10.0},{"price":84.0,"size":10.0},{"price":84.1,"size":10.0},{"price":84.3,"size":10.0},{"price":84.5,"size":10.0},{"price":90.0,"size":100.0},{"price":93.572,"size":21.3836},{"price":94.4,"size":10.0},{"price":100.0,"size":733.94},{"price":101.0,"size":80.0},{"price":104.0,"size":60.0},{"price":105.0,"size":10.0},{"price":107.61,"size":18.5945},{"price":108.11,"size":10.0},{"price":110.0,"size":5.0},{"price":112.011,"size":30.0},{"price":120.0,"size":51.1},{"price":121.0,"size":150.0},{"price":123.75,"size":16.1691},{"price":125.0,"size":573.0},{"price":125.911,"size":30.0},{"price":126.27,"size":100.0},{"price":127.0,"size":150.0},{"price":128.0,"size":800.0},{"price":130.0,"size":1468.2},{"price":130.1,"size":5.0},{"price":131.0,"size":150.0},{"price":132.0,"size":321.0},{"price":135.0,"size":150.0},{"price":137.0,"size":350.0},{"price":139.0,"size":40.0},{"price":139.6,"size":10.0},{"price":139.811,"size":30.0},{"price":140.0,"size":2846.1},{"price":140.183,"size":28.535},{"price":141.1,"size":2510.0},{"price":141.4,"size":10.0},{"price":142.311,"size":14.0601},{"price":142.537,"size":140.0},{"price":145.0,"size":10.0},{"price":146.0,"size":20.0},{"price":146.1,"size":2000.0},{"price":147.0,"size":370.85714285},{"price":148.0,"size":769.0},{"price":149.0,"size":9.0},{"price":149.3,"size":50.0},{"price":149.36,"size":14.2},{"price":149.4,"size":24.18684765},{"price":149.8,"size":120.0},{"price":149.9,"size":50.0},{"price":150.0,"size":1582.63333},{"price":151.0,"size":258.1},{"price":151.1,"size":2000.0},{"price":152.0,"size":28.1},{"price":153.0,"size":458.1},{"price":153.65,"size":10.0},{"price":153.772,"size":2446.0},{"price":154.0,"size":8.1},{"price":154.524,"size":1.0014},{"price":155.0,"size":3925.10450676},{"price":155.06,"size":2489.0},{"price":155.2,"size":50.0},{"price":155.3,"size":4000.0},{"price":155.311,"size":69.51},{"price":156.0,"size":578.3},{"price":156.1,"size":1500.0},{"price":156.4,"size":10.0},{"price":157.0,"size":99.1},{"price":158.0,"size":221.1},{"price":158.375,"size":126.0},{"price":158.5,"size":30.0},{"price":158.628,"size":2472.0},{"price":158.879,"size":1000.0},{"price":159.0,"size":552.158},{"price":160.0,"size":5968.3525},{"price":160.039,"size":11.0},{"price":160.5,"size":10.0},{"price":160.545,"size":50.0},{"price":160.577,"size":4923.0},{"price":160.639,"size":30.0},{"price":161.0,"size":1460.2},{"price":161.1,"size":8461.71687854},{"price":161.2,"size":5.0},{"price":161.245,"size":2400.0},{"price":161.392,"size":9754.0},{"price":161.4,"size":5.0},{"price":161.6,"size":5.0},{"price":161.8,"size":683.0},{"price":162.0,"size":305.24691358},{"price":162.2,"size":5.0},{"price":162.207,"size":25175.0},{"price":162.4,"size":5.0},{"price":162.6,"size":5.0},{"price":162.8,"size":5.0},{"price":162.835,"size":2506.0},{"price":162.901,"size":964.0},{"price":163.0,"size":977.73337133},{"price":163.001,"size":10.0},{"price":163.14,"size":6.0},{"price":163.2,"size":5.0},{"price":163.4,"size":5.0},{"price":163.6,"size":5.0},{"price":163.8,"size":5.0},{"price":163.86,"size":1000.0},{"price":164.0,"size":399.5068536},{"price":164.02,"size":0.1},{"price":165.0,"size":206.93939393},{"price":165.002,"size":0.11515011},{"price":165.02,"size":500.0000002},{"price":165.021,"size":98.0}],"asks":[{"price":166.998,"size":0.80479767},{"price":166.999,"size":98.0},{"price":167.0,"size":161.0},{"price":167.5,"size":4.09152951},{"price":167.784,"size":23.841},{"price":167.999,"size":566.0},{"price":168.0,"size":311.5},{"price":168.49,"size":83.3},{"price":168.839,"size":1000.0},{"price":169.0,"size":307.99},{"price":170.0,"size":315.0},{"price":170.2,"size":5.0},{"price":170.4,"size":5.0},{"price":170.6,"size":5.0},{"price":170.8,"size":5.0},{"price":170.999,"size":100.0},{"price":171.0,"size":415.0},{"price":171.2,"size":5.0},{"price":171.4,"size":5.0},{"price":171.6,"size":5.0},{"price":171.8,"size":5.0},{"price":171.999,"size":53.9},{"price":172.0,"size":515.0},{"price":172.2,"size":5.0},{"price":172.4,"size":5.0},{"price":172.6,"size":5.0},{"price":172.8,"size":5.0},{"price":173.0,"size":446.92},{"price":173.2,"size":5.0},{"price":173.4,"size":5.0},{"price":173.6,"size":5.0},{"price":173.8,"size":5.0},{"price":173.82,"size":1000.0},{"price":173.997,"size":7589.25902325},{"price":174.0,"size":1562.23062369},{"price":174.1,"size":199.7},{"price":174.2,"size":5.0},{"price":174.4,"size":5.0},{"price":174.6,"size":5.0},{"price":174.8,"size":5.0},{"price":174.9,"size":99.74},{"price":174.99,"size":730.0},{"price":175.0,"size":617.0},{"price":175.2,"size":5.0},{"price":175.4,"size":5.0},{"price":175.584,"size":4.9},{"price":175.6,"size":5.0},{"price":175.8,"size":5.0},{"price":176.0,"size":2532.5},{"price":176.2,"size":5.0},{"price":176.4,"size":5.0},{"price":176.6,"size":5.0},{"price":176.607,"size":4.9},{"price":176.8,"size":5.0},{"price":177.0,"size":365.0},{"price":177.2,"size":5.0},{"price":177.4,"size":5.0},{"price":177.6,"size":5.0},{"price":177.8,"size":5.0},{"price":178.0,"size":126.5},{"price":178.2,"size":5.0},{"price":178.4,"size":5.0},{"price":178.5,"size":2.238},{"price":178.6,"size":5.0},{"price":178.8,"size":5.0},{"price":179.0,"size":465.0},{"price":179.2,"size":5.0},{"price":179.4,"size":5.0},{"price":179.6,"size":5.0},{"price":179.7,"size":124.2},{"price":179.8,"size":5.0},{"price":180.0,"size":21159.143985},{"price":180.2,"size":5.0},{"price":180.4,"size":5.0},{"price":180.6,"size":5.0},{"price":180.8,"size":5.0},{"price":181.0,"size":165.0},{"price":181.2,"size":5.0},{"price":181.4,"size":5.0},{"price":181.6,"size":5.0},{"price":181.8,"size":5.0},{"price":182.0,"size":65.0},{"price":182.2,"size":5.0},{"price":182.4,"size":5.0},{"price":182.6,"size":5.0},{"price":182.8,"size":5.0},{"price":183.0,"size":365.0},{"price":183.2,"size":5.0},{"price":183.4,"size":5.0},{"price":183.6,"size":5.0},{"price":183.8,"size":5.0},{"price":184.0,"size":65.0},{"price":184.2,"size":5.0},{"price":184.4,"size":5.0},{"price":184.6,"size":5.0},{"price":184.8,"size":5.0},{"price":185.0,"size":1624.85618696},{"price":185.01,"size":5.87639265},{"price":185.2,"size":5.0},{"price":185.4,"size":5.0},{"price":185.6,"size":5.0},{"price":185.8,"size":5.0},{"price":186.0,"size":306.5},{"price":186.8,"size":5.0},{"price":187.0,"size":415.0},{"price":187.2,"size":5.0},{"price":187.4,"size":5.0},{"price":187.425,"size":1.0},{"price":187.6,"size":5.0},{"price":187.8,"size":5.0},{"price":188.0,"size":315.0},{"price":188.2,"size":5.0},{"price":188.211,"size":12.2262},{"price":188.4,"size":5.0},{"price":188.6,"size":5.0},{"price":188.8,"size":5.0},{"price":188.999,"size":50.0},{"price":189.0,"size":3582.0},{"price":189.2,"size":5.0},{"price":189.4,"size":5.0},{"price":189.6,"size":5.0},{"price":189.8,"size":5.0},{"price":189.999,"size":50.0},{"price":190.0,"size":674.96230901},{"price":190.2,"size":5.0},{"price":190.4,"size":5.0},{"price":190.6,"size":5.0},{"price":190.8,"size":5.0},{"price":190.999,"size":19.0},{"price":191.0,"size":415.0},{"price":191.113,"size":9.99},{"price":191.2,"size":5.0},{"price":191.4,"size":5.0},{"price":191.6,"size":5.0},{"price":191.8,"size":5.0},{"price":191.999,"size":50.0},{"price":192.0,"size":815.0},{"price":192.2,"size":5.0},{"price":192.4,"size":5.0},{"price":192.6,"size":5.0},{"price":192.747,"size":20.0},{"price":192.8,"size":5.0},{"price":192.999,"size":50.0},{"price":193.0,"size":465.75789053},{"price":193.2,"size":5.0},{"price":193.4,"size":5.0},{"price":193.6,"size":5.0},{"price":193.8,"size":5.0},{"price":193.999,"size":50.0},{"price":194.0,"size":325.5},{"price":194.2,"size":5.0},{"price":194.4,"size":5.0},{"price":194.6,"size":5.0},{"price":194.8,"size":5.0},{"price":194.999,"size":50.0},{"price":195.0,"size":1386.2},{"price":195.2,"size":5.0},{"price":195.4,"size":5.0},{"price":195.6,"size":5.0},{"price":195.8,"size":5.0},{"price":195.999,"size":50.0},{"price":196.0,"size":315.0},{"price":196.2,"size":5.0},{"price":196.4,"size":5.0},{"price":196.6,"size":5.0},{"price":196.8,"size":6.01474},{"price":196.999,"size":50.0},{"price":197.0,"size":1934.64296797},{"price":197.2,"size":5.0},{"price":197.4,"size":5.0},{"price":197.6,"size":5.0},{"price":197.8,"size":5.0},{"price":198.0,"size":516.6},{"price":199.0,"size":2042.88},{"price":199.2,"size":5.0},{"price":199.4,"size":5.0},{"price":199.5,"size":497.0},{"price":199.6,"size":5.0},{"price":199.8,"size":5.0},{"price":200.0,"size":1667.42438504},{"price":200.109,"size":4.9},{"price":200.2,"size":5.0},{"price":200.4,"size":5.0},{"price":200.8,"size":5.0},{"price":200.897,"size":50.0},{"price":201.0,"size":280.2},{"price":201.2,"size":5.0},{"price":201.4,"size":5.0},{"price":201.6,"size":5.0},{"price":201.8,"size":5.0},{"price":202.0,"size":325.2},{"price":202.2,"size":5.0},{"price":202.4,"size":5.0},{"price":202.6,"size":5.0},{"price":202.8,"size":5.0},{"price":203.0,"size":115.2},{"price":203.2,"size":5.0},{"price":203.6,"size":20.0},{"price":203.66,"size":270.0},{"price":204.0,"size":359.50071915},{"price":204.8,"size":8156.68824317},{"price":205.0,"size":33869.616},{"price":205.275,"size":200.0},{"price":206.0,"size":348.5607011},{"price":206.8,"size":10.0},{"price":207.0,"size":130.91515376},{"price":208.0,"size":329.2},{"price":209.0,"size":169.2},{"price":209.811,"size":26.5101},{"price":210.0,"size":5122.1978011},{"price":210.03,"size":994.0},{"price":211.0,"size":2270.42259506},{"price":211.167,"size":226.0},{"price":211.7,"size":10.0},{"price":212.0,"size":570.2},{"price":212.134,"size":0.985},{"price":213.0,"size":207.52986169},{"price":214.0,"size":3288.55795542},{"price":214.8,"size":1000.0},{"price":215.0,"size":1753.04052022},{"price":215.1,"size":299.28079113},{"price":216.0,"size":2265.1},{"price":216.3,"size":50.0},{"price":216.444,"size":10.6314},{"price":216.972,"size":1.0},{"price":216.998,"size":100.0},{"price":217.0,"size":1983.1},{"price":217.5,"size":5.0},{"price":218.0,"size":461.6},{"price":218.4,"size":5.0},{"price":219.0,"size":360.1},{"price":220.0,"size":9229.57604492},{"price":221.0,"size":33.1},{"price":222.0,"size":514.82664685},{"price":222.2,"size":45.0},{"price":222.222,"size":150.0},{"price":222.5,"size":5.0},{"price":223.0,"size":735.77279265},{"price":224.0,"size":135.1},{"price":224.01,"size":500.0},{"price":225.0,"size":3214.4},{"price":225.009,"size":300.0},{"price":225.17,"size":50.0},{"price":226.0,"size":114.1},{"price":226.8,"size":15.0},{"price":227.0,"size":50.1},{"price":227.5,"size":5.0},{"price":228.0,"size":43.1},{"price":229.0,"size":50.1},{"price":229.8,"size":10.0},{"price":230.0,"size":1975.239331},{"price":230.1,"size":110.0},{"price":231.86,"size":2.26},{"price":235.0,"size":317.0},{"price":235.4,"size":43.35581731},{"price":237.0,"size":6.0},{"price":239.0,"size":2998.0},{"price":239.899,"size":15.0},{"price":240.0,"size":999.4},{"price":240.1,"size":290.0},{"price":245.0,"size":605.0},{"price":245.009,"size":300.0},{"price":248.0,"size":219.0},{"price":248.911,"size":9.2447},{"price":250.0,"size":4097.79714313},{"price":253.0,"size":5.0},{"price":255.0,"size":205.0},{"price":257.0,"size":50.0},{"price":260.0,"size":220.5},{"price":264.0,"size":200.0},{"price":265.0,"size":5.0},{"price":268.0,"size":100.0},{"price":270.0,"size":573.56},{"price":273.0,"size":199.5},{"price":275.0,"size":27.0},{"price":279.0,"size":200.0},{"price":280.0,"size":1310.8},{"price":285.0,"size":5.0},{"price":286.25,"size":8.0389},{"price":289.91,"size":1.59648246},{"price":290.0,"size":110.7},{"price":292.0,"size":42.5},{"price":295.0,"size":10.1},{"price":298.0,"size":200.0},{"price":299.0,"size":200.0},{"price":300.0,"size":1637.62059002},{"price":301.0,"size":58.22738048},{"price":302.0,"size":30.0},{"price":305.0,"size":5.1},{"price":310.0,"size":1105.9},{"price":312.0,"size":6.0},{"price":315.0,"size":22.0},{"price":317.0,"size":5.0},{"price":320.0,"size":110.1},{"price":321.0,"size":100.0},{"price":325.0,"size":5.0},{"price":329.19,"size":6.9903},{"price":330.0,"size":604.0},{"price":332.0,"size":190.0},{"price":335.0,"size":5.0},{"price":338.0,"size":32.68899798},{"price":340.0,"size":58.5},{"price":341.0,"size":34.69794721},{"price":342.0,"size":1000.0},{"price":350.0,"size":1631.8225},{"price":360.0,"size":0.2},{"price":370.0,"size":20.0},{"price":380.0,"size":358.2},{"price":397.0,"size":1841.88271694},{"price":400.0,"size":103.81018981},{"price":435.0,"size":336.55349638}]}}}
