1618677597.551939: {"jsonrpc":"2.0","method":"channelMessage","params":{"channel":"lightning_board_snapshot_XRP_JPY","message":{"mid_price":173.01,"bids":[{"price":172.97,"size":1503.37},{"price":172.9,"size":355.23},{"price":172.8,"size":614.19},{"price":172.71,"size":1672.29},{"price":172.7,"size":1860.03},{"price":172.64,"size":12297.0},{"price":172.52,"size":49.9},{"price":172.4,"size":60.0},{"price":172.39,"size":3117.0},{"price":172.35,"size":3059.0},{"price":172.28,"size":2988.0},{"price":172.26,"size":200.0},{"price":172.1,"size":50.0},{"price":172.02,"size":100.0},{"price":172.0,"size":746.8},{"price":171.82,"size":119828.0},{"price":171.52,"size":100.0},{"price":171.5,"size":10.0},{"price":171.4,"size":500.0},{"price":171.12,"size":9.0},{"price":171.02,"size":100.0},{"price":171.0,"size":46948.0},{"price":170.52,"size":100.0},{"price":170.12,"size":23744.0},{"price":170.11,"size":50.0},{"price":170.02,"size":100.0},{"price":170.0,"size":2521.0},{"price":169.95,"size":49.35},{"price":169.6,"size":819.0},{"price":169.59,"size":2000.0},{"price":169.52,"size":100.0},{"price":169.5,"size":200.0},{"price":169.17,"size":12248.0},{"price":169.11,"size":150.0},{"price":169.02,"size":100.0},{"price":169.0,"size":39820.8},{"price":168.83,"size":100.0},{"price":168.8,"size":3001.0},{"price":168.51,"size":10003.0},{"price":168.5,"size":2190.0},{"price":168.4,"size":3000.0},{"price":168.22,"size":600.0},{"price":168.2,"size":3512.0},{"price":168.14,"size":10000.0},{"price":168.11,"size":150.0},{"price":168.1,"size":6000.0},{"price":168.0,"size":23957.0},{"price":167.99,"size":50.0},{"price":167.7,"size":53.0},{"price":167.5,"size":150.0},{"price":167.3,"size":300.0},{"price":167.23,"size":10.0},{"price":167.2,"size":250.0},{"price":167.12,"size":10.0},{"price":167.11,"size":50.0},{"price":167.0,"size":34250.426946},{"price":166.93,"size":11719.0},{"price":166.9,"size":15.0},{"price":166.6,"size":9480.0},{"price":166.33,"size":15000.0},{"price":166.11,"size":200.0},{"price":166.1,"size":950.0},{"price":166.04,"size":200.0},{"price":166.0,"size":9062.048},{"price":165.9,"size":300.0},{"price":165.76,"size":1000.0},{"price":165.6,"size":100.0},{"price":165.5,"size":250.0},{"price":165.44,"size":301.0},{"price":165.12,"size":10.0},{"price":165.1,"size":100.0},{"price":165.06,"size":20.0},{"price":165.02,"size":2000.0},{"price":165.0,"size":84835.174696},{"price":164.6,"size":700.0},{"price":164.58,"size":5000.0},{"price":164.15,"size":22.0},{"price":164.12,"size":10.0},{"price":164.08,"size":10.0},{"price":164.0,"size":6273.857317},{"price":163.8,"size":1020.0},{"price":163.6,"size":700.0},{"price":163.56,"size":11882.0},{"price":163.4,"size":200.0},{"price":163.12,"size":10.0},{"price":163.1,"size":200.0},{"price":163.06,"size":100.1},{"price":163.0,"size":3886.0},{"price":162.68,"size":1500.0},{"price":162.6,"size":700.0},{"price":162.4,"size":1001.0},{"price":162.2,"size":250.0},{"price":162.19,"size":2000.0},{"price":162.12,"size":10.0},{"price":162.0,"size":26402.0},{"price":161.6,"size":700.0},{"price":161.42,"size":1000.0},{"price":161.3,"size":300.0},{"price":161.12,"size":10.0},{"price":161.0,"size":2323.1},{"price":160.99,"size":2020.0},{"price":160.8,"size":230.0},{"price":160.6,"size":800.0},{"price":160.5,"size":1135.0},{"price":160.2,"size":8306.0},{"price":160.12,"size":10.0},{"price":160.1,"size":1080.0},{"price":160.04,"size":100.0},{"price":160.01,"size":500.0},{"price":160.0,"size":89737.4},{"price":159.8,"size":86.0},{"price":159.73,"size":10.0},{"price":159.7,"size":70.0},{"price":159.2,"size":560.0},{"price":159.15,"size":1500.0},{"price":159.11,"size":50.0},{"price":159.1,"size":508.0},{"price":159.08,"size":300.27},{"price":159.0,"size":23003.0},{"price":158.96,"size":100.0},{"price":158.8,"size":480.0},{"price":158.75,"size":2000.0},{"price":158.51,"size":100.0},{"price":158.5,"size":2800.0},{"price":158.4,"size":402.0},{"price":158.11,"size":100.0},{"price":158.1,"size":50.0},{"price":158.0,"size":13871.0},{"price":157.95,"size":5000.0},{"price":157.2,"size":110.0},{"price":157.19,"size":1500.0},{"price":157.11,"size":50.0},{"price":157.1,"size":201.0},{"price":157.0,"size":10282.089171},{"price":156.9,"size":200.0},{"price":156.23,"size":580.0},{"price":156.2,"size":101.0},{"price":156.11,"size":100.0},{"price":156.0,"size":24883.166666},{"price":155.5,"size":65.0},{"price":155.11,"size":50.0},{"price":155.1,"size":3135.0},{"price":155.0,"size":84519.2},{"price":154.2,"size":3000.2},{"price":154.15,"size":22.0},{"price":154.12,"size":1.0},{"price":154.11,"size":100.0},{"price":154.1,"size":50.0},{"price":154.04,"size":10.0},{"price":154.0,"size":572.0},{"price":153.11,"size":50.0},{"price":153.1,"size":50.0},{"price":153.04,"size":10.0},{"price":153.0,"size":3217.0},{"price":152.9,"size":1000.0},{"price":152.77,"size":33.0},{"price":152.74,"size":50.0},{"price":152.55,"size":100.0},{"price":152.51,"size":40.0},{"price":152.5,"size":100.0},{"price":152.11,"size":50.0},{"price":152.05,"size":0.5},{"price":152.04,"size":10.0},{"price":152.0,"size":4519.0},{"price":151.6,"size":400.0},{"price":151.25,"size":1200.0},{"price":151.11,"size":50.0},{"price":151.1,"size":1050.0},{"price":151.0,"size":20712.013245},{"price":150.8,"size":100.0},{"price":150.6,"size":1000.0},{"price":150.56,"size":1000.0},{"price":150.55,"size":1000.0},{"price":150.52,"size":500.0},{"price":150.5,"size":4000.0},{"price":150.27,"size":1000.0},{"price":150.11,"size":100.0},{"price":150.1,"size":1040.0},{"price":150.06,"size":22.481395},{"price":150.04,"size":15.0},{"price":150.01,"size":1412.0},{"price":150.0,"size":101672.588523},{"price":149.9,"size":101.0},{"price":149.11,"size":50.0},{"price":149.0,"size":1675.0},{"price":148.6,"size":14189.111709},{"price":148.4,"size":1000.0},{"price":148.11,"size":50.0},{"price":148.1,"size":50.0},{"price":148.0,"size":13055.0},{"price":147.7,"size":11700.0},{"price":147.23,"size":41.0},{"price":147.11,"size":50.0},{"price":147.0,"size":5721.24},{"price":146.61,"size":25.0},{"price":146.6,"size":1900.0},{"price":146.5,"size":300.0},{"price":146.11,"size":50.0},{"price":146.0,"size":1175.0},{"price":145.92,"size":10.0},{"price":145.51,"size":100.0},{"price":145.5,"size":2950.0},{"price":145.1,"size":1050.0},{"price":145.01,"size":700.0},{"price":145.0,"size":8418.4},{"price":144.5,"size":5.0},{"price":144.15,"size":22.0},{"price":144.1,"size":15000.0},{"price":144.0,"size":681.0},{"price":143.5,"size":5.0},{"price":143.25,"size":2000.0},{"price":143.03,"size":2000.0},{"price":143.0,"size":435.58034},{"price":142.72,"size":50.0},{"price":142.6,"size":2000.0},{"price":142.11,"size":1.0},{"price":142.1,"size":50.0},{"price":142.0,"size":1696.0},{"price":141.81,"size":5.0},{"price":141.77,"size":50.0},{"price":141.7,"size":11000.0},{"price":141.0,"size":500.0},{"price":140.5,"size":5000.0},{"price":140.2,"size":2000.0},{"price":140.1,"size":31000.0},{"price":140.0,"size":11264.757142},{"price":139.1,"size":50.0},{"price":139.07,"size":100.0},{"price":138.6,"size":74.9},{"price":138.0,"size":510.0},{"price":137.82,"size":2.91},{"price":137.6,"size":201.0},{"price":137.5,"size":10000.0},{"price":137.0,"size":350.0},{"price":136.1,"size":50.0},{"price":135.72,"size":50.0},{"price":135.57,"size":80.0},{"price":135.5,"size":3700.0},{"price":135.0,"size":511.1},{"price":134.83,"size":50.0},{"price":134.0,"size":1.0},{"price":133.1,"size":50.0},{"price":132.55,"size":100.0},{"price":132.29,"size":50.0},{"price":132.0,"size":100.0},{"price":131.5,"size":761.0},{"price":131.11,"size":1000.0},{"price":130.1,"size":50.0},{"price":130.0,"size":9115.1},{"price":129.0,"size":1.0},{"price":128.8,"size":300.0},{"price":128.0,"size":100.0},{"price":127.96,"size":10.0},{"price":127.4,"size":11.0},{"price":126.7,"size":2000.0},{"price":126.35,"size":100.0},{"price":125.77,"size":10000.0},{"price":125.5,"size":5000.0},{"price":125.1,"size":10000.0},{"price":125.0,"size":2034.1},{"price":124.8,"size":1000.0},{"price":124.0,"size":1339.548387},{"price":123.5,"size":166.0},{"price":123.0,"size":105100.0},{"price":122.6,"size":3000.0},{"price":121.11,"size":1000.0},{"price":120.8,"size":300.0},{"price":120.6,"size":10.0},{"price":120.01,"size":50000.0},{"price":120.0,"size":17769.1},{"price":118.6,"size":610.0},{"price":118.3,"size":700.0},{"price":118.0,"size":10.0},{"price":117.0,"size":60.0},{"price":116.0,"size":10.0},{"price":115.8,"size":20.0},{"price":115.0,"size":10.1},{"price":114.85,"size":3.492},{"price":114.0,"size":10.0},{"price":113.0,"size":500.0},{"price":112.55,"size":100.0},{"price":112.1,"size":2150.0},{"price":112.0,"size":100.0},{"price":111.3,"size":887.0},{"price":111.11,"size":1000.0},{"price":110.8,"size":20.0},{"price":110.0,"size":1432.0},{"price":109.0,"size":10.0},{"price":108.56,"size":100.0},{"price":107.0,"size":500.0},{"price":105.5,"size":120.0},{"price":105.3,"size":3000.0},{"price":105.13,"size":10.0},{"price":105.02,"size":96.0},{"price":105.0,"size":100.0},{"price":103.0,"size":90.0},{"price":102.71,"size":2.0},{"price":102.1,"size":100.0},{"price":101.11,"size":1000.0},{"price":100.02,"size":30.0}],"asks":[{"price":173.05,"size":1.0},{"price":173.06,"size":1.0},{"price":173.07,"size":1.0},{"price":173.1,"size":1.0},{"price":173.12,"size":1.0},{"price":173.15,"size":2.0},{"price":173.18,"size":1.0},{"price":173.2,"size":1.0},{"price":173.22,"size":1.0},{"price":173.23,"size":1503.37},{"price":173.24,"size":1.0},{"price":173.26,"size":240.21},{"price":173.28,"size":1.0},{"price":173.36,"size":1.0},{"price":173.38,"size":3505.7},{"price":173.64,"size":5016.87},{"price":173.65,"size":2888.0},{"price":173.72,"size":2918.0},{"price":173.76,"size":2970.0},{"price":173.99,"size":12297.0},{"price":174.0,"size":1.0},{"price":174.33,"size":20.0},{"price":174.4,"size":23909.4},{"price":174.43,"size":40.0},{"price":174.98,"size":400.0},{"price":174.99,"size":200.0},{"price":175.0,"size":5201.0},{"price":176.0,"size":7988.0},{"price":176.05,"size":48488.0},{"price":176.49,"size":5380.0},{"price":177.0,"size":2004.0},{"price":177.19,"size":24373.0},{"price":177.36,"size":400.0},{"price":177.9,"size":1396.0},{"price":177.94,"size":11881.0},{"price":178.0,"size":420.8},{"price":178.46,"size":647.99},{"price":178.5,"size":20.0},{"price":178.6,"size":50.0},{"price":178.8,"size":399.2},{"price":178.86,"size":11641.0},{"price":179.0,"size":15025.0},{"price":179.31,"size":1999.0},{"price":179.99,"size":3995.593818},{"price":180.0,"size":10834.370097},{"price":180.03,"size":1000.0},{"price":180.15,"size":1614.0},{"price":180.5,"size":25.0},{"price":180.9,"size":499.3},{"price":181.0,"size":27087.466924},{"price":181.5,"size":276.3},{"price":181.6,"size":250.0},{"price":182.0,"size":9540.97648},{"price":182.1,"size":50.0},{"price":182.2,"size":3242.0},{"price":182.3,"size":2.0},{"price":182.47,"size":819.59},{"price":182.7,"size":2500.0},{"price":182.8,"size":99.3075},{"price":183.0,"size":1569.058042},{"price":183.1,"size":1000.0},{"price":183.43,"size":815.31},{"price":183.52,"size":148.9},{"price":183.91,"size":15.0},{"price":184.0,"size":4750.1},{"price":184.1,"size":50.0},{"price":184.2,"size":3439.0},{"price":184.4,"size":2998.0},{"price":184.45,"size":2000.0},{"price":184.5,"size":499.0},{"price":184.52,"size":20.0},{"price":184.9,"size":5321.0},{"price":185.0,"size":14324.491577},{"price":185.42,"size":6017.0},{"price":185.5,"size":182.925612},{"price":185.53,"size":41.4},{"price":185.56,"size":500.0},{"price":185.69,"size":5000.0},{"price":185.75,"size":300.0},{"price":185.79,"size":1424.665794},{"price":186.0,"size":20542.2509},{"price":186.1,"size":51.0},{"price":186.33,"size":500.0},{"price":186.5,"size":19091.0},{"price":186.56,"size":200.0},{"price":187.0,"size":3814.848},{"price":187.1,"size":50.0},{"price":187.13,"size":50.0},{"price":187.2,"size":20.0},{"price":187.23,"size":200.0},{"price":187.3,"size":6000.0},{"price":187.41,"size":10000.0},{"price":187.75,"size":400.0},{"price":187.89,"size":30.0},{"price":187.9,"size":1000.0},{"price":188.0,"size":71219.411997},{"price":188.01,"size":62.4},{"price":188.1,"size":50.0},{"price":188.28,"size":2500.0},{"price":188.38,"size":1000.0},{"price":188.43,"size":100.0},{"price":188.55,"size":1057.95},{"price":188.6,"size":10000.97},{"price":188.61,"size":3000.0},{"price":188.8,"size":5500.0},{"price":188.85,"size":2924.0},{"price":188.86,"size":2000.0},{"price":188.9,"size":40.0},{"price":189.0,"size":46670.4454},{"price":189.11,"size":500.0},{"price":189.2,"size":6595.220175},{"price":189.3,"size":500.0},{"price":189.4,"size":100.0},{"price":189.49,"size":2000.0},{"price":189.5,"size":5000.0},{"price":189.69,"size":62.5},{"price":189.7,"size":2003.0},{"price":189.75,"size":350.0},{"price":189.8,"size":6600.0},{"price":189.81,"size":39093.83007},{"price":189.9,"size":2000.0},{"price":189.99,"size":600.0},{"price":190.0,"size":77774.190312},{"price":190.1,"size":50.0},{"price":190.2,"size":514.0},{"price":190.26,"size":200.0},{"price":190.3,"size":5001.0},{"price":190.56,"size":200.0},{"price":190.86,"size":1.0},{"price":190.9,"size":599.7},{"price":190.92,"size":783.34},{"price":191.0,"size":6580.0},{"price":191.26,"size":200.0},{"price":191.31,"size":1500.0},{"price":191.4,"size":34.0},{"price":191.5,"size":1463.5},{"price":191.66,"size":200.0},{"price":191.75,"size":350.0},{"price":192.0,"size":7153.757487},{"price":192.1,"size":50.0},{"price":192.13,"size":55.782},{"price":192.28,"size":20.0},{"price":192.3,"size":1.0},{"price":192.66,"size":200.0},{"price":192.69,"size":62.5},{"price":192.8,"size":1000.0},{"price":193.0,"size":16617.45},{"price":193.1,"size":400.0},{"price":193.2,"size":1960.0},{"price":193.33,"size":20.0},{"price":193.37,"size":773.4},{"price":193.5,"size":195.0},{"price":193.6,"size":100.0},{"price":193.66,"size":100.0},{"price":193.75,"size":350.0},{"price":194.0,"size":42295.431725},{"price":194.1,"size":50.0},{"price":194.15,"size":22.0},{"price":194.41,"size":769.28},{"price":194.9,"size":2868.4},{"price":194.91,"size":500.0},{"price":194.98,"size":2000.0},{"price":195.0,"size":38115.585124},{"price":195.21,"size":1400.0},{"price":195.39,"size":100.0},{"price":195.4,"size":765.35},{"price":195.5,"size":100.0},{"price":195.75,"size":400.0},{"price":195.99,"size":3045.661},{"price":196.0,"size":5590.0},{"price":196.06,"size":0.4},{"price":196.1,"size":1550.0},{"price":196.2,"size":19673.0},{"price":196.39,"size":100.0},{"price":196.4,"size":50.0},{"price":196.5,"size":2545.0},{"price":196.61,"size":760.65},{"price":197.0,"size":6160.0},{"price":197.39,"size":100.0},{"price":197.46,"size":100.0},{"price":197.5,"size":506.0},{"price":197.75,"size":300.0},{"price":197.8,"size":529.0},{"price":197.86,"size":3490.0},{"price":197.9,"size":1150.30961},{"price":197.98,"size":2000.0},{"price":198.0,"size":284322.95},{"price":198.08,"size":1000.0},{"price":198.1,"size":50.0},{"price":198.31,"size":399.303397},{"price":198.36,"size":2.425},{"price":198.39,"size":100.0},{"price":198.5,"size":3500.0},{"price":198.56,"size":458.0},{"price":198.6,"size":1995.0},{"price":198.69,"size":752.68},{"price":198.71,"size":752.6},{"price":198.75,"size":150.0},{"price":199.0,"size":84245.805866},{"price":199.07,"size":2366.0},{"price":199.25,"size":150.0},{"price":199.3,"size":2000.0},{"price":199.38,"size":11995.0},{"price":199.39,"size":100.0},{"price":199.4,"size":1000.0},{"price":199.5,"size":6511.221445},{"price":199.52,"size":3000.0},{"price":199.6,"size":500.0},{"price":199.7,"size":2466.271},{"price":199.75,"size":500.0},{"price":199.77,"size":1027.0},{"price":199.79,"size":100.0},{"price":199.8,"size":30.0},{"price":199.89,"size":3000.0},{"price":199.94,"size":40.0},{"price":199.95,"size":41.0},{"price":199.98,"size":124.5},{"price":200.0,"size":185445.838335},{"price":200.1,"size":416.7},{"price":200.25,"size":200.0},{"price":200.4,"size":200.0},{"price":200.42,"size":162.0},{"price":200.55,"size":28922.1},{"price":200.6,"size":199.0},{"price":200.61,"size":499.0},{"price":200.75,"size":200.0},{"price":200.77,"size":255.33},{"price":200.88,"size":500.0},{"price":200.9,"size":10.0},{"price":200.97,"size":744.16},{"price":201.0,"size":1257.700999},{"price":201.05,"size":500.0},{"price":201.36,"size":50.0},{"price":201.43,"size":100.0},{"price":201.5,"size":200.0},{"price":201.86,"size":50.0},{"price":201.93,"size":100.0},{"price":202.0,"size":8262.371821},{"price":202.1,"size":50.0},{"price":202.19,"size":25.0},{"price":202.46,"size":92.969756},{"price":203.0,"size":8332.8},{"price":203.99,"size":225.0},{"price":204.0,"size":30504.3},{"price":204.15,"size":22.0},{"price":204.2,"size":282.24},{"price":204.25,"size":598.96},{"price":204.36,"size":50.0},{"price":204.5,"size":1000.0},{"price":204.6,"size":12345.0},{"price":204.79,"size":125.0},{"price":204.85,"size":250.0},{"price":204.89,"size":100.0},{"price":204.9,"size":509.53015},{"price":204.94,"size":40.0},{"price":205.0,"size":60109.378355},{"price":205.09,"size":100.0},{"price":205.1,"size":2000.0},{"price":205.15,"size":40.0},{"price":205.2,"size":2000.0},{"price":205.26,"size":728.58},{"price":205.3,"size":1997.60048},{"price":205.4,"size":1998.40031},{"price":205.5,"size":2500.0},{"price":205.6,"size":2000.0},{"price":205.67,"size":4620.0},{"price":205.7,"size":2248.24035},{"price":205.78,"size":400.0},{"price":205.8,"size":2000.0},{"price":205.9,"size":2200.0},{"price":206.0,"size":31861.00049},{"price":206.1,"size":2050.0},{"price":206.12,"size":2895.0},{"price":206.2,"size":2246.0},{"price":206.28,"size":31.1111},{"price":206.3,"size":1998.40032},{"price":206.4,"size":1998.40032},{"price":206.5,"size":10000.0},{"price":206.6,"size":2029.188325},{"price":207.0,"size":38799.468812},{"price":207.18,"size":200.0},{"price":208.0,"size":6817.862207},{"price":208.1,"size":50.0},{"price":208.5,"size":52100.0},{"price":208.9,"size":20.0},{"price":209.0,"size":5689.46},{"price":209.07,"size":1000.0},{"price":209.09,"size":9998.0},{"price":209.35,"size":814.36},{"price":209.5,"size":10.0},{"price":209.85,"size":450.0},{"price":209.9,"size":11130.0},{"price":210.0,"size":144566.548027},{"price":210.01,"size":86.0},{"price":210.07,"size":1000.0},{"price":210.1,"size":50.0},{"price":210.15,"size":1500.0},{"price":210.21,"size":100.0},{"price":210.3,"size":1000.0},{"price":210.42,"size":710.74}]}}}
1618677597.562506: {"jsonrpc":"2.0","method":"channelMessage","params":{"channel":"lightning_board_snapshot_MONA_JPY","message":{"mid_price":401.795,"bids":[{"price":120.0,"size":200.0},{"price":125.0,"size":0.1},{"price":137.82,"size":2.91},{"price":140.0,"size":10.2},{"price":150.0,"size":0.2},{"price":151.0,"size":5000.0},{"price":165.0,"size":0.1},{"price":165.38,"size":2.425},{"price":175.0,"size":0.1},{"price":180.0,"size":193.0},{"price":180.01,"size":100.0},{"price":190.0,"size":50.0},{"price":198.46,"size":2.021},{"price":199.0,"size":1.41},{"price":200.0,"size":823.3},{"price":201.0,"size":200.0},{"price":202.5,"size":10.0},{"price":210.0,"size":15.3},{"price":210.249,"size":50.0},{"price":211.1,"size":2000.0},{"price":212.0,"size":41.1},{"price":214.0,"size":0.1},{"price":215.0,"size":0.1},{"price":215.65,"size":3.0},{"price":216.0,"size":50.2},{"price":217.0,"size":0.1},{"price":218.0,"size":0.2},{"price":219.0,"size":907.4},{"price":220.0,"size":344.85},{"price":221.0,"size":10.1},{"price":222.0,"size":100.0},{"price":222.3,"size":11.0},{"price":225.0,"size":253.2},{"price":226.0,"size":50.0},{"price":226.251,"size":5.0},{"price":228.0,"size":505.65},{"price":229.0,"size":5.0},{"price":230.0,"size":16.21},{"price":231.0,"size":250.0},{"price":231.002,"size":100.0},{"price":233.513,"size":5.0},{"price":234.0,"size":100.0},{"price":235.0,"size":592.0},{"price":236.0,"size":200.0},{"price":238.0,"size":200.0},{"price":238.15,"size":1.684},{"price":240.0,"size":311.2},{"price":240.166,"size":1.0},{"price":243.0,"size":22.0},{"price":245.0,"size":2511.1},{"price":247.872,"size":0.10045},{"price":248.0,"size":300.0},{"price":249.118,"size":0.10045},{"price":250.0,"size":953.2},{"price":250.1,"size":20.0},{"price":250.823,"size":100.0},{"price":251.0,"size":30.0},{"price":251.1,"size":2000.0},{"price":252.0,"size":1.0},{"price":252.5,"size":252.0},{"price":253.0,"size":1.0},{"price":253.28,"size":200.0},{"price":253.466,"size":192.06},{"price":254.0,"size":15.6},{"price":255.0,"size":466.38},{"price":255.1,"size":20.0},{"price":255.349,"size":40.0},{"price":257.0,"size":100.0},{"price":257.1,"size":20.0},{"price":258.0,"size":202.0},{"price":259.1,"size":20.0},{"price":260.0,"size":201.1},{"price":260.25,"size":1000.0},{"price":261.1,"size":20.0},{"price":264.01,"size":100.0},{"price":265.0,"size":21.0},{"price":267.0,"size":500.0},{"price":268.0,"size":500.0},{"price":270.0,"size":211.1},{"price":271.1,"size":20.0},{"price":275.0,"size":340.0},{"price":276.622,"size":153.61778608},{"price":278.0,"size":0.3417249},{"price":280.0,"size":670.1},{"price":281.1,"size":20.0},{"price":282.11,"size":0.1},{"price":283.0,"size":500.0},{"price":285.0,"size":50.0},{"price":285.78,"size":1.403},{"price":290.0,"size":0.2},{"price":290.2,"size":100.0},{"price":291.1,"size":20.0},{"price":295.0,"size":17.0},{"price":296.66,"size":1000.0},{"price":299.1,"size":20.0},{"price":300.0,"size":1677.9},{"price":300.2,"size":100.0},{"price":301.1,"size":120.0},{"price":302.12,"size":240.0},{"price":303.784,"size":202.0},{"price":305.0,"size":16.5},{"price":306.1,"size":100.0},{"price":306.71,"size":1000.0},{"price":307.368,"size":30.0},{"price":310.0,"size":526.5},{"price":310.2,"size":100.0},{"price":311.0,"size":120.0},{"price":311.1,"size":2120.0},{"price":314.111,"size":2200.0},{"price":315.0,"size":16.4746},{"price":315.13,"size":100.0},{"price":316.1,"size":100.0},{"price":318.0,"size":3.0},{"price":320.0,"size":667.4},{"price":320.5,"size":100.0},{"price":320.563,"size":80.0},{"price":321.1,"size":100.0},{"price":322.0,"size":210.0},{"price":323.0,"size":1500.0},{"price":325.0,"size":6184.423},{"price":326.1,"size":100.0},{"price":326.34,"size":240.0},{"price":327.368,"size":211.0},{"price":328.0,"size":750.6517},{"price":329.986,"size":142.01},{"price":330.0,"size":15.5},{"price":330.01,"size":10.0},{"price":330.5,"size":100.0},{"price":331.1,"size":100.0},{"price":332.01,"size":205.0},{"price":333.0,"size":28.0},{"price":335.0,"size":15.1},{"price":335.001,"size":10.0},{"price":335.5,"size":1513.64828614},{"price":336.1,"size":100.0},{"price":337.423,"size":800.0},{"price":337.52,"size":10.0},{"price":337.775,"size":320.0},{"price":340.0,"size":426.5},{"price":340.5,"size":100.0},{"price":341.1,"size":100.0},{"price":342.94,"size":1.169},{"price":343.0,"size":1000.0},{"price":345.0,"size":14.6},{"price":345.513,"size":200.0},{"price":346.1,"size":100.0},{"price":346.13,"size":221.0},{"price":347.52,"size":10.0},{"price":350.0,"size":2298.5},{"price":350.5,"size":100.0},{"price":351.0,"size":150.0},{"price":351.1,"size":2100.0},{"price":353.0,"size":1000.0},{"price":353.008,"size":200.0},{"price":355.0,"size":14.3},{"price":356.1,"size":100.0},{"price":357.52,"size":10.0},{"price":357.98,"size":25.0},{"price":358.08,"size":22.3},{"price":360.0,"size":742.4},{"price":361.0,"size":2000.0},{"price":361.076,"size":828.0},{"price":361.1,"size":300.0},{"price":361.6,"size":250.0},{"price":362.0,"size":60.0},{"price":363.0,"size":40.0},{"price":363.12,"size":1000.0},{"price":365.0,"size":73.9},{"price":365.73,"size":210.0},{"price":366.0,"size":53.0},{"price":366.1,"size":100.0},{"price":366.66,"size":857.0},{"price":367.52,"size":10.0},{"price":368.688,"size":200.0},{"price":370.0,"size":258.8},{"price":371.1,"size":100.0},{"price":373.0,"size":40.0},{"price":376.0,"size":335.0},{"price":377.52,"size":10.0},{"price":377.525,"size":835.0},{"price":379.392,"size":1729.0},{"price":380.0,"size":3825.0},{"price":381.36,"size":8441.0},{"price":382.1,"size":300.0},{"price":383.224,"size":839.0},{"price":386.01,"size":200.0},{"price":387.0,"size":323.0},{"price":387.52,"size":10.0},{"price":390.0,"size":0.1},{"price":391.0,"size":0.1},{"price":392.11,"size":84.0},{"price":392.237,"size":143.0},{"price":393.9,"size":97.0},{"price":393.999,"size":437.24},{"price":394.0,"size":116.81051051},{"price":394.18,"size":13.0},{"price":394.507,"size":124.21},{"price":395.0,"size":10.015},{"price":397.576,"size":585.3},{"price":399.897,"size":80.53},{"price":400.0,"size":70.0},{"price":400.097,"size":88.0},{"price":400.298,"size":88.4},{"price":401.02,"size":89.6},{"price":401.678,"size":106.11},{"price":401.688,"size":286.89}],"asks":[{"price":401.902,"size":117.27},{"price":402.0,"size":1432.48338339},{"price":402.1,"size":0.1},{"price":402.103,"size":82.1},{"price":402.2,"size":0.1},{"price":402.3,"size":0.1},{"price":402.303,"size":77.67},{"price":402.4,"size":0.1},{"price":402.5,"size":0.1},{"price":402.6,"size":0.1},{"price":402.7,"size":0.1},{"price":402.8,"size":0.1},{"price":402.9,"size":0.1},{"price":403.0,"size":0.2},{"price":403.1,"size":0.1},{"price":403.2,"size":0.1},{"price":403.3,"size":0.1},{"price":403.4,"size":0.1},{"price":403.5,"size":0.1},{"price":403.6,"size":0.1},{"price":403.7,"size":0.1},{"price":403.8,"size":0.1},{"price":403.9,"size":0.1},{"price":404.0,"size":0.1},{"price":405.0,"size":0.1},{"price":405.608,"size":585.6},{"price":405.666,"size":100.0},{"price":406.0,"size":0.1},{"price":406.1,"size":0.1},{"price":406.2,"size":0.2},{"price":406.3,"size":0.1},{"price":406.4,"size":0.1},{"price":406.5,"size":0.1},{"price":406.6,"size":0.1},{"price":406.7,"size":0.1},{"price":406.8,"size":0.1},{"price":406.9,"size":0.1},{"price":407.0,"size":0.1},{"price":407.1,"size":0.1},{"price":407.2,"size":0.1},{"price":407.3,"size":0.1},{"price":407.4,"size":0.1},{"price":407.5,"size":0.1},{"price":407.6,"size":0.1},{"price":407.7,"size":0.1},{"price":407.8,"size":0.1},{"price":407.9,"size":0.1},{"price":408.0,"size":0.2},{"price":408.1,"size":0.1},{"price":408.2,"size":0.2},{"price":408.3,"size":0.1},{"price":408.4,"size":0.2},{"price":408.5,"size":0.1},{"price":408.6,"size":0.2},{"price":408.7,"size":0.1},{"price":408.8,"size":0.2},{"price":408.9,"size":0.1},{"price":409.0,"size":0.2},{"price":409.1,"size":0.1},{"price":409.2,"size":0.2},{"price":409.3,"size":0.1},{"price":409.4,"size":0.2},{"price":409.5,"size":100.1},{"price":409.6,"size":0.2},{"price":409.7,"size":0.1},{"price":409.8,"size":0.2},{"price":409.9,"size":1274.1},{"price":410.0,"size":6.691},{"price":410.081,"size":378.14},{"price":410.2,"size":0.1},{"price":410.4,"size":0.1},{"price":410.6,"size":0.1},{"price":411.0,"size":0.1},{"price":411.071,"size":839.0},{"price":411.2,"size":0.1},{"price":411.4,"size":0.1},{"price":411.6,"size":0.1},{"price":411.8,"size":0.1},{"price":412.0,"size":0.1},{"price":412.2,"size":0.1},{"price":412.4,"size":0.1},{"price":413.0,"size":0.1},{"price":414.0,"size":0.2},{"price":414.001,"size":100.0},{"price":415.0,"size":99.9},{"price":416.0,"size":0.2},{"price":417.0,"size":0.1},{"price":417.4,"size":0.1},{"price":417.5,"size":0.1},{"price":417.6,"size":0.1},{"price":418.1,"size":0.1},{"price":418.2,"size":0.1},{"price":418.3,"size":0.1},{"price":418.4,"size":0.1},{"price":418.5,"size":0.1},{"price":418.6,"size":0.1},{"price":418.7,"size":0.1},{"price":418.8,"size":0.1},{"price":418.9,"size":0.1},{"price":419.2,"size":0.1},{"price":419.3,"size":0.1},{"price":419.5,"size":0.1},{"price":419.6,"size":0.1},{"price":419.66,"size":825.0},{"price":419.7,"size":0.1},{"price":419.8,"size":0.1},{"price":419.9,"size":0.1},{"price":420.0,"size":25.2750125},{"price":420.1,"size":0.1},{"price":420.2,"size":0.1},{"price":420.3,"size":1.0},{"price":420.4,"size":1.0},{"price":420.45,"size":200.0},{"price":420.5,"size":1.0},{"price":420.6,"size":1.0},{"price":420.7,"size":1.0},{"price":420.75,"size":117.65},{"price":420.8,"size":1.0},{"price":420.9,"size":1.0},{"price":421.0,"size":1.0},{"price":421.1,"size":0.1},{"price":421.2,"size":0.1},{"price":421.3,"size":0.1},{"price":421.354,"size":116.48},{"price":421.4,"size":0.1},{"price":421.5,"size":0.1},{"price":421.6,"size":0.1},{"price":421.7,"size":0.1},{"price":421.8,"size":0.1},{"price":421.9,"size":0.1},{"price":422.0,"size":0.1},{"price":422.1,"size":0.1},{"price":422.2,"size":0.1},{"price":422.3,"size":0.1},{"price":422.4,"size":0.1},{"price":422.5,"size":0.1},{"price":422.6,"size":4117.45607667},{"price":422.7,"size":0.1},{"price":422.8,"size":0.1},{"price":422.9,"size":0.1},{"price":423.0,"size":0.1},{"price":424.0,"size":0.1},{"price":425.0,"size":255.92},{"price":425.369,"size":116.37},{"price":426.0,"size":0.1},{"price":426.825,"size":19.8615},{"price":427.0,"size":0.1},{"price":428.0,"size":0.1},{"price":428.7,"size":55.19225102},{"price":429.0,"size":0.1},{"price":429.001,"size":100.0},{"price":429.9,"size":20.0},{"price":430.0,"size":1204.69527263},{"price":431.0,"size":0.1},{"price":431.64,"size":114.68},{"price":431.928,"size":114.61},{"price":432.0,"size":0.1},{"price":432.534,"size":530.0},{"price":433.0,"size":0.1},{"price":433.9,"size":20.0},{"price":434.0,"size":0.1},{"price":435.0,"size":200.2},{"price":436.0,"size":48.12454619},{"price":436.1,"size":2600.0},{"price":437.0,"size":0.1},{"price":438.0,"size":20.1},{"price":438.03,"size":0.5996},{"price":438.47,"size":10.0},{"price":439.0,"size":0.1},{"price":440.0,"size":0.2},{"price":441.0,"size":0.1},{"price":442.0,"size":20.1},{"price":443.0,"size":200.1},{"price":444.0,"size":0.1},{"price":445.0,"size":2119.93629},{"price":445.55,"size":100.0},{"price":446.0,"size":0.2},{"price":447.0,"size":0.2},{"price":448.0,"size":100.2},{"price":448.47,"size":10.0},{"price":448.855,"size":210.0},{"price":449.0,"size":100.2},{"price":449.9,"size":100.0},{"price":449.99,"size":100.0},{"price":450.0,"size":2450.45238395},{"price":450.1,"size":50.0},{"price":453.437,"size":24.32},{"price":454.894,"size":10.0},{"price":454.99,"size":100.0},{"price":455.0,"size":0.1},{"price":458.47,"size":10.0},{"price":460.0,"size":576.42949246},{"price":461.0,"size":133.0},{"price":462.0,"size":7.98},{"price":462.185,"size":23.8},{"price":463.0,"size":1501.0},{"price":464.894,"size":10.0},{"price":465.0,"size":700.1},{"price":468.47,"size":10.0},{"price":470.0,"size":28.031},{"price":471.0,"size":5.0},{"price":474.894,"size":10.0},{"price":475.0,"size":0.1},{"price":475.1,"size":100.0},{"price":476.0,"size":401.0},{"price":477.0,"size":200.0},{"price":478.47,"size":10.0},{"price":479.0,"size":1768.7},{"price":480.0,"size":457.48343531},{"price":481.0,"size":399.6},{"price":482.21,"size":580.0},{"price":484.0,"size":1085.0},{"price":484.894,"size":10.0},{"price":485.0,"size":700.1},{"price":488.0,"size":0.5},{"price":488.47,"size":10.0},{"price":488.87,"size":10.0},{"price":489.0,"size":10050.0},{"price":490.0,"size":3102.2},{"price":493.0,"size":480.0},{"price":493.84,"size":0.974},{"price":494.0,"size":54.85718567},{"price":494.451,"size":80.0},{"price":494.894,"size":10.0},{"price":495.0,"size":150.1},{"price":495.999,"size":20.24024025},{"price":498.5,"size":2498.49900884},{"price":498.855,"size":10.0},{"price":498.87,"size":10.0},{"price":498.9,"size":8.0},{"price":499.0,"size":628.5},{"price":499.1,"size":100.0},{"price":499.47,"size":9.5},{"price":499.9,"size":700.0},{"price":500.0,"size":12538.91090088},{"price":501.0,"size":127.5},{"price":510.0,"size":510.1},{"price":520.0,"size":1220.1},{"price":524.45,"size":10.0},{"price":525.0,"size":98.3},{"price":525.1,"size":100.0},{"price":530.0,"size":0.2},{"price":532.45,"size":10.0},{"price":540.0,"size":46.41404455},{"price":544.94,"size":20.0},{"price":548.0,"size":50.0},{"price":548.45,"size":10.0},{"price":549.1,"size":100.0},{"price":550.0,"size":6257.74688116},{"price":554.0,"size":10.0},{"price":555.555,"size":555.555555},{"price":560.0,"size":997.3624},{"price":572.0,"size":20.0},{"price":575.0,"size":0.1},{"price":575.1,"size":100.0},{"price":580.0,"size":100.0},{"price":590.0,"size":1905.68170578},{"price":592.61,"size":100.812},{"price":598.598,"size":241.18},{"price":599.1,"size":100.0},{"price":600.0,"size":410.6},{"price":601.0,"size":100.0},{"price":625.0,"size":100.0},{"price":625.1,"size":100.0},{"price":639.0,"size":100.0},{"price":647.0,"size":55.0},{"price":649.1,"size":100.0},{"price":650.0,"size":2538.64523714},{"price":666.666,"size":666.666666},{"price":666.999,"size":30.77464322},{"price":672.0,"size":883.0},{"price":675.1,"size":100.0},{"price":679.0,"size":1000.0},{"price":684.4,"size":25.0},{"price":685.0,"size":150.0},{"price":690.0,"size":4387.0},{"price":696.5,"size":10.0},{"price":698.0,"size":11000.0},{"price":699.0,"size":499.0},{"price":699.1,"size":100.0},{"price":700.0,"size":5251.53641859},{"price":711.13,"size":0.677},{"price":715.0,"size":81.0},{"price":720.0,"size":450.0},{"price":725.0,"size":200.0},{"price":728.0,"size":432.73010138},{"price":735.0,"size":1682.0},{"price":742.0,"size":10.0},{"price":750.0,"size":269.19121318},{"price":777.777,"size":777.777777},{"price":798.0,"size":3195.54134535},{"price":799.0,"size":150.0},{"price":800.0,"size":20000.0},{"price":853.36,"size":0.564},{"price":880.0,"size":1.0},{"price":886.0,"size":1012.46944917},{"price":888.0,"size":50.0}]}}}
1618677597.5640461: {"jsonrpc":"2.0","method":"channelMessage","params":{"channel":"lightning_board_snapshot_XLM_JPY","message":{"mid_price":65.973,"bids":[{"price":25.0,"size":100.1},{"price":26.0,"size":0.2},{"price":27.0,"size":0.1},{"price":28.0,"size":1400.2},{"price":29.0,"size":0.2},{"price":30.0,"size":100.1},{"price":31.0,"size":0.2},{"price":32.0,"size":0.1},{"price":33.0,"size":0.2},{"price":34.0,"size":200.2},{"price":35.0,"size":1.1},{"price":35.49,"size":200.0},{"price":36.0,"size":101.2},{"price":37.0,"size":0.1},{"price":38.0,"size":1122.884},{"price":38.47,"size":10.424},{"price":39.0,"size":500.2},{"price":39.78,"size":30.0},{"price":40.0,"size":838.1},{"price":40.5,"size":300.0},{"price":41.0,"size":0.2},{"price":41.6,"size":50.1},{"price":41.65,"size":5000.0},{"price":42.0,"size":110.2},{"price":43.0,"size":51.315},{"price":43.001,"size":200.0},{"price":43.025,"size":30.0},{"price":43.729,"size":109.21627},{"price":44.0,"size":110.2},{"price":44.001,"size":20.0},{"price":44.1,"size":23.0},{"price":44.494,"size":100.0},{"price":45.0,"size":2803.0},{"price":45.105,"size":300.0},{"price":45.5,"size":6500.0},{"price":45.6,"size":100.0},{"price":45.877,"size":700.0},{"price":46.0,"size":1100.0},{"price":46.1,"size":20.0},{"price":46.16,"size":8.687},{"price":46.82,"size":200.0},{"price":47.0,"size":11.105},{"price":47.23,"size":200.0},{"price":47.5,"size":502.0},{"price":48.0,"size":150.0},{"price":48.01,"size":1002.0},{"price":48.767,"size":441.84},{"price":49.35,"size":300.0},{"price":49.5,"size":2.0},{"price":50.0,"size":4255.0},{"price":50.009,"size":5.0},{"price":50.1,"size":5000.0},{"price":50.13,"size":10.0},{"price":50.5,"size":102.0},{"price":51.0,"size":1.198},{"price":51.001,"size":10000.0},{"price":51.17,"size":30.0},{"price":51.442,"size":100.0},{"price":51.5,"size":3.009},{"price":52.0,"size":5151.4985},{"price":52.1,"size":400.0},{"price":52.2,"size":100.0},{"price":52.31,"size":1000.0},{"price":52.317,"size":50.0},{"price":52.5,"size":52.0},{"price":52.592,"size":0.1},{"price":53.0,"size":2363.827},{"price":53.05,"size":1.3},{"price":53.26,"size":100.0},{"price":53.4,"size":30.0},{"price":53.5,"size":1102.0},{"price":53.64,"size":300.0},{"price":54.0,"size":2020.0},{"price":54.18,"size":0.04},{"price":54.37,"size":400.0},{"price":54.5,"size":2.0},{"price":55.0,"size":19621.391},{"price":55.2,"size":182.0},{"price":55.39,"size":7.24},{"price":55.5,"size":22102.0},{"price":55.72,"size":1800.0},{"price":55.8,"size":10.0},{"price":56.0,"size":10025.0},{"price":56.23,"size":400.0},{"price":56.3,"size":5205.0},{"price":56.5,"size":400.0},{"price":57.0,"size":5007.5},{"price":57.1,"size":501.0},{"price":57.15,"size":6010.0},{"price":57.997,"size":10.0},{"price":58.0,"size":15612.0},{"price":58.01,"size":100000.0},{"price":58.2,"size":50.0},{"price":58.4,"size":2000.0},{"price":58.45,"size":200.0},{"price":58.5,"size":19.0},{"price":58.95,"size":200.0},{"price":59.0,"size":429.2122373},{"price":59.1,"size":300.0},{"price":59.5,"size":201.6},{"price":59.6,"size":500.0},{"price":60.0,"size":13065.32036},{"price":60.1,"size":10485.0},{"price":60.2,"size":167.0},{"price":60.251,"size":5.0},{"price":60.43,"size":30.6998179},{"price":60.5,"size":1175.0},{"price":60.57,"size":600.0},{"price":60.6,"size":800.0},{"price":60.7,"size":11.0},{"price":61.0,"size":14547.5149792},{"price":61.1,"size":200.0},{"price":61.2,"size":5.0},{"price":61.5,"size":10550.0},{"price":61.57,"size":60.0},{"price":61.8,"size":50.0},{"price":62.0,"size":23636.1924108},{"price":62.01,"size":1703.0},{"price":62.1,"size":100.0},{"price":62.25,"size":49.0},{"price":62.273,"size":8149.0},{"price":62.38,"size":2019.9377},{"price":62.4,"size":799.18269},{"price":62.5,"size":321.688},{"price":62.51,"size":10.0},{"price":62.578,"size":5.0},{"price":62.6,"size":2000.0},{"price":62.744,"size":20.025},{"price":62.826,"size":7972.0},{"price":62.995,"size":91.3},{"price":63.0,"size":10307.9606667},{"price":63.001,"size":1800.0},{"price":63.1,"size":20301.0},{"price":63.11,"size":100.0},{"price":63.31,"size":2010.0},{"price":63.5,"size":100.0},{"price":63.637,"size":115.8},{"price":63.917,"size":108.69},{"price":63.95,"size":476.0},{"price":64.0,"size":2818.6},{"price":64.01,"size":150.0},{"price":64.1,"size":2250.0},{"price":64.2,"size":2000.5},{"price":64.316,"size":101.13},{"price":64.413,"size":7994.0},{"price":64.5,"size":10011.0},{"price":64.627,"size":16225.0},{"price":64.701,"size":96.7},{"price":64.78,"size":500.0},{"price":64.8,"size":9650.0},{"price":64.81,"size":1000.0},{"price":64.844,"size":100.0},{"price":64.998,"size":2.0},{"price":65.0,"size":6483.09231},{"price":65.022,"size":31911.0},{"price":65.1,"size":1814.0572},{"price":65.101,"size":117.9},{"price":65.266,"size":83.5},{"price":65.442,"size":81387.0},{"price":65.526,"size":899.74},{"price":65.611,"size":677.0},{"price":65.692,"size":4139.0},{"price":65.707,"size":7928.0},{"price":65.713,"size":3791.0},{"price":65.728,"size":4083.0},{"price":65.738,"size":617.1},{"price":65.825,"size":997.0},{"price":65.91,"size":2505.618},{"price":65.911,"size":757.84}],"asks":[{"price":66.036,"size":534.0},{"price":66.05,"size":2505.618},{"price":66.133,"size":948.15},{"price":66.254,"size":7928.0},{"price":66.271,"size":631.9},{"price":66.516,"size":3030.68},{"price":66.517,"size":811.4},{"price":66.584,"size":107.7},{"price":66.659,"size":32027.0},{"price":66.749,"size":112.62},{"price":66.819,"size":122.23},{"price":66.87,"size":299.1},{"price":67.085,"size":8127.0},{"price":67.132,"size":15699.0},{"price":67.275,"size":105.64},{"price":67.614,"size":89.0},{"price":67.8,"size":99.0},{"price":67.87,"size":97.91},{"price":67.95,"size":100.0},{"price":68.0,"size":50.0},{"price":68.244,"size":112.7},{"price":68.253,"size":105.0},{"price":68.4,"size":3983.0},{"price":68.465,"size":7842.0},{"price":68.5,"size":200.0},{"price":68.569,"size":200.0},{"price":68.75,"size":500.0},{"price":69.0,"size":2253.0},{"price":69.3,"size":5999.0},{"price":69.55,"size":6000.0},{"price":69.738,"size":99.3075},{"price":69.795,"size":4000.0},{"price":69.871,"size":5000.0},{"price":70.0,"size":11653.6638107},{"price":70.1,"size":712.704576},{"price":70.2,"size":7100.0},{"price":70.23,"size":5000.0},{"price":70.237,"size":2500.0},{"price":70.32,"size":2000.0},{"price":70.4,"size":1000.0},{"price":70.49,"size":20.0},{"price":70.5,"size":2600.0},{"price":70.569,"size":199.12},{"price":70.8,"size":450.0},{"price":70.85,"size":498.948},{"price":70.9,"size":4760.0},{"price":70.942,"size":598.8011989},{"price":71.0,"size":36229.05},{"price":71.1,"size":500.0},{"price":71.2,"size":6250.0},{"price":71.24,"size":5002.5},{"price":71.28,"size":500.0},{"price":71.314,"size":0.458},{"price":71.32,"size":2000.0},{"price":71.5,"size":5870.0},{"price":71.6,"size":250.0},{"price":71.677,"size":9.0},{"price":71.8,"size":5300.0},{"price":71.804,"size":15.521},{"price":71.98,"size":81.9},{"price":72.0,"size":13411.4003199},{"price":72.15,"size":38.8383333},{"price":72.4,"size":48034.05044},{"price":72.46,"size":14.9827},{"price":72.5,"size":4495.0},{"price":72.6,"size":99.0},{"price":72.765,"size":5000.0},{"price":72.981,"size":683.06},{"price":73.0,"size":6352.6448612},{"price":73.096,"size":681.98},{"price":73.101,"size":681.94},{"price":73.29,"size":57201.694009},{"price":73.351,"size":1299.0},{"price":73.4,"size":8000.0},{"price":73.468,"size":678.53},{"price":73.5,"size":2829.9},{"price":73.569,"size":677.6},{"price":73.579,"size":677.51},{"price":73.6,"size":5000.0},{"price":73.65,"size":2000.0},{"price":73.957,"size":44046.085926},{"price":74.0,"size":997.7041439},{"price":74.01,"size":100.0},{"price":74.1,"size":1739.3},{"price":74.49,"size":400.0},{"price":74.5,"size":5070.0},{"price":74.69,"size":233.0},{"price":74.71,"size":676.0},{"price":74.78,"size":10000.0},{"price":74.85,"size":3996.0},{"price":74.9,"size":10003.7016532},{"price":74.92,"size":35.0},{"price":74.99,"size":800.0},{"price":75.0,"size":20568.2355105},{"price":75.1,"size":1000.0},{"price":75.555,"size":350.0},{"price":75.6,"size":5.0},{"price":75.78,"size":470.0},{"price":76.0,"size":4909.88},{"price":76.26,"size":200.0},{"price":76.292,"size":100.0},{"price":76.83,"size":40000.0},{"price":77.0,"size":7683.56},{"price":77.1,"size":100.0},{"price":77.5,"size":1446.0},{"price":77.777,"size":100.0},{"price":78.0,"size":6127.9},{"price":78.1,"size":100.0},{"price":78.3,"size":2000.0},{"price":78.5,"size":5000.0},{"price":79.0,"size":219990.601},{"price":79.05,"size":1300.0},{"price":79.1,"size":100.0},{"price":79.76,"size":6.033},{"price":80.0,"size":11272.581954},{"price":80.1,"size":100.0},{"price":81.0,"size":1.0},{"price":82.0,"size":598.0},{"price":82.5,"size":5000.0},{"price":83.0,"size":70.0},{"price":85.0,"size":43960.0},{"price":87.6,"size":5000.0},{"price":88.0,"size":152000.0},{"price":89.9,"size":299.7},{"price":90.0,"size":12.1},{"price":91.0,"size":100.0},{"price":91.264,"size":52.25972},{"price":91.5,"size":5000.0},{"price":94.53,"size":100.0},{"price":95.0,"size":10.0},{"price":95.71,"size":5.028},{"price":97.77,"size":10000.0},{"price":99.0,"size":8978.0},{"price":99.47,"size":1440.0},{"price":100.0,"size":3530.1},{"price":105.6,"size":4960.0},{"price":110.0,"size":998.0},{"price":114.85,"size":4.19},{"price":120.0,"size":1829.7339845},{"price":126.35,"size":100.0},{"price":130.0,"size":3052.0},{"price":135.26,"size":100.0}]}}}
1618677597.5688992: {"jsonrpc":"2.0","method":"channelMessage","params":{"channel":"lightning_board_XRP_JPY","message":{"mid_price":173.01,"bids":[{"price":172.71,"size":1672.29}],"asks":[]}}}
1618677597.569026: {"jsonrpc":"2.0","method":"channelMessage","params":{"channel":"lightning_board_BTC_USD","message":{"mid_price":60542.25,"bids":[],"asks":[{"price":60856.38,"size":0.39}]}}}
1618677597.569081: {"jsonrpc":"2.0","method":"channelMessage","params":{"channel":"lightning_board_ETH_JPY","message":{"mid_price":258826.0,"bids":[{"price":258730.0,"size":0.0}],"asks":[]}}}
1618677597.569108: {"jsonrpc":"2.0","method":"channelMessage","params":{"channel":"lightning_board_MONA_JPY","message":{"mid_price":401.795,"bids":[{"price":383.224,"size":839.0}],"asks":[]}}}
1618677597.612443: {"jsonrpc":"2.0","method":"channelMessage","params":{"channel":"lightning_board_FX_BTC_JPY","message":{"mid_price":7187389.0,"bids":[{"price":6943995.0,"size":2.80127036}],"asks":[{"price":7190389.0,"size":0.0}]}}}
1618677597.651605: {"jsonrpc":"2.0","method":"channelMessage","params":{"channel":"lightning_ticker_BTC_EUR","message":{"product_code":"BTC_EUR","state":"RUNNING","timestamp":"2021-04-17T16:39:57.5005418Z","tick_id":1845540,"best_bid":50764.2,"best_ask":50896.12,"best_bid_size":2.12603015,"best_ask_size":0.40077,"total_bid_depth":9.97747715,"total_ask_depth":11.98508706,"market_bid_size":0.0,"market_ask_size":0.0,"ltp":50500.0,"volume":12.650261930000,"volume_by_product":12.650261930000}}}
1618677597.651716: {"jsonrpc":"2.0","method":"channelMessage","params":{"channel":"lightning_board_BTC_EUR","message":{"mid_price":50830.16,"bids":[{"price":50618.25,"size":0.0},{"price":50601.53,"size":0.0},{"price":50590.24,"size":0.2},{"price":50606.94,"size":0.2}],"asks":[]}}}
1618677597.651815: {"jsonrpc":"2.0","method":"channelMessage","params":{"channel":"lightning_board_ETH_JPY","message":{"mid_price":258821.0,"bids":[{"price":258177.0,"size":2.1157752},{"price":258235.0,"size":1.2694257},{"price":258726.0,"size":0.0}],"asks":[{"price":258908.0,"size":0.0},{"price":258886.0,"size":2.55},{"price":258894.0,"size":1.0}]}}}
1618677597.651895: {"jsonrpc":"2.0","method":"channelMessage","params":{"channel":"lightning_board_XRP_JPY","message":{"mid_price":173.01,"bids":[{"price":172.9,"size":0.0}],"asks":[]}}}
1618677597.7233438: {"jsonrpc":"2.0","method":"channelMessage","params":{"channel":"lightning_ticker_BTCJPY23APR2021","message":{"product_code":"BTCJPY23APR2021","state":"RUNNING","timestamp":"2021-04-17T16:39:57.6011541Z","tick_id":86407,"best_bid":6590603.0,"best_ask":6614181.0,"best_bid_size":0.04,"best_ask_size":0.01,"total_bid_depth":460.940,"total_ask_depth":451.401,"market_bid_size":0.0,"market_ask_size":0.0,"ltp":6582268.0,"volume":1.679,"volume_by_product":1.679}}}
1618677597.723453: {"jsonrpc":"2.0","method":"channelMessage","params":{"channel":"lightning_board_BTCJPY23APR2021","message":{"mid_price":6602392.0,"bids":[{"price":6590603.0,"size":0.04}],"asks":[]}}}
1618677597.7235231: {"jsonrpc":"2.0","method":"channelMessage","params":{"channel":"lightning_ticker_FX_BTC_JPY","message":{"product_code":"FX_BTC_JPY","state":"RUNNING","timestamp":"2021-04-17T16:39:57.6011541Z","tick_id":42420509,"best_bid":7186230.0,"best_ask":7188549.0,"best_bid_size":0.01,"best_ask_size":0.072,"total_bid_depth":2428.875523960000,"total_ask_depth":2471.064814510000,"market_bid_size":0.0,"market_ask_size":0.0,"ltp":7186655.0,"volume":2105.774486030000,"volume_by_product":2105.774486030000}}}
1618677597.723575: {"jsonrpc":"2.0","method":"channelMessage","params":{"channel":"lightning_board_FX_BTC_JPY","message":{"mid_price":7187389.0,"bids":[{"price":6943995.0,"size":0.0}],"asks":[]}}}
1618677597.763008: {"jsonrpc":"2.0","method":"channelMessage","params":{"channel":"lightning_board_ETH_JPY","message":{"mid_price":258821.0,"bids":[{"price":258235.0,"size":0.0}],"asks":[]}}}
1618677597.7631328: {"jsonrpc":"2.0","method":"channelMessage","params":{"channel":"lightning_board_BTC_USD","message":{"mid_price":60542.25,"bids":[{"price":60199.79,"size":0.007},{"price":60514.3,"size":0.056}],"asks":[{"price":60566.9,"size":0.091}]}}}
1618677597.8686929: {"jsonrpc":"2.0","method":"channelMessage","params":{"channel":"lightning_ticker_ETH_JPY","message":{"product_code":"ETH_JPY","state":"RUNNING","timestamp":"2021-04-17T16:39:57.7385478Z","tick_id":10943332,"best_bid":258757.0,"best_ask":258886.0,"best_bid_size":0.700000,"best_ask_size":2.55,"total_bid_depth":2393.027373100000,"total_ask_depth":2101.9285831,"market_bid_size":0.0,"market_ask_size":0.0,"ltp":258811.0,"volume":18068.180445400000,"volume_by_product":18068.180445400000}}}
1618677597.874028: {"jsonrpc":"2.0","method":"channelMessage","params":{"channel":"lightning_board_ETH_JPY","message":{"mid_price":258821.0,"bids":[{"price":258147.0,"size":5.824},{"price":258272.0,"size":0.0}],"asks":[]}}}
1618677597.874157: {"jsonrpc":"2.0","method":"channelMessage","params":{"channel":"lightning_board_XRP_JPY","message":{"mid_price":173.01,"bids":[{"price":172.71,"size":0.0},{"price":172.65,"size":3344.58}],"asks":[]}}}
1618677597.890489: {"jsonrpc":"2.0","method":"channelMessage","params":{"channel":"lightning_board_FX_BTC_JPY","message":{"mid_price":7187389.0,"bids":[],"asks":[{"price":7188549.0,"size":0.082}]}}}
1618677597.992106: {"jsonrpc":"2.0","method":"channelMessage","params":{"channel":"lightning_ticker_BCH_BTC","message":{"product_code":"BCH_BTC","state":"RUNNING","timestamp":"2021-04-17T16:39:57.8667544Z","tick_id":895713,"best_bid":0.01668,"best_ask":0.01754,"best_bid_size":1.25,"best_ask_size":0.30,"total_bid_depth":261.85068360,"total_ask_depth":159.48924376,"market_bid_size":0.0,"market_ask_size":0.0,"ltp":0.0167,"volume":1007.840099870000,"volume_by_product":1007.840099870000}}}
1618677597.992218: {"jsonrpc":"2.0","method":"channelMessage","params":{"channel":"lightning_board_BCH_BTC","message":{"mid_price":0.01711,"bids":[],"asks":[{"price":0.01764,"size":14.04}]}}}
1618677597.99229: {"jsonrpc":"2.0","method":"channelMessage","params":{"channel":"lightning_ticker_XRP_JPY","message":{"product_code":"XRP_JPY","state":"RUNNING","timestamp":"2021-04-17T16:39:57.8667544Z","tick_id":8062980,"best_bid":172.97,"best_ask":173.04,"best_bid_size":1503.37,"best_ask_size":1.0,"total_bid_depth":1509660.93693700,"total_ask_depth":2546939.13723400,"market_bid_size":0.0,"market_ask_size":0.0,"ltp":173.14,"volume":8347324.511315000000,"volume_by_product":8347324.511315000000}}}
1618677597.992343: {"jsonrpc":"2.0","method":"channelMessage","params":{"channel":"lightning_board_XRP_JPY","message":{"mid_price":173.0,"bids":[],"asks":[{"price":173.04,"size":1.0}]}}}
1618677598.1020749: {"jsonrpc":"2.0","method":"channelMessage","params":{"channel":"lightning_board_BTC_EUR","message":{"mid_price":50858.04,"bids":[{"price":50819.96,"size":0.40077}],"asks":[]}}}
1618677598.102141: {"jsonrpc":"2.0","method":"channelMessage","params":{"channel":"lightning_board_XRP_JPY","message":{"mid_price":173.0,"bids":[{"price":172.39,"size":0.0}],"asks":[]}}}
1618677598.130621: {"jsonrpc":"2.0","method":"channelMessage","params":{"channel":"lightning_board_BTCJPY23APR2021","message":{"mid_price":6602392.0,"bids":[{"price":6588500.0,"size":0.0}],"asks":[]}}}
1618677598.208214: {"jsonrpc":"2.0","method":"channelMessage","params":{"channel":"lightning_board_XRP_JPY","message":{"mid_price":172.92,"bids":[{"price":172.97,"size":0.0},{"price":172.65,"size":0.0}],"asks":[]}}}
1618677598.2083452: {"jsonrpc":"2.0","method":"channelMessage","params":{"channel":"lightning_board_ETH_JPY","message":{"mid_price":258821.0,"bids":[{"price":258147.0,"size":0.0}],"asks":[]}}}
1618677598.327451: {"jsonrpc":"2.0","method":"channelMessage","params":{"channel":"lightning_board_ETH_JPY","message":{"mid_price":258821.0,"bids":[{"price":258677.0,"size":1.0}],"asks":[{"price":258886.0,"size":3.55}]}}}
1618677598.3306298: {"jsonrpc":"2.0","method":"channelMessage","params":{"channel":"lightning_ticker_BTC_EUR","message":{"product_code":"BTC_EUR","state":"RUNNING","timestamp":"2021-04-17T16:39:58.1948688Z","tick_id":1845544,"best_bid":50819.96,"best_ask":50896.12,"best_bid_size":0.40077,"best_ask_size":0.40077,"total_bid_depth":9.61824715,"total_ask_depth":11.98508706,"market_bid_size":0.0,"market_ask_size":0.0,"ltp":50500.0,"volume":12.650261930000,"volume_by_product":12.650261930000}}}
1618677598.3307421: {"jsonrpc":"2.0","method":"channelMessage","params":{"channel":"lightning_board_BTC_EUR","message":{"mid_price":50858.04,"bids":[{"price":50740.69,"size":0.0},{"price":50718.33,"size":0.0},{"price":50550.59,"size":0.0}],"asks":[]}}}
1618677598.4391491: {"jsonrpc":"2.0","method":"channelMessage","params":{"channel":"lightning_board_BTC_EUR","message":{"mid_price":50858.04,"bids":[{"price":50578.32,"size":0.35},{"price":50746.15,"size":0.26}],"asks":[]}}}
1618677598.4971242: {"jsonrpc":"2.0","method":"channelMessage","params":{"channel":"lightning_ticker_BTCJPY23APR2021","message":{"product_code":"BTCJPY23APR2021","state":"RUNNING","timestamp":"2021-04-17T16:39:58.3822088Z","tick_id":86409,"best_bid":6590603.0,"best_ask":6614181.0,"best_bid_size":0.04,"best_ask_size":0.01,"total_bid_depth":460.940,"total_ask_depth":451.401,"market_bid_size":0.0,"market_ask_size":0.0,"ltp":6582268.0,"volume":1.679,"volume_by_product":1.679}}}
1618677598.501756: {"jsonrpc":"2.0","method":"channelMessage","params":{"channel":"lightning_board_BTCJPY23APR2021","message":{"mid_price":6602392.0,"bids":[{"price":6588900.0,"size":0.2}],"asks":[]}}}
1618677598.552395: {"jsonrpc":"2.0","method":"channelMessage","params":{"channel":"lightning_board_BTC_EUR","message":{"mid_price":50858.04,"bids":[{"price":50768.52,"size":0.15}],"asks":[]}}}
1618677598.552479: {"jsonrpc":"2.0","method":"channelMessage","params":{"channel":"lightning_ticker_BTC_USD","message":{"product_code":"BTC_USD","state":"RUNNING","timestamp":"2021-04-17T16:39:58.3511256Z","tick_id":5565351,"best_bid":60517.6,"best_ask":60566.9,"best_bid_size":0.02,"best_ask_size":0.091,"total_bid_depth":8.96481782,"total_ask_depth":6.63369080,"market_bid_size":0.0,"market_ask_size":0.0,"ltp":60201.0,"volume":55.569921930000,"volume_by_product":55.569921930000}}}
1618677598.552526: {"jsonrpc":"2.0","method":"channelMessage","params":{"channel":"lightning_board_BTC_USD","message":{"mid_price":60542.25,"bids":[],"asks":[{"price":63245.22,"size":0.011}]}}}
1618677598.6570292: {"jsonrpc":"2.0","method":"channelMessage","params":{"channel":"lightning_board_BTC_USD","message":{"mid_price":60542.25,"bids":[],"asks":[{"price":60574.42,"size":0.0}]}}}
1618677598.657147: {"jsonrpc":"2.0","method":"channelMessage","params":{"channel":"lightning_ticker_XRP_JPY","message":{"product_code":"XRP_JPY","state":"RUNNING","timestamp":"2021-04-17T16:39:58.5084976Z","tick_id":8062984,"best_bid":172.8,"best_ask":173.04,"best_bid_size":614.19000000,"best_ask_size":1.0,"total_bid_depth":1503369.68693700,"total_ask_depth":2546939.13723400,"market_bid_size":0.0,"market_ask_size":0.0,"ltp":173.14,"volume":8347324.511315000000,"volume_by_product":8347324.511315000000}}}
1618677598.657218: {"jsonrpc":"2.0","method":"channelMessage","params":{"channel":"lightning_board_XRP_JPY","message":{"mid_price":172.92,"bids":[{"price":172.65,"size":1673.7}],"asks":[]}}}
1618677598.6639118: {"jsonrpc":"2.0","method":"channelMessage","params":{"channel":"lightning_ticker_ETH_JPY","message":{"product_code":"ETH_JPY","state":"RUNNING","timestamp":"2021-04-17T16:39:58.5241556Z","tick_id":10943337,"best_bid":258757.0,"best_ask":258886.0,"best_bid_size":0.700000,"best_ask_size":3.550000,"total_bid_depth":2391.723373100000,"total_ask_depth":2099.0565831,"market_bid_size":0.0,"market_ask_size":0.0,"ltp":258811.0,"volume":18068.168445400000,"volume_by_product":18068.168445400000}}}
1618677598.664023: {"jsonrpc":"2.0","method":"channelMessage","params":{"channel":"lightning_board_ETH_JPY","message":{"mid_price":258821.0,"bids":[{"price":258178.0,"size":3.52}],"asks":[{"price":259072.0,"size":0.0}]}}}
1618677598.664107: {"jsonrpc":"2.0","method":"channelMessage","params":{"channel":"lightning_board_BTC_EUR","message":{"mid_price":50858.04,"bids":[{"price":50678.96,"size":0.185}],"asks":[]}}}
1618677598.770319: {"jsonrpc":"2.0","method":"channelMessage","params":{"channel":"lightning_board_XRP_JPY","message":{"mid_price":172.92,"bids":[{"price":172.53,"size":317.37}],"asks":[]}}}
1618677598.7704031: {"jsonrpc":"2.0","method":"channelMessage","params":{"channel":"lightning_board_ETH_JPY","message":{"mid_price":258821.0,"bids":[{"price":258695.0,"size":0.0}],"asks":[{"price":258964.0,"size":3.872}]}}}
1618677598.869098: {"jsonrpc":"2.0","method":"channelMessage","params":{"channel":"lightning_ticker_FX_BTC_JPY","message":{"product_code":"FX_BTC_JPY","state":"RUNNING","timestamp":"2021-04-17T16:39:58.7460387Z","tick_id":42420511,"best_bid":7186230.0,"best_ask":7188549.0,"best_bid_size":0.01,"best_ask_size":0.082,"total_bid_depth":2428.875523960000,"total_ask_depth":2471.004814510000,"market_bid_size":0.0,"market_ask_size":0.0,"ltp":7186655.0,"volume":2105.774486030000,"volume_by_product":2105.774486030000}}}
1618677598.869211: {"jsonrpc":"2.0","method":"channelMessage","params":{"channel":"lightning_board_FX_BTC_JPY","message":{"mid_price":7187389.0,"bids":[],"asks":[{"price":7196655.0,"size":0.0}]}}}
1618677598.872503: {"jsonrpc":"2.0","method":"channelMessage","params":{"channel":"lightning_ticker_XLM_JPY","message":{"product_code":"XLM_JPY","state":"RUNNING","timestamp":"2021-04-17T16:39:58.7619469Z","tick_id":4215944,"best_bid":65.911,"best_ask":66.036,"best_bid_size":757.84,"best_ask_size":534.0,"total_bid_depth":580954.8581419,"total_ask_depth":1016905.44764110,"market_bid_size":0.0,"market_ask_size":0.0,"ltp":65.902,"volume":2182293.365166500000,"volume_by_product":2182293.365166500000}}}
1618677598.875808: {"jsonrpc":"2.0","method":"channelMessage","params":{"channel":"lightning_board_XLM_JPY","message":{"mid_price":65.973,"bids":[{"price":65.91,"size":0.0}],"asks":[]}}}
1618677598.983449: {"jsonrpc":"2.0","method":"channelMessage","params":{"channel":"lightning_board_XLM_JPY","message":{"mid_price":65.983,"bids":[{"price":65.93,"size":2505.618}],"asks":[]}}}
1618677599.097496: {"jsonrpc":"2.0","method":"channelMessage","params":{"channel":"lightning_board_ETH_JPY","message":{"mid_price":258821.0,"bids":[{"price":258178.0,"size":3.2}],"asks":[]}}}
1618677599.097609: {"jsonrpc":"2.0","method":"channelMessage","params":{"channel":"lightning_ticker_BTC_USD","message":{"product_code":"BTC_USD","state":"RUNNING","timestamp":"2021-04-17T16:39:58.9204227Z","tick_id":5565355,"best_bid":60517.6,"best_ask":60561.98,"best_bid_size":0.02,"best_ask_size":0.12,"total_bid_depth":9.16481782,"total_ask_depth":6.88369080,"market_bid_size":0.0,"market_ask_size":0.0,"ltp":60201.0,"volume":55.569921930000,"volume_by_product":55.569921930000}}}
1618677599.0976782: {"jsonrpc":"2.0","method":"channelMessage","params":{"channel":"lightning_board_BTC_USD","message":{"mid_price":60539.79,"bids":[{"price":60405.07,"size":0.2}],"asks":[{"price":60561.98,"size":0.12},{"price":60613.94,"size":0.25}]}}}
1618677599.274352: {"jsonrpc":"2.0","method":"channelMessage","params":{"channel":"lightning_board_FX_BTC_JPY","message":{"mid_price":7187389.0,"bids":[],"asks":[{"price":7188548.0,"size":0.01}]}}}
1618677599.317579: {"jsonrpc":"2.0","method":"channelMessage","params":{"channel":"lightning_board_XLM_JPY","message":{"mid_price":65.989,"bids":[{"price":65.911,"size":0.0}],"asks":[{"price":66.036,"size":0.0},{"price":66.049,"size":534.0}]}}}
1618677599.317715: {"jsonrpc":"2.0","method":"channelMessage","params":{"channel":"lightning_ticker_ETH_JPY","message":{"product_code":"ETH_JPY","state":"RUNNING","timestamp":"2021-04-17T16:39:59.1547852Z","tick_id":10943342,"best_bid":258757.0,"best_ask":258886.0,"best_bid_size":0.700000,"best_ask_size":3.550000,"total_bid_depth":2388.531373100000,"total_ask_depth":2102.9285831,"market_bid_size":0.0,"market_ask_size":0.0,"ltp":258811.0,"volume":18068.168445400000,"volume_by_product":18068.168445400000}}}
1618677599.317787: {"jsonrpc":"2.0","method":"channelMessage","params":{"channel":"lightning_board_ETH_JPY","message":{"mid_price":258821.0,"bids":[{"price":258676.0,"size":1.0}],"asks":[]}}}
1618677599.42153: {"jsonrpc":"2.0","method":"channelMessage","params":{"channel":"lightning_ticker_XLM_JPY","message":{"product_code":"XLM_JPY","state":"RUNNING","timestamp":"2021-04-17T16:39:59.2954199Z","tick_id":4215949,"best_bid":65.931,"best_ask":66.049,"best_bid_size":757.67,"best_ask_size":534.0,"total_bid_depth":583460.3061419,"total_ask_depth":1016905.44764110,"market_bid_size":0.0,"market_ask_size":0.0,"ltp":65.902,"volume":2182293.365166500000,"volume_by_product":2182293.365166500000}}}
1618677599.4246988: {"jsonrpc":"2.0","method":"channelMessage","params":{"channel":"lightning_board_XLM_JPY","message":{"mid_price":65.99,"bids":[{"price":65.931,"size":757.67}],"asks":[]}}}
1618677599.540962: {"jsonrpc":"2.0","method":"channelMessage","params":{"channel":"lightning_board_ETH_JPY","message":{"mid_price":258811.0,"bids":[],"asks":[{"price":258865.0,"size":1.0},{"price":258895.0,"size":1.0},{"price":258894.0,"size":0.0}]}}}
1618677599.5410519: {"jsonrpc":"2.0","method":"channelMessage","params":{"channel":"lightning_ticker_XRP_JPY","message":{"product_code":"XRP_JPY","state":"RUNNING","timestamp":"2021-04-17T16:39:59.4204093Z","tick_id":8062988,"best_bid":172.94,"best_ask":173.04,"best_bid_size":1503.37,"best_ask_size":1.0,"total_bid_depth":1507882.05693700,"total_ask_depth":2546939.13723400,"market_bid_size":0.0,"market_ask_size":0.0,"ltp":173.14,"volume":8347324.511315000000,"volume_by_product":8347324.511315000000}}}
1618677599.5411: {"jsonrpc":"2.0","method":"channelMessage","params":{"channel":"lightning_board_XRP_JPY","message":{"mid_price":172.99,"bids":[{"price":172.39,"size":3009.0},{"price":172.94,"size":1503.37},{"price":172.53,"size":0.0}],"asks":[]}}}
1618677599.5411441: {"jsonrpc":"2.0","method":"channelMessage","params":{"channel":"lightning_board_XLM_JPY","message":{"mid_price":65.99,"bids":[],"asks":[{"price":66.049,"size":0.0}]}}}
1618677599.541174: {"jsonrpc":"2.0","method":"channelMessage","params":{"channel":"lightning_board_BTC_USD","message":{"mid_price":60539.79,"bids":[{"price":60199.79,"size":0.0},{"price":60507.61,"size":0.0}],"asks":[{"price":60574.41,"size":0.0}]}}}
1618677599.632946: {"jsonrpc":"2.0","method":"channelMessage","params":{"channel":"lightning_board_snapshot_FX_BTC_JPY","message":{"mid_price":7187389.0,"bids":[{"price":7186230.0,"size":0.01},{"price":7185301.0,"size":0.04},{"price":7185234.0,"size":0.1078},{"price":7185233.0,"size":0.05},{"price":7184300.0,"size":0.01},{"price":7183170.0,"size":1.22780847},{"price":7182455.0,"size":0.0905287},{"price":7182265.0,"size":0.36},{"price":7181820.0,"size":0.024},{"price":7181589.0,"size":0.01012998},{"price":7181455.0,"size":0.082},{"price":7181192.0,"size":0.1},{"price":7180049.0,"size":0.04},{"price":7179923.0,"size":0.44894306},{"price":7179785.0,"size":0.0408},{"price":7179570.0,"size":0.024},{"price":7179508.0,"size":1.95004875},{"price":7179328.0,"size":0.33},{"price":7177097.0,"size":0.23},{"price":7177050.0,"size":0.1},{"price":7176667.0,"size":0.3},{"price":7176590.0,"size":0.204},{"price":7175887.0,"size":0.107},{"price":7175486.0,"size":0.01},{"price":7175109.0,"size":0.2},{"price":7174610.0,"size":0.08},{"price":7174582.0,"size":0.03},{"price":7171892.0,"size":0.01},{"price":7171565.0,"size":0.01},{"price":7170176.0,"size":0.19539},{"price":7168898.0,"size":0.02},{"price":7168127.0,"size":0.2},{"price":7167469.0,"size":0.11},{"price":7166022.0,"size":1.0},{"price":7165318.0,"size":0.01},{"price":7163036.0,"size":0.05},{"price":7161208.0,"size":0.05},{"price":7160109.0,"size":0.02},{"price":7159369.0,"size":1.0},{"price":7158681.0,"size":0.64129},{"price":7158600.0,"size":0.02},{"price":7158385.0,"size":0.01722096},{"price":7158340.0,"size":0.41},{"price":7155000.0,"size":0.098},{"price":7152716.0,"size":0.8},{"price":7151561.0,"size":0.01},{"price":7150000.0,"size":0.01},{"price":7146320.0,"size":0.01},{"price":7143000.0,"size":0.01},{"price":7140000.0,"size":2.05},{"price":7139000.0,"size":0.05},{"price":7138223.0,"size":0.09},{"price":7138142.0,"size":3.28919},{"price":7138000.0,"size":0.05},{"price":7137000.0,"size":0.05},{"price":7136050.0,"size":0.01},{"price":7136000.0,"size":0.05},{"price":7135323.0,"size":1.0},{"price":7135102.0,"size":0.01},{"price":7135000.0,"size":0.05},{"price":7133448.0,"size":0.2},{"price":7133000.0,"size":0.01},{"price":7132756.0,"size":1.4},{"price":7132146.0,"size":0.01},{"price":7130715.0,"size":0.05},{"price":7129350.0,"size":0.01},{"price":7128896.0,"size":0.05},{"price":7127076.0,"size":0.05},{"price":7126103.0,"size":1.6},{"price":7121000.0,"size":0.31},{"price":7120224.0,"size":0.01},{"price":7120000.0,"size":0.01},{"price":7114991.0,"size":1.1},{"price":7112527.0,"size":0.01},{"price":7112000.0,"size":0.07},{"price":7111555.0,"size":0.05},{"price":7111111.0,"size":0.14},{"price":7111000.0,"size":0.31},{"price":7110842.0,"size":0.01},{"price":7110512.0,"size":0.01},{"price":7110322.0,"size":0.01},{"price":7110000.0,"size":0.17},{"price":7109400.0,"size":0.02},{"price":7109039.0,"size":0.2},{"price":7108852.0,"size":0.02},{"price":7108487.0,"size":0.02},{"price":7106999.0,"size":0.01},{"price":7105000.0,"size":0.1},{"price":7104580.0,"size":0.04},{"price":7104444.0,"size":0.1},{"price":7104260.0,"size":0.1},{"price":7103500.0,"size":0.06},{"price":7103333.0,"size":0.011},{"price":7103330.0,"size":0.01},{"price":7102004.0,"size":0.04},{"price":7101604.0,"size":0.03},{"price":7101000.0,"size":0.3},{"price":7100666.0,"size":0.01},{"price":7100055.0,"size":0.03},{"price":7100000.0,"size":4.0648},{"price":7099832.0,"size":0.34},{"price":7099824.0,"size":0.01},{"price":7098100.0,"size":0.01},{"price":7096710.0,"size":0.035},{"price":7095007.0,"size":0.025},{"price":7094766.0,"size":0.014},{"price":7094024.0,"size":0.832},{"price":7092211.0,"size":0.05},{"price":7091000.0,"size":0.3},{"price":7090750.0,"size":0.04},{"price":7090000.0,"size":0.93},{"price":7088000.0,"size":0.08},{"price":7087523.0,"size":0.05},{"price":7085354.0,"size":0.01},{"price":7085000.0,"size":0.07},{"price":7084095.0,"size":1.9214},{"price":7081000.0,"size":0.31},{"price":7080844.0,"size":0.01},{"price":7080020.0,"size":0.05},{"price":7080000.0,"size":0.61},{"price":7079867.0,"size":0.1},{"price":7079800.0,"size":0.011},{"price":7077777.0,"size":0.035},{"price":7076657.0,"size":0.1},{"price":7075550.0,"size":0.01},{"price":7075010.0,"size":0.2},{"price":7073521.0,"size":0.01},{"price":7073337.0,"size":0.04},{"price":7072000.0,"size":0.1},{"price":7071800.0,"size":0.01},{"price":7071612.0,"size":0.3},{"price":7071000.0,"size":0.3},{"price":7070967.0,"size":0.1},{"price":7070100.0,"size":0.01},{"price":7070050.0,"size":0.01},{"price":7070000.0,"size":0.06},{"price":7066666.0,"size":0.02},{"price":7066500.0,"size":0.15},{"price":7066000.0,"size":0.01},{"price":7065275.0,"size":1.98185},{"price":7063450.0,"size":0.01},{"price":7063150.0,"size":0.02},{"price":7063000.0,"size":0.2},{"price":7062350.0,"size":0.01},{"price":7062123.0,"size":0.01},{"price":7062117.0,"size":0.1},{"price":7062000.0,"size":0.25},{"price":7061007.0,"size":0.025},{"price":7061000.0,"size":0.33},{"price":7060355.0,"size":0.15},{"price":7060051.0,"size":0.01},{"price":7060010.0,"size":0.0102},{"price":7060000.0,"size":5.98},{"price":7059000.0,"size":0.01},{"price":7058565.0,"size":0.5},{"price":7058000.0,"size":0.1},{"price":7056666.0,"size":0.01},{"price":7056609.0,"size":2.2},{"price":7055930.0,"size":0.4},{"price":7055010.0,"size":0.03},{"price":7055000.0,"size":0.13},{"price":7054317.0,"size":0.1},{"price":7053945.0,"size":0.1375},{"price":7051752.0,"size":0.01},{"price":7051000.0,"size":0.3},{"price":7050861.0,"size":0.02},{"price":7050750.0,"size":0.01},{"price":7050027.0,"size":0.01},{"price":7050000.0,"size":2.262},{"price":7048163.0,"size":0.1},{"price":7047870.0,"size":0.13},{"price":7047523.0,"size":0.1},{"price":7045898.0,"size":0.5},{"price":7045350.0,"size":0.1},{"price":7045000.0,"size":0.02},{"price":7044456.0,"size":0.01058},{"price":7044444.0,"size":0.1},{"price":7043211.0,"size":0.075},{"price":7042350.0,"size":0.01},{"price":7041000.0,"size":0.3},{"price":7040000.0,"size":0.56},{"price":7039661.0,"size":0.03},{"price":7036666.0,"size":0.01},{"price":7034495.0,"size":0.2},{"price":7034263.0,"size":0.02},{"price":7033353.0,"size":0.01},{"price":7033000.0,"size":0.01},{"price":7032752.0,"size":1.0},{"price":7031000.0,"size":0.3},{"price":7030029.0,"size":0.1},{"price":7030000.0,"size":1.3},{"price":7028155.0,"size":0.055},{"price":7026918.0,"size":0.46},{"price":7026657.0,"size":0.1},{"price":7026007.0,"size":0.025},{"price":7026000.0,"size":0.01},{"price":7025900.0,"size":0.05},{"price":7025000.0,"size":0.1},{"price":7024444.0,"size":0.04},{"price":7024250.0,"size":0.01},{"price":7023652.0,"size":0.1},{"price":7022222.0,"size":0.01},{"price":7021053.0,"size":0.01},{"price":7021000.0,"size":0.4},{"price":7020800.0,"size":0.1},{"price":7020721.0,"size":0.01},{"price":7020000.0,"size":0.3},{"price":7019544.0,"size":0.01},{"price":7019523.0,"size":0.05},{"price":7018274.0,"size":0.04},{"price":7018193.0,"size":0.0132},{"price":7016931.0,"size":3.7},{"price":7016695.0,"size":0.02},{"price":7015671.0,"size":0.1},{"price":7015000.0,"size":0.13},{"price":7013211.0,"size":0.02},{"price":7013000.0,"size":0.1},{"price":7012527.0,"size":0.01},{"price":7012356.0,"size":0.02},{"price":7012222.0,"size":0.01},{"price":7012000.0,"size":0.02},{"price":7011111.0,"size":0.01},{"price":7011000.0,"size":0.3},{"price":7010980.0,"size":0.02},{"price":7010000.0,"size":0.48069},{"price":7009000.0,"size":0.01},{"price":7007777.0,"size":0.04},{"price":7007007.0,"size":0.05},{"price":7006019.0,"size":0.38},{"price":7005780.0,"size":0.0688},{"price":7005000.0,"size":0.156},{"price":7003100.0,"size":0.01},{"price":7002000.0,"size":0.01},{"price":7001098.0,"size":0.1},{"price":7001000.0,"size":0.53},{"price":7000666.0,"size":0.01},{"price":7000555.0,"size":0.01},{"price":7000001.0,"size":0.01},{"price":7000000.0,"size":6.032},{"price":6999999.0,"size":0.51},{"price":6999000.0,"size":0.01},{"price":6998590.0,"size":0.1},{"price":6998500.0,"size":0.1},{"price":6993950.0,"size":0.01},{"price":6992145.0,"size":0.5},{"price":6991000.0,"size":0.3},{"price":6990011.0,"size":0.01},{"price":6990000.0,"size":0.5},{"price":6989800.0,"size":0.01},{"price":6989000.0,"size":0.01},{"price":6988888.0,"size":0.01},{"price":6988585.0,"size":0.01},{"price":6988000.0,"size":0.1},{"price":6987500.0,"size":0.01},{"price":6986668.0,"size":0.01},{"price":6984603.0,"size":1.2935},{"price":6980000.0,"size":1.2},{"price":6978588.0,"size":0.01},{"price":6978000.0,"size":0.2},{"price":6977777.0,"size":0.01},{"price":6977385.0,"size":3.1},{"price":6971350.0,"size":0.01},{"price":6970000.0,"size":0.12},{"price":6968900.0,"size":3.0},{"price":6968526.0,"size":0.49},{"price":6963594.0,"size":0.66924},{"price":6962306.0,"size":0.01},{"price":6962098.0,"size":3.41},{"price":6962000.0,"size":0.04},{"price":6960100.0,"size":0.01},{"price":6960000.0,"size":0.46},{"price":6956855.0,"size":0.01},{"price":6952650.0,"size":0.05},{"price":6951000.0,"size":0.05},{"price":6950499.0,"size":0.05},{"price":6950001.0,"size":0.01},{"price":6950000.0,"size":0.61},{"price":6949761.0,"size":0.72},{"price":6947470.0,"size":0.01},{"price":6944691.0,"size":0.06},{"price":6944620.0,"size":0.022},{"price":6944444.0,"size":0.1},{"price":6941900.0,"size":0.01},{"price":6940000.0,"size":0.03},{"price":6939000.0,"size":0.01},{"price":6938856.0,"size":0.01},{"price":6936666.0,"size":0.01},{"price":6935000.0,"size":0.22},{"price":6934231.0,"size":0.01},{"price":6934121.0,"size":0.01},{"price":6933333.0,"size":0.01},{"price":6932000.0,"size":0.2},{"price":6930000.0,"size":1.05},{"price":6929950.0,"size":0.05},{"price":6927777.0,"size":0.015},{"price":6926666.0,"size":0.01},{"price":6925000.0,"size":0.3},{"price":6922222.0,"size":1.01},{"price":6920000.0,"size":0.15},{"price":6919250.0,"size":3.0}],"asks":[{"price":7188548.0,"size":0.01},{"price":7188549.0,"size":0.072},{"price":7188550.0,"size":1.26722305},{"price":7188993.0,"size":0.05},{"price":7189259.0,"size":0.04999181},{"price":7190274.0,"size":0.01},{"price":7190390.0,"size":0.04},{"price":7190499.0,"size":0.04},{"price":7190518.0,"size":0.05},{"price":7190575.0,"size":0.04},{"price":7190639.0,"size":0.1},{"price":7190678.0,"size":0.04},{"price":7190688.0,"size":0.05},{"price":7190954.0,"size":0.04},{"price":7190965.0,"size":0.04},{"price":7191008.0,"size":0.04},{"price":7191106.0,"size":0.04},{"price":7191249.0,"size":0.04},{"price":7191252.0,"size":0.04},{"price":7191382.0,"size":0.04},{"price":7191446.0,"size":0.04},{"price":7191449.0,"size":0.04},{"price":7191460.0,"size":0.04},{"price":7191479.0,"size":0.04},{"price":7191481.0,"size":0.05},{"price":7191491.0,"size":0.04},{"price":7191547.0,"size":0.03},{"price":7191554.0,"size":0.04},{"price":7191555.0,"size":0.04},{"price":7191634.0,"size":0.04},{"price":7191638.0,"size":0.04},{"price":7191740.0,"size":0.04},{"price":7191950.0,"size":0.01},{"price":7192087.0,"size":0.0128},{"price":7192130.0,"size":0.02},{"price":7192275.0,"size":2.01264837},{"price":7193380.0,"size":0.0164},{"price":7193388.0,"size":0.02},{"price":7193568.0,"size":0.04},{"price":7193598.0,"size":0.04},{"price":7193686.0,"size":0.04},{"price":7193886.0,"size":0.04},{"price":7193888.0,"size":0.04},{"price":7194050.0,"size":0.01},{"price":7194055.0,"size":0.04},{"price":7194058.0,"size":0.04},{"price":7194145.0,"size":0.04},{"price":7194149.0,"size":0.04},{"price":7194216.0,"size":0.04},{"price":7194270.0,"size":0.04},{"price":7194331.0,"size":0.04},{"price":7194335.0,"size":0.04},{"price":7194357.0,"size":0.04},{"price":7194404.0,"size":0.04},{"price":7194421.0,"size":0.03},{"price":7194436.0,"size":0.04},{"price":7194556.0,"size":0.04},{"price":7194568.0,"size":0.04},{"price":7194631.0,"size":0.04},{"price":7194710.0,"size":0.04},{"price":7194770.0,"size":0.04},{"price":7194895.0,"size":0.04},{"price":7195003.0,"size":0.01},{"price":7195114.0,"size":0.04},{"price":7195380.0,"size":0.01},{"price":7195498.0,"size":0.01},{"price":7195625.0,"size":0.46},{"price":7195626.0,"size":0.46},{"price":7195628.0,"size":0.46},{"price":7195630.0,"size":0.04},{"price":7195665.0,"size":0.04},{"price":7195730.0,"size":0.04},{"price":7196130.0,"size":0.04},{"price":7196226.0,"size":0.04},{"price":7196339.0,"size":0.19539},{"price":7196340.0,"size":0.04},{"price":7196348.0,"size":0.04},{"price":7196504.0,"size":0.05},{"price":7196555.0,"size":0.01},{"price":7196744.0,"size":0.27},{"price":7197645.0,"size":0.0128},{"price":7197663.0,"size":0.01},{"price":7197688.0,"size":0.02},{"price":7198313.0,"size":0.01},{"price":7199859.0,"size":0.05},{"price":7200000.0,"size":0.12},{"price":7200049.0,"size":0.04},{"price":7200224.0,"size":0.0164},{"price":7200513.0,"size":0.01},{"price":7201000.0,"size":0.1},{"price":7201065.0,"size":0.44894306},{"price":7203389.0,"size":0.6},{"price":7203498.0,"size":0.64129},{"price":7204000.0,"size":0.01},{"price":7205889.0,"size":0.11},{"price":7206558.0,"size":0.01},{"price":7208400.0,"size":0.1},{"price":7208943.0,"size":1.0},{"price":7209387.0,"size":0.01},{"price":7209737.0,"size":0.05},{"price":7210049.0,"size":0.04},{"price":7211000.0,"size":0.1},{"price":7211159.0,"size":0.2},{"price":7211578.0,"size":0.05},{"price":7212050.0,"size":0.01},{"price":7213420.0,"size":0.05},{"price":7215263.0,"size":0.05},{"price":7216655.0,"size":0.11},{"price":7217100.0,"size":0.01},{"price":7217107.0,"size":0.05},{"price":7219035.0,"size":0.1},{"price":7220000.0,"size":0.06},{"price":7220049.0,"size":0.04},{"price":7221000.0,"size":0.1},{"price":7222000.0,"size":0.01},{"price":7223000.0,"size":0.01},{"price":7223387.0,"size":0.02},{"price":7224000.0,"size":0.01},{"price":7224163.0,"size":0.01058},{"price":7224881.0,"size":0.01},{"price":7225000.0,"size":0.02},{"price":7225901.0,"size":0.7},{"price":7226655.0,"size":0.09},{"price":7231000.0,"size":0.1},{"price":7232554.0,"size":0.92},{"price":7236290.0,"size":1.21},{"price":7238120.0,"size":2.0},{"price":7238148.0,"size":3.30791},{"price":7239207.0,"size":0.9},{"price":7239768.0,"size":0.1},{"price":7240000.0,"size":0.01},{"price":7240687.0,"size":0.01},{"price":7241000.0,"size":0.1},{"price":7241774.0,"size":3.0},{"price":7244387.0,"size":0.02},{"price":7246585.0,"size":1.0},{"price":7250000.0,"size":0.04},{"price":7251000.0,"size":0.1},{"price":7252513.0,"size":1.7},{"price":7253000.0,"size":0.01},{"price":7255518.0,"size":0.05},{"price":7256657.0,"size":0.1},{"price":7258280.0,"size":1.97951},{"price":7259000.0,"size":0.02},{"price":7261000.0,"size":0.1},{"price":7261207.0,"size":0.01},{"price":7268890.0,"size":0.12},{"price":7271000.0,"size":0.1},{"price":7272387.0,"size":0.02},{"price":7272918.0,"size":1.93745},{"price":7275953.0,"size":0.033},{"price":7281000.0,"size":0.1},{"price":7281452.0,"size":3.0},{"price":7287777.0,"size":0.1},{"price":7290000.0,"size":0.01},{"price":7291000.0,"size":0.1},{"price":7294209.0,"size":0.289},{"price":7294214.0,"size":3.1},{"price":7294600.0,"size":0.04},{"price":7295000.0,"size":0.05},{"price":7295845.0,"size":1.26659},{"price":7296000.0,"size":0.05},{"price":7296805.0,"size":0.01},{"price":7297000.0,"size":0.05},{"price":7297434.0,"size":0.02},{"price":7298000.0,"size":0.25},{"price":7299000.0,"size":0.05},{"price":7299999.0,"size":0.02},{"price":7300000.0,"size":0.91},{"price":7300557.0,"size":0.012},{"price":7301000.0,"size":0.15},{"price":7301509.0,"size":0.1401},{"price":7302000.0,"size":0.05},{"price":7302509.0,"size":0.1049},{"price":7303000.0,"size":0.05},{"price":7303909.0,"size":0.14596822},{"price":7304000.0,"size":0.05},{"price":7304444.0,"size":0.1},{"price":7305000.0,"size":0.1},{"price":7305750.0,"size":0.01},{"price":7307387.0,"size":0.04},{"price":7311000.0,"size":0.1},{"price":7316419.0,"size":0.01},{"price":7319736.0,"size":0.0102},{"price":7320000.0,"size":0.01},{"price":7321000.0,"size":0.1},{"price":7327777.0,"size":0.3},{"price":7331000.0,"size":0.1},{"price":7331986.0,"size":0.01058},{"price":7336180.0,"size":0.07},{"price":7337278.0,"size":0.07},{"price":7337600.0,"size":0.01},{"price":7340000.0,"size":0.01},{"price":7340155.0,"size":0.055},{"price":7341000.0,"size":0.1},{"price":7342387.0,"size":0.04},{"price":7344444.0,"size":0.1},{"price":7344866.0,"size":0.01},{"price":7345000.0,"size":0.2},{"price":7349000.0,"size":0.5},{"price":7350000.0,"size":0.54},{"price":7350667.0,"size":0.01},{"price":7351000.0,"size":0.1},{"price":7351662.0,"size":0.26},{"price":7353421.0,"size":0.01},{"price":7357169.0,"size":0.66755},{"price":7357600.0,"size":0.01},{"price":7360413.0,"size":4.5},{"price":7361000.0,"size":0.1},{"price":7363553.0,"size":0.062},{"price":7368000.0,"size":0.12},{"price":7370000.0,"size":0.01},{"price":7371000.0,"size":0.1},{"price":7373701.0,"size":0.5},{"price":7374273.0,"size":0.05},{"price":7375000.0,"size":0.3},{"price":7377600.0,"size":0.02},{"price":7378000.0,"size":0.04},{"price":7380000.0,"size":0.01},{"price":7381000.0,"size":0.1},{"price":7383866.0,"size":6.0},{"price":7384000.0,"size":0.01},{"price":7384387.0,"size":0.04},{"price":7385032.0,"size":0.01},{"price":7387220.0,"size":0.02},{"price":7388223.0,"size":0.017},{"price":7391000.0,"size":0.1},{"price":7394209.0,"size":0.578},{"price":7395000.0,"size":0.01},{"price":7397400.0,"size":0.01},{"price":7397600.0,"size":0.04},{"price":7397664.0,"size":0.04},{"price":7397789.0,"size":0.2},{"price":7398000.0,"size":0.2},{"price":7398890.0,"size":0.24},{"price":7399999.0,"size":0.05},{"price":7400000.0,"size":1.38},{"price":7400007.0,"size":0.24},{"price":7401000.0,"size":0.1},{"price":7402000.0,"size":0.05},{"price":7405500.0,"size":0.01},{"price":7407750.0,"size":0.01},{"price":7408319.0,"size":0.03},{"price":7410000.0,"size":0.04},{"price":7410444.0,"size":0.1},{"price":7411000.0,"size":0.1},{"price":7412000.0,"size":0.01},{"price":7412152.0,"size":2.0},{"price":7413105.0,"size":0.01},{"price":7415000.0,"size":0.13},{"price":7416113.0,"size":0.01},{"price":7416823.0,"size":0.01},{"price":7417600.0,"size":0.08},{"price":7420000.0,"size":0.33},{"price":7421000.0,"size":0.1},{"price":7422152.0,"size":2.0},{"price":7422512.0,"size":0.05},{"price":7423000.0,"size":0.05},{"price":7423580.0,"size":0.01},{"price":7424743.0,"size":0.03},{"price":7425000.0,"size":0.2},{"price":7426500.0,"size":0.01},{"price":7426600.0,"size":0.01},{"price":7428530.0,"size":0.1},{"price":7428930.0,"size":0.01},{"price":7429000.0,"size":0.01},{"price":7429438.0,"size":0.01},{"price":7430000.0,"size":0.22},{"price":7431000.0,"size":0.1},{"price":7431352.0,"size":0.01},{"price":7431639.0,"size":0.02},{"price":7432555.0,"size":0.25},{"price":7433387.0,"size":0.06},{"price":7433450.0,"size":0.1},{"price":7433693.0,"size":0.013},{"price":7434050.0,"size":0.01},{"price":7435447.0,"size":0.02},{"price":7436450.0,"size":0.01},{"price":7437600.0,"size":0.09},{"price":7437658.0,"size":0.2},{"price":7438250.0,"size":0.3},{"price":7438530.0,"size":0.1},{"price":7439010.0,"size":0.02},{"price":7439380.0,"size":0.08},{"price":7440000.0,"size":0.11},{"price":7441000.0,"size":0.3},{"price":7441062.0,"size":0.033},{"price":7441347.0,"size":0.05},{"price":7443450.0,"size":0.1},{"price":7444438.0,"size":0.01},{"price":7444444.0,"size":0.11},{"price":7445500.0,"size":0.01},{"price":7447000.0,"size":0.01},{"price":7447121.0,"size":0.05},{"price":7448530.0,"size":0.1},{"price":7449000.0,"size":0.01},{"price":7449475.0,"size":0.315},{"price":7450000.0,"size":1.565},{"price":7450528.0,"size":0.02},{"price":7452723.0,"size":0.01}]}}}
1618677599.6347232: {"jsonrpc":"2.0","method":"channelMessage","params":{"channel":"lightning_board_snapshot_BTCJPY25JUN2021","message":{"mid_price":6606605.0,"bids":[{"price":3816100.0,"size":0.01},{"price":4500540.0,"size":0.001},{"price":5500540.0,"size":0.001},{"price":6000540.0,"size":0.003},{"price":6319806.0,"size":5.0},{"price":6413161.0,"size":0.001},{"price":6426022.0,"size":4.67},{"price":6432351.0,"size":2.7},{"price":6480800.0,"size":2.8},{"price":6501376.0,"size":2.98},{"price":6515780.0,"size":2.4},{"price":6518928.0,"size":0.001},{"price":6539368.0,"size":0.001},{"price":6553629.0,"size":0.1},{"price":6565413.0,"size":1.0},{"price":6568789.0,"size":1.4},{"price":6571302.0,"size":1.0},{"price":6575709.0,"size":0.001},{"price":6577409.0,"size":0.71},{"price":6581065.0,"size":1.0},{"price":6582757.0,"size":0.2},{"price":6583508.0,"size":0.01},{"price":6588900.0,"size":0.199},{"price":6596070.0,"size":0.14}],"asks":[{"price":6617140.0,"size":0.01},{"price":6619579.0,"size":0.01},{"price":6620808.0,"size":0.01},{"price":6623251.0,"size":0.01},{"price":6627161.0,"size":0.01},{"price":6627300.0,"size":0.2},{"price":6629607.0,"size":0.01},{"price":6632369.0,"size":0.01},{"price":6642110.0,"size":0.01},{"price":6662054.0,"size":2.3},{"price":6663305.0,"size":1.3},{"price":6696708.0,"size":3.1},{"price":6725109.0,"size":2.6},{"price":6736890.0,"size":2.94},{"price":6743161.0,"size":0.006},{"price":6792845.0,"size":3.2},{"price":6800312.0,"size":0.001},{"price":6805440.0,"size":6.0},{"price":6838735.0,"size":0.006},{"price":6848068.0,"size":0.001},{"price":6922524.0,"size":0.001},{"price":6967647.0,"size":0.001},{"price":7041390.0,"size":0.001},{"price":7800000.0,"size":0.2}]}}}
1618677599.642563: {"jsonrpc":"2.0","method":"channelMessage","params":{"channel":"lightning_board_snapshot_BTCJPY23APR2021","message":{"mid_price":6602392.0,"bids":[{"price":3545683.0,"size":94.2},{"price":4156219.0,"size":57.0},{"price":4415233.0,"size":45.25},{"price":4630227.0,"size":35.0},{"price":4871602.0,"size":56.2},{"price":5141588.0,"size":43.0},{"price":5411876.0,"size":36.49},{"price":5516225.0,"size":21.53},{"price":5668246.0,"size":12.5},{"price":5731032.0,"size":6.3},{"price":5928406.0,"size":7.84},{"price":5931519.0,"size":5.0},{"price":6037480.0,"size":6.0},{"price":6059078.0,"size":3.0},{"price":6101953.0,"size":7.0},{"price":6186638.0,"size":1.0},{"price":6217047.0,"size":5.0},{"price":6250417.0,"size":0.5},{"price":6293194.0,"size":4.12},{"price":6313642.0,"size":2.8},{"price":6314197.0,"size":0.25},{"price":6413544.0,"size":2.89},{"price":6425630.0,"size":1.9},{"price":6476298.0,"size":1.61},{"price":6495002.0,"size":1.0},{"price":6514260.0,"size":1.2},{"price":6556619.0,"size":0.6},{"price":6562214.0,"size":0.5},{"price":6569650.0,"size":0.3},{"price":6578084.0,"size":0.2},{"price":6579312.0,"size":0.3},{"price":6580122.0,"size":0.11},{"price":6580526.0,"size":0.1},{"price":6588458.0,"size":0.01},{"price":6588900.0,"size":0.2},{"price":6590603.0,"size":0.04}],"asks":[{"price":6614181.0,"size":0.01},{"price":6617368.0,"size":0.01},{"price":6617853.0,"size":0.01},{"price":6622730.0,"size":0.01},{"price":6624727.0,"size":0.01},{"price":6624758.0,"size":0.01},{"price":6627300.0,"size":0.2},{"price":6639607.0,"size":0.01},{"price":6654380.0,"size":0.8},{"price":6656651.0,"size":1.0},{"price":6690142.0,"size":1.0},{"price":6720438.0,"size":2.0},{"price":6729851.0,"size":1.9},{"price":6767443.0,"size":3.0},{"price":6854822.0,"size":3.0},{"price":6903543.0,"size":3.9},{"price":6920092.0,"size":5.74},{"price":6952175.0,"size":0.001},{"price":7096265.0,"size":4.7},{"price":7209468.0,"size":7.5},{"price":7365395.0,"size":6.7},{"price":7475269.0,"size":7.1},{"price":7635596.0,"size":14.1},{"price":7697489.0,"size":30.0},{"price":7855092.0,"size":32.9},{"price":8079366.0,"size":36.39},{"price":8285391.0,"size":62.2},{"price":8581554.0,"size":28.6},{"price":8865937.0,"size":39.4},{"price":9117736.0,"size":41.2},{"price":9652479.0,"size":118.0}]}}}
1618677599.646071: {"jsonrpc":"2.0","method":"channelMessage","params":{"channel":"lightning_board_XLM_JPY","message":{"mid_price":65.983,"bids":[],"asks":[{"price":66.035,"size":534.0}]}}}
1618677599.646153: {"jsonrpc":"2.0","method":"channelMessage","params":{"channel":"lightning_board_ETH_JPY","message":{"mid_price":258811.0,"bids":[],"asks":[{"price":258964.0,"size":0.0},{"price":258885.0,"size":1.0}]}}}
1618677599.700768: {"jsonrpc":"2.0","method":"channelMessage","params":{"channel":"lightning_executions_ETH_JPY","message":[{"id":2207056266,"side":"BUY","price":258865.0,"size":0.01,"exec_date":"2021-04-17T16:39:59.5934514Z","buy_child_order_acceptance_id":"JRF20210417-163959-430475","sell_child_order_acceptance_id":"JRF20210417-163959-025588"}]}}
1618677599.755072: {"jsonrpc":"2.0","method":"channelMessage","params":{"channel":"lightning_ticker_BTC_USD","message":{"product_code":"BTC_USD","state":"RUNNING","timestamp":"2021-04-17T16:39:59.5466005Z","tick_id":5565362,"best_bid":60515.68,"best_ask":60566.9,"best_bid_size":0.02,"best_ask_size":0.091,"total_bid_depth":9.04681782,"total_ask_depth":6.28669080,"market_bid_size":0.0,"market_ask_size":0.0,"ltp":60201.0,"volume":55.569921930000,"volume_by_product":55.569921930000}}}
1618677599.765764: {"jsonrpc":"2.0","method":"channelMessage","params":{"channel":"lightning_board_BTC_USD","message":{"mid_price":60541.29,"bids":[{"price":60517.6,"size":0.0}],"asks":[{"price":60561.98,"size":0.0},{"price":60590.27,"size":0.0},{"price":60746.98,"size":0.0}]}}}
1618677599.765908: {"jsonrpc":"2.0","method":"channelMessage","params":{"channel":"lightning_board_ETH_JPY","message":{"mid_price":258811.0,"bids":[{"price":258197.0,"size":1.2696319},{"price":257775.0,"size":0.0}],"asks":[{"price":260015.0,"size":0.0},{"price":259846.0,"size":0.01},{"price":258865.0,"size":0.99}]}}}
1618677599.869157: {"jsonrpc":"2.0","method":"channelMessage","params":{"channel":"lightning_ticker_ETH_JPY","message":{"product_code":"ETH_JPY","state":"RUNNING","timestamp":"2021-04-17T16:39:59.7057644Z","tick_id":10943353,"best_bid":258757.0,"best_ask":258885.0,"best_bid_size":0.700000,"best_ask_size":1.0,"total_bid_depth":2389.781005000000,"total_ask_depth":2098.0565831,"market_bid_size":0.0,"market_ask_size":0.0,"ltp":258865.0,"volume":18068.178445400000,"volume_by_product":18068.178445400000}}}
1618677599.8692238: {"jsonrpc":"2.0","method":"channelMessage","params":{"channel":"lightning_board_ETH_JPY","message":{"mid_price":258821.0,"bids":[],"asks":[{"price":258865.0,"size":0.0}]}}}
1618677599.869267: {"jsonrpc":"2.0","method":"channelMessage","params":{"channel":"lightning_board_BTC_USD","message":{"mid_price":60541.29,"bids":[],"asks":[{"price":63999.97,"size":0.0}]}}}
1618677599.9727669: {"jsonrpc":"2.0","method":"channelMessage","params":{"channel":"lightning_board_BTC_USD","message":{"mid_price":60541.29,"bids":[],"asks":[{"price":63999.98,"size":0.0}]}}}
1618677599.9796212: {"jsonrpc":"2.0","method":"channelMessage","params":{"channel":"lightning_board_XRP_JPY","message":{"mid_price":172.92,"bids":[{"price":172.52,"size":0.0},{"price":172.94,"size":0.0}],"asks":[{"price":173.23,"size":0.0},{"price":173.38,"size":0.0}]}}}
1618677600.0123541: {"jsonrpc":"2.0","method":"channelMessage","params":{"channel":"lightning_ticker_FX_BTC_JPY","message":{"product_code":"FX_BTC_JPY","state":"RUNNING","timestamp":"2021-04-17T16:39:59.9017918Z","tick_id":42420516,"best_bid":7186230.0,"best_ask":7188548.0,"best_bid_size":0.01,"best_ask_size":0.01,"total_bid_depth":2428.677195260000,"total_ask_depth":2470.974814510000,"market_bid_size":0.0,"market_ask_size":0.0,"ltp":7186655.0,"volume":2105.774486030000,"volume_by_product":2105.774486030000}}}
1618677600.018687: {"jsonrpc":"2.0","method":"channelMessage","params":{"channel":"lightning_board_FX_BTC_JPY","message":{"mid_price":7187389.0,"bids":[{"price":7185234.0,"size":0.0},{"price":7182455.0,"size":0.0}],"asks":[{"price":7191547.0,"size":0.0}]}}}
1618677600.089323: {"jsonrpc":"2.0","method":"channelMessage","params":{"channel":"lightning_board_ETH_JPY","message":{"mid_price":258821.0,"bids":[{"price":257220.0,"size":0.0}],"asks":[]}}}
1618677600.089443: {"jsonrpc":"2.0","method":"channelMessage","params":{"channel":"lightning_board_BTC_USD","message":{"mid_price":60541.29,"bids":[],"asks":[{"price":60576.14,"size":0.11}]}}}
1618677600.128437: {"jsonrpc":"2.0","method":"channelMessage","params":{"channel":"lightning_board_FX_BTC_JPY","message":{"mid_price":7186441.0,"bids":[{"price":7183171.0,"size":0.1078},{"price":7179923.0,"size":0.0}],"asks":[{"price":7190639.0,"size":0.0},{"price":7186653.0,"size":0.01}]}}}
1618677600.201003: {"jsonrpc":"2.0","method":"channelMessage","params":{"channel":"lightning_board_BTC_USD","message":{"mid_price":60541.29,"bids":[{"price":60503.5,"size":0.02}],"asks":[{"price":60730.5,"size":0.25}]}}}
1618677600.201122: {"jsonrpc":"2.0","method":"channelMessage","params":{"channel":"lightning_ticker_XRP_JPY","message":{"product_code":"XRP_JPY","state":"RUNNING","timestamp":"2021-04-17T16:40:00.0171387Z","tick_id":8062993,"best_bid":172.8,"best_ask":173.04,"best_bid_size":614.19000000,"best_ask_size":1.0,"total_bid_depth":1506328.78693700,"total_ask_depth":2541689.85723400,"market_bid_size":0.0,"market_ask_size":0.0,"ltp":173.14,"volume":8347324.511315000000,"volume_by_product":8347324.511315000000}}}
1618677600.201195: {"jsonrpc":"2.0","method":"channelMessage","params":{"channel":"lightning_board_XRP_JPY","message":{"mid_price":172.92,"bids":[],"asks":[{"price":173.26,"size":0.0}]}}}
1618677600.2012532: {"jsonrpc":"2.0","method":"channelMessage","params":{"channel":"lightning_board_ETH_JPY","message":{"mid_price":258821.0,"bids":[{"price":258178.0,"size":0.0}],"asks":[]}}}
1618677600.28427: {"jsonrpc":"2.0","method":"channelMessage","params":{"channel":"lightning_board_FX_BTC_JPY","message":{"mid_price":7186441.0,"bids":[{"price":7181687.0,"size":0.0905287},{"price":7174199.0,"size":0.44894306},{"price":7183170.0,"size":0.0},{"price":7179508.0,"size":0.0},{"price":7185301.0,"size":0.0}],"asks":[{"price":7190224.0,"size":0.03},{"price":7189009.0,"size":0.1},{"price":7188549.0,"size":0.0},{"price":7188550.0,"size":0.0},{"price":7192275.0,"size":0.0}]}}}
1618677600.310595: {"jsonrpc":"2.0","method":"channelMessage","params":{"channel":"lightning_board_ETH_JPY","message":{"mid_price":258821.0,"bids":[{"price":258198.0,"size":1.984},{"price":258702.0,"size":0.0}],"asks":[{"price":258885.0,"size":2.0}]}}}
1618677600.3107321: {"jsonrpc":"2.0","method":"channelMessage","params":{"channel":"lightning_ticker_XLM_JPY","message":{"product_code":"XLM_JPY","state":"RUNNING","timestamp":"2021-04-17T16:40:00.1265189Z","tick_id":4215952,"best_bid":65.931,"best_ask":66.035,"best_bid_size":757.67,"best_ask_size":534.0,"total_bid_depth":580460.3061419,"total_ask_depth":1016905.44764110,"market_bid_size":0.0,"market_ask_size":0.0,"ltp":65.902,"volume":2182293.365166500000,"volume_by_product":2182293.365166500000}}}
1618677600.310806: {"jsonrpc":"2.0","method":"channelMessage","params":{"channel":"lightning_board_XLM_JPY","message":{"mid_price":65.983,"bids":[{"price":63.0,"size":7307.9606667}],"asks":[]}}}
1618677600.310858: {"jsonrpc":"2.0","method":"channelMessage","params":{"channel":"lightning_board_XRP_JPY","message":{"mid_price":172.92,"bids":[{"price":172.39,"size":0.0}],"asks":[]}}}
1618677600.369591: {"jsonrpc":"2.0","method":"channelMessage","params":{"channel":"lightning_executions_FX_BTC_JPY","message":[{"id":2207054800,"side":"SELL","price":7186230.0,"size":0.01,"exec_date":"2021-04-17T16:40:00.1517841Z","buy_child_order_acceptance_id":"JRF20210417-163934-209100","sell_child_order_acceptance_id":"JRF20210417-164000-008863"}]}}
1618677600.407679: {"jsonrpc":"2.0","method":"channelMessage","params":{"channel":"lightning_board_FX_BTC_JPY","message":{"mid_price":7185943.0,"bids":[{"price":7186230.0,"size":0.0}],"asks":[]}}}
1618677600.411063: {"jsonrpc":"2.0","method":"channelMessage","params":{"channel":"lightning_ticker_ETH_JPY","message":{"product_code":"ETH_JPY","state":"RUNNING","timestamp":"2021-04-17T16:40:00.1421776Z","tick_id":10943359,"best_bid":258757.0,"best_ask":258885.0,"best_bid_size":0.700000,"best_ask_size":2.000000,"total_bid_depth":2386.555005000000,"total_ask_depth":2099.0565831,"market_bid_size":0.0,"market_ask_size":0.0,"ltp":258865.0,"volume":18068.178445400000,"volume_by_product":18068.178445400000}}}
1618677600.415492: {"jsonrpc":"2.0","method":"channelMessage","params":{"channel":"lightning_board_ETH_JPY","message":{"mid_price":258821.0,"bids":[{"price":258699.0,"size":0.0}],"asks":[]}}}
1618677600.423894: {"jsonrpc":"2.0","method":"channelMessage","params":{"channel":"lightning_board_XRP_JPY","message":{"mid_price":172.92,"bids":[{"price":172.35,"size":0.0}],"asks":[{"price":173.76,"size":0.0}]}}}
1618677600.424021: {"jsonrpc":"2.0","method":"channelMessage","params":{"channel":"lightning_ticker_MONA_JPY","message":{"product_code":"MONA_JPY","state":"RUNNING","timestamp":"2021-04-17T16:40:00.1577344Z","tick_id":629665,"best_bid":401.688,"best_ask":401.902,"best_bid_size":286.89,"best_ask_size":117.27,"total_bid_depth":82436.94550763,"total_ask_depth":129554.20901728,"market_bid_size":0.0,"market_ask_size":0.0,"ltp":401.688,"volume":1030433.339113290000,"volume_by_product":1030433.339113290000}}}
1618677600.424094: {"jsonrpc":"2.0","method":"channelMessage","params":{"channel":"lightning_board_MONA_JPY","message":{"mid_price":401.795,"bids":[{"price":401.02,"size":0.0}],"asks":[]}}}
1618677600.483553: {"jsonrpc":"2.0","method":"channelMessage","params":{"channel":"lightning_executions_ETH_JPY","message":[{"id":2207056267,"side":"SELL","price":258757.0,"size":0.7,"exec_date":"2021-04-17T16:40:00.3296568Z","buy_child_order_acceptance_id":"JRF20210417-163929-375238","sell_child_order_acceptance_id":"JRF20210417-164000-054083"}]}}
1618677600.526405: {"jsonrpc":"2.0","method":"channelMessage","params":{"channel":"lightning_ticker_FX_BTC_JPY","message":{"product_code":"FX_BTC_JPY","state":"RUNNING","timestamp":"2021-04-17T16:40:00.3997078Z","tick_id":42420543,"best_bid":7185233.0,"best_ask":7186653.0,"best_bid_size":0.05,"best_ask_size":0.01,"total_bid_depth":2425.677666740000,"total_ask_depth":2467.502943090000,"market_bid_size":0.0,"market_ask_size":0.0,"ltp":7186230.0,"volume":2105.784486030000,"volume_by_product":2105.784486030000}}}
1618677600.53133: {"jsonrpc":"2.0","method":"channelMessage","params":{"channel":"lightning_board_FX_BTC_JPY","message":{"mid_price":7185943.0,"bids":[{"price":7183171.0,"size":0.0},{"price":7184081.0,"size":0.04},{"price":7182266.0,"size":0.1078},{"price":7167837.0,"size":0.01},{"price":7176535.0,"size":0.01},{"price":7163036.0,"size":0.0},{"price":7172365.0,"size":0.02}],"asks":[{"price":7188548.0,"size":0.0},{"price":7209737.0,"size":0.0},{"price":7211578.0,"size":0.0},{"price":7213420.0,"size":0.0}]}}}
1618677600.557329: {"jsonrpc":"2.0","method":"channelMessage","params":{"channel":"lightning_board_XRP_JPY","message":{"mid_price":172.92,"bids":[],"asks":[{"price":173.29,"size":3505.7}]}}}
1618677600.5574431: {"jsonrpc":"2.0","method":"channelMessage","params":{"channel":"lightning_board_ETH_JPY","message":{"mid_price":258786.0,"bids":[{"price":258757.0,"size":0.0},{"price":258177.0,"size":0.0},{"price":258197.0,"size":0.0}],"asks":[]}}}
1618677600.557524: {"jsonrpc":"2.0","method":"channelMessage","params":{"channel":"lightning_ticker_BTC_USD","message":{"product_code":"BTC_USD","state":"RUNNING","timestamp":"2021-04-17T16:40:00.3765243Z","tick_id":5565370,"best_bid":60515.68,"best_ask":60566.9,"best_bid_size":0.02,"best_ask_size":0.091,"total_bid_depth":8.87681782,"total_ask_depth":6.04369080,"market_bid_size":0.0,"market_ask_size":0.0,"ltp":60201.0,"volume":55.569921930000,"volume_by_product":55.569921930000}}}
1618677600.5575922: {"jsonrpc":"2.0","method":"channelMessage","params":{"channel":"lightning_board_BTC_USD","message":{"mid_price":60541.29,"bids":[{"price":60438.65,"size":0.0}],"asks":[{"price":60638.44,"size":0.0},{"price":60674.76,"size":0.0}]}}}
1618677600.644921: {"jsonrpc":"2.0","method":"channelMessage","params":{"channel":"lightning_board_FX_BTC_JPY","message":{"mid_price":7185723.0,"bids":[{"price":7182266.0,"size":0.0},{"price":7181229.0,"size":1.45050074},{"price":7177844.0,"size":2.30373647}],"asks":[{"price":7196230.0,"size":0.07},{"price":7186213.0,"size":1.63916396},{"price":7191481.0,"size":0.0},{"price":7189259.0,"size":0.0},{"price":7188993.0,"size":0.0},{"price":7189731.0,"size":2.60337805}]}}}
1618677600.669386: {"jsonrpc":"2.0","method":"channelMessage","params":{"channel":"lightning_board_ETH_JPY","message":{"mid_price":258786.0,"bids":[{"price":258198.0,"size":1.472}],"asks":[]}}}
1618677600.6694982: {"jsonrpc":"2.0","method":"channelMessage","params":{"channel":"lightning_board_XRP_JPY","message":{"mid_price":172.92,"bids":[{"price":172.66,"size":313.95},{"price":172.43,"size":49.9}],"asks":[{"price":173.52,"size":3092.0}]}}}
1618677600.669566: {"jsonrpc":"2.0","method":"channelMessage","params":{"channel":"lightning_ticker_BTC_EUR","message":{"product_code":"BTC_EUR","state":"RUNNING","timestamp":"2021-04-17T16:40:00.4870943Z","tick_id":1845549,"best_bid":50819.96,"best_ask":50896.12,"best_bid_size":0.40077,"best_ask_size":0.40077,"total_bid_depth":10.37824715,"total_ask_depth":11.98508706,"market_bid_size":0.0,"market_ask_size":0.0,"ltp":50500.0,"volume":12.650261930000,"volume_by_product":12.650261930000}}}
1618677600.669634: {"jsonrpc":"2.0","method":"channelMessage","params":{"channel":"lightning_board_BTC_EUR","message":{"mid_price":50858.04,"bids":[{"price":50678.96,"size":0.0}],"asks":[]}}}
1618677600.752906: {"jsonrpc":"2.0","method":"channelMessage","params":{"channel":"lightning_board_FX_BTC_JPY","message":{"mid_price":7185723.0,"bids":[{"price":7183172.0,"size":0.1075},{"price":7181821.0,"size":0.01}],"asks":[{"price":7190688.0,"size":0.0},{"price":7201294.0,"size":0.02},{"price":7189009.0,"size":0.0},{"price":7188964.0,"size":0.05},{"price":7187053.0,"size":0.05},{"price":7192087.0,"size":0.0}]}}}
1618677600.8651772: {"jsonrpc":"2.0","method":"channelMessage","params":{"channel":"lightning_board_FX_BTC_JPY","message":{"mid_price":7185723.0,"bids":[{"price":7183172.0,"size":0.0}],"asks":[{"price":7193932.0,"size":0.01},{"price":7188548.0,"size":0.01},{"price":7186784.0,"size":0.04999181},{"price":7189453.0,"size":0.21}]}}}
1618677600.891291: {"jsonrpc":"2.0","method":"channelMessage","params":{"channel":"lightning_board_ETH_JPY","message":{"mid_price":258774.0,"bids":[{"price":258687.0,"size":0.0},{"price":258683.0,"size":0.0},{"price":258684.0,"size":0.0},{"price":258640.0,"size":0.1},{"price":258622.0,"size":3.872},{"price":258677.0,"size":0.0},{"price":258676.0,"size":0.0}],"asks":[{"price":258915.0,"size":3.872}]}}}
1618677600.8914628: {"jsonrpc":"2.0","method":"channelMessage","params":{"channel":"lightning_board_BTC_EUR","message":{"mid_price":50858.04,"bids":[{"price":50764.2,"size":0.0}],"asks":[]}}}
1618677600.891519: {"jsonrpc":"2.0","method":"channelMessage","params":{"channel":"lightning_board_BTC_USD","message":{"mid_price":60541.29,"bids":[{"price":60514.28,"size":0.0}],"asks":[{"price":60566.91,"size":0.0}]}}}
1618677600.8927171: {"jsonrpc":"2.0","method":"channelMessage","params":{"channel":"lightning_ticker_XLM_JPY","message":{"product_code":"XLM_JPY","state":"RUNNING","timestamp":"2021-04-17T16:40:00.7717768Z","tick_id":4215953,"best_bid":65.931,"best_ask":66.035,"best_bid_size":757.67,"best_ask_size":534.0,"total_bid_depth":576377.3061419,"total_ask_depth":1016905.44764110,"market_bid_size":0.0,"market_ask_size":0.0,"ltp":65.902,"volume":2182293.365166500000,"volume_by_product":2182293.365166500000}}}
1618677600.895005: {"jsonrpc":"2.0","method":"channelMessage","params":{"channel":"lightning_board_XLM_JPY","message":{"mid_price":65.983,"bids":[{"price":65.728,"size":0.0}],"asks":[]}}}
1618677601.0047958: {"jsonrpc":"2.0","method":"channelMessage","params":{"channel":"lightning_board_FX_BTC_JPY","message":{"mid_price":7185723.0,"bids":[{"price":7182266.0,"size":0.1075},{"price":6942171.0,"size":1.40862363},{"price":7171892.0,"size":0.0}],"asks":[{"price":7188929.0,"size":0.05},{"price":7197645.0,"size":0.0},{"price":7202632.0,"size":0.01}]}}}
1618677601.1071842: {"jsonrpc":"2.0","method":"channelMessage","params":{"channel":"lightning_ticker_FX_BTC_JPY","message":{"product_code":"FX_BTC_JPY","state":"RUNNING","timestamp":"2021-04-17T16:40:00.9330548Z","tick_id":42420580,"best_bid":7185233.0,"best_ask":7186213.0,"best_bid_size":0.05,"best_ask_size":1.63916396,"total_bid_depth":2432.075374310000,"total_ask_depth":2472.052685100000,"market_bid_size":0.0,"market_ask_size":0.0,"ltp":7186230.0,"volume":2105.784486030000,"volume_by_product":2105.784486030000}}}
1618677601.120178: {"jsonrpc":"2.0","method":"channelMessage","params":{"channel":"lightning_board_FX_BTC_JPY","message":{"mid_price":7185723.0,"bids":[{"price":7161208.0,"size":0.0},{"price":6942171.0,"size":2.80127036},{"price":7182266.0,"size":0.0}],"asks":[{"price":7190964.0,"size":0.01},{"price":7190109.0,"size":0.0128},{"price":7191950.0,"size":0.0},{"price":7187978.0,"size":0.1},{"price":7186653.0,"size":0.0}]}}}
1618677601.1202931: {"jsonrpc":"2.0","method":"channelMessage","params":{"channel":"lightning_ticker_BTC_USD","message":{"product_code":"BTC_USD","state":"RUNNING","timestamp":"2021-04-17T16:40:00.8979659Z","tick_id":5565373,"best_bid":60515.68,"best_ask":60566.9,"best_bid_size":0.02,"best_ask_size":0.091,"total_bid_depth":8.58661782,"total_ask_depth":5.85349080,"market_bid_size":0.0,"market_ask_size":0.0,"ltp":60201.0,"volume":55.569921930000,"volume_by_product":55.569921930000}}}
1618677601.123897: {"jsonrpc":"2.0","method":"channelMessage","params":{"channel":"lightning_board_BTC_USD","message":{"mid_price":60541.29,"bids":[{"price":60506.27,"size":0.0}],"asks":[]}}}
1618677601.123944: {"jsonrpc":"2.0","method":"channelMessage","params":{"channel":"lightning_ticker_ETH_JPY","message":{"product_code":"ETH_JPY","state":"RUNNING","timestamp":"2021-04-17T16:40:00.913585Z","tick_id":10943373,"best_bid":258664.0,"best_ask":258885.0,"best_bid_size":1.000000,"best_ask_size":2.000000,"total_bid_depth":2374.382597900000,"total_ask_depth":2102.9285831,"market_bid_size":0.0,"market_ask_size":0.0,"ltp":258757.0,"volume":18068.878445400000,"volume_by_product":18068.878445400000}}}
1618677601.123978: {"jsonrpc":"2.0","method":"channelMessage","params":{"channel":"lightning_board_ETH_JPY","message":{"mid_price":258774.0,"bids":[{"price":258622.0,"size":0.0}],"asks":[]}}}
1618677601.1240058: {"jsonrpc":"2.0","method":"channelMessage","params":{"channel":"lightning_ticker_XRP_JPY","message":{"product_code":"XRP_JPY","state":"RUNNING","timestamp":"2021-04-17T16:40:00.913585Z","tick_id":8063001,"best_bid":172.8,"best_ask":173.04,"best_bid_size":614.19000000,"best_ask_size":1.0,"total_bid_depth":1500624.63693700,"total_ask_depth":2542399.55723400,"market_bid_size":0.0,"market_ask_size":0.0,"ltp":173.14,"volume":8347324.511315000000,"volume_by_product":8347324.511315000000}}}
1618677601.124031: {"jsonrpc":"2.0","method":"channelMessage","params":{"channel":"lightning_board_XRP_JPY","message":{"mid_price":172.92,"bids":[],"asks":[{"price":173.72,"size":0.0}]}}}
1618677601.1240551: {"jsonrpc":"2.0","method":"channelMessage","params":{"channel":"lightning_board_XLM_JPY","message":{"mid_price":65.983,"bids":[{"price":65.93,"size":0.0}],"asks":[]}}}
1618677601.22268: {"jsonrpc":"2.0","method":"channelMessage","params":{"channel":"lightning_board_FX_BTC_JPY","message":{"mid_price":7185723.0,"bids":[{"price":7167469.0,"size":0.0},{"price":7184082.0,"size":0.0},{"price":7170234.0,"size":0.01327181},{"price":7128896.0,"size":0.0},{"price":7173568.0,"size":0.01},{"price":7130715.0,"size":0.0},{"price":6595655.0,"size":2.7817},{"price":7179785.0,"size":0.0308}],"asks":[{"price":7205889.0,"size":0.0}]}}}
1618677601.332094: {"jsonrpc":"2.0","method":"channelMessage","params":{"channel":"lightning_board_FX_BTC_JPY","message":{"mid_price":7185723.0,"bids":[{"price":7165318.0,"size":0.03},{"price":7181687.0,"size":0.0}],"asks":[{"price":7193388.0,"size":0.0},{"price":7196630.0,"size":0.01}]}}}
1618677601.412229: {"jsonrpc":"2.0","method":"channelMessage","params":{"channel":"lightning_board_ETH_JPY","message":{"mid_price":258736.0,"bids":[{"price":258199.0,"size":0.512},{"price":258198.0,"size":0.0},{"price":258664.0,"size":0.0},{"price":258615.0,"size":1.0}],"asks":[{"price":258832.0,"size":2.425},{"price":258915.0,"size":0.0},{"price":258884.0,"size":0.3}]}}}
1618677601.412388: {"jsonrpc":"2.0","method":"channelMessage","params":{"channel":"lightning_board_BTC_USD","message":{"mid_price":60544.19,"bids":[{"price":60515.69,"size":0.099},{"price":60521.49,"size":0.1902}],"asks":[{"price":60566.9,"size":0.195},{"price":63245.22,"size":0.107},{"price":60566.91,"size":0.1902}]}}}
1618677601.4124641: {"jsonrpc":"2.0","method":"channelMessage","params":{"channel":"lightning_board_XRP_JPY","message":{"mid_price":172.92,"bids":[],"asks":[{"price":173.1,"size":356.51}]}}}
1618677601.4394538: {"jsonrpc":"2.0","method":"channelMessage","params":{"channel":"lightning_board_FX_BTC_JPY","message":{"mid_price":7185723.0,"bids":[],"asks":[{"price":7217107.0,"size":0.0},{"price":7215263.0,"size":0.0},{"price":7195453.0,"size":0.0128},{"price":7337000.0,"size":0.1},{"price":7196348.0,"size":0.0}]}}}
1618677601.522848: {"jsonrpc":"2.0","method":"channelMessage","params":{"channel":"lightning_board_BTC_USD","message":{"mid_price":60535.75,"bids":[{"price":60264.47,"size":0.002},{"price":60495.88,"size":0.1}],"asks":[{"price":63245.21,"size":0.06},{"price":60550.02,"size":0.12}]}}}
1618677601.5229802: {"jsonrpc":"2.0","method":"channelMessage","params":{"channel":"lightning_board_XRP_JPY","message":{"mid_price":172.94,"bids":[{"price":172.84,"size":1503.37},{"price":172.28,"size":0.0}],"asks":[{"price":173.15,"size":1505.37}]}}}
1618677601.580068: {"jsonrpc":"2.0","method":"channelMessage","params":{"channel":"lightning_board_FX_BTC_JPY","message":{"mid_price":7185723.0,"bids":[{"price":7175046.0,"size":0.02}],"asks":[{"price":7193380.0,"size":0.0},{"price":7200224.0,"size":0.0},{"price":7189509.0,"size":0.01},{"price":7209498.0,"size":0.05}]}}}
1618677601.626733: {"jsonrpc":"2.0","method":"channelMessage","params":{"channel":"lightning_ticker_BTC_USD","message":{"product_code":"BTC_USD","state":"RUNNING","timestamp":"2021-04-17T16:40:01.4031658Z","tick_id":5565384,"best_bid":60521.49,"best_ask":60550.02,"best_bid_size":0.1902,"best_ask_size":0.12,"total_bid_depth":8.97781782,"total_ask_depth":6.88369080,"market_bid_size":0.0,"market_ask_size":0.0,"ltp":60201.0,"volume":55.459921930000,"volume_by_product":55.459921930000}}}
1618677601.633125: {"jsonrpc":"2.0","method":"channelMessage","params":{"channel":"lightning_board_BTC_USD","message":{"mid_price":60535.75,"bids":[],"asks":[{"price":60658.96,"size":0.28},{"price":60622.64,"size":0.18}]}}}
1618677601.6332438: {"jsonrpc":"2.0","method":"channelMessage","params":{"channel":"lightning_ticker_ETH_JPY","message":{"product_code":"ETH_JPY","state":"RUNNING","timestamp":"2021-04-17T16:40:01.4031658Z","tick_id":10943382,"best_bid":258640.0,"best_ask":258832.0,"best_bid_size":0.100,"best_ask_size":2.425,"total_bid_depth":2373.412597900000,"total_ask_depth":2101.77158310,"market_bid_size":0.0,"market_ask_size":0.0,"ltp":258757.0,"volume":18068.878445400000,"volume_by_product":18068.878445400000}}}
1618677601.633315: {"jsonrpc":"2.0","method":"channelMessage","params":{"channel":"lightning_board_ETH_JPY","message":{"mid_price":258736.0,"bids":[{"price":254985.0,"size":0.0}],"asks":[{"price":261761.0,"size":0.0}]}}}
1618677601.6333818: {"jsonrpc":"2.0","method":"channelMessage","params":{"channel":"lightning_ticker_XRP_JPY","message":{"product_code":"XRP_JPY","state":"RUNNING","timestamp":"2021-04-17T16:40:01.4670054Z","tick_id":8063011,"best_bid":172.84,"best_ask":173.04,"best_bid_size":1503.37,"best_ask_size":1.0,"total_bid_depth":1512215.65693700,"total_ask_depth":2545658.96723400,"market_bid_size":0.0,"market_ask_size":0.0,"ltp":173.14,"volume":8347324.511315000000,"volume_by_product":8347324.511315000000}}}
1618677601.633434: {"jsonrpc":"2.0","method":"channelMessage","params":{"channel":"lightning_board_XRP_JPY","message":{"mid_price":172.94,"bids":[{"price":172.65,"size":0.0},{"price":172.66,"size":0.0},{"price":172.29,"size":15063.3}],"asks":[{"price":173.64,"size":0.0},{"price":173.47,"size":3070.0},{"price":173.51,"size":3347.4}]}}}
1618677601.699616: {"jsonrpc":"2.0","method":"channelMessage","params":{"channel":"lightning_ticker_FX_BTC_JPY","message":{"product_code":"FX_BTC_JPY","state":"RUNNING","timestamp":"2021-04-17T16:40:01.5560245Z","tick_id":42420609,"best_bid":7185233.0,"best_ask":7186213.0,"best_bid_size":0.05,"best_ask_size":1.63916396,"total_bid_depth":2431.875546120000,"total_ask_depth":2471.992685100000,"market_bid_size":0.0,"market_ask_size":0.0,"ltp":7186230.0,"volume":2105.784486030000,"volume_by_product":2105.784486030000}}}
1618677601.707096: {"jsonrpc":"2.0","method":"channelMessage","params":{"channel":"lightning_board_FX_BTC_JPY","message":{"mid_price":7185723.0,"bids":[{"price":7180243.0,"size":0.0905287},{"price":7160971.0,"size":0.05}],"asks":[{"price":7211339.0,"size":0.05},{"price":7192130.0,"size":0.0},{"price":7207658.0,"size":0.05},{"price":7197688.0,"size":0.0}]}}}
1618677601.816278: {"jsonrpc":"2.0","method":"channelMessage","params":{"channel":"lightning_board_FX_BTC_JPY","message":{"mid_price":7185723.0,"bids":[{"price":7127076.0,"size":0.0},{"price":6611253.0,"size":0.0}],"asks":[{"price":7197966.0,"size":0.0164},{"price":7191124.0,"size":0.0164},{"price":7189873.0,"size":0.02}]}}}
1618677601.869876: {"jsonrpc":"2.0","method":"channelMessage","params":{"channel":"lightning_board_XRP_JPY","message":{"mid_price":172.94,"bids":[{"price":172.16,"size":3062.0}],"asks":[]}}}
1618677601.8699899: {"jsonrpc":"2.0","method":"channelMessage","params":{"channel":"lightning_board_ETH_JPY","message":{"mid_price":258736.0,"bids":[{"price":258199.0,"size":0.0}],"asks":[{"price":259061.0,"size":0.0},{"price":262145.0,"size":0.01},{"price":258884.0,"size":0.0}]}}}
1618677601.870074: {"jsonrpc":"2.0","method":"channelMessage","params":{"channel":"lightning_board_BTC_USD","message":{"mid_price":60535.75,"bids":[{"price":60422.91,"size":0.19}],"asks":[]}}}
1618677601.956836: {"jsonrpc":"2.0","method":"channelMessage","params":{"channel":"lightning_board_FX_BTC_JPY","message":{"mid_price":7185723.0,"bids":[{"price":7165318.0,"size":0.02},{"price":7184082.0,"size":0.1075}],"asks":[{"price":7196230.0,"size":0.0},{"price":7274374.0,"size":0.01}]}}}
1618677601.980431: {"jsonrpc":"2.0","method":"channelMessage","params":{"channel":"lightning_board_ETH_JPY","message":{"mid_price":258735.0,"bids":[{"price":257822.0,"size":0.02}],"asks":[{"price":258831.0,"size":0.3}]}}}
1618677601.980551: {"jsonrpc":"2.0","method":"channelMessage","params":{"channel":"lightning_board_XRP_JPY","message":{"mid_price":172.94,"bids":[],"asks":[{"price":173.51,"size":0.0},{"price":173.46,"size":3346.74}]}}}
1618677601.9806201: {"jsonrpc":"2.0","method":"channelMessage","params":{"channel":"lightning_ticker_XLM_JPY","message":{"product_code":"XLM_JPY","state":"RUNNING","timestamp":"2021-04-17T16:40:01.8466809Z","tick_id":4215955,"best_bid":65.825,"best_ask":66.035,"best_bid_size":997.0,"best_ask_size":534.0,"total_bid_depth":573114.0181419,"total_ask_depth":1016905.44764110,"market_bid_size":0.0,"market_ask_size":0.0,"ltp":65.902,"volume":2182293.365166500000,"volume_by_product":2182293.365166500000}}}
1618677601.9806879: {"jsonrpc":"2.0","method":"channelMessage","params":{"channel":"lightning_board_XLM_JPY","message":{"mid_price":65.93,"bids":[{"price":65.931,"size":0.0}],"asks":[]}}}
1618677602.067883: {"jsonrpc":"2.0","method":"channelMessage","params":{"channel":"lightning_board_FX_BTC_JPY","message":{"mid_price":7185723.0,"bids":[],"asks":[{"price":7195485.0,"size":0.02},{"price":7188548.0,"size":0.0}]}}}
1618677602.097662: {"jsonrpc":"2.0","method":"channelMessage","params":{"channel":"lightning_ticker_BTC_EUR","message":{"product_code":"BTC_EUR","state":"RUNNING","timestamp":"2021-04-17T16:40:01.9716839Z","tick_id":1845552,"best_bid":50819.96,"best_ask":50879.64,"best_bid_size":0.40077,"best_ask_size":0.40077,"total_bid_depth":8.25221700,"total_ask_depth":11.98508706,"market_bid_size":0.0,"market_ask_size":0.0,"ltp":50500.0,"volume":12.650261930000,"volume_by_product":12.650261930000}}}
1618677602.1029592: {"jsonrpc":"2.0","method":"channelMessage","params":{"channel":"lightning_board_BTC_EUR","message":{"mid_price":50849.8,"bids":[],"asks":[{"price":50896.12,"size":0.0},{"price":50879.64,"size":0.40077}]}}}
1618677602.1030898: {"jsonrpc":"2.0","method":"channelMessage","params":{"channel":"lightning_board_BTC_USD","message":{"mid_price":60535.75,"bids":[{"price":60220.71,"size":0.0},{"price":60338.76,"size":0.0}],"asks":[{"price":60576.14,"size":0.0},{"price":60856.38,"size":0.0}]}}}
1618677602.1042309: {"jsonrpc":"2.0","method":"channelMessage","params":{"channel":"lightning_board_XLM_JPY","message":{"mid_price":65.937,"bids":[],"asks":[{"price":66.035,"size":0.0}]}}}
1618677602.1785758: {"jsonrpc":"2.0","method":"channelMessage","params":{"channel":"lightning_board_FX_BTC_JPY","message":{"mid_price":7185723.0,"bids":[],"asks":[{"price":7196504.0,"size":0.0}]}}}
1618677602.2376692: {"jsonrpc":"2.0","method":"channelMessage","params":{"channel":"lightning_ticker_ETH_JPY","message":{"product_code":"ETH_JPY","state":"RUNNING","timestamp":"2021-04-17T16:40:02.1279442Z","tick_id":10943390,"best_bid":258640.0,"best_ask":258831.0,"best_bid_size":0.100,"best_ask_size":1.30000000,"total_bid_depth":2373.880597900000,"total_ask_depth":2100.20658310,"market_bid_size":0.0,"market_ask_size":0.0,"ltp":258757.0,"volume":18068.878445400000,"volume_by_product":18068.878445400000}}}
1618677602.24212: {"jsonrpc":"2.0","method":"channelMessage","params":{"channel":"lightning_board_ETH_JPY","message":{"mid_price":258735.0,"bids":[{"price":258605.0,"size":1.0}],"asks":[{"price":258831.0,"size":1.3}]}}}
1618677602.277921: {"jsonrpc":"2.0","method":"channelMessage","params":{"channel":"lightning_ticker_FX_BTC_JPY","message":{"product_code":"FX_BTC_JPY","state":"RUNNING","timestamp":"2021-04-17T16:40:02.1362243Z","tick_id":42420624,"best_bid":7185233.0,"best_ask":7186213.0,"best_bid_size":0.05,"best_ask_size":1.63916396,"total_bid_depth":2431.855546120000,"total_ask_depth":2471.955485100000,"market_bid_size":0.0,"market_ask_size":0.0,"ltp":7186230.0,"volume":2105.784486030000,"volume_by_product":2105.784486030000}}}
1618677602.28351: {"jsonrpc":"2.0","method":"channelMessage","params":{"channel":"lightning_board_FX_BTC_JPY","message":{"mid_price":7185723.0,"bids":[{"price":7184082.0,"size":0.0},{"price":7159143.0,"size":0.05}],"asks":[{"price":7186234.0,"size":0.01}]}}}
1618677602.3546848: {"jsonrpc":"2.0","method":"channelMessage","params":{"channel":"lightning_ticker_BTC_USD","message":{"product_code":"BTC_USD","state":"RUNNING","timestamp":"2021-04-17T16:40:02.1436024Z","tick_id":5565393,"best_bid":60515.69,"best_ask":60550.02,"best_bid_size":0.099,"best_ask_size":0.12,"total_bid_depth":8.01841782,"total_ask_depth":6.38369080,"market_bid_size":0.0,"market_ask_size":0.0,"ltp":60201.0,"volume":55.459921930000,"volume_by_product":55.459921930000}}}
1618677602.354798: {"jsonrpc":"2.0","method":"channelMessage","params":{"channel":"lightning_board_BTC_USD","message":{"mid_price":60532.85,"bids":[{"price":60521.49,"size":0.0},{"price":60514.29,"size":0.0},{"price":60512.41,"size":0.0},{"price":60503.5,"size":0.0}],"asks":[]}}}
1618677602.3549: {"jsonrpc":"2.0","method":"channelMessage","params":{"channel":"lightning_ticker_XRP_JPY","message":{"product_code":"XRP_JPY","state":"RUNNING","timestamp":"2021-04-17T16:40:02.1436024Z","tick_id":8063015,"best_bid":172.84,"best_ask":173.04,"best_bid_size":1503.37,"best_ask_size":1.0,"total_bid_depth":1518171.65693700,"total_ask_depth":2545658.30723400,"market_bid_size":0.0,"market_ask_size":0.0,"ltp":173.14,"volume":8346290.491315000000,"volume_by_product":8346290.491315000000}}}
1618677602.355009: {"jsonrpc":"2.0","method":"channelMessage","params":{"channel":"lightning_board_XRP_JPY","message":{"mid_price":172.94,"bids":[{"price":172.26,"size":3094.0}],"asks":[]}}}
1618677602.3550699: {"jsonrpc":"2.0","method":"channelMessage","params":{"channel":"lightning_board_BTC_EUR","message":{"mid_price":50849.8,"bids":[{"price":50578.32,"size":0.0}],"asks":[]}}}
1618677602.358469: {"jsonrpc":"2.0","method":"channelMessage","params":{"channel":"lightning_board_XLM_JPY","message":{"mid_price":65.937,"bids":[{"price":65.0,"size":29781.4852782}],"asks":[]}}}
1618677602.3641658: {"jsonrpc":"2.0","method":"channelMessage","params":{"channel":"lightning_board_ETH_JPY","message":{"mid_price":258735.0,"bids":[{"price":255847.0,"size":5.670943}],"asks":[]}}}
1618677602.396199: {"jsonrpc":"2.0","method":"channelMessage","params":{"channel":"lightning_board_FX_BTC_JPY","message":{"mid_price":7185722.0,"bids":[{"price":7165905.0,"size":0.11},{"price":7183172.0,"size":0.02}],"asks":[{"price":7192717.0,"size":0.05},{"price":7186212.0,"size":0.01},{"price":7196340.0,"size":0.0},{"price":7200513.0,"size":0.0}]}}}
1618677602.465364: {"jsonrpc":"2.0","method":"channelMessage","params":{"channel":"lightning_board_BTC_EUR","message":{"mid_price":50849.8,"bids":[{"price":50665.47,"size":0.185},{"price":50570.12,"size":0.35}],"asks":[]}}}
1618677602.465481: {"jsonrpc":"2.0","method":"channelMessage","params":{"channel":"lightning_board_XLM_JPY","message":{"mid_price":65.938,"bids":[{"price":65.826,"size":2273.01}],"asks":[]}}}
1618677602.465536: {"jsonrpc":"2.0","method":"channelMessage","params":{"channel":"lightning_board_XRP_JPY","message":{"mid_price":172.94,"bids":[],"asks":[{"price":173.47,"size":0.0},{"price":173.15,"size":2.0}]}}}
1618677602.515003: {"jsonrpc":"2.0","method":"channelMessage","params":{"channel":"lightning_board_snapshot_BCH_BTC","message":{"mid_price":0.01711,"bids":[{"price":0.007,"size":0.1},{"price":0.0072,"size":0.1},{"price":0.0074,"size":0.1},{"price":0.0076,"size":0.1},{"price":0.0078,"size":0.2},{"price":0.008,"size":0.1},{"price":0.0082,"size":0.1},{"price":0.0084,"size":0.11},{"price":0.00851,"size":5.1},{"price":0.0086,"size":0.1},{"price":0.0088,"size":0.1},{"price":0.009,"size":12.1},{"price":0.0091,"size":1.0},{"price":0.0092,"size":1.1},{"price":0.00927,"size":0.1},{"price":0.0093,"size":1.0},{"price":0.0094,"size":1.1},{"price":0.0095,"size":1.0},{"price":0.0096,"size":1.1},{"price":0.0097,"size":1.0},{"price":0.0098,"size":2.12},{"price":0.0099,"size":1.0},{"price":0.00996,"size":0.1},{"price":0.01,"size":1.06},{"price":0.01001,"size":15.0},{"price":0.0101,"size":1.03},{"price":0.0102,"size":2.0},{"price":0.0103,"size":1.0},{"price":0.0104,"size":1.0},{"price":0.0105,"size":1.02},{"price":0.0106,"size":1.0},{"price":0.0107,"size":1.0},{"price":0.0108,"size":2.0},{"price":0.0109,"size":1.0},{"price":0.011,"size":1.07},{"price":0.0111,"size":1.02},{"price":0.01113,"size":0.01},{"price":0.0112,"size":1.02},{"price":0.0113,"size":1.01},{"price":0.0114,"size":1.31},{"price":0.0115,"size":1.53},{"price":0.0116,"size":1.03},{"price":0.0117,"size":1.0},{"price":0.0118,"size":101.3},{"price":0.0119,"size":1.0},{"price":0.012,"size":1.05},{"price":0.0121,"size":1.0},{"price":0.01211,"size":20.0},{"price":0.0123,"size":0.3},{"price":0.0124,"size":0.01},{"price":0.0125,"size":0.02},{"price":0.0126,"size":0.31},{"price":0.01294,"size":0.0148},{"price":0.013,"size":0.02},{"price":0.01322,"size":10.0},{"price":0.0135,"size":0.06},{"price":0.0145,"size":0.01},{"price":0.015,"size":0.01},{"price":0.01513,"size":0.1},{"price":0.0153,"size":9.52},{"price":0.0155,"size":0.41},{"price":0.01561,"size":10.0},{"price":0.01562,"size":15.0},{"price":0.0159,"size":5.1},{"price":0.016,"size":0.07},{"price":0.01621,"size":1.0},{"price":0.01622,"size":2.06},{"price":0.01623,"size":0.7},{"price":0.01633,"size":4.23},{"price":0.01645,"size":10.55},{"price":0.01664,"size":1.4158836},{"price":0.01667,"size":0.3},{"price":0.01668,"size":1.25}],"asks":[{"price":0.01754,"size":0.3},{"price":0.01755,"size":13.3658066},{"price":0.01756,"size":1.05},{"price":0.01764,"size":14.04},{"price":0.01767,"size":9.516},{"price":0.01776,"size":0.5},{"price":0.01777,"size":14.24},{"price":0.01786,"size":2.11},{"price":0.01794,"size":1.01},{"price":0.01825,"size":3.35},{"price":0.0183,"size":1.19520958},{"price":0.01866,"size":3.0},{"price":0.01867,"size":0.3646},{"price":0.019,"size":2.1},{"price":0.01905,"size":1.386},{"price":0.01908,"size":12.93},{"price":0.01909,"size":1.0},{"price":0.01913,"size":0.6},{"price":0.01942,"size":0.05},{"price":0.01946,"size":0.1},{"price":0.0195,"size":5.51},{"price":0.01975,"size":0.1},{"price":0.0198,"size":0.05},{"price":0.01986,"size":0.3},{"price":0.02,"size":21.95783634},{"price":0.02007,"size":0.1},{"price":0.02025,"size":0.1},{"price":0.0205,"size":0.6},{"price":0.02075,"size":0.1},{"price":0.021,"size":1.12},{"price":0.02125,"size":0.1},{"price":0.0215,"size":0.1},{"price":0.02175,"size":0.1},{"price":0.022,"size":2.31},{"price":0.02225,"size":0.1},{"price":0.0225,"size":0.15},{"price":0.02275,"size":0.1},{"price":0.023,"size":6.21},{"price":0.02325,"size":0.1},{"price":0.0235,"size":0.1},{"price":0.02375,"size":0.1},{"price":0.0238,"size":0.224},{"price":0.024,"size":1.11},{"price":0.02425,"size":0.1},{"price":0.0245,"size":0.1},{"price":0.02475,"size":0.1},{"price":0.025,"size":2.36},{"price":0.02525,"size":0.1},{"price":0.0255,"size":0.1},{"price":0.02575,"size":0.1},{"price":0.026,"size":1.11},{"price":0.02625,"size":0.1},{"price":0.0265,"size":0.1},{"price":0.02675,"size":0.1},{"price":0.027,"size":1.11},{"price":0.02725,"size":0.1},{"price":0.0275,"size":0.1},{"price":0.02775,"size":0.1},{"price":0.028,"size":2.1},{"price":0.0285,"size":0.1},{"price":0.029,"size":1.1},{"price":0.0298,"size":19.95},{"price":0.03,"size":1.15},{"price":0.032,"size":3.22688165},{"price":0.035,"size":3.13290959}]}}}
1618677602.5157518: {"jsonrpc":"2.0","method":"channelMessage","params":{"channel":"lightning_board_snapshot_BTC_USD","message":{"mid_price":60532.85,"bids":[{"price":27750.0,"size":0.3},{"price":50000.0,"size":0.07},{"price":52000.0,"size":0.019},{"price":53248.67,"size":0.017469},{"price":54300.0,"size":0.016299},{"price":54984.76,"size":0.00142021},{"price":55000.0,"size":0.01},{"price":55067.55,"size":0.01},{"price":55784.76,"size":0.00308151},{"price":56000.0,"size":0.011},{"price":56015.83,"size":0.01605},{"price":56100.0,"size":0.01},{"price":56945.86,"size":0.01667},{"price":57000.0,"size":0.01},{"price":57500.0,"size":0.0821},{"price":58000.0,"size":0.01},{"price":58500.0,"size":0.01},{"price":58890.68,"size":0.001},{"price":59000.0,"size":0.01},{"price":59311.0,"size":0.03},{"price":59400.0,"size":0.06},{"price":59500.0,"size":0.2},{"price":59600.0,"size":0.2},{"price":59814.58,"size":1.1361185},{"price":59881.44,"size":0.6456875},{"price":60006.39,"size":0.194},{"price":60134.6,"size":0.5595824},{"price":60225.95,"size":0.39},{"price":60264.46,"size":0.4237397},{"price":60264.47,"size":0.002},{"price":60341.84,"size":0.25},{"price":60405.07,"size":0.2},{"price":60405.09,"size":0.2},{"price":60411.13,"size":1.358},{"price":60422.91,"size":0.19},{"price":60438.98,"size":0.19},{"price":60468.66,"size":0.18},{"price":60477.74,"size":0.12},{"price":60479.02,"size":0.18},{"price":60488.1,"size":0.12},{"price":60495.88,"size":0.1},{"price":60496.29,"size":0.1902},{"price":60507.6,"size":0.1},{"price":60514.3,"size":0.056},{"price":60515.68,"size":0.02},{"price":60515.69,"size":0.099}],"asks":[{"price":60550.02,"size":0.12},{"price":60566.9,"size":0.195},{"price":60566.91,"size":0.1902},{"price":60584.29,"size":0.11},{"price":60591.82,"size":0.1902},{"price":60592.55,"size":0.1902},{"price":60604.89,"size":0.18},{"price":60613.94,"size":0.25},{"price":60613.97,"size":0.25},{"price":60615.27,"size":0.18},{"price":60622.64,"size":0.18},{"price":60638.77,"size":0.18},{"price":60658.96,"size":0.28},{"price":60675.1,"size":0.28},{"price":60730.5,"size":0.25},{"price":60730.63,"size":0.1596235},{"price":60861.67,"size":0.39},{"price":60911.26,"size":0.229186},{"price":61190.48,"size":0.2427313},{"price":61788.5,"size":0.0017},{"price":61987.15,"size":0.002},{"price":62185.67,"size":0.0019},{"price":63245.21,"size":0.06},{"price":63245.22,"size":0.107},{"price":63867.17,"size":0.0019},{"price":64000.0,"size":1.039},{"price":64432.47,"size":0.0017},{"price":64864.98,"size":0.015},{"price":64875.0,"size":0.045},{"price":64983.77,"size":0.027},{"price":64983.8,"size":0.002},{"price":65000.0,"size":0.1},{"price":65059.85,"size":0.015},{"price":65836.8,"size":0.0022},{"price":65875.0,"size":0.065},{"price":66000.0,"size":0.499},{"price":66376.91,"size":0.015},{"price":66777.69,"size":0.002},{"price":67267.5,"size":0.015},{"price":67456.41,"size":0.00185},{"price":67875.0,"size":0.085},{"price":67950.0,"size":0.097},{"price":68182.88,"size":0.0015},{"price":69782.39,"size":0.0018},{"price":69875.0,"size":0.105},{"price":70302.17,"size":0.015},{"price":71264.63,"size":0.002},{"price":75000.0,"size":0.01}]}}}
1618677602.516064: {"jsonrpc":"2.0","method":"channelMessage","params":{"channel":"lightning_board_snapshot_BTC_EUR","message":{"mid_price":50849.8,"bids":[{"price":27418.0,"size":0.001},{"price":30666.0,"size":0.001},{"price":34565.0,"size":0.001},{"price":42000.0,"size":0.072},{"price":44400.0,"size":0.05},{"price":44500.0,"size":0.00184},{"price":44700.0,"size":0.0022612},{"price":46000.0,"size":1.0100658},{"price":46250.0,"size":0.5},{"price":46500.0,"size":1.0054},{"price":47000.0,"size":1.0},{"price":47500.0,"size":1.0},{"price":47550.0,"size":0.0045},{"price":47900.0,"size":0.00315},{"price":48000.0,"size":1.001},{"price":48400.0,"size":1.01},{"price":49000.0,"size":0.00613},{"price":49300.0,"size":0.0031},{"price":49601.0,"size":0.019},{"price":50570.12,"size":0.35},{"price":50590.24,"size":0.2},{"price":50606.94,"size":0.2},{"price":50665.47,"size":0.185},{"price":50746.15,"size":0.26},{"price":50768.52,"size":0.15},{"price":50819.96,"size":0.40077}],"asks":[{"price":50879.64,"size":0.40077},{"price":52450.0,"size":0.00287019},{"price":52499.94,"size":0.42},{"price":52499.96,"size":8.95744687},{"price":52500.0,"size":0.567},{"price":52966.0,"size":0.0081},{"price":53650.0,"size":0.36},{"price":54099.0,"size":0.498},{"price":54142.0,"size":0.0059},{"price":54200.0,"size":0.05},{"price":55000.0,"size":0.01},{"price":55378.0,"size":0.002},{"price":56200.0,"size":0.09},{"price":58025.0,"size":0.2},{"price":58699.0,"size":0.001},{"price":60000.0,"size":0.01},{"price":61314.0,"size":0.001},{"price":63025.0,"size":0.4},{"price":65242.0,"size":0.001}]}}}
1618677602.5334709: {"jsonrpc":"2.0","method":"channelMessage","params":{"channel":"lightning_board_snapshot_ETH_JPY","message":{"mid_price":258735.0,"bids":[{"price":258640.0,"size":0.1},{"price":258615.0,"size":1.0},{"price":258605.0,"size":1.0},{"price":258598.0,"size":0.99},{"price":258597.0,"size":1.0},{"price":258596.0,"size":1.0},{"price":258594.0,"size":1.0},{"price":258589.0,"size":1.0},{"price":258588.0,"size":1.0},{"price":258587.0,"size":3.475},{"price":258586.0,"size":1.0},{"price":258580.0,"size":1.0},{"price":258579.0,"size":1.0},{"price":258567.0,"size":1.0},{"price":258564.0,"size":1.0},{"price":258503.0,"size":0.1},{"price":258500.0,"size":0.038},{"price":258495.0,"size":2.475},{"price":258146.0,"size":5.549},{"price":258138.0,"size":0.1},{"price":258082.0,"size":0.02},{"price":258034.0,"size":0.02},{"price":258033.0,"size":0.02},{"price":257980.0,"size":0.02},{"price":257933.0,"size":0.1},{"price":257822.0,"size":0.02},{"price":257757.0,"size":0.1},{"price":257727.0,"size":0.0128896},{"price":257628.0,"size":17.977},{"price":257500.0,"size":0.02},{"price":257450.0,"size":3.0},{"price":257317.0,"size":0.01},{"price":257118.0,"size":0.9720086},{"price":257000.0,"size":1.4},{"price":256999.0,"size":0.013},{"price":256954.0,"size":0.4},{"price":256898.0,"size":0.01},{"price":256780.0,"size":0.1},{"price":256659.0,"size":182.56},{"price":256641.0,"size":0.05},{"price":256556.0,"size":0.01},{"price":256345.0,"size":0.04},{"price":256298.0,"size":0.01},{"price":256090.0,"size":2.0},{"price":256025.0,"size":6.3},{"price":256010.0,"size":0.53},{"price":256000.0,"size":11.682},{"price":255860.0,"size":0.1},{"price":255847.0,"size":5.670943},{"price":255700.0,"size":0.1},{"price":255699.0,"size":71.068},{"price":255595.0,"size":0.01},{"price":255500.0,"size":9.07},{"price":255257.0,"size":10.0},{"price":255100.0,"size":0.01005},{"price":255000.0,"size":4.18},{"price":254800.0,"size":0.19},{"price":254793.0,"size":0.06},{"price":254621.0,"size":0.5},{"price":254620.0,"size":0.1},{"price":254520.0,"size":4.18},{"price":254500.0,"size":0.025},{"price":254323.0,"size":0.05},{"price":254288.0,"size":0.236},{"price":254200.0,"size":0.5},{"price":254155.0,"size":0.01},{"price":254108.0,"size":0.01},{"price":254100.0,"size":1.0},{"price":254000.0,"size":16.087},{"price":253699.0,"size":0.01},{"price":253620.0,"size":0.1},{"price":253600.0,"size":0.5},{"price":253588.0,"size":0.2},{"price":253514.0,"size":5.0},{"price":253501.0,"size":1.0},{"price":253500.0,"size":2.5977},{"price":253300.0,"size":5.5},{"price":253288.0,"size":0.119},{"price":253250.0,"size":1.679},{"price":253245.0,"size":37.031},{"price":253200.0,"size":2.832427},{"price":253100.0,"size":1.0},{"price":253026.0,"size":0.04},{"price":253020.0,"size":0.2},{"price":253001.0,"size":0.4},{"price":253000.0,"size":20.4613},{"price":252924.0,"size":0.1},{"price":252900.0,"size":1.0},{"price":252872.0,"size":0.01},{"price":252868.0,"size":1.8},{"price":252850.0,"size":0.1},{"price":252800.0,"size":1.0},{"price":252788.0,"size":0.119},{"price":252750.0,"size":10.0},{"price":252632.0,"size":0.1838286},{"price":252600.0,"size":1.0},{"price":252580.0,"size":0.3},{"price":252500.0,"size":7.525},{"price":252480.0,"size":0.01},{"price":252400.0,"size":2.0},{"price":252350.0,"size":3.0},{"price":252300.0,"size":1.0},{"price":252288.0,"size":0.119},{"price":252235.0,"size":0.01},{"price":252233.0,"size":0.01},{"price":252101.0,"size":1.1},{"price":252100.0,"size":13.05},{"price":252081.0,"size":0.1},{"price":252018.0,"size":0.02},{"price":252001.0,"size":1.1},{"price":252000.0,"size":27.114},{"price":251905.0,"size":0.1},{"price":251900.0,"size":0.01},{"price":251872.0,"size":1.0},{"price":251800.0,"size":0.0199},{"price":251788.0,"size":0.12},{"price":251700.0,"size":1.0},{"price":251652.0,"size":0.1},{"price":251546.0,"size":18.388},{"price":251524.0,"size":0.1},{"price":251505.0,"size":0.5},{"price":251500.0,"size":1.575},{"price":251473.0,"size":0.01},{"price":251400.0,"size":6.0},{"price":251288.0,"size":0.12},{"price":251249.0,"size":10.0},{"price":251235.0,"size":0.05},{"price":251234.0,"size":0.2},{"price":251233.0,"size":0.01},{"price":251200.0,"size":2.0},{"price":251111.0,"size":4.44},{"price":251110.0,"size":0.05},{"price":251100.0,"size":2.0},{"price":251090.0,"size":0.7},{"price":251034.0,"size":0.02},{"price":251001.0,"size":0.1},{"price":251000.0,"size":51.06195},{"price":250980.0,"size":0.8},{"price":250800.0,"size":1.0},{"price":250794.0,"size":0.5},{"price":250788.0,"size":0.12},{"price":250780.0,"size":0.25},{"price":250700.0,"size":5.0},{"price":250650.0,"size":0.2},{"price":250592.0,"size":0.04},{"price":250555.0,"size":0.2002},{"price":250521.0,"size":0.013},{"price":250500.0,"size":5.025},{"price":250311.0,"size":0.2},{"price":250300.0,"size":0.6},{"price":250288.0,"size":0.964},{"price":250250.0,"size":0.5},{"price":250235.0,"size":0.05},{"price":250233.0,"size":0.01},{"price":250200.0,"size":1.0},{"price":250113.0,"size":0.0399},{"price":250111.0,"size":2.2},{"price":250100.0,"size":2.762},{"price":250046.0,"size":1.0},{"price":250028.0,"size":0.04},{"price":250020.0,"size":0.8},{"price":250019.0,"size":0.1},{"price":250005.0,"size":1.0},{"price":250002.0,"size":0.2502},{"price":250001.0,"size":12.28012},{"price":250000.0,"size":144.333336},{"price":249990.0,"size":3.0},{"price":249936.0,"size":0.01},{"price":249900.0,"size":2.0},{"price":249890.0,"size":1.0},{"price":249849.0,"size":0.01983},{"price":249800.0,"size":0.01},{"price":249788.0,"size":0.121},{"price":249750.0,"size":0.1},{"price":249655.0,"size":0.5013},{"price":249644.0,"size":2.0},{"price":249600.0,"size":1.0},{"price":249500.0,"size":0.2},{"price":249300.0,"size":1.5},{"price":249288.0,"size":0.121},{"price":249233.0,"size":0.01},{"price":249200.0,"size":1.0},{"price":249140.0,"size":5.0},{"price":249000.0,"size":2.63},{"price":248900.0,"size":0.05},{"price":248788.0,"size":0.121},{"price":248700.0,"size":1.0},{"price":248511.0,"size":0.15},{"price":248500.0,"size":3.0},{"price":248400.0,"size":1.45},{"price":248288.0,"size":0.121},{"price":248233.0,"size":0.01},{"price":248195.0,"size":0.01},{"price":248182.0,"size":0.05},{"price":248100.0,"size":2.0},{"price":248050.0,"size":0.1},{"price":248008.0,"size":0.4},{"price":248001.0,"size":0.1},{"price":248000.0,"size":23.804},{"price":247800.0,"size":0.2},{"price":247788.0,"size":0.122},{"price":247771.0,"size":1.0},{"price":247700.0,"size":4.0},{"price":247644.0,"size":2.0},{"price":247500.0,"size":0.435},{"price":247484.0,"size":18.185},{"price":247288.0,"size":0.122},{"price":247252.0,"size":0.1},{"price":247233.0,"size":0.01},{"price":247200.0,"size":0.1},{"price":247000.0,"size":5.425},{"price":246850.0,"size":0.1},{"price":246800.0,"size":1.0},{"price":246788.0,"size":0.122},{"price":246703.0,"size":0.1},{"price":246678.0,"size":3.0},{"price":246666.0,"size":0.1},{"price":246500.0,"size":0.025},{"price":246467.0,"size":0.04},{"price":246288.0,"size":0.122},{"price":246233.0,"size":0.01},{"price":246101.0,"size":0.01},{"price":246100.0,"size":1.0},{"price":246000.0,"size":5.905},{"price":245888.0,"size":0.2},{"price":245796.0,"size":0.1},{"price":245788.0,"size":0.123},{"price":245780.0,"size":0.25},{"price":245675.0,"size":0.0177},{"price":245650.0,"size":0.1},{"price":245644.0,"size":2.0},{"price":245621.0,"size":1.0},{"price":245593.0,"size":0.04},{"price":245555.0,"size":0.1002},{"price":245518.0,"size":0.2},{"price":245500.0,"size":0.025},{"price":245400.0,"size":2.5},{"price":245300.0,"size":0.05},{"price":245288.0,"size":0.123},{"price":245250.0,"size":0.5},{"price":245233.0,"size":0.01},{"price":245173.0,"size":0.02},{"price":245134.0,"size":0.1},{"price":245123.0,"size":0.01},{"price":245067.0,"size":1.0},{"price":245050.0,"size":1.0},{"price":245000.0,"size":33.853},{"price":244800.0,"size":0.01},{"price":244788.0,"size":0.123},{"price":244745.0,"size":0.5},{"price":244500.0,"size":2.025},{"price":244288.0,"size":0.123},{"price":244100.0,"size":2.0},{"price":244050.0,"size":1.0},{"price":244035.0,"size":0.041},{"price":244000.0,"size":2.317},{"price":243788.0,"size":0.124},{"price":243742.0,"size":0.01162},{"price":243555.0,"size":0.7},{"price":243288.0,"size":0.124},{"price":243240.0,"size":1.0},{"price":243201.0,"size":1.0},{"price":243016.0,"size":0.1},{"price":243011.0,"size":0.0207},{"price":243000.0,"size":6.53},{"price":242788.0,"size":0.124},{"price":242761.0,"size":1.0},{"price":242680.0,"size":0.15},{"price":242500.0,"size":0.1},{"price":242400.0,"size":0.6},{"price":242288.0,"size":0.124},{"price":242200.0,"size":2.0},{"price":242101.0,"size":1.0},{"price":242100.0,"size":1.0},{"price":242000.0,"size":3.077},{"price":241893.0,"size":0.1},{"price":241800.0,"size":1.3},{"price":241788.0,"size":0.125},{"price":241650.0,"size":0.1},{"price":241600.0,"size":0.3},{"price":241500.0,"size":0.4},{"price":241486.0,"size":0.01122},{"price":241288.0,"size":0.125},{"price":241011.0,"size":0.1},{"price":241000.0,"size":8.17},{"price":240788.0,"size":0.125},{"price":240780.0,"size":0.25},{"price":240750.0,"size":1.0},{"price":240671.0,"size":0.01},{"price":240555.0,"size":0.1002},{"price":240513.0,"size":0.5},{"price":240500.0,"size":4.3},{"price":240300.0,"size":0.5011},{"price":240288.0,"size":0.126},{"price":240250.0,"size":0.5},{"price":240200.0,"size":0.33},{"price":240194.0,"size":1.0},{"price":240111.0,"size":0.1},{"price":240100.0,"size":3.002},{"price":240009.0,"size":0.05}],"asks":[{"price":258831.0,"size":1.3},{"price":258832.0,"size":2.425},{"price":258885.0,"size":2.0},{"price":258886.0,"size":3.55},{"price":258895.0,"size":1.0},{"price":258917.0,"size":1.0},{"price":258924.0,"size":1.0},{"price":258927.0,"size":1.0},{"price":258930.0,"size":1.0},{"price":258931.0,"size":1.0},{"price":258944.0,"size":2.575},{"price":258979.0,"size":1.0},{"price":258984.0,"size":1.0},{"price":258987.0,"size":1.0},{"price":258988.0,"size":1.0},{"price":259000.0,"size":0.38},{"price":259002.0,"size":1.0},{"price":259003.0,"size":2.425},{"price":259012.0,"size":4.3},{"price":259032.0,"size":1.0},{"price":259036.0,"size":1.0},{"price":259037.0,"size":1.0},{"price":259048.0,"size":1.0},{"price":259058.0,"size":1.0},{"price":259073.0,"size":1.0},{"price":259078.0,"size":1.0},{"price":259083.0,"size":0.01},{"price":259085.0,"size":1.0},{"price":259087.0,"size":1.0},{"price":259091.0,"size":1.0},{"price":259095.0,"size":1.0},{"price":259103.0,"size":1.0},{"price":259341.0,"size":0.01},{"price":259459.0,"size":5.549},{"price":259460.0,"size":1.0},{"price":259712.0,"size":17.877},{"price":259713.0,"size":0.1},{"price":259727.0,"size":0.01},{"price":259844.0,"size":0.04},{"price":259846.0,"size":0.01},{"price":259937.0,"size":0.04},{"price":260000.0,"size":5.48},{"price":260143.0,"size":174.983},{"price":260584.0,"size":0.01},{"price":260627.0,"size":0.07},{"price":261000.0,"size":0.38},{"price":261062.0,"size":0.1},{"price":261280.0,"size":0.04},{"price":261519.0,"size":0.77},{"price":261594.0,"size":0.1},{"price":261677.0,"size":35.08},{"price":262000.0,"size":0.39},{"price":262145.0,"size":0.01},{"price":262557.0,"size":0.06},{"price":263000.0,"size":0.600027},{"price":263010.0,"size":0.04},{"price":263250.0,"size":0.9996216},{"price":263423.0,"size":0.0000008},{"price":263500.0,"size":0.9990002},{"price":263501.0,"size":0.1},{"price":263506.0,"size":17.721},{"price":263612.0,"size":1.0},{"price":263671.0,"size":0.04},{"price":263708.0,"size":0.04},{"price":263822.0,"size":0.23},{"price":263900.0,"size":8.8444208},{"price":264000.0,"size":0.38},{"price":264123.0,"size":0.4},{"price":264323.0,"size":10.0},{"price":264695.0,"size":0.1},{"price":264759.0,"size":0.1},{"price":264822.0,"size":0.23},{"price":265000.0,"size":1.4491},{"price":265012.0,"size":0.4},{"price":265107.0,"size":0.04},{"price":265111.0,"size":0.999},{"price":265400.0,"size":0.3},{"price":265500.0,"size":0.2},{"price":265652.0,"size":0.0489363},{"price":265752.0,"size":0.0489178},{"price":265822.0,"size":0.23},{"price":265990.0,"size":0.5},{"price":266000.0,"size":4.225},{"price":266080.0,"size":0.19976},{"price":266123.0,"size":0.2},{"price":266198.0,"size":0.2},{"price":266200.0,"size":1.1},{"price":266207.0,"size":0.04},{"price":266369.0,"size":0.04},{"price":266450.0,"size":0.8},{"price":266480.0,"size":0.0995},{"price":266500.0,"size":2.68},{"price":266619.0,"size":0.0000058},{"price":266654.0,"size":0.0487524},{"price":266666.0,"size":0.02},{"price":266822.0,"size":0.72},{"price":266826.0,"size":18.012},{"price":267000.0,"size":7.849},{"price":267010.0,"size":14.79},{"price":267123.0,"size":0.2},{"price":267210.0,"size":0.255},{"price":267355.0,"size":0.097249},{"price":267431.0,"size":0.79856},{"price":267500.0,"size":0.998},{"price":267650.0,"size":2.9958},{"price":267822.0,"size":0.22},{"price":267893.0,"size":0.7},{"price":267982.0,"size":0.63},{"price":268000.0,"size":10.469302},{"price":268106.0,"size":0.75},{"price":268123.0,"size":0.2},{"price":268200.0,"size":4.93},{"price":268320.0,"size":2.0},{"price":268324.0,"size":0.2},{"price":268326.0,"size":0.75},{"price":268385.0,"size":1.0},{"price":268481.0,"size":0.75},{"price":268499.0,"size":10.0},{"price":268500.0,"size":7.0},{"price":268520.0,"size":0.15},{"price":268727.0,"size":0.75},{"price":268750.0,"size":0.1},{"price":268758.0,"size":0.0483708},{"price":268822.0,"size":0.22},{"price":268892.0,"size":0.4},{"price":268950.0,"size":0.1},{"price":268980.0,"size":0.12},{"price":269000.0,"size":5.4},{"price":269200.0,"size":0.1},{"price":269241.0,"size":5.0},{"price":269292.0,"size":0.3},{"price":269450.0,"size":2.0},{"price":269492.0,"size":0.3},{"price":269500.0,"size":8.455},{"price":269648.0,"size":0.04},{"price":269660.0,"size":0.0259587},{"price":269700.0,"size":0.1},{"price":269792.0,"size":0.3},{"price":269822.0,"size":0.22},{"price":269890.0,"size":0.2},{"price":269892.0,"size":0.3},{"price":269900.0,"size":4.0},{"price":269945.0,"size":0.11977},{"price":269950.0,"size":1.0},{"price":269999.0,"size":27.94},{"price":270000.0,"size":207.479775},{"price":270100.0,"size":1.0},{"price":270200.0,"size":5.0},{"price":270352.0,"size":0.9994},{"price":270450.0,"size":2.0},{"price":270500.0,"size":6.505},{"price":270600.0,"size":0.1},{"price":270683.0,"size":0.08},{"price":270684.0,"size":0.3715},{"price":270700.0,"size":0.08},{"price":270721.0,"size":1.27},{"price":270822.0,"size":0.22},{"price":270892.0,"size":0.3},{"price":270920.0,"size":3.09},{"price":270998.0,"size":5.448},{"price":271000.0,"size":26.9827},{"price":271009.0,"size":0.33},{"price":271041.0,"size":0.1},{"price":271234.0,"size":0.015},{"price":271450.0,"size":2.0},{"price":271460.0,"size":0.1641},{"price":271500.0,"size":10.07},{"price":271505.0,"size":0.05},{"price":271537.0,"size":0.04},{"price":271555.0,"size":10.0},{"price":271621.0,"size":0.5},{"price":271650.0,"size":1.0861896},{"price":271796.0,"size":0.1},{"price":271800.0,"size":5.0},{"price":271810.0,"size":0.099309},{"price":271822.0,"size":0.22},{"price":271888.0,"size":11.0},{"price":271892.0,"size":0.3},{"price":271900.0,"size":0.46},{"price":271981.0,"size":0.10035},{"price":272000.0,"size":28.3623222},{"price":272100.0,"size":1.0},{"price":272111.0,"size":10.0},{"price":272131.0,"size":1.0},{"price":272222.0,"size":1.19},{"price":272243.0,"size":0.04},{"price":272264.0,"size":0.0367291},{"price":272269.0,"size":0.74},{"price":272300.0,"size":0.71},{"price":272345.0,"size":1.8845},{"price":272364.0,"size":0.74},{"price":272409.0,"size":0.685},{"price":272422.0,"size":0.2},{"price":272450.0,"size":2.0},{"price":272567.0,"size":0.02},{"price":272750.0,"size":0.25},{"price":272758.0,"size":0.74},{"price":272773.0,"size":0.01},{"price":272777.0,"size":0.1},{"price":272800.0,"size":0.28},{"price":272822.0,"size":0.22},{"price":272850.0,"size":0.25},{"price":272890.0,"size":0.25},{"price":272900.0,"size":3.27},{"price":272990.0,"size":1.7562419},{"price":273000.0,"size":80.0725},{"price":273010.0,"size":1.05},{"price":273188.0,"size":2.9},{"price":273200.0,"size":0.4},{"price":273300.0,"size":0.25},{"price":273400.0,"size":2.3169598},{"price":273403.0,"size":0.04},{"price":273450.0,"size":2.0},{"price":273500.0,"size":4.215},{"price":273650.0,"size":3.0},{"price":273822.0,"size":0.22},{"price":273900.0,"size":0.25},{"price":273995.0,"size":0.9},{"price":273998.0,"size":0.3},{"price":274000.0,"size":19.1649},{"price":274027.0,"size":0.04},{"price":274090.0,"size":0.01},{"price":274100.0,"size":1.0},{"price":274211.0,"size":0.9994},{"price":274253.0,"size":0.198},{"price":274300.0,"size":0.25},{"price":274444.0,"size":0.955},{"price":274450.0,"size":2.0},{"price":274468.0,"size":2.0},{"price":274500.0,"size":8.36},{"price":274561.0,"size":0.1},{"price":274600.0,"size":6.1},{"price":274619.0,"size":0.35},{"price":274700.0,"size":0.1},{"price":274715.0,"size":0.02},{"price":274797.0,"size":0.999},{"price":274800.0,"size":0.2},{"price":274815.0,"size":0.5},{"price":274822.0,"size":0.22},{"price":274890.0,"size":0.03},{"price":274900.0,"size":0.35},{"price":274940.0,"size":0.73},{"price":274998.0,"size":0.09487},{"price":275000.0,"size":43.7160439},{"price":275200.0,"size":1.1},{"price":275234.0,"size":1.0},{"price":275250.0,"size":0.2},{"price":275300.0,"size":0.35},{"price":275393.0,"size":0.04},{"price":275400.0,"size":8.7},{"price":275450.0,"size":2.0},{"price":275490.0,"size":0.1},{"price":275500.0,"size":1.215},{"price":275644.0,"size":10.0},{"price":275716.0,"size":0.01},{"price":275822.0,"size":0.22},{"price":275867.0,"size":0.9976},{"price":275883.0,"size":1.019},{"price":275900.0,"size":0.25},{"price":276000.0,"size":20.1217923},{"price":276050.0,"size":0.03},{"price":276100.0,"size":1.0},{"price":276111.0,"size":0.05},{"price":276200.0,"size":0.8},{"price":276300.0,"size":0.25},{"price":276388.0,"size":0.99},{"price":276450.0,"size":2.0},{"price":276488.0,"size":0.2},{"price":276500.0,"size":29.886},{"price":276550.0,"size":1.015},{"price":276644.0,"size":2.3},{"price":276800.0,"size":10.47},{"price":276822.0,"size":0.22},{"price":276888.0,"size":9.996},{"price":276900.0,"size":0.45},{"price":276921.0,"size":0.02},{"price":276966.0,"size":5.0},{"price":276990.0,"size":8.67},{"price":276998.0,"size":0.5},{"price":277000.0,"size":147.874144},{"price":277199.0,"size":0.0360698},{"price":277200.0,"size":0.284},{"price":277222.0,"size":2.0},{"price":277312.0,"size":0.03},{"price":277386.0,"size":0.1994},{"price":277400.0,"size":1.25},{"price":277450.0,"size":2.0},{"price":277497.0,"size":0.03},{"price":277500.0,"size":1.01},{"price":277600.0,"size":0.25},{"price":277644.0,"size":2.0},{"price":277666.0,"size":0.25},{"price":277755.0,"size":1.0},{"price":277777.0,"size":0.3},{"price":277822.0,"size":0.22},{"price":277899.0,"size":1.0},{"price":277900.0,"size":0.25},{"price":278000.0,"size":3.042},{"price":278100.0,"size":1.0},{"price":278394.0,"size":0.1}]}}}
1618677602.55657: {"jsonrpc":"2.0","method":"channelMessage","params":{"channel":"lightning_board_snapshot_XRP_JPY","message":{"mid_price":172.94,"bids":[{"price":172.84,"size":1503.37},{"price":172.8,"size":614.19},{"price":172.7,"size":1860.03},{"price":172.64,"size":12297.0},{"price":172.43,"size":49.9},{"price":172.4,"size":60.0},{"price":172.29,"size":15063.3},{"price":172.26,"size":3094.0},{"price":172.16,"size":3062.0},{"price":172.1,"size":50.0},{"price":172.02,"size":100.0},{"price":172.0,"size":746.8},{"price":171.82,"size":119828.0},{"price":171.52,"size":100.0},{"price":171.5,"size":10.0},{"price":171.4,"size":500.0},{"price":171.12,"size":9.0},{"price":171.02,"size":100.0},{"price":171.0,"size":46948.0},{"price":170.52,"size":100.0},{"price":170.12,"size":23744.0},{"price":170.11,"size":50.0},{"price":170.02,"size":100.0},{"price":170.0,"size":2521.0},{"price":169.95,"size":49.35},{"price":169.6,"size":819.0},{"price":169.59,"size":2000.0},{"price":169.52,"size":100.0},{"price":169.5,"size":200.0},{"price":169.17,"size":12248.0},{"price":169.11,"size":150.0},{"price":169.02,"size":100.0},{"price":169.0,"size":39820.8},{"price":168.83,"size":100.0},{"price":168.8,"size":3001.0},{"price":168.51,"size":10003.0},{"price":168.5,"size":2190.0},{"price":168.4,"size":3000.0},{"price":168.22,"size":600.0},{"price":168.2,"size":3512.0},{"price":168.14,"size":10000.0},{"price":168.11,"size":150.0},{"price":168.1,"size":6000.0},{"price":168.0,"size":23957.0},{"price":167.99,"size":50.0},{"price":167.7,"size":53.0},{"price":167.5,"size":150.0},{"price":167.3,"size":300.0},{"price":167.23,"size":10.0},{"price":167.2,"size":250.0},{"price":167.12,"size":10.0},{"price":167.11,"size":50.0},{"price":167.0,"size":34250.426946},{"price":166.93,"size":11719.0},{"price":166.9,"size":15.0},{"price":166.6,"size":9480.0},{"price":166.33,"size":15000.0},{"price":166.11,"size":200.0},{"price":166.1,"size":950.0},{"price":166.04,"size":200.0},{"price":166.0,"size":9062.048},{"price":165.9,"size":300.0},{"price":165.76,"size":1000.0},{"price":165.6,"size":100.0},{"price":165.5,"size":250.0},{"price":165.44,"size":301.0},{"price":165.12,"size":10.0},{"price":165.1,"size":100.0},{"price":165.06,"size":20.0},{"price":165.02,"size":2000.0},{"price":165.0,"size":84835.174696},{"price":164.6,"size":700.0},{"price":164.58,"size":5000.0},{"price":164.15,"size":22.0},{"price":164.12,"size":10.0},{"price":164.08,"size":10.0},{"price":164.0,"size":6273.857317},{"price":163.8,"size":1020.0},{"price":163.6,"size":700.0},{"price":163.56,"size":11882.0},{"price":163.4,"size":200.0},{"price":163.12,"size":10.0},{"price":163.1,"size":200.0},{"price":163.06,"size":100.1},{"price":163.0,"size":3886.0},{"price":162.68,"size":1500.0},{"price":162.6,"size":700.0},{"price":162.4,"size":1001.0},{"price":162.2,"size":250.0},{"price":162.19,"size":2000.0},{"price":162.12,"size":10.0},{"price":162.0,"size":26402.0},{"price":161.6,"size":700.0},{"price":161.42,"size":1000.0},{"price":161.3,"size":300.0},{"price":161.12,"size":10.0},{"price":161.0,"size":2323.1},{"price":160.99,"size":2020.0},{"price":160.8,"size":230.0},{"price":160.6,"size":800.0},{"price":160.5,"size":1135.0},{"price":160.2,"size":8306.0},{"price":160.12,"size":10.0},{"price":160.1,"size":1080.0},{"price":160.04,"size":100.0},{"price":160.01,"size":500.0},{"price":160.0,"size":89737.4},{"price":159.8,"size":86.0},{"price":159.73,"size":10.0},{"price":159.7,"size":70.0},{"price":159.2,"size":560.0},{"price":159.15,"size":1500.0},{"price":159.11,"size":50.0},{"price":159.1,"size":508.0},{"price":159.08,"size":300.27},{"price":159.0,"size":23003.0},{"price":158.96,"size":100.0},{"price":158.8,"size":480.0},{"price":158.75,"size":2000.0},{"price":158.51,"size":100.0},{"price":158.5,"size":2800.0},{"price":158.4,"size":402.0},{"price":158.11,"size":100.0},{"price":158.1,"size":50.0},{"price":158.0,"size":13871.0},{"price":157.95,"size":5000.0},{"price":157.2,"size":110.0},{"price":157.19,"size":1500.0},{"price":157.11,"size":50.0},{"price":157.1,"size":201.0},{"price":157.0,"size":10282.089171},{"price":156.9,"size":200.0},{"price":156.23,"size":580.0},{"price":156.2,"size":101.0},{"price":156.11,"size":100.0},{"price":156.0,"size":24883.166666},{"price":155.5,"size":65.0},{"price":155.11,"size":50.0},{"price":155.1,"size":3135.0},{"price":155.0,"size":84519.2},{"price":154.2,"size":3000.2},{"price":154.15,"size":22.0},{"price":154.12,"size":1.0},{"price":154.11,"size":100.0},{"price":154.1,"size":50.0},{"price":154.04,"size":10.0},{"price":154.0,"size":572.0},{"price":153.11,"size":50.0},{"price":153.1,"size":50.0},{"price":153.04,"size":10.0},{"price":153.0,"size":3217.0},{"price":152.9,"size":1000.0},{"price":152.77,"size":33.0},{"price":152.74,"size":50.0},{"price":152.55,"size":100.0},{"price":152.51,"size":40.0},{"price":152.5,"size":100.0},{"price":152.11,"size":50.0},{"price":152.05,"size":0.5},{"price":152.04,"size":10.0},{"price":152.0,"size":4519.0},{"price":151.6,"size":400.0},{"price":151.25,"size":1200.0},{"price":151.11,"size":50.0},{"price":151.1,"size":1050.0},{"price":151.0,"size":20712.013245},{"price":150.8,"size":100.0},{"price":150.6,"size":1000.0},{"price":150.56,"size":1000.0},{"price":150.55,"size":1000.0},{"price":150.52,"size":500.0},{"price":150.5,"size":4000.0},{"price":150.27,"size":1000.0},{"price":150.11,"size":100.0},{"price":150.1,"size":1040.0},{"price":150.06,"size":22.481395},{"price":150.04,"size":15.0},{"price":150.01,"size":1412.0},{"price":150.0,"size":101672.588523},{"price":149.9,"size":101.0},{"price":149.11,"size":50.0},{"price":149.0,"size":1675.0},{"price":148.6,"size":14189.111709},{"price":148.4,"size":1000.0},{"price":148.11,"size":50.0},{"price":148.1,"size":50.0},{"price":148.0,"size":13055.0},{"price":147.7,"size":11700.0},{"price":147.23,"size":41.0},{"price":147.11,"size":50.0},{"price":147.0,"size":5721.24},{"price":146.61,"size":25.0},{"price":146.6,"size":1900.0},{"price":146.5,"size":300.0},{"price":146.11,"size":50.0},{"price":146.0,"size":1175.0},{"price":145.92,"size":10.0},{"price":145.51,"size":100.0},{"price":145.5,"size":2950.0},{"price":145.1,"size":1050.0},{"price":145.01,"size":700.0},{"price":145.0,"size":8418.4},{"price":144.5,"size":5.0},{"price":144.15,"size":22.0},{"price":144.1,"size":15000.0},{"price":144.0,"size":681.0},{"price":143.5,"size":5.0},{"price":143.25,"size":2000.0},{"price":143.03,"size":2000.0},{"price":143.0,"size":435.58034},{"price":142.72,"size":50.0},{"price":142.6,"size":2000.0},{"price":142.11,"size":1.0},{"price":142.1,"size":50.0},{"price":142.0,"size":1696.0},{"price":141.81,"size":5.0},{"price":141.77,"size":50.0},{"price":141.7,"size":11000.0},{"price":141.0,"size":500.0},{"price":140.5,"size":5000.0},{"price":140.2,"size":2000.0},{"price":140.1,"size":31000.0},{"price":140.0,"size":11264.757142},{"price":139.1,"size":50.0},{"price":139.07,"size":100.0},{"price":138.6,"size":74.9},{"price":138.0,"size":510.0},{"price":137.82,"size":2.91},{"price":137.6,"size":201.0},{"price":137.5,"size":10000.0},{"price":137.0,"size":350.0},{"price":136.1,"size":50.0},{"price":135.72,"size":50.0},{"price":135.57,"size":80.0},{"price":135.5,"size":3700.0},{"price":135.0,"size":511.1},{"price":134.83,"size":50.0},{"price":134.0,"size":1.0},{"price":133.1,"size":50.0},{"price":132.55,"size":100.0},{"price":132.29,"size":50.0},{"price":132.0,"size":100.0},{"price":131.5,"size":761.0},{"price":131.11,"size":1000.0},{"price":130.1,"size":50.0},{"price":130.0,"size":9115.1},{"price":129.0,"size":1.0},{"price":128.8,"size":300.0},{"price":128.0,"size":100.0},{"price":127.96,"size":10.0},{"price":127.4,"size":11.0},{"price":126.7,"size":2000.0},{"price":126.35,"size":100.0},{"price":125.77,"size":10000.0},{"price":125.5,"size":5000.0},{"price":125.1,"size":10000.0},{"price":125.0,"size":2034.1},{"price":124.8,"size":1000.0},{"price":124.0,"size":1339.548387},{"price":123.5,"size":166.0},{"price":123.0,"size":105100.0},{"price":122.6,"size":3000.0},{"price":121.11,"size":1000.0},{"price":120.8,"size":300.0},{"price":120.6,"size":10.0},{"price":120.01,"size":50000.0},{"price":120.0,"size":17769.1},{"price":118.6,"size":610.0},{"price":118.3,"size":700.0},{"price":118.0,"size":10.0},{"price":117.0,"size":60.0},{"price":116.0,"size":10.0},{"price":115.8,"size":20.0},{"price":115.0,"size":10.1},{"price":114.85,"size":3.492},{"price":114.0,"size":10.0},{"price":113.0,"size":500.0},{"price":112.55,"size":100.0},{"price":112.1,"size":2150.0},{"price":112.0,"size":100.0},{"price":111.3,"size":887.0},{"price":111.11,"size":1000.0},{"price":110.8,"size":20.0},{"price":110.0,"size":1432.0},{"price":109.0,"size":10.0},{"price":108.56,"size":100.0},{"price":107.0,"size":500.0},{"price":105.5,"size":120.0},{"price":105.3,"size":3000.0},{"price":105.13,"size":10.0},{"price":105.02,"size":96.0},{"price":105.0,"size":100.0},{"price":103.0,"size":90.0},{"price":102.71,"size":2.0},{"price":102.1,"size":100.0},{"price":101.11,"size":1000.0},{"price":100.02,"size":30.0},{"price":100.0,"size":36750.3},{"price":99.88,"size":100.0},{"price":99.0,"size":310.0}],"asks":[{"price":173.04,"size":1.0},{"price":173.05,"size":1.0},{"price":173.06,"size":1.0},{"price":173.07,"size":1.0},{"price":173.1,"size":356.51},{"price":173.12,"size":1.0},{"price":173.15,"size":2.0},{"price":173.18,"size":1.0},{"price":173.2,"size":1.0},{"price":173.22,"size":1.0},{"price":173.24,"size":1.0},{"price":173.28,"size":1.0},{"price":173.29,"size":3505.7},{"price":173.36,"size":1.0},{"price":173.46,"size":3346.74},{"price":173.52,"size":3092.0},{"price":173.65,"size":2888.0},{"price":173.99,"size":12297.0},{"price":174.0,"size":1.0},{"price":174.33,"size":20.0},{"price":174.4,"size":23909.4},{"price":174.43,"size":40.0},{"price":174.98,"size":400.0},{"price":174.99,"size":200.0},{"price":175.0,"size":5201.0},{"price":176.0,"size":7988.0},{"price":176.05,"size":48488.0},{"price":176.49,"size":5380.0},{"price":177.0,"size":2004.0},{"price":177.19,"size":24373.0},{"price":177.36,"size":400.0},{"price":177.9,"size":1396.0},{"price":177.94,"size":11881.0},{"price":178.0,"size":420.8},{"price":178.46,"size":647.99},{"price":178.5,"size":20.0},{"price":178.6,"size":50.0},{"price":178.8,"size":399.2},{"price":178.86,"size":11641.0},{"price":179.0,"size":15025.0},{"price":179.31,"size":1999.0},{"price":179.99,"size":3995.593818},{"price":180.0,"size":10834.370097},{"price":180.03,"size":1000.0},{"price":180.15,"size":1614.0},{"price":180.5,"size":25.0},{"price":180.9,"size":499.3},{"price":181.0,"size":27087.466924},{"price":181.5,"size":276.3},{"price":181.6,"size":250.0},{"price":182.0,"size":9540.97648},{"price":182.1,"size":50.0},{"price":182.2,"size":3242.0},{"price":182.3,"size":2.0},{"price":182.47,"size":819.59},{"price":182.7,"size":2500.0},{"price":182.8,"size":99.3075},{"price":183.0,"size":1569.058042},{"price":183.1,"size":1000.0},{"price":183.43,"size":815.31},{"price":183.52,"size":148.9},{"price":183.91,"size":15.0},{"price":184.0,"size":4750.1},{"price":184.1,"size":50.0},{"price":184.2,"size":3439.0},{"price":184.4,"size":2998.0},{"price":184.45,"size":2000.0},{"price":184.5,"size":499.0},{"price":184.52,"size":20.0},{"price":184.9,"size":5321.0},{"price":185.0,"size":14324.491577},{"price":185.42,"size":6017.0},{"price":185.5,"size":182.925612},{"price":185.53,"size":41.4},{"price":185.56,"size":500.0},{"price":185.69,"size":5000.0},{"price":185.75,"size":300.0},{"price":185.79,"size":1424.665794},{"price":186.0,"size":20542.2509},{"price":186.1,"size":51.0},{"price":186.33,"size":500.0},{"price":186.5,"size":19091.0},{"price":186.56,"size":200.0},{"price":187.0,"size":3814.848},{"price":187.1,"size":50.0},{"price":187.13,"size":50.0},{"price":187.2,"size":20.0},{"price":187.23,"size":200.0},{"price":187.3,"size":6000.0},{"price":187.41,"size":10000.0},{"price":187.75,"size":400.0},{"price":187.89,"size":30.0},{"price":187.9,"size":1000.0},{"price":188.0,"size":71219.411997},{"price":188.01,"size":62.4},{"price":188.1,"size":50.0},{"price":188.28,"size":2500.0},{"price":188.38,"size":1000.0},{"price":188.43,"size":100.0},{"price":188.55,"size":1057.95},{"price":188.6,"size":10000.97},{"price":188.61,"size":3000.0},{"price":188.8,"size":5500.0},{"price":188.85,"size":2924.0},{"price":188.86,"size":2000.0},{"price":188.9,"size":40.0},{"price":189.0,"size":46670.4454},{"price":189.11,"size":500.0},{"price":189.2,"size":6595.220175},{"price":189.3,"size":500.0},{"price":189.4,"size":100.0},{"price":189.49,"size":2000.0},{"price":189.5,"size":5000.0},{"price":189.69,"size":62.5},{"price":189.7,"size":2003.0},{"price":189.75,"size":350.0},{"price":189.8,"size":6600.0},{"price":189.81,"size":39093.83007},{"price":189.9,"size":2000.0},{"price":189.99,"size":600.0},{"price":190.0,"size":77774.190312},{"price":190.1,"size":50.0},{"price":190.2,"size":514.0},{"price":190.26,"size":200.0},{"price":190.3,"size":5001.0},{"price":190.56,"size":200.0},{"price":190.86,"size":1.0},{"price":190.9,"size":599.7},{"price":190.92,"size":783.34},{"price":191.0,"size":6580.0},{"price":191.26,"size":200.0},{"price":191.31,"size":1500.0},{"price":191.4,"size":34.0},{"price":191.5,"size":1463.5},{"price":191.66,"size":200.0},{"price":191.75,"size":350.0},{"price":192.0,"size":7153.757487},{"price":192.1,"size":50.0},{"price":192.13,"size":55.782},{"price":192.28,"size":20.0},{"price":192.3,"size":1.0},{"price":192.66,"size":200.0},{"price":192.69,"size":62.5},{"price":192.8,"size":1000.0},{"price":193.0,"size":16617.45},{"price":193.1,"size":400.0},{"price":193.2,"size":1960.0},{"price":193.33,"size":20.0},{"price":193.37,"size":773.4},{"price":193.5,"size":195.0},{"price":193.6,"size":100.0},{"price":193.66,"size":100.0},{"price":193.75,"size":350.0},{"price":194.0,"size":42295.431725},{"price":194.1,"size":50.0},{"price":194.15,"size":22.0},{"price":194.41,"size":769.28},{"price":194.9,"size":2868.4},{"price":194.91,"size":500.0},{"price":194.98,"size":2000.0},{"price":195.0,"size":38115.585124},{"price":195.21,"size":1400.0},{"price":195.39,"size":100.0},{"price":195.4,"size":765.35},{"price":195.5,"size":100.0},{"price":195.75,"size":400.0},{"price":195.99,"size":3045.661},{"price":196.0,"size":5590.0},{"price":196.06,"size":0.4},{"price":196.1,"size":1550.0},{"price":196.2,"size":19673.0},{"price":196.39,"size":100.0},{"price":196.4,"size":50.0},{"price":196.5,"size":2545.0},{"price":196.61,"size":760.65},{"price":197.0,"size":6160.0},{"price":197.39,"size":100.0},{"price":197.46,"size":100.0},{"price":197.5,"size":506.0},{"price":197.75,"size":300.0},{"price":197.8,"size":529.0},{"price":197.86,"size":3490.0},{"price":197.9,"size":1150.30961},{"price":197.98,"size":2000.0},{"price":198.0,"size":284322.95},{"price":198.08,"size":1000.0},{"price":198.1,"size":50.0},{"price":198.31,"size":399.303397},{"price":198.36,"size":2.425},{"price":198.39,"size":100.0},{"price":198.5,"size":3500.0},{"price":198.56,"size":458.0},{"price":198.6,"size":1995.0},{"price":198.69,"size":752.68},{"price":198.71,"size":752.6},{"price":198.75,"size":150.0},{"price":199.0,"size":84245.805866},{"price":199.07,"size":2366.0},{"price":199.25,"size":150.0},{"price":199.3,"size":2000.0},{"price":199.38,"size":11995.0},{"price":199.39,"size":100.0},{"price":199.4,"size":1000.0},{"price":199.5,"size":6511.221445},{"price":199.52,"size":3000.0},{"price":199.6,"size":500.0},{"price":199.7,"size":2466.271},{"price":199.75,"size":500.0},{"price":199.77,"size":1027.0},{"price":199.79,"size":100.0},{"price":199.8,"size":30.0},{"price":199.89,"size":3000.0},{"price":199.94,"size":40.0},{"price":199.95,"size":41.0},{"price":199.98,"size":124.5},{"price":200.0,"size":185445.838335},{"price":200.1,"size":416.7},{"price":200.25,"size":200.0},{"price":200.4,"size":200.0},{"price":200.42,"size":162.0},{"price":200.55,"size":28922.1},{"price":200.6,"size":199.0},{"price":200.61,"size":499.0},{"price":200.75,"size":200.0},{"price":200.77,"size":255.33},{"price":200.88,"size":500.0},{"price":200.9,"size":10.0},{"price":200.97,"size":744.16},{"price":201.0,"size":1257.700999},{"price":201.05,"size":500.0},{"price":201.36,"size":50.0},{"price":201.43,"size":100.0},{"price":201.5,"size":200.0},{"price":201.86,"size":50.0},{"price":201.93,"size":100.0},{"price":202.0,"size":8262.371821},{"price":202.1,"size":50.0},{"price":202.19,"size":25.0},{"price":202.46,"size":92.969756},{"price":203.0,"size":8332.8},{"price":203.99,"size":225.0},{"price":204.0,"size":30504.3},{"price":204.15,"size":22.0},{"price":204.2,"size":282.24},{"price":204.25,"size":598.96},{"price":204.36,"size":50.0},{"price":204.5,"size":1000.0},{"price":204.6,"size":12345.0},{"price":204.79,"size":125.0},{"price":204.85,"size":250.0},{"price":204.89,"size":100.0},{"price":204.9,"size":509.53015},{"price":204.94,"size":40.0},{"price":205.0,"size":60109.378355},{"price":205.09,"size":100.0},{"price":205.1,"size":2000.0},{"price":205.15,"size":40.0},{"price":205.2,"size":2000.0},{"price":205.26,"size":728.58},{"price":205.3,"size":1997.60048},{"price":205.4,"size":1998.40031},{"price":205.5,"size":2500.0},{"price":205.6,"size":2000.0},{"price":205.67,"size":4620.0},{"price":205.7,"size":2248.24035},{"price":205.78,"size":400.0},{"price":205.8,"size":2000.0},{"price":205.9,"size":2200.0},{"price":206.0,"size":31861.00049},{"price":206.1,"size":2050.0},{"price":206.12,"size":2895.0},{"price":206.2,"size":2246.0},{"price":206.28,"size":31.1111},{"price":206.3,"size":1998.40032},{"price":206.4,"size":1998.40032},{"price":206.5,"size":10000.0},{"price":206.6,"size":2029.188325},{"price":207.0,"size":38799.468812},{"price":207.18,"size":200.0},{"price":208.0,"size":6817.862207},{"price":208.1,"size":50.0},{"price":208.5,"size":52100.0},{"price":208.9,"size":20.0},{"price":209.0,"size":5689.46},{"price":209.07,"size":1000.0},{"price":209.09,"size":9998.0},{"price":209.35,"size":814.36},{"price":209.5,"size":10.0},{"price":209.85,"size":450.0},{"price":209.9,"size":11130.0},{"price":210.0,"size":144566.548027},{"price":210.01,"size":86.0},{"price":210.07,"size":1000.0},{"price":210.1,"size":50.0},{"price":210.15,"size":1500.0},{"price":210.21,"size":100.0},{"price":210.3,"size":1000.0},{"price":210.42,"size":710.74},{"price":210.46,"size":100.0},{"price":211.0,"size":3503.79}]}}}
1618677602.569834: {"jsonrpc":"2.0","method":"channelMessage","params":{"channel":"lightning_board_snapshot_MONA_JPY","message":{"mid_price":401.795,"bids":[{"price":120.0,"size":200.0},{"price":125.0,"size":0.1},{"price":137.82,"size":2.91},{"price":140.0,"size":10.2},{"price":150.0,"size":0.2},{"price":151.0,"size":5000.0},{"price":165.0,"size":0.1},{"price":165.38,"size":2.425},{"price":175.0,"size":0.1},{"price":180.0,"size":193.0},{"price":180.01,"size":100.0},{"price":190.0,"size":50.0},{"price":198.46,"size":2.021},{"price":199.0,"size":1.41},{"price":200.0,"size":823.3},{"price":201.0,"size":200.0},{"price":202.5,"size":10.0},{"price":210.0,"size":15.3},{"price":210.249,"size":50.0},{"price":211.1,"size":2000.0},{"price":212.0,"size":41.1},{"price":214.0,"size":0.1},{"price":215.0,"size":0.1},{"price":215.65,"size":3.0},{"price":216.0,"size":50.2},{"price":217.0,"size":0.1},{"price":218.0,"size":0.2},{"price":219.0,"size":907.4},{"price":220.0,"size":344.85},{"price":221.0,"size":10.1},{"price":222.0,"size":100.0},{"price":222.3,"size":11.0},{"price":225.0,"size":253.2},{"price":226.0,"size":50.0},{"price":226.251,"size":5.0},{"price":228.0,"size":505.65},{"price":229.0,"size":5.0},{"price":230.0,"size":16.21},{"price":231.0,"size":250.0},{"price":231.002,"size":100.0},{"price":233.513,"size":5.0},{"price":234.0,"size":100.0},{"price":235.0,"size":592.0},{"price":236.0,"size":200.0},{"price":238.0,"size":200.0},{"price":238.15,"size":1.684},{"price":240.0,"size":311.2},{"price":240.166,"size":1.0},{"price":243.0,"size":22.0},{"price":245.0,"size":2511.1},{"price":247.872,"size":0.10045},{"price":248.0,"size":300.0},{"price":249.118,"size":0.10045},{"price":250.0,"size":953.2},{"price":250.1,"size":20.0},{"price":250.823,"size":100.0},{"price":251.0,"size":30.0},{"price":251.1,"size":2000.0},{"price":252.0,"size":1.0},{"price":252.5,"size":252.0},{"price":253.0,"size":1.0},{"price":253.28,"size":200.0},{"price":253.466,"size":192.06},{"price":254.0,"size":15.6},{"price":255.0,"size":466.38},{"price":255.1,"size":20.0},{"price":255.349,"size":40.0},{"price":257.0,"size":100.0},{"price":257.1,"size":20.0},{"price":258.0,"size":202.0},{"price":259.1,"size":20.0},{"price":260.0,"size":201.1},{"price":260.25,"size":1000.0},{"price":261.1,"size":20.0},{"price":264.01,"size":100.0},{"price":265.0,"size":21.0},{"price":267.0,"size":500.0},{"price":268.0,"size":500.0},{"price":270.0,"size":211.1},{"price":271.1,"size":20.0},{"price":275.0,"size":340.0},{"price":276.622,"size":153.61778608},{"price":278.0,"size":0.3417249},{"price":280.0,"size":670.1},{"price":281.1,"size":20.0},{"price":282.11,"size":0.1},{"price":283.0,"size":500.0},{"price":285.0,"size":50.0},{"price":285.78,"size":1.403},{"price":290.0,"size":0.2},{"price":290.2,"size":100.0},{"price":291.1,"size":20.0},{"price":295.0,"size":17.0},{"price":296.66,"size":1000.0},{"price":299.1,"size":20.0},{"price":300.0,"size":1677.9},{"price":300.2,"size":100.0},{"price":301.1,"size":120.0},{"price":302.12,"size":240.0},{"price":303.784,"size":202.0},{"price":305.0,"size":16.5},{"price":306.1,"size":100.0},{"price":306.71,"size":1000.0},{"price":307.368,"size":30.0},{"price":310.0,"size":526.5},{"price":310.2,"size":100.0},{"price":311.0,"size":120.0},{"price":311.1,"size":2120.0},{"price":314.111,"size":2200.0},{"price":315.0,"size":16.4746},{"price":315.13,"size":100.0},{"price":316.1,"size":100.0},{"price":318.0,"size":3.0},{"price":320.0,"size":667.4},{"price":320.5,"size":100.0},{"price":320.563,"size":80.0},{"price":321.1,"size":100.0},{"price":322.0,"size":210.0},{"price":323.0,"size":1500.0},{"price":325.0,"size":6184.423},{"price":326.1,"size":100.0},{"price":326.34,"size":240.0},{"price":327.368,"size":211.0},{"price":328.0,"size":750.6517},{"price":329.986,"size":142.01},{"price":330.0,"size":15.5},{"price":330.01,"size":10.0},{"price":330.5,"size":100.0},{"price":331.1,"size":100.0},{"price":332.01,"size":205.0},{"price":333.0,"size":28.0},{"price":335.0,"size":15.1},{"price":335.001,"size":10.0},{"price":335.5,"size":1513.64828614},{"price":336.1,"size":100.0},{"price":337.423,"size":800.0},{"price":337.52,"size":10.0},{"price":337.775,"size":320.0},{"price":340.0,"size":426.5},{"price":340.5,"size":100.0},{"price":341.1,"size":100.0},{"price":342.94,"size":1.169},{"price":343.0,"size":1000.0},{"price":345.0,"size":14.6},{"price":345.513,"size":200.0},{"price":346.1,"size":100.0},{"price":346.13,"size":221.0},{"price":347.52,"size":10.0},{"price":350.0,"size":2298.5},{"price":350.5,"size":100.0},{"price":351.0,"size":150.0},{"price":351.1,"size":2100.0},{"price":353.0,"size":1000.0},{"price":353.008,"size":200.0},{"price":355.0,"size":14.3},{"price":356.1,"size":100.0},{"price":357.52,"size":10.0},{"price":357.98,"size":25.0},{"price":358.08,"size":22.3},{"price":360.0,"size":742.4},{"price":361.0,"size":2000.0},{"price":361.076,"size":828.0},{"price":361.1,"size":300.0},{"price":361.6,"size":250.0},{"price":362.0,"size":60.0},{"price":363.0,"size":40.0},{"price":363.12,"size":1000.0},{"price":365.0,"size":73.9},{"price":365.73,"size":210.0},{"price":366.0,"size":53.0},{"price":366.1,"size":100.0},{"price":366.66,"size":857.0},{"price":367.52,"size":10.0},{"price":368.688,"size":200.0},{"price":370.0,"size":258.8},{"price":371.1,"size":100.0},{"price":373.0,"size":40.0},{"price":376.0,"size":335.0},{"price":377.52,"size":10.0},{"price":377.525,"size":835.0},{"price":379.392,"size":1729.0},{"price":380.0,"size":3825.0},{"price":381.36,"size":8441.0},{"price":382.1,"size":300.0},{"price":383.224,"size":839.0},{"price":386.01,"size":200.0},{"price":387.0,"size":323.0},{"price":387.52,"size":10.0},{"price":390.0,"size":0.1},{"price":391.0,"size":0.1},{"price":392.11,"size":84.0},{"price":392.237,"size":143.0},{"price":393.9,"size":97.0},{"price":393.999,"size":437.24},{"price":394.0,"size":116.81051051},{"price":394.18,"size":13.0},{"price":394.507,"size":124.21},{"price":395.0,"size":10.015},{"price":397.576,"size":585.3},{"price":399.897,"size":80.53},{"price":400.0,"size":70.0},{"price":400.097,"size":88.0},{"price":400.298,"size":88.4},{"price":401.678,"size":106.11},{"price":401.688,"size":286.89}],"asks":[{"price":401.902,"size":117.27},{"price":402.0,"size":1432.48338339},{"price":402.1,"size":0.1},{"price":402.103,"size":82.1},{"price":402.2,"size":0.1},{"price":402.3,"size":0.1},{"price":402.303,"size":77.67},{"price":402.4,"size":0.1},{"price":402.5,"size":0.1},{"price":402.6,"size":0.1},{"price":402.7,"size":0.1},{"price":402.8,"size":0.1},{"price":402.9,"size":0.1},{"price":403.0,"size":0.2},{"price":403.1,"size":0.1},{"price":403.2,"size":0.1},{"price":403.3,"size":0.1},{"price":403.4,"size":0.1},{"price":403.5,"size":0.1},{"price":403.6,"size":0.1},{"price":403.7,"size":0.1},{"price":403.8,"size":0.1},{"price":403.9,"size":0.1},{"price":404.0,"size":0.1},{"price":405.0,"size":0.1},{"price":405.608,"size":585.6},{"price":405.666,"size":100.0},{"price":406.0,"size":0.1},{"price":406.1,"size":0.1},{"price":406.2,"size":0.2},{"price":406.3,"size":0.1},{"price":406.4,"size":0.1},{"price":406.5,"size":0.1},{"price":406.6,"size":0.1},{"price":406.7,"size":0.1},{"price":406.8,"size":0.1},{"price":406.9,"size":0.1},{"price":407.0,"size":0.1},{"price":407.1,"size":0.1},{"price":407.2,"size":0.1},{"price":407.3,"size":0.1},{"price":407.4,"size":0.1},{"price":407.5,"size":0.1},{"price":407.6,"size":0.1},{"price":407.7,"size":0.1},{"price":407.8,"size":0.1},{"price":407.9,"size":0.1},{"price":408.0,"size":0.2},{"price":408.1,"size":0.1},{"price":408.2,"size":0.2},{"price":408.3,"size":0.1},{"price":408.4,"size":0.2},{"price":408.5,"size":0.1},{"price":408.6,"size":0.2},{"price":408.7,"size":0.1},{"price":408.8,"size":0.2},{"price":408.9,"size":0.1},{"price":409.0,"size":0.2},{"price":409.1,"size":0.1},{"price":409.2,"size":0.2},{"price":409.3,"size":0.1},{"price":409.4,"size":0.2},{"price":409.5,"size":100.1},{"price":409.6,"size":0.2},{"price":409.7,"size":0.1},{"price":409.8,"size":0.2},{"price":409.9,"size":1274.1},{"price":410.0,"size":6.691},{"price":410.081,"size":378.14},{"price":410.2,"size":0.1},{"price":410.4,"size":0.1},{"price":410.6,"size":0.1},{"price":411.0,"size":0.1},{"price":411.071,"size":839.0},{"price":411.2,"size":0.1},{"price":411.4,"size":0.1},{"price":411.6,"size":0.1},{"price":411.8,"size":0.1},{"price":412.0,"size":0.1},{"price":412.2,"size":0.1},{"price":412.4,"size":0.1},{"price":413.0,"size":0.1},{"price":414.0,"size":0.2},{"price":414.001,"size":100.0},{"price":415.0,"size":99.9},{"price":416.0,"size":0.2},{"price":417.0,"size":0.1},{"price":417.4,"size":0.1},{"price":417.5,"size":0.1},{"price":417.6,"size":0.1},{"price":418.1,"size":0.1},{"price":418.2,"size":0.1},{"price":418.3,"size":0.1},{"price":418.4,"size":0.1},{"price":418.5,"size":0.1},{"price":418.6,"size":0.1},{"price":418.7,"size":0.1},{"price":418.8,"size":0.1},{"price":418.9,"size":0.1},{"price":419.2,"size":0.1},{"price":419.3,"size":0.1},{"price":419.5,"size":0.1},{"price":419.6,"size":0.1},{"price":419.66,"size":825.0},{"price":419.7,"size":0.1},{"price":419.8,"size":0.1},{"price":419.9,"size":0.1},{"price":420.0,"size":25.2750125},{"price":420.1,"size":0.1},{"price":420.2,"size":0.1},{"price":420.3,"size":1.0},{"price":420.4,"size":1.0},{"price":420.45,"size":200.0},{"price":420.5,"size":1.0},{"price":420.6,"size":1.0},{"price":420.7,"size":1.0},{"price":420.75,"size":117.65},{"price":420.8,"size":1.0},{"price":420.9,"size":1.0},{"price":421.0,"size":1.0},{"price":421.1,"size":0.1},{"price":421.2,"size":0.1},{"price":421.3,"size":0.1},{"price":421.354,"size":116.48},{"price":421.4,"size":0.1},{"price":421.5,"size":0.1},{"price":421.6,"size":0.1},{"price":421.7,"size":0.1},{"price":421.8,"size":0.1},{"price":421.9,"size":0.1},{"price":422.0,"size":0.1},{"price":422.1,"size":0.1},{"price":422.2,"size":0.1},{"price":422.3,"size":0.1},{"price":422.4,"size":0.1},{"price":422.5,"size":0.1},{"price":422.6,"size":4117.45607667},{"price":422.7,"size":0.1},{"price":422.8,"size":0.1},{"price":422.9,"size":0.1},{"price":423.0,"size":0.1},{"price":424.0,"size":0.1},{"price":425.0,"size":255.92},{"price":425.369,"size":116.37},{"price":426.0,"size":0.1},{"price":426.825,"size":19.8615},{"price":427.0,"size":0.1},{"price":428.0,"size":0.1},{"price":428.7,"size":55.19225102},{"price":429.0,"size":0.1},{"price":429.001,"size":100.0},{"price":429.9,"size":20.0},{"price":430.0,"size":1204.69527263},{"price":431.0,"size":0.1},{"price":431.64,"size":114.68},{"price":431.928,"size":114.61},{"price":432.0,"size":0.1},{"price":432.534,"size":530.0},{"price":433.0,"size":0.1},{"price":433.9,"size":20.0},{"price":434.0,"size":0.1},{"price":435.0,"size":200.2},{"price":436.0,"size":48.12454619},{"price":436.1,"size":2600.0},{"price":437.0,"size":0.1},{"price":438.0,"size":20.1},{"price":438.03,"size":0.5996},{"price":438.47,"size":10.0},{"price":439.0,"size":0.1},{"price":440.0,"size":0.2},{"price":441.0,"size":0.1},{"price":442.0,"size":20.1},{"price":443.0,"size":200.1},{"price":444.0,"size":0.1},{"price":445.0,"size":2119.93629},{"price":445.55,"size":100.0},{"price":446.0,"size":0.2},{"price":447.0,"size":0.2},{"price":448.0,"size":100.2},{"price":448.47,"size":10.0},{"price":448.855,"size":210.0},{"price":449.0,"size":100.2},{"price":449.9,"size":100.0},{"price":449.99,"size":100.0},{"price":450.0,"size":2450.45238395},{"price":450.1,"size":50.0},{"price":453.437,"size":24.32},{"price":454.894,"size":10.0},{"price":454.99,"size":100.0},{"price":455.0,"size":0.1},{"price":458.47,"size":10.0},{"price":460.0,"size":576.42949246},{"price":461.0,"size":133.0},{"price":462.0,"size":7.98},{"price":462.185,"size":23.8},{"price":463.0,"size":1501.0},{"price":464.894,"size":10.0},{"price":465.0,"size":700.1},{"price":468.47,"size":10.0},{"price":470.0,"size":28.031},{"price":471.0,"size":5.0},{"price":474.894,"size":10.0},{"price":475.0,"size":0.1},{"price":475.1,"size":100.0},{"price":476.0,"size":401.0},{"price":477.0,"size":200.0},{"price":478.47,"size":10.0},{"price":479.0,"size":1768.7},{"price":480.0,"size":457.48343531},{"price":481.0,"size":399.6},{"price":482.21,"size":580.0},{"price":484.0,"size":1085.0},{"price":484.894,"size":10.0},{"price":485.0,"size":700.1},{"price":488.0,"size":0.5},{"price":488.47,"size":10.0},{"price":488.87,"size":10.0},{"price":489.0,"size":10050.0},{"price":490.0,"size":3102.2},{"price":493.0,"size":480.0},{"price":493.84,"size":0.974},{"price":494.0,"size":54.85718567},{"price":494.451,"size":80.0},{"price":494.894,"size":10.0},{"price":495.0,"size":150.1},{"price":495.999,"size":20.24024025},{"price":498.5,"size":2498.49900884},{"price":498.855,"size":10.0},{"price":498.87,"size":10.0},{"price":498.9,"size":8.0},{"price":499.0,"size":628.5},{"price":499.1,"size":100.0},{"price":499.47,"size":9.5},{"price":499.9,"size":700.0},{"price":500.0,"size":12538.91090088},{"price":501.0,"size":127.5},{"price":510.0,"size":510.1},{"price":520.0,"size":1220.1},{"price":524.45,"size":10.0},{"price":525.0,"size":98.3},{"price":525.1,"size":100.0},{"price":530.0,"size":0.2},{"price":532.45,"size":10.0},{"price":540.0,"size":46.41404455},{"price":544.94,"size":20.0},{"price":548.0,"size":50.0},{"price":548.45,"size":10.0},{"price":549.1,"size":100.0},{"price":550.0,"size":6257.74688116},{"price":554.0,"size":10.0},{"price":555.555,"size":555.555555},{"price":560.0,"size":997.3624},{"price":572.0,"size":20.0},{"price":575.0,"size":0.1},{"price":575.1,"size":100.0},{"price":580.0,"size":100.0},{"price":590.0,"size":1905.68170578},{"price":592.61,"size":100.812},{"price":598.598,"size":241.18},{"price":599.1,"size":100.0},{"price":600.0,"size":410.6},{"price":601.0,"size":100.0},{"price":625.0,"size":100.0},{"price":625.1,"size":100.0},{"price":639.0,"size":100.0},{"price":647.0,"size":55.0},{"price":649.1,"size":100.0},{"price":650.0,"size":2538.64523714},{"price":666.666,"size":666.666666},{"price":666.999,"size":30.77464322},{"price":672.0,"size":883.0},{"price":675.1,"size":100.0},{"price":679.0,"size":1000.0},{"price":684.4,"size":25.0},{"price":685.0,"size":150.0},{"price":690.0,"size":4387.0},{"price":696.5,"size":10.0},{"price":698.0,"size":11000.0},{"price":699.0,"size":499.0},{"price":699.1,"size":100.0},{"price":700.0,"size":5251.53641859},{"price":711.13,"size":0.677},{"price":715.0,"size":81.0},{"price":720.0,"size":450.0},{"price":725.0,"size":200.0},{"price":728.0,"size":432.73010138},{"price":735.0,"size":1682.0},{"price":742.0,"size":10.0},{"price":750.0,"size":269.19121318},{"price":777.777,"size":777.777777},{"price":798.0,"size":3195.54134535},{"price":799.0,"size":150.0},{"price":800.0,"size":20000.0},{"price":853.36,"size":0.564},{"price":880.0,"size":1.0},{"price":886.0,"size":1012.46944917},{"price":888.0,"size":50.0}]}}}
1618677602.571344: {"jsonrpc":"2.0","method":"channelMessage","params":{"channel":"lightning_board_snapshot_XLM_JPY","message":{"mid_price":65.937,"bids":[{"price":25.0,"size":100.1},{"price":26.0,"size":0.2},{"price":27.0,"size":0.1},{"price":28.0,"size":1400.2},{"price":29.0,"size":0.2},{"price":30.0,"size":100.1},{"price":31.0,"size":0.2},{"price":32.0,"size":0.1},{"price":33.0,"size":0.2},{"price":34.0,"size":200.2},{"price":35.0,"size":1.1},{"price":35.49,"size":200.0},{"price":36.0,"size":101.2},{"price":37.0,"size":0.1},{"price":38.0,"size":1122.884},{"price":38.47,"size":10.424},{"price":39.0,"size":500.2},{"price":39.78,"size":30.0},{"price":40.0,"size":838.1},{"price":40.5,"size":300.0},{"price":41.0,"size":0.2},{"price":41.6,"size":50.1},{"price":41.65,"size":5000.0},{"price":42.0,"size":110.2},{"price":43.0,"size":51.315},{"price":43.001,"size":200.0},{"price":43.025,"size":30.0},{"price":43.729,"size":109.21627},{"price":44.0,"size":110.2},{"price":44.001,"size":20.0},{"price":44.1,"size":23.0},{"price":44.494,"size":100.0},{"price":45.0,"size":2803.0},{"price":45.105,"size":300.0},{"price":45.5,"size":6500.0},{"price":45.6,"size":100.0},{"price":45.877,"size":700.0},{"price":46.0,"size":1100.0},{"price":46.1,"size":20.0},{"price":46.16,"size":8.687},{"price":46.82,"size":200.0},{"price":47.0,"size":11.105},{"price":47.23,"size":200.0},{"price":47.5,"size":502.0},{"price":48.0,"size":150.0},{"price":48.01,"size":1002.0},{"price":48.767,"size":441.84},{"price":49.35,"size":300.0},{"price":49.5,"size":2.0},{"price":50.0,"size":4255.0},{"price":50.009,"size":5.0},{"price":50.1,"size":5000.0},{"price":50.13,"size":10.0},{"price":50.5,"size":102.0},{"price":51.0,"size":1.198},{"price":51.001,"size":10000.0},{"price":51.17,"size":30.0},{"price":51.442,"size":100.0},{"price":51.5,"size":3.009},{"price":52.0,"size":5151.4985},{"price":52.1,"size":400.0},{"price":52.2,"size":100.0},{"price":52.31,"size":1000.0},{"price":52.317,"size":50.0},{"price":52.5,"size":52.0},{"price":52.592,"size":0.1},{"price":53.0,"size":2363.827},{"price":53.05,"size":1.3},{"price":53.26,"size":100.0},{"price":53.4,"size":30.0},{"price":53.5,"size":1102.0},{"price":53.64,"size":300.0},{"price":54.0,"size":2020.0},{"price":54.18,"size":0.04},{"price":54.37,"size":400.0},{"price":54.5,"size":2.0},{"price":55.0,"size":19621.391},{"price":55.2,"size":182.0},{"price":55.39,"size":7.24},{"price":55.5,"size":22102.0},{"price":55.72,"size":1800.0},{"price":55.8,"size":10.0},{"price":56.0,"size":10025.0},{"price":56.23,"size":400.0},{"price":56.3,"size":5205.0},{"price":56.5,"size":400.0},{"price":57.0,"size":5007.5},{"price":57.1,"size":501.0},{"price":57.15,"size":6010.0},{"price":57.997,"size":10.0},{"price":58.0,"size":15612.0},{"price":58.01,"size":100000.0},{"price":58.2,"size":50.0},{"price":58.4,"size":2000.0},{"price":58.45,"size":200.0},{"price":58.5,"size":19.0},{"price":58.95,"size":200.0},{"price":59.0,"size":429.2122373},{"price":59.1,"size":300.0},{"price":59.5,"size":201.6},{"price":59.6,"size":500.0},{"price":60.0,"size":13065.32036},{"price":60.1,"size":10485.0},{"price":60.2,"size":167.0},{"price":60.251,"size":5.0},{"price":60.43,"size":30.6998179},{"price":60.5,"size":1175.0},{"price":60.57,"size":600.0},{"price":60.6,"size":800.0},{"price":60.7,"size":11.0},{"price":61.0,"size":14547.5149792},{"price":61.1,"size":200.0},{"price":61.2,"size":5.0},{"price":61.5,"size":10550.0},{"price":61.57,"size":60.0},{"price":61.8,"size":50.0},{"price":62.0,"size":23636.1924108},{"price":62.01,"size":1703.0},{"price":62.1,"size":100.0},{"price":62.25,"size":49.0},{"price":62.273,"size":8149.0},{"price":62.38,"size":2019.9377},{"price":62.4,"size":799.18269},{"price":62.5,"size":321.688},{"price":62.51,"size":10.0},{"price":62.578,"size":5.0},{"price":62.6,"size":2000.0},{"price":62.744,"size":20.025},{"price":62.826,"size":7972.0},{"price":62.995,"size":91.3},{"price":63.0,"size":7307.9606667},{"price":63.001,"size":1800.0},{"price":63.1,"size":20301.0},{"price":63.11,"size":100.0},{"price":63.31,"size":2010.0},{"price":63.5,"size":100.0},{"price":63.637,"size":115.8},{"price":63.917,"size":108.69},{"price":63.95,"size":476.0},{"price":64.0,"size":2818.6},{"price":64.01,"size":150.0},{"price":64.1,"size":2250.0},{"price":64.2,"size":2000.5},{"price":64.316,"size":101.13},{"price":64.413,"size":7994.0},{"price":64.5,"size":10011.0},{"price":64.627,"size":16225.0},{"price":64.701,"size":96.7},{"price":64.78,"size":500.0},{"price":64.8,"size":9650.0},{"price":64.81,"size":1000.0},{"price":64.844,"size":100.0},{"price":64.998,"size":2.0},{"price":65.0,"size":29781.4852782},{"price":65.022,"size":31911.0},{"price":65.1,"size":1814.0572},{"price":65.101,"size":117.9},{"price":65.266,"size":83.5},{"price":65.442,"size":81387.0},{"price":65.526,"size":899.74},{"price":65.611,"size":677.0},{"price":65.692,"size":4139.0},{"price":65.707,"size":7928.0},{"price":65.713,"size":3791.0},{"price":65.738,"size":617.1},{"price":65.825,"size":997.0},{"price":65.826,"size":2273.01}],"asks":[{"price":66.049,"size":534.0},{"price":66.05,"size":2505.618},{"price":66.133,"size":948.15},{"price":66.254,"size":7928.0},{"price":66.271,"size":631.9},{"price":66.516,"size":3030.68},{"price":66.517,"size":811.4},{"price":66.584,"size":107.7},{"price":66.659,"size":32027.0},{"price":66.749,"size":112.62},{"price":66.819,"size":122.23},{"price":66.87,"size":299.1},{"price":67.0,"size":21859.4649274},{"price":67.085,"size":8127.0},{"price":67.132,"size":15699.0},{"price":67.275,"size":105.64},{"price":67.614,"size":89.0},{"price":67.8,"size":99.0},{"price":67.87,"size":97.91},{"price":67.95,"size":100.0},{"price":68.0,"size":50.0},{"price":68.244,"size":112.7},{"price":68.253,"size":105.0},{"price":68.4,"size":3983.0},{"price":68.465,"size":7842.0},{"price":68.5,"size":200.0},{"price":68.569,"size":200.0},{"price":68.75,"size":500.0},{"price":69.0,"size":2253.0},{"price":69.3,"size":5999.0},{"price":69.55,"size":6000.0},{"price":69.738,"size":99.3075},{"price":69.795,"size":4000.0},{"price":69.871,"size":5000.0},{"price":70.0,"size":11653.6638107},{"price":70.1,"size":712.704576},{"price":70.2,"size":7100.0},{"price":70.23,"size":5000.0},{"price":70.237,"size":2500.0},{"price":70.32,"size":2000.0},{"price":70.4,"size":1000.0},{"price":70.49,"size":20.0},{"price":70.5,"size":2600.0},{"price":70.569,"size":199.12},{"price":70.8,"size":450.0},{"price":70.85,"size":498.948},{"price":70.9,"size":4760.0},{"price":70.942,"size":598.8011989},{"price":71.0,"size":36229.05},{"price":71.1,"size":500.0},{"price":71.2,"size":6250.0},{"price":71.24,"size":5002.5},{"price":71.28,"size":500.0},{"price":71.314,"size":0.458},{"price":71.32,"size":2000.0},{"price":71.5,"size":5870.0},{"price":71.6,"size":250.0},{"price":71.677,"size":9.0},{"price":71.8,"size":5300.0},{"price":71.804,"size":15.521},{"price":71.98,"size":81.9},{"price":72.0,"size":13411.4003199},{"price":72.15,"size":38.8383333},{"price":72.4,"size":48034.05044},{"price":72.46,"size":14.9827},{"price":72.5,"size":4495.0},{"price":72.6,"size":99.0},{"price":72.765,"size":5000.0},{"price":72.981,"size":683.06},{"price":73.0,"size":6352.6448612},{"price":73.096,"size":681.98},{"price":73.101,"size":681.94},{"price":73.29,"size":57201.694009},{"price":73.351,"size":1299.0},{"price":73.4,"size":8000.0},{"price":73.468,"size":678.53},{"price":73.5,"size":2829.9},{"price":73.569,"size":677.6},{"price":73.579,"size":677.51},{"price":73.6,"size":5000.0},{"price":73.65,"size":2000.0},{"price":73.957,"size":44046.085926},{"price":74.0,"size":997.7041439},{"price":74.01,"size":100.0},{"price":74.1,"size":1739.3},{"price":74.49,"size":400.0},{"price":74.5,"size":5070.0},{"price":74.69,"size":233.0},{"price":74.71,"size":676.0},{"price":74.78,"size":10000.0},{"price":74.85,"size":3996.0},{"price":74.9,"size":10003.7016532},{"price":74.92,"size":35.0},{"price":74.99,"size":800.0},{"price":75.0,"size":20568.2355105},{"price":75.1,"size":1000.0},{"price":75.555,"size":350.0},{"price":75.6,"size":5.0},{"price":75.78,"size":470.0},{"price":76.0,"size":4909.88},{"price":76.26,"size":200.0},{"price":76.292,"size":100.0},{"price":76.83,"size":40000.0},{"price":77.0,"size":7683.56},{"price":77.1,"size":100.0},{"price":77.5,"size":1446.0},{"price":77.777,"size":100.0},{"price":78.0,"size":6127.9},{"price":78.1,"size":100.0},{"price":78.3,"size":2000.0},{"price":78.5,"size":5000.0},{"price":79.0,"size":219990.601},{"price":79.05,"size":1300.0},{"price":79.1,"size":100.0},{"price":79.76,"size":6.033},{"price":80.0,"size":11272.581954},{"price":80.1,"size":100.0},{"price":81.0,"size":1.0},{"price":82.0,"size":598.0},{"price":82.5,"size":5000.0},{"price":83.0,"size":70.0},{"price":85.0,"size":43960.0},{"price":87.6,"size":5000.0},{"price":88.0,"size":152000.0},{"price":89.9,"size":299.7},{"price":90.0,"size":12.1},{"price":91.0,"size":100.0},{"price":91.264,"size":52.25972},{"price":91.5,"size":5000.0},{"price":94.53,"size":100.0},{"price":95.0,"size":10.0},{"price":95.71,"size":5.028},{"price":97.77,"size":10000.0},{"price":99.0,"size":8978.0},{"price":99.47,"size":1440.0},{"price":100.0,"size":3530.1},{"price":105.6,"size":4960.0},{"price":110.0,"size":998.0},{"price":114.85,"size":4.19},{"price":120.0,"size":1829.7339845},{"price":126.35,"size":100.0},{"price":130.0,"size":3052.0},{"price":135.26,"size":100.0}]}}}
1618677602.577065: {"jsonrpc":"2.0","method":"channelMessage","params":{"channel":"lightning_board_FX_BTC_JPY","message":{"mid_price":7185722.0,"bids":[{"price":7128659.0,"size":0.05},{"price":7126840.0,"size":0.05}],"asks":[{"price":7186916.0,"size":0.04},{"price":7204375.0,"size":0.11},{"price":7213182.0,"size":0.05}]}}}
1618677602.577204: {"jsonrpc":"2.0","method":"channelMessage","params":{"channel":"lightning_ticker_XLM_JPY","message":{"product_code":"XLM_JPY","state":"RUNNING","timestamp":"2021-04-17T16:40:02.427294Z","tick_id":4215961,"best_bid":65.826,"best_ask":66.05,"best_bid_size":2273.01,"best_ask_size":2505.618,"total_bid_depth":598685.4211101,"total_ask_depth":1038230.91256850,"market_bid_size":0.0,"market_ask_size":0.0,"ltp":65.902,"volume":2182293.365166500000,"volume_by_product":2182293.365166500000}}}
1618677602.581151: {"jsonrpc":"2.0","method":"channelMessage","params":{"channel":"lightning_board_XLM_JPY","message":{"mid_price":65.938,"bids":[],"asks":[{"price":67.0,"size":21859.4649274},{"price":66.049,"size":0.0}]}}}
1618677602.581302: {"jsonrpc":"2.0","method":"channelMessage","params":{"channel":"lightning_board_ETH_JPY","message":{"mid_price":258735.0,"bids":[],"asks":[{"price":258831.0,"size":1.0},{"price":260298.0,"size":5.607402}]}}}
1618677602.581341: {"jsonrpc":"2.0","method":"channelMessage","params":{"channel":"lightning_board_XRP_JPY","message":{"mid_price":172.94,"bids":[{"price":172.76,"size":430.36}],"asks":[{"price":173.29,"size":0.0}]}}}
1618677602.678394: {"jsonrpc":"2.0","method":"channelMessage","params":{"channel":"lightning_board_FX_BTC_JPY","message":{"mid_price":7185722.0,"bids":[{"price":7183173.0,"size":0.1075}],"asks":[{"price":7215025.0,"size":0.05}]}}}
1618677602.712268: {"jsonrpc":"2.0","method":"channelMessage","params":{"channel":"lightning_board_XLM_JPY","message":{"mid_price":65.93,"bids":[],"asks":[{"price":66.035,"size":534.0}]}}}
1618677602.7123861: {"jsonrpc":"2.0","method":"channelMessage","params":{"channel":"lightning_board_XRP_JPY","message":{"mid_price":172.94,"bids":[{"price":172.32,"size":2991.0}],"asks":[]}}}
1618677602.71244: {"jsonrpc":"2.0","method":"channelMessage","params":{"channel":"lightning_board_ETH_JPY","message":{"mid_price":258735.0,"bids":[{"price":258147.0,"size":2.624}],"asks":[]}}}
1618677602.7124832: {"jsonrpc":"2.0","method":"channelMessage","params":{"channel":"lightning_executions_FX_BTC_JPY","message":[{"id":2207054801,"side":"SELL","price":7185233.0,"size":0.03,"exec_date":"2021-04-17T16:40:02.5772212Z","buy_child_order_acceptance_id":"JRF20210417-163718-130186","sell_child_order_acceptance_id":"JRF20210417-164002-054085"}]}}
1618677602.7931: {"jsonrpc":"2.0","method":"channelMessage","params":{"channel":"lightning_ticker_FX_BTC_JPY","message":{"product_code":"FX_BTC_JPY","state":"RUNNING","timestamp":"2021-04-17T16:40:02.5772212Z","tick_id":42420638,"best_bid":7185233.0,"best_ask":7186212.0,"best_bid_size":0.020000,"best_ask_size":0.01,"total_bid_depth":2432.163046120000,"total_ask_depth":2472.215485100000,"market_bid_size":0.0,"market_ask_size":0.0,"ltp":7185233.0,"volume":2105.814486030000,"volume_by_product":2105.814486030000}}}
1618677602.793212: {"jsonrpc":"2.0","method":"channelMessage","params":{"channel":"lightning_board_FX_BTC_JPY","message":{"mid_price":7185722.0,"bids":[{"price":7185233.0,"size":0.02}],"asks":[]}}}
1618677602.809068: {"jsonrpc":"2.0","method":"channelMessage","params":{"channel":"lightning_ticker_ETH_JPY","message":{"product_code":"ETH_JPY","state":"RUNNING","timestamp":"2021-04-17T16:40:02.6523247Z","tick_id":10943399,"best_bid":258640.0,"best_ask":258830.0,"best_bid_size":0.100,"best_ask_size":0.30000000,"total_bid_depth":2389.433879700000,"total_ask_depth":2109.68598510,"market_bid_size":0.0,"market_ask_size":0.0,"ltp":258757.0,"volume":18068.878445400000,"volume_by_product":18068.878445400000}}}
1618677602.809181: {"jsonrpc":"2.0","method":"channelMessage","params":{"channel":"lightning_board_ETH_JPY","message":{"mid_price":258735.0,"bids":[{"price":258607.0,"size":3.872},{"price":258118.0,"size":1.270006},{"price":258113.0,"size":2.1163328}],"asks":[{"price":258830.0,"size":0.3},{"price":258981.0,"size":3.872}]}}}
1618677602.8132858: {"jsonrpc":"2.0","method":"channelMessage","params":{"channel":"lightning_board_BTC_USD","message":{"mid_price":60532.85,"bids":[{"price":60320.0,"size":0.25},{"price":60201.99,"size":0.39},{"price":60492.48,"size":0.02}],"asks":[{"price":60565.12,"size":0.11},{"price":60837.46,"size":0.39}]}}}
1618677602.813418: {"jsonrpc":"2.0","method":"channelMessage","params":{"channel":"lightning_board_XRP_JPY","message":{"mid_price":172.94,"bids":[{"price":172.32,"size":0.0}],"asks":[]}}}
1618677602.901949: {"jsonrpc":"2.0","method":"channelMessage","params":{"channel":"lightning_board_FX_BTC_JPY","message":{"mid_price":7185722.0,"bids":[],"asks":[{"price":7193597.0,"size":0.01}]}}}
1618677603.012266: {"jsonrpc":"2.0","method":"channelMessage","params":{"channel":"lightning_board_FX_BTC_JPY","message":{"mid_price":7185722.0,"bids":[{"price":7124805.0,"size":0.05}],"asks":[]}}}
1618677603.123412: {"jsonrpc":"2.0","method":"channelMessage","params":{"channel":"lightning_board_FX_BTC_JPY","message":{"mid_price":7185722.0,"bids":[],"asks":[{"price":7274374.0,"size":0.0}]}}}
1618677603.163145: {"jsonrpc":"2.0","method":"channelMessage","params":{"channel":"lightning_ticker_XLM_JPY","message":{"product_code":"XLM_JPY","state":"RUNNING","timestamp":"2021-04-17T16:40:02.9696417Z","tick_id":4215963,"best_bid":65.91,"best_ask":66.035,"best_bid_size":2505.618,"best_ask_size":534.0,"total_bid_depth":601191.0391101,"total_ask_depth":1038764.91256850,"market_bid_size":0.0,"market_ask_size":0.0,"ltp":65.902,"volume":2182293.365166500000,"volume_by_product":2182293.365166500000}}}
1618677603.16326: {"jsonrpc":"2.0","method":"channelMessage","params":{"channel":"lightning_board_XLM_JPY","message":{"mid_price":65.972,"bids":[{"price":65.91,"size":2505.618}],"asks":[]}}}
1618677603.1671622: {"jsonrpc":"2.0","method":"channelMessage","params":{"channel":"lightning_board_ETH_JPY","message":{"mid_price":258735.0,"bids":[{"price":258147.0,"size":2.176}],"asks":[]}}}
1618677603.167273: {"jsonrpc":"2.0","method":"channelMessage","params":{"channel":"lightning_ticker_XRP_JPY","message":{"product_code":"XRP_JPY","state":"RUNNING","timestamp":"2021-04-17T16:40:02.9852977Z","tick_id":8063024,"best_bid":172.84,"best_ask":173.04,"best_bid_size":1503.37,"best_ask_size":1.0,"total_bid_depth":1518552.11693700,"total_ask_depth":2534131.72723400,"market_bid_size":0.0,"market_ask_size":0.0,"ltp":173.14,"volume":8345521.391062000000,"volume_by_product":8345521.391062000000}}}
1618677603.168343: {"jsonrpc":"2.0","method":"channelMessage","params":{"channel":"lightning_board_XRP_JPY","message":{"mid_price":172.94,"bids":[{"price":172.43,"size":0.0}],"asks":[{"price":173.52,"size":0.0},{"price":173.1,"size":1.0}]}}}
1618677603.247741: {"jsonrpc":"2.0","method":"channelMessage","params":{"channel":"lightning_board_FX_BTC_JPY","message":{"mid_price":7185722.0,"bids":[],"asks":[{"price":7186234.0,"size":0.0}]}}}
1618677603.271646: {"jsonrpc":"2.0","method":"channelMessage","params":{"channel":"lightning_board_ETH_JPY","message":{"mid_price":258735.0,"bids":[],"asks":[{"price":258830.0,"size":1.3}]}}}
1618677603.351995: {"jsonrpc":"2.0","method":"channelMessage","params":{"channel":"lightning_ticker_FX_BTC_JPY","message":{"product_code":"FX_BTC_JPY","state":"RUNNING","timestamp":"2021-04-17T16:40:03.2562697Z","tick_id":42420644,"best_bid":7185233.0,"best_ask":7186212.0,"best_bid_size":0.020000,"best_ask_size":0.01,"total_bid_depth":2432.253046120000,"total_ask_depth":2472.165485100000,"market_bid_size":0.0,"market_ask_size":0.0,"ltp":7185233.0,"volume":2105.814486030000,"volume_by_product":2105.814486030000}}}
1618677603.357213: {"jsonrpc":"2.0","method":"channelMessage","params":{"channel":"lightning_board_FX_BTC_JPY","message":{"mid_price":7185722.0,"bids":[{"price":7183260.0,"size":0.04}],"asks":[{"price":7196226.0,"size":0.0}]}}}
1618677603.376584: {"jsonrpc":"2.0","method":"channelMessage","params":{"channel":"lightning_ticker_ETH_JPY","message":{"product_code":"ETH_JPY","state":"RUNNING","timestamp":"2021-04-17T16:40:03.1727738Z","tick_id":10943404,"best_bid":258640.0,"best_ask":258830.0,"best_bid_size":0.100,"best_ask_size":1.30000000,"total_bid_depth":2390.085879700000,"total_ask_depth":2110.68598510,"market_bid_size":0.0,"market_ask_size":0.0,"ltp":258757.0,"volume":18068.878445400000,"volume_by_product":18068.878445400000}}}
1618677603.385201: {"jsonrpc":"2.0","method":"channelMessage","params":{"channel":"lightning_board_ETH_JPY","message":{"mid_price":258735.0,"bids":[{"price":258623.0,"size":1.0},{"price":258587.0,"size":3.575}],"asks":[]}}}
1618677603.385322: {"jsonrpc":"2.0","method":"channelMessage","params":{"channel":"lightning_board_XRP_JPY","message":{"mid_price":172.94,"bids":[{"price":172.16,"size":0.0}],"asks":[]}}}
1618677603.3853838: {"jsonrpc":"2.0","method":"channelMessage","params":{"channel":"lightning_ticker_BTC_USD","message":{"product_code":"BTC_USD","state":"RUNNING","timestamp":"2021-04-17T16:40:03.1727738Z","tick_id":5565399,"best_bid":60515.69,"best_ask":60550.02,"best_bid_size":0.099,"best_ask_size":0.12,"total_bid_depth":8.67841782,"total_ask_depth":6.69349080,"market_bid_size":0.0,"market_ask_size":0.0,"ltp":60201.0,"volume":55.459921930000,"volume_by_product":55.459921930000}}}
1618677603.3854542: {"jsonrpc":"2.0","method":"channelMessage","params":{"channel":"lightning_board_BTC_USD","message":{"mid_price":60532.85,"bids":[],"asks":[{"price":60591.82,"size":0.0}]}}}
1618677603.422979: {"jsonrpc":"2.0","method":"channelMessage","params":{"channel":"lightning_executions_MONA_JPY","message":[{"id":2207056271,"side":"BUY","price":401.902,"size":117.27,"exec_date":"2021-04-17T16:40:03.3290276Z","buy_child_order_acceptance_id":"JRF20210417-164003-122924","sell_child_order_acceptance_id":"JRF20210417-163948-075507"}]}}
1618677603.487205: {"jsonrpc":"2.0","method":"channelMessage","params":{"channel":"lightning_board_BTC_USD","message":{"mid_price":60530.35,"bids":[{"price":60199.79,"size":0.01},{"price":60490.53,"size":0.1902},{"price":60481.46,"size":0.1902},{"price":60225.96,"size":0.002},{"price":60496.3,"size":0.096}],"asks":[{"price":60545.01,"size":0.1902}]}}}
1618677603.487345: {"jsonrpc":"2.0","method":"channelMessage","params":{"channel":"lightning_ticker_MONA_JPY","message":{"product_code":"MONA_JPY","state":"RUNNING","timestamp":"2021-04-17T16:40:03.3290276Z","tick_id":629667,"best_bid":401.902,"best_ask":402.0,"best_bid_size":182.73,"best_ask_size":1432.48338339,"total_bid_depth":82619.67550763,"total_ask_depth":129436.93901728,"market_bid_size":0.0,"market_ask_size":0.0,"ltp":401.902,"volume":1030550.609113290000,"volume_by_product":1030550.609113290000}}}
1618677603.487419: {"jsonrpc":"2.0","method":"channelMessage","params":{"channel":"lightning_board_MONA_JPY","message":{"mid_price":401.951,"bids":[{"price":401.902,"size":182.73}],"asks":[{"price":401.902,"size":0.0}]}}}
