1649290078.4007192: {"action":"snapshot","arg":{"instType":"sp","channel":"ticker","instId":"GOGUSDT"},"data":[{"instId":"GOGUSDT","last":"0.5555","open24h":"0.5563","high24h":"0.5708","low24h":"0.5508","bestBid":"0.554700","bestAsk":"0.559000","baseVolume":"134610.9070","quoteVolume":"78726.5933","ts":1649290078350,"labeId":0}]}
1649290078.4928792: {"action":"snapshot","arg":{"instType":"sp","channel":"ticker","instId":"SUNUSDT"},"data":[{"instId":"SUNUSDT","last":"0.01507","open24h":"0.01521","high24h":"0.01559","low24h":"0.01481","bestBid":"0.015030","bestAsk":"0.015070","baseVolume":"11682349","quoteVolume":"180214","ts":1649290078446,"labeId":0}]}
1649290078.553119: {"action":"snapshot","arg":{"instType":"sp","channel":"ticker","instId":"STGUSDT"},"data":[{"instId":"STGUSDT","last":"2.881","open24h":"3.045","high24h":"3.164","low24h":"2.757","bestBid":"2.861000","bestAsk":"2.917000","baseVolume":"35327.890","quoteVolume":"111744.124","ts":1649290078509,"labeId":0}]}
1649290078.568038: {"action":"snapshot","arg":{"instType":"sp","channel":"ticker","instId":"CULTUSDT"},"data":[{"instId":"CULTUSDT","last":"0.00003507","open24h":"0.00004340","high24h":"0.00004397","low24h":"0.00003500","bestBid":"0.000036","bestAsk":"0.000036","baseVolume":"13526772930","quoteVolume":"557436","ts":1649290078524,"labeId":0}]}
1649290078.6181052: {"action":"update","arg":{"instType":"sp","channel":"books","instId":"HOTUSDT"},"data":[{"asks":[["0.0056180","0"],["0.0056220","0"],["0.0056230","0"],["0.0056240","0"],["0.0056250","0"],["0.0056260","0"],["0.0056270","0"],["0.0056280","8459.1000"],["0.0056290","281050.6500"],["0.0056300","32810.4000"],["0.0056310","41896.8000"],["0.0056330","121222.3500"],["0.0056340","163386.0000"],["0.0056360","260112.6000"],["0.0056400","119829.6000"],["0.0056410","226707.3000"],["0.0056550","122763.6000"],["0.0056580","176619.1500"],["0.0056590","32088.6000"],["0.0056600","641539.3500"],["0.0056760","355759.2000"],["0.0056770","304128.9000"],["0.0056780","4524.3000"],["0.0056790","288587.7000"],["0.0056800","800000.0000"],["0.0056810","63108.9000"],["0.0058960","0"],["0.0059000","5750.0000"],["0.0059020","0"],["0.0059060","7750.0000"],["0.0059080","0"],["0.0059120","3750.0000"],["0.0059140","0"],["0.0059180","4750.0000"],["0.0059200","0"],["0.0059240","4250.0000"],["0.0059260","0"],["0.0059300","8750.0000"],["0.0059320","0"],["0.0059360","12250.0000"],["0.0059380","0"],["0.0059420","6250.0000"],["0.0059440","0"],["0.0059480","8250.0000"],["0.0059500","0"],["0.0059540","11250.0000"],["0.0059560","0"],["0.0059600","2750.0000"],["0.0059620","0"],["0.0059660","3250.0000"],["0.0059680","0"],["0.0059720","9250.0000"],["0.0059740","0"],["0.0059780","10250.0000"],["0.0059800","0"],["0.0059840","11750.0000"],["0.0059860","0"],["0.0059900","9750.0000"],["0.0059920","0"],["0.0059960","6750.0000"],["0.0059980","0"],["0.0060020","5250.0000"],["0.0060040","0"],["0.0060080","10750.0000"],["0.0060100","0"],["0.0060140","7250.0000"]],"bids":[["0.0056100","87354.0000"],["0.0056090","226169.1000"],["0.0056080","292088.7000"],["0.0056070","0"],["0.0056060","153256.5000"],["0.0056050","131400.0000"],["0.0056040","180046.8000"],["0.0056030","33229.8900"],["0.0056010","553649.4000"],["0.0055990","200233.3500"],["0.0055980","30743.5500"],["0.0055970","125183.2500"],["0.0055960","800000.0000"],["0.0055940","361155.6000"],["0.0055900","139725.0000"],["0.0055890","765793.8000"],["0.0055880","779703.3000"],["0.0055810","260358.3000"],["0.0055790","243286.2000"],["0.0055760","94140.9000"],["0.0055740","15548.8500"],["0.0055730","42040.8000"],["0.0055630","800000.0000"],["0.0055620","0"],["0.0055510","0"],["0.0055500","0"],["0.0055490","0"],["0.0055480","0"],["0.0053380","10750.0000"],["0.0053330","0"],["0.0053320","5750.0000"],["0.0053270","0"],["0.0053260","10250.0000"],["0.0053210","0"],["0.0053200","6750.0000"],["0.0053150","0"],["0.0053140","8250.0000"],["0.0053090","0"],["0.0053080","3750.0000"],["0.0053030","0"],["0.0053020","11250.0000"],["0.0052970","0"],["0.0052960","7750.0000"],["0.0052910","0"],["0.0052900","3250.0000"],["0.0052850","0"],["0.0052840","5250.0000"],["0.0052790","0"],["0.0052780","8750.0000"],["0.0052730","0"],["0.0052720","4750.0000"],["0.0052670","0"],["0.0052660","7250.0000"],["0.0052610","0"],["0.0052600","9750.0000"],["0.0052550","0"],["0.0052540","12250.0000"],["0.0052490","0"],["0.0052480","4250.0000"],["0.0052430","0"],["0.0052420","9250.0000"],["0.0052370","0"],["0.0052360","11750.0000"],["0.0052310","0"],["0.0052300","6250.0000"],["0.0052250","0"],["0.0052240","2750.0000"],["0.0052190","0"]],"checksum":-1479185791,"ts":"1649290078587"}]}
1649290078.7026591: {"action":"update","arg":{"instType":"sp","channel":"books","instId":"GOGUSDT"},"data":[{"asks":[["0.5625","8.8899"],["0.5631","8.8804"],["0.5637","8.8710"],["0.5643","14.3333"],["0.5649","8.8521"],["0.5655","2342.8000"],["0.5661","13.0000"],["0.5667","8.8240"],["0.5673","10.3333"],["0.5679","12.3333"],["0.5685","9.6667"],["0.5703","11.0000"],["0.5715","13.6667"],["0.5721","16.3333"],["0.5727","15.6667"],["0.5733","15.0000"],["0.5739","11.6667"]],"bids":[["0.5512","12.4000"],["0.5500","11.6667"],["0.5494","9.1018"],["0.5488","9.1118"],["0.5482","3672.9000"],["0.5470","10.3333"],["0.5452","15.0000"],["0.5446","14.3333"],["0.5440","13.0000"],["0.5434","13.6667"],["0.5428","16.3333"],["0.5422","12.3333"],["0.5416","15.6667"],["0.5410","9.2431"]],"checksum":-177917114,"ts":"1649290078676"}]}
1649290078.7439628: {"action":"update","arg":{"instType":"sp","channel":"books","instId":"STGUSDT"},"data":[{"asks":[["3.034","2.047"],["3.037","3.062"],["3.043","2.554"],["3.046","3.569"],["3.049","3.964"],["3.052","1.920"],["3.055","1.793"],["3.061","3.442"],["3.064","2.301"],["3.067","1.631"],["3.070","1.630"],["3.073","2.428"],["3.076","1.626"],["3.082","1.623"],["3.085","3.315"],["3.088","2.808"],["3.091","3.188"],["3.094","2.935"],["3.097","2.681"],["3.100","2.174"]],"bids":[["2.741","1.892"],["2.738","20.075"],["2.735","1.829"],["2.732","98.993"],["2.729","1.833"],["2.726","75.036"],["2.720","2.108"],["2.717","2.646"],["2.714","1.843"],["2.711","2.862"],["2.708","1.847"],["2.705","2.969"],["2.702","1.851"],["2.699","2.431"],["2.696","92.954"],["2.690","2.754"],["2.684","2.538"],["2.672","3.077"]],"checksum":-1083168126,"ts":"1649290078717"}]}
1649290078.7482939: {"action":"update","arg":{"instType":"sp","channel":"books","instId":"AVAXUSDT"},"data":[{"asks":[["83.0312","0"],["83.1215","0"],["83.1315","0"],["83.1415","0"],["83.1515","173.5790"],["83.1615","17.7310"],["83.1715","15.6730"],["83.1815","2.8280"],["83.2115","180.0000"],["83.2215","107.7930"],["83.2315","179.7250"],["83.2415","35.0000"],["83.2515","52.4160"],["83.2715","61.2430"],["83.2915","8.0430"],["83.3515","132.0900"],["83.3815","2.5270"],["83.4015","0"],["83.4115","5.1730"],["83.4715","0"],["83.4815","180.0000"],["83.6415","45.0590"],["83.6615","0.2870"],["83.6715","8.0010"],["83.6815","180.0000"],["83.6915","2.4220"],["83.7015","2.4150"],["88.0066","0"],["88.0383","0.3167"],["88.0897","0"],["88.1214","0.5167"],["88.1728","0"],["88.2045","0.6167"],["88.2559","0"],["88.2876","0.5500"],["88.3390","0"],["88.3707","0.3833"],["88.4221","0"],["88.4538","0.4833"],["88.5052","0"],["88.5369","0.1833"],["88.5883","0"],["88.6200","0.8167"],["88.6714","0"],["88.7031","0.4167"],["88.7545","0"],["88.7862","0.2833"],["88.8376","0"],["88.8693","0.6833"],["88.9207","0"],["88.9524","0.2167"],["89.0038","0"],["89.0355","0.4500"],["89.0869","0"],["89.1186","0.2500"],["89.1700","0"],["89.2017","0.6500"],["89.2531","0"],["89.2848","0.7167"],["89.3362","0"],["89.3679","0.7833"],["89.4193","0"],["89.4510","0.5833"],["89.5024","0"],["89.5341","0.7500"],["89.5855","0"],["89.6172","0.3500"]],"bids":[["82.9585","103.6840"],["82.9485","136.2690"],["82.9385","10.5910"],["82.9285","27.4960"],["82.9185","100.1280"],["82.9085","36.5890"],["82.8985","26.8450"],["82.8885","0"],["82.8785","43.9460"],["82.8685","146.2090"],["82.8585","3.2130"],["82.8485","128.5970"],["82.8385","180.0000"],["82.8285","20.0550"],["82.8185","46.9420"],["82.8085","73.6890"],["82.7985","164.8010"],["82.7785","31.7450"],["82.7685","9.7790"],["82.7585","16.5760"],["82.7385","152.2360"],["82.7285","173.2640"],["82.7185","134.2040"],["82.6985","92.0220"],["82.6685","180.0000"],["82.5985","79.6460"],["82.5585","138.6420"],["82.5485","98.0630"],["82.5385","143.5140"],["82.5185","170.6740"],["82.4785","122.6260"],["82.4485","0"],["82.4385","0"],["78.0717","0.4167"],["78.0435","0"],["77.9886","0.5833"],["77.9604","0"],["77.9055","0.5167"],["77.8773","0"],["77.8224","0.2167"],["77.7942","0"],["77.7393","0.7833"],["77.7111","0"],["77.6562","0.7500"],["77.6280","0"],["77.5731","0.1833"],["77.5449","0"],["77.4900","0.4833"],["77.4618","0"],["77.4069","0.3500"],["77.3787","0"],["77.3238","0.6833"],["77.2956","0"],["77.2407","0.3167"],["77.2125","0"],["77.1576","0.2833"],["77.1294","0"],["77.0745","0.6500"],["77.0463","0"],["76.9914","0.6167"],["76.9632","0"],["76.9083","0.3833"],["76.8801","0"],["76.8252","0.7167"],["76.7970","0"],["76.7421","0.2500"],["76.7139","0"],["76.6590","0.4500"],["76.6308","0"],["76.5759","0.5500"],["76.5477","0"],["76.4928","0.8167"],["76.4646","0"]],"checksum":-150329699,"ts":"1649290078722"}]}
1649290078.780628: {"action":"update","arg":{"instType":"sp","channel":"books","instId":"CULTUSDT"},"data":[{"asks":[["0.00003614","493333"],["0.00003618","413333"],["0.00003622","306667"],["0.00003626","173333"],["0.00003630","520000"],["0.00003634","386667"],["0.00003638","653333"],["0.00003642","146667"],["0.00003646","500390"],["0.00003650","253333"],["0.00003654","573333"],["0.00003658","546667"],["0.00003662","466667"],["0.00003666","440000"],["0.00003670","333333"],["0.00003674","280000"],["0.00003678","626667"],["0.00003682","600000"],["0.00003686","360000"],["0.00003690","200000"]],"bids":[["0.00003471","493333"],["0.00003467","1581897"],["0.00003463","600000"],["0.00003459","573333"],["0.00003455","668154"],["0.00003451","360000"],["0.00003447","413333"],["0.00003443","626667"],["0.00003439","466667"],["0.00003435","226667"],["0.00003431","146667"],["0.00003427","200000"],["0.00003423","546667"],["0.00003419","333333"],["0.00003415","253333"],["0.00003411","386667"],["0.00003407","653333"],["0.00003403","520000"],["0.00003399","173333"],["0.00003395","306667"]],"checksum":373962595,"ts":"1649290078757"}]}
1649290078.797363: {"action":"update","arg":{"instType":"sp","channel":"books","instId":"VVSUSDT"},"data":[{"asks":[["0.00002370","616959.1000"],["0.00002373","453216.4000"],["0.00002379","576023.4000"],["0.00002382","330409.4000"],["0.00002385","494152.0000"],["0.00002391","209118.5000"],["0.00002397","657894.7000"],["0.00002403","289473.7000"],["0.00002406","698830.4000"],["0.00002409","821637.4000"]],"bids":[["0.00002261","739766.1000"],["0.00002258","371345.0000"],["0.00002252","616959.1000"],["0.00002249","330409.4000"],["0.00002243","821637.4000"],["0.00002240","412280.7000"],["0.00002237","903508.8000"],["0.00002234","223814.8000"],["0.00002231","248538.0000"],["0.00002228","780701.8000"]],"checksum":846916687,"ts":"1649290078775"}]}
1649290078.908809: {"action":"update","arg":{"instType":"sp","channel":"books","instId":"SUNUSDT"},"data":[{"asks":[["0.01507","0"],["0.01508","9649"],["0.01509","78861"],["0.01510","16180"],["0.01511","258576"],["0.01512","276083"],["0.01515","1039032"],["0.01519","696172"],["0.01531","58896"],["0.01539","825"],["0.01549","197875"],["0.01581","3833"],["0.01583","6833"],["0.01585","5833"],["0.01587","4500"],["0.01589","7833"],["0.01591","5500"],["0.01593","2833"],["0.01595","3500"],["0.01597","2500"],["0.01599","4167"],["0.01601","1833"],["0.01603","5167"],["0.01605","7500"],["0.01607","7167"],["0.01609","6167"],["0.01611","3167"],["0.01613","4833"],["0.01615","8167"],["0.01617","6500"],["0.01619","2167"]],"bids":[["0.01503","181800"],["0.01502","108390"],["0.01501","702152"],["0.01499","294035"],["0.01498","97886"],["0.01497","1180533"],["0.01496","278786"],["0.01495","28276"],["0.01486","11602"],["0.01485","438074"],["0.01484","113297"],["0.01430","5500"],["0.01429","0"],["0.01428","1833"],["0.01427","0"],["0.01426","2833"],["0.01425","0"],["0.01424","2167"],["0.01423","0"],["0.01422","7167"],["0.01421","0"],["0.01420","3500"],["0.01419","0"],["0.01418","5167"],["0.01417","0"],["0.01416","8167"],["0.01415","0"],["0.01414","6833"],["0.01413","0"],["0.01412","2500"],["0.01411","0"],["0.01410","3833"],["0.01409","0"],["0.01408","6167"],["0.01407","0"],["0.01406","7833"],["0.01405","0"],["0.01404","6500"],["0.01403","0"],["0.01402","3167"],["0.01401","0"],["0.01400","7500"],["0.01399","0"],["0.01398","4833"],["0.01397","0"],["0.01396","5833"],["0.01395","0"],["0.01394","4167"],["0.01393","0"],["0.01392","4500"],["0.01391","0"]],"checksum":215261866,"ts":"1649290078883"}]}
1649290078.933899: {"action":"update","arg":{"instType":"sp","channel":"books","instId":"EOSUSDT"},"data":[{"asks":[["2.4400","0"],["2.4412","0"],["2.4413","0"],["2.4414","0"],["2.4417","30.0462"],["2.4418","0"],["2.4419","0"],["2.4420","325.1371"],["2.4421","0"],["2.4422","110.3698"],["2.4423","87.2679"],["2.4425","343.6973"],["2.4426","512.7501"],["2.4428","0"],["2.4429","735.3900"],["2.4430","379.2794"],["2.4432","483.4359"],["2.4433","43.1339"],["2.4434","208.7985"],["2.4436","2074.0204"],["2.4437","61.4580"],["2.4438","2646.7502"],["2.4439","2631.8228"],["2.4441","1095.2386"],["2.4442","124.5873"],["2.4443","1848.9921"],["2.4444","1834.5664"],["2.4445","0"],["2.4446","2467.8220"],["2.4449","1573.2330"],["2.4450","4549.8622"],["2.4451","945.8829"],["2.4454","0"],["2.4456","1302.9096"],["2.4458","82.1185"],["2.4459","1551.2464"],["2.4460","2599.6500"],["2.4461","1015.7584"],["2.4462","0"],["2.4464","8.0438"],["2.4469","2727.5113"],["2.4470","2457.7740"],["2.4471","45.6167"],["2.4472","1925.7321"],["2.4473","433.1185"],["2.4474","604.8000"],["2.4475","164.5730"],["2.4477","1765.4392"],["2.4563","0"],["2.4568","530.9524"],["2.4573","478.5714"],["2.4578","540.4762"],["2.4583","526.1905"],["2.4588","497.6190"],["2.4593","535.7143"],["2.4598","483.3333"],["2.4603","473.8095"],["2.4608","469.0476"],["2.4613","511.9048"],["2.4618","545.2381"],["2.4623","459.5238"],["2.4628","516.6667"],["2.4633","454.7619"],["2.4638","464.2857"],["2.4643","502.3810"],["2.4648","521.4286"],["2.4653","507.1429"],["2.4658","488.0952"],["2.4663","492.8571"]],"bids":[["2.4376","2081.6867"],["2.4375","61.4580"],["2.4374","3400.8433"],["2.4372","0"],["2.4371","1189.9700"],["2.4370","0"],["2.4366","57.0451"],["2.4365","126.6751"],["2.4364","0"],["2.4363","757.9800"],["2.4362","2156.5773"],["2.4361","3272.4900"],["2.4360","103.8222"],["2.4359","1462.2660"],["2.4358","2761.9243"],["2.4357","486.0185"],["2.4356","3574.3824"],["2.4355","1161.0000"],["2.4354","869.9412"],["2.4351","4187.7000"],["2.4349","798.3297"],["2.4344","2311.6844"],["2.4343","573.2363"],["2.4341","5446.9616"],["2.4339","956.8851"],["2.4338","0"],["2.4333","724.5262"],["2.4331","5595.4350"],["2.4329","393.3933"],["2.4328","1915.2998"],["2.4327","270.9000"],["2.4326","0"],["2.4325","72.9188"],["2.4321","6459.6578"],["2.4319","618.5087"],["2.4317","0"],["2.4225","464.2857"],["2.4221","0"],["2.4220","507.1429"],["2.4216","0"],["2.4215","492.8571"],["2.4211","0"],["2.4210","478.5714"],["2.4206","0"],["2.4205","473.8095"],["2.4201","0"],["2.4200","488.0952"],["2.4196","0"],["2.4195","459.5238"],["2.4191","0"],["2.4190","530.9524"],["2.4186","0"],["2.4185","540.4762"],["2.4181","0"],["2.4180","483.3333"],["2.4176","0"],["2.4175","535.7143"],["2.4171","0"],["2.4170","545.2381"],["2.4166","0"],["2.4165","526.1905"],["2.4161","0"],["2.4160","469.0476"],["2.4156","0"],["2.4155","511.9048"],["2.4151","0"],["2.4150","521.4286"],["2.4146","0"],["2.4145","497.6190"],["2.4141","0"],["2.4140","454.7619"],["2.4136","0"],["2.4135","516.6667"],["2.4131","0"],["2.4130","502.3810"],["2.4126","0"]],"checksum":1235102873,"ts":"1649290078911"}]}
1649290079.045454: {"action":"update","arg":{"instType":"sp","channel":"trade","instId":"AVAXUSDT"},"data":[["1649290079010","83.1253","0.0603","sell"]]}
1649290079.149879: {"action":"update","arg":{"instType":"sp","channel":"books","instId":"HOTUSDT"},"data":[{"asks":[["0.0056280","0"],["0.0056290","0"],["0.0056300","0"],["0.0056310","0"],["0.0056320","2883.6000"],["0.0056330","34808.4000"],["0.0056340","197185.0500"],["0.0056350","208418.4000"],["0.0056360","287197.6500"],["0.0056370","330597.4500"],["0.0056380","597478.9500"],["0.0056400","384992.1000"],["0.0056410","165926.2500"],["0.0056490","120600.4500"],["0.0056530","311731.2000"],["0.0056560","37080.0000"],["0.0056600","702038.2500"],["0.0056670","800000.0000"],["0.0056820","3240.0000"],["0.0056830","800000.0000"],["0.0056840","6421.5000"],["0.0056850","7616.7000"],["0.0059000","0"],["0.0059050","10750.0000"],["0.0059060","0"],["0.0059110","8750.0000"],["0.0059120","0"],["0.0059170","2750.0000"],["0.0059180","0"],["0.0059230","11250.0000"],["0.0059240","0"],["0.0059290","9750.0000"],["0.0059300","0"],["0.0059350","3750.0000"],["0.0059360","0"],["0.0059410","4250.0000"],["0.0059420","0"],["0.0059470","8250.0000"],["0.0059480","0"],["0.0059530","6250.0000"],["0.0059540","0"],["0.0059590","11750.0000"],["0.0059600","0"],["0.0059650","10250.0000"],["0.0059660","0"],["0.0059710","7750.0000"],["0.0059720","0"],["0.0059770","7250.0000"],["0.0059780","0"],["0.0059830","5750.0000"],["0.0059840","0"],["0.0059890","3250.0000"],["0.0059900","0"],["0.0059950","12250.0000"],["0.0059960","0"],["0.0060010","4750.0000"],["0.0060020","0"],["0.0060070","9250.0000"],["0.0060080","0"],["0.0060130","6750.0000"],["0.0060140","0"],["0.0060190","5250.0000"]],"bids":[["0.0056150","82521.0000"],["0.0056140","57267.0000"],["0.0056130","36163.4400"],["0.0056120","320683.5000"],["0.0056100","155553.3000"],["0.0056090","162900.0000"],["0.0056080","410465.7000"],["0.0056060","313413.3000"],["0.0056030","417614.0000"],["0.0056020","277136.1000"],["0.0055990","124693.2000"],["0.0055980","123771.6000"],["0.0055930","712875.1100"],["0.0055890","464400.0000"],["0.0055870","129358.8000"],["0.0055850","0"],["0.0055740","11042.1000"],["0.0055730","213448.5000"],["0.0055630","30470.3100"],["0.0055540","0"],["0.0055530","0"],["0.0055520","0"],["0.0053420","7750.0000"],["0.0053380","0"],["0.0053360","5250.0000"],["0.0053320","0"],["0.0053300","6750.0000"],["0.0053260","0"],["0.0053240","4750.0000"],["0.0053200","0"],["0.0053180","10250.0000"],["0.0053140","0"],["0.0053120","6250.0000"],["0.0053080","0"],["0.0053060","3250.0000"],["0.0053020","0"],["0.0053000","3750.0000"],["0.0052960","0"],["0.0052940","12250.0000"],["0.0052900","0"],["0.0052880","10750.0000"],["0.0052840","0"],["0.0052820","2750.0000"],["0.0052780","0"],["0.0052760","8250.0000"],["0.0052720","0"],["0.0052700","9250.0000"],["0.0052660","0"],["0.0052640","4250.0000"],["0.0052600","0"],["0.0052580","8750.0000"],["0.0052540","0"],["0.0052520","9750.0000"],["0.0052480","0"],["0.0052460","11250.0000"],["0.0052420","0"],["0.0052400","5750.0000"],["0.0052360","0"],["0.0052340","7250.0000"],["0.0052300","0"],["0.0052280","11750.0000"],["0.0052240","0"]],"checksum":-1820341062,"ts":"1649290079126"}]}
1649290079.2250931: {"action":"update","arg":{"instType":"sp","channel":"candle1m","instId":"GOGUSDT"},"data":[["1649290020000","0.556","0.5586","0.5554","0.5555","104.1713"]]}
1649290079.272474: {"action":"update","arg":{"instType":"sp","channel":"books","instId":"GOGUSDT"},"data":[{"asks":[["0.5625","12.3333"],["0.5631","9.0000"],["0.5643","8.8615"],["0.5649","11.0000"],["0.5655","2347.4667"],["0.5661","15.6667"],["0.5679","8.8054"],["0.5685","8.7961"],["0.5691","16.3333"],["0.5703","13.0000"],["0.5709","15.0000"],["0.5715","14.3333"],["0.5721","8.7407"],["0.5727","9.6667"],["0.5733","8.7224"]],"bids":[["0.5512","10.4000"],["0.5506","15.6667"],["0.5500","9.0919"],["0.5494","13.6667"],["0.5488","10.3333"],["0.5482","3678.2333"],["0.5476","11.6667"],["0.5470","16.3333"],["0.5452","9.1719"],["0.5446","9.1821"],["0.5440","15.0000"],["0.5434","11.0000"],["0.5428","13.0000"],["0.5422","9.2227"],["0.5416","9.6667"],["0.5404","14.3333"]],"checksum":1119344361,"ts":"1649290079244"}]}
1649290079.2767491: {"action":"update","arg":{"instType":"sp","channel":"books","instId":"STGUSDT"},"data":[{"asks":[["3.034","2.428"],["3.037","1.667"],["3.040","3.442"],["3.043","1.644"],["3.046","2.554"],["3.049","4.725"],["3.052","2.174"],["3.055","2.047"],["3.058","3.062"],["3.061","2.681"],["3.064","1.920"],["3.067","2.808"],["3.070","2.935"],["3.073","1.628"],["3.079","6.472"],["3.085","3.188"],["3.088","3.569"],["3.091","1.619"],["3.094","1.793"],["3.097","1.615"],["3.100","2.301"]],"bids":[["2.744","1.823"],["2.741","1.825"],["2.738","19.429"],["2.735","2.538"],["2.732","98.454"],["2.729","2.000"],["2.726","75.575"],["2.723","3.077"],["2.720","1.839"],["2.717","3.185"],["2.714","3.292"],["2.711","2.646"],["2.705","1.849"],["2.702","2.108"],["2.699","1.892"],["2.696","92.416"],["2.693","2.323"],["2.690","2.969"],["2.684","2.862"],["2.678","1.868"],["2.675","2.215"],["2.672","2.431"]],"checksum":1518500422,"ts":"1649290079255"}]}
1649290079.3063118: {"action":"update","arg":{"instType":"sp","channel":"books","instId":"AVAXUSDT"},"data":[{"asks":[["83.1515","0"],["83.1615","0"],["83.1715","0"],["83.1815","0"],["83.1915","0"],["83.2015","0"],["83.2016","106.4000"],["83.2115","0"],["83.2116","179.6900"],["83.2215","0"],["83.2216","102.2070"],["83.2315","0"],["83.2316","180.0000"],["83.2415","0"],["83.2416","126.0560"],["83.2515","0"],["83.2516","35.1330"],["83.2615","0"],["83.2616","142.2890"],["83.2715","0"],["83.2716","56.6160"],["83.2815","0"],["83.2816","2.8000"],["83.2915","0"],["83.2916","42.5670"],["83.3015","0"],["83.3016","123.0180"],["83.3115","0"],["83.3116","2.5270"],["83.3215","0"],["83.3216","109.5640"],["83.3415","0"],["83.3416","0.2660"],["83.3515","0"],["83.3516","132.0900"],["83.3615","0"],["83.3616","78.4350"],["83.3715","0"],["83.3716","2.8000"],["83.3815","0"],["83.3816","180.0000"],["83.4115","0"],["83.4116","13.6430"],["83.4215","0"],["83.4216","2.3240"],["83.4315","0"],["83.4316","180.0000"],["83.4415","0"],["83.4416","0.1330"],["83.4615","0"],["83.4616","13.7550"],["83.4716","5.0750"],["83.4815","0"],["83.4816","180.0000"],["83.4915","0"],["83.4916","2.0440"],["83.5115","0"],["83.5116","7.5950"],["83.5215","0"],["83.5216","0.2660"],["83.5315","0"],["83.5316","180.0000"],["83.5415","0"],["83.5416","159.1450"],["83.5515","0"],["83.5516","0.2730"],["83.5615","0"],["83.5616","1.8970"],["83.5715","0"],["83.5716","0.2660"],["83.5815","0"],["83.5816","3.3110"],["83.5915","0"],["83.5916","13.6080"],["83.6015","0"],["83.6016","126.1470"],["83.6115","0"],["83.6116","3.1220"],["83.6215","0"],["83.6216","5.0610"],["83.6315","0"],["83.6316","0.9800"],["83.6415","0"],["83.6416","45.0590"],["83.6515","0"],["83.6516","0.2310"],["83.6615","0"],["83.6616","0.2870"],["83.6715","0"],["83.6716","8.0010"],["83.6815","0"],["83.6816","180.0000"],["83.6915","0"],["83.6916","2.4220"],["83.7015","0"],["83.7016","2.4150"],["83.7116","2.6110"],["83.7216","0.6300"],["83.7316","2.3870"],["83.7416","0.9660"],["88.0383","0"],["88.0913","0.2500"],["88.1214","0"],["88.1745","0.3500"],["88.2045","0"],["88.2577","0.6167"],["88.2876","0"],["88.3409","0.4833"],["88.3707","0"],["88.4241","0.4500"],["88.4538","0"],["88.5073","0.1833"],["88.5369","0"],["88.5905","0.3167"],["88.6200","0"],["88.6737","0.7500"],["88.7031","0"],["88.7569","0.5833"],["88.7862","0"],["88.8401","0.5167"],["88.8693","0"],["88.9233","0.2167"],["88.9524","0"],["89.0065","0.6500"],["89.0355","0"],["89.0897","0.3833"],["89.1186","0"],["89.1729","0.2833"],["89.2017","0"],["89.2561","0.5500"],["89.2848","0"],["89.3393","0.7167"],["89.3679","0"],["89.4225","0.7833"],["89.4510","0"],["89.5057","0.6833"],["89.5341","0"],["89.5889","0.8167"],["89.6172","0"],["89.6721","0.4167"]],"bids":[["83.0084","38.2270"],["82.9884","48.9790"],["82.9784","25.2490"],["82.9684","104.7900"],["82.9585","0"],["82.9584","68.4250"],["82.9485","0"],["82.9484","117.7190"],["82.9385","0"],["82.9384","10.5910"],["82.9285","0"],["82.9284","117.5440"],["82.9185","0"],["82.9184","105.7140"],["82.9085","0"],["82.9084","35.0140"],["82.8985","0"],["82.8984","26.8450"],["82.8785","0"],["82.8784","43.9460"],["82.8685","0"],["82.8684","137.8090"],["82.8585","0"],["82.8584","74.2980"],["82.8485","0"],["82.8484","89.5720"],["82.8385","0"],["82.8384","180.0000"],["82.8285","0"],["82.8284","116.5500"],["82.8185","0"],["82.8184","116.9770"],["82.8085","0"],["82.8084","35.4620"],["82.7985","0"],["82.7984","139.6780"],["82.7885","0"],["82.7884","127.1480"],["82.7785","0"],["82.7784","31.7450"],["82.7685","0"],["82.7684","9.7790"],["82.7585","0"],["82.7584","16.5760"],["82.7485","0"],["82.7484","180.0000"],["82.7385","0"],["82.7384","39.5220"],["82.7285","0"],["82.7284","173.2640"],["82.7185","0"],["82.7184","134.2040"],["82.7085","0"],["82.7084","141.1060"],["82.6985","0"],["82.6984","88.0320"],["82.6885","0"],["82.6884","180.0000"],["82.6785","0"],["82.6784","180.0000"],["82.6685","0"],["82.6684","180.0000"],["82.6585","0"],["82.6584","180.0000"],["82.6485","0"],["82.6484","180.0000"],["82.6385","0"],["82.6384","180.0000"],["82.6285","0"],["82.6284","180.0000"],["82.6185","0"],["82.6184","180.0000"],["82.6085","0"],["82.6084","12.8660"],["82.5985","0"],["82.5984","87.9620"],["82.5885","0"],["82.5884","25.1720"],["82.5785","0"],["82.5784","17.8500"],["82.5685","0"],["82.5684","180.0000"],["82.5585","0"],["82.5584","149.2190"],["82.5485","0"],["82.5484","109.4450"],["82.5385","0"],["82.5384","156.0860"],["82.5285","0"],["82.5284","25.1370"],["82.5185","0"],["82.5184","170.6740"],["82.5085","0"],["82.5084","180.0000"],["82.4985","0"],["82.4984","32.2000"],["82.4885","0"],["82.4785","0"],["82.4685","0"],["82.4585","0"],["78.1187","0.8167"],["78.0717","0"],["78.0355","0.7500"],["77.9886","0"],["77.9523","0.5500"],["77.9055","0"],["77.8691","0.2167"],["77.8224","0"],["77.7859","0.7833"],["77.7393","0"],["77.7027","0.4167"],["77.6562","0"],["77.6195","0.4500"],["77.5731","0"],["77.5363","0.6500"],["77.4900","0"],["77.4531","0.3833"],["77.4069","0"],["77.3699","0.6833"],["77.3238","0"],["77.2867","0.2500"],["77.2407","0"],["77.2035","0.5833"],["77.1576","0"],["77.1203","0.1833"],["77.0745","0"],["77.0371","0.2833"],["76.9914","0"],["76.9539","0.4833"],["76.9083","0"],["76.8707","0.5167"],["76.8252","0"],["76.7875","0.7167"],["76.7421","0"],["76.7043","0.3167"],["76.6590","0"],["76.6211","0.6167"],["76.5759","0"],["76.5379","0.3500"],["76.4928","0"]],"checksum":-989707056,"ts":"1649290079279"}]}
1649290079.307439: {"action":"update","arg":{"instType":"sp","channel":"books","instId":"VVSUSDT"},"data":[{"asks":[["0.00002370","657894.7000"],["0.00002373","494152.0000"],["0.00002379","289473.7000"],["0.00002382","821637.4000"],["0.00002385","698830.4000"],["0.00002397","330409.4000"],["0.00002403","780701.8000"],["0.00002406","739766.1000"],["0.00002409","453216.4000"]],"bids":[["0.00002314","40268614.5000"],["0.00002261","821637.4000"],["0.00002258","453216.4000"],["0.00002255","698830.4000"],["0.00002252","371345.0000"],["0.00002249","248538.0000"],["0.00002243","535087.7000"],["0.00002240","739766.1000"],["0.00002237","616959.1000"],["0.00002234","657894.7000"],["0.00002231","903508.8000"],["0.00002228","494152.0000"]],"checksum":-1693544231,"ts":"1649290079281"}]}
1649290079.382263: {"action":"update","arg":{"instType":"sp","channel":"books","instId":"CULTUSDT"},"data":[{"asks":[["0.00003614","573333"],["0.00003622","626667"],["0.00003626","360000"],["0.00003630","280000"],["0.00003634","440000"],["0.00003638","146667"],["0.00003642","493333"],["0.00003646","607056"],["0.00003650","386667"],["0.00003654","600000"],["0.00003658","226667"],["0.00003662","200000"],["0.00003666","520000"],["0.00003670","306667"],["0.00003674","253333"],["0.00003678","546667"],["0.00003682","653333"],["0.00003686","466667"],["0.00003690","173333"]],"bids":[["0.00003471","306667"],["0.00003467","1368564"],["0.00003463","573333"],["0.00003459","146667"],["0.00003451","253333"],["0.00003447","200000"],["0.00003443","653333"],["0.00003439","600000"],["0.00003435","626667"],["0.00003431","520000"],["0.00003427","333333"],["0.00003423","360000"],["0.00003419","546667"],["0.00003415","386667"],["0.00003411","440000"],["0.00003407","413333"],["0.00003403","466667"],["0.00003399","493333"],["0.00003395","173333"]],"checksum":1951879533,"ts":"1649290079360"}]}
1649290079.412012: {"action":"update","arg":{"instType":"sp","channel":"candle1m","instId":"AVAXUSDT"},"data":[["1649290020000","82.989","83.1532","82.8767","83.1253","0.4824"]]}
1649290079.4524128: {"action":"update","arg":{"instType":"sp","channel":"books","instId":"EOSUSDT"},"data":[{"asks":[["2.4417","0"],["2.4420","0"],["2.4422","0"],["2.4423","0"],["2.4425","0"],["2.4426","831.1653"],["2.4427","183.7476"],["2.4429","250.7400"],["2.4430","8.0467"],["2.4432","0"],["2.4433","72.9188"],["2.4434","389.5983"],["2.4435","83.8474"],["2.4436","0"],["2.4437","8.0461"],["2.4438","3729.2220"],["2.4439","2367.5378"],["2.4440","0"],["2.4441","1057.9929"],["2.4442","36.8705"],["2.4443","1535.2246"],["2.4444","1844.1117"],["2.4446","1414.0416"],["2.4447","229.9566"],["2.4448","834.3810"],["2.4449","1863.2201"],["2.4450","3756.0411"],["2.4451","140.0635"],["2.4452","896.0828"],["2.4453","0"],["2.4454","208.4364"],["2.4455","156.3734"],["2.4456","45.7226"],["2.4457","1021.5894"],["2.4459","1472.5251"],["2.4460","4320.0000"],["2.4461","1607.5117"],["2.4463","2325.5654"],["2.4464","107.3855"],["2.4465","1666.6268"],["2.4466","2124.8335"],["2.4467","583.3350"],["2.4468","1386.5986"],["2.4469","2804.2943"],["2.4470","1706.9490"],["2.4471","1362.4430"],["2.4473","82.1185"],["2.4474","1747.6985"],["2.4477","1949.7220"],["2.4478","2826.2638"],["2.4479","1819.7389"],["2.4480","37.7100"],["2.4483","311.7141"],["2.4485","90.0000"],["2.4486","45.6167"],["2.4488","634.6938"],["2.4568","0"],["2.4573","0"],["2.4578","511.9048"],["2.4583","545.2381"],["2.4588","488.0952"],["2.4593","464.2857"],["2.4598","478.5714"],["2.4608","459.5238"],["2.4613","497.6190"],["2.4618","483.3333"],["2.4623","521.4286"],["2.4628","492.8571"],["2.4633","469.0476"],["2.4638","526.1905"],["2.4643","507.1429"],["2.4648","530.9524"],["2.4653","540.4762"],["2.4658","454.7619"],["2.4663","535.7143"],["2.4668","502.3810"],["2.4673","516.6667"]],"bids":[["2.4387","61.4580"],["2.4386","2140.5876"],["2.4384","2365.9126"],["2.4383","96.7293"],["2.4382","1356.4168"],["2.4381","4503.1500"],["2.4380","2929.0808"],["2.4376","462.1959"],["2.4375","3763.5214"],["2.4374","1114.7199"],["2.4373","71.3356"],["2.4372","837.0000"],["2.4371","2880.1842"],["2.4370","2214.8184"],["2.4369","1390.3326"],["2.4368","2970.9900"],["2.4367","117.4950"],["2.4366","1682.5904"],["2.4365","246.2739"],["2.4364","308.4064"],["2.4363","402.4800"],["2.4362","2094.4890"],["2.4361","1200.6300"],["2.4360","1739.5392"],["2.4359","1546.1100"],["2.4358","0"],["2.4357","967.5729"],["2.4356","1547.1486"],["2.4355","69.8649"],["2.4354","1742.4290"],["2.4353","2559.2249"],["2.4351","2906.3340"],["2.4350","0"],["2.4349","1093.4995"],["2.4348","0"],["2.4347","350.5998"],["2.4345","727.9840"],["2.4344","1203.1106"],["2.4343","910.8924"],["2.4342","316.2263"],["2.4341","4497.8577"],["2.4340","2599.6500"],["2.4339","1420.1144"],["2.4338","351.0000"],["2.4337","552.9821"],["2.4336","1890.2543"],["2.4335","0"],["2.4334","794.7244"],["2.4333","81.4582"],["2.4332","1330.7594"],["2.4331","6056.1450"],["2.4330","1396.9391"],["2.4329","0"],["2.4328","0"],["2.4327","0"],["2.4325","0"],["2.4324","0"],["2.4323","0"],["2.4322","0"],["2.4321","0"],["2.4320","0"],["2.4319","0"],["2.4318","0"],["2.4235","535.7143"],["2.4230","473.8095"],["2.4225","497.6190"],["2.4220","526.1905"],["2.4215","507.1429"],["2.4210","530.9524"],["2.4205","545.2381"],["2.4200","483.3333"],["2.4195","502.3810"],["2.4190","516.6667"],["2.4185","488.0952"],["2.4180","492.8571"],["2.4175","464.2857"],["2.4170","521.4286"],["2.4165","469.0476"],["2.4160","459.5238"],["2.4150","478.5714"],["2.4145","540.4762"],["2.4135","0"],["2.4130","0"]],"checksum":393581867,"ts":"1649290079426"}]}
1649290079.454654: {"action":"update","arg":{"instType":"sp","channel":"books","instId":"SUNUSDT"},"data":[{"asks":[["0.01508","14227"],["0.01510","5155"],["0.01515","1037299"],["0.01517","25303"],["0.01581","0"],["0.01582","6500"],["0.01583","0"],["0.01584","6167"],["0.01585","0"],["0.01586","7500"],["0.01587","0"],["0.01588","3167"],["0.01589","0"],["0.01590","5833"],["0.01591","0"],["0.01592","7167"],["0.01593","0"],["0.01594","4167"],["0.01595","0"],["0.01596","3833"],["0.01597","0"],["0.01598","4833"],["0.01599","0"],["0.01600","2500"],["0.01601","0"],["0.01602","2167"],["0.01603","0"],["0.01604","5167"],["0.01605","0"],["0.01606","8167"],["0.01607","0"],["0.01608","3500"],["0.01609","0"],["0.01610","6833"],["0.01611","0"],["0.01612","5500"],["0.01613","0"],["0.01614","4500"],["0.01615","0"],["0.01616","1833"],["0.01617","0"],["0.01618","7833"],["0.01619","0"],["0.01620","2833"]],"bids":[["0.01504","27266"],["0.01502","85958"],["0.01501","709578"],["0.01500","536550"],["0.01499","1403875"],["0.01498","22917"],["0.01497","115662"],["0.01495","87729"],["0.01485","437770"],["0.01450","0"],["0.01430","3500"],["0.01426","2167"],["0.01424","4833"],["0.01422","8167"],["0.01420","2833"],["0.01418","6167"],["0.01416","5167"],["0.01414","3167"],["0.01412","6833"],["0.01410","6500"],["0.01408","7500"],["0.01406","4500"],["0.01404","7833"],["0.01402","2500"],["0.01400","3833"],["0.01398","5833"],["0.01396","4167"],["0.01394","7167"],["0.01392","5500"]],"checksum":-633732055,"ts":"1649290079432"}]}
1649290079.716436: {"action":"update","arg":{"instType":"sp","channel":"books","instId":"HOTUSDT"},"data":[{"asks":[["0.0056320","0"],["0.0056330","0"],["0.0056340","0"],["0.0056350","89146.8000"],["0.0056360","111529.8000"],["0.0056370","269207.1000"],["0.0056380","800000.0000"],["0.0056390","464760.0000"],["0.0056400","230984.1000"],["0.0056410","86049.0000"],["0.0056450","416917.8000"],["0.0056460","139779.9000"],["0.0056470","328111.2000"],["0.0056510","240786.0000"],["0.0056520","132047.5500"],["0.0056530","191364.3000"],["0.0056590","0"],["0.0056600","86598.9000"],["0.0056610","0"],["0.0056640","800000.0000"],["0.0056800","271800.0000"],["0.0056830","102600.0000"],["0.0056860","38396.7000"],["0.0056870","262003.5000"],["0.0056890","5535.0000"],["0.0056910","2519.1000"],["0.0059050","0"],["0.0059080","6250.0000"],["0.0059110","0"],["0.0059140","6750.0000"],["0.0059170","0"],["0.0059200","11250.0000"],["0.0059230","0"],["0.0059260","8750.0000"],["0.0059290","0"],["0.0059320","5750.0000"],["0.0059350","0"],["0.0059380","7250.0000"],["0.0059410","0"],["0.0059440","11750.0000"],["0.0059470","0"],["0.0059500","9750.0000"],["0.0059530","0"],["0.0059560","4750.0000"],["0.0059590","0"],["0.0059620","10750.0000"],["0.0059650","0"],["0.0059680","3250.0000"],["0.0059710","0"],["0.0059740","7750.0000"],["0.0059770","0"],["0.0059800","12250.0000"],["0.0059830","0"],["0.0059860","10250.0000"],["0.0059890","0"],["0.0059920","8250.0000"],["0.0059950","0"],["0.0059980","5250.0000"],["0.0060010","0"],["0.0060040","2750.0000"],["0.0060070","0"],["0.0060100","4250.0000"],["0.0060130","0"],["0.0060160","9250.0000"],["0.0060190","0"],["0.0060220","3750.0000"]],"bids":[["0.0056170","20404.8000"],["0.0056160","85076.1000"],["0.0056150","296525.7000"],["0.0056140","99163.8000"],["0.0056130","115339.5900"],["0.0056120","490389.3000"],["0.0056110","160188.3000"],["0.0056100","190425.6000"],["0.0056080","152477.1000"],["0.0056060","235380.1500"],["0.0056050","184642.2000"],["0.0056030","76775.4500"],["0.0056020","109383.4268"],["0.0056010","501182.5500"],["0.0056000","727456.5000"],["0.0055980","84743.5500"],["0.0055970","114706.8000"],["0.0055940","300898.3500"],["0.0055920","160119.0000"],["0.0055910","500985.9000"],["0.0055900","158850.0000"],["0.0055860","120686.4000"],["0.0055840","230864.8500"],["0.0055810","104640.3000"],["0.0055790","0"],["0.0055670","30573.0000"],["0.0055600","294261.3000"],["0.0055590","136695.6000"],["0.0055570","0"],["0.0055560","0"],["0.0055550","0"],["0.0053440","5750.0000"],["0.0053420","0"],["0.0053380","7750.0000"],["0.0053360","0"],["0.0053320","3250.0000"],["0.0053300","0"],["0.0053260","9250.0000"],["0.0053240","0"],["0.0053200","7250.0000"],["0.0053180","0"],["0.0053140","4750.0000"],["0.0053120","0"],["0.0053080","10250.0000"],["0.0053060","0"],["0.0053020","11750.0000"],["0.0053000","0"],["0.0052960","6750.0000"],["0.0052940","0"],["0.0052900","12250.0000"],["0.0052880","0"],["0.0052840","8250.0000"],["0.0052820","0"],["0.0052780","10750.0000"],["0.0052760","0"],["0.0052720","6250.0000"],["0.0052700","0"],["0.0052660","8750.0000"],["0.0052640","0"],["0.0052600","5250.0000"],["0.0052580","0"],["0.0052540","3750.0000"],["0.0052520","0"],["0.0052480","4250.0000"],["0.0052460","0"],["0.0052420","11250.0000"],["0.0052400","0"],["0.0052360","9750.0000"],["0.0052340","0"],["0.0052300","2750.0000"],["0.0052280","0"]],"checksum":-193346563,"ts":"1649290079687"}]}
1649290079.781207: {"action":"update","arg":{"instType":"sp","channel":"books","instId":"GOGUSDT"},"data":[{"asks":[["0.5625","8.8899"],["0.5631","11.0000"],["0.5643","13.6667"],["0.5649","8.8521"],["0.5655","2342.1333"],["0.5661","9.6667"],["0.5667","13.0000"],["0.5673","8.8147"],["0.5685","12.3333"],["0.5691","11.6667"],["0.5697","15.6667"],["0.5703","9.0000"],["0.5715","8.7499"],["0.5727","16.3333"],["0.5733","14.3333"],["0.5739","10.3333"]],"bids":[["0.5512","9.0721"],["0.5506","9.0820"],["0.5500","10.3333"],["0.5494","13.0000"],["0.5488","13.6667"],["0.5482","3681.5667"],["0.5476","14.3333"],["0.5470","9.1418"],["0.5464","11.0000"],["0.5452","12.3333"],["0.5440","9.1922"],["0.5434","9.2023"],["0.5428","15.0000"],["0.5422","16.3333"],["0.5416","9.2329"],["0.5410","9.6667"],["0.5404","11.6667"]],"checksum":579217949,"ts":"1649290079759"}]}
1649290079.808107: {"action":"update","arg":{"instType":"sp","channel":"books","instId":"STGUSDT"},"data":[{"asks":[["3.037","1.647"],["3.040","1.646"],["3.046","3.569"],["3.049","6.373"],["3.052","2.935"],["3.058","2.554"],["3.061","3.442"],["3.064","2.174"],["3.070","1.630"],["3.073","1.793"],["3.079","5.458"],["3.082","2.681"],["3.085","3.315"],["3.088","1.920"],["3.094","3.062"],["3.097","1.667"],["3.100","1.614"]],"bids":[["2.741","2.323"],["2.738","19.644"],["2.735","1.829"],["2.732","100.608"],["2.729","2.862"],["2.726","73.744"],["2.723","2.108"],["2.717","1.841"],["2.714","1.843"],["2.711","3.292"],["2.708","2.000"],["2.702","2.538"],["2.699","2.215"],["2.696","92.739"],["2.693","1.858"],["2.690","3.185"],["2.687","2.431"],["2.684","2.754"],["2.681","2.646"],["2.678","2.969"],["2.675","1.870"],["2.672","1.872"]],"checksum":1397482024,"ts":"1649290079786"}]}
1649290079.81142: {"action":"update","arg":{"instType":"sp","channel":"books","instId":"VVSUSDT"},"data":[{"asks":[["0.00002370","210971.5000"],["0.00002373","657894.7000"],["0.00002379","412280.7000"],["0.00002382","862573.1000"],["0.00002385","248538.0000"],["0.00002391","289473.7000"],["0.00002397","739766.1000"],["0.00002403","821637.4000"],["0.00002406","494152.0000"],["0.00002409","616959.1000"]],"bids":[["0.00002261","698830.4000"],["0.00002258","903508.8000"],["0.00002255","616959.1000"],["0.00002252","739766.1000"],["0.00002249","862573.1000"],["0.00002243","494152.0000"],["0.00002240","330409.4000"],["0.00002237","371345.0000"],["0.00002234","780701.8000"],["0.00002231","821637.4000"],["0.00002228","224417.5000"]],"checksum":1536619840,"ts":"1649290079788"}]}
1649290079.846324: {"action":"update","arg":{"instType":"sp","channel":"books","instId":"AVAXUSDT"},"data":[{"asks":[["83.1815","38.9200"],["83.1915","77.1960"],["83.2015","180.0000"],["83.2016","0"],["83.2115","6.7270"],["83.2116","0"],["83.2215","180.0000"],["83.2216","0"],["83.2315","180.0000"],["83.2316","0"],["83.2415","180.0000"],["83.2416","0"],["83.2515","91.5110"],["83.2516","0"],["83.2615","180.0000"],["83.2616","0"],["83.2715","13.4890"],["83.2716","0"],["83.2815","36.4280"],["83.2816","0"],["83.2915","101.6470"],["83.2916","0"],["83.3015","123.0180"],["83.3016","0"],["83.3115","2.5270"],["83.3116","0"],["83.3215","109.5640"],["83.3216","0"],["83.3415","0.2660"],["83.3416","0"],["83.3515","132.0900"],["83.3516","0"],["83.3615","78.4350"],["83.3616","0"],["83.3715","2.8000"],["83.3716","0"],["83.3815","180.0000"],["83.3816","0"],["83.4115","180.0000"],["83.4116","0"],["83.4215","2.3240"],["83.4216","0"],["83.4315","180.0000"],["83.4316","0"],["83.4415","0.1330"],["83.4416","0"],["83.4615","13.7550"],["83.4616","0"],["83.4715","5.0750"],["83.4716","0"],["83.4815","180.0000"],["83.4816","0"],["83.4915","2.0440"],["83.4916","0"],["83.5115","7.5950"],["83.5116","0"],["83.5215","2.4780"],["83.5216","0"],["83.5315","180.0000"],["83.5316","0"],["83.5415","159.1450"],["83.5416","0"],["83.5515","0.2730"],["83.5516","0"],["83.5615","8.5470"],["83.5616","0"],["83.5715","0.2660"],["83.5716","0"],["83.5815","3.3110"],["83.5816","0"],["83.5915","13.6080"],["83.5916","0"],["83.6015","128.3590"],["83.6016","0"],["83.6115","3.1220"],["83.6116","0"],["83.6215","5.0610"],["83.6216","0"],["83.6315","0.9800"],["83.6316","0"],["83.6415","0.7280"],["83.6416","0"],["83.6515","0.2310"],["83.6516","0"],["83.6615","0.2870"],["83.6616","0"],["83.6715","8.0010"],["83.6716","0"],["83.6815","180.0000"],["83.6816","0"],["83.6915","2.4220"],["83.6916","0"],["83.7015","2.4150"],["83.7016","0"],["83.7115","2.6110"],["83.7116","0"],["83.7215","0.6300"],["83.7216","0"],["83.7316","0"],["83.7416","0"],["88.0701","0.4167"],["88.0913","0"],["88.1532","0.7500"],["88.1745","0"],["88.2363","0.8167"],["88.2577","0"],["88.3194","0.3833"],["88.3409","0"],["88.4025","0.3500"],["88.4241","0"],["88.4856","0.2833"],["88.5073","0"],["88.5687","0.6833"],["88.5905","0"],["88.6518","0.5167"],["88.6737","0"],["88.7349","0.5500"],["88.7569","0"],["88.8180","0.2500"],["88.8401","0"],["88.9011","0.6167"],["88.9233","0"],["88.9842","0.2167"],["89.0065","0"],["89.0673","0.4833"],["89.0897","0"],["89.1504","0.3167"],["89.1729","0"],["89.2335","0.1833"],["89.2561","0"],["89.3166","0.7833"],["89.3393","0"],["89.3997","0.6500"],["89.4225","0"],["89.4828","0.7167"],["89.5057","0"],["89.5659","0.5833"],["89.5889","0"],["89.6490","0.4500"],["89.6721","0"]],"bids":[["83.0084","0"],["82.9885","23.0230"],["82.9884","0"],["82.9785","57.2110"],["82.9784","0"],["82.9685","104.7900"],["82.9684","0"],["82.9585","68.4250"],["82.9584","0"],["82.9485","162.0290"],["82.9484","0"],["82.9385","10.5910"],["82.9384","0"],["82.9285","151.1440"],["82.9284","0"],["82.9185","84.2450"],["82.9184","0"],["82.9085","23.7790"],["82.9084","0"],["82.8985","180.0000"],["82.8984","0"],["82.8885","138.5860"],["82.8785","43.9460"],["82.8784","0"],["82.8685","138.3480"],["82.8684","0"],["82.8585","12.6700"],["82.8584","0"],["82.8485","89.5720"],["82.8484","0"],["82.8385","83.1810"],["82.8384","0"],["82.8285","116.5500"],["82.8284","0"],["82.8185","144.1370"],["82.8184","0"],["82.8085","35.4620"],["82.8084","0"],["82.7985","1.0570"],["82.7984","0"],["82.7885","1.1270"],["82.7884","0"],["82.7785","35.7280"],["82.7784","0"],["82.7685","9.7790"],["82.7684","0"],["82.7585","16.5760"],["82.7584","0"],["82.7485","180.0000"],["82.7484","0"],["82.7385","39.5220"],["82.7384","0"],["82.7285","173.2640"],["82.7284","0"],["82.7185","127.1130"],["82.7184","0"],["82.7085","141.1060"],["82.7084","0"],["82.6985","96.4600"],["82.6984","0"],["82.6885","180.0000"],["82.6884","0"],["82.6785","180.0000"],["82.6784","0"],["82.6685","180.0000"],["82.6684","0"],["82.6585","180.0000"],["82.6584","0"],["82.6485","180.0000"],["82.6484","0"],["82.6385","180.0000"],["82.6384","0"],["82.6285","180.0000"],["82.6284","0"],["82.6185","180.0000"],["82.6184","0"],["82.6085","12.8660"],["82.6084","0"],["82.5985","87.9620"],["82.5984","0"],["82.5885","16.8350"],["82.5884","0"],["82.5785","17.8500"],["82.5784","0"],["82.5685","180.0000"],["82.5684","0"],["82.5585","149.2190"],["82.5584","0"],["82.5485","109.4450"],["82.5484","0"],["82.5385","156.0860"],["82.5384","0"],["82.5285","25.1370"],["82.5284","0"],["82.5185","162.2600"],["82.5184","0"],["82.5085","180.0000"],["82.5084","0"],["82.4985","32.2000"],["82.4984","0"],["78.1187","0"],["78.0998","0.1833"],["78.0355","0"],["78.0167","0.6833"],["77.9523","0"],["77.9336","0.4167"],["77.8691","0"],["77.8505","0.2167"],["77.7859","0"],["77.7674","0.7167"],["77.7027","0"],["77.6843","0.6500"],["77.6195","0"],["77.6012","0.2500"],["77.5363","0"],["77.5181","0.4500"],["77.4531","0"],["77.4350","0.8167"],["77.3699","0"],["77.3519","0.3167"],["77.2867","0"],["77.2688","0.5500"],["77.2035","0"],["77.1857","0.7833"],["77.1203","0"],["77.1026","0.7500"],["77.0371","0"],["77.0195","0.3833"],["76.9539","0"],["76.9364","0.4833"],["76.8707","0"],["76.8533","0.3500"],["76.7875","0"],["76.7702","0.2833"],["76.7043","0"],["76.6871","0.5167"],["76.6211","0"],["76.6040","0.5833"],["76.5379","0"],["76.5209","0.6167"]],"checksum":-500280990,"ts":"1649290079822"}]}
1649290079.914554: {"action":"update","arg":{"instType":"sp","channel":"books","instId":"CULTUSDT"},"data":[{"asks":[["0.00003614","333333"],["0.00003622","146667"],["0.00003626","440000"],["0.00003630","386667"],["0.00003634","173333"],["0.00003638","226667"],["0.00003642","546667"],["0.00003646","580390"],["0.00003650","600000"],["0.00003654","573333"],["0.00003658","360000"],["0.00003662","520000"],["0.00003666","626667"],["0.00003670","653333"],["0.00003674","200000"],["0.00003678","253333"],["0.00003682","280000"],["0.00003690","493333"]],"bids":[["0.00003471","386667"],["0.00003467","1341897"],["0.00003463","493333"],["0.00003459","360000"],["0.00003455","561487"],["0.00003451","440000"],["0.00003447","306667"],["0.00003443","280000"],["0.00003439","146667"],["0.00003435","253333"],["0.00003431","333333"],["0.00003427","413333"],["0.00003423","226667"],["0.00003419","573333"],["0.00003415","466667"],["0.00003411","520000"],["0.00003407","600000"],["0.00003403","626667"],["0.00003399","546667"],["0.00003395","653333"],["0.00003388","0"],["0.00003144","1479733"]],"checksum":1052722983,"ts":"1649290079891"}]}
1649290079.994011: {"action":"update","arg":{"instType":"sp","channel":"books","instId":"SUNUSDT"},"data":[{"asks":[["0.01508","832"],["0.01509","85525"],["0.01510","5605"],["0.01511","212970"],["0.01512","246083"],["0.01513","56134"],["0.01514","334219"],["0.01582","3833"],["0.01584","1833"],["0.01586","5833"],["0.01590","2833"],["0.01594","4833"],["0.01596","4167"],["0.01598","7833"],["0.01600","2167"],["0.01602","3500"],["0.01604","7500"],["0.01606","4500"],["0.01608","6500"],["0.01610","2500"],["0.01614","5167"],["0.01616","6833"],["0.01618","6167"],["0.01620","8167"]],"bids":[["0.01504","549266"],["0.01503","530420"],["0.01502","94138"],["0.01501","679854"],["0.01500","536267"],["0.01498","8472"],["0.01486","21016"],["0.01430","3167"],["0.01428","7500"],["0.01426","6833"],["0.01424","6167"],["0.01420","5500"],["0.01418","1833"],["0.01416","7167"],["0.01414","2167"],["0.01412","5167"],["0.01410","2500"],["0.01408","4833"],["0.01406","4167"],["0.01404","3833"],["0.01402","3500"],["0.01400","4500"],["0.01398","7833"],["0.01396","2833"],["0.01394","6500"],["0.01392","5833"]],"checksum":1679021070,"ts":"1649290079970"}]}
1649290080.035439: {"action":"update","arg":{"instType":"sp","channel":"books","instId":"EOSUSDT"},"data":[{"asks":[["2.4426","0"],["2.4427","0"],["2.4429","0"],["2.4430","0"],["2.4433","0"],["2.4435","0"],["2.4437","0"],["2.4438","7374.6000"],["2.4439","2050.5600"],["2.4441","45.6167"],["2.4442","38.7163"],["2.4443","1325.7631"],["2.4444","2766.6234"],["2.4446","1432.0648"],["2.4447","45.4566"],["2.4448","430.6905"],["2.4449","1541.7000"],["2.4450","2087.4621"],["2.4451","115.4291"],["2.4453","207.9900"],["2.4454","658.8514"],["2.4457","773.2068"],["2.4458","775.0767"],["2.4459","1242.3351"],["2.4460","2539.0735"],["2.4461","1667.8023"],["2.4463","4426.1307"],["2.4464","144.4563"],["2.4465","91.4355"],["2.4466","322.1980"],["2.4467","444.8760"],["2.4468","256.9415"],["2.4469","2800.1876"],["2.4470","814.2480"],["2.4471","2229.3690"],["2.4472","2195.7716"],["2.4473","1551.9727"],["2.4474","2771.6735"],["2.4476","2592.0000"],["2.4477","1323.1023"],["2.4478","3164.6276"],["2.4479","2547.6889"],["2.4480","1697.9880"],["2.4482","1566.9130"],["2.4484","8.0421"],["2.4489","3379.3200"],["2.4490","30.7404"],["2.4491","3687.3000"],["2.4578","0"],["2.4583","0"],["2.4585","454.7619"],["2.4588","0"],["2.4590","483.3333"],["2.4593","0"],["2.4595","502.3810"],["2.4598","0"],["2.4600","464.2857"],["2.4603","0"],["2.4605","488.0952"],["2.4608","0"],["2.4610","521.4286"],["2.4613","0"],["2.4615","459.5238"],["2.4618","0"],["2.4620","530.9524"],["2.4623","0"],["2.4625","545.2381"],["2.4628","0"],["2.4630","526.1905"],["2.4633","0"],["2.4635","507.1429"],["2.4638","0"],["2.4640","473.8095"],["2.4643","0"],["2.4645","492.8571"],["2.4648","0"],["2.4650","497.6190"],["2.4653","0"],["2.4655","535.7143"],["2.4658","0"],["2.4660","478.5714"],["2.4663","0"],["2.4665","516.6667"],["2.4668","0"],["2.4670","469.0476"],["2.4673","0"],["2.4675","511.9048"],["2.4680","540.4762"]],"bids":[["2.4394","1746.7792"],["2.4393","730.9800"],["2.4392","2006.1229"],["2.4391","842.8500"],["2.4388","150.5348"],["2.4387","8.0503"],["2.4386","0"],["2.4385","920.7000"],["2.4384","0"],["2.4383","167.2730"],["2.4382","2505.0587"],["2.4381","1941.9300"],["2.4380","2889.4945"],["2.4379","2180.6499"],["2.4378","608.5885"],["2.4377","3715.2000"],["2.4376","73.2306"],["2.4374","935.3640"],["2.4373","190.5071"],["2.4371","2473.0175"],["2.4370","1671.8792"],["2.4369","1528.5657"],["2.4368","0"],["2.4367","535.4092"],["2.4366","920.0684"],["2.4365","63.6978"],["2.4364","26.3453"],["2.4363","414.8047"],["2.4362","91.4355"],["2.4361","1223.6384"],["2.4359","48.6687"],["2.4354","2573.2489"],["2.4353","2581.5063"],["2.4352","8.0532"],["2.4351","3437.1240"],["2.4348","61.4754"],["2.4347","485.9946"],["2.4345","1346.4326"],["2.4344","1378.6106"],["2.4341","2741.1446"],["2.4338","0"],["2.4337","183.8543"],["2.4334","0"],["2.4333","0"],["2.4332","0"],["2.4331","0"],["2.4330","0"],["2.4243","540.4762"],["2.4238","535.7143"],["2.4235","0"],["2.4233","473.8095"],["2.4230","0"],["2.4228","483.3333"],["2.4225","0"],["2.4223","497.6190"],["2.4220","0"],["2.4218","511.9048"],["2.4215","0"],["2.4213","454.7619"],["2.4210","0"],["2.4208","521.4286"],["2.4205","0"],["2.4203","530.9524"],["2.4200","0"],["2.4198","526.1905"],["2.4195","0"],["2.4193","507.1429"],["2.4190","0"],["2.4188","502.3810"],["2.4185","0"],["2.4183","492.8571"],["2.4180","0"],["2.4178","464.2857"],["2.4175","0"],["2.4173","488.0952"],["2.4170","0"],["2.4168","478.5714"],["2.4165","0"],["2.4163","469.0476"],["2.4160","0"],["2.4158","459.5238"],["2.4155","0"],["2.4153","516.6667"],["2.4150","0"],["2.4148","545.2381"],["2.4145","0"],["2.4140","0"]],"checksum":-853313883,"ts":"1649290080002"}]}
1649290080.121135: {"action":"update","arg":{"instType":"sp","channel":"trade","instId":"EOSUSDT"},"data":[["1649290080017","2.4421","2.0702","buy"]]}
1649290080.1913202: {"action":"snapshot","arg":{"instType":"sp","channel":"ticker","instId":"EOSUSDT"},"data":[{"instId":"EOSUSDT","last":"2.4383","open24h":"2.5667","high24h":"2.5767","low24h":"2.4155","bestBid":"2.439400","bestAsk":"2.443400","baseVolume":"145518.8442","quoteVolume":"378707.9474","ts":1649290080029,"labeId":0}]}
1649290080.217657: {"action":"update","arg":{"instType":"sp","channel":"candle1m","instId":"GOGUSDT"},"data":[["1649290080000","0.5555","0.5555","0.5555","0.5555","0"]]}
1649290080.259609: {"action":"update","arg":{"instType":"sp","channel":"books","instId":"HOTUSDT"},"data":[{"asks":[["0.0056340","41896.8000"],["0.0056350","409830.3000"],["0.0056360","0"],["0.0056370","615614.8500"],["0.0056380","603228.1500"],["0.0056390","624572.1000"],["0.0056400","253534.5000"],["0.0056410","97324.2000"],["0.0056420","0"],["0.0056430","800000.0000"],["0.0056540","97738.6500"],["0.0056730","0"],["0.0056840","8736.7500"],["0.0056930","800000.0000"],["0.0056940","17307.9000"],["0.0059070","5750.0000"],["0.0059080","0"],["0.0059130","3250.0000"],["0.0059140","0"],["0.0059190","8750.0000"],["0.0059200","0"],["0.0059250","5250.0000"],["0.0059260","0"],["0.0059310","12250.0000"],["0.0059320","0"],["0.0059370","9250.0000"],["0.0059380","0"],["0.0059430","10250.0000"],["0.0059440","0"],["0.0059490","8250.0000"],["0.0059500","0"],["0.0059550","6750.0000"],["0.0059560","0"],["0.0059610","4750.0000"],["0.0059620","0"],["0.0059670","6250.0000"],["0.0059680","0"],["0.0059730","10750.0000"],["0.0059740","0"],["0.0059790","11750.0000"],["0.0059800","0"],["0.0059850","7250.0000"],["0.0059860","0"],["0.0059910","11250.0000"],["0.0059920","0"],["0.0059970","4250.0000"],["0.0059980","0"],["0.0060030","2750.0000"],["0.0060040","0"],["0.0060090","7750.0000"],["0.0060100","0"],["0.0060150","9750.0000"],["0.0060160","0"],["0.0060210","3750.0000"],["0.0060220","0"]],"bids":[["0.0056170","890.1600"],["0.0056160","43179.3000"],["0.0056150","82521.0000"],["0.0056130","110285.6400"],["0.0056120","256469.8500"],["0.0056110","91369.3500"],["0.0056100","590960.2500"],["0.0056090","22550.4000"],["0.0056080","800000.0000"],["0.0056040","6611.4000"],["0.0056030","151397.4300"],["0.0056010","295005.1500"],["0.0056000","800000.0000"],["0.0055980","73468.3500"],["0.0055960","180502.6500"],["0.0055830","212287.5000"],["0.0055730","42040.8000"],["0.0055660","7897.5000"],["0.0055590","215988.7500"],["0.0053440","9750.0000"],["0.0053380","6250.0000"],["0.0053320","10250.0000"],["0.0053260","4250.0000"],["0.0053140","9250.0000"],["0.0053080","3750.0000"],["0.0053020","5750.0000"],["0.0052960","12250.0000"],["0.0052900","10750.0000"],["0.0052840","11250.0000"],["0.0052780","11750.0000"],["0.0052720","3250.0000"],["0.0052660","2750.0000"],["0.0052600","8750.0000"],["0.0052540","8250.0000"],["0.0052480","7750.0000"],["0.0052420","5250.0000"],["0.0052360","4750.0000"],["0.0052300","6750.0000"]],"checksum":-1810958742,"ts":"1649290080237"}]}
1649290080.300437: {"action":"update","arg":{"instType":"sp","channel":"books","instId":"GOGUSDT"},"data":[{"asks":[["0.5625","9.0000"],["0.5631","8.8804"],["0.5637","12.3333"],["0.5643","15.6667"],["0.5649","14.3333"],["0.5655","2348.8000"],["0.5661","8.8334"],["0.5667","8.8240"],["0.5685","9.6667"],["0.5691","11.0000"],["0.5697","11.6667"],["0.5703","10.3333"],["0.5709","8.7591"],["0.5733","13.0000"],["0.5739","13.6667"]],"bids":[["0.5500","15.0000"],["0.5494","12.3333"],["0.5488","16.3333"],["0.5482","3678.9000"],["0.5476","9.1318"],["0.5464","9.6667"],["0.5458","13.6667"],["0.5452","11.6667"],["0.5440","15.6667"],["0.5434","11.0000"],["0.5428","9.2125"],["0.5422","9.2227"],["0.5410","9.2431"],["0.5404","14.3333"],["0.5398","10.3333"]],"checksum":-2042728763,"ts":"1649290080277"}]}
1649290080.306754: {"action":"update","arg":{"instType":"sp","channel":"candle1m","instId":"HOTUSDT"},"data":[["1649290080000","0.005613","0.005613","0.005613","0.005613","0"]]}
1649290080.320149: {"action":"update","arg":{"instType":"sp","channel":"candle1m","instId":"CULTUSDT"},"data":[["1649290080000","0.00003507","0.00003507","0.00003507","0.00003507","0"]]}
1649290080.327976: {"action":"update","arg":{"instType":"sp","channel":"books","instId":"VVSUSDT"},"data":[{"asks":[["0.00002370","821637.4000"],["0.00002373","616959.1000"],["0.00002379","862573.1000"],["0.00002382","535087.7000"],["0.00002385","780701.8000"],["0.00002391","248538.0000"],["0.00002397","371345.0000"],["0.00002403","289473.7000"],["0.00002406","412280.7000"],["0.00002409","576023.4000"]],"bids":[["0.00002267","780701.8000"],["0.00002261","289473.7000"],["0.00002255","698830.4000"],["0.00002249","330409.4000"],["0.00002243","821637.4000"],["0.00002240","248538.0000"],["0.00002237","862573.1000"],["0.00002234","371345.0000"],["0.00002231","224115.7000"],["0.00002228","657894.7000"]],"checksum":791825490,"ts":"1649290080305"}]}
1649290080.369388: {"action":"update","arg":{"instType":"sp","channel":"books","instId":"STGUSDT"},"data":[{"asks":[["2.902","36.372"],["2.908","41.370"],["2.937","82.250"],["2.938","0"],["2.941","0"],["2.944","0"],["2.946","0"],["3.026","2.619"],["3.029","1.652"],["3.032","1.650"],["3.034","0"],["3.035","1.648"],["3.037","0"],["3.038","3.449"],["3.040","0"],["3.041","2.204"],["3.043","0"],["3.044","2.895"],["3.046","0"],["3.047","3.034"],["3.049","3.185"],["3.050","3.310"],["3.052","0"],["3.053","2.065"],["3.055","0"],["3.056","2.757"],["3.058","0"],["3.059","1.927"],["3.061","0"],["3.062","3.725"],["3.064","0"],["3.065","2.342"],["3.067","0"],["3.068","3.587"],["3.070","0"],["3.071","3.172"],["3.073","0"],["3.074","2.480"],["3.076","0"],["3.077","1.626"],["3.079","3.157"],["3.080","1.650"],["3.082","0"],["3.083","1.623"],["3.085","0"],["3.086","1.621"],["3.088","0"],["3.089","1.789"],["3.091","0"],["3.094","0"],["3.097","0"],["3.100","0"],["3.513","43.204"],["3.528","2.751"],["3.563","2.723"]],"bids":[["2.755","0"],["2.744","0"],["2.741","0"],["2.738","17.752"],["2.737","3.077"],["2.735","0"],["2.734","42.170"],["2.732","97.531"],["2.731","20.269"],["2.729","0"],["2.728","1.834"],["2.726","72.821"],["2.725","2.646"],["2.723","39.648"],["2.722","1.838"],["2.720","0"],["2.719","2.862"],["2.717","0"],["2.716","1.842"],["2.714","0"],["2.713","2.969"],["2.711","0"],["2.710","1.846"],["2.708","0"],["2.707","2.000"],["2.705","0"],["2.704","2.323"],["2.702","0"],["2.701","2.431"],["2.699","0"],["2.698","2.538"],["2.696","91.385"],["2.695","2.108"],["2.693","0"],["2.692","1.858"],["2.690","0"],["2.689","1.860"],["2.687","0"],["2.686","2.215"],["2.684","0"],["2.683","1.865"],["2.681","0"],["2.680","3.185"],["2.678","0"],["2.677","3.292"],["2.675","0"],["2.674","2.754"],["2.672","0"],["2.671","1.873"],["2.668","1.875"],["2.665","1.877"]],"checksum":-946414897,"ts":"1649290080341"}]}
1649290080.3699431: {"action":"update","arg":{"instType":"sp","channel":"books","instId":"AVAXUSDT"},"data":[{"asks":[["83.1515","19.9850"],["83.1615","34.1600"],["83.1715","8.9250"],["83.1815","27.6570"],["83.1915","167.3490"],["83.2115","76.6570"],["83.2515","180.0000"],["83.2615","142.2890"],["83.2715","126.7490"],["83.2915","8.0430"],["83.4715","9.7020"],["83.5115","2.9680"],["83.7015","0"],["83.7115","0"],["83.7215","0"],["88.0383","0.2167"],["88.0701","0"],["88.1214","0.3833"],["88.1532","0"],["88.2045","0.6833"],["88.2363","0"],["88.2876","0.4833"],["88.3194","0"],["88.3707","0.3500"],["88.4025","0"],["88.4538","0.2833"],["88.4856","0"],["88.5369","0.7167"],["88.5687","0"],["88.6200","0.5833"],["88.6518","0"],["88.7031","0.6500"],["88.7349","0"],["88.7862","0.2500"],["88.8180","0"],["88.8693","0.4167"],["88.9011","0"],["88.9524","0.5500"],["88.9842","0"],["89.0355","0.3167"],["89.0673","0"],["89.1186","0.8167"],["89.1504","0"],["89.2017","0.7500"],["89.2335","0"],["89.2848","0.1833"],["89.3166","0"],["89.3679","0.6167"],["89.3997","0"],["89.4510","0.5167"],["89.4828","0"],["89.5341","0.7833"],["89.5659","0"],["89.6172","0.4500"],["89.6490","0"]],"bids":[["82.9885","0"],["82.9785","0"],["82.9685","0"],["82.9585","17.9340"],["82.9485","42.1330"],["82.9385","49.2100"],["82.9285","106.9180"],["82.9085","146.6290"],["82.8685","180.0000"],["82.8585","0.6650"],["82.8485","11.5360"],["82.4985","23.8700"],["82.4885","180.0000"],["82.4785","114.2680"],["82.4685","180.0000"],["78.0998","0"],["78.0717","0.3500"],["78.0167","0"],["77.9886","0.1833"],["77.9336","0"],["77.9055","0.6167"],["77.8505","0"],["77.8224","0.2833"],["77.7674","0"],["77.7393","0.3167"],["77.6843","0"],["77.6562","0.5167"],["77.6012","0"],["77.5731","0.6500"],["77.5181","0"],["77.4900","0.6833"],["77.4350","0"],["77.4069","0.7167"],["77.3519","0"],["77.3238","0.8167"],["77.2688","0"],["77.2407","0.4500"],["77.1857","0"],["77.1576","0.3833"],["77.1026","0"],["77.0745","0.7833"],["77.0195","0"],["76.9914","0.4167"],["76.9364","0"],["76.9083","0.5500"],["76.8533","0"],["76.8252","0.4833"],["76.7702","0"],["76.7421","0.7500"],["76.6871","0"],["76.6590","0.2167"],["76.6040","0"],["76.5759","0.5833"],["76.5209","0"],["76.4928","0.2500"]],"checksum":-1374141708,"ts":"1649290080343"}]}
1649290080.370385: {"action":"update","arg":{"instType":"sp","channel":"candle1m","instId":"EOSUSDT"},"data":[["1649290080000","2.4383","2.4421","2.4383","2.4421","2.0702"]]}
1649290080.402018: {"action":"update","arg":{"instType":"sp","channel":"candle1m","instId":"AVAXUSDT"},"data":[["1649290080000","83.1253","83.1253","83.1253","83.1253","0"]]}
1649290080.4065878: {"action":"snapshot","arg":{"instType":"sp","channel":"ticker","instId":"VVSUSDT"},"data":[{"instId":"VVSUSDT","last":"0.00002324","open24h":"0.00002350","high24h":"0.00002359","low24h":"0.00002313","bestBid":"0.000024","bestAsk":"0.000024","baseVolume":"2375151440.6083","quoteVolume":"56979.8991","ts":1649290080328,"labeId":0}]}
1649290080.443308: {"action":"snapshot","arg":{"instType":"sp","channel":"ticker","instId":"AVAXUSDT"},"data":[{"instId":"AVAXUSDT","last":"83.1253","open24h":"85.1099","high24h":"86.7605","low24h":"82.5893","bestBid":"82.958500","bestAsk":"83.151500","baseVolume":"3330.7209","quoteVolume":"287723.8289","ts":1649290080353,"labeId":0}]}
1649290080.4433951: {"action":"snapshot","arg":{"instType":"sp","channel":"ticker","instId":"HOTUSDT"},"data":[{"instId":"HOTUSDT","last":"0.0056130","open24h":"0.0058560","high24h":"0.0059320","low24h":"0.0055520","bestBid":"0.005617","bestAsk":"0.005635","baseVolume":"10203207.8809","quoteVolume":"60796.5347","ts":1649290080376,"labeId":0}]}
1649290080.457031: {"action":"update","arg":{"instType":"sp","channel":"trade","instId":"SUNUSDT"},"data":[["1649290080392","0.01505","1432","buy"]]}
1649290080.472073: {"action":"update","arg":{"instType":"sp","channel":"books","instId":"CULTUSDT"},"data":[{"asks":[["0.00003614","226667"],["0.00003618","520000"],["0.00003622","653333"],["0.00003626","466667"],["0.00003630","173333"],["0.00003634","440000"],["0.00003638","306667"],["0.00003642","253333"],["0.00003646","847056"],["0.00003650","386667"],["0.00003654","626667"],["0.00003658","333333"],["0.00003662","200000"],["0.00003666","360000"],["0.00003670","413333"],["0.00003674","280000"],["0.00003678","600000"],["0.00003682","146667"],["0.00003686","546667"]],"bids":[["0.00003471","653333"],["0.00003467","1715230"],["0.00003463","466667"],["0.00003459","226667"],["0.00003455","908154"],["0.00003451","546667"],["0.00003447","360000"],["0.00003443","600000"],["0.00003439","440000"],["0.00003435","280000"],["0.00003431","173333"],["0.00003423","146667"],["0.00003419","333333"],["0.00003415","386667"],["0.00003411","200000"],["0.00003407","493333"],["0.00003403","306667"],["0.00003399","626667"],["0.00003395","253333"]],"checksum":-152869014,"ts":"1649290080450"}]}
1649290080.472399: {"action":"snapshot","arg":{"instType":"sp","channel":"ticker","instId":"GOGUSDT"},"data":[{"instId":"GOGUSDT","last":"0.5555","open24h":"0.5563","high24h":"0.5708","low24h":"0.5508","bestBid":"0.554700","bestAsk":"0.559000","baseVolume":"134629.2566","quoteVolume":"78736.7865","ts":1649290080414,"labeId":0}]}
1649290080.513802: {"action":"update","arg":{"instType":"sp","channel":"candle1m","instId":"SUNUSDT"},"data":[["1649290080000","0.01507","0.01507","0.01505","0.01505","1432"]]}
1649290080.5138948: {"action":"snapshot","arg":{"instType":"sp","channel":"ticker","instId":"SUNUSDT"},"data":[{"instId":"SUNUSDT","last":"0.01505","open24h":"0.01521","high24h":"0.01559","low24h":"0.01481","bestBid":"0.015040","bestAsk":"0.015080","baseVolume":"11682349","quoteVolume":"180214","ts":1649290080446,"labeId":0}]}
1649290080.537089: {"action":"update","arg":{"instType":"sp","channel":"books","instId":"EOSUSDT"},"data":[{"asks":[["2.4434","0"],["2.4438","0"],["2.4441","0"],["2.4442","48.6687"],["2.4443","0"],["2.4444","0"],["2.4446","110.2267"],["2.4448","379.2456"],["2.4449","913.2937"],["2.4450","8.0450"],["2.4451","180.0000"],["2.4452","311.2178"],["2.4453","0"],["2.4454","644.8500"],["2.4455","453.7847"],["2.4456","105.3369"],["2.4457","1863.1789"],["2.4458","1129.3861"],["2.4459","974.9798"],["2.4460","392.7242"],["2.4461","1404.8463"],["2.4462","1662.7231"],["2.4463","2317.0604"],["2.4464","91.3771"],["2.4465","3983.9171"],["2.4466","1070.8604"],["2.4467","560.0820"],["2.4469","3155.2813"],["2.4470","3182.1558"],["2.4471","1859.0880"],["2.4472","2231.7321"],["2.4474","6048.0000"],["2.4477","198.4707"],["2.4478","2826.2638"],["2.4479","3246.3884"],["2.4480","1712.7194"],["2.4481","2599.6500"],["2.4483","156.9761"],["2.4486","773.2276"],["2.4488","1148.4571"],["2.4492","680.6122"],["2.4495","600.3450"],["2.4496","375.5700"],["2.4497","358.7103"],["2.4585","0"],["2.4589","540.4762"],["2.4590","0"],["2.4594","516.6667"],["2.4595","0"],["2.4599","478.5714"],["2.4600","0"],["2.4604","459.5238"],["2.4605","0"],["2.4609","521.4286"],["2.4610","0"],["2.4614","545.2381"],["2.4615","0"],["2.4619","535.7143"],["2.4620","0"],["2.4624","511.9048"],["2.4625","0"],["2.4629","469.0476"],["2.4630","0"],["2.4634","502.3810"],["2.4635","0"],["2.4639","497.6190"],["2.4640","0"],["2.4644","464.2857"],["2.4645","0"],["2.4649","483.3333"],["2.4650","50.0000"],["2.4654","492.8571"],["2.4655","0"],["2.4659","473.8095"],["2.4660","0"],["2.4664","507.1429"],["2.4665","0"],["2.4669","488.0952"],["2.4670","0"],["2.4674","530.9524"],["2.4675","0"],["2.4679","454.7619"],["2.4680","0"],["2.4684","526.1905"]],"bids":[["2.4397","8.0494"],["2.4396","35.0100"],["2.4395","59.6143"],["2.4392","1005.2936"],["2.4391","244.7482"],["2.4390","8.0500"],["2.4389","8.0501"],["2.4388","0"],["2.4387","1293.2121"],["2.4386","1153.2456"],["2.4385","948.9000"],["2.4384","11462.1399"],["2.4383","296.3322"],["2.4382","2763.2664"],["2.4381","1491.9300"],["2.4380","1551.8991"],["2.4379","1180.3250"],["2.4378","77.3612"],["2.4377","1376.3635"],["2.4376","150.3456"],["2.4375","244.0417"],["2.4374","1767.9299"],["2.4371","1726.0175"],["2.4370","1285.3596"],["2.4369","1395.6121"],["2.4367","862.8285"],["2.4366","564.5443"],["2.4365","3574.1571"],["2.4364","1344.1582"],["2.4362","113.2178"],["2.4361","1583.6384"],["2.4360","1067.1158"],["2.4359","1867.2117"],["2.4358","1849.1040"],["2.4357","0"],["2.4356","1208.6816"],["2.4355","1344.1582"],["2.4354","1983.0608"],["2.4353","184.9594"],["2.4351","3342.1410"],["2.4349","2209.6863"],["2.4348","738.2557"],["2.4347","676.5642"],["2.4345","267.2048"],["2.4343","0"],["2.4342","0"],["2.4341","0"],["2.4340","0"],["2.4339","0"],["2.4337","0"],["2.4336","0"],["2.4247","473.8095"],["2.4243","0"],["2.4242","516.6667"],["2.4238","0"],["2.4237","540.4762"],["2.4233","0"],["2.4232","469.0476"],["2.4228","0"],["2.4227","526.1905"],["2.4223","0"],["2.4222","545.2381"],["2.4218","0"],["2.4217","511.9048"],["2.4213","0"],["2.4212","483.3333"],["2.4208","0"],["2.4207","478.5714"],["2.4203","0"],["2.4202","521.4286"],["2.4198","0"],["2.4197","492.8571"],["2.4193","0"],["2.4192","530.9524"],["2.4188","0"],["2.4187","459.5238"],["2.4183","0"],["2.4182","497.6190"],["2.4178","0"],["2.4177","488.0952"],["2.4173","0"],["2.4172","507.1429"],["2.4168","0"],["2.4167","502.3810"],["2.4163","0"],["2.4162","454.7619"],["2.4158","0"],["2.4157","535.7143"],["2.4153","0"],["2.4152","464.2857"],["2.4148","0"]],"checksum":1405151201,"ts":"1649290080512"}]}
1649290080.546643: {"action":"update","arg":{"instType":"sp","channel":"books","instId":"SUNUSDT"},"data":[{"asks":[["0.01508","9649"],["0.01509","78861"],["0.01510","16180"],["0.01511","258576"],["0.01512","276083"],["0.01513","54520"],["0.01514","289219"],["0.01515","1038873"],["0.01517","6117"],["0.01582","4167"],["0.01584","7500"],["0.01586","6167"],["0.01588","8167"],["0.01590","3167"],["0.01592","2500"],["0.01594","2833"],["0.01596","7167"],["0.01598","3500"],["0.01600","6500"],["0.01602","5833"],["0.01604","1833"],["0.01606","4833"],["0.01608","5167"],["0.01610","4500"],["0.01612","2167"],["0.01614","3833"],["0.01616","5500"],["0.01618","7833"],["0.01620","6833"]],"bids":[["0.01504","27266"],["0.01503","181800"],["0.01502","108996"],["0.01501","637755"],["0.01500","542147"],["0.01498","22917"],["0.01495","82308"],["0.01493","624236"],["0.01486","11602"],["0.01485","291948"],["0.01430","7833"],["0.01428","8167"],["0.01426","3833"],["0.01424","3500"],["0.01422","3167"],["0.01420","2500"],["0.01418","4833"],["0.01416","1833"],["0.01414","5500"],["0.01412","5833"],["0.01410","4500"],["0.01408","6500"],["0.01406","5167"],["0.01404","2167"],["0.01402","7500"],["0.01400","7167"],["0.01398","2833"],["0.01396","6833"],["0.01394","4167"],["0.01392","6167"]],"checksum":852979247,"ts":"1649290080524"}]}
1649290080.561661: {"action":"snapshot","arg":{"instType":"sp","channel":"ticker","instId":"STGUSDT"},"data":[{"instId":"STGUSDT","last":"2.881","open24h":"3.045","high24h":"3.164","low24h":"2.757","bestBid":"2.861000","bestAsk":"2.902000","baseVolume":"35327.890","quoteVolume":"111744.124","ts":1649290080489,"labeId":0}]}
1649290080.5650518: {"action":"snapshot","arg":{"instType":"sp","channel":"ticker","instId":"CULTUSDT"},"data":[{"instId":"CULTUSDT","last":"0.00003507","open24h":"0.00004340","high24h":"0.00004397","low24h":"0.00003500","bestBid":"0.000036","bestAsk":"0.000036","baseVolume":"13526772930","quoteVolume":"557436","ts":1649290080509,"labeId":0}]}
1649290080.5978072: {"action":"update","arg":{"instType":"sp","channel":"candle1m","instId":"STGUSDT"},"data":[["1649290080000","2.881","2.881","2.881","2.881","0"]]}
1649290080.8138518: {"action":"update","arg":{"instType":"sp","channel":"books","instId":"GOGUSDT"},"data":[{"asks":[["0.5625","10.3333"],["0.5637","8.8710"],["0.5643","8.8615"],["0.5649","13.0000"],["0.5655","2345.4667"],["0.5661","11.0000"],["0.5679","15.6667"],["0.5685","9.0000"],["0.5691","9.6667"],["0.5697","13.6667"],["0.5703","16.3333"],["0.5721","14.3333"],["0.5727","12.3333"],["0.5733","8.7224"],["0.5739","15.0000"]],"bids":[["0.5512","15.7333"],["0.5500","9.0919"],["0.5494","15.0000"],["0.5488","9.6667"],["0.5482","3681.5667"],["0.5470","13.6667"],["0.5464","9.1518"],["0.5458","9.1619"],["0.5452","9.1719"],["0.5446","10.3333"],["0.5440","9.1922"],["0.5422","13.0000"],["0.5416","11.6667"],["0.5410","12.3333"],["0.5404","16.3333"],["0.5398","9.2637"]],"checksum":-694687944,"ts":"1649290080787"}]}
1649290080.8227: {"action":"update","arg":{"instType":"sp","channel":"books","instId":"HOTUSDT"},"data":[{"asks":[["0.0056320","41896.8000"],["0.0056330","43753.9500"],["0.0056340","455665.0500"],["0.0056350","320683.5000"],["0.0056370","431889.3000"],["0.0056400","255134.7000"],["0.0056470","216382.0500"],["0.0056480","11998.8000"],["0.0056510","604035.9000"],["0.0056520","159442.2000"],["0.0056540","62916.7500"],["0.0056740","23150.2500"],["0.0056910","0"],["0.0056930","0"],["0.0056940","0"],["0.0059060","11250.0000"],["0.0059070","0"],["0.0059120","5750.0000"],["0.0059130","0"],["0.0059180","4750.0000"],["0.0059190","0"],["0.0059240","5250.0000"],["0.0059250","0"],["0.0059300","8250.0000"],["0.0059310","0"],["0.0059360","3250.0000"],["0.0059370","0"],["0.0059420","6250.0000"],["0.0059430","0"],["0.0059480","3750.0000"],["0.0059490","0"],["0.0059540","10750.0000"],["0.0059550","0"],["0.0059600","4250.0000"],["0.0059610","0"],["0.0059660","12250.0000"],["0.0059670","0"],["0.0059720","9250.0000"],["0.0059730","0"],["0.0059780","7250.0000"],["0.0059790","0"],["0.0059840","10250.0000"],["0.0059850","0"],["0.0059900","2750.0000"],["0.0059910","0"],["0.0059960","8750.0000"],["0.0059970","0"],["0.0060020","7750.0000"],["0.0060030","0"],["0.0060080","11750.0000"],["0.0060090","0"],["0.0060140","9750.0000"],["0.0060150","0"],["0.0060200","6750.0000"],["0.0060210","0"]],"bids":[["0.0056160","0"],["0.0056150","51273.0000"],["0.0056140","57267.0000"],["0.0056130","83067.8400"],["0.0056120","278218.3500"],["0.0056110","160188.3000"],["0.0056100","208875.6000"],["0.0056090","42199.2000"],["0.0056050","53242.2000"],["0.0056030","155397.0300"],["0.0055980","38936.7000"],["0.0055700","628394.8500"],["0.0055660","4743.0000"],["0.0055570","546189.3000"],["0.0053440","0"],["0.0053430","4250.0000"],["0.0053380","0"],["0.0053370","5250.0000"],["0.0053320","0"],["0.0053310","12250.0000"],["0.0053260","0"],["0.0053250","6250.0000"],["0.0053200","0"],["0.0053190","10250.0000"],["0.0053140","0"],["0.0053130","11750.0000"],["0.0053080","0"],["0.0053070","3750.0000"],["0.0053020","0"],["0.0053010","2750.0000"],["0.0052960","0"],["0.0052950","5750.0000"],["0.0052900","0"],["0.0052890","9750.0000"],["0.0052840","0"],["0.0052830","8750.0000"],["0.0052780","0"],["0.0052770","10750.0000"],["0.0052720","0"],["0.0052710","4750.0000"],["0.0052660","0"],["0.0052650","8250.0000"],["0.0052600","0"],["0.0052590","3250.0000"],["0.0052540","0"],["0.0052530","6750.0000"],["0.0052480","0"],["0.0052470","11250.0000"],["0.0052420","0"],["0.0052410","7250.0000"],["0.0052360","0"],["0.0052350","9250.0000"],["0.0052300","0"],["0.0052290","7750.0000"]],"checksum":606631625,"ts":"1649290080796"}]}
1649290080.857385: {"action":"update","arg":{"instType":"sp","channel":"candle1m","instId":"VVSUSDT"},"data":[["1649290080000","0.00002324","0.00002324","0.00002324","0.00002324","0"]]}
1649290080.8918889: {"action":"update","arg":{"instType":"sp","channel":"books","instId":"STGUSDT"},"data":[{"asks":[["2.902","0"],["2.908","0"],["3.026","0"],["3.029","0"],["3.032","0"],["3.034","1.649"],["3.035","0"],["3.037","1.927"],["3.038","0"],["3.040","2.204"],["3.041","0"],["3.043","3.310"],["3.044","0"],["3.046","1.642"],["3.047","0"],["3.049","4.420"],["3.050","0"],["3.052","1.650"],["3.053","0"],["3.055","1.638"],["3.056","0"],["3.058","2.342"],["3.059","0"],["3.061","2.065"],["3.062","0"],["3.064","1.633"],["3.065","0"],["3.067","3.034"],["3.068","0"],["3.070","3.449"],["3.071","0"],["3.073","1.789"],["3.074","0"],["3.076","2.757"],["3.077","0"],["3.079","6.329"],["3.080","0"],["3.082","2.480"],["3.083","0"],["3.085","2.895"],["3.086","0"],["3.088","2.619"],["3.089","0"],["3.091","1.619"],["3.094","3.587"],["3.097","3.725"],["3.573","291.494"],["3.598","2.695"]],"bids":[["2.744","2.646"],["2.741","2.538"],["2.738","20.506"],["2.737","0"],["2.735","3.292"],["2.734","40.278"],["2.732","98.239"],["2.731","18.592"],["2.729","1.833"],["2.728","0"],["2.726","75.144"],["2.725","0"],["2.723","42.617"],["2.722","0"],["2.720","3.077"],["2.719","0"],["2.717","1.841"],["2.716","0"],["2.714","2.000"],["2.713","0"],["2.711","2.215"],["2.710","0"],["2.708","1.847"],["2.707","0"],["2.705","3.185"],["2.704","0"],["2.702","1.851"],["2.701","0"],["2.699","1.854"],["2.698","0"],["2.696","92.308"],["2.695","0"],["2.693","2.108"],["2.692","0"],["2.690","1.860"],["2.689","0"],["2.687","1.862"],["2.686","0"],["2.684","2.862"],["2.683","0"],["2.681","1.866"],["2.680","0"],["2.678","1.892"],["2.677","0"],["2.675","2.431"],["2.674","0"],["2.672","1.872"],["2.671","0"],["2.668","0"],["2.665","0"]],"checksum":-1104196442,"ts":"1649290080870"}]}
1649290080.902456: {"action":"update","arg":{"instType":"sp","channel":"books","instId":"VVSUSDT"},"data":[{"asks":[["0.00002370","248538.0000"],["0.00002373","371345.0000"],["0.00002379","494152.0000"],["0.00002382","209908.6000"],["0.00002385","330409.4000"],["0.00002391","535087.7000"],["0.00002397","780701.8000"],["0.00002403","903508.8000"],["0.00002406","821637.4000"],["0.00002409","289473.7000"]],"bids":[["0.00002267","453216.4000"],["0.00002261","739766.1000"],["0.00002258","371345.0000"],["0.00002255","821637.4000"],["0.00002252","535087.7000"],["0.00002249","657894.7000"],["0.00002243","576023.4000"],["0.00002240","616959.1000"],["0.00002237","903508.8000"],["0.00002234","223814.8000"],["0.00002231","494152.0000"],["0.00002228","248538.0000"]],"checksum":-1358369860,"ts":"1649290080880"}]}
1649290080.9304729: {"action":"update","arg":{"instType":"sp","channel":"books","instId":"AVAXUSDT"},"data":[{"asks":[["83.1515","21.0140"],["83.1615","76.3070"],["83.1715","22.8270"],["83.1915","180.0000"],["83.2115","38.0520"],["83.2515","142.7510"],["83.2715","153.9860"],["83.2815","11.2280"],["83.4015","4.6270"],["83.4715","5.0750"],["83.5215","0.2660"],["83.5615","1.8970"],["83.6915","0"],["88.0383","0.5500"],["88.1214","0.4833"],["88.2045","0.6167"],["88.2876","0.6500"],["88.3707","0.3167"],["88.4538","0.5167"],["88.5369","0.2167"],["88.6200","0.8167"],["88.7031","0.3500"],["88.7862","0.7167"],["88.8693","0.5833"],["88.9524","0.1833"],["89.0355","0.4167"],["89.1186","0.2500"],["89.2848","0.2833"],["89.3679","0.3833"],["89.4510","0.6833"],["89.5341","0.4500"],["89.6172","0.7833"]],"bids":[["82.9585","11.2350"],["82.9485","1.9950"],["82.9285","23.1000"],["82.9185","75.6630"],["82.9085","108.0310"],["82.8985","34.9020"],["82.8885","109.2070"],["82.8785","69.1460"],["82.8585","172.1720"],["82.8485","180.0000"],["82.8385","58.1770"],["82.8285","180.0000"],["82.8185","173.1730"],["82.8085","180.0000"],["82.6685","79.7090"],["82.6285","70.0070"],["82.5885","8.5120"],["82.5485","101.0660"],["82.5285","16.8140"],["78.0717","0.7833"],["77.9886","0.7500"],["77.9055","0.2833"],["77.8224","0.1833"],["77.7393","0.5833"],["77.6562","0.2500"],["77.5731","0.4833"],["77.4900","0.7167"],["77.4069","0.3500"],["77.3238","0.5500"],["77.2407","0.8167"],["77.0745","0.6500"],["76.9914","0.6167"],["76.9083","0.6833"],["76.8252","0.2167"],["76.7421","0.5167"],["76.6590","0.4500"],["76.5759","0.4167"],["76.4928","0.3167"]],"checksum":652217465,"ts":"1649290080900"}]}
1649290080.98848: {"action":"update","arg":{"instType":"sp","channel":"books","instId":"CULTUSDT"},"data":[{"asks":[["0.00003614","173333"],["0.00003618","546667"],["0.00003622","146667"],["0.00003626","386667"],["0.00003630","200000"],["0.00003634","600000"],["0.00003638","653333"],["0.00003642","626667"],["0.00003646","580390"],["0.00003650","280000"],["0.00003654","466667"],["0.00003658","573333"],["0.00003662","493333"],["0.00003666","520000"],["0.00003670","440000"],["0.00003674","333333"],["0.00003678","360000"],["0.00003682","253333"],["0.00003686","413333"],["0.00003690","226667"]],"bids":[["0.00003467","1528564"],["0.00003463","546667"],["0.00003459","520000"],["0.00003455","854821"],["0.00003451","360000"],["0.00003447","280000"],["0.00003443","253333"],["0.00003439","173333"],["0.00003435","493333"],["0.00003431","226667"],["0.00003419","306667"],["0.00003415","200000"],["0.00003411","440000"],["0.00003407","333333"],["0.00003403","600000"],["0.00003395","573333"],["0.00003388","147581"],["0.00003144","0"]],"checksum":1569171680,"ts":"1649290080960"}]}
1649290081.053426: {"action":"update","arg":{"instType":"sp","channel":"books","instId":"EOSUSDT"},"data":[{"asks":[["2.4439","2493.1800"],["2.4442","120.6091"],["2.4446","57.8061"],["2.4447","17.9944"],["2.4448","203.1228"],["2.4449","856.0886"],["2.4450","43.7696"],["2.4451","103.5000"],["2.4452","362.7824"],["2.4453","2185.0740"],["2.4454","686.7720"],["2.4456","682.7576"],["2.4457","1113.8656"],["2.4458","1519.9754"],["2.4459","1244.3179"],["2.4460","797.6407"],["2.4461","1335.5163"],["2.4463","1704.0412"],["2.4464","104.9362"],["2.4466","3967.0929"],["2.4467","4338.0905"],["2.4469","3391.7563"],["2.4473","3668.5582"],["2.4474","3326.2381"],["2.4476","0"],["2.4477","368.5656"],["2.4479","4177.8884"],["2.4480","1269.2541"],["2.4484","0"],["2.4486","848.2276"],["2.4489","2153.4750"],["2.4498","8.0410"],["2.4587","488.0952"],["2.4589","0"],["2.4592","535.7143"],["2.4594","0"],["2.4597","464.2857"],["2.4599","0"],["2.4602","469.0476"],["2.4604","0"],["2.4607","497.6190"],["2.4609","0"],["2.4612","478.5714"],["2.4614","0"],["2.4617","502.3810"],["2.4619","0"],["2.4622","507.1429"],["2.4624","0"],["2.4627","459.5238"],["2.4629","0"],["2.4632","521.4286"],["2.4634","0"],["2.4637","511.9048"],["2.4639","0"],["2.4642","483.3333"],["2.4644","0"],["2.4647","473.8095"],["2.4649","0"],["2.4652","540.4762"],["2.4654","0"],["2.4657","545.2381"],["2.4659","0"],["2.4662","492.8571"],["2.4664","0"],["2.4667","526.1905"],["2.4669","0"],["2.4672","530.9524"],["2.4674","0"],["2.4677","454.7619"],["2.4679","0"],["2.4682","516.6667"],["2.4684","0"]],"bids":[["2.4397","0"],["2.4396","0"],["2.4395","0"],["2.4394","0"],["2.4393","476.6220"],["2.4392","8.0499"],["2.4391","57.2400"],["2.4388","19.3475"],["2.4387","2435.8894"],["2.4386","1488.7726"],["2.4385","1002.8223"],["2.4384","6285.9200"],["2.4383","308.0773"],["2.4381","476.7300"],["2.4380","1485.4950"],["2.4379","1125.0000"],["2.4376","235.0369"],["2.4375","469.5945"],["2.4374","1356.6299"],["2.4373","629.2916"],["2.4371","2124.7625"],["2.4367","935.7472"],["2.4366","240.4757"],["2.4365","3367.0714"],["2.4364","0"],["2.4363","411.7674"],["2.4361","2165.8784"],["2.4359","2539.2771"],["2.4356","955.7877"],["2.4355","415.9980"],["2.4354","1109.4081"],["2.4353","187.9967"],["2.4352","425.6658"],["2.4351","2492.5410"],["2.4350","1344.1307"],["2.4347","553.2642"],["2.4345","42.2048"],["2.4344","1491.1106"],["2.4343","602.3126"],["2.4342","1901.6618"],["2.4341","3979.4804"],["2.4247","0"],["2.4245","540.4762"],["2.4242","0"],["2.4240","516.6667"],["2.4237","0"],["2.4235","473.8095"],["2.4232","0"],["2.4230","507.1429"],["2.4227","0"],["2.4225","497.6190"],["2.4222","0"],["2.4220","545.2381"],["2.4217","0"],["2.4215","464.2857"],["2.4212","0"],["2.4210","488.0952"],["2.4207","0"],["2.4205","535.7143"],["2.4202","0"],["2.4200","526.1905"],["2.4197","0"],["2.4195","521.4286"],["2.4192","0"],["2.4190","502.3810"],["2.4187","0"],["2.4185","459.5238"],["2.4182","0"],["2.4180","530.9524"],["2.4177","0"],["2.4175","492.8571"],["2.4172","0"],["2.4170","478.5714"],["2.4167","0"],["2.4165","469.0476"],["2.4162","0"],["2.4160","483.3333"],["2.4157","0"],["2.4155","454.7619"],["2.4152","0"],["2.4150","511.9048"]],"checksum":-314398875,"ts":"1649290081031"}]}
1649290081.101622: {"action":"update","arg":{"instType":"sp","channel":"books","instId":"SUNUSDT"},"data":[{"asks":[["0.01508","184739"],["0.01509","87712"],["0.01510","5155"],["0.01511","212427"],["0.01512","248750"],["0.01513","57186"],["0.01514","334219"],["0.01515","1037299"],["0.01517","6131"],["0.01518","829"],["0.01528","2004"],["0.01582","7833"],["0.01584","8167"],["0.01586","3500"],["0.01588","2833"],["0.01590","2500"],["0.01592","7167"],["0.01594","5500"],["0.01596","5833"],["0.01598","4167"],["0.01602","6833"],["0.01604","4500"],["0.01608","6167"],["0.01610","2167"],["0.01612","3167"],["0.01614","1833"],["0.01616","5167"],["0.01618","7500"],["0.01620","3833"]],"bids":[["0.01504","569758"],["0.01503","415140"],["0.01502","94138"],["0.01501","585230"],["0.01500","454910"],["0.01499","1358875"],["0.01498","8472"],["0.01496","457066"],["0.01495","22855"],["0.01493","642954"],["0.01489","682452"],["0.01488","4275"],["0.01486","21016"],["0.01485","437770"],["0.01453","5064"],["0.01430","2167"],["0.01428","2833"],["0.01426","4833"],["0.01424","3833"],["0.01422","4167"],["0.01420","5167"],["0.01418","5833"],["0.01414","7500"],["0.01412","4500"],["0.01410","2500"],["0.01408","7167"],["0.01406","8167"],["0.01404","7833"],["0.01402","3167"],["0.01400","5500"],["0.01398","6500"],["0.01396","6167"],["0.01394","3500"],["0.01392","6833"]],"checksum":-2019825375,"ts":"1649290081079"}]}
1649290081.348139: {"action":"update","arg":{"instType":"sp","channel":"books","instId":"GOGUSDT"},"data":[{"asks":[["0.5625","15.6667"],["0.5631","9.6667"],["0.5637","12.3333"],["0.5643","11.6667"],["0.5649","8.8521"],["0.5655","2348.8000"],["0.5661","10.3333"],["0.5667","16.3333"],["0.5679","8.8054"],["0.5685","8.7961"],["0.5691","14.3333"],["0.5703","8.7683"],["0.5715","9.0000"],["0.5721","13.0000"],["0.5727","8.7316"],["0.5739","11.0000"]],"bids":[["0.5512","9.7333"],["0.5506","9.6667"],["0.5500","11.6667"],["0.5494","15.6667"],["0.5488","16.3333"],["0.5482","3678.2333"],["0.5476","13.6667"],["0.5470","13.0000"],["0.5446","9.1821"],["0.5440","11.0000"],["0.5434","9.2023"],["0.5428","14.3333"],["0.5422","10.3333"],["0.5416","15.0000"],["0.5410","9.2431"],["0.5404","9.2534"]],"checksum":-898232788,"ts":"1649290081325"}]}
1649290081.3555899: {"action":"update","arg":{"instType":"sp","channel":"books","instId":"HOTUSDT"},"data":[{"asks":[["0.0056310","887.9500"],["0.0056320","89146.8000"],["0.0056330","32097.1500"],["0.0056340","111556.8000"],["0.0056350","163991.7000"],["0.0056370","233067.6000"],["0.0056390","329551.6500"],["0.0056400","253534.5000"],["0.0056430","766888.6500"],["0.0056440","79877.7000"],["0.0056470","328111.2000"],["0.0056480","0"],["0.0056600","96598.8000"],["0.0056880","39999.6000"],["0.0056890","0"],["0.0059050","8250.0000"],["0.0059060","0"],["0.0059110","2750.0000"],["0.0059120","0"],["0.0059170","10750.0000"],["0.0059180","0"],["0.0059230","5250.0000"],["0.0059240","0"],["0.0059290","6250.0000"],["0.0059300","0"],["0.0059350","9250.0000"],["0.0059360","0"],["0.0059410","11250.0000"],["0.0059420","0"],["0.0059470","9750.0000"],["0.0059480","0"],["0.0059530","7250.0000"],["0.0059540","0"],["0.0059590","11750.0000"],["0.0059600","0"],["0.0059650","10250.0000"],["0.0059660","0"],["0.0059710","7750.0000"],["0.0059720","0"],["0.0059770","3250.0000"],["0.0059780","0"],["0.0059830","12250.0000"],["0.0059840","0"],["0.0059890","6750.0000"],["0.0059900","0"],["0.0059950","8750.0000"],["0.0059960","0"],["0.0060010","3750.0000"],["0.0060020","0"],["0.0060070","4250.0000"],["0.0060080","0"],["0.0060130","4750.0000"],["0.0060140","0"],["0.0060190","5750.0000"],["0.0060200","0"]],"bids":[["0.0056170","0"],["0.0056150","98523.0000"],["0.0056140","59836.5000"],["0.0056130","110288.3400"],["0.0056120","277418.2500"],["0.0056090","199902.1500"],["0.0056080","793003.0500"],["0.0056070","244377.0000"],["0.0056060","216834.7500"],["0.0056030","151397.4300"],["0.0056020","332191.8000"],["0.0056000","716642.5500"],["0.0055970","195020.1000"],["0.0055930","551367.8600"],["0.0055900","89424.9000"],["0.0055880","699390.0000"],["0.0055760","63070.2000"],["0.0055670","20812.5000"],["0.0055620","39999.6000"],["0.0055570","0"],["0.0053430","0"],["0.0053410","8750.0000"],["0.0053370","0"],["0.0053350","10750.0000"],["0.0053310","0"],["0.0053290","6750.0000"],["0.0053250","0"],["0.0053230","11750.0000"],["0.0053190","0"],["0.0053170","6250.0000"],["0.0053130","0"],["0.0053110","5750.0000"],["0.0053070","0"],["0.0053050","11250.0000"],["0.0053010","0"],["0.0052990","7750.0000"],["0.0052950","0"],["0.0052930","4750.0000"],["0.0052890","0"],["0.0052870","7250.0000"],["0.0052830","0"],["0.0052810","2750.0000"],["0.0052770","0"],["0.0052750","5250.0000"],["0.0052710","0"],["0.0052690","10250.0000"],["0.0052650","0"],["0.0052630","9250.0000"],["0.0052590","0"],["0.0052570","9750.0000"],["0.0052530","0"],["0.0052510","3750.0000"],["0.0052470","0"],["0.0052450","3250.0000"],["0.0052410","0"],["0.0052390","8250.0000"],["0.0052350","0"],["0.0052330","4250.0000"],["0.0052290","0"],["0.0052270","12250.0000"]],"checksum":-1270633376,"ts":"1649290081328"}]}
1649290081.406614: {"action":"update","arg":{"instType":"sp","channel":"books","instId":"VVSUSDT"},"data":[{"asks":[["0.00002370","371345.0000"],["0.00002373","453216.4000"],["0.00002379","739766.1000"],["0.00002382","657894.7000"],["0.00002385","248538.0000"],["0.00002391","209118.5000"],["0.00002397","535087.7000"],["0.00002403","821637.4000"],["0.00002406","494152.0000"],["0.00002409","698830.4000"]],"bids":[["0.00002267","494152.0000"],["0.00002258","535087.7000"],["0.00002255","221730.5000"],["0.00002252","616959.1000"],["0.00002249","698830.4000"],["0.00002243","412280.7000"],["0.00002240","330409.4000"],["0.00002237","862573.1000"],["0.00002234","821637.4000"],["0.00002231","903508.8000"],["0.00002228","453216.4000"]],"checksum":1792069516,"ts":"1649290081385"}]}
1649290081.455598: {"action":"update","arg":{"instType":"sp","channel":"books","instId":"STGUSDT"},"data":[{"asks":[["2.936","54.320"],["2.942","44.982"],["3.034","2.301"],["3.037","1.647"],["3.040","2.935"],["3.043","2.047"],["3.046","3.188"],["3.049","6.247"],["3.052","1.667"],["3.058","3.569"],["3.061","1.634"],["3.064","3.315"],["3.067","1.631"],["3.070","1.630"],["3.073","1.628"],["3.076","1.626"],["3.079","5.965"],["3.082","3.442"],["3.085","1.793"],["3.088","2.681"],["3.091","2.554"],["3.094","2.174"],["3.097","1.920"],["3.100","2.428"],["3.573","0"],["3.598","0"]],"bids":[["2.759","41.923"],["2.753","11.235"],["2.744","2.431"],["2.741","2.108"],["2.738","18.567"],["2.735","1.829"],["2.732","100.500"],["2.726","76.113"],["2.724","0"],["2.723","2.862"],["2.720","1.839"],["2.714","2.215"],["2.711","1.845"],["2.705","1.892"],["2.702","2.754"],["2.696","93.923"],["2.693","2.323"],["2.690","3.077"],["2.687","2.646"],["2.684","1.864"],["2.681","3.185"],["2.678","1.868"],["2.675","1.870"],["2.672","2.000"]],"checksum":476211897,"ts":"1649290081430"}]}
1649290081.481141: {"action":"update","arg":{"instType":"sp","channel":"books","instId":"AVAXUSDT"},"data":[{"asks":[["83.1413","7.3751"],["83.1515","0"],["83.1615","0"],["83.1715","30.1000"],["83.1815","35.1050"],["83.1915","165.6900"],["83.2015","12.6700"],["83.2115","71.5680"],["83.2515","83.7760"],["83.2815","176.6310"],["83.6115","104.9860"],["83.6915","2.4220"],["83.7015","2.4150"],["88.0383","0"],["88.0596","0.3833"],["88.1214","0"],["88.1427","0.5833"],["88.2045","0"],["88.2258","0.7833"],["88.2876","0"],["88.3089","0.2167"],["88.3707","0"],["88.3920","0.7500"],["88.4538","0"],["88.4751","0.6500"],["88.5369","0"],["88.5582","0.7167"],["88.6200","0"],["88.6413","0.3167"],["88.7031","0"],["88.7244","0.8167"],["88.7862","0"],["88.8075","0.1833"],["88.8693","0"],["88.8906","0.6167"],["88.9524","0"],["88.9737","0.6833"],["89.0355","0"],["89.0568","0.5167"],["89.1186","0"],["89.1399","0.2833"],["89.2017","0"],["89.2230","0.2500"],["89.2848","0"],["89.3061","0.4167"],["89.3679","0"],["89.3892","0.4500"],["89.4510","0"],["89.4723","0.4833"],["89.5341","0"],["89.5554","0.3500"],["89.6172","0"],["89.6385","0.5500"]],"bids":[["82.9785","13.0270"],["82.9685","22.7780"],["82.9585","43.0010"],["82.9485","110.4040"],["82.9385","82.7260"],["82.9285","6.5590"],["82.9185","0"],["82.9085","104.4890"],["82.8985","80.8990"],["82.8885","180.0000"],["82.8785","180.0000"],["82.8585","0.6650"],["82.8385","57.9670"],["82.7085","92.3860"],["82.6685","88.0390"],["82.6085","21.2450"],["82.5785","26.2010"],["82.4985","15.4420"],["82.4685","0"],["78.0904","0.6167"],["78.0717","0"],["78.0073","0.2167"],["77.9886","0"],["77.9242","0.4500"],["77.9055","0"],["77.8411","0.2833"],["77.8224","0"],["77.7580","0.7167"],["77.7393","0"],["77.6749","0.3833"],["77.6562","0"],["77.5918","0.4833"],["77.5731","0"],["77.5087","0.6833"],["77.4900","0"],["77.4256","0.2500"],["77.4069","0"],["77.3425","0.7833"],["77.3238","0"],["77.2594","0.5833"],["77.2407","0"],["77.1763","0.5500"],["77.1576","0"],["77.0932","0.1833"],["77.0745","0"],["77.0101","0.3500"],["76.9914","0"],["76.9270","0.5167"],["76.9083","0"],["76.8439","0.4167"],["76.8252","0"],["76.7608","0.6500"],["76.7421","0"],["76.6777","0.8167"],["76.6590","0"],["76.5946","0.3167"],["76.5759","0"],["76.5115","0.7500"],["76.4928","0"]],"checksum":1863870477,"ts":"1649290081459"}]}
1649290081.5402648: {"action":"update","arg":{"instType":"sp","channel":"books","instId":"CULTUSDT"},"data":[{"asks":[["0.00003614","386667"],["0.00003618","173333"],["0.00003622","520000"],["0.00003626","626667"],["0.00003630","306667"],["0.00003634","360000"],["0.00003638","466667"],["0.00003642","440000"],["0.00003646","607056"],["0.00003654","146667"],["0.00003658","413333"],["0.00003662","200000"],["0.00003666","493333"],["0.00003670","253333"],["0.00003674","653333"],["0.00003678","546667"],["0.00003682","226667"],["0.00003686","600000"],["0.00003690","573333"],["0.00003880","128867"],["0.00003916","0"],["0.00004065","123002"],["0.00004086","0"]],"bids":[["0.00003471","280000"],["0.00003467","1608564"],["0.00003463","200000"],["0.00003459","546667"],["0.00003455","721487"],["0.00003451","573333"],["0.00003447","413333"],["0.00003443","600000"],["0.00003435","253333"],["0.00003431","360000"],["0.00003427","306667"],["0.00003423","440000"],["0.00003419","226667"],["0.00003415","626667"],["0.00003411","653333"],["0.00003407","386667"],["0.00003403","493333"],["0.00003399","520000"],["0.00003395","147276"],["0.00003150","158731"],["0.00003145","0"]],"checksum":-973664622,"ts":"1649290081518"}]}
1649290081.659999: {"action":"update","arg":{"instType":"sp","channel":"books","instId":"EOSUSDT"},"data":[{"asks":[["2.4439","2204.1900"],["2.4442","84.4032"],["2.4443","83.8474"],["2.4446","0"],["2.4447","13.0481"],["2.4448","158.0356"],["2.4449","581.8291"],["2.4450","457.2534"],["2.4451","180.0000"],["2.4452","364.5041"],["2.4453","0"],["2.4455","304.5506"],["2.4457","1210.3384"],["2.4458","297.9194"],["2.4459","1654.5403"],["2.4460","2534.4872"],["2.4463","1634.7112"],["2.4466","4018.3929"],["2.4467","2208.4551"],["2.4470","1742.1558"],["2.4471","1362.2320"],["2.4472","2873.0296"],["2.4473","3259.9992"],["2.4474","2288.2005"],["2.4479","3446.7734"],["2.4480","2456.6040"],["2.4481","0"],["2.4484","8.0421"],["2.4486","965.2276"],["2.4493","145.9712"],["2.4497","29.0403"],["2.4586","526.1905"],["2.4587","0"],["2.4591","516.6667"],["2.4592","0"],["2.4596","469.0476"],["2.4597","0"],["2.4601","483.3333"],["2.4602","0"],["2.4606","459.5238"],["2.4607","0"],["2.4611","545.2381"],["2.4612","0"],["2.4616","540.4762"],["2.4617","0"],["2.4621","521.4286"],["2.4622","0"],["2.4626","464.2857"],["2.4627","0"],["2.4631","473.8095"],["2.4632","0"],["2.4636","488.0952"],["2.4637","0"],["2.4641","507.1429"],["2.4642","0"],["2.4646","478.5714"],["2.4647","0"],["2.4651","511.9048"],["2.4652","0"],["2.4656","492.8571"],["2.4657","0"],["2.4661","502.3810"],["2.4662","0"],["2.4666","454.7619"],["2.4667","0"],["2.4671","535.7143"],["2.4672","0"],["2.4676","497.6190"],["2.4677","0"],["2.4681","530.9524"],["2.4682","0"]],"bids":[["2.4393","0"],["2.4392","0"],["2.4391","265.0050"],["2.4390","975.5538"],["2.4388","0"],["2.4387","0"],["2.4386","2048.6421"],["2.4385","581.8966"],["2.4383","223.9122"],["2.4382","1383.3397"],["2.4381","506.2383"],["2.4380","0"],["2.4379","1177.6104"],["2.4378","70.8750"],["2.4377","1695.9850"],["2.4376","463.5000"],["2.4375","1265.4246"],["2.4373","1400.5490"],["2.4371","4031.4106"],["2.4370","1204.8996"],["2.4369","2763.9000"],["2.4365","2907.0349"],["2.4364","369.0000"],["2.4363","414.8047"],["2.4361","2588.9384"],["2.4360","1283.1158"],["2.4359","1701.5503"],["2.4358","0"],["2.4355","4320.0000"],["2.4354","1089.4111"],["2.4353","184.9594"],["2.4351","2042.5410"],["2.4349","1819.7226"],["2.4348","61.4754"],["2.4347","78.8800"],["2.4342","1775.6618"],["2.4341","2901.9104"],["2.4339","677.1659"],["2.4337","819.0861"],["2.4336","1890.2543"],["2.4335","948.8405"],["2.4334","958.4404"],["2.4333","81.4582"],["2.4245","0"],["2.4244","545.2381"],["2.4240","0"],["2.4239","535.7143"],["2.4235","0"],["2.4234","540.4762"],["2.4230","0"],["2.4229","502.3810"],["2.4225","0"],["2.4224","469.0476"],["2.4220","0"],["2.4219","497.6190"],["2.4215","0"],["2.4214","478.5714"],["2.4210","0"],["2.4209","530.9524"],["2.4205","0"],["2.4204","516.6667"],["2.4200","0"],["2.4199","521.4286"],["2.4195","0"],["2.4194","483.3333"],["2.4190","0"],["2.4189","473.8095"],["2.4185","0"],["2.4184","507.1429"],["2.4180","0"],["2.4179","459.5238"],["2.4175","0"],["2.4174","511.9048"],["2.4170","0"],["2.4169","464.2857"],["2.4165","0"],["2.4164","454.7619"],["2.4160","0"],["2.4159","526.1905"],["2.4155","0"],["2.4154","488.0952"],["2.4150","0"],["2.4149","492.8571"]],"checksum":1203092726,"ts":"1649290081628"}]}
1649290081.660317: {"action":"update","arg":{"instType":"sp","channel":"books","instId":"SUNUSDT"},"data":[{"asks":[["0.01508","320658"],["0.01509","83236"],["0.01510","5605"],["0.01511","242760"],["0.01512","337164"],["0.01517","8294"],["0.01518","0"],["0.01528","886"],["0.01531","0"],["0.01566","2122"],["0.01567","5116"],["0.01582","1833"],["0.01584","3167"],["0.01586","5167"],["0.01588","4833"],["0.01590","6167"],["0.01592","2500"],["0.01594","7167"],["0.01596","7500"],["0.01598","8167"],["0.01600","6833"],["0.01602","4167"],["0.01604","2833"],["0.01606","6500"],["0.01608","5833"],["0.01610","5500"],["0.01612","7833"],["0.01614","3500"],["0.01616","4500"],["0.01618","3833"],["0.01620","2167"]],"bids":[["0.01504","551758"],["0.01503","327037"],["0.01502","84058"],["0.01500","595873"],["0.01499","1448875"],["0.01496","436500"],["0.01495","2289"],["0.01494","5401"],["0.01493","618837"],["0.01491","2028977"],["0.01489","682148"],["0.01488","2951"],["0.01460","157226"],["0.01451","0"],["0.01430","3833"],["0.01428","7500"],["0.01426","3500"],["0.01424","3167"],["0.01422","7833"],["0.01420","2833"],["0.01418","5500"],["0.01416","6500"],["0.01414","6167"],["0.01412","4833"],["0.01410","6833"],["0.01408","1833"],["0.01404","4167"],["0.01402","5833"],["0.01400","4500"],["0.01398","5167"],["0.01396","2167"],["0.01394","2500"],["0.01392","7167"]],"checksum":1836590721,"ts":"1649290081629"}]}
1649290081.7236412: {"action":"update","arg":{"instType":"sp","channel":"trade","instId":"VVSUSDT"},"data":[["1649290081642","0.00002319","215610.3","buy"]]}
1649290081.89745: {"action":"update","arg":{"instType":"sp","channel":"candle1m","instId":"VVSUSDT"},"data":[["1649290080000","0.00002324","0.00002324","0.00002319","0.00002319","215610.3"]]}
1649290081.897541: {"action":"update","arg":{"instType":"sp","channel":"books","instId":"GOGUSDT"},"data":[{"asks":[["0.5625","14.3333"],["0.5631","11.0000"],["0.5637","10.3333"],["0.5643","8.8615"],["0.5655","2346.1333"],["0.5661","9.6667"],["0.5667","13.6667"],["0.5685","9.0000"],["0.5691","8.7868"],["0.5697","8.7775"],["0.5703","16.3333"],["0.5715","15.6667"],["0.5721","15.0000"],["0.5727","13.0000"],["0.5739","11.6667"]],"bids":[["0.5512","9.0721"],["0.5506","14.3333"],["0.5500","9.0919"],["0.5494","13.0000"],["0.5488","9.1118"],["0.5482","3670.2333"],["0.5476","9.6667"],["0.5470","9.1418"],["0.5464","15.0000"],["0.5452","10.3333"],["0.5446","11.6667"],["0.5440","13.6667"],["0.5434","12.3333"],["0.5428","9.2125"],["0.5422","11.0000"],["0.5416","9.2329"],["0.5410","16.3333"],["0.5398","15.6667"]],"checksum":-1788981,"ts":"1649290081874"}]}
1649290081.916297: {"action":"update","arg":{"instType":"sp","channel":"books","instId":"HOTUSDT"},"data":[{"asks":[["0.0056310","0"],["0.0056320","0"],["0.0056330","0"],["0.0056340","105369.3000"],["0.0056350","274020.3000"],["0.0056360","41896.8000"],["0.0056380","604028.2500"],["0.0056440","147749.4000"],["0.0056460","145781.5500"],["0.0056550","192396.6000"],["0.0056820","7146.0000"],["0.0056830","210522.1500"],["0.0056840","6421.5000"],["0.0056890","5535.0000"],["0.0056910","2519.1000"],["0.0059050","0"],["0.0059070","10750.0000"],["0.0059110","0"],["0.0059130","9250.0000"],["0.0059170","0"],["0.0059190","3250.0000"],["0.0059230","0"],["0.0059250","11750.0000"],["0.0059290","0"],["0.0059310","7750.0000"],["0.0059350","0"],["0.0059370","12250.0000"],["0.0059410","0"],["0.0059430","8750.0000"],["0.0059470","0"],["0.0059490","11250.0000"],["0.0059530","0"],["0.0059550","2750.0000"],["0.0059590","0"],["0.0059610","6250.0000"],["0.0059650","0"],["0.0059670","5250.0000"],["0.0059710","0"],["0.0059730","4250.0000"],["0.0059770","0"],["0.0059790","4750.0000"],["0.0059830","0"],["0.0059850","9750.0000"],["0.0059890","0"],["0.0059910","7250.0000"],["0.0059950","0"],["0.0059970","5750.0000"],["0.0060010","0"],["0.0060030","6750.0000"],["0.0060070","0"],["0.0060090","8250.0000"],["0.0060130","0"],["0.0060150","3750.0000"],["0.0060190","0"],["0.0060210","10250.0000"]],"bids":[["0.0056170","405000.0000"],["0.0056160","78625.3500"],["0.0056150","122110.6500"],["0.0056140","114745.9500"],["0.0056130","89339.9400"],["0.0056120","273746.7000"],["0.0056110","171362.2500"],["0.0056100","228215.7000"],["0.0056090","317159.1000"],["0.0056080","800000.0000"],["0.0056070","483144.3000"],["0.0056060","216856.3500"],["0.0056010","61810.2000"],["0.0055980","73468.3500"],["0.0055700","8068.5000"],["0.0055670","30573.0000"],["0.0055650","11052.0000"],["0.0055630","440991.4100"],["0.0055600","0"],["0.0055590","0"],["0.0055580","0"],["0.0053440","12250.0000"],["0.0053410","0"],["0.0053380","5750.0000"],["0.0053350","0"],["0.0053320","10250.0000"],["0.0053290","0"],["0.0053260","9750.0000"],["0.0053230","0"],["0.0053200","6250.0000"],["0.0053170","0"],["0.0053140","6750.0000"],["0.0053110","0"],["0.0053080","4750.0000"],["0.0053050","0"],["0.0053020","8250.0000"],["0.0052990","0"],["0.0052960","5250.0000"],["0.0052930","0"],["0.0052900","3250.0000"],["0.0052870","0"],["0.0052840","3750.0000"],["0.0052810","0"],["0.0052780","7750.0000"],["0.0052750","0"],["0.0052720","8750.0000"],["0.0052690","0"],["0.0052660","2750.0000"],["0.0052630","0"],["0.0052600","9250.0000"],["0.0052570","0"],["0.0052540","10750.0000"],["0.0052510","0"],["0.0052480","11250.0000"],["0.0052450","0"],["0.0052420","11750.0000"],["0.0052390","0"],["0.0052360","4250.0000"],["0.0052330","0"],["0.0052300","7250.0000"],["0.0052270","0"]],"checksum":-833913501,"ts":"1649290081893"}]}
1649290081.937717: {"action":"update","arg":{"instType":"sp","channel":"books","instId":"VVSUSDT"},"data":[{"asks":[["0.00002370","248538.0000"],["0.00002373","657894.7000"],["0.00002379","821637.4000"],["0.00002382","209908.6000"],["0.00002385","330409.4000"],["0.00002391","780701.8000"],["0.00002397","576023.4000"],["0.00002403","289473.7000"],["0.00002406","535087.7000"],["0.00002409","371345.0000"]],"bids":[["0.00002267","371345.0000"],["0.00002261","535087.7000"],["0.00002258","412280.7000"],["0.00002255","657894.7000"],["0.00002252","821637.4000"],["0.00002249","330409.4000"],["0.00002243","576023.4000"],["0.00002240","616959.1000"],["0.00002237","248538.0000"],["0.00002234","494152.0000"],["0.00002231","453216.4000"],["0.00002228","289473.7000"]],"checksum":-1358369860,"ts":"1649290081915"}]}
1649290082.00736: {"action":"update","arg":{"instType":"sp","channel":"books","instId":"STGUSDT"},"data":[{"asks":[["3.034","1.649"],["3.037","2.047"],["3.040","3.569"],["3.043","1.644"],["3.046","2.935"],["3.049","4.725"],["3.052","1.920"],["3.058","3.062"],["3.061","3.315"],["3.064","2.428"],["3.067","2.554"],["3.070","2.808"],["3.073","1.667"],["3.076","1.793"],["3.079","3.936"],["3.082","2.681"],["3.085","1.622"],["3.088","3.442"],["3.091","3.188"],["3.097","1.615"],["3.100","2.301"]],"bids":[["2.744","1.823"],["2.741","2.000"],["2.738","20.290"],["2.735","2.754"],["2.732","100.177"],["2.726","75.898"],["2.723","1.837"],["2.720","2.215"],["2.714","1.843"],["2.711","2.969"],["2.708","2.323"],["2.705","1.849"],["2.702","2.108"],["2.696","94.570"],["2.693","2.431"],["2.690","1.860"],["2.687","2.862"],["2.684","1.892"],["2.681","1.866"],["2.678","3.292"],["2.672","1.872"]],"checksum":-734515569,"ts":"1649290081982"}]}
1649290082.014006: {"action":"update","arg":{"instType":"sp","channel":"books","instId":"AVAXUSDT"},"data":[{"asks":[["83.1615","31.5840"],["83.1715","37.1000"],["83.1915","130.2420"],["83.2015","54.8100"],["83.2115","113.6870"],["83.2715","180.0000"],["83.4615","2.8980"],["83.7015","0"],["88.0489","0.7833"],["88.0596","0"],["88.1320","0.4167"],["88.1427","0"],["88.2151","0.1833"],["88.2258","0"],["88.2982","0.5167"],["88.3089","0"],["88.3813","0.4500"],["88.3920","0"],["88.4644","0.6833"],["88.4751","0"],["88.5475","0.5833"],["88.5582","0"],["88.6306","0.6167"],["88.6413","0"],["88.7137","0.4833"],["88.7244","0"],["88.7968","0.7167"],["88.8075","0"],["88.8799","0.2833"],["88.8906","0"],["88.9630","0.7500"],["88.9737","0"],["89.0461","0.5500"],["89.0568","0"],["89.1292","0.3167"],["89.1399","0"],["89.2123","0.3833"],["89.2230","0"],["89.2954","0.6500"],["89.3061","0"],["89.3785","0.8167"],["89.3892","0"],["89.4616","0.3500"],["89.4723","0"],["89.5447","0.2167"],["89.5554","0"],["89.6278","0.2500"],["89.6385","0"]],"bids":[["82.9785","0"],["82.9685","10.5910"],["82.9585","82.5020"],["82.9285","48.6710"],["82.9085","0"],["82.8985","114.7440"],["82.7185","121.7020"],["82.5185","158.0320"],["82.4685","178.7310"],["82.4585","83.9930"],["78.0904","0"],["78.0810","0.4167"],["78.0073","0"],["77.9979","0.4833"],["77.9242","0"],["77.9148","0.5167"],["77.8411","0"],["77.8317","0.2167"],["77.7580","0"],["77.7486","0.4500"],["77.6749","0"],["77.6655","0.8167"],["77.5918","0"],["77.5824","0.2500"],["77.5087","0"],["77.4993","0.3833"],["77.4256","0"],["77.4162","0.6167"],["77.3425","0"],["77.3331","0.7833"],["77.2594","0"],["77.2500","0.3500"],["77.1763","0"],["77.1669","0.6833"],["77.0932","0"],["77.0838","0.2833"],["77.0101","0"],["77.0007","0.7167"],["76.9270","0"],["76.9176","0.6500"],["76.8439","0"],["76.8345","0.1833"],["76.7608","0"],["76.7514","0.5833"],["76.6777","0"],["76.6683","0.3167"],["76.5946","0"],["76.5852","0.7500"],["76.5115","0"],["76.5021","0.5500"]],"checksum":-1025758418,"ts":"1649290081986"}]}
1649290082.1225111: {"action":"snapshot","arg":{"instType":"sp","channel":"ticker","instId":"EOSUSDT"},"data":[{"instId":"EOSUSDT","last":"2.4421","open24h":"2.5667","high24h":"2.5767","low24h":"2.4155","bestBid":"2.439300","bestAsk":"2.443900","baseVolume":"145520.9144","quoteVolume":"378713.0030","ts":1649290082057,"labeId":0}]}
1649290082.1610081: {"action":"update","arg":{"instType":"sp","channel":"books","instId":"CULTUSDT"},"data":[{"asks":[["0.00003614","653333"],["0.00003618","253333"],["0.00003622","493333"],["0.00003626","280000"],["0.00003630","600000"],["0.00003634","626667"],["0.00003638","306667"],["0.00003642","466667"],["0.00003646","713723"],["0.00003650","146667"],["0.00003654","333333"],["0.00003658","573333"],["0.00003662","520000"],["0.00003666","413333"],["0.00003670","386667"],["0.00003674","226667"],["0.00003678","173333"],["0.00003682","200000"],["0.00003686","546667"],["0.00003690","360000"]],"bids":[["0.00003471","226667"],["0.00003467","1315230"],["0.00003463","413333"],["0.00003459","466667"],["0.00003455","988154"],["0.00003447","653333"],["0.00003443","360000"],["0.00003439","146667"],["0.00003435","200000"],["0.00003431","253333"],["0.00003427","333333"],["0.00003423","626667"],["0.00003419","306667"],["0.00003415","546667"],["0.00003411","493333"],["0.00003407","280000"],["0.00003403","386667"],["0.00003399","440000"],["0.00003395","520000"]],"checksum":2009153474,"ts":"1649290082136"}]}
1649290082.19796: {"action":"update","arg":{"instType":"sp","channel":"books","instId":"SUNUSDT"},"data":[{"asks":[["0.01513","54970"],["0.01514","500502"],["0.01517","1151393"],["0.01528","2004"],["0.01582","6833"],["0.01584","5833"],["0.01586","6500"],["0.01588","4500"],["0.01590","7167"],["0.01594","5167"],["0.01596","4167"],["0.01598","7500"],["0.01600","4833"],["0.01602","7833"],["0.01604","5500"],["0.01606","8167"],["0.01608","1833"],["0.01610","3833"],["0.01612","6167"],["0.01614","2833"],["0.01616","3167"],["0.01618","2167"],["0.01620","3500"]],"bids":[["0.01500","670842"],["0.01499","1373906"],["0.01498","154476"],["0.01497","18326"],["0.01479","156739"],["0.01476","0"],["0.01451","2398"],["0.01430","2167"],["0.01428","4500"],["0.01426","6167"],["0.01424","2833"],["0.01422","3500"],["0.01420","8167"],["0.01418","3167"],["0.01416","3833"],["0.01414","5500"],["0.01410","5167"],["0.01408","4167"],["0.01406","6500"],["0.01404","2500"],["0.01402","1833"],["0.01400","7167"],["0.01398","6833"],["0.01396","7500"],["0.01394","5833"],["0.01392","7833"]],"checksum":1847391920,"ts":"1649290082176"}]}
1649290082.222323: {"action":"update","arg":{"instType":"sp","channel":"books","instId":"EOSUSDT"},"data":[{"asks":[["2.4439","2345.4900"],["2.4441","8.1820"],["2.4442","87.3523"],["2.4443","0"],["2.4446","27.0000"],["2.4447","44.9897"],["2.4448","149.0356"],["2.4449","956.6236"],["2.4450","101.0405"],["2.4451","103.5000"],["2.4454","615.3480"],["2.4455","453.7847"],["2.4457","1140.6441"],["2.4458","317.9915"],["2.4460","17.9944"],["2.4461","1418.4094"],["2.4466","2736.8438"],["2.4467","1700.9509"],["2.4470","2222.1558"],["2.4471","2454.6532"],["2.4478","2382.6773"],["2.4480","2668.3020"],["2.4486","848.2276"],["2.4491","2019.1500"],["2.4493","738.3653"],["2.4498","0"],["2.4586","0"],["2.4588","507.1429"],["2.4591","0"],["2.4593","526.1905"],["2.4596","0"],["2.4598","464.2857"],["2.4601","0"],["2.4603","511.9048"],["2.4606","0"],["2.4608","521.4286"],["2.4611","0"],["2.4613","473.8095"],["2.4616","0"],["2.4618","516.6667"],["2.4621","0"],["2.4623","492.8571"],["2.4626","0"],["2.4628","530.9524"],["2.4631","0"],["2.4633","545.2381"],["2.4636","0"],["2.4638","459.5238"],["2.4641","0"],["2.4643","483.3333"],["2.4646","0"],["2.4648","454.7619"],["2.4651","0"],["2.4653","478.5714"],["2.4656","0"],["2.4658","535.7143"],["2.4661","0"],["2.4663","488.0952"],["2.4666","0"],["2.4668","540.4762"],["2.4671","0"],["2.4673","502.3810"],["2.4676","0"],["2.4678","497.6190"],["2.4681","0"],["2.4683","469.0476"]],"bids":[["2.4394","8.0497"],["2.4393","35.0100"],["2.4392","2135.5336"],["2.4391","249.7321"],["2.4390","977.3963"],["2.4389","2952.9852"],["2.4387","64.1764"],["2.4386","1574.9547"],["2.4385","1103.0850"],["2.4383","333.6362"],["2.4382","2763.2664"],["2.4381","697.6800"],["2.4377","1488.1100"],["2.4376","103.6129"],["2.4373","1297.1617"],["2.4372","498.1847"],["2.4371","2238.1606"],["2.4370","924.0254"],["2.4368","59.0499"],["2.4365","4334.6454"],["2.4361","2951.0684"],["2.4355","0"],["2.4344","1860.2384"],["2.4341","3171.9104"],["2.4337","859.5014"],["2.4336","0"],["2.4335","0"],["2.4334","0"],["2.4333","0"],["2.4245","483.3333"],["2.4244","0"],["2.4240","535.7143"],["2.4239","0"],["2.4235","545.2381"],["2.4234","0"],["2.4230","497.6190"],["2.4229","0"],["2.4225","488.0952"],["2.4224","0"],["2.4220","502.3810"],["2.4219","0"],["2.4215","469.0476"],["2.4214","0"],["2.4210","464.2857"],["2.4209","0"],["2.4205","492.8571"],["2.4204","0"],["2.4200","516.6667"],["2.4199","0"],["2.4195","454.7619"],["2.4194","0"],["2.4190","530.9524"],["2.4189","0"],["2.4185","526.1905"],["2.4184","0"],["2.4180","507.1429"],["2.4179","0"],["2.4175","473.8095"],["2.4174","0"],["2.4170","511.9048"],["2.4169","0"],["2.4165","540.4762"],["2.4164","0"],["2.4160","459.5238"],["2.4159","0"],["2.4155","521.4286"],["2.4154","0"],["2.4150","478.5714"],["2.4149","0"]],"checksum":-1292642148,"ts":"1649290082190"}]}
1649290082.252362: {"action":"snapshot","arg":{"instType":"sp","channel":"ticker","instId":"AVAXUSDT"},"data":[{"instId":"AVAXUSDT","last":"83.1253","open24h":"85.1099","high24h":"86.7605","low24h":"82.5893","bestBid":"82.948500","bestAsk":"83.161500","baseVolume":"3330.7209","quoteVolume":"287723.8289","ts":1649290082175,"labeId":0}]}
1649290082.258359: {"action":"snapshot","arg":{"instType":"sp","channel":"ticker","instId":"HOTUSDT"},"data":[{"instId":"HOTUSDT","last":"0.0056130","open24h":"0.0058560","high24h":"0.0059320","low24h":"0.0055520","bestBid":"0.005616","bestAsk":"0.005634","baseVolume":"10203207.8809","quoteVolume":"60796.5347","ts":1649290082210,"labeId":0}]}
1649290082.2588422: {"action":"snapshot","arg":{"instType":"sp","channel":"ticker","instId":"VVSUSDT"},"data":[{"instId":"VVSUSDT","last":"0.00002319","open24h":"0.00002350","high24h":"0.00002359","low24h":"0.00002313","bestBid":"0.000024","bestAsk":"0.000024","baseVolume":"2375367050.9083","quoteVolume":"56984.8991","ts":1649290082212,"labeId":0}]}
1649290082.2856581: {"action":"snapshot","arg":{"instType":"sp","channel":"ticker","instId":"GOGUSDT"},"data":[{"instId":"GOGUSDT","last":"0.5555","open24h":"0.5563","high24h":"0.5708","low24h":"0.5508","bestBid":"0.554700","bestAsk":"0.559000","baseVolume":"134629.2566","quoteVolume":"78736.7865","ts":1649290082234,"labeId":0}]}
1649290082.313034: {"action":"snapshot","arg":{"instType":"sp","channel":"ticker","instId":"SUNUSDT"},"data":[{"instId":"SUNUSDT","last":"0.01505","open24h":"0.01521","high24h":"0.01559","low24h":"0.01481","bestBid":"0.015040","bestAsk":"0.015080","baseVolume":"11683781","quoteVolume":"180235","ts":1649290082266,"labeId":0}]}
1649290082.339295: {"action":"snapshot","arg":{"instType":"sp","channel":"ticker","instId":"CULTUSDT"},"data":[{"instId":"CULTUSDT","last":"0.00003507","open24h":"0.00004340","high24h":"0.00004397","low24h":"0.00003500","bestBid":"0.000036","bestAsk":"0.000036","baseVolume":"13526772930","quoteVolume":"557436","ts":1649290082292,"labeId":0}]}
1649290082.33938: {"action":"snapshot","arg":{"instType":"sp","channel":"ticker","instId":"STGUSDT"},"data":[{"instId":"STGUSDT","last":"2.881","open24h":"3.045","high24h":"3.164","low24h":"2.757","bestBid":"2.861000","bestAsk":"2.917000","baseVolume":"35327.890","quoteVolume":"111744.124","ts":1649290082294,"labeId":0}]}
1649290082.425932: {"action":"update","arg":{"instType":"sp","channel":"books","instId":"GOGUSDT"},"data":[{"asks":[["0.5625","8.8899"],["0.5631","15.6667"],["0.5637","8.8710"],["0.5655","2343.4667"],["0.5661","8.8334"],["0.5667","15.0000"],["0.5679","13.0000"],["0.5685","13.6667"],["0.5697","14.3333"],["0.5703","11.0000"],["0.5709","11.6667"],["0.5715","10.3333"],["0.5721","12.3333"],["0.5727","8.7316"],["0.5733","9.0000"],["0.5739","16.3333"]],"bids":[["0.5512","17.0667"],["0.5506","9.6667"],["0.5494","9.1018"],["0.5488","16.3333"],["0.5482","3676.2333"],["0.5476","13.0000"],["0.5464","14.3333"],["0.5452","15.0000"],["0.5446","12.3333"],["0.5434","9.2023"],["0.5422","9.2227"],["0.5410","11.0000"],["0.5404","11.6667"],["0.5398","9.2637"]],"checksum":1472502323,"ts":"1649290082404"}]}
1649290082.468962: {"action":"update","arg":{"instType":"sp","channel":"books","instId":"HOTUSDT"},"data":[{"asks":[["0.0056330","109143.7826"],["0.0056340","175007.7000"],["0.0056390","172410.3000"],["0.0056420","237145.5000"],["0.0056470","800000.0000"],["0.0056550","122763.6000"],["0.0056820","3240.0000"],["0.0056830","102600.0000"],["0.0056910","0"],["0.0059070","4750.0000"],["0.0059250","7250.0000"],["0.0059310","8750.0000"],["0.0059370","4250.0000"],["0.0059430","8250.0000"],["0.0059490","5250.0000"],["0.0059550","11750.0000"],["0.0059610","5750.0000"],["0.0059670","10250.0000"],["0.0059730","7750.0000"],["0.0059790","3750.0000"],["0.0059850","6250.0000"],["0.0059910","2750.0000"],["0.0059970","11250.0000"],["0.0060030","9750.0000"],["0.0060090","12250.0000"],["0.0060150","6750.0000"],["0.0060210","10750.0000"]],"bids":[["0.0056170","0"],["0.0056160","41434.6500"],["0.0056150","138844.3500"],["0.0056140","51913.8000"],["0.0056130","70465.8600"],["0.0056120","256469.8500"],["0.0056110","193273.2000"],["0.0056090","717768.9000"],["0.0056070","0"],["0.0056060","136756.3500"],["0.0055650","0"],["0.0055600","294261.3000"],["0.0055590","215988.7500"],["0.0055580","602030.7000"],["0.0053440","0"],["0.0053430","9250.0000"],["0.0053380","0"],["0.0053370","7250.0000"],["0.0053320","0"],["0.0053310","8750.0000"],["0.0053260","0"],["0.0053250","6250.0000"],["0.0053200","0"],["0.0053190","4250.0000"],["0.0053140","0"],["0.0053130","8250.0000"],["0.0053080","0"],["0.0053070","2750.0000"],["0.0053020","0"],["0.0053010","4750.0000"],["0.0052960","0"],["0.0052950","3750.0000"],["0.0052900","0"],["0.0052890","11750.0000"],["0.0052840","0"],["0.0052830","3250.0000"],["0.0052780","0"],["0.0052770","11250.0000"],["0.0052720","0"],["0.0052710","6750.0000"],["0.0052660","0"],["0.0052650","7750.0000"],["0.0052600","0"],["0.0052590","12250.0000"],["0.0052540","0"],["0.0052530","10250.0000"],["0.0052480","0"],["0.0052470","10750.0000"],["0.0052420","0"],["0.0052410","5750.0000"],["0.0052360","0"],["0.0052350","9750.0000"],["0.0052300","0"],["0.0052290","5250.0000"]],"checksum":-1801826599,"ts":"1649290082447"}]}
1649290082.535667: {"action":"update","arg":{"instType":"sp","channel":"books","instId":"VVSUSDT"},"data":[{"asks":[["0.00002370","657894.7000"],["0.00002373","862573.1000"],["0.00002379","616959.1000"],["0.00002382","698830.4000"],["0.00002385","371345.0000"],["0.00002391","330409.4000"],["0.00002397","780701.8000"],["0.00002403","821637.4000"],["0.00002406","903508.8000"],["0.00002409","453216.4000"]],"bids":[["0.00002309","27736837.0000"],["0.00002267","248538.0000"],["0.00002261","862573.1000"],["0.00002258","616959.1000"],["0.00002255","412280.7000"],["0.00002252","222025.9000"],["0.00002249","739766.1000"],["0.00002243","535087.7000"],["0.00002240","453216.4000"],["0.00002237","371345.0000"],["0.00002234","289473.7000"],["0.00002231","698830.4000"],["0.00002228","657894.7000"]],"checksum":985684603,"ts":"1649290082514"}]}
1649290082.54782: {"action":"update","arg":{"instType":"sp","channel":"books","instId":"AVAXUSDT"},"data":[{"asks":[["83.1515","110.8520"],["83.1615","33.0400"],["83.1715","165.6900"],["83.1815","56.7070"],["83.1915","163.7580"],["83.2015","12.6700"],["83.2115","80.1710"],["83.2515","50.7780"],["83.2715","153.9860"],["83.6615","0.7490"],["83.6915","0"],["88.0383","0.6500"],["88.0489","0"],["88.1214","0.8167"],["88.1320","0"],["88.2045","0.2167"],["88.2151","0"],["88.2876","0.7833"],["88.2982","0"],["88.3707","0.6167"],["88.3813","0"],["88.4538","0.4167"],["88.4644","0"],["88.5369","0.3833"],["88.5475","0"],["88.6200","0.2833"],["88.6306","0"],["88.7031","0.7500"],["88.7137","0"],["88.7862","0.3500"],["88.7968","0"],["88.8693","0.5500"],["88.8799","0"],["88.9524","0.3167"],["88.9630","0"],["89.0355","0.4500"],["89.0461","0"],["89.1186","0.5833"],["89.1292","0"],["89.2017","0.1833"],["89.2123","0"],["89.2848","0.2500"],["89.2954","0"],["89.3679","0.6833"],["89.3785","0"],["89.4510","0.7167"],["89.4616","0"],["89.5341","0.5167"],["89.5447","0"],["89.6172","0.4833"],["89.6278","0"]],"bids":[["82.9685","0"],["82.9585","14.7000"],["82.9485","108.4090"],["82.9385","49.2100"],["82.9185","33.5160"],["82.8985","123.1440"],["82.8885","24.9410"],["82.8585","168.9660"],["82.8385","36.5540"],["82.6685","96.4460"],["82.5785","30.4290"],["82.5385","147.7280"],["82.4685","179.1930"],["78.0810","0"],["78.0717","0.2167"],["77.9979","0"],["77.9886","0.3500"],["77.9148","0"],["77.9055","0.5500"],["77.8317","0"],["77.8224","0.2833"],["77.7486","0"],["77.7393","0.2500"],["77.6655","0"],["77.6562","0.6500"],["77.5824","0"],["77.5731","0.3167"],["77.4993","0"],["77.4900","0.8167"],["77.4162","0"],["77.4069","0.5833"],["77.3331","0"],["77.3238","0.7833"],["77.2500","0"],["77.2407","0.6833"],["77.1669","0"],["77.1576","0.6167"],["77.0838","0"],["77.0745","0.7500"],["77.0007","0"],["76.9914","0.3833"],["76.9176","0"],["76.9083","0.5167"],["76.8345","0"],["76.8252","0.4167"],["76.7514","0"],["76.7421","0.7167"],["76.6683","0"],["76.6590","0.1833"],["76.5852","0"],["76.5759","0.4833"],["76.5021","0"],["76.4928","0.4500"]],"checksum":-1330863778,"ts":"1649290082523"}]}
1649290082.566258: {"action":"update","arg":{"instType":"sp","channel":"books","instId":"STGUSDT"},"data":[{"asks":[["3.034","2.301"],["3.037","2.808"],["3.040","1.646"],["3.043","1.793"],["3.046","2.174"],["3.049","6.627"],["3.052","3.062"],["3.055","3.188"],["3.058","2.428"],["3.061","2.935"],["3.064","2.681"],["3.067","1.631"],["3.070","1.630"],["3.073","1.628"],["3.076","2.554"],["3.079","4.443"],["3.082","1.623"],["3.085","1.667"],["3.088","3.315"],["3.091","1.619"],["3.094","2.047"],["3.097","1.920"],["3.100","3.569"]],"bids":[["2.744","2.000"],["2.741","1.825"],["2.738","20.937"],["2.732","98.562"],["2.726","75.144"],["2.720","1.892"],["2.717","2.431"],["2.711","2.108"],["2.708","2.538"],["2.705","3.077"],["2.702","2.215"],["2.699","2.862"],["2.696","94.354"],["2.693","2.646"],["2.687","3.292"],["2.684","1.864"],["2.678","1.868"]],"checksum":-968803337,"ts":"1649290082534"}]}
1649290082.7401652: {"action":"update","arg":{"instType":"sp","channel":"books","instId":"EOSUSDT"},"data":[{"asks":[["2.4439","3487.3200"],["2.4442","114.3523"],["2.4447","38.8135"],["2.4449","958.4627"],["2.4450","83.8474"],["2.4451","180.0000"],["2.4452","709.3973"],["2.4453","490.8524"],["2.4454","2318.6280"],["2.4455","467.1201"],["2.4457","995.7406"],["2.4458","2899.8665"],["2.4459","1835.4624"],["2.4460","37.0875"],["2.4461","1485.5163"],["2.4462","1034.4807"],["2.4463","2227.0668"],["2.4465","4564.4171"],["2.4467","3323.0820"],["2.4470","3182.1558"],["2.4471","1451.2882"],["2.4474","1164.8333"],["2.4475","340.3648"],["2.4479","3470.8034"],["2.4480","2456.6040"],["2.4482","0"],["2.4484","119.4752"],["2.4486","938.2276"],["2.4489","2527.1006"],["2.4495","1150.2900"],["2.4496","1566.9130"],["2.4586","473.8095"],["2.4588","0"],["2.4591","535.7143"],["2.4593","0"],["2.4596","483.3333"],["2.4598","0"],["2.4601","521.4286"],["2.4603","0"],["2.4606","488.0952"],["2.4608","0"],["2.4611","464.2857"],["2.4613","0"],["2.4616","511.9048"],["2.4618","0"],["2.4621","454.7619"],["2.4623","0"],["2.4626","516.6667"],["2.4628","0"],["2.4631","492.8571"],["2.4633","0"],["2.4636","502.3810"],["2.4638","0"],["2.4641","540.4762"],["2.4643","0"],["2.4646","459.5238"],["2.4648","0"],["2.4651","530.9524"],["2.4653","0"],["2.4656","526.1905"],["2.4658","0"],["2.4661","545.2381"],["2.4663","0"],["2.4666","469.0476"],["2.4668","0"],["2.4671","497.6190"],["2.4673","0"],["2.4676","478.5714"],["2.4678","0"],["2.4681","507.1429"],["2.4683","0"]],"bids":[["2.4394","0"],["2.4393","0"],["2.4392","0"],["2.4391","0"],["2.4390","8.0500"],["2.4389","19.5314"],["2.4388","57.2400"],["2.4387","1827.4847"],["2.4386","863.7085"],["2.4385","64.8425"],["2.4384","4269.3633"],["2.4383","307.6761"],["2.4382","1456.9006"],["2.4381","928.3950"],["2.4377","2688.1100"],["2.4376","1851.8064"],["2.4374","1062.4724"],["2.4372","504.7830"],["2.4371","2152.3006"],["2.4370","864.0254"],["2.4369","1566.4500"],["2.4368","0"],["2.4366","426.1673"],["2.4365","3382.5539"],["2.4364","0"],["2.4363","1086.9114"],["2.4361","3153.4484"],["2.4360","1017.6158"],["2.4359","1867.2117"],["2.4358","146.0634"],["2.4355","2880.0000"],["2.4354","1417.9667"],["2.4352","253.1123"],["2.4351","1799.5410"],["2.4350","0"],["2.4347","0"],["2.4344","1491.1106"],["2.4341","3375.3449"],["2.4340","738.2557"],["2.4336","1890.2543"],["2.4335","1016.3405"],["2.4334","958.4404"],["2.4333","81.4582"],["2.4245","0"],["2.4243","502.3810"],["2.4240","0"],["2.4238","521.4286"],["2.4235","0"],["2.4233","507.1429"],["2.4230","0"],["2.4228","454.7619"],["2.4225","0"],["2.4223","492.8571"],["2.4220","0"],["2.4218","540.4762"],["2.4215","0"],["2.4213","535.7143"],["2.4210","0"],["2.4208","464.2857"],["2.4205","0"],["2.4203","511.9048"],["2.4200","0"],["2.4198","516.6667"],["2.4195","0"],["2.4193","545.2381"],["2.4190","0"],["2.4188","478.5714"],["2.4185","0"],["2.4183","469.0476"],["2.4180","0"],["2.4178","459.5238"],["2.4175","0"],["2.4173","488.0952"],["2.4170","0"],["2.4168","473.8095"],["2.4165","0"],["2.4163","483.3333"],["2.4160","0"],["2.4158","530.9524"],["2.4155","0"],["2.4153","497.6190"],["2.4150","0"],["2.4148","526.1905"]],"checksum":-672501664,"ts":"1649290082718"}]}
1649290082.7808: {"action":"update","arg":{"instType":"sp","channel":"books","instId":"SUNUSDT"},"data":[{"asks":[["0.01511","238260"],["0.01512","352250"],["0.01513","57186"],["0.01514","334219"],["0.01517","1148614"],["0.01518","1126"],["0.01567","0"],["0.01582","2500"],["0.01586","3167"],["0.01588","6167"],["0.01590","1833"],["0.01592","3500"],["0.01594","6500"],["0.01596","5167"],["0.01598","2833"],["0.01600","8167"],["0.01602","7167"],["0.01604","7500"],["0.01606","4167"],["0.01608","3833"],["0.01610","4500"],["0.01612","5500"],["0.01614","7833"],["0.01616","4833"],["0.01618","6833"],["0.01620","2167"]],"bids":[["0.01503","472274"],["0.01501","596795"],["0.01500","658557"],["0.01496","377047"],["0.01495","3671970"],["0.01494","0"],["0.01493","642945"],["0.01492","418720"],["0.01491","2016872"],["0.01488","4275"],["0.01485","438074"],["0.01450","15637"],["0.01430","3833"],["0.01428","4833"],["0.01426","1833"],["0.01424","5500"],["0.01422","7500"],["0.01420","7833"],["0.01418","6500"],["0.01416","2500"],["0.01414","5833"],["0.01412","4167"],["0.01410","6833"],["0.01408","5167"],["0.01406","8167"],["0.01404","3500"],["0.01402","3167"],["0.01398","2833"],["0.01396","6167"],["0.01394","2167"],["0.01392","4500"]],"checksum":-1963363778,"ts":"1649290082750"}]}
1649290082.781593: {"action":"update","arg":{"instType":"sp","channel":"books","instId":"CULTUSDT"},"data":[{"asks":[["0.00003614","360000"],["0.00003618","413333"],["0.00003622","306667"],["0.00003626","653333"],["0.00003630","386667"],["0.00003634","226667"],["0.00003638","466667"],["0.00003642","520000"],["0.00003646","820390"],["0.00003650","333333"],["0.00003654","173333"],["0.00003658","200000"],["0.00003662","626667"],["0.00003666","146667"],["0.00003670","440000"],["0.00003674","600000"],["0.00003678","253333"],["0.00003682","493333"],["0.00003686","573333"],["0.00003690","280000"]],"bids":[["0.00003471","360000"],["0.00003467","1688564"],["0.00003463","253333"],["0.00003459","200000"],["0.00003455","694821"],["0.00003451","386667"],["0.00003447","146667"],["0.00003443","573333"],["0.00003439","440000"],["0.00003435","226667"],["0.00003431","173333"],["0.00003427","280000"],["0.00003419","493333"],["0.00003415","413333"],["0.00003411","333333"],["0.00003407","653333"],["0.00003403","466667"],["0.00003399","600000"]],"checksum":-976252257,"ts":"1649290082758"}]}
1649290082.955212: {"action":"update","arg":{"instType":"sp","channel":"books","instId":"GOGUSDT"},"data":[{"asks":[["0.5631","8.8804"],["0.5637","15.6667"],["0.5643","16.3333"],["0.5649","15.0000"],["0.5655","2347.4667"],["0.5667","8.8240"],["0.5673","9.6667"],["0.5679","10.3333"],["0.5685","13.0000"],["0.5691","9.0000"],["0.5697","8.7775"],["0.5703","8.7683"],["0.5715","11.0000"],["0.5721","8.7407"],["0.5733","14.3333"],["0.5739","12.3333"]],"bids":[["0.5512","9.0721"],["0.5494","11.6667"],["0.5482","3669.5667"],["0.5476","15.0000"],["0.5470","10.3333"],["0.5464","15.6667"],["0.5458","14.3333"],["0.5452","9.1719"],["0.5446","9.1821"],["0.5440","9.1922"],["0.5434","13.6667"],["0.5422","11.0000"],["0.5410","13.0000"],["0.5404","12.3333"]],"checksum":-104945068,"ts":"1649290082932"}]}
1649290083.013898: {"action":"update","arg":{"instType":"sp","channel":"books","instId":"HOTUSDT"},"data":[{"asks":[["0.0056300","52830.0000"],["0.0056310","102749.8500"],["0.0056320","89146.8000"],["0.0056340","95877.9000"],["0.0056350","731234.2500"],["0.0056360","0"],["0.0056390","182692.3500"],["0.0056840","8736.7500"],["0.0056870","0"],["0.0056880","0"],["0.0056890","0"],["0.0059040","3250.0000"],["0.0059070","0"],["0.0059100","10250.0000"],["0.0059130","0"],["0.0059160","6250.0000"],["0.0059190","0"],["0.0059220","11250.0000"],["0.0059250","0"],["0.0059280","5750.0000"],["0.0059310","0"],["0.0059340","9250.0000"],["0.0059370","0"],["0.0059400","11750.0000"],["0.0059430","0"],["0.0059460","7750.0000"],["0.0059490","0"],["0.0059520","5250.0000"],["0.0059550","0"],["0.0059580","6750.0000"],["0.0059610","0"],["0.0059640","9750.0000"],["0.0059670","0"],["0.0059700","4750.0000"],["0.0059730","0"],["0.0059760","4250.0000"],["0.0059790","0"],["0.0059820","8750.0000"],["0.0059850","0"],["0.0059880","8250.0000"],["0.0059910","0"],["0.0059940","2750.0000"],["0.0059970","0"],["0.0060000","10750.0000"],["0.0060030","0"],["0.0060060","12250.0000"],["0.0060090","0"],["0.0060120","7250.0000"],["0.0060150","0"],["0.0060180","3750.0000"],["0.0060210","0"]],"bids":[["0.0056160","0"],["0.0056150","137268.9000"],["0.0056140","20404.8000"],["0.0056130","47823.0600"],["0.0056120","32223.6000"],["0.0056110","24319.3500"],["0.0056100","209675.7000"],["0.0056090","756171.9000"],["0.0056070","160302.6000"],["0.0056030","76775.4500"],["0.0056020","323014.5000"],["0.0055990","69247.3500"],["0.0055720","800000.0000"],["0.0055660","7897.5000"],["0.0055580","0"],["0.0053430","0"],["0.0053410","11250.0000"],["0.0053370","0"],["0.0053350","2750.0000"],["0.0053310","0"],["0.0053290","3250.0000"],["0.0053250","0"],["0.0053230","8750.0000"],["0.0053190","0"],["0.0053170","12250.0000"],["0.0053130","0"],["0.0053110","5250.0000"],["0.0053070","0"],["0.0053050","6250.0000"],["0.0053010","0"],["0.0052990","9750.0000"],["0.0052950","0"],["0.0052930","8250.0000"],["0.0052890","0"],["0.0052870","10250.0000"],["0.0052830","0"],["0.0052810","7250.0000"],["0.0052770","0"],["0.0052750","11750.0000"],["0.0052710","0"],["0.0052690","9250.0000"],["0.0052650","0"],["0.0052630","5750.0000"],["0.0052590","0"],["0.0052570","4250.0000"],["0.0052530","0"],["0.0052510","3750.0000"],["0.0052470","0"],["0.0052450","7750.0000"],["0.0052410","0"],["0.0052390","10750.0000"],["0.0052350","0"],["0.0052330","6750.0000"],["0.0052290","0"],["0.0052270","4750.0000"]],"checksum":-520553334,"ts":"1649290082984"}]}
1649290083.0802681: {"action":"update","arg":{"instType":"sp","channel":"books","instId":"VVSUSDT"},"data":[{"asks":[["0.00002370","616959.1000"],["0.00002373","535087.7000"],["0.00002379","576023.4000"],["0.00002382","739766.1000"],["0.00002385","412280.7000"],["0.00002391","698830.4000"],["0.00002397","289473.7000"],["0.00002403","371345.0000"],["0.00002409","494152.0000"]],"bids":[["0.00002267","821637.4000"],["0.00002261","616959.1000"],["0.00002258","330409.4000"],["0.00002255","289473.7000"],["0.00002252","657894.7000"],["0.00002249","222322.0000"],["0.00002243","371345.0000"],["0.00002240","412280.7000"],["0.00002237","862573.1000"],["0.00002234","576023.4000"],["0.00002228","780701.8000"]],"checksum":-1582396528,"ts":"1649290083047"}]}
1649290083.102185: {"action":"update","arg":{"instType":"sp","channel":"books","instId":"AVAXUSDT"},"data":[{"asks":[["83.1015","8.5190"],["83.1115","18.2700"],["83.1215","34.8460"],["83.1315","10.3950"],["83.1415","19.8870"],["83.1515","50.3440"],["83.1615","113.8340"],["83.1715","180.0000"],["83.1815","180.0000"],["83.1915","77.3500"],["83.2015","7.9030"],["83.2115","6.7270"],["83.2215","102.0460"],["83.3215","99.2740"],["83.3515","180.0000"],["83.3615","8.4000"],["83.5515","90.0760"],["83.6415","0"],["83.6515","0"],["83.6615","0"],["83.6715","0"],["83.6815","0"],["87.9853","0.7167"],["88.0383","0"],["88.0684","0.4167"],["88.1214","0"],["88.1515","0.8167"],["88.2045","0"],["88.2346","0.5167"],["88.2876","0"],["88.3177","0.2500"],["88.3707","0"],["88.4008","0.7833"],["88.4538","0"],["88.4839","0.4833"],["88.5369","0"],["88.5670","0.3500"],["88.6200","0"],["88.6501","0.2833"],["88.7031","0"],["88.7332","0.1833"],["88.7862","0"],["88.8163","0.6167"],["88.8693","0"],["88.8994","0.3833"],["88.9524","0"],["88.9825","0.2167"],["89.0355","0"],["89.0656","0.7500"],["89.1186","0"],["89.1487","0.6500"],["89.2017","0"],["89.2318","0.6833"],["89.2848","0"],["89.3149","0.4500"],["89.3679","0"],["89.3980","0.5833"],["89.4510","0"],["89.4811","0.5500"],["89.5341","0"],["89.5642","0.3167"],["89.6172","0"]],"bids":[["82.9585","0"],["82.9485","0"],["82.9385","0"],["82.9285","0"],["82.9185","0"],["82.9085","43.8620"],["82.8985","0"],["82.8885","1.6870"],["82.8785","47.8240"],["82.8585","1.2040"],["82.8485","11.5360"],["82.8385","180.0000"],["82.8185","124.5160"],["82.7985","35.0840"],["82.7785","47.9080"],["82.7585","49.6650"],["82.6085","29.6660"],["82.5985","96.3760"],["82.5585","157.5350"],["82.5485","109.3890"],["82.5385","151.9560"],["82.5285","16.7930"],["82.4785","105.8960"],["82.4485","78.2460"],["82.4385","3.4370"],["82.4285","100.5620"],["82.4185","54.2780"],["82.4085","180.0000"],["78.0717","0"],["78.0247","0.6167"],["77.9886","0"],["77.9416","0.1833"],["77.9055","0"],["77.8585","0.3167"],["77.8224","0"],["77.7754","0.7833"],["77.7393","0"],["77.6923","0.2167"],["77.6562","0"],["77.6092","0.4167"],["77.5731","0"],["77.5261","0.7500"],["77.4900","0"],["77.4430","0.8167"],["77.4069","0"],["77.3599","0.5833"],["77.3238","0"],["77.2768","0.3500"],["77.2407","0"],["77.1937","0.5500"],["77.1576","0"],["77.1106","0.4500"],["77.0745","0"],["77.0275","0.2500"],["76.9914","0"],["76.9444","0.3833"],["76.9083","0"],["76.8613","0.2833"],["76.8252","0"],["76.7782","0.6500"],["76.7421","0"],["76.6951","0.5167"],["76.6590","0"],["76.6120","0.7167"],["76.5759","0"],["76.5289","0.4833"],["76.4928","0"],["76.4458","0.6833"]],"checksum":-949195626,"ts":"1649290083067"}]}
1649290083.1028988: {"action":"update","arg":{"instType":"sp","channel":"books","instId":"STGUSDT"},"data":[{"asks":[["3.034","3.315"],["3.037","2.554"],["3.040","2.681"],["3.043","1.644"],["3.046","3.062"],["3.049","5.232"],["3.052","2.301"],["3.058","2.935"],["3.061","1.667"],["3.064","3.442"],["3.073","2.808"],["3.076","1.626"],["3.079","4.570"],["3.082","2.428"],["3.085","1.920"],["3.088","1.620"],["3.094","1.793"],["3.097","2.174"]],"bids":[["2.744","2.538"],["2.741","2.323"],["2.738","21.044"],["2.735","2.000"],["2.732","100.608"],["2.726","73.636"],["2.720","3.185"],["2.717","1.841"],["2.714","2.646"],["2.711","1.845"],["2.708","2.754"],["2.705","2.431"],["2.702","1.851"],["2.699","1.854"],["2.693","2.862"],["2.687","1.862"],["2.684","2.215"],["2.681","1.892"],["2.672","2.108"]],"checksum":1848117746,"ts":"1649290083071"}]}
1649290083.250296: {"action":"update","arg":{"instType":"sp","channel":"books","instId":"EOSUSDT"},"data":[{"asks":[["2.4439","3362.5800"],["2.4442","87.3523"],["2.4443","176.5562"],["2.4444","549.0000"],["2.4447","20.2226"],["2.4448","221.7110"],["2.4449","642.4534"],["2.4451","463.5591"],["2.4452","774.6726"],["2.4453","2392.3061"],["2.4454","2195.6280"],["2.4455","810.3393"],["2.4456","1440.8183"],["2.4457","1131.5884"],["2.4459","1440.4654"],["2.4460","4320.0000"],["2.4461","1643.4094"],["2.4463","4426.1307"],["2.4464","91.3771"],["2.4465","3983.9171"],["2.4466","3967.0929"],["2.4469","4994.4394"],["2.4470","1742.1558"],["2.4471","2874.2004"],["2.4472","3260.0296"],["2.4474","1707.7005"],["2.4479","2132.5934"],["2.4483","291.9761"],["2.4491","1394.7571"],["2.4493","1330.7594"],["2.4496","0"],["2.4497","0"],["2.4586","540.4762"],["2.4591","502.3810"],["2.4596","488.0952"],["2.4601","530.9524"],["2.4606","464.2857"],["2.4611","454.7619"],["2.4616","521.4286"],["2.4621","507.1429"],["2.4626","469.0476"],["2.4631","511.9048"],["2.4636","483.3333"],["2.4641","545.2381"],["2.4646","478.5714"],["2.4651","535.7143"],["2.4656","492.8571"],["2.4661","459.5238"],["2.4666","516.6667"],["2.4671","473.8095"],["2.4676","497.6190"],["2.4681","526.1905"]],"bids":[["2.4388","0"],["2.4387","64.1764"],["2.4386","506.4912"],["2.4384","6285.9200"],["2.4383","583.4250"],["2.4382","2763.2664"],["2.4381","272.9700"],["2.4379","819.2583"],["2.4377","2057.7200"],["2.4376","225.0501"],["2.4374","1993.0229"],["2.4372","837.0000"],["2.4371","1988.8606"],["2.4370","494.2622"],["2.4369","2763.9000"],["2.4367","696.0920"],["2.4366","2040.4757"],["2.4365","2907.0955"],["2.4363","399.5365"],["2.4361","2990.7884"],["2.4360","1703.2789"],["2.4358","95.8401"],["2.4356","982.7877"],["2.4355","1440.0000"],["2.4354","1081.9134"],["2.4352","425.6658"],["2.4351","2609.9252"],["2.4345","1521.9878"],["2.4335","948.8405"],["2.4332","4605.2452"],["2.4243","473.8095"],["2.4238","478.5714"],["2.4233","459.5238"],["2.4228","492.8571"],["2.4223","535.7143"],["2.4218","507.1429"],["2.4213","497.6190"],["2.4208","516.6667"],["2.4203","540.4762"],["2.4198","502.3810"],["2.4193","454.7619"],["2.4188","511.9048"],["2.4183","521.4286"],["2.4178","488.0952"],["2.4173","483.3333"],["2.4168","545.2381"],["2.4163","530.9524"],["2.4158","469.0476"],["2.4153","464.2857"]],"checksum":-1781256574,"ts":"1649290083228"}]}
1649290083.317109: {"action":"update","arg":{"instType":"sp","channel":"books","instId":"SUNUSDT"},"data":[{"asks":[["0.01508","329925"],["0.01509","33316"],["0.01513","108630"],["0.01514","449508"],["0.01517","1201010"],["0.01518","0"],["0.01519","74231"],["0.01523","1159"],["0.01526","206268"],["0.01528","886"],["0.01532","27159"],["0.01582","5167"],["0.01584","2167"],["0.01586","7500"],["0.01590","4833"],["0.01592","6833"],["0.01594","4500"],["0.01596","7833"],["0.01598","3833"],["0.01600","6500"],["0.01604","2833"],["0.01608","3167"],["0.01610","2500"],["0.01612","1833"],["0.01614","5833"],["0.01616","5500"],["0.01618","8167"],["0.01620","3500"]],"bids":[["0.01503","471661"],["0.01502","112367"],["0.01501","585230"],["0.01500","670842"],["0.01498","154780"],["0.01496","382388"],["0.01495","3097823"],["0.01493","25703"],["0.01492","502341"],["0.01491","2004833"],["0.01430","6167"],["0.01426","3167"],["0.01424","8167"],["0.01422","6500"],["0.01420","2167"],["0.01418","3833"],["0.01416","5500"],["0.01414","3500"],["0.01412","2500"],["0.01410","1833"],["0.01408","5833"],["0.01406","7167"],["0.01404","4500"],["0.01402","4167"],["0.01400","7833"],["0.01398","6833"],["0.01396","7500"],["0.01394","5167"],["0.01392","2833"]],"checksum":1076944949,"ts":"1649290083290"}]}
1649290083.384385: {"action":"update","arg":{"instType":"sp","channel":"books","instId":"CULTUSDT"},"data":[{"asks":[["0.00003614","626667"],["0.00003618","173333"],["0.00003622","466667"],["0.00003630","520000"],["0.00003634","333333"],["0.00003638","600000"],["0.00003642","280000"],["0.00003646","473723"],["0.00003650","413333"],["0.00003654","146667"],["0.00003658","253333"],["0.00003662","493333"],["0.00003666","546667"],["0.00003670","386667"],["0.00003674","360000"],["0.00003678","306667"],["0.00003682","440000"],["0.00003690","226667"]],"bids":[["0.00003471","600000"],["0.00003467","1581897"],["0.00003463","573333"],["0.00003459","253333"],["0.00003455","908154"],["0.00003443","413333"],["0.00003439","360000"],["0.00003435","653333"],["0.00003431","546667"],["0.00003427","226667"],["0.00003423","173333"],["0.00003419","626667"],["0.00003415","333333"],["0.00003411","306667"],["0.00003407","200000"],["0.00003399","280000"],["0.00003395","493333"]],"checksum":-1520579482,"ts":"1649290083362"}]}
1649290083.479692: {"action":"update","arg":{"instType":"sp","channel":"books","instId":"GOGUSDT"},"data":[{"asks":[["0.5637","14.3333"],["0.5643","15.0000"],["0.5649","11.6667"],["0.5673","8.8147"],["0.5679","16.3333"],["0.5691","8.7868"],["0.5697","12.3333"],["0.5703","11.0000"],["0.5709","9.6667"],["0.5715","9.0000"],["0.5727","10.3333"],["0.5733","15.6667"],["0.5739","8.7133"]],"bids":[["0.5506","15.0000"],["0.5500","9.6667"],["0.5494","9.1018"],["0.5488","9.1118"],["0.5482","3678.2333"],["0.5476","9.1318"],["0.5470","13.0000"],["0.5464","11.0000"],["0.5458","10.3333"],["0.5452","11.6667"],["0.5446","14.3333"],["0.5434","9.2023"],["0.5428","15.6667"],["0.5422","9.2227"],["0.5416","16.3333"],["0.5410","9.2431"],["0.5404","13.6667"]],"checksum":-218704755,"ts":"1649290083457"}]}
1649290083.5522711: {"action":"update","arg":{"instType":"sp","channel":"books","instId":"HOTUSDT"},"data":[{"asks":[["0.0056300","186490.8000"],["0.0056310","502880.4000"],["0.0056320","47250.0000"],["0.0056330","144765.9000"],["0.0056350","655507.8000"],["0.0056360","159896.7000"],["0.0056370","433494.4500"],["0.0056380","603228.1500"],["0.0056390","102786.3000"],["0.0056400","800000.0000"],["0.0056410","177306.3000"],["0.0056420","104652.9000"],["0.0056460","131705.1000"],["0.0056800","141426.0000"],["0.0056830","210522.1500"],["0.0056840","6421.5000"],["0.0056860","0"],["0.0059040","3750.0000"],["0.0059100","6250.0000"],["0.0059160","5250.0000"],["0.0059220","10250.0000"],["0.0059280","8750.0000"],["0.0059340","3250.0000"],["0.0059400","4250.0000"],["0.0059460","8250.0000"],["0.0059520","5750.0000"],["0.0059580","10750.0000"],["0.0059640","4750.0000"],["0.0059700","12250.0000"],["0.0059760","9250.0000"],["0.0059820","11750.0000"],["0.0059880","7750.0000"],["0.0059940","6750.0000"],["0.0060000","7250.0000"],["0.0060060","9750.0000"],["0.0060120","2750.0000"],["0.0060180","11250.0000"]],"bids":[["0.0056150","33467.4000"],["0.0056140","0"],["0.0056130","44514.0900"],["0.0056120","100433.7000"],["0.0056110","41896.8000"],["0.0056100","10017.0000"],["0.0056090","306684.4500"],["0.0056080","152477.1000"],["0.0056050","0"],["0.0056010","89047.3500"],["0.0056000","800000.0000"],["0.0055980","38936.7000"],["0.0055930","403578.5700"],["0.0055660","4743.0000"],["0.0055620","51051.6000"],["0.0055580","428472.9000"],["0.0055570","546189.3000"],["0.0053410","8250.0000"],["0.0053350","9250.0000"],["0.0053290","4750.0000"],["0.0053230","11750.0000"],["0.0053170","6750.0000"],["0.0053110","2750.0000"],["0.0053050","7750.0000"],["0.0052990","5250.0000"],["0.0052930","3750.0000"],["0.0052870","9750.0000"],["0.0052810","8750.0000"],["0.0052750","5750.0000"],["0.0052690","4250.0000"],["0.0052630","11250.0000"],["0.0052570","6250.0000"],["0.0052510","7250.0000"],["0.0052450","10750.0000"],["0.0052390","12250.0000"],["0.0052330","10250.0000"],["0.0052270","3250.0000"]],"checksum":-943490907,"ts":"1649290083528"}]}
1649290083.594979: {"action":"update","arg":{"instType":"sp","channel":"books","instId":"VVSUSDT"},"data":[{"asks":[["0.00002370","903508.8000"],["0.00002373","616959.1000"],["0.00002382","248538.0000"],["0.00002385","739766.1000"],["0.00002391","494152.0000"],["0.00002397","535087.7000"],["0.00002403","289473.7000"],["0.00002406","453216.4000"],["0.00002409","330409.4000"]],"bids":[["0.00002309","35236837.0000"],["0.00002267","453216.4000"],["0.00002261","862573.1000"],["0.00002258","494152.0000"],["0.00002255","248538.0000"],["0.00002243","535087.7000"],["0.00002240","289473.7000"],["0.00002237","412280.7000"],["0.00002234","698830.4000"],["0.00002231","739766.1000"],["0.00002228","821637.4000"]],"checksum":-1879082692,"ts":"1649290083570"}]}
1649290083.693441: {"action":"update","arg":{"instType":"sp","channel":"books","instId":"AVAXUSDT"},"data":[{"asks":[["83.1015","0"],["83.1115","64.9880"],["83.1215","27.8460"],["83.1415","48.6010"],["83.1515","118.9790"],["83.1615","71.7150"],["83.1715","63.0560"],["83.1915","180.0000"],["83.2015","13.9510"],["83.2215","17.1150"],["83.2315","133.7490"],["83.2815","180.0000"],["83.4715","0"],["83.6415","0.7280"],["83.6515","0.2310"],["87.9853","0"],["87.9959","0.6833"],["88.0684","0"],["88.0790","0.6500"],["88.1515","0"],["88.1621","0.5833"],["88.2346","0"],["88.2452","0.5500"],["88.3177","0"],["88.3283","0.7500"],["88.4008","0"],["88.4114","0.3167"],["88.4839","0"],["88.4945","0.3833"],["88.5670","0"],["88.5776","0.8167"],["88.6501","0"],["88.6607","0.5167"],["88.7332","0"],["88.7438","0.4167"],["88.8163","0"],["88.8269","0.4500"],["88.8994","0"],["88.9100","0.2500"],["88.9825","0"],["88.9931","0.7167"],["89.0656","0"],["89.0762","0.1833"],["89.1487","0"],["89.1593","0.2167"],["89.2318","0"],["89.2424","0.2833"],["89.3149","0"],["89.3255","0.4833"],["89.3980","0"],["89.4086","0.3500"],["89.4811","0"],["89.4917","0.7833"],["89.5642","0"],["89.5748","0.6167"]],"bids":[["82.9185","8.1970"],["82.9085","42.7070"],["82.8785","83.3350"],["82.8585","26.1030"],["82.8485","157.9270"],["82.8385","75.8660"],["82.8285","72.6460"],["82.8185","180.0000"],["82.8085","129.8920"],["82.7885","123.9350"],["82.7585","131.4110"],["82.7385","43.0220"],["82.6085","38.0450"],["82.5985","104.7550"],["82.5785","38.7450"],["82.5485","87.3110"],["82.5385","156.1840"],["82.4485","92.0360"],["82.4085","0"],["78.0341","0.2500"],["78.0247","0"],["77.9510","0.4833"],["77.9416","0"],["77.8679","0.2833"],["77.8585","0"],["77.7848","0.3833"],["77.7754","0"],["77.7017","0.3500"],["77.6923","0"],["77.6186","0.7167"],["77.6092","0"],["77.5355","0.4167"],["77.5261","0"],["77.4524","0.5833"],["77.4430","0"],["77.3693","0.3167"],["77.3599","0"],["77.2862","0.6500"],["77.2768","0"],["77.2031","0.4500"],["77.1937","0"],["77.1200","0.7500"],["77.1106","0"],["77.0369","0.6833"],["77.0275","0"],["76.9538","0.6167"],["76.9444","0"],["76.8707","0.2167"],["76.8613","0"],["76.7876","0.8167"],["76.7782","0"],["76.7045","0.5167"],["76.6951","0"],["76.6214","0.7833"],["76.6120","0"],["76.5383","0.5500"],["76.5289","0"],["76.4552","0.1833"],["76.4458","0"]],"checksum":1713671194,"ts":"1649290083620"}]}
1649290083.6940968: {"action":"update","arg":{"instType":"sp","channel":"books","instId":"STGUSDT"},"data":[{"asks":[["3.034","3.188"],["3.037","1.920"],["3.040","1.646"],["3.046","1.642"],["3.049","6.120"],["3.052","2.047"],["3.055","1.638"],["3.058","3.062"],["3.061","3.315"],["3.064","3.569"],["3.067","1.793"],["3.070","1.667"],["3.073","2.428"],["3.079","5.458"],["3.082","1.623"],["3.085","2.681"],["3.088","3.442"],["3.091","2.808"],["3.094","1.617"],["3.097","2.554"],["3.100","2.174"]],"bids":[["2.744","1.823"],["2.741","2.538"],["2.738","19.537"],["2.735","2.215"],["2.732","98.346"],["2.729","3.077"],["2.726","74.175"],["2.723","2.646"],["2.720","3.292"],["2.717","2.754"],["2.714","1.843"],["2.711","2.431"],["2.708","2.000"],["2.705","2.969"],["2.696","92.847"],["2.693","3.185"],["2.687","2.862"],["2.684","2.323"],["2.681","1.866"],["2.678","2.108"],["2.672","1.892"]],"checksum":493967689,"ts":"1649290083631"}]}
1649290083.843956: {"action":"update","arg":{"instType":"sp","channel":"books","instId":"EOSUSDT"},"data":[{"asks":[["2.4429","2431.2600"],["2.4430","57.9761"],["2.4431","83.8474"],["2.4433","8.0464"],["2.4434","35.0100"],["2.4435","131.2014"],["2.4436","60.0208"],["2.4437","27.1670"],["2.4438","55.4220"],["2.4439","3377.4300"],["2.4440","132.7222"],["2.4441","0"],["2.4442","27.1182"],["2.4443","634.8031"],["2.4444","735.3000"],["2.4445","161.6513"],["2.4446","106.0408"],["2.4447","13.2782"],["2.4448","379.2456"],["2.4449","2449.8753"],["2.4450","308.4047"],["2.4451","900.0000"],["2.4453","435.3778"],["2.4454","3091.5450"],["2.4455","5713.2224"],["2.4456","1122.3008"],["2.4457","2382.2921"],["2.4458","5266.7710"],["2.4459","1817.0573"],["2.4462","3403.4727"],["2.4464","38.2978"],["2.4465","1427.9171"],["2.4466","2286.7876"],["2.4467","560.0820"],["2.4469","3373.1794"],["2.4470","1841.1558"],["2.4472","1922.0296"],["2.4473","1630.0092"],["2.4474","302.2381"],["2.4475","164.5730"],["2.4479","1409.3984"],["2.4480","3278.9520"],["2.4482","351.0000"],["2.4483","0"],["2.4484","0"],["2.4485","0"],["2.4486","0"],["2.4488","0"],["2.4489","0"],["2.4490","0"],["2.4491","0"],["2.4492","0"],["2.4493","0"],["2.4495","0"],["2.4581","540.4762"],["2.4586","502.3810"],["2.4591","516.6667"],["2.4596","464.2857"],["2.4601","473.8095"],["2.4606","507.1429"],["2.4611","492.8571"],["2.4616","459.5238"],["2.4621","521.4286"],["2.4626","454.7619"],["2.4631","526.1905"],["2.4636","530.9524"],["2.4641","497.6190"],["2.4646","488.0952"],["2.4651","483.3333"],["2.4656","545.2381"],["2.4661","511.9048"],["2.4666","535.7143"],["2.4671","469.0476"],["2.4676","478.5714"],["2.4681","0"]],"bids":[["2.4389","8.0501"],["2.4387","0"],["2.4384","11462.1399"],["2.4381","0"],["2.4379","772.4700"],["2.4378","0"],["2.4377","217.6250"],["2.4375","56.2869"],["2.4374","3433.0617"],["2.4373","0"],["2.4372","0"],["2.4371","761.6193"],["2.4370","1234.4404"],["2.4368","57.9761"],["2.4367","264.6777"],["2.4366","3003.4262"],["2.4365","2865.5707"],["2.4364","90.6309"],["2.4363","439.2000"],["2.4362","531.7178"],["2.4361","2112.2984"],["2.4360","1611.5897"],["2.4359","2111.4090"],["2.4356","925.0263"],["2.4355","738.6191"],["2.4354","1151.4222"],["2.4353","78.9934"],["2.4351","1776.9960"],["2.4349","3164.5968"],["2.4348","112.7434"],["2.4344","1315.6106"],["2.4343","94.8084"],["2.4341","6929.4104"],["2.4340","0"],["2.4339","1125.4573"],["2.4335","971.0836"],["2.4333","189.6873"],["2.4332","1330.7594"],["2.4331","2594.7450"],["2.4330","97.7841"],["2.4329","48.6687"],["2.4243","0"],["2.4233","492.8571"],["2.4228","540.4762"],["2.4223","473.8095"],["2.4218","459.5238"],["2.4208","464.2857"],["2.4203","511.9048"],["2.4198","521.4286"],["2.4193","516.6667"],["2.4188","454.7619"],["2.4183","469.0476"],["2.4178","530.9524"],["2.4173","545.2381"],["2.4168","526.1905"],["2.4163","535.7143"],["2.4158","488.0952"],["2.4153","483.3333"],["2.4148","502.3810"],["2.4143","507.1429"]],"checksum":-544503674,"ts":"1649290083821"}]}
1649290083.8692548: {"action":"update","arg":{"instType":"sp","channel":"books","instId":"SUNUSDT"},"data":[{"asks":[["0.01508","315532"],["0.01509","33304"],["0.01511","388198"],["0.01512","400322"],["0.01513","107016"],["0.01517","1201011"],["0.01582","2167"],["0.01584","4833"],["0.01586","4500"],["0.01588","5167"],["0.01590","7833"],["0.01592","2500"],["0.01594","7167"],["0.01596","2833"],["0.01598","7500"],["0.01600","3167"],["0.01602","3833"],["0.01604","5500"],["0.01606","8167"],["0.01608","6833"],["0.01610","3500"],["0.01614","4167"],["0.01616","5833"],["0.01618","6500"],["0.01620","6167"]],"bids":[["0.01503","307237"],["0.01502","84058"],["0.01501","567257"],["0.01500","703557"],["0.01498","154476"],["0.01496","377047"],["0.01495","3162680"],["0.01493","33212"],["0.01492","628132"],["0.01488","4579"],["0.01485","437770"],["0.01460","76718"],["0.01430","3833"],["0.01428","4500"],["0.01426","5167"],["0.01424","5833"],["0.01422","6167"],["0.01420","5500"],["0.01418","8167"],["0.01416","7833"],["0.01414","4833"],["0.01410","2167"],["0.01408","4167"],["0.01406","2833"],["0.01404","6500"],["0.01402","7167"],["0.01400","7500"],["0.01396","3167"],["0.01394","1833"],["0.01392","3500"]],"checksum":282853904,"ts":"1649290083833"}]}
1649290083.9889011: {"action":"update","arg":{"instType":"sp","channel":"books","instId":"CULTUSDT"},"data":[{"asks":[["0.00003614","600000"],["0.00003618","546667"],["0.00003622","146667"],["0.00003626","333333"],["0.00003630","200000"],["0.00003634","226667"],["0.00003638","520000"],["0.00003642","173333"],["0.00003646","847056"],["0.00003650","626667"],["0.00003654","253333"],["0.00003658","440000"],["0.00003662","280000"],["0.00003666","413333"],["0.00003670","493333"],["0.00003674","466667"],["0.00003678","653333"],["0.00003682","306667"],["0.00003686","360000"],["0.00003690","386667"]],"bids":[["0.00003471","546667"],["0.00003467","1635230"],["0.00003463","466667"],["0.00003459","653333"],["0.00003455","1014821"],["0.00003451","173333"],["0.00003447","413333"],["0.00003443","306667"],["0.00003439","573333"],["0.00003435","253333"],["0.00003431","386667"],["0.00003427","146667"],["0.00003423","200000"],["0.00003419","600000"],["0.00003415","360000"],["0.00003411","440000"],["0.00003407","226667"],["0.00003403","280000"],["0.00003399","333333"],["0.00003395","520000"]],"checksum":464682167,"ts":"1649290083962"}]}
1649290084.024941: {"action":"update","arg":{"instType":"sp","channel":"books","instId":"GOGUSDT"},"data":[{"asks":[["0.5631","13.0000"],["0.5637","8.8710"],["0.5643","8.8615"],["0.5649","15.0000"],["0.5655","2345.4667"],["0.5661","9.0000"],["0.5667","9.6667"],["0.5679","15.6667"],["0.5685","10.3333"],["0.5697","13.6667"],["0.5703","8.7683"],["0.5709","8.7591"],["0.5715","14.3333"],["0.5727","12.3333"],["0.5733","11.0000"],["0.5739","16.3333"]],"bids":[["0.5512","10.4000"],["0.5506","14.3333"],["0.5500","9.0919"],["0.5494","16.3333"],["0.5482","3678.9000"],["0.5470","9.1418"],["0.5464","9.1518"],["0.5452","9.1719"],["0.5446","15.6667"],["0.5440","11.6667"],["0.5434","13.6667"],["0.5428","12.3333"],["0.5416","15.0000"],["0.5404","11.0000"],["0.5398","9.6667"]],"checksum":1742204655,"ts":"1649290084001"}]}
1649290084.1112828: {"action":"update","arg":{"instType":"sp","channel":"books","instId":"VVSUSDT"},"data":[{"asks":[["0.00002370","821637.4000"],["0.00002373","698830.4000"],["0.00002379","453216.4000"],["0.00002382","739766.1000"],["0.00002385","576023.4000"],["0.00002397","657894.7000"],["0.00002403","780701.8000"],["0.00002406","616959.1000"],["0.00002409","862573.1000"]],"bids":[["0.00002267","616959.1000"],["0.00002261","535087.7000"],["0.00002258","371345.0000"],["0.00002255","698830.4000"],["0.00002252","412280.7000"],["0.00002249","289473.7000"],["0.00002243","903508.8000"],["0.00002240","223215.3000"],["0.00002237","248538.0000"],["0.00002234","862573.1000"],["0.00002231","494152.0000"],["0.00002228","739766.1000"]],"checksum":791825490,"ts":"1649290084085"}]}
1649290084.114202: {"action":"update","arg":{"instType":"sp","channel":"books","instId":"HOTUSDT"},"data":[{"asks":[["0.0056280","27189.9000"],["0.0056290","408228.3000"],["0.0056300","47250.0000"],["0.0056310","106023.6000"],["0.0056320","0"],["0.0056330","179815.0500"],["0.0056340","60042.6000"],["0.0056350","344769.7500"],["0.0056360","0"],["0.0056370","475517.7000"],["0.0056380","800000.0000"],["0.0056390","216125.5500"],["0.0056410","797442.7500"],["0.0056420","116664.3000"],["0.0056430","800000.0000"],["0.0056440","269311.5000"],["0.0056450","268320.6000"],["0.0056460","119701.8000"],["0.0056490","119638.8000"],["0.0056510","544238.1000"],["0.0056600","326792.7000"],["0.0059010","12250.0000"],["0.0059040","0"],["0.0059070","8750.0000"],["0.0059100","0"],["0.0059130","7750.0000"],["0.0059160","0"],["0.0059190","10750.0000"],["0.0059220","0"],["0.0059250","4750.0000"],["0.0059280","0"],["0.0059310","6750.0000"],["0.0059340","0"],["0.0059370","4250.0000"],["0.0059400","0"],["0.0059430","9250.0000"],["0.0059460","0"],["0.0059490","11750.0000"],["0.0059520","0"],["0.0059550","3750.0000"],["0.0059580","0"],["0.0059610","5250.0000"],["0.0059640","0"],["0.0059670","3250.0000"],["0.0059700","0"],["0.0059730","8250.0000"],["0.0059760","0"],["0.0059790","7250.0000"],["0.0059820","0"],["0.0059850","11250.0000"],["0.0059880","0"],["0.0059910","5750.0000"],["0.0059940","0"],["0.0059970","10250.0000"],["0.0060000","0"],["0.0060030","2750.0000"],["0.0060060","0"],["0.0060090","6250.0000"],["0.0060120","0"],["0.0060150","9750.0000"],["0.0060180","0"]],"bids":[["0.0056150","0"],["0.0056130","0"],["0.0056120","147683.7000"],["0.0056110","0"],["0.0056090","202335.7500"],["0.0056080","251324.1000"],["0.0056070","107679.6000"],["0.0056060","88704.4500"],["0.0056050","260336.7000"],["0.0056040","127654.6500"],["0.0056030","92800.8500"],["0.0056020","210800.2500"],["0.0056010","61810.2000"],["0.0055970","224866.3500"],["0.0055940","299830.0500"],["0.0055930","430349.6700"],["0.0055560","800000.0000"],["0.0055550","182157.3000"],["0.0053410","0"],["0.0053390","6250.0000"],["0.0053350","0"],["0.0053330","3750.0000"],["0.0053290","0"],["0.0053270","11750.0000"],["0.0053230","0"],["0.0053210","4250.0000"],["0.0053170","0"],["0.0053150","6750.0000"],["0.0053110","0"],["0.0053090","7750.0000"],["0.0053050","0"],["0.0053030","10250.0000"],["0.0052990","0"],["0.0052970","3250.0000"],["0.0052930","0"],["0.0052910","7250.0000"],["0.0052870","0"],["0.0052850","9250.0000"],["0.0052810","0"],["0.0052790","10750.0000"],["0.0052750","0"],["0.0052730","12250.0000"],["0.0052690","0"],["0.0052670","2750.0000"],["0.0052630","0"],["0.0052610","4750.0000"],["0.0052570","0"],["0.0052550","5750.0000"],["0.0052510","0"],["0.0052490","11250.0000"],["0.0052450","0"],["0.0052430","5250.0000"],["0.0052390","0"],["0.0052370","8250.0000"],["0.0052330","0"],["0.0052310","8750.0000"],["0.0052270","0"],["0.0052250","9750.0000"]],"checksum":1711206514,"ts":"1649290084088"}]}
1649290084.114728: {"action":"snapshot","arg":{"instType":"sp","channel":"ticker","instId":"EOSUSDT"},"data":[{"instId":"EOSUSDT","last":"2.4421","open24h":"2.5667","high24h":"2.5767","low24h":"2.4155","bestBid":"2.438400","bestAsk":"2.442600","baseVolume":"145520.9144","quoteVolume":"378713.0030","ts":1649290084065,"labeId":0}]}
1649290084.170132: {"action":"update","arg":{"instType":"sp","channel":"books","instId":"AVAXUSDT"},"data":[{"asks":[["83.1115","7.0000"],["83.1215","40.4880"],["83.1315","65.8630"],["83.1515","112.5810"],["83.1615","100.3730"],["83.1715","180.0000"],["83.1915","120.3930"],["83.2315","133.8400"],["83.2715","110.7610"],["83.3515","137.1650"],["87.9959","0.5500"],["88.0790","0.5167"],["88.1621","0.7500"],["88.2452","0.7833"],["88.3283","0.3833"],["88.4114","0.3500"],["88.4945","0.6167"],["88.5776","0.2167"],["88.6607","0.7167"],["88.7438","0.8167"],["88.8269","0.4167"],["88.9100","0.1833"],["88.9931","0.2833"],["89.0762","0.6833"],["89.1593","0.6500"],["89.2424","0.2500"],["89.4086","0.5833"],["89.4917","0.4500"],["89.5748","0.3167"]],"bids":[["82.9185","48.6710"],["82.9085","75.0890"],["82.8985","32.5780"],["82.8885","2.7370"],["82.8785","115.8990"],["82.8485","180.0000"],["82.7885","132.9160"],["82.7185","121.4850"],["82.5585","146.9580"],["82.4685","180.0000"],["82.4185","0"],["78.0341","0.5833"],["77.9510","0.2500"],["77.8679","0.7167"],["77.7848","0.8167"],["77.7017","0.7833"],["77.6186","0.4833"],["77.5355","0.3500"],["77.4524","0.5167"],["77.3693","0.7500"],["77.2862","0.4167"],["77.2031","0.2833"],["77.1200","0.3167"],["77.0369","0.4500"],["76.9538","0.2167"],["76.8707","0.6500"],["76.7876","0.3833"],["76.7045","0.1833"],["76.6214","0.6833"],["76.5383","0.6167"],["76.4552","0.5500"]],"checksum":-14328998,"ts":"1649290084145"}]}
1649290084.170605: {"action":"snapshot","arg":{"instType":"sp","channel":"ticker","instId":"AVAXUSDT"},"data":[{"instId":"AVAXUSDT","last":"83.1253","open24h":"85.1099","high24h":"86.7605","low24h":"82.5893","bestBid":"82.918500","bestAsk":"83.111500","baseVolume":"3330.7209","quoteVolume":"287723.8289","ts":1649290084123,"labeId":0}]}
1649290084.1706398: {"action":"snapshot","arg":{"instType":"sp","channel":"ticker","instId":"VVSUSDT"},"data":[{"instId":"VVSUSDT","last":"0.00002319","open24h":"0.00002350","high24h":"0.00002359","low24h":"0.00002313","bestBid":"0.000024","bestAsk":"0.000024","baseVolume":"2375367050.9083","quoteVolume":"56984.8991","ts":1649290084127,"labeId":0}]}
1649290084.184214: {"action":"snapshot","arg":{"instType":"sp","channel":"ticker","instId":"HOTUSDT"},"data":[{"instId":"HOTUSDT","last":"0.0056130","open24h":"0.0058560","high24h":"0.0059320","low24h":"0.0055520","bestBid":"0.005612","bestAsk":"0.005628","baseVolume":"10203207.8809","quoteVolume":"60796.5347","ts":1649290084137,"labeId":0}]}
1649290084.1917608: {"action":"update","arg":{"instType":"sp","channel":"books","instId":"STGUSDT"},"data":[{"asks":[["3.034","2.808"],["3.037","1.647"],["3.046","2.935"],["3.049","6.373"],["3.052","2.301"],["3.058","1.667"],["3.061","1.920"],["3.064","3.442"],["3.067","3.569"],["3.070","2.428"],["3.073","1.628"],["3.076","3.062"],["3.079","5.711"],["3.085","2.174"],["3.088","1.793"],["3.091","2.047"],["3.094","2.681"],["3.097","3.315"],["3.100","1.614"]],"bids":[["2.744","3.292"],["2.741","2.215"],["2.735","3.185"],["2.732","99.208"],["2.729","2.754"],["2.726","74.929"],["2.723","1.837"],["2.720","3.077"],["2.717","2.862"],["2.714","2.538"],["2.711","1.845"],["2.708","2.646"],["2.705","1.892"],["2.696","92.631"],["2.693","2.969"],["2.687","1.862"],["2.684","1.864"],["2.681","2.323"],["2.678","2.431"],["2.672","2.000"]],"checksum":-708547784,"ts":"1649290084169"}]}
1649290084.198185: {"action":"snapshot","arg":{"instType":"sp","channel":"ticker","instId":"GOGUSDT"},"data":[{"instId":"GOGUSDT","last":"0.5555","open24h":"0.5563","high24h":"0.5708","low24h":"0.5508","bestBid":"0.554700","bestAsk":"0.559000","baseVolume":"134629.2566","quoteVolume":"78736.7865","ts":1649290084153,"labeId":0}]}
1649290084.234151: {"action":"snapshot","arg":{"instType":"sp","channel":"ticker","instId":"SUNUSDT"},"data":[{"instId":"SUNUSDT","last":"0.01505","open24h":"0.01521","high24h":"0.01559","low24h":"0.01481","bestBid":"0.015040","bestAsk":"0.015080","baseVolume":"11683781","quoteVolume":"180235","ts":1649290084180,"labeId":0}]}
1649290084.23424: {"action":"update","arg":{"instType":"sp","channel":"trade","instId":"GOGUSDT"},"data":[["1649290084145","0.5575","8.9687","buy"]]}
1649290084.242742: {"action":"snapshot","arg":{"instType":"sp","channel":"ticker","instId":"STGUSDT"},"data":[{"instId":"STGUSDT","last":"2.881","open24h":"3.045","high24h":"3.164","low24h":"2.757","bestBid":"2.861000","bestAsk":"2.917000","baseVolume":"35327.890","quoteVolume":"111744.124","ts":1649290084196,"labeId":0}]}
1649290084.24283: {"action":"snapshot","arg":{"instType":"sp","channel":"ticker","instId":"CULTUSDT"},"data":[{"instId":"CULTUSDT","last":"0.00003507","open24h":"0.00004340","high24h":"0.00004397","low24h":"0.00003500","bestBid":"0.000036","bestAsk":"0.000036","baseVolume":"13526772930","quoteVolume":"557436","ts":1649290084198,"labeId":0}]}
1649290084.394331: {"action":"update","arg":{"instType":"sp","channel":"books","instId":"EOSUSDT"},"data":[{"asks":[["2.4426","93.7585"],["2.4427","8.0469"],["2.4428","195.6669"],["2.4429","1905.6234"],["2.4430","0"],["2.4431","0"],["2.4432","236.2500"],["2.4433","0"],["2.4434","343.7880"],["2.4435","20.1373"],["2.4436","56.0893"],["2.4438","83.8440"],["2.4439","3009.3387"],["2.4440","502.6977"],["2.4442","280.0401"],["2.4443","1726.5180"],["2.4444","474.8014"],["2.4445","1831.7404"],["2.4446","977.6425"],["2.4447","0"],["2.4448","1309.4829"],["2.4449","2269.1830"],["2.4450","3663.1179"],["2.4451","603.3715"],["2.4452","673.1968"],["2.4453","4082.9405"],["2.4454","5559.8400"],["2.4455","4491.2194"],["2.4456","62.6852"],["2.4457","4626.4052"],["2.4458","5163.7500"],["2.4459","1320.0149"],["2.4460","2880.0000"],["2.4461","1418.4094"],["2.4462","1331.0104"],["2.4464","52.5376"],["2.4468","191.0412"],["2.4469","3332.4463"],["2.4470","1832.1508"],["2.4472","1877.0296"],["2.4473","318.3942"],["2.4474","598.4010"],["2.4475","582.3195"],["2.4476","1330.7594"],["2.4478","3021.9816"],["2.4482","0"],["2.4575","454.7619"],["2.4580","483.3333"],["2.4581","0"],["2.4585","502.3810"],["2.4586","0"],["2.4590","459.5238"],["2.4591","0"],["2.4595","535.7143"],["2.4596","0"],["2.4600","488.0952"],["2.4601","0"],["2.4605","469.0476"],["2.4606","0"],["2.4610","492.8571"],["2.4611","0"],["2.4615","530.9524"],["2.4616","0"],["2.4620","478.5714"],["2.4621","0"],["2.4625","516.6667"],["2.4626","0"],["2.4630","473.8095"],["2.4631","0"],["2.4635","521.4286"],["2.4636","0"],["2.4640","497.6190"],["2.4641","0"],["2.4645","526.1905"],["2.4646","0"],["2.4650","464.2857"],["2.4651","0"],["2.4655","507.1429"],["2.4656","0"],["2.4660","540.4762"],["2.4661","0"],["2.4665","511.9048"],["2.4666","0"],["2.4670","545.2381"],["2.4671","0"],["2.4676","0"]],"bids":[["2.4390","0"],["2.4389","0"],["2.4386","0"],["2.4385","0"],["2.4384","0"],["2.4383","0"],["2.4379","180.0000"],["2.4377","400.2399"],["2.4375","82.1185"],["2.4373","8.0515"],["2.4371","727.1550"],["2.4370","2977.6730"],["2.4369","57.2400"],["2.4368","8.0519"],["2.4367","515.4475"],["2.4366","542.8356"],["2.4365","2764.6164"],["2.4364","0"],["2.4363","1495.8000"],["2.4362","928.4355"],["2.4361","1710.0300"],["2.4360","1598.1158"],["2.4359","2271.5578"],["2.4358","207.0203"],["2.4357","494.0311"],["2.4356","865.7877"],["2.4355","0"],["2.4354","1406.1881"],["2.4353","42.9531"],["2.4352","462.8677"],["2.4351","1193.8860"],["2.4350","409.5000"],["2.4349","1911.1581"],["2.4348","2111.3466"],["2.4347","26.5493"],["2.4345","1482.2048"],["2.4344","2035.6106"],["2.4343","51.6914"],["2.4342","0"],["2.4341","4612.8900"],["2.4339","1662.4645"],["2.4338","138.8451"],["2.4337","734.3973"],["2.4335","948.8405"],["2.4334","752.5803"],["2.4333","14.1873"],["2.4332","2346.5375"],["2.4331","4071.1950"],["2.4329","168.3933"],["2.4328","783.8386"],["2.4327","1662.2204"],["2.4325","1035.0094"],["2.4324","1070.6892"],["2.4323","2812.1256"],["2.4238","0"],["2.4228","507.1429"],["2.4223","483.3333"],["2.4218","545.2381"],["2.4213","478.5714"],["2.4208","454.7619"],["2.4203","516.6667"],["2.4198","511.9048"],["2.4193","473.8095"],["2.4188","540.4762"],["2.4183","488.0952"],["2.4178","535.7143"],["2.4173","526.1905"],["2.4168","502.3810"],["2.4163","530.9524"],["2.4158","497.6190"],["2.4153","459.5238"],["2.4148","464.2857"],["2.4143","469.0476"],["2.4138","521.4286"]],"checksum":158451138,"ts":"1649290084368"}]}
1649290084.400539: {"action":"update","arg":{"instType":"sp","channel":"books","instId":"SUNUSDT"},"data":[{"asks":[["0.01513","253020"],["0.01514","607009"],["0.01582","5167"],["0.01584","2833"],["0.01586","4167"],["0.01588","2500"],["0.01590","3167"],["0.01592","1833"],["0.01594","7500"],["0.01596","3500"],["0.01598","3833"],["0.01600","2167"],["0.01602","4833"],["0.01604","7167"],["0.01606","6500"],["0.01608","5500"],["0.01610","4500"],["0.01612","7833"],["0.01614","6167"],["0.01616","8167"],["0.01618","6833"],["0.01620","5833"]],"bids":[["0.01430","3167"],["0.01428","6500"],["0.01426","2500"],["0.01424","4167"],["0.01422","7833"],["0.01420","3833"],["0.01418","2833"],["0.01416","5167"],["0.01414","6167"],["0.01412","2167"],["0.01410","8167"],["0.01408","4500"],["0.01406","5500"],["0.01404","3500"],["0.01402","7500"],["0.01400","1833"],["0.01398","7167"],["0.01396","6833"],["0.01394","4833"],["0.01392","5833"]],"checksum":-25826628,"ts":"1649290084377"}]}
1649290084.562911: {"action":"update","arg":{"instType":"sp","channel":"books","instId":"GOGUSDT"},"data":[{"asks":[["0.5631","15.0000"],["0.5649","13.6667"],["0.5667","8.8240"],["0.5673","11.0000"],["0.5679","8.8054"],["0.5685","14.3333"],["0.5697","8.7775"],["0.5703","9.6667"],["0.5709","15.6667"],["0.5715","16.3333"],["0.5721","13.0000"],["0.5733","10.3333"],["0.5739","8.7133"]],"bids":[["0.5512","9.0721"],["0.5506","9.0820"],["0.5494","9.1018"],["0.5488","11.6667"],["0.5482","3673.5667"],["0.5470","13.6667"],["0.5458","14.3333"],["0.5452","15.6667"],["0.5446","9.1821"],["0.5440","11.0000"],["0.5434","16.3333"],["0.5428","9.2125"],["0.5422","13.0000"],["0.5410","12.3333"],["0.5404","9.6667"],["0.5398","10.3333"]],"checksum":1966970781,"ts":"1649290084534"}]}
1649290084.587397: {"action":"update","arg":{"instType":"sp","channel":"books","instId":"CULTUSDT"},"data":[{"asks":[["0.00003614","280000"],["0.00003618","440000"],["0.00003626","626667"],["0.00003630","600000"],["0.00003638","173333"],["0.00003642","333333"],["0.00003646","927056"],["0.00003650","573333"],["0.00003654","466667"],["0.00003658","253333"],["0.00003662","386667"],["0.00003666","520000"],["0.00003670","546667"],["0.00003674","200000"],["0.00003678","306667"],["0.00003682","360000"],["0.00003686","493333"],["0.00003690","413333"]],"bids":[["0.00003471","280000"],["0.00003467","1715230"],["0.00003463","386667"],["0.00003459","306667"],["0.00003455","1041487"],["0.00003451","466667"],["0.00003447","546667"],["0.00003443","226667"],["0.00003439","520000"],["0.00003435","200000"],["0.00003431","600000"],["0.00003427","440000"],["0.00003423","333333"],["0.00003419","626667"],["0.00003415","493333"],["0.00003411","360000"],["0.00003407","146758"],["0.00003403","253333"],["0.00003399","413333"],["0.00003395","173333"]],"checksum":975495510,"ts":"1649290084559"}]}
1649290084.656606: {"action":"update","arg":{"instType":"sp","channel":"books","instId":"HOTUSDT"},"data":[{"asks":[["0.0056280","74439.9000"],["0.0056290","15995.7000"],["0.0056300","423805.9500"],["0.0056320","69693.3000"],["0.0056330","278142.3000"],["0.0056340","25195.9500"],["0.0056350","655507.8000"],["0.0056360","32038.2000"],["0.0056380","608723.1000"],["0.0056390","171041.4000"],["0.0056410","800000.0000"],["0.0056420","104652.9000"],["0.0056440","256675.0500"],["0.0056540","72927.4500"],["0.0056600","316792.8000"],["0.0056840","0"],["0.0056850","0"],["0.0059010","5250.0000"],["0.0059070","11750.0000"],["0.0059130","2750.0000"],["0.0059190","4750.0000"],["0.0059250","9250.0000"],["0.0059310","8750.0000"],["0.0059370","7250.0000"],["0.0059430","3750.0000"],["0.0059490","3250.0000"],["0.0059550","7750.0000"],["0.0059610","8250.0000"],["0.0059670","5750.0000"],["0.0059730","9750.0000"],["0.0059790","6250.0000"],["0.0059850","4250.0000"],["0.0059910","12250.0000"],["0.0059970","6750.0000"],["0.0060030","10750.0000"],["0.0060090","10250.0000"],["0.0060150","11250.0000"]],"bids":[["0.0056120","0"],["0.0056110","168088.5000"],["0.0056090","0"],["0.0056080","255814.2000"],["0.0056060","96013.8000"],["0.0056050","7138.8000"],["0.0056040","14580.9000"],["0.0056010","193406.8500"],["0.0055970","224867.2500"],["0.0055900","158850.0000"],["0.0055840","142361.1000"],["0.0055540","7211.7000"],["0.0053390","0"],["0.0053380","5250.0000"],["0.0053330","0"],["0.0053320","6250.0000"],["0.0053270","0"],["0.0053260","3750.0000"],["0.0053210","0"],["0.0053200","4250.0000"],["0.0053150","0"],["0.0053140","11250.0000"],["0.0053090","0"],["0.0053080","9250.0000"],["0.0053030","0"],["0.0053020","9750.0000"],["0.0052970","0"],["0.0052960","7750.0000"],["0.0052910","0"],["0.0052900","3250.0000"],["0.0052850","0"],["0.0052840","5750.0000"],["0.0052790","0"],["0.0052780","10750.0000"],["0.0052730","0"],["0.0052720","11750.0000"],["0.0052670","0"],["0.0052660","10250.0000"],["0.0052610","0"],["0.0052600","6750.0000"],["0.0052550","0"],["0.0052540","12250.0000"],["0.0052490","0"],["0.0052480","8250.0000"],["0.0052430","0"],["0.0052420","7250.0000"],["0.0052370","0"],["0.0052360","2750.0000"],["0.0052310","0"],["0.0052300","8750.0000"],["0.0052250","0"],["0.0052240","4750.0000"]],"checksum":1325600635,"ts":"1649290084627"}]}
1649290084.691971: {"action":"update","arg":{"instType":"sp","channel":"books","instId":"STGUSDT"},"data":[{"asks":[["3.034","2.174"],["3.040","2.428"],["3.043","3.315"],["3.046","1.642"],["3.049","4.725"],["3.058","1.920"],["3.061","2.681"],["3.064","1.633"],["3.067","3.442"],["3.070","2.047"],["3.073","3.188"],["3.079","4.824"],["3.082","3.569"],["3.085","2.808"],["3.088","2.935"],["3.091","1.619"],["3.094","1.617"],["3.097","2.554"],["3.100","1.793"]],"bids":[["2.744","2.646"],["2.741","1.825"],["2.738","19.967"],["2.735","2.323"],["2.729","3.292"],["2.726","74.713"],["2.723","2.108"],["2.720","1.839"],["2.717","1.841"],["2.714","1.843"],["2.708","2.431"],["2.705","2.969"],["2.702","3.185"],["2.699","2.538"],["2.696","94.247"],["2.693","1.858"],["2.684","2.754"],["2.681","3.077"],["2.678","1.868"]],"checksum":-1237270752,"ts":"1649290084668"}]}
1649290084.713811: {"action":"update","arg":{"instType":"sp","channel":"books","instId":"VVSUSDT"},"data":[{"asks":[["0.00002370","698830.4000"],["0.00002373","210704.8000"],["0.00002379","289473.7000"],["0.00002382","780701.8000"],["0.00002385","739766.1000"],["0.00002391","576023.4000"],["0.00002397","494152.0000"],["0.00002403","616959.1000"],["0.00002406","535087.7000"],["0.00002409","657894.7000"]],"bids":[["0.00002267","494152.0000"],["0.00002261","221142.1000"],["0.00002258","821637.4000"],["0.00002255","657894.7000"],["0.00002249","371345.0000"],["0.00002243","330409.4000"],["0.00002240","903508.8000"],["0.00002237","780701.8000"],["0.00002234","739766.1000"],["0.00002231","862573.1000"],["0.00002228","535087.7000"]],"checksum":1596289960,"ts":"1649290084688"}]}
1649290084.768511: {"action":"update","arg":{"instType":"sp","channel":"books","instId":"AVAXUSDT"},"data":[{"asks":[["83.1915","180.0000"],["83.2215","41.1740"],["87.9959","0.4167"],["88.1621","0.3167"],["88.2452","0.2500"],["88.3283","0.7500"],["88.4114","0.6167"],["88.4945","0.3500"],["88.5776","0.4500"],["88.6607","0.8167"],["88.7438","0.7833"],["88.8269","0.2833"],["88.9100","0.5500"],["88.9931","0.2167"],["89.0762","0.6500"],["89.1593","0.1833"],["89.2424","0.5833"],["89.3255","0.6833"],["89.4086","0.4833"],["89.4917","0.3833"],["89.5748","0.7167"]],"bids":[["82.8585","26.8450"],["82.7785","71.4280"],["82.7185","123.5850"],["82.5785","30.3520"],["82.5585","138.6140"],["82.5485","95.7040"],["82.5385","156.1700"],["82.5285","21.0210"],["82.5185","174.7900"],["82.4785","114.2470"],["78.0341","0.3167"],["77.9510","0.4167"],["77.8679","0.7833"],["77.7848","0.3500"],["77.7017","0.8167"],["77.6186","0.5500"],["77.5355","0.5833"],["77.4524","0.6500"],["77.2862","0.4500"],["77.2031","0.3833"],["77.1200","0.1833"],["77.0369","0.2500"],["76.9538","0.6167"],["76.8707","0.2167"],["76.7876","0.7167"],["76.7045","0.4833"],["76.5383","0.2833"],["76.4552","0.5167"]],"checksum":-169927060,"ts":"1649290084742"}]}
1649290084.925322: {"action":"update","arg":{"instType":"sp","channel":"books","instId":"EOSUSDT"},"data":[{"asks":[["2.4419","1719.7200"],["2.4425","54.9289"],["2.4426","68.4193"],["2.4429","2064.6534"],["2.4434","292.0050"],["2.4435","13.2746"],["2.4436","0"],["2.4439","2088.4488"],["2.4441","4265.5140"],["2.4443","477.8760"],["2.4445","358.0951"],["2.4448","2181.7152"],["2.4449","3852.7330"],["2.4450","3528.1179"],["2.4451","1169.7300"],["2.4453","3690.0000"],["2.4455","5094.2194"],["2.4457","1863.1789"],["2.4459","1646.5349"],["2.4466","2764.3158"],["2.4468","880.3713"],["2.4469","2874.8413"],["2.4470","1877.1508"],["2.4471","1060.7292"],["2.4473","658.1185"],["2.4478","2904.9816"],["2.4479","0"],["2.4480","0"],["2.4570","540.4762"],["2.4575","530.9524"],["2.4580","473.8095"],["2.4585","526.1905"],["2.4590","464.2857"],["2.4595","454.7619"],["2.4600","511.9048"],["2.4605","492.8571"],["2.4610","521.4286"],["2.4615","488.0952"],["2.4620","459.5238"],["2.4625","502.3810"],["2.4630","535.7143"],["2.4635","478.5714"],["2.4640","507.1429"],["2.4645","516.6667"],["2.4650","545.2381"],["2.4655","469.0476"],["2.4660","497.6190"],["2.4665","483.3333"],["2.4670","0"]],"bids":[["2.4382","0"],["2.4371","2455.2450"],["2.4370","367.8399"],["2.4369","583.4700"],["2.4367","486.4594"],["2.4366","738.9860"],["2.4364","50.6784"],["2.4362","91.4355"],["2.4361","359.0400"],["2.4359","2192.8078"],["2.4358","325.1453"],["2.4357","257.7811"],["2.4356","715.1533"],["2.4355","837.0000"],["2.4351","861.3867"],["2.4350","785.5174"],["2.4347","294.3253"],["2.4346","2075.3312"],["2.4344","1923.1106"],["2.4341","5102.8650"],["2.4339","1125.5583"],["2.4337","899.2323"],["2.4336","1516.3245"],["2.4331","4562.0100"],["2.4328","414.7107"],["2.4326","738.2557"],["2.4324","0"],["2.4323","0"],["2.4233","0"],["2.4228","535.7143"],["2.4223","540.4762"],["2.4218","521.4286"],["2.4213","464.2857"],["2.4208","526.1905"],["2.4203","507.1429"],["2.4193","483.3333"],["2.4188","545.2381"],["2.4183","473.8095"],["2.4178","459.5238"],["2.4173","497.6190"],["2.4168","492.8571"],["2.4163","454.7619"],["2.4158","502.3810"],["2.4153","469.0476"],["2.4148","488.0952"],["2.4143","478.5714"],["2.4138","530.9524"],["2.4133","516.6667"]],"checksum":1411558617,"ts":"1649290084903"}]}
1649290084.9599738: {"action":"update","arg":{"instType":"sp","channel":"books","instId":"SUNUSDT"},"data":[{"asks":[["0.01508","485405"],["0.01509","26107"],["0.01511","390655"],["0.01513","251518"],["0.01516","1344"],["0.01517","1198231"],["0.01523","2262"],["0.01566","0"],["0.01582","5500"],["0.01584","2500"],["0.01586","5167"],["0.01588","6500"],["0.01590","7833"],["0.01592","2833"],["0.01598","2167"],["0.01600","4167"],["0.01602","3833"],["0.01604","1833"],["0.01606","7167"],["0.01608","6833"],["0.01610","5833"],["0.01612","8167"],["0.01614","4500"],["0.01616","4833"],["0.01618","3167"],["0.01620","6167"]],"bids":[["0.01504","27266"],["0.01503","162613"],["0.01502","74101"],["0.01501","540534"],["0.01500","754551"],["0.01499","1322912"],["0.01493","1595"],["0.01492","676363"],["0.01453","124136"],["0.01430","8167"],["0.01428","5167"],["0.01426","6167"],["0.01424","4833"],["0.01422","5833"],["0.01420","3500"],["0.01418","4500"],["0.01416","3833"],["0.01414","1833"],["0.01412","7500"],["0.01410","3167"],["0.01408","2167"],["0.01406","7833"],["0.01404","4167"],["0.01402","2500"],["0.01400","2833"],["0.01394","6500"],["0.01392","5500"]],"checksum":-713482830,"ts":"1649290084938"}]}
1649290085.109652: {"action":"update","arg":{"instType":"sp","channel":"books","instId":"CULTUSDT"},"data":[{"asks":[["0.00003614","493333"],["0.00003618","466667"],["0.00003622","520000"],["0.00003626","573333"],["0.00003630","413333"],["0.00003638","386667"],["0.00003642","173333"],["0.00003646","607056"],["0.00003650","200000"],["0.00003654","280000"],["0.00003658","146667"],["0.00003662","253333"],["0.00003666","600000"],["0.00003670","360000"],["0.00003674","626667"],["0.00003682","653333"],["0.00003686","546667"],["0.00003690","440000"],["0.00003880","0"],["0.00004065","0"],["0.00004086","332267"],["0.00004100","331126"]],"bids":[["0.00003471","333333"],["0.00003467","1395230"],["0.00003463","546667"],["0.00003459","413333"],["0.00003455","988154"],["0.00003451","200000"],["0.00003447","173333"],["0.00003443","520000"],["0.00003439","226667"],["0.00003435","440000"],["0.00003431","493333"],["0.00003427","466667"],["0.00003423","386667"],["0.00003419","146667"],["0.00003415","306667"],["0.00003411","280000"],["0.00003407","360000"],["0.00003403","626667"],["0.00003399","653333"],["0.00003395","573333"],["0.00003150","0"],["0.00003145","192392"]],"checksum":1587525199,"ts":"1649290085072"}]}
1649290085.110025: {"action":"update","arg":{"instType":"sp","channel":"books","instId":"GOGUSDT"},"data":[{"asks":[["0.5625","14.3333"],["0.5631","8.8804"],["0.5637","11.6667"],["0.5643","11.0000"],["0.5649","8.8521"],["0.5655","2347.4667"],["0.5661","16.3333"],["0.5667","9.0000"],["0.5673","8.8147"],["0.5685","9.6667"],["0.5697","15.6667"],["0.5703","8.7683"],["0.5709","8.7591"],["0.5715","12.3333"],["0.5727","8.7316"],["0.5733","15.0000"],["0.5739","10.3333"]],"bids":[["0.5506","10.3333"],["0.5500","16.3333"],["0.5494","11.0000"],["0.5488","12.3333"],["0.5482","3680.2333"],["0.5470","9.1418"],["0.5458","9.1619"],["0.5452","11.6667"],["0.5446","9.6667"],["0.5440","13.6667"],["0.5434","9.2023"],["0.5422","9.2227"],["0.5416","13.0000"],["0.5410","15.0000"],["0.5404","9.2534"],["0.5398","15.6667"]],"checksum":441858875,"ts":"1649290085080"}]}
1649290085.151683: {"action":"update","arg":{"instType":"sp","channel":"books","instId":"HOTUSDT"},"data":[{"asks":[["0.0056270","27189.9000"],["0.0056280","47250.0000"],["0.0056300","47250.0000"],["0.0056310","109344.6000"],["0.0056320","69698.7000"],["0.0056830","0"],["0.0059000","12250.0000"],["0.0059010","0"],["0.0059060","9750.0000"],["0.0059070","0"],["0.0059120","4250.0000"],["0.0059130","0"],["0.0059180","7750.0000"],["0.0059190","0"],["0.0059240","4750.0000"],["0.0059250","0"],["0.0059300","5750.0000"],["0.0059310","0"],["0.0059360","5250.0000"],["0.0059370","0"],["0.0059420","10750.0000"],["0.0059430","0"],["0.0059480","3250.0000"],["0.0059490","0"],["0.0059540","3750.0000"],["0.0059550","0"],["0.0059600","7250.0000"],["0.0059610","0"],["0.0059660","11750.0000"],["0.0059670","0"],["0.0059720","11250.0000"],["0.0059730","0"],["0.0059780","6250.0000"],["0.0059790","0"],["0.0059840","10250.0000"],["0.0059850","0"],["0.0059900","8250.0000"],["0.0059910","0"],["0.0059960","6750.0000"],["0.0059970","0"],["0.0060020","9250.0000"],["0.0060030","0"],["0.0060080","2750.0000"],["0.0060090","0"],["0.0060140","8750.0000"],["0.0060150","0"]],"bids":[["0.0056110","147683.7000"],["0.0056070","91426.5000"],["0.0056060","176092.2000"],["0.0056040","31761.4500"],["0.0056010","390552.7500"],["0.0055840","240875.5500"],["0.0055720","0"],["0.0055660","632322.9000"],["0.0055530","140835.6900"],["0.0053380","4750.0000"],["0.0053320","10250.0000"],["0.0053260","9750.0000"],["0.0053200","2750.0000"],["0.0053140","3750.0000"],["0.0053080","8250.0000"],["0.0053020","11250.0000"],["0.0052960","5750.0000"],["0.0052900","7250.0000"],["0.0052840","6250.0000"],["0.0052780","8750.0000"],["0.0052720","10750.0000"],["0.0052660","5250.0000"],["0.0052600","7750.0000"],["0.0052480","4250.0000"],["0.0052420","6750.0000"],["0.0052360","3250.0000"],["0.0052300","11750.0000"],["0.0052240","9250.0000"]],"checksum":1939258453,"ts":"1649290085129"}]}
1649290085.2093859: {"action":"update","arg":{"instType":"sp","channel":"books","instId":"VVSUSDT"},"data":[{"asks":[["0.00002370","657894.7000"],["0.00002373","371345.0000"],["0.00002379","739766.1000"],["0.00002382","209908.6000"],["0.00002385","412280.7000"],["0.00002391","862573.1000"],["0.00002397","903508.8000"],["0.00002403","494152.0000"],["0.00002406","289473.7000"],["0.00002409","821637.4000"]],"bids":[["0.00002267","821637.4000"],["0.00002261","371345.0000"],["0.00002258","494152.0000"],["0.00002255","453216.4000"],["0.00002252","222025.9000"],["0.00002249","903508.8000"],["0.00002243","412280.7000"],["0.00002240","780701.8000"],["0.00002237","698830.4000"],["0.00002234","289473.7000"],["0.00002231","739766.1000"],["0.00002228","862573.1000"]],"checksum":-1693544231,"ts":"1649290085186"}]}
1649290085.262697: {"action":"update","arg":{"instType":"sp","channel":"candle1m","instId":"GOGUSDT"},"data":[["1649290080000","0.5555","0.5575","0.5555","0.5575","8.9687"]]}
1649290085.265901: {"action":"update","arg":{"instType":"sp","channel":"books","instId":"AVAXUSDT"},"data":[{"asks":[["83.1215","82.6560"],["83.1315","55.4680"],["83.2115","9.4920"],["83.2415","130.0880"],["83.2515","180.0000"],["83.3715","7.4270"],["83.4015","0"],["83.6615","0.7490"],["87.9959","0.4833"],["88.0790","0.5500"],["88.1621","0.6833"],["88.3283","0.8167"],["88.4114","0.4500"],["88.4945","0.3167"],["88.5776","0.3833"],["88.6607","0.5833"],["88.7438","0.1833"],["88.8269","0.6167"],["88.9100","0.3500"],["88.9931","0.4167"],["89.0762","0.7500"],["89.1593","0.7833"],["89.2424","0.6500"],["89.3255","0.2833"],["89.4086","0.7167"],["89.4917","0.2167"],["89.5748","0.5167"]],"bids":[["82.8885","44.8980"],["82.8585","71.9460"],["82.8285","180.0000"],["82.8185","124.5160"],["82.7985","46.5010"],["82.7585","148.3580"],["82.7185","121.4850"],["82.6685","104.7970"],["82.6285","78.4140"],["82.6085","46.4380"],["82.5985","113.0990"],["82.5185","180.0000"],["82.4985","23.8350"],["78.0341","0.8167"],["77.9510","0.5833"],["77.8679","0.6167"],["77.7848","0.2833"],["77.7017","0.7167"],["77.6186","0.5167"],["77.5355","0.2167"],["77.4524","0.2500"],["77.3693","0.4500"],["77.2862","0.7500"],["77.2031","0.4167"],["77.1200","0.7833"],["77.0369","0.3500"],["76.9538","0.5500"],["76.8707","0.3167"],["76.7876","0.4833"],["76.7045","0.6500"],["76.5383","0.3833"],["76.4552","0.1833"]],"checksum":-399003619,"ts":"1649290085244"}]}
1649290085.276475: {"action":"update","arg":{"instType":"sp","channel":"books","instId":"STGUSDT"},"data":[{"asks":[["3.034","1.649"],["3.037","2.935"],["3.040","1.667"],["3.043","3.062"],["3.049","5.486"],["3.052","2.174"],["3.055","2.808"],["3.058","2.047"],["3.061","3.569"],["3.064","2.554"],["3.067","1.631"],["3.070","1.630"],["3.073","2.681"],["3.076","3.442"],["3.079","4.950"],["3.082","1.623"],["3.085","1.622"],["3.088","3.315"],["3.091","1.920"],["3.094","2.428"],["3.097","1.615"],["3.100","3.188"]],"bids":[["2.744","3.077"],["2.738","19.860"],["2.735","2.969"],["2.732","100.393"],["2.729","2.323"],["2.726","74.283"],["2.723","1.837"],["2.720","2.538"],["2.711","2.754"],["2.708","3.185"],["2.705","2.215"],["2.702","1.851"],["2.699","2.646"],["2.696","92.631"],["2.687","2.431"],["2.684","3.292"],["2.681","1.866"],["2.675","2.000"],["2.672","1.892"]],"checksum":929885747,"ts":"1649290085255"}]}
1649290085.4549708: {"action":"update","arg":{"instType":"sp","channel":"books","instId":"EOSUSDT"},"data":[{"asks":[["2.4415","32.8332"],["2.4418","195.6669"],["2.4419","1560.6900"],["2.4420","76.2408"],["2.4422","125.0496"],["2.4423","15.3426"],["2.4424","65.7244"],["2.4425","157.9779"],["2.4426","76.5000"],["2.4428","224.1531"],["2.4429","2293.4067"],["2.4430","13.0640"],["2.4431","555.7133"],["2.4432","462.1929"],["2.4433","157.5591"],["2.4434","445.8899"],["2.4435","0"],["2.4437","531.0000"],["2.4438","2981.2759"],["2.4439","2079.7071"],["2.4440","1354.6263"],["2.4441","1355.2879"],["2.4442","3181.5557"],["2.4443","688.1940"],["2.4444","252.0000"],["2.4445","783.0000"],["2.4446","1017.9330"],["2.4447","2766.1329"],["2.4448","1636.6152"],["2.4449","2402.2575"],["2.4450","4743.1179"],["2.4451","2620.3950"],["2.4452","643.9832"],["2.4453","1507.5000"],["2.4454","4414.7700"],["2.4455","7769.6178"],["2.4456","43.1113"],["2.4459","2641.5857"],["2.4460","0"],["2.4462","1289.7069"],["2.4466","604.8000"],["2.4467","37.8900"],["2.4468","308.0412"],["2.4470","1440.7266"],["2.4472","0"],["2.4473","0"],["2.4474","0"],["2.4475","0"],["2.4476","0"],["2.4477","0"],["2.4478","0"],["2.4566","535.7143"],["2.4570","0"],["2.4571","454.7619"],["2.4575","0"],["2.4576","492.8571"],["2.4580","0"],["2.4581","502.3810"],["2.4585","0"],["2.4586","526.1905"],["2.4590","0"],["2.4591","521.4286"],["2.4595","0"],["2.4596","507.1429"],["2.4600","0"],["2.4601","540.4762"],["2.4605","0"],["2.4606","497.6190"],["2.4610","0"],["2.4611","530.9524"],["2.4615","0"],["2.4616","464.2857"],["2.4620","0"],["2.4621","488.0952"],["2.4625","0"],["2.4626","511.9048"],["2.4630","0"],["2.4631","545.2381"],["2.4635","0"],["2.4636","516.6667"],["2.4640","0"],["2.4641","483.3333"],["2.4645","0"],["2.4646","478.5714"],["2.4650","50.0000"],["2.4651","459.5238"],["2.4655","0"],["2.4656","473.8095"],["2.4660","0"],["2.4661","469.0476"],["2.4665","0"]],"bids":[["2.4379","0"],["2.4377","0"],["2.4374","0"],["2.4371","25.2000"],["2.4369","0"],["2.4368","0"],["2.4367","72.9188"],["2.4366","213.6573"],["2.4365","50.6784"],["2.4364","3511.2960"],["2.4363","438.5068"],["2.4362","74.3378"],["2.4361","1096.4250"],["2.4360","813.0985"],["2.4359","1248.6788"],["2.4358","101.1896"],["2.4357","2700.0000"],["2.4356","1746.7517"],["2.4355","0"],["2.4354","1925.5500"],["2.4353","72.9188"],["2.4352","39.6791"],["2.4351","602.0097"],["2.4350","76.2887"],["2.4349","842.1135"],["2.4348","1438.7717"],["2.4347","864.0743"],["2.4346","1929.6778"],["2.4345","267.2048"],["2.4344","1324.8344"],["2.4343","1685.7804"],["2.4341","2255.1091"],["2.4340","98.2696"],["2.4339","72.9188"],["2.4337","225.5085"],["2.4336","1890.2543"],["2.4335","3375.3476"],["2.4334","775.6406"],["2.4332","820.1797"],["2.4331","3954.6309"],["2.4328","279.0309"],["2.4326","504.1279"],["2.4325","1418.3994"],["2.4324","1456.4920"],["2.4323","2812.1256"],["2.4321","6243.0039"],["2.4320","1546.2169"],["2.4319","117.2138"],["2.4228","0"],["2.4224","516.6667"],["2.4223","0"],["2.4219","483.3333"],["2.4218","0"],["2.4214","492.8571"],["2.4213","0"],["2.4209","464.2857"],["2.4208","0"],["2.4204","478.5714"],["2.4203","0"],["2.4199","454.7619"],["2.4198","0"],["2.4194","545.2381"],["2.4193","0"],["2.4189","530.9524"],["2.4188","0"],["2.4184","469.0476"],["2.4183","0"],["2.4179","521.4286"],["2.4178","0"],["2.4174","507.1429"],["2.4173","0"],["2.4169","497.6190"],["2.4168","0"],["2.4164","502.3810"],["2.4163","0"],["2.4159","511.9048"],["2.4158","0"],["2.4154","473.8095"],["2.4153","0"],["2.4149","526.1905"],["2.4148","0"],["2.4144","535.7143"],["2.4143","0"],["2.4139","540.4762"],["2.4138","0"],["2.4134","459.5238"],["2.4133","0"],["2.4129","488.0952"]],"checksum":510152023,"ts":"1649290085433"}]}
1649290085.532906: {"action":"update","arg":{"instType":"sp","channel":"books","instId":"SUNUSDT"},"data":[{"asks":[["0.01510","11785"],["0.01511","731703"],["0.01516","2929"],["0.01582","2500"],["0.01584","5500"],["0.01586","3833"],["0.01588","3500"],["0.01592","6833"],["0.01594","3167"],["0.01596","2833"],["0.01598","8167"],["0.01600","2167"],["0.01602","6167"],["0.01604","4833"],["0.01606","5833"],["0.01608","1833"],["0.01610","6500"],["0.01612","7167"],["0.01614","4167"],["0.01616","4500"],["0.01618","5167"],["0.01620","7500"]],"bids":[["0.01503","176400"],["0.01501","540230"],["0.01496","382431"],["0.01495","3157276"],["0.01492","652201"],["0.01428","5500"],["0.01426","7167"],["0.01424","3500"],["0.01422","6833"],["0.01420","5167"],["0.01418","7833"],["0.01416","2500"],["0.01414","3833"],["0.01412","1833"],["0.01410","4167"],["0.01408","3167"],["0.01406","5833"],["0.01404","4500"],["0.01402","6500"],["0.01400","7500"],["0.01398","6167"],["0.01396","2833"],["0.01394","4833"],["0.01392","2167"]],"checksum":758990037,"ts":"1649290085505"}]}
1649290085.618392: {"action":"update","arg":{"instType":"sp","channel":"books","instId":"GOGUSDT"},"data":[{"asks":[["0.5625","8.8899"],["0.5631","9.0000"],["0.5637","9.6667"],["0.5643","8.8615"],["0.5649","14.3333"],["0.5655","2344.8000"],["0.5661","8.8334"],["0.5667","16.3333"],["0.5673","13.6667"],["0.5679","11.6667"],["0.5685","15.0000"],["0.5697","12.3333"],["0.5703","13.0000"],["0.5715","15.6667"],["0.5721","8.7407"],["0.5727","10.3333"],["0.5733","8.7224"],["0.5739","8.7133"]],"bids":[["0.5506","9.0820"],["0.5500","9.0919"],["0.5488","9.1118"],["0.5482","3681.5667"],["0.5476","13.6667"],["0.5470","13.0000"],["0.5464","11.6667"],["0.5458","10.3333"],["0.5452","9.1719"],["0.5446","9.1821"],["0.5440","12.3333"],["0.5422","16.3333"],["0.5416","14.3333"],["0.5410","9.6667"],["0.5404","15.0000"],["0.5398","9.2637"]],"checksum":-404919394,"ts":"1649290085594"}]}
1649290085.720022: {"action":"update","arg":{"instType":"sp","channel":"books","instId":"CULTUSDT"},"data":[{"asks":[["0.00003614","306667"],["0.00003618","440000"],["0.00003622","653333"],["0.00003626","626667"],["0.00003634","146667"],["0.00003638","546667"],["0.00003642","573333"],["0.00003646","873723"],["0.00003650","360000"],["0.00003654","200000"],["0.00003658","173333"],["0.00003662","280000"],["0.00003666","333333"],["0.00003670","520000"],["0.00003674","253333"],["0.00003678","226667"],["0.00003682","466667"],["0.00003686","386667"],["0.00003690","493333"]],"bids":[["0.00003471","146667"],["0.00003467","1795230"],["0.00003463","360000"],["0.00003459","600000"],["0.00003455","668154"],["0.00003451","626667"],["0.00003447","386667"],["0.00003443","333333"],["0.00003439","253333"],["0.00003435","546667"],["0.00003431","226667"],["0.00003427","173333"],["0.00003423","466667"],["0.00003419","306667"],["0.00003415","520000"],["0.00003411","573333"],["0.00003407","493333"],["0.00003403","440000"],["0.00003399","200000"],["0.00003395","413333"]],"checksum":-123107852,"ts":"1649290085696"}]}
1649290085.738485: {"action":"update","arg":{"instType":"sp","channel":"books","instId":"VVSUSDT"},"data":[{"asks":[["0.00002370","739766.1000"],["0.00002373","780701.8000"],["0.00002379","494152.0000"],["0.00002382","698830.4000"],["0.00002385","616959.1000"],["0.00002397","453216.4000"],["0.00002403","330409.4000"],["0.00002406","248538.0000"],["0.00002409","657894.7000"]],"bids":[["0.00002267","739766.1000"],["0.00002261","330409.4000"],["0.00002258","698830.4000"],["0.00002255","576023.4000"],["0.00002252","780701.8000"],["0.00002249","821637.4000"],["0.00002243","453216.4000"],["0.00002240","657894.7000"],["0.00002237","616959.1000"],["0.00002234","862573.1000"],["0.00002231","248538.0000"],["0.00002228","494152.0000"]],"checksum":-1046943345,"ts":"1649290085715"}]}
1649290085.759265: {"action":"update","arg":{"instType":"sp","channel":"books","instId":"HOTUSDT"},"data":[{"asks":[["0.0056270","0"],["0.0056280","0"],["0.0056290","47250.0000"],["0.0056300","89146.8000"],["0.0056310","24269.4000"],["0.0056320","15995.7000"],["0.0056340","60042.6000"],["0.0056370","555581.7000"],["0.0056410","112133.7000"],["0.0056610","800000.0000"],["0.0056800","271800.0000"],["0.0056830","210522.1500"],["0.0059000","0"],["0.0059030","6250.0000"],["0.0059060","0"],["0.0059090","8250.0000"],["0.0059120","0"],["0.0059150","3250.0000"],["0.0059180","0"],["0.0059210","12250.0000"],["0.0059240","0"],["0.0059270","2750.0000"],["0.0059300","0"],["0.0059330","10250.0000"],["0.0059360","0"],["0.0059390","5250.0000"],["0.0059420","0"],["0.0059450","7750.0000"],["0.0059480","0"],["0.0059510","7250.0000"],["0.0059540","0"],["0.0059570","5750.0000"],["0.0059600","0"],["0.0059630","8750.0000"],["0.0059660","0"],["0.0059690","10750.0000"],["0.0059720","0"],["0.0059750","11250.0000"],["0.0059780","0"],["0.0059810","11750.0000"],["0.0059840","0"],["0.0059870","9750.0000"],["0.0059900","0"],["0.0059930","9250.0000"],["0.0059960","0"],["0.0059990","4750.0000"],["0.0060020","0"],["0.0060050","3750.0000"],["0.0060080","0"],["0.0060110","6750.0000"],["0.0060140","0"],["0.0060170","4250.0000"]],"bids":[["0.0056130","56310.4800"],["0.0056120","67654.8000"],["0.0056100","51913.8000"],["0.0056090","54485.1000"],["0.0056050","800000.0000"],["0.0056040","670752.4500"],["0.0056030","65558.3000"],["0.0056020","298847.2500"],["0.0055990","165547.3500"],["0.0055980","73468.3500"],["0.0055930","591524.5100"],["0.0055680","800000.0000"],["0.0055660","4743.0000"],["0.0055620","39999.6000"],["0.0055610","250792.2000"],["0.0055560","0"],["0.0055550","0"],["0.0055540","0"],["0.0055530","0"],["0.0053390","4750.0000"],["0.0053380","0"],["0.0053330","2750.0000"],["0.0053320","0"],["0.0053270","12250.0000"],["0.0053260","0"],["0.0053210","7250.0000"],["0.0053200","0"],["0.0053150","10250.0000"],["0.0053140","0"],["0.0053090","5750.0000"],["0.0053080","0"],["0.0053030","6250.0000"],["0.0053020","0"],["0.0052970","3250.0000"],["0.0052960","0"],["0.0052910","4250.0000"],["0.0052900","0"],["0.0052850","8750.0000"],["0.0052840","0"],["0.0052790","11250.0000"],["0.0052780","0"],["0.0052730","9750.0000"],["0.0052720","0"],["0.0052670","8250.0000"],["0.0052660","0"],["0.0052610","7750.0000"],["0.0052600","0"],["0.0052550","5250.0000"],["0.0052540","0"],["0.0052490","9250.0000"],["0.0052480","0"],["0.0052430","11750.0000"],["0.0052420","0"],["0.0052370","10750.0000"],["0.0052360","0"],["0.0052310","6750.0000"],["0.0052300","0"],["0.0052250","3750.0000"],["0.0052240","0"]],"checksum":1142730364,"ts":"1649290085733"}]}
1649290085.820298: {"action":"update","arg":{"instType":"sp","channel":"books","instId":"AVAXUSDT"},"data":[{"asks":[["83.1315","97.6290"],["83.1615","180.0000"],["83.4515","140.0700"],["83.4815","78.7010"],["83.6615","0"],["87.9959","0.8167"],["88.0790","0.3833"],["88.1621","0.4167"],["88.2452","0.7833"],["88.3283","0.4500"],["88.4114","0.4833"],["88.4945","0.6167"],["88.5776","0.3500"],["88.6607","0.6500"],["88.7438","0.3167"],["88.8269","0.7500"],["88.9100","0.2167"],["88.9931","0.2500"],["89.0762","0.7167"],["89.1593","0.5500"],["89.2424","0.5167"],["89.3255","0.5833"],["89.4086","0.6833"],["89.4917","0.2833"],["89.5748","0.1833"]],"bids":[["82.8085","180.0000"],["82.7885","180.0000"],["82.7585","137.9770"],["82.7285","178.6750"],["82.5885","16.8630"],["78.0341","0.7833"],["77.9510","0.4833"],["77.7848","0.4167"],["77.7017","0.2833"],["77.6186","0.3167"],["77.5355","0.8167"],["77.4524","0.1833"],["77.3693","0.7500"],["77.2862","0.2500"],["77.2031","0.3833"],["77.1200","0.5500"],["77.0369","0.5833"],["76.9538","0.3500"],["76.8707","0.6500"],["76.7876","0.6833"],["76.7045","0.2167"],["76.6214","0.4500"],["76.5383","0.5167"],["76.4552","0.7167"]],"checksum":-457399506,"ts":"1649290085798"}]}
1649290085.829033: {"action":"update","arg":{"instType":"sp","channel":"books","instId":"STGUSDT"},"data":[{"asks":[["3.034","3.442"],["3.040","2.047"],["3.043","3.188"],["3.046","3.569"],["3.049","6.247"],["3.052","2.681"],["3.055","2.174"],["3.058","1.636"],["3.061","1.634"],["3.064","1.667"],["3.070","2.808"],["3.073","1.628"],["3.076","1.920"],["3.079","6.472"],["3.085","2.428"],["3.088","2.301"],["3.091","1.793"],["3.094","1.617"],["3.100","2.554"]],"bids":[["2.759","0"],["2.744","1.823"],["2.738","18.567"],["2.735","1.829"],["2.732","98.885"],["2.729","1.833"],["2.726","76.113"],["2.723","3.185"],["2.720","1.839"],["2.717","2.108"],["2.714","2.862"],["2.711","2.538"],["2.708","1.847"],["2.705","2.000"],["2.702","3.077"],["2.699","1.854"],["2.696","93.277"],["2.690","2.323"],["2.687","1.862"],["2.684","2.969"],["2.681","2.646"],["2.678","2.215"],["2.675","2.431"],["2.672","2.754"],["1.296","330.000"]],"checksum":-1448213433,"ts":"1649290085803"}]}
1649290086.031244: {"action":"update","arg":{"instType":"sp","channel":"books","instId":"EOSUSDT"},"data":[{"asks":[["2.4419","828.1842"],["2.4420","138.2508"],["2.4422","108.3215"],["2.4424","70.5420"],["2.4428","251.6951"],["2.4429","2283.9182"],["2.4430","2588.4070"],["2.4433","2387.0250"],["2.4436","190.8000"],["2.4438","1504.2214"],["2.4439","2932.1649"],["2.4440","953.5145"],["2.4443","1873.0362"],["2.4444","139.5591"],["2.4447","1419.5258"],["2.4448","1300.6152"],["2.4452","541.4355"],["2.4453","1137.3000"],["2.4454","4918.7700"],["2.4458","0"],["2.4459","3185.9057"],["2.4466","414.9000"],["2.4469","1860.5413"],["2.4471","45.6167"],["2.4565","545.2381"],["2.4566","0"],["2.4570","459.5238"],["2.4571","0"],["2.4575","464.2857"],["2.4576","0"],["2.4580","483.3333"],["2.4581","0"],["2.4585","526.1905"],["2.4586","0"],["2.4590","535.7143"],["2.4591","0"],["2.4595","502.3810"],["2.4596","0"],["2.4600","521.4286"],["2.4601","0"],["2.4605","478.5714"],["2.4606","0"],["2.4610","497.6190"],["2.4611","0"],["2.4615","492.8571"],["2.4616","0"],["2.4620","454.7619"],["2.4621","0"],["2.4625","473.8095"],["2.4626","0"],["2.4630","469.0476"],["2.4631","0"],["2.4635","507.1429"],["2.4636","0"],["2.4640","516.6667"],["2.4641","0"],["2.4645","530.9524"],["2.4646","0"],["2.4650","540.4762"],["2.4651","0"],["2.4655","511.9048"],["2.4656","0"],["2.4660","488.0952"],["2.4661","0"]],"bids":[["2.4377","167.4122"],["2.4375","0"],["2.4365","2076.2100"],["2.4363","196.9601"],["2.4362","57.2400"],["2.4361","1214.9550"],["2.4359","957.4701"],["2.4356","1639.0023"],["2.4355","45.8839"],["2.4354","715.9783"],["2.4352","8.0532"],["2.4351","2103.7948"],["2.4349","1763.1135"],["2.4343","1704.3120"],["2.4342","863.6420"],["2.4337","473.9986"],["2.4335","3830.5398"],["2.4326","614.7585"],["2.4319","0"],["2.4224","0"],["2.4223","464.2857"],["2.4219","0"],["2.4218","459.5238"],["2.4214","0"],["2.4213","545.2381"],["2.4209","0"],["2.4208","507.1429"],["2.4204","0"],["2.4203","535.7143"],["2.4199","0"],["2.4198","492.8571"],["2.4194","0"],["2.4193","516.6667"],["2.4189","0"],["2.4188","502.3810"],["2.4184","0"],["2.4183","469.0476"],["2.4179","0"],["2.4178","478.5714"],["2.4174","0"],["2.4173","483.3333"],["2.4169","0"],["2.4168","454.7619"],["2.4164","0"],["2.4163","526.1905"],["2.4159","0"],["2.4158","540.4762"],["2.4154","0"],["2.4153","521.4286"],["2.4149","0"],["2.4148","511.9048"],["2.4144","0"],["2.4143","473.8095"],["2.4139","0"],["2.4138","488.0952"],["2.4134","0"],["2.4133","497.6190"],["2.4129","0"],["2.4128","530.9524"]],"checksum":-164174271,"ts":"1649290086005"}]}
1649290086.050681: {"action":"update","arg":{"instType":"sp","channel":"trade","instId":"AVAXUSDT"},"data":[["1649290086013","82.9972","0.0603","buy"]]}
1649290086.0633411: {"action":"update","arg":{"instType":"sp","channel":"books","instId":"SUNUSDT"},"data":[{"asks":[["0.01508","103119"],["0.01509","36637"],["0.01511","647365"],["0.01512","446824"],["0.01514","517009"],["0.01516","1138"],["0.01523","0"],["0.01566","2122"],["0.01582","6500"],["0.01584","7833"],["0.01586","2833"],["0.01588","5833"],["0.01590","3833"],["0.01592","3167"],["0.01594","7500"],["0.01596","2167"],["0.01598","5167"],["0.01600","5500"],["0.01604","1833"],["0.01606","8167"],["0.01608","4833"],["0.01610","4167"],["0.01612","3500"],["0.01614","2500"],["0.01618","6833"],["0.01620","7167"]],"bids":[["0.01502","144097"],["0.01499","1323730"],["0.01494","24096"],["0.01493","49837"],["0.01492","603970"],["0.01450","0"],["0.01430","3167"],["0.01428","4500"],["0.01426","2167"],["0.01424","8167"],["0.01422","4167"],["0.01418","1833"],["0.01416","2833"],["0.01414","2500"],["0.01412","5833"],["0.01410","3500"],["0.01408","6833"],["0.01406","7167"],["0.01404","4833"],["0.01402","7500"],["0.01400","5500"],["0.01398","6500"],["0.01396","3833"],["0.01394","7833"],["0.01392","6167"]],"checksum":1640087735,"ts":"1649290086041"}]}
