1649290096.722373: {"action":"snapshot","arg":{"instType":"mc","channel":"ticker","instId":"UNIUSDT"},"data":[{"instId":"UNIUSDT","last":"9.9860","bestAsk":"9.985","bestBid":"9.98","high24h":"10.4280","low24h":"9.9030","priceChangePercent":"-0.0385","capitalRate":"-0.000100","nextSettleTime":1649314800000,"systemTime":1649290096685,"markPrice":"9.9875","indexPrice":"9.9951","holding":"369411","baseVolume":"313098","quoteVolume":"3294594"}]}
1649290096.731831: {"action":"snapshot","arg":{"instType":"mc","channel":"ticker","instId":"DASHUSDT"},"data":[{"instId":"DASHUSDT","last":"113.550","bestAsk":"113.52","bestBid":"113.47","high24h":"118.870","low24h":"113.140","priceChangePercent":"-0.035","capitalRate":"-0.000100","nextSettleTime":1649314800000,"systemTime":1649290096702,"markPrice":"113.457","indexPrice":"113.503","holding":"21957.17","baseVolume":"25305.79","quoteVolume":"3062825.39"}]}
1649290097.003106: {"action":"update","arg":{"instType":"mc","channel":"books","instId":"UNIUSDT"},"data":[{"asks":[["9.983","230"],["9.985","237"],["9.986","215"],["9.987","292"],["9.988","170"],["9.989","118"],["9.990","363"],["9.991","687"],["9.992","1496"],["9.993","934"],["9.994","2316"],["9.995","295"],["9.996","790"],["9.997","639"],["9.998","320"],["9.999","1045"],["10.000","339"],["10.001","1167"],["10.002","2633"],["10.003","905"],["10.004","684"],["10.005","1079"],["10.006","973"],["10.007","904"],["10.008","226"],["10.010","591"],["10.011","1372"],["10.012","663"],["10.013","1426"],["10.016","287"],["10.017","155"],["10.020","4291"],["10.022","903"],["10.025","1093"],["10.027","5746"],["10.028","264"],["10.030","197"],["10.031","13174"],["10.032","704"],["10.033","1759"],["10.036","12597"],["10.038","0"],["10.041","11828"],["10.043","0"],["10.046","13559"],["10.048","0"],["10.051","12405"],["10.053","0"],["10.056","13366"],["10.058","0"],["10.061","12982"],["10.063","0"],["10.066","11636"],["10.068","0"],["10.071","12213"],["10.073","0"],["10.076","12789"],["10.078","0"],["10.081","12020"],["10.083","0"],["10.086","11443"],["10.088","0"],["10.117","231"],["10.125","0"],["10.169","255"],["10.177","0"],["10.221","44"],["10.229","0"],["10.273","159"],["10.281","0"],["10.325","242"],["10.333","0"],["10.377","86"],["10.385","0"],["10.429","123"],["10.437","0"],["10.481","170"],["10.489","0"],["10.533","223"],["10.541","0"],["10.585","323"],["10.593","0"],["10.637","333"],["10.645","0"],["10.689","52"],["10.697","0"],["10.741","163"],["10.749","0"],["10.793","17"],["10.801","0"],["10.845","144"],["10.853","0"],["10.897","162"],["10.905","0"],["10.949","368"],["10.957","0"],["11.001","356"],["11.009","0"],["11.053","84"],["11.061","0"],["11.105","325"],["11.113","0"],["11.157","114"],["11.165","0"],["11.209","236"],["11.217","0"],["11.261","167"],["11.269","0"],["11.313","98"],["11.321","0"],["11.365","134"],["11.373","0"],["11.417","247"],["11.425","0"],["11.469","171"],["11.477","0"]],"bids":[["9.980","0"],["9.979","0"],["9.978","174"],["9.977","262"],["9.976","76"],["9.975","101"],["9.974","135"],["9.973","775"],["9.972","49"],["9.971","306"],["9.970","255"],["9.969","135"],["9.968","1053"],["9.967","368"],["9.966","67"],["9.965","74"],["9.964","1370"],["9.963","755"],["9.962","301"],["9.961","2079"],["9.960","576"],["9.958","830"],["9.957","1061"],["9.956","716"],["9.955","462"],["9.953","593"],["9.952","1246"],["9.951","882"],["9.950","4351"],["9.949","646"],["9.948","1048"],["9.947","384"],["9.945","1080"],["9.944","192"],["9.943","887"],["9.942","1004"],["9.941","2087"],["9.940","3906"],["9.939","976"],["9.938","162"],["9.934","3671"],["9.933","6939"],["9.932","633"],["9.930","14493"],["9.929","369"],["9.927","0"],["9.925","12982"],["9.922","0"],["9.920","13559"],["9.917","0"],["9.915","12597"],["9.912","0"],["9.910","13174"],["9.907","0"],["9.905","11828"],["9.902","0"],["9.900","12020"],["9.897","0"],["9.895","13366"],["9.892","0"],["9.890","12405"],["9.887","0"],["9.885","11443"],["9.882","0"],["9.880","12213"],["9.877","0"],["9.875","11636"],["9.747","0"],["9.739","351"],["9.696","0"],["9.688","399"],["9.645","0"],["9.637","274"],["9.593","0"],["9.585","23"],["9.542","0"],["9.534","112"],["9.491","0"],["9.483","47"],["9.440","0"],["9.432","290"],["9.389","0"],["9.381","318"],["9.338","0"],["9.330","326"],["9.287","0"],["9.279","106"],["9.236","0"],["9.228","193"],["9.185","0"],["9.177","376"],["9.134","0"],["9.126","231"],["9.083","0"],["9.075","4"],["9.032","0"],["9.024","149"],["8.981","0"],["8.973","85"],["8.930","0"],["8.922","320"],["8.879","0"],["8.871","61"],["8.828","0"],["8.820","131"],["8.777","0"],["8.769","477"],["8.726","0"],["8.718","367"],["8.675","0"],["8.667","253"],["8.624","0"],["8.616","83"],["8.573","0"],["8.565","48"]],"checksum":1567000410,"ts":"1649290096976"}]}
1649290097.019288: {"action":"update","arg":{"instType":"mc","channel":"books","instId":"DASHUSDT"},"data":[{"asks":[["113.49","3.29"],["113.50","3.97"],["113.51","38.34"],["113.52","32.55"],["113.53","5.85"],["113.55","2.95"],["113.56","71.83"],["113.57","13.87"],["113.58","35.35"],["113.59","8.37"],["113.60","92.83"],["113.61","25.11"],["113.62","21.10"],["113.63","250.34"],["113.64","130.05"],["113.65","179.17"],["113.66","20.59"],["113.67","41.88"],["113.68","1600.02"],["113.69","17.45"],["113.70","71.74"],["113.71","84.13"],["113.72","51.37"],["113.73","61.70"],["113.74","73.20"],["113.75","239.07"],["113.76","231.67"],["113.77","755.97"],["113.78","249.09"],["113.79","107.22"],["113.80","74.23"],["113.81","16.70"],["113.82","27.05"],["113.83","12.58"],["113.84","256.18"],["113.85","340.31"],["113.86","109.07"],["113.87","168.45"],["113.88","134.73"],["113.89","120.16"],["113.91","24.31"],["113.92","2070.01"],["113.93","27.64"],["113.94","277.90"],["113.96","127.82"],["113.97","214.84"],["113.98","1750.44"],["113.99","0"],["114.04","1930.16"],["114.05","0"],["114.10","1974.27"],["114.11","0"],["114.16","1753.69"],["114.17","0"],["114.22","1709.57"],["114.23","0"],["114.28","1841.92"],["114.29","0"],["114.34","2018.39"],["114.35","0"],["114.40","1797.80"],["114.41","0"],["114.46","2040.45"],["114.47","0"],["114.52","1952.22"],["114.53","0"],["114.58","1996.33"],["114.59","0"],["114.64","1819.86"],["114.65","0"],["114.70","1886.04"],["114.71","0"],["114.76","1775.75"],["114.77","0"],["114.82","1863.98"],["114.83","0"],["115.78","0.73"],["116.00","0"],["116.37","68.26"],["116.59","0"],["116.96","70.90"],["117.18","0"],["117.55","49.89"],["117.77","0"],["118.14","22.59"],["118.36","0"],["118.73","47.85"],["118.95","0"],["119.32","46.71"],["119.54","0"],["119.91","23.57"],["120.13","0"],["120.50","59.15"],["120.72","0"],["121.09","6.51"],["121.31","0"],["121.68","54.25"],["121.90","0"],["122.27","14.99"],["122.49","0"],["122.86","11.21"],["123.08","0"],["123.45","66.50"],["123.67","0"],["124.04","64.47"],["124.26","0"],["124.63","42.85"],["124.85","0"],["125.22","29.99"],["125.44","0"],["125.81","4.07"],["126.03","0"],["126.40","26.70"],["126.62","0"],["126.99","20.67"],["127.21","0"],["127.58","56.99"],["127.80","0"],["128.17","44.01"],["128.39","0"],["128.76","46.60"],["128.98","0"],["129.35","39.07"],["129.57","0"],["129.94","19.33"],["130.16","0"],["130.53","20.66"],["130.75","0"],["131.12","28.11"],["131.34","0"],["131.71","13.65"],["131.93","0"],["132.52","0"],["133.11","0"],["133.70","0"]],"bids":[["113.45","0"],["113.43","338.59"],["113.42","9.91"],["113.41","342.55"],["113.39","71.29"],["113.38","12.66"],["113.37","119.62"],["113.36","72.28"],["113.35","1600.21"],["113.34","14.01"],["113.33","26.60"],["113.32","13.20"],["113.31","14.62"],["113.30","33.20"],["113.29","168.67"],["113.28","14.40"],["113.27","11.70"],["113.26","103.79"],["113.25","66.43"],["113.23","198.66"],["113.22","52.47"],["113.21","35.77"],["113.20","39.43"],["113.19","0"],["113.18","62.70"],["113.17","91.09"],["113.16","2.58"],["113.15","112.93"],["113.14","396.81"],["113.13","68.49"],["113.12","13.23"],["113.10","1600.08"],["113.09","36.26"],["113.08","164.91"],["113.07","18.87"],["113.04","16.47"],["113.03","56.72"],["113.02","43.38"],["113.01","37.62"],["113.00","1839.88"],["112.99","23.88"],["112.98","529.91"],["112.96","190.26"],["112.94","1776.48"],["112.93","14.16"],["112.90","0"],["112.88","1974.27"],["112.84","0"],["112.82","1886.04"],["112.78","0"],["112.76","1908.10"],["112.72","0"],["112.70","1996.33"],["112.66","0"],["112.64","1731.63"],["112.60","0"],["112.58","2040.45"],["112.54","0"],["112.52","1952.22"],["112.48","0"],["112.46","1753.69"],["112.42","0"],["112.40","1930.16"],["112.36","0"],["112.34","2018.39"],["112.30","0"],["112.28","1841.92"],["112.24","0"],["112.22","1863.98"],["112.18","0"],["112.16","1819.86"],["112.12","0"],["112.10","1797.80"],["111.66","54.98"],["111.61","0"],["111.07","56.15"],["111.02","0"],["110.47","22.20"],["110.43","0"],["109.88","45.95"],["109.84","0"],["109.29","29.62"],["109.25","0"],["108.70","21.93"],["108.66","0"],["108.11","6.02"],["108.07","0"],["107.52","55.97"],["107.48","0"],["106.93","21.31"],["106.89","0"],["106.34","8.95"],["106.30","0"],["105.75","10.15"],["105.71","0"],["105.16","40.07"],["105.12","0"],["104.57","15.36"],["104.53","0"],["103.98","46.47"],["103.94","0"],["103.39","11.11"],["103.35","0"],["102.80","1.87"],["102.76","0"],["102.21","37.67"],["102.17","0"],["101.62","21.48"],["101.58","0"],["101.03","49.80"],["100.99","0"],["100.44","49.32"],["100.40","0"],["99.85","42.14"],["99.26","8.55"],["98.67","30.36"],["98.08","20.32"],["97.49","36.65"],["96.90","21.95"],["96.31","8.41"],["95.72","31.49"],["95.13","57.35"],["94.54","3.45"],["93.95","4.85"],["93.36","74.35"],["92.77","33.85"],["92.18","20.24"]],"checksum":-2069883470,"ts":"1649290096990"}]}
1649290097.025398: {"action":"snapshot","arg":{"instType":"mc","channel":"ticker","instId":"UNIUSDT"},"data":[{"instId":"UNIUSDT","last":"9.9860","bestAsk":"9.983","bestBid":"9.978","high24h":"10.4280","low24h":"9.9030","priceChangePercent":"-0.0385","capitalRate":"-0.000100","nextSettleTime":1649314800000,"systemTime":1649290096992,"markPrice":"9.9875","indexPrice":"9.9902","holding":"369411","baseVolume":"313098","quoteVolume":"3294594"}]}
1649290097.076378: {"action":"snapshot","arg":{"instType":"mc","channel":"ticker","instId":"DASHUSDT"},"data":[{"instId":"DASHUSDT","last":"113.550","bestAsk":"113.49","bestBid":"113.43","high24h":"118.870","low24h":"113.140","priceChangePercent":"-0.035","capitalRate":"-0.000100","nextSettleTime":1649314800000,"systemTime":1649290097044,"markPrice":"113.467","indexPrice":"113.490","holding":"21957.17","baseVolume":"25305.79","quoteVolume":"3062825.39"}]}
1649290097.27857: {"action":"update","arg":{"instType":"mc","channel":"trade","instId":"UNIUSDT"},"data":[["1649290097158","9.98","3","buy"]]}
1649290097.3054368: {"action":"update","arg":{"instType":"mc","channel":"books","instId":"UNIUSDT"},"data":[{"asks":[["9.981","143"],["9.982","288"],["9.985","154"],["9.986","220"],["9.987","525"],["9.988","675"],["9.989","161"],["9.990","469"],["9.991","230"],["9.992","1699"],["9.993","703"],["9.994","2222"],["9.995","470"],["9.996","943"],["9.997","821"],["9.998","342"],["9.999","1183"],["10.000","567"],["10.001","930"],["10.002","2472"],["10.003","1083"],["10.004","598"],["10.005","579"],["10.006","948"],["10.007","629"],["10.008","225"],["10.010","543"],["10.011","1830"],["10.012","658"],["10.013","1400"],["10.014","5332"],["10.015","221"],["10.016","376"],["10.017","197"],["10.018","70"],["10.019","141"],["10.022","4245"],["10.025","1209"],["10.026","4995"],["10.027","1780"],["10.029","20117"],["10.031","0"],["10.033","0"],["10.034","13174"],["10.036","0"],["10.039","12982"],["10.041","0"],["10.044","11636"],["10.046","0"],["10.049","12405"],["10.051","0"],["10.054","12020"],["10.056","0"],["10.059","12213"],["10.061","0"],["10.064","13366"],["10.066","0"],["10.069","12789"],["10.071","0"],["10.074","12597"],["10.076","0"],["10.079","13559"],["10.081","0"],["10.084","11443"],["10.086","0"],["10.111","231"],["10.117","0"],["10.163","255"],["10.169","0"],["10.215","44"],["10.221","0"],["10.267","159"],["10.273","0"],["10.319","242"],["10.325","0"],["10.371","86"],["10.377","0"],["10.423","123"],["10.429","0"],["10.475","170"],["10.481","0"],["10.527","223"],["10.533","0"],["10.579","323"],["10.585","0"],["10.631","333"],["10.637","0"],["10.683","52"],["10.689","0"],["10.735","163"],["10.741","0"],["10.787","17"],["10.793","0"],["10.839","144"],["10.845","0"],["10.891","162"],["10.897","0"],["10.943","368"],["10.949","0"],["10.995","356"],["11.001","0"],["11.047","84"],["11.053","0"],["11.099","325"],["11.105","0"],["11.151","114"],["11.157","0"],["11.203","236"],["11.209","0"],["11.255","167"],["11.261","0"],["11.307","98"],["11.313","0"],["11.359","134"],["11.365","0"],["11.411","247"],["11.417","0"],["11.463","171"],["11.469","0"]],"bids":[["9.978","0"],["9.977","0"],["9.976","229"],["9.975","39"],["9.974","291"],["9.973","1050"],["9.972","228"],["9.971","213"],["9.970","147"],["9.969","241"],["9.968","665"],["9.967","151"],["9.966","235"],["9.965","86"],["9.964","1644"],["9.963","1012"],["9.962","332"],["9.961","562"],["9.960","273"],["9.958","772"],["9.957","814"],["9.956","600"],["9.955","413"],["9.954","284"],["9.953","709"],["9.952","325"],["9.951","872"],["9.950","4173"],["9.949","630"],["9.948","1267"],["9.947","393"],["9.946","288"],["9.945","1183"],["9.944","336"],["9.943","900"],["9.942","1591"],["9.941","1280"],["9.940","515"],["9.937","3758"],["9.936","678"],["9.935","181"],["9.934","3839"],["9.933","149"],["9.932","517"],["9.930","1705"],["9.929","222"],["9.928","13174"],["9.927","5113"],["9.926","431"],["9.925","0"],["9.923","11636"],["9.920","0"],["9.918","11828"],["9.915","0"],["9.913","11443"],["9.910","0"],["9.908","12020"],["9.905","0"],["9.903","12982"],["9.900","0"],["9.898","13366"],["9.895","0"],["9.893","12405"],["9.890","0"],["9.888","12213"],["9.885","0"],["9.883","13559"],["9.880","0"],["9.878","12789"],["9.875","0"],["9.873","12597"],["9.739","0"],["9.733","351"],["9.688","0"],["9.682","399"],["9.637","0"],["9.631","274"],["9.585","0"],["9.579","23"],["9.534","0"],["9.528","112"],["9.483","0"],["9.477","47"],["9.432","0"],["9.426","290"],["9.381","0"],["9.375","318"],["9.330","0"],["9.324","326"],["9.279","0"],["9.273","106"],["9.228","0"],["9.222","193"],["9.177","0"],["9.171","376"],["9.126","0"],["9.120","231"],["9.075","0"],["9.069","4"],["9.024","0"],["9.018","149"],["8.973","0"],["8.967","85"],["8.922","0"],["8.916","320"],["8.871","0"],["8.865","61"],["8.820","0"],["8.814","131"],["8.769","0"],["8.763","477"],["8.718","0"],["8.712","367"],["8.667","0"],["8.661","253"],["8.616","0"],["8.610","83"],["8.565","0"],["8.559","48"]],"checksum":-867570414,"ts":"1649290097277"}]}
1649290097.331187: {"action":"update","arg":{"instType":"mc","channel":"books","instId":"DASHUSDT"},"data":[{"asks":[["113.48","6.96"],["113.50","10.95"],["113.52","41.71"],["113.53","3.13"],["113.54","51.66"],["113.57","26.21"],["113.59","1.88"],["113.60","63.15"],["113.62","18.82"],["113.63","20.25"],["113.64","133.35"],["113.65","97.99"],["113.66","26.53"],["113.67","24.41"],["113.68","7.04"],["113.69","61.32"],["113.70","81.56"],["113.71","93.25"],["113.72","40.02"],["113.73","1527.89"],["113.74","77.55"],["113.75","121.93"],["113.77","753.07"],["113.78","658.45"],["113.79","37.08"],["113.80","68.29"],["113.82","29.28"],["113.83","14.07"],["113.85","497.72"],["113.87","173.22"],["113.89","130.36"],["113.91","1963.19"],["113.92","152.15"],["113.95","9.65"],["113.96","254.14"],["113.97","1974.95"],["113.98","0"],["114.03","1974.27"],["114.04","0"],["114.09","1863.98"],["114.10","0"],["114.15","1952.22"],["114.16","0"],["114.21","1886.04"],["114.22","0"],["114.27","1797.80"],["114.28","0"],["114.33","1731.63"],["114.34","0"],["114.39","2018.39"],["114.40","0"],["114.45","2040.45"],["114.46","0"],["114.51","1908.10"],["114.52","0"],["114.57","1841.92"],["114.58","0"],["114.63","1930.16"],["114.64","0"],["114.69","1819.86"],["114.70","0"],["114.75","1996.33"],["114.76","0"],["114.81","1753.69"],["114.82","0"]],"bids":[["113.43","0"],["113.41","1600.18"],["113.40","99.28"],["113.39","20.80"],["113.38","15.66"],["113.36","42.58"],["113.35","566.29"],["113.34","27.24"],["113.33","23.58"],["113.31","149.82"],["113.30","29.57"],["113.29","7.74"],["113.27","170.59"],["113.26","88.45"],["113.25","69.21"],["113.24","25.48"],["113.23","140.43"],["113.21","50.17"],["113.20","28.04"],["113.18","60.37"],["113.16","214.15"],["113.15","130.15"],["113.14","395.65"],["113.13","45.90"],["113.12","7.45"],["113.10","1502.75"],["113.09","5.68"],["113.08","147.10"],["113.07","42.03"],["113.02","44.26"],["113.00","64.14"],["112.99","1844.40"],["112.94","66.92"],["112.93","1767.84"],["112.92","20.24"],["112.88","0"],["112.87","2040.45"],["112.82","0"],["112.81","1841.92"],["112.76","0"],["112.75","1908.10"],["112.70","0"],["112.69","1863.98"],["112.64","0"],["112.63","1709.57"],["112.58","0"],["112.57","1775.75"],["112.52","0"],["112.51","2018.39"],["112.46","0"],["112.45","1930.16"],["112.40","0"],["112.39","1974.27"],["112.34","0"],["112.33","1797.80"],["112.28","0"],["112.27","1731.63"],["112.22","0"],["112.21","1886.04"],["112.16","0"],["112.15","1952.22"],["112.10","0"],["112.09","1996.33"]],"checksum":1108258891,"ts":"1649290097303"}]}
1649290097.3577962: {"action":"snapshot","arg":{"instType":"mc","channel":"ticker","instId":"UNIUSDT"},"data":[{"instId":"UNIUSDT","last":"9.9800","bestAsk":"9.981","bestBid":"9.976","high24h":"10.4280","low24h":"9.9030","priceChangePercent":"-0.0385","capitalRate":"-0.000100","nextSettleTime":1649314800000,"systemTime":1649290097316,"markPrice":"9.9865","indexPrice":"9.9951","holding":"369411","baseVolume":"313098","quoteVolume":"3294594"}]}
1649290097.3578932: {"action":"snapshot","arg":{"instType":"mc","channel":"ticker","instId":"DASHUSDT"},"data":[{"instId":"DASHUSDT","last":"113.550","bestAsk":"113.48","bestBid":"113.43","high24h":"118.870","low24h":"113.140","priceChangePercent":"-0.035","capitalRate":"-0.000100","nextSettleTime":1649314800000,"systemTime":1649290097326,"markPrice":"113.467","indexPrice":"113.503","holding":"21957.17","baseVolume":"25305.79","quoteVolume":"3062825.39"}]}
1649290097.565542: {"action":"update","arg":{"instType":"mc","channel":"candle1m","instId":"UNIUSDT"},"data":[["1649290080000","9.977","9.986","9.976","9.98","28"]]}
1649290097.603929: {"action":"snapshot","arg":{"instType":"mc","channel":"ticker","instId":"UNIUSDT"},"data":[{"instId":"UNIUSDT","last":"9.9800","bestAsk":"9.98","bestBid":"9.975","high24h":"10.4280","low24h":"9.9030","priceChangePercent":"-0.0385","capitalRate":"-0.000100","nextSettleTime":1649314800000,"systemTime":1649290097572,"markPrice":"9.9865","indexPrice":"9.9951","holding":"369411","baseVolume":"313098","quoteVolume":"3294594"}]}
1649290097.615078: {"action":"snapshot","arg":{"instType":"mc","channel":"ticker","instId":"DASHUSDT"},"data":[{"instId":"DASHUSDT","last":"113.550","bestAsk":"113.46","bestBid":"113.41","high24h":"118.870","low24h":"113.140","priceChangePercent":"-0.035","capitalRate":"-0.000100","nextSettleTime":1649314800000,"systemTime":1649290097577,"markPrice":"113.467","indexPrice":"113.503","holding":"21957.17","baseVolume":"25305.79","quoteVolume":"3062825.39"}]}
1649290097.615177: {"action":"update","arg":{"instType":"mc","channel":"books","instId":"UNIUSDT"},"data":[{"asks":[["9.980","14"],["9.981","445"],["9.982","513"],["9.983","241"],["9.984","132"],["9.985","326"],["9.986","71"],["9.987","1238"],["9.988","237"],["9.989","414"],["9.990","141"],["9.991","274"],["9.992","1695"],["9.993","670"],["9.994","2188"],["9.995","189"],["9.996","1126"],["9.997","1028"],["9.998","433"],["9.999","855"],["10.000","1416"],["10.001","1212"],["10.002","1635"],["10.003","1138"],["10.005","894"],["10.006","866"],["10.007","328"],["10.008","523"],["10.009","395"],["10.010","482"],["10.011","5038"],["10.012","656"],["10.014","4770"],["10.015","160"],["10.017","101"],["10.018","41"],["10.019","931"],["10.021","442"],["10.022","4460"],["10.023","4453"],["10.024","2023"],["10.026","4854"],["10.028","13772"],["10.029","771"],["10.030","0"],["10.032","0"],["10.033","13174"],["10.034","0"],["10.038","12982"],["10.039","0"],["10.043","12020"],["10.044","0"],["10.048","12789"],["10.049","0"],["10.053","11443"],["10.054","0"],["10.058","11828"],["10.059","0"],["10.063","12597"],["10.064","0"],["10.068","13559"],["10.069","0"],["10.073","12405"],["10.074","0"],["10.078","12213"],["10.079","0"],["10.083","11636"],["10.084","0"],["10.105","231"],["10.111","0"],["10.157","255"],["10.163","0"],["10.209","44"],["10.215","0"],["10.261","159"],["10.267","0"],["10.313","242"],["10.319","0"],["10.365","86"],["10.371","0"],["10.417","123"],["10.423","0"],["10.469","170"],["10.475","0"],["10.521","223"],["10.527","0"],["10.573","323"],["10.579","0"],["10.625","333"],["10.631","0"],["10.677","52"],["10.683","0"],["10.729","163"],["10.735","0"],["10.781","17"],["10.787","0"],["10.833","144"],["10.839","0"],["10.885","162"],["10.891","0"],["10.937","368"],["10.943","0"],["10.989","356"],["10.995","0"],["11.041","84"],["11.047","0"],["11.093","325"],["11.099","0"],["11.145","114"],["11.151","0"],["11.197","236"],["11.203","0"],["11.249","167"],["11.255","0"],["11.301","98"],["11.307","0"],["11.353","134"],["11.359","0"],["11.405","247"],["11.411","0"],["11.457","171"],["11.463","0"]],"bids":[["9.976","0"],["9.974","579"],["9.973","47"],["9.972","271"],["9.971","143"],["9.970","49"],["9.969","176"],["9.968","696"],["9.967","719"],["9.966","237"],["9.965","293"],["9.964","984"],["9.963","375"],["9.962","345"],["9.961","613"],["9.960","303"],["9.958","392"],["9.956","530"],["9.955","281"],["9.954","220"],["9.953","604"],["9.952","344"],["9.951","343"],["9.950","217"],["9.949","339"],["9.948","3546"],["9.946","377"],["9.945","1051"],["9.944","4296"],["9.943","1056"],["9.942","1383"],["9.941","1131"],["9.940","710"],["9.939","186"],["9.938","225"],["9.937","3902"],["9.936","708"],["9.934","3892"],["9.932","628"],["9.930","1170"],["9.929","369"],["9.928","4068"],["9.927","18094"],["9.923","0"],["9.922","12213"],["9.918","0"],["9.917","11636"],["9.913","0"],["9.912","12405"],["9.908","0"],["9.907","11828"],["9.903","0"],["9.902","11443"],["9.898","0"],["9.897","12597"],["9.893","0"],["9.892","12020"],["9.888","0"],["9.887","13174"],["9.883","0"],["9.882","13366"],["9.878","0"],["9.877","13559"],["9.873","0"],["9.872","12789"],["9.733","0"],["9.727","351"],["9.682","0"],["9.676","399"],["9.631","0"],["9.625","274"],["9.579","0"],["9.573","23"],["9.528","0"],["9.522","112"],["9.477","0"],["9.471","47"],["9.426","0"],["9.420","290"],["9.375","0"],["9.369","318"],["9.324","0"],["9.318","326"],["9.273","0"],["9.267","106"],["9.222","0"],["9.216","193"],["9.171","0"],["9.165","376"],["9.120","0"],["9.114","231"],["9.069","0"],["9.063","4"],["9.018","0"],["9.012","149"],["8.967","0"],["8.961","85"],["8.916","0"],["8.910","320"],["8.865","0"],["8.859","61"],["8.814","0"],["8.808","131"],["8.763","0"],["8.757","477"],["8.712","0"],["8.706","367"],["8.661","0"],["8.655","253"],["8.610","0"],["8.604","83"],["8.559","0"],["8.553","48"]],"checksum":-504399932,"ts":"1649290097584"}]}
1649290097.636218: {"action":"update","arg":{"instType":"mc","channel":"books","instId":"DASHUSDT"},"data":[{"asks":[["113.45","2.04"],["113.46","7.20"],["113.47","11.33"],["113.50","6.77"],["113.51","61.52"],["113.52","39.84"],["113.54","92.04"],["113.56","58.61"],["113.57","86.49"],["113.58","10.84"],["113.59","20.56"],["113.60","83.43"],["113.61","68.32"],["113.62","8.83"],["113.63","228.64"],["113.64","103.50"],["113.65","1600.43"],["113.66","20.27"],["113.67","24.64"],["113.68","575.25"],["113.69","20.24"],["113.70","374.46"],["113.72","48.56"],["113.73","90.56"],["113.74","107.25"],["113.75","246.19"],["113.76","229.69"],["113.77","884.40"],["113.78","261.96"],["113.79","114.48"],["113.80","160.36"],["113.81","9.44"],["113.82","18.35"],["113.83","8.76"],["113.85","257.23"],["113.86","108.38"],["113.87","48.24"],["113.88","2124.35"],["113.89","7.27"],["113.90","170.11"],["113.91","3.63"],["113.92","143.41"],["113.93","34.57"],["113.94","2148.87"],["113.95","0"],["113.96","0"],["113.97","0"],["114.00","1996.33"],["114.03","0"],["114.06","1753.69"],["114.09","0"],["114.12","1930.16"],["114.15","0"],["114.18","1731.63"],["114.21","0"],["114.24","1819.86"],["114.27","0"],["114.30","1886.04"],["114.33","0"],["114.36","1797.80"],["114.39","0"],["114.42","1841.92"],["114.45","0"],["114.48","2040.45"],["114.51","0"],["114.54","2018.39"],["114.57","0"],["114.60","1974.27"],["114.63","0"],["114.66","1709.57"],["114.69","0"],["114.72","1775.75"],["114.75","0"],["114.78","1952.22"],["114.81","0"],["115.78","0"],["116.00","31.47"],["116.37","0"],["116.59","50.46"],["116.96","0"],["117.18","49.40"],["117.55","0"],["117.77","27.41"],["118.14","0"],["118.36","50.42"],["118.73","0"],["118.95","50.07"],["119.32","0"],["119.54","36.12"],["119.91","0"],["120.13","8.62"],["120.50","0"],["120.72","54.60"],["121.09","0"],["121.31","1.48"],["121.68","0"],["121.90","43.49"],["122.27","0"],["122.49","7.73"],["122.86","0"],["123.08","58.21"],["123.45","0"],["123.67","52.67"],["124.04","0"],["124.26","53.84"],["124.63","0"],["124.85","4.99"],["125.22","0"],["125.44","44.04"],["125.81","0"],["126.03","25.10"],["126.40","0"],["126.62","39.09"],["126.99","0"],["127.21","44.51"],["127.58","0"],["127.80","19.01"],["128.17","0"],["128.39","29.39"],["128.76","0"],["128.98","3.89"],["129.35","0"],["129.57","23.37"],["129.94","0"],["130.16","24.18"],["130.53","0"],["130.75","9.15"],["131.12","0"],["131.34","27.04"],["131.71","0"],["131.93","7.10"],["132.52","13.38"],["133.11","33.57"],["133.70","76.51"]],"bids":[["113.42","0"],["113.41","0"],["113.40","49.78"],["113.38","10.31"],["113.37","702.91"],["113.36","189.10"],["113.35","1600.48"],["113.34","2.59"],["113.33","42.83"],["113.32","54.47"],["113.31","11.44"],["113.30","46.40"],["113.29","12.07"],["113.28","17.81"],["113.27","142.38"],["113.26","23.30"],["113.23","274.90"],["113.22","17.02"],["113.21","29.87"],["113.20","19.42"],["113.19","32.68"],["113.18","126.20"],["113.16","29.71"],["113.15","126.34"],["113.14","394.12"],["113.12","15.38"],["113.11","28.35"],["113.10","1600.11"],["113.09","50.39"],["113.08","144.53"],["113.07","35.79"],["113.04","34.29"],["113.03","45.60"],["113.02","24.65"],["113.00","57.55"],["112.99","24.55"],["112.98","550.33"],["112.97","2157.63"],["112.96","180.36"],["112.95","346.12"],["112.94","71.30"],["112.93","14.16"],["112.91","1883.79"],["112.87","0"],["112.85","1775.75"],["112.81","0"],["112.79","2018.39"],["112.75","0"],["112.73","1709.57"],["112.69","0"],["112.67","1886.04"],["112.63","0"],["112.61","1819.86"],["112.57","0"],["112.55","1731.63"],["112.51","0"],["112.49","1841.92"],["112.45","0"],["112.43","1908.10"],["112.39","0"],["112.37","1952.22"],["112.33","0"],["112.31","1753.69"],["112.27","0"],["112.25","1797.80"],["112.21","0"],["112.19","2040.45"],["112.15","0"],["112.13","1930.16"],["112.09","0"],["112.07","1974.27"],["111.66","0"],["111.61","44.63"],["111.07","0"],["111.02","97.81"],["110.47","0"],["110.43","40.49"],["109.88","0"],["109.84","85.27"],["109.29","0"],["109.25","84.73"],["108.70","0"],["108.66","59.74"],["108.11","0"],["108.07","61.13"],["107.52","0"],["107.48","33.01"],["106.93","0"],["106.89","56.85"],["106.34","0"],["106.30","24.34"],["105.75","0"],["105.71","1.74"],["105.16","0"],["105.12","57.94"],["104.57","0"],["104.53","58.21"],["103.98","0"],["103.94","46.12"],["103.39","0"],["103.35","52.32"],["102.80","0"],["102.76","45.29"],["102.21","0"],["102.17","22.94"],["101.62","0"],["101.58","36.02"],["101.03","0"],["100.99","38.02"],["100.44","0"],["100.40","53.60"],["99.85","0"],["99.26","0"],["98.67","0"],["98.08","0"],["97.49","0"],["96.90","0"],["96.31","0"],["95.72","0"],["95.13","0"],["94.54","0"],["93.95","0"],["93.36","0"],["92.77","0"],["92.18","0"]],"checksum":-408525898,"ts":"1649290097607"}]}
1649290097.765867: {"action":"update","arg":{"instType":"mc","channel":"trade","instId":"DASHUSDT"},"data":[["1649290097687","113.4","0.91","sell"]]}
1649290097.860576: {"action":"snapshot","arg":{"instType":"mc","channel":"ticker","instId":"UNIUSDT"},"data":[{"instId":"UNIUSDT","last":"9.9800","bestAsk":"9.979","bestBid":"9.974","high24h":"10.4280","low24h":"9.9030","priceChangePercent":"-0.0390","capitalRate":"-0.000100","nextSettleTime":1649314800000,"systemTime":1649290097828,"markPrice":"9.9865","indexPrice":"9.9902","holding":"369411","baseVolume":"313101","quoteVolume":"3294624"}]}
1649290097.876819: {"action":"snapshot","arg":{"instType":"mc","channel":"ticker","instId":"DASHUSDT"},"data":[{"instId":"DASHUSDT","last":"113.400","bestAsk":"113.44","bestBid":"113.39","high24h":"118.870","low24h":"113.140","priceChangePercent":"-0.035","capitalRate":"-0.000100","nextSettleTime":1649314800000,"systemTime":1649290097840,"markPrice":"113.467","indexPrice":"113.490","holding":"21957.17","baseVolume":"25305.79","quoteVolume":"3062825.39"}]}
1649290097.911585: {"action":"update","arg":{"instType":"mc","channel":"books","instId":"UNIUSDT"},"data":[{"asks":[["9.978","46"],["9.979","126"],["9.980","126"],["9.981","488"],["9.982","479"],["9.983","364"],["9.984","390"],["9.985","592"],["9.986","161"],["9.987","884"],["9.988","248"],["9.989","399"],["9.990","607"],["9.991","293"],["9.992","1719"],["9.993","335"],["9.994","2152"],["9.995","266"],["9.996","616"],["9.997","743"],["9.998","449"],["9.999","737"],["10.000","1257"],["10.001","1811"],["10.002","839"],["10.004","481"],["10.006","859"],["10.008","567"],["10.009","389"],["10.010","546"],["10.011","1363"],["10.012","635"],["10.016","365"],["10.017","3574"],["10.019","923"],["10.020","4273"],["10.022","4050"],["10.025","1399"],["10.026","17258"],["10.027","57"],["10.028","0"],["10.029","0"],["10.031","11828"],["10.033","0"],["10.036","12213"],["10.038","0"],["10.041","12597"],["10.043","0"],["10.046","13366"],["10.048","0"],["10.051","11636"],["10.053","0"],["10.056","13559"],["10.058","0"],["10.061","13174"],["10.063","0"],["10.066","11443"],["10.068","0"],["10.071","12982"],["10.073","0"],["10.076","12020"],["10.078","0"],["10.081","12789"],["10.083","0"],["10.099","231"],["10.105","0"],["10.151","255"],["10.157","0"],["10.203","44"],["10.209","0"],["10.255","159"],["10.261","0"],["10.307","242"],["10.313","0"],["10.359","86"],["10.365","0"],["10.411","123"],["10.417","0"],["10.463","170"],["10.469","0"],["10.515","223"],["10.521","0"],["10.567","323"],["10.573","0"],["10.619","333"],["10.625","0"],["10.671","52"],["10.677","0"],["10.723","163"],["10.729","0"],["10.775","17"],["10.781","0"],["10.827","144"],["10.833","0"],["10.879","162"],["10.885","0"],["10.931","368"],["10.937","0"],["10.983","356"],["10.989","0"],["11.035","84"],["11.041","0"],["11.087","325"],["11.093","0"],["11.139","114"],["11.145","0"],["11.191","236"],["11.197","0"],["11.243","167"],["11.249","0"],["11.295","98"],["11.301","0"],["11.347","134"],["11.353","0"],["11.399","247"],["11.405","0"],["11.451","171"],["11.457","0"]],"bids":[["9.975","0"],["9.974","0"],["9.973","49"],["9.971","81"],["9.969","144"],["9.968","385"],["9.967","745"],["9.966","115"],["9.965","38"],["9.964","1181"],["9.963","339"],["9.962","255"],["9.961","514"],["9.960","308"],["9.959","381"],["9.958","417"],["9.957","795"],["9.956","545"],["9.955","342"],["9.954","246"],["9.953","513"],["9.952","381"],["9.951","498"],["9.948","2649"],["9.947","1185"],["9.945","803"],["9.943","1032"],["9.942","1210"],["9.941","1031"],["9.939","266"],["9.938","624"],["9.937","3779"],["9.936","510"],["9.935","8"],["9.933","237"],["9.927","4714"],["9.925","17238"],["9.924","1186"],["9.922","0"],["9.920","11443"],["9.917","0"],["9.915","13366"],["9.912","0"],["9.910","12020"],["9.907","0"],["9.905","13174"],["9.902","0"],["9.900","11636"],["9.897","0"],["9.895","11828"],["9.892","0"],["9.890","12597"],["9.887","0"],["9.885","12789"],["9.882","0"],["9.880","13559"],["9.877","0"],["9.875","12982"],["9.872","0"],["9.870","12213"],["9.820","376"],["9.769","371"],["9.727","0"],["9.719","19"],["9.676","0"],["9.669","296"],["9.625","0"],["9.619","321"],["9.573","0"],["9.569","66"],["9.522","0"],["9.519","192"],["9.471","0"],["9.469","82"],["9.420","0"],["9.419","16"],["9.369","382"],["9.319","2"],["9.318","0"],["9.269","300"],["9.267","0"],["9.219","268"],["9.216","0"],["9.169","348"],["9.165","0"],["9.119","307"],["9.114","0"],["9.069","104"],["9.063","0"],["9.019","266"],["9.012","0"],["8.969","90"],["8.961","0"],["8.919","213"],["8.910","0"],["8.869","105"],["8.859","0"],["8.819","295"],["8.808","0"],["8.769","108"],["8.757","0"],["8.719","52"],["8.706","0"],["8.669","119"],["8.655","0"],["8.619","179"],["8.604","0"],["8.569","149"],["8.553","17"]],"checksum":-1005247124,"ts":"1649290097884"}]}
1649290097.954179: {"action":"update","arg":{"instType":"mc","channel":"books","instId":"DASHUSDT"},"data":[{"asks":[["113.43","6.75"],["113.44","3.95"],["113.45","2.46"],["113.46","18.86"],["113.47","13.76"],["113.48","1.49"],["113.49","3.06"],["113.50","2.28"],["113.52","31.20"],["113.53","1.25"],["113.56","50.61"],["113.57","69.53"],["113.58","62.61"],["113.59","17.84"],["113.60","148.87"],["113.61","31.49"],["113.62","54.53"],["113.63","226.08"],["113.64","116.59"],["113.66","10.04"],["113.67","46.81"],["113.69","25.91"],["113.70","20.85"],["113.71","128.17"],["113.72","53.52"],["113.73","95.02"],["113.74","41.03"],["113.75","399.80"],["113.77","910.55"],["113.80","158.88"],["113.81","7.82"],["113.84","58.18"],["113.85","249.72"],["113.86","1838.12"],["113.87","46.08"],["113.88","290.08"],["113.90","165.16"],["113.92","1925.47"],["113.93","0"],["113.94","0"],["113.98","1819.86"],["114.00","0"],["114.04","1930.16"],["114.06","0"],["114.10","1974.27"],["114.12","0"],["114.16","1709.57"],["114.18","0"],["114.22","2040.45"],["114.24","0"],["114.28","1863.98"],["114.30","0"],["114.34","1797.80"],["114.36","0"],["114.40","1775.75"],["114.42","0"],["114.46","1841.92"],["114.48","0"],["114.52","1908.10"],["114.54","0"],["114.58","1952.22"],["114.60","0"],["114.64","1886.04"],["114.66","0"],["114.70","2018.39"],["114.72","0"],["114.76","1996.33"],["114.78","0"],["115.78","0.73"],["116.00","0"],["116.37","68.26"],["116.59","0"],["116.96","70.90"],["117.18","0"],["117.55","49.89"],["117.77","0"],["118.14","22.59"],["118.36","0"],["118.73","47.85"],["118.95","0"],["119.32","46.71"],["119.54","0"],["119.91","23.57"],["120.13","0"],["120.50","59.15"],["120.72","0"],["121.09","6.51"],["121.31","0"],["121.68","54.25"],["121.90","0"],["122.27","14.99"],["122.49","0"],["122.86","11.21"],["123.08","0"],["123.45","66.50"],["123.67","0"],["124.04","64.47"],["124.26","0"],["124.63","42.85"],["124.85","0"],["125.22","29.99"],["125.44","0"],["125.81","4.07"],["126.03","0"],["126.40","26.70"],["126.62","0"],["126.99","20.67"],["127.21","0"],["127.58","56.99"],["127.80","0"],["128.17","44.01"],["128.39","0"],["128.76","46.60"],["128.98","0"],["129.35","39.07"],["129.57","0"],["129.94","19.33"],["130.16","0"],["130.53","20.66"],["130.75","0"],["131.12","28.11"],["131.34","0"],["131.71","13.65"],["131.93","0"],["132.52","0"],["133.11","0"],["133.70","0"]],"bids":[["113.40","0"],["113.39","0"],["113.38","10.89"],["113.37","237.61"],["113.35","660.34"],["113.34","0"],["113.33","1600.44"],["113.32","55.11"],["113.30","58.20"],["113.29","14.77"],["113.25","65.21"],["113.24","29.28"],["113.23","193.89"],["113.22","11.38"],["113.21","11.96"],["113.20","61.88"],["113.18","132.51"],["113.17","93.87"],["113.16","18.38"],["113.15","185.23"],["113.14","585.03"],["113.13","66.68"],["113.12","11.11"],["113.11","2.15"],["113.10","21.12"],["113.09","54.78"],["113.08","145.69"],["113.07","37.13"],["113.06","34.73"],["113.05","1490.08"],["113.04","200.63"],["113.03","55.27"],["113.02","1509.65"],["113.01","28.50"],["112.98","536.55"],["112.97","161.64"],["112.95","2188.03"],["112.94","124.75"],["112.93","17.36"],["112.92","27.97"],["112.91","0"],["112.90","90.82"],["112.89","1966.19"],["112.88","37.93"],["112.87","426.26"],["112.85","0"],["112.83","2018.39"],["112.79","0"],["112.77","1731.63"],["112.73","0"],["112.71","2040.45"],["112.67","0"],["112.65","1775.75"],["112.61","0"],["112.59","1863.98"],["112.55","0"],["112.53","1709.57"],["112.49","0"],["112.47","1819.86"],["112.43","0"],["112.41","1797.80"],["112.37","0"],["112.35","1753.69"],["112.31","0"],["112.29","1974.27"],["112.25","0"],["112.23","1908.10"],["112.19","0"],["112.17","1996.33"],["112.13","0"],["112.11","1930.16"],["112.07","0"],["112.05","1886.04"],["111.66","54.98"],["111.61","0"],["111.07","56.15"],["111.02","0"],["110.47","22.20"],["110.43","0"],["109.88","45.95"],["109.84","0"],["109.29","29.62"],["109.25","0"],["108.70","21.93"],["108.66","0"],["108.11","6.02"],["108.07","0"],["107.52","55.97"],["107.48","0"],["106.93","21.31"],["106.89","0"],["106.34","8.95"],["106.30","0"],["105.75","10.15"],["105.71","0"],["105.16","40.07"],["105.12","0"],["104.57","15.36"],["104.53","0"],["103.98","46.47"],["103.94","0"],["103.39","11.11"],["103.35","0"],["102.80","1.87"],["102.76","0"],["102.21","37.67"],["102.17","0"],["101.62","21.48"],["101.58","0"],["101.03","49.80"],["100.99","0"],["100.44","49.32"],["100.40","0"],["99.85","42.14"],["99.26","8.55"],["98.67","30.36"],["98.08","20.32"],["97.49","36.65"],["96.90","21.95"],["96.31","8.41"],["95.72","31.49"],["95.13","57.35"],["94.54","3.45"],["93.95","4.85"],["93.36","74.35"],["92.77","33.85"],["92.18","20.24"]],"checksum":383566183,"ts":"1649290097925"}]}
1649290098.109356: {"action":"snapshot","arg":{"instType":"mc","channel":"ticker","instId":"UNIUSDT"},"data":[{"instId":"UNIUSDT","last":"9.9800","bestAsk":"9.978","bestBid":"9.973","high24h":"10.4280","low24h":"9.9030","priceChangePercent":"-0.0390","capitalRate":"-0.000100","nextSettleTime":1649314800000,"systemTime":1649290098082,"markPrice":"9.9865","indexPrice":"9.9852","holding":"369411","baseVolume":"313101","quoteVolume":"3294624"}]}
1649290098.126378: {"action":"snapshot","arg":{"instType":"mc","channel":"ticker","instId":"DASHUSDT"},"data":[{"instId":"DASHUSDT","last":"113.400","bestAsk":"113.42","bestBid":"113.37","high24h":"118.870","low24h":"113.140","priceChangePercent":"-0.035","capitalRate":"-0.000100","nextSettleTime":1649314800000,"systemTime":1649290098094,"markPrice":"113.473","indexPrice":"113.490","holding":"21957.17","baseVolume":"25305.79","quoteVolume":"3062825.39"}]}
1649290098.1545842: {"action":"update","arg":{"instType":"mc","channel":"candle1m","instId":"DASHUSDT"},"data":[["1649290080000","113.37","113.55","113.37","113.4","4.81"]]}
1649290098.2164931: {"action":"update","arg":{"instType":"mc","channel":"books","instId":"UNIUSDT"},"data":[{"asks":[["9.978","98"],["9.980","189"],["9.982","291"],["9.985","663"],["9.986","608"],["9.987","406"],["9.989","406"],["9.990","817"],["9.991","318"],["9.992","433"],["9.993","485"],["9.994","2171"],["9.996","542"],["9.997","806"],["9.998","583"],["9.999","751"],["10.001","1166"],["10.004","564"],["10.005","893"],["10.012","718"],["10.019","841"],["10.021","562"],["10.022","4483"],["10.025","1283"],["10.026","17642"],["10.031","12597"],["10.036","12020"],["10.041","11443"],["10.046","11828"],["10.056","12982"],["10.061","12405"],["10.066","13559"],["10.071","13174"],["10.076","12213"],["10.081","13366"],["10.093","231"],["10.099","0"],["10.145","255"],["10.151","0"],["10.197","44"],["10.203","0"],["10.249","159"],["10.255","0"],["10.301","242"],["10.307","0"],["10.353","86"],["10.359","0"],["10.405","123"],["10.411","0"],["10.457","170"],["10.463","0"],["10.509","223"],["10.515","0"],["10.561","323"],["10.567","0"],["10.613","333"],["10.619","0"],["10.665","52"],["10.671","0"],["10.717","163"],["10.723","0"],["10.769","17"],["10.775","0"],["10.821","144"],["10.827","0"],["10.873","162"],["10.879","0"],["10.925","368"],["10.931","0"],["10.977","356"],["10.983","0"],["11.029","84"],["11.035","0"],["11.081","325"],["11.087","0"],["11.133","114"],["11.139","0"],["11.185","236"],["11.191","0"],["11.237","167"],["11.243","0"],["11.289","98"],["11.295","0"],["11.341","134"],["11.347","0"],["11.393","247"],["11.399","0"],["11.445","171"],["11.451","0"]],"bids":[["9.972","292"],["9.971","84"],["9.969","263"],["9.968","390"],["9.967","1014"],["9.965","51"],["9.964","487"],["9.963","328"],["9.961","595"],["9.958","406"],["9.957","1634"],["9.956","1203"],["9.954","307"],["9.952","379"],["9.947","314"],["9.946","1169"],["9.945","819"],["9.944","4194"],["9.943","1048"],["9.937","276"],["9.935","177"],["9.933","334"],["9.925","17627"],["9.924","894"],["9.920","12982"],["9.915","13174"],["9.910","12405"],["9.905","13559"],["9.900","12020"],["9.895","13366"],["9.890","11828"],["9.885","12213"],["9.880","12597"],["9.875","11636"],["9.870","11443"],["9.820","0"],["9.814","376"],["9.769","0"],["9.763","371"],["9.719","0"],["9.713","19"],["9.669","0"],["9.663","296"],["9.619","0"],["9.613","321"],["9.569","0"],["9.563","66"],["9.519","0"],["9.513","192"],["9.469","0"],["9.463","82"],["9.419","0"],["9.413","16"],["9.369","0"],["9.363","382"],["9.319","0"],["9.313","2"],["9.269","0"],["9.263","300"],["9.219","0"],["9.213","268"],["9.169","0"],["9.163","348"],["9.119","0"],["9.113","307"],["9.069","0"],["9.063","104"],["9.019","0"],["9.013","266"],["8.969","0"],["8.963","90"],["8.919","0"],["8.913","213"],["8.869","0"],["8.863","105"],["8.819","0"],["8.813","295"],["8.769","0"],["8.763","108"],["8.719","0"],["8.713","52"],["8.669","0"],["8.663","119"],["8.619","0"],["8.613","179"],["8.569","0"],["8.563","149"]],"checksum":-2089106378,"ts":"1649290098187"}]}
1649290098.26256: {"action":"update","arg":{"instType":"mc","channel":"books","instId":"DASHUSDT"},"data":[{"asks":[["113.42","11.62"],["113.43","0.59"],["113.44","5.44"],["113.45","6.77"],["113.46","13.42"],["113.47","19.70"],["113.49","1.85"],["113.51","64.23"],["113.52","18.51"],["113.53","13.28"],["113.54","142.55"],["113.55","38.53"],["113.56","72.70"],["113.57","89.08"],["113.58","21.11"],["113.60","114.58"],["113.61","1365.68"],["113.62","43.47"],["113.64","79.05"],["113.65","119.86"],["113.66","7.79"],["113.67","19.34"],["113.68","581.09"],["113.69","30.36"],["113.70","39.33"],["113.71","123.81"],["113.72","119.09"],["113.73","244.01"],["113.74","25.62"],["113.75","241.89"],["113.76","227.08"],["113.77","804.19"],["113.79","124.38"],["113.81","8.91"],["113.83","78.64"],["113.85","2113.69"],["113.86","110.95"],["113.87","44.43"],["113.90","162.19"],["113.91","2162.20"],["113.92","0"],["113.97","1908.10"],["113.98","0"],["114.03","1797.80"],["114.04","0"],["114.09","2040.45"],["114.10","0"],["114.15","1731.63"],["114.16","0"],["114.21","1709.57"],["114.22","0"],["114.27","1753.69"],["114.28","0"],["114.33","1841.92"],["114.34","0"],["114.39","1930.16"],["114.40","0"],["114.45","1775.75"],["114.46","0"],["114.51","1996.33"],["114.52","0"],["114.57","2018.39"],["114.58","0"],["114.63","1886.04"],["114.64","0"],["114.69","1952.22"],["114.70","0"],["114.75","1819.86"],["114.76","0"],["115.78","0"],["116.00","31.47"],["116.37","0"],["116.59","50.46"],["116.96","0"],["117.18","49.40"],["117.55","0"],["117.77","27.41"],["118.14","0"],["118.36","50.42"],["118.73","0"],["118.95","50.07"],["119.32","0"],["119.54","36.12"],["119.91","0"],["120.13","8.62"],["120.50","0"],["120.72","54.60"],["121.09","0"],["121.31","1.48"],["121.68","0"],["121.90","43.49"],["122.27","0"],["122.49","7.73"],["122.86","0"],["123.08","58.21"],["123.45","0"],["123.67","52.67"],["124.04","0"],["124.26","53.84"],["124.63","0"],["124.85","4.99"],["125.22","0"],["125.44","44.04"],["125.81","0"],["126.03","25.10"],["126.40","0"],["126.62","39.09"],["126.99","0"],["127.21","44.51"],["127.58","0"],["127.80","19.01"],["128.17","0"],["128.39","29.39"],["128.76","0"],["128.98","3.89"],["129.35","0"],["129.57","23.37"],["129.94","0"],["130.16","24.18"],["130.53","0"],["130.75","9.15"],["131.12","0"],["131.34","27.04"],["131.71","0"],["131.93","7.10"],["132.52","13.38"],["133.11","33.57"],["133.70","76.51"]],"bids":[["113.38","0"],["113.36","18.82"],["113.35","247.51"],["113.33","8.42"],["113.32","24.92"],["113.30","59.54"],["113.29","1600.42"],["113.28","14.92"],["113.27","175.05"],["113.26","21.81"],["113.24","30.76"],["113.23","16.43"],["113.20","16.20"],["113.19","158.31"],["113.18","49.32"],["113.17","19.62"],["113.15","475.95"],["113.13","62.72"],["113.12","63.91"],["113.11","10.64"],["113.08","75.01"],["113.07","92.82"],["113.05","1475.23"],["113.03","62.58"],["113.02","1510.03"],["113.00","71.46"],["112.98","504.03"],["112.95","346.12"],["112.94","2099.01"],["112.93","13.55"],["112.92","30.82"],["112.89","13.98"],["112.88","1790.11"],["112.86","4.03"],["112.83","0"],["112.82","1908.10"],["112.77","0"],["112.76","1886.04"],["112.71","0"],["112.70","1952.22"],["112.65","0"],["112.64","1775.75"],["112.59","0"],["112.58","1709.57"],["112.53","0"],["112.52","1930.16"],["112.47","0"],["112.46","1841.92"],["112.41","0"],["112.40","2040.45"],["112.35","0"],["112.34","1863.98"],["112.29","0"],["112.28","1819.86"],["112.23","0"],["112.22","1797.80"],["112.17","0"],["112.16","1731.63"],["112.11","0"],["112.10","1996.33"],["112.05","0"],["112.04","2018.39"],["111.66","0"],["111.61","44.63"],["111.07","0"],["111.02","97.81"],["110.47","0"],["110.43","40.49"],["109.88","0"],["109.84","85.27"],["109.29","0"],["109.25","84.73"],["108.70","0"],["108.66","59.74"],["108.11","0"],["108.07","61.13"],["107.52","0"],["107.48","33.01"],["106.93","0"],["106.89","56.85"],["106.34","0"],["106.30","24.34"],["105.75","0"],["105.71","1.74"],["105.16","0"],["105.12","57.94"],["104.57","0"],["104.53","58.21"],["103.98","0"],["103.94","46.12"],["103.39","0"],["103.35","52.32"],["102.80","0"],["102.76","45.29"],["102.21","0"],["102.17","22.94"],["101.62","0"],["101.58","36.02"],["101.03","0"],["100.99","38.02"],["100.44","0"],["100.40","53.60"],["99.85","0"],["99.26","0"],["98.67","0"],["98.08","0"],["97.49","0"],["96.90","0"],["96.31","0"],["95.72","0"],["95.13","0"],["94.54","0"],["93.95","0"],["93.36","0"],["92.77","0"],["92.18","0"]],"checksum":-118273131,"ts":"1649290098232"}]}
1649290098.372101: {"action":"snapshot","arg":{"instType":"mc","channel":"ticker","instId":"UNIUSDT"},"data":[{"instId":"UNIUSDT","last":"9.9800","bestAsk":"9.978","bestBid":"9.973","high24h":"10.4280","low24h":"9.9030","priceChangePercent":"-0.0390","capitalRate":"-0.000100","nextSettleTime":1649314800000,"systemTime":1649290098343,"markPrice":"9.9841","indexPrice":"9.9902","holding":"369411","baseVolume":"313101","quoteVolume":"3294624"}]}
1649290098.379415: {"action":"snapshot","arg":{"instType":"mc","channel":"ticker","instId":"DASHUSDT"},"data":[{"instId":"DASHUSDT","last":"113.400","bestAsk":"113.42","bestBid":"113.37","high24h":"118.870","low24h":"113.140","priceChangePercent":"-0.036","capitalRate":"-0.000100","nextSettleTime":1649314800000,"systemTime":1649290098352,"markPrice":"113.473","indexPrice":"113.490","holding":"21957.17","baseVolume":"25306.70","quoteVolume":"3062928.58"}]}
1649290098.5701802: {"action":"update","arg":{"instType":"mc","channel":"books","instId":"UNIUSDT"},"data":[{"asks":[["9.978","284"],["9.979","149"],["9.980","208"],["9.981","344"],["9.982","102"],["9.983","588"],["9.984","318"],["9.985","527"],["9.986","645"],["9.987","478"],["9.988","417"],["9.989","457"],["9.990","932"],["9.991","280"],["9.992","427"],["9.993","624"],["9.994","2096"],["9.995","494"],["9.997","777"],["9.998","437"],["9.999","535"],["10.002","876"],["10.003","815"],["10.005","936"],["10.006","842"],["10.007","556"],["10.009","343"],["10.011","1350"],["10.012","672"],["10.016","380"],["10.017","3768"],["10.021","785"],["10.022","4445"],["10.024","2001"],["10.025","1676"],["10.026","18087"],["10.027","30"],["10.031","12213"],["10.041","11636"],["10.046","13174"],["10.051","12597"],["10.061","13366"],["10.066","11443"],["10.071","11828"],["10.076","12405"],["10.081","13559"],["10.086","231"],["10.093","0"],["10.138","255"],["10.145","0"],["10.190","44"],["10.197","0"],["10.242","159"],["10.249","0"],["10.294","242"],["10.301","0"],["10.346","86"],["10.353","0"],["10.398","123"],["10.405","0"],["10.450","170"],["10.457","0"],["10.502","223"],["10.509","0"],["10.554","323"],["10.561","0"],["10.606","333"],["10.613","0"],["10.658","52"],["10.665","0"],["10.710","163"],["10.717","0"],["10.762","17"],["10.769","0"],["10.814","144"],["10.821","0"],["10.866","162"],["10.873","0"],["10.918","368"],["10.925","0"],["10.970","356"],["10.977","0"],["11.022","84"],["11.029","0"],["11.074","325"],["11.081","0"],["11.126","114"],["11.133","0"],["11.178","236"],["11.185","0"],["11.230","167"],["11.237","0"],["11.282","98"],["11.289","0"],["11.334","134"],["11.341","0"],["11.386","247"],["11.393","0"],["11.438","171"],["11.445","0"]],"bids":[["9.973","185"],["9.972","319"],["9.971","115"],["9.970","227"],["9.969","324"],["9.968","315"],["9.967","722"],["9.966","173"],["9.964","560"],["9.963","339"],["9.962","745"],["9.961","611"],["9.960","234"],["9.959","374"],["9.958","333"],["9.957","3513"],["9.956","1031"],["9.955","391"],["9.954","284"],["9.952","511"],["9.951","372"],["9.950","441"],["9.949","355"],["9.948","2048"],["9.947","456"],["9.946","382"],["9.944","4582"],["9.943","1035"],["9.942","1237"],["9.940","733"],["9.934","3864"],["9.932","662"],["9.925","21485"],["9.920","12020"],["9.915","12405"],["9.910","11636"],["9.905","12597"],["9.900","13366"],["9.895","13559"],["9.880","11443"],["9.875","12789"],["9.870","12982"],["9.814","0"],["9.807","376"],["9.763","0"],["9.756","371"],["9.713","0"],["9.706","19"],["9.663","0"],["9.656","296"],["9.613","0"],["9.606","321"],["9.563","0"],["9.556","66"],["9.513","0"],["9.506","192"],["9.463","0"],["9.456","82"],["9.413","0"],["9.406","16"],["9.363","0"],["9.356","382"],["9.313","0"],["9.306","2"],["9.263","0"],["9.256","300"],["9.213","0"],["9.206","268"],["9.163","0"],["9.156","348"],["9.113","0"],["9.106","307"],["9.063","0"],["9.056","104"],["9.013","0"],["9.006","266"],["8.963","0"],["8.956","90"],["8.913","0"],["8.906","213"],["8.863","0"],["8.856","105"],["8.813","0"],["8.806","295"],["8.763","0"],["8.756","108"],["8.713","0"],["8.706","52"],["8.663","0"],["8.656","119"],["8.613","0"],["8.606","179"],["8.563","0"],["8.556","149"]],"checksum":-98878387,"ts":"1649290098536"}]}
1649290098.573266: {"action":"update","arg":{"instType":"mc","channel":"books","instId":"DASHUSDT"},"data":[{"asks":[["113.42","6.19"],["113.49","0.41"],["113.51","88.33"],["113.52","38.48"],["113.53","32.12"],["113.54","137.60"],["113.55","57.10"],["113.56","75.75"],["113.57","33.51"],["113.59","17.61"],["113.60","100.77"],["113.62","41.71"],["113.64","79.71"],["113.66","8.83"],["113.68","585.54"],["113.69","25.91"],["113.70","29.10"],["113.71","34.71"],["113.72","136.69"],["113.73","206.39"],["113.74","23.70"],["113.77","766.51"],["113.78","249.09"],["113.79","117.12"],["113.81","10.17"],["113.84","58.63"],["113.85","2294.62"],["113.86","106.50"],["113.90","1600.34"],["113.91","2073.97"],["113.97","2018.39"],["114.03","1952.22"],["114.09","1753.69"],["114.15","1841.92"],["114.21","1775.75"],["114.27","1797.80"],["114.33","1709.57"],["114.39","1819.86"],["114.45","1863.98"],["114.51","1974.27"],["114.57","1908.10"],["114.63","1731.63"],["114.69","1930.16"],["114.75","1996.33"],["115.78","0.73"],["116.00","0"],["116.37","68.26"],["116.59","0"],["116.96","70.90"],["117.18","0"],["117.55","49.89"],["117.77","0"],["118.14","22.59"],["118.36","0"],["118.73","47.85"],["118.95","0"],["119.32","46.71"],["119.54","0"],["119.91","23.57"],["120.13","0"],["120.50","59.15"],["120.72","0"],["121.09","6.51"],["121.31","0"],["121.68","54.25"],["121.90","0"],["122.27","14.99"],["122.49","0"],["122.86","11.21"],["123.08","0"],["123.45","66.50"],["123.67","0"],["124.04","64.47"],["124.26","0"],["124.63","42.85"],["124.85","0"],["125.22","29.99"],["125.44","0"],["125.81","4.07"],["126.03","0"],["126.40","26.70"],["126.62","0"],["126.99","20.67"],["127.21","0"],["127.58","56.99"],["127.80","0"],["128.17","44.01"],["128.39","0"],["128.76","46.60"],["128.98","0"],["129.35","39.07"],["129.57","0"],["129.94","19.33"],["130.16","0"],["130.53","20.66"],["130.75","0"],["131.12","28.11"],["131.34","0"],["131.71","13.65"],["131.93","0"],["132.52","0"],["133.11","0"],["133.70","0"]],"bids":[["113.36","36.64"],["113.33","11.89"],["113.32","28.38"],["113.31","54.99"],["113.30","58.83"],["113.29","1600.44"],["113.28","33.66"],["113.27","142.38"],["113.26","90.53"],["113.21","54.84"],["113.20","60.39"],["113.18","30.87"],["113.17","57.24"],["113.16","28.85"],["113.14","615.72"],["113.12","3.52"],["113.10","20.38"],["113.08","81.14"],["113.07","92.55"],["113.00","48.85"],["112.98","628.12"],["112.94","1856.37"],["112.93","43.27"],["112.88","1900.40"],["112.82","2018.39"],["112.76","1908.10"],["112.70","1753.69"],["112.58","1841.92"],["112.52","2040.45"],["112.46","1709.57"],["112.40","1952.22"],["112.34","1974.27"],["112.28","1996.33"],["112.22","1930.16"],["112.16","1819.86"],["112.10","1797.80"],["112.04","1886.04"],["111.66","54.98"],["111.61","0"],["111.07","56.15"],["111.02","0"],["110.47","22.20"],["110.43","0"],["109.88","45.95"],["109.84","0"],["109.29","29.62"],["109.25","0"],["108.70","21.93"],["108.66","0"],["108.11","6.02"],["108.07","0"],["107.52","55.97"],["107.48","0"],["106.93","21.31"],["106.89","0"],["106.34","8.95"],["106.30","0"],["105.75","10.15"],["105.71","0"],["105.16","40.07"],["105.12","0"],["104.57","15.36"],["104.53","0"],["103.98","46.47"],["103.94","0"],["103.39","11.11"],["103.35","0"],["102.80","1.87"],["102.76","0"],["102.21","37.67"],["102.17","0"],["101.62","21.48"],["101.58","0"],["101.03","49.80"],["100.99","0"],["100.44","49.32"],["100.40","0"],["99.85","42.14"],["99.26","8.55"],["98.67","30.36"],["98.08","20.32"],["97.49","36.65"],["96.90","21.95"],["96.31","8.41"],["95.72","31.49"],["95.13","57.35"],["94.54","3.45"],["93.95","4.85"],["93.36","74.35"],["92.77","33.85"],["92.18","20.24"]],"checksum":-1374782553,"ts":"1649290098545"}]}
1649290098.6202948: {"action":"snapshot","arg":{"instType":"mc","channel":"ticker","instId":"UNIUSDT"},"data":[{"instId":"UNIUSDT","last":"9.9800","bestAsk":"9.978","bestBid":"9.973","high24h":"10.4280","low24h":"9.9030","priceChangePercent":"-0.0390","capitalRate":"-0.000100","nextSettleTime":1649314800000,"systemTime":1649290098593,"markPrice":"9.9841","indexPrice":"9.9852","holding":"369411","baseVolume":"313101","quoteVolume":"3294624"}]}
1649290098.627688: {"action":"snapshot","arg":{"instType":"mc","channel":"ticker","instId":"DASHUSDT"},"data":[{"instId":"DASHUSDT","last":"113.400","bestAsk":"113.42","bestBid":"113.37","high24h":"118.870","low24h":"113.140","priceChangePercent":"-0.036","capitalRate":"-0.000100","nextSettleTime":1649314800000,"systemTime":1649290098599,"markPrice":"113.473","indexPrice":"113.490","holding":"21957.17","baseVolume":"25306.70","quoteVolume":"3062928.58"}]}
1649290098.856448: {"action":"update","arg":{"instType":"mc","channel":"trade","instId":"UNIUSDT"},"data":[["1649290098722","9.974","5","buy"]]}
1649290098.864201: {"action":"update","arg":{"instType":"mc","channel":"books","instId":"UNIUSDT"},"data":[{"asks":[["9.985","1029"],["9.986","146"],["9.987","580"],["9.989","586"],["9.999","1327"],["10.000","1298"],["10.002","664"],["10.026","18857"],["10.031","11828"],["10.036","13366"],["10.041","12789"],["10.046","11636"],["10.051","12982"],["10.056","12405"],["10.061","11443"],["10.066","12213"],["10.071","12020"],["10.076","12597"],["10.081","13174"],["10.086","0"],["10.132","325"],["10.138","0"],["10.183","114"],["10.190","0"],["10.234","62"],["10.242","0"],["10.285","96"],["10.294","0"],["10.336","302"],["10.346","0"],["10.387","402"],["10.398","0"],["10.438","79"],["10.450","0"],["10.489","6"],["10.502","0"],["10.540","327"],["10.554","0"],["10.591","102"],["10.606","0"],["10.642","300"],["10.658","0"],["10.693","115"],["10.710","0"],["10.744","146"],["10.762","0"],["10.795","298"],["10.814","0"],["10.846","401"],["10.866","0"],["10.897","133"],["10.918","0"],["10.948","97"],["10.970","0"],["10.999","343"],["11.022","0"],["11.050","381"],["11.074","0"],["11.101","240"],["11.126","0"],["11.152","75"],["11.178","0"],["11.203","310"],["11.230","0"],["11.254","224"],["11.282","0"],["11.305","146"],["11.334","0"],["11.386","0"],["11.438","0"]],"bids":[["9.967","675"],["9.963","311"],["9.962","716"],["9.961","635"],["9.958","390"],["9.954","309"],["9.953","882"],["9.950","565"],["9.947","522"],["9.946","534"],["9.942","1282"],["9.925","19754"],["9.920","13559"],["9.910","12789"],["9.905","11828"],["9.900","12020"],["9.895","13174"],["9.890","11636"],["9.885","12982"],["9.880","12597"],["9.875","13366"],["9.870","12213"],["9.807","0"],["9.801","376"],["9.756","0"],["9.750","371"],["9.706","0"],["9.700","19"],["9.656","0"],["9.650","296"],["9.606","0"],["9.600","321"],["9.556","0"],["9.550","66"],["9.506","0"],["9.500","192"],["9.456","0"],["9.450","82"],["9.406","0"],["9.400","16"],["9.356","0"],["9.350","382"],["9.306","0"],["9.300","2"],["9.256","0"],["9.250","300"],["9.206","0"],["9.200","268"],["9.156","0"],["9.150","348"],["9.106","0"],["9.100","307"],["9.056","0"],["9.050","104"],["9.006","0"],["9.000","266"],["8.956","0"],["8.950","90"],["8.906","0"],["8.900","213"],["8.856","0"],["8.850","105"],["8.806","0"],["8.800","295"],["8.756","0"],["8.750","108"],["8.706","0"],["8.700","52"],["8.656","0"],["8.650","119"],["8.606","0"],["8.600","179"],["8.556","0"],["8.550","149"]],"checksum":-256026648,"ts":"1649290098834"}]}
1649290098.8909051: {"action":"update","arg":{"instType":"mc","channel":"books","instId":"DASHUSDT"},"data":[{"asks":[["113.42","12.13"],["113.43","0"],["113.46","17.74"],["113.51","64.23"],["113.52","49.31"],["113.53","4.56"],["113.54","92.04"],["113.55","3.31"],["113.56","60.73"],["113.57","56.63"],["113.59","32.69"],["113.60","173.41"],["113.61","49.64"],["113.62","38.09"],["113.64","116.59"],["113.65","1600.14"],["113.67","31.13"],["113.68","639.18"],["113.70","20.85"],["113.71","123.81"],["113.72","69.06"],["113.73","90.56"],["113.74","104.39"],["113.75","206.25"],["113.77","893.89"],["113.78","202.38"],["113.79","114.48"],["113.80","160.36"],["113.81","8.52"],["113.83","8.76"],["113.84","256.63"],["113.85","2293.13"],["113.87","46.08"],["113.88","260.38"],["113.90","170.11"],["113.91","1823.48"],["113.92","184.66"],["114.03","1930.16"],["114.09","1709.57"],["114.15","1974.27"],["114.21","1731.63"],["114.27","1841.92"],["114.33","1775.75"],["114.39","1908.10"],["114.51","1952.22"],["114.57","1753.69"],["114.63","1797.80"],["114.69","1996.33"],["114.75","1886.04"],["115.78","0"],["116.00","31.47"],["116.37","0"],["116.59","50.46"],["116.96","0"],["117.18","49.40"],["117.55","0"],["117.77","27.41"],["118.14","0"],["118.36","50.42"],["118.73","0"],["118.95","50.07"],["119.32","0"],["119.54","36.12"],["119.91","0"],["120.13","8.62"],["120.50","0"],["120.72","54.60"],["121.09","0"],["121.31","1.48"],["121.68","0"],["121.90","43.49"],["122.27","0"],["122.49","7.73"],["122.86","0"],["123.08","58.21"],["123.45","0"],["123.67","52.67"],["124.04","0"],["124.26","53.84"],["124.63","0"],["124.85","4.99"],["125.22","0"],["125.44","44.04"],["125.81","0"],["126.03","25.10"],["126.40","0"],["126.62","39.09"],["126.99","0"],["127.21","44.51"],["127.58","0"],["127.80","19.01"],["128.17","0"],["128.39","29.39"],["128.76","0"],["128.98","3.89"],["129.35","0"],["129.57","23.37"],["129.94","0"],["130.16","24.18"],["130.53","0"],["130.75","9.15"],["131.12","0"],["131.34","27.04"],["131.71","0"],["131.93","7.10"],["132.52","13.38"],["133.11","33.57"],["133.70","76.51"]],"bids":[["113.37","702.91"],["113.36","189.10"],["113.35","1600.23"],["113.32","55.11"],["113.31","10.44"],["113.30","47.90"],["113.29","11.99"],["113.28","17.81"],["113.26","22.22"],["113.25","67.99"],["113.24","29.28"],["113.23","283.79"],["113.22","16.59"],["113.21","40.29"],["113.20","17.69"],["113.19","16.74"],["113.18","95.96"],["113.17","91.09"],["113.16","24.54"],["113.15","140.91"],["113.14","577.01"],["113.13","70.09"],["113.12","6.49"],["113.11","8.66"],["113.10","1600.16"],["113.08","147.16"],["113.07","36.59"],["113.05","1488.33"],["113.04","3.23"],["113.03","52.24"],["113.02","25.36"],["113.01","17.23"],["112.99","21.55"],["112.98","535.06"],["112.94","2076.96"],["112.82","1753.69"],["112.76","1930.16"],["112.70","2018.39"],["112.64","1996.33"],["112.58","1886.04"],["112.52","1974.27"],["112.46","1731.63"],["112.40","1841.92"],["112.34","1775.75"],["112.28","1819.86"],["112.22","1709.57"],["112.16","2040.45"],["112.10","1908.10"],["112.04","1797.80"],["111.66","0"],["111.61","44.63"],["111.07","0"],["111.02","97.81"],["110.47","0"],["110.43","40.49"],["109.88","0"],["109.84","85.27"],["109.29","0"],["109.25","84.73"],["108.70","0"],["108.66","59.74"],["108.11","0"],["108.07","61.13"],["107.52","0"],["107.48","33.01"],["106.93","0"],["106.89","56.85"],["106.34","0"],["106.30","24.34"],["105.75","0"],["105.71","1.74"],["105.16","0"],["105.12","57.94"],["104.57","0"],["104.53","58.21"],["103.98","0"],["103.94","46.12"],["103.39","0"],["103.35","52.32"],["102.80","0"],["102.76","45.29"],["102.21","0"],["102.17","22.94"],["101.62","0"],["101.58","36.02"],["101.03","0"],["100.99","38.02"],["100.44","0"],["100.40","53.60"],["99.85","0"],["99.26","0"],["98.67","0"],["98.08","0"],["97.49","0"],["96.90","0"],["96.31","0"],["95.72","0"],["95.13","0"],["94.54","0"],["93.95","0"],["93.36","0"],["92.77","0"],["92.18","0"]],"checksum":-2140958284,"ts":"1649290098859"}]}
1649290098.8963451: {"action":"snapshot","arg":{"instType":"mc","channel":"ticker","instId":"UNIUSDT"},"data":[{"instId":"UNIUSDT","last":"9.9740","bestAsk":"9.978","bestBid":"9.973","high24h":"10.4280","low24h":"9.9030","priceChangePercent":"-0.0390","capitalRate":"-0.000100","nextSettleTime":1649314800000,"systemTime":1649290098859,"markPrice":"9.9841","indexPrice":"9.9826","holding":"369411","baseVolume":"313101","quoteVolume":"3294624"}]}
1649290098.907454: {"action":"snapshot","arg":{"instType":"mc","channel":"ticker","instId":"DASHUSDT"},"data":[{"instId":"DASHUSDT","last":"113.400","bestAsk":"113.42","bestBid":"113.37","high24h":"118.870","low24h":"113.140","priceChangePercent":"-0.036","capitalRate":"-0.000100","nextSettleTime":1649314800000,"systemTime":1649290098872,"markPrice":"113.477","indexPrice":"113.490","holding":"21957.17","baseVolume":"25306.70","quoteVolume":"3062928.58"}]}
1649290099.163098: {"action":"snapshot","arg":{"instType":"mc","channel":"ticker","instId":"UNIUSDT"},"data":[{"instId":"UNIUSDT","last":"9.9740","bestAsk":"9.978","bestBid":"9.973","high24h":"10.4280","low24h":"9.9030","priceChangePercent":"-0.0390","capitalRate":"-0.000100","nextSettleTime":1649314800000,"systemTime":1649290099135,"markPrice":"9.9841","indexPrice":"9.9826","holding":"369411","baseVolume":"313101","quoteVolume":"3294624"}]}
1649290099.169136: {"action":"update","arg":{"instType":"mc","channel":"books","instId":"UNIUSDT"},"data":[{"asks":[["9.977","194"],["9.978","119"],["9.979","256"],["9.980","114"],["9.982","144"],["9.983","546"],["9.984","786"],["9.985","1089"],["9.986","97"],["9.987","645"],["9.988","436"],["9.989","1052"],["9.990","1610"],["9.991","385"],["9.993","585"],["9.994","2115"],["9.995","542"],["9.996","619"],["9.997","736"],["9.998","586"],["9.999","535"],["10.002","596"],["10.003","872"],["10.004","577"],["10.006","1082"],["10.007","594"],["10.008","482"],["10.009","312"],["10.010","512"],["10.012","571"],["10.014","4791"],["10.022","4050"],["10.024","2043"],["10.025","13503"],["10.026","1822"],["10.027","0"],["10.030","11636"],["10.031","0"],["10.035","12020"],["10.036","0"],["10.040","12789"],["10.041","0"],["10.045","12597"],["10.046","0"],["10.050","13174"],["10.051","0"],["10.055","12982"],["10.056","0"],["10.060","12405"],["10.061","0"],["10.065","13559"],["10.066","0"],["10.070","11443"],["10.071","0"],["10.075","12213"],["10.076","0"],["10.080","13366"],["10.081","0"],["10.126","325"],["10.132","0"],["10.177","114"],["10.183","0"],["10.228","62"],["10.234","0"],["10.279","96"],["10.285","0"],["10.330","302"],["10.336","0"],["10.381","402"],["10.387","0"],["10.432","79"],["10.438","0"],["10.483","6"],["10.489","0"],["10.534","327"],["10.540","0"],["10.585","102"],["10.591","0"],["10.636","300"],["10.642","0"],["10.687","115"],["10.693","0"],["10.738","146"],["10.744","0"],["10.789","298"],["10.795","0"],["10.840","401"],["10.846","0"],["10.891","133"],["10.897","0"],["10.942","97"],["10.948","0"],["10.993","343"],["10.999","0"],["11.044","381"],["11.050","0"],["11.095","240"],["11.101","0"],["11.146","75"],["11.152","0"],["11.197","310"],["11.203","0"],["11.248","224"],["11.254","0"],["11.299","146"],["11.305","0"]],"bids":[["9.973","0"],["9.971","227"],["9.970","164"],["9.969","181"],["9.968","273"],["9.967","175"],["9.966","165"],["9.965","30"],["9.964","1507"],["9.963","297"],["9.962","841"],["9.961","453"],["9.960","285"],["9.959","320"],["9.957","3563"],["9.956","1108"],["9.955","333"],["9.952","542"],["9.951","453"],["9.950","441"],["9.949","983"],["9.948","2066"],["9.946","336"],["9.944","8557"],["9.943","972"],["9.942","1414"],["9.941","995"],["9.940","538"],["9.934","3831"],["9.932","635"],["9.931","3644"],["9.927","4128"],["9.926","416"],["9.925","8312"],["9.924","14765"],["9.923","365"],["9.920","0"],["9.919","12597"],["9.915","0"],["9.914","13559"],["9.910","0"],["9.909","13174"],["9.905","0"],["9.904","12020"],["9.900","0"],["9.899","11828"],["9.895","0"],["9.894","12789"],["9.890","0"],["9.889","11636"],["9.885","0"],["9.884","12405"],["9.880","0"],["9.879","13366"],["9.875","0"],["9.874","11443"],["9.870","0"],["9.869","12213"],["9.801","0"],["9.795","376"],["9.750","0"],["9.744","371"],["9.700","0"],["9.694","19"],["9.650","0"],["9.644","296"],["9.600","0"],["9.594","321"],["9.550","0"],["9.544","66"],["9.500","0"],["9.494","192"],["9.450","0"],["9.444","82"],["9.400","0"],["9.394","16"],["9.350","0"],["9.344","382"],["9.300","0"],["9.294","2"],["9.250","0"],["9.244","300"],["9.200","0"],["9.194","268"],["9.150","0"],["9.144","348"],["9.100","0"],["9.094","307"],["9.050","0"],["9.044","104"],["9.000","0"],["8.994","266"],["8.950","0"],["8.944","90"],["8.900","0"],["8.894","213"],["8.850","0"],["8.844","105"],["8.800","0"],["8.794","295"],["8.750","0"],["8.744","108"],["8.700","0"],["8.694","52"],["8.650","0"],["8.644","119"],["8.600","0"],["8.594","179"],["8.550","0"],["8.544","149"]],"checksum":-306187182,"ts":"1649290099137"}]}
1649290099.170141: {"action":"snapshot","arg":{"instType":"mc","channel":"ticker","instId":"DASHUSDT"},"data":[{"instId":"DASHUSDT","last":"113.400","bestAsk":"113.42","bestBid":"113.37","high24h":"118.870","low24h":"113.140","priceChangePercent":"-0.036","capitalRate":"-0.000100","nextSettleTime":1649314800000,"systemTime":1649290099140,"markPrice":"113.477","indexPrice":"113.490","holding":"21957.17","baseVolume":"25306.70","quoteVolume":"3062928.58"}]}
1649290099.191479: {"action":"update","arg":{"instType":"mc","channel":"books","instId":"DASHUSDT"},"data":[{"asks":[["113.41","7.66"],["113.42","11.97"],["113.43","2.16"],["113.51","88.33"],["113.52","51.69"],["113.53","19.88"],["113.54","174.34"],["113.56","73.31"],["113.57","33.66"],["113.58","1600.05"],["113.59","30.22"],["113.60","70.85"],["113.61","43.76"],["113.62","30.05"],["113.64","92.91"],["113.65","119.86"],["113.67","39.53"],["113.68","645.12"],["113.70","32.40"],["113.71","34.71"],["113.72","158.98"],["113.73","206.39"],["113.74","23.70"],["113.75","241.89"],["113.77","766.51"],["113.78","189.51"],["113.79","117.12"],["113.80","158.88"],["113.81","24.69"],["113.83","93.49"],["113.84","2105.51"],["113.85","232.40"],["113.87","44.43"],["113.89","4.47"],["113.90","3353.88"],["113.91","0"],["113.92","0"],["113.96","1908.10"],["113.97","0"],["114.02","1709.57"],["114.03","0"],["114.08","1863.98"],["114.09","0"],["114.14","1974.27"],["114.15","0"],["114.20","1952.22"],["114.21","0"],["114.26","2018.39"],["114.27","0"],["114.32","1930.16"],["114.33","0"],["114.38","1996.33"],["114.39","0"],["114.44","1841.92"],["114.45","0"],["114.50","1886.04"],["114.51","0"],["114.56","1819.86"],["114.57","0"],["114.62","1731.63"],["114.63","0"],["114.68","1775.75"],["114.69","0"],["114.74","1797.80"],["114.75","0"],["115.78","0.73"],["116.00","0"],["116.37","68.26"],["116.59","0"],["116.96","70.90"],["117.18","0"],["117.55","49.89"],["117.77","0"],["118.14","22.59"],["118.36","0"],["118.73","47.85"],["118.95","0"],["119.32","46.71"],["119.54","0"],["119.91","23.57"],["120.13","0"],["120.50","59.15"],["120.72","0"],["121.09","6.51"],["121.31","0"],["121.68","54.25"],["121.90","0"],["122.27","14.99"],["122.49","0"],["122.86","11.21"],["123.08","0"],["123.45","66.50"],["123.67","0"],["124.04","64.47"],["124.26","0"],["124.63","42.85"],["124.85","0"],["125.22","29.99"],["125.44","0"],["125.81","4.07"],["126.03","0"],["126.40","26.70"],["126.62","0"],["126.99","20.67"],["127.21","0"],["127.58","56.99"],["127.80","0"],["128.17","44.01"],["128.39","0"],["128.76","46.60"],["128.98","0"],["129.35","39.07"],["129.57","0"],["129.94","19.33"],["130.16","0"],["130.53","20.66"],["130.75","0"],["131.12","28.11"],["131.34","0"],["131.71","13.65"],["131.93","0"],["132.52","0"],["133.11","0"],["133.70","0"]],"bids":[["113.37","0"],["113.36","11.89"],["113.35","247.51"],["113.34","30.70"],["113.32","24.60"],["113.31","58.78"],["113.30","46.22"],["113.29","11.63"],["113.28","25.73"],["113.27","1600.16"],["113.26","107.36"],["113.24","30.76"],["113.23","23.93"],["113.22","11.38"],["113.21","50.08"],["113.20","16.20"],["113.19","158.31"],["113.18","35.52"],["113.17","16.84"],["113.16","28.27"],["113.15","506.22"],["113.14","616.61"],["113.13","63.22"],["113.12","3.52"],["113.11","96.10"],["113.10","20.38"],["113.08","78.66"],["113.07","92.55"],["113.04","199.62"],["113.03","59.96"],["113.02","1510.03"],["112.98","628.12"],["112.94","124.75"],["112.93","1752.83"],["112.88","36.43"],["112.87","2202.00"],["112.82","0"],["112.81","1908.10"],["112.76","0"],["112.75","1863.98"],["112.70","0"],["112.69","1974.27"],["112.64","0"],["112.63","2018.39"],["112.58","0"],["112.57","1841.92"],["112.52","0"],["112.51","1952.22"],["112.46","0"],["112.45","1886.04"],["112.40","0"],["112.39","1753.69"],["112.34","0"],["112.33","2040.45"],["112.28","0"],["112.27","1930.16"],["112.22","0"],["112.21","1819.86"],["112.16","0"],["112.15","1731.63"],["112.10","0"],["112.09","1996.33"],["112.04","0"],["112.03","1797.80"],["111.66","54.98"],["111.61","0"],["111.07","56.15"],["111.02","0"],["110.47","22.20"],["110.43","0"],["109.88","45.95"],["109.84","0"],["109.29","29.62"],["109.25","0"],["108.70","21.93"],["108.66","0"],["108.11","6.02"],["108.07","0"],["107.52","55.97"],["107.48","0"],["106.93","21.31"],["106.89","0"],["106.34","8.95"],["106.30","0"],["105.75","10.15"],["105.71","0"],["105.16","40.07"],["105.12","0"],["104.57","15.36"],["104.53","0"],["103.98","46.47"],["103.94","0"],["103.39","11.11"],["103.35","0"],["102.80","1.87"],["102.76","0"],["102.21","37.67"],["102.17","0"],["101.62","21.48"],["101.58","0"],["101.03","49.80"],["100.99","0"],["100.44","49.32"],["100.40","0"],["99.85","42.14"],["99.26","8.55"],["98.67","30.36"],["98.08","20.32"],["97.49","36.65"],["96.90","21.95"],["96.31","8.41"],["95.72","31.49"],["95.13","57.35"],["94.54","3.45"],["93.95","4.85"],["93.36","74.35"],["92.77","33.85"],["92.18","20.24"]],"checksum":390575320,"ts":"1649290099159"}]}
1649290099.4285812: {"action":"snapshot","arg":{"instType":"mc","channel":"ticker","instId":"UNIUSDT"},"data":[{"instId":"UNIUSDT","last":"9.9740","bestAsk":"9.977","bestBid":"9.972","high24h":"10.4280","low24h":"9.9030","priceChangePercent":"-0.0390","capitalRate":"-0.000100","nextSettleTime":1649314800000,"systemTime":1649290099390,"markPrice":"9.9810","indexPrice":"9.9826","holding":"369411","baseVolume":"313101","quoteVolume":"3294624"}]}
1649290099.435261: {"action":"snapshot","arg":{"instType":"mc","channel":"ticker","instId":"DASHUSDT"},"data":[{"instId":"DASHUSDT","last":"113.400","bestAsk":"113.41","bestBid":"113.36","high24h":"118.870","low24h":"113.140","priceChangePercent":"-0.036","capitalRate":"-0.000100","nextSettleTime":1649314800000,"systemTime":1649290099402,"markPrice":"113.477","indexPrice":"113.420","holding":"21957.17","baseVolume":"25306.70","quoteVolume":"3062928.58"}]}
1649290099.4716742: {"action":"update","arg":{"instType":"mc","channel":"books","instId":"UNIUSDT"},"data":[{"asks":[["9.977","104"],["9.978","228"],["9.979","324"],["9.980","164"],["9.982","104"],["9.984","904"],["9.985","835"],["9.986","107"],["9.987","684"],["9.989","755"],["9.990","1635"],["9.991","434"],["9.992","415"],["9.993","689"],["9.995","771"],["9.996","1741"],["9.998","634"],["9.999","383"],["10.000","439"],["10.001","1009"],["10.006","2132"],["10.009","279"],["10.010","510"],["10.011","1486"],["10.013","1069"],["10.014","8173"],["10.016","278"],["10.023","4648"],["10.024","2001"],["10.025","14080"],["10.026","1773"],["10.030","12213"],["10.035","13174"],["10.040","13366"],["10.045","12789"],["10.050","11636"],["10.055","11443"],["10.060","13559"],["10.065","12597"],["10.070","12982"],["10.075","12020"],["10.080","11828"],["10.120","325"],["10.126","0"],["10.171","114"],["10.177","0"],["10.222","62"],["10.228","0"],["10.273","96"],["10.279","0"],["10.324","302"],["10.330","0"],["10.375","402"],["10.381","0"],["10.426","79"],["10.432","0"],["10.483","0"],["10.528","327"],["10.534","0"],["10.579","102"],["10.585","0"],["10.630","300"],["10.636","0"],["10.681","115"],["10.687","0"],["10.732","146"],["10.738","0"],["10.783","298"],["10.789","0"],["10.834","401"],["10.840","0"],["10.885","133"],["10.891","0"],["10.936","97"],["10.942","0"],["10.987","343"],["10.993","0"],["11.038","381"],["11.044","0"],["11.089","240"],["11.095","0"],["11.140","75"],["11.146","0"],["11.191","310"],["11.197","0"],["11.242","224"],["11.248","0"],["11.293","146"],["11.299","0"]],"bids":[["9.970","177"],["9.968","224"],["9.967","201"],["9.966","196"],["9.962","829"],["9.961","509"],["9.959","417"],["9.958","519"],["9.957","3302"],["9.955","282"],["9.952","494"],["9.948","712"],["9.945","1597"],["9.944","8058"],["9.941","1249"],["9.940","559"],["9.939","431"],["9.935","8"],["9.924","14957"],["9.919","13366"],["9.914","11636"],["9.909","12982"],["9.904","12597"],["9.899","12020"],["9.894","12405"],["9.889","11443"],["9.884","12213"],["9.879","12789"],["9.874","11828"],["9.869","13559"],["9.795","0"],["9.789","376"],["9.744","0"],["9.738","371"],["9.694","0"],["9.688","19"],["9.644","0"],["9.638","296"],["9.594","0"],["9.588","321"],["9.544","0"],["9.538","66"],["9.494","0"],["9.488","192"],["9.444","0"],["9.438","82"],["9.394","0"],["9.388","16"],["9.344","0"],["9.338","382"],["9.294","0"],["9.288","2"],["9.244","0"],["9.238","300"],["9.194","0"],["9.188","268"],["9.144","0"],["9.138","348"],["9.094","0"],["9.088","307"],["9.044","0"],["9.038","104"],["8.994","0"],["8.988","266"],["8.944","0"],["8.938","90"],["8.894","0"],["8.888","213"],["8.844","0"],["8.838","105"],["8.794","0"],["8.788","295"],["8.744","0"],["8.738","108"],["8.694","0"],["8.688","52"],["8.644","0"],["8.638","119"],["8.594","0"],["8.588","179"],["8.544","0"],["8.538","149"]],"checksum":-1377409841,"ts":"1649290099442"}]}
1649290099.507234: {"action":"update","arg":{"instType":"mc","channel":"books","instId":"DASHUSDT"},"data":[{"asks":[["113.41","5.30"],["113.42","10.18"],["113.48","3.27"],["113.49","1.53"],["113.50","11.75"],["113.52","37.11"],["113.53","16.58"],["113.54","194.52"],["113.55","8.42"],["113.56","57.76"],["113.57","42.69"],["113.59","35.69"],["113.60","72.83"],["113.62","38.09"],["113.67","41.87"],["113.68","797.08"],["113.69","30.36"],["113.72","102.32"],["113.77","769.10"],["113.84","2018.38"],["113.85","227.94"],["113.86","110.95"],["113.87","48.03"],["113.90","3486.21"],["113.96","1863.98"],["114.02","2018.39"],["114.08","1819.86"],["114.14","1797.80"],["114.20","1841.92"],["114.26","1996.33"],["114.32","1974.27"],["114.38","1709.57"],["114.44","1731.63"],["114.50","1775.75"],["114.56","1930.16"],["114.62","2040.45"],["114.68","1908.10"],["114.74","1753.69"]],"bids":[["113.36","26.74"],["113.34","0"],["113.30","66.56"],["113.28","134.38"],["113.23","26.42"],["113.22","20.11"],["113.19","0.80"],["113.17","174.75"],["113.15","493.79"],["113.14","650.27"],["113.08","81.14"],["113.06","18.42"],["112.98","625.09"],["112.95","365.09"],["112.93","1841.06"],["112.92","27.97"],["112.87","2246.11"],["112.85","128.00"],["112.81","2040.45"],["112.75","1753.69"],["112.69","1952.22"],["112.63","1996.33"],["112.57","1775.75"],["112.51","1930.16"],["112.45","1709.57"],["112.39","1731.63"],["112.33","1886.04"],["112.27","1863.98"],["112.21","1841.92"],["112.15","1974.27"],["112.09","1908.10"],["112.03","2018.39"]],"checksum":154287564,"ts":"1649290099479"}]}
1649290099.586623: {"action":"update","arg":{"instType":"mc","channel":"candle1m","instId":"UNIUSDT"},"data":[["1649290080000","9.977","9.986","9.974","9.974","33"]]}
1649290099.67711: {"action":"snapshot","arg":{"instType":"mc","channel":"ticker","instId":"UNIUSDT"},"data":[{"instId":"UNIUSDT","last":"9.9740","bestAsk":"9.977","bestBid":"9.972","high24h":"10.4280","low24h":"9.9030","priceChangePercent":"-0.0396","capitalRate":"-0.000100","nextSettleTime":1649314800000,"systemTime":1649290099648,"markPrice":"9.9810","indexPrice":"9.9826","holding":"369411","baseVolume":"313106","quoteVolume":"3294674"}]}
1649290099.683288: {"action":"snapshot","arg":{"instType":"mc","channel":"ticker","instId":"DASHUSDT"},"data":[{"instId":"DASHUSDT","last":"113.400","bestAsk":"113.41","bestBid":"113.36","high24h":"118.870","low24h":"113.140","priceChangePercent":"-0.036","capitalRate":"-0.000100","nextSettleTime":1649314800000,"systemTime":1649290099655,"markPrice":"113.477","indexPrice":"113.490","holding":"21957.17","baseVolume":"25306.70","quoteVolume":"3062928.58"}]}
1649290099.7746189: {"action":"update","arg":{"instType":"mc","channel":"books","instId":"UNIUSDT"},"data":[{"asks":[["9.978","134"],["9.982","135"],["9.983","507"],["9.984","1411"],["9.987","635"],["9.990","1570"],["9.993","732"],["9.994","2167"],["9.998","439"],["10.012","602"],["10.017","7564"],["10.022","683"],["10.025","14464"],["10.030","12597"],["10.035","12982"],["10.040","13174"],["10.045","12405"],["10.055","12213"],["10.060","11828"],["10.065","11443"],["10.070","13366"],["10.075","13559"],["10.080","12020"],["10.114","325"],["10.120","0"],["10.165","114"],["10.171","0"],["10.216","62"],["10.222","0"],["10.267","96"],["10.273","0"],["10.318","302"],["10.324","0"],["10.369","402"],["10.375","0"],["10.420","79"],["10.426","0"],["10.471","6"],["10.522","327"],["10.528","0"],["10.573","102"],["10.579","0"],["10.624","300"],["10.630","0"],["10.675","115"],["10.681","0"],["10.726","146"],["10.732","0"],["10.777","298"],["10.783","0"],["10.828","401"],["10.834","0"],["10.879","133"],["10.885","0"],["10.930","97"],["10.936","0"],["10.981","343"],["10.987","0"],["11.032","381"],["11.038","0"],["11.083","240"],["11.089","0"],["11.134","75"],["11.140","0"],["11.185","310"],["11.191","0"],["11.236","224"],["11.242","0"],["11.287","146"],["11.293","0"]],"bids":[["9.970","274"],["9.969","163"],["9.968","260"],["9.964","1008"],["9.962","721"],["9.961","622"],["9.960","256"],["9.954","361"],["9.949","841"],["9.945","863"],["9.944","8140"],["9.937","489"],["9.934","3625"],["9.933","3332"],["9.924","13803"],["9.919","12213"],["9.914","11443"],["9.909","13366"],["9.904","13559"],["9.899","12789"],["9.894","12597"],["9.889","12982"],["9.884","11636"],["9.879","11828"],["9.874","13174"],["9.869","12405"],["9.789","0"],["9.783","376"],["9.738","0"],["9.732","371"],["9.688","0"],["9.682","19"],["9.638","0"],["9.632","296"],["9.588","0"],["9.582","321"],["9.538","0"],["9.532","66"],["9.488","0"],["9.482","192"],["9.438","0"],["9.432","82"],["9.388","0"],["9.382","16"],["9.338","0"],["9.332","382"],["9.288","0"],["9.282","2"],["9.238","0"],["9.232","300"],["9.188","0"],["9.182","268"],["9.138","0"],["9.132","348"],["9.088","0"],["9.082","307"],["9.038","0"],["9.032","104"],["8.988","0"],["8.982","266"],["8.938","0"],["8.932","90"],["8.888","0"],["8.882","213"],["8.838","0"],["8.832","105"],["8.788","0"],["8.782","295"],["8.738","0"],["8.732","108"],["8.688","0"],["8.682","52"],["8.638","0"],["8.632","119"],["8.588","0"],["8.582","179"],["8.538","0"],["8.532","149"]],"checksum":454754723,"ts":"1649290099741"}]}
1649290099.816257: {"action":"update","arg":{"instType":"mc","channel":"books","instId":"DASHUSDT"},"data":[{"asks":[["113.41","9.16"],["113.42","7.31"],["113.46","9.87"],["113.48","2.28"],["113.51","91.63"],["113.52","28.94"],["113.53","52.55"],["113.54","138.09"],["113.56","116.50"],["113.57","40.71"],["113.59","30.22"],["113.60","88.37"],["113.62","38.96"],["113.65","122.45"],["113.76","241.93"],["113.79","92.17"],["113.84","1775.73"],["113.90","3552.60"],["113.96","1930.16"],["114.02","1819.86"],["114.08","1974.27"],["114.14","1731.63"],["114.20","1996.33"],["114.26","1841.92"],["114.32","1886.04"],["114.38","1753.69"],["114.44","1863.98"],["114.50","2040.45"],["114.56","2018.39"],["114.62","1797.80"],["114.68","1775.75"],["114.74","1908.10"]],"bids":[["113.36","11.89"],["113.33","27.20"],["113.30","68.00"],["113.29","50.24"],["113.28","118.77"],["113.26","22.22"],["113.23","37.35"],["113.20","60.39"],["113.18","68.81"],["113.15","506.22"],["113.08","78.66"],["113.07","67.18"],["113.03","55.18"],["113.01","21.39"],["113.00","26.22"],["112.93","1796.95"],["112.87","2135.82"],["112.81","1863.98"],["112.75","2040.45"],["112.69","1819.86"],["112.63","1731.63"],["112.57","1886.04"],["112.51","1974.27"],["112.45","1841.92"],["112.39","1996.33"],["112.33","1930.16"],["112.27","2018.39"],["112.21","1775.75"],["112.15","1797.80"],["112.09","1952.22"],["112.03","1908.10"]],"checksum":1572655060,"ts":"1649290099785"}]}
1649290099.933774: {"action":"snapshot","arg":{"instType":"mc","channel":"ticker","instId":"UNIUSDT"},"data":[{"instId":"UNIUSDT","last":"9.9740","bestAsk":"9.977","bestBid":"9.972","high24h":"10.4280","low24h":"9.9030","priceChangePercent":"-0.0396","capitalRate":"-0.000100","nextSettleTime":1649314800000,"systemTime":1649290099902,"markPrice":"9.9810","indexPrice":"9.9826","holding":"369411","baseVolume":"313106","quoteVolume":"3294674"}]}
1649290099.951467: {"action":"snapshot","arg":{"instType":"mc","channel":"ticker","instId":"DASHUSDT"},"data":[{"instId":"DASHUSDT","last":"113.400","bestAsk":"113.41","bestBid":"113.36","high24h":"118.870","low24h":"113.140","priceChangePercent":"-0.036","capitalRate":"-0.000100","nextSettleTime":1649314800000,"systemTime":1649290099914,"markPrice":"113.459","indexPrice":"113.420","holding":"21957.17","baseVolume":"25306.70","quoteVolume":"3062928.58"}]}
1649290100.11425: {"action":"update","arg":{"instType":"mc","channel":"books","instId":"DASHUSDT"},"data":[{"asks":[["113.41","5.30"],["113.47","14.50"],["113.59","22.10"],["113.60","98.20"],["113.62","28.58"],["113.64","107.99"],["113.69","36.04"],["113.84","1863.96"],["113.90","3640.80"],["113.96","1775.75"],["114.02","1841.92"],["114.08","1863.98"],["114.20","2018.39"],["114.26","1930.16"],["114.32","1753.69"],["114.38","1996.33"],["114.44","1952.22"],["114.50","1974.27"],["114.56","1908.10"],["114.62","1886.04"],["114.68","1819.86"],["114.74","1709.57"]],"bids":[["113.32","23.38"],["113.31","54.99"],["113.28","125.85"],["113.20","15.77"],["113.17","177.53"],["113.03","64.23"],["112.97","163.34"],["112.93","1774.89"],["112.87","2268.17"],["112.81","1775.75"],["112.75","1908.10"],["112.69","1753.69"],["112.63","2018.39"],["112.57","1996.33"],["112.51","1797.80"],["112.45","1886.04"],["112.39","1863.98"],["112.33","1952.22"],["112.27","1819.86"],["112.21","1974.27"],["112.15","1709.57"],["112.09","2040.45"],["112.03","1930.16"]],"checksum":400945720,"ts":"1649290100084"}]}
1649290100.126106: {"action":"update","arg":{"instType":"mc","channel":"books","instId":"UNIUSDT"},"data":[{"asks":[["9.978","223"],["9.981","261"],["9.983","572"],["9.985","895"],["9.986","203"],["9.987","430"],["9.988","416"],["9.991","438"],["9.997","599"],["9.999","1175"],["10.001","993"],["10.002","526"],["10.009","304"],["10.012","571"],["10.013","1066"],["10.019","844"],["10.020","4471"],["10.021","191"],["10.022","256"],["10.025","13503"],["10.035","11443"],["10.040","12982"],["10.045","12020"],["10.050","12213"],["10.055","13174"],["10.060","11636"],["10.065","12789"],["10.075","12405"],["10.080","13559"],["10.107","325"],["10.114","0"],["10.158","114"],["10.165","0"],["10.209","62"],["10.216","0"],["10.260","96"],["10.267","0"],["10.311","302"],["10.318","0"],["10.362","402"],["10.369","0"],["10.413","79"],["10.420","0"],["10.464","6"],["10.471","0"],["10.515","327"],["10.522","0"],["10.566","102"],["10.573","0"],["10.617","300"],["10.624","0"],["10.668","115"],["10.675","0"],["10.719","146"],["10.726","0"],["10.770","298"],["10.777","0"],["10.821","401"],["10.828","0"],["10.872","133"],["10.879","0"],["10.923","97"],["10.930","0"],["10.974","343"],["10.981","0"],["11.025","381"],["11.032","0"],["11.076","240"],["11.083","0"],["11.127","75"],["11.134","0"],["11.178","310"],["11.185","0"],["11.229","224"],["11.236","0"],["11.280","146"],["11.287","0"]],"bids":[["9.971","224"],["9.969","165"],["9.968","237"],["9.966","224"],["9.965","53"],["9.959","553"],["9.958","772"],["9.957","3269"],["9.956","1211"],["9.955","290"],["9.953","875"],["9.951","466"],["9.950","599"],["9.949","916"],["9.947","407"],["9.946","364"],["9.945","1655"],["9.944","7854"],["9.941","1421"],["9.935","177"],["9.933","1697"],["9.924","14957"],["9.919","11828"],["9.914","12597"],["9.909","11636"],["9.904","12020"],["9.894","12405"],["9.889","13559"],["9.884","11443"],["9.879","12213"],["9.874","12982"],["9.869","13366"],["9.783","0"],["9.776","376"],["9.732","0"],["9.725","371"],["9.682","0"],["9.675","19"],["9.632","0"],["9.625","296"],["9.582","0"],["9.575","321"],["9.532","0"],["9.525","66"],["9.482","0"],["9.475","192"],["9.432","0"],["9.425","82"],["9.382","0"],["9.375","16"],["9.332","0"],["9.325","382"],["9.282","0"],["9.275","2"],["9.232","0"],["9.225","300"],["9.182","0"],["9.175","268"],["9.132","0"],["9.125","348"],["9.082","0"],["9.075","307"],["9.032","0"],["9.025","104"],["8.982","0"],["8.975","266"],["8.932","0"],["8.925","90"],["8.882","0"],["8.875","213"],["8.832","0"],["8.825","105"],["8.782","0"],["8.775","295"],["8.732","0"],["8.725","108"],["8.682","0"],["8.675","52"],["8.632","0"],["8.625","119"],["8.582","0"],["8.575","179"],["8.532","0"],["8.525","149"]],"checksum":1713577655,"ts":"1649290100089"}]}
1649290100.196992: {"action":"snapshot","arg":{"instType":"mc","channel":"ticker","instId":"UNIUSDT"},"data":[{"instId":"UNIUSDT","last":"9.9740","bestAsk":"9.977","bestBid":"9.972","high24h":"10.4280","low24h":"9.9030","priceChangePercent":"-0.0396","capitalRate":"-0.000100","nextSettleTime":1649314800000,"systemTime":1649290100165,"markPrice":"9.9810","indexPrice":"9.9817","holding":"369411","baseVolume":"313106","quoteVolume":"3294674"}]}
1649290100.201368: {"action":"snapshot","arg":{"instType":"mc","channel":"ticker","instId":"DASHUSDT"},"data":[{"instId":"DASHUSDT","last":"113.400","bestAsk":"113.41","bestBid":"113.36","high24h":"118.870","low24h":"113.140","priceChangePercent":"-0.036","capitalRate":"-0.000100","nextSettleTime":1649314800000,"systemTime":1649290100172,"markPrice":"113.459","indexPrice":"113.420","holding":"21957.17","baseVolume":"25306.70","quoteVolume":"3062928.58"}]}
1649290100.425951: {"action":"update","arg":{"instType":"mc","channel":"books","instId":"DASHUSDT"},"data":[{"asks":[["113.41","7.58"],["113.42","13.88"],["113.45","5.68"],["113.47","13.99"],["113.49","3.18"],["113.50","16.34"],["113.51","95.95"],["113.52","39.32"],["113.55","3.31"],["113.59","37.64"],["113.60","112.22"],["113.67","40.62"],["113.70","47.35"],["113.84","2084.55"],["113.90","3420.10"],["113.96","1731.63"],["114.02","1775.75"],["114.08","1753.69"],["114.14","1841.92"],["114.20","1797.80"],["114.26","1863.98"],["114.32","1908.10"],["114.38","2040.45"],["114.44","1996.33"],["114.50","1886.04"],["114.56","1974.27"],["114.62","1952.22"],["114.68","1709.57"],["114.74","1930.16"]],"bids":[["113.33","23.58"],["113.30","120.79"],["113.29","47.70"],["113.28","128.13"],["113.22","24.38"],["113.20","59.96"],["113.15","493.79"],["113.11","113.92"],["113.10","1.57"],["113.08","84.43"],["113.07","105.65"],["112.96","179.27"],["112.93","1929.30"],["112.81","1974.27"],["112.75","1930.16"],["112.69","1819.86"],["112.63","1709.57"],["112.57","1775.75"],["112.51","2040.45"],["112.45","1908.10"],["112.39","1797.80"],["112.33","2018.39"],["112.27","1952.22"],["112.21","1863.98"],["112.15","1731.63"],["112.09","1753.69"],["112.03","1996.33"]],"checksum":-612339155,"ts":"1649290100391"}]}
1649290100.4321861: {"action":"update","arg":{"instType":"mc","channel":"books","instId":"UNIUSDT"},"data":[{"asks":[["9.977","177"],["9.978","212"],["9.979","240"],["9.980","178"],["9.981","314"],["9.982","79"],["9.983","506"],["9.984","1485"],["9.985","957"],["9.986","246"],["9.987","384"],["9.988","440"],["9.990","1519"],["9.991","529"],["9.993","556"],["9.994","2147"],["9.996","1757"],["9.997","619"],["9.998","528"],["9.999","549"],["10.001","765"],["10.002","600"],["10.003","941"],["10.004","635"],["10.007","501"],["10.010","527"],["10.012","595"],["10.013","1856"],["10.019","51"],["10.020","4613"],["10.022","690"],["10.023","4666"],["10.024","14476"],["10.025","1676"],["10.029","11443"],["10.030","0"],["10.034","13366"],["10.035","0"],["10.039","12020"],["10.040","0"],["10.044","12789"],["10.045","0"],["10.049","11636"],["10.050","0"],["10.054","13559"],["10.055","0"],["10.059","13174"],["10.060","0"],["10.064","12405"],["10.065","0"],["10.069","12213"],["10.070","0"],["10.074","11828"],["10.075","0"],["10.079","12982"],["10.080","0"],["10.101","325"],["10.107","0"],["10.152","114"],["10.158","0"],["10.203","62"],["10.209","0"],["10.254","96"],["10.260","0"],["10.305","302"],["10.311","0"],["10.356","402"],["10.362","0"],["10.407","79"],["10.413","0"],["10.458","6"],["10.464","0"],["10.509","327"],["10.515","0"],["10.560","102"],["10.566","0"],["10.611","300"],["10.617","0"],["10.662","115"],["10.668","0"],["10.713","146"],["10.719","0"],["10.764","298"],["10.770","0"],["10.815","401"],["10.821","0"],["10.866","133"],["10.872","0"],["10.917","97"],["10.923","0"],["10.968","343"],["10.974","0"],["11.019","381"],["11.025","0"],["11.070","240"],["11.076","0"],["11.121","75"],["11.127","0"],["11.172","310"],["11.178","0"],["11.223","224"],["11.229","0"],["11.274","146"],["11.280","0"]],"bids":[["9.972","0"],["9.971","26"],["9.970","373"],["9.969","49"],["9.968","168"],["9.967","223"],["9.966","255"],["9.965","282"],["9.964","863"],["9.962","768"],["9.959","652"],["9.957","3318"],["9.955","311"],["9.954","293"],["9.953","848"],["9.952","556"],["9.951","363"],["9.949","936"],["9.946","458"],["9.944","7874"],["9.942","1372"],["9.941","1478"],["9.940","466"],["9.939","1552"],["9.936","523"],["9.935","150"],["9.934","3650"],["9.933","4376"],["9.931","3616"],["9.930","1155"],["9.924","14380"],["9.922","572"],["9.919","11443"],["9.914","12789"],["9.909","11828"],["9.904","12405"],["9.899","13366"],["9.894","13559"],["9.889","12020"],["9.884","12982"],["9.879","11636"],["9.874","13174"],["9.869","12213"],["9.776","0"],["9.770","376"],["9.725","0"],["9.719","371"],["9.675","0"],["9.669","19"],["9.625","0"],["9.619","296"],["9.575","0"],["9.569","321"],["9.525","0"],["9.519","66"],["9.475","0"],["9.469","192"],["9.425","0"],["9.419","82"],["9.375","0"],["9.369","16"],["9.325","0"],["9.319","382"],["9.275","0"],["9.269","2"],["9.225","0"],["9.219","300"],["9.175","0"],["9.169","268"],["9.125","0"],["9.119","348"],["9.075","0"],["9.069","307"],["9.025","0"],["9.019","104"],["8.975","0"],["8.969","266"],["8.925","0"],["8.919","90"],["8.875","0"],["8.869","213"],["8.825","0"],["8.819","105"],["8.775","0"],["8.769","295"],["8.725","0"],["8.719","108"],["8.675","0"],["8.669","52"],["8.625","0"],["8.619","119"],["8.575","0"],["8.569","179"],["8.525","0"],["8.519","149"]],"checksum":-1478700057,"ts":"1649290100400"}]}
1649290100.45463: {"action":"snapshot","arg":{"instType":"mc","channel":"ticker","instId":"UNIUSDT"},"data":[{"instId":"UNIUSDT","last":"9.9740","bestAsk":"9.977","bestBid":"9.971","high24h":"10.4280","low24h":"9.9030","priceChangePercent":"-0.0396","capitalRate":"-0.000100","nextSettleTime":1649314800000,"systemTime":1649290100426,"markPrice":"9.9810","indexPrice":"9.9817","holding":"369411","baseVolume":"313106","quoteVolume":"3294674"}]}
1649290100.4590468: {"action":"snapshot","arg":{"instType":"mc","channel":"ticker","instId":"DASHUSDT"},"data":[{"instId":"DASHUSDT","last":"113.400","bestAsk":"113.41","bestBid":"113.36","high24h":"118.870","low24h":"113.140","priceChangePercent":"-0.036","capitalRate":"-0.000100","nextSettleTime":1649314800000,"systemTime":1649290100429,"markPrice":"113.459","indexPrice":"113.420","holding":"21957.17","baseVolume":"25306.70","quoteVolume":"3062928.58"}]}
1649290100.735708: {"action":"update","arg":{"instType":"mc","channel":"books","instId":"DASHUSDT"},"data":[{"asks":[["113.39","3.23"],["113.40","11.25"],["113.42","10.89"],["113.45","10.83"],["113.47","15.97"],["113.48","3.42"],["113.50","28.87"],["113.51","102.40"],["113.52","29.05"],["113.57","38.64"],["113.64","109.58"],["113.70","49.42"],["113.75","225.46"],["113.76","241.62"],["113.82","1974.86"],["113.84","66.17"],["113.88","2300.82"],["113.89","0"],["113.90","0"],["113.94","1974.27"],["113.96","0"],["114.00","1819.86"],["114.02","0"],["114.06","1930.16"],["114.08","0"],["114.12","1775.75"],["114.14","0"],["114.18","1753.69"],["114.20","0"],["114.24","1863.98"],["114.26","0"],["114.30","1996.33"],["114.32","0"],["114.36","1841.92"],["114.38","0"],["114.42","1731.63"],["114.44","0"],["114.48","2018.39"],["114.50","0"],["114.54","1886.04"],["114.56","0"],["114.60","1797.80"],["114.62","0"],["114.66","1709.57"],["114.68","0"],["114.72","1908.10"],["114.74","0"]],"bids":[["113.36","0"],["113.35","0"],["113.32","46.54"],["113.31","109.90"],["113.29","45.01"],["113.28","131.95"],["113.26","22.15"],["113.24","25.48"],["113.23","55.80"],["113.22","20.11"],["113.21","58.59"],["113.20","65.66"],["113.18","68.73"],["113.13","61.77"],["113.11","111.94"],["113.09","56.76"],["113.08","81.94"],["113.07","88.20"],["113.04","200.78"],["112.99","20.05"],["112.97","124.10"],["112.93","43.27"],["112.92","44.91"],["112.91","3.00"],["112.90","1977.84"],["112.89","9.60"],["112.87","426.26"],["112.84","1846.77"],["112.81","0"],["112.78","1841.92"],["112.75","0"],["112.72","1753.69"],["112.69","0"],["112.66","1797.80"],["112.63","0"],["112.60","1996.33"],["112.57","0"],["112.54","1731.63"],["112.51","0"],["112.48","2040.45"],["112.45","0"],["112.42","1709.57"],["112.39","0"],["112.36","1930.16"],["112.33","0"],["112.30","1952.22"],["112.27","0"],["112.24","1775.75"],["112.21","0"],["112.18","1974.27"],["112.15","0"],["112.12","1908.10"],["112.09","0"],["112.06","1863.98"],["112.03","0"],["112.00","2018.39"]],"checksum":1969429497,"ts":"1649290100704"}]}
1649290100.771446: {"action":"update","arg":{"instType":"mc","channel":"books","instId":"UNIUSDT"},"data":[{"asks":[["9.976","43"],["9.979","587"],["9.980","116"],["9.981","341"],["9.982","185"],["9.983","523"],["9.984","2114"],["9.985","554"],["9.986","188"],["9.987","323"],["9.988","409"],["9.989","854"],["9.990","1551"],["9.992","427"],["9.993","507"],["9.994","2278"],["9.995","720"],["9.996","1921"],["9.997","662"],["9.998","412"],["9.999","1990"],["10.000","425"],["10.001","814"],["10.002","603"],["10.003","815"],["10.005","696"],["10.006","1077"],["10.007","494"],["10.008","438"],["10.010","414"],["10.012","461"],["10.014","8145"],["10.016","266"],["10.022","597"],["10.023","4482"],["10.024","17156"],["10.025","2106"],["10.026","0"],["10.029","11636"],["10.034","13174"],["10.039","12789"],["10.044","11443"],["10.049","11828"],["10.054","12597"],["10.059","13366"],["10.074","12982"],["10.079","12020"],["10.094","325"],["10.101","0"],["10.145","114"],["10.152","0"],["10.196","62"],["10.203","0"],["10.247","96"],["10.254","0"],["10.298","302"],["10.305","0"],["10.349","402"],["10.356","0"],["10.400","79"],["10.407","0"],["10.451","6"],["10.458","0"],["10.502","327"],["10.509","0"],["10.553","102"],["10.560","0"],["10.604","300"],["10.611","0"],["10.655","115"],["10.662","0"],["10.706","146"],["10.713","0"],["10.757","298"],["10.764","0"],["10.808","401"],["10.815","0"],["10.859","133"],["10.866","0"],["10.910","97"],["10.917","0"],["10.961","343"],["10.968","0"],["11.012","381"],["11.019","0"],["11.063","240"],["11.070","0"],["11.114","75"],["11.121","0"],["11.165","310"],["11.172","0"],["11.216","224"],["11.223","0"],["11.267","146"],["11.274","0"]],"bids":[["9.969","88"],["9.968","115"],["9.965","53"],["9.964","924"],["9.962","743"],["9.961","531"],["9.960","231"],["9.959","741"],["9.958","621"],["9.957","3443"],["9.956","1142"],["9.954","212"],["9.951","303"],["9.950","294"],["9.949","861"],["9.948","786"],["9.947","265"],["9.945","1651"],["9.943","1081"],["9.942","1113"],["9.939","1636"],["9.938","236"],["9.936","493"],["9.935","29"],["9.934","206"],["9.933","6011"],["9.932","679"],["9.924","1784"],["9.923","12577"],["9.919","0"],["9.918","11828"],["9.914","0"],["9.913","12597"],["9.909","0"],["9.908","12789"],["9.904","0"],["9.903","12405"],["9.899","0"],["9.898","13174"],["9.894","0"],["9.893","13366"],["9.889","0"],["9.888","12982"],["9.884","0"],["9.883","13559"],["9.879","0"],["9.878","12020"],["9.874","0"],["9.873","11636"],["9.869","0"],["9.868","11443"],["9.770","0"],["9.763","376"],["9.719","0"],["9.712","371"],["9.669","0"],["9.662","19"],["9.619","0"],["9.612","296"],["9.569","0"],["9.562","321"],["9.519","0"],["9.512","66"],["9.469","0"],["9.462","192"],["9.419","0"],["9.412","82"],["9.369","0"],["9.362","16"],["9.319","0"],["9.312","382"],["9.269","0"],["9.262","2"],["9.219","0"],["9.212","300"],["9.169","0"],["9.162","268"],["9.119","0"],["9.112","348"],["9.069","0"],["9.062","307"],["9.019","0"],["9.012","104"],["8.969","0"],["8.962","266"],["8.919","0"],["8.912","90"],["8.869","0"],["8.862","213"],["8.819","0"],["8.812","105"],["8.769","0"],["8.762","295"],["8.719","0"],["8.712","108"],["8.669","0"],["8.662","52"],["8.619","0"],["8.612","119"],["8.569","0"],["8.562","179"],["8.519","0"],["8.512","149"]],"checksum":816817723,"ts":"1649290100737"}]}
1649290100.825561: {"action":"snapshot","arg":{"instType":"mc","channel":"ticker","instId":"UNIUSDT"},"data":[{"instId":"UNIUSDT","last":"9.9740","bestAsk":"9.976","bestBid":"9.971","high24h":"10.4280","low24h":"9.9030","priceChangePercent":"-0.0396","capitalRate":"-0.000100","nextSettleTime":1649314800000,"systemTime":1649290100786,"markPrice":"9.9774","indexPrice":"9.9824","holding":"369411","baseVolume":"313106","quoteVolume":"3294674"}]}
1649290100.8297641: {"action":"snapshot","arg":{"instType":"mc","channel":"ticker","instId":"DASHUSDT"},"data":[{"instId":"DASHUSDT","last":"113.400","bestAsk":"113.39","bestBid":"113.33","high24h":"118.870","low24h":"113.140","priceChangePercent":"-0.036","capitalRate":"-0.000100","nextSettleTime":1649314800000,"systemTime":1649290100797,"markPrice":"113.459","indexPrice":"113.420","holding":"21957.17","baseVolume":"25306.70","quoteVolume":"3062928.58"}]}
1649290100.8860831: {"action":"update","arg":{"instType":"mc","channel":"trade","instId":"UNIUSDT"},"data":[["1649290100795","9.972","5","sell"]]}
1649290100.9074292: {"action":"update","arg":{"instType":"mc","channel":"trade","instId":"DASHUSDT"},"data":[["1649290100782","113.34","0.44","sell"]]}
1649290101.059463: {"action":"update","arg":{"instType":"mc","channel":"books","instId":"DASHUSDT"},"data":[{"asks":[["113.39","1.91"],["113.40","10.14"],["113.42","12.65"],["113.46","16.86"],["113.49","12.94"],["113.50","106.35"],["113.51","92.42"],["113.52","21.19"],["113.53","37.40"],["113.54","139.35"],["113.55","1.82"],["113.56","124.39"],["113.57","28.32"],["113.59","28.89"],["113.60","174.20"],["113.62","9.40"],["113.64","113.41"],["113.65","170.13"],["113.67","36.65"],["113.68","792.73"],["113.70","50.91"],["113.72","225.08"],["113.73","204.91"],["113.76","315.87"],["113.77","772.12"],["113.81","20.41"],["113.82","2062.76"],["113.83","19.24"],["113.85","796.96"],["113.86","212.86"],["113.87","7.81"],["113.88","1863.98"],["113.89","5.65"],["113.94","1886.04"],["114.00","1797.80"],["114.06","1753.69"],["114.12","1841.92"],["114.18","1952.22"],["114.24","1930.16"],["114.36","2018.39"],["114.42","1974.27"],["114.48","1775.75"],["114.54","1709.57"],["114.60","1819.86"],["114.66","1908.10"],["114.72","1731.63"],["115.78","0"],["116.00","31.47"],["116.37","0"],["116.59","50.46"],["116.96","0"],["117.18","49.40"],["117.55","0"],["117.77","27.41"],["118.14","0"],["118.36","50.42"],["118.73","0"],["118.95","50.07"],["119.32","0"],["119.54","36.12"],["119.91","0"],["120.13","8.62"],["120.50","0"],["120.72","54.60"],["121.09","0"],["121.31","1.48"],["121.68","0"],["121.90","43.49"],["122.27","0"],["122.49","7.73"],["122.86","0"],["123.08","58.21"],["123.45","0"],["123.67","52.67"],["124.04","0"],["124.26","53.84"],["124.63","0"],["124.85","4.99"],["125.22","0"],["125.44","44.04"],["125.81","0"],["126.03","25.10"],["126.40","0"],["126.62","39.09"],["126.99","0"],["127.21","44.51"],["127.58","0"],["127.80","19.01"],["128.17","0"],["128.39","29.39"],["128.76","0"],["128.98","3.89"],["129.35","0"],["129.57","23.37"],["129.94","0"],["130.16","24.18"],["130.53","0"],["130.75","9.15"],["131.12","0"],["131.34","27.04"],["131.71","0"],["131.93","7.10"],["132.52","13.38"],["133.11","33.57"],["133.70","76.51"]],"bids":[["113.33","31.30"],["113.32","379.18"],["113.30","74.64"],["113.29","9.91"],["113.28","17.49"],["113.25","64.77"],["113.24","19.03"],["113.23","55.65"],["113.22","11.12"],["113.21","15.71"],["113.20","199.40"],["113.19","12.45"],["113.18","36.16"],["113.16","29.76"],["113.15","546.63"],["113.13","60.61"],["113.12","3.99"],["113.11","107.98"],["113.10","12.68"],["113.08","76.03"],["113.07","27.02"],["113.06","16.68"],["113.03","61.52"],["113.02","1560.69"],["113.00","12.31"],["112.98","534.94"],["112.97","122.03"],["112.96","185.92"],["112.95","356.19"],["112.94","0.89"],["112.93","120.89"],["112.90","2066.07"],["112.88","39.71"],["112.84","1833.64"],["112.78","1753.69"],["112.72","1952.22"],["112.66","1908.10"],["112.60","1731.63"],["112.54","1819.86"],["112.48","1930.16"],["112.42","1996.33"],["112.36","1841.92"],["112.30","2040.45"],["112.24","2018.39"],["112.18","1863.98"],["112.12","1709.57"],["112.06","1886.04"],["112.00","1775.75"],["111.66","0"],["111.61","44.63"],["111.07","0"],["111.02","97.81"],["110.47","0"],["110.43","40.49"],["109.88","0"],["109.84","85.27"],["109.29","0"],["109.25","84.73"],["108.70","0"],["108.66","59.74"],["108.11","0"],["108.07","61.13"],["107.52","0"],["107.48","33.01"],["106.93","0"],["106.89","56.85"],["106.34","0"],["106.30","24.34"],["105.75","0"],["105.71","1.74"],["105.16","0"],["105.12","57.94"],["104.57","0"],["104.53","58.21"],["103.98","0"],["103.94","46.12"],["103.39","0"],["103.35","52.32"],["102.80","0"],["102.76","45.29"],["102.21","0"],["102.17","22.94"],["101.62","0"],["101.58","36.02"],["101.03","0"],["100.99","38.02"],["100.44","0"],["100.40","53.60"],["99.85","0"],["99.26","0"],["98.67","0"],["98.08","0"],["97.49","0"],["96.90","0"],["96.31","0"],["95.72","0"],["95.13","0"],["94.54","0"],["93.95","0"],["93.36","0"],["92.77","0"],["92.18","0"]],"checksum":-1487296953,"ts":"1649290101019"}]}
1649290101.1112251: {"action":"snapshot","arg":{"instType":"mc","channel":"ticker","instId":"DASHUSDT"},"data":[{"instId":"DASHUSDT","last":"113.340","bestAsk":"113.39","bestBid":"113.33","high24h":"118.870","low24h":"113.140","priceChangePercent":"-0.036","capitalRate":"-0.000100","nextSettleTime":1649314800000,"systemTime":1649290101074,"markPrice":"113.435","indexPrice":"113.420","holding":"21957.17","baseVolume":"25306.70","quoteVolume":"3062928.58"}]}
1649290101.114599: {"action":"update","arg":{"instType":"mc","channel":"books","instId":"UNIUSDT"},"data":[{"asks":[["9.975","117"],["9.977","161"],["9.978","642"],["9.979","351"],["9.980","264"],["9.981","153"],["9.982","838"],["9.983","649"],["9.984","1911"],["9.985","497"],["9.986","241"],["9.987","567"],["9.988","388"],["9.989","788"],["9.990","1200"],["9.991","382"],["9.992","392"],["9.993","1994"],["9.994","2432"],["9.995","702"],["9.996","1470"],["9.997","593"],["9.998","400"],["9.999","1226"],["10.000","530"],["10.001","789"],["10.003","902"],["10.006","775"],["10.007","338"],["10.010","395"],["10.011","1315"],["10.012","423"],["10.015","117"],["10.022","256"],["10.023","17878"],["10.024","3598"],["10.025","0"],["10.028","12405"],["10.029","0"],["10.033","12213"],["10.034","0"],["10.038","12597"],["10.039","0"],["10.043","11636"],["10.044","0"],["10.048","12789"],["10.049","0"],["10.053","11443"],["10.054","0"],["10.058","13174"],["10.059","0"],["10.063","12982"],["10.064","0"],["10.068","12020"],["10.069","0"],["10.073","13559"],["10.074","0"],["10.078","11828"],["10.079","0"],["10.088","325"],["10.094","0"],["10.139","114"],["10.145","0"],["10.190","62"],["10.196","0"],["10.241","96"],["10.247","0"],["10.292","302"],["10.298","0"],["10.343","402"],["10.349","0"],["10.394","79"],["10.400","0"],["10.445","6"],["10.451","0"],["10.496","327"],["10.502","0"],["10.547","102"],["10.553","0"],["10.598","300"],["10.604","0"],["10.649","115"],["10.655","0"],["10.700","146"],["10.706","0"],["10.751","298"],["10.757","0"],["10.802","401"],["10.808","0"],["10.853","133"],["10.859","0"],["10.904","97"],["10.910","0"],["10.955","343"],["10.961","0"],["11.006","381"],["11.012","0"],["11.057","240"],["11.063","0"],["11.108","75"],["11.114","0"],["11.159","310"],["11.165","0"],["11.210","224"],["11.216","0"],["11.261","146"],["11.267","0"]],"bids":[["9.971","0"],["9.969","76"],["9.968","293"],["9.966","307"],["9.964","233"],["9.963","324"],["9.962","1200"],["9.961","485"],["9.960","284"],["9.959","720"],["9.958","656"],["9.957","3045"],["9.956","1139"],["9.955","378"],["9.953","801"],["9.952","595"],["9.951","328"],["9.950","335"],["9.949","842"],["9.948","1038"],["9.947","365"],["9.946","474"],["9.945","859"],["9.944","8131"],["9.942","1972"],["9.941","2369"],["9.939","1614"],["9.938","103"],["9.935","267"],["9.934","183"],["9.933","4376"],["9.932","548"],["9.923","365"],["9.922","16833"],["9.921","56"],["9.918","0"],["9.917","11636"],["9.913","0"],["9.912","12982"],["9.908","0"],["9.907","11828"],["9.903","0"],["9.902","13366"],["9.898","0"],["9.897","12405"],["9.893","0"],["9.892","11443"],["9.888","0"],["9.887","12213"],["9.883","0"],["9.882","13559"],["9.878","0"],["9.877","12597"],["9.873","0"],["9.872","12020"],["9.868","0"],["9.867","13174"],["9.763","0"],["9.757","376"],["9.712","0"],["9.706","371"],["9.662","0"],["9.656","19"],["9.612","0"],["9.606","296"],["9.562","0"],["9.556","321"],["9.512","0"],["9.506","66"],["9.462","0"],["9.456","192"],["9.412","0"],["9.406","82"],["9.362","0"],["9.356","16"],["9.312","0"],["9.306","382"],["9.262","0"],["9.256","2"],["9.212","0"],["9.206","300"],["9.162","0"],["9.156","268"],["9.112","0"],["9.106","348"],["9.062","0"],["9.056","307"],["9.012","0"],["9.006","104"],["8.962","0"],["8.956","266"],["8.912","0"],["8.906","90"],["8.862","0"],["8.856","213"],["8.812","0"],["8.806","105"],["8.762","0"],["8.756","295"],["8.712","0"],["8.706","108"],["8.662","0"],["8.656","52"],["8.612","0"],["8.606","119"],["8.562","0"],["8.556","179"],["8.512","0"],["8.506","149"]],"checksum":1301985116,"ts":"1649290101086"}]}
1649290101.1375449: {"action":"snapshot","arg":{"instType":"mc","channel":"ticker","instId":"UNIUSDT"},"data":[{"instId":"UNIUSDT","last":"9.9720","bestAsk":"9.975","bestBid":"9.97","high24h":"10.4280","low24h":"9.9030","priceChangePercent":"-0.0396","capitalRate":"-0.000100","nextSettleTime":1649314800000,"systemTime":1649290101107,"markPrice":"9.9774","indexPrice":"9.9817","holding":"369411","baseVolume":"313106","quoteVolume":"3294674"}]}
1649290101.163533: {"action":"update","arg":{"instType":"mc","channel":"candle1m","instId":"DASHUSDT"},"data":[["1649290080000","113.37","113.55","113.34","113.34","5.25"]]}
1649290101.355745: {"action":"update","arg":{"instType":"mc","channel":"books","instId":"DASHUSDT"},"data":[{"asks":[["113.36","1.69"],["113.37","6.06"],["113.38","6.25"],["113.39","0.59"],["113.41","2.83"],["113.44","6.53"],["113.47","19.18"],["113.48","43.79"],["113.49","11.13"],["113.50","66.77"],["113.51","94.23"],["113.52","18.78"],["113.53","36.94"],["113.54","139.78"],["113.55","24.23"],["113.57","21.77"],["113.58","1328.73"],["113.61","63.07"],["113.66","9.82"],["113.79","1801.73"],["113.82","22.32"],["113.85","2837.40"],["113.86","0"],["113.87","0"],["113.88","0"],["113.89","0"],["113.91","1974.27"],["113.94","0"],["113.97","1930.16"],["114.00","0"],["114.03","1731.63"],["114.06","0"],["114.09","1863.98"],["114.12","0"],["114.15","1819.86"],["114.18","0"],["114.21","1886.04"],["114.24","0"],["114.27","1908.10"],["114.30","0"],["114.33","1996.33"],["114.36","0"],["114.39","1841.92"],["114.42","0"],["114.45","1797.80"],["114.48","0"],["114.51","1775.75"],["114.54","0"],["114.57","1952.22"],["114.60","0"],["114.63","2018.39"],["114.66","0"],["114.69","1753.69"],["114.72","0"],["115.78","0.73"],["116.00","0"],["116.37","68.26"],["116.59","0"],["116.96","70.90"],["117.18","0"],["117.55","49.89"],["117.77","0"],["118.14","22.59"],["118.36","0"],["118.73","47.85"],["118.95","0"],["119.32","46.71"],["119.54","0"],["119.91","23.57"],["120.13","0"],["120.50","59.15"],["120.72","0"],["121.09","6.51"],["121.31","0"],["121.68","54.25"],["121.90","0"],["122.27","14.99"],["122.49","0"],["122.86","11.21"],["123.08","0"],["123.45","66.50"],["123.67","0"],["124.04","64.47"],["124.26","0"],["124.63","42.85"],["124.85","0"],["125.22","29.99"],["125.44","0"],["125.81","4.07"],["126.03","0"],["126.40","26.70"],["126.62","0"],["126.99","20.67"],["127.21","0"],["127.58","56.99"],["127.80","0"],["128.17","44.01"],["128.39","0"],["128.76","46.60"],["128.98","0"],["129.35","39.07"],["129.57","0"],["129.94","19.33"],["130.16","0"],["130.53","20.66"],["130.75","0"],["131.12","28.11"],["131.34","0"],["131.71","13.65"],["131.93","0"],["132.52","0"],["133.11","0"],["133.70","0"]],"bids":[["113.33","0"],["113.32","0"],["113.28","17.25"],["113.27","1600.14"],["113.25","64.44"],["113.24","18.67"],["113.21","14.43"],["113.17","178.17"],["113.15","543.28"],["113.14","654.15"],["113.11","106.00"],["113.09","59.85"],["113.08","72.75"],["113.06","31.86"],["113.04","138.55"],["113.02","1559.81"],["112.99","40.51"],["112.98","512.67"],["112.95","331.07"],["112.90","91.81"],["112.88","1837.50"],["112.85","189.28"],["112.84","35.85"],["112.83","5.02"],["112.82","1821.41"],["112.78","0"],["112.76","1930.16"],["112.72","0"],["112.70","1974.27"],["112.66","0"],["112.64","1841.92"],["112.60","0"],["112.58","1996.33"],["112.54","0"],["112.52","1886.04"],["112.48","0"],["112.46","1753.69"],["112.42","0"],["112.40","2018.39"],["112.36","0"],["112.34","1908.10"],["112.30","0"],["112.28","2040.45"],["112.24","0"],["112.22","1731.63"],["112.18","0"],["112.16","1709.57"],["112.12","0"],["112.10","1863.98"],["112.06","0"],["112.04","1952.22"],["112.00","0"],["111.98","1775.75"],["111.66","54.98"],["111.61","0"],["111.07","56.15"],["111.02","0"],["110.47","22.20"],["110.43","0"],["109.88","45.95"],["109.84","0"],["109.29","29.62"],["109.25","0"],["108.70","21.93"],["108.66","0"],["108.11","6.02"],["108.07","0"],["107.52","55.97"],["107.48","0"],["106.93","21.31"],["106.89","0"],["106.34","8.95"],["106.30","0"],["105.75","10.15"],["105.71","0"],["105.16","40.07"],["105.12","0"],["104.57","15.36"],["104.53","0"],["103.98","46.47"],["103.94","0"],["103.39","11.11"],["103.35","0"],["102.80","1.87"],["102.76","0"],["102.21","37.67"],["102.17","0"],["101.62","21.48"],["101.58","0"],["101.03","49.80"],["100.99","0"],["100.44","49.32"],["100.40","0"],["99.85","42.14"],["99.26","8.55"],["98.67","30.36"],["98.08","20.32"],["97.49","36.65"],["96.90","21.95"],["96.31","8.41"],["95.72","31.49"],["95.13","57.35"],["94.54","3.45"],["93.95","4.85"],["93.36","74.35"],["92.77","33.85"],["92.18","20.24"]],"checksum":1209584393,"ts":"1649290101326"}]}
1649290101.416899: {"action":"update","arg":{"instType":"mc","channel":"books","instId":"UNIUSDT"},"data":[{"asks":[["9.974","3"],["9.975","327"],["9.976","78"],["9.977","339"],["9.978","462"],["9.979","248"],["9.980","206"],["9.982","892"],["9.983","409"],["9.985","840"],["9.986","381"],["9.989","796"],["9.990","1850"],["9.991","288"],["9.993","1955"],["9.994","2511"],["9.997","716"],["9.999","1056"],["10.000","469"],["10.002","680"],["10.004","442"],["10.006","959"],["10.007","450"],["10.010","292"],["10.011","1330"],["10.016","501"],["10.019","299"],["10.022","13072"],["10.023","4686"],["10.024","0"],["10.027","12213"],["10.028","0"],["10.032","12597"],["10.033","0"],["10.037","13174"],["10.038","0"],["10.042","11636"],["10.043","0"],["10.047","12020"],["10.048","0"],["10.052","13366"],["10.053","0"],["10.057","13559"],["10.058","0"],["10.062","11828"],["10.063","0"],["10.067","12982"],["10.068","0"],["10.072","11443"],["10.073","0"],["10.077","12405"],["10.078","0"],["10.081","325"],["10.088","0"],["10.132","114"],["10.139","0"],["10.183","62"],["10.190","0"],["10.234","96"],["10.241","0"],["10.285","302"],["10.292","0"],["10.336","402"],["10.343","0"],["10.387","79"],["10.394","0"],["10.438","6"],["10.445","0"],["10.489","327"],["10.496","0"],["10.540","102"],["10.547","0"],["10.591","300"],["10.598","0"],["10.642","115"],["10.649","0"],["10.693","146"],["10.700","0"],["10.744","298"],["10.751","0"],["10.795","401"],["10.802","0"],["10.846","133"],["10.853","0"],["10.897","97"],["10.904","0"],["10.948","343"],["10.955","0"],["10.999","381"],["11.006","0"],["11.050","240"],["11.057","0"],["11.101","75"],["11.108","0"],["11.152","310"],["11.159","0"],["11.203","224"],["11.210","0"],["11.254","146"],["11.261","0"]],"bids":[["9.970","0"],["9.969","14"],["9.967","164"],["9.966","394"],["9.965","51"],["9.964","293"],["9.963","297"],["9.961","336"],["9.959","662"],["9.958","1115"],["9.957","3012"],["9.956","1159"],["9.955","427"],["9.954","286"],["9.953","762"],["9.952","636"],["9.950","373"],["9.948","1121"],["9.946","432"],["9.941","2438"],["9.940","546"],["9.939","2236"],["9.936","505"],["9.935","314"],["9.934","217"],["9.931","3571"],["9.925","8324"],["9.922","4045"],["9.921","12652"],["9.920","1086"],["9.917","0"],["9.916","13559"],["9.912","0"],["9.911","11828"],["9.907","0"],["9.906","11443"],["9.902","0"],["9.901","12789"],["9.897","0"],["9.896","12405"],["9.892","0"],["9.891","13366"],["9.887","0"],["9.886","12213"],["9.882","0"],["9.881","12020"],["9.877","0"],["9.876","11636"],["9.872","0"],["9.871","13174"],["9.867","0"],["9.866","12982"],["9.757","0"],["9.750","376"],["9.706","0"],["9.699","371"],["9.656","0"],["9.649","19"],["9.606","0"],["9.599","296"],["9.556","0"],["9.549","321"],["9.506","0"],["9.499","66"],["9.456","0"],["9.449","192"],["9.406","0"],["9.399","82"],["9.356","0"],["9.349","16"],["9.306","0"],["9.299","382"],["9.256","0"],["9.249","2"],["9.206","0"],["9.199","300"],["9.156","0"],["9.149","268"],["9.106","0"],["9.099","348"],["9.056","0"],["9.049","307"],["9.006","0"],["8.999","104"],["8.956","0"],["8.949","266"],["8.906","0"],["8.899","90"],["8.856","0"],["8.849","213"],["8.806","0"],["8.799","105"],["8.756","0"],["8.749","295"],["8.706","0"],["8.699","108"],["8.656","0"],["8.649","52"],["8.606","0"],["8.599","119"],["8.556","0"],["8.549","179"],["8.506","0"],["8.499","149"]],"checksum":1713676752,"ts":"1649290101387"}]}
1649290101.550823: {"action":"snapshot","arg":{"instType":"mc","channel":"ticker","instId":"UNIUSDT"},"data":[{"instId":"UNIUSDT","last":"9.9720","bestAsk":"9.974","bestBid":"9.969","high24h":"10.4280","low24h":"9.9030","priceChangePercent":"-0.0396","capitalRate":"-0.000100","nextSettleTime":1649314800000,"systemTime":1649290101508,"markPrice":"9.9755","indexPrice":"9.9824","holding":"369411","baseVolume":"313106","quoteVolume":"3294674"}]}
1649290101.550921: {"action":"snapshot","arg":{"instType":"mc","channel":"ticker","instId":"DASHUSDT"},"data":[{"instId":"DASHUSDT","last":"113.340","bestAsk":"113.36","bestBid":"113.31","high24h":"118.870","low24h":"113.140","priceChangePercent":"-0.036","capitalRate":"-0.000100","nextSettleTime":1649314800000,"systemTime":1649290101514,"markPrice":"113.435","indexPrice":"113.420","holding":"21957.17","baseVolume":"25307.14","quoteVolume":"3062978.45"}]}
1649290101.600686: {"action":"update","arg":{"instType":"mc","channel":"candle1m","instId":"UNIUSDT"},"data":[["1649290080000","9.977","9.986","9.972","9.972","38"]]}
1649290101.655676: {"action":"update","arg":{"instType":"mc","channel":"books","instId":"DASHUSDT"},"data":[{"asks":[["113.37","3.37"],["113.38","4.02"],["113.39","6.02"],["113.40","1.54"],["113.47","15.63"],["113.48","101.74"],["113.49","2.96"],["113.50","65.98"],["113.51","108.39"],["113.52","16.36"],["113.53","38.59"],["113.54","28.40"],["113.55","19.46"],["113.56","126.37"],["113.57","26.13"],["113.59","40.41"],["113.60","184.33"],["113.62","8.12"],["113.66","160.63"],["113.67","11.01"],["113.68","805.10"],["113.69","428.08"],["113.70","31.60"],["113.72","219.14"],["113.73","29.68"],["113.74","25.62"],["113.75","35.34"],["113.76","317.76"],["113.77","771.90"],["113.79","2066.43"],["113.80","170.76"],["113.85","2037.84"],["113.91","2018.39"],["113.97","1886.04"],["114.03","1753.69"],["114.09","2040.45"],["114.15","1930.16"],["114.21","1731.63"],["114.27","1841.92"],["114.33","1952.22"],["114.39","1819.86"],["114.45","1863.98"],["114.51","1709.57"],["114.57","1797.80"],["114.63","1908.10"],["114.69","1996.33"]],"bids":[["113.30","49.89"],["113.29","14.86"],["113.28","58.41"],["113.27","177.86"],["113.26","23.85"],["113.25","1600.13"],["113.24","52.83"],["113.23","28.43"],["113.22","19.25"],["113.21","5.92"],["113.20","200.88"],["113.18","31.51"],["113.17","20.26"],["113.16","28.27"],["113.15","444.77"],["113.14","646.73"],["113.13","100.21"],["113.12","162.43"],["113.11","30.48"],["113.09","68.76"],["113.08","72.42"],["113.07","25.89"],["113.05","1532.92"],["113.04","86.41"],["113.03","43.68"],["113.02","74.81"],["112.98","623.72"],["112.95","314.73"],["112.88","2092.76"],["112.82","1823.60"],["112.76","1996.33"],["112.70","2040.45"],["112.64","1709.57"],["112.58","1797.80"],["112.52","1731.63"],["112.46","1952.22"],["112.40","1841.92"],["112.34","1753.69"],["112.28","1775.75"],["112.22","1886.04"],["112.16","1863.98"],["112.10","1974.27"],["112.04","1908.10"],["111.98","1930.16"]],"checksum":-1260058308,"ts":"1649290101628"}]}
1649290101.713521: {"action":"update","arg":{"instType":"mc","channel":"books","instId":"UNIUSDT"},"data":[{"asks":[["9.975","232"],["9.977","173"],["9.978","353"],["9.979","274"],["9.980","305"],["9.982","874"],["9.983","449"],["9.984","816"],["9.985","814"],["9.986","332"],["9.988","360"],["9.993","2080"],["9.995","932"],["9.996","692"],["9.998","380"],["9.999","1071"],["10.000","436"],["10.003","885"],["10.004","460"],["10.006","1085"],["10.007","399"],["10.010","279"],["10.011","4847"],["10.022","13265"],["10.023","1209"],["10.027","11443"],["10.032","11636"],["10.037","13559"],["10.042","12405"],["10.047","12789"],["10.052","12020"],["10.057","12597"],["10.062","12213"],["10.067","13174"],["10.072","11828"],["10.077","13366"],["10.081","0"],["10.127","249"],["10.132","0"],["10.179","295"],["10.183","0"],["10.231","328"],["10.234","0"],["10.283","292"],["10.285","0"],["10.335","215"],["10.336","0"],["10.387","133"],["10.438","0"],["10.439","104"],["10.489","0"],["10.491","4"],["10.540","0"],["10.543","120"],["10.591","0"],["10.595","234"],["10.642","0"],["10.647","126"],["10.693","0"],["10.699","26"],["10.744","0"],["10.751","164"],["10.795","0"],["10.803","168"],["10.846","0"],["10.855","220"],["10.897","0"],["10.907","161"],["10.948","0"],["10.959","146"],["10.999","0"],["11.011","23"],["11.050","0"],["11.063","31"],["11.101","0"],["11.115","350"],["11.152","0"],["11.167","208"],["11.203","0"],["11.219","281"],["11.254","0"],["11.271","192"],["11.323","234"],["11.375","32"],["11.427","15"],["11.479","47"],["11.531","630"]],"bids":[["9.969","234"],["9.968","229"],["9.967","231"],["9.965","198"],["9.961","483"],["9.956","1139"],["9.955","572"],["9.953","795"],["9.952","657"],["9.951","316"],["9.948","1146"],["9.946","404"],["9.943","1102"],["9.941","2270"],["9.939","2666"],["9.937","468"],["9.934","201"],["9.931","3591"],["9.928","3802"],["9.922","4612"],["9.921","12462"],["9.916","13174"],["9.911","13366"],["9.906","12597"],["9.901","11636"],["9.896","12982"],["9.891","13559"],["9.886","11828"],["9.881","12789"],["9.876","11443"],["9.871","12213"],["9.866","12020"],["9.750","0"],["9.744","376"],["9.699","0"],["9.693","371"],["9.649","0"],["9.643","19"],["9.599","0"],["9.593","296"],["9.549","0"],["9.543","321"],["9.499","0"],["9.493","66"],["9.449","0"],["9.443","192"],["9.399","0"],["9.393","82"],["9.349","0"],["9.343","16"],["9.299","0"],["9.293","382"],["9.249","0"],["9.243","2"],["9.199","0"],["9.193","300"],["9.149","16"],["9.143","268"],["9.099","0"],["9.093","348"],["9.049","0"],["9.043","307"],["8.999","0"],["8.993","104"],["8.949","0"],["8.943","266"],["8.899","0"],["8.893","90"],["8.849","0"],["8.843","213"],["8.799","0"],["8.793","105"],["8.749","0"],["8.743","295"],["8.699","0"],["8.693","108"],["8.649","0"],["8.643","52"],["8.599","0"],["8.593","119"],["8.549","0"],["8.543","179"],["8.499","0"],["8.493","149"]],"checksum":-592348665,"ts":"1649290101687"}]}
1649290101.799407: {"action":"snapshot","arg":{"instType":"mc","channel":"ticker","instId":"DASHUSDT"},"data":[{"instId":"DASHUSDT","last":"113.340","bestAsk":"113.36","bestBid":"113.31","high24h":"118.870","low24h":"113.140","priceChangePercent":"-0.036","capitalRate":"-0.000100","nextSettleTime":1649314800000,"systemTime":1649290101770,"markPrice":"113.435","indexPrice":"113.420","holding":"21957.17","baseVolume":"25307.14","quoteVolume":"3062978.45"}]}
1649290101.8036191: {"action":"snapshot","arg":{"instType":"mc","channel":"ticker","instId":"UNIUSDT"},"data":[{"instId":"UNIUSDT","last":"9.9720","bestAsk":"9.974","bestBid":"9.969","high24h":"10.4280","low24h":"9.9030","priceChangePercent":"-0.0396","capitalRate":"-0.000100","nextSettleTime":1649314800000,"systemTime":1649290101768,"markPrice":"9.9755","indexPrice":"9.9824","holding":"369411","baseVolume":"313106","quoteVolume":"3294674"}]}
1649290101.959342: {"action":"update","arg":{"instType":"mc","channel":"books","instId":"DASHUSDT"},"data":[{"asks":[["113.36","0"],["113.37","0"],["113.38","0"],["113.40","10.93"],["113.41","8.27"],["113.42","13.94"],["113.44","4.26"],["113.47","22.06"],["113.48","87.30"],["113.51","106.58"],["113.55","1336.16"],["113.58","13.08"],["113.72","153.80"],["113.77","786.42"],["113.79","92.17"],["113.80","171.86"],["113.81","5.89"],["113.82","1820.11"],["113.84","76.07"],["113.85","493.03"],["113.86","8.92"],["113.87","7.81"],["113.88","1753.69"],["113.89","5.65"],["113.91","0"],["113.94","1819.86"],["113.97","0"],["114.00","1974.27"],["114.03","0"],["114.06","1731.63"],["114.09","0"],["114.12","1841.92"],["114.15","0"],["114.18","1996.33"],["114.21","0"],["114.24","1930.16"],["114.27","0"],["114.30","1886.04"],["114.33","0"],["114.36","2018.39"],["114.39","0"],["114.42","2040.45"],["114.45","0"],["114.48","1863.98"],["114.51","0"],["114.54","1709.57"],["114.57","0"],["114.60","1952.22"],["114.63","0"],["114.66","1908.10"],["114.69","0"],["114.72","1775.75"]],"bids":[["113.34","11.89"],["113.33","19.92"],["113.32","464.32"],["113.30","22.17"],["113.29","81.49"],["113.27","190.63"],["113.26","6.49"],["113.24","54.27"],["113.22","26.46"],["113.20","239.99"],["113.19","55.32"],["113.18","32.65"],["113.14","582.38"],["113.12","166.39"],["113.11","28.50"],["113.10","51.35"],["112.95","1600.31"],["112.91","1978.25"],["112.88","74.38"],["112.87","416.36"],["112.85","1965.02"],["112.84","0"],["112.83","0"],["112.82","0"],["112.79","2018.39"],["112.76","0"],["112.73","1797.80"],["112.70","0"],["112.67","1996.33"],["112.64","0"],["112.61","1930.16"],["112.58","0"],["112.55","1863.98"],["112.52","0"],["112.49","1886.04"],["112.46","0"],["112.43","2040.45"],["112.40","0"],["112.37","1841.92"],["112.34","0"],["112.31","1753.69"],["112.28","0"],["112.25","1731.63"],["112.22","0"],["112.19","1952.22"],["112.16","0"],["112.13","1709.57"],["112.10","0"],["112.07","1819.86"],["112.04","0"],["112.01","1908.10"],["111.98","0"]],"checksum":1300573156,"ts":"1649290101933"}]}
1649290102.020152: {"action":"update","arg":{"instType":"mc","channel":"books","instId":"UNIUSDT"},"data":[{"asks":[["9.975","384"],["9.976","168"],["9.977","130"],["9.978","317"],["9.980","279"],["9.986","351"],["9.987","429"],["9.989","828"],["9.995","1081"],["9.997","595"],["10.003","813"],["10.004","446"],["10.005","644"],["10.007","475"],["10.017","7851"],["10.021","205"],["10.022","13649"],["10.023","1036"],["10.027","13174"],["10.032","12405"],["10.037","12982"],["10.042","12597"],["10.047","11636"],["10.052","12789"],["10.057","13559"],["10.062","11828"],["10.067","12020"],["10.072","12213"],["10.077","11443"],["10.121","249"],["10.127","0"],["10.173","295"],["10.179","0"],["10.225","328"],["10.231","0"],["10.277","292"],["10.283","0"],["10.329","215"],["10.335","0"],["10.381","133"],["10.387","0"],["10.433","104"],["10.439","0"],["10.485","4"],["10.491","0"],["10.537","120"],["10.543","0"],["10.589","234"],["10.595","0"],["10.641","126"],["10.647","0"],["10.693","26"],["10.699","0"],["10.745","164"],["10.751","0"],["10.797","168"],["10.803","0"],["10.849","220"],["10.855","0"],["10.901","161"],["10.907","0"],["10.953","146"],["10.959","0"],["11.005","23"],["11.011","0"],["11.057","31"],["11.063","0"],["11.109","350"],["11.115","0"],["11.161","208"],["11.167","0"],["11.213","281"],["11.219","0"],["11.265","192"],["11.271","0"],["11.317","234"],["11.323","0"],["11.369","32"],["11.375","0"],["11.421","15"],["11.427","0"],["11.473","47"],["11.479","0"],["11.525","630"],["11.531","0"]],"bids":[["9.964","417"],["9.959","792"],["9.958","766"],["9.953","762"],["9.952","704"],["9.943","1178"],["9.924","1180"],["9.921","13616"],["9.916","12982"],["9.911","11443"],["9.906","11828"],["9.901","13366"],["9.896","11636"],["9.891","13174"],["9.886","12405"],["9.881","12213"],["9.876","12020"],["9.871","12789"],["9.866","12597"],["9.744","0"],["9.738","376"],["9.693","0"],["9.687","371"],["9.643","0"],["9.637","19"],["9.593","0"],["9.587","296"],["9.543","0"],["9.537","321"],["9.493","0"],["9.487","66"],["9.443","0"],["9.437","192"],["9.393","0"],["9.387","82"],["9.343","0"],["9.337","16"],["9.293","0"],["9.287","382"],["9.243","0"],["9.237","2"],["9.193","0"],["9.187","300"],["9.143","0"],["9.137","268"],["9.093","0"],["9.087","348"],["9.043","0"],["9.037","307"],["8.993","0"],["8.987","104"],["8.943","0"],["8.937","266"],["8.893","0"],["8.887","90"],["8.843","0"],["8.837","213"],["8.793","0"],["8.787","105"],["8.743","0"],["8.737","295"],["8.693","0"],["8.687","108"],["8.643","0"],["8.637","52"],["8.593","0"],["8.587","119"],["8.543","0"],["8.537","179"],["8.493","0"],["8.487","149"]],"checksum":-46513239,"ts":"1649290101992"}]}
1649290102.0590131: {"action":"snapshot","arg":{"instType":"mc","channel":"ticker","instId":"UNIUSDT"},"data":[{"instId":"UNIUSDT","last":"9.9720","bestAsk":"9.974","bestBid":"9.969","high24h":"10.4280","low24h":"9.9030","priceChangePercent":"-0.0398","capitalRate":"-0.000100","nextSettleTime":1649314800000,"systemTime":1649290102024,"markPrice":"9.9755","indexPrice":"9.9822","holding":"369411","baseVolume":"313111","quoteVolume":"3294724"}]}
1649290102.061952: {"action":"snapshot","arg":{"instType":"mc","channel":"ticker","instId":"DASHUSDT"},"data":[{"instId":"DASHUSDT","last":"113.340","bestAsk":"113.39","bestBid":"113.34","high24h":"118.870","low24h":"113.140","priceChangePercent":"-0.036","capitalRate":"-0.000100","nextSettleTime":1649314800000,"systemTime":1649290102033,"markPrice":"113.410","indexPrice":"113.402","holding":"21957.17","baseVolume":"25307.14","quoteVolume":"3062978.45"}]}
1649290102.263756: {"action":"update","arg":{"instType":"mc","channel":"books","instId":"DASHUSDT"},"data":[{"asks":[["113.42","12.47"],["113.43","4.29"],["113.44","24.96"],["113.45","5.68"],["113.46","129.71"],["113.47","49.17"],["113.48","70.54"],["113.50","119.63"],["113.51","47.87"],["113.52","19.25"],["113.57","34.05"],["113.60","186.31"],["113.63","230.54"],["113.64","112.09"],["113.65","273.33"],["113.68","856.58"],["113.69","126.63"],["113.76","302.91"],["113.77","788.07"],["113.81","4.24"],["113.82","1753.94"],["113.84","31.57"],["113.85","262.10"],["113.88","1775.75"],["114.06","2040.45"],["114.12","1952.22"],["114.18","1797.80"],["114.24","1886.04"],["114.30","1841.92"],["114.36","1930.16"],["114.42","1996.33"],["114.48","1908.10"],["114.60","1753.69"],["114.66","2018.39"],["114.72","1863.98"]],"bids":[["113.33","123.87"],["113.32","424.72"],["113.30","40.98"],["113.29","50.80"],["113.28","52.84"],["113.27","41.10"],["113.26","223.60"],["113.24","52.83"],["113.13","135.19"],["113.11","18.94"],["113.09","24.25"],["113.08","66.48"],["113.04","96.31"],["112.99","41.85"],["112.98","500.45"],["112.95","1600.06"],["112.91","1912.08"],["112.85","1898.84"],["112.79","1731.63"],["112.73","1841.92"],["112.67","1886.04"],["112.61","1753.69"],["112.55","1996.33"],["112.49","1974.27"],["112.43","1775.75"],["112.37","1863.98"],["112.31","1819.86"],["112.25","1797.80"],["112.19","2040.45"],["112.13","1930.16"],["112.07","1952.22"],["112.01","2018.39"]],"checksum":-2055128078,"ts":"1649290102233"}]}
1649290102.324509: {"action":"update","arg":{"instType":"mc","channel":"books","instId":"UNIUSDT"},"data":[{"asks":[["9.974","5"],["9.978","254"],["9.979","326"],["9.980","862"],["9.981","377"],["9.984","318"],["9.985","670"],["9.986","378"],["9.987","384"],["9.989","706"],["9.991","334"],["9.993","1980"],["9.995","919"],["9.996","1484"],["9.997","602"],["9.999","1173"],["10.006","1124"],["10.007","481"],["10.011","5033"],["10.015","152"],["10.016","488"],["10.027","12405"],["10.032","11828"],["10.037","11636"],["10.042","12020"],["10.047","12789"],["10.052","13174"],["10.057","12982"],["10.062","13559"],["10.067","12597"],["10.115","249"],["10.121","0"],["10.167","295"],["10.173","0"],["10.219","328"],["10.225","0"],["10.271","292"],["10.277","0"],["10.323","215"],["10.329","0"],["10.375","133"],["10.381","0"],["10.427","104"],["10.433","0"],["10.479","4"],["10.485","0"],["10.531","120"],["10.537","0"],["10.583","234"],["10.589","0"],["10.635","126"],["10.641","0"],["10.687","26"],["10.693","0"],["10.739","164"],["10.745","0"],["10.791","168"],["10.797","0"],["10.843","220"],["10.849","0"],["10.895","161"],["10.901","0"],["10.947","146"],["10.953","0"],["10.999","23"],["11.005","0"],["11.051","31"],["11.057","0"],["11.103","350"],["11.109","0"],["11.155","208"],["11.161","0"],["11.207","281"],["11.213","0"],["11.259","192"],["11.265","0"],["11.311","234"],["11.317","0"],["11.363","32"],["11.369","0"],["11.415","15"],["11.421","0"],["11.467","47"],["11.473","0"],["11.519","630"],["11.525","0"]],"bids":[["9.964","464"],["9.960","235"],["9.959","709"],["9.958","882"],["9.956","1082"],["9.955","648"],["9.952","683"],["9.948","1188"],["9.942","1662"],["9.939","2716"],["9.933","4328"],["9.929","466"],["9.921","13231"],["9.916","12213"],["9.911","12597"],["9.906","12020"],["9.901","12405"],["9.896","12982"],["9.891","13559"],["9.886","11828"],["9.881","13366"],["9.876","11443"],["9.866","11636"],["9.738","0"],["9.732","376"],["9.687","0"],["9.681","371"],["9.637","0"],["9.631","19"],["9.587","0"],["9.581","296"],["9.537","0"],["9.531","321"],["9.487","0"],["9.481","66"],["9.437","0"],["9.431","192"],["9.387","0"],["9.381","82"],["9.337","0"],["9.331","16"],["9.287","0"],["9.281","382"],["9.237","0"],["9.231","2"],["9.187","0"],["9.181","300"],["9.137","0"],["9.131","268"],["9.087","0"],["9.081","348"],["9.037","0"],["9.031","307"],["8.987","0"],["8.981","104"],["8.937","0"],["8.931","266"],["8.887","0"],["8.881","90"],["8.837","0"],["8.831","213"],["8.787","0"],["8.781","105"],["8.737","0"],["8.731","295"],["8.687","0"],["8.681","108"],["8.637","0"],["8.631","52"],["8.587","0"],["8.581","119"],["8.537","0"],["8.531","179"],["8.487","0"],["8.481","149"]],"checksum":863210570,"ts":"1649290102291"}]}
1649290102.365088: {"action":"snapshot","arg":{"instType":"mc","channel":"ticker","instId":"UNIUSDT"},"data":[{"instId":"UNIUSDT","last":"9.9720","bestAsk":"9.974","bestBid":"9.969","high24h":"10.4280","low24h":"9.9030","priceChangePercent":"-0.0398","capitalRate":"-0.000100","nextSettleTime":1649314800000,"systemTime":1649290102328,"markPrice":"9.9755","indexPrice":"9.9822","holding":"369411","baseVolume":"313111","quoteVolume":"3294724"}]}
1649290102.371572: {"action":"snapshot","arg":{"instType":"mc","channel":"ticker","instId":"DASHUSDT"},"data":[{"instId":"DASHUSDT","last":"113.340","bestAsk":"113.39","bestBid":"113.34","high24h":"118.870","low24h":"113.140","priceChangePercent":"-0.036","capitalRate":"-0.000100","nextSettleTime":1649314800000,"systemTime":1649290102335,"markPrice":"113.410","indexPrice":"113.402","holding":"21957.17","baseVolume":"25307.14","quoteVolume":"3062978.45"}]}
1649290102.576457: {"action":"update","arg":{"instType":"mc","channel":"books","instId":"DASHUSDT"},"data":[{"asks":[["113.39","0"],["113.40","0.82"],["113.41","2.91"],["113.42","11.21"],["113.43","8.78"],["113.44","0"],["113.45","6.78"],["113.46","16.86"],["113.47","10.26"],["113.48","80.11"],["113.49","2.19"],["113.50","65.98"],["113.51","108.66"],["113.52","6.27"],["113.53","39.18"],["113.54","48.59"],["113.55","5.87"],["113.56","141.91"],["113.57","20.44"],["113.58","1328.73"],["113.60","170.09"],["113.62","6.40"],["113.63","225.59"],["113.64","113.41"],["113.65","167.60"],["113.66","190.36"],["113.67","15.44"],["113.68","805.10"],["113.69","428.08"],["113.72","219.14"],["113.76","317.76"],["113.77","775.09"],["113.81","20.41"],["113.82","1840.38"],["113.83","18.52"],["113.87","42.59"],["113.88","1974.27"],["113.89","4.47"],["113.90","1600.20"],["113.91","3.63"],["113.94","1996.33"],["114.00","2018.39"],["114.06","1952.22"],["114.12","1908.10"],["114.18","1863.98"],["114.24","1775.75"],["114.30","1753.69"],["114.42","1731.63"],["114.48","1886.04"],["114.54","1841.92"],["114.60","1797.80"],["114.66","1709.57"],["114.72","2040.45"],["115.78","0"],["116.00","31.47"],["116.37","0"],["116.59","50.46"],["116.96","0"],["117.18","49.40"],["117.55","0"],["117.77","27.41"],["118.14","0"],["118.36","50.42"],["118.73","0"],["118.95","50.07"],["119.32","0"],["119.54","36.12"],["119.91","0"],["120.13","8.62"],["120.50","0"],["120.72","54.60"],["121.09","0"],["121.31","1.48"],["121.68","0"],["121.90","43.49"],["122.27","0"],["122.49","7.73"],["122.86","0"],["123.08","58.21"],["123.45","0"],["123.67","52.67"],["124.04","0"],["124.26","53.84"],["124.63","0"],["124.85","4.99"],["125.22","0"],["125.44","44.04"],["125.81","0"],["126.03","25.10"],["126.40","0"],["126.62","39.09"],["126.99","0"],["127.21","44.51"],["127.58","0"],["127.80","19.01"],["128.17","0"],["128.39","29.39"],["128.76","0"],["128.98","3.89"],["129.35","0"],["129.57","23.37"],["129.94","0"],["130.16","24.18"],["130.53","0"],["130.75","9.15"],["131.12","0"],["131.34","27.04"],["131.71","0"],["131.93","7.10"],["132.52","13.38"],["133.11","33.57"],["133.70","76.51"]],"bids":[["113.34","0"],["113.33","17.24"],["113.32","236.22"],["113.31","58.92"],["113.30","36.11"],["113.29","14.67"],["113.28","55.12"],["113.27","172.98"],["113.26","23.12"],["113.23","33.59"],["113.22","21.23"],["113.21","48.80"],["113.20","198.10"],["113.19","12.45"],["113.18","66.55"],["113.17","20.81"],["113.14","649.51"],["113.13","97.97"],["113.11","10.76"],["113.10","11.39"],["113.09","68.80"],["113.08","82.78"],["113.07","30.23"],["113.04","86.53"],["113.03","45.16"],["112.98","488.10"],["112.97","124.10"],["112.95","314.73"],["112.93","122.46"],["112.91","1735.61"],["112.88","71.82"],["112.85","2207.66"],["112.84","31.46"],["112.79","1930.16"],["112.73","2040.45"],["112.67","1996.33"],["112.61","1952.22"],["112.55","1863.98"],["112.49","1908.10"],["112.43","1709.57"],["112.37","1775.75"],["112.25","1974.27"],["112.19","1886.04"],["112.13","1753.69"],["112.07","1841.92"],["112.01","1797.80"],["111.66","0"],["111.61","44.63"],["111.07","0"],["111.02","97.81"],["110.47","0"],["110.43","40.49"],["109.88","0"],["109.84","85.27"],["109.29","0"],["109.25","84.73"],["108.70","0"],["108.66","59.74"],["108.11","0"],["108.07","61.13"],["107.52","0"],["107.48","33.01"],["106.93","0"],["106.89","56.85"],["106.34","0"],["106.30","24.34"],["105.75","0"],["105.71","1.74"],["105.16","0"],["105.12","57.94"],["104.57","0"],["104.53","58.21"],["103.98","0"],["103.94","46.12"],["103.39","0"],["103.35","52.32"],["102.80","0"],["102.76","45.29"],["102.21","0"],["102.17","22.94"],["101.62","0"],["101.58","36.02"],["101.03","0"],["100.99","38.02"],["100.44","0"],["100.40","53.60"],["99.85","0"],["99.26","0"],["98.67","0"],["98.08","0"],["97.49","0"],["96.90","0"],["96.31","0"],["95.72","0"],["95.13","0"],["94.54","0"],["93.95","0"],["93.36","0"],["92.77","0"],["92.18","0"]],"checksum":536679416,"ts":"1649290102538"}]}
1649290102.6185422: {"action":"snapshot","arg":{"instType":"mc","channel":"ticker","instId":"UNIUSDT"},"data":[{"instId":"UNIUSDT","last":"9.9720","bestAsk":"9.975","bestBid":"9.97","high24h":"10.4280","low24h":"9.9030","priceChangePercent":"-0.0398","capitalRate":"-0.000100","nextSettleTime":1649314800000,"systemTime":1649290102590,"markPrice":"9.9748","indexPrice":"9.9822","holding":"369411","baseVolume":"313111","quoteVolume":"3294724"}]}
1649290102.625118: {"action":"snapshot","arg":{"instType":"mc","channel":"ticker","instId":"DASHUSDT"},"data":[{"instId":"DASHUSDT","last":"113.340","bestAsk":"113.4","bestBid":"113.33","high24h":"118.870","low24h":"113.140","priceChangePercent":"-0.036","capitalRate":"-0.000100","nextSettleTime":1649314800000,"systemTime":1649290102598,"markPrice":"113.410","indexPrice":"113.402","holding":"21957.17","baseVolume":"25307.14","quoteVolume":"3062978.45"}]}
1649290102.65275: {"action":"update","arg":{"instType":"mc","channel":"books","instId":"UNIUSDT"},"data":[{"asks":[["9.974","0"],["9.975","0"],["9.976","0"],["9.977","80"],["9.978","171"],["9.979","126"],["9.980","150"],["9.981","311"],["9.982","740"],["9.983","479"],["9.984","201"],["9.985","669"],["9.986","256"],["9.987","400"],["9.988","602"],["9.989","296"],["9.990","1436"],["9.991","342"],["9.993","735"],["9.994","2449"],["9.995","721"],["9.996","711"],["9.997","1716"],["10.001","758"],["10.002","267"],["10.003","761"],["10.004","3752"],["10.006","999"],["10.007","362"],["10.011","4847"],["10.014","7275"],["10.016","915"],["10.017","7533"],["10.020","4471"],["10.022","284"],["10.023","1209"],["10.024","14051"],["10.025","1676"],["10.026","1773"],["10.027","0"],["10.029","12213"],["10.032","0"],["10.034","13174"],["10.037","0"],["10.039","11443"],["10.042","0"],["10.044","12405"],["10.047","0"],["10.049","11636"],["10.052","0"],["10.054","12597"],["10.057","0"],["10.059","12982"],["10.062","113"],["10.064","13366"],["10.067","0"],["10.069","13559"],["10.072","0"],["10.074","12789"],["10.077","0"],["10.079","11828"],["10.109","249"],["10.115","0"],["10.161","295"],["10.167","0"],["10.213","328"],["10.219","0"],["10.265","292"],["10.271","0"],["10.317","215"],["10.323","0"],["10.369","133"],["10.375","0"],["10.421","104"],["10.427","0"],["10.473","4"],["10.479","0"],["10.525","120"],["10.531","0"],["10.577","234"],["10.583","0"],["10.629","126"],["10.635","0"],["10.681","26"],["10.687","0"],["10.733","164"],["10.739","0"],["10.785","168"],["10.791","0"],["10.837","220"],["10.843","0"],["10.889","161"],["10.895","0"],["10.941","146"],["10.947","0"],["10.993","23"],["10.999","0"],["11.045","31"],["11.051","0"],["11.097","350"],["11.103","0"],["11.149","208"],["11.155","0"],["11.201","281"],["11.207","0"],["11.253","192"],["11.259","0"],["11.305","234"],["11.311","0"],["11.357","32"],["11.363","0"],["11.409","15"],["11.415","0"],["11.461","47"],["11.467","0"],["11.513","630"],["11.519","0"]],"bids":[["9.971","125"],["9.970","239"],["9.969","358"],["9.968","244"],["9.967","309"],["9.966","410"],["9.965","271"],["9.964","495"],["9.963","363"],["9.962","1766"],["9.961","1145"],["9.960","148"],["9.959","996"],["9.958","684"],["9.957","3045"],["9.955","618"],["9.954","217"],["9.953","598"],["9.952","715"],["9.951","290"],["9.950","348"],["9.949","863"],["9.948","1203"],["9.947","265"],["9.945","1977"],["9.942","870"],["9.941","1379"],["9.935","247"],["9.934","231"],["9.933","5914"],["9.932","665"],["9.925","8522"],["9.924","14161"],["9.921","0"],["9.920","0"],["9.919","11828"],["9.916","0"],["9.914","13174"],["9.911","0"],["9.909","11443"],["9.906","0"],["9.904","12020"],["9.901","0"],["9.899","12213"],["9.896","0"],["9.894","13559"],["9.891","0"],["9.889","12405"],["9.886","0"],["9.884","11636"],["9.881","0"],["9.879","12789"],["9.876","0"],["9.874","13366"],["9.871","0"],["9.869","12597"],["9.866","0"],["9.732","0"],["9.726","376"],["9.681","0"],["9.675","371"],["9.631","0"],["9.625","19"],["9.581","0"],["9.575","296"],["9.531","0"],["9.525","321"],["9.481","0"],["9.475","66"],["9.431","0"],["9.425","192"],["9.381","0"],["9.375","82"],["9.331","0"],["9.325","16"],["9.281","0"],["9.275","382"],["9.231","0"],["9.225","2"],["9.181","0"],["9.175","300"],["9.131","0"],["9.125","268"],["9.081","0"],["9.075","348"],["9.031","0"],["9.025","307"],["8.981","0"],["8.975","104"],["8.931","0"],["8.925","266"],["8.881","0"],["8.875","90"],["8.831","0"],["8.825","213"],["8.781","0"],["8.775","105"],["8.731","0"],["8.725","295"],["8.681","0"],["8.675","108"],["8.631","0"],["8.625","52"],["8.581","0"],["8.575","119"],["8.531","0"],["8.525","179"],["8.481","0"],["8.475","149"]],"checksum":-1099480873,"ts":"1649290102625"}]}
1649290102.882071: {"action":"snapshot","arg":{"instType":"mc","channel":"ticker","instId":"UNIUSDT"},"data":[{"instId":"UNIUSDT","last":"9.9720","bestAsk":"9.978","bestBid":"9.973","high24h":"10.4280","low24h":"9.9030","priceChangePercent":"-0.0398","capitalRate":"-0.000100","nextSettleTime":1649314800000,"systemTime":1649290102853,"markPrice":"9.9748","indexPrice":"9.9822","holding":"369411","baseVolume":"313111","quoteVolume":"3294724"}]}
1649290102.8961642: {"action":"update","arg":{"instType":"mc","channel":"books","instId":"DASHUSDT"},"data":[{"asks":[["113.40","0"],["113.41","0"],["113.42","0"],["113.43","1.86"],["113.44","1.97"],["113.45","16.39"],["113.46","4.33"],["113.47","69.09"],["113.48","6.42"],["113.50","26.03"],["113.51","27.12"],["113.52","34.70"],["113.53","52.98"],["113.54","48.08"],["113.55","1600.47"],["113.56","115.59"],["113.57","27.14"],["113.58","19.71"],["113.59","37.86"],["113.60","95.63"],["113.61","58.86"],["113.62","7.42"],["113.63","230.54"],["113.64","97.01"],["113.65","149.40"],["113.66","230.98"],["113.67","19.47"],["113.68","919.45"],["113.69","385.51"],["113.70","33.88"],["113.72","96.03"],["113.73","44.53"],["113.76","302.91"],["113.77","803.31"],["113.78","234.08"],["113.81","7.26"],["113.82","20.53"],["113.86","1762.66"],["113.88","0"],["113.89","5.55"],["113.92","2014.00"],["113.93","43.81"],["113.94","0"],["113.98","1797.80"],["114.00","0"],["114.04","2040.45"],["114.06","0"],["114.10","1863.98"],["114.12","0"],["114.16","1775.75"],["114.18","0"],["114.22","1731.63"],["114.24","0"],["114.28","1819.86"],["114.30","0"],["114.34","1996.33"],["114.36","0"],["114.40","1841.92"],["114.42","0"],["114.46","1709.57"],["114.48","0"],["114.52","1952.22"],["114.54","0"],["114.58","1886.04"],["114.60","0"],["114.64","1930.16"],["114.66","0"],["114.70","2018.39"],["114.72","0"],["114.76","1974.27"]],"bids":[["113.38","3.81"],["113.37","242.56"],["113.36","13.87"],["113.35","58.42"],["113.34","1.99"],["113.33","82.34"],["113.32","222.89"],["113.31","46.98"],["113.30","21.55"],["113.29","14.27"],["113.28","69.33"],["113.27","71.29"],["113.26","283.86"],["113.23","46.63"],["113.22","27.45"],["113.20","290.78"],["113.16","41.15"],["113.15","431.67"],["113.14","585.35"],["113.13","92.56"],["113.12","168.64"],["113.10","50.50"],["113.09","24.25"],["113.08","76.84"],["113.07","17.13"],["113.06","2.50"],["113.05","1519.82"],["113.04","96.43"],["113.03","46.56"],["113.02","73.64"],["113.01","29.11"],["112.99","21.14"],["112.98","608.28"],["112.95","3331.82"],["112.93","123.81"],["112.91","12.76"],["112.89","2005.92"],["112.88","0"],["112.87","0"],["112.86","0"],["112.85","0"],["112.84","0"],["112.83","1974.27"],["112.79","0"],["112.77","1819.86"],["112.73","0"],["112.71","1886.04"],["112.67","0"],["112.65","1775.75"],["112.61","0"],["112.59","1841.92"],["112.55","0"],["112.53","1908.10"],["112.49","0"],["112.47","1863.98"],["112.43","0"],["112.41","1753.69"],["112.37","0"],["112.35","1930.16"],["112.31","0"],["112.29","2040.45"],["112.25","0"],["112.23","1797.80"],["112.19","0"],["112.17","1952.22"],["112.13","0"],["112.11","2018.39"],["112.07","0"],["112.05","1709.57"],["112.01","0"]],"checksum":-274699988,"ts":"1649290102863"}]}
1649290102.896929: {"action":"snapshot","arg":{"instType":"mc","channel":"ticker","instId":"DASHUSDT"},"data":[{"instId":"DASHUSDT","last":"113.340","bestAsk":"113.42","bestBid":"113.37","high24h":"118.870","low24h":"113.140","priceChangePercent":"-0.036","capitalRate":"-0.000100","nextSettleTime":1649314800000,"systemTime":1649290102859,"markPrice":"113.410","indexPrice":"113.402","holding":"21957.17","baseVolume":"25307.14","quoteVolume":"3062978.45"}]}
1649290102.9791942: {"action":"update","arg":{"instType":"mc","channel":"books","instId":"UNIUSDT"},"data":[{"asks":[["9.977","0"],["9.978","0"],["9.979","48"],["9.980","21"],["9.981","196"],["9.982","1200"],["9.983","555"],["9.984","218"],["9.985","350"],["9.986","201"],["9.987","545"],["9.988","581"],["9.989","285"],["9.990","889"],["9.991","529"],["9.992","1141"],["9.993","718"],["9.994","2274"],["9.995","700"],["9.996","939"],["9.997","2415"],["9.998","284"],["9.999","1905"],["10.000","524"],["10.003","812"],["10.004","452"],["10.008","451"],["10.009","353"],["10.010","217"],["10.011","5346"],["10.013","1393"],["10.014","7344"],["10.022","256"],["10.024","3598"],["10.027","14101"],["10.028","264"],["10.029","0"],["10.032","11636"],["10.034","0"],["10.037","12982"],["10.039","0"],["10.042","11828"],["10.044","0"],["10.047","13174"],["10.049","0"],["10.052","12213"],["10.054","0"],["10.057","12020"],["10.059","0"],["10.062","13559"],["10.064","0"],["10.067","11443"],["10.069","0"],["10.072","12405"],["10.074","0"],["10.077","12597"],["10.079","0"],["10.082","13366"],["10.103","249"],["10.109","0"],["10.155","295"],["10.161","0"],["10.207","328"],["10.213","0"],["10.259","292"],["10.265","0"],["10.311","215"],["10.317","0"],["10.363","133"],["10.369","0"],["10.415","104"],["10.421","0"],["10.467","4"],["10.473","0"],["10.519","120"],["10.525","0"],["10.571","234"],["10.577","0"],["10.623","126"],["10.629","0"],["10.675","26"],["10.681","0"],["10.727","164"],["10.733","0"],["10.779","168"],["10.785","0"],["10.831","220"],["10.837","0"],["10.883","161"],["10.889","0"],["10.935","146"],["10.941","0"],["10.987","23"],["10.993","0"],["11.039","31"],["11.045","0"],["11.091","350"],["11.097","0"],["11.143","208"],["11.149","0"],["11.195","281"],["11.201","0"],["11.247","192"],["11.253","0"],["11.299","234"],["11.305","0"],["11.351","32"],["11.357","0"],["11.403","15"],["11.409","0"],["11.455","47"],["11.461","0"],["11.507","630"],["11.513","0"]],"bids":[["9.974","402"],["9.973","129"],["9.972","325"],["9.971","132"],["9.970","362"],["9.969","217"],["9.968","224"],["9.967","867"],["9.966","511"],["9.965","1119"],["9.964","602"],["9.963","314"],["9.962","2089"],["9.961","1136"],["9.960","180"],["9.959","623"],["9.958","709"],["9.957","3077"],["9.956","1111"],["9.955","633"],["9.954","247"],["9.953","737"],["9.952","586"],["9.951","483"],["9.950","324"],["9.948","1184"],["9.946","1175"],["9.945","1965"],["9.944","8006"],["9.943","1292"],["9.942","1135"],["9.940","559"],["9.939","2666"],["9.938","144"],["9.937","692"],["9.936","737"],["9.933","6011"],["9.929","263"],["9.926","12435"],["9.925","8655"],["9.924","0"],["9.923","0"],["9.922","0"],["9.921","13559"],["9.919","0"],["9.916","12597"],["9.914","0"],["9.911","11828"],["9.909","0"],["9.906","13174"],["9.904","0"],["9.901","11636"],["9.899","0"],["9.896","12982"],["9.894","0"],["9.891","12405"],["9.889","0"],["9.886","12213"],["9.884","0"],["9.881","13366"],["9.879","0"],["9.876","11443"],["9.874","0"],["9.871","12789"],["9.869","0"],["9.821","109"],["9.770","308"],["9.726","0"],["9.720","160"],["9.675","0"],["9.670","151"],["9.625","0"],["9.620","245"],["9.575","0"],["9.570","194"],["9.525","0"],["9.520","352"],["9.475","0"],["9.470","104"],["9.425","0"],["9.420","260"],["9.375","0"],["9.370","181"],["9.325","0"],["9.320","236"],["9.275","0"],["9.270","196"],["9.225","0"],["9.220","326"],["9.175","0"],["9.170","70"],["9.125","0"],["9.120","222"],["9.075","0"],["9.070","174"],["9.025","0"],["9.020","321"],["8.975","0"],["8.970","170"],["8.925","0"],["8.920","63"],["8.875","0"],["8.870","102"],["8.825","0"],["8.820","141"],["8.775","0"],["8.770","261"],["8.725","0"],["8.720","42"],["8.675","0"],["8.670","371"],["8.625","0"],["8.620","156"],["8.575","0"],["8.570","119"],["8.525","0"],["8.475","0"]],"checksum":1696653028,"ts":"1649290102948"}]}
1649290102.993949: {"action":"update","arg":{"instType":"mc","channel":"trade","instId":"UNIUSDT"},"data":[["1649290102878","9.977","3","buy"]]}
1649290103.1382: {"action":"snapshot","arg":{"instType":"mc","channel":"ticker","instId":"UNIUSDT"},"data":[{"instId":"UNIUSDT","last":"9.9720","bestAsk":"9.979","bestBid":"9.974","high24h":"10.4280","low24h":"9.9030","priceChangePercent":"-0.0398","capitalRate":"-0.000100","nextSettleTime":1649314800000,"systemTime":1649290103108,"markPrice":"9.9748","indexPrice":"9.9822","holding":"369411","baseVolume":"313111","quoteVolume":"3294724"}]}
1649290103.138303: {"action":"snapshot","arg":{"instType":"mc","channel":"ticker","instId":"DASHUSDT"},"data":[{"instId":"DASHUSDT","last":"113.340","bestAsk":"113.43","bestBid":"113.38","high24h":"118.870","low24h":"113.140","priceChangePercent":"-0.036","capitalRate":"-0.000100","nextSettleTime":1649314800000,"systemTime":1649290103109,"markPrice":"113.387","indexPrice":"113.402","holding":"21957.17","baseVolume":"25307.14","quoteVolume":"3062978.45"}]}
1649290103.1924832: {"action":"update","arg":{"instType":"mc","channel":"books","instId":"DASHUSDT"},"data":[{"asks":[["113.42","0.54"],["113.43","0.82"],["113.44","2.74"],["113.45","18.05"],["113.47","12.98"],["113.48","7.36"],["113.49","4.79"],["113.50","20.60"],["113.51","66.72"],["113.52","11.76"],["113.53","23.78"],["113.54","95.16"],["113.55","119.30"],["113.56","121.78"],["113.57","821.54"],["113.58","12.09"],["113.59","20.80"],["113.60","96.62"],["113.62","28.66"],["113.64","89.60"],["113.65","66.65"],["113.66","231.97"],["113.67","20.29"],["113.69","227.61"],["113.70","42.39"],["113.71","36.20"],["113.72","96.88"],["113.73","29.68"],["113.77","799.65"],["113.81","8.91"],["113.82","44.42"],["113.85","2081.95"],["113.86","8.98"],["113.87","42.05"],["113.91","1867.60"],["113.92","113.67"],["113.93","0"],["113.97","1974.27"],["113.98","0"],["114.03","1886.04"],["114.04","0"],["114.09","1908.10"],["114.10","0"],["114.15","1709.57"],["114.16","0"],["114.21","1775.75"],["114.22","0"],["114.27","2018.39"],["114.28","0"],["114.33","1753.69"],["114.34","0"],["114.39","1797.80"],["114.40","0"],["114.45","1841.92"],["114.46","0"],["114.51","1731.63"],["114.52","0"],["114.57","1996.33"],["114.58","0"],["114.63","1930.16"],["114.64","0"],["114.69","1952.22"],["114.70","0"],["114.75","2040.45"],["114.76","0"]],"bids":[["113.38","0"],["113.37","420.76"],["113.36","1.99"],["113.35","0"],["113.34","211.44"],["113.33","82.58"],["113.32","182.98"],["113.31","46.64"],["113.29","5.66"],["113.28","109.05"],["113.27","27.73"],["113.26","225.95"],["113.24","54.81"],["113.23","30.62"],["113.22","40.82"],["113.20","330.47"],["113.18","72.78"],["113.17","19.52"],["113.15","419.24"],["113.14","581.59"],["113.13","100.64"],["113.12","165.86"],["113.11","49.85"],["113.10","61.84"],["113.08","73.82"],["113.05","1534.67"],["113.04","9.64"],["113.03","40.60"],["112.98","631.34"],["112.96","186.64"],["112.95","1600.09"],["112.94","1776.63"],["112.93","122.68"],["112.89","10.19"],["112.88","1824.77"],["112.87","416.36"],["112.83","0"],["112.82","1996.33"],["112.77","0"],["112.76","1731.63"],["112.71","0"],["112.70","1930.16"],["112.65","0"],["112.64","1974.27"],["112.59","0"],["112.58","1886.04"],["112.53","0"],["112.52","1863.98"],["112.47","0"],["112.46","1819.86"],["112.41","0"],["112.40","2018.39"],["112.35","0"],["112.34","1841.92"],["112.29","0"],["112.28","1908.10"],["112.23","0"],["112.22","1797.80"],["112.17","0"],["112.16","2040.45"],["112.11","0"],["112.10","1952.22"],["112.05","0"],["112.04","1709.57"]],"checksum":-1614596567,"ts":"1649290103165"}]}
1649290103.31912: {"action":"update","arg":{"instType":"mc","channel":"books","instId":"UNIUSDT"},"data":[{"asks":[["9.980","42"],["9.982","1283"],["9.986","204"],["9.987","531"],["9.988","649"],["9.991","578"],["9.992","1159"],["9.993","1589"],["9.995","628"],["9.996","843"],["9.997","2465"],["9.998","421"],["9.999","1966"],["10.001","812"],["10.002","363"],["10.003","843"],["10.005","597"],["10.016","1552"],["10.017","7590"],["10.024","2048"],["10.027","13885"],["10.032","12020"],["10.037","11443"],["10.042","13559"],["10.047","12789"],["10.052","13174"],["10.057","12597"],["10.062","12405"],["10.067","11636"],["10.072","11828"],["10.077","13366"],["10.082","12213"],["10.096","249"],["10.103","0"],["10.148","295"],["10.155","0"],["10.200","328"],["10.207","0"],["10.252","292"],["10.259","0"],["10.304","215"],["10.311","0"],["10.356","133"],["10.363","0"],["10.408","104"],["10.415","0"],["10.460","4"],["10.467","0"],["10.512","120"],["10.519","0"],["10.564","234"],["10.571","0"],["10.616","126"],["10.623","0"],["10.668","26"],["10.675","0"],["10.720","164"],["10.727","0"],["10.772","168"],["10.779","0"],["10.824","220"],["10.831","0"],["10.876","161"],["10.883","0"],["10.928","146"],["10.935","0"],["10.980","23"],["10.987","0"],["11.032","31"],["11.039","0"],["11.084","350"],["11.091","0"],["11.136","208"],["11.143","0"],["11.188","281"],["11.195","0"],["11.240","192"],["11.247","0"],["11.292","234"],["11.299","0"],["11.344","32"],["11.351","0"],["11.396","15"],["11.403","0"],["11.448","47"],["11.455","0"],["11.500","630"],["11.507","0"]],"bids":[["9.973","131"],["9.971","233"],["9.970","298"],["9.969","283"],["9.968","177"],["9.967","693"],["9.966","412"],["9.964","604"],["9.963","313"],["9.962","2155"],["9.961","1177"],["9.958","684"],["9.956","449"],["9.952","639"],["9.951","433"],["9.948","1263"],["9.946","1081"],["9.944","7956"],["9.939","2633"],["9.934","259"],["9.930","2225"],["9.926","13204"],["9.921","12597"],["9.916","11828"],["9.911","11443"],["9.906","11636"],["9.901","12213"],["9.886","13174"],["9.881","13559"],["9.876","12020"],["9.871","13366"],["9.821","0"],["9.814","109"],["9.770","0"],["9.763","308"],["9.720","0"],["9.713","160"],["9.670","0"],["9.663","151"],["9.620","0"],["9.613","245"],["9.570","0"],["9.563","194"],["9.520","0"],["9.513","352"],["9.470","0"],["9.463","104"],["9.420","0"],["9.413","260"],["9.370","0"],["9.363","181"],["9.320","0"],["9.313","236"],["9.270","0"],["9.263","196"],["9.220","0"],["9.213","326"],["9.170","0"],["9.163","70"],["9.120","0"],["9.113","222"],["9.070","0"],["9.063","174"],["9.020","0"],["9.013","321"],["8.970","0"],["8.963","170"],["8.920","0"],["8.913","63"],["8.870","0"],["8.863","102"],["8.820","0"],["8.813","141"],["8.770","0"],["8.763","261"],["8.720","0"],["8.713","42"],["8.670","0"],["8.663","371"],["8.620","0"],["8.613","156"],["8.570","0"],["8.563","111"]],"checksum":644853112,"ts":"1649290103289"}]}
1649290103.389071: {"action":"snapshot","arg":{"instType":"mc","channel":"ticker","instId":"UNIUSDT"},"data":[{"instId":"UNIUSDT","last":"9.9770","bestAsk":"9.979","bestBid":"9.974","high24h":"10.4280","low24h":"9.9030","priceChangePercent":"-0.0398","capitalRate":"-0.000100","nextSettleTime":1649314800000,"systemTime":1649290103359,"markPrice":"9.9748","indexPrice":"9.9814","holding":"369411","baseVolume":"313111","quoteVolume":"3294724"}]}
1649290103.403244: {"action":"snapshot","arg":{"instType":"mc","channel":"ticker","instId":"DASHUSDT"},"data":[{"instId":"DASHUSDT","last":"113.340","bestAsk":"113.43","bestBid":"113.38","high24h":"118.870","low24h":"113.140","priceChangePercent":"-0.036","capitalRate":"-0.000100","nextSettleTime":1649314800000,"systemTime":1649290103369,"markPrice":"113.387","indexPrice":"113.402","holding":"21957.17","baseVolume":"25307.14","quoteVolume":"3062978.45"}]}
1649290103.5051699: {"action":"update","arg":{"instType":"mc","channel":"books","instId":"DASHUSDT"},"data":[{"asks":[["113.42","0"],["113.43","0"],["113.46","7.62"],["113.47","16.72"],["113.51","38.20"],["113.52","56.89"],["113.54","50.06"],["113.55","97.52"],["113.56","55.22"],["113.57","34.29"],["113.58","14.28"],["113.59","54.21"],["113.60","86.54"],["113.61","26.40"],["113.62","904.16"],["113.63","277.56"],["113.65","126.70"],["113.66","30.67"],["113.67","26.01"],["113.68","636.80"],["113.69","36.04"],["113.70","62.78"],["113.71","34.71"],["113.72","252.31"],["113.73","171.25"],["113.74","158.84"],["113.75","29.66"],["113.76","243.51"],["113.77","795.03"],["113.81","21.78"],["113.85","264.57"],["113.86","53.53"],["113.87","2023.84"],["113.88","18.82"],["113.91","3.63"],["113.92","109.89"],["113.93","1832.19"],["113.97","0"],["113.99","1974.27"],["114.03","0"],["114.05","1753.69"],["114.09","0"],["114.11","1886.04"],["114.15","0"],["114.17","1709.57"],["114.21","0"],["114.23","1996.33"],["114.27","0"],["114.29","1819.86"],["114.33","0"],["114.35","1731.63"],["114.39","0"],["114.41","2018.39"],["114.45","0"],["114.47","1908.10"],["114.51","0"],["114.53","1863.98"],["114.57","0"],["114.59","1930.16"],["114.63","0"],["114.65","1841.92"],["114.69","0"],["114.71","2040.45"],["114.75","0"],["114.77","1775.75"]],"bids":[["113.38","3.81"],["113.34","5.95"],["113.33","84.35"],["113.32","15.14"],["113.31","118.82"],["113.30","1600.42"],["113.29","11.87"],["113.28","75.80"],["113.26","259.61"],["113.25","26.98"],["113.24","274.09"],["113.23","32.35"],["113.22","23.99"],["113.20","331.96"],["113.18","76.33"],["113.17","18.03"],["113.16","51.61"],["113.15","199.96"],["113.14","803.85"],["113.12","7.95"],["113.10","28.84"],["113.05","1519.82"],["113.03","38.82"],["112.98","608.76"],["112.96","225.75"],["112.95","3552.30"],["112.94","0.89"],["112.93","100.38"],["112.89","1896.22"],["112.88","48.80"],["112.87","0"],["112.83","1797.80"],["112.82","0"],["112.77","1753.69"],["112.76","0"],["112.71","1974.27"],["112.70","0"],["112.65","1731.63"],["112.64","0"],["112.59","1841.92"],["112.58","0"],["112.53","1930.16"],["112.52","0"],["112.47","2018.39"],["112.46","0"],["112.41","1908.10"],["112.40","0"],["112.35","1863.98"],["112.34","0"],["112.29","2040.45"],["112.28","0"],["112.23","1819.86"],["112.22","0"],["112.17","1996.33"],["112.16","0"],["112.11","1775.75"],["112.10","0"],["112.05","1709.57"],["112.04","0"]],"checksum":-817847831,"ts":"1649290103468"}]}
1649290103.6187851: {"action":"update","arg":{"instType":"mc","channel":"candle1m","instId":"UNIUSDT"},"data":[["1649290080000","9.977","9.986","9.972","9.977","41"]]}
1649290103.630316: {"action":"update","arg":{"instType":"mc","channel":"books","instId":"UNIUSDT"},"data":[{"asks":[["9.982","1308"],["9.983","361"],["9.984","265"],["9.985","323"],["9.986","185"],["9.988","564"],["9.989","656"],["9.991","430"],["10.008","3804"],["10.013","3259"],["10.027","13308"],["10.032","13174"],["10.037","12597"],["10.042","13366"],["10.047","13559"],["10.052","11636"],["10.057","11443"],["10.062","12789"],["10.067","12982"],["10.072","12020"],["10.077","12213"],["10.082","11828"],["10.089","249"],["10.096","0"],["10.141","295"],["10.148","0"],["10.193","328"],["10.200","0"],["10.245","292"],["10.252","0"],["10.297","215"],["10.304","0"],["10.349","133"],["10.356","0"],["10.401","104"],["10.408","0"],["10.453","4"],["10.460","0"],["10.505","120"],["10.512","0"],["10.557","234"],["10.564","0"],["10.609","126"],["10.616","0"],["10.661","26"],["10.668","0"],["10.713","164"],["10.720","0"],["10.765","168"],["10.772","0"],["10.817","220"],["10.824","0"],["10.869","161"],["10.876","0"],["10.921","146"],["10.928","0"],["10.973","23"],["10.980","0"],["11.025","31"],["11.032","0"],["11.077","350"],["11.084","0"],["11.129","208"],["11.136","0"],["11.181","281"],["11.188","0"],["11.233","192"],["11.240","0"],["11.285","234"],["11.292","0"],["11.337","32"],["11.344","0"],["11.389","15"],["11.396","0"],["11.441","47"],["11.448","0"],["11.493","630"],["11.500","0"]],"bids":[["9.974","233"],["9.972","370"],["9.971","328"],["9.970","309"],["9.969","285"],["9.968","77"],["9.967","663"],["9.966","391"],["9.965","773"],["9.962","2146"],["9.961","1138"],["9.956","543"],["9.955","671"],["9.951","359"],["9.948","1050"],["9.945","2180"],["9.939","2368"],["9.926","12051"],["9.921","12789"],["9.916","12982"],["9.911","13174"],["9.906","12405"],["9.901","12597"],["9.896","12213"],["9.891","13366"],["9.886","11828"],["9.876","11443"],["9.871","12020"],["9.814","0"],["9.807","109"],["9.763","0"],["9.756","308"],["9.713","0"],["9.706","160"],["9.663","0"],["9.656","151"],["9.613","0"],["9.606","245"],["9.563","0"],["9.556","194"],["9.513","0"],["9.506","352"],["9.463","0"],["9.456","104"],["9.413","0"],["9.406","260"],["9.363","0"],["9.356","181"],["9.313","0"],["9.306","236"],["9.263","0"],["9.256","196"],["9.213","0"],["9.206","326"],["9.163","0"],["9.156","70"],["9.113","0"],["9.106","222"],["9.063","0"],["9.056","174"],["9.013","0"],["9.006","321"],["8.963","0"],["8.956","170"],["8.913","0"],["8.906","63"],["8.863","0"],["8.856","102"],["8.813","0"],["8.806","141"],["8.763","0"],["8.756","261"],["8.713","0"],["8.706","42"],["8.663","0"],["8.656","371"],["8.613","0"],["8.606","156"],["8.563","0"],["8.556","111"]],"checksum":632802953,"ts":"1649290103597"}]}
1649290103.668006: {"action":"snapshot","arg":{"instType":"mc","channel":"ticker","instId":"UNIUSDT"},"data":[{"instId":"UNIUSDT","last":"9.9770","bestAsk":"9.979","bestBid":"9.974","high24h":"10.4280","low24h":"9.9030","priceChangePercent":"-0.0393","capitalRate":"-0.000100","nextSettleTime":1649314800000,"systemTime":1649290103631,"markPrice":"9.9745","indexPrice":"9.9814","holding":"369411","baseVolume":"313114","quoteVolume":"3294754"}]}
1649290103.6776562: {"action":"snapshot","arg":{"instType":"mc","channel":"ticker","instId":"DASHUSDT"},"data":[{"instId":"DASHUSDT","last":"113.340","bestAsk":"113.43","bestBid":"113.38","high24h":"118.870","low24h":"113.140","priceChangePercent":"-0.036","capitalRate":"-0.000100","nextSettleTime":1649314800000,"systemTime":1649290103639,"markPrice":"113.387","indexPrice":"113.432","holding":"21957.17","baseVolume":"25307.14","quoteVolume":"3062978.45"}]}
1649290103.79852: {"action":"update","arg":{"instType":"mc","channel":"books","instId":"DASHUSDT"},"data":[{"asks":[["113.42","0.16"],["113.43","2.39"],["113.47","14.84"],["113.53","24.33"],["113.56","55.06"],["113.85","2062.36"],["113.87","71.63"],["113.91","1845.54"],["113.92","0"],["113.93","0"],["113.97","1731.63"],["113.99","0"],["114.03","1996.33"],["114.05","0"],["114.09","1952.22"],["114.11","0"],["114.15","2040.45"],["114.17","0"],["114.21","1908.10"],["114.23","0"],["114.27","1863.98"],["114.29","0"],["114.33","2018.39"],["114.35","0"],["114.39","1886.04"],["114.41","0"],["114.45","1775.75"],["114.47","0"],["114.51","1930.16"],["114.53","0"],["114.57","1974.27"],["114.59","0"],["114.63","1709.57"],["114.65","0"],["114.69","1819.86"],["114.71","0"],["114.75","1753.69"],["114.77","0"],["115.78","0.73"],["116.00","0"],["116.37","68.26"],["116.59","0"],["116.96","70.90"],["117.18","0"],["117.55","49.89"],["117.77","0"],["118.14","22.59"],["118.36","0"],["118.73","47.85"],["118.95","0"],["119.32","46.71"],["119.54","0"],["119.91","23.57"],["120.13","0"],["120.50","59.15"],["120.72","0"],["121.09","6.51"],["121.31","0"],["121.68","54.25"],["121.90","0"],["122.27","14.99"],["122.49","0"],["122.86","11.21"],["123.08","0"],["123.45","66.50"],["123.67","0"],["124.04","64.47"],["124.26","0"],["124.63","42.85"],["124.85","0"],["125.22","29.99"],["125.44","0"],["125.81","4.07"],["126.03","0"],["126.40","26.70"],["126.62","0"],["126.99","20.67"],["127.21","0"],["127.58","56.99"],["127.80","0"],["128.17","44.01"],["128.39","0"],["128.76","46.60"],["128.98","0"],["129.35","39.07"],["129.57","0"],["129.94","19.33"],["130.16","0"],["130.53","20.66"],["130.75","0"],["131.12","28.11"],["131.34","0"],["131.71","13.65"],["131.93","0"],["132.52","0"],["133.11","0"],["133.70","0"]],"bids":[["113.38","0"],["113.33","66.24"],["113.32","15.42"],["113.31","118.26"],["113.30","1600.10"],["113.27","14.94"],["113.20","275.05"],["113.18","71.68"],["112.95","1600.32"],["112.94","1798.68"],["112.89","10.19"],["112.88","2067.18"],["112.87","416.36"],["112.83","0"],["112.82","1775.75"],["112.77","0"],["112.76","2040.45"],["112.71","0"],["112.70","1841.92"],["112.65","0"],["112.64","1930.16"],["112.59","0"],["112.58","1996.33"],["112.53","0"],["112.52","1908.10"],["112.47","0"],["112.46","1974.27"],["112.41","0"],["112.40","1709.57"],["112.35","0"],["112.34","1819.86"],["112.29","0"],["112.28","1753.69"],["112.23","0"],["112.22","1863.98"],["112.17","0"],["112.16","1886.04"],["112.11","0"],["112.10","1731.63"],["112.05","0"],["112.04","1952.22"],["111.66","54.98"],["111.61","0"],["111.07","56.15"],["111.02","0"],["110.47","22.20"],["110.43","0"],["109.88","45.95"],["109.84","0"],["109.29","29.62"],["109.25","0"],["108.70","21.93"],["108.66","0"],["108.11","6.02"],["108.07","0"],["107.52","55.97"],["107.48","0"],["106.93","21.31"],["106.89","0"],["106.34","8.95"],["106.30","0"],["105.75","10.15"],["105.71","0"],["105.16","40.07"],["105.12","0"],["104.57","15.36"],["104.53","0"],["103.98","46.47"],["103.94","0"],["103.39","11.11"],["103.35","0"],["102.80","1.87"],["102.76","0"],["102.21","37.67"],["102.17","0"],["101.62","21.48"],["101.58","0"],["101.03","49.80"],["100.99","0"],["100.44","49.32"],["100.40","0"],["99.85","42.14"],["99.26","8.55"],["98.67","30.36"],["98.08","20.32"],["97.49","36.65"],["96.90","21.95"],["96.31","8.41"],["95.72","31.49"],["95.13","57.35"],["94.54","3.45"],["93.95","4.85"],["93.36","74.35"],["92.77","33.85"],["92.18","20.24"]],"checksum":1531921801,"ts":"1649290103769"}]}
1649290103.925185: {"action":"snapshot","arg":{"instType":"mc","channel":"ticker","instId":"UNIUSDT"},"data":[{"instId":"UNIUSDT","last":"9.9770","bestAsk":"9.98","bestBid":"9.974","high24h":"10.4280","low24h":"9.9030","priceChangePercent":"-0.0393","capitalRate":"-0.000100","nextSettleTime":1649314800000,"systemTime":1649290103894,"markPrice":"9.9745","indexPrice":"9.9814","holding":"369411","baseVolume":"313114","quoteVolume":"3294754"}]}
1649290103.925282: {"action":"update","arg":{"instType":"mc","channel":"books","instId":"UNIUSDT"},"data":[{"asks":[["9.979","0"],["9.980","23"],["9.981","241"],["9.982","1235"],["9.983","932"],["9.984","388"],["9.985","417"],["9.987","730"],["9.989","702"],["9.990","919"],["9.992","1137"],["9.996","707"],["9.999","1736"],["10.003","856"],["10.006","1075"],["10.010","279"],["10.013","2445"],["10.029","5648"],["10.032","12982"],["10.037","13366"],["10.042","12213"],["10.047","13174"],["10.052","13559"],["10.057","12020"],["10.062","11636"],["10.067","11443"],["10.072","12789"],["10.077","11828"],["10.082","12597"],["10.083","249"],["10.089","0"],["10.135","295"],["10.141","0"],["10.187","328"],["10.193","0"],["10.239","292"],["10.245","0"],["10.291","215"],["10.297","0"],["10.343","133"],["10.349","0"],["10.395","104"],["10.401","0"],["10.447","4"],["10.453","0"],["10.499","120"],["10.505","0"],["10.551","234"],["10.557","0"],["10.603","126"],["10.609","0"],["10.655","26"],["10.661","0"],["10.707","164"],["10.713","0"],["10.759","168"],["10.765","0"],["10.811","220"],["10.817","0"],["10.863","161"],["10.869","0"],["10.915","146"],["10.921","0"],["10.967","23"],["10.973","0"],["11.019","31"],["11.025","0"],["11.071","350"],["11.077","0"],["11.123","208"],["11.129","0"],["11.175","281"],["11.181","0"],["11.227","192"],["11.233","0"],["11.279","234"],["11.285","0"],["11.331","32"],["11.337","0"],["11.383","15"],["11.389","0"],["11.435","47"],["11.441","0"],["11.487","630"],["11.493","0"]],"bids":[["9.967","415"],["9.966","416"],["9.965","814"],["9.963","337"],["9.962","1571"],["9.961","531"],["9.958","698"],["9.956","556"],["9.954","339"],["9.953","724"],["9.952","678"],["9.951","365"],["9.948","1080"],["9.946","1133"],["9.944","8080"],["9.939","2299"],["9.927","17301"],["9.926","416"],["9.922","12405"],["9.921","0"],["9.917","12789"],["9.916","0"],["9.912","11443"],["9.911","0"],["9.907","12597"],["9.906","0"],["9.902","13559"],["9.901","0"],["9.897","13366"],["9.896","0"],["9.892","12020"],["9.891","0"],["9.887","11636"],["9.886","0"],["9.882","12982"],["9.881","0"],["9.877","11828"],["9.876","0"],["9.872","12213"],["9.871","0"],["9.807","0"],["9.801","109"],["9.756","0"],["9.750","308"],["9.706","0"],["9.700","160"],["9.656","0"],["9.650","151"],["9.606","0"],["9.600","245"],["9.556","0"],["9.550","194"],["9.506","0"],["9.500","352"],["9.456","0"],["9.450","104"],["9.406","0"],["9.400","260"],["9.356","0"],["9.350","181"],["9.306","0"],["9.300","236"],["9.256","0"],["9.250","196"],["9.206","0"],["9.200","326"],["9.156","0"],["9.150","70"],["9.106","0"],["9.100","222"],["9.056","0"],["9.050","174"],["9.006","0"],["9.000","321"],["8.956","0"],["8.950","170"],["8.906","0"],["8.900","63"],["8.856","0"],["8.850","102"],["8.806","0"],["8.800","141"],["8.756","0"],["8.750","261"],["8.706","0"],["8.700","42"],["8.656","0"],["8.650","371"],["8.606","0"],["8.600","156"],["8.556","0"],["8.550","111"]],"checksum":1882370656,"ts":"1649290103897"}]}
1649290103.93881: {"action":"snapshot","arg":{"instType":"mc","channel":"ticker","instId":"DASHUSDT"},"data":[{"instId":"DASHUSDT","last":"113.340","bestAsk":"113.42","bestBid":"113.37","high24h":"118.870","low24h":"113.140","priceChangePercent":"-0.036","capitalRate":"-0.000100","nextSettleTime":1649314800000,"systemTime":1649290103904,"markPrice":"113.390","indexPrice":"113.402","holding":"21957.17","baseVolume":"25307.14","quoteVolume":"3062978.45"}]}
1649290104.1038542: {"action":"update","arg":{"instType":"mc","channel":"books","instId":"DASHUSDT"},"data":[{"asks":[["113.42","2.65"],["113.43","7.33"],["113.44","6.34"],["113.45","20.76"],["113.46","4.33"],["113.51","27.12"],["113.54","95.16"],["113.56","84.43"],["113.57","36.33"],["113.59","102.97"],["113.60","160.00"],["113.62","818.68"],["113.65","66.65"],["113.66","37.19"],["113.68","672.94"],["113.72","195.93"],["113.76","366.27"],["113.82","43.08"],["113.91","1735.25"],["113.97","1841.92"],["114.03","1886.04"],["114.09","1974.27"],["114.15","1908.10"],["114.21","1753.69"],["114.27","1775.75"],["114.33","1952.22"],["114.39","2018.39"],["114.45","1930.16"],["114.51","1863.98"],["114.57","1709.57"],["114.63","1996.33"],["114.69","2040.45"],["114.75","1819.86"],["115.78","0"],["116.00","31.47"],["116.37","0"],["116.59","50.46"],["116.96","0"],["117.18","49.40"],["117.55","0"],["117.77","27.41"],["118.14","0"],["118.36","50.42"],["118.73","0"],["118.95","50.07"],["119.32","0"],["119.54","36.12"],["119.91","0"],["120.13","8.62"],["120.50","0"],["120.72","54.60"],["121.09","0"],["121.31","1.48"],["121.68","0"],["121.90","43.49"],["122.27","0"],["122.49","7.73"],["122.86","0"],["123.08","58.21"],["123.45","0"],["123.67","52.67"],["124.04","0"],["124.26","53.84"],["124.63","0"],["124.85","4.99"],["125.22","0"],["125.44","44.04"],["125.81","0"],["126.03","25.10"],["126.40","0"],["126.62","39.09"],["126.99","0"],["127.21","44.51"],["127.58","0"],["127.80","19.01"],["128.17","0"],["128.39","29.39"],["128.76","0"],["128.98","3.89"],["129.35","0"],["129.57","23.37"],["129.94","0"],["130.16","24.18"],["130.53","0"],["130.75","9.15"],["131.12","0"],["131.34","27.04"],["131.71","0"],["131.93","7.10"],["132.52","13.38"],["133.11","33.57"],["133.70","76.51"]],"bids":[["113.33","68.52"],["113.32","13.91"],["113.31","48.30"],["113.27","17.72"],["113.26","258.12"],["113.24","275.58"],["113.23","41.73"],["113.21","26.61"],["113.20","285.99"],["113.18","74.60"],["113.16","64.42"],["113.13","109.04"],["113.12","16.86"],["113.11","23.61"],["113.09","15.34"],["113.08","68.87"],["113.07","9.50"],["113.05","1138.56"],["113.03","46.76"],["112.98","631.29"],["112.94","1754.57"],["112.88","1758.36"],["112.82","1841.92"],["112.76","1775.75"],["112.70","1797.80"],["112.58","1974.27"],["112.46","1886.04"],["112.40","1863.98"],["112.28","1731.63"],["112.22","1952.22"],["112.16","1996.33"],["112.10","2040.45"],["112.04","2018.39"],["111.66","0"],["111.61","44.63"],["111.07","0"],["111.02","97.81"],["110.47","0"],["110.43","40.49"],["109.88","0"],["109.84","85.27"],["109.29","0"],["109.25","84.73"],["108.70","0"],["108.66","59.74"],["108.11","0"],["108.07","61.13"],["107.52","0"],["107.48","33.01"],["106.93","0"],["106.89","56.85"],["106.34","0"],["106.30","24.34"],["105.75","0"],["105.71","1.74"],["105.16","0"],["105.12","57.94"],["104.57","0"],["104.53","58.21"],["103.98","0"],["103.94","46.12"],["103.39","0"],["103.35","52.32"],["102.80","0"],["102.76","45.29"],["102.21","0"],["102.17","22.94"],["101.62","0"],["101.58","36.02"],["101.03","0"],["100.99","38.02"],["100.44","0"],["100.40","53.60"],["99.85","0"],["99.26","0"],["98.67","0"],["98.08","0"],["97.49","0"],["96.90","0"],["96.31","0"],["95.72","0"],["95.13","0"],["94.54","0"],["93.95","0"],["93.36","0"],["92.77","0"],["92.18","0"]],"checksum":-814058450,"ts":"1649290104074"}]}
1649290104.1908622: {"action":"snapshot","arg":{"instType":"mc","channel":"ticker","instId":"UNIUSDT"},"data":[{"instId":"UNIUSDT","last":"9.9770","bestAsk":"9.98","bestBid":"9.974","high24h":"10.4280","low24h":"9.9030","priceChangePercent":"-0.0393","capitalRate":"-0.000100","nextSettleTime":1649314800000,"systemTime":1649290104151,"markPrice":"9.9745","indexPrice":"9.9814","holding":"369411","baseVolume":"313114","quoteVolume":"3294754"}]}
1649290104.190922: {"action":"snapshot","arg":{"instType":"mc","channel":"ticker","instId":"DASHUSDT"},"data":[{"instId":"DASHUSDT","last":"113.340","bestAsk":"113.42","bestBid":"113.37","high24h":"118.870","low24h":"113.140","priceChangePercent":"-0.036","capitalRate":"-0.000100","nextSettleTime":1649314800000,"systemTime":1649290104153,"markPrice":"113.390","indexPrice":"113.402","holding":"21957.17","baseVolume":"25307.14","quoteVolume":"3062978.45"}]}
1649290104.260532: {"action":"update","arg":{"instType":"mc","channel":"books","instId":"UNIUSDT"},"data":[{"asks":[["9.979","16"],["9.980","133"],["9.982","1308"],["9.983","433"],["9.984","450"],["9.986","106"],["9.987","822"],["9.988","678"],["9.989","679"],["9.993","1596"],["9.999","1306"],["10.002","953"],["10.008","3598"],["10.027","12731"],["10.029","0"],["10.037","12597"],["10.042","13559"],["10.047","11636"],["10.052","12213"],["10.057","12789"],["10.062","11443"],["10.067","13174"],["10.072","13366"],["10.077","12020"],["10.082","12405"],["10.083","0"],["10.129","60"],["10.135","0"],["10.181","174"],["10.187","0"],["10.233","366"],["10.239","0"],["10.285","361"],["10.291","0"],["10.337","240"],["10.343","0"],["10.389","123"],["10.395","0"],["10.441","268"],["10.447","0"],["10.493","79"],["10.499","0"],["10.545","164"],["10.551","0"],["10.597","327"],["10.603","0"],["10.649","205"],["10.655","0"],["10.701","204"],["10.707","0"],["10.753","24"],["10.759","0"],["10.805","134"],["10.811","0"],["10.857","170"],["10.863","0"],["10.909","84"],["10.915","0"],["10.961","94"],["10.967","0"],["11.013","41"],["11.019","0"],["11.065","221"],["11.071","0"],["11.117","421"],["11.123","0"],["11.169","28"],["11.175","0"],["11.221","103"],["11.227","0"],["11.273","180"],["11.279","0"],["11.325","312"],["11.331","0"],["11.377","123"],["11.383","0"],["11.429","186"],["11.435","0"],["11.481","335"],["11.487","0"]],"bids":[["9.970","191"],["9.967","378"],["9.964","630"],["9.963","313"],["9.951","1462"],["9.950","466"],["9.927","4128"],["9.926","13781"],["9.922","0"],["9.921","12789"],["9.917","0"],["9.916","11443"],["9.912","0"],["9.911","12405"],["9.907","0"],["9.906","12597"],["9.902","0"],["9.901","13174"],["9.897","0"],["9.896","11828"],["9.892","0"],["9.891","13559"],["9.887","0"],["9.886","11636"],["9.882","0"],["9.881","12982"],["9.877","0"],["9.876","12213"],["9.872","0"],["9.871","12020"],["9.801","0"],["9.795","109"],["9.750","0"],["9.744","308"],["9.700","0"],["9.694","160"],["9.650","0"],["9.644","151"],["9.600","0"],["9.594","245"],["9.550","0"],["9.544","194"],["9.500","0"],["9.494","352"],["9.450","0"],["9.444","104"],["9.400","0"],["9.394","260"],["9.350","0"],["9.344","181"],["9.300","0"],["9.294","236"],["9.250","0"],["9.244","196"],["9.200","0"],["9.194","326"],["9.150","0"],["9.144","70"],["9.100","0"],["9.094","222"],["9.050","0"],["9.044","174"],["9.000","0"],["8.994","321"],["8.950","0"],["8.944","170"],["8.900","0"],["8.894","63"],["8.850","0"],["8.844","102"],["8.800","0"],["8.794","141"],["8.750","0"],["8.744","261"],["8.700","0"],["8.694","42"],["8.650","0"],["8.644","371"],["8.600","0"],["8.594","156"],["8.550","0"],["8.544","111"]],"checksum":-1418036403,"ts":"1649290104230"}]}
1649290104.414774: {"action":"update","arg":{"instType":"mc","channel":"books","instId":"DASHUSDT"},"data":[{"asks":[["113.41","1.45"],["113.42","5.53"],["113.43","2.16"],["113.48","4.97"],["113.49","2.52"],["113.50","16.64"],["113.51","43.45"],["113.53","28.09"],["113.54","51.05"],["113.55","88.61"],["113.57","50.26"],["113.59","20.80"],["113.60","154.32"],["113.62","817.24"],["113.67","28.98"],["113.69","31.59"],["113.74","163.29"],["113.77","785.13"],["113.80","212.45"],["113.83","1860.43"],["113.85","254.67"],["113.86","49.08"],["113.89","1825.40"],["113.90","1600.26"],["113.91","0"],["113.95","1753.69"],["113.97","0"],["114.01","1996.33"],["114.03","0"],["114.07","1797.80"],["114.09","0"],["114.13","2040.45"],["114.15","0"],["114.19","1908.10"],["114.21","0"],["114.25","1952.22"],["114.27","0"],["114.31","1886.04"],["114.33","0"],["114.37","2018.39"],["114.39","0"],["114.43","1731.63"],["114.45","0"],["114.49","1775.75"],["114.51","0"],["114.55","1930.16"],["114.57","0"],["114.61","1974.27"],["114.63","0"],["114.67","1863.98"],["114.69","0"],["114.73","1709.57"],["114.75","0"],["115.78","0.73"],["116.00","0"],["116.37","68.26"],["116.59","0"],["116.96","70.90"],["117.18","0"],["117.55","49.89"],["117.77","0"],["118.14","22.59"],["118.36","0"],["118.73","47.85"],["118.95","0"],["119.32","46.71"],["119.54","0"],["119.91","23.57"],["120.13","0"],["120.50","59.15"],["120.72","0"],["121.09","6.51"],["121.31","0"],["121.68","54.25"],["121.90","0"],["122.27","14.99"],["122.49","0"],["122.86","11.21"],["123.08","0"],["123.45","66.50"],["123.67","0"],["124.04","64.47"],["124.26","0"],["124.63","42.85"],["124.85","0"],["125.22","29.99"],["125.44","0"],["125.81","4.07"],["126.03","0"],["126.40","26.70"],["126.62","0"],["126.99","20.67"],["127.21","0"],["127.58","56.99"],["127.80","0"],["128.17","44.01"],["128.39","0"],["128.76","46.60"],["128.98","0"],["129.35","39.07"],["129.57","0"],["129.94","19.33"],["130.16","0"],["130.53","20.66"],["130.75","0"],["131.12","28.11"],["131.34","0"],["131.71","13.65"],["131.93","0"],["132.52","0"],["133.11","0"],["133.70","0"]],"bids":[["113.37","0"],["113.36","0"],["113.34","338.59"],["113.33","87.68"],["113.32","0"],["113.31","218.80"],["113.27","14.94"],["113.26","254.44"],["113.24","273.60"],["113.23","38.92"],["113.21","48.27"],["113.20","203.25"],["113.18","72.00"],["113.17","25.12"],["113.16","19.75"],["113.12","103.98"],["113.10","10.69"],["113.09","30.19"],["113.03","44.50"],["113.00","1600.37"],["112.95","356.92"],["112.94","0.89"],["112.92","2042.22"],["112.91","3.99"],["112.88","48.80"],["112.86","1716.42"],["112.85","128.07"],["112.84","36.82"],["112.82","0"],["112.80","1775.75"],["112.76","0"],["112.74","1974.27"],["112.70","0"],["112.68","2040.45"],["112.64","0"],["112.62","1731.63"],["112.58","0"],["112.56","1930.16"],["112.52","0"],["112.50","1908.10"],["112.46","0"],["112.44","1797.80"],["112.40","0"],["112.38","1753.69"],["112.34","0"],["112.32","1841.92"],["112.28","0"],["112.26","1952.22"],["112.22","0"],["112.20","2018.39"],["112.16","0"],["112.14","1819.86"],["112.10","0"],["112.08","1886.04"],["112.04","0"],["112.02","1863.98"],["111.66","54.98"],["111.61","0"],["111.07","56.15"],["111.02","0"],["110.47","22.20"],["110.43","0"],["109.88","45.95"],["109.84","0"],["109.29","29.62"],["109.25","0"],["108.70","21.93"],["108.66","0"],["108.11","6.02"],["108.07","0"],["107.52","55.97"],["107.48","0"],["106.93","21.31"],["106.89","0"],["106.34","8.95"],["106.30","0"],["105.75","10.15"],["105.71","0"],["105.16","40.07"],["105.12","0"],["104.57","15.36"],["104.53","0"],["103.98","46.47"],["103.94","0"],["103.39","11.11"],["103.35","0"],["102.80","1.87"],["102.76","0"],["102.21","37.67"],["102.17","0"],["101.62","21.48"],["101.58","0"],["101.03","49.80"],["100.99","0"],["100.44","49.32"],["100.40","0"],["99.85","42.14"],["99.26","8.55"],["98.67","30.36"],["98.08","20.32"],["97.49","36.65"],["96.90","21.95"],["96.31","8.41"],["95.72","31.49"],["95.13","57.35"],["94.54","3.45"],["93.95","4.85"],["93.36","74.35"],["92.77","33.85"],["92.18","20.24"]],"checksum":2973949,"ts":"1649290104385"}]}
1649290104.436275: {"action":"snapshot","arg":{"instType":"mc","channel":"ticker","instId":"UNIUSDT"},"data":[{"instId":"UNIUSDT","last":"9.9770","bestAsk":"9.977","bestBid":"9.972","high24h":"10.4280","low24h":"9.9030","priceChangePercent":"-0.0393","capitalRate":"-0.000100","nextSettleTime":1649314800000,"systemTime":1649290104403,"markPrice":"9.9744","indexPrice":"9.9814","holding":"369411","baseVolume":"313114","quoteVolume":"3294754"}]}
1649290104.43948: {"action":"snapshot","arg":{"instType":"mc","channel":"ticker","instId":"DASHUSDT"},"data":[{"instId":"DASHUSDT","last":"113.340","bestAsk":"113.42","bestBid":"113.37","high24h":"118.870","low24h":"113.140","priceChangePercent":"-0.036","capitalRate":"-0.000100","nextSettleTime":1649314800000,"systemTime":1649290104408,"markPrice":"113.390","indexPrice":"113.432","holding":"21957.17","baseVolume":"25307.14","quoteVolume":"3062978.45"}]}
1649290104.574791: {"action":"update","arg":{"instType":"mc","channel":"books","instId":"UNIUSDT"},"data":[{"asks":[["9.975","228"],["9.976","255"],["9.977","80"],["9.978","306"],["9.979","397"],["9.980","256"],["9.981","385"],["9.982","1970"],["9.984","318"],["9.985","387"],["9.986","189"],["9.987","833"],["9.988","392"],["9.989","589"],["9.991","560"],["9.992","929"],["9.993","1655"],["9.994","2240"],["9.995","420"],["9.996","726"],["9.997","3122"],["9.999","432"],["10.003","1137"],["10.006","1175"],["10.008","3542"],["10.009","397"],["10.011","5267"],["10.013","3253"],["10.014","7277"],["10.015","178"],["10.016","633"],["10.017","7548"],["10.021","191"],["10.023","14382"],["10.024","1998"],["10.025","0"],["10.026","0"],["10.027","0"],["10.028","12597"],["10.032","0"],["10.033","12405"],["10.037","0"],["10.038","12213"],["10.042","0"],["10.043","12789"],["10.047","0"],["10.048","12020"],["10.052","0"],["10.053","11828"],["10.057","0"],["10.058","12982"],["10.062","113"],["10.063","11636"],["10.067","0"],["10.068","11443"],["10.072","0"],["10.073","13559"],["10.077","0"],["10.078","13366"],["10.082","0"],["10.122","60"],["10.129","0"],["10.174","174"],["10.181","0"],["10.226","366"],["10.233","0"],["10.278","361"],["10.285","0"],["10.330","240"],["10.337","0"],["10.382","123"],["10.389","0"],["10.434","268"],["10.441","0"],["10.486","79"],["10.493","0"],["10.538","164"],["10.545","0"],["10.590","327"],["10.597","0"],["10.642","205"],["10.649","0"],["10.694","204"],["10.701","0"],["10.746","24"],["10.753","0"],["10.798","134"],["10.805","0"],["10.850","170"],["10.857","0"],["10.902","84"],["10.909","0"],["10.954","94"],["10.961","0"],["11.006","41"],["11.013","0"],["11.058","221"],["11.065","0"],["11.110","421"],["11.117","0"],["11.162","28"],["11.169","0"],["11.214","103"],["11.221","0"],["11.266","180"],["11.273","0"],["11.318","312"],["11.325","0"],["11.370","123"],["11.377","0"],["11.422","186"],["11.429","0"],["11.474","335"],["11.481","0"]],"bids":[["9.974","0"],["9.973","0"],["9.972","0"],["9.971","0"],["9.970","264"],["9.969","240"],["9.968","69"],["9.967","177"],["9.966","342"],["9.965","729"],["9.964","200"],["9.963","332"],["9.962","1015"],["9.961","415"],["9.960","252"],["9.959","811"],["9.958","710"],["9.957","2482"],["9.956","1201"],["9.955","533"],["9.953","723"],["9.952","601"],["9.951","1130"],["9.950","358"],["9.947","204"],["9.946","366"],["9.944","7091"],["9.943","1941"],["9.942","1294"],["9.936","492"],["9.935","407"],["9.933","2882"],["9.931","3587"],["9.927","419"],["9.926","416"],["9.925","8457"],["9.924","1180"],["9.923","365"],["9.922","19764"],["9.921","58"],["9.917","12982"],["9.916","0"],["9.912","13174"],["9.911","0"],["9.907","13559"],["9.906","0"],["9.902","11636"],["9.901","0"],["9.897","12213"],["9.896","0"],["9.892","12020"],["9.891","0"],["9.887","13366"],["9.886","0"],["9.882","12597"],["9.881","0"],["9.877","12789"],["9.876","0"],["9.872","11828"],["9.871","0"],["9.867","12405"],["9.795","0"],["9.788","109"],["9.744","0"],["9.737","308"],["9.694","0"],["9.687","160"],["9.644","0"],["9.637","151"],["9.594","0"],["9.587","245"],["9.544","0"],["9.537","194"],["9.494","0"],["9.487","352"],["9.444","0"],["9.437","104"],["9.394","0"],["9.387","260"],["9.344","0"],["9.337","181"],["9.294","0"],["9.287","236"],["9.244","0"],["9.237","196"],["9.194","0"],["9.187","326"],["9.144","0"],["9.137","70"],["9.094","0"],["9.087","222"],["9.044","0"],["9.037","174"],["8.994","0"],["8.987","321"],["8.944","0"],["8.937","170"],["8.894","0"],["8.887","63"],["8.844","0"],["8.837","102"],["8.794","0"],["8.787","141"],["8.744","0"],["8.737","261"],["8.694","0"],["8.687","42"],["8.644","0"],["8.637","371"],["8.594","0"],["8.587","156"],["8.544","0"],["8.537","111"]],"checksum":-1828478409,"ts":"1649290104548"}]}
1649290104.697527: {"action":"snapshot","arg":{"instType":"mc","channel":"ticker","instId":"UNIUSDT"},"data":[{"instId":"UNIUSDT","last":"9.9770","bestAsk":"9.975","bestBid":"9.97","high24h":"10.4280","low24h":"9.9030","priceChangePercent":"-0.0393","capitalRate":"-0.000100","nextSettleTime":1649314800000,"systemTime":1649290104663,"markPrice":"9.9744","indexPrice":"9.9818","holding":"369411","baseVolume":"313114","quoteVolume":"3294754"}]}
1649290104.700732: {"action":"snapshot","arg":{"instType":"mc","channel":"ticker","instId":"DASHUSDT"},"data":[{"instId":"DASHUSDT","last":"113.340","bestAsk":"113.41","bestBid":"113.36","high24h":"118.870","low24h":"113.140","priceChangePercent":"-0.036","capitalRate":"-0.000100","nextSettleTime":1649314800000,"systemTime":1649290104672,"markPrice":"113.390","indexPrice":"113.402","holding":"21957.17","baseVolume":"25307.14","quoteVolume":"3062978.45"}]}
1649290104.721691: {"action":"update","arg":{"instType":"mc","channel":"books","instId":"DASHUSDT"},"data":[{"asks":[["113.41","0"],["113.42","22.65"],["113.44","5.25"],["113.45","20.50"],["113.47","10.78"],["113.48","2.26"],["113.50","23.47"],["113.51","30.62"],["113.52","86.27"],["113.53","29.22"],["113.54","53.39"],["113.57","33.80"],["113.59","54.08"],["113.60","202.26"],["113.61","28.58"],["113.62","812.31"],["113.66","40.09"],["113.67","26.15"],["113.70","36.55"],["113.77","795.03"],["113.82","46.96"],["113.83","18.52"],["113.85","2052.46"],["113.89","5.55"],["113.90","1600.35"],["113.91","1828.77"],["113.95","0"],["113.97","2018.39"],["114.01","0"],["114.03","1731.63"],["114.07","0"],["114.09","1886.04"],["114.13","0"],["114.15","1952.22"],["114.19","0"],["114.21","1775.75"],["114.25","0"],["114.27","1841.92"],["114.31","0"],["114.33","1753.69"],["114.37","0"],["114.39","1996.33"],["114.43","0"],["114.45","1863.98"],["114.49","0"],["114.51","1908.10"],["114.55","0"],["114.57","1709.57"],["114.61","0"],["114.63","1930.16"],["114.67","0"],["114.69","2040.45"],["114.73","0"],["114.75","1974.27"]],"bids":[["113.36","1.99"],["113.35","6.22"],["113.34","5.95"],["113.33","237.61"],["113.32","25.75"],["113.29","0"],["113.28","74.56"],["113.22","20.05"],["113.21","55.90"],["113.18","33.33"],["113.16","25.69"],["113.13","106.84"],["113.12","106.76"],["113.08","73.42"],["113.06","16.68"],["113.05","1519.82"],["113.03","43.45"],["113.02","74.81"],["113.00","14.48"],["112.98","625.57"],["112.95","1600.18"],["112.93","2141.06"],["112.92","56.86"],["112.88","46.53"],["112.87","2236.21"],["112.86","6.86"],["112.85","0"],["112.84","0"],["112.81","1775.75"],["112.80","0"],["112.75","1974.27"],["112.74","0"],["112.69","1841.92"],["112.68","0"],["112.63","1709.57"],["112.62","0"],["112.57","1908.10"],["112.56","0"],["112.51","1930.16"],["112.50","0"],["112.45","1996.33"],["112.44","0"],["112.39","2040.45"],["112.38","0"],["112.33","1797.80"],["112.32","0"],["112.27","1731.63"],["112.26","0"],["112.21","1863.98"],["112.20","0"],["112.15","1753.69"],["112.14","0"],["112.09","1952.22"],["112.08","0"],["112.03","1886.04"],["112.02","0"]],"checksum":1625987708,"ts":"1649290104692"}]}
1649290104.893187: {"action":"update","arg":{"instType":"mc","channel":"books","instId":"UNIUSDT"},"data":[{"asks":[["9.975","155"],["9.976","182"],["9.977","129"],["9.978","365"],["9.979","601"],["9.980","109"],["9.981","583"],["9.982","2076"],["9.983","909"],["9.984","293"],["9.985","384"],["9.986","126"],["9.987","719"],["9.988","370"],["9.989","567"],["9.990","901"],["9.991","614"],["9.992","966"],["9.993","2642"],["9.994","2325"],["9.995","366"],["9.996","1508"],["9.997","837"],["9.998","448"],["10.000","525"],["10.004","502"],["10.007","394"],["10.008","133"],["10.010","362"],["10.011","4821"],["10.020","4507"],["10.023","13611"],["10.024","3499"],["10.028","11636"],["10.033","12020"],["10.038","12789"],["10.043","13366"],["10.048","12597"],["10.053","13174"],["10.058","11828"],["10.063","12982"],["10.068","13559"],["10.073","12213"],["10.078","11443"],["10.116","60"],["10.122","0"],["10.168","174"],["10.174","0"],["10.220","366"],["10.226","0"],["10.272","361"],["10.278","0"],["10.324","240"],["10.330","0"],["10.376","123"],["10.382","0"],["10.428","268"],["10.434","0"],["10.480","79"],["10.486","0"],["10.532","164"],["10.538","0"],["10.584","327"],["10.590","0"],["10.636","205"],["10.642","0"],["10.688","204"],["10.694","0"],["10.740","24"],["10.746","0"],["10.792","134"],["10.798","0"],["10.844","170"],["10.850","0"],["10.896","84"],["10.902","0"],["10.948","94"],["10.954","0"],["11.000","41"],["11.006","0"],["11.052","221"],["11.058","0"],["11.104","421"],["11.110","0"],["11.156","28"],["11.162","0"],["11.208","103"],["11.214","0"],["11.260","180"],["11.266","0"],["11.312","312"],["11.318","0"],["11.364","123"],["11.370","0"],["11.416","186"],["11.422","0"],["11.468","335"],["11.474","0"]],"bids":[["9.969","448"],["9.968","75"],["9.967","360"],["9.966","279"],["9.965","1030"],["9.964","292"],["9.962","1472"],["9.961","428"],["9.960","265"],["9.959","822"],["9.958","594"],["9.957","2395"],["9.956","487"],["9.955","435"],["9.954","674"],["9.952","1331"],["9.951","1214"],["9.950","406"],["9.949","927"],["9.948","641"],["9.947","370"],["9.946","427"],["9.945","1094"],["9.943","1022"],["9.942","1135"],["9.941","2330"],["9.940","556"],["9.939","2349"],["9.936","505"],["9.934","263"],["9.925","8324"],["9.922","20500"],["9.917","13366"],["9.912","11636"],["9.907","12020"],["9.902","12597"],["9.897","12405"],["9.892","13174"],["9.887","12982"],["9.882","13559"],["9.877","11443"],["9.867","12789"],["9.788","0"],["9.782","109"],["9.737","0"],["9.731","308"],["9.687","0"],["9.681","160"],["9.637","0"],["9.631","151"],["9.587","0"],["9.581","245"],["9.537","0"],["9.531","194"],["9.487","0"],["9.481","352"],["9.437","0"],["9.431","104"],["9.387","0"],["9.381","260"],["9.337","0"],["9.331","181"],["9.287","0"],["9.281","236"],["9.237","0"],["9.231","196"],["9.187","0"],["9.181","326"],["9.137","0"],["9.131","70"],["9.087","0"],["9.081","222"],["9.037","0"],["9.031","174"],["8.987","0"],["8.981","321"],["8.937","0"],["8.931","170"],["8.887","0"],["8.881","63"],["8.837","0"],["8.831","102"],["8.787","0"],["8.781","141"],["8.737","0"],["8.731","261"],["8.687","0"],["8.681","42"],["8.637","0"],["8.631","371"],["8.587","0"],["8.581","156"],["8.537","0"],["8.531","111"]],"checksum":-639538253,"ts":"1649290104865"}]}
