1649290079.689881: {"action":"snapshot","arg":{"instType":"mc","channel":"ticker","instId":"UNIUSDT"},"data":[{"instId":"UNIUSDT","last":"9.9770","bestAsk":"9.98","bestBid":"9.975","high24h":"10.4280","low24h":"9.9030","priceChangePercent":"-0.0393","capitalRate":"-0.000100","nextSettleTime":1649314800000,"systemTime":1649290079657,"markPrice":"9.9656","indexPrice":"9.9810","holding":"369411","baseVolume":"313072","quoteVolume":"3294334"}]}
1649290079.696289: {"action":"snapshot","arg":{"instType":"mc","channel":"ticker","instId":"DASHUSDT"},"data":[{"instId":"DASHUSDT","last":"113.370","bestAsk":"113.55","bestBid":"113.5","high24h":"118.870","low24h":"113.140","priceChangePercent":"-0.036","capitalRate":"-0.000100","nextSettleTime":1649314800000,"systemTime":1649290079659,"markPrice":"113.395","indexPrice":"113.481","holding":"21957.17","baseVolume":"25301.89","quoteVolume":"3062382.87"}]}
1649290079.899713: {"action":"update","arg":{"instType":"mc","channel":"books","instId":"UNIUSDT"},"data":[{"asks":[["9.980","53"],["9.981","244"],["9.982","365"],["9.983","383"],["9.985","146"],["9.986","750"],["9.987","272"],["9.988","586"],["9.989","512"],["9.990","500"],["9.991","848"],["9.992","688"],["9.993","827"],["9.996","1465"],["9.997","947"],["9.998","630"],["10.000","670"],["10.002","303"],["10.004","1870"],["10.005","513"],["10.008","1012"],["10.010","878"],["10.011","704"],["10.015","154"],["10.016","740"],["10.018","459"],["10.020","3672"],["10.022","503"],["10.023","4223"],["10.024","488"],["10.028","11834"],["10.029","5291"],["10.033","11636"],["10.038","13366"],["10.043","12405"],["10.048","13174"],["10.053","12982"],["10.058","12213"],["10.063","11828"],["10.068","12020"],["10.073","12789"],["10.078","13559"],["10.083","12597"],["10.096","247"],["10.102","0"],["10.148","252"],["10.154","0"],["10.200","19"],["10.206","0"],["10.252","150"],["10.258","0"],["10.304","413"],["10.310","0"],["10.356","113"],["10.362","0"],["10.408","15"],["10.414","0"],["10.460","298"],["10.466","0"],["10.512","112"],["10.518","0"],["10.564","258"],["10.570","0"],["10.616","130"],["10.622","0"],["10.668","116"],["10.674","0"],["10.720","241"],["10.726","0"],["10.772","99"],["10.778","0"],["10.824","186"],["10.830","0"],["10.876","246"],["10.882","0"],["10.928","225"],["10.934","0"],["10.980","141"],["10.986","0"],["11.032","207"],["11.038","0"],["11.084","90"],["11.090","0"],["11.136","609"],["11.142","0"],["11.188","493"],["11.194","0"],["11.240","189"],["11.246","0"],["11.292","175"],["11.298","0"]],"bids":[["9.975","546"],["9.972","186"],["9.971","167"],["9.970","214"],["9.969","261"],["9.968","390"],["9.967","127"],["9.965","310"],["9.964","291"],["9.963","402"],["9.962","871"],["9.961","655"],["9.960","347"],["9.959","190"],["9.957","544"],["9.956","470"],["9.955","227"],["9.954","338"],["9.953","801"],["9.952","171"],["9.951","596"],["9.950","1418"],["9.949","653"],["9.946","2310"],["9.941","1035"],["9.940","849"],["9.937","504"],["9.934","684"],["9.930","1914"],["9.928","7282"],["9.927","14082"],["9.926","2476"],["9.922","11828"],["9.917","12789"],["9.912","13366"],["9.907","12597"],["9.902","12213"],["9.897","13174"],["9.892","11443"],["9.887","12405"],["9.877","12020"],["9.872","13559"],["9.787","0"],["9.781","341"],["9.736","0"],["9.730","236"],["9.686","0"],["9.680","8"],["9.636","0"],["9.630","63"],["9.586","0"],["9.580","343"],["9.536","0"],["9.530","321"],["9.486","0"],["9.480","309"],["9.436","0"],["9.430","298"],["9.386","0"],["9.380","21"],["9.336","0"],["9.330","127"],["9.286","0"],["9.280","223"],["9.236","0"],["9.230","145"],["9.186","0"],["9.180","46"],["9.136","0"],["9.130","69"],["9.086","0"],["9.080","145"],["9.036","0"],["9.030","161"],["8.986","0"],["8.980","297"],["8.936","0"],["8.930","16"],["8.886","0"],["8.880","94"],["8.836","0"],["8.830","183"],["8.786","0"],["8.780","74"],["8.736","0"],["8.730","254"],["8.686","0"],["8.680","280"],["8.636","0"],["8.630","169"],["8.586","0"],["8.580","62"],["8.536","0"],["8.530","362"],["8.486","0"],["8.480","206"],["8.436","0"],["8.430","169"],["8.386","0"],["8.380","7"]],"checksum":-589575089,"ts":"1649290079871"}]}
1649290079.909376: {"action":"update","arg":{"instType":"mc","channel":"books","instId":"DASHUSDT"},"data":[{"asks":[["113.55","0.38"],["113.56","0.65"],["113.57","6.58"],["113.60","0.87"],["113.61","37.24"],["113.62","33.57"],["113.63","37.23"],["113.64","61.16"],["113.67","33.83"],["113.69","62.54"],["113.70","19.32"],["113.71","1600.19"],["113.73","263.58"],["113.74","30.55"],["113.76","8.08"],["113.77","664.92"],["113.78","649.06"],["113.79","35.50"],["113.80","229.63"],["113.81","51.71"],["113.82","34.54"],["113.83","191.25"],["113.84","206.67"],["113.85","384.81"],["113.86","153.99"],["113.87","41.98"],["113.88","12.88"],["113.89","23.14"],["113.90","348.82"],["113.91","18.34"],["113.92","159.30"],["113.93","20.54"],["113.98","1775.75"],["113.99","485.05"],["114.01","109.46"],["114.02","77.74"],["114.03","1600.40"],["114.04","1984.55"],["114.05","139.75"],["114.10","1908.10"],["114.16","1731.63"],["114.22","1996.33"],["114.28","1952.22"],["114.34","1819.86"],["114.40","2040.45"],["114.46","1753.69"],["114.52","1841.92"],["114.58","1974.27"],["114.64","1886.04"],["114.70","1709.57"],["114.76","1797.80"],["114.82","2018.39"],["114.88","1863.98"],["115.78","0"],["116.00","31.47"],["116.37","0"],["116.59","50.46"],["116.96","0"],["117.18","49.40"],["117.55","0"],["117.77","27.41"],["118.14","0"],["118.36","50.42"],["118.73","0"],["118.95","50.07"],["119.32","0"],["119.54","36.12"],["119.91","0"],["120.13","8.62"],["120.50","0"],["120.72","54.60"],["121.09","0"],["121.31","1.48"],["121.68","0"],["121.90","43.49"],["122.27","0"],["122.49","7.73"],["122.86","0"],["123.08","58.21"],["123.45","0"],["123.67","52.67"],["124.04","0"],["124.26","53.84"],["124.63","0"],["124.85","4.99"],["125.22","0"],["125.44","44.04"],["125.81","0"],["126.03","25.10"],["126.40","0"],["126.62","39.09"],["126.99","0"],["127.21","44.51"],["127.58","0"],["127.80","19.01"],["128.17","0"],["128.39","29.39"],["128.76","0"],["128.98","3.89"],["129.35","0"],["129.57","23.37"],["129.94","0"],["130.16","24.18"],["130.53","0"],["130.75","9.15"],["131.12","0"],["131.34","27.04"],["131.71","0"],["131.93","7.10"],["132.52","13.38"],["133.11","33.57"],["133.70","76.51"]],"bids":[["113.50","37.63"],["113.49","247.51"],["113.48","13.80"],["113.47","119.45"],["113.46","2.53"],["113.45","17.51"],["113.44","2.61"],["113.43","1006.38"],["113.42","2.31"],["113.40","27.20"],["113.39","32.38"],["113.38","22.98"],["113.37","306.91"],["113.36","16.80"],["113.35","281.80"],["113.34","0"],["113.33","87.49"],["113.32","8.83"],["113.30","68.21"],["113.29","157.19"],["113.28","55.85"],["113.27","21.40"],["113.26","225.32"],["113.25","23.08"],["113.24","27.24"],["113.23","18.07"],["113.22","11.72"],["113.20","145.96"],["113.19","428.07"],["113.18","44.82"],["113.17","46.17"],["113.16","13.81"],["113.15","122.79"],["113.13","32.48"],["113.11","40.38"],["113.10","21.11"],["113.09","1600.12"],["113.08","78.45"],["113.07","1842.25"],["113.06","116.86"],["113.04","11.80"],["113.03","79.28"],["113.02","55.02"],["113.01","1749.29"],["113.00","35.74"],["112.95","1908.10"],["112.89","1753.69"],["112.83","2040.45"],["112.77","1930.16"],["112.71","1863.98"],["112.65","1731.63"],["112.59","1996.33"],["112.53","2018.39"],["112.47","1819.86"],["112.41","1974.27"],["112.35","1952.22"],["112.29","1841.92"],["111.66","0"],["111.61","44.63"],["111.07","0"],["111.02","97.81"],["110.47","0"],["110.43","40.49"],["109.88","0"],["109.84","85.27"],["109.29","0"],["109.25","84.73"],["108.70","0"],["108.66","59.74"],["108.11","0"],["108.07","61.13"],["107.52","0"],["107.48","33.01"],["106.93","0"],["106.89","56.85"],["106.34","0"],["106.30","24.34"],["105.75","0"],["105.71","1.74"],["105.16","0"],["105.12","57.94"],["104.57","0"],["104.53","58.21"],["103.98","0"],["103.94","46.12"],["103.39","0"],["103.35","52.32"],["102.80","0"],["102.76","45.29"],["102.21","0"],["102.17","22.94"],["101.62","0"],["101.58","36.02"],["101.03","0"],["100.99","38.02"],["100.44","0"],["100.40","53.60"],["99.85","0"],["99.26","0"],["98.67","0"],["98.08","0"],["97.49","0"],["96.90","0"],["96.31","0"],["95.72","0"],["95.13","0"],["94.54","0"],["93.95","0"],["93.36","0"],["92.77","0"],["92.18","0"]],"checksum":-1514481556,"ts":"1649290079881"}]}
1649290079.9336011: {"action":"snapshot","arg":{"instType":"mc","channel":"ticker","instId":"UNIUSDT"},"data":[{"instId":"UNIUSDT","last":"9.9770","bestAsk":"9.98","bestBid":"9.975","high24h":"10.4280","low24h":"9.9030","priceChangePercent":"-0.0393","capitalRate":"-0.000100","nextSettleTime":1649314800000,"systemTime":1649290079906,"markPrice":"9.9656","indexPrice":"9.9810","holding":"369411","baseVolume":"313072","quoteVolume":"3294334"}]}
1649290079.942581: {"action":"snapshot","arg":{"instType":"mc","channel":"ticker","instId":"DASHUSDT"},"data":[{"instId":"DASHUSDT","last":"113.370","bestAsk":"113.55","bestBid":"113.5","high24h":"118.870","low24h":"113.140","priceChangePercent":"-0.036","capitalRate":"-0.000100","nextSettleTime":1649314800000,"systemTime":1649290079910,"markPrice":"113.395","indexPrice":"113.481","holding":"21957.17","baseVolume":"25301.89","quoteVolume":"3062382.87"}]}
1649290080.098269: {"action":"update","arg":{"instType":"mc","channel":"trade","instId":"UNIUSDT"},"data":[["1649290079982","9.977","1","buy"]]}
1649290080.20318: {"action":"update","arg":{"instType":"mc","channel":"books","instId":"UNIUSDT"},"data":[{"asks":[["9.980","0"],["9.981","133"],["9.983","532"],["9.984","309"],["9.985","216"],["9.986","673"],["9.987","255"],["9.988","669"],["9.989","529"],["9.990","326"],["9.991","1140"],["9.992","639"],["9.993","982"],["9.994","2688"],["9.995","859"],["9.996","1732"],["9.997","1134"],["9.998","686"],["9.999","2237"],["10.001","511"],["10.002","336"],["10.003","888"],["10.004","1053"],["10.008","712"],["10.010","3115"],["10.014","3565"],["10.015","944"],["10.016","990"],["10.022","452"],["10.023","8016"],["10.026","1399"],["10.028","392"],["10.029","18876"],["10.030","46"],["10.033","0"],["10.034","12982"],["10.038","0"],["10.039","13174"],["10.043","0"],["10.044","12597"],["10.048","0"],["10.049","12405"],["10.053","0"],["10.054","12213"],["10.058","0"],["10.059","12789"],["10.063","0"],["10.064","11636"],["10.068","0"],["10.069","13366"],["10.073","0"],["10.074","11828"],["10.078","0"],["10.079","12020"],["10.083","0"],["10.084","11443"],["10.091","247"],["10.096","0"],["10.143","252"],["10.148","0"],["10.195","19"],["10.200","0"],["10.247","150"],["10.252","0"],["10.299","413"],["10.304","0"],["10.351","113"],["10.356","0"],["10.403","15"],["10.408","0"],["10.455","298"],["10.460","0"],["10.507","112"],["10.512","0"],["10.559","258"],["10.564","0"],["10.611","130"],["10.616","0"],["10.663","116"],["10.668","0"],["10.715","241"],["10.720","0"],["10.767","99"],["10.772","0"],["10.819","186"],["10.824","0"],["10.871","246"],["10.876","0"],["10.923","225"],["10.928","0"],["10.975","141"],["10.980","0"],["11.027","207"],["11.032","0"],["11.079","90"],["11.084","0"],["11.131","609"],["11.136","0"],["11.183","493"],["11.188","0"],["11.235","189"],["11.240","0"],["11.287","175"],["11.292","0"]],"bids":[["9.976","519"],["9.975","0"],["9.974","199"],["9.973","91"],["9.972","212"],["9.971","185"],["9.970","238"],["9.969","289"],["9.968","438"],["9.967","111"],["9.966","1151"],["9.965","386"],["9.964","325"],["9.963","353"],["9.962","747"],["9.961","427"],["9.960","483"],["9.958","495"],["9.957","584"],["9.955","208"],["9.954","320"],["9.953","724"],["9.951","584"],["9.950","626"],["9.949","673"],["9.946","2292"],["9.945","1390"],["9.944","1013"],["9.938","689"],["9.937","522"],["9.936","591"],["9.934","465"],["9.933","3337"],["9.929","323"],["9.928","20274"],["9.927","1101"],["9.925","0"],["9.923","13366"],["9.922","0"],["9.918","12789"],["9.917","0"],["9.913","11636"],["9.912","0"],["9.908","11828"],["9.907","0"],["9.903","12020"],["9.902","0"],["9.898","12213"],["9.897","0"],["9.893","11443"],["9.892","0"],["9.888","13559"],["9.887","0"],["9.883","13174"],["9.882","0"],["9.878","12405"],["9.877","0"],["9.873","12597"],["9.872","0"],["9.781","0"],["9.776","341"],["9.730","0"],["9.725","236"],["9.680","0"],["9.675","8"],["9.630","0"],["9.625","63"],["9.580","0"],["9.575","343"],["9.530","0"],["9.525","321"],["9.480","0"],["9.475","309"],["9.430","0"],["9.425","298"],["9.380","0"],["9.375","21"],["9.330","0"],["9.325","127"],["9.280","0"],["9.275","223"],["9.230","0"],["9.225","145"],["9.180","0"],["9.175","46"],["9.130","0"],["9.125","69"],["9.080","0"],["9.075","145"],["9.030","0"],["9.025","161"],["8.980","0"],["8.975","297"],["8.930","0"],["8.925","16"],["8.880","0"],["8.875","94"],["8.830","0"],["8.825","183"],["8.780","0"],["8.775","74"],["8.730","0"],["8.725","254"],["8.680","0"],["8.675","280"],["8.630","0"],["8.625","169"],["8.580","0"],["8.575","62"],["8.530","0"],["8.525","362"],["8.480","0"],["8.475","206"],["8.430","0"],["8.425","169"],["8.380","0"],["8.375","7"]],"checksum":-1386586208,"ts":"1649290080175"}]}
1649290080.216942: {"action":"snapshot","arg":{"instType":"mc","channel":"ticker","instId":"UNIUSDT"},"data":[{"instId":"UNIUSDT","last":"9.9770","bestAsk":"9.981","bestBid":"9.976","high24h":"10.4280","low24h":"9.9030","priceChangePercent":"-0.0393","capitalRate":"-0.000100","nextSettleTime":1649314800000,"systemTime":1649290080185,"markPrice":"9.9683","indexPrice":"9.9810","holding":"369411","baseVolume":"313072","quoteVolume":"3294334"}]}
1649290080.2170382: {"action":"snapshot","arg":{"instType":"mc","channel":"ticker","instId":"DASHUSDT"},"data":[{"instId":"DASHUSDT","last":"113.370","bestAsk":"113.55","bestBid":"113.5","high24h":"118.870","low24h":"113.140","priceChangePercent":"-0.036","capitalRate":"-0.000100","nextSettleTime":1649314800000,"systemTime":1649290080187,"markPrice":"113.409","indexPrice":"113.481","holding":"21957.17","baseVolume":"25301.89","quoteVolume":"3062382.87"}]}
1649290080.226781: {"action":"update","arg":{"instType":"mc","channel":"books","instId":"DASHUSDT"},"data":[{"asks":[["113.57","7.34"],["113.60","22.22"],["113.64","21.26"],["113.66","70.81"],["113.69","68.97"],["113.70","160.39"],["113.72","40.17"],["113.73","168.53"],["113.74","67.18"],["113.75","26.02"],["113.76","5.86"],["113.78","405.91"],["113.80","522.67"],["113.81","232.91"],["113.82","101.61"],["113.83","238.77"],["113.85","82.86"],["113.86","9.05"],["113.87","13.93"],["113.88","485.11"],["113.89","4.01"],["113.90","258.40"],["113.92","148.00"],["113.93","31.17"],["113.98","1841.92"],["113.99","509.80"],["114.01","107.06"],["114.02","101.80"],["114.03","483.98"],["114.04","1874.25"],["114.10","1886.04"],["114.16","2040.45"],["114.22","1952.22"],["114.28","1974.27"],["114.34","2018.39"],["114.40","1775.75"],["114.46","1908.10"],["114.52","1797.80"],["114.58","1930.16"],["114.64","1731.63"],["114.70","1753.69"],["114.76","1863.98"],["114.82","1709.57"],["114.88","1996.33"],["115.78","0.73"],["116.00","0"],["116.37","68.26"],["116.59","0"],["116.96","70.90"],["117.18","0"],["117.55","49.89"],["117.77","0"],["118.14","22.59"],["118.36","0"],["118.73","47.85"],["118.95","0"],["119.32","46.71"],["119.54","0"],["119.91","23.57"],["120.13","0"],["120.50","59.15"],["120.72","0"],["121.09","6.51"],["121.31","0"],["121.68","54.25"],["121.90","0"],["122.27","14.99"],["122.49","0"],["122.86","11.21"],["123.08","0"],["123.45","66.50"],["123.67","0"],["124.04","64.47"],["124.26","0"],["124.63","42.85"],["124.85","0"],["125.22","29.99"],["125.44","0"],["125.81","4.07"],["126.03","0"],["126.40","26.70"],["126.62","0"],["126.99","20.67"],["127.21","0"],["127.58","56.99"],["127.80","0"],["128.17","44.01"],["128.39","0"],["128.76","46.60"],["128.98","0"],["129.35","39.07"],["129.57","0"],["129.94","19.33"],["130.16","0"],["130.53","20.66"],["130.75","0"],["131.12","28.11"],["131.34","0"],["131.71","13.65"],["131.93","0"],["132.52","0"],["133.11","0"],["133.70","0"]],"bids":[["113.50","42.58"],["113.49","237.61"],["113.48","56.77"],["113.47","124.40"],["113.43","17.08"],["113.40","1600.03"],["113.38","53.42"],["113.37","237.61"],["113.36","1.46"],["113.35","278.83"],["113.34","0.45"],["113.33","74.38"],["113.31","9.45"],["113.30","25.34"],["113.29","6.48"],["113.28","36.12"],["113.27","77.53"],["113.26","240.67"],["113.24","16.35"],["113.23","13.12"],["113.22","17.16"],["113.20","144.64"],["113.19","376.59"],["113.18","49.38"],["113.15","106.34"],["113.14","578.78"],["113.13","30.07"],["113.11","237.69"],["113.09","9.49"],["113.07","1974.60"],["113.02","57.78"],["113.01","2058.11"],["113.00","0"],["112.95","1863.98"],["112.89","1974.27"],["112.83","1996.33"],["112.71","1886.04"],["112.65","1775.75"],["112.59","1709.57"],["112.53","1753.69"],["112.47","1841.92"],["112.41","1952.22"],["112.35","1819.86"],["112.29","1731.63"],["112.23","2040.45"],["111.66","54.98"],["111.61","0"],["111.07","56.15"],["111.02","0"],["110.47","22.20"],["110.43","0"],["109.88","45.95"],["109.84","0"],["109.29","29.62"],["109.25","0"],["108.70","21.93"],["108.66","0"],["108.11","6.02"],["108.07","0"],["107.52","55.97"],["107.48","0"],["106.93","21.31"],["106.89","0"],["106.34","8.95"],["106.30","0"],["105.75","10.15"],["105.71","0"],["105.16","40.07"],["105.12","0"],["104.57","15.36"],["104.53","0"],["103.98","46.47"],["103.94","0"],["103.39","11.11"],["103.35","0"],["102.80","1.87"],["102.76","0"],["102.21","37.67"],["102.17","0"],["101.62","21.48"],["101.58","0"],["101.03","49.80"],["100.99","0"],["100.44","49.32"],["100.40","0"],["99.85","42.14"],["99.26","8.55"],["98.67","30.36"],["98.08","20.32"],["97.49","36.65"],["96.90","21.95"],["96.31","8.41"],["95.72","31.49"],["95.13","57.35"],["94.54","3.45"],["93.95","4.85"],["93.36","74.35"],["92.77","33.85"],["92.18","20.24"]],"checksum":1089289250,"ts":"1649290080193"}]}
1649290080.434819: {"action":"update","arg":{"instType":"mc","channel":"candle1m","instId":"UNIUSDT"},"data":[["1649290020000","9.97","9.977","9.961","9.977","48"]]}
1649290080.486868: {"action":"snapshot","arg":{"instType":"mc","channel":"ticker","instId":"UNIUSDT"},"data":[{"instId":"UNIUSDT","last":"9.9770","bestAsk":"9.98","bestBid":"9.974","high24h":"10.4280","low24h":"9.9030","priceChangePercent":"-0.0393","capitalRate":"-0.000100","nextSettleTime":1649314800000,"systemTime":1649290080454,"markPrice":"9.9683","indexPrice":"9.9808","holding":"369411","baseVolume":"313073","quoteVolume":"3294344"}]}
1649290080.510494: {"action":"snapshot","arg":{"instType":"mc","channel":"ticker","instId":"DASHUSDT"},"data":[{"instId":"DASHUSDT","last":"113.370","bestAsk":"113.55","bestBid":"113.49","high24h":"118.870","low24h":"113.140","priceChangePercent":"-0.036","capitalRate":"-0.000100","nextSettleTime":1649314800000,"systemTime":1649290080475,"markPrice":"113.409","indexPrice":"113.483","holding":"21957.17","baseVolume":"25301.89","quoteVolume":"3062382.87"}]}
1649290080.52757: {"action":"update","arg":{"instType":"mc","channel":"books","instId":"UNIUSDT"},"data":[{"asks":[["9.980","284"],["9.981","340"],["9.982","418"],["9.983","564"],["9.984","205"],["9.985","964"],["9.986","779"],["9.987","208"],["9.988","971"],["9.989","539"],["9.990","395"],["9.991","623"],["9.992","688"],["9.993","1376"],["9.994","2583"],["9.995","617"],["9.996","1800"],["9.997","1051"],["9.998","759"],["9.999","1685"],["10.000","942"],["10.001","1197"],["10.002","442"],["10.003","1546"],["10.004","1061"],["10.005","527"],["10.006","514"],["10.007","373"],["10.020","3706"],["10.027","841"],["10.028","13388"],["10.029","461"],["10.030","0"],["10.033","13366"],["10.034","0"],["10.038","12405"],["10.039","0"],["10.043","13174"],["10.044","0"],["10.048","12213"],["10.049","0"],["10.053","12789"],["10.054","0"],["10.058","13559"],["10.059","0"],["10.063","11828"],["10.064","0"],["10.068","12597"],["10.069","0"],["10.073","11443"],["10.074","0"],["10.078","11636"],["10.079","0"],["10.083","12020"],["10.084","0"],["10.085","247"],["10.091","0"],["10.137","252"],["10.143","0"],["10.189","19"],["10.195","0"],["10.241","150"],["10.247","0"],["10.293","413"],["10.299","0"],["10.345","113"],["10.351","0"],["10.397","15"],["10.403","0"],["10.449","298"],["10.455","0"],["10.501","112"],["10.507","0"],["10.553","258"],["10.559","0"],["10.605","130"],["10.611","0"],["10.657","116"],["10.663","0"],["10.709","241"],["10.715","0"],["10.761","99"],["10.767","0"],["10.813","186"],["10.819","0"],["10.865","246"],["10.871","0"],["10.917","225"],["10.923","0"],["10.969","141"],["10.975","0"],["11.021","207"],["11.027","0"],["11.073","90"],["11.079","0"],["11.125","609"],["11.131","0"],["11.177","493"],["11.183","0"],["11.229","189"],["11.235","0"],["11.281","175"],["11.287","0"]],"bids":[["9.976","0"],["9.975","199"],["9.974","14"],["9.973","194"],["9.972","330"],["9.971","99"],["9.970","54"],["9.969","269"],["9.968","354"],["9.967","140"],["9.966","1027"],["9.965","505"],["9.964","295"],["9.962","707"],["9.961","414"],["9.960","304"],["9.958","1074"],["9.957","634"],["9.956","352"],["9.954","258"],["9.953","692"],["9.950","595"],["9.949","1358"],["9.948","629"],["9.947","2454"],["9.946","2497"],["9.945","1301"],["9.944","845"],["9.942","724"],["9.940","887"],["9.939","1439"],["9.938","582"],["9.930","1942"],["9.928","7293"],["9.927","12544"],["9.926","3647"],["9.923","0"],["9.922","11828"],["9.918","0"],["9.917","13366"],["9.913","0"],["9.912","13559"],["9.908","0"],["9.907","12213"],["9.903","0"],["9.902","12982"],["9.898","0"],["9.897","12597"],["9.893","0"],["9.892","12020"],["9.888","0"],["9.887","12405"],["9.883","0"],["9.882","13174"],["9.878","0"],["9.877","11636"],["9.873","0"],["9.872","12789"],["9.776","0"],["9.770","341"],["9.725","0"],["9.719","236"],["9.675","0"],["9.669","8"],["9.625","0"],["9.619","63"],["9.575","0"],["9.569","343"],["9.525","0"],["9.519","321"],["9.475","0"],["9.469","309"],["9.425","0"],["9.419","298"],["9.375","0"],["9.369","21"],["9.325","0"],["9.319","127"],["9.275","0"],["9.269","223"],["9.225","0"],["9.219","145"],["9.175","0"],["9.169","46"],["9.125","0"],["9.119","69"],["9.075","0"],["9.069","145"],["9.025","0"],["9.019","161"],["8.975","0"],["8.969","297"],["8.925","0"],["8.919","16"],["8.875","0"],["8.869","94"],["8.825","0"],["8.819","183"],["8.775","0"],["8.769","74"],["8.725","0"],["8.719","254"],["8.675","0"],["8.669","280"],["8.625","0"],["8.619","169"],["8.575","0"],["8.569","62"],["8.525","0"],["8.519","362"],["8.475","0"],["8.469","206"],["8.425","0"],["8.419","169"],["8.375","0"],["8.369","7"]],"checksum":-2065794128,"ts":"1649290080496"}]}
1649290080.52859: {"action":"update","arg":{"instType":"mc","channel":"books","instId":"DASHUSDT"},"data":[{"asks":[["113.56","0.78"],["113.57","8.65"],["113.58","7.78"],["113.61","39.66"],["113.63","340.17"],["113.65","107.42"],["113.66","77.26"],["113.67","1345.67"],["113.68","629.73"],["113.69","104.57"],["113.70","31.69"],["113.71","41.69"],["113.72","113.44"],["113.73","310.10"],["113.74","18.34"],["113.75","238.98"],["113.76","16.57"],["113.77","668.07"],["113.78","204.61"],["113.79","38.19"],["113.80","324.67"],["113.81","75.00"],["113.82","95.42"],["113.83","63.54"],["113.84","63.49"],["113.85","81.38"],["113.86","13.93"],["113.88","9.91"],["113.89","4.33"],["113.90","301.87"],["113.92","1253.15"],["113.93","23.43"],["113.94","125.98"],["113.98","1996.33"],["114.00","140.96"],["114.02","88.63"],["114.03","505.76"],["114.04","2072.78"],["114.10","1974.27"],["114.22","1841.92"],["114.28","1819.86"],["114.34","1731.63"],["114.40","1863.98"],["114.46","1797.80"],["114.52","1908.10"],["114.58","1775.75"],["114.64","1952.22"],["114.70","1930.16"],["114.76","1709.57"],["114.82","1886.04"],["114.88","1753.69"]],"bids":[["113.50","0"],["113.49","420.76"],["113.48","1.92"],["113.47","237.61"],["113.45","18.28"],["113.44","23.39"],["113.43","17.76"],["113.41","8.89"],["113.40","1600.20"],["113.38","50.29"],["113.37","355.42"],["113.33","73.30"],["113.30","21.01"],["113.28","37.58"],["113.27","32.49"],["113.26","240.23"],["113.24","148.51"],["113.23","20.10"],["113.22","29.54"],["113.20","171.70"],["113.19","368.08"],["113.18","44.82"],["113.17","41.72"],["113.15","162.89"],["113.14","588.68"],["113.13","37.64"],["113.12","28.20"],["113.11","240.60"],["113.10","21.44"],["113.09","8.77"],["113.07","78.88"],["113.06","2092.44"],["113.04","16.75"],["113.01","39.73"],["113.00","3336.74"],["112.95","0"],["112.94","1797.80"],["112.89","0"],["112.88","1775.75"],["112.83","0"],["112.82","1908.10"],["112.77","0"],["112.76","1753.69"],["112.71","0"],["112.70","1930.16"],["112.65","0"],["112.64","1996.33"],["112.59","0"],["112.58","1952.22"],["112.53","0"],["112.52","2040.45"],["112.47","0"],["112.46","1709.57"],["112.41","0"],["112.40","1731.63"],["112.35","0"],["112.34","1863.98"],["112.29","0"],["112.28","1841.92"],["112.23","0"],["112.22","1886.04"],["112.17","0"],["112.16","2018.39"]],"checksum":-846630122,"ts":"1649290080496"}]}
1649290080.674586: {"action":"update","arg":{"instType":"mc","channel":"trade","instId":"DASHUSDT"},"data":[["1649290080580","113.49","0.43","sell"]]}
1649290080.829642: {"action":"update","arg":{"instType":"mc","channel":"books","instId":"UNIUSDT"},"data":[{"asks":[["9.980","199"],["9.981","242"],["9.983","470"],["9.984","171"],["9.985","1097"],["9.986","724"],["9.987","231"],["9.988","964"],["9.989","681"],["9.990","479"],["9.991","519"],["9.992","720"],["9.993","1421"],["9.994","2846"],["9.996","1836"],["9.998","686"],["10.001","1128"],["10.002","1234"],["10.003","754"],["10.007","392"],["10.011","817"],["10.012","1387"],["10.013","427"],["10.014","6394"],["10.020","3720"],["10.028","12426"],["10.033","12405"],["10.038","12789"],["10.043","12213"],["10.048","11636"],["10.053","11828"],["10.063","13366"],["10.068","11443"],["10.073","12597"],["10.078","12982"],["10.083","13174"],["10.085","0"],["10.132","30"],["10.137","0"],["10.183","175"],["10.189","0"],["10.234","128"],["10.241","0"],["10.285","325"],["10.293","0"],["10.337","44"],["10.345","0"],["10.388","194"],["10.397","0"],["10.439","24"],["10.449","0"],["10.490","62"],["10.501","0"],["10.541","318"],["10.553","0"],["10.592","186"],["10.605","0"],["10.643","139"],["10.657","0"],["10.694","348"],["10.709","0"],["10.745","163"],["10.761","0"],["10.796","58"],["10.813","0"],["10.847","328"],["10.865","0"],["10.898","190"],["10.917","0"],["10.949","208"],["10.969","0"],["11.000","117"],["11.021","0"],["11.051","279"],["11.073","0"],["11.102","252"],["11.125","0"],["11.153","215"],["11.177","0"],["11.204","223"],["11.229","0"],["11.255","254"],["11.281","0"],["11.306","226"],["11.357","91"],["11.408","133"],["11.459","23"],["11.510","295"]],"bids":[["9.973","89"],["9.972","580"],["9.970","38"],["9.969","321"],["9.968","291"],["9.967","124"],["9.965","624"],["9.963","249"],["9.962","42"],["9.961","502"],["9.959","324"],["9.958","1053"],["9.956","567"],["9.953","744"],["9.952","210"],["9.951","680"],["9.950","719"],["9.949","641"],["9.948","1458"],["9.947","4553"],["9.946","2783"],["9.944","874"],["9.943","962"],["9.934","370"],["9.931","3670"],["9.927","13520"],["9.926","2476"],["9.922","11443"],["9.917","12020"],["9.912","11828"],["9.907","13559"],["9.897","11636"],["9.892","13174"],["9.887","12597"],["9.882","12789"],["9.877","13366"],["9.872","12213"],["9.770","0"],["9.764","341"],["9.719","0"],["9.713","236"],["9.669","0"],["9.663","8"],["9.619","0"],["9.613","63"],["9.569","0"],["9.563","343"],["9.519","0"],["9.513","321"],["9.469","0"],["9.463","309"],["9.419","0"],["9.413","298"],["9.369","0"],["9.363","21"],["9.319","0"],["9.313","127"],["9.269","0"],["9.263","223"],["9.219","0"],["9.213","145"],["9.169","0"],["9.163","46"],["9.119","0"],["9.113","69"],["9.069","0"],["9.063","145"],["9.019","0"],["9.013","161"],["8.969","0"],["8.963","297"],["8.919","0"],["8.913","16"],["8.869","0"],["8.863","94"],["8.819","0"],["8.813","183"],["8.769","0"],["8.763","74"],["8.719","0"],["8.713","254"],["8.669","0"],["8.663","280"],["8.619","0"],["8.613","169"],["8.569","0"],["8.563","62"],["8.519","0"],["8.513","362"],["8.469","0"],["8.463","206"],["8.419","0"],["8.413","169"],["8.369","0"],["8.363","7"]],"checksum":-379867157,"ts":"1649290080798"}]}
1649290080.8546932: {"action":"update","arg":{"instType":"mc","channel":"books","instId":"DASHUSDT"},"data":[{"asks":[["113.54","0.89"],["113.55","2.96"],["113.56","5.00"],["113.57","9.74"],["113.58","5.65"],["113.60","0.87"],["113.62","25.68"],["113.63","32.28"],["113.64","34.72"],["113.65","114.09"],["113.66","55.63"],["113.67","38.50"],["113.68","50.20"],["113.69","108.03"],["113.70","16.35"],["113.71","39.21"],["113.72","94.24"],["113.73","177.11"],["113.74","1330.75"],["113.75","26.63"],["113.77","670.25"],["113.78","468.28"],["113.79","35.50"],["113.80","229.63"],["113.81","1.49"],["113.82","28.35"],["113.83","183.73"],["113.84","59.14"],["113.85","369.47"],["113.86","9.05"],["113.87","148.50"],["113.88","553.42"],["113.89","30.40"],["113.90","275.47"],["113.91","83.42"],["113.92","129.50"],["113.94","128.46"],["113.97","2041.75"],["113.98","0"],["113.99","485.05"],["114.00","269.86"],["114.01","115.97"],["114.02","116.85"],["114.03","3419.94"],["114.04","20.68"],["114.05","0"],["114.09","1996.33"],["114.10","0"],["114.15","1952.22"],["114.16","0"],["114.21","1930.16"],["114.22","0"],["114.27","2040.45"],["114.28","0"],["114.33","1908.10"],["114.34","0"],["114.39","1709.57"],["114.40","0"],["114.45","2018.39"],["114.46","0"],["114.51","1797.80"],["114.52","0"],["114.57","1886.04"],["114.58","0"],["114.63","1974.27"],["114.64","0"],["114.69","1753.69"],["114.70","0"],["114.75","1841.92"],["114.76","0"],["114.81","1731.63"],["114.82","0"],["114.87","1863.98"],["114.88","0"],["115.78","0"],["116.00","31.47"],["116.37","0"],["116.59","50.46"],["116.96","0"],["117.18","49.40"],["117.55","0"],["117.77","27.41"],["118.14","0"],["118.36","50.42"],["118.73","0"],["118.95","50.07"],["119.32","0"],["119.54","36.12"],["119.91","0"],["120.13","8.62"],["120.50","0"],["120.72","54.60"],["121.09","0"],["121.31","1.48"],["121.68","0"],["121.90","43.49"],["122.27","0"],["122.49","7.73"],["122.86","0"],["123.08","58.21"],["123.45","0"],["123.67","52.67"],["124.04","0"],["124.26","53.84"],["124.63","0"],["124.85","4.99"],["125.22","0"],["125.44","44.04"],["125.81","0"],["126.03","25.10"],["126.40","0"],["126.62","39.09"],["126.99","0"],["127.21","44.51"],["127.58","0"],["127.80","19.01"],["128.17","0"],["128.39","29.39"],["128.76","0"],["128.98","3.89"],["129.35","0"],["129.57","23.37"],["129.94","0"],["130.16","24.18"],["130.53","0"],["130.75","9.15"],["131.12","0"],["131.34","27.04"],["131.71","0"],["131.93","7.10"],["132.52","13.38"],["133.11","33.57"],["133.70","76.51"]],"bids":[["113.49","237.61"],["113.46","4.40"],["113.45","34.66"],["113.44","1.86"],["113.43","1035.59"],["113.42","5.32"],["113.41","6.84"],["113.40","26.32"],["113.39","28.02"],["113.37","157.52"],["113.36","16.80"],["113.35","540.19"],["113.33","103.22"],["113.32","6.85"],["113.31","6.22"],["113.30","70.50"],["113.29","158.44"],["113.28","19.58"],["113.27","94.36"],["113.26","224.88"],["113.24","32.32"],["113.23","23.30"],["113.22","29.37"],["113.20","136.06"],["113.19","434.90"],["113.16","81.16"],["113.15","233.08"],["113.14","391.20"],["113.13","48.53"],["113.12","25.23"],["113.11","7.97"],["113.10","8.81"],["113.09","1493.77"],["113.08","85.41"],["113.07","177.33"],["113.06","1881.46"],["113.02","55.02"],["113.01","19.31"],["113.00","1789.42"],["112.94","1709.57"],["112.88","2018.39"],["112.82","1775.75"],["112.76","1886.04"],["112.70","1863.98"],["112.64","2040.45"],["112.58","1974.27"],["112.52","1952.22"],["112.46","1996.33"],["112.34","1930.16"],["112.28","1908.10"],["112.22","1797.80"],["112.16","1819.86"],["111.66","0"],["111.61","44.63"],["111.07","0"],["111.02","97.81"],["110.47","0"],["110.43","40.49"],["109.88","0"],["109.84","85.27"],["109.29","0"],["109.25","84.73"],["108.70","0"],["108.66","59.74"],["108.11","0"],["108.07","61.13"],["107.52","0"],["107.48","33.01"],["106.93","0"],["106.89","56.85"],["106.34","0"],["106.30","24.34"],["105.75","0"],["105.71","1.74"],["105.16","0"],["105.12","57.94"],["104.57","0"],["104.53","58.21"],["103.98","0"],["103.94","46.12"],["103.39","0"],["103.35","52.32"],["102.80","0"],["102.76","45.29"],["102.21","0"],["102.17","22.94"],["101.62","0"],["101.58","36.02"],["101.03","0"],["100.99","38.02"],["100.44","0"],["100.40","53.60"],["99.85","0"],["99.26","0"],["98.67","0"],["98.08","0"],["97.49","0"],["96.90","0"],["96.31","0"],["95.72","0"],["95.13","0"],["94.54","0"],["93.95","0"],["93.36","0"],["92.77","0"],["92.18","0"]],"checksum":2134596417,"ts":"1649290080825"}]}
1649290080.8628988: {"action":"snapshot","arg":{"instType":"mc","channel":"ticker","instId":"UNIUSDT"},"data":[{"instId":"UNIUSDT","last":"9.9770","bestAsk":"9.98","bestBid":"9.975","high24h":"10.4280","low24h":"9.9030","priceChangePercent":"-0.0393","capitalRate":"-0.000100","nextSettleTime":1649314800000,"systemTime":1649290080828,"markPrice":"9.9683","indexPrice":"9.9805","holding":"369411","baseVolume":"313073","quoteVolume":"3294344"}]}
1649290080.875722: {"action":"snapshot","arg":{"instType":"mc","channel":"ticker","instId":"DASHUSDT"},"data":[{"instId":"DASHUSDT","last":"113.490","bestAsk":"113.54","bestBid":"113.49","high24h":"118.870","low24h":"113.140","priceChangePercent":"-0.036","capitalRate":"-0.000100","nextSettleTime":1649314800000,"systemTime":1649290080847,"markPrice":"113.434","indexPrice":"113.513","holding":"21957.17","baseVolume":"25301.89","quoteVolume":"3062382.87"}]}
1649290081.102072: {"action":"update","arg":{"instType":"mc","channel":"candle1m","instId":"DASHUSDT"},"data":[["1649290080000","113.37","113.49","113.37","113.49","0.43"]]}
1649290081.1372: {"action":"update","arg":{"instType":"mc","channel":"books","instId":"UNIUSDT"},"data":[{"asks":[["9.983","316"],["9.984","200"],["9.985","1047"],["9.986","776"],["9.987","275"],["9.988","1004"],["9.989","556"],["9.990","664"],["9.991","503"],["9.992","656"],["9.993","1386"],["9.994","2680"],["9.997","1101"],["10.000","607"],["10.002","1260"],["10.009","297"],["10.010","853"],["10.012","1809"],["10.019","476"],["10.021","192"],["10.027","30"],["10.028","13965"],["10.033","12789"],["10.038","12597"],["10.043","11636"],["10.048","13366"],["10.053","11443"],["10.058","12982"],["10.063","12405"],["10.068","12020"],["10.073","13174"],["10.078","12213"],["10.083","11828"],["10.126","30"],["10.132","0"],["10.177","175"],["10.183","0"],["10.228","128"],["10.234","0"],["10.279","325"],["10.285","0"],["10.331","44"],["10.337","0"],["10.382","194"],["10.388","0"],["10.433","24"],["10.439","0"],["10.484","62"],["10.490","0"],["10.535","318"],["10.541","0"],["10.586","186"],["10.592","0"],["10.637","139"],["10.643","0"],["10.688","348"],["10.694","0"],["10.739","163"],["10.745","0"],["10.790","58"],["10.796","0"],["10.841","328"],["10.847","0"],["10.892","190"],["10.898","0"],["10.943","208"],["10.949","0"],["10.994","117"],["11.000","0"],["11.045","279"],["11.051","0"],["11.096","252"],["11.102","0"],["11.147","215"],["11.153","0"],["11.198","223"],["11.204","0"],["11.249","254"],["11.255","0"],["11.300","226"],["11.306","0"],["11.351","91"],["11.357","0"],["11.402","133"],["11.408","0"],["11.453","23"],["11.459","0"],["11.504","295"],["11.510","0"]],"bids":[["9.975","100"],["9.973","191"],["9.972","480"],["9.971","86"],["9.970","265"],["9.969","323"],["9.968","192"],["9.967","203"],["9.965","462"],["9.964","228"],["9.963","190"],["9.962","66"],["9.960","267"],["9.959","926"],["9.958","1135"],["9.952","425"],["9.951","599"],["9.950","849"],["9.949","1433"],["9.948","666"],["9.944","917"],["9.942","748"],["9.941","1269"],["9.939","1400"],["9.927","13712"],["9.922","12789"],["9.917","11828"],["9.912","13366"],["9.907","12405"],["9.902","11443"],["9.897","13559"],["9.887","12213"],["9.882","11636"],["9.877","12020"],["9.872","12982"],["9.764","0"],["9.758","341"],["9.713","0"],["9.707","236"],["9.663","0"],["9.657","8"],["9.613","0"],["9.607","63"],["9.563","0"],["9.557","343"],["9.513","0"],["9.507","321"],["9.463","0"],["9.457","309"],["9.413","0"],["9.407","298"],["9.363","0"],["9.357","21"],["9.313","0"],["9.307","127"],["9.263","0"],["9.257","223"],["9.213","0"],["9.207","145"],["9.163","0"],["9.157","46"],["9.113","0"],["9.107","69"],["9.063","0"],["9.057","145"],["9.013","0"],["9.007","161"],["8.963","0"],["8.957","297"],["8.913","0"],["8.907","16"],["8.863","0"],["8.857","94"],["8.813","0"],["8.807","183"],["8.763","0"],["8.757","74"],["8.713","0"],["8.707","254"],["8.663","0"],["8.657","280"],["8.613","0"],["8.607","169"],["8.563","0"],["8.557","62"],["8.513","0"],["8.507","362"],["8.463","0"],["8.457","206"],["8.413","0"],["8.407","169"],["8.363","0"],["8.357","7"]],"checksum":1483433463,"ts":"1649290081108"}]}
1649290081.1533: {"action":"update","arg":{"instType":"mc","channel":"books","instId":"DASHUSDT"},"data":[{"asks":[["113.53","5.57"],["113.54","7.74"],["113.56","11.47"],["113.57","16.32"],["113.60","4.50"],["113.61","39.81"],["113.62","30.80"],["113.63","21.88"],["113.64","32.66"],["113.65","104.08"],["113.67","43.26"],["113.69","102.59"],["113.70","11.40"],["113.72","77.37"],["113.75","35.64"],["113.77","665.89"],["113.80","283.06"],["113.81","5.70"],["113.83","341.14"],["113.85","212.06"],["113.87","228.77"],["113.90","223.72"],["113.91","84.08"],["113.92","127.04"],["113.95","12.22"],["113.96","1778.49"],["113.97","266.01"],["114.02","2113.17"],["114.03","1600.38"],["114.04","0"],["114.08","2018.39"],["114.09","0"],["114.14","1753.69"],["114.15","0"],["114.20","1797.80"],["114.21","0"],["114.26","1863.98"],["114.27","0"],["114.32","2040.45"],["114.33","0"],["114.38","1886.04"],["114.39","0"],["114.44","1841.92"],["114.45","0"],["114.50","1709.57"],["114.51","0"],["114.56","1952.22"],["114.57","0"],["114.62","1908.10"],["114.63","0"],["114.68","1930.16"],["114.69","0"],["114.74","1974.27"],["114.75","0"],["114.80","1731.63"],["114.81","0"],["114.86","1819.86"],["114.87","0"]],"bids":[["113.49","0"],["113.46","8.92"],["113.45","27.20"],["113.44","0"],["113.43","1035.43"],["113.42","6.65"],["113.41","10.23"],["113.40","22.53"],["113.39","32.60"],["113.38","22.99"],["113.36","21.75"],["113.35","550.09"],["113.33","37.64"],["113.29","167.85"],["113.28","24.44"],["113.27","98.03"],["113.25","21.77"],["113.24","21.43"],["113.23","18.35"],["113.22","17.98"],["113.20","30.79"],["113.19","438.13"],["113.10","23.72"],["113.08","83.41"],["113.06","39.55"],["113.05","3255.83"],["113.04","25.51"],["113.00","35.74"],["112.99","1903.78"],["112.98","696.74"],["112.94","0"],["112.93","2040.45"],["112.88","0"],["112.87","1709.57"],["112.82","0"],["112.81","1753.69"],["112.76","0"],["112.75","1974.27"],["112.70","0"],["112.69","1908.10"],["112.64","0"],["112.63","1819.86"],["112.58","0"],["112.57","1731.63"],["112.52","0"],["112.51","1841.92"],["112.46","0"],["112.45","1930.16"],["112.40","0"],["112.39","1797.80"],["112.34","0"],["112.33","1952.22"],["112.28","0"],["112.27","1886.04"],["112.22","0"],["112.21","1775.75"],["112.16","0"],["112.15","2018.39"]],"checksum":-1370695647,"ts":"1649290081124"}]}
1649290081.3009431: {"action":"snapshot","arg":{"instType":"mc","channel":"ticker","instId":"UNIUSDT"},"data":[{"instId":"UNIUSDT","last":"9.9770","bestAsk":"9.98","bestBid":"9.975","high24h":"10.4280","low24h":"9.9030","priceChangePercent":"-0.0393","capitalRate":"-0.000100","nextSettleTime":1649314800000,"systemTime":1649290081273,"markPrice":"9.9708","indexPrice":"9.9808","holding":"369411","baseVolume":"313073","quoteVolume":"3294344"}]}
1649290081.316399: {"action":"snapshot","arg":{"instType":"mc","channel":"ticker","instId":"DASHUSDT"},"data":[{"instId":"DASHUSDT","last":"113.490","bestAsk":"113.53","bestBid":"113.48","high24h":"118.870","low24h":"113.140","priceChangePercent":"-0.035","capitalRate":"-0.000100","nextSettleTime":1649314800000,"systemTime":1649290081278,"markPrice":"113.434","indexPrice":"113.483","holding":"21957.17","baseVolume":"25302.32","quoteVolume":"3062431.67"}]}
1649290081.444587: {"action":"update","arg":{"instType":"mc","channel":"books","instId":"UNIUSDT"},"data":[{"asks":[["9.980","0"],["9.981","36"],["9.982","309"],["9.983","223"],["9.984","146"],["9.985","463"],["9.986","332"],["9.987","248"],["9.988","302"],["9.989","526"],["9.990","582"],["9.991","436"],["9.992","507"],["9.993","1307"],["9.994","2759"],["9.995","869"],["9.996","926"],["9.997","1002"],["10.001","1094"],["10.002","544"],["10.003","1546"],["10.006","561"],["10.008","718"],["10.010","3115"],["10.011","1527"],["10.012","367"],["10.013","1150"],["10.016","866"],["10.022","256"],["10.027","705"],["10.028","390"],["10.029","17530"],["10.030","46"],["10.033","0"],["10.034","13366"],["10.038","0"],["10.039","12789"],["10.043","0"],["10.044","13559"],["10.048","0"],["10.049","12982"],["10.053","0"],["10.054","13174"],["10.058","0"],["10.059","11636"],["10.063","0"],["10.064","11828"],["10.068","0"],["10.069","12405"],["10.073","0"],["10.074","12597"],["10.078","0"],["10.079","12020"],["10.083","0"],["10.084","11443"],["10.120","30"],["10.126","0"],["10.171","175"],["10.177","0"],["10.222","128"],["10.228","0"],["10.273","325"],["10.279","0"],["10.325","44"],["10.331","0"],["10.376","194"],["10.382","0"],["10.427","24"],["10.433","0"],["10.478","62"],["10.484","0"],["10.529","318"],["10.535","0"],["10.580","186"],["10.586","0"],["10.631","139"],["10.637","0"],["10.682","348"],["10.688","0"],["10.733","163"],["10.739","0"],["10.784","58"],["10.790","0"],["10.835","328"],["10.841","0"],["10.886","190"],["10.892","0"],["10.937","208"],["10.943","0"],["10.988","117"],["10.994","0"],["11.039","279"],["11.045","0"],["11.090","252"],["11.096","0"],["11.141","215"],["11.147","0"],["11.192","223"],["11.198","0"],["11.243","254"],["11.249","0"],["11.294","226"],["11.300","0"],["11.345","91"],["11.351","0"],["11.396","133"],["11.402","0"],["11.447","23"],["11.453","0"],["11.498","295"],["11.504","0"]],"bids":[["9.976","205"],["9.974","34"],["9.973","242"],["9.972","346"],["9.971","180"],["9.969","311"],["9.968","79"],["9.967","184"],["9.966","1206"],["9.965","983"],["9.964","1814"],["9.963","302"],["9.962","92"],["9.961","2127"],["9.960","320"],["9.959","1089"],["9.958","1555"],["9.957","748"],["9.956","529"],["9.954","242"],["9.953","877"],["9.952","365"],["9.951","528"],["9.949","1358"],["9.946","2581"],["9.944","815"],["9.943","1054"],["9.941","1283"],["9.938","529"],["9.936","520"],["9.932","1068"],["9.931","3657"],["9.928","19312"],["9.927","1116"],["9.926","0"],["9.923","13559"],["9.922","0"],["9.918","13366"],["9.917","0"],["9.913","12213"],["9.912","0"],["9.908","12597"],["9.907","0"],["9.903","12789"],["9.902","0"],["9.898","13174"],["9.897","0"],["9.893","12405"],["9.892","0"],["9.888","12982"],["9.887","0"],["9.883","11828"],["9.882","0"],["9.878","11636"],["9.877","0"],["9.873","11443"],["9.872","0"],["9.758","0"],["9.752","341"],["9.707","0"],["9.701","236"],["9.657","0"],["9.651","8"],["9.607","0"],["9.601","63"],["9.557","0"],["9.551","343"],["9.507","0"],["9.501","321"],["9.457","0"],["9.451","309"],["9.407","0"],["9.401","298"],["9.357","0"],["9.351","21"],["9.307","0"],["9.301","127"],["9.257","0"],["9.251","223"],["9.207","0"],["9.201","145"],["9.157","0"],["9.151","46"],["9.107","0"],["9.101","69"],["9.057","0"],["9.051","145"],["9.007","0"],["9.001","161"],["8.957","0"],["8.951","297"],["8.907","0"],["8.901","16"],["8.857","0"],["8.851","94"],["8.807","0"],["8.801","183"],["8.757","0"],["8.751","74"],["8.707","0"],["8.701","254"],["8.657","0"],["8.651","280"],["8.607","0"],["8.601","169"],["8.557","0"],["8.551","62"],["8.507","0"],["8.501","362"],["8.457","0"],["8.451","206"],["8.407","0"],["8.401","169"],["8.357","0"],["8.351","7"]],"checksum":494026697,"ts":"1649290081415"}]}
1649290081.476668: {"action":"update","arg":{"instType":"mc","channel":"books","instId":"DASHUSDT"},"data":[{"asks":[["113.53","0"],["113.54","0.90"],["113.55","1.34"],["113.56","1.59"],["113.57","8.12"],["113.58","9.77"],["113.60","6.42"],["113.62","17.93"],["113.63","24.36"],["113.64","24.49"],["113.65","129.49"],["113.70","266.78"],["113.71","41.19"],["113.72","154.59"],["113.75","26.63"],["113.76","14.59"],["113.80","274.78"],["113.82","30.58"],["113.83","553.00"],["113.87","74.00"],["113.90","233.62"],["113.96","2.75"],["113.97","2291.81"],["113.99","489.50"],["114.00","266.89"],["114.01","107.06"],["114.02","116.85"],["114.03","3442.08"],["114.04","20.68"],["114.08","0"],["114.09","1775.75"],["114.14","0"],["114.15","1753.69"],["114.20","0"],["114.21","1886.04"],["114.26","0"],["114.27","1974.27"],["114.32","0"],["114.33","1709.57"],["114.38","0"],["114.39","2040.45"],["114.44","0"],["114.45","1930.16"],["114.50","0"],["114.51","1819.86"],["114.56","0"],["114.57","1908.10"],["114.62","0"],["114.63","1952.22"],["114.68","0"],["114.69","1797.80"],["114.74","0"],["114.75","1996.33"],["114.80","0"],["114.81","1863.98"],["114.86","0"],["114.87","1731.63"]],"bids":[["113.48","45.78"],["113.47","119.79"],["113.45","70.76"],["113.44","11.04"],["113.43","1003.44"],["113.42","4.45"],["113.41","91.46"],["113.40","24.83"],["113.39","19.73"],["113.38","17.58"],["113.37","156.03"],["113.35","298.40"],["113.34","25.83"],["113.33","39.85"],["113.32","4.87"],["113.31","162.14"],["113.29","165.11"],["113.28","25.87"],["113.18","50.89"],["113.14","579.44"],["113.05","3145.54"],["113.04","20.78"],["113.01","37.62"],["112.98","0"],["112.93","1819.86"],["112.87","1841.92"],["112.81","1709.57"],["112.69","1775.75"],["112.63","1797.80"],["112.57","1908.10"],["112.51","1930.16"],["112.45","1952.22"],["112.39","1753.69"],["112.33","2040.45"],["112.27","1731.63"],["112.21","2018.39"],["112.15","1996.33"]],"checksum":1592517157,"ts":"1649290081449"}]}
1649290081.5848262: {"action":"snapshot","arg":{"instType":"mc","channel":"ticker","instId":"UNIUSDT"},"data":[{"instId":"UNIUSDT","last":"9.9770","bestAsk":"9.981","bestBid":"9.976","high24h":"10.4280","low24h":"9.9030","priceChangePercent":"-0.0393","capitalRate":"-0.000100","nextSettleTime":1649314800000,"systemTime":1649290081550,"markPrice":"9.9708","indexPrice":"9.9805","holding":"369411","baseVolume":"313073","quoteVolume":"3294344"}]}
1649290081.586824: {"action":"snapshot","arg":{"instType":"mc","channel":"ticker","instId":"DASHUSDT"},"data":[{"instId":"DASHUSDT","last":"113.490","bestAsk":"113.54","bestBid":"113.48","high24h":"118.870","low24h":"113.140","priceChangePercent":"-0.035","capitalRate":"-0.000100","nextSettleTime":1649314800000,"systemTime":1649290081559,"markPrice":"113.434","indexPrice":"113.513","holding":"21957.17","baseVolume":"25302.32","quoteVolume":"3062431.67"}]}
1649290081.775298: {"action":"update","arg":{"instType":"mc","channel":"books","instId":"UNIUSDT"},"data":[{"asks":[["9.983","228"],["9.984","177"],["9.985","265"],["9.986","276"],["9.987","198"],["9.988","387"],["9.989","521"],["9.990","460"],["9.991","514"],["9.992","1025"],["9.993","1385"],["9.994","2858"],["9.995","947"],["9.997","898"],["9.999","1620"],["10.002","578"],["10.003","754"],["10.004","1853"],["10.006","596"],["10.011","807"],["10.012","791"],["10.013","1450"],["10.029","17722"],["10.034","11828"],["10.039","12020"],["10.044","12213"],["10.049","11443"],["10.054","12982"],["10.059","12597"],["10.064","12789"],["10.069","13559"],["10.074","13366"],["10.079","13174"],["10.084","11636"],["10.115","30"],["10.120","0"],["10.166","175"],["10.171","0"],["10.217","128"],["10.222","0"],["10.268","325"],["10.273","0"],["10.320","44"],["10.325","0"],["10.371","194"],["10.376","0"],["10.422","24"],["10.427","0"],["10.473","62"],["10.478","0"],["10.524","318"],["10.529","0"],["10.575","186"],["10.580","0"],["10.626","139"],["10.631","0"],["10.677","348"],["10.682","0"],["10.728","163"],["10.733","0"],["10.779","58"],["10.784","0"],["10.830","328"],["10.835","0"],["10.881","190"],["10.886","0"],["10.932","208"],["10.937","0"],["10.983","117"],["10.988","0"],["11.034","279"],["11.039","0"],["11.085","252"],["11.090","0"],["11.136","215"],["11.141","0"],["11.187","223"],["11.192","0"],["11.238","254"],["11.243","0"],["11.289","226"],["11.294","0"],["11.340","91"],["11.345","0"],["11.391","133"],["11.396","0"],["11.442","23"],["11.447","0"],["11.493","295"],["11.498","0"]],"bids":[["9.974","35"],["9.973","217"],["9.972","172"],["9.970","463"],["9.969","306"],["9.968","148"],["9.967","257"],["9.966","708"],["9.965","546"],["9.964","1132"],["9.963","353"],["9.961","2058"],["9.960","274"],["9.959","1079"],["9.958","1576"],["9.957","708"],["9.953","802"],["9.952","411"],["9.951","675"],["9.950","1558"],["9.949","566"],["9.938","512"],["9.937","758"],["9.936","693"],["9.934","3937"],["9.928","19505"],["9.923","12405"],["9.918","12982"],["9.913","13559"],["9.908","11828"],["9.903","12020"],["9.898","11443"],["9.893","12597"],["9.888","11636"],["9.883","12789"],["9.878","13174"],["9.873","13366"],["9.752","0"],["9.747","341"],["9.701","0"],["9.696","236"],["9.651","0"],["9.646","8"],["9.601","0"],["9.596","63"],["9.551","0"],["9.546","343"],["9.501","0"],["9.496","321"],["9.451","0"],["9.446","309"],["9.401","0"],["9.396","298"],["9.351","0"],["9.346","21"],["9.301","0"],["9.296","127"],["9.251","0"],["9.246","223"],["9.201","0"],["9.196","145"],["9.151","0"],["9.146","46"],["9.101","0"],["9.096","69"],["9.051","0"],["9.046","145"],["9.001","0"],["8.996","161"],["8.951","0"],["8.946","297"],["8.901","0"],["8.896","16"],["8.851","16"],["8.846","94"],["8.801","0"],["8.796","183"],["8.751","0"],["8.746","74"],["8.701","0"],["8.696","254"],["8.651","0"],["8.646","280"],["8.601","0"],["8.596","169"],["8.551","0"],["8.546","62"],["8.501","0"],["8.496","362"],["8.451","0"],["8.446","206"],["8.401","0"],["8.396","169"],["8.351","0"],["8.346","7"]],"checksum":223995539,"ts":"1649290081743"}]}
1649290081.7944078: {"action":"update","arg":{"instType":"mc","channel":"books","instId":"DASHUSDT"},"data":[{"asks":[["113.54","2.69"],["113.55","5.28"],["113.56","2.17"],["113.59","18.49"],["113.60","7.43"],["113.65","137.65"],["113.66","58.48"],["113.67","38.50"],["113.68","47.35"],["113.71","39.42"],["113.72","154.76"],["113.77","666.17"],["113.82","27.34"],["113.92","129.68"],["113.97","2203.58"],["114.01","100.55"],["114.02","119.86"],["114.03","3420.12"],["114.09","1709.57"],["114.15","1952.22"],["114.21","1974.27"],["114.27","1841.92"],["114.33","2018.39"],["114.39","1886.04"],["114.45","1863.98"],["114.51","2040.45"],["114.57","1753.69"],["114.63","1775.75"],["114.69","1996.33"],["114.75","1908.10"],["114.81","1731.63"],["114.87","1797.80"]],"bids":[["113.49","237.61"],["113.48","34.82"],["113.47","237.61"],["113.45","33.16"],["113.44","8.40"],["113.43","999.89"],["113.42","7.72"],["113.41","92.77"],["113.39","25.15"],["113.35","550.09"],["113.32","7.51"],["113.18","53.08"],["113.09","1600.51"],["113.08","86.19"],["113.06","2079.99"],["113.05","1259.51"],["113.04","25.51"],["113.01","48.97"],["113.00","1877.65"],["112.99","0"],["112.94","1775.75"],["112.93","0"],["112.88","1908.10"],["112.87","0"],["112.82","1709.57"],["112.81","0"],["112.76","1952.22"],["112.75","0"],["112.70","1886.04"],["112.69","0"],["112.64","1863.98"],["112.63","0"],["112.58","1819.86"],["112.57","0"],["112.52","2018.39"],["112.51","0"],["112.46","1753.69"],["112.45","0"],["112.40","1797.80"],["112.39","0"],["112.34","1974.27"],["112.33","0"],["112.28","1996.33"],["112.27","0"],["112.22","1930.16"],["112.21","0"],["112.16","1731.63"],["112.15","0"]],"checksum":-1328678132,"ts":"1649290081766"}]}
1649290081.958604: {"action":"snapshot","arg":{"instType":"mc","channel":"ticker","instId":"UNIUSDT"},"data":[{"instId":"UNIUSDT","last":"9.9770","bestAsk":"9.981","bestBid":"9.976","high24h":"10.4280","low24h":"9.9030","priceChangePercent":"-0.0393","capitalRate":"-0.000100","nextSettleTime":1649314800000,"systemTime":1649290081922,"markPrice":"9.9708","indexPrice":"9.9805","holding":"369411","baseVolume":"313073","quoteVolume":"3294344"}]}
1649290081.968524: {"action":"snapshot","arg":{"instType":"mc","channel":"ticker","instId":"DASHUSDT"},"data":[{"instId":"DASHUSDT","last":"113.490","bestAsk":"113.54","bestBid":"113.49","high24h":"118.870","low24h":"113.140","priceChangePercent":"-0.035","capitalRate":"-0.000100","nextSettleTime":1649314800000,"systemTime":1649290081934,"markPrice":"113.460","indexPrice":"113.516","holding":"21957.17","baseVolume":"25302.32","quoteVolume":"3062431.67"}]}
1649290082.0941849: {"action":"update","arg":{"instType":"mc","channel":"books","instId":"UNIUSDT"},"data":[{"asks":[["9.981","57"],["9.982","418"],["9.983","336"],["9.984","222"],["9.985","361"],["9.986","185"],["9.987","216"],["9.988","350"],["9.989","570"],["9.990","390"],["9.991","633"],["9.992","1239"],["9.993","1364"],["9.994","2900"],["9.995","934"],["9.996","601"],["9.997","1195"],["10.000","732"],["10.001","1167"],["10.002","454"],["10.004","1061"],["10.005","641"],["10.008","817"],["10.009","215"],["10.012","367"],["10.026","1330"],["10.029","12673"],["10.034","12020"],["10.039","12982"],["10.044","12789"],["10.049","12597"],["10.054","13559"],["10.059","13174"],["10.064","12405"],["10.069","11828"],["10.079","11443"],["10.109","30"],["10.115","0"],["10.160","175"],["10.166","0"],["10.211","128"],["10.217","0"],["10.262","325"],["10.268","0"],["10.314","44"],["10.320","0"],["10.365","194"],["10.371","0"],["10.416","24"],["10.422","0"],["10.467","62"],["10.473","0"],["10.518","318"],["10.524","0"],["10.569","186"],["10.575","0"],["10.620","139"],["10.626","0"],["10.671","348"],["10.677","0"],["10.722","163"],["10.728","0"],["10.773","58"],["10.779","0"],["10.824","328"],["10.830","0"],["10.875","190"],["10.881","0"],["10.926","208"],["10.932","0"],["10.977","117"],["10.983","0"],["11.028","279"],["11.034","0"],["11.079","252"],["11.085","0"],["11.130","215"],["11.136","0"],["11.181","223"],["11.187","0"],["11.232","254"],["11.238","0"],["11.283","226"],["11.289","0"],["11.334","91"],["11.340","0"],["11.385","133"],["11.391","0"],["11.436","23"],["11.442","0"],["11.487","295"],["11.493","0"]],"bids":[["9.976","397"],["9.975","4"],["9.974","127"],["9.973","116"],["9.972","157"],["9.971","249"],["9.970","184"],["9.969","309"],["9.968","134"],["9.966","1054"],["9.965","521"],["9.964","1055"],["9.963","551"],["9.961","2196"],["9.960","290"],["9.959","860"],["9.957","684"],["9.956","510"],["9.954","265"],["9.953","826"],["9.952","318"],["9.950","543"],["9.949","686"],["9.948","782"],["9.944","844"],["9.943","978"],["9.942","893"],["9.941","1243"],["9.937","529"],["9.936","520"],["9.931","3605"],["9.929","399"],["9.928","18819"],["9.923","11443"],["9.913","12597"],["9.908","13366"],["9.903","12789"],["9.898","13174"],["9.893","12213"],["9.888","13559"],["9.883","12405"],["9.878","11828"],["9.873","12020"],["9.747","0"],["9.741","341"],["9.696","0"],["9.690","236"],["9.646","0"],["9.640","8"],["9.596","0"],["9.590","63"],["9.546","0"],["9.540","343"],["9.496","0"],["9.490","321"],["9.446","0"],["9.440","309"],["9.396","0"],["9.390","298"],["9.346","0"],["9.340","21"],["9.296","0"],["9.290","127"],["9.246","0"],["9.240","223"],["9.196","0"],["9.190","145"],["9.146","0"],["9.140","46"],["9.096","0"],["9.090","69"],["9.046","0"],["9.040","145"],["8.996","0"],["8.990","161"],["8.946","0"],["8.940","297"],["8.896","0"],["8.890","16"],["8.846","0"],["8.840","94"],["8.796","0"],["8.790","183"],["8.746","0"],["8.740","74"],["8.696","0"],["8.690","254"],["8.646","0"],["8.640","280"],["8.596","0"],["8.590","169"],["8.546","0"],["8.540","62"],["8.496","0"],["8.490","362"],["8.446","0"],["8.440","206"],["8.396","0"],["8.390","169"],["8.346","0"],["8.340","7"]],"checksum":-1838248005,"ts":"1649290082062"}]}
1649290082.0996091: {"action":"update","arg":{"instType":"mc","channel":"trade","instId":"UNIUSDT"},"data":[["1649290081995","9.977","1","buy"]]}
1649290082.117057: {"action":"update","arg":{"instType":"mc","channel":"books","instId":"DASHUSDT"},"data":[{"asks":[["113.54","3.73"],["113.55","1.27"],["113.56","1.47"],["113.57","11.08"],["113.58","18.32"],["113.60","14.09"],["113.61","41.10"],["113.62","15.35"],["113.64","24.20"],["113.71","38.92"],["113.72","165.48"],["113.76","5.86"],["113.82","26.59"],["113.92","131.73"],["113.97","1982.27"],["114.02","114.12"],["114.03","3420.24"],["114.09","1974.27"],["114.21","1886.04"],["114.27","1930.16"],["114.33","1753.69"],["114.39","1996.33"],["114.45","1797.80"],["114.51","1908.10"],["114.57","1775.75"],["114.63","1863.98"],["114.69","1731.63"],["114.75","2040.45"],["114.81","1841.92"],["114.87","2018.39"]],"bids":[["113.48","30.86"],["113.45","33.79"],["113.44","0.82"],["113.43","1003.92"],["113.42","9.06"],["113.41","90.03"],["113.35","298.39"],["113.33","27.03"],["113.30","71.37"],["113.28","22.75"],["113.23","18.63"],["113.20","37.73"],["113.18","50.68"],["113.14","388.02"],["113.13","51.59"],["113.10","42.79"],["113.09","1497.12"],["113.08","83.42"],["113.06","1837.34"],["113.03","81.96"],["113.00","1730.92"],["112.94","1863.98"],["112.88","1753.69"],["112.82","2040.45"],["112.76","1974.27"],["112.70","1819.86"],["112.64","1775.75"],["112.58","1996.33"],["112.46","1731.63"],["112.40","1908.10"],["112.34","1886.04"],["112.28","1952.22"],["112.16","1841.92"]],"checksum":936386219,"ts":"1649290082088"}]}
1649290082.252186: {"action":"snapshot","arg":{"instType":"mc","channel":"ticker","instId":"UNIUSDT"},"data":[{"instId":"UNIUSDT","last":"9.9770","bestAsk":"9.98","bestBid":"9.975","high24h":"10.4280","low24h":"9.9030","priceChangePercent":"-0.0393","capitalRate":"-0.000100","nextSettleTime":1649314800000,"systemTime":1649290082219,"markPrice":"9.9708","indexPrice":"9.9856","holding":"369411","baseVolume":"313073","quoteVolume":"3294344"}]}
1649290082.2618759: {"action":"snapshot","arg":{"instType":"mc","channel":"ticker","instId":"DASHUSDT"},"data":[{"instId":"DASHUSDT","last":"113.490","bestAsk":"113.54","bestBid":"113.49","high24h":"118.870","low24h":"113.140","priceChangePercent":"-0.035","capitalRate":"-0.000100","nextSettleTime":1649314800000,"systemTime":1649290082234,"markPrice":"113.460","indexPrice":"113.516","holding":"21957.17","baseVolume":"25302.32","quoteVolume":"3062431.67"}]}
1649290082.436934: {"action":"update","arg":{"instType":"mc","channel":"books","instId":"DASHUSDT"},"data":[{"asks":[["113.54","3.36"],["113.55","3.54"],["113.57","12.55"],["113.62","18.52"],["113.63","33.85"],["113.65","116.90"],["113.68","36.06"],["113.69","113.97"],["113.70","212.33"],["113.71","39.91"],["113.72","57.08"],["113.82","29.51"],["113.83","438.66"],["113.85","395.21"],["113.87","71.10"],["114.00","273.49"],["114.03","3530.43"],["114.04","0.88"],["114.09","1731.63"],["114.15","1996.33"],["114.21","2018.39"],["114.27","1908.10"],["114.33","1952.22"],["114.39","1797.80"],["114.45","1753.69"],["114.51","1974.27"],["114.57","1819.86"],["114.63","1886.04"],["114.69","1863.98"],["114.75","1841.92"],["114.81","1775.75"],["114.87","2040.45"]],"bids":[["113.48","37.79"],["113.46","43.57"],["113.45","12.01"],["113.44","1600.07"],["113.43","13.93"],["113.38","19.71"],["113.36","23.24"],["113.34","23.35"],["113.33","26.93"],["113.30","79.69"],["113.28","18.74"],["113.27","14.37"],["113.26","310.02"],["113.24","24.18"],["113.20","46.97"],["113.19","433.67"],["113.18","46.92"],["113.15","310.30"],["113.13","45.19"],["113.09","1600.05"],["113.08","68.82"],["113.06","2079.99"],["113.02","56.06"],["113.00","2039.74"],["112.94","1841.92"],["112.88","1731.63"],["112.82","1709.57"],["112.70","1753.69"],["112.64","1886.04"],["112.58","1819.86"],["112.52","1908.10"],["112.46","1996.33"],["112.40","1952.22"],["112.34","1930.16"],["112.28","1863.98"],["112.22","1775.75"],["112.16","1797.80"]],"checksum":958700413,"ts":"1649290082406"}]}
1649290082.4374: {"action":"update","arg":{"instType":"mc","channel":"books","instId":"UNIUSDT"},"data":[{"asks":[["9.980","163"],["9.981","82"],["9.982","558"],["9.983","356"],["9.984","128"],["9.985","1047"],["9.986","148"],["9.987","275"],["9.988","355"],["9.989","772"],["9.990","443"],["9.991","868"],["9.992","1322"],["9.993","1379"],["9.994","2804"],["9.997","1344"],["9.999","1436"],["10.003","1546"],["10.004","985"],["10.005","654"],["10.006","668"],["10.010","853"],["10.013","2451"],["10.014","6379"],["10.015","1069"],["10.018","609"],["10.021","786"],["10.023","7719"],["10.024","275"],["10.028","12602"],["10.029","461"],["10.030","0"],["10.033","11443"],["10.034","0"],["10.038","12789"],["10.039","0"],["10.043","12405"],["10.044","0"],["10.048","12020"],["10.049","0"],["10.053","13559"],["10.054","0"],["10.058","11828"],["10.059","0"],["10.063","13174"],["10.064","0"],["10.068","12982"],["10.069","0"],["10.073","13366"],["10.074","0"],["10.078","12597"],["10.079","0"],["10.083","11636"],["10.084","0"],["10.101","30"],["10.109","0"],["10.152","175"],["10.160","0"],["10.203","128"],["10.211","0"],["10.254","325"],["10.262","0"],["10.306","44"],["10.314","0"],["10.357","194"],["10.365","0"],["10.408","24"],["10.416","0"],["10.459","62"],["10.467","0"],["10.510","318"],["10.518","0"],["10.561","186"],["10.569","0"],["10.612","139"],["10.620","0"],["10.663","348"],["10.671","0"],["10.714","163"],["10.722","0"],["10.765","58"],["10.773","0"],["10.816","328"],["10.824","0"],["10.867","190"],["10.875","0"],["10.918","208"],["10.926","0"],["10.969","117"],["10.977","0"],["11.020","279"],["11.028","0"],["11.071","252"],["11.079","0"],["11.122","215"],["11.130","0"],["11.173","223"],["11.181","0"],["11.224","254"],["11.232","0"],["11.275","226"],["11.283","0"],["11.326","91"],["11.334","0"],["11.377","133"],["11.385","0"],["11.428","23"],["11.436","0"],["11.479","295"],["11.487","0"]],"bids":[["9.976","0"],["9.974","199"],["9.972","127"],["9.971","199"],["9.969","379"],["9.968","261"],["9.967","302"],["9.966","741"],["9.965","692"],["9.964","1144"],["9.963","624"],["9.962","69"],["9.959","899"],["9.958","1557"],["9.957","739"],["9.956","597"],["9.955","325"],["9.954","322"],["9.952","349"],["9.951","766"],["9.950","636"],["9.949","1478"],["9.948","652"],["9.947","4504"],["9.946","2533"],["9.944","787"],["9.940","632"],["9.934","3842"],["9.928","7184"],["9.927","13519"],["9.926","2476"],["9.923","0"],["9.922","11828"],["9.918","0"],["9.917","12020"],["9.913","0"],["9.912","12789"],["9.908","0"],["9.907","12213"],["9.903","0"],["9.902","13174"],["9.898","0"],["9.897","11636"],["9.893","0"],["9.892","12597"],["9.888","0"],["9.887","11443"],["9.883","0"],["9.882","13366"],["9.878","0"],["9.877","12982"],["9.873","0"],["9.872","13559"],["9.741","0"],["9.733","341"],["9.690","0"],["9.682","236"],["9.640","0"],["9.632","8"],["9.590","0"],["9.582","63"],["9.540","0"],["9.532","343"],["9.490","0"],["9.482","321"],["9.440","0"],["9.432","309"],["9.390","0"],["9.382","298"],["9.340","0"],["9.332","21"],["9.290","0"],["9.282","127"],["9.240","0"],["9.232","223"],["9.190","0"],["9.182","145"],["9.140","0"],["9.132","46"],["9.090","0"],["9.082","69"],["9.040","0"],["9.032","145"],["8.990","0"],["8.982","161"],["8.940","0"],["8.932","297"],["8.890","0"],["8.882","16"],["8.840","0"],["8.832","94"],["8.790","0"],["8.782","183"],["8.740","0"],["8.732","74"],["8.690","0"],["8.682","254"],["8.640","0"],["8.632","280"],["8.590","0"],["8.582","169"],["8.540","0"],["8.532","62"],["8.490","0"],["8.482","362"],["8.440","0"],["8.432","206"],["8.390","0"],["8.382","169"],["8.340","0"],["8.332","7"]],"checksum":1380759591,"ts":"1649290082409"}]}
1649290082.4525561: {"action":"update","arg":{"instType":"mc","channel":"candle1m","instId":"UNIUSDT"},"data":[["1649290080000","9.977","9.977","9.977","9.977","1"]]}
1649290082.511122: {"action":"snapshot","arg":{"instType":"mc","channel":"ticker","instId":"UNIUSDT"},"data":[{"instId":"UNIUSDT","last":"9.9770","bestAsk":"9.98","bestBid":"9.975","high24h":"10.4280","low24h":"9.9030","priceChangePercent":"-0.0393","capitalRate":"-0.000100","nextSettleTime":1649314800000,"systemTime":1649290082481,"markPrice":"9.9726","indexPrice":"9.9805","holding":"369411","baseVolume":"313074","quoteVolume":"3294354"}]}
1649290082.523309: {"action":"snapshot","arg":{"instType":"mc","channel":"ticker","instId":"DASHUSDT"},"data":[{"instId":"DASHUSDT","last":"113.490","bestAsk":"113.54","bestBid":"113.49","high24h":"118.870","low24h":"113.140","priceChangePercent":"-0.035","capitalRate":"-0.000100","nextSettleTime":1649314800000,"systemTime":1649290082492,"markPrice":"113.460","indexPrice":"113.516","holding":"21957.17","baseVolume":"25302.32","quoteVolume":"3062431.67"}]}
1649290082.74851: {"action":"update","arg":{"instType":"mc","channel":"books","instId":"DASHUSDT"},"data":[{"asks":[["113.53","6.24"],["113.54","10.40"],["113.55","0"],["113.57","11.31"],["113.60","7.83"],["113.61","39.81"],["113.63","28.08"],["113.64","102.80"],["113.65","104.08"],["113.68","47.35"],["113.70","212.82"],["113.71","124.06"],["113.91","79.45"],["113.96","1823.52"],["113.97","272.71"],["114.02","1845.74"],["114.03","1600.14"],["114.08","2040.45"],["114.09","0"],["114.14","1797.80"],["114.15","0"],["114.20","1886.04"],["114.21","0"],["114.26","1952.22"],["114.27","0"],["114.32","1974.27"],["114.33","0"],["114.38","1709.57"],["114.39","0"],["114.44","1775.75"],["114.45","0"],["114.50","1863.98"],["114.51","0"],["114.56","1908.10"],["114.57","0"],["114.62","1930.16"],["114.63","0"],["114.68","1996.33"],["114.69","0"],["114.74","1753.69"],["114.75","0"],["114.80","2018.39"],["114.81","0"],["114.86","1841.92"],["114.87","0"],["115.78","0.73"],["116.00","0"],["116.37","68.26"],["116.59","0"],["116.96","70.90"],["117.18","0"],["117.55","49.89"],["117.77","0"],["118.14","22.59"],["118.36","0"],["118.73","47.85"],["118.95","0"],["119.32","46.71"],["119.54","0"],["119.91","23.57"],["120.13","0"],["120.50","59.15"],["120.72","0"],["121.09","6.51"],["121.31","0"],["121.68","54.25"],["121.90","0"],["122.27","14.99"],["122.49","0"],["122.86","11.21"],["123.08","0"],["123.45","66.50"],["123.67","0"],["124.04","64.47"],["124.26","0"],["124.63","42.85"],["124.85","0"],["125.22","29.99"],["125.44","0"],["125.81","4.07"],["126.03","0"],["126.40","26.70"],["126.62","0"],["126.99","20.67"],["127.21","0"],["127.58","56.99"],["127.80","0"],["128.17","44.01"],["128.39","0"],["128.76","46.60"],["128.98","0"],["129.35","39.07"],["129.57","0"],["129.94","19.33"],["130.16","0"],["130.53","20.66"],["130.75","0"],["131.12","28.11"],["131.34","0"],["131.71","13.65"],["131.93","0"],["132.52","0"],["133.11","0"],["133.70","0"]],"bids":[["113.49","0"],["113.48","56.78"],["113.46","325.72"],["113.45","20.80"],["113.44","1600.32"],["113.43","16.21"],["113.42","89.68"],["113.41","86.04"],["113.40","24.74"],["113.37","121.38"],["113.33","26.27"],["113.32","9.49"],["113.31","164.88"],["113.25","24.51"],["113.23","16.72"],["113.22","19.17"],["113.20","40.03"],["113.08","83.41"],["113.07","182.11"],["113.06","39.55"],["113.05","3057.30"],["113.00","21.36"],["112.99","1969.96"],["112.94","0"],["112.93","1731.63"],["112.88","0"],["112.87","1753.69"],["112.82","0"],["112.81","2040.45"],["112.76","0"],["112.75","1709.57"],["112.70","0"],["112.69","1841.92"],["112.64","0"],["112.63","1974.27"],["112.58","0"],["112.57","1886.04"],["112.52","0"],["112.51","1952.22"],["112.46","0"],["112.45","1775.75"],["112.40","0"],["112.39","2018.39"],["112.34","0"],["112.33","1908.10"],["112.28","0"],["112.27","1819.86"],["112.22","0"],["112.21","1996.33"],["112.16","0"],["112.15","1863.98"],["111.66","54.98"],["111.61","0"],["111.07","56.15"],["111.02","0"],["110.47","22.20"],["110.43","0"],["109.88","45.95"],["109.84","0"],["109.29","29.62"],["109.25","0"],["108.70","21.93"],["108.66","0"],["108.11","6.02"],["108.07","0"],["107.52","55.97"],["107.48","0"],["106.93","21.31"],["106.89","0"],["106.34","8.95"],["106.30","0"],["105.75","10.15"],["105.71","0"],["105.16","40.07"],["105.12","0"],["104.57","15.36"],["104.53","0"],["103.98","46.47"],["103.94","0"],["103.39","11.11"],["103.35","0"],["102.80","1.87"],["102.76","0"],["102.21","37.67"],["102.17","0"],["101.62","21.48"],["101.58","0"],["101.03","49.80"],["100.99","0"],["100.44","49.32"],["100.40","0"],["99.85","42.14"],["99.26","8.55"],["98.67","30.36"],["98.08","20.32"],["97.49","36.65"],["96.90","21.95"],["96.31","8.41"],["95.72","31.49"],["95.13","57.35"],["94.54","3.45"],["93.95","4.85"],["93.36","74.35"],["92.77","33.85"],["92.18","20.24"]],"checksum":607745221,"ts":"1649290082721"}]}
1649290082.7774642: {"action":"snapshot","arg":{"instType":"mc","channel":"ticker","instId":"UNIUSDT"},"data":[{"instId":"UNIUSDT","last":"9.9770","bestAsk":"9.98","bestBid":"9.975","high24h":"10.4280","low24h":"9.9030","priceChangePercent":"-0.0393","capitalRate":"-0.000100","nextSettleTime":1649314800000,"systemTime":1649290082743,"markPrice":"9.9726","indexPrice":"9.9856","holding":"369411","baseVolume":"313074","quoteVolume":"3294354"}]}
1649290082.782858: {"action":"snapshot","arg":{"instType":"mc","channel":"ticker","instId":"DASHUSDT"},"data":[{"instId":"DASHUSDT","last":"113.490","bestAsk":"113.53","bestBid":"113.48","high24h":"118.870","low24h":"113.140","priceChangePercent":"-0.035","capitalRate":"-0.000100","nextSettleTime":1649314800000,"systemTime":1649290082754,"markPrice":"113.460","indexPrice":"113.516","holding":"21957.17","baseVolume":"25302.32","quoteVolume":"3062431.67"}]}
1649290082.790258: {"action":"update","arg":{"instType":"mc","channel":"books","instId":"UNIUSDT"},"data":[{"asks":[["9.980","245"],["9.981","133"],["9.982","471"],["9.984","793"],["9.985","946"],["9.986","332"],["9.987","298"],["9.988","344"],["9.991","834"],["9.992","1339"],["9.994","2752"],["9.996","597"],["10.001","962"],["10.002","1339"],["10.003","793"],["10.006","576"],["10.012","801"],["10.027","30"],["10.028","13965"],["10.033","11828"],["10.038","12213"],["10.043","12789"],["10.048","11636"],["10.053","13366"],["10.058","13174"],["10.063","12020"],["10.073","12405"],["10.083","11443"],["10.094","30"],["10.101","0"],["10.145","175"],["10.152","0"],["10.196","128"],["10.203","0"],["10.247","325"],["10.254","0"],["10.299","44"],["10.306","0"],["10.350","194"],["10.357","0"],["10.401","24"],["10.408","0"],["10.452","62"],["10.459","0"],["10.503","318"],["10.510","0"],["10.554","186"],["10.561","0"],["10.605","139"],["10.612","0"],["10.656","348"],["10.663","0"],["10.707","163"],["10.714","0"],["10.758","58"],["10.765","0"],["10.809","328"],["10.816","0"],["10.860","190"],["10.867","0"],["10.911","208"],["10.918","0"],["10.962","117"],["10.969","0"],["11.013","279"],["11.020","0"],["11.064","252"],["11.071","0"],["11.115","215"],["11.122","0"],["11.166","223"],["11.173","0"],["11.217","254"],["11.224","0"],["11.268","226"],["11.275","0"],["11.319","91"],["11.326","0"],["11.370","133"],["11.377","0"],["11.421","23"],["11.428","0"],["11.472","295"],["11.479","0"]],"bids":[["9.970","241"],["9.969","368"],["9.967","186"],["9.966","727"],["9.965","681"],["9.964","1214"],["9.963","426"],["9.959","962"],["9.957","717"],["9.953","947"],["9.951","683"],["9.949","1544"],["9.927","14480"],["9.922","12405"],["9.917","13174"],["9.912","12213"],["9.907","12597"],["9.902","11636"],["9.897","11443"],["9.892","12789"],["9.887","12020"],["9.882","13559"],["9.872","11828"],["9.733","0"],["9.726","341"],["9.682","0"],["9.675","236"],["9.632","0"],["9.625","8"],["9.582","0"],["9.575","63"],["9.532","0"],["9.525","343"],["9.482","0"],["9.475","321"],["9.432","0"],["9.425","309"],["9.382","0"],["9.375","298"],["9.332","0"],["9.325","21"],["9.282","0"],["9.275","127"],["9.232","0"],["9.225","223"],["9.182","0"],["9.175","145"],["9.132","0"],["9.125","46"],["9.082","0"],["9.075","69"],["9.032","0"],["9.025","145"],["8.982","0"],["8.975","161"],["8.932","0"],["8.925","297"],["8.882","0"],["8.875","16"],["8.832","0"],["8.825","94"],["8.782","0"],["8.775","183"],["8.732","0"],["8.725","74"],["8.682","0"],["8.675","254"],["8.632","0"],["8.625","280"],["8.582","0"],["8.575","169"],["8.532","0"],["8.525","62"],["8.482","0"],["8.475","362"],["8.432","0"],["8.425","206"],["8.382","0"],["8.375","169"],["8.332","0"],["8.325","7"]],"checksum":1948323709,"ts":"1649290082763"}]}
1649290083.0380218: {"action":"snapshot","arg":{"instType":"mc","channel":"ticker","instId":"UNIUSDT"},"data":[{"instId":"UNIUSDT","last":"9.9770","bestAsk":"9.98","bestBid":"9.975","high24h":"10.4280","low24h":"9.9030","priceChangePercent":"-0.0393","capitalRate":"-0.000100","nextSettleTime":1649314800000,"systemTime":1649290082989,"markPrice":"9.9726","indexPrice":"9.9856","holding":"369411","baseVolume":"313074","quoteVolume":"3294354"}]}
1649290083.0671282: {"action":"snapshot","arg":{"instType":"mc","channel":"ticker","instId":"DASHUSDT"},"data":[{"instId":"DASHUSDT","last":"113.490","bestAsk":"113.52","bestBid":"113.47","high24h":"118.870","low24h":"113.140","priceChangePercent":"-0.035","capitalRate":"-0.000100","nextSettleTime":1649314800000,"systemTime":1649290083011,"markPrice":"113.476","indexPrice":"113.516","holding":"21957.17","baseVolume":"25302.32","quoteVolume":"3062431.67"}]}
1649290083.0696309: {"action":"update","arg":{"instType":"mc","channel":"books","instId":"DASHUSDT"},"data":[{"asks":[["113.51","12.10"],["113.52","3.57"],["113.55","4.94"],["113.57","10.25"],["113.64","96.53"],["113.67","39.78"],["113.72","50.54"],["113.75","25.47"],["113.76","3.84"],["113.77","671.06"],["113.90","223.72"],["113.94","2058.61"],["113.96","3.67"],["114.00","2049.23"],["114.02","0"],["114.03","0"],["114.04","0"],["114.06","1952.22"],["114.08","0"],["114.12","1886.04"],["114.14","0"],["114.18","2018.39"],["114.20","0"],["114.24","1819.86"],["114.26","0"],["114.30","1908.10"],["114.32","0"],["114.36","1841.92"],["114.38","0"],["114.42","1797.80"],["114.44","0"],["114.48","1974.27"],["114.50","0"],["114.54","1731.63"],["114.56","0"],["114.60","1996.33"],["114.62","0"],["114.66","1863.98"],["114.68","0"],["114.72","1709.57"],["114.74","0"],["114.78","1753.69"],["114.80","0"],["114.84","2040.45"],["114.86","0"]],"bids":[["113.48","0"],["113.47","0"],["113.46","4.40"],["113.43","27.16"],["113.42","93.66"],["113.41","89.69"],["113.40","23.74"],["113.39","26.47"],["113.38","17.58"],["113.37","237.61"],["113.36","21.75"],["113.34","24.84"],["113.32","7.51"],["113.30","97.52"],["113.28","20.30"],["113.25","21.77"],["113.22","8.63"],["113.18","43.11"],["113.17","46.17"],["113.07","176.77"],["113.05","1259.51"],["113.02","2030.32"],["112.99","39.81"],["112.98","522.68"],["112.97","112.08"],["112.96","2073.04"],["112.93","0"],["112.90","1863.98"],["112.87","0"],["112.84","1996.33"],["112.81","0"],["112.78","1709.57"],["112.75","0"],["112.72","1775.75"],["112.69","0"],["112.66","1819.86"],["112.63","0"],["112.60","1797.80"],["112.57","0"],["112.54","2040.45"],["112.51","0"],["112.48","1930.16"],["112.45","0"],["112.42","2018.39"],["112.39","0"],["112.36","1908.10"],["112.33","0"],["112.30","1841.92"],["112.27","0"],["112.24","1886.04"],["112.21","0"],["112.18","1731.63"],["112.15","0"],["112.12","1753.69"]],"checksum":1354507337,"ts":"1649290083039"}]}
1649290083.134167: {"action":"update","arg":{"instType":"mc","channel":"books","instId":"UNIUSDT"},"data":[{"asks":[["9.978","3"],["9.979","387"],["9.980","625"],["9.981","265"],["9.982","703"],["9.983","232"],["9.984","901"],["9.985","1100"],["9.986","213"],["9.987","268"],["9.988","326"],["9.989","904"],["9.990","387"],["9.991","729"],["9.992","1260"],["9.993","1222"],["9.994","2864"],["9.996","673"],["9.997","2542"],["9.999","545"],["10.000","1468"],["10.002","523"],["10.003","845"],["10.009","79"],["10.012","367"],["10.021","459"],["10.026","14078"],["10.028","0"],["10.029","0"],["10.031","13559"],["10.033","0"],["10.036","12597"],["10.038","0"],["10.041","11636"],["10.043","0"],["10.046","11443"],["10.048","0"],["10.051","12789"],["10.053","0"],["10.056","12213"],["10.058","0"],["10.061","11828"],["10.063","0"],["10.066","12020"],["10.068","0"],["10.071","12982"],["10.073","0"],["10.076","13174"],["10.078","0"],["10.081","13366"],["10.083","0"],["10.087","30"],["10.094","0"],["10.138","175"],["10.145","0"],["10.189","128"],["10.196","0"],["10.240","325"],["10.247","0"],["10.292","44"],["10.299","0"],["10.343","194"],["10.350","0"],["10.394","24"],["10.401","0"],["10.445","62"],["10.452","0"],["10.496","318"],["10.503","20"],["10.547","186"],["10.554","0"],["10.598","139"],["10.605","0"],["10.649","348"],["10.656","0"],["10.700","163"],["10.707","0"],["10.751","58"],["10.758","0"],["10.802","328"],["10.809","0"],["10.853","190"],["10.860","0"],["10.904","208"],["10.911","0"],["10.955","117"],["10.962","0"],["11.006","279"],["11.013","0"],["11.057","252"],["11.064","0"],["11.108","215"],["11.115","0"],["11.159","223"],["11.166","0"],["11.210","254"],["11.217","0"],["11.261","226"],["11.268","0"],["11.312","91"],["11.319","0"],["11.363","133"],["11.370","0"],["11.414","23"],["11.421","0"],["11.465","295"],["11.472","0"]],"bids":[["9.975","0"],["9.974","0"],["9.973","227"],["9.972","229"],["9.971","165"],["9.970","169"],["9.969","426"],["9.968","77"],["9.966","1118"],["9.965","627"],["9.964","1226"],["9.963","706"],["9.962","55"],["9.961","2087"],["9.960","261"],["9.959","448"],["9.958","1510"],["9.957","678"],["9.956","436"],["9.955","241"],["9.953","609"],["9.952","324"],["9.951","786"],["9.950","546"],["9.949","795"],["9.947","3019"],["9.946","3325"],["9.945","2192"],["9.941","998"],["9.940","887"],["9.933","3197"],["9.927","1115"],["9.926","1238"],["9.925","16965"],["9.924","981"],["9.922","0"],["9.920","13559"],["9.917","0"],["9.915","11443"],["9.912","0"],["9.910","12405"],["9.907","0"],["9.905","12213"],["9.902","0"],["9.900","11636"],["9.897","0"],["9.895","12982"],["9.892","0"],["9.890","12020"],["9.887","0"],["9.885","13174"],["9.882","0"],["9.880","11828"],["9.877","0"],["9.875","13366"],["9.872","0"],["9.870","12789"],["9.818","24"],["9.767","7"],["9.726","0"],["9.717","345"],["9.675","0"],["9.667","358"],["9.625","0"],["9.617","317"],["9.575","0"],["9.567","24"],["9.525","0"],["9.517","244"],["9.475","0"],["9.467","188"],["9.425","0"],["9.417","49"],["9.375","0"],["9.367","288"],["9.325","0"],["9.317","359"],["9.275","0"],["9.267","348"],["9.225","0"],["9.217","49"],["9.175","0"],["9.167","128"],["9.125","0"],["9.117","9"],["9.075","0"],["9.067","102"],["9.025","0"],["9.017","268"],["8.975","0"],["8.967","24"],["8.925","0"],["8.917","75"],["8.875","0"],["8.867","312"],["8.825","0"],["8.817","269"],["8.775","0"],["8.767","322"],["8.725","0"],["8.717","29"],["8.675","0"],["8.667","245"],["8.625","0"],["8.617","371"],["8.575","0"],["8.567","239"],["8.525","0"],["8.517","34"],["8.475","0"],["8.425","0"],["8.375","0"],["8.325","0"]],"checksum":1561481981,"ts":"1649290083107"}]}
1649290083.3341281: {"action":"snapshot","arg":{"instType":"mc","channel":"ticker","instId":"UNIUSDT"},"data":[{"instId":"UNIUSDT","last":"9.9770","bestAsk":"9.978","bestBid":"9.973","high24h":"10.4280","low24h":"9.9030","priceChangePercent":"-0.0393","capitalRate":"-0.000100","nextSettleTime":1649314800000,"systemTime":1649290083306,"markPrice":"9.9741","indexPrice":"9.9869","holding":"369411","baseVolume":"313074","quoteVolume":"3294354"}]}
1649290083.355238: {"action":"snapshot","arg":{"instType":"mc","channel":"ticker","instId":"DASHUSDT"},"data":[{"instId":"DASHUSDT","last":"113.490","bestAsk":"113.5","bestBid":"113.45","high24h":"118.870","low24h":"113.140","priceChangePercent":"-0.035","capitalRate":"-0.000100","nextSettleTime":1649314800000,"systemTime":1649290083315,"markPrice":"113.476","indexPrice":"113.504","holding":"21957.17","baseVolume":"25302.32","quoteVolume":"3062431.67"}]}
1649290083.3553312: {"action":"update","arg":{"instType":"mc","channel":"books","instId":"DASHUSDT"},"data":[{"asks":[["113.49","0.91"],["113.50","7.05"],["113.51","44.30"],["113.52","5.85"],["113.53","11.27"],["113.54","43.25"],["113.55","56.00"],["113.56","71.24"],["113.57","14.18"],["113.58","5.51"],["113.59","81.63"],["113.61","49.11"],["113.62","59.70"],["113.63","75.79"],["113.64","14.57"],["113.65","106.57"],["113.66","11.62"],["113.67","27.49"],["113.68","46.39"],["113.69","84.64"],["113.70","131.52"],["113.71","37.44"],["113.72","49.48"],["113.73","183.20"],["113.74","1600.22"],["113.75","29.60"],["113.76","8.64"],["113.77","815.55"],["113.78","700.04"],["113.81","7.19"],["113.82","24.07"],["113.83","443.77"],["113.87","65.21"],["113.88","556.39"],["113.90","233.62"],["113.92","1903.32"],["113.93","20.54"],["113.94","128.46"],["113.97","276.57"],["113.98","1974.27"],["114.00","0"],["114.01","0"],["114.04","1886.04"],["114.06","0"],["114.10","1996.33"],["114.12","0"],["114.16","2018.39"],["114.18","0"],["114.22","1775.75"],["114.24","0"],["114.28","2040.45"],["114.30","0"],["114.34","1709.57"],["114.36","0"],["114.40","1930.16"],["114.42","0"],["114.46","1863.98"],["114.48","0"],["114.52","1753.69"],["114.54","0"],["114.58","1841.92"],["114.60","0"],["114.64","1819.86"],["114.66","0"],["114.70","1731.63"],["114.72","0"],["114.76","1952.22"],["114.78","0"],["114.82","1908.10"],["114.84","0"]],"bids":[["113.46","0"],["113.45","0"],["113.44","0"],["113.43","1325.72"],["113.42","0"],["113.41","168.31"],["113.40","43.57"],["113.39","20.80"],["113.38","19.68"],["113.37","154.78"],["113.36","23.12"],["113.35","550.09"],["113.34","15.57"],["113.33","40.49"],["113.31","158.45"],["113.30","54.36"],["113.29","168.17"],["113.28","23.06"],["113.26","222.26"],["113.24","115.53"],["113.23","12.90"],["113.22","18.47"],["113.21","5.39"],["113.19","438.13"],["113.18","45.66"],["113.17","41.72"],["113.16","55.13"],["113.15","233.08"],["113.14","576.79"],["113.13","73.01"],["113.11","2.15"],["113.09","1489.61"],["113.08","75.37"],["113.04","30.65"],["113.03","82.52"],["113.02","56.06"],["113.00","2068.41"],["112.98","526.49"],["112.97","117.42"],["112.96","120.83"],["112.95","280.48"],["112.94","1844.14"],["112.93","11.82"],["112.90","0"],["112.88","1709.57"],["112.84","0"],["112.82","1908.10"],["112.78","0"],["112.76","1753.69"],["112.72","0"],["112.70","2018.39"],["112.66","0"],["112.64","1819.86"],["112.60","0"],["112.58","1797.80"],["112.54","0"],["112.52","1952.22"],["112.48","0"],["112.46","1731.63"],["112.42","0"],["112.40","1930.16"],["112.36","0"],["112.34","1996.33"],["112.30","0"],["112.28","1863.98"],["112.24","0"],["112.22","1886.04"],["112.18","0"],["112.16","1775.75"],["112.12","0"],["112.10","1974.27"]],"checksum":1963883711,"ts":"1649290083328"}]}
1649290083.445209: {"action":"update","arg":{"instType":"mc","channel":"books","instId":"UNIUSDT"},"data":[{"asks":[["9.978","416"],["9.979","568"],["9.980","719"],["9.981","181"],["9.982","686"],["9.983","272"],["9.984","1066"],["9.985","892"],["9.986","219"],["9.987","382"],["9.988","315"],["9.989","903"],["9.990","479"],["9.991","886"],["9.992","1516"],["9.993","1270"],["9.994","2725"],["9.995","1033"],["9.996","640"],["9.997","1097"],["9.999","1345"],["10.000","698"],["10.002","566"],["10.004","973"],["10.005","701"],["10.008","784"],["10.009","250"],["10.010","3115"],["10.011","1501"],["10.012","782"],["10.015","954"],["10.021","786"],["10.026","14503"],["10.031","13366"],["10.036","11443"],["10.041","12405"],["10.046","12213"],["10.051","11636"],["10.056","12597"],["10.061","12020"],["10.066","12789"],["10.071","13559"],["10.076","12982"],["10.081","11828"],["10.087","0"],["10.132","5"],["10.138","0"],["10.183","262"],["10.189","0"],["10.234","158"],["10.240","0"],["10.285","292"],["10.292","0"],["10.336","106"],["10.343","0"],["10.387","32"],["10.394","0"],["10.438","152"],["10.445","0"],["10.489","260"],["10.496","0"],["10.540","230"],["10.547","0"],["10.591","307"],["10.598","0"],["10.642","308"],["10.649","0"],["10.693","214"],["10.700","0"],["10.744","208"],["10.751","0"],["10.795","204"],["10.802","0"],["10.846","112"],["10.853","0"],["10.897","39"],["10.904","0"],["10.948","236"],["10.955","0"],["10.999","260"],["11.006","0"],["11.050","80"],["11.057","0"],["11.101","180"],["11.108","0"],["11.152","156"],["11.159","0"],["11.203","228"],["11.210","0"],["11.254","69"],["11.261","0"],["11.305","236"],["11.312","0"],["11.356","267"],["11.363","0"],["11.407","134"],["11.414","0"],["11.458","68"],["11.465","0"],["11.509","31"],["11.560","195"]],"bids":[["9.973","117"],["9.971","401"],["9.970","212"],["9.968","163"],["9.967","115"],["9.966","805"],["9.964","1183"],["9.963","487"],["9.962","97"],["9.961","2119"],["9.960","270"],["9.958","1921"],["9.957","1174"],["9.955","292"],["9.954","283"],["9.951","694"],["9.950","521"],["9.949","784"],["9.947","2877"],["9.946","3326"],["9.945","707"],["9.944","683"],["9.943","922"],["9.941","1078"],["9.940","1014"],["9.934","3804"],["9.925","16196"],["9.924","1876"],["9.920","12405"],["9.915","12020"],["9.910","12597"],["9.905","12789"],["9.900","12213"],["9.890","13559"],["9.885","11443"],["9.880","13366"],["9.875","13174"],["9.870","11636"],["9.818","0"],["9.812","24"],["9.767","0"],["9.761","7"],["9.717","0"],["9.711","345"],["9.667","0"],["9.661","358"],["9.617","0"],["9.611","317"],["9.567","0"],["9.561","24"],["9.517","0"],["9.511","244"],["9.467","0"],["9.461","188"],["9.417","0"],["9.411","49"],["9.367","0"],["9.361","288"],["9.317","0"],["9.311","359"],["9.267","0"],["9.261","348"],["9.217","0"],["9.211","49"],["9.167","0"],["9.161","128"],["9.117","0"],["9.111","9"],["9.067","0"],["9.061","102"],["9.017","0"],["9.011","268"],["8.967","0"],["8.961","24"],["8.917","0"],["8.911","75"],["8.867","0"],["8.861","312"],["8.817","0"],["8.811","269"],["8.767","0"],["8.761","322"],["8.717","0"],["8.711","29"],["8.667","0"],["8.661","245"],["8.617","0"],["8.611","371"],["8.567","0"],["8.561","239"],["8.517","0"],["8.511","34"]],"checksum":-1113568485,"ts":"1649290083416"}]}
1649290083.6207: {"action":"snapshot","arg":{"instType":"mc","channel":"ticker","instId":"UNIUSDT"},"data":[{"instId":"UNIUSDT","last":"9.9770","bestAsk":"9.978","bestBid":"9.973","high24h":"10.4280","low24h":"9.9030","priceChangePercent":"-0.0393","capitalRate":"-0.000100","nextSettleTime":1649314800000,"systemTime":1649290083579,"markPrice":"9.9741","indexPrice":"9.9869","holding":"369411","baseVolume":"313074","quoteVolume":"3294354"}]}
1649290083.620796: {"action":"snapshot","arg":{"instType":"mc","channel":"ticker","instId":"DASHUSDT"},"data":[{"instId":"DASHUSDT","last":"113.490","bestAsk":"113.5","bestBid":"113.45","high24h":"118.870","low24h":"113.140","priceChangePercent":"-0.035","capitalRate":"-0.000100","nextSettleTime":1649314800000,"systemTime":1649290083591,"markPrice":"113.476","indexPrice":"113.504","holding":"21957.17","baseVolume":"25302.32","quoteVolume":"3062431.67"}]}
1649290083.6533241: {"action":"update","arg":{"instType":"mc","channel":"books","instId":"DASHUSDT"},"data":[{"asks":[["113.49","14.00"],["113.50","6.56"],["113.51","40.86"],["113.52","9.17"],["113.53","10.87"],["113.54","50.60"],["113.55","18.10"],["113.57","18.19"],["113.58","19.37"],["113.59","105.83"],["113.60","6.94"],["113.61","8.73"],["113.62","86.26"],["113.63","102.53"],["113.64","13.87"],["113.65","121.22"],["113.67","31.03"],["113.69","84.15"],["113.70","131.68"],["113.71","36.89"],["113.72","51.08"],["113.75","26.63"],["113.77","824.25"],["113.81","5.70"],["113.82","43.15"],["113.83","448.22"],["113.87","71.04"],["113.88","553.42"],["113.91","74.91"],["113.92","1838.41"],["113.97","273.97"],["113.98","2040.45"],["113.99","485.05"],["114.04","1863.98"],["114.10","1908.10"],["114.16","1797.80"],["114.22","1819.86"],["114.28","1709.57"],["114.34","2018.39"],["114.40","1775.75"],["114.46","1974.27"],["114.52","1886.04"],["114.58","1996.33"],["114.64","1930.16"],["114.70","1952.22"],["114.76","1753.69"],["114.82","1841.92"]],"bids":[["113.43","10.13"],["113.41","85.02"],["113.39","11.34"],["113.38","28.74"],["113.37","306.91"],["113.35","299.72"],["113.34","19.92"],["113.33","65.08"],["113.32","16.02"],["113.31","161.84"],["113.30","75.80"],["113.29","172.71"],["113.28","17.54"],["113.27","13.68"],["113.24","28.91"],["113.23","12.91"],["113.22","17.98"],["113.19","431.10"],["113.18","44.20"],["113.17","46.17"],["113.15","132.54"],["113.14","591.63"],["113.10","23.39"],["113.08","73.06"],["113.07","249.40"],["113.02","57.97"],["113.00","2015.22"],["112.98","524.74"],["112.96","126.78"],["112.94","1866.20"],["112.88","1908.10"],["112.82","1709.57"],["112.70","1952.22"],["112.64","1886.04"],["112.58","2040.45"],["112.52","1797.80"],["112.46","1841.92"],["112.40","1731.63"],["112.34","1775.75"],["112.28","2018.39"],["112.22","1974.27"],["112.16","1930.16"],["112.10","1819.86"]],"checksum":-1366164596,"ts":"1649290083626"}]}
1649290083.766051: {"action":"update","arg":{"instType":"mc","channel":"books","instId":"UNIUSDT"},"data":[{"asks":[["9.978","0"],["9.979","413"],["9.980","182"],["9.981","237"],["9.982","752"],["9.983","433"],["9.984","741"],["9.985","402"],["9.986","178"],["9.987","526"],["9.988","246"],["9.989","1087"],["9.990","513"],["9.991","658"],["9.992","905"],["9.993","1216"],["9.994","2825"],["9.995","2207"],["9.996","595"],["9.997","1051"],["9.999","553"],["10.000","1435"],["10.002","523"],["10.004","986"],["10.009","224"],["10.010","3178"],["10.011","1493"],["10.012","367"],["10.013","1365"],["10.026","14118"],["10.027","705"],["10.028","407"],["10.031","12020"],["10.036","11828"],["10.046","13559"],["10.051","12982"],["10.061","13174"],["10.066","11636"],["10.071","13366"],["10.076","11443"],["10.081","12213"],["10.126","5"],["10.132","0"],["10.177","262"],["10.183","0"],["10.228","158"],["10.234","0"],["10.279","292"],["10.285","0"],["10.330","106"],["10.336","0"],["10.381","32"],["10.387","0"],["10.432","152"],["10.438","0"],["10.483","260"],["10.489","0"],["10.534","230"],["10.540","0"],["10.585","307"],["10.591","0"],["10.636","308"],["10.642","0"],["10.687","214"],["10.693","0"],["10.738","208"],["10.744","0"],["10.789","204"],["10.795","0"],["10.840","112"],["10.846","0"],["10.891","39"],["10.897","0"],["10.942","236"],["10.948","0"],["10.993","260"],["10.999","0"],["11.044","80"],["11.050","0"],["11.095","180"],["11.101","0"],["11.146","156"],["11.152","0"],["11.197","228"],["11.203","0"],["11.248","69"],["11.254","0"],["11.299","236"],["11.305","0"],["11.350","267"],["11.356","0"],["11.401","134"],["11.407","0"],["11.452","68"],["11.458","0"],["11.503","31"],["11.509","0"],["11.554","195"],["11.560","0"]],"bids":[["9.973","80"],["9.972","181"],["9.971","259"],["9.970","198"],["9.969","238"],["9.968","15"],["9.967","146"],["9.966","796"],["9.965","593"],["9.964","1156"],["9.963","1075"],["9.962","58"],["9.961","2087"],["9.960","237"],["9.959","389"],["9.958","1573"],["9.957","1265"],["9.956","412"],["9.955","260"],["9.953","649"],["9.952","364"],["9.951","683"],["9.950","667"],["9.948","663"],["9.946","3292"],["9.945","662"],["9.943","2036"],["9.942","941"],["9.941","1342"],["9.939","1179"],["9.934","3900"],["9.933","3337"],["9.931","3563"],["9.930","1914"],["9.927","1161"],["9.926","12680"],["9.925","4369"],["9.924","981"],["9.921","13366"],["9.920","0"],["9.916","12789"],["9.915","0"],["9.911","12405"],["9.910","0"],["9.906","11828"],["9.905","0"],["9.901","12597"],["9.900","0"],["9.896","11636"],["9.895","0"],["9.891","13559"],["9.890","0"],["9.886","12982"],["9.885","0"],["9.881","12020"],["9.880","0"],["9.876","12213"],["9.875","0"],["9.871","13174"],["9.870","0"],["9.812","0"],["9.806","24"],["9.761","0"],["9.755","7"],["9.711","0"],["9.705","345"],["9.661","0"],["9.655","358"],["9.611","0"],["9.605","317"],["9.561","0"],["9.555","24"],["9.511","0"],["9.505","244"],["9.461","0"],["9.455","188"],["9.411","0"],["9.405","49"],["9.361","0"],["9.355","288"],["9.311","0"],["9.305","359"],["9.261","0"],["9.255","348"],["9.211","0"],["9.205","49"],["9.161","0"],["9.155","128"],["9.111","0"],["9.105","9"],["9.061","0"],["9.055","102"],["9.011","0"],["9.005","268"],["8.961","0"],["8.955","24"],["8.911","0"],["8.905","75"],["8.861","0"],["8.855","312"],["8.811","0"],["8.805","269"],["8.761","0"],["8.755","322"],["8.711","0"],["8.705","29"],["8.661","0"],["8.655","245"],["8.611","0"],["8.605","371"],["8.561","0"],["8.555","239"],["8.511","0"],["8.505","34"]],"checksum":1690027501,"ts":"1649290083738"}]}
1649290083.88162: {"action":"snapshot","arg":{"instType":"mc","channel":"ticker","instId":"UNIUSDT"},"data":[{"instId":"UNIUSDT","last":"9.9770","bestAsk":"9.979","bestBid":"9.974","high24h":"10.4280","low24h":"9.9030","priceChangePercent":"-0.0393","capitalRate":"-0.000100","nextSettleTime":1649314800000,"systemTime":1649290083850,"markPrice":"9.9741","indexPrice":"9.9869","holding":"369411","baseVolume":"313074","quoteVolume":"3294354"}]}
1649290083.8911612: {"action":"snapshot","arg":{"instType":"mc","channel":"ticker","instId":"DASHUSDT"},"data":[{"instId":"DASHUSDT","last":"113.490","bestAsk":"113.48","bestBid":"113.43","high24h":"118.870","low24h":"113.140","priceChangePercent":"-0.035","capitalRate":"-0.000100","nextSettleTime":1649314800000,"systemTime":1649290083858,"markPrice":"113.476","indexPrice":"113.504","holding":"21957.17","baseVolume":"25302.32","quoteVolume":"3062431.67"}]}
1649290083.9770648: {"action":"update","arg":{"instType":"mc","channel":"books","instId":"DASHUSDT"},"data":[{"asks":[["113.48","1.63"],["113.49","12.90"],["113.50","26.44"],["113.51","53.26"],["113.52","12.99"],["113.55","9.37"],["113.56","49.01"],["113.57","75.58"],["113.58","19.87"],["113.59","47.46"],["113.60","68.98"],["113.61","19.22"],["113.62","108.13"],["113.64","561.74"],["113.65","127.66"],["113.66","1332.78"],["113.67","28.53"],["113.68","594.92"],["113.69","130.14"],["113.70","140.10"],["113.71","90.68"],["113.72","79.30"],["113.73","37.01"],["113.74","68.32"],["113.75","181.56"],["113.76","7.37"],["113.77","812.10"],["113.78","47.14"],["113.79","29.94"],["113.80","270.33"],["113.82","45.07"],["113.83","326.95"],["113.85","492.72"],["113.87","43.98"],["113.88","273.25"],["113.89","23.14"],["113.90","218.11"],["113.91","2097.75"],["113.92","114.96"],["113.94","125.98"],["113.95","91.12"],["113.96","1488.67"],["113.97","2124.03"],["113.98","0"],["113.99","0"],["114.03","1753.69"],["114.04","0"],["114.09","1819.86"],["114.10","0"],["114.15","1841.92"],["114.16","0"],["114.21","1930.16"],["114.22","0"],["114.27","1775.75"],["114.28","0"],["114.33","1974.27"],["114.34","0"],["114.39","2040.45"],["114.40","0"],["114.45","1952.22"],["114.46","0"],["114.51","1908.10"],["114.52","0"],["114.57","1886.04"],["114.58","0"],["114.63","1709.57"],["114.64","0"],["114.69","1996.33"],["114.70","0"],["114.75","1731.63"],["114.76","0"],["114.81","1797.80"],["114.82","0"],["115.78","0"],["116.00","31.47"],["116.37","0"],["116.59","50.46"],["116.96","0"],["117.18","49.40"],["117.55","0"],["117.77","27.41"],["118.14","0"],["118.36","50.42"],["118.73","0"],["118.95","50.07"],["119.32","0"],["119.54","36.12"],["119.91","0"],["120.13","8.62"],["120.50","0"],["120.72","54.60"],["121.09","0"],["121.31","1.48"],["121.68","0"],["121.90","43.49"],["122.27","0"],["122.49","7.73"],["122.86","0"],["123.08","58.21"],["123.45","0"],["123.67","52.67"],["124.04","0"],["124.26","53.84"],["124.63","0"],["124.85","4.99"],["125.22","0"],["125.44","44.04"],["125.81","0"],["126.03","25.10"],["126.40","0"],["126.62","39.09"],["126.99","0"],["127.21","44.51"],["127.58","0"],["127.80","19.01"],["128.17","0"],["128.39","29.39"],["128.76","0"],["128.98","3.89"],["129.35","0"],["129.57","23.37"],["129.94","0"],["130.16","24.18"],["130.53","0"],["130.75","9.15"],["131.12","0"],["131.34","27.04"],["131.71","0"],["131.93","7.10"],["132.52","13.38"],["133.11","33.57"],["133.70","76.51"]],"bids":[["113.43","13.94"],["113.42","186.13"],["113.41","141.58"],["113.39","20.80"],["113.38","130.79"],["113.37","119.87"],["113.36","1600.14"],["113.35","169.04"],["113.34","12.11"],["113.33","37.97"],["113.32","8.85"],["113.31","13.85"],["113.29","163.31"],["113.28","20.55"],["113.27","2.59"],["113.26","237.61"],["113.25","193.48"],["113.24","30.85"],["113.22","6.26"],["113.21","53.45"],["113.20","67.60"],["113.19","244.98"],["113.18","57.26"],["113.15","156.30"],["113.13","152.71"],["113.12","33.05"],["113.10","31.85"],["113.08","76.36"],["113.04","59.38"],["113.03","78.16"],["113.00","1772.58"],["112.97","113.13"],["112.94","1822.08"],["112.93","0"],["112.88","2018.39"],["112.82","1886.04"],["112.76","2040.45"],["112.70","1797.80"],["112.64","1709.57"],["112.58","1974.27"],["112.52","1908.10"],["112.46","1731.63"],["112.40","1841.92"],["112.34","1863.98"],["112.28","1952.22"],["112.22","1996.33"],["112.10","1775.75"],["111.66","0"],["111.61","44.63"],["111.07","0"],["111.02","97.81"],["110.47","0"],["110.43","40.49"],["109.88","0"],["109.84","85.27"],["109.29","0"],["109.25","84.73"],["108.70","0"],["108.66","59.74"],["108.11","0"],["108.07","61.13"],["107.52","0"],["107.48","33.01"],["106.93","0"],["106.89","56.85"],["106.34","0"],["106.30","24.34"],["105.75","0"],["105.71","1.74"],["105.16","0"],["105.12","57.94"],["104.57","0"],["104.53","58.21"],["103.98","0"],["103.94","46.12"],["103.39","0"],["103.35","52.32"],["102.80","0"],["102.76","45.29"],["102.21","0"],["102.17","22.94"],["101.62","0"],["101.58","36.02"],["101.03","0"],["100.99","38.02"],["100.44","0"],["100.40","53.60"],["99.85","0"],["99.26","0"],["98.67","0"],["98.08","0"],["97.49","0"],["96.90","0"],["96.31","0"],["95.72","0"],["95.13","0"],["94.54","0"],["93.95","0"],["93.36","0"],["92.77","0"],["92.18","0"]],"checksum":-543455538,"ts":"1649290083949"}]}
1649290084.090587: {"action":"update","arg":{"instType":"mc","channel":"books","instId":"UNIUSDT"},"data":[{"asks":[["9.982","250"],["9.983","628"],["9.984","438"],["9.985","283"],["9.986","219"],["9.987","389"],["9.988","356"],["9.989","960"],["9.990","577"],["9.991","882"],["9.992","1244"],["9.993","1270"],["9.994","2802"],["9.996","1192"],["9.997","1003"],["10.000","693"],["10.004","948"],["10.005","696"],["10.007","438"],["10.011","807"],["10.012","390"],["10.016","990"],["10.022","691"],["10.026","1330"],["10.027","13301"],["10.031","0"],["10.032","13366"],["10.036","0"],["10.037","12982"],["10.041","0"],["10.042","11636"],["10.046","0"],["10.047","13559"],["10.051","0"],["10.052","11443"],["10.056","0"],["10.057","13174"],["10.061","0"],["10.062","12020"],["10.066","0"],["10.067","11828"],["10.071","0"],["10.072","12213"],["10.076","0"],["10.077","12789"],["10.081","0"],["10.082","12405"],["10.119","5"],["10.126","0"],["10.170","262"],["10.177","0"],["10.221","158"],["10.228","0"],["10.272","292"],["10.279","0"],["10.323","106"],["10.330","0"],["10.374","32"],["10.381","0"],["10.425","152"],["10.432","0"],["10.476","260"],["10.483","0"],["10.527","230"],["10.534","0"],["10.578","307"],["10.585","0"],["10.629","308"],["10.636","0"],["10.680","214"],["10.687","0"],["10.731","208"],["10.738","0"],["10.782","204"],["10.789","0"],["10.833","112"],["10.840","0"],["10.884","39"],["10.891","0"],["10.935","236"],["10.942","0"],["10.986","260"],["10.993","0"],["11.037","80"],["11.044","0"],["11.088","180"],["11.095","0"],["11.139","156"],["11.146","0"],["11.190","228"],["11.197","0"],["11.241","69"],["11.248","0"],["11.292","236"],["11.299","0"],["11.343","267"],["11.350","0"],["11.394","134"],["11.401","0"],["11.445","68"],["11.452","0"],["11.496","31"],["11.503","0"],["11.547","195"],["11.554","0"]],"bids":[["9.974","199"],["9.973","79"],["9.971","287"],["9.970","223"],["9.969","257"],["9.968","163"],["9.967","235"],["9.966","792"],["9.965","487"],["9.964","866"],["9.963","765"],["9.961","2102"],["9.960","270"],["9.959","448"],["9.958","1607"],["9.957","1245"],["9.956","387"],["9.955","235"],["9.954","294"],["9.952","327"],["9.951","807"],["9.949","833"],["9.948","803"],["9.947","3669"],["9.946","2214"],["9.944","1112"],["9.941","1705"],["9.936","504"],["9.934","3937"],["9.933","3306"],["9.929","429"],["9.927","1115"],["9.926","14026"],["9.924","0"],["9.921","12405"],["9.916","11636"],["9.911","13366"],["9.906","12020"],["9.901","12982"],["9.896","13559"],["9.891","12213"],["9.886","12597"],["9.881","11828"],["9.876","13174"],["9.871","11443"],["9.806","0"],["9.799","24"],["9.755","0"],["9.748","7"],["9.705","0"],["9.698","345"],["9.655","0"],["9.648","358"],["9.605","0"],["9.598","317"],["9.555","0"],["9.548","24"],["9.505","0"],["9.498","244"],["9.455","0"],["9.448","188"],["9.405","0"],["9.398","49"],["9.355","0"],["9.348","288"],["9.305","0"],["9.298","359"],["9.255","0"],["9.248","348"],["9.205","0"],["9.198","49"],["9.155","0"],["9.148","128"],["9.105","0"],["9.098","9"],["9.055","0"],["9.048","102"],["9.005","0"],["8.998","268"],["8.955","0"],["8.948","24"],["8.905","0"],["8.898","75"],["8.855","0"],["8.848","312"],["8.805","0"],["8.798","269"],["8.755","0"],["8.748","322"],["8.705","0"],["8.698","29"],["8.655","0"],["8.648","245"],["8.605","0"],["8.598","371"],["8.555","0"],["8.548","239"],["8.505","0"],["8.498","34"]],"checksum":1057729459,"ts":"1649290084061"}]}
1649290084.157901: {"action":"snapshot","arg":{"instType":"mc","channel":"ticker","instId":"UNIUSDT"},"data":[{"instId":"UNIUSDT","last":"9.9770","bestAsk":"9.979","bestBid":"9.974","high24h":"10.4280","low24h":"9.9030","priceChangePercent":"-0.0393","capitalRate":"-0.000100","nextSettleTime":1649314800000,"systemTime":1649290084125,"markPrice":"9.9741","indexPrice":"9.9869","holding":"369411","baseVolume":"313074","quoteVolume":"3294354"}]}
1649290084.164638: {"action":"snapshot","arg":{"instType":"mc","channel":"ticker","instId":"DASHUSDT"},"data":[{"instId":"DASHUSDT","last":"113.490","bestAsk":"113.48","bestBid":"113.43","high24h":"118.870","low24h":"113.140","priceChangePercent":"-0.035","capitalRate":"-0.000100","nextSettleTime":1649314800000,"systemTime":1649290084132,"markPrice":"113.483","indexPrice":"113.504","holding":"21957.17","baseVolume":"25302.32","quoteVolume":"3062431.67"}]}
1649290084.2236102: {"action":"update","arg":{"instType":"mc","channel":"trade","instId":"UNIUSDT"},"data":[["1649290084119","9.979","3","buy"]]}
1649290084.279779: {"action":"update","arg":{"instType":"mc","channel":"books","instId":"DASHUSDT"},"data":[{"asks":[["113.48","5.57"],["113.52","16.03"],["113.56","71.03"],["113.57","21.78"],["113.58","24.85"],["113.59","89.96"],["113.60","6.94"],["113.61","8.73"],["113.62","106.34"],["113.63","134.36"],["113.64","344.43"],["113.65","116.27"],["113.66","12.78"],["113.67","37.75"],["113.69","1600.02"],["113.70","163.20"],["113.71","237.53"],["113.72","51.00"],["113.73","53.43"],["113.74","8.72"],["113.75","25.47"],["113.77","823.27"],["113.78","128.32"],["113.79","35.50"],["113.80","259.44"],["113.81","10.16"],["113.82","45.34"],["113.83","443.77"],["113.84","58.18"],["113.85","477.87"],["113.87","69.26"],["113.88","292.02"],["113.89","30.40"],["113.90","224.35"],["113.91","1938.88"],["113.92","104.07"],["113.94","128.46"],["113.95","130.74"],["113.96","3.67"],["113.97","2290.56"],["114.03","1952.22"],["114.09","1908.10"],["114.15","1753.69"],["114.27","2040.45"],["114.33","1841.92"],["114.39","1996.33"],["114.45","1819.86"],["114.51","1709.57"],["114.57","1974.27"],["114.63","1886.04"],["114.69","1775.75"],["115.78","0.73"],["116.00","0"],["116.37","68.26"],["116.59","0"],["116.96","70.90"],["117.18","0"],["117.55","49.89"],["117.77","0"],["118.14","22.59"],["118.36","0"],["118.73","47.85"],["118.95","0"],["119.32","46.71"],["119.54","0"],["119.91","23.57"],["120.13","0"],["120.50","59.15"],["120.72","0"],["121.09","6.51"],["121.31","0"],["121.68","54.25"],["121.90","0"],["122.27","14.99"],["122.49","0"],["122.86","11.21"],["123.08","0"],["123.45","66.50"],["123.67","0"],["124.04","64.47"],["124.26","0"],["124.63","42.85"],["124.85","0"],["125.22","29.99"],["125.44","0"],["125.81","4.07"],["126.03","0"],["126.40","26.70"],["126.62","0"],["126.99","20.67"],["127.21","0"],["127.58","56.99"],["127.80","0"],["128.17","44.01"],["128.39","0"],["128.76","46.60"],["128.98","0"],["129.35","39.07"],["129.57","0"],["129.94","19.33"],["130.16","0"],["130.53","20.66"],["130.75","0"],["131.12","28.11"],["131.34","0"],["131.71","13.65"],["131.93","0"],["132.52","0"],["133.11","0"],["133.70","0"]],"bids":[["113.43","11.01"],["113.41","178.21"],["113.39","1600.38"],["113.38","29.37"],["113.37","237.61"],["113.36","8.13"],["113.35","299.72"],["113.34","7.55"],["113.33","33.57"],["113.32","3.86"],["113.31","17.10"],["113.30","96.19"],["113.29","330.12"],["113.28","19.15"],["113.27","13.68"],["113.26","323.18"],["113.25","22.21"],["113.24","29.36"],["113.23","16.18"],["113.21","20.29"],["113.20","52.75"],["113.19","233.10"],["113.18","44.66"],["113.15","171.15"],["113.13","150.79"],["113.12","25.79"],["113.10","23.39"],["113.04","30.65"],["113.03","79.71"],["112.98","527.96"],["112.97","117.42"],["112.94","1976.49"],["112.88","1930.16"],["112.82","2018.39"],["112.76","1709.57"],["112.70","1863.98"],["112.64","1996.33"],["112.58","1841.92"],["112.52","1797.80"],["112.46","1952.22"],["112.40","1886.04"],["112.34","1819.86"],["112.28","2040.45"],["112.22","1775.75"],["112.16","1908.10"],["112.10","1731.63"],["111.66","54.98"],["111.61","0"],["111.07","56.15"],["111.02","0"],["110.47","22.20"],["110.43","0"],["109.88","45.95"],["109.84","0"],["109.29","29.62"],["109.25","0"],["108.70","21.93"],["108.66","0"],["108.11","6.02"],["108.07","0"],["107.52","55.97"],["107.48","0"],["106.93","21.31"],["106.89","0"],["106.34","8.95"],["106.30","0"],["105.75","10.15"],["105.71","0"],["105.16","40.07"],["105.12","0"],["104.57","15.36"],["104.53","0"],["103.98","46.47"],["103.94","0"],["103.39","11.11"],["103.35","0"],["102.80","1.87"],["102.76","0"],["102.21","37.67"],["102.17","0"],["101.62","21.48"],["101.58","0"],["101.03","49.80"],["100.99","0"],["100.44","49.32"],["100.40","0"],["99.85","42.14"],["99.26","8.55"],["98.67","30.36"],["98.08","20.32"],["97.49","36.65"],["96.90","21.95"],["96.31","8.41"],["95.72","31.49"],["95.13","57.35"],["94.54","3.45"],["93.95","4.85"],["93.36","74.35"],["92.77","33.85"],["92.18","20.24"]],"checksum":674358049,"ts":"1649290084247"}]}
1649290084.30129: {"action":"update","arg":{"instType":"mc","channel":"trade","instId":"DASHUSDT"},"data":[["1649290084193","113.45","0.84","buy"]]}
1649290084.42595: {"action":"snapshot","arg":{"instType":"mc","channel":"ticker","instId":"UNIUSDT"},"data":[{"instId":"UNIUSDT","last":"9.9790","bestAsk":"9.979","bestBid":"9.974","high24h":"10.4280","low24h":"9.9030","priceChangePercent":"-0.0393","capitalRate":"-0.000100","nextSettleTime":1649314800000,"systemTime":1649290084391,"markPrice":"9.9755","indexPrice":"9.9868","holding":"369411","baseVolume":"313074","quoteVolume":"3294354"}]}
1649290084.4316318: {"action":"snapshot","arg":{"instType":"mc","channel":"ticker","instId":"DASHUSDT"},"data":[{"instId":"DASHUSDT","last":"113.450","bestAsk":"113.48","bestBid":"113.43","high24h":"118.870","low24h":"113.140","priceChangePercent":"-0.035","capitalRate":"-0.000100","nextSettleTime":1649314800000,"systemTime":1649290084402,"markPrice":"113.483","indexPrice":"113.504","holding":"21957.17","baseVolume":"25302.32","quoteVolume":"3062431.67"}]}
1649290084.4317288: {"action":"update","arg":{"instType":"mc","channel":"books","instId":"UNIUSDT"},"data":[{"asks":[["9.979","445"],["9.980","360"],["9.982","190"],["9.983","433"],["9.984","742"],["9.985","450"],["9.987","404"],["9.988","450"],["9.989","1070"],["9.990","1011"],["9.991","572"],["9.993","750"],["9.994","2857"],["9.996","1147"],["9.997","1137"],["10.000","657"],["10.001","1393"],["10.002","451"],["10.004","399"],["10.005","684"],["10.008","979"],["10.012","1309"],["10.013","1303"],["10.014","7278"],["10.018","459"],["10.019","621"],["10.022","679"],["10.027","13109"],["10.032","13174"],["10.037","12789"],["10.047","11828"],["10.052","13559"],["10.057","12982"],["10.062","11443"],["10.067","12020"],["10.072","13366"],["10.077","12213"],["10.082","12597"],["10.112","5"],["10.119","0"],["10.163","262"],["10.170","0"],["10.214","158"],["10.221","0"],["10.265","292"],["10.272","0"],["10.316","106"],["10.323","0"],["10.367","32"],["10.374","0"],["10.418","152"],["10.425","0"],["10.469","260"],["10.476","0"],["10.520","230"],["10.527","0"],["10.571","307"],["10.578","0"],["10.622","308"],["10.629","0"],["10.673","214"],["10.680","0"],["10.724","208"],["10.731","0"],["10.775","204"],["10.782","0"],["10.826","112"],["10.833","0"],["10.877","39"],["10.884","0"],["10.928","236"],["10.935","0"],["10.979","260"],["10.986","0"],["11.030","80"],["11.037","0"],["11.081","180"],["11.088","0"],["11.132","156"],["11.139","0"],["11.183","228"],["11.190","0"],["11.234","69"],["11.241","0"],["11.285","236"],["11.292","0"],["11.336","267"],["11.343","0"],["11.387","134"],["11.394","0"],["11.438","68"],["11.445","0"],["11.489","31"],["11.496","0"],["11.540","195"],["11.547","0"]],"bids":[["9.974","9"],["9.973","139"],["9.971","258"],["9.968","120"],["9.967","302"],["9.966","90"],["9.965","261"],["9.964","1577"],["9.963","673"],["9.961","2135"],["9.960","281"],["9.959","389"],["9.957","1269"],["9.956","444"],["9.953","578"],["9.950","718"],["9.949","874"],["9.947","1196"],["9.944","4825"],["9.941","1739"],["9.938","765"],["9.934","3900"],["9.933","3182"],["9.927","1161"],["9.926","13065"],["9.921","12597"],["9.916","13366"],["9.911","11636"],["9.906","12213"],["9.901","13559"],["9.896","13174"],["9.891","12982"],["9.886","12405"],["9.881","12789"],["9.876","11443"],["9.871","12020"],["9.799","0"],["9.792","24"],["9.748","0"],["9.741","7"],["9.698","0"],["9.691","345"],["9.648","0"],["9.641","358"],["9.598","0"],["9.591","317"],["9.548","0"],["9.541","24"],["9.498","0"],["9.491","244"],["9.448","15"],["9.441","188"],["9.398","0"],["9.391","49"],["9.348","0"],["9.341","288"],["9.298","0"],["9.291","359"],["9.248","0"],["9.241","348"],["9.198","0"],["9.191","49"],["9.148","0"],["9.141","128"],["9.098","0"],["9.091","9"],["9.048","0"],["9.041","102"],["8.998","0"],["8.991","268"],["8.948","0"],["8.941","24"],["8.898","0"],["8.891","75"],["8.848","0"],["8.841","312"],["8.798","0"],["8.791","269"],["8.748","0"],["8.741","322"],["8.698","0"],["8.691","29"],["8.648","0"],["8.641","245"],["8.598","0"],["8.591","371"],["8.548","0"],["8.541","239"],["8.498","0"],["8.491","34"]],"checksum":-372875796,"ts":"1649290084404"}]}
1649290084.4629278: {"action":"update","arg":{"instType":"mc","channel":"candle1m","instId":"UNIUSDT"},"data":[["1649290080000","9.977","9.979","9.977","9.979","4"]]}
1649290084.583176: {"action":"update","arg":{"instType":"mc","channel":"books","instId":"DASHUSDT"},"data":[{"asks":[["113.48","0"],["113.50","10.19"],["113.52","18.22"],["113.54","31.74"],["113.55","14.32"],["113.56","72.03"],["113.57","79.52"],["113.58","19.87"],["113.59","91.27"],["113.60","74.26"],["113.61","19.22"],["113.62","62.42"],["113.63","75.29"],["113.64","561.74"],["113.65","116.87"],["113.66","1332.78"],["113.67","29.81"],["113.69","130.14"],["113.70","140.10"],["113.71","152.06"],["113.72","51.99"],["113.73","54.92"],["113.74","38.52"],["113.75","184.53"],["113.76","8.64"],["113.78","47.14"],["113.79","117.06"],["113.80","270.33"],["113.81","5.70"],["113.83","326.95"],["113.85","492.72"],["113.87","42.20"],["113.88","137.08"],["113.89","23.14"],["113.90","218.74"],["113.91","79.37"],["113.92","1846.58"],["113.94","125.98"],["113.95","91.12"],["113.96","1488.67"],["113.97","260.06"],["113.98","1996.33"],["113.99","963.28"],["114.03","0"],["114.04","1863.98"],["114.09","0"],["114.10","1797.80"],["114.15","0"],["114.16","1841.92"],["114.21","0"],["114.22","1908.10"],["114.27","0"],["114.28","1930.16"],["114.33","0"],["114.34","2040.45"],["114.39","0"],["114.40","1753.69"],["114.45","0"],["114.46","1819.86"],["114.51","0"],["114.52","1709.57"],["114.57","0"],["114.58","2018.39"],["114.63","0"],["114.64","1952.22"],["114.69","0"],["114.70","1886.04"],["114.75","0"],["114.76","1974.27"],["114.81","0"],["114.82","1775.75"],["115.78","0"],["116.00","31.47"],["116.37","0"],["116.59","50.46"],["116.96","0"],["117.18","49.40"],["117.55","0"],["117.77","27.41"],["118.14","0"],["118.36","50.42"],["118.73","0"],["118.95","50.07"],["119.32","0"],["119.54","36.12"],["119.91","0"],["120.13","8.62"],["120.50","0"],["120.72","54.60"],["121.09","0"],["121.31","1.48"],["121.68","0"],["121.90","43.49"],["122.27","0"],["122.49","7.73"],["122.86","0"],["123.08","58.21"],["123.45","0"],["123.67","52.67"],["124.04","0"],["124.26","53.84"],["124.63","0"],["124.85","4.99"],["125.22","0"],["125.44","44.04"],["125.81","0"],["126.03","25.10"],["126.40","0"],["126.62","39.09"],["126.99","0"],["127.21","44.51"],["127.58","0"],["127.80","19.01"],["128.17","0"],["128.39","29.39"],["128.76","0"],["128.98","3.89"],["129.35","0"],["129.57","23.37"],["129.94","0"],["130.16","24.18"],["130.53","0"],["130.75","9.15"],["131.12","0"],["131.34","27.04"],["131.71","0"],["131.93","7.10"],["132.52","13.38"],["133.11","33.57"],["133.70","76.51"]],"bids":[["113.43","8.99"],["113.41","21.79"],["113.39","10.50"],["113.38","52.25"],["113.37","122.60"],["113.36","69.11"],["113.35","173.87"],["113.34","1600.10"],["113.33","37.97"],["113.32","23.56"],["113.31","18.95"],["113.30","75.80"],["113.29","27.68"],["113.28","20.55"],["113.27","2.59"],["113.26","368.72"],["113.25","35.57"],["113.24","30.85"],["113.21","189.08"],["113.20","212.08"],["113.19","244.98"],["113.18","55.35"],["113.17","41.72"],["113.15","156.30"],["113.14","596.41"],["113.12","33.05"],["113.10","34.82"],["113.09","6.31"],["113.04","59.38"],["113.03","75.35"],["113.02","1550.27"],["113.00","2037.28"],["112.97","113.13"],["112.94","1777.97"],["112.88","1908.10"],["112.82","1841.92"],["112.76","1753.69"],["112.70","1709.57"],["112.64","1731.63"],["112.58","1952.22"],["112.52","1886.04"],["112.46","1797.80"],["112.40","2040.45"],["112.34","1996.33"],["112.28","1819.86"],["112.22","1930.16"],["112.16","1974.27"],["112.10","1863.98"],["111.66","0"],["111.61","44.63"],["111.07","0"],["111.02","97.81"],["110.47","0"],["110.43","40.49"],["109.88","0"],["109.84","85.27"],["109.29","0"],["109.25","84.73"],["108.70","0"],["108.66","59.74"],["108.11","0"],["108.07","61.13"],["107.52","0"],["107.48","33.01"],["106.93","0"],["106.89","56.85"],["106.34","0"],["106.30","24.34"],["105.75","0"],["105.71","1.74"],["105.16","0"],["105.12","57.94"],["104.57","0"],["104.53","58.21"],["103.98","0"],["103.94","46.12"],["103.39","0"],["103.35","52.32"],["102.80","0"],["102.76","45.29"],["102.21","0"],["102.17","22.94"],["101.62","0"],["101.58","36.02"],["101.03","0"],["100.99","38.02"],["100.44","0"],["100.40","53.60"],["99.85","0"],["99.26","0"],["98.67","0"],["98.08","0"],["97.49","0"],["96.90","0"],["96.31","0"],["95.72","0"],["95.13","0"],["94.54","0"],["93.95","0"],["93.36","0"],["92.77","0"],["92.18","0"]],"checksum":251746077,"ts":"1649290084553"}]}
1649290084.692621: {"action":"snapshot","arg":{"instType":"mc","channel":"ticker","instId":"UNIUSDT"},"data":[{"instId":"UNIUSDT","last":"9.9790","bestAsk":"9.978","bestBid":"9.973","high24h":"10.4280","low24h":"9.9030","priceChangePercent":"-0.0391","capitalRate":"-0.000100","nextSettleTime":1649314800000,"systemTime":1649290084660,"markPrice":"9.9755","indexPrice":"9.9868","holding":"369411","baseVolume":"313077","quoteVolume":"3294384"}]}
1649290084.7065868: {"action":"snapshot","arg":{"instType":"mc","channel":"ticker","instId":"DASHUSDT"},"data":[{"instId":"DASHUSDT","last":"113.450","bestAsk":"113.49","bestBid":"113.43","high24h":"118.870","low24h":"113.140","priceChangePercent":"-0.035","capitalRate":"-0.000100","nextSettleTime":1649314800000,"systemTime":1649290084673,"markPrice":"113.483","indexPrice":"113.504","holding":"21957.17","baseVolume":"25302.32","quoteVolume":"3062431.67"}]}
1649290084.749409: {"action":"update","arg":{"instType":"mc","channel":"books","instId":"UNIUSDT"},"data":[{"asks":[["9.979","442"],["9.981","316"],["9.982","767"],["9.983","384"],["9.984","394"],["9.986","176"],["9.988","438"],["9.990","1054"],["9.991","585"],["9.992","1201"],["9.997","1029"],["10.004","689"],["10.005","832"],["10.007","283"],["10.010","937"],["10.012","1269"],["10.019","819"],["10.021","192"],["10.022","256"],["10.023","7707"],["10.027","14070"],["10.032","13559"],["10.042","13174"],["10.047","12020"],["10.052","12213"],["10.057","12405"],["10.062","12982"],["10.067","11636"],["10.072","11828"],["10.077","11443"],["10.106","5"],["10.112","0"],["10.157","262"],["10.163","0"],["10.208","158"],["10.214","0"],["10.259","292"],["10.265","0"],["10.310","106"],["10.316","0"],["10.361","32"],["10.367","0"],["10.412","152"],["10.418","0"],["10.463","260"],["10.469","0"],["10.514","230"],["10.520","0"],["10.565","307"],["10.571","0"],["10.616","308"],["10.622","0"],["10.667","214"],["10.673","0"],["10.718","208"],["10.724","0"],["10.769","204"],["10.775","0"],["10.820","112"],["10.826","0"],["10.871","39"],["10.877","0"],["10.922","236"],["10.928","0"],["10.973","260"],["10.979","0"],["11.024","80"],["11.030","0"],["11.075","180"],["11.081","0"],["11.126","156"],["11.132","0"],["11.177","228"],["11.183","0"],["11.228","69"],["11.234","0"],["11.279","236"],["11.285","0"],["11.330","267"],["11.336","0"],["11.381","134"],["11.387","0"],["11.432","68"],["11.438","0"],["11.483","31"],["11.489","0"],["11.534","195"],["11.540","0"]],"bids":[["9.973","157"],["9.972","249"],["9.970","184"],["9.969","234"],["9.968","207"],["9.967","227"],["9.966","329"],["9.965","226"],["9.964","2414"],["9.961","2254"],["9.960","323"],["9.958","1580"],["9.957","1275"],["9.956","469"],["9.955","281"],["9.954","300"],["9.951","700"],["9.950","516"],["9.949","1048"],["9.948","661"],["9.942","915"],["9.939","1156"],["9.935","217"],["9.933","3306"],["9.930","1716"],["9.928","7269"],["9.926","13648"],["9.921","13559"],["9.916","13174"],["9.911","11828"],["9.906","13366"],["9.901","12789"],["9.896","11636"],["9.891","11443"],["9.886","12597"],["9.881","12405"],["9.876","12982"],["9.792","0"],["9.786","24"],["9.741","0"],["9.735","7"],["9.691","0"],["9.685","345"],["9.641","0"],["9.635","358"],["9.591","0"],["9.585","317"],["9.541","0"],["9.535","24"],["9.491","0"],["9.485","244"],["9.441","0"],["9.435","188"],["9.391","0"],["9.385","49"],["9.341","0"],["9.335","288"],["9.291","0"],["9.285","359"],["9.241","0"],["9.235","348"],["9.191","0"],["9.185","49"],["9.141","0"],["9.135","128"],["9.091","0"],["9.085","9"],["9.041","0"],["9.035","102"],["8.991","0"],["8.985","268"],["8.941","0"],["8.935","24"],["8.891","0"],["8.885","75"],["8.841","0"],["8.835","312"],["8.791","0"],["8.785","269"],["8.741","0"],["8.735","322"],["8.691","0"],["8.685","29"],["8.641","0"],["8.635","245"],["8.591","0"],["8.585","371"],["8.541","0"],["8.535","239"],["8.491","0"],["8.485","34"]],"checksum":74825344,"ts":"1649290084719"}]}
1649290084.918581: {"action":"update","arg":{"instType":"mc","channel":"books","instId":"DASHUSDT"},"data":[{"asks":[["113.48","7.19"],["113.50","13.37"],["113.52","19.33"],["113.54","50.60"],["113.55","9.37"],["113.56","60.10"],["113.57","66.95"],["113.58","35.88"],["113.59","48.61"],["113.67","24.11"],["113.77","827.06"],["113.91","2119.81"],["113.92","114.96"],["113.94","135.88"],["113.97","2168.15"],["113.98","0"],["113.99","0"],["114.03","1996.33"],["114.04","0"],["114.09","1731.63"],["114.10","0"],["114.15","1841.92"],["114.16","0"],["114.21","1775.75"],["114.22","0"],["114.27","1886.04"],["114.28","0"],["114.33","1974.27"],["114.34","0"],["114.39","1930.16"],["114.40","0"],["114.45","1753.69"],["114.46","0"],["114.51","2018.39"],["114.52","0"],["114.57","1863.98"],["114.58","0"],["114.63","1819.86"],["114.64","0"],["114.69","1952.22"],["114.70","0"],["114.75","1797.80"],["114.76","0"],["114.81","1709.57"],["114.82","0"],["115.78","0.73"],["116.00","0"],["116.37","68.26"],["116.59","0"],["116.96","70.90"],["117.18","0"],["117.55","49.89"],["117.77","0"],["118.14","22.59"],["118.36","0"],["118.73","47.85"],["118.95","0"],["119.32","46.71"],["119.54","0"],["119.91","23.57"],["120.13","0"],["120.50","59.15"],["120.72","0"],["121.09","6.51"],["121.31","0"],["121.68","54.25"],["121.90","0"],["122.27","14.99"],["122.49","0"],["122.86","11.21"],["123.08","0"],["123.45","66.50"],["123.67","0"],["124.04","64.47"],["124.26","0"],["124.63","42.85"],["124.85","0"],["125.22","29.99"],["125.44","0"],["125.81","4.07"],["126.03","0"],["126.40","26.70"],["126.62","0"],["126.99","20.67"],["127.21","0"],["127.58","56.99"],["127.80","0"],["128.17","44.01"],["128.39","0"],["128.76","46.60"],["128.98","0"],["129.35","39.07"],["129.57","0"],["129.94","19.33"],["130.16","0"],["130.53","20.66"],["130.75","0"],["131.12","28.11"],["131.34","0"],["131.71","13.65"],["131.93","0"],["132.52","0"],["133.11","0"],["133.70","0"]],"bids":[["113.43","40.34"],["113.39","20.80"],["113.36","8.72"],["113.35","233.41"],["113.32","20.70"],["113.27","5.31"],["113.25","24.94"],["113.23","28.92"],["113.21","382.86"],["113.20","55.03"],["113.15","117.69"],["113.10","15.75"],["113.05","880.15"],["113.01","38.61"],["113.00","1813.89"],["112.99","20.01"],["112.94","1932.38"],["112.88","1797.80"],["112.82","1753.69"],["112.76","2018.39"],["112.70","1886.04"],["112.64","2040.45"],["112.58","1863.98"],["112.52","1731.63"],["112.46","1974.27"],["112.40","1709.57"],["112.34","1841.92"],["112.28","1952.22"],["112.22","1908.10"],["112.16","1819.86"],["112.10","1996.33"],["111.66","54.98"],["111.61","0"],["111.07","56.15"],["111.02","0"],["110.47","22.20"],["110.43","0"],["109.88","45.95"],["109.84","0"],["109.29","29.62"],["109.25","0"],["108.70","21.93"],["108.66","0"],["108.11","6.02"],["108.07","0"],["107.52","55.97"],["107.48","0"],["106.93","21.31"],["106.89","0"],["106.34","8.95"],["106.30","0"],["105.75","10.15"],["105.71","0"],["105.16","40.07"],["105.12","0"],["104.57","15.36"],["104.53","0"],["103.98","46.47"],["103.94","0"],["103.39","11.11"],["103.35","0"],["102.80","1.87"],["102.76","0"],["102.21","37.67"],["102.17","0"],["101.62","21.48"],["101.58","0"],["101.03","49.80"],["100.99","0"],["100.44","49.32"],["100.40","0"],["99.85","42.14"],["99.26","8.55"],["98.67","30.36"],["98.08","20.32"],["97.49","36.65"],["96.90","21.95"],["96.31","8.41"],["95.72","31.49"],["95.13","57.35"],["94.54","3.45"],["93.95","4.85"],["93.36","74.35"],["92.77","33.85"],["92.18","20.24"]],"checksum":617382819,"ts":"1649290084891"}]}
1649290084.943978: {"action":"snapshot","arg":{"instType":"mc","channel":"ticker","instId":"UNIUSDT"},"data":[{"instId":"UNIUSDT","last":"9.9790","bestAsk":"9.979","bestBid":"9.974","high24h":"10.4280","low24h":"9.9030","priceChangePercent":"-0.0391","capitalRate":"-0.000100","nextSettleTime":1649314800000,"systemTime":1649290084917,"markPrice":"9.9755","indexPrice":"9.9868","holding":"369411","baseVolume":"313077","quoteVolume":"3294384"}]}
1649290084.955563: {"action":"snapshot","arg":{"instType":"mc","channel":"ticker","instId":"DASHUSDT"},"data":[{"instId":"DASHUSDT","last":"113.450","bestAsk":"113.48","bestBid":"113.43","high24h":"118.870","low24h":"113.140","priceChangePercent":"-0.035","capitalRate":"-0.000100","nextSettleTime":1649314800000,"systemTime":1649290084924,"markPrice":"113.475","indexPrice":"113.504","holding":"21957.17","baseVolume":"25302.32","quoteVolume":"3062431.67"}]}
1649290085.044669: {"action":"update","arg":{"instType":"mc","channel":"books","instId":"UNIUSDT"},"data":[{"asks":[["9.979","251"],["9.980","182"],["9.982","403"],["9.984","566"],["9.985","494"],["9.986","477"],["9.987","514"],["9.988","834"],["9.989","1094"],["9.990","1003"],["9.991","629"],["9.992","997"],["9.993","950"],["9.994","2789"],["9.995","2042"],["9.999","607"],["10.003","953"],["10.004","701"],["10.010","3178"],["10.011","911"],["10.012","1289"],["10.021","172"],["10.022","694"],["10.027","12917"],["10.032","12597"],["10.037","12020"],["10.042","12982"],["10.047","11828"],["10.052","12405"],["10.057","13174"],["10.062","11636"],["10.067","13366"],["10.072","13559"],["10.077","12789"],["10.082","11443"],["10.100","5"],["10.106","0"],["10.151","262"],["10.157","0"],["10.202","158"],["10.208","0"],["10.253","292"],["10.259","0"],["10.304","106"],["10.310","0"],["10.355","32"],["10.361","0"],["10.406","152"],["10.412","0"],["10.457","260"],["10.463","0"],["10.508","230"],["10.514","0"],["10.559","307"],["10.565","0"],["10.610","308"],["10.616","0"],["10.661","214"],["10.667","0"],["10.712","208"],["10.718","0"],["10.763","204"],["10.769","0"],["10.814","112"],["10.820","0"],["10.865","39"],["10.871","0"],["10.916","236"],["10.922","0"],["10.967","260"],["10.973","0"],["11.018","80"],["11.024","0"],["11.069","180"],["11.075","0"],["11.120","156"],["11.126","0"],["11.171","228"],["11.177","0"],["11.222","69"],["11.228","0"],["11.273","236"],["11.279","0"],["11.324","267"],["11.330","0"],["11.375","134"],["11.381","0"],["11.426","68"],["11.432","0"],["11.477","31"],["11.483","0"],["11.528","195"],["11.534","0"]],"bids":[["9.972","167"],["9.969","196"],["9.967","279"],["9.966","229"],["9.964","2246"],["9.962","415"],["9.961","2114"],["9.959","538"],["9.958","1137"],["9.956","390"],["9.954","379"],["9.953","612"],["9.951","728"],["9.950","733"],["9.949","848"],["9.946","2185"],["9.942","997"],["9.933","3182"],["9.932","844"],["9.926","14609"],["9.921","12213"],["9.916","12597"],["9.911","11443"],["9.906","12405"],["9.901","12982"],["9.896","12789"],["9.891","13559"],["9.886","12020"],["9.881","11636"],["9.876","11828"],["9.871","13366"],["9.786","0"],["9.780","24"],["9.735","0"],["9.729","7"],["9.685","0"],["9.679","345"],["9.635","0"],["9.629","358"],["9.585","0"],["9.579","317"],["9.535","0"],["9.529","24"],["9.485","0"],["9.479","244"],["9.435","0"],["9.429","188"],["9.385","0"],["9.379","49"],["9.335","0"],["9.329","288"],["9.285","0"],["9.279","359"],["9.235","0"],["9.229","348"],["9.185","0"],["9.179","49"],["9.135","0"],["9.129","128"],["9.085","0"],["9.079","9"],["9.035","0"],["9.029","102"],["8.985","0"],["8.979","268"],["8.935","0"],["8.929","24"],["8.885","0"],["8.879","75"],["8.835","0"],["8.829","312"],["8.785","0"],["8.779","269"],["8.735","0"],["8.729","322"],["8.685","0"],["8.679","29"],["8.635","0"],["8.629","245"],["8.585","0"],["8.579","371"],["8.535","0"],["8.529","239"],["8.485","0"],["8.479","34"]],"checksum":1774996946,"ts":"1649290085017"}]}
1649290085.1020858: {"action":"update","arg":{"instType":"mc","channel":"candle1m","instId":"DASHUSDT"},"data":[["1649290080000","113.37","113.49","113.37","113.45","1.27"]]}
1649290085.2037: {"action":"snapshot","arg":{"instType":"mc","channel":"ticker","instId":"UNIUSDT"},"data":[{"instId":"UNIUSDT","last":"9.9790","bestAsk":"9.979","bestBid":"9.974","high24h":"10.4280","low24h":"9.9030","priceChangePercent":"-0.0391","capitalRate":"-0.000100","nextSettleTime":1649314800000,"systemTime":1649290085171,"markPrice":"9.9770","indexPrice":"9.9868","holding":"369411","baseVolume":"313077","quoteVolume":"3294384"}]}
1649290085.2092092: {"action":"snapshot","arg":{"instType":"mc","channel":"ticker","instId":"DASHUSDT"},"data":[{"instId":"DASHUSDT","last":"113.450","bestAsk":"113.48","bestBid":"113.43","high24h":"118.870","low24h":"113.140","priceChangePercent":"-0.035","capitalRate":"-0.000100","nextSettleTime":1649314800000,"systemTime":1649290085176,"markPrice":"113.475","indexPrice":"113.504","holding":"21957.17","baseVolume":"25303.16","quoteVolume":"3062526.96"}]}
1649290085.231925: {"action":"update","arg":{"instType":"mc","channel":"books","instId":"DASHUSDT"},"data":[{"asks":[["113.50","20.05"],["113.57","67.05"],["113.65","130.20"],["113.69","48.78"],["113.71","153.05"],["113.72","52.51"],["113.75","185.66"],["113.97","2101.97"],["114.03","1908.10"],["114.09","1775.75"],["114.15","1709.57"],["114.21","1731.63"],["114.27","1797.80"],["114.33","1930.16"],["114.39","1974.27"],["114.63","1996.33"],["114.69","1819.86"],["114.75","1952.22"],["114.81","1886.04"],["115.78","0"],["116.00","31.47"],["116.37","0"],["116.59","50.46"],["116.96","0"],["117.18","49.40"],["117.55","0"],["117.77","27.41"],["118.14","0"],["118.36","50.42"],["118.73","0"],["118.95","50.07"],["119.32","0"],["119.54","36.12"],["119.91","0"],["120.13","8.62"],["120.50","0"],["120.72","54.60"],["121.09","0"],["121.31","1.48"],["121.68","0"],["121.90","43.49"],["122.27","0"],["122.49","7.73"],["122.86","0"],["123.08","58.21"],["123.45","0"],["123.67","52.67"],["124.04","0"],["124.26","53.84"],["124.63","0"],["124.85","4.99"],["125.22","0"],["125.44","44.04"],["125.81","0"],["126.03","25.10"],["126.40","0"],["126.62","39.09"],["126.99","0"],["127.21","44.51"],["127.58","0"],["127.80","19.01"],["128.17","0"],["128.39","29.39"],["128.76","0"],["128.98","3.89"],["129.35","0"],["129.57","23.37"],["129.94","0"],["130.16","24.18"],["130.53","0"],["130.75","9.15"],["131.12","0"],["131.34","27.04"],["131.71","0"],["131.93","7.10"],["132.52","13.38"],["133.11","33.57"],["133.70","76.51"]],"bids":[["113.43","38.45"],["113.38","52.28"],["113.37","119.47"],["113.36","7.29"],["113.35","234.13"],["113.23","22.38"],["113.19","242.32"],["113.16","54.83"],["113.15","134.13"],["113.14","595.74"],["113.13","140.88"],["113.08","84.29"],["113.00","2078.59"],["112.94","1844.14"],["112.88","2018.39"],["112.82","1974.27"],["112.76","1797.80"],["112.70","1930.16"],["112.64","1731.63"],["112.58","1819.86"],["112.52","1952.22"],["112.46","1886.04"],["112.40","1753.69"],["112.34","1709.57"],["112.28","1775.75"],["112.22","1996.33"],["112.16","1863.98"],["112.10","1908.10"],["111.66","0"],["111.61","44.63"],["111.07","0"],["111.02","97.81"],["110.47","0"],["110.43","40.49"],["109.88","0"],["109.84","85.27"],["109.29","0"],["109.25","84.73"],["108.70","0"],["108.66","59.74"],["108.11","0"],["108.07","61.13"],["107.52","0"],["107.48","33.01"],["106.93","0"],["106.89","56.85"],["106.34","0"],["106.30","24.34"],["105.75","0"],["105.71","1.74"],["105.16","0"],["105.12","57.94"],["104.57","0"],["104.53","58.21"],["103.98","0"],["103.94","46.12"],["103.39","0"],["103.35","52.32"],["102.80","0"],["102.76","45.29"],["102.21","0"],["102.17","22.94"],["101.62","0"],["101.58","36.02"],["101.03","0"],["100.99","38.02"],["100.44","0"],["100.40","53.60"],["99.85","0"],["99.26","0"],["98.67","0"],["98.08","0"],["97.49","0"],["96.90","0"],["96.31","0"],["95.72","0"],["95.13","0"],["94.54","0"],["93.95","0"],["93.36","0"],["92.77","0"],["92.18","0"]],"checksum":-1209475926,"ts":"1649290085204"}]}
1649290085.353836: {"action":"update","arg":{"instType":"mc","channel":"books","instId":"UNIUSDT"},"data":[{"asks":[["9.980","194"],["9.981","237"],["9.987","353"],["9.989","1123"],["9.991","643"],["9.992","986"],["9.996","1071"],["10.002","386"],["10.010","3190"],["10.012","1304"],["10.016","874"],["10.021","192"],["10.022","679"],["10.027","12532"],["10.037","11443"],["10.042","12020"],["10.047","13366"],["10.052","12213"],["10.057","12982"],["10.062","13174"],["10.067","13559"],["10.072","12405"],["10.082","11636"],["10.094","5"],["10.100","0"],["10.145","262"],["10.151","0"],["10.196","158"],["10.202","0"],["10.247","292"],["10.253","0"],["10.298","106"],["10.304","0"],["10.349","32"],["10.355","0"],["10.400","152"],["10.406","0"],["10.451","260"],["10.457","0"],["10.502","230"],["10.508","0"],["10.553","307"],["10.559","0"],["10.604","308"],["10.610","0"],["10.655","214"],["10.661","0"],["10.706","208"],["10.712","0"],["10.757","204"],["10.763","0"],["10.808","112"],["10.814","0"],["10.859","39"],["10.865","0"],["10.910","236"],["10.916","0"],["10.961","260"],["10.967","0"],["11.012","80"],["11.018","0"],["11.063","180"],["11.069","0"],["11.114","156"],["11.120","0"],["11.165","228"],["11.171","0"],["11.216","69"],["11.222","0"],["11.267","236"],["11.273","0"],["11.318","267"],["11.324","0"],["11.369","134"],["11.375","0"],["11.420","68"],["11.426","0"],["11.471","31"],["11.477","0"],["11.522","195"],["11.528","0"]],"bids":[["9.970","212"],["9.969","263"],["9.966","42"],["9.964","2260"],["9.962","935"],["9.958","1169"],["9.955","309"],["9.953","578"],["9.952","272"],["9.951","625"],["9.945","726"],["9.942","928"],["9.929","415"],["9.926","14994"],["9.921","12597"],["9.916","12213"],["9.911","13366"],["9.906","13174"],["9.901","12789"],["9.896","11636"],["9.891","12020"],["9.886","12405"],["9.881","12982"],["9.871","11443"],["9.780","0"],["9.774","24"],["9.729","0"],["9.723","7"],["9.679","0"],["9.673","345"],["9.629","0"],["9.623","358"],["9.579","0"],["9.573","317"],["9.529","0"],["9.523","24"],["9.479","0"],["9.473","244"],["9.429","0"],["9.423","188"],["9.379","0"],["9.373","49"],["9.329","0"],["9.323","288"],["9.279","0"],["9.273","359"],["9.229","0"],["9.223","348"],["9.179","0"],["9.173","49"],["9.129","0"],["9.123","128"],["9.079","0"],["9.073","9"],["9.029","0"],["9.023","102"],["8.979","0"],["8.973","268"],["8.929","0"],["8.923","24"],["8.879","0"],["8.873","75"],["8.829","0"],["8.823","312"],["8.779","0"],["8.773","269"],["8.729","0"],["8.723","322"],["8.679","0"],["8.673","29"],["8.629","0"],["8.623","245"],["8.579","0"],["8.573","371"],["8.529","0"],["8.523","239"],["8.479","0"],["8.473","34"]],"checksum":-360268552,"ts":"1649290085326"}]}
1649290085.459102: {"action":"snapshot","arg":{"instType":"mc","channel":"ticker","instId":"UNIUSDT"},"data":[{"instId":"UNIUSDT","last":"9.9790","bestAsk":"9.979","bestBid":"9.974","high24h":"10.4280","low24h":"9.9030","priceChangePercent":"-0.0391","capitalRate":"-0.000100","nextSettleTime":1649314800000,"systemTime":1649290085430,"markPrice":"9.9770","indexPrice":"9.9868","holding":"369411","baseVolume":"313077","quoteVolume":"3294384"}]}
1649290085.477416: {"action":"snapshot","arg":{"instType":"mc","channel":"ticker","instId":"DASHUSDT"},"data":[{"instId":"DASHUSDT","last":"113.450","bestAsk":"113.48","bestBid":"113.43","high24h":"118.870","low24h":"113.140","priceChangePercent":"-0.035","capitalRate":"-0.000100","nextSettleTime":1649314800000,"systemTime":1649290085446,"markPrice":"113.475","indexPrice":"113.487","holding":"21957.17","baseVolume":"25303.16","quoteVolume":"3062526.96"}]}
1649290085.572851: {"action":"update","arg":{"instType":"mc","channel":"books","instId":"DASHUSDT"},"data":[{"asks":[["113.49","2.90"],["113.55","37.09"],["113.56","61.75"],["113.58","61.84"],["113.59","51.08"],["113.60","76.90"],["113.65","155.43"],["113.67","30.98"],["113.70","159.90"],["113.72","56.53"],["113.73","215.79"],["113.74","16.74"],["113.75","37.16"],["113.76","18.54"],["113.78","36.25"],["113.79","110.79"],["113.80","259.44"],["113.82","40.92"],["113.85","477.87"],["113.90","221.71"],["113.91","1806.53"],["113.92","107.53"],["113.97","2260.84"],["114.03","1841.92"],["114.09","1996.33"],["114.15","1886.04"],["114.21","1952.22"],["114.27","1753.69"],["114.33","2018.39"],["114.39","1819.86"],["114.45","1797.80"],["114.51","1863.98"],["114.57","1709.57"],["114.63","2040.45"],["114.69","1775.75"],["114.75","1974.27"],["114.81","1908.10"],["115.78","0.73"],["116.00","0"],["116.37","68.26"],["116.59","0"],["116.96","70.90"],["117.18","0"],["117.55","49.89"],["117.77","0"],["118.14","22.59"],["118.36","0"],["118.73","47.85"],["118.95","0"],["119.32","46.71"],["119.54","0"],["119.91","23.57"],["120.13","0"],["120.50","59.15"],["120.72","0"],["121.09","6.51"],["121.31","0"],["121.68","54.25"],["121.90","0"],["122.27","14.99"],["122.49","0"],["122.86","11.21"],["123.08","0"],["123.45","66.50"],["123.67","0"],["124.04","64.47"],["124.26","0"],["124.63","42.85"],["124.85","0"],["125.22","29.99"],["125.44","0"],["125.81","4.07"],["126.03","0"],["126.40","26.70"],["126.62","0"],["126.99","20.67"],["127.21","0"],["127.58","56.99"],["127.80","0"],["128.17","44.01"],["128.39","0"],["128.76","46.60"],["128.98","0"],["129.35","39.07"],["129.57","0"],["129.94","19.33"],["130.16","0"],["130.53","20.66"],["130.75","0"],["131.12","28.11"],["131.34","0"],["131.71","13.65"],["131.93","0"],["132.52","0"],["133.11","0"],["133.70","0"]],"bids":[["113.42","205.93"],["113.37","119.68"],["113.35","219.28"],["113.23","28.93"],["113.22","32.43"],["113.21","179.42"],["113.20","42.16"],["113.19","228.06"],["113.18","86.28"],["113.16","168.35"],["113.15","159.87"],["113.14","607.04"],["113.11","3.48"],["113.10","5.85"],["113.08","87.33"],["113.00","1917.34"],["112.98","526.01"],["112.94","1888.26"],["112.88","1974.27"],["112.82","2018.39"],["112.76","1841.92"],["112.70","1952.22"],["112.64","1775.75"],["112.58","2040.45"],["112.52","1753.69"],["112.46","1819.86"],["112.40","1709.57"],["112.34","1930.16"],["112.28","1908.10"],["112.22","1731.63"],["112.16","1996.33"],["112.10","1797.80"],["111.66","54.98"],["111.61","0"],["111.07","56.15"],["111.02","0"],["110.47","22.20"],["110.43","0"],["109.88","45.95"],["109.84","0"],["109.29","29.62"],["109.25","0"],["108.70","21.93"],["108.66","0"],["108.11","6.02"],["108.07","0"],["107.52","55.97"],["107.48","0"],["106.93","21.31"],["106.89","0"],["106.34","8.95"],["106.30","0"],["105.75","10.15"],["105.71","0"],["105.16","40.07"],["105.12","0"],["104.57","15.36"],["104.53","0"],["103.98","46.47"],["103.94","0"],["103.39","11.11"],["103.35","0"],["102.80","1.87"],["102.76","0"],["102.21","37.67"],["102.17","0"],["101.62","21.48"],["101.58","0"],["101.03","49.80"],["100.99","0"],["100.44","49.32"],["100.40","0"],["99.85","42.14"],["99.26","8.55"],["98.67","30.36"],["98.08","20.32"],["97.49","36.65"],["96.90","21.95"],["96.31","8.41"],["95.72","31.49"],["95.13","57.35"],["94.54","3.45"],["93.95","4.85"],["93.36","74.35"],["92.77","33.85"],["92.18","20.24"]],"checksum":89834933,"ts":"1649290085542"}]}
1649290085.664545: {"action":"update","arg":{"instType":"mc","channel":"books","instId":"UNIUSDT"},"data":[{"asks":[["9.979","121"],["9.982","220"],["9.983","286"],["9.986","496"],["9.989","1049"],["9.991","697"],["9.998","749"],["9.999","603"],["10.003","850"],["10.019","677"],["10.027","12147"],["10.032","12789"],["10.037","13366"],["10.042","12405"],["10.047","11636"],["10.057","12020"],["10.062","13559"],["10.067","12597"],["10.072","11828"],["10.077","12982"],["10.082","13174"],["10.088","5"],["10.094","0"],["10.139","262"],["10.145","0"],["10.190","158"],["10.196","0"],["10.241","292"],["10.247","0"],["10.292","106"],["10.298","0"],["10.343","32"],["10.349","0"],["10.394","152"],["10.400","0"],["10.445","260"],["10.451","0"],["10.496","230"],["10.502","0"],["10.547","307"],["10.553","0"],["10.598","308"],["10.604","0"],["10.649","214"],["10.655","0"],["10.700","208"],["10.706","0"],["10.751","204"],["10.757","0"],["10.802","112"],["10.808","0"],["10.853","39"],["10.859","0"],["10.904","236"],["10.910","0"],["10.955","260"],["10.961","0"],["11.006","80"],["11.012","0"],["11.057","180"],["11.063","0"],["11.108","156"],["11.114","0"],["11.159","228"],["11.165","0"],["11.210","69"],["11.216","0"],["11.261","236"],["11.267","0"],["11.312","267"],["11.318","0"],["11.363","134"],["11.369","0"],["11.414","68"],["11.420","0"],["11.465","31"],["11.471","0"],["11.516","195"],["11.522","0"]],"bids":[["9.971","215"],["9.970","271"],["9.969","187"],["9.958","1208"],["9.957","1353"],["9.952","346"],["9.949","774"],["9.943","2037"],["9.942","935"],["9.932","1068"],["9.926","14032"],["9.921","12982"],["9.916","11636"],["9.911","11443"],["9.906","12020"],["9.896","13174"],["9.891","13366"],["9.886","12213"],["9.881","12405"],["9.876","13559"],["9.871","11828"],["9.774","0"],["9.768","24"],["9.723","0"],["9.717","7"],["9.673","0"],["9.667","345"],["9.623","0"],["9.617","358"],["9.573","0"],["9.567","317"],["9.523","0"],["9.517","24"],["9.473","0"],["9.467","244"],["9.423","0"],["9.417","188"],["9.373","0"],["9.367","49"],["9.323","0"],["9.317","288"],["9.273","0"],["9.267","359"],["9.223","0"],["9.217","348"],["9.173","0"],["9.167","49"],["9.123","0"],["9.117","128"],["9.073","0"],["9.067","9"],["9.023","0"],["9.017","102"],["8.973","0"],["8.967","268"],["8.923","0"],["8.917","24"],["8.873","0"],["8.867","75"],["8.823","0"],["8.817","312"],["8.773","0"],["8.767","269"],["8.723","0"],["8.717","322"],["8.673","0"],["8.667","29"],["8.623","0"],["8.617","245"],["8.573","0"],["8.567","371"],["8.523","0"],["8.517","239"],["8.473","0"],["8.467","34"]],"checksum":970248144,"ts":"1649290085638"}]}
1649290085.791587: {"action":"update","arg":{"instType":"mc","channel":"trade","instId":"UNIUSDT"},"data":[["1649290085679","9.977","3","sell"]]}
1649290085.7941031: {"action":"snapshot","arg":{"instType":"mc","channel":"ticker","instId":"UNIUSDT"},"data":[{"instId":"UNIUSDT","last":"9.9770","bestAsk":"9.979","bestBid":"9.974","high24h":"10.4280","low24h":"9.9030","priceChangePercent":"-0.0391","capitalRate":"-0.000100","nextSettleTime":1649314800000,"systemTime":1649290085766,"markPrice":"9.9770","indexPrice":"9.9868","holding":"369411","baseVolume":"313077","quoteVolume":"3294384"}]}
1649290085.8056269: {"action":"snapshot","arg":{"instType":"mc","channel":"ticker","instId":"DASHUSDT"},"data":[{"instId":"DASHUSDT","last":"113.450","bestAsk":"113.48","bestBid":"113.43","high24h":"118.870","low24h":"113.140","priceChangePercent":"-0.035","capitalRate":"-0.000100","nextSettleTime":1649314800000,"systemTime":1649290085777,"markPrice":"113.475","indexPrice":"113.487","holding":"21957.17","baseVolume":"25303.16","quoteVolume":"3062526.96"}]}
1649290085.879445: {"action":"update","arg":{"instType":"mc","channel":"books","instId":"DASHUSDT"},"data":[{"asks":[["113.49","8.05"],["113.53","19.19"],["113.56","49.67"],["113.57","68.94"],["113.58","73.72"],["113.60","65.68"],["113.61","42.98"],["113.62","60.68"],["113.71","151.40"],["113.72","58.72"],["113.80","214.29"],["113.81","141.33"],["113.83","341.80"],["113.90","141.19"],["113.91","2028.93"],["113.97","2168.15"],["114.03","1819.86"],["114.09","1731.63"],["114.15","2018.39"],["114.21","1930.16"],["114.27","1863.98"],["114.33","1886.04"],["114.39","1709.57"],["114.45","1841.92"],["114.51","1797.80"],["114.57","2040.45"],["114.63","1996.33"],["114.69","1753.69"],["114.81","1775.75"],["115.78","0"],["116.00","31.47"],["116.37","0"],["116.59","50.46"],["116.96","0"],["117.18","49.40"],["117.55","0"],["117.77","27.41"],["118.14","0"],["118.36","50.42"],["118.73","0"],["118.95","50.07"],["119.32","0"],["119.54","36.12"],["119.91","0"],["120.13","8.62"],["120.50","0"],["120.72","54.60"],["121.09","0"],["121.31","1.48"],["121.68","0"],["121.90","43.49"],["122.27","0"],["122.49","7.73"],["122.86","0"],["123.08","58.21"],["123.45","0"],["123.67","52.67"],["124.04","0"],["124.26","53.84"],["124.63","0"],["124.85","4.99"],["125.22","0"],["125.44","44.04"],["125.81","0"],["126.03","25.10"],["126.40","0"],["126.62","39.09"],["126.99","0"],["127.21","44.51"],["127.58","0"],["127.80","19.01"],["128.17","0"],["128.39","29.39"],["128.76","0"],["128.98","3.89"],["129.35","0"],["129.57","23.37"],["129.94","0"],["130.16","24.18"],["130.53","0"],["130.75","9.15"],["131.12","0"],["131.34","27.04"],["131.71","0"],["131.93","7.10"],["132.52","13.38"],["133.11","33.57"],["133.70","76.51"]],"bids":[["113.41","347.50"],["113.39","10.95"],["113.37","123.92"],["113.36","7.59"],["113.35","390.51"],["113.30","30.21"],["113.29","32.04"],["113.26","165.77"],["113.23","22.38"],["113.20","47.16"],["113.18","88.02"],["113.00","1986.34"],["112.94","1861.28"],["112.88","1886.04"],["112.82","1775.75"],["112.76","1731.63"],["112.70","1908.10"],["112.64","1819.86"],["112.58","1841.92"],["112.52","1930.16"],["112.46","2040.45"],["112.40","2018.39"],["112.34","1753.69"],["112.28","1996.33"],["112.22","1974.27"],["112.16","1709.57"],["112.10","1863.98"],["111.66","0"],["111.61","44.63"],["111.07","0"],["111.02","97.81"],["110.47","0"],["110.43","40.49"],["109.88","0"],["109.84","85.27"],["109.29","0"],["109.25","84.73"],["108.70","0"],["108.66","59.74"],["108.11","0"],["108.07","61.13"],["107.52","0"],["107.48","33.01"],["106.93","0"],["106.89","56.85"],["106.34","0"],["106.30","24.34"],["105.75","0"],["105.71","1.74"],["105.16","0"],["105.12","57.94"],["104.57","0"],["104.53","58.21"],["103.98","0"],["103.94","46.12"],["103.39","0"],["103.35","52.32"],["102.80","0"],["102.76","45.29"],["102.21","0"],["102.17","22.94"],["101.62","0"],["101.58","36.02"],["101.03","0"],["100.99","38.02"],["100.44","0"],["100.40","53.60"],["99.85","0"],["99.26","0"],["98.67","0"],["98.08","0"],["97.49","0"],["96.90","0"],["96.31","0"],["95.72","0"],["95.13","0"],["94.54","0"],["93.95","0"],["93.36","0"],["92.77","0"],["92.18","0"]],"checksum":1748717365,"ts":"1649290085851"}]}
1649290085.991124: {"action":"update","arg":{"instType":"mc","channel":"books","instId":"UNIUSDT"},"data":[{"asks":[["9.979","77"],["9.980","166"],["9.982","498"],["9.984","708"],["9.986","846"],["9.988","438"],["9.989","927"],["9.990","244"],["9.992","1002"],["9.995","786"],["9.997","1193"],["9.999","1544"],["10.000","594"],["10.001","2236"],["10.003","865"],["10.006","528"],["10.007","273"],["10.009","318"],["10.011","1528"],["10.012","1303"],["10.022","680"],["10.023","7920"],["10.025","257"],["10.027","13301"],["10.032","11636"],["10.037","11828"],["10.042","11443"],["10.047","12982"],["10.052","12020"],["10.057","13174"],["10.062","12789"],["10.067","13366"],["10.072","12213"],["10.077","13559"],["10.082","12405"],["10.088","0"],["10.132","89"],["10.139","0"],["10.183","363"],["10.190","0"],["10.234","34"],["10.241","0"],["10.285","59"],["10.292","0"],["10.337","135"],["10.343","0"],["10.388","44"],["10.394","0"],["10.439","282"],["10.445","0"],["10.490","268"],["10.496","0"],["10.541","344"],["10.547","0"],["10.592","88"],["10.598","0"],["10.643","299"],["10.649","0"],["10.694","113"],["10.700","0"],["10.745","238"],["10.751","0"],["10.796","207"],["10.802","0"],["10.847","269"],["10.853","0"],["10.898","23"],["10.904","0"],["10.949","283"],["10.955","0"],["11.000","212"],["11.006","0"],["11.051","6"],["11.057","0"],["11.102","78"],["11.108","0"],["11.153","428"],["11.159","0"],["11.204","97"],["11.210","0"],["11.255","324"],["11.261","0"],["11.306","254"],["11.312","0"],["11.357","220"],["11.363","0"],["11.408","98"],["11.414","0"],["11.459","172"],["11.465","0"],["11.516","0"]],"bids":[["9.973","136"],["9.971","233"],["9.970","208"],["9.968","310"],["9.967","241"],["9.966","75"],["9.965","258"],["9.964","2299"],["9.962","894"],["9.961","2102"],["9.960","406"],["9.956","516"],["9.954","280"],["9.949","846"],["9.947","2685"],["9.943","944"],["9.942","907"],["9.935","121"],["9.934","3872"],["9.933","3148"],["9.926","13455"],["9.921","12405"],["9.916","13174"],["9.911","12789"],["9.906","11443"],["9.901","12213"],["9.896","12597"],["9.891","12982"],["9.886","11636"],["9.881","11828"],["9.876","13366"],["9.871","13559"],["9.768","0"],["9.761","24"],["9.717","0"],["9.710","7"],["9.667","0"],["9.660","345"],["9.617","0"],["9.610","358"],["9.567","0"],["9.560","317"],["9.517","0"],["9.510","24"],["9.467","0"],["9.460","244"],["9.417","0"],["9.410","188"],["9.367","0"],["9.360","49"],["9.317","0"],["9.310","288"],["9.267","0"],["9.260","359"],["9.217","0"],["9.210","348"],["9.167","0"],["9.160","49"],["9.117","0"],["9.110","128"],["9.067","0"],["9.060","9"],["9.017","0"],["9.010","102"],["8.967","0"],["8.960","268"],["8.917","0"],["8.910","24"],["8.867","0"],["8.860","75"],["8.817","0"],["8.810","312"],["8.767","0"],["8.760","269"],["8.717","0"],["8.710","322"],["8.667","0"],["8.660","29"],["8.617","0"],["8.610","245"],["8.567","0"],["8.560","371"],["8.517","0"],["8.510","239"],["8.467","0"],["8.460","34"]],"checksum":-249769636,"ts":"1649290085963"}]}
1649290086.145445: {"action":"snapshot","arg":{"instType":"mc","channel":"ticker","instId":"UNIUSDT"},"data":[{"instId":"UNIUSDT","last":"9.9770","bestAsk":"9.979","bestBid":"9.974","high24h":"10.4280","low24h":"9.9030","priceChangePercent":"-0.0391","capitalRate":"-0.000100","nextSettleTime":1649314800000,"systemTime":1649290086107,"markPrice":"9.9770","indexPrice":"9.9868","holding":"369411","baseVolume":"313077","quoteVolume":"3294384"}]}
1649290086.150768: {"action":"snapshot","arg":{"instType":"mc","channel":"ticker","instId":"DASHUSDT"},"data":[{"instId":"DASHUSDT","last":"113.450","bestAsk":"113.48","bestBid":"113.43","high24h":"118.870","low24h":"113.140","priceChangePercent":"-0.035","capitalRate":"-0.000100","nextSettleTime":1649314800000,"systemTime":1649290086117,"markPrice":"113.467","indexPrice":"113.487","holding":"21957.17","baseVolume":"25303.16","quoteVolume":"3062526.96"}]}
1649290086.186951: {"action":"update","arg":{"instType":"mc","channel":"books","instId":"DASHUSDT"},"data":[{"asks":[["113.49","16.00"],["113.53","25.93"],["113.56","57.92"],["113.57","79.37"],["113.59","38.83"],["113.61","52.88"],["113.62","49.74"],["113.65","169.67"],["113.67","25.98"],["113.70","205.05"],["113.72","56.53"],["113.73","217.28"],["113.83","325.73"],["113.87","43.41"],["113.90","129.64"],["113.97","2256.38"],["114.03","1974.27"],["114.09","1819.86"],["114.15","1753.69"],["114.21","2040.45"],["114.33","2018.39"],["114.45","1775.75"],["114.51","1731.63"],["114.57","1908.10"],["114.63","1886.04"],["114.69","1797.80"],["114.75","1841.92"],["114.81","1930.16"]],"bids":[["113.42","210.88"],["113.41","342.55"],["113.37","122.60"],["113.36","49.36"],["113.35","390.69"],["113.25","70.09"],["113.20","34.47"],["113.18","90.56"],["113.10","10.73"],["113.00","1942.22"],["112.94","1773.05"],["112.88","2018.39"],["112.82","1952.22"],["112.76","1841.92"],["112.70","2040.45"],["112.64","1930.16"],["112.58","1775.75"],["112.52","1731.63"],["112.46","1797.80"],["112.40","1886.04"],["112.34","1996.33"],["112.28","1819.86"],["112.22","1863.98"],["112.16","1974.27"],["112.10","1753.69"]],"checksum":-1768177053,"ts":"1649290086157"}]}
1649290086.296129: {"action":"update","arg":{"instType":"mc","channel":"books","instId":"UNIUSDT"},"data":[{"asks":[["9.979","116"],["9.983","408"],["9.984","507"],["9.985","456"],["9.986","853"],["9.987","739"],["9.988","339"],["9.989","979"],["9.991","722"],["9.993","874"],["10.000","622"],["10.003","850"],["10.004","742"],["10.005","879"],["10.012","1269"],["10.013","1039"],["10.022","256"],["10.024","233"],["10.026","1358"],["10.027","13878"],["10.032","12405"],["10.037","12213"],["10.042","11828"],["10.047","13559"],["10.052","11443"],["10.057","12789"],["10.062","12020"],["10.067","12597"],["10.072","11636"],["10.077","13366"],["10.082","12982"],["10.126","89"],["10.132","0"],["10.177","363"],["10.183","0"],["10.228","34"],["10.234","0"],["10.279","59"],["10.285","0"],["10.331","135"],["10.337","0"],["10.382","44"],["10.388","0"],["10.433","282"],["10.439","0"],["10.484","268"],["10.490","0"],["10.535","344"],["10.541","0"],["10.586","88"],["10.592","0"],["10.637","299"],["10.643","0"],["10.688","113"],["10.694","0"],["10.739","238"],["10.745","0"],["10.790","207"],["10.796","0"],["10.841","269"],["10.847","0"],["10.892","23"],["10.898","0"],["10.943","283"],["10.949","0"],["10.994","212"],["11.000","0"],["11.045","6"],["11.051","0"],["11.096","78"],["11.102","0"],["11.147","428"],["11.153","0"],["11.198","97"],["11.204","0"],["11.249","324"],["11.255","0"],["11.300","254"],["11.306","0"],["11.351","220"],["11.357","0"],["11.402","98"],["11.408","0"],["11.453","172"],["11.459","0"]],"bids":[["9.974","21"],["9.969","263"],["9.965","287"],["9.960","363"],["9.958","1238"],["9.956","591"],["9.954","204"],["9.952","384"],["9.949","903"],["9.931","3579"],["9.927","1115"],["9.926","12878"],["9.921","12789"],["9.916","11828"],["9.911","12020"],["9.906","12405"],["9.901","13559"],["9.896","11636"],["9.891","13366"],["9.886","12213"],["9.881","13174"],["9.876","12597"],["9.871","12982"],["9.761","0"],["9.755","24"],["9.710","0"],["9.704","7"],["9.660","0"],["9.654","345"],["9.610","0"],["9.604","358"],["9.560","0"],["9.554","317"],["9.510","0"],["9.504","24"],["9.460","0"],["9.454","244"],["9.410","0"],["9.404","188"],["9.360","0"],["9.354","49"],["9.310","0"],["9.304","288"],["9.260","0"],["9.254","359"],["9.210","0"],["9.204","348"],["9.160","0"],["9.154","49"],["9.110","0"],["9.104","128"],["9.060","0"],["9.054","9"],["9.010","0"],["9.004","102"],["8.960","0"],["8.954","268"],["8.910","0"],["8.904","24"],["8.860","0"],["8.854","75"],["8.810","0"],["8.804","312"],["8.760","0"],["8.754","269"],["8.710","0"],["8.704","322"],["8.660","0"],["8.654","29"],["8.610","0"],["8.604","245"],["8.560","0"],["8.554","371"],["8.510","0"],["8.504","239"],["8.460","0"],["8.454","34"]],"checksum":-1338610233,"ts":"1649290086267"}]}
1649290086.3319218: {"action":"update","arg":{"instType":"mc","channel":"trade","instId":"DASHUSDT"},"data":[["1649290086276","113.46","0.56","buy"]]}
1649290086.479868: {"action":"update","arg":{"instType":"mc","channel":"candle1m","instId":"UNIUSDT"},"data":[["1649290080000","9.977","9.979","9.977","9.977","7"]]}
1649290086.5135381: {"action":"update","arg":{"instType":"mc","channel":"books","instId":"DASHUSDT"},"data":[{"asks":[["113.48","10.30"],["113.57","112.17"],["113.62","16.95"],["113.75","36.02"],["113.91","2073.04"],["113.93","23.37"],["113.97","2232.90"],["114.03","1797.80"],["114.09","1886.04"],["114.15","1841.92"],["114.21","1775.75"],["114.27","2018.39"],["114.33","1709.57"],["114.39","1952.22"],["114.45","2040.45"],["114.51","1908.10"],["114.57","1731.63"],["114.63","1863.98"],["114.69","1930.16"],["114.75","1819.86"],["114.81","1753.69"],["115.78","0.73"],["116.00","0"],["116.37","68.26"],["116.59","0"],["116.96","70.90"],["117.18","0"],["117.55","49.89"],["117.77","0"],["118.14","22.59"],["118.36","0"],["118.73","47.85"],["118.95","0"],["119.32","46.71"],["119.54","0"],["119.91","23.57"],["120.13","0"],["120.50","59.15"],["120.72","0"],["121.09","6.51"],["121.31","0"],["121.68","54.25"],["121.90","0"],["122.27","14.99"],["122.49","0"],["122.86","11.21"],["123.08","0"],["123.45","66.50"],["123.67","0"],["124.04","64.47"],["124.26","0"],["124.63","42.85"],["124.85","0"],["125.22","29.99"],["125.44","0"],["125.81","4.07"],["126.03","0"],["126.40","26.70"],["126.62","0"],["126.99","20.67"],["127.21","0"],["127.58","56.99"],["127.80","0"],["128.17","44.01"],["128.39","0"],["128.76","46.60"],["128.98","0"],["129.35","39.07"],["129.57","0"],["129.94","19.33"],["130.16","0"],["130.53","20.66"],["130.75","0"],["131.12","28.11"],["131.34","0"],["131.71","13.65"],["131.93","0"],["132.52","0"],["133.11","0"],["133.70","0"]],"bids":[["113.39","15.05"],["113.37","123.92"],["113.36","49.50"],["113.35","390.33"],["113.30","34.47"],["113.23","28.93"],["113.20","47.17"],["113.18","88.02"],["113.00","1743.69"],["112.94","1861.28"],["112.88","1841.92"],["112.82","1775.75"],["112.76","1819.86"],["112.70","1908.10"],["112.58","1731.63"],["112.52","1974.27"],["112.46","1952.22"],["112.28","2040.45"],["112.22","1753.69"],["112.16","2018.39"],["112.10","1863.98"],["111.66","54.98"],["111.61","0"],["111.07","56.15"],["111.02","0"],["110.47","22.20"],["110.43","0"],["109.88","45.95"],["109.84","0"],["109.29","29.62"],["109.25","0"],["108.70","21.93"],["108.66","0"],["108.11","6.02"],["108.07","0"],["107.52","55.97"],["107.48","0"],["106.93","21.31"],["106.89","0"],["106.34","8.95"],["106.30","0"],["105.75","10.15"],["105.71","0"],["105.16","40.07"],["105.12","0"],["104.57","15.36"],["104.53","0"],["103.98","46.47"],["103.94","0"],["103.39","11.11"],["103.35","0"],["102.80","1.87"],["102.76","0"],["102.21","37.67"],["102.17","0"],["101.62","21.48"],["101.58","0"],["101.03","49.80"],["100.99","0"],["100.44","49.32"],["100.40","0"],["99.85","42.14"],["99.26","8.55"],["98.67","30.36"],["98.08","20.32"],["97.49","36.65"],["96.90","21.95"],["96.31","8.41"],["95.72","31.49"],["95.13","57.35"],["94.54","3.45"],["93.95","4.85"],["93.36","74.35"],["92.77","33.85"],["92.18","20.24"]],"checksum":-419478864,"ts":"1649290086485"}]}
1649290086.575808: {"action":"snapshot","arg":{"instType":"mc","channel":"ticker","instId":"UNIUSDT"},"data":[{"instId":"UNIUSDT","last":"9.9770","bestAsk":"9.979","bestBid":"9.974","high24h":"10.4280","low24h":"9.9030","priceChangePercent":"-0.0393","capitalRate":"-0.000100","nextSettleTime":1649314800000,"systemTime":1649290086548,"markPrice":"9.9779","indexPrice":"9.9864","holding":"369411","baseVolume":"313080","quoteVolume":"3294414"}]}
1649290086.589141: {"action":"snapshot","arg":{"instType":"mc","channel":"ticker","instId":"DASHUSDT"},"data":[{"instId":"DASHUSDT","last":"113.460","bestAsk":"113.48","bestBid":"113.43","high24h":"118.870","low24h":"113.140","priceChangePercent":"-0.035","capitalRate":"-0.000100","nextSettleTime":1649314800000,"systemTime":1649290086554,"markPrice":"113.467","indexPrice":"113.487","holding":"21957.17","baseVolume":"25303.16","quoteVolume":"3062526.96"}]}
1649290086.5935302: {"action":"update","arg":{"instType":"mc","channel":"books","instId":"UNIUSDT"},"data":[{"asks":[["9.981","120"],["9.989","962"],["10.003","717"],["10.006","653"],["10.012","1296"],["10.022","687"],["10.027","12147"],["10.032","13366"],["10.037","12789"],["10.042","12597"],["10.047","12982"],["10.052","12213"],["10.057","11828"],["10.062","11636"],["10.067","13559"],["10.072","12020"],["10.077","12405"],["10.082","13174"],["10.120","89"],["10.126","0"],["10.171","363"],["10.177","0"],["10.222","34"],["10.228","0"],["10.273","59"],["10.279","0"],["10.325","135"],["10.331","0"],["10.376","44"],["10.382","0"],["10.427","282"],["10.433","0"],["10.478","268"],["10.484","0"],["10.529","344"],["10.535","0"],["10.580","88"],["10.586","0"],["10.631","299"],["10.637","0"],["10.682","113"],["10.688","0"],["10.733","238"],["10.739","0"],["10.784","207"],["10.790","0"],["10.835","269"],["10.841","0"],["10.886","23"],["10.892","0"],["10.937","283"],["10.943","0"],["10.988","212"],["10.994","0"],["11.039","6"],["11.045","0"],["11.090","78"],["11.096","0"],["11.141","428"],["11.147","0"],["11.192","97"],["11.198","0"],["11.243","324"],["11.249","0"],["11.294","254"],["11.300","0"],["11.345","220"],["11.351","0"],["11.396","98"],["11.402","0"],["11.447","172"],["11.453","0"]],"bids":[["9.970","263"],["9.969","185"],["9.962","895"],["9.959","521"],["9.957","1216"],["9.955","321"],["9.953","616"],["9.926","14224"],["9.921","12982"],["9.916","11443"],["9.906","12213"],["9.901","11636"],["9.896","13366"],["9.891","12597"],["9.886","13559"],["9.881","11828"],["9.876","13174"],["9.871","12405"],["9.755","0"],["9.749","24"],["9.704","0"],["9.698","7"],["9.654","0"],["9.648","345"],["9.604","0"],["9.598","358"],["9.554","0"],["9.548","317"],["9.504","0"],["9.498","24"],["9.454","0"],["9.448","244"],["9.404","0"],["9.398","188"],["9.354","0"],["9.348","49"],["9.304","0"],["9.298","288"],["9.254","0"],["9.248","359"],["9.204","0"],["9.198","348"],["9.154","0"],["9.148","49"],["9.104","0"],["9.098","128"],["9.054","0"],["9.048","9"],["9.004","0"],["8.998","102"],["8.954","0"],["8.948","268"],["8.904","0"],["8.898","24"],["8.854","0"],["8.848","75"],["8.804","0"],["8.798","312"],["8.754","0"],["8.748","269"],["8.704","0"],["8.698","322"],["8.654","0"],["8.648","29"],["8.604","0"],["8.598","245"],["8.554","0"],["8.548","371"],["8.504","0"],["8.498","239"],["8.454","0"],["8.448","34"]],"checksum":1119888591,"ts":"1649290086567"}]}
1649290086.8281379: {"action":"update","arg":{"instType":"mc","channel":"books","instId":"DASHUSDT"},"data":[{"asks":[["113.55","9.37"],["113.59","51.08"],["113.61","38.03"],["113.62","22.27"],["113.64","581.48"],["113.69","29.35"],["113.72","37.18"],["113.77","820.55"],["113.83","340.58"],["113.91","2095.10"],["113.94","133.65"],["114.03","1863.98"],["114.09","1775.75"],["114.15","1819.86"],["114.21","1908.10"],["114.27","1709.57"],["114.33","2040.45"],["114.39","1731.63"],["114.45","1753.69"],["114.51","1996.33"],["114.57","1886.04"],["114.63","1952.22"],["114.75","1841.92"],["114.81","1797.80"],["115.78","0"],["116.00","31.47"],["116.37","0"],["116.59","50.46"],["116.96","0"],["117.18","49.40"],["117.55","0"],["117.77","27.41"],["118.14","0"],["118.36","50.42"],["118.73","0"],["118.95","50.07"],["119.32","0"],["119.54","36.12"],["119.91","0"],["120.13","8.62"],["120.50","0"],["120.72","54.60"],["121.09","0"],["121.31","1.48"],["121.68","0"],["121.90","43.49"],["122.27","0"],["122.49","7.73"],["122.86","0"],["123.08","58.21"],["123.45","0"],["123.67","52.67"],["124.04","0"],["124.26","53.84"],["124.63","0"],["124.85","4.99"],["125.22","0"],["125.44","44.04"],["125.81","0"],["126.03","25.10"],["126.40","0"],["126.62","39.09"],["126.99","0"],["127.21","44.51"],["127.58","0"],["127.80","19.01"],["128.17","0"],["128.39","29.39"],["128.76","0"],["128.98","3.89"],["129.35","0"],["129.57","23.37"],["129.94","0"],["130.16","24.18"],["130.53","0"],["130.75","9.15"],["131.12","0"],["131.34","27.04"],["131.71","0"],["131.93","7.10"],["132.52","13.38"],["133.11","33.57"],["133.70","76.51"]],"bids":[["113.43","39.11"],["113.42","196.03"],["113.41","332.65"],["113.39","9.37"],["113.32","13.87"],["113.31","57.72"],["113.30","24.00"],["113.29","36.99"],["113.25","67.36"],["113.23","21.29"],["113.16","167.76"],["113.11","5.25"],["113.00","1853.98"],["112.94","1927.46"],["112.88","1709.57"],["112.82","1886.04"],["112.76","1908.10"],["112.70","1797.80"],["112.64","1952.22"],["112.58","1841.92"],["112.46","1996.33"],["112.40","2040.45"],["112.34","1930.16"],["112.28","1753.69"],["112.22","2018.39"],["112.16","1775.75"],["112.10","1731.63"],["111.66","0"],["111.61","44.63"],["111.07","0"],["111.02","97.81"],["110.47","0"],["110.43","40.49"],["109.88","0"],["109.84","85.27"],["109.29","0"],["109.25","84.73"],["108.70","0"],["108.66","59.74"],["108.11","0"],["108.07","61.13"],["107.52","0"],["107.48","33.01"],["106.93","0"],["106.89","56.85"],["106.34","0"],["106.30","24.34"],["105.75","0"],["105.71","1.74"],["105.16","0"],["105.12","57.94"],["104.57","0"],["104.53","58.21"],["103.98","0"],["103.94","46.12"],["103.39","0"],["103.35","52.32"],["102.80","0"],["102.76","45.29"],["102.21","0"],["102.17","22.94"],["101.62","0"],["101.58","36.02"],["101.03","0"],["100.99","38.02"],["100.44","0"],["100.40","53.60"],["99.85","0"],["99.26","0"],["98.67","0"],["98.08","0"],["97.49","0"],["96.90","0"],["96.31","0"],["95.72","0"],["95.13","0"],["94.54","0"],["93.95","0"],["93.36","0"],["92.77","0"],["92.18","0"]],"checksum":-1453609817,"ts":"1649290086800"}]}
1649290086.898586: {"action":"update","arg":{"instType":"mc","channel":"books","instId":"UNIUSDT"},"data":[{"asks":[["9.980","344"],["9.981","237"],["9.982","532"],["9.983","275"],["9.986","773"],["9.987","689"],["9.988","394"],["9.989","1157"],["9.990","359"],["9.991","642"],["9.993","962"],["10.003","728"],["10.007","344"],["10.012","1295"],["10.022","688"],["10.027","12340"],["10.032","11828"],["10.037","13366"],["10.042","13559"],["10.047","12213"],["10.052","13174"],["10.057","12789"],["10.062","11443"],["10.067","12597"],["10.072","12982"],["10.082","12020"],["10.114","89"],["10.120","0"],["10.165","363"],["10.171","0"],["10.216","34"],["10.222","0"],["10.267","59"],["10.273","0"],["10.319","135"],["10.325","0"],["10.370","44"],["10.376","0"],["10.421","282"],["10.427","0"],["10.472","268"],["10.478","0"],["10.523","344"],["10.529","0"],["10.574","88"],["10.580","0"],["10.625","299"],["10.631","0"],["10.676","113"],["10.682","0"],["10.727","238"],["10.733","0"],["10.778","207"],["10.784","0"],["10.829","269"],["10.835","0"],["10.880","23"],["10.886","0"],["10.931","283"],["10.937","0"],["10.982","212"],["10.988","0"],["11.033","6"],["11.039","0"],["11.084","78"],["11.090","0"],["11.135","428"],["11.141","0"],["11.186","97"],["11.192","0"],["11.237","324"],["11.243","0"],["11.288","254"],["11.294","0"],["11.339","220"],["11.345","0"],["11.390","98"],["11.396","0"],["11.441","172"],["11.447","0"]],"bids":[["9.974","199"],["9.973","72"],["9.972","220"],["9.971","190"],["9.970","191"],["9.969","256"],["9.968","244"],["9.967","897"],["9.965","436"],["9.964","1309"],["9.962","908"],["9.960","492"],["9.957","1026"],["9.956","665"],["9.943","927"],["9.941","1677"],["9.939","1178"],["9.928","7184"],["9.926","13071"],["9.921","11443"],["9.916","12405"],["9.911","12789"],["9.906","12020"],["9.901","13174"],["9.891","12982"],["9.886","11828"],["9.881","12213"],["9.876","13559"],["9.871","12597"],["9.749","0"],["9.743","24"],["9.698","0"],["9.692","7"],["9.648","0"],["9.642","345"],["9.598","0"],["9.592","358"],["9.548","0"],["9.542","317"],["9.498","0"],["9.492","24"],["9.448","15"],["9.442","244"],["9.398","0"],["9.392","188"],["9.348","0"],["9.342","49"],["9.298","0"],["9.292","288"],["9.248","0"],["9.242","359"],["9.198","0"],["9.192","348"],["9.148","0"],["9.142","49"],["9.098","0"],["9.092","128"],["9.048","0"],["9.042","9"],["8.998","0"],["8.992","102"],["8.948","0"],["8.942","268"],["8.898","0"],["8.892","24"],["8.848","0"],["8.842","75"],["8.798","0"],["8.792","312"],["8.748","0"],["8.742","269"],["8.698","0"],["8.692","322"],["8.648","0"],["8.642","29"],["8.598","0"],["8.592","245"],["8.548","0"],["8.542","371"],["8.498","0"],["8.492","239"],["8.448","0"],["8.442","34"]],"checksum":693430486,"ts":"1649290086869"}]}
1649290086.9762769: {"action":"snapshot","arg":{"instType":"mc","channel":"ticker","instId":"UNIUSDT"},"data":[{"instId":"UNIUSDT","last":"9.9770","bestAsk":"9.979","bestBid":"9.974","high24h":"10.4280","low24h":"9.9030","priceChangePercent":"-0.0393","capitalRate":"-0.000100","nextSettleTime":1649314800000,"systemTime":1649290086943,"markPrice":"9.9779","indexPrice":"9.9864","holding":"369411","baseVolume":"313080","quoteVolume":"3294414"}]}
1649290086.9855711: {"action":"snapshot","arg":{"instType":"mc","channel":"ticker","instId":"DASHUSDT"},"data":[{"instId":"DASHUSDT","last":"113.460","bestAsk":"113.48","bestBid":"113.43","high24h":"118.870","low24h":"113.140","priceChangePercent":"-0.035","capitalRate":"-0.000100","nextSettleTime":1649314800000,"systemTime":1649290086952,"markPrice":"113.460","indexPrice":"113.487","holding":"21957.17","baseVolume":"25303.16","quoteVolume":"3062526.96"}]}
1649290087.121202: {"action":"update","arg":{"instType":"mc","channel":"candle1m","instId":"DASHUSDT"},"data":[["1649290080000","113.37","113.49","113.37","113.46","1.83"]]}
1649290087.1361642: {"action":"update","arg":{"instType":"mc","channel":"books","instId":"DASHUSDT"},"data":[{"asks":[["113.53","30.24"],["113.55","14.32"],["113.56","56.27"],["113.58","103.78"],["113.59","38.83"],["113.61","46.45"],["113.62","125.60"],["113.63","105.32"],["113.64","364.17"],["113.67","33.50"],["113.71","93.98"],["113.72","35.00"],["113.74","8.72"],["113.75","30.88"],["113.76","8.64"],["113.78","48.62"],["113.79","117.39"],["113.80","224.19"],["113.90","139.54"],["113.91","1984.81"],["113.97","2210.85"],["114.03","1886.04"],["114.09","1731.63"],["114.15","1753.69"],["114.21","1775.75"],["114.27","1841.92"],["114.33","2018.39"],["114.39","1930.16"],["114.45","1863.98"],["114.51","2040.45"],["114.57","1996.33"],["114.63","1819.86"],["114.69","1974.27"],["114.75","1709.57"]],"bids":[["113.43","40.76"],["113.42","19.81"],["113.37","155.11"],["113.36","7.43"],["113.30","21.26"],["113.25","232.39"],["113.22","36.85"],["113.16","62.49"],["113.00","1942.22"],["112.94","1883.34"],["112.88","1996.33"],["112.82","1731.63"],["112.76","2040.45"],["112.70","2018.39"],["112.64","1841.92"],["112.58","1952.22"],["112.46","1886.04"],["112.40","1775.75"],["112.34","1709.57"],["112.28","1930.16"],["112.22","1863.98"],["112.16","1753.69"],["112.10","1797.80"]],"checksum":-412069329,"ts":"1649290087097"}]}
1649290087.2296479: {"action":"update","arg":{"instType":"mc","channel":"books","instId":"UNIUSDT"},"data":[{"asks":[["9.981","120"],["9.984","654"],["9.985","493"],["9.988","364"],["9.991","788"],["9.999","1755"],["10.027","12724"],["10.032","12982"],["10.037","12597"],["10.042","12213"],["10.047","13559"],["10.052","11828"],["10.067","13366"],["10.072","13174"],["10.077","11636"],["10.082","12405"],["10.108","89"],["10.114","0"],["10.159","363"],["10.165","0"],["10.210","34"],["10.216","0"],["10.261","59"],["10.267","0"],["10.313","135"],["10.319","0"],["10.364","44"],["10.370","0"],["10.415","282"],["10.421","0"],["10.466","268"],["10.472","0"],["10.517","344"],["10.523","0"],["10.568","88"],["10.574","0"],["10.619","299"],["10.625","0"],["10.670","113"],["10.676","0"],["10.721","238"],["10.727","0"],["10.772","207"],["10.778","0"],["10.823","269"],["10.829","0"],["10.874","23"],["10.880","0"],["10.925","283"],["10.931","0"],["10.976","212"],["10.982","0"],["11.027","6"],["11.033","0"],["11.078","78"],["11.084","0"],["11.129","428"],["11.135","0"],["11.180","97"],["11.186","0"],["11.231","324"],["11.237","0"],["11.282","254"],["11.288","0"],["11.333","220"],["11.339","0"],["11.384","98"],["11.390","0"],["11.435","172"],["11.441","0"]],"bids":[["9.959","346"],["9.958","1413"],["9.949","1112"],["9.946","2472"],["9.944","4395"],["9.929","1009"],["9.926","14411"],["9.916","12213"],["9.911","11828"],["9.906","12789"],["9.901","11636"],["9.891","12020"],["9.886","12597"],["9.881","12405"],["9.871","12982"],["9.743","0"],["9.737","24"],["9.692","0"],["9.686","7"],["9.642","0"],["9.636","345"],["9.592","0"],["9.586","358"],["9.542","0"],["9.536","317"],["9.492","0"],["9.486","24"],["9.442","0"],["9.436","244"],["9.392","0"],["9.386","188"],["9.342","0"],["9.336","49"],["9.292","0"],["9.286","288"],["9.242","0"],["9.236","359"],["9.192","0"],["9.186","348"],["9.142","0"],["9.136","49"],["9.092","0"],["9.086","128"],["9.042","0"],["9.036","9"],["8.992","0"],["8.986","102"],["8.942","0"],["8.936","268"],["8.892","0"],["8.886","24"],["8.842","0"],["8.836","75"],["8.792","0"],["8.786","312"],["8.742","0"],["8.736","269"],["8.692","0"],["8.686","322"],["8.642","0"],["8.636","29"],["8.592","0"],["8.586","245"],["8.542","0"],["8.536","371"],["8.492","0"],["8.486","239"],["8.442","0"],["8.436","34"]],"checksum":-880637060,"ts":"1649290087202"}]}
1649290087.320965: {"action":"snapshot","arg":{"instType":"mc","channel":"ticker","instId":"DASHUSDT"},"data":[{"instId":"DASHUSDT","last":"113.460","bestAsk":"113.48","bestBid":"113.43","high24h":"118.870","low24h":"113.140","priceChangePercent":"-0.035","capitalRate":"-0.000100","nextSettleTime":1649314800000,"systemTime":1649290087293,"markPrice":"113.460","indexPrice":"113.487","holding":"21957.17","baseVolume":"25303.72","quoteVolume":"3062590.50"}]}
1649290087.3538299: {"action":"update","arg":{"instType":"mc","channel":"trade","instId":"UNIUSDT"},"data":[["1649290087238","9.979","3","buy"]]}
1649290087.3873532: {"action":"snapshot","arg":{"instType":"mc","channel":"ticker","instId":"UNIUSDT"},"data":[{"instId":"UNIUSDT","last":"9.9790","bestAsk":"9.979","bestBid":"9.974","high24h":"10.4280","low24h":"9.9030","priceChangePercent":"-0.0393","capitalRate":"-0.000100","nextSettleTime":1649314800000,"systemTime":1649290087347,"markPrice":"9.9780","indexPrice":"9.9864","holding":"369411","baseVolume":"313080","quoteVolume":"3294414"}]}
1649290087.4287648: {"action":"update","arg":{"instType":"mc","channel":"books","instId":"DASHUSDT"},"data":[{"asks":[["113.58","99.82"],["113.78","50.51"],["113.82","44.03"],["113.91","2073.04"],["113.92","108.64"],["113.97","2277.02"],["114.03","1841.92"],["114.09","1974.27"],["114.15","1797.80"],["114.21","1886.04"],["114.27","1952.22"],["114.33","1908.10"],["114.39","1753.69"],["114.45","2040.45"],["114.51","1863.98"],["114.57","1819.86"],["114.63","1709.57"],["114.69","1731.63"],["114.75","1775.75"],["114.81","1930.16"]],"bids":[["113.43","38.45"],["113.42","32.68"],["113.28","18.15"],["113.23","23.30"],["113.18","85.12"],["113.08","90.39"],["113.00","1920.16"],["112.98","530.04"],["112.94","1839.23"],["112.88","1974.27"],["112.70","1863.98"],["112.64","1930.16"],["112.58","2018.39"],["112.52","1709.57"],["112.46","1753.69"],["112.40","1841.92"],["112.34","1819.86"],["112.28","1952.22"],["112.22","1797.80"],["112.16","1996.33"],["112.10","1908.10"]],"checksum":-1924756668,"ts":"1649290087397"}]}
1649290087.4839811: {"action":"update","arg":{"instType":"mc","channel":"candle1m","instId":"UNIUSDT"},"data":[["1649290080000","9.977","9.979","9.977","9.979","10"]]}
1649290087.542103: {"action":"update","arg":{"instType":"mc","channel":"books","instId":"UNIUSDT"},"data":[{"asks":[["9.980","166"],["9.982","438"],["9.983","338"],["9.985","543"],["9.987","766"],["9.990","281"],["9.991","779"],["9.997","1147"],["9.998","687"],["10.001","1849"],["10.002","404"],["10.003","1588"],["10.004","832"],["10.005","912"],["10.012","1298"],["10.022","685"],["10.027","12742"],["10.032","11443"],["10.037","13174"],["10.042","12597"],["10.052","13366"],["10.057","11828"],["10.062","12789"],["10.067","11636"],["10.072","12213"],["10.077","12982"],["10.101","89"],["10.108","0"],["10.152","363"],["10.159","0"],["10.203","34"],["10.210","0"],["10.254","59"],["10.261","0"],["10.306","135"],["10.313","0"],["10.357","44"],["10.364","0"],["10.408","282"],["10.415","0"],["10.459","268"],["10.466","0"],["10.510","344"],["10.517","0"],["10.561","88"],["10.568","0"],["10.612","299"],["10.619","0"],["10.663","113"],["10.670","0"],["10.714","238"],["10.721","0"],["10.765","207"],["10.772","0"],["10.816","269"],["10.823","0"],["10.867","23"],["10.874","0"],["10.918","283"],["10.925","0"],["10.969","212"],["10.976","0"],["11.020","6"],["11.027","0"],["11.071","78"],["11.078","0"],["11.122","428"],["11.129","0"],["11.173","97"],["11.180","0"],["11.224","324"],["11.231","0"],["11.275","254"],["11.282","0"],["11.326","220"],["11.333","0"],["11.377","98"],["11.384","0"],["11.428","172"],["11.435","0"]],"bids":[["9.970","262"],["9.968","181"],["9.963","665"],["9.962","885"],["9.955","244"],["9.952","452"],["9.951","760"],["9.949","970"],["9.944","4271"],["9.941","1698"],["9.939","1206"],["9.937","488"],["9.926","14796"],["9.921","12789"],["9.916","11443"],["9.911","12213"],["9.906","13174"],["9.901","11828"],["9.891","12405"],["9.886","12020"],["9.881","12597"],["9.876","11636"],["9.737","0"],["9.730","24"],["9.686","0"],["9.679","7"],["9.636","0"],["9.629","345"],["9.586","0"],["9.579","358"],["9.536","0"],["9.529","317"],["9.486","0"],["9.479","24"],["9.436","0"],["9.429","244"],["9.386","0"],["9.379","188"],["9.336","0"],["9.329","49"],["9.286","0"],["9.279","288"],["9.236","0"],["9.229","359"],["9.186","0"],["9.179","348"],["9.136","0"],["9.129","49"],["9.086","0"],["9.079","128"],["9.036","0"],["9.029","9"],["8.986","0"],["8.979","102"],["8.936","0"],["8.929","268"],["8.886","0"],["8.879","24"],["8.836","0"],["8.829","75"],["8.786","0"],["8.779","312"],["8.736","0"],["8.729","269"],["8.686","0"],["8.679","322"],["8.636","0"],["8.629","29"],["8.586","0"],["8.579","245"],["8.536","0"],["8.529","371"],["8.486","0"],["8.479","239"],["8.436","0"],["8.429","34"]],"checksum":-2083843326,"ts":"1649290087514"}]}
1649290087.6037838: {"action":"snapshot","arg":{"instType":"mc","channel":"ticker","instId":"UNIUSDT"},"data":[{"instId":"UNIUSDT","last":"9.9790","bestAsk":"9.979","bestBid":"9.974","high24h":"10.4280","low24h":"9.9030","priceChangePercent":"-0.0391","capitalRate":"-0.000100","nextSettleTime":1649314800000,"systemTime":1649290087570,"markPrice":"9.9780","indexPrice":"9.9864","holding":"369411","baseVolume":"313083","quoteVolume":"3294444"}]}
1649290087.620702: {"action":"snapshot","arg":{"instType":"mc","channel":"ticker","instId":"DASHUSDT"},"data":[{"instId":"DASHUSDT","last":"113.460","bestAsk":"113.48","bestBid":"113.43","high24h":"118.870","low24h":"113.140","priceChangePercent":"-0.035","capitalRate":"-0.000100","nextSettleTime":1649314800000,"systemTime":1649290087588,"markPrice":"113.460","indexPrice":"113.487","holding":"21957.17","baseVolume":"25303.72","quoteVolume":"3062590.50"}]}
1649290087.728493: {"action":"update","arg":{"instType":"mc","channel":"books","instId":"DASHUSDT"},"data":[{"asks":[["113.48","4.75"],["113.52","18.09"],["113.53","38.97"],["113.55","9.37"],["113.57","99.19"],["113.58","55.49"],["113.60","67.33"],["113.64","366.95"],["113.73","59.37"],["113.77","822.19"],["113.85","508.56"],["113.89","4.01"],["113.91","1940.69"],["113.97","2166.73"],["114.03","2040.45"],["114.09","1753.69"],["114.15","1775.75"],["114.21","1930.16"],["114.27","1974.27"],["114.33","1886.04"],["114.39","1952.22"],["114.45","1996.33"],["114.51","1797.80"],["114.57","1841.92"],["114.63","1731.63"],["114.69","1709.57"],["114.75","2018.39"],["114.81","1819.86"]],"bids":[["113.37","372.79"],["113.36","7.48"],["113.35","173.02"],["113.18","83.37"],["113.02","1535.19"],["113.00","1942.22"],["112.98","531.27"],["112.94","1795.11"],["112.88","1930.16"],["112.82","2040.45"],["112.76","2018.39"],["112.70","1775.75"],["112.64","1996.33"],["112.58","1974.27"],["112.52","1841.92"],["112.46","1952.22"],["112.40","1797.80"],["112.34","1753.69"],["112.28","1709.57"],["112.22","1863.98"],["112.16","1886.04"],["112.10","1819.86"]],"checksum":377207450,"ts":"1649290087701"}]}
1649290087.8456059: {"action":"update","arg":{"instType":"mc","channel":"books","instId":"UNIUSDT"},"data":[{"asks":[["9.979","0"],["9.980","153"],["9.982","413"],["9.983","307"],["9.984","633"],["9.985","566"],["9.986","709"],["9.987","815"],["9.988","345"],["9.989","959"],["9.990","232"],["9.991","754"],["9.994","2868"],["9.996","1105"],["10.000","683"],["10.006","528"],["10.012","1269"],["10.022","256"],["10.027","13319"],["10.028","578"],["10.029","461"],["10.032","12405"],["10.037","12982"],["10.042","11828"],["10.052","11636"],["10.057","11443"],["10.062","12020"],["10.067","12213"],["10.072","12789"],["10.077","13174"],["10.082","13366"],["10.095","89"],["10.101","0"],["10.146","363"],["10.152","0"],["10.197","34"],["10.203","0"],["10.248","59"],["10.254","0"],["10.300","135"],["10.306","0"],["10.351","44"],["10.357","0"],["10.402","282"],["10.408","0"],["10.453","268"],["10.459","0"],["10.504","344"],["10.510","0"],["10.555","88"],["10.561","0"],["10.606","299"],["10.612","0"],["10.657","113"],["10.663","0"],["10.708","238"],["10.714","0"],["10.759","207"],["10.765","0"],["10.810","269"],["10.816","0"],["10.861","23"],["10.867","0"],["10.912","283"],["10.918","0"],["10.963","212"],["10.969","0"],["11.014","6"],["11.020","0"],["11.065","78"],["11.071","0"],["11.116","428"],["11.122","0"],["11.167","97"],["11.173","0"],["11.218","324"],["11.224","0"],["11.269","254"],["11.275","0"],["11.320","220"],["11.326","0"],["11.371","98"],["11.377","0"],["11.422","172"],["11.428","0"]],"bids":[["9.973","106"],["9.971","172"],["9.970","253"],["9.969","362"],["9.968","194"],["9.964","1277"],["9.963","688"],["9.962","222"],["9.961","2200"],["9.960","408"],["9.958","1533"],["9.948","699"],["9.947","2716"],["9.927","14480"],["9.926","1238"],["9.922","11443"],["9.921","0"],["9.917","12213"],["9.916","0"],["9.912","13559"],["9.911","0"],["9.907","12597"],["9.906","0"],["9.902","12405"],["9.901","0"],["9.897","12020"],["9.896","0"],["9.892","11828"],["9.891","0"],["9.887","12789"],["9.886","0"],["9.882","11636"],["9.881","0"],["9.877","13174"],["9.876","0"],["9.872","12982"],["9.871","0"],["9.730","0"],["9.724","24"],["9.679","0"],["9.673","7"],["9.629","0"],["9.623","345"],["9.579","0"],["9.573","358"],["9.529","0"],["9.523","317"],["9.479","0"],["9.473","24"],["9.429","0"],["9.423","244"],["9.379","0"],["9.373","188"],["9.329","0"],["9.323","49"],["9.279","0"],["9.273","288"],["9.229","0"],["9.223","359"],["9.179","0"],["9.173","348"],["9.129","0"],["9.123","49"],["9.079","0"],["9.073","128"],["9.029","0"],["9.023","9"],["8.979","0"],["8.973","102"],["8.929","0"],["8.923","268"],["8.879","0"],["8.873","24"],["8.829","0"],["8.823","75"],["8.779","0"],["8.773","312"],["8.729","0"],["8.723","269"],["8.679","0"],["8.673","322"],["8.629","0"],["8.623","29"],["8.579","0"],["8.573","245"],["8.529","0"],["8.523","371"],["8.479","0"],["8.473","239"],["8.429","0"],["8.423","34"]],"checksum":-642123124,"ts":"1649290087816"}]}
1649290087.881304: {"action":"snapshot","arg":{"instType":"mc","channel":"ticker","instId":"UNIUSDT"},"data":[{"instId":"UNIUSDT","last":"9.9790","bestAsk":"9.98","bestBid":"9.974","high24h":"10.4280","low24h":"9.9030","priceChangePercent":"-0.0391","capitalRate":"-0.000100","nextSettleTime":1649314800000,"systemTime":1649290087849,"markPrice":"9.9780","indexPrice":"9.9864","holding":"369411","baseVolume":"313083","quoteVolume":"3294444"}]}
1649290087.8892002: {"action":"snapshot","arg":{"instType":"mc","channel":"ticker","instId":"DASHUSDT"},"data":[{"instId":"DASHUSDT","last":"113.460","bestAsk":"113.48","bestBid":"113.43","high24h":"118.870","low24h":"113.140","priceChangePercent":"-0.035","capitalRate":"-0.000100","nextSettleTime":1649314800000,"systemTime":1649290087862,"markPrice":"113.460","indexPrice":"113.500","holding":"21957.17","baseVolume":"25303.72","quoteVolume":"3062590.50"}]}
1649290088.06865: {"action":"update","arg":{"instType":"mc","channel":"books","instId":"DASHUSDT"},"data":[{"asks":[["113.48","0"],["113.52","19.33"],["113.55","14.32"],["113.57","101.26"],["113.60","65.68"],["113.70","223.69"],["113.73","217.28"],["113.85","477.87"],["113.88","91.79"],["113.89","23.14"],["113.91","76.72"],["113.92","1884.38"],["113.97","258.64"],["113.98","1863.98"],["113.99","494.95"],["114.03","0"],["114.04","1797.80"],["114.09","0"],["114.10","1930.16"],["114.15","0"],["114.16","2040.45"],["114.21","0"],["114.22","1731.63"],["114.27","0"],["114.28","1886.04"],["114.33","0"],["114.34","1841.92"],["114.39","0"],["114.40","1819.86"],["114.45","0"],["114.46","1908.10"],["114.51","0"],["114.52","1974.27"],["114.57","0"],["114.58","1709.57"],["114.63","0"],["114.64","2018.39"],["114.69","0"],["114.70","1996.33"],["114.75","0"],["114.76","1753.69"],["114.81","0"],["114.82","1952.22"],["115.78","0.73"],["116.00","0"],["116.37","68.26"],["116.59","0"],["116.96","70.90"],["117.18","0"],["117.55","49.89"],["117.77","0"],["118.14","22.59"],["118.36","0"],["118.73","47.85"],["118.95","0"],["119.32","46.71"],["119.54","0"],["119.91","23.57"],["120.13","0"],["120.50","59.15"],["120.72","0"],["121.09","6.51"],["121.31","0"],["121.68","54.25"],["121.90","0"],["122.27","14.99"],["122.49","0"],["122.86","11.21"],["123.08","0"],["123.45","66.50"],["123.67","0"],["124.04","64.47"],["124.26","0"],["124.63","42.85"],["124.85","0"],["125.22","29.99"],["125.44","0"],["125.81","4.07"],["126.03","0"],["126.40","26.70"],["126.62","0"],["126.99","20.67"],["127.21","0"],["127.58","56.99"],["127.80","0"],["128.17","44.01"],["128.39","0"],["128.76","46.60"],["128.98","0"],["129.35","39.07"],["129.57","0"],["129.94","19.33"],["130.16","0"],["130.53","20.66"],["130.75","0"],["131.12","28.11"],["131.34","0"],["131.71","13.65"],["131.93","0"],["132.52","0"],["133.11","0"],["133.70","0"]],"bids":[["113.44","11.89"],["113.43","40.76"],["113.42","19.81"],["113.39","5.15"],["113.38","56.86"],["113.37","155.48"],["113.35","390.33"],["113.32","20.70"],["113.20","35.82"],["113.18","85.12"],["113.16","77.56"],["113.09","5.64"],["113.07","250.24"],["113.01","1836.40"],["113.00","34.13"],["112.95","2188.57"],["112.94","0"],["112.89","1709.57"],["112.88","0"],["112.83","1775.75"],["112.82","0"],["112.77","1974.27"],["112.76","0"],["112.71","2018.39"],["112.70","0"],["112.65","1841.92"],["112.64","0"],["112.59","1886.04"],["112.58","0"],["112.53","2040.45"],["112.52","0"],["112.47","1996.33"],["112.46","0"],["112.41","1952.22"],["112.40","0"],["112.35","1753.69"],["112.34","0"],["112.29","1819.86"],["112.28","0"],["112.23","1930.16"],["112.22","0"],["112.17","1731.63"],["112.16","0"],["112.11","1863.98"],["112.10","0"],["111.66","54.98"],["111.61","0"],["111.07","56.15"],["111.02","0"],["110.47","22.20"],["110.43","0"],["109.88","45.95"],["109.84","0"],["109.29","29.62"],["109.25","0"],["108.70","21.93"],["108.66","0"],["108.11","6.02"],["108.07","0"],["107.52","55.97"],["107.48","0"],["106.93","21.31"],["106.89","0"],["106.34","8.95"],["106.30","0"],["105.75","10.15"],["105.71","0"],["105.16","40.07"],["105.12","0"],["104.57","15.36"],["104.53","0"],["103.98","46.47"],["103.94","0"],["103.39","11.11"],["103.35","0"],["102.80","1.87"],["102.76","0"],["102.21","37.67"],["102.17","0"],["101.62","21.48"],["101.58","0"],["101.03","49.80"],["100.99","0"],["100.44","49.32"],["100.40","0"],["99.85","42.14"],["99.26","8.55"],["98.67","30.36"],["98.08","20.32"],["97.49","36.65"],["96.90","21.95"],["96.31","8.41"],["95.72","31.49"],["95.13","57.35"],["94.54","3.45"],["93.95","4.85"],["93.36","74.35"],["92.77","33.85"],["92.18","20.24"]],"checksum":-1140094051,"ts":"1649290088039"}]}
1649290088.147945: {"action":"update","arg":{"instType":"mc","channel":"books","instId":"UNIUSDT"},"data":[{"asks":[["9.983","456"],["9.985","604"],["9.986","807"],["9.987","810"],["9.991","779"],["9.993","874"],["9.994","2835"],["9.995","687"],["9.996","1140"],["9.997","1269"],["10.011","1403"],["10.012","1295"],["10.022","688"],["10.027","13704"],["10.032","12020"],["10.037","11828"],["10.042","11636"],["10.047","12597"],["10.052","13366"],["10.057","12405"],["10.062","13174"],["10.067","12789"],["10.072","13559"],["10.077","11443"],["10.082","12213"],["10.089","89"],["10.095","0"],["10.140","363"],["10.146","0"],["10.191","34"],["10.197","0"],["10.242","59"],["10.248","0"],["10.294","135"],["10.300","0"],["10.345","44"],["10.351","0"],["10.396","282"],["10.402","0"],["10.447","268"],["10.453","0"],["10.498","344"],["10.504","0"],["10.549","88"],["10.555","0"],["10.600","299"],["10.606","0"],["10.651","113"],["10.657","0"],["10.702","238"],["10.708","0"],["10.753","207"],["10.759","0"],["10.804","269"],["10.810","0"],["10.855","23"],["10.861","0"],["10.906","283"],["10.912","0"],["10.957","212"],["10.963","0"],["11.008","6"],["11.014","0"],["11.059","78"],["11.065","0"],["11.110","428"],["11.116","0"],["11.161","97"],["11.167","0"],["11.212","324"],["11.218","0"],["11.263","254"],["11.269","0"],["11.314","220"],["11.320","0"],["11.365","98"],["11.371","0"],["11.416","172"],["11.422","0"]],"bids":[["9.973","139"],["9.970","323"],["9.969","263"],["9.968","266"],["9.967","864"],["9.965","452"],["9.964","1375"],["9.962","885"],["9.961","2135"],["9.959","290"],["9.952","368"],["9.944","4375"],["9.939","1102"],["9.934","3839"],["9.933","3181"],["9.927","14673"],["9.925","5717"],["9.922","12213"],["9.917","12789"],["9.912","12020"],["9.907","13366"],["9.902","13174"],["9.897","12982"],["9.892","12405"],["9.887","12597"],["9.882","11828"],["9.877","11443"],["9.872","11636"],["9.817","34"],["9.767","75"],["9.724","0"],["9.717","180"],["9.673","0"],["9.667","248"],["9.623","0"],["9.617","267"],["9.573","0"],["9.567","238"],["9.523","0"],["9.517","153"],["9.473","0"],["9.467","265"],["9.423","0"],["9.417","254"],["9.373","0"],["9.367","80"],["9.323","0"],["9.317","161"],["9.273","0"],["9.267","99"],["9.223","0"],["9.217","100"],["9.173","0"],["9.167","50"],["9.123","0"],["9.117","92"],["9.073","0"],["9.067","333"],["9.023","0"],["9.017","341"],["8.973","0"],["8.967","239"],["8.923","0"],["8.917","43"],["8.873","0"],["8.867","262"],["8.823","0"],["8.817","300"],["8.773","0"],["8.767","27"],["8.723","0"],["8.717","326"],["8.673","0"],["8.667","76"],["8.623","0"],["8.617","188"],["8.573","0"],["8.567","131"],["8.523","0"],["8.517","106"],["8.473","0"],["8.467","90"],["8.423","0"],["8.417","271"]],"checksum":1428900193,"ts":"1649290088118"}]}
1649290088.242385: {"action":"snapshot","arg":{"instType":"mc","channel":"ticker","instId":"UNIUSDT"},"data":[{"instId":"UNIUSDT","last":"9.9790","bestAsk":"9.98","bestBid":"9.974","high24h":"10.4280","low24h":"9.9030","priceChangePercent":"-0.0391","capitalRate":"-0.000100","nextSettleTime":1649314800000,"systemTime":1649290088209,"markPrice":"9.9780","indexPrice":"9.9864","holding":"369411","baseVolume":"313083","quoteVolume":"3294444"}]}
1649290088.2449: {"action":"snapshot","arg":{"instType":"mc","channel":"ticker","instId":"DASHUSDT"},"data":[{"instId":"DASHUSDT","last":"113.460","bestAsk":"113.49","bestBid":"113.44","high24h":"118.870","low24h":"113.140","priceChangePercent":"-0.035","capitalRate":"-0.000100","nextSettleTime":1649314800000,"systemTime":1649290088212,"markPrice":"113.459","indexPrice":"113.500","holding":"21957.17","baseVolume":"25303.72","quoteVolume":"3062590.50"}]}
1649290088.3697631: {"action":"update","arg":{"instType":"mc","channel":"books","instId":"DASHUSDT"},"data":[{"asks":[["113.49","20.68"],["113.52","18.09"],["113.56","60.92"],["113.61","8.73"],["113.62","147.13"],["113.73","59.37"],["113.75","188.79"],["113.83","325.73"],["113.84","132.43"],["113.85","508.56"],["113.89","4.01"],["113.91","4.94"],["113.92","2149.08"],["113.93","209.49"],["113.98","1952.22"],["114.04","1775.75"],["114.10","1996.33"],["114.16","1753.69"],["114.22","1819.86"],["114.28","1797.80"],["114.34","1863.98"],["114.40","2018.39"],["114.46","1886.04"],["114.58","1731.63"],["114.64","1908.10"],["114.70","1709.57"],["114.76","1841.92"],["114.82","1930.16"]],"bids":[["113.44","16.84"],["113.43","38.45"],["113.42","32.68"],["113.39","6.41"],["113.38","53.89"],["113.37","348.04"],["113.35","173.02"],["113.33","25.00"],["113.20","32.49"],["113.16","28.06"],["113.09","79.89"],["113.07","128.23"],["113.04","52.44"],["113.01","2201.75"],["113.00","48.03"],["112.95","2078.27"],["112.89","1908.10"],["112.83","1709.57"],["112.77","1753.69"],["112.71","1886.04"],["112.65","1974.27"],["112.59","1731.63"],["112.53","1930.16"],["112.47","2040.45"],["112.41","1863.98"],["112.35","1819.86"],["112.29","1841.92"],["112.23","2018.39"],["112.17","1775.75"],["112.11","1952.22"]],"checksum":1510741485,"ts":"1649290088342"}]}
1649290088.446699: {"action":"update","arg":{"instType":"mc","channel":"books","instId":"UNIUSDT"},"data":[{"asks":[["9.979","109"],["9.981","326"],["9.982","438"],["9.983","471"],["9.984","535"],["9.985","405"],["9.986","579"],["9.987","742"],["9.988","581"],["9.989","1117"],["9.990","329"],["9.991","759"],["9.994","2952"],["9.995","711"],["9.997","1236"],["9.998","739"],["9.999","1451"],["10.000","752"],["10.003","1713"],["10.007","469"],["10.010","3178"],["10.012","1301"],["10.015","781"],["10.022","682"],["10.023","7707"],["10.024","446"],["10.027","11665"],["10.028","407"],["10.029","0"],["10.032","13559"],["10.037","12405"],["10.042","12020"],["10.057","12213"],["10.062","12982"],["10.067","11443"],["10.072","12789"],["10.077","11828"],["10.082","13174"],["10.084","89"],["10.089","0"],["10.135","363"],["10.140","0"],["10.186","34"],["10.191","0"],["10.237","59"],["10.242","0"],["10.289","135"],["10.294","0"],["10.340","44"],["10.345","0"],["10.391","282"],["10.396","0"],["10.442","268"],["10.447","0"],["10.493","344"],["10.498","0"],["10.544","88"],["10.549","0"],["10.595","299"],["10.600","0"],["10.646","113"],["10.651","0"],["10.697","238"],["10.702","0"],["10.748","207"],["10.753","0"],["10.799","269"],["10.804","0"],["10.850","23"],["10.855","0"],["10.901","283"],["10.906","0"],["10.952","212"],["10.957","0"],["11.003","6"],["11.008","0"],["11.054","78"],["11.059","0"],["11.105","428"],["11.110","0"],["11.156","97"],["11.161","0"],["11.207","324"],["11.212","0"],["11.258","254"],["11.263","0"],["11.309","220"],["11.314","0"],["11.360","98"],["11.365","0"],["11.411","172"],["11.416","0"]],"bids":[["9.974","21"],["9.973","190"],["9.972","153"],["9.971","277"],["9.970","189"],["9.969","241"],["9.968","284"],["9.967","208"],["9.965","1067"],["9.964","1433"],["9.962","384"],["9.961","2096"],["9.960","492"],["9.959","319"],["9.958","1498"],["9.957","982"],["9.954","212"],["9.953","577"],["9.952","348"],["9.951","618"],["9.949","1069"],["9.948","840"],["9.945","957"],["9.942","1193"],["9.939","822"],["9.927","1115"],["9.926","14026"],["9.925","4369"],["9.922","0"],["9.921","11636"],["9.917","0"],["9.916","12020"],["9.912","0"],["9.911","12405"],["9.907","0"],["9.906","13559"],["9.902","0"],["9.901","13174"],["9.897","0"],["9.896","11443"],["9.892","0"],["9.891","13366"],["9.887","0"],["9.886","12213"],["9.882","0"],["9.881","11828"],["9.877","0"],["9.876","12982"],["9.872","0"],["9.871","12597"],["9.817","0"],["9.812","34"],["9.767","0"],["9.762","75"],["9.717","0"],["9.712","180"],["9.667","0"],["9.662","248"],["9.617","0"],["9.612","267"],["9.567","0"],["9.562","238"],["9.517","0"],["9.512","153"],["9.467","0"],["9.462","265"],["9.417","0"],["9.412","254"],["9.367","0"],["9.362","80"],["9.317","0"],["9.312","161"],["9.267","0"],["9.262","99"],["9.217","0"],["9.212","100"],["9.167","0"],["9.162","50"],["9.117","0"],["9.112","92"],["9.067","0"],["9.062","333"],["9.017","0"],["9.012","341"],["8.967","0"],["8.962","239"],["8.917","0"],["8.912","43"],["8.867","0"],["8.862","262"],["8.817","0"],["8.812","300"],["8.767","0"],["8.762","27"],["8.717","0"],["8.712","326"],["8.667","0"],["8.662","76"],["8.617","0"],["8.612","188"],["8.567","0"],["8.562","131"],["8.517","0"],["8.512","106"],["8.467","0"],["8.462","90"],["8.417","0"],["8.412","271"]],"checksum":2096030438,"ts":"1649290088418"}]}
1649290088.5028899: {"action":"snapshot","arg":{"instType":"mc","channel":"ticker","instId":"UNIUSDT"},"data":[{"instId":"UNIUSDT","last":"9.9790","bestAsk":"9.979","bestBid":"9.974","high24h":"10.4280","low24h":"9.9030","priceChangePercent":"-0.0391","capitalRate":"-0.000100","nextSettleTime":1649314800000,"systemTime":1649290088472,"markPrice":"9.9779","indexPrice":"9.9864","holding":"369411","baseVolume":"313083","quoteVolume":"3294444"}]}
1649290088.507766: {"action":"snapshot","arg":{"instType":"mc","channel":"ticker","instId":"DASHUSDT"},"data":[{"instId":"DASHUSDT","last":"113.460","bestAsk":"113.49","bestBid":"113.44","high24h":"118.870","low24h":"113.140","priceChangePercent":"-0.035","capitalRate":"-0.000100","nextSettleTime":1649314800000,"systemTime":1649290088479,"markPrice":"113.459","indexPrice":"113.500","holding":"21957.17","baseVolume":"25303.72","quoteVolume":"3062590.50"}]}
1649290088.6845791: {"action":"update","arg":{"instType":"mc","channel":"books","instId":"DASHUSDT"},"data":[{"asks":[["113.48","4.07"],["113.49","16.74"],["113.52","19.33"],["113.91","1824.79"],["113.92","108.64"],["113.97","2034.38"],["113.98","0"],["113.99","0"],["114.03","1974.27"],["114.04","0"],["114.09","1952.22"],["114.10","0"],["114.15","1863.98"],["114.16","0"],["114.21","1731.63"],["114.22","0"],["114.27","1841.92"],["114.28","0"],["114.33","1753.69"],["114.34","0"],["114.39","1996.33"],["114.40","0"],["114.45","1797.80"],["114.46","0"],["114.51","1930.16"],["114.52","0"],["114.57","2040.45"],["114.58","0"],["114.63","1886.04"],["114.64","0"],["114.69","1709.57"],["114.70","0"],["114.75","1908.10"],["114.76","0"],["114.81","2018.39"],["114.82","0"]],"bids":[["113.44","0"],["113.43","55.45"],["113.39","6.44"],["113.38","42.95"],["113.35","179.42"],["113.30","124.95"],["113.03","25.87"],["113.01","205.43"],["113.00","1956.12"],["112.95","280.48"],["112.94","1949.52"],["112.89","0"],["112.88","1863.98"],["112.83","0"],["112.82","1841.92"],["112.77","0"],["112.76","1930.16"],["112.71","0"],["112.70","1775.75"],["112.65","0"],["112.64","1753.69"],["112.59","0"],["112.58","1819.86"],["112.53","0"],["112.52","2040.45"],["112.47","0"],["112.46","1797.80"],["112.41","0"],["112.40","1952.22"],["112.35","0"],["112.34","1731.63"],["112.29","0"],["112.28","1996.33"],["112.23","0"],["112.22","2018.39"],["112.17","0"],["112.16","1709.57"],["112.11","0"],["112.10","1974.27"]],"checksum":-1192634769,"ts":"1649290088656"}]}
