1649290088.78094: {"action":"snapshot","arg":{"instType":"mc","channel":"ticker","instId":"UNIUSDT"},"data":[{"instId":"UNIUSDT","last":"9.9790","bestAsk":"9.979","bestBid":"9.974","high24h":"10.4280","low24h":"9.9030","priceChangePercent":"-0.0391","capitalRate":"-0.000100","nextSettleTime":1649314800000,"systemTime":1649290088753,"markPrice":"9.9779","indexPrice":"9.9864","holding":"369411","baseVolume":"313083","quoteVolume":"3294444"}]}
1649290088.790741: {"action":"snapshot","arg":{"instType":"mc","channel":"ticker","instId":"DASHUSDT"},"data":[{"instId":"DASHUSDT","last":"113.460","bestAsk":"113.48","bestBid":"113.43","high24h":"118.870","low24h":"113.140","priceChangePercent":"-0.035","capitalRate":"-0.000100","nextSettleTime":1649314800000,"systemTime":1649290088763,"markPrice":"113.459","indexPrice":"113.478","holding":"21957.17","baseVolume":"25303.72","quoteVolume":"3062590.50"}]}
1649290088.795168: {"action":"update","arg":{"instType":"mc","channel":"books","instId":"UNIUSDT"},"data":[{"asks":[["9.979","96"],["9.980","387"],["9.982","634"],["9.983","459"],["9.984","225"],["9.986","595"],["9.987","427"],["9.988","531"],["9.989","892"],["9.990","276"],["9.991","717"],["9.992","984"],["9.994","2835"],["10.004","750"],["10.010","3285"],["10.012","1269"],["10.015","944"],["10.022","256"],["10.026","1716"],["10.027","12434"],["10.032","11443"],["10.037","13174"],["10.042","13366"],["10.047","12982"],["10.052","11636"],["10.057","13559"],["10.062","12213"],["10.067","11828"],["10.072","12020"],["10.077","12789"],["10.082","12597"],["10.084","0"],["10.128","338"],["10.135","0"],["10.179","76"],["10.186","0"],["10.230","227"],["10.237","0"],["10.281","282"],["10.289","0"],["10.333","384"],["10.340","0"],["10.384","325"],["10.391","0"],["10.435","125"],["10.442","0"],["10.486","37"],["10.493","0"],["10.537","394"],["10.544","0"],["10.588","115"],["10.595","0"],["10.639","229"],["10.646","0"],["10.690","245"],["10.697","0"],["10.741","240"],["10.748","0"],["10.792","51"],["10.799","0"],["10.843","341"],["10.850","0"],["10.894","191"],["10.901","0"],["10.945","84"],["10.952","0"],["10.996","238"],["11.003","0"],["11.047","177"],["11.054","0"],["11.098","22"],["11.105","0"],["11.149","264"],["11.156","0"],["11.200","195"],["11.207","0"],["11.251","187"],["11.258","0"],["11.302","257"],["11.309","0"],["11.360","0"],["11.411","0"]],"bids":[["9.974","199"],["9.973","121"],["9.972","328"],["9.971","159"],["9.970","255"],["9.969","226"],["9.968","249"],["9.967","678"],["9.965","473"],["9.964","1236"],["9.963","879"],["9.962","248"],["9.961","2759"],["9.960","408"],["9.956","613"],["9.953","681"],["9.950","721"],["9.948","796"],["9.944","4390"],["9.942","818"],["9.941","1622"],["9.939","1058"],["9.938","964"],["9.933","3219"],["9.925","5717"],["9.921","12213"],["9.916","11828"],["9.911","13174"],["9.901","12597"],["9.896","13366"],["9.891","12405"],["9.886","11636"],["9.881","12020"],["9.871","11443"],["9.812","0"],["9.805","34"],["9.762","0"],["9.755","75"],["9.712","0"],["9.705","180"],["9.662","0"],["9.655","248"],["9.612","0"],["9.605","267"],["9.562","0"],["9.555","238"],["9.512","0"],["9.505","153"],["9.462","0"],["9.455","265"],["9.412","0"],["9.405","254"],["9.362","0"],["9.355","80"],["9.312","0"],["9.305","161"],["9.262","0"],["9.255","99"],["9.212","0"],["9.205","100"],["9.162","0"],["9.155","50"],["9.112","0"],["9.105","92"],["9.062","0"],["9.055","333"],["9.012","0"],["9.005","341"],["8.962","0"],["8.955","239"],["8.912","0"],["8.905","43"],["8.862","0"],["8.855","262"],["8.812","0"],["8.805","300"],["8.762","0"],["8.755","27"],["8.712","0"],["8.705","326"],["8.662","0"],["8.655","76"],["8.612","0"],["8.605","188"],["8.562","0"],["8.555","131"],["8.512","0"],["8.505","106"],["8.462","0"],["8.455","90"],["8.412","0"],["8.405","271"]],"checksum":-796470650,"ts":"1649290088768"}]}
1649290088.958816: {"action":"update","arg":{"instType":"mc","channel":"trade","instId":"DASHUSDT"},"data":[["1649290088899","113.39","0.76","sell"]]}
1649290089.0066628: {"action":"update","arg":{"instType":"mc","channel":"books","instId":"DASHUSDT"},"data":[{"asks":[["113.44","0.77"],["113.45","0.82"],["113.46","4.62"],["113.47","12.23"],["113.48","7.98"],["113.49","7.28"],["113.50","6.95"],["113.51","49.00"],["113.52","28.71"],["113.53","78.50"],["113.54","24.56"],["113.56","56.27"],["113.57","85.08"],["113.58","21.30"],["113.59","36.53"],["113.61","11.10"],["113.62","123.16"],["113.63","144.91"],["113.64","364.17"],["113.66","1330.92"],["113.67","28.78"],["113.69","5.39"],["113.72","29.50"],["113.74","0"],["113.75","192.93"],["113.78","34.07"],["113.79","120.80"],["113.80","222.70"],["113.83","340.58"],["113.87","1970.53"],["113.88","137.08"],["113.89","7.93"],["113.91","4.94"],["113.92","115.19"],["113.93","2007.28"],["113.94","237.61"],["113.95","0"],["113.96","0"],["113.97","0"],["113.99","2040.45"],["114.03","0"],["114.05","2018.39"],["114.09","0"],["114.11","1819.86"],["114.15","0"],["114.17","1952.22"],["114.21","0"],["114.23","1886.04"],["114.27","0"],["114.29","1753.69"],["114.33","0"],["114.35","1974.27"],["114.39","0"],["114.41","1996.33"],["114.45","0"],["114.47","1731.63"],["114.51","0"],["114.53","1908.10"],["114.57","0"],["114.59","1863.98"],["114.63","0"],["114.65","1841.92"],["114.69","0"],["114.71","1775.75"],["114.75","0"],["114.77","1709.57"],["114.81","0"],["115.78","0"],["116.00","31.47"],["116.37","0"],["116.59","50.46"],["116.96","0"],["117.18","49.40"],["117.55","0"],["117.77","27.41"],["118.14","0"],["118.36","50.42"],["118.73","0"],["118.95","50.07"],["119.32","0"],["119.54","36.12"],["119.91","0"],["120.13","8.62"],["120.50","0"],["120.72","54.60"],["121.09","0"],["121.31","1.48"],["121.68","0"],["121.90","43.49"],["122.27","0"],["122.49","7.73"],["122.86","0"],["123.08","58.21"],["123.45","0"],["123.67","52.67"],["124.04","0"],["124.26","53.84"],["124.63","0"],["124.85","4.99"],["125.22","0"],["125.44","44.04"],["125.81","0"],["126.03","25.10"],["126.40","0"],["126.62","39.09"],["126.99","0"],["127.21","44.51"],["127.58","0"],["127.80","19.01"],["128.17","0"],["128.39","29.39"],["128.76","0"],["128.98","3.89"],["129.35","0"],["129.57","23.37"],["129.94","0"],["130.16","24.18"],["130.53","0"],["130.75","9.15"],["131.12","0"],["131.34","27.04"],["131.71","0"],["131.93","7.10"],["132.52","13.38"],["133.11","33.57"],["133.70","76.51"]],"bids":[["113.43","0"],["113.42","0"],["113.41","0"],["113.40","0"],["113.39","13.87"],["113.38","42.21"],["113.37","685.09"],["113.36","11.89"],["113.35","252.62"],["113.33","12.89"],["113.31","28.64"],["113.30","117.77"],["113.29","24.91"],["113.28","16.66"],["113.26","167.30"],["113.25","241.01"],["113.24","29.19"],["113.23","21.12"],["113.22","32.43"],["113.20","28.61"],["113.19","229.73"],["113.18","112.30"],["113.17","17.67"],["113.16","15.88"],["113.15","143.87"],["113.14","399.35"],["113.13","127.46"],["113.10","23.32"],["113.09","81.64"],["113.08","100.01"],["113.06","38.23"],["113.05","1127.99"],["113.04","48.32"],["113.00","48.03"],["112.98","530.04"],["112.96","1984.80"],["112.95","275.73"],["112.94","124.75"],["112.93","11.82"],["112.92","26.45"],["112.91","9.08"],["112.90","1812.47"],["112.88","0"],["112.84","1797.80"],["112.82","0"],["112.78","1819.86"],["112.76","0"],["112.72","1775.75"],["112.70","0"],["112.66","1952.22"],["112.64","0"],["112.60","1996.33"],["112.58","0"],["112.54","1908.10"],["112.52","0"],["112.48","1731.63"],["112.46","0"],["112.42","2040.45"],["112.40","0"],["112.36","1930.16"],["112.34","0"],["112.30","1974.27"],["112.28","0"],["112.24","1753.69"],["112.22","0"],["112.18","2018.39"],["112.16","0"],["112.12","1841.92"],["112.10","0"],["112.06","1886.04"],["111.66","0"],["111.61","44.63"],["111.07","0"],["111.02","97.81"],["110.47","0"],["110.43","40.49"],["109.88","0"],["109.84","85.27"],["109.29","0"],["109.25","84.73"],["108.70","0"],["108.66","59.74"],["108.11","0"],["108.07","61.13"],["107.52","0"],["107.48","33.01"],["106.93","0"],["106.89","56.85"],["106.34","0"],["106.30","24.34"],["105.75","0"],["105.71","1.74"],["105.16","0"],["105.12","57.94"],["104.57","0"],["104.53","58.21"],["103.98","0"],["103.94","46.12"],["103.39","0"],["103.35","52.32"],["102.80","0"],["102.76","45.29"],["102.21","0"],["102.17","22.94"],["101.62","0"],["101.58","36.02"],["101.03","0"],["100.99","38.02"],["100.44","0"],["100.40","53.60"],["99.85","0"],["99.26","0"],["98.67","0"],["98.08","0"],["97.49","0"],["96.90","0"],["96.31","0"],["95.72","0"],["95.13","0"],["94.54","0"],["93.95","0"],["93.36","0"],["92.77","0"],["92.18","0"]],"checksum":5119060,"ts":"1649290088978"}]}
1649290089.059341: {"action":"snapshot","arg":{"instType":"mc","channel":"ticker","instId":"UNIUSDT"},"data":[{"instId":"UNIUSDT","last":"9.9790","bestAsk":"9.978","bestBid":"9.973","high24h":"10.4280","low24h":"9.9030","priceChangePercent":"-0.0391","capitalRate":"-0.000100","nextSettleTime":1649314800000,"systemTime":1649290089026,"markPrice":"9.9779","indexPrice":"9.9864","holding":"369411","baseVolume":"313083","quoteVolume":"3294444"}]}
1649290089.070466: {"action":"snapshot","arg":{"instType":"mc","channel":"ticker","instId":"DASHUSDT"},"data":[{"instId":"DASHUSDT","last":"113.390","bestAsk":"113.44","bestBid":"113.39","high24h":"118.870","low24h":"113.140","priceChangePercent":"-0.035","capitalRate":"-0.000100","nextSettleTime":1649314800000,"systemTime":1649290089033,"markPrice":"113.462","indexPrice":"113.478","holding":"21957.17","baseVolume":"25303.72","quoteVolume":"3062590.50"}]}
1649290089.0919979: {"action":"update","arg":{"instType":"mc","channel":"books","instId":"UNIUSDT"},"data":[{"asks":[["9.978","28"],["9.979","582"],["9.981","345"],["9.982","536"],["9.983","269"],["9.984","253"],["9.985","697"],["9.986","336"],["9.987","802"],["9.988","486"],["9.989","961"],["9.990","877"],["9.991","378"],["9.992","278"],["9.993","933"],["9.994","2799"],["9.995","507"],["9.997","1107"],["9.999","557"],["10.003","1701"],["10.005","896"],["10.007","536"],["10.008","663"],["10.011","1473"],["10.012","394"],["10.013","1296"],["10.022","682"],["10.026","14916"],["10.027","30"],["10.028","0"],["10.031","13174"],["10.032","0"],["10.036","12982"],["10.037","0"],["10.041","13366"],["10.042","0"],["10.046","12789"],["10.047","0"],["10.051","12213"],["10.052","0"],["10.056","12597"],["10.057","0"],["10.061","12020"],["10.062","113"],["10.066","11443"],["10.067","0"],["10.071","11828"],["10.072","0"],["10.076","12405"],["10.077","0"],["10.081","11636"],["10.082","0"],["10.121","338"],["10.128","0"],["10.172","76"],["10.179","0"],["10.223","227"],["10.230","0"],["10.274","282"],["10.281","0"],["10.326","384"],["10.333","0"],["10.377","325"],["10.384","0"],["10.428","125"],["10.435","0"],["10.479","37"],["10.486","0"],["10.530","394"],["10.537","0"],["10.581","115"],["10.588","0"],["10.632","229"],["10.639","0"],["10.683","245"],["10.690","0"],["10.734","240"],["10.741","0"],["10.785","51"],["10.792","0"],["10.836","341"],["10.843","0"],["10.887","191"],["10.894","0"],["10.938","84"],["10.945","0"],["10.989","238"],["10.996","0"],["11.040","177"],["11.047","0"],["11.091","22"],["11.098","0"],["11.142","264"],["11.149","0"],["11.193","195"],["11.200","0"],["11.244","187"],["11.251","0"],["11.295","257"],["11.302","0"]],"bids":[["9.974","0"],["9.972","339"],["9.971","173"],["9.970","250"],["9.969","438"],["9.968","205"],["9.967","230"],["9.966","73"],["9.965","1035"],["9.963","731"],["9.962","229"],["9.961","2112"],["9.960","455"],["9.959","417"],["9.958","1453"],["9.957","1160"],["9.955","229"],["9.953","639"],["9.951","572"],["9.949","982"],["9.948","807"],["9.947","1231"],["9.946","2157"],["9.945","1243"],["9.942","1193"],["9.940","852"],["9.939","1084"],["9.933","3181"],["9.931","3624"],["9.926","1238"],["9.925","16196"],["9.924","1892"],["9.921","0"],["9.920","12982"],["9.916","0"],["9.915","11636"],["9.911","0"],["9.910","11443"],["9.906","0"],["9.905","12405"],["9.901","0"],["9.900","13559"],["9.896","0"],["9.895","13366"],["9.891","0"],["9.890","12789"],["9.886","0"],["9.885","13174"],["9.881","0"],["9.880","12597"],["9.876","0"],["9.875","12213"],["9.871","0"],["9.870","12020"],["9.805","0"],["9.798","34"],["9.755","0"],["9.748","75"],["9.705","0"],["9.698","180"],["9.655","0"],["9.648","248"],["9.605","0"],["9.598","267"],["9.555","0"],["9.548","238"],["9.505","0"],["9.498","153"],["9.455","0"],["9.448","265"],["9.405","0"],["9.398","254"],["9.355","0"],["9.348","80"],["9.305","0"],["9.298","161"],["9.255","0"],["9.248","99"],["9.205","0"],["9.198","100"],["9.155","0"],["9.148","50"],["9.105","0"],["9.098","92"],["9.055","0"],["9.048","333"],["9.005","0"],["8.998","341"],["8.955","0"],["8.948","239"],["8.905","0"],["8.898","43"],["8.855","0"],["8.848","262"],["8.805","0"],["8.798","300"],["8.755","0"],["8.748","27"],["8.705","0"],["8.698","326"],["8.655","0"],["8.648","76"],["8.605","0"],["8.598","188"],["8.555","0"],["8.548","131"],["8.505","0"],["8.498","106"],["8.455","0"],["8.448","90"],["8.405","0"],["8.398","271"]],"checksum":980571907,"ts":"1649290089064"}]}
1649290089.146881: {"action":"update","arg":{"instType":"mc","channel":"candle1m","instId":"DASHUSDT"},"data":[["1649290080000","113.37","113.49","113.37","113.39","2.59"]]}
1649290089.31024: {"action":"snapshot","arg":{"instType":"mc","channel":"ticker","instId":"UNIUSDT"},"data":[{"instId":"UNIUSDT","last":"9.9790","bestAsk":"9.978","bestBid":"9.973","high24h":"10.4280","low24h":"9.9030","priceChangePercent":"-0.0391","capitalRate":"-0.000100","nextSettleTime":1649314800000,"systemTime":1649290089282,"markPrice":"9.9779","indexPrice":"9.9864","holding":"369411","baseVolume":"313083","quoteVolume":"3294444"}]}
1649290089.313471: {"action":"snapshot","arg":{"instType":"mc","channel":"ticker","instId":"DASHUSDT"},"data":[{"instId":"DASHUSDT","last":"113.390","bestAsk":"113.42","bestBid":"113.37","high24h":"118.870","low24h":"113.140","priceChangePercent":"-0.035","capitalRate":"-0.000100","nextSettleTime":1649314800000,"systemTime":1649290089286,"markPrice":"113.462","indexPrice":"113.478","holding":"21957.17","baseVolume":"25303.72","quoteVolume":"3062590.50"}]}
1649290089.328862: {"action":"update","arg":{"instType":"mc","channel":"books","instId":"DASHUSDT"},"data":[{"asks":[["113.42","22.79"],["113.43","0.43"],["113.47","22.50"],["113.48","15.90"],["113.50","12.08"],["113.52","22.37"],["113.53","25.93"],["113.54","27.92"],["113.55","97.06"],["113.56","85.69"],["113.57","84.08"],["113.58","45.44"],["113.59","68.72"],["113.60","34.84"],["113.61","7.13"],["113.62","125.26"],["113.63","1425.32"],["113.64","241.75"],["113.66","50.84"],["113.67","20.48"],["113.68","576.64"],["113.69","9.75"],["113.70","180.62"],["113.71","160.58"],["113.72","127.36"],["113.75","190.32"],["113.77","781.40"],["113.79","123.37"],["113.80","24.70"],["113.82","23.80"],["113.83","320.62"],["113.85","2483.15"],["113.87","38.38"],["113.88","142.03"],["113.91","2045.38"],["113.92","121.96"],["113.93","0"],["113.94","0"],["113.97","1996.33"],["113.99","0"],["114.03","1797.80"],["114.05","0"],["114.09","1841.92"],["114.11","0"],["114.15","1930.16"],["114.17","0"],["114.21","1819.86"],["114.23","0"],["114.27","1753.69"],["114.29","0"],["114.33","1886.04"],["114.35","0"],["114.39","1775.75"],["114.41","0"],["114.45","2018.39"],["114.47","0"],["114.51","1731.63"],["114.53","0"],["114.57","1863.98"],["114.59","0"],["114.63","1908.10"],["114.65","0"],["114.69","1709.57"],["114.71","0"],["114.75","1952.22"],["114.77","0"]],"bids":[["113.39","0"],["113.38","0"],["113.37","237.61"],["113.36","336.61"],["113.35","255.43"],["113.33","6.01"],["113.32","22.28"],["113.31","14.32"],["113.30","20.96"],["113.29","25.52"],["113.28","20.45"],["113.26","153.89"],["113.25","184.50"],["113.24","21.77"],["113.23","22.22"],["113.22","6.26"],["113.21","180.48"],["113.20","52.06"],["113.19","235.55"],["113.18","89.42"],["113.16","24.76"],["113.15","135.33"],["113.14","605.91"],["113.13","134.14"],["113.12","14.88"],["113.11","9.69"],["113.10","125.12"],["113.09","78.75"],["113.08","85.85"],["113.07","22.39"],["113.05","1508.33"],["113.03","57.36"],["113.02","1525.25"],["113.01","137.38"],["113.00","64.14"],["112.98","700.73"],["112.96","186.37"],["112.95","286.60"],["112.94","1856.37"],["112.93","14.42"],["112.91","0"],["112.90","107.30"],["112.89","11.48"],["112.88","2066.73"],["112.87","421.64"],["112.84","0"],["112.82","1863.98"],["112.78","0"],["112.76","1709.57"],["112.72","0"],["112.70","1753.69"],["112.66","0"],["112.64","1841.92"],["112.60","0"],["112.58","1908.10"],["112.54","0"],["112.52","1886.04"],["112.48","0"],["112.46","1952.22"],["112.42","0"],["112.40","2018.39"],["112.36","0"],["112.34","1996.33"],["112.30","0"],["112.28","1775.75"],["112.24","0"],["112.22","1974.27"],["112.18","0"],["112.16","1930.16"],["112.12","0"],["112.10","1797.80"],["112.06","0"],["112.04","1819.86"]],"checksum":-231666830,"ts":"1649290089302"}]}
1649290089.409568: {"action":"update","arg":{"instType":"mc","channel":"books","instId":"UNIUSDT"},"data":[{"asks":[["9.980","460"],["9.981","251"],["9.982","508"],["9.983","334"],["9.984","286"],["9.985","1799"],["9.986","377"],["9.987","740"],["9.988","527"],["9.989","1798"],["9.990","1140"],["9.991","395"],["9.992","262"],["9.993","1057"],["9.995","734"],["9.996","1988"],["9.997","1008"],["9.999","514"],["10.000","734"],["10.001","1803"],["10.008","787"],["10.010","3169"],["10.011","911"],["10.012","407"],["10.016","1026"],["10.020","3570"],["10.022","669"],["10.026","14697"],["10.031","13366"],["10.036","13174"],["10.041","12020"],["10.046","13559"],["10.051","12597"],["10.056","11828"],["10.061","12789"],["10.066","11636"],["10.071","11443"],["10.081","12213"],["10.115","338"],["10.121","0"],["10.166","76"],["10.172","0"],["10.217","227"],["10.223","0"],["10.268","282"],["10.274","0"],["10.320","384"],["10.326","0"],["10.371","325"],["10.377","0"],["10.422","125"],["10.428","0"],["10.473","37"],["10.479","0"],["10.524","394"],["10.530","0"],["10.575","115"],["10.581","0"],["10.626","229"],["10.632","0"],["10.677","245"],["10.683","0"],["10.728","240"],["10.734","0"],["10.779","51"],["10.785","0"],["10.830","341"],["10.836","0"],["10.881","191"],["10.887","0"],["10.932","84"],["10.938","0"],["10.983","238"],["10.989","0"],["11.034","177"],["11.040","0"],["11.085","22"],["11.091","0"],["11.136","264"],["11.142","0"],["11.187","195"],["11.193","0"],["11.238","187"],["11.244","0"],["11.289","257"],["11.295","0"]],"bids":[["9.973","92"],["9.971","207"],["9.970","120"],["9.969","426"],["9.968","201"],["9.967","676"],["9.966","100"],["9.965","453"],["9.964","879"],["9.963","757"],["9.962","247"],["9.960","942"],["9.959","598"],["9.958","1786"],["9.957","1130"],["9.956","610"],["9.955","288"],["9.954","321"],["9.953","627"],["9.952","310"],["9.951","620"],["9.950","651"],["9.949","951"],["9.947","1225"],["9.946","2284"],["9.944","4481"],["9.941","1703"],["9.940","1014"],["9.936","506"],["9.935","88"],["9.933","3243"],["9.931","3604"],["9.929","978"],["9.925","17552"],["9.920","13559"],["9.910","12020"],["9.905","12597"],["9.900","12789"],["9.895","11828"],["9.890","12213"],["9.885","13366"],["9.880","12405"],["9.875","12982"],["9.870","11443"],["9.798","0"],["9.792","34"],["9.748","0"],["9.742","75"],["9.698","0"],["9.692","180"],["9.648","0"],["9.642","248"],["9.598","0"],["9.592","267"],["9.548","0"],["9.542","238"],["9.498","0"],["9.492","153"],["9.448","15"],["9.442","265"],["9.398","0"],["9.392","254"],["9.348","0"],["9.342","80"],["9.298","0"],["9.292","161"],["9.248","0"],["9.242","99"],["9.198","0"],["9.192","100"],["9.148","0"],["9.142","50"],["9.098","0"],["9.092","92"],["9.048","0"],["9.042","333"],["8.998","0"],["8.992","341"],["8.948","0"],["8.942","239"],["8.898","0"],["8.892","43"],["8.848","0"],["8.842","262"],["8.798","0"],["8.792","300"],["8.748","0"],["8.742","27"],["8.698","0"],["8.692","326"],["8.648","0"],["8.642","76"],["8.598","0"],["8.592","188"],["8.548","0"],["8.542","131"],["8.498","0"],["8.492","106"],["8.448","0"],["8.442","90"],["8.398","0"],["8.392","271"]],"checksum":-1894693812,"ts":"1649290089372"}]}
1649290089.445667: {"action":"update","arg":{"instType":"mc","channel":"trade","instId":"UNIUSDT"},"data":[["1649290089346","9.976","3","sell"]]}
1649290089.51931: {"action":"update","arg":{"instType":"mc","channel":"candle1m","instId":"UNIUSDT"},"data":[["1649290080000","9.977","9.979","9.976","9.976","13"]]}
1649290089.586402: {"action":"snapshot","arg":{"instType":"mc","channel":"ticker","instId":"UNIUSDT"},"data":[{"instId":"UNIUSDT","last":"9.9760","bestAsk":"9.978","bestBid":"9.973","high24h":"10.4280","low24h":"9.9030","priceChangePercent":"-0.0394","capitalRate":"-0.000100","nextSettleTime":1649314800000,"systemTime":1649290089553,"markPrice":"9.9778","indexPrice":"9.9864","holding":"369411","baseVolume":"313086","quoteVolume":"3294474"}]}
1649290089.5941498: {"action":"snapshot","arg":{"instType":"mc","channel":"ticker","instId":"DASHUSDT"},"data":[{"instId":"DASHUSDT","last":"113.390","bestAsk":"113.41","bestBid":"113.36","high24h":"118.870","low24h":"113.140","priceChangePercent":"-0.036","capitalRate":"-0.000100","nextSettleTime":1649314800000,"systemTime":1649290089558,"markPrice":"113.462","indexPrice":"113.478","holding":"21957.17","baseVolume":"25304.48","quoteVolume":"3062676.68"}]}
1649290089.633888: {"action":"update","arg":{"instType":"mc","channel":"books","instId":"DASHUSDT"},"data":[{"asks":[["113.42","8.87"],["113.44","2.27"],["113.45","6.37"],["113.46","5.71"],["113.47","8.89"],["113.48","7.04"],["113.52","79.70"],["113.54","56.83"],["113.56","55.21"],["113.57","49.83"],["113.58","1600.34"],["113.60","169.42"],["113.61","13.26"],["113.62","126.46"],["113.63","105.32"],["113.64","95.89"],["113.65","216.42"],["113.66","76.02"],["113.67","28.43"],["113.68","578.12"],["113.69","111.72"],["113.71","70.99"],["113.72","149.64"],["113.73","233.12"],["113.77","779.76"],["113.80","160.82"],["113.82","25.03"],["113.83","218.65"],["113.85","2210.14"],["113.87","36.73"],["113.88","142.48"],["113.89","18.47"],["113.90","130.08"],["113.91","2022.01"],["113.97","2040.45"],["114.03","1731.63"],["114.09","1863.98"],["114.15","1908.10"],["114.21","1775.75"],["114.27","1974.27"],["114.33","1797.80"],["114.39","1819.86"],["114.45","1930.16"],["114.51","1753.69"],["114.57","1709.57"],["114.63","1841.92"],["114.69","1886.04"],["114.75","1996.33"]],"bids":[["113.37","0"],["113.36","11.89"],["113.35","266.25"],["113.34","0"],["113.31","12.34"],["113.30","1600.39"],["113.29","11.26"],["113.28","25.31"],["113.26","151.82"],["113.25","43.43"],["113.24","20.28"],["113.20","39.36"],["113.19","392.11"],["113.18","101.21"],["113.15","120.48"],["113.13","50.05"],["113.10","137.53"],["113.08","74.85"],["113.07","146.93"],["113.03","64.79"],["112.94","124.75"],["112.93","1922.51"],["112.90","78.29"],["112.88","26.29"],["112.87","2307.67"],["112.86","9.03"],["112.85","188.84"],["112.82","0"],["112.81","1930.16"],["112.76","0"],["112.75","1797.80"],["112.70","0"],["112.69","1974.27"],["112.64","0"],["112.63","1841.92"],["112.58","0"],["112.57","1819.86"],["112.52","0"],["112.51","1709.57"],["112.46","0"],["112.45","1731.63"],["112.40","0"],["112.39","1775.75"],["112.34","0"],["112.33","1753.69"],["112.28","0"],["112.27","2040.45"],["112.22","0"],["112.21","2018.39"],["112.16","0"],["112.15","1863.98"],["112.10","0"],["112.09","1996.33"],["112.04","0"],["112.03","1952.22"]],"checksum":270172467,"ts":"1649290089601"}]}
1649290089.709624: {"action":"update","arg":{"instType":"mc","channel":"books","instId":"UNIUSDT"},"data":[{"asks":[["9.978","3"],["9.979","184"],["9.980","791"],["9.981","152"],["9.982","342"],["9.983","406"],["9.984","320"],["9.985","1032"],["9.986","310"],["9.987","813"],["9.988","477"],["9.989","1348"],["9.990","1148"],["9.991","421"],["9.992","360"],["9.993","990"],["9.994","2832"],["9.995","714"],["9.997","1126"],["10.000","757"],["10.001","1765"],["10.002","423"],["10.004","673"],["10.005","820"],["10.007","469"],["10.008","969"],["10.011","817"],["10.012","354"],["10.015","962"],["10.020","3556"],["10.022","256"],["10.023","7734"],["10.026","14146"],["10.027","714"],["10.031","13174"],["10.036","11828"],["10.041","12213"],["10.046","12020"],["10.051","11636"],["10.056","12597"],["10.061","13366"],["10.066","12982"],["10.071","13559"],["10.081","11443"],["10.109","338"],["10.115","0"],["10.160","76"],["10.166","0"],["10.211","227"],["10.217","0"],["10.262","282"],["10.268","0"],["10.314","384"],["10.320","0"],["10.365","325"],["10.371","0"],["10.416","125"],["10.422","0"],["10.467","37"],["10.473","0"],["10.518","394"],["10.524","0"],["10.569","115"],["10.575","0"],["10.620","229"],["10.626","0"],["10.671","245"],["10.677","0"],["10.722","240"],["10.728","0"],["10.773","51"],["10.779","0"],["10.824","341"],["10.830","0"],["10.875","191"],["10.881","0"],["10.926","84"],["10.932","0"],["10.977","238"],["10.983","0"],["11.028","177"],["11.034","0"],["11.079","22"],["11.085","0"],["11.130","264"],["11.136","0"],["11.181","195"],["11.187","0"],["11.232","187"],["11.238","0"],["11.283","257"],["11.289","0"]],"bids":[["9.973","47"],["9.972","389"],["9.971","259"],["9.969","305"],["9.968","168"],["9.967","785"],["9.965","390"],["9.963","794"],["9.962","363"],["9.960","290"],["9.959","758"],["9.958","1723"],["9.957","1254"],["9.955","397"],["9.953","694"],["9.951","559"],["9.949","852"],["9.947","1324"],["9.943","989"],["9.940","716"],["9.929","963"],["9.927","1101"],["9.925","17748"],["9.920","12982"],["9.915","11443"],["9.910","12789"],["9.905","12213"],["9.900","12020"],["9.895","11636"],["9.890","13559"],["9.885","11828"],["9.875","13174"],["9.870","12597"],["9.792","0"],["9.786","34"],["9.742","0"],["9.736","75"],["9.692","0"],["9.686","180"],["9.642","0"],["9.636","248"],["9.592","0"],["9.586","267"],["9.542","0"],["9.536","238"],["9.492","0"],["9.486","153"],["9.442","0"],["9.436","265"],["9.392","0"],["9.386","254"],["9.342","0"],["9.336","80"],["9.292","0"],["9.286","161"],["9.242","0"],["9.236","99"],["9.192","0"],["9.186","100"],["9.142","0"],["9.136","50"],["9.092","0"],["9.086","92"],["9.042","0"],["9.036","333"],["8.992","0"],["8.986","341"],["8.942","0"],["8.936","239"],["8.892","0"],["8.886","43"],["8.842","0"],["8.836","262"],["8.792","0"],["8.786","300"],["8.742","0"],["8.736","27"],["8.692","0"],["8.686","326"],["8.642","0"],["8.636","76"],["8.592","0"],["8.586","188"],["8.542","0"],["8.536","131"],["8.492","0"],["8.486","106"],["8.442","0"],["8.436","90"],["8.392","0"],["8.386","271"]],"checksum":-1080424220,"ts":"1649290089682"}]}
1649290089.8419158: {"action":"snapshot","arg":{"instType":"mc","channel":"ticker","instId":"UNIUSDT"},"data":[{"instId":"UNIUSDT","last":"9.9760","bestAsk":"9.979","bestBid":"9.974","high24h":"10.4280","low24h":"9.9030","priceChangePercent":"-0.0394","capitalRate":"-0.000100","nextSettleTime":1649314800000,"systemTime":1649290089810,"markPrice":"9.9778","indexPrice":"9.9864","holding":"369411","baseVolume":"313086","quoteVolume":"3294474"}]}
1649290089.850454: {"action":"snapshot","arg":{"instType":"mc","channel":"ticker","instId":"DASHUSDT"},"data":[{"instId":"DASHUSDT","last":"113.390","bestAsk":"113.43","bestBid":"113.37","high24h":"118.870","low24h":"113.140","priceChangePercent":"-0.036","capitalRate":"-0.000100","nextSettleTime":1649314800000,"systemTime":1649290089819,"markPrice":"113.459","indexPrice":"113.478","holding":"21957.17","baseVolume":"25304.48","quoteVolume":"3062676.68"}]}
1649290089.933557: {"action":"update","arg":{"instType":"mc","channel":"books","instId":"DASHUSDT"},"data":[{"asks":[["113.42","4.31"],["113.43","0.33"],["113.44","2.28"],["113.46","4.62"],["113.47","9.48"],["113.48","1.10"],["113.50","14.30"],["113.51","34.32"],["113.52","68.76"],["113.53","29.89"],["113.54","58.41"],["113.55","141.11"],["113.56","77.56"],["113.57","65.75"],["113.58","6.95"],["113.60","171.40"],["113.62","1114.97"],["113.63","106.64"],["113.66","96.81"],["113.68","716.72"],["113.69","107.36"],["113.70","172.79"],["113.72","144.12"],["113.73","242.52"],["113.74","20.80"],["113.77","843.91"],["113.78","24.83"],["113.79","71.23"],["113.80","162.80"],["113.83","23.62"],["113.84","58.18"],["113.85","1955.61"],["113.86","190.65"],["113.87","43.00"],["113.88","136.04"],["113.91","1735.25"],["113.92","0"],["113.97","1797.80"],["114.03","2040.45"],["114.09","1952.22"],["114.15","1819.86"],["114.21","2018.39"],["114.27","1996.33"],["114.33","1974.27"],["114.39","1886.04"],["114.51","1863.98"],["114.57","1775.75"],["114.69","1753.69"],["114.75","1908.10"]],"bids":[["113.37","237.61"],["113.36","110.89"],["113.34","324.73"],["113.33","9.65"],["113.32","1600.12"],["113.31","13.17"],["113.30","23.85"],["113.29","13.63"],["113.28","27.05"],["113.27","34.49"],["113.26","29.87"],["113.25","47.68"],["113.24","21.77"],["113.21","44.35"],["113.20","31.01"],["113.19","234.21"],["113.18","47.50"],["113.15","292.16"],["113.13","146.89"],["113.12","45.57"],["113.10","134.56"],["113.09","4.50"],["113.08","72.31"],["113.05","1482.85"],["113.04","47.63"],["113.03","105.89"],["113.02","1508.75"],["113.01","19.95"],["112.98","526.54"],["112.97","108.47"],["112.94","2520.75"],["112.93","63.37"],["112.90","75.37"],["112.88","1802.03"],["112.87","421.64"],["112.86","0"],["112.85","0"],["112.82","1841.92"],["112.81","0"],["112.76","1952.22"],["112.75","0"],["112.70","1886.04"],["112.69","0"],["112.64","1930.16"],["112.63","0"],["112.58","1819.86"],["112.57","0"],["112.52","1908.10"],["112.51","0"],["112.46","1797.80"],["112.45","0"],["112.40","2040.45"],["112.39","0"],["112.34","1709.57"],["112.33","0"],["112.28","1996.33"],["112.27","0"],["112.22","1731.63"],["112.21","0"],["112.16","1863.98"],["112.15","0"],["112.10","1753.69"],["112.09","0"],["112.04","2018.39"],["112.03","0"]],"checksum":-1915993855,"ts":"1649290089905"}]}
1649290090.042084: {"action":"update","arg":{"instType":"mc","channel":"books","instId":"UNIUSDT"},"data":[{"asks":[["9.980","237"],["9.982","489"],["9.983","376"],["9.985","513"],["9.986","920"],["9.987","436"],["9.989","1549"],["9.990","950"],["9.991","444"],["9.994","2881"],["9.996","2115"],["9.997","1098"],["9.999","420"],["10.000","1614"],["10.001","1024"],["10.002","404"],["10.003","1818"],["10.006","604"],["10.008","1768"],["10.009","310"],["10.010","924"],["10.012","390"],["10.013","1365"],["10.015","1051"],["10.022","678"],["10.026","13377"],["10.031","12982"],["10.036","12213"],["10.041","12789"],["10.046","13559"],["10.051","13366"],["10.056","13174"],["10.061","12405"],["10.066","11636"],["10.071","11443"],["10.076","12597"],["10.081","11828"],["10.102","338"],["10.109","0"],["10.153","76"],["10.160","0"],["10.204","227"],["10.211","0"],["10.255","282"],["10.262","0"],["10.307","384"],["10.314","0"],["10.358","325"],["10.365","0"],["10.409","125"],["10.416","0"],["10.460","37"],["10.467","0"],["10.511","394"],["10.518","0"],["10.562","115"],["10.569","0"],["10.613","229"],["10.620","0"],["10.664","245"],["10.671","0"],["10.715","240"],["10.722","0"],["10.766","51"],["10.773","0"],["10.817","341"],["10.824","0"],["10.868","191"],["10.875","0"],["10.919","84"],["10.926","0"],["10.970","238"],["10.977","0"],["11.021","177"],["11.028","0"],["11.072","22"],["11.079","0"],["11.123","264"],["11.130","0"],["11.174","195"],["11.181","0"],["11.225","187"],["11.232","0"],["11.276","257"],["11.283","0"]],"bids":[["9.972","344"],["9.971","236"],["9.970","238"],["9.969","406"],["9.968","227"],["9.967","807"],["9.965","375"],["9.963","875"],["9.962","229"],["9.961","2283"],["9.960","629"],["9.959","572"],["9.958","1326"],["9.955","417"],["9.954","363"],["9.953","677"],["9.952","324"],["9.951","704"],["9.950","721"],["9.948","833"],["9.947","532"],["9.946","3084"],["9.944","4455"],["9.943","851"],["9.941","1723"],["9.940","1014"],["9.925","16595"],["9.920","11636"],["9.915","11828"],["9.910","12020"],["9.905","13174"],["9.900","11443"],["9.895","13366"],["9.890","12982"],["9.885","13559"],["9.880","12597"],["9.875","12405"],["9.870","12789"],["9.786","0"],["9.779","34"],["9.736","0"],["9.729","75"],["9.686","0"],["9.679","180"],["9.636","0"],["9.629","248"],["9.586","0"],["9.579","267"],["9.536","0"],["9.529","238"],["9.486","0"],["9.479","153"],["9.436","0"],["9.429","265"],["9.386","0"],["9.379","254"],["9.336","0"],["9.329","80"],["9.286","0"],["9.279","161"],["9.236","0"],["9.229","99"],["9.186","0"],["9.179","100"],["9.136","0"],["9.129","50"],["9.086","0"],["9.079","92"],["9.036","0"],["9.029","333"],["8.986","0"],["8.979","341"],["8.936","0"],["8.929","239"],["8.886","0"],["8.879","43"],["8.836","0"],["8.829","262"],["8.786","0"],["8.779","300"],["8.736","0"],["8.729","27"],["8.686","0"],["8.679","326"],["8.636","0"],["8.629","76"],["8.586","0"],["8.579","188"],["8.536","0"],["8.529","131"],["8.486","0"],["8.479","106"],["8.436","0"],["8.429","90"],["8.386","0"],["8.379","271"]],"checksum":-18806694,"ts":"1649290090010"}]}
1649290090.099581: {"action":"snapshot","arg":{"instType":"mc","channel":"ticker","instId":"UNIUSDT"},"data":[{"instId":"UNIUSDT","last":"9.9760","bestAsk":"9.978","bestBid":"9.973","high24h":"10.4280","low24h":"9.9030","priceChangePercent":"-0.0394","capitalRate":"-0.000100","nextSettleTime":1649314800000,"systemTime":1649290090071,"markPrice":"9.9778","indexPrice":"9.9845","holding":"369411","baseVolume":"313086","quoteVolume":"3294474"}]}
1649290090.147786: {"action":"snapshot","arg":{"instType":"mc","channel":"ticker","instId":"DASHUSDT"},"data":[{"instId":"DASHUSDT","last":"113.390","bestAsk":"113.43","bestBid":"113.38","high24h":"118.870","low24h":"113.140","priceChangePercent":"-0.036","capitalRate":"-0.000100","nextSettleTime":1649314800000,"systemTime":1649290090112,"markPrice":"113.459","indexPrice":"113.448","holding":"21957.17","baseVolume":"25304.48","quoteVolume":"3062676.68"}]}
1649290090.234807: {"action":"update","arg":{"instType":"mc","channel":"books","instId":"DASHUSDT"},"data":[{"asks":[["113.42","0"],["113.43","5.23"],["113.44","1.66"],["113.45","1.59"],["113.46","1.88"],["113.48","0"],["113.50","12.95"],["113.51","38.94"],["113.52","63.56"],["113.54","52.10"],["113.55","97.06"],["113.56","81.08"],["113.57","55.21"],["113.59","63.15"],["113.60","176.96"],["113.61","95.24"],["113.62","1124.61"],["113.64","104.62"],["113.67","25.37"],["113.73","246.88"],["113.75","32.41"],["113.77","846.33"],["113.79","68.20"],["113.82","21.86"],["113.85","246.05"],["113.86","2120.80"],["113.87","49.15"],["113.90","136.59"],["113.91","3.63"],["113.92","2133.20"],["113.93","36.82"],["113.97","0"],["113.98","1886.04"],["114.03","0"],["114.04","2040.45"],["114.09","0"],["114.10","1819.86"],["114.15","0"],["114.16","1797.80"],["114.21","0"],["114.22","1952.22"],["114.27","0"],["114.28","1731.63"],["114.33","0"],["114.34","1709.57"],["114.39","0"],["114.40","2018.39"],["114.45","0"],["114.46","1775.75"],["114.51","0"],["114.52","1974.27"],["114.57","0"],["114.58","1841.92"],["114.63","0"],["114.64","1908.10"],["114.69","0"],["114.70","1753.69"],["114.75","0"],["114.76","1863.98"]],"bids":[["113.38","7.40"],["113.36","130.69"],["113.34","235.43"],["113.30","42.82"],["113.28","63.79"],["113.27","13.62"],["113.26","25.50"],["113.25","43.43"],["113.24","35.63"],["113.23","24.62"],["113.20","28.27"],["113.18","45.61"],["113.15","295.07"],["113.13","145.30"],["113.11","15.16"],["113.05","1475.90"],["113.04","52.08"],["113.03","100.79"],["112.98","532.02"],["112.95","2195.57"],["112.94","421.75"],["112.93","58.02"],["112.92","88.82"],["112.91","9.08"],["112.89","1963.69"],["112.88","0"],["112.87","0"],["112.83","1886.04"],["112.82","0"],["112.77","1709.57"],["112.76","0"],["112.71","1974.27"],["112.70","0"],["112.65","1797.80"],["112.64","0"],["112.59","2018.39"],["112.58","0"],["112.53","1775.75"],["112.52","0"],["112.47","1731.63"],["112.46","0"],["112.41","1863.98"],["112.40","0"],["112.35","1996.33"],["112.34","0"],["112.29","1841.92"],["112.28","0"],["112.23","1930.16"],["112.22","0"],["112.17","1819.86"],["112.16","0"],["112.11","2040.45"],["112.10","0"],["112.05","1753.69"],["112.04","0"]],"checksum":1233032124,"ts":"1649290090205"}]}
1649290090.345929: {"action":"update","arg":{"instType":"mc","channel":"books","instId":"UNIUSDT"},"data":[{"asks":[["9.979","32"],["9.980","118"],["9.981","60"],["9.982","157"],["9.983","435"],["9.984","342"],["9.985","421"],["9.986","570"],["9.987","588"],["9.988","560"],["9.989","917"],["9.990","746"],["9.991","471"],["9.992","284"],["9.993","911"],["9.994","2921"],["9.995","942"],["9.996","1334"],["9.999","1265"],["10.000","822"],["10.001","972"],["10.003","1693"],["10.008","656"],["10.010","3169"],["10.011","1519"],["10.012","380"],["10.013","1296"],["10.018","4260"],["10.019","479"],["10.022","688"],["10.023","4238"],["10.024","233"],["10.026","13954"],["10.031","13366"],["10.036","12020"],["10.041","11636"],["10.046","11828"],["10.051","12213"],["10.056","11443"],["10.061","12789"],["10.066","12982"],["10.071","13559"],["10.076","13174"],["10.081","12405"],["10.096","338"],["10.102","0"],["10.147","76"],["10.153","0"],["10.198","227"],["10.204","0"],["10.249","282"],["10.255","0"],["10.301","384"],["10.307","0"],["10.352","325"],["10.358","0"],["10.403","125"],["10.409","0"],["10.454","37"],["10.460","0"],["10.505","394"],["10.511","0"],["10.556","115"],["10.562","0"],["10.607","229"],["10.613","0"],["10.658","245"],["10.664","0"],["10.709","240"],["10.715","0"],["10.760","51"],["10.766","0"],["10.811","341"],["10.817","0"],["10.862","191"],["10.868","0"],["10.913","84"],["10.919","0"],["10.964","238"],["10.970","0"],["11.015","177"],["11.021","0"],["11.066","22"],["11.072","0"],["11.117","264"],["11.123","0"],["11.168","195"],["11.174","0"],["11.219","187"],["11.225","0"],["11.270","257"],["11.276","0"]],"bids":[["9.973","67"],["9.972","359"],["9.971","319"],["9.969","331"],["9.967","789"],["9.964","947"],["9.963","1483"],["9.962","313"],["9.961","2811"],["9.960","597"],["9.959","479"],["9.958","1353"],["9.954","341"],["9.952","398"],["9.951","601"],["9.949","776"],["9.947","1918"],["9.946","2282"],["9.944","4403"],["9.940","800"],["9.930","1914"],["9.929","369"],["9.925","16210"],["9.920","12597"],["9.915","13366"],["9.910","11443"],["9.905","12020"],["9.900","13559"],["9.895","12213"],["9.890","11636"],["9.885","12789"],["9.880","12982"],["9.870","13174"],["9.779","0"],["9.773","34"],["9.729","0"],["9.723","75"],["9.679","0"],["9.673","180"],["9.629","0"],["9.623","248"],["9.579","0"],["9.573","267"],["9.529","0"],["9.523","238"],["9.479","0"],["9.473","153"],["9.429","0"],["9.423","265"],["9.379","0"],["9.373","254"],["9.329","0"],["9.323","80"],["9.279","0"],["9.273","161"],["9.229","0"],["9.223","99"],["9.179","0"],["9.173","100"],["9.129","0"],["9.123","50"],["9.079","0"],["9.073","92"],["9.029","0"],["9.023","333"],["8.979","0"],["8.973","341"],["8.929","0"],["8.923","239"],["8.879","0"],["8.873","43"],["8.829","0"],["8.823","262"],["8.779","0"],["8.773","300"],["8.729","0"],["8.723","27"],["8.679","0"],["8.673","326"],["8.629","0"],["8.623","76"],["8.579","0"],["8.573","188"],["8.529","0"],["8.523","131"],["8.479","0"],["8.473","106"],["8.429","0"],["8.423","90"],["8.379","0"],["8.373","271"]],"checksum":200922912,"ts":"1649290090315"}]}
1649290090.389071: {"action":"snapshot","arg":{"instType":"mc","channel":"ticker","instId":"UNIUSDT"},"data":[{"instId":"UNIUSDT","last":"9.9760","bestAsk":"9.979","bestBid":"9.973","high24h":"10.4280","low24h":"9.9030","priceChangePercent":"-0.0394","capitalRate":"-0.000100","nextSettleTime":1649314800000,"systemTime":1649290090357,"markPrice":"9.9779","indexPrice":"9.9845","holding":"369411","baseVolume":"313086","quoteVolume":"3294474"}]}
1649290090.393109: {"action":"snapshot","arg":{"instType":"mc","channel":"ticker","instId":"DASHUSDT"},"data":[{"instId":"DASHUSDT","last":"113.390","bestAsk":"113.44","bestBid":"113.38","high24h":"118.870","low24h":"113.140","priceChangePercent":"-0.036","capitalRate":"-0.000100","nextSettleTime":1649314800000,"systemTime":1649290090366,"markPrice":"113.459","indexPrice":"113.448","holding":"21957.17","baseVolume":"25304.48","quoteVolume":"3062676.68"}]}
1649290090.573164: {"action":"update","arg":{"instType":"mc","channel":"books","instId":"DASHUSDT"},"data":[{"asks":[["113.43","0"],["113.44","0"],["113.45","0"],["113.46","0.79"],["113.47","7.76"],["113.48","3.42"],["113.50","7.67"],["113.51","49.00"],["113.52","12.53"],["113.53","34.68"],["113.54","33.95"],["113.56","77.56"],["113.57","21.99"],["113.58","11.71"],["113.59","84.55"],["113.60","439.57"],["113.61","94.06"],["113.62","1126.69"],["113.63","108.49"],["113.64","156.34"],["113.65","206.72"],["113.66","95.82"],["113.68","386.01"],["113.69","108.85"],["113.70","153.79"],["113.72","121.14"],["113.73","242.52"],["113.74","303.94"],["113.76","143.36"],["113.79","64.79"],["113.83","28.07"],["113.86","190.65"],["113.87","64.70"],["113.88","138.87"],["113.89","2036.21"],["113.90","130.08"],["113.92","136.88"],["113.93","31.17"],["113.94","119.50"],["113.95","1939.87"],["113.98","0"],["114.01","1731.63"],["114.04","0"],["114.07","1709.57"],["114.10","0"],["114.13","1952.22"],["114.16","0"],["114.19","1930.16"],["114.22","0"],["114.25","1863.98"],["114.28","0"],["114.31","1753.69"],["114.34","0"],["114.37","1996.33"],["114.40","0"],["114.43","1797.80"],["114.46","0"],["114.49","1819.86"],["114.52","0"],["114.55","1886.04"],["114.58","0"],["114.61","1908.10"],["114.64","0"],["114.67","1974.27"],["114.70","0"],["114.73","2040.45"],["114.76","0"],["114.79","1775.75"],["115.78","0.73"],["116.00","0"],["116.37","68.26"],["116.59","0"],["116.96","70.90"],["117.18","0"],["117.55","49.89"],["117.77","0"],["118.14","22.59"],["118.36","0"],["118.73","47.85"],["118.95","0"],["119.32","46.71"],["119.54","0"],["119.91","23.57"],["120.13","0"],["120.50","59.15"],["120.72","0"],["121.09","6.51"],["121.31","0"],["121.68","54.25"],["121.90","0"],["122.27","14.99"],["122.49","0"],["122.86","11.21"],["123.08","0"],["123.45","66.50"],["123.67","0"],["124.04","64.47"],["124.26","0"],["124.63","42.85"],["124.85","0"],["125.22","29.99"],["125.44","0"],["125.81","4.07"],["126.03","0"],["126.40","26.70"],["126.62","0"],["126.99","20.67"],["127.21","0"],["127.58","56.99"],["127.80","0"],["128.17","44.01"],["128.39","0"],["128.76","46.60"],["128.98","0"],["129.35","39.07"],["129.57","0"],["129.94","19.33"],["130.16","0"],["130.53","20.66"],["130.75","0"],["131.12","28.11"],["131.34","0"],["131.71","13.65"],["131.93","0"],["132.52","0"],["133.11","0"],["133.70","0"]],"bids":[["113.40","43.57"],["113.38","13.80"],["113.36","69.15"],["113.35","138.23"],["113.34","166.13"],["113.33","6.66"],["113.32","1600.19"],["113.31","45.89"],["113.30","26.04"],["113.29","10.89"],["113.28","67.34"],["113.26","21.72"],["113.23","89.60"],["113.21","5.18"],["113.20","27.86"],["113.19","265.39"],["113.18","41.30"],["113.15","285.98"],["113.13","142.90"],["113.12","39.28"],["113.11","9.69"],["113.10","125.01"],["113.09","7.99"],["113.08","68.05"],["113.07","223.70"],["113.05","1475.23"],["113.04","47.63"],["113.00","78.04"],["112.97","2149.37"],["112.96","183.84"],["112.95","287.48"],["112.93","11.14"],["112.91","1985.32"],["112.89","0"],["112.85","2018.39"],["112.83","0"],["112.79","1908.10"],["112.77","0"],["112.73","1731.63"],["112.71","0"],["112.67","1841.92"],["112.65","0"],["112.61","1952.22"],["112.59","0"],["112.55","1863.98"],["112.53","0"],["112.49","1996.33"],["112.47","0"],["112.43","1930.16"],["112.41","0"],["112.37","1709.57"],["112.35","0"],["112.31","1753.69"],["112.29","0"],["112.25","1819.86"],["112.23","0"],["112.19","1775.75"],["112.17","0"],["112.13","1886.04"],["112.11","0"],["112.07","1797.80"],["112.05","0"],["111.66","54.98"],["111.61","0"],["111.07","56.15"],["111.02","0"],["110.47","22.20"],["110.43","0"],["109.88","45.95"],["109.84","0"],["109.29","29.62"],["109.25","0"],["108.70","21.93"],["108.66","0"],["108.11","6.02"],["108.07","0"],["107.52","55.97"],["107.48","0"],["106.93","21.31"],["106.89","0"],["106.34","8.95"],["106.30","0"],["105.75","10.15"],["105.71","0"],["105.16","40.07"],["105.12","0"],["104.57","15.36"],["104.53","0"],["103.98","46.47"],["103.94","0"],["103.39","11.11"],["103.35","0"],["102.80","1.87"],["102.76","0"],["102.21","37.67"],["102.17","0"],["101.62","21.48"],["101.58","0"],["101.03","49.80"],["100.99","0"],["100.44","49.32"],["100.40","0"],["99.85","42.14"],["99.26","8.55"],["98.67","30.36"],["98.08","20.32"],["97.49","36.65"],["96.90","21.95"],["96.31","8.41"],["95.72","31.49"],["95.13","57.35"],["94.54","3.45"],["93.95","4.85"],["93.36","74.35"],["92.77","33.85"],["92.18","20.24"]],"checksum":-1830850979,"ts":"1649290090538"}]}
1649290090.639439: {"action":"snapshot","arg":{"instType":"mc","channel":"ticker","instId":"UNIUSDT"},"data":[{"instId":"UNIUSDT","last":"9.9760","bestAsk":"9.98","bestBid":"9.975","high24h":"10.4280","low24h":"9.9030","priceChangePercent":"-0.0394","capitalRate":"-0.000100","nextSettleTime":1649314800000,"systemTime":1649290090611,"markPrice":"9.9779","indexPrice":"9.9845","holding":"369411","baseVolume":"313086","quoteVolume":"3294474"}]}
1649290090.6481652: {"action":"update","arg":{"instType":"mc","channel":"books","instId":"UNIUSDT"},"data":[{"asks":[["9.978","0"],["9.979","0"],["9.981","73"],["9.982","114"],["9.983","270"],["9.984","445"],["9.985","852"],["9.986","556"],["9.987","436"],["9.988","730"],["9.989","1120"],["9.990","972"],["9.991","511"],["9.992","301"],["9.993","1084"],["9.994","2793"],["9.995","786"],["9.996","1378"],["9.997","1399"],["9.998","773"],["10.000","842"],["10.001","1029"],["10.002","1204"],["10.003","1540"],["10.005","900"],["10.008","969"],["10.009","222"],["10.011","1377"],["10.013","1034"],["10.015","794"],["10.016","766"],["10.022","830"],["10.026","1322"],["10.028","12471"],["10.029","5291"],["10.031","0"],["10.033","13366"],["10.036","0"],["10.038","12213"],["10.041","0"],["10.043","12789"],["10.046","0"],["10.048","12405"],["10.051","0"],["10.053","11443"],["10.056","0"],["10.058","13559"],["10.061","0"],["10.063","13174"],["10.066","0"],["10.068","12597"],["10.071","0"],["10.073","11636"],["10.076","0"],["10.078","11828"],["10.081","0"],["10.083","12982"],["10.091","338"],["10.096","0"],["10.142","76"],["10.147","0"],["10.193","227"],["10.198","0"],["10.244","282"],["10.249","0"],["10.296","384"],["10.301","0"],["10.347","325"],["10.352","0"],["10.398","125"],["10.403","0"],["10.449","37"],["10.454","0"],["10.500","394"],["10.505","0"],["10.551","115"],["10.556","0"],["10.602","229"],["10.607","0"],["10.653","245"],["10.658","0"],["10.704","240"],["10.709","0"],["10.755","51"],["10.760","0"],["10.806","341"],["10.811","0"],["10.857","191"],["10.862","0"],["10.908","84"],["10.913","0"],["10.959","238"],["10.964","0"],["11.010","177"],["11.015","0"],["11.061","22"],["11.066","0"],["11.112","264"],["11.117","0"],["11.163","195"],["11.168","0"],["11.214","187"],["11.219","0"],["11.265","257"],["11.270","0"]],"bids":[["9.975","181"],["9.974","129"],["9.973","36"],["9.972","257"],["9.971","262"],["9.970","189"],["9.969","767"],["9.968","212"],["9.967","808"],["9.965","416"],["9.964","831"],["9.963","1546"],["9.962","230"],["9.961","3162"],["9.960","237"],["9.959","499"],["9.957","1407"],["9.956","746"],["9.955","482"],["9.954","330"],["9.953","601"],["9.952","413"],["9.951","584"],["9.949","772"],["9.948","1614"],["9.945","997"],["9.944","4832"],["9.943","901"],["9.942","1145"],["9.940","674"],["9.937","696"],["9.936","680"],["9.935","118"],["9.931","3624"],["9.927","13120"],["9.925","0"],["9.924","0"],["9.922","12597"],["9.920","0"],["9.917","13559"],["9.915","0"],["9.912","11828"],["9.910","0"],["9.907","11443"],["9.905","0"],["9.902","13366"],["9.900","0"],["9.897","12405"],["9.895","0"],["9.892","11636"],["9.890","0"],["9.887","13174"],["9.885","0"],["9.882","12982"],["9.880","0"],["9.877","12789"],["9.875","0"],["9.872","12213"],["9.870","0"],["9.773","0"],["9.768","34"],["9.723","0"],["9.718","75"],["9.673","0"],["9.668","180"],["9.623","0"],["9.618","248"],["9.573","0"],["9.568","267"],["9.523","0"],["9.518","238"],["9.473","0"],["9.468","153"],["9.423","0"],["9.418","265"],["9.373","0"],["9.368","254"],["9.323","0"],["9.318","80"],["9.273","0"],["9.268","161"],["9.223","0"],["9.218","99"],["9.173","0"],["9.168","100"],["9.123","0"],["9.118","50"],["9.073","0"],["9.068","92"],["9.023","0"],["9.018","333"],["8.973","0"],["8.968","341"],["8.923","0"],["8.918","239"],["8.873","0"],["8.868","43"],["8.823","0"],["8.818","262"],["8.773","0"],["8.768","300"],["8.723","0"],["8.718","27"],["8.673","0"],["8.668","326"],["8.623","0"],["8.618","76"],["8.573","0"],["8.568","188"],["8.523","0"],["8.518","131"],["8.473","0"],["8.468","106"],["8.423","0"],["8.418","90"],["8.373","0"],["8.368","271"]],"checksum":-1855594922,"ts":"1649290090619"}]}
1649290090.6533701: {"action":"snapshot","arg":{"instType":"mc","channel":"ticker","instId":"DASHUSDT"},"data":[{"instId":"DASHUSDT","last":"113.390","bestAsk":"113.46","bestBid":"113.4","high24h":"118.870","low24h":"113.140","priceChangePercent":"-0.036","capitalRate":"-0.000100","nextSettleTime":1649314800000,"systemTime":1649290090618,"markPrice":"113.459","indexPrice":"113.448","holding":"21957.17","baseVolume":"25304.48","quoteVolume":"3062676.68"}]}
1649290090.867947: {"action":"update","arg":{"instType":"mc","channel":"books","instId":"DASHUSDT"},"data":[{"asks":[["113.46","0"],["113.47","3.63"],["113.48","4.96"],["113.50","11.38"],["113.52","18.26"],["113.53","58.44"],["113.54","17.38"],["113.55","6.03"],["113.57","20.22"],["113.58","31.90"],["113.59","37.60"],["113.60","519.76"],["113.61","109.60"],["113.62","1056.02"],["113.63","107.17"],["113.65","152.94"],["113.66","76.12"],["113.67","16.95"],["113.69","5.39"],["113.70","177.74"],["113.71","171.69"],["113.73","226.68"],["113.74","300.97"],["113.75","424.76"],["113.77","816.63"],["113.82","20.62"],["113.86","193.12"],["113.87","59.76"],["113.89","17.83"],["113.90","2170.52"],["113.95","97.96"],["113.96","3263.60"],["114.01","0"],["114.02","2018.39"],["114.07","0"],["114.08","1863.98"],["114.13","0"],["114.14","1775.75"],["114.19","0"],["114.20","1908.10"],["114.25","0"],["114.26","1731.63"],["114.31","0"],["114.32","1952.22"],["114.37","0"],["114.38","1930.16"],["114.43","0"],["114.44","1709.57"],["114.49","0"],["114.50","1886.04"],["114.55","0"],["114.56","1996.33"],["114.61","0"],["114.62","1797.80"],["114.67","0"],["114.68","1841.92"],["114.73","0"],["114.74","1974.27"],["114.79","0"],["114.80","1819.86"]],"bids":[["113.41","4.96"],["113.40","142.57"],["113.39","4.96"],["113.38","9.14"],["113.36","16.23"],["113.35","187.89"],["113.34","7.53"],["113.33","15.85"],["113.31","13.71"],["113.30","90.67"],["113.28","56.87"],["113.24","34.14"],["113.23","81.47"],["113.22","40.35"],["113.20","29.34"],["113.18","55.22"],["113.14","404.80"],["113.13","137.55"],["113.11","5.54"],["113.10","42.27"],["113.08","70.17"],["113.03","84.80"],["113.00","79.38"],["112.98","2395.99"],["112.97","108.93"],["112.92","2129.26"],["112.91","0"],["112.90","0"],["112.86","1952.22"],["112.85","0"],["112.80","1886.04"],["112.79","0"],["112.74","2018.39"],["112.73","0"],["112.68","1974.27"],["112.67","0"],["112.62","1930.16"],["112.61","0"],["112.56","1996.33"],["112.55","0"],["112.50","1908.10"],["112.49","0"],["112.44","1753.69"],["112.43","0"],["112.38","1731.63"],["112.37","0"],["112.32","1841.92"],["112.31","0"],["112.26","1819.86"],["112.25","0"],["112.20","1775.75"],["112.19","0"],["112.14","1709.57"],["112.13","0"],["112.08","1797.80"],["112.07","0"]],"checksum":-1702463679,"ts":"1649290090841"}]}
1649290090.906823: {"action":"snapshot","arg":{"instType":"mc","channel":"ticker","instId":"UNIUSDT"},"data":[{"instId":"UNIUSDT","last":"9.9760","bestAsk":"9.982","bestBid":"9.977","high24h":"10.4280","low24h":"9.9030","priceChangePercent":"-0.0394","capitalRate":"-0.000100","nextSettleTime":1649314800000,"systemTime":1649290090879,"markPrice":"9.9779","indexPrice":"9.9845","holding":"369411","baseVolume":"313086","quoteVolume":"3294474"}]}
1649290090.918564: {"action":"snapshot","arg":{"instType":"mc","channel":"ticker","instId":"DASHUSDT"},"data":[{"instId":"DASHUSDT","last":"113.390","bestAsk":"113.47","bestBid":"113.41","high24h":"118.870","low24h":"113.140","priceChangePercent":"-0.036","capitalRate":"-0.000100","nextSettleTime":1649314800000,"systemTime":1649290090887,"markPrice":"113.459","indexPrice":"113.448","holding":"21957.17","baseVolume":"25304.48","quoteVolume":"3062676.68"}]}
1649290090.978226: {"action":"update","arg":{"instType":"mc","channel":"books","instId":"UNIUSDT"},"data":[{"asks":[["9.980","0"],["9.981","0"],["9.982","55"],["9.983","108"],["9.984","91"],["9.985","269"],["9.986","463"],["9.987","564"],["9.988","512"],["9.989","602"],["9.990","801"],["9.991","458"],["9.992","216"],["9.993","1014"],["9.994","2828"],["9.995","692"],["9.996","1382"],["9.997","946"],["9.998","566"],["9.999","1611"],["10.000","926"],["10.001","1026"],["10.002","421"],["10.003","2421"],["10.004","881"],["10.005","908"],["10.007","509"],["10.008","663"],["10.009","97"],["10.010","3105"],["10.012","207"],["10.013","1103"],["10.015","962"],["10.016","884"],["10.022","662"],["10.023","3947"],["10.026","1350"],["10.028","452"],["10.029","4994"],["10.030","11818"],["10.031","26"],["10.033","0"],["10.035","12405"],["10.038","0"],["10.040","13559"],["10.043","0"],["10.045","13174"],["10.048","0"],["10.050","12982"],["10.053","0"],["10.055","11828"],["10.058","0"],["10.060","13366"],["10.063","0"],["10.065","12020"],["10.068","0"],["10.070","12597"],["10.073","0"],["10.075","12213"],["10.078","0"],["10.080","12789"],["10.083","0"],["10.085","11443"],["10.091","0"],["10.135","317"],["10.142","0"],["10.186","191"],["10.193","0"],["10.237","49"],["10.244","0"],["10.289","178"],["10.296","0"],["10.340","225"],["10.347","0"],["10.391","286"],["10.398","0"],["10.442","307"],["10.449","0"],["10.493","131"],["10.500","0"],["10.544","171"],["10.551","0"],["10.595","312"],["10.602","0"],["10.646","282"],["10.653","0"],["10.697","90"],["10.704","0"],["10.748","84"],["10.755","0"],["10.799","279"],["10.806","0"],["10.850","257"],["10.857","0"],["10.901","178"],["10.908","0"],["10.952","257"],["10.959","0"],["11.003","221"],["11.010","0"],["11.054","63"],["11.061","0"],["11.105","16"],["11.112","0"],["11.156","64"],["11.163","0"],["11.207","139"],["11.214","0"],["11.258","234"],["11.265","0"],["11.309","147"],["11.360","29"],["11.411","328"],["11.462","76"],["11.513","117"]],"bids":[["9.977","225"],["9.976","75"],["9.975","252"],["9.974","143"],["9.973","121"],["9.972","177"],["9.971","462"],["9.970","251"],["9.969","796"],["9.968","311"],["9.967","871"],["9.966","208"],["9.965","558"],["9.964","1843"],["9.963","1337"],["9.961","2101"],["9.959","374"],["9.958","1381"],["9.957","1368"],["9.956","548"],["9.955","457"],["9.954","367"],["9.952","462"],["9.950","694"],["9.949","1690"],["9.948","822"],["9.946","2317"],["9.945","1175"],["9.942","770"],["9.941","1795"],["9.939","1032"],["9.938","772"],["9.937","520"],["9.936","510"],["9.934","3577"],["9.933","3195"],["9.929","11811"],["9.928","7180"],["9.927","0"],["9.926","0"],["9.924","12020"],["9.922","0"],["9.919","13174"],["9.917","0"],["9.914","13559"],["9.912","0"],["9.909","12213"],["9.907","0"],["9.904","12789"],["9.902","0"],["9.899","12982"],["9.897","0"],["9.894","12405"],["9.892","0"],["9.889","11636"],["9.887","0"],["9.884","12597"],["9.882","0"],["9.879","11828"],["9.877","0"],["9.874","13366"],["9.872","0"],["9.768","0"],["9.761","34"],["9.718","0"],["9.711","75"],["9.668","0"],["9.661","180"],["9.618","0"],["9.611","248"],["9.568","0"],["9.561","267"],["9.518","0"],["9.511","238"],["9.468","0"],["9.461","153"],["9.418","0"],["9.411","265"],["9.368","0"],["9.361","254"],["9.318","0"],["9.311","80"],["9.268","0"],["9.261","161"],["9.218","0"],["9.211","99"],["9.168","0"],["9.161","100"],["9.118","0"],["9.111","50"],["9.068","0"],["9.061","92"],["9.018","0"],["9.011","333"],["8.968","0"],["8.961","341"],["8.918","0"],["8.911","239"],["8.868","0"],["8.861","43"],["8.818","0"],["8.811","262"],["8.768","0"],["8.761","300"],["8.718","0"],["8.711","27"],["8.668","0"],["8.661","326"],["8.618","0"],["8.611","76"],["8.568","0"],["8.561","188"],["8.518","0"],["8.511","131"],["8.468","0"],["8.461","106"],["8.418","0"],["8.411","90"],["8.368","0"],["8.361","271"]],"checksum":225755607,"ts":"1649290090949"}]}
1649290091.1684139: {"action":"update","arg":{"instType":"mc","channel":"books","instId":"DASHUSDT"},"data":[{"asks":[["113.47","0"],["113.48","0.82"],["113.49","4.31"],["113.50","4.78"],["113.52","14.41"],["113.53","58.90"],["113.56","62.43"],["113.57","23.34"],["113.58","12.58"],["113.59","39.13"],["113.60","299.41"],["113.61","142.57"],["113.62","87.37"],["113.63","122.71"],["113.64","144.99"],["113.65","1447.14"],["113.66","53.18"],["113.67","17.77"],["113.72","118.50"],["113.73","215.79"],["113.74","280.18"],["113.76","139.01"],["113.77","814.97"],["113.78","33.08"],["113.79","71.06"],["113.80","173.20"],["113.82","22.73"],["113.87","63.14"],["113.90","130.08"],["113.91","1845.54"],["113.92","132.80"],["113.96","1509.92"],["113.97","2367.11"],["114.02","0"],["114.03","1886.04"],["114.08","0"],["114.09","1952.22"],["114.14","0"],["114.15","1753.69"],["114.20","0"],["114.21","1908.10"],["114.26","0"],["114.27","1819.86"],["114.32","0"],["114.33","1797.80"],["114.38","0"],["114.39","1863.98"],["114.44","0"],["114.45","1930.16"],["114.50","0"],["114.51","1731.63"],["114.56","0"],["114.57","1974.27"],["114.62","0"],["114.63","1775.75"],["114.68","0"],["114.69","1996.33"],["114.74","0"],["114.75","2040.45"],["114.80","0"],["114.81","1709.57"],["115.78","0"],["116.00","31.47"],["116.37","0"],["116.59","50.46"],["116.96","0"],["117.18","49.40"],["117.55","0"],["117.77","27.41"],["118.14","0"],["118.36","50.42"],["118.73","0"],["118.95","50.07"],["119.32","0"],["119.54","36.12"],["119.91","0"],["120.13","8.62"],["120.50","0"],["120.72","54.60"],["121.09","0"],["121.31","1.48"],["121.68","0"],["121.90","43.49"],["122.27","0"],["122.49","7.73"],["122.86","0"],["123.08","58.21"],["123.45","0"],["123.67","52.67"],["124.04","0"],["124.26","53.84"],["124.63","0"],["124.85","4.99"],["125.22","0"],["125.44","44.04"],["125.81","0"],["126.03","25.10"],["126.40","0"],["126.62","39.09"],["126.99","0"],["127.21","44.51"],["127.58","0"],["127.80","19.01"],["128.17","0"],["128.39","29.39"],["128.76","0"],["128.98","3.89"],["129.35","0"],["129.57","23.37"],["129.94","0"],["130.16","24.18"],["130.53","0"],["130.75","9.15"],["131.12","0"],["131.34","27.04"],["131.71","0"],["131.93","7.10"],["132.52","13.38"],["133.11","33.57"],["133.70","76.51"]],"bids":[["113.43","4.96"],["113.42","13.87"],["113.41","32.68"],["113.39","8.90"],["113.38","11.59"],["113.37","121.90"],["113.36","19.22"],["113.33","21.67"],["113.29","5.95"],["113.28","52.86"],["113.23","85.24"],["113.22","32.43"],["113.18","134.17"],["113.15","125.34"],["113.08","78.24"],["113.07","219.24"],["113.03","83.63"],["113.01","38.61"],["113.00","1921.29"],["112.98","554.30"],["112.94","2131.31"],["112.93","0"],["112.92","0"],["112.88","2018.39"],["112.86","0"],["112.82","1886.04"],["112.80","0"],["112.76","1908.10"],["112.74","0"],["112.70","1974.27"],["112.68","0"],["112.64","1996.33"],["112.62","0"],["112.58","1930.16"],["112.56","0"],["112.52","1797.80"],["112.50","0"],["112.46","1952.22"],["112.44","0"],["112.40","1753.69"],["112.38","0"],["112.34","1863.98"],["112.32","0"],["112.28","1775.75"],["112.26","0"],["112.22","1819.86"],["112.20","0"],["112.16","2040.45"],["112.14","0"],["112.10","1731.63"],["112.08","0"],["111.66","0"],["111.61","44.63"],["111.07","0"],["111.02","97.81"],["110.47","0"],["110.43","40.49"],["109.88","0"],["109.84","85.27"],["109.29","0"],["109.25","84.73"],["108.70","0"],["108.66","59.74"],["108.11","0"],["108.07","61.13"],["107.52","0"],["107.48","33.01"],["106.93","0"],["106.89","56.85"],["106.34","0"],["106.30","24.34"],["105.75","0"],["105.71","1.74"],["105.16","0"],["105.12","57.94"],["104.57","0"],["104.53","58.21"],["103.98","0"],["103.94","46.12"],["103.39","0"],["103.35","52.32"],["102.80","0"],["102.76","45.29"],["102.21","0"],["102.17","22.94"],["101.62","0"],["101.58","36.02"],["101.03","0"],["100.99","38.02"],["100.44","0"],["100.40","53.60"],["99.85","0"],["99.26","0"],["98.67","0"],["98.08","0"],["97.49","0"],["96.90","0"],["96.31","0"],["95.72","0"],["95.13","0"],["94.54","0"],["93.95","0"],["93.36","0"],["92.77","0"],["92.18","0"]],"checksum":-1251296598,"ts":"1649290091138"}]}
1649290091.1750941: {"action":"snapshot","arg":{"instType":"mc","channel":"ticker","instId":"UNIUSDT"},"data":[{"instId":"UNIUSDT","last":"9.9760","bestAsk":"9.982","bestBid":"9.977","high24h":"10.4280","low24h":"9.9030","priceChangePercent":"-0.0394","capitalRate":"-0.000100","nextSettleTime":1649314800000,"systemTime":1649290091139,"markPrice":"9.9779","indexPrice":"9.9845","holding":"369411","baseVolume":"313086","quoteVolume":"3294474"}]}
1649290091.175162: {"action":"snapshot","arg":{"instType":"mc","channel":"ticker","instId":"DASHUSDT"},"data":[{"instId":"DASHUSDT","last":"113.390","bestAsk":"113.48","bestBid":"113.43","high24h":"118.870","low24h":"113.140","priceChangePercent":"-0.036","capitalRate":"-0.000100","nextSettleTime":1649314800000,"systemTime":1649290091141,"markPrice":"113.449","indexPrice":"113.448","holding":"21957.17","baseVolume":"25304.48","quoteVolume":"3062676.68"}]}
1649290091.2943401: {"action":"update","arg":{"instType":"mc","channel":"books","instId":"UNIUSDT"},"data":[{"asks":[["9.982","0"],["9.983","53"],["9.984","43"],["9.985","139"],["9.986","399"],["9.987","642"],["9.988","620"],["9.989","266"],["9.990","696"],["9.991","444"],["9.992","171"],["9.993","668"],["9.994","2418"],["9.995","573"],["9.996","1627"],["9.997","456"],["9.998","235"],["9.999","1501"],["10.000","1011"],["10.001","1069"],["10.002","687"],["10.003","1239"],["10.004","598"],["10.005","667"],["10.006","851"],["10.007","524"],["10.009","280"],["10.010","2719"],["10.011","1354"],["10.012","367"],["10.013","850"],["10.014","3886"],["10.015","1060"],["10.016","660"],["10.017","3582"],["10.018","527"],["10.019","429"],["10.021","359"],["10.022","256"],["10.023","3920"],["10.026","4819"],["10.027","1601"],["10.028","4124"],["10.029","5344"],["10.030","251"],["10.031","13199"],["10.032","135"],["10.035","0"],["10.036","11828"],["10.040","0"],["10.041","11636"],["10.045","0"],["10.046","13366"],["10.050","0"],["10.051","12597"],["10.055","0"],["10.056","12405"],["10.060","0"],["10.061","12213"],["10.065","0"],["10.066","11443"],["10.070","0"],["10.071","12020"],["10.075","0"],["10.076","13559"],["10.080","0"],["10.081","12789"],["10.085","0"],["10.086","12982"],["10.128","317"],["10.135","0"],["10.179","191"],["10.186","0"],["10.230","49"],["10.237","0"],["10.282","178"],["10.289","0"],["10.333","225"],["10.340","0"],["10.384","286"],["10.391","0"],["10.435","307"],["10.442","0"],["10.486","131"],["10.493","0"],["10.537","171"],["10.544","0"],["10.588","312"],["10.595","0"],["10.639","282"],["10.646","0"],["10.690","90"],["10.697","0"],["10.741","84"],["10.748","0"],["10.792","279"],["10.799","0"],["10.843","257"],["10.850","0"],["10.894","178"],["10.901","0"],["10.945","257"],["10.952","0"],["10.996","221"],["11.003","0"],["11.047","63"],["11.054","0"],["11.098","16"],["11.105","0"],["11.149","64"],["11.156","0"],["11.200","139"],["11.207","0"],["11.251","234"],["11.258","0"],["11.302","147"],["11.309","0"],["11.353","29"],["11.360","0"],["11.404","328"],["11.411","0"],["11.455","76"],["11.462","0"],["11.506","117"],["11.513","0"]],"bids":[["9.978","36"],["9.977","216"],["9.976","101"],["9.975","249"],["9.974","159"],["9.973","174"],["9.972","325"],["9.971","682"],["9.970","105"],["9.969","908"],["9.968","408"],["9.967","979"],["9.966","17"],["9.965","435"],["9.964","814"],["9.963","625"],["9.962","273"],["9.961","2045"],["9.960","238"],["9.959","391"],["9.958","1361"],["9.957","2079"],["9.956","629"],["9.955","526"],["9.954","290"],["9.953","782"],["9.952","589"],["9.951","608"],["9.950","737"],["9.949","1030"],["9.948","567"],["9.946","2400"],["9.945","1090"],["9.944","4852"],["9.943","833"],["9.942","1073"],["9.941","1757"],["9.937","654"],["9.936","680"],["9.932","694"],["9.931","3636"],["9.930","13306"],["9.929","289"],["9.928","0"],["9.925","11636"],["9.924","0"],["9.920","12982"],["9.919","0"],["9.915","12020"],["9.914","0"],["9.910","13366"],["9.909","0"],["9.905","13559"],["9.904","0"],["9.900","11828"],["9.899","0"],["9.895","12405"],["9.894","0"],["9.890","12789"],["9.889","0"],["9.885","12213"],["9.884","0"],["9.880","12597"],["9.879","0"],["9.875","13174"],["9.874","0"],["9.761","0"],["9.754","34"],["9.711","0"],["9.704","75"],["9.661","0"],["9.654","180"],["9.611","0"],["9.604","248"],["9.561","0"],["9.554","267"],["9.511","0"],["9.504","238"],["9.461","0"],["9.454","153"],["9.411","0"],["9.404","265"],["9.361","0"],["9.354","254"],["9.311","0"],["9.304","80"],["9.261","0"],["9.254","161"],["9.211","0"],["9.204","99"],["9.161","0"],["9.154","100"],["9.111","0"],["9.104","50"],["9.061","0"],["9.054","92"],["9.011","0"],["9.004","333"],["8.961","0"],["8.954","341"],["8.911","0"],["8.904","239"],["8.861","0"],["8.854","43"],["8.811","0"],["8.804","262"],["8.761","0"],["8.754","300"],["8.711","0"],["8.704","27"],["8.661","0"],["8.654","326"],["8.611","0"],["8.604","76"],["8.561","0"],["8.554","188"],["8.511","0"],["8.504","131"],["8.461","0"],["8.454","106"],["8.411","0"],["8.404","90"],["8.361","0"],["8.354","271"]],"checksum":604912114,"ts":"1649290091266"}]}
1649290091.4404988: {"action":"snapshot","arg":{"instType":"mc","channel":"ticker","instId":"UNIUSDT"},"data":[{"instId":"UNIUSDT","last":"9.9760","bestAsk":"9.983","bestBid":"9.978","high24h":"10.4280","low24h":"9.9030","priceChangePercent":"-0.0394","capitalRate":"-0.000100","nextSettleTime":1649314800000,"systemTime":1649290091400,"markPrice":"9.9774","indexPrice":"9.9845","holding":"369411","baseVolume":"313086","quoteVolume":"3294474"}]}
1649290091.440595: {"action":"snapshot","arg":{"instType":"mc","channel":"ticker","instId":"DASHUSDT"},"data":[{"instId":"DASHUSDT","last":"113.390","bestAsk":"113.49","bestBid":"113.43","high24h":"118.870","low24h":"113.140","priceChangePercent":"-0.036","capitalRate":"-0.000100","nextSettleTime":1649314800000,"systemTime":1649290091407,"markPrice":"113.449","indexPrice":"113.478","holding":"21957.17","baseVolume":"25304.48","quoteVolume":"3062676.68"}]}
1649290091.469364: {"action":"update","arg":{"instType":"mc","channel":"books","instId":"DASHUSDT"},"data":[{"asks":[["113.49","1.88"],["113.51","50.48"],["113.54","40.71"],["113.55","17.81"],["113.56","61.91"],["113.57","63.53"],["113.58","10.10"],["113.59","34.82"],["113.60","304.36"],["113.61","94.06"],["113.62","77.23"],["113.63","107.50"],["113.64","198.45"],["113.65","1462.68"],["113.66","51.49"],["113.68","386.48"],["113.70","207.44"],["113.72","119.64"],["113.73","57.89"],["113.74","145.93"],["113.77","844.67"],["113.80","172.21"],["113.82","20.46"],["113.86","197.66"],["113.90","139.98"],["113.91","1999.95"],["113.97","2063.17"],["114.03","1731.63"],["114.21","1930.16"],["114.27","1709.57"],["114.33","1841.92"],["114.39","2040.45"],["114.45","1863.98"],["114.51","1886.04"],["114.57","2018.39"],["114.63","1974.27"],["114.69","1819.86"],["114.75","1908.10"],["114.81","1775.75"],["115.78","0.73"],["116.00","0"],["116.37","68.26"],["116.59","0"],["116.96","70.90"],["117.18","0"],["117.55","49.89"],["117.77","0"],["118.14","22.59"],["118.36","0"],["118.73","47.85"],["118.95","0"],["119.32","46.71"],["119.54","0"],["119.91","23.57"],["120.13","0"],["120.50","59.15"],["120.72","0"],["121.09","6.51"],["121.31","0"],["121.68","54.25"],["121.90","0"],["122.27","14.99"],["122.49","0"],["122.86","11.21"],["123.08","0"],["123.45","66.50"],["123.67","0"],["124.04","64.47"],["124.26","0"],["124.63","42.85"],["124.85","0"],["125.22","29.99"],["125.44","0"],["125.81","4.07"],["126.03","0"],["126.40","26.70"],["126.62","0"],["126.99","20.67"],["127.21","0"],["127.58","56.99"],["127.80","0"],["128.17","44.01"],["128.39","0"],["128.76","46.60"],["128.98","0"],["129.35","39.07"],["129.57","0"],["129.94","19.33"],["130.16","0"],["130.53","20.66"],["130.75","0"],["131.12","28.11"],["131.34","0"],["131.71","13.65"],["131.93","0"],["132.52","0"],["133.11","0"],["133.70","0"]],"bids":[["113.43","1.92"],["113.42","4.96"],["113.40","82.13"],["113.39","7.61"],["113.38","9.31"],["113.37","143.33"],["113.36","63.27"],["113.35","1600.36"],["113.33","45.82"],["113.32","104.95"],["113.30","92.16"],["113.24","43.11"],["113.23","83.06"],["113.22","6.26"],["113.20","97.01"],["113.19","515.80"],["113.18","128.63"],["113.16","12.58"],["113.15","153.29"],["113.13","98.20"],["113.12","31.71"],["113.11","2.66"],["113.10","24.49"],["113.09","10.96"],["113.08","74.85"],["113.05","1107.09"],["113.04","58.57"],["113.03","76.08"],["113.00","2009.81"],["112.98","553.51"],["112.94","2219.54"],["112.88","1841.92"],["112.82","1731.63"],["112.76","2018.39"],["112.70","1886.04"],["112.58","1819.86"],["112.52","1709.57"],["112.46","2040.45"],["112.34","1952.22"],["112.22","1974.27"],["112.16","1863.98"],["112.10","1908.10"],["111.66","54.98"],["111.61","0"],["111.07","56.15"],["111.02","0"],["110.47","22.20"],["110.43","0"],["109.88","45.95"],["109.84","0"],["109.29","29.62"],["109.25","0"],["108.70","21.93"],["108.66","0"],["108.11","6.02"],["108.07","0"],["107.52","55.97"],["107.48","0"],["106.93","21.31"],["106.89","0"],["106.34","8.95"],["106.30","0"],["105.75","10.15"],["105.71","0"],["105.16","40.07"],["105.12","0"],["104.57","15.36"],["104.53","0"],["103.98","46.47"],["103.94","0"],["103.39","11.11"],["103.35","0"],["102.80","1.87"],["102.76","0"],["102.21","37.67"],["102.17","0"],["101.62","21.48"],["101.58","0"],["101.03","49.80"],["100.99","0"],["100.44","49.32"],["100.40","0"],["99.85","42.14"],["99.26","8.55"],["98.67","30.36"],["98.08","20.32"],["97.49","36.65"],["96.90","21.95"],["96.31","8.41"],["95.72","31.49"],["95.13","57.35"],["94.54","3.45"],["93.95","4.85"],["93.36","74.35"],["92.77","33.85"],["92.18","20.24"]],"checksum":107416132,"ts":"1649290091442"}]}
1649290091.481596: {"action":"update","arg":{"instType":"mc","channel":"trade","instId":"UNIUSDT"},"data":[["1649290091417","9.984","5","buy"]]}
1649290091.6014059: {"action":"update","arg":{"instType":"mc","channel":"books","instId":"UNIUSDT"},"data":[{"asks":[["9.983","0"],["9.984","0"],["9.985","74"],["9.986","160"],["9.987","1313"],["9.988","885"],["9.989","322"],["9.990","701"],["9.991","455"],["9.992","568"],["9.993","593"],["9.994","2426"],["9.995","607"],["9.996","1717"],["9.997","432"],["9.998","240"],["9.999","1864"],["10.000","794"],["10.001","826"],["10.002","772"],["10.003","801"],["10.005","630"],["10.006","743"],["10.007","1498"],["10.008","969"],["10.009","167"],["10.010","2805"],["10.011","1545"],["10.012","738"],["10.013","786"],["10.015","920"],["10.016","761"],["10.018","385"],["10.019","372"],["10.020","4194"],["10.021","71"],["10.022","687"],["10.023","3904"],["10.024","1833"],["10.025","383"],["10.026","4758"],["10.027","1901"],["10.029","5374"],["10.030","201"],["10.031","26"],["10.033","14945"],["10.034","11"],["10.036","0"],["10.038","12982"],["10.041","0"],["10.043","13366"],["10.046","0"],["10.048","12597"],["10.051","0"],["10.053","11828"],["10.056","0"],["10.058","12020"],["10.061","0"],["10.063","11443"],["10.066","0"],["10.068","13559"],["10.071","0"],["10.073","11636"],["10.076","0"],["10.078","13174"],["10.081","0"],["10.083","12213"],["10.086","0"],["10.088","12405"],["10.122","317"],["10.128","0"],["10.173","191"],["10.179","0"],["10.224","49"],["10.230","0"],["10.276","178"],["10.282","0"],["10.327","225"],["10.333","0"],["10.378","286"],["10.384","0"],["10.429","307"],["10.435","0"],["10.480","131"],["10.486","0"],["10.531","171"],["10.537","0"],["10.582","312"],["10.588","0"],["10.633","282"],["10.639","0"],["10.684","90"],["10.690","0"],["10.735","84"],["10.741","0"],["10.786","279"],["10.792","0"],["10.837","257"],["10.843","0"],["10.888","178"],["10.894","0"],["10.939","257"],["10.945","0"],["10.990","221"],["10.996","0"],["11.041","63"],["11.047","0"],["11.092","16"],["11.098","0"],["11.143","64"],["11.149","0"],["11.194","139"],["11.200","0"],["11.245","234"],["11.251","0"],["11.296","147"],["11.302","0"],["11.347","29"],["11.353","0"],["11.398","328"],["11.404","0"],["11.449","76"],["11.455","0"],["11.500","117"],["11.506","0"]],"bids":[["9.980","500"],["9.979","127"],["9.978","175"],["9.977","94"],["9.976","145"],["9.975","96"],["9.974","321"],["9.973","55"],["9.972","284"],["9.971","126"],["9.970","169"],["9.969","598"],["9.968","199"],["9.967","1094"],["9.966","243"],["9.965","305"],["9.963","833"],["9.962","291"],["9.961","2128"],["9.960","123"],["9.959","325"],["9.958","1260"],["9.956","528"],["9.955","392"],["9.954","1154"],["9.953","748"],["9.952","574"],["9.951","755"],["9.949","855"],["9.948","379"],["9.947","1448"],["9.946","2365"],["9.945","1078"],["9.944","892"],["9.943","836"],["9.942","1045"],["9.941","2089"],["9.937","4073"],["9.933","3209"],["9.932","14252"],["9.930","0"],["9.929","0"],["9.927","12789"],["9.925","0"],["9.922","13366"],["9.920","0"],["9.917","12982"],["9.915","0"],["9.912","12597"],["9.910","0"],["9.907","11443"],["9.905","0"],["9.902","12020"],["9.900","0"],["9.897","12213"],["9.895","0"],["9.892","11828"],["9.890","0"],["9.887","11636"],["9.885","0"],["9.882","13174"],["9.880","0"],["9.877","12405"],["9.875","0"],["9.754","0"],["9.748","34"],["9.704","0"],["9.698","75"],["9.654","0"],["9.648","180"],["9.604","0"],["9.598","248"],["9.554","0"],["9.548","267"],["9.504","0"],["9.498","238"],["9.454","0"],["9.448","153"],["9.404","0"],["9.398","265"],["9.354","0"],["9.348","254"],["9.304","0"],["9.298","80"],["9.254","0"],["9.248","161"],["9.204","0"],["9.198","99"],["9.154","0"],["9.148","100"],["9.104","0"],["9.098","50"],["9.054","0"],["9.048","92"],["9.004","0"],["8.998","333"],["8.954","0"],["8.948","341"],["8.904","0"],["8.898","239"],["8.854","0"],["8.848","43"],["8.804","0"],["8.798","262"],["8.754","0"],["8.748","300"],["8.704","0"],["8.698","27"],["8.654","0"],["8.648","326"],["8.604","0"],["8.598","76"],["8.554","0"],["8.548","188"],["8.504","0"],["8.498","131"],["8.454","0"],["8.448","106"],["8.404","0"],["8.398","90"],["8.354","0"],["8.348","271"]],"checksum":-200613271,"ts":"1649290091574"}]}
1649290091.701663: {"action":"snapshot","arg":{"instType":"mc","channel":"ticker","instId":"UNIUSDT"},"data":[{"instId":"UNIUSDT","last":"9.9840","bestAsk":"9.986","bestBid":"9.98","high24h":"10.4280","low24h":"9.9030","priceChangePercent":"-0.0394","capitalRate":"-0.000100","nextSettleTime":1649314800000,"systemTime":1649290091674,"markPrice":"9.9774","indexPrice":"9.9845","holding":"369411","baseVolume":"313086","quoteVolume":"3294474"}]}
1649290091.7235699: {"action":"snapshot","arg":{"instType":"mc","channel":"ticker","instId":"DASHUSDT"},"data":[{"instId":"DASHUSDT","last":"113.390","bestAsk":"113.5","bestBid":"113.43","high24h":"118.870","low24h":"113.140","priceChangePercent":"-0.036","capitalRate":"-0.000100","nextSettleTime":1649314800000,"systemTime":1649290091691,"markPrice":"113.449","indexPrice":"113.478","holding":"21957.17","baseVolume":"25304.48","quoteVolume":"3062676.68"}]}
1649290091.774973: {"action":"update","arg":{"instType":"mc","channel":"books","instId":"DASHUSDT"},"data":[{"asks":[["113.48","0"],["113.49","0"],["113.50","3.68"],["113.51","10.20"],["113.52","8.43"],["113.53","34.05"],["113.54","8.85"],["113.55","0"],["113.56","20.37"],["113.57","46.19"],["113.58","4.30"],["113.59","2.80"],["113.60","267.61"],["113.61","86.34"],["113.62","56.39"],["113.63","123.09"],["113.64","159.17"],["113.65","336.34"],["113.66","70.68"],["113.67","1008.26"],["113.68","576.11"],["113.69","36.96"],["113.70","88.31"],["113.71","170.07"],["113.72","145.94"],["113.73","48.98"],["113.74","280.18"],["113.76","201.08"],["113.77","689.49"],["113.78","108.60"],["113.79","29.48"],["113.80","162.70"],["113.81","142.82"],["113.82","22.85"],["113.83","44.73"],["113.84","98.77"],["113.86","195.19"],["113.87","77.54"],["113.89","13.91"],["113.90","141.63"],["113.91","3.63"],["113.93","2005.43"],["113.94","123.42"],["113.96","1503.32"],["113.97","263.92"],["113.98","49.51"],["113.99","2183.67"],["114.00","142.81"],["114.03","0"],["114.05","1863.98"],["114.09","0"],["114.11","1841.92"],["114.15","0"],["114.17","1731.63"],["114.21","0"],["114.23","1908.10"],["114.27","0"],["114.29","1709.57"],["114.33","0"],["114.35","1886.04"],["114.39","0"],["114.41","1996.33"],["114.45","0"],["114.47","1753.69"],["114.51","0"],["114.53","1930.16"],["114.57","0"],["114.59","2040.45"],["114.63","0"],["114.65","1952.22"],["114.69","0"],["114.71","2018.39"],["114.75","0"],["114.77","1797.80"],["114.81","0"],["114.83","1775.75"]],"bids":[["113.45","183.16"],["113.43","12.62"],["113.41","24.39"],["113.40","82.51"],["113.39","0"],["113.37","237.61"],["113.36","53.37"],["113.35","1600.30"],["113.33","29.43"],["113.32","106.93"],["113.31","11.97"],["113.29","5.85"],["113.28","21.17"],["113.24","43.51"],["113.20","100.36"],["113.15","149.93"],["113.14","403.55"],["113.11","3.92"],["113.10","20.68"],["113.09","7.99"],["113.08","72.14"],["113.04","65.52"],["113.03","75.19"],["113.02","3373.27"],["113.01","22.28"],["113.00","64.41"],["112.98","548.25"],["112.97","107.25"],["112.96","2219.40"],["112.95","296.55"],["112.94","421.75"],["112.90","1908.10"],["112.88","0"],["112.84","1974.27"],["112.82","0"],["112.78","1819.86"],["112.76","0"],["112.72","1886.04"],["112.70","0"],["112.66","1775.75"],["112.64","0"],["112.60","1952.22"],["112.58","0"],["112.54","1930.16"],["112.52","0"],["112.48","1841.92"],["112.46","0"],["112.42","1996.33"],["112.40","0"],["112.36","2018.39"],["112.34","0"],["112.30","1797.80"],["112.28","0"],["112.24","1709.57"],["112.22","0"],["112.18","1731.63"],["112.16","0"],["112.12","1753.69"],["112.10","0"]],"checksum":-30179778,"ts":"1649290091746"}]}
1649290091.9019089: {"action":"update","arg":{"instType":"mc","channel":"books","instId":"UNIUSDT"},"data":[{"asks":[["9.985","0"],["9.986","55"],["9.987","371"],["9.988","581"],["9.989","438"],["9.990","1500"],["9.991","423"],["9.992","576"],["9.993","482"],["9.994","2493"],["9.995","521"],["9.996","927"],["9.997","907"],["9.998","438"],["9.999","911"],["10.000","587"],["10.001","836"],["10.002","820"],["10.003","642"],["10.004","2250"],["10.005","552"],["10.006","540"],["10.010","330"],["10.012","633"],["10.015","1183"],["10.016","861"],["10.017","3595"],["10.018","37"],["10.020","4289"],["10.021","51"],["10.022","684"],["10.023","3873"],["10.025","1213"],["10.026","4865"],["10.031","268"],["10.033","15302"],["10.034","147"],["10.036","55"],["10.038","12020"],["10.043","13174"],["10.048","12405"],["10.053","13559"],["10.058","12597"],["10.063","11828"],["10.068","11636"],["10.073","11443"],["10.078","12789"],["10.088","12982"],["10.116","317"],["10.122","0"],["10.167","191"],["10.173","0"],["10.218","49"],["10.224","0"],["10.270","178"],["10.276","0"],["10.321","225"],["10.327","0"],["10.372","286"],["10.378","0"],["10.423","307"],["10.429","0"],["10.474","131"],["10.480","0"],["10.525","171"],["10.531","0"],["10.576","312"],["10.582","0"],["10.627","282"],["10.633","0"],["10.678","90"],["10.684","0"],["10.729","84"],["10.735","0"],["10.780","279"],["10.786","0"],["10.831","257"],["10.837","0"],["10.882","178"],["10.888","0"],["10.933","257"],["10.939","0"],["10.984","221"],["10.990","0"],["11.035","63"],["11.041","0"],["11.086","16"],["11.092","0"],["11.137","64"],["11.143","0"],["11.188","139"],["11.194","0"],["11.239","234"],["11.245","0"],["11.290","147"],["11.296","0"],["11.341","29"],["11.347","0"],["11.392","328"],["11.398","0"],["11.443","76"],["11.449","0"],["11.494","117"],["11.500","0"]],"bids":[["9.979","305"],["9.978","203"],["9.977","287"],["9.976","201"],["9.975","319"],["9.974","333"],["9.973","87"],["9.972","234"],["9.970","914"],["9.969","140"],["9.968","490"],["9.967","855"],["9.965","443"],["9.964","977"],["9.963","680"],["9.962","118"],["9.961","2277"],["9.960","168"],["9.959","253"],["9.958","1207"],["9.957","2018"],["9.956","798"],["9.955","341"],["9.954","1034"],["9.952","1384"],["9.951","1041"],["9.950","815"],["9.949","2711"],["9.948","548"],["9.947","334"],["9.944","642"],["9.943","1022"],["9.942","1013"],["9.941","2014"],["9.940","719"],["9.938","576"],["9.937","3685"],["9.936","677"],["9.935","88"],["9.933","18357"],["9.932","694"],["9.928","13174"],["9.927","0"],["9.923","11636"],["9.922","0"],["9.918","13366"],["9.917","0"],["9.913","11828"],["9.912","0"],["9.908","12405"],["9.907","0"],["9.903","12789"],["9.902","0"],["9.898","12213"],["9.897","0"],["9.893","13559"],["9.892","0"],["9.888","12597"],["9.887","0"],["9.883","12982"],["9.882","0"],["9.878","12020"],["9.877","0"],["9.748","0"],["9.742","34"],["9.698","0"],["9.692","75"],["9.648","0"],["9.642","180"],["9.598","0"],["9.592","248"],["9.548","0"],["9.542","267"],["9.498","0"],["9.492","238"],["9.448","15"],["9.442","153"],["9.398","0"],["9.392","265"],["9.348","0"],["9.342","254"],["9.298","0"],["9.292","80"],["9.248","0"],["9.242","161"],["9.198","0"],["9.192","99"],["9.148","0"],["9.142","100"],["9.098","0"],["9.092","50"],["9.048","0"],["9.042","92"],["8.998","0"],["8.992","333"],["8.948","0"],["8.942","341"],["8.898","0"],["8.892","239"],["8.848","0"],["8.842","43"],["8.798","0"],["8.792","262"],["8.748","0"],["8.742","300"],["8.698","0"],["8.692","27"],["8.648","0"],["8.642","326"],["8.598","0"],["8.592","76"],["8.548","0"],["8.542","188"],["8.498","0"],["8.492","131"],["8.448","0"],["8.442","106"],["8.398","0"],["8.392","90"],["8.348","0"],["8.342","271"]],"checksum":509356507,"ts":"1649290091870"}]}
1649290091.97807: {"action":"snapshot","arg":{"instType":"mc","channel":"ticker","instId":"UNIUSDT"},"data":[{"instId":"UNIUSDT","last":"9.9840","bestAsk":"9.986","bestBid":"9.98","high24h":"10.4280","low24h":"9.9030","priceChangePercent":"-0.0394","capitalRate":"-0.000100","nextSettleTime":1649314800000,"systemTime":1649290091945,"markPrice":"9.9774","indexPrice":"9.9845","holding":"369411","baseVolume":"313086","quoteVolume":"3294474"}]}
1649290091.989749: {"action":"snapshot","arg":{"instType":"mc","channel":"ticker","instId":"DASHUSDT"},"data":[{"instId":"DASHUSDT","last":"113.390","bestAsk":"113.51","bestBid":"113.46","high24h":"118.870","low24h":"113.140","priceChangePercent":"-0.036","capitalRate":"-0.000100","nextSettleTime":1649314800000,"systemTime":1649290091957,"markPrice":"113.444","indexPrice":"113.478","holding":"21957.17","baseVolume":"25304.48","quoteVolume":"3062676.68"}]}
1649290092.085057: {"action":"update","arg":{"instType":"mc","channel":"books","instId":"DASHUSDT"},"data":[{"asks":[["113.50","0"],["113.51","0"],["113.52","0"],["113.53","0.35"],["113.54","1.76"],["113.55","7.43"],["113.56","11.04"],["113.57","17.85"],["113.58","0"],["113.59","2.15"],["113.60","11.86"],["113.61","41.11"],["113.62","23.74"],["113.63","17.32"],["113.64","199.19"],["113.65","436.33"],["113.66","70.48"],["113.67","13.99"],["113.68","54.69"],["113.69","27.48"],["113.70","1600.33"],["113.71","82.45"],["113.72","36.11"],["113.73","263.81"],["113.74","87.13"],["113.75","130.24"],["113.76","95.81"],["113.77","674.99"],["113.78","671.23"],["113.79","161.48"],["113.80","184.97"],["113.81","96.21"],["113.82","43.79"],["113.83","49.19"],["113.85","465.83"],["113.86","311.92"],["113.87","70.79"],["113.89","23.14"],["113.90","141.68"],["113.92","104.30"],["113.93","31.17"],["113.95","97.42"],["113.96","3284.61"],["113.99","363.82"],["114.00","152.38"],["114.01","100.84"],["114.02","2041.41"],["114.03","507.74"],["114.05","0"],["114.08","1886.04"],["114.11","0"],["114.14","1841.92"],["114.17","0"],["114.20","2018.39"],["114.23","0"],["114.26","1709.57"],["114.29","0"],["114.32","1996.33"],["114.35","0"],["114.38","1974.27"],["114.41","0"],["114.44","1863.98"],["114.47","0"],["114.50","1753.69"],["114.53","0"],["114.56","1908.10"],["114.59","0"],["114.62","1952.22"],["114.65","0"],["114.68","1731.63"],["114.71","0"],["114.74","1930.16"],["114.77","0"],["114.80","1775.75"],["114.83","0"],["114.86","1819.86"],["115.78","0"],["116.00","31.47"],["116.37","0"],["116.59","50.46"],["116.96","0"],["117.18","49.40"],["117.55","0"],["117.77","27.41"],["118.14","0"],["118.36","50.42"],["118.73","0"],["118.95","50.07"],["119.32","0"],["119.54","36.12"],["119.91","0"],["120.13","8.62"],["120.50","0"],["120.72","54.60"],["121.09","0"],["121.31","1.48"],["121.68","0"],["121.90","43.49"],["122.27","0"],["122.49","7.73"],["122.86","0"],["123.08","58.21"],["123.45","0"],["123.67","52.67"],["124.04","0"],["124.26","53.84"],["124.63","0"],["124.85","4.99"],["125.22","0"],["125.44","44.04"],["125.81","0"],["126.03","25.10"],["126.40","0"],["126.62","39.09"],["126.99","0"],["127.21","44.51"],["127.58","0"],["127.80","19.01"],["128.17","0"],["128.39","29.39"],["128.76","0"],["128.98","3.89"],["129.35","0"],["129.57","23.37"],["129.94","0"],["130.16","24.18"],["130.53","0"],["130.75","9.15"],["131.12","0"],["131.34","27.04"],["131.71","0"],["131.93","7.10"],["132.52","13.38"],["133.11","33.57"],["133.70","76.51"]],"bids":[["113.48","10.37"],["113.47","34.66"],["113.46","36.64"],["113.44","7.59"],["113.43","8.79"],["113.42","7.12"],["113.41","72.74"],["113.40","126.95"],["113.39","1600.06"],["113.38","6.55"],["113.37","122.28"],["113.36","24.66"],["113.35","130.93"],["113.33","48.79"],["113.32","16.74"],["113.31","10.97"],["113.30","90.67"],["113.29","28.49"],["113.28","22.48"],["113.26","5.78"],["113.25","26.80"],["113.24","36.21"],["113.23","18.70"],["113.22","138.76"],["113.20","71.30"],["113.18","104.15"],["113.16","46.55"],["113.15","136.84"],["113.14","607.00"],["113.13","32.61"],["113.12","10.09"],["113.10","26.56"],["113.08","73.07"],["113.06","28.31"],["113.05","2818.26"],["113.04","58.57"],["113.03","92.32"],["113.02","1509.30"],["113.01","38.61"],["113.00","73.17"],["112.99","1851.92"],["112.98","0"],["112.97","0"],["112.96","0"],["112.95","0"],["112.94","0"],["112.93","1996.33"],["112.90","0"],["112.87","1908.10"],["112.84","0"],["112.81","1753.69"],["112.78","0"],["112.75","1952.22"],["112.72","0"],["112.69","1841.92"],["112.66","0"],["112.63","1886.04"],["112.60","0"],["112.57","2040.45"],["112.54","0"],["112.51","1775.75"],["112.48","0"],["112.45","1930.16"],["112.42","0"],["112.39","1797.80"],["112.36","0"],["112.33","1863.98"],["112.30","0"],["112.27","2018.39"],["112.24","0"],["112.21","1974.27"],["112.18","0"],["112.15","1731.63"],["112.12","0"],["111.66","0"],["111.61","44.63"],["111.07","0"],["111.02","97.81"],["110.47","0"],["110.43","40.49"],["109.88","0"],["109.84","85.27"],["109.29","0"],["109.25","84.73"],["108.70","0"],["108.66","59.74"],["108.11","0"],["108.07","61.13"],["107.52","0"],["107.48","33.01"],["106.93","0"],["106.89","56.85"],["106.34","0"],["106.30","24.34"],["105.75","0"],["105.71","1.74"],["105.16","0"],["105.12","57.94"],["104.57","0"],["104.53","58.21"],["103.98","0"],["103.94","46.12"],["103.39","0"],["103.35","52.32"],["102.80","0"],["102.76","45.29"],["102.21","0"],["102.17","22.94"],["101.62","0"],["101.58","36.02"],["101.03","0"],["100.99","38.02"],["100.44","0"],["100.40","53.60"],["99.85","0"],["99.26","0"],["98.67","0"],["98.08","0"],["97.49","0"],["96.90","0"],["96.31","0"],["95.72","0"],["95.13","0"],["94.54","0"],["93.95","0"],["93.36","0"],["92.77","0"],["92.18","0"]],"checksum":-1315180513,"ts":"1649290092051"}]}
1649290092.086124: {"action":"update","arg":{"instType":"mc","channel":"trade","instId":"DASHUSDT"},"data":[["1649290091995","113.5","0.77","sell"]]}
1649290092.2057312: {"action":"update","arg":{"instType":"mc","channel":"books","instId":"UNIUSDT"},"data":[{"asks":[["9.986","0"],["9.987","0"],["9.988","27"],["9.989","93"],["9.990","726"],["9.991","477"],["9.992","267"],["9.993","435"],["9.994","2794"],["9.995","396"],["9.996","905"],["9.997","468"],["9.998","605"],["9.999","746"],["10.000","244"],["10.001","694"],["10.002","568"],["10.003","561"],["10.004","2230"],["10.005","658"],["10.006","542"],["10.007","765"],["10.008","628"],["10.009","363"],["10.011","1649"],["10.012","667"],["10.015","625"],["10.016","760"],["10.017","123"],["10.019","426"],["10.020","4456"],["10.022","714"],["10.023","4191"],["10.024","1283"],["10.025","1087"],["10.026","4590"],["10.027","873"],["10.029","5498"],["10.030","58"],["10.031","560"],["10.033","1937"],["10.035","12894"],["10.036","365"],["10.037","1280"],["10.038","0"],["10.040","12405"],["10.043","0"],["10.045","12213"],["10.048","0"],["10.050","13559"],["10.053","0"],["10.055","12982"],["10.058","0"],["10.060","11636"],["10.063","0"],["10.065","11443"],["10.068","0"],["10.070","13366"],["10.073","0"],["10.075","11828"],["10.078","0"],["10.080","12597"],["10.083","0"],["10.085","12020"],["10.088","0"],["10.090","13174"],["10.110","317"],["10.116","0"],["10.161","191"],["10.167","0"],["10.212","49"],["10.218","0"],["10.264","178"],["10.270","0"],["10.315","225"],["10.321","0"],["10.366","286"],["10.372","0"],["10.417","307"],["10.423","0"],["10.468","131"],["10.474","0"],["10.519","171"],["10.525","0"],["10.570","312"],["10.576","0"],["10.621","282"],["10.627","0"],["10.672","90"],["10.678","0"],["10.723","84"],["10.729","0"],["10.774","279"],["10.780","0"],["10.825","257"],["10.831","0"],["10.876","178"],["10.882","0"],["10.927","257"],["10.933","0"],["10.978","221"],["10.984","0"],["11.029","63"],["11.035","0"],["11.080","16"],["11.086","0"],["11.131","64"],["11.137","0"],["11.182","139"],["11.188","0"],["11.233","234"],["11.239","0"],["11.284","147"],["11.290","0"],["11.335","29"],["11.341","0"],["11.386","328"],["11.392","0"],["11.437","76"],["11.443","0"],["11.488","117"],["11.494","0"]],"bids":[["9.982","187"],["9.981","36"],["9.980","333"],["9.979","269"],["9.977","264"],["9.976","234"],["9.975","253"],["9.974","283"],["9.973","296"],["9.972","261"],["9.971","222"],["9.970","851"],["9.969","106"],["9.967","830"],["9.966","278"],["9.965","331"],["9.964","618"],["9.963","629"],["9.962","179"],["9.961","2087"],["9.960","197"],["9.959","366"],["9.958","1150"],["9.957","2066"],["9.956","879"],["9.955","526"],["9.954","215"],["9.953","1033"],["9.952","1315"],["9.951","743"],["9.949","2728"],["9.948","418"],["9.947","430"],["9.946","2352"],["9.945","1012"],["9.943","1043"],["9.942","228"],["9.940","680"],["9.938","522"],["9.937","3726"],["9.935","12300"],["9.934","3874"],["9.933","6915"],["9.932","0"],["9.931","0"],["9.930","12405"],["9.928","0"],["9.925","12597"],["9.923","0"],["9.920","13174"],["9.918","0"],["9.915","13366"],["9.913","0"],["9.910","12020"],["9.908","0"],["9.905","11828"],["9.903","0"],["9.900","11443"],["9.898","0"],["9.895","12982"],["9.893","0"],["9.890","13559"],["9.888","0"],["9.885","12789"],["9.883","0"],["9.880","11636"],["9.878","0"],["9.742","0"],["9.736","34"],["9.692","0"],["9.686","75"],["9.642","0"],["9.636","180"],["9.592","0"],["9.586","248"],["9.542","0"],["9.536","267"],["9.492","0"],["9.486","238"],["9.442","0"],["9.436","153"],["9.392","0"],["9.386","265"],["9.342","0"],["9.336","254"],["9.292","0"],["9.286","80"],["9.242","0"],["9.236","161"],["9.192","0"],["9.186","99"],["9.142","0"],["9.136","100"],["9.092","0"],["9.086","50"],["9.042","0"],["9.036","92"],["8.992","0"],["8.986","333"],["8.942","0"],["8.936","341"],["8.892","0"],["8.886","239"],["8.842","0"],["8.836","43"],["8.792","0"],["8.786","262"],["8.742","0"],["8.736","300"],["8.692","0"],["8.686","27"],["8.642","0"],["8.636","326"],["8.592","0"],["8.586","76"],["8.542","0"],["8.536","188"],["8.492","0"],["8.486","131"],["8.442","0"],["8.436","106"],["8.392","0"],["8.386","90"],["8.342","0"],["8.336","271"]],"checksum":86895515,"ts":"1649290092177"}]}
1649290092.2384992: {"action":"snapshot","arg":{"instType":"mc","channel":"ticker","instId":"UNIUSDT"},"data":[{"instId":"UNIUSDT","last":"9.9840","bestAsk":"9.988","bestBid":"9.982","high24h":"10.4280","low24h":"9.9030","priceChangePercent":"-0.0394","capitalRate":"-0.000100","nextSettleTime":1649314800000,"systemTime":1649290092207,"markPrice":"9.9774","indexPrice":"9.9845","holding":"369411","baseVolume":"313086","quoteVolume":"3294474"}]}
1649290092.238988: {"action":"snapshot","arg":{"instType":"mc","channel":"ticker","instId":"DASHUSDT"},"data":[{"instId":"DASHUSDT","last":"113.390","bestAsk":"113.53","bestBid":"113.48","high24h":"118.870","low24h":"113.140","priceChangePercent":"-0.036","capitalRate":"-0.000100","nextSettleTime":1649314800000,"systemTime":1649290092213,"markPrice":"113.444","indexPrice":"113.478","holding":"21957.17","baseVolume":"25304.48","quoteVolume":"3062676.68"}]}
1649290092.387315: {"action":"update","arg":{"instType":"mc","channel":"books","instId":"DASHUSDT"},"data":[{"asks":[["113.53","3.17"],["113.54","1.82"],["113.55","1.54"],["113.56","3.46"],["113.57","11.56"],["113.59","3.24"],["113.60","14.29"],["113.61","40.41"],["113.62","16.29"],["113.64","177.62"],["113.65","435.42"],["113.66","72.73"],["113.67","10.59"],["113.68","0"],["113.69","39.31"],["113.70","1600.08"],["113.71","84.20"],["113.72","34.50"],["113.73","177.66"],["113.76","98.29"],["113.77","676.91"],["113.80","198.24"],["113.82","41.35"],["113.86","316.27"],["113.87","37.69"],["113.90","141.25"],["113.91","13.84"],["113.92","94.99"],["113.94","119.50"],["113.95","90.82"],["113.96","3505.20"],["113.97","275.58"],["114.00","154.99"],["114.02","1958.60"],["114.04","20.68"],["114.08","1908.10"],["114.20","1863.98"],["114.26","1731.63"],["114.32","1974.27"],["114.38","1930.16"],["114.44","1797.80"],["114.50","1996.33"],["114.56","1819.86"],["114.62","1775.75"],["114.68","1886.04"],["114.74","1709.57"],["114.80","2040.45"],["114.86","1753.69"]],"bids":[["113.48","16.31"],["113.43","7.94"],["113.42","6.23"],["113.41","71.42"],["113.40","70.29"],["113.39","1600.38"],["113.38","12.53"],["113.36","26.91"],["113.35","251.94"],["113.34","2.43"],["113.33","45.77"],["113.32","13.38"],["113.31","13.71"],["113.30","92.33"],["113.25","26.86"],["113.24","30.61"],["113.23","15.47"],["113.21","7.91"],["113.18","105.49"],["113.07","216.28"],["113.05","3149.80"],["113.04","62.23"],["113.03","96.36"],["113.02","1600.15"],["113.00","64.41"],["112.99","1816.41"],["112.93","1908.10"],["112.87","1709.57"],["112.81","1863.98"],["112.75","1731.63"],["112.69","1819.86"],["112.57","1996.33"],["112.45","1974.27"],["112.39","1952.22"],["112.33","1930.16"],["112.27","1841.92"],["112.21","1753.69"],["112.15","2018.39"]],"checksum":-1323669839,"ts":"1649290092355"}]}
1649290092.497699: {"action":"snapshot","arg":{"instType":"mc","channel":"ticker","instId":"UNIUSDT"},"data":[{"instId":"UNIUSDT","last":"9.9840","bestAsk":"9.988","bestBid":"9.983","high24h":"10.4280","low24h":"9.9030","priceChangePercent":"-0.0394","capitalRate":"-0.000100","nextSettleTime":1649314800000,"systemTime":1649290092467,"markPrice":"9.9774","indexPrice":"9.9886","holding":"369411","baseVolume":"313091","quoteVolume":"3294524"}]}
1649290092.5039518: {"action":"snapshot","arg":{"instType":"mc","channel":"ticker","instId":"DASHUSDT"},"data":[{"instId":"DASHUSDT","last":"113.500","bestAsk":"113.53","bestBid":"113.48","high24h":"118.870","low24h":"113.140","priceChangePercent":"-0.036","capitalRate":"-0.000100","nextSettleTime":1649314800000,"systemTime":1649290092475,"markPrice":"113.444","indexPrice":"113.478","holding":"21957.17","baseVolume":"25304.48","quoteVolume":"3062676.68"}]}
1649290092.5244281: {"action":"update","arg":{"instType":"mc","channel":"candle1m","instId":"UNIUSDT"},"data":[["1649290080000","9.977","9.984","9.976","9.984","18"]]}
1649290092.599961: {"action":"update","arg":{"instType":"mc","channel":"books","instId":"UNIUSDT"},"data":[{"asks":[["9.988","0"],["9.989","0"],["9.990","134"],["9.991","347"],["9.992","317"],["9.993","316"],["9.994","2507"],["9.995","113"],["9.996","264"],["9.997","318"],["9.998","592"],["9.999","1199"],["10.000","247"],["10.001","1318"],["10.002","1072"],["10.003","1036"],["10.004","420"],["10.005","581"],["10.006","840"],["10.007","1060"],["10.008","1392"],["10.009","353"],["10.010","412"],["10.011","2488"],["10.012","597"],["10.014","3822"],["10.015","1084"],["10.016","721"],["10.017","32"],["10.018","67"],["10.019","51"],["10.020","4611"],["10.021","4986"],["10.022","668"],["10.023","4337"],["10.024","2110"],["10.025","1237"],["10.026","4857"],["10.027","1077"],["10.029","5134"],["10.030","107"],["10.031","1010"],["10.032","527"],["10.033","2196"],["10.035","184"],["10.037","13500"],["10.038","40"],["10.039","167"],["10.040","0"],["10.042","13174"],["10.045","0"],["10.047","12213"],["10.050","0"],["10.052","12789"],["10.055","0"],["10.057","12405"],["10.060","0"],["10.062","12982"],["10.065","0"],["10.067","13559"],["10.070","0"],["10.072","12597"],["10.075","0"],["10.077","13366"],["10.080","0"],["10.082","11443"],["10.085","0"],["10.087","12020"],["10.090","0"],["10.092","11636"],["10.102","317"],["10.110","0"],["10.153","191"],["10.161","0"],["10.204","49"],["10.212","0"],["10.256","178"],["10.264","0"],["10.307","225"],["10.315","0"],["10.358","286"],["10.366","0"],["10.409","307"],["10.417","0"],["10.460","131"],["10.468","0"],["10.511","171"],["10.519","0"],["10.562","312"],["10.570","0"],["10.613","282"],["10.621","0"],["10.664","90"],["10.672","0"],["10.715","84"],["10.723","0"],["10.766","279"],["10.774","0"],["10.817","257"],["10.825","0"],["10.868","178"],["10.876","0"],["10.919","257"],["10.927","0"],["10.970","221"],["10.978","0"],["11.021","63"],["11.029","0"],["11.072","16"],["11.080","0"],["11.123","64"],["11.131","0"],["11.174","139"],["11.182","0"],["11.225","234"],["11.233","0"],["11.276","147"],["11.284","0"],["11.327","29"],["11.335","0"],["11.378","328"],["11.386","0"],["11.429","76"],["11.437","0"],["11.480","117"],["11.488","0"]],"bids":[["9.984","338"],["9.983","235"],["9.982","265"],["9.981","198"],["9.980","100"],["9.979","360"],["9.978","189"],["9.977","165"],["9.976","249"],["9.975","1254"],["9.974","214"],["9.973","249"],["9.972","272"],["9.971","202"],["9.970","1280"],["9.969","627"],["9.968","471"],["9.967","233"],["9.966","124"],["9.965","278"],["9.964","650"],["9.963","825"],["9.962","165"],["9.961","2131"],["9.960","206"],["9.959","517"],["9.958","984"],["9.957","2671"],["9.956","2279"],["9.955","445"],["9.954","194"],["9.953","1064"],["9.952","555"],["9.951","831"],["9.950","703"],["9.949","2644"],["9.948","873"],["9.947","475"],["9.945","1396"],["9.944","242"],["9.943","333"],["9.942","156"],["9.941","1985"],["9.940","3848"],["9.939","990"],["9.938","692"],["9.937","16059"],["9.936","422"],["9.935","8"],["9.934","0"],["9.933","0"],["9.932","11636"],["9.930","0"],["9.927","12597"],["9.925","0"],["9.922","12405"],["9.920","0"],["9.917","11443"],["9.915","0"],["9.912","13366"],["9.910","0"],["9.907","12020"],["9.905","0"],["9.902","11828"],["9.900","0"],["9.897","12982"],["9.895","0"],["9.892","13559"],["9.890","0"],["9.887","13174"],["9.885","0"],["9.882","12789"],["9.880","0"],["9.827","351"],["9.776","399"],["9.736","0"],["9.725","274"],["9.686","0"],["9.673","23"],["9.636","0"],["9.622","112"],["9.586","0"],["9.571","47"],["9.536","0"],["9.520","290"],["9.486","0"],["9.469","318"],["9.436","0"],["9.418","326"],["9.386","0"],["9.367","106"],["9.336","0"],["9.316","193"],["9.286","0"],["9.265","376"],["9.236","0"],["9.214","231"],["9.186","0"],["9.163","4"],["9.136","0"],["9.112","149"],["9.086","0"],["9.061","85"],["9.036","0"],["9.010","320"],["8.986","0"],["8.959","61"],["8.936","0"],["8.908","131"],["8.886","0"],["8.857","477"],["8.836","0"],["8.806","367"],["8.786","0"],["8.755","253"],["8.736","0"],["8.704","83"],["8.686","0"],["8.653","48"],["8.636","0"],["8.586","0"],["8.536","0"],["8.486","0"],["8.436","0"],["8.386","0"],["8.336","0"]],"checksum":-942064712,"ts":"1649290092573"}]}
1649290092.692183: {"action":"update","arg":{"instType":"mc","channel":"books","instId":"DASHUSDT"},"data":[{"asks":[["113.54","3.07"],["113.55","7.73"],["113.56","12.18"],["113.58","5.56"],["113.60","15.71"],["113.61","42.00"],["113.62","17.98"],["113.63","25.33"],["113.65","328.51"],["113.67","14.89"],["113.70","1600.38"],["113.72","33.59"],["113.73","180.80"],["113.76","97.89"],["113.77","675.53"],["113.78","669.34"],["113.79","163.39"],["113.80","200.60"],["113.83","48.47"],["113.85","465.50"],["113.87","40.69"],["113.88","138.43"],["113.91","15.26"],["113.92","91.59"],["113.96","3284.61"],["113.97","278.54"],["113.98","25.09"],["114.02","1929.91"],["114.03","507.28"],["114.04","0"],["114.08","1863.98"],["114.14","1930.16"],["114.20","1974.27"],["114.26","2018.39"],["114.32","1952.22"],["114.38","1775.75"],["114.44","1753.69"],["114.50","1841.92"],["114.56","1996.33"],["114.62","1709.57"],["114.68","1731.63"],["114.74","2040.45"],["114.80","1886.04"],["114.86","1819.86"],["115.78","0.73"],["116.00","0"],["116.37","68.26"],["116.59","0"],["116.96","70.90"],["117.18","0"],["117.55","49.89"],["117.77","0"],["118.14","22.59"],["118.36","0"],["118.73","47.85"],["118.95","0"],["119.32","46.71"],["119.54","0"],["119.91","23.57"],["120.13","0"],["120.50","59.15"],["120.72","0"],["121.09","6.51"],["121.31","0"],["121.68","54.25"],["121.90","0"],["122.27","14.99"],["122.49","0"],["122.86","11.21"],["123.08","0"],["123.45","66.50"],["123.67","0"],["124.04","64.47"],["124.26","0"],["124.63","42.85"],["124.85","0"],["125.22","29.99"],["125.44","0"],["125.81","4.07"],["126.03","0"],["126.40","26.70"],["126.62","0"],["126.99","20.67"],["127.21","0"],["127.58","56.99"],["127.80","0"],["128.17","44.01"],["128.39","0"],["128.76","46.60"],["128.98","0"],["129.35","39.07"],["129.57","0"],["129.94","19.33"],["130.16","0"],["130.53","20.66"],["130.75","0"],["131.12","28.11"],["131.34","0"],["131.71","13.65"],["131.93","0"],["132.52","0"],["133.11","0"],["133.70","0"]],"bids":[["113.48","10.87"],["113.45","95.95"],["113.44","0"],["113.43","9.75"],["113.42","5.68"],["113.41","75.40"],["113.38","13.83"],["113.37","127.17"],["113.35","129.18"],["113.34","3.16"],["113.33","54.86"],["113.30","27.69"],["113.24","30.21"],["113.23","13.22"],["113.22","93.37"],["113.21","5.18"],["113.20","74.00"],["113.18","130.74"],["113.16","46.05"],["113.14","605.67"],["113.13","24.31"],["113.09","4.79"],["113.08","73.21"],["113.05","2951.27"],["113.04","63.24"],["113.03","96.27"],["113.02","1600.35"],["112.99","1970.83"],["112.98","525.76"],["112.93","1974.27"],["112.87","1775.75"],["112.75","1797.80"],["112.69","1908.10"],["112.63","1753.69"],["112.57","2018.39"],["112.51","1996.33"],["112.45","1709.57"],["112.39","1819.86"],["112.33","1731.63"],["112.27","1886.04"],["112.21","1930.16"],["112.15","2040.45"],["111.66","54.98"],["111.61","0"],["111.07","56.15"],["111.02","0"],["110.47","22.20"],["110.43","0"],["109.88","45.95"],["109.84","0"],["109.29","29.62"],["109.25","0"],["108.70","21.93"],["108.66","0"],["108.11","6.02"],["108.07","0"],["107.52","55.97"],["107.48","0"],["106.93","21.31"],["106.89","0"],["106.34","8.95"],["106.30","0"],["105.75","10.15"],["105.71","0"],["105.16","40.07"],["105.12","0"],["104.57","15.36"],["104.53","0"],["103.98","46.47"],["103.94","0"],["103.39","11.11"],["103.35","0"],["102.80","1.87"],["102.76","0"],["102.21","37.67"],["102.17","0"],["101.62","21.48"],["101.58","0"],["101.03","49.80"],["100.99","0"],["100.44","49.32"],["100.40","0"],["99.85","42.14"],["99.26","8.55"],["98.67","30.36"],["98.08","20.32"],["97.49","36.65"],["96.90","21.95"],["96.31","8.41"],["95.72","31.49"],["95.13","57.35"],["94.54","3.45"],["93.95","4.85"],["93.36","74.35"],["92.77","33.85"],["92.18","20.24"]],"checksum":-93450187,"ts":"1649290092664"}]}
1649290092.758822: {"action":"snapshot","arg":{"instType":"mc","channel":"ticker","instId":"DASHUSDT"},"data":[{"instId":"DASHUSDT","last":"113.500","bestAsk":"113.53","bestBid":"113.48","high24h":"118.870","low24h":"113.140","priceChangePercent":"-0.036","capitalRate":"-0.000100","nextSettleTime":1649314800000,"systemTime":1649290092731,"markPrice":"113.444","indexPrice":"113.478","holding":"21957.17","baseVolume":"25304.48","quoteVolume":"3062676.68"}]}
1649290092.764643: {"action":"snapshot","arg":{"instType":"mc","channel":"ticker","instId":"UNIUSDT"},"data":[{"instId":"UNIUSDT","last":"9.9840","bestAsk":"9.99","bestBid":"9.984","high24h":"10.4280","low24h":"9.9030","priceChangePercent":"-0.0394","capitalRate":"-0.000100","nextSettleTime":1649314800000,"systemTime":1649290092729,"markPrice":"9.9771","indexPrice":"9.9886","holding":"369411","baseVolume":"313091","quoteVolume":"3294524"}]}
1649290092.9511628: {"action":"update","arg":{"instType":"mc","channel":"books","instId":"UNIUSDT"},"data":[{"asks":[["9.990","57"],["9.991","422"],["9.992","289"],["9.993","229"],["9.994","2181"],["9.995","263"],["9.996","719"],["9.997","1222"],["9.998","616"],["9.999","1067"],["10.000","372"],["10.001","1189"],["10.002","1308"],["10.003","818"],["10.004","489"],["10.005","578"],["10.006","680"],["10.007","1085"],["10.008","1433"],["10.009","688"],["10.010","369"],["10.011","2524"],["10.012","641"],["10.013","813"],["10.014","3811"],["10.015","822"],["10.017","47"],["10.020","4515"],["10.022","618"],["10.023","4024"],["10.025","1219"],["10.028","332"],["10.029","8642"],["10.031","300"],["10.032","623"],["10.033","6580"],["10.034","439"],["10.035","155"],["10.037","13885"],["10.042","12789"],["10.047","12020"],["10.052","11443"],["10.057","12597"],["10.062","12405"],["10.067","11636"],["10.072","13366"],["10.077","13559"],["10.082","11828"],["10.087","13174"],["10.092","12982"],["10.095","317"],["10.102","0"],["10.146","191"],["10.153","0"],["10.197","49"],["10.204","0"],["10.249","178"],["10.256","0"],["10.300","225"],["10.307","0"],["10.351","286"],["10.358","0"],["10.402","307"],["10.409","0"],["10.453","131"],["10.460","0"],["10.504","171"],["10.511","0"],["10.555","312"],["10.562","0"],["10.606","282"],["10.613","0"],["10.657","90"],["10.664","0"],["10.708","84"],["10.715","0"],["10.759","279"],["10.766","0"],["10.810","257"],["10.817","0"],["10.861","178"],["10.868","0"],["10.912","257"],["10.919","0"],["10.963","221"],["10.970","0"],["11.014","63"],["11.021","0"],["11.065","16"],["11.072","0"],["11.116","64"],["11.123","0"],["11.167","139"],["11.174","0"],["11.218","234"],["11.225","0"],["11.269","147"],["11.276","0"],["11.320","29"],["11.327","0"],["11.371","328"],["11.378","0"],["11.422","76"],["11.429","0"],["11.473","117"],["11.480","0"]],"bids":[["9.983","247"],["9.982","187"],["9.981","174"],["9.980","98"],["9.979","269"],["9.978","238"],["9.977","116"],["9.976","191"],["9.975","1188"],["9.973","348"],["9.972","423"],["9.971","126"],["9.969","810"],["9.968","504"],["9.967","332"],["9.966","216"],["9.964","753"],["9.963","603"],["9.962","307"],["9.961","2054"],["9.960","413"],["9.958","813"],["9.957","2656"],["9.956","2285"],["9.954","140"],["9.952","703"],["9.951","943"],["9.949","2658"],["9.948","678"],["9.946","2374"],["9.942","210"],["9.941","1969"],["9.940","4046"],["9.938","4099"],["9.937","15482"],["9.935","88"],["9.932","13366"],["9.927","12982"],["9.922","12789"],["9.917","12405"],["9.912","11828"],["9.907","13559"],["9.902","13174"],["9.897","12213"],["9.892","12597"],["9.887","12020"],["9.882","11443"],["9.827","0"],["9.820","351"],["9.776","0"],["9.769","399"],["9.725","0"],["9.718","274"],["9.673","0"],["9.666","23"],["9.622","0"],["9.615","112"],["9.571","0"],["9.564","47"],["9.520","0"],["9.513","290"],["9.469","0"],["9.462","318"],["9.418","0"],["9.411","326"],["9.367","0"],["9.360","106"],["9.316","0"],["9.309","193"],["9.265","0"],["9.258","376"],["9.214","0"],["9.207","231"],["9.163","0"],["9.156","4"],["9.112","0"],["9.105","149"],["9.061","0"],["9.054","85"],["9.010","0"],["9.003","320"],["8.959","0"],["8.952","61"],["8.908","0"],["8.901","131"],["8.857","0"],["8.850","477"],["8.806","0"],["8.799","367"],["8.755","0"],["8.748","253"],["8.704","0"],["8.697","83"],["8.653","0"],["8.646","48"]],"checksum":-409994798,"ts":"1649290092919"}]}
1649290092.9947488: {"action":"update","arg":{"instType":"mc","channel":"books","instId":"DASHUSDT"},"data":[{"asks":[["113.53","0"],["113.55","6.42"],["113.56","12.95"],["113.57","10.90"],["113.59","1.10"],["113.62","10.11"],["113.63","20.38"],["113.64","58.32"],["113.65","121.93"],["113.66","81.30"],["113.68","9.91"],["113.70","91.16"],["113.71","114.89"],["113.72","829.84"],["113.73","179.48"],["113.74","146.53"],["113.75","28.27"],["113.76","10.77"],["113.80","59.86"],["113.81","111.06"],["113.83","41.54"],["113.84","58.18"],["113.85","590.73"],["113.86","418.24"],["113.88","260.38"],["113.89","144.91"],["113.90","139.60"],["113.92","91.91"],["113.93","20.54"],["113.94","121.98"],["113.96","11.73"],["113.97","2010.16"],["113.99","367.09"],["114.02","21.82"],["114.03","2259.26"],["114.08","0"],["114.09","1797.80"],["114.14","0"],["114.15","1996.33"],["114.20","0"],["114.21","1886.04"],["114.26","0"],["114.27","1974.27"],["114.32","0"],["114.33","1819.86"],["114.38","0"],["114.39","1952.22"],["114.44","0"],["114.45","1753.69"],["114.50","0"],["114.51","1709.57"],["114.56","0"],["114.57","1863.98"],["114.62","0"],["114.63","1908.10"],["114.68","0"],["114.69","1841.92"],["114.74","0"],["114.75","1930.16"],["114.80","0"],["114.81","2018.39"],["114.86","0"],["114.87","2040.45"]],"bids":[["113.49","4.96"],["113.48","16.81"],["113.47","99.01"],["113.45","15.08"],["113.44","3.22"],["113.43","4.87"],["113.42","37.48"],["113.41","48.18"],["113.40","30.71"],["113.39","1600.34"],["113.38","8.82"],["113.37","124.69"],["113.35","247.51"],["113.33","58.30"],["113.32","16.99"],["113.27","13.18"],["113.26","9.12"],["113.25","95.17"],["113.24","16.35"],["113.23","20.15"],["113.22","95.08"],["113.20","63.85"],["113.19","538.57"],["113.18","136.43"],["113.17","16.84"],["113.16","40.77"],["113.15","111.10"],["113.14","596.08"],["113.13","28.62"],["113.12","15.19"],["113.08","81.08"],["113.06","2002.12"],["113.05","1109.36"],["113.04","63.74"],["113.03","94.52"],["113.02","35.65"],["113.00","1994.56"],["112.99","0"],["112.98","0"],["112.94","1908.10"],["112.93","0"],["112.88","1886.04"],["112.87","0"],["112.82","1797.80"],["112.81","0"],["112.76","1753.69"],["112.75","0"],["112.70","1709.57"],["112.69","0"],["112.64","1863.98"],["112.63","0"],["112.58","1775.75"],["112.57","0"],["112.52","1731.63"],["112.51","0"],["112.46","1952.22"],["112.45","0"],["112.40","1819.86"],["112.39","0"],["112.34","1996.33"],["112.33","0"],["112.28","2018.39"],["112.27","0"],["112.22","2040.45"],["112.21","0"],["112.16","1841.92"],["112.15","0"]],"checksum":1437851535,"ts":"1649290092966"}]}
1649290093.0118458: {"action":"snapshot","arg":{"instType":"mc","channel":"ticker","instId":"UNIUSDT"},"data":[{"instId":"UNIUSDT","last":"9.9840","bestAsk":"9.988","bestBid":"9.983","high24h":"10.4280","low24h":"9.9030","priceChangePercent":"-0.0387","capitalRate":"-0.000100","nextSettleTime":1649314800000,"systemTime":1649290092983,"markPrice":"9.9771","indexPrice":"9.9886","holding":"369411","baseVolume":"313091","quoteVolume":"3294524"}]}
1649290093.022047: {"action":"snapshot","arg":{"instType":"mc","channel":"ticker","instId":"DASHUSDT"},"data":[{"instId":"DASHUSDT","last":"113.500","bestAsk":"113.54","bestBid":"113.49","high24h":"118.870","low24h":"113.140","priceChangePercent":"-0.036","capitalRate":"-0.000100","nextSettleTime":1649314800000,"systemTime":1649290092995,"markPrice":"113.439","indexPrice":"113.478","holding":"21957.17","baseVolume":"25304.48","quoteVolume":"3062676.68"}]}
1649290093.1004748: {"action":"update","arg":{"instType":"mc","channel":"trade","instId":"UNIUSDT"},"data":[["1649290092998","9.986","2","buy"]]}
1649290093.135395: {"action":"update","arg":{"instType":"mc","channel":"candle1m","instId":"DASHUSDT"},"data":[["1649290080000","113.37","113.5","113.37","113.5","3.36"]]}
1649290093.2584052: {"action":"update","arg":{"instType":"mc","channel":"books","instId":"UNIUSDT"},"data":[{"asks":[["9.990","0"],["9.991","0"],["9.992","114"],["9.993","149"],["9.994","2129"],["9.995","35"],["9.996","824"],["9.997","992"],["9.998","703"],["9.999","546"],["10.000","335"],["10.001","849"],["10.002","1587"],["10.003","1150"],["10.004","357"],["10.005","528"],["10.006","650"],["10.007","1140"],["10.009","712"],["10.010","430"],["10.011","2659"],["10.013","800"],["10.014","3910"],["10.015","780"],["10.016","819"],["10.020","4431"],["10.022","260"],["10.023","4859"],["10.024","1468"],["10.025","1113"],["10.026","5647"],["10.029","8414"],["10.031","434"],["10.033","6975"],["10.035","228"],["10.037","1673"],["10.039","12734"],["10.040","622"],["10.042","80"],["10.044","12213"],["10.047","0"],["10.049","12597"],["10.052","0"],["10.054","13174"],["10.057","0"],["10.059","12405"],["10.062","113"],["10.064","11636"],["10.067","0"],["10.069","12982"],["10.072","0"],["10.074","11443"],["10.077","0"],["10.079","13559"],["10.082","0"],["10.084","11828"],["10.087","0"],["10.089","13366"],["10.092","0"],["10.094","12789"],["10.095","0"],["10.141","53"],["10.146","0"],["10.192","26"],["10.197","0"],["10.243","141"],["10.249","0"],["10.294","190"],["10.300","0"],["10.345","404"],["10.351","0"],["10.396","197"],["10.402","0"],["10.447","156"],["10.453","0"],["10.498","21"],["10.504","0"],["10.549","328"],["10.555","0"],["10.601","36"],["10.606","0"],["10.652","224"],["10.657","0"],["10.703","266"],["10.708","0"],["10.754","156"],["10.759","0"],["10.805","477"],["10.810","0"],["10.856","146"],["10.861","0"],["10.907","307"],["10.912","0"],["10.958","357"],["10.963","0"],["11.009","279"],["11.014","0"],["11.060","370"],["11.065","0"],["11.111","212"],["11.116","0"],["11.162","331"],["11.167","0"],["11.213","151"],["11.218","0"],["11.264","89"],["11.269","0"],["11.315","107"],["11.320","0"],["11.371","0"],["11.422","0"],["11.473","0"]],"bids":[["9.986","199"],["9.985","165"],["9.984","330"],["9.983","209"],["9.982","246"],["9.981","316"],["9.980","267"],["9.979","144"],["9.978","393"],["9.977","125"],["9.976","683"],["9.975","1174"],["9.974","160"],["9.973","320"],["9.972","517"],["9.971","257"],["9.970","1068"],["9.969","653"],["9.968","572"],["9.967","355"],["9.966","103"],["9.965","245"],["9.963","589"],["9.961","2119"],["9.960","465"],["9.958","830"],["9.957","4496"],["9.956","4689"],["9.955","564"],["9.954","122"],["9.949","794"],["9.948","786"],["9.943","203"],["9.942","148"],["9.939","12634"],["9.937","3847"],["9.936","0"],["9.935","0"],["9.934","13366"],["9.932","0"],["9.929","12597"],["9.927","0"],["9.924","13559"],["9.922","0"],["9.919","11828"],["9.917","0"],["9.914","12982"],["9.912","0"],["9.909","12213"],["9.907","0"],["9.904","13174"],["9.902","0"],["9.899","11443"],["9.897","0"],["9.894","12405"],["9.892","0"],["9.889","12020"],["9.887","0"],["9.884","12789"],["9.882","0"],["9.820","0"],["9.815","351"],["9.769","0"],["9.764","399"],["9.718","0"],["9.713","274"],["9.666","0"],["9.661","23"],["9.615","0"],["9.610","112"],["9.564","0"],["9.559","47"],["9.513","0"],["9.508","290"],["9.462","0"],["9.457","318"],["9.411","0"],["9.406","326"],["9.360","0"],["9.355","106"],["9.309","0"],["9.304","193"],["9.258","0"],["9.253","376"],["9.207","0"],["9.202","231"],["9.156","0"],["9.151","4"],["9.105","0"],["9.100","149"],["9.054","0"],["9.049","85"],["9.003","0"],["8.998","320"],["8.952","0"],["8.947","61"],["8.901","0"],["8.896","131"],["8.850","0"],["8.845","477"],["8.799","0"],["8.794","367"],["8.748","0"],["8.743","253"],["8.697","0"],["8.692","83"],["8.646","0"],["8.641","48"]],"checksum":1282156646,"ts":"1649290093224"}]}
1649290093.28897: {"action":"snapshot","arg":{"instType":"mc","channel":"ticker","instId":"UNIUSDT"},"data":[{"instId":"UNIUSDT","last":"9.9860","bestAsk":"9.992","bestBid":"9.986","high24h":"10.4280","low24h":"9.9030","priceChangePercent":"-0.0387","capitalRate":"-0.000100","nextSettleTime":1649314800000,"systemTime":1649290093249,"markPrice":"9.9793","indexPrice":"9.9941","holding":"369411","baseVolume":"313091","quoteVolume":"3294524"}]}
1649290093.289064: {"action":"snapshot","arg":{"instType":"mc","channel":"ticker","instId":"DASHUSDT"},"data":[{"instId":"DASHUSDT","last":"113.500","bestAsk":"113.54","bestBid":"113.48","high24h":"118.870","low24h":"113.140","priceChangePercent":"-0.035","capitalRate":"-0.000100","nextSettleTime":1649314800000,"systemTime":1649290093257,"markPrice":"113.439","indexPrice":"113.478","holding":"21957.17","baseVolume":"25305.25","quoteVolume":"3062764.07"}]}
1649290093.297591: {"action":"update","arg":{"instType":"mc","channel":"books","instId":"DASHUSDT"},"data":[{"asks":[["113.54","3.00"],["113.55","8.19"],["113.57","14.76"],["113.58","11.31"],["113.59","0"],["113.63","23.35"],["113.65","113.70"],["113.66","73.46"],["113.67","14.46"],["113.68","155.44"],["113.71","160.08"],["113.74","494.02"],["113.77","678.70"],["113.78","656.97"],["113.79","157.12"],["113.80","49.47"],["113.81","67.85"],["113.82","46.05"],["113.83","51.43"],["113.84","69.07"],["113.85","340.26"],["113.86","296.97"],["113.87","175.98"],["113.89","124.45"],["113.90","144.49"],["113.92","116.28"],["113.93","34.40"],["113.94","278.48"],["113.97","2076.56"],["113.98","14.69"],["114.03","2457.78"],["114.04","20.68"],["114.09","1863.98"],["114.15","1908.10"],["114.21","1731.63"],["114.27","1996.33"],["114.33","2040.45"],["114.39","1709.57"],["114.45","1775.75"],["114.51","1753.69"],["114.57","1886.04"],["114.63","1930.16"],["114.69","2018.39"],["114.75","1841.92"],["114.81","1952.22"],["114.87","1819.86"]],"bids":[["113.49","0"],["113.48","19.28"],["113.45","16.56"],["113.44","0"],["113.43","60.24"],["113.42","1600.10"],["113.40","32.83"],["113.39","63.28"],["113.38","21.96"],["113.35","313.73"],["113.33","22.77"],["113.28","21.38"],["113.22","95.87"],["113.21","8.00"],["113.20","72.57"],["113.19","271.03"],["113.18","62.93"],["113.17","21.30"],["113.16","38.58"],["113.13","37.32"],["113.12","7.93"],["113.06","27.86"],["113.05","3017.45"],["113.02","59.90"],["113.00","64.41"],["112.99","1728.18"],["112.98","525.76"],["112.94","0"],["112.93","1886.04"],["112.88","0"],["112.87","1753.69"],["112.82","0"],["112.81","1819.86"],["112.76","0"],["112.75","1775.75"],["112.70","0"],["112.69","1863.98"],["112.64","0"],["112.63","1797.80"],["112.58","0"],["112.57","2040.45"],["112.52","0"],["112.51","1952.22"],["112.46","0"],["112.45","1996.33"],["112.40","0"],["112.39","2018.39"],["112.34","0"],["112.33","1974.27"],["112.28","0"],["112.27","1841.92"],["112.22","0"],["112.21","1731.63"],["112.16","0"],["112.15","1930.16"]],"checksum":-1907446518,"ts":"1649290093270"}]}
1649290093.544671: {"action":"update","arg":{"instType":"mc","channel":"candle1m","instId":"UNIUSDT"},"data":[["1649290080000","9.977","9.986","9.976","9.986","20"]]}
1649290093.556797: {"action":"update","arg":{"instType":"mc","channel":"books","instId":"UNIUSDT"},"data":[{"asks":[["9.990","47"],["9.993","285"],["9.994","2611"],["9.996","717"],["9.997","241"],["9.998","701"],["9.999","444"],["10.000","347"],["10.001","894"],["10.002","1664"],["10.003","1094"],["10.004","319"],["10.005","572"],["10.006","722"],["10.007","1113"],["10.008","1600"],["10.009","813"],["10.010","419"],["10.011","2556"],["10.012","660"],["10.018","186"],["10.019","132"],["10.022","635"],["10.023","4943"],["10.024","2114"],["10.026","6434"],["10.028","347"],["10.030","123"],["10.031","902"],["10.038","11680"],["10.039","715"],["10.042","0"],["10.043","13174"],["10.044","0"],["10.048","11828"],["10.049","0"],["10.053","12597"],["10.054","0"],["10.058","11636"],["10.059","0"],["10.063","12405"],["10.064","0"],["10.068","12020"],["10.069","0"],["10.073","13366"],["10.074","0"],["10.078","12789"],["10.079","0"],["10.083","12982"],["10.084","0"],["10.088","13559"],["10.089","0"],["10.093","12213"],["10.094","0"],["10.135","53"],["10.141","0"],["10.186","26"],["10.192","0"],["10.237","141"],["10.243","0"],["10.288","190"],["10.294","0"],["10.339","404"],["10.345","0"],["10.390","197"],["10.396","0"],["10.441","156"],["10.447","0"],["10.492","21"],["10.498","0"],["10.543","328"],["10.549","0"],["10.595","36"],["10.601","0"],["10.646","224"],["10.652","0"],["10.697","266"],["10.703","0"],["10.748","156"],["10.754","0"],["10.799","477"],["10.805","0"],["10.850","146"],["10.856","0"],["10.901","307"],["10.907","0"],["10.952","357"],["10.958","0"],["11.003","279"],["11.009","0"],["11.054","370"],["11.060","0"],["11.105","212"],["11.111","0"],["11.156","331"],["11.162","0"],["11.207","151"],["11.213","0"],["11.258","89"],["11.264","0"],["11.309","107"],["11.315","0"]],"bids":[["9.986","0"],["9.984","354"],["9.982","268"],["9.981","105"],["9.980","414"],["9.979","104"],["9.978","367"],["9.977","129"],["9.976","880"],["9.975","1157"],["9.974","292"],["9.973","258"],["9.972","348"],["9.971","380"],["9.968","605"],["9.967","379"],["9.966","116"],["9.964","830"],["9.962","405"],["9.961","2031"],["9.959","501"],["9.958","814"],["9.957","2687"],["9.956","4755"],["9.953","1000"],["9.952","734"],["9.949","693"],["9.948","1177"],["9.947","481"],["9.946","2501"],["9.945","1609"],["9.939","999"],["9.937","16059"],["9.936","719"],["9.934","0"],["9.932","12982"],["9.929","0"],["9.927","13366"],["9.924","0"],["9.922","11636"],["9.919","0"],["9.917","13559"],["9.914","0"],["9.912","12789"],["9.909","0"],["9.907","12020"],["9.904","0"],["9.902","11828"],["9.899","0"],["9.897","11443"],["9.894","0"],["9.892","13174"],["9.889","0"],["9.887","12405"],["9.884","0"],["9.882","12597"],["9.815","0"],["9.809","351"],["9.764","0"],["9.758","399"],["9.713","0"],["9.707","274"],["9.661","0"],["9.655","23"],["9.610","0"],["9.604","112"],["9.559","0"],["9.553","47"],["9.508","0"],["9.502","290"],["9.457","0"],["9.451","318"],["9.406","0"],["9.400","326"],["9.355","0"],["9.349","106"],["9.304","0"],["9.298","193"],["9.253","0"],["9.247","376"],["9.202","0"],["9.196","231"],["9.151","0"],["9.145","4"],["9.100","0"],["9.094","149"],["9.049","0"],["9.043","85"],["8.998","0"],["8.992","320"],["8.947","0"],["8.941","61"],["8.896","0"],["8.890","131"],["8.845","0"],["8.839","477"],["8.794","0"],["8.788","367"],["8.743","0"],["8.737","253"],["8.692","0"],["8.686","83"],["8.641","0"],["8.635","48"]],"checksum":2034113404,"ts":"1649290093524"}]}
1649290093.5786822: {"action":"snapshot","arg":{"instType":"mc","channel":"ticker","instId":"UNIUSDT"},"data":[{"instId":"UNIUSDT","last":"9.9860","bestAsk":"9.99","bestBid":"9.985","high24h":"10.4280","low24h":"9.9030","priceChangePercent":"-0.0385","capitalRate":"-0.000100","nextSettleTime":1649314800000,"systemTime":1649290093544,"markPrice":"9.9793","indexPrice":"9.9941","holding":"369411","baseVolume":"313093","quoteVolume":"3294544"}]}
1649290093.59429: {"action":"snapshot","arg":{"instType":"mc","channel":"ticker","instId":"DASHUSDT"},"data":[{"instId":"DASHUSDT","last":"113.500","bestAsk":"113.56","bestBid":"113.48","high24h":"118.870","low24h":"113.140","priceChangePercent":"-0.035","capitalRate":"-0.000100","nextSettleTime":1649314800000,"systemTime":1649290093560,"markPrice":"113.439","indexPrice":"113.478","holding":"21957.17","baseVolume":"25305.25","quoteVolume":"3062764.07"}]}
1649290093.609635: {"action":"update","arg":{"instType":"mc","channel":"books","instId":"DASHUSDT"},"data":[{"asks":[["113.54","0"],["113.55","0"],["113.56","2.81"],["113.57","17.63"],["113.58","0.27"],["113.59","5.57"],["113.60","6.99"],["113.61","44.29"],["113.62","12.60"],["113.63","20.88"],["113.64","38.13"],["113.65","116.21"],["113.67","20.71"],["113.68","76.63"],["113.69","39.27"],["113.70","87.69"],["113.71","165.02"],["113.72","828.58"],["113.74","440.56"],["113.77","680.53"],["113.80","80.65"],["113.82","23.78"],["113.83","29.65"],["113.84","226.98"],["113.85","346.10"],["113.86","293.30"],["113.87","146.29"],["113.91","29.42"],["113.97","274.07"],["113.98","1966.90"],["114.03","483.52"],["114.04","1886.91"],["114.05","98.52"],["114.09","0"],["114.10","1819.86"],["114.15","0"],["114.16","1930.16"],["114.21","0"],["114.22","1908.10"],["114.27","0"],["114.28","1731.63"],["114.33","0"],["114.34","1841.92"],["114.39","0"],["114.40","1775.75"],["114.45","0"],["114.46","1753.69"],["114.51","0"],["114.52","1974.27"],["114.57","0"],["114.58","2040.45"],["114.63","0"],["114.64","1996.33"],["114.69","0"],["114.70","1863.98"],["114.75","0"],["114.76","1797.80"],["114.81","0"],["114.82","2018.39"],["114.87","0"],["114.88","1709.57"]],"bids":[["113.49","4.96"],["113.48","16.81"],["113.47","51.50"],["113.46","24.64"],["113.45","15.68"],["113.44","2.78"],["113.43","64.68"],["113.40","79.22"],["113.39","54.55"],["113.38","7.38"],["113.37","121.82"],["113.33","29.36"],["113.32","30.06"],["113.31","10.97"],["113.29","29.98"],["113.28","19.78"],["113.27","12.88"],["113.24","185.64"],["113.23","24.61"],["113.22","103.46"],["113.21","22.85"],["113.20","45.70"],["113.19","259.65"],["113.16","170.58"],["113.14","409.63"],["113.13","33.53"],["113.11","2.15"],["113.10","27.25"],["113.07","1922.57"],["113.05","1109.36"],["113.01","2056.00"],["112.99","0"],["112.98","0"],["112.95","1930.16"],["112.93","0"],["112.89","1775.75"],["112.87","0"],["112.83","2040.45"],["112.81","0"],["112.77","1863.98"],["112.75","0"],["112.71","1753.69"],["112.69","0"],["112.65","1709.57"],["112.63","0"],["112.59","1731.63"],["112.57","0"],["112.53","1908.10"],["112.51","0"],["112.47","1841.92"],["112.45","0"],["112.41","1996.33"],["112.39","0"],["112.35","1819.86"],["112.33","0"],["112.29","1797.80"],["112.27","0"],["112.23","1974.27"],["112.21","0"],["112.17","1952.22"],["112.15","0"]],"checksum":-1011866972,"ts":"1649290093580"}]}
1649290093.851406: {"action":"update","arg":{"instType":"mc","channel":"books","instId":"UNIUSDT"},"data":[{"asks":[["9.990","0"],["9.991","104"],["9.992","103"],["9.993","270"],["9.994","2599"],["9.996","790"],["9.999","441"],["10.000","269"],["10.002","2045"],["10.003","1164"],["10.004","358"],["10.005","473"],["10.008","1324"],["10.009","631"],["10.010","495"],["10.011","2235"],["10.012","664"],["10.022","695"],["10.023","5075"],["10.024","1489"],["10.028","332"],["10.031","858"],["10.034","314"],["10.035","186"],["10.038","238"],["10.039","12157"],["10.043","0"],["10.044","12213"],["10.048","0"],["10.049","12789"],["10.053","0"],["10.054","12597"],["10.058","0"],["10.059","13366"],["10.063","0"],["10.064","13559"],["10.068","0"],["10.069","12020"],["10.073","0"],["10.074","11828"],["10.078","0"],["10.079","11636"],["10.083","0"],["10.084","13174"],["10.088","0"],["10.089","12982"],["10.093","0"],["10.094","12405"],["10.128","53"],["10.135","0"],["10.179","26"],["10.186","0"],["10.230","141"],["10.237","0"],["10.281","190"],["10.288","0"],["10.332","404"],["10.339","0"],["10.383","197"],["10.390","0"],["10.434","156"],["10.441","0"],["10.485","21"],["10.492","0"],["10.536","328"],["10.543","0"],["10.588","36"],["10.595","0"],["10.639","224"],["10.646","0"],["10.690","266"],["10.697","0"],["10.741","156"],["10.748","0"],["10.792","477"],["10.799","0"],["10.843","146"],["10.850","0"],["10.894","307"],["10.901","0"],["10.945","357"],["10.952","0"],["10.996","279"],["11.003","0"],["11.047","370"],["11.054","0"],["11.098","212"],["11.105","0"],["11.149","331"],["11.156","0"],["11.200","151"],["11.207","0"],["11.251","89"],["11.258","0"],["11.302","107"],["11.309","0"]],"bids":[["9.986","104"],["9.985","145"],["9.984","305"],["9.983","14"],["9.980","445"],["9.979","142"],["9.978","399"],["9.977","115"],["9.976","587"],["9.975","1137"],["9.974","800"],["9.973","384"],["9.970","1080"],["9.969","695"],["9.968","622"],["9.961","2097"],["9.956","5042"],["9.955","592"],["9.953","713"],["9.951","921"],["9.950","654"],["9.948","1250"],["9.946","2811"],["9.945","1651"],["9.942","210"],["9.941","1815"],["9.938","16311"],["9.937","3847"],["9.936","0"],["9.933","11828"],["9.932","0"],["9.928","12405"],["9.927","0"],["9.923","13366"],["9.922","0"],["9.918","13174"],["9.917","0"],["9.913","11636"],["9.912","0"],["9.908","11443"],["9.907","0"],["9.903","12020"],["9.902","0"],["9.898","12597"],["9.897","0"],["9.893","12789"],["9.892","0"],["9.888","12982"],["9.887","0"],["9.883","13559"],["9.882","0"],["9.809","0"],["9.802","351"],["9.758","0"],["9.751","399"],["9.707","0"],["9.700","274"],["9.655","0"],["9.648","23"],["9.604","0"],["9.597","112"],["9.553","0"],["9.546","47"],["9.502","0"],["9.495","290"],["9.451","0"],["9.444","318"],["9.400","0"],["9.393","326"],["9.349","0"],["9.342","106"],["9.298","0"],["9.291","193"],["9.247","0"],["9.240","376"],["9.196","0"],["9.189","231"],["9.145","0"],["9.138","4"],["9.094","0"],["9.087","149"],["9.043","0"],["9.036","85"],["8.992","0"],["8.985","320"],["8.941","0"],["8.934","61"],["8.890","0"],["8.883","131"],["8.839","0"],["8.832","477"],["8.788","0"],["8.781","367"],["8.737","0"],["8.730","253"],["8.686","0"],["8.679","83"],["8.635","0"],["8.628","48"]],"checksum":121777380,"ts":"1649290093820"}]}
1649290093.8523111: {"action":"snapshot","arg":{"instType":"mc","channel":"ticker","instId":"UNIUSDT"},"data":[{"instId":"UNIUSDT","last":"9.9860","bestAsk":"9.991","bestBid":"9.986","high24h":"10.4280","low24h":"9.9030","priceChangePercent":"-0.0385","capitalRate":"-0.000100","nextSettleTime":1649314800000,"systemTime":1649290093816,"markPrice":"9.9793","indexPrice":"9.9941","holding":"369411","baseVolume":"313093","quoteVolume":"3294544"}]}
1649290093.852349: {"action":"snapshot","arg":{"instType":"mc","channel":"ticker","instId":"DASHUSDT"},"data":[{"instId":"DASHUSDT","last":"113.500","bestAsk":"113.57","bestBid":"113.52","high24h":"118.870","low24h":"113.140","priceChangePercent":"-0.035","capitalRate":"-0.000100","nextSettleTime":1649314800000,"systemTime":1649290093818,"markPrice":"113.439","indexPrice":"113.478","holding":"21957.17","baseVolume":"25305.25","quoteVolume":"3062764.07"}]}
1649290093.934368: {"action":"update","arg":{"instType":"mc","channel":"books","instId":"DASHUSDT"},"data":[{"asks":[["113.56","0"],["113.58","0.82"],["113.59","0.86"],["113.60","8.99"],["113.61","37.64"],["113.62","15.30"],["113.63","25.83"],["113.64","42.07"],["113.67","9.03"],["113.68","35.54"],["113.70","85.02"],["113.71","207.70"],["113.72","45.06"],["113.73","210.50"],["113.74","4.37"],["113.75","27.09"],["113.76","1329.78"],["113.78","672.31"],["113.79","27.10"],["113.80","162.82"],["113.81","10.76"],["113.82","21.28"],["113.83","32.62"],["113.84","256.18"],["113.85","347.98"],["113.86","305.18"],["113.87","437.68"],["113.88","279.19"],["113.89","120.16"],["113.90","145.48"],["113.92","151.42"],["113.93","24.50"],["113.94","282.44"],["113.96","2.73"],["113.97","265.41"],["113.98","17.17"],["114.00","1940.63"],["114.01","100.12"],["114.02","17.71"],["114.03","1600.10"],["114.04","0"],["114.06","2020.38"],["114.07","102.68"],["114.10","0"],["114.12","1974.27"],["114.16","0"],["114.18","1841.92"],["114.22","0"],["114.24","1863.98"],["114.28","0"],["114.30","1731.63"],["114.34","0"],["114.36","1819.86"],["114.40","0"],["114.42","2040.45"],["114.46","0"],["114.48","1709.57"],["114.52","0"],["114.54","1797.80"],["114.58","0"],["114.60","1996.33"],["114.64","0"],["114.66","1753.69"],["114.70","0"],["114.72","1908.10"],["114.76","0"],["114.78","1930.16"],["114.82","0"],["114.84","1886.04"],["114.88","0"],["114.90","1952.22"],["115.78","0"],["116.00","31.47"],["116.37","0"],["116.59","50.46"],["116.96","0"],["117.18","49.40"],["117.55","0"],["117.77","27.41"],["118.14","0"],["118.36","50.42"],["118.73","0"],["118.95","50.07"],["119.32","0"],["119.54","36.12"],["119.91","0"],["120.13","8.62"],["120.50","0"],["120.72","54.60"],["121.09","0"],["121.31","1.48"],["121.68","0"],["121.90","43.49"],["122.27","0"],["122.49","7.73"],["122.86","0"],["123.08","58.21"],["123.45","0"],["123.67","52.67"],["124.04","0"],["124.26","53.84"],["124.63","0"],["124.85","4.99"],["125.22","0"],["125.44","44.04"],["125.81","0"],["126.03","25.10"],["126.40","0"],["126.62","39.09"],["126.99","0"],["127.21","44.51"],["127.58","0"],["127.80","19.01"],["128.17","0"],["128.39","29.39"],["128.76","0"],["128.98","3.89"],["129.35","0"],["129.57","23.37"],["129.94","0"],["130.16","24.18"],["130.53","0"],["130.75","9.15"],["131.12","0"],["131.34","27.04"],["131.71","0"],["131.93","7.10"],["132.52","13.38"],["133.11","33.57"],["133.70","76.51"]],"bids":[["113.52","60.40"],["113.51","519.76"],["113.48","12.50"],["113.47","0.77"],["113.46","4.95"],["113.44","220.18"],["113.43","107.93"],["113.41","7.68"],["113.40","34.37"],["113.39","42.89"],["113.38","12.03"],["113.35","403.99"],["113.33","27.06"],["113.32","32.03"],["113.31","12.46"],["113.29","11.66"],["113.28","23.20"],["113.26","91.40"],["113.25","40.63"],["113.23","20.73"],["113.21","63.62"],["113.19","221.04"],["113.18","68.76"],["113.17","16.84"],["113.16","173.34"],["113.13","34.04"],["113.12","10.26"],["113.10","1503.17"],["113.09","1736.41"],["113.08","82.73"],["113.07","36.54"],["113.03","1848.20"],["113.02","41.40"],["113.01","0"],["113.00","0"],["112.97","2040.45"],["112.95","0"],["112.91","1841.92"],["112.89","0"],["112.85","1775.75"],["112.83","0"],["112.79","1908.10"],["112.77","0"],["112.73","1886.04"],["112.71","0"],["112.67","2018.39"],["112.65","0"],["112.61","1996.33"],["112.59","0"],["112.55","1819.86"],["112.53","0"],["112.49","1709.57"],["112.47","0"],["112.43","1863.98"],["112.41","0"],["112.37","1930.16"],["112.35","0"],["112.31","1974.27"],["112.29","0"],["112.25","1797.80"],["112.23","0"],["112.19","1952.22"],["112.17","0"],["111.66","0"],["111.61","44.63"],["111.07","0"],["111.02","97.81"],["110.47","0"],["110.43","40.49"],["109.88","0"],["109.84","85.27"],["109.29","0"],["109.25","84.73"],["108.70","0"],["108.66","59.74"],["108.11","0"],["108.07","61.13"],["107.52","0"],["107.48","33.01"],["106.93","0"],["106.89","56.85"],["106.34","0"],["106.30","24.34"],["105.75","0"],["105.71","1.74"],["105.16","0"],["105.12","57.94"],["104.57","0"],["104.53","58.21"],["103.98","0"],["103.94","46.12"],["103.39","0"],["103.35","52.32"],["102.80","0"],["102.76","45.29"],["102.21","0"],["102.17","22.94"],["101.62","0"],["101.58","36.02"],["101.03","0"],["100.99","38.02"],["100.44","0"],["100.40","53.60"],["99.85","0"],["99.26","0"],["98.67","0"],["98.08","0"],["97.49","0"],["96.90","0"],["96.31","0"],["95.72","0"],["95.13","0"],["94.54","0"],["93.95","0"],["93.36","0"],["92.77","0"],["92.18","0"]],"checksum":1237043486,"ts":"1649290093905"}]}
1649290094.1001432: {"action":"snapshot","arg":{"instType":"mc","channel":"ticker","instId":"UNIUSDT"},"data":[{"instId":"UNIUSDT","last":"9.9860","bestAsk":"9.991","bestBid":"9.986","high24h":"10.4280","low24h":"9.9030","priceChangePercent":"-0.0385","capitalRate":"-0.000100","nextSettleTime":1649314800000,"systemTime":1649290094066,"markPrice":"9.9793","indexPrice":"9.9941","holding":"369411","baseVolume":"313093","quoteVolume":"3294544"}]}
1649290094.103117: {"action":"snapshot","arg":{"instType":"mc","channel":"ticker","instId":"DASHUSDT"},"data":[{"instId":"DASHUSDT","last":"113.500","bestAsk":"113.57","bestBid":"113.52","high24h":"118.870","low24h":"113.140","priceChangePercent":"-0.035","capitalRate":"-0.000100","nextSettleTime":1649314800000,"systemTime":1649290094075,"markPrice":"113.441","indexPrice":"113.478","holding":"21957.17","baseVolume":"25305.25","quoteVolume":"3062764.07"}]}
1649290094.153311: {"action":"update","arg":{"instType":"mc","channel":"books","instId":"UNIUSDT"},"data":[{"asks":[["9.990","41"],["9.991","150"],["9.992","113"],["9.993","330"],["9.995","157"],["9.997","240"],["9.998","698"],["9.999","582"],["10.000","240"],["10.001","763"],["10.003","590"],["10.004","452"],["10.009","700"],["10.011","2297"],["10.012","621"],["10.014","5362"],["10.038","13603"],["10.039","715"],["10.040","0"],["10.043","11828"],["10.044","0"],["10.048","13174"],["10.049","0"],["10.053","12213"],["10.054","0"],["10.058","12789"],["10.059","0"],["10.063","12982"],["10.064","0"],["10.068","12597"],["10.069","0"],["10.073","12405"],["10.074","0"],["10.078","11443"],["10.079","0"],["10.083","11636"],["10.084","0"],["10.088","13559"],["10.089","0"],["10.093","12020"],["10.094","0"],["10.122","53"],["10.128","0"],["10.173","26"],["10.179","0"],["10.224","141"],["10.230","0"],["10.275","190"],["10.281","0"],["10.326","404"],["10.332","0"],["10.377","197"],["10.383","0"],["10.428","156"],["10.434","0"],["10.479","21"],["10.485","0"],["10.530","328"],["10.536","0"],["10.582","36"],["10.588","0"],["10.633","224"],["10.639","0"],["10.684","266"],["10.690","0"],["10.735","156"],["10.741","0"],["10.786","477"],["10.792","0"],["10.837","146"],["10.843","0"],["10.888","307"],["10.894","0"],["10.939","357"],["10.945","0"],["10.990","279"],["10.996","0"],["11.041","370"],["11.047","0"],["11.092","212"],["11.098","0"],["11.143","331"],["11.149","0"],["11.194","151"],["11.200","0"],["11.245","89"],["11.251","0"],["11.296","107"],["11.302","0"]],"bids":[["9.986","0"],["9.985","211"],["9.984","306"],["9.983","80"],["9.981","40"],["9.980","460"],["9.979","152"],["9.977","140"],["9.976","807"],["9.975","997"],["9.974","833"],["9.973","404"],["9.971","348"],["9.970","1119"],["9.969","702"],["9.968","721"],["9.965","105"],["9.964","849"],["9.963","578"],["9.959","502"],["9.958","772"],["9.957","2730"],["9.956","5125"],["9.951","927"],["9.938","4099"],["9.937","17212"],["9.936","719"],["9.933","0"],["9.932","12982"],["9.928","0"],["9.927","11636"],["9.923","0"],["9.922","13559"],["9.918","0"],["9.917","12213"],["9.913","0"],["9.912","11828"],["9.908","0"],["9.907","12597"],["9.903","0"],["9.902","12405"],["9.898","0"],["9.897","13174"],["9.893","0"],["9.892","12789"],["9.888","0"],["9.887","12020"],["9.883","0"],["9.882","11443"],["9.802","0"],["9.796","351"],["9.751","0"],["9.745","399"],["9.700","0"],["9.694","274"],["9.648","0"],["9.642","23"],["9.597","0"],["9.591","112"],["9.546","0"],["9.540","47"],["9.495","0"],["9.489","290"],["9.444","0"],["9.438","318"],["9.393","0"],["9.387","326"],["9.342","0"],["9.336","106"],["9.291","0"],["9.285","193"],["9.240","0"],["9.234","376"],["9.189","0"],["9.183","231"],["9.138","0"],["9.132","4"],["9.087","0"],["9.081","149"],["9.036","0"],["9.030","85"],["8.985","0"],["8.979","320"],["8.934","0"],["8.928","61"],["8.883","0"],["8.877","131"],["8.832","0"],["8.826","477"],["8.781","0"],["8.775","367"],["8.730","0"],["8.724","253"],["8.679","0"],["8.673","83"],["8.628","0"],["8.622","48"]],"checksum":184067232,"ts":"1649290094122"}]}
1649290094.2384582: {"action":"update","arg":{"instType":"mc","channel":"books","instId":"DASHUSDT"},"data":[{"asks":[["113.57","9.05"],["113.59","2.01"],["113.60","2.77"],["113.62","26.30"],["113.63","27.37"],["113.67","10.71"],["113.68","35.65"],["113.70","66.74"],["113.71","163.77"],["113.73","218.75"],["113.75","43.52"],["113.76","1600.38"],["113.77","672.18"],["113.78","656.97"],["113.79","28.88"],["113.80","175.90"],["113.83","9.25"],["113.87","447.49"],["113.89","93.10"],["113.90","135.58"],["113.92","181.09"],["113.93","65.09"],["113.95","100.72"],["114.00","1874.45"],["114.06","1932.15"],["114.07","109.34"],["114.18","1908.10"],["114.24","2040.45"],["114.30","1863.98"],["114.36","1952.22"],["114.42","2018.39"],["114.48","1731.63"],["114.60","1819.86"],["114.72","1996.33"],["114.78","1775.75"],["114.90","1841.92"],["115.78","0.73"],["116.00","0"],["116.37","68.26"],["116.59","0"],["116.96","70.90"],["117.18","0"],["117.55","49.89"],["117.77","0"],["118.14","22.59"],["118.36","0"],["118.73","47.85"],["118.95","0"],["119.32","46.71"],["119.54","0"],["119.91","23.57"],["120.13","0"],["120.50","59.15"],["120.72","0"],["121.09","6.51"],["121.31","0"],["121.68","54.25"],["121.90","0"],["122.27","14.99"],["122.49","0"],["122.86","11.21"],["123.08","0"],["123.45","66.50"],["123.67","0"],["124.04","64.47"],["124.26","0"],["124.63","42.85"],["124.85","0"],["125.22","29.99"],["125.44","0"],["125.81","4.07"],["126.03","0"],["126.40","26.70"],["126.62","0"],["126.99","20.67"],["127.21","0"],["127.58","56.99"],["127.80","0"],["128.17","44.01"],["128.39","0"],["128.76","46.60"],["128.98","0"],["129.35","39.07"],["129.57","0"],["129.94","19.33"],["130.16","0"],["130.53","20.66"],["130.75","0"],["131.12","28.11"],["131.34","0"],["131.71","13.65"],["131.93","0"],["132.52","0"],["133.11","0"],["133.70","0"]],"bids":[["113.52","0"],["113.51","262.36"],["113.50","2.96"],["113.49","16.80"],["113.48","10.82"],["113.47","64.85"],["113.46","5.94"],["113.45","1600.27"],["113.44","167.71"],["113.43","81.16"],["113.42","37.43"],["113.41","3.11"],["113.40","55.81"],["113.39","0"],["113.37","123.11"],["113.35","271.85"],["113.34","14.76"],["113.33","22.55"],["113.31","10.97"],["113.29","5.85"],["113.27","24.26"],["113.26","115.65"],["113.25","54.49"],["113.24","174.25"],["113.23","10.73"],["113.22","96.16"],["113.21","34.30"],["113.20","55.60"],["113.17","12.98"],["113.14","399.73"],["113.09","6.70"],["113.08","1902.58"],["113.05","1476.22"],["113.03","96.79"],["113.02","1839.19"],["113.01","48.97"],["112.97","0"],["112.96","1908.10"],["112.91","0"],["112.90","1731.63"],["112.85","0"],["112.84","1709.57"],["112.79","0"],["112.78","1775.75"],["112.73","0"],["112.72","1753.69"],["112.67","0"],["112.66","1930.16"],["112.61","0"],["112.60","2040.45"],["112.55","0"],["112.54","1996.33"],["112.49","0"],["112.48","1886.04"],["112.43","0"],["112.42","1863.98"],["112.37","0"],["112.36","1952.22"],["112.31","0"],["112.30","1841.92"],["112.25","0"],["112.24","1974.27"],["112.19","0"],["112.18","2018.39"],["111.66","54.98"],["111.61","0"],["111.07","56.15"],["111.02","0"],["110.47","22.20"],["110.43","0"],["109.88","45.95"],["109.84","0"],["109.29","29.62"],["109.25","0"],["108.70","21.93"],["108.66","0"],["108.11","6.02"],["108.07","0"],["107.52","55.97"],["107.48","0"],["106.93","21.31"],["106.89","0"],["106.34","8.95"],["106.30","0"],["105.75","10.15"],["105.71","0"],["105.16","40.07"],["105.12","0"],["104.57","15.36"],["104.53","0"],["103.98","46.47"],["103.94","0"],["103.39","11.11"],["103.35","0"],["102.80","1.87"],["102.76","0"],["102.21","37.67"],["102.17","0"],["101.62","21.48"],["101.58","0"],["101.03","49.80"],["100.99","0"],["100.44","49.32"],["100.40","0"],["99.85","42.14"],["99.26","8.55"],["98.67","30.36"],["98.08","20.32"],["97.49","36.65"],["96.90","21.95"],["96.31","8.41"],["95.72","31.49"],["95.13","57.35"],["94.54","3.45"],["93.95","4.85"],["93.36","74.35"],["92.77","33.85"],["92.18","20.24"]],"checksum":1251498166,"ts":"1649290094207"}]}
1649290094.3595588: {"action":"snapshot","arg":{"instType":"mc","channel":"ticker","instId":"UNIUSDT"},"data":[{"instId":"UNIUSDT","last":"9.9860","bestAsk":"9.991","bestBid":"9.986","high24h":"10.4280","low24h":"9.9030","priceChangePercent":"-0.0385","capitalRate":"-0.000100","nextSettleTime":1649314800000,"systemTime":1649290094325,"markPrice":"9.9820","indexPrice":"9.9941","holding":"369411","baseVolume":"313093","quoteVolume":"3294544"}]}
1649290094.3660622: {"action":"snapshot","arg":{"instType":"mc","channel":"ticker","instId":"DASHUSDT"},"data":[{"instId":"DASHUSDT","last":"113.500","bestAsk":"113.57","bestBid":"113.52","high24h":"118.870","low24h":"113.140","priceChangePercent":"-0.035","capitalRate":"-0.000100","nextSettleTime":1649314800000,"systemTime":1649290094330,"markPrice":"113.441","indexPrice":"113.478","holding":"21957.17","baseVolume":"25305.25","quoteVolume":"3062764.07"}]}
1649290094.4553: {"action":"update","arg":{"instType":"mc","channel":"books","instId":"UNIUSDT"},"data":[{"asks":[["9.990","0"],["9.991","149"],["9.993","360"],["9.994","2681"],["9.995","275"],["9.997","332"],["9.998","648"],["9.999","606"],["10.000","188"],["10.001","926"],["10.002","1993"],["10.003","547"],["10.004","537"],["10.005","565"],["10.006","683"],["10.007","1062"],["10.008","1638"],["10.011","2316"],["10.012","648"],["10.013","826"],["10.016","894"],["10.018","207"],["10.020","4402"],["10.022","711"],["10.023","4598"],["10.028","374"],["10.038","266"],["10.039","13696"],["10.040","622"],["10.043","0"],["10.044","11443"],["10.048","0"],["10.049","12789"],["10.053","0"],["10.054","12405"],["10.058","0"],["10.059","12213"],["10.063","0"],["10.064","12597"],["10.068","0"],["10.069","13174"],["10.073","0"],["10.074","11828"],["10.078","0"],["10.079","13559"],["10.083","0"],["10.084","11636"],["10.088","0"],["10.089","13366"],["10.093","0"],["10.094","12020"],["10.116","53"],["10.122","0"],["10.167","26"],["10.173","0"],["10.218","141"],["10.224","0"],["10.269","190"],["10.275","0"],["10.320","404"],["10.326","0"],["10.371","197"],["10.377","0"],["10.422","156"],["10.428","0"],["10.473","21"],["10.479","0"],["10.524","328"],["10.530","0"],["10.576","36"],["10.582","0"],["10.627","224"],["10.633","0"],["10.678","266"],["10.684","0"],["10.729","156"],["10.735","0"],["10.780","477"],["10.786","0"],["10.831","146"],["10.837","0"],["10.882","307"],["10.888","0"],["10.933","357"],["10.939","0"],["10.984","279"],["10.990","0"],["11.035","370"],["11.041","0"],["11.086","212"],["11.092","0"],["11.137","331"],["11.143","0"],["11.188","151"],["11.194","0"],["11.239","89"],["11.245","0"],["11.290","107"],["11.296","0"]],"bids":[["9.986","68"],["9.985","222"],["9.984","254"],["9.983","140"],["9.982","188"],["9.981","122"],["9.979","852"],["9.977","110"],["9.976","407"],["9.973","419"],["9.972","259"],["9.971","345"],["9.963","762"],["9.959","440"],["9.957","2544"],["9.953","664"],["9.952","659"],["9.950","505"],["9.949","550"],["9.948","834"],["9.938","17657"],["9.937","3847"],["9.936","0"],["9.933","12789"],["9.932","0"],["9.928","11636"],["9.927","0"],["9.923","12982"],["9.922","0"],["9.918","12020"],["9.917","0"],["9.913","13366"],["9.912","0"],["9.908","11443"],["9.907","0"],["9.903","12213"],["9.902","0"],["9.898","11828"],["9.897","0"],["9.893","12597"],["9.892","0"],["9.888","13174"],["9.887","0"],["9.883","12405"],["9.882","0"],["9.796","0"],["9.790","351"],["9.745","0"],["9.739","399"],["9.694","0"],["9.688","274"],["9.642","0"],["9.636","23"],["9.591","0"],["9.585","112"],["9.540","0"],["9.534","47"],["9.489","0"],["9.483","290"],["9.438","0"],["9.432","318"],["9.387","0"],["9.381","326"],["9.336","0"],["9.330","106"],["9.285","0"],["9.279","193"],["9.234","0"],["9.228","376"],["9.183","0"],["9.177","231"],["9.132","0"],["9.126","4"],["9.081","0"],["9.075","149"],["9.030","0"],["9.024","85"],["8.979","0"],["8.973","320"],["8.928","0"],["8.922","61"],["8.877","0"],["8.871","131"],["8.826","0"],["8.820","477"],["8.775","0"],["8.769","367"],["8.724","0"],["8.718","253"],["8.673","0"],["8.667","83"],["8.622","0"],["8.616","48"]],"checksum":173214728,"ts":"1649290094428"}]}
1649290094.548213: {"action":"update","arg":{"instType":"mc","channel":"books","instId":"DASHUSDT"},"data":[{"asks":[["113.56","0.49"],["113.57","0"],["113.61","38.58"],["113.62","20.02"],["113.65","113.00"],["113.67","18.16"],["113.68","40.38"],["113.69","44.81"],["113.70","55.37"],["113.71","124.31"],["113.72","49.45"],["113.73","320.74"],["113.76","1329.68"],["113.77","673.69"],["113.78","670.05"],["113.80","199.83"],["113.82","18.46"],["113.85","183.19"],["113.91","193.26"],["113.92","177.74"],["113.95","25.99"],["113.98","26.93"],["113.99","2098.71"],["114.00","158.29"],["114.02","21.25"],["114.05","1874.26"],["114.06","126.98"],["114.07","89.79"],["114.11","1709.57"],["114.12","0"],["114.17","1863.98"],["114.18","0"],["114.23","2040.45"],["114.24","0"],["114.29","1797.80"],["114.30","0"],["114.35","1974.27"],["114.36","0"],["114.41","2018.39"],["114.42","0"],["114.47","1753.69"],["114.48","0"],["114.53","1930.16"],["114.54","0"],["114.59","1952.22"],["114.60","0"],["114.65","1996.33"],["114.66","0"],["114.71","1819.86"],["114.72","0"],["114.77","1841.92"],["114.78","0"],["114.83","1886.04"],["114.84","0"],["114.89","1908.10"],["114.90","0"]],"bids":[["113.50","0"],["113.49","16.17"],["113.48","14.82"],["113.47","45.24"],["113.46","1.10"],["113.45","1600.18"],["113.44","2.78"],["113.43","89.26"],["113.41","5.58"],["113.38","8.43"],["113.37","121.82"],["113.35","681.41"],["113.34","16.91"],["113.32","18.95"],["113.31","146.60"],["113.26","77.27"],["113.25","53.79"],["113.24","187.34"],["113.23","117.58"],["113.22","16.04"],["113.20","45.89"],["113.19","3.50"],["113.18","66.86"],["113.08","2054.92"],["113.04","59.36"],["113.03","95.21"],["113.02","1883.71"],["113.01","68.77"],["113.00","64.41"],["112.96","1863.98"],["112.90","1930.16"],["112.84","2040.45"],["112.78","1819.86"],["112.72","1886.04"],["112.66","1996.33"],["112.60","1731.63"],["112.54","1753.69"],["112.48","1709.57"],["112.42","1908.10"],["112.36","1797.80"],["112.30","2018.39"],["112.24","1775.75"],["112.18","1952.22"]],"checksum":65633473,"ts":"1649290094521"}]}
1649290094.6142569: {"action":"snapshot","arg":{"instType":"mc","channel":"ticker","instId":"UNIUSDT"},"data":[{"instId":"UNIUSDT","last":"9.9860","bestAsk":"9.991","bestBid":"9.986","high24h":"10.4280","low24h":"9.9030","priceChangePercent":"-0.0385","capitalRate":"-0.000100","nextSettleTime":1649314800000,"systemTime":1649290094580,"markPrice":"9.9820","indexPrice":"9.9942","holding":"369411","baseVolume":"313093","quoteVolume":"3294544"}]}
1649290094.6258729: {"action":"snapshot","arg":{"instType":"mc","channel":"ticker","instId":"DASHUSDT"},"data":[{"instId":"DASHUSDT","last":"113.500","bestAsk":"113.58","bestBid":"113.53","high24h":"118.870","low24h":"113.140","priceChangePercent":"-0.035","capitalRate":"-0.000100","nextSettleTime":1649314800000,"systemTime":1649290094592,"markPrice":"113.441","indexPrice":"113.478","holding":"21957.17","baseVolume":"25305.25","quoteVolume":"3062764.07"}]}
1649290094.674073: {"action":"update","arg":{"instType":"mc","channel":"trade","instId":"UNIUSDT"},"data":[["1649290094578","9.986","5","sell"]]}
1649290094.753729: {"action":"update","arg":{"instType":"mc","channel":"books","instId":"UNIUSDT"},"data":[{"asks":[["9.991","127"],["9.993","406"],["9.994","2654"],["9.997","376"],["9.998","616"],["9.999","608"],["10.002","1869"],["10.005","664"],["10.006","872"],["10.009","565"],["10.010","576"],["10.011","2755"],["10.012","621"],["10.022","280"],["10.023","5075"],["10.027","1954"],["10.038","464"],["10.039","13311"],["10.044","12405"],["10.049","11636"],["10.054","13174"],["10.059","12982"],["10.064","13366"],["10.069","12213"],["10.074","11443"],["10.079","11828"],["10.084","12020"],["10.089","13559"],["10.094","12789"],["10.110","53"],["10.116","0"],["10.161","26"],["10.167","0"],["10.212","141"],["10.218","0"],["10.263","190"],["10.269","0"],["10.314","404"],["10.320","0"],["10.365","197"],["10.371","0"],["10.416","156"],["10.422","0"],["10.467","21"],["10.473","0"],["10.518","328"],["10.524","0"],["10.570","36"],["10.576","0"],["10.621","224"],["10.627","0"],["10.672","266"],["10.678","0"],["10.723","156"],["10.729","0"],["10.774","477"],["10.780","0"],["10.825","146"],["10.831","0"],["10.876","307"],["10.882","0"],["10.927","357"],["10.933","0"],["10.978","279"],["10.984","0"],["11.029","370"],["11.035","0"],["11.080","212"],["11.086","0"],["11.131","331"],["11.137","0"],["11.182","151"],["11.188","0"],["11.233","89"],["11.239","0"],["11.284","107"],["11.290","0"]],"bids":[["9.986","168"],["9.985","188"],["9.984","320"],["9.983","91"],["9.982","254"],["9.981","23"],["9.977","113"],["9.976","344"],["9.975","1145"],["9.974","638"],["9.973","322"],["9.971","428"],["9.969","1290"],["9.966","224"],["9.956","4939"],["9.955","668"],["9.948","1250"],["9.938","15541"],["9.937","3877"],["9.933","12597"],["9.928","12405"],["9.923","11636"],["9.918","11828"],["9.913","13174"],["9.908","12982"],["9.903","13366"],["9.898","12789"],["9.893","12020"],["9.888","12213"],["9.883","13559"],["9.790","0"],["9.784","351"],["9.739","0"],["9.733","399"],["9.688","0"],["9.682","274"],["9.636","0"],["9.630","23"],["9.585","0"],["9.579","112"],["9.534","0"],["9.528","47"],["9.483","0"],["9.477","290"],["9.432","0"],["9.426","318"],["9.381","0"],["9.375","326"],["9.330","0"],["9.324","106"],["9.279","0"],["9.273","193"],["9.228","0"],["9.222","376"],["9.177","0"],["9.171","231"],["9.126","0"],["9.120","4"],["9.075","0"],["9.069","149"],["9.024","0"],["9.018","85"],["8.973","0"],["8.967","320"],["8.922","0"],["8.916","61"],["8.871","0"],["8.865","131"],["8.820","0"],["8.814","477"],["8.769","0"],["8.763","367"],["8.718","0"],["8.712","253"],["8.667","0"],["8.661","83"],["8.616","0"],["8.610","48"]],"checksum":-1340863599,"ts":"1649290094726"}]}
1649290094.868414: {"action":"update","arg":{"instType":"mc","channel":"books","instId":"DASHUSDT"},"data":[{"asks":[["113.56","0"],["113.58","0"],["113.61","36.72"],["113.62","19.42"],["113.67","20.91"],["113.68","25.15"],["113.69","37.84"],["113.70","54.65"],["113.72","52.82"],["113.76","1331.49"],["113.77","690.95"],["113.78","671.13"],["113.82","20.61"],["113.83","8.13"],["113.87","443.97"],["113.90","150.64"],["113.99","368.19"],["114.02","1928.91"],["114.05","98.52"],["114.07","115.94"],["114.08","2060.47"],["114.09","82.44"],["114.11","0"],["114.14","1753.69"],["114.17","0"],["114.20","1819.86"],["114.23","0"],["114.26","1709.57"],["114.29","0"],["114.32","1863.98"],["114.35","0"],["114.38","1797.80"],["114.41","0"],["114.44","1974.27"],["114.47","0"],["114.50","1996.33"],["114.53","0"],["114.56","1930.16"],["114.59","0"],["114.62","1952.22"],["114.65","0"],["114.68","1886.04"],["114.71","0"],["114.74","2018.39"],["114.77","0"],["114.80","1775.75"],["114.83","0"],["114.86","1731.63"],["114.89","0"],["114.92","1841.92"]],"bids":[["113.53","7.73"],["113.52","56.44"],["113.50","5.70"],["113.49","18.64"],["113.48","56.89"],["113.47","0.77"],["113.43","33.05"],["113.40","51.38"],["113.39","2.72"],["113.38","12.57"],["113.35","566.29"],["113.34","14.20"],["113.33","16.16"],["113.32","15.98"],["113.23","121.05"],["113.22","18.91"],["113.18","63.57"],["113.13","38.59"],["113.10","3521.35"],["113.08","80.66"],["113.04","1883.59"],["113.03","0"],["113.02","0"],["113.01","0"],["113.00","0"],["112.98","1841.92"],["112.96","0"],["112.92","1930.16"],["112.90","0"],["112.86","1908.10"],["112.84","0"],["112.80","1797.80"],["112.78","0"],["112.74","1974.27"],["112.72","0"],["112.68","1952.22"],["112.66","0"],["112.62","1709.57"],["112.60","0"],["112.56","1863.98"],["112.54","0"],["112.50","1886.04"],["112.48","0"],["112.44","2040.45"],["112.42","0"],["112.38","1775.75"],["112.36","0"],["112.32","1996.33"],["112.30","0"],["112.26","1753.69"],["112.24","0"],["112.20","1731.63"],["112.18","0"]],"checksum":-852295057,"ts":"1649290094837"}]}
1649290094.87625: {"action":"snapshot","arg":{"instType":"mc","channel":"ticker","instId":"UNIUSDT"},"data":[{"instId":"UNIUSDT","last":"9.9860","bestAsk":"9.991","bestBid":"9.986","high24h":"10.4280","low24h":"9.9030","priceChangePercent":"-0.0385","capitalRate":"-0.000100","nextSettleTime":1649314800000,"systemTime":1649290094846,"markPrice":"9.9820","indexPrice":"9.9942","holding":"369411","baseVolume":"313093","quoteVolume":"3294544"}]}
1649290094.890348: {"action":"snapshot","arg":{"instType":"mc","channel":"ticker","instId":"DASHUSDT"},"data":[{"instId":"DASHUSDT","last":"113.500","bestAsk":"113.59","bestBid":"113.53","high24h":"118.870","low24h":"113.140","priceChangePercent":"-0.035","capitalRate":"-0.000100","nextSettleTime":1649314800000,"systemTime":1649290094849,"markPrice":"113.441","indexPrice":"113.478","holding":"21957.17","baseVolume":"25305.25","quoteVolume":"3062764.07"}]}
1649290095.073371: {"action":"update","arg":{"instType":"mc","channel":"books","instId":"UNIUSDT"},"data":[{"asks":[["9.991","100"],["9.996","765"],["9.997","332"],["9.998","649"],["10.001","899"],["10.003","434"],["10.004","655"],["10.005","575"],["10.007","999"],["10.008","1544"],["10.009","629"],["10.010","790"],["10.011","1912"],["10.012","1496"],["10.014","5487"],["10.019","145"],["10.020","4379"],["10.022","905"],["10.023","5227"],["10.028","306"],["10.035","158"],["10.039","12350"],["10.044","12213"],["10.049","12405"],["10.054","13559"],["10.059","11828"],["10.064","12597"],["10.069","12020"],["10.074","12789"],["10.079","11443"],["10.084","13366"],["10.089","13174"],["10.094","12982"],["10.104","53"],["10.110","0"],["10.155","26"],["10.161","0"],["10.206","141"],["10.212","0"],["10.257","190"],["10.263","0"],["10.308","404"],["10.314","0"],["10.359","197"],["10.365","0"],["10.410","156"],["10.416","0"],["10.461","21"],["10.467","0"],["10.512","328"],["10.518","0"],["10.564","36"],["10.570","0"],["10.615","224"],["10.621","0"],["10.666","266"],["10.672","0"],["10.717","156"],["10.723","0"],["10.768","477"],["10.774","0"],["10.819","146"],["10.825","0"],["10.870","307"],["10.876","0"],["10.921","357"],["10.927","0"],["10.972","279"],["10.978","0"],["11.023","370"],["11.029","0"],["11.074","212"],["11.080","0"],["11.125","331"],["11.131","0"],["11.176","151"],["11.182","0"],["11.227","89"],["11.233","0"],["11.278","107"],["11.284","0"]],"bids":[["9.986","136"],["9.983","80"],["9.981","67"],["9.977","164"],["9.976","367"],["9.974","735"],["9.973","292"],["9.971","370"],["9.969","1310"],["9.966","290"],["9.964","1040"],["9.961","2121"],["9.960","665"],["9.958","1296"],["9.957","1752"],["9.952","770"],["9.949","740"],["9.946","2531"],["9.945","1602"],["9.938","17657"],["9.933","12213"],["9.928","11443"],["9.923","12982"],["9.918","13366"],["9.913","12020"],["9.908","12405"],["9.903","11636"],["9.893","13174"],["9.888","12597"],["9.883","11828"],["9.784","0"],["9.778","351"],["9.733","0"],["9.727","399"],["9.682","0"],["9.676","274"],["9.630","0"],["9.624","23"],["9.579","0"],["9.573","112"],["9.528","0"],["9.522","47"],["9.477","0"],["9.471","290"],["9.426","0"],["9.420","318"],["9.375","0"],["9.369","326"],["9.324","0"],["9.318","106"],["9.273","0"],["9.267","193"],["9.222","0"],["9.216","376"],["9.171","0"],["9.165","231"],["9.120","0"],["9.114","4"],["9.069","0"],["9.063","149"],["9.018","0"],["9.012","85"],["8.967","0"],["8.961","320"],["8.916","0"],["8.910","61"],["8.865","0"],["8.859","131"],["8.814","0"],["8.808","477"],["8.763","0"],["8.757","367"],["8.712","0"],["8.706","253"],["8.661","0"],["8.655","83"],["8.610","0"],["8.604","48"]],"checksum":633827125,"ts":"1649290095042"}]}
1649290095.166869: {"action":"update","arg":{"instType":"mc","channel":"books","instId":"DASHUSDT"},"data":[{"asks":[["113.59","5.65"],["113.60","4.15"],["113.61","38.63"],["113.62","14.43"],["113.63","16.97"],["113.64","45.43"],["113.65","102.41"],["113.67","16.92"],["113.70","53.00"],["113.71","136.56"],["113.75","83.45"],["113.76","1474.55"],["113.77","684.41"],["113.85","340.60"],["113.87","339.03"],["113.95","11.14"],["114.00","148.39"],["114.02","1862.73"],["114.08","1906.06"],["114.20","1974.27"],["114.26","2040.45"],["114.32","1731.63"],["114.38","1908.10"],["114.44","1996.33"],["114.50","1952.22"],["114.56","1819.86"],["114.62","1709.57"],["114.68","1775.75"],["114.74","1797.80"],["114.80","2018.39"],["114.86","1863.98"],["114.92","1930.16"]],"bids":[["113.50","9.57"],["113.49","19.96"],["113.48","17.59"],["113.47","33.06"],["113.46","86.14"],["113.43","35.06"],["113.38","8.43"],["113.37","124.59"],["113.35","289.20"],["113.34","40.35"],["113.33","13.83"],["113.31","149.38"],["113.23","126.49"],["113.20","58.32"],["113.18","58.12"],["113.10","3455.18"],["113.04","1861.53"],["112.98","1775.75"],["112.92","1753.69"],["112.86","1731.63"],["112.80","1819.86"],["112.74","1930.16"],["112.68","2040.45"],["112.62","1974.27"],["112.56","1886.04"],["112.50","1908.10"],["112.44","1841.92"],["112.38","2018.39"],["112.32","1709.57"],["112.26","1996.33"],["112.20","1863.98"]],"checksum":1070520430,"ts":"1649290095140"}]}
1649290095.1747699: {"action":"snapshot","arg":{"instType":"mc","channel":"ticker","instId":"UNIUSDT"},"data":[{"instId":"UNIUSDT","last":"9.9860","bestAsk":"9.991","bestBid":"9.986","high24h":"10.4280","low24h":"9.9030","priceChangePercent":"-0.0385","capitalRate":"-0.000100","nextSettleTime":1649314800000,"systemTime":1649290095143,"markPrice":"9.9820","indexPrice":"9.9942","holding":"369411","baseVolume":"313093","quoteVolume":"3294544"}]}
1649290095.182142: {"action":"snapshot","arg":{"instType":"mc","channel":"ticker","instId":"DASHUSDT"},"data":[{"instId":"DASHUSDT","last":"113.500","bestAsk":"113.59","bestBid":"113.53","high24h":"118.870","low24h":"113.140","priceChangePercent":"-0.035","capitalRate":"-0.000100","nextSettleTime":1649314800000,"systemTime":1649290095151,"markPrice":"113.452","indexPrice":"113.478","holding":"21957.17","baseVolume":"25305.25","quoteVolume":"3062764.07"}]}
1649290095.412332: {"action":"update","arg":{"instType":"mc","channel":"books","instId":"UNIUSDT"},"data":[{"asks":[["9.990","4"],["9.991","213"],["9.992","225"],["9.993","465"],["9.995","402"],["9.996","715"],["9.997","377"],["9.998","393"],["9.999","526"],["10.000","399"],["10.002","2301"],["10.003","493"],["10.004","669"],["10.007","1025"],["10.010","644"],["10.012","1382"],["10.013","942"],["10.015","730"],["10.016","570"],["10.019","225"],["10.022","908"],["10.023","4557"],["10.026","5591"],["10.027","2925"],["10.029","8290"],["10.031","434"],["10.033","6014"],["10.038","12918"],["10.039","167"],["10.040","0"],["10.043","12020"],["10.044","0"],["10.048","13559"],["10.049","0"],["10.053","13366"],["10.054","0"],["10.058","12789"],["10.059","0"],["10.063","12597"],["10.064","0"],["10.068","11828"],["10.069","0"],["10.073","11443"],["10.074","0"],["10.078","12213"],["10.079","0"],["10.083","12982"],["10.084","0"],["10.088","12405"],["10.089","0"],["10.093","13174"],["10.094","0"],["10.097","53"],["10.104","0"],["10.148","26"],["10.155","0"],["10.199","141"],["10.206","0"],["10.250","190"],["10.257","0"],["10.301","404"],["10.308","0"],["10.352","197"],["10.359","0"],["10.403","156"],["10.410","0"],["10.454","21"],["10.461","0"],["10.505","328"],["10.512","0"],["10.557","36"],["10.564","0"],["10.608","224"],["10.615","0"],["10.659","266"],["10.666","0"],["10.710","156"],["10.717","0"],["10.761","477"],["10.768","0"],["10.812","146"],["10.819","0"],["10.863","307"],["10.870","0"],["10.914","357"],["10.921","0"],["10.965","279"],["10.972","0"],["11.016","370"],["11.023","0"],["11.067","212"],["11.074","0"],["11.118","331"],["11.125","0"],["11.169","151"],["11.176","0"],["11.220","89"],["11.227","0"],["11.271","107"],["11.278","0"]],"bids":[["9.986","0"],["9.985","212"],["9.984","400"],["9.983","17"],["9.982","243"],["9.981","54"],["9.977","151"],["9.976","344"],["9.973","322"],["9.969","1290"],["9.966","393"],["9.964","746"],["9.963","847"],["9.959","416"],["9.957","2182"],["9.956","4652"],["9.955","522"],["9.941","1963"],["9.940","3848"],["9.938","4099"],["9.937","15704"],["9.936","1016"],["9.933","0"],["9.932","12789"],["9.928","0"],["9.927","12020"],["9.923","0"],["9.922","12597"],["9.918","0"],["9.917","11443"],["9.913","0"],["9.912","12405"],["9.908","0"],["9.907","13559"],["9.903","0"],["9.902","11636"],["9.898","0"],["9.897","13366"],["9.893","0"],["9.892","12982"],["9.888","0"],["9.887","13174"],["9.883","0"],["9.882","12213"],["9.778","0"],["9.771","351"],["9.727","0"],["9.720","399"],["9.676","0"],["9.669","274"],["9.624","0"],["9.617","23"],["9.573","0"],["9.566","112"],["9.522","0"],["9.515","47"],["9.471","0"],["9.464","290"],["9.420","0"],["9.413","318"],["9.369","0"],["9.362","326"],["9.318","0"],["9.311","106"],["9.267","0"],["9.260","193"],["9.216","0"],["9.209","376"],["9.165","0"],["9.158","231"],["9.114","0"],["9.107","4"],["9.063","0"],["9.056","149"],["9.012","0"],["9.005","85"],["8.961","0"],["8.954","320"],["8.910","0"],["8.903","61"],["8.859","0"],["8.852","131"],["8.808","0"],["8.801","477"],["8.757","0"],["8.750","367"],["8.706","0"],["8.699","253"],["8.655","0"],["8.648","83"],["8.604","0"],["8.597","48"]],"checksum":-1307305116,"ts":"1649290095377"}]}
1649290095.4421399: {"action":"snapshot","arg":{"instType":"mc","channel":"ticker","instId":"DASHUSDT"},"data":[{"instId":"DASHUSDT","last":"113.500","bestAsk":"113.59","bestBid":"113.53","high24h":"118.870","low24h":"113.140","priceChangePercent":"-0.035","capitalRate":"-0.000100","nextSettleTime":1649314800000,"systemTime":1649290095409,"markPrice":"113.452","indexPrice":"113.478","holding":"21957.17","baseVolume":"25305.25","quoteVolume":"3062764.07"}]}
1649290095.442235: {"action":"snapshot","arg":{"instType":"mc","channel":"ticker","instId":"UNIUSDT"},"data":[{"instId":"UNIUSDT","last":"9.9860","bestAsk":"9.99","bestBid":"9.985","high24h":"10.4280","low24h":"9.9030","priceChangePercent":"-0.0385","capitalRate":"-0.000100","nextSettleTime":1649314800000,"systemTime":1649290095406,"markPrice":"9.9820","indexPrice":"9.9942","holding":"369411","baseVolume":"313093","quoteVolume":"3294544"}]}
1649290095.489675: {"action":"update","arg":{"instType":"mc","channel":"books","instId":"DASHUSDT"},"data":[{"asks":[["113.58","0.77"],["113.59","5.78"],["113.60","8.17"],["113.63","12.61"],["113.64","36.70"],["113.68","8.47"],["113.71","124.31"],["113.82","27.15"],["114.01","1853.80"],["114.02","20.82"],["114.07","2024.03"],["114.08","15.69"],["114.09","0"],["114.13","1731.63"],["114.14","0"],["114.19","1886.04"],["114.20","0"],["114.25","1775.75"],["114.26","0"],["114.31","2018.39"],["114.32","0"],["114.37","1819.86"],["114.38","0"],["114.43","1797.80"],["114.44","0"],["114.49","1952.22"],["114.50","0"],["114.55","1863.98"],["114.56","0"],["114.61","1974.27"],["114.62","0"],["114.67","1841.92"],["114.68","0"],["114.73","2040.45"],["114.74","0"],["114.79","1996.33"],["114.80","0"],["114.85","1930.16"],["114.86","0"],["114.91","1709.57"],["114.92","0"],["115.78","0"],["116.00","31.47"],["116.37","0"],["116.59","50.46"],["116.96","0"],["117.18","49.40"],["117.55","0"],["117.77","27.41"],["118.14","0"],["118.36","50.42"],["118.73","0"],["118.95","50.07"],["119.32","0"],["119.54","36.12"],["119.91","0"],["120.13","8.62"],["120.50","0"],["120.72","54.60"],["121.09","0"],["121.31","1.48"],["121.68","0"],["121.90","43.49"],["122.27","0"],["122.49","7.73"],["122.86","0"],["123.08","58.21"],["123.45","0"],["123.67","52.67"],["124.04","0"],["124.26","53.84"],["124.63","0"],["124.85","4.99"],["125.22","0"],["125.44","44.04"],["125.81","0"],["126.03","25.10"],["126.40","0"],["126.62","39.09"],["126.99","0"],["127.21","44.51"],["127.58","0"],["127.80","19.01"],["128.17","0"],["128.39","29.39"],["128.76","0"],["128.98","3.89"],["129.35","0"],["129.57","23.37"],["129.94","0"],["130.16","24.18"],["130.53","0"],["130.75","9.15"],["131.12","0"],["131.34","27.04"],["131.71","0"],["131.93","7.10"],["132.52","13.38"],["133.11","33.57"],["133.70","76.51"]],"bids":[["113.51","519.76"],["113.50","5.70"],["113.49","30.70"],["113.48","17.93"],["113.47","36.60"],["113.46","45.42"],["113.41","7.04"],["113.40","28.40"],["113.36","23.54"],["113.35","292.35"],["113.31","146.60"],["113.22","16.24"],["113.18","57.09"],["113.10","3433.90"],["113.04","2099.80"],["112.98","1709.57"],["112.92","1731.63"],["112.86","1886.04"],["112.80","1952.22"],["112.74","1863.98"],["112.68","2018.39"],["112.62","1775.75"],["112.56","1996.33"],["112.50","1819.86"],["112.44","1753.69"],["112.38","1797.80"],["112.32","1908.10"],["112.26","1841.92"],["112.20","1974.27"],["111.66","0"],["111.61","44.63"],["111.07","0"],["111.02","97.81"],["110.47","0"],["110.43","40.49"],["109.88","0"],["109.84","85.27"],["109.29","0"],["109.25","84.73"],["108.70","0"],["108.66","59.74"],["108.11","0"],["108.07","61.13"],["107.52","0"],["107.48","33.01"],["106.93","0"],["106.89","56.85"],["106.34","0"],["106.30","24.34"],["105.75","0"],["105.71","1.74"],["105.16","0"],["105.12","57.94"],["104.57","0"],["104.53","58.21"],["103.98","0"],["103.94","46.12"],["103.39","0"],["103.35","52.32"],["102.80","0"],["102.76","45.29"],["102.21","0"],["102.17","22.94"],["101.62","0"],["101.58","36.02"],["101.03","0"],["100.99","38.02"],["100.44","0"],["100.40","53.60"],["99.85","0"],["99.26","0"],["98.67","0"],["98.08","0"],["97.49","0"],["96.90","0"],["96.31","0"],["95.72","0"],["95.13","0"],["94.54","0"],["93.95","0"],["93.36","0"],["92.77","0"],["92.18","0"]],"checksum":-2098735711,"ts":"1649290095461"}]}
1649290095.564208: {"action":"update","arg":{"instType":"mc","channel":"candle1m","instId":"UNIUSDT"},"data":[["1649290080000","9.977","9.986","9.976","9.986","25"]]}
1649290095.694358: {"action":"snapshot","arg":{"instType":"mc","channel":"ticker","instId":"UNIUSDT"},"data":[{"instId":"UNIUSDT","last":"9.9860","bestAsk":"9.988","bestBid":"9.982","high24h":"10.4280","low24h":"9.9030","priceChangePercent":"-0.0385","capitalRate":"-0.000100","nextSettleTime":1649314800000,"systemTime":1649290095663,"markPrice":"9.9846","indexPrice":"9.9942","holding":"369411","baseVolume":"313098","quoteVolume":"3294594"}]}
1649290095.708367: {"action":"update","arg":{"instType":"mc","channel":"books","instId":"UNIUSDT"},"data":[{"asks":[["9.987","14"],["9.988","9"],["9.989","74"],["9.990","291"],["9.991","627"],["9.992","136"],["9.993","1048"],["9.994","2781"],["9.995","412"],["9.996","814"],["9.997","452"],["9.998","410"],["9.999","511"],["10.000","384"],["10.001","813"],["10.002","2217"],["10.003","756"],["10.004","629"],["10.005","590"],["10.006","941"],["10.007","1026"],["10.008","1689"],["10.009","565"],["10.012","652"],["10.013","933"],["10.014","5345"],["10.015","590"],["10.016","580"],["10.018","226"],["10.019","175"],["10.021","71"],["10.022","457"],["10.035","13716"],["10.036","55"],["10.037","0"],["10.038","0"],["10.039","0"],["10.040","12020"],["10.043","0"],["10.045","12213"],["10.048","0"],["10.050","11443"],["10.053","0"],["10.055","12982"],["10.058","0"],["10.060","11636"],["10.063","0"],["10.065","13174"],["10.068","0"],["10.070","12789"],["10.073","0"],["10.075","12597"],["10.078","0"],["10.080","13366"],["10.083","0"],["10.085","11828"],["10.088","0"],["10.090","12405"],["10.091","53"],["10.093","0"],["10.097","0"],["10.142","26"],["10.148","0"],["10.193","141"],["10.199","0"],["10.244","190"],["10.250","0"],["10.295","404"],["10.301","0"],["10.346","197"],["10.352","0"],["10.397","156"],["10.403","0"],["10.448","21"],["10.454","0"],["10.499","328"],["10.505","0"],["10.551","36"],["10.557","0"],["10.602","224"],["10.608","0"],["10.653","266"],["10.659","0"],["10.704","156"],["10.710","0"],["10.755","477"],["10.761","0"],["10.806","146"],["10.812","0"],["10.857","307"],["10.863","0"],["10.908","357"],["10.914","0"],["10.959","279"],["10.965","0"],["11.010","370"],["11.016","0"],["11.061","212"],["11.067","0"],["11.112","331"],["11.118","0"],["11.163","151"],["11.169","0"],["11.214","89"],["11.220","0"],["11.265","107"],["11.271","0"]],"bids":[["9.985","0"],["9.984","0"],["9.983","0"],["9.982","600"],["9.981","18"],["9.980","170"],["9.979","773"],["9.978","267"],["9.977","67"],["9.976","120"],["9.975","1196"],["9.974","858"],["9.973","285"],["9.972","312"],["9.971","352"],["9.970","621"],["9.968","575"],["9.967","323"],["9.966","344"],["9.964","663"],["9.963","796"],["9.962","159"],["9.961","2191"],["9.960","709"],["9.959","378"],["9.958","504"],["9.956","4567"],["9.951","974"],["9.949","553"],["9.948","834"],["9.947","447"],["9.946","2372"],["9.945","1017"],["9.943","887"],["9.937","3877"],["9.935","15"],["9.934","16368"],["9.933","3630"],["9.932","0"],["9.929","13174"],["9.927","0"],["9.924","12213"],["9.922","0"],["9.919","12597"],["9.917","0"],["9.914","13559"],["9.912","0"],["9.909","11828"],["9.907","0"],["9.904","13366"],["9.902","0"],["9.899","11443"],["9.897","0"],["9.894","12020"],["9.892","0"],["9.889","12789"],["9.887","0"],["9.884","11636"],["9.882","0"],["9.879","12982"],["9.771","0"],["9.765","351"],["9.720","0"],["9.714","399"],["9.669","0"],["9.663","274"],["9.617","0"],["9.611","23"],["9.566","0"],["9.560","112"],["9.515","0"],["9.509","47"],["9.464","0"],["9.458","290"],["9.413","0"],["9.407","318"],["9.362","0"],["9.356","326"],["9.311","0"],["9.305","106"],["9.260","0"],["9.254","193"],["9.209","0"],["9.203","376"],["9.158","0"],["9.152","231"],["9.107","0"],["9.101","4"],["9.056","0"],["9.050","149"],["9.005","0"],["8.999","85"],["8.954","0"],["8.948","320"],["8.903","0"],["8.897","61"],["8.852","0"],["8.846","131"],["8.801","0"],["8.795","477"],["8.750","0"],["8.744","367"],["8.699","0"],["8.693","253"],["8.648","0"],["8.642","83"],["8.597","0"],["8.591","48"]],"checksum":1193746478,"ts":"1649290095679"}]}
1649290095.709131: {"action":"update","arg":{"instType":"mc","channel":"trade","instId":"DASHUSDT"},"data":[["1649290095611","113.55","0.54","buy"]]}
1649290095.709161: {"action":"snapshot","arg":{"instType":"mc","channel":"ticker","instId":"DASHUSDT"},"data":[{"instId":"DASHUSDT","last":"113.500","bestAsk":"113.56","bestBid":"113.51","high24h":"118.870","low24h":"113.140","priceChangePercent":"-0.035","capitalRate":"-0.000100","nextSettleTime":1649314800000,"systemTime":1649290095674,"markPrice":"113.452","indexPrice":"113.478","holding":"21957.17","baseVolume":"25305.25","quoteVolume":"3062764.07"}]}
1649290095.7996259: {"action":"update","arg":{"instType":"mc","channel":"books","instId":"DASHUSDT"},"data":[{"asks":[["113.55","1.82"],["113.56","4.60"],["113.57","3.25"],["113.58","0.90"],["113.60","5.94"],["113.61","41.30"],["113.62","17.34"],["113.63","17.91"],["113.66","74.58"],["113.67","19.10"],["113.68","13.66"],["113.69","37.40"],["113.70","68.97"],["113.72","54.50"],["113.75","84.63"],["113.80","175.90"],["113.85","343.17"],["113.87","343.47"],["113.95","25.99"],["113.97","213.06"],["113.98","1802.67"],["113.99","365.36"],["114.00","145.42"],["114.01","100.12"],["114.02","23.48"],["114.03","1600.07"],["114.04","1957.86"],["114.05","0"],["114.06","0"],["114.07","0"],["114.08","0"],["114.10","2040.45"],["114.13","0"],["114.16","1863.98"],["114.19","0"],["114.22","1930.16"],["114.25","0"],["114.28","1974.27"],["114.31","0"],["114.34","2018.39"],["114.37","0"],["114.40","1731.63"],["114.43","0"],["114.46","1709.57"],["114.49","0"],["114.52","1797.80"],["114.55","0"],["114.58","1908.10"],["114.61","0"],["114.64","1753.69"],["114.67","0"],["114.70","1996.33"],["114.73","0"],["114.76","1819.86"],["114.79","0"],["114.82","1841.92"],["114.85","0"],["114.88","1886.04"],["114.91","0"]],"bids":[["113.53","0"],["113.52","0"],["113.51","0"],["113.50","0"],["113.49","35.65"],["113.48","46.64"],["113.47","0"],["113.46","44.71"],["113.43","29.98"],["113.40","23.54"],["113.34","41.13"],["113.33","17.13"],["113.31","149.38"],["113.28","23.75"],["113.26","115.65"],["113.23","125.11"],["113.21","48.77"],["113.18","60.20"],["113.10","1503.75"],["113.06","1980.07"],["113.04","59.36"],["113.03","97.40"],["113.02","41.80"],["113.01","68.77"],["113.00","2104.58"],["112.99","14.52"],["112.98","0"],["112.94","1908.10"],["112.92","0"],["112.88","1709.57"],["112.86","0"],["112.82","1974.27"],["112.80","0"],["112.76","1886.04"],["112.74","0"],["112.70","1863.98"],["112.68","0"],["112.64","2018.39"],["112.62","0"],["112.58","1753.69"],["112.56","0"],["112.52","1797.80"],["112.50","0"],["112.46","1841.92"],["112.44","0"],["112.40","1775.75"],["112.38","0"],["112.34","1819.86"],["112.32","0"],["112.28","1930.16"],["112.26","0"],["112.22","1731.63"],["112.20","0"],["112.16","1996.33"]],"checksum":-1463134623,"ts":"1649290095771"}]}
1649290095.950793: {"action":"snapshot","arg":{"instType":"mc","channel":"ticker","instId":"DASHUSDT"},"data":[{"instId":"DASHUSDT","last":"113.500","bestAsk":"113.55","bestBid":"113.49","high24h":"118.870","low24h":"113.140","priceChangePercent":"-0.035","capitalRate":"-0.000100","nextSettleTime":1649314800000,"systemTime":1649290095923,"markPrice":"113.452","indexPrice":"113.478","holding":"21957.17","baseVolume":"25305.25","quoteVolume":"3062764.07"}]}
1649290095.955214: {"action":"snapshot","arg":{"instType":"mc","channel":"ticker","instId":"UNIUSDT"},"data":[{"instId":"UNIUSDT","last":"9.9860","bestAsk":"9.987","bestBid":"9.982","high24h":"10.4280","low24h":"9.9030","priceChangePercent":"-0.0385","capitalRate":"-0.000100","nextSettleTime":1649314800000,"systemTime":1649290095921,"markPrice":"9.9846","indexPrice":"9.9942","holding":"369411","baseVolume":"313098","quoteVolume":"3294594"}]}
1649290096.0535119: {"action":"update","arg":{"instType":"mc","channel":"books","instId":"UNIUSDT"},"data":[{"asks":[["9.986","94"],["9.987","124"],["9.988","97"],["9.989","202"],["9.992","224"],["9.993","560"],["9.994","2594"],["9.995","641"],["9.996","808"],["9.997","542"],["9.998","462"],["9.999","650"],["10.000","480"],["10.001","936"],["10.002","2109"],["10.003","740"],["10.005","1388"],["10.006","1100"],["10.007","927"],["10.008","1048"],["10.012","660"],["10.015","636"],["10.016","432"],["10.018","173"],["10.021","150"],["10.022","890"],["10.023","4473"],["10.024","2075"],["10.029","8403"],["10.033","6262"],["10.034","13102"],["10.035","158"],["10.036","0"],["10.039","13174"],["10.040","0"],["10.044","13366"],["10.045","0"],["10.049","11828"],["10.050","0"],["10.054","11636"],["10.055","0"],["10.059","12982"],["10.060","0"],["10.064","11443"],["10.065","0"],["10.069","12597"],["10.070","0"],["10.074","12020"],["10.075","0"],["10.079","12405"],["10.080","0"],["10.084","12213"],["10.085","0"],["10.089","13559"],["10.090","0"],["10.091","0"],["10.137","231"],["10.142","0"],["10.189","255"],["10.193","0"],["10.241","44"],["10.244","0"],["10.293","159"],["10.295","0"],["10.345","242"],["10.346","0"],["10.397","86"],["10.448","0"],["10.449","123"],["10.499","0"],["10.501","170"],["10.551","0"],["10.553","223"],["10.602","0"],["10.605","323"],["10.653","0"],["10.657","333"],["10.704","0"],["10.709","52"],["10.755","0"],["10.761","163"],["10.806","0"],["10.813","17"],["10.857","0"],["10.865","144"],["10.908","0"],["10.917","162"],["10.959","0"],["10.969","368"],["11.010","0"],["11.021","356"],["11.061","0"],["11.073","84"],["11.112","0"],["11.125","325"],["11.163","0"],["11.177","114"],["11.214","0"],["11.229","236"],["11.265","0"],["11.281","167"],["11.333","98"],["11.385","134"],["11.437","247"],["11.489","171"]],"bids":[["9.982","0"],["9.980","184"],["9.979","219"],["9.978","35"],["9.977","55"],["9.976","111"],["9.975","1439"],["9.974","829"],["9.973","406"],["9.972","452"],["9.971","427"],["9.970","641"],["9.969","1248"],["9.968","488"],["9.967","176"],["9.966","250"],["9.965","464"],["9.964","677"],["9.962","139"],["9.961","2206"],["9.960","729"],["9.958","617"],["9.957","2331"],["9.956","910"],["9.955","494"],["9.954","914"],["9.953","1624"],["9.950","4081"],["9.945","989"],["9.942","1004"],["9.940","3876"],["9.938","395"],["9.934","3964"],["9.933","18778"],["9.932","1112"],["9.929","0"],["9.928","13174"],["9.924","0"],["9.923","13559"],["9.919","0"],["9.918","12982"],["9.914","0"],["9.913","11828"],["9.909","0"],["9.908","12597"],["9.904","0"],["9.903","12405"],["9.899","0"],["9.898","13366"],["9.894","0"],["9.893","12020"],["9.889","0"],["9.888","11636"],["9.884","0"],["9.883","12789"],["9.879","0"],["9.878","12213"],["9.765","0"],["9.759","351"],["9.714","0"],["9.708","399"],["9.663","0"],["9.657","274"],["9.611","0"],["9.605","23"],["9.560","0"],["9.554","112"],["9.509","0"],["9.503","47"],["9.458","0"],["9.452","290"],["9.407","0"],["9.401","318"],["9.356","0"],["9.350","326"],["9.305","0"],["9.299","106"],["9.254","0"],["9.248","193"],["9.203","0"],["9.197","376"],["9.152","0"],["9.146","231"],["9.101","0"],["9.095","4"],["9.050","0"],["9.044","149"],["8.999","0"],["8.993","85"],["8.948","0"],["8.942","320"],["8.897","0"],["8.891","61"],["8.846","0"],["8.840","131"],["8.795","0"],["8.789","477"],["8.744","0"],["8.738","367"],["8.693","0"],["8.687","253"],["8.642","0"],["8.636","83"],["8.591","0"],["8.585","48"]],"checksum":1024499808,"ts":"1649290096026"}]}
1649290096.097356: {"action":"update","arg":{"instType":"mc","channel":"books","instId":"DASHUSDT"},"data":[{"asks":[["113.54","20.63"],["113.55","4.30"],["113.56","3.06"],["113.57","17.62"],["113.58","0"],["113.60","2.30"],["113.61","41.99"],["113.62","9.85"],["113.64","35.79"],["113.65","106.11"],["113.66","81.77"],["113.68","11.19"],["113.69","36.70"],["113.70","81.95"],["113.74","7.87"],["113.77","680.06"],["113.78","658.05"],["113.80","162.82"],["113.82","40.62"],["113.85","338.82"],["113.97","2054.97"],["113.98","26.93"],["114.03","3398.24"],["114.04","5.65"],["114.09","1709.57"],["114.10","0"],["114.15","1775.75"],["114.16","0"],["114.21","1996.33"],["114.22","0"],["114.27","1974.27"],["114.28","0"],["114.33","2018.39"],["114.34","0"],["114.39","1886.04"],["114.40","0"],["114.45","2040.45"],["114.46","0"],["114.51","1930.16"],["114.52","0"],["114.57","1819.86"],["114.58","0"],["114.63","1731.63"],["114.64","0"],["114.69","1952.22"],["114.70","0"],["114.75","1908.10"],["114.76","0"],["114.81","1753.69"],["114.82","0"],["114.87","1863.98"],["114.88","0"],["115.78","0.73"],["116.00","0"],["116.37","68.26"],["116.59","0"],["116.96","70.90"],["117.18","0"],["117.55","49.89"],["117.77","0"],["118.14","22.59"],["118.36","0"],["118.73","47.85"],["118.95","0"],["119.32","46.71"],["119.54","0"],["119.91","23.57"],["120.13","0"],["120.50","59.15"],["120.72","0"],["121.09","6.51"],["121.31","0"],["121.68","54.25"],["121.90","0"],["122.27","14.99"],["122.49","0"],["122.86","11.21"],["123.08","0"],["123.45","66.50"],["123.67","0"],["124.04","64.47"],["124.26","0"],["124.63","42.85"],["124.85","0"],["125.22","29.99"],["125.44","0"],["125.81","4.07"],["126.03","0"],["126.40","26.70"],["126.62","0"],["126.99","20.67"],["127.21","0"],["127.58","56.99"],["127.80","0"],["128.17","44.01"],["128.39","0"],["128.76","46.60"],["128.98","0"],["129.35","39.07"],["129.57","0"],["129.94","19.33"],["130.16","0"],["130.53","20.66"],["130.75","0"],["131.12","28.11"],["131.34","0"],["131.71","13.65"],["131.93","0"],["132.52","0"],["133.11","0"],["133.70","0"]],"bids":[["113.49","30.70"],["113.48","23.87"],["113.47","65.35"],["113.46","86.14"],["113.44","3.85"],["113.43","28.71"],["113.42","36.40"],["113.41","6.87"],["113.38","8.79"],["113.34","14.98"],["113.32","16.41"],["113.29","8.63"],["113.28","35.04"],["113.27","23.08"],["113.24","174.25"],["113.22","13.36"],["113.16","170.58"],["113.13","43.14"],["113.08","77.01"],["113.06","1759.48"],["113.03","95.21"],["113.00","1906.05"],["112.99","0"],["112.94","1775.75"],["112.88","1974.27"],["112.82","1930.16"],["112.76","1996.33"],["112.64","1797.80"],["112.58","1908.10"],["112.52","1952.22"],["112.46","1753.69"],["112.40","2040.45"],["112.34","1709.57"],["112.28","1819.86"],["112.22","1886.04"],["112.16","2018.39"],["111.66","54.98"],["111.61","0"],["111.07","56.15"],["111.02","0"],["110.47","22.20"],["110.43","0"],["109.88","45.95"],["109.84","0"],["109.29","29.62"],["109.25","0"],["108.70","21.93"],["108.66","0"],["108.11","6.02"],["108.07","0"],["107.52","55.97"],["107.48","0"],["106.93","21.31"],["106.89","0"],["106.34","8.95"],["106.30","0"],["105.75","10.15"],["105.71","0"],["105.16","40.07"],["105.12","0"],["104.57","15.36"],["104.53","0"],["103.98","46.47"],["103.94","0"],["103.39","11.11"],["103.35","0"],["102.80","1.87"],["102.76","0"],["102.21","37.67"],["102.17","0"],["101.62","21.48"],["101.58","0"],["101.03","49.80"],["100.99","0"],["100.44","49.32"],["100.40","0"],["99.85","42.14"],["99.26","8.55"],["98.67","30.36"],["98.08","20.32"],["97.49","36.65"],["96.90","21.95"],["96.31","8.41"],["95.72","31.49"],["95.13","57.35"],["94.54","3.45"],["93.95","4.85"],["93.36","74.35"],["92.77","33.85"],["92.18","20.24"]],"checksum":1581919629,"ts":"1649290096070"}]}
1649290096.147427: {"action":"update","arg":{"instType":"mc","channel":"candle1m","instId":"DASHUSDT"},"data":[["1649290080000","113.37","113.55","113.37","113.55","3.9"]]}
1649290096.2038789: {"action":"snapshot","arg":{"instType":"mc","channel":"ticker","instId":"UNIUSDT"},"data":[{"instId":"UNIUSDT","last":"9.9860","bestAsk":"9.986","bestBid":"9.981","high24h":"10.4280","low24h":"9.9030","priceChangePercent":"-0.0385","capitalRate":"-0.000100","nextSettleTime":1649314800000,"systemTime":1649290096170,"markPrice":"9.9846","indexPrice":"9.9942","holding":"369411","baseVolume":"313098","quoteVolume":"3294594"}]}
1649290096.211294: {"action":"snapshot","arg":{"instType":"mc","channel":"ticker","instId":"DASHUSDT"},"data":[{"instId":"DASHUSDT","last":"113.550","bestAsk":"113.54","bestBid":"113.49","high24h":"118.870","low24h":"113.140","priceChangePercent":"-0.035","capitalRate":"-0.000100","nextSettleTime":1649314800000,"systemTime":1649290096179,"markPrice":"113.457","indexPrice":"113.478","holding":"21957.17","baseVolume":"25305.79","quoteVolume":"3062825.39"}]}
1649290096.354829: {"action":"update","arg":{"instType":"mc","channel":"books","instId":"UNIUSDT"},"data":[{"asks":[["9.986","37"],["9.987","164"],["9.992","270"],["9.993","433"],["9.994","2619"],["9.995","684"],["9.996","768"],["9.997","620"],["9.998","474"],["9.999","631"],["10.001","1139"],["10.002","2076"],["10.004","728"],["10.005","1368"],["10.008","1030"],["10.010","540"],["10.011","1860"],["10.012","666"],["10.013","1487"],["10.015","756"],["10.019","248"],["10.020","4345"],["10.022","451"],["10.034","11756"],["10.039","11636"],["10.044","12213"],["10.049","12982"],["10.054","12597"],["10.059","12789"],["10.064","12020"],["10.069","13174"],["10.074","13559"],["10.079","11828"],["10.084","13366"],["10.089","12405"],["10.130","231"],["10.137","0"],["10.182","255"],["10.189","0"],["10.234","44"],["10.241","0"],["10.286","159"],["10.293","0"],["10.338","242"],["10.345","0"],["10.390","86"],["10.397","0"],["10.442","123"],["10.449","0"],["10.494","170"],["10.501","0"],["10.546","223"],["10.553","0"],["10.598","323"],["10.605","0"],["10.650","333"],["10.657","0"],["10.702","52"],["10.709","0"],["10.754","163"],["10.761","0"],["10.806","17"],["10.813","0"],["10.858","144"],["10.865","0"],["10.910","162"],["10.917","0"],["10.962","368"],["10.969","0"],["11.014","356"],["11.021","0"],["11.066","84"],["11.073","0"],["11.118","325"],["11.125","0"],["11.170","114"],["11.177","0"],["11.222","236"],["11.229","0"],["11.274","167"],["11.281","0"],["11.326","98"],["11.333","0"],["11.378","134"],["11.385","0"],["11.430","247"],["11.437","0"],["11.482","171"],["11.489","0"]],"bids":[["9.980","144"],["9.979","233"],["9.977","65"],["9.976","180"],["9.974","803"],["9.972","542"],["9.971","421"],["9.970","596"],["9.967","170"],["9.966","233"],["9.965","506"],["9.964","511"],["9.963","828"],["9.961","2124"],["9.959","416"],["9.957","2642"],["9.956","613"],["9.952","552"],["9.949","723"],["9.946","2403"],["9.945","957"],["9.944","289"],["9.942","210"],["9.941","1987"],["9.938","225"],["9.933","20509"],["9.928","12405"],["9.923","12020"],["9.918","11828"],["9.913","11636"],["9.908","12213"],["9.903","11443"],["9.893","12789"],["9.888","13559"],["9.883","12597"],["9.878","12982"],["9.759","0"],["9.752","351"],["9.708","0"],["9.701","399"],["9.657","0"],["9.650","274"],["9.605","0"],["9.598","23"],["9.554","0"],["9.547","112"],["9.503","0"],["9.496","47"],["9.452","0"],["9.445","290"],["9.401","0"],["9.394","318"],["9.350","0"],["9.343","326"],["9.299","0"],["9.292","106"],["9.248","0"],["9.241","193"],["9.197","0"],["9.190","376"],["9.146","0"],["9.139","231"],["9.095","0"],["9.088","4"],["9.044","0"],["9.037","149"],["8.993","0"],["8.986","85"],["8.942","0"],["8.935","320"],["8.891","0"],["8.884","61"],["8.840","0"],["8.833","131"],["8.789","0"],["8.782","477"],["8.738","0"],["8.731","367"],["8.687","0"],["8.680","253"],["8.636","0"],["8.629","83"],["8.585","0"],["8.578","48"]],"checksum":-598015282,"ts":"1649290096326"}]}
1649290096.405191: {"action":"update","arg":{"instType":"mc","channel":"books","instId":"DASHUSDT"},"data":[{"asks":[["113.54","24.49"],["113.55","1.82"],["113.57","11.53"],["113.58","6.84"],["113.62","11.65"],["113.64","121.73"],["113.65","103.63"],["113.66","73.60"],["113.68","29.76"],["113.69","74.81"],["113.70","116.60"],["113.72","41.30"],["113.73","321.45"],["113.74","44.69"],["113.76","1476.53"],["113.78","439.10"],["113.79","39.75"],["113.80","79.17"],["113.82","43.59"],["113.85","332.88"],["113.94","297.29"],["113.95","11.14"],["113.97","2187.32"],["113.98","21.98"],["113.99","369.82"],["114.01","110.02"],["114.02","18.44"],["114.03","3618.86"],["114.04","0"],["114.09","1775.75"],["114.15","1908.10"],["114.21","1819.86"],["114.27","1863.98"],["114.33","1952.22"],["114.39","1996.33"],["114.45","1930.16"],["114.51","1841.92"],["114.57","1797.80"],["114.63","1753.69"],["114.69","2040.45"],["114.75","1886.04"],["114.81","1709.57"],["114.87","1731.63"]],"bids":[["113.49","99.01"],["113.48","20.41"],["113.47","138.61"],["113.43","42.12"],["113.42","99.01"],["113.40","43.57"],["113.39","16.69"],["113.38","7.28"],["113.37","131.73"],["113.36","26.32"],["113.35","276.01"],["113.34","6.09"],["113.33","14.22"],["113.32","175.30"],["113.29","11.66"],["113.28","32.86"],["113.25","40.02"],["113.24","16.35"],["113.21","57.34"],["113.17","16.84"],["113.09","8.48"],["113.06","1825.65"],["113.03","92.94"],["113.01","77.53"],["113.00","2082.52"],["112.94","1886.04"],["112.88","1731.63"],["112.82","1775.75"],["112.76","1819.86"],["112.70","1930.16"],["112.64","1908.10"],["112.58","1709.57"],["112.52","1863.98"],["112.46","1841.92"],["112.40","1974.27"],["112.34","1996.33"],["112.28","2040.45"],["112.22","1952.22"],["112.16","1753.69"]],"checksum":840212916,"ts":"1649290096375"}]}
1649290096.467445: {"action":"snapshot","arg":{"instType":"mc","channel":"ticker","instId":"DASHUSDT"},"data":[{"instId":"DASHUSDT","last":"113.550","bestAsk":"113.53","bestBid":"113.48","high24h":"118.870","low24h":"113.140","priceChangePercent":"-0.035","capitalRate":"-0.000100","nextSettleTime":1649314800000,"systemTime":1649290096436,"markPrice":"113.457","indexPrice":"113.478","holding":"21957.17","baseVolume":"25305.79","quoteVolume":"3062825.39"}]}
1649290096.467542: {"action":"snapshot","arg":{"instType":"mc","channel":"ticker","instId":"UNIUSDT"},"data":[{"instId":"UNIUSDT","last":"9.9860","bestAsk":"9.986","bestBid":"9.981","high24h":"10.4280","low24h":"9.9030","priceChangePercent":"-0.0385","capitalRate":"-0.000100","nextSettleTime":1649314800000,"systemTime":1649290096433,"markPrice":"9.9875","indexPrice":"9.9942","holding":"369411","baseVolume":"313098","quoteVolume":"3294594"}]}
1649290096.6736362: {"action":"update","arg":{"instType":"mc","channel":"books","instId":"UNIUSDT"},"data":[{"asks":[["9.985","75"],["9.986","71"],["9.987","166"],["9.988","98"],["9.990","246"],["9.991","188"],["9.992","200"],["9.993","699"],["9.994","2985"],["9.995","196"],["9.996","807"],["9.997","599"],["9.998","544"],["9.999","536"],["10.000","448"],["10.001","1097"],["10.002","1953"],["10.004","778"],["10.005","1374"],["10.006","1057"],["10.007","873"],["10.008","238"],["10.011","1509"],["10.015","937"],["10.021","279"],["10.022","884"],["10.027","6717"],["10.033","14876"],["10.034","11"],["10.035","0"],["10.038","11636"],["10.039","0"],["10.043","11828"],["10.044","0"],["10.048","13366"],["10.049","0"],["10.053","12020"],["10.054","0"],["10.058","12982"],["10.059","0"],["10.063","12597"],["10.064","0"],["10.068","13174"],["10.069","0"],["10.073","13559"],["10.074","0"],["10.078","12213"],["10.079","0"],["10.083","12789"],["10.084","0"],["10.088","11443"],["10.089","0"],["10.125","231"],["10.130","0"],["10.177","255"],["10.182","0"],["10.229","44"],["10.234","0"],["10.281","159"],["10.286","0"],["10.333","242"],["10.338","0"],["10.385","86"],["10.390","0"],["10.437","123"],["10.442","0"],["10.489","170"],["10.494","0"],["10.541","223"],["10.546","0"],["10.593","323"],["10.598","0"],["10.645","333"],["10.650","0"],["10.697","52"],["10.702","0"],["10.749","163"],["10.754","0"],["10.801","17"],["10.806","0"],["10.853","144"],["10.858","0"],["10.905","162"],["10.910","0"],["10.957","368"],["10.962","0"],["11.009","356"],["11.014","0"],["11.061","84"],["11.066","0"],["11.113","325"],["11.118","0"],["11.165","114"],["11.170","0"],["11.217","236"],["11.222","0"],["11.269","167"],["11.274","0"],["11.321","98"],["11.326","0"],["11.373","134"],["11.378","0"],["11.425","247"],["11.430","0"],["11.477","171"],["11.482","0"]],"bids":[["9.981","0"],["9.980","451"],["9.979","245"],["9.977","108"],["9.976","140"],["9.975","1147"],["9.973","175"],["9.972","494"],["9.971","509"],["9.970","572"],["9.968","563"],["9.967","203"],["9.966","111"],["9.965","207"],["9.964","593"],["9.963","779"],["9.962","155"],["9.961","2024"],["9.960","696"],["9.959","444"],["9.957","2281"],["9.956","758"],["9.954","185"],["9.953","1579"],["9.951","946"],["9.947","321"],["9.944","436"],["9.943","203"],["9.933","7336"],["9.932","13032"],["9.931","3583"],["9.928","0"],["9.927","11443"],["9.923","0"],["9.922","12789"],["9.918","0"],["9.917","12405"],["9.913","0"],["9.912","13559"],["9.908","0"],["9.907","11636"],["9.903","0"],["9.902","11828"],["9.898","0"],["9.897","13174"],["9.893","0"],["9.892","12597"],["9.888","0"],["9.887","12020"],["9.883","0"],["9.882","13366"],["9.878","0"],["9.877","12982"],["9.752","0"],["9.747","351"],["9.701","0"],["9.696","399"],["9.650","0"],["9.645","274"],["9.598","0"],["9.593","23"],["9.547","0"],["9.542","112"],["9.496","0"],["9.491","47"],["9.445","0"],["9.440","290"],["9.394","0"],["9.389","318"],["9.343","0"],["9.338","326"],["9.292","0"],["9.287","106"],["9.241","0"],["9.236","193"],["9.190","0"],["9.185","376"],["9.139","0"],["9.134","231"],["9.088","0"],["9.083","4"],["9.037","0"],["9.032","149"],["8.986","0"],["8.981","85"],["8.935","0"],["8.930","320"],["8.884","0"],["8.879","61"],["8.833","0"],["8.828","131"],["8.782","0"],["8.777","477"],["8.731","0"],["8.726","367"],["8.680","0"],["8.675","253"],["8.629","0"],["8.624","83"],["8.578","0"],["8.573","48"]],"checksum":-1392891444,"ts":"1649290096643"}]}
1649290096.705301: {"action":"update","arg":{"instType":"mc","channel":"books","instId":"DASHUSDT"},"data":[{"asks":[["113.50","0.74"],["113.51","6.52"],["113.52","17.78"],["113.53","12.10"],["113.54","55.60"],["113.55","3.31"],["113.57","11.89"],["113.58","10.84"],["113.59","7.31"],["113.60","33.87"],["113.61","27.52"],["113.62","22.87"],["113.64","93.55"],["113.66","26.74"],["113.67","22.27"],["113.68","7.04"],["113.69","50.34"],["113.70","115.38"],["113.72","41.28"],["113.73","207.89"],["113.74","14.30"],["113.76","1476.86"],["113.77","833.82"],["113.79","37.08"],["113.80","151.95"],["113.82","34.08"],["113.84","260.64"],["113.87","343.68"],["113.91","188.16"],["113.92","146.96"],["113.93","1973.84"],["113.97","213.06"],["113.98","12.22"],["113.99","2141.10"],["114.00","0"],["114.01","0"],["114.02","0"],["114.03","0"],["114.05","2040.45"],["114.09","0"],["114.11","1731.63"],["114.15","0"],["114.17","1930.16"],["114.21","0"],["114.23","1819.86"],["114.27","0"],["114.29","1974.27"],["114.33","0"],["114.35","1886.04"],["114.39","0"],["114.41","2018.39"],["114.45","0"],["114.47","1996.33"],["114.51","0"],["114.53","1952.22"],["114.57","0"],["114.59","1709.57"],["114.63","0"],["114.65","1841.92"],["114.69","0"],["114.71","1863.98"],["114.75","0"],["114.77","1753.69"],["114.81","0"],["114.83","1797.80"],["114.87","0"],["115.78","0"],["116.00","31.47"],["116.37","0"],["116.59","50.46"],["116.96","0"],["117.18","49.40"],["117.55","0"],["117.77","27.41"],["118.14","0"],["118.36","50.42"],["118.73","0"],["118.95","50.07"],["119.32","0"],["119.54","36.12"],["119.91","0"],["120.13","8.62"],["120.50","0"],["120.72","54.60"],["121.09","0"],["121.31","1.48"],["121.68","0"],["121.90","43.49"],["122.27","0"],["122.49","7.73"],["122.86","0"],["123.08","58.21"],["123.45","0"],["123.67","52.67"],["124.04","0"],["124.26","53.84"],["124.63","0"],["124.85","4.99"],["125.22","0"],["125.44","44.04"],["125.81","0"],["126.03","25.10"],["126.40","0"],["126.62","39.09"],["126.99","0"],["127.21","44.51"],["127.58","0"],["127.80","19.01"],["128.17","0"],["128.39","29.39"],["128.76","0"],["128.98","3.89"],["129.35","0"],["129.57","23.37"],["129.94","0"],["130.16","24.18"],["130.53","0"],["130.75","9.15"],["131.12","0"],["131.34","27.04"],["131.71","0"],["131.93","7.10"],["132.52","13.38"],["133.11","33.57"],["133.70","76.51"]],"bids":[["113.49","0"],["113.48","0"],["113.47","0"],["113.46","0"],["113.44","0"],["113.43","55.56"],["113.41","9.91"],["113.39","32.68"],["113.38","5.53"],["113.37","119.96"],["113.36","24.07"],["113.35","533.62"],["113.34","7.26"],["113.33","13.99"],["113.32","174.66"],["113.31","150.37"],["113.28","29.83"],["113.26","112.70"],["113.25","41.68"],["113.24","17.05"],["113.23","124.39"],["113.22","12.18"],["113.21","58.54"],["113.18","55.95"],["113.16","168.64"],["113.13","39.10"],["113.10","1501.59"],["113.06","27.86"],["113.04","60.52"],["113.03","93.85"],["113.02","1927.43"],["113.01","68.77"],["113.00","64.14"],["112.99","19.05"],["112.98","524.97"],["112.97","161.31"],["112.96","1921.88"],["112.95","324.22"],["112.94","0"],["112.90","1709.57"],["112.88","0"],["112.84","1952.22"],["112.82","0"],["112.78","1930.16"],["112.76","0"],["112.72","1819.86"],["112.70","0"],["112.66","1753.69"],["112.64","0"],["112.60","2018.39"],["112.58","0"],["112.54","1996.33"],["112.52","0"],["112.48","1974.27"],["112.46","0"],["112.42","1797.80"],["112.40","0"],["112.36","2040.45"],["112.34","0"],["112.30","1908.10"],["112.28","0"],["112.24","1863.98"],["112.22","0"],["112.18","1775.75"],["112.16","0"],["112.12","1841.92"],["111.66","0"],["111.61","44.63"],["111.07","0"],["111.02","97.81"],["110.47","0"],["110.43","40.49"],["109.88","0"],["109.84","85.27"],["109.29","0"],["109.25","84.73"],["108.70","0"],["108.66","59.74"],["108.11","0"],["108.07","61.13"],["107.52","0"],["107.48","33.01"],["106.93","0"],["106.89","56.85"],["106.34","0"],["106.30","24.34"],["105.75","0"],["105.71","1.74"],["105.16","0"],["105.12","57.94"],["104.57","0"],["104.53","58.21"],["103.98","0"],["103.94","46.12"],["103.39","0"],["103.35","52.32"],["102.80","0"],["102.76","45.29"],["102.21","0"],["102.17","22.94"],["101.62","0"],["101.58","36.02"],["101.03","0"],["100.99","38.02"],["100.44","0"],["100.40","53.60"],["99.85","0"],["99.26","0"],["98.67","0"],["98.08","0"],["97.49","0"],["96.90","0"],["96.31","0"],["95.72","0"],["95.13","0"],["94.54","0"],["93.95","0"],["93.36","0"],["92.77","0"],["92.18","0"]],"checksum":204565512,"ts":"1649290096677"}]}
