1649290086.136957: {"action":"snapshot","arg":{"instType":"sp","channel":"ticker","instId":"EOSUSDT"},"data":[{"instId":"EOSUSDT","last":"2.4421","open24h":"2.5667","high24h":"2.5767","low24h":"2.4155","bestBid":"2.437300","bestAsk":"2.441500","baseVolume":"145520.9144","quoteVolume":"378713.0030","ts":1649290086089,"labeId":0}]}
1649290086.137048: {"action":"update","arg":{"instType":"sp","channel":"trade","instId":"EOSUSDT"},"data":[["1649290086022","2.4393","2.0499","buy"]]}
1649290086.164576: {"action":"update","arg":{"instType":"sp","channel":"books","instId":"GOGUSDT"},"data":[{"asks":[["0.5637","13.0000"],["0.5649","8.8521"],["0.5655","2348.1333"],["0.5661","15.6667"],["0.5667","8.8240"],["0.5673","10.3333"],["0.5679","11.0000"],["0.5685","8.7961"],["0.5697","8.7775"],["0.5703","8.7683"],["0.5709","9.6667"],["0.5715","15.0000"],["0.5721","13.6667"],["0.5727","12.3333"],["0.5733","16.3333"],["0.5739","11.6667"]],"bids":[["0.5512","14.4000"],["0.5500","9.6667"],["0.5494","9.1018"],["0.5482","3682.2333"],["0.5476","9.1318"],["0.5470","9.1418"],["0.5464","14.3333"],["0.5458","15.6667"],["0.5446","13.6667"],["0.5440","11.6667"],["0.5434","10.3333"],["0.5422","11.0000"],["0.5416","15.0000"],["0.5410","12.3333"],["0.5404","9.2534"]],"checksum":-1629979182,"ts":"1649290086143"}]}
1649290086.252129: {"action":"update","arg":{"instType":"sp","channel":"books","instId":"VVSUSDT"},"data":[{"asks":[["0.00002370","616959.1000"],["0.00002379","371345.0000"],["0.00002382","494152.0000"],["0.00002385","657894.7000"],["0.00002391","412280.7000"],["0.00002397","903508.8000"],["0.00002403","862573.1000"],["0.00002406","576023.4000"],["0.00002409","698830.4000"]],"bids":[["0.00002267","412280.7000"],["0.00002261","862573.1000"],["0.00002258","739766.1000"],["0.00002255","371345.0000"],["0.00002252","222025.9000"],["0.00002249","453216.4000"],["0.00002243","576023.4000"],["0.00002240","330409.4000"],["0.00002237","535087.7000"],["0.00002234","698830.4000"],["0.00002231","780701.8000"],["0.00002228","616959.1000"]],"checksum":6308146,"ts":"1649290086226"}]}
1649290086.304647: {"action":"update","arg":{"instType":"sp","channel":"books","instId":"HOTUSDT"},"data":[{"asks":[["0.0056300","155121.3000"],["0.0056310","424383.7500"],["0.0056340","51931.3500"],["0.0056350","339029.1000"],["0.0059030","8250.0000"],["0.0059090","12250.0000"],["0.0059150","9250.0000"],["0.0059210","3750.0000"],["0.0059330","5250.0000"],["0.0059390","4250.0000"],["0.0059450","11250.0000"],["0.0059510","10250.0000"],["0.0059570","6750.0000"],["0.0059690","9750.0000"],["0.0059750","7750.0000"],["0.0059810","10750.0000"],["0.0059870","7250.0000"],["0.0059930","11750.0000"],["0.0059990","3250.0000"],["0.0060050","4750.0000"],["0.0060110","5750.0000"],["0.0060170","6250.0000"]],"bids":[["0.0056060","187367.4000"],["0.0056040","800000.0000"],["0.0053390","10750.0000"],["0.0053330","11250.0000"],["0.0053270","5250.0000"],["0.0053150","4250.0000"],["0.0053090","6250.0000"],["0.0053030","9250.0000"],["0.0052970","8250.0000"],["0.0052910","8750.0000"],["0.0052850","11750.0000"],["0.0052790","5750.0000"],["0.0052730","3250.0000"],["0.0052670","3750.0000"],["0.0052610","10250.0000"],["0.0052550","4750.0000"],["0.0052490","6750.0000"],["0.0052430","12250.0000"],["0.0052370","7750.0000"],["0.0052310","9750.0000"],["0.0052250","2750.0000"]],"checksum":-406928751,"ts":"1649290086282"}]}
1649290086.345885: {"action":"update","arg":{"instType":"sp","channel":"books","instId":"CULTUSDT"},"data":[{"asks":[["0.00003614","493333"],["0.00003618","280000"],["0.00003622","173333"],["0.00003626","333333"],["0.00003630","546667"],["0.00003634","626667"],["0.00003638","306667"],["0.00003642","386667"],["0.00003650","200000"],["0.00003654","466667"],["0.00003658","520000"],["0.00003662","653333"],["0.00003666","253333"],["0.00003670","226667"],["0.00003674","573333"],["0.00003678","146667"],["0.00003682","413333"],["0.00003686","360000"],["0.00003690","440000"]],"bids":[["0.00003471","653333"],["0.00003467","1715230"],["0.00003463","306667"],["0.00003459","280000"],["0.00003455","748154"],["0.00003451","226667"],["0.00003447","600000"],["0.00003443","493333"],["0.00003439","413333"],["0.00003435","333333"],["0.00003431","253333"],["0.00003427","466667"],["0.00003423","546667"],["0.00003419","520000"],["0.00003415","173333"],["0.00003411","146667"],["0.00003407","626667"],["0.00003395","386667"]],"checksum":-1471297980,"ts":"1649290086320"}]}
1649290086.367917: {"action":"update","arg":{"instType":"sp","channel":"books","instId":"AVAXUSDT"},"data":[{"asks":[["83.1115","70.1330"],["83.1315","46.0040"],["83.1515","115.8920"],["87.9959","0.3167"],["88.0790","0.5167"],["88.1621","0.5833"],["88.2452","0.6500"],["88.3283","0.7500"],["88.4114","0.3500"],["88.4945","0.4500"],["88.5776","0.6167"],["88.6607","0.7167"],["88.7438","0.2500"],["88.8269","0.8167"],["88.9100","0.3833"],["88.9931","0.2167"],["89.0762","0.4833"],["89.2424","0.7833"],["89.3255","0.4167"],["89.4086","0.1833"],["89.4917","0.6833"],["89.5748","0.2833"]],"bids":[["82.9185","7.1470"],["82.7985","178.1080"],["82.6785","174.7760"],["82.6085","38.1080"],["82.5985","104.7830"],["82.5885","8.5750"],["82.5785","22.0220"],["82.5485","104.0830"],["82.5385","143.5980"],["82.4985","15.5190"],["78.0341","0.4500"],["77.9510","0.7167"],["77.8679","0.6833"],["77.7017","0.8167"],["77.6186","0.2167"],["77.5355","0.5833"],["77.4524","0.6167"],["77.3693","0.3167"],["77.2862","0.7500"],["77.2031","0.5167"],["77.1200","0.7833"],["77.0369","0.2833"],["76.9538","0.2500"],["76.8707","0.5500"],["76.7876","0.3833"],["76.7045","0.4833"],["76.6214","0.6500"],["76.5383","0.3500"],["76.4552","0.1833"]],"checksum":64040310,"ts":"1649290086345"}]}
1649290086.376587: {"action":"update","arg":{"instType":"sp","channel":"books","instId":"STGUSDT"},"data":[{"asks":[["2.945","31.262"],["3.034","1.649"],["3.037","1.647"],["3.040","1.793"],["3.046","3.442"],["3.049","3.964"],["3.052","2.301"],["3.055","2.554"],["3.058","1.667"],["3.061","2.174"],["3.064","2.428"],["3.067","3.062"],["3.076","2.047"],["3.079","4.570"],["3.082","1.920"],["3.085","1.622"],["3.088","1.620"],["3.091","2.935"],["3.094","3.315"],["3.097","2.681"],["3.100","3.569"],["3.563","0"]],"bids":[["2.738","19.106"],["2.732","99.854"],["2.729","2.108"],["2.726","75.036"],["2.723","1.837"],["2.720","2.754"],["2.717","1.841"],["2.714","2.646"],["2.711","1.845"],["2.705","3.077"],["2.702","1.851"],["2.699","2.862"],["2.696","94.677"],["2.693","2.969"],["2.690","2.431"],["2.684","3.185"],["2.681","2.000"],["2.678","1.892"],["2.675","1.870"],["2.672","2.538"]],"checksum":-752622713,"ts":"1649290086354"}]}
1649290086.402696: {"action":"update","arg":{"instType":"sp","channel":"candle1m","instId":"EOSUSDT"},"data":[["1649290080000","2.4383","2.4421","2.4383","2.4393","4.1201"]]}
1649290086.426807: {"action":"update","arg":{"instType":"sp","channel":"trade","instId":"CULTUSDT"},"data":[["1649290086337","0.00003508","233570","buy"]]}
1649290086.438411: {"action":"update","arg":{"instType":"sp","channel":"candle1m","instId":"AVAXUSDT"},"data":[["1649290080000","83.1253","83.1253","82.9972","82.9972","0.0603"]]}
1649290086.54119: {"action":"snapshot","arg":{"instType":"sp","channel":"ticker","instId":"AVAXUSDT"},"data":[{"instId":"AVAXUSDT","last":"82.9972","open24h":"85.1099","high24h":"86.7605","low24h":"82.5893","bestBid":"82.918500","bestAsk":"83.111500","baseVolume":"3330.7812","quoteVolume":"287728.8336","ts":1649290086491,"labeId":0}]}
1649290086.591427: {"action":"update","arg":{"instType":"sp","channel":"books","instId":"EOSUSDT"},"data":[{"asks":[["2.4415","0"],["2.4419","1560.6900"],["2.4420","0"],["2.4422","236.2500"],["2.4423","110.9482"],["2.4424","8.8571"],["2.4428","193.7551"],["2.4430","13.0640"],["2.4432","988.1596"],["2.4433","1332.6930"],["2.4434","438.8892"],["2.4436","113.9145"],["2.4438","1101.6167"],["2.4439","2919.7820"],["2.4440","640.2441"],["2.4442","2952.9000"],["2.4443","856.8000"],["2.4444","477.1182"],["2.4445","28.0029"],["2.4448","718.3398"],["2.4449","1709.5016"],["2.4451","783.0000"],["2.4452","1494.7178"],["2.4454","2363.8500"],["2.4455","2781.5115"],["2.4457","2411.5143"],["2.4459","2128.3277"],["2.4466","366.6000"],["2.4468","239.6998"],["2.4469","2382.6763"],["2.4472","1583.3285"],["2.4473","453.3942"],["2.4565","0"],["2.4568","464.2857"],["2.4570","0"],["2.4573","473.8095"],["2.4575","0"],["2.4578","507.1429"],["2.4580","0"],["2.4583","526.1905"],["2.4585","0"],["2.4588","469.0476"],["2.4590","0"],["2.4593","511.9048"],["2.4595","0"],["2.4598","540.4762"],["2.4600","0"],["2.4603","488.0952"],["2.4605","0"],["2.4608","497.6190"],["2.4610","0"],["2.4613","478.5714"],["2.4615","0"],["2.4618","521.4286"],["2.4620","0"],["2.4623","545.2381"],["2.4625","0"],["2.4628","492.8571"],["2.4630","0"],["2.4633","530.9524"],["2.4635","0"],["2.4638","502.3810"],["2.4640","0"],["2.4643","459.5238"],["2.4645","0"],["2.4648","516.6667"],["2.4650","50.0000"],["2.4653","483.3333"],["2.4655","0"],["2.4658","535.7143"],["2.4660","0"],["2.4663","454.7619"]],"bids":[["2.4374","2957.6653"],["2.4372","2295.4846"],["2.4370","1190.5464"],["2.4369","35.0100"],["2.4368","45.8839"],["2.4366","1036.9787"],["2.4364","1126.9174"],["2.4363","196.8068"],["2.4360","436.4562"],["2.4359","955.4881"],["2.4358","450.8656"],["2.4357","2729.0759"],["2.4356","1729.8330"],["2.4355","160.5451"],["2.4354","729.4783"],["2.4353","324.9136"],["2.4352","35.5959"],["2.4351","1612.0348"],["2.4350","351.2250"],["2.4348","1130.1526"],["2.4347","25.1295"],["2.4345","1482.2048"],["2.4344","1008.5359"],["2.4343","1409.0786"],["2.4342","724.3210"],["2.4340","314.6348"],["2.4338","277.7243"],["2.4336","1344.1695"],["2.4335","5021.4304"],["2.4330","602.4655"],["2.4324","0"],["2.4323","0"],["2.4321","0"],["2.4320","0"],["2.4225","483.3333"],["2.4223","0"],["2.4220","507.1429"],["2.4218","0"],["2.4215","454.7619"],["2.4213","0"],["2.4210","469.0476"],["2.4208","0"],["2.4205","488.0952"],["2.4203","0"],["2.4200","521.4286"],["2.4198","0"],["2.4195","530.9524"],["2.4193","0"],["2.4190","473.8095"],["2.4188","0"],["2.4185","526.1905"],["2.4183","0"],["2.4180","516.6667"],["2.4178","0"],["2.4175","545.2381"],["2.4173","0"],["2.4170","464.2857"],["2.4168","0"],["2.4165","540.4762"],["2.4163","0"],["2.4160","535.7143"],["2.4158","0"],["2.4155","502.3810"],["2.4153","0"],["2.4150","511.9048"],["2.4148","0"],["2.4145","459.5238"],["2.4143","0"],["2.4140","492.8571"],["2.4138","0"],["2.4135","497.6190"],["2.4133","0"],["2.4130","478.5714"],["2.4128","0"]],"checksum":115617508,"ts":"1649290086569"}]}
1649290086.597752: {"action":"update","arg":{"instType":"sp","channel":"books","instId":"SUNUSDT"},"data":[{"asks":[["0.01510","25210"],["0.01511","647704"],["0.01512","445322"],["0.01516","7762"],["0.01523","2035"],["0.01566","0"],["0.01582","2167"],["0.01584","6833"],["0.01586","3833"],["0.01588","3167"],["0.01590","4833"],["0.01592","8167"],["0.01596","6167"],["0.01598","5500"],["0.01600","5167"],["0.01602","4167"],["0.01604","2833"],["0.01606","6500"],["0.01608","5833"],["0.01610","3500"],["0.01612","7167"],["0.01616","7833"],["0.01618","4500"],["0.01620","1833"]],"bids":[["0.01501","566953"],["0.01498","104473"],["0.01486","11602"],["0.01430","2500"],["0.01428","7167"],["0.01426","1833"],["0.01424","7500"],["0.01422","5833"],["0.01420","2167"],["0.01418","3167"],["0.01416","4833"],["0.01414","5500"],["0.01412","2833"],["0.01410","3833"],["0.01408","6500"],["0.01406","3500"],["0.01404","6833"],["0.01402","8167"],["0.01400","7833"],["0.01398","4167"],["0.01396","5167"],["0.01394","6167"],["0.01392","4500"]],"checksum":1626407278,"ts":"1649290086573"}]}
1649290086.606348: {"action":"snapshot","arg":{"instType":"sp","channel":"ticker","instId":"VVSUSDT"},"data":[{"instId":"VVSUSDT","last":"0.00002319","open24h":"0.00002350","high24h":"0.00002359","low24h":"0.00002313","bestBid":"0.000024","bestAsk":"0.000024","baseVolume":"2375367050.9083","quoteVolume":"56984.8991","ts":1649290086556,"labeId":0}]}
1649290086.659186: {"action":"snapshot","arg":{"instType":"sp","channel":"ticker","instId":"GOGUSDT"},"data":[{"instId":"GOGUSDT","last":"0.5575","open24h":"0.5563","high24h":"0.5708","low24h":"0.5508","bestBid":"0.554700","bestAsk":"0.559000","baseVolume":"134638.2253","quoteVolume":"78741.7865","ts":1649290086609,"labeId":0}]}
1649290086.670021: {"action":"snapshot","arg":{"instType":"sp","channel":"ticker","instId":"HOTUSDT"},"data":[{"instId":"HOTUSDT","last":"0.0056130","open24h":"0.0058560","high24h":"0.0059320","low24h":"0.0055520","bestBid":"0.005613","bestAsk":"0.005629","baseVolume":"10203207.8809","quoteVolume":"60796.5347","ts":1649290086617,"labeId":0}]}
1649290086.698486: {"action":"snapshot","arg":{"instType":"sp","channel":"ticker","instId":"SUNUSDT"},"data":[{"instId":"SUNUSDT","last":"0.01505","open24h":"0.01521","high24h":"0.01559","low24h":"0.01481","bestBid":"0.015040","bestAsk":"0.015080","baseVolume":"11683781","quoteVolume":"180235","ts":1649290086650,"labeId":0}]}
1649290086.701691: {"action":"update","arg":{"instType":"sp","channel":"books","instId":"GOGUSDT"},"data":[{"asks":[["0.5631","13.6667"],["0.5637","12.3333"],["0.5643","15.0000"],["0.5649","13.0000"],["0.5655","2345.4667"],["0.5673","8.8147"],["0.5679","8.8054"],["0.5691","10.3333"],["0.5697","9.0000"],["0.5703","9.6667"],["0.5709","16.3333"],["0.5715","8.7499"],["0.5721","14.3333"],["0.5727","8.7316"],["0.5733","11.0000"],["0.5739","8.7133"]],"bids":[["0.5512","15.7333"],["0.5506","13.6667"],["0.5500","10.3333"],["0.5494","13.0000"],["0.5482","3670.9000"],["0.5464","9.1518"],["0.5458","9.1619"],["0.5452","12.3333"],["0.5446","9.1821"],["0.5440","15.6667"],["0.5434","9.2023"],["0.5428","11.0000"],["0.5422","9.2227"],["0.5416","16.3333"],["0.5410","15.0000"],["0.5404","11.6667"],["0.5398","9.6667"]],"checksum":-1198274110,"ts":"1649290086679"}]}
1649290086.72624: {"action":"snapshot","arg":{"instType":"sp","channel":"ticker","instId":"STGUSDT"},"data":[{"instId":"STGUSDT","last":"2.881","open24h":"3.045","high24h":"3.164","low24h":"2.757","bestBid":"2.861000","bestAsk":"2.917000","baseVolume":"35327.890","quoteVolume":"111744.124","ts":1649290086674,"labeId":0}]}
1649290086.730182: {"action":"snapshot","arg":{"instType":"sp","channel":"ticker","instId":"CULTUSDT"},"data":[{"instId":"CULTUSDT","last":"0.00003508","open24h":"0.00004340","high24h":"0.00004397","low24h":"0.00003500","bestBid":"0.000036","bestAsk":"0.000036","baseVolume":"13526772930","quoteVolume":"557436","ts":1649290086686,"labeId":0}]}
1649290086.76339: {"action":"update","arg":{"instType":"sp","channel":"books","instId":"VVSUSDT"},"data":[{"asks":[["0.00002370","535087.7000"],["0.00002373","210704.8000"],["0.00002379","453216.4000"],["0.00002385","862573.1000"],["0.00002391","330409.4000"],["0.00002397","821637.4000"],["0.00002403","412280.7000"],["0.00002406","780701.8000"],["0.00002409","289473.7000"]],"bids":[["0.00002267","698830.4000"],["0.00002261","903508.8000"],["0.00002258","248538.0000"],["0.00002255","780701.8000"],["0.00002252","616959.1000"],["0.00002249","494152.0000"],["0.00002243","453216.4000"],["0.00002240","412280.7000"],["0.00002237","289473.7000"],["0.00002234","821637.4000"],["0.00002231","535087.7000"],["0.00002228","657894.7000"]],"checksum":419819997,"ts":"1649290086736"}]}
1649290086.8720589: {"action":"update","arg":{"instType":"sp","channel":"books","instId":"HOTUSDT"},"data":[{"asks":[["0.0056280","5580.0000"],["0.0056340","51133.0500"],["0.0056350","339829.6500"],["0.0056410","106127.1000"],["0.0056420","116663.4000"],["0.0056650","32050.8000"],["0.0056740","14297.4000"],["0.0056820","0"],["0.0056830","0"],["0.0059010","7750.0000"],["0.0059030","0"],["0.0059070","4250.0000"],["0.0059090","0"],["0.0059130","9250.0000"],["0.0059150","0"],["0.0059190","9750.0000"],["0.0059210","0"],["0.0059250","3750.0000"],["0.0059270","0"],["0.0059310","8250.0000"],["0.0059330","0"],["0.0059370","10750.0000"],["0.0059390","0"],["0.0059430","12250.0000"],["0.0059450","0"],["0.0059490","4750.0000"],["0.0059510","0"],["0.0059550","11750.0000"],["0.0059570","0"],["0.0059610","6750.0000"],["0.0059630","0"],["0.0059670","5750.0000"],["0.0059690","0"],["0.0059730","8750.0000"],["0.0059750","0"],["0.0059790","7250.0000"],["0.0059810","0"],["0.0059850","3250.0000"],["0.0059870","0"],["0.0059910","10250.0000"],["0.0059930","0"],["0.0059970","11250.0000"],["0.0059990","0"],["0.0060030","5250.0000"],["0.0060050","0"],["0.0060090","2750.0000"],["0.0060110","0"],["0.0060150","6250.0000"],["0.0060170","0"]],"bids":[["0.0056130","0"],["0.0056120","0"],["0.0056090","61122.1500"],["0.0056070","92227.0500"],["0.0056060","186566.8500"],["0.0056010","800000.0000"],["0.0055980","79473.6000"],["0.0055970","437721.3000"],["0.0055830","41030.6900"],["0.0055760","94140.9000"],["0.0055670","31311.9000"],["0.0055560","800000.0000"],["0.0055550","182157.3000"],["0.0053390","0"],["0.0053380","3250.0000"],["0.0053330","0"],["0.0053320","11750.0000"],["0.0053270","0"],["0.0053260","4250.0000"],["0.0053210","0"],["0.0053200","9250.0000"],["0.0053150","0"],["0.0053140","8750.0000"],["0.0053090","0"],["0.0053080","2750.0000"],["0.0053030","0"],["0.0053020","7750.0000"],["0.0052970","0"],["0.0052960","11250.0000"],["0.0052910","0"],["0.0052900","5750.0000"],["0.0052850","0"],["0.0052840","9750.0000"],["0.0052790","0"],["0.0052780","6750.0000"],["0.0052730","0"],["0.0052720","8250.0000"],["0.0052670","0"],["0.0052660","7250.0000"],["0.0052610","0"],["0.0052600","6250.0000"],["0.0052550","0"],["0.0052540","3750.0000"],["0.0052490","0"],["0.0052480","4750.0000"],["0.0052430","0"],["0.0052420","10250.0000"],["0.0052370","0"],["0.0052360","12250.0000"],["0.0052310","0"],["0.0052300","5250.0000"],["0.0052250","0"],["0.0052240","10750.0000"]],"checksum":-214167344,"ts":"1649290086848"}]}
1649290086.9064572: {"action":"update","arg":{"instType":"sp","channel":"books","instId":"STGUSDT"},"data":[{"asks":[["3.037","1.667"],["3.040","3.315"],["3.043","2.301"],["3.046","1.642"],["3.049","4.218"],["3.052","2.808"],["3.055","1.793"],["3.058","3.188"],["3.061","2.681"],["3.064","2.174"],["3.067","1.631"],["3.070","2.428"],["3.073","2.935"],["3.076","1.626"],["3.079","5.077"],["3.082","1.623"],["3.085","3.569"],["3.088","3.442"],["3.091","2.554"],["3.094","1.617"],["3.097","2.047"],["3.100","3.062"]],"bids":[["2.744","2.538"],["2.738","18.890"],["2.732","99.962"],["2.726","76.113"],["2.723","2.754"],["2.720","2.862"],["2.717","1.892"],["2.714","2.969"],["2.711","2.323"],["2.708","3.077"],["2.705","1.849"],["2.699","1.854"],["2.696","93.385"],["2.693","1.858"],["2.690","1.860"],["2.687","2.215"],["2.684","1.864"],["2.681","2.646"],["2.678","1.868"],["2.672","3.185"]],"checksum":-2028530316,"ts":"1649290086870"}]}
1649290086.922355: {"action":"update","arg":{"instType":"sp","channel":"books","instId":"AVAXUSDT"},"data":[{"asks":[["83.1415","38.0100"],["83.1515","73.7730"],["83.3715","2.8000"],["87.9959","0.4833"],["88.0790","0.1833"],["88.1621","0.2833"],["88.2452","0.4500"],["88.3283","0.5833"],["88.4114","0.3833"],["88.4945","0.5167"],["88.5776","0.6500"],["88.6607","0.2167"],["88.7438","0.4167"],["88.8269","0.6833"],["88.9100","0.5500"],["88.9931","0.3500"],["89.0762","0.8167"],["89.1593","0.7500"],["89.2424","0.2500"],["89.3255","0.7833"],["89.4086","0.3167"],["89.4917","0.6167"],["89.5748","0.7167"]],"bids":[["82.9185","49.6020"],["82.8985","0"],["82.6785","180.0000"],["82.6685","96.4110"],["82.5985","113.0920"],["82.5885","16.9820"],["82.4885","130.8440"],["82.4185","54.2780"],["78.0341","0.3833"],["77.9510","0.5833"],["77.8679","0.2167"],["77.7017","0.2833"],["77.6186","0.8167"],["77.5355","0.3500"],["77.4524","0.7500"],["77.3693","0.6500"],["77.2862","0.5500"],["77.2031","0.7833"],["77.1200","0.6833"],["77.0369","0.6167"],["76.9538","0.4500"],["76.8707","0.2500"],["76.7876","0.7167"],["76.7045","0.5167"],["76.6214","0.4833"],["76.5383","0.1833"],["76.4552","0.3167"]],"checksum":633592718,"ts":"1649290086899"}]}
1649290086.985201: {"action":"update","arg":{"instType":"sp","channel":"books","instId":"CULTUSDT"},"data":[{"asks":[["0.00003614","360000"],["0.00003618","253333"],["0.00003622","493333"],["0.00003626","626667"],["0.00003630","413333"],["0.00003634","466667"],["0.00003642","146667"],["0.00003646","500390"],["0.00003650","546667"],["0.00003654","333333"],["0.00003658","600000"],["0.00003666","173333"],["0.00003670","573333"],["0.00003674","280000"],["0.00003678","440000"],["0.00003682","200000"],["0.00003686","520000"],["0.00003690","386667"]],"bids":[["0.00003471","360000"],["0.00003467","1475230"],["0.00003463","626667"],["0.00003459","173333"],["0.00003455","774821"],["0.00003451","493333"],["0.00003447","146667"],["0.00003443","520000"],["0.00003439","226667"],["0.00003435","413333"],["0.00003431","546667"],["0.00003427","600000"],["0.00003423","573333"],["0.00003419","466667"],["0.00003415","200000"],["0.00003411","253333"],["0.00003407","306667"],["0.00003403","280000"],["0.00003399","440000"],["0.00003395","653333"]],"checksum":-1170925879,"ts":"1649290086957"}]}
1649290087.102379: {"action":"update","arg":{"instType":"sp","channel":"books","instId":"EOSUSDT"},"data":[{"asks":[["2.4424","33.4049"],["2.4428","243.0455"],["2.4429","2549.5382"],["2.4430","2591.2870"],["2.4431","542.4399"],["2.4432","462.1929"],["2.4433","2411.1180"],["2.4434","445.6809"],["2.4435","2570.9096"],["2.4438","2817.3510"],["2.4439","4625.3720"],["2.4440","640.0076"],["2.4444","450.0000"],["2.4445","128.3152"],["2.4453","1651.9500"],["2.4455","2610.4661"],["2.4457","1863.1789"],["2.4464","123.6376"],["2.4469","3158.5213"],["2.4473","0"],["2.4568","507.1429"],["2.4573","535.7143"],["2.4578","464.2857"],["2.4583","469.0476"],["2.4588","521.4286"],["2.4593","478.5714"],["2.4598","516.6667"],["2.4603","483.3333"],["2.4608","545.2381"],["2.4613","526.1905"],["2.4618","497.6190"],["2.4623","530.9524"],["2.4633","502.3810"],["2.4638","488.0952"],["2.4643","473.8095"],["2.4648","459.5238"],["2.4653","511.9048"],["2.4658","454.7619"],["2.4663","540.4762"]],"bids":[["2.4373","0"],["2.4370","367.8399"],["2.4368","0"],["2.4366","1544.3871"],["2.4364","1080.6263"],["2.4363","269.9954"],["2.4362","61.7042"],["2.4361","1158.7050"],["2.4358","25.9222"],["2.4351","1991.1598"],["2.4350","194.1219"],["2.4347","13.1327"],["2.4341","2998.1223"],["2.4330","331.0319"],["2.4325","2156.6551"],["2.4324","1456.4920"],["2.4323","2812.1256"],["2.4225","464.2857"],["2.4220","497.6190"],["2.4215","511.9048"],["2.4210","526.1905"],["2.4205","540.4762"],["2.4200","454.7619"],["2.4195","483.3333"],["2.4190","535.7143"],["2.4185","545.2381"],["2.4180","473.8095"],["2.4175","507.1429"],["2.4170","488.0952"],["2.4165","469.0476"],["2.4160","521.4286"],["2.4150","492.8571"],["2.4145","478.5714"],["2.4140","516.6667"],["2.4135","530.9524"],["2.4130","459.5238"]],"checksum":1588755708,"ts":"1649290087075"}]}
1649290087.180492: {"action":"update","arg":{"instType":"sp","channel":"books","instId":"SUNUSDT"},"data":[{"asks":[["0.01510","25252"],["0.01511","646201"],["0.01512","444241"],["0.01516","3847"],["0.01582","5167"],["0.01584","7833"],["0.01586","7500"],["0.01590","6500"],["0.01592","6833"],["0.01594","5500"],["0.01596","2500"],["0.01598","7167"],["0.01600","1833"],["0.01602","6167"],["0.01604","4500"],["0.01606","3833"],["0.01608","2167"],["0.01610","4167"],["0.01612","3500"],["0.01614","4833"],["0.01616","5833"],["0.01618","2833"],["0.01620","8167"]],"bids":[["0.01503","177013"],["0.01498","154476"],["0.01496","397613"],["0.01494","29579"],["0.01488","7461"],["0.01481","1284041"],["0.01480","1328"],["0.01430","4833"],["0.01428","6167"],["0.01426","2167"],["0.01424","5833"],["0.01422","3167"],["0.01420","1833"],["0.01418","2500"],["0.01416","3833"],["0.01414","5167"],["0.01412","6833"],["0.01410","4500"],["0.01408","8167"],["0.01406","4167"],["0.01404","3500"],["0.01402","6500"],["0.01400","7500"],["0.01398","7833"],["0.01396","5500"],["0.01394","7167"],["0.01392","2833"]],"checksum":-1424209884,"ts":"1649290087158"}]}
1649290087.230429: {"action":"update","arg":{"instType":"sp","channel":"books","instId":"GOGUSDT"},"data":[{"asks":[["0.5625","13.0000"],["0.5631","16.3333"],["0.5637","9.6667"],["0.5643","15.6667"],["0.5649","12.3333"],["0.5655","2344.8000"],["0.5661","10.3333"],["0.5667","9.0000"],["0.5679","11.6667"],["0.5685","13.6667"],["0.5691","14.3333"],["0.5697","15.0000"],["0.5703","8.7683"],["0.5709","8.7591"],["0.5721","8.7407"],["0.5733","8.7224"]],"bids":[["0.5512","13.7333"],["0.5506","15.6667"],["0.5500","14.3333"],["0.5494","9.1018"],["0.5488","9.6667"],["0.5482","3673.5667"],["0.5476","13.0000"],["0.5470","11.6667"],["0.5458","16.3333"],["0.5452","9.1719"],["0.5446","13.6667"],["0.5440","9.1922"],["0.5428","9.2125"],["0.5416","10.3333"],["0.5410","11.0000"],["0.5404","9.2534"],["0.5398","15.0000"]],"checksum":609055762,"ts":"1649290087207"}]}
1649290087.2709482: {"action":"update","arg":{"instType":"sp","channel":"books","instId":"VVSUSDT"},"data":[{"asks":[["0.00002370","821637.4000"],["0.00002373","289473.7000"],["0.00002379","657894.7000"],["0.00002382","330409.4000"],["0.00002385","698830.4000"],["0.00002391","780701.8000"],["0.00002397","208595.1000"],["0.00002403","453216.4000"],["0.00002406","903508.8000"],["0.00002409","535087.7000"]],"bids":[["0.00002261","412280.7000"],["0.00002258","535087.7000"],["0.00002255","862573.1000"],["0.00002252","576023.4000"],["0.00002249","222322.0000"],["0.00002243","330409.4000"],["0.00002240","616959.1000"],["0.00002237","371345.0000"],["0.00002234","453216.4000"],["0.00002231","780701.8000"],["0.00002228","289473.7000"]],"checksum":791825490,"ts":"1649290087247"}]}
1649290087.38306: {"action":"update","arg":{"instType":"sp","channel":"candle1m","instId":"CULTUSDT"},"data":[["1649290080000","0.00003507","0.00003508","0.00003507","0.00003508","233570"]]}
1649290087.4018931: {"action":"update","arg":{"instType":"sp","channel":"books","instId":"HOTUSDT"},"data":[{"asks":[["0.0056280","0"],["0.0056290","0"],["0.0056300","0"],["0.0056310","0"],["0.0056320","0"],["0.0056330","109143.7826"],["0.0056340","0"],["0.0056350","22550.4000"],["0.0056360","18809.1000"],["0.0056370","218175.3000"],["0.0056390","0"],["0.0056400","245920.5000"],["0.0056410","139781.7000"],["0.0056420","12010.5000"],["0.0056440","147749.4000"],["0.0056450","75824.5500"],["0.0056490","252024.3000"],["0.0056500","311647.5000"],["0.0056600","147097.8000"],["0.0056670","143732.7000"],["0.0056770","800000.0000"],["0.0056820","3240.0000"],["0.0056830","210522.1500"],["0.0056840","6421.5000"],["0.0056850","7616.7000"],["0.0056860","38396.7000"],["0.0056870","262003.5000"],["0.0056880","39999.6000"],["0.0056890","5535.0000"],["0.0059010","0"],["0.0059070","0"],["0.0059090","2750.0000"],["0.0059130","0"],["0.0059150","4750.0000"],["0.0059190","0"],["0.0059210","5250.0000"],["0.0059250","0"],["0.0059270","3250.0000"],["0.0059310","0"],["0.0059330","6250.0000"],["0.0059370","0"],["0.0059390","11250.0000"],["0.0059430","0"],["0.0059450","7750.0000"],["0.0059490","0"],["0.0059510","8250.0000"],["0.0059550","0"],["0.0059570","9750.0000"],["0.0059610","0"],["0.0059630","4250.0000"],["0.0059670","0"],["0.0059690","9250.0000"],["0.0059730","0"],["0.0059750","3750.0000"],["0.0059790","0"],["0.0059810","11750.0000"],["0.0059850","0"],["0.0059870","7250.0000"],["0.0059910","0"],["0.0059930","10250.0000"],["0.0059970","0"],["0.0059990","10750.0000"],["0.0060030","0"],["0.0060050","5750.0000"],["0.0060090","0"],["0.0060110","12250.0000"],["0.0060150","0"],["0.0060170","8750.0000"],["0.0060230","6750.0000"]],"bids":[["0.0056200","161052.3000"],["0.0056180","320312.7000"],["0.0056170","185855.4000"],["0.0056150","6611.4000"],["0.0056140","176102.1000"],["0.0056130","107716.1400"],["0.0056120","144441.9000"],["0.0056110","800000.0000"],["0.0056100","800000.0000"],["0.0056090","67726.8000"],["0.0056070","22550.4000"],["0.0056060","107289.4500"],["0.0056050","40694.4000"],["0.0056040","650266.2000"],["0.0055990","157543.2000"],["0.0055940","279760.0500"],["0.0055730","213297.6200"],["0.0055610","0"],["0.0055600","0"],["0.0055590","0"],["0.0055580","0"],["0.0055570","0"],["0.0055560","0"],["0.0055550","0"],["0.0053460","6250.0000"],["0.0053400","7750.0000"],["0.0053380","0"],["0.0053340","3250.0000"],["0.0053320","0"],["0.0053280","7250.0000"],["0.0053260","0"],["0.0053220","11750.0000"],["0.0053200","0"],["0.0053160","4250.0000"],["0.0053140","0"],["0.0053100","5250.0000"],["0.0053080","0"],["0.0053040","10250.0000"],["0.0053020","0"],["0.0052980","12250.0000"],["0.0052960","0"],["0.0052920","9250.0000"],["0.0052900","0"],["0.0052860","3750.0000"],["0.0052840","0"],["0.0052800","8250.0000"],["0.0052780","0"],["0.0052740","4750.0000"],["0.0052720","0"],["0.0052680","2750.0000"],["0.0052660","0"],["0.0052620","10750.0000"],["0.0052600","0"],["0.0052560","8750.0000"],["0.0052540","0"],["0.0052500","5750.0000"],["0.0052480","0"],["0.0052440","11250.0000"],["0.0052420","0"],["0.0052380","6750.0000"],["0.0052360","0"],["0.0052320","9750.0000"],["0.0052300","0"],["0.0052240","0"]],"checksum":-671123721,"ts":"1649290087378"}]}
1649290087.441663: {"action":"update","arg":{"instType":"sp","channel":"books","instId":"STGUSDT"},"data":[{"asks":[["3.034","2.174"],["3.037","1.647"],["3.040","3.569"],["3.043","1.644"],["3.046","1.920"],["3.049","4.091"],["3.052","3.442"],["3.055","1.638"],["3.058","2.808"],["3.061","2.554"],["3.064","1.633"],["3.067","2.681"],["3.070","1.630"],["3.073","1.793"],["3.076","2.935"],["3.079","6.345"],["3.082","3.315"],["3.085","1.667"],["3.088","1.620"],["3.091","2.301"],["3.094","2.047"],["3.097","3.062"],["3.100","2.428"]],"bids":[["2.744","1.823"],["2.741","3.185"],["2.738","19.860"],["2.735","2.646"],["2.732","100.285"],["2.729","1.833"],["2.726","73.744"],["2.723","2.323"],["2.720","2.000"],["2.717","1.841"],["2.714","2.431"],["2.711","1.845"],["2.705","2.969"],["2.696","92.847"],["2.693","2.538"],["2.687","1.862"],["2.681","3.292"],["2.678","2.862"],["2.675","2.215"],["2.672","1.892"]],"checksum":-887162395,"ts":"1649290087420"}]}
1649290087.4833531: {"action":"update","arg":{"instType":"sp","channel":"books","instId":"AVAXUSDT"},"data":[{"asks":[["83.1115","0"],["83.1215","42.1680"],["83.1415","60.8370"],["83.1515","115.8920"],["83.2215","17.2620"],["83.3415","4.8930"],["83.5815","180.0000"],["83.6615","0.7490"],["87.9959","0"],["88.0066","0.5167"],["88.0790","0"],["88.0897","0.4167"],["88.1621","0"],["88.1728","0.2500"],["88.2452","0"],["88.2559","0.6500"],["88.3283","0"],["88.3390","0.2833"],["88.4114","0"],["88.4221","0.1833"],["88.4945","0"],["88.5052","0.7833"],["88.5776","0"],["88.5883","0.7500"],["88.6607","0"],["88.6714","0.3500"],["88.7438","0"],["88.7545","0.5833"],["88.8269","0"],["88.8376","0.4833"],["88.9100","0"],["88.9207","0.3833"],["88.9931","0"],["89.0038","0.7167"],["89.0762","0"],["89.0869","0.4500"],["89.1593","0"],["89.1700","0.2167"],["89.2424","0"],["89.2531","0.6833"],["89.3255","0"],["89.3362","0.3167"],["89.4086","0"],["89.4193","0.5500"],["89.4917","0"],["89.5024","0.6167"],["89.5748","0"],["89.5855","0.8167"]],"bids":[["82.9285","111.3350"],["82.9185","41.7620"],["82.8985","42.1610"],["82.8885","43.8480"],["82.7793","1.5303"],["82.7585","180.0000"],["82.7285","173.2640"],["82.6785","174.7410"],["82.6085","46.4310"],["82.5885","25.2980"],["82.5585","146.9650"],["82.5485","112.4340"],["82.4285","0"],["82.4185","0"],["78.0435","0.6833"],["78.0341","0"],["77.9604","0.3833"],["77.9510","0"],["77.8773","0.1833"],["77.8679","0"],["77.7942","0.4167"],["77.7848","0"],["77.7111","0.6500"],["77.7017","0"],["77.6280","0.3500"],["77.6186","0"],["77.5449","0.2833"],["77.5355","0"],["77.4618","0.7500"],["77.4524","0"],["77.3787","0.5500"],["77.3693","0"],["77.2956","0.6167"],["77.2862","0"],["77.2125","0.4833"],["77.2031","0"],["77.1294","0.2167"],["77.1200","0"],["77.0463","0.7167"],["77.0369","0"],["76.9632","0.5833"],["76.9538","0"],["76.8801","0.8167"],["76.8707","0"],["76.7970","0.7833"],["76.7876","0"],["76.7139","0.5167"],["76.7045","0"],["76.6308","0.3167"],["76.6214","0"],["76.5477","0.2500"],["76.5383","0"],["76.4646","0.4500"],["76.4552","0"]],"checksum":-707158442,"ts":"1649290087459"}]}
1649290087.582756: {"action":"update","arg":{"instType":"sp","channel":"books","instId":"CULTUSDT"},"data":[{"asks":[["0.00003614","600000"],["0.00003618","466667"],["0.00003622","413333"],["0.00003626","226667"],["0.00003630","146667"],["0.00003634","173333"],["0.00003638","333333"],["0.00003642","360000"],["0.00003646","553723"],["0.00003650","440000"],["0.00003654","493333"],["0.00003658","546667"],["0.00003666","626667"],["0.00003670","520000"],["0.00003674","573333"],["0.00003678","253333"],["0.00003682","306667"],["0.00003686","200000"]],"bids":[["0.00003471","173333"],["0.00003467","1741897"],["0.00003463","360000"],["0.00003459","466667"],["0.00003455","614821"],["0.00003451","146667"],["0.00003447","626667"],["0.00003443","280000"],["0.00003439","386667"],["0.00003435","493333"],["0.00003431","573333"],["0.00003427","653333"],["0.00003423","520000"],["0.00003419","333333"],["0.00003415","253333"],["0.00003411","306667"],["0.00003407","546667"],["0.00003403","413333"],["0.00003395","200000"]],"checksum":-155586881,"ts":"1649290087561"}]}
1649290087.659241: {"action":"update","arg":{"instType":"sp","channel":"books","instId":"EOSUSDT"},"data":[{"asks":[["2.4415","32.8332"],["2.4420","27.0000"],["2.4421","8.0474"],["2.4422","57.9526"],["2.4423","27.0000"],["2.4424","61.2545"],["2.4426","181.1250"],["2.4427","0"],["2.4432","988.1596"],["2.4442","4044.9023"],["2.4448","569.4228"],["2.4454","1602.9000"],["2.4467","194.4450"],["2.4469","3020.1913"],["2.4470","0"],["2.4471","0"],["2.4472","0"],["2.4564","521.4286"],["2.4568","0"],["2.4569","492.8571"],["2.4573","0"],["2.4574","488.0952"],["2.4578","0"],["2.4579","454.7619"],["2.4583","0"],["2.4584","459.5238"],["2.4588","0"],["2.4589","507.1429"],["2.4593","0"],["2.4594","526.1905"],["2.4598","0"],["2.4599","478.5714"],["2.4603","0"],["2.4604","540.4762"],["2.4608","0"],["2.4609","530.9524"],["2.4613","0"],["2.4614","483.3333"],["2.4618","0"],["2.4619","516.6667"],["2.4623","0"],["2.4624","464.2857"],["2.4628","0"],["2.4629","469.0476"],["2.4633","0"],["2.4634","511.9048"],["2.4638","0"],["2.4639","497.6190"],["2.4643","0"],["2.4644","545.2381"],["2.4648","0"],["2.4649","502.3810"],["2.4653","0"],["2.4654","473.8095"],["2.4658","0"],["2.4659","535.7143"],["2.4663","0"]],"bids":[["2.4374","0"],["2.4372","0"],["2.4371","35.5500"],["2.4369","1340.6311"],["2.4368","2201.0179"],["2.4366","1761.7307"],["2.4365","8.0521"],["2.4364","1053.3717"],["2.4363","1042.9353"],["2.4362","57.2400"],["2.4361","983.5545"],["2.4360","813.0985"],["2.4359","993.1218"],["2.4358","67.8459"],["2.4356","1555.2495"],["2.4355","148.4010"],["2.4354","715.9783"],["2.4353","72.9188"],["2.4352","1075.0959"],["2.4351","2753.4631"],["2.4350","351.2250"],["2.4348","1261.7835"],["2.4345","60.7101"],["2.4343","1634.0786"],["2.4342","499.3210"],["2.4335","5981.4304"],["2.4332","309.6000"],["2.4331","3791.1909"],["2.4325","1418.3994"],["2.4324","1364.2764"],["2.4321","6243.0039"],["2.4225","0"],["2.4222","511.9048"],["2.4220","0"],["2.4217","469.0476"],["2.4215","0"],["2.4212","516.6667"],["2.4210","0"],["2.4207","497.6190"],["2.4205","0"],["2.4202","492.8571"],["2.4200","0"],["2.4197","483.3333"],["2.4195","0"],["2.4192","521.4286"],["2.4190","0"],["2.4187","540.4762"],["2.4185","0"],["2.4182","488.0952"],["2.4180","0"],["2.4177","478.5714"],["2.4175","0"],["2.4172","464.2857"],["2.4170","0"],["2.4167","526.1905"],["2.4165","0"],["2.4162","502.3810"],["2.4160","0"],["2.4157","530.9524"],["2.4155","0"],["2.4152","545.2381"],["2.4150","0"],["2.4147","454.7619"],["2.4145","0"],["2.4142","459.5238"],["2.4140","0"],["2.4137","507.1429"],["2.4135","0"],["2.4132","473.8095"],["2.4130","0"],["2.4127","535.7143"]],"checksum":-1438533319,"ts":"1649290087634"}]}
1649290087.695474: {"action":"update","arg":{"instType":"sp","channel":"trade","instId":"VVSUSDT"},"data":[["1649290087641","0.00002314","215239","sell"]]}
1649290087.7265139: {"action":"update","arg":{"instType":"sp","channel":"books","instId":"SUNUSDT"},"data":[{"asks":[["0.01510","12382"],["0.01511","731703"],["0.01512","445743"],["0.01582","8167"],["0.01584","7500"],["0.01586","6833"],["0.01588","4500"],["0.01590","2500"],["0.01592","3833"],["0.01594","5833"],["0.01596","6500"],["0.01598","7833"],["0.01600","6167"],["0.01602","5167"],["0.01604","2167"],["0.01606","5500"],["0.01608","1833"],["0.01610","3167"],["0.01612","2833"],["0.01614","3500"],["0.01616","7167"],["0.01618","4833"],["0.01620","4167"]],"bids":[["0.01488","4579"],["0.01486","21016"],["0.01430","2167"],["0.01428","7167"],["0.01426","5833"],["0.01424","4833"],["0.01422","3500"],["0.01420","7500"],["0.01418","4167"],["0.01416","5500"],["0.01414","7833"],["0.01410","8167"],["0.01408","5167"],["0.01406","3167"],["0.01404","1833"],["0.01402","3833"],["0.01400","2833"],["0.01398","6167"],["0.01396","6500"],["0.01394","2500"],["0.01392","4500"]],"checksum":-991603404,"ts":"1649290087704"}]}
1649290087.770571: {"action":"update","arg":{"instType":"sp","channel":"books","instId":"GOGUSDT"},"data":[{"asks":[["0.5625","13.6667"],["0.5637","15.0000"],["0.5643","12.3333"],["0.5649","14.3333"],["0.5655","2342.8000"],["0.5661","11.0000"],["0.5667","8.8240"],["0.5679","8.8054"],["0.5685","8.7961"],["0.5691","13.0000"],["0.5697","9.6667"],["0.5709","10.3333"],["0.5727","15.6667"],["0.5739","11.6667"]],"bids":[["0.5512","15.0667"],["0.5506","9.0820"],["0.5500","9.0919"],["0.5494","11.6667"],["0.5482","3681.5667"],["0.5476","9.1318"],["0.5470","11.0000"],["0.5464","13.0000"],["0.5458","9.1619"],["0.5452","10.3333"],["0.5446","14.3333"],["0.5440","16.3333"],["0.5422","15.0000"],["0.5416","9.2329"],["0.5410","12.3333"],["0.5398","9.2637"]],"checksum":2025623073,"ts":"1649290087745"}]}
1649290087.800676: {"action":"update","arg":{"instType":"sp","channel":"books","instId":"VVSUSDT"},"data":[{"asks":[["0.00002370","780701.8000"],["0.00002373","698830.4000"],["0.00002379","210173.3000"],["0.00002382","535087.7000"],["0.00002385","330409.4000"],["0.00002391","248538.0000"],["0.00002397","289473.7000"],["0.00002406","821637.4000"],["0.00002409","371345.0000"]],"bids":[["0.00002267","862573.1000"],["0.00002261","780701.8000"],["0.00002258","657894.7000"],["0.00002255","330409.4000"],["0.00002252","739766.1000"],["0.00002243","821637.4000"],["0.00002240","371345.0000"],["0.00002237","494152.0000"],["0.00002234","412280.7000"],["0.00002231","616959.1000"],["0.00002228","535087.7000"]],"checksum":1072120802,"ts":"1649290087778"}]}
1649290087.90693: {"action":"update","arg":{"instType":"sp","channel":"candle1m","instId":"VVSUSDT"},"data":[["1649290080000","0.00002324","0.00002324","0.00002314","0.00002314","430849.3"]]}
1649290087.9433548: {"action":"update","arg":{"instType":"sp","channel":"books","instId":"HOTUSDT"},"data":[{"asks":[["0.0056350","83696.4000"],["0.0056360","0"],["0.0056370","316457.1000"],["0.0056380","800000.0000"],["0.0056390","799056.0000"],["0.0056400","0"],["0.0056410","80677.3500"],["0.0056420","0"],["0.0056430","78269.4000"],["0.0056440","202997.7000"],["0.0056450","31925.7000"],["0.0056460","136008.4500"],["0.0056490","380675.2500"],["0.0056520","800000.0000"],["0.0056540","62916.7500"],["0.0056610","19998.0000"],["0.0056650","0"],["0.0056660","120869.1000"],["0.0056690","76747.0500"],["0.0056740","23150.7000"],["0.0056830","102600.0000"],["0.0056860","24724.3500"],["0.0056910","2519.1000"],["0.0056930","800000.0000"],["0.0059090","5750.0000"],["0.0059150","10250.0000"],["0.0059210","8250.0000"],["0.0059270","2750.0000"],["0.0059330","4250.0000"],["0.0059390","9750.0000"],["0.0059510","7250.0000"],["0.0059570","6250.0000"],["0.0059630","11750.0000"],["0.0059690","10750.0000"],["0.0059750","4750.0000"],["0.0059810","9250.0000"],["0.0059870","6750.0000"],["0.0059930","8750.0000"],["0.0059990","11250.0000"],["0.0060050","5250.0000"],["0.0060110","3750.0000"],["0.0060170","3250.0000"],["0.0060230","12250.0000"]],"bids":[["0.0056180","0"],["0.0056150","410298.3000"],["0.0056140","214842.6000"],["0.0056130","72343.8600"],["0.0056090","37071.0000"],["0.0056080","185769.0000"],["0.0056070","172782.4500"],["0.0056060","106488.4500"],["0.0056050","110074.5000"],["0.0056040","800000.0000"],["0.0056030","123919.5300"],["0.0056020","477351.9000"],["0.0055990","192600.0000"],["0.0055980","38936.7000"],["0.0055970","114706.8000"],["0.0055960","120062.7000"],["0.0055950","240985.8000"],["0.0055930","84495.2700"],["0.0055920","141302.7000"],["0.0055900","89424.0000"],["0.0055890","354429.9000"],["0.0055870","17388.0000"],["0.0055860","0"],["0.0055840","339390.0000"],["0.0055760","63068.8500"],["0.0055670","30573.0000"],["0.0055610","250792.2000"],["0.0055600","294261.3000"],["0.0053460","10250.0000"],["0.0053400","3750.0000"],["0.0053340","5250.0000"],["0.0053280","3250.0000"],["0.0053220","8750.0000"],["0.0053160","10750.0000"],["0.0053100","6750.0000"],["0.0053040","4750.0000"],["0.0052980","7250.0000"],["0.0052920","11250.0000"],["0.0052860","7750.0000"],["0.0052800","2750.0000"],["0.0052740","8250.0000"],["0.0052680","12250.0000"],["0.0052620","11750.0000"],["0.0052560","9750.0000"],["0.0052500","4250.0000"],["0.0052440","5750.0000"],["0.0052380","9250.0000"],["0.0052320","6250.0000"]],"checksum":-1580542488,"ts":"1649290087919"}]}
1649290087.992214: {"action":"update","arg":{"instType":"sp","channel":"books","instId":"STGUSDT"},"data":[{"asks":[["3.034","2.554"],["3.040","2.681"],["3.046","3.315"],["3.049","3.964"],["3.052","1.639"],["3.055","2.047"],["3.058","3.188"],["3.061","2.935"],["3.064","2.301"],["3.067","3.062"],["3.070","1.667"],["3.073","2.174"],["3.076","1.626"],["3.079","6.599"],["3.082","1.920"],["3.085","3.569"],["3.091","2.428"],["3.094","2.808"],["3.097","1.793"],["3.100","1.614"]],"bids":[["2.744","3.185"],["2.741","2.323"],["2.738","19.537"],["2.735","3.292"],["2.732","98.669"],["2.729","2.431"],["2.726","75.575"],["2.723","1.837"],["2.720","2.969"],["2.717","2.000"],["2.714","2.862"],["2.708","2.646"],["2.705","1.849"],["2.702","2.215"],["2.696","94.462"],["2.693","1.858"],["2.687","1.892"],["2.681","1.866"],["2.678","2.108"],["2.675","1.870"],["2.672","2.538"]],"checksum":1103461997,"ts":"1649290087969"}]}
1649290088.043052: {"action":"update","arg":{"instType":"sp","channel":"books","instId":"AVAXUSDT"},"data":[{"asks":[["83.1215","49.1680"],["83.1415","58.8980"],["83.2315","74.8650"],["88.0066","0.7500"],["88.0897","0.5500"],["88.1728","0.3500"],["88.2559","0.5833"],["88.3390","0.7833"],["88.4221","0.6833"],["88.5052","0.3167"],["88.5883","0.3833"],["88.6714","0.4167"],["88.7545","0.6500"],["88.8376","0.7167"],["88.9207","0.4500"],["89.0038","0.2500"],["89.0869","0.1833"],["89.1700","0.6167"],["89.2531","0.8167"],["89.3362","0.4833"],["89.4193","0.2833"],["89.5024","0.5167"],["89.5855","0.2167"]],"bids":[["82.9185","37.9120"],["82.9085","42.7070"],["82.7785","76.8390"],["82.6285","86.7930"],["82.5885","33.6280"],["82.5785","30.3450"],["82.5585","163.6600"],["82.5485","120.7850"],["78.0435","0.3500"],["77.9604","0.2833"],["77.8773","0.4167"],["77.7942","0.3833"],["77.7111","0.4833"],["77.6280","0.5167"],["77.5449","0.7167"],["77.4618","0.8167"],["77.3787","0.2167"],["77.2956","0.7833"],["77.2125","0.4500"],["77.1294","0.6500"],["77.0463","0.6833"],["76.9632","0.1833"],["76.8801","0.2500"],["76.7970","0.3167"],["76.7139","0.7500"],["76.6308","0.5833"],["76.5477","0.6167"],["76.4646","0.5500"]],"checksum":1316193955,"ts":"1649290088019"}]}
1649290088.113264: {"action":"snapshot","arg":{"instType":"sp","channel":"ticker","instId":"EOSUSDT"},"data":[{"instId":"EOSUSDT","last":"2.4393","open24h":"2.5667","high24h":"2.5767","low24h":"2.4155","bestBid":"2.437100","bestAsk":"2.441500","baseVolume":"145522.9643","quoteVolume":"378718.0033","ts":1649290088067,"labeId":0}]}
1649290088.176398: {"action":"snapshot","arg":{"instType":"sp","channel":"ticker","instId":"AVAXUSDT"},"data":[{"instId":"AVAXUSDT","last":"82.9972","open24h":"85.1099","high24h":"86.7605","low24h":"82.5893","bestBid":"82.928500","bestAsk":"83.121500","baseVolume":"3330.7812","quoteVolume":"287728.8336","ts":1649290088123,"labeId":0}]}
1649290088.1765: {"action":"snapshot","arg":{"instType":"sp","channel":"ticker","instId":"VVSUSDT"},"data":[{"instId":"VVSUSDT","last":"0.00002314","open24h":"0.00002350","high24h":"0.00002359","low24h":"0.00002313","bestBid":"0.000024","bestAsk":"0.000024","baseVolume":"2375582289.9083","quoteVolume":"56989.8797","ts":1649290088133,"labeId":0}]}
1649290088.182611: {"action":"snapshot","arg":{"instType":"sp","channel":"ticker","instId":"HOTUSDT"},"data":[{"instId":"HOTUSDT","last":"0.0056130","open24h":"0.0058560","high24h":"0.0059320","low24h":"0.0055520","bestBid":"0.005620","bestAsk":"0.005637","baseVolume":"10203207.8809","quoteVolume":"60796.5347","ts":1649290088137,"labeId":0}]}
1649290088.198666: {"action":"update","arg":{"instType":"sp","channel":"books","instId":"CULTUSDT"},"data":[{"asks":[["0.00003614","440000"],["0.00003618","360000"],["0.00003622","146667"],["0.00003626","280000"],["0.00003630","173333"],["0.00003634","306667"],["0.00003638","200000"],["0.00003642","253333"],["0.00003646","767056"],["0.00003650","386667"],["0.00003654","333333"],["0.00003658","626667"],["0.00003662","466667"],["0.00003666","226667"],["0.00003670","413333"],["0.00003674","653333"],["0.00003678","520000"],["0.00003682","546667"],["0.00003686","600000"],["0.00003690","573333"]],"bids":[["0.00003471","520000"],["0.00003467","1421897"],["0.00003463","333333"],["0.00003459","386667"],["0.00003451","253333"],["0.00003447","360000"],["0.00003443","440000"],["0.00003439","173333"],["0.00003435","200000"],["0.00003431","600000"],["0.00003427","413333"],["0.00003423","306667"],["0.00003419","466667"],["0.00003415","653333"],["0.00003411","493333"],["0.00003407","626667"],["0.00003403","546667"],["0.00003399","147103"],["0.00003395","573333"],["0.00003388","0"],["0.00003144","1479733"]],"checksum":100453634,"ts":"1649290088165"}]}
1649290088.215435: {"action":"snapshot","arg":{"instType":"sp","channel":"ticker","instId":"GOGUSDT"},"data":[{"instId":"GOGUSDT","last":"0.5575","open24h":"0.5563","high24h":"0.5708","low24h":"0.5508","bestBid":"0.554700","bestAsk":"0.559000","baseVolume":"134638.2253","quoteVolume":"78741.7865","ts":1649290088160,"labeId":0}]}
1649290088.235589: {"action":"snapshot","arg":{"instType":"sp","channel":"ticker","instId":"SUNUSDT"},"data":[{"instId":"SUNUSDT","last":"0.01505","open24h":"0.01521","high24h":"0.01559","low24h":"0.01481","bestBid":"0.015040","bestAsk":"0.015080","baseVolume":"11683781","quoteVolume":"180235","ts":1649290088190,"labeId":0}]}
1649290088.252467: {"action":"update","arg":{"instType":"sp","channel":"books","instId":"EOSUSDT"},"data":[{"asks":[["2.4415","0"],["2.4419","1644.4800"],["2.4422","8.0473"],["2.4424","68.9832"],["2.4425","236.2500"],["2.4427","97.5724"],["2.4428","262.8871"],["2.4429","2283.9182"],["2.4430","5169.5100"],["2.4432","462.1929"],["2.4433","1950.3180"],["2.4435","2577.5316"],["2.4436","147.4019"],["2.4439","5854.5117"],["2.4440","501.6754"],["2.4441","1370.4934"],["2.4443","1123.6590"],["2.4449","2069.5016"],["2.4450","4455.0000"],["2.4451","1310.3753"],["2.4453","2907.0000"],["2.4455","1525.9568"],["2.4459","2220.5240"],["2.4460","921.6000"],["2.4462","1128.6720"],["2.4468","191.0412"],["2.4469","0"],["2.4564","0"],["2.4567","454.7619"],["2.4569","0"],["2.4572","526.1905"],["2.4574","0"],["2.4577","464.2857"],["2.4579","0"],["2.4582","502.3810"],["2.4584","0"],["2.4587","540.4762"],["2.4589","0"],["2.4592","521.4286"],["2.4594","0"],["2.4597","473.8095"],["2.4599","0"],["2.4602","530.9524"],["2.4604","0"],["2.4607","488.0952"],["2.4609","0"],["2.4612","545.2381"],["2.4614","0"],["2.4617","469.0476"],["2.4619","0"],["2.4622","497.6190"],["2.4624","0"],["2.4627","483.3333"],["2.4629","0"],["2.4632","478.5714"],["2.4634","0"],["2.4637","507.1429"],["2.4639","0"],["2.4642","535.7143"],["2.4644","0"],["2.4647","459.5238"],["2.4649","0"],["2.4652","511.9048"],["2.4654","0"],["2.4657","516.6667"],["2.4659","0"],["2.4662","492.8571"]],"bids":[["2.4374","719.0751"],["2.4373","30.5518"],["2.4372","2553.4126"],["2.4368","0"],["2.4365","2210.5440"],["2.4364","1095.4824"],["2.4362","103.8874"],["2.4361","1214.9550"],["2.4359","1867.2117"],["2.4358","25.9222"],["2.4352","1081.8694"],["2.4351","3210.0942"],["2.4349","1775.5135"],["2.4348","392.1502"],["2.4347","0"],["2.4345","42.2048"],["2.4341","3096.6723"],["2.4339","497.2594"],["2.4336","1792.6906"],["2.4335","6007.8470"],["2.4329","575.9912"],["2.4328","239.2107"],["2.4326","519.3585"],["2.4325","811.1745"],["2.4321","0"],["2.4225","526.1905"],["2.4222","0"],["2.4220","507.1429"],["2.4217","0"],["2.4215","535.7143"],["2.4212","0"],["2.4210","483.3333"],["2.4207","0"],["2.4205","511.9048"],["2.4202","0"],["2.4200","469.0476"],["2.4197","0"],["2.4195","454.7619"],["2.4192","0"],["2.4190","459.5238"],["2.4187","0"],["2.4185","497.6190"],["2.4182","0"],["2.4180","545.2381"],["2.4177","0"],["2.4175","488.0952"],["2.4172","0"],["2.4170","473.8095"],["2.4167","0"],["2.4165","478.5714"],["2.4162","0"],["2.4160","530.9524"],["2.4157","0"],["2.4155","516.6667"],["2.4152","0"],["2.4150","502.3810"],["2.4147","0"],["2.4145","464.2857"],["2.4142","0"],["2.4140","540.4762"],["2.4137","0"],["2.4135","492.8571"],["2.4132","0"],["2.4130","521.4286"],["2.4127","0"]],"checksum":-1528202214,"ts":"1649290088230"}]}
1649290088.263784: {"action":"snapshot","arg":{"instType":"sp","channel":"ticker","instId":"STGUSDT"},"data":[{"instId":"STGUSDT","last":"2.881","open24h":"3.045","high24h":"3.164","low24h":"2.757","bestBid":"2.861000","bestAsk":"2.917000","baseVolume":"35327.890","quoteVolume":"111744.124","ts":1649290088215,"labeId":0}]}
1649290088.264979: {"action":"snapshot","arg":{"instType":"sp","channel":"ticker","instId":"CULTUSDT"},"data":[{"instId":"CULTUSDT","last":"0.00003508","open24h":"0.00004340","high24h":"0.00004397","low24h":"0.00003500","bestBid":"0.000036","bestAsk":"0.000036","baseVolume":"13527006500","quoteVolume":"557444","ts":1649290088219,"labeId":0}]}
1649290088.271275: {"action":"update","arg":{"instType":"sp","channel":"books","instId":"SUNUSDT"},"data":[{"asks":[["0.01510","25252"],["0.01511","647704"],["0.01512","444241"],["0.01536","0"],["0.01566","2122"],["0.01582","7500"],["0.01584","4500"],["0.01586","1833"],["0.01588","2500"],["0.01590","5500"],["0.01592","8167"],["0.01596","3167"],["0.01598","3500"],["0.01600","5167"],["0.01602","3833"],["0.01604","4167"],["0.01606","6833"],["0.01608","2833"],["0.01610","4833"],["0.01612","6500"],["0.01614","7833"],["0.01618","6167"],["0.01620","2167"]],"bids":[["0.01502","237141"],["0.01500","709551"],["0.01498","199476"],["0.01488","7461"],["0.01430","4167"],["0.01428","2167"],["0.01426","7833"],["0.01424","3500"],["0.01422","4500"],["0.01420","6833"],["0.01418","6167"],["0.01416","3167"],["0.01414","3833"],["0.01412","1833"],["0.01410","6500"],["0.01408","2500"],["0.01406","7500"],["0.01404","5167"],["0.01402","5500"],["0.01398","8167"],["0.01396","5833"],["0.01394","4833"],["0.01392","7167"]],"checksum":-505087719,"ts":"1649290088247"}]}
1649290088.310654: {"action":"update","arg":{"instType":"sp","channel":"books","instId":"GOGUSDT"},"data":[{"asks":[["0.5625","11.0000"],["0.5631","8.8804"],["0.5637","16.3333"],["0.5643","14.3333"],["0.5649","13.6667"],["0.5655","2344.1333"],["0.5661","11.6667"],["0.5673","15.6667"],["0.5685","15.0000"],["0.5691","9.0000"],["0.5697","8.7775"],["0.5703","12.3333"],["0.5709","9.6667"],["0.5727","8.7316"],["0.5739","13.0000"],["0.6068","0"],["0.6418","9.8000"]],"bids":[["0.5512","9.0721"],["0.5506","11.6667"],["0.5500","9.6667"],["0.5494","15.0000"],["0.5488","15.6667"],["0.5482","3676.9000"],["0.5470","9.1418"],["0.5464","12.3333"],["0.5458","16.3333"],["0.5452","13.6667"],["0.5446","9.1821"],["0.5440","14.3333"],["0.5428","10.3333"],["0.5422","13.0000"],["0.5410","9.2431"]],"checksum":2131218970,"ts":"1649290088278"}]}
1649290088.402766: {"action":"update","arg":{"instType":"sp","channel":"books","instId":"VVSUSDT"},"data":[{"asks":[["0.00002370","903508.8000"],["0.00002373","821637.4000"],["0.00002379","248538.0000"],["0.00002382","371345.0000"],["0.00002385","535087.7000"],["0.00002391","494152.0000"],["0.00002397","412280.7000"],["0.00002403","208074.2000"],["0.00002406","780701.8000"],["0.00002409","698830.4000"]],"bids":[["0.00002267","330409.4000"],["0.00002261","657894.7000"],["0.00002258","616959.1000"],["0.00002255","739766.1000"],["0.00002252","371345.0000"],["0.00002249","535087.7000"],["0.00002243","903508.8000"],["0.00002240","780701.8000"],["0.00002237","821637.4000"],["0.00002234","698830.4000"],["0.00002231","453216.4000"],["0.00002228","412280.7000"]],"checksum":-1879082692,"ts":"1649290088375"}]}
1649290088.480392: {"action":"update","arg":{"instType":"sp","channel":"trade","instId":"SUNUSDT"},"data":[["1649290088390","0.01505","1702","sell"]]}
1649290088.49045: {"action":"update","arg":{"instType":"sp","channel":"books","instId":"HOTUSDT"},"data":[{"asks":[["0.0056370","287554.5000"],["0.0056390","0"],["0.0056400","800000.0000"],["0.0056410","159755.4000"],["0.0056420","92039.4000"],["0.0056430","89544.6000"],["0.0056510","800000.0000"],["0.0056930","0"],["0.0059090","7750.0000"],["0.0059150","9250.0000"],["0.0059210","5750.0000"],["0.0059270","5250.0000"],["0.0059330","9750.0000"],["0.0059390","10250.0000"],["0.0059450","6250.0000"],["0.0059510","4250.0000"],["0.0059570","3750.0000"],["0.0059630","8750.0000"],["0.0059690","12250.0000"],["0.0059750","11250.0000"],["0.0059810","4750.0000"],["0.0059930","2750.0000"],["0.0059990","3250.0000"],["0.0060050","7250.0000"],["0.0060110","10750.0000"],["0.0060170","11750.0000"],["0.0060230","8250.0000"]],"bids":[["0.0056200","113802.3000"],["0.0056190","41896.8000"],["0.0056180","57888.9000"],["0.0056150","216424.3500"],["0.0056140","108444.1500"],["0.0056130","107716.1400"],["0.0056120","109188.5170"],["0.0056070","323014.5000"],["0.0056060","365926.5000"],["0.0056040","795283.2000"],["0.0055610","0"],["0.0055600","0"],["0.0053460","9750.0000"],["0.0053400","10750.0000"],["0.0053340","3750.0000"],["0.0053280","5750.0000"],["0.0053220","11750.0000"],["0.0053160","5250.0000"],["0.0053040","7750.0000"],["0.0052980","12250.0000"],["0.0052920","3250.0000"],["0.0052860","7250.0000"],["0.0052800","11250.0000"],["0.0052740","10250.0000"],["0.0052680","8750.0000"],["0.0052620","9250.0000"],["0.0052560","6250.0000"],["0.0052440","4750.0000"],["0.0052380","8250.0000"],["0.0052320","2750.0000"]],"checksum":1485712435,"ts":"1649290088464"}]}
1649290088.5021062: {"action":"update","arg":{"instType":"sp","channel":"books","instId":"STGUSDT"},"data":[{"asks":[["3.034","3.062"],["3.037","2.808"],["3.040","2.047"],["3.043","2.428"],["3.046","1.642"],["3.049","4.218"],["3.052","2.554"],["3.055","2.681"],["3.058","1.636"],["3.061","1.793"],["3.064","1.633"],["3.067","2.935"],["3.070","3.188"],["3.073","1.628"],["3.082","2.301"],["3.085","2.174"],["3.088","3.569"],["3.091","1.619"],["3.094","1.920"],["3.097","1.667"],["3.100","3.315"]],"bids":[["2.744","2.215"],["2.741","2.538"],["2.738","18.675"],["2.735","1.829"],["2.732","99.962"],["2.729","1.833"],["2.726","76.006"],["2.723","1.892"],["2.720","2.108"],["2.714","1.843"],["2.711","2.646"],["2.708","2.754"],["2.705","2.323"],["2.702","2.862"],["2.696","92.200"],["2.687","1.862"],["2.684","3.077"],["2.681","2.969"],["2.678","3.292"],["2.672","1.872"]],"checksum":1494856293,"ts":"1649290088474"}]}
1649290088.566037: {"action":"update","arg":{"instType":"sp","channel":"candle1m","instId":"SUNUSDT"},"data":[["1649290080000","0.01507","0.01507","0.01505","0.01505","3134"]]}
1649290088.570681: {"action":"update","arg":{"instType":"sp","channel":"books","instId":"AVAXUSDT"},"data":[{"asks":[["83.0814","32.0950"],["83.0914","10.5910"],["83.1014","15.2040"],["83.1114","111.3770"],["83.1214","74.3260"],["83.1215","0"],["83.1314","37.3590"],["83.1315","0"],["83.1414","82.6070"],["83.1415","0"],["83.1514","180.0000"],["83.1515","0"],["83.1614","180.0000"],["83.1615","0"],["83.1714","94.6260"],["83.1715","0"],["83.1814","180.0000"],["83.1815","0"],["83.1914","180.0000"],["83.1915","0"],["83.2014","7.1610"],["83.2015","0"],["83.2114","11.3890"],["83.2115","0"],["83.2214","17.2620"],["83.2215","0"],["83.2314","108.8920"],["83.2315","0"],["83.2414","157.2480"],["83.2415","0"],["83.2514","180.0000"],["83.2515","0"],["83.2614","142.2890"],["83.2615","0"],["83.2714","76.7340"],["83.2715","0"],["83.2814","176.6310"],["83.2815","0"],["83.2914","8.0430"],["83.2915","0"],["83.3014","123.0180"],["83.3015","0"],["83.3114","2.5270"],["83.3115","0"],["83.3214","99.2740"],["83.3215","0"],["83.3414","4.8930"],["83.3415","0"],["83.3514","137.1650"],["83.3515","0"],["83.3614","8.4000"],["83.3615","0"],["83.3714","2.8000"],["83.3715","0"],["83.3814","180.0000"],["83.3815","0"],["83.4114","180.0000"],["83.4115","0"],["83.4214","2.3240"],["83.4215","0"],["83.4314","180.0000"],["83.4315","0"],["83.4414","0.1330"],["83.4415","0"],["83.4514","140.0700"],["83.4515","0"],["83.4614","2.8980"],["83.4615","0"],["83.4814","78.7010"],["83.4815","0"],["83.4914","2.0440"],["83.4915","0"],["83.5114","2.9680"],["83.5115","0"],["83.5214","0.2660"],["83.5215","0"],["83.5314","180.0000"],["83.5315","0"],["83.5414","159.1450"],["83.5415","0"],["83.5514","90.0760"],["83.5515","0"],["83.5614","1.8970"],["83.5615","0"],["83.5714","0.2660"],["83.5715","0"],["83.5814","180.0000"],["83.5815","0"],["83.5914","13.6080"],["83.5915","0"],["83.6014","128.3590"],["83.6015","0"],["83.6114","104.9860"],["83.6115","0"],["83.6214","5.0610"],["83.6215","0"],["83.6315","0"],["83.6415","0"],["83.6515","0"],["83.6615","0"],["87.9641","0.3833"],["88.0066","0"],["88.0471","0.8167"],["88.0897","0"],["88.1301","0.1833"],["88.1728","0"],["88.2131","0.5500"],["88.2559","0"],["88.2961","0.2167"],["88.3390","0"],["88.3791","0.4500"],["88.4221","0"],["88.4621","0.6500"],["88.5052","0"],["88.5451","0.4833"],["88.5883","0"],["88.6281","0.6167"],["88.6714","0"],["88.7111","0.2500"],["88.7545","0"],["88.7941","0.7167"],["88.8376","0"],["88.8771","0.6833"],["88.9207","0"],["88.9601","0.5167"],["89.0038","0"],["89.0431","0.7500"],["89.0869","0"],["89.1261","0.3167"],["89.1700","0"],["89.2091","0.4167"],["89.2531","0"],["89.2921","0.2833"],["89.3362","0"],["89.3751","0.7833"],["89.4193","0"],["89.4581","0.5833"],["89.5024","0"],["89.5411","0.3500"],["89.5855","0"]],"bids":[["82.9285","0"],["82.9185","0"],["82.9085","0"],["82.8985","0"],["82.8886","1.6870"],["82.8885","0"],["82.8786","35.9870"],["82.8785","0"],["82.8686","19.8100"],["82.8685","0"],["82.8586","46.0670"],["82.8585","0"],["82.8486","169.3440"],["82.8485","0"],["82.8386","154.4970"],["82.8385","0"],["82.8286","64.8200"],["82.8285","0"],["82.8186","44.5900"],["82.8185","0"],["82.8086","119.3990"],["82.8085","0"],["82.7986","180.0000"],["82.7985","0"],["82.7886","180.0000"],["82.7885","0"],["82.7786","180.0000"],["82.7785","0"],["82.7686","180.0000"],["82.7685","0"],["82.7586","180.0000"],["82.7585","0"],["82.7486","180.0000"],["82.7485","0"],["82.7386","70.1820"],["82.7385","0"],["82.7286","173.2640"],["82.7285","0"],["82.7186","121.4850"],["82.7185","0"],["82.7086","92.3860"],["82.7085","0"],["82.6986","96.4600"],["82.6985","0"],["82.6886","180.0000"],["82.6885","0"],["82.6786","174.7410"],["82.6785","0"],["82.6686","88.0810"],["82.6685","0"],["82.6586","180.0000"],["82.6585","0"],["82.6486","180.0000"],["82.6485","0"],["82.6386","180.0000"],["82.6385","0"],["82.6286","86.7930"],["82.6285","0"],["82.6186","180.0000"],["82.6185","0"],["82.6086","38.0520"],["82.6085","0"],["82.5986","113.0920"],["82.5985","0"],["82.5886","33.6280"],["82.5885","0"],["82.5786","30.3380"],["82.5785","0"],["82.5686","180.0000"],["82.5685","0"],["82.5586","163.6600"],["82.5585","0"],["82.5486","137.4940"],["82.5485","0"],["82.5386","143.5980"],["82.5385","0"],["82.5286","21.0210"],["82.5285","0"],["82.5186","180.0000"],["82.5185","0"],["82.5086","180.0000"],["82.5085","0"],["82.4986","15.5190"],["82.4985","0"],["82.4886","130.8440"],["82.4885","0"],["82.4786","114.2470"],["82.4785","0"],["82.4686","180.0000"],["82.4685","0"],["82.4586","83.9930"],["82.4585","0"],["82.4486","92.0360"],["82.4485","0"],["82.4386","3.4370"],["82.4385","0"],["82.4286","10.7590"],["82.4186","54.2780"],["82.4086","180.0000"],["82.3986","7.0560"],["78.0435","0"],["78.0059","0.8167"],["77.9604","0"],["77.9229","0.5500"],["77.8773","0"],["77.8399","0.6500"],["77.7942","0"],["77.7569","0.3500"],["77.7111","0"],["77.6739","0.5167"],["77.6280","0"],["77.5909","0.4167"],["77.5449","0"],["77.5079","0.2833"],["77.4618","0"],["77.4249","0.6167"],["77.3787","0"],["77.3419","0.2167"],["77.2956","0"],["77.2589","0.4833"],["77.2125","0"],["77.1759","0.6833"],["77.1294","0"],["77.0929","0.5833"],["77.0463","0"],["77.0099","0.4500"],["76.9632","0"],["76.9269","0.3167"],["76.8801","0"],["76.8439","0.3833"],["76.7970","0"],["76.7609","0.7500"],["76.7139","0"],["76.6779","0.2500"],["76.6308","0"],["76.5949","0.7833"],["76.5477","0"],["76.5119","0.1833"],["76.4646","0"],["76.4289","0.7167"]],"checksum":461474766,"ts":"1649290088547"}]}
1649290088.791287: {"action":"update","arg":{"instType":"sp","channel":"books","instId":"CULTUSDT"},"data":[{"asks":[["0.00003614","520000"],["0.00003618","333333"],["0.00003622","360000"],["0.00003626","626667"],["0.00003630","600000"],["0.00003634","226667"],["0.00003638","253333"],["0.00003642","200000"],["0.00003646","420390"],["0.00003650","493333"],["0.00003654","306667"],["0.00003658","386667"],["0.00003666","573333"],["0.00003670","440000"],["0.00003674","413333"],["0.00003678","173333"],["0.00003682","653333"],["0.00003686","546667"],["0.00003690","280000"]],"bids":[["0.00003471","600000"],["0.00003467","1688564"],["0.00003463","200000"],["0.00003455","1041487"],["0.00003451","520000"],["0.00003447","280000"],["0.00003443","413333"],["0.00003439","626667"],["0.00003435","226667"],["0.00003431","146667"],["0.00003427","173333"],["0.00003423","333333"],["0.00003415","360000"],["0.00003411","440000"],["0.00003407","573333"],["0.00003403","253333"],["0.00003399","306667"],["0.00003395","493333"]],"checksum":850328939,"ts":"1649290088769"}]}
1649290088.7976582: {"action":"update","arg":{"instType":"sp","channel":"books","instId":"SUNUSDT"},"data":[{"asks":[["0.01508","8953"],["0.01509","37087"],["0.01510","386005"],["0.01511","367203"],["0.01512","445743"],["0.01516","11609"],["0.01523","1990"],["0.01581","4833"],["0.01582","0"],["0.01583","2833"],["0.01584","0"],["0.01585","5500"],["0.01586","0"],["0.01587","4500"],["0.01588","0"],["0.01589","4167"],["0.01590","0"],["0.01591","3500"],["0.01592","0"],["0.01593","5833"],["0.01594","0"],["0.01595","7167"],["0.01596","0"],["0.01597","6167"],["0.01598","0"],["0.01599","8167"],["0.01600","0"],["0.01601","1833"],["0.01602","0"],["0.01603","5167"],["0.01604","0"],["0.01605","7833"],["0.01606","0"],["0.01607","2167"],["0.01608","0"],["0.01609","3833"],["0.01610","0"],["0.01611","3167"],["0.01612","0"],["0.01613","2500"],["0.01614","0"],["0.01615","7500"],["0.01616","0"],["0.01617","6833"],["0.01618","0"],["0.01619","6500"],["0.01620","0"]],"bids":[["0.01504","0"],["0.01503","176400"],["0.01502","153677"],["0.01501","613330"],["0.01499","1322912"],["0.01498","104473"],["0.01496","402983"],["0.01494","24096"],["0.01493","1595"],["0.01488","4326"],["0.01450","15637"],["0.01430","5500"],["0.01428","7833"],["0.01426","3167"],["0.01424","1833"],["0.01422","4833"],["0.01420","3500"],["0.01418","3833"],["0.01416","6500"],["0.01414","8167"],["0.01412","6167"],["0.01410","2500"],["0.01408","6833"],["0.01406","4167"],["0.01404","7167"],["0.01402","4500"],["0.01400","7500"],["0.01398","5167"],["0.01396","2167"],["0.01394","2833"],["0.01392","5833"]],"checksum":-460040149,"ts":"1649290088774"}]}
1649290088.803379: {"action":"update","arg":{"instType":"sp","channel":"books","instId":"EOSUSDT"},"data":[{"asks":[["2.4419","1978.2900"],["2.4422","0"],["2.4429","3001.7582"],["2.4432","988.1596"],["2.4439","5085.1017"],["2.4440","726.6754"],["2.4444","0"],["2.4469","3295.1413"],["2.4470","1440.7266"],["2.4567","469.0476"],["2.4572","511.9048"],["2.4577","459.5238"],["2.4582","545.2381"],["2.4587","497.6190"],["2.4592","526.1905"],["2.4597","478.5714"],["2.4602","483.3333"],["2.4607","535.7143"],["2.4612","521.4286"],["2.4617","492.8571"],["2.4622","473.8095"],["2.4627","454.7619"],["2.4632","502.3810"],["2.4637","464.2857"],["2.4642","530.9524"],["2.4647","507.1429"],["2.4652","516.6667"],["2.4657","540.4762"],["2.4662","488.0952"]],"bids":[["2.4369","2646.2522"],["2.4367","0"],["2.4365","0"],["2.4363","745.4685"],["2.4362","57.2400"],["2.4361","999.0675"],["2.4351","1346.1642"],["2.4341","2823.6723"],["2.4336","2563.0360"],["2.4331","3400.8909"],["2.4321","4500.6994"],["2.4320","937.1197"],["2.4225","459.5238"],["2.4220","473.8095"],["2.4215","521.4286"],["2.4210","526.1905"],["2.4205","464.2857"],["2.4200","497.6190"],["2.4195","540.4762"],["2.4190","502.3810"],["2.4185","492.8571"],["2.4180","488.0952"],["2.4175","507.1429"],["2.4170","511.9048"],["2.4165","530.9524"],["2.4160","469.0476"],["2.4155","483.3333"],["2.4150","545.2381"],["2.4145","535.7143"],["2.4140","454.7619"],["2.4135","516.6667"],["2.4130","478.5714"]],"checksum":736262406,"ts":"1649290088781"}]}
1649290088.842964: {"action":"update","arg":{"instType":"sp","channel":"books","instId":"GOGUSDT"},"data":[{"asks":[["0.5625","8.8899"],["0.5637","10.3333"],["0.5643","8.8615"],["0.5649","8.8521"],["0.5655","2346.8000"],["0.5661","16.3333"],["0.5667","12.3333"],["0.5673","9.6667"],["0.5679","13.6667"],["0.5685","8.7961"],["0.5691","11.0000"],["0.5697","11.6667"],["0.5703","8.7683"],["0.5709","15.6667"],["0.5715","15.0000"],["0.5721","9.0000"],["0.5733","14.3333"],["0.5739","8.7133"]],"bids":[["0.5506","16.3333"],["0.5500","9.0919"],["0.5494","9.6667"],["0.5488","10.3333"],["0.5482","3681.5667"],["0.5476","13.0000"],["0.5464","11.6667"],["0.5458","9.1619"],["0.5452","9.1719"],["0.5440","13.6667"],["0.5434","15.0000"],["0.5428","9.2125"],["0.5422","9.2227"],["0.5416","14.3333"],["0.5410","12.3333"],["0.5398","11.0000"]],"checksum":1334763350,"ts":"1649290088814"}]}
1649290089.0457149: {"action":"update","arg":{"instType":"sp","channel":"books","instId":"HOTUSDT"},"data":[{"asks":[["0.0056350","77560.2000"],["0.0056360","159896.7000"],["0.0056370","240304.5000"],["0.0056410","0"],["0.0056420","24149.7000"],["0.0056430","175683.6000"],["0.0056440","258246.0000"],["0.0056610","97644.1500"],["0.0056620","0"],["0.0056630","371034.9000"],["0.0056670","281721.6000"],["0.0056930","800000.0000"],["0.0059070","4750.0000"],["0.0059090","0"],["0.0059130","7750.0000"],["0.0059150","0"],["0.0059190","12250.0000"],["0.0059210","0"],["0.0059250","2750.0000"],["0.0059270","0"],["0.0059310","9250.0000"],["0.0059330","0"],["0.0059370","7250.0000"],["0.0059390","0"],["0.0059430","6250.0000"],["0.0059450","0"],["0.0059490","8250.0000"],["0.0059510","0"],["0.0059550","6750.0000"],["0.0059570","0"],["0.0059610","3750.0000"],["0.0059630","0"],["0.0059670","5750.0000"],["0.0059690","0"],["0.0059730","3250.0000"],["0.0059750","0"],["0.0059790","5250.0000"],["0.0059810","0"],["0.0059850","10750.0000"],["0.0059870","0"],["0.0059910","10250.0000"],["0.0059930","0"],["0.0059970","11750.0000"],["0.0059990","0"],["0.0060030","11250.0000"],["0.0060050","0"],["0.0060090","9750.0000"],["0.0060110","0"],["0.0060150","4250.0000"],["0.0060170","0"],["0.0060210","8750.0000"],["0.0060230","0"]],"bids":[["0.0056200","0"],["0.0056190","0"],["0.0056180","0"],["0.0056170","0"],["0.0056150","153378.4500"],["0.0056140","56785.5000"],["0.0056110","721200.6000"],["0.0056090","98658.4500"],["0.0056080","239769.0000"],["0.0056070","0"],["0.0056060","190426.5000"],["0.0056040","800000.0000"],["0.0055690","623335.5000"],["0.0055610","250792.2000"],["0.0055600","294261.3000"],["0.0055590","215988.7500"],["0.0055580","428472.9000"],["0.0055570","546189.3000"],["0.0053460","0"],["0.0053430","8750.0000"],["0.0053400","0"],["0.0053370","5250.0000"],["0.0053340","0"],["0.0053310","4250.0000"],["0.0053280","0"],["0.0053250","6750.0000"],["0.0053220","0"],["0.0053190","11250.0000"],["0.0053160","0"],["0.0053130","6250.0000"],["0.0053100","0"],["0.0053070","8250.0000"],["0.0053040","0"],["0.0053010","12250.0000"],["0.0052980","0"],["0.0052950","5750.0000"],["0.0052920","0"],["0.0052890","3750.0000"],["0.0052860","0"],["0.0052830","3250.0000"],["0.0052800","0"],["0.0052770","10250.0000"],["0.0052740","0"],["0.0052710","9750.0000"],["0.0052680","0"],["0.0052650","10750.0000"],["0.0052620","0"],["0.0052590","4750.0000"],["0.0052560","0"],["0.0052530","2750.0000"],["0.0052500","0"],["0.0052470","9250.0000"],["0.0052440","0"],["0.0052410","7250.0000"],["0.0052380","0"],["0.0052350","7750.0000"],["0.0052320","0"],["0.0052290","11750.0000"]],"checksum":1532419295,"ts":"1649290089015"}]}
1649290089.0948212: {"action":"update","arg":{"instType":"sp","channel":"books","instId":"STGUSDT"},"data":[{"asks":[["3.034","1.920"],["3.037","2.554"],["3.040","1.646"],["3.043","3.188"],["3.046","3.442"],["3.049","5.866"],["3.052","1.639"],["3.055","2.935"],["3.061","1.634"],["3.064","3.569"],["3.067","1.631"],["3.070","3.315"],["3.073","2.174"],["3.076","2.301"],["3.079","4.063"],["3.082","2.428"],["3.085","2.808"],["3.088","3.062"],["3.094","2.047"],["3.100","1.793"]],"bids":[["2.861","15.358"],["2.744","1.823"],["2.741","1.825"],["2.738","19.752"],["2.735","2.754"],["2.732","99.746"],["2.726","73.529"],["2.723","1.837"],["2.720","1.839"],["2.717","2.108"],["2.714","2.323"],["2.711","1.845"],["2.708","2.431"],["2.705","2.538"],["2.702","1.851"],["2.699","1.892"],["2.696","94.354"],["2.690","2.862"],["2.684","1.864"],["2.681","2.646"],["2.675","3.185"],["2.672","3.077"]],"checksum":603911647,"ts":"1649290089058"}]}
1649290089.1461592: {"action":"update","arg":{"instType":"sp","channel":"books","instId":"AVAXUSDT"},"data":[{"asks":[["83.0614","127.7080"],["83.0714","22.2320"],["83.0814","10.2340"],["83.0914","52.7730"],["83.1114","144.8930"],["83.1214","117.5230"],["83.1314","180.0000"],["83.1714","6.7900"],["83.1814","131.0330"],["83.2314","56.5180"],["83.2414","145.3200"],["83.2914","4.2000"],["83.5114","13.8250"],["83.6114","0"],["83.6214","0"],["87.9430","0.7500"],["87.9641","0"],["88.0260","0.6500"],["88.0471","0"],["88.1090","0.4167"],["88.1301","0"],["88.1920","0.3500"],["88.2131","0"],["88.2750","0.4500"],["88.2961","0"],["88.3580","0.3833"],["88.3791","0"],["88.4410","0.4833"],["88.4621","0"],["88.5240","0.8167"],["88.5451","0"],["88.6070","0.5167"],["88.6281","0"],["88.6900","0.6833"],["88.7111","0"],["88.7730","0.7167"],["88.7941","0"],["88.8560","0.1833"],["88.8771","0"],["88.9390","0.7833"],["88.9601","0"],["89.0220","0.5500"],["89.0431","0"],["89.1050","0.2167"],["89.1261","0"],["89.1880","0.2500"],["89.2091","0"],["89.2710","0.6167"],["89.2921","0"],["89.3540","0.5833"],["89.3751","0"],["89.4370","0.2833"],["89.4581","0"],["89.5200","0.3167"],["89.5411","0"]],"bids":[["82.8886","0"],["82.8786","0"],["82.8686","8.4280"],["82.8586","72.3730"],["82.8486","82.6840"],["82.8386","180.0000"],["82.8286","38.7730"],["82.8186","131.2920"],["82.8086","138.7400"],["82.7686","177.8770"],["82.7386","180.0000"],["82.7286","178.6750"],["82.6986","26.4600"],["82.6786","180.0000"],["82.6286","180.0000"],["82.3886","20.6500"],["82.3786","87.4440"],["78.0059","0"],["77.9871","0.3833"],["77.9229","0"],["77.9041","0.8167"],["77.8399","0"],["77.8211","0.5833"],["77.7569","0"],["77.7381","0.5167"],["77.6739","0"],["77.6551","0.4167"],["77.5909","0"],["77.5721","0.3500"],["77.5079","0"],["77.4891","0.4500"],["77.4249","0"],["77.4061","0.6167"],["77.3419","0"],["77.3231","0.2833"],["77.2589","0"],["77.2401","0.5500"],["77.1759","0"],["77.1571","0.3167"],["77.0929","0"],["77.0741","0.7833"],["77.0099","0"],["76.9911","0.1833"],["76.9269","0"],["76.9081","0.7167"],["76.8439","0"],["76.8251","0.2500"],["76.7609","0"],["76.7421","0.6833"],["76.6779","0"],["76.6591","0.6500"],["76.5949","0"],["76.5761","0.2167"],["76.5119","0"],["76.4931","0.7500"],["76.4289","0"],["76.4101","0.4833"]],"checksum":-175681734,"ts":"1649290089123"}]}
1649290089.340128: {"action":"update","arg":{"instType":"sp","channel":"books","instId":"EOSUSDT"},"data":[{"asks":[["2.4412","8.0482"],["2.4413","160.7102"],["2.4415","32.8332"],["2.4416","236.2500"],["2.4419","1299.1050"],["2.4420","0"],["2.4421","112.8066"],["2.4423","0"],["2.4424","1628.0513"],["2.4425","666.9777"],["2.4426","243.9737"],["2.4427","102.2113"],["2.4428","214.6005"],["2.4429","4109.6880"],["2.4430","1035.0000"],["2.4431","1165.9410"],["2.4432","161.7139"],["2.4433","590.3014"],["2.4434","330.3758"],["2.4435","922.2605"],["2.4436","1623.8519"],["2.4437","0"],["2.4438","1683.8415"],["2.4439","3806.9217"],["2.4440","2436.6754"],["2.4441","1470.8751"],["2.4442","1018.3795"],["2.4443","1992.8295"],["2.4444","2763.0000"],["2.4445","756.6867"],["2.4446","2414.4410"],["2.4447","2000.0258"],["2.4449","1719.8145"],["2.4450","0"],["2.4451","527.3753"],["2.4452","91.4355"],["2.4453","0"],["2.4454","1268.9251"],["2.4455","81.9135"],["2.4459","1944.5477"],["2.4461","1467.9106"],["2.4462","869.4480"],["2.4464","120.6000"],["2.4467","37.8900"],["2.4469","2980.1863"],["2.4562","530.9524"],["2.4567","459.5238"],["2.4572","483.3333"],["2.4577","540.4762"],["2.4582","473.8095"],["2.4587","464.2857"],["2.4592","521.4286"],["2.4597","488.0952"],["2.4602","492.8571"],["2.4607","516.6667"],["2.4612","511.9048"],["2.4617","502.3810"],["2.4622","507.1429"],["2.4627","478.5714"],["2.4632","454.7619"],["2.4637","469.0476"],["2.4642","535.7143"],["2.4647","545.2381"],["2.4652","526.1905"],["2.4657","497.6190"],["2.4662","0"]],"bids":[["2.4376","0"],["2.4374","0"],["2.4373","0"],["2.4372","0"],["2.4371","0"],["2.4369","0"],["2.4366","1042.3567"],["2.4365","2210.5440"],["2.4364","2103.3000"],["2.4363","389.4561"],["2.4362","35.0100"],["2.4361","940.8150"],["2.4360","82.1185"],["2.4359","1246.2959"],["2.4357","0"],["2.4356","206.9735"],["2.4355","71.9759"],["2.4354","1588.0739"],["2.4353","886.4741"],["2.4352","2081.4771"],["2.4351","261.8280"],["2.4350","108.8544"],["2.4349","2611.6493"],["2.4348","112.7434"],["2.4347","3600.0000"],["2.4346","2159.6316"],["2.4344","1209.6687"],["2.4343","1757.0517"],["2.4341","2434.6960"],["2.4340","98.2696"],["2.4336","1560.1695"],["2.4335","5477.1304"],["2.4334","439.2704"],["2.4333","17.2247"],["2.4331","2432.6709"],["2.4330","97.7841"],["2.4329","1804.1925"],["2.4327","0"],["2.4325","72.9188"],["2.4324","1700.7293"],["2.4321","6563.7189"],["2.4320","761.6197"],["2.4319","117.2138"],["2.4318","1330.7594"],["2.4317","868.2724"],["2.4316","1434.2981"],["2.4315","1150.2900"],["2.4225","0"],["2.4210","530.9524"],["2.4205","516.6667"],["2.4200","502.3810"],["2.4195","469.0476"],["2.4190","511.9048"],["2.4185","526.1905"],["2.4180","464.2857"],["2.4175","488.0952"],["2.4170","545.2381"],["2.4165","497.6190"],["2.4160","492.8571"],["2.4155","478.5714"],["2.4150","535.7143"],["2.4145","540.4762"],["2.4140","459.5238"],["2.4135","483.3333"],["2.4130","507.1429"],["2.4125","454.7619"]],"checksum":1184736983,"ts":"1649290089317"}]}
1649290089.382539: {"action":"update","arg":{"instType":"sp","channel":"books","instId":"SUNUSDT"},"data":[{"asks":[["0.01508","103119"],["0.01509","36637"],["0.01510","395919"],["0.01511","282415"],["0.01512","448279"],["0.01516","3847"],["0.01523","2035"],["0.01549","192465"],["0.01581","2500"],["0.01583","6833"],["0.01585","4500"],["0.01587","2167"],["0.01589","5500"],["0.01591","6167"],["0.01593","5167"],["0.01595","2833"],["0.01597","1833"],["0.01599","5833"],["0.01601","6500"],["0.01603","8167"],["0.01605","3833"],["0.01607","7833"],["0.01609","4833"],["0.01611","3500"],["0.01613","4167"],["0.01615","3167"],["0.01617","7167"],["0.01619","7500"]],"bids":[["0.01503","189879"],["0.01502","220146"],["0.01501","613539"],["0.01500","711428"],["0.01498","154476"],["0.01496","397613"],["0.01494","53598"],["0.01493","25705"],["0.01492","628139"],["0.01430","2167"],["0.01428","5833"],["0.01426","6500"],["0.01424","7833"],["0.01422","2833"],["0.01420","5167"],["0.01418","6833"],["0.01416","4167"],["0.01414","1833"],["0.01412","7167"],["0.01410","4500"],["0.01408","2500"],["0.01406","3167"],["0.01404","6167"],["0.01402","4833"],["0.01400","8167"],["0.01398","5500"],["0.01396","7500"],["0.01394","3500"],["0.01392","3833"]],"checksum":1396406953,"ts":"1649290089351"}]}
1649290089.382993: {"action":"update","arg":{"instType":"sp","channel":"books","instId":"GOGUSDT"},"data":[{"asks":[["0.5625","13.6667"],["0.5631","15.6667"],["0.5637","14.3333"],["0.5649","16.3333"],["0.5655","2345.4667"],["0.5661","8.8334"],["0.5667","8.8240"],["0.5673","11.0000"],["0.5679","8.8054"],["0.5685","9.6667"],["0.5691","12.3333"],["0.5697","10.3333"],["0.5709","8.7591"],["0.5715","8.7499"],["0.5721","15.0000"],["0.5727","13.0000"],["0.5733","9.0000"],["0.6068","16.8000"],["0.6418","0"]],"bids":[["0.5512","14.4000"],["0.5506","9.0820"],["0.5500","14.3333"],["0.5494","11.0000"],["0.5488","16.3333"],["0.5482","3675.5667"],["0.5476","9.1318"],["0.5464","9.1518"],["0.5446","12.3333"],["0.5434","11.6667"],["0.5422","15.6667"],["0.5416","9.2329"],["0.5410","10.3333"],["0.5404","15.0000"],["0.5398","9.2637"]],"checksum":-1745363614,"ts":"1649290089358"}]}
1649290089.388191: {"action":"update","arg":{"instType":"sp","channel":"books","instId":"CULTUSDT"},"data":[{"asks":[["0.00003614","573333"],["0.00003618","386667"],["0.00003622","253333"],["0.00003630","413333"],["0.00003634","653333"],["0.00003638","333333"],["0.00003642","440000"],["0.00003646","553723"],["0.00003650","200000"],["0.00003658","226667"],["0.00003662","600000"],["0.00003666","520000"],["0.00003670","546667"],["0.00003674","493333"],["0.00003678","360000"],["0.00003682","173333"],["0.00003686","146667"],["0.00003690","466667"]],"bids":[["0.00003471","386667"],["0.00003467","1635230"],["0.00003463","600000"],["0.00003459","333333"],["0.00003455","748154"],["0.00003451","173333"],["0.00003447","146667"],["0.00003443","653333"],["0.00003439","546667"],["0.00003435","440000"],["0.00003431","573333"],["0.00003427","253333"],["0.00003423","200000"],["0.00003419","226667"],["0.00003415","280000"],["0.00003411","306667"],["0.00003407","520000"],["0.00003403","626667"],["0.00003399","466667"],["0.00003395","413333"]],"checksum":2080229232,"ts":"1649290089366"}]}
1649290089.5504901: {"action":"update","arg":{"instType":"sp","channel":"books","instId":"HOTUSDT"},"data":[{"asks":[["0.0056340","47250.0000"],["0.0056380","606442.9500"],["0.0056390","119851.2000"],["0.0056400","55335.6000"],["0.0056420","160814.7000"],["0.0056430","22550.4000"],["0.0056440","0"],["0.0056450","140180.8500"],["0.0056490","252024.3000"],["0.0056500","146042.1000"],["0.0056580","336669.3000"],["0.0056610","157336.2000"],["0.0056630","245984.4000"],["0.0056660","339390.0000"],["0.0056690","32688.9000"],["0.0056860","38396.7000"],["0.0056910","0"],["0.0056930","0"],["0.0059050","6750.0000"],["0.0059070","0"],["0.0059110","4750.0000"],["0.0059130","0"],["0.0059170","7250.0000"],["0.0059190","0"],["0.0059230","7750.0000"],["0.0059250","0"],["0.0059290","11750.0000"],["0.0059310","0"],["0.0059350","10250.0000"],["0.0059370","0"],["0.0059410","2750.0000"],["0.0059430","0"],["0.0059470","4250.0000"],["0.0059490","0"],["0.0059530","9750.0000"],["0.0059550","0"],["0.0059590","12250.0000"],["0.0059610","0"],["0.0059650","3750.0000"],["0.0059670","0"],["0.0059710","5250.0000"],["0.0059730","0"],["0.0059770","8250.0000"],["0.0059790","0"],["0.0059830","10750.0000"],["0.0059850","0"],["0.0059890","8750.0000"],["0.0059910","0"],["0.0059950","11250.0000"],["0.0059970","0"],["0.0060010","9250.0000"],["0.0060030","0"],["0.0060070","6250.0000"],["0.0060090","0"],["0.0060130","3250.0000"],["0.0060150","0"],["0.0060190","5750.0000"],["0.0060210","0"]],"bids":[["0.0056150","0"],["0.0056140","89146.8000"],["0.0056130","49103.6400"],["0.0056120","124153.2000"],["0.0056110","800000.0000"],["0.0056100","5808.6000"],["0.0056090","209132.1000"],["0.0056080","129019.9500"],["0.0056060","513325.8000"],["0.0056050","99871.2000"],["0.0056030","119812.5300"],["0.0056020","244676.7000"],["0.0055960","504472.5000"],["0.0055950","160649.5500"],["0.0055830","68140.8900"],["0.0055820","122382.9000"],["0.0055690","617809.5000"],["0.0055620","40198.0500"],["0.0055560","800000.0000"],["0.0053430","0"],["0.0053420","9250.0000"],["0.0053370","0"],["0.0053360","12250.0000"],["0.0053310","0"],["0.0053300","11750.0000"],["0.0053250","0"],["0.0053240","9750.0000"],["0.0053190","0"],["0.0053180","8750.0000"],["0.0053130","0"],["0.0053120","6750.0000"],["0.0053070","0"],["0.0053060","6250.0000"],["0.0053010","0"],["0.0053000","4750.0000"],["0.0052950","0"],["0.0052940","7250.0000"],["0.0052890","0"],["0.0052880","3250.0000"],["0.0052830","0"],["0.0052820","10250.0000"],["0.0052770","0"],["0.0052760","8250.0000"],["0.0052710","0"],["0.0052700","5250.0000"],["0.0052650","0"],["0.0052640","3750.0000"],["0.0052590","0"],["0.0052580","2750.0000"],["0.0052530","0"],["0.0052520","4250.0000"],["0.0052470","0"],["0.0052460","10750.0000"],["0.0052410","0"],["0.0052400","11250.0000"],["0.0052350","0"],["0.0052340","7750.0000"],["0.0052290","0"],["0.0052280","5750.0000"]],"checksum":-299676708,"ts":"1649290089528"}]}
1649290089.645216: {"action":"update","arg":{"instType":"sp","channel":"books","instId":"STGUSDT"},"data":[{"asks":[["3.034","1.667"],["3.037","2.935"],["3.040","2.428"],["3.043","1.644"],["3.046","1.642"],["3.049","6.754"],["3.052","1.920"],["3.055","2.808"],["3.058","2.554"],["3.064","2.301"],["3.067","3.442"],["3.073","1.628"],["3.076","1.626"],["3.079","5.331"],["3.082","2.047"],["3.085","3.062"],["3.088","1.793"],["3.091","3.188"],["3.094","1.617"],["3.097","2.681"],["3.100","1.614"]],"bids":[["2.744","1.892"],["2.738","18.998"],["2.735","2.538"],["2.732","99.208"],["2.729","2.215"],["2.726","75.467"],["2.723","2.108"],["2.717","2.969"],["2.714","1.843"],["2.711","3.185"],["2.708","2.862"],["2.705","1.849"],["2.702","2.323"],["2.699","2.754"],["2.696","92.847"],["2.690","3.292"],["2.684","2.000"],["2.681","1.866"],["2.678","1.868"],["2.675","2.431"]],"checksum":-446858039,"ts":"1649290089610"}]}
1649290089.6862102: {"action":"update","arg":{"instType":"sp","channel":"books","instId":"AVAXUSDT"},"data":[{"asks":[["83.0614","133.5670"],["83.0814","3.5350"],["83.0914","55.6010"],["83.1014","57.3230"],["83.1214","180.0000"],["83.1414","36.0710"],["83.1514","43.2460"],["83.1614","169.1690"],["83.1714","9.3170"],["83.1814","116.9210"],["83.2214","87.2970"],["83.2314","26.3340"],["83.2714","6.6990"],["88.0260","0.6167"],["88.1090","0.6833"],["88.1920","0.3833"],["88.2750","0.5833"],["88.3580","0.3167"],["88.4410","0.7833"],["88.5240","0.3500"],["88.6070","0.6500"],["88.6900","0.2167"],["88.7730","0.4833"],["88.8560","0.7167"],["88.9390","0.4500"],["89.0220","0.1833"],["89.1050","0.4167"],["89.1880","0.8167"],["89.2710","0.5500"],["89.3540","0.2500"],["89.4370","0.5167"],["89.5200","0.2833"]],"bids":[["82.8086","131.9500"],["82.7886","80.8010"],["82.7686","174.2090"],["82.7386","133.7350"],["82.7186","130.7810"],["82.7086","119.5460"],["82.6686","79.6740"],["82.5786","74.3960"],["82.5586","180.0000"],["82.4586","92.3440"],["77.9871","0.6500"],["77.9041","0.3167"],["77.8211","0.7500"],["77.7381","0.2833"],["77.6551","0.8167"],["77.5721","0.5833"],["77.4891","0.7167"],["77.4061","0.2500"],["77.3231","0.7833"],["77.2401","0.4500"],["77.1571","0.4833"],["77.0741","0.4167"],["76.9911","0.3500"],["76.9081","0.6833"],["76.8251","0.2167"],["76.7421","0.1833"],["76.6591","0.3833"],["76.5761","0.5500"],["76.4931","0.6167"],["76.4101","0.5167"]],"checksum":679341511,"ts":"1649290089660"}]}
1649290089.85377: {"action":"update","arg":{"instType":"sp","channel":"books","instId":"EOSUSDT"},"data":[{"asks":[["2.4409","2567.4300"],["2.4410","35.0100"],["2.4411","158.3277"],["2.4412","270.3948"],["2.4413","151.5259"],["2.4415","71.8386"],["2.4416","104.4999"],["2.4419","4240.7550"],["2.4420","533.9098"],["2.4421","107.9947"],["2.4422","5117.5800"],["2.4423","153.0000"],["2.4425","1652.5145"],["2.4426","309.9737"],["2.4427","5279.1913"],["2.4428","1893.1125"],["2.4430","1614.9150"],["2.4431","1470.2100"],["2.4432","386.8093"],["2.4433","368.9460"],["2.4434","607.1570"],["2.4435","1502.7605"],["2.4436","1528.9019"],["2.4440","2385.0000"],["2.4441","436.2508"],["2.4442","599.8795"],["2.4444","0"],["2.4445","642.3729"],["2.4446","2361.4206"],["2.4447","1419.5258"],["2.4466","0"],["2.4467","0"],["2.4468","0"],["2.4469","0"],["2.4470","0"],["2.4559","535.7143"],["2.4562","0"],["2.4564","540.4762"],["2.4567","0"],["2.4569","492.8571"],["2.4572","0"],["2.4574","454.7619"],["2.4577","0"],["2.4579","521.4286"],["2.4582","0"],["2.4584","511.9048"],["2.4587","0"],["2.4589","502.3810"],["2.4592","0"],["2.4594","488.0952"],["2.4597","0"],["2.4599","530.9524"],["2.4602","0"],["2.4604","497.6190"],["2.4607","0"],["2.4609","516.6667"],["2.4612","0"],["2.4614","507.1429"],["2.4617","0"],["2.4619","483.3333"],["2.4622","0"],["2.4624","526.1905"],["2.4627","0"],["2.4629","464.2857"],["2.4632","0"],["2.4634","473.8095"],["2.4637","0"],["2.4639","545.2381"],["2.4642","0"],["2.4644","459.5238"],["2.4647","0"],["2.4649","478.5714"],["2.4652","0"],["2.4654","469.0476"],["2.4657","0"]],"bids":[["2.4370","0"],["2.4366","213.6573"],["2.4362","0"],["2.4355","0"],["2.4354","1060.4237"],["2.4352","8.0532"],["2.4351","725.8064"],["2.4350","0"],["2.4349","320.2880"],["2.4348","150.5348"],["2.4346","2041.5066"],["2.4344","4992.3273"],["2.4343","1406.0413"],["2.4341","4937.6435"],["2.4340","1259.2696"],["2.4338","415.6433"],["2.4337","1010.6236"],["2.4336","1722.5710"],["2.4335","4874.1304"],["2.4334","510.6939"],["2.4329","327.7425"],["2.4328","297.1831"],["2.4326","794.8981"],["2.4324","1364.2764"],["2.4322","1809.0000"],["2.4321","6344.4126"],["2.4317","1541.2610"],["2.4314","292.8176"],["2.4313","1298.3452"],["2.4312","385.2466"],["2.4220","0"],["2.4216","540.4762"],["2.4215","0"],["2.4211","478.5714"],["2.4210","0"],["2.4206","473.8095"],["2.4205","0"],["2.4201","502.3810"],["2.4200","0"],["2.4196","459.5238"],["2.4195","0"],["2.4191","454.7619"],["2.4190","0"],["2.4186","483.3333"],["2.4185","0"],["2.4181","492.8571"],["2.4180","0"],["2.4176","469.0476"],["2.4175","0"],["2.4171","464.2857"],["2.4170","0"],["2.4166","526.1905"],["2.4165","0"],["2.4161","530.9524"],["2.4160","0"],["2.4156","521.4286"],["2.4155","0"],["2.4151","545.2381"],["2.4150","0"],["2.4146","507.1429"],["2.4145","0"],["2.4141","497.6190"],["2.4140","0"],["2.4136","535.7143"],["2.4135","0"],["2.4131","488.0952"],["2.4130","0"],["2.4126","511.9048"],["2.4125","0"],["2.4121","516.6667"]],"checksum":2065668684,"ts":"1649290089831"}]}
1649290089.897102: {"action":"update","arg":{"instType":"sp","channel":"books","instId":"CULTUSDT"},"data":[{"asks":[["0.00003614","626667"],["0.00003618","440000"],["0.00003622","466667"],["0.00003626","386667"],["0.00003630","520000"],["0.00003634","200000"],["0.00003638","146667"],["0.00003642","333333"],["0.00003646","580390"],["0.00003650","413333"],["0.00003654","493333"],["0.00003658","360000"],["0.00003662","573333"],["0.00003666","600000"],["0.00003670","653333"],["0.00003674","173333"],["0.00003678","226667"],["0.00003682","280000"],["0.00003686","253333"],["0.00003690","546667"]],"bids":[["0.00003471","626667"],["0.00003467","1581897"],["0.00003463","386667"],["0.00003455","908154"],["0.00003451","413333"],["0.00003447","200000"],["0.00003443","226667"],["0.00003439","573333"],["0.00003435","493333"],["0.00003431","546667"],["0.00003427","306667"],["0.00003423","280000"],["0.00003419","146667"],["0.00003415","600000"],["0.00003411","253333"],["0.00003407","173333"],["0.00003403","653333"],["0.00003399","360000"],["0.00003395","466667"]],"checksum":-1203082080,"ts":"1649290089871"}]}
1649290089.909867: {"action":"update","arg":{"instType":"sp","channel":"books","instId":"GOGUSDT"},"data":[{"asks":[["0.5625","8.8899"],["0.5631","8.8804"],["0.5637","13.6667"],["0.5643","14.3333"],["0.5649","9.0000"],["0.5655","2340.8000"],["0.5661","10.3333"],["0.5667","15.0000"],["0.5673","8.8147"],["0.5685","8.7961"],["0.5697","11.0000"],["0.5703","9.6667"],["0.5709","16.3333"],["0.5715","13.0000"],["0.5721","8.7407"],["0.5727","11.6667"],["0.5733","8.7224"],["0.5739","15.6667"]],"bids":[["0.5512","9.0721"],["0.5500","11.0000"],["0.5494","9.1018"],["0.5488","15.0000"],["0.5482","3678.2333"],["0.5476","15.6667"],["0.5470","14.3333"],["0.5452","13.6667"],["0.5446","9.1821"],["0.5440","9.6667"],["0.5434","9.2023"],["0.5428","13.0000"],["0.5422","9.2227"],["0.5416","11.6667"],["0.5404","16.3333"]],"checksum":50317601,"ts":"1649290089885"}]}
1649290089.921778: {"action":"update","arg":{"instType":"sp","channel":"books","instId":"SUNUSDT"},"data":[{"asks":[["0.01508","8953"],["0.01509","37087"],["0.01510","399556"],["0.01511","367203"],["0.01512","445855"],["0.01517","3671970"],["0.01520","0"],["0.01523","1990"],["0.01549","197952"],["0.01567","5116"],["0.01581","3167"],["0.01583","8167"],["0.01585","4167"],["0.01587","4500"],["0.01589","3833"],["0.01591","6500"],["0.01593","2833"],["0.01595","7167"],["0.01597","6833"],["0.01599","3500"],["0.01601","5500"],["0.01603","5167"],["0.01605","1833"],["0.01607","6167"],["0.01609","7833"],["0.01611","5833"],["0.01613","7500"],["0.01615","2167"],["0.01617","4833"],["0.01619","2500"]],"bids":[["0.01502","153677"],["0.01501","585230"],["0.01499","1323214"],["0.01494","5415"],["0.01430","2833"],["0.01428","4500"],["0.01426","5167"],["0.01424","4167"],["0.01422","7500"],["0.01420","7167"],["0.01418","5500"],["0.01416","4833"],["0.01414","6500"],["0.01412","2167"],["0.01410","1833"],["0.01408","6833"],["0.01406","8167"],["0.01404","3500"],["0.01402","2500"],["0.01400","7833"],["0.01398","5833"],["0.01396","3167"],["0.01394","3833"],["0.01392","6167"]],"checksum":-39980574,"ts":"1649290089900"}]}
1649290090.125619: {"action":"update","arg":{"instType":"sp","channel":"books","instId":"HOTUSDT"},"data":[{"asks":[["0.0056340","1601.1000"],["0.0056370","137505.1500"],["0.0056380","713635.6500"],["0.0056400","22550.4000"],["0.0056440","12006.9000"],["0.0056460","243657.9000"],["0.0056580","259421.8500"],["0.0056820","7146.0000"],["0.0056830","210522.1500"],["0.0056890","0"],["0.0059050","0"],["0.0059060","8750.0000"],["0.0059110","0"],["0.0059120","3750.0000"],["0.0059170","0"],["0.0059180","5750.0000"],["0.0059230","0"],["0.0059240","7250.0000"],["0.0059290","0"],["0.0059300","4750.0000"],["0.0059350","0"],["0.0059360","11750.0000"],["0.0059410","0"],["0.0059420","9750.0000"],["0.0059470","0"],["0.0059480","4250.0000"],["0.0059530","0"],["0.0059540","3250.0000"],["0.0059590","0"],["0.0059600","9250.0000"],["0.0059650","0"],["0.0059660","6750.0000"],["0.0059710","0"],["0.0059720","10750.0000"],["0.0059770","0"],["0.0059780","6250.0000"],["0.0059830","0"],["0.0059840","8250.0000"],["0.0059890","0"],["0.0059900","5250.0000"],["0.0059950","0"],["0.0059960","2750.0000"],["0.0060010","0"],["0.0060020","7750.0000"],["0.0060070","0"],["0.0060080","12250.0000"],["0.0060130","0"],["0.0060140","10250.0000"],["0.0060190","0"],["0.0060200","11250.0000"]],"bids":[["0.0056160","139413.6000"],["0.0056150","142330.5000"],["0.0056140","127642.5000"],["0.0056130","112034.7900"],["0.0056120","527140.8000"],["0.0056100","10017.0000"],["0.0056090","195363.4500"],["0.0056070","800000.0000"],["0.0056060","800000.0000"],["0.0056020","298847.2500"],["0.0055990","102303.4500"],["0.0055980","301210.2000"],["0.0055970","117578.2500"],["0.0055950","100403.1000"],["0.0055940","334811.7000"],["0.0055890","293314.9500"],["0.0055840","282049.2000"],["0.0055640","84685.5000"],["0.0055580","0"],["0.0055570","0"],["0.0055560","0"],["0.0053430","7750.0000"],["0.0053420","0"],["0.0053370","12250.0000"],["0.0053360","0"],["0.0053310","6750.0000"],["0.0053300","0"],["0.0053250","3750.0000"],["0.0053240","0"],["0.0053190","8250.0000"],["0.0053180","0"],["0.0053130","7250.0000"],["0.0053120","0"],["0.0053070","9750.0000"],["0.0053060","0"],["0.0053010","11250.0000"],["0.0053000","0"],["0.0052950","10250.0000"],["0.0052940","0"],["0.0052890","11750.0000"],["0.0052880","0"],["0.0052830","2750.0000"],["0.0052820","0"],["0.0052770","8750.0000"],["0.0052760","0"],["0.0052710","9250.0000"],["0.0052700","0"],["0.0052650","4750.0000"],["0.0052640","0"],["0.0052590","5750.0000"],["0.0052580","0"],["0.0052530","4250.0000"],["0.0052520","0"],["0.0052470","6250.0000"],["0.0052460","0"],["0.0052410","3250.0000"],["0.0052400","0"],["0.0052350","10750.0000"],["0.0052340","0"],["0.0052290","5250.0000"],["0.0052280","0"]],"checksum":-262674350,"ts":"1649290090102"}]}
1649290090.188131: {"action":"snapshot","arg":{"instType":"sp","channel":"ticker","instId":"EOSUSDT"},"data":[{"instId":"EOSUSDT","last":"2.4393","open24h":"2.5667","high24h":"2.5767","low24h":"2.4155","bestBid":"2.436600","bestAsk":"2.440800","baseVolume":"145522.9643","quoteVolume":"378718.0033","ts":1649290090085,"labeId":0}]}
1649290090.1882198: {"action":"update","arg":{"instType":"sp","channel":"books","instId":"STGUSDT"},"data":[{"asks":[["3.034","1.649"],["3.037","2.554"],["3.040","1.793"],["3.043","3.188"],["3.046","2.174"],["3.049","5.866"],["3.052","1.639"],["3.055","3.062"],["3.058","1.636"],["3.064","1.667"],["3.067","1.631"],["3.070","2.935"],["3.073","2.047"],["3.079","4.570"],["3.082","3.315"],["3.085","2.808"],["3.088","2.301"],["3.091","3.442"],["3.094","1.920"],["3.097","2.428"],["3.100","3.569"]],"bids":[["2.744","3.077"],["2.738","20.506"],["2.735","1.829"],["2.732","100.393"],["2.729","1.833"],["2.726","75.252"],["2.723","1.837"],["2.717","2.323"],["2.711","2.108"],["2.708","2.538"],["2.702","2.646"],["2.699","1.854"],["2.696","93.385"],["2.693","1.892"],["2.690","2.215"],["2.684","1.864"],["2.681","2.969"],["2.678","3.292"],["2.675","1.870"],["2.672","3.185"]],"checksum":-518693229,"ts":"1649290090165"}]}
1649290090.222784: {"action":"update","arg":{"instType":"sp","channel":"books","instId":"AVAXUSDT"},"data":[{"asks":[["83.0614","0"],["83.0714","0"],["83.0814","0"],["83.0914","0"],["83.1014","0"],["83.1015","6.6990"],["83.1114","0"],["83.1115","35.8120"],["83.1214","0"],["83.1215","163.4150"],["83.1314","0"],["83.1315","180.0000"],["83.1414","0"],["83.1415","78.1900"],["83.1514","0"],["83.1515","101.7030"],["83.1614","0"],["83.1615","174.4610"],["83.1714","0"],["83.1715","9.3170"],["83.1814","0"],["83.1815","97.7410"],["83.1914","0"],["83.1915","180.0000"],["83.2014","0"],["83.2015","7.1610"],["83.2114","0"],["83.2115","11.3890"],["83.2214","0"],["83.2215","87.2970"],["83.2314","0"],["83.2315","26.3340"],["83.2414","0"],["83.2415","145.3200"],["83.2514","0"],["83.2515","180.0000"],["83.2614","0"],["83.2615","142.2890"],["83.2714","0"],["83.2715","6.6990"],["83.2814","0"],["83.2815","176.6310"],["83.2914","0"],["83.2915","4.2000"],["83.3014","0"],["83.3015","123.0180"],["83.3114","0"],["83.3115","7.1540"],["83.3214","0"],["83.3215","99.2740"],["83.3414","0"],["83.3415","0.2660"],["83.3514","0"],["83.3515","137.1650"],["83.3614","0"],["83.3615","8.4000"],["83.3714","0"],["83.3715","2.8000"],["83.3814","0"],["83.3815","180.0000"],["83.4114","0"],["83.4115","180.0000"],["83.4214","0"],["83.4215","2.3240"],["83.4314","0"],["83.4315","180.0000"],["83.4414","0"],["83.4415","0.1330"],["83.4514","0"],["83.4515","140.0700"],["83.4614","0"],["83.4615","2.8980"],["83.4814","0"],["83.4815","78.7010"],["83.4914","0"],["83.4915","2.0440"],["83.5114","0"],["83.5115","11.0600"],["83.5214","0"],["83.5215","0.2660"],["83.5314","0"],["83.5315","180.0000"],["83.5414","0"],["83.5415","159.1450"],["83.5514","0"],["83.5515","90.0760"],["83.5614","0"],["83.5615","1.8970"],["83.5714","0"],["83.5715","0.2660"],["83.5814","0"],["83.5815","180.0000"],["83.5914","0"],["83.5915","13.6080"],["83.6014","0"],["83.6015","128.3590"],["83.6115","104.9860"],["83.6215","5.0610"],["83.6315","0.9800"],["83.6415","0.7280"],["87.9430","0"],["87.9853","0.4500"],["88.0260","0"],["88.0684","0.5500"],["88.1090","0"],["88.1515","0.2167"],["88.1920","0"],["88.2346","0.3500"],["88.2750","0"],["88.3177","0.6500"],["88.3580","0"],["88.4008","0.5833"],["88.4410","0"],["88.4839","0.8167"],["88.5240","0"],["88.5670","0.2833"],["88.6070","0"],["88.6501","0.6167"],["88.6900","0"],["88.7332","0.2500"],["88.7730","0"],["88.8163","0.7500"],["88.8560","0"],["88.8994","0.3167"],["88.9390","0"],["88.9825","0.4167"],["89.0220","0"],["89.0656","0.7167"],["89.1050","0"],["89.1487","0.6833"],["89.1880","0"],["89.2318","0.3833"],["89.2710","0"],["89.3149","0.4833"],["89.3540","0"],["89.3980","0.5167"],["89.4370","0"],["89.4811","0.1833"],["89.5200","0"],["89.5642","0.7833"]],"bids":[["82.9085","10.5910"],["82.8985","10.5910"],["82.8885","23.7230"],["82.8785","76.7760"],["82.8686","0"],["82.8685","19.0190"],["82.8586","0"],["82.8585","115.2060"],["82.8486","0"],["82.8485","84.8260"],["82.8386","0"],["82.8385","44.0510"],["82.8286","0"],["82.8285","5.2570"],["82.8186","0"],["82.8185","46.9560"],["82.8086","0"],["82.8085","180.0000"],["82.7986","0"],["82.7985","180.0000"],["82.7886","0"],["82.7885","35.8330"],["82.7786","0"],["82.7785","180.0000"],["82.7686","0"],["82.7685","174.2090"],["82.7586","0"],["82.7585","180.0000"],["82.7486","0"],["82.7485","180.0000"],["82.7386","0"],["82.7385","133.7350"],["82.7286","0"],["82.7285","173.2640"],["82.7186","0"],["82.7185","117.4810"],["82.7086","0"],["82.7085","119.5460"],["82.6986","0"],["82.6985","26.4600"],["82.6886","0"],["82.6885","180.0000"],["82.6786","0"],["82.6785","180.0000"],["82.6686","0"],["82.6685","79.6740"],["82.6586","0"],["82.6585","180.0000"],["82.6486","0"],["82.6485","180.0000"],["82.6386","0"],["82.6385","180.0000"],["82.6286","0"],["82.6285","180.0000"],["82.6186","0"],["82.6185","180.0000"],["82.6086","0"],["82.6085","29.6310"],["82.5986","0"],["82.5985","104.6780"],["82.5886","0"],["82.5885","33.6280"],["82.5786","0"],["82.5785","74.3960"],["82.5686","0"],["82.5685","180.0000"],["82.5586","0"],["82.5585","180.0000"],["82.5486","0"],["82.5485","129.1710"],["82.5386","0"],["82.5385","139.3700"],["82.5286","0"],["82.5285","12.6420"],["82.5186","0"],["82.5185","180.0000"],["82.5086","0"],["82.5085","180.0000"],["82.4986","0"],["82.4985","15.5190"],["82.4886","0"],["82.4885","130.8440"],["82.4786","0"],["82.4785","114.2470"],["82.4686","0"],["82.4685","180.0000"],["82.4586","0"],["82.4585","92.3440"],["82.4486","0"],["82.4485","92.0360"],["82.4386","0"],["82.4385","3.4370"],["82.4286","0"],["82.4285","10.7590"],["82.4186","0"],["82.4185","54.2780"],["82.4086","0"],["82.3986","0"],["82.3886","0"],["82.3786","0"],["78.0247","0.3167"],["77.9871","0"],["77.9416","0.3833"],["77.9041","0"],["77.8585","0.7500"],["77.8211","0"],["77.7754","0.5500"],["77.7381","0"],["77.6923","0.4167"],["77.6551","0"],["77.6092","0.3500"],["77.5721","0"],["77.5261","0.5167"],["77.4891","0"],["77.4430","0.7167"],["77.4061","0"],["77.3599","0.8167"],["77.3231","0"],["77.2768","0.4500"],["77.2401","0"],["77.1937","0.5833"],["77.1571","0"],["77.1106","0.1833"],["77.0741","0"],["77.0275","0.4833"],["76.9911","0"],["76.9444","0.7833"],["76.9081","0"],["76.8613","0.2833"],["76.8251","0"],["76.7782","0.6833"],["76.7421","0"],["76.6951","0.6500"],["76.6591","0"],["76.6120","0.2167"],["76.5761","0"],["76.5289","0.6167"],["76.4931","0"],["76.4458","0.2500"],["76.4101","0"]],"checksum":1034248306,"ts":"1649290090199"}]}
1649290090.2354681: {"action":"snapshot","arg":{"instType":"sp","channel":"ticker","instId":"AVAXUSDT"},"data":[{"instId":"AVAXUSDT","last":"82.9972","open24h":"85.1099","high24h":"86.7605","low24h":"82.5893","bestBid":"82.868600","bestAsk":"83.061400","baseVolume":"3330.7812","quoteVolume":"287728.8336","ts":1649290090185,"labeId":0}]}
1649290090.235508: {"action":"snapshot","arg":{"instType":"sp","channel":"ticker","instId":"VVSUSDT"},"data":[{"instId":"VVSUSDT","last":"0.00002314","open24h":"0.00002350","high24h":"0.00002359","low24h":"0.00002313","bestBid":"0.000024","bestAsk":"0.000024","baseVolume":"2375582289.9083","quoteVolume":"56989.8797","ts":1649290090184,"labeId":0}]}
1649290090.2510478: {"action":"snapshot","arg":{"instType":"sp","channel":"ticker","instId":"HOTUSDT"},"data":[{"instId":"HOTUSDT","last":"0.0056130","open24h":"0.0058560","high24h":"0.0059320","low24h":"0.0055520","bestBid":"0.005616","bestAsk":"0.005633","baseVolume":"10203207.8809","quoteVolume":"60796.5347","ts":1649290090200,"labeId":0}]}
1649290090.259464: {"action":"update","arg":{"instType":"sp","channel":"trade","instId":"STGUSDT"},"data":[["1649290090204","2.879","3.104","buy"]]}
1649290090.25952: {"action":"snapshot","arg":{"instType":"sp","channel":"ticker","instId":"GOGUSDT"},"data":[{"instId":"GOGUSDT","last":"0.5575","open24h":"0.5563","high24h":"0.5708","low24h":"0.5508","bestBid":"0.554700","bestAsk":"0.559000","baseVolume":"134638.2253","quoteVolume":"78741.7865","ts":1649290090213,"labeId":0}]}
1649290090.301667: {"action":"snapshot","arg":{"instType":"sp","channel":"ticker","instId":"SUNUSDT"},"data":[{"instId":"SUNUSDT","last":"0.01505","open24h":"0.01521","high24h":"0.01559","low24h":"0.01481","bestBid":"0.015030","bestAsk":"0.015080","baseVolume":"11685483","quoteVolume":"180261","ts":1649290090240,"labeId":0}]}
1649290090.330028: {"action":"snapshot","arg":{"instType":"sp","channel":"ticker","instId":"STGUSDT"},"data":[{"instId":"STGUSDT","last":"2.879","open24h":"3.045","high24h":"3.164","low24h":"2.757","bestBid":"2.861000","bestAsk":"2.917000","baseVolume":"35327.890","quoteVolume":"111744.124","ts":1649290090278,"labeId":0}]}
1649290090.330601: {"action":"snapshot","arg":{"instType":"sp","channel":"ticker","instId":"CULTUSDT"},"data":[{"instId":"CULTUSDT","last":"0.00003508","open24h":"0.00004340","high24h":"0.00004397","low24h":"0.00003500","bestBid":"0.000036","bestAsk":"0.000036","baseVolume":"13527006500","quoteVolume":"557444","ts":1649290090285,"labeId":0}]}
1649290090.438179: {"action":"update","arg":{"instType":"sp","channel":"books","instId":"EOSUSDT"},"data":[{"asks":[["2.4407","28.5099"],["2.4408","195.6669"],["2.4409","2236.7700"],["2.4410","112.4972"],["2.4411","152.9308"],["2.4412","447.0588"],["2.4413","122.8512"],["2.4414","83.8474"],["2.4416","104.7824"],["2.4418","0"],["2.4419","2874.0996"],["2.4420","191.9503"],["2.4421","103.1827"],["2.4423","481.7228"],["2.4424","975.1589"],["2.4425","1842.4279"],["2.4426","447.6783"],["2.4427","2854.2494"],["2.4428","2616.9448"],["2.4429","4393.1259"],["2.4430","376.0337"],["2.4431","2426.9982"],["2.4432","837.0000"],["2.4433","37.0439"],["2.4434","517.1570"],["2.4435","1768.4262"],["2.4436","2544.9002"],["2.4438","207.3915"],["2.4439","2664.4064"],["2.4440","2829.9000"],["2.4441","210.3117"],["2.4442","591.4614"],["2.4443","2033.8887"],["2.4447","76.7104"],["2.4448","450.0000"],["2.4449","1454.3145"],["2.4451","0"],["2.4452","3370.4201"],["2.4453","59.2407"],["2.4454","43.5376"],["2.4455","8.0446"],["2.4457","399.6687"],["2.4459","2388.1342"],["2.4460","573.3000"],["2.4462","1128.6720"],["2.4464","0"],["2.4465","0"],["2.4556","545.2381"],["2.4559","0"],["2.4561","473.8095"],["2.4564","0"],["2.4566","540.4762"],["2.4569","0"],["2.4571","535.7143"],["2.4574","0"],["2.4576","454.7619"],["2.4579","0"],["2.4581","516.6667"],["2.4584","0"],["2.4586","488.0952"],["2.4589","0"],["2.4591","478.5714"],["2.4594","0"],["2.4596","483.3333"],["2.4599","0"],["2.4601","507.1429"],["2.4604","0"],["2.4606","492.8571"],["2.4609","0"],["2.4611","464.2857"],["2.4614","0"],["2.4616","459.5238"],["2.4619","0"],["2.4621","530.9524"],["2.4624","0"],["2.4626","469.0476"],["2.4629","0"],["2.4631","497.6190"],["2.4634","0"],["2.4636","502.3810"],["2.4639","0"],["2.4641","526.1905"],["2.4644","0"],["2.4646","521.4286"],["2.4649","0"],["2.4651","511.9048"],["2.4654","0"]],"bids":[["2.4366","0"],["2.4365","0"],["2.4364","0"],["2.4363","677.4561"],["2.4361","1029.5550"],["2.4360","8.0525"],["2.4359","0"],["2.4358","8.0527"],["2.4357","200.7000"],["2.4356","356.7069"],["2.4355","478.4343"],["2.4354","1088.1000"],["2.4353","38.6915"],["2.4352","1121.0890"],["2.4351","1637.7876"],["2.4350","3689.1455"],["2.4349","356.7069"],["2.4348","84.2674"],["2.4347","0"],["2.4346","2700.0000"],["2.4344","2229.3273"],["2.4343","45.6167"],["2.4342","28.2142"],["2.4341","7002.4500"],["2.4340","2953.4704"],["2.4338","474.0603"],["2.4337","621.2543"],["2.4336","2120.3254"],["2.4335","2248.4389"],["2.4334","675.4098"],["2.4332","0"],["2.4329","743.6829"],["2.4328","1120.1013"],["2.4326","2149.4386"],["2.4325","149.0224"],["2.4324","1229.0342"],["2.4322","972.0000"],["2.4321","6028.1437"],["2.4320","0"],["2.4318","1858.0820"],["2.4317","1172.1331"],["2.4316","1212.5397"],["2.4315","0"],["2.4314","405.3176"],["2.4313","1991.8904"],["2.4311","2740.2105"],["2.4310","1247.6357"],["2.4309","526.1376"],["2.4308","1347.5988"],["2.4307","1566.9130"],["2.4216","0"],["2.4214","521.4286"],["2.4211","0"],["2.4209","478.5714"],["2.4206","0"],["2.4204","469.0476"],["2.4201","0"],["2.4199","516.6667"],["2.4196","0"],["2.4194","492.8571"],["2.4191","0"],["2.4189","530.9524"],["2.4186","0"],["2.4184","540.4762"],["2.4181","0"],["2.4179","545.2381"],["2.4176","0"],["2.4174","454.7619"],["2.4171","0"],["2.4169","507.1429"],["2.4166","0"],["2.4164","497.6190"],["2.4161","0"],["2.4159","511.9048"],["2.4156","0"],["2.4154","464.2857"],["2.4151","0"],["2.4149","488.0952"],["2.4146","0"],["2.4144","526.1905"],["2.4141","0"],["2.4139","473.8095"],["2.4136","0"],["2.4134","502.3810"],["2.4131","0"],["2.4129","459.5238"],["2.4126","0"],["2.4124","535.7143"],["2.4121","0"],["2.4119","483.3333"]],"checksum":-1376639057,"ts":"1649290090416"}]}
1649290090.45518: {"action":"update","arg":{"instType":"sp","channel":"books","instId":"GOGUSDT"},"data":[{"asks":[["0.5625","15.0000"],["0.5637","16.3333"],["0.5643","8.8615"],["0.5649","11.0000"],["0.5655","2346.8000"],["0.5661","8.8334"],["0.5667","15.6667"],["0.5673","11.6667"],["0.5685","9.6667"],["0.5691","8.7868"],["0.5697","12.3333"],["0.5703","8.7683"],["0.5709","9.0000"],["0.5715","14.3333"],["0.5727","10.3333"],["0.5739","13.6667"]],"bids":[["0.5512","12.4000"],["0.5506","11.6667"],["0.5500","9.0919"],["0.5494","12.3333"],["0.5488","9.1118"],["0.5482","3672.9000"],["0.5476","13.6667"],["0.5470","9.6667"],["0.5452","9.1719"],["0.5446","13.0000"],["0.5440","9.1922"],["0.5428","10.3333"],["0.5416","15.0000"],["0.5410","14.3333"],["0.5398","15.6667"]],"checksum":-900937878,"ts":"1649290090432"}]}
1649290090.475649: {"action":"update","arg":{"instType":"sp","channel":"books","instId":"SUNUSDT"},"data":[{"asks":[["0.01509","36637"],["0.01510","400006"],["0.01512","445743"],["0.01581","2833"],["0.01583","6500"],["0.01585","4833"],["0.01587","5167"],["0.01589","4167"],["0.01591","7833"],["0.01593","4500"],["0.01595","8167"],["0.01597","7167"],["0.01599","2500"],["0.01601","3833"],["0.01603","5833"],["0.01605","6833"],["0.01607","7500"],["0.01609","5500"],["0.01611","1833"],["0.01613","6167"],["0.01615","3167"],["0.01617","2167"],["0.01619","3500"]],"bids":[["0.01501","600202"],["0.01500","709551"],["0.01499","1324089"],["0.01496","399211"],["0.01492","603970"],["0.01430","2167"],["0.01428","5167"],["0.01426","5500"],["0.01424","3500"],["0.01420","3833"],["0.01418","3167"],["0.01412","8167"],["0.01410","2500"],["0.01408","5833"],["0.01406","4167"],["0.01404","1833"],["0.01402","6167"],["0.01400","4500"],["0.01398","7833"],["0.01396","2833"],["0.01394","6833"],["0.01392","7167"]],"checksum":-100345502,"ts":"1649290090450"}]}
1649290090.526488: {"action":"update","arg":{"instType":"sp","channel":"books","instId":"CULTUSDT"},"data":[{"asks":[["0.00003614","280000"],["0.00003618","653333"],["0.00003622","253333"],["0.00003626","546667"],["0.00003630","386667"],["0.00003634","573333"],["0.00003638","520000"],["0.00003642","600000"],["0.00003646","633723"],["0.00003650","146667"],["0.00003654","626667"],["0.00003658","493333"],["0.00003662","200000"],["0.00003666","466667"],["0.00003670","413333"],["0.00003674","440000"],["0.00003678","306667"],["0.00003682","226667"],["0.00003686","333333"],["0.00003690","173333"]],"bids":[["0.00003471","200000"],["0.00003463","573333"],["0.00003459","466667"],["0.00003455","748154"],["0.00003451","653333"],["0.00003447","626667"],["0.00003443","306667"],["0.00003439","600000"],["0.00003435","146667"],["0.00003431","333333"],["0.00003427","413333"],["0.00003419","493333"],["0.00003415","253333"],["0.00003411","386667"],["0.00003407","520000"],["0.00003403","226667"],["0.00003399","546667"],["0.00003395","173333"]],"checksum":721277923,"ts":"1649290090504"}]}
1649290090.618217: {"action":"update","arg":{"instType":"sp","channel":"candle1m","instId":"STGUSDT"},"data":[["1649290080000","2.881","2.881","2.879","2.879","3.104"]]}
1649290090.626724: {"action":"update","arg":{"instType":"sp","channel":"books","instId":"VVSUSDT"},"data":[{"asks":[["0.00002323","500000.0000"],["0.00002370","289473.7000"],["0.00002373","453216.4000"],["0.00002379","657894.7000"],["0.00002382","494152.0000"],["0.00002385","371345.0000"],["0.00002391","535087.7000"],["0.00002397","698830.4000"],["0.00002403","862573.1000"],["0.00002406","412280.7000"],["0.00002409","616959.1000"]],"bids":[["0.00002267","220556.8000"],["0.00002261","412280.7000"],["0.00002258","371345.0000"],["0.00002255","821637.4000"],["0.00002252","289473.7000"],["0.00002249","780701.8000"],["0.00002243","330409.4000"],["0.00002240","698830.4000"],["0.00002237","453216.4000"],["0.00002234","576023.4000"],["0.00002231","248538.0000"],["0.00002228","616959.1000"]],"checksum":-350073657,"ts":"1649290090603"}]}
1649290090.692713: {"action":"update","arg":{"instType":"sp","channel":"books","instId":"HOTUSDT"},"data":[{"asks":[["0.0056340","0"],["0.0056360","0"],["0.0056370","131427.4500"],["0.0056380","724910.8500"],["0.0056390","1599.3000"],["0.0056400","159783.3000"],["0.0056410","32768.1000"],["0.0056420","33611.4000"],["0.0056430","119765.7000"],["0.0056440","0"],["0.0056460","367614.0000"],["0.0056480","11997.9000"],["0.0056660","120869.1000"],["0.0056820","3240.0000"],["0.0056890","5535.0000"],["0.0056910","2519.1000"],["0.0059060","0"],["0.0059080","9750.0000"],["0.0059120","0"],["0.0059140","11750.0000"],["0.0059180","0"],["0.0059200","4250.0000"],["0.0059240","0"],["0.0059260","6250.0000"],["0.0059300","0"],["0.0059320","6750.0000"],["0.0059360","0"],["0.0059380","3750.0000"],["0.0059420","0"],["0.0059440","3250.0000"],["0.0059480","0"],["0.0059500","12250.0000"],["0.0059540","0"],["0.0059560","11250.0000"],["0.0059600","0"],["0.0059620","10750.0000"],["0.0059660","0"],["0.0059680","5750.0000"],["0.0059720","0"],["0.0059740","8750.0000"],["0.0059780","0"],["0.0059800","9250.0000"],["0.0059840","0"],["0.0059860","7250.0000"],["0.0059900","0"],["0.0059920","10250.0000"],["0.0059960","0"],["0.0059980","7750.0000"],["0.0060020","0"],["0.0060040","5250.0000"],["0.0060080","0"],["0.0060100","8250.0000"],["0.0060140","0"],["0.0060160","4750.0000"],["0.0060200","0"],["0.0060220","2750.0000"]],"bids":[["0.0056180","192249.9000"],["0.0056170","41896.8000"],["0.0056160","62778.1500"],["0.0056140","48512.7000"],["0.0056130","192013.2900"],["0.0056120","687301.2000"],["0.0056110","756517.9500"],["0.0056100","16283.7000"],["0.0056090","115240.5000"],["0.0056080","214129.8000"],["0.0056030","123811.8300"],["0.0056020","364359.6000"],["0.0055990","192600.0000"],["0.0055980","339846.3000"],["0.0055870","69026.4000"],["0.0055850","122317.2000"],["0.0055830","41030.6900"],["0.0055820","0"],["0.0055730","42040.8000"],["0.0055640","158319.0000"],["0.0055600","0"],["0.0055590","0"],["0.0053450","2750.0000"],["0.0053430","0"],["0.0053390","5750.0000"],["0.0053370","0"],["0.0053330","11750.0000"],["0.0053310","0"],["0.0053270","10250.0000"],["0.0053250","0"],["0.0053210","11250.0000"],["0.0053190","0"],["0.0053150","3750.0000"],["0.0053130","0"],["0.0053090","8750.0000"],["0.0053070","0"],["0.0053030","6750.0000"],["0.0053010","0"],["0.0052970","7250.0000"],["0.0052950","0"],["0.0052910","9750.0000"],["0.0052890","0"],["0.0052850","9250.0000"],["0.0052830","0"],["0.0052790","7750.0000"],["0.0052770","0"],["0.0052730","8250.0000"],["0.0052710","0"],["0.0052670","4250.0000"],["0.0052650","0"],["0.0052610","6250.0000"],["0.0052590","0"],["0.0052550","12250.0000"],["0.0052530","0"],["0.0052490","4750.0000"],["0.0052470","0"],["0.0052430","10750.0000"],["0.0052410","0"],["0.0052370","3250.0000"],["0.0052350","0"],["0.0052310","5250.0000"],["0.0052290","0"]],"checksum":739501142,"ts":"1649290090657"}]}
1649290090.6985931: {"action":"update","arg":{"instType":"sp","channel":"books","instId":"STGUSDT"},"data":[{"asks":[["3.034","2.174"],["3.037","1.647"],["3.040","3.188"],["3.043","2.301"],["3.046","2.935"],["3.049","6.500"],["3.055","1.638"],["3.061","3.442"],["3.064","2.681"],["3.070","3.062"],["3.076","2.428"],["3.079","5.711"],["3.082","1.623"],["3.088","1.620"],["3.091","3.569"],["3.094","1.667"],["3.097","1.920"],["3.100","1.793"]],"bids":[["2.744","3.292"],["2.741","2.323"],["2.738","20.829"],["2.732","98.669"],["2.729","2.108"],["2.726","74.498"],["2.723","1.892"],["2.720","2.862"],["2.717","1.841"],["2.714","2.754"],["2.711","1.845"],["2.708","2.969"],["2.705","2.646"],["2.702","1.851"],["2.696","92.093"],["2.693","2.431"],["2.690","1.860"],["2.687","2.000"],["2.681","3.185"],["2.678","2.215"],["2.672","2.538"]],"checksum":859839021,"ts":"1649290090675"}]}
1649290090.7600992: {"action":"update","arg":{"instType":"sp","channel":"books","instId":"AVAXUSDT"},"data":[{"asks":[["83.1015","0"],["83.1115","3.5140"],["83.1215","29.3300"],["83.1315","133.2170"],["83.1515","117.8730"],["83.1615","180.0000"],["83.1815","173.7890"],["83.2115","70.3640"],["83.2215","17.2620"],["83.2315","62.0760"],["83.2715","76.7340"],["83.6515","0.2310"],["87.9853","0"],["87.9959","0.6500"],["88.0684","0"],["88.0790","0.6833"],["88.1515","0"],["88.1621","0.1833"],["88.2346","0"],["88.2452","0.3500"],["88.3177","0"],["88.3283","0.2167"],["88.4008","0"],["88.4114","0.7833"],["88.4839","0"],["88.4945","0.2833"],["88.5670","0"],["88.5776","0.8167"],["88.6501","0"],["88.6607","0.7500"],["88.7332","0"],["88.7438","0.5833"],["88.8163","0"],["88.8269","0.7167"],["88.8994","0"],["88.9100","0.4500"],["88.9825","0"],["88.9931","0.4167"],["89.0656","0"],["89.0762","0.5500"],["89.1487","0"],["89.1593","0.2500"],["89.2318","0"],["89.2424","0.5167"],["89.3149","0"],["89.3255","0.4833"],["89.3980","0"],["89.4086","0.3833"],["89.4811","0"],["89.4917","0.3167"],["89.5642","0"],["89.5748","0.6167"]],"bids":[["82.9185","18.2700"],["82.9085","24.6190"],["82.8985","43.6310"],["82.8885","79.1280"],["82.8785","44.9330"],["82.8685","52.5350"],["82.8585","136.2060"],["82.8485","22.7430"],["82.8385","128.9050"],["82.8185","180.0000"],["82.7985","26.1030"],["82.7885","152.7400"],["82.7685","124.6700"],["82.7385","63.7000"],["82.7085","92.3860"],["82.6085","21.2520"],["82.5985","96.2990"],["82.5785","66.0800"],["82.5685","80.1080"],["82.5485","137.4940"],["82.5385","135.1420"],["82.5285","14.7420"],["82.4785","122.6330"],["82.4185","0"],["78.0341","0.7500"],["78.0247","0"],["77.9510","0.5500"],["77.9416","0"],["77.8679","0.2500"],["77.8585","0"],["77.7848","0.5833"],["77.7754","0"],["77.7017","0.3167"],["77.6923","0"],["77.6186","0.4500"],["77.6092","0"],["77.5355","0.4833"],["77.5261","0"],["77.4524","0.6167"],["77.4430","0"],["77.3693","0.1833"],["77.3599","0"],["77.2862","0.7167"],["77.2768","0"],["77.2031","0.2833"],["77.1937","0"],["77.1200","0.6500"],["77.1106","0"],["77.0369","0.6833"],["77.0275","0"],["76.9538","0.5167"],["76.9444","0"],["76.8707","0.3833"],["76.8613","0"],["76.7876","0.4167"],["76.7782","0"],["76.7045","0.3500"],["76.6951","0"],["76.6214","0.8167"],["76.6120","0"],["76.5383","0.7833"],["76.5289","0"],["76.4552","0.2167"],["76.4458","0"]],"checksum":463387113,"ts":"1649290090737"}]}
1649290090.9982889: {"action":"update","arg":{"instType":"sp","channel":"books","instId":"EOSUSDT"},"data":[{"asks":[["2.4407","0"],["2.4409","1454.3100"],["2.4410","77.4872"],["2.4412","538.9632"],["2.4416","104.9237"],["2.4419","1406.2050"],["2.4420","20.9705"],["2.4421","0"],["2.4422","0"],["2.4423","810.4457"],["2.4425","659.5106"],["2.4426","348.6783"],["2.4427","265.7594"],["2.4428","114.5096"],["2.4429","3069.4587"],["2.4430","377.4175"],["2.4432","0"],["2.4434","240.3758"],["2.4435","1412.9262"],["2.4436","2963.4002"],["2.4437","1123.6590"],["2.4438","399.2610"],["2.4439","2640.6426"],["2.4440","3015.9000"],["2.4441","790.8117"],["2.4443","2161.1185"],["2.4445","276.7458"],["2.4450","3278.7156"],["2.4452","91.4355"],["2.4464","661.2444"],["2.4465","1427.9171"],["2.4466","247.5000"],["2.4556","0"],["2.4558","540.4762"],["2.4561","0"],["2.4563","507.1429"],["2.4566","0"],["2.4568","521.4286"],["2.4571","0"],["2.4573","454.7619"],["2.4576","0"],["2.4578","492.8571"],["2.4581","0"],["2.4583","483.3333"],["2.4586","0"],["2.4588","459.5238"],["2.4591","0"],["2.4593","469.0476"],["2.4596","0"],["2.4598","526.1905"],["2.4601","0"],["2.4603","488.0952"],["2.4606","0"],["2.4608","473.8095"],["2.4611","0"],["2.4613","497.6190"],["2.4616","0"],["2.4618","545.2381"],["2.4621","0"],["2.4623","535.7143"],["2.4626","0"],["2.4628","502.3810"],["2.4631","0"],["2.4633","516.6667"],["2.4636","0"],["2.4638","511.9048"],["2.4641","0"],["2.4643","478.5714"],["2.4646","0"],["2.4648","530.9524"],["2.4651","0"],["2.4653","464.2857"]],"bids":[["2.4364","30.0894"],["2.4363","1399.4133"],["2.4362","30.0894"],["2.4361","1314.4147"],["2.4357","211.6723"],["2.4352","2158.0272"],["2.4351","1493.6175"],["2.4349","1564.3535"],["2.4348","285.7982"],["2.4347","185.1089"],["2.4345","55.7048"],["2.4344","48.6687"],["2.4343","281.8667"],["2.4341","8494.2900"],["2.4340","754.4702"],["2.4338","394.5583"],["2.4331","2113.3209"],["2.4327","2952.9000"],["2.4321","5088.2437"],["2.4314","949.9455"],["2.4311","2494.1252"],["2.4310","0"],["2.4309","0"],["2.4308","0"],["2.4307","0"],["2.4215","516.6667"],["2.4214","0"],["2.4210","530.9524"],["2.4209","0"],["2.4205","454.7619"],["2.4204","0"],["2.4200","483.3333"],["2.4199","0"],["2.4195","478.5714"],["2.4194","0"],["2.4190","526.1905"],["2.4189","0"],["2.4185","459.5238"],["2.4184","0"],["2.4180","469.0476"],["2.4179","0"],["2.4175","502.3810"],["2.4174","0"],["2.4170","473.8095"],["2.4169","0"],["2.4165","521.4286"],["2.4164","0"],["2.4160","545.2381"],["2.4159","0"],["2.4155","507.1429"],["2.4154","0"],["2.4150","492.8571"],["2.4149","0"],["2.4145","535.7143"],["2.4144","0"],["2.4140","497.6190"],["2.4139","0"],["2.4135","511.9048"],["2.4134","0"],["2.4130","464.2857"],["2.4129","0"],["2.4125","488.0952"],["2.4124","0"],["2.4120","540.4762"],["2.4119","0"]],"checksum":2046690861,"ts":"1649290090975"}]}
1649290091.0023339: {"action":"update","arg":{"instType":"sp","channel":"books","instId":"GOGUSDT"},"data":[{"asks":[["0.5625","8.8899"],["0.5631","12.3333"],["0.5637","11.6667"],["0.5643","11.0000"],["0.5649","8.8521"],["0.5655","2348.1333"],["0.5667","13.0000"],["0.5673","10.3333"],["0.5685","13.6667"],["0.5697","16.3333"],["0.5703","15.0000"],["0.5709","15.6667"],["0.5715","8.7499"],["0.5727","8.7316"],["0.5733","9.6667"],["0.5739","9.0000"]],"bids":[["0.5512","9.0721"],["0.5506","9.0820"],["0.5500","16.3333"],["0.5494","9.1018"],["0.5488","10.3333"],["0.5482","3680.9000"],["0.5476","9.1318"],["0.5470","11.6667"],["0.5464","13.6667"],["0.5458","15.6667"],["0.5452","14.3333"],["0.5446","9.1821"],["0.5434","12.3333"],["0.5428","9.2125"],["0.5416","9.2329"],["0.5410","13.0000"],["0.5404","9.6667"],["0.5398","11.0000"]],"checksum":1063299991,"ts":"1649290090978"}]}
1649290091.002514: {"action":"update","arg":{"instType":"sp","channel":"books","instId":"SUNUSDT"},"data":[{"asks":[["0.01508","0"],["0.01509","37087"],["0.01510","541106"],["0.01511","171903"],["0.01512","445405"],["0.01515","1042432"],["0.01523","2202"],["0.01568","2533"],["0.01581","0"],["0.01582","7167"],["0.01583","0"],["0.01584","6167"],["0.01585","0"],["0.01586","7833"],["0.01587","0"],["0.01588","4833"],["0.01589","0"],["0.01590","5500"],["0.01591","0"],["0.01592","8167"],["0.01593","0"],["0.01594","2500"],["0.01595","0"],["0.01596","6500"],["0.01597","0"],["0.01598","6833"],["0.01599","0"],["0.01600","3500"],["0.01601","0"],["0.01602","4500"],["0.01603","0"],["0.01604","7500"],["0.01605","0"],["0.01606","1833"],["0.01607","0"],["0.01608","3833"],["0.01609","0"],["0.01610","5833"],["0.01611","0"],["0.01612","4167"],["0.01613","0"],["0.01614","5167"],["0.01615","0"],["0.01616","2167"],["0.01617","0"],["0.01618","2833"],["0.01619","0"],["0.01620","3167"]],"bids":[["0.01503","202766"],["0.01502","177541"],["0.01501","601032"],["0.01499","1323214"],["0.01498","104473"],["0.01497","34482"],["0.01495","3155446"],["0.01494","5504"],["0.01493","1595"],["0.01430","2833"],["0.01428","6500"],["0.01426","6167"],["0.01424","1833"],["0.01422","2500"],["0.01420","5167"],["0.01418","2167"],["0.01416","5833"],["0.01414","4500"],["0.01412","7167"],["0.01410","7833"],["0.01408","4833"],["0.01406","3500"],["0.01404","7500"],["0.01402","4167"],["0.01400","3167"],["0.01398","8167"],["0.01396","3833"],["0.01394","5500"],["0.01392","6833"]],"checksum":181191243,"ts":"1649290090979"}]}
1649290091.066426: {"action":"update","arg":{"instType":"sp","channel":"trade","instId":"AVAXUSDT"},"data":[["1649290091013","83.1159","0.0603","sell"]]}
1649290091.1481469: {"action":"update","arg":{"instType":"sp","channel":"books","instId":"VVSUSDT"},"data":[{"asks":[["0.00002323","215239.9000"],["0.00002370","657894.7000"],["0.00002373","494152.0000"],["0.00002379","412280.7000"],["0.00002382","535087.7000"],["0.00002385","739766.1000"],["0.00002391","903508.8000"],["0.00002397","862573.1000"],["0.00002403","248538.0000"],["0.00002406","821637.4000"],["0.00002409","289473.7000"]],"bids":[["0.00002267","412280.7000"],["0.00002261","494152.0000"],["0.00002258","862573.1000"],["0.00002255","780701.8000"],["0.00002252","371345.0000"],["0.00002249","576023.4000"],["0.00002243","698830.4000"],["0.00002240","330409.4000"],["0.00002237","535087.7000"],["0.00002234","739766.1000"],["0.00002231","224115.7000"],["0.00002228","248538.0000"]],"checksum":-1812523359,"ts":"1649290091120"}]}
1649290091.148396: {"action":"update","arg":{"instType":"sp","channel":"books","instId":"CULTUSDT"},"data":[{"asks":[["0.00003614","520000"],["0.00003618","440000"],["0.00003622","573333"],["0.00003626","200000"],["0.00003630","626667"],["0.00003634","280000"],["0.00003638","653333"],["0.00003642","253333"],["0.00003646","420390"],["0.00003650","600000"],["0.00003654","333333"],["0.00003658","413333"],["0.00003662","466667"],["0.00003666","173333"],["0.00003670","386667"],["0.00003674","360000"],["0.00003686","546667"],["0.00003690","493333"]],"bids":[["0.00003471","440000"],["0.00003467","1315230"],["0.00003463","600000"],["0.00003459","520000"],["0.00003455","534821"],["0.00003451","200000"],["0.00003447","546667"],["0.00003443","653333"],["0.00003439","333333"],["0.00003435","306667"],["0.00003431","280000"],["0.00003427","226667"],["0.00003423","493333"],["0.00003419","573333"],["0.00003415","413333"],["0.00003411","360000"],["0.00003407","626667"],["0.00003403","386667"],["0.00003399","466667"],["0.00003395","253333"]],"checksum":1228483014,"ts":"1649290091126"}]}
1649290091.242959: {"action":"update","arg":{"instType":"sp","channel":"books","instId":"HOTUSDT"},"data":[{"asks":[["0.0056380","800000.0000"],["0.0056610","139382.1000"],["0.0056830","102600.0000"],["0.0059080","0"],["0.0059090","5250.0000"],["0.0059140","0"],["0.0059150","11750.0000"],["0.0059200","0"],["0.0059210","9250.0000"],["0.0059260","0"],["0.0059270","6750.0000"],["0.0059320","0"],["0.0059330","7250.0000"],["0.0059380","0"],["0.0059390","3250.0000"],["0.0059440","0"],["0.0059450","11250.0000"],["0.0059500","0"],["0.0059510","9750.0000"],["0.0059560","0"],["0.0059570","4750.0000"],["0.0059620","0"],["0.0059630","10250.0000"],["0.0059680","0"],["0.0059690","10750.0000"],["0.0059740","0"],["0.0059750","5750.0000"],["0.0059800","0"],["0.0059810","8250.0000"],["0.0059860","0"],["0.0059870","8750.0000"],["0.0059920","0"],["0.0059930","7750.0000"],["0.0059980","0"],["0.0059990","2750.0000"],["0.0060040","0"],["0.0060050","4250.0000"],["0.0060100","0"],["0.0060110","3750.0000"],["0.0060160","0"],["0.0060170","6250.0000"],["0.0060220","0"],["0.0060230","12250.0000"]],"bids":[["0.0056200","87849.9000"],["0.0056190","57889.8000"],["0.0056180","193546.8000"],["0.0056160","144558.0000"],["0.0056150","470470.5000"],["0.0056140","10017.0000"],["0.0056130","130339.8600"],["0.0056120","314111.2500"],["0.0056110","753043.5000"],["0.0056090","9533.7000"],["0.0056080","197044.2000"],["0.0056020","120342.6000"],["0.0055980","38936.7000"],["0.0055830","212287.5000"],["0.0055740","98210.7000"],["0.0055620","0"],["0.0055610","0"],["0.0053460","6750.0000"],["0.0053450","0"],["0.0053400","7250.0000"],["0.0053390","0"],["0.0053340","11250.0000"],["0.0053330","0"],["0.0053280","4250.0000"],["0.0053270","0"],["0.0053220","7750.0000"],["0.0053210","0"],["0.0053160","5250.0000"],["0.0053150","0"],["0.0053100","6250.0000"],["0.0053090","0"],["0.0053040","12250.0000"],["0.0053030","0"],["0.0052980","4750.0000"],["0.0052970","0"],["0.0052920","9750.0000"],["0.0052910","0"],["0.0052860","3750.0000"],["0.0052850","0"],["0.0052800","2750.0000"],["0.0052790","0"],["0.0052740","11750.0000"],["0.0052730","0"],["0.0052680","9250.0000"],["0.0052670","0"],["0.0052620","10250.0000"],["0.0052610","0"],["0.0052560","3250.0000"],["0.0052550","0"],["0.0052500","10750.0000"],["0.0052490","0"],["0.0052440","5750.0000"],["0.0052430","0"],["0.0052380","8250.0000"],["0.0052370","0"],["0.0052320","8750.0000"],["0.0052310","0"]],"checksum":1239556869,"ts":"1649290091209"}]}
1649290091.287485: {"action":"update","arg":{"instType":"sp","channel":"books","instId":"STGUSDT"},"data":[{"asks":[["3.034","2.935"],["3.037","3.442"],["3.040","1.646"],["3.043","2.554"],["3.046","1.642"],["3.049","5.486"],["3.052","2.808"],["3.055","3.188"],["3.058","2.174"],["3.061","1.634"],["3.064","3.062"],["3.070","3.315"],["3.073","3.569"],["3.076","1.920"],["3.079","4.697"],["3.082","2.047"],["3.085","1.667"],["3.088","1.793"],["3.091","2.681"],["3.094","2.428"],["3.097","1.615"],["3.100","1.614"]],"bids":[["2.760","18.081"],["2.744","2.538"],["2.741","2.000"],["2.738","19.214"],["2.735","3.077"],["2.732","100.500"],["2.729","2.754"],["2.726","73.959"],["2.723","1.837"],["2.720","1.839"],["2.714","3.185"],["2.711","2.323"],["2.708","1.847"],["2.705","1.849"],["2.702","2.646"],["2.699","2.862"],["2.696","93.816"],["2.693","1.892"],["2.690","2.108"],["2.687","1.862"],["2.681","3.292"],["2.678","1.868"],["2.675","2.215"],["2.672","1.872"],["1.296","0"]],"checksum":50173049,"ts":"1649290091265"}]}
1649290091.303146: {"action":"update","arg":{"instType":"sp","channel":"books","instId":"AVAXUSDT"},"data":[{"asks":[["83.1115","0"],["83.1215","20.3770"],["83.1315","42.3010"],["83.1415","74.4450"],["83.1515","131.5090"],["83.1715","90.9580"],["83.1815","180.0000"],["83.2115","77.1540"],["83.2315","96.1030"],["83.2415","151.4940"],["83.2715","33.8590"],["83.2815","180.0000"],["83.2915","74.2350"],["83.6615","0.7490"],["87.9959","0"],["88.0066","0.3500"],["88.0790","0"],["88.0897","0.4167"],["88.1621","0"],["88.1728","0.6833"],["88.2452","0"],["88.2559","0.8167"],["88.3283","0"],["88.3390","0.1833"],["88.4114","0"],["88.4221","0.5167"],["88.4945","0"],["88.5052","0.6167"],["88.5776","0"],["88.5883","0.7167"],["88.6607","0"],["88.6714","0.2167"],["88.7438","0"],["88.7545","0.3167"],["88.8269","0"],["88.8376","0.7833"],["88.9100","0"],["88.9207","0.2833"],["88.9931","0"],["89.0038","0.5833"],["89.0762","0"],["89.0869","0.2500"],["89.1593","0"],["89.1700","0.5500"],["89.2424","0"],["89.2531","0.7500"],["89.3255","0"],["89.3362","0.3833"],["89.4086","0"],["89.4193","0.6500"],["89.4917","0"],["89.5024","0.4500"],["89.5748","0"],["89.5855","0.4833"]],"bids":[["82.9285","57.8900"],["82.9185","66.9620"],["82.9085","62.9230"],["82.8985","10.5910"],["82.8885","111.5240"],["82.8785","73.5840"],["82.8685","19.0190"],["82.8585","80.0170"],["82.8485","134.4490"],["82.8385","180.0000"],["82.8285","64.2320"],["82.8185","48.9580"],["82.7885","80.1430"],["82.5985","87.4860"],["82.5885","41.9440"],["82.5385","126.8050"],["82.4885","126.6160"],["82.4285","0"],["78.0435","0.7167"],["78.0341","0"],["77.9604","0.4500"],["77.9510","0"],["77.8773","0.7500"],["77.8679","0"],["77.7942","0.1833"],["77.7848","0"],["77.7111","0.3833"],["77.7017","0"],["77.6280","0.2500"],["77.6186","0"],["77.5449","0.4167"],["77.5355","0"],["77.4618","0.5500"],["77.4524","0"],["77.3787","0.5833"],["77.3693","0"],["77.2956","0.3167"],["77.2862","0"],["77.2125","0.4833"],["77.2031","0"],["77.1294","0.8167"],["77.1200","0"],["77.0463","0.2833"],["77.0369","0"],["76.9632","0.3500"],["76.9538","0"],["76.8801","0.2167"],["76.8707","0"],["76.7970","0.7833"],["76.7876","0"],["76.7139","0.5167"],["76.7045","0"],["76.6308","0.6500"],["76.6214","0"],["76.5477","0.6833"],["76.5383","0"],["76.4646","0.6167"],["76.4552","0"]],"checksum":1444630618,"ts":"1649290091279"}]}
1649290091.451045: {"action":"update","arg":{"instType":"sp","channel":"candle1m","instId":"AVAXUSDT"},"data":[["1649290080000","83.1253","83.1253","82.9972","83.1159","0.1206"]]}
1649290091.502868: {"action":"update","arg":{"instType":"sp","channel":"books","instId":"GOGUSDT"},"data":[{"asks":[["0.5631","9.0000"],["0.5643","8.8615"],["0.5649","15.0000"],["0.5655","2346.8000"],["0.5667","15.6667"],["0.5673","8.8147"],["0.5685","8.7961"],["0.5697","13.6667"],["0.5703","11.0000"],["0.5709","9.6667"],["0.5715","14.3333"],["0.5721","16.3333"],["0.5733","10.3333"],["0.5739","12.3333"]],"bids":[["0.5512","11.7333"],["0.5506","9.6667"],["0.5488","15.0000"],["0.5482","3674.9000"],["0.5476","11.0000"],["0.5470","13.0000"],["0.5464","14.3333"],["0.5458","12.3333"],["0.5452","9.1719"],["0.5434","9.2023"],["0.5422","11.6667"],["0.5416","15.6667"],["0.5410","9.2431"],["0.5404","9.2534"],["0.5398","13.6667"]],"checksum":-1066238183,"ts":"1649290091481"}]}
1649290091.553544: {"action":"update","arg":{"instType":"sp","channel":"books","instId":"EOSUSDT"},"data":[{"asks":[["2.4411","0"],["2.4412","841.6764"],["2.4413","182.4314"],["2.4415","79.3169"],["2.4416","223.0487"],["2.4420","38.2500"],["2.4422","112.8066"],["2.4423","8.0473"],["2.4424","908.9786"],["2.4425","657.0216"],["2.4428","8.0468"],["2.4429","3443.8829"],["2.4431","2435.8944"],["2.4432","257.7747"],["2.4436","2834.5128"],["2.4438","553.8915"],["2.4447","72.9188"],["2.4454","42.1685"],["2.4456","77.4419"],["2.4457","334.8344"],["2.4459","2535.1342"],["2.4464","1223.4888"],["2.4466","0"],["2.4558","473.8095"],["2.4563","483.3333"],["2.4568","530.9524"],["2.4573","469.0476"],["2.4578","507.1429"],["2.4583","526.1905"],["2.4588","492.8571"],["2.4593","540.4762"],["2.4598","488.0952"],["2.4603","464.2857"],["2.4608","497.6190"],["2.4613","535.7143"],["2.4618","454.7619"],["2.4623","516.6667"],["2.4628","511.9048"],["2.4633","521.4286"],["2.4638","545.2381"],["2.4643","502.3810"],["2.4648","459.5238"],["2.4653","478.5714"]],"bids":[["2.4364","16.8904"],["2.4363","1555.3200"],["2.4361","1598.6618"],["2.4355","715.8060"],["2.4353","72.9188"],["2.4352","2081.4771"],["2.4351","1972.4100"],["2.4350","3689.5321"],["2.4349","1053.2453"],["2.4347","474.5062"],["2.4346","4929.5944"],["2.4345","68.9763"],["2.4343","178.8173"],["2.4341","10057.5000"],["2.4340","663.2588"],["2.4339","410.2563"],["2.4338","448.7243"],["2.4337","531.2543"],["2.4336","2995.9880"],["2.4335","2071.4389"],["2.4331","2104.9809"],["2.4328","1147.2753"],["2.4326","2189.9386"],["2.4321","5062.2083"],["2.4316","1254.5397"],["2.4312","0"],["2.4310","1247.6357"],["2.4215","540.4762"],["2.4210","521.4286"],["2.4205","516.6667"],["2.4200","488.0952"],["2.4195","526.1905"],["2.4190","497.6190"],["2.4185","454.7619"],["2.4180","464.2857"],["2.4175","483.3333"],["2.4170","502.3810"],["2.4165","478.5714"],["2.4160","511.9048"],["2.4155","530.9524"],["2.4150","507.1429"],["2.4140","459.5238"],["2.4135","545.2381"],["2.4130","473.8095"],["2.4125","469.0476"],["2.4120","492.8571"]],"checksum":-252072295,"ts":"1649290091531"}]}
1649290091.583276: {"action":"update","arg":{"instType":"sp","channel":"books","instId":"SUNUSDT"},"data":[{"asks":[["0.01509","26557"],["0.01510","528236"],["0.01511","335593"],["0.01512","104599"],["0.01513","252681"],["0.01514","1647783"],["0.01515","2428"],["0.01582","3167"],["0.01584","7500"],["0.01586","5500"],["0.01588","5833"],["0.01590","5167"],["0.01592","6167"],["0.01594","3833"],["0.01596","7167"],["0.01598","2167"],["0.01602","1833"],["0.01604","8167"],["0.01606","4833"],["0.01608","6833"],["0.01610","7833"],["0.01614","2833"],["0.01616","4500"],["0.01618","6500"],["0.01620","2500"]],"bids":[["0.01503","203379"],["0.01502","197341"],["0.01501","601412"],["0.01497","13916"],["0.01496","378645"],["0.01489","682452"],["0.01488","4022"],["0.01430","7167"],["0.01428","3833"],["0.01426","1833"],["0.01424","3167"],["0.01422","8167"],["0.01420","2167"],["0.01418","6500"],["0.01416","4167"],["0.01414","4833"],["0.01412","7500"],["0.01410","5833"],["0.01408","7833"],["0.01406","6833"],["0.01404","2833"],["0.01402","6167"],["0.01400","5500"],["0.01398","3500"],["0.01396","2500"],["0.01394","4500"],["0.01392","5167"]],"checksum":-1663933321,"ts":"1649290091561"}]}
1649290091.688321: {"action":"update","arg":{"instType":"sp","channel":"books","instId":"VVSUSDT"},"data":[{"asks":[["0.00002323","0"],["0.00002370","0"],["0.00002373","0"],["0.00002375","453216.4000"],["0.00002378","371345.0000"],["0.00002379","0"],["0.00002381","412280.7000"],["0.00002382","0"],["0.00002385","0"],["0.00002387","209469.0000"],["0.00002390","739766.1000"],["0.00002391","0"],["0.00002393","780701.8000"],["0.00002397","0"],["0.00002399","862573.1000"],["0.00002402","616959.1000"],["0.00002403","0"],["0.00002405","494152.0000"],["0.00002406","0"],["0.00002408","698830.4000"],["0.00002409","0"],["0.00002411","903508.8000"],["0.00002554","130000000.0000"]],"bids":[["0.00002269","535087.7000"],["0.00002267","0"],["0.00002263","494152.0000"],["0.00002261","0"],["0.00002258","0"],["0.00002257","221534.0000"],["0.00002255","0"],["0.00002254","903508.8000"],["0.00002252","0"],["0.00002251","698830.4000"],["0.00002249","0"],["0.00002248","453216.4000"],["0.00002245","657894.7000"],["0.00002243","0"],["0.00002242","739766.1000"],["0.00002240","0"],["0.00002239","576023.4000"],["0.00002237","0"],["0.00002234","0"],["0.00002233","371345.0000"],["0.00002231","0"],["0.00002230","862573.1000"],["0.00002228","0"]],"checksum":2090931483,"ts":"1649290091665"}]}
1649290091.757747: {"action":"update","arg":{"instType":"sp","channel":"books","instId":"HOTUSDT"},"data":[{"asks":[["0.0056360","15984.0000"],["0.0056370","134856.4500"],["0.0056380","617718.1500"],["0.0056390","0"],["0.0056420","138264.3000"],["0.0056460","407770.2000"],["0.0059080","10750.0000"],["0.0059090","0"],["0.0059140","5750.0000"],["0.0059150","0"],["0.0059200","11750.0000"],["0.0059210","0"],["0.0059260","11250.0000"],["0.0059270","0"],["0.0059320","6250.0000"],["0.0059330","0"],["0.0059380","3250.0000"],["0.0059390","0"],["0.0059440","10250.0000"],["0.0059450","0"],["0.0059500","4750.0000"],["0.0059510","0"],["0.0059560","8750.0000"],["0.0059570","0"],["0.0059620","9750.0000"],["0.0059630","0"],["0.0059680","5250.0000"],["0.0059690","0"],["0.0059740","7750.0000"],["0.0059750","0"],["0.0059800","4250.0000"],["0.0059810","0"],["0.0059860","2750.0000"],["0.0059870","0"],["0.0059920","7250.0000"],["0.0059930","0"],["0.0059980","12250.0000"],["0.0059990","0"],["0.0060040","3750.0000"],["0.0060050","0"],["0.0060100","8250.0000"],["0.0060110","0"],["0.0060160","6750.0000"],["0.0060170","0"],["0.0060220","9250.0000"],["0.0060230","0"]],"bids":[["0.0056200","0"],["0.0056190","0"],["0.0056160","62301.6000"],["0.0056150","443030.4000"],["0.0056130","118405.2600"],["0.0056110","752243.8500"],["0.0056100","17083.8000"],["0.0056020","210518.5500"],["0.0055750","800000.0000"],["0.0055620","40198.0500"],["0.0053460","0"],["0.0053450","6250.0000"],["0.0053400","0"],["0.0053390","9250.0000"],["0.0053340","0"],["0.0053330","7250.0000"],["0.0053280","0"],["0.0053270","11750.0000"],["0.0053220","0"],["0.0053210","5750.0000"],["0.0053160","0"],["0.0053150","10750.0000"],["0.0053100","0"],["0.0053090","2750.0000"],["0.0053040","0"],["0.0053030","8250.0000"],["0.0052980","0"],["0.0052970","12250.0000"],["0.0052920","0"],["0.0052910","4250.0000"],["0.0052860","0"],["0.0052850","7750.0000"],["0.0052800","0"],["0.0052790","11250.0000"],["0.0052740","0"],["0.0052730","9750.0000"],["0.0052680","0"],["0.0052670","8750.0000"],["0.0052620","0"],["0.0052610","5250.0000"],["0.0052560","0"],["0.0052550","6750.0000"],["0.0052500","0"],["0.0052490","4750.0000"],["0.0052440","0"],["0.0052430","10250.0000"],["0.0052380","0"],["0.0052370","3750.0000"],["0.0052320","0"],["0.0052310","3250.0000"]],"checksum":-1630067028,"ts":"1649290091736"}]}
1649290091.777886: {"action":"update","arg":{"instType":"sp","channel":"books","instId":"CULTUSDT"},"data":[{"asks":[["0.00003614","306667"],["0.00003618","253333"],["0.00003622","546667"],["0.00003626","520000"],["0.00003630","200000"],["0.00003634","386667"],["0.00003638","146667"],["0.00003642","440000"],["0.00003646","500390"],["0.00003650","653333"],["0.00003654","493333"],["0.00003658","280000"],["0.00003662","413333"],["0.00003666","573333"],["0.00003670","626667"],["0.00003674","466667"],["0.00003678","333333"],["0.00003682","173333"],["0.00003686","360000"],["0.00003690","600000"]],"bids":[["0.00003471","493333"],["0.00003467","1341897"],["0.00003463","466667"],["0.00003459","440000"],["0.00003455","1014821"],["0.00003451","653333"],["0.00003447","173333"],["0.00003443","520000"],["0.00003439","413333"],["0.00003435","386667"],["0.00003431","546667"],["0.00003427","146667"],["0.00003423","226667"],["0.00003419","333333"],["0.00003415","600000"],["0.00003407","573333"],["0.00003403","306667"],["0.00003399","253333"],["0.00003395","280000"]],"checksum":1507901464,"ts":"1649290091756"}]}
1649290091.831637: {"action":"update","arg":{"instType":"sp","channel":"trade","instId":"HOTUSDT"},"data":[["1649290091784","0.005631","887.95","buy"]]}
1649290091.8317199: {"action":"update","arg":{"instType":"sp","channel":"books","instId":"STGUSDT"},"data":[{"asks":[["3.034","2.428"],["3.037","3.188"],["3.040","3.569"],["3.043","1.644"],["3.046","2.301"],["3.049","4.725"],["3.052","2.047"],["3.055","1.638"],["3.058","1.636"],["3.061","2.554"],["3.064","3.442"],["3.067","3.062"],["3.070","1.793"],["3.073","2.681"],["3.076","1.626"],["3.079","4.190"],["3.082","2.935"],["3.085","1.920"],["3.088","2.808"],["3.091","1.667"],["3.094","2.174"],["3.097","3.315"]],"bids":[["2.744","1.823"],["2.741","3.185"],["2.738","19.752"],["2.735","2.862"],["2.732","98.239"],["2.729","1.833"],["2.726","75.467"],["2.720","2.108"],["2.717","1.892"],["2.714","1.843"],["2.711","3.077"],["2.705","2.323"],["2.702","2.754"],["2.699","1.854"],["2.696","92.523"],["2.693","1.858"],["2.690","1.860"],["2.687","2.431"],["2.684","3.292"],["2.681","2.215"],["2.678","2.538"],["2.675","2.969"]],"checksum":-463664090,"ts":"1649290091809"}]}
1649290091.8527732: {"action":"update","arg":{"instType":"sp","channel":"books","instId":"AVAXUSDT"},"data":[{"asks":[["83.1215","0"],["83.1315","0"],["83.1415","0"],["83.1515","3.6400"],["83.1615","5.2920"],["83.1715","36.8480"],["83.1815","111.8390"],["83.1915","108.3180"],["83.2015","178.8360"],["83.2115","11.3890"],["83.2215","66.1010"],["83.2315","180.0000"],["83.2715","78.4280"],["83.2815","176.6310"],["83.3115","29.6870"],["83.3315","3.8430"],["83.5815","3.3110"],["83.6715","52.3320"],["83.6815","180.0000"],["88.0066","0"],["88.0383","0.3833"],["88.0897","0"],["88.1214","0.4500"],["88.1728","0"],["88.2045","0.4167"],["88.2559","0"],["88.2876","0.7833"],["88.3390","0"],["88.3707","0.5167"],["88.4221","0"],["88.4538","0.3500"],["88.5052","0"],["88.5369","0.7167"],["88.5883","0"],["88.6200","0.5833"],["88.6714","0"],["88.7031","0.2500"],["88.7545","0"],["88.7862","0.7500"],["88.8376","0"],["88.8693","0.2167"],["88.9207","0"],["88.9524","0.8167"],["89.0038","0"],["89.0355","0.1833"],["89.0869","0"],["89.1186","0.6500"],["89.1700","0"],["89.2017","0.6833"],["89.2531","0"],["89.2848","0.3167"],["89.3362","0"],["89.3679","0.2833"],["89.4193","0"],["89.4510","0.5500"],["89.5024","0"],["89.5341","0.4833"],["89.5855","0"],["89.6172","0.6167"]],"bids":[["82.9585","96.7120"],["82.9485","43.1410"],["82.9385","30.3660"],["82.9285","96.4880"],["82.9185","80.6470"],["82.9085","53.4450"],["82.8985","53.3050"],["82.8885","132.6080"],["82.8785","180.0000"],["82.8585","25.3540"],["82.8285","5.2570"],["82.8185","160.6290"],["82.7885","10.1080"],["82.7685","36.7360"],["82.7285","154.7140"],["82.7185","120.7920"],["82.7085","162.3860"],["82.6785","174.7410"],["82.6685","88.0670"],["82.5985","95.8160"],["82.5785","26.1240"],["82.5685","63.4060"],["82.5485","129.1080"],["82.5285","10.5140"],["82.4885","118.2580"],["82.4785","114.2820"],["82.4585","0"],["82.4485","0"],["82.4385","0"],["78.0717","0.6167"],["78.0435","0"],["77.9886","0.2167"],["77.9604","0"],["77.9055","0.8167"],["77.8773","0"],["77.8224","0.4500"],["77.7942","0"],["77.7393","0.5833"],["77.7111","0"],["77.6562","0.7167"],["77.6280","0"],["77.5731","0.3833"],["77.5449","0"],["77.4900","0.7500"],["77.4618","0"],["77.4069","0.3167"],["77.3787","0"],["77.3238","0.2500"],["77.2956","0"],["77.2407","0.5500"],["77.2125","0"],["77.1576","0.4167"],["77.1294","0"],["77.0745","0.3500"],["77.0463","0"],["76.9914","0.5167"],["76.9632","0"],["76.9083","0.2833"],["76.8801","0"],["76.8252","0.6833"],["76.7970","0"],["76.7421","0.6500"],["76.7139","0"],["76.6590","0.1833"],["76.6308","0"],["76.5759","0.4833"],["76.5477","0"],["76.4928","0.7833"],["76.4646","0"]],"checksum":-437501812,"ts":"1649290091826"}]}
1649290092.0621219: {"action":"update","arg":{"instType":"sp","channel":"books","instId":"EOSUSDT"},"data":[{"asks":[["2.4408","0"],["2.4409","0"],["2.4410","0"],["2.4412","0"],["2.4413","288.0000"],["2.4414","0"],["2.4415","94.2734"],["2.4419","236.0250"],["2.4423","119.9708"],["2.4425","490.6260"],["2.4426","118.6025"],["2.4427","214.6538"],["2.4429","2466.6414"],["2.4430","550.4914"],["2.4431","2177.3916"],["2.4433","103.3614"],["2.4434","412.5033"],["2.4435","1187.9262"],["2.4436","3907.2228"],["2.4437","2989.9324"],["2.4438","324.7830"],["2.4439","1046.3772"],["2.4440","4019.8500"],["2.4441","628.8117"],["2.4442","252.7647"],["2.4443","82.1185"],["2.4444","3546.0000"],["2.4446","2865.4206"],["2.4447","3312.9188"],["2.4449","3017.8800"],["2.4450","553.4828"],["2.4453","155.0759"],["2.4455","54.4190"],["2.4457","159.3344"],["2.4459","3519.4342"],["2.4466","247.5000"],["2.4468","256.9415"],["2.4469","2061.5077"],["2.4558","0"],["2.4563","540.4762"],["2.4568","478.5714"],["2.4578","545.2381"],["2.4583","502.3810"],["2.4588","454.7619"],["2.4593","530.9524"],["2.4598","535.7143"],["2.4603","492.8571"],["2.4608","526.1905"],["2.4613","516.6667"],["2.4618","483.3333"],["2.4623","464.2857"],["2.4633","488.0952"],["2.4638","507.1429"],["2.4643","521.4286"],["2.4648","497.6190"],["2.4653","473.8095"],["2.4658","459.5238"]],"bids":[["2.4371","2420.3700"],["2.4369","35.0100"],["2.4368","76.2432"],["2.4367","2283.2185"],["2.4366","30.0894"],["2.4365","1883.6307"],["2.4364","8.0522"],["2.4363","882.6795"],["2.4362","150.5348"],["2.4361","1772.5925"],["2.4360","89.0070"],["2.4357","200.7000"],["2.4355","1278.8010"],["2.4354","557.5500"],["2.4353","1018.4029"],["2.4351","2303.6700"],["2.4350","2486.8727"],["2.4349","1062.2453"],["2.4347","435.2045"],["2.4346","3374.7705"],["2.4345","55.4763"],["2.4343","178.1430"],["2.4342","1070.8147"],["2.4341","5881.1175"],["2.4340","82.7588"],["2.4337","225.5085"],["2.4336","3031.8359"],["2.4335","3055.7389"],["2.4334","724.6716"],["2.4331","3080.9409"],["2.4328","1108.6270"],["2.4327","0"],["2.4321","3528.1583"],["2.4318","2596.3377"],["2.4316","0"],["2.4314","0"],["2.4313","0"],["2.4311","0"],["2.4310","0"],["2.4221","492.8571"],["2.4216","521.4286"],["2.4215","0"],["2.4211","469.0476"],["2.4210","0"],["2.4206","540.4762"],["2.4205","0"],["2.4201","488.0952"],["2.4200","0"],["2.4196","511.9048"],["2.4195","0"],["2.4191","454.7619"],["2.4190","0"],["2.4186","478.5714"],["2.4185","0"],["2.4181","535.7143"],["2.4180","0"],["2.4176","516.6667"],["2.4175","0"],["2.4171","530.9524"],["2.4170","0"],["2.4166","459.5238"],["2.4165","0"],["2.4161","473.8095"],["2.4160","0"],["2.4156","502.3810"],["2.4155","0"],["2.4151","545.2381"],["2.4150","0"],["2.4146","526.1905"],["2.4145","0"],["2.4141","483.3333"],["2.4140","0"],["2.4136","497.6190"],["2.4135","0"],["2.4131","507.1429"],["2.4130","0"],["2.4126","464.2857"],["2.4125","0"],["2.4120","0"]],"checksum":-864679241,"ts":"1649290092030"}]}
1649290092.065383: {"action":"update","arg":{"instType":"sp","channel":"books","instId":"GOGUSDT"},"data":[{"asks":[["0.5631","9.6667"],["0.5637","8.8710"],["0.5649","13.0000"],["0.5655","2348.1333"],["0.5661","9.0000"],["0.5667","8.8240"],["0.5685","11.0000"],["0.5691","15.0000"],["0.5697","8.7775"],["0.5703","11.6667"],["0.5709","15.6667"],["0.5715","13.6667"],["0.5721","10.3333"],["0.5727","16.3333"],["0.5733","12.3333"],["0.5739","8.7133"]],"bids":[["0.5512","9.0721"],["0.5506","15.6667"],["0.5500","9.0919"],["0.5494","10.3333"],["0.5488","9.1118"],["0.5482","3670.2333"],["0.5476","13.6667"],["0.5470","14.3333"],["0.5464","9.1518"],["0.5446","13.0000"],["0.5428","16.3333"],["0.5422","9.6667"],["0.5416","15.0000"],["0.5410","11.0000"],["0.5404","11.6667"],["0.5398","9.2637"]],"checksum":1322011877,"ts":"1649290092042"}]}
1649290092.0675771: {"action":"snapshot","arg":{"instType":"sp","channel":"ticker","instId":"EOSUSDT"},"data":[{"instId":"EOSUSDT","last":"2.4393","open24h":"2.5667","high24h":"2.5767","low24h":"2.4155","bestBid":"2.437100","bestAsk":"2.441300","baseVolume":"145522.9643","quoteVolume":"378718.0033","ts":1649290092022,"labeId":0}]}
1649290092.137085: {"action":"update","arg":{"instType":"sp","channel":"books","instId":"SUNUSDT"},"data":[{"asks":[["0.01509","37500"],["0.01511","171903"],["0.01512","167389"],["0.01514","518523"],["0.01515","1037299"],["0.01582","4500"],["0.01584","2500"],["0.01586","5833"],["0.01588","5500"],["0.01590","3833"],["0.01592","7833"],["0.01594","1833"],["0.01596","4833"],["0.01598","6833"],["0.01600","3167"],["0.01602","3500"],["0.01604","2833"],["0.01606","7500"],["0.01608","6500"],["0.01610","4167"],["0.01612","6167"],["0.01614","2167"],["0.01616","5167"],["0.01618","7167"],["0.01620","8167"]],"bids":[["0.01504","580500"],["0.01503","233287"],["0.01502","177541"],["0.01501","576186"],["0.01500","691824"],["0.01490","115917"],["0.01489","682148"],["0.01450","0"],["0.01431","7500"],["0.01430","0"],["0.01429","6167"],["0.01428","0"],["0.01427","7833"],["0.01426","0"],["0.01425","3833"],["0.01424","0"],["0.01423","1833"],["0.01422","0"],["0.01421","5833"],["0.01420","0"],["0.01419","3500"],["0.01418","0"],["0.01417","7167"],["0.01416","0"],["0.01415","4833"],["0.01414","0"],["0.01413","3167"],["0.01412","0"],["0.01411","2500"],["0.01410","0"],["0.01409","5500"],["0.01408","0"],["0.01407","2167"],["0.01406","0"],["0.01405","6833"],["0.01404","0"],["0.01403","8167"],["0.01402","0"],["0.01401","5167"],["0.01400","0"],["0.01399","4167"],["0.01398","0"],["0.01397","4500"],["0.01396","0"],["0.01395","2833"],["0.01394","0"],["0.01393","6500"],["0.01392","0"]],"checksum":1349321325,"ts":"1649290092111"}]}
1649290092.151636: {"action":"snapshot","arg":{"instType":"sp","channel":"ticker","instId":"AVAXUSDT"},"data":[{"instId":"AVAXUSDT","last":"83.1159","open24h":"85.1099","high24h":"86.7605","low24h":"82.5893","bestBid":"82.988500","bestAsk":"83.181500","baseVolume":"3330.8415","quoteVolume":"287733.8455","ts":1649290092097,"labeId":0}]}
1649290092.157357: {"action":"snapshot","arg":{"instType":"sp","channel":"ticker","instId":"VVSUSDT"},"data":[{"instId":"VVSUSDT","last":"0.00002314","open24h":"0.00002350","high24h":"0.00002359","low24h":"0.00002313","bestBid":"0.000024","bestAsk":"0.000024","baseVolume":"2375582289.9083","quoteVolume":"56989.8797","ts":1649290092110,"labeId":0}]}
1649290092.1574469: {"action":"snapshot","arg":{"instType":"sp","channel":"ticker","instId":"HOTUSDT"},"data":[{"instId":"HOTUSDT","last":"0.0056310","open24h":"0.0058560","high24h":"0.0059320","low24h":"0.0055520","bestBid":"0.005620","bestAsk":"0.005636","baseVolume":"10203207.8809","quoteVolume":"60796.5347","ts":1649290092110,"labeId":0}]}
1649290092.179765: {"action":"snapshot","arg":{"instType":"sp","channel":"ticker","instId":"GOGUSDT"},"data":[{"instId":"GOGUSDT","last":"0.5575","open24h":"0.5563","high24h":"0.5708","low24h":"0.5508","bestBid":"0.554700","bestAsk":"0.559000","baseVolume":"134638.2253","quoteVolume":"78741.7865","ts":1649290092131,"labeId":0}]}
1649290092.192783: {"action":"update","arg":{"instType":"sp","channel":"trade","instId":"GOGUSDT"},"data":[["1649290092141","0.5587","8.9494","buy"]]}
1649290092.1973991: {"action":"snapshot","arg":{"instType":"sp","channel":"ticker","instId":"SUNUSDT"},"data":[{"instId":"SUNUSDT","last":"0.01505","open24h":"0.01521","high24h":"0.01559","low24h":"0.01481","bestBid":"0.015040","bestAsk":"0.015090","baseVolume":"11685483","quoteVolume":"180261","ts":1649290092149,"labeId":0}]}
1649290092.199363: {"action":"update","arg":{"instType":"sp","channel":"books","instId":"VVSUSDT"},"data":[{"asks":[["0.00002378","210261.7000"],["0.00002381","862573.1000"],["0.00002387","576023.4000"],["0.00002390","903508.8000"],["0.00002393","657894.7000"],["0.00002399","371345.0000"],["0.00002402","780701.8000"],["0.00002405","739766.1000"],["0.00002408","494152.0000"],["0.00002411","330409.4000"]],"bids":[["0.00002314","39768615.0000"],["0.00002269","289473.7000"],["0.00002263","576023.4000"],["0.00002257","903508.8000"],["0.00002254","780701.8000"],["0.00002251","494152.0000"],["0.00002248","412280.7000"],["0.00002245","453216.4000"],["0.00002242","248538.0000"],["0.00002239","371345.0000"],["0.00002233","535087.7000"]],"checksum":-1177444358,"ts":"1649290092177"}]}
1649290092.221369: {"action":"snapshot","arg":{"instType":"sp","channel":"ticker","instId":"CULTUSDT"},"data":[{"instId":"CULTUSDT","last":"0.00003508","open24h":"0.00004340","high24h":"0.00004397","low24h":"0.00003500","bestBid":"0.000036","bestAsk":"0.000036","baseVolume":"13527006500","quoteVolume":"557444","ts":1649290092174,"labeId":0}]}
1649290092.221461: {"action":"snapshot","arg":{"instType":"sp","channel":"ticker","instId":"STGUSDT"},"data":[{"instId":"STGUSDT","last":"2.879","open24h":"3.045","high24h":"3.164","low24h":"2.757","bestBid":"2.861000","bestAsk":"2.917000","baseVolume":"35330.994","quoteVolume":"111753.060","ts":1649290092175,"labeId":0}]}
1649290092.305826: {"action":"update","arg":{"instType":"sp","channel":"candle1m","instId":"GOGUSDT"},"data":[["1649290080000","0.5555","0.5587","0.5555","0.5587","17.9181"]]}
1649290092.3186822: {"action":"update","arg":{"instType":"sp","channel":"books","instId":"HOTUSDT"},"data":[{"asks":[["0.0056350","0"],["0.0056360","23071.5000"],["0.0056370","123581.2500"],["0.0056380","616015.3500"],["0.0056400","479374.6500"],["0.0056410","55318.5000"],["0.0056420","238536.0000"],["0.0056430","61585.6500"],["0.0056480","0"],["0.0056720","648215.5500"],["0.0056860","24724.3500"],["0.0056930","800000.0000"],["0.0056940","17307.9000"],["0.0059080","0"],["0.0059100","5750.0000"],["0.0059140","0"],["0.0059160","3250.0000"],["0.0059200","0"],["0.0059220","5250.0000"],["0.0059260","0"],["0.0059280","8250.0000"],["0.0059320","0"],["0.0059340","4250.0000"],["0.0059380","0"],["0.0059400","7750.0000"],["0.0059440","0"],["0.0059460","10750.0000"],["0.0059500","0"],["0.0059520","9750.0000"],["0.0059560","0"],["0.0059580","11750.0000"],["0.0059620","0"],["0.0059640","6750.0000"],["0.0059680","0"],["0.0059700","6250.0000"],["0.0059740","0"],["0.0059760","7250.0000"],["0.0059800","0"],["0.0059820","12250.0000"],["0.0059860","0"],["0.0059880","8750.0000"],["0.0059920","0"],["0.0059940","10250.0000"],["0.0059980","0"],["0.0060000","2750.0000"],["0.0060040","0"],["0.0060060","11250.0000"],["0.0060100","0"],["0.0060120","3750.0000"],["0.0060160","0"],["0.0060180","4750.0000"],["0.0060220","0"],["0.0060240","9250.0000"]],"bids":[["0.0056210","67654.8000"],["0.0056200","89146.8000"],["0.0056190","41896.8000"],["0.0056180","156313.8000"],["0.0056170","0"],["0.0056160","0"],["0.0056150","251330.4000"],["0.0056140","450445.9500"],["0.0056130","190368.6600"],["0.0056120","297782.5500"],["0.0056100","5808.6000"],["0.0056080","319900.9500"],["0.0056030","83812.5300"],["0.0056020","216518.8500"],["0.0055970","114706.8000"],["0.0055620","0"],["0.0053470","7750.0000"],["0.0053450","0"],["0.0053410","9250.0000"],["0.0053390","0"],["0.0053350","8250.0000"],["0.0053330","0"],["0.0053290","5250.0000"],["0.0053270","0"],["0.0053230","5750.0000"],["0.0053210","0"],["0.0053170","7250.0000"],["0.0053150","0"],["0.0053110","11250.0000"],["0.0053090","0"],["0.0053050","10750.0000"],["0.0053030","0"],["0.0052990","3750.0000"],["0.0052970","0"],["0.0052930","2750.0000"],["0.0052910","0"],["0.0052870","6750.0000"],["0.0052850","0"],["0.0052810","11750.0000"],["0.0052790","0"],["0.0052750","3250.0000"],["0.0052730","0"],["0.0052690","12250.0000"],["0.0052670","0"],["0.0052630","10250.0000"],["0.0052610","0"],["0.0052570","8750.0000"],["0.0052550","0"],["0.0052510","9750.0000"],["0.0052490","0"],["0.0052450","4750.0000"],["0.0052430","0"],["0.0052390","6250.0000"],["0.0052370","0"],["0.0052330","4250.0000"],["0.0052310","0"]],"checksum":225027048,"ts":"1649290092296"}]}
1649290092.332575: {"action":"update","arg":{"instType":"sp","channel":"candle1m","instId":"HOTUSDT"},"data":[["1649290080000","0.005613","0.005631","0.005613","0.005631","887.95"]]}
1649290092.3717902: {"action":"update","arg":{"instType":"sp","channel":"books","instId":"AVAXUSDT"},"data":[{"asks":[["83.1515","0"],["83.1615","0"],["83.1715","0"],["83.1815","2.0300"],["83.1915","10.5910"],["83.2015","59.0310"],["83.2115","67.1930"],["83.2215","87.6330"],["83.2415","180.0000"],["83.2515","85.8410"],["83.2615","167.4890"],["83.2715","91.1960"],["83.2815","180.0000"],["83.2915","39.8790"],["83.3515","180.0000"],["83.3915","23.8910"],["83.4215","12.0260"],["83.6915","2.4360"],["83.7015","2.4150"],["88.0383","0"],["88.0701","0.4167"],["88.1214","0"],["88.1532","0.4500"],["88.2045","0"],["88.2363","0.7500"],["88.2876","0"],["88.3194","0.7167"],["88.3707","0"],["88.4025","0.1833"],["88.4538","0"],["88.4856","0.2500"],["88.5369","0"],["88.5687","0.6167"],["88.6200","0"],["88.6518","0.6833"],["88.7031","0"],["88.7349","0.3500"],["88.7862","0"],["88.8180","0.3167"],["88.8693","0"],["88.9011","0.5833"],["88.9524","0"],["88.9842","0.3833"],["89.0355","0"],["89.0673","0.8167"],["89.1186","0"],["89.1504","0.5167"],["89.2017","0"],["89.2335","0.4833"],["89.2848","0"],["89.3166","0.2167"],["89.3679","0"],["89.3997","0.6500"],["89.4510","0"],["89.4828","0.5500"],["89.5341","0"],["89.5659","0.7833"],["89.6172","0"],["89.6490","0.2833"]],"bids":[["82.9885","35.3850"],["82.9785","10.5910"],["82.9685","85.0010"],["82.9585","131.9360"],["82.9485","44.1070"],["82.9285","57.8900"],["82.9185","97.8670"],["82.9085","180.0000"],["82.8885","85.1480"],["82.8785","37.7090"],["82.8691","6.6176"],["82.8685","67.4030"],["82.8585","24.6120"],["82.8485","94.0100"],["82.8385","130.6200"],["82.8285","30.6320"],["82.8185","180.0000"],["82.7793","0"],["82.6285","153.6500"],["82.6085","12.8590"],["82.5985","87.4720"],["82.5185","174.8250"],["82.4985","7.1260"],["82.4885","0"],["82.4785","0"],["82.4685","0"],["78.0998","0.3500"],["78.0717","0"],["78.0167","0.7167"],["77.9886","0"],["77.9336","0.4500"],["77.9055","0"],["77.8505","0.7833"],["77.8224","0"],["77.7674","0.3833"],["77.7393","0"],["77.6843","0.2833"],["77.6562","0"],["77.6012","0.4167"],["77.5731","0"],["77.5181","0.5500"],["77.4900","0"],["77.4350","0.1833"],["77.4069","0"],["77.3519","0.3167"],["77.3238","0"],["77.2688","0.6833"],["77.2407","0"],["77.1857","0.2500"],["77.1576","0"],["77.1026","0.4833"],["77.0745","0"],["77.0195","0.6167"],["76.9914","0"],["76.9364","0.6500"],["76.9083","0"],["76.8533","0.2167"],["76.8252","0"],["76.7702","0.7500"],["76.7421","0"],["76.6871","0.8167"],["76.6590","0"],["76.6040","0.5167"],["76.5759","0"],["76.5209","0.5833"],["76.4928","0"]],"checksum":916080780,"ts":"1649290092348"}]}
1649290092.372494: {"action":"update","arg":{"instType":"sp","channel":"books","instId":"STGUSDT"},"data":[{"asks":[["3.034","1.649"],["3.037","1.793"],["3.040","1.646"],["3.043","3.442"],["3.046","2.174"],["3.049","5.486"],["3.052","1.639"],["3.055","3.188"],["3.058","2.808"],["3.061","2.681"],["3.064","2.935"],["3.067","1.631"],["3.070","2.554"],["3.073","3.569"],["3.076","3.062"],["3.079","4.697"],["3.082","3.315"],["3.088","2.428"],["3.091","2.047"],["3.094","1.617"],["3.097","1.667"]],"bids":[["2.741","1.825"],["2.738","20.829"],["2.735","1.829"],["2.732","98.777"],["2.729","2.646"],["2.726","74.929"],["2.723","2.862"],["2.720","2.215"],["2.717","2.000"],["2.714","2.754"],["2.711","1.892"],["2.705","2.538"],["2.702","1.851"],["2.699","2.323"],["2.696","94.570"],["2.684","1.864"],["2.681","1.866"],["2.678","1.868"],["2.672","3.292"]],"checksum":1444020496,"ts":"1649290092350"}]}
1649290092.386569: {"action":"update","arg":{"instType":"sp","channel":"books","instId":"CULTUSDT"},"data":[{"asks":[["0.00003614","333333"],["0.00003618","360000"],["0.00003622","520000"],["0.00003626","653333"],["0.00003630","386667"],["0.00003634","146667"],["0.00003638","546667"],["0.00003642","226667"],["0.00003646","687056"],["0.00003650","466667"],["0.00003654","253333"],["0.00003658","173333"],["0.00003662","573333"],["0.00003666","600000"],["0.00003670","306667"],["0.00003674","280000"],["0.00003678","493333"],["0.00003682","626667"],["0.00003686","200000"],["0.00003690","440000"]],"bids":[["0.00003471","466667"],["0.00003467","1688564"],["0.00003463","226667"],["0.00003459","306667"],["0.00003455","881487"],["0.00003451","280000"],["0.00003447","653333"],["0.00003443","146667"],["0.00003439","253333"],["0.00003435","200000"],["0.00003431","440000"],["0.00003427","626667"],["0.00003423","413333"],["0.00003419","573333"],["0.00003415","386667"],["0.00003411","173333"],["0.00003407","333333"],["0.00003403","600000"],["0.00003399","360000"],["0.00003395","520000"]],"checksum":-1768216886,"ts":"1649290092364"}]}
1649290092.602875: {"action":"update","arg":{"instType":"sp","channel":"books","instId":"GOGUSDT"},"data":[{"asks":[["0.5625","12.3333"],["0.5631","8.8804"],["0.5637","11.0000"],["0.5643","14.3333"],["0.5649","8.8521"],["0.5655","2344.1333"],["0.5661","8.8334"],["0.5667","15.0000"],["0.5679","9.6667"],["0.5685","9.0000"],["0.5691","13.6667"],["0.5697","13.0000"],["0.5703","8.7683"],["0.5709","8.7591"],["0.5715","16.3333"],["0.5721","8.7407"],["0.5727","15.6667"],["0.5733","8.7224"],["0.5739","11.6667"]],"bids":[["0.5506","9.0820"],["0.5494","16.3333"],["0.5488","15.0000"],["0.5482","3681.5667"],["0.5476","13.0000"],["0.5470","9.1418"],["0.5464","9.6667"],["0.5458","10.3333"],["0.5452","11.0000"],["0.5446","9.1821"],["0.5434","13.6667"],["0.5428","11.6667"],["0.5422","12.3333"],["0.5416","9.2329"],["0.5410","14.3333"],["0.5404","9.2534"]],"checksum":636802005,"ts":"1649290092581"}]}
1649290092.6537778: {"action":"update","arg":{"instType":"sp","channel":"books","instId":"EOSUSDT"},"data":[{"asks":[["2.4413","0"],["2.4415","0"],["2.4416","0"],["2.4419","0"],["2.4420","0"],["2.4422","0"],["2.4423","0"],["2.4424","295.4250"],["2.4426","91.4355"],["2.4427","833.3786"],["2.4428","180.0000"],["2.4429","2290.0361"],["2.4430","37.9800"],["2.4431","220.8573"],["2.4432","0"],["2.4433","237.3976"],["2.4434","375.0066"],["2.4435","559.7073"],["2.4436","0"],["2.4437","27.0000"],["2.4438","82.7986"],["2.4439","1059.7463"],["2.4440","3719.7000"],["2.4441","210.3117"],["2.4442","339.0446"],["2.4443","4114.8577"],["2.4444","2570.5414"],["2.4445","0"],["2.4446","1456.9206"],["2.4447","2631.7416"],["2.4449","1301.5800"],["2.4450","2178.5055"],["2.4452","3655.0418"],["2.4453","59.2407"],["2.4454","79.8774"],["2.4457","1458.0894"],["2.4458","27.1182"],["2.4459","3453.6427"],["2.4460","2881.1266"],["2.4461","2496.9106"],["2.4462","1742.4480"],["2.4466","341.3452"],["2.4469","2511.8384"],["2.4470","1292.2266"],["2.4471","45.6167"],["2.4472","1877.0296"],["2.4473","983.7739"],["2.4474","1123.4713"],["2.4475","582.3195"],["2.4476","1085.9157"],["2.4477","2310.0570"],["2.4478","2326.7229"],["2.4563","0"],["2.4568","0"],["2.4573","0"],["2.4574","459.5238"],["2.4578","0"],["2.4579","464.2857"],["2.4583","0"],["2.4584","545.2381"],["2.4588","0"],["2.4589","483.3333"],["2.4593","0"],["2.4594","535.7143"],["2.4598","0"],["2.4599","502.3810"],["2.4603","0"],["2.4604","492.8571"],["2.4608","0"],["2.4609","473.8095"],["2.4613","0"],["2.4614","526.1905"],["2.4618","0"],["2.4619","540.4762"],["2.4623","0"],["2.4624","521.4286"],["2.4628","0"],["2.4629","530.9524"],["2.4633","0"],["2.4634","488.0952"],["2.4638","0"],["2.4639","454.7619"],["2.4643","0"],["2.4644","511.9048"],["2.4648","0"],["2.4649","478.5714"],["2.4653","0"],["2.4654","497.6190"],["2.4658","0"],["2.4659","469.0476"],["2.4664","507.1429"],["2.4669","516.6667"]],"bids":[["2.4382","35.0100"],["2.4381","1501.6510"],["2.4380","254.4698"],["2.4379","2191.8794"],["2.4377","291.3593"],["2.4375","83.8440"],["2.4374","83.8474"],["2.4371","995.8611"],["2.4370","68.3821"],["2.4369","8.0518"],["2.4368","571.6144"],["2.4367","57.2400"],["2.4366","2493.0834"],["2.4365","2700.0000"],["2.4363","403.9526"],["2.4362","2140.8380"],["2.4361","1305.2700"],["2.4360","397.6712"],["2.4358","1398.1139"],["2.4357","794.6311"],["2.4356","390.4924"],["2.4355","861.8387"],["2.4354","604.5914"],["2.4353","3971.3029"],["2.4352","41.7385"],["2.4351","3892.4400"],["2.4350","3700.7760"],["2.4349","222.0361"],["2.4348","1345.2876"],["2.4347","763.9034"],["2.4346","1929.6778"],["2.4345","2202.2048"],["2.4343","1115.3184"],["2.4342","119.4285"],["2.4341","8160.6600"],["2.4340","258.6240"],["2.4339","497.2594"],["2.4338","2168.1388"],["2.4337","502.1476"],["2.4336","1897.6179"],["2.4335","947.1583"],["2.4333","192.7247"],["2.4331","2179.9209"],["2.4330","836.0399"],["2.4328","1081.4530"],["2.4327","1253.2395"],["2.4326","0"],["2.4325","0"],["2.4324","0"],["2.4323","0"],["2.4322","0"],["2.4321","0"],["2.4319","0"],["2.4318","0"],["2.4317","0"],["2.4232","469.0476"],["2.4227","473.8095"],["2.4222","526.1905"],["2.4221","0"],["2.4217","497.6190"],["2.4216","0"],["2.4212","511.9048"],["2.4211","0"],["2.4207","492.8571"],["2.4206","0"],["2.4202","530.9524"],["2.4201","0"],["2.4197","516.6667"],["2.4196","0"],["2.4192","540.4762"],["2.4191","0"],["2.4187","454.7619"],["2.4186","0"],["2.4182","459.5238"],["2.4181","0"],["2.4177","502.3810"],["2.4176","0"],["2.4172","545.2381"],["2.4171","0"],["2.4167","535.7143"],["2.4166","0"],["2.4162","488.0952"],["2.4161","0"],["2.4157","464.2857"],["2.4156","0"],["2.4152","521.4286"],["2.4151","0"],["2.4147","507.1429"],["2.4146","0"],["2.4142","483.3333"],["2.4141","0"],["2.4137","478.5714"],["2.4136","0"],["2.4131","0"],["2.4126","0"]],"checksum":15968494,"ts":"1649290092627"}]}
1649290092.67921: {"action":"update","arg":{"instType":"sp","channel":"books","instId":"SUNUSDT"},"data":[{"asks":[["0.01509","33797"],["0.01510","5155"],["0.01511","232129"],["0.01512","34821"],["0.01513","251518"],["0.01514","1648060"],["0.01515","2428"],["0.01522","211169"],["0.01568","0"],["0.01582","0"],["0.01583","2833"],["0.01584","0"],["0.01585","5167"],["0.01586","0"],["0.01587","2167"],["0.01588","0"],["0.01589","7167"],["0.01590","0"],["0.01591","7500"],["0.01592","0"],["0.01593","3833"],["0.01594","0"],["0.01595","6167"],["0.01596","0"],["0.01597","4500"],["0.01598","0"],["0.01599","6500"],["0.01600","0"],["0.01601","7833"],["0.01602","0"],["0.01603","8167"],["0.01604","0"],["0.01605","2500"],["0.01606","0"],["0.01607","4833"],["0.01608","0"],["0.01609","5833"],["0.01610","0"],["0.01611","3167"],["0.01612","0"],["0.01613","1833"],["0.01614","0"],["0.01615","5500"],["0.01616","0"],["0.01617","6833"],["0.01618","0"],["0.01619","3500"],["0.01620","0"],["0.01621","4167"]],"bids":[["0.01505","19800"],["0.01504","380700"],["0.01503","237608"],["0.01502","304774"],["0.01501","627180"],["0.01500","641169"],["0.01489","341226"],["0.01451","0"],["0.01431","7167"],["0.01429","3500"],["0.01427","6167"],["0.01425","7833"],["0.01423","2833"],["0.01421","6500"],["0.01419","4833"],["0.01417","1833"],["0.01415","3833"],["0.01413","7500"],["0.01411","4500"],["0.01409","3167"],["0.01407","2500"],["0.01405","4167"],["0.01403","6833"],["0.01399","5833"],["0.01397","2167"],["0.01395","8167"],["0.01393","5500"]],"checksum":969733139,"ts":"1649290092655"}]}
1649290092.716993: {"action":"update","arg":{"instType":"sp","channel":"trade","instId":"VVSUSDT"},"data":[["1649290092641","0.00002327","214869","buy"]]}
