1649290104.9485161: {"action":"snapshot","arg":{"instType":"mc","channel":"ticker","instId":"UNIUSDT"},"data":[{"instId":"UNIUSDT","last":"9.9770","bestAsk":"9.975","bestBid":"9.97","high24h":"10.4280","low24h":"9.9030","priceChangePercent":"-0.0393","capitalRate":"-0.000100","nextSettleTime":1649314800000,"systemTime":1649290104921,"markPrice":"9.9744","indexPrice":"9.9818","holding":"369411","baseVolume":"313114","quoteVolume":"3294754"}]}
1649290104.964117: {"action":"snapshot","arg":{"instType":"mc","channel":"ticker","instId":"DASHUSDT"},"data":[{"instId":"DASHUSDT","last":"113.340","bestAsk":"113.4","bestBid":"113.35","high24h":"118.870","low24h":"113.140","priceChangePercent":"-0.036","capitalRate":"-0.000100","nextSettleTime":1649314800000,"systemTime":1649290104934,"markPrice":"113.386","indexPrice":"113.402","holding":"21957.17","baseVolume":"25307.14","quoteVolume":"3062978.45"}]}
1649290104.984256: {"action":"update","arg":{"instType":"mc","channel":"trade","instId":"DASHUSDT"},"data":[["1649290104884","113.37","0.95","buy"]]}
1649290105.021457: {"action":"update","arg":{"instType":"mc","channel":"books","instId":"DASHUSDT"},"data":[{"asks":[["113.37","6.12"],["113.38","10.72"],["113.39","0.47"],["113.40","9.47"],["113.44","10.41"],["113.46","9.76"],["113.47","28.77"],["113.49","3.85"],["113.50","139.78"],["113.51","32.86"],["113.52","91.24"],["113.53","22.62"],["113.54","40.07"],["113.55","86.48"],["113.56","109.16"],["113.57","35.61"],["113.58","9.72"],["113.59","1600.40"],["113.61","218.50"],["113.62","15.20"],["113.64","87.29"],["113.65","59.93"],["113.67","23.27"],["113.68","674.42"],["113.69","30.51"],["113.70","35.07"],["113.72","197.19"],["113.73","175.70"],["113.74","158.84"],["113.77","798.05"],["113.80","1922.01"],["113.81","18.76"],["113.82","44.24"],["113.85","254.67"],["113.86","1890.99"],["113.87","72.33"],["113.88","0"],["113.89","0"],["113.90","0"],["113.91","0"],["113.92","1753.69"],["113.97","0"],["113.98","1797.80"],["114.03","0"],["114.04","2040.45"],["114.09","0"],["114.10","2018.39"],["114.15","0"],["114.16","1731.63"],["114.21","0"],["114.22","1775.75"],["114.27","0"],["114.28","1974.27"],["114.33","0"],["114.34","1996.33"],["114.39","0"],["114.40","1886.04"],["114.45","0"],["114.46","1952.22"],["114.51","0"],["114.52","1908.10"],["114.57","0"],["114.58","1930.16"],["114.63","0"],["114.64","1819.86"],["114.69","0"],["114.70","1863.98"],["114.75","0"]],"bids":[["113.36","0"],["113.35","0"],["113.34","0"],["113.33","0"],["113.32","0"],["113.31","89.11"],["113.30","12.27"],["113.29","4.96"],["113.28","73.66"],["113.26","1600.28"],["113.24","101.98"],["113.23","36.54"],["113.22","11.38"],["113.21","13.02"],["113.20","187.17"],["113.19","0.80"],["113.18","24.23"],["113.15","402.67"],["113.14","651.08"],["113.13","103.93"],["113.11","19.89"],["113.08","68.03"],["113.06","31.86"],["113.04","6.23"],["113.02","80.29"],["113.00","1497.92"],["112.99","41.18"],["112.98","629.12"],["112.97","121.01"],["112.95","331.62"],["112.94","25.20"],["112.93","122.92"],["112.88","1898.13"],["112.87","419.36"],["112.86","2.76"],["112.85","194.16"],["112.84","41.36"],["112.83","5.02"],["112.82","1890.53"],["112.81","0"],["112.76","1841.92"],["112.75","0"],["112.70","1775.75"],["112.69","0"],["112.64","1930.16"],["112.63","0"],["112.58","1974.27"],["112.57","0"],["112.52","1731.63"],["112.51","0"],["112.46","1797.80"],["112.45","0"],["112.40","1908.10"],["112.39","0"],["112.34","1753.69"],["112.33","0"],["112.28","2018.39"],["112.27","0"],["112.22","1819.86"],["112.21","0"],["112.16","1709.57"],["112.15","0"],["112.10","2040.45"],["112.09","0"],["112.04","1952.22"],["112.03","0"],["111.98","1996.33"]],"checksum":738352951,"ts":"1649290104992"}]}
1649290105.189039: {"action":"update","arg":{"instType":"mc","channel":"candle1m","instId":"DASHUSDT"},"data":[["1649290080000","113.37","113.55","113.34","113.37","6.2"]]}
1649290105.2080278: {"action":"update","arg":{"instType":"mc","channel":"books","instId":"UNIUSDT"},"data":[{"asks":[["9.974","30"],["9.975","161"],["9.977","252"],["9.978","306"],["9.979","397"],["9.980","148"],["9.981","718"],["9.982","1944"],["9.983","903"],["9.984","369"],["9.985","309"],["9.986","150"],["9.987","736"],["9.988","359"],["9.989","705"],["9.990","840"],["9.991","813"],["9.992","508"],["9.993","2437"],["9.994","2358"],["9.995","465"],["9.996","1532"],["9.997","769"],["9.998","332"],["10.002","948"],["10.004","496"],["10.007","475"],["10.008","245"],["10.011","4589"],["10.015","124"],["10.017","7830"],["10.019","493"],["10.020","4522"],["10.022","12468"],["10.023","1012"],["10.024","0"],["10.027","12597"],["10.028","0"],["10.032","11828"],["10.033","0"],["10.037","12789"],["10.038","0"],["10.042","13366"],["10.043","0"],["10.047","12020"],["10.048","0"],["10.052","13174"],["10.053","0"],["10.057","11636"],["10.058","0"],["10.062","12405"],["10.063","0"],["10.067","11443"],["10.068","0"],["10.072","13559"],["10.073","0"],["10.077","12982"],["10.078","0"],["10.110","60"],["10.116","0"],["10.162","174"],["10.168","0"],["10.214","366"],["10.220","0"],["10.266","361"],["10.272","0"],["10.318","240"],["10.324","0"],["10.370","123"],["10.376","0"],["10.422","268"],["10.428","0"],["10.474","79"],["10.480","0"],["10.526","164"],["10.532","0"],["10.578","327"],["10.584","0"],["10.630","205"],["10.636","0"],["10.682","204"],["10.688","0"],["10.734","24"],["10.740","0"],["10.786","134"],["10.792","0"],["10.838","170"],["10.844","0"],["10.890","84"],["10.896","0"],["10.942","94"],["10.948","0"],["10.994","41"],["11.000","0"],["11.046","221"],["11.052","0"],["11.098","421"],["11.104","0"],["11.150","28"],["11.156","0"],["11.202","103"],["11.208","0"],["11.254","180"],["11.260","0"],["11.306","312"],["11.312","0"],["11.358","123"],["11.364","0"],["11.410","186"],["11.416","0"],["11.462","335"],["11.468","0"]],"bids":[["9.970","0"],["9.969","228"],["9.968","33"],["9.967","265"],["9.965","767"],["9.964","151"],["9.962","1397"],["9.960","450"],["9.959","693"],["9.958","592"],["9.956","562"],["9.954","724"],["9.952","1413"],["9.951","1191"],["9.948","564"],["9.945","891"],["9.944","3363"],["9.942","1140"],["9.940","466"],["9.939","2629"],["9.938","103"],["9.937","825"],["9.936","647"],["9.935","309"],["9.934","221"],["9.932","820"],["9.930","1155"],["9.929","311"],["9.928","3535"],["9.925","8509"],["9.923","552"],["9.922","8288"],["9.921","11498"],["9.920","675"],["9.917","0"],["9.916","12213"],["9.912","0"],["9.911","12597"],["9.907","0"],["9.906","12405"],["9.902","0"],["9.901","13559"],["9.897","0"],["9.896","12982"],["9.892","0"],["9.891","13174"],["9.887","0"],["9.886","11828"],["9.882","0"],["9.881","13366"],["9.877","0"],["9.876","12020"],["9.872","0"],["9.871","11636"],["9.867","0"],["9.866","12789"],["9.782","0"],["9.776","109"],["9.731","0"],["9.725","308"],["9.681","0"],["9.675","160"],["9.631","0"],["9.625","151"],["9.581","0"],["9.575","245"],["9.531","0"],["9.525","194"],["9.481","0"],["9.475","352"],["9.431","0"],["9.425","104"],["9.381","0"],["9.375","260"],["9.331","0"],["9.325","181"],["9.281","0"],["9.275","236"],["9.231","0"],["9.225","196"],["9.181","0"],["9.175","326"],["9.131","0"],["9.125","70"],["9.081","0"],["9.075","222"],["9.031","0"],["9.025","174"],["8.981","0"],["8.975","321"],["8.931","0"],["8.925","170"],["8.881","0"],["8.875","63"],["8.831","0"],["8.825","102"],["8.781","0"],["8.775","141"],["8.731","0"],["8.725","261"],["8.681","0"],["8.675","42"],["8.631","0"],["8.625","371"],["8.581","0"],["8.575","156"],["8.531","0"],["8.525","111"]],"checksum":-1610075146,"ts":"1649290105177"}]}
1649290105.2219331: {"action":"snapshot","arg":{"instType":"mc","channel":"ticker","instId":"UNIUSDT"},"data":[{"instId":"UNIUSDT","last":"9.9770","bestAsk":"9.974","bestBid":"9.969","high24h":"10.4280","low24h":"9.9030","priceChangePercent":"-0.0393","capitalRate":"-0.000100","nextSettleTime":1649314800000,"systemTime":1649290105188,"markPrice":"9.9744","indexPrice":"9.9818","holding":"369411","baseVolume":"313114","quoteVolume":"3294754"}]}
1649290105.221983: {"action":"snapshot","arg":{"instType":"mc","channel":"ticker","instId":"DASHUSDT"},"data":[{"instId":"DASHUSDT","last":"113.370","bestAsk":"113.39","bestBid":"113.34","high24h":"118.870","low24h":"113.140","priceChangePercent":"-0.036","capitalRate":"-0.000100","nextSettleTime":1649314800000,"systemTime":1649290105192,"markPrice":"113.386","indexPrice":"113.402","holding":"21957.17","baseVolume":"25308.09","quoteVolume":"3063086.16"}]}
1649290105.31984: {"action":"update","arg":{"instType":"mc","channel":"books","instId":"DASHUSDT"},"data":[{"asks":[["113.37","10.27"],["113.38","7.53"],["113.40","3.97"],["113.42","23.80"],["113.43","3.76"],["113.44","5.17"],["113.45","18.50"],["113.46","21.72"],["113.47","13.88"],["113.48","34.70"],["113.49","67.06"],["113.50","181.15"],["113.51","40.87"],["113.52","98.02"],["113.53","15.71"],["113.56","54.38"],["113.57","33.13"],["113.58","8.46"],["113.59","1600.03"],["113.60","136.81"],["113.61","147.38"],["113.62","17.93"],["113.63","362.11"],["113.64","88.01"],["113.65","51.42"],["113.66","142.46"],["113.68","639.28"],["113.69","31.99"],["113.70","28.23"],["113.73","171.25"],["113.74","157.35"],["113.75","35.34"],["113.76","248.95"],["113.77","812.57"],["113.79","14.50"],["113.80","1925.54"],["113.81","5.89"],["113.83","27.93"],["113.85","256.65"],["113.86","1798.67"],["113.87","56.48"],["113.92","1952.22"],["113.98","2040.45"],["114.04","1996.33"],["114.10","1974.27"],["114.22","1908.10"],["114.28","1819.86"],["114.34","1841.92"],["114.40","1863.98"],["114.46","1797.80"],["114.52","1930.16"],["114.58","2018.39"],["114.64","1775.75"],["114.70","1886.04"]],"bids":[["113.31","94.06"],["113.30","146.75"],["113.29","0"],["113.27","18.90"],["113.26","43.85"],["113.25","121.22"],["113.24","1600.34"],["113.23","39.02"],["113.20","188.66"],["113.19","0"],["113.18","18.88"],["113.17","23.93"],["113.16","27.95"],["113.15","425.00"],["113.14","588.21"],["113.13","105.25"],["113.12","187.87"],["113.10","50.50"],["113.08","97.76"],["113.07","16.21"],["113.03","41.39"],["112.96","214.64"],["112.93","155.45"],["112.92","63.82"],["112.88","1813.48"],["112.83","6.35"],["112.82","2044.94"],["112.81","82.64"],["112.80","4.91"],["112.76","2018.39"],["112.70","1797.80"],["112.64","1996.33"],["112.58","1753.69"],["112.52","1908.10"],["112.46","1709.57"],["112.40","1886.04"],["112.34","1930.16"],["112.28","1731.63"],["112.22","1974.27"],["112.16","1841.92"],["112.10","1952.22"],["112.04","1819.86"],["111.98","1863.98"]],"checksum":-274365031,"ts":"1649290105291"}]}
1649290105.4806569: {"action":"snapshot","arg":{"instType":"mc","channel":"ticker","instId":"UNIUSDT"},"data":[{"instId":"UNIUSDT","last":"9.9770","bestAsk":"9.974","bestBid":"9.969","high24h":"10.4280","low24h":"9.9030","priceChangePercent":"-0.0393","capitalRate":"-0.000100","nextSettleTime":1649314800000,"systemTime":1649290105448,"markPrice":"9.9742","indexPrice":"9.9818","holding":"369411","baseVolume":"313114","quoteVolume":"3294754"}]}
1649290105.492286: {"action":"snapshot","arg":{"instType":"mc","channel":"ticker","instId":"DASHUSDT"},"data":[{"instId":"DASHUSDT","last":"113.370","bestAsk":"113.39","bestBid":"113.34","high24h":"118.870","low24h":"113.140","priceChangePercent":"-0.036","capitalRate":"-0.000100","nextSettleTime":1649314800000,"systemTime":1649290105457,"markPrice":"113.386","indexPrice":"113.402","holding":"21957.17","baseVolume":"25308.09","quoteVolume":"3063086.16"}]}
1649290105.529449: {"action":"update","arg":{"instType":"mc","channel":"books","instId":"UNIUSDT"},"data":[{"asks":[["9.974","119"],["9.975","209"],["9.976","320"],["9.977","356"],["9.978","851"],["9.979","517"],["9.980","49"],["9.981","580"],["9.982","1410"],["9.983","791"],["9.984","344"],["9.986","125"],["9.987","769"],["9.988","348"],["9.989","1203"],["9.990","1076"],["9.991","639"],["9.992","565"],["9.993","2526"],["9.995","367"],["9.998","356"],["9.999","456"],["10.000","419"],["10.002","931"],["10.007","387"],["10.009","300"],["10.011","4579"],["10.013","3071"],["10.015","181"],["10.016","915"],["10.017","8065"],["10.019","617"],["10.021","86"],["10.022","13044"],["10.027","12020"],["10.032","12405"],["10.037","12597"],["10.042","11636"],["10.047","11828"],["10.057","13366"],["10.062","13559"],["10.067","12982"],["10.072","12213"],["10.077","11443"],["10.103","60"],["10.110","0"],["10.155","174"],["10.162","0"],["10.207","366"],["10.214","0"],["10.259","361"],["10.266","0"],["10.311","240"],["10.318","0"],["10.363","123"],["10.370","0"],["10.415","268"],["10.422","0"],["10.467","79"],["10.474","0"],["10.519","164"],["10.526","0"],["10.571","327"],["10.578","0"],["10.623","205"],["10.630","0"],["10.675","204"],["10.682","0"],["10.727","24"],["10.734","0"],["10.779","134"],["10.786","0"],["10.831","170"],["10.838","0"],["10.883","84"],["10.890","0"],["10.935","94"],["10.942","0"],["10.987","41"],["10.994","0"],["11.039","221"],["11.046","0"],["11.091","421"],["11.098","0"],["11.143","28"],["11.150","0"],["11.195","103"],["11.202","0"],["11.247","180"],["11.254","0"],["11.299","312"],["11.306","0"],["11.351","123"],["11.358","0"],["11.403","186"],["11.410","0"],["11.455","335"],["11.462","0"]],"bids":[["9.969","211"],["9.968","71"],["9.966","427"],["9.965","142"],["9.964","107"],["9.963","785"],["9.962","1337"],["9.961","245"],["9.960","462"],["9.959","774"],["9.958","595"],["9.956","615"],["9.954","667"],["9.953","818"],["9.952","1316"],["9.951","1109"],["9.950","572"],["9.949","905"],["9.947","392"],["9.946","355"],["9.944","3465"],["9.942","2170"],["9.940","453"],["9.938","2599"],["9.937","383"],["9.936","729"],["9.935","286"],["9.934","346"],["9.933","2828"],["9.932","1033"],["9.931","3581"],["9.930","2225"],["9.929","361"],["9.928","3591"],["9.925","8494"],["9.922","7738"],["9.921","11514"],["9.916","12020"],["9.911","11636"],["9.906","12213"],["9.896","13174"],["9.891","12405"],["9.881","12982"],["9.876","13366"],["9.871","12597"],["9.776","0"],["9.769","109"],["9.725","0"],["9.718","308"],["9.675","0"],["9.668","160"],["9.625","0"],["9.618","151"],["9.575","0"],["9.568","245"],["9.525","0"],["9.518","194"],["9.475","0"],["9.468","352"],["9.425","0"],["9.418","104"],["9.375","0"],["9.368","260"],["9.325","0"],["9.318","181"],["9.275","0"],["9.268","236"],["9.225","0"],["9.218","196"],["9.175","0"],["9.168","326"],["9.125","0"],["9.118","70"],["9.075","0"],["9.068","222"],["9.025","0"],["9.018","174"],["8.975","0"],["8.968","321"],["8.925","0"],["8.918","170"],["8.875","0"],["8.868","63"],["8.825","0"],["8.818","102"],["8.775","0"],["8.768","141"],["8.725","0"],["8.718","261"],["8.675","0"],["8.668","42"],["8.625","0"],["8.618","371"],["8.575","0"],["8.568","156"],["8.525","0"],["8.518","111"]],"checksum":-365816491,"ts":"1649290105497"}]}
1649290105.5356271: {"action":"update","arg":{"instType":"mc","channel":"trade","instId":"UNIUSDT"},"data":[["1649290105469","9.971","5","sell"]]}
1649290105.630677: {"action":"update","arg":{"instType":"mc","channel":"books","instId":"DASHUSDT"},"data":[{"asks":[["113.37","0"],["113.38","0"],["113.39","5.72"],["113.40","11.69"],["113.42","33.23"],["113.46","44.70"],["113.47","17.64"],["113.48","14.51"],["113.49","5.16"],["113.50","68.91"],["113.51","28.90"],["113.52","57.43"],["113.53","16.99"],["113.54","53.39"],["113.55","88.53"],["113.56","83.75"],["113.57","29.57"],["113.58","6.33"],["113.59","54.08"],["113.60","122.35"],["113.61","3.77"],["113.62","806.34"],["113.63","281.92"],["113.66","38.18"],["113.68","672.94"],["113.69","30.51"],["113.70","45.06"],["113.74","161.81"],["113.75","29.66"],["113.76","364.38"],["113.77","798.05"],["113.79","92.17"],["113.80","212.45"],["113.81","18.76"],["113.82","1753.80"],["113.83","18.52"],["113.85","254.67"],["113.86","89.11"],["113.88","1948.97"],["113.89","5.65"],["113.92","0"],["113.94","1841.92"],["113.98","0"],["114.00","1908.10"],["114.04","0"],["114.06","1886.04"],["114.10","0"],["114.12","2018.39"],["114.16","0"],["114.18","1775.75"],["114.22","0"],["114.24","1753.69"],["114.28","0"],["114.30","1797.80"],["114.34","0"],["114.36","1996.33"],["114.40","0"],["114.42","1731.63"],["114.46","0"],["114.48","1819.86"],["114.52","0"],["114.54","1974.27"],["114.58","0"],["114.60","1952.22"],["114.64","0"],["114.66","1863.98"],["114.70","0"],["114.72","2040.45"]],"bids":[["113.34","4.96"],["113.33","121.91"],["113.32","25.75"],["113.31","218.80"],["113.30","1600.13"],["113.27","14.94"],["113.26","254.72"],["113.25","44.00"],["113.24","540.55"],["113.22","20.05"],["113.16","25.20"],["113.15","206.40"],["113.14","808.98"],["113.13","99.61"],["113.12","117.08"],["113.10","13.77"],["113.09","26.79"],["113.08","71.68"],["113.00","17.88"],["112.99","39.58"],["112.95","1600.05"],["112.94","0.89"],["112.91","2022.37"],["112.88","51.38"],["112.85","1903.72"],["112.82","0"],["112.81","0"],["112.80","0"],["112.79","1863.98"],["112.76","0"],["112.73","1753.69"],["112.70","0"],["112.67","1952.22"],["112.64","0"],["112.61","1775.75"],["112.58","0"],["112.55","1996.33"],["112.52","0"],["112.49","1731.63"],["112.46","0"],["112.43","1797.80"],["112.40","0"],["112.37","1886.04"],["112.34","0"],["112.31","1819.86"],["112.28","0"],["112.25","2040.45"],["112.22","0"],["112.19","1841.92"],["112.16","0"],["112.13","1974.27"],["112.10","0"],["112.07","1908.10"],["112.04","0"],["112.01","1930.16"],["111.98","0"]],"checksum":952670769,"ts":"1649290105601"}]}
1649290105.6651819: {"action":"update","arg":{"instType":"mc","channel":"candle1m","instId":"UNIUSDT"},"data":[["1649290080000","9.977","9.986","9.971","9.971","46"]]}
1649290105.7766788: {"action":"snapshot","arg":{"instType":"mc","channel":"ticker","instId":"UNIUSDT"},"data":[{"instId":"UNIUSDT","last":"9.9710","bestAsk":"9.974","bestBid":"9.969","high24h":"10.4280","low24h":"9.9030","priceChangePercent":"-0.0399","capitalRate":"-0.000100","nextSettleTime":1649314800000,"systemTime":1649290105737,"markPrice":"9.9742","indexPrice":"9.9818","holding":"369411","baseVolume":"313119","quoteVolume":"3294803"}]}
1649290105.776778: {"action":"snapshot","arg":{"instType":"mc","channel":"ticker","instId":"DASHUSDT"},"data":[{"instId":"DASHUSDT","last":"113.370","bestAsk":"113.37","bestBid":"113.32","high24h":"118.870","low24h":"113.140","priceChangePercent":"-0.036","capitalRate":"-0.000100","nextSettleTime":1649314800000,"systemTime":1649290105743,"markPrice":"113.386","indexPrice":"113.402","holding":"21957.17","baseVolume":"25308.09","quoteVolume":"3063086.16"}]}
1649290105.866016: {"action":"update","arg":{"instType":"mc","channel":"books","instId":"UNIUSDT"},"data":[{"asks":[["9.974","48"],["9.975","142"],["9.976","14"],["9.977","240"],["9.978","264"],["9.980","390"],["9.981","462"],["9.982","919"],["9.983","639"],["9.984","466"],["9.986","144"],["9.987","857"],["9.991","677"],["9.992","620"],["9.993","2453"],["9.996","1485"],["9.998","283"],["10.003","1123"],["10.007","405"],["10.008","358"],["10.011","4621"],["10.019","493"],["10.021","128"],["10.022","12083"],["10.027","11443"],["10.037","12789"],["10.047","12597"],["10.052","12982"],["10.057","12020"],["10.062","13366"],["10.067","13174"],["10.077","13559"],["10.097","60"],["10.103","0"],["10.149","174"],["10.155","0"],["10.201","366"],["10.207","0"],["10.253","361"],["10.259","0"],["10.305","240"],["10.311","0"],["10.357","123"],["10.363","0"],["10.409","268"],["10.415","0"],["10.461","79"],["10.467","0"],["10.513","164"],["10.519","0"],["10.565","327"],["10.571","0"],["10.617","205"],["10.623","0"],["10.669","204"],["10.675","0"],["10.721","24"],["10.727","0"],["10.773","134"],["10.779","0"],["10.825","170"],["10.831","0"],["10.877","84"],["10.883","0"],["10.929","94"],["10.935","0"],["10.981","41"],["10.987","0"],["11.033","221"],["11.039","0"],["11.085","421"],["11.091","0"],["11.137","28"],["11.143","0"],["11.189","103"],["11.195","0"],["11.241","180"],["11.247","0"],["11.293","312"],["11.299","0"],["11.345","123"],["11.351","0"],["11.397","186"],["11.403","0"],["11.449","335"],["11.455","0"]],"bids":[["9.969","152"],["9.968","51"],["9.966","732"],["9.965","202"],["9.964","56"],["9.963","834"],["9.961","304"],["9.960","410"],["9.958","656"],["9.956","659"],["9.955","708"],["9.953","797"],["9.951","1150"],["9.950","519"],["9.949","927"],["9.946","318"],["9.943","999"],["9.941","2257"],["9.940","552"],["9.939","2606"],["9.938","2625"],["9.936","643"],["9.934","378"],["9.931","3604"],["9.921","12860"],["9.916","12405"],["9.911","13174"],["9.906","11828"],["9.901","13366"],["9.896","11636"],["9.891","12213"],["9.886","12020"],["9.881","12597"],["9.876","12982"],["9.871","11443"],["9.866","13559"],["9.769","0"],["9.763","109"],["9.718","0"],["9.712","308"],["9.668","0"],["9.662","160"],["9.618","0"],["9.612","151"],["9.568","0"],["9.562","245"],["9.518","0"],["9.512","194"],["9.468","0"],["9.462","352"],["9.418","0"],["9.412","104"],["9.368","0"],["9.362","260"],["9.318","0"],["9.312","181"],["9.268","0"],["9.262","236"],["9.218","0"],["9.212","196"],["9.168","0"],["9.162","326"],["9.118","0"],["9.112","70"],["9.068","0"],["9.062","222"],["9.018","0"],["9.012","174"],["8.968","0"],["8.962","321"],["8.918","0"],["8.912","170"],["8.868","0"],["8.862","63"],["8.818","0"],["8.812","102"],["8.768","0"],["8.762","141"],["8.718","0"],["8.712","261"],["8.668","0"],["8.662","42"],["8.618","0"],["8.612","371"],["8.568","0"],["8.562","156"],["8.518","0"],["8.512","111"]],"checksum":1709679445,"ts":"1649290105829"}]}
1649290105.9396322: {"action":"update","arg":{"instType":"mc","channel":"books","instId":"DASHUSDT"},"data":[{"asks":[["113.37","7.20"],["113.38","7.53"],["113.41","9.52"],["113.42","30.51"],["113.43","1.80"],["113.44","7.78"],["113.45","111.88"],["113.46","36.71"],["113.47","15.36"],["113.49","111.00"],["113.50","181.57"],["113.51","30.55"],["113.52","43.41"],["113.53","13.64"],["113.54","39.08"],["113.55","86.48"],["113.56","1374.38"],["113.57","32.35"],["113.59","16.46"],["113.60","95.83"],["113.61","147.38"],["113.62","26.22"],["113.63","315.08"],["113.64","86.69"],["113.65","6.26"],["113.66","201.86"],["113.67","19.68"],["113.68","647.69"],["113.69","42.39"],["113.70","174.26"],["113.72","199.41"],["113.73","30.67"],["113.74","22.64"],["113.75","35.34"],["113.76","249.54"],["113.77","802.67"],["113.79","14.50"],["113.80","2033.05"],["113.81","4.24"],["113.82","44.24"],["113.83","27.93"],["113.84","36.02"],["113.85","473.23"],["113.86","1841.92"],["113.88","0"],["113.89","0"],["113.92","1775.75"],["113.94","0"],["113.98","1908.10"],["114.00","0"],["114.04","2040.45"],["114.06","0"],["114.10","1819.86"],["114.12","0"],["114.16","1930.16"],["114.18","0"],["114.22","1753.69"],["114.24","0"],["114.28","1863.98"],["114.30","0"],["114.34","1797.80"],["114.36","0"],["114.40","1709.57"],["114.42","0"],["114.46","1952.22"],["114.48","0"],["114.52","2018.39"],["114.54","0"],["114.58","1974.27"],["114.60","0"],["114.64","1886.04"],["114.66","0"],["114.70","1731.63"],["114.72","0"]],"bids":[["113.34","0"],["113.33","0"],["113.32","66.34"],["113.31","89.11"],["113.30","288.32"],["113.27","35.65"],["113.26","27.02"],["113.25","58.66"],["113.24","1600.40"],["113.22","22.53"],["113.20","57.98"],["113.16","27.95"],["113.15","377.75"],["113.14","588.21"],["113.13","93.05"],["113.12","178.96"],["113.11","17.99"],["113.10","52.08"],["113.09","11.22"],["113.08","108.31"],["113.07","18.51"],["113.06","27.82"],["113.04","19.57"],["113.02","74.56"],["113.01","74.38"],["113.00","1500.19"],["112.97","119.99"],["112.95","331.62"],["112.91","3.99"],["112.89","1852.10"],["112.88","39.01"],["112.87","444.11"],["112.85","193.66"],["112.83","1870.32"],["112.82","4.50"],["112.81","75.18"],["112.79","0"],["112.77","1709.57"],["112.73","0"],["112.71","1775.75"],["112.67","0"],["112.65","1974.27"],["112.61","0"],["112.59","2018.39"],["112.55","0"],["112.53","1819.86"],["112.49","0"],["112.47","1996.33"],["112.43","0"],["112.41","2040.45"],["112.37","0"],["112.35","1886.04"],["112.31","0"],["112.29","1753.69"],["112.25","0"],["112.23","1908.10"],["112.19","0"],["112.17","1952.22"],["112.13","0"],["112.11","1930.16"],["112.07","0"],["112.05","1731.63"],["112.01","0"],["111.99","1797.80"]],"checksum":1769565577,"ts":"1649290105903"}]}
1649290106.185739: {"action":"update","arg":{"instType":"mc","channel":"books","instId":"UNIUSDT"},"data":[{"asks":[["9.976","0"],["9.977","149"],["9.978","231"],["9.979","533"],["9.980","675"],["9.982","1002"],["9.983","372"],["9.984","544"],["9.985","653"],["9.986","164"],["9.987","840"],["9.988","335"],["9.995","396"],["9.996","693"],["9.997","1561"],["9.998","314"],["10.001","895"],["10.007","335"],["10.008","3702"],["10.010","388"],["10.011","4579"],["10.022","12852"],["10.024","2076"],["10.027","13366"],["10.032","12982"],["10.037","11443"],["10.042","12405"],["10.047","12020"],["10.052","11636"],["10.057","13174"],["10.062","11828"],["10.067","13559"],["10.072","12789"],["10.077","12213"],["10.090","60"],["10.097","0"],["10.142","174"],["10.149","0"],["10.194","366"],["10.201","0"],["10.246","361"],["10.253","0"],["10.298","240"],["10.305","0"],["10.350","123"],["10.357","0"],["10.402","268"],["10.409","0"],["10.454","79"],["10.461","0"],["10.506","164"],["10.513","0"],["10.558","327"],["10.565","0"],["10.610","205"],["10.617","0"],["10.662","204"],["10.669","0"],["10.714","24"],["10.721","0"],["10.766","134"],["10.773","0"],["10.818","170"],["10.825","0"],["10.870","84"],["10.877","0"],["10.922","94"],["10.929","0"],["10.974","41"],["10.981","0"],["11.026","221"],["11.033","0"],["11.078","421"],["11.085","0"],["11.130","28"],["11.137","0"],["11.182","103"],["11.189","0"],["11.234","180"],["11.241","0"],["11.286","312"],["11.293","0"],["11.338","123"],["11.345","0"],["11.390","186"],["11.397","0"],["11.442","335"],["11.449","0"]],"bids":[["9.969","211"],["9.968","37"],["9.967","244"],["9.966","444"],["9.965","136"],["9.964","163"],["9.963","1042"],["9.960","427"],["9.959","943"],["9.958","536"],["9.956","639"],["9.952","1235"],["9.948","550"],["9.945","903"],["9.943","1959"],["9.942","2165"],["9.933","2916"],["9.931","3581"],["9.921","13053"],["9.916","11636"],["9.911","11828"],["9.906","13366"],["9.901","13174"],["9.896","12789"],["9.891","12405"],["9.886","11443"],["9.881","13559"],["9.876","12213"],["9.871","12597"],["9.866","12020"],["9.763","0"],["9.756","109"],["9.712","0"],["9.705","308"],["9.662","0"],["9.655","160"],["9.612","0"],["9.605","151"],["9.562","0"],["9.555","245"],["9.512","0"],["9.505","194"],["9.462","0"],["9.455","352"],["9.412","0"],["9.405","104"],["9.362","0"],["9.355","260"],["9.312","0"],["9.305","181"],["9.262","0"],["9.255","236"],["9.212","0"],["9.205","196"],["9.162","0"],["9.155","326"],["9.112","0"],["9.105","70"],["9.062","0"],["9.055","222"],["9.012","0"],["9.005","174"],["8.962","0"],["8.955","321"],["8.912","0"],["8.905","170"],["8.862","0"],["8.855","63"],["8.812","0"],["8.805","102"],["8.762","0"],["8.755","141"],["8.712","0"],["8.705","261"],["8.662","0"],["8.655","42"],["8.612","0"],["8.605","371"],["8.562","0"],["8.555","156"],["8.512","0"],["8.505","111"]],"checksum":-2112133569,"ts":"1649290106149"}]}
1649290106.199379: {"action":"snapshot","arg":{"instType":"mc","channel":"ticker","instId":"UNIUSDT"},"data":[{"instId":"UNIUSDT","last":"9.9710","bestAsk":"9.974","bestBid":"9.969","high24h":"10.4280","low24h":"9.9030","priceChangePercent":"-0.0399","capitalRate":"-0.000100","nextSettleTime":1649314800000,"systemTime":1649290106170,"markPrice":"9.9742","indexPrice":"9.9818","holding":"369411","baseVolume":"313119","quoteVolume":"3294803"}]}
1649290106.231383: {"action":"snapshot","arg":{"instType":"mc","channel":"ticker","instId":"DASHUSDT"},"data":[{"instId":"DASHUSDT","last":"113.370","bestAsk":"113.36","bestBid":"113.31","high24h":"118.870","low24h":"113.140","priceChangePercent":"-0.036","capitalRate":"-0.000100","nextSettleTime":1649314800000,"systemTime":1649290106201,"markPrice":"113.386","indexPrice":"113.402","holding":"21957.17","baseVolume":"25308.09","quoteVolume":"3063086.16"}]}
1649290106.2439969: {"action":"update","arg":{"instType":"mc","channel":"books","instId":"DASHUSDT"},"data":[{"asks":[["113.36","4.81"],["113.37","6.06"],["113.38","9.94"],["113.39","7.72"],["113.40","15.36"],["113.42","25.78"],["113.45","115.82"],["113.48","2.26"],["113.49","119.17"],["113.50","137.48"],["113.57","41.39"],["113.62","31.46"],["113.71","36.60"],["113.79","1746.12"],["113.80","36.73"],["113.85","2027.94"],["113.86","0"],["113.87","0"],["113.91","1797.80"],["113.92","0"],["113.97","2040.45"],["113.98","0"],["114.03","1996.33"],["114.04","0"],["114.09","1709.57"],["114.10","0"],["114.15","1930.16"],["114.16","0"],["114.21","1863.98"],["114.22","0"],["114.27","1908.10"],["114.28","0"],["114.33","1819.86"],["114.34","0"],["114.39","1952.22"],["114.40","0"],["114.45","1841.92"],["114.46","0"],["114.51","1886.04"],["114.52","0"],["114.57","2018.39"],["114.58","0"],["114.63","1753.69"],["114.64","0"],["114.69","1974.27"],["114.70","0"]],"bids":[["113.32","0"],["113.23","38.34"],["113.20","63.19"],["113.19","42.89"],["113.15","422.90"],["113.09","16.41"],["113.00","1500.48"],["112.98","514.22"],["112.96","215.73"],["112.89","10.19"],["112.88","1991.89"],["112.83","6.35"],["112.82","1736.12"],["112.77","0"],["112.76","2040.45"],["112.71","0"],["112.70","1709.57"],["112.65","0"],["112.64","1886.04"],["112.59","0"],["112.58","1797.80"],["112.53","0"],["112.52","1908.10"],["112.47","0"],["112.46","1775.75"],["112.41","0"],["112.40","1974.27"],["112.35","0"],["112.34","1753.69"],["112.29","0"],["112.28","1996.33"],["112.23","0"],["112.22","1863.98"],["112.17","0"],["112.16","2018.39"],["112.11","0"],["112.10","1930.16"],["112.05","0"],["112.04","1819.86"],["111.99","0"],["111.98","1841.92"]],"checksum":-2087199864,"ts":"1649290106216"}]}
1649290106.478196: {"action":"update","arg":{"instType":"mc","channel":"books","instId":"UNIUSDT"},"data":[{"asks":[["9.973","117"],["9.974","0"],["9.975","63"],["9.976","577"],["9.977","309"],["9.978","766"],["9.979","771"],["9.980","421"],["9.981","417"],["9.982","1511"],["9.983","435"],["9.984","506"],["9.985","672"],["9.986","208"],["9.987","915"],["9.988","353"],["9.989","1373"],["9.991","664"],["9.992","653"],["9.995","509"],["9.996","668"],["9.997","769"],["9.999","430"],["10.002","846"],["10.003","1055"],["10.004","482"],["10.006","702"],["10.007","330"],["10.008","358"],["10.009","194"],["10.011","4621"],["10.017","8364"],["10.019","543"],["10.021","13493"],["10.022","256"],["10.024","0"],["10.026","12597"],["10.027","0"],["10.031","13559"],["10.032","0"],["10.036","11443"],["10.037","0"],["10.041","11636"],["10.042","0"],["10.046","11828"],["10.047","0"],["10.051","12982"],["10.052","0"],["10.056","12405"],["10.057","0"],["10.061","12020"],["10.062","113"],["10.066","12213"],["10.067","0"],["10.071","13174"],["10.072","0"],["10.076","12789"],["10.077","0"],["10.084","60"],["10.090","0"],["10.136","174"],["10.142","0"],["10.188","366"],["10.194","0"],["10.240","361"],["10.246","0"],["10.292","240"],["10.298","0"],["10.344","123"],["10.350","0"],["10.396","268"],["10.402","0"],["10.448","79"],["10.454","0"],["10.500","164"],["10.506","0"],["10.552","327"],["10.558","0"],["10.604","205"],["10.610","0"],["10.656","204"],["10.662","0"],["10.708","24"],["10.714","0"],["10.760","134"],["10.766","0"],["10.812","170"],["10.818","0"],["10.864","84"],["10.870","0"],["10.916","94"],["10.922","0"],["10.968","41"],["10.974","0"],["11.020","221"],["11.026","0"],["11.072","421"],["11.078","0"],["11.124","28"],["11.130","0"],["11.176","103"],["11.182","0"],["11.228","180"],["11.234","0"],["11.280","312"],["11.286","0"],["11.332","123"],["11.338","0"],["11.384","186"],["11.390","0"],["11.436","335"],["11.442","0"]],"bids":[["9.969","0"],["9.968","77"],["9.967","263"],["9.966","516"],["9.964","166"],["9.963","974"],["9.962","1324"],["9.961","192"],["9.960","680"],["9.959","585"],["9.958","261"],["9.957","2441"],["9.956","794"],["9.955","847"],["9.954","612"],["9.951","1092"],["9.950","632"],["9.949","833"],["9.948","372"],["9.947","342"],["9.946","396"],["9.943","1067"],["9.942","1979"],["9.940","515"],["9.938","2654"],["9.937","262"],["9.936","772"],["9.933","2828"],["9.932","1194"],["9.930","2599"],["9.921","72"],["9.920","12117"],["9.919","392"],["9.916","0"],["9.915","12405"],["9.911","0"],["9.910","13559"],["9.906","0"],["9.905","13174"],["9.901","0"],["9.900","11828"],["9.896","0"],["9.895","12020"],["9.891","0"],["9.890","13366"],["9.886","0"],["9.885","12213"],["9.881","0"],["9.880","12982"],["9.876","0"],["9.875","11636"],["9.871","0"],["9.870","12597"],["9.866","0"],["9.865","12789"],["9.756","0"],["9.750","109"],["9.705","0"],["9.699","308"],["9.655","0"],["9.649","160"],["9.605","0"],["9.599","151"],["9.555","0"],["9.549","245"],["9.505","0"],["9.499","194"],["9.455","0"],["9.449","352"],["9.405","0"],["9.399","104"],["9.355","0"],["9.349","260"],["9.305","0"],["9.299","181"],["9.255","0"],["9.249","236"],["9.205","0"],["9.199","196"],["9.155","0"],["9.149","326"],["9.105","0"],["9.099","70"],["9.055","0"],["9.049","222"],["9.005","0"],["8.999","174"],["8.955","0"],["8.949","321"],["8.905","0"],["8.899","170"],["8.855","0"],["8.849","63"],["8.805","0"],["8.799","102"],["8.755","0"],["8.749","141"],["8.705","0"],["8.699","261"],["8.655","0"],["8.649","42"],["8.605","0"],["8.599","371"],["8.555","0"],["8.549","156"],["8.505","0"],["8.499","111"]],"checksum":-51428852,"ts":"1649290106451"}]}
1649290106.566829: {"action":"update","arg":{"instType":"mc","channel":"books","instId":"DASHUSDT"},"data":[{"asks":[["113.37","5.03"],["113.38","5.94"],["113.42","28.82"],["113.45","125.72"],["113.46","44.70"],["113.47","22.79"],["113.48","63.58"],["113.49","88.48"],["113.50","189.46"],["113.52","14.04"],["113.53","11.66"],["113.57","43.26"],["113.59","14.98"],["113.60","69.46"],["113.61","3.77"],["113.62","20.12"],["113.64","92.30"],["113.65","224.21"],["113.66","240.14"],["113.67","85.27"],["113.68","645.71"],["113.69","30.51"],["113.70","163.86"],["113.72","195.74"],["113.74","0.88"],["113.75","40.06"],["113.77","799.70"],["113.78","70.56"],["113.79","1944.44"],["113.80","24.85"],["113.83","1600.33"],["113.84","29.59"],["113.85","2049.99"],["113.91","1952.22"],["113.97","1974.27"],["114.03","1775.75"],["114.09","1819.86"],["114.15","1886.04"],["114.21","2018.39"],["114.27","1863.98"],["114.33","1731.63"],["114.39","1841.92"],["114.45","1709.57"],["114.51","1753.69"],["114.57","2040.45"],["114.63","1996.33"],["114.69","1908.10"],["115.78","0"],["116.00","31.47"],["116.37","0"],["116.59","50.46"],["116.96","0"],["117.18","49.40"],["117.55","0"],["117.77","27.41"],["118.14","0"],["118.36","50.42"],["118.73","0"],["118.95","50.07"],["119.32","0"],["119.54","36.12"],["119.91","0"],["120.13","8.62"],["120.50","0"],["120.72","54.60"],["121.09","0"],["121.31","1.48"],["121.68","0"],["121.90","43.49"],["122.27","0"],["122.49","7.73"],["122.86","0"],["123.08","58.21"],["123.45","0"],["123.67","52.67"],["124.04","0"],["124.26","53.84"],["124.63","0"],["124.85","4.99"],["125.22","0"],["125.44","44.04"],["125.81","0"],["126.03","25.10"],["126.40","0"],["126.62","39.09"],["126.99","0"],["127.21","44.51"],["127.58","0"],["127.80","19.01"],["128.17","0"],["128.39","29.39"],["128.76","0"],["128.98","3.89"],["129.35","0"],["129.57","23.37"],["129.94","0"],["130.16","24.18"],["130.53","0"],["130.75","9.15"],["131.12","0"],["131.34","27.04"],["131.71","0"],["131.93","7.10"],["132.52","13.38"],["133.11","33.57"],["133.70","76.51"]],"bids":[["113.31","94.06"],["113.23","146.99"],["113.20","24.08"],["113.19","60.55"],["113.16","46.32"],["113.15","569.97"],["113.14","746.12"],["113.12","34.15"],["113.10","51.61"],["113.09","12.18"],["113.07","20.89"],["113.04","25.34"],["113.03","32.88"],["113.01","78.83"],["113.00","18.32"],["112.98","527.76"],["112.94","1600.41"],["112.91","1.00"],["112.88","1900.97"],["112.86","4.25"],["112.84","40.16"],["112.82","1912.59"],["112.76","1731.63"],["112.70","1974.27"],["112.64","1819.86"],["112.58","1930.16"],["112.52","1952.22"],["112.46","2040.45"],["112.40","1886.04"],["112.34","1775.75"],["112.28","1797.80"],["112.22","1709.57"],["112.10","1996.33"],["112.04","1753.69"],["111.66","0"],["111.61","44.63"],["111.07","0"],["111.02","97.81"],["110.47","0"],["110.43","40.49"],["109.88","0"],["109.84","85.27"],["109.29","0"],["109.25","84.73"],["108.70","0"],["108.66","59.74"],["108.11","0"],["108.07","61.13"],["107.52","0"],["107.48","33.01"],["106.93","0"],["106.89","56.85"],["106.34","0"],["106.30","24.34"],["105.75","0"],["105.71","1.74"],["105.16","0"],["105.12","57.94"],["104.57","0"],["104.53","58.21"],["103.98","0"],["103.94","46.12"],["103.39","0"],["103.35","52.32"],["102.80","0"],["102.76","45.29"],["102.21","0"],["102.17","22.94"],["101.62","0"],["101.58","36.02"],["101.03","0"],["100.99","38.02"],["100.44","0"],["100.40","53.60"],["99.85","0"],["99.26","0"],["98.67","0"],["98.08","0"],["97.49","0"],["96.90","0"],["96.31","0"],["95.72","0"],["95.13","0"],["94.54","0"],["93.95","0"],["93.36","0"],["92.77","0"],["92.18","0"]],"checksum":-189437958,"ts":"1649290106534"}]}
1649290106.572892: {"action":"snapshot","arg":{"instType":"mc","channel":"ticker","instId":"UNIUSDT"},"data":[{"instId":"UNIUSDT","last":"9.9710","bestAsk":"9.973","bestBid":"9.968","high24h":"10.4280","low24h":"9.9030","priceChangePercent":"-0.0399","capitalRate":"-0.000100","nextSettleTime":1649314800000,"systemTime":1649290106541,"markPrice":"9.9741","indexPrice":"9.9818","holding":"369411","baseVolume":"313119","quoteVolume":"3294803"}]}
1649290106.58181: {"action":"snapshot","arg":{"instType":"mc","channel":"ticker","instId":"DASHUSDT"},"data":[{"instId":"DASHUSDT","last":"113.370","bestAsk":"113.36","bestBid":"113.31","high24h":"118.870","low24h":"113.140","priceChangePercent":"-0.036","capitalRate":"-0.000100","nextSettleTime":1649314800000,"systemTime":1649290106546,"markPrice":"113.386","indexPrice":"113.402","holding":"21957.17","baseVolume":"25308.09","quoteVolume":"3063086.16"}]}
1649290106.7755709: {"action":"update","arg":{"instType":"mc","channel":"books","instId":"UNIUSDT"},"data":[{"asks":[["9.973","356"],["9.974","137"],["9.975","275"],["9.976","531"],["9.977","1708"],["9.978","565"],["9.979","402"],["9.980","524"],["9.981","273"],["9.982","1461"],["9.983","410"],["9.984","463"],["9.985","693"],["9.986","659"],["9.987","863"],["9.988","511"],["9.989","757"],["9.990","1228"],["9.991","689"],["9.992","596"],["9.993","2529"],["9.994","2184"],["9.995","1236"],["9.996","736"],["9.998","330"],["10.002","1087"],["10.003","1035"],["10.004","311"],["10.005","651"],["10.006","647"],["10.007","399"],["10.010","376"],["10.011","4634"],["10.017","8391"],["10.021","12340"],["10.022","306"],["10.023","0"],["10.026","13366"],["10.031","12020"],["10.036","13174"],["10.041","12405"],["10.046","11636"],["10.051","13559"],["10.056","12597"],["10.061","12789"],["10.066","11828"],["10.071","11443"],["10.076","12982"],["10.078","60"],["10.084","0"],["10.130","174"],["10.136","0"],["10.182","366"],["10.188","0"],["10.234","361"],["10.240","0"],["10.286","240"],["10.292","0"],["10.338","123"],["10.344","0"],["10.390","268"],["10.396","0"],["10.442","79"],["10.448","0"],["10.494","164"],["10.500","0"],["10.546","327"],["10.552","0"],["10.598","205"],["10.604","0"],["10.650","204"],["10.656","0"],["10.702","24"],["10.708","0"],["10.754","134"],["10.760","0"],["10.806","170"],["10.812","0"],["10.858","84"],["10.864","0"],["10.910","94"],["10.916","0"],["10.962","41"],["10.968","0"],["11.014","221"],["11.020","0"],["11.066","421"],["11.072","0"],["11.118","28"],["11.124","0"],["11.170","103"],["11.176","0"],["11.222","180"],["11.228","0"],["11.274","312"],["11.280","0"],["11.326","123"],["11.332","0"],["11.378","186"],["11.384","0"],["11.430","335"],["11.436","0"]],"bids":[["9.967","216"],["9.966","266"],["9.965","177"],["9.964","56"],["9.963","193"],["9.962","1480"],["9.961","184"],["9.960","185"],["9.959","512"],["9.958","244"],["9.957","2373"],["9.956","673"],["9.955","745"],["9.954","499"],["9.953","826"],["9.952","983"],["9.951","789"],["9.950","725"],["9.948","268"],["9.947","347"],["9.946","404"],["9.945","1071"],["9.944","3321"],["9.942","1774"],["9.939","2275"],["9.938","2941"],["9.937","239"],["9.936","835"],["9.934","620"],["9.932","1210"],["9.931","3604"],["9.930","2749"],["9.929","561"],["9.926","1173"],["9.922","7686"],["9.920","13656"],["9.915","12597"],["9.910","12789"],["9.905","12020"],["9.900","12405"],["9.895","13559"],["9.885","11443"],["9.880","11636"],["9.875","11828"],["9.870","13174"],["9.865","12213"],["9.750","0"],["9.744","109"],["9.699","0"],["9.693","308"],["9.649","0"],["9.643","160"],["9.599","0"],["9.593","151"],["9.549","0"],["9.543","245"],["9.499","0"],["9.493","194"],["9.449","0"],["9.443","352"],["9.399","0"],["9.393","104"],["9.349","0"],["9.343","260"],["9.299","0"],["9.293","181"],["9.249","0"],["9.243","236"],["9.199","0"],["9.193","196"],["9.149","16"],["9.143","326"],["9.099","0"],["9.093","70"],["9.049","0"],["9.043","222"],["8.999","0"],["8.993","174"],["8.949","0"],["8.943","321"],["8.899","0"],["8.893","170"],["8.849","0"],["8.843","63"],["8.799","0"],["8.793","102"],["8.749","0"],["8.743","141"],["8.699","0"],["8.693","261"],["8.649","0"],["8.643","42"],["8.599","0"],["8.593","371"],["8.549","0"],["8.543","156"],["8.499","0"],["8.493","111"]],"checksum":252412330,"ts":"1649290106747"}]}
1649290106.826633: {"action":"snapshot","arg":{"instType":"mc","channel":"ticker","instId":"UNIUSDT"},"data":[{"instId":"UNIUSDT","last":"9.9710","bestAsk":"9.973","bestBid":"9.968","high24h":"10.4280","low24h":"9.9030","priceChangePercent":"-0.0399","capitalRate":"-0.000100","nextSettleTime":1649314800000,"systemTime":1649290106797,"markPrice":"9.9741","indexPrice":"9.9798","holding":"369411","baseVolume":"313119","quoteVolume":"3294803"}]}
1649290106.837368: {"action":"snapshot","arg":{"instType":"mc","channel":"ticker","instId":"DASHUSDT"},"data":[{"instId":"DASHUSDT","last":"113.370","bestAsk":"113.36","bestBid":"113.31","high24h":"118.870","low24h":"113.140","priceChangePercent":"-0.036","capitalRate":"-0.000100","nextSettleTime":1649314800000,"systemTime":1649290106807,"markPrice":"113.386","indexPrice":"113.402","holding":"21957.17","baseVolume":"25308.09","quoteVolume":"3063086.16"}]}
1649290106.874711: {"action":"update","arg":{"instType":"mc","channel":"books","instId":"DASHUSDT"},"data":[{"asks":[["113.36","8.96"],["113.37","9.30"],["113.42","24.86"],["113.44","10.60"],["113.45","145.90"],["113.46","4.33"],["113.47","30.02"],["113.48","33.27"],["113.49","79.58"],["113.50","137.48"],["113.51","62.89"],["113.52","33.97"],["113.56","1390.13"],["113.61","3.50"],["113.64","92.10"],["113.66","130.58"],["113.69","31.16"],["113.78","234.41"],["113.79","1834.62"],["113.81","5.70"],["113.82","49.19"],["113.83","1600.41"],["113.85","2094.11"],["113.91","1974.27"],["113.97","1996.33"],["114.03","1908.10"],["114.09","2040.45"],["114.15","1731.63"],["114.21","1775.75"],["114.27","1886.04"],["114.33","1753.69"],["114.39","1797.80"],["114.45","2018.39"],["114.51","1952.22"],["114.57","1709.57"],["114.63","1863.98"],["114.69","1930.16"],["115.78","0.73"],["116.00","0"],["116.37","68.26"],["116.59","0"],["116.96","70.90"],["117.18","0"],["117.55","49.89"],["117.77","0"],["118.14","22.59"],["118.36","0"],["118.73","47.85"],["118.95","0"],["119.32","46.71"],["119.54","0"],["119.91","23.57"],["120.13","0"],["120.50","59.15"],["120.72","0"],["121.09","6.51"],["121.31","0"],["121.68","54.25"],["121.90","0"],["122.27","14.99"],["122.49","0"],["122.86","11.21"],["123.08","0"],["123.45","66.50"],["123.67","0"],["124.04","64.47"],["124.26","0"],["124.63","42.85"],["124.85","0"],["125.22","29.99"],["125.44","0"],["125.81","4.07"],["126.03","0"],["126.40","26.70"],["126.62","0"],["126.99","20.67"],["127.21","0"],["127.58","56.99"],["127.80","0"],["128.17","44.01"],["128.39","0"],["128.76","46.60"],["128.98","0"],["129.35","39.07"],["129.57","0"],["129.94","19.33"],["130.16","0"],["130.53","20.66"],["130.75","0"],["131.12","28.11"],["131.34","0"],["131.71","13.65"],["131.93","0"],["132.52","0"],["133.11","0"],["133.70","0"]],"bids":[["113.31","89.11"],["113.23","147.07"],["113.20","26.69"],["113.18","17.43"],["113.16","27.51"],["113.14","588.21"],["113.13","94.90"],["113.12","192.06"],["112.89","8.00"],["112.88","1834.79"],["112.84","30.26"],["112.82","1890.53"],["112.76","1841.92"],["112.70","1908.10"],["112.64","2040.45"],["112.52","1753.69"],["112.46","1952.22"],["112.40","1709.57"],["112.34","2018.39"],["112.28","1863.98"],["112.22","1996.33"],["112.16","1731.63"],["112.10","1974.27"],["112.04","1819.86"],["111.98","1775.75"],["111.66","54.98"],["111.61","0"],["111.07","56.15"],["111.02","0"],["110.47","22.20"],["110.43","0"],["109.88","45.95"],["109.84","0"],["109.29","29.62"],["109.25","0"],["108.70","21.93"],["108.66","0"],["108.11","6.02"],["108.07","0"],["107.52","55.97"],["107.48","0"],["106.93","21.31"],["106.89","0"],["106.34","8.95"],["106.30","0"],["105.75","10.15"],["105.71","0"],["105.16","40.07"],["105.12","0"],["104.57","15.36"],["104.53","0"],["103.98","46.47"],["103.94","0"],["103.39","11.11"],["103.35","0"],["102.80","1.87"],["102.76","0"],["102.21","37.67"],["102.17","0"],["101.62","21.48"],["101.58","0"],["101.03","49.80"],["100.99","0"],["100.44","49.32"],["100.40","0"],["99.85","42.14"],["99.26","8.55"],["98.67","30.36"],["98.08","20.32"],["97.49","36.65"],["96.90","21.95"],["96.31","8.41"],["95.72","31.49"],["95.13","57.35"],["94.54","3.45"],["93.95","4.85"],["93.36","74.35"],["92.77","33.85"],["92.18","20.24"]],"checksum":140846786,"ts":"1649290106839"}]}
1649290107.0891452: {"action":"update","arg":{"instType":"mc","channel":"books","instId":"UNIUSDT"},"data":[{"asks":[["9.972","178"],["9.973","192"],["9.974","212"],["9.975","189"],["9.976","335"],["9.977","1604"],["9.978","186"],["9.980","633"],["9.981","291"],["9.982","1629"],["9.983","703"],["9.984","772"],["9.985","758"],["9.986","1464"],["9.987","1147"],["9.988","415"],["9.989","829"],["9.990","1075"],["9.991","740"],["9.992","471"],["9.993","1480"],["9.994","2976"],["9.995","569"],["9.998","253"],["9.999","391"],["10.000","432"],["10.002","1109"],["10.003","910"],["10.004","380"],["10.008","232"],["10.013","3161"],["10.020","17503"],["10.021","128"],["10.022","0"],["10.025","11443"],["10.026","0"],["10.030","13174"],["10.031","0"],["10.035","12213"],["10.036","0"],["10.040","12020"],["10.041","0"],["10.045","12405"],["10.046","0"],["10.050","12789"],["10.051","0"],["10.055","11636"],["10.056","0"],["10.060","13559"],["10.061","0"],["10.065","12597"],["10.066","0"],["10.070","13366"],["10.071","0"],["10.075","11828"],["10.076","0"],["10.078","0"],["10.123","11"],["10.130","0"],["10.174","200"],["10.182","0"],["10.225","230"],["10.234","0"],["10.276","253"],["10.286","0"],["10.327","73"],["10.338","0"],["10.379","235"],["10.390","0"],["10.430","23"],["10.442","0"],["10.481","370"],["10.494","0"],["10.532","107"],["10.546","0"],["10.583","81"],["10.598","0"],["10.634","42"],["10.650","0"],["10.685","310"],["10.702","0"],["10.736","283"],["10.754","0"],["10.787","212"],["10.806","0"],["10.838","262"],["10.858","0"],["10.889","104"],["10.910","0"],["10.940","278"],["10.962","0"],["10.991","21"],["11.014","0"],["11.042","194"],["11.066","0"],["11.093","194"],["11.118","0"],["11.144","354"],["11.170","0"],["11.195","147"],["11.222","0"],["11.246","370"],["11.274","0"],["11.297","301"],["11.326","0"],["11.348","168"],["11.378","0"],["11.399","139"],["11.430","0"],["11.450","65"]],"bids":[["9.968","0"],["9.967","250"],["9.966","344"],["9.965","121"],["9.964","44"],["9.963","502"],["9.962","1313"],["9.961","279"],["9.960","114"],["9.959","322"],["9.958","185"],["9.957","2233"],["9.956","620"],["9.955","1075"],["9.954","548"],["9.953","742"],["9.952","287"],["9.951","1517"],["9.950","567"],["9.949","814"],["9.948","369"],["9.947","329"],["9.946","452"],["9.945","903"],["9.944","3395"],["9.943","1227"],["9.942","2265"],["9.941","1418"],["9.940","640"],["9.939","2178"],["9.938","2963"],["9.937","195"],["9.936","666"],["9.933","3041"],["9.932","997"],["9.929","399"],["9.927","435"],["9.923","357"],["9.920","675"],["9.919","13565"],["9.918","265"],["9.915","0"],["9.914","11443"],["9.910","0"],["9.909","13366"],["9.905","0"],["9.904","12213"],["9.900","0"],["9.899","13559"],["9.895","0"],["9.894","12597"],["9.890","0"],["9.889","12405"],["9.885","0"],["9.884","12020"],["9.880","0"],["9.879","12789"],["9.875","0"],["9.874","11828"],["9.870","0"],["9.869","12982"],["9.865","0"],["9.864","11636"],["9.744","0"],["9.738","109"],["9.693","0"],["9.687","308"],["9.643","0"],["9.637","160"],["9.593","0"],["9.587","151"],["9.543","0"],["9.537","245"],["9.493","0"],["9.487","194"],["9.443","0"],["9.437","352"],["9.393","0"],["9.387","104"],["9.343","0"],["9.337","260"],["9.293","0"],["9.287","181"],["9.243","0"],["9.237","236"],["9.193","0"],["9.187","196"],["9.143","0"],["9.137","326"],["9.093","0"],["9.087","70"],["9.043","0"],["9.037","222"],["8.993","0"],["8.987","174"],["8.943","0"],["8.937","321"],["8.893","0"],["8.887","170"],["8.843","0"],["8.837","63"],["8.793","0"],["8.787","102"],["8.743","0"],["8.737","141"],["8.693","0"],["8.687","261"],["8.643","0"],["8.637","42"],["8.593","0"],["8.587","371"],["8.543","0"],["8.537","156"],["8.493","0"],["8.487","111"]],"checksum":1870994557,"ts":"1649290107055"}]}
1649290107.1085062: {"action":"snapshot","arg":{"instType":"mc","channel":"ticker","instId":"UNIUSDT"},"data":[{"instId":"UNIUSDT","last":"9.9710","bestAsk":"9.972","bestBid":"9.967","high24h":"10.4280","low24h":"9.9030","priceChangePercent":"-0.0399","capitalRate":"-0.000100","nextSettleTime":1649314800000,"systemTime":1649290107080,"markPrice":"9.9741","indexPrice":"9.9798","holding":"369411","baseVolume":"313119","quoteVolume":"3294803"}]}
1649290107.116079: {"action":"snapshot","arg":{"instType":"mc","channel":"ticker","instId":"DASHUSDT"},"data":[{"instId":"DASHUSDT","last":"113.370","bestAsk":"113.36","bestBid":"113.31","high24h":"118.870","low24h":"113.140","priceChangePercent":"-0.036","capitalRate":"-0.000100","nextSettleTime":1649314800000,"systemTime":1649290107085,"markPrice":"113.386","indexPrice":"113.402","holding":"21957.17","baseVolume":"25308.09","quoteVolume":"3063086.16"}]}
1649290107.125953: {"action":"update","arg":{"instType":"mc","channel":"trade","instId":"UNIUSDT"},"data":[["1649290107025","9.969","3","sell"]]}
1649290107.1713989: {"action":"update","arg":{"instType":"mc","channel":"books","instId":"DASHUSDT"},"data":[{"asks":[["113.35","1.10"],["113.36","8.92"],["113.37","12.02"],["113.38","11.10"],["113.39","11.01"],["113.40","6.63"],["113.41","7.55"],["113.44","5.17"],["113.45","138.48"],["113.46","16.52"],["113.47","33.59"],["113.48","4.42"],["113.49","113.86"],["113.50","135.80"],["113.51","30.55"],["113.52","44.69"],["113.53","13.64"],["113.54","40.82"],["113.55","125.68"],["113.56","1374.58"],["113.59","16.46"],["113.61","147.38"],["113.64","86.49"],["113.65","6.26"],["113.66","201.86"],["113.67","19.68"],["113.68","658.58"],["113.69","43.04"],["113.70","174.26"],["113.75","35.34"],["113.78","2208.67"],["113.79","14.77"],["113.80","36.73"],["113.83","27.93"],["113.84","2038.90"],["113.85","0"],["113.90","1908.10"],["113.91","0"],["113.96","1775.75"],["113.97","0"],["114.02","1886.04"],["114.03","0"],["114.08","1841.92"],["114.09","0"],["114.14","1731.63"],["114.15","0"],["114.20","1753.69"],["114.21","0"],["114.26","1863.98"],["114.27","0"],["114.32","1930.16"],["114.33","0"],["114.38","1819.86"],["114.39","0"],["114.44","1952.22"],["114.45","0"],["114.50","1709.57"],["114.51","0"],["114.56","2040.45"],["114.57","0"],["114.62","2018.39"],["114.63","0"],["114.68","1797.80"],["114.69","0"]],"bids":[["113.31","0"],["113.28","97.63"],["113.25","102.97"],["113.23","38.84"],["113.22","23.81"],["113.21","5.39"],["113.20","189.38"],["113.19","5.57"],["113.18","18.61"],["113.17","16.84"],["113.16","30.70"],["113.15","442.04"],["113.13","93.05"],["113.08","134.71"],["113.06","33.47"],["113.05","1476.11"],["113.04","27.42"],["113.03","33.69"],["113.02","104.29"],["113.01","29.83"],["113.00","1600.47"],["112.99","18.24"],["112.98","511.33"],["112.94","0.89"],["112.92","56.86"],["112.88","40.49"],["112.87","2286.02"],["112.85","189.28"],["112.83","9.30"],["112.82","4.50"],["112.81","2100.72"],["112.80","4.91"],["112.76","0"],["112.75","1930.16"],["112.70","0"],["112.69","1886.04"],["112.64","0"],["112.63","1819.86"],["112.58","0"],["112.57","1996.33"],["112.52","0"],["112.51","1731.63"],["112.46","0"],["112.45","1797.80"],["112.40","0"],["112.39","1863.98"],["112.34","0"],["112.33","1908.10"],["112.28","0"],["112.27","1775.75"],["112.22","0"],["112.21","1753.69"],["112.16","0"],["112.15","1974.27"],["112.10","0"],["112.09","1952.22"],["112.04","0"],["112.03","1709.57"],["111.98","0"],["111.97","2040.45"]],"checksum":-894234061,"ts":"1649290107139"}]}
1649290107.371542: {"action":"snapshot","arg":{"instType":"mc","channel":"ticker","instId":"DASHUSDT"},"data":[{"instId":"DASHUSDT","last":"113.370","bestAsk":"113.34","bestBid":"113.28","high24h":"118.870","low24h":"113.140","priceChangePercent":"-0.036","capitalRate":"-0.000100","nextSettleTime":1649314800000,"systemTime":1649290107341,"markPrice":"113.386","indexPrice":"113.402","holding":"21957.17","baseVolume":"25308.09","quoteVolume":"3063086.16"}]}
1649290107.371636: {"action":"snapshot","arg":{"instType":"mc","channel":"ticker","instId":"UNIUSDT"},"data":[{"instId":"UNIUSDT","last":"9.9710","bestAsk":"9.971","bestBid":"9.966","high24h":"10.4280","low24h":"9.9030","priceChangePercent":"-0.0399","capitalRate":"-0.000100","nextSettleTime":1649314800000,"systemTime":1649290107338,"markPrice":"9.9737","indexPrice":"9.9798","holding":"369411","baseVolume":"313119","quoteVolume":"3294803"}]}
1649290107.427264: {"action":"update","arg":{"instType":"mc","channel":"books","instId":"UNIUSDT"},"data":[{"asks":[["9.971","225"],["9.972","359"],["9.973","369"],["9.974","225"],["9.975","378"],["9.976","261"],["9.977","1652"],["9.978","105"],["9.979","328"],["9.980","597"],["9.981","439"],["9.982","1596"],["9.983","699"],["9.984","946"],["9.985","469"],["9.986","274"],["9.987","734"],["9.989","764"],["9.990","1874"],["9.991","756"],["9.992","632"],["9.994","2948"],["9.995","1049"],["9.996","764"],["9.997","627"],["9.998","250"],["9.999","463"],["10.000","2342"],["10.002","437"],["10.003","907"],["10.005","601"],["10.008","1419"],["10.012","624"],["10.013","2370"],["10.017","8094"],["10.019","11866"],["10.020","4522"],["10.021","0"],["10.024","12789"],["10.025","0"],["10.029","13366"],["10.030","0"],["10.034","11443"],["10.035","0"],["10.039","13559"],["10.040","0"],["10.044","13174"],["10.045","0"],["10.049","12405"],["10.050","0"],["10.054","12597"],["10.055","0"],["10.059","11636"],["10.060","0"],["10.064","12020"],["10.065","0"],["10.069","12982"],["10.070","0"],["10.074","12213"],["10.075","0"],["10.116","11"],["10.123","0"],["10.167","200"],["10.174","0"],["10.218","230"],["10.225","0"],["10.269","253"],["10.276","0"],["10.320","73"],["10.327","0"],["10.372","235"],["10.379","0"],["10.423","23"],["10.430","0"],["10.474","370"],["10.481","0"],["10.525","107"],["10.532","0"],["10.576","81"],["10.583","0"],["10.627","42"],["10.634","0"],["10.678","310"],["10.685","0"],["10.729","283"],["10.736","0"],["10.780","212"],["10.787","0"],["10.831","262"],["10.838","0"],["10.882","104"],["10.889","0"],["10.933","278"],["10.940","0"],["10.984","21"],["10.991","0"],["11.035","194"],["11.042","0"],["11.086","194"],["11.093","0"],["11.137","354"],["11.144","0"],["11.188","147"],["11.195","0"],["11.239","370"],["11.246","0"],["11.290","301"],["11.297","0"],["11.341","168"],["11.348","0"],["11.392","139"],["11.399","0"],["11.443","65"],["11.450","0"]],"bids":[["9.967","0"],["9.965","188"],["9.963","457"],["9.962","961"],["9.961","257"],["9.960","54"],["9.959","337"],["9.958","828"],["9.957","2292"],["9.956","610"],["9.955","1015"],["9.954","625"],["9.953","838"],["9.952","514"],["9.950","777"],["9.949","794"],["9.948","240"],["9.946","496"],["9.945","813"],["9.944","3365"],["9.943","1228"],["9.942","1639"],["9.941","1368"],["9.940","1423"],["9.939","2125"],["9.938","4467"],["9.936","635"],["9.934","847"],["9.933","3223"],["9.932","1061"],["9.931","131"],["9.929","367"],["9.928","3561"],["9.925","8328"],["9.924","688"],["9.920","972"],["9.919","192"],["9.918","12092"],["9.917","8686"],["9.914","0"],["9.913","11443"],["9.909","0"],["9.908","12405"],["9.904","0"],["9.903","12213"],["9.899","0"],["9.898","12597"],["9.894","0"],["9.893","12982"],["9.889","0"],["9.888","12020"],["9.884","0"],["9.883","13366"],["9.879","0"],["9.878","12789"],["9.874","0"],["9.873","11636"],["9.869","0"],["9.868","13559"],["9.864","0"],["9.863","13174"],["9.738","0"],["9.731","109"],["9.687","0"],["9.680","308"],["9.637","0"],["9.630","160"],["9.587","0"],["9.580","151"],["9.537","0"],["9.530","245"],["9.487","0"],["9.480","194"],["9.437","0"],["9.430","352"],["9.387","0"],["9.380","104"],["9.337","0"],["9.330","260"],["9.287","0"],["9.280","181"],["9.237","0"],["9.230","236"],["9.187","0"],["9.180","196"],["9.137","0"],["9.130","326"],["9.087","0"],["9.080","70"],["9.037","0"],["9.030","222"],["8.987","0"],["8.980","174"],["8.937","0"],["8.930","321"],["8.887","0"],["8.880","170"],["8.837","0"],["8.830","63"],["8.787","0"],["8.780","102"],["8.737","0"],["8.730","141"],["8.687","0"],["8.680","261"],["8.637","0"],["8.630","42"],["8.587","0"],["8.580","371"],["8.537","0"],["8.530","156"],["8.487","0"],["8.480","111"]],"checksum":1677844646,"ts":"1649290107394"}]}
1649290107.473858: {"action":"update","arg":{"instType":"mc","channel":"books","instId":"DASHUSDT"},"data":[{"asks":[["113.33","9.06"],["113.34","5.45"],["113.35","14.85"],["113.37","8.29"],["113.38","5.17"],["113.39","2.28"],["113.40","15.25"],["113.43","3.38"],["113.44","18.20"],["113.45","79.56"],["113.46","20.59"],["113.47","55.62"],["113.48","32.32"],["113.49","82.75"],["113.50","211.77"],["113.51","39.29"],["113.52","24.92"],["113.53","0.70"],["113.54","29.16"],["113.55","113.35"],["113.57","37.60"],["113.58","4.01"],["113.59","14.98"],["113.60","47.65"],["113.61","2.37"],["113.62","14.88"],["113.63","310.73"],["113.64","92.10"],["113.65","224.21"],["113.66","360.00"],["113.67","85.27"],["113.68","645.71"],["113.69","25.49"],["113.70","163.86"],["113.72","200.31"],["113.73","56.99"],["113.75","40.06"],["113.76","2025.28"],["113.77","781.95"],["113.78","70.56"],["113.80","24.85"],["113.82","1849.75"],["113.83","0"],["113.84","0"],["113.88","1908.10"],["113.90","0"],["113.94","1863.98"],["113.96","0"],["114.00","1841.92"],["114.02","0"],["114.06","1886.04"],["114.08","0"],["114.12","1996.33"],["114.14","0"],["114.18","1930.16"],["114.20","0"],["114.24","1974.27"],["114.26","0"],["114.30","1731.63"],["114.32","0"],["114.36","1709.57"],["114.38","0"],["114.42","1952.22"],["114.44","0"],["114.48","1753.69"],["114.50","0"],["114.54","2018.39"],["114.56","0"],["114.60","2040.45"],["114.62","0"],["114.66","1797.80"],["114.68","0"],["115.78","0"],["116.00","31.47"],["116.37","0"],["116.59","50.46"],["116.96","0"],["117.18","49.40"],["117.55","0"],["117.77","27.41"],["118.14","0"],["118.36","50.42"],["118.73","0"],["118.95","50.07"],["119.32","0"],["119.54","36.12"],["119.91","0"],["120.13","8.62"],["120.50","0"],["120.72","54.60"],["121.09","0"],["121.31","1.48"],["121.68","0"],["121.90","43.49"],["122.27","0"],["122.49","7.73"],["122.86","0"],["123.08","58.21"],["123.45","0"],["123.67","52.67"],["124.04","0"],["124.26","53.84"],["124.63","0"],["124.85","4.99"],["125.22","0"],["125.44","44.04"],["125.81","0"],["126.03","25.10"],["126.40","0"],["126.62","39.09"],["126.99","0"],["127.21","44.51"],["127.58","0"],["127.80","19.01"],["128.17","0"],["128.39","29.39"],["128.76","0"],["128.98","3.89"],["129.35","0"],["129.57","23.37"],["129.94","0"],["130.16","24.18"],["130.53","0"],["130.75","9.15"],["131.12","0"],["131.34","27.04"],["131.71","0"],["131.93","7.10"],["132.52","13.38"],["133.11","33.57"],["133.70","76.51"]],"bids":[["113.30","0"],["113.28","174.25"],["113.26","45.55"],["113.25","120.79"],["113.23","122.77"],["113.22","22.53"],["113.21","0"],["113.20","13.39"],["113.19","6.58"],["113.18","35.80"],["113.15","493.28"],["113.13","190.94"],["113.12","21.05"],["113.11","4.13"],["113.10","32.13"],["113.09","5.19"],["113.08","134.42"],["113.07","16.15"],["113.06","73.29"],["113.04","15.30"],["113.03","21.67"],["113.02","109.40"],["113.01","78.83"],["113.00","20.00"],["112.98","644.18"],["112.97","120.83"],["112.95","355.09"],["112.94","1600.40"],["112.93","129.51"],["112.92","54.88"],["112.90","47.76"],["112.88","40.15"],["112.87","441.11"],["112.86","6.36"],["112.85","2141.49"],["112.84","25.72"],["112.83","11.36"],["112.82","10.52"],["112.81","74.57"],["112.80","11.41"],["112.79","1779.66"],["112.78","113.73"],["112.75","0"],["112.73","1886.04"],["112.69","0"],["112.67","1731.63"],["112.63","0"],["112.61","1709.57"],["112.57","0"],["112.55","1930.16"],["112.51","0"],["112.49","2018.39"],["112.45","0"],["112.43","1974.27"],["112.39","0"],["112.37","1797.80"],["112.33","0"],["112.31","1753.69"],["112.27","0"],["112.25","1863.98"],["112.21","0"],["112.19","1908.10"],["112.15","0"],["112.13","1819.86"],["112.09","0"],["112.07","1996.33"],["112.03","0"],["112.01","1841.92"],["111.97","0"],["111.95","2040.45"],["111.66","0"],["111.61","44.63"],["111.07","0"],["111.02","97.81"],["110.47","0"],["110.43","40.49"],["109.88","0"],["109.84","85.27"],["109.29","0"],["109.25","84.73"],["108.70","0"],["108.66","59.74"],["108.11","0"],["108.07","61.13"],["107.52","0"],["107.48","33.01"],["106.93","0"],["106.89","56.85"],["106.34","0"],["106.30","24.34"],["105.75","0"],["105.71","1.74"],["105.16","0"],["105.12","57.94"],["104.57","0"],["104.53","58.21"],["103.98","0"],["103.94","46.12"],["103.39","0"],["103.35","52.32"],["102.80","0"],["102.76","45.29"],["102.21","0"],["102.17","22.94"],["101.62","0"],["101.58","36.02"],["101.03","0"],["100.99","38.02"],["100.44","0"],["100.40","53.60"],["99.85","0"],["99.26","0"],["98.67","0"],["98.08","0"],["97.49","0"],["96.90","0"],["96.31","0"],["95.72","0"],["95.13","0"],["94.54","0"],["93.95","0"],["93.36","0"],["92.77","0"],["92.18","0"]],"checksum":1597278650,"ts":"1649290107445"}]}
1649290107.628789: {"action":"snapshot","arg":{"instType":"mc","channel":"ticker","instId":"UNIUSDT"},"data":[{"instId":"UNIUSDT","last":"9.9690","bestAsk":"9.971","bestBid":"9.966","high24h":"10.4280","low24h":"9.9030","priceChangePercent":"-0.0399","capitalRate":"-0.000100","nextSettleTime":1649314800000,"systemTime":1649290107597,"markPrice":"9.9737","indexPrice":"9.9798","holding":"369411","baseVolume":"313119","quoteVolume":"3294803"}]}
