wss://pubwss.bithumb.com/pub/ws <-> 1622591001.8883781
wss://pubwss.bithumb.com/pub/ws <- 1622591002.2931998: {"type":"transaction","symbols":["SOC_KRW","GOM2_KRW","ANV_KRW","BNB_KRW","RNT_KRW","CHZ_KRW","ETH_BTC","FNB_KRW","CON_KRW","BAL_BTC"]}
wss://pubwss.bithumb.com/pub/ws <- 1622591002.2933: {"type":"orderbookdepth","symbols":["SOC_KRW","GOM2_KRW","ANV_KRW","BNB_KRW","RNT_KRW","CHZ_KRW","ETH_BTC","FNB_KRW","CON_KRW","BAL_BTC"]}
1622591002.2936409: {"status":"0000","resmsg":"Connected Successfully"}
1622591002.598911: {"status":"0000","resmsg":"Filter Registered Successfully"}
1622591012.636585: {"status":"0000","resmsg":"Filter Registered Successfully"}
1622591013.045269: {"type":"orderbookdepth","content":{"list":[{"symbol":"ETH_BTC","orderType":"ask","price":"0.07232378","quantity":"0","total":"0"},{"symbol":"ETH_BTC","orderType":"ask","price":"0.07232376","quantity":"1.6088","total":"1"},{"symbol":"ETH_BTC","orderType":"bid","price":"0.07108345","quantity":"0","total":"0"},{"symbol":"ETH_BTC","orderType":"bid","price":"0.07108354","quantity":"2.2972","total":"2"},{"symbol":"ETH_BTC","orderType":"bid","price":"0.0710835","quantity":"1.8443","total":"1"},{"symbol":"ETH_BTC","orderType":"bid","price":"0.07108346","quantity":"0.4529","total":"1"}],"datetime":"1622591012656250"}}
1622591013.046994: {"type":"orderbookdepth","content":{"list":[{"symbol":"GOM2_KRW","orderType":"ask","price":"7.533","quantity":"0","total":"0"},{"symbol":"GOM2_KRW","orderType":"bid","price":"7.401","quantity":"0","total":"0"},{"symbol":"GOM2_KRW","orderType":"bid","price":"7.33","quantity":"3680","total":"1"}],"datetime":"1622591012596500"}}
1622591013.047153: {"type":"orderbookdepth","content":{"list":[{"symbol":"CHZ_KRW","orderType":"bid","price":"320.1","quantity":"25000","total":"1"}],"datetime":"1622591012748228"}}
1622591013.864497: {"type":"orderbookdepth","content":{"list":[{"symbol":"GOM2_KRW","orderType":"bid","price":"7.243","quantity":"0","total":"0"}],"datetime":"1622591013596495"}}
1622591013.8648598: {"type":"orderbookdepth","content":{"list":[{"symbol":"ETH_BTC","orderType":"ask","price":"0.07232377","quantity":"0","total":"0"},{"symbol":"ETH_BTC","orderType":"ask","price":"0.07232375","quantity":"0.1083","total":"1"},{"symbol":"ETH_BTC","orderType":"bid","price":"0.0710835","quantity":"0","total":"0"},{"symbol":"ETH_BTC","orderType":"bid","price":"0.07105666","quantity":"0","total":"0"},{"symbol":"ETH_BTC","orderType":"bid","price":"0.07108358","quantity":"1.8443","total":"1"},{"symbol":"ETH_BTC","orderType":"bid","price":"0.07108355","quantity":"0.4529","total":"1"},{"symbol":"ETH_BTC","orderType":"bid","price":"0.07108354","quantity":"0.6043","total":"1"},{"symbol":"ETH_BTC","orderType":"bid","price":"0.07108329","quantity":"0.015","total":"1"}],"datetime":"1622591013656259"}}
1622591013.865084: {"type":"orderbookdepth","content":{"list":[{"symbol":"ANV_KRW","orderType":"ask","price":"1514","quantity":"0","total":"0"}],"datetime":"1622591013641158"}}
1622591013.879086: {"type":"orderbookdepth","content":{"list":[{"symbol":"CHZ_KRW","orderType":"ask","price":"322.3","quantity":"0","total":"0"},{"symbol":"CHZ_KRW","orderType":"ask","price":"322.1","quantity":"63345.942","total":"1"},{"symbol":"CHZ_KRW","orderType":"bid","price":"320.1","quantity":"0","total":"0"},{"symbol":"CHZ_KRW","orderType":"bid","price":"317.3","quantity":"0","total":"0"},{"symbol":"CHZ_KRW","orderType":"bid","price":"320.2","quantity":"42325.272","total":"1"},{"symbol":"CHZ_KRW","orderType":"bid","price":"319.9","quantity":"2897.6562","total":"1"},{"symbol":"CHZ_KRW","orderType":"bid","price":"318.1","quantity":"115.3228","total":"1"}],"datetime":"1622591013748240"}}
1622591014.759711: {"type":"orderbookdepth","content":{"list":[{"symbol":"BNB_KRW","orderType":"ask","price":"427500","quantity":"28.4179","total":"3"},{"symbol":"BNB_KRW","orderType":"ask","price":"428500","quantity":"3.0825","total":"5"},{"symbol":"BNB_KRW","orderType":"ask","price":"428600","quantity":"4","total":"1"},{"symbol":"BNB_KRW","orderType":"bid","price":"397200","quantity":"0","total":"0"}],"datetime":"1622591014355192"}}
1622591015.093489: {"type":"orderbookdepth","content":{"list":[{"symbol":"CON_KRW","orderType":"ask","price":"3.908","quantity":"12365.191","total":"1"}],"datetime":"1622591014449141"}}
1622591015.093842: {"type":"transaction","content":{"list":[{"buySellGb":"2","contPrice":"3.908","contQty":"12365.191","contAmt":"48323.166","contDtm":"2021-06-02 08:43:34.555058","updn":"dn","symbol":"CON_KRW"}]}}
1622591015.138912: {"type":"orderbookdepth","content":{"list":[{"symbol":"ETH_BTC","orderType":"bid","price":"0.07108358","quantity":"0","total":"0"},{"symbol":"ETH_BTC","orderType":"bid","price":"0.07108346","quantity":"0","total":"0"},{"symbol":"ETH_BTC","orderType":"bid","price":"0.07108371","quantity":"1.8443","total":"1"},{"symbol":"ETH_BTC","orderType":"bid","price":"0.07108359","quantity":"1.8443","total":"1"},{"symbol":"ETH_BTC","orderType":"bid","price":"0.07108336","quantity":"0.055","total":"1"}],"datetime":"1622591014656246"}}
1622591015.141245: {"type":"orderbookdepth","content":{"list":[{"symbol":"ANV_KRW","orderType":"ask","price":"1513","quantity":"0","total":"0"},{"symbol":"ANV_KRW","orderType":"ask","price":"1515","quantity":"589.7791","total":"1"},{"symbol":"ANV_KRW","orderType":"bid","price":"1493","quantity":"0","total":"0"},{"symbol":"ANV_KRW","orderType":"bid","price":"1505","quantity":"35.5375","total":"1"}],"datetime":"1622591014641166"}}
1622591015.1838531: {"type":"orderbookdepth","content":{"list":[{"symbol":"CHZ_KRW","orderType":"ask","price":"322.2","quantity":"0","total":"0"},{"symbol":"CHZ_KRW","orderType":"ask","price":"322","quantity":"3623.4009","total":"1"}],"datetime":"1622591014748202"}}
1622591015.579745: {"type":"orderbookdepth","content":{"list":[{"symbol":"BNB_KRW","orderType":"bid","price":"397700","quantity":"0.836","total":"1"}],"datetime":"1622591015355160"}}
1622591015.752079: {"type":"orderbookdepth","content":{"list":[{"symbol":"CON_KRW","orderType":"ask","price":"3.908","quantity":"0","total":"0"}],"datetime":"1622591015449158"}}
1622591015.88202: {"type":"orderbookdepth","content":{"list":[{"symbol":"ETH_BTC","orderType":"bid","price":"0.07108371","quantity":"0","total":"0"},{"symbol":"ETH_BTC","orderType":"bid","price":"0.07108355","quantity":"0","total":"0"},{"symbol":"ETH_BTC","orderType":"bid","price":"0.07108363","quantity":"1.8443","total":"1"},{"symbol":"ETH_BTC","orderType":"bid","price":"0.07108359","quantity":"2.2972","total":"2"}],"datetime":"1622591015656242"}}
1622591015.9031081: {"type":"orderbookdepth","content":{"list":[{"symbol":"GOM2_KRW","orderType":"ask","price":"7.533","quantity":"32003.694","total":"1"},{"symbol":"GOM2_KRW","orderType":"bid","price":"7.421","quantity":"0","total":"0"},{"symbol":"GOM2_KRW","orderType":"bid","price":"7.245","quantity":"4140","total":"1"}],"datetime":"1622591015596500"}}
1622591016.004158: {"type":"orderbookdepth","content":{"list":[{"symbol":"CHZ_KRW","orderType":"ask","price":"322.5","quantity":"25243.2578","total":"2"},{"symbol":"CHZ_KRW","orderType":"bid","price":"319.1","quantity":"0","total":"0"},{"symbol":"CHZ_KRW","orderType":"bid","price":"319.5","quantity":"2402.1042","total":"3"}],"datetime":"1622591015748231"}}
1622591016.5384161: {"type":"orderbookdepth","content":{"list":[{"symbol":"BNB_KRW","orderType":"ask","price":"427300","quantity":"0","total":"0"},{"symbol":"BNB_KRW","orderType":"ask","price":"427700","quantity":"6","total":"1"}],"datetime":"1622591016355196"}}
1622591016.963286: {"type":"orderbookdepth","content":{"list":[{"symbol":"ETH_BTC","orderType":"bid","price":"0.07108363","quantity":"0","total":"0"},{"symbol":"ETH_BTC","orderType":"bid","price":"0.07108359","quantity":"0","total":"0"},{"symbol":"ETH_BTC","orderType":"bid","price":"0.07108381","quantity":"1.8443","total":"1"},{"symbol":"ETH_BTC","orderType":"bid","price":"0.07108368","quantity":"1.8443","total":"1"},{"symbol":"ETH_BTC","orderType":"bid","price":"0.07108364","quantity":"0.4529","total":"1"}],"datetime":"1622591016656269"}}
1622591016.976318: {"type":"orderbookdepth","content":{"list":[{"symbol":"GOM2_KRW","orderType":"ask","price":"7.579","quantity":"0","total":"0"},{"symbol":"GOM2_KRW","orderType":"bid","price":"7.401","quantity":"3433.4486","total":"1"}],"datetime":"1622591016596497"}}
1622591017.0608692: {"type":"orderbookdepth","content":{"list":[{"symbol":"CHZ_KRW","orderType":"bid","price":"318.1","quantity":"0","total":"0"},{"symbol":"CHZ_KRW","orderType":"bid","price":"317.3","quantity":"115.3228","total":"1"}],"datetime":"1622591016748199"}}
1622591017.725097: {"type":"orderbookdepth","content":{"list":[{"symbol":"BNB_KRW","orderType":"ask","price":"427700","quantity":"0","total":"0"},{"symbol":"BNB_KRW","orderType":"ask","price":"427400","quantity":"152.348","total":"3"}],"datetime":"1622591017355197"}}
1622591017.725471: {"type":"orderbookdepth","content":{"list":[{"symbol":"RNT_KRW","orderType":"bid","price":"16.63","quantity":"0","total":"0"}],"datetime":"1622591017393264"}}
1622591017.824534: {"type":"orderbookdepth","content":{"list":[{"symbol":"ETH_BTC","orderType":"bid","price":"0.07108368","quantity":"0","total":"0"},{"symbol":"ETH_BTC","orderType":"bid","price":"0.07108382","quantity":"0.4529","total":"1"}],"datetime":"1622591017656262"}}
1622591017.845025: {"type":"orderbookdepth","content":{"list":[{"symbol":"GOM2_KRW","orderType":"ask","price":"7.579","quantity":"69140.265","total":"1"},{"symbol":"GOM2_KRW","orderType":"bid","price":"7.522","quantity":"0","total":"0"},{"symbol":"GOM2_KRW","orderType":"bid","price":"7.421","quantity":"16720.2726","total":"1"}],"datetime":"1622591017596498"}}
1622591017.951267: {"type":"orderbookdepth","content":{"list":[{"symbol":"ANV_KRW","orderType":"ask","price":"1514","quantity":"351.5619","total":"1"}],"datetime":"1622591017641165"}}
1622591018.0355709: {"type":"orderbookdepth","content":{"list":[{"symbol":"CHZ_KRW","orderType":"ask","price":"323.3","quantity":"0","total":"0"},{"symbol":"CHZ_KRW","orderType":"ask","price":"323.5","quantity":"0","total":"0"},{"symbol":"CHZ_KRW","orderType":"ask","price":"323.6","quantity":"2400","total":"2"},{"symbol":"CHZ_KRW","orderType":"bid","price":"320.3","quantity":"25000","total":"1"}],"datetime":"1622591017748198"}}
1622591018.56346: {"type":"orderbookdepth","content":{"list":[{"symbol":"BNB_KRW","orderType":"ask","price":"427800","quantity":"0","total":"0"},{"symbol":"BNB_KRW","orderType":"ask","price":"427400","quantity":"145.5704","total":"1"},{"symbol":"BNB_KRW","orderType":"ask","price":"427500","quantity":"18.4179","total":"2"},{"symbol":"BNB_KRW","orderType":"ask","price":"427700","quantity":"6","total":"1"}],"datetime":"1622591018355158"}}
1622591019.668184: {"type":"orderbookdepth","content":{"list":[{"symbol":"GOM2_KRW","orderType":"ask","price":"7.533","quantity":"0","total":"0"},{"symbol":"GOM2_KRW","orderType":"bid","price":"7.401","quantity":"0","total":"0"}],"datetime":"1622591018596503"}}
1622591019.6867871: {"type":"orderbookdepth","content":{"list":[{"symbol":"ETH_BTC","orderType":"ask","price":"0.07232376","quantity":"0","total":"0"},{"symbol":"ETH_BTC","orderType":"ask","price":"0.07232399","quantity":"0","total":"0"},{"symbol":"ETH_BTC","orderType":"ask","price":"0.07232374","quantity":"1.6093","total":"1"},{"symbol":"ETH_BTC","orderType":"bid","price":"0.07108381","quantity":"0","total":"0"},{"symbol":"ETH_BTC","orderType":"bid","price":"0.07108336","quantity":"0","total":"0"},{"symbol":"ETH_BTC","orderType":"bid","price":"0.07108329","quantity":"0","total":"0"},{"symbol":"ETH_BTC","orderType":"bid","price":"0.07108394","quantity":"1.8443","total":"1"},{"symbol":"ETH_BTC","orderType":"bid","price":"0.07108386","quantity":"1.8443","total":"1"},{"symbol":"ETH_BTC","orderType":"bid","price":"0.07108364","quantity":"0.0144","total":"1"}],"datetime":"1622591018656265"}}
1622591019.773372: {"type":"orderbookdepth","content":{"list":[{"symbol":"ANV_KRW","orderType":"ask","price":"1515","quantity":"0","total":"0"},{"symbol":"ANV_KRW","orderType":"ask","price":"1513","quantity":"370.7993","total":"1"}],"datetime":"1622591018641208"}}
1622591019.77374: {"type":"orderbookdepth","content":{"list":[{"symbol":"CHZ_KRW","orderType":"bid","price":"317.3","quantity":"0","total":"0"},{"symbol":"CHZ_KRW","orderType":"bid","price":"318.1","quantity":"115.3228","total":"1"}],"datetime":"1622591018748234"}}
1622591020.318681: {"type":"orderbookdepth","content":{"list":[{"symbol":"BNB_KRW","orderType":"ask","price":"427400","quantity":"0","total":"0"},{"symbol":"BNB_KRW","orderType":"ask","price":"428600","quantity":"0","total":"0"},{"symbol":"BNB_KRW","orderType":"ask","price":"427600","quantity":"188.5852","total":"1"},{"symbol":"BNB_KRW","orderType":"ask","price":"428500","quantity":"2.2825","total":"4"},{"symbol":"BNB_KRW","orderType":"ask","price":"428800","quantity":"0.8","total":"1"},{"symbol":"BNB_KRW","orderType":"ask","price":"429500","quantity":"0.5847","total":"1"},{"symbol":"BNB_KRW","orderType":"bid","price":"425500","quantity":"0","total":"0"}],"datetime":"1622591019355174"}}
1622591020.7258098: {"type":"orderbookdepth","content":{"list":[{"symbol":"GOM2_KRW","orderType":"ask","price":"7.579","quantity":"0","total":"0"},{"symbol":"GOM2_KRW","orderType":"ask","price":"7.536","quantity":"37394.8663","total":"1"}],"datetime":"1622591019596496"}}
1622591020.726184: {"type":"orderbookdepth","content":{"list":[{"symbol":"ETH_BTC","orderType":"ask","price":"0.07232375","quantity":"0","total":"0"},{"symbol":"ETH_BTC","orderType":"ask","price":"0.07232373","quantity":"0.1083","total":"1"},{"symbol":"ETH_BTC","orderType":"bid","price":"0.07108394","quantity":"0","total":"0"},{"symbol":"ETH_BTC","orderType":"bid","price":"0.07108354","quantity":"0","total":"0"},{"symbol":"ETH_BTC","orderType":"bid","price":"0.07108399","quantity":"1.8443","total":"1"},{"symbol":"ETH_BTC","orderType":"bid","price":"0.07108395","quantity":"0.4529","total":"1"},{"symbol":"ETH_BTC","orderType":"bid","price":"0.07108382","quantity":"0.4415","total":"1"}],"datetime":"1622591019656241"}}
1622591020.726496: {"type":"orderbookdepth","content":{"list":[{"symbol":"ANV_KRW","orderType":"bid","price":"1505","quantity":"0","total":"0"},{"symbol":"ANV_KRW","orderType":"bid","price":"1496","quantity":"9.0971","total":"1"}],"datetime":"1622591019641161"}}
1622591020.826988: {"type":"orderbookdepth","content":{"list":[{"symbol":"CHZ_KRW","orderType":"ask","price":"322.1","quantity":"0","total":"0"},{"symbol":"CHZ_KRW","orderType":"ask","price":"321.9","quantity":"25744.752","total":"1"},{"symbol":"CHZ_KRW","orderType":"ask","price":"323.1","quantity":"3400.5","total":"1"},{"symbol":"CHZ_KRW","orderType":"bid","price":"320.3","quantity":"0","total":"0"},{"symbol":"CHZ_KRW","orderType":"bid","price":"320.2","quantity":"0","total":"0"},{"symbol":"CHZ_KRW","orderType":"bid","price":"320.1","quantity":"121984.533","total":"1"}],"datetime":"1622591019748231"}}
1622591021.515048: {"type":"orderbookdepth","content":{"list":[{"symbol":"BNB_KRW","orderType":"ask","price":"428800","quantity":"0","total":"0"},{"symbol":"BNB_KRW","orderType":"ask","price":"429000","quantity":"4.8","total":"2"},{"symbol":"BNB_KRW","orderType":"bid","price":"425700","quantity":"258.3285","total":"2"}],"datetime":"1622591020355191"}}
1622591021.851645: {"type":"orderbookdepth","content":{"list":[{"symbol":"ETH_BTC","orderType":"ask","price":"0.07254048","quantity":"10","total":"1"},{"symbol":"ETH_BTC","orderType":"bid","price":"0.07108382","quantity":"0","total":"0"},{"symbol":"ETH_BTC","orderType":"bid","price":"0.071084","quantity":"0.4529","total":"1"},{"symbol":"ETH_BTC","orderType":"bid","price":"0.07108383","quantity":"0.055","total":"1"}],"datetime":"1622591020656243"}}
1622591021.851927: {"type":"orderbookdepth","content":{"list":[{"symbol":"GOM2_KRW","orderType":"ask","price":"7.536","quantity":"0","total":"0"},{"symbol":"GOM2_KRW","orderType":"ask","price":"7.533","quantity":"48806.5695","total":"1"}],"datetime":"1622591020596499"}}
1622591022.004481: {"type":"orderbookdepth","content":{"list":[{"symbol":"CHZ_KRW","orderType":"ask","price":"322","quantity":"0","total":"0"},{"symbol":"CHZ_KRW","orderType":"ask","price":"323.6","quantity":"0","total":"0"},{"symbol":"CHZ_KRW","orderType":"ask","price":"324","quantity":"400","total":"1"},{"symbol":"CHZ_KRW","orderType":"ask","price":"324.1","quantity":"2000","total":"1"},{"symbol":"CHZ_KRW","orderType":"ask","price":"326.9","quantity":"3968.3175","total":"1"},{"symbol":"CHZ_KRW","orderType":"bid","price":"318.1","quantity":"0","total":"0"},{"symbol":"CHZ_KRW","orderType":"bid","price":"319.8","quantity":"115.3228","total":"1"}],"datetime":"1622591020748230"}}
1622591022.386975: {"type":"transaction","content":{"list":[{"buySellGb":"1","contPrice":"7.524","contQty":"626","contAmt":"4710.024","contDtm":"2021-06-02 08:43:41.416901","updn":"up","symbol":"GOM2_KRW"}]}}
1622591022.4157498: {"type":"orderbookdepth","content":{"list":[{"symbol":"BNB_KRW","orderType":"ask","price":"430400","quantity":"20","total":"1"},{"symbol":"BNB_KRW","orderType":"bid","price":"424700","quantity":"0","total":"0"},{"symbol":"BNB_KRW","orderType":"bid","price":"425500","quantity":"4.8","total":"2"}],"datetime":"1622591021355183"}}
1622591022.7130098: {"type":"orderbookdepth","content":{"list":[{"symbol":"ETH_BTC","orderType":"bid","price":"0.07108386","quantity":"0","total":"0"},{"symbol":"ETH_BTC","orderType":"bid","price":"0.07108404","quantity":"1.8443","total":"1"},{"symbol":"ETH_BTC","orderType":"bid","price":"0.07108395","quantity":"0.5256","total":"1"},{"symbol":"ETH_BTC","orderType":"bid","price":"0.07108394","quantity":"0.1082","total":"1"},{"symbol":"ETH_BTC","orderType":"bid","price":"0.07074046","quantity":"3.262","total":"1"}],"datetime":"1622591021656243"}}
1622591022.722702: {"type":"orderbookdepth","content":{"list":[{"symbol":"GOM2_KRW","orderType":"ask","price":"7.524","quantity":"76999.569","total":"1"},{"symbol":"GOM2_KRW","orderType":"bid","price":"7.421","quantity":"0","total":"0"},{"symbol":"GOM2_KRW","orderType":"bid","price":"7.422","quantity":"21341.956","total":"1"},{"symbol":"GOM2_KRW","orderType":"bid","price":"7.33","quantity":"7160","total":"2"}],"datetime":"1622591021596496"}}
1622591022.7877069: {"type":"orderbookdepth","content":{"list":[{"symbol":"ANV_KRW","orderType":"ask","price":"1514","quantity":"0","total":"0"}],"datetime":"1622591021641175"}}
1622591022.823814: {"type":"orderbookdepth","content":{"list":[{"symbol":"CHZ_KRW","orderType":"bid","price":"320.1","quantity":"146984.533","total":"2"}],"datetime":"1622591021748232"}}
1622591023.1954188: {"type":"transaction","content":{"list":[{"buySellGb":"2","contPrice":"7.523","contQty":"526","contAmt":"3957.098","contDtm":"2021-06-02 08:43:42.239684","updn":"dn","symbol":"GOM2_KRW"}]}}
1622591023.593179: {"type":"orderbookdepth","content":{"list":[{"symbol":"BNB_KRW","orderType":"bid","price":"425500","quantity":"0","total":"0"},{"symbol":"BNB_KRW","orderType":"bid","price":"397700","quantity":"0","total":"0"},{"symbol":"BNB_KRW","orderType":"bid","price":"425400","quantity":"4.8","total":"2"}],"datetime":"1622591022355175"}}
1622591023.998402: {"type":"orderbookdepth","content":{"list":[{"symbol":"GOM2_KRW","orderType":"ask","price":"7.524","quantity":"0","total":"0"},{"symbol":"GOM2_KRW","orderType":"ask","price":"7.525","quantity":"0","total":"0"},{"symbol":"GOM2_KRW","orderType":"ask","price":"7.533","quantity":"0","total":"0"},{"symbol":"GOM2_KRW","orderType":"bid","price":"7.525","quantity":"48123.7197","total":"1"},{"symbol":"GOM2_KRW","orderType":"bid","price":"7.523","quantity":"526","total":"1"},{"symbol":"GOM2_KRW","orderType":"bid","price":"7.355","quantity":"16720.2726","total":"1"}],"datetime":"1622591022596499"}}
1622591024.0118778: {"type":"orderbookdepth","content":{"list":[{"symbol":"ETH_BTC","orderType":"bid","price":"0.07108404","quantity":"0","total":"0"},{"symbol":"ETH_BTC","orderType":"bid","price":"0.07108405","quantity":"0.4529","total":"1"},{"symbol":"ETH_BTC","orderType":"bid","price":"0.07108395","quantity":"0.6037","total":"1"}],"datetime":"1622591022656241"}}
1622591024.076223: {"type":"orderbookdepth","content":{"list":[{"symbol":"ANV_KRW","orderType":"ask","price":"1515","quantity":"576.8256","total":"1"},{"symbol":"ANV_KRW","orderType":"bid","price":"1505","quantity":"35.5375","total":"1"}],"datetime":"1622591022641156"}}
1622591024.111331: {"type":"orderbookdepth","content":{"list":[{"symbol":"CHZ_KRW","orderType":"ask","price":"323.9","quantity":"25000","total":"1"}],"datetime":"1622591022748208"}}
1622591024.414725: {"type":"transaction","content":{"list":[{"buySellGb":"2","contPrice":"7.524","contQty":"76999.569","contAmt":"579344.757","contDtm":"2021-06-02 08:43:42.240601","updn":"up","symbol":"GOM2_KRW"},{"buySellGb":"2","contPrice":"7.525","contQty":"537","contAmt":"4040.925","contDtm":"2021-06-02 08:43:42.241208","updn":"up","symbol":"GOM2_KRW"},{"buySellGb":"2","contPrice":"7.525","contQty":"524","contAmt":"3943.100","contDtm":"2021-06-02 08:43:42.241810","updn":"dn","symbol":"GOM2_KRW"},{"buySellGb":"1","contPrice":"7.525","contQty":"556","contAmt":"4183.900","contDtm":"2021-06-02 08:43:43.188333","updn":"dn","symbol":"GOM2_KRW"}]}}
1622591024.719946: {"type":"orderbookdepth","content":{"list":[{"symbol":"BNB_KRW","orderType":"ask","price":"429000","quantity":"0","total":"0"},{"symbol":"BNB_KRW","orderType":"ask","price":"429100","quantity":"4.8024","total":"3"},{"symbol":"BNB_KRW","orderType":"bid","price":"425700","quantity":"248.3285","total":"1"}],"datetime":"1622591023355193"}}
1622591024.7203698: {"type":"orderbookdepth","content":{"list":[{"symbol":"RNT_KRW","orderType":"bid","price":"16.63","quantity":"210463.0186","total":"1"}],"datetime":"1622591023393258"}}
1622591024.822409: {"type":"orderbookdepth","content":{"list":[{"symbol":"GOM2_KRW","orderType":"ask","price":"7.53","quantity":"49555.4648","total":"1"},{"symbol":"GOM2_KRW","orderType":"bid","price":"7.525","quantity":"47567.7197","total":"1"},{"symbol":"GOM2_KRW","orderType":"bid","price":"7.423","quantity":"16720.2726","total":"1"}],"datetime":"1622591023596497"}}
1622591024.82278: {"type":"orderbookdepth","content":{"list":[{"symbol":"ETH_BTC","orderType":"ask","price":"0.07232374","quantity":"0","total":"0"},{"symbol":"ETH_BTC","orderType":"ask","price":"0.07232372","quantity":"1.6082","total":"1"},{"symbol":"ETH_BTC","orderType":"bid","price":"0.07074046","quantity":"0","total":"0"},{"symbol":"ETH_BTC","orderType":"bid","price":"0.07108405","quantity":"1.8443","total":"1"}],"datetime":"1622591023656245"}}
1622591024.82439: {"type":"orderbookdepth","content":{"list":[{"symbol":"ANV_KRW","orderType":"ask","price":"1513","quantity":"0","total":"0"},{"symbol":"ANV_KRW","orderType":"bid","price":"1496","quantity":"0","total":"0"}],"datetime":"1622591023641180"}}
1622591024.901283: {"type":"orderbookdepth","content":{"list":[{"symbol":"CHZ_KRW","orderType":"ask","price":"324","quantity":"0","total":"0"},{"symbol":"CHZ_KRW","orderType":"ask","price":"324.1","quantity":"0","total":"0"},{"symbol":"CHZ_KRW","orderType":"ask","price":"323","quantity":"1583.76","total":"2"},{"symbol":"CHZ_KRW","orderType":"ask","price":"324.2","quantity":"2400","total":"2"}],"datetime":"1622591023748222"}}
1622591025.436476: {"type":"orderbookdepth","content":{"list":[{"symbol":"BNB_KRW","orderType":"ask","price":"427700","quantity":"16","total":"2"},{"symbol":"BNB_KRW","orderType":"bid","price":"425400","quantity":"0","total":"0"},{"symbol":"BNB_KRW","orderType":"bid","price":"425300","quantity":"0.8","total":"1"},{"symbol":"BNB_KRW","orderType":"bid","price":"425200","quantity":"10","total":"2"}],"datetime":"1622591024355178"}}
1622591025.436913: {"type":"orderbookdepth","content":{"list":[{"symbol":"RNT_KRW","orderType":"ask","price":"22.29","quantity":"0","total":"0"}],"datetime":"1622591024393262"}}
1622591025.505616: {"type":"orderbookdepth","content":{"list":[{"symbol":"GOM2_KRW","orderType":"bid","price":"7.422","quantity":"0","total":"0"},{"symbol":"GOM2_KRW","orderType":"bid","price":"7.523","quantity":"1082","total":"2"},{"symbol":"GOM2_KRW","orderType":"bid","price":"7.33","quantity":"3480","total":"1"}],"datetime":"1622591024596496"}}
1622591025.506002: {"type":"orderbookdepth","content":{"list":[{"symbol":"ETH_BTC","orderType":"ask","price":"0.07232373","quantity":"0","total":"0"},{"symbol":"ETH_BTC","orderType":"ask","price":"0.07232371","quantity":"0.1083","total":"1"},{"symbol":"ETH_BTC","orderType":"bid","price":"0.071084","quantity":"0","total":"0"},{"symbol":"ETH_BTC","orderType":"bid","price":"0.07108399","quantity":"0","total":"0"},{"symbol":"ETH_BTC","orderType":"bid","price":"0.07108395","quantity":"0","total":"0"},{"symbol":"ETH_BTC","orderType":"bid","price":"0.07108417","quantity":"1.8443","total":"1"},{"symbol":"ETH_BTC","orderType":"bid","price":"0.07108412","quantity":"1.8443","total":"1"},{"symbol":"ETH_BTC","orderType":"bid","price":"0.07108406","quantity":"0.4529","total":"1"},{"symbol":"ETH_BTC","orderType":"bid","price":"0.07108405","quantity":"0.6037","total":"1"}],"datetime":"1622591024656244"}}
1622591025.658184: {"type":"orderbookdepth","content":{"list":[{"symbol":"CHZ_KRW","orderType":"ask","price":"326.9","quantity":"0","total":"0"}],"datetime":"1622591024748200"}}
1622591026.1532302: {"type":"orderbookdepth","content":{"list":[{"symbol":"BNB_KRW","orderType":"ask","price":"427900","quantity":"0","total":"0"},{"symbol":"BNB_KRW","orderType":"ask","price":"427400","quantity":"6","total":"1"},{"symbol":"BNB_KRW","orderType":"ask","price":"427700","quantity":"10","total":"1"},{"symbol":"BNB_KRW","orderType":"ask","price":"428400","quantity":"19","total":"1"}],"datetime":"1622591025355197"}}
1622591026.667188: {"type":"orderbookdepth","content":{"list":[{"symbol":"ETH_BTC","orderType":"bid","price":"0.07108412","quantity":"0","total":"0"},{"symbol":"ETH_BTC","orderType":"bid","price":"0.07108383","quantity":"0","total":"0"},{"symbol":"ETH_BTC","orderType":"bid","price":"0.07108364","quantity":"0","total":"0"},{"symbol":"ETH_BTC","orderType":"bid","price":"0.0710843","quantity":"1.8443","total":"1"},{"symbol":"ETH_BTC","orderType":"bid","price":"0.07108418","quantity":"0.4529","total":"1"},{"symbol":"ETH_BTC","orderType":"bid","price":"0.07108405","quantity":"0.6177","total":"2"},{"symbol":"ETH_BTC","orderType":"bid","price":"0.07074048","quantity":"3.262","total":"1"}],"datetime":"1622591025656240"}}
1622591026.667491: {"type":"orderbookdepth","content":{"list":[{"symbol":"GOM2_KRW","orderType":"ask","price":"7.579","quantity":"67602.7929","total":"1"},{"symbol":"GOM2_KRW","orderType":"bid","price":"7.355","quantity":"0","total":"0"}],"datetime":"1622591025596498"}}
1622591026.667657: {"type":"orderbookdepth","content":{"list":[{"symbol":"ANV_KRW","orderType":"ask","price":"1514","quantity":"351.5619","total":"1"}],"datetime":"1622591025641160"}}
1622591026.6677818: {"type":"orderbookdepth","content":{"list":[{"symbol":"CHZ_KRW","orderType":"ask","price":"321.9","quantity":"0","total":"0"},{"symbol":"CHZ_KRW","orderType":"ask","price":"322.4","quantity":"10447.371","total":"1"},{"symbol":"CHZ_KRW","orderType":"bid","price":"320.2","quantity":"14283.819","total":"1"},{"symbol":"CHZ_KRW","orderType":"bid","price":"320.1","quantity":"25000","total":"1"}],"datetime":"1622591025748231"}}
1622591026.968547: {"type":"orderbookdepth","content":{"list":[{"symbol":"BNB_KRW","orderType":"ask","price":"427400","quantity":"0","total":"0"},{"symbol":"BNB_KRW","orderType":"ask","price":"427600","quantity":"0","total":"0"},{"symbol":"BNB_KRW","orderType":"ask","price":"427700","quantity":"155.7392","total":"1"},{"symbol":"BNB_KRW","orderType":"ask","price":"427900","quantity":"6","total":"1"},{"symbol":"BNB_KRW","orderType":"bid","price":"425700","quantity":"0","total":"0"}],"datetime":"1622591026355163"}}
1622591027.116725: {"type":"orderbookdepth","content":{"list":[{"symbol":"ETH_BTC","orderType":"ask","price":"0.07232372","quantity":"0","total":"0"},{"symbol":"ETH_BTC","orderType":"ask","price":"0.0723237","quantity":"1.6077","total":"1"},{"symbol":"ETH_BTC","orderType":"bid","price":"0.0710843","quantity":"0","total":"0"},{"symbol":"ETH_BTC","orderType":"bid","price":"0.07108417","quantity":"0","total":"0"},{"symbol":"ETH_BTC","orderType":"bid","price":"0.07108406","quantity":"0","total":"0"},{"symbol":"ETH_BTC","orderType":"bid","price":"0.07108431","quantity":"0.4529","total":"1"},{"symbol":"ETH_BTC","orderType":"bid","price":"0.07108415","quantity":"1.8443","total":"1"},{"symbol":"ETH_BTC","orderType":"bid","price":"0.07108405","quantity":"0.014","total":"1"}],"datetime":"1622591026656246"}}
1622591027.271165: {"type":"orderbookdepth","content":{"list":[{"symbol":"GOM2_KRW","orderType":"ask","price":"7.579","quantity":"0","total":"0"},{"symbol":"GOM2_KRW","orderType":"bid","price":"7.33","quantity":"0","total":"0"},{"symbol":"GOM2_KRW","orderType":"bid","price":"7.401","quantity":"8100.0826","total":"1"}],"datetime":"1622591026596496"}}
1622591027.3705459: {"type":"orderbookdepth","content":{"list":[{"symbol":"ANV_KRW","orderType":"ask","price":"1515","quantity":"0","total":"0"},{"symbol":"ANV_KRW","orderType":"ask","price":"1513","quantity":"378.431","total":"1"},{"symbol":"ANV_KRW","orderType":"bid","price":"1505","quantity":"0","total":"0"},{"symbol":"ANV_KRW","orderType":"bid","price":"1496","quantity":"9.6718","total":"1"}],"datetime":"1622591026641161"}}
1622591027.404639: {"type":"orderbookdepth","content":{"list":[{"symbol":"CHZ_KRW","orderType":"ask","price":"322.7","quantity":"3716.8427","total":"1"},{"symbol":"CHZ_KRW","orderType":"ask","price":"323","quantity":"2.1042","total":"1"},{"symbol":"CHZ_KRW","orderType":"bid","price":"319.8","quantity":"0","total":"0"},{"symbol":"CHZ_KRW","orderType":"bid","price":"320.5","quantity":"115.3228","total":"1"}],"datetime":"1622591026748209"}}
1622591027.688232: {"type":"orderbookdepth","content":{"list":[{"symbol":"BNB_KRW","orderType":"ask","price":"427900","quantity":"0","total":"0"},{"symbol":"BNB_KRW","orderType":"ask","price":"427500","quantity":"24.4179","total":"3"},{"symbol":"BNB_KRW","orderType":"bid","price":"425800","quantity":"10","total":"1"}],"datetime":"1622591027355177"}}
1622591027.9959428: {"type":"orderbookdepth","content":{"list":[{"symbol":"GOM2_KRW","orderType":"bid","price":"7.423","quantity":"0","total":"0"}],"datetime":"1622591027596496"}}
1622591027.996188: {"type":"orderbookdepth","content":{"list":[{"symbol":"ETH_BTC","orderType":"ask","price":"0.07232371","quantity":"0","total":"0"},{"symbol":"ETH_BTC","orderType":"ask","price":"0.07232369","quantity":"0.1083","total":"1"},{"symbol":"ETH_BTC","orderType":"bid","price":"0.07108418","quantity":"0.5462","total":"1"}],"datetime":"1622591027656296"}}
1622591028.692537: {"type":"orderbookdepth","content":{"list":[{"symbol":"BNB_KRW","orderType":"ask","price":"427900","quantity":"10","total":"1"}],"datetime":"1622591028355162"}}
1622591029.0200908: {"type":"orderbookdepth","content":{"list":[{"symbol":"ETH_BTC","orderType":"bid","price":"0.07108431","quantity":"0","total":"0"},{"symbol":"ETH_BTC","orderType":"bid","price":"0.07108415","quantity":"0","total":"0"},{"symbol":"ETH_BTC","orderType":"bid","price":"0.07108432","quantity":"0.5156","total":"1"},{"symbol":"ETH_BTC","orderType":"bid","price":"0.0710843","quantity":"1.8443","total":"1"},{"symbol":"ETH_BTC","orderType":"bid","price":"0.07108425","quantity":"1.8443","total":"1"},{"symbol":"ETH_BTC","orderType":"bid","price":"0.07108419","quantity":"0.4529","total":"1"},{"symbol":"ETH_BTC","orderType":"bid","price":"0.07108418","quantity":"0.056","total":"1"}],"datetime":"1622591028656240"}}
1622591029.590414: {"type":"orderbookdepth","content":{"list":[{"symbol":"BNB_KRW","orderType":"ask","price":"428400","quantity":"0","total":"0"},{"symbol":"BNB_KRW","orderType":"ask","price":"427900","quantity":"29","total":"2"}],"datetime":"1622591029355159"}}
1622591030.044775: {"type":"orderbookdepth","content":{"list":[{"symbol":"ETH_BTC","orderType":"bid","price":"0.07108432","quantity":"0","total":"0"},{"symbol":"ETH_BTC","orderType":"bid","price":"0.07108425","quantity":"0","total":"0"},{"symbol":"ETH_BTC","orderType":"bid","price":"0.07108433","quantity":"0.4529","total":"1"},{"symbol":"ETH_BTC","orderType":"bid","price":"0.07108431","quantity":"1.8443","total":"1"}],"datetime":"1622591029656272"}}
1622591030.045195: {"type":"orderbookdepth","content":{"list":[{"symbol":"ANV_KRW","orderType":"ask","price":"1514","quantity":"0","total":"0"}],"datetime":"1622591029641161"}}
1622591030.556533: {"type":"orderbookdepth","content":{"list":[{"symbol":"BNB_KRW","orderType":"ask","price":"427700","quantity":"165.7392","total":"2"},{"symbol":"BNB_KRW","orderType":"bid","price":"425800","quantity":"0","total":"0"},{"symbol":"BNB_KRW","orderType":"bid","price":"426600","quantity":"0.699","total":"2"}],"datetime":"1622591030355159"}}
1622591030.9617321: {"type":"orderbookdepth","content":{"list":[{"symbol":"ETH_BTC","orderType":"bid","price":"0.0710843","quantity":"0","total":"0"},{"symbol":"ETH_BTC","orderType":"bid","price":"0.07108419","quantity":"0","total":"0"},{"symbol":"ETH_BTC","orderType":"bid","price":"0.07074048","quantity":"0","total":"0"},{"symbol":"ETH_BTC","orderType":"bid","price":"0.07108449","quantity":"1.8443","total":"1"},{"symbol":"ETH_BTC","orderType":"bid","price":"0.07108432","quantity":"1.0566","total":"2"}],"datetime":"1622591030656242"}}
1622591030.962174: {"type":"orderbookdepth","content":{"list":[{"symbol":"ANV_KRW","orderType":"ask","price":"1513","quantity":"0","total":"0"},{"symbol":"ANV_KRW","orderType":"ask","price":"1515","quantity":"564.8407","total":"1"},{"symbol":"ANV_KRW","orderType":"bid","price":"1496","quantity":"0","total":"0"},{"symbol":"ANV_KRW","orderType":"bid","price":"1505","quantity":"35.5375","total":"1"}],"datetime":"1622591030641173"}}
1622591031.5236201: {"type":"orderbookdepth","content":{"list":[{"symbol":"BNB_KRW","orderType":"ask","price":"427900","quantity":"19","total":"1"},{"symbol":"BNB_KRW","orderType":"bid","price":"425700","quantity":"201.3221","total":"1"}],"datetime":"1622591031355158"}}
1622591031.8881779: {"type":"orderbookdepth","content":{"list":[{"symbol":"GOM2_KRW","orderType":"bid","price":"7.245","quantity":"0","total":"0"},{"symbol":"GOM2_KRW","orderType":"bid","price":"7.32","quantity":"4440","total":"1"}],"datetime":"1622591031596495"}}
1622591031.888555: {"type":"orderbookdepth","content":{"list":[{"symbol":"ETH_BTC","orderType":"ask","price":"0.0723237","quantity":"0","total":"0"},{"symbol":"ETH_BTC","orderType":"ask","price":"0.07254048","quantity":"0","total":"0"},{"symbol":"ETH_BTC","orderType":"bid","price":"0.07108433","quantity":"0","total":"0"},{"symbol":"ETH_BTC","orderType":"bid","price":"0.07108431","quantity":"0","total":"0"},{"symbol":"ETH_BTC","orderType":"bid","price":"0.07108418","quantity":"0","total":"0"},{"symbol":"ETH_BTC","orderType":"bid","price":"0.0710845","quantity":"0.4529","total":"1"},{"symbol":"ETH_BTC","orderType":"bid","price":"0.07108432","quantity":"0.6037","total":"1"},{"symbol":"ETH_BTC","orderType":"bid","price":"0.07074049","quantity":"3.262","total":"1"}],"datetime":"1622591031656256"}}
1622591031.9468968: {"type":"orderbookdepth","content":{"list":[{"symbol":"CHZ_KRW","orderType":"ask","price":"322.4","quantity":"0","total":"0"},{"symbol":"CHZ_KRW","orderType":"bid","price":"320.2","quantity":"0","total":"0"}],"datetime":"1622591031748228"}}
1622591032.486801: {"type":"orderbookdepth","content":{"list":[{"symbol":"BNB_KRW","orderType":"ask","price":"426900","quantity":"24.1012","total":"1"},{"symbol":"BNB_KRW","orderType":"ask","price":"427500","quantity":"18.4179","total":"2"},{"symbol":"BNB_KRW","orderType":"ask","price":"427800","quantity":"6","total":"1"}],"datetime":"1622591032355158"}}
1622591032.629588: {"type":"orderbookdepth","content":{"list":[{"symbol":"CON_KRW","orderType":"ask","price":"12.07","quantity":"0","total":"0"}],"datetime":"1622591032449142"}}
1622591032.815813: {"type":"orderbookdepth","content":{"list":[{"symbol":"ETH_BTC","orderType":"ask","price":"0.07232369","quantity":"0","total":"0"},{"symbol":"ETH_BTC","orderType":"ask","price":"0.07232368","quantity":"1.6088","total":"1"},{"symbol":"ETH_BTC","orderType":"ask","price":"0.07232399","quantity":"0.1083","total":"1"},{"symbol":"ETH_BTC","orderType":"bid","price":"0.07108449","quantity":"0","total":"0"},{"symbol":"ETH_BTC","orderType":"bid","price":"0.07108432","quantity":"0","total":"0"},{"symbol":"ETH_BTC","orderType":"bid","price":"0.07108405","quantity":"0","total":"0"},{"symbol":"ETH_BTC","orderType":"bid","price":"0.07108443","quantity":"1.8443","total":"1"},{"symbol":"ETH_BTC","orderType":"bid","price":"0.07108442","quantity":"1.8443","total":"1"},{"symbol":"ETH_BTC","orderType":"bid","price":"0.07108434","quantity":"0.0147","total":"1"}],"datetime":"1622591032656272"}}
1622591032.891793: {"type":"orderbookdepth","content":{"list":[{"symbol":"CHZ_KRW","orderType":"ask","price":"322.4","quantity":"43394.076","total":"1"},{"symbol":"CHZ_KRW","orderType":"bid","price":"320.2","quantity":"6479.154","total":"1"}],"datetime":"1622591032748199"}}

