1618677671.149295: {"table":"orderBookL2","action":"update","data":[{"symbol":"EOSM21","id":52499998735,"side":"Buy","size":1913}]}
1618677671.149392: {"table":"orderBookL2","action":"update","data":[{"symbol":"EOSM21","id":52499998732,"side":"Sell","size":322}]}
1618677671.172972: {"table":"orderBookL2","action":"insert","data":[{"symbol":"XLMUSDT","id":52199939385,"side":"Buy","size":63,"price":0.60615}]}
1618677671.1752372: {"table":"orderBookL2","action":"delete","data":[{"symbol":"XLMUSDT","id":52199939498,"side":"Buy"}]}
1618677671.177931: {"table":"orderBookL2","action":"update","data":[{"symbol":"EOSUSDT","id":53899984095,"side":"Sell","size":14}]}
1618677671.205656: {"table":"orderBookL2","action":"insert","data":[{"symbol":"DOGEUSDT","id":47599970487,"side":"Sell","size":200,"price":0.29513}]}
1618677671.301588: {"table":"orderBookL2","action":"delete","data":[{"symbol":"LTCUSD","id":40699968681,"side":"Sell"}]}
1618677671.3017018: {"table":"orderBookL2","action":"insert","data":[{"symbol":"LTCUSD","id":40699968714,"side":"Sell","size":125,"price":312.86}]}
1618677671.313868: {"table":"orderBookL2","action":"delete","data":[{"symbol":"LTCM21","id":52899998913,"side":"Sell"},{"symbol":"LTCM21","id":52899998947,"side":"Buy"},{"symbol":"LTCM21","id":52899998953,"side":"Buy"}]}
1618677671.314008: {"table":"orderBookL2","action":"update","data":[{"symbol":"LTCM21","id":52899998914,"side":"Sell","size":10},{"symbol":"LTCM21","id":52899998916,"side":"Sell","size":50},{"symbol":"LTCM21","id":52899998919,"side":"Sell","size":348},{"symbol":"LTCM21","id":52899998921,"side":"Sell","size":204},{"symbol":"LTCM21","id":52899998922,"side":"Sell","size":485},{"symbol":"LTCM21","id":52899998924,"side":"Sell","size":485},{"symbol":"LTCM21","id":52899998925,"side":"Sell","size":494},{"symbol":"LTCM21","id":52899998927,"side":"Sell","size":203},{"symbol":"LTCM21","id":52899998928,"side":"Sell","size":552},{"symbol":"LTCM21","id":52899998932,"side":"Sell","size":277},{"symbol":"LTCM21","id":52899998933,"side":"Sell","size":231},{"symbol":"LTCM21","id":52899998935,"side":"Sell","size":200},{"symbol":"LTCM21","id":52899998937,"side":"Sell","size":202},{"symbol":"LTCM21","id":52899998938,"side":"Sell","size":304},{"symbol":"LTCM21","id":52899998940,"side":"Sell","size":278},{"symbol":"LTCM21","id":52899998941,"side":"Sell","size":52},{"symbol":"LTCM21","id":52899998943,"side":"Sell","size":18},{"symbol":"LTCM21","id":52899998949,"side":"Buy","size":26},{"symbol":"LTCM21","id":52899998950,"side":"Buy","size":203},{"symbol":"LTCM21","id":52899998952,"side":"Buy","size":376},{"symbol":"LTCM21","id":52899998957,"side":"Buy","size":204},{"symbol":"LTCM21","id":52899998958,"side":"Buy","size":280},{"symbol":"LTCM21","id":52899998960,"side":"Buy","size":346},{"symbol":"LTCM21","id":52899998962,"side":"Buy","size":5},{"symbol":"LTCM21","id":52899998963,"side":"Buy","size":506},{"symbol":"LTCM21","id":52899998965,"side":"Buy","size":211},{"symbol":"LTCM21","id":52899998966,"side":"Buy","size":632},{"symbol":"LTCM21","id":52899998969,"side":"Buy","size":206},{"symbol":"LTCM21","id":52899998972,"side":"Buy","size":151},{"symbol":"LTCM21","id":52899998974,"side":"Buy","size":13},{"symbol":"LTCM21","id":52899998976,"side":"Buy","size":35},{"symbol":"LTCM21","id":52899998977,"side":"Buy","size":97}]}
1618677671.314181: {"table":"orderBookL2","action":"insert","data":[{"symbol":"LTCM21","id":52899998918,"side":"Sell","size":8,"price":0.00541},{"symbol":"LTCM21","id":52899998930,"side":"Sell","size":4,"price":0.00535},{"symbol":"LTCM21","id":52899998955,"side":"Buy","size":2,"price":0.005225},{"symbol":"LTCM21","id":52899998968,"side":"Buy","size":6,"price":0.00516},{"symbol":"LTCM21","id":52899998971,"side":"Buy","size":6,"price":0.005145}]}
1618677671.314261: {"table":"orderBookL2","action":"update","data":[{"symbol":"LTCUSD","id":40699968781,"side":"Buy","size":5247}]}
1618677671.373142: {"table":"orderBookL2","action":"update","data":[{"symbol":"TRXM21","id":52999999734,"side":"Sell","size":10003969},{"symbol":"TRXM21","id":52999999737,"side":"Sell","size":12000400}]}
1618677671.440902: {"table":"orderBookL2","action":"insert","data":[{"symbol":"LTCUSD","id":40699968641,"side":"Sell","size":42,"price":313.59}]}
1618677671.4594948: {"table":"orderBookL2","action":"delete","data":[{"symbol":"XLMUSDT","id":52199939066,"side":"Sell"}]}
1618677671.459609: {"table":"orderBookL2","action":"delete","data":[{"symbol":"XLMUSDT","id":52199939097,"side":"Sell"}]}
1618677671.47122: {"table":"orderBookL2","action":"update","data":[{"symbol":"LTCUSD","id":40699968781,"side":"Buy","size":5000}]}
1618677671.482007: {"table":"orderBookL2","action":"update","data":[{"symbol":"LTCUSD","id":40699968668,"side":"Sell","size":520}]}
1618677671.4821131: {"table":"orderBookL2","action":"insert","data":[{"symbol":"LTCUSD","id":40699968694,"side":"Sell","size":154,"price":313.06}]}
1618677671.5085719: {"table":"orderBookL2","action":"delete","data":[{"symbol":"XLMUSDT","id":52199939401,"side":"Buy"}]}
1618677671.508688: {"table":"orderBookL2","action":"insert","data":[{"symbol":"XLMUSDT","id":52199939381,"side":"Buy","size":112,"price":0.60619}]}
1618677671.538669: {"table":"orderBookL2","action":"delete","data":[{"symbol":"LTCUSD","id":40699968216,"side":"Sell"},{"symbol":"LTCUSD","id":40699968548,"side":"Sell"},{"symbol":"LTCUSD","id":40699969042,"side":"Buy"},{"symbol":"LTCUSD","id":40699969243,"side":"Buy"}]}
1618677671.538777: {"table":"orderBookL2","action":"update","data":[{"symbol":"LTCUSD","id":40699968437,"side":"Sell","size":1783},{"symbol":"LTCUSD","id":40699969058,"side":"Buy","size":11433}]}
1618677671.538822: {"table":"orderBookL2","action":"insert","data":[{"symbol":"LTCUSD","id":40699968225,"side":"Sell","size":580,"price":317.75},{"symbol":"LTCUSD","id":40699968444,"side":"Sell","size":580,"price":315.56},{"symbol":"LTCUSD","id":40699968554,"side":"Sell","size":580,"price":314.46},{"symbol":"LTCUSD","id":40699969247,"side":"Buy","size":580,"price":307.53}]}
1618677671.53914: {"table":"orderBookL2","action":"delete","data":[{"symbol":"DOGEUSDT","id":47599971790,"side":"Buy"}]}
1618677671.541188: {"table":"orderBookL2","action":"insert","data":[{"symbol":"DOGEUSDT","id":47599971776,"side":"Buy","size":154,"price":0.28224}]}
1618677671.552713: {"table":"orderBookL2","action":"delete","data":[{"symbol":"LTCUSD","id":40699968712,"side":"Sell"}]}
1618677671.554684: {"table":"orderBookL2","action":"delete","data":[{"symbol":"LTCUSD","id":40699968444,"side":"Sell"},{"symbol":"LTCUSD","id":40699968554,"side":"Sell"},{"symbol":"LTCUSD","id":40699969247,"side":"Buy"}]}
1618677671.5547872: {"table":"orderBookL2","action":"insert","data":[{"symbol":"LTCUSD","id":40699968445,"side":"Sell","size":580,"price":315.55},{"symbol":"LTCUSD","id":40699968555,"side":"Sell","size":580,"price":314.45},{"symbol":"LTCUSD","id":40699969245,"side":"Buy","size":580,"price":307.55}]}
1618677671.56749: {"table":"orderBookL2","action":"delete","data":[{"symbol":"LTCUSD","id":40699968714,"side":"Sell"}]}
1618677671.568165: {"table":"orderBookL2","action":"delete","data":[{"symbol":"LTCUSD","id":40699968711,"side":"Sell"}]}
1618677671.571261: {"table":"orderBookL2","action":"delete","data":[{"symbol":"LTCUSD","id":40699968672,"side":"Sell"}]}
1618677671.675199: {"table":"orderBookL2","action":"delete","data":[{"symbol":"LTCUSD","id":40699968763,"side":"Buy"}]}
1618677671.679042: {"table":"orderBookL2","action":"delete","data":[{"symbol":"LTCUSD","id":40699968602,"side":"Sell"}]}
1618677671.6790988: {"table":"orderBookL2","action":"insert","data":[{"symbol":"LTCUSD","id":40699968699,"side":"Sell","size":155,"price":313.01}]}
1618677671.682245: {"table":"orderBookL2","action":"delete","data":[{"symbol":"LTCUSD","id":40699968225,"side":"Sell"},{"symbol":"LTCUSD","id":40699968445,"side":"Sell"},{"symbol":"LTCUSD","id":40699968555,"side":"Sell"},{"symbol":"LTCUSD","id":40699969245,"side":"Buy"}]}
1618677671.682382: {"table":"orderBookL2","action":"update","data":[{"symbol":"LTCUSD","id":40699968437,"side":"Sell","size":2363},{"symbol":"LTCUSD","id":40699968536,"side":"Sell","size":777}]}
1618677671.682417: {"table":"orderBookL2","action":"insert","data":[{"symbol":"LTCUSD","id":40699968217,"side":"Sell","size":580,"price":317.83},{"symbol":"LTCUSD","id":40699969243,"side":"Buy","size":580,"price":307.57}]}
1618677671.6839502: {"table":"orderBookL2","action":"insert","data":[{"symbol":"LTCUSD","id":40699968780,"side":"Buy","size":236,"price":312.2}]}
1618677671.7039979: {"table":"orderBookL2","action":"insert","data":[{"symbol":"LTCUSD","id":40699968763,"side":"Buy","size":1,"price":312.37}]}
1618677671.7959628: {"table":"orderBookL2","action":"insert","data":[{"symbol":"LTCUSD","id":40699968674,"side":"Sell","size":106,"price":313.26}]}
1618677671.805609: {"table":"orderBookL2","action":"insert","data":[{"symbol":"LTCUSD","id":40699968838,"side":"Buy","size":106,"price":311.62}]}
1618677671.805741: {"table":"orderBookL2","action":"delete","data":[{"symbol":"LTCUSD","id":40699968694,"side":"Sell"}]}
1618677671.807873: {"table":"orderBookL2","action":"insert","data":[{"symbol":"LTCUSD","id":40699968642,"side":"Sell","size":176,"price":313.58}]}
1618677671.8173828: {"table":"orderBookL2","action":"insert","data":[{"symbol":"LTCUSD","id":40699968711,"side":"Sell","size":39,"price":312.89}]}
1618677671.8205938: {"table":"orderBookL2","action":"delete","data":[{"symbol":"LTCUSD","id":40699968695,"side":"Sell"}]}
1618677671.835588: {"table":"orderBookL2","action":"insert","data":[{"symbol":"LTCUSD","id":40699968673,"side":"Sell","size":5000,"price":313.27}]}
1618677671.8982139: {"table":"orderBookL2","action":"delete","data":[{"symbol":"LTCUSD","id":40699968217,"side":"Sell"},{"symbol":"LTCUSD","id":40699968658,"side":"Sell"},{"symbol":"LTCUSD","id":40699969243,"side":"Buy"}]}
1618677671.8983622: {"table":"orderBookL2","action":"update","data":[{"symbol":"LTCUSD","id":40699968437,"side":"Sell","size":1783},{"symbol":"LTCUSD","id":40699968536,"side":"Sell","size":197}]}
1618677671.898428: {"table":"orderBookL2","action":"insert","data":[{"symbol":"LTCUSD","id":40699968211,"side":"Sell","size":580,"price":317.89},{"symbol":"LTCUSD","id":40699968431,"side":"Sell","size":580,"price":315.69},{"symbol":"LTCUSD","id":40699968540,"side":"Sell","size":580,"price":314.6},{"symbol":"LTCUSD","id":40699968648,"side":"Sell","size":580,"price":313.52},{"symbol":"LTCUSD","id":40699969231,"side":"Buy","size":580,"price":307.69}]}
1618677671.898821: {"table":"orderBookL2","action":"delete","data":[{"symbol":"LTCUSD","id":40699968778,"side":"Buy"}]}
1618677671.911551: {"table":"orderBookL2","action":"insert","data":[{"symbol":"LTCUSD","id":40699968779,"side":"Buy","size":685,"price":312.21}]}
1618677671.913962: {"table":"orderBookL2","action":"delete","data":[{"symbol":"LTCUSD","id":40699968699,"side":"Sell"}]}
1618677671.9140759: {"table":"orderBookL2","action":"insert","data":[{"symbol":"LTCUSD","id":40699968669,"side":"Sell","size":154,"price":313.31}]}
1618677671.920398: {"table":"orderBookL2","action":"delete","data":[{"symbol":"LTCUSD","id":40699968711,"side":"Sell"}]}
1618677671.952024: {"table":"orderBookL2","action":"update","data":[{"symbol":"ADAM21","id":52299997836,"side":"Buy","size":39209}]}
1618677672.0075881: {"table":"orderBookL2","action":"delete","data":[{"symbol":"LTCUSD","id":40699968805,"side":"Buy"}]}
1618677672.007703: {"table":"orderBookL2","action":"insert","data":[{"symbol":"LTCUSD","id":40699968786,"side":"Buy","size":133,"price":312.14}]}
1618677672.015349: {"table":"orderBookL2","action":"delete","data":[{"symbol":"LTCUSD","id":40699968780,"side":"Buy"}]}
1618677672.0154712: {"table":"orderBookL2","action":"insert","data":[{"symbol":"LTCUSD","id":40699968778,"side":"Buy","size":236,"price":312.22}]}
1618677672.041963: {"table":"orderBookL2","action":"delete","data":[{"symbol":"LTCUSD","id":40699968713,"side":"Sell"}]}
1618677672.042046: {"table":"orderBookL2","action":"insert","data":[{"symbol":"LTCUSD","id":40699968694,"side":"Sell","size":452,"price":313.06}]}
1618677672.054692: {"table":"orderBookL2","action":"insert","data":[{"symbol":"LTCUSD","id":40699968684,"side":"Sell","size":256,"price":313.16}]}
1618677672.057068: {"table":"orderBookL2","action":"delete","data":[{"symbol":"LTCUSD","id":40699968763,"side":"Buy"}]}
1618677672.057538: {"table":"orderBookL2","action":"delete","data":[{"symbol":"LTCUSD","id":40699968622,"side":"Sell"}]}
1618677672.0678: {"table":"orderBookL2","action":"delete","data":[{"symbol":"LTCUSD","id":40699968781,"side":"Buy"}]}
1618677672.072085: {"table":"orderBookL2","action":"delete","data":[{"symbol":"ADAM21","id":52299997831,"side":"Sell"}]}
1618677672.078224: {"table":"orderBookL2","action":"insert","data":[{"symbol":"LTCUSD","id":40699968757,"side":"Buy","size":5000,"price":312.43}]}
1618677672.0809898: {"table":"orderBookL2","action":"insert","data":[{"symbol":"LTCUSD","id":40699968687,"side":"Sell","size":538,"price":313.13}]}
1618677672.0849652: {"table":"orderBookL2","action":"update","data":[{"symbol":"ADAM21","id":52299997829,"side":"Sell","size":38008}]}
1618677672.085065: {"table":"orderBookL2","action":"insert","data":[{"symbol":"ADAM21","id":52299997817,"side":"Sell","size":536,"price":0.00002183}]}
1618677672.087212: {"table":"orderBookL2","action":"insert","data":[{"symbol":"ADAM21","id":52299997831,"side":"Sell","size":4300,"price":0.00002169}]}
1618677672.101046: {"table":"orderBookL2","action":"update","data":[{"symbol":"ADAM21","id":52299997828,"side":"Sell","size":38387}]}
1618677672.1016781: {"table":"orderBookL2","action":"delete","data":[{"symbol":"ADAM21","id":52299997831,"side":"Sell"}]}
1618677672.1046379: {"table":"orderBookL2","action":"delete","data":[{"symbol":"LTCUSD","id":40699968693,"side":"Sell"}]}
1618677672.12015: {"table":"orderBookL2","action":"insert","data":[{"symbol":"ADAM21","id":52299997831,"side":"Sell","size":4300,"price":0.00002169}]}
1618677672.129808: {"table":"orderBookL2","action":"insert","data":[{"symbol":"LTCUSD","id":40699968680,"side":"Sell","size":247,"price":313.2}]}
1618677672.1382668: {"table":"orderBookL2","action":"delete","data":[{"symbol":"ADAM21","id":52299997831,"side":"Sell"}]}
1618677672.153298: {"table":"orderBookL2","action":"insert","data":[{"symbol":"LTCUSD","id":40699968777,"side":"Buy","size":43,"price":312.23}]}
1618677672.156899: {"table":"orderBookL2","action":"insert","data":[{"symbol":"ADAM21","id":52299997831,"side":"Sell","size":4300,"price":0.00002169}]}
1618677672.168483: {"table":"orderBookL2","action":"delete","data":[{"symbol":"ADAM21","id":52299997831,"side":"Sell"}]}
1618677672.187694: {"table":"orderBookL2","action":"insert","data":[{"symbol":"ADAM21","id":52299997831,"side":"Sell","size":4300,"price":0.00002169}]}
1618677672.2035: {"table":"orderBookL2","action":"delete","data":[{"symbol":"ADAM21","id":52299997831,"side":"Sell"}]}
1618677672.221811: {"table":"orderBookL2","action":"insert","data":[{"symbol":"ADAM21","id":52299997831,"side":"Sell","size":4300,"price":0.00002169}]}
1618677672.238857: {"table":"orderBookL2","action":"delete","data":[{"symbol":"ADAM21","id":52299997831,"side":"Sell"}]}
1618677672.2485602: {"table":"orderBookL2","action":"delete","data":[{"symbol":"EOSM21","id":52499998733,"side":"Sell"}]}
1618677672.251789: {"table":"orderBookL2","action":"insert","data":[{"symbol":"ADAM21","id":52299997831,"side":"Sell","size":4300,"price":0.00002169}]}
1618677672.252335: {"table":"orderBookL2","action":"delete","data":[{"symbol":"XLMUSDT","id":52199939468,"side":"Buy"}]}
1618677672.261194: {"table":"orderBookL2","action":"update","data":[{"symbol":"EOSM21","id":52499998734,"side":"Buy","size":1200}]}
1618677672.267675: {"table":"orderBookL2","action":"insert","data":[{"symbol":"EOSM21","id":52499998733,"side":"Buy","size":330,"price":0.0001267}]}
1618677672.2677639: {"table":"orderBookL2","action":"delete","data":[{"symbol":"ADAM21","id":52299997831,"side":"Sell"}]}
1618677672.281653: {"table":"orderBookL2","action":"update","data":[{"symbol":"EOSM21","id":52499998732,"side":"Sell","size":652}]}
1618677672.2846599: {"table":"orderBookL2","action":"insert","data":[{"symbol":"ADAM21","id":52299997831,"side":"Sell","size":4300,"price":0.00002169}]}
1618677672.286548: {"table":"orderBookL2","action":"update","data":[{"symbol":"LTCUSD","id":40699968777,"side":"Buy","size":63}]}
1618677672.295933: {"table":"orderBookL2","action":"update","data":[{"symbol":"EOSM21","id":52499998743,"side":"Buy","size":6}]}
1618677672.296031: {"table":"orderBookL2","action":"insert","data":[{"symbol":"EOSM21","id":52499998747,"side":"Buy","size":979,"price":0.0001253}]}
1618677672.297976: {"table":"orderBookL2","action":"delete","data":[{"symbol":"EOSUSDT","id":53899984036,"side":"Sell"}]}
1618677672.298097: {"table":"orderBookL2","action":"insert","data":[{"symbol":"EOSUSDT","id":53899984017,"side":"Sell","size":496,"price":7.9915}]}
1618677672.301516: {"table":"orderBookL2","action":"delete","data":[{"symbol":"ADAM21","id":52299997831,"side":"Sell"}]}
1618677672.307342: {"table":"orderBookL2","action":"delete","data":[{"symbol":"LTCUSD","id":40699968211,"side":"Sell"},{"symbol":"LTCUSD","id":40699968431,"side":"Sell"},{"symbol":"LTCUSD","id":40699968540,"side":"Sell"},{"symbol":"LTCUSD","id":40699968648,"side":"Sell"},{"symbol":"LTCUSD","id":40699969231,"side":"Buy"}]}
1618677672.307508: {"table":"orderBookL2","action":"update","data":[{"symbol":"LTCUSD","id":40699968641,"side":"Sell","size":622},{"symbol":"LTCUSD","id":40699969027,"side":"Buy","size":2397},{"symbol":"LTCUSD","id":40699969058,"side":"Buy","size":10853},{"symbol":"LTCUSD","id":40699969222,"side":"Buy","size":2408}]}
1618677672.307575: {"table":"orderBookL2","action":"insert","data":[{"symbol":"LTCUSD","id":40699968203,"side":"Sell","size":580,"price":317.97},{"symbol":"LTCUSD","id":40699968422,"side":"Sell","size":580,"price":315.78},{"symbol":"LTCUSD","id":40699968532,"side":"Sell","size":580,"price":314.68}]}
1618677672.3154502: {"table":"orderBookL2","action":"insert","data":[{"symbol":"ADAM21","id":52299997831,"side":"Sell","size":4300,"price":0.00002169}]}
1618677672.332566: {"table":"orderBookL2","action":"delete","data":[{"symbol":"ADAM21","id":52299997831,"side":"Sell"}]}
1618677672.349134: {"table":"orderBookL2","action":"delete","data":[{"symbol":"EOSM21","id":52499998747,"side":"Buy"}]}
1618677672.349185: {"table":"orderBookL2","action":"update","data":[{"symbol":"EOSM21","id":52499998743,"side":"Buy","size":985}]}
1618677672.358655: {"table":"orderBookL2","action":"insert","data":[{"symbol":"XLMUSDT","id":52199939346,"side":"Buy","size":56,"price":0.60654}]}
1618677672.365485: {"table":"orderBookL2","action":"delete","data":[{"symbol":"DOGEUSDT","id":47599971486,"side":"Sell"}]}
1618677672.393712: {"table":"orderBookL2","action":"delete","data":[{"symbol":"LTCUSD","id":40699968203,"side":"Sell"},{"symbol":"LTCUSD","id":40699968422,"side":"Sell"},{"symbol":"LTCUSD","id":40699968532,"side":"Sell"}]}
1618677672.393855: {"table":"orderBookL2","action":"update","data":[{"symbol":"LTCUSD","id":40699968536,"side":"Sell","size":777},{"symbol":"LTCUSD","id":40699968641,"side":"Sell","size":42},{"symbol":"LTCUSD","id":40699968646,"side":"Sell","size":1265},{"symbol":"LTCUSD","id":40699969222,"side":"Buy","size":1828}]}
1618677672.393924: {"table":"orderBookL2","action":"insert","data":[{"symbol":"LTCUSD","id":40699968206,"side":"Sell","size":580,"price":317.94},{"symbol":"LTCUSD","id":40699968426,"side":"Sell","size":580,"price":315.74},{"symbol":"LTCUSD","id":40699969229,"side":"Buy","size":580,"price":307.71}]}
1618677672.394026: {"table":"orderBookL2","action":"insert","data":[{"symbol":"LTCUSD","id":40699968685,"side":"Sell","size":90,"price":313.15}]}
1618677672.3940558: {"table":"orderBookL2","action":"insert","data":[{"symbol":"LTCUSD","id":40699968758,"side":"Buy","size":90,"price":312.42}]}
1618677672.399172: {"table":"orderBookL2","action":"insert","data":[{"symbol":"DOGEUSDT","id":47599971666,"side":"Buy","size":350,"price":0.28334}]}
1618677672.40783: {"table":"orderBookL2","action":"delete","data":[{"symbol":"LTCUSD","id":40699968680,"side":"Sell"}]}
1618677672.419521: {"table":"orderBookL2","action":"delete","data":[{"symbol":"DOGEUSDT","id":47599971666,"side":"Buy"}]}
1618677672.466995: {"table":"orderBookL2","action":"delete","data":[{"symbol":"LTCUSD","id":40699968206,"side":"Sell"},{"symbol":"LTCUSD","id":40699968426,"side":"Sell"},{"symbol":"LTCUSD","id":40699969229,"side":"Buy"}]}
1618677672.467138: {"table":"orderBookL2","action":"insert","data":[{"symbol":"LTCUSD","id":40699968208,"side":"Sell","size":580,"price":317.92},{"symbol":"LTCUSD","id":40699968427,"side":"Sell","size":580,"price":315.73},{"symbol":"LTCUSD","id":40699969227,"side":"Buy","size":580,"price":307.73}]}
1618677672.469391: {"table":"orderBookL2","action":"delete","data":[{"symbol":"LTCUSD","id":40699968758,"side":"Buy"}]}
1618677672.4782012: {"table":"orderBookL2","action":"delete","data":[{"symbol":"XLMUSDT","id":52199939113,"side":"Sell"}]}
1618677672.50233: {"table":"orderBookL2","action":"delete","data":[{"symbol":"LTCUSD","id":40699968208,"side":"Sell"},{"symbol":"LTCUSD","id":40699968427,"side":"Sell"}]}
1618677672.503111: {"table":"orderBookL2","action":"update","data":[{"symbol":"LTCUSD","id":40699968536,"side":"Sell","size":197},{"symbol":"LTCUSD","id":40699968646,"side":"Sell","size":685}]}
1618677672.503196: {"table":"orderBookL2","action":"insert","data":[{"symbol":"LTCUSD","id":40699968203,"side":"Sell","size":580,"price":317.97},{"symbol":"LTCUSD","id":40699968423,"side":"Sell","size":580,"price":315.77},{"symbol":"LTCUSD","id":40699968533,"side":"Sell","size":580,"price":314.67},{"symbol":"LTCUSD","id":40699968643,"side":"Sell","size":580,"price":313.57}]}
1618677672.510009: {"table":"orderBookL2","action":"delete","data":[{"symbol":"LTCUSD","id":40699969227,"side":"Buy"}]}
1618677672.510468: {"table":"orderBookL2","action":"insert","data":[{"symbol":"LTCUSD","id":40699969225,"side":"Buy","size":580,"price":307.75}]}
1618677672.548427: {"table":"orderBookL2","action":"insert","data":[{"symbol":"LTCUSD","id":40699968773,"side":"Buy","size":247,"price":312.27}]}
1618677672.54915: {"table":"orderBookL2","action":"insert","data":[{"symbol":"DOGEUSDT","id":47599971523,"side":"Buy","size":53,"price":0.28477}]}
1618677672.57165: {"table":"orderBookL2","action":"delete","data":[{"symbol":"DOGEUSDT","id":47599971523,"side":"Buy"}]}
1618677672.575857: {"table":"orderBookL2","action":"delete","data":[{"symbol":"XLMUSDT","id":52199939346,"side":"Buy"}]}
1618677672.662024: {"table":"orderBookL2","action":"update","data":[{"symbol":"TRXM21","id":52999999767,"side":"Buy","size":219496}]}
1618677672.662122: {"table":"orderBookL2","action":"insert","data":[{"symbol":"LTCUSD","id":40699968693,"side":"Sell","size":236,"price":313.07}]}
1618677672.676596: {"table":"orderBookL2","action":"insert","data":[{"symbol":"XLMUSDT","id":52199939087,"side":"Sell","size":232,"price":0.60913}]}
1618677672.721248: {"table":"orderBookL2","action":"update","data":[{"symbol":"LTCUSD","id":40699968777,"side":"Buy","size":20}]}
1618677672.7213418: {"table":"orderBookL2","action":"insert","data":[{"symbol":"LTCUSD","id":40699968849,"side":"Buy","size":43,"price":311.51}]}
1618677672.8628852: {"table":"orderBookL2","action":"delete","data":[{"symbol":"DOGEUSDT","id":47599971776,"side":"Buy"}]}
1618677672.863005: {"table":"orderBookL2","action":"insert","data":[{"symbol":"DOGEUSDT","id":47599971762,"side":"Buy","size":154,"price":0.28238}]}
1618677672.884423: {"table":"orderBookL2","action":"delete","data":[{"symbol":"LINKUSDTM21","id":52799885896,"side":"Sell"}]}
1618677672.889473: {"table":"orderBookL2","action":"delete","data":[{"symbol":"LINKUSDTM21","id":52799885066,"side":"Sell"}]}
1618677672.889527: {"table":"orderBookL2","action":"insert","data":[{"symbol":"LINKUSDTM21","id":52799885006,"side":"Sell","size":330,"price":57.497}]}
1618677672.934716: {"table":"orderBookL2","action":"update","data":[{"symbol":"XLMUSDT","id":52199939139,"side":"Sell","size":456}]}
1618677672.945158: {"table":"orderBookL2","action":"delete","data":[{"symbol":"LTCUSD","id":40699968693,"side":"Sell"}]}
1618677672.945207: {"table":"orderBookL2","action":"insert","data":[{"symbol":"LTCUSD","id":40699968695,"side":"Sell","size":236,"price":313.05}]}
1618677672.953923: {"table":"orderBookL2","action":"insert","data":[{"symbol":"EOSUSDT","id":53899984074,"side":"Sell","size":70,"price":7.963}]}
1618677672.9549062: {"table":"orderBookL2","action":"insert","data":[{"symbol":"EOSUSDT","id":53899984148,"side":"Buy","size":70,"price":7.926}]}
1618677672.989006: {"table":"orderBookL2","action":"delete","data":[{"symbol":"LTCUSD","id":40699968600,"side":"Sell"}]}
1618677673.001801: {"table":"orderBookL2","action":"insert","data":[{"symbol":"LTCUSD","id":40699968756,"side":"Buy","size":731,"price":312.44}]}
1618677673.0018518: {"table":"orderBookL2","action":"insert","data":[{"symbol":"LTCUSD","id":40699968696,"side":"Sell","size":163,"price":313.04}]}
1618677673.004287: {"table":"orderBookL2","action":"delete","data":[{"symbol":"LTCUSD","id":40699968203,"side":"Sell"},{"symbol":"LTCUSD","id":40699968423,"side":"Sell"},{"symbol":"LTCUSD","id":40699968533,"side":"Sell"},{"symbol":"LTCUSD","id":40699968643,"side":"Sell"},{"symbol":"LTCUSD","id":40699969225,"side":"Buy"}]}
1618677673.0043561: {"table":"orderBookL2","action":"update","data":[{"symbol":"LTCUSD","id":40699969027,"side":"Buy","size":1817}]}
1618677673.004386: {"table":"orderBookL2","action":"insert","data":[{"symbol":"LTCUSD","id":40699968212,"side":"Sell","size":580,"price":317.88},{"symbol":"LTCUSD","id":40699968432,"side":"Sell","size":580,"price":315.68},{"symbol":"LTCUSD","id":40699968542,"side":"Sell","size":580,"price":314.58},{"symbol":"LTCUSD","id":40699968648,"side":"Sell","size":580,"price":313.52},{"symbol":"LTCUSD","id":40699969032,"side":"Buy","size":580,"price":309.68},{"symbol":"LTCUSD","id":40699969234,"side":"Buy","size":580,"price":307.66}]}
1618677673.044388: {"table":"orderBookL2","action":"insert","data":[{"symbol":"LTCUSD","id":40699968755,"side":"Buy","size":48,"price":312.45}]}
1618677673.0625122: {"table":"orderBookL2","action":"delete","data":[{"symbol":"LTCUSD","id":40699968694,"side":"Sell"}]}
1618677673.063193: {"table":"orderBookL2","action":"delete","data":[{"symbol":"LTCUSD","id":40699968212,"side":"Sell"},{"symbol":"LTCUSD","id":40699969032,"side":"Buy"},{"symbol":"LTCUSD","id":40699969234,"side":"Buy"}]}
1618677673.063251: {"table":"orderBookL2","action":"update","data":[{"symbol":"LTCUSD","id":40699968213,"side":"Sell","size":600}]}
1618677673.064805: {"table":"orderBookL2","action":"insert","data":[{"symbol":"LTCUSD","id":40699969030,"side":"Buy","size":580,"price":309.7},{"symbol":"LTCUSD","id":40699969233,"side":"Buy","size":580,"price":307.67}]}
1618677673.1297631: {"table":"orderBookL2","action":"delete","data":[{"symbol":"LTCUSD","id":40699969030,"side":"Buy"}]}
1618677673.129798: {"table":"orderBookL2","action":"insert","data":[{"symbol":"LTCUSD","id":40699969031,"side":"Buy","size":580,"price":309.69}]}
1618677673.152776: {"table":"orderBookL2","action":"update","data":[{"symbol":"EOSM21","id":52499998743,"side":"Buy","size":6}]}
1618677673.152818: {"table":"orderBookL2","action":"insert","data":[{"symbol":"EOSM21","id":52499998747,"side":"Buy","size":979,"price":0.0001253}]}
1618677673.259167: {"table":"orderBookL2","action":"update","data":[{"symbol":"LINKUSDTM21","id":52799886587,"side":"Buy","size":104}]}
1618677673.274705: {"table":"orderBookL2","action":"update","data":[{"symbol":"LTCM21","id":52899998948,"side":"Buy","size":215}]}
1618677673.276803: {"table":"orderBookL2","action":"update","data":[{"symbol":"LINKUSDTM21","id":52799885947,"side":"Sell","size":80}]}
1618677673.31317: {"table":"orderBookL2","action":"delete","data":[{"symbol":"LTCUSD","id":40699969031,"side":"Buy"}]}
1618677673.313209: {"table":"orderBookL2","action":"insert","data":[{"symbol":"LTCUSD","id":40699969030,"side":"Buy","size":580,"price":309.7}]}
1618677673.368188: {"table":"orderBookL2","action":"insert","data":[{"symbol":"LTCUSD","id":40699968697,"side":"Sell","size":125,"price":313.03}]}
1618677673.3855271: {"table":"orderBookL2","action":"delete","data":[{"symbol":"LTCUSD","id":40699968696,"side":"Sell"}]}
1618677673.385559: {"table":"orderBookL2","action":"insert","data":[{"symbol":"LTCUSD","id":40699968698,"side":"Sell","size":38,"price":313.02}]}
1618677673.421957: {"table":"orderBookL2","action":"delete","data":[{"symbol":"LTCUSD","id":40699968648,"side":"Sell"},{"symbol":"LTCUSD","id":40699969030,"side":"Buy"},{"symbol":"LTCUSD","id":40699969233,"side":"Buy"}]}
1618677673.4219992: {"table":"orderBookL2","action":"update","data":[{"symbol":"LTCUSD","id":40699968652,"side":"Sell","size":597}]}
1618677673.422016: {"table":"orderBookL2","action":"insert","data":[{"symbol":"LTCUSD","id":40699969032,"side":"Buy","size":580,"price":309.68},{"symbol":"LTCUSD","id":40699969234,"side":"Buy","size":580,"price":307.66}]}
1618677673.438828: {"table":"orderBookL2","action":"delete","data":[{"symbol":"LTCUSD","id":40699968432,"side":"Sell"},{"symbol":"LTCUSD","id":40699968542,"side":"Sell"},{"symbol":"LTCUSD","id":40699969032,"side":"Buy"},{"symbol":"LTCUSD","id":40699969234,"side":"Buy"}]}
1618677673.438878: {"table":"orderBookL2","action":"update","data":[{"symbol":"LTCUSD","id":40699968213,"side":"Sell","size":20}]}
1618677673.4388962: {"table":"orderBookL2","action":"insert","data":[{"symbol":"LTCUSD","id":40699968214,"side":"Sell","size":580,"price":317.86},{"symbol":"LTCUSD","id":40699968433,"side":"Sell","size":580,"price":315.67},{"symbol":"LTCUSD","id":40699968543,"side":"Sell","size":580,"price":314.57},{"symbol":"LTCUSD","id":40699969031,"side":"Buy","size":580,"price":309.69},{"symbol":"LTCUSD","id":40699969233,"side":"Buy","size":580,"price":307.67}]}
1618677673.48224: {"table":"orderBookL2","action":"delete","data":[{"symbol":"LTCUSD","id":40699968214,"side":"Sell"},{"symbol":"LTCUSD","id":40699968433,"side":"Sell"},{"symbol":"LTCUSD","id":40699968543,"side":"Sell"},{"symbol":"LTCUSD","id":40699969233,"side":"Buy"}]}
1618677673.4822981: {"table":"orderBookL2","action":"update","data":[{"symbol":"LTCUSD","id":40699968652,"side":"Sell","size":17}]}
1618677673.482316: {"table":"orderBookL2","action":"insert","data":[{"symbol":"LTCUSD","id":40699968212,"side":"Sell","size":580,"price":317.88},{"symbol":"LTCUSD","id":40699968432,"side":"Sell","size":580,"price":315.68},{"symbol":"LTCUSD","id":40699968542,"side":"Sell","size":580,"price":314.58},{"symbol":"LTCUSD","id":40699968648,"side":"Sell","size":580,"price":313.52},{"symbol":"LTCUSD","id":40699969234,"side":"Buy","size":580,"price":307.66}]}
1618677673.5154078: {"table":"orderBookL2","action":"insert","data":[{"symbol":"LTCUSD","id":40699968770,"side":"Buy","size":90,"price":312.3}]}
1618677673.608423: {"table":"orderBookL2","action":"insert","data":[{"symbol":"LINKUSDTM21","id":52799885862,"side":"Sell","size":4,"price":57.069}]}
1618677673.6123562: {"table":"orderBookL2","action":"update","data":[{"symbol":"TRXM21","id":52999999782,"side":"Buy","size":123525}]}
1618677673.6200588: {"table":"orderBookL2","action":"delete","data":[{"symbol":"EOSUSDT","id":53899984017,"side":"Sell"}]}
1618677673.620111: {"table":"orderBookL2","action":"insert","data":[{"symbol":"EOSUSDT","id":53899984036,"side":"Sell","size":496,"price":7.982}]}
1618677673.6641788: {"table":"orderBookL2","action":"insert","data":[{"symbol":"LTCUSD","id":40699968618,"side":"Sell","size":4,"price":313.82}]}
1618677673.719197: {"table":"orderBookL2","action":"delete","data":[{"symbol":"LTCUSD","id":40699968212,"side":"Sell"},{"symbol":"LTCUSD","id":40699968432,"side":"Sell"},{"symbol":"LTCUSD","id":40699968542,"side":"Sell"},{"symbol":"LTCUSD","id":40699969031,"side":"Buy"},{"symbol":"LTCUSD","id":40699969234,"side":"Buy"}]}
1618677673.7192729: {"table":"orderBookL2","action":"insert","data":[{"symbol":"LTCUSD","id":40699968210,"side":"Sell","size":580,"price":317.9},{"symbol":"LTCUSD","id":40699968429,"side":"Sell","size":580,"price":315.71},{"symbol":"LTCUSD","id":40699968539,"side":"Sell","size":580,"price":314.61},{"symbol":"LTCUSD","id":40699969028,"side":"Buy","size":580,"price":309.72},{"symbol":"LTCUSD","id":40699969230,"side":"Buy","size":580,"price":307.7}]}
1618677673.749237: {"table":"orderBookL2","action":"delete","data":[{"symbol":"DOGEUSDT","id":47599971846,"side":"Buy"}]}
1618677673.749295: {"table":"orderBookL2","action":"insert","data":[{"symbol":"DOGEUSDT","id":47599971799,"side":"Buy","size":176,"price":0.28201}]}
1618677673.763783: {"table":"orderBookL2","action":"update","data":[{"symbol":"LTCUSD","id":40699968668,"side":"Sell","size":302}]}
1618677673.763813: {"table":"orderBookL2","action":"insert","data":[{"symbol":"LTCUSD","id":40699968682,"side":"Sell","size":218,"price":313.18}]}
1618677674.019383: {"table":"orderBookL2","action":"delete","data":[{"symbol":"XLMUSDT","id":52199939412,"side":"Buy"}]}
1618677674.0194829: {"table":"orderBookL2","action":"delete","data":[{"symbol":"XLMUSDT","id":52199939385,"side":"Buy"}]}
1618677674.034632: {"table":"orderBookL2","action":"insert","data":[{"symbol":"EOSUSDT","id":53899984156,"side":"Buy","size":76,"price":7.922}]}
1618677674.0347211: {"table":"orderBookL2","action":"delete","data":[{"symbol":"EOSUSDT","id":53899984148,"side":"Buy"}]}
1618677674.053996: {"table":"orderBookL2","action":"insert","data":[{"symbol":"LTCUSD","id":40699968699,"side":"Sell","size":452,"price":313.01}]}
1618677674.057226: {"table":"orderBookL2","action":"delete","data":[{"symbol":"LTCUSD","id":40699968755,"side":"Buy"}]}
1618677674.057292: {"table":"orderBookL2","action":"delete","data":[{"symbol":"LTCUSD","id":40699968210,"side":"Sell"},{"symbol":"LTCUSD","id":40699968429,"side":"Sell"},{"symbol":"LTCUSD","id":40699968539,"side":"Sell"},{"symbol":"LTCUSD","id":40699969028,"side":"Buy"},{"symbol":"LTCUSD","id":40699969230,"side":"Buy"}]}
1618677674.057355: {"table":"orderBookL2","action":"insert","data":[{"symbol":"LTCUSD","id":40699968211,"side":"Sell","size":580,"price":317.89},{"symbol":"LTCUSD","id":40699968431,"side":"Sell","size":580,"price":315.69},{"symbol":"LTCUSD","id":40699968541,"side":"Sell","size":580,"price":314.59},{"symbol":"LTCUSD","id":40699969031,"side":"Buy","size":580,"price":309.69},{"symbol":"LTCUSD","id":40699969234,"side":"Buy","size":580,"price":307.66}]}
1618677674.068775: {"table":"orderBookL2","action":"delete","data":[{"symbol":"LTCUSD","id":40699968698,"side":"Sell"}]}
1618677674.0983858: {"table":"orderBookL2","action":"delete","data":[{"symbol":"LTCUSD","id":40699968211,"side":"Sell"},{"symbol":"LTCUSD","id":40699968431,"side":"Sell"},{"symbol":"LTCUSD","id":40699968541,"side":"Sell"},{"symbol":"LTCUSD","id":40699968648,"side":"Sell"},{"symbol":"LTCUSD","id":40699969031,"side":"Buy"}]}
1618677674.098526: {"table":"orderBookL2","action":"update","data":[{"symbol":"LTCUSD","id":40699968213,"side":"Sell","size":600},{"symbol":"LTCUSD","id":40699968652,"side":"Sell","size":597}]}
1618677674.0985842: {"table":"orderBookL2","action":"insert","data":[{"symbol":"LTCUSD","id":40699968433,"side":"Sell","size":580,"price":315.67},{"symbol":"LTCUSD","id":40699968543,"side":"Sell","size":580,"price":314.57},{"symbol":"LTCUSD","id":40699969032,"side":"Buy","size":580,"price":309.68}]}
1618677674.176805: {"table":"orderBookL2","action":"delete","data":[{"symbol":"LTCUSD","id":40699968433,"side":"Sell"},{"symbol":"LTCUSD","id":40699968543,"side":"Sell"},{"symbol":"LTCUSD","id":40699969032,"side":"Buy"},{"symbol":"LTCUSD","id":40699969234,"side":"Buy"}]}
1618677674.1769578: {"table":"orderBookL2","action":"update","data":[{"symbol":"LTCUSD","id":40699968213,"side":"Sell","size":20}]}
1618677674.177011: {"table":"orderBookL2","action":"insert","data":[{"symbol":"LTCUSD","id":40699968215,"side":"Sell","size":580,"price":317.85},{"symbol":"LTCUSD","id":40699968434,"side":"Sell","size":580,"price":315.66},{"symbol":"LTCUSD","id":40699968544,"side":"Sell","size":580,"price":314.56},{"symbol":"LTCUSD","id":40699969033,"side":"Buy","size":580,"price":309.67},{"symbol":"LTCUSD","id":40699969235,"side":"Buy","size":580,"price":307.65}]}
1618677674.186628: {"table":"orderBookL2","action":"update","data":[{"symbol":"LTCUSD","id":40699970700,"side":"Buy","size":500}]}
1618677674.252875: {"table":"orderBookL2","action":"delete","data":[{"symbol":"LTCUSD","id":40699969033,"side":"Buy"}]}
1618677674.2529762: {"table":"orderBookL2","action":"insert","data":[{"symbol":"LTCUSD","id":40699969032,"side":"Buy","size":580,"price":309.68}]}
1618677674.2549329: {"table":"orderBookL2","action":"delete","data":[{"symbol":"LTCUSD","id":40699968215,"side":"Sell"}]}
1618677674.2550201: {"table":"orderBookL2","action":"insert","data":[{"symbol":"LTCUSD","id":40699968214,"side":"Sell","size":580,"price":317.86}]}
1618677674.260519: {"table":"orderBookL2","action":"delete","data":[{"symbol":"LTCUSD","id":40699968434,"side":"Sell"},{"symbol":"LTCUSD","id":40699968544,"side":"Sell"},{"symbol":"LTCUSD","id":40699969235,"side":"Buy"}]}
1618677674.260632: {"table":"orderBookL2","action":"insert","data":[{"symbol":"LTCUSD","id":40699968433,"side":"Sell","size":580,"price":315.67},{"symbol":"LTCUSD","id":40699968543,"side":"Sell","size":580,"price":314.57},{"symbol":"LTCUSD","id":40699969234,"side":"Buy","size":580,"price":307.66}]}
1618677674.267714: {"table":"orderBookL2","action":"delete","data":[{"symbol":"LTCUSD","id":40699968695,"side":"Sell"}]}
1618677674.267801: {"table":"orderBookL2","action":"insert","data":[{"symbol":"LTCUSD","id":40699968700,"side":"Sell","size":236,"price":313}]}
1618677674.281607: {"table":"orderBookL2","action":"update","data":[{"symbol":"LTCUSD","id":40699968700,"side":"Sell","size":489}]}
1618677674.2847428: {"table":"orderBookL2","action":"delete","data":[{"symbol":"LTCUSD","id":40699968636,"side":"Sell"}]}
1618677674.300883: {"table":"orderBookL2","action":"delete","data":[{"symbol":"LTCUSD","id":40699971594,"side":"Buy"}]}
1618677674.40065: {"table":"orderBookL2","action":"update","data":[{"symbol":"LTCUSD","id":40699968700,"side":"Sell","size":253}]}
1618677674.438139: {"table":"orderBookL2","action":"delete","data":[{"symbol":"LTCUSD","id":40699968214,"side":"Sell"},{"symbol":"LTCUSD","id":40699968433,"side":"Sell"},{"symbol":"LTCUSD","id":40699968543,"side":"Sell"},{"symbol":"LTCUSD","id":40699969032,"side":"Buy"},{"symbol":"LTCUSD","id":40699969234,"side":"Buy"}]}
1618677674.438315: {"table":"orderBookL2","action":"update","data":[{"symbol":"LTCUSD","id":40699968430,"side":"Sell","size":588},{"symbol":"LTCUSD","id":40699968652,"side":"Sell","size":17}]}
1618677674.438376: {"table":"orderBookL2","action":"insert","data":[{"symbol":"LTCUSD","id":40699968210,"side":"Sell","size":580,"price":317.9},{"symbol":"LTCUSD","id":40699968539,"side":"Sell","size":580,"price":314.61},{"symbol":"LTCUSD","id":40699968648,"side":"Sell","size":580,"price":313.52},{"symbol":"LTCUSD","id":40699969028,"side":"Buy","size":580,"price":309.72},{"symbol":"LTCUSD","id":40699969230,"side":"Buy","size":580,"price":307.7}]}
1618677674.535806: {"table":"orderBookL2","action":"insert","data":[{"symbol":"LTCUSD","id":40699971594,"side":"Buy","size":920,"price":284.06}]}
1618677674.5692108: {"table":"orderBookL2","action":"delete","data":[{"symbol":"LTCUSD","id":40699968697,"side":"Sell"}]}
1618677674.569332: {"table":"orderBookL2","action":"update","data":[{"symbol":"LTCUSD","id":40699968700,"side":"Sell","size":378}]}
1618677674.585077: {"table":"orderBookL2","action":"insert","data":[{"symbol":"LTCUSD","id":40699968689,"side":"Sell","size":236,"price":313.11}]}
1618677674.616471: {"table":"orderBookL2","action":"update","data":[{"symbol":"TRXM21","id":52999999704,"side":"Sell","size":131558}]}
1618677674.6287072: {"table":"orderBookL2","action":"update","data":[{"symbol":"LTCUSD","id":40699968700,"side":"Sell","size":253}]}
1618677674.646797: {"table":"orderBookL2","action":"delete","data":[{"symbol":"DOGEUSDT","id":47599971762,"side":"Buy"}]}
1618677674.64689: {"table":"orderBookL2","action":"insert","data":[{"symbol":"DOGEUSDT","id":47599971778,"side":"Buy","size":154,"price":0.28222}]}
1618677674.6533089: {"table":"orderBookL2","action":"delete","data":[{"symbol":"DOGEUSDT","id":47599971799,"side":"Buy"}]}
1618677674.653397: {"table":"orderBookL2","action":"insert","data":[{"symbol":"DOGEUSDT","id":47599971841,"side":"Buy","size":206,"price":0.28159}]}
1618677674.7768672: {"table":"orderBookL2","action":"insert","data":[{"symbol":"LTCUSD","id":40699968755,"side":"Buy","size":1,"price":312.45}]}
1618677674.942645: {"table":"orderBookL2","action":"update","data":[{"symbol":"LTCUSD","id":40699970700,"side":"Buy","size":1415}]}
1618677675.021309: {"table":"orderBookL2","action":"update","data":[{"symbol":"TRXM21","id":52999999763,"side":"Buy","size":174609},{"symbol":"TRXM21","id":52999999768,"side":"Buy","size":118373}]}
1618677675.0317981: {"table":"orderBookL2","action":"update","data":[{"symbol":"ADAM21","id":52299997836,"side":"Buy","size":35514}]}
1618677675.068491: {"table":"orderBookL2","action":"update","data":[{"symbol":"TRXM21","id":52999999757,"side":"Sell","size":3538589}]}
1618677675.148476: {"table":"orderBookL2","action":"delete","data":[{"symbol":"LTCUSD","id":40699968699,"side":"Sell"}]}
1618677675.14859: {"table":"orderBookL2","action":"insert","data":[{"symbol":"LTCUSD","id":40699968701,"side":"Sell","size":452,"price":312.99}]}
1618677675.1919832: {"table":"orderBookL2","action":"update","data":[{"symbol":"TRXM21","id":52999999763,"side":"Buy","size":125144},{"symbol":"TRXM21","id":52999999769,"side":"Buy","size":506095}]}
1618677675.487421: {"table":"orderBookL2","action":"delete","data":[{"symbol":"DOGEUSDT","id":47599971547,"side":"Buy"}]}
1618677675.487502: {"table":"orderBookL2","action":"delete","data":[{"symbol":"DOGEUSDT","id":47599971688,"side":"Buy"},{"symbol":"DOGEUSDT","id":47599971689,"side":"Buy"},{"symbol":"DOGEUSDT","id":47599971690,"side":"Buy"},{"symbol":"DOGEUSDT","id":47599971691,"side":"Buy"},{"symbol":"DOGEUSDT","id":47599971692,"side":"Buy"}]}
1618677675.4875588: {"table":"orderBookL2","action":"update","data":[{"symbol":"DOGEUSDT","id":47599971385,"side":"Sell","size":63}]}
1618677675.487587: {"table":"orderBookL2","action":"insert","data":[{"symbol":"DOGEUSDT","id":47599971456,"side":"Sell","size":300,"price":0.28544}]}
1618677675.487627: {"table":"orderBookL2","action":"insert","data":[{"symbol":"DOGEUSDT","id":47599971580,"side":"Buy","size":4000,"price":0.2842}]}
1618677675.487655: {"table":"orderBookL2","action":"delete","data":[{"symbol":"DOGEUSDT","id":47599971737,"side":"Buy"}]}
1618677675.487678: {"table":"orderBookL2","action":"insert","data":[{"symbol":"DOGEUSDT","id":47599971763,"side":"Buy","size":100,"price":0.28237},{"symbol":"DOGEUSDT","id":47599971764,"side":"Buy","size":100,"price":0.28236},{"symbol":"DOGEUSDT","id":47599971765,"side":"Buy","size":100,"price":0.28235},{"symbol":"DOGEUSDT","id":47599971766,"side":"Buy","size":100,"price":0.28234},{"symbol":"DOGEUSDT","id":47599971767,"side":"Buy","size":100,"price":0.28233}]}
1618677675.4877372: {"table":"orderBookL2","action":"delete","data":[{"symbol":"DOGEUSDT","id":47599971455,"side":"Sell"}]}
1618677675.487762: {"table":"orderBookL2","action":"delete","data":[{"symbol":"LTCUSD","id":40699968210,"side":"Sell"},{"symbol":"LTCUSD","id":40699968539,"side":"Sell"},{"symbol":"LTCUSD","id":40699968648,"side":"Sell"},{"symbol":"LTCUSD","id":40699969028,"side":"Buy"},{"symbol":"LTCUSD","id":40699969230,"side":"Buy"}]}
1618677675.487818: {"table":"orderBookL2","action":"update","data":[{"symbol":"LTCUSD","id":40699968430,"side":"Sell","size":8}]}
1618677675.487839: {"table":"orderBookL2","action":"insert","data":[{"symbol":"LTCUSD","id":40699968205,"side":"Sell","size":580,"price":317.95},{"symbol":"LTCUSD","id":40699968424,"side":"Sell","size":580,"price":315.76},{"symbol":"LTCUSD","id":40699968534,"side":"Sell","size":580,"price":314.66},{"symbol":"LTCUSD","id":40699968643,"side":"Sell","size":580,"price":313.57},{"symbol":"LTCUSD","id":40699969022,"side":"Buy","size":580,"price":309.78},{"symbol":"LTCUSD","id":40699969224,"side":"Buy","size":580,"price":307.76}]}
1618677675.487904: {"table":"orderBookL2","action":"insert","data":[{"symbol":"LINKUSDTM21","id":52799885911,"side":"Sell","size":4,"price":57.0445}]}
1618677675.4879339: {"table":"orderBookL2","action":"insert","data":[{"symbol":"LINKUSDTM21","id":52799886635,"side":"Buy","size":4,"price":56.6825}]}
1618677675.48796: {"table":"orderBookL2","action":"delete","data":[{"symbol":"DOGEUSDT","id":47599971580,"side":"Buy"}]}
1618677675.4880462: {"table":"orderBookL2","action":"delete","data":[{"symbol":"DOGEUSDT","id":47599971524,"side":"Buy"}]}
1618677675.488634: {"table":"orderBookL2","action":"insert","data":[{"symbol":"XLMUSDT","id":52199939393,"side":"Buy","size":50,"price":0.60607}]}
1618677675.488696: {"table":"orderBookL2","action":"insert","data":[{"symbol":"DOGEUSDT","id":47599971502,"side":"Sell","size":250,"price":0.28498}]}
1618677675.503819: {"table":"orderBookL2","action":"delete","data":[{"symbol":"DOGEUSDT","id":47599971501,"side":"Sell"}]}
1618677675.5038788: {"table":"orderBookL2","action":"insert","data":[{"symbol":"DOGEUSDT","id":47599971503,"side":"Sell","size":300,"price":0.28497}]}
1618677675.515529: {"table":"orderBookL2","action":"delete","data":[{"symbol":"EOSUSDT","id":53899984156,"side":"Buy"}]}
1618677675.5371368: {"table":"orderBookL2","action":"delete","data":[{"symbol":"DOGEUSDT","id":47599971808,"side":"Buy"}]}
1618677675.53725: {"table":"orderBookL2","action":"insert","data":[{"symbol":"DOGEUSDT","id":47599971800,"side":"Buy","size":2110,"price":0.282}]}
1618677675.586355: {"table":"orderBookL2","action":"delete","data":[{"symbol":"DOGEUSDT","id":47599970109,"side":"Sell"},{"symbol":"DOGEUSDT","id":47599970251,"side":"Sell"},{"symbol":"DOGEUSDT","id":47599970394,"side":"Sell"},{"symbol":"DOGEUSDT","id":47599970536,"side":"Sell"},{"symbol":"DOGEUSDT","id":47599970678,"side":"Sell"},{"symbol":"DOGEUSDT","id":47599970820,"side":"Sell"},{"symbol":"DOGEUSDT","id":47599971104,"side":"Sell"},{"symbol":"DOGEUSDT","id":47599971246,"side":"Sell"},{"symbol":"DOGEUSDT","id":47599971388,"side":"Sell"},{"symbol":"DOGEUSDT","id":47599971675,"side":"Buy"},{"symbol":"DOGEUSDT","id":47599971755,"side":"Buy"},{"symbol":"DOGEUSDT","id":47599971898,"side":"Buy"},{"symbol":"DOGEUSDT","id":47599972040,"side":"Buy"},{"symbol":"DOGEUSDT","id":47599972182,"side":"Buy"},{"symbol":"DOGEUSDT","id":47599972324,"side":"Buy"},{"symbol":"DOGEUSDT","id":47599972466,"side":"Buy"},{"symbol":"DOGEUSDT","id":47599972608,"side":"Buy"},{"symbol":"DOGEUSDT","id":47599972750,"side":"Buy"},{"symbol":"DOGEUSDT","id":47599972892,"side":"Buy"}]}
1618677675.586613: {"table":"orderBookL2","action":"update","data":[{"symbol":"DOGEUSDT","id":47599970962,"side":"Sell","size":12438},{"symbol":"DOGEUSDT","id":47599971159,"side":"Sell","size":2267}]}
1618677675.586671: {"table":"orderBookL2","action":"insert","data":[{"symbol":"DOGEUSDT","id":47599970162,"side":"Sell","size":126,"price":0.29838},{"symbol":"DOGEUSDT","id":47599970304,"side":"Sell","size":126,"price":0.29696},{"symbol":"DOGEUSDT","id":47599970446,"side":"Sell","size":126,"price":0.29554},{"symbol":"DOGEUSDT","id":47599970589,"side":"Sell","size":126,"price":0.29411},{"symbol":"DOGEUSDT","id":47599970731,"side":"Sell","size":110,"price":0.29269},{"symbol":"DOGEUSDT","id":47599970874,"side":"Sell","size":90,"price":0.29126},{"symbol":"DOGEUSDT","id":47599971016,"side":"Sell","size":70,"price":0.28984},{"symbol":"DOGEUSDT","id":47599971301,"side":"Sell","size":37,"price":0.28699},{"symbol":"DOGEUSDT","id":47599971444,"side":"Sell","size":37,"price":0.28556},{"symbol":"DOGEUSDT","id":47599971668,"side":"Buy","size":37,"price":0.28332},{"symbol":"DOGEUSDT","id":47599971811,"side":"Buy","size":44,"price":0.28189},{"symbol":"DOGEUSDT","id":47599971953,"side":"Buy","size":75,"price":0.28047},{"symbol":"DOGEUSDT","id":47599972095,"side":"Buy","size":107,"price":0.27905},{"symbol":"DOGEUSDT","id":47599972238,"side":"Buy","size":140,"price":0.27762},{"symbol":"DOGEUSDT","id":47599972380,"side":"Buy","size":172,"price":0.2762},{"symbol":"DOGEUSDT","id":47599972523,"side":"Buy","size":186,"price":0.27477},{"symbol":"DOGEUSDT","id":47599972665,"side":"Buy","size":186,"price":0.27335},{"symbol":"DOGEUSDT","id":47599972808,"side":"Buy","size":186,"price":0.27192},{"symbol":"DOGEUSDT","id":47599972950,"side":"Buy","size":186,"price":0.2705}]}
1618677675.6667461: {"table":"orderBookL2","action":"delete","data":[{"symbol":"DOGEUSDT","id":47599971778,"side":"Buy"}]}
1618677675.666862: {"table":"orderBookL2","action":"insert","data":[{"symbol":"DOGEUSDT","id":47599971808,"side":"Buy","size":154,"price":0.28192}]}
1618677675.680053: {"table":"orderBookL2","action":"insert","data":[{"symbol":"DOGEUSDT","id":47599971504,"side":"Sell","size":1659,"price":0.28496}]}
1618677675.7153978: {"table":"orderBookL2","action":"delete","data":[{"symbol":"DOGEUSDT","id":47599971818,"side":"Buy"}]}
1618677675.715486: {"table":"orderBookL2","action":"update","data":[{"symbol":"DOGEUSDT","id":47599972086,"side":"Buy","size":13753}]}
1618677675.7261598: {"table":"orderBookL2","action":"delete","data":[{"symbol":"EOSM21","id":52499998709,"side":"Sell"}]}
1618677675.72625: {"table":"orderBookL2","action":"update","data":[{"symbol":"EOSM21","id":52499998697,"side":"Sell","size":5543},{"symbol":"EOSM21","id":52499998699,"side":"Sell","size":4998},{"symbol":"EOSM21","id":52499998704,"side":"Sell","size":3899},{"symbol":"EOSM21","id":52499998764,"side":"Buy","size":3119},{"symbol":"EOSM21","id":52499998772,"side":"Buy","size":8463},{"symbol":"EOSM21","id":52499998784,"side":"Buy","size":5458}]}
1618677675.726325: {"table":"orderBookL2","action":"insert","data":[{"symbol":"EOSM21","id":52499998757,"side":"Buy","size":3119,"price":0.0001243}]}
1618677675.76862: {"table":"orderBookL2","action":"delete","data":[{"symbol":"LTCUSD","id":40699968682,"side":"Sell"}]}
1618677675.873606: {"table":"orderBookL2","action":"delete","data":[{"symbol":"DOGEUSDT","id":47599971841,"side":"Buy"}]}
1618677675.873729: {"table":"orderBookL2","action":"insert","data":[{"symbol":"DOGEUSDT","id":47599972145,"side":"Buy","size":297,"price":0.27855}]}
1618677675.8921118: {"table":"orderBookL2","action":"delete","data":[{"symbol":"DOGEUSDT","id":47599971808,"side":"Buy"}]}
1618677675.8922071: {"table":"orderBookL2","action":"insert","data":[{"symbol":"DOGEUSDT","id":47599971883,"side":"Buy","size":154,"price":0.28117}]}
1618677675.947256: {"table":"orderBookL2","action":"delete","data":[{"symbol":"DOGEUSDT","id":47599971456,"side":"Sell"}]}
1618677675.947371: {"table":"orderBookL2","action":"insert","data":[{"symbol":"DOGEUSDT","id":47599971505,"side":"Sell","size":300,"price":0.28495}]}
1618677675.9502761: {"table":"orderBookL2","action":"delete","data":[{"symbol":"DOGEUSDT","id":47599971763,"side":"Buy"},{"symbol":"DOGEUSDT","id":47599971764,"side":"Buy"},{"symbol":"DOGEUSDT","id":47599971765,"side":"Buy"},{"symbol":"DOGEUSDT","id":47599971766,"side":"Buy"},{"symbol":"DOGEUSDT","id":47599971767,"side":"Buy"}]}
1618677675.9599411: {"table":"orderBookL2","action":"delete","data":[{"symbol":"DOGEUSDT","id":47599971504,"side":"Sell"}]}
1618677675.960041: {"table":"orderBookL2","action":"insert","data":[{"symbol":"DOGEUSDT","id":47599971506,"side":"Sell","size":1659,"price":0.28494}]}
1618677675.96556: {"table":"orderBookL2","action":"delete","data":[{"symbol":"DOGEUSDT","id":47599971886,"side":"Buy"}]}
1618677675.965646: {"table":"orderBookL2","action":"insert","data":[{"symbol":"DOGEUSDT","id":47599971942,"side":"Buy","size":207,"price":0.28058}]}
1618677675.967943: {"table":"orderBookL2","action":"insert","data":[{"symbol":"DOGEUSDT","id":47599971839,"side":"Buy","size":100,"price":0.28161},{"symbol":"DOGEUSDT","id":47599971840,"side":"Buy","size":100,"price":0.2816},{"symbol":"DOGEUSDT","id":47599971841,"side":"Buy","size":100,"price":0.28159},{"symbol":"DOGEUSDT","id":47599971842,"side":"Buy","size":100,"price":0.28158},{"symbol":"DOGEUSDT","id":47599971843,"side":"Buy","size":100,"price":0.28157}]}
1618677675.978019: {"table":"orderBookL2","action":"delete","data":[{"symbol":"DOGEUSDT","id":47599971944,"side":"Buy"}]}
1618677675.978103: {"table":"orderBookL2","action":"update","data":[{"symbol":"DOGEUSDT","id":47599971919,"side":"Buy","size":4094}]}
1618677675.9976692: {"table":"orderBookL2","action":"delete","data":[{"symbol":"LTCUSD","id":40699968687,"side":"Sell"}]}
1618677676.082121: {"table":"orderBookL2","action":"insert","data":[{"symbol":"LTCUSD","id":40699968659,"side":"Sell","size":105,"price":313.41}]}
1618677676.084513: {"table":"orderBookL2","action":"delete","data":[{"symbol":"LTCUSD","id":40699968674,"side":"Sell"}]}
1618677676.084607: {"table":"orderBookL2","action":"insert","data":[{"symbol":"LTCUSD","id":40699968671,"side":"Sell","size":218,"price":313.29}]}
1618677676.084673: {"table":"orderBookL2","action":"delete","data":[{"symbol":"LTCUSD","id":40699968838,"side":"Buy"}]}
1618677676.085612: {"table":"orderBookL2","action":"insert","data":[{"symbol":"LTCUSD","id":40699968823,"side":"Buy","size":106,"price":311.77}]}
1618677676.0963452: {"table":"orderBookL2","action":"delete","data":[{"symbol":"LTCUSD","id":40699968701,"side":"Sell"}]}
1618677676.099726: {"table":"orderBookL2","action":"insert","data":[{"symbol":"LTCUSD","id":40699968754,"side":"Buy","size":48,"price":312.46}]}
1618677676.099823: {"table":"orderBookL2","action":"delete","data":[{"symbol":"LINKUSDTM21","id":52799885911,"side":"Sell"}]}
1618677676.1207628: {"table":"orderBookL2","action":"insert","data":[{"symbol":"LTCUSD","id":40699968753,"side":"Buy","size":1,"price":312.47}]}
1618677676.1208708: {"table":"orderBookL2","action":"delete","data":[{"symbol":"LTCUSD","id":40699968689,"side":"Sell"}]}
1618677676.1221828: {"table":"orderBookL2","action":"delete","data":[{"symbol":"LTCUSD","id":40699968755,"side":"Buy"}]}
1618677676.131626: {"table":"orderBookL2","action":"delete","data":[{"symbol":"LTCUSD","id":40699968754,"side":"Buy"}]}
1618677676.133848: {"table":"orderBookL2","action":"insert","data":[{"symbol":"LTCUSD","id":40699968701,"side":"Sell","size":452,"price":312.99}]}
1618677676.136802: {"table":"orderBookL2","action":"update","data":[{"symbol":"LTCUSD","id":40699968684,"side":"Sell","size":492}]}
1618677676.145448: {"table":"orderBookL2","action":"insert","data":[{"symbol":"EOSUSDT","id":53899984085,"side":"Sell","size":77,"price":7.9575}]}
1618677676.1462421: {"table":"orderBookL2","action":"delete","data":[{"symbol":"LTCUSD","id":40699968700,"side":"Sell"}]}
1618677676.149269: {"table":"orderBookL2","action":"insert","data":[{"symbol":"EOSUSDT","id":53899984158,"side":"Buy","size":77,"price":7.921}]}
1618677676.1725838: {"table":"orderBookL2","action":"insert","data":[{"symbol":"LTCUSD","id":40699968686,"side":"Sell","size":125,"price":313.14},{"symbol":"LTCUSD","id":40699968755,"side":"Buy","size":125,"price":312.45}]}
1618677676.175955: {"table":"orderBookL2","action":"delete","data":[{"symbol":"DOGEUSDT","id":47599970162,"side":"Sell"},{"symbol":"DOGEUSDT","id":47599970304,"side":"Sell"},{"symbol":"DOGEUSDT","id":47599970446,"side":"Sell"},{"symbol":"DOGEUSDT","id":47599970589,"side":"Sell"},{"symbol":"DOGEUSDT","id":47599970731,"side":"Sell"},{"symbol":"DOGEUSDT","id":47599970874,"side":"Sell"},{"symbol":"DOGEUSDT","id":47599971016,"side":"Sell"},{"symbol":"DOGEUSDT","id":47599971301,"side":"Sell"},{"symbol":"DOGEUSDT","id":47599971444,"side":"Sell"},{"symbol":"DOGEUSDT","id":47599971668,"side":"Buy"},{"symbol":"DOGEUSDT","id":47599971811,"side":"Buy"},{"symbol":"DOGEUSDT","id":47599971953,"side":"Buy"},{"symbol":"DOGEUSDT","id":47599972095,"side":"Buy"},{"symbol":"DOGEUSDT","id":47599972238,"side":"Buy"},{"symbol":"DOGEUSDT","id":47599972380,"side":"Buy"},{"symbol":"DOGEUSDT","id":47599972523,"side":"Buy"},{"symbol":"DOGEUSDT","id":47599972665,"side":"Buy"},{"symbol":"DOGEUSDT","id":47599972808,"side":"Buy"},{"symbol":"DOGEUSDT","id":47599972950,"side":"Buy"}]}
1618677676.176213: {"table":"orderBookL2","action":"update","data":[{"symbol":"DOGEUSDT","id":47599971159,"side":"Sell","size":2218},{"symbol":"DOGEUSDT","id":47599971503,"side":"Sell","size":337}]}
1618677676.17627: {"table":"orderBookL2","action":"insert","data":[{"symbol":"DOGEUSDT","id":47599970224,"side":"Sell","size":126,"price":0.29776},{"symbol":"DOGEUSDT","id":47599970366,"side":"Sell","size":126,"price":0.29634},{"symbol":"DOGEUSDT","id":47599970508,"side":"Sell","size":126,"price":0.29492},{"symbol":"DOGEUSDT","id":47599970651,"side":"Sell","size":126,"price":0.29349},{"symbol":"DOGEUSDT","id":47599970793,"side":"Sell","size":110,"price":0.29207},{"symbol":"DOGEUSDT","id":47599970935,"side":"Sell","size":90,"price":0.29065},{"symbol":"DOGEUSDT","id":47599971077,"side":"Sell","size":70,"price":0.28923},{"symbol":"DOGEUSDT","id":47599971219,"side":"Sell","size":49,"price":0.28781},{"symbol":"DOGEUSDT","id":47599971361,"side":"Sell","size":37,"price":0.28639},{"symbol":"DOGEUSDT","id":47599971727,"side":"Buy","size":37,"price":0.28273},{"symbol":"DOGEUSDT","id":47599971869,"side":"Buy","size":44,"price":0.28131},{"symbol":"DOGEUSDT","id":47599972011,"side":"Buy","size":75,"price":0.27989},{"symbol":"DOGEUSDT","id":47599972153,"side":"Buy","size":108,"price":0.27847},{"symbol":"DOGEUSDT","id":47599972295,"side":"Buy","size":140,"price":0.27705},{"symbol":"DOGEUSDT","id":47599972437,"side":"Buy","size":173,"price":0.27563},{"symbol":"DOGEUSDT","id":47599972579,"side":"Buy","size":186,"price":0.27421},{"symbol":"DOGEUSDT","id":47599972721,"side":"Buy","size":186,"price":0.27279},{"symbol":"DOGEUSDT","id":47599972864,"side":"Buy","size":186,"price":0.27136},{"symbol":"DOGEUSDT","id":47599973006,"side":"Buy","size":186,"price":0.26994}]}
1618677676.19192: {"table":"orderBookL2","action":"delete","data":[{"symbol":"DOGEUSDT","id":47599971738,"side":"Buy"},{"symbol":"DOGEUSDT","id":47599971757,"side":"Buy"}]}
1618677676.192035: {"table":"orderBookL2","action":"update","data":[{"symbol":"DOGEUSDT","id":47599971840,"side":"Buy","size":494}]}
1618677676.192084: {"table":"orderBookL2","action":"insert","data":[{"symbol":"DOGEUSDT","id":47599971882,"side":"Buy","size":1179,"price":0.28118}]}
1618677676.197184: {"table":"orderBookL2","action":"delete","data":[{"symbol":"DOGEUSDT","id":47599971883,"side":"Buy"}]}
1618677676.197272: {"table":"orderBookL2","action":"insert","data":[{"symbol":"DOGEUSDT","id":47599971909,"side":"Buy","size":154,"price":0.28091}]}
1618677676.2159019: {"table":"orderBookL2","action":"delete","data":[{"symbol":"LTCUSD","id":40699968685,"side":"Sell"}]}
1618677676.259743: {"table":"orderBookL2","action":"update","data":[{"symbol":"DOGEUSDT","id":47599971919,"side":"Buy","size":3917}]}
1618677676.25984: {"table":"orderBookL2","action":"insert","data":[{"symbol":"DOGEUSDT","id":47599971971,"side":"Buy","size":207,"price":0.28029}]}
1618677676.2994719: {"table":"orderBookL2","action":"delete","data":[{"symbol":"LTCUSD","id":40699968679,"side":"Sell"}]}
1618677676.299573: {"table":"orderBookL2","action":"update","data":[{"symbol":"LTCUSD","id":40699968655,"side":"Sell","size":400}]}
1618677676.3071628: {"table":"orderBookL2","action":"insert","data":[{"symbol":"LTCUSD","id":40699968689,"side":"Sell","size":247,"price":313.11}]}
1618677676.3103502: {"table":"orderBookL2","action":"delete","data":[{"symbol":"LTCUSD","id":40699968671,"side":"Sell"}]}
1618677676.3263638: {"table":"orderBookL2","action":"delete","data":[{"symbol":"DOGEUSDT","id":47599972993,"side":"Buy"}]}
1618677676.337034: {"table":"orderBookL2","action":"delete","data":[{"symbol":"LTCUSD","id":40699968689,"side":"Sell"}]}
1618677676.35311: {"table":"orderBookL2","action":"delete","data":[{"symbol":"LTCUSD","id":40699968824,"side":"Buy"}]}
1618677676.353226: {"table":"orderBookL2","action":"update","data":[{"symbol":"LTCUSD","id":40699968777,"side":"Buy","size":153}]}
1618677676.384109: {"table":"orderBookL2","action":"update","data":[{"symbol":"TRXM21","id":52999999763,"side":"Buy","size":174609},{"symbol":"TRXM21","id":52999999769,"side":"Buy","size":456630}]}
1618677676.402117: {"table":"orderBookL2","action":"delete","data":[{"symbol":"DOGEUSDT","id":47599971971,"side":"Buy"}]}
1618677676.404236: {"table":"orderBookL2","action":"delete","data":[{"symbol":"DOGEUSDT","id":47599971942,"side":"Buy"}]}
1618677676.4687319: {"table":"orderBookL2","action":"insert","data":[{"symbol":"XLMUSDT","id":52199939364,"side":"Buy","size":45,"price":0.60636}]}
1618677676.4739509: {"table":"orderBookL2","action":"delete","data":[{"symbol":"DOGEUSDT","id":47599971909,"side":"Buy"}]}
1618677676.47404: {"table":"orderBookL2","action":"insert","data":[{"symbol":"DOGEUSDT","id":47599971933,"side":"Buy","size":154,"price":0.28067}]}
1618677676.4755259: {"table":"orderBookL2","action":"delete","data":[{"symbol":"EOSM21","id":52499998747,"side":"Buy"}]}
1618677676.4756448: {"table":"orderBookL2","action":"update","data":[{"symbol":"EOSM21","id":52499998743,"side":"Buy","size":985}]}
1618677676.475696: {"table":"orderBookL2","action":"delete","data":[{"symbol":"DOGEUSDT","id":47599971505,"side":"Sell"}]}
1618677676.476702: {"table":"orderBookL2","action":"insert","data":[{"symbol":"DOGEUSDT","id":47599971507,"side":"Sell","size":300,"price":0.28493}]}
1618677676.476817: {"table":"orderBookL2","action":"delete","data":[{"symbol":"EOSUSDT","id":53899984085,"side":"Sell"}]}
1618677676.478935: {"table":"orderBookL2","action":"update","data":[{"symbol":"EOSUSDT","id":53899984151,"side":"Buy","size":1069}]}
1618677676.488677: {"table":"orderBookL2","action":"delete","data":[{"symbol":"DOGEUSDT","id":47599971506,"side":"Sell"}]}
1618677676.4887738: {"table":"orderBookL2","action":"insert","data":[{"symbol":"DOGEUSDT","id":47599971504,"side":"Sell","size":1659,"price":0.28496}]}
1618677676.492519: {"table":"orderBookL2","action":"insert","data":[{"symbol":"DOGEUSDT","id":47599971594,"side":"Sell","size":248,"price":0.28406},{"symbol":"DOGEUSDT","id":47599971686,"side":"Buy","size":4000,"price":0.28314}]}
1618677676.507593: {"table":"orderBookL2","action":"update","data":[{"symbol":"DOGEUSDT","id":47599971385,"side":"Sell","size":13},{"symbol":"DOGEUSDT","id":47599971507,"side":"Sell","size":350}]}
1618677676.523941: {"table":"orderBookL2","action":"update","data":[{"symbol":"DOGEUSDT","id":47599971503,"side":"Sell","size":37}]}
1618677676.524014: {"table":"orderBookL2","action":"insert","data":[{"symbol":"DOGEUSDT","id":47599971595,"side":"Sell","size":208,"price":0.28405}]}
1618677676.524653: {"table":"orderBookL2","action":"delete","data":[{"symbol":"DOGEUSDT","id":47599971595,"side":"Sell"}]}
1618677676.537197: {"table":"orderBookL2","action":"delete","data":[{"symbol":"LTCUSD","id":40699968778,"side":"Buy"}]}
1618677676.5372548: {"table":"orderBookL2","action":"update","data":[{"symbol":"LTCUSD","id":40699968756,"side":"Buy","size":967}]}
1618677676.6148689: {"table":"orderBookL2","action":"delete","data":[{"symbol":"DOGEUSDT","id":47599971502,"side":"Sell"}]}
1618677676.61499: {"table":"orderBookL2","action":"delete","data":[{"symbol":"DOGEUSDT","id":47599971504,"side":"Sell"}]}
1618677676.615042: {"table":"orderBookL2","action":"insert","data":[{"symbol":"DOGEUSDT","id":47599971508,"side":"Sell","size":1659,"price":0.28492}]}
1618677676.6391082: {"table":"orderBookL2","action":"update","data":[{"symbol":"DOGEUSDT","id":47599971507,"side":"Sell","size":50}]}
1618677676.699393: {"table":"orderBookL2","action":"delete","data":[{"symbol":"DOGEUSDT","id":47599971508,"side":"Sell"}]}
1618677676.69951: {"table":"orderBookL2","action":"insert","data":[{"symbol":"DOGEUSDT","id":47599971595,"side":"Sell","size":150,"price":0.28405}]}
1618677676.762681: {"table":"orderBookL2","action":"update","data":[{"symbol":"TRXM21","id":52999999757,"side":"Sell","size":3549769}]}
1618677676.895025: {"table":"orderBookL2","action":"update","data":[{"symbol":"EOSUSDT","id":53899984151,"side":"Buy","size":1000}]}
1618677676.9730592: {"table":"orderBookL2","action":"delete","data":[{"symbol":"DOGEUSDT","id":47599971933,"side":"Buy"}]}
1618677676.973175: {"table":"orderBookL2","action":"insert","data":[{"symbol":"DOGEUSDT","id":47599971958,"side":"Buy","size":154,"price":0.28042}]}
1618677676.973808: {"table":"orderBookL2","action":"update","data":[{"symbol":"LTCM21","id":52899998966,"side":"Buy","size":147},{"symbol":"LTCM21","id":52899998976,"side":"Buy","size":555}]}
1618677676.992059: {"table":"orderBookL2","action":"insert","data":[{"symbol":"DOGEUSDT","id":47599971596,"side":"Sell","size":349,"price":0.28404}]}
1618677676.999655: {"table":"orderBookL2","action":"update","data":[{"symbol":"DOGEUSDT","id":47599971595,"side":"Sell","size":50}]}
1618677677.0219321: {"table":"orderBookL2","action":"delete","data":[{"symbol":"DOGEUSDT","id":47599971594,"side":"Sell"}]}
1618677677.060616: {"table":"orderBookL2","action":"update","data":[{"symbol":"LTCUSD","id":40699968701,"side":"Sell","size":432}]}
1618677677.063489: {"table":"orderBookL2","action":"delete","data":[{"symbol":"DOGEUSDT","id":47599971686,"side":"Buy"}]}
1618677677.072119: {"table":"orderBookL2","action":"update","data":[{"symbol":"LTCUSD","id":40699968756,"side":"Buy","size":731}]}
1618677677.0775821: {"table":"orderBookL2","action":"delete","data":[{"symbol":"LTCUSD","id":40699968701,"side":"Sell"}]}
1618677677.0776682: {"table":"orderBookL2","action":"insert","data":[{"symbol":"LTCUSD","id":40699968702,"side":"Sell","size":432,"price":312.98}]}
1618677677.086006: {"table":"orderBookL2","action":"delete","data":[{"symbol":"DOGEUSDT","id":47599971596,"side":"Sell"}]}
1618677677.0925472: {"table":"orderBookL2","action":"insert","data":[{"symbol":"LTCUSD","id":40699968703,"side":"Sell","size":102,"price":312.97}]}
1618677677.092641: {"table":"orderBookL2","action":"update","data":[{"symbol":"LTCUSD","id":40699968684,"side":"Sell","size":256}]}
1618677677.092685: {"table":"orderBookL2","action":"insert","data":[{"symbol":"LTCUSD","id":40699968687,"side":"Sell","size":236,"price":313.13}]}
1618677677.093194: {"table":"orderBookL2","action":"update","data":[{"symbol":"LTCUSD","id":40699968753,"side":"Buy","size":203}]}
1618677677.097617: {"table":"orderBookL2","action":"delete","data":[{"symbol":"LTCUSD","id":40699968703,"side":"Sell"}]}
1618677677.098419: {"table":"orderBookL2","action":"update","data":[{"symbol":"DOGEUSDT","id":47599971385,"side":"Sell","size":313}]}
1618677677.118093: {"table":"orderBookL2","action":"delete","data":[{"symbol":"LTCUSD","id":40699968755,"side":"Buy"}]}
1618677677.118179: {"table":"orderBookL2","action":"insert","data":[{"symbol":"LTCUSD","id":40699968752,"side":"Buy","size":125,"price":312.48}]}
1618677677.122116: {"table":"orderBookL2","action":"delete","data":[{"symbol":"DOGEUSDT","id":47599971595,"side":"Sell"}]}
1618677677.1222138: {"table":"orderBookL2","action":"insert","data":[{"symbol":"DOGEUSDT","id":47599971597,"side":"Sell","size":50,"price":0.28403}]}
1618677677.1328309: {"table":"orderBookL2","action":"insert","data":[{"symbol":"LTCUSD","id":40699968751,"side":"Buy","size":1,"price":312.49}]}
1618677677.138379: {"table":"orderBookL2","action":"update","data":[{"symbol":"LTCUSD","id":40699968753,"side":"Buy","size":202}]}
1618677677.17456: {"table":"orderBookL2","action":"delete","data":[{"symbol":"DOGEUSDT","id":47599971919,"side":"Buy"}]}
1618677677.175315: {"table":"orderBookL2","action":"insert","data":[{"symbol":"DOGEUSDT","id":47599972076,"side":"Buy","size":3917,"price":0.27924}]}
1618677677.179957: {"table":"orderBookL2","action":"update","data":[{"symbol":"LTCUSD","id":40699968655,"side":"Sell","size":295}]}
1618677677.1800299: {"table":"orderBookL2","action":"insert","data":[{"symbol":"LTCUSD","id":40699968688,"side":"Sell","size":105,"price":313.12}]}
1618677677.1857011: {"table":"orderBookL2","action":"delete","data":[{"symbol":"LTCUSD","id":40699968798,"side":"Buy"}]}
1618677677.185816: {"table":"orderBookL2","action":"insert","data":[{"symbol":"LTCUSD","id":40699968763,"side":"Buy","size":104,"price":312.37}]}
1618677677.1927722: {"table":"orderBookL2","action":"delete","data":[{"symbol":"DOGEUSDT","id":47599971839,"side":"Buy"},{"symbol":"DOGEUSDT","id":47599971841,"side":"Buy"},{"symbol":"DOGEUSDT","id":47599971842,"side":"Buy"},{"symbol":"DOGEUSDT","id":47599971843,"side":"Buy"}]}
1618677677.19286: {"table":"orderBookL2","action":"update","data":[{"symbol":"DOGEUSDT","id":47599971840,"side":"Buy","size":394}]}
1618677677.19696: {"table":"orderBookL2","action":"delete","data":[{"symbol":"DOGEUSDT","id":47599971958,"side":"Buy"}]}
1618677677.197016: {"table":"orderBookL2","action":"insert","data":[{"symbol":"DOGEUSDT","id":47599971930,"side":"Buy","size":154,"price":0.2807}]}
1618677677.211495: {"table":"orderBookL2","action":"update","data":[{"symbol":"DOGEUSDT","id":47599971930,"side":"Buy","size":736}]}
1618677677.2115688: {"table":"orderBookL2","action":"insert","data":[{"symbol":"DOGEUSDT","id":47599971929,"side":"Buy","size":582,"price":0.28071},{"symbol":"DOGEUSDT","id":47599971931,"side":"Buy","size":582,"price":0.28069}]}
1618677677.227485: {"table":"orderBookL2","action":"insert","data":[{"symbol":"DOGEUSDT","id":47599971807,"side":"Buy","size":100,"price":0.28193},{"symbol":"DOGEUSDT","id":47599971808,"side":"Buy","size":100,"price":0.28192},{"symbol":"DOGEUSDT","id":47599971809,"side":"Buy","size":100,"price":0.28191},{"symbol":"DOGEUSDT","id":47599971810,"side":"Buy","size":100,"price":0.2819},{"symbol":"DOGEUSDT","id":47599971811,"side":"Buy","size":100,"price":0.28189}]}
1618677677.2401762: {"table":"orderBookL2","action":"delete","data":[{"symbol":"DOGEUSDT","id":47599971597,"side":"Sell"}]}
1618677677.240234: {"table":"orderBookL2","action":"insert","data":[{"symbol":"DOGEUSDT","id":47599971508,"side":"Sell","size":50,"price":0.28492}]}
1618677677.247514: {"table":"orderBookL2","action":"delete","data":[{"symbol":"DOGEUSDT","id":47599971929,"side":"Buy"},{"symbol":"DOGEUSDT","id":47599971931,"side":"Buy"}]}
1618677677.2475789: {"table":"orderBookL2","action":"update","data":[{"symbol":"DOGEUSDT","id":47599971930,"side":"Buy","size":154}]}
1618677677.29568: {"table":"orderBookL2","action":"insert","data":[{"symbol":"LTCUSD","id":40699968672,"side":"Sell","size":218,"price":313.28}]}
1618677677.3303308: {"table":"orderBookL2","action":"delete","data":[{"symbol":"XLMUSDT","id":52199939364,"side":"Buy"}]}
1618677677.3637602: {"table":"orderBookL2","action":"delete","data":[{"symbol":"DOGEUSDT","id":47599971508,"side":"Sell"}]}
1618677677.392237: {"table":"orderBookL2","action":"delete","data":[{"symbol":"DOGEUSDT","id":47599971800,"side":"Buy"}]}
1618677677.392341: {"table":"orderBookL2","action":"insert","data":[{"symbol":"DOGEUSDT","id":47599971796,"side":"Buy","size":2110,"price":0.28204}]}
1618677677.4029288: {"table":"orderBookL2","action":"delete","data":[{"symbol":"DOGEUSDT","id":47599971507,"side":"Sell"}]}
1618677677.403019: {"table":"orderBookL2","action":"update","data":[{"symbol":"DOGEUSDT","id":47599971385,"side":"Sell","size":363}]}
1618677677.500462: {"table":"orderBookL2","action":"insert","data":[{"symbol":"DOGEUSDT","id":47599971794,"side":"Buy","size":352,"price":0.28206}]}
1618677677.507762: {"table":"orderBookL2","action":"insert","data":[{"symbol":"DOGEUSDT","id":47599971508,"side":"Sell","size":1658,"price":0.28492}]}
1618677677.510976: {"table":"orderBookL2","action":"delete","data":[{"symbol":"XLMUSDT","id":52199939137,"side":"Sell"}]}
1618677677.527248: {"table":"orderBookL2","action":"delete","data":[{"symbol":"XLMUSDT","id":52199939139,"side":"Sell"}]}
1618677677.527334: {"table":"orderBookL2","action":"insert","data":[{"symbol":"XLMUSDT","id":52199939140,"side":"Sell","size":178,"price":0.6086}]}
1618677677.527403: {"table":"orderBookL2","action":"update","data":[{"symbol":"DOGEUSDT","id":47599971385,"side":"Sell","size":63}]}
1618677677.527443: {"table":"orderBookL2","action":"insert","data":[{"symbol":"DOGEUSDT","id":47599971509,"side":"Sell","size":300,"price":0.28491}]}
1618677677.527849: {"table":"orderBookL2","action":"insert","data":[{"symbol":"XLMUSDT","id":52199939102,"side":"Sell","size":500,"price":0.60898}]}
1618677677.542808: {"table":"orderBookL2","action":"delete","data":[{"symbol":"XLMUSDT","id":52199939140,"side":"Sell"}]}
1618677677.546304: {"table":"orderBookL2","action":"insert","data":[{"symbol":"XLMUSDT","id":52199939057,"side":"Sell","size":67,"price":0.60943}]}
1618677677.552742: {"table":"orderBookL2","action":"insert","data":[{"symbol":"XLMUSDT","id":52199939139,"side":"Sell","size":178,"price":0.60861}]}
1618677677.559123: {"table":"orderBookL2","action":"delete","data":[{"symbol":"XLMUSDT","id":52199939139,"side":"Sell"}]}
1618677677.678308: {"table":"orderBookL2","action":"delete","data":[{"symbol":"LTCUSD","id":40699968205,"side":"Sell"},{"symbol":"LTCUSD","id":40699968424,"side":"Sell"},{"symbol":"LTCUSD","id":40699968534,"side":"Sell"},{"symbol":"LTCUSD","id":40699968643,"side":"Sell"},{"symbol":"LTCUSD","id":40699969022,"side":"Buy"},{"symbol":"LTCUSD","id":40699969224,"side":"Buy"}]}
1618677677.678427: {"table":"orderBookL2","action":"update","data":[{"symbol":"LTCUSD","id":40699968948,"side":"Buy","size":2728},{"symbol":"LTCUSD","id":40699969222,"side":"Buy","size":2407}]}
1618677677.6784651: {"table":"orderBookL2","action":"insert","data":[{"symbol":"LTCUSD","id":40699968200,"side":"Sell","size":579,"price":318},{"symbol":"LTCUSD","id":40699968420,"side":"Sell","size":579,"price":315.8},{"symbol":"LTCUSD","id":40699968530,"side":"Sell","size":579,"price":314.7},{"symbol":"LTCUSD","id":40699968619,"side":"Sell","size":579,"price":313.81},{"symbol":"LTCUSD","id":40699969019,"side":"Buy","size":579,"price":309.81}]}
1618677677.678537: {"table":"orderBookL2","action":"delete","data":[{"symbol":"DOGEUSDT","id":47599971508,"side":"Sell"}]}
1618677677.678569: {"table":"orderBookL2","action":"insert","data":[{"symbol":"DOGEUSDT","id":47599971504,"side":"Sell","size":1659,"price":0.28496}]}
1618677677.678598: {"table":"orderBookL2","action":"delete","data":[{"symbol":"LINKUSDTM21","id":52799885365,"side":"Sell"}]}
1618677677.678626: {"table":"orderBookL2","action":"insert","data":[{"symbol":"LINKUSDTM21","id":52799885329,"side":"Sell","size":6,"price":57.3355}]}
1618677677.681032: {"table":"orderBookL2","action":"delete","data":[{"symbol":"DOGEUSDT","id":47599971509,"side":"Sell"}]}
1618677677.687397: {"table":"orderBookL2","action":"update","data":[{"symbol":"LTCUSD","id":40699968751,"side":"Buy","size":248}]}
1618677677.693669: {"table":"orderBookL2","action":"delete","data":[{"symbol":"LTCUSD","id":40699968200,"side":"Sell"},{"symbol":"LTCUSD","id":40699968420,"side":"Sell"},{"symbol":"LTCUSD","id":40699968530,"side":"Sell"},{"symbol":"LTCUSD","id":40699969019,"side":"Buy"}]}
1618677677.693748: {"table":"orderBookL2","action":"update","data":[{"symbol":"LTCUSD","id":40699968197,"side":"Sell","size":2348},{"symbol":"LTCUSD","id":40699969222,"side":"Buy","size":1828}]}
1618677677.693783: {"table":"orderBookL2","action":"insert","data":[{"symbol":"LTCUSD","id":40699968417,"side":"Sell","size":579,"price":315.83},{"symbol":"LTCUSD","id":40699968528,"side":"Sell","size":579,"price":314.72},{"symbol":"LTCUSD","id":40699969018,"side":"Buy","size":579,"price":309.82},{"symbol":"LTCUSD","id":40699969221,"side":"Buy","size":579,"price":307.79}]}
1618677677.702506: {"table":"orderBookL2","action":"delete","data":[{"symbol":"LTCUSD","id":40699968687,"side":"Sell"}]}
1618677677.7705832: {"table":"orderBookL2","action":"delete","data":[{"symbol":"DOGEUSDT","id":47599971794,"side":"Buy"}]}
1618677677.775263: {"table":"orderBookL2","action":"insert","data":[{"symbol":"LTCUSD","id":40699968755,"side":"Buy","size":236,"price":312.45}]}
1618677677.7908192: {"table":"orderBookL2","action":"delete","data":[{"symbol":"LTCUSD","id":40699968417,"side":"Sell"},{"symbol":"LTCUSD","id":40699968528,"side":"Sell"},{"symbol":"LTCUSD","id":40699969018,"side":"Buy"},{"symbol":"LTCUSD","id":40699969221,"side":"Buy"}]}
1618677677.7909389: {"table":"orderBookL2","action":"update","data":[{"symbol":"LTCUSD","id":40699968197,"side":"Sell","size":1769}]}
1618677677.7909892: {"table":"orderBookL2","action":"insert","data":[{"symbol":"LTCUSD","id":40699968196,"side":"Sell","size":579,"price":318.04},{"symbol":"LTCUSD","id":40699968416,"side":"Sell","size":579,"price":315.84},{"symbol":"LTCUSD","id":40699968525,"side":"Sell","size":579,"price":314.75},{"symbol":"LTCUSD","id":40699969015,"side":"Buy","size":579,"price":309.85},{"symbol":"LTCUSD","id":40699969218,"side":"Buy","size":579,"price":307.82}]}
1618677677.79755: {"table":"orderBookL2","action":"delete","data":[{"symbol":"LTCUSD","id":40699968756,"side":"Buy"}]}
1618677677.797641: {"table":"orderBookL2","action":"insert","data":[{"symbol":"LTCUSD","id":40699968750,"side":"Buy","size":404,"price":312.5}]}
1618677677.80672: {"table":"orderBookL2","action":"insert","data":[{"symbol":"LTCUSD","id":40699968749,"side":"Buy","size":1,"price":312.51}]}
1618677677.809549: {"table":"orderBookL2","action":"update","data":[{"symbol":"LTCUSD","id":40699968751,"side":"Buy","size":247}]}
1618677677.8315341: {"table":"orderBookL2","action":"delete","data":[{"symbol":"LTCUSD","id":40699968686,"side":"Sell"}]}
1618677677.838243: {"table":"orderBookL2","action":"delete","data":[{"symbol":"DOGEUSDT","id":47599971504,"side":"Sell"}]}
1618677677.838336: {"table":"orderBookL2","action":"insert","data":[{"symbol":"DOGEUSDT","id":47599971510,"side":"Sell","size":1658,"price":0.2849}]}
1618677677.972327: {"table":"orderBookL2","action":"delete","data":[{"symbol":"LTCUSD","id":40699968755,"side":"Buy"}]}
1618677677.991095: {"table":"orderBookL2","action":"delete","data":[{"symbol":"LTCUSD","id":40699968751,"side":"Buy"}]}
1618677677.991186: {"table":"orderBookL2","action":"update","data":[{"symbol":"LTCUSD","id":40699968749,"side":"Buy","size":248}]}
1618677678.011057: {"table":"orderBookL2","action":"delete","data":[{"symbol":"DOGEUSDT","id":47599971510,"side":"Sell"}]}
1618677678.0111449: {"table":"orderBookL2","action":"insert","data":[{"symbol":"DOGEUSDT","id":47599971504,"side":"Sell","size":1659,"price":0.28496}]}
1618677678.017756: {"table":"orderBookL2","action":"delete","data":[{"symbol":"LTCUSD","id":40699968196,"side":"Sell"},{"symbol":"LTCUSD","id":40699968416,"side":"Sell"}]}
1618677678.017857: {"table":"orderBookL2","action":"insert","data":[{"symbol":"LTCUSD","id":40699968195,"side":"Sell","size":579,"price":318.05},{"symbol":"LTCUSD","id":40699968415,"side":"Sell","size":579,"price":315.85}]}
1618677678.033612: {"table":"orderBookL2","action":"insert","data":[{"symbol":"LTCM21","id":52899998947,"side":"Buy","size":15,"price":0.005265}]}
1618677678.038721: {"table":"orderBookL2","action":"insert","data":[{"symbol":"DOGEUSDT","id":47599971505,"side":"Sell","size":300,"price":0.28495}]}
1618677678.06339: {"table":"orderBookL2","action":"insert","data":[{"symbol":"XLMUSDT","id":52199939368,"side":"Buy","size":60,"price":0.60632}]}
1618677678.121081: {"table":"orderBookL2","action":"update","data":[{"symbol":"LTCUSD","id":40699968749,"side":"Buy","size":247}]}
1618677678.127421: {"table":"orderBookL2","action":"insert","data":[{"symbol":"LTCUSD","id":40699968748,"side":"Buy","size":68,"price":312.52}]}
1618677678.1275148: {"table":"orderBookL2","action":"update","data":[{"symbol":"LTCUSD","id":40699968684,"side":"Sell","size":492}]}
1618677678.141902: {"table":"orderBookL2","action":"update","data":[{"symbol":"LTCUSD","id":40699968777,"side":"Buy","size":133}]}
1618677678.1464682: {"table":"orderBookL2","action":"delete","data":[{"symbol":"LTCUSD","id":40699968702,"side":"Sell"}]}
1618677678.156374: {"table":"orderBookL2","action":"update","data":[{"symbol":"LTCUSD","id":40699968678,"side":"Sell","size":286}]}
1618677678.159615: {"table":"orderBookL2","action":"update","data":[{"symbol":"LTCUSD","id":40699968752,"side":"Buy","size":145}]}
1618677678.1698601: {"table":"orderBookL2","action":"update","data":[{"symbol":"TRXM21","id":52999999763,"side":"Buy","size":125144},{"symbol":"TRXM21","id":52999999769,"side":"Buy","size":506095}]}
1618677678.2022378: {"table":"orderBookL2","action":"delete","data":[{"symbol":"DOGEUSDT","id":47599971504,"side":"Sell"}]}
1618677678.202326: {"table":"orderBookL2","action":"insert","data":[{"symbol":"DOGEUSDT","id":47599971506,"side":"Sell","size":1659,"price":0.28494}]}
1618677678.223614: {"table":"orderBookL2","action":"delete","data":[{"symbol":"DOGEUSDT","id":47599971505,"side":"Sell"}]}
1618677678.232069: {"table":"orderBookL2","action":"insert","data":[{"symbol":"DOGEUSDT","id":47599971507,"side":"Sell","size":300,"price":0.28493}]}
1618677678.347241: {"table":"orderBookL2","action":"update","data":[{"symbol":"DOGEUSDT","id":47599971385,"side":"Sell","size":13}]}
1618677678.347324: {"table":"orderBookL2","action":"insert","data":[{"symbol":"DOGEUSDT","id":47599971505,"side":"Sell","size":50,"price":0.28495}]}
1618677678.396839: {"table":"orderBookL2","action":"delete","data":[{"symbol":"DOGEUSDT","id":47599971506,"side":"Sell"}]}
1618677678.3969269: {"table":"orderBookL2","action":"insert","data":[{"symbol":"DOGEUSDT","id":47599971508,"side":"Sell","size":1658,"price":0.28492}]}
1618677678.399883: {"table":"orderBookL2","action":"insert","data":[{"symbol":"LTCUSD","id":40699968676,"side":"Sell","size":538,"price":313.24}]}
1618677678.399982: {"table":"orderBookL2","action":"delete","data":[{"symbol":"LTCUSD","id":40699968195,"side":"Sell"},{"symbol":"LTCUSD","id":40699969015,"side":"Buy"},{"symbol":"LTCUSD","id":40699969218,"side":"Buy"}]}
1618677678.405618: {"table":"orderBookL2","action":"insert","data":[{"symbol":"LTCUSD","id":40699968194,"side":"Sell","size":579,"price":318.06},{"symbol":"LTCUSD","id":40699969017,"side":"Buy","size":579,"price":309.83},{"symbol":"LTCUSD","id":40699969220,"side":"Buy","size":579,"price":307.8}]}
1618677678.413332: {"table":"orderBookL2","action":"delete","data":[{"symbol":"XLMUSDT","id":52199939368,"side":"Buy"}]}
1618677678.431127: {"table":"orderBookL2","action":"delete","data":[{"symbol":"DOGEUSDT","id":47599971507,"side":"Sell"}]}
1618677678.440108: {"table":"orderBookL2","action":"insert","data":[{"symbol":"DOGEUSDT","id":47599971509,"side":"Sell","size":300,"price":0.28491}]}
1618677678.455195: {"table":"orderBookL2","action":"update","data":[{"symbol":"TRXM21","id":52999999763,"side":"Buy","size":174609},{"symbol":"TRXM21","id":52999999769,"side":"Buy","size":456630}]}
1618677678.460394: {"table":"orderBookL2","action":"insert","data":[{"symbol":"LTCUSD","id":40699968685,"side":"Sell","size":90,"price":313.15}]}
1618677678.4781902: {"table":"orderBookL2","action":"update","data":[{"symbol":"LTCUSD","id":40699968684,"side":"Sell","size":256},{"symbol":"LTCUSD","id":40699968685,"side":"Sell","size":326}]}
1618677678.4970188: {"table":"orderBookL2","action":"delete","data":[{"symbol":"LTCUSD","id":40699968194,"side":"Sell"},{"symbol":"LTCUSD","id":40699968415,"side":"Sell"},{"symbol":"LTCUSD","id":40699968525,"side":"Sell"}]}
1618677678.4971268: {"table":"orderBookL2","action":"update","data":[{"symbol":"LTCUSD","id":40699968197,"side":"Sell","size":2348}]}
1618677678.497175: {"table":"orderBookL2","action":"insert","data":[{"symbol":"LTCUSD","id":40699968417,"side":"Sell","size":579,"price":315.83},{"symbol":"LTCUSD","id":40699968527,"side":"Sell","size":579,"price":314.73}]}
1618677678.548949: {"table":"orderBookL2","action":"delete","data":[{"symbol":"LTCUSD","id":40699968672,"side":"Sell"}]}
1618677678.60961: {"table":"orderBookL2","action":"delete","data":[{"symbol":"DOGEUSDT","id":47599971508,"side":"Sell"}]}
1618677678.609726: {"table":"orderBookL2","action":"insert","data":[{"symbol":"DOGEUSDT","id":47599971510,"side":"Sell","size":1658,"price":0.2849}]}
1618677678.6212502: {"table":"orderBookL2","action":"delete","data":[{"symbol":"DOGEUSDT","id":47599971509,"side":"Sell"}]}
1618677678.6382148: {"table":"orderBookL2","action":"insert","data":[{"symbol":"DOGEUSDT","id":47599971511,"side":"Sell","size":300,"price":0.28489}]}
1618677678.6673338: {"table":"orderBookL2","action":"update","data":[{"symbol":"LTCUSD","id":40699968685,"side":"Sell","size":236}]}
1618677678.746311: {"table":"orderBookL2","action":"delete","data":[{"symbol":"LTCUSD","id":40699968685,"side":"Sell"}]}
1618677678.790206: {"table":"orderBookL2","action":"insert","data":[{"symbol":"LTCUSD","id":40699968756,"side":"Buy","size":236,"price":312.44}]}
1618677678.8571332: {"table":"orderBookL2","action":"delete","data":[{"symbol":"DOGEUSDT","id":47599971510,"side":"Sell"}]}
1618677678.857236: {"table":"orderBookL2","action":"insert","data":[{"symbol":"DOGEUSDT","id":47599971512,"side":"Sell","size":1658,"price":0.28488}]}
1618677678.872243: {"table":"orderBookL2","action":"delete","data":[{"symbol":"DOGEUSDT","id":47599971511,"side":"Sell"}]}
1618677678.884039: {"table":"orderBookL2","action":"insert","data":[{"symbol":"DOGEUSDT","id":47599971513,"side":"Sell","size":300,"price":0.28487}]}
1618677678.946938: {"table":"orderBookL2","action":"update","data":[{"symbol":"LTCUSD","id":40699968678,"side":"Sell","size":39}]}
1618677679.096338: {"table":"orderBookL2","action":"insert","data":[{"symbol":"DOGEUSDT","id":47599971589,"side":"Sell","size":248,"price":0.28411},{"symbol":"DOGEUSDT","id":47599971685,"side":"Buy","size":4000,"price":0.28315}]}
1618677679.1080709: {"table":"orderBookL2","action":"delete","data":[{"symbol":"DOGEUSDT","id":47599971796,"side":"Buy"}]}
1618677679.1081622: {"table":"orderBookL2","action":"insert","data":[{"symbol":"DOGEUSDT","id":47599971792,"side":"Buy","size":2110,"price":0.28208}]}
1618677679.112163: {"table":"orderBookL2","action":"delete","data":[{"symbol":"XLMUSDT","id":52199939393,"side":"Buy"}]}
1618677679.123877: {"table":"orderBookL2","action":"insert","data":[{"symbol":"EOSUSDT","id":53899984090,"side":"Sell","size":56,"price":7.955}]}
1618677679.13147: {"table":"orderBookL2","action":"delete","data":[{"symbol":"DOGEUSDT","id":47599971512,"side":"Sell"}]}
1618677679.1315682: {"table":"orderBookL2","action":"insert","data":[{"symbol":"DOGEUSDT","id":47599971590,"side":"Sell","size":1654,"price":0.2841}]}
1618677679.146472: {"table":"orderBookL2","action":"delete","data":[{"symbol":"DOGEUSDT","id":47599971513,"side":"Sell"}]}
1618677679.1465569: {"table":"orderBookL2","action":"update","data":[{"symbol":"LTCUSD","id":40699968752,"side":"Buy","size":20}]}
1618677679.1466072: {"table":"orderBookL2","action":"insert","data":[{"symbol":"LTCUSD","id":40699968747,"side":"Buy","size":125,"price":312.53}]}
1618677679.1602318: {"table":"orderBookL2","action":"delete","data":[{"symbol":"LTCUSD","id":40699968748,"side":"Buy"}]}
1618677679.160321: {"table":"orderBookL2","action":"insert","data":[{"symbol":"LTCUSD","id":40699968746,"side":"Buy","size":68,"price":312.54}]}
1618677679.179384: {"table":"orderBookL2","action":"insert","data":[{"symbol":"LTCUSD","id":40699968745,"side":"Buy","size":39,"price":312.55}]}
1618677679.1794748: {"table":"orderBookL2","action":"update","data":[{"symbol":"LTCUSD","id":40699968673,"side":"Sell","size":5247}]}
1618677679.244577: {"table":"orderBookL2","action":"delete","data":[{"symbol":"LTCUSD","id":40699968749,"side":"Buy"}]}
1618677679.244682: {"table":"orderBookL2","action":"update","data":[{"symbol":"LTCUSD","id":40699968746,"side":"Buy","size":315}]}
1618677679.27828: {"table":"orderBookL2","action":"delete","data":[{"symbol":"DOGEUSDT","id":47599971505,"side":"Sell"}]}
1618677679.278367: {"table":"orderBookL2","action":"insert","data":[{"symbol":"DOGEUSDT","id":47599971591,"side":"Sell","size":50,"price":0.28409}]}
1618677679.336093: {"table":"orderBookL2","action":"delete","data":[{"symbol":"LTCUSD","id":40699968417,"side":"Sell"},{"symbol":"LTCUSD","id":40699968527,"side":"Sell"},{"symbol":"LTCUSD","id":40699969017,"side":"Buy"},{"symbol":"LTCUSD","id":40699969220,"side":"Buy"}]}
1618677679.3362188: {"table":"orderBookL2","action":"update","data":[{"symbol":"LTCUSD","id":40699968197,"side":"Sell","size":1769},{"symbol":"LTCUSD","id":40699968508,"side":"Sell","size":879},{"symbol":"LTCUSD","id":40699968948,"side":"Buy","size":2149}]}
1618677679.3362792: {"table":"orderBookL2","action":"insert","data":[{"symbol":"LTCUSD","id":40699968195,"side":"Sell","size":579,"price":318.05},{"symbol":"LTCUSD","id":40699968415,"side":"Sell","size":579,"price":315.85},{"symbol":"LTCUSD","id":40699968914,"side":"Buy","size":579,"price":310.86},{"symbol":"LTCUSD","id":40699969016,"side":"Buy","size":579,"price":309.84},{"symbol":"LTCUSD","id":40699969219,"side":"Buy","size":579,"price":307.81}]}
1618677679.3363872: {"table":"orderBookL2","action":"insert","data":[{"symbol":"XLMUSDT","id":52199939139,"side":"Sell","size":178,"price":0.60861}]}
1618677679.347308: {"table":"orderBookL2","action":"update","data":[{"symbol":"XLMUSDT","id":52199939139,"side":"Sell","size":250}]}
1618677679.387449: {"table":"orderBookL2","action":"update","data":[{"symbol":"LTCUSD","id":40699968668,"side":"Sell","size":520}]}
1618677679.4045749: {"table":"orderBookL2","action":"delete","data":[{"symbol":"EOSUSDT","id":53899984876,"side":"Buy"}]}
1618677679.404624: {"table":"orderBookL2","action":"insert","data":[{"symbol":"EOSUSDT","id":53899984209,"side":"Buy","size":1425,"price":7.8955}]}
1618677679.423906: {"table":"orderBookL2","action":"delete","data":[{"symbol":"DOGEUSDT","id":47599971590,"side":"Sell"}]}
1618677679.4239628: {"table":"orderBookL2","action":"insert","data":[{"symbol":"DOGEUSDT","id":47599971592,"side":"Sell","size":918,"price":0.28408}]}
1618677679.437824: {"table":"orderBookL2","action":"update","data":[{"symbol":"DOGEUSDT","id":47599971385,"side":"Sell","size":313}]}
1618677679.4507442: {"table":"orderBookL2","action":"delete","data":[{"symbol":"DOGEUSDT","id":47599971930,"side":"Buy"}]}
1618677679.450836: {"table":"orderBookL2","action":"insert","data":[{"symbol":"DOGEUSDT","id":47599971959,"side":"Buy","size":154,"price":0.28041}]}
1618677679.476233: {"table":"orderBookL2","action":"delete","data":[{"symbol":"EOSUSDT","id":53899984158,"side":"Buy"}]}
1618677679.477383: {"table":"orderBookL2","action":"update","data":[{"symbol":"EOSUSDT","id":53899984166,"side":"Buy","size":80}]}
1618677679.583824: {"table":"orderBookL2","action":"update","data":[{"symbol":"LTCUSD","id":40699968684,"side":"Sell","size":346}]}
1618677679.595528: {"table":"orderBookL2","action":"update","data":[{"symbol":"LTCUSD","id":40699968684,"side":"Sell","size":582}]}
1618677679.71588: {"table":"orderBookL2","action":"delete","data":[{"symbol":"DOGEUSDT","id":47599971592,"side":"Sell"}]}
1618677679.906322: {"table":"orderBookL2","action":"delete","data":[{"symbol":"XLMUSDT","id":52199939443,"side":"Buy"}]}
1618677679.9115012: {"table":"orderBookL2","action":"insert","data":[{"symbol":"EOSUSDT","id":53899984097,"side":"Sell","size":48,"price":7.9515}]}
1618677679.939188: {"table":"orderBookL2","action":"delete","data":[{"symbol":"DOGEUSDT","id":47599971685,"side":"Buy"}]}
1618677679.951589: {"table":"orderBookL2","action":"insert","data":[{"symbol":"DOGEUSDT","id":47599971835,"side":"Buy","size":352,"price":0.28165}]}
1618677679.97522: {"table":"orderBookL2","action":"insert","data":[{"symbol":"LTCUSD","id":40699968692,"side":"Sell","size":85,"price":313.08}]}
1618677680.034888: {"table":"orderBookL2","action":"update","data":[{"symbol":"LTCUSD","id":40699968746,"side":"Buy","size":68}]}
1618677680.034945: {"table":"orderBookL2","action":"insert","data":[{"symbol":"DOGEUSDT","id":47599971592,"side":"Sell","size":601,"price":0.28408}]}
1618677680.0355961: {"table":"orderBookL2","action":"delete","data":[{"symbol":"LTCUSD","id":40699968756,"side":"Buy"}]}
1618677680.0465002: {"table":"orderBookL2","action":"delete","data":[{"symbol":"LTCUSD","id":40699968746,"side":"Buy"}]}
1618677680.0498729: {"table":"orderBookL2","action":"update","data":[{"symbol":"DOGEUSDT","id":47599971385,"side":"Sell","size":13}]}
1618677680.04993: {"table":"orderBookL2","action":"insert","data":[{"symbol":"DOGEUSDT","id":47599971593,"side":"Sell","size":300,"price":0.28407}]}
1618677680.061381: {"table":"orderBookL2","action":"delete","data":[{"symbol":"LTCUSD","id":40699968659,"side":"Sell"}]}
1618677680.061463: {"table":"orderBookL2","action":"update","data":[{"symbol":"LTCUSD","id":40699968763,"side":"Buy","size":340}]}
1618677680.061496: {"table":"orderBookL2","action":"insert","data":[{"symbol":"LTCUSD","id":40699968674,"side":"Sell","size":106,"price":313.26}]}
1618677680.064053: {"table":"orderBookL2","action":"insert","data":[{"symbol":"LTCUSD","id":40699968693,"side":"Sell","size":432,"price":313.07}]}
1618677680.072435: {"table":"orderBookL2","action":"delete","data":[{"symbol":"DOGEUSDT","id":47599971593,"side":"Sell"}]}
1618677680.078927: {"table":"orderBookL2","action":"delete","data":[{"symbol":"LTCUSD","id":40699968753,"side":"Buy"}]}
1618677680.0790179: {"table":"orderBookL2","action":"delete","data":[{"symbol":"LTCUSD","id":40699968692,"side":"Sell"}]}
1618677680.079411: {"table":"orderBookL2","action":"insert","data":[{"symbol":"LTCUSD","id":40699968694,"side":"Sell","size":243,"price":313.06}]}
1618677680.085591: {"table":"orderBookL2","action":"delete","data":[{"symbol":"LTCUSD","id":40699968747,"side":"Buy"}]}
1618677680.093724: {"table":"orderBookL2","action":"delete","data":[{"symbol":"LTCUSD","id":40699968752,"side":"Buy"}]}
1618677680.146413: {"table":"orderBookL2","action":"insert","data":[{"symbol":"LTCUSD","id":40699968762,"side":"Buy","size":20,"price":312.38}]}
1618677680.146516: {"table":"orderBookL2","action":"update","data":[{"symbol":"LTCUSD","id":40699968763,"side":"Buy","size":104}]}
1618677680.146561: {"table":"orderBookL2","action":"delete","data":[{"symbol":"LTCUSD","id":40699968676,"side":"Sell"}]}
1618677680.146611: {"table":"orderBookL2","action":"insert","data":[{"symbol":"LTCUSD","id":40699968687,"side":"Sell","size":538,"price":313.13}]}
1618677680.1466591: {"table":"orderBookL2","action":"delete","data":[{"symbol":"DOGEUSDT","id":47599971591,"side":"Sell"}]}
1618677680.146705: {"table":"orderBookL2","action":"update","data":[{"symbol":"DOGEUSDT","id":47599971385,"side":"Sell","size":63}]}
1618677680.174902: {"table":"orderBookL2","action":"delete","data":[{"symbol":"LTCUSD","id":40699968195,"side":"Sell"},{"symbol":"LTCUSD","id":40699968415,"side":"Sell"},{"symbol":"LTCUSD","id":40699968619,"side":"Sell"},{"symbol":"LTCUSD","id":40699968914,"side":"Buy"},{"symbol":"LTCUSD","id":40699969016,"side":"Buy"},{"symbol":"LTCUSD","id":40699969219,"side":"Buy"}]}
1618677680.1750422: {"table":"orderBookL2","action":"update","data":[{"symbol":"LTCUSD","id":40699968508,"side":"Sell","size":300},{"symbol":"LTCUSD","id":40699968948,"side":"Buy","size":2728}]}
1618677680.175578: {"table":"orderBookL2","action":"insert","data":[{"symbol":"LTCUSD","id":40699968203,"side":"Sell","size":579,"price":317.97},{"symbol":"LTCUSD","id":40699968423,"side":"Sell","size":579,"price":315.77},{"symbol":"LTCUSD","id":40699968533,"side":"Sell","size":579,"price":314.67},{"symbol":"LTCUSD","id":40699968643,"side":"Sell","size":579,"price":313.57},{"symbol":"LTCUSD","id":40699969023,"side":"Buy","size":579,"price":309.77},{"symbol":"LTCUSD","id":40699969226,"side":"Buy","size":579,"price":307.74}]}
1618677680.176268: {"table":"orderBookL2","action":"delete","data":[{"symbol":"DOGEUSDT","id":47599971589,"side":"Sell"}]}
1618677680.1780732: {"table":"orderBookL2","action":"delete","data":[{"symbol":"DOGEUSDT","id":47599971807,"side":"Buy"},{"symbol":"DOGEUSDT","id":47599971808,"side":"Buy"},{"symbol":"DOGEUSDT","id":47599971809,"side":"Buy"},{"symbol":"DOGEUSDT","id":47599971810,"side":"Buy"},{"symbol":"DOGEUSDT","id":47599971811,"side":"Buy"}]}
1618677680.184771: {"table":"orderBookL2","action":"update","data":[{"symbol":"LINKUSDTM21","id":52799886587,"side":"Buy","size":100}]}
1618677680.1947148: {"table":"orderBookL2","action":"update","data":[{"symbol":"EOSM21","id":52499998732,"side":"Sell","size":1387}]}
1618677680.1948001: {"table":"orderBookL2","action":"update","data":[{"symbol":"DOGEUSDT","id":47599971882,"side":"Buy","size":1279}]}
1618677680.1948469: {"table":"orderBookL2","action":"insert","data":[{"symbol":"DOGEUSDT","id":47599971879,"side":"Buy","size":100,"price":0.28121},{"symbol":"DOGEUSDT","id":47599971880,"side":"Buy","size":100,"price":0.2812},{"symbol":"DOGEUSDT","id":47599971881,"side":"Buy","size":100,"price":0.28119},{"symbol":"DOGEUSDT","id":47599971883,"side":"Buy","size":100,"price":0.28117}]}
1618677680.196778: {"table":"orderBookL2","action":"insert","data":[{"symbol":"DOGEUSDT","id":47599971929,"side":"Buy","size":582,"price":0.28071},{"symbol":"DOGEUSDT","id":47599971930,"side":"Buy","size":582,"price":0.2807},{"symbol":"DOGEUSDT","id":47599971931,"side":"Buy","size":582,"price":0.28069}]}
1618677680.197545: {"table":"orderBookL2","action":"delete","data":[{"symbol":"LTCM21","id":52899998947,"side":"Buy"}]}
1618677680.201897: {"table":"orderBookL2","action":"delete","data":[{"symbol":"LTCUSD","id":40699968203,"side":"Sell"},{"symbol":"LTCUSD","id":40699968423,"side":"Sell"},{"symbol":"LTCUSD","id":40699968533,"side":"Sell"},{"symbol":"LTCUSD","id":40699969023,"side":"Buy"},{"symbol":"LTCUSD","id":40699969226,"side":"Buy"}]}
1618677680.202024: {"table":"orderBookL2","action":"insert","data":[{"symbol":"LTCUSD","id":40699968205,"side":"Sell","size":579,"price":317.95},{"symbol":"LTCUSD","id":40699968425,"side":"Sell","size":579,"price":315.75},{"symbol":"LTCUSD","id":40699968535,"side":"Sell","size":579,"price":314.65},{"symbol":"LTCUSD","id":40699969025,"side":"Buy","size":579,"price":309.75},{"symbol":"LTCUSD","id":40699969228,"side":"Buy","size":579,"price":307.72}]}
1618677680.21103: {"table":"orderBookL2","action":"delete","data":[{"symbol":"DOGEUSDT","id":47599971929,"side":"Buy"},{"symbol":"DOGEUSDT","id":47599971930,"side":"Buy"},{"symbol":"DOGEUSDT","id":47599971931,"side":"Buy"}]}
1618677680.3647091: {"table":"orderBookL2","action":"insert","data":[{"symbol":"EOSUSDT","id":53899984150,"side":"Buy","size":200,"price":7.925}]}
1618677680.378664: {"table":"orderBookL2","action":"delete","data":[{"symbol":"DOGEUSDT","id":47599971592,"side":"Sell"}]}
1618677680.378761: {"table":"orderBookL2","action":"insert","data":[{"symbol":"DOGEUSDT","id":47599971504,"side":"Sell","size":603,"price":0.28496}]}
1618677680.385327: {"table":"orderBookL2","action":"insert","data":[{"symbol":"LTCUSD","id":40699968837,"side":"Buy","size":106,"price":311.63}]}
1618677680.388563: {"table":"orderBookL2","action":"delete","data":[{"symbol":"LTCUSD","id":40699968823,"side":"Buy"}]}
1618677680.4602711: {"table":"orderBookL2","action":"insert","data":[{"symbol":"LINKUSDTM21","id":52799885915,"side":"Sell","size":5,"price":57.0425}]}
1618677680.49737: {"table":"orderBookL2","action":"delete","data":[{"symbol":"EOSUSDT","id":53899984097,"side":"Sell"}]}
1618677680.515435: {"table":"orderBookL2","action":"update","data":[{"symbol":"EOSM21","id":52499998732,"side":"Sell","size":1057}]}
1618677680.553558: {"table":"orderBookL2","action":"delete","data":[{"symbol":"XLMUSDT","id":52199939087,"side":"Sell"}]}
1618677680.553673: {"table":"orderBookL2","action":"insert","data":[{"symbol":"XLMUSDT","id":52199939107,"side":"Sell","size":232,"price":0.60893}]}
1618677680.558176: {"table":"orderBookL2","action":"insert","data":[{"symbol":"DOGEUSDT","id":47599971505,"side":"Sell","size":300,"price":0.28495}]}
1618677680.6085382: {"table":"orderBookL2","action":"delete","data":[{"symbol":"EOSUSDT","id":53899984151,"side":"Buy"}]}
1618677680.6232011: {"table":"orderBookL2","action":"insert","data":[{"symbol":"EOSUSDT","id":53899984141,"side":"Buy","size":1000,"price":7.9295}]}
1618677680.693238: {"table":"orderBookL2","action":"update","data":[{"symbol":"EOSM21","id":52499998740,"side":"Buy","size":83}]}
1618677680.719102: {"table":"orderBookL2","action":"delete","data":[{"symbol":"DOGEUSDT","id":47599971504,"side":"Sell"}]}
1618677680.719179: {"table":"orderBookL2","action":"insert","data":[{"symbol":"DOGEUSDT","id":47599971506,"side":"Sell","size":603,"price":0.28494}]}
1618677680.7332091: {"table":"orderBookL2","action":"delete","data":[{"symbol":"DOGEUSDT","id":47599971505,"side":"Sell"}]}
1618677680.747463: {"table":"orderBookL2","action":"insert","data":[{"symbol":"DOGEUSDT","id":47599971507,"side":"Sell","size":300,"price":0.28493}]}
1618677680.79124: {"table":"orderBookL2","action":"delete","data":[{"symbol":"LTCUSD","id":40699968694,"side":"Sell"}]}
1618677680.791299: {"table":"orderBookL2","action":"insert","data":[{"symbol":"LTCUSD","id":40699968695,"side":"Sell","size":152,"price":313.05}]}
1618677680.803966: {"table":"orderBookL2","action":"update","data":[{"symbol":"LTCUSD","id":40699968684,"side":"Sell","size":346}]}
1618677680.8040059: {"table":"orderBookL2","action":"insert","data":[{"symbol":"LTCUSD","id":40699968694,"side":"Sell","size":236,"price":313.06}]}
1618677680.810464: {"table":"orderBookL2","action":"delete","data":[{"symbol":"DOGEUSDT","id":47599971792,"side":"Buy"}]}
1618677680.810522: {"table":"orderBookL2","action":"insert","data":[{"symbol":"DOGEUSDT","id":47599971789,"side":"Buy","size":2110,"price":0.28211}]}
1618677680.848955: {"table":"orderBookL2","action":"update","data":[{"symbol":"EOSUSDT","id":53899984157,"side":"Buy","size":547}]}
1618677680.849581: {"table":"orderBookL2","action":"insert","data":[{"symbol":"EOSUSDT","id":53899984083,"side":"Sell","size":51,"price":7.9585}]}
1618677680.9129422: {"table":"orderBookL2","action":"delete","data":[{"symbol":"DOGEUSDT","id":47599970224,"side":"Sell"},{"symbol":"DOGEUSDT","id":47599970366,"side":"Sell"},{"symbol":"DOGEUSDT","id":47599970508,"side":"Sell"},{"symbol":"DOGEUSDT","id":47599970651,"side":"Sell"},{"symbol":"DOGEUSDT","id":47599970793,"side":"Sell"},{"symbol":"DOGEUSDT","id":47599970935,"side":"Sell"},{"symbol":"DOGEUSDT","id":47599971077,"side":"Sell"},{"symbol":"DOGEUSDT","id":47599971219,"side":"Sell"},{"symbol":"DOGEUSDT","id":47599971361,"side":"Sell"},{"symbol":"DOGEUSDT","id":47599971503,"side":"Sell"},{"symbol":"DOGEUSDT","id":47599971727,"side":"Buy"},{"symbol":"DOGEUSDT","id":47599971869,"side":"Buy"},{"symbol":"DOGEUSDT","id":47599972011,"side":"Buy"},{"symbol":"DOGEUSDT","id":47599972153,"side":"Buy"},{"symbol":"DOGEUSDT","id":47599972295,"side":"Buy"},{"symbol":"DOGEUSDT","id":47599972437,"side":"Buy"},{"symbol":"DOGEUSDT","id":47599972579,"side":"Buy"},{"symbol":"DOGEUSDT","id":47599972721,"side":"Buy"},{"symbol":"DOGEUSDT","id":47599972864,"side":"Buy"},{"symbol":"DOGEUSDT","id":47599973006,"side":"Buy"}]}
1618677680.9132328: {"table":"orderBookL2","action":"update","data":[{"symbol":"DOGEUSDT","id":47599970424,"side":"Sell","size":2288},{"symbol":"DOGEUSDT","id":47599970566,"side":"Sell","size":129},{"symbol":"DOGEUSDT","id":47599971275,"side":"Sell","size":150},{"symbol":"DOGEUSDT","id":47599971506,"side":"Sell","size":640}]}
1618677680.913302: {"table":"orderBookL2","action":"insert","data":[{"symbol":"DOGEUSDT","id":47599970282,"side":"Sell","size":126,"price":0.29718},{"symbol":"DOGEUSDT","id":47599970708,"side":"Sell","size":126,"price":0.29292},{"symbol":"DOGEUSDT","id":47599970849,"side":"Sell","size":111,"price":0.29151},{"symbol":"DOGEUSDT","id":47599970991,"side":"Sell","size":90,"price":0.29009},{"symbol":"DOGEUSDT","id":47599971133,"side":"Sell","size":70,"price":0.28867},{"symbol":"DOGEUSDT","id":47599971417,"side":"Sell","size":37,"price":0.28583},{"symbol":"DOGEUSDT","id":47599971784,"side":"Buy","size":37,"price":0.28216},{"symbol":"DOGEUSDT","id":47599971926,"side":"Buy","size":44,"price":0.28074},{"symbol":"DOGEUSDT","id":47599972068,"side":"Buy","size":75,"price":0.27932},{"symbol":"DOGEUSDT","id":47599972210,"side":"Buy","size":107,"price":0.2779},{"symbol":"DOGEUSDT","id":47599972352,"side":"Buy","size":140,"price":0.27648},{"symbol":"DOGEUSDT","id":47599972494,"side":"Buy","size":173,"price":0.27506},{"symbol":"DOGEUSDT","id":47599972635,"side":"Buy","size":186,"price":0.27365},{"symbol":"DOGEUSDT","id":47599972777,"side":"Buy","size":186,"price":0.27223},{"symbol":"DOGEUSDT","id":47599972919,"side":"Buy","size":186,"price":0.27081},{"symbol":"DOGEUSDT","id":47599973061,"side":"Buy","size":186,"price":0.26939}]}
1618677680.957741: {"table":"orderBookL2","action":"delete","data":[{"symbol":"DOGEUSDT","id":47599971932,"side":"Buy"}]}
1618677680.9743612: {"table":"orderBookL2","action":"insert","data":[{"symbol":"DOGEUSDT","id":47599972693,"side":"Buy","size":12563,"price":0.27307}]}
1618677680.978131: {"table":"orderBookL2","action":"insert","data":[{"symbol":"DOGEUSDT","id":47599971508,"side":"Sell","size":348,"price":0.28492}]}
1618677680.988968: {"table":"orderBookL2","action":"delete","data":[{"symbol":"DOGEUSDT","id":47599971789,"side":"Buy"}]}
1618677680.989025: {"table":"orderBookL2","action":"insert","data":[{"symbol":"DOGEUSDT","id":47599971788,"side":"Buy","size":2110,"price":0.28212}]}
1618677680.994281: {"table":"orderBookL2","action":"delete","data":[{"symbol":"DOGEUSDT","id":47599971507,"side":"Sell"}]}
1618677680.994345: {"table":"orderBookL2","action":"insert","data":[{"symbol":"DOGEUSDT","id":47599971509,"side":"Sell","size":300,"price":0.28491}]}
1618677681.037976: {"table":"orderBookL2","action":"delete","data":[{"symbol":"LTCUSD","id":40699968837,"side":"Buy"}]}
1618677681.1034439: {"table":"orderBookL2","action":"update","data":[{"symbol":"DOGEUSDT","id":47599971506,"side":"Sell","size":37}]}
1618677681.103484: {"table":"orderBookL2","action":"insert","data":[{"symbol":"DOGEUSDT","id":47599971510,"side":"Sell","size":603,"price":0.2849}]}
1618677681.119055: {"table":"orderBookL2","action":"delete","data":[{"symbol":"LTCUSD","id":40699968693,"side":"Sell"}]}
1618677681.119095: {"table":"orderBookL2","action":"insert","data":[{"symbol":"LTCUSD","id":40699968696,"side":"Sell","size":432,"price":313.04}]}
1618677681.124769: {"table":"orderBookL2","action":"delete","data":[{"symbol":"XLMUSDT","id":52199939107,"side":"Sell"}]}
1618677681.1354601: {"table":"orderBookL2","action":"delete","data":[{"symbol":"LTCUSD","id":40699968695,"side":"Sell"}]}
1618677681.163101: {"table":"orderBookL2","action":"insert","data":[{"symbol":"DOGEUSDT","id":47599971783,"side":"Buy","size":2147,"price":0.28217}]}
1618677681.167663: {"table":"orderBookL2","action":"insert","data":[{"symbol":"DOGEUSDT","id":47599971511,"side":"Sell","size":1288,"price":0.28489}]}
1618677681.176065: {"table":"orderBookL2","action":"delete","data":[{"symbol":"EOSUSDT","id":53899984185,"side":"Buy"}]}
1618677681.1761: {"table":"orderBookL2","action":"update","data":[{"symbol":"EOSUSDT","id":53899984140,"side":"Buy","size":667},{"symbol":"EOSUSDT","id":53899984157,"side":"Buy","size":51}]}
1618677681.1761222: {"table":"orderBookL2","action":"insert","data":[{"symbol":"EOSUSDT","id":53899984156,"side":"Buy","size":1610,"price":7.922}]}
1618677681.191023: {"table":"orderBookL2","action":"delete","data":[{"symbol":"LTCUSD","id":40699968205,"side":"Sell"},{"symbol":"LTCUSD","id":40699968425,"side":"Sell"},{"symbol":"LTCUSD","id":40699968535,"side":"Sell"},{"symbol":"LTCUSD","id":40699968643,"side":"Sell"},{"symbol":"LTCUSD","id":40699969025,"side":"Buy"},{"symbol":"LTCUSD","id":40699969228,"side":"Buy"}]}
1618677681.1910882: {"table":"orderBookL2","action":"update","data":[{"symbol":"LTCUSD","id":40699968430,"side":"Sell","size":587},{"symbol":"LTCUSD","id":40699968536,"side":"Sell","size":776}]}
1618677681.191112: {"table":"orderBookL2","action":"insert","data":[{"symbol":"LTCUSD","id":40699968210,"side":"Sell","size":579,"price":317.9},{"symbol":"LTCUSD","id":40699968648,"side":"Sell","size":579,"price":313.52},{"symbol":"LTCUSD","id":40699969028,"side":"Buy","size":579,"price":309.72},{"symbol":"LTCUSD","id":40699969231,"side":"Buy","size":579,"price":307.69}]}
1618677681.2112799: {"table":"orderBookL2","action":"delete","data":[{"symbol":"EOSUSDT","id":53899984090,"side":"Sell"}]}
1618677681.2541592: {"table":"orderBookL2","action":"insert","data":[{"symbol":"LTCUSD","id":40699968766,"side":"Buy","size":236,"price":312.34}]}
1618677681.25476: {"table":"orderBookL2","action":"insert","data":[{"symbol":"LTCUSD","id":40699968744,"side":"Buy","size":1,"price":312.56}]}
1618677681.269156: {"table":"orderBookL2","action":"delete","data":[{"symbol":"LTCUSD","id":40699968694,"side":"Sell"}]}
1618677681.278375: {"table":"orderBookL2","action":"delete","data":[{"symbol":"EOSUSDT","id":53899984083,"side":"Sell"}]}
1618677681.278422: {"table":"orderBookL2","action":"insert","data":[{"symbol":"EOSUSDT","id":53899984148,"side":"Buy","size":63,"price":7.926}]}
1618677681.285171: {"table":"orderBookL2","action":"delete","data":[{"symbol":"LTCUSD","id":40699968744,"side":"Buy"}]}
1618677681.317506: {"table":"orderBookL2","action":"insert","data":[{"symbol":"XLMUSDT","id":52199939085,"side":"Sell","size":232,"price":0.60915}]}
1618677681.335907: {"table":"orderBookL2","action":"delete","data":[{"symbol":"LINKUSDTM21","id":52799886587,"side":"Buy"}]}
1618677681.350969: {"table":"orderBookL2","action":"insert","data":[{"symbol":"LINKUSDTM21","id":52799882610,"side":"Sell","size":100,"price":58.695}]}
1618677681.4092731: {"table":"orderBookL2","action":"update","data":[{"symbol":"DOGEUSDT","id":47599971385,"side":"Sell","size":13}]}
1618677681.409373: {"table":"orderBookL2","action":"insert","data":[{"symbol":"DOGEUSDT","id":47599971512,"side":"Sell","size":50,"price":0.28488}]}
1618677681.427237: {"table":"orderBookL2","action":"delete","data":[{"symbol":"DOGEUSDT","id":47599971385,"side":"Sell"}]}
1618677681.469899: {"table":"orderBookL2","action":"delete","data":[{"symbol":"LTCUSD","id":40699968687,"side":"Sell"}]}
1618677681.488327: {"table":"orderBookL2","action":"delete","data":[{"symbol":"DOGEUSDT","id":47599971510,"side":"Sell"}]}
1618677681.488416: {"table":"orderBookL2","action":"insert","data":[{"symbol":"DOGEUSDT","id":47599971513,"side":"Sell","size":603,"price":0.28487}]}
1618677681.488929: {"table":"orderBookL2","action":"update","data":[{"symbol":"EOSM21","id":52499998734,"side":"Buy","size":1725}]}
1618677681.496116: {"table":"orderBookL2","action":"delete","data":[{"symbol":"DOGEUSDT","id":47599971509,"side":"Sell"}]}
1618677681.496203: {"table":"orderBookL2","action":"update","data":[{"symbol":"DOGEUSDT","id":47599971512,"side":"Sell","size":350}]}
1618677681.501339: {"table":"orderBookL2","action":"insert","data":[{"symbol":"DOGEUSDT","id":47599971385,"side":"Sell","size":17,"price":0.28615}]}
1618677681.503863: {"table":"orderBookL2","action":"insert","data":[{"symbol":"LTCUSD","id":40699968749,"side":"Buy","size":247,"price":312.51}]}
1618677681.505929: {"table":"orderBookL2","action":"delete","data":[{"symbol":"DOGEUSDT","id":47599971385,"side":"Sell"}]}
1618677681.506016: {"table":"orderBookL2","action":"update","data":[{"symbol":"EOSM21","id":52499998731,"side":"Sell","size":322}]}
1618677681.506638: {"table":"orderBookL2","action":"delete","data":[{"symbol":"DOGEUSDT","id":47599971788,"side":"Buy"}]}
1618677681.5071008: {"table":"orderBookL2","action":"insert","data":[{"symbol":"DOGEUSDT","id":47599971787,"side":"Buy","size":2110,"price":0.28213}]}
1618677681.517385: {"table":"orderBookL2","action":"insert","data":[{"symbol":"DOGEUSDT","id":47599971385,"side":"Sell","size":17,"price":0.28615}]}
1618677681.522789: {"table":"orderBookL2","action":"delete","data":[{"symbol":"DOGEUSDT","id":47599971783,"side":"Buy"}]}
1618677681.522874: {"table":"orderBookL2","action":"insert","data":[{"symbol":"DOGEUSDT","id":47599971782,"side":"Buy","size":37,"price":0.28218}]}
1618677681.525655: {"table":"orderBookL2","action":"delete","data":[{"symbol":"XLMUSDT","id":52199939057,"side":"Sell"}]}
1618677681.534438: {"table":"orderBookL2","action":"update","data":[{"symbol":"ADAM21","id":52299997882,"side":"Buy","size":143607},{"symbol":"ADAM21","id":52299997888,"side":"Buy","size":128820}]}
1618677681.5506911: {"table":"orderBookL2","action":"delete","data":[{"symbol":"ADAM21","id":52299997817,"side":"Sell"}]}
1618677681.5507772: {"table":"orderBookL2","action":"insert","data":[{"symbol":"ADAM21","id":52299997823,"side":"Sell","size":536,"price":0.00002177}]}
1618677681.5644422: {"table":"orderBookL2","action":"update","data":[{"symbol":"LTCUSD","id":40699968684,"side":"Sell","size":582}]}
1618677681.567668: {"table":"orderBookL2","action":"delete","data":[{"symbol":"LTCUSD","id":40699968674,"side":"Sell"}]}
1618677681.6592379: {"table":"orderBookL2","action":"delete","data":[{"symbol":"XLMUSDT","id":52199939381,"side":"Buy"}]}
1618677681.6593568: {"table":"orderBookL2","action":"insert","data":[{"symbol":"XLMUSDT","id":52199939361,"side":"Buy","size":112,"price":0.60639}]}
1618677681.675353: {"table":"orderBookL2","action":"update","data":[{"symbol":"EOSM21","id":52499998733,"side":"Buy","size":1530}]}
1618677681.709446: {"table":"orderBookL2","action":"insert","data":[{"symbol":"EOSM21","id":52499998739,"side":"Buy","size":8339,"price":0.0001261}]}
1618677681.774081: {"table":"orderBookL2","action":"update","data":[{"symbol":"LTCUSD","id":40699968684,"side":"Sell","size":346}]}
1618677681.787832: {"table":"orderBookL2","action":"update","data":[{"symbol":"ADAM21","id":52299997836,"side":"Buy","size":39449}]}
1618677681.799951: {"table":"orderBookL2","action":"delete","data":[{"symbol":"LTCUSD","id":40699968210,"side":"Sell"},{"symbol":"LTCUSD","id":40699968648,"side":"Sell"},{"symbol":"LTCUSD","id":40699969028,"side":"Buy"},{"symbol":"LTCUSD","id":40699969231,"side":"Buy"}]}
1618677681.8000798: {"table":"orderBookL2","action":"update","data":[{"symbol":"LTCUSD","id":40699968430,"side":"Sell","size":8},{"symbol":"LTCUSD","id":40699968508,"side":"Sell","size":879},{"symbol":"LTCUSD","id":40699968536,"side":"Sell","size":197},{"symbol":"LTCUSD","id":40699969222,"side":"Buy","size":2407}]}
1618677681.8001459: {"table":"orderBookL2","action":"insert","data":[{"symbol":"LTCUSD","id":40699968199,"side":"Sell","size":579,"price":318.01},{"symbol":"LTCUSD","id":40699968419,"side":"Sell","size":579,"price":315.81},{"symbol":"LTCUSD","id":40699968619,"side":"Sell","size":579,"price":313.81},{"symbol":"LTCUSD","id":40699969019,"side":"Buy","size":579,"price":309.81}]}
1618677681.8065002: {"table":"orderBookL2","action":"insert","data":[{"symbol":"LTCUSD","id":40699968689,"side":"Sell","size":247,"price":313.11}]}
1618677681.843564: {"table":"orderBookL2","action":"delete","data":[{"symbol":"LINKUSDTM21","id":52799885915,"side":"Sell"}]}
1618677681.8436449: {"table":"orderBookL2","action":"update","data":[{"symbol":"LTCUSD","id":40699968684,"side":"Sell","size":256}]}
1618677681.868885: {"table":"orderBookL2","action":"delete","data":[{"symbol":"LTCUSD","id":40699968689,"side":"Sell"}]}
1618677681.878808: {"table":"orderBookL2","action":"delete","data":[{"symbol":"LTCUSD","id":40699968766,"side":"Buy"}]}
1618677681.878926: {"table":"orderBookL2","action":"insert","data":[{"symbol":"LTCUSD","id":40699968748,"side":"Buy","size":236,"price":312.52}]}
1618677681.893152: {"table":"orderBookL2","action":"delete","data":[{"symbol":"EOSUSDT","id":53899984179,"side":"Buy"}]}
1618677681.893273: {"table":"orderBookL2","action":"delete","data":[{"symbol":"EOSUSDT","id":53899984074,"side":"Sell"}]}
1618677681.895266: {"table":"orderBookL2","action":"delete","data":[{"symbol":"LTCUSD","id":40699968748,"side":"Buy"}]}
1618677681.895356: {"table":"orderBookL2","action":"update","data":[{"symbol":"EOSUSDT","id":53899984140,"side":"Buy","size":728}]}
1618677681.926549: {"table":"orderBookL2","action":"delete","data":[{"symbol":"DOGEUSDT","id":47599971511,"side":"Sell"}]}
1618677681.9319448: {"table":"orderBookL2","action":"update","data":[{"symbol":"XLMUSDT","id":52199939139,"side":"Sell","size":72}]}
1618677681.93202: {"table":"orderBookL2","action":"update","data":[{"symbol":"LTCM21","id":52899998944,"side":"Sell","size":23}]}
1618677681.938175: {"table":"orderBookL2","action":"delete","data":[{"symbol":"XLMUSDT","id":52199939085,"side":"Sell"}]}
1618677681.943452: {"table":"orderBookL2","action":"insert","data":[{"symbol":"XLMUSDT","id":52199938982,"side":"Sell","size":48,"price":0.61018}]}
1618677681.9442801: {"table":"orderBookL2","action":"delete","data":[{"symbol":"XLMUSDT","id":52199939012,"side":"Sell"}]}
1618677681.947398: {"table":"orderBookL2","action":"update","data":[{"symbol":"LTCM21","id":52899998946,"side":"Buy","size":18}]}
1618677681.9474728: {"table":"orderBookL2","action":"update","data":[{"symbol":"LTCM21","id":52899998943,"side":"Sell","size":68}]}
1618677681.957582: {"table":"orderBookL2","action":"insert","data":[{"symbol":"LTCUSD","id":40699968744,"side":"Buy","size":1,"price":312.56}]}
1618677681.959614: {"table":"orderBookL2","action":"delete","data":[{"symbol":"LTCUSD","id":40699968199,"side":"Sell"},{"symbol":"LTCUSD","id":40699968419,"side":"Sell"},{"symbol":"LTCUSD","id":40699969019,"side":"Buy"}]}
1618677681.95973: {"table":"orderBookL2","action":"insert","data":[{"symbol":"LTCUSD","id":40699968193,"side":"Sell","size":579,"price":318.07},{"symbol":"LTCUSD","id":40699968414,"side":"Sell","size":579,"price":315.86},{"symbol":"LTCUSD","id":40699969018,"side":"Buy","size":579,"price":309.82}]}
1618677681.9598231: {"table":"orderBookL2","action":"delete","data":[{"symbol":"XLMUSDT","id":52199939139,"side":"Sell"}]}
1618677681.9713311: {"table":"orderBookL2","action":"insert","data":[{"symbol":"XLMUSDT","id":52199939294,"side":"Buy","size":74,"price":0.60706}]}
1618677681.974519: {"table":"orderBookL2","action":"delete","data":[{"symbol":"LTCUSD","id":40699968684,"side":"Sell"}]}
1618677681.9752781: {"table":"orderBookL2","action":"update","data":[{"symbol":"LTCUSD","id":40699968673,"side":"Sell","size":247}]}
1618677681.988534: {"table":"orderBookL2","action":"delete","data":[{"symbol":"DOGEUSDT","id":47599971787,"side":"Buy"}]}
1618677681.9886248: {"table":"orderBookL2","action":"insert","data":[{"symbol":"DOGEUSDT","id":47599971786,"side":"Buy","size":2110,"price":0.28214}]}
1618677681.988693: {"table":"orderBookL2","action":"update","data":[{"symbol":"LTCUSD","id":40699968656,"side":"Sell","size":5038}]}
1618677681.991551: {"table":"orderBookL2","action":"delete","data":[{"symbol":"LTCUSD","id":40699968673,"side":"Sell"}]}
1618677682.005545: {"table":"orderBookL2","action":"update","data":[{"symbol":"DOGEUSDT","id":47599971512,"side":"Sell","size":50}]}
1618677682.005619: {"table":"orderBookL2","action":"insert","data":[{"symbol":"DOGEUSDT","id":47599971514,"side":"Sell","size":300,"price":0.28486}]}
1618677682.0077162: {"table":"orderBookL2","action":"delete","data":[{"symbol":"LINKUSDTM21","id":52799882610,"side":"Sell"}]}
1618677682.0193338: {"table":"orderBookL2","action":"delete","data":[{"symbol":"DOGEUSDT","id":47599971513,"side":"Sell"}]}
1618677682.01942: {"table":"orderBookL2","action":"insert","data":[{"symbol":"DOGEUSDT","id":47599971515,"side":"Sell","size":603,"price":0.28485}]}
1618677682.0236428: {"table":"orderBookL2","action":"delete","data":[{"symbol":"LTCUSD","id":40699968193,"side":"Sell"},{"symbol":"LTCUSD","id":40699969018,"side":"Buy"}]}
1618677682.0237398: {"table":"orderBookL2","action":"update","data":[{"symbol":"LTCUSD","id":40699969222,"side":"Buy","size":1828}]}
1618677682.023788: {"table":"orderBookL2","action":"insert","data":[{"symbol":"LTCUSD","id":40699968194,"side":"Sell","size":579,"price":318.06},{"symbol":"LTCUSD","id":40699969015,"side":"Buy","size":579,"price":309.85},{"symbol":"LTCUSD","id":40699969218,"side":"Buy","size":579,"price":307.82}]}
1618677682.026923: {"table":"orderBookL2","action":"delete","data":[{"symbol":"LTCUSD","id":40699968657,"side":"Sell"}]}
1618677682.0270112: {"table":"orderBookL2","action":"update","data":[{"symbol":"LTCUSD","id":40699968619,"side":"Sell","size":621}]}
1618677682.040719: {"table":"orderBookL2","action":"delete","data":[{"symbol":"LTCUSD","id":40699968688,"side":"Sell"}]}
1618677682.040786: {"table":"orderBookL2","action":"insert","data":[{"symbol":"LTCUSD","id":40699968674,"side":"Sell","size":105,"price":313.26}]}
1618677682.053459: {"table":"orderBookL2","action":"delete","data":[{"symbol":"LTCUSD","id":40699968696,"side":"Sell"}]}
1618677682.0588212: {"table":"orderBookL2","action":"update","data":[{"symbol":"LTCUSD","id":40699968668,"side":"Sell","size":218}]}
1618677682.0628538: {"table":"orderBookL2","action":"insert","data":[{"symbol":"LTCUSD","id":40699968743,"side":"Buy","size":68,"price":312.57}]}
1618677682.062921: {"table":"orderBookL2","action":"delete","data":[{"symbol":"LTCUSD","id":40699968691,"side":"Sell"}]}
1618677682.071527: {"table":"orderBookL2","action":"insert","data":[{"symbol":"LTCUSD","id":40699968664,"side":"Sell","size":247,"price":313.36}]}
1618677682.074767: {"table":"orderBookL2","action":"delete","data":[{"symbol":"LTCUSD","id":40699968668,"side":"Sell"}]}
1618677682.077865: {"table":"orderBookL2","action":"delete","data":[{"symbol":"LTCUSD","id":40699968655,"side":"Sell"}]}
1618677682.077952: {"table":"orderBookL2","action":"insert","data":[{"symbol":"LTCUSD","id":40699968742,"side":"Buy","size":1,"price":312.58}]}
1618677682.081451: {"table":"orderBookL2","action":"delete","data":[{"symbol":"LTCUSD","id":40699968744,"side":"Buy"}]}
1618677682.081568: {"table":"orderBookL2","action":"update","data":[{"symbol":"EOSM21","id":52499998730,"side":"Sell","size":322}]}
1618677682.0856671: {"table":"orderBookL2","action":"insert","data":[{"symbol":"LTCUSD","id":40699968666,"side":"Sell","size":538,"price":313.34}]}
1618677682.089757: {"table":"orderBookL2","action":"update","data":[{"symbol":"TRXUSDT","id":53999983906,"side":"Sell","size":500}]}
1618677682.095299: {"table":"orderBookL2","action":"delete","data":[{"symbol":"LTCM21","id":52899998918,"side":"Sell"},{"symbol":"LTCM21","id":52899998930,"side":"Sell"},{"symbol":"LTCM21","id":52899998955,"side":"Buy"},{"symbol":"LTCM21","id":52899998968,"side":"Buy"},{"symbol":"LTCM21","id":52899998971,"side":"Buy"}]}
1618677682.095435: {"table":"orderBookL2","action":"update","data":[{"symbol":"LTCM21","id":52899998914,"side":"Sell","size":1},{"symbol":"LTCM21","id":52899998916,"side":"Sell","size":58},{"symbol":"LTCM21","id":52899998919,"side":"Sell","size":355},{"symbol":"LTCM21","id":52899998921,"side":"Sell","size":197},{"symbol":"LTCM21","id":52899998922,"side":"Sell","size":491},{"symbol":"LTCM21","id":52899998924,"side":"Sell","size":479},{"symbol":"LTCM21","id":52899998925,"side":"Sell","size":499},{"symbol":"LTCM21","id":52899998927,"side":"Sell","size":198},{"symbol":"LTCM21","id":52899998929,"side":"Sell","size":303},{"symbol":"LTCM21","id":52899998932,"side":"Sell","size":280},{"symbol":"LTCM21","id":52899998933,"side":"Sell","size":228},{"symbol":"LTCM21","id":52899998935,"side":"Sell","size":202},{"symbol":"LTCM21","id":52899998937,"side":"Sell","size":200},{"symbol":"LTCM21","id":52899998938,"side":"Sell","size":306},{"symbol":"LTCM21","id":52899998940,"side":"Sell","size":276},{"symbol":"LTCM21","id":52899998941,"side":"Sell","size":54},{"symbol":"LTCM21","id":52899998943,"side":"Sell","size":66},{"symbol":"LTCM21","id":52899998949,"side":"Buy","size":24},{"symbol":"LTCM21","id":52899998950,"side":"Buy","size":205},{"symbol":"LTCM21","id":52899998952,"side":"Buy","size":374},{"symbol":"LTCM21","id":52899998954,"side":"Buy","size":205},{"symbol":"LTCM21","id":52899998957,"side":"Buy","size":207},{"symbol":"LTCM21","id":52899998958,"side":"Buy","size":277},{"symbol":"LTCM21","id":52899998960,"side":"Buy","size":350},{"symbol":"LTCM21","id":52899998962,"side":"Buy","size":1},{"symbol":"LTCM21","id":52899998963,"side":"Buy","size":511},{"symbol":"LTCM21","id":52899998965,"side":"Buy","size":206},{"symbol":"LTCM21","id":52899998966,"side":"Buy","size":152},{"symbol":"LTCM21","id":52899998969,"side":"Buy","size":212},{"symbol":"LTCM21","id":52899998974,"side":"Buy","size":6},{"symbol":"LTCM21","id":52899998976,"side":"Buy","size":563},{"symbol":"LTCM21","id":52899998977,"side":"Buy","size":89}]}
1618677682.0956259: {"table":"orderBookL2","action":"insert","data":[{"symbol":"LTCM21","id":52899998913,"side":"Sell","size":9,"price":0.005435},{"symbol":"LTCM21","id":52899998947,"side":"Buy","size":2,"price":0.005265},{"symbol":"LTCM21","id":52899998973,"side":"Buy","size":8,"price":0.005135}]}
1618677682.097245: {"table":"orderBookL2","action":"insert","data":[{"symbol":"XLMUSDT","id":52199939269,"side":"Buy","size":58,"price":0.60731}]}
1618677682.102412: {"table":"orderBookL2","action":"delete","data":[{"symbol":"XLMUSDT","id":52199938982,"side":"Sell"}]}
1618677682.105313: {"table":"orderBookL2","action":"delete","data":[{"symbol":"TRXUSDT","id":53999983895,"side":"Sell"}]}
1618677682.1080651: {"table":"orderBookL2","action":"delete","data":[{"symbol":"EOSUSDT","id":53899984150,"side":"Buy"}]}
1618677682.108125: {"table":"orderBookL2","action":"insert","data":[{"symbol":"EOSUSDT","id":53899984139,"side":"Buy","size":200,"price":7.9305}]}
1618677682.10994: {"table":"orderBookL2","action":"delete","data":[{"symbol":"LTCUSD","id":40699968742,"side":"Buy"}]}
1618677682.109998: {"table":"orderBookL2","action":"delete","data":[{"symbol":"EOSUSDT","id":53899984109,"side":"Sell"}]}
1618677682.119264: {"table":"orderBookL2","action":"delete","data":[{"symbol":"LTCUSD","id":40699968664,"side":"Sell"}]}
1618677682.119352: {"table":"orderBookL2","action":"insert","data":[{"symbol":"EOSUSDT","id":53899984099,"side":"Sell","size":1000,"price":7.9505}]}
1618677682.1292002: {"table":"orderBookL2","action":"delete","data":[{"symbol":"EOSM21","id":52499998732,"side":"Sell"}]}
1618677682.1297028: {"table":"orderBookL2","action":"update","data":[{"symbol":"EOSM21","id":52499998733,"side":"Buy","size":1200}]}
1618677682.129964: {"table":"orderBookL2","action":"delete","data":[{"symbol":"LTCUSD","id":40699968757,"side":"Buy"}]}
1618677682.13204: {"table":"orderBookL2","action":"insert","data":[{"symbol":"EOSM21","id":52499998732,"side":"Buy","size":330,"price":0.0001268}]}
1618677682.135263: {"table":"orderBookL2","action":"delete","data":[{"symbol":"XLMUSDT","id":52199939361,"side":"Buy"}]}
1618677682.135351: {"table":"orderBookL2","action":"insert","data":[{"symbol":"XLMUSDT","id":52199939339,"side":"Buy","size":112,"price":0.60661}]}
1618677682.136107: {"table":"orderBookL2","action":"insert","data":[{"symbol":"XLMUSDT","id":52199939055,"side":"Sell","size":232,"price":0.60945}]}
1618677682.146097: {"table":"orderBookL2","action":"insert","data":[{"symbol":"LTCUSD","id":40699968734,"side":"Buy","size":5000,"price":312.66}]}
1618677682.1461911: {"table":"orderBookL2","action":"update","data":[{"symbol":"EOSM21","id":52499998732,"side":"Buy","size":1530}]}
1618677682.159796: {"table":"orderBookL2","action":"delete","data":[{"symbol":"LTCUSD","id":40699968750,"side":"Buy"}]}
1618677682.173641: {"table":"orderBookL2","action":"delete","data":[{"symbol":"DOGEUSDT","id":47599971512,"side":"Sell"}]}
1618677682.173704: {"table":"orderBookL2","action":"update","data":[{"symbol":"DOGEUSDT","id":47599971385,"side":"Sell","size":67}]}
1618677682.191218: {"table":"orderBookL2","action":"insert","data":[{"symbol":"DOGEUSDT","id":47599971568,"side":"Sell","size":248,"price":0.28432},{"symbol":"DOGEUSDT","id":47599971677,"side":"Buy","size":4000,"price":0.28323}]}
1618677682.1932092: {"table":"orderBookL2","action":"delete","data":[{"symbol":"EOSM21","id":52499998731,"side":"Sell"}]}
1618677682.204927: {"table":"orderBookL2","action":"delete","data":[{"symbol":"DOGEUSDT","id":47599971782,"side":"Buy"}]}
1618677682.2050161: {"table":"orderBookL2","action":"delete","data":[{"symbol":"DOGEUSDT","id":47599971508,"side":"Sell"}]}
1618677682.207343: {"table":"orderBookL2","action":"delete","data":[{"symbol":"DOGEUSDT","id":47599971835,"side":"Buy"}]}
1618677682.2074292: {"table":"orderBookL2","action":"insert","data":[{"symbol":"EOSM21","id":52499998731,"side":"Buy","size":330,"price":0.0001269}]}
1618677682.2080681: {"table":"orderBookL2","action":"update","data":[{"symbol":"EOSM21","id":52499998732,"side":"Buy","size":1200}]}
1618677682.224493: {"table":"orderBookL2","action":"update","data":[{"symbol":"EOSM21","id":52499998730,"side":"Sell","size":652}]}
1618677682.245952: {"table":"orderBookL2","action":"update","data":[{"symbol":"ADAM21","id":52299997829,"side":"Sell","size":35000}]}
1618677682.254551: {"table":"orderBookL2","action":"update","data":[{"symbol":"TRXM21","id":52999999757,"side":"Sell","size":3504180}]}
1618677682.278435: {"table":"orderBookL2","action":"update","data":[{"symbol":"TRXM21","id":52999999758,"side":"Buy","size":33000}]}
1618677682.283103: {"table":"orderBookL2","action":"delete","data":[{"symbol":"EOSUSDT","id":53899984141,"side":"Buy"}]}
1618677682.288563: {"table":"orderBookL2","action":"delete","data":[{"symbol":"LINKUSDTM21","id":52799885862,"side":"Sell"}]}
1618677682.2948742: {"table":"orderBookL2","action":"insert","data":[{"symbol":"EOSUSDT","id":53899984131,"side":"Buy","size":1000,"price":7.9345}]}
1618677682.2982059: {"table":"orderBookL2","action":"insert","data":[{"symbol":"LTCUSD","id":40699968675,"side":"Sell","size":125,"price":313.25},{"symbol":"LTCUSD","id":40699968733,"side":"Buy","size":125,"price":312.67}]}
1618677682.31107: {"table":"orderBookL2","action":"insert","data":[{"symbol":"TRXUSDT","id":53999983876,"side":"Sell","size":484,"price":0.16124}]}
1618677682.311164: {"table":"orderBookL2","action":"delete","data":[{"symbol":"TRXUSDT","id":53999983888,"side":"Sell"}]}
1618677682.314183: {"table":"orderBookL2","action":"delete","data":[{"symbol":"LTCUSD","id":40699968762,"side":"Buy"}]}
1618677682.317683: {"table":"orderBookL2","action":"delete","data":[{"symbol":"EOSUSDT","id":53899984099,"side":"Sell"}]}
1618677682.318518: {"table":"orderBookL2","action":"delete","data":[{"symbol":"LTCUSD","id":40699968777,"side":"Buy"}]}
1618677682.319768: {"table":"orderBookL2","action":"insert","data":[{"symbol":"LTCUSD","id":40699968760,"side":"Buy","size":133,"price":312.4}]}
1618677682.329376: {"table":"orderBookL2","action":"insert","data":[{"symbol":"LTCUSD","id":40699968748,"side":"Buy","size":20,"price":312.52}]}
1618677682.335742: {"table":"orderBookL2","action":"insert","data":[{"symbol":"EOSUSDT","id":53899984087,"side":"Sell","size":1000,"price":7.9565}]}
1618677682.340208: {"table":"orderBookL2","action":"delete","data":[{"symbol":"DOGEUSDT","id":47599971959,"side":"Buy"}]}
1618677682.340296: {"table":"orderBookL2","action":"insert","data":[{"symbol":"DOGEUSDT","id":47599971937,"side":"Buy","size":154,"price":0.28063}]}
1618677682.3507571: {"table":"orderBookL2","action":"update","data":[{"symbol":"TRXM21","id":52999999760,"side":"Buy","size":453141},{"symbol":"TRXM21","id":52999999764,"side":"Buy","size":175600}]}
1618677682.390003: {"table":"orderBookL2","action":"insert","data":[{"symbol":"LINKUSDTM21","id":52799886502,"side":"Buy","size":100,"price":56.749}]}
1618677682.399591: {"table":"orderBookL2","action":"update","data":[{"symbol":"LTCUSD","id":40699968656,"side":"Sell","size":5256}]}
1618677682.406058: {"table":"orderBookL2","action":"insert","data":[{"symbol":"LINKUSDTM21","id":52799886532,"side":"Buy","size":4,"price":56.734}]}
1618677682.414911: {"table":"orderBookL2","action":"delete","data":[{"symbol":"LTCUSD","id":40699968749,"side":"Buy"}]}
1618677682.414998: {"table":"orderBookL2","action":"insert","data":[{"symbol":"LTCUSD","id":40699968732,"side":"Buy","size":247,"price":312.68}]}
1618677682.42549: {"table":"orderBookL2","action":"insert","data":[{"symbol":"LTCUSD","id":40699968737,"side":"Buy","size":90,"price":312.63}]}
1618677682.4601731: {"table":"orderBookL2","action":"delete","data":[{"symbol":"XLMUSDT","id":52199939138,"side":"Sell"}]}
1618677682.460238: {"table":"orderBookL2","action":"insert","data":[{"symbol":"XLMUSDT","id":52199939056,"side":"Sell","size":178,"price":0.60944}]}
1618677682.4974442: {"table":"orderBookL2","action":"delete","data":[{"symbol":"DOGEUSDT","id":47599971879,"side":"Buy"},{"symbol":"DOGEUSDT","id":47599971880,"side":"Buy"},{"symbol":"DOGEUSDT","id":47599971881,"side":"Buy"},{"symbol":"DOGEUSDT","id":47599971883,"side":"Buy"}]}
1618677682.497566: {"table":"orderBookL2","action":"update","data":[{"symbol":"DOGEUSDT","id":47599971882,"side":"Buy","size":1179}]}
1618677682.5028238: {"table":"orderBookL2","action":"update","data":[{"symbol":"ADAM21","id":52299997835,"side":"Buy","size":28050}]}
1618677682.5092108: {"table":"orderBookL2","action":"delete","data":[{"symbol":"DOGEUSDT","id":47599971514,"side":"Sell"}]}
1618677682.509301: {"table":"orderBookL2","action":"insert","data":[{"symbol":"DOGEUSDT","id":47599971516,"side":"Sell","size":300,"price":0.28484}]}
1618677682.5112362: {"table":"orderBookL2","action":"insert","data":[{"symbol":"DOGEUSDT","id":47599971842,"side":"Buy","size":100,"price":0.28158},{"symbol":"DOGEUSDT","id":47599971843,"side":"Buy","size":100,"price":0.28157},{"symbol":"DOGEUSDT","id":47599971844,"side":"Buy","size":100,"price":0.28156},{"symbol":"DOGEUSDT","id":47599971845,"side":"Buy","size":100,"price":0.28155},{"symbol":"DOGEUSDT","id":47599971846,"side":"Buy","size":100,"price":0.28154}]}
1618677682.549831: {"table":"orderBookL2","action":"update","data":[{"symbol":"LTCM21","id":52899998944,"side":"Sell","size":5}]}
1618677682.5505311: {"table":"orderBookL2","action":"delete","data":[{"symbol":"DOGEUSDT","id":47599971515,"side":"Sell"}]}
1618677682.5509079: {"table":"orderBookL2","action":"insert","data":[{"symbol":"DOGEUSDT","id":47599971569,"side":"Sell","size":601,"price":0.28431}]}
1618677682.56054: {"table":"orderBookL2","action":"update","data":[{"symbol":"TRXUSDT","id":53999983887,"side":"Sell","size":1905}]}
1618677682.5647528: {"table":"orderBookL2","action":"update","data":[{"symbol":"TRXM21","id":52999999763,"side":"Buy","size":125144},{"symbol":"TRXM21","id":52999999768,"side":"Buy","size":167838}]}
1618677682.566849: {"table":"orderBookL2","action":"delete","data":[{"symbol":"DOGEUSDT","id":47599971516,"side":"Sell"}]}
1618677682.5892549: {"table":"orderBookL2","action":"delete","data":[{"symbol":"DOGEUSDT","id":47599971677,"side":"Buy"}]}
1618677682.5960472: {"table":"orderBookL2","action":"delete","data":[{"symbol":"LINKUSDTM21","id":52799885006,"side":"Sell"}]}
1618677682.607689: {"table":"orderBookL2","action":"insert","data":[{"symbol":"LINKUSDTM21","id":52799884948,"side":"Sell","size":330,"price":57.526}]}
1618677682.650667: {"table":"orderBookL2","action":"update","data":[{"symbol":"TRXM21","id":52999999758,"side":"Buy","size":10000}]}
1618677682.650741: {"table":"orderBookL2","action":"delete","data":[{"symbol":"XLMUSDT","id":52199939258,"side":"Buy"}]}
1618677682.659153: {"table":"orderBookL2","action":"insert","data":[{"symbol":"XLMUSDT","id":52199939221,"side":"Buy","size":500,"price":0.60779}]}
1618677682.6618629: {"table":"orderBookL2","action":"delete","data":[{"symbol":"XLMUSDT","id":52199939255,"side":"Buy"}]}
1618677682.661949: {"table":"orderBookL2","action":"insert","data":[{"symbol":"XLMUSDT","id":52199939220,"side":"Buy","size":58,"price":0.6078}]}
1618677682.665945: {"table":"orderBookL2","action":"delete","data":[{"symbol":"XLMUSDT","id":52199939487,"side":"Buy"}]}
1618677682.6660311: {"table":"orderBookL2","action":"insert","data":[{"symbol":"XLMUSDT","id":52199939466,"side":"Buy","size":100,"price":0.60534}]}
1618677682.6692412: {"table":"orderBookL2","action":"update","data":[{"symbol":"TRXM21","id":52999999757,"side":"Sell","size":3540308}]}
1618677682.674874: {"table":"orderBookL2","action":"insert","data":[{"symbol":"XLMUSDT","id":52199939229,"side":"Buy","size":60,"price":0.60771}]}
1618677682.76394: {"table":"orderBookL2","action":"delete","data":[{"symbol":"DOGEUSDT","id":47599970282,"side":"Sell"},{"symbol":"DOGEUSDT","id":47599970708,"side":"Sell"},{"symbol":"DOGEUSDT","id":47599970849,"side":"Sell"},{"symbol":"DOGEUSDT","id":47599970991,"side":"Sell"},{"symbol":"DOGEUSDT","id":47599971133,"side":"Sell"},{"symbol":"DOGEUSDT","id":47599971417,"side":"Sell"},{"symbol":"DOGEUSDT","id":47599971506,"side":"Sell"},{"symbol":"DOGEUSDT","id":47599971784,"side":"Buy"},{"symbol":"DOGEUSDT","id":47599971926,"side":"Buy"},{"symbol":"DOGEUSDT","id":47599972068,"side":"Buy"},{"symbol":"DOGEUSDT","id":47599972210,"side":"Buy"},{"symbol":"DOGEUSDT","id":47599972352,"side":"Buy"},{"symbol":"DOGEUSDT","id":47599972494,"side":"Buy"},{"symbol":"DOGEUSDT","id":47599972635,"side":"Buy"},{"symbol":"DOGEUSDT","id":47599972777,"side":"Buy"},{"symbol":"DOGEUSDT","id":47599972919,"side":"Buy"},{"symbol":"DOGEUSDT","id":47599973061,"side":"Buy"}]}
1618677682.7641048: {"table":"orderBookL2","action":"update","data":[{"symbol":"DOGEUSDT","id":47599970424,"side":"Sell","size":2162},{"symbol":"DOGEUSDT","id":47599970566,"side":"Sell","size":3},{"symbol":"DOGEUSDT","id":47599970650,"side":"Sell","size":176},{"symbol":"DOGEUSDT","id":47599971275,"side":"Sell","size":100}]}
1618677682.764149: {"table":"orderBookL2","action":"insert","data":[{"symbol":"DOGEUSDT","id":47599970224,"side":"Sell","size":126,"price":0.29776},{"symbol":"DOGEUSDT","id":47599970366,"side":"Sell","size":126,"price":0.29634},{"symbol":"DOGEUSDT","id":47599970508,"side":"Sell","size":126,"price":0.29492},{"symbol":"DOGEUSDT","id":47599970792,"side":"Sell","size":110,"price":0.29208},{"symbol":"DOGEUSDT","id":47599970934,"side":"Sell","size":90,"price":0.29066},{"symbol":"DOGEUSDT","id":47599971076,"side":"Sell","size":70,"price":0.28924},{"symbol":"DOGEUSDT","id":47599971218,"side":"Sell","size":50,"price":0.28782},{"symbol":"DOGEUSDT","id":47599971359,"side":"Sell","size":37,"price":0.28641},{"symbol":"DOGEUSDT","id":47599971501,"side":"Sell","size":37,"price":0.28499},{"symbol":"DOGEUSDT","id":47599971726,"side":"Buy","size":37,"price":0.28274},{"symbol":"DOGEUSDT","id":47599971868,"side":"Buy","size":43,"price":0.28132},{"symbol":"DOGEUSDT","id":47599972010,"side":"Buy","size":75,"price":0.2799},{"symbol":"DOGEUSDT","id":47599972152,"side":"Buy","size":107,"price":0.27848},{"symbol":"DOGEUSDT","id":47599972294,"side":"Buy","size":140,"price":0.27706},{"symbol":"DOGEUSDT","id":47599972436,"side":"Buy","size":172,"price":0.27564},{"symbol":"DOGEUSDT","id":47599972578,"side":"Buy","size":186,"price":0.27422},{"symbol":"DOGEUSDT","id":47599972720,"side":"Buy","size":186,"price":0.2728},{"symbol":"DOGEUSDT","id":47599972861,"side":"Buy","size":186,"price":0.27139},{"symbol":"DOGEUSDT","id":47599973003,"side":"Buy","size":186,"price":0.26997}]}
1618677682.785142: {"table":"orderBookL2","action":"delete","data":[{"symbol":"XLMUSDT","id":52199939339,"side":"Buy"}]}
1618677682.785221: {"table":"orderBookL2","action":"insert","data":[{"symbol":"XLMUSDT","id":52199939318,"side":"Buy","size":112,"price":0.60682}]}
1618677682.799119: {"table":"orderBookL2","action":"delete","data":[{"symbol":"LINKUSDTM21","id":52799885814,"side":"Sell"}]}
1618677682.835176: {"table":"orderBookL2","action":"insert","data":[{"symbol":"TRXUSDT","id":53999983901,"side":"Sell","size":402,"price":0.16099}]}
1618677682.856777: {"table":"orderBookL2","action":"delete","data":[{"symbol":"LTCUSD","id":40699968194,"side":"Sell"},{"symbol":"LTCUSD","id":40699968414,"side":"Sell"},{"symbol":"LTCUSD","id":40699969218,"side":"Buy"}]}
1618677682.856891: {"table":"orderBookL2","action":"update","data":[{"symbol":"LTCUSD","id":40699968494,"side":"Sell","size":668},{"symbol":"LTCUSD","id":40699968508,"side":"Sell","size":300},{"symbol":"LTCUSD","id":40699968910,"side":"Buy","size":2389},{"symbol":"LTCUSD","id":40699968948,"side":"Buy","size":2149}]}
1618677682.856956: {"table":"orderBookL2","action":"insert","data":[{"symbol":"LTCUSD","id":40699968164,"side":"Sell","size":579,"price":318.36},{"symbol":"LTCUSD","id":40699968393,"side":"Sell","size":579,"price":316.07},{"symbol":"LTCUSD","id":40699969225,"side":"Buy","size":579,"price":307.75}]}
1618677682.8673139: {"table":"orderBookL2","action":"delete","data":[{"symbol":"EOSM21","id":52499998724,"side":"Sell"}]}
1618677682.8791308: {"table":"orderBookL2","action":"insert","data":[{"symbol":"LTCUSD","id":40699968736,"side":"Buy","size":236,"price":312.64}]}
1618677682.8812869: {"table":"orderBookL2","action":"delete","data":[{"symbol":"DOGEUSDT","id":47599971569,"side":"Sell"}]}
1618677682.881376: {"table":"orderBookL2","action":"update","data":[{"symbol":"EOSM21","id":52499998744,"side":"Buy","size":113}]}
1618677682.882157: {"table":"orderBookL2","action":"delete","data":[{"symbol":"EOSM21","id":52499998742,"side":"Buy"}]}
1618677682.992223: {"table":"orderBookL2","action":"update","data":[{"symbol":"EOSM21","id":52499998721,"side":"Sell","size":4003}]}
1618677683.012009: {"table":"orderBookL2","action":"update","data":[{"symbol":"DOGEUSDT","id":47599971385,"side":"Sell","size":367}]}
1618677683.048695: {"table":"orderBookL2","action":"delete","data":[{"symbol":"LTCUSD","id":40699968743,"side":"Buy"}]}
1618677683.048782: {"table":"orderBookL2","action":"insert","data":[{"symbol":"LTCUSD","id":40699968731,"side":"Buy","size":68,"price":312.69}]}
1618677683.071262: {"table":"orderBookL2","action":"update","data":[{"symbol":"ADAM21","id":52299997830,"side":"Sell","size":39481}]}
1618677683.084173: {"table":"orderBookL2","action":"delete","data":[{"symbol":"ADAM21","id":52299997823,"side":"Sell"}]}
1618677683.08426: {"table":"orderBookL2","action":"insert","data":[{"symbol":"ADAM21","id":52299997817,"side":"Sell","size":536,"price":0.00002183}]}
1618677683.148247: {"table":"orderBookL2","action":"delete","data":[{"symbol":"EOSUSDT","id":53899984036,"side":"Sell"}]}
1618677683.148362: {"table":"orderBookL2","action":"insert","data":[{"symbol":"EOSUSDT","id":53899984017,"side":"Sell","size":496,"price":7.9915}]}
1618677683.1925938: {"table":"orderBookL2","action":"update","data":[{"symbol":"XLMUSDT","id":52199939033,"side":"Sell","size":18}]}
1618677683.192692: {"table":"orderBookL2","action":"insert","data":[{"symbol":"XLMUSDT","id":52199938831,"side":"Sell","size":475,"price":0.61169}]}
1618677683.232343: {"table":"orderBookL2","action":"delete","data":[{"symbol":"LTCUSD","id":40699968164,"side":"Sell"},{"symbol":"LTCUSD","id":40699968393,"side":"Sell"},{"symbol":"LTCUSD","id":40699969015,"side":"Buy"},{"symbol":"LTCUSD","id":40699969225,"side":"Buy"}]}
1618677683.2324722: {"table":"orderBookL2","action":"insert","data":[{"symbol":"LTCUSD","id":40699968170,"side":"Sell","size":579,"price":318.3},{"symbol":"LTCUSD","id":40699968395,"side":"Sell","size":579,"price":316.05},{"symbol":"LTCUSD","id":40699969009,"side":"Buy","size":579,"price":309.91},{"symbol":"LTCUSD","id":40699969216,"side":"Buy","size":579,"price":307.84}]}
1618677683.2447: {"table":"orderBookL2","action":"insert","data":[{"symbol":"LTCUSD","id":40699968665,"side":"Sell","size":236,"price":313.35}]}
1618677683.350282: {"table":"orderBookL2","action":"insert","data":[{"symbol":"DOGEUSDT","id":47599971569,"side":"Sell","size":1343,"price":0.28431}]}
1618677683.3720121: {"table":"orderBookL2","action":"delete","data":[{"symbol":"LTCUSD","id":40699968748,"side":"Buy"}]}
1618677683.395185: {"table":"orderBookL2","action":"delete","data":[{"symbol":"LTCUSD","id":40699968736,"side":"Buy"}]}
1618677683.415338: {"table":"orderBookL2","action":"delete","data":[{"symbol":"LTCUSD","id":40699968170,"side":"Sell"},{"symbol":"LTCUSD","id":40699968395,"side":"Sell"},{"symbol":"LTCUSD","id":40699969009,"side":"Buy"},{"symbol":"LTCUSD","id":40699969216,"side":"Buy"}]}
1618677683.415495: {"table":"orderBookL2","action":"insert","data":[{"symbol":"LTCUSD","id":40699968167,"side":"Sell","size":579,"price":318.33},{"symbol":"LTCUSD","id":40699968394,"side":"Sell","size":579,"price":316.06},{"symbol":"LTCUSD","id":40699969011,"side":"Buy","size":579,"price":309.89},{"symbol":"LTCUSD","id":40699969219,"side":"Buy","size":579,"price":307.81}]}
1618677683.426178: {"table":"orderBookL2","action":"update","data":[{"symbol":"DOGEUSDT","id":47599971385,"side":"Sell","size":317}]}
1618677683.426281: {"table":"orderBookL2","action":"insert","data":[{"symbol":"DOGEUSDT","id":47599971570,"side":"Sell","size":50,"price":0.2843}]}
1618677683.445407: {"table":"orderBookL2","action":"update","data":[{"symbol":"DOGEUSDT","id":47599971385,"side":"Sell","size":17},{"symbol":"DOGEUSDT","id":47599971570,"side":"Sell","size":350}]}
1618677683.456177: {"table":"orderBookL2","action":"delete","data":[{"symbol":"LTCUSD","id":40699968732,"side":"Buy"}]}
1618677683.46363: {"table":"orderBookL2","action":"delete","data":[{"symbol":"LTCUSD","id":40699968733,"side":"Buy"}]}
1618677683.465512: {"table":"orderBookL2","action":"delete","data":[{"symbol":"LTCUSD","id":40699968737,"side":"Buy"}]}
1618677683.479359: {"table":"orderBookL2","action":"delete","data":[{"symbol":"XLMUSDT","id":52199939318,"side":"Buy"}]}
1618677683.522238: {"table":"orderBookL2","action":"delete","data":[{"symbol":"LTCUSD","id":40699968167,"side":"Sell"},{"symbol":"LTCUSD","id":40699968394,"side":"Sell"},{"symbol":"LTCUSD","id":40699969011,"side":"Buy"},{"symbol":"LTCUSD","id":40699969219,"side":"Buy"}]}
1618677683.522345: {"table":"orderBookL2","action":"update","data":[{"symbol":"LTCUSD","id":40699968494,"side":"Sell","size":89},{"symbol":"LTCUSD","id":40699968508,"side":"Sell","size":879},{"symbol":"LTCUSD","id":40699968910,"side":"Buy","size":1810},{"symbol":"LTCUSD","id":40699968948,"side":"Buy","size":2728}]}
1618677683.523581: {"table":"orderBookL2","action":"insert","data":[{"symbol":"LTCUSD","id":40699968168,"side":"Sell","size":579,"price":318.32},{"symbol":"LTCUSD","id":40699968396,"side":"Sell","size":579,"price":316.04},{"symbol":"LTCUSD","id":40699969015,"side":"Buy","size":579,"price":309.85},{"symbol":"LTCUSD","id":40699969225,"side":"Buy","size":579,"price":307.75}]}
1618677683.535945: {"table":"orderBookL2","action":"delete","data":[{"symbol":"XLMUSDT","id":52199939269,"side":"Buy"}]}
1618677683.54044: {"table":"orderBookL2","action":"delete","data":[{"symbol":"XLMUSDT","id":52199939229,"side":"Buy"}]}
1618677683.541588: {"table":"orderBookL2","action":"update","data":[{"symbol":"DOGEUSDT","id":47599971570,"side":"Sell","size":50}]}
1618677683.563353: {"table":"orderBookL2","action":"delete","data":[{"symbol":"LTCUSD","id":40699968665,"side":"Sell"}]}
1618677683.563474: {"table":"orderBookL2","action":"insert","data":[{"symbol":"LTCUSD","id":40699968676,"side":"Sell","size":236,"price":313.24}]}
1618677683.581908: {"table":"orderBookL2","action":"delete","data":[{"symbol":"LTCUSD","id":40699968168,"side":"Sell"},{"symbol":"LTCUSD","id":40699968396,"side":"Sell"},{"symbol":"LTCUSD","id":40699969225,"side":"Buy"}]}
1618677683.582027: {"table":"orderBookL2","action":"insert","data":[{"symbol":"LTCUSD","id":40699968175,"side":"Sell","size":579,"price":318.25},{"symbol":"LTCUSD","id":40699968400,"side":"Sell","size":579,"price":316},{"symbol":"LTCUSD","id":40699969223,"side":"Buy","size":579,"price":307.77}]}
1618677683.583837: {"table":"orderBookL2","action":"insert","data":[{"symbol":"LTCUSD","id":40699968661,"side":"Sell","size":247,"price":313.39}]}
1618677683.5927172: {"table":"orderBookL2","action":"delete","data":[{"symbol":"DOGEUSDT","id":47599971568,"side":"Sell"}]}
1618677683.670678: {"table":"orderBookL2","action":"insert","data":[{"symbol":"XLMUSDT","id":52199939333,"side":"Buy","size":112,"price":0.60667}]}
1618677683.6758919: {"table":"orderBookL2","action":"update","data":[{"symbol":"TRXM21","id":52999999760,"side":"Buy","size":201189},{"symbol":"TRXM21","id":52999999764,"side":"Buy","size":427552}]}
1618677683.79955: {"table":"orderBookL2","action":"delete","data":[{"symbol":"DOGEUSDT","id":47599971786,"side":"Buy"}]}
1618677683.799666: {"table":"orderBookL2","action":"insert","data":[{"symbol":"DOGEUSDT","id":47599971783,"side":"Buy","size":2110,"price":0.28217}]}
1618677683.813097: {"table":"orderBookL2","action":"insert","data":[{"symbol":"LTCUSD","id":40699968762,"side":"Buy","size":20,"price":312.38}]}
1618677683.813199: {"table":"orderBookL2","action":"delete","data":[{"symbol":"EOSM21","id":52499998770,"side":"Buy"}]}
1618677683.813257: {"table":"orderBookL2","action":"update","data":[{"symbol":"EOSM21","id":52499998766,"side":"Buy","size":9649}]}
1618677683.820714: {"table":"orderBookL2","action":"delete","data":[{"symbol":"DOGEUSDT","id":47599971569,"side":"Sell"}]}
1618677683.820802: {"table":"orderBookL2","action":"insert","data":[{"symbol":"DOGEUSDT","id":47599971571,"side":"Sell","size":822,"price":0.28429}]}
1618677683.8613381: {"table":"orderBookL2","action":"insert","data":[{"symbol":"ADAM21","id":52299997831,"side":"Sell","size":4300,"price":0.00002169}]}
1618677683.862037: {"table":"orderBookL2","action":"update","data":[{"symbol":"ADAM21","id":52299997830,"side":"Sell","size":35181}]}
1618677683.8706229: {"table":"orderBookL2","action":"delete","data":[{"symbol":"XLMUSDT","id":52199939294,"side":"Buy"}]}
1618677683.872737: {"table":"orderBookL2","action":"insert","data":[{"symbol":"XLMUSDT","id":52199939330,"side":"Buy","size":74,"price":0.6067}]}
1618677683.876053: {"table":"orderBookL2","action":"delete","data":[{"symbol":"ADAM21","id":52299997831,"side":"Sell"}]}
1618677683.876103: {"table":"orderBookL2","action":"update","data":[{"symbol":"EOSM21","id":52499998722,"side":"Sell","size":8439}]}
1618677683.8910668: {"table":"orderBookL2","action":"insert","data":[{"symbol":"ADAM21","id":52299997831,"side":"Sell","size":4300,"price":0.00002169}]}
1618677683.904939: {"table":"orderBookL2","action":"update","data":[{"symbol":"ADAM21","id":52299997829,"side":"Sell","size":39100}]}
1618677683.9058309: {"table":"orderBookL2","action":"delete","data":[{"symbol":"ADAM21","id":52299997831,"side":"Sell"}]}
1618677683.924475: {"table":"orderBookL2","action":"insert","data":[{"symbol":"ADAM21","id":52299997831,"side":"Sell","size":4300,"price":0.00002169}]}
1618677683.9381351: {"table":"orderBookL2","action":"delete","data":[{"symbol":"ADAM21","id":52299997831,"side":"Sell"}]}
1618677683.953799: {"table":"orderBookL2","action":"insert","data":[{"symbol":"ADAM21","id":52299997831,"side":"Sell","size":4300,"price":0.00002169}]}
1618677683.9697568: {"table":"orderBookL2","action":"delete","data":[{"symbol":"ADAM21","id":52299997831,"side":"Sell"}]}
1618677683.969845: {"table":"orderBookL2","action":"insert","data":[{"symbol":"DOGEUSDT","id":47599971572,"side":"Sell","size":300,"price":0.28428}]}
1618677683.983157: {"table":"orderBookL2","action":"insert","data":[{"symbol":"ADAM21","id":52299997831,"side":"Sell","size":4300,"price":0.00002169}]}
1618677684.000797: {"table":"orderBookL2","action":"delete","data":[{"symbol":"ADAM21","id":52299997831,"side":"Sell"}]}
1618677684.0102668: {"table":"orderBookL2","action":"update","data":[{"symbol":"TRXM21","id":52999999763,"side":"Buy","size":174609},{"symbol":"TRXM21","id":52999999768,"side":"Buy","size":118373}]}
1618677684.014634: {"table":"orderBookL2","action":"insert","data":[{"symbol":"ADAM21","id":52299997831,"side":"Sell","size":4300,"price":0.00002169}]}
1618677684.028679: {"table":"orderBookL2","action":"insert","data":[{"symbol":"LTCUSD","id":40699968730,"side":"Buy","size":1,"price":312.7}]}
1618677684.031174: {"table":"orderBookL2","action":"delete","data":[{"symbol":"ADAM21","id":52299997831,"side":"Sell"}]}
1618677684.0451431: {"table":"orderBookL2","action":"insert","data":[{"symbol":"ADAM21","id":52299997831,"side":"Sell","size":4300,"price":0.00002169}]}
1618677684.050632: {"table":"orderBookL2","action":"delete","data":[{"symbol":"EOSUSDT","id":53899984017,"side":"Sell"}]}
1618677684.0512938: {"table":"orderBookL2","action":"insert","data":[{"symbol":"EOSUSDT","id":53899984036,"side":"Sell","size":496,"price":7.982}]}
1618677684.056065: {"table":"orderBookL2","action":"insert","data":[{"symbol":"LTCUSD","id":40699968654,"side":"Sell","size":105,"price":313.46}]}
1618677684.059547: {"table":"orderBookL2","action":"delete","data":[{"symbol":"ADAM21","id":52299997831,"side":"Sell"}]}
1618677684.059629: {"table":"orderBookL2","action":"delete","data":[{"symbol":"LTCUSD","id":40699968731,"side":"Buy"}]}
1618677684.070703: {"table":"orderBookL2","action":"insert","data":[{"symbol":"LTCUSD","id":40699968679,"side":"Sell","size":432,"price":313.21}]}
1618677684.073345: {"table":"orderBookL2","action":"insert","data":[{"symbol":"ADAM21","id":52299997831,"side":"Sell","size":4300,"price":0.00002169}]}
1618677684.094154: {"table":"orderBookL2","action":"delete","data":[{"symbol":"ADAM21","id":52299997831,"side":"Sell"}]}
1618677684.094271: {"table":"orderBookL2","action":"delete","data":[{"symbol":"EOSM21","id":52499998731,"side":"Buy"}]}
1618677684.1093628: {"table":"orderBookL2","action":"insert","data":[{"symbol":"ADAM21","id":52299997831,"side":"Sell","size":4300,"price":0.00002169}]}
1618677684.109494: {"table":"orderBookL2","action":"insert","data":[{"symbol":"EOSM21","id":52499998731,"side":"Buy","size":330,"price":0.0001269}]}
1618677684.138033: {"table":"orderBookL2","action":"update","data":[{"symbol":"TRXM21","id":52999999760,"side":"Buy","size":453141},{"symbol":"TRXM21","id":52999999764,"side":"Buy","size":175600}]}
1618677684.1417458: {"table":"orderBookL2","action":"delete","data":[{"symbol":"ADAM21","id":52299997831,"side":"Sell"}]}
1618677684.147551: {"table":"orderBookL2","action":"delete","data":[{"symbol":"LTCUSD","id":40699968175,"side":"Sell"},{"symbol":"LTCUSD","id":40699968400,"side":"Sell"},{"symbol":"LTCUSD","id":40699969223,"side":"Buy"}]}
1618677684.147669: {"table":"orderBookL2","action":"insert","data":[{"symbol":"LTCUSD","id":40699968190,"side":"Sell","size":579,"price":318.1},{"symbol":"LTCUSD","id":40699968412,"side":"Sell","size":579,"price":315.88},{"symbol":"LTCUSD","id":40699969219,"side":"Buy","size":579,"price":307.81}]}
1618677684.149717: {"table":"orderBookL2","action":"delete","data":[{"symbol":"EOSM21","id":52499998731,"side":"Buy"}]}
1618677684.161431: {"table":"orderBookL2","action":"insert","data":[{"symbol":"ADAM21","id":52299997831,"side":"Sell","size":4300,"price":0.00002169}]}
1618677684.168799: {"table":"orderBookL2","action":"insert","data":[{"symbol":"EOSM21","id":52499998731,"side":"Sell","size":330,"price":0.0001269}]}
1618677684.1695812: {"table":"orderBookL2","action":"update","data":[{"symbol":"EOSM21","id":52499998730,"side":"Sell","size":322}]}
1618677684.187407: {"table":"orderBookL2","action":"update","data":[{"symbol":"LTCM21","id":52899998944,"side":"Sell","size":24}]}
1618677684.187505: {"table":"orderBookL2","action":"update","data":[{"symbol":"EOSM21","id":52499998732,"side":"Buy","size":1530}]}
1618677684.2083251: {"table":"orderBookL2","action":"insert","data":[{"symbol":"XLMUSDT","id":52199939300,"side":"Buy","size":59,"price":0.607}]}
1618677684.211492: {"table":"orderBookL2","action":"update","data":[{"symbol":"EOSUSDT","id":53899984131,"side":"Buy","size":1074}]}
1618677684.215761: {"table":"orderBookL2","action":"update","data":[{"symbol":"EOSUSDT","id":53899984166,"side":"Buy","size":14}]}
1618677684.219931: {"table":"orderBookL2","action":"delete","data":[{"symbol":"ADAM21","id":52299997831,"side":"Sell"}]}
1618677684.230788: {"table":"orderBookL2","action":"update","data":[{"symbol":"ADAM21","id":52299997830,"side":"Sell","size":39481}]}
1618677684.301282: {"table":"orderBookL2","action":"update","data":[{"symbol":"EOSM21","id":52499998743,"side":"Buy","size":979}]}
1618677684.324507: {"table":"orderBookL2","action":"delete","data":[{"symbol":"DOGEUSDT","id":47599971571,"side":"Sell"}]}
1618677684.3246279: {"table":"orderBookL2","action":"insert","data":[{"symbol":"DOGEUSDT","id":47599971573,"side":"Sell","size":822,"price":0.28427}]}
1618677684.345031: {"table":"orderBookL2","action":"delete","data":[{"symbol":"DOGEUSDT","id":47599971572,"side":"Sell"}]}
1618677684.361067: {"table":"orderBookL2","action":"insert","data":[{"symbol":"DOGEUSDT","id":47599971574,"side":"Sell","size":300,"price":0.28426}]}
1618677684.398437: {"table":"orderBookL2","action":"insert","data":[{"symbol":"DOGEUSDT","id":47599971837,"side":"Buy","size":352,"price":0.28163}]}
1618677684.409504: {"table":"orderBookL2","action":"delete","data":[{"symbol":"DOGEUSDT","id":47599970224,"side":"Sell"},{"symbol":"DOGEUSDT","id":47599970366,"side":"Sell"},{"symbol":"DOGEUSDT","id":47599970508,"side":"Sell"},{"symbol":"DOGEUSDT","id":47599970792,"side":"Sell"},{"symbol":"DOGEUSDT","id":47599970934,"side":"Sell"},{"symbol":"DOGEUSDT","id":47599971076,"side":"Sell"},{"symbol":"DOGEUSDT","id":47599971218,"side":"Sell"},{"symbol":"DOGEUSDT","id":47599971359,"side":"Sell"},{"symbol":"DOGEUSDT","id":47599971501,"side":"Sell"},{"symbol":"DOGEUSDT","id":47599971726,"side":"Buy"},{"symbol":"DOGEUSDT","id":47599971868,"side":"Buy"},{"symbol":"DOGEUSDT","id":47599972010,"side":"Buy"},{"symbol":"DOGEUSDT","id":47599972152,"side":"Buy"},{"symbol":"DOGEUSDT","id":47599972294,"side":"Buy"},{"symbol":"DOGEUSDT","id":47599972436,"side":"Buy"},{"symbol":"DOGEUSDT","id":47599972578,"side":"Buy"},{"symbol":"DOGEUSDT","id":47599972720,"side":"Buy"},{"symbol":"DOGEUSDT","id":47599972861,"side":"Buy"},{"symbol":"DOGEUSDT","id":47599973003,"side":"Buy"}]}
1618677684.409704: {"table":"orderBookL2","action":"update","data":[{"symbol":"DOGEUSDT","id":47599970286,"side":"Sell","size":176},{"symbol":"DOGEUSDT","id":47599970650,"side":"Sell","size":50}]}
1618677684.409743: {"table":"orderBookL2","action":"insert","data":[{"symbol":"DOGEUSDT","id":47599970428,"side":"Sell","size":126,"price":0.29572},{"symbol":"DOGEUSDT","id":47599970569,"side":"Sell","size":126,"price":0.29431},{"symbol":"DOGEUSDT","id":47599970711,"side":"Sell","size":126,"price":0.29289},{"symbol":"DOGEUSDT","id":47599970853,"side":"Sell","size":111,"price":0.29147},{"symbol":"DOGEUSDT","id":47599970995,"side":"Sell","size":91,"price":0.29005},{"symbol":"DOGEUSDT","id":47599971137,"side":"Sell","size":70,"price":0.28863},{"symbol":"DOGEUSDT","id":47599971278,"side":"Sell","size":50,"price":0.28722},{"symbol":"DOGEUSDT","id":47599971420,"side":"Sell","size":37,"price":0.2858},{"symbol":"DOGEUSDT","id":47599971562,"side":"Sell","size":37,"price":0.28438},{"symbol":"DOGEUSDT","id":47599971785,"side":"Buy","size":37,"price":0.28215},{"symbol":"DOGEUSDT","id":47599971927,"side":"Buy","size":43,"price":0.28073},{"symbol":"DOGEUSDT","id":47599972069,"side":"Buy","size":75,"price":0.27931},{"symbol":"DOGEUSDT","id":47599972211,"side":"Buy","size":107,"price":0.27789},{"symbol":"DOGEUSDT","id":47599972352,"side":"Buy","size":140,"price":0.27648},{"symbol":"DOGEUSDT","id":47599972494,"side":"Buy","size":172,"price":0.27506},{"symbol":"DOGEUSDT","id":47599972636,"side":"Buy","size":186,"price":0.27364},{"symbol":"DOGEUSDT","id":47599972778,"side":"Buy","size":186,"price":0.27222},{"symbol":"DOGEUSDT","id":47599972919,"side":"Buy","size":186,"price":0.27081},{"symbol":"DOGEUSDT","id":47599973061,"side":"Buy","size":186,"price":0.26939}]}
1618677684.418248: {"table":"orderBookL2","action":"delete","data":[{"symbol":"DOGEUSDT","id":47599971570,"side":"Sell"}]}
1618677684.418365: {"table":"orderBookL2","action":"update","data":[{"symbol":"DOGEUSDT","id":47599971385,"side":"Sell","size":67}]}
1618677684.4490612: {"table":"orderBookL2","action":"insert","data":[{"symbol":"LTCUSD","id":40699968813,"side":"Buy","size":106,"price":311.87}]}
1618677684.453471: {"table":"orderBookL2","action":"delete","data":[{"symbol":"DOGEUSDT","id":47599971937,"side":"Buy"}]}
1618677684.453564: {"table":"orderBookL2","action":"insert","data":[{"symbol":"DOGEUSDT","id":47599971960,"side":"Buy","size":154,"price":0.2804}]}
1618677684.4536278: {"table":"orderBookL2","action":"update","data":[{"symbol":"LTCM21","id":52899998947,"side":"Buy","size":20}]}
1618677684.545162: {"table":"orderBookL2","action":"delete","data":[{"symbol":"LTCUSD","id":40699968190,"side":"Sell"},{"symbol":"LTCUSD","id":40699968412,"side":"Sell"},{"symbol":"LTCUSD","id":40699969015,"side":"Buy"}]}
1618677684.545274: {"table":"orderBookL2","action":"insert","data":[{"symbol":"LTCUSD","id":40699968186,"side":"Sell","size":579,"price":318.14},{"symbol":"LTCUSD","id":40699968408,"side":"Sell","size":579,"price":315.92},{"symbol":"LTCUSD","id":40699969014,"side":"Buy","size":579,"price":309.86}]}
1618677684.560915: {"table":"orderBookL2","action":"insert","data":[{"symbol":"LTCUSD","id":40699968748,"side":"Buy","size":236,"price":312.52}]}
1618677684.5793998: {"table":"orderBookL2","action":"update","data":[{"symbol":"LTCUSD","id":40699968656,"side":"Sell","size":5038}]}
1618677684.5794759: {"table":"orderBookL2","action":"insert","data":[{"symbol":"LTCUSD","id":40699968664,"side":"Sell","size":218,"price":313.36}]}
1618677684.592507: {"table":"orderBookL2","action":"delete","data":[{"symbol":"LTCUSD","id":40699968675,"side":"Sell"}]}
1618677684.592596: {"table":"orderBookL2","action":"insert","data":[{"symbol":"LTCUSD","id":40699968680,"side":"Sell","size":125,"price":313.2}]}
1618677684.6073978: {"table":"orderBookL2","action":"insert","data":[{"symbol":"DOGEUSDT","id":47599971623,"side":"Sell","size":248,"price":0.28377},{"symbol":"DOGEUSDT","id":47599971719,"side":"Buy","size":4000,"price":0.28281}]}
1618677684.651378: {"table":"orderBookL2","action":"insert","data":[{"symbol":"LTCUSD","id":40699968733,"side":"Buy","size":247,"price":312.67}]}
1618677684.662336: {"table":"orderBookL2","action":"delete","data":[{"symbol":"LTCUSD","id":40699968676,"side":"Sell"}]}
1618677684.677075: {"table":"orderBookL2","action":"delete","data":[{"symbol":"DOGEUSDT","id":47599971960,"side":"Buy"}]}
1618677684.6771321: {"table":"orderBookL2","action":"insert","data":[{"symbol":"DOGEUSDT","id":47599971942,"side":"Buy","size":154,"price":0.28058}]}
1618677684.801143: {"table":"orderBookL2","action":"insert","data":[{"symbol":"LTCUSD","id":40699968735,"side":"Buy","size":247,"price":312.65}]}
1618677684.804047: {"table":"orderBookL2","action":"delete","data":[{"symbol":"LTCUSD","id":40699968664,"side":"Sell"}]}
1618677684.812814: {"table":"orderBookL2","action":"delete","data":[{"symbol":"DOGEUSDT","id":47599965620,"side":"Sell"}]}
1618677684.812901: {"table":"orderBookL2","action":"insert","data":[{"symbol":"DOGEUSDT","id":47599970346,"side":"Sell","size":10,"price":0.29654}]}
1618677684.872852: {"table":"orderBookL2","action":"delete","data":[{"symbol":"DOGEUSDT","id":47599971573,"side":"Sell"}]}
1618677684.872967: {"table":"orderBookL2","action":"insert","data":[{"symbol":"DOGEUSDT","id":47599971624,"side":"Sell","size":134,"price":0.28376}]}
1618677684.877218: {"table":"orderBookL2","action":"delete","data":[{"symbol":"LTCUSD","id":40699968186,"side":"Sell"},{"symbol":"LTCUSD","id":40699968408,"side":"Sell"},{"symbol":"LTCUSD","id":40699969014,"side":"Buy"},{"symbol":"LTCUSD","id":40699969219,"side":"Buy"}]}
1618677684.8773801: {"table":"orderBookL2","action":"insert","data":[{"symbol":"LTCUSD","id":40699968185,"side":"Sell","size":579,"price":318.15},{"symbol":"LTCUSD","id":40699968407,"side":"Sell","size":579,"price":315.93},{"symbol":"LTCUSD","id":40699969013,"side":"Buy","size":579,"price":309.87},{"symbol":"LTCUSD","id":40699969218,"side":"Buy","size":579,"price":307.82}]}
1618677684.887774: {"table":"orderBookL2","action":"delete","data":[{"symbol":"DOGEUSDT","id":47599971574,"side":"Sell"}]}
1618677684.89132: {"table":"orderBookL2","action":"insert","data":[{"symbol":"LTCUSD","id":40699968667,"side":"Sell","size":236,"price":313.33}]}
1618677684.897814: {"table":"orderBookL2","action":"delete","data":[{"symbol":"LTCUSD","id":40699968762,"side":"Buy"}]}
1618677684.903137: {"table":"orderBookL2","action":"insert","data":[{"symbol":"DOGEUSDT","id":47599971575,"side":"Sell","size":300,"price":0.28425}]}
1618677684.905561: {"table":"orderBookL2","action":"delete","data":[{"symbol":"DOGEUSDT","id":47599971575,"side":"Sell"}]}
1618677684.917435: {"table":"orderBookL2","action":"insert","data":[{"symbol":"DOGEUSDT","id":47599971576,"side":"Sell","size":300,"price":0.28424}]}
1618677684.920728: {"table":"orderBookL2","action":"delete","data":[{"symbol":"DOGEUSDT","id":47599971576,"side":"Sell"}]}
1618677684.9325042: {"table":"orderBookL2","action":"insert","data":[{"symbol":"DOGEUSDT","id":47599971577,"side":"Sell","size":300,"price":0.28423}]}
1618677684.949336: {"table":"orderBookL2","action":"delete","data":[{"symbol":"DOGEUSDT","id":47599971577,"side":"Sell"}]}
1618677685.0737238: {"table":"orderBookL2","action":"update","data":[{"symbol":"LTCM21","id":52899998974,"side":"Buy","size":526},{"symbol":"LTCM21","id":52899998976,"side":"Buy","size":43},{"symbol":"LTCM21","id":52899998978,"side":"Buy","size":7}]}
1618677685.073819: {"table":"orderBookL2","action":"insert","data":[{"symbol":"LTCM21","id":52899998968,"side":"Buy","size":485,"price":0.00516}]}
1618677685.147635: {"table":"orderBookL2","action":"insert","data":[{"symbol":"LTCUSD","id":40699968657,"side":"Sell","size":218,"price":313.43}]}
1618677685.1792698: {"table":"orderBookL2","action":"update","data":[{"symbol":"TRXM21","id":52999999763,"side":"Buy","size":125144},{"symbol":"TRXM21","id":52999999768,"side":"Buy","size":167838}]}
1618677685.179374: {"table":"orderBookL2","action":"delete","data":[{"symbol":"LTCUSD","id":40699968679,"side":"Sell"}]}
1618677685.179443: {"table":"orderBookL2","action":"insert","data":[{"symbol":"LTCUSD","id":40699968681,"side":"Sell","size":432,"price":313.19}]}
1618677685.185069: {"table":"orderBookL2","action":"insert","data":[{"symbol":"LTCUSD","id":40699968665,"side":"Sell","size":253,"price":313.35}]}
1618677685.189235: {"table":"orderBookL2","action":"delete","data":[{"symbol":"EOSM21","id":52499998731,"side":"Sell"}]}
1618677685.198535: {"table":"orderBookL2","action":"delete","data":[{"symbol":"EOSUSDT","id":53899984026,"side":"Sell"}]}
1618677685.1986518: {"table":"orderBookL2","action":"insert","data":[{"symbol":"EOSUSDT","id":53899984048,"side":"Sell","size":171,"price":7.976}]}
1618677685.204845: {"table":"orderBookL2","action":"insert","data":[{"symbol":"EOSM21","id":52499998731,"side":"Buy","size":330,"price":0.0001269}]}
1618677685.204973: {"table":"orderBookL2","action":"update","data":[{"symbol":"EOSM21","id":52499998732,"side":"Buy","size":1200}]}
1618677685.208128: {"table":"orderBookL2","action":"delete","data":[{"symbol":"LTCUSD","id":40699968185,"side":"Sell"},{"symbol":"LTCUSD","id":40699969013,"side":"Buy"},{"symbol":"LTCUSD","id":40699969218,"side":"Buy"}]}
1618677685.2082298: {"table":"orderBookL2","action":"insert","data":[{"symbol":"LTCUSD","id":40699968184,"side":"Sell","size":579,"price":318.16},{"symbol":"LTCUSD","id":40699969015,"side":"Buy","size":579,"price":309.85},{"symbol":"LTCUSD","id":40699969221,"side":"Buy","size":579,"price":307.79}]}
1618677685.217029: {"table":"orderBookL2","action":"update","data":[{"symbol":"EOSM21","id":52499998730,"side":"Sell","size":652}]}
1618677685.269359: {"table":"orderBookL2","action":"delete","data":[{"symbol":"DOGEUSDT","id":47599971976,"side":"Buy"}]}
1618677685.269474: {"table":"orderBookL2","action":"insert","data":[{"symbol":"DOGEUSDT","id":47599973159,"side":"Buy","size":2383,"price":0.26841}]}
1618677685.277266: {"table":"orderBookL2","action":"insert","data":[{"symbol":"XLMUSDT","id":52199939103,"side":"Sell","size":386,"price":0.60897}]}
1618677685.292848: {"table":"orderBookL2","action":"insert","data":[{"symbol":"XLMUSDT","id":52199938999,"side":"Sell","size":60,"price":0.61001}]}
1618677685.35543: {"table":"orderBookL2","action":"delete","data":[{"symbol":"DOGEUSDT","id":47599971783,"side":"Buy"}]}
1618677685.355545: {"table":"orderBookL2","action":"insert","data":[{"symbol":"DOGEUSDT","id":47599971786,"side":"Buy","size":2110,"price":0.28214}]}
1618677685.469961: {"table":"orderBookL2","action":"delete","data":[{"symbol":"EOSM21","id":52499998731,"side":"Buy"}]}
1618677685.495691: {"table":"orderBookL2","action":"insert","data":[{"symbol":"EOSM21","id":52499998731,"side":"Sell","size":330,"price":0.0001269}]}
1618677685.495821: {"table":"orderBookL2","action":"update","data":[{"symbol":"EOSM21","id":52499998730,"side":"Sell","size":322}]}
1618677685.519637: {"table":"orderBookL2","action":"update","data":[{"symbol":"EOSM21","id":52499998729,"side":"Sell","size":867}]}
1618677685.519733: {"table":"orderBookL2","action":"update","data":[{"symbol":"EOSM21","id":52499998732,"side":"Buy","size":1530}]}
1618677685.553796: {"table":"orderBookL2","action":"delete","data":[{"symbol":"XLMUSDT","id":52199938831,"side":"Sell"}]}
1618677685.553909: {"table":"orderBookL2","action":"insert","data":[{"symbol":"XLMUSDT","id":52199939000,"side":"Sell","size":475,"price":0.61}]}
1618677685.570693: {"table":"orderBookL2","action":"update","data":[{"symbol":"ADAM21","id":52299997829,"side":"Sell","size":35000}]}
1618677685.6977952: {"table":"orderBookL2","action":"insert","data":[{"symbol":"LTCUSD","id":40699968732,"side":"Buy","size":125,"price":312.68}]}
1618677685.706548: {"table":"orderBookL2","action":"delete","data":[{"symbol":"TRXUSDT","id":53999983901,"side":"Sell"}]}
1618677685.738036: {"table":"orderBookL2","action":"delete","data":[{"symbol":"DOGEUSDT","id":47599971624,"side":"Sell"}]}
1618677685.7516081: {"table":"orderBookL2","action":"update","data":[{"symbol":"DOGEUSDT","id":47599971385,"side":"Sell","size":367}]}
1618677685.766413: {"table":"orderBookL2","action":"update","data":[{"symbol":"TRXM21","id":52999999757,"side":"Sell","size":3540915}]}
1618677685.778317: {"table":"orderBookL2","action":"update","data":[{"symbol":"LTCUSD","id":40699968734,"side":"Buy","size":5020}]}
1618677685.8986251: {"table":"orderBookL2","action":"update","data":[{"symbol":"LTCUSD","id":40699968680,"side":"Sell","size":372}]}
1618677685.918617: {"table":"orderBookL2","action":"delete","data":[{"symbol":"DOGEUSDT","id":47599971623,"side":"Sell"}]}
1618677685.928859: {"table":"orderBookL2","action":"delete","data":[{"symbol":"DOGEUSDT","id":47599971719,"side":"Buy"}]}
1618677686.0663471: {"table":"orderBookL2","action":"insert","data":[{"symbol":"LTCUSD","id":40699968729,"side":"Buy","size":777,"price":312.71}]}
1618677686.066477: {"table":"orderBookL2","action":"insert","data":[{"symbol":"LTCUSD","id":40699968682,"side":"Sell","size":59,"price":313.18}]}
1618677686.081014: {"table":"orderBookL2","action":"delete","data":[{"symbol":"LTCUSD","id":40699968681,"side":"Sell"}]}
1618677686.081106: {"table":"orderBookL2","action":"insert","data":[{"symbol":"LTCUSD","id":40699968683,"side":"Sell","size":432,"price":313.17}]}
1618677686.083437: {"table":"orderBookL2","action":"delete","data":[{"symbol":"LTCUSD","id":40699968730,"side":"Buy"}]}
1618677686.088916: {"table":"orderBookL2","action":"insert","data":[{"symbol":"LTCUSD","id":40699968728,"side":"Buy","size":1,"price":312.72}]}
1618677686.089012: {"table":"orderBookL2","action":"update","data":[{"symbol":"LTCUSD","id":40699968729,"side":"Buy","size":1008}]}
1618677686.103227: {"table":"orderBookL2","action":"delete","data":[{"symbol":"DOGEUSDT","id":47599971786,"side":"Buy"}]}
1618677686.103345: {"table":"orderBookL2","action":"insert","data":[{"symbol":"DOGEUSDT","id":47599971788,"side":"Buy","size":2110,"price":0.28212}]}
1618677686.103421: {"table":"orderBookL2","action":"delete","data":[{"symbol":"LTCUSD","id":40699968682,"side":"Sell"}]}
1618677686.1034722: {"table":"orderBookL2","action":"insert","data":[{"symbol":"LTCUSD","id":40699968727,"side":"Buy","size":39,"price":312.73}]}
1618677686.114068: {"table":"orderBookL2","action":"delete","data":[{"symbol":"LTCUSD","id":40699968683,"side":"Sell"}]}
1618677686.114187: {"table":"orderBookL2","action":"insert","data":[{"symbol":"LTCUSD","id":40699968681,"side":"Sell","size":432,"price":313.19}]}
1618677686.117941: {"table":"orderBookL2","action":"delete","data":[{"symbol":"LTCUSD","id":40699968732,"side":"Buy"}]}
1618677686.1218822: {"table":"orderBookL2","action":"insert","data":[{"symbol":"LTCUSD","id":40699968726,"side":"Buy","size":1,"price":312.74}]}
1618677686.12698: {"table":"orderBookL2","action":"delete","data":[{"symbol":"LTCUSD","id":40699968728,"side":"Buy"}]}
1618677686.140144: {"table":"orderBookL2","action":"delete","data":[{"symbol":"LTCUSD","id":40699968735,"side":"Buy"}]}
1618677686.1492102: {"table":"orderBookL2","action":"update","data":[{"symbol":"TRXM21","id":52999999753,"side":"Sell","size":134597},{"symbol":"TRXM21","id":52999999754,"side":"Sell","size":63962}]}
1618677686.175157: {"table":"orderBookL2","action":"insert","data":[{"symbol":"DOGEUSDT","id":47599971563,"side":"Sell","size":37,"price":0.28437}]}
1618677686.178327: {"table":"orderBookL2","action":"insert","data":[{"symbol":"DOGEUSDT","id":47599971784,"side":"Buy","size":2147,"price":0.28216}]}
1618677686.187962: {"table":"orderBookL2","action":"update","data":[{"symbol":"LTCUSD","id":40699968681,"side":"Sell","size":422}]}
1618677686.289909: {"table":"orderBookL2","action":"insert","data":[{"symbol":"DOGEUSDT","id":47599971564,"side":"Sell","size":1663,"price":0.28436}]}
1618677686.309244: {"table":"orderBookL2","action":"update","data":[{"symbol":"DOGEUSDT","id":47599971385,"side":"Sell","size":67}]}
1618677686.309342: {"table":"orderBookL2","action":"insert","data":[{"symbol":"DOGEUSDT","id":47599971565,"side":"Sell","size":300,"price":0.28435}]}
1618677686.318948: {"table":"orderBookL2","action":"delete","data":[{"symbol":"DOGEUSDT","id":47599971942,"side":"Buy"}]}
1618677686.319068: {"table":"orderBookL2","action":"insert","data":[{"symbol":"DOGEUSDT","id":47599971964,"side":"Buy","size":154,"price":0.28036}]}
1618677686.322189: {"table":"orderBookL2","action":"delete","data":[{"symbol":"DOGEUSDT","id":47599971784,"side":"Buy"}]}
1618677686.454525: {"table":"orderBookL2","action":"delete","data":[{"symbol":"LTCUSD","id":40699968184,"side":"Sell"},{"symbol":"LTCUSD","id":40699968407,"side":"Sell"},{"symbol":"LTCUSD","id":40699969015,"side":"Buy"},{"symbol":"LTCUSD","id":40699969221,"side":"Buy"}]}
1618677686.4546812: {"table":"orderBookL2","action":"update","data":[{"symbol":"LTCUSD","id":40699968183,"side":"Sell","size":619}]}
1618677686.454731: {"table":"orderBookL2","action":"insert","data":[{"symbol":"LTCUSD","id":40699968406,"side":"Sell","size":579,"price":315.94},{"symbol":"LTCUSD","id":40699969014,"side":"Buy","size":579,"price":309.86},{"symbol":"LTCUSD","id":40699969220,"side":"Buy","size":579,"price":307.8}]}
1618677686.478855: {"table":"orderBookL2","action":"update","data":[{"symbol":"DOGEUSDT","id":47599971385,"side":"Sell","size":17},{"symbol":"DOGEUSDT","id":47599971565,"side":"Sell","size":350}]}
1618677686.504854: {"table":"orderBookL2","action":"insert","data":[{"symbol":"LTCUSD","id":40699968744,"side":"Buy","size":274,"price":312.56}]}
1618677686.504982: {"table":"orderBookL2","action":"update","data":[{"symbol":"LTCUSD","id":40699968729,"side":"Buy","size":777}]}
1618677686.5198998: {"table":"orderBookL2","action":"insert","data":[{"symbol":"LTCUSD","id":40699968740,"side":"Buy","size":247,"price":312.6}]}
1618677686.65669: {"table":"orderBookL2","action":"delete","data":[{"symbol":"DOGEUSDT","id":47599971788,"side":"Buy"}]}
1618677686.656806: {"table":"orderBookL2","action":"insert","data":[{"symbol":"DOGEUSDT","id":47599971787,"side":"Buy","size":2110,"price":0.28213}]}
1618677686.817633: {"table":"orderBookL2","action":"delete","data":[{"symbol":"LINKUSDTM21","id":52799885329,"side":"Sell"}]}
1618677686.81775: {"table":"orderBookL2","action":"insert","data":[{"symbol":"LINKUSDTM21","id":52799885297,"side":"Sell","size":6,"price":57.3515}]}
1618677686.881899: {"table":"orderBookL2","action":"delete","data":[{"symbol":"DOGEUSDT","id":47599971564,"side":"Sell"}]}
1618677686.882022: {"table":"orderBookL2","action":"insert","data":[{"symbol":"DOGEUSDT","id":47599971566,"side":"Sell","size":1663,"price":0.28434}]}
1618677686.895147: {"table":"orderBookL2","action":"update","data":[{"symbol":"DOGEUSDT","id":47599971565,"side":"Sell","size":50}]}
1618677686.908261: {"table":"orderBookL2","action":"insert","data":[{"symbol":"DOGEUSDT","id":47599971567,"side":"Sell","size":300,"price":0.28433}]}
1618677687.002389: {"table":"orderBookL2","action":"insert","data":[{"symbol":"DOGEUSDT","id":47599971568,"side":"Sell","size":349,"price":0.28432}]}
1618677687.0184362: {"table":"orderBookL2","action":"delete","data":[{"symbol":"DOGEUSDT","id":47599971567,"side":"Sell"}]}
1618677687.018527: {"table":"orderBookL2","action":"insert","data":[{"symbol":"DOGEUSDT","id":47599971569,"side":"Sell","size":300,"price":0.28431}]}
1618677687.018595: {"table":"orderBookL2","action":"delete","data":[{"symbol":"DOGEUSDT","id":47599971385,"side":"Sell"}]}
1618677687.032877: {"table":"orderBookL2","action":"insert","data":[{"symbol":"DOGEUSDT","id":47599971385,"side":"Sell","size":18,"price":0.28615}]}
1618677687.038993: {"table":"orderBookL2","action":"delete","data":[{"symbol":"DOGEUSDT","id":47599971385,"side":"Sell"}]}
1618677687.159904: {"table":"orderBookL2","action":"update","data":[{"symbol":"LTCUSD","id":40699968680,"side":"Sell","size":619}]}
1618677687.193078: {"table":"orderBookL2","action":"delete","data":[{"symbol":"LTCUSD","id":40699968729,"side":"Buy"}]}
1618677687.2260559: {"table":"orderBookL2","action":"delete","data":[{"symbol":"LTCUSD","id":40699969014,"side":"Buy"},{"symbol":"LTCUSD","id":40699969220,"side":"Buy"}]}
1618677687.2261171: {"table":"orderBookL2","action":"update","data":[{"symbol":"LTCUSD","id":40699968183,"side":"Sell","size":40},{"symbol":"LTCUSD","id":40699968948,"side":"Buy","size":2149}]}
1618677687.2261472: {"table":"orderBookL2","action":"insert","data":[{"symbol":"LTCUSD","id":40699968182,"side":"Sell","size":579,"price":318.18},{"symbol":"LTCUSD","id":40699968913,"side":"Buy","size":579,"price":310.87},{"symbol":"LTCUSD","id":40699969017,"side":"Buy","size":579,"price":309.83},{"symbol":"LTCUSD","id":40699969223,"side":"Buy","size":579,"price":307.77}]}
1618677687.2459252: {"table":"orderBookL2","action":"delete","data":[{"symbol":"DOGEUSDT","id":47599972016,"side":"Buy"}]}
1618677687.246013: {"table":"orderBookL2","action":"insert","data":[{"symbol":"DOGEUSDT","id":47599972524,"side":"Buy","size":361,"price":0.27476}]}
1618677687.274108: {"table":"orderBookL2","action":"delete","data":[{"symbol":"LTCUSD","id":40699968182,"side":"Sell"},{"symbol":"LTCUSD","id":40699968406,"side":"Sell"},{"symbol":"LTCUSD","id":40699968913,"side":"Buy"},{"symbol":"LTCUSD","id":40699969017,"side":"Buy"},{"symbol":"LTCUSD","id":40699969223,"side":"Buy"}]}
1618677687.274281: {"table":"orderBookL2","action":"insert","data":[{"symbol":"LTCUSD","id":40699968186,"side":"Sell","size":579,"price":318.14},{"symbol":"LTCUSD","id":40699968408,"side":"Sell","size":579,"price":315.92},{"symbol":"LTCUSD","id":40699968912,"side":"Buy","size":579,"price":310.88},{"symbol":"LTCUSD","id":40699969014,"side":"Buy","size":579,"price":309.86},{"symbol":"LTCUSD","id":40699969219,"side":"Buy","size":579,"price":307.81}]}
1618677687.2968152: {"table":"orderBookL2","action":"delete","data":[{"symbol":"LTCUSD","id":40699968186,"side":"Sell"},{"symbol":"LTCUSD","id":40699968408,"side":"Sell"},{"symbol":"LTCUSD","id":40699968912,"side":"Buy"},{"symbol":"LTCUSD","id":40699969014,"side":"Buy"},{"symbol":"LTCUSD","id":40699969219,"side":"Buy"}]}
1618677687.296978: {"table":"orderBookL2","action":"insert","data":[{"symbol":"LTCUSD","id":40699968189,"side":"Sell","size":579,"price":318.11},{"symbol":"LTCUSD","id":40699968411,"side":"Sell","size":579,"price":315.89},{"symbol":"LTCUSD","id":40699968913,"side":"Buy","size":579,"price":310.87},{"symbol":"LTCUSD","id":40699969015,"side":"Buy","size":579,"price":309.85},{"symbol":"LTCUSD","id":40699969220,"side":"Buy","size":579,"price":307.8}]}
1618677687.357701: {"table":"orderBookL2","action":"delete","data":[{"symbol":"DOGEUSDT","id":47599971565,"side":"Sell"}]}
1618677687.357815: {"table":"orderBookL2","action":"insert","data":[{"symbol":"DOGEUSDT","id":47599971567,"side":"Sell","size":50,"price":0.28433}]}
1618677687.373618: {"table":"orderBookL2","action":"insert","data":[{"symbol":"DOGEUSDT","id":47599971385,"side":"Sell","size":18,"price":0.28615}]}
1618677687.375087: {"table":"orderBookL2","action":"delete","data":[{"symbol":"DOGEUSDT","id":47599971385,"side":"Sell"}]}
1618677687.422484: {"table":"orderBookL2","action":"update","data":[{"symbol":"TRXUSDT","id":53999984000,"side":"Buy","size":2915}]}
1618677687.469274: {"table":"orderBookL2","action":"delete","data":[{"symbol":"DOGEUSDT","id":47599971566,"side":"Sell"}]}
1618677687.469376: {"table":"orderBookL2","action":"insert","data":[{"symbol":"DOGEUSDT","id":47599971570,"side":"Sell","size":1662,"price":0.2843}]}
1618677687.486776: {"table":"orderBookL2","action":"insert","data":[{"symbol":"DOGEUSDT","id":47599971385,"side":"Sell","size":18,"price":0.28615}]}
1618677687.514734: {"table":"orderBookL2","action":"delete","data":[{"symbol":"DOGEUSDT","id":47599971787,"side":"Buy"}]}
1618677687.514821: {"table":"orderBookL2","action":"insert","data":[{"symbol":"DOGEUSDT","id":47599971786,"side":"Buy","size":2110,"price":0.28214}]}
1618677687.526585: {"table":"orderBookL2","action":"delete","data":[{"symbol":"DOGEUSDT","id":47599971569,"side":"Sell"}]}
1618677687.5266712: {"table":"orderBookL2","action":"insert","data":[{"symbol":"DOGEUSDT","id":47599971571,"side":"Sell","size":300,"price":0.28429}]}
1618677687.530346: {"table":"orderBookL2","action":"update","data":[{"symbol":"LTCM21","id":52899998952,"side":"Buy","size":232}]}
1618677687.648685: {"table":"orderBookL2","action":"update","data":[{"symbol":"LTCUSD","id":40699968680,"side":"Sell","size":494}]}
1618677687.648747: {"table":"orderBookL2","action":"insert","data":[{"symbol":"LTCUSD","id":40699968682,"side":"Sell","size":125,"price":313.18}]}
1618677687.659703: {"table":"orderBookL2","action":"delete","data":[{"symbol":"LTCUSD","id":40699968681,"side":"Sell"}]}
1618677687.6597629: {"table":"orderBookL2","action":"insert","data":[{"symbol":"LTCUSD","id":40699968683,"side":"Sell","size":422,"price":313.17}]}
1618677687.660314: {"table":"orderBookL2","action":"delete","data":[{"symbol":"EOSUSDT","id":53899983798,"side":"Sell"}]}
1618677687.662153: {"table":"orderBookL2","action":"insert","data":[{"symbol":"EOSUSDT","id":53899983879,"side":"Sell","size":8511,"price":8.0605}]}
1618677687.698335: {"table":"orderBookL2","action":"update","data":[{"symbol":"EOSM21","id":52499998722,"side":"Sell","size":100}]}
1618677687.703226: {"table":"orderBookL2","action":"delete","data":[{"symbol":"DOGEUSDT","id":47599971786,"side":"Buy"}]}
1618677687.703319: {"table":"orderBookL2","action":"update","data":[{"symbol":"DOGEUSDT","id":47599971785,"side":"Buy","size":2147}]}
1618677687.735907: {"table":"orderBookL2","action":"insert","data":[{"symbol":"TRXUSDT","id":53999983904,"side":"Sell","size":512,"price":0.16096}]}
1618677687.741586: {"table":"orderBookL2","action":"insert","data":[{"symbol":"XLMUSDT","id":52199938962,"side":"Sell","size":57,"price":0.61038}]}
1618677687.756259: {"table":"orderBookL2","action":"delete","data":[{"symbol":"XLMUSDT","id":52199938999,"side":"Sell"}]}
1618677687.773633: {"table":"orderBookL2","action":"delete","data":[{"symbol":"LTCUSD","id":40699968813,"side":"Buy"}]}
1618677687.780288: {"table":"orderBookL2","action":"insert","data":[{"symbol":"LTCUSD","id":40699968799,"side":"Buy","size":106,"price":312.01}]}
1618677687.813214: {"table":"orderBookL2","action":"delete","data":[{"symbol":"EOSM21","id":52499998731,"side":"Sell"}]}
1618677687.8267908: {"table":"orderBookL2","action":"update","data":[{"symbol":"EOSM21","id":52499998732,"side":"Buy","size":1200}]}
1618677687.83026: {"table":"orderBookL2","action":"insert","data":[{"symbol":"EOSM21","id":52499998731,"side":"Buy","size":330,"price":0.0001269}]}
1618677687.845129: {"table":"orderBookL2","action":"update","data":[{"symbol":"EOSM21","id":52499998730,"side":"Sell","size":652}]}
1618677687.87185: {"table":"orderBookL2","action":"update","data":[{"symbol":"EOSM21","id":52499998729,"side":"Sell","size":83}]}
1618677687.871947: {"table":"orderBookL2","action":"update","data":[{"symbol":"EOSM21","id":52499998733,"side":"Buy","size":1715}]}
1618677687.903574: {"table":"orderBookL2","action":"delete","data":[{"symbol":"LINKUSDTM21","id":52799880436,"side":"Sell"}]}
1618677687.9036942: {"table":"orderBookL2","action":"insert","data":[{"symbol":"LINKUSDTM21","id":52799880077,"side":"Sell","size":2512,"price":59.9615}]}
1618677687.921132: {"table":"orderBookL2","action":"insert","data":[{"symbol":"LTCUSD","id":40699968650,"side":"Sell","size":286,"price":313.5}]}
1618677687.929018: {"table":"orderBookL2","action":"delete","data":[{"symbol":"LTCUSD","id":40699968665,"side":"Sell"}]}
1618677687.9732742: {"table":"orderBookL2","action":"update","data":[{"symbol":"DOGEUSDT","id":47599971785,"side":"Buy","size":37}]}
1618677687.973372: {"table":"orderBookL2","action":"insert","data":[{"symbol":"DOGEUSDT","id":47599971786,"side":"Buy","size":2110,"price":0.28214}]}
1618677687.9866061: {"table":"orderBookL2","action":"delete","data":[{"symbol":"DOGEUSDT","id":47599971786,"side":"Buy"}]}
1618677687.986721: {"table":"orderBookL2","action":"insert","data":[{"symbol":"DOGEUSDT","id":47599971790,"side":"Buy","size":2110,"price":0.2821}]}
1618677687.997252: {"table":"orderBookL2","action":"delete","data":[{"symbol":"TRXUSDT","id":53999983904,"side":"Sell"}]}
1618677688.000273: {"table":"orderBookL2","action":"insert","data":[{"symbol":"TRXUSDT","id":53999983896,"side":"Sell","size":402,"price":0.16104}]}
1618677688.068376: {"table":"orderBookL2","action":"delete","data":[{"symbol":"DOGEUSDT","id":47599971570,"side":"Sell"}]}
1618677688.068497: {"table":"orderBookL2","action":"insert","data":[{"symbol":"DOGEUSDT","id":47599971572,"side":"Sell","size":1662,"price":0.28428}]}
1618677688.072722: {"table":"orderBookL2","action":"delete","data":[{"symbol":"LTCUSD","id":40699968726,"side":"Buy"}]}
1618677688.08054: {"table":"orderBookL2","action":"delete","data":[{"symbol":"DOGEUSDT","id":47599971571,"side":"Sell"}]}
1618677688.080627: {"table":"orderBookL2","action":"insert","data":[{"symbol":"DOGEUSDT","id":47599971573,"side":"Sell","size":300,"price":0.28427}]}
1618677688.113836: {"table":"orderBookL2","action":"update","data":[{"symbol":"DOGEUSDT","id":47599971850,"side":"Buy","size":357}]}
1618677688.118141: {"table":"orderBookL2","action":"delete","data":[{"symbol":"DOGEUSDT","id":47599971837,"side":"Buy"}]}
1618677688.1285582: {"table":"orderBookL2","action":"delete","data":[{"symbol":"LTCM21","id":52899998968,"side":"Buy"}]}
1618677688.128652: {"table":"orderBookL2","action":"update","data":[{"symbol":"LTCM21","id":52899998914,"side":"Sell","size":486},{"symbol":"LTCM21","id":52899998922,"side":"Sell","size":6},{"symbol":"LTCM21","id":52899998926,"side":"Sell","size":623},{"symbol":"LTCM21","id":52899998932,"side":"Sell","size":3},{"symbol":"LTCM21","id":52899998966,"side":"Buy","size":637},{"symbol":"LTCM21","id":52899998972,"side":"Buy","size":671},{"symbol":"LTCM21","id":52899998974,"side":"Buy","size":6}]}
1618677688.1449652: {"table":"orderBookL2","action":"delete","data":[{"symbol":"DOGEUSDT","id":47599971790,"side":"Buy"}]}
1618677688.14505: {"table":"orderBookL2","action":"insert","data":[{"symbol":"DOGEUSDT","id":47599971791,"side":"Buy","size":2110,"price":0.28209}]}
1618677688.15444: {"table":"orderBookL2","action":"update","data":[{"symbol":"DOGEUSDT","id":47599971850,"side":"Buy","size":5}]}
1618677688.171246: {"table":"orderBookL2","action":"delete","data":[{"symbol":"DOGEUSDT","id":47599971791,"side":"Buy"}]}
1618677688.1713111: {"table":"orderBookL2","action":"insert","data":[{"symbol":"DOGEUSDT","id":47599971793,"side":"Buy","size":2110,"price":0.28207}]}
1618677688.1851761: {"table":"orderBookL2","action":"delete","data":[{"symbol":"DOGEUSDT","id":47599971793,"side":"Buy"}]}
1618677688.185237: {"table":"orderBookL2","action":"insert","data":[{"symbol":"DOGEUSDT","id":47599971795,"side":"Buy","size":2110,"price":0.28205}]}
1618677688.2004201: {"table":"orderBookL2","action":"delete","data":[{"symbol":"DOGEUSDT","id":47599971567,"side":"Sell"}]}
1618677688.200541: {"table":"orderBookL2","action":"update","data":[{"symbol":"DOGEUSDT","id":47599971573,"side":"Sell","size":350}]}
1618677688.2303932: {"table":"orderBookL2","action":"delete","data":[{"symbol":"DOGEUSDT","id":47599971795,"side":"Buy"}]}
1618677688.23051: {"table":"orderBookL2","action":"insert","data":[{"symbol":"DOGEUSDT","id":47599971798,"side":"Buy","size":2110,"price":0.28202}]}
1618677688.297805: {"table":"orderBookL2","action":"delete","data":[{"symbol":"DOGEUSDT","id":47599971798,"side":"Buy"}]}
1618677688.297869: {"table":"orderBookL2","action":"insert","data":[{"symbol":"DOGEUSDT","id":47599971799,"side":"Buy","size":2110,"price":0.28201}]}
1618677688.308971: {"table":"orderBookL2","action":"delete","data":[{"symbol":"DOGEUSDT","id":47599971799,"side":"Buy"}]}
1618677688.3090298: {"table":"orderBookL2","action":"insert","data":[{"symbol":"DOGEUSDT","id":47599971803,"side":"Buy","size":2110,"price":0.28197}]}
1618677688.3642108: {"table":"orderBookL2","action":"delete","data":[{"symbol":"DOGEUSDT","id":47599971195,"side":"Sell"}]}
1618677688.36433: {"table":"orderBookL2","action":"update","data":[{"symbol":"DOGEUSDT","id":47599971279,"side":"Sell","size":454}]}
1618677688.398962: {"table":"orderBookL2","action":"delete","data":[{"symbol":"DOGEUSDT","id":47599971803,"side":"Buy"}]}
1618677688.399082: {"table":"orderBookL2","action":"insert","data":[{"symbol":"DOGEUSDT","id":47599971804,"side":"Buy","size":2110,"price":0.28196}]}
1618677688.414409: {"table":"orderBookL2","action":"delete","data":[{"symbol":"DOGEUSDT","id":47599971804,"side":"Buy"}]}
1618677688.4145348: {"table":"orderBookL2","action":"insert","data":[{"symbol":"DOGEUSDT","id":47599971806,"side":"Buy","size":2110,"price":0.28194}]}
1618677688.425885: {"table":"orderBookL2","action":"delete","data":[{"symbol":"DOGEUSDT","id":47599971806,"side":"Buy"}]}
1618677688.426002: {"table":"orderBookL2","action":"insert","data":[{"symbol":"DOGEUSDT","id":47599971809,"side":"Buy","size":2110,"price":0.28191}]}
1618677688.543896: {"table":"orderBookL2","action":"delete","data":[{"symbol":"DOGEUSDT","id":47599971964,"side":"Buy"}]}
1618677688.5440168: {"table":"orderBookL2","action":"insert","data":[{"symbol":"DOGEUSDT","id":47599971987,"side":"Buy","size":154,"price":0.28013}]}
1618677688.5446699: {"table":"orderBookL2","action":"update","data":[{"symbol":"LTCM21","id":52899998950,"side":"Buy","size":347}]}
1618677688.582: {"table":"orderBookL2","action":"insert","data":[{"symbol":"LTCUSD","id":40699968668,"side":"Sell","size":261,"price":313.32}]}
1618677688.64721: {"table":"orderBookL2","action":"delete","data":[{"symbol":"LINKUSDTM21","id":52799886532,"side":"Buy"}]}
1618677688.659658: {"table":"orderBookL2","action":"insert","data":[{"symbol":"LTCUSD","id":40699968732,"side":"Buy","size":125,"price":312.68}]}
1618677688.69155: {"table":"orderBookL2","action":"insert","data":[{"symbol":"TRXUSDT","id":53999984008,"side":"Buy","size":390,"price":0.15992}]}
1618677688.6916108: {"table":"orderBookL2","action":"update","data":[{"symbol":"TRXUSDT","id":53999983905,"side":"Sell","size":2490}]}
1618677688.6976361: {"table":"orderBookL2","action":"delete","data":[{"symbol":"EOSM21","id":52499998739,"side":"Buy"}]}
1618677688.7095559: {"table":"orderBookL2","action":"insert","data":[{"symbol":"XLMUSDT","id":52199938990,"side":"Sell","size":69,"price":0.6101}]}
1618677688.721327: {"table":"orderBookL2","action":"insert","data":[{"symbol":"DOGEUSDT","id":47599972935,"side":"Buy","size":26253,"price":0.27065}]}
1618677688.7535691: {"table":"orderBookL2","action":"delete","data":[{"symbol":"DOGEUSDT","id":47599971572,"side":"Sell"}]}
1618677688.7536461: {"table":"orderBookL2","action":"insert","data":[{"symbol":"DOGEUSDT","id":47599971574,"side":"Sell","size":1662,"price":0.28426}]}
1618677688.764268: {"table":"orderBookL2","action":"delete","data":[{"symbol":"DOGEUSDT","id":47599972935,"side":"Buy"}]}
1618677688.7751439: {"table":"orderBookL2","action":"delete","data":[{"symbol":"DOGEUSDT","id":47599971563,"side":"Sell"}]}
1618677688.775199: {"table":"orderBookL2","action":"insert","data":[{"symbol":"DOGEUSDT","id":47599971575,"side":"Sell","size":2324,"price":0.28425}]}
1618677688.775242: {"table":"orderBookL2","action":"update","data":[{"symbol":"DOGEUSDT","id":47599971573,"side":"Sell","size":50},{"symbol":"DOGEUSDT","id":47599971575,"side":"Sell","size":2624}]}
1618677688.82225: {"table":"orderBookL2","action":"delete","data":[{"symbol":"DOGEUSDT","id":47599971842,"side":"Buy"},{"symbol":"DOGEUSDT","id":47599971843,"side":"Buy"},{"symbol":"DOGEUSDT","id":47599971844,"side":"Buy"},{"symbol":"DOGEUSDT","id":47599971845,"side":"Buy"},{"symbol":"DOGEUSDT","id":47599971846,"side":"Buy"}]}
1618677688.837127: {"table":"orderBookL2","action":"insert","data":[{"symbol":"DOGEUSDT","id":47599971974,"side":"Buy","size":583,"price":0.28026},{"symbol":"DOGEUSDT","id":47599971975,"side":"Buy","size":583,"price":0.28025},{"symbol":"DOGEUSDT","id":47599971976,"side":"Buy","size":583,"price":0.28024}]}
1618677688.839233: {"table":"orderBookL2","action":"insert","data":[{"symbol":"DOGEUSDT","id":47599971915,"side":"Buy","size":100,"price":0.28085},{"symbol":"DOGEUSDT","id":47599971916,"side":"Buy","size":100,"price":0.28084},{"symbol":"DOGEUSDT","id":47599971917,"side":"Buy","size":100,"price":0.28083},{"symbol":"DOGEUSDT","id":47599971918,"side":"Buy","size":100,"price":0.28082},{"symbol":"DOGEUSDT","id":47599971919,"side":"Buy","size":100,"price":0.28081}]}
1618677688.8437388: {"table":"orderBookL2","action":"insert","data":[{"symbol":"DOGEUSDT","id":47599971654,"side":"Sell","size":248,"price":0.28346},{"symbol":"DOGEUSDT","id":47599971750,"side":"Buy","size":4000,"price":0.2825}]}
1618677688.854329: {"table":"orderBookL2","action":"delete","data":[{"symbol":"DOGEUSDT","id":47599971974,"side":"Buy"},{"symbol":"DOGEUSDT","id":47599971975,"side":"Buy"},{"symbol":"DOGEUSDT","id":47599971976,"side":"Buy"}]}
1618677688.859282: {"table":"orderBookL2","action":"delete","data":[{"symbol":"DOGEUSDT","id":47599970838,"side":"Sell"},{"symbol":"DOGEUSDT","id":47599971122,"side":"Sell"},{"symbol":"DOGEUSDT","id":47599971977,"side":"Buy"},{"symbol":"DOGEUSDT","id":47599972261,"side":"Buy"}]}
1618677688.8600519: {"table":"orderBookL2","action":"delete","data":[{"symbol":"DOGEUSDT","id":47599971385,"side":"Sell"}]}
1618677688.863671: {"table":"orderBookL2","action":"delete","data":[{"symbol":"DOGEUSDT","id":47599971568,"side":"Sell"}]}
1618677688.8727481: {"table":"orderBookL2","action":"insert","data":[{"symbol":"DOGEUSDT","id":47599971749,"side":"Buy","size":583,"price":0.28251}]}
1618677688.874811: {"table":"orderBookL2","action":"insert","data":[{"symbol":"DOGEUSDT","id":47599970994,"side":"Sell","size":7065,"price":0.29006},{"symbol":"DOGEUSDT","id":47599971277,"side":"Sell","size":7135,"price":0.28723},{"symbol":"DOGEUSDT","id":47599972127,"side":"Buy","size":7352,"price":0.27873},{"symbol":"DOGEUSDT","id":47599972410,"side":"Buy","size":7428,"price":0.2759}]}
1618677688.87808: {"table":"orderBookL2","action":"insert","data":[{"symbol":"DOGEUSDT","id":47599971385,"side":"Sell","size":19,"price":0.28615}]}
1618677689.0411232: {"table":"orderBookL2","action":"insert","data":[{"symbol":"LTCUSD","id":40699968726,"side":"Buy","size":78,"price":312.74}]}
1618677689.050356: {"table":"orderBookL2","action":"delete","data":[{"symbol":"LTCUSD","id":40699968683,"side":"Sell"}]}
1618677689.0556989: {"table":"orderBookL2","action":"delete","data":[{"symbol":"LTCUSD","id":40699968740,"side":"Buy"}]}
1618677689.055767: {"table":"orderBookL2","action":"update","data":[{"symbol":"LTCUSD","id":40699968732,"side":"Buy","size":372}]}
1618677689.068563: {"table":"orderBookL2","action":"delete","data":[{"symbol":"LTCUSD","id":40699968189,"side":"Sell"},{"symbol":"LTCUSD","id":40699968411,"side":"Sell"},{"symbol":"LTCUSD","id":40699968913,"side":"Buy"},{"symbol":"LTCUSD","id":40699969015,"side":"Buy"},{"symbol":"LTCUSD","id":40699969220,"side":"Buy"}]}
1618677689.068676: {"table":"orderBookL2","action":"update","data":[{"symbol":"LTCUSD","id":40699968508,"side":"Sell","size":300}]}
1618677689.06946: {"table":"orderBookL2","action":"insert","data":[{"symbol":"LTCUSD","id":40699968174,"side":"Sell","size":579,"price":318.26},{"symbol":"LTCUSD","id":40699968399,"side":"Sell","size":579,"price":316.01},{"symbol":"LTCUSD","id":40699968511,"side":"Sell","size":579,"price":314.89},{"symbol":"LTCUSD","id":40699968909,"side":"Buy","size":579,"price":310.91},{"symbol":"LTCUSD","id":40699969012,"side":"Buy","size":579,"price":309.88},{"symbol":"LTCUSD","id":40699969219,"side":"Buy","size":579,"price":307.81}]}
1618677689.072025: {"table":"orderBookL2","action":"update","data":[{"symbol":"LTCUSD","id":40699968732,"side":"Buy","size":125}]}
1618677689.0784042: {"table":"orderBookL2","action":"insert","data":[{"symbol":"XLMUSDT","id":52199939025,"side":"Sell","size":49,"price":0.60975}]}
1618677689.081936: {"table":"orderBookL2","action":"update","data":[{"symbol":"TRXUSDT","id":53999983905,"side":"Sell","size":2100}]}
1618677689.1249018: {"table":"orderBookL2","action":"delete","data":[{"symbol":"DOGEUSDT","id":47599971987,"side":"Buy"}]}
1618677689.125015: {"table":"orderBookL2","action":"insert","data":[{"symbol":"DOGEUSDT","id":47599972011,"side":"Buy","size":154,"price":0.27989}]}
1618677689.137175: {"table":"orderBookL2","action":"delete","data":[{"symbol":"DOGEUSDT","id":47599971573,"side":"Sell"}]}
1618677689.137235: {"table":"orderBookL2","action":"insert","data":[{"symbol":"DOGEUSDT","id":47599971576,"side":"Sell","size":50,"price":0.28424}]}
1618677689.1925461: {"table":"orderBookL2","action":"delete","data":[{"symbol":"DOGEUSDT","id":47599971882,"side":"Buy"}]}
1618677689.1926: {"table":"orderBookL2","action":"insert","data":[{"symbol":"DOGEUSDT","id":47599971986,"side":"Buy","size":1179,"price":0.28014}]}
1618677689.19534: {"table":"orderBookL2","action":"delete","data":[{"symbol":"LTCUSD","id":40699968763,"side":"Buy"}]}
1618677689.195392: {"table":"orderBookL2","action":"update","data":[{"symbol":"LTCUSD","id":40699968748,"side":"Buy","size":340}]}
1618677689.222872: {"table":"orderBookL2","action":"delete","data":[{"symbol":"LTCUSD","id":40699968726,"side":"Buy"}]}
1618677689.2251499: {"table":"orderBookL2","action":"insert","data":[{"symbol":"LTCUSD","id":40699968683,"side":"Sell","size":422,"price":313.17}]}
1618677689.230282: {"table":"orderBookL2","action":"delete","data":[{"symbol":"LTCUSD","id":40699968174,"side":"Sell"},{"symbol":"LTCUSD","id":40699968399,"side":"Sell"},{"symbol":"LTCUSD","id":40699968909,"side":"Buy"},{"symbol":"LTCUSD","id":40699969219,"side":"Buy"}]}
1618677689.23041: {"table":"orderBookL2","action":"update","data":[{"symbol":"LTCUSD","id":40699968405,"side":"Sell","size":10817},{"symbol":"LTCUSD","id":40699968910,"side":"Buy","size":2389}]}
