1618677689.230464: {"table":"orderBookL2","action":"insert","data":[{"symbol":"LTCUSD","id":40699968182,"side":"Sell","size":579,"price":318.18},{"symbol":"LTCUSD","id":40699969218,"side":"Buy","size":579,"price":307.82}]}
1618677689.232511: {"table":"orderBookL2","action":"delete","data":[{"symbol":"DOGEUSDT","id":47599971749,"side":"Buy"}]}
1618677689.238781: {"table":"orderBookL2","action":"delete","data":[{"symbol":"DOGEUSDT","id":47599971809,"side":"Buy"}]}
1618677689.238873: {"table":"orderBookL2","action":"insert","data":[{"symbol":"DOGEUSDT","id":47599971814,"side":"Buy","size":2110,"price":0.28186}]}
1618677689.2453701: {"table":"orderBookL2","action":"insert","data":[{"symbol":"LTCUSD","id":40699968726,"side":"Buy","size":1,"price":312.74}]}
1618677689.296747: {"table":"orderBookL2","action":"delete","data":[{"symbol":"DOGEUSDT","id":47599971814,"side":"Buy"}]}
1618677689.296861: {"table":"orderBookL2","action":"insert","data":[{"symbol":"DOGEUSDT","id":47599971822,"side":"Buy","size":2110,"price":0.28178}]}
1618677689.353746: {"table":"orderBookL2","action":"delete","data":[{"symbol":"DOGEUSDT","id":47599971822,"side":"Buy"}]}
1618677689.3538618: {"table":"orderBookL2","action":"insert","data":[{"symbol":"DOGEUSDT","id":47599971830,"side":"Buy","size":2110,"price":0.2817}]}
1618677689.358475: {"table":"orderBookL2","action":"delete","data":[{"symbol":"DOGEUSDT","id":47599971654,"side":"Sell"},{"symbol":"DOGEUSDT","id":47599971750,"side":"Buy"}]}
1618677689.376101: {"table":"orderBookL2","action":"delete","data":[{"symbol":"DOGEUSDT","id":47599970428,"side":"Sell"},{"symbol":"DOGEUSDT","id":47599970569,"side":"Sell"},{"symbol":"DOGEUSDT","id":47599970711,"side":"Sell"},{"symbol":"DOGEUSDT","id":47599970853,"side":"Sell"},{"symbol":"DOGEUSDT","id":47599970995,"side":"Sell"},{"symbol":"DOGEUSDT","id":47599971137,"side":"Sell"},{"symbol":"DOGEUSDT","id":47599971278,"side":"Sell"},{"symbol":"DOGEUSDT","id":47599971420,"side":"Sell"},{"symbol":"DOGEUSDT","id":47599971562,"side":"Sell"},{"symbol":"DOGEUSDT","id":47599971785,"side":"Buy"},{"symbol":"DOGEUSDT","id":47599971927,"side":"Buy"},{"symbol":"DOGEUSDT","id":47599972069,"side":"Buy"},{"symbol":"DOGEUSDT","id":47599972211,"side":"Buy"},{"symbol":"DOGEUSDT","id":47599972352,"side":"Buy"},{"symbol":"DOGEUSDT","id":47599972494,"side":"Buy"},{"symbol":"DOGEUSDT","id":47599972636,"side":"Buy"},{"symbol":"DOGEUSDT","id":47599972778,"side":"Buy"},{"symbol":"DOGEUSDT","id":47599972919,"side":"Buy"},{"symbol":"DOGEUSDT","id":47599973061,"side":"Buy"}]}
1618677689.376296: {"table":"orderBookL2","action":"update","data":[{"symbol":"DOGEUSDT","id":47599970286,"side":"Sell","size":50}]}
1618677689.37633: {"table":"orderBookL2","action":"insert","data":[{"symbol":"DOGEUSDT","id":47599970354,"side":"Sell","size":126,"price":0.29646},{"symbol":"DOGEUSDT","id":47599970496,"side":"Sell","size":126,"price":0.29504},{"symbol":"DOGEUSDT","id":47599970637,"side":"Sell","size":126,"price":0.29363},{"symbol":"DOGEUSDT","id":47599970779,"side":"Sell","size":126,"price":0.29221},{"symbol":"DOGEUSDT","id":47599970920,"side":"Sell","size":111,"price":0.2908},{"symbol":"DOGEUSDT","id":47599971062,"side":"Sell","size":91,"price":0.28938},{"symbol":"DOGEUSDT","id":47599971203,"side":"Sell","size":70,"price":0.28797},{"symbol":"DOGEUSDT","id":47599971345,"side":"Sell","size":50,"price":0.28655},{"symbol":"DOGEUSDT","id":47599971486,"side":"Sell","size":38,"price":0.28514},{"symbol":"DOGEUSDT","id":47599971628,"side":"Sell","size":38,"price":0.28372},{"symbol":"DOGEUSDT","id":47599971852,"side":"Buy","size":38,"price":0.28148},{"symbol":"DOGEUSDT","id":47599971993,"side":"Buy","size":43,"price":0.28007},{"symbol":"DOGEUSDT","id":47599972135,"side":"Buy","size":75,"price":0.27865},{"symbol":"DOGEUSDT","id":47599972276,"side":"Buy","size":107,"price":0.27724},{"symbol":"DOGEUSDT","id":47599972418,"side":"Buy","size":140,"price":0.27582},{"symbol":"DOGEUSDT","id":47599972559,"side":"Buy","size":172,"price":0.27441},{"symbol":"DOGEUSDT","id":47599972701,"side":"Buy","size":186,"price":0.27299},{"symbol":"DOGEUSDT","id":47599972842,"side":"Buy","size":186,"price":0.27158},{"symbol":"DOGEUSDT","id":47599972984,"side":"Buy","size":186,"price":0.27016},{"symbol":"DOGEUSDT","id":47599973125,"side":"Buy","size":186,"price":0.26875}]}
1618677689.3928902: {"table":"orderBookL2","action":"delete","data":[{"symbol":"LTCUSD","id":40699968733,"side":"Buy"}]}
1618677689.392941: {"table":"orderBookL2","action":"insert","data":[{"symbol":"LTCUSD","id":40699968731,"side":"Buy","size":247,"price":312.69}]}
1618677689.40356: {"table":"orderBookL2","action":"delete","data":[{"symbol":"TRXUSDT","id":53999983896,"side":"Sell"}]}
1618677689.403604: {"table":"orderBookL2","action":"delete","data":[{"symbol":"XLMUSDT","id":52199939300,"side":"Buy"}]}
1618677689.410186: {"table":"orderBookL2","action":"delete","data":[{"symbol":"DOGEUSDT","id":47599971830,"side":"Buy"}]}
1618677689.410235: {"table":"orderBookL2","action":"insert","data":[{"symbol":"DOGEUSDT","id":47599971832,"side":"Buy","size":2110,"price":0.28168}]}
1618677689.4154701: {"table":"orderBookL2","action":"insert","data":[{"symbol":"EOSUSDT","id":53899984055,"side":"Sell","size":55,"price":7.9725}]}
1618677689.424361: {"table":"orderBookL2","action":"delete","data":[{"symbol":"DOGEUSDT","id":47599971832,"side":"Buy"}]}
1618677689.424403: {"table":"orderBookL2","action":"insert","data":[{"symbol":"DOGEUSDT","id":47599971838,"side":"Buy","size":2110,"price":0.28162}]}
1618677689.440083: {"table":"orderBookL2","action":"delete","data":[{"symbol":"DOGEUSDT","id":47599971838,"side":"Buy"}]}
1618677689.440129: {"table":"orderBookL2","action":"insert","data":[{"symbol":"DOGEUSDT","id":47599971849,"side":"Buy","size":2110,"price":0.28151}]}
1618677689.441904: {"table":"orderBookL2","action":"delete","data":[{"symbol":"LTCUSD","id":40699968731,"side":"Buy"}]}
1618677689.4516978: {"table":"orderBookL2","action":"delete","data":[{"symbol":"DOGEUSDT","id":47599971849,"side":"Buy"}]}
1618677689.451744: {"table":"orderBookL2","action":"insert","data":[{"symbol":"DOGEUSDT","id":47599971851,"side":"Buy","size":2110,"price":0.28149}]}
1618677689.5009909: {"table":"orderBookL2","action":"delete","data":[{"symbol":"DOGEUSDT","id":47599971851,"side":"Buy"}]}
1618677689.501109: {"table":"orderBookL2","action":"insert","data":[{"symbol":"DOGEUSDT","id":47599971855,"side":"Buy","size":2110,"price":0.28145}]}
1618677689.5051441: {"table":"orderBookL2","action":"delete","data":[{"symbol":"DOGEUSDT","id":47599971574,"side":"Sell"}]}
1618677689.505246: {"table":"orderBookL2","action":"insert","data":[{"symbol":"DOGEUSDT","id":47599971629,"side":"Sell","size":1659,"price":0.28371}]}
1618677689.5199628: {"table":"orderBookL2","action":"update","data":[{"symbol":"DOGEUSDT","id":47599971575,"side":"Sell","size":2324}]}
1618677689.5200331: {"table":"orderBookL2","action":"insert","data":[{"symbol":"DOGEUSDT","id":47599971630,"side":"Sell","size":300,"price":0.2837}]}
1618677689.522872: {"table":"orderBookL2","action":"delete","data":[{"symbol":"DOGEUSDT","id":47599971575,"side":"Sell"}]}
1618677689.522966: {"table":"orderBookL2","action":"insert","data":[{"symbol":"DOGEUSDT","id":47599971631,"side":"Sell","size":728,"price":0.28369}]}
1618677689.5230389: {"table":"orderBookL2","action":"delete","data":[{"symbol":"DOGEUSDT","id":47599971631,"side":"Sell"}]}
1618677689.6143591: {"table":"orderBookL2","action":"delete","data":[{"symbol":"DOGEUSDT","id":47599972011,"side":"Buy"}]}
1618677689.614462: {"table":"orderBookL2","action":"insert","data":[{"symbol":"DOGEUSDT","id":47599972043,"side":"Buy","size":154,"price":0.27957}]}
1618677689.621634: {"table":"orderBookL2","action":"delete","data":[{"symbol":"ADAM21","id":52299997774,"side":"Sell"}]}
1618677689.621724: {"table":"orderBookL2","action":"update","data":[{"symbol":"ADAM21","id":52299997765,"side":"Sell","size":50365},{"symbol":"ADAM21","id":52299997862,"side":"Buy","size":69260},{"symbol":"ADAM21","id":52299997869,"side":"Buy","size":32096},{"symbol":"ADAM21","id":52299997875,"side":"Buy","size":151571},{"symbol":"ADAM21","id":52299997893,"side":"Buy","size":70303},{"symbol":"ADAM21","id":52299997896,"side":"Buy","size":14857}]}
1618677689.621799: {"table":"orderBookL2","action":"insert","data":[{"symbol":"ADAM21","id":52299997771,"side":"Sell","size":47031,"price":0.00002229},{"symbol":"ADAM21","id":52299997778,"side":"Sell","size":40312,"price":0.00002222},{"symbol":"ADAM21","id":52299997858,"side":"Buy","size":26875,"price":0.00002142},{"symbol":"ADAM21","id":52299997866,"side":"Buy","size":33594,"price":0.00002134},{"symbol":"ADAM21","id":52299997871,"side":"Buy","size":40312,"price":0.00002129}]}
1618677689.6240032: {"table":"orderBookL2","action":"update","data":[{"symbol":"TRXM21","id":52999999757,"side":"Sell","size":3504787}]}
1618677689.6428921: {"table":"orderBookL2","action":"delete","data":[{"symbol":"ADAM21","id":52299997817,"side":"Sell"}]}
1618677689.643011: {"table":"orderBookL2","action":"insert","data":[{"symbol":"ADAM21","id":52299997823,"side":"Sell","size":536,"price":0.00002177}]}
1618677689.699612: {"table":"orderBookL2","action":"update","data":[{"symbol":"DOGEUSDT","id":47599972086,"side":"Buy","size":13456}]}
1618677689.6996648: {"table":"orderBookL2","action":"insert","data":[{"symbol":"DOGEUSDT","id":47599972226,"side":"Buy","size":268,"price":0.27774}]}
1618677689.725852: {"table":"orderBookL2","action":"insert","data":[{"symbol":"LTCUSD","id":40699968740,"side":"Buy","size":247,"price":312.6}]}
1618677689.725986: {"table":"orderBookL2","action":"update","data":[{"symbol":"LTCUSD","id":40699968732,"side":"Buy","size":372}]}
1618677689.735942: {"table":"orderBookL2","action":"delete","data":[{"symbol":"LTCUSD","id":40699968182,"side":"Sell"},{"symbol":"LTCUSD","id":40699968511,"side":"Sell"},{"symbol":"LTCUSD","id":40699969012,"side":"Buy"},{"symbol":"LTCUSD","id":40699969218,"side":"Buy"}]}
1618677689.736087: {"table":"orderBookL2","action":"update","data":[{"symbol":"LTCUSD","id":40699968405,"side":"Sell","size":10238},{"symbol":"LTCUSD","id":40699968508,"side":"Sell","size":879},{"symbol":"LTCUSD","id":40699968910,"side":"Buy","size":1810},{"symbol":"LTCUSD","id":40699968948,"side":"Buy","size":2728}]}
1618677689.736156: {"table":"orderBookL2","action":"insert","data":[{"symbol":"LTCUSD","id":40699968158,"side":"Sell","size":579,"price":318.42},{"symbol":"LTCUSD","id":40699968391,"side":"Sell","size":579,"price":316.09},{"symbol":"LTCUSD","id":40699969026,"side":"Buy","size":579,"price":309.74},{"symbol":"LTCUSD","id":40699969241,"side":"Buy","size":579,"price":307.59}]}
1618677689.8375711: {"table":"orderBookL2","action":"delete","data":[{"symbol":"DOGEUSDT","id":47599972043,"side":"Buy"}]}
1618677689.837628: {"table":"orderBookL2","action":"insert","data":[{"symbol":"DOGEUSDT","id":47599972066,"side":"Buy","size":154,"price":0.27934}]}
1618677689.880568: {"table":"orderBookL2","action":"delete","data":[{"symbol":"LTCUSD","id":40699968682,"side":"Sell"}]}
1618677689.880616: {"table":"orderBookL2","action":"insert","data":[{"symbol":"LTCUSD","id":40699968684,"side":"Sell","size":125,"price":313.16}]}
1618677689.953803: {"table":"orderBookL2","action":"delete","data":[{"symbol":"LTCUSD","id":40699968684,"side":"Sell"}]}
1618677689.9681349: {"table":"orderBookL2","action":"insert","data":[{"symbol":"LTCUSD","id":40699968725,"side":"Buy","size":412,"price":312.75}]}
1618677689.988428: {"table":"orderBookL2","action":"delete","data":[{"symbol":"LTCUSD","id":40699968726,"side":"Buy"}]}
1618677689.9936159: {"table":"orderBookL2","action":"delete","data":[{"symbol":"DOGEUSDT","id":47599971576,"side":"Sell"}]}
1618677689.993671: {"table":"orderBookL2","action":"update","data":[{"symbol":"DOGEUSDT","id":47599971630,"side":"Sell","size":350}]}
1618677690.053195: {"table":"orderBookL2","action":"delete","data":[{"symbol":"LTCUSD","id":40699968683,"side":"Sell"}]}
1618677690.0575192: {"table":"orderBookL2","action":"insert","data":[{"symbol":"LTCUSD","id":40699968724,"side":"Buy","size":78,"price":312.76}]}
1618677690.060628: {"table":"orderBookL2","action":"delete","data":[{"symbol":"DOGEUSDT","id":47599972066,"side":"Buy"}]}
1618677690.060672: {"table":"orderBookL2","action":"insert","data":[{"symbol":"DOGEUSDT","id":47599972094,"side":"Buy","size":154,"price":0.27906}]}
1618677690.073635: {"table":"orderBookL2","action":"insert","data":[{"symbol":"LINKUSDTM21","id":52799886585,"side":"Buy","size":5,"price":56.7075}]}
1618677690.146003: {"table":"orderBookL2","action":"insert","data":[{"symbol":"DOGEUSDT","id":47599971954,"side":"Buy","size":354,"price":0.28046}]}
1618677690.19189: {"table":"orderBookL2","action":"delete","data":[{"symbol":"DOGEUSDT","id":47599971915,"side":"Buy"},{"symbol":"DOGEUSDT","id":47599971916,"side":"Buy"},{"symbol":"DOGEUSDT","id":47599971917,"side":"Buy"},{"symbol":"DOGEUSDT","id":47599971918,"side":"Buy"},{"symbol":"DOGEUSDT","id":47599971919,"side":"Buy"}]}
1618677690.1970549: {"table":"orderBookL2","action":"delete","data":[{"symbol":"XLMUSDT","id":52199939025,"side":"Sell"}]}
1618677690.1983: {"table":"orderBookL2","action":"delete","data":[{"symbol":"DOGEUSDT","id":47599972236,"side":"Buy"}]}
1618677690.199553: {"table":"orderBookL2","action":"insert","data":[{"symbol":"DOGEUSDT","id":47599972568,"side":"Buy","size":40095,"price":0.27432}]}
1618677690.2014132: {"table":"orderBookL2","action":"delete","data":[{"symbol":"DOGEUSDT","id":47599971840,"side":"Buy"}]}
1618677690.201499: {"table":"orderBookL2","action":"insert","data":[{"symbol":"DOGEUSDT","id":47599971992,"side":"Buy","size":394,"price":0.28008}]}
1618677690.204834: {"table":"orderBookL2","action":"update","data":[{"symbol":"DOGEUSDT","id":47599972000,"side":"Buy","size":300}]}
1618677690.204909: {"table":"orderBookL2","action":"insert","data":[{"symbol":"DOGEUSDT","id":47599971997,"side":"Buy","size":100,"price":0.28003},{"symbol":"DOGEUSDT","id":47599971998,"side":"Buy","size":100,"price":0.28002},{"symbol":"DOGEUSDT","id":47599971999,"side":"Buy","size":100,"price":0.28001},{"symbol":"DOGEUSDT","id":47599972001,"side":"Buy","size":100,"price":0.27999}]}
1618677690.271515: {"table":"orderBookL2","action":"delete","data":[{"symbol":"DOGEUSDT","id":47599971855,"side":"Buy"}]}
1618677690.271583: {"table":"orderBookL2","action":"insert","data":[{"symbol":"DOGEUSDT","id":47599971859,"side":"Buy","size":2110,"price":0.28141}]}
1618677690.3137221: {"table":"orderBookL2","action":"delete","data":[{"symbol":"DOGEUSDT","id":47599971629,"side":"Sell"}]}
1618677690.3137898: {"table":"orderBookL2","action":"insert","data":[{"symbol":"DOGEUSDT","id":47599971631,"side":"Sell","size":1659,"price":0.28369}]}
1618677690.317725: {"table":"orderBookL2","action":"delete","data":[{"symbol":"DOGEUSDT","id":47599971954,"side":"Buy"}]}
1618677690.327788: {"table":"orderBookL2","action":"update","data":[{"symbol":"DOGEUSDT","id":47599971630,"side":"Sell","size":50}]}
1618677690.3416152: {"table":"orderBookL2","action":"insert","data":[{"symbol":"DOGEUSDT","id":47599971632,"side":"Sell","size":300,"price":0.28368}]}
1618677690.4110541: {"table":"orderBookL2","action":"delete","data":[{"symbol":"DOGEUSDT","id":47599970354,"side":"Sell"},{"symbol":"DOGEUSDT","id":47599970496,"side":"Sell"},{"symbol":"DOGEUSDT","id":47599970637,"side":"Sell"},{"symbol":"DOGEUSDT","id":47599970779,"side":"Sell"},{"symbol":"DOGEUSDT","id":47599970920,"side":"Sell"},{"symbol":"DOGEUSDT","id":47599971062,"side":"Sell"},{"symbol":"DOGEUSDT","id":47599971203,"side":"Sell"},{"symbol":"DOGEUSDT","id":47599971345,"side":"Sell"},{"symbol":"DOGEUSDT","id":47599971486,"side":"Sell"},{"symbol":"DOGEUSDT","id":47599971628,"side":"Sell"},{"symbol":"DOGEUSDT","id":47599971852,"side":"Buy"},{"symbol":"DOGEUSDT","id":47599971993,"side":"Buy"},{"symbol":"DOGEUSDT","id":47599972135,"side":"Buy"},{"symbol":"DOGEUSDT","id":47599972276,"side":"Buy"},{"symbol":"DOGEUSDT","id":47599972418,"side":"Buy"},{"symbol":"DOGEUSDT","id":47599972559,"side":"Buy"},{"symbol":"DOGEUSDT","id":47599972701,"side":"Buy"},{"symbol":"DOGEUSDT","id":47599972842,"side":"Buy"},{"symbol":"DOGEUSDT","id":47599972984,"side":"Buy"},{"symbol":"DOGEUSDT","id":47599973125,"side":"Buy"}]}
1618677690.411227: {"table":"orderBookL2","action":"update","data":[{"symbol":"DOGEUSDT","id":47599971121,"side":"Sell","size":12974},{"symbol":"DOGEUSDT","id":47599971262,"side":"Sell","size":178},{"symbol":"DOGEUSDT","id":47599971631,"side":"Sell","size":1697},{"symbol":"DOGEUSDT","id":47599972475,"side":"Buy","size":2464}]}
1618677690.4112709: {"table":"orderBookL2","action":"insert","data":[{"symbol":"DOGEUSDT","id":47599970414,"side":"Sell","size":126,"price":0.29586},{"symbol":"DOGEUSDT","id":47599970556,"side":"Sell","size":126,"price":0.29444},{"symbol":"DOGEUSDT","id":47599970697,"side":"Sell","size":126,"price":0.29303},{"symbol":"DOGEUSDT","id":47599970838,"side":"Sell","size":126,"price":0.29162},{"symbol":"DOGEUSDT","id":47599970980,"side":"Sell","size":111,"price":0.2902},{"symbol":"DOGEUSDT","id":47599971404,"side":"Sell","size":50,"price":0.28596},{"symbol":"DOGEUSDT","id":47599971545,"side":"Sell","size":38,"price":0.28455},{"symbol":"DOGEUSDT","id":47599971910,"side":"Buy","size":38,"price":0.2809},{"symbol":"DOGEUSDT","id":47599972051,"side":"Buy","size":43,"price":0.27949},{"symbol":"DOGEUSDT","id":47599972193,"side":"Buy","size":75,"price":0.27807},{"symbol":"DOGEUSDT","id":47599972334,"side":"Buy","size":108,"price":0.27666},{"symbol":"DOGEUSDT","id":47599972617,"side":"Buy","size":173,"price":0.27383},{"symbol":"DOGEUSDT","id":47599972758,"side":"Buy","size":186,"price":0.27242},{"symbol":"DOGEUSDT","id":47599972899,"side":"Buy","size":186,"price":0.27101},{"symbol":"DOGEUSDT","id":47599973041,"side":"Buy","size":186,"price":0.26959},{"symbol":"DOGEUSDT","id":47599973182,"side":"Buy","size":186,"price":0.26818}]}
1618677690.4593248: {"table":"orderBookL2","action":"delete","data":[{"symbol":"LTCUSD","id":40699968667,"side":"Sell"}]}
1618677690.4593868: {"table":"orderBookL2","action":"update","data":[{"symbol":"LTCUSD","id":40699968680,"side":"Sell","size":247}]}
1618677690.4701161: {"table":"orderBookL2","action":"update","data":[{"symbol":"LTCM21","id":52899998914,"side":"Sell","size":1},{"symbol":"LTCM21","id":52899998922,"side":"Sell","size":491},{"symbol":"LTCM21","id":52899998926,"side":"Sell","size":277},{"symbol":"LTCM21","id":52899998932,"side":"Sell","size":280},{"symbol":"LTCM21","id":52899998972,"side":"Buy","size":151},{"symbol":"LTCM21","id":52899998978,"side":"Buy","size":527}]}
1618677690.480438: {"table":"orderBookL2","action":"delete","data":[{"symbol":"LTCUSD","id":40699968680,"side":"Sell"}]}
1618677690.500027: {"table":"orderBookL2","action":"delete","data":[{"symbol":"DOGEUSDT","id":47599971859,"side":"Buy"}]}
1618677690.500082: {"table":"orderBookL2","action":"insert","data":[{"symbol":"DOGEUSDT","id":47599971858,"side":"Buy","size":2110,"price":0.28142}]}
1618677690.5096772: {"table":"orderBookL2","action":"delete","data":[{"symbol":"LTCUSD","id":40699968657,"side":"Sell"}]}
1618677690.51158: {"table":"orderBookL2","action":"delete","data":[{"symbol":"LTCUSD","id":40699968668,"side":"Sell"}]}
1618677690.5506392: {"table":"orderBookL2","action":"update","data":[{"symbol":"TRXUSDT","id":53999983887,"side":"Sell","size":1425}]}
1618677690.7143629: {"table":"orderBookL2","action":"delete","data":[{"symbol":"LTCUSD","id":40699968158,"side":"Sell"},{"symbol":"LTCUSD","id":40699968391,"side":"Sell"},{"symbol":"LTCUSD","id":40699969026,"side":"Buy"},{"symbol":"LTCUSD","id":40699969241,"side":"Buy"}]}
