1618677663.0200808: {"table":"orderBookL2","action":"partial","keys":["symbol","id","side"],"types":{"symbol":"symbol","id":"long","side":"symbol","size":"long","price":"float"},"foreignKeys":{"symbol":"instrument","side":"side"},"attributes":{"symbol":"parted","id":"sorted"},"filter":{"symbol":"LTCM21"},"data":[{"symbol":"LTCM21","id":52899995700,"side":"Sell","size":5,"price":0.0215},{"symbol":"LTCM21","id":52899996310,"side":"Sell","size":600,"price":0.01845},{"symbol":"LTCM21","id":52899996644,"side":"Sell","size":600,"price":0.01678},{"symbol":"LTCM21","id":52899996800,"side":"Sell","size":5,"price":0.016},{"symbol":"LTCM21","id":52899996950,"side":"Sell","size":600,"price":0.01525},{"symbol":"LTCM21","id":52899997000,"side":"Sell","size":1,"price":0.015},{"symbol":"LTCM21","id":52899997228,"side":"Sell","size":600,"price":0.01386},{"symbol":"LTCM21","id":52899997355,"side":"Sell","size":38,"price":0.013225},{"symbol":"LTCM21","id":52899997480,"side":"Sell","size":600,"price":0.0126},{"symbol":"LTCM21","id":52899997708,"side":"Sell","size":600,"price":0.01146},{"symbol":"LTCM21","id":52899997774,"side":"Sell","size":50,"price":0.01113},{"symbol":"LTCM21","id":52899997916,"side":"Sell","size":600,"price":0.01042},{"symbol":"LTCM21","id":52899998000,"side":"Sell","size":32,"price":0.01},{"symbol":"LTCM21","id":52899998020,"side":"Sell","size":32,"price":0.0099},{"symbol":"LTCM21","id":52899998041,"side":"Sell","size":32,"price":0.009795},{"symbol":"LTCM21","id":52899998062,"side":"Sell","size":32,"price":0.00969},{"symbol":"LTCM21","id":52899998083,"side":"Sell","size":32,"price":0.009585},{"symbol":"LTCM21","id":52899998100,"side":"Sell","size":100,"price":0.0095},{"symbol":"LTCM21","id":52899998104,"side":"Sell","size":33,"price":0.00948},{"symbol":"LTCM21","id":52899998106,"side":"Sell","size":600,"price":0.00947},{"symbol":"LTCM21","id":52899998124,"side":"Sell","size":32,"price":0.00938},{"symbol":"LTCM21","id":52899998145,"side":"Sell","size":32,"price":0.009275},{"symbol":"LTCM21","id":52899998166,"side":"Sell","size":32,"price":0.00917},{"symbol":"LTCM21","id":52899998187,"side":"Sell","size":32,"price":0.009065},{"symbol":"LTCM21","id":52899998208,"side":"Sell","size":32,"price":0.00896},{"symbol":"LTCM21","id":52899998220,"side":"Sell","size":50,"price":0.0089},{"symbol":"LTCM21","id":52899998229,"side":"Sell","size":32,"price":0.008855},{"symbol":"LTCM21","id":52899998249,"side":"Sell","size":32,"price":0.008755},{"symbol":"LTCM21","id":52899998270,"side":"Sell","size":32,"price":0.00865},{"symbol":"LTCM21","id":52899998278,"side":"Sell","size":600,"price":0.00861},{"symbol":"LTCM21","id":52899998291,"side":"Sell","size":32,"price":0.008545},{"symbol":"LTCM21","id":52899998312,"side":"Sell","size":32,"price":0.00844},{"symbol":"LTCM21","id":52899998333,"side":"Sell","size":32,"price":0.008335},{"symbol":"LTCM21","id":52899998354,"side":"Sell","size":32,"price":0.00823},{"symbol":"LTCM21","id":52899998375,"side":"Sell","size":32,"price":0.008125},{"symbol":"LTCM21","id":52899998395,"side":"Sell","size":32,"price":0.008025},{"symbol":"LTCM21","id":52899998416,"side":"Sell","size":32,"price":0.00792},{"symbol":"LTCM21","id":52899998434,"side":"Sell","size":600,"price":0.00783},{"symbol":"LTCM21","id":52899998437,"side":"Sell","size":32,"price":0.007815},{"symbol":"LTCM21","id":52899998458,"side":"Sell","size":32,"price":0.00771},{"symbol":"LTCM21","id":52899998479,"side":"Sell","size":32,"price":0.007605},{"symbol":"LTCM21","id":52899998500,"side":"Sell","size":132,"price":0.0075},{"symbol":"LTCM21","id":52899998566,"side":"Sell","size":10,"price":0.00717},{"symbol":"LTCM21","id":52899998584,"side":"Sell","size":2,"price":0.00708},{"symbol":"LTCM21","id":52899998596,"side":"Sell","size":1,"price":0.00702},{"symbol":"LTCM21","id":52899998597,"side":"Sell","size":50,"price":0.007015},{"symbol":"LTCM21","id":52899998600,"side":"Sell","size":3,"price":0.007},{"symbol":"LTCM21","id":52899998610,"side":"Sell","size":40,"price":0.00695},{"symbol":"LTCM21","id":52899998644,"side":"Sell","size":5,"price":0.00678},{"symbol":"LTCM21","id":52899998653,"side":"Sell","size":700,"price":0.006735},{"symbol":"LTCM21","id":52899998662,"side":"Sell","size":150,"price":0.00669},{"symbol":"LTCM21","id":52899998672,"side":"Sell","size":2,"price":0.00664},{"symbol":"LTCM21","id":52899998694,"side":"Sell","size":10,"price":0.00653},{"symbol":"LTCM21","id":52899998706,"side":"Sell","size":41,"price":0.00647},{"symbol":"LTCM21","id":52899998732,"side":"Sell","size":55,"price":0.00634},{"symbol":"LTCM21","id":52899998734,"side":"Sell","size":25,"price":0.00633},{"symbol":"LTCM21","id":52899998742,"side":"Sell","size":5,"price":0.00629},{"symbol":"LTCM21","id":52899998760,"side":"Sell","size":10,"price":0.0062},{"symbol":"LTCM21","id":52899998761,"side":"Sell","size":59,"price":0.006195},{"symbol":"LTCM21","id":52899998763,"side":"Sell","size":59,"price":0.006185},{"symbol":"LTCM21","id":52899998766,"side":"Sell","size":21,"price":0.00617},{"symbol":"LTCM21","id":52899998774,"side":"Sell","size":32,"price":0.00613},{"symbol":"LTCM21","id":52899998776,"side":"Sell","size":5,"price":0.00612},{"symbol":"LTCM21","id":52899998780,"side":"Sell","size":35,"price":0.0061},{"symbol":"LTCM21","id":52899998782,"side":"Sell","size":5,"price":0.00609},{"symbol":"LTCM21","id":52899998800,"side":"Sell","size":125,"price":0.006},{"symbol":"LTCM21","id":52899998804,"side":"Sell","size":13,"price":0.00598},{"symbol":"LTCM21","id":52899998808,"side":"Sell","size":25,"price":0.00596},{"symbol":"LTCM21","id":52899998814,"side":"Sell","size":21,"price":0.00593},{"symbol":"LTCM21","id":52899998816,"side":"Sell","size":62,"price":0.00592},{"symbol":"LTCM21","id":52899998820,"side":"Sell","size":35,"price":0.0059},{"symbol":"LTCM21","id":52899998821,"side":"Sell","size":5,"price":0.005895},{"symbol":"LTCM21","id":52899998824,"side":"Sell","size":4,"price":0.00588},{"symbol":"LTCM21","id":52899998826,"side":"Sell","size":50,"price":0.00587},{"symbol":"LTCM21","id":52899998830,"side":"Sell","size":81,"price":0.00585},{"symbol":"LTCM21","id":52899998834,"side":"Sell","size":5,"price":0.00583},{"symbol":"LTCM21","id":52899998836,"side":"Sell","size":5,"price":0.00582},{"symbol":"LTCM21","id":52899998837,"side":"Sell","size":58,"price":0.005815},{"symbol":"LTCM21","id":52899998838,"side":"Sell","size":21,"price":0.00581},{"symbol":"LTCM21","id":52899998840,"side":"Sell","size":35,"price":0.0058},{"symbol":"LTCM21","id":52899998844,"side":"Sell","size":53,"price":0.00578},{"symbol":"LTCM21","id":52899998846,"side":"Sell","size":50,"price":0.00577},{"symbol":"LTCM21","id":52899998848,"side":"Sell","size":82,"price":0.00576},{"symbol":"LTCM21","id":52899998850,"side":"Sell","size":106,"price":0.00575},{"symbol":"LTCM21","id":52899998852,"side":"Sell","size":50,"price":0.00574},{"symbol":"LTCM21","id":52899998854,"side":"Sell","size":50,"price":0.00573},{"symbol":"LTCM21","id":52899998856,"side":"Sell","size":50,"price":0.00572},{"symbol":"LTCM21","id":52899998858,"side":"Sell","size":141,"price":0.00571},{"symbol":"LTCM21","id":52899998860,"side":"Sell","size":168,"price":0.0057},{"symbol":"LTCM21","id":52899998862,"side":"Sell","size":50,"price":0.00569},{"symbol":"LTCM21","id":52899998863,"side":"Sell","size":5,"price":0.005685},{"symbol":"LTCM21","id":52899998864,"side":"Sell","size":53,"price":0.00568},{"symbol":"LTCM21","id":52899998866,"side":"Sell","size":50,"price":0.00567},{"symbol":"LTCM21","id":52899998868,"side":"Sell","size":70,"price":0.00566},{"symbol":"LTCM21","id":52899998870,"side":"Sell","size":61,"price":0.00565},{"symbol":"LTCM21","id":52899998872,"side":"Sell","size":76,"price":0.00564},{"symbol":"LTCM21","id":52899998874,"side":"Sell","size":70,"price":0.00563},{"symbol":"LTCM21","id":52899998877,"side":"Sell","size":59,"price":0.005615},{"symbol":"LTCM21","id":52899998878,"side":"Sell","size":50,"price":0.00561},{"symbol":"LTCM21","id":52899998880,"side":"Sell","size":40,"price":0.0056},{"symbol":"LTCM21","id":52899998881,"side":"Sell","size":5,"price":0.005595},{"symbol":"LTCM21","id":52899998882,"side":"Sell","size":50,"price":0.00559},{"symbol":"LTCM21","id":52899998884,"side":"Sell","size":3,"price":0.00558},{"symbol":"LTCM21","id":52899998886,"side":"Sell","size":5,"price":0.00557},{"symbol":"LTCM21","id":52899998888,"side":"Sell","size":50,"price":0.00556},{"symbol":"LTCM21","id":52899998889,"side":"Sell","size":59,"price":0.005555},{"symbol":"LTCM21","id":52899998890,"side":"Sell","size":51,"price":0.00555},{"symbol":"LTCM21","id":52899998891,"side":"Sell","size":5,"price":0.005545},{"symbol":"LTCM21","id":52899998892,"side":"Sell","size":2217,"price":0.00554},{"symbol":"LTCM21","id":52899998894,"side":"Sell","size":70,"price":0.00553},{"symbol":"LTCM21","id":52899998896,"side":"Sell","size":5,"price":0.00552},{"symbol":"LTCM21","id":52899998897,"side":"Sell","size":50,"price":0.005515},{"symbol":"LTCM21","id":52899998900,"side":"Sell","size":70,"price":0.0055},{"symbol":"LTCM21","id":52899998901,"side":"Sell","size":5,"price":0.005495},{"symbol":"LTCM21","id":52899998906,"side":"Sell","size":61,"price":0.00547},{"symbol":"LTCM21","id":52899998908,"side":"Sell","size":5,"price":0.00546},{"symbol":"LTCM21","id":52899998912,"side":"Sell","size":1,"price":0.00544},{"symbol":"LTCM21","id":52899998913,"side":"Sell","size":9,"price":0.005435},{"symbol":"LTCM21","id":52899998914,"side":"Sell","size":486,"price":0.00543},{"symbol":"LTCM21","id":52899998916,"side":"Sell","size":58,"price":0.00542},{"symbol":"LTCM21","id":52899998917,"side":"Sell","size":88,"price":0.005415},{"symbol":"LTCM21","id":52899998919,"side":"Sell","size":355,"price":0.005405},{"symbol":"LTCM21","id":52899998921,"side":"Sell","size":197,"price":0.005395},{"symbol":"LTCM21","id":52899998922,"side":"Sell","size":6,"price":0.00539},{"symbol":"LTCM21","id":52899998923,"side":"Sell","size":197,"price":0.005385},{"symbol":"LTCM21","id":52899998924,"side":"Sell","size":479,"price":0.00538},{"symbol":"LTCM21","id":52899998925,"side":"Sell","size":499,"price":0.005375},{"symbol":"LTCM21","id":52899998926,"side":"Sell","size":623,"price":0.00537},{"symbol":"LTCM21","id":52899998927,"side":"Sell","size":198,"price":0.005365},{"symbol":"LTCM21","id":52899998928,"side":"Sell","size":556,"price":0.00536},{"symbol":"LTCM21","id":52899998929,"side":"Sell","size":299,"price":0.005355},{"symbol":"LTCM21","id":52899998931,"side":"Sell","size":199,"price":0.005345},{"symbol":"LTCM21","id":52899998932,"side":"Sell","size":3,"price":0.00534},{"symbol":"LTCM21","id":52899998933,"side":"Sell","size":228,"price":0.005335},{"symbol":"LTCM21","id":52899998935,"side":"Sell","size":202,"price":0.005325},{"symbol":"LTCM21","id":52899998936,"side":"Sell","size":77,"price":0.00532},{"symbol":"LTCM21","id":52899998937,"side":"Sell","size":200,"price":0.005315},{"symbol":"LTCM21","id":52899998938,"side":"Sell","size":21,"price":0.00531},{"symbol":"LTCM21","id":52899998939,"side":"Sell","size":200,"price":0.005305},{"symbol":"LTCM21","id":52899998940,"side":"Sell","size":276,"price":0.0053},{"symbol":"LTCM21","id":52899998941,"side":"Sell","size":54,"price":0.005295},{"symbol":"LTCM21","id":52899998942,"side":"Sell","size":63,"price":0.00529},{"symbol":"LTCM21","id":52899998943,"side":"Sell","size":16,"price":0.005285},{"symbol":"LTCM21","id":52899998944,"side":"Sell","size":18,"price":0.00528},{"symbol":"LTCM21","id":52899998945,"side":"Buy","size":18,"price":0.005275},{"symbol":"LTCM21","id":52899998946,"side":"Buy","size":20,"price":0.00527},{"symbol":"LTCM21","id":52899998947,"side":"Buy","size":15,"price":0.005265},{"symbol":"LTCM21","id":52899998948,"side":"Buy","size":215,"price":0.00526},{"symbol":"LTCM21","id":52899998949,"side":"Buy","size":11,"price":0.005255},{"symbol":"LTCM21","id":52899998950,"side":"Buy","size":205,"price":0.00525},{"symbol":"LTCM21","id":52899998952,"side":"Buy","size":374,"price":0.00524},{"symbol":"LTCM21","id":52899998953,"side":"Buy","size":2,"price":0.005235},{"symbol":"LTCM21","id":52899998954,"side":"Buy","size":203,"price":0.00523},{"symbol":"LTCM21","id":52899998956,"side":"Buy","size":204,"price":0.00522},{"symbol":"LTCM21","id":52899998957,"side":"Buy","size":207,"price":0.005215},{"symbol":"LTCM21","id":52899998958,"side":"Buy","size":277,"price":0.00521},{"symbol":"LTCM21","id":52899998959,"side":"Buy","size":204,"price":0.005205},{"symbol":"LTCM21","id":52899998960,"side":"Buy","size":350,"price":0.0052},{"symbol":"LTCM21","id":52899998961,"side":"Buy","size":205,"price":0.005195},{"symbol":"LTCM21","id":52899998962,"side":"Buy","size":1,"price":0.00519},{"symbol":"LTCM21","id":52899998963,"side":"Buy","size":511,"price":0.005185},{"symbol":"LTCM21","id":52899998964,"side":"Buy","size":416,"price":0.00518},{"symbol":"LTCM21","id":52899998965,"side":"Buy","size":206,"price":0.005175},{"symbol":"LTCM21","id":52899998966,"side":"Buy","size":638,"price":0.00517},{"symbol":"LTCM21","id":52899998967,"side":"Buy","size":206,"price":0.005165},{"symbol":"LTCM21","id":52899998969,"side":"Buy","size":212,"price":0.005155},{"symbol":"LTCM21","id":52899998970,"side":"Buy","size":102,"price":0.00515},{"symbol":"LTCM21","id":52899998972,"side":"Buy","size":678,"price":0.00514},{"symbol":"LTCM21","id":52899998974,"side":"Buy","size":6,"price":0.00513},{"symbol":"LTCM21","id":52899998976,"side":"Buy","size":43,"price":0.00512},{"symbol":"LTCM21","id":52899998977,"side":"Buy","size":89,"price":0.005115},{"symbol":"LTCM21","id":52899998978,"side":"Buy","size":7,"price":0.00511},{"symbol":"LTCM21","id":52899998980,"side":"Buy","size":700,"price":0.0051},{"symbol":"LTCM21","id":52899998982,"side":"Buy","size":98,"price":0.00509},{"symbol":"LTCM21","id":52899998984,"side":"Buy","size":68,"price":0.00508},{"symbol":"LTCM21","id":52899998986,"side":"Buy","size":64,"price":0.00507},{"symbol":"LTCM21","id":52899998987,"side":"Buy","size":5,"price":0.005065},{"symbol":"LTCM21","id":52899998988,"side":"Buy","size":2337,"price":0.00506},{"symbol":"LTCM21","id":52899998990,"side":"Buy","size":1886,"price":0.00505},{"symbol":"LTCM21","id":52899998991,"side":"Buy","size":18,"price":0.005045},{"symbol":"LTCM21","id":52899998992,"side":"Buy","size":158,"price":0.00504},{"symbol":"LTCM21","id":52899998993,"side":"Buy","size":2,"price":0.005035},{"symbol":"LTCM21","id":52899998994,"side":"Buy","size":232,"price":0.00503},{"symbol":"LTCM21","id":52899998995,"side":"Buy","size":3,"price":0.005025},{"symbol":"LTCM21","id":52899998996,"side":"Buy","size":162,"price":0.00502},{"symbol":"LTCM21","id":52899998998,"side":"Buy","size":307,"price":0.00501},{"symbol":"LTCM21","id":52899999000,"side":"Buy","size":3426,"price":0.005},{"symbol":"LTCM21","id":52899999002,"side":"Buy","size":5,"price":0.00499},{"symbol":"LTCM21","id":52899999004,"side":"Buy","size":216,"price":0.00498},{"symbol":"LTCM21","id":52899999005,"side":"Buy","size":58,"price":0.004975},{"symbol":"LTCM21","id":52899999006,"side":"Buy","size":157,"price":0.00497},{"symbol":"LTCM21","id":52899999008,"side":"Buy","size":113,"price":0.00496},{"symbol":"LTCM21","id":52899999010,"side":"Buy","size":18,"price":0.00495},{"symbol":"LTCM21","id":52899999012,"side":"Buy","size":152,"price":0.00494},{"symbol":"LTCM21","id":52899999016,"side":"Buy","size":148,"price":0.00492},{"symbol":"LTCM21","id":52899999018,"side":"Buy","size":60,"price":0.00491},{"symbol":"LTCM21","id":52899999020,"side":"Buy","size":1025,"price":0.0049},{"symbol":"LTCM21","id":52899999022,"side":"Buy","size":268,"price":0.00489},{"symbol":"LTCM21","id":52899999024,"side":"Buy","size":48,"price":0.00488},{"symbol":"LTCM21","id":52899999026,"side":"Buy","size":257,"price":0.00487},{"symbol":"LTCM21","id":52899999027,"side":"Buy","size":3,"price":0.004865},{"symbol":"LTCM21","id":52899999028,"side":"Buy","size":58,"price":0.00486},{"symbol":"LTCM21","id":52899999029,"side":"Buy","size":3,"price":0.004855},{"symbol":"LTCM21","id":52899999030,"side":"Buy","size":170,"price":0.00485},{"symbol":"LTCM21","id":52899999032,"side":"Buy","size":1337,"price":0.00484},{"symbol":"LTCM21","id":52899999033,"side":"Buy","size":24,"price":0.004835},{"symbol":"LTCM21","id":52899999034,"side":"Buy","size":42,"price":0.00483},{"symbol":"LTCM21","id":52899999035,"side":"Buy","size":3,"price":0.004825},{"symbol":"LTCM21","id":52899999036,"side":"Buy","size":100,"price":0.00482},{"symbol":"LTCM21","id":52899999037,"side":"Buy","size":200,"price":0.004815},{"symbol":"LTCM21","id":52899999038,"side":"Buy","size":19,"price":0.00481},{"symbol":"LTCM21","id":52899999039,"side":"Buy","size":23,"price":0.004805},{"symbol":"LTCM21","id":52899999040,"side":"Buy","size":3089,"price":0.0048},{"symbol":"LTCM21","id":52899999041,"side":"Buy","size":59,"price":0.004795},{"symbol":"LTCM21","id":52899999042,"side":"Buy","size":161,"price":0.00479},{"symbol":"LTCM21","id":52899999046,"side":"Buy","size":46,"price":0.00477},{"symbol":"LTCM21","id":52899999050,"side":"Buy","size":1,"price":0.00475},{"symbol":"LTCM21","id":52899999054,"side":"Buy","size":15,"price":0.00473},{"symbol":"LTCM21","id":52899999058,"side":"Buy","size":190,"price":0.00471},{"symbol":"LTCM21","id":52899999060,"side":"Buy","size":11,"price":0.0047},{"symbol":"LTCM21","id":52899999064,"side":"Buy","size":109,"price":0.00468},{"symbol":"LTCM21","id":52899999067,"side":"Buy","size":20,"price":0.004665},{"symbol":"LTCM21","id":52899999068,"side":"Buy","size":177,"price":0.00466},{"symbol":"LTCM21","id":52899999070,"side":"Buy","size":110,"price":0.00465},{"symbol":"LTCM21","id":52899999074,"side":"Buy","size":145,"price":0.00463},{"symbol":"LTCM21","id":52899999076,"side":"Buy","size":54,"price":0.00462},{"symbol":"LTCM21","id":52899999077,"side":"Buy","size":75,"price":0.004615},{"symbol":"LTCM21","id":52899999080,"side":"Buy","size":18,"price":0.0046},{"symbol":"LTCM21","id":52899999084,"side":"Buy","size":49,"price":0.00458},{"symbol":"LTCM21","id":52899999088,"side":"Buy","size":59,"price":0.00456},{"symbol":"LTCM21","id":52899999091,"side":"Buy","size":33,"price":0.004545},{"symbol":"LTCM21","id":52899999095,"side":"Buy","size":2,"price":0.004525},{"symbol":"LTCM21","id":52899999096,"side":"Buy","size":29,"price":0.00452},{"symbol":"LTCM21","id":52899999098,"side":"Buy","size":5,"price":0.00451},{"symbol":"LTCM21","id":52899999100,"side":"Buy","size":59,"price":0.0045},{"symbol":"LTCM21","id":52899999103,"side":"Buy","size":3,"price":0.004485},{"symbol":"LTCM21","id":52899999106,"side":"Buy","size":181,"price":0.00447},{"symbol":"LTCM21","id":52899999111,"side":"Buy","size":2,"price":0.004445},{"symbol":"LTCM21","id":52899999112,"side":"Buy","size":6,"price":0.00444},{"symbol":"LTCM21","id":52899999120,"side":"Buy","size":115,"price":0.0044},{"symbol":"LTCM21","id":52899999122,"side":"Buy","size":1,"price":0.00439},{"symbol":"LTCM21","id":52899999125,"side":"Buy","size":60,"price":0.004375},{"symbol":"LTCM21","id":52899999130,"side":"Buy","size":7,"price":0.00435},{"symbol":"LTCM21","id":52899999134,"side":"Buy","size":4,"price":0.00433},{"symbol":"LTCM21","id":52899999136,"side":"Buy","size":69,"price":0.00432},{"symbol":"LTCM21","id":52899999138,"side":"Buy","size":66,"price":0.00431},{"symbol":"LTCM21","id":52899999139,"side":"Buy","size":3,"price":0.004305},{"symbol":"LTCM21","id":52899999140,"side":"Buy","size":103,"price":0.0043},{"symbol":"LTCM21","id":52899999141,"side":"Buy","size":1,"price":0.004295},{"symbol":"LTCM21","id":52899999144,"side":"Buy","size":190,"price":0.00428},{"symbol":"LTCM21","id":52899999145,"side":"Buy","size":55,"price":0.004275},{"symbol":"LTCM21","id":52899999149,"side":"Buy","size":3,"price":0.004255},{"symbol":"LTCM21","id":52899999150,"side":"Buy","size":6,"price":0.00425},{"symbol":"LTCM21","id":52899999151,"side":"Buy","size":1,"price":0.004245},{"symbol":"LTCM21","id":52899999153,"side":"Buy","size":3,"price":0.004235},{"symbol":"LTCM21","id":52899999154,"side":"Buy","size":59,"price":0.00423},{"symbol":"LTCM21","id":52899999155,"side":"Buy","size":28,"price":0.004225},{"symbol":"LTCM21","id":52899999159,"side":"Buy","size":3,"price":0.004205},{"symbol":"LTCM21","id":52899999164,"side":"Buy","size":5,"price":0.00418},{"symbol":"LTCM21","id":52899999166,"side":"Buy","size":3,"price":0.00417},{"symbol":"LTCM21","id":52899999168,"side":"Buy","size":17,"price":0.00416},{"symbol":"LTCM21","id":52899999169,"side":"Buy","size":60,"price":0.004155},{"symbol":"LTCM21","id":52899999170,"side":"Buy","size":49,"price":0.00415},{"symbol":"LTCM21","id":52899999173,"side":"Buy","size":3,"price":0.004135},{"symbol":"LTCM21","id":52899999176,"side":"Buy","size":56,"price":0.00412},{"symbol":"LTCM21","id":52899999177,"side":"Buy","size":4,"price":0.004115},{"symbol":"LTCM21","id":52899999179,"side":"Buy","size":2,"price":0.004105},{"symbol":"LTCM21","id":52899999180,"side":"Buy","size":8,"price":0.0041},{"symbol":"LTCM21","id":52899999189,"side":"Buy","size":3,"price":0.004055},{"symbol":"LTCM21","id":52899999191,"side":"Buy","size":15,"price":0.004045},{"symbol":"LTCM21","id":52899999195,"side":"Buy","size":7,"price":0.004025},{"symbol":"LTCM21","id":52899999198,"side":"Buy","size":50,"price":0.00401},{"symbol":"LTCM21","id":52899999200,"side":"Buy","size":10,"price":0.004},{"symbol":"LTCM21","id":52899999209,"side":"Buy","size":3,"price":0.003955},{"symbol":"LTCM21","id":52899999210,"side":"Buy","size":15,"price":0.00395},{"symbol":"LTCM21","id":52899999211,"side":"Buy","size":28,"price":0.003945},{"symbol":"LTCM21","id":52899999212,"side":"Buy","size":3,"price":0.00394},{"symbol":"LTCM21","id":52899999213,"side":"Buy","size":50,"price":0.003935},{"symbol":"LTCM21","id":52899999215,"side":"Buy","size":3,"price":0.003925},{"symbol":"LTCM21","id":52899999217,"side":"Buy","size":2,"price":0.003915},{"symbol":"LTCM21","id":52899999218,"side":"Buy","size":53,"price":0.00391},{"symbol":"LTCM21","id":52899999219,"side":"Buy","size":4,"price":0.003905},{"symbol":"LTCM21","id":52899999221,"side":"Buy","size":61,"price":0.003895},{"symbol":"LTCM21","id":52899999223,"side":"Buy","size":20,"price":0.003885},{"symbol":"LTCM21","id":52899999230,"side":"Buy","size":519,"price":0.00385},{"symbol":"LTCM21","id":52899999233,"side":"Buy","size":20,"price":0.003835},{"symbol":"LTCM21","id":52899999234,"side":"Buy","size":50,"price":0.00383},{"symbol":"LTCM21","id":52899999244,"side":"Buy","size":50,"price":0.00378},{"symbol":"LTCM21","id":52899999249,"side":"Buy","size":3,"price":0.003755},{"symbol":"LTCM21","id":52899999250,"side":"Buy","size":3,"price":0.00375},{"symbol":"LTCM21","id":52899999256,"side":"Buy","size":10,"price":0.00372},{"symbol":"LTCM21","id":52899999258,"side":"Buy","size":16,"price":0.00371},{"symbol":"LTCM21","id":52899999260,"side":"Buy","size":6,"price":0.0037},{"symbol":"LTCM21","id":52899999263,"side":"Buy","size":50,"price":0.003685},{"symbol":"LTCM21","id":52899999274,"side":"Buy","size":10,"price":0.00363},{"symbol":"LTCM21","id":52899999275,"side":"Buy","size":3,"price":0.003625},{"symbol":"LTCM21","id":52899999280,"side":"Buy","size":1020,"price":0.0036},{"symbol":"LTCM21","id":52899999300,"side":"Buy","size":20,"price":0.0035},{"symbol":"LTCM21","id":52899999313,"side":"Buy","size":519,"price":0.003435},{"symbol":"LTCM21","id":52899999320,"side":"Buy","size":31,"price":0.0034},{"symbol":"LTCM21","id":52899999325,"side":"Buy","size":10,"price":0.003375},{"symbol":"LTCM21","id":52899999326,"side":"Buy","size":311,"price":0.00337},{"symbol":"LTCM21","id":52899999327,"side":"Buy","size":2,"price":0.003365},{"symbol":"LTCM21","id":52899999332,"side":"Buy","size":411,"price":0.00334},{"symbol":"LTCM21","id":52899999338,"side":"Buy","size":10,"price":0.00331},{"symbol":"LTCM21","id":52899999340,"side":"Buy","size":30,"price":0.0033},{"symbol":"LTCM21","id":52899999347,"side":"Buy","size":5,"price":0.003265},{"symbol":"LTCM21","id":52899999350,"side":"Buy","size":15,"price":0.00325},{"symbol":"LTCM21","id":52899999357,"side":"Buy","size":5,"price":0.003215},{"symbol":"LTCM21","id":52899999358,"side":"Buy","size":50,"price":0.00321},{"symbol":"LTCM21","id":52899999360,"side":"Buy","size":45,"price":0.0032},{"symbol":"LTCM21","id":52899999370,"side":"Buy","size":5,"price":0.00315},{"symbol":"LTCM21","id":52899999372,"side":"Buy","size":10,"price":0.00314},{"symbol":"LTCM21","id":52899999380,"side":"Buy","size":45,"price":0.0031},{"symbol":"LTCM21","id":52899999389,"side":"Buy","size":50,"price":0.003055},{"symbol":"LTCM21","id":52899999392,"side":"Buy","size":10,"price":0.00304},{"symbol":"LTCM21","id":52899999397,"side":"Buy","size":1,"price":0.003015},{"symbol":"LTCM21","id":52899999400,"side":"Buy","size":43,"price":0.003},{"symbol":"LTCM21","id":52899999420,"side":"Buy","size":20,"price":0.0029},{"symbol":"LTCM21","id":52899999425,"side":"Buy","size":25,"price":0.002875},{"symbol":"LTCM21","id":52899999438,"side":"Buy","size":10,"price":0.00281},{"symbol":"LTCM21","id":52899999460,"side":"Buy","size":20,"price":0.0027},{"symbol":"LTCM21","id":52899999475,"side":"Buy","size":19,"price":0.002625},{"symbol":"LTCM21","id":52899999487,"side":"Buy","size":1,"price":0.002565},{"symbol":"LTCM21","id":52899999520,"side":"Buy","size":300,"price":0.0024},{"symbol":"LTCM21","id":52899999530,"side":"Buy","size":2,"price":0.00235},{"symbol":"LTCM21","id":52899999560,"side":"Buy","size":235,"price":0.0022},{"symbol":"LTCM21","id":52899999600,"side":"Buy","size":2,"price":0.002},{"symbol":"LTCM21","id":52899999894,"side":"Buy","size":104,"price":0.00053},{"symbol":"LTCM21","id":52899999998,"side":"Buy","size":11200,"price":0.00001},{"symbol":"LTCM21","id":52899999999,"side":"Buy","size":11000,"price":0.000005}]}
1618677663.048373: {"table":"orderBookL2","action":"partial","keys":["symbol","id","side"],"types":{"symbol":"symbol","id":"long","side":"symbol","size":"long","price":"float"},"foreignKeys":{"symbol":"instrument","side":"side"},"attributes":{"symbol":"parted","id":"sorted"},"filter":{"symbol":"DOGEUSDT"},"data":[{"symbol":"DOGEUSDT","id":47523569671,"side":"Sell","size":15,"price":764.30329},{"symbol":"DOGEUSDT","id":47598601000,"side":"Sell","size":30000,"price":13.99},{"symbol":"DOGEUSDT","id":47598612000,"side":"Sell","size":30000,"price":13.88},{"symbol":"DOGEUSDT","id":47598623000,"side":"Sell","size":30000,"price":13.77},{"symbol":"DOGEUSDT","id":47598634000,"side":"Sell","size":30000,"price":13.66},{"symbol":"DOGEUSDT","id":47598645000,"side":"Sell","size":30000,"price":13.55},{"symbol":"DOGEUSDT","id":47598656000,"side":"Sell","size":30000,"price":13.44},{"symbol":"DOGEUSDT","id":47598667000,"side":"Sell","size":30000,"price":13.33},{"symbol":"DOGEUSDT","id":47598678000,"side":"Sell","size":30000,"price":13.22},{"symbol":"DOGEUSDT","id":47598689000,"side":"Sell","size":30000,"price":13.11},{"symbol":"DOGEUSDT","id":47598700000,"side":"Sell","size":30000,"price":13},{"symbol":"DOGEUSDT","id":47599000000,"side":"Sell","size":19,"price":10},{"symbol":"DOGEUSDT","id":47599675000,"side":"Sell","size":35,"price":3.25},{"symbol":"DOGEUSDT","id":47599680000,"side":"Sell","size":100,"price":3.2},{"symbol":"DOGEUSDT","id":47599842000,"side":"Sell","size":25,"price":1.58},{"symbol":"DOGEUSDT","id":47599900000,"side":"Sell","size":60,"price":1},{"symbol":"DOGEUSDT","id":47599900100,"side":"Sell","size":500,"price":0.999},{"symbol":"DOGEUSDT","id":47599902637,"side":"Sell","size":110,"price":0.97363},{"symbol":"DOGEUSDT","id":47599906300,"side":"Sell","size":12000,"price":0.937},{"symbol":"DOGEUSDT","id":47599910000,"side":"Sell","size":20000,"price":0.9},{"symbol":"DOGEUSDT","id":47599910100,"side":"Sell","size":500,"price":0.899},{"symbol":"DOGEUSDT","id":47599910579,"side":"Sell","size":100,"price":0.89421},{"symbol":"DOGEUSDT","id":47599911308,"side":"Sell","size":100,"price":0.88692},{"symbol":"DOGEUSDT","id":47599918000,"side":"Sell","size":100,"price":0.82},{"symbol":"DOGEUSDT","id":47599920000,"side":"Sell","size":5085,"price":0.8},{"symbol":"DOGEUSDT","id":47599920100,"side":"Sell","size":500,"price":0.799},{"symbol":"DOGEUSDT","id":47599920500,"side":"Sell","size":25,"price":0.795},{"symbol":"DOGEUSDT","id":47599925300,"side":"Sell","size":9000,"price":0.747},{"symbol":"DOGEUSDT","id":47599926916,"side":"Sell","size":25,"price":0.73084},{"symbol":"DOGEUSDT","id":47599929887,"side":"Sell","size":100,"price":0.70113},{"symbol":"DOGEUSDT","id":47599930000,"side":"Sell","size":100,"price":0.7},{"symbol":"DOGEUSDT","id":47599930100,"side":"Sell","size":500,"price":0.699},{"symbol":"DOGEUSDT","id":47599931000,"side":"Sell","size":100,"price":0.69},{"symbol":"DOGEUSDT","id":47599931026,"side":"Sell","size":100,"price":0.68974},{"symbol":"DOGEUSDT","id":47599931420,"side":"Sell","size":100,"price":0.6858},{"symbol":"DOGEUSDT","id":47599932259,"side":"Sell","size":100,"price":0.67741},{"symbol":"DOGEUSDT","id":47599933522,"side":"Sell","size":100,"price":0.66478},{"symbol":"DOGEUSDT","id":47599934101,"side":"Sell","size":100,"price":0.65899},{"symbol":"DOGEUSDT","id":47599934502,"side":"Sell","size":500,"price":0.65498},{"symbol":"DOGEUSDT","id":47599934672,"side":"Sell","size":2,"price":0.65328},{"symbol":"DOGEUSDT","id":47599934774,"side":"Sell","size":100,"price":0.65226},{"symbol":"DOGEUSDT","id":47599935618,"side":"Sell","size":20,"price":0.64382},{"symbol":"DOGEUSDT","id":47599936017,"side":"Sell","size":100,"price":0.63983},{"symbol":"DOGEUSDT","id":47599936383,"side":"Sell","size":100,"price":0.63617},{"symbol":"DOGEUSDT","id":47599936389,"side":"Sell","size":100,"price":0.63611},{"symbol":"DOGEUSDT","id":47599936638,"side":"Sell","size":100,"price":0.63362},{"symbol":"DOGEUSDT","id":47599937000,"side":"Sell","size":70,"price":0.63},{"symbol":"DOGEUSDT","id":47599937415,"side":"Sell","size":100,"price":0.62585},{"symbol":"DOGEUSDT","id":47599937881,"side":"Sell","size":100,"price":0.62119},{"symbol":"DOGEUSDT","id":47599938000,"side":"Sell","size":76,"price":0.62},{"symbol":"DOGEUSDT","id":47599938061,"side":"Sell","size":11,"price":0.61939},{"symbol":"DOGEUSDT","id":47599938813,"side":"Sell","size":100,"price":0.61187},{"symbol":"DOGEUSDT","id":47599939000,"side":"Sell","size":62,"price":0.61},{"symbol":"DOGEUSDT","id":47599939745,"side":"Sell","size":100,"price":0.60255},{"symbol":"DOGEUSDT","id":47599940000,"side":"Sell","size":175,"price":0.6},{"symbol":"DOGEUSDT","id":47599940100,"side":"Sell","size":500,"price":0.599},{"symbol":"DOGEUSDT","id":47599940677,"side":"Sell","size":100,"price":0.59323},{"symbol":"DOGEUSDT","id":47599941000,"side":"Sell","size":55,"price":0.59},{"symbol":"DOGEUSDT","id":47599941174,"side":"Sell","size":100,"price":0.58826},{"symbol":"DOGEUSDT","id":47599941183,"side":"Sell","size":100,"price":0.58817},{"symbol":"DOGEUSDT","id":47599941764,"side":"Sell","size":100,"price":0.58236},{"symbol":"DOGEUSDT","id":47599942000,"side":"Sell","size":62,"price":0.58},{"symbol":"DOGEUSDT","id":47599943000,"side":"Sell","size":139,"price":0.57},{"symbol":"DOGEUSDT","id":47599943007,"side":"Sell","size":100,"price":0.56993},{"symbol":"DOGEUSDT","id":47599943200,"side":"Sell","size":10000,"price":0.568},{"symbol":"DOGEUSDT","id":47599943700,"side":"Sell","size":7000,"price":0.563},{"symbol":"DOGEUSDT","id":47599943783,"side":"Sell","size":100,"price":0.56217},{"symbol":"DOGEUSDT","id":47599944000,"side":"Sell","size":136,"price":0.56},{"symbol":"DOGEUSDT","id":47599944500,"side":"Sell","size":3,"price":0.555},{"symbol":"DOGEUSDT","id":47599944560,"side":"Sell","size":100,"price":0.5544},{"symbol":"DOGEUSDT","id":47599944672,"side":"Sell","size":1,"price":0.55328},{"symbol":"DOGEUSDT","id":47599945000,"side":"Sell","size":1162,"price":0.55},{"symbol":"DOGEUSDT","id":47599945020,"side":"Sell","size":5,"price":0.5498},{"symbol":"DOGEUSDT","id":47599945519,"side":"Sell","size":25,"price":0.54481},{"symbol":"DOGEUSDT","id":47599945618,"side":"Sell","size":20,"price":0.54382},{"symbol":"DOGEUSDT","id":47599945900,"side":"Sell","size":10,"price":0.541},{"symbol":"DOGEUSDT","id":47599946000,"side":"Sell","size":130,"price":0.54},{"symbol":"DOGEUSDT","id":47599947000,"side":"Sell","size":128,"price":0.53},{"symbol":"DOGEUSDT","id":47599947778,"side":"Sell","size":20,"price":0.52222},{"symbol":"DOGEUSDT","id":47599948000,"side":"Sell","size":126,"price":0.52},{"symbol":"DOGEUSDT","id":47599948382,"side":"Sell","size":1,"price":0.51618},{"symbol":"DOGEUSDT","id":47599948384,"side":"Sell","size":2,"price":0.51616},{"symbol":"DOGEUSDT","id":47599949000,"side":"Sell","size":224,"price":0.51},{"symbol":"DOGEUSDT","id":47599949800,"side":"Sell","size":90,"price":0.502},{"symbol":"DOGEUSDT","id":47599949955,"side":"Sell","size":12500,"price":0.50045},{"symbol":"DOGEUSDT","id":47599950000,"side":"Sell","size":588,"price":0.5},{"symbol":"DOGEUSDT","id":47599950010,"side":"Sell","size":500,"price":0.4999},{"symbol":"DOGEUSDT","id":47599950100,"side":"Sell","size":500,"price":0.499},{"symbol":"DOGEUSDT","id":47599950105,"side":"Sell","size":1000,"price":0.49895},{"symbol":"DOGEUSDT","id":47599950580,"side":"Sell","size":48,"price":0.4942},{"symbol":"DOGEUSDT","id":47599951000,"side":"Sell","size":136,"price":0.49},{"symbol":"DOGEUSDT","id":47599951112,"side":"Sell","size":4,"price":0.48888},{"symbol":"DOGEUSDT","id":47599951116,"side":"Sell","size":50,"price":0.48884},{"symbol":"DOGEUSDT","id":47599951767,"side":"Sell","size":100,"price":0.48233},{"symbol":"DOGEUSDT","id":47599951967,"side":"Sell","size":50,"price":0.48033},{"symbol":"DOGEUSDT","id":47599952000,"side":"Sell","size":79,"price":0.48},{"symbol":"DOGEUSDT","id":47599952200,"side":"Sell","size":900,"price":0.478},{"symbol":"DOGEUSDT","id":47599953000,"side":"Sell","size":28,"price":0.47},{"symbol":"DOGEUSDT","id":47599953200,"side":"Sell","size":20000,"price":0.468},{"symbol":"DOGEUSDT","id":47599953539,"side":"Sell","size":40,"price":0.46461},{"symbol":"DOGEUSDT","id":47599953672,"side":"Sell","size":1,"price":0.46328},{"symbol":"DOGEUSDT","id":47599953827,"side":"Sell","size":100,"price":0.46173},{"symbol":"DOGEUSDT","id":47599953851,"side":"Sell","size":250,"price":0.46149},{"symbol":"DOGEUSDT","id":47599953933,"side":"Sell","size":600,"price":0.46067},{"symbol":"DOGEUSDT","id":47599954000,"side":"Sell","size":25,"price":0.46},{"symbol":"DOGEUSDT","id":47599954164,"side":"Sell","size":100,"price":0.45836},{"symbol":"DOGEUSDT","id":47599954390,"side":"Sell","size":200,"price":0.4561},{"symbol":"DOGEUSDT","id":47599954500,"side":"Sell","size":2,"price":0.455},{"symbol":"DOGEUSDT","id":47599954859,"side":"Sell","size":100,"price":0.45141},{"symbol":"DOGEUSDT","id":47599954992,"side":"Sell","size":100,"price":0.45008},{"symbol":"DOGEUSDT","id":47599955000,"side":"Sell","size":1101,"price":0.45},{"symbol":"DOGEUSDT","id":47599955400,"side":"Sell","size":10,"price":0.446},{"symbol":"DOGEUSDT","id":47599955832,"side":"Sell","size":250,"price":0.44168},{"symbol":"DOGEUSDT","id":47599955890,"side":"Sell","size":50,"price":0.4411},{"symbol":"DOGEUSDT","id":47599956000,"side":"Sell","size":1220,"price":0.44},{"symbol":"DOGEUSDT","id":47599956019,"side":"Sell","size":8,"price":0.43981},{"symbol":"DOGEUSDT","id":47599956045,"side":"Sell","size":10,"price":0.43955},{"symbol":"DOGEUSDT","id":47599956097,"side":"Sell","size":40,"price":0.43903},{"symbol":"DOGEUSDT","id":47599956283,"side":"Sell","size":5,"price":0.43717},{"symbol":"DOGEUSDT","id":47599956300,"side":"Sell","size":5000,"price":0.437},{"symbol":"DOGEUSDT","id":47599956359,"side":"Sell","size":100,"price":0.43641},{"symbol":"DOGEUSDT","id":47599956373,"side":"Sell","size":288,"price":0.43627},{"symbol":"DOGEUSDT","id":47599956445,"side":"Sell","size":200,"price":0.43555},{"symbol":"DOGEUSDT","id":47599956600,"side":"Sell","size":30,"price":0.434},{"symbol":"DOGEUSDT","id":47599956633,"side":"Sell","size":40,"price":0.43367},{"symbol":"DOGEUSDT","id":47599957000,"side":"Sell","size":100,"price":0.43},{"symbol":"DOGEUSDT","id":47599957501,"side":"Sell","size":50,"price":0.42499},{"symbol":"DOGEUSDT","id":47599957521,"side":"Sell","size":50,"price":0.42479},{"symbol":"DOGEUSDT","id":47599957591,"side":"Sell","size":30,"price":0.42409},{"symbol":"DOGEUSDT","id":47599957808,"side":"Sell","size":50,"price":0.42192},{"symbol":"DOGEUSDT","id":47599958000,"side":"Sell","size":2650,"price":0.42},{"symbol":"DOGEUSDT","id":47599958104,"side":"Sell","size":10,"price":0.41896},{"symbol":"DOGEUSDT","id":47599958450,"side":"Sell","size":40,"price":0.4155},{"symbol":"DOGEUSDT","id":47599958490,"side":"Sell","size":250,"price":0.4151},{"symbol":"DOGEUSDT","id":47599958744,"side":"Sell","size":200,"price":0.41256},{"symbol":"DOGEUSDT","id":47599959000,"side":"Sell","size":542,"price":0.41},{"symbol":"DOGEUSDT","id":47599959127,"side":"Sell","size":10,"price":0.40873},{"symbol":"DOGEUSDT","id":47599960000,"side":"Sell","size":1202,"price":0.4},{"symbol":"DOGEUSDT","id":47599960100,"side":"Sell","size":564,"price":0.399},{"symbol":"DOGEUSDT","id":47599960300,"side":"Sell","size":49,"price":0.397},{"symbol":"DOGEUSDT","id":47599960384,"side":"Sell","size":10,"price":0.39616},{"symbol":"DOGEUSDT","id":47599960400,"side":"Sell","size":100,"price":0.396},{"symbol":"DOGEUSDT","id":47599960483,"side":"Sell","size":10,"price":0.39517},{"symbol":"DOGEUSDT","id":47599960599,"side":"Sell","size":14,"price":0.39401},{"symbol":"DOGEUSDT","id":47599960670,"side":"Sell","size":200,"price":0.3933},{"symbol":"DOGEUSDT","id":47599960814,"side":"Sell","size":20,"price":0.39186},{"symbol":"DOGEUSDT","id":47599961000,"side":"Sell","size":1010,"price":0.39},{"symbol":"DOGEUSDT","id":47599961031,"side":"Sell","size":8073,"price":0.38969},{"symbol":"DOGEUSDT","id":47599961037,"side":"Sell","size":6000,"price":0.38963},{"symbol":"DOGEUSDT","id":47599961164,"side":"Sell","size":100,"price":0.38836},{"symbol":"DOGEUSDT","id":47599961200,"side":"Sell","size":7777,"price":0.388},{"symbol":"DOGEUSDT","id":47599961300,"side":"Sell","size":200,"price":0.387},{"symbol":"DOGEUSDT","id":47599961410,"side":"Sell","size":20,"price":0.3859},{"symbol":"DOGEUSDT","id":47599961500,"side":"Sell","size":240,"price":0.385},{"symbol":"DOGEUSDT","id":47599961505,"side":"Sell","size":100,"price":0.38495},{"symbol":"DOGEUSDT","id":47599961543,"side":"Sell","size":100,"price":0.38457},{"symbol":"DOGEUSDT","id":47599961700,"side":"Sell","size":1200,"price":0.383},{"symbol":"DOGEUSDT","id":47599962000,"side":"Sell","size":4950,"price":0.38},{"symbol":"DOGEUSDT","id":47599962053,"side":"Sell","size":8165,"price":0.37947},{"symbol":"DOGEUSDT","id":47599962300,"side":"Sell","size":7777,"price":0.377},{"symbol":"DOGEUSDT","id":47599962527,"side":"Sell","size":3600,"price":0.37473},{"symbol":"DOGEUSDT","id":47599962629,"side":"Sell","size":30,"price":0.37371},{"symbol":"DOGEUSDT","id":47599962827,"side":"Sell","size":555,"price":0.37173},{"symbol":"DOGEUSDT","id":47599962829,"side":"Sell","size":58,"price":0.37171},{"symbol":"DOGEUSDT","id":47599962845,"side":"Sell","size":300,"price":0.37155},{"symbol":"DOGEUSDT","id":47599962942,"side":"Sell","size":7952,"price":0.37058},{"symbol":"DOGEUSDT","id":47599963169,"side":"Sell","size":300,"price":0.36831},{"symbol":"DOGEUSDT","id":47599963257,"side":"Sell","size":1300,"price":0.36743},{"symbol":"DOGEUSDT","id":47599963298,"side":"Sell","size":84,"price":0.36702},{"symbol":"DOGEUSDT","id":47599963345,"side":"Sell","size":25,"price":0.36655},{"symbol":"DOGEUSDT","id":47599963385,"side":"Sell","size":8,"price":0.36615},{"symbol":"DOGEUSDT","id":47599963600,"side":"Sell","size":7777,"price":0.364},{"symbol":"DOGEUSDT","id":47599963692,"side":"Sell","size":100,"price":0.36308},{"symbol":"DOGEUSDT","id":47599963842,"side":"Sell","size":126,"price":0.36158},{"symbol":"DOGEUSDT","id":47599963934,"side":"Sell","size":120,"price":0.36066},{"symbol":"DOGEUSDT","id":47599963980,"side":"Sell","size":100,"price":0.3602},{"symbol":"DOGEUSDT","id":47599964000,"side":"Sell","size":1250,"price":0.36},{"symbol":"DOGEUSDT","id":47599964606,"side":"Sell","size":200,"price":0.35394},{"symbol":"DOGEUSDT","id":47599964697,"side":"Sell","size":30,"price":0.35303},{"symbol":"DOGEUSDT","id":47599964992,"side":"Sell","size":15,"price":0.35008},{"symbol":"DOGEUSDT","id":47599965000,"side":"Sell","size":211,"price":0.35},{"symbol":"DOGEUSDT","id":47599965034,"side":"Sell","size":500,"price":0.34966},{"symbol":"DOGEUSDT","id":47599965054,"side":"Sell","size":7829,"price":0.34946},{"symbol":"DOGEUSDT","id":47599965065,"side":"Sell","size":5000,"price":0.34935},{"symbol":"DOGEUSDT","id":47599965159,"side":"Sell","size":400,"price":0.34841},{"symbol":"DOGEUSDT","id":47599965210,"side":"Sell","size":89,"price":0.3479},{"symbol":"DOGEUSDT","id":47599965234,"side":"Sell","size":500,"price":0.34766},{"symbol":"DOGEUSDT","id":47599965482,"side":"Sell","size":555,"price":0.34518},{"symbol":"DOGEUSDT","id":47599965534,"side":"Sell","size":500,"price":0.34466},{"symbol":"DOGEUSDT","id":47599965565,"side":"Sell","size":500,"price":0.34435},{"symbol":"DOGEUSDT","id":47599965600,"side":"Sell","size":7777,"price":0.344},{"symbol":"DOGEUSDT","id":47599965620,"side":"Sell","size":10,"price":0.3438},{"symbol":"DOGEUSDT","id":47599965670,"side":"Sell","size":200,"price":0.3433},{"symbol":"DOGEUSDT","id":47599965679,"side":"Sell","size":1000,"price":0.34321},{"symbol":"DOGEUSDT","id":47599965807,"side":"Sell","size":130,"price":0.34193},{"symbol":"DOGEUSDT","id":47599966000,"side":"Sell","size":30,"price":0.34},{"symbol":"DOGEUSDT","id":47599966010,"side":"Sell","size":60,"price":0.3399},{"symbol":"DOGEUSDT","id":47599966034,"side":"Sell","size":500,"price":0.33966},{"symbol":"DOGEUSDT","id":47599966099,"side":"Sell","size":7806,"price":0.33901},{"symbol":"DOGEUSDT","id":47599966185,"side":"Sell","size":1000,"price":0.33815},{"symbol":"DOGEUSDT","id":47599966200,"side":"Sell","size":1500,"price":0.338},{"symbol":"DOGEUSDT","id":47599966300,"side":"Sell","size":1500,"price":0.337},{"symbol":"DOGEUSDT","id":47599966320,"side":"Sell","size":299,"price":0.3368},{"symbol":"DOGEUSDT","id":47599966400,"side":"Sell","size":1500,"price":0.336},{"symbol":"DOGEUSDT","id":47599966500,"side":"Sell","size":500,"price":0.335},{"symbol":"DOGEUSDT","id":47599966543,"side":"Sell","size":158,"price":0.33457},{"symbol":"DOGEUSDT","id":47599966600,"side":"Sell","size":500,"price":0.334},{"symbol":"DOGEUSDT","id":47599966619,"side":"Sell","size":100,"price":0.33381},{"symbol":"DOGEUSDT","id":47599966667,"side":"Sell","size":338,"price":0.33333},{"symbol":"DOGEUSDT","id":47599966700,"side":"Sell","size":1500,"price":0.333},{"symbol":"DOGEUSDT","id":47599966800,"side":"Sell","size":500,"price":0.332},{"symbol":"DOGEUSDT","id":47599966870,"side":"Sell","size":30,"price":0.3313},{"symbol":"DOGEUSDT","id":47599966900,"side":"Sell","size":500,"price":0.331},{"symbol":"DOGEUSDT","id":47599966997,"side":"Sell","size":132,"price":0.33003},{"symbol":"DOGEUSDT","id":47599967000,"side":"Sell","size":800,"price":0.33},{"symbol":"DOGEUSDT","id":47599967023,"side":"Sell","size":80,"price":0.32977},{"symbol":"DOGEUSDT","id":47599967041,"side":"Sell","size":1500,"price":0.32959},{"symbol":"DOGEUSDT","id":47599967229,"side":"Sell","size":8083,"price":0.32771},{"symbol":"DOGEUSDT","id":47599967250,"side":"Sell","size":50,"price":0.3275},{"symbol":"DOGEUSDT","id":47599967257,"side":"Sell","size":101,"price":0.32743},{"symbol":"DOGEUSDT","id":47599967390,"side":"Sell","size":19,"price":0.3261},{"symbol":"DOGEUSDT","id":47599967400,"side":"Sell","size":550,"price":0.326},{"symbol":"DOGEUSDT","id":47599967405,"side":"Sell","size":122,"price":0.32595},{"symbol":"DOGEUSDT","id":47599967433,"side":"Sell","size":50,"price":0.32567},{"symbol":"DOGEUSDT","id":47599967500,"side":"Sell","size":50,"price":0.325},{"symbol":"DOGEUSDT","id":47599967531,"side":"Sell","size":218,"price":0.32469},{"symbol":"DOGEUSDT","id":47599967583,"side":"Sell","size":7981,"price":0.32417},{"symbol":"DOGEUSDT","id":47599967600,"side":"Sell","size":7777,"price":0.324},{"symbol":"DOGEUSDT","id":47599967618,"side":"Sell","size":1,"price":0.32382},{"symbol":"DOGEUSDT","id":47599967619,"side":"Sell","size":100,"price":0.32381},{"symbol":"DOGEUSDT","id":47599967666,"side":"Sell","size":25,"price":0.32334},{"symbol":"DOGEUSDT","id":47599967667,"side":"Sell","size":200,"price":0.32333},{"symbol":"DOGEUSDT","id":47599967678,"side":"Sell","size":158,"price":0.32322},{"symbol":"DOGEUSDT","id":47599967679,"side":"Sell","size":1000,"price":0.32321},{"symbol":"DOGEUSDT","id":47599967800,"side":"Sell","size":50,"price":0.322},{"symbol":"DOGEUSDT","id":47599967900,"side":"Sell","size":7874,"price":0.321},{"symbol":"DOGEUSDT","id":47599967916,"side":"Sell","size":100,"price":0.32084},{"symbol":"DOGEUSDT","id":47599968138,"side":"Sell","size":555,"price":0.31862},{"symbol":"DOGEUSDT","id":47599968171,"side":"Sell","size":100,"price":0.31829},{"symbol":"DOGEUSDT","id":47599968218,"side":"Sell","size":50,"price":0.31782},{"symbol":"DOGEUSDT","id":47599968227,"side":"Sell","size":40,"price":0.31773},{"symbol":"DOGEUSDT","id":47599968262,"side":"Sell","size":150,"price":0.31738},{"symbol":"DOGEUSDT","id":47599968289,"side":"Sell","size":1000,"price":0.31711},{"symbol":"DOGEUSDT","id":47599968330,"side":"Sell","size":1,"price":0.3167},{"symbol":"DOGEUSDT","id":47599968360,"side":"Sell","size":100,"price":0.3164},{"symbol":"DOGEUSDT","id":47599968415,"side":"Sell","size":74,"price":0.31585},{"symbol":"DOGEUSDT","id":47599968431,"side":"Sell","size":15,"price":0.31569},{"symbol":"DOGEUSDT","id":47599968518,"side":"Sell","size":2,"price":0.31482},{"symbol":"DOGEUSDT","id":47599968554,"side":"Sell","size":100,"price":0.31446},{"symbol":"DOGEUSDT","id":47599968579,"side":"Sell","size":80,"price":0.31421},{"symbol":"DOGEUSDT","id":47599968619,"side":"Sell","size":100,"price":0.31381},{"symbol":"DOGEUSDT","id":47599968620,"side":"Sell","size":8,"price":0.3138},{"symbol":"DOGEUSDT","id":47599968637,"side":"Sell","size":50,"price":0.31363},{"symbol":"DOGEUSDT","id":47599968667,"side":"Sell","size":200,"price":0.31333},{"symbol":"DOGEUSDT","id":47599968749,"side":"Sell","size":7994,"price":0.31251},{"symbol":"DOGEUSDT","id":47599968750,"side":"Sell","size":3,"price":0.3125},{"symbol":"DOGEUSDT","id":47599968837,"side":"Sell","size":50,"price":0.31163},{"symbol":"DOGEUSDT","id":47599968889,"side":"Sell","size":4200,"price":0.31111},{"symbol":"DOGEUSDT","id":47599968903,"side":"Sell","size":100,"price":0.31097},{"symbol":"DOGEUSDT","id":47599969000,"side":"Sell","size":442,"price":0.31},{"symbol":"DOGEUSDT","id":47599969003,"side":"Sell","size":50,"price":0.30997},{"symbol":"DOGEUSDT","id":47599969099,"side":"Sell","size":58,"price":0.30901},{"symbol":"DOGEUSDT","id":47599969166,"side":"Sell","size":100,"price":0.30834},{"symbol":"DOGEUSDT","id":47599969200,"side":"Sell","size":8,"price":0.308},{"symbol":"DOGEUSDT","id":47599969400,"side":"Sell","size":150,"price":0.306},{"symbol":"DOGEUSDT","id":47599969408,"side":"Sell","size":100,"price":0.30592},{"symbol":"DOGEUSDT","id":47599969420,"side":"Sell","size":100,"price":0.3058},{"symbol":"DOGEUSDT","id":47599969447,"side":"Sell","size":5967,"price":0.30553},{"symbol":"DOGEUSDT","id":47599969474,"side":"Sell","size":470,"price":0.30526},{"symbol":"DOGEUSDT","id":47599969500,"side":"Sell","size":50,"price":0.305},{"symbol":"DOGEUSDT","id":47599969526,"side":"Sell","size":500,"price":0.30474},{"symbol":"DOGEUSDT","id":47599969619,"side":"Sell","size":110,"price":0.30381},{"symbol":"DOGEUSDT","id":47599969620,"side":"Sell","size":100,"price":0.3038},{"symbol":"DOGEUSDT","id":47599969638,"side":"Sell","size":2,"price":0.30362},{"symbol":"DOGEUSDT","id":47599969667,"side":"Sell","size":200,"price":0.30333},{"symbol":"DOGEUSDT","id":47599969669,"side":"Sell","size":10,"price":0.30331},{"symbol":"DOGEUSDT","id":47599969684,"side":"Sell","size":67,"price":0.30316},{"symbol":"DOGEUSDT","id":47599969815,"side":"Sell","size":100,"price":0.30185},{"symbol":"DOGEUSDT","id":47599969826,"side":"Sell","size":100,"price":0.30174},{"symbol":"DOGEUSDT","id":47599969838,"side":"Sell","size":8016,"price":0.30162},{"symbol":"DOGEUSDT","id":47599969919,"side":"Sell","size":20,"price":0.30081},{"symbol":"DOGEUSDT","id":47599970000,"side":"Sell","size":30247,"price":0.3},{"symbol":"DOGEUSDT","id":47599970010,"side":"Sell","size":2,"price":0.2999},{"symbol":"DOGEUSDT","id":47599970100,"side":"Sell","size":500,"price":0.299},{"symbol":"DOGEUSDT","id":47599970103,"side":"Sell","size":2139,"price":0.29897},{"symbol":"DOGEUSDT","id":47599970105,"side":"Sell","size":30,"price":0.29895},{"symbol":"DOGEUSDT","id":47599970109,"side":"Sell","size":126,"price":0.29891},{"symbol":"DOGEUSDT","id":47599970122,"side":"Sell","size":100,"price":0.29878},{"symbol":"DOGEUSDT","id":47599970139,"side":"Sell","size":25106,"price":0.29861},{"symbol":"DOGEUSDT","id":47599970145,"side":"Sell","size":100,"price":0.29855},{"symbol":"DOGEUSDT","id":47599970189,"side":"Sell","size":200,"price":0.29811},{"symbol":"DOGEUSDT","id":47599970211,"side":"Sell","size":2147,"price":0.29789},{"symbol":"DOGEUSDT","id":47599970226,"side":"Sell","size":80,"price":0.29774},{"symbol":"DOGEUSDT","id":47599970233,"side":"Sell","size":10,"price":0.29767},{"symbol":"DOGEUSDT","id":47599970245,"side":"Sell","size":300,"price":0.29755},{"symbol":"DOGEUSDT","id":47599970251,"side":"Sell","size":126,"price":0.29749},{"symbol":"DOGEUSDT","id":47599970286,"side":"Sell","size":50,"price":0.29714},{"symbol":"DOGEUSDT","id":47599970300,"side":"Sell","size":40,"price":0.297},{"symbol":"DOGEUSDT","id":47599970318,"side":"Sell","size":2155,"price":0.29682},{"symbol":"DOGEUSDT","id":47599970320,"side":"Sell","size":12250,"price":0.2968},{"symbol":"DOGEUSDT","id":47599970394,"side":"Sell","size":126,"price":0.29606},{"symbol":"DOGEUSDT","id":47599970424,"side":"Sell","size":2162,"price":0.29576},{"symbol":"DOGEUSDT","id":47599970479,"side":"Sell","size":11523,"price":0.29521},{"symbol":"DOGEUSDT","id":47599970492,"side":"Sell","size":470,"price":0.29508},{"symbol":"DOGEUSDT","id":47599970500,"side":"Sell","size":80,"price":0.295},{"symbol":"DOGEUSDT","id":47599970530,"side":"Sell","size":2170,"price":0.2947},{"symbol":"DOGEUSDT","id":47599970536,"side":"Sell","size":126,"price":0.29464},{"symbol":"DOGEUSDT","id":47599970538,"side":"Sell","size":19413,"price":0.29462},{"symbol":"DOGEUSDT","id":47599970566,"side":"Sell","size":3,"price":0.29434},{"symbol":"DOGEUSDT","id":47599970636,"side":"Sell","size":2178,"price":0.29364},{"symbol":"DOGEUSDT","id":47599970639,"side":"Sell","size":1000,"price":0.29361},{"symbol":"DOGEUSDT","id":47599970641,"side":"Sell","size":11697,"price":0.29359},{"symbol":"DOGEUSDT","id":47599970650,"side":"Sell","size":50,"price":0.2935},{"symbol":"DOGEUSDT","id":47599970678,"side":"Sell","size":110,"price":0.29322},{"symbol":"DOGEUSDT","id":47599970685,"side":"Sell","size":50,"price":0.29315},{"symbol":"DOGEUSDT","id":47599970705,"side":"Sell","size":18897,"price":0.29295},{"symbol":"DOGEUSDT","id":47599970709,"side":"Sell","size":100,"price":0.29291},{"symbol":"DOGEUSDT","id":47599970727,"side":"Sell","size":31609,"price":0.29273},{"symbol":"DOGEUSDT","id":47599970741,"side":"Sell","size":2186,"price":0.29259},{"symbol":"DOGEUSDT","id":47599970801,"side":"Sell","size":300,"price":0.29199},{"symbol":"DOGEUSDT","id":47599970802,"side":"Sell","size":11675,"price":0.29198},{"symbol":"DOGEUSDT","id":47599970820,"side":"Sell","size":90,"price":0.2918},{"symbol":"DOGEUSDT","id":47599970838,"side":"Sell","size":7027,"price":0.29162},{"symbol":"DOGEUSDT","id":47599970846,"side":"Sell","size":2194,"price":0.29154},{"symbol":"DOGEUSDT","id":47599970876,"side":"Sell","size":10,"price":0.29124},{"symbol":"DOGEUSDT","id":47599970951,"side":"Sell","size":2202,"price":0.29049},{"symbol":"DOGEUSDT","id":47599970962,"side":"Sell","size":12508,"price":0.29038},{"symbol":"DOGEUSDT","id":47599970999,"side":"Sell","size":20,"price":0.29001},{"symbol":"DOGEUSDT","id":47599971000,"side":"Sell","size":210,"price":0.29},{"symbol":"DOGEUSDT","id":47599971012,"side":"Sell","size":1,"price":0.28988},{"symbol":"DOGEUSDT","id":47599971015,"side":"Sell","size":100,"price":0.28985},{"symbol":"DOGEUSDT","id":47599971053,"side":"Sell","size":123,"price":0.28947},{"symbol":"DOGEUSDT","id":47599971054,"side":"Sell","size":3917,"price":0.28946},{"symbol":"DOGEUSDT","id":47599971055,"side":"Sell","size":2210,"price":0.28945},{"symbol":"DOGEUSDT","id":47599971070,"side":"Sell","size":50,"price":0.2893},{"symbol":"DOGEUSDT","id":47599971104,"side":"Sell","size":49,"price":0.28896},{"symbol":"DOGEUSDT","id":47599971112,"side":"Sell","size":2000,"price":0.28888},{"symbol":"DOGEUSDT","id":47599971121,"side":"Sell","size":12883,"price":0.28879},{"symbol":"DOGEUSDT","id":47599971122,"side":"Sell","size":7096,"price":0.28878},{"symbol":"DOGEUSDT","id":47599971159,"side":"Sell","size":2218,"price":0.28841},{"symbol":"DOGEUSDT","id":47599971188,"side":"Sell","size":1179,"price":0.28812},{"symbol":"DOGEUSDT","id":47599971195,"side":"Sell","size":394,"price":0.28805},{"symbol":"DOGEUSDT","id":47599971246,"side":"Sell","size":37,"price":0.28754},{"symbol":"DOGEUSDT","id":47599971262,"side":"Sell","size":108,"price":0.28738},{"symbol":"DOGEUSDT","id":47599971275,"side":"Sell","size":100,"price":0.28725},{"symbol":"DOGEUSDT","id":47599971279,"side":"Sell","size":60,"price":0.28721},{"symbol":"DOGEUSDT","id":47599971312,"side":"Sell","size":500,"price":0.28688},{"symbol":"DOGEUSDT","id":47599971384,"side":"Sell","size":5005,"price":0.28616},{"symbol":"DOGEUSDT","id":47599971385,"side":"Sell","size":363,"price":0.28615},{"symbol":"DOGEUSDT","id":47599971388,"side":"Sell","size":37,"price":0.28612},{"symbol":"DOGEUSDT","id":47599971487,"side":"Sell","size":1,"price":0.28513},{"symbol":"DOGEUSDT","id":47599971500,"side":"Sell","size":50,"price":0.285},{"symbol":"DOGEUSDT","id":47599971675,"side":"Buy","size":37,"price":0.28325},{"symbol":"DOGEUSDT","id":47599971688,"side":"Buy","size":100,"price":0.28312},{"symbol":"DOGEUSDT","id":47599971689,"side":"Buy","size":100,"price":0.28311},{"symbol":"DOGEUSDT","id":47599971690,"side":"Buy","size":100,"price":0.2831},{"symbol":"DOGEUSDT","id":47599971691,"side":"Buy","size":100,"price":0.28309},{"symbol":"DOGEUSDT","id":47599971692,"side":"Buy","size":100,"price":0.28308},{"symbol":"DOGEUSDT","id":47599971737,"side":"Buy","size":300,"price":0.28263},{"symbol":"DOGEUSDT","id":47599971738,"side":"Buy","size":394,"price":0.28262},{"symbol":"DOGEUSDT","id":47599971755,"side":"Buy","size":43,"price":0.28245},{"symbol":"DOGEUSDT","id":47599971757,"side":"Buy","size":1179,"price":0.28243},{"symbol":"DOGEUSDT","id":47599971772,"side":"Buy","size":154,"price":0.28228},{"symbol":"DOGEUSDT","id":47599971808,"side":"Buy","size":2110,"price":0.28192},{"symbol":"DOGEUSDT","id":47599971809,"side":"Buy","size":176,"price":0.28191},{"symbol":"DOGEUSDT","id":47599971827,"side":"Buy","size":206,"price":0.28173},{"symbol":"DOGEUSDT","id":47599971850,"side":"Buy","size":5,"price":0.2815},{"symbol":"DOGEUSDT","id":47599971869,"side":"Buy","size":235,"price":0.28131},{"symbol":"DOGEUSDT","id":47599971898,"side":"Buy","size":75,"price":0.28102},{"symbol":"DOGEUSDT","id":47599971900,"side":"Buy","size":25,"price":0.281},{"symbol":"DOGEUSDT","id":47599971919,"side":"Buy","size":3917,"price":0.28081},{"symbol":"DOGEUSDT","id":47599971923,"side":"Buy","size":265,"price":0.28077},{"symbol":"DOGEUSDT","id":47599971932,"side":"Buy","size":13280,"price":0.28068},{"symbol":"DOGEUSDT","id":47599971944,"side":"Buy","size":266,"price":0.28056},{"symbol":"DOGEUSDT","id":47599971976,"side":"Buy","size":2282,"price":0.28024},{"symbol":"DOGEUSDT","id":47599971977,"side":"Buy","size":7313,"price":0.28023},{"symbol":"DOGEUSDT","id":47599972000,"side":"Buy","size":200,"price":0.28},{"symbol":"DOGEUSDT","id":47599972016,"side":"Buy","size":266,"price":0.27984},{"symbol":"DOGEUSDT","id":47599972040,"side":"Buy","size":107,"price":0.2796},{"symbol":"DOGEUSDT","id":47599972077,"side":"Buy","size":2290,"price":0.27923},{"symbol":"DOGEUSDT","id":47599972086,"side":"Buy","size":13456,"price":0.27914},{"symbol":"DOGEUSDT","id":47599972089,"side":"Buy","size":200,"price":0.27911},{"symbol":"DOGEUSDT","id":47599972100,"side":"Buy","size":3,"price":0.279},{"symbol":"DOGEUSDT","id":47599972177,"side":"Buy","size":2299,"price":0.27823},{"symbol":"DOGEUSDT","id":47599972182,"side":"Buy","size":139,"price":0.27818},{"symbol":"DOGEUSDT","id":47599972236,"side":"Buy","size":40095,"price":0.27764},{"symbol":"DOGEUSDT","id":47599972239,"side":"Buy","size":13179,"price":0.27761},{"symbol":"DOGEUSDT","id":47599972261,"side":"Buy","size":7388,"price":0.27739},{"symbol":"DOGEUSDT","id":47599972277,"side":"Buy","size":2307,"price":0.27723},{"symbol":"DOGEUSDT","id":47599972285,"side":"Buy","size":100,"price":0.27715},{"symbol":"DOGEUSDT","id":47599972324,"side":"Buy","size":172,"price":0.27676},{"symbol":"DOGEUSDT","id":47599972354,"side":"Buy","size":359,"price":0.27646},{"symbol":"DOGEUSDT","id":47599972360,"side":"Buy","size":100,"price":0.2764},{"symbol":"DOGEUSDT","id":47599972376,"side":"Buy","size":2315,"price":0.27624},{"symbol":"DOGEUSDT","id":47599972382,"side":"Buy","size":20222,"price":0.27618},{"symbol":"DOGEUSDT","id":47599972391,"side":"Buy","size":13204,"price":0.27609},{"symbol":"DOGEUSDT","id":47599972422,"side":"Buy","size":200,"price":0.27578},{"symbol":"DOGEUSDT","id":47599972451,"side":"Buy","size":7,"price":0.27549},{"symbol":"DOGEUSDT","id":47599972466,"side":"Buy","size":186,"price":0.27534},{"symbol":"DOGEUSDT","id":47599972475,"side":"Buy","size":2324,"price":0.27525},{"symbol":"DOGEUSDT","id":47599972500,"side":"Buy","size":50,"price":0.275},{"symbol":"DOGEUSDT","id":47599972543,"side":"Buy","size":12528,"price":0.27457},{"symbol":"DOGEUSDT","id":47599972574,"side":"Buy","size":2332,"price":0.27426},{"symbol":"DOGEUSDT","id":47599972608,"side":"Buy","size":186,"price":0.27392},{"symbol":"DOGEUSDT","id":47599972639,"side":"Buy","size":158,"price":0.27361},{"symbol":"DOGEUSDT","id":47599972646,"side":"Buy","size":5,"price":0.27354},{"symbol":"DOGEUSDT","id":47599972672,"side":"Buy","size":2340,"price":0.27328},{"symbol":"DOGEUSDT","id":47599972700,"side":"Buy","size":70,"price":0.273},{"symbol":"DOGEUSDT","id":47599972746,"side":"Buy","size":45,"price":0.27254},{"symbol":"DOGEUSDT","id":47599972750,"side":"Buy","size":186,"price":0.2725},{"symbol":"DOGEUSDT","id":47599972770,"side":"Buy","size":2349,"price":0.2723},{"symbol":"DOGEUSDT","id":47599972800,"side":"Buy","size":10,"price":0.272},{"symbol":"DOGEUSDT","id":47599972816,"side":"Buy","size":500,"price":0.27184},{"symbol":"DOGEUSDT","id":47599972847,"side":"Buy","size":11668,"price":0.27153},{"symbol":"DOGEUSDT","id":47599972866,"side":"Buy","size":15,"price":0.27134},{"symbol":"DOGEUSDT","id":47599972868,"side":"Buy","size":2357,"price":0.27132},{"symbol":"DOGEUSDT","id":47599972892,"side":"Buy","size":186,"price":0.27108},{"symbol":"DOGEUSDT","id":47599972929,"side":"Buy","size":300,"price":0.27071},{"symbol":"DOGEUSDT","id":47599972965,"side":"Buy","size":2366,"price":0.27035},{"symbol":"DOGEUSDT","id":47599972993,"side":"Buy","size":17278,"price":0.27007},{"symbol":"DOGEUSDT","id":47599973000,"side":"Buy","size":77,"price":0.27},{"symbol":"DOGEUSDT","id":47599973062,"side":"Buy","size":2374,"price":0.26938},{"symbol":"DOGEUSDT","id":47599973100,"side":"Buy","size":70,"price":0.269},{"symbol":"DOGEUSDT","id":47599973223,"side":"Buy","size":470,"price":0.26777},{"symbol":"DOGEUSDT","id":47599973245,"side":"Buy","size":300,"price":0.26755},{"symbol":"DOGEUSDT","id":47599973269,"side":"Buy","size":8019,"price":0.26731},{"symbol":"DOGEUSDT","id":47599973296,"side":"Buy","size":3000,"price":0.26704},{"symbol":"DOGEUSDT","id":47599973300,"side":"Buy","size":4000,"price":0.267},{"symbol":"DOGEUSDT","id":47599973369,"side":"Buy","size":20,"price":0.26631},{"symbol":"DOGEUSDT","id":47599973400,"side":"Buy","size":8,"price":0.266},{"symbol":"DOGEUSDT","id":47599973401,"side":"Buy","size":500,"price":0.26599},{"symbol":"DOGEUSDT","id":47599973486,"side":"Buy","size":116,"price":0.26514},{"symbol":"DOGEUSDT","id":47599973500,"side":"Buy","size":50,"price":0.265},{"symbol":"DOGEUSDT","id":47599973539,"side":"Buy","size":500,"price":0.26461},{"symbol":"DOGEUSDT","id":47599973726,"side":"Buy","size":15,"price":0.26274},{"symbol":"DOGEUSDT","id":47599973773,"side":"Buy","size":158,"price":0.26227},{"symbol":"DOGEUSDT","id":47599973800,"side":"Buy","size":210,"price":0.262},{"symbol":"DOGEUSDT","id":47599973806,"side":"Buy","size":8013,"price":0.26194},{"symbol":"DOGEUSDT","id":47599973902,"side":"Buy","size":3000,"price":0.26098},{"symbol":"DOGEUSDT","id":47599973925,"side":"Buy","size":22689,"price":0.26075},{"symbol":"DOGEUSDT","id":47599973930,"side":"Buy","size":25,"price":0.2607},{"symbol":"DOGEUSDT","id":47599974000,"side":"Buy","size":2251,"price":0.26},{"symbol":"DOGEUSDT","id":47599974106,"side":"Buy","size":2066,"price":0.25894},{"symbol":"DOGEUSDT","id":47599974146,"side":"Buy","size":2000,"price":0.25854},{"symbol":"DOGEUSDT","id":47599974167,"side":"Buy","size":200,"price":0.25833},{"symbol":"DOGEUSDT","id":47599974236,"side":"Buy","size":9,"price":0.25764},{"symbol":"DOGEUSDT","id":47599974245,"side":"Buy","size":300,"price":0.25755},{"symbol":"DOGEUSDT","id":47599974269,"side":"Buy","size":8064,"price":0.25731},{"symbol":"DOGEUSDT","id":47599974300,"side":"Buy","size":50,"price":0.257},{"symbol":"DOGEUSDT","id":47599974310,"side":"Buy","size":21,"price":0.2569},{"symbol":"DOGEUSDT","id":47599974482,"side":"Buy","size":158,"price":0.25518},{"symbol":"DOGEUSDT","id":47599974500,"side":"Buy","size":50,"price":0.255},{"symbol":"DOGEUSDT","id":47599974572,"side":"Buy","size":7902,"price":0.25428},{"symbol":"DOGEUSDT","id":47599974599,"side":"Buy","size":5,"price":0.25401},{"symbol":"DOGEUSDT","id":47599974624,"side":"Buy","size":61,"price":0.25376},{"symbol":"DOGEUSDT","id":47599974680,"side":"Buy","size":200,"price":0.2532},{"symbol":"DOGEUSDT","id":47599974693,"side":"Buy","size":172,"price":0.25307},{"symbol":"DOGEUSDT","id":47599974760,"side":"Buy","size":100,"price":0.2524},{"symbol":"DOGEUSDT","id":47599974780,"side":"Buy","size":158,"price":0.2522},{"symbol":"DOGEUSDT","id":47599974795,"side":"Buy","size":15,"price":0.25205},{"symbol":"DOGEUSDT","id":47599974800,"side":"Buy","size":210,"price":0.252},{"symbol":"DOGEUSDT","id":47599974889,"side":"Buy","size":200,"price":0.25111},{"symbol":"DOGEUSDT","id":47599974892,"side":"Buy","size":2070,"price":0.25108},{"symbol":"DOGEUSDT","id":47599974987,"side":"Buy","size":50,"price":0.25013},{"symbol":"DOGEUSDT","id":47599975000,"side":"Buy","size":131,"price":0.25},{"symbol":"DOGEUSDT","id":47599975189,"side":"Buy","size":200,"price":0.24811},{"symbol":"DOGEUSDT","id":47599975240,"side":"Buy","size":200,"price":0.2476},{"symbol":"DOGEUSDT","id":47599975244,"side":"Buy","size":200,"price":0.24756},{"symbol":"DOGEUSDT","id":47599975248,"side":"Buy","size":200,"price":0.24752},{"symbol":"DOGEUSDT","id":47599975251,"side":"Buy","size":200,"price":0.24749},{"symbol":"DOGEUSDT","id":47599975254,"side":"Buy","size":22,"price":0.24746},{"symbol":"DOGEUSDT","id":47599975256,"side":"Buy","size":200,"price":0.24744},{"symbol":"DOGEUSDT","id":47599975260,"side":"Buy","size":200,"price":0.2474},{"symbol":"DOGEUSDT","id":47599975263,"side":"Buy","size":200,"price":0.24737},{"symbol":"DOGEUSDT","id":47599975265,"side":"Buy","size":200,"price":0.24735},{"symbol":"DOGEUSDT","id":47599975268,"side":"Buy","size":15,"price":0.24732},{"symbol":"DOGEUSDT","id":47599975290,"side":"Buy","size":200,"price":0.2471},{"symbol":"DOGEUSDT","id":47599975315,"side":"Buy","size":450,"price":0.24685},{"symbol":"DOGEUSDT","id":47599975350,"side":"Buy","size":20,"price":0.2465},{"symbol":"DOGEUSDT","id":47599975384,"side":"Buy","size":200,"price":0.24616},{"symbol":"DOGEUSDT","id":47599975400,"side":"Buy","size":1,"price":0.246},{"symbol":"DOGEUSDT","id":47599975405,"side":"Buy","size":10,"price":0.24595},{"symbol":"DOGEUSDT","id":47599975415,"side":"Buy","size":10,"price":0.24585},{"symbol":"DOGEUSDT","id":47599975443,"side":"Buy","size":61,"price":0.24557},{"symbol":"DOGEUSDT","id":47599975450,"side":"Buy","size":400,"price":0.2455},{"symbol":"DOGEUSDT","id":47599975459,"side":"Buy","size":2000,"price":0.24541},{"symbol":"DOGEUSDT","id":47599975466,"side":"Buy","size":20,"price":0.24534},{"symbol":"DOGEUSDT","id":47599975500,"side":"Buy","size":360,"price":0.245},{"symbol":"DOGEUSDT","id":47599975575,"side":"Buy","size":80,"price":0.24425},{"symbol":"DOGEUSDT","id":47599975582,"side":"Buy","size":2,"price":0.24418},{"symbol":"DOGEUSDT","id":47599975596,"side":"Buy","size":7818,"price":0.24404},{"symbol":"DOGEUSDT","id":47599975673,"side":"Buy","size":15,"price":0.24327},{"symbol":"DOGEUSDT","id":47599975704,"side":"Buy","size":1141,"price":0.24296},{"symbol":"DOGEUSDT","id":47599975785,"side":"Buy","size":555,"price":0.24215},{"symbol":"DOGEUSDT","id":47599975800,"side":"Buy","size":106,"price":0.242},{"symbol":"DOGEUSDT","id":47599975825,"side":"Buy","size":1,"price":0.24175},{"symbol":"DOGEUSDT","id":47599975860,"side":"Buy","size":941,"price":0.2414},{"symbol":"DOGEUSDT","id":47599975868,"side":"Buy","size":500,"price":0.24132},{"symbol":"DOGEUSDT","id":47599975885,"side":"Buy","size":165,"price":0.24115},{"symbol":"DOGEUSDT","id":47599975889,"side":"Buy","size":200,"price":0.24111},{"symbol":"DOGEUSDT","id":47599975957,"side":"Buy","size":7960,"price":0.24043},{"symbol":"DOGEUSDT","id":47599975962,"side":"Buy","size":600,"price":0.24038},{"symbol":"DOGEUSDT","id":47599975990,"side":"Buy","size":10,"price":0.2401},{"symbol":"DOGEUSDT","id":47599976000,"side":"Buy","size":944,"price":0.24},{"symbol":"DOGEUSDT","id":47599976045,"side":"Buy","size":30,"price":0.23955},{"symbol":"DOGEUSDT","id":47599976063,"side":"Buy","size":60,"price":0.23937},{"symbol":"DOGEUSDT","id":47599976067,"side":"Buy","size":50,"price":0.23933},{"symbol":"DOGEUSDT","id":47599976077,"side":"Buy","size":555,"price":0.23923},{"symbol":"DOGEUSDT","id":47599976111,"side":"Buy","size":1000,"price":0.23889},{"symbol":"DOGEUSDT","id":47599976112,"side":"Buy","size":1,"price":0.23888},{"symbol":"DOGEUSDT","id":47599976201,"side":"Buy","size":8050,"price":0.23799},{"symbol":"DOGEUSDT","id":47599976245,"side":"Buy","size":10,"price":0.23755},{"symbol":"DOGEUSDT","id":47599976344,"side":"Buy","size":15,"price":0.23656},{"symbol":"DOGEUSDT","id":47599976345,"side":"Buy","size":100000,"price":0.23655},{"symbol":"DOGEUSDT","id":47599976360,"side":"Buy","size":50,"price":0.2364},{"symbol":"DOGEUSDT","id":47599976380,"side":"Buy","size":50,"price":0.2362},{"symbol":"DOGEUSDT","id":47599976410,"side":"Buy","size":100,"price":0.2359},{"symbol":"DOGEUSDT","id":47599976430,"side":"Buy","size":250,"price":0.2357},{"symbol":"DOGEUSDT","id":47599976438,"side":"Buy","size":100,"price":0.23562},{"symbol":"DOGEUSDT","id":47599976450,"side":"Buy","size":1400,"price":0.2355},{"symbol":"DOGEUSDT","id":47599976480,"side":"Buy","size":500,"price":0.2352},{"symbol":"DOGEUSDT","id":47599976485,"side":"Buy","size":25,"price":0.23515},{"symbol":"DOGEUSDT","id":47599976500,"side":"Buy","size":320,"price":0.235},{"symbol":"DOGEUSDT","id":47599976596,"side":"Buy","size":50,"price":0.23404},{"symbol":"DOGEUSDT","id":47599976637,"side":"Buy","size":125,"price":0.23363},{"symbol":"DOGEUSDT","id":47599976678,"side":"Buy","size":200,"price":0.23322},{"symbol":"DOGEUSDT","id":47599976689,"side":"Buy","size":200,"price":0.23311},{"symbol":"DOGEUSDT","id":47599976701,"side":"Buy","size":100,"price":0.23299},{"symbol":"DOGEUSDT","id":47599976708,"side":"Buy","size":200,"price":0.23292},{"symbol":"DOGEUSDT","id":47599976770,"side":"Buy","size":750,"price":0.2323},{"symbol":"DOGEUSDT","id":47599976835,"side":"Buy","size":750,"price":0.23165},{"symbol":"DOGEUSDT","id":47599976852,"side":"Buy","size":4000,"price":0.23148},{"symbol":"DOGEUSDT","id":47599976900,"side":"Buy","size":50,"price":0.231},{"symbol":"DOGEUSDT","id":47599976918,"side":"Buy","size":10,"price":0.23082},{"symbol":"DOGEUSDT","id":47599977000,"side":"Buy","size":1346,"price":0.23},{"symbol":"DOGEUSDT","id":47599977038,"side":"Buy","size":14,"price":0.22962},{"symbol":"DOGEUSDT","id":47599977050,"side":"Buy","size":1000,"price":0.2295},{"symbol":"DOGEUSDT","id":47599977060,"side":"Buy","size":60,"price":0.2294},{"symbol":"DOGEUSDT","id":47599977100,"side":"Buy","size":350,"price":0.229},{"symbol":"DOGEUSDT","id":47599977204,"side":"Buy","size":100,"price":0.22796},{"symbol":"DOGEUSDT","id":47599977254,"side":"Buy","size":800,"price":0.22746},{"symbol":"DOGEUSDT","id":47599977300,"side":"Buy","size":50,"price":0.227},{"symbol":"DOGEUSDT","id":47599977373,"side":"Buy","size":5000,"price":0.22627},{"symbol":"DOGEUSDT","id":47599977383,"side":"Buy","size":500,"price":0.22617},{"symbol":"DOGEUSDT","id":47599977411,"side":"Buy","size":111,"price":0.22589},{"symbol":"DOGEUSDT","id":47599977444,"side":"Buy","size":19,"price":0.22556},{"symbol":"DOGEUSDT","id":47599977445,"side":"Buy","size":200,"price":0.22555},{"symbol":"DOGEUSDT","id":47599977450,"side":"Buy","size":1000,"price":0.2255},{"symbol":"DOGEUSDT","id":47599977500,"side":"Buy","size":1075,"price":0.225},{"symbol":"DOGEUSDT","id":47599977521,"side":"Buy","size":25,"price":0.22479},{"symbol":"DOGEUSDT","id":47599977530,"side":"Buy","size":110,"price":0.2247},{"symbol":"DOGEUSDT","id":47599977562,"side":"Buy","size":50,"price":0.22438},{"symbol":"DOGEUSDT","id":47599977650,"side":"Buy","size":40,"price":0.2235},{"symbol":"DOGEUSDT","id":47599977678,"side":"Buy","size":200,"price":0.22322},{"symbol":"DOGEUSDT","id":47599977686,"side":"Buy","size":5000,"price":0.22314},{"symbol":"DOGEUSDT","id":47599977700,"side":"Buy","size":100,"price":0.223},{"symbol":"DOGEUSDT","id":47599977714,"side":"Buy","size":15,"price":0.22286},{"symbol":"DOGEUSDT","id":47599977730,"side":"Buy","size":250,"price":0.2227},{"symbol":"DOGEUSDT","id":47599977778,"side":"Buy","size":200,"price":0.22222},{"symbol":"DOGEUSDT","id":47599977816,"side":"Buy","size":50,"price":0.22184},{"symbol":"DOGEUSDT","id":47599977890,"side":"Buy","size":100,"price":0.2211},{"symbol":"DOGEUSDT","id":47599977900,"side":"Buy","size":850,"price":0.221},{"symbol":"DOGEUSDT","id":47599977928,"side":"Buy","size":5000,"price":0.22072},{"symbol":"DOGEUSDT","id":47599977938,"side":"Buy","size":100,"price":0.22062},{"symbol":"DOGEUSDT","id":47599978000,"side":"Buy","size":651,"price":0.22},{"symbol":"DOGEUSDT","id":47599978001,"side":"Buy","size":400,"price":0.21999},{"symbol":"DOGEUSDT","id":47599978010,"side":"Buy","size":10,"price":0.2199},{"symbol":"DOGEUSDT","id":47599978040,"side":"Buy","size":255,"price":0.2196},{"symbol":"DOGEUSDT","id":47599978113,"side":"Buy","size":9,"price":0.21887},{"symbol":"DOGEUSDT","id":47599978200,"side":"Buy","size":15,"price":0.218},{"symbol":"DOGEUSDT","id":47599978210,"side":"Buy","size":5,"price":0.2179},{"symbol":"DOGEUSDT","id":47599978237,"side":"Buy","size":25,"price":0.21763},{"symbol":"DOGEUSDT","id":47599978248,"side":"Buy","size":200,"price":0.21752},{"symbol":"DOGEUSDT","id":47599978256,"side":"Buy","size":5000,"price":0.21744},{"symbol":"DOGEUSDT","id":47599978323,"side":"Buy","size":1000,"price":0.21677},{"symbol":"DOGEUSDT","id":47599978347,"side":"Buy","size":100,"price":0.21653},{"symbol":"DOGEUSDT","id":47599978352,"side":"Buy","size":15,"price":0.21648},{"symbol":"DOGEUSDT","id":47599978396,"side":"Buy","size":20,"price":0.21604},{"symbol":"DOGEUSDT","id":47599978413,"side":"Buy","size":555,"price":0.21587},{"symbol":"DOGEUSDT","id":47599978500,"side":"Buy","size":100,"price":0.215},{"symbol":"DOGEUSDT","id":47599978507,"side":"Buy","size":30,"price":0.21493},{"symbol":"DOGEUSDT","id":47599978527,"side":"Buy","size":500,"price":0.21473},{"symbol":"DOGEUSDT","id":47599978528,"side":"Buy","size":5000,"price":0.21472},{"symbol":"DOGEUSDT","id":47599978588,"side":"Buy","size":5000,"price":0.21412},{"symbol":"DOGEUSDT","id":47599978590,"side":"Buy","size":300,"price":0.2141},{"symbol":"DOGEUSDT","id":47599978600,"side":"Buy","size":50,"price":0.214},{"symbol":"DOGEUSDT","id":47599978716,"side":"Buy","size":5000,"price":0.21284},{"symbol":"DOGEUSDT","id":47599978789,"side":"Buy","size":5518,"price":0.21211},{"symbol":"DOGEUSDT","id":47599978800,"side":"Buy","size":600,"price":0.212},{"symbol":"DOGEUSDT","id":47599978804,"side":"Buy","size":100,"price":0.21196},{"symbol":"DOGEUSDT","id":47599978837,"side":"Buy","size":5000,"price":0.21163},{"symbol":"DOGEUSDT","id":47599978889,"side":"Buy","size":1,"price":0.21111},{"symbol":"DOGEUSDT","id":47599978891,"side":"Buy","size":5000,"price":0.21109},{"symbol":"DOGEUSDT","id":47599978900,"side":"Buy","size":5095,"price":0.211},{"symbol":"DOGEUSDT","id":47599978920,"side":"Buy","size":5000,"price":0.2108},{"symbol":"DOGEUSDT","id":47599979000,"side":"Buy","size":60831,"price":0.21},{"symbol":"DOGEUSDT","id":47599979020,"side":"Buy","size":10,"price":0.2098},{"symbol":"DOGEUSDT","id":47599979194,"side":"Buy","size":5000,"price":0.20806},{"symbol":"DOGEUSDT","id":47599979231,"side":"Buy","size":147,"price":0.20769},{"symbol":"DOGEUSDT","id":47599979251,"side":"Buy","size":100,"price":0.20749},{"symbol":"DOGEUSDT","id":47599979272,"side":"Buy","size":500,"price":0.20728},{"symbol":"DOGEUSDT","id":47599979289,"side":"Buy","size":150,"price":0.20711},{"symbol":"DOGEUSDT","id":47599979340,"side":"Buy","size":8000,"price":0.2066},{"symbol":"DOGEUSDT","id":47599979375,"side":"Buy","size":100,"price":0.20625},{"symbol":"DOGEUSDT","id":47599979376,"side":"Buy","size":5000,"price":0.20624},{"symbol":"DOGEUSDT","id":47599979394,"side":"Buy","size":1,"price":0.20606},{"symbol":"DOGEUSDT","id":47599979437,"side":"Buy","size":5000,"price":0.20563},{"symbol":"DOGEUSDT","id":47599979445,"side":"Buy","size":200,"price":0.20555},{"symbol":"DOGEUSDT","id":47599979497,"side":"Buy","size":5000,"price":0.20503},{"symbol":"DOGEUSDT","id":47599979505,"side":"Buy","size":15,"price":0.20495},{"symbol":"DOGEUSDT","id":47599979516,"side":"Buy","size":7843,"price":0.20484},{"symbol":"DOGEUSDT","id":47599979558,"side":"Buy","size":8000,"price":0.20442},{"symbol":"DOGEUSDT","id":47599979565,"side":"Buy","size":5000,"price":0.20435},{"symbol":"DOGEUSDT","id":47599979660,"side":"Buy","size":5000,"price":0.2034},{"symbol":"DOGEUSDT","id":47599979678,"side":"Buy","size":200,"price":0.20322},{"symbol":"DOGEUSDT","id":47599979740,"side":"Buy","size":3000,"price":0.2026},{"symbol":"DOGEUSDT","id":47599979787,"side":"Buy","size":100,"price":0.20213},{"symbol":"DOGEUSDT","id":47599979800,"side":"Buy","size":2244,"price":0.202},{"symbol":"DOGEUSDT","id":47599979832,"side":"Buy","size":100,"price":0.20168},{"symbol":"DOGEUSDT","id":47599979861,"side":"Buy","size":5000,"price":0.20139},{"symbol":"DOGEUSDT","id":47599979900,"side":"Buy","size":50,"price":0.201},{"symbol":"DOGEUSDT","id":47599979922,"side":"Buy","size":5000,"price":0.20078},{"symbol":"DOGEUSDT","id":47599979949,"side":"Buy","size":20,"price":0.20051},{"symbol":"DOGEUSDT","id":47599979977,"side":"Buy","size":600,"price":0.20023},{"symbol":"DOGEUSDT","id":47599979982,"side":"Buy","size":10000,"price":0.20018},{"symbol":"DOGEUSDT","id":47599980000,"side":"Buy","size":32831,"price":0.2},{"symbol":"DOGEUSDT","id":47599980043,"side":"Buy","size":5000,"price":0.19957},{"symbol":"DOGEUSDT","id":47599980100,"side":"Buy","size":300,"price":0.199},{"symbol":"DOGEUSDT","id":47599980103,"side":"Buy","size":5000,"price":0.19897},{"symbol":"DOGEUSDT","id":47599980115,"side":"Buy","size":5,"price":0.19885},{"symbol":"DOGEUSDT","id":47599980167,"side":"Buy","size":2756,"price":0.19833},{"symbol":"DOGEUSDT","id":47599980175,"side":"Buy","size":100,"price":0.19825},{"symbol":"DOGEUSDT","id":47599980270,"side":"Buy","size":100,"price":0.1973},{"symbol":"DOGEUSDT","id":47599980387,"side":"Buy","size":100,"price":0.19613},{"symbol":"DOGEUSDT","id":47599980403,"side":"Buy","size":50,"price":0.19597},{"symbol":"DOGEUSDT","id":47599980407,"side":"Buy","size":30,"price":0.19593},{"symbol":"DOGEUSDT","id":47599980420,"side":"Buy","size":100,"price":0.1958},{"symbol":"DOGEUSDT","id":47599980455,"side":"Buy","size":100,"price":0.19545},{"symbol":"DOGEUSDT","id":47599980460,"side":"Buy","size":200,"price":0.1954},{"symbol":"DOGEUSDT","id":47599980500,"side":"Buy","size":56004,"price":0.195},{"symbol":"DOGEUSDT","id":47599980528,"side":"Buy","size":3000,"price":0.19472},{"symbol":"DOGEUSDT","id":47599980632,"side":"Buy","size":100,"price":0.19368},{"symbol":"DOGEUSDT","id":47599980693,"side":"Buy","size":2131,"price":0.19307},{"symbol":"DOGEUSDT","id":47599980709,"side":"Buy","size":5000,"price":0.19291},{"symbol":"DOGEUSDT","id":47599980767,"side":"Buy","size":100,"price":0.19233},{"symbol":"DOGEUSDT","id":47599980780,"side":"Buy","size":20,"price":0.1922},{"symbol":"DOGEUSDT","id":47599980810,"side":"Buy","size":20,"price":0.1919},{"symbol":"DOGEUSDT","id":47599980831,"side":"Buy","size":5000,"price":0.19169},{"symbol":"DOGEUSDT","id":47599980889,"side":"Buy","size":400,"price":0.19111},{"symbol":"DOGEUSDT","id":47599980891,"side":"Buy","size":4100,"price":0.19109},{"symbol":"DOGEUSDT","id":47599981000,"side":"Buy","size":771,"price":0.19},{"symbol":"DOGEUSDT","id":47599981012,"side":"Buy","size":8000,"price":0.18988},{"symbol":"DOGEUSDT","id":47599981073,"side":"Buy","size":5000,"price":0.18927},{"symbol":"DOGEUSDT","id":47599981089,"side":"Buy","size":100,"price":0.18911},{"symbol":"DOGEUSDT","id":47599981155,"side":"Buy","size":1,"price":0.18845},{"symbol":"DOGEUSDT","id":47599981235,"side":"Buy","size":3,"price":0.18765},{"symbol":"DOGEUSDT","id":47599981256,"side":"Buy","size":20,"price":0.18744},{"symbol":"DOGEUSDT","id":47599981262,"side":"Buy","size":5000,"price":0.18738},{"symbol":"DOGEUSDT","id":47599981334,"side":"Buy","size":400,"price":0.18666},{"symbol":"DOGEUSDT","id":47599981339,"side":"Buy","size":100,"price":0.18661},{"symbol":"DOGEUSDT","id":47599981370,"side":"Buy","size":4,"price":0.1863},{"symbol":"DOGEUSDT","id":47599981510,"side":"Buy","size":500,"price":0.1849},{"symbol":"DOGEUSDT","id":47599981516,"side":"Buy","size":5000,"price":0.18484},{"symbol":"DOGEUSDT","id":47599981528,"side":"Buy","size":50000,"price":0.18472},{"symbol":"DOGEUSDT","id":47599981576,"side":"Buy","size":5000,"price":0.18424},{"symbol":"DOGEUSDT","id":47599981661,"side":"Buy","size":100,"price":0.18339},{"symbol":"DOGEUSDT","id":47599981684,"side":"Buy","size":100,"price":0.18316},{"symbol":"DOGEUSDT","id":47599981700,"side":"Buy","size":2700,"price":0.183},{"symbol":"DOGEUSDT","id":47599981703,"side":"Buy","size":500,"price":0.18297},{"symbol":"DOGEUSDT","id":47599981819,"side":"Buy","size":5000,"price":0.18181},{"symbol":"DOGEUSDT","id":47599981865,"side":"Buy","size":10,"price":0.18135},{"symbol":"DOGEUSDT","id":47599981889,"side":"Buy","size":400,"price":0.18111},{"symbol":"DOGEUSDT","id":47599981920,"side":"Buy","size":2000,"price":0.1808},{"symbol":"DOGEUSDT","id":47599981928,"side":"Buy","size":1000,"price":0.18072},{"symbol":"DOGEUSDT","id":47599982000,"side":"Buy","size":6259,"price":0.18},{"symbol":"DOGEUSDT","id":47599982003,"side":"Buy","size":100,"price":0.17997},{"symbol":"DOGEUSDT","id":47599982010,"side":"Buy","size":1,"price":0.1799},{"symbol":"DOGEUSDT","id":47599982018,"side":"Buy","size":30,"price":0.17982},{"symbol":"DOGEUSDT","id":47599982020,"side":"Buy","size":2000,"price":0.1798},{"symbol":"DOGEUSDT","id":47599982061,"side":"Buy","size":5000,"price":0.17939},{"symbol":"DOGEUSDT","id":47599982078,"side":"Buy","size":30665,"price":0.17922},{"symbol":"DOGEUSDT","id":47599982080,"side":"Buy","size":50,"price":0.1792},{"symbol":"DOGEUSDT","id":47599982081,"side":"Buy","size":100,"price":0.17919},{"symbol":"DOGEUSDT","id":47599982120,"side":"Buy","size":2000,"price":0.1788},{"symbol":"DOGEUSDT","id":47599982122,"side":"Buy","size":5000,"price":0.17878},{"symbol":"DOGEUSDT","id":47599982140,"side":"Buy","size":5,"price":0.1786},{"symbol":"DOGEUSDT","id":47599982182,"side":"Buy","size":5000,"price":0.17818},{"symbol":"DOGEUSDT","id":47599982220,"side":"Buy","size":2000,"price":0.1778},{"symbol":"DOGEUSDT","id":47599982243,"side":"Buy","size":5000,"price":0.17757},{"symbol":"DOGEUSDT","id":47599982300,"side":"Buy","size":100,"price":0.177},{"symbol":"DOGEUSDT","id":47599982320,"side":"Buy","size":1000,"price":0.1768},{"symbol":"DOGEUSDT","id":47599982389,"side":"Buy","size":600,"price":0.17611},{"symbol":"DOGEUSDT","id":47599982424,"side":"Buy","size":100,"price":0.17576},{"symbol":"DOGEUSDT","id":47599982425,"side":"Buy","size":5000,"price":0.17575},{"symbol":"DOGEUSDT","id":47599982696,"side":"Buy","size":20,"price":0.17304},{"symbol":"DOGEUSDT","id":47599982728,"side":"Buy","size":5000,"price":0.17272},{"symbol":"DOGEUSDT","id":47599982803,"side":"Buy","size":100,"price":0.17197},{"symbol":"DOGEUSDT","id":47599982874,"side":"Buy","size":100,"price":0.17126},{"symbol":"DOGEUSDT","id":47599982889,"side":"Buy","size":400,"price":0.17111},{"symbol":"DOGEUSDT","id":47599982892,"side":"Buy","size":10,"price":0.17108},{"symbol":"DOGEUSDT","id":47599982934,"side":"Buy","size":10,"price":0.17066},{"symbol":"DOGEUSDT","id":47599983000,"side":"Buy","size":80115,"price":0.17},{"symbol":"DOGEUSDT","id":47599983016,"side":"Buy","size":80,"price":0.16984},{"symbol":"DOGEUSDT","id":47599983180,"side":"Buy","size":50,"price":0.1682},{"symbol":"DOGEUSDT","id":47599983183,"side":"Buy","size":10,"price":0.16817},{"symbol":"DOGEUSDT","id":47599983200,"side":"Buy","size":100,"price":0.168},{"symbol":"DOGEUSDT","id":47599983400,"side":"Buy","size":100,"price":0.166},{"symbol":"DOGEUSDT","id":47599983454,"side":"Buy","size":30,"price":0.16546},{"symbol":"DOGEUSDT","id":47599983500,"side":"Buy","size":300,"price":0.165},{"symbol":"DOGEUSDT","id":47599983518,"side":"Buy","size":8109,"price":0.16482},{"symbol":"DOGEUSDT","id":47599983584,"side":"Buy","size":2,"price":0.16416},{"symbol":"DOGEUSDT","id":47599983600,"side":"Buy","size":250,"price":0.164},{"symbol":"DOGEUSDT","id":47599983718,"side":"Buy","size":50,"price":0.16282},{"symbol":"DOGEUSDT","id":47599983800,"side":"Buy","size":100,"price":0.162},{"symbol":"DOGEUSDT","id":47599984000,"side":"Buy","size":400,"price":0.16},{"symbol":"DOGEUSDT","id":47599984019,"side":"Buy","size":200,"price":0.15981},{"symbol":"DOGEUSDT","id":47599984078,"side":"Buy","size":30665,"price":0.15922},{"symbol":"DOGEUSDT","id":47599984200,"side":"Buy","size":100,"price":0.158},{"symbol":"DOGEUSDT","id":47599984211,"side":"Buy","size":1000,"price":0.15789},{"symbol":"DOGEUSDT","id":47599984267,"side":"Buy","size":1000,"price":0.15733},{"symbol":"DOGEUSDT","id":47599984281,"side":"Buy","size":1000,"price":0.15719},{"symbol":"DOGEUSDT","id":47599984292,"side":"Buy","size":1000,"price":0.15708},{"symbol":"DOGEUSDT","id":47599984394,"side":"Buy","size":500,"price":0.15606},{"symbol":"DOGEUSDT","id":47599984400,"side":"Buy","size":100,"price":0.156},{"symbol":"DOGEUSDT","id":47599984484,"side":"Buy","size":200,"price":0.15516},{"symbol":"DOGEUSDT","id":47599984500,"side":"Buy","size":370,"price":0.155},{"symbol":"DOGEUSDT","id":47599984600,"side":"Buy","size":100,"price":0.154},{"symbol":"DOGEUSDT","id":47599984640,"side":"Buy","size":125,"price":0.1536},{"symbol":"DOGEUSDT","id":47599984651,"side":"Buy","size":101703,"price":0.15349},{"symbol":"DOGEUSDT","id":47599984656,"side":"Buy","size":140,"price":0.15344},{"symbol":"DOGEUSDT","id":47599984714,"side":"Buy","size":2,"price":0.15286},{"symbol":"DOGEUSDT","id":47599984783,"side":"Buy","size":15,"price":0.15217},{"symbol":"DOGEUSDT","id":47599984790,"side":"Buy","size":100,"price":0.1521},{"symbol":"DOGEUSDT","id":47599984799,"side":"Buy","size":120,"price":0.15201},{"symbol":"DOGEUSDT","id":47599984800,"side":"Buy","size":100,"price":0.152},{"symbol":"DOGEUSDT","id":47599984820,"side":"Buy","size":1,"price":0.1518},{"symbol":"DOGEUSDT","id":47599985000,"side":"Buy","size":601,"price":0.15},{"symbol":"DOGEUSDT","id":47599985110,"side":"Buy","size":70,"price":0.1489},{"symbol":"DOGEUSDT","id":47599985199,"side":"Buy","size":120,"price":0.14801},{"symbol":"DOGEUSDT","id":47599985200,"side":"Buy","size":100,"price":0.148},{"symbol":"DOGEUSDT","id":47599985255,"side":"Buy","size":100,"price":0.14745},{"symbol":"DOGEUSDT","id":47599985292,"side":"Buy","size":10,"price":0.14708},{"symbol":"DOGEUSDT","id":47599985350,"side":"Buy","size":250,"price":0.1465},{"symbol":"DOGEUSDT","id":47599985400,"side":"Buy","size":100,"price":0.146},{"symbol":"DOGEUSDT","id":47599985445,"side":"Buy","size":120,"price":0.14555},{"symbol":"DOGEUSDT","id":47599985489,"side":"Buy","size":9000,"price":0.14511},{"symbol":"DOGEUSDT","id":47599985500,"side":"Buy","size":300,"price":0.145},{"symbol":"DOGEUSDT","id":47599985586,"side":"Buy","size":80,"price":0.14414},{"symbol":"DOGEUSDT","id":47599985600,"side":"Buy","size":100,"price":0.144},{"symbol":"DOGEUSDT","id":47599985644,"side":"Buy","size":100,"price":0.14356},{"symbol":"DOGEUSDT","id":47599985743,"side":"Buy","size":94,"price":0.14257},{"symbol":"DOGEUSDT","id":47599985750,"side":"Buy","size":25,"price":0.1425},{"symbol":"DOGEUSDT","id":47599985800,"side":"Buy","size":100,"price":0.142},{"symbol":"DOGEUSDT","id":47599985900,"side":"Buy","size":600,"price":0.141},{"symbol":"DOGEUSDT","id":47599986000,"side":"Buy","size":38926,"price":0.14},{"symbol":"DOGEUSDT","id":47599986047,"side":"Buy","size":2,"price":0.13953},{"symbol":"DOGEUSDT","id":47599986056,"side":"Buy","size":60,"price":0.13944},{"symbol":"DOGEUSDT","id":47599986100,"side":"Buy","size":100,"price":0.139},{"symbol":"DOGEUSDT","id":47599986112,"side":"Buy","size":100,"price":0.13888},{"symbol":"DOGEUSDT","id":47599986238,"side":"Buy","size":125,"price":0.13762},{"symbol":"DOGEUSDT","id":47599986386,"side":"Buy","size":8113,"price":0.13614},{"symbol":"DOGEUSDT","id":47599986400,"side":"Buy","size":100,"price":0.136},{"symbol":"DOGEUSDT","id":47599986441,"side":"Buy","size":150,"price":0.13559},{"symbol":"DOGEUSDT","id":47599986500,"side":"Buy","size":300,"price":0.135},{"symbol":"DOGEUSDT","id":47599986680,"side":"Buy","size":10,"price":0.1332},{"symbol":"DOGEUSDT","id":47599986700,"side":"Buy","size":100,"price":0.133},{"symbol":"DOGEUSDT","id":47599986778,"side":"Buy","size":2000,"price":0.13222},{"symbol":"DOGEUSDT","id":47599986892,"side":"Buy","size":10,"price":0.13108},{"symbol":"DOGEUSDT","id":47599987000,"side":"Buy","size":400,"price":0.13},{"symbol":"DOGEUSDT","id":47599987137,"side":"Buy","size":1,"price":0.12863},{"symbol":"DOGEUSDT","id":47599987200,"side":"Buy","size":100,"price":0.128},{"symbol":"DOGEUSDT","id":47599987355,"side":"Buy","size":70,"price":0.12645},{"symbol":"DOGEUSDT","id":47599987400,"side":"Buy","size":100,"price":0.126},{"symbol":"DOGEUSDT","id":47599987553,"side":"Buy","size":125,"price":0.12447},{"symbol":"DOGEUSDT","id":47599987618,"side":"Buy","size":20,"price":0.12382},{"symbol":"DOGEUSDT","id":47599987800,"side":"Buy","size":100,"price":0.122},{"symbol":"DOGEUSDT","id":47599987861,"side":"Buy","size":200,"price":0.12139},{"symbol":"DOGEUSDT","id":47599987970,"side":"Buy","size":200,"price":0.1203},{"symbol":"DOGEUSDT","id":47599988000,"side":"Buy","size":45000,"price":0.12},{"symbol":"DOGEUSDT","id":47599988200,"side":"Buy","size":100,"price":0.118},{"symbol":"DOGEUSDT","id":47599988315,"side":"Buy","size":10,"price":0.11685},{"symbol":"DOGEUSDT","id":47599988383,"side":"Buy","size":150,"price":0.11617},{"symbol":"DOGEUSDT","id":47599988620,"side":"Buy","size":10,"price":0.1138},{"symbol":"DOGEUSDT","id":47599988637,"side":"Buy","size":9000,"price":0.11363},{"symbol":"DOGEUSDT","id":47599988940,"side":"Buy","size":10,"price":0.1106},{"symbol":"DOGEUSDT","id":47599989000,"side":"Buy","size":40000,"price":0.11},{"symbol":"DOGEUSDT","id":47599989200,"side":"Buy","size":1000,"price":0.108},{"symbol":"DOGEUSDT","id":47599989204,"side":"Buy","size":600,"price":0.10796},{"symbol":"DOGEUSDT","id":47599989208,"side":"Buy","size":50,"price":0.10792},{"symbol":"DOGEUSDT","id":47599989300,"side":"Buy","size":1000,"price":0.107},{"symbol":"DOGEUSDT","id":47599989370,"side":"Buy","size":220,"price":0.1063},{"symbol":"DOGEUSDT","id":47599989400,"side":"Buy","size":1000,"price":0.106},{"symbol":"DOGEUSDT","id":47599989475,"side":"Buy","size":200,"price":0.10525},{"symbol":"DOGEUSDT","id":47599989500,"side":"Buy","size":1001,"price":0.105},{"symbol":"DOGEUSDT","id":47599989600,"side":"Buy","size":1000,"price":0.104},{"symbol":"DOGEUSDT","id":47599989800,"side":"Buy","size":1000,"price":0.102},{"symbol":"DOGEUSDT","id":47599989803,"side":"Buy","size":150,"price":0.10197},{"symbol":"DOGEUSDT","id":47599989855,"side":"Buy","size":200,"price":0.10145},{"symbol":"DOGEUSDT","id":47599989990,"side":"Buy","size":5000,"price":0.1001},{"symbol":"DOGEUSDT","id":47599990000,"side":"Buy","size":8100,"price":0.1},{"symbol":"DOGEUSDT","id":47599990291,"side":"Buy","size":681,"price":0.09709},{"symbol":"DOGEUSDT","id":47599990336,"side":"Buy","size":32,"price":0.09664},{"symbol":"DOGEUSDT","id":47599990400,"side":"Buy","size":100,"price":0.096},{"symbol":"DOGEUSDT","id":47599990472,"side":"Buy","size":18,"price":0.09528},{"symbol":"DOGEUSDT","id":47599990494,"side":"Buy","size":200,"price":0.09506},{"symbol":"DOGEUSDT","id":47599990520,"side":"Buy","size":100,"price":0.0948},{"symbol":"DOGEUSDT","id":47599990624,"side":"Buy","size":200,"price":0.09376},{"symbol":"DOGEUSDT","id":47599990770,"side":"Buy","size":200,"price":0.0923},{"symbol":"DOGEUSDT","id":47599991000,"side":"Buy","size":1,"price":0.09},{"symbol":"DOGEUSDT","id":47599991367,"side":"Buy","size":15000,"price":0.08633},{"symbol":"DOGEUSDT","id":47599991425,"side":"Buy","size":1000,"price":0.08575},{"symbol":"DOGEUSDT","id":47599991625,"side":"Buy","size":50,"price":0.08375},{"symbol":"DOGEUSDT","id":47599991626,"side":"Buy","size":10000,"price":0.08374},{"symbol":"DOGEUSDT","id":47599991700,"side":"Buy","size":100,"price":0.083},{"symbol":"DOGEUSDT","id":47599991760,"side":"Buy","size":240,"price":0.0824},{"symbol":"DOGEUSDT","id":47599991800,"side":"Buy","size":200,"price":0.082},{"symbol":"DOGEUSDT","id":47599992000,"side":"Buy","size":10000,"price":0.08},{"symbol":"DOGEUSDT","id":47599992005,"side":"Buy","size":150,"price":0.07995},{"symbol":"DOGEUSDT","id":47599992026,"side":"Buy","size":501,"price":0.07974},{"symbol":"DOGEUSDT","id":47599992068,"side":"Buy","size":30,"price":0.07932},{"symbol":"DOGEUSDT","id":47599992300,"side":"Buy","size":650,"price":0.077},{"symbol":"DOGEUSDT","id":47599992342,"side":"Buy","size":100,"price":0.07658},{"symbol":"DOGEUSDT","id":47599992499,"side":"Buy","size":185,"price":0.07501},{"symbol":"DOGEUSDT","id":47599992500,"side":"Buy","size":320,"price":0.075},{"symbol":"DOGEUSDT","id":47599992637,"side":"Buy","size":20000,"price":0.07363},{"symbol":"DOGEUSDT","id":47599992708,"side":"Buy","size":200,"price":0.07292},{"symbol":"DOGEUSDT","id":47599993000,"side":"Buy","size":100,"price":0.07},{"symbol":"DOGEUSDT","id":47599993300,"side":"Buy","size":300,"price":0.067},{"symbol":"DOGEUSDT","id":47599993383,"side":"Buy","size":20,"price":0.06617},{"symbol":"DOGEUSDT","id":47599993400,"side":"Buy","size":200,"price":0.066},{"symbol":"DOGEUSDT","id":47599994283,"side":"Buy","size":11111,"price":0.05717},{"symbol":"DOGEUSDT","id":47599994293,"side":"Buy","size":400,"price":0.05707},{"symbol":"DOGEUSDT","id":47599994330,"side":"Buy","size":11111,"price":0.0567},{"symbol":"DOGEUSDT","id":47599994338,"side":"Buy","size":333,"price":0.05662},{"symbol":"DOGEUSDT","id":47599994389,"side":"Buy","size":200,"price":0.05611},{"symbol":"DOGEUSDT","id":47599994391,"side":"Buy","size":11111,"price":0.05609},{"symbol":"DOGEUSDT","id":47599994690,"side":"Buy","size":600,"price":0.0531},{"symbol":"DOGEUSDT","id":47599994788,"side":"Buy","size":700,"price":0.05212},{"symbol":"DOGEUSDT","id":47599994800,"side":"Buy","size":2000,"price":0.052},{"symbol":"DOGEUSDT","id":47599994848,"side":"Buy","size":100,"price":0.05152},{"symbol":"DOGEUSDT","id":47599994971,"side":"Buy","size":5,"price":0.05029},{"symbol":"DOGEUSDT","id":47599995100,"side":"Buy","size":10,"price":0.049},{"symbol":"DOGEUSDT","id":47599995188,"side":"Buy","size":40,"price":0.04812},{"symbol":"DOGEUSDT","id":47599995500,"side":"Buy","size":600,"price":0.045},{"symbol":"DOGEUSDT","id":47599995558,"side":"Buy","size":8,"price":0.04442},{"symbol":"DOGEUSDT","id":47599995856,"side":"Buy","size":1000,"price":0.04144},{"symbol":"DOGEUSDT","id":47599995921,"side":"Buy","size":400,"price":0.04079},{"symbol":"DOGEUSDT","id":47599996112,"side":"Buy","size":1000,"price":0.03888},{"symbol":"DOGEUSDT","id":47599996136,"side":"Buy","size":50,"price":0.03864},{"symbol":"DOGEUSDT","id":47599996621,"side":"Buy","size":50,"price":0.03379},{"symbol":"DOGEUSDT","id":47599996667,"side":"Buy","size":5800,"price":0.03333},{"symbol":"DOGEUSDT","id":47599997711,"side":"Buy","size":230000,"price":0.02289},{"symbol":"DOGEUSDT","id":47599998900,"side":"Buy","size":300,"price":0.011},{"symbol":"DOGEUSDT","id":47599998999,"side":"Buy","size":19300,"price":0.01001},{"symbol":"DOGEUSDT","id":47599999000,"side":"Buy","size":2000,"price":0.01},{"symbol":"DOGEUSDT","id":47599999200,"side":"Buy","size":2014,"price":0.008},{"symbol":"DOGEUSDT","id":47599999367,"side":"Buy","size":4000,"price":0.00633},{"symbol":"DOGEUSDT","id":47599999489,"side":"Buy","size":30000,"price":0.00511},{"symbol":"DOGEUSDT","id":47599999711,"side":"Buy","size":230000,"price":0.00289},{"symbol":"DOGEUSDT","id":47599999998,"side":"Buy","size":2000000,"price":0.00002},{"symbol":"DOGEUSDT","id":47599999999,"side":"Buy","size":2700001,"price":0.00001}]}
1618677663.054085: {"table":"orderBookL2","action":"insert","data":[{"symbol":"EOSM21","id":52499998716,"side":"Sell","size":30,"price":0.0001284}]}
1618677663.0541499: {"table":"orderBookL2","action":"update","data":[{"symbol":"LTCUSD","id":40699968720,"side":"Buy","size":247}]}
1618677663.0541701: {"table":"orderBookL2","action":"delete","data":[{"symbol":"LTCUSD","id":40699968720,"side":"Buy"}]}
1618677663.054195: {"table":"orderBookL2","action":"delete","data":[{"symbol":"LTCUSD","id":40699968113,"side":"Sell"},{"symbol":"LTCUSD","id":40699968355,"side":"Sell"},{"symbol":"LTCUSD","id":40699968476,"side":"Sell"},{"symbol":"LTCUSD","id":40699968566,"side":"Sell"},{"symbol":"LTCUSD","id":40699969012,"side":"Buy"},{"symbol":"LTCUSD","id":40699969235,"side":"Buy"}]}
1618677663.05424: {"table":"orderBookL2","action":"update","data":[{"symbol":"LTCUSD","id":40699968117,"side":"Sell","size":2344},{"symbol":"LTCUSD","id":40699968600,"side":"Sell","size":582}]}
1618677663.054259: {"table":"orderBookL2","action":"insert","data":[{"symbol":"LTCUSD","id":40699968359,"side":"Sell","size":579,"price":316.41},{"symbol":"LTCUSD","id":40699968479,"side":"Sell","size":579,"price":315.21},{"symbol":"LTCUSD","id":40699969015,"side":"Buy","size":579,"price":309.85},{"symbol":"LTCUSD","id":40699969238,"side":"Buy","size":579,"price":307.62}]}
1618677663.054297: {"table":"orderBookL2","action":"insert","data":[{"symbol":"LTCUSD","id":40699968654,"side":"Sell","size":285,"price":313.46}]}
1618677663.054662: {"table":"orderBookL2","action":"update","data":[{"symbol":"LTCUSD","id":40699968905,"side":"Buy","size":200},{"symbol":"LTCUSD","id":40699968910,"side":"Buy","size":2389}]}
1618677663.054692: {"table":"orderBookL2","action":"delete","data":[{"symbol":"LTCUSD","id":40699968359,"side":"Sell"},{"symbol":"LTCUSD","id":40699968479,"side":"Sell"},{"symbol":"LTCUSD","id":40699969015,"side":"Buy"},{"symbol":"LTCUSD","id":40699969238,"side":"Buy"}]}
1618677663.05473: {"table":"orderBookL2","action":"update","data":[{"symbol":"LTCUSD","id":40699968117,"side":"Sell","size":1765},{"symbol":"LTCUSD","id":40699968477,"side":"Sell","size":2364},{"symbol":"LTCUSD","id":40699968600,"side":"Sell","size":3}]}
1618677663.054751: {"table":"orderBookL2","action":"insert","data":[{"symbol":"LTCUSD","id":40699968110,"side":"Sell","size":579,"price":318.9},{"symbol":"LTCUSD","id":40699968355,"side":"Sell","size":579,"price":316.45},{"symbol":"LTCUSD","id":40699968566,"side":"Sell","size":579,"price":314.34},{"symbol":"LTCUSD","id":40699969020,"side":"Buy","size":579,"price":309.8},{"symbol":"LTCUSD","id":40699969245,"side":"Buy","size":579,"price":307.55}]}
1618677663.054794: {"table":"orderBookL2","action":"delete","data":[{"symbol":"XLMUSDT","id":52199939138,"side":"Sell"}]}
1618677663.054817: {"table":"orderBookL2","action":"insert","data":[{"symbol":"XLMUSDT","id":52199939071,"side":"Sell","size":178,"price":0.60929}]}
1618677663.055451: {"table":"orderBookL2","action":"delete","data":[{"symbol":"DOGEUSDT","id":47599971772,"side":"Buy"}]}
1618677663.0554922: {"table":"orderBookL2","action":"insert","data":[{"symbol":"DOGEUSDT","id":47599971801,"side":"Buy","size":154,"price":0.28199}]}
1618677663.055522: {"table":"orderBookL2","action":"delete","data":[{"symbol":"XLMUSDT","id":52199939292,"side":"Buy"}]}
1618677663.055543: {"table":"orderBookL2","action":"insert","data":[{"symbol":"XLMUSDT","id":52199939382,"side":"Buy","size":53,"price":0.60618}]}
1618677663.055563: {"table":"orderBookL2","action":"delete","data":[{"symbol":"DOGEUSDT","id":47599971809,"side":"Buy"}]}
1618677663.05558: {"table":"orderBookL2","action":"insert","data":[{"symbol":"DOGEUSDT","id":47599972356,"side":"Buy","size":359,"price":0.27644}]}
1618677663.0555992: {"table":"orderBookL2","action":"delete","data":[{"symbol":"LTCUSD","id":40699968782,"side":"Buy"}]}
1618677663.055616: {"table":"orderBookL2","action":"delete","data":[{"symbol":"TRXUSDT","id":53999980026,"side":"Sell"}]}
1618677663.055634: {"table":"orderBookL2","action":"update","data":[{"symbol":"TRXUSDT","id":53999980000,"side":"Sell","size":4210}]}
1618677663.058293: {"table":"orderBookL2","action":"delete","data":[{"symbol":"LTCUSD","id":40699968110,"side":"Sell"},{"symbol":"LTCUSD","id":40699968355,"side":"Sell"},{"symbol":"LTCUSD","id":40699968566,"side":"Sell"},{"symbol":"LTCUSD","id":40699969020,"side":"Buy"},{"symbol":"LTCUSD","id":40699969245,"side":"Buy"}]}
1618677663.058382: {"table":"orderBookL2","action":"update","data":[{"symbol":"LTCUSD","id":40699968477,"side":"Sell","size":1785},{"symbol":"LTCUSD","id":40699968601,"side":"Sell","size":826}]}
1618677663.05841: {"table":"orderBookL2","action":"insert","data":[{"symbol":"LTCUSD","id":40699968111,"side":"Sell","size":579,"price":318.89},{"symbol":"LTCUSD","id":40699968356,"side":"Sell","size":579,"price":316.44},{"symbol":"LTCUSD","id":40699968479,"side":"Sell","size":579,"price":315.21},{"symbol":"LTCUSD","id":40699969022,"side":"Buy","size":579,"price":309.78},{"symbol":"LTCUSD","id":40699969248,"side":"Buy","size":579,"price":307.52}]}
1618677663.058462: {"table":"orderBookL2","action":"delete","data":[{"symbol":"XLMUSDT","id":52199939351,"side":"Buy"}]}
1618677663.0702488: {"table":"orderBookL2","action":"insert","data":[{"symbol":"DOGEUSDT","id":47599971483,"side":"Sell","size":348,"price":0.28517}]}
1618677663.070409: {"table":"orderBookL2","action":"insert","data":[{"symbol":"LTCUSD","id":40699968794,"side":"Buy","size":106,"price":312.06}]}
1618677663.070482: {"table":"orderBookL2","action":"delete","data":[{"symbol":"LTCUSD","id":40699968111,"side":"Sell"},{"symbol":"LTCUSD","id":40699968356,"side":"Sell"},{"symbol":"LTCUSD","id":40699968479,"side":"Sell"},{"symbol":"LTCUSD","id":40699969022,"side":"Buy"},{"symbol":"LTCUSD","id":40699969248,"side":"Buy"}]}
1618677663.070549: {"table":"orderBookL2","action":"update","data":[{"symbol":"LTCUSD","id":40699968601,"side":"Sell","size":247},{"symbol":"LTCUSD","id":40699968602,"side":"Sell","size":755}]}
1618677663.0705762: {"table":"orderBookL2","action":"insert","data":[{"symbol":"LTCUSD","id":40699968116,"side":"Sell","size":579,"price":318.84},{"symbol":"LTCUSD","id":40699968359,"side":"Sell","size":579,"price":316.41},{"symbol":"LTCUSD","id":40699968481,"side":"Sell","size":579,"price":315.19},{"symbol":"LTCUSD","id":40699969020,"side":"Buy","size":579,"price":309.8},{"symbol":"LTCUSD","id":40699969244,"side":"Buy","size":579,"price":307.56}]}
1618677663.0706391: {"table":"orderBookL2","action":"insert","data":[{"symbol":"LTCUSD","id":40699968726,"side":"Buy","size":236,"price":312.74}]}
1618677663.070666: {"table":"orderBookL2","action":"update","data":[{"symbol":"XLMUSDT","id":52199939382,"side":"Buy","size":165}]}
1618677663.070687: {"table":"orderBookL2","action":"delete","data":[{"symbol":"XLMUSDT","id":52199939070,"side":"Sell"}]}
1618677663.070714: {"table":"orderBookL2","action":"insert","data":[{"symbol":"XLMUSDT","id":52199939090,"side":"Sell","size":232,"price":0.6091}]}
1618677663.139935: {"table":"orderBookL2","action":"delete","data":[{"symbol":"LTCUSD","id":40699968116,"side":"Sell"},{"symbol":"LTCUSD","id":40699968359,"side":"Sell"},{"symbol":"LTCUSD","id":40699968481,"side":"Sell"},{"symbol":"LTCUSD","id":40699969020,"side":"Buy"}]}
1618677663.140016: {"table":"orderBookL2","action":"update","data":[{"symbol":"LTCUSD","id":40699968477,"side":"Sell","size":2364},{"symbol":"LTCUSD","id":40699968602,"side":"Sell","size":176}]}
1618677663.140047: {"table":"orderBookL2","action":"insert","data":[{"symbol":"LTCUSD","id":40699968111,"side":"Sell","size":579,"price":318.89},{"symbol":"LTCUSD","id":40699968355,"side":"Sell","size":579,"price":316.45},{"symbol":"LTCUSD","id":40699968566,"side":"Sell","size":579,"price":314.34},{"symbol":"LTCUSD","id":40699969019,"side":"Buy","size":579,"price":309.81}]}
1618677663.1432462: {"table":"orderBookL2","action":"update","data":[{"symbol":"EOSM21","id":52499998733,"side":"Buy","size":1200}]}
1618677663.1433442: {"table":"orderBookL2","action":"update","data":[{"symbol":"LTCM21","id":52899998942,"side":"Sell","size":205}]}
1618677663.2034361: {"table":"orderBookL2","action":"delete","data":[{"symbol":"LTCUSD","id":40699968111,"side":"Sell"},{"symbol":"LTCUSD","id":40699968355,"side":"Sell"},{"symbol":"LTCUSD","id":40699968566,"side":"Sell"},{"symbol":"LTCUSD","id":40699969244,"side":"Buy"}]}
1618677663.203598: {"table":"orderBookL2","action":"update","data":[{"symbol":"LTCUSD","id":40699968357,"side":"Sell","size":2357},{"symbol":"LTCUSD","id":40699968477,"side":"Sell","size":1785},{"symbol":"LTCUSD","id":40699968601,"side":"Sell","size":826}]}
1618677663.203661: {"table":"orderBookL2","action":"insert","data":[{"symbol":"LTCUSD","id":40699968114,"side":"Sell","size":579,"price":318.86},{"symbol":"LTCUSD","id":40699968479,"side":"Sell","size":579,"price":315.21},{"symbol":"LTCUSD","id":40699969243,"side":"Buy","size":579,"price":307.57}]}
1618677663.21616: {"table":"orderBookL2","action":"update","data":[{"symbol":"LTCUSD","id":40699968727,"side":"Buy","size":603}]}
1618677663.242912: {"table":"orderBookL2","action":"delete","data":[{"symbol":"EOSM21","id":52499998733,"side":"Buy"}]}
1618677663.2481: {"table":"orderBookL2","action":"update","data":[{"symbol":"TRXUSDT","id":53999983983,"side":"Buy","size":359}]}
1618677663.253655: {"table":"orderBookL2","action":"delete","data":[{"symbol":"TRXUSDT","id":53999984000,"side":"Buy"}]}
1618677663.254216: {"table":"orderBookL2","action":"insert","data":[{"symbol":"TRXUSDT","id":53999984018,"side":"Buy","size":427,"price":0.15982}]}
1618677663.2542799: {"table":"orderBookL2","action":"update","data":[{"symbol":"EOSM21","id":52499998731,"side":"Sell","size":974}]}
1618677663.258293: {"table":"orderBookL2","action":"insert","data":[{"symbol":"EOSM21","id":52499998733,"side":"Sell","size":330,"price":0.0001267}]}
1618677663.258448: {"table":"orderBookL2","action":"insert","data":[{"symbol":"XLMUSDT","id":52199939414,"side":"Buy","size":48,"price":0.60586}]}
1618677663.258728: {"table":"orderBookL2","action":"update","data":[{"symbol":"EOSM21","id":52499998732,"side":"Sell","size":322}]}
1618677663.262639: {"table":"orderBookL2","action":"delete","data":[{"symbol":"TRXUSDT","id":53999983983,"side":"Buy"}]}
1618677663.2627919: {"table":"orderBookL2","action":"update","data":[{"symbol":"XLMUSDT","id":52199939382,"side":"Buy","size":112}]}
1618677663.26308: {"table":"orderBookL2","action":"insert","data":[{"symbol":"TRXUSDT","id":53999984025,"side":"Buy","size":344,"price":0.15975}]}
1618677663.263842: {"table":"orderBookL2","action":"insert","data":[{"symbol":"TRXUSDT","id":53999984000,"side":"Buy","size":2500,"price":0.16}]}
1618677663.2753952: {"table":"orderBookL2","action":"insert","data":[{"symbol":"EOSUSDT","id":53899984158,"side":"Buy","size":60,"price":7.921}]}
1618677663.275485: {"table":"orderBookL2","action":"update","data":[{"symbol":"EOSM21","id":52499998734,"side":"Buy","size":2110}]}
1618677663.277497: {"table":"orderBookL2","action":"delete","data":[{"symbol":"EOSUSDT","id":53899984151,"side":"Buy"}]}
1618677663.27758: {"table":"orderBookL2","action":"update","data":[{"symbol":"TRXUSDT","id":53999983906,"side":"Sell","size":1006}]}
1618677663.2776132: {"table":"orderBookL2","action":"update","data":[{"symbol":"EOSUSDT","id":53899984141,"side":"Buy","size":1000}]}
1618677663.278102: {"table":"orderBookL2","action":"delete","data":[{"symbol":"TRXUSDT","id":53999984025,"side":"Buy"}]}
1618677663.2929149: {"table":"orderBookL2","action":"delete","data":[{"symbol":"TRXUSDT","id":53999984018,"side":"Buy"}]}
1618677663.3026319: {"table":"orderBookL2","action":"delete","data":[{"symbol":"EOSUSDT","id":53899984141,"side":"Buy"}]}
1618677663.313854: {"table":"orderBookL2","action":"insert","data":[{"symbol":"EOSUSDT","id":53899984151,"side":"Buy","size":1000,"price":7.9245}]}
1618677663.3938391: {"table":"orderBookL2","action":"insert","data":[{"symbol":"DOGEUSDT","id":47599971468,"side":"Sell","size":301,"price":0.28532},{"symbol":"DOGEUSDT","id":47599971559,"side":"Buy","size":4000,"price":0.28441}]}
1618677663.4313889: {"table":"orderBookL2","action":"delete","data":[{"symbol":"LTCUSD","id":40699968114,"side":"Sell"},{"symbol":"LTCUSD","id":40699968479,"side":"Sell"},{"symbol":"LTCUSD","id":40699969019,"side":"Buy"},{"symbol":"LTCUSD","id":40699969243,"side":"Buy"}]}
1618677663.431544: {"table":"orderBookL2","action":"update","data":[{"symbol":"LTCUSD","id":40699968357,"side":"Sell","size":1778}]}
1618677663.431593: {"table":"orderBookL2","action":"insert","data":[{"symbol":"LTCUSD","id":40699968119,"side":"Sell","size":579,"price":318.81},{"symbol":"LTCUSD","id":40699968360,"side":"Sell","size":579,"price":316.4},{"symbol":"LTCUSD","id":40699968481,"side":"Sell","size":579,"price":315.19},{"symbol":"LTCUSD","id":40699969016,"side":"Buy","size":579,"price":309.84},{"symbol":"LTCUSD","id":40699969239,"side":"Buy","size":579,"price":307.61}]}
1618677663.444166: {"table":"orderBookL2","action":"update","data":[{"symbol":"LTCUSD","id":40699968650,"side":"Sell","size":154}]}
1618677663.444264: {"table":"orderBookL2","action":"insert","data":[{"symbol":"LTCUSD","id":40699968655,"side":"Sell","size":236,"price":313.45}]}
1618677663.462303: {"table":"orderBookL2","action":"delete","data":[{"symbol":"LTCUSD","id":40699968119,"side":"Sell"},{"symbol":"LTCUSD","id":40699968481,"side":"Sell"},{"symbol":"LTCUSD","id":40699969239,"side":"Buy"}]}
1618677663.4624488: {"table":"orderBookL2","action":"insert","data":[{"symbol":"LTCUSD","id":40699968114,"side":"Sell","size":579,"price":318.86},{"symbol":"LTCUSD","id":40699968479,"side":"Sell","size":579,"price":315.21},{"symbol":"LTCUSD","id":40699969243,"side":"Buy","size":579,"price":307.57}]}
1618677663.46443: {"table":"orderBookL2","action":"delete","data":[{"symbol":"DOGEUSDT","id":47599971483,"side":"Sell"}]}
1618677663.464549: {"table":"orderBookL2","action":"delete","data":[{"symbol":"LTCUSD","id":40699968360,"side":"Sell"},{"symbol":"LTCUSD","id":40699969016,"side":"Buy"}]}
1618677663.464958: {"table":"orderBookL2","action":"insert","data":[{"symbol":"LTCUSD","id":40699968361,"side":"Sell","size":579,"price":316.39},{"symbol":"LTCUSD","id":40699969017,"side":"Buy","size":579,"price":309.83}]}
1618677663.492521: {"table":"orderBookL2","action":"update","data":[{"symbol":"ADAM21","id":52299997835,"side":"Buy","size":24359}]}
1618677663.5459661: {"table":"orderBookL2","action":"delete","data":[{"symbol":"DOGEUSDT","id":47599971468,"side":"Sell"}]}
1618677663.563968: {"table":"orderBookL2","action":"insert","data":[{"symbol":"TRXUSDT","id":53999984024,"side":"Buy","size":545,"price":0.15976}]}
1618677663.5668328: {"table":"orderBookL2","action":"insert","data":[{"symbol":"XLMUSDT","id":52199939365,"side":"Buy","size":55,"price":0.60635}]}
1618677663.5715442: {"table":"orderBookL2","action":"delete","data":[{"symbol":"DOGEUSDT","id":47599971559,"side":"Buy"}]}
1618677663.595947: {"table":"orderBookL2","action":"delete","data":[{"symbol":"LTCUSD","id":40699968114,"side":"Sell"},{"symbol":"LTCUSD","id":40699968361,"side":"Sell"},{"symbol":"LTCUSD","id":40699968479,"side":"Sell"},{"symbol":"LTCUSD","id":40699969017,"side":"Buy"}]}
1618677663.5960598: {"table":"orderBookL2","action":"update","data":[{"symbol":"LTCUSD","id":40699968480,"side":"Sell","size":776},{"symbol":"LTCUSD","id":40699968905,"side":"Buy","size":779},{"symbol":"LTCUSD","id":40699968910,"side":"Buy","size":1810}]}
1618677663.596101: {"table":"orderBookL2","action":"insert","data":[{"symbol":"LTCUSD","id":40699968118,"side":"Sell","size":579,"price":318.82},{"symbol":"LTCUSD","id":40699968360,"side":"Sell","size":579,"price":316.4},{"symbol":"LTCUSD","id":40699969016,"side":"Buy","size":579,"price":309.84}]}
1618677663.6067798: {"table":"orderBookL2","action":"delete","data":[{"symbol":"DOGEUSDT","id":47599971869,"side":"Buy"}]}
1618677663.6069: {"table":"orderBookL2","action":"insert","data":[{"symbol":"DOGEUSDT","id":47599971818,"side":"Buy","size":176,"price":0.28182}]}
1618677663.622905: {"table":"orderBookL2","action":"insert","data":[{"symbol":"DOGEUSDT","id":47599971674,"side":"Buy","size":350,"price":0.28326}]}
1618677663.653856: {"table":"orderBookL2","action":"insert","data":[{"symbol":"ADAM21","id":52299997831,"side":"Sell","size":4300,"price":0.00002169}]}
1618677663.667964: {"table":"orderBookL2","action":"update","data":[{"symbol":"ADAM21","id":52299997830,"side":"Sell","size":38968}]}
1618677663.7118971: {"table":"orderBookL2","action":"delete","data":[{"symbol":"LTCUSD","id":40699968118,"side":"Sell"},{"symbol":"LTCUSD","id":40699968360,"side":"Sell"},{"symbol":"LTCUSD","id":40699969016,"side":"Buy"}]}
1618677663.712042: {"table":"orderBookL2","action":"update","data":[{"symbol":"LTCUSD","id":40699968357,"side":"Sell","size":2357},{"symbol":"LTCUSD","id":40699968480,"side":"Sell","size":197},{"symbol":"LTCUSD","id":40699968905,"side":"Buy","size":200},{"symbol":"LTCUSD","id":40699968910,"side":"Buy","size":2389}]}
1618677663.712109: {"table":"orderBookL2","action":"insert","data":[{"symbol":"LTCUSD","id":40699968114,"side":"Sell","size":579,"price":318.86},{"symbol":"LTCUSD","id":40699968479,"side":"Sell","size":579,"price":315.21},{"symbol":"LTCUSD","id":40699969019,"side":"Buy","size":579,"price":309.81}]}
1618677663.7353961: {"table":"orderBookL2","action":"delete","data":[{"symbol":"LTCUSD","id":40699968114,"side":"Sell"},{"symbol":"LTCUSD","id":40699968479,"side":"Sell"},{"symbol":"LTCUSD","id":40699969019,"side":"Buy"},{"symbol":"LTCUSD","id":40699969243,"side":"Buy"}]}
1618677663.7355509: {"table":"orderBookL2","action":"update","data":[{"symbol":"LTCUSD","id":40699968357,"side":"Sell","size":1778},{"symbol":"LTCUSD","id":40699968905,"side":"Buy","size":779},{"symbol":"LTCUSD","id":40699968910,"side":"Buy","size":1810}]}
1618677663.735612: {"table":"orderBookL2","action":"insert","data":[{"symbol":"LTCUSD","id":40699968119,"side":"Sell","size":579,"price":318.81},{"symbol":"LTCUSD","id":40699968360,"side":"Sell","size":579,"price":316.4},{"symbol":"LTCUSD","id":40699968481,"side":"Sell","size":579,"price":315.19},{"symbol":"LTCUSD","id":40699969015,"side":"Buy","size":579,"price":309.85},{"symbol":"LTCUSD","id":40699969238,"side":"Buy","size":579,"price":307.62}]}
1618677663.747117: {"table":"orderBookL2","action":"delete","data":[{"symbol":"ADAM21","id":52299997817,"side":"Sell"}]}
1618677663.747232: {"table":"orderBookL2","action":"update","data":[{"symbol":"ADAM21","id":52299997829,"side":"Sell","size":35536}]}
1618677663.7513149: {"table":"orderBookL2","action":"delete","data":[{"symbol":"DOGEUSDT","id":47599971801,"side":"Buy"}]}
1618677663.751434: {"table":"orderBookL2","action":"insert","data":[{"symbol":"DOGEUSDT","id":47599971777,"side":"Buy","size":154,"price":0.28223}]}
1618677663.8223119: {"table":"orderBookL2","action":"delete","data":[{"symbol":"LTCUSD","id":40699968119,"side":"Sell"},{"symbol":"LTCUSD","id":40699968360,"side":"Sell"},{"symbol":"LTCUSD","id":40699968481,"side":"Sell"},{"symbol":"LTCUSD","id":40699969015,"side":"Buy"},{"symbol":"LTCUSD","id":40699969238,"side":"Buy"}]}
1618677663.822433: {"table":"orderBookL2","action":"update","data":[{"symbol":"LTCUSD","id":40699968357,"side":"Sell","size":2357},{"symbol":"LTCUSD","id":40699968600,"side":"Sell","size":582},{"symbol":"LTCUSD","id":40699968601,"side":"Sell","size":247},{"symbol":"LTCUSD","id":40699968905,"side":"Buy","size":200},{"symbol":"LTCUSD","id":40699968910,"side":"Buy","size":2389}]}
1618677663.822483: {"table":"orderBookL2","action":"insert","data":[{"symbol":"LTCUSD","id":40699968113,"side":"Sell","size":579,"price":318.87},{"symbol":"LTCUSD","id":40699968479,"side":"Sell","size":579,"price":315.21},{"symbol":"LTCUSD","id":40699969018,"side":"Buy","size":579,"price":309.82},{"symbol":"LTCUSD","id":40699969243,"side":"Buy","size":579,"price":307.57}]}
1618677663.855391: {"table":"orderBookL2","action":"update","data":[{"symbol":"EOSM21","id":52499998732,"side":"Sell","size":878}]}
1618677663.8589902: {"table":"orderBookL2","action":"delete","data":[{"symbol":"LTCUSD","id":40699968718,"side":"Buy"}]}
1618677663.8771431: {"table":"orderBookL2","action":"update","data":[{"symbol":"LTCUSD","id":40699968600,"side":"Sell","size":3},{"symbol":"LTCUSD","id":40699968603,"side":"Sell","size":596}]}
1618677663.958394: {"table":"orderBookL2","action":"insert","data":[{"symbol":"LTCUSD","id":40699968661,"side":"Sell","size":452,"price":313.39}]}
1618677663.9722009: {"table":"orderBookL2","action":"delete","data":[{"symbol":"LTCUSD","id":40699968660,"side":"Sell"}]}
1618677663.97232: {"table":"orderBookL2","action":"insert","data":[{"symbol":"LTCUSD","id":40699968662,"side":"Sell","size":125,"price":313.38}]}
1618677663.987984: {"table":"orderBookL2","action":"delete","data":[{"symbol":"LTCUSD","id":40699968661,"side":"Sell"}]}
1618677663.988101: {"table":"orderBookL2","action":"insert","data":[{"symbol":"LTCUSD","id":40699968658,"side":"Sell","size":452,"price":313.42}]}
1618677664.0029619: {"table":"orderBookL2","action":"delete","data":[{"symbol":"LTCUSD","id":40699968658,"side":"Sell"}]}
1618677664.003078: {"table":"orderBookL2","action":"insert","data":[{"symbol":"LTCUSD","id":40699968663,"side":"Sell","size":452,"price":313.37}]}
1618677664.024137: {"table":"orderBookL2","action":"delete","data":[{"symbol":"EOSUSDT","id":53899984015,"side":"Sell"}]}
1618677664.024252: {"table":"orderBookL2","action":"insert","data":[{"symbol":"EOSUSDT","id":53899984036,"side":"Sell","size":496,"price":7.982}]}
1618677664.060363: {"table":"orderBookL2","action":"delete","data":[{"symbol":"LTCUSD","id":40699968113,"side":"Sell"},{"symbol":"LTCUSD","id":40699968479,"side":"Sell"},{"symbol":"LTCUSD","id":40699969018,"side":"Buy"},{"symbol":"LTCUSD","id":40699969243,"side":"Buy"}]}
1618677664.060524: {"table":"orderBookL2","action":"update","data":[{"symbol":"LTCUSD","id":40699968357,"side":"Sell","size":1778},{"symbol":"LTCUSD","id":40699968480,"side":"Sell","size":776},{"symbol":"LTCUSD","id":40699968602,"side":"Sell","size":755},{"symbol":"LTCUSD","id":40699968603,"side":"Sell","size":17}]}
1618677664.060589: {"table":"orderBookL2","action":"insert","data":[{"symbol":"LTCUSD","id":40699968115,"side":"Sell","size":579,"price":318.85},{"symbol":"LTCUSD","id":40699968358,"side":"Sell","size":579,"price":316.42},{"symbol":"LTCUSD","id":40699969021,"side":"Buy","size":579,"price":309.79},{"symbol":"LTCUSD","id":40699969245,"side":"Buy","size":579,"price":307.55}]}
1618677664.093482: {"table":"orderBookL2","action":"delete","data":[{"symbol":"LTCUSD","id":40699968115,"side":"Sell"},{"symbol":"LTCUSD","id":40699968358,"side":"Sell"},{"symbol":"LTCUSD","id":40699969021,"side":"Buy"}]}
1618677664.093641: {"table":"orderBookL2","action":"update","data":[{"symbol":"LTCUSD","id":40699968480,"side":"Sell","size":197},{"symbol":"LTCUSD","id":40699968905,"side":"Buy","size":779},{"symbol":"LTCUSD","id":40699968910,"side":"Buy","size":1810}]}
1618677664.0937011: {"table":"orderBookL2","action":"insert","data":[{"symbol":"LTCUSD","id":40699968119,"side":"Sell","size":579,"price":318.81},{"symbol":"LTCUSD","id":40699968360,"side":"Sell","size":579,"price":316.4},{"symbol":"LTCUSD","id":40699968481,"side":"Sell","size":579,"price":315.19},{"symbol":"LTCUSD","id":40699969016,"side":"Buy","size":579,"price":309.84}]}
1618677664.096538: {"table":"orderBookL2","action":"delete","data":[{"symbol":"LTCUSD","id":40699968635,"side":"Sell"}]}
1618677664.0966232: {"table":"orderBookL2","action":"update","data":[{"symbol":"LTCUSD","id":40699968646,"side":"Sell","size":903}]}
1618677664.1214101: {"table":"orderBookL2","action":"update","data":[{"symbol":"ADAM21","id":52299997829,"side":"Sell","size":38544}]}
1618677664.177664: {"table":"orderBookL2","action":"delete","data":[{"symbol":"XLMUSDT","id":52199939071,"side":"Sell"}]}
1618677664.1777458: {"table":"orderBookL2","action":"insert","data":[{"symbol":"XLMUSDT","id":52199939138,"side":"Sell","size":178,"price":0.60862}]}
1618677664.179373: {"table":"orderBookL2","action":"insert","data":[{"symbol":"ADAM21","id":52299997832,"side":"Buy","size":200,"price":0.00002168}]}
1618677664.1829739: {"table":"orderBookL2","action":"delete","data":[{"symbol":"EOSUSDT","id":53899984036,"side":"Sell"},{"symbol":"EOSUSDT","id":53899984162,"side":"Buy"}]}
1618677664.1830678: {"table":"orderBookL2","action":"update","data":[{"symbol":"EOSUSDT","id":53899984140,"side":"Buy","size":171}]}
1618677664.183103: {"table":"orderBookL2","action":"insert","data":[{"symbol":"EOSUSDT","id":53899984017,"side":"Sell","size":496,"price":7.9915},{"symbol":"EOSUSDT","id":53899984157,"side":"Buy","size":496,"price":7.9215},{"symbol":"EOSUSDT","id":53899984185,"side":"Buy","size":1610,"price":7.9075}]}
1618677664.194317: {"table":"orderBookL2","action":"insert","data":[{"symbol":"XLMUSDT","id":52199939120,"side":"Sell","size":63,"price":0.6088}]}
1618677664.204174: {"table":"orderBookL2","action":"delete","data":[{"symbol":"XLMUSDT","id":52199939365,"side":"Buy"}]}
1618677664.227521: {"table":"orderBookL2","action":"update","data":[{"symbol":"EOSM21","id":52499998743,"side":"Buy","size":6}]}
1618677664.2276192: {"table":"orderBookL2","action":"insert","data":[{"symbol":"EOSM21","id":52499998747,"side":"Buy","size":979,"price":0.0001253}]}
1618677664.456515: {"table":"orderBookL2","action":"update","data":[{"symbol":"LTCUSD","id":40699968646,"side":"Sell","size":685}]}
1618677664.474119: {"table":"orderBookL2","action":"delete","data":[{"symbol":"LTCUSD","id":40699968119,"side":"Sell"},{"symbol":"LTCUSD","id":40699968360,"side":"Sell"},{"symbol":"LTCUSD","id":40699968481,"side":"Sell"},{"symbol":"LTCUSD","id":40699969016,"side":"Buy"},{"symbol":"LTCUSD","id":40699969245,"side":"Buy"}]}
1618677664.4742851: {"table":"orderBookL2","action":"update","data":[{"symbol":"LTCUSD","id":40699968117,"side":"Sell","size":2344},{"symbol":"LTCUSD","id":40699968480,"side":"Sell","size":776},{"symbol":"LTCUSD","id":40699968601,"side":"Sell","size":826},{"symbol":"LTCUSD","id":40699968602,"side":"Sell","size":176},{"symbol":"LTCUSD","id":40699968905,"side":"Buy","size":200},{"symbol":"LTCUSD","id":40699968910,"side":"Buy","size":2389}]}
1618677664.475769: {"table":"orderBookL2","action":"insert","data":[{"symbol":"LTCUSD","id":40699968359,"side":"Sell","size":579,"price":316.41},{"symbol":"LTCUSD","id":40699969017,"side":"Buy","size":579,"price":309.83},{"symbol":"LTCUSD","id":40699969241,"side":"Buy","size":579,"price":307.59}]}
1618677664.529783: {"table":"orderBookL2","action":"insert","data":[{"symbol":"XLMUSDT","id":52199939094,"side":"Sell","size":58,"price":0.60906}]}
1618677664.532356: {"table":"orderBookL2","action":"delete","data":[{"symbol":"XLMUSDT","id":52199939120,"side":"Sell"}]}
1618677664.5324721: {"table":"orderBookL2","action":"insert","data":[{"symbol":"TRXUSDT","id":53999984012,"side":"Buy","size":430,"price":0.15988}]}
1618677664.540902: {"table":"orderBookL2","action":"delete","data":[{"symbol":"LTCUSD","id":40699968359,"side":"Sell"},{"symbol":"LTCUSD","id":40699969017,"side":"Buy"},{"symbol":"LTCUSD","id":40699969241,"side":"Buy"}]}
1618677664.541047: {"table":"orderBookL2","action":"update","data":[{"symbol":"LTCUSD","id":40699968117,"side":"Sell","size":1765},{"symbol":"LTCUSD","id":40699968480,"side":"Sell","size":197}]}
1618677664.541104: {"table":"orderBookL2","action":"insert","data":[{"symbol":"LTCUSD","id":40699968114,"side":"Sell","size":579,"price":318.86},{"symbol":"LTCUSD","id":40699968358,"side":"Sell","size":579,"price":316.42},{"symbol":"LTCUSD","id":40699968479,"side":"Sell","size":579,"price":315.21},{"symbol":"LTCUSD","id":40699969019,"side":"Buy","size":579,"price":309.81},{"symbol":"LTCUSD","id":40699969243,"side":"Buy","size":579,"price":307.57}]}
1618677664.615762: {"table":"orderBookL2","action":"delete","data":[{"symbol":"LTCUSD","id":40699968114,"side":"Sell"},{"symbol":"LTCUSD","id":40699968358,"side":"Sell"},{"symbol":"LTCUSD","id":40699968479,"side":"Sell"},{"symbol":"LTCUSD","id":40699969019,"side":"Buy"},{"symbol":"LTCUSD","id":40699969243,"side":"Buy"}]}
1618677664.615935: {"table":"orderBookL2","action":"update","data":[{"symbol":"LTCUSD","id":40699968601,"side":"Sell","size":247},{"symbol":"LTCUSD","id":40699968602,"side":"Sell","size":755}]}
1618677664.615992: {"table":"orderBookL2","action":"insert","data":[{"symbol":"LTCUSD","id":40699968120,"side":"Sell","size":579,"price":318.8},{"symbol":"LTCUSD","id":40699968361,"side":"Sell","size":579,"price":316.39},{"symbol":"LTCUSD","id":40699968482,"side":"Sell","size":579,"price":315.18},{"symbol":"LTCUSD","id":40699969016,"side":"Buy","size":579,"price":309.84},{"symbol":"LTCUSD","id":40699969239,"side":"Buy","size":579,"price":307.61}]}
1618677664.670092: {"table":"orderBookL2","action":"insert","data":[{"symbol":"LTCUSD","id":40699968641,"side":"Sell","size":218,"price":313.59}]}
1618677664.7065222: {"table":"orderBookL2","action":"delete","data":[{"symbol":"LTCUSD","id":40699968482,"side":"Sell"}]}
1618677664.7066371: {"table":"orderBookL2","action":"update","data":[{"symbol":"LTCUSD","id":40699968601,"side":"Sell","size":826},{"symbol":"LTCUSD","id":40699968602,"side":"Sell","size":176}]}
1618677664.7066948: {"table":"orderBookL2","action":"insert","data":[{"symbol":"LTCUSD","id":40699968479,"side":"Sell","size":579,"price":315.21}]}
1618677664.708122: {"table":"orderBookL2","action":"delete","data":[{"symbol":"LTCUSD","id":40699968655,"side":"Sell"}]}
1618677664.728487: {"table":"orderBookL2","action":"update","data":[{"symbol":"LTCUSD","id":40699968650,"side":"Sell","size":390}]}
1618677664.8535428: {"table":"orderBookL2","action":"update","data":[{"symbol":"EOSM21","id":52499998732,"side":"Sell","size":322}]}
1618677664.855128: {"table":"orderBookL2","action":"update","data":[{"symbol":"EOSM21","id":52499998730,"side":"Sell","size":826}]}
1618677664.868258: {"table":"orderBookL2","action":"delete","data":[{"symbol":"EOSM21","id":52499998733,"side":"Sell"}]}
1618677664.868373: {"table":"orderBookL2","action":"delete","data":[{"symbol":"XLMUSDT","id":52199939382,"side":"Buy"}]}
1618677664.868428: {"table":"orderBookL2","action":"insert","data":[{"symbol":"XLMUSDT","id":52199939362,"side":"Buy","size":112,"price":0.60638}]}
1618677664.879893: {"table":"orderBookL2","action":"update","data":[{"symbol":"LTCUSD","id":40699968721,"side":"Buy","size":5247},{"symbol":"LTCUSD","id":40699968727,"side":"Buy","size":356}]}
1618677664.882459: {"table":"orderBookL2","action":"insert","data":[{"symbol":"EOSM21","id":52499998733,"side":"Buy","size":330,"price":0.0001267}]}
1618677664.882586: {"table":"orderBookL2","action":"update","data":[{"symbol":"EOSM21","id":52499998734,"side":"Buy","size":1780}]}
1618677664.8826392: {"table":"orderBookL2","action":"update","data":[{"symbol":"EOSM21","id":52499998731,"side":"Sell","size":322}]}
1618677664.886613: {"table":"orderBookL2","action":"delete","data":[{"symbol":"XLMUSDT","id":52199939094,"side":"Sell"}]}
1618677664.894468: {"table":"orderBookL2","action":"insert","data":[{"symbol":"EOSUSDT","id":53899984146,"side":"Buy","size":67,"price":7.927}]}
1618677664.894599: {"table":"orderBookL2","action":"update","data":[{"symbol":"EOSM21","id":52499998732,"side":"Sell","size":652}]}
1618677664.9569979: {"table":"orderBookL2","action":"delete","data":[{"symbol":"LTCUSD","id":40699968641,"side":"Sell"}]}
1618677664.972922: {"table":"orderBookL2","action":"insert","data":[{"symbol":"LTCUSD","id":40699968664,"side":"Sell","size":14,"price":313.36}]}
1618677664.985728: {"table":"orderBookL2","action":"delete","data":[{"symbol":"LTCUSD","id":40699968654,"side":"Sell"}]}
1618677664.9862468: {"table":"orderBookL2","action":"delete","data":[{"symbol":"LTCUSD","id":40699968663,"side":"Sell"}]}
1618677664.9889321: {"table":"orderBookL2","action":"insert","data":[{"symbol":"LTCUSD","id":40699968718,"side":"Buy","size":48,"price":312.82}]}
1618677665.25823: {"table":"orderBookL2","action":"update","data":[{"symbol":"TRXUSDT","id":53999984000,"side":"Buy","size":3003}]}
1618677665.278559: {"table":"orderBookL2","action":"update","data":[{"symbol":"LTCM21","id":52899998942,"side":"Sell","size":63}]}
1618677665.291467: {"table":"orderBookL2","action":"delete","data":[{"symbol":"LTCUSD","id":40699968120,"side":"Sell"},{"symbol":"LTCUSD","id":40699968361,"side":"Sell"},{"symbol":"LTCUSD","id":40699968479,"side":"Sell"},{"symbol":"LTCUSD","id":40699969016,"side":"Buy"},{"symbol":"LTCUSD","id":40699969239,"side":"Buy"}]}
1618677665.2916322: {"table":"orderBookL2","action":"update","data":[{"symbol":"LTCUSD","id":40699968477,"side":"Sell","size":2364},{"symbol":"LTCUSD","id":40699968601,"side":"Sell","size":247},{"symbol":"LTCUSD","id":40699968905,"side":"Buy","size":779},{"symbol":"LTCUSD","id":40699968910,"side":"Buy","size":1810}]}
1618677665.2917: {"table":"orderBookL2","action":"insert","data":[{"symbol":"LTCUSD","id":40699968115,"side":"Sell","size":579,"price":318.85},{"symbol":"LTCUSD","id":40699968356,"side":"Sell","size":579,"price":316.44},{"symbol":"LTCUSD","id":40699968566,"side":"Sell","size":579,"price":314.34},{"symbol":"LTCUSD","id":40699969012,"side":"Buy","size":579,"price":309.88},{"symbol":"LTCUSD","id":40699969234,"side":"Buy","size":579,"price":307.66}]}
1618677665.307447: {"table":"orderBookL2","action":"delete","data":[{"symbol":"LTCUSD","id":40699968726,"side":"Buy"}]}
1618677665.3075688: {"table":"orderBookL2","action":"insert","data":[{"symbol":"LTCUSD","id":40699968720,"side":"Buy","size":236,"price":312.8}]}
1618677665.375015: {"table":"orderBookL2","action":"delete","data":[{"symbol":"LTCUSD","id":40699968115,"side":"Sell"}]}
1618677665.375136: {"table":"orderBookL2","action":"insert","data":[{"symbol":"LTCUSD","id":40699968114,"side":"Sell","size":579,"price":318.86}]}
1618677665.382397: {"table":"orderBookL2","action":"update","data":[{"symbol":"ADAM21","id":52299997781,"side":"Sell","size":50728},{"symbol":"ADAM21","id":52299997882,"side":"Buy","size":96576},{"symbol":"ADAM21","id":52299997888,"side":"Buy","size":175851}]}
1618677665.382512: {"table":"orderBookL2","action":"insert","data":[{"symbol":"ADAM21","id":52299997784,"side":"Sell","size":33594,"price":0.00002216}]}
1618677665.400203: {"table":"orderBookL2","action":"insert","data":[{"symbol":"XLMUSDT","id":52199939257,"side":"Buy","size":334,"price":0.60743}]}
1618677665.400335: {"table":"orderBookL2","action":"insert","data":[{"symbol":"XLMUSDT","id":52199939139,"side":"Sell","size":456,"price":0.60861}]}
1618677665.4135082: {"table":"orderBookL2","action":"insert","data":[{"symbol":"XLMUSDT","id":52199939317,"side":"Buy","size":71,"price":0.60683}]}
1618677665.452317: {"table":"orderBookL2","action":"update","data":[{"symbol":"LTCUSD","id":40699968721,"side":"Buy","size":5000}]}
1618677665.457696: {"table":"orderBookL2","action":"delete","data":[{"symbol":"LTCUSD","id":40699968720,"side":"Buy"}]}
1618677665.465912: {"table":"orderBookL2","action":"delete","data":[{"symbol":"LTCUSD","id":40699968114,"side":"Sell"},{"symbol":"LTCUSD","id":40699968356,"side":"Sell"},{"symbol":"LTCUSD","id":40699969012,"side":"Buy"},{"symbol":"LTCUSD","id":40699969234,"side":"Buy"}]}
1618677665.466068: {"table":"orderBookL2","action":"update","data":[{"symbol":"LTCUSD","id":40699968477,"side":"Sell","size":1785}]}
1618677665.4661179: {"table":"orderBookL2","action":"insert","data":[{"symbol":"LTCUSD","id":40699968110,"side":"Sell","size":579,"price":318.9},{"symbol":"LTCUSD","id":40699968353,"side":"Sell","size":579,"price":316.47},{"symbol":"LTCUSD","id":40699968475,"side":"Sell","size":579,"price":315.25},{"symbol":"LTCUSD","id":40699969015,"side":"Buy","size":579,"price":309.85},{"symbol":"LTCUSD","id":40699969239,"side":"Buy","size":579,"price":307.61}]}
1618677665.4662552: {"table":"orderBookL2","action":"insert","data":[{"symbol":"LTCUSD","id":40699968717,"side":"Buy","size":1,"price":312.83}]}
1618677665.478716: {"table":"orderBookL2","action":"insert","data":[{"symbol":"LTCUSD","id":40699968665,"side":"Sell","size":452,"price":313.35}]}
1618677665.478849: {"table":"orderBookL2","action":"delete","data":[{"symbol":"LTCUSD","id":40699968718,"side":"Buy"}]}
1618677665.47932: {"table":"orderBookL2","action":"insert","data":[{"symbol":"LTCUSD","id":40699968725,"side":"Buy","size":247,"price":312.75}]}
1618677665.492853: {"table":"orderBookL2","action":"delete","data":[{"symbol":"LTCUSD","id":40699968664,"side":"Sell"}]}
1618677665.492969: {"table":"orderBookL2","action":"delete","data":[{"symbol":"DOGEUSDT","id":47599971923,"side":"Buy"}]}
1618677665.4932852: {"table":"orderBookL2","action":"insert","data":[{"symbol":"DOGEUSDT","id":47599971804,"side":"Buy","size":176,"price":0.28196}]}
1618677665.508545: {"table":"orderBookL2","action":"delete","data":[{"symbol":"LTCUSD","id":40699968665,"side":"Sell"}]}
1618677665.508662: {"table":"orderBookL2","action":"insert","data":[{"symbol":"LTCUSD","id":40699968663,"side":"Sell","size":452,"price":313.37}]}
1618677665.586529: {"table":"orderBookL2","action":"insert","data":[{"symbol":"DOGEUSDT","id":47599971451,"side":"Sell","size":301,"price":0.28549},{"symbol":"DOGEUSDT","id":47599971541,"side":"Buy","size":4000,"price":0.28459}]}
1618677665.5925188: {"table":"orderBookL2","action":"delete","data":[{"symbol":"XLMUSDT","id":52199939317,"side":"Buy"}]}
1618677665.592638: {"table":"orderBookL2","action":"insert","data":[{"symbol":"XLMUSDT","id":52199939066,"side":"Sell","size":74,"price":0.60934}]}
1618677665.657944: {"table":"orderBookL2","action":"delete","data":[{"symbol":"LTCUSD","id":40699968110,"side":"Sell"},{"symbol":"LTCUSD","id":40699968353,"side":"Sell"},{"symbol":"LTCUSD","id":40699968475,"side":"Sell"}]}
1618677665.6580858: {"table":"orderBookL2","action":"insert","data":[{"symbol":"LTCUSD","id":40699968112,"side":"Sell","size":579,"price":318.88},{"symbol":"LTCUSD","id":40699968355,"side":"Sell","size":579,"price":316.45},{"symbol":"LTCUSD","id":40699968476,"side":"Sell","size":579,"price":315.24}]}
1618677665.667287: {"table":"orderBookL2","action":"update","data":[{"symbol":"LTCUSD","id":40699968725,"side":"Buy","size":483}]}
1618677665.728134: {"table":"orderBookL2","action":"update","data":[{"symbol":"TRXM21","id":52999999755,"side":"Sell","size":98192}]}
1618677665.85569: {"table":"orderBookL2","action":"delete","data":[{"symbol":"DOGEUSDT","id":47599971827,"side":"Buy"}]}
1618677665.855754: {"table":"orderBookL2","action":"insert","data":[{"symbol":"DOGEUSDT","id":47599971886,"side":"Buy","size":236,"price":0.28114}]}
1618677665.857106: {"table":"orderBookL2","action":"delete","data":[{"symbol":"DOGEUSDT","id":47599971674,"side":"Buy"}]}
1618677665.967663: {"table":"orderBookL2","action":"update","data":[{"symbol":"ADAM21","id":52299997830,"side":"Sell","size":35181}]}
1618677665.99756: {"table":"orderBookL2","action":"delete","data":[{"symbol":"EOSM21","id":52499998733,"side":"Buy"}]}
1618677666.01037: {"table":"orderBookL2","action":"update","data":[{"symbol":"EOSM21","id":52499998732,"side":"Sell","size":322}]}
1618677666.013962: {"table":"orderBookL2","action":"insert","data":[{"symbol":"EOSM21","id":52499998733,"side":"Sell","size":330,"price":0.0001267}]}
1618677666.0269089: {"table":"orderBookL2","action":"update","data":[{"symbol":"EOSM21","id":52499998734,"side":"Buy","size":2110}]}
1618677666.048949: {"table":"orderBookL2","action":"update","data":[{"symbol":"EOSM21","id":52499998731,"side":"Sell","size":946}]}
1618677666.0718179: {"table":"orderBookL2","action":"update","data":[{"symbol":"TRXM21","id":52999999754,"side":"Sell","size":50162}]}
1618677666.08448: {"table":"orderBookL2","action":"insert","data":[{"symbol":"DOGEUSDT","id":47599971678,"side":"Buy","size":350,"price":0.28322}]}
1618677666.1083982: {"table":"orderBookL2","action":"delete","data":[{"symbol":"DOGEUSDT","id":47599971541,"side":"Buy"}]}
1618677666.1994371: {"table":"orderBookL2","action":"insert","data":[{"symbol":"DOGEUSDT","id":47599971501,"side":"Sell","size":50,"price":0.28499}]}
1618677666.199571: {"table":"orderBookL2","action":"insert","data":[{"symbol":"DOGEUSDT","id":47599971674,"side":"Buy","size":387,"price":0.28326}]}
1618677666.202215: {"table":"orderBookL2","action":"delete","data":[{"symbol":"DOGEUSDT","id":47599971804,"side":"Buy"}]}
1618677666.2023308: {"table":"orderBookL2","action":"insert","data":[{"symbol":"DOGEUSDT","id":47599971846,"side":"Buy","size":206,"price":0.28154}]}
1618677666.2118778: {"table":"orderBookL2","action":"delete","data":[{"symbol":"EOSM21","id":52499998747,"side":"Buy"}]}
1618677666.211995: {"table":"orderBookL2","action":"update","data":[{"symbol":"EOSM21","id":52499998743,"side":"Buy","size":985}]}
1618677666.2213938: {"table":"orderBookL2","action":"delete","data":[{"symbol":"DOGEUSDT","id":47599971777,"side":"Buy"}]}
1618677666.22151: {"table":"orderBookL2","action":"insert","data":[{"symbol":"DOGEUSDT","id":47599971806,"side":"Buy","size":154,"price":0.28194}]}
1618677666.238626: {"table":"orderBookL2","action":"update","data":[{"symbol":"TRXM21","id":52999999757,"side":"Sell","size":3488589}]}
1618677666.243032: {"table":"orderBookL2","action":"delete","data":[{"symbol":"TRXUSDT","id":53999984171,"side":"Buy"}]}
1618677666.24315: {"table":"orderBookL2","action":"insert","data":[{"symbol":"TRXUSDT","id":53999983999,"side":"Buy","size":100,"price":0.16001}]}
1618677666.2536051: {"table":"orderBookL2","action":"update","data":[{"symbol":"TRXUSDT","id":53999984000,"side":"Buy","size":2500}]}
1618677666.343808: {"table":"orderBookL2","action":"delete","data":[{"symbol":"LTCUSD","id":40699968112,"side":"Sell"},{"symbol":"LTCUSD","id":40699968355,"side":"Sell"},{"symbol":"LTCUSD","id":40699968476,"side":"Sell"},{"symbol":"LTCUSD","id":40699968566,"side":"Sell"},{"symbol":"LTCUSD","id":40699969015,"side":"Buy"},{"symbol":"LTCUSD","id":40699969239,"side":"Buy"}]}
1618677666.3439832: {"table":"orderBookL2","action":"update","data":[{"symbol":"LTCUSD","id":40699968480,"side":"Sell","size":776},{"symbol":"LTCUSD","id":40699968601,"side":"Sell","size":826}]}
1618677666.3440409: {"table":"orderBookL2","action":"insert","data":[{"symbol":"LTCUSD","id":40699968119,"side":"Sell","size":579,"price":318.81},{"symbol":"LTCUSD","id":40699968360,"side":"Sell","size":579,"price":316.4},{"symbol":"LTCUSD","id":40699969014,"side":"Buy","size":579,"price":309.86},{"symbol":"LTCUSD","id":40699969236,"side":"Buy","size":579,"price":307.64}]}
1618677666.373914: {"table":"orderBookL2","action":"insert","data":[{"symbol":"LINKUSDTM21","id":52799882612,"side":"Sell","size":100,"price":58.694}]}
1618677666.377156: {"table":"orderBookL2","action":"delete","data":[{"symbol":"XLMUSDT","id":52199939362,"side":"Buy"}]}
1618677666.392961: {"table":"orderBookL2","action":"delete","data":[{"symbol":"LTCUSD","id":40699968119,"side":"Sell"}]}
1618677666.393078: {"table":"orderBookL2","action":"insert","data":[{"symbol":"LTCUSD","id":40699968120,"side":"Sell","size":579,"price":318.8}]}
1618677666.393159: {"table":"orderBookL2","action":"delete","data":[{"symbol":"LTCUSD","id":40699968360,"side":"Sell"},{"symbol":"LTCUSD","id":40699969014,"side":"Buy"},{"symbol":"LTCUSD","id":40699969236,"side":"Buy"}]}
1618677666.3932102: {"table":"orderBookL2","action":"update","data":[{"symbol":"LTCUSD","id":40699968480,"side":"Sell","size":197},{"symbol":"LTCUSD","id":40699968484,"side":"Sell","size":2728},{"symbol":"LTCUSD","id":40699968601,"side":"Sell","size":247}]}
1618677666.3932421: {"table":"orderBookL2","action":"insert","data":[{"symbol":"LTCUSD","id":40699968366,"side":"Sell","size":579,"price":316.34},{"symbol":"LTCUSD","id":40699968604,"side":"Sell","size":579,"price":313.96},{"symbol":"LTCUSD","id":40699969012,"side":"Buy","size":579,"price":309.88},{"symbol":"LTCUSD","id":40699969230,"side":"Buy","size":579,"price":307.7}]}
1618677666.411238: {"table":"orderBookL2","action":"delete","data":[{"symbol":"LTCUSD","id":40699968120,"side":"Sell"},{"symbol":"LTCUSD","id":40699968366,"side":"Sell"},{"symbol":"LTCUSD","id":40699968604,"side":"Sell"},{"symbol":"LTCUSD","id":40699969012,"side":"Buy"},{"symbol":"LTCUSD","id":40699969230,"side":"Buy"}]}
1618677666.411403: {"table":"orderBookL2","action":"update","data":[{"symbol":"LTCUSD","id":40699968484,"side":"Sell","size":2149},{"symbol":"LTCUSD","id":40699968602,"side":"Sell","size":755},{"symbol":"LTCUSD","id":40699968905,"side":"Buy","size":200},{"symbol":"LTCUSD","id":40699968910,"side":"Buy","size":2389}]}
1618677666.4114711: {"table":"orderBookL2","action":"insert","data":[{"symbol":"LTCUSD","id":40699968118,"side":"Sell","size":579,"price":318.82},{"symbol":"LTCUSD","id":40699968360,"side":"Sell","size":579,"price":316.4},{"symbol":"LTCUSD","id":40699968481,"side":"Sell","size":579,"price":315.19},{"symbol":"LTCUSD","id":40699969017,"side":"Buy","size":579,"price":309.83},{"symbol":"LTCUSD","id":40699969240,"side":"Buy","size":579,"price":307.6}]}
1618677666.4237592: {"table":"orderBookL2","action":"delete","data":[{"symbol":"DOGEUSDT","id":47599971678,"side":"Buy"}]}
1618677666.4340868: {"table":"orderBookL2","action":"delete","data":[{"symbol":"LTCUSD","id":40699968662,"side":"Sell"}]}
1618677666.434208: {"table":"orderBookL2","action":"insert","data":[{"symbol":"LTCUSD","id":40699968664,"side":"Sell","size":125,"price":313.36}]}
1618677666.4433951: {"table":"orderBookL2","action":"delete","data":[{"symbol":"DOGEUSDT","id":47599971674,"side":"Buy"}]}
1618677666.443512: {"table":"orderBookL2","action":"insert","data":[{"symbol":"DOGEUSDT","id":47599971673,"side":"Buy","size":37,"price":0.28327}]}
1618677666.4463449: {"table":"orderBookL2","action":"insert","data":[{"symbol":"LTCUSD","id":40699968655,"side":"Sell","size":295,"price":313.45}]}
1618677666.44716: {"table":"orderBookL2","action":"delete","data":[{"symbol":"LTCUSD","id":40699968663,"side":"Sell"}]}
1618677666.447252: {"table":"orderBookL2","action":"insert","data":[{"symbol":"LTCUSD","id":40699968658,"side":"Sell","size":452,"price":313.42}]}
1618677666.453799: {"table":"orderBookL2","action":"delete","data":[{"symbol":"DOGEUSDT","id":47599971673,"side":"Buy"}]}
1618677666.489676: {"table":"orderBookL2","action":"delete","data":[{"symbol":"LTCUSD","id":40699968118,"side":"Sell"},{"symbol":"LTCUSD","id":40699968360,"side":"Sell"},{"symbol":"LTCUSD","id":40699968481,"side":"Sell"},{"symbol":"LTCUSD","id":40699969017,"side":"Buy"},{"symbol":"LTCUSD","id":40699969240,"side":"Buy"}]}
1618677666.489843: {"table":"orderBookL2","action":"update","data":[{"symbol":"LTCUSD","id":40699968357,"side":"Sell","size":2357},{"symbol":"LTCUSD","id":40699968602,"side":"Sell","size":176},{"symbol":"LTCUSD","id":40699968905,"side":"Buy","size":779},{"symbol":"LTCUSD","id":40699968910,"side":"Buy","size":1810}]}
1618677666.4899101: {"table":"orderBookL2","action":"insert","data":[{"symbol":"LTCUSD","id":40699968115,"side":"Sell","size":579,"price":318.85},{"symbol":"LTCUSD","id":40699968478,"side":"Sell","size":579,"price":315.22},{"symbol":"LTCUSD","id":40699968566,"side":"Sell","size":579,"price":314.34},{"symbol":"LTCUSD","id":40699969015,"side":"Buy","size":579,"price":309.85},{"symbol":"LTCUSD","id":40699969237,"side":"Buy","size":579,"price":307.63}]}
1618677666.53026: {"table":"orderBookL2","action":"update","data":[{"symbol":"LTCUSD","id":40699968725,"side":"Buy","size":236}]}
1618677666.537426: {"table":"orderBookL2","action":"delete","data":[{"symbol":"LTCUSD","id":40699968725,"side":"Buy"}]}
1618677666.537546: {"table":"orderBookL2","action":"update","data":[{"symbol":"LTCUSD","id":40699968645,"side":"Sell","size":90}]}
1618677666.537596: {"table":"orderBookL2","action":"insert","data":[{"symbol":"LTCUSD","id":40699968657,"side":"Sell","size":538,"price":313.43}]}
1618677666.537657: {"table":"orderBookL2","action":"insert","data":[{"symbol":"LTCUSD","id":40699968649,"side":"Sell","size":247,"price":313.51}]}
1618677666.5447638: {"table":"orderBookL2","action":"delete","data":[{"symbol":"TRXUSDT","id":53999983999,"side":"Buy"}]}
1618677666.5448818: {"table":"orderBookL2","action":"insert","data":[{"symbol":"TRXUSDT","id":53999984171,"side":"Buy","size":100,"price":0.15829}]}
1618677666.564393: {"table":"orderBookL2","action":"delete","data":[{"symbol":"LTCUSD","id":40699968649,"side":"Sell"}]}
1618677666.578131: {"table":"orderBookL2","action":"insert","data":[{"symbol":"XLMUSDT","id":52199939379,"side":"Buy","size":112,"price":0.60621}]}
1618677666.615693: {"table":"orderBookL2","action":"delete","data":[{"symbol":"LTCUSD","id":40699968115,"side":"Sell"},{"symbol":"LTCUSD","id":40699968478,"side":"Sell"},{"symbol":"LTCUSD","id":40699968566,"side":"Sell"},{"symbol":"LTCUSD","id":40699969015,"side":"Buy"},{"symbol":"LTCUSD","id":40699969237,"side":"Buy"}]}
1618677666.6158578: {"table":"orderBookL2","action":"update","data":[{"symbol":"LTCUSD","id":40699968357,"side":"Sell","size":1778},{"symbol":"LTCUSD","id":40699968603,"side":"Sell","size":596},{"symbol":"LTCUSD","id":40699968905,"side":"Buy","size":200},{"symbol":"LTCUSD","id":40699968910,"side":"Buy","size":2389}]}
1618677666.615926: {"table":"orderBookL2","action":"insert","data":[{"symbol":"LTCUSD","id":40699968120,"side":"Sell","size":579,"price":318.8},{"symbol":"LTCUSD","id":40699968361,"side":"Sell","size":579,"price":316.39},{"symbol":"LTCUSD","id":40699968482,"side":"Sell","size":579,"price":315.18},{"symbol":"LTCUSD","id":40699969017,"side":"Buy","size":579,"price":309.83},{"symbol":"LTCUSD","id":40699969239,"side":"Buy","size":579,"price":307.61}]}
1618677666.62656: {"table":"orderBookL2","action":"insert","data":[{"symbol":"TRXUSDT","id":53999983898,"side":"Sell","size":526,"price":0.16102}]}
1618677666.846632: {"table":"orderBookL2","action":"delete","data":[{"symbol":"LTCUSD","id":40699968120,"side":"Sell"},{"symbol":"LTCUSD","id":40699968361,"side":"Sell"},{"symbol":"LTCUSD","id":40699968482,"side":"Sell"},{"symbol":"LTCUSD","id":40699969017,"side":"Buy"},{"symbol":"LTCUSD","id":40699969239,"side":"Buy"}]}
1618677666.84675: {"table":"orderBookL2","action":"update","data":[{"symbol":"LTCUSD","id":40699968602,"side":"Sell","size":755},{"symbol":"LTCUSD","id":40699968603,"side":"Sell","size":17},{"symbol":"LTCUSD","id":40699968905,"side":"Buy","size":779},{"symbol":"LTCUSD","id":40699968910,"side":"Buy","size":1810}]}
1618677666.846794: {"table":"orderBookL2","action":"insert","data":[{"symbol":"LTCUSD","id":40699968119,"side":"Sell","size":579,"price":318.81},{"symbol":"LTCUSD","id":40699968360,"side":"Sell","size":579,"price":316.4},{"symbol":"LTCUSD","id":40699968481,"side":"Sell","size":579,"price":315.19},{"symbol":"LTCUSD","id":40699969016,"side":"Buy","size":579,"price":309.84},{"symbol":"LTCUSD","id":40699969238,"side":"Buy","size":579,"price":307.62}]}
1618677666.8620338: {"table":"orderBookL2","action":"insert","data":[{"symbol":"LTCUSD","id":40699968729,"side":"Buy","size":236,"price":312.71}]}
1618677666.951908: {"table":"orderBookL2","action":"insert","data":[{"symbol":"XLMUSDT","id":52199939124,"side":"Sell","size":53,"price":0.60876}]}
1618677666.962023: {"table":"orderBookL2","action":"delete","data":[{"symbol":"EOSUSDT","id":53899984146,"side":"Buy"}]}
1618677667.012651: {"table":"orderBookL2","action":"delete","data":[{"symbol":"LTCUSD","id":40699968119,"side":"Sell"},{"symbol":"LTCUSD","id":40699968360,"side":"Sell"},{"symbol":"LTCUSD","id":40699968481,"side":"Sell"},{"symbol":"LTCUSD","id":40699969016,"side":"Buy"},{"symbol":"LTCUSD","id":40699969238,"side":"Buy"}]}
1618677667.012819: {"table":"orderBookL2","action":"update","data":[{"symbol":"LTCUSD","id":40699968117,"side":"Sell","size":2344},{"symbol":"LTCUSD","id":40699968357,"side":"Sell","size":2357},{"symbol":"LTCUSD","id":40699968602,"side":"Sell","size":176}]}
1618677667.0128798: {"table":"orderBookL2","action":"insert","data":[{"symbol":"LTCUSD","id":40699968478,"side":"Sell","size":579,"price":315.22},{"symbol":"LTCUSD","id":40699968566,"side":"Sell","size":579,"price":314.34},{"symbol":"LTCUSD","id":40699969011,"side":"Buy","size":579,"price":309.89},{"symbol":"LTCUSD","id":40699969232,"side":"Buy","size":579,"price":307.68}]}
1618677667.0200582: {"table":"orderBookL2","action":"insert","data":[{"symbol":"LTCUSD","id":40699968665,"side":"Sell","size":12,"price":313.35}]}
1618677667.0448499: {"table":"orderBookL2","action":"delete","data":[{"symbol":"LTCUSD","id":40699968665,"side":"Sell"}]}
1618677667.044968: {"table":"orderBookL2","action":"insert","data":[{"symbol":"LTCUSD","id":40699968666,"side":"Sell","size":2,"price":313.34}]}
1618677667.056621: {"table":"orderBookL2","action":"delete","data":[{"symbol":"LTCUSD","id":40699968658,"side":"Sell"}]}
1618677667.0567381: {"table":"orderBookL2","action":"insert","data":[{"symbol":"LTCUSD","id":40699968667,"side":"Sell","size":452,"price":313.33}]}
1618677667.059772: {"table":"orderBookL2","action":"delete","data":[{"symbol":"LTCUSD","id":40699968666,"side":"Sell"}]}
1618677667.06866: {"table":"orderBookL2","action":"delete","data":[{"symbol":"LTCUSD","id":40699968478,"side":"Sell"},{"symbol":"LTCUSD","id":40699969011,"side":"Buy"}]}
1618677667.068802: {"table":"orderBookL2","action":"update","data":[{"symbol":"LTCUSD","id":40699968117,"side":"Sell","size":1765},{"symbol":"LTCUSD","id":40699968357,"side":"Sell","size":1778}]}
1618677667.068862: {"table":"orderBookL2","action":"insert","data":[{"symbol":"LTCUSD","id":40699968114,"side":"Sell","size":579,"price":318.86},{"symbol":"LTCUSD","id":40699968355,"side":"Sell","size":579,"price":316.45},{"symbol":"LTCUSD","id":40699968476,"side":"Sell","size":579,"price":315.24},{"symbol":"LTCUSD","id":40699969013,"side":"Buy","size":579,"price":309.87}]}
1618677667.2623832: {"table":"orderBookL2","action":"delete","data":[{"symbol":"EOSUSDT","id":53899984017,"side":"Sell"}]}
1618677667.2624772: {"table":"orderBookL2","action":"insert","data":[{"symbol":"EOSUSDT","id":53899984036,"side":"Sell","size":496,"price":7.982}]}
1618677667.26847: {"table":"orderBookL2","action":"delete","data":[{"symbol":"LINKUSDTM21","id":52799882612,"side":"Sell"}]}
1618677667.2713401: {"table":"orderBookL2","action":"update","data":[{"symbol":"LTCM21","id":52899998942,"side":"Sell","size":205}]}
1618677667.277089: {"table":"orderBookL2","action":"update","data":[{"symbol":"LTCM21","id":52899998936,"side":"Sell","size":523}]}
1618677667.2775948: {"table":"orderBookL2","action":"update","data":[{"symbol":"EOSM21","id":52499998740,"side":"Buy","size":8422}]}
1618677667.280318: {"table":"orderBookL2","action":"insert","data":[{"symbol":"LTCM21","id":52899998951,"side":"Buy","size":285,"price":0.005245}]}
1618677667.280446: {"table":"orderBookL2","action":"update","data":[{"symbol":"EOSM21","id":52499998744,"side":"Buy","size":20152}]}
1618677667.283412: {"table":"orderBookL2","action":"insert","data":[{"symbol":"LTCM21","id":52899998955,"side":"Buy","size":446,"price":0.005225}]}
1618677667.2866719: {"table":"orderBookL2","action":"update","data":[{"symbol":"EOSM21","id":52499998720,"side":"Sell","size":10980}]}
1618677667.286772: {"table":"orderBookL2","action":"update","data":[{"symbol":"EOSM21","id":52499998718,"side":"Sell","size":20177}]}
1618677667.291085: {"table":"orderBookL2","action":"insert","data":[{"symbol":"EOSM21","id":52499998742,"side":"Buy","size":10001,"price":0.0001258}]}
1618677667.2912152: {"table":"orderBookL2","action":"insert","data":[{"symbol":"XLMUSDT","id":52199939097,"side":"Sell","size":56,"price":0.60903}]}
1618677667.293728: {"table":"orderBookL2","action":"update","data":[{"symbol":"LTCM21","id":52899998938,"side":"Sell","size":306}]}
1618677667.304276: {"table":"orderBookL2","action":"delete","data":[{"symbol":"XLMUSDT","id":52199939124,"side":"Sell"}]}
1618677667.3043892: {"table":"orderBookL2","action":"insert","data":[{"symbol":"LINKUSDTM21","id":52799882580,"side":"Sell","size":300,"price":58.71}]}
1618677667.306298: {"table":"orderBookL2","action":"insert","data":[{"symbol":"LINKUSDTM21","id":52799886580,"side":"Buy","size":300,"price":56.71}]}
1618677667.4570382: {"table":"orderBookL2","action":"delete","data":[{"symbol":"LINKUSDTM21","id":52799886580,"side":"Buy"}]}
1618677667.4727209: {"table":"orderBookL2","action":"delete","data":[{"symbol":"LINKUSDTM21","id":52799882580,"side":"Sell"}]}
1618677667.524711: {"table":"orderBookL2","action":"delete","data":[{"symbol":"LTCUSD","id":40699968114,"side":"Sell"},{"symbol":"LTCUSD","id":40699968355,"side":"Sell"},{"symbol":"LTCUSD","id":40699968476,"side":"Sell"},{"symbol":"LTCUSD","id":40699968566,"side":"Sell"},{"symbol":"LTCUSD","id":40699969013,"side":"Buy"},{"symbol":"LTCUSD","id":40699969232,"side":"Buy"}]}
1618677667.524884: {"table":"orderBookL2","action":"insert","data":[{"symbol":"LTCUSD","id":40699968136,"side":"Sell","size":579,"price":318.64},{"symbol":"LTCUSD","id":40699968371,"side":"Sell","size":579,"price":316.29},{"symbol":"LTCUSD","id":40699968489,"side":"Sell","size":579,"price":315.11},{"symbol":"LTCUSD","id":40699968604,"side":"Sell","size":579,"price":313.96},{"symbol":"LTCUSD","id":40699969010,"side":"Buy","size":579,"price":309.9},{"symbol":"LTCUSD","id":40699969226,"side":"Buy","size":579,"price":307.74}]}
1618677667.537175: {"table":"orderBookL2","action":"insert","data":[{"symbol":"LTCUSD","id":40699968730,"side":"Buy","size":247,"price":312.7}]}
1618677667.563005: {"table":"orderBookL2","action":"insert","data":[{"symbol":"TRXUSDT","id":53999983888,"side":"Sell","size":367,"price":0.16112}]}
1618677667.564802: {"table":"orderBookL2","action":"delete","data":[{"symbol":"DOGEUSDT","id":47599971451,"side":"Sell"}]}
1618677667.56834: {"table":"orderBookL2","action":"delete","data":[{"symbol":"TRXUSDT","id":53999983898,"side":"Sell"}]}
1618677667.587838: {"table":"orderBookL2","action":"delete","data":[{"symbol":"DOGEUSDT","id":47599971806,"side":"Buy"}]}
1618677667.58796: {"table":"orderBookL2","action":"insert","data":[{"symbol":"DOGEUSDT","id":47599971777,"side":"Buy","size":154,"price":0.28223}]}
1618677667.647688: {"table":"orderBookL2","action":"delete","data":[{"symbol":"LTCUSD","id":40699968136,"side":"Sell"},{"symbol":"LTCUSD","id":40699968371,"side":"Sell"},{"symbol":"LTCUSD","id":40699968489,"side":"Sell"},{"symbol":"LTCUSD","id":40699968604,"side":"Sell"},{"symbol":"LTCUSD","id":40699969010,"side":"Buy"},{"symbol":"LTCUSD","id":40699969226,"side":"Buy"}]}
1618677667.647858: {"table":"orderBookL2","action":"update","data":[{"symbol":"LTCUSD","id":40699968603,"side":"Sell","size":596},{"symbol":"LTCUSD","id":40699968905,"side":"Buy","size":200},{"symbol":"LTCUSD","id":40699968910,"side":"Buy","size":2389}]}
1618677667.6479201: {"table":"orderBookL2","action":"insert","data":[{"symbol":"LTCUSD","id":40699968120,"side":"Sell","size":579,"price":318.8},{"symbol":"LTCUSD","id":40699968362,"side":"Sell","size":579,"price":316.38},{"symbol":"LTCUSD","id":40699968482,"side":"Sell","size":579,"price":315.18},{"symbol":"LTCUSD","id":40699969018,"side":"Buy","size":579,"price":309.82},{"symbol":"LTCUSD","id":40699969240,"side":"Buy","size":579,"price":307.6}]}
1618677667.681448: {"table":"orderBookL2","action":"delete","data":[{"symbol":"LTCUSD","id":40699968120,"side":"Sell"},{"symbol":"LTCUSD","id":40699968362,"side":"Sell"},{"symbol":"LTCUSD","id":40699968482,"side":"Sell"},{"symbol":"LTCUSD","id":40699969018,"side":"Buy"},{"symbol":"LTCUSD","id":40699969240,"side":"Buy"}]}
1618677667.6815622: {"table":"orderBookL2","action":"update","data":[{"symbol":"LTCUSD","id":40699968603,"side":"Sell","size":17},{"symbol":"LTCUSD","id":40699968905,"side":"Buy","size":779},{"symbol":"LTCUSD","id":40699968910,"side":"Buy","size":1810}]}
1618677667.681602: {"table":"orderBookL2","action":"insert","data":[{"symbol":"LTCUSD","id":40699968132,"side":"Sell","size":579,"price":318.68},{"symbol":"LTCUSD","id":40699968369,"side":"Sell","size":579,"price":316.31},{"symbol":"LTCUSD","id":40699968488,"side":"Sell","size":579,"price":315.12},{"symbol":"LTCUSD","id":40699968605,"side":"Sell","size":579,"price":313.95},{"symbol":"LTCUSD","id":40699969014,"side":"Buy","size":579,"price":309.86},{"symbol":"LTCUSD","id":40699969232,"side":"Buy","size":579,"price":307.68}]}
1618677667.703033: {"table":"orderBookL2","action":"delete","data":[{"symbol":"LTCUSD","id":40699968717,"side":"Buy"}]}
1618677667.717022: {"table":"orderBookL2","action":"delete","data":[{"symbol":"XLMUSDT","id":52199939257,"side":"Buy"}]}
1618677667.717143: {"table":"orderBookL2","action":"insert","data":[{"symbol":"XLMUSDT","id":52199939256,"side":"Buy","size":222,"price":0.60744}]}
1618677667.720042: {"table":"orderBookL2","action":"insert","data":[{"symbol":"DOGEUSDT","id":47599971524,"side":"Buy","size":53,"price":0.28476}]}
1618677667.7319329: {"table":"orderBookL2","action":"delete","data":[{"symbol":"LTCUSD","id":40699968664,"side":"Sell"}]}
1618677667.732064: {"table":"orderBookL2","action":"insert","data":[{"symbol":"LTCUSD","id":40699968668,"side":"Sell","size":125,"price":313.32}]}
1618677667.732566: {"table":"orderBookL2","action":"delete","data":[{"symbol":"XLMUSDT","id":52199938981,"side":"Sell"}]}
1618677667.735647: {"table":"orderBookL2","action":"update","data":[{"symbol":"XLMUSDT","id":52199939139,"side":"Sell","size":501}]}
1618677667.735751: {"table":"orderBookL2","action":"insert","data":[{"symbol":"XLMUSDT","id":52199939445,"side":"Buy","size":66,"price":0.60555}]}
1618677667.737144: {"table":"orderBookL2","action":"delete","data":[{"symbol":"XLMUSDT","id":52199939414,"side":"Buy"}]}
1618677667.7471611: {"table":"orderBookL2","action":"delete","data":[{"symbol":"LTCUSD","id":40699968729,"side":"Buy"}]}
1618677667.7477372: {"table":"orderBookL2","action":"delete","data":[{"symbol":"LTCUSD","id":40699968730,"side":"Buy"}]}
1618677667.747791: {"table":"orderBookL2","action":"update","data":[{"symbol":"LTCUSD","id":40699968668,"side":"Sell","size":427}]}
1618677667.7484539: {"table":"orderBookL2","action":"delete","data":[{"symbol":"XLMUSDT","id":52199939445,"side":"Buy"}]}
1618677667.755774: {"table":"orderBookL2","action":"update","data":[{"symbol":"LTCUSD","id":40699968646,"side":"Sell","size":790}]}
1618677667.759188: {"table":"orderBookL2","action":"insert","data":[{"symbol":"LTCUSD","id":40699968652,"side":"Sell","size":247,"price":313.48}]}
1618677667.762028: {"table":"orderBookL2","action":"delete","data":[{"symbol":"LTCUSD","id":40699968132,"side":"Sell"},{"symbol":"LTCUSD","id":40699968369,"side":"Sell"},{"symbol":"LTCUSD","id":40699968488,"side":"Sell"},{"symbol":"LTCUSD","id":40699969014,"side":"Buy"},{"symbol":"LTCUSD","id":40699969232,"side":"Buy"}]}
1618677667.762193: {"table":"orderBookL2","action":"update","data":[{"symbol":"LTCUSD","id":40699968133,"side":"Sell","size":619},{"symbol":"LTCUSD","id":40699968905,"side":"Buy","size":200},{"symbol":"LTCUSD","id":40699968910,"side":"Buy","size":2389}]}
1618677667.762256: {"table":"orderBookL2","action":"insert","data":[{"symbol":"LTCUSD","id":40699968370,"side":"Sell","size":579,"price":316.3},{"symbol":"LTCUSD","id":40699968489,"side":"Sell","size":579,"price":315.11},{"symbol":"LTCUSD","id":40699969015,"side":"Buy","size":579,"price":309.85},{"symbol":"LTCUSD","id":40699969233,"side":"Buy","size":579,"price":307.67}]}
1618677667.762955: {"table":"orderBookL2","action":"delete","data":[{"symbol":"LTCUSD","id":40699968631,"side":"Sell"}]}
1618677667.763011: {"table":"orderBookL2","action":"update","data":[{"symbol":"LTCUSD","id":40699968727,"side":"Buy","size":39}]}
1618677667.7693791: {"table":"orderBookL2","action":"delete","data":[{"symbol":"LTCUSD","id":40699968719,"side":"Buy"}]}
1618677667.775062: {"table":"orderBookL2","action":"delete","data":[{"symbol":"LTCUSD","id":40699968721,"side":"Buy"}]}
1618677667.779325: {"table":"orderBookL2","action":"insert","data":[{"symbol":"LTCUSD","id":40699968811,"side":"Buy","size":106,"price":311.89}]}
1618677667.7856052: {"table":"orderBookL2","action":"delete","data":[{"symbol":"LTCUSD","id":40699968370,"side":"Sell"},{"symbol":"LTCUSD","id":40699968489,"side":"Sell"},{"symbol":"LTCUSD","id":40699968605,"side":"Sell"},{"symbol":"LTCUSD","id":40699969015,"side":"Buy"}]}
1618677667.785714: {"table":"orderBookL2","action":"update","data":[{"symbol":"LTCUSD","id":40699968133,"side":"Sell","size":40},{"symbol":"LTCUSD","id":40699968610,"side":"Sell","size":585}]}
1618677667.785751: {"table":"orderBookL2","action":"insert","data":[{"symbol":"LTCUSD","id":40699968138,"side":"Sell","size":579,"price":318.62},{"symbol":"LTCUSD","id":40699968374,"side":"Sell","size":579,"price":316.26},{"symbol":"LTCUSD","id":40699968492,"side":"Sell","size":579,"price":315.08},{"symbol":"LTCUSD","id":40699969016,"side":"Buy","size":579,"price":309.84}]}
1618677667.78882: {"table":"orderBookL2","action":"delete","data":[{"symbol":"LTCUSD","id":40699969233,"side":"Buy"}]}
1618677667.788865: {"table":"orderBookL2","action":"insert","data":[{"symbol":"LTCUSD","id":40699969231,"side":"Buy","size":579,"price":307.69}]}
1618677667.7888992: {"table":"orderBookL2","action":"update","data":[{"symbol":"LTCUSD","id":40699968739,"side":"Buy","size":5039}]}
1618677667.788919: {"table":"orderBookL2","action":"update","data":[{"symbol":"LTCUSD","id":40699968910,"side":"Buy","size":1810},{"symbol":"LTCUSD","id":40699968939,"side":"Buy","size":603}]}
1618677667.7909079: {"table":"orderBookL2","action":"update","data":[{"symbol":"LTCM21","id":52899998944,"side":"Sell","size":36}]}
1618677667.790956: {"table":"orderBookL2","action":"insert","data":[{"symbol":"LTCUSD","id":40699968726,"side":"Buy","size":1,"price":312.74}]}
1618677667.800672: {"table":"orderBookL2","action":"delete","data":[{"symbol":"LTCUSD","id":40699968794,"side":"Buy"}]}
1618677667.8043551: {"table":"orderBookL2","action":"delete","data":[{"symbol":"XLMUSDT","id":52199939379,"side":"Buy"}]}
1618677667.804472: {"table":"orderBookL2","action":"delete","data":[{"symbol":"LTCUSD","id":40699968657,"side":"Sell"}]}
1618677667.80453: {"table":"orderBookL2","action":"update","data":[{"symbol":"LTCUSD","id":40699968667,"side":"Sell","size":990}]}
1618677667.8065689: {"table":"orderBookL2","action":"insert","data":[{"symbol":"TRXUSDT","id":53999983895,"side":"Sell","size":429,"price":0.16105}]}
1618677667.806664: {"table":"orderBookL2","action":"delete","data":[{"symbol":"LTCUSD","id":40699968726,"side":"Buy"}]}
1618677667.806707: {"table":"orderBookL2","action":"update","data":[{"symbol":"LTCM21","id":52899998946,"side":"Buy","size":5}]}
1618677667.819896: {"table":"orderBookL2","action":"delete","data":[{"symbol":"LTCUSD","id":40699968632,"side":"Sell"}]}
1618677667.8200161: {"table":"orderBookL2","action":"delete","data":[{"symbol":"XLMUSDT","id":52199939526,"side":"Buy"}]}
1618677667.8236768: {"table":"orderBookL2","action":"insert","data":[{"symbol":"LTCUSD","id":40699968725,"side":"Buy","size":1,"price":312.75}]}
1618677667.827481: {"table":"orderBookL2","action":"delete","data":[{"symbol":"EOSUSDT","id":53899984158,"side":"Buy"}]}
1618677667.839366: {"table":"orderBookL2","action":"update","data":[{"symbol":"LTCUSD","id":40699968737,"side":"Buy","size":43}]}
1618677667.839436: {"table":"orderBookL2","action":"update","data":[{"symbol":"LTCUSD","id":40699968655,"side":"Sell","size":5295}]}
1618677667.865054: {"table":"orderBookL2","action":"insert","data":[{"symbol":"EOSUSDT","id":53899984172,"side":"Buy","size":73,"price":7.914}]}
1618677667.877839: {"table":"orderBookL2","action":"delete","data":[{"symbol":"LTCUSD","id":40699968138,"side":"Sell"},{"symbol":"LTCUSD","id":40699968374,"side":"Sell"},{"symbol":"LTCUSD","id":40699968492,"side":"Sell"},{"symbol":"LTCUSD","id":40699969016,"side":"Buy"},{"symbol":"LTCUSD","id":40699969231,"side":"Buy"}]}
1618677667.878002: {"table":"orderBookL2","action":"update","data":[{"symbol":"LTCUSD","id":40699968494,"side":"Sell","size":668},{"symbol":"LTCUSD","id":40699968610,"side":"Sell","size":6}]}
1618677667.8783228: {"table":"orderBookL2","action":"insert","data":[{"symbol":"LTCUSD","id":40699968136,"side":"Sell","size":579,"price":318.64},{"symbol":"LTCUSD","id":40699968375,"side":"Sell","size":579,"price":316.25},{"symbol":"LTCUSD","id":40699968614,"side":"Sell","size":579,"price":313.86},{"symbol":"LTCUSD","id":40699969024,"side":"Buy","size":579,"price":309.76},{"symbol":"LTCUSD","id":40699969245,"side":"Buy","size":579,"price":307.55}]}
1618677667.885762: {"table":"orderBookL2","action":"delete","data":[{"symbol":"LTCUSD","id":40699968759,"side":"Buy"}]}
1618677667.888009: {"table":"orderBookL2","action":"update","data":[{"symbol":"LTCM21","id":52899998945,"side":"Buy","size":5}]}
1618677667.896478: {"table":"orderBookL2","action":"delete","data":[{"symbol":"LTCUSD","id":40699968375,"side":"Sell"}]}
1618677667.896597: {"table":"orderBookL2","action":"insert","data":[{"symbol":"LTCUSD","id":40699968382,"side":"Sell","size":579,"price":316.18}]}
1618677667.912284: {"table":"orderBookL2","action":"insert","data":[{"symbol":"LTCUSD","id":40699968752,"side":"Buy","size":236,"price":312.48}]}
1618677667.91905: {"table":"orderBookL2","action":"delete","data":[{"symbol":"LTCM21","id":52899998945,"side":"Buy"}]}
1618677667.919536: {"table":"orderBookL2","action":"delete","data":[{"symbol":"LTCUSD","id":40699968737,"side":"Buy"}]}
1618677667.920618: {"table":"orderBookL2","action":"insert","data":[{"symbol":"LTCUSD","id":40699968817,"side":"Buy","size":43,"price":311.83}]}
1618677667.9248068: {"table":"orderBookL2","action":"update","data":[{"symbol":"LTCUSD","id":40699968650,"side":"Sell","size":236},{"symbol":"LTCUSD","id":40699968668,"side":"Sell","size":559}]}
1618677667.929485: {"table":"orderBookL2","action":"insert","data":[{"symbol":"LTCM21","id":52899998945,"side":"Sell","size":5,"price":0.005275}]}
1618677667.941223: {"table":"orderBookL2","action":"update","data":[{"symbol":"LTCM21","id":52899998945,"side":"Sell","size":18}]}
1618677667.94132: {"table":"orderBookL2","action":"update","data":[{"symbol":"LTCM21","id":52899998944,"side":"Sell","size":23}]}
1618677667.943487: {"table":"orderBookL2","action":"update","data":[{"symbol":"LTCM21","id":52899998947,"side":"Buy","size":2}]}
1618677667.9487932: {"table":"orderBookL2","action":"update","data":[{"symbol":"LTCM21","id":52899998946,"side":"Buy","size":18}]}
1618677667.964169: {"table":"orderBookL2","action":"delete","data":[{"symbol":"LTCUSD","id":40699968725,"side":"Buy"}]}
1618677667.971715: {"table":"orderBookL2","action":"update","data":[{"symbol":"LINKUSDTM21","id":52799886587,"side":"Buy","size":100}]}
1618677667.971814: {"table":"orderBookL2","action":"insert","data":[{"symbol":"LINKUSDTM21","id":52799885896,"side":"Sell","size":5,"price":57.052}]}
1618677667.976328: {"table":"orderBookL2","action":"insert","data":[{"symbol":"LTCUSD","id":40699968724,"side":"Buy","size":1,"price":312.76}]}
1618677667.9796422: {"table":"orderBookL2","action":"update","data":[{"symbol":"EOSM21","id":52499998734,"side":"Buy","size":1530}]}
1618677667.979743: {"table":"orderBookL2","action":"update","data":[{"symbol":"LTCUSD","id":40699968646,"side":"Sell","size":685}]}
1618677667.993653: {"table":"orderBookL2","action":"delete","data":[{"symbol":"LTCUSD","id":40699968724,"side":"Buy"}]}
1618677667.994132: {"table":"orderBookL2","action":"update","data":[{"symbol":"EOSM21","id":52499998732,"side":"Sell","size":1127}]}
1618677667.9968052: {"table":"orderBookL2","action":"update","data":[{"symbol":"EOSM21","id":52499998735,"side":"Buy","size":1200}]}
1618677668.0003068: {"table":"orderBookL2","action":"insert","data":[{"symbol":"XLMUSDT","id":52199939401,"side":"Buy","size":112,"price":0.60599}]}
1618677668.000959: {"table":"orderBookL2","action":"insert","data":[{"symbol":"EOSUSDT","id":53899984182,"side":"Buy","size":79,"price":7.909}]}
1618677668.0074828: {"table":"orderBookL2","action":"delete","data":[{"symbol":"LTCUSD","id":40699968752,"side":"Buy"}]}
1618677668.009208: {"table":"orderBookL2","action":"delete","data":[{"symbol":"EOSUSDT","id":53899984172,"side":"Buy"}]}
1618677668.010924: {"table":"orderBookL2","action":"insert","data":[{"symbol":"LTCUSD","id":40699968726,"side":"Buy","size":1,"price":312.74}]}
1618677668.023108: {"table":"orderBookL2","action":"delete","data":[{"symbol":"LTCUSD","id":40699968136,"side":"Sell"},{"symbol":"LTCUSD","id":40699968382,"side":"Sell"},{"symbol":"LTCUSD","id":40699969024,"side":"Buy"},{"symbol":"LTCUSD","id":40699969245,"side":"Buy"}]}
1618677668.023218: {"table":"orderBookL2","action":"insert","data":[{"symbol":"LTCUSD","id":40699968144,"side":"Sell","size":579,"price":318.56},{"symbol":"LTCUSD","id":40699968381,"side":"Sell","size":579,"price":316.19},{"symbol":"LTCUSD","id":40699969025,"side":"Buy","size":579,"price":309.75},{"symbol":"LTCUSD","id":40699969244,"side":"Buy","size":579,"price":307.56}]}
1618677668.0339708: {"table":"orderBookL2","action":"update","data":[{"symbol":"LTCUSD","id":40699968910,"side":"Buy","size":2389},{"symbol":"LTCUSD","id":40699968939,"side":"Buy","size":24}]}
1618677668.046676: {"table":"orderBookL2","action":"delete","data":[{"symbol":"LTCUSD","id":40699968381,"side":"Sell"}]}
1618677668.046794: {"table":"orderBookL2","action":"insert","data":[{"symbol":"LTCUSD","id":40699968392,"side":"Sell","size":579,"price":316.08}]}
1618677668.062797: {"table":"orderBookL2","action":"update","data":[{"symbol":"LTCUSD","id":40699968667,"side":"Sell","size":452}]}
1618677668.062897: {"table":"orderBookL2","action":"insert","data":[{"symbol":"LTCUSD","id":40699968677,"side":"Sell","size":538,"price":313.23}]}
1618677668.0664918: {"table":"orderBookL2","action":"delete","data":[{"symbol":"LTCUSD","id":40699968667,"side":"Sell"}]}
1618677668.066612: {"table":"orderBookL2","action":"insert","data":[{"symbol":"LTCUSD","id":40699968678,"side":"Sell","size":452,"price":313.22}]}
1618677668.072008: {"table":"orderBookL2","action":"delete","data":[{"symbol":"LTCUSD","id":40699968144,"side":"Sell"},{"symbol":"LTCUSD","id":40699968392,"side":"Sell"},{"symbol":"LTCUSD","id":40699969025,"side":"Buy"},{"symbol":"LTCUSD","id":40699969244,"side":"Buy"}]}
1618677668.07212: {"table":"orderBookL2","action":"insert","data":[{"symbol":"LTCUSD","id":40699968167,"side":"Sell","size":579,"price":318.33},{"symbol":"LTCUSD","id":40699968394,"side":"Sell","size":579,"price":316.06},{"symbol":"LTCUSD","id":40699969014,"side":"Buy","size":579,"price":309.86},{"symbol":"LTCUSD","id":40699969224,"side":"Buy","size":579,"price":307.76}]}
1618677668.073096: {"table":"orderBookL2","action":"delete","data":[{"symbol":"LTCUSD","id":40699968726,"side":"Buy"}]}
1618677668.0781598: {"table":"orderBookL2","action":"delete","data":[{"symbol":"LTCM21","id":52899998951,"side":"Buy"}]}
1618677668.079067: {"table":"orderBookL2","action":"delete","data":[{"symbol":"LTCM21","id":52899998955,"side":"Buy"}]}
1618677668.0835369: {"table":"orderBookL2","action":"update","data":[{"symbol":"LTCUSD","id":40699968678,"side":"Sell","size":491}]}
1618677668.155033: {"table":"orderBookL2","action":"update","data":[{"symbol":"EOSM21","id":52499998743,"side":"Buy","size":6}]}
1618677668.155134: {"table":"orderBookL2","action":"insert","data":[{"symbol":"EOSM21","id":52499998747,"side":"Buy","size":979,"price":0.0001253}]}
1618677668.1709492: {"table":"orderBookL2","action":"update","data":[{"symbol":"LINKUSDTM21","id":52799885947,"side":"Sell","size":84}]}
1618677668.171047: {"table":"orderBookL2","action":"delete","data":[{"symbol":"LINKUSDTM21","id":52799886648,"side":"Buy"}]}
1618677668.17111: {"table":"orderBookL2","action":"insert","data":[{"symbol":"LTCUSD","id":40699968657,"side":"Sell","size":42,"price":313.43}]}
1618677668.172502: {"table":"orderBookL2","action":"delete","data":[{"symbol":"EOSUSDT","id":53899984036,"side":"Sell"}]}
1618677668.17302: {"table":"orderBookL2","action":"insert","data":[{"symbol":"EOSUSDT","id":53899984017,"side":"Sell","size":496,"price":7.9915}]}
1618677668.173122: {"table":"orderBookL2","action":"update","data":[{"symbol":"LTCM21","id":52899998945,"side":"Sell","size":34}]}
1618677668.184875: {"table":"orderBookL2","action":"delete","data":[{"symbol":"TRXUSDT","id":53999984024,"side":"Buy"}]}
1618677668.1874099: {"table":"orderBookL2","action":"delete","data":[{"symbol":"TRXUSDT","id":53999984012,"side":"Buy"}]}
1618677668.212689: {"table":"orderBookL2","action":"delete","data":[{"symbol":"EOSUSDT","id":53899984182,"side":"Buy"}]}
1618677668.281142: {"table":"orderBookL2","action":"insert","data":[{"symbol":"LINKUSDTM21","id":52799882699,"side":"Sell","size":100,"price":58.6505}]}
1618677668.306838: {"table":"orderBookL2","action":"update","data":[{"symbol":"LTCUSD","id":40699968668,"side":"Sell","size":777}]}
1618677668.322927: {"table":"orderBookL2","action":"delete","data":[{"symbol":"LTCUSD","id":40699968650,"side":"Sell"}]}
1618677668.323046: {"table":"orderBookL2","action":"insert","data":[{"symbol":"LTCUSD","id":40699968679,"side":"Sell","size":236,"price":313.21}]}
1618677668.333601: {"table":"orderBookL2","action":"delete","data":[{"symbol":"LTCUSD","id":40699968677,"side":"Sell"}]}
1618677668.333722: {"table":"orderBookL2","action":"insert","data":[{"symbol":"LTCUSD","id":40699968689,"side":"Sell","size":538,"price":313.11}]}
1618677668.349322: {"table":"orderBookL2","action":"update","data":[{"symbol":"ADAM21","id":52299997836,"side":"Buy","size":35514}]}
1618677668.390955: {"table":"orderBookL2","action":"delete","data":[{"symbol":"LTCUSD","id":40699968689,"side":"Sell"}]}
1618677668.4080262: {"table":"orderBookL2","action":"update","data":[{"symbol":"LTCUSD","id":40699968678,"side":"Sell","size":1029}]}
1618677668.4253619: {"table":"orderBookL2","action":"delete","data":[{"symbol":"LTCUSD","id":40699967758,"side":"Sell"},{"symbol":"LTCUSD","id":40699967852,"side":"Sell"},{"symbol":"LTCUSD","id":40699967946,"side":"Sell"},{"symbol":"LTCUSD","id":40699968133,"side":"Sell"},{"symbol":"LTCUSD","id":40699968227,"side":"Sell"},{"symbol":"LTCUSD","id":40699968321,"side":"Sell"},{"symbol":"LTCUSD","id":40699968415,"side":"Sell"},{"symbol":"LTCUSD","id":40699968509,"side":"Sell"},{"symbol":"LTCUSD","id":40699968603,"side":"Sell"},{"symbol":"LTCUSD","id":40699968751,"side":"Buy"},{"symbol":"LTCUSD","id":40699968845,"side":"Buy"},{"symbol":"LTCUSD","id":40699968939,"side":"Buy"},{"symbol":"LTCUSD","id":40699969033,"side":"Buy"},{"symbol":"LTCUSD","id":40699969127,"side":"Buy"},{"symbol":"LTCUSD","id":40699969221,"side":"Buy"},{"symbol":"LTCUSD","id":40699969315,"side":"Buy"},{"symbol":"LTCUSD","id":40699969408,"side":"Buy"},{"symbol":"LTCUSD","id":40699969596,"side":"Buy"}]}
1618677668.4256608: {"table":"orderBookL2","action":"update","data":[{"symbol":"LTCUSD","id":40699968039,"side":"Sell","size":100},{"symbol":"LTCUSD","id":40699968277,"side":"Sell","size":1807},{"symbol":"LTCUSD","id":40699968652,"side":"Sell","size":264},{"symbol":"LTCUSD","id":40699968801,"side":"Buy","size":60},{"symbol":"LTCUSD","id":40699969502,"side":"Buy","size":4853}]}
1618677668.425712: {"table":"orderBookL2","action":"insert","data":[{"symbol":"LTCUSD","id":40699967807,"side":"Sell","size":68,"price":321.93},{"symbol":"LTCUSD","id":40699967901,"side":"Sell","size":61,"price":320.99},{"symbol":"LTCUSD","id":40699967995,"side":"Sell","size":54,"price":320.05},{"symbol":"LTCUSD","id":40699968089,"side":"Sell","size":47,"price":319.11},{"symbol":"LTCUSD","id":40699968183,"side":"Sell","size":40,"price":318.17},{"symbol":"LTCUSD","id":40699968370,"side":"Sell","size":26,"price":316.3},{"symbol":"LTCUSD","id":40699968464,"side":"Sell","size":18,"price":315.36},{"symbol":"LTCUSD","id":40699968558,"side":"Sell","size":17,"price":314.42},{"symbol":"LTCUSD","id":40699968895,"side":"Buy","size":17,"price":311.05},{"symbol":"LTCUSD","id":40699968989,"side":"Buy","size":24,"price":310.11},{"symbol":"LTCUSD","id":40699969082,"side":"Buy","size":33,"price":309.18},{"symbol":"LTCUSD","id":40699969176,"side":"Buy","size":43,"price":308.24},{"symbol":"LTCUSD","id":40699969270,"side":"Buy","size":52,"price":307.3},{"symbol":"LTCUSD","id":40699969364,"side":"Buy","size":62,"price":306.36},{"symbol":"LTCUSD","id":40699969458,"side":"Buy","size":72,"price":305.42},{"symbol":"LTCUSD","id":40699969552,"side":"Buy","size":81,"price":304.48},{"symbol":"LTCUSD","id":40699969646,"side":"Buy","size":91,"price":303.54}]}
1618677668.494258: {"table":"orderBookL2","action":"delete","data":[{"symbol":"LINKUSDTM21","id":52799882699,"side":"Sell"}]}
1618677668.529404: {"table":"orderBookL2","action":"delete","data":[{"symbol":"XLMUSDT","id":52199939090,"side":"Sell"}]}
1618677668.529519: {"table":"orderBookL2","action":"insert","data":[{"symbol":"XLMUSDT","id":52199939113,"side":"Sell","size":232,"price":0.60887}]}
1618677668.536412: {"table":"orderBookL2","action":"delete","data":[{"symbol":"LTCUSD","id":40699968167,"side":"Sell"},{"symbol":"LTCUSD","id":40699968394,"side":"Sell"},{"symbol":"LTCUSD","id":40699968614,"side":"Sell"},{"symbol":"LTCUSD","id":40699969014,"side":"Buy"}]}
1618677668.5365188: {"table":"orderBookL2","action":"update","data":[{"symbol":"LTCUSD","id":40699968494,"side":"Sell","size":89},{"symbol":"LTCUSD","id":40699968508,"side":"Sell","size":879},{"symbol":"LTCUSD","id":40699968910,"side":"Buy","size":1810},{"symbol":"LTCUSD","id":40699968948,"side":"Buy","size":2728},{"symbol":"LTCUSD","id":40699969027,"side":"Buy","size":2396}]}
1618677668.536567: {"table":"orderBookL2","action":"insert","data":[{"symbol":"LTCUSD","id":40699968191,"side":"Sell","size":579,"price":318.09},{"symbol":"LTCUSD","id":40699968414,"side":"Sell","size":579,"price":315.86},{"symbol":"LTCUSD","id":40699968635,"side":"Sell","size":579,"price":313.65}]}
1618677668.5438201: {"table":"orderBookL2","action":"delete","data":[{"symbol":"LTCUSD","id":40699968613,"side":"Sell"}]}
1618677668.543936: {"table":"orderBookL2","action":"insert","data":[{"symbol":"LTCUSD","id":40699968647,"side":"Sell","size":246,"price":313.53}]}
1618677668.609235: {"table":"orderBookL2","action":"delete","data":[{"symbol":"LTCUSD","id":40699968630,"side":"Sell"}]}
1618677668.609354: {"table":"orderBookL2","action":"update","data":[{"symbol":"LTCUSD","id":40699968679,"side":"Sell","size":368}]}
1618677668.612679: {"table":"orderBookL2","action":"delete","data":[{"symbol":"LTCUSD","id":40699968741,"side":"Buy"}]}
1618677668.612797: {"table":"orderBookL2","action":"insert","data":[{"symbol":"LTCUSD","id":40699968779,"side":"Buy","size":155,"price":312.21}]}
1618677668.7469041: {"table":"orderBookL2","action":"delete","data":[{"symbol":"XLMUSDT","id":52199939256,"side":"Buy"}]}
1618677668.74702: {"table":"orderBookL2","action":"insert","data":[{"symbol":"XLMUSDT","id":52199939255,"side":"Buy","size":146,"price":0.60745}]}
1618677668.760711: {"table":"orderBookL2","action":"delete","data":[{"symbol":"XLMUSDT","id":52199939488,"side":"Buy"}]}
1618677668.7671301: {"table":"orderBookL2","action":"update","data":[{"symbol":"LTCM21","id":52899998942,"side":"Sell","size":155}]}
1618677668.782767: {"table":"orderBookL2","action":"update","data":[{"symbol":"LTCM21","id":52899998944,"side":"Sell","size":73}]}
1618677668.794987: {"table":"orderBookL2","action":"delete","data":[{"symbol":"LTCUSD","id":40699968191,"side":"Sell"},{"symbol":"LTCUSD","id":40699968414,"side":"Sell"},{"symbol":"LTCUSD","id":40699968635,"side":"Sell"},{"symbol":"LTCUSD","id":40699969224,"side":"Buy"}]}
1618677668.7951438: {"table":"orderBookL2","action":"insert","data":[{"symbol":"LTCUSD","id":40699968187,"side":"Sell","size":579,"price":318.13},{"symbol":"LTCUSD","id":40699968410,"side":"Sell","size":579,"price":315.9},{"symbol":"LTCUSD","id":40699968623,"side":"Sell","size":579,"price":313.77},{"symbol":"LTCUSD","id":40699969225,"side":"Buy","size":579,"price":307.75}]}
1618677668.811848: {"table":"orderBookL2","action":"insert","data":[{"symbol":"LTCUSD","id":40699968757,"side":"Buy","size":247,"price":312.43}]}
1618677668.828981: {"table":"orderBookL2","action":"delete","data":[{"symbol":"LINKUSDTM21","id":52799885008,"side":"Sell"}]}
1618677668.829063: {"table":"orderBookL2","action":"insert","data":[{"symbol":"LINKUSDTM21","id":52799885066,"side":"Sell","size":330,"price":57.467}]}
1618677668.8601549: {"table":"orderBookL2","action":"update","data":[{"symbol":"LTCUSD","id":40699968738,"side":"Buy","size":20}]}
1618677668.860254: {"table":"orderBookL2","action":"insert","data":[{"symbol":"LTCUSD","id":40699968773,"side":"Buy","size":104,"price":312.27}]}
1618677668.895309: {"table":"orderBookL2","action":"update","data":[{"symbol":"LTCM21","id":52899998914,"side":"Sell","size":1},{"symbol":"LTCM21","id":52899998922,"side":"Sell","size":491},{"symbol":"LTCM21","id":52899998926,"side":"Sell","size":277},{"symbol":"LTCM21","id":52899998932,"side":"Sell","size":280},{"symbol":"LTCM21","id":52899998972,"side":"Buy","size":158},{"symbol":"LTCM21","id":52899998978,"side":"Buy","size":527}]}
1618677668.921885: {"table":"orderBookL2","action":"insert","data":[{"symbol":"XLMUSDT","id":52199939498,"side":"Buy","size":47,"price":0.60502}]}
1618677668.923458: {"table":"orderBookL2","action":"insert","data":[{"symbol":"DOGEUSDT","id":47599971482,"side":"Sell","size":348,"price":0.28518}]}
1618677668.938584: {"table":"orderBookL2","action":"delete","data":[{"symbol":"DOGEUSDT","id":47599971482,"side":"Sell"}]}
1618677669.078902: {"table":"orderBookL2","action":"delete","data":[{"symbol":"DOGEUSDT","id":47599972100,"side":"Buy"}]}
1618677669.087971: {"table":"orderBookL2","action":"delete","data":[{"symbol":"LTCUSD","id":40699968187,"side":"Sell"},{"symbol":"LTCUSD","id":40699968410,"side":"Sell"},{"symbol":"LTCUSD","id":40699968623,"side":"Sell"},{"symbol":"LTCUSD","id":40699969225,"side":"Buy"}]}
1618677669.088126: {"table":"orderBookL2","action":"update","data":[{"symbol":"LTCUSD","id":40699969027,"side":"Buy","size":1817},{"symbol":"LTCUSD","id":40699969222,"side":"Buy","size":2407}]}
1618677669.088182: {"table":"orderBookL2","action":"insert","data":[{"symbol":"LTCUSD","id":40699968192,"side":"Sell","size":579,"price":318.08},{"symbol":"LTCUSD","id":40699968413,"side":"Sell","size":579,"price":315.87},{"symbol":"LTCUSD","id":40699968635,"side":"Sell","size":579,"price":313.65},{"symbol":"LTCUSD","id":40699969018,"side":"Buy","size":579,"price":309.82}]}
1618677669.102279: {"table":"orderBookL2","action":"update","data":[{"symbol":"LTCUSD","id":40699968757,"side":"Buy","size":483}]}
1618677669.120576: {"table":"orderBookL2","action":"update","data":[{"symbol":"LTCUSD","id":40699968678,"side":"Sell","size":577}]}
1618677669.1206741: {"table":"orderBookL2","action":"insert","data":[{"symbol":"LTCUSD","id":40699968680,"side":"Sell","size":452,"price":313.2}]}
1618677669.146174: {"table":"orderBookL2","action":"delete","data":[{"symbol":"LTCUSD","id":40699968811,"side":"Buy"}]}
1618677669.2017531: {"table":"orderBookL2","action":"insert","data":[{"symbol":"XLMUSDT","id":52199939468,"side":"Buy","size":64,"price":0.60532}]}
1618677669.21932: {"table":"orderBookL2","action":"update","data":[{"symbol":"LTCUSD","id":40699968652,"side":"Sell","size":17},{"symbol":"LTCUSD","id":40699968680,"side":"Sell","size":699}]}
1618677669.2728279: {"table":"orderBookL2","action":"update","data":[{"symbol":"LTCUSD","id":40699968668,"side":"Sell","size":652}]}
1618677669.2728908: {"table":"orderBookL2","action":"insert","data":[{"symbol":"LTCUSD","id":40699968681,"side":"Sell","size":125,"price":313.19}]}
1618677669.30701: {"table":"orderBookL2","action":"delete","data":[{"symbol":"XLMUSDT","id":52199939527,"side":"Buy"}]}
1618677669.307147: {"table":"orderBookL2","action":"insert","data":[{"symbol":"XLMUSDT","id":52199939467,"side":"Buy","size":375,"price":0.60533}]}
1618677669.314304: {"table":"orderBookL2","action":"update","data":[{"symbol":"LTCUSD","id":40699968678,"side":"Sell","size":39}]}
1618677669.3144078: {"table":"orderBookL2","action":"insert","data":[{"symbol":"LTCUSD","id":40699968690,"side":"Sell","size":538,"price":313.1}]}
1618677669.334473: {"table":"orderBookL2","action":"insert","data":[{"symbol":"LTCUSD","id":40699968691,"side":"Sell","size":39,"price":313.09}]}
1618677669.384128: {"table":"orderBookL2","action":"delete","data":[{"symbol":"LTCUSD","id":40699968192,"side":"Sell"},{"symbol":"LTCUSD","id":40699968413,"side":"Sell"},{"symbol":"LTCUSD","id":40699968635,"side":"Sell"},{"symbol":"LTCUSD","id":40699969018,"side":"Buy"}]}
1618677669.384282: {"table":"orderBookL2","action":"update","data":[{"symbol":"LTCUSD","id":40699969222,"side":"Buy","size":1828}]}
1618677669.384332: {"table":"orderBookL2","action":"insert","data":[{"symbol":"LTCUSD","id":40699968199,"side":"Sell","size":579,"price":318.01},{"symbol":"LTCUSD","id":40699968420,"side":"Sell","size":579,"price":315.8},{"symbol":"LTCUSD","id":40699968637,"side":"Sell","size":579,"price":313.63},{"symbol":"LTCUSD","id":40699969023,"side":"Buy","size":579,"price":309.77},{"symbol":"LTCUSD","id":40699969227,"side":"Buy","size":579,"price":307.73}]}
1618677669.424842: {"table":"orderBookL2","action":"delete","data":[{"symbol":"LTCUSD","id":40699968653,"side":"Sell"}]}
1618677669.424959: {"table":"orderBookL2","action":"update","data":[{"symbol":"LTCUSD","id":40699968679,"side":"Sell","size":473}]}
1618677669.425007: {"table":"orderBookL2","action":"update","data":[{"symbol":"LTCUSD","id":40699968679,"side":"Sell","size":341}]}
1618677669.425436: {"table":"orderBookL2","action":"insert","data":[{"symbol":"LTCUSD","id":40699968697,"side":"Sell","size":132,"price":313.03}]}
1618677669.587355: {"table":"orderBookL2","action":"insert","data":[{"symbol":"DOGEUSDT","id":47599971455,"side":"Sell","size":301,"price":0.28545},{"symbol":"DOGEUSDT","id":47599971547,"side":"Buy","size":4000,"price":0.28453}]}
1618677669.5931652: {"table":"orderBookL2","action":"update","data":[{"symbol":"LTCUSD","id":40699968697,"side":"Sell","size":112}]}
1618677669.6198342: {"table":"orderBookL2","action":"update","data":[{"symbol":"TRXM21","id":52999999704,"side":"Sell","size":128558},{"symbol":"TRXM21","id":52999999767,"side":"Buy","size":217996},{"symbol":"TRXM21","id":52999999782,"side":"Buy","size":122025}]}
1618677669.636873: {"table":"orderBookL2","action":"delete","data":[{"symbol":"LTCUSD","id":40699968697,"side":"Sell"}]}
1618677669.791818: {"table":"orderBookL2","action":"insert","data":[{"symbol":"LTCUSD","id":40699968673,"side":"Sell","size":106,"price":313.27}]}
1618677669.791944: {"table":"orderBookL2","action":"insert","data":[{"symbol":"LTCUSD","id":40699968830,"side":"Buy","size":106,"price":311.7}]}
1618677669.817575: {"table":"orderBookL2","action":"update","data":[{"symbol":"LTCUSD","id":40699968757,"side":"Buy","size":236}]}
1618677669.90952: {"table":"orderBookL2","action":"update","data":[{"symbol":"LTCUSD","id":40699968760,"side":"Buy","size":932}]}
1618677669.97706: {"table":"orderBookL2","action":"insert","data":[{"symbol":"XLMUSDT","id":52199939443,"side":"Buy","size":68,"price":0.60557}]}
1618677669.9956229: {"table":"orderBookL2","action":"insert","data":[{"symbol":"LTCUSD","id":40699968692,"side":"Sell","size":268,"price":313.08}]}
1618677670.093547: {"table":"orderBookL2","action":"delete","data":[{"symbol":"LTCUSD","id":40699968199,"side":"Sell"},{"symbol":"LTCUSD","id":40699968420,"side":"Sell"},{"symbol":"LTCUSD","id":40699969023,"side":"Buy"},{"symbol":"LTCUSD","id":40699969227,"side":"Buy"}]}
1618677670.093708: {"table":"orderBookL2","action":"update","data":[{"symbol":"LTCUSD","id":40699968508,"side":"Sell","size":300}]}
1618677670.093761: {"table":"orderBookL2","action":"insert","data":[{"symbol":"LTCUSD","id":40699968200,"side":"Sell","size":579,"price":318},{"symbol":"LTCUSD","id":40699968421,"side":"Sell","size":579,"price":315.79},{"symbol":"LTCUSD","id":40699968532,"side":"Sell","size":579,"price":314.68},{"symbol":"LTCUSD","id":40699969024,"side":"Buy","size":579,"price":309.76},{"symbol":"LTCUSD","id":40699969228,"side":"Buy","size":579,"price":307.72}]}
1618677670.146754: {"table":"orderBookL2","action":"update","data":[{"symbol":"LTCUSD","id":40699968655,"side":"Sell","size":295}]}
1618677670.173629: {"table":"orderBookL2","action":"insert","data":[{"symbol":"LTCUSD","id":40699968675,"side":"Sell","size":5000,"price":313.25}]}
1618677670.173727: {"table":"orderBookL2","action":"update","data":[{"symbol":"LTCUSD","id":40699968680,"side":"Sell","size":247}]}
1618677670.173752: {"table":"orderBookL2","action":"insert","data":[{"symbol":"LTCUSD","id":40699968693,"side":"Sell","size":452,"price":313.07}]}
1618677670.184787: {"table":"orderBookL2","action":"delete","data":[{"symbol":"TRXUSDT","id":53999983851,"side":"Sell"}]}
1618677670.190033: {"table":"orderBookL2","action":"insert","data":[{"symbol":"TRXUSDT","id":53999983889,"side":"Sell","size":5080,"price":0.16111}]}
1618677670.195182: {"table":"orderBookL2","action":"delete","data":[{"symbol":"LTCUSD","id":40699968692,"side":"Sell"}]}
1618677670.195304: {"table":"orderBookL2","action":"insert","data":[{"symbol":"LTCUSD","id":40699968694,"side":"Sell","size":264,"price":313.06}]}
1618677670.245206: {"table":"orderBookL2","action":"delete","data":[{"symbol":"EOSM21","id":52499998747,"side":"Buy"}]}
1618677670.2453198: {"table":"orderBookL2","action":"update","data":[{"symbol":"EOSM21","id":52499998743,"side":"Buy","size":985}]}
1618677670.2720902: {"table":"orderBookL2","action":"update","data":[{"symbol":"LTCM21","id":52899998948,"side":"Buy","size":202}]}
1618677670.279707: {"table":"orderBookL2","action":"update","data":[{"symbol":"LTCM21","id":52899998949,"side":"Buy","size":24}]}
1618677670.326375: {"table":"orderBookL2","action":"update","data":[{"symbol":"EOSUSDT","id":53899984095,"side":"Sell","size":64}]}
1618677670.326473: {"table":"orderBookL2","action":"delete","data":[{"symbol":"DOGEUSDT","id":47599971777,"side":"Buy"}]}
1618677670.326796: {"table":"orderBookL2","action":"insert","data":[{"symbol":"DOGEUSDT","id":47599971790,"side":"Buy","size":154,"price":0.2821}]}
1618677670.328598: {"table":"orderBookL2","action":"insert","data":[{"symbol":"EOSUSDT","id":53899984172,"side":"Buy","size":50,"price":7.914}]}
1618677670.3940322: {"table":"orderBookL2","action":"delete","data":[{"symbol":"LTCUSD","id":40699968757,"side":"Buy"}]}
1618677670.409021: {"table":"orderBookL2","action":"update","data":[{"symbol":"LTCUSD","id":40699968760,"side":"Buy","size":685}]}
1618677670.4114969: {"table":"orderBookL2","action":"delete","data":[{"symbol":"LTCUSD","id":40699968200,"side":"Sell"},{"symbol":"LTCUSD","id":40699968421,"side":"Sell"},{"symbol":"LTCUSD","id":40699969024,"side":"Buy"},{"symbol":"LTCUSD","id":40699969228,"side":"Buy"}]}
1618677670.411662: {"table":"orderBookL2","action":"insert","data":[{"symbol":"LTCUSD","id":40699968201,"side":"Sell","size":579,"price":317.99},{"symbol":"LTCUSD","id":40699968422,"side":"Sell","size":579,"price":315.78},{"symbol":"LTCUSD","id":40699969023,"side":"Buy","size":579,"price":309.77},{"symbol":"LTCUSD","id":40699969226,"side":"Buy","size":579,"price":307.74}]}
1618677670.411777: {"table":"orderBookL2","action":"update","data":[{"symbol":"LTCUSD","id":40699968739,"side":"Buy","size":39}]}
1618677670.464344: {"table":"orderBookL2","action":"insert","data":[{"symbol":"LTCUSD","id":40699968761,"side":"Buy","size":5000,"price":312.39}]}
1618677670.480282: {"table":"orderBookL2","action":"insert","data":[{"symbol":"LTCUSD","id":40699968772,"side":"Buy","size":227,"price":312.28}]}
1618677670.482372: {"table":"orderBookL2","action":"update","data":[{"symbol":"LTCUSD","id":40699968764,"side":"Buy","size":275}]}
1618677670.48975: {"table":"orderBookL2","action":"delete","data":[{"symbol":"LTCUSD","id":40699968201,"side":"Sell"},{"symbol":"LTCUSD","id":40699968422,"side":"Sell"},{"symbol":"LTCUSD","id":40699968532,"side":"Sell"}]}
1618677670.489892: {"table":"orderBookL2","action":"insert","data":[{"symbol":"LTCUSD","id":40699968203,"side":"Sell","size":579,"price":317.97},{"symbol":"LTCUSD","id":40699968423,"side":"Sell","size":579,"price":315.77},{"symbol":"LTCUSD","id":40699968533,"side":"Sell","size":579,"price":314.67}]}
1618677670.489991: {"table":"orderBookL2","action":"delete","data":[{"symbol":"LTCUSD","id":40699968690,"side":"Sell"}]}
1618677670.490037: {"table":"orderBookL2","action":"insert","data":[{"symbol":"LTCUSD","id":40699968701,"side":"Sell","size":538,"price":312.99}]}
1618677670.4929368: {"table":"orderBookL2","action":"delete","data":[{"symbol":"LTCUSD","id":40699968637,"side":"Sell"},{"symbol":"LTCUSD","id":40699969023,"side":"Buy"},{"symbol":"LTCUSD","id":40699969226,"side":"Buy"}]}
1618677670.493081: {"table":"orderBookL2","action":"update","data":[{"symbol":"LTCUSD","id":40699968647,"side":"Sell","size":825},{"symbol":"LTCUSD","id":40699969027,"side":"Buy","size":2396}]}
1618677670.4931378: {"table":"orderBookL2","action":"insert","data":[{"symbol":"LTCUSD","id":40699969229,"side":"Buy","size":579,"price":307.71}]}
1618677670.501524: {"table":"orderBookL2","action":"update","data":[{"symbol":"LTCUSD","id":40699968764,"side":"Buy","size":39}]}
1618677670.519656: {"table":"orderBookL2","action":"delete","data":[{"symbol":"LTCUSD","id":40699968694,"side":"Sell"}]}
1618677670.5197718: {"table":"orderBookL2","action":"insert","data":[{"symbol":"LTCUSD","id":40699968702,"side":"Sell","size":50,"price":312.98}]}
1618677670.519953: {"table":"orderBookL2","action":"delete","data":[{"symbol":"LTCUSD","id":40699968727,"side":"Buy"}]}
1618677670.552885: {"table":"orderBookL2","action":"update","data":[{"symbol":"LTCM21","id":52899998946,"side":"Buy","size":5}]}
1618677670.560126: {"table":"orderBookL2","action":"update","data":[{"symbol":"LTCUSD","id":40699968948,"side":"Buy","size":2729}]}
1618677670.582046: {"table":"orderBookL2","action":"delete","data":[{"symbol":"LTCUSD","id":40699968772,"side":"Buy"}]}
1618677670.607903: {"table":"orderBookL2","action":"delete","data":[{"symbol":"EOSUSDT","id":53899984017,"side":"Sell"}]}
1618677670.608022: {"table":"orderBookL2","action":"insert","data":[{"symbol":"EOSUSDT","id":53899984036,"side":"Sell","size":496,"price":7.982}]}
1618677670.608095: {"table":"orderBookL2","action":"delete","data":[{"symbol":"EOSUSDT","id":53899984172,"side":"Buy"}]}
1618677670.6081421: {"table":"orderBookL2","action":"insert","data":[{"symbol":"EOSUSDT","id":53899984179,"side":"Buy","size":59,"price":7.9105}]}
1618677670.608191: {"table":"orderBookL2","action":"delete","data":[{"symbol":"LTCUSD","id":40699968673,"side":"Sell"}]}
1618677670.623544: {"table":"orderBookL2","action":"delete","data":[{"symbol":"LTCUSD","id":40699968761,"side":"Buy"}]}
1618677670.643477: {"table":"orderBookL2","action":"insert","data":[{"symbol":"LTCUSD","id":40699968781,"side":"Buy","size":5000,"price":312.19}]}
1618677670.643606: {"table":"orderBookL2","action":"insert","data":[{"symbol":"LTCUSD","id":40699968672,"side":"Sell","size":158,"price":313.28}]}
1618677670.643669: {"table":"orderBookL2","action":"delete","data":[{"symbol":"LTCUSD","id":40699968830,"side":"Buy"}]}
1618677670.694714: {"table":"orderBookL2","action":"update","data":[{"symbol":"LTCUSD","id":40699968769,"side":"Buy","size":155}]}
1618677670.694814: {"table":"orderBookL2","action":"insert","data":[{"symbol":"LTCUSD","id":40699968833,"side":"Buy","size":43,"price":311.67}]}
1618677670.716353: {"table":"orderBookL2","action":"delete","data":[{"symbol":"LTCUSD","id":40699968701,"side":"Sell"}]}
1618677670.71647: {"table":"orderBookL2","action":"insert","data":[{"symbol":"LTCUSD","id":40699968711,"side":"Sell","size":538,"price":312.89}]}
1618677670.718524: {"table":"orderBookL2","action":"delete","data":[{"symbol":"LTCUSD","id":40699968675,"side":"Sell"}]}
1618677670.7323399: {"table":"orderBookL2","action":"insert","data":[{"symbol":"LTCUSD","id":40699968695,"side":"Sell","size":5000,"price":313.05}]}
1618677670.751887: {"table":"orderBookL2","action":"update","data":[{"symbol":"LTCUSD","id":40699968679,"side":"Sell","size":105},{"symbol":"LTCUSD","id":40699968702,"side":"Sell","size":286}]}
1618677670.781109: {"table":"orderBookL2","action":"delete","data":[{"symbol":"LTCUSD","id":40699968773,"side":"Buy"}]}
1618677670.781227: {"table":"orderBookL2","action":"insert","data":[{"symbol":"LTCUSD","id":40699968798,"side":"Buy","size":104,"price":312.02}]}
1618677670.784456: {"table":"orderBookL2","action":"delete","data":[{"symbol":"LTCUSD","id":40699968769,"side":"Buy"}]}
1618677670.784517: {"table":"orderBookL2","action":"insert","data":[{"symbol":"LTCUSD","id":40699968854,"side":"Buy","size":177,"price":311.46}]}
1618677670.7978659: {"table":"orderBookL2","action":"delete","data":[{"symbol":"LTCUSD","id":40699968739,"side":"Buy"}]}
1618677670.7983959: {"table":"orderBookL2","action":"delete","data":[{"symbol":"LTCUSD","id":40699968634,"side":"Sell"}]}
1618677670.8032231: {"table":"orderBookL2","action":"delete","data":[{"symbol":"LTCUSD","id":40699968203,"side":"Sell"},{"symbol":"LTCUSD","id":40699968423,"side":"Sell"},{"symbol":"LTCUSD","id":40699968533,"side":"Sell"},{"symbol":"LTCUSD","id":40699969229,"side":"Buy"}]}
1618677670.803385: {"table":"orderBookL2","action":"update","data":[{"symbol":"LTCUSD","id":40699968550,"side":"Sell","size":605},{"symbol":"LTCUSD","id":40699968647,"side":"Sell","size":246},{"symbol":"LTCUSD","id":40699969027,"side":"Buy","size":1817}]}
1618677670.803447: {"table":"orderBookL2","action":"insert","data":[{"symbol":"LTCUSD","id":40699968222,"side":"Sell","size":580,"price":317.78},{"symbol":"LTCUSD","id":40699968442,"side":"Sell","size":580,"price":315.58},{"symbol":"LTCUSD","id":40699968658,"side":"Sell","size":580,"price":313.42},{"symbol":"LTCUSD","id":40699969042,"side":"Buy","size":580,"price":309.58},{"symbol":"LTCUSD","id":40699969245,"side":"Buy","size":580,"price":307.55}]}
1618677670.8455942: {"table":"orderBookL2","action":"delete","data":[{"symbol":"LTCUSD","id":40699968738,"side":"Buy"}]}
1618677670.863929: {"table":"orderBookL2","action":"delete","data":[{"symbol":"LTCUSD","id":40699968779,"side":"Buy"}]}
1618677670.8640482: {"table":"orderBookL2","action":"insert","data":[{"symbol":"LTCUSD","id":40699968805,"side":"Buy","size":133,"price":311.95}]}
1618677670.875803: {"table":"orderBookL2","action":"delete","data":[{"symbol":"LTCUSD","id":40699968777,"side":"Buy"}]}
1618677670.882329: {"table":"orderBookL2","action":"delete","data":[{"symbol":"LTCUSD","id":40699968222,"side":"Sell"},{"symbol":"LTCUSD","id":40699968442,"side":"Sell"},{"symbol":"LTCUSD","id":40699969245,"side":"Buy"}]}
1618677670.8824792: {"table":"orderBookL2","action":"insert","data":[{"symbol":"LTCUSD","id":40699968221,"side":"Sell","size":580,"price":317.79},{"symbol":"LTCUSD","id":40699968441,"side":"Sell","size":580,"price":315.59},{"symbol":"LTCUSD","id":40699969244,"side":"Buy","size":580,"price":307.56}]}
1618677670.8825989: {"table":"orderBookL2","action":"insert","data":[{"symbol":"XLMUSDT","id":52199939412,"side":"Buy","size":45,"price":0.60588}]}
1618677670.88533: {"table":"orderBookL2","action":"delete","data":[{"symbol":"XLMUSDT","id":52199939528,"side":"Buy"}]}
1618677670.8965518: {"table":"orderBookL2","action":"delete","data":[{"symbol":"LTCUSD","id":40699968760,"side":"Buy"}]}
1618677670.906427: {"table":"orderBookL2","action":"delete","data":[{"symbol":"LTCUSD","id":40699969244,"side":"Buy"}]}
1618677670.9065442: {"table":"orderBookL2","action":"insert","data":[{"symbol":"LTCUSD","id":40699969243,"side":"Buy","size":580,"price":307.57}]}
1618677670.919851: {"table":"orderBookL2","action":"insert","data":[{"symbol":"LTCUSD","id":40699968778,"side":"Buy","size":20,"price":312.22}]}
1618677670.926524: {"table":"orderBookL2","action":"insert","data":[{"symbol":"DOGEUSDT","id":47599971486,"side":"Sell","size":348,"price":0.28514}]}
1618677670.968705: {"table":"orderBookL2","action":"delete","data":[{"symbol":"LTCUSD","id":40699968680,"side":"Sell"}]}
1618677670.968819: {"table":"orderBookL2","action":"update","data":[{"symbol":"LTCUSD","id":40699968693,"side":"Sell","size":699}]}
1618677670.984556: {"table":"orderBookL2","action":"insert","data":[{"symbol":"LTCUSD","id":40699968759,"side":"Buy","size":1,"price":312.41}]}
1618677670.997787: {"table":"orderBookL2","action":"delete","data":[{"symbol":"LTCUSD","id":40699968759,"side":"Buy"}]}
1618677671.010772: {"table":"orderBookL2","action":"insert","data":[{"symbol":"LTCUSD","id":40699968763,"side":"Buy","size":1,"price":312.37}]}
1618677671.0264268: {"table":"orderBookL2","action":"delete","data":[{"symbol":"LTCUSD","id":40699968785,"side":"Buy"}]}
1618677671.050157: {"table":"orderBookL2","action":"update","data":[{"symbol":"LTCUSD","id":40699968693,"side":"Sell","size":247}]}
1618677671.050227: {"table":"orderBookL2","action":"insert","data":[{"symbol":"LTCUSD","id":40699968712,"side":"Sell","size":452,"price":312.88}]}
1618677671.0593321: {"table":"orderBookL2","action":"update","data":[{"symbol":"LTCUSD","id":40699968702,"side":"Sell","size":50},{"symbol":"LTCUSD","id":40699968712,"side":"Sell","size":688}]}
1618677671.061007: {"table":"orderBookL2","action":"delete","data":[{"symbol":"LTCUSD","id":40699968702,"side":"Sell"}]}
1618677671.073088: {"table":"orderBookL2","action":"delete","data":[{"symbol":"LTCUSD","id":40699968221,"side":"Sell"},{"symbol":"LTCUSD","id":40699968441,"side":"Sell"}]}
1618677671.07322: {"table":"orderBookL2","action":"update","data":[{"symbol":"LTCUSD","id":40699968437,"side":"Sell","size":2363},{"symbol":"LTCUSD","id":40699968550,"side":"Sell","size":25}]}
1618677671.0732758: {"table":"orderBookL2","action":"insert","data":[{"symbol":"LTCUSD","id":40699968216,"side":"Sell","size":580,"price":317.84},{"symbol":"LTCUSD","id":40699968548,"side":"Sell","size":580,"price":314.52}]}
1618677671.073351: {"table":"orderBookL2","action":"update","data":[{"symbol":"LTCUSD","id":40699968712,"side":"Sell","size":236}]}
1618677671.073385: {"table":"orderBookL2","action":"insert","data":[{"symbol":"LTCUSD","id":40699968713,"side":"Sell","size":452,"price":312.87}]}
