wss://ws.bitstamp.net/ <-> 1618677690.992526
wss://ws.bitstamp.net/ <- 1618677691.495689: {"event":"bts:subscribe","data":{"channel":"diff_order_book_ltcusd"}}
wss://ws.bitstamp.net/ <- 1618677691.495797: {"event":"bts:subscribe","data":{"channel":"diff_order_book_ethgbp"}}
wss://ws.bitstamp.net/ <- 1618677691.4958642: {"event":"bts:subscribe","data":{"channel":"diff_order_book_btcusd"}}
wss://ws.bitstamp.net/ <- 1618677691.495918: {"event":"bts:subscribe","data":{"channel":"diff_order_book_bchgbp"}}
wss://ws.bitstamp.net/ <- 1618677691.495973: {"event":"bts:subscribe","data":{"channel":"diff_order_book_knceur"}}
wss://ws.bitstamp.net/ <- 1618677691.496023: {"event":"bts:subscribe","data":{"channel":"diff_order_book_linkbtc"}}
wss://ws.bitstamp.net/ <- 1618677691.496072: {"event":"bts:subscribe","data":{"channel":"diff_order_book_gbpusd"}}
wss://ws.bitstamp.net/ <- 1618677691.496119: {"event":"bts:subscribe","data":{"channel":"diff_order_book_gusdusd"}}
wss://ws.bitstamp.net/ <- 1618677691.496166: {"event":"bts:subscribe","data":{"channel":"diff_order_book_bcheur"}}
wss://ws.bitstamp.net/ <- 1618677691.496215: {"event":"bts:subscribe","data":{"channel":"diff_order_book_kncusd"}}
wss://ws.bitstamp.net/ <- 1618677691.496263: {"event":"bts:subscribe","data":{"channel":"live_trades_ltcusd"}}
wss://ws.bitstamp.net/ <- 1618677691.496311: {"event":"bts:subscribe","data":{"channel":"live_trades_ethgbp"}}
wss://ws.bitstamp.net/ <- 1618677691.4963572: {"event":"bts:subscribe","data":{"channel":"live_trades_btcusd"}}
wss://ws.bitstamp.net/ <- 1618677691.496402: {"event":"bts:subscribe","data":{"channel":"live_trades_bchgbp"}}
wss://ws.bitstamp.net/ <- 1618677691.496449: {"event":"bts:subscribe","data":{"channel":"live_trades_knceur"}}
wss://ws.bitstamp.net/ <- 1618677691.496494: {"event":"bts:subscribe","data":{"channel":"live_trades_linkbtc"}}
wss://ws.bitstamp.net/ <- 1618677691.4965389: {"event":"bts:subscribe","data":{"channel":"live_trades_gbpusd"}}
wss://ws.bitstamp.net/ <- 1618677691.496586: {"event":"bts:subscribe","data":{"channel":"live_trades_gusdusd"}}
wss://ws.bitstamp.net/ <- 1618677691.4966311: {"event":"bts:subscribe","data":{"channel":"live_trades_bcheur"}}
wss://ws.bitstamp.net/ <- 1618677691.4966779: {"event":"bts:subscribe","data":{"channel":"live_trades_kncusd"}}
1618677697.763598: {"event":"bts:subscription_succeeded","channel":"diff_order_book_ltcusd","data":{}}
1618677697.763608: {"event":"bts:subscription_succeeded","channel":"diff_order_book_ethgbp","data":{}}
1618677697.7636118: {"event":"bts:subscription_succeeded","channel":"diff_order_book_btcusd","data":{}}
1618677697.763616: {"event":"bts:subscription_succeeded","channel":"diff_order_book_bchgbp","data":{}}
1618677697.7636192: {"event":"bts:subscription_succeeded","channel":"diff_order_book_knceur","data":{}}
1618677697.7636218: {"event":"bts:subscription_succeeded","channel":"diff_order_book_linkbtc","data":{}}
1618677697.763625: {"event":"bts:subscription_succeeded","channel":"diff_order_book_gbpusd","data":{}}
1618677697.763628: {"event":"bts:subscription_succeeded","channel":"diff_order_book_gusdusd","data":{}}
1618677697.763631: {"event":"bts:subscription_succeeded","channel":"diff_order_book_bcheur","data":{}}
1618677697.763634: {"event":"bts:subscription_succeeded","channel":"diff_order_book_kncusd","data":{}}
1618677697.763637: {"event":"bts:subscription_succeeded","channel":"live_trades_ltcusd","data":{}}
1618677697.7636402: {"event":"bts:subscription_succeeded","channel":"live_trades_ethgbp","data":{}}
1618677697.7636428: {"event":"bts:subscription_succeeded","channel":"live_trades_btcusd","data":{}}
1618677697.763646: {"event":"bts:subscription_succeeded","channel":"live_trades_bchgbp","data":{}}
1618677697.763649: {"event":"bts:subscription_succeeded","channel":"live_trades_knceur","data":{}}
1618677697.763652: {"event":"bts:subscription_succeeded","channel":"live_trades_linkbtc","data":{}}
1618677697.763655: {"event":"bts:subscription_succeeded","channel":"live_trades_gbpusd","data":{}}
1618677697.763658: {"event":"bts:subscription_succeeded","channel":"live_trades_gusdusd","data":{}}
1618677697.7636611: {"event":"bts:subscription_succeeded","channel":"live_trades_bcheur","data":{}}
1618677697.7636638: {"event":"bts:subscription_succeeded","channel":"live_trades_kncusd","data":{}}
1618677697.7636669: {"data":{"timestamp":"1618677691","microtimestamp":"1618677691471830","bids":[],"asks":[["60567.75","0.00000000"],["60576.78","0.34836429"],["60623.12","0.00000000"],["60653.97","0.00000000"],["60803.33","0.52587429"],["60864.76","0.00000000"]]},"channel":"diff_order_book_btcusd","event":"data"}
1618677697.763683: {"data":{"timestamp":"1618677691","microtimestamp":"1618677691591574","bids":[["309.68","0.00000000"],["305.41","0.00000000"]],"asks":[]},"channel":"diff_order_book_ltcusd","event":"data"}
1618677697.763691: {"data":{"timestamp":"1618677691","microtimestamp":"1618677691609137","bids":[["882.47","3.00000000"],["882.45","41.25600136"],["881.44","7.97778798"]],"asks":[["883.84","2.37684468"],["884.02","2.90000000"],["884.15","2.20000000"],["884.85","2.37684468"],["885.90","6.00000000"]]},"channel":"diff_order_book_bcheur","event":"data"}
1618677697.763699: {"data":{"timestamp":"1618677691","microtimestamp":"1618677691719149","bids":[["0.00067852","0.00000000"]],"asks":[]},"channel":"diff_order_book_linkbtc","event":"data"}
1618677697.763705: {"data":{"timestamp":"1618677691","microtimestamp":"1618677691765808","bids":[["882.47","0.00000000"],["882.45","0.00000000"]],"asks":[["883.99","2.90000000"],["884.02","0.00000000"],["884.15","0.00000000"],["885.99","8.38400000"]]},"channel":"diff_order_book_bcheur","event":"data"}
1618677697.763712: {"data":{"timestamp":"1618677691","microtimestamp":"1618677691838074","bids":[["0.00067782","24.33388041"]],"asks":[]},"channel":"diff_order_book_linkbtc","event":"data"}
1618677697.763718: {"data":{"timestamp":"1618677691","microtimestamp":"1618677691945861","bids":[["882.46","44.25600136"]],"asks":[["883.80","3.00000000"],["883.99","0.00000000"],["884.00","2.20000000"],["884.05","0.00000000"],["884.35","0.00000000"],["884.45","5.36727464"]]},"channel":"diff_order_book_bcheur","event":"data"}
1618677697.763725: {"data":{"timestamp":"1618677691","microtimestamp":"1618677691961541","bids":[["60526.75","0.12391066"],["60520.52","0.00000000"],["59935.00","0.40338395"]],"asks":[["60550.78","0.00000000"],["60553.97","0.00000000"],["60557.07","0.12391066"],["60560.09","0.16521421"],["60564.51","0.19738221"],["60576.78","0.00000000"],["60601.79","0.03192428"],["60621.06","0.37766248"],["60803.33","0.00000000"],["61544.68","0.49868513"]]},"channel":"diff_order_book_btcusd","event":"data"}
1618677697.763733: {"data":{"timestamp":"1618677692","microtimestamp":"1618677692079864","bids":[["2.82322","0.00000000"],["2.82244","100.00000000"]],"asks":[]},"channel":"diff_order_book_knceur","event":"data"}
1618677697.7637389: {"data":{"timestamp":"1618677692","microtimestamp":"1618677692068730","bids":[["3.37540","3942.58371000"]],"asks":[["3.39237","1595.50677000"]]},"channel":"diff_order_book_kncusd","event":"data"}
1618677697.763746: {"data":{"timestamp":"1618677692","microtimestamp":"1618677692094825","bids":[["882.46","0.00000000"]],"asks":[["883.70","2.80000000"],["884.15","0.73303373"]]},"channel":"diff_order_book_bcheur","event":"data"}
1618677697.763752: {"data":{"timestamp":"1618677692","microtimestamp":"1618677692211859","bids":[["0.00067818","0.00000000"]],"asks":[]},"channel":"diff_order_book_linkbtc","event":"data"}
1618677697.7637582: {"data":{"timestamp":"1618677692","microtimestamp":"1618677692235013","bids":[["312.56","17.19659401"],["312.49","0.00000000"],["312.47","139.35430581"],["312.45","1.54500000"],["312.42","1.69012868"],["312.41","0.00000000"],["312.38","1.48500000"],["312.16","0.00000000"]],"asks":[["312.87","0.00000000"],["313.04","0.00000000"],["313.10","0.00000000"],["313.13","1.47000000"],["313.28","1.51500000"]]},"channel":"diff_order_book_ltcusd","event":"data"}
1618677697.763766: {"data":{"timestamp":"1618677692","microtimestamp":"1618677692255774","bids":[["882.45","37.25600136"],["882.44","56.45842000"]],"asks":[["884.00","0.00000000"]]},"channel":"diff_order_book_bcheur","event":"data"}
1618677697.763772: {"data":{"timestamp":"1618677692","microtimestamp":"1618677692328893","bids":[["0.00067800","15.89747026"]],"asks":[]},"channel":"diff_order_book_linkbtc","event":"data"}
1618677697.763778: {"data":{"timestamp":"1618677692","microtimestamp":"1618677692320772","bids":[["60485.65","0.05002508"],["59995.01","0.00142283"]],"asks":[]},"channel":"diff_order_book_btcusd","event":"data"}
1618677697.763784: {"data":{"timestamp":"1618677692","microtimestamp":"1618677692446960","bids":[["764.33","0.00000000"]],"asks":[]},"channel":"diff_order_book_bchgbp","event":"data"}
1618677697.7637901: {"data":{"timestamp":"1618677692","microtimestamp":"1618677692435755","bids":[["882.44","52.45842000"],["882.19","0.00000000"]],"asks":[["883.66","3.00000000"],["883.68","0.60794000"],["883.84","0.00000000"],["884.00","2.20000000"],["884.01","0.00000000"],["884.46","0.00000000"]]},"channel":"diff_order_book_bcheur","event":"data"}
1618677697.7637959: {"data":{"timestamp":"1618677692","microtimestamp":"1618677692441716","bids":[["312.49","305.60540000"],["312.40","0.00000000"]],"asks":[["313.02","0.00000000"]]},"channel":"diff_order_book_ltcusd","event":"data"}
1618677697.763802: {"data":{"timestamp":"1618677692","microtimestamp":"1618677692562301","bids":[],"asks":[["0.00067948","0.00000000"]]},"channel":"diff_order_book_linkbtc","event":"data"}
1618677697.763808: {"data":{"timestamp":"1618677692","microtimestamp":"1618677692564958","bids":[["763.98","0.00000000"]],"asks":[]},"channel":"diff_order_book_bchgbp","event":"data"}
1618677697.763814: {"data":{"timestamp":"1618677692","microtimestamp":"1618677692603962","bids":[["312.51","4.00000000"],["312.50","114.17858000"],["306.96","0.25886984"]],"asks":[["313.06","0.00000000"],["313.12","37.11870944"],["313.15","360.35560000"]]},"channel":"diff_order_book_ltcusd","event":"data"}
1618677697.7638211: {"data":{"timestamp":"1618677692","microtimestamp":"1618677692681391","bids":[],"asks":[["0.00067933","15.89731796"]]},"channel":"diff_order_book_linkbtc","event":"data"}
1618677697.763826: {"data":{"timestamp":"1618677692","microtimestamp":"1618677692717854","bids":[],"asks":[["884.00","0.00000000"],["884.13","2.20000000"],["884.22","37.34536000"]]},"channel":"diff_order_book_bcheur","event":"data"}
1618677697.763833: {"data":{"timestamp":"1618677692","microtimestamp":"1618677692753830","bids":[],"asks":[["312.99","4.73066231"],["313.15","361.95560000"]]},"channel":"diff_order_book_ltcusd","event":"data"}
1618677697.763839: {"data":{"timestamp":"1618677692","microtimestamp":"1618677692869197","bids":[],"asks":[["884.13","0.00000000"]]},"channel":"diff_order_book_bcheur","event":"data"}
1618677697.7638452: {"data":{"timestamp":"1618677692","microtimestamp":"1618677692915618","bids":[],"asks":[["2.85156","0.00000000"]]},"channel":"diff_order_book_knceur","event":"data"}
1618677697.763851: {"data":{"timestamp":"1618677692","microtimestamp":"1618677692795262","bids":[["60485.65","0.00000000"]],"asks":[["60564.51","0.00000000"],["60619.98","0.47645381"],["60621.06","0.00000000"],["60803.55","0.46286423"]]},"channel":"diff_order_book_btcusd","event":"data"}
1618677697.763857: {"data":{"timestamp":"1618677692","microtimestamp":"1618677692925971","bids":[],"asks":[["0.00067932","24.24088208"]]},"channel":"diff_order_book_linkbtc","event":"data"}
1618677697.763863: {"data":{"timestamp":"1618677692","microtimestamp":"1618677692932392","bids":[["312.50","0.00000000"],["312.49","0.00000000"]],"asks":[["313.15","1.60000000"]]},"channel":"diff_order_book_ltcusd","event":"data"}
1618677697.763869: {"data":{"timestamp":"1618677693","microtimestamp":"1618677693046948","bids":[],"asks":[["0.00067932","0.00000000"]]},"channel":"diff_order_book_linkbtc","event":"data"}
1618677697.763875: {"data":{"timestamp":"1618677693","microtimestamp":"1618677693105246","bids":[["312.51","0.00000000"],["312.47","4.85230581"],["312.34","4.00000000"]],"asks":[["313.06","1.47000000"]]},"channel":"diff_order_book_ltcusd","event":"data"}
1618677697.763881: {"data":{"timestamp":"1618677693","microtimestamp":"1618677693158653","bids":[["764.23","0.00000000"]],"asks":[]},"channel":"diff_order_book_bchgbp","event":"data"}
1618677697.7638872: {"data":{"timestamp":"1618677693","microtimestamp":"1618677693206549","bids":[["882.27","0.00000000"],["881.97","35.08379000"]],"asks":[["884.15","0.00000000"]]},"channel":"diff_order_book_bcheur","event":"data"}
1618677697.763893: {"data":{"timestamp":"1618677693","microtimestamp":"1618677693279161","bids":[["764.17","1.42640529"],["763.51","2.85291201"],["763.49","0.00000000"]],"asks":[]},"channel":"diff_order_book_bchgbp","event":"data"}
1618677697.7638988: {"data":{"timestamp":"1618677693","microtimestamp":"1618677693280017","bids":[["312.42","135.38002868"],["312.34","0.00000000"],["311.99","114.17858000"]],"asks":[]},"channel":"diff_order_book_ltcusd","event":"data"}
1618677697.763905: {"data":{"timestamp":"1618677693","microtimestamp":"1618677693173400","bids":[],"asks":[["60576.56","0.43080382"],["60619.98","0.00000000"],["60621.54","0.38228353"],["60803.55","0.00000000"]]},"channel":"diff_order_book_btcusd","event":"data"}
1618677697.763912: {"data":{"timestamp":"1618677693","microtimestamp":"1618677693361191","bids":[["882.45","0.00000000"],["882.44","0.00000000"],["882.22","0.00000000"],["882.19","50.23375000"],["881.98","0.73314284"],["881.79","0.00000000"]],"asks":[["883.79","2.90000000"],["884.10","2.20000000"],["884.11","0.73311454"]]},"channel":"diff_order_book_bcheur","event":"data"}
1618677697.763919: {"data":{"timestamp":"1618677693","microtimestamp":"1618677693439967","bids":[["312.58","14.70000000"],["312.43","4.00000000"],["312.41","309.18480000"],["311.99","0.00000000"]],"asks":[["312.87","14.00000000"]]},"channel":"diff_order_book_ltcusd","event":"data"}
1618677697.763925: {"channel": "live_trades_ltcusd", "data": {"amount": 6.33171283, "amount_str": "6.33171283", "buy_order_id": 1351035776413697, "id": 164507734, "microtimestamp": "1618677693509000", "price": 312.88, "price_str": "312.88", "sell_order_id": 1351035736915970, "timestamp": "1618677693", "type": 0}, "event": "trade"}
1618677697.763944: {"data":{"timestamp":"1618677693","microtimestamp":"1618677693518866","bids":[["3.37540","780.00000000"]],"asks":[["3.39237","0.00000000"]]},"channel":"diff_order_book_kncusd","event":"data"}
1618677697.763952: {"data":{"timestamp":"1618677693","microtimestamp":"1618677693529775","bids":[["882.21","4.00000000"],["882.04","2.37754540"],["881.03","2.37754540"]],"asks":[["883.66","5.37734216"],["883.79","0.00000000"],["884.10","0.00000000"],["884.85","0.00000000"]]},"channel":"diff_order_book_bcheur","event":"data"}
1618677697.763958: {"data":{"timestamp":"1618677693","microtimestamp":"1618677693591089","bids":[["312.58","14.00000000"],["312.44","5.60000000"],["312.43","114.17858000"],["312.42","133.68990000"]],"asks":[["312.87","0.00000000"],["312.88","54.07047717"],["312.99","0.00000000"],["313.06","347.47520000"],["313.89","5.40890511"]]},"channel":"diff_order_book_ltcusd","event":"data"}
1618677697.763965: {"data":{"timestamp":"1618677693","microtimestamp":"1618677693682295","bids":[["882.24","37.25600136"]],"asks":[["883.78","2.20000000"]]},"channel":"diff_order_book_bcheur","event":"data"}
1618677697.763971: {"data":{"timestamp":"1618677693","microtimestamp":"1618677693756021","bids":[["0.00067823","24.28350071"]],"asks":[]},"channel":"diff_order_book_linkbtc","event":"data"}
1618677697.763977: {"data":{"timestamp":"1618677693","microtimestamp":"1618677693658370","bids":[["60488.05","0.04960152"],["60354.77","0.00000000"],["60340.11","0.09757488"],["60253.44","0.00000000"],["60085.62","0.00000000"]],"asks":[["60557.90","0.00000000"],["60601.69","0.00000000"]]},"channel":"diff_order_book_btcusd","event":"data"}
1618677697.763984: {"data":{"timestamp":"1618677693","microtimestamp":"1618677693776463","bids":[["312.46","1.68995471"],["312.44","1.60000000"]],"asks":[]},"channel":"diff_order_book_ltcusd","event":"data"}
1618677697.763989: {"data":{"timestamp":"1618677693","microtimestamp":"1618677693828010","bids":[["882.24","0.00000000"],["882.21","0.00000000"],["881.03","0.00000000"]],"asks":[["883.78","0.00000000"]]},"channel":"diff_order_book_bcheur","event":"data"}
1618677697.763996: {"data":{"timestamp":"1618677693","microtimestamp":"1618677693875096","bids":[["0.00067823","0.00000000"]],"asks":[]},"channel":"diff_order_book_linkbtc","event":"data"}
1618677697.7640011: {"channel": "live_trades_btcusd", "data": {"amount": 0.032712, "amount_str": "0.03271200", "buy_order_id": 1351035778150400, "id": 164507735, "microtimestamp": "1618677693933000", "price": 60553.64, "price_str": "60553.64", "sell_order_id": 1351035756818432, "timestamp": "1618677693", "type": 0}, "event": "trade"}
1618677697.764013: {"data":{"timestamp":"1618677693","microtimestamp":"1618677693992060","bids":[],"asks":[["765.72","5.65316905"]]},"channel":"diff_order_book_bchgbp","event":"data"}
1618677697.764019: {"data":{"timestamp":"1618677693","microtimestamp":"1618677693949900","bids":[["312.45","5.54500000"]],"asks":[["318.87","63.07060788"]]},"channel":"diff_order_book_ltcusd","event":"data"}
1618677697.7640262: {"data":{"timestamp":"1618677693","microtimestamp":"1618677693984760","bids":[["882.21","4.00000000"],["882.20","40.25600136"]],"asks":[["883.79","2.20000000"]]},"channel":"diff_order_book_bcheur","event":"data"}
1618677697.764033: {"data":{"timestamp":"1618677694","microtimestamp":"1618677694112644","bids":[],"asks":[["765.72","2.85316905"]]},"channel":"diff_order_book_bchgbp","event":"data"}
1618677697.7640378: {"data":{"timestamp":"1618677694","microtimestamp":"1618677694125710","bids":[["312.41","0.00000000"]],"asks":[["312.88","0.00000000"],["313.06","346.00520000"],["313.33","23.97345476"]]},"channel":"diff_order_book_ltcusd","event":"data"}
1618677697.764045: {"data":{"timestamp":"1618677694","microtimestamp":"1618677694161904","bids":[["882.21","3.00000000"],["882.20","4.00000000"]],"asks":[["883.78","2.20000000"],["883.79","0.00000000"]]},"channel":"diff_order_book_bcheur","event":"data"}
1618677697.764051: {"data":{"timestamp":"1618677694","microtimestamp":"1618677694139942","bids":[["60480.54","2.60000000"],["60065.16","10.09000000"]],"asks":[["60576.56","0.00000000"],["60578.24","0.37006358"],["60621.54","0.00000000"],["60805.68","0.40737363"],["60831.19","2.10000000"]]},"channel":"diff_order_book_btcusd","event":"data"}
1618677697.764058: {"data":{"timestamp":"1618677694","microtimestamp":"1618677694242778","bids":[],"asks":[["0.00067933","0.00000000"],["0.00067948","15.89414495"],["0.00067949","0.00000000"]]},"channel":"diff_order_book_linkbtc","event":"data"}
1618677697.764064: {"data":{"timestamp":"1618677694","microtimestamp":"1618677694292802","bids":[["312.56","14.00000000"],["312.54","1.44000000"],["312.45","1.54500000"],["312.44","0.00000000"],["312.43","0.00000000"],["312.42","0.00000000"],["312.28","0.00000000"],["312.24","1.51500000"],["311.99","114.17858000"]],"asks":[["313.05","30.00000000"],["313.06","0.00000000"],["313.07","0.00000000"],["313.13","0.00000000"],["313.15","0.00000000"],["313.30","0.00000000"],["313.42","0.00000000"],["313.58","398.37422431"],["318.87","0.00000000"]]},"channel":"diff_order_book_ltcusd","event":"data"}
1618677697.764072: {"data":{"timestamp":"1618677694","microtimestamp":"1618677694330990","bids":[["882.23","40.25600136"],["882.21","0.00000000"],["882.04","0.00000000"]],"asks":[["883.66","0.00000000"],["883.68","0.00000000"],["883.78","0.00000000"],["883.80","0.00000000"]]},"channel":"diff_order_book_bcheur","event":"data"}
1618677697.764079: {"data":{"timestamp":"1618677694","microtimestamp":"1618677694366055","bids":[["0.00067800","0.00000000"]],"asks":[]},"channel":"diff_order_book_linkbtc","event":"data"}
1618677697.764085: {"data":{"timestamp":"1618677694","microtimestamp":"1618677694360798","bids":[["1717.49","0.05000000"]],"asks":[["1722.56","0.22100000"],["1724.08","0.00000000"]]},"channel":"diff_order_book_ethgbp","event":"data"}
1618677697.7640908: {"data":{"timestamp":"1618677694","microtimestamp":"1618677694479248","bids":[["312.60","301.92540000"],["312.58","14.70000000"],["312.55","1.60000000"],["312.36","4.00000000"],["312.35","39.10000000"],["312.24","0.00000000"],["312.18","1.46800000"],["312.13","0.00000000"],["311.99","0.00000000"],["311.63","114.17858000"]],"asks":[["312.98","0.00000000"],["313.05","0.00000000"],["313.08","0.00000000"],["313.12","21.13100000"],["313.16","0.00000000"],["313.41","39.10000000"]]},"channel":"diff_order_book_ltcusd","event":"data"}
1618677697.7640991: {"data":{"timestamp":"1618677694","microtimestamp":"1618677694488275","bids":[["0.00067827","15.89157675"]],"asks":[]},"channel":"diff_order_book_linkbtc","event":"data"}
1618677697.764106: {"data":{"timestamp":"1618677694","microtimestamp":"1618677694482455","bids":[["882.23","0.00000000"],["882.21","37.98890754"],["882.20","0.00000000"],["881.98","0.00000000"]],"asks":[["884.15","2.20000000"]]},"channel":"diff_order_book_bcheur","event":"data"}
1618677697.7641118: {"data":{"timestamp":"1618677694","microtimestamp":"1618677694479480","bids":[["1716.00","0.00000000"],["1715.87","0.00000000"]],"asks":[["1724.66","0.00000000"]]},"channel":"diff_order_book_ethgbp","event":"data"}
1618677697.764118: {"data":{"timestamp":"1618677694","microtimestamp":"1618677694576013","bids":[["764.08","2.85279742"],["763.51","0.00000000"]],"asks":[["765.26","0.00000000"],["765.36","0.00000000"]]},"channel":"diff_order_book_bchgbp","event":"data"}
1618677697.764124: {"data":{"timestamp":"1618677694","microtimestamp":"1618677694596430","bids":[["1716.36","0.10600000"]],"asks":[["1729.19","0.50600000"],["1729.20","0.00000000"]]},"channel":"diff_order_book_ethgbp","event":"data"}
1618677697.764131: {"data":{"timestamp":"1618677694","microtimestamp":"1618677694497446","bids":[["60535.19","0.24830840"],["60529.71","0.07540873"],["60527.48","0.27478585"],["60527.47","0.59818409"],["60526.62","0.16520579"],["60520.92","0.00000000"],["60518.49","0.00000000"],["60517.36","0.00000000"],["60510.03","0.00000000"],["60505.63","0.02000000"],["60499.70","6.79440000"],["60499.64","2.57000000"],["60496.12","0.08250000"],["60495.54","0.00000000"],["60491.30","0.33000000"],["60489.61","0.09260006"],["60486.94","0.50000000"],["60484.40","0.00000000"],["60476.85","0.00000000"],["60444.72","0.00000000"],["60426.56","1.00000000"],["60406.36","0.00000000"],["60366.17","2.00000000"],["60350.97","0.15522453"],["60345.99","0.00000000"],["60275.67","0.00000000"],["60065.16","0.00000000"],["59935.00","0.00043682"]],"asks":[["60553.64","0.00000000"],["60555.30","0.00000000"],["60557.07","0.00000000"],["60558.11","0.00000000"],["60560.09","0.00000000"],["60560.79","0.00000000"],["60560.80","0.00000000"],["60566.37","0.00000000"],["60567.30","0.00000000"],["60568.74","0.29436414"],["60570.99","0.27122128"],["60571.00","0.00000000"],["60571.58","0.00000000"],["60573.40","0.00000000"],["60575.44","0.00000000"],["60578.24","0.00000000"],["60578.35","0.49284755"],["60579.53","0.00000000"],["60580.60","0.00000000"],["60582.67","0.82727429"],["60582.83","0.08803200"],["60588.85","0.50000000"],["60589.41","0.00000000"],["60591.04","0.46055693"],["60594.22","0.32523080"],["60604.50","0.00000000"],["60605.50","0.00000000"],["60620.90","6.49420000"],["60638.39","0.45927892"],["60805.68","0.00000000"],["61544.68","0.00081682"]]},"channel":"diff_order_book_btcusd","event":"data"}
1618677697.7641442: {"data":{"timestamp":"1618677694","microtimestamp":"1618677694642686","bids":[["882.25","35.21205000"],["882.21","0.73290618"],["882.20","4.00000000"],["882.19","0.00000000"],["881.97","0.00000000"],["881.77","2.37717835"],["881.44","5.60000000"]],"asks":[["883.60","2.80000000"],["883.70","0.00000000"],["884.02","2.37651092"],["884.15","5.10000000"],["884.84","2.37697004"]]},"channel":"diff_order_book_bcheur","event":"data"}
1618677697.764152: {"data":{"timestamp":"1618677694","microtimestamp":"1618677694713082","bids":[],"asks":[["1720.58","0.00000000"],["1722.56","0.00000000"],["1729.19","0.00000000"]]},"channel":"diff_order_book_ethgbp","event":"data"}
1618677697.764158: {"data":{"timestamp":"1618677694","microtimestamp":"1618677694759420","bids":[["2.83785","0.00000000"]],"asks":[]},"channel":"diff_order_book_knceur","event":"data"}
1618677697.7641642: {"data":{"timestamp":"1618677694","microtimestamp":"1618677694769468","bids":[["312.61","130.40858000"],["312.56","0.00000000"],["312.36","0.00000000"],["312.31","0.00000000"],["311.63","0.00000000"]],"asks":[["313.00","476.81210000"],["313.12","0.00000000"],["313.20","0.00000000"],["313.23","373.90710000"],["313.27","218.38100000"],["313.45","1.48500000"],["313.89","0.00000000"],["313.90","0.00000000"],["314.91","61.56000000"]]},"channel":"diff_order_book_ltcusd","event":"data"}
1618677697.764172: {"data":{"timestamp":"1618677694","microtimestamp":"1618677694850266","bids":[],"asks":[["0.00067934","0.00000000"]]},"channel":"diff_order_book_linkbtc","event":"data"}
1618677697.764178: {"data":{"timestamp":"1618677694","microtimestamp":"1618677694817800","bids":[["882.48","37.25600136"],["882.47","49.96827000"],["882.20","0.00000000"],["881.50","1.00000000"]],"asks":[["883.60","0.00000000"],["884.00","2.90000000"],["884.15","2.20000000"]]},"channel":"diff_order_book_bcheur","event":"data"}
1618677697.7641852: {"data":{"timestamp":"1618677694","microtimestamp":"1618677694817849","bids":[],"asks":[["765.74","0.00000000"]]},"channel":"diff_order_book_bchgbp","event":"data"}
1618677697.764191: {"data":{"timestamp":"1618677694","microtimestamp":"1618677694833648","bids":[],"asks":[["1722.62","1.26847860"],["1724.08","0.22100000"],["1729.20","0.50600000"],["1732.08","1.01100000"]]},"channel":"diff_order_book_ethgbp","event":"data"}
1618677697.764197: {"data":{"timestamp":"1618677694","microtimestamp":"1618677694890636","bids":[["2.83989","443.09384789"]],"asks":[]},"channel":"diff_order_book_knceur","event":"data"}
1618677697.764203: {"data":{"timestamp":"1618677694","microtimestamp":"1618677694972282","bids":[["0.00067819","24.24839595"]],"asks":[["0.00068002","24.31998576"]]},"channel":"diff_order_book_linkbtc","event":"data"}
1618677697.7642088: {"data":{"timestamp":"1618677694","microtimestamp":"1618677694951200","bids":[["1716.74","0.10600000"],["1716.36","0.00000000"]],"asks":[]},"channel":"diff_order_book_ethgbp","event":"data"}
1618677697.764215: {"data":{"timestamp":"1618677694","microtimestamp":"1618677694954425","bids":[["312.64","4.76810388"],["312.63","14.00000000"],["312.62","0.70000000"],["312.61","14.00000000"],["312.60","301.22540000"],["312.58","0.70000000"],["312.19","0.00000000"]],"asks":[["313.00","471.14000000"],["313.20","1.50000000"]]},"channel":"diff_order_book_ltcusd","event":"data"}
1618677697.764222: {"data":{"timestamp":"1618677694","microtimestamp":"1618677694968243","bids":[["882.66","3.00000000"],["882.60","3.00000000"],["882.48","0.00000000"]],"asks":[["883.92","2.80000000"],["884.00","0.00000000"],["884.11","0.00000000"],["884.45","0.00000000"]]},"channel":"diff_order_book_bcheur","event":"data"}
1618677697.764229: {"data":{"timestamp":"1618677694","microtimestamp":"1618677694989742","bids":[["3.38073","0.00000000"]],"asks":[]},"channel":"diff_order_book_kncusd","event":"data"}
1618677697.764235: {"data":{"timestamp":"1618677694","microtimestamp":"1618677694975768","bids":[["60548.05","0.04667916"],["60535.19","0.20000000"],["60527.47","0.80000000"],["60526.75","0.00000000"],["60520.90","0.00000000"],["60517.37","0.00000000"],["60517.35","0.00000000"],["60515.05","0.02000000"],["60505.63","0.00000000"],["60502.02","0.08220000"],["60501.70","2.69600000"],["60497.66","0.00000000"],["60496.36","0.50000000"],["60496.12","0.00000000"],["60491.30","0.00000000"],["60487.23","0.00000000"],["60486.94","0.00000000"],["60486.40","0.00000000"],["60484.41","0.00000000"],["60340.11","0.00000000"],["60074.95","9.81000000"]],"asks":[["60578.35","0.46492639"],["60588.85","0.00000000"],["60591.05","0.00000000"],["60594.22","0.00000000"],["60599.18","0.50000000"],["60607.60","0.00000000"],["60618.05","0.00000000"],["60622.90","2.75760000"],["60638.39","0.00000000"],["60638.55","0.00000000"],["60640.78","0.42447056"],["60659.61","1.00000000"],["60845.09","2.70000000"],["61489.04","0.00000000"]]},"channel":"diff_order_book_btcusd","event":"data"}
1618677697.764245: {"data":{"timestamp":"1618677695","microtimestamp":"1618677695124622","bids":[["882.60","0.00000000"],["882.50","4.00000000"],["882.44","2.80000000"]],"asks":[["884.22","0.00000000"],["884.49","37.93186000"]]},"channel":"diff_order_book_bcheur","event":"data"}
1618677697.764252: {"data":{"timestamp":"1618677695","microtimestamp":"1618677695107007","bids":[["312.65","14.00000000"],["312.61","4.00000000"],["312.37","0.27868065"]],"asks":[["313.00","470.44000000"],["313.22","37.61509764"]]},"channel":"diff_order_book_ltcusd","event":"data"}
1618677697.7642791: {"data":{"timestamp":"1618677695","microtimestamp":"1618677695106161","bids":[["3.38278","443.04875193"]],"asks":[]},"channel":"diff_order_book_kncusd","event":"data"}
1618677697.764286: {"data":{"timestamp":"1618677695","microtimestamp":"1618677695185535","bids":[["1713.57","0.00000000"]],"asks":[]},"channel":"diff_order_book_ethgbp","event":"data"}
1618677697.764301: {"data":{"timestamp":"1618677695","microtimestamp":"1618677695216675","bids":[],"asks":[["0.00068106","0.00000000"]]},"channel":"diff_order_book_linkbtc","event":"data"}
1618677697.7643142: {"data":{"timestamp":"1618677695","microtimestamp":"1618677695229812","bids":[["3.38280","189.19238000"]],"asks":[]},"channel":"diff_order_book_kncusd","event":"data"}
1618677697.764321: {"data":{"timestamp":"1618677695","microtimestamp":"1618677695294334","bids":[["882.69","3.00000000"],["882.54","0.00000000"],["882.50","0.00000000"]],"asks":[["883.88","3.00000000"],["884.14","2.20000000"],["884.15","0.00000000"],["884.83","5.50617477"]]},"channel":"diff_order_book_bcheur","event":"data"}
1618677697.764328: {"data":{"timestamp":"1618677695","microtimestamp":"1618677695291295","bids":[["312.66","114.17858000"],["312.59","138.54720000"]],"asks":[["313.22","199.63879764"]]},"channel":"diff_order_book_ltcusd","event":"data"}
1618677697.764344: {"data":{"timestamp":"1618677695","microtimestamp":"1618677695351183","bids":[["3.38160","0.00000000"]],"asks":[]},"channel":"diff_order_book_kncusd","event":"data"}
1618677697.764351: {"data":{"timestamp":"1618677695","microtimestamp":"1618677695337946","bids":[["0.00067799","0.00000000"]],"asks":[["0.00067948","0.00000000"],["0.00068304","103.10000000"]]},"channel":"diff_order_book_linkbtc","event":"data"}
1618677697.764377: {"data":{"timestamp":"1618677695","microtimestamp":"1618677695426045","bids":[["1715.99","0.00000000"]],"asks":[]},"channel":"diff_order_book_ethgbp","event":"data"}
1618677697.764392: {"data":{"timestamp":"1618677695","microtimestamp":"1618677695450654","bids":[["2.83372","0.00000000"]],"asks":[["2.85200","0.00000000"]]},"channel":"diff_order_book_knceur","event":"data"}
1618677697.764399: {"data":{"timestamp":"1618677695","microtimestamp":"1618677695467229","bids":[],"asks":[["3.39238","0.00000000"]]},"channel":"diff_order_book_kncusd","event":"data"}
1618677697.764405: {"data":{"timestamp":"1618677695","microtimestamp":"1618677695457479","bids":[["0.00067827","0.00000000"],["0.00067710","70.39000748"]],"asks":[["0.00067960","15.88926438"]]},"channel":"diff_order_book_linkbtc","event":"data"}
1618677697.764427: {"data":{"timestamp":"1618677695","microtimestamp":"1618677695461608","bids":[["882.73","3.00000000"],["882.69","0.00000000"],["882.67","3.00000000"],["881.77","0.00000000"]],"asks":[["884.14","0.00000000"],["884.15","2.20000000"]]},"channel":"diff_order_book_bcheur","event":"data"}
1618677697.764435: {"data":{"timestamp":"1618677695","microtimestamp":"1618677695468819","bids":[["312.68","4.00000000"],["312.67","14.00000000"],["312.66","0.00000000"],["312.63","0.00000000"],["312.61","0.00000000"],["312.46","0.00000000"],["309.68","78.14216716"]],"asks":[]},"channel":"diff_order_book_ltcusd","event":"data"}
1618677697.764469: {"data":{"timestamp":"1618677695","microtimestamp":"1618677695542273","bids":[["1713.61","0.22100000"]],"asks":[]},"channel":"diff_order_book_ethgbp","event":"data"}
1618677697.764483: {"data":{"timestamp":"1618677695","microtimestamp":"1618677695378609","bids":[["60551.07","1.10000000"],["60550.37","0.04307050"],["60535.20","0.28189789"],["60535.19","0.00000000"],["60534.15","0.45154390"],["60534.14","0.28059006"],["60534.13","0.45296805"],["60531.10","0.00000000"],["60527.48","0.00000000"],["60527.47","0.00000000"],["60527.46","0.00000000"],["60526.63","0.80000000"],["60504.81","0.08230000"],["60504.74","0.04982088"],["60502.09","0.32990000"],["60502.02","0.00000000"]],"asks":[["60567.31","0.00000000"],["60568.02","0.03948843"],["60568.74","0.00000000"],["60570.99","0.00000000"],["60574.42","0.16673156"],["60574.71","0.30000000"],["60578.35","0.28431918"],["60581.97","0.49902294"],["60581.98","0.27813854"],["60582.68","0.00000000"],["60582.83","0.00000000"],["60594.62","0.08803200"],["60601.79","0.03108574"],["60630.50","0.41916271"],["60640.78","0.00000000"],["60799.60","0.00000000"],["60844.65","0.81587729"],["61476.47","3.71000000"]]},"channel":"diff_order_book_btcusd","event":"data"}
1618677697.7645462: {"data":{"timestamp":"1618677695","microtimestamp":"1618677695576260","bids":[["0.00067828","15.88791970"],["0.00067710","0.00000000"]],"asks":[]},"channel":"diff_order_book_linkbtc","event":"data"}
1618677697.764566: {"data":{"timestamp":"1618677695","microtimestamp":"1618677695581530","bids":[],"asks":[["2.85344","1460.00000000"]]},"channel":"diff_order_book_knceur","event":"data"}
1618677697.7645729: {"data":{"timestamp":"1618677695","microtimestamp":"1618677695657597","bids":[["1716.74","0.00000000"]],"asks":[]},"channel":"diff_order_book_ethgbp","event":"data"}
1618677697.764588: {"data":{"timestamp":"1618677695","microtimestamp":"1618677695617351","bids":[["882.67","0.00000000"],["882.48","41.25600136"]],"asks":[["884.15","0.00000000"]]},"channel":"diff_order_book_bcheur","event":"data"}
1618677697.764595: {"data":{"timestamp":"1618677695","microtimestamp":"1618677695660371","bids":[["312.69","14.00000000"],["312.68","0.00000000"],["312.65","0.00000000"],["312.62","4.70000000"],["312.61","114.17858000"],["309.68","0.00000000"]],"asks":[["313.19","4.79373542"]]},"channel":"diff_order_book_ltcusd","event":"data"}
1618677697.764626: {"data":{"timestamp":"1618677695","microtimestamp":"1618677695701487","bids":[],"asks":[["3.39409","1024.00000000"]]},"channel":"diff_order_book_kncusd","event":"data"}
1618677697.7646341: {"data":{"timestamp":"1618677695","microtimestamp":"1618677695692808","bids":[["0.00067710","70.00592893"]],"asks":[]},"channel":"diff_order_book_linkbtc","event":"data"}
1618677697.764648: {"data":{"timestamp":"1618677695","microtimestamp":"1618677695716830","bids":[["2.83514","1430.00000000"]],"asks":[]},"channel":"diff_order_book_knceur","event":"data"}
1618677697.764655: {"data":{"timestamp":"1618677695","microtimestamp":"1618677695803238","bids":[["882.66","0.00000000"],["882.50","3.00000000"],["882.48","4.00000000"]],"asks":[["884.15","2.20000000"]]},"channel":"diff_order_book_bcheur","event":"data"}
1618677697.764661: {"data":{"timestamp":"1618677695","microtimestamp":"1618677695838131","bids":[["312.67","3.19545888"],["312.62","0.70000000"],["312.61","0.00000000"],["312.60","0.00000000"],["312.59","0.00000000"],["312.54","0.00000000"],["312.51","311.79700000"],["312.49","15.98070122"],["312.01","119.02554002"]],"asks":[["312.99","20.39020000"],["313.14","377.35180000"],["313.22","37.61509764"],["313.23","3.19501360"],["313.29","20.79103099"]]},"channel":"diff_order_book_ltcusd","event":"data"}
1618677697.764707: {"data":{"timestamp":"1618677695","microtimestamp":"1618677695889154","bids":[["1716.56","0.10600000"]],"asks":[]},"channel":"diff_order_book_ethgbp","event":"data"}
1618677697.7647219: {"data":{"timestamp":"1618677695","microtimestamp":"1618677695944336","bids":[],"asks":[["3.40420","241.00000000"]]},"channel":"diff_order_book_kncusd","event":"data"}
1618677697.764729: {"data":{"timestamp":"1618677695","microtimestamp":"1618677695964990","bids":[["882.50","0.00000000"],["882.48","0.00000000"],["881.51","1.00000000"],["881.45","0.00000000"]],"asks":[["884.15","0.00000000"]]},"channel":"diff_order_book_bcheur","event":"data"}
1618677697.764736: {"data":{"timestamp":"1618677695","microtimestamp":"1618677695887214","bids":[["60550.37","0.00000000"],["60535.21","0.48772939"],["60504.81","0.00000000"],["60504.74","0.00000000"],["60502.09","0.00000000"],["60499.32","0.08240000"],["60496.60","0.32990000"]],"asks":[["60568.02","0.00000000"],["60572.76","0.04836772"],["60574.42","0.00000000"],["60574.71","0.00000000"],["60574.98","0.14227194"],["60582.67","0.33053088"],["60611.76","0.14329037"],["60630.50","0.00000000"]]},"channel":"diff_order_book_btcusd","event":"data"}
1618677697.7647932: {"data":{"timestamp":"1618677696","microtimestamp":"1618677696015741","bids":[["312.69","0.00000000"],["312.62","0.00000000"],["312.58","0.00000000"],["312.53","4.00000000"],["312.52","114.17858000"],["312.01","4.84696002"]],"asks":[["313.13","1.48500000"],["313.23","0.00000000"],["314.91","0.00000000"]]},"channel":"diff_order_book_ltcusd","event":"data"}
1618677697.764831: {"data":{"timestamp":"1618677696","microtimestamp":"1618677696059679","bids":[],"asks":[["3.41974","780.00000000"]]},"channel":"diff_order_book_kncusd","event":"data"}
1618677697.764847: {"data":{"timestamp":"1618677696","microtimestamp":"1618677696126473","bids":[["1715.22","1.26843969"]],"asks":[]},"channel":"diff_order_book_ethgbp","event":"data"}
1618677697.7648609: {"data":{"timestamp":"1618677696","microtimestamp":"1618677696175671","bids":[],"asks":[["3.40420","1021.00000000"],["3.41974","0.00000000"]]},"channel":"diff_order_book_kncusd","event":"data"}
1618677697.764878: {"data":{"timestamp":"1618677696","microtimestamp":"1618677696124236","bids":[["882.53","3.00000000"]],"asks":[["884.14","2.20000000"],["884.49","0.00000000"]]},"channel":"diff_order_book_bcheur","event":"data"}
1618677697.764885: {"data":{"timestamp":"1618677696","microtimestamp":"1618677696165926","bids":[["312.57","0.00000000"],["312.53","114.17858000"],["312.52","0.00000000"],["312.37","0.00000000"],["312.18","1.74684892"]],"asks":[["314.19","61.56000000"]]},"channel":"diff_order_book_ltcusd","event":"data"}
1618677697.7649128: {"data":{"timestamp":"1618677696","microtimestamp":"1618677696283446","bids":[],"asks":[["0.00068106","103.10000000"],["0.00068304","0.00000000"]]},"channel":"diff_order_book_linkbtc","event":"data"}
1618677697.764931: {"data":{"timestamp":"1618677696","microtimestamp":"1618677696283469","bids":[["882.53","0.00000000"],["882.48","3.00000000"]],"asks":[["884.14","0.00000000"],["884.21","36.38508000"]]},"channel":"diff_order_book_bcheur","event":"data"}
1618677697.764939: {"data":{"timestamp":"1618677696","microtimestamp":"1618677696318657","bids":[["312.53","0.00000000"],["312.52","4.00000000"],["312.43","132.23260000"]],"asks":[["313.05","30.00000000"],["313.06","151.26740000"],["313.27","216.78100000"]]},"channel":"diff_order_book_ltcusd","event":"data"}
1618677697.7649658: {"data":{"timestamp":"1618677696","microtimestamp":"1618677696434824","bids":[["882.49","3.00000000"],["882.48","0.00000000"]],"asks":[]},"channel":"diff_order_book_bcheur","event":"data"}
1618677697.7649732: {"data":{"timestamp":"1618677696","microtimestamp":"1618677696496939","bids":[["312.68","14.00000000"],["312.53","115.86803122"],["312.52","1.44000000"],["312.43","0.00000000"]],"asks":[["313.05","0.00000000"],["313.06","0.00000000"],["313.13","0.00000000"],["313.14","0.00000000"],["313.21","1.60000000"]]},"channel":"diff_order_book_ltcusd","event":"data"}
1618677697.765009: {"data":{"timestamp":"1618677696","microtimestamp":"1618677696424814","bids":[["60548.05","0.00000000"],["60542.00","0.04131110"],["60525.43","0.00000000"],["60521.36","0.02000000"],["60515.05","0.00000000"],["60502.66","0.50000000"],["60499.32","0.00000000"],["60496.60","0.00000000"],["60496.36","0.00000000"],["60496.12","0.08240000"],["60493.40","0.32990000"],["60442.26","1.00000000"],["60426.56","0.00000000"]],"asks":[["60553.64","0.38200000"],["60574.28","0.04336623"],["60574.98","0.00000000"],["60578.40","0.07064223"],["60585.08","0.37176841"],["60599.17","0.48037506"],["60599.18","0.00000000"],["60608.55","0.50000000"],["60812.55","0.46579648"]]},"channel":"diff_order_book_btcusd","event":"data"}
1618677697.765087: {"data":{"timestamp":"1618677696","microtimestamp":"1618677696611469","bids":[["764.15","2.85181311"]],"asks":[["765.42","1.42590656"],["766.06","2.85181311"],["768.34","5.45519973"]]},"channel":"diff_order_book_bchgbp","event":"data"}
1618677697.765111: {"data":{"timestamp":"1618677696","microtimestamp":"1618677696595197","bids":[["882.51","4.00000000"],["882.49","0.00000000"],["882.44","0.00000000"],["882.35","2.37652191"],["882.09","2.37632552"],["881.32","2.37652191"]],"asks":[["884.14","2.20000000"]]},"channel":"diff_order_book_bcheur","event":"data"}
1618677697.765119: {"data":{"timestamp":"1618677696","microtimestamp":"1618677696638452","bids":[["0.00067828","0.00000000"]],"asks":[]},"channel":"diff_order_book_linkbtc","event":"data"}
1618677697.765134: {"data":{"timestamp":"1618677696","microtimestamp":"1618677696646349","bids":[["312.59","1.47000000"],["312.54","4.00000000"],["312.53","1.68945122"],["312.51","0.00000000"]],"asks":[]},"channel":"diff_order_book_ltcusd","event":"data"}
1618677697.765156: {"data":{"timestamp":"1618677696","microtimestamp":"1618677696761758","bids":[["882.52","41.25600136"],["882.51","0.00000000"]],"asks":[["884.14","0.00000000"]]},"channel":"diff_order_book_bcheur","event":"data"}
1618677697.7651641: {"data":{"timestamp":"1618677696","microtimestamp":"1618677696766650","bids":[["0.00067820","15.89148558"],["0.00067710","0.00000000"]],"asks":[["0.00067930","24.32991010"],["0.00068002","0.00000000"]]},"channel":"diff_order_book_linkbtc","event":"data"}
1618677697.765188: {"data":{"timestamp":"1618677696","microtimestamp":"1618677696796219","bids":[["312.60","327.48360000"],["312.54","0.00000000"],["312.36","1.46800000"],["312.18","0.27884892"]],"asks":[["312.99","6.39020000"],["313.21","0.00000000"],["313.24","366.66960000"],["313.27","218.38100000"]]},"channel":"diff_order_book_ltcusd","event":"data"}
1618677697.765219: {"data":{"timestamp":"1618677696","microtimestamp":"1618677696886379","bids":[["0.00067710","68.37951824"]],"asks":[["0.00067960","0.00000000"]]},"channel":"diff_order_book_linkbtc","event":"data"}
1618677697.765238: {"data":{"timestamp":"1618677696","microtimestamp":"1618677696822503","bids":[["60551.07","0.00000000"],["60542.00","0.00000000"],["60538.23","1.10000000"],["60535.21","0.00000000"],["60534.15","0.00000000"],["60526.63","0.00000000"],["60496.12","0.00000000"],["60494.62","0.08220000"],["60493.40","0.00000000"],["60491.90","0.32990000"]],"asks":[["60578.33","0.47336352"],["60578.34","0.27950167"],["60581.98","0.00000000"],["60585.08","0.00000000"],["60599.17","0.00000000"],["60599.71","0.55282488"],["60809.38","0.40890373"],["60812.55","0.00000000"],["60844.64","1.88294212"],["60856.02","0.00000000"]]},"channel":"diff_order_book_btcusd","event":"data"}
1618677697.76531: {"data":{"timestamp":"1618677696","microtimestamp":"1618677696908731","bids":[["882.54","3.00000000"],["882.52","0.00000000"],["882.49","6.80000000"]],"asks":[["884.02","0.00000000"],["884.15","2.20000000"]]},"channel":"diff_order_book_bcheur","event":"data"}
1618677697.7653189: {"data":{"timestamp":"1618677696","microtimestamp":"1618677696949667","bids":[["312.61","4.00000000"]],"asks":[["312.99","0.00000000"]]},"channel":"diff_order_book_ltcusd","event":"data"}
1618677697.765337: {"data":{"timestamp":"1618677697","microtimestamp":"1618677697005510","bids":[],"asks":[["0.00067950","15.89151063"]]},"channel":"diff_order_book_linkbtc","event":"data"}
1618677697.7653508: {"data":{"timestamp":"1618677697","microtimestamp":"1618677697075244","bids":[["882.54","0.00000000"],["882.49","2.80000000"],["882.25","0.00000000"]],"asks":[]},"channel":"diff_order_book_bcheur","event":"data"}
1618677697.765368: {"data":{"timestamp":"1618677697","microtimestamp":"1618677697113613","bids":[["312.17","118.93043706"]],"asks":[["312.98","14.00000000"],["313.17","3.19566608"]]},"channel":"diff_order_book_ltcusd","event":"data"}
1618677697.7653859: {"data":{"timestamp":"1618677697","microtimestamp":"1618677697238860","bids":[["3.37540","2847.86250000"]],"asks":[["3.39252","769.27158000"]]},"channel":"diff_order_book_kncusd","event":"data"}
1618677697.765402: {"data":{"timestamp":"1618677697","microtimestamp":"1618677697234157","bids":[["882.48","32.75173000"]],"asks":[]},"channel":"diff_order_book_bcheur","event":"data"}
1618677697.765415: {"data":{"timestamp":"1618677697","microtimestamp":"1618677697267087","bids":[["312.69","6.39050000"],["312.61","0.00000000"],["312.60","0.00000000"],["312.59","0.00000000"],["312.52","115.61858000"],["312.51","136.94650000"],["312.17","4.75185706"]],"asks":[["313.17","155.29846608"],["313.22","39.21509764"],["313.24","0.00000000"],["313.27","216.78100000"]]},"channel":"diff_order_book_ltcusd","event":"data"}
1618677697.765453: {"data":{"timestamp":"1618677697","microtimestamp":"1618677697329352","bids":[["764.27","2.80000000"],["764.17","0.00000000"]],"asks":[]},"channel":"diff_order_book_bchgbp","event":"data"}
1618677697.76547: {"data":{"timestamp":"1618677697","microtimestamp":"1618677697390350","bids":[["882.50","4.00000000"]],"asks":[["884.21","0.00000000"],["884.44","39.62399000"]]},"channel":"diff_order_book_bcheur","event":"data"}
1618677697.7654881: {"data":{"timestamp":"1618677697","microtimestamp":"1618677697544737","bids":[["882.82","48.16471000"],["882.50","0.00000000"],["882.47","0.00000000"],["882.00","0.00000000"]],"asks":[["884.15","0.00000000"],["884.17","0.00000000"],["884.44","69.81667000"]]},"channel":"diff_order_book_bcheur","event":"data"}
1618677697.7655108: {"data":{"timestamp":"1618677697","microtimestamp":"1618677697552358","bids":[["312.68","0.00000000"],["312.64","0.00000000"],["312.52","5.44000000"]],"asks":[]},"channel":"diff_order_book_ltcusd","event":"data"}
1618677697.76553: {"data":{"timestamp":"1618677697","microtimestamp":"1618677697584232","bids":[["763.56","0.00000000"]],"asks":[]},"channel":"diff_order_book_bchgbp","event":"data"}
1618677697.765544: {"data":{"timestamp":"1618677697","microtimestamp":"1618677697429476","bids":[["60536.09","0.12389170"],["60517.83","0.24778339"],["60517.82","0.24778339"],["60509.69","0.96463697"],["60505.04","0.05031150"],["60494.82","0.08220000"],["60494.62","0.00000000"],["60417.99","0.00000000"],["59900.00","5.13604101"]],"asks":[["60563.25","0.06045913"],["60571.41","0.27774399"],["60571.42","0.12388545"],["60572.76","0.00000000"],["60574.55","0.16518059"],["60578.35","0.00000000"],["60582.17","0.24779582"],["60590.01","0.24777090"],["60594.62","0.00000000"],["60611.54","0.33036119"],["60809.38","0.00000000"],["61719.09","0.49786831"]]},"channel":"diff_order_book_btcusd","event":"data"}
1618677697.765837: {"data":{"timestamp":"1618677697","microtimestamp":"1618677697700367","bids":[["764.45","2.85135640"],["764.40","1.42598494"],["763.89","0.00000000"]],"asks":[]},"channel":"diff_order_book_bchgbp","event":"data"}
1618677697.836176: {"data":{"timestamp":"1618677697","microtimestamp":"1618677697728212","bids":[["312.69","0.00000000"],["311.63","114.17858000"]],"asks":[]},"channel":"diff_order_book_ltcusd","event":"data"}
1618677697.8967118: {"data":{"timestamp":"1618677697","microtimestamp":"1618677697820197","bids":[["1.37101","0.00000"],["1.37001","265.00000"]],"asks":[]},"channel":"diff_order_book_gbpusd","event":"data"}
1618677697.923517: {"data":{"timestamp":"1618677697","microtimestamp":"1618677697855033","bids":[["0.00067827","15.88987308"],["0.00067820","0.00000000"],["0.00067710","0.00000000"]],"asks":[]},"channel":"diff_order_book_linkbtc","event":"data"}
1618677697.932126: {"data":{"timestamp":"1618677697","microtimestamp":"1618677697862082","bids":[["882.86","3.00000000"],["882.84","4.00000000"]],"asks":[]},"channel":"diff_order_book_bcheur","event":"data"}
1618677697.952162: {"data":{"timestamp":"1618677697","microtimestamp":"1618677697894557","bids":[["312.51","441.53440000"]],"asks":[["312.99","30.00000000"],["313.15","360.54560000"]]},"channel":"diff_order_book_ltcusd","event":"data"}
1618677698.037868: {"data":{"timestamp":"1618677697","microtimestamp":"1618677697973567","bids":[["0.00067710","71.16493899"]],"asks":[]},"channel":"diff_order_book_linkbtc","event":"data"}
1618677698.1034398: {"data":{"timestamp":"1618677698","microtimestamp":"1618677698031888","bids":[["882.84","0.00000000"],["882.83","37.25600136"],["846.34","4.03975732"],["845.01","0.00000000"]],"asks":[]},"channel":"diff_order_book_bcheur","event":"data"}
1618677698.1182349: {"data":{"timestamp":"1618677698","microtimestamp":"1618677698045670","bids":[],"asks":[["312.99","0.00000000"],["313.00","500.44000000"]]},"channel":"diff_order_book_ltcusd","event":"data"}
1618677698.150856: {"data":{"timestamp":"1618677698","microtimestamp":"1618677698092607","bids":[],"asks":[["0.00067950","0.00000000"],["0.00067960","15.88977930"]]},"channel":"diff_order_book_linkbtc","event":"data"}
1618677698.1963332: {"data":{"timestamp":"1618677698","microtimestamp":"1618677698013787","bids":[["60509.69","0.48384365"],["60505.04","0.00000000"],["60495.52","0.08220000"],["60494.82","0.00000000"],["60492.80","0.33000000"],["60491.90","0.00000000"],["60432.99","0.55300000"]],"asks":[["60585.55","0.08803200"],["60610.93","0.05650256"]]},"channel":"diff_order_book_btcusd","event":"data"}
1618677698.2410932: {"data":{"timestamp":"1618677698","microtimestamp":"1618677698166104","bids":[["1.37101","67.00000"],["1.37001","198.00000"]],"asks":[]},"channel":"diff_order_book_gbpusd","event":"data"}
1618677698.254285: {"data":{"timestamp":"1618677698","microtimestamp":"1618677698197361","bids":[],"asks":[["1722.61","0.22100000"],["1724.08","0.00000000"]]},"channel":"diff_order_book_ethgbp","event":"data"}
1618677698.2846348: {"data":{"timestamp":"1618677698","microtimestamp":"1618677698230042","bids":[],"asks":[["313.00","470.44000000"]]},"channel":"diff_order_book_ltcusd","event":"data"}
1618677698.3177621: {"data":{"timestamp":"1618677698","microtimestamp":"1618677698220477","bids":[["882.51","2.37612909"],["882.50","5.63897004"],["882.35","0.00000000"]],"asks":[["884.03","2.37624066"]]},"channel":"diff_order_book_bcheur","event":"data"}
1618677698.3682501: {"data":{"timestamp":"1618677698","microtimestamp":"1618677698318580","bids":[["1716.56","0.00000000"]],"asks":[]},"channel":"diff_order_book_ethgbp","event":"data"}
1618677698.374502: {"data":{"timestamp":"1618677698","microtimestamp":"1618677698335056","bids":[["3.37540","780.00000000"]],"asks":[]},"channel":"diff_order_book_kncusd","event":"data"}
1618677698.451786: {"data":{"timestamp":"1618677698","microtimestamp":"1618677698393620","bids":[],"asks":[["313.11","3.19618507"],["313.17","152.10280000"]]},"channel":"diff_order_book_ltcusd","event":"data"}
1618677698.468467: {"data":{"timestamp":"1618677698","microtimestamp":"1618677698391355","bids":[["1.37101","0.00000"]],"asks":[]},"channel":"diff_order_book_gbpusd","event":"data"}
1618677698.484919: {"data":{"timestamp":"1618677698","microtimestamp":"1618677698438688","bids":[["1716.36","0.10600000"]],"asks":[]},"channel":"diff_order_book_ethgbp","event":"data"}
1618677698.532217: {"data":{"timestamp":"1618677698","microtimestamp":"1618677698504281","bids":[["1.37001","265.00000"]],"asks":[]},"channel":"diff_order_book_gbpusd","event":"data"}
1618677698.566736: {"data":{"timestamp":"1618677698","microtimestamp":"1618677698388226","bids":[["60542.54","0.05097100"],["60517.84","0.47541939"]],"asks":[["60620.50","0.08355990"],["60625.31","0.47384076"]]},"channel":"diff_order_book_btcusd","event":"data"}
1618677698.59655: {"data":{"timestamp":"1618677698","microtimestamp":"1618677698532269","bids":[["882.83","0.00000000"]],"asks":[]},"channel":"diff_order_book_bcheur","event":"data"}
1618677698.6161978: {"data":{"timestamp":"1618677698","microtimestamp":"1618677698547355","bids":[["312.64","4.85926304"],["312.52","119.61858000"],["311.63","0.00000000"]],"asks":[]},"channel":"diff_order_book_ltcusd","event":"data"}
1618677698.668697: {"data":{"timestamp":"1618677698","microtimestamp":"1618677698619517","bids":[],"asks":[["765.42","0.00000000"],["765.54","0.00000000"]]},"channel":"diff_order_book_bchgbp","event":"data"}
1618677698.7609851: {"data":{"timestamp":"1618677698","microtimestamp":"1618677698683378","bids":[["882.84","3.00000000"],["882.48","0.00000000"]],"asks":[["883.88","0.00000000"]]},"channel":"diff_order_book_bcheur","event":"data"}
1618677698.782339: {"data":{"timestamp":"1618677698","microtimestamp":"1618677698732893","bids":[["759.12","5.48710017"]],"asks":[]},"channel":"diff_order_book_bchgbp","event":"data"}
1618677698.782419: {"data":{"timestamp":"1618677698","microtimestamp":"1618677698699020","bids":[["312.68","14.00000000"],["312.53","5.68945122"],["312.52","115.61858000"]],"asks":[["312.97","6.38860000"],["312.98","0.00000000"]]},"channel":"diff_order_book_ltcusd","event":"data"}
1618677698.8965209: {"data":{"timestamp":"1618677698","microtimestamp":"1618677698846133","bids":[],"asks":[["765.72","0.00000000"],["765.80","1.42524369"],["766.26","2.85106582"]]},"channel":"diff_order_book_bchgbp","event":"data"}
1618677698.896629: {"data":{"timestamp":"1618677698","microtimestamp":"1618677698850216","bids":[],"asks":[["312.97","0.00000000"],["313.11","0.00000000"]]},"channel":"diff_order_book_ltcusd","event":"data"}
1618677698.929035: {"data":{"timestamp":"1618677698","microtimestamp":"1618677698832216","bids":[["882.88","7.00000000"],["882.84","0.00000000"],["882.73","36.14898000"],["882.51","0.00000000"]],"asks":[["884.03","0.00000000"],["884.44","0.00000000"],["884.70","32.26847000"],["884.74","39.81152000"]]},"channel":"diff_order_book_bcheur","event":"data"}
1618677699.0056791: {"data":{"timestamp":"1618677698","microtimestamp":"1618677698926027","bids":[["0.00067827","0.00000000"]],"asks":[]},"channel":"diff_order_book_linkbtc","event":"data"}
1618677699.064627: {"data":{"timestamp":"1618677698","microtimestamp":"1618677698999733","bids":[["312.64","0.00000000"]],"asks":[["313.26","1.91654100"]]},"channel":"diff_order_book_ltcusd","event":"data"}
1618677699.07137: {"data":{"timestamp":"1618677698","microtimestamp":"1618677698908797","bids":[["60536.82","0.04556137"],["60509.69","0.00000000"]],"asks":[["60601.79","0.02996657"],["60625.16","0.47179037"],["60625.31","0.00000000"]]},"channel":"diff_order_book_btcusd","event":"data"}
1618677699.093676: {"data":{"timestamp":"1618677698","microtimestamp":"1618677698995355","bids":[["882.90","37.25600136"],["882.89","3.00000000"],["882.88","0.00000000"],["882.87","2.70000000"],["882.73","33.14898000"],["882.49","0.00000000"]],"asks":[["883.92","0.00000000"],["884.69","0.73252623"]]},"channel":"diff_order_book_bcheur","event":"data"}
1618677699.1170921: {"data":{"timestamp":"1618677699","microtimestamp":"1618677699044067","bids":[["0.00067827","15.88967238"],["0.00067710","69.34118465"]],"asks":[]},"channel":"diff_order_book_linkbtc","event":"data"}
1618677699.2112472: {"data":{"timestamp":"1618677699","microtimestamp":"1618677699159845","bids":[["882.92","3.00000000"],["882.90","0.00000000"],["882.89","0.00000000"],["882.88","7.00000000"],["882.87","0.00000000"],["882.73","0.00000000"]],"asks":[["884.36","0.00000000"],["884.70","0.00000000"]]},"channel":"diff_order_book_bcheur","event":"data"}
1618677699.233908: {"data":{"timestamp":"1618677699","microtimestamp":"1618677699167479","bids":[],"asks":[["312.99","14.00000000"]]},"channel":"diff_order_book_ltcusd","event":"data"}
1618677699.238753: {"data":{"timestamp":"1618677699","microtimestamp":"1618677699188418","bids":[["759.10","1.55000000"]],"asks":[]},"channel":"diff_order_book_bchgbp","event":"data"}
1618677699.345032: {"data":{"timestamp":"1618677699","microtimestamp":"1618677699283304","bids":[["1715.23","0.22100000"],["1713.61","0.00000000"]],"asks":[]},"channel":"diff_order_book_ethgbp","event":"data"}
1618677699.3523898: {"data":{"timestamp":"1618677699","microtimestamp":"1618677699302898","bids":[["759.12","0.00000000"],["759.11","0.55400000"]],"asks":[]},"channel":"diff_order_book_bchgbp","event":"data"}
1618677699.423934: {"data":{"timestamp":"1618677699","microtimestamp":"1618677699321475","bids":[["882.95","37.25600136"],["882.88","0.00000000"],["882.40","2.80000000"]],"asks":[]},"channel":"diff_order_book_bcheur","event":"data"}
1618677699.445437: {"data":{"timestamp":"1618677699","microtimestamp":"1618677699272501","bids":[["60517.85","0.45932074"],["60504.20","0.04939987"],["60495.52","0.00000000"],["60494.03","0.08230000"],["59995.01","0.00000000"]],"asks":[["60563.58","0.19355599"],["60620.32","0.38581219"],["60625.16","0.00000000"],["60842.50","0.30000000"]]},"channel":"diff_order_book_btcusd","event":"data"}
1618677699.581089: {"data":{"timestamp":"1618677699","microtimestamp":"1618677699545061","bids":[["764.41","5.25905611"],["763.94","0.00000000"]],"asks":[["765.68","0.00000000"],["768.34","0.00000000"]]},"channel":"diff_order_book_bchgbp","event":"data"}
1618677699.589437: {"data":{"timestamp":"1618677699","microtimestamp":"1618677699512277","bids":[["882.95","0.00000000"],["882.87","37.25600136"],["882.84","4.00000000"],["881.44","0.00000000"]],"asks":[]},"channel":"diff_order_book_bcheur","event":"data"}
1618677699.755059: {"data":{"timestamp":"1618677699","microtimestamp":"1618677699677685","bids":[["882.99","3.00000000"],["882.92","0.00000000"],["882.87","0.00000000"],["882.86","0.00000000"],["882.84","41.25600136"]],"asks":[["885.90","0.00000000"]]},"channel":"diff_order_book_bcheur","event":"data"}
1618677699.860159: {"data":{"timestamp":"1618677699","microtimestamp":"1618677699795635","bids":[["764.40","8.62598494"]],"asks":[["766.08","7.40000000"]]},"channel":"diff_order_book_bchgbp","event":"data"}
1618677699.898667: {"data":{"timestamp":"1618677699","microtimestamp":"1618677699818647","bids":[],"asks":[["312.98","6.37510000"]]},"channel":"diff_order_book_ltcusd","event":"data"}
1618677699.9189131: {"data":{"timestamp":"1618677699","microtimestamp":"1618677699858737","bids":[["882.84","0.00000000"],["882.71","32.22702000"],["881.95","5.00000000"]],"asks":[["884.06","2.80000000"],["884.68","32.15776000"],["886.36","6.20000000"]]},"channel":"diff_order_book_bcheur","event":"data"}
1618677699.93078: {"data":{"timestamp":"1618677699","microtimestamp":"1618677699744245","bids":[["60543.12","0.03574203"],["60542.54","0.00000000"]],"asks":[["60563.58","0.00000000"],["60578.34","0.00000000"],["60600.88","0.19065659"],["60620.32","0.00000000"],["60804.29","0.42846455"]]},"channel":"diff_order_book_btcusd","event":"data"}
1618677700.086823: {"data":{"timestamp":"1618677700","microtimestamp":"1618677700025589","bids":[["882.85","37.25600136"],["882.66","2.37572040"]],"asks":[["884.37","2.37542557"],["884.74","0.00000000"],["885.02","39.67298000"],["885.21","2.37579858"],["885.99","0.00000000"],["888.03","8.38400000"]]},"channel":"diff_order_book_bcheur","event":"data"}
1618677700.198803: {"data":{"timestamp":"1618677700","microtimestamp":"1618677700137979","bids":[["0.00067827","15.88843465"],["0.00067710","0.00000000"]],"asks":[["0.00067951","24.52757170"]]},"channel":"diff_order_book_linkbtc","event":"data"}
1618677700.250398: {"data":{"timestamp":"1618677700","microtimestamp":"1618677700187560","bids":[["882.87","41.25600136"],["882.85","0.00000000"]],"asks":[]},"channel":"diff_order_book_bcheur","event":"data"}
1618677700.312799: {"data":{"timestamp":"1618677700","microtimestamp":"1618677700258537","bids":[["0.00067710","70.38534100"]],"asks":[["0.00067960","0.00000000"],["0.00068106","0.00000000"]]},"channel":"diff_order_book_linkbtc","event":"data"}
1618677700.363005: {"data":{"timestamp":"1618677700","microtimestamp":"1618677700143988","bids":[["312.64","4.75802840"]],"asks":[["313.18","3.19551984"]]},"channel":"diff_order_book_ltcusd","event":"data"}
1618677700.3939672: {"channel": "live_trades_btcusd", "data": {"amount": 0.02449, "amount_str": "0.02449000", "buy_order_id": 1351035804241920, "id": 164507740, "microtimestamp": "1618677700302000", "price": 60553.64, "price_str": "60553.64", "sell_order_id": 1351035787067392, "timestamp": "1618677700", "type": 0}, "event": "trade"}
1618677700.416404: {"data":{"timestamp":"1618677700","microtimestamp":"1618677700352688","bids":[["882.87","0.00000000"],["882.84","4.00000000"],["882.83","3.00000000"]],"asks":[["886.35","8.38400000"],["888.03","0.00000000"]]},"channel":"diff_order_book_bcheur","event":"data"}
1618677700.42801: {"data":{"timestamp":"1618677700","microtimestamp":"1618677700384511","bids":[],"asks":[["0.00067950","15.88910541"],["0.00068304","103.10000000"]]},"channel":"diff_order_book_linkbtc","event":"data"}
1618677700.472946: {"data":{"timestamp":"1618677700","microtimestamp":"1618677700184362","bids":[["59970.01","0.00142343"]],"asks":[["60578.32","0.29416396"],["60611.76","0.00000000"],["60804.29","0.00000000"]]},"channel":"diff_order_book_btcusd","event":"data"}
1618677700.4784892: {"data":{"timestamp":"1618677700","microtimestamp":"1618677700429939","bids":[],"asks":[["312.97","14.00000000"]]},"channel":"diff_order_book_ltcusd","event":"data"}
1618677700.544924: {"data":{"timestamp":"1618677700","microtimestamp":"1618677700483194","bids":[],"asks":[["766.44","2.85048736"]]},"channel":"diff_order_book_bchgbp","event":"data"}
1618677700.5862: {"data":{"timestamp":"1618677700","microtimestamp":"1618677700517041","bids":[["882.84","3.00000000"],["882.83","0.00000000"]],"asks":[]},"channel":"diff_order_book_bcheur","event":"data"}
1618677700.660415: {"data":{"timestamp":"1618677700","microtimestamp":"1618677700598555","bids":[],"asks":[["765.93","5.43550533"]]},"channel":"diff_order_book_bchgbp","event":"data"}
1618677700.750185: {"data":{"timestamp":"1618677700","microtimestamp":"1618677700701057","bids":[["882.84","0.00000000"],["882.72","4.00000000"]],"asks":[["884.15","2.20000000"],["884.37","0.00000000"]]},"channel":"diff_order_book_bcheur","event":"data"}
1618677700.7771919: {"data":{"timestamp":"1618677700","microtimestamp":"1618677700712886","bids":[],"asks":[["766.08","10.20000000"]]},"channel":"diff_order_book_bchgbp","event":"data"}
1618677700.85809: {"channel": "live_trades_bcheur", "data": {"amount": 3.0, "amount_str": "3.00000000", "buy_order_id": 1351035801006080, "id": 164507741, "microtimestamp": "1618677700785000", "price": 882.99, "price_str": "882.99", "sell_order_id": 1351035806220288, "timestamp": "1618677700", "type": 1}, "event": "trade"}
1618677700.860179: {"data":{"timestamp":"1618677700","microtimestamp":"1618677700753440","bids":[],"asks":[["314.86","154.76031065"]]},"channel":"diff_order_book_ltcusd","event":"data"}
1618677700.915659: {"data":{"timestamp":"1618677700","microtimestamp":"1618677700851299","bids":[["882.99","0.00000000"],["882.83","37.25600136"],["882.71","0.00000000"]],"asks":[["884.02","3.00000000"],["884.15","0.00000000"],["884.68","0.00000000"],["884.69","0.00000000"],["885.02","0.00000000"]]},"channel":"diff_order_book_bcheur","event":"data"}
1618677700.9508858: {"data":{"timestamp":"1618677700","microtimestamp":"1618677700752690","bids":[["60504.20","0.00000000"],["60361.91","0.12247231"],["60350.97","0.00000000"]],"asks":[["60553.64","0.35751000"],["60563.25","0.00000000"],["60569.41","0.19184276"],["60807.97","0.37772090"]]},"channel":"diff_order_book_btcusd","event":"data"}
1618677701.009224: {"data":{"timestamp":"1618677700","microtimestamp":"1618677700958808","bids":[],"asks":[["766.08","7.40000000"]]},"channel":"diff_order_book_bchgbp","event":"data"}
1618677701.026098: {"data":{"timestamp":"1618677700","microtimestamp":"1618677700948831","bids":[],"asks":[["314.86","0.00000000"]]},"channel":"diff_order_book_ltcusd","event":"data"}
1618677701.087322: {"data":{"timestamp":"1618677701","microtimestamp":"1618677701008183","bids":[["882.84","37.25600136"],["882.83","0.00000000"],["882.82","0.00000000"],["882.72","0.00000000"],["882.66","0.00000000"],["882.53","7.00000000"],["882.52","48.43916000"],["882.43","2.37617105"],["882.41","34.38791000"]],"asks":[["884.16","30.10000000"],["884.17","2.37596997"],["884.41","32.26668000"],["884.62","37.54022000"]]},"channel":"diff_order_book_bcheur","event":"data"}
1618677701.195461: {"data":{"timestamp":"1618677701","microtimestamp":"1618677701112106","bids":[["309.68","78.14216716"]],"asks":[]},"channel":"diff_order_book_ltcusd","event":"data"}
1618677701.2384052: {"data":{"timestamp":"1618677701","microtimestamp":"1618677701197915","bids":[["759.11","0.15400000"]],"asks":[]},"channel":"diff_order_book_bchgbp","event":"data"}
1618677701.25725: {"data":{"timestamp":"1618677701","microtimestamp":"1618677701183474","bids":[["882.84","0.00000000"],["882.55","7.00000000"],["882.53","0.00000000"],["882.40","0.00000000"]],"asks":[["884.14","5.10000000"],["884.16","25.00000000"],["885.21","0.00000000"]]},"channel":"diff_order_book_bcheur","event":"data"}
1618677701.285465: {"data":{"timestamp":"1618677701","microtimestamp":"1618677701224282","bids":[["0.00067827","0.00000000"],["0.00067710","0.00000000"]],"asks":[]},"channel":"diff_order_book_linkbtc","event":"data"}
1618677701.348246: {"data":{"timestamp":"1618677701","microtimestamp":"1618677701313265","bids":[["759.10","1.95000000"]],"asks":[]},"channel":"diff_order_book_bchgbp","event":"data"}
1618677701.360744: {"data":{"timestamp":"1618677701","microtimestamp":"1618677701269612","bids":[["312.64","0.00000000"]],"asks":[["313.18","0.00000000"]]},"channel":"diff_order_book_ltcusd","event":"data"}
1618677701.3962922: {"data":{"timestamp":"1618677701","microtimestamp":"1618677701338971","bids":[],"asks":[["3.39252","0.00000000"]]},"channel":"diff_order_book_kncusd","event":"data"}
1618677701.399462: {"data":{"timestamp":"1618677701","microtimestamp":"1618677701340731","bids":[["0.00067828","15.88756214"],["0.00067710","69.50959561"]],"asks":[["0.00067950","0.00000000"]]},"channel":"diff_order_book_linkbtc","event":"data"}
1618677701.421773: {"data":{"timestamp":"1618677701","microtimestamp":"1618677701342580","bids":[["882.58","37.25600136"],["882.57","3.00000000"],["882.55","0.00000000"],["882.53","3.00000000"],["882.30","2.80000000"]],"asks":[["884.14","0.00000000"],["884.15","5.10000000"]]},"channel":"diff_order_book_bcheur","event":"data"}
1618677701.425611: {"data":{"timestamp":"1618677701","microtimestamp":"1618677701263917","bids":[["59900.00","4.73309388"]],"asks":[["60569.41","0.00000000"],["60571.41","0.00000000"],["60578.32","0.00000000"],["60579.62","0.35667522"],["60807.97","0.00000000"],["61719.09","0.00000000"]]},"channel":"diff_order_book_btcusd","event":"data"}
1618677701.514373: {"data":{"timestamp":"1618677701","microtimestamp":"1618677701460288","bids":[],"asks":[["0.00067960","15.88759962"]]},"channel":"diff_order_book_linkbtc","event":"data"}
1618677701.525683: {"data":{"timestamp":"1618677701","microtimestamp":"1618677701448697","bids":[["312.69","6.37570000"]],"asks":[["313.12","3.19614927"]]},"channel":"diff_order_book_ltcusd","event":"data"}
1618677701.583362: {"data":{"timestamp":"1618677701","microtimestamp":"1618677701507660","bids":[["882.62","3.00000000"],["882.58","0.00000000"],["882.53","0.00000000"]],"asks":[["884.14","2.90000000"],["884.15","0.00000000"]]},"channel":"diff_order_book_bcheur","event":"data"}
1618677701.6910238: {"data":{"timestamp":"1618677701","microtimestamp":"1618677701625199","bids":[["309.68","0.00000000"]],"asks":[]},"channel":"diff_order_book_ltcusd","event":"data"}
1618677701.744504: {"data":{"timestamp":"1618677701","microtimestamp":"1618677701708515","bids":[["3.37539","0.00000000"]],"asks":[]},"channel":"diff_order_book_kncusd","event":"data"}
1618677701.755836: {"data":{"timestamp":"1618677701","microtimestamp":"1618677701658659","bids":[["882.59","3.00000000"],["882.58","37.25600136"],["882.54","4.00000000"]],"asks":[["884.05","2.90000000"],["884.14","0.00000000"]]},"channel":"diff_order_book_bcheur","event":"data"}
1618677701.84944: {"data":{"timestamp":"1618677701","microtimestamp":"1618677701666586","bids":[["60542.43","0.05735573"],["60496.72","0.08230000"],["60494.03","0.00000000"],["60494.00","0.33020000"],["60492.80","0.00000000"]],"asks":[["60564.32","0.05151115"],["60567.18","0.15411040"],["60571.41","0.29275251"],["60574.54","0.29096555"],["60579.62","0.00000000"],["60623.25","0.51576345"]]},"channel":"diff_order_book_btcusd","event":"data"}
1618677701.86579: {"data":{"timestamp":"1618677701","microtimestamp":"1618677701786069","bids":[["312.70","14.00000000"]],"asks":[]},"channel":"diff_order_book_ltcusd","event":"data"}
1618677701.8659341: {"data":{"timestamp":"1618677701","microtimestamp":"1618677701826547","bids":[["3.37791","8795.81241329"]],"asks":[]},"channel":"diff_order_book_kncusd","event":"data"}
1618677701.996628: {"data":{"timestamp":"1618677701","microtimestamp":"1618677701925215","bids":[["882.63","37.25600136"],["882.59","0.00000000"],["882.58","3.00000000"],["882.54","0.00000000"],["882.53","4.00000000"]],"asks":[["884.05","0.00000000"],["884.14","2.20000000"],["884.15","2.90000000"]]},"channel":"diff_order_book_bcheur","event":"data"}
1618677702.025811: {"data":{"timestamp":"1618677701","microtimestamp":"1618677701934951","bids":[],"asks":[["314.96","159.02371056"]]},"channel":"diff_order_book_ltcusd","event":"data"}
1618677702.17221: {"data":{"timestamp":"1618677702","microtimestamp":"1618677702070409","bids":[["882.68","3.00000000"],["882.66","3.00000000"],["882.64","4.00000000"],["882.63","0.00000000"],["882.58","0.00000000"],["882.57","0.00000000"],["882.53","0.00000000"]],"asks":[["884.14","0.00000000"],["884.15","0.00000000"],["884.16","30.10000000"],["884.17","0.00000000"]]},"channel":"diff_order_book_bcheur","event":"data"}
1618677702.196704: {"data":{"timestamp":"1618677702","microtimestamp":"1618677702092598","bids":[],"asks":[["314.96","0.00000000"]]},"channel":"diff_order_book_ltcusd","event":"data"}
1618677702.252516: {"data":{"timestamp":"1618677702","microtimestamp":"1618677702206380","bids":[],"asks":[["0.00067951","0.00000000"]]},"channel":"diff_order_book_linkbtc","event":"data"}
1618677702.3390138: {"data":{"timestamp":"1618677702","microtimestamp":"1618677702233307","bids":[["882.73","3.00000000"],["882.66","0.00000000"],["882.64","0.00000000"],["882.62","0.00000000"],["882.53","4.00000000"]],"asks":[["883.98","2.37637469"],["884.14","2.20000000"],["884.16","25.00000000"],["884.48","2.37628319"]]},"channel":"diff_order_book_bcheur","event":"data"}
1618677702.379694: {"data":{"timestamp":"1618677702","microtimestamp":"1618677702192825","bids":[],"asks":[["60565.09","0.04690477"],["60567.18","0.00000000"],["60579.59","0.36546631"],["60623.25","0.00000000"]]},"channel":"diff_order_book_btcusd","event":"data"}
1618677702.5065238: {"data":{"timestamp":"1618677702","microtimestamp":"1618677702399416","bids":[["882.72","3.00000000"],["882.53","0.00000000"]],"asks":[["884.14","0.00000000"]]},"channel":"diff_order_book_bcheur","event":"data"}
1618677702.620103: {"data":{"timestamp":"1618677702","microtimestamp":"1618677702556399","bids":[["882.79","3.00000000"],["882.76","37.25600136"],["882.72","0.00000000"],["882.68","0.00000000"]],"asks":[]},"channel":"diff_order_book_bcheur","event":"data"}
1618677702.780525: {"data":{"timestamp":"1618677702","microtimestamp":"1618677702719411","bids":[["882.76","0.00000000"],["882.73","0.00000000"]],"asks":[]},"channel":"diff_order_book_bcheur","event":"data"}
1618677702.838926: {"data":{"timestamp":"1618677702","microtimestamp":"1618677702558903","bids":[],"asks":[["60564.32","0.00000000"],["60565.09","0.00000000"],["60579.59","0.00000000"],["60583.65","0.42968807"]]},"channel":"diff_order_book_btcusd","event":"data"}
1618677702.951251: {"data":{"timestamp":"1618677702","microtimestamp":"1618677702888249","bids":[["882.55","3.00000000"]],"asks":[["883.94","3.00000000"]]},"channel":"diff_order_book_bcheur","event":"data"}
1618677703.059253: {"data":{"timestamp":"1618677702","microtimestamp":"1618677702981763","bids":[["1716.55","0.00000000"]],"asks":[]},"channel":"diff_order_book_ethgbp","event":"data"}
1618677703.1155531: {"data":{"timestamp":"1618677703","microtimestamp":"1618677703055877","bids":[["882.55","0.00000000"]],"asks":[["884.15","2.20000000"]]},"channel":"diff_order_book_bcheur","event":"data"}
1618677703.1453261: {"data":{"timestamp":"1618677703","microtimestamp":"1618677703075329","bids":[["312.70","0.00000000"],["312.65","4.74492243"]],"asks":[]},"channel":"diff_order_book_ltcusd","event":"data"}
1618677703.172189: {"data":{"timestamp":"1618677703","microtimestamp":"1618677703111846","bids":[["1717.91","1.26854394"]],"asks":[]},"channel":"diff_order_book_ethgbp","event":"data"}
1618677703.2649658: {"data":{"timestamp":"1618677703","microtimestamp":"1618677703066514","bids":[["60536.44","0.16517687"],["60517.82","0.00000000"],["60496.72","0.00000000"],["60494.00","0.00000000"],["60257.68","0.14099627"],["60230.45","0.00000000"]],"asks":[["60583.65","0.00000000"],["60807.80","0.39634793"]]},"channel":"diff_order_book_btcusd","event":"data"}
1618677703.2862642: {"data":{"timestamp":"1618677703","microtimestamp":"1618677703222486","bids":[["882.59","44.25600136"]],"asks":[["884.06","7.90000000"],["884.15","0.00000000"]]},"channel":"diff_order_book_bcheur","event":"data"}
1618677703.310098: {"data":{"timestamp":"1618677703","microtimestamp":"1618677703237135","bids":[["312.69","6.38130000"]],"asks":[["313.13","1.44000000"],["313.26","0.00000000"]]},"channel":"diff_order_book_ltcusd","event":"data"}
1618677703.343644: {"data":{"timestamp":"1618677703","microtimestamp":"1618677703299947","bids":[],"asks":[["0.00067952","24.32287857"],["0.00067960","0.00000000"]]},"channel":"diff_order_book_linkbtc","event":"data"}
1618677703.453666: {"data":{"timestamp":"1618677703","microtimestamp":"1618677703376148","bids":[["882.59","0.00000000"],["882.30","0.00000000"]],"asks":[["884.05","2.90000000"],["884.06","2.80000000"]]},"channel":"diff_order_book_bcheur","event":"data"}
1618677703.50921: {"data":{"timestamp":"1618677703","microtimestamp":"1618677703433082","bids":[],"asks":[["0.00067951","15.88954813"]]},"channel":"diff_order_book_linkbtc","event":"data"}
1618677703.616618: {"data":{"timestamp":"1618677703","microtimestamp":"1618677703546084","bids":[["882.56","7.00000000"],["882.13","2.80000000"]],"asks":[["884.02","5.20000000"]]},"channel":"diff_order_book_bcheur","event":"data"}
1618677703.64072: {"data":{"timestamp":"1618677703","microtimestamp":"1618677703564857","bids":[["312.70","14.00000000"]],"asks":[["312.97","0.00000000"]]},"channel":"diff_order_book_ltcusd","event":"data"}
1618677703.666656: {"channel": "live_trades_bcheur", "data": {"amount": 3.0, "amount_str": "3.00000000", "buy_order_id": 1351035813306368, "id": 164507746, "microtimestamp": "1618677703589000", "price": 882.79, "price_str": "882.79", "sell_order_id": 1351035817705474, "timestamp": "1618677703", "type": 1}, "event": "trade"}
1618677703.730468: {"data":{"timestamp":"1618677703","microtimestamp":"1618677703568272","bids":[["60536.09","0.00000000"],["60496.92","0.08240000"],["60494.20","0.33010000"],["60444.32","0.00000000"]],"asks":[["60566.39","0.03829518"],["60571.41","0.29195559"],["60601.79","0.00000000"],["60807.80","0.00000000"],["60809.42","0.41344094"]]},"channel":"diff_order_book_btcusd","event":"data"}
1618677703.7421172: {"data":{"timestamp":"1618677703","microtimestamp":"1618677703704239","bids":[],"asks":[["1722.62","0.00000000"]]},"channel":"diff_order_book_ethgbp","event":"data"}
1618677703.780983: {"data":{"timestamp":"1618677703","microtimestamp":"1618677703702006","bids":[["882.79","0.00000000"],["882.56","0.00000000"],["882.53","44.25600136"]],"asks":[["883.97","2.90000000"],["884.02","3.00000000"],["884.05","0.00000000"]]},"channel":"diff_order_book_bcheur","event":"data"}
1618677703.808618: {"data":{"timestamp":"1618677703","microtimestamp":"1618677703730120","bids":[],"asks":[["312.98","20.37510000"],["312.99","0.00000000"]]},"channel":"diff_order_book_ltcusd","event":"data"}
1618677703.8961961: {"data":{"timestamp":"1618677703","microtimestamp":"1618677703850156","bids":[["882.54","37.25600136"],["882.53","0.00000000"]],"asks":[["884.05","2.20000000"]]},"channel":"diff_order_book_bcheur","event":"data"}
1618677704.1117299: {"data":{"timestamp":"1618677704","microtimestamp":"1618677704024055","bids":[["882.54","0.00000000"],["882.52","51.43916000"]],"asks":[["884.05","0.00000000"]]},"channel":"diff_order_book_bcheur","event":"data"}
1618677704.152492: {"data":{"timestamp":"1618677704","microtimestamp":"1618677704085143","bids":[["312.70","14.70000000"],["312.54","4.00000000"],["312.53","1.68945122"]],"asks":[["313.26","5.40890511"]]},"channel":"diff_order_book_ltcusd","event":"data"}
1618677704.22252: {"data":{"timestamp":"1618677704","microtimestamp":"1618677704009823","bids":[["60464.29","0.12500000"],["59950.00","1.80294713"]],"asks":[["60564.76","0.04977751"],["60566.39","0.00000000"],["60568.96","0.17257839"],["60569.61","0.28722012"],["60571.41","0.00000000"],["60625.03","0.51881376"],["60635.23","0.13000000"],["60809.42","0.00000000"],["61506.43","0.56716831"]]},"channel":"diff_order_book_btcusd","event":"data"}
1618677704.260996: {"data":{"timestamp":"1618677704","microtimestamp":"1618677704178669","bids":[],"asks":[["1722.39","0.00000000"]]},"channel":"diff_order_book_ethgbp","event":"data"}
1618677704.278147: {"data":{"timestamp":"1618677704","microtimestamp":"1618677704191279","bids":[["882.57","37.25600136"],["882.53","7.00000000"],["882.52","48.43916000"]],"asks":[["883.97","0.00000000"],["884.00","2.20000000"],["884.01","2.90000000"]]},"channel":"diff_order_book_bcheur","event":"data"}
1618677704.316606: {"data":{"timestamp":"1618677704","microtimestamp":"1618677704265773","bids":[["312.70","14.00000000"],["312.67","0.00000000"],["312.54","0.00000000"],["312.53","5.68945122"]],"asks":[]},"channel":"diff_order_book_ltcusd","event":"data"}
1618677704.375902: {"data":{"timestamp":"1618677704","microtimestamp":"1618677704300157","bids":[["1717.49","0.00000000"],["1713.60","0.00000000"]],"asks":[["1721.24","1.26861661"],["1721.83","1.26856794"],["1729.20","0.00000000"],["1732.08","0.00000000"]]},"channel":"diff_order_book_ethgbp","event":"data"}
1618677704.396906: {"data":{"timestamp":"1618677704","microtimestamp":"1618677704336794","bids":[["882.60","3.00000000"],["882.57","0.00000000"]],"asks":[["884.00","0.00000000"],["884.01","0.00000000"]]},"channel":"diff_order_book_bcheur","event":"data"}
1618677704.424952: {"data":{"timestamp":"1618677704","microtimestamp":"1618677704385281","bids":[],"asks":[["766.08","0.00000000"]]},"channel":"diff_order_book_bchgbp","event":"data"}
1618677704.476704: {"data":{"timestamp":"1618677704","microtimestamp":"1618677704407801","bids":[],"asks":[["0.00067951","0.00000000"],["0.00067952","0.00000000"]]},"channel":"diff_order_book_linkbtc","event":"data"}
1618677704.48101: {"data":{"timestamp":"1618677704","microtimestamp":"1618677704424539","bids":[["312.60","3.19609500"]],"asks":[["313.12","0.00000000"]]},"channel":"diff_order_book_ltcusd","event":"data"}
1618677704.4911208: {"data":{"timestamp":"1618677704","microtimestamp":"1618677704418577","bids":[["1713.06","0.21300000"]],"asks":[["1724.66","0.50600000"],["1729.20","1.01100000"]]},"channel":"diff_order_book_ethgbp","event":"data"}
1618677704.539506: {"data":{"timestamp":"1618677704","microtimestamp":"1618677704505233","bids":[],"asks":[["765.86","2.70000000"]]},"channel":"diff_order_book_bchgbp","event":"data"}
1618677704.590143: {"data":{"timestamp":"1618677704","microtimestamp":"1618677704532420","bids":[],"asks":[["0.00067960","15.88833183"]]},"channel":"diff_order_book_linkbtc","event":"data"}
1618677704.592244: {"data":{"timestamp":"1618677704","microtimestamp":"1618677704532858","bids":[["3.37541","3020.72562000"]],"asks":[["3.39252","1352.08755000"]]},"channel":"diff_order_book_kncusd","event":"data"}
1618677704.608628: {"data":{"timestamp":"1618677704","microtimestamp":"1618677704536745","bids":[],"asks":[["1721.83","0.00000000"]]},"channel":"diff_order_book_ethgbp","event":"data"}
1618677704.611047: {"data":{"timestamp":"1618677704","microtimestamp":"1618677704512376","bids":[["882.53","4.00000000"],["882.52","0.00000000"]],"asks":[["886.36","0.00000000"]]},"channel":"diff_order_book_bcheur","event":"data"}
1618677704.645975: {"data":{"timestamp":"1618677704","microtimestamp":"1618677704573628","bids":[["312.65","0.00000000"],["312.55","0.00000000"]],"asks":[["313.22","37.61509764"]]},"channel":"diff_order_book_ltcusd","event":"data"}
1618677704.6849558: {"data":{"timestamp":"1618677704","microtimestamp":"1618677704530917","bids":[["60464.29","0.00000000"],["60119.74","0.77562994"]],"asks":[["60568.96","0.00000000"],["60625.03","0.00000000"],["60635.23","0.00000000"],["60808.01","0.38091431"]]},"channel":"diff_order_book_btcusd","event":"data"}
1618677704.706336: {"data":{"timestamp":"1618677704","microtimestamp":"1618677704627757","bids":[],"asks":[["765.74","5.20000000"]]},"channel":"diff_order_book_bchgbp","event":"data"}
1618677704.7272162: {"data":{"timestamp":"1618677704","microtimestamp":"1618677704670374","bids":[["882.83","37.25600136"],["882.82","50.12248000"],["882.66","3.00000000"],["882.53","0.00000000"]],"asks":[["884.04","2.90000000"],["885.97","6.70000000"],["886.35","0.00000000"],["888.03","8.38400000"]]},"channel":"diff_order_book_bcheur","event":"data"}
1618677704.8087559: {"channel": "live_trades_bcheur", "data": {"amount": 10.16, "amount_str": "10.16000000", "buy_order_id": 1351035821903874, "id": 164507749, "microtimestamp": "1618677704735000", "price": 882.83, "price_str": "882.83", "sell_order_id": 1351035822399488, "timestamp": "1618677704", "type": 1}, "event": "trade"}
1618677704.809827: {"data":{"timestamp":"1618677704","microtimestamp":"1618677704734236","bids":[["312.70","0.00000000"],["312.49","17.58070122"]],"asks":[["313.16","1.60000000"]]},"channel":"diff_order_book_ltcusd","event":"data"}
1618677704.8203788: {"data":{"timestamp":"1618677704","microtimestamp":"1618677704743356","bids":[],"asks":[["765.80","0.00000000"]]},"channel":"diff_order_book_bchgbp","event":"data"}
1618677704.888715: {"data":{"timestamp":"1618677704","microtimestamp":"1618677704857848","bids":[],"asks":[["765.43","1.42581209"],["765.53","2.85162418"],["766.44","0.00000000"]]},"channel":"diff_order_book_bchgbp","event":"data"}
1618677704.888919: {"data":{"timestamp":"1618677704","microtimestamp":"1618677704819171","bids":[["882.83","0.00000000"],["882.60","0.00000000"]],"asks":[["884.04","0.00000000"],["884.05","2.20000000"],["885.96","8.38400000"],["888.03","0.00000000"]]},"channel":"diff_order_book_bcheur","event":"data"}
1618677704.949656: {"data":{"timestamp":"1618677704","microtimestamp":"1618677704885562","bids":[["1716.36","0.00000000"]],"asks":[]},"channel":"diff_order_book_ethgbp","event":"data"}
1618677704.975404: {"data":{"timestamp":"1618677704","microtimestamp":"1618677704889637","bids":[["312.68","0.00000000"],["312.52","114.17858000"]],"asks":[["313.07","30.00000000"],["313.08","164.88330000"],["313.17","0.00000000"]]},"channel":"diff_order_book_ltcusd","event":"data"}
1618677705.0646698: {"data":{"timestamp":"1618677705","microtimestamp":"1618677705006568","bids":[["1715.24","0.10600000"]],"asks":[]},"channel":"diff_order_book_ethgbp","event":"data"}
1618677705.1894422: {"data":{"timestamp":"1618677705","microtimestamp":"1618677705118105","bids":[["882.83","27.09600136"]],"asks":[["883.96","10.16000000"],["884.00","2.90000000"],["884.05","0.00000000"]]},"channel":"diff_order_book_bcheur","event":"data"}
1618677705.202202: {"data":{"timestamp":"1618677705","microtimestamp":"1618677705009086","bids":[["60473.88","0.16450000"],["60198.79","0.04956385"],["60155.07","0.00000000"],["60119.74","0.00000000"],["54488.80","0.00200000"]],"asks":[["60565.66","0.04267990"],["60574.54","0.00000000"],["60631.82","0.13000000"],["60808.01","0.00000000"]]},"channel":"diff_order_book_btcusd","event":"data"}
1618677705.232379: {"data":{"timestamp":"1618677705","microtimestamp":"1618677705156418","bids":[["312.69","0.00000000"],["312.53","12.07915122"]],"asks":[]},"channel":"diff_order_book_ltcusd","event":"data"}
1618677705.3582458: {"data":{"timestamp":"1618677705","microtimestamp":"1618677705272187","bids":[["882.83","0.00000000"],["882.82","0.00000000"],["882.21","0.00000000"]],"asks":[["883.96","0.00000000"],["884.00","0.00000000"],["884.01","2.20000000"],["884.40","5.48993485"],["884.83","0.00000000"]]},"channel":"diff_order_book_bcheur","event":"data"}
1618677705.3956091: {"data":{"timestamp":"1618677705","microtimestamp":"1618677705320207","bids":[],"asks":[["313.27","195.65000000"],["320.00","10.49206736"]]},"channel":"diff_order_book_ltcusd","event":"data"}
1618677705.524585: {"data":{"timestamp":"1618677705","microtimestamp":"1618677705433165","bids":[["882.53","27.09600136"],["882.44","0.73268850"]],"asks":[["883.93","10.16000000"],["883.96","2.90000000"]]},"channel":"diff_order_book_bcheur","event":"data"}
1618677705.5615559: {"data":{"timestamp":"1618677705","microtimestamp":"1618677705484658","bids":[],"asks":[["313.16","22.73100000"]]},"channel":"diff_order_book_ltcusd","event":"data"}
1618677705.566071: {"data":{"timestamp":"1618677705","microtimestamp":"1618677705374067","bids":[["60542.43","0.00000000"],["60520.95","0.24776537"]],"asks":[["60571.41","0.28908894"],["60625.25","0.49109129"],["60631.42","0.25587650"],["60631.82","0.00000000"]]},"channel":"diff_order_book_btcusd","event":"data"}
1618677705.628169: {"data":{"timestamp":"1618677705","microtimestamp":"1618677705575355","bids":[],"asks":[["765.86","0.00000000"]]},"channel":"diff_order_book_bchgbp","event":"data"}
1618677705.69262: {"data":{"timestamp":"1618677705","microtimestamp":"1618677705623482","bids":[["882.76","49.37079000"],["882.53","0.00000000"],["882.51","3.00000000"],["882.44","4.73268850"]],"asks":[["883.89","3.00000000"],["883.93","0.00000000"],["883.96","0.00000000"],["884.01","0.00000000"],["884.02","0.00000000"]]},"channel":"diff_order_book_bcheur","event":"data"}
1618677705.725725: {"data":{"timestamp":"1618677705","microtimestamp":"1618677705648877","bids":[["312.61","14.00000000"],["312.60","0.00000000"],["312.53","11.27577988"],["312.52","4.00000000"]],"asks":[["313.00","473.63655162"],["313.07","0.00000000"],["313.08","0.00000000"]]},"channel":"diff_order_book_ltcusd","event":"data"}
1618677705.857163: {"data":{"timestamp":"1618677705","microtimestamp":"1618677705776349","bids":[["882.77","27.09600136"],["882.64","34.69334000"],["882.49","2.80000000"],["882.41","0.00000000"],["882.13","0.00000000"],["881.95","0.00000000"]],"asks":[["883.94","0.00000000"],["884.15","10.16000000"]]},"channel":"diff_order_book_bcheur","event":"data"}
1618677705.892823: {"data":{"timestamp":"1618677705","microtimestamp":"1618677705806223","bids":[["312.53","12.07915122"],["312.52","115.67858000"],["312.36","0.00000000"]],"asks":[["313.00","470.44000000"],["313.16","1.60000000"],["313.26","0.00000000"]]},"channel":"diff_order_book_ltcusd","event":"data"}
1618677706.028948: {"data":{"timestamp":"1618677705","microtimestamp":"1618677705961836","bids":[["881.56","6.50000000"]],"asks":[]},"channel":"diff_order_book_bcheur","event":"data"}
1618677706.062846: {"data":{"timestamp":"1618677705","microtimestamp":"1618677705963179","bids":[],"asks":[["313.13","0.00000000"],["313.18","152.12760000"],["313.28","22.64600000"]]},"channel":"diff_order_book_ltcusd","event":"data"}
1618677706.0892649: {"data":{"timestamp":"1618677706","microtimestamp":"1618677706054687","bids":[["764.40","1.42598494"]],"asks":[]},"channel":"diff_order_book_bchgbp","event":"data"}
1618677706.105803: {"data":{"timestamp":"1618677705","microtimestamp":"1618677705905806","bids":[["60473.88","0.00000000"]],"asks":[["60589.75","0.13263478"],["60600.88","0.00000000"],["60625.11","0.50859525"],["60625.25","0.00000000"],["60631.42","0.00000000"]]},"channel":"diff_order_book_btcusd","event":"data"}
1618677706.141716: {"data":{"timestamp":"1618677706","microtimestamp":"1618677706104850","bids":[],"asks":[["1720.52","1.26869566"]]},"channel":"diff_order_book_ethgbp","event":"data"}
1618677706.1971252: {"data":{"timestamp":"1618677706","microtimestamp":"1618677706128968","bids":[["882.81","3.00000000"],["882.77","0.00000000"],["882.76","0.00000000"]],"asks":[["884.13","2.20000000"],["884.15","0.00000000"],["884.41","0.00000000"],["884.62","0.00000000"],["884.71","29.54608000"],["884.87","38.04862000"]]},"channel":"diff_order_book_bcheur","event":"data"}
1618677706.1988769: {"data":{"timestamp":"1618677706","microtimestamp":"1618677706135478","bids":[["312.31","1.46800000"]],"asks":[["313.28","1.51500000"]]},"channel":"diff_order_book_ltcusd","event":"data"}
1618677706.2517009: {"data":{"timestamp":"1618677706","microtimestamp":"1618677706176637","bids":[["764.06","5.80000000"]],"asks":[]},"channel":"diff_order_book_bchgbp","event":"data"}
1618677706.36021: {"data":{"timestamp":"1618677706","microtimestamp":"1618677706310909","bids":[["882.83","27.09600136"],["882.68","3.00000000"],["882.66","4.00000000"],["882.57","2.37608619"],["882.51","0.00000000"],["882.44","0.73268850"],["882.43","0.00000000"]],"asks":[["883.98","0.00000000"],["884.13","0.00000000"],["884.84","0.00000000"],["885.18","2.37576092"],["888.03","10.16000000"]]},"channel":"diff_order_book_bcheur","event":"data"}
1618677706.36798: {"data":{"timestamp":"1618677706","microtimestamp":"1618677706296384","bids":[],"asks":[["765.43","0.00000000"],["765.53","0.00000000"],["765.64","1.42545655"]]},"channel":"diff_order_book_bchgbp","event":"data"}
1618677706.520494: {"data":{"timestamp":"1618677706","microtimestamp":"1618677706319558","bids":[["60539.89","0.05408150"],["60517.83","0.00000000"],["60496.92","0.00000000"],["60494.82","0.08240000"],["60494.20","0.00000000"],["60492.10","0.33010000"]],"asks":[["60622.96","0.50894349"],["60625.11","0.00000000"]]},"channel":"diff_order_book_btcusd","event":"data"}
1618677706.525771: {"data":{"timestamp":"1618677706","microtimestamp":"1618677706462067","bids":[["882.87","3.00000000"],["882.83","0.00000000"],["882.68","0.00000000"],["882.66","0.00000000"],["882.65","3.00000000"],["881.57","1.00000000"],["881.51","0.00000000"]],"asks":[["884.14","2.20000000"],["884.15","2.90000000"],["884.71","0.00000000"]]},"channel":"diff_order_book_bcheur","event":"data"}
1618677706.597395: {"data":{"timestamp":"1618677706","microtimestamp":"1618677706535298","bids":[["759.11","0.55400000"],["759.10","1.55000000"]],"asks":[]},"channel":"diff_order_book_bchgbp","event":"data"}
1618677706.6964312: {"data":{"timestamp":"1618677706","microtimestamp":"1618677706622043","bids":[["882.81","0.00000000"],["882.76","27.09600136"],["882.75","50.47693000"],["882.65","0.00000000"],["882.49","0.00000000"]],"asks":[["884.14","0.00000000"],["884.15","0.00000000"],["884.87","0.00000000"],["888.03","0.00000000"]]},"channel":"diff_order_book_bcheur","event":"data"}
1618677706.8584478: {"data":{"timestamp":"1618677706","microtimestamp":"1618677706767437","bids":[["882.65","4.00000000"],["882.40","2.80000000"]],"asks":[["884.05","2.90000000"]]},"channel":"diff_order_book_bcheur","event":"data"}
1618677707.0100968: {"data":{"timestamp":"1618677706","microtimestamp":"1618677706811126","bids":[["60473.88","0.01025000"]],"asks":[["60568.47","0.17901122"],["60622.96","0.00000000"],["60807.03","0.39863345"]]},"channel":"diff_order_book_btcusd","event":"data"}
1618677707.024906: {"data":{"timestamp":"1618677706","microtimestamp":"1618677706948388","bids":[["882.65","0.00000000"]],"asks":[["884.05","0.00000000"]]},"channel":"diff_order_book_bcheur","event":"data"}
1618677707.084508: {"data":{"timestamp":"1618677706","microtimestamp":"1618677706993715","bids":[],"asks":[["313.07","3.19585027"]]},"channel":"diff_order_book_ltcusd","event":"data"}
1618677707.187979: {"data":{"timestamp":"1618677707","microtimestamp":"1618677707094810","bids":[["882.77","27.09600136"],["882.76","0.00000000"],["882.75","0.00000000"],["882.64","0.00000000"],["882.58","3.00000000"],["882.51","4.00000000"],["882.30","34.32705000"]],"asks":[["884.05","2.90000000"],["884.14","2.20000000"],["884.32","30.74630000"]]},"channel":"diff_order_book_bcheur","event":"data"}
1618677707.255685: {"data":{"timestamp":"1618677707","microtimestamp":"1618677707186015","bids":[["312.59","3.19606639"],["309.68","78.14216716"]],"asks":[]},"channel":"diff_order_book_ltcusd","event":"data"}
1618677707.354605: {"data":{"timestamp":"1618677707","microtimestamp":"1618677707257922","bids":[["882.77","0.00000000"],["882.58","0.00000000"],["882.51","0.00000000"]],"asks":[["884.14","0.00000000"],["884.15","10.16000000"],["884.44","39.76278000"]]},"channel":"diff_order_book_bcheur","event":"data"}
1618677707.463561: {"data":{"timestamp":"1618677707","microtimestamp":"1618677707172237","bids":[["60536.32","0.16517745"],["60492.10","0.00000000"],["60491.50","0.33000000"],["60473.88","0.01275000"],["60257.68","0.00000000"],["59950.00","1.40000000"]],"asks":[["60566.12","0.19348859"],["60568.47","0.00000000"],["60569.60","0.29807115"],["60571.41","0.00000000"],["60576.46","0.37800399"],["60667.46","0.00000000"],["60807.03","0.00000000"],["61506.43","0.06930000"]]},"channel":"diff_order_book_btcusd","event":"data"}
1618677707.497697: {"data":{"timestamp":"1618677707","microtimestamp":"1618677707429776","bids":[["0.00067828","0.00000000"],["0.00067827","15.89122945"],["0.00067710","0.00000000"]],"asks":[]},"channel":"diff_order_book_linkbtc","event":"data"}
1618677707.518251: {"data":{"timestamp":"1618677707","microtimestamp":"1618677707437073","bids":[["882.52","31.09600136"],["881.59","1.00000000"],["881.57","0.00000000"]],"asks":[["884.03","2.90000000"],["884.05","0.00000000"],["884.15","0.00000000"]]},"channel":"diff_order_book_bcheur","event":"data"}
1618677707.611876: {"data":{"timestamp":"1618677707","microtimestamp":"1618677707571341","bids":[["2.55000","21428.89215681"]],"asks":[]},"channel":"diff_order_book_knceur","event":"data"}
1618677707.611965: {"data":{"timestamp":"1618677707","microtimestamp":"1618677707547774","bids":[["0.00067710","72.82209242"]],"asks":[["0.00067951","15.89260328"],["0.00067952","24.26528396"],["0.00067960","0.00000000"]]},"channel":"diff_order_book_linkbtc","event":"data"}
1618677707.627414: {"data":{"timestamp":"1618677707","microtimestamp":"1618677707584376","bids":[],"asks":[["765.65","2.85119392"]]},"channel":"diff_order_book_bchgbp","event":"data"}
1618677707.684: {"data":{"timestamp":"1618677707","microtimestamp":"1618677707611078","bids":[["882.61","34.09600136"],["882.60","50.20225000"],["882.52","0.00000000"],["882.30","0.00000000"]],"asks":[["884.03","0.00000000"]]},"channel":"diff_order_book_bcheur","event":"data"}
1618677707.7252128: {"data":{"timestamp":"1618677707","microtimestamp":"1618677707661097","bids":[["3.37541","0.00000000"]],"asks":[["3.39252","0.00000000"]]},"channel":"diff_order_book_kncusd","event":"data"}
1618677707.73223: {"data":{"timestamp":"1618677707","microtimestamp":"1618677707658382","bids":[["312.68","302.45480000"],["312.52","1.50000000"],["312.51","0.00000000"]],"asks":[["313.15","0.00000000"],["313.18","0.00000000"],["313.31","342.38200000"]]},"channel":"diff_order_book_ltcusd","event":"data"}
1618677707.884334: {"data":{"timestamp":"1618677707","microtimestamp":"1618677707691566","bids":[["60535.20","0.00000000"],["60503.44","0.04925173"],["60473.88","0.01025000"],["60361.91","0.00000000"],["60329.19","0.12462436"]],"asks":[["60566.11","0.28406222"],["60566.12","0.00000000"],["60569.61","0.00000000"],["60576.46","0.00000000"],["60587.71","0.16301427"],["60589.75","0.00000000"]]},"channel":"diff_order_book_btcusd","event":"data"}
1618677707.899585: {"data":{"timestamp":"1618677707","microtimestamp":"1618677707826939","bids":[["312.68","0.00000000"],["312.56","1.60000000"],["312.53","6.38970000"],["312.50","1.68968432"],["312.49","15.98070122"],["312.48","4.00000000"],["309.68","0.00000000"]],"asks":[["313.13","1.53000000"],["313.16","0.00000000"],["313.23","1.60000000"],["313.29","183.22783099"],["313.31","0.00000000"]]},"channel":"diff_order_book_ltcusd","event":"data"}
1618677707.953795: {"data":{"timestamp":"1618677707","microtimestamp":"1618677707883528","bids":[["882.61","3.00000000"]],"asks":[["884.04","2.90000000"],["884.15","12.36000000"]]},"channel":"diff_order_book_bcheur","event":"data"}
1618677707.953988: {"data":{"timestamp":"1618677707","microtimestamp":"1618677707906998","bids":[["0.00067819","0.00000000"]],"asks":[]},"channel":"diff_order_book_linkbtc","event":"data"}
1618677707.969345: {"data":{"timestamp":"1618677707","microtimestamp":"1618677707938491","bids":[],"asks":[["765.99","2.70000000"]]},"channel":"diff_order_book_bchgbp","event":"data"}
1618677708.063092: {"data":{"timestamp":"1618677707","microtimestamp":"1618677707979150","bids":[["312.69","14.00000000"],["312.61","0.00000000"],["312.48","0.00000000"],["312.36","4.00000000"]],"asks":[]},"channel":"diff_order_book_ltcusd","event":"data"}
1618677708.068404: {"data":{"timestamp":"1618677708","microtimestamp":"1618677708031225","bids":[["0.00067827","0.00000000"],["0.00067798","15.89401107"],["0.00067710","0.00000000"]],"asks":[]},"channel":"diff_order_book_linkbtc","event":"data"}
1618677708.118083: {"data":{"timestamp":"1618677708","microtimestamp":"1618677708041304","bids":[["882.64","27.09600136"],["882.61","0.00000000"],["882.56","35.33315000"]],"asks":[["884.13","2.20000000"],["884.15","0.00000000"]]},"channel":"diff_order_book_bcheur","event":"data"}
1618677708.2299242: {"data":{"timestamp":"1618677708","microtimestamp":"1618677708131592","bids":[["312.69","0.00000000"],["312.53","0.00000000"]],"asks":[]},"channel":"diff_order_book_ltcusd","event":"data"}
1618677708.2341352: {"data":{"timestamp":"1618677708","microtimestamp":"1618677708151872","bids":[["0.00067710","71.07087041"]],"asks":[]},"channel":"diff_order_book_linkbtc","event":"data"}
1618677708.287277: {"data":{"timestamp":"1618677708","microtimestamp":"1618677708207095","bids":[["882.64","0.00000000"],["882.60","0.00000000"],["882.58","3.00000000"]],"asks":[["884.04","0.00000000"],["884.13","0.00000000"],["884.15","2.20000000"],["884.32","0.00000000"],["884.44","0.00000000"],["884.56","31.53321000"],["884.72","38.14534000"]]},"channel":"diff_order_book_bcheur","event":"data"}
1618677708.3443289: {"data":{"timestamp":"1618677708","microtimestamp":"1618677708287884","bids":[["312.54","6.39290000"],["312.52","0.00000000"],["311.41","114.17858000"]],"asks":[]},"channel":"diff_order_book_ltcusd","event":"data"}
1618677708.3495018: {"data":{"timestamp":"1618677708","microtimestamp":"1618677708275264","bids":[],"asks":[["0.00068106","103.10000000"],["0.00068304","0.00000000"]]},"channel":"diff_order_book_linkbtc","event":"data"}
1618677708.375166: {"data":{"timestamp":"1618677708","microtimestamp":"1618677708209619","bids":[["60520.96","0.28041919"],["60503.44","0.00000000"],["60473.88","0.00000000"],["60471.18","0.16450000"],["60229.42","0.10990735"]],"asks":[["60628.72","0.48833000"],["60711.03","0.15526401"],["60805.38","0.37485665"]]},"channel":"diff_order_book_btcusd","event":"data"}
1618677708.453109: {"data":{"timestamp":"1618677708","microtimestamp":"1618677708361667","bids":[["882.65","3.00000000"],["882.64","4.00000000"],["882.58","0.00000000"]],"asks":[["884.14","5.10000000"],["884.15","10.16000000"]]},"channel":"diff_order_book_bcheur","event":"data"}
1618677708.460514: {"data":{"timestamp":"1618677708","microtimestamp":"1618677708395184","bids":[["3.37540","0.00000000"]],"asks":[]},"channel":"diff_order_book_kncusd","event":"data"}
1618677708.518069: {"data":{"timestamp":"1618677708","microtimestamp":"1618677708446670","bids":[["312.60","14.00000000"],["312.54","0.00000000"],["311.42","114.17858000"],["311.41","0.00000000"]],"asks":[["313.29","204.35883099"]]},"channel":"diff_order_book_ltcusd","event":"data"}
1618677708.56656: {"data":{"timestamp":"1618677708","microtimestamp":"1618677708508161","bids":[["882.65","0.00000000"],["882.64","0.00000000"],["882.58","3.00000000"],["882.57","6.37608619"]],"asks":[["884.14","12.36000000"],["884.15","0.00000000"]]},"channel":"diff_order_book_bcheur","event":"data"}
1618677708.576206: {"data":{"timestamp":"1618677708","microtimestamp":"1618677708512914","bids":[["3.35248","780.00000000"]],"asks":[]},"channel":"diff_order_book_kncusd","event":"data"}
1618677708.691063: {"data":{"timestamp":"1618677708","microtimestamp":"1618677708632684","bids":[["3.37652","780.00000000"],["3.35248","0.00000000"]],"asks":[]},"channel":"diff_order_book_kncusd","event":"data"}
1618677708.692356: {"data":{"timestamp":"1618677708","microtimestamp":"1618677708648656","bids":[],"asks":[["0.00067951","0.00000000"]]},"channel":"diff_order_book_linkbtc","event":"data"}
1618677708.718983: {"data":{"timestamp":"1618677708","microtimestamp":"1618677708649171","bids":[["1717.44","0.05000000"]],"asks":[]},"channel":"diff_order_book_ethgbp","event":"data"}
1618677708.7316449: {"data":{"timestamp":"1618677708","microtimestamp":"1618677708654537","bids":[["882.88","27.09600136"],["882.85","47.74598000"],["882.58","0.00000000"],["882.57","2.37608619"]],"asks":[["884.04","2.37606896"],["884.14","0.00000000"]]},"channel":"diff_order_book_bcheur","event":"data"}
1618677708.732627: {"data":{"timestamp":"1618677708","microtimestamp":"1618677708643845","bids":[["312.61","4.00000000"],["312.60","340.59970000"],["312.58","140.57630000"],["312.50","8.07038432"],["312.36","0.00000000"],["311.63","153.84262069"],["311.42","0.00000000"]],"asks":[["313.23","368.15260000"]]},"channel":"diff_order_book_ltcusd","event":"data"}
1618677708.7963789: {"data":{"timestamp":"1618677708","microtimestamp":"1618677708608752","bids":[["60534.14","0.00000000"],["60520.97","0.27621716"],["60471.18","0.17475000"],["60259.86","0.12420997"]],"asks":[["60600.16","0.14970109"],["60628.72","0.40420650"],["60680.33","0.15286903"],["60805.38","0.00000000"]]},"channel":"diff_order_book_btcusd","event":"data"}
1618677708.8092659: {"data":{"timestamp":"1618677708","microtimestamp":"1618677708765886","bids":[],"asks":[["0.00067929","15.89514821"]]},"channel":"diff_order_book_linkbtc","event":"data"}
1618677708.8480582: {"data":{"timestamp":"1618677708","microtimestamp":"1618677708795828","bids":[["312.62","14.00000000"],["311.63","39.66404069"],["311.39","0.00000000"]],"asks":[]},"channel":"diff_order_book_ltcusd","event":"data"}
1618677708.9484348: {"data":{"timestamp":"1618677708","microtimestamp":"1618677708883247","bids":[["1715.24","0.00000000"]],"asks":[["1724.66","0.00000000"]]},"channel":"diff_order_book_ethgbp","event":"data"}
1618677709.013946: {"data":{"timestamp":"1618677708","microtimestamp":"1618677708946504","bids":[["312.62","18.00000000"],["312.61","114.17858000"]],"asks":[["313.20","167.74000000"],["313.29","41.92203099"]]},"channel":"diff_order_book_ltcusd","event":"data"}
1618677709.06078: {"data":{"timestamp":"1618677708","microtimestamp":"1618677708960874","bids":[["882.92","3.00000000"]],"asks":[["884.14","2.20000000"]]},"channel":"diff_order_book_bcheur","event":"data"}
1618677709.060888: {"data":{"timestamp":"1618677708","microtimestamp":"1618677708999996","bids":[],"asks":[["1729.19","0.50600000"],["1729.20","0.00000000"]]},"channel":"diff_order_book_ethgbp","event":"data"}
1618677709.175793: {"data":{"timestamp":"1618677709","microtimestamp":"1618677709126608","bids":[["1716.36","0.10600000"]],"asks":[["1732.08","1.01100000"]]},"channel":"diff_order_book_ethgbp","event":"data"}
1618677709.178751: {"data":{"timestamp":"1618677709","microtimestamp":"1618677709116303","bids":[["312.52","1.48500000"]],"asks":[]},"channel":"diff_order_book_ltcusd","event":"data"}
1618677709.1993961: {"data":{"timestamp":"1618677709","microtimestamp":"1618677709128695","bids":[["0.00067798","15.89419979"],["0.00067710","0.00000000"]],"asks":[]},"channel":"diff_order_book_linkbtc","event":"data"}
1618677709.229177: {"data":{"timestamp":"1618677709","microtimestamp":"1618677709139582","bids":[],"asks":[["884.14","0.00000000"],["884.15","10.16000000"]]},"channel":"diff_order_book_bcheur","event":"data"}
1618677709.2900631: {"data":{"timestamp":"1618677709","microtimestamp":"1618677709242549","bids":[],"asks":[["1729.19","0.00000000"]]},"channel":"diff_order_book_ethgbp","event":"data"}
1618677709.2976482: {"data":{"timestamp":"1618677709","microtimestamp":"1618677709116155","bids":[["60534.14","0.28452448"],["60520.96","0.00000000"],["60471.18","0.17725000"],["60229.42","0.00000000"]],"asks":[["60567.89","0.28824880"],["60569.60","0.00000000"],["60587.71","0.00000000"],["60711.03","0.00000000"],["60807.11","0.45108512"]]},"channel":"diff_order_book_btcusd","event":"data"}
1618677709.314441: {"data":{"timestamp":"1618677709","microtimestamp":"1618677709259052","bids":[["3.37643","0.00000000"]],"asks":[["3.39409","0.00000000"]]},"channel":"diff_order_book_kncusd","event":"data"}
1618677709.3151932: {"data":{"timestamp":"1618677709","microtimestamp":"1618677709246389","bids":[["0.00067710","72.95425096"]],"asks":[]},"channel":"diff_order_book_linkbtc","event":"data"}
1618677709.4077828: {"data":{"timestamp":"1618677709","microtimestamp":"1618677709362754","bids":[],"asks":[["1729.20","0.50600000"]]},"channel":"diff_order_book_ethgbp","event":"data"}
1618677709.536287: {"data":{"timestamp":"1618677709","microtimestamp":"1618677709469420","bids":[],"asks":[["313.13","0.00000000"]]},"channel":"diff_order_book_ltcusd","event":"data"}
1618677709.5575838: {"data":{"timestamp":"1618677709","microtimestamp":"1618677709486976","bids":[],"asks":[["884.15","0.00000000"],["884.47","36.67569000"],["884.72","0.00000000"]]},"channel":"diff_order_book_bcheur","event":"data"}
1618677709.5638862: {"data":{"timestamp":"1618677709","microtimestamp":"1618677709497843","bids":[],"asks":[["765.99","0.00000000"]]},"channel":"diff_order_book_bchgbp","event":"data"}
1618677709.579114: {"channel": "live_trades_bcheur", "data": {"amount": 3.0, "amount_str": "3.00000000", "buy_order_id": 1351035839041536, "id": 164507761, "microtimestamp": "1618677709504000", "price": 882.92, "price_str": "882.92", "sell_order_id": 1351035841933312, "timestamp": "1618677709", "type": 1}, "event": "trade"}
1618677709.579199: {"channel": "live_trades_bcheur", "data": {"amount": 16.41, "amount_str": "16.41000000", "buy_order_id": 1351035838173184, "id": 164507762, "microtimestamp": "1618677709504000", "price": 882.88, "price_str": "882.88", "sell_order_id": 1351035841933312, "timestamp": "1618677709", "type": 1}, "event": "trade"}
1618677709.586445: {"channel": "live_trades_bcheur", "data": {"amount": 10.68600136, "amount_str": "10.68600136", "buy_order_id": 1351035838173184, "id": 164507763, "microtimestamp": "1618677709530000", "price": 882.88, "price_str": "882.88", "sell_order_id": 1351035842039808, "timestamp": "1618677709", "type": 1}, "event": "trade"}
1618677709.586524: {"channel": "live_trades_bcheur", "data": {"amount": 2.99399864, "amount_str": "2.99399864", "buy_order_id": 1351035828903937, "id": 164507764, "microtimestamp": "1618677709530000", "price": 882.87, "price_str": "882.87", "sell_order_id": 1351035842039808, "timestamp": "1618677709", "type": 1}, "event": "trade"}
1618677709.656576: {"data":{"timestamp":"1618677709","microtimestamp":"1618677709620742","bids":[["3.37780","1440.00000000"]],"asks":[["3.39364","1288.00000000"]]},"channel":"diff_order_book_kncusd","event":"data"}
1618677709.65892: {"data":{"timestamp":"1618677709","microtimestamp":"1618677709600386","bids":[["0.00067817","24.64188402"],["0.00067710","0.00000000"]],"asks":[["0.00067952","0.00000000"]]},"channel":"diff_order_book_linkbtc","event":"data"}
1618677709.731562: {"data":{"timestamp":"1618677709","microtimestamp":"1618677709658910","bids":[["882.92","0.00000000"],["882.88","0.00000000"],["882.87","0.00600136"]],"asks":[["884.12","2.90000000"],["884.15","37.25600136"]]},"channel":"diff_order_book_bcheur","event":"data"}
1618677709.745516: {"data":{"timestamp":"1618677709","microtimestamp":"1618677709673610","bids":[["2.83488","1440.00000000"]],"asks":[["2.85305","1190.00000000"]]},"channel":"diff_order_book_knceur","event":"data"}
1618677709.75015: {"data":{"timestamp":"1618677709","microtimestamp":"1618677709482703","bids":[["60471.28","0.20560879"],["60471.18","0.00000000"],["60364.13","0.11919727"],["60329.19","0.00000000"]],"asks":[["60564.76","0.00000000"],["60565.66","0.00000000"],["60628.72","0.00000000"],["60634.93","0.01833000"],["60807.11","0.00000000"]]},"channel":"diff_order_book_btcusd","event":"data"}
1618677709.762173: {"data":{"timestamp":"1618677709","microtimestamp":"1618677709649378","bids":[["312.65","3.19529619"],["312.59","0.00000000"]],"asks":[["312.98","6.37510000"]]},"channel":"diff_order_book_ltcusd","event":"data"}
1618677709.776989: {"data":{"timestamp":"1618677709","microtimestamp":"1618677709720572","bids":[["0.00067799","71.84166138"]],"asks":[["0.00067929","0.00000000"],["0.00067960","15.89068726"]]},"channel":"diff_order_book_linkbtc","event":"data"}
1618677709.804228: {"data":{"timestamp":"1618677709","microtimestamp":"1618677709720955","bids":[],"asks":[["1724.94","6.30000000"]]},"channel":"diff_order_book_ethgbp","event":"data"}
1618677709.900386: {"data":{"timestamp":"1618677709","microtimestamp":"1618677709836018","bids":[],"asks":[["883.88","25.10000000"],["884.12","0.00000000"],["884.15","0.00000000"],["884.47","0.00000000"]]},"channel":"diff_order_book_bcheur","event":"data"}
1618677709.913601: {"data":{"timestamp":"1618677709","microtimestamp":"1618677709832473","bids":[["2.83615","738.36106362"],["2.83351","0.00000000"]],"asks":[]},"channel":"diff_order_book_knceur","event":"data"}
1618677709.917108: {"data":{"timestamp":"1618677709","microtimestamp":"1618677709839313","bids":[],"asks":[["1729.20","0.00000000"],["1732.08","0.00000000"]]},"channel":"diff_order_book_ethgbp","event":"data"}
1618677709.927328: {"data":{"timestamp":"1618677709","microtimestamp":"1618677709849125","bids":[["312.66","4.81337554"],["312.50","1.68968432"],["312.37","0.27868456"],["312.18","0.00000000"]],"asks":[["312.98","0.00000000"],["312.99","6.38260000"],["313.07","0.00000000"],["313.19","0.00000000"],["313.26","5.40890511"]]},"channel":"diff_order_book_ltcusd","event":"data"}
1618677710.040277: {"data":{"timestamp":"1618677709","microtimestamp":"1618677709959212","bids":[],"asks":[["1724.93","0.50600000"]]},"channel":"diff_order_book_ethgbp","event":"data"}
1618677710.068647: {"data":{"timestamp":"1618677710","microtimestamp":"1618677710008899","bids":[["882.71","2.80000000"],["882.40","0.00000000"]],"asks":[["883.87","37.25600136"]]},"channel":"diff_order_book_bcheur","event":"data"}
1618677710.1227899: {"data":{"timestamp":"1618677709","microtimestamp":"1618677709959246","bids":[["60495.50","0.33020000"],["60491.50","0.00000000"],["60474.38","0.01025000"],["60471.28","0.00000000"],["54488.80","0.00000000"]],"asks":[["60634.93","0.00000000"],["60635.03","0.01651454"]]},"channel":"diff_order_book_btcusd","event":"data"}
1618677710.137046: {"data":{"timestamp":"1618677710","microtimestamp":"1618677710082578","bids":[["764.06","0.00000000"]],"asks":[["765.74","0.00000000"]]},"channel":"diff_order_book_bchgbp","event":"data"}
1618677710.154181: {"data":{"timestamp":"1618677710","microtimestamp":"1618677710077861","bids":[],"asks":[["1729.20","1.01100000"]]},"channel":"diff_order_book_ethgbp","event":"data"}
1618677710.1938791: {"data":{"timestamp":"1618677710","microtimestamp":"1618677710118839","bids":[["2.82302","100.00000000"],["2.82244","0.00000000"]],"asks":[]},"channel":"diff_order_book_knceur","event":"data"}
1618677710.21616: {"data":{"timestamp":"1618677710","microtimestamp":"1618677710128863","bids":[["312.67","14.00000000"],["312.65","0.00000000"],["312.64","1.68896499"],["312.63","7.97440000"],["312.60","326.59970000"],["312.56","0.00000000"],["312.50","0.00000000"],["312.23","0.00000000"],["311.98","0.00000000"],["311.80","78.20000000"],["311.62","0.00000000"]],"asks":[["313.20","1.50000000"],["313.23","366.55260000"],["313.26","0.00000000"],["313.28","156.60860000"],["313.31","1.60000000"],["313.41","0.00000000"],["313.50","39.10000000"],["313.94","0.00000000"],["314.13","78.20000000"]]},"channel":"diff_order_book_ltcusd","event":"data"}
1618677710.286568: {"data":{"timestamp":"1618677710","microtimestamp":"1618677710208553","bids":[["0.00067798","0.00000000"]],"asks":[]},"channel":"diff_order_book_linkbtc","event":"data"}
1618677710.338633: {"data":{"timestamp":"1618677710","microtimestamp":"1618677710271078","bids":[],"asks":[["885.97","0.00000000"]]},"channel":"diff_order_book_bcheur","event":"data"}
1618677710.367809: {"data":{"timestamp":"1618677710","microtimestamp":"1618677710291784","bids":[["312.67","14.70000000"],["312.62","89.00000000"]],"asks":[["313.27","0.00000000"],["313.42","195.65000000"]]},"channel":"diff_order_book_ltcusd","event":"data"}
1618677710.37846: {"data":{"timestamp":"1618677710","microtimestamp":"1618677710316383","bids":[["1717.44","0.00000000"]],"asks":[]},"channel":"diff_order_book_ethgbp","event":"data"}
1618677710.408264: {"data":{"timestamp":"1618677710","microtimestamp":"1618677710331405","bids":[["0.00067827","15.88836126"]],"asks":[]},"channel":"diff_order_book_linkbtc","event":"data"}
1618677710.5042071: {"data":{"timestamp":"1618677710","microtimestamp":"1618677710428604","bids":[["881.67","1.00000000"],["881.66","6.90000000"],["881.59","0.00000000"]],"asks":[["883.73","2.80000000"],["883.83","3.00000000"],["883.86","37.25600136"],["883.87","0.00000000"],["884.06","0.00000000"],["885.96","0.00000000"],["888.03","8.38400000"]]},"channel":"diff_order_book_bcheur","event":"data"}
1618677710.5155149: {"data":{"timestamp":"1618677710","microtimestamp":"1618677710456741","bids":[["3.38159","0.00000000"]],"asks":[]},"channel":"diff_order_book_kncusd","event":"data"}
1618677710.531936: {"data":{"timestamp":"1618677710","microtimestamp":"1618677710456650","bids":[["312.67","14.00000000"],["312.63","11.97440000"],["312.62","85.00000000"],["312.61","0.00000000"],["312.30","0.00000000"]],"asks":[]},"channel":"diff_order_book_ltcusd","event":"data"}
1618677710.584403: {"data":{"timestamp":"1618677710","microtimestamp":"1618677710522444","bids":[["2.83888","0.00000000"],["2.83358","0.00000000"]],"asks":[]},"channel":"diff_order_book_knceur","event":"data"}
1618677710.629172: {"data":{"timestamp":"1618677710","microtimestamp":"1618677710573543","bids":[["3.38416","442.90968050"]],"asks":[]},"channel":"diff_order_book_kncusd","event":"data"}
1618677710.669614: {"data":{"timestamp":"1618677710","microtimestamp":"1618677710586320","bids":[["882.71","0.00000000"],["882.56","38.03315000"]],"asks":[["883.69","3.00000000"],["883.86","0.00000000"],["883.89","0.00000000"],["884.56","0.00000000"],["884.66","39.51137000"]]},"channel":"diff_order_book_bcheur","event":"data"}
1618677710.674609: {"data":{"timestamp":"1618677710","microtimestamp":"1618677710471299","bids":[["60505.23","0.04966182"],["60499.82","0.08250000"],["60474.38","0.00000000"],["59959.99","0.42200842"]],"asks":[["61550.12","0.49786831"]]},"channel":"diff_order_book_btcusd","event":"data"}
1618677710.7444968: {"data":{"timestamp":"1618677710","microtimestamp":"1618677710690603","bids":[["3.36123","3020.72562000"]],"asks":[["3.39252","1500.58755000"]]},"channel":"diff_order_book_kncusd","event":"data"}
1618677710.762058: {"data":{"timestamp":"1618677710","microtimestamp":"1618677710651835","bids":[["311.64","114.17858000"]],"asks":[["313.29","20.79103099"]]},"channel":"diff_order_book_ltcusd","event":"data"}
1618677710.8207538: {"data":{"timestamp":"1618677710","microtimestamp":"1618677710786347","bids":[["764.13","5.20000000"]],"asks":[["765.66","7.00000000"]]},"channel":"diff_order_book_bchgbp","event":"data"}
1618677710.844935: {"data":{"timestamp":"1618677710","microtimestamp":"1618677710768845","bids":[["882.56","35.33315000"]],"asks":[["884.32","31.32475000"],["884.66","0.00000000"],["885.87","4.70000000"],["888.03","0.00000000"]]},"channel":"diff_order_book_bcheur","event":"data"}
1618677710.914478: {"data":{"timestamp":"1618677710","microtimestamp":"1618677710810740","bids":[["311.65","114.17858000"],["311.64","0.00000000"]],"asks":[["313.49","21.13100000"]]},"channel":"diff_order_book_ltcusd","event":"data"}
1618677711.015543: {"data":{"timestamp":"1618677710","microtimestamp":"1618677710917787","bids":[["882.50","8.43897004"]],"asks":[["884.15","37.25600136"],["885.86","8.38400000"]]},"channel":"diff_order_book_bcheur","event":"data"}
1618677711.050425: {"data":{"timestamp":"1618677710","microtimestamp":"1618677710860251","bids":[["60505.23","0.00000000"],["60499.82","0.00000000"],["60496.52","0.08220000"],["60495.50","0.00000000"],["60494.82","0.00000000"],["60493.80","0.32990000"]],"asks":[["60566.58","0.04759883"],["60570.04","0.05894098"]]},"channel":"diff_order_book_btcusd","event":"data"}
1618677711.3161669: {"data":{"timestamp":"1618677711","microtimestamp":"1618677711280449","bids":[["3.38416","0.00000000"],["3.37652","0.00000000"]],"asks":[]},"channel":"diff_order_book_kncusd","event":"data"}
1618677711.321422: {"data":{"timestamp":"1618677711","microtimestamp":"1618677711285276","bids":[],"asks":[["0.00067953","24.23336595"]]},"channel":"diff_order_book_linkbtc","event":"data"}
1618677711.420248: {"data":{"timestamp":"1618677711","microtimestamp":"1618677711352188","bids":[["2.83859","443.08334921"],["2.83827","738.18280083"]],"asks":[]},"channel":"diff_order_book_knceur","event":"data"}
1618677711.4299982: {"data":{"timestamp":"1618677711","microtimestamp":"1618677711398566","bids":[["3.36124","780.00000000"]],"asks":[]},"channel":"diff_order_book_kncusd","event":"data"}
1618677711.4854789: {"data":{"timestamp":"1618677711","microtimestamp":"1618677711409849","bids":[["0.00067827","0.00000000"]],"asks":[["0.00067952","15.89194860"],["0.00067960","0.00000000"]]},"channel":"diff_order_book_linkbtc","event":"data"}
1618677711.527837: {"data":{"timestamp":"1618677711","microtimestamp":"1618677711367313","bids":[["60538.75","0.12388265"],["60526.62","0.00000000"],["60475.97","0.01025000"]],"asks":[["60635.03","0.00000000"]]},"channel":"diff_order_book_btcusd","event":"data"}
1618677711.562251: {"data":{"timestamp":"1618677711","microtimestamp":"1618677711532919","bids":[],"asks":[["766.12","2.80000000"]]},"channel":"diff_order_book_bchgbp","event":"data"}
1618677711.565279: {"data":{"timestamp":"1618677711","microtimestamp":"1618677711459103","bids":[],"asks":[["884.41","37.24743000"]]},"channel":"diff_order_book_bcheur","event":"data"}
1618677711.5848792: {"data":{"timestamp":"1618677711","microtimestamp":"1618677711511052","bids":[["312.63","10.37440000"],["312.58","142.17630000"],["312.46","35.88270534"],["311.65","0.00000000"]],"asks":[["313.26","1.60000000"],["313.31","0.00000000"]]},"channel":"diff_order_book_ltcusd","event":"data"}
1618677711.596121: {"data":{"timestamp":"1618677711","microtimestamp":"1618677711529860","bids":[["3.38280","0.00000000"]],"asks":[]},"channel":"diff_order_book_kncusd","event":"data"}
1618677711.599684: {"data":{"timestamp":"1618677711","microtimestamp":"1618677711531921","bids":[["0.00067818","15.89165710"]],"asks":[]},"channel":"diff_order_book_linkbtc","event":"data"}
1618677711.680258: {"data":{"timestamp":"1618677711","microtimestamp":"1618677711626949","bids":[["882.85","0.00000000"],["882.62","49.80741000"]],"asks":[["884.15","0.00000000"]]},"channel":"diff_order_book_bcheur","event":"data"}
1618677711.749867: {"data":{"timestamp":"1618677711","microtimestamp":"1618677711680976","bids":[["312.68","3.19502677"],["312.61","114.17858000"],["312.54","23.95598046"]],"asks":[["312.98","14.00000000"],["313.11","3.19493475"]]},"channel":"diff_order_book_ltcusd","event":"data"}
1618677711.841836: {"data":{"timestamp":"1618677711","microtimestamp":"1618677711774929","bids":[["759.11","0.15400000"],["759.10","1.95000000"]],"asks":[]},"channel":"diff_order_book_bchgbp","event":"data"}
1618677711.847002: {"data":{"timestamp":"1618677711","microtimestamp":"1618677711773778","bids":[["882.58","3.00000000"]],"asks":[["883.64","3.00000000"],["883.83","0.00000000"]]},"channel":"diff_order_book_bcheur","event":"data"}
1618677711.885195: {"data":{"timestamp":"1618677711","microtimestamp":"1618677711812559","bids":[["0.00067817","0.00000000"]],"asks":[]},"channel":"diff_order_book_linkbtc","event":"data"}
1618677711.929392: {"data":{"timestamp":"1618677711","microtimestamp":"1618677711850135","bids":[["312.68","0.00000000"],["312.67","0.00000000"],["312.64","0.00000000"],["312.63","6.37440000"],["312.61","0.00000000"],["312.58","140.57630000"],["312.52","3.08500000"]],"asks":[["313.11","0.00000000"],["313.18","151.85010000"],["313.19","4.83779813"],["313.20","3.10000000"],["313.26","0.00000000"],["313.28","1.51500000"],["313.32","21.13100000"],["313.40","39.10000000"],["313.49","0.00000000"],["313.50","0.00000000"]]},"channel":"diff_order_book_ltcusd","event":"data"}
1618677711.942262: {"data":{"timestamp":"1618677711","microtimestamp":"1618677711903968","bids":[["2.83514","0.00000000"]],"asks":[]},"channel":"diff_order_book_knceur","event":"data"}
1618677712.012495: {"data":{"timestamp":"1618677711","microtimestamp":"1618677711941458","bids":[["882.58","0.00000000"]],"asks":[["883.69","0.00000000"],["883.87","37.25600136"]]},"channel":"diff_order_book_bcheur","event":"data"}
1618677712.029622: {"data":{"timestamp":"1618677711","microtimestamp":"1618677711855621","bids":[["60521.36","0.00000000"],["60497.72","0.08230000"],["60496.52","0.00000000"],["60495.00","0.33000000"],["60493.80","0.00000000"],["60475.97","0.00000000"]],"asks":[["60553.64","0.49151000"],["60577.83","0.19961295"],["60588.91","0.32407396"],["60633.90","0.45019325"]]},"channel":"diff_order_book_btcusd","event":"data"}
1618677712.034587: {"data":{"timestamp":"1618677711","microtimestamp":"1618677711974535","bids":[],"asks":[["1724.67","0.00000000"]]},"channel":"diff_order_book_ethgbp","event":"data"}
1618677712.092757: {"data":{"timestamp":"1618677712","microtimestamp":"1618677712003429","bids":[["312.63","0.00000000"],["312.62","14.00000000"],["312.61","4.00000000"],["312.54","0.00000000"],["312.52","1.48500000"],["312.47","6.45230581"]],"asks":[["313.13","1.44000000"],["313.29","4.81272151"]]},"channel":"diff_order_book_ltcusd","event":"data"}
1618677712.106817: {"data":{"timestamp":"1618677712","microtimestamp":"1618677712046901","bids":[["2.82302","0.00000000"],["2.82244","100.00000000"]],"asks":[["2.85344","0.00000000"]]},"channel":"diff_order_book_knceur","event":"data"}
1618677712.181924: {"data":{"timestamp":"1618677712","microtimestamp":"1618677712106617","bids":[["882.58","3.00000000"],["882.57","6.37608619"],["882.50","5.63897004"]],"asks":[]},"channel":"diff_order_book_bcheur","event":"data"}
1618677712.259289: {"data":{"timestamp":"1618677712","microtimestamp":"1618677712172128","bids":[["312.55","71.00000000"],["312.47","120.63088581"]],"asks":[]},"channel":"diff_order_book_ltcusd","event":"data"}
1618677712.346447: {"data":{"timestamp":"1618677712","microtimestamp":"1618677712264578","bids":[["882.49","2.80000000"]],"asks":[]},"channel":"diff_order_book_bcheur","event":"data"}
1618677712.405115: {"data":{"timestamp":"1618677712","microtimestamp":"1618677712214767","bids":[["60536.32","0.00000000"],["60512.52","0.02000000"],["60502.66","0.00000000"],["60497.72","0.00000000"],["60495.00","0.00000000"],["60493.83","0.50000000"]],"asks":[["60572.90","0.16346465"],["60577.83","0.00000000"],["60583.98","0.35965575"],["60588.91","0.00000000"],["60598.99","0.50000000"],["60608.55","0.00000000"],["60628.97","0.37720287"],["60633.90","0.00000000"]]},"channel":"diff_order_book_btcusd","event":"data"}
1618677712.424205: {"data":{"timestamp":"1618677712","microtimestamp":"1618677712339527","bids":[["312.67","14.00000000"],["312.65","6.38300000"],["312.47","6.45230581"]],"asks":[]},"channel":"diff_order_book_ltcusd","event":"data"}
1618677712.496536: {"data":{"timestamp":"1618677712","microtimestamp":"1618677712416758","bids":[["3.38115","443.08334921"]],"asks":[]},"channel":"diff_order_book_kncusd","event":"data"}
1618677712.588276: {"data":{"timestamp":"1618677712","microtimestamp":"1618677712530688","bids":[["312.61","114.17858000"]],"asks":[]},"channel":"diff_order_book_ltcusd","event":"data"}
1618677712.616797: {"data":{"timestamp":"1618677712","microtimestamp":"1618677712542422","bids":[["0.00067818","0.00000000"]],"asks":[["0.00067929","15.89578389"],["0.00067952","0.00000000"],["0.00068037","0.00000000"]]},"channel":"diff_order_book_linkbtc","event":"data"}
1618677712.725621: {"data":{"timestamp":"1618677712","microtimestamp":"1618677712656314","bids":[["3.36124","0.00000000"]],"asks":[]},"channel":"diff_order_book_kncusd","event":"data"}
1618677712.7335339: {"data":{"timestamp":"1618677712","microtimestamp":"1618677712664488","bids":[["0.00067800","15.89588023"]],"asks":[["0.00067972","48.67407687"]]},"channel":"diff_order_book_linkbtc","event":"data"}
1618677712.775994: {"data":{"timestamp":"1618677712","microtimestamp":"1618677712699518","bids":[],"asks":[["883.90","2.37643995"],["884.04","0.00000000"]]},"channel":"diff_order_book_bcheur","event":"data"}
1618677712.841743: {"data":{"timestamp":"1618677712","microtimestamp":"1618677712778822","bids":[["3.37652","780.00000000"]],"asks":[]},"channel":"diff_order_book_kncusd","event":"data"}
1618677712.848515: {"data":{"timestamp":"1618677712","microtimestamp":"1618677712787298","bids":[],"asks":[["0.00067961","0.00000000"]]},"channel":"diff_order_book_linkbtc","event":"data"}
1618677712.8869429: {"data":{"timestamp":"1618677712","microtimestamp":"1618677712817583","bids":[["312.62","18.00000000"]],"asks":[]},"channel":"diff_order_book_ltcusd","event":"data"}
1618677712.940311: {"data":{"timestamp":"1618677712","microtimestamp":"1618677712858771","bids":[["882.58","0.00000000"],["882.57","2.37608619"]],"asks":[]},"channel":"diff_order_book_bcheur","event":"data"}
1618677712.9679759: {"data":{"timestamp":"1618677712","microtimestamp":"1618677712693751","bids":[["60471.48","0.00250000"]],"asks":[["60572.90","0.00000000"],["60583.98","0.00000000"],["60628.97","0.00000000"],["60810.17","0.49804664"]]},"channel":"diff_order_book_btcusd","event":"data"}
1618677713.029401: {"channel": "live_trades_btcusd", "data": {"amount": 0.11, "amount_str": "0.11000000", "buy_order_id": 1351035856179200, "id": 164507769, "microtimestamp": "1618677712983000", "price": 60553.64, "price_str": "60553.64", "sell_order_id": 1351035787067392, "timestamp": "1618677712", "type": 0}, "event": "trade"}
1618677713.055394: {"data":{"timestamp":"1618677712","microtimestamp":"1618677712982840","bids":[["312.62","14.00000000"],["312.60","330.59970000"]],"asks":[]},"channel":"diff_order_book_ltcusd","event":"data"}
1618677713.0685382: {"data":{"timestamp":"1618677713","microtimestamp":"1618677713017496","bids":[["3.37652","0.00000000"]],"asks":[]},"channel":"diff_order_book_kncusd","event":"data"}
1618677713.1044312: {"data":{"timestamp":"1618677713","microtimestamp":"1618677713038017","bids":[["882.57","6.37608619"],["881.56","0.00000000"]],"asks":[]},"channel":"diff_order_book_bcheur","event":"data"}
1618677713.182647: {"data":{"timestamp":"1618677713","microtimestamp":"1618677713138249","bids":[["3.36124","780.00000000"]],"asks":[]},"channel":"diff_order_book_kncusd","event":"data"}
1618677713.226584: {"data":{"timestamp":"1618677713","microtimestamp":"1618677713143526","bids":[["312.62","17.19554783"],["312.61","118.17858000"],["312.60","326.59970000"],["312.36","23.97156179"],["312.31","0.00000000"]],"asks":[["312.96","3.19620824"],["313.11","15.97882303"]]},"channel":"diff_order_book_ltcusd","event":"data"}
1618677713.336062: {"data":{"timestamp":"1618677713","microtimestamp":"1618677713159248","bids":[["60519.57","0.24776928"],["60495.92","0.08240000"],["60493.20","0.32990000"],["60472.88","0.16400000"],["60471.48","0.00000000"]],"asks":[["60553.64","0.38151000"],["60587.03","0.11346336"],["60600.16","0.00000000"],["60626.21","0.44963054"],["60810.17","0.00000000"],["60844.65","0.00000000"]]},"channel":"diff_order_book_btcusd","event":"data"}
1618677713.338433: {"data":{"timestamp":"1618677713","microtimestamp":"1618677713305844","bids":[],"asks":[["766.12","0.00000000"]]},"channel":"diff_order_book_bchgbp","event":"data"}
1618677713.4384441: {"data":{"timestamp":"1618677713","microtimestamp":"1618677713363078","bids":[["882.58","3.00000000"]],"asks":[]},"channel":"diff_order_book_bcheur","event":"data"}
1618677713.559385: {"data":{"timestamp":"1618677713","microtimestamp":"1618677713475111","bids":[["312.67","14.70000000"]],"asks":[]},"channel":"diff_order_book_ltcusd","event":"data"}
1618677713.604036: {"data":{"timestamp":"1618677713","microtimestamp":"1618677713527652","bids":[["882.58","0.00000000"]],"asks":[]},"channel":"diff_order_book_bcheur","event":"data"}
1618677713.698465: {"data":{"timestamp":"1618677713","microtimestamp":"1618677713628155","bids":[["0.00067817","24.11718583"]],"asks":[]},"channel":"diff_order_book_linkbtc","event":"data"}
1618677713.7334242: {"data":{"timestamp":"1618677713","microtimestamp":"1618677713640079","bids":[["312.67","14.00000000"],["312.61","114.17858000"],["312.59","4.00000000"]],"asks":[]},"channel":"diff_order_book_ltcusd","event":"data"}
1618677713.768675: {"data":{"timestamp":"1618677713","microtimestamp":"1618677713684009","bids":[["882.56","38.33315000"]],"asks":[]},"channel":"diff_order_book_bcheur","event":"data"}
1618677713.812924: {"data":{"timestamp":"1618677713","microtimestamp":"1618677713744136","bids":[["0.00067817","0.00000000"]],"asks":[]},"channel":"diff_order_book_linkbtc","event":"data"}
1618677713.824599: {"data":{"timestamp":"1618677713","microtimestamp":"1618677713635948","bids":[["60472.88","0.18214188"],["59959.99","0.01906129"]],"asks":[["60630.42","0.53583000"],["61550.12","0.00000000"]]},"channel":"diff_order_book_btcusd","event":"data"}
1618677713.848209: {"data":{"timestamp":"1618677713","microtimestamp":"1618677713794850","bids":[["312.59","0.00000000"],["312.42","1.46800000"]],"asks":[]},"channel":"diff_order_book_ltcusd","event":"data"}
1618677713.893089: {"data":{"timestamp":"1618677713","microtimestamp":"1618677713836762","bids":[["882.57","9.37608619"],["882.56","35.33315000"]],"asks":[]},"channel":"diff_order_book_bcheur","event":"data"}
1618677713.919039: {"data":{"timestamp":"1618677713","microtimestamp":"1618677713859002","bids":[["3.36124","0.00000000"],["3.36123","0.00000000"]],"asks":[["3.39252","0.00000000"]]},"channel":"diff_order_book_kncusd","event":"data"}
1618677713.9491708: {"data":{"timestamp":"1618677713","microtimestamp":"1618677713871621","bids":[["2.82302","100.00000000"],["2.82244","0.00000000"]],"asks":[]},"channel":"diff_order_book_knceur","event":"data"}
1618677714.0134761: {"data":{"timestamp":"1618677713","microtimestamp":"1618677713947434","bids":[["312.60","330.59970000"]],"asks":[]},"channel":"diff_order_book_ltcusd","event":"data"}
1618677714.034857: {"data":{"timestamp":"1618677713","microtimestamp":"1618677713977864","bids":[["3.37652","780.00000000"]],"asks":[]},"channel":"diff_order_book_kncusd","event":"data"}
1618677714.041547: {"data":{"timestamp":"1618677713","microtimestamp":"1618677713982254","bids":[],"asks":[["0.00067902","24.33629504"]]},"channel":"diff_order_book_linkbtc","event":"data"}
1618677714.050153: {"data":{"timestamp":"1618677713","microtimestamp":"1618677713986596","bids":[["882.57","2.37608619"]],"asks":[]},"channel":"diff_order_book_bcheur","event":"data"}
1618677714.188978: {"data":{"timestamp":"1618677714","microtimestamp":"1618677714115879","bids":[["312.61","118.17858000"],["312.60","326.59970000"]],"asks":[["312.96","0.00000000"]]},"channel":"diff_order_book_ltcusd","event":"data"}
1618677714.214723: {"data":{"timestamp":"1618677714","microtimestamp":"1618677714154658","bids":[["882.58","3.00000000"]],"asks":[]},"channel":"diff_order_book_bcheur","event":"data"}
1618677714.3566751: {"data":{"timestamp":"1618677714","microtimestamp":"1618677714283123","bids":[["312.62","21.19554783"],["312.61","114.17858000"]],"asks":[]},"channel":"diff_order_book_ltcusd","event":"data"}
1618677714.432975: {"data":{"timestamp":"1618677714","microtimestamp":"1618677714097622","bids":[],"asks":[["60572.81","0.16796669"],["60626.21","0.00000000"],["60630.42","0.00000000"],["60634.03","0.25587650"],["60811.37","0.46384709"]]},"channel":"diff_order_book_btcusd","event":"data"}
1618677714.521206: {"data":{"timestamp":"1618677714","microtimestamp":"1618677714443052","bids":[["882.57","6.37608619"]],"asks":[]},"channel":"diff_order_book_bcheur","event":"data"}
1618677714.624668: {"data":{"timestamp":"1618677714","microtimestamp":"1618677714564221","bids":[["2.84086","442.93908534"],["2.83859","0.00000000"]],"asks":[]},"channel":"diff_order_book_knceur","event":"data"}
1618677714.685431: {"data":{"timestamp":"1618677714","microtimestamp":"1618677714594987","bids":[["882.58","0.00000000"],["882.57","9.37608619"]],"asks":[]},"channel":"diff_order_book_bcheur","event":"data"}
1618677714.857534: {"data":{"timestamp":"1618677714","microtimestamp":"1618677714675293","bids":[["60472.88","0.13403342"]],"asks":[["60630.52","0.49333000"],["60634.03","0.00000000"]]},"channel":"diff_order_book_btcusd","event":"data"}
1618677714.90445: {"data":{"timestamp":"1618677714","microtimestamp":"1618677714818411","bids":[],"asks":[["313.13","0.00000000"]]},"channel":"diff_order_book_ltcusd","event":"data"}
1618677714.990324: {"data":{"timestamp":"1618677714","microtimestamp":"1618677714953147","bids":[],"asks":[["766.29","2.70000000"]]},"channel":"diff_order_book_bchgbp","event":"data"}
1618677715.0116758: {"data":{"timestamp":"1618677714","microtimestamp":"1618677714955844","bids":[["1717.77","0.05000000"]],"asks":[]},"channel":"diff_order_book_ethgbp","event":"data"}
1618677715.144089: {"data":{"timestamp":"1618677715","microtimestamp":"1618677715089152","bids":[["882.85","48.58985000"],["882.62","0.00000000"],["882.58","3.00000000"],["882.57","6.37608619"]],"asks":[["883.64","0.00000000"],["883.72","37.25600136"],["883.87","0.00000000"],["883.88","0.00000000"],["884.15","2.20000000"],["884.32","0.00000000"],["884.56","30.61675000"]]},"channel":"diff_order_book_bcheur","event":"data"}
1618677715.234354: {"data":{"timestamp":"1618677715","microtimestamp":"1618677715145931","bids":[],"asks":[["313.01","3.19596273"]]},"channel":"diff_order_book_ltcusd","event":"data"}
1618677715.24016: {"data":{"timestamp":"1618677715","microtimestamp":"1618677715193305","bids":[],"asks":[["1722.61","0.00000000"]]},"channel":"diff_order_book_ethgbp","event":"data"}
1618677715.308655: {"data":{"timestamp":"1618677715","microtimestamp":"1618677715240949","bids":[["882.80","7.00000000"],["882.79","32.09663000"],["882.68","2.80000000"],["882.58","0.00000000"],["882.57","2.37608619"],["882.56","0.00000000"],["882.49","0.00000000"]],"asks":[["883.72","2.80000000"],["883.73","0.00000000"],["883.90","0.00000000"],["884.04","2.37604942"],["884.15","42.35600136"],["884.41","0.00000000"],["884.71","38.72745000"]]},"channel":"diff_order_book_bcheur","event":"data"}
1618677715.3538601: {"data":{"timestamp":"1618677715","microtimestamp":"1618677715308508","bids":[],"asks":[["1724.08","0.22100000"]]},"channel":"diff_order_book_ethgbp","event":"data"}
1618677715.49718: {"data":{"timestamp":"1618677715","microtimestamp":"1618677715403779","bids":[["882.80","0.00000000"],["882.68","0.00000000"]],"asks":[["884.13","37.25600136"],["884.15","0.00000000"]]},"channel":"diff_order_book_bcheur","event":"data"}
1618677715.497397: {"data":{"timestamp":"1618677715","microtimestamp":"1618677715286908","bids":[["60512.15","0.04958177"],["60472.88","0.14678342"]],"asks":[["60572.14","0.17147578"],["60572.81","0.00000000"],["60630.52","0.00000000"],["60634.03","0.38587650"],["60810.70","0.40910809"],["60811.37","0.00000000"]]},"channel":"diff_order_book_btcusd","event":"data"}
1618677715.582515: {"data":{"timestamp":"1618677715","microtimestamp":"1618677715547933","bids":[],"asks":[["1724.93","0.00000000"],["1729.19","0.50600000"],["1729.20","0.00000000"],["1732.08","1.01100000"]]},"channel":"diff_order_book_ethgbp","event":"data"}
1618677715.6378932: {"data":{"timestamp":"1618677715","microtimestamp":"1618677715560395","bids":[],"asks":[["883.68","3.00000000"],["883.72","0.00000000"],["884.11","37.25600136"],["884.13","0.00000000"]]},"channel":"diff_order_book_bcheur","event":"data"}
1618677715.6646762: {"data":{"timestamp":"1618677715","microtimestamp":"1618677715603461","bids":[["312.62","18.00000000"]],"asks":[["313.01","0.00000000"]]},"channel":"diff_order_book_ltcusd","event":"data"}
1618677715.746996: {"data":{"timestamp":"1618677715","microtimestamp":"1618677715668538","bids":[],"asks":[["1721.24","0.00000000"],["1729.19","0.00000000"]]},"channel":"diff_order_book_ethgbp","event":"data"}
1618677715.815964: {"data":{"timestamp":"1618677715","microtimestamp":"1618677715738802","bids":[],"asks":[["883.68","5.80000000"],["884.04","0.00000000"],["884.11","0.00000000"],["884.13","37.25600136"]]},"channel":"diff_order_book_bcheur","event":"data"}
1618677715.833389: {"data":{"timestamp":"1618677715","microtimestamp":"1618677715766739","bids":[["312.67","14.70000000"]],"asks":[]},"channel":"diff_order_book_ltcusd","event":"data"}
1618677715.852514: {"data":{"timestamp":"1618677715","microtimestamp":"1618677715666320","bids":[["60495.92","0.00000000"],["60494.03","0.08220000"],["60493.20","0.00000000"],["60491.30","0.32980000"],["60472.98","0.01275000"],["60472.88","0.00000000"]],"asks":[["60572.14","0.00000000"],["60582.97","0.39772562"],["60627.72","0.46770239"],["60634.03","0.00000000"],["60810.70","0.00000000"]]},"channel":"diff_order_book_btcusd","event":"data"}
1618677715.861156: {"data":{"timestamp":"1618677715","microtimestamp":"1618677715788525","bids":[],"asks":[["1729.20","0.50600000"]]},"channel":"diff_order_book_ethgbp","event":"data"}
1618677715.9756742: {"data":{"timestamp":"1618677715","microtimestamp":"1618677715909640","bids":[],"asks":[["1722.33","1.26860741"]]},"channel":"diff_order_book_ethgbp","event":"data"}
1618677715.98464: {"data":{"timestamp":"1618677715","microtimestamp":"1618677715909694","bids":[["0.00067800","0.00000000"]],"asks":[]},"channel":"diff_order_book_linkbtc","event":"data"}
1618677715.9850361: {"data":{"timestamp":"1618677715","microtimestamp":"1618677715909018","bids":[],"asks":[["884.13","2.20000000"]]},"channel":"diff_order_book_bcheur","event":"data"}
1618677715.996702: {"data":{"timestamp":"1618677715","microtimestamp":"1618677715930352","bids":[["312.67","14.00000000"]],"asks":[]},"channel":"diff_order_book_ltcusd","event":"data"}
1618677716.096009: {"data":{"timestamp":"1618677716","microtimestamp":"1618677716038270","bids":[["0.00067798","15.89814482"]],"asks":[]},"channel":"diff_order_book_linkbtc","event":"data"}
1618677716.1508532: {"data":{"timestamp":"1618677716","microtimestamp":"1618677716061576","bids":[["882.65","2.80000000"]],"asks":[["884.13","0.00000000"],["884.15","2.20000000"]]},"channel":"diff_order_book_bcheur","event":"data"}
1618677716.2072499: {"data":{"timestamp":"1618677716","microtimestamp":"1618677716156524","bids":[["1716.74","0.10600000"],["1716.36","0.00000000"]],"asks":[]},"channel":"diff_order_book_ethgbp","event":"data"}
1618677716.330698: {"data":{"timestamp":"1618677716","microtimestamp":"1618677716144145","bids":[["60534.14","0.00000000"],["60520.98","0.28608297"],["60472.98","0.00250000"]],"asks":[["60571.28","0.15770240"],["60582.97","0.00000000"],["60627.72","0.00000000"],["60630.52","0.36833000"],["60811.60","0.39863341"]]},"channel":"diff_order_book_btcusd","event":"data"}
1618677716.431079: {"data":{"timestamp":"1618677716","microtimestamp":"1618677716356016","bids":[],"asks":[["884.14","37.25600136"]]},"channel":"diff_order_book_bcheur","event":"data"}
1618677716.4851708: {"data":{"timestamp":"1618677716","microtimestamp":"1618677716407613","bids":[["1717.77","0.00000000"]],"asks":[]},"channel":"diff_order_book_ethgbp","event":"data"}
1618677716.6012218: {"data":{"timestamp":"1618677716","microtimestamp":"1618677716532244","bids":[["1716.74","0.00000000"]],"asks":[["1724.93","0.50600000"],["1729.20","0.00000000"],["1732.08","0.00000000"]]},"channel":"diff_order_book_ethgbp","event":"data"}
1618677716.605559: {"data":{"timestamp":"1618677716","microtimestamp":"1618677716513746","bids":[["882.79","0.00000000"],["882.53","34.28474000"]],"asks":[["884.14","0.00000000"],["884.15","0.00000000"],["884.31","30.44507000"],["884.45","37.58472000"],["884.56","0.00000000"],["884.71","0.00000000"]]},"channel":"diff_order_book_bcheur","event":"data"}
1618677716.658643: {"data":{"timestamp":"1618677716","microtimestamp":"1618677716595119","bids":[],"asks":[["313.41","5.40890511"]]},"channel":"diff_order_book_ltcusd","event":"data"}
1618677716.7137222: {"data":{"timestamp":"1618677716","microtimestamp":"1618677716657828","bids":[["1716.36","0.10600000"]],"asks":[["1724.93","0.00000000"],["1729.20","1.01100000"]]},"channel":"diff_order_book_ethgbp","event":"data"}
1618677716.7675478: {"data":{"timestamp":"1618677716","microtimestamp":"1618677716670035","bids":[],"asks":[["883.91","2.37637278"],["884.15","37.25600136"]]},"channel":"diff_order_book_bcheur","event":"data"}
1618677716.826276: {"data":{"timestamp":"1618677716","microtimestamp":"1618677716777086","bids":[],"asks":[["1729.19","0.50600000"]]},"channel":"diff_order_book_ethgbp","event":"data"}
1618677716.8838558: {"data":{"timestamp":"1618677716","microtimestamp":"1618677716825070","bids":[],"asks":[["884.15","39.45600136"]]},"channel":"diff_order_book_bcheur","event":"data"}
1618677716.938487: {"data":{"timestamp":"1618677716","microtimestamp":"1618677716536869","bids":[["60512.15","0.00000000"],["60472.98","0.00000000"],["59951.00","0.40394713"]],"asks":[["60571.28","0.00000000"],["60585.06","0.31066323"],["60628.90","0.38609300"],["60630.52","0.22000000"],["60811.60","0.00000000"],["61539.58","0.49786831"]]},"channel":"diff_order_book_btcusd","event":"data"}
1618677716.9412742: {"data":{"timestamp":"1618677716","microtimestamp":"1618677716892588","bids":[],"asks":[["1729.20","0.00000000"]]},"channel":"diff_order_book_ethgbp","event":"data"}
1618677717.049716: {"data":{"timestamp":"1618677716","microtimestamp":"1618677716971777","bids":[],"asks":[["884.15","0.00000000"]]},"channel":"diff_order_book_bcheur","event":"data"}
1618677717.051496: {"data":{"timestamp":"1618677717","microtimestamp":"1618677717003160","bids":[["3.37652","3567.89841000"]],"asks":[["3.39252","1411.25094000"]]},"channel":"diff_order_book_kncusd","event":"data"}
1618677717.05709: {"data":{"timestamp":"1618677717","microtimestamp":"1618677717011972","bids":[],"asks":[["1732.08","1.01100000"]]},"channel":"diff_order_book_ethgbp","event":"data"}
1618677717.067724: {"data":{"timestamp":"1618677717","microtimestamp":"1618677717022221","bids":[["0.00067798","0.00000000"]],"asks":[]},"channel":"diff_order_book_linkbtc","event":"data"}
1618677717.1713762: {"data":{"timestamp":"1618677717","microtimestamp":"1618677717130771","bids":[],"asks":[["1729.19","0.00000000"],["1729.20","0.50600000"]]},"channel":"diff_order_book_ethgbp","event":"data"}
1618677717.207935: {"data":{"timestamp":"1618677717","microtimestamp":"1618677717102571","bids":[["312.67","17.19542394"]],"asks":[["313.06","3.19542394"]]},"channel":"diff_order_book_ltcusd","event":"data"}
1618677717.2159848: {"data":{"timestamp":"1618677717","microtimestamp":"1618677717132452","bids":[],"asks":[["884.14","2.20000000"]]},"channel":"diff_order_book_bcheur","event":"data"}
1618677717.23349: {"data":{"timestamp":"1618677717","microtimestamp":"1618677717150000","bids":[["0.00067800","15.89596897"]],"asks":[]},"channel":"diff_order_book_linkbtc","event":"data"}
1618677717.307532: {"data":{"timestamp":"1618677717","microtimestamp":"1618677717129882","bids":[["60511.86","0.33035339"],["60474.57","0.00000000"],["60471.18","0.05000000"]],"asks":[["60572.71","0.14656173"],["60585.06","0.00000000"],["60628.78","0.47195974"],["60628.90","0.00000000"],["60630.52","0.00000000"],["60634.23","0.02000000"]]},"channel":"diff_order_book_btcusd","event":"data"}
1618677717.3468668: {"data":{"timestamp":"1618677717","microtimestamp":"1618677717275370","bids":[["0.00067826","0.00000000"],["0.00067766","24.33784830"]],"asks":[]},"channel":"diff_order_book_linkbtc","event":"data"}
1618677717.380379: {"data":{"timestamp":"1618677717","microtimestamp":"1618677717286957","bids":[],"asks":[["884.14","0.00000000"],["884.15","39.45600136"]]},"channel":"diff_order_book_bcheur","event":"data"}
1618677717.461372: {"data":{"timestamp":"1618677717","microtimestamp":"1618677717395388","bids":[["0.00067766","0.00000000"]],"asks":[]},"channel":"diff_order_book_linkbtc","event":"data"}
1618677717.548621: {"data":{"timestamp":"1618677717","microtimestamp":"1618677717454383","bids":[],"asks":[["884.14","37.25600136"],["884.15","0.00000000"]]},"channel":"diff_order_book_bcheur","event":"data"}
1618677717.671299: {"data":{"timestamp":"1618677717","microtimestamp":"1618677717608819","bids":[["882.53","0.00000000"]],"asks":[["884.14","0.00000000"],["884.15","2.20000000"],["884.31","0.00000000"]]},"channel":"diff_order_book_bcheur","event":"data"}
1618677717.781276: {"data":{"timestamp":"1618677717","microtimestamp":"1618677717715465","bids":[["764.41","0.00000000"]],"asks":[]},"channel":"diff_order_book_bchgbp","event":"data"}
1618677717.8432121: {"data":{"timestamp":"1618677717","microtimestamp":"1618677717761635","bids":[["882.87","0.00000000"],["882.85","0.00000000"],["882.65","0.00000000"],["882.50","0.00000000"],["882.44","0.00000000"],["882.43","50.72101000"],["881.67","0.00000000"]],"asks":[["884.05","39.45600136"],["884.06","30.38837000"],["884.15","0.00000000"],["884.20","40.09375000"],["884.45","0.00000000"]]},"channel":"diff_order_book_bcheur","event":"data"}
1618677717.843521: {"data":{"timestamp":"1618677717","microtimestamp":"1618677717625548","bids":[["60512.14","0.05009737"],["60471.18","0.00000000"]],"asks":[]},"channel":"diff_order_book_btcusd","event":"data"}
1618677717.893142: {"data":{"timestamp":"1618677717","microtimestamp":"1618677717831910","bids":[["764.45","0.00000000"]],"asks":[["766.26","0.00000000"]]},"channel":"diff_order_book_bchgbp","event":"data"}
1618677718.000845: {"data":{"timestamp":"1618677717","microtimestamp":"1618677717909363","bids":[["882.57","0.00000000"],["882.43","0.00000000"],["882.09","0.00000000"],["881.67","5.43065540"],["846.34","0.00000000"],["845.01","4.03975732"]],"asks":[["883.67","2.90000000"],["883.75","2.37682104"],["883.91","0.00000000"],["884.05","0.00000000"],["884.06","0.00000000"],["884.15","5.60109808"],["884.18","2.37668601"],["884.20","0.00000000"],["884.40","0.00000000"],["885.18","0.00000000"]]},"channel":"diff_order_book_bcheur","event":"data"}
1618677718.015409: {"data":{"timestamp":"1618677717","microtimestamp":"1618677717951222","bids":[["764.40","0.00000000"],["764.27","0.00000000"],["764.25","1.42642920"],["759.12","5.20807076"]],"asks":[["765.66","9.85269295"],["765.93","0.00000000"]]},"channel":"diff_order_book_bchgbp","event":"data"}
1618677718.120873: {"data":{"timestamp":"1618677718","microtimestamp":"1618677718073134","bids":[["763.67","2.85269295"]],"asks":[]},"channel":"diff_order_book_bchgbp","event":"data"}
1618677718.204546: {"data":{"timestamp":"1618677718","microtimestamp":"1618677718109552","bids":[],"asks":[["313.06","0.00000000"]]},"channel":"diff_order_book_ltcusd","event":"data"}
1618677718.2046459: {"data":{"timestamp":"1618677718","microtimestamp":"1618677718023504","bids":[["60543.12","0.00000000"],["60000.00","30.81088625"]],"asks":[["60572.02","0.17460866"],["60572.71","0.00000000"],["60627.47","0.40348575"],["60628.78","0.00000000"],["60634.23","0.01895090"]]},"channel":"diff_order_book_btcusd","event":"data"}
1618677718.3107011: {"data":{"timestamp":"1618677718","microtimestamp":"1618677718086154","bids":[["882.26","2.80000000"],["881.69","3.00000000"],["881.68","4.73303275"]],"asks":[["883.62","37.25600136"],["883.63","3.00000000"],["883.67","5.10000000"],["883.75","0.00000000"],["884.48","0.00000000"]]},"channel":"diff_order_book_bcheur","event":"data"}
1618677718.351796: {"data":{"timestamp":"1618677718","microtimestamp":"1618677718315841","bids":[["759.10","0.40000000"],["753.16","6.03300000"]],"asks":[]},"channel":"diff_order_book_bchgbp","event":"data"}
1618677718.4250681: {"data":{"timestamp":"1618677718","microtimestamp":"1618677718363237","bids":[["882.26","0.00000000"],["881.82","3.00000000"],["881.78","2.80000000"],["881.69","0.00000000"],["881.68","3.73303275"],["881.66","0.00000000"],["881.33","1.00000000"],["875.83","0.40000000"]],"asks":[["883.57","37.25600136"],["883.58","3.00000000"],["883.62","2.90000000"],["883.63","0.00000000"],["883.67","0.00000000"],["883.68","2.80000000"]]},"channel":"diff_order_book_bcheur","event":"data"}
1618677718.46573: {"data":{"timestamp":"1618677718","microtimestamp":"1618677718263694","bids":[],"asks":[["313.02","3.19572902"],["313.32","0.00000000"]]},"channel":"diff_order_book_ltcusd","event":"data"}
1618677718.514648: {"data":{"timestamp":"1618677718","microtimestamp":"1618677718444379","bids":[],"asks":[["765.86","2.80000000"],["766.29","0.00000000"]]},"channel":"diff_order_book_bchgbp","event":"data"}
1618677718.578151: {"data":{"timestamp":"1618677718","microtimestamp":"1618677718528382","bids":[["312.42","0.00000000"]],"asks":[["313.22","58.74609764"]]},"channel":"diff_order_book_ltcusd","event":"data"}
1618677718.58529: {"data":{"timestamp":"1618677718","microtimestamp":"1618677718530904","bids":[["881.79","3.00000000"],["881.69","4.00000000"],["881.68","0.73303275"],["881.27","5.50000000"]],"asks":[["883.57","0.00000000"],["883.62","0.00000000"],["884.14","2.20000000"]]},"channel":"diff_order_book_bcheur","event":"data"}
1618677718.626077: {"data":{"timestamp":"1618677718","microtimestamp":"1618677718558031","bids":[["759.12","0.00000000"]],"asks":[["765.63","5.35754573"],["765.64","2.03339655"]]},"channel":"diff_order_book_bchgbp","event":"data"}
1618677718.7405472: {"data":{"timestamp":"1618677718","microtimestamp":"1618677718673368","bids":[["763.78","7.10000000"]],"asks":[]},"channel":"diff_order_book_bchgbp","event":"data"}
1618677718.752558: {"data":{"timestamp":"1618677718","microtimestamp":"1618677718685732","bids":[["882.36","49.60187000"],["882.22","33.34798000"],["881.79","0.00000000"],["881.69","0.00000000"]],"asks":[["884.00","31.98424000"],["884.12","37.25600136"],["884.14","38.26491000"]]},"channel":"diff_order_book_bcheur","event":"data"}
1618677718.794919: {"data":{"timestamp":"1618677718","microtimestamp":"1618677718577375","bids":[],"asks":[["60572.02","0.00000000"],["60627.47","0.00000000"],["60634.23","0.00000000"],["60635.93","0.01833000"]]},"channel":"diff_order_book_btcusd","event":"data"}
1618677718.856611: {"data":{"timestamp":"1618677718","microtimestamp":"1618677718795097","bids":[],"asks":[["765.62","0.60794000"],["765.64","0.00000000"],["766.06","0.00000000"]]},"channel":"diff_order_book_bchgbp","event":"data"}
1618677718.8697548: {"data":{"timestamp":"1618677718","microtimestamp":"1618677718839195","bids":[["1.37001","198.00000"]],"asks":[]},"channel":"diff_order_book_gbpusd","event":"data"}
1618677718.910383: {"data":{"timestamp":"1618677718","microtimestamp":"1618677718841403","bids":[["312.62","14.00000000"],["312.60","330.59970000"]],"asks":[]},"channel":"diff_order_book_ltcusd","event":"data"}
1618677718.916939: {"data":{"timestamp":"1618677718","microtimestamp":"1618677718835582","bids":[["881.79","3.00000000"],["881.68","4.73303275"]],"asks":[["883.67","2.90000000"],["883.97","2.20000000"],["884.12","0.00000000"]]},"channel":"diff_order_book_bcheur","event":"data"}
1618677718.984551: {"data":{"timestamp":"1618677718","microtimestamp":"1618677718954479","bids":[["1.37101","67.00000"]],"asks":[]},"channel":"diff_order_book_gbpusd","event":"data"}
1618677719.005014: {"data":{"timestamp":"1618677718","microtimestamp":"1618677718941066","bids":[["0.00067805","24.33784830"]],"asks":[]},"channel":"diff_order_book_linkbtc","event":"data"}
1618677719.073108: {"data":{"timestamp":"1618677718","microtimestamp":"1618677718997039","bids":[["312.62","18.00000000"],["312.60","326.59970000"],["312.44","1.46800000"]],"asks":[]},"channel":"diff_order_book_ltcusd","event":"data"}
1618677719.084613: {"data":{"timestamp":"1618677718","microtimestamp":"1618677718980056","bids":[["882.20","2.80000000"],["881.78","0.00000000"]],"asks":[["883.67","0.00000000"],["883.97","0.00000000"]]},"channel":"diff_order_book_bcheur","event":"data"}
1618677719.197561: {"data":{"timestamp":"1618677719","microtimestamp":"1618677719152567","bids":[],"asks":[["765.66","2.85269295"]]},"channel":"diff_order_book_bchgbp","event":"data"}
1618677719.207032: {"data":{"timestamp":"1618677719","microtimestamp":"1618677719148065","bids":[["882.40","3.00000000"],["881.27","0.00000000"]],"asks":[["883.65","2.90000000"],["883.97","37.25600136"]]},"channel":"diff_order_book_bcheur","event":"data"}
1618677719.311569: {"data":{"timestamp":"1618677719","microtimestamp":"1618677719268683","bids":[["764.16","5.08189389"],["753.16","4.48300000"]],"asks":[["765.86","0.00000000"]]},"channel":"diff_order_book_bchgbp","event":"data"}
1618677719.340369: {"data":{"timestamp":"1618677719","microtimestamp":"1618677719288505","bids":[["1717.62","0.05000000"]],"asks":[]},"channel":"diff_order_book_ethgbp","event":"data"}
1618677719.3468459: {"data":{"timestamp":"1618677719","microtimestamp":"1618677719300639","bids":[["0.00067800","0.00000000"]],"asks":[["0.00067953","0.00000000"]]},"channel":"diff_order_book_linkbtc","event":"data"}
1618677719.377234: {"data":{"timestamp":"1618677719","microtimestamp":"1618677719307998","bids":[],"asks":[["883.65","0.00000000"],["883.97","0.00000000"],["883.99","37.25600136"],["885.87","0.00000000"]]},"channel":"diff_order_book_bcheur","event":"data"}
1618677719.4095502: {"data":{"timestamp":"1618677719","microtimestamp":"1618677719316426","bids":[],"asks":[["312.98","0.00000000"],["312.99","0.00000000"]]},"channel":"diff_order_book_ltcusd","event":"data"}
1618677719.427813: {"data":{"timestamp":"1618677719","microtimestamp":"1618677719389852","bids":[["759.11","1.70400000"]],"asks":[["766.10","4.40000000"]]},"channel":"diff_order_book_bchgbp","event":"data"}
1618677719.461941: {"data":{"timestamp":"1618677719","microtimestamp":"1618677719425296","bids":[["0.00067806","15.89496459"]],"asks":[["0.00067929","0.00000000"]]},"channel":"diff_order_book_linkbtc","event":"data"}
1618677719.465608: {"data":{"timestamp":"1618677719","microtimestamp":"1618677719247572","bids":[["60543.66","0.04824232"],["60512.14","0.00000000"],["60451.26","0.00000000"]],"asks":[["60586.06","0.31685924"],["60631.05","0.41475843"],["60634.43","0.55000000"],["60635.93","0.00000000"]]},"channel":"diff_order_book_btcusd","event":"data"}
1618677719.5415838: {"data":{"timestamp":"1618677719","microtimestamp":"1618677719511270","bids":[],"asks":[["765.31","1.42602673"]]},"channel":"diff_order_book_bchgbp","event":"data"}
1618677719.542217: {"data":{"timestamp":"1618677719","microtimestamp":"1618677719476749","bids":[["881.83","2.37724413"]],"asks":[["883.80","2.37682890"],["883.99","0.00000000"],["884.61","2.37730375"],["886.38","7.30000000"]]},"channel":"diff_order_book_bcheur","event":"data"}
1618677719.576542: {"data":{"timestamp":"1618677719","microtimestamp":"1618677719500888","bids":[["312.62","14.00000000"],["309.68","78.14216716"]],"asks":[["312.99","6.38840000"]]},"channel":"diff_order_book_ltcusd","event":"data"}
1618677719.625658: {"data":{"timestamp":"1618677719","microtimestamp":"1618677719552876","bids":[],"asks":[["0.00067971","15.89289972"]]},"channel":"diff_order_book_linkbtc","event":"data"}
1618677719.7414122: {"data":{"timestamp":"1618677719","microtimestamp":"1618677719666576","bids":[["312.61","118.17858000"],["309.68","0.00000000"]],"asks":[]},"channel":"diff_order_book_ltcusd","event":"data"}
1618677719.758996: {"data":{"timestamp":"1618677719","microtimestamp":"1618677719668839","bids":[["882.36","52.60187000"],["881.79","0.00000000"],["881.68","0.73303275"]],"asks":[["883.99","2.20000000"],["888.07","0.00000000"]]},"channel":"diff_order_book_bcheur","event":"data"}
1618677719.837722: {"data":{"timestamp":"1618677719","microtimestamp":"1618677719675915","bids":[["60470.58","0.01025000"],["59951.00","0.00100000"]],"asks":[["60578.33","0.00000000"],["60581.97","0.00000000"],["60586.06","0.00000000"],["60590.00","0.47018951"],["60606.97","0.49604633"],["60631.05","0.00000000"]]},"channel":"diff_order_book_btcusd","event":"data"}
1618677719.907001: {"data":{"timestamp":"1618677719","microtimestamp":"1618677719824507","bids":[["312.61","114.17858000"],["312.47","4.85230581"]],"asks":[]},"channel":"diff_order_book_ltcusd","event":"data"}
1618677719.924234: {"data":{"timestamp":"1618677719","microtimestamp":"1618677719829453","bids":[["882.36","49.60187000"]],"asks":[["883.80","0.00000000"],["883.99","0.00000000"],["884.18","0.00000000"],["886.37","20.46300000"]]},"channel":"diff_order_book_bcheur","event":"data"}
1618677720.072404: {"data":{"timestamp":"1618677719","microtimestamp":"1618677719999132","bids":[["312.62","18.00000000"],["312.54","1.60000000"]],"asks":[["313.02","0.00000000"],["313.07","3.19511685"],["313.18","0.00000000"],["313.19","0.00000000"],["313.20","1.50000000"],["313.26","1.60000000"]]},"channel":"diff_order_book_ltcusd","event":"data"}
1618677720.072892: {"data":{"timestamp":"1618677720","microtimestamp":"1618677720007880","bids":[["3.37652","780.00000000"]],"asks":[["3.39252","0.00000000"]]},"channel":"diff_order_book_kncusd","event":"data"}
1618677720.088788: {"data":{"timestamp":"1618677720","microtimestamp":"1618677720007747","bids":[],"asks":[["883.95","2.20000000"],["883.98","37.25600136"]]},"channel":"diff_order_book_bcheur","event":"data"}
1618677720.088941: {"data":{"timestamp":"1618677720","microtimestamp":"1618677720033560","bids":[["0.00067782","0.00000000"]],"asks":[]},"channel":"diff_order_book_linkbtc","event":"data"}
1618677720.104586: {"channel": "live_trades_btcusd", "data": {"amount": 0.19544126, "amount_str": "0.19544126", "buy_order_id": 1351035885146116, "id": 164507776, "microtimestamp": "1618677720055000", "price": 60553.64, "price_str": "60553.64", "sell_order_id": 1351035787067392, "timestamp": "1618677720", "type": 0}, "event": "trade"}
1618677720.254132: {"data":{"timestamp":"1618677720","microtimestamp":"1618677720175678","bids":[["875.83","0.00000000"]],"asks":[["883.95","0.00000000"],["883.96","2.20000000"],["883.98","0.00000000"]]},"channel":"diff_order_book_bcheur","event":"data"}
1618677720.308973: {"data":{"timestamp":"1618677720","microtimestamp":"1618677720145519","bids":[["60470.58","0.00000000"]],"asks":[["60573.80","0.18659905"],["60584.81","0.41530437"],["60606.97","0.00000000"],["60634.43","0.00000000"]]},"channel":"diff_order_book_btcusd","event":"data"}
1618677720.419017: {"data":{"timestamp":"1618677720","microtimestamp":"1618677720354327","bids":[["882.37","4.00000000"],["882.20","0.00000000"]],"asks":[["883.96","0.00000000"],["883.98","37.25600136"],["883.99","2.20000000"],["886.37","0.00000000"],["888.03","20.46300000"]]},"channel":"diff_order_book_bcheur","event":"data"}
1618677720.431777: {"data":{"timestamp":"1618677720","microtimestamp":"1618677720395044","bids":[],"asks":[["0.00067955","23.97503235"]]},"channel":"diff_order_book_linkbtc","event":"data"}
1618677720.441045: {"channel": "live_trades_bcheur", "data": {"amount": 0.244214, "amount_str": "0.24421400", "buy_order_id": 1351035880955905, "id": 164507780, "microtimestamp": "1618677720359000", "price": 882.4, "price_str": "882.40", "sell_order_id": 1351035886395393, "timestamp": "1618677720", "type": 1}, "event": "trade"}
1618677720.590097: {"data":{"timestamp":"1618677720","microtimestamp":"1618677720513876","bids":[["882.40","2.75578600"],["882.37","0.00000000"],["882.26","2.80000000"]],"asks":[["883.97","2.20000000"],["883.98","0.00000000"],["883.99","0.00000000"],["884.00","0.00000000"],["884.14","0.00000000"]]},"channel":"diff_order_book_bcheur","event":"data"}
1618677720.626406: {"data":{"timestamp":"1618677720","microtimestamp":"1618677720573298","bids":[],"asks":[["765.63","0.00000000"],["768.34","5.31104960"]]},"channel":"diff_order_book_bchgbp","event":"data"}
1618677720.684017: {"data":{"timestamp":"1618677720","microtimestamp":"1618677720521013","bids":[["60536.82","0.00000000"],["60520.98","0.00000000"],["60494.72","0.08220000"],["60494.03","0.00000000"],["60492.00","0.33010000"],["60491.30","0.00000000"]],"asks":[["60553.64","0.18606874"],["60566.58","0.00000000"],["60573.80","0.00000000"],["60584.81","0.00000000"],["60586.21","0.42834764"],["60589.99","0.47654479"],["60631.63","0.46677714"],["61539.58","0.00000000"]]},"channel":"diff_order_book_btcusd","event":"data"}
1618677720.7075489: {"channel": "live_trades_btcusd", "data": {"amount": 0.05206874, "amount_str": "0.05206874", "buy_order_id": 1351035887398912, "id": 164507781, "microtimestamp": "1618677720604000", "price": 60553.64, "price_str": "60553.64", "sell_order_id": 1351035787067392, "timestamp": "1618677720", "type": 0}, "event": "trade"}
1618677720.716247: {"channel": "live_trades_btcusd", "data": {"amount": 0.11120469, "amount_str": "0.11120469", "buy_order_id": 1351035887398912, "id": 164507782, "microtimestamp": "1618677720604000", "price": 60553.64, "price_str": "60553.64", "sell_order_id": 1351035849076736, "timestamp": "1618677720", "type": 0}, "event": "trade"}
1618677720.717361: {"channel": "live_trades_btcusd", "data": {"amount": 0.02279531, "amount_str": "0.02279531", "buy_order_id": 1351035887501312, "id": 164507785, "microtimestamp": "1618677720629000", "price": 60553.64, "price_str": "60553.64", "sell_order_id": 1351035849076736, "timestamp": "1618677720", "type": 0}, "event": "trade"}
1618677720.776431: {"data":{"timestamp":"1618677720","microtimestamp":"1618677720717298","bids":[],"asks":[["1720.52","0.00000000"]]},"channel":"diff_order_book_ethgbp","event":"data"}
1618677720.81349: {"data":{"timestamp":"1618677720","microtimestamp":"1618677720704446","bids":[["882.53","33.32588000"],["882.36","0.00000000"],["882.22","0.00000000"]],"asks":[["883.97","0.00000000"],["884.14","0.73291035"],["884.15","2.20000000"],["884.49","37.72160000"],["888.02","37.25600136"]]},"channel":"diff_order_book_bcheur","event":"data"}
1618677720.852003: {"data":{"timestamp":"1618677720","microtimestamp":"1618677720812122","bids":[],"asks":[["765.31","0.00000000"]]},"channel":"diff_order_book_bchgbp","event":"data"}
1618677720.890301: {"data":{"timestamp":"1618677720","microtimestamp":"1618677720837608","bids":[["1716.36","0.00000000"]],"asks":[["1720.51","0.00000000"],["1722.53","1.26846906"]]},"channel":"diff_order_book_ethgbp","event":"data"}
1618677720.9108129: {"data":{"timestamp":"1618677720","microtimestamp":"1618677720849732","bids":[],"asks":[["0.00067954","15.89221495"],["0.00067955","0.00000000"],["0.00067971","0.00000000"]]},"channel":"diff_order_book_linkbtc","event":"data"}
1618677720.966016: {"data":{"timestamp":"1618677720","microtimestamp":"1618677720929493","bids":[["764.13","0.00000000"],["763.67","0.00000000"]],"asks":[["765.62","0.00000000"]]},"channel":"diff_order_book_bchgbp","event":"data"}
1618677720.980893: {"data":{"timestamp":"1618677720","microtimestamp":"1618677720880871","bids":[["882.63","49.10394000"],["882.57","3.00000000"],["882.54","4.00000000"],["882.26","0.00000000"],["881.82","0.00000000"],["881.67","0.00000000"],["881.32","0.00000000"]],"asks":[["883.58","0.00000000"],["884.14","2.93291035"],["884.15","0.00000000"],["884.49","0.00000000"],["888.01","5.32315963"],["888.02","0.00000000"]]},"channel":"diff_order_book_bcheur","event":"data"}
1618677721.000148: {"data":{"timestamp":"1618677720","microtimestamp":"1618677720952306","bids":[["312.67","17.89542394"],["312.62","21.28908705"],["312.59","1.51500000"],["312.54","0.00000000"],["312.49","0.00000000"]],"asks":[["312.99","0.00000000"],["313.07","0.00000000"],["313.11","0.00000000"],["313.24","159.46920000"],["313.26","0.00000000"],["313.31","1.60000000"],["313.40","0.00000000"],["313.41","0.00000000"],["313.50","39.10000000"]]},"channel":"diff_order_book_ltcusd","event":"data"}
1618677721.010827: {"data":{"timestamp":"1618677720","microtimestamp":"1618677720953216","bids":[["1718.24","0.05000000"],["1709.13","0.24000000"]],"asks":[["1720.80","0.00000000"],["1722.02","0.00000000"],["1724.94","0.00000000"]]},"channel":"diff_order_book_ethgbp","event":"data"}
1618677721.025695: {"data":{"timestamp":"1618677720","microtimestamp":"1618677720969917","bids":[["0.00067826","24.33094710"]],"asks":[["0.00067902","0.00000000"]]},"channel":"diff_order_book_linkbtc","event":"data"}
1618677721.040687: {"data":{"timestamp":"1618677720","microtimestamp":"1618677720980710","bids":[["3.38280","189.19238000"]],"asks":[["3.40420","241.00000000"]]},"channel":"diff_order_book_kncusd","event":"data"}
1618677721.088512: {"data":{"timestamp":"1618677721","microtimestamp":"1618677721046888","bids":[],"asks":[["765.65","0.00000000"],["765.66","0.00000000"],["766.16","2.85126334"]]},"channel":"diff_order_book_bchgbp","event":"data"}
1618677721.120301: {"data":{"timestamp":"1618677721","microtimestamp":"1618677721071803","bids":[["1717.91","0.00000000"],["1717.85","0.00000000"],["1717.45","0.00000000"],["1716.99","0.00000000"],["1716.74","0.10600000"],["1716.35","0.00000000"]],"asks":[]},"channel":"diff_order_book_ethgbp","event":"data"}
1618677721.139313: {"data":{"timestamp":"1618677721","microtimestamp":"1618677721089628","bids":[["0.00067822","24.65192788"],["0.00067806","0.00000000"]],"asks":[]},"channel":"diff_order_book_linkbtc","event":"data"}
1618677721.152095: {"data":{"timestamp":"1618677721","microtimestamp":"1618677721069940","bids":[["882.67","3.00000000"],["882.64","3.00000000"],["882.63","2.70000000"],["882.54","0.00000000"],["882.53","0.00000000"],["881.68","1.00000000"],["881.33","0.00000000"],["881.01","5.27712668"],["845.01","0.00000000"]],"asks":[["883.68","0.00000000"],["884.14","0.00000000"],["884.15","2.90000000"],["888.00","37.25600136"]]},"channel":"diff_order_book_bcheur","event":"data"}
1618677721.1522791: {"data":{"timestamp":"1618677721","microtimestamp":"1618677721097729","bids":[["3.38115","0.00000000"]],"asks":[["3.41974","780.00000000"]]},"channel":"diff_order_book_kncusd","event":"data"}
1618677721.2012029: {"data":{"timestamp":"1618677721","microtimestamp":"1618677721167201","bids":[],"asks":[["768.34","0.00000000"]]},"channel":"diff_order_book_bchgbp","event":"data"}
1618677721.217471: {"data":{"timestamp":"1618677721","microtimestamp":"1618677721115064","bids":[["312.63","4.00000000"],["312.62","17.28908705"],["312.36","0.00000000"]],"asks":[["313.10","6.38430000"],["313.20","0.00000000"]]},"channel":"diff_order_book_ltcusd","event":"data"}
1618677721.237834: {"data":{"timestamp":"1618677721","microtimestamp":"1618677721191426","bids":[],"asks":[["1723.58","0.05000000"],["1724.43","0.00000000"],["1726.55","5.60000000"]]},"channel":"diff_order_book_ethgbp","event":"data"}
1618677721.2384279: {"data":{"timestamp":"1618677721","microtimestamp":"1618677721051689","bids":[["60534.14","0.26993254"],["60517.85","0.00000000"],["60517.84","0.00000000"],["60515.70","7.07030000"],["60512.52","0.00000000"],["60505.29","0.50000000"],["60502.82","0.08220000"],["60500.19","0.01312500"],["60500.09","0.32990000"],["60499.70","0.00000000"],["60493.83","0.00000000"],["60486.38","1.49297473"],["60484.39","0.00000000"],["60471.78","0.16000000"],["60467.92","0.00000000"],["60384.48","2.00000000"],["60366.17","0.00000000"],["60324.73","0.00000000"],["60050.00","0.07045678"]],"asks":[["60553.64","0.00000000"],["60566.11","0.00000000"],["60567.89","0.00000000"],["60570.04","0.00000000"],["60574.28","0.00000000"],["60574.54","0.29298099"],["60578.35","0.28621195"],["60578.40","0.00000000"],["60586.21","0.00000000"],["60589.99","0.00000000"],["60591.04","0.00000000"],["60598.99","0.00000000"],["60599.59","0.17279520"],["60599.71","0.00000000"],["60606.98","0.00000000"],["60610.07","0.50000000"],["60610.92","0.47298993"],["60611.55","0.00000000"],["60620.90","0.00000000"],["60627.38","0.01312500"],["60627.97","1.71833547"],["60631.63","0.00000000"],["60636.90","6.45680000"],["60825.74","0.38793974"]]},"channel":"diff_order_book_btcusd","event":"data"}
1618677721.248429: {"data":{"timestamp":"1618677721","microtimestamp":"1618677721201927","bids":[],"asks":[["2.84821","0.00000000"]]},"channel":"diff_order_book_knceur","event":"data"}
1618677721.2536: {"data":{"timestamp":"1618677721","microtimestamp":"1618677721207245","bids":[["0.00067827","15.88695096"],["0.00067822","0.00000000"]],"asks":[]},"channel":"diff_order_book_linkbtc","event":"data"}
1618677721.2719092: {"data":{"timestamp":"1618677721","microtimestamp":"1618677721216976","bids":[["3.38406","442.89756709"]],"asks":[]},"channel":"diff_order_book_kncusd","event":"data"}
1618677721.322135: {"data":{"timestamp":"1618677721","microtimestamp":"1618677721232894","bids":[["882.66","3.00000000"],["882.64","0.00000000"],["882.63","0.00000000"],["882.58","0.73250696"],["882.40","0.00000000"],["881.83","0.00000000"]],"asks":[["884.15","0.00000000"],["888.00","0.00000000"]]},"channel":"diff_order_book_bcheur","event":"data"}
1618677721.351012: {"data":{"timestamp":"1618677721","microtimestamp":"1618677721306506","bids":[["1716.74","0.00000000"]],"asks":[["1721.03","0.00000000"],["1729.19","0.67400000"],["1729.20","0.00000000"],["1732.08","0.00000000"]]},"channel":"diff_order_book_ethgbp","event":"data"}
1618677721.3680289: {"data":{"timestamp":"1618677721","microtimestamp":"1618677721329025","bids":[["0.00067805","0.00000000"]],"asks":[["0.00067997","0.00000000"],["0.00068106","0.00000000"]]},"channel":"diff_order_book_linkbtc","event":"data"}
1618677721.383242: {"data":{"timestamp":"1618677721","microtimestamp":"1618677721283407","bids":[["312.67","14.70000000"],["312.65","22.35697532"],["312.64","4.00000000"],["312.63","23.95491378"]],"asks":[["313.19","3.19398851"],["313.22","74.71940265"]]},"channel":"diff_order_book_ltcusd","event":"data"}
1618677721.413145: {"data":{"timestamp":"1618677721","microtimestamp":"1618677721346673","bids":[],"asks":[["2.85197","2835.00000000"]]},"channel":"diff_order_book_knceur","event":"data"}
1618677721.466408: {"data":{"timestamp":"1618677721","microtimestamp":"1618677721423891","bids":[["1717.21","0.10600000"]],"asks":[["1726.54","0.50600000"],["1729.20","1.01100000"]]},"channel":"diff_order_book_ethgbp","event":"data"}
1618677721.4873831: {"data":{"timestamp":"1618677721","microtimestamp":"1618677721450165","bids":[],"asks":[["0.00068062","10.30000000"],["0.00068304","103.10000000"]]},"channel":"diff_order_book_linkbtc","event":"data"}
1618677721.491542: {"data":{"timestamp":"1618677721","microtimestamp":"1618677721394231","bids":[["882.77","2.70000000"],["882.67","6.00000000"],["882.66","0.00000000"],["881.85","4.00000000"],["875.83","53.92443471"]],"asks":[["884.05","2.80000000"],["885.85","0.73238994"]]},"channel":"diff_order_book_bcheur","event":"data"}
1618677721.579844: {"data":{"timestamp":"1618677721","microtimestamp":"1618677721543343","bids":[["1709.13","0.00000000"]],"asks":[]},"channel":"diff_order_book_ethgbp","event":"data"}
1618677721.60573: {"data":{"timestamp":"1618677721","microtimestamp":"1618677721545619","bids":[["882.81","3.00000000"],["882.78","3.00000000"],["882.67","3.00000000"],["882.58","4.73250696"],["882.57","0.00000000"],["881.85","0.00000000"],["881.01","0.00000000"],["878.03","0.00000000"],["871.10","0.00000000"]],"asks":[["884.87","39.03296000"],["888.00","37.25600136"]]},"channel":"diff_order_book_bcheur","event":"data"}
1618677721.6944761: {"data":{"timestamp":"1618677721","microtimestamp":"1618677721660185","bids":[["1708.87","2.42500000"]],"asks":[]},"channel":"diff_order_book_ethgbp","event":"data"}
1618677721.695255: {"data":{"timestamp":"1618677721","microtimestamp":"1618677721419053","bids":[["60546.68","1.10000000"],["60545.72","0.12386821"],["60539.91","0.75144803"],["60539.90","0.77007037"],["60538.75","0.00000000"],["60538.25","0.29644449"],["60538.24","0.49391664"],["60534.98","0.02000000"],["60534.14","0.00000000"],["60534.13","0.00000000"],["60534.12","0.00000000"],["60533.53","0.20645742"],["60520.97","0.00000000"],["60519.57","0.00000000"],["60516.28","0.50000000"],["60509.71","0.08240000"],["60507.17","0.04997754"],["60506.99","0.33010000"],["60505.29","0.00000000"],["60502.82","0.00000000"],["60500.09","0.00000000"],["60494.72","0.00000000"],["60492.00","0.00000000"],["60478.37","0.16450000"],["60471.78","0.00000000"],["60455.86","1.00000000"],["60442.26","0.00000000"],["60432.99","0.00000000"],["60391.41","0.11589762"],["60321.21","0.02818627"],["59912.00","0.41294713"]],"asks":[["60571.42","0.00000000"],["60574.54","0.00000000"],["60574.55","0.00000000"],["60577.89","0.30000000"],["60578.00","0.27714930"],["60578.01","0.12386821"],["60578.35","0.00000000"],["60578.36","0.00000000"],["60581.08","0.16515761"],["60582.67","0.00000000"],["60583.34","0.04732931"],["60585.55","0.00000000"],["60587.03","0.00000000"],["60589.99","0.27825053"],["60592.65","0.00000000"],["60599.59","0.00000000"],["60606.01","0.08803200"],["60610.06","0.48552305"],["60610.07","0.00000000"],["60611.27","0.16268176"],["60614.47","0.33033188"],["60619.10","0.50000000"],["60623.15","0.18648061"],["60635.93","0.01651377"],["60644.91","0.37634585"],["60659.61","0.00000000"],["60679.55","1.00000000"],["60825.74","0.00000000"],["61719.09","0.49786831"]]},"channel":"diff_order_book_btcusd","event":"data"}
1618677721.712838: {"data":{"timestamp":"1618677721","microtimestamp":"1618677721615196","bids":[],"asks":[["313.19","0.00000000"],["313.22","53.58840265"],["313.39","21.13100000"]]},"channel":"diff_order_book_ltcusd","event":"data"}
1618677721.809949: {"data":{"timestamp":"1618677721","microtimestamp":"1618677721774938","bids":[],"asks":[["1729.19","0.00000000"],["1729.32","0.00000000"]]},"channel":"diff_order_book_ethgbp","event":"data"}
1618677721.8215868: {"data":{"timestamp":"1618677721","microtimestamp":"1618677721724230","bids":[["882.78","0.00000000"],["882.74","34.93892000"],["882.58","0.73250696"]],"asks":[["884.14","2.90000000"],["888.00","0.00000000"]]},"channel":"diff_order_book_bcheur","event":"data"}
1618677721.829068: {"data":{"timestamp":"1618677721","microtimestamp":"1618677721779218","bids":[],"asks":[["313.19","4.81864043"],["313.22","37.61509764"]]},"channel":"diff_order_book_ltcusd","event":"data"}
1618677721.881345: {"data":{"timestamp":"1618677721","microtimestamp":"1618677721815530","bids":[],"asks":[["0.00067954","0.00000000"],["0.00067971","15.88811137"]]},"channel":"diff_order_book_linkbtc","event":"data"}
1618677721.93717: {"data":{"timestamp":"1618677721","microtimestamp":"1618677721882491","bids":[["882.88","3.00000000"],["882.87","48.15459000"],["878.04","22.02410214"],["877.91","5.15543591"],["875.84","0.40000000"]],"asks":[["884.14","0.00000000"],["884.86","37.25600136"],["888.01","0.00000000"]]},"channel":"diff_order_book_bcheur","event":"data"}
1618677721.972416: {"data":{"timestamp":"1618677721","microtimestamp":"1618677721896007","bids":[],"asks":[["1726.53","2.85900000"]]},"channel":"diff_order_book_ethgbp","event":"data"}
1618677722.0021062: {"data":{"timestamp":"1618677721","microtimestamp":"1618677721963342","bids":[],"asks":[["766.48","2.80000000"],["768.34","5.52384576"]]},"channel":"diff_order_book_bchgbp","event":"data"}


