wss://ws.bitstamp.net/ <-> 1641343690.598303
wss://ws.bitstamp.net/ <- 1641343691.067583: {"event":"bts:subscribe","data":{"channel":"diff_order_book_sgbeur"}}
wss://ws.bitstamp.net/ <- 1641343691.067776: {"event":"bts:subscribe","data":{"channel":"diff_order_book_ethusd"}}
wss://ws.bitstamp.net/ <- 1641343691.067845: {"event":"bts:subscribe","data":{"channel":"diff_order_book_xrpeur"}}
wss://ws.bitstamp.net/ <- 1641343691.067899: {"event":"bts:subscribe","data":{"channel":"diff_order_book_bateur"}}
wss://ws.bitstamp.net/ <- 1641343691.06795: {"event":"bts:subscribe","data":{"channel":"diff_order_book_usdteur"}}
wss://ws.bitstamp.net/ <- 1641343691.067997: {"event":"bts:subscribe","data":{"channel":"diff_order_book_usdtusd"}}
wss://ws.bitstamp.net/ <- 1641343691.068044: {"event":"bts:subscribe","data":{"channel":"diff_order_book_xlmgbp"}}
wss://ws.bitstamp.net/ <- 1641343691.068091: {"event":"bts:subscribe","data":{"channel":"diff_order_book_adaeur"}}
wss://ws.bitstamp.net/ <- 1641343691.068137: {"event":"bts:subscribe","data":{"channel":"diff_order_book_batbtc"}}
wss://ws.bitstamp.net/ <- 1641343691.068183: {"event":"bts:subscribe","data":{"channel":"diff_order_book_galaeur"}}
wss://ws.bitstamp.net/ <- 1641343691.068228: {"event":"bts:subscribe","data":{"channel":"live_trades_sgbeur"}}
wss://ws.bitstamp.net/ <- 1641343691.0682728: {"event":"bts:subscribe","data":{"channel":"live_trades_ethusd"}}
wss://ws.bitstamp.net/ <- 1641343691.068317: {"event":"bts:subscribe","data":{"channel":"live_trades_xrpeur"}}
wss://ws.bitstamp.net/ <- 1641343691.068361: {"event":"bts:subscribe","data":{"channel":"live_trades_bateur"}}
wss://ws.bitstamp.net/ <- 1641343691.068405: {"event":"bts:subscribe","data":{"channel":"live_trades_usdteur"}}
wss://ws.bitstamp.net/ <- 1641343691.0684521: {"event":"bts:subscribe","data":{"channel":"live_trades_usdtusd"}}
wss://ws.bitstamp.net/ <- 1641343691.068497: {"event":"bts:subscribe","data":{"channel":"live_trades_xlmgbp"}}
wss://ws.bitstamp.net/ <- 1641343691.0685408: {"event":"bts:subscribe","data":{"channel":"live_trades_adaeur"}}
wss://ws.bitstamp.net/ <- 1641343691.068585: {"event":"bts:subscribe","data":{"channel":"live_trades_batbtc"}}
wss://ws.bitstamp.net/ <- 1641343691.068628: {"event":"bts:subscribe","data":{"channel":"live_trades_galaeur"}}
1641343697.4033659: {"event":"bts:subscription_succeeded","channel":"diff_order_book_sgbeur","data":{}}
1641343697.40338: {"event":"bts:subscription_succeeded","channel":"diff_order_book_ethusd","data":{}}
1641343697.4033868: {"event":"bts:subscription_succeeded","channel":"diff_order_book_xrpeur","data":{}}
1641343697.403392: {"event":"bts:subscription_succeeded","channel":"diff_order_book_bateur","data":{}}
1641343697.403397: {"event":"bts:subscription_succeeded","channel":"diff_order_book_usdteur","data":{}}
1641343697.403403: {"event":"bts:subscription_succeeded","channel":"diff_order_book_usdtusd","data":{}}
1641343697.4034078: {"event":"bts:subscription_succeeded","channel":"diff_order_book_xlmgbp","data":{}}
1641343697.4034119: {"event":"bts:subscription_succeeded","channel":"diff_order_book_adaeur","data":{}}
1641343697.403417: {"event":"bts:subscription_succeeded","channel":"diff_order_book_batbtc","data":{}}
1641343697.403421: {"event":"bts:subscription_succeeded","channel":"diff_order_book_galaeur","data":{}}
1641343697.403425: {"event":"bts:subscription_succeeded","channel":"live_trades_sgbeur","data":{}}
1641343697.403429: {"event":"bts:subscription_succeeded","channel":"live_trades_ethusd","data":{}}
1641343697.403434: {"event":"bts:subscription_succeeded","channel":"live_trades_xrpeur","data":{}}
1641343697.403438: {"event":"bts:subscription_succeeded","channel":"live_trades_bateur","data":{}}
1641343697.403442: {"event":"bts:subscription_succeeded","channel":"live_trades_usdteur","data":{}}
1641343697.4034472: {"event":"bts:subscription_succeeded","channel":"live_trades_usdtusd","data":{}}
1641343697.403451: {"event":"bts:subscription_succeeded","channel":"live_trades_xlmgbp","data":{}}
1641343697.403455: {"event":"bts:subscription_succeeded","channel":"live_trades_adaeur","data":{}}
1641343697.40346: {"event":"bts:subscription_succeeded","channel":"live_trades_batbtc","data":{}}
1641343697.4034638: {"event":"bts:subscription_succeeded","channel":"live_trades_galaeur","data":{}}
1641343697.4034681: {"data":{"timestamp":"1641343691","microtimestamp":"1641343691244908","bids":[["1.15979","993.02588113"],["1.14866","7758.51900928"]],"asks":[["1.16601","1200.00000000"]]},"channel":"diff_order_book_bateur","event":"data"}
1641343697.403487: {"data":{"timestamp":"1641343691","microtimestamp":"1641343691310202","bids":[],"asks":[["1.17438","853.01809477"],["1.17484","0.00000000"]]},"channel":"diff_order_book_adaeur","event":"data"}
1641343697.403498: {"data":{"timestamp":"1641343691","microtimestamp":"1641343691355099","bids":[],"asks":[["0.00002921","3213.71284910"],["0.00002922","0.00000000"],["0.00002925","0.00000000"]]},"channel":"diff_order_book_batbtc","event":"data"}
1641343697.403507: {"data":{"timestamp":"1641343691","microtimestamp":"1641343691468521","bids":[["0.00002756","7752.76328758"]],"asks":[["0.00002920","839.17692634"],["0.00002921","428.69204724"]]},"channel":"diff_order_book_batbtc","event":"data"}
1641343697.4035149: {"data":{"timestamp":"1641343691","microtimestamp":"1641343691406478","bids":[["3800.71","1.76200000"],["3800.07","10.00000000"],["3799.64","0.00000000"],["3797.93","2.73248242"]],"asks":[]},"channel":"diff_order_book_ethusd","event":"data"}
1641343697.403523: {"data":{"timestamp":"1641343691","microtimestamp":"1641343691521564","bids":[["0.20820","0.00000000"],["0.20814","0.00000000"]],"asks":[["0.20861","0.00000000"]]},"channel":"diff_order_book_xlmgbp","event":"data"}
1641343697.403531: {"data":{"timestamp":"1641343691","microtimestamp":"1641343691457199","bids":[["0.73467","0.00000000"],["0.73445","14075.40293430"],["0.73444","0.00000000"]],"asks":[["0.73541","0.00000000"]]},"channel":"diff_order_book_xrpeur","event":"data"}
1641343697.403541: {"data":{"timestamp":"1641343691","microtimestamp":"1641343691591603","bids":[],"asks":[["0.99991","0.00000"]]},"channel":"diff_order_book_usdtusd","event":"data"}
1641343697.403549: {"data":{"timestamp":"1641343691","microtimestamp":"1641343691582304","bids":[["0.00002829","3149.33673265"]],"asks":[["0.00002921","1500.25357752"]]},"channel":"diff_order_book_batbtc","event":"data"}
1641343697.403557: {"data":{"timestamp":"1641343691","microtimestamp":"1641343691580748","bids":[],"asks":[["0.88680","0.00000"],["0.88704","0.00000"],["0.89661","0.00000"],["0.89933","0.00000"]]},"channel":"diff_order_book_usdteur","event":"data"}
1641343697.4035652: {"data":{"timestamp":"1641343691","microtimestamp":"1641343691648492","bids":[["0.20816","14234.15097929"]],"asks":[["0.20868","0.00000000"]]},"channel":"diff_order_book_xlmgbp","event":"data"}
1641343697.403572: {"data":{"timestamp":"1641343691","microtimestamp":"1641343691705619","bids":[],"asks":[["0.99998","3000.00000"]]},"channel":"diff_order_book_usdtusd","event":"data"}
1641343697.40358: {"data":{"timestamp":"1641343691","microtimestamp":"1641343691697531","bids":[],"asks":[["0.88704","18000.00000"],["0.89661","32000.00000"]]},"channel":"diff_order_book_usdteur","event":"data"}
1641343697.403588: {"data":{"timestamp":"1641343691","microtimestamp":"1641343691692695","bids":[["3802.70","0.00000000"],["3801.92","0.00000000"],["3801.48","0.40000000"],["3801.40","1.70851184"],["3801.00","0.00000000"],["3800.46","0.00000000"],["3800.33","4.80000000"],["3800.19","7.94289028"],["3800.07","0.00000000"],["3799.85","0.00000000"],["3795.12","0.00000000"],["3422.60","0.00000000"]],"asks":[["3805.16","0.00000000"],["3805.17","0.00000000"],["3805.44","0.00000000"],["3805.61","0.00000000"],["3805.83","13.07397578"],["3805.84","0.00000000"],["3806.00","0.65711994"],["3806.17","0.00000000"],["3806.18","0.00000000"],["3806.27","0.40000000"],["3807.06","1.70882068"],["3807.47","1.70848604"],["3807.79","0.00000000"]]},"channel":"diff_order_book_ethusd","event":"data"}
1641343697.4036028: {"data":{"timestamp":"1641343691","microtimestamp":"1641343691772111","bids":[["1.16008","1473.12000000"],["0.45397","44.05596870"]],"asks":[]},"channel":"diff_order_book_bateur","event":"data"}
1641343697.403612: {"data":{"timestamp":"1641343691","microtimestamp":"1641343691818909","bids":[["0.00002756","5599.51931814"]],"asks":[]},"channel":"diff_order_book_batbtc","event":"data"}
1641343697.403619: {"data":{"timestamp":"1641343691","microtimestamp":"1641343691815369","bids":[["0.88424","45621.62593"]],"asks":[["0.88676","15883.96385"],["0.89931","28000.00000"],["0.89932","0.00000"],["0.89999","93342.64801"]]},"channel":"diff_order_book_usdteur","event":"data"}
1641343697.403627: {"data":{"timestamp":"1641343691","microtimestamp":"1641343691843553","bids":[],"asks":[["0.99994","14883.96385"]]},"channel":"diff_order_book_usdtusd","event":"data"}
1641343697.4036338: {"data":{"timestamp":"1641343691","microtimestamp":"1641343691879007","bids":[],"asks":[["0.20906","0.00000000"],["0.20976","1428.00000000"]]},"channel":"diff_order_book_xlmgbp","event":"data"}
1641343697.4036422: {"data":{"timestamp":"1641343691","microtimestamp":"1641343691891455","bids":[["1.16085","101.76135984"]],"asks":[]},"channel":"diff_order_book_bateur","event":"data"}
1641343697.403649: {"data":{"timestamp":"1641343691","microtimestamp":"1641343691932669","bids":[["0.00002757","2153.11245670"]],"asks":[]},"channel":"diff_order_book_batbtc","event":"data"}
1641343697.403656: {"data":{"timestamp":"1641343691","microtimestamp":"1641343691963989","bids":[["0.99948","0.00000"],["0.99771","0.00000"],["0.99761","0.00000"],["0.99522","0.00000"],["0.98452","0.00000"]],"asks":[]},"channel":"diff_order_book_usdtusd","event":"data"}
1641343697.4036639: {"data":{"timestamp":"1641343691","microtimestamp":"1641343691947415","bids":[["3802.38","1.31417521"],["3798.06","2.73248242"],["3798.05","3.94252562"],["3797.93","0.00000000"]],"asks":[["3805.47","8.26964788"],["3806.65","0.00000000"],["3809.13","2.62839156"]]},"channel":"diff_order_book_ethusd","event":"data"}
1641343697.4036732: {"data":{"timestamp":"1641343692","microtimestamp":"1641343692013455","bids":[["1.16055","0.00000000"]],"asks":[["1.16306","0.00000000"],["1.16389","0.00000000"],["1.16424","0.00000000"]]},"channel":"diff_order_book_bateur","event":"data"}
1641343697.403681: {"data":{"timestamp":"1641343691","microtimestamp":"1641343691903443","bids":[],"asks":[["0.73540","0.00000000"],["0.73542","1800.00000000"]]},"channel":"diff_order_book_xrpeur","event":"data"}
1641343697.403689: {"data":{"timestamp":"1641343692","microtimestamp":"1641343692045909","bids":[["0.00002830","0.00000000"]],"asks":[["0.00002842","920.00755283"]]},"channel":"diff_order_book_batbtc","event":"data"}
1641343697.403696: {"data":{"timestamp":"1641343692","microtimestamp":"1641343692044279","bids":[["0.88422","0.00000"],["0.88252","0.00000"],["0.88101","0.00000"]],"asks":[["0.89662","0.00000"],["0.89930","93342.64801"],["0.89999","0.00000"]]},"channel":"diff_order_book_usdteur","event":"data"}
1641343697.4037042: {"data":{"timestamp":"1641343692","microtimestamp":"1641343692077795","bids":[["0.99948","3105.20768"],["0.99773","58633.09713"],["0.99522","50240.14790"],["0.98452","66529.87117"]],"asks":[]},"channel":"diff_order_book_usdtusd","event":"data"}
1641343697.403712: {"data":{"timestamp":"1641343692","microtimestamp":"1641343692139165","bids":[["1.16101","4628.70684786"],["1.15956","0.00000000"],["0.34048","58.74129160"]],"asks":[["1.16304","0.00000000"],["1.16331","0.00000000"],["1.16349","762.70684786"],["1.16390","0.00000000"],["1.16398","1645.10584651"],["1.16509","98.69738468"],["1.16834","0.00000000"]]},"channel":"diff_order_book_bateur","event":"data"}
1641343697.4037209: {"data":{"timestamp":"1641343692","microtimestamp":"1641343692159263","bids":[["0.00002833","8084.22509639"],["0.00002830","839.07335762"],["0.00002828","0.00000000"]],"asks":[["0.00002844","5811.57905784"]]},"channel":"diff_order_book_batbtc","event":"data"}
1641343697.40373: {"data":{"timestamp":"1641343692","microtimestamp":"1641343692160365","bids":[],"asks":[["0.89660","14566.33531"]]},"channel":"diff_order_book_usdteur","event":"data"}
1641343697.403737: {"data":{"timestamp":"1641343692","microtimestamp":"1641343692273513","bids":[["0.00002756","0.00000000"]],"asks":[]},"channel":"diff_order_book_batbtc","event":"data"}
1641343697.403744: {"data":{"timestamp":"1641343692","microtimestamp":"1641343692273998","bids":[["0.88424","53644.83151"],["0.88254","77050.33199"],["0.88101","67536.12331"]],"asks":[]},"channel":"diff_order_book_usdteur","event":"data"}
1641343697.403751: {"data":{"timestamp":"1641343692","microtimestamp":"1641343692221498","bids":[["0.73461","6029.38262442"]],"asks":[["0.73536","6029.84191370"],["0.73542","0.00000000"],["0.73594","11328.72012704"],["0.73596","0.00000000"]]},"channel":"diff_order_book_xrpeur","event":"data"}
1641343697.4037602: {"data":{"timestamp":"1641343692","microtimestamp":"1641343692263892","bids":[["1.15979","0.00000000"]],"asks":[["1.16396","863.68055980"],["1.16413","1906.52056541"],["1.17029","2781.29900310"]]},"channel":"diff_order_book_bateur","event":"data"}
1641343697.403767: {"data":{"timestamp":"1641343692","microtimestamp":"1641343692225336","bids":[["3800.19","0.00000000"],["3798.08","2.73248242"],["3798.06","0.00000000"]],"asks":[["3805.99","3.24341641"],["3806.26","8.17173874"],["3806.75","0.39505124"],["3815.09","0.00000000"],["3815.30","0.29640332"]]},"channel":"diff_order_book_ethusd","event":"data"}
1641343697.4037771: {"data":{"timestamp":"1641343692","microtimestamp":"1641343692333097","bids":[],"asks":[["0.20905","0.00000000"],["0.20975","3997.99569442"]]},"channel":"diff_order_book_xlmgbp","event":"data"}
1641343697.403784: {"data":{"timestamp":"1641343692","microtimestamp":"1641343692390710","bids":[["0.00002757","7752.08115885"]],"asks":[]},"channel":"diff_order_book_batbtc","event":"data"}
1641343697.4037912: {"data":{"timestamp":"1641343692","microtimestamp":"1641343692389243","bids":[["0.88423","0.00000"],["0.88253","0.00000"]],"asks":[["0.88677","0.00000"]]},"channel":"diff_order_book_usdteur","event":"data"}
1641343697.403799: {"data":{"timestamp":"1641343692","microtimestamp":"1641343692388786","bids":[["1.15989","992.87655478"]],"asks":[["1.16398","0.00000000"],["1.16454","2218.93000911"]]},"channel":"diff_order_book_bateur","event":"data"}
1641343697.403807: {"data":{"timestamp":"1641343692","microtimestamp":"1641343692436345","bids":[["0.99772","0.00000"]],"asks":[]},"channel":"diff_order_book_usdtusd","event":"data"}
1641343697.4038138: {"data":{"timestamp":"1641343692","microtimestamp":"1641343692505996","bids":[["0.00002833","1906.56509639"]],"asks":[]},"channel":"diff_order_book_batbtc","event":"data"}
1641343697.403821: {"data":{"timestamp":"1641343692","microtimestamp":"1641343692550058","bids":[["0.99771","5625.02452"]],"asks":[]},"channel":"diff_order_book_usdtusd","event":"data"}
1641343697.403828: {"data":{"timestamp":"1641343692","microtimestamp":"1641343692621877","bids":[["0.00002835","7159.36203756"]],"asks":[]},"channel":"diff_order_book_batbtc","event":"data"}
1641343697.403836: {"data":{"timestamp":"1641343692","microtimestamp":"1641343692621873","bids":[["0.88425","17587.43984"]],"asks":[["0.88675","5692.64822"]]},"channel":"diff_order_book_usdteur","event":"data"}
1641343697.4038432: {"data":{"timestamp":"1641343692","microtimestamp":"1641343692685501","bids":[["0.20813","17738.28378595"]],"asks":[["0.20858","0.00000000"],["0.20869","17738.28378595"]]},"channel":"diff_order_book_xlmgbp","event":"data"}
1641343697.403851: {"data":{"timestamp":"1641343692","microtimestamp":"1641343692673983","bids":[],"asks":[["1.19571","0.00000000"],["1.19572","0.00000000"]]},"channel":"diff_order_book_adaeur","event":"data"}
1641343697.403858: {"data":{"timestamp":"1641343692","microtimestamp":"1641343692638884","bids":[["3800.27","10.00000000"]],"asks":[["3807.16","25.00000000"],["3815.30","0.00000000"],["3816.79","1.03757667"]]},"channel":"diff_order_book_ethusd","event":"data"}
1641343697.403866: {"data":{"timestamp":"1641343692","microtimestamp":"1641343692797994","bids":[],"asks":[["1.19751","29165.30374689"]]},"channel":"diff_order_book_adaeur","event":"data"}
1641343697.403873: {"data":{"timestamp":"1641343692","microtimestamp":"1641343692822939","bids":[],"asks":[["0.20863","10642.72270630"]]},"channel":"diff_order_book_xlmgbp","event":"data"}
1641343697.40388: {"data":{"timestamp":"1641343692","microtimestamp":"1641343692939738","bids":[],"asks":[["0.20863","0.00000000"],["0.20869","0.00000000"],["0.20877","0.00000000"],["0.20977","0.00000000"]]},"channel":"diff_order_book_xlmgbp","event":"data"}
1641343697.4038882: {"data":{"timestamp":"1641343692","microtimestamp":"1641343692945613","bids":[["3801.78","0.40000000"],["3801.48","0.00000000"],["3798.09","2.73248242"],["3798.08","0.00000000"]],"asks":[["3806.27","0.00000000"],["3806.60","0.40000000"],["3806.99","0.00000000"],["3807.75","4.80000000"]]},"channel":"diff_order_book_ethusd","event":"data"}
1641343697.403897: {"data":{"timestamp":"1641343693","microtimestamp":"1641343693052978","bids":[],"asks":[["0.20875","3595.53928400"],["0.20889","26600.81461547"],["0.21030","3342.00000000"]]},"channel":"diff_order_book_xlmgbp","event":"data"}
1641343697.403904: {"data":{"timestamp":"1641343693","microtimestamp":"1641343693076976","bids":[],"asks":[["0.00002842","0.00000000"]]},"channel":"diff_order_book_batbtc","event":"data"}
1641343697.4039118: {"data":{"timestamp":"1641343693","microtimestamp":"1641343693190009","bids":[["0.00002830","0.00000000"]],"asks":[["0.00002919","2784.75240722"],["0.00002923","0.00000000"]]},"channel":"diff_order_book_batbtc","event":"data"}
1641343697.4039192: {"data":{"timestamp":"1641343693","microtimestamp":"1641343693233885","bids":[["3803.12","0.65706579"],["3802.92","0.60000000"],["3802.91","0.00000000"],["3798.09","0.00000000"],["3788.73","0.08718578"],["3788.72","0.00000000"]],"asks":[]},"channel":"diff_order_book_ethusd","event":"data"}
1641343697.403927: {"data":{"timestamp":"1641343693","microtimestamp":"1641343693304866","bids":[["0.00002830","839.02913724"]],"asks":[["0.00002843","2064.32304089"],["0.00002918","839.03663077"],["0.00002919","0.00000000"],["0.00002920","0.00000000"]]},"channel":"diff_order_book_batbtc","event":"data"}
1641343697.403935: {"data":{"timestamp":"1641343693","microtimestamp":"1641343693421077","bids":[["0.00002755","0.00000000"]],"asks":[["0.00002919","428.64878511"]]},"channel":"diff_order_book_batbtc","event":"data"}
1641343697.4039428: {"data":{"timestamp":"1641343693","microtimestamp":"1641343693473045","bids":[["0.99771","0.00000"]],"asks":[]},"channel":"diff_order_book_usdtusd","event":"data"}
1641343697.4039521: {"data":{"timestamp":"1641343693","microtimestamp":"1641343693510322","bids":[["1.15989","0.00000000"]],"asks":[]},"channel":"diff_order_book_bateur","event":"data"}
1641343697.40396: {"data":{"timestamp":"1641343693","microtimestamp":"1641343693513312","bids":[["3803.13","0.60000000"],["3803.12","4.20706579"],["3802.92","0.00000000"],["3802.90","0.00000000"],["3798.07","2.73248242"]],"asks":[]},"channel":"diff_order_book_ethusd","event":"data"}
1641343697.403968: {"data":{"timestamp":"1641343693","microtimestamp":"1641343693535302","bids":[["0.73456","10168.63761652"],["0.73455","6029.91436966"],["0.73453","0.00000000"]],"asks":[["0.73554","9045.30127263"],["0.73566","0.00000000"]]},"channel":"diff_order_book_xrpeur","event":"data"}
1641343697.403976: {"data":{"timestamp":"1641343693","microtimestamp":"1641343693632892","bids":[["1.15989","992.86428270"]],"asks":[]},"channel":"diff_order_book_bateur","event":"data"}
1641343697.403983: {"data":{"timestamp":"1641343693","microtimestamp":"1641343693705480","bids":[["0.99774","5624.85539"]],"asks":[]},"channel":"diff_order_book_usdtusd","event":"data"}
1641343697.40399: {"data":{"timestamp":"1641343693","microtimestamp":"1641343693784392","bids":[],"asks":[["1.19570","91.11535390"]]},"channel":"diff_order_book_adaeur","event":"data"}
1641343697.403997: {"data":{"timestamp":"1641343693","microtimestamp":"1641343693779589","bids":[["0.73461","0.00000000"],["0.73460","6030.11498579"],["0.73456","0.00000000"],["0.73455","0.00000000"],["0.73445","2017.62000000"],["0.73428","12060.65305878"]],"asks":[["0.73535","1800.00000000"],["0.73536","0.00000000"],["0.73537","6030.41602536"],["0.73543","0.00000000"],["0.73558","12060.83205071"],["0.73573","0.00000000"]]},"channel":"diff_order_book_xrpeur","event":"data"}
1641343697.404006: {"data":{"timestamp":"1641343693","microtimestamp":"1641343693911887","bids":[],"asks":[["1.19569","29165.30374689"],["1.19751","0.00000000"]]},"channel":"diff_order_book_adaeur","event":"data"}
1641343697.404016: {"data":{"timestamp":"1641343694","microtimestamp":"1641343694033567","bids":[["0.73485","0.00000000"],["0.73479","14722.10011783"]],"asks":[["0.73532","6030.11109498"],["0.73535","0.00000000"]]},"channel":"diff_order_book_xrpeur","event":"data"}
1641343697.4041889: {"data":{"timestamp":"1641343694","microtimestamp":"1641343694119181","bids":[],"asks":[["0.00002921","428.69204724"]]},"channel":"diff_order_book_batbtc","event":"data"}
1641343697.404201: {"data":{"timestamp":"1641343694","microtimestamp":"1641343694211193","bids":[["0.20797","0.00000000"]],"asks":[]},"channel":"diff_order_book_xlmgbp","event":"data"}
1641343697.404209: {"data":{"timestamp":"1641343694","microtimestamp":"1641343694249155","bids":[],"asks":[["0.00002917","2784.52261107"]]},"channel":"diff_order_book_batbtc","event":"data"}
1641343697.404217: {"data":{"timestamp":"1641343694","microtimestamp":"1641343694246365","bids":[],"asks":[["0.88678","0.00000"]]},"channel":"diff_order_book_usdteur","event":"data"}
1641343697.404224: {"data":{"timestamp":"1641343694","microtimestamp":"1641343694206780","bids":[["3803.12","0.65706579"],["3802.39","2.10800000"],["3801.20","0.00000000"],["3798.08","2.73248242"],["3798.07","0.00000000"]],"asks":[["3806.59","1.31424576"],["3807.06","0.00000000"]]},"channel":"diff_order_book_ethusd","event":"data"}
1641343697.404233: {"data":{"timestamp":"1641343694","microtimestamp":"1641343694296542","bids":[],"asks":[["0.99989","0.00000"]]},"channel":"diff_order_book_usdtusd","event":"data"}
1641343697.40424: {"data":{"timestamp":"1641343694","microtimestamp":"1641343694281811","bids":[["1.16048","0.00000000"]],"asks":[]},"channel":"diff_order_book_bateur","event":"data"}
1641343697.404248: {"data":{"timestamp":"1641343694","microtimestamp":"1641343694326642","bids":[["0.20797","30012.38640150"]],"asks":[["0.20874","5855.58528256"]]},"channel":"diff_order_book_xlmgbp","event":"data"}
1641343697.404255: {"data":{"timestamp":"1641343694","microtimestamp":"1641343694361888","bids":[["0.00002830","839.04139392"]],"asks":[["0.00002916","2784.45716181"],["0.00002917","428.66184141"],["0.00002918","0.00000000"],["0.00002921","0.00000000"]]},"channel":"diff_order_book_batbtc","event":"data"}
1641343697.404263: {"data":{"timestamp":"1641343694","microtimestamp":"1641343694360988","bids":[],"asks":[["0.88674","9000.00000"]]},"channel":"diff_order_book_usdteur","event":"data"}
1641343697.4042711: {"data":{"timestamp":"1641343694","microtimestamp":"1641343694317514","bids":[["0.73442","6051.00000000"],["0.73440","0.00000000"]],"asks":[]},"channel":"diff_order_book_xrpeur","event":"data"}
1641343697.4042912: {"data":{"timestamp":"1641343694","microtimestamp":"1641343694413955","bids":[],"asks":[["0.99993","8122.14370"]]},"channel":"diff_order_book_usdtusd","event":"data"}
1641343697.4043: {"data":{"timestamp":"1641343694","microtimestamp":"1641343694435337","bids":[["1.16133","1200.00000000"],["1.16119","96.23296657"],["1.16007","0.00000000"]],"asks":[["1.16456","0.00000000"]]},"channel":"diff_order_book_bateur","event":"data"}
1641343697.404308: {"data":{"timestamp":"1641343694","microtimestamp":"1641343694474398","bids":[],"asks":[["0.00002915","839.04153491"],["0.00002916","0.00000000"]]},"channel":"diff_order_book_batbtc","event":"data"}
1641343697.404315: {"data":{"timestamp":"1641343694","microtimestamp":"1641343694566943","bids":[["1.16134","3866.00000000"],["1.16101","762.70684786"],["1.14866","5603.67737239"]],"asks":[]},"channel":"diff_order_book_bateur","event":"data"}
1641343697.404323: {"data":{"timestamp":"1641343694","microtimestamp":"1641343694590576","bids":[["0.00002757","7773.34086142"]],"asks":[["0.00002916","428.66184141"]]},"channel":"diff_order_book_batbtc","event":"data"}
1641343697.40433: {"data":{"timestamp":"1641343694","microtimestamp":"1641343694496671","bids":[["3803.13","0.00000000"],["3803.12","0.00000000"],["3802.90","0.60000000"],["3802.72","0.65713495"],["3798.08","0.00000000"]],"asks":[["3807.06","25.00000000"],["3807.16","0.00000000"],["3809.12","0.30876129"]]},"channel":"diff_order_book_ethusd","event":"data"}
1641343697.4043388: {"data":{"timestamp":"1641343694","microtimestamp":"1641343694565663","bids":[["0.73443","10168.63761652"]],"asks":[]},"channel":"diff_order_book_xrpeur","event":"data"}
1641343697.404354: {"data":{"timestamp":"1641343694","microtimestamp":"1641343694680441","bids":[],"asks":[["0.20864","10642.11817751"],["0.20876","24420.94932258"]]},"channel":"diff_order_book_xlmgbp","event":"data"}
1641343697.404363: {"data":{"timestamp":"1641343694","microtimestamp":"1641343694690726","bids":[["1.15989","0.00000000"],["1.15679","2154.01948949"]],"asks":[["1.16472","101.38370962"]]},"channel":"diff_order_book_bateur","event":"data"}
1641343697.404372: {"data":{"timestamp":"1641343694","microtimestamp":"1641343694706106","bids":[["0.00002829","2288.20971418"]],"asks":[]},"channel":"diff_order_book_batbtc","event":"data"}
1641343697.404379: {"data":{"timestamp":"1641343694","microtimestamp":"1641343694796724","bids":[],"asks":[["0.21030","0.00000000"]]},"channel":"diff_order_book_xlmgbp","event":"data"}
1641343697.404386: {"data":{"timestamp":"1641343694","microtimestamp":"1641343694811330","bids":[["1.15989","992.87215214"]],"asks":[]},"channel":"diff_order_book_bateur","event":"data"}
1641343697.404394: {"data":{"timestamp":"1641343694","microtimestamp":"1641343694822631","bids":[["0.00002830","1699.80492003"]],"asks":[]},"channel":"diff_order_book_batbtc","event":"data"}
1641343697.404404: {"data":{"timestamp":"1641343694","microtimestamp":"1641343694821444","bids":[],"asks":[["0.88675","0.00000"]]},"channel":"diff_order_book_usdteur","event":"data"}
1641343697.4044118: {"data":{"timestamp":"1641343694","microtimestamp":"1641343694870544","bids":[],"asks":[["0.99988","0.00000"]]},"channel":"diff_order_book_usdtusd","event":"data"}
1641343697.4044192: {"data":{"timestamp":"1641343694","microtimestamp":"1641343694764827","bids":[["3798.11","2.73248242"]],"asks":[]},"channel":"diff_order_book_ethusd","event":"data"}
1641343697.404427: {"data":{"timestamp":"1641343694","microtimestamp":"1641343694916862","bids":[],"asks":[["0.20977","3342.00000000"]]},"channel":"diff_order_book_xlmgbp","event":"data"}
1641343697.404434: {"data":{"timestamp":"1641343694","microtimestamp":"1641343694938459","bids":[],"asks":[["0.88673","3692.64822"]]},"channel":"diff_order_book_usdteur","event":"data"}
1641343697.404441: {"data":{"timestamp":"1641343694","microtimestamp":"1641343694983497","bids":[],"asks":[["0.99992","5692.64822"]]},"channel":"diff_order_book_usdtusd","event":"data"}
1641343697.404448: {"data":{"timestamp":"1641343695","microtimestamp":"1641343695048601","bids":[["0.00002757","21.25970257"]],"asks":[]},"channel":"diff_order_book_batbtc","event":"data"}
1641343697.404456: {"data":{"timestamp":"1641343695","microtimestamp":"1641343695027150","bids":[["0.38083","0.00000000"]],"asks":[]},"channel":"diff_order_book_galaeur","event":"data"}
1641343697.404463: {"data":{"timestamp":"1641343695","microtimestamp":"1641343695161902","bids":[["0.00002758","7750.87957355"]],"asks":[]},"channel":"diff_order_book_batbtc","event":"data"}
1641343697.40447: {"data":{"timestamp":"1641343695","microtimestamp":"1641343695140519","bids":[["0.38083","41095.89000000"]],"asks":[]},"channel":"diff_order_book_galaeur","event":"data"}
1641343697.404477: {"data":{"timestamp":"1641343695","microtimestamp":"1641343695041220","bids":[],"asks":[["0.73531","1800.00000000"]]},"channel":"diff_order_book_xrpeur","event":"data"}
1641343697.4044921: {"data":{"timestamp":"1641343695","microtimestamp":"1641343695332709","bids":[["0.73454","10168.63761652"],["0.73453","6030.11109498"],["0.73443","0.00000000"]],"asks":[["0.73531","0.00000000"]]},"channel":"diff_order_book_xrpeur","event":"data"}
1641343697.4045172: {"data":{"timestamp":"1641343695","microtimestamp":"1641343695512336","bids":[["0.00002831","3125.40549011"],["0.00002830","860.76352611"]],"asks":[]},"channel":"diff_order_book_batbtc","event":"data"}
1641343697.404526: {"data":{"timestamp":"1641343695","microtimestamp":"1641343695681418","bids":[["3802.51","1.73610437"],["3799.38","2.73248242"],["3798.11","0.00000000"]],"asks":[]},"channel":"diff_order_book_ethusd","event":"data"}
1641343697.4046972: {"data":{"timestamp":"1641343695","microtimestamp":"1641343695940347","bids":[["1.15989","0.00000000"]],"asks":[]},"channel":"diff_order_book_bateur","event":"data"}
1641343697.4047282: {"data":{"timestamp":"1641343695","microtimestamp":"1641343695973837","bids":[["3802.91","0.60000000"],["3802.90","3.55000000"],["3799.38","0.00000000"]],"asks":[["3815.30","0.29640800"],["3816.79","0.74118114"]]},"channel":"diff_order_book_ethusd","event":"data"}
1641343697.404754: {"data":{"timestamp":"1641343696","microtimestamp":"1641343696065131","bids":[["1.16102","1366.27762275"],["1.15989","992.85896733"]],"asks":[]},"channel":"diff_order_book_bateur","event":"data"}
1641343697.404772: {"data":{"timestamp":"1641343696","microtimestamp":"1641343696189948","bids":[],"asks":[["1.16741","0.00000000"]]},"channel":"diff_order_book_bateur","event":"data"}
1641343697.4047868: {"data":{"timestamp":"1641343696","microtimestamp":"1641343696223289","bids":[["3788.74","0.08718945"],["3788.73","0.00000000"]],"asks":[]},"channel":"diff_order_book_ethusd","event":"data"}
1641343697.404804: {"data":{"timestamp":"1641343696","microtimestamp":"1641343696314030","bids":[],"asks":[["1.16822","428.18152716"],["1.16823","0.00000000"]]},"channel":"diff_order_book_bateur","event":"data"}
1641343697.404821: {"data":{"timestamp":"1641343696","microtimestamp":"1641343696327715","bids":[["0.88424","45621.62593"],["0.88254","0.00000"],["0.88101","0.00000"],["0.88060","0.00000"]],"asks":[["0.88676","0.00000"],["0.88704","0.00000"],["0.89661","0.00000"],["0.89931","0.00000"]]},"channel":"diff_order_book_usdteur","event":"data"}
1641343697.404861: {"data":{"timestamp":"1641343696","microtimestamp":"1641343696383222","bids":[["0.99773","0.00000"],["0.99522","0.00000"],["0.98452","0.00000"]],"asks":[["0.99994","0.00000"],["0.99998","0.00000"]]},"channel":"diff_order_book_usdtusd","event":"data"}
1641343697.4048908: {"data":{"timestamp":"1641343696","microtimestamp":"1641343696438031","bids":[],"asks":[["1.16821","992.85768044"]]},"channel":"diff_order_book_bateur","event":"data"}
1641343697.404906: {"data":{"timestamp":"1641343696","microtimestamp":"1641343696499389","bids":[],"asks":[["0.99991","21883.96385"]]},"channel":"diff_order_book_usdtusd","event":"data"}
1641343697.404921: {"data":{"timestamp":"1641343696","microtimestamp":"1641343696555469","bids":[["0.88426","67960.14668"],["0.88101","38592.07046"],["0.88060","40881.21735"]],"asks":[["0.88672","9883.96385"],["0.88704","26000.00000"],["0.89659","31000.00000"],["0.89929","23000.00000"],["0.89930","0.00000"]]},"channel":"diff_order_book_usdteur","event":"data"}
1641343697.404955: {"data":{"timestamp":"1641343696","microtimestamp":"1641343696532880","bids":[["0.73454","0.00000000"],["0.73453","0.00000000"]],"asks":[["0.73532","0.00000000"]]},"channel":"diff_order_book_xrpeur","event":"data"}
1641343697.4049761: {"data":{"timestamp":"1641343696","microtimestamp":"1641343696613861","bids":[["0.99775","57128.53921"],["0.99522","51747.35234"],["0.98452","66529.87748"]],"asks":[]},"channel":"diff_order_book_usdtusd","event":"data"}
1641343697.4049962: {"data":{"timestamp":"1641343696","microtimestamp":"1641343696529802","bids":[["3802.91","0.00000000"],["3802.90","0.00000000"],["3800.27","0.00000000"]],"asks":[]},"channel":"diff_order_book_ethusd","event":"data"}
1641343697.405015: {"data":{"timestamp":"1641343696","microtimestamp":"1641343696644764","bids":[],"asks":[["0.21237","0.00000000"]]},"channel":"diff_order_book_xlmgbp","event":"data"}
1641343697.405038: {"data":{"timestamp":"1641343696","microtimestamp":"1641343696671942","bids":[],"asks":[["1.19569","0.00000000"]]},"channel":"diff_order_book_adaeur","event":"data"}
1641343697.405068: {"data":{"timestamp":"1641343696","microtimestamp":"1641343696671892","bids":[],"asks":[["0.89999","93621.49371"]]},"channel":"diff_order_book_usdteur","event":"data"}
1641343697.405087: {"data":{"timestamp":"1641343696","microtimestamp":"1641343696758765","bids":[],"asks":[["0.21237","54372.30059550"]]},"channel":"diff_order_book_xlmgbp","event":"data"}
1641343697.405102: {"data":{"timestamp":"1641343696","microtimestamp":"1641343696792107","bids":[],"asks":[["1.19569","14479.30131201"]]},"channel":"diff_order_book_adaeur","event":"data"}
1641343697.4051158: {"data":{"timestamp":"1641343696","microtimestamp":"1641343696783418","bids":[["0.73453","6030.08968952"],["0.73445","0.00000000"],["0.73443","7124.04000000"]],"asks":[["0.73533","6030.08968952"],["0.73536","3100.00000000"],["0.73576","0.00000000"],["0.73588","13190.87476705"],["0.74499","27897.23363841"]]},"channel":"diff_order_book_xrpeur","event":"data"}
1641343697.40515: {"data":{"timestamp":"1641343696","microtimestamp":"1641343696905299","bids":[],"asks":[["0.89660","0.00000"],["0.89928","93506.24301"],["0.89999","0.00000"]]},"channel":"diff_order_book_usdteur","event":"data"}
1641343697.405169: {"data":{"timestamp":"1641343696","microtimestamp":"1641343696991906","bids":[],"asks":[["0.20864","0.00000000"],["0.20869","10639.35379144"],["0.20874","9451.12456656"]]},"channel":"diff_order_book_xlmgbp","event":"data"}
1641343697.405189: {"data":{"timestamp":"1641343696","microtimestamp":"1641343696975621","bids":[["3802.90","0.60000000"],["3802.51","0.00000000"],["3800.27","4.14149328"],["3798.06","2.73248242"]],"asks":[]},"channel":"diff_order_book_ethusd","event":"data"}
1641343697.40521: {"data":{"timestamp":"1641343697","microtimestamp":"1641343697105770","bids":[],"asks":[["0.20869","0.00000000"],["0.20875","0.00000000"]]},"channel":"diff_order_book_xlmgbp","event":"data"}
1641343697.4052281: {"data":{"timestamp":"1641343697","microtimestamp":"1641343697065200","bids":[["0.73480","4900.00000000"],["0.73454","10168.63761652"]],"asks":[]},"channel":"diff_order_book_xrpeur","event":"data"}
1641343697.4052448: {"data":{"timestamp":"1641343697","microtimestamp":"1641343697145847","bids":[],"asks":[["0.89658","14566.33531"]]},"channel":"diff_order_book_usdteur","event":"data"}
1641343697.40526: {"data":{"timestamp":"1641343697","microtimestamp":"1641343697199311","bids":[["1.16052","1055.34000000"],["1.16008","0.00000000"],["1.15989","0.00000000"]],"asks":[["1.16453","1427.58000000"]]},"channel":"diff_order_book_bateur","event":"data"}
1641343697.405283: {"data":{"timestamp":"1641343697","microtimestamp":"1641343697225018","bids":[],"asks":[["0.20977","0.00000000"],["0.21030","3342.00000000"]]},"channel":"diff_order_book_xlmgbp","event":"data"}
1641343697.4053: {"data":{"timestamp":"1641343697","microtimestamp":"1641343697304817","bids":[["0.99774","0.00000"]],"asks":[["0.99992","0.00000"]]},"channel":"diff_order_book_usdtusd","event":"data"}
1641343697.405317: {"data":{"timestamp":"1641343697","microtimestamp":"1641343697336958","bids":[["1.15989","992.77501818"]],"asks":[["1.16452","2218.93000911"],["1.16454","0.00000000"]]},"channel":"diff_order_book_bateur","event":"data"}
1641343697.40534: {"data":{"timestamp":"1641343697","microtimestamp":"1641343697277443","bids":[["3798.07","2.73248242"],["3798.06","0.00000000"]],"asks":[["3805.98","9.51380100"]]},"channel":"diff_order_book_ethusd","event":"data"}
1641343697.4053602: {"data":{"timestamp":"1641343697","microtimestamp":"1641343697373272","bids":[["0.88425","0.00000"]],"asks":[["0.88671","3692.64822"],["0.88673","0.00000"]]},"channel":"diff_order_book_usdteur","event":"data"}
1641343697.40538: {"data":{"timestamp":"1641343697","microtimestamp":"1641343697419164","bids":[["0.99776","5624.74264"]],"asks":[["0.99990","5692.64822"]]},"channel":"diff_order_book_usdtusd","event":"data"}
1641343697.441119: {"data":{"timestamp":"1641343697","microtimestamp":"1641343697491889","bids":[["0.00002758","2152.54838518"]],"asks":[["0.00002916","0.00000000"],["0.00002919","0.00000000"]]},"channel":"diff_order_book_batbtc","event":"data"}
1641343697.557225: {"data":{"timestamp":"1641343697","microtimestamp":"1641343697608402","bids":[],"asks":[["0.00002914","428.64056165"],["0.00002915","0.00000000"]]},"channel":"diff_order_book_batbtc","event":"data"}
1641343697.5662029: {"data":{"timestamp":"1641343697","microtimestamp":"1641343697608656","bids":[["0.88427","16456.16574"]],"asks":[]},"channel":"diff_order_book_usdteur","event":"data"}
1641343697.6692731: {"data":{"timestamp":"1641343697","microtimestamp":"1641343697721278","bids":[["0.00002759","2152.58033827"]],"asks":[["0.00002913","838.96260840"],["0.00002914","1500.04084389"]]},"channel":"diff_order_book_batbtc","event":"data"}
1641343697.8396459: {"data":{"timestamp":"1641343697","microtimestamp":"1641343697794028","bids":[["0.73454","0.00000000"],["0.73453","0.00000000"]],"asks":[["0.73533","0.00000000"],["0.73536","0.00000000"]]},"channel":"diff_order_book_xrpeur","event":"data"}
1641343697.9588962: {"data":{"timestamp":"1641343697","microtimestamp":"1641343697924734","bids":[["3802.38","0.00000000"],["3801.88","1.31435373"],["3798.07","0.00000000"]],"asks":[]},"channel":"diff_order_book_ethusd","event":"data"}
1641343698.1247392: {"data":{"timestamp":"1641343698","microtimestamp":"1641343698087326","bids":[["0.73480","3100.00000000"],["0.73454","10168.63761652"],["0.73453","6030.09725686"]],"asks":[["0.73537","9130.41602536"],["0.73543","6029.81645152"]]},"channel":"diff_order_book_xrpeur","event":"data"}
1641343698.13248: {"data":{"timestamp":"1641343698","microtimestamp":"1641343698178059","bids":[["0.00002758","0.00000000"]],"asks":[]},"channel":"diff_order_book_batbtc","event":"data"}
1641343698.245045: {"data":{"timestamp":"1641343698","microtimestamp":"1641343698310138","bids":[["0.00002759","7750.91383076"]],"asks":[]},"channel":"diff_order_book_batbtc","event":"data"}
1641343698.27811: {"data":{"timestamp":"1641343698","microtimestamp":"1641343698322155","bids":[["1.15989","0.00000000"]],"asks":[]},"channel":"diff_order_book_bateur","event":"data"}
1641343698.3926709: {"data":{"timestamp":"1641343698","microtimestamp":"1641343698450319","bids":[["1.15989","992.83754590"]],"asks":[]},"channel":"diff_order_book_bateur","event":"data"}
1641343698.395445: {"data":{"timestamp":"1641343698","microtimestamp":"1641343698366158","bids":[["3802.91","0.36782080"],["3802.75","14.71958678"],["3800.27","7.13082215"],["3799.38","2.73248242"]],"asks":[["3805.45","14.72019264"],["3805.46","0.36679841"],["3805.99","0.00000000"]]},"channel":"diff_order_book_ethusd","event":"data"}
1641343698.446389: {"data":{"timestamp":"1641343698","microtimestamp":"1641343698418012","bids":[["0.73483","12142.73439776"],["0.73481","6028.90086502"],["0.73479","11622.10011783"],["0.73454","0.00000000"]],"asks":[["0.73528","9042.03408523"],["0.73536","6024.36658353"]]},"channel":"diff_order_book_xrpeur","event":"data"}
1641343698.450819: {"data":{"timestamp":"1641343698","microtimestamp":"1641343698508990","bids":[["0.20796","0.00000000"]],"asks":[]},"channel":"diff_order_book_xlmgbp","event":"data"}
1641343698.473894: {"data":{"timestamp":"1641343698","microtimestamp":"1641343698544148","bids":[],"asks":[["0.00002912","2784.38132796"],["0.00002917","0.00000000"]]},"channel":"diff_order_book_batbtc","event":"data"}
1641343698.475929: {"data":{"timestamp":"1641343698","microtimestamp":"1641343698540505","bids":[],"asks":[["0.38190","0.00000000"]]},"channel":"diff_order_book_galaeur","event":"data"}
1641343698.591069: {"data":{"timestamp":"1641343698","microtimestamp":"1641343698652890","bids":[],"asks":[["0.38177","1162.56488323"]]},"channel":"diff_order_book_galaeur","event":"data"}
1641343698.61124: {"data":{"timestamp":"1641343698","microtimestamp":"1641343698599396","bids":[["3800.27","0.00000000"],["3799.87","2.73248242"],["3799.38","0.00000000"],["3799.37","3.91682256"]],"asks":[["3805.44","3.30726204"],["3809.13","3.91493298"]]},"channel":"diff_order_book_ethusd","event":"data"}
1641343698.6160052: {"data":{"timestamp":"1641343698","microtimestamp":"1641343698638661","bids":[["0.20806","26597.43011231"]],"asks":[["0.20870","10638.97204493"]]},"channel":"diff_order_book_xlmgbp","event":"data"}
1641343698.6380968: {"data":{"timestamp":"1641343698","microtimestamp":"1641343698660692","bids":[["0.00002835","1191.09203756"]],"asks":[["0.00002844","1143.93905784"],["0.00002912","0.00000000"]]},"channel":"diff_order_book_batbtc","event":"data"}
1641343698.6718478: {"data":{"timestamp":"1641343698","microtimestamp":"1641343698697885","bids":[["1.16100","0.00000000"]],"asks":[["1.16497","0.00000000"]]},"channel":"diff_order_book_bateur","event":"data"}
1641343698.711968: {"data":{"timestamp":"1641343698","microtimestamp":"1641343698695631","bids":[["0.73484","1800.00000000"],["0.73480","0.00000000"],["0.73442","0.00000000"]],"asks":[["0.73543","0.00000000"],["0.73594","5277.72012704"]]},"channel":"diff_order_book_xrpeur","event":"data"}
1641343698.751997: {"data":{"timestamp":"1641343698","microtimestamp":"1641343698791357","bids":[["0.00002835","7297.66203756"]],"asks":[["0.00002846","4780.56000000"],["0.00002912","428.65682153"],["0.00002913","0.00000000"]]},"channel":"diff_order_book_batbtc","event":"data"}
1641343698.786539: {"data":{"timestamp":"1641343698","microtimestamp":"1641343698826335","bids":[["1.16113","5637.10000000"]],"asks":[["1.16509","5152.53738468"]]},"channel":"diff_order_book_bateur","event":"data"}
1641343698.868384: {"data":{"timestamp":"1641343698","microtimestamp":"1641343698910735","bids":[],"asks":[["0.00002911","839.01537620"]]},"channel":"diff_order_book_batbtc","event":"data"}
1641343698.8770308: {"data":{"timestamp":"1641343698","microtimestamp":"1641343698874953","bids":[["3800.27","5.67034412"]],"asks":[]},"channel":"diff_order_book_ethusd","event":"data"}
1641343698.934976: {"data":{"timestamp":"1641343698","microtimestamp":"1641343698929583","bids":[["0.73484","0.00000000"],["0.73483","9042.73439776"],["0.73453","0.00000000"]],"asks":[["0.73587","6051.00000000"]]},"channel":"diff_order_book_xrpeur","event":"data"}
1641343698.935116: {"data":{"timestamp":"1641343698","microtimestamp":"1641343698992761","bids":[["0.38082","0.00000000"]],"asks":[]},"channel":"diff_order_book_galaeur","event":"data"}
1641343699.050089: {"data":{"timestamp":"1641343699","microtimestamp":"1641343699109231","bids":[["0.38069","1162.66401548"]],"asks":[]},"channel":"diff_order_book_galaeur","event":"data"}
1641343699.109678: {"data":{"timestamp":"1641343699","microtimestamp":"1641343699134275","bids":[],"asks":[["1.19570","0.00000000"]]},"channel":"diff_order_book_adaeur","event":"data"}
1641343699.166162: {"data":{"timestamp":"1641343699","microtimestamp":"1641343699230931","bids":[["0.88424","0.00000"]],"asks":[["0.88674","0.00000"]]},"channel":"diff_order_book_usdteur","event":"data"}
1641343699.2004101: {"data":{"timestamp":"1641343699","microtimestamp":"1641343699181952","bids":[["0.73464","6029.81996261"],["0.73453","10168.63761652"]],"asks":[]},"channel":"diff_order_book_xrpeur","event":"data"}
1641343699.222768: {"data":{"timestamp":"1641343699","microtimestamp":"1641343699256598","bids":[],"asks":[["1.19569","0.00000000"]]},"channel":"diff_order_book_adaeur","event":"data"}
1641343699.2596228: {"data":{"timestamp":"1641343699","microtimestamp":"1641343699291075","bids":[["0.99777","198000.00000"]],"asks":[["0.99993","0.00000"]]},"channel":"diff_order_book_usdtusd","event":"data"}
1641343699.28052: {"data":{"timestamp":"1641343699","microtimestamp":"1641343699344515","bids":[],"asks":[["0.88670","9000.00000"]]},"channel":"diff_order_book_usdteur","event":"data"}
1641343699.337334: {"data":{"timestamp":"1641343699","microtimestamp":"1641343699377616","bids":[],"asks":[["1.19751","14463.06676981"]]},"channel":"diff_order_book_adaeur","event":"data"}
1641343699.373779: {"data":{"timestamp":"1641343699","microtimestamp":"1641343699406641","bids":[],"asks":[["0.99989","8122.14370"]]},"channel":"diff_order_book_usdtusd","event":"data"}
1641343699.381597: {"data":{"timestamp":"1641343699","microtimestamp":"1641343699382392","bids":[["3799.87","0.00000000"],["3788.75","0.08719311"],["3788.74","0.00000000"]],"asks":[]},"channel":"diff_order_book_ethusd","event":"data"}
1641343699.5250292: {"data":{"timestamp":"1641343699","microtimestamp":"1641343699579642","bids":[["1.16119","0.00000000"],["1.15989","0.00000000"]],"asks":[]},"channel":"diff_order_book_bateur","event":"data"}
1641343699.529292: {"data":{"id":216000477,"timestamp":"1641343699","amount":0.0792,"amount_str":"0.07920000","price":3805.44,"price_str":"3805.44","type":0,"microtimestamp":"1641343699596000","buy_order_id":1443875737346049,"sell_order_id":1443875731320832},"channel":"live_trades_ethusd","event":"trade"}
1641343699.6212962: {"data":{"timestamp":"1641343699","microtimestamp":"1641343699592062","bids":[["0.73464","0.00000000"]],"asks":[]},"channel":"diff_order_book_xrpeur","event":"data"}
1641343699.6427279: {"data":{"timestamp":"1641343699","microtimestamp":"1641343699702687","bids":[["1.15989","992.83942758"]],"asks":[]},"channel":"diff_order_book_bateur","event":"data"}
1641343699.73789: {"data":{"timestamp":"1641343699","microtimestamp":"1641343699802982","bids":[["0.88427","0.00000"]],"asks":[]},"channel":"diff_order_book_usdteur","event":"data"}
1641343699.83281: {"data":{"timestamp":"1641343699","microtimestamp":"1641343699866040","bids":[["0.99776","0.00000"]],"asks":[]},"channel":"diff_order_book_usdtusd","event":"data"}
1641343699.888475: {"data":{"timestamp":"1641343699","microtimestamp":"1641343699861762","bids":[["0.73460","0.00000000"],["0.73456","6029.88826194"]],"asks":[["0.73543","6029.81996261"]]},"channel":"diff_order_book_xrpeur","event":"data"}
1641343699.907359: {"data":{"timestamp":"1641343699","microtimestamp":"1641343699948228","bids":[],"asks":[["0.00002910","1071.59721176"],["0.00002911","0.00000000"],["0.00002914","1071.40028224"]]},"channel":"diff_order_book_batbtc","event":"data"}
1641343699.958326: {"data":{"timestamp":"1641343699","microtimestamp":"1641343699980884","bids":[["0.99778","5624.62989"]],"asks":[]},"channel":"diff_order_book_usdtusd","event":"data"}
1641343699.967764: {"data":{"timestamp":"1641343700","microtimestamp":"1641343700033302","bids":[["0.88427","6278.27890"]],"asks":[]},"channel":"diff_order_book_usdteur","event":"data"}
1641343700.020834: {"data":{"timestamp":"1641343700","microtimestamp":"1641343700065107","bids":[],"asks":[["0.00002909","839.01947300"],["0.00002910","428.69109194"]]},"channel":"diff_order_book_batbtc","event":"data"}
1641343700.063623: {"data":{"timestamp":"1641343700","microtimestamp":"1641343700100854","bids":[],"asks":[["0.99991","0.00000"]]},"channel":"diff_order_book_usdtusd","event":"data"}
1641343700.0744698: {"data":{"timestamp":"1641343700","microtimestamp":"1641343700127626","bids":[],"asks":[["1.19568","91.11535390"]]},"channel":"diff_order_book_adaeur","event":"data"}
1641343700.082322: {"data":{"timestamp":"1641343700","microtimestamp":"1641343700148956","bids":[],"asks":[["0.88672","0.00000"],["0.88704","0.00000"],["0.89659","0.00000"],["0.89928","0.00000"],["0.89929","0.00000"]]},"channel":"diff_order_book_usdteur","event":"data"}
1641343700.1086888: {"data":{"timestamp":"1641343700","microtimestamp":"1641343700101265","bids":[["3802.92","0.60000000"],["3802.91","3.91782080"],["3802.90","0.00000000"],["3799.87","2.73248242"]],"asks":[["3805.44","4.51514831"],["3809.13","2.62839156"]]},"channel":"diff_order_book_ethusd","event":"data"}
1641343700.135189: {"data":{"timestamp":"1641343700","microtimestamp":"1641343700178472","bids":[["0.00002759","5598.33349249"]],"asks":[["0.00002910","0.00000000"]]},"channel":"diff_order_book_batbtc","event":"data"}
1641343700.18912: {"data":{"timestamp":"1641343700","microtimestamp":"1641343700256214","bids":[],"asks":[["1.19751","0.00000000"]]},"channel":"diff_order_book_adaeur","event":"data"}
1641343700.196637: {"data":{"timestamp":"1641343700","microtimestamp":"1641343700268341","bids":[],"asks":[["0.89999","93448.77206"]]},"channel":"diff_order_book_usdteur","event":"data"}
1641343700.2073028: {"data":{"timestamp":"1641343700","microtimestamp":"1641343700148073","bids":[["0.73429","6051.00000000"]],"asks":[]},"channel":"diff_order_book_xrpeur","event":"data"}
1641343700.25023: {"data":{"timestamp":"1641343700","microtimestamp":"1641343700291773","bids":[["0.00002760","2152.76073261"]],"asks":[["0.00002944","428.69109194"]]},"channel":"diff_order_book_batbtc","event":"data"}
1641343700.2968068: {"data":{"timestamp":"1641343700","microtimestamp":"1641343700329484","bids":[["0.99775","0.00000"],["0.99522","0.00000"],["0.98452","0.00000"]],"asks":[["0.99994","12883.96385"],["0.99998","3000.00000"]]},"channel":"diff_order_book_usdtusd","event":"data"}
1641343700.3525918: {"data":{"timestamp":"1641343700","microtimestamp":"1641343700380465","bids":[],"asks":[["1.19567","14463.06676981"]]},"channel":"diff_order_book_adaeur","event":"data"}
1641343700.361454: {"data":{"timestamp":"1641343700","microtimestamp":"1641343700383808","bids":[],"asks":[["0.88669","7383.96385"],["0.88704","28500.00000"],["0.89657","30000.00000"],["0.89927","30000.00000"]]},"channel":"diff_order_book_usdteur","event":"data"}
1641343700.3795142: {"data":{"timestamp":"1641343700","microtimestamp":"1641343700344234","bids":[["3800.27","0.00000000"]],"asks":[]},"channel":"diff_order_book_ethusd","event":"data"}
1641343700.484415: {"data":{"timestamp":"1641343700","microtimestamp":"1641343700499567","bids":[],"asks":[["0.89658","0.00000"]]},"channel":"diff_order_book_usdteur","event":"data"}
1641343700.528543: {"data":{"timestamp":"1641343700","microtimestamp":"1641343700577633","bids":[["0.99778","139922.77176"],["0.98452","40628.91937"]],"asks":[]},"channel":"diff_order_book_usdtusd","event":"data"}
1641343700.5470989: {"data":{"timestamp":"1641343700","microtimestamp":"1641343700613535","bids":[["0.88426","0.00000"],["0.88101","0.00000"],["0.88060","0.00000"]],"asks":[["0.89662","14566.33531"],["0.89926","93448.77206"],["0.89999","0.00000"]]},"channel":"diff_order_book_usdteur","event":"data"}
1641343700.646399: {"data":{"timestamp":"1641343700","microtimestamp":"1641343700648531","bids":[["3800.27","10.00000000"]],"asks":[]},"channel":"diff_order_book_ethusd","event":"data"}
1641343700.663595: {"data":{"timestamp":"1641343700","microtimestamp":"1641343700702910","bids":[],"asks":[["1.16452","0.00000000"]]},"channel":"diff_order_book_bateur","event":"data"}
1641343700.711982: {"data":{"timestamp":"1641343700","microtimestamp":"1641343700737223","bids":[["0.88428","11980.86500"],["0.88252","56089.38041"],["0.88101","85697.09764"],["0.88060","19872.81399"]],"asks":[]},"channel":"diff_order_book_usdteur","event":"data"}
1641343700.779766: {"data":{"timestamp":"1641343700","microtimestamp":"1641343700825150","bids":[["1.15989","0.00000000"]],"asks":[["1.16412","2218.93000911"]]},"channel":"diff_order_book_bateur","event":"data"}
1641343700.825681: {"data":{"timestamp":"1641343700","microtimestamp":"1641343700871386","bids":[["0.00002757","0.00000000"]],"asks":[]},"channel":"diff_order_book_batbtc","event":"data"}
1641343700.868417: {"data":{"timestamp":"1641343700","microtimestamp":"1641343700931359","bids":[["0.99778","134298.14187"]],"asks":[]},"channel":"diff_order_book_usdtusd","event":"data"}
1641343700.8947031: {"data":{"timestamp":"1641343700","microtimestamp":"1641343700951683","bids":[["1.15989","992.84939350"]],"asks":[]},"channel":"diff_order_book_bateur","event":"data"}
1641343700.983352: {"data":{"timestamp":"1641343701","microtimestamp":"1641343701047237","bids":[],"asks":[["0.99990","0.00000"]]},"channel":"diff_order_book_usdtusd","event":"data"}
1641343701.016103: {"data":{"timestamp":"1641343701","microtimestamp":"1641343701079183","bids":[],"asks":[["1.16436","95.42846932"]]},"channel":"diff_order_book_bateur","event":"data"}
1641343701.0586529: {"data":{"timestamp":"1641343701","microtimestamp":"1641343701093866","bids":[["0.88427","0.00000"]],"asks":[["0.88671","0.00000"]]},"channel":"diff_order_book_usdteur","event":"data"}
1641343701.097468: {"data":{"timestamp":"1641343701","microtimestamp":"1641343701162576","bids":[["0.99779","5624.57352"]],"asks":[["0.99988","5692.64822"]]},"channel":"diff_order_book_usdtusd","event":"data"}
1641343701.174644: {"data":{"timestamp":"1641343701","microtimestamp":"1641343701210566","bids":[],"asks":[["0.88668","3692.64822"]]},"channel":"diff_order_book_usdteur","event":"data"}
1641343701.2811022: {"data":{"timestamp":"1641343701","microtimestamp":"1641343701332806","bids":[["0.00002759","0.00000000"]],"asks":[]},"channel":"diff_order_book_batbtc","event":"data"}
1641343701.288637: {"data":{"timestamp":"1641343701","microtimestamp":"1641343701327284","bids":[["0.88252","74844.41563"]],"asks":[]},"channel":"diff_order_book_usdteur","event":"data"}
1641343701.347336: {"data":{"timestamp":"1641343701","microtimestamp":"1641343701330962","bids":[["0.73429","0.00000000"]],"asks":[["0.73533","6030.06936909"],["0.73543","0.00000000"],["0.73587","0.00000000"]]},"channel":"diff_order_book_xrpeur","event":"data"}
1641343701.395481: {"data":{"timestamp":"1641343701","microtimestamp":"1641343701446897","bids":[["0.00002760","7751.72793876"]],"asks":[]},"channel":"diff_order_book_batbtc","event":"data"}
1641343701.466626: {"data":{"timestamp":"1641343701","microtimestamp":"1641343701463238","bids":[["3802.92","0.00000000"],["3802.91","0.36782080"],["3802.58","2.13597264"],["3800.27","6.99034412"],["3799.87","0.00000000"],["3799.38","2.73248242"]],"asks":[["3805.44","12.56951035"],["3806.26","0.00000000"]]},"channel":"diff_order_book_ethusd","event":"data"}
1641343701.61917: {"data":{"timestamp":"1641343701","microtimestamp":"1641343701585628","bids":[["0.73440","6051.00000000"]],"asks":[]},"channel":"diff_order_book_xrpeur","event":"data"}
1641343701.710766: {"data":{"timestamp":"1641343701","microtimestamp":"1641343701731660","bids":[],"asks":[["1.17446","0.00000000"]]},"channel":"diff_order_book_adaeur","event":"data"}
1641343701.7420318: {"data":{"timestamp":"1641343701","microtimestamp":"1641343701770944","bids":[["0.20797","0.00000000"]],"asks":[["0.20874","3595.53928400"]]},"channel":"diff_order_book_xlmgbp","event":"data"}
1641343701.7859042: {"data":{"timestamp":"1641343701","microtimestamp":"1641343701749481","bids":[["3802.92","0.01461245"],["3800.27","5.35482215"],["3799.87","2.73248242"],["3799.38","0.00000000"]],"asks":[]},"channel":"diff_order_book_ethusd","event":"data"}
1641343701.8253682: {"data":{"timestamp":"1641343701","microtimestamp":"1641343701853050","bids":[],"asks":[["1.17481","11932.43465114"]]},"channel":"diff_order_book_adaeur","event":"data"}
1641343701.856909: {"data":{"timestamp":"1641343701","microtimestamp":"1641343701903928","bids":[],"asks":[["0.00002908","1071.47491300"],["0.00002914","0.00000000"]]},"channel":"diff_order_book_batbtc","event":"data"}
1641343701.8570309: {"data":{"timestamp":"1641343701","microtimestamp":"1641343701884391","bids":[["0.20807","19284.19051992"]],"asks":[["0.20869","5855.58528256"]]},"channel":"diff_order_book_xlmgbp","event":"data"}
1641343701.890121: {"data":{"timestamp":"1641343701","microtimestamp":"1641343701860870","bids":[["0.73443","0.00000000"]],"asks":[["0.73588","0.00000000"],["0.73592","6051.00000000"]]},"channel":"diff_order_book_xrpeur","event":"data"}
1641343701.925353: {"data":{"timestamp":"1641343701","microtimestamp":"1641343701961215","bids":[["1.15989","0.00000000"]],"asks":[["1.17029","0.00000000"]]},"channel":"diff_order_book_bateur","event":"data"}
1641343701.9269068: {"data":{"timestamp":"1641343701","microtimestamp":"1641343701997595","bids":[],"asks":[["0.21030","0.00000000"]]},"channel":"diff_order_book_xlmgbp","event":"data"}
1641343701.968713: {"data":{"timestamp":"1641343702","microtimestamp":"1641343702019003","bids":[["0.00002760","7772.96453296"]],"asks":[["0.00002907","839.02897878"],["0.00002908","0.00000000"],["0.00002909","0.00000000"]]},"channel":"diff_order_book_batbtc","event":"data"}
1641343702.0480561: {"data":{"timestamp":"1641343702","microtimestamp":"1641343702084150","bids":[["1.15989","992.85350316"]],"asks":[["1.16834","2782.86307640"]]},"channel":"diff_order_book_bateur","event":"data"}
1641343702.0481799: {"data":{"timestamp":"1641343702","microtimestamp":"1641343702113417","bids":[],"asks":[["0.20977","3342.00000000"]]},"channel":"diff_order_book_xlmgbp","event":"data"}
1641343702.068374: {"data":{"timestamp":"1641343702","microtimestamp":"1641343702030392","bids":[["3802.90","0.60000000"],["3799.87","0.00000000"],["3792.71","0.00000000"]],"asks":[]},"channel":"diff_order_book_ethusd","event":"data"}
1641343702.0822039: {"data":{"timestamp":"1641343702","microtimestamp":"1641343702137112","bids":[],"asks":[["0.00002908","428.67630554"]]},"channel":"diff_order_book_batbtc","event":"data"}
1641343702.197515: {"data":{"timestamp":"1641343702","microtimestamp":"1641343702252692","bids":[],"asks":[["0.00002908","0.00000000"],["0.00002944","857.36739748"]]},"channel":"diff_order_book_batbtc","event":"data"}
1641343702.3238568: {"data":{"timestamp":"1641343702","microtimestamp":"1641343702366172","bids":[["0.88252","56089.38041"]],"asks":[]},"channel":"diff_order_book_usdteur","event":"data"}
1641343702.33009: {"data":{"timestamp":"1641343702","microtimestamp":"1641343702151699","bids":[["0.73442","6051.00000000"],["0.73441","12450.24000000"],["0.73440","0.00000000"]],"asks":[["0.73588","13190.87476705"]]},"channel":"diff_order_book_xrpeur","event":"data"}
1641343702.3516538: {"data":{"timestamp":"1641343702","microtimestamp":"1641343702315645","bids":[["3800.27","5.67034246"],["3790.49","0.01341637"],["3790.48","0.00000000"],["3788.75","0.03354093"],["3788.68","0.01341637"]],"asks":[]},"channel":"diff_order_book_ethusd","event":"data"}
1641343702.428253: {"data":{"timestamp":"1641343702","microtimestamp":"1641343702482759","bids":[],"asks":[["0.00002912","0.00000000"],["0.00002944","428.67630554"]]},"channel":"diff_order_book_batbtc","event":"data"}
1641343702.437682: {"data":{"timestamp":"1641343702","microtimestamp":"1641343702480302","bids":[["0.88429","4016.43543"],["0.88253","13597.27148"]],"asks":[]},"channel":"diff_order_book_usdteur","event":"data"}
1641343702.5419772: {"data":{"timestamp":"1641343702","microtimestamp":"1641343702600134","bids":[],"asks":[["0.00002906","428.68600309"]]},"channel":"diff_order_book_batbtc","event":"data"}
1641343702.6589298: {"data":{"timestamp":"1641343702","microtimestamp":"1641343702716419","bids":[],"asks":[["0.00002906","1500.21284869"]]},"channel":"diff_order_book_batbtc","event":"data"}
1641343702.777365: {"data":{"timestamp":"1641343702","microtimestamp":"1641343702839882","bids":[],"asks":[["1.16395","2218.93000911"],["1.16412","0.00000000"]]},"channel":"diff_order_book_bateur","event":"data"}
1641343702.888617: {"data":{"timestamp":"1641343702","microtimestamp":"1641343702949024","bids":[["0.00002831","2286.37110419"]],"asks":[["0.00002907","0.00000000"]]},"channel":"diff_order_book_batbtc","event":"data"}
1641343702.9420328: {"data":{"timestamp":"1641343702","microtimestamp":"1641343702963032","bids":[["1.15989","0.00000000"]],"asks":[["1.16821","0.00000000"]]},"channel":"diff_order_book_bateur","event":"data"}
1641343702.9832408: {"data":{"timestamp":"1641343703","microtimestamp":"1641343703019862","bids":[["0.38083","0.00000000"],["0.38070","71724.51000000"]],"asks":[]},"channel":"diff_order_book_galaeur","event":"data"}
1641343702.998592: {"data":{"timestamp":"1641343703","microtimestamp":"1641343703063881","bids":[["0.00002831","3125.39635876"]],"asks":[["0.00002905","839.02547341"]]},"channel":"diff_order_book_batbtc","event":"data"}
1641343703.0466838: {"data":{"timestamp":"1641343703","microtimestamp":"1641343703008277","bids":[["3802.93","0.60000000"],["3802.92","3.56461245"],["3802.90","0.00000000"]],"asks":[]},"channel":"diff_order_book_ethusd","event":"data"}
1641343703.0615711: {"data":{"timestamp":"1641343703","microtimestamp":"1641343703089792","bids":[["1.15990","992.84908621"]],"asks":[["1.16821","992.84935281"]]},"channel":"diff_order_book_bateur","event":"data"}
1641343703.210536: {"data":{"timestamp":"1641343703","microtimestamp":"1641343703243194","bids":[["0.37987","0.00000000"]],"asks":[]},"channel":"diff_order_book_galaeur","event":"data"}
1641343703.3147259: {"data":{"timestamp":"1641343703","microtimestamp":"1641343703318655","bids":[["0.73462","6030.01659475"]],"asks":[["0.73528","12142.03408523"]]},"channel":"diff_order_book_xrpeur","event":"data"}
1641343703.324765: {"data":{"timestamp":"1641343703","microtimestamp":"1641343703355526","bids":[["0.37910","4651.48461615"]],"asks":[["0.38177","0.00000000"]]},"channel":"diff_order_book_galaeur","event":"data"}
1641343703.37489: {"data":{"timestamp":"1641343703","microtimestamp":"1641343703333373","bids":[["3800.27","0.00000000"]],"asks":[]},"channel":"diff_order_book_ethusd","event":"data"}
1641343703.4400551: {"data":{"timestamp":"1641343703","microtimestamp":"1641343703467999","bids":[],"asks":[["0.38165","1162.94444520"]]},"channel":"diff_order_book_galaeur","event":"data"}
1641343703.507703: {"data":{"timestamp":"1641343703","microtimestamp":"1641343703580049","bids":[["0.99779","0.00000"]],"asks":[]},"channel":"diff_order_book_usdtusd","event":"data"}
1641343703.556226: {"data":{"timestamp":"1641343703","microtimestamp":"1641343703580489","bids":[],"asks":[["0.38163","2622.60000526"],["0.38164","15834.58496090"],["0.38172","0.00000000"],["0.38173","0.00000000"]]},"channel":"diff_order_book_galaeur","event":"data"}
1641343703.622308: {"data":{"timestamp":"1641343703","microtimestamp":"1641343703651014","bids":[["0.00002830","0.00000000"],["0.00002761","861.01555197"]],"asks":[]},"channel":"diff_order_book_batbtc","event":"data"}
1641343703.6428711: {"data":{"timestamp":"1641343703","microtimestamp":"1641343703612875","bids":[["3800.27","5.67034132"]],"asks":[]},"channel":"diff_order_book_ethusd","event":"data"}
1641343703.674357: {"data":{"timestamp":"1641343703","microtimestamp":"1641343703706946","bids":[["0.99946","1242.09954"],["0.99779","2505.53723"]],"asks":[]},"channel":"diff_order_book_usdtusd","event":"data"}
1641343703.7377: {"data":{"timestamp":"1641343703","microtimestamp":"1641343703766176","bids":[["0.00002760","21.23659420"]],"asks":[]},"channel":"diff_order_book_batbtc","event":"data"}
1641343703.8069062: {"data":{"timestamp":"1641343703","microtimestamp":"1641343703783049","bids":[["0.73462","0.00000000"],["0.73451","6030.32042693"]],"asks":[["0.73528","9042.03408523"]]},"channel":"diff_order_book_xrpeur","event":"data"}
1641343703.851403: {"data":{"timestamp":"1641343703","microtimestamp":"1641343703880885","bids":[["0.00002761","8612.92882837"]],"asks":[]},"channel":"diff_order_book_batbtc","event":"data"}
1641343703.9137878: {"data":{"timestamp":"1641343703","microtimestamp":"1641343703865625","bids":[["3801.78","0.00000000"],["3801.53","0.40000000"],["3800.27","0.00000000"]],"asks":[["3806.35","0.40000000"],["3806.60","0.00000000"]]},"channel":"diff_order_book_ethusd","event":"data"}
1641343704.0716941: {"data":{"timestamp":"1641343704","microtimestamp":"1641343704039964","bids":[],"asks":[["0.73528","15072.50293137"],["0.73537","3100.00000000"],["0.73580","18091.40653842"],["0.73592","0.00000000"],["0.73593","6051.00000000"],["0.73598","0.00000000"]]},"channel":"diff_order_book_xrpeur","event":"data"}
1641343704.082175: {"data":{"timestamp":"1641343704","microtimestamp":"1641343704110151","bids":[["0.00002831","2286.37110419"]],"asks":[]},"channel":"diff_order_book_batbtc","event":"data"}
1641343704.159734: {"data":{"timestamp":"1641343704","microtimestamp":"1641343704218119","bids":[],"asks":[["0.88670","0.00000"]]},"channel":"diff_order_book_usdteur","event":"data"}
1641343704.1967518: {"data":{"timestamp":"1641343704","microtimestamp":"1641343704223391","bids":[["0.00002830","839.02627126"]],"asks":[]},"channel":"diff_order_book_batbtc","event":"data"}
1641343704.249321: {"data":{"timestamp":"1641343704","microtimestamp":"1641343704289881","bids":[],"asks":[["0.99989","0.00000"]]},"channel":"diff_order_book_usdtusd","event":"data"}
1641343704.2673862: {"data":{"timestamp":"1641343704","microtimestamp":"1641343704329684","bids":[],"asks":[["1.16435","239.58000000"],["1.16453","0.00000000"]]},"channel":"diff_order_book_bateur","event":"data"}
1641343704.373476: {"data":{"timestamp":"1641343704","microtimestamp":"1641343704324036","bids":[["3800.27","5.35482215"]],"asks":[]},"channel":"diff_order_book_ethusd","event":"data"}
1641343704.3886771: {"data":{"timestamp":"1641343704","microtimestamp":"1641343704459101","bids":[],"asks":[["0.88667","9000.00000"],["0.88669","0.00000"],["0.88704","0.00000"],["0.89657","0.00000"],["0.89927","0.00000"]]},"channel":"diff_order_book_usdteur","event":"data"}
1641343704.477817: {"data":{"timestamp":"1641343704","microtimestamp":"1641343704530203","bids":[],"asks":[["0.99993","8122.14370"]]},"channel":"diff_order_book_usdtusd","event":"data"}
1641343704.503038: {"data":{"timestamp":"1641343704","microtimestamp":"1641343704574924","bids":[],"asks":[["0.88667","15383.96385"],["0.88704","29500.00000"],["0.89661","42500.00000"],["0.89925","17500.00000"],["0.89926","0.00000"]]},"channel":"diff_order_book_usdteur","event":"data"}
1641343704.592723: {"data":{"timestamp":"1641343704","microtimestamp":"1641343704645033","bids":[["0.99778","0.00000"],["0.98452","0.00000"]],"asks":[]},"channel":"diff_order_book_usdtusd","event":"data"}
1641343704.62065: {"data":{"timestamp":"1641343704","microtimestamp":"1641343704689050","bids":[],"asks":[["0.89999","94059.07571"]]},"channel":"diff_order_book_usdteur","event":"data"}
1641343704.620764: {"data":{"timestamp":"1641343704","microtimestamp":"1641343704654331","bids":[],"asks":[["0.21237","0.00000000"]]},"channel":"diff_order_book_xlmgbp","event":"data"}
1641343704.648631: {"data":{"timestamp":"1641343704","microtimestamp":"1641343704623473","bids":[["3800.27","0.00000000"]],"asks":[["3805.98","0.00000000"],["3805.99","12.14928000"]]},"channel":"diff_order_book_ethusd","event":"data"}
1641343704.7062058: {"data":{"timestamp":"1641343704","microtimestamp":"1641343704758112","bids":[["0.99780","130286.63058"],["0.98452","44691.82749"]],"asks":[]},"channel":"diff_order_book_usdtusd","event":"data"}
1641343704.719029: {"data":{"timestamp":"1641343704","microtimestamp":"1641343704737238","bids":[],"asks":[["1.19567","29087.57222315"]]},"channel":"diff_order_book_adaeur","event":"data"}
1641343704.7339551: {"data":{"timestamp":"1641343704","microtimestamp":"1641343704802387","bids":[],"asks":[["0.89662","0.00000"],["0.89924","94040.69785"],["0.89999","0.00000"]]},"channel":"diff_order_book_usdteur","event":"data"}
1641343704.7365031: {"data":{"timestamp":"1641343704","microtimestamp":"1641343704768755","bids":[],"asks":[["0.21237","108877.11260460"]]},"channel":"diff_order_book_xlmgbp","event":"data"}
1641343704.8214521: {"data":{"timestamp":"1641343704","microtimestamp":"1641343704873079","bids":[["0.99946","0.00000"],["0.99779","0.00000"]],"asks":[["0.99988","0.00000"]]},"channel":"diff_order_book_usdtusd","event":"data"}
1641343704.838308: {"data":{"timestamp":"1641343704","microtimestamp":"1641343704841375","bids":[],"asks":[["0.74499","57523.68455420"]]},"channel":"diff_order_book_xrpeur","event":"data"}
1641343704.847748: {"data":{"timestamp":"1641343704","microtimestamp":"1641343704916179","bids":[["0.88428","0.00000"],["0.88252","0.00000"],["0.88101","0.00000"]],"asks":[]},"channel":"diff_order_book_usdteur","event":"data"}
1641343704.873038: {"data":{"timestamp":"1641343704","microtimestamp":"1641343704926623","bids":[["0.38069","0.00000000"]],"asks":[]},"channel":"diff_order_book_galaeur","event":"data"}
1641343704.925935: {"data":{"timestamp":"1641343704","microtimestamp":"1641343704915964","bids":[["3800.27","10.00000000"]],"asks":[]},"channel":"diff_order_book_ethusd","event":"data"}
1641343704.935565: {"data":{"timestamp":"1641343704","microtimestamp":"1641343704989640","bids":[["0.99779","5624.57352"],["0.99777","0.00000"]],"asks":[["0.99993","13814.79192"]]},"channel":"diff_order_book_usdtusd","event":"data"}
1641343704.962327: {"data":{"timestamp":"1641343705","microtimestamp":"1641343705030676","bids":[["0.88254","124180.70490"],["0.88101","28376.52240"]],"asks":[["0.89660","14566.33531"]]},"channel":"diff_order_book_usdteur","event":"data"}
1641343704.988458: {"data":{"timestamp":"1641343705","microtimestamp":"1641343705038508","bids":[["0.38056","1163.06361528"]],"asks":[]},"channel":"diff_order_book_galaeur","event":"data"}
1641343705.0513332: {"data":{"timestamp":"1641343705","microtimestamp":"1641343705103903","bids":[["0.99781","198000.00000"]],"asks":[]},"channel":"diff_order_book_usdtusd","event":"data"}
1641343705.18941: {"data":{"timestamp":"1641343705","microtimestamp":"1641343705261190","bids":[["0.00002830","839.01734586"]],"asks":[]},"channel":"diff_order_book_batbtc","event":"data"}
1641343705.1936: {"data":{"timestamp":"1641343705","microtimestamp":"1641343705168999","bids":[["3802.91","0.00000000"],["3802.75","0.00000000"],["3799.37","2.62881192"]],"asks":[["3805.44","11.28242408"]]},"channel":"diff_order_book_ethusd","event":"data"}
1641343705.541933: {"data":{"timestamp":"1641343705","microtimestamp":"1641343705504345","bids":[["0.73483","0.00000000"],["0.73471","9039.32415250"],["0.73461","6030.09819156"],["0.73451","0.00000000"]],"asks":[["0.73528","0.00000000"],["0.73535","9039.99023512"],["0.73540","6030.09819156"]]},"channel":"diff_order_book_xrpeur","event":"data"}
1641343705.565313: {"data":{"timestamp":"1641343705","microtimestamp":"1641343705595121","bids":[],"asks":[["1.19568","0.00000000"]]},"channel":"diff_order_book_adaeur","event":"data"}
1641343705.5707362: {"data":{"timestamp":"1641343705","microtimestamp":"1641343705597243","bids":[],"asks":[["1.16834","0.00000000"],["1.17029","2782.53299828"]]},"channel":"diff_order_book_bateur","event":"data"}
1641343705.655274: {"data":{"timestamp":"1641343705","microtimestamp":"1641343705635626","bids":[["3802.63","0.36769791"],["3802.58","0.00000000"],["3802.52","14.72129113"],["3802.42","1.31416087"],["3801.88","0.00000000"],["3799.86","6.28655770"]],"asks":[["3806.59","2.60104311"],["3807.06","0.00000000"]]},"channel":"diff_order_book_ethusd","event":"data"}
1641343705.683056: {"data":{"timestamp":"1641343705","microtimestamp":"1641343705722212","bids":[],"asks":[["1.19567","0.00000000"],["1.19751","29087.57222315"]]},"channel":"diff_order_book_adaeur","event":"data"}
1641343705.924201: {"data":{"timestamp":"1641343705","microtimestamp":"1641343705910017","bids":[["3792.97","0.01341489"],["3790.49","0.00000000"],["3788.69","0.08719953"],["3788.68","0.00000000"]],"asks":[["3807.16","25.00000000"]]},"channel":"diff_order_book_ethusd","event":"data"}
1641343706.051957: {"data":{"timestamp":"1641343706","microtimestamp":"1641343706078230","bids":[["0.88253","0.00000"]],"asks":[["0.88668","0.00000"]]},"channel":"diff_order_book_usdteur","event":"data"}
1641343706.0589619: {"data":{"timestamp":"1641343706","microtimestamp":"1641343706035568","bids":[],"asks":[["0.73531","3100.00000000"],["0.73532","1800.00000000"],["0.73533","9130.06936909"],["0.73537","0.00000000"]]},"channel":"diff_order_book_xrpeur","event":"data"}
1641343706.082442: {"data":{"timestamp":"1641343706","microtimestamp":"1641343706151099","bids":[["0.99779","0.00000"]],"asks":[["0.99993","8122.14370"]]},"channel":"diff_order_book_usdtusd","event":"data"}
1641343706.103436: {"data":{"timestamp":"1641343706","microtimestamp":"1641343706169318","bids":[["0.00002761","6460.00120474"]],"asks":[]},"channel":"diff_order_book_batbtc","event":"data"}
1641343706.1652758: {"data":{"timestamp":"1641343706","microtimestamp":"1641343706192152","bids":[["0.88429","0.00000"]],"asks":[]},"channel":"diff_order_book_usdteur","event":"data"}
1641343706.217128: {"data":{"timestamp":"1641343706","microtimestamp":"1641343706285057","bids":[["0.00002762","2152.92762363"]],"asks":[]},"channel":"diff_order_book_batbtc","event":"data"}
1641343706.248259: {"data":{"timestamp":"1641343706","microtimestamp":"1641343706268533","bids":[["0.99782","5624.40442"]],"asks":[["0.99992","5692.64822"]]},"channel":"diff_order_book_usdtusd","event":"data"}
1641343706.281893: {"data":{"timestamp":"1641343706","microtimestamp":"1641343706306077","bids":[["0.88255","18754.39769"]],"asks":[["0.88666","3692.64822"]]},"channel":"diff_order_book_usdteur","event":"data"}
1641343706.3311949: {"data":{"timestamp":"1641343706","microtimestamp":"1641343706398377","bids":[["0.00002831","3125.39033612"],["0.00002830","0.00000000"],["0.00002762","0.00000000"],["0.00002761","861.01555197"]],"asks":[["0.00002904","4285.36554659"],["0.00002906","0.00000000"],["0.00002944","0.00000000"]]},"channel":"diff_order_book_batbtc","event":"data"}
1641343706.44837: {"data":{"timestamp":"1641343706","microtimestamp":"1641343706513167","bids":[["0.00002762","861.04309650"]],"asks":[["0.00002905","0.00000000"]]},"channel":"diff_order_book_batbtc","event":"data"}
1641343706.458357: {"data":{"timestamp":"1641343706","microtimestamp":"1641343706466935","bids":[["3802.93","0.00000000"],["3802.92","0.01461245"],["3802.90","0.60000000"]],"asks":[]},"channel":"diff_order_book_ethusd","event":"data"}
1641343706.458761: {"data":{"timestamp":"1641343706","microtimestamp":"1641343706446666","bids":[],"asks":[["0.73532","0.00000000"]]},"channel":"diff_order_book_xrpeur","event":"data"}
1641343706.566327: {"data":{"timestamp":"1641343706","microtimestamp":"1641343706633571","bids":[["0.00002761","3013.94317560"]],"asks":[["0.00002903","839.02119684"]]},"channel":"diff_order_book_batbtc","event":"data"}
1641343706.733697: {"data":{"timestamp":"1641343706","microtimestamp":"1641343706711029","bids":[],"asks":[["3807.16","0.00000000"]]},"channel":"diff_order_book_ethusd","event":"data"}
1641343706.792654: {"data":{"timestamp":"1641343706","microtimestamp":"1641343706857947","bids":[["0.00002761","2152.92762363"]],"asks":[]},"channel":"diff_order_book_batbtc","event":"data"}
1641343706.8132522: {"data":{"timestamp":"1641343706","microtimestamp":"1641343706833735","bids":[],"asks":[["1.19566","91.11535390"],["1.19751","0.00000000"]]},"channel":"diff_order_book_adaeur","event":"data"}
1641343706.907129: {"data":{"timestamp":"1641343706","microtimestamp":"1641343706971243","bids":[["0.00002762","6460.17959217"]],"asks":[]},"channel":"diff_order_book_batbtc","event":"data"}
1641343706.9262269: {"data":{"timestamp":"1641343706","microtimestamp":"1641343706955655","bids":[],"asks":[["1.19565","29296.64845131"]]},"channel":"diff_order_book_adaeur","event":"data"}
1641343707.02094: {"data":{"timestamp":"1641343707","microtimestamp":"1641343707087605","bids":[["0.00002835","1191.09203756"],["0.00002762","3013.97072013"]],"asks":[["0.00002846","0.00000000"]]},"channel":"diff_order_book_batbtc","event":"data"}
1641343707.049268: {"data":{"timestamp":"1641343707","microtimestamp":"1641343707101692","bids":[["1.16113","0.00000000"]],"asks":[["1.16509","98.69738468"]]},"channel":"diff_order_book_bateur","event":"data"}
1641343707.1350179: {"data":{"timestamp":"1641343707","microtimestamp":"1641343707201245","bids":[["0.00002834","6827.68434124"]],"asks":[["0.00002845","5981.87539196"]]},"channel":"diff_order_book_batbtc","event":"data"}
1641343707.1635919: {"data":{"timestamp":"1641343707","microtimestamp":"1641343707222016","bids":[["1.16066","5895.30000000"]],"asks":[["1.16462","4906.49000000"]]},"channel":"diff_order_book_bateur","event":"data"}
1641343707.2177842: {"data":{"timestamp":"1641343707","microtimestamp":"1641343707191775","bids":[["0.73482","1800.00000000"],["0.73463","6029.92800464"],["0.73461","0.00000000"]],"asks":[]},"channel":"diff_order_book_xrpeur","event":"data"}
1641343707.241347: {"data":{"timestamp":"1641343707","microtimestamp":"1641343707190380","bids":[["3802.62","2.42918104"]],"asks":[["3807.06","25.00000000"]]},"channel":"diff_order_book_ethusd","event":"data"}
1641343707.273659: {"data":{"timestamp":"1641343707","microtimestamp":"1641343707325038","bids":[["1.17142","0.00000000"]],"asks":[]},"channel":"diff_order_book_adaeur","event":"data"}
1641343707.3901062: {"data":{"timestamp":"1641343707","microtimestamp":"1641343707453433","bids":[["1.17178","2644.15181203"]],"asks":[["1.17690","0.00000000"],["1.17713","4507.00000000"]]},"channel":"diff_order_book_adaeur","event":"data"}
1641343707.416641: {"data":{"timestamp":"1641343707","microtimestamp":"1641343707446420","bids":[["0.00002831","2286.37110419"]],"asks":[]},"channel":"diff_order_book_batbtc","event":"data"}
1641343707.504537: {"data":{"timestamp":"1641343707","microtimestamp":"1641343707464202","bids":[["0.73482","0.00000000"]],"asks":[]},"channel":"diff_order_book_xrpeur","event":"data"}
1641343707.50971: {"data":{"timestamp":"1641343707","microtimestamp":"1641343707458761","bids":[["3802.92","0.00000000"],["3802.62","0.00000000"]],"asks":[]},"channel":"diff_order_book_ethusd","event":"data"}
1641343707.53196: {"data":{"timestamp":"1641343707","microtimestamp":"1641343707561094","bids":[["0.00002830","839.03535514"]],"asks":[]},"channel":"diff_order_book_batbtc","event":"data"}
1641343707.5465941: {"data":{"timestamp":"1641343707","microtimestamp":"1641343707591505","bids":[],"asks":[["0.88667","9000.00000"],["0.88704","0.00000"],["0.89661","0.00000"],["0.89925","0.00000"]]},"channel":"diff_order_book_usdteur","event":"data"}
1641343707.553316: {"data":{"timestamp":"1641343707","microtimestamp":"1641343707574052","bids":[],"asks":[["1.17713","0.00000000"]]},"channel":"diff_order_book_adaeur","event":"data"}
1641343707.598606: {"data":{"timestamp":"1641343707","microtimestamp":"1641343707637348","bids":[["1.16102","0.00000000"],["1.16052","1292.94000000"]],"asks":[]},"channel":"diff_order_book_bateur","event":"data"}
1641343707.627488: {"data":{"timestamp":"1641343707","microtimestamp":"1641343707658647","bids":[],"asks":[["0.99994","0.00000"],["0.99998","0.00000"]]},"channel":"diff_order_book_usdtusd","event":"data"}
1641343707.661898: {"data":{"timestamp":"1641343707","microtimestamp":"1641343707707441","bids":[],"asks":[["0.89924","0.00000"]]},"channel":"diff_order_book_usdteur","event":"data"}
1641343707.668203: {"data":{"timestamp":"1641343707","microtimestamp":"1641343707694858","bids":[],"asks":[["1.18273","4507.00000000"]]},"channel":"diff_order_book_adaeur","event":"data"}
1641343707.7288609: {"data":{"timestamp":"1641343707","microtimestamp":"1641343707713240","bids":[["3802.90","0.00000000"],["3802.52","0.00000000"],["3802.42","0.00000000"],["3801.89","1.31434502"],["3800.27","0.00000000"],["3799.38","2.73248242"],["3792.97","0.00000000"]],"asks":[["3805.43","3.55000000"],["3807.06","0.00000000"]]},"channel":"diff_order_book_ethusd","event":"data"}
1641343707.775167: {"data":{"timestamp":"1641343707","microtimestamp":"1641343707821994","bids":[],"asks":[["0.88665","5383.96385"],["0.89660","0.00000"],["0.89923","12500.00000"],["0.89999","94171.00734"]]},"channel":"diff_order_book_usdteur","event":"data"}
1641343707.783015: {"data":{"timestamp":"1641343707","microtimestamp":"1641343707815797","bids":[],"asks":[["1.17439","0.00000000"]]},"channel":"diff_order_book_adaeur","event":"data"}
1641343707.857449: {"data":{"timestamp":"1641343707","microtimestamp":"1641343707891905","bids":[["0.99948","0.00000"],["0.99780","0.00000"],["0.98452","0.00000"]],"asks":[["0.99991","21883.96385"]]},"channel":"diff_order_book_usdtusd","event":"data"}
1641343707.890505: {"data":{"timestamp":"1641343707","microtimestamp":"1641343707946444","bids":[],"asks":[["0.88704","30500.00000"],["0.89659","41500.00000"]]},"channel":"diff_order_book_usdteur","event":"data"}
1641343707.89659: {"data":{"timestamp":"1641343707","microtimestamp":"1641343707955007","bids":[],"asks":[["1.17466","1888.53690591"]]},"channel":"diff_order_book_adaeur","event":"data"}
1641343707.97202: {"data":{"timestamp":"1641343708","microtimestamp":"1641343708006124","bids":[["0.98452","42152.50743"]],"asks":[]},"channel":"diff_order_book_usdtusd","event":"data"}
1641343707.980587: {"data":{"timestamp":"1641343707","microtimestamp":"1641343707950205","bids":[],"asks":[["0.73535","0.00000000"]]},"channel":"diff_order_book_xrpeur","event":"data"}
1641343708.0038059: {"data":{"timestamp":"1641343707","microtimestamp":"1641343707957960","bids":[["3802.39","0.00000000"],["3802.34","2.10800000"],["3802.33","21.19170698"],["3800.27","5.35482215"],["3799.38","0.00000000"]],"asks":[]},"channel":"diff_order_book_ethusd","event":"data"}
1641343708.003905: {"data":{"timestamp":"1641343708","microtimestamp":"1641343708062245","bids":[["0.88254","0.00000"],["0.88101","0.00000"],["0.88060","0.00000"]],"asks":[["0.89662","14566.33531"],["0.89999","0.00000"]]},"channel":"diff_order_book_usdteur","event":"data"}
1641343708.087544: {"data":{"timestamp":"1641343708","microtimestamp":"1641343708122432","bids":[["0.99948","3070.65872"],["0.99783","129781.62612"]],"asks":[]},"channel":"diff_order_book_usdtusd","event":"data"}
1641343708.119442: {"data":{"timestamp":"1641343708","microtimestamp":"1641343708178513","bids":[],"asks":[["0.89922","94171.00734"]]},"channel":"diff_order_book_usdteur","event":"data"}
1641343708.233563: {"data":{"timestamp":"1641343708","microtimestamp":"1641343708294368","bids":[["0.88256","142306.96984"],["0.88101","9080.48716"],["0.88060","8516.92028"]],"asks":[]},"channel":"diff_order_book_usdteur","event":"data"}
1641343708.2455502: {"data":{"timestamp":"1641343708","microtimestamp":"1641343708208333","bids":[],"asks":[["0.73542","9037.87911843"]]},"channel":"diff_order_book_xrpeur","event":"data"}
1641343708.333621: {"data":{"timestamp":"1641343708","microtimestamp":"1641343708377216","bids":[["0.00002760","0.00000000"]],"asks":[]},"channel":"diff_order_book_batbtc","event":"data"}
1641343708.451048: {"data":{"timestamp":"1641343708","microtimestamp":"1641343708457849","bids":[["3802.63","0.00000000"],["3802.33","6.46940276"],["3800.27","0.00000000"],["3799.86","5.00000000"],["3798.06","2.73248242"],["3788.75","0.00000000"],["3788.69","0.03354093"],["3788.68","0.01341489"]],"asks":[["3806.86","25.00000000"]]},"channel":"diff_order_book_ethusd","event":"data"}
1641343708.4512131: {"data":{"timestamp":"1641343708","microtimestamp":"1641343708512068","bids":[],"asks":[["1.16395","0.00000000"]]},"channel":"diff_order_book_bateur","event":"data"}
1641343708.4607801: {"data":{"timestamp":"1641343708","microtimestamp":"1641343708525684","bids":[],"asks":[["0.89662","0.00000"]]},"channel":"diff_order_book_usdteur","event":"data"}
1641343708.518304: {"data":{"timestamp":"1641343708","microtimestamp":"1641343708568589","bids":[],"asks":[["1.18273","0.00000000"]]},"channel":"diff_order_book_adaeur","event":"data"}
1641343708.548594: {"data":{"timestamp":"1641343708","microtimestamp":"1641343708595901","bids":[["0.99782","0.00000"]],"asks":[["0.99992","0.00000"]]},"channel":"diff_order_book_usdtusd","event":"data"}
1641343708.561549: {"data":{"timestamp":"1641343708","microtimestamp":"1641343708606588","bids":[["0.00002830","0.00000000"]],"asks":[]},"channel":"diff_order_book_batbtc","event":"data"}
1641343708.5668359: {"data":{"timestamp":"1641343708","microtimestamp":"1641343708631569","bids":[["1.16067","1317.19415555"]],"asks":[]},"channel":"diff_order_book_bateur","event":"data"}
1641343708.57021: {"data":{"timestamp":"1641343708","microtimestamp":"1641343708529683","bids":[],"asks":[["0.73533","0.00000000"],["0.73535","6029.91954879"]]},"channel":"diff_order_book_xrpeur","event":"data"}
1641343708.576376: {"data":{"timestamp":"1641343708","microtimestamp":"1641343708638929","bids":[],"asks":[["0.88664","3692.64822"],["0.88666","0.00000"]]},"channel":"diff_order_book_usdteur","event":"data"}
1641343708.632189: {"data":{"timestamp":"1641343708","microtimestamp":"1641343708690859","bids":[],"asks":[["1.17713","4507.00000000"]]},"channel":"diff_order_book_adaeur","event":"data"}
1641343708.663251: {"data":{"timestamp":"1641343708","microtimestamp":"1641343708710411","bids":[["0.99784","5624.29169"]],"asks":[["0.99990","5692.64822"]]},"channel":"diff_order_book_usdtusd","event":"data"}
1641343708.6752052: {"data":{"timestamp":"1641343708","microtimestamp":"1641343708723746","bids":[["0.00002830","839.03662838"]],"asks":[]},"channel":"diff_order_book_batbtc","event":"data"}
1641343708.685036: {"data":{"timestamp":"1641343708","microtimestamp":"1641343708753452","bids":[],"asks":[["0.20870","0.00000000"]]},"channel":"diff_order_book_xlmgbp","event":"data"}
1641343708.6903622: {"data":{"timestamp":"1641343708","microtimestamp":"1641343708754407","bids":[],"asks":[["0.89658","14566.33531"]]},"channel":"diff_order_book_usdteur","event":"data"}
1641343708.742124: {"data":{"timestamp":"1641343708","microtimestamp":"1641343708702006","bids":[["3801.53","0.00000000"],["3801.08","0.40000000"],["3788.69","0.01341672"],["3788.68","0.02683126"]],"asks":[["3805.59","0.65718151"],["3805.87","0.40000000"],["3806.00","0.00000000"],["3806.35","0.00000000"],["3807.02","4.80000000"],["3807.75","0.00000000"]]},"channel":"diff_order_book_ethusd","event":"data"}
1641343708.7904818: {"data":{"timestamp":"1641343708","microtimestamp":"1641343708842614","bids":[["0.00002761","0.00000000"]],"asks":[]},"channel":"diff_order_book_batbtc","event":"data"}
1641343708.8352408: {"data":{"timestamp":"1641343708","microtimestamp":"1641343708830585","bids":[["0.73482","1800.00000000"]],"asks":[]},"channel":"diff_order_book_xrpeur","event":"data"}
1641343708.850898: {"data":{"timestamp":"1641343708","microtimestamp":"1641343708873898","bids":[],"asks":[["0.20867","10639.86697727"]]},"channel":"diff_order_book_xlmgbp","event":"data"}
1641343708.904792: {"data":{"timestamp":"1641343708","microtimestamp":"1641343708960374","bids":[["0.00002762","8612.16120454"]],"asks":[]},"channel":"diff_order_book_batbtc","event":"data"}
1641343708.91266: {"data":{"timestamp":"1641343708","microtimestamp":"1641343708933919","bids":[],"asks":[["1.17442","1888.92019469"],["1.17466","0.00000000"]]},"channel":"diff_order_book_adaeur","event":"data"}
1641343708.9227421: {"data":{"timestamp":"1641343708","microtimestamp":"1641343708989980","bids":[],"asks":[["0.20869","0.00000000"]]},"channel":"diff_order_book_xlmgbp","event":"data"}
1641343709.019559: {"data":{"timestamp":"1641343709","microtimestamp":"1641343709076121","bids":[["0.00002762","7751.11810804"]],"asks":[]},"channel":"diff_order_book_batbtc","event":"data"}
1641343709.01964: {"data":{"timestamp":"1641343709","microtimestamp":"1641343709020657","bids":[["3802.93","0.93100000"],["3802.72","0.00000000"],["3802.30","0.65720282"],["3801.40","0.00000000"],["3800.17","0.15439777"],["3799.33","2.62881128"],["3798.06","0.00000000"]],"asks":[["3806.08","1.31440564"],["3806.59","1.28679735"]]},"channel":"diff_order_book_ethusd","event":"data"}
1641343709.0472279: {"data":{"timestamp":"1641343709","microtimestamp":"1641343709103756","bids":[["0.38070","0.00000000"]],"asks":[]},"channel":"diff_order_book_galaeur","event":"data"}
1641343709.084714: {"data":{"timestamp":"1641343709","microtimestamp":"1641343709109294","bids":[],"asks":[["0.20866","3493.71000000"]]},"channel":"diff_order_book_xlmgbp","event":"data"}
1641343709.099692: {"data":{"timestamp":"1641343709","microtimestamp":"1641343709070481","bids":[["0.73482","0.00000000"]],"asks":[]},"channel":"diff_order_book_xrpeur","event":"data"}
1641343709.133706: {"data":{"timestamp":"1641343709","microtimestamp":"1641343709190359","bids":[["0.00002762","8612.20254256"]],"asks":[]},"channel":"diff_order_book_batbtc","event":"data"}
1641343709.148989: {"data":{"timestamp":"1641343709","microtimestamp":"1641343709214860","bids":[],"asks":[["0.88667","0.00000"]]},"channel":"diff_order_book_usdteur","event":"data"}
1641343709.160755: {"data":{"timestamp":"1641343709","microtimestamp":"1641343709215604","bids":[["0.38057","60565.79144481"]],"asks":[]},"channel":"diff_order_book_galaeur","event":"data"}
1641343709.1951842: {"data":{"timestamp":"1641343709","microtimestamp":"1641343709243856","bids":[],"asks":[["1.17029","0.00000000"]]},"channel":"diff_order_book_bateur","event":"data"}
1641343709.199471: {"data":{"timestamp":"1641343709","microtimestamp":"1641343709240001","bids":[],"asks":[["0.20867","0.00000000"]]},"channel":"diff_order_book_xlmgbp","event":"data"}
1641343709.237941: {"data":{"timestamp":"1641343709","microtimestamp":"1641343709282709","bids":[],"asks":[["0.99993","0.00000"]]},"channel":"diff_order_book_usdtusd","event":"data"}
1641343709.2569458: {"data":{"timestamp":"1641343709","microtimestamp":"1641343709297136","bids":[["1.17178","0.00000000"]],"asks":[["1.17442","0.00000000"]]},"channel":"diff_order_book_adaeur","event":"data"}
1641343709.28513: {"data":{"timestamp":"1641343709","microtimestamp":"1641343709277006","bids":[["3802.78","0.36790369"],["3802.36","14.72247232"],["3799.86","6.28750332"]],"asks":[["3806.86","0.00000000"]]},"channel":"diff_order_book_ethusd","event":"data"}
1641343709.309814: {"data":{"timestamp":"1641343709","microtimestamp":"1641343709375091","bids":[["1.16134","0.00000000"]],"asks":[["1.16821","0.00000000"],["1.16822","0.00000000"],["1.16824","0.00000000"]]},"channel":"diff_order_book_bateur","event":"data"}
1641343709.352052: {"data":{"timestamp":"1641343709","microtimestamp":"1641343709399229","bids":[],"asks":[["0.99989","8122.14370"]]},"channel":"diff_order_book_usdtusd","event":"data"}
1641343709.3626392: {"data":{"timestamp":"1641343709","microtimestamp":"1641343709418862","bids":[["0.00002763","21.21353601"]],"asks":[]},"channel":"diff_order_book_batbtc","event":"data"}
1641343709.371223: {"data":{"timestamp":"1641343709","microtimestamp":"1641343709417578","bids":[["1.17139","2645.02436397"]],"asks":[]},"channel":"diff_order_book_adaeur","event":"data"}
1641343709.378674: {"data":{"timestamp":"1641343709","microtimestamp":"1641343709445853","bids":[["0.88406","27643.85072"]],"asks":[["0.88663","9000.00000"]]},"channel":"diff_order_book_usdteur","event":"data"}
1641343709.429426: {"data":{"timestamp":"1641343709","microtimestamp":"1641343709466504","bids":[["0.20807","0.00000000"]],"asks":[["0.20869","17738.29237110"],["0.20876","6687.07291226"]]},"channel":"diff_order_book_xlmgbp","event":"data"}
1641343709.473953: {"data":{"timestamp":"1641343709","microtimestamp":"1641343709502640","bids":[],"asks":[["1.16819","992.87136508"],["1.16820","4282.18069560"]]},"channel":"diff_order_book_bateur","event":"data"}
1641343709.485804: {"data":{"timestamp":"1641343709","microtimestamp":"1641343709541590","bids":[],"asks":[["1.17517","3778.82873828"],["1.17598","797.33672010"]]},"channel":"diff_order_book_adaeur","event":"data"}
1641343709.5328372: {"data":{"id":216000484,"timestamp":"1641343709","amount":0.931,"amount_str":"0.93100000","price":3802.93,"price_str":"3802.93","type":1,"microtimestamp":"1641343709599000","buy_order_id":1443875774971904,"sell_order_id":1443875778322433},"channel":"live_trades_ethusd","event":"trade"}
1641343709.545449: {"data":{"id":216000485,"timestamp":"1641343709","amount":3.2394864,"amount_str":"3.23948640","price":3802.89,"price_str":"3802.89","type":1,"microtimestamp":"1641343709599000","buy_order_id":1443875635982337,"sell_order_id":1443875778322433},"channel":"live_trades_ethusd","event":"trade"}
1641343709.589352: {"data":{"timestamp":"1641343709","microtimestamp":"1641343709628850","bids":[["1.16102","3866.00000000"],["1.15990","0.00000000"]],"asks":[["1.16435","0.00000000"]]},"channel":"diff_order_book_bateur","event":"data"}
1641343709.658572: {"data":{"timestamp":"1641343709","microtimestamp":"1641343709698373","bids":[["0.20790","30839.49000000"]],"asks":[]},"channel":"diff_order_book_xlmgbp","event":"data"}
1641343709.703763: {"data":{"timestamp":"1641343709","microtimestamp":"1641343709755541","bids":[["1.16052","0.00000000"],["1.15989","992.95655488"]],"asks":[]},"channel":"diff_order_book_bateur","event":"data"}
1641343709.7038841: {"data":{"timestamp":"1641343709","microtimestamp":"1641343709686100","bids":[["3802.78","0.00000000"],["3802.36","0.00000000"],["3802.34","0.00000000"],["3801.89","0.00000000"],["3801.08","0.00000000"],["3800.33","0.00000000"],["3800.17","0.00000000"],["3797.92","0.00000000"]],"asks":[["3805.59","0.00000000"],["3805.87","0.00000000"],["3807.02","0.00000000"],["3809.13","0.00000000"],["3815.09","0.74128894"],["3816.79","0.00000000"]]},"channel":"diff_order_book_ethusd","event":"data"}
1641343709.706315: {"data":{"timestamp":"1641343709","microtimestamp":"1641343709763321","bids":[["0.00002830","0.00000000"]],"asks":[]},"channel":"diff_order_book_batbtc","event":"data"}
1641343709.77164: {"data":{"timestamp":"1641343709","microtimestamp":"1641343709807574","bids":[],"asks":[["0.88664","0.00000"]]},"channel":"diff_order_book_usdteur","event":"data"}
1641343709.804738: {"data":{"timestamp":"1641343709","microtimestamp":"1641343709781332","bids":[["0.73453","0.00000000"],["0.73443","12955.14000000"],["0.73442","0.00000000"],["0.73441","0.00000000"],["0.73440","6051.00000000"]],"asks":[["0.73527","1800.00000000"],["0.73531","0.00000000"],["0.73579","13190.87476705"],["0.73588","0.00000000"]]},"channel":"diff_order_book_xrpeur","event":"data"}
1641343709.821986: {"data":{"timestamp":"1641343709","microtimestamp":"1641343709878023","bids":[],"asks":[["1.16395","2673.99143898"],["1.16435","1645.10584651"]]},"channel":"diff_order_book_bateur","event":"data"}
1641343709.822109: {"data":{"timestamp":"1641343709","microtimestamp":"1641343709879600","bids":[["0.00002831","3125.49070660"]],"asks":[["0.00002904","1500.47991303"]]},"channel":"diff_order_book_batbtc","event":"data"}
1641343709.887514: {"data":{"timestamp":"1641343709","microtimestamp":"1641343709921654","bids":[["0.88255","0.00000"]],"asks":[["0.88664","1692.64822"],["0.88703","2000.00000"]]},"channel":"diff_order_book_usdteur","event":"data"}
1641343709.890681: {"data":{"timestamp":"1641343709","microtimestamp":"1641343709938647","bids":[],"asks":[["0.20858","10644.12964935"],["0.20889","0.00000000"]]},"channel":"diff_order_book_xlmgbp","event":"data"}
1641343709.942094: {"data":{"timestamp":"1641343709","microtimestamp":"1641343709993741","bids":[],"asks":[["0.00002902","2786.41057910"],["0.00002903","0.00000000"]]},"channel":"diff_order_book_batbtc","event":"data"}
1641343709.974972: {"data":{"timestamp":"1641343709","microtimestamp":"1641343709953385","bids":[["3802.93","0.00000000"],["3802.89","0.00000000"],["3802.32","0.00000000"],["3802.30","0.00000000"],["3801.43","1.31449399"],["3801.42","14.72674047"],["3800.55","0.40000000"],["3799.86","5.00000000"],["3799.45","0.15457672"],["3799.40","4.80000000"],["3798.05","0.00000000"],["3797.91","0.00000000"],["3795.14","5.25802874"]],"asks":[["3805.00","3.55000000"],["3805.19","0.65724700"],["3805.23","3.55000000"],["3805.41","17.30000000"],["3805.42","0.40000000"],["3805.43","0.00000000"],["3805.83","0.00000000"],["3805.99","0.00000000"],["3806.07","28.23093900"],["3806.08","0.00000000"],["3806.55","4.80000000"],["3806.59","2.99563953"],["3807.34","0.21300000"],["3815.08","0.29654049"],["3815.09","0.29651866"],["3815.30","0.00000000"]]},"channel":"diff_order_book_ethusd","event":"data"}
1641343710.006081: {"data":{"timestamp":"1641343710","microtimestamp":"1641343710035620","bids":[["0.88257","18753.97270"]],"asks":[]},"channel":"diff_order_book_usdteur","event":"data"}
1641343710.006537: {"data":{"timestamp":"1641343710","microtimestamp":"1641343710053898","bids":[["0.20806","0.00000000"]],"asks":[["0.20869","0.00000000"],["0.20879","27395.41681155"]]},"channel":"diff_order_book_xlmgbp","event":"data"}
1641343710.0517812: {"data":{"timestamp":"1641343710","microtimestamp":"1641343710108639","bids":[],"asks":[["0.00002901","839.17336021"],["0.00002902","4287.07802934"],["0.00002904","0.00000000"]]},"channel":"diff_order_book_batbtc","event":"data"}
1641343710.076819: {"data":{"timestamp":"1641343710","microtimestamp":"1641343710071672","bids":[],"asks":[["0.73527","4900.00000000"]]},"channel":"diff_order_book_xrpeur","event":"data"}
1641343710.123476: {"data":{"timestamp":"1641343710","microtimestamp":"1641343710165818","bids":[["0.20795","26613.86801004"]],"asks":[]},"channel":"diff_order_book_xlmgbp","event":"data"}
1641343710.22404: {"data":{"timestamp":"1641343710","microtimestamp":"1641343710259192","bids":[["1.16133","0.00000000"],["1.16085","0.00000000"],["1.16036","1200.00000000"]],"asks":[]},"channel":"diff_order_book_bateur","event":"data"}
1641343710.240313: {"data":{"timestamp":"1641343710","microtimestamp":"1641343710215320","bids":[["3802.76","0.00000000"],["3802.33","0.00000000"],["3802.31","0.00000000"],["3799.45","0.00000000"],["3799.41","2.73248242"]],"asks":[["3804.80","3.55000000"],["3804.99","8.14101895"],["3805.23","0.00000000"],["3805.47","0.00000000"],["3806.16","25.00000000"],["3807.34","0.00000000"]]},"channel":"diff_order_book_ethusd","event":"data"}
1641343710.3521469: {"data":{"timestamp":"1641343710","microtimestamp":"1641343710388273","bids":[],"asks":[["0.21237","0.00000000"]]},"channel":"diff_order_book_xlmgbp","event":"data"}
1641343710.3939772: {"data":{"timestamp":"1641343710","microtimestamp":"1641343710431375","bids":[],"asks":[["1.19565","14051.76424366"]]},"channel":"diff_order_book_adaeur","event":"data"}
1641343710.398558: {"data":{"timestamp":"1641343710","microtimestamp":"1641343710468545","bids":[["0.00002833","0.00000000"]],"asks":[]},"channel":"diff_order_book_batbtc","event":"data"}
1641343710.4534888: {"data":{"timestamp":"1641343710","microtimestamp":"1641343710512534","bids":[["1.16101","0.00000000"],["1.16060","762.98828860"]],"asks":[]},"channel":"diff_order_book_bateur","event":"data"}
1641343710.4650009: {"data":{"timestamp":"1641343710","microtimestamp":"1641343710501628","bids":[],"asks":[["0.21237","52816.97275840"]]},"channel":"diff_order_book_xlmgbp","event":"data"}
1641343710.513341: {"data":{"timestamp":"1641343710","microtimestamp":"1641343710582435","bids":[["0.00002828","2288.96486578"]],"asks":[]},"channel":"diff_order_book_batbtc","event":"data"}
1641343710.5134542: {"data":{"timestamp":"1641343710","microtimestamp":"1641343710499567","bids":[["3801.46","2.73248242"],["3801.45","0.60000000"],["3801.44","15.86920103"],["3800.72","6.11028089"],["3799.41","0.00000000"],["3799.34","10.00000000"],["3788.68","0.01341637"]],"asks":[["3804.64","3.55000000"],["3804.79","3.27655592"],["3804.98","12.79865850"],["3805.00","0.00000000"],["3805.44","8.05436204"],["3807.06","1.32000000"]]},"channel":"diff_order_book_ethusd","event":"data"}
1641343710.567412: {"data":{"timestamp":"1641343710","microtimestamp":"1641343710565975","bids":[["0.73453","10168.63761652"]],"asks":[["0.74499","28445.15312630"]]},"channel":"diff_order_book_xrpeur","event":"data"}
1641343710.582283: {"data":{"timestamp":"1641343710","microtimestamp":"1641343710617865","bids":[],"asks":[["0.20858","0.00000000"],["0.20870","17737.19688494"]]},"channel":"diff_order_book_xlmgbp","event":"data"}
1641343710.786512: {"data":{"timestamp":"1641343710","microtimestamp":"1641343710804918","bids":[["1.17198","0.00000000"]],"asks":[["1.17418","1889.30311712"]]},"channel":"diff_order_book_adaeur","event":"data"}
1641343710.796461: {"data":{"timestamp":"1641343710","microtimestamp":"1641343710793182","bids":[["3801.54","3.33248242"],["3801.53","2.10800000"],["3801.46","0.00000000"],["3801.45","0.00000000"],["3800.72","0.00000000"],["3788.68","0.04696647"]],"asks":[["3807.06","0.00000000"]]},"channel":"diff_order_book_ethusd","event":"data"}
1641343710.815171: {"data":{"timestamp":"1641343710","microtimestamp":"1641343710845894","bids":[["0.20813","0.00000000"]],"asks":[["0.20870","0.00000000"]]},"channel":"diff_order_book_xlmgbp","event":"data"}
1641343710.851182: {"data":{"timestamp":"1641343710","microtimestamp":"1641343710898134","bids":[["1.15989","0.00000000"]],"asks":[]},"channel":"diff_order_book_bateur","event":"data"}
1641343710.900552: {"data":{"timestamp":"1641343710","microtimestamp":"1641343710927963","bids":[["1.17173","1889.52436770"],["1.17143","0.00000000"]],"asks":[["1.17482","0.00000000"]]},"channel":"diff_order_book_adaeur","event":"data"}
1641343710.905853: {"data":{"timestamp":"1641343710","microtimestamp":"1641343710940334","bids":[["0.00002831","2286.37110419"],["0.00002762","6459.27491893"]],"asks":[]},"channel":"diff_order_book_batbtc","event":"data"}
1641343710.9294589: {"data":{"timestamp":"1641343710","microtimestamp":"1641343710962001","bids":[],"asks":[["0.20855","10645.79873531"]]},"channel":"diff_order_book_xlmgbp","event":"data"}
1641343710.9654882: {"data":{"timestamp":"1641343711","microtimestamp":"1641343711020806","bids":[["1.15900","993.15733053"]],"asks":[]},"channel":"diff_order_book_bateur","event":"data"}
1641343710.97295: {"data":{"timestamp":"1641343711","microtimestamp":"1641343711033586","bids":[],"asks":[["0.99990","0.00000"]]},"channel":"diff_order_book_usdtusd","event":"data"}
1641343711.0156538: {"data":{"timestamp":"1641343711","microtimestamp":"1641343711048035","bids":[["1.17140","68889.69210000"]],"asks":[["1.17446","2645.41683831"],["1.17620","7558.49807233"],["1.17714","0.00000000"]]},"channel":"diff_order_book_adaeur","event":"data"}
1641343711.020093: {"data":{"timestamp":"1641343711","microtimestamp":"1641343711053948","bids":[["0.00002830","839.28568269"]],"asks":[]},"channel":"diff_order_book_batbtc","event":"data"}
1641343711.054816: {"data":{"timestamp":"1641343711","microtimestamp":"1641343711084744","bids":[["0.88257","0.00000"]],"asks":[["0.88664","0.00000"],["0.88703","0.00000"]]},"channel":"diff_order_book_usdteur","event":"data"}
1641343711.0549572: {"data":{"timestamp":"1641343711","microtimestamp":"1641343711077276","bids":[["0.20807","17743.18919300"]],"asks":[]},"channel":"diff_order_book_xlmgbp","event":"data"}
1641343711.1348732: {"data":{"timestamp":"1641343711","microtimestamp":"1641343711166425","bids":[["0.00002764","861.16717049"]],"asks":[["0.00002901","0.00000000"]]},"channel":"diff_order_book_batbtc","event":"data"}
1641343711.154743: {"data":{"timestamp":"1641343711","microtimestamp":"1641343711199725","bids":[["0.88407","16459.88856"]],"asks":[["0.88662","3692.64822"]]},"channel":"diff_order_book_usdteur","event":"data"}
1641343711.201494: {"data":{"timestamp":"1641343711","microtimestamp":"1641343711267571","bids":[],"asks":[["0.99988","5692.64822"]]},"channel":"diff_order_book_usdtusd","event":"data"}
1641343711.245465: {"data":{"timestamp":"1641343711","microtimestamp":"1641343711235048","bids":[["3801.81","0.65728099"],["3801.55","2.73248242"],["3801.54","6.33851650"]],"asks":[["3805.63","1.31456197"],["3806.92","1.51901457"]]},"channel":"diff_order_book_ethusd","event":"data"}
1641343711.2489998: {"data":{"timestamp":"1641343711","microtimestamp":"1641343711279038","bids":[["1.16102","0.00000000"]],"asks":[["1.16347","863.68055980"],["1.16396","0.00000000"]]},"channel":"diff_order_book_bateur","event":"data"}
1641343711.2522812: {"data":{"timestamp":"1641343711","microtimestamp":"1641343711285348","bids":[],"asks":[["0.00002901","839.28884020"]]},"channel":"diff_order_book_batbtc","event":"data"}
1641343711.3627572: {"data":{"timestamp":"1641343711","microtimestamp":"1641343711409831","bids":[["1.16076","3866.00000000"]],"asks":[["1.16309","762.94309226"],["1.16346","2673.99143898"],["1.16349","0.00000000"],["1.16395","0.00000000"],["1.16672","2225.00000000"],["1.16835","0.00000000"]]},"channel":"diff_order_book_bateur","event":"data"}
1641343711.512017: {"data":{"timestamp":"1641343711","microtimestamp":"1641343711489498","bids":[["3801.96","8.23636921"],["3801.55","0.00000000"],["3801.54","0.00000000"],["3801.44","8.18855525"],["3801.43","0.00000000"],["3801.42","0.00000000"],["3800.95","1.31464328"],["3800.28","0.37166334"],["3799.41","2.73248242"],["3799.34","0.00000000"]],"asks":[["3804.76","0.65732164"],["3804.97","8.02897840"],["3805.19","0.00000000"],["3805.44","0.00000000"],["3805.93","0.34798611"],["3806.16","0.00000000"]]},"channel":"diff_order_book_ethusd","event":"data"}
1641343711.732961: {"data":{"timestamp":"1641343711","microtimestamp":"1641343711722080","bids":[["3801.54","6.29124705"],["3800.96","6.65740853"],["3799.17","4.14100506"]],"asks":[["3806.92","0.00000000"]]},"channel":"diff_order_book_ethusd","event":"data"}
1641343711.7768: {"data":{"timestamp":"1641343711","microtimestamp":"1641343711837729","bids":[["0.99781","0.00000"]],"asks":[["0.99991","0.00000"]]},"channel":"diff_order_book_usdtusd","event":"data"}
1641343711.8419251: {"data":{"timestamp":"1641343711","microtimestamp":"1641343711897259","bids":[],"asks":[["0.88665","0.00000"],["0.88704","0.00000"],["0.89659","0.00000"],["0.89923","0.00000"]]},"channel":"diff_order_book_usdteur","event":"data"}
1641343711.874723: {"data":{"timestamp":"1641343711","microtimestamp":"1641343711908855","bids":[["1.15679","0.00000000"]],"asks":[]},"channel":"diff_order_book_bateur","event":"data"}
1641343711.956678: {"data":{"timestamp":"1641343712","microtimestamp":"1641343712016282","bids":[],"asks":[["0.89921","13500.00000"],["0.89922","0.00000"],["0.89999","93042.70746"]]},"channel":"diff_order_book_usdteur","event":"data"}
1641343711.9875698: {"data":{"timestamp":"1641343712","microtimestamp":"1641343712049600","bids":[["1.14866","7758.57984642"]],"asks":[]},"channel":"diff_order_book_bateur","event":"data"}
1641343712.0041332: {"data":{"timestamp":"1641343712","microtimestamp":"1641343712065825","bids":[["0.99948","0.00000"],["0.99783","0.00000"],["0.98452","0.00000"]],"asks":[["0.99994","18383.96385"],["0.99998","3500.00000"]]},"channel":"diff_order_book_usdtusd","event":"data"}
1641343712.009588: {"data":{"timestamp":"1641343711","microtimestamp":"1641343711970332","bids":[["3801.96","0.00000000"],["3801.54","0.00000000"],["3800.96","0.00000000"],["3799.41","0.00000000"],["3799.17","0.00000000"]],"asks":[["3806.80","0.14139075"]]},"channel":"diff_order_book_ethusd","event":"data"}
1641343712.0709581: {"data":{"timestamp":"1641343712","microtimestamp":"1641343712133100","bids":[],"asks":[["0.88661","2883.96385"],["0.88704","33000.00000"],["0.89657","40500.00000"],["0.89999","0.00000"]]},"channel":"diff_order_book_usdteur","event":"data"}
1641343712.119715: {"data":{"timestamp":"1641343712","microtimestamp":"1641343712180037","bids":[["0.99948","3105.20768"],["0.99785","128275.79295"],["0.98452","46723.25577"]],"asks":[]},"channel":"diff_order_book_usdtusd","event":"data"}
1641343712.184681: {"data":{"timestamp":"1641343712","microtimestamp":"1641343712247733","bids":[],"asks":[["0.89658","0.00000"],["0.89920","93042.70746"]]},"channel":"diff_order_book_usdteur","event":"data"}
1641343712.212254: {"data":{"timestamp":"1641343712","microtimestamp":"1641343712272553","bids":[],"asks":[["1.19565","0.00000000"],["1.19566","0.00000000"]]},"channel":"diff_order_book_adaeur","event":"data"}
1641343712.286844: {"data":{"timestamp":"1641343712","microtimestamp":"1641343712323014","bids":[["0.00002764","3014.63243750"],["0.00002762","5598.19048441"]],"asks":[["0.00002901","0.00000000"]]},"channel":"diff_order_book_batbtc","event":"data"}
1641343712.292929: {"data":{"timestamp":"1641343712","microtimestamp":"1641343712243714","bids":[["3801.96","7.50149994"],["3800.98","12.81429261"],["3799.42","2.73248242"],["3799.17","4.14100833"],["3788.69","0.10064699"],["3788.68","0.03355010"]],"asks":[]},"channel":"diff_order_book_ethusd","event":"data"}
1641343712.298219: {"data":{"timestamp":"1641343712","microtimestamp":"1641343712362425","bids":[["0.88256","0.00000"],["0.88101","0.00000"],["0.88060","0.00000"]],"asks":[]},"channel":"diff_order_book_usdteur","event":"data"}
1641343712.3289442: {"data":{"timestamp":"1641343712","microtimestamp":"1641343712396261","bids":[],"asks":[["1.19751","14051.76424366"]]},"channel":"diff_order_book_adaeur","event":"data"}
1641343712.382394: {"data":{"timestamp":"1641343712","microtimestamp":"1641343712418551","bids":[["1.16051","0.00000000"]],"asks":[["1.16388","95.62336027"]]},"channel":"diff_order_book_bateur","event":"data"}
1641343712.401835: {"data":{"timestamp":"1641343712","microtimestamp":"1641343712435956","bids":[["0.00002762","0.00000000"]],"asks":[["0.00002901","839.39252156"]]},"channel":"diff_order_book_batbtc","event":"data"}
1641343712.413653: {"data":{"timestamp":"1641343712","microtimestamp":"1641343712477859","bids":[["0.88408","62318.38669"],["0.88101","63563.41017"],["0.88060","31796.50238"]],"asks":[["0.89662","14566.33531"]]},"channel":"diff_order_book_usdteur","event":"data"}
1641343712.499674: {"data":{"timestamp":"1641343712","microtimestamp":"1641343712551993","bids":[],"asks":[["1.16413","0.00000000"]]},"channel":"diff_order_book_bateur","event":"data"}
1641343712.5257401: {"data":{"timestamp":"1641343712","microtimestamp":"1641343712555784","bids":[["0.00002835","46.78702717"],["0.00002764","8614.07289293"]],"asks":[]},"channel":"diff_order_book_batbtc","event":"data"}
1641343712.608771: {"data":{"timestamp":"1641343712","microtimestamp":"1641343712650467","bids":[["1.17088","0.00000000"]],"asks":[]},"channel":"diff_order_book_adaeur","event":"data"}
1641343712.637507: {"data":{"timestamp":"1641343712","microtimestamp":"1641343712673672","bids":[["0.00002833","1144.63977818"]],"asks":[]},"channel":"diff_order_book_batbtc","event":"data"}
1641343712.665449: {"data":{"timestamp":"1641343712","microtimestamp":"1641343712690982","bids":[],"asks":[["1.16334","1907.73296363"]]},"channel":"diff_order_book_bateur","event":"data"}
1641343712.669753: {"data":{"timestamp":"1641343712","microtimestamp":"1641343712722431","bids":[],"asks":[["0.20865","17742.09533865"]]},"channel":"diff_order_book_xlmgbp","event":"data"}
1641343712.724514: {"data":{"timestamp":"1641343712","microtimestamp":"1641343712776081","bids":[["1.17001","3779.28553266"]],"asks":[]},"channel":"diff_order_book_adaeur","event":"data"}
1641343712.7462358: {"data":{"timestamp":"1641343712","microtimestamp":"1641343712701402","bids":[["3801.98","8.21120089"],["3801.97","3.05941102"],["3801.96","0.00000000"],["3801.81","0.00000000"],["3801.42","0.65734838"],["3800.98","6.21512684"],["3788.69","0.04696682"]],"asks":[["3805.18","1.31469675"],["3805.63","0.00000000"],["3815.09","0.00000000"]]},"channel":"diff_order_book_ethusd","event":"data"}
1641343712.779158: {"data":{"timestamp":"1641343712","microtimestamp":"1641343712815522","bids":[["1.16027","96.20260682"]],"asks":[["1.16671","428.49892347"],["1.16820","3853.77854205"]]},"channel":"diff_order_book_bateur","event":"data"}
1641343712.865516: {"data":{"timestamp":"1641343712","microtimestamp":"1641343712902024","bids":[],"asks":[["0.00002902","3215.19003420"]]},"channel":"diff_order_book_batbtc","event":"data"}
1641343712.893562: {"data":{"timestamp":"1641343712","microtimestamp":"1641343712938834","bids":[],"asks":[["1.16333","2673.99143898"],["1.16346","0.00000000"]]},"channel":"diff_order_book_bateur","event":"data"}
1641343713.029876: {"data":{"timestamp":"1641343712","microtimestamp":"1641343712990488","bids":[["3797.91","0.12142006"]],"asks":[["3815.08","1.03792299"]]},"channel":"diff_order_book_ethusd","event":"data"}
1641343713.037441: {"data":{"timestamp":"1641343713","microtimestamp":"1641343713059448","bids":[],"asks":[["0.89662","0.00000"]]},"channel":"diff_order_book_usdteur","event":"data"}
1641343713.084034: {"data":{"timestamp":"1641343713","microtimestamp":"1641343713037711","bids":[],"asks":[["0.73526","1800.00000000"],["0.73527","0.00000000"]]},"channel":"diff_order_book_xrpeur","event":"data"}
1641343713.094798: {"data":{"timestamp":"1641343713","microtimestamp":"1641343713143340","bids":[],"asks":[["0.00002900","429.00647389"],["0.00002902","0.00000000"]]},"channel":"diff_order_book_batbtc","event":"data"}
1641343713.132653: {"data":{"timestamp":"1641343713","microtimestamp":"1641343713192895","bids":[],"asks":[["0.20855","0.00000000"]]},"channel":"diff_order_book_xlmgbp","event":"data"}
1641343713.151933: {"data":{"timestamp":"1641343713","microtimestamp":"1641343713189264","bids":[],"asks":[["0.89656","14566.33531"]]},"channel":"diff_order_book_usdteur","event":"data"}
1641343713.211637: {"data":{"timestamp":"1641343713","microtimestamp":"1641343713259929","bids":[],"asks":[["0.00002900","4288.76806259"]]},"channel":"diff_order_book_batbtc","event":"data"}
1641343713.2472022: {"data":{"timestamp":"1641343713","microtimestamp":"1641343713306548","bids":[],"asks":[["0.20859","10643.86932497"]]},"channel":"diff_order_book_xlmgbp","event":"data"}
1641343713.295947: {"data":{"timestamp":"1641343713","microtimestamp":"1641343713262177","bids":[["3801.54","6.57205001"],["3799.42","0.00000000"],["3788.69","0.13420030"],["3788.68","0.00000000"]],"asks":[["3806.09","2.51571293"]]},"channel":"diff_order_book_ethusd","event":"data"}
1641343713.307689: {"data":{"timestamp":"1641343713","microtimestamp":"1641343713299467","bids":[],"asks":[["0.73526","0.00000000"]]},"channel":"diff_order_book_xrpeur","event":"data"}
1641343713.348269: {"data":{"timestamp":"1641343713","microtimestamp":"1641343713404335","bids":[],"asks":[["1.19564","91.11535390"]]},"channel":"diff_order_book_adaeur","event":"data"}
1641343713.379222: {"data":{"timestamp":"1641343713","microtimestamp":"1641343713437986","bids":[["0.99784","0.00000"]],"asks":[]},"channel":"diff_order_book_usdtusd","event":"data"}
1641343713.3798358: {"data":{"timestamp":"1641343713","microtimestamp":"1641343713420233","bids":[],"asks":[["0.88662","0.00000"]]},"channel":"diff_order_book_usdteur","event":"data"}
1641343713.438412: {"data":{"timestamp":"1641343713","microtimestamp":"1641343713490312","bids":[],"asks":[["0.00002899","839.39196532"],["0.00002901","0.00000000"]]},"channel":"diff_order_book_batbtc","event":"data"}
1641343713.4619179: {"data":{"timestamp":"1641343713","microtimestamp":"1641343713526274","bids":[],"asks":[["1.19563","14136.39413103"],["1.19751","0.00000000"]]},"channel":"diff_order_book_adaeur","event":"data"}
1641343713.492985: {"data":{"timestamp":"1641343713","microtimestamp":"1641343713553482","bids":[["0.99786","5624.17896"]],"asks":[]},"channel":"diff_order_book_usdtusd","event":"data"}
1641343713.495449: {"data":{"timestamp":"1641343713","microtimestamp":"1641343713535232","bids":[["0.88407","0.00000"]],"asks":[["0.88660","3692.64822"]]},"channel":"diff_order_book_usdteur","event":"data"}
1641343713.512257: {"data":{"timestamp":"1641343713","microtimestamp":"1641343713512115","bids":[["3801.98","0.00000000"],["3801.97","0.00000000"],["3801.54","0.00000000"],["3800.98","0.00000000"],["3799.42","2.73248242"],["3799.17","0.00000000"],["3797.91","1.33565986"]],"asks":[["3804.64","0.00000000"],["3806.09","0.00000000"]]},"channel":"diff_order_book_ethusd","event":"data"}
1641343713.592837: {"data":{"timestamp":"1641343713","microtimestamp":"1641343713577559","bids":[["0.73463","0.00000000"],["0.73451","6030.30643522"]],"asks":[["0.73531","1800.00000000"],["0.73532","3100.00000000"]]},"channel":"diff_order_book_xrpeur","event":"data"}
1641343713.6110551: {"data":{"timestamp":"1641343713","microtimestamp":"1641343713656885","bids":[["0.88409","17590.62277"]],"asks":[]},"channel":"diff_order_book_usdteur","event":"data"}
1641343713.973494: {"data":{"timestamp":"1641343713","microtimestamp":"1641343713956751","bids":[["3801.55","3.81433098"],["3801.54","8.21001825"],["3801.53","0.00000000"],["3801.45","2.10800000"],["3800.96","6.43609491"],["3799.42","0.00000000"],["3799.17","10.00000000"],["3797.91","0.00000000"]],"asks":[["3804.76","4.20732164"],["3806.16","25.00000000"],["3817.64","0.00000000"]]},"channel":"diff_order_book_ethusd","event":"data"}
1641343714.0174441: {"data":{"timestamp":"1641343714","microtimestamp":"1641343714011785","bids":[],"asks":[["0.73529","7830.32568846"],["0.73530","3100.00000000"],["0.73531","0.00000000"],["0.73532","0.00000000"],["0.73540","0.00000000"]]},"channel":"diff_order_book_xrpeur","event":"data"}
1641343714.180067: {"data":{"timestamp":"1641343714","microtimestamp":"1641343714243682","bids":[],"asks":[["0.99989","0.00000"]]},"channel":"diff_order_book_usdtusd","event":"data"}
1641343714.180182: {"data":{"timestamp":"1641343714","microtimestamp":"1641343714233616","bids":[],"asks":[["0.88663","0.00000"]]},"channel":"diff_order_book_usdteur","event":"data"}
1641343714.2834759: {"data":{"timestamp":"1641343714","microtimestamp":"1641343714261867","bids":[["0.73461","6030.13187608"],["0.73451","0.00000000"]],"asks":[["0.73529","4900.00000000"],["0.73541","6029.94956392"]]},"channel":"diff_order_book_xrpeur","event":"data"}
1641343714.2839959: {"data":{"timestamp":"1641343714","microtimestamp":"1641343714338257","bids":[],"asks":[["0.20866","0.00000000"]]},"channel":"diff_order_book_xlmgbp","event":"data"}
1641343714.291817: {"data":{"timestamp":"1641343714","microtimestamp":"1641343714267601","bids":[["3801.55","3.21433098"],["3800.97","6.56907805"],["3800.96","0.00000000"],["3799.17","0.00000000"],["3799.00","10.00000000"]],"asks":[["3805.93","0.00000000"],["3806.80","0.04015313"],["3815.30","1.92759573"]]},"channel":"diff_order_book_ethusd","event":"data"}
1641343714.294135: {"data":{"timestamp":"1641343714","microtimestamp":"1641343714358085","bids":[],"asks":[["0.99993","8122.14370"]]},"channel":"diff_order_book_usdtusd","event":"data"}
1641343714.2942579: {"data":{"timestamp":"1641343714","microtimestamp":"1641343714348385","bids":[],"asks":[["0.88659","9000.00000"]]},"channel":"diff_order_book_usdteur","event":"data"}
1641343714.305572: {"data":{"timestamp":"1641343714","microtimestamp":"1641343714347876","bids":[["1.15989","1954.26000000"]],"asks":[]},"channel":"diff_order_book_bateur","event":"data"}
1641343714.401075: {"data":{"timestamp":"1641343714","microtimestamp":"1641343714454573","bids":[],"asks":[["0.20858","133.65000000"]]},"channel":"diff_order_book_xlmgbp","event":"data"}
1641343714.4743328: {"data":{"timestamp":"1641343714","microtimestamp":"1641343714524242","bids":[],"asks":[["0.00002899","0.00000000"]]},"channel":"diff_order_book_batbtc","event":"data"}
1641343714.5554712: {"data":{"timestamp":"1641343714","microtimestamp":"1641343714552532","bids":[],"asks":[["0.73541","0.00000000"]]},"channel":"diff_order_book_xrpeur","event":"data"}
1641343714.587631: {"data":{"timestamp":"1641343714","microtimestamp":"1641343714638532","bids":[],"asks":[["0.00002899","839.38138936"]]},"channel":"diff_order_book_batbtc","event":"data"}
1641343714.626438: {"data":{"timestamp":"1641343714","microtimestamp":"1641343714587414","bids":[["3801.56","6.50045829"],["3800.97","0.00000000"],["3799.42","2.73248242"],["3799.00","0.00000000"],["3797.91","55.04304127"]],"asks":[["3806.80","0.00000000"]]},"channel":"diff_order_book_ethusd","event":"data"}
1641343714.698046: {"data":{"timestamp":"1641343714","microtimestamp":"1641343714756323","bids":[],"asks":[["1.16307","863.68055980"],["1.16347","0.00000000"]]},"channel":"diff_order_book_bateur","event":"data"}
1641343714.70374: {"data":{"timestamp":"1641343714","microtimestamp":"1641343714755161","bids":[["0.00002764","7752.90572244"]],"asks":[]},"channel":"diff_order_book_batbtc","event":"data"}
1641343714.818027: {"data":{"timestamp":"1641343714","microtimestamp":"1641343714871757","bids":[["0.00002765","861.36392785"]],"asks":[]},"channel":"diff_order_book_batbtc","event":"data"}
1641343714.825444: {"data":{"timestamp":"1641343714","microtimestamp":"1641343714836129","bids":[["0.73461","0.00000000"]],"asks":[]},"channel":"diff_order_book_xrpeur","event":"data"}
1641343714.863611: {"data":{"timestamp":"1641343714","microtimestamp":"1641343714890335","bids":[["1.16076","0.00000000"]],"asks":[]},"channel":"diff_order_book_bateur","event":"data"}
1641343714.8673248: {"data":{"timestamp":"1641343714","microtimestamp":"1641343714927624","bids":[],"asks":[["0.99988","0.00000"]]},"channel":"diff_order_book_usdtusd","event":"data"}
1641343714.867438: {"data":{"timestamp":"1641343714","microtimestamp":"1641343714924045","bids":[],"asks":[["0.88660","0.00000"]]},"channel":"diff_order_book_usdteur","event":"data"}
1641343714.9344919: {"data":{"timestamp":"1641343714","microtimestamp":"1641343714988661","bids":[["0.00002834","1195.92434124"]],"asks":[["0.00002845","1142.85539196"]]},"channel":"diff_order_book_batbtc","event":"data"}
1641343714.946312: {"data":{"timestamp":"1641343714","microtimestamp":"1641343714880430","bids":[["3802.73","0.00000000"],["3801.57","6.30998819"],["3801.55","0.00000000"],["3801.54","0.00000000"],["3799.42","0.00000000"],["3799.15","4.14104308"]],"asks":[["3806.71","0.14172939"]]},"channel":"diff_order_book_ethusd","event":"data"}
1641343714.977545: {"data":{"timestamp":"1641343715","microtimestamp":"1641343715015585","bids":[["1.16068","3866.00000000"],["1.16066","0.00000000"]],"asks":[["1.16462","0.00000000"]]},"channel":"diff_order_book_bateur","event":"data"}
1641343714.981741: {"data":{"timestamp":"1641343715","microtimestamp":"1641343715047668","bids":[],"asks":[["0.99993","13814.79192"]]},"channel":"diff_order_book_usdtusd","event":"data"}
1641343714.981796: {"data":{"timestamp":"1641343715","microtimestamp":"1641343715041698","bids":[],"asks":[["0.88703","3692.64822"]]},"channel":"diff_order_book_usdteur","event":"data"}
1641343715.05087: {"data":{"timestamp":"1641343715","microtimestamp":"1641343715105616","bids":[["0.00002834","7107.57434124"]],"asks":[["0.00002844","5951.41905784"]]},"channel":"diff_order_book_batbtc","event":"data"}
1641343715.090354: {"data":{"timestamp":"1641343715","microtimestamp":"1641343715069315","bids":[],"asks":[["0.73529","0.00000000"]]},"channel":"diff_order_book_xrpeur","event":"data"}
1641343715.092196: {"data":{"timestamp":"1641343715","microtimestamp":"1641343715140627","bids":[["1.16045","6182.11000000"]],"asks":[["1.16387","1645.10584651"],["1.16435","0.00000000"],["1.16441","4910.21000000"]]},"channel":"diff_order_book_bateur","event":"data"}
1641343715.3243918: {"data":{"timestamp":"1641343715","microtimestamp":"1641343715376389","bids":[["0.20807","0.00000000"]],"asks":[]},"channel":"diff_order_book_xlmgbp","event":"data"}
1641343715.380277: {"data":{"timestamp":"1641343715","microtimestamp":"1641343715353664","bids":[["3801.60","2.73248242"],["3801.58","11.07028339"],["3799.15","0.00000000"],["3799.08","4.14109705"]],"asks":[["3805.21","0.40000000"],["3805.42","0.00000000"],["3805.45","0.00000000"],["3805.46","0.00000000"],["3806.59","1.70884218"],["3806.71","0.00000000"]]},"channel":"diff_order_book_ethusd","event":"data"}
1641343715.438466: {"data":{"timestamp":"1641343715","microtimestamp":"1641343715491692","bids":[["0.20813","17737.48609585"]],"asks":[]},"channel":"diff_order_book_xlmgbp","event":"data"}
1641343715.544416: {"data":{"timestamp":"1641343715","microtimestamp":"1641343715537585","bids":[],"asks":[["0.73529","1800.00000000"],["0.73530","0.00000000"],["0.73535","9129.91954879"]]},"channel":"diff_order_book_xrpeur","event":"data"}
1641343715.554156: {"data":{"timestamp":"1641343715","microtimestamp":"1641343715610687","bids":[],"asks":[["0.20859","0.00000000"],["0.20865","0.00000000"]]},"channel":"diff_order_book_xlmgbp","event":"data"}
1641343715.62099: {"data":{"timestamp":"1641343715","microtimestamp":"1641343715676701","bids":[],"asks":[["0.00002899","0.00000000"]]},"channel":"diff_order_book_batbtc","event":"data"}
1641343715.647528: {"data":{"timestamp":"1641343715","microtimestamp":"1641343715605848","bids":[["3801.60","0.00000000"],["3801.59","3.09241401"],["3801.58","0.00000000"],["3801.57","0.00000000"],["3801.56","0.00000000"],["3799.08","0.00000000"]],"asks":[["3806.16","0.00000000"],["3806.71","0.18158252"],["3815.30","0.00000000"],["3816.79","1.92755386"]]},"channel":"diff_order_book_ethusd","event":"data"}
1641343715.669198: {"data":{"timestamp":"1641343715","microtimestamp":"1641343715721580","bids":[],"asks":[["0.20864","10641.38896527"],["0.20873","17735.64827544"]]},"channel":"diff_order_book_xlmgbp","event":"data"}
1641343715.7347322: {"data":{"timestamp":"1641343715","microtimestamp":"1641343715789499","bids":[["0.00002763","0.00000000"]],"asks":[["0.00002899","839.37838201"]]},"channel":"diff_order_book_batbtc","event":"data"}
1641343715.809949: {"data":{"timestamp":"1641343715","microtimestamp":"1641343715788990","bids":[["0.73481","0.00000000"],["0.73479","14722.10011783"],["0.73471","0.00000000"],["0.73457","10168.63761652"],["0.73453","0.00000000"],["0.73443","0.00000000"],["0.73442","6051.00000000"],["0.73441","16542.90000000"],["0.73440","0.00000000"]],"asks":[["0.73529","0.00000000"],["0.73534","4900.00000000"],["0.73536","0.00000000"],["0.73542","0.00000000"]]},"channel":"diff_order_book_xrpeur","event":"data"}
1641343715.851671: {"data":{"timestamp":"1641343715","microtimestamp":"1641343715905474","bids":[["0.00002764","5599.44045543"]],"asks":[["0.00002900","3859.76158870"]]},"channel":"diff_order_book_batbtc","event":"data"}
1641343715.865624: {"data":{"timestamp":"1641343715","microtimestamp":"1641343715863375","bids":[["3801.63","0.60000000"],["3801.62","8.00234427"],["3799.08","4.14110830"]],"asks":[["3806.71","0.00000000"]]},"channel":"diff_order_book_ethusd","event":"data"}
1641343715.898441: {"data":{"timestamp":"1641343715","microtimestamp":"1641343715968049","bids":[],"asks":[["0.99993","8122.14370"]]},"channel":"diff_order_book_usdtusd","event":"data"}
1641343715.949559: {"data":{"timestamp":"1641343715","microtimestamp":"1641343715973653","bids":[["0.88409","0.00000"]],"asks":[["0.88703","0.00000"]]},"channel":"diff_order_book_usdteur","event":"data"}
1641343715.9655502: {"data":{"timestamp":"1641343716","microtimestamp":"1641343716020132","bids":[["0.00002765","3014.77374746"],["0.00002764","0.00000000"]],"asks":[["0.00002847","2334.92470786"],["0.00002900","1072.34327030"]]},"channel":"diff_order_book_batbtc","event":"data"}
1641343716.07877: {"data":{"timestamp":"1641343716","microtimestamp":"1641343716133215","bids":[["0.00002765","8614.12134986"]],"asks":[["0.00002898","2787.35946246"]]},"channel":"diff_order_book_batbtc","event":"data"}
1641343716.182407: {"data":{"timestamp":"1641343716","microtimestamp":"1641343716211009","bids":[["0.88409","16459.51621"]],"asks":[["0.88658","1692.64822"]]},"channel":"diff_order_book_usdteur","event":"data"}
1641343716.182531: {"data":{"timestamp":"1641343716","microtimestamp":"1641343716200809","bids":[],"asks":[["0.99992","7692.64822"]]},"channel":"diff_order_book_usdtusd","event":"data"}
1641343716.188569: {"data":{"timestamp":"1641343716","microtimestamp":"1641343716187818","bids":[["3801.64","2.73248242"],["3799.08","0.00000000"]],"asks":[["3806.71","0.03985313"]]},"channel":"diff_order_book_ethusd","event":"data"}
1641343716.1930208: {"data":{"timestamp":"1641343716","microtimestamp":"1641343716247089","bids":[],"asks":[["0.00002898","0.00000000"]]},"channel":"diff_order_book_batbtc","event":"data"}
1641343716.2509792: {"data":{"timestamp":"1641343716","microtimestamp":"1641343716304140","bids":[["0.20795","0.00000000"]],"asks":[]},"channel":"diff_order_book_xlmgbp","event":"data"}
1641343716.312468: {"data":{"timestamp":"1641343716","microtimestamp":"1641343716360269","bids":[],"asks":[["0.00002898","1072.32284644"]]},"channel":"diff_order_book_batbtc","event":"data"}
1641343716.3478029: {"data":{"timestamp":"1641343716","microtimestamp":"1641343716397511","bids":[],"asks":[["1.19563","0.00000000"]]},"channel":"diff_order_book_adaeur","event":"data"}
1641343716.3683689: {"data":{"timestamp":"1641343716","microtimestamp":"1641343716435458","bids":[["0.20805","26599.64193945"]],"asks":[["0.21237","0.00000000"]]},"channel":"diff_order_book_xlmgbp","event":"data"}
1641343716.3875499: {"data":{"timestamp":"1641343716","microtimestamp":"1641343716359647","bids":[["0.73465","6029.77797659"],["0.73457","0.00000000"]],"asks":[["0.73532","1800.00000000"],["0.73533","3100.00000000"],["0.73534","0.00000000"],["0.73542","6029.91436918"]]},"channel":"diff_order_book_xrpeur","event":"data"}
1641343716.3917801: {"data":{"timestamp":"1641343716","microtimestamp":"1641343716413100","bids":[["1.16068","0.00000000"]],"asks":[]},"channel":"diff_order_book_bateur","event":"data"}
1641343716.4246788: {"data":{"timestamp":"1641343716","microtimestamp":"1641343716472707","bids":[["0.00002835","0.00000000"]],"asks":[]},"channel":"diff_order_book_batbtc","event":"data"}
1641343716.461877: {"data":{"timestamp":"1641343716","microtimestamp":"1641343716519723","bids":[["1.17001","0.00000000"]],"asks":[["1.19563","29069.28651922"]]},"channel":"diff_order_book_adaeur","event":"data"}
1641343716.4811509: {"data":{"timestamp":"1641343716","microtimestamp":"1641343716551126","bids":[],"asks":[["0.21237","108815.80959090"]]},"channel":"diff_order_book_xlmgbp","event":"data"}
1641343716.5065129: {"data":{"timestamp":"1641343716","microtimestamp":"1641343716540608","bids":[["1.16067","0.00000000"]],"asks":[]},"channel":"diff_order_book_bateur","event":"data"}
1641343716.511272: {"data":{"timestamp":"1641343716","microtimestamp":"1641343716478141","bids":[["3801.64","0.00000000"],["3801.60","6.42994640"],["3801.46","6.62260220"],["3799.08","10.00000000"]],"asks":[["3806.56","25.00000000"]]},"channel":"diff_order_book_ethusd","event":"data"}
1641343716.5389829: {"data":{"timestamp":"1641343716","microtimestamp":"1641343716586601","bids":[["0.00002831","2331.32352488"]],"asks":[]},"channel":"diff_order_book_batbtc","event":"data"}
1641343716.575459: {"data":{"timestamp":"1641343716","microtimestamp":"1641343716640326","bids":[["1.17087","3778.43063643"]],"asks":[]},"channel":"diff_order_book_adaeur","event":"data"}
1641343716.6202939: {"data":{"timestamp":"1641343716","microtimestamp":"1641343716663042","bids":[["1.16040","3866.00000000"]],"asks":[]},"channel":"diff_order_book_bateur","event":"data"}
1641343716.6542249: {"data":{"timestamp":"1641343716","microtimestamp":"1641343716700979","bids":[],"asks":[["0.00002900","0.00000000"]]},"channel":"diff_order_book_batbtc","event":"data"}
1641343716.658918: {"data":{"timestamp":"1641343716","microtimestamp":"1641343716628488","bids":[["0.73443","10168.63761652"]],"asks":[["0.73533","0.00000000"],["0.74499","57729.63916210"]]},"channel":"diff_order_book_xrpeur","event":"data"}
1641343716.7530072: {"data":{"timestamp":"1641343716","microtimestamp":"1641343716803449","bids":[["0.88406","0.00000"]],"asks":[]},"channel":"diff_order_book_usdteur","event":"data"}
1641343716.76085: {"data":{"timestamp":"1641343716","microtimestamp":"1641343716824375","bids":[["0.38057","2623.51685867"]],"asks":[]},"channel":"diff_order_book_galaeur","event":"data"}
1641343716.766965: {"data":{"timestamp":"1641343716","microtimestamp":"1641343716817709","bids":[],"asks":[["0.00002898","3859.44345325"],["0.00002899","0.00000000"]]},"channel":"diff_order_book_batbtc","event":"data"}
1641343716.867023: {"data":{"timestamp":"1641343716","microtimestamp":"1641343716920924","bids":[],"asks":[["0.89656","0.00000"]]},"channel":"diff_order_book_usdteur","event":"data"}
1641343716.881957: {"data":{"timestamp":"1641343716","microtimestamp":"1641343716938456","bids":[["0.00002765","8635.31954154"]],"asks":[["0.00002897","839.34703902"]]},"channel":"diff_order_book_batbtc","event":"data"}
1641343716.9451299: {"data":{"timestamp":"1641343717","microtimestamp":"1641343717006449","bids":[],"asks":[["0.99994","0.00000"],["0.99998","0.00000"]]},"channel":"diff_order_book_usdtusd","event":"data"}
1641343716.982987: {"data":{"timestamp":"1641343717","microtimestamp":"1641343717034938","bids":[],"asks":[["0.88661","0.00000"],["0.88704","0.00000"],["0.89657","0.00000"],["0.89660","14566.33531"],["0.89921","0.00000"]]},"channel":"diff_order_book_usdteur","event":"data"}
1641343717.0968351: {"data":{"timestamp":"1641343717","microtimestamp":"1641343717149730","bids":[],"asks":[["0.88704","34383.96385"],["0.89919","14500.00000"],["0.89920","0.00000"]]},"channel":"diff_order_book_usdteur","event":"data"}
1641343717.113145: {"data":{"timestamp":"1641343717","microtimestamp":"1641343717169108","bids":[["0.00002765","7773.95561369"]],"asks":[]},"channel":"diff_order_book_batbtc","event":"data"}
1641343717.174413: {"data":{"timestamp":"1641343717","microtimestamp":"1641343717236358","bids":[],"asks":[["0.99991","21883.96385"]]},"channel":"diff_order_book_usdtusd","event":"data"}
1641343717.1989892: {"data":{"timestamp":"1641343717","microtimestamp":"1641343717160763","bids":[["3797.92","0.12141448"]],"asks":[["3804.76","0.65732164"],["3805.20","11.39549400"],["3805.85","0.39316602"],["3806.07","0.00000000"]]},"channel":"diff_order_book_ethusd","event":"data"}
1641343717.213965: {"data":{"timestamp":"1641343717","microtimestamp":"1641343717265439","bids":[],"asks":[["0.89655","41000.00000"],["0.89660","0.00000"],["0.89999","94327.69530"]]},"channel":"diff_order_book_usdteur","event":"data"}
1641343717.226686: {"data":{"timestamp":"1641343717","microtimestamp":"1641343717283660","bids":[["0.00002766","861.36392785"]],"asks":[]},"channel":"diff_order_book_batbtc","event":"data"}
1641343717.288675: {"data":{"timestamp":"1641343717","microtimestamp":"1641343717350773","bids":[["0.99785","0.00000"],["0.98452","0.00000"]],"asks":[]},"channel":"diff_order_book_usdtusd","event":"data"}
1641343717.3215082: {"data":{"timestamp":"1641343717","microtimestamp":"1641343717309994","bids":[["0.73457","10168.63761652"],["0.73456","6029.92518287"],["0.73444","6051.00000000"],["0.73443","0.00000000"],["0.73442","0.00000000"]],"asks":[["0.73532","0.00000000"],["0.73535","0.00000000"],["0.73541","1800.00000000"],["0.73542","0.00000000"],["0.73545","0.00000000"],["0.73547","6029.50381429"],["0.73578","11069.06891470"],["0.73593","0.00000000"],["0.73594","0.00000000"],["0.73614","9197.63088289"],["0.73772","3399.79710011"]]},"channel":"diff_order_book_xrpeur","event":"data"}
1641343717.3268428: {"data":{"timestamp":"1641343717","microtimestamp":"1641343717382471","bids":[],"asks":[["0.89999","0.00000"]]},"channel":"diff_order_book_usdteur","event":"data"}
1641343717.406851: {"data":{"timestamp":"1641343717","microtimestamp":"1641343717466344","bids":[["0.99787","41087.51640"],["0.99761","9522.75939"],["0.99522","58278.57157"],["0.98452","66529.85357"]],"asks":[]},"channel":"diff_order_book_usdtusd","event":"data"}
1641343717.441868: {"data":{"timestamp":"1641343717","microtimestamp":"1641343717509907","bids":[],"asks":[["0.89662","14566.33531"],["0.89918","94327.69530"]]},"channel":"diff_order_book_usdteur","event":"data"}
1641343717.591719: {"data":{"timestamp":"1641343717","microtimestamp":"1641343717546046","bids":[["0.73469","6029.44754921"],["0.73457","0.00000000"],["0.73456","0.00000000"],["0.73453","10168.63761652"]],"asks":[["0.73541","0.00000000"],["0.73601","6051.00000000"],["0.73869","8838.78600316"]]},"channel":"diff_order_book_xrpeur","event":"data"}
1641343717.606006: {"data":{"timestamp":"1641343717","microtimestamp":"1641343717630774","bids":[["0.88408","0.00000"],["0.88101","0.00000"],["0.88060","0.00000"]],"asks":[]},"channel":"diff_order_book_usdteur","event":"data"}
1641343717.694857: {"data":{"timestamp":"1641343717","microtimestamp":"1641343717668842","bids":[["3801.64","3.08973709"],["3801.63","0.00000000"],["3801.60","0.00000000"],["3801.59","0.00000000"],["3801.46","0.00000000"],["3799.41","2.73248242"],["3797.93","1.21423912"]],"asks":[]},"channel":"diff_order_book_ethusd","event":"data"}
1641343717.722784: {"data":{"timestamp":"1641343717","microtimestamp":"1641343717748100","bids":[["0.88410","62882.52381"],["0.88101","64698.47107"],["0.88060","43720.19077"]],"asks":[]},"channel":"diff_order_book_usdteur","event":"data"}
1641343717.855154: {"data":{"timestamp":"1641343717","microtimestamp":"1641343717817594","bids":[],"asks":[["0.73546","1800.00000000"],["0.73577","13190.87476705"],["0.73579","0.00000000"],["0.73601","0.00000000"],["0.73613","6051.00000000"]]},"channel":"diff_order_book_xrpeur","event":"data"}
1641343717.914332: {"data":{"timestamp":"1641343717","microtimestamp":"1641343717983422","bids":[],"asks":[["0.00002897","0.00000000"]]},"channel":"diff_order_book_batbtc","event":"data"}
1641343717.950253: {"data":{"timestamp":"1641343717","microtimestamp":"1641343717987309","bids":[],"asks":[["0.89662","0.00000"]]},"channel":"diff_order_book_usdteur","event":"data"}
1641343717.966214: {"data":{"timestamp":"1641343717","microtimestamp":"1641343717932627","bids":[["3801.96","0.60000000"],["3801.95","3.93854689"]],"asks":[["3806.71","0.04754850"],["3807.56","0.00000000"]]},"channel":"diff_order_book_ethusd","event":"data"}
1641343718.034324: {"data":{"timestamp":"1641343718","microtimestamp":"1641343718098828","bids":[],"asks":[["0.00002897","839.34643980"]]},"channel":"diff_order_book_batbtc","event":"data"}
1641343718.137922: {"data":{"timestamp":"1641343718","microtimestamp":"1641343718072016","bids":[["0.73469","0.00000000"]],"asks":[]},"channel":"diff_order_book_xrpeur","event":"data"}
1641343718.144694: {"data":{"timestamp":"1641343718","microtimestamp":"1641343718187953","bids":[["0.20790","0.00000000"]],"asks":[]},"channel":"diff_order_book_xlmgbp","event":"data"}
1641343718.181018: {"data":{"timestamp":"1641343718","microtimestamp":"1641343718214920","bids":[],"asks":[["0.89654","14566.33531"]]},"channel":"diff_order_book_usdteur","event":"data"}
1641343718.259108: {"data":{"timestamp":"1641343718","microtimestamp":"1641343718302171","bids":[["0.20790","43844.13000000"]],"asks":[["0.20864","0.00000000"]]},"channel":"diff_order_book_xlmgbp","event":"data"}
1641343718.306869: {"data":{"timestamp":"1641343718","microtimestamp":"1641343718347011","bids":[["0.00002765","5620.54579408"]],"asks":[]},"channel":"diff_order_book_batbtc","event":"data"}
1641343718.374105: {"data":{"timestamp":"1641343718","microtimestamp":"1641343718416726","bids":[],"asks":[["0.20859","10643.89994837"],["0.20873","0.00000000"]]},"channel":"diff_order_book_xlmgbp","event":"data"}
1641343718.394866: {"data":{"timestamp":"1641343718","microtimestamp":"1641343718348030","bids":[["3801.96","0.00000000"],["3801.95","0.38854689"],["3801.64","0.00000000"],["3801.62","0.00000000"],["3801.46","17.85095401"],["3800.56","6.05848503"],["3799.41","0.00000000"]],"asks":[["3804.74","3.55000000"],["3806.71","0.00000000"]]},"channel":"diff_order_book_ethusd","event":"data"}
1641343718.4089348: {"data":{"timestamp":"1641343718","microtimestamp":"1641343718459044","bids":[],"asks":[["0.88658","0.00000"]]},"channel":"diff_order_book_usdteur","event":"data"}
1641343718.420631: {"data":{"timestamp":"1641343718","microtimestamp":"1641343718463890","bids":[["0.00002766","3014.77374746"]],"asks":[]},"channel":"diff_order_book_batbtc","event":"data"}
1641343718.447791: {"data":{"timestamp":"1641343718","microtimestamp":"1641343718497668","bids":[["0.99786","0.00000"]],"asks":[["0.99992","0.00000"]]},"channel":"diff_order_book_usdtusd","event":"data"}
1641343718.488512: {"data":{"timestamp":"1641343718","microtimestamp":"1641343718530369","bids":[],"asks":[["0.20868","17740.24056795"]]},"channel":"diff_order_book_xlmgbp","event":"data"}
1641343718.525856: {"data":{"timestamp":"1641343718","microtimestamp":"1641343718574982","bids":[["0.88409","0.00000"]],"asks":[["0.88703","1000.00000"]]},"channel":"diff_order_book_usdteur","event":"data"}
1641343718.532556: {"data":{"timestamp":"1641343718","microtimestamp":"1641343718521929","bids":[["0.73479","11622.10011783"],["0.73465","0.00000000"]],"asks":[["0.73542","1800.00000000"],["0.73543","3100.00000000"],["0.73546","0.00000000"],["0.73547","0.00000000"],["0.73578","0.00000000"]]},"channel":"diff_order_book_xrpeur","event":"data"}
1641343718.561428: {"data":{"timestamp":"1641343718","microtimestamp":"1641343718611787","bids":[["0.99788","5624.06624"]],"asks":[["0.99990","7692.64822"]]},"channel":"diff_order_book_usdtusd","event":"data"}
1641343718.617075: {"data":{"timestamp":"1641343718","microtimestamp":"1641343718608555","bids":[["3801.47","0.60000000"],["3801.46","6.06358639"],["3801.45","4.65083042"],["3800.56","0.00000000"],["3799.41","2.73248242"]],"asks":[["3804.73","0.70000000"],["3806.71","0.40068772"]]},"channel":"diff_order_book_ethusd","event":"data"}
1641343718.638881: {"data":{"timestamp":"1641343718","microtimestamp":"1641343718691026","bids":[["0.88411","16459.14386"]],"asks":[["0.88658","692.64822"]]},"channel":"diff_order_book_usdteur","event":"data"}
1641343718.6561558: {"data":{"timestamp":"1641343718","microtimestamp":"1641343718694109","bids":[],"asks":[["0.00002898","2787.12060681"]]},"channel":"diff_order_book_batbtc","event":"data"}
1641343718.6763499: {"data":{"timestamp":"1641343718","microtimestamp":"1641343718727346","bids":[],"asks":[["1.19564","0.00000000"]]},"channel":"diff_order_book_adaeur","event":"data"}
1641343718.772369: {"data":{"timestamp":"1641343718","microtimestamp":"1641343718811941","bids":[["0.00002834","1195.92434124"]],"asks":[["0.00002844","1143.93905784"],["0.00002896","1072.40831561"]]},"channel":"diff_order_book_batbtc","event":"data"}
1641343718.788308: {"data":{"timestamp":"1641343718","microtimestamp":"1641343718845591","bids":[["1.16045","0.00000000"]],"asks":[["1.16441","0.00000000"]]},"channel":"diff_order_book_bateur","event":"data"}
1641343718.7914171: {"data":{"timestamp":"1641343718","microtimestamp":"1641343718851186","bids":[],"asks":[["1.19563","0.00000000"]]},"channel":"diff_order_book_adaeur","event":"data"}
1641343718.801288: {"data":{"timestamp":"1641343718","microtimestamp":"1641343718765547","bids":[["0.73453","0.00000000"]],"asks":[["0.73530","3100.00000000"],["0.73542","0.00000000"],["0.73543","0.00000000"],["0.73553","11335.65029254"]]},"channel":"diff_order_book_xrpeur","event":"data"}
1641343718.882946: {"data":{"timestamp":"1641343718","microtimestamp":"1641343718925630","bids":[["0.00002833","7137.40977818"]],"asks":[["0.00002844","6192.68905784"]]},"channel":"diff_order_book_batbtc","event":"data"}
1641343718.946938: {"data":{"timestamp":"1641343718","microtimestamp":"1641343718900358","bids":[["3801.49","0.60000000"],["3801.48","10.55167678"],["3801.47","0.00000000"]],"asks":[]},"channel":"diff_order_book_ethusd","event":"data"}
1641343718.9494941: {"data":{"timestamp":"1641343718","microtimestamp":"1641343718984297","bids":[["0.20805","0.00000000"]],"asks":[]},"channel":"diff_order_book_xlmgbp","event":"data"}
1641343718.961511: {"data":{"timestamp":"1641343718","microtimestamp":"1641343718973563","bids":[["1.16031","6058.47000000"]],"asks":[["1.16333","0.00000000"],["1.16427","4863.79000000"]]},"channel":"diff_order_book_bateur","event":"data"}
1641343718.9616451: {"data":{"timestamp":"1641343718","microtimestamp":"1641343718978464","bids":[],"asks":[["1.19751","29148.57315895"]]},"channel":"diff_order_book_adaeur","event":"data"}
1641343719.066944: {"data":{"timestamp":"1641343719","microtimestamp":"1641343719100918","bids":[["0.20813","0.00000000"],["0.20794","26613.51767627"]],"asks":[]},"channel":"diff_order_book_xlmgbp","event":"data"}
1641343719.0670679: {"data":{"timestamp":"1641343719","microtimestamp":"1641343719040189","bids":[["0.73453","10168.63761652"]],"asks":[]},"channel":"diff_order_book_xrpeur","event":"data"}
1641343719.070598: {"data":{"timestamp":"1641343719","microtimestamp":"1641343719097144","bids":[["1.16040","0.00000000"]],"asks":[["1.16306","2673.99143898"],["1.16671","0.00000000"],["1.16820","2783.24975270"]]},"channel":"diff_order_book_bateur","event":"data"}
1641343719.112478: {"data":{"timestamp":"1641343719","microtimestamp":"1641343719156935","bids":[],"asks":[["0.00002897","0.00000000"]]},"channel":"diff_order_book_batbtc","event":"data"}
1641343719.184173: {"data":{"timestamp":"1641343719","microtimestamp":"1641343719216259","bids":[["0.20807","17742.78876441"]],"asks":[["0.20859","0.00000000"]]},"channel":"diff_order_book_xlmgbp","event":"data"}
1641343719.184247: {"data":{"timestamp":"1641343719","microtimestamp":"1641343719219433","bids":[["1.16027","0.00000000"],["1.15988","0.00000000"],["1.15875","98.46221655"]],"asks":[["1.16300","94.23076707"],["1.16304","863.68055980"],["1.16307","0.00000000"],["1.16356","101.09855447"],["1.16436","0.00000000"],["1.16472","0.00000000"],["1.16509","0.00000000"],["1.16600","428.59798035"],["1.16670","1071.14833016"]]},"channel":"diff_order_book_bateur","event":"data"}
1641343719.187428: {"data":{"timestamp":"1641343719","microtimestamp":"1641343719224068","bids":[["1.17087","0.00000000"]],"asks":[]},"channel":"diff_order_book_adaeur","event":"data"}
1641343719.210753: {"data":{"timestamp":"1641343719","microtimestamp":"1641343719280470","bids":[],"asks":[["0.88659","0.00000"]]},"channel":"diff_order_book_usdteur","event":"data"}
1641343719.216304: {"data":{"timestamp":"1641343719","microtimestamp":"1641343719208260","bids":[["3801.49","0.00000000"],["3801.48","0.00000000"],["3801.46","0.00000000"],["3801.45","0.00000000"],["3800.73","2.73248242"],["3800.56","6.53228956"],["3800.28","0.00000000"],["3799.41","0.00000000"],["3799.08","0.00000000"],["3797.93","0.00000000"]],"asks":[["3804.73","0.00000000"],["3806.56","0.00000000"],["3809.82","0.00000000"],["3816.79","0.00000000"]]},"channel":"diff_order_book_ethusd","event":"data"}
1641343719.2258859: {"data":{"timestamp":"1641343719","microtimestamp":"1641343719272650","bids":[["0.00002831","2286.37110419"]],"asks":[["0.00002895","839.37865767"]]},"channel":"diff_order_book_batbtc","event":"data"}
1641343719.253736: {"data":{"timestamp":"1641343719","microtimestamp":"1641343719301375","bids":[],"asks":[["0.99993","0.00000"]]},"channel":"diff_order_book_usdtusd","event":"data"}
1641343719.299978: {"data":{"timestamp":"1641343719","microtimestamp":"1641343719330439","bids":[["0.20807","0.00000000"]],"asks":[]},"channel":"diff_order_book_xlmgbp","event":"data"}
1641343719.300569: {"data":{"timestamp":"1641343719","microtimestamp":"1641343719344020","bids":[["1.16060","0.00000000"],["1.16039","0.00000000"],["1.15924","97.91351444"]],"asks":[["1.16303","2673.99143898"],["1.16306","0.00000000"],["1.16309","0.00000000"]]},"channel":"diff_order_book_bateur","event":"data"}
1641343719.302639: {"data":{"timestamp":"1641343719","microtimestamp":"1641343719344961","bids":[["1.17173","0.00000000"],["1.17139","0.00000000"],["1.17001","3779.46430069"]],"asks":[]},"channel":"diff_order_book_adaeur","event":"data"}
1641343719.343759: {"data":{"timestamp":"1641343719","microtimestamp":"1641343719385414","bids":[["0.00002835","47.15548485"]],"asks":[]},"channel":"diff_order_book_batbtc","event":"data"}
1641343719.344295: {"data":{"timestamp":"1641343719","microtimestamp":"1641343719341908","bids":[["0.73444","0.00000000"],["0.72662","0.00000000"]],"asks":[["0.73529","4900.00000000"],["0.73530","0.00000000"],["0.73588","6051.00000000"],["0.73613","0.00000000"]]},"channel":"diff_order_book_xrpeur","event":"data"}
1641343719.367316: {"data":{"timestamp":"1641343719","microtimestamp":"1641343719416650","bids":[],"asks":[["0.99989","8122.14370"]]},"channel":"diff_order_book_usdtusd","event":"data"}
1641343719.375811: {"data":{"timestamp":"1641343719","microtimestamp":"1641343719398534","bids":[],"asks":[["0.88657","9000.00000"]]},"channel":"diff_order_book_usdteur","event":"data"}
1641343719.388643: {"data":{"timestamp":"1641343719","microtimestamp":"1641343719413789","bids":[],"asks":[["0.38165","0.00000000"]]},"channel":"diff_order_book_galaeur","event":"data"}
1641343719.422648: {"data":{"timestamp":"1641343719","microtimestamp":"1641343719469587","bids":[["1.16031","0.00000000"],["1.16011","763.30165076"],["1.15957","1908.30244762"],["1.15925","2302.69008950"],["1.15900","0.00000000"]],"asks":[["1.16265","763.32097905"],["1.16427","0.00000000"]]},"channel":"diff_order_book_bateur","event":"data"}
1641343719.452526: {"data":{"timestamp":"1641343719","microtimestamp":"1641343719525501","bids":[["0.38032","0.00000000"]],"asks":[["0.38154","1163.33270164"],["0.38213","0.00000000"]]},"channel":"diff_order_book_galaeur","event":"data"}
1641343719.458615: {"data":{"timestamp":"1641343719","microtimestamp":"1641343719498063","bids":[],"asks":[["0.00002847","1905.91886928"]]},"channel":"diff_order_book_batbtc","event":"data"}
1641343719.545729: {"data":{"timestamp":"1641343719","microtimestamp":"1641343719593495","bids":[["1.16011","0.00000000"],["1.15989","0.00000000"]],"asks":[]},"channel":"diff_order_book_bateur","event":"data"}
1641343719.545818: {"data":{"timestamp":"1641343719","microtimestamp":"1641343719589070","bids":[["1.17148","1890.00773815"],["1.17101","2646.01083340"],["1.16936","0.00000000"]],"asks":[]},"channel":"diff_order_book_adaeur","event":"data"}
1641343719.565162: {"data":{"timestamp":"1641343719","microtimestamp":"1641343719637098","bids":[["0.38009","2326.81440930"]],"asks":[["0.38190","2326.81440930"]]},"channel":"diff_order_book_galaeur","event":"data"}
1641343719.568692: {"data":{"timestamp":"1641343719","microtimestamp":"1641343719612007","bids":[["0.00002835","0.00000000"],["0.00002834","52.52866685"]],"asks":[["0.00002846","429.10301152"]]},"channel":"diff_order_book_batbtc","event":"data"}
1641343719.582704: {"data":{"timestamp":"1641343719","microtimestamp":"1641343719581528","bids":[["0.73453","0.00000000"],["0.73451","6030.62941994"],["0.73439","0.00000000"],["0.73423","12062.26667151"],["0.73416","0.00000000"],["0.72570","18343.61519280"]],"asks":[["0.73523","3100.00000000"],["0.73526","6030.95250154"],["0.73529","3100.00000000"],["0.73554","0.00000000"],["0.73576","6051.00000000"],["0.73588","0.00000000"],["0.73772","0.00000000"]]},"channel":"diff_order_book_xrpeur","event":"data"}
1641343719.646471: {"data":{"timestamp":"1641343719","microtimestamp":"1641343719678162","bids":[["0.20816","3588.26617941"]],"asks":[["0.20863","17744.46415767"],["0.20868","0.00000000"]]},"channel":"diff_order_book_xlmgbp","event":"data"}
1641343719.6496692: {"data":{"timestamp":"1641343719","microtimestamp":"1641343719712980","bids":[["1.17148","0.00000000"],["1.17140","0.00000000"],["1.16658","4507.00000000"]],"asks":[["1.17481","0.00000000"],["1.17570","0.00000000"]]},"channel":"diff_order_book_adaeur","event":"data"}
1641343719.650212: {"data":{"timestamp":"1641343719","microtimestamp":"1641343719718151","bids":[["1.15924","0.00000000"]],"asks":[["1.16264","2673.99143898"],["1.16269","95.29056006"],["1.16303","0.00000000"]]},"channel":"diff_order_book_bateur","event":"data"}
1641343719.679714: {"data":{"timestamp":"1641343719","microtimestamp":"1641343719748481","bids":[["0.38056","0.00000000"]],"asks":[]},"channel":"diff_order_book_galaeur","event":"data"}
1641343719.6829371: {"data":{"timestamp":"1641343719","microtimestamp":"1641343719737453","bids":[["0.00002832","1188.76632010"]],"asks":[]},"channel":"diff_order_book_batbtc","event":"data"}
1641343719.688412: {"data":{"timestamp":"1641343719","microtimestamp":"1641343719672280","bids":[["3801.95","0.00000000"],["3801.46","7.86976905"],["3801.42","0.00000000"],["3801.13","0.39946463"],["3801.03","0.65742482"],["3800.95","0.00000000"],["3800.73","0.00000000"],["3800.57","6.56567745"],["3800.56","0.00000000"],["3800.55","0.00000000"],["3800.48","0.00000000"],["3799.87","6.18941961"],["3799.81","0.40000000"],["3799.60","0.40400042"],["3799.40","0.00000000"],["3799.37","0.00000000"],["3799.33","0.00000000"],["3798.66","4.80000000"],["3797.92","0.00000000"],["3796.15","0.00000000"],["3788.69","0.04696682"],["3760.01","0.00000000"]],"asks":[["3803.97","0.65745972"],["3804.71","1.31487800"],["3804.73","1.10000000"],["3804.76","0.00000000"],["3804.80","0.00000000"],["3805.18","0.00000000"],["3805.21","0.00000000"],["3805.71","1.70924715"],["3805.80","4.80000000"],["3806.55","0.00000000"],["3806.56","25.00000000"],["3806.71","0.00000000"],["3807.47","0.00000000"],["3808.18","34.16519141"],["3808.23","0.00000000"],["3809.12","0.00000000"],["3809.15","3.94450675"],["3809.44","48.64830000"],["3811.01","0.00000000"],["3811.71","0.00000000"],["3815.08","0.74138250"],["3815.30","1.92757546"]]},"channel":"diff_order_book_ethusd","event":"data"}
1641343719.7077818: {"data":{"timestamp":"1641343719","microtimestamp":"1641343719762852","bids":[],"asks":[["0.99990","0.00000"]]},"channel":"diff_order_book_usdtusd","event":"data"}
1641343719.762054: {"data":{"timestamp":"1641343719","microtimestamp":"1641343719793843","bids":[["0.20811","0.00000000"]],"asks":[["0.20863","0.00000000"],["0.20879","784.00000000"]]},"channel":"diff_order_book_xlmgbp","event":"data"}
1641343719.785027: {"data":{"timestamp":"1641343719","microtimestamp":"1641343719855793","bids":[],"asks":[["0.88658","0.00000"],["0.88703","0.00000"]]},"channel":"diff_order_book_usdteur","event":"data"}
1641343719.7940621: {"data":{"timestamp":"1641343719","microtimestamp":"1641343719860204","bids":[["0.38044","1163.51332800"]],"asks":[]},"channel":"diff_order_book_galaeur","event":"data"}
1641343719.820479: {"data":{"timestamp":"1641343719","microtimestamp":"1641343719836002","bids":[["1.17064","0.00000000"],["1.17034","0.00000000"]],"asks":[["1.17464","3780.72335438"],["1.19562","91.11535390"],["1.19751","0.00000000"]]},"channel":"diff_order_book_adaeur","event":"data"}
1641343719.820628: {"data":{"timestamp":"1641343719","microtimestamp":"1641343719860612","bids":[["1.15830","99.20063653"],["1.15680","0.00000000"],["1.14866","8620.73886405"]],"asks":[]},"channel":"diff_order_book_bateur","event":"data"}
1641343719.8769011: {"data":{"timestamp":"1641343719","microtimestamp":"1641343719907352","bids":[["0.20794","0.00000000"]],"asks":[["0.20869","26625.31487782"]]},"channel":"diff_order_book_xlmgbp","event":"data"}
1641343719.9008288: {"data":{"timestamp":"1641343719","microtimestamp":"1641343719972379","bids":[],"asks":[["0.88703","5692.64822"]]},"channel":"diff_order_book_usdteur","event":"data"}
1641343719.9081721: {"data":{"timestamp":"1641343719","microtimestamp":"1641343719971529","bids":[],"asks":[["0.38164","0.00000000"]]},"channel":"diff_order_book_galaeur","event":"data"}
1641343719.93166: {"data":{"timestamp":"1641343719","microtimestamp":"1641343719956639","bids":[["1.16982","2380.00000000"]],"asks":[["1.19561","29148.57315895"]]},"channel":"diff_order_book_adaeur","event":"data"}
1641343719.932333: {"data":{"timestamp":"1641343719","microtimestamp":"1641343719992039","bids":[["1.15925","7946.87008950"],["1.15908","97.78091537"],["1.15900","1515.69000000"]],"asks":[["1.16320","4852.93000000"]]},"channel":"diff_order_book_bateur","event":"data"}
1641343719.936791: {"data":{"timestamp":"1641343719","microtimestamp":"1641343719990877","bids":[],"asks":[["0.99990","3692.64822"]]},"channel":"diff_order_book_usdtusd","event":"data"}
1641343719.99122: {"data":{"timestamp":"1641343720","microtimestamp":"1641343720027982","bids":[["0.20791","6534.98470037"]],"asks":[]},"channel":"diff_order_book_xlmgbp","event":"data"}
1641343720.0030222: {"data":{"timestamp":"1641343719","microtimestamp":"1641343719998041","bids":[["0.73382","4068.00000000"]],"asks":[["0.73543","9047.10833454"],["0.73553","0.00000000"],["0.73772","3400.02828824"]]},"channel":"diff_order_book_xrpeur","event":"data"}
1641343720.024698: {"data":{"timestamp":"1641343719","microtimestamp":"1641343719947282","bids":[["3801.46","0.00000000"],["3801.13","0.00000000"],["3801.03","0.00000000"],["3800.73","8.06833676"],["3800.72","3.05045572"],["3800.71","0.00000000"],["3799.87","0.00000000"],["3799.81","0.00000000"],["3799.58","1.70932413"],["3799.32","0.40000000"],["3798.66","0.00000000"],["3798.57","0.50589517"],["3798.52","1.76200000"],["3798.17","4.80000000"],["3798.09","2.62967117"],["3793.65","5.25967774"],["3788.11","0.08725965"],["3756.62","10.62759983"]],"asks":[["3803.77","0.70000000"],["3803.78","3.55000000"],["3803.95","8.04257683"],["3803.96","10.98828029"],["3804.20","6.04164874"],["3804.21","0.40000000"],["3804.54","3.55000000"],["3804.73","0.00000000"],["3804.74","0.00000000"],["3804.79","0.00000000"],["3804.97","0.00000000"],["3804.98","0.00000000"],["3804.99","0.00000000"],["3806.56","0.00000000"],["3806.71","0.40068772"],["3806.97","2.62983887"],["3812.51","0.29662162"],["3841.98","56.32171156"],["3844.65","0.00000000"]]},"channel":"diff_order_book_ethusd","event":"data"}
1641343720.048289: {"data":{"timestamp":"1641343720","microtimestamp":"1641343720076824","bids":[["1.17102","28809.59400000"]],"asks":[["1.17417","11932.43465114"]]},"channel":"diff_order_book_adaeur","event":"data"}
1641343720.105043: {"data":{"timestamp":"1641343720","microtimestamp":"1641343720138901","bids":[],"asks":[["0.20858","0.00000000"]]},"channel":"diff_order_book_xlmgbp","event":"data"}
1641343720.139584: {"data":{"timestamp":"1641343720","microtimestamp":"1641343720202059","bids":[["0.00002765","21.19819168"]],"asks":[["0.00002895","0.00000000"]]},"channel":"diff_order_book_batbtc","event":"data"}
1641343720.218153: {"data":{"timestamp":"1641343720","microtimestamp":"1641343720238504","bids":[],"asks":[["1.16264","0.00000000"],["1.16455","0.00000000"],["1.16671","2785.15433412"],["1.16820","0.00000000"]]},"channel":"diff_order_book_bateur","event":"data"}
1641343720.2206259: {"data":{"timestamp":"1641343720","microtimestamp":"1641343720251787","bids":[["0.20789","0.00000000"],["0.20774","784.00000000"]],"asks":[["0.20868","5855.58528256"]]},"channel":"diff_order_book_xlmgbp","event":"data"}
1641343720.250313: {"data":{"timestamp":"1641343720","microtimestamp":"1641343720307521","bids":[],"asks":[["0.38153","15834.58496090"]]},"channel":"diff_order_book_galaeur","event":"data"}
1641343720.268573: {"data":{"timestamp":"1641343720","microtimestamp":"1641343720260339","bids":[["0.72570","0.00000000"]],"asks":[["0.73520","3100.00000000"],["0.73523","0.00000000"],["0.73529","0.00000000"],["0.73869","8838.84861015"],["0.74499","0.00000000"]]},"channel":"diff_order_book_xrpeur","event":"data"}
1641343720.286287: {"data":{"timestamp":"1641343720","microtimestamp":"1641343720335051","bids":[],"asks":[["1.17418","0.00000000"]]},"channel":"diff_order_book_adaeur","event":"data"}
1641343720.3037388: {"data":{"timestamp":"1641343720","microtimestamp":"1641343720329659","bids":[["0.00002766","7755.48688806"]],"asks":[["0.00002895","839.51711629"]]},"channel":"diff_order_book_batbtc","event":"data"}
1641343720.309298: {"data":{"timestamp":"1641343720","microtimestamp":"1641343720256843","bids":[["3800.73","14.35781476"],["3798.18","2.73248242"],["3797.91","0.00000000"]],"asks":[["3805.71","26.70924715"],["3806.71","0.00000000"]]},"channel":"diff_order_book_ethusd","event":"data"}
1641343720.335254: {"data":{"timestamp":"1641343720","microtimestamp":"1641343720365264","bids":[],"asks":[["1.16269","0.00000000"],["1.16287","2673.99143898"],["1.16333","1645.10584651"],["1.16387","0.00000000"]]},"channel":"diff_order_book_bateur","event":"data"}
1641343720.400148: {"data":{"timestamp":"1641343720","microtimestamp":"1641343720460746","bids":[["1.16956","3780.92431093"]],"asks":[["1.17374","1890.47725565"]]},"channel":"diff_order_book_adaeur","event":"data"}
1641343720.419725: {"data":{"timestamp":"1641343720","microtimestamp":"1641343720442820","bids":[["0.00002766","8616.96141823"]],"asks":[]},"channel":"diff_order_book_batbtc","event":"data"}
1641343720.4493089: {"data":{"timestamp":"1641343720","microtimestamp":"1641343720490260","bids":[["1.16036","0.00000000"],["1.15949","101.39141760"],["1.15899","0.00000000"]],"asks":[["1.16671","0.00000000"]]},"channel":"diff_order_book_bateur","event":"data"}
1641343720.4780002: {"data":{"timestamp":"1641343720","microtimestamp":"1641343720530885","bids":[],"asks":[["0.38154","0.00000000"]]},"channel":"diff_order_book_galaeur","event":"data"}
1641343720.500084: {"data":{"timestamp":"1641343720","microtimestamp":"1641343720555422","bids":[],"asks":[["0.00002846","0.00000000"],["0.00002847","2334.96080544"],["0.00002894","2787.81643958"],["0.00002898","0.00000000"]]},"channel":"diff_order_book_batbtc","event":"data"}
1641343720.5135849: {"data":{"timestamp":"1641343720","microtimestamp":"1641343720583434","bids":[["1.17101","0.00000000"]],"asks":[["1.17464","0.00000000"],["1.17961","24077.00000000"],["1.18274","0.00000000"]]},"channel":"diff_order_book_adaeur","event":"data"}
1641343720.540971: {"data":{"timestamp":"1641343720","microtimestamp":"1641343720525526","bids":[["0.73453","10168.63761652"],["0.73426","6051.00000000"]],"asks":[["0.73542","11435.13761480"]]},"channel":"diff_order_book_xrpeur","event":"data"}
1641343720.563572: {"data":{"timestamp":"1641343720","microtimestamp":"1641343720618804","bids":[["1.15979","3866.00000000"],["1.15937","1200.00000000"],["1.15679","2225.00000000"]],"asks":[["1.16332","1229.06259411"],["1.16818","2784.26162307"],["1.16819","0.00000000"]]},"channel":"diff_order_book_bateur","event":"data"}
1641343720.5734131: {"data":{"timestamp":"1641343720","microtimestamp":"1641343720598832","bids":[["0.20800","17748.12797337"],["0.20783","26627.58556714"]],"asks":[["0.20847","10650.12595113"]]},"channel":"diff_order_book_xlmgbp","event":"data"}
1641343720.577482: {"data":{"timestamp":"1641343720","microtimestamp":"1641343720562549","bids":[["3798.57","0.00000000"],["3796.02","55.47165530"]],"asks":[["3803.60","3.55000000"],["3803.76","6.63152608"],["3803.77","0.00000000"],["3804.54","0.00000000"],["3806.20","0.40068772"]]},"channel":"diff_order_book_ethusd","event":"data"}
1641343720.591975: {"data":{"timestamp":"1641343720","microtimestamp":"1641343720643383","bids":[],"asks":[["0.38370","0.00000000"]]},"channel":"diff_order_book_galaeur","event":"data"}
1641343720.619064: {"data":{"timestamp":"1641343720","microtimestamp":"1641343720670940","bids":[],"asks":[["0.00002894","0.00000000"]]},"channel":"diff_order_book_batbtc","event":"data"}
1641343720.6775281: {"data":{"timestamp":"1641343720","microtimestamp":"1641343720741130","bids":[],"asks":[["1.16817","993.44771046"]]},"channel":"diff_order_book_bateur","event":"data"}
1641343720.6781929: {"data":{"timestamp":"1641343720","microtimestamp":"1641343720703654","bids":[["1.17049","2646.66815791"]],"asks":[["1.17567","3780.95451130"]]},"channel":"diff_order_book_adaeur","event":"data"}
1641343720.6847098: {"data":{"timestamp":"1641343720","microtimestamp":"1641343720713981","bids":[],"asks":[["0.20847","0.00000000"]]},"channel":"diff_order_book_xlmgbp","event":"data"}
1641343720.705021: {"data":{"timestamp":"1641343720","microtimestamp":"1641343720754762","bids":[],"asks":[["0.38293","4654.67701754"]]},"channel":"diff_order_book_galaeur","event":"data"}
1641343720.777131: {"data":{"timestamp":"1641343720","microtimestamp":"1641343720775848","bids":[["0.73453","0.00000000"],["0.73445","6031.13333576"],["0.73442","10168.63761652"],["0.73382","0.00000000"]],"asks":[["0.73519","4900.00000000"],["0.73520","0.00000000"],["0.73521","6031.40540266"]]},"channel":"diff_order_book_xrpeur","event":"data"}
1641343720.779268: {"data":{"timestamp":"1641343720","microtimestamp":"1641343720803616","bids":[],"asks":[["0.00002894","1072.53225536"]]},"channel":"diff_order_book_batbtc","event":"data"}
1641343720.801942: {"data":{"timestamp":"1641343720","microtimestamp":"1641343720829190","bids":[["0.20805","10651.10107754"],["0.20791","0.00000000"]],"asks":[["0.20852","17753.61036891"]]},"channel":"diff_order_book_xlmgbp","event":"data"}
1641343720.8543591: {"data":{"timestamp":"1641343720","microtimestamp":"1641343720828107","bids":[["3801.44","0.00000000"],["3800.73","6.28947800"],["3800.72","0.00000000"],["3800.57","0.00000000"],["3800.53","2.10800000"],["3798.18","0.00000000"]],"asks":[["3803.59","0.70000000"],["3806.20","0.00000000"]]},"channel":"diff_order_book_ethusd","event":"data"}
1641343720.984382: {"data":{"timestamp":"1641343721","microtimestamp":"1641343721025860","bids":[],"asks":[["0.88703","0.00000"]]},"channel":"diff_order_book_usdteur","event":"data"}
1641343721.019735: {"data":{"timestamp":"1641343721","microtimestamp":"1641343721046941","bids":[],"asks":[["0.99990","0.00000"]]},"channel":"diff_order_book_usdtusd","event":"data"}
1641343721.020305: {"data":{"timestamp":"1641343721","microtimestamp":"1641343721068960","bids":[["1.16994","0.00000000"]],"asks":[]},"channel":"diff_order_book_adaeur","event":"data"}
1641343721.043357: {"data":{"timestamp":"1641343721","microtimestamp":"1641343721017741","bids":[["0.73451","0.00000000"],["0.73445","55030.19333576"],["0.73442","0.00000000"],["0.73441","0.00000000"],["0.73413","0.00000000"],["0.73412","4068.00000000"],["0.73394","18094.99440337"]],"asks":[["0.73521","0.00000000"]]},"channel":"diff_order_book_xrpeur","event":"data"}
1641343721.071462: {"data":{"timestamp":"1641343721","microtimestamp":"1641343721113576","bids":[["1.15679","0.00000000"]],"asks":[]},"channel":"diff_order_book_bateur","event":"data"}
1641343721.09969: {"data":{"timestamp":"1641343721","microtimestamp":"1641343721140010","bids":[],"asks":[["0.88703","1692.64822"]]},"channel":"diff_order_book_usdteur","event":"data"}
1641343721.133176: {"data":{"timestamp":"1641343721","microtimestamp":"1641343721162685","bids":[["0.00002766","6463.55159862"]],"asks":[]},"channel":"diff_order_book_batbtc","event":"data"}
1641343721.133725: {"data":{"timestamp":"1641343721","microtimestamp":"1641343721163577","bids":[],"asks":[["0.99988","7692.64822"]]},"channel":"diff_order_book_usdtusd","event":"data"}
1641343721.13732: {"data":{"timestamp":"1641343721","microtimestamp":"1641343721189277","bids":[["1.15657","28.62090864"]],"asks":[]},"channel":"diff_order_book_adaeur","event":"data"}
1641343721.1514418: {"data":{"timestamp":"1641343721","microtimestamp":"1641343721178138","bids":[["0.20805","0.00000000"]],"asks":[["0.20852","0.00000000"]]},"channel":"diff_order_book_xlmgbp","event":"data"}
1641343721.176756: {"data":{"id":216000500,"timestamp":"1641343721","amount":0.6,"amount_str":"0.60000000","price":3800.75,"price_str":"3800.75","type":1,"microtimestamp":"1641343721243000","buy_order_id":1443875825774594,"sell_order_id":1443875826016256},"channel":"live_trades_ethusd","event":"trade"}
1641343721.1853938: {"data":{"timestamp":"1641343721","microtimestamp":"1641343721246717","bids":[["1.15831","2225.00000000"]],"asks":[]},"channel":"diff_order_book_bateur","event":"data"}
1641343721.221728: {"data":{"id":216000501,"timestamp":"1641343721","amount":7.56178113,"amount_str":"7.56178113","price":3800.74,"price_str":"3800.74","type":1,"microtimestamp":"1641343721243000","buy_order_id":1443875824185348,"sell_order_id":1443875826016256},"channel":"live_trades_ethusd","event":"trade"}
1641343721.221819: {"data":{"id":216000502,"timestamp":"1641343721","amount":3.10111288,"amount_str":"3.10111288","price":3800.74,"price_str":"3800.74","type":1,"microtimestamp":"1641343721243000","buy_order_id":1443875824185350,"sell_order_id":1443875826016256},"channel":"live_trades_ethusd","event":"trade"}
1641343721.2218602: {"data":{"id":216000503,"timestamp":"1641343721","amount":6.289478,"amount_str":"6.28947800","price":3800.73,"price_str":"3800.73","type":1,"microtimestamp":"1641343721243000","buy_order_id":1443875820396545,"sell_order_id":1443875826016256},"channel":"live_trades_ethusd","event":"trade"}
1641343721.221892: {"data":{"id":216000504,"timestamp":"1641343721","amount":8.27640641,"amount_str":"8.27640641","price":3800.54,"price_str":"3800.54","type":1,"microtimestamp":"1641343721243000","buy_order_id":1443875824185345,"sell_order_id":1443875826016256},"channel":"live_trades_ethusd","event":"trade"}
1641343721.223592: {"data":{"id":216000505,"timestamp":"1641343721","amount":2.108,"amount_str":"2.10800000","price":3800.53,"price_str":"3800.53","type":1,"microtimestamp":"1641343721243000","buy_order_id":1443875822977028,"sell_order_id":1443875826016256},"channel":"live_trades_ethusd","event":"trade"}
1641343721.224481: {"data":{"id":216000506,"timestamp":"1641343721","amount":2.73248242,"amount_str":"2.73248242","price":3800.8,"price_str":"3800.80","type":1,"microtimestamp":"1641343721269000","buy_order_id":1443875826053121,"sell_order_id":1443875826118657},"channel":"live_trades_ethusd","event":"trade"}
1641343721.2461581: {"data":{"timestamp":"1641343721","microtimestamp":"1641343721277160","bids":[["0.00002767","2153.68632543"]],"asks":[]},"channel":"diff_order_book_batbtc","event":"data"}
1641343721.249717: {"data":{"timestamp":"1641343721","microtimestamp":"1641343721278510","bids":[],"asks":[["0.99991","0.00000"]]},"channel":"diff_order_book_usdtusd","event":"data"}
1641343721.249832: {"data":{"timestamp":"1641343721","microtimestamp":"1641343721309849","bids":[["1.15658","11499.94136679"],["1.15656","0.00000000"]],"asks":[]},"channel":"diff_order_book_adaeur","event":"data"}
1641343721.268244: {"data":{"timestamp":"1641343721","microtimestamp":"1641343721294375","bids":[["0.20791","6597.07544904"]],"asks":[]},"channel":"diff_order_book_xlmgbp","event":"data"}
1641343721.295209: {"data":{"timestamp":"1641343721","microtimestamp":"1641343721305912","bids":[["3800.78","0.60000000"],["3800.74","10.66289401"],["3800.54","8.93388405"],["3799.87","6.61452839"],["3799.16","1.70941583"],["3797.91","2.62979309"],["3787.70","0.00000000"]],"asks":[["3803.58","15.09750054"],["3803.59","0.00000000"],["3805.71","1.70924715"],["3805.95","0.40068772"],["3809.13","1.28765422"]]},"channel":"diff_order_book_ethusd","event":"data"}
1641343721.30273: {"data":{"timestamp":"1641343721","microtimestamp":"1641343721369756","bids":[["1.15960","763.58427196"]],"asks":[["1.16601","0.00000000"]]},"channel":"diff_order_book_bateur","event":"data"}
1641343721.3344152: {"data":{"timestamp":"1641343721","microtimestamp":"1641343721367441","bids":[],"asks":[["0.88704","0.00000"],["0.89654","0.00000"],["0.89655","0.00000"],["0.89918","0.00000"],["0.89919","0.00000"]]},"channel":"diff_order_book_usdteur","event":"data"}
1641343721.360692: {"data":{"timestamp":"1641343721","microtimestamp":"1641343721390798","bids":[["0.00002767","0.00000000"]],"asks":[["0.00002895","0.00000000"]]},"channel":"diff_order_book_batbtc","event":"data"}
1641343721.4268: {"data":{"timestamp":"1641343721","microtimestamp":"1641343721422939","bids":[["0.73480","6022.52500636"],["0.73451","6031.23461512"],["0.73445","6031.13333576"]],"asks":[["0.73518","1800.00000000"],["0.73519","3100.00000000"],["0.73525","6022.56856019"],["0.73530","9041.64521703"],["0.73532","6031.09000747"]]},"channel":"diff_order_book_xrpeur","event":"data"}
1641343721.448546: {"data":{"timestamp":"1641343721","microtimestamp":"1641343721481461","bids":[],"asks":[["0.89653","36000.00000"],["0.89917","24000.00000"],["0.89999","93858.89671"]]},"channel":"diff_order_book_usdteur","event":"data"}
1641343721.4692118: {"data":{"timestamp":"1641343721","microtimestamp":"1641343721496724","bids":[],"asks":[["1.16531","1200.00000000"],["1.16670","0.00000000"]]},"channel":"diff_order_book_bateur","event":"data"}
1641343721.474627: {"data":{"timestamp":"1641343721","microtimestamp":"1641343721504163","bids":[["0.00002766","7325.02612879"]],"asks":[["0.00002893","839.52157290"]]},"channel":"diff_order_book_batbtc","event":"data"}
1641343721.482126: {"data":{"timestamp":"1641343721","microtimestamp":"1641343721506497","bids":[["0.99787","0.00000"],["0.99761","0.00000"],["0.98452","0.00000"]],"asks":[["0.99994","14883.96385"],["0.99998","3000.00000"]]},"channel":"diff_order_book_usdtusd","event":"data"}
1641343721.563203: {"data":{"timestamp":"1641343721","microtimestamp":"1641343721598250","bids":[],"asks":[["0.88702","33883.96385"],["0.89655","14566.33531"],["0.89999","0.00000"]]},"channel":"diff_order_book_usdteur","event":"data"}
1641343721.617897: {"data":{"timestamp":"1641343721","microtimestamp":"1641343721663333","bids":[],"asks":[["0.38142","1163.70962488"]]},"channel":"diff_order_book_galaeur","event":"data"}
