wss://ws.prod.blockchain.info/mercury-gateway/v1/ws <-> 1626993562.522777
wss://ws.prod.blockchain.info/mercury-gateway/v1/ws <- 1626993562.745064: {"action":"subscribe","symbol":"ALGO-BTC","channel":"l2"}
wss://ws.prod.blockchain.info/mercury-gateway/v1/ws <- 1626993562.7452831: {"action":"subscribe","symbol":"ENJ-USD","channel":"l2"}
wss://ws.prod.blockchain.info/mercury-gateway/v1/ws <- 1626993562.7453482: {"action":"subscribe","symbol":"USDC-USDT","channel":"l2"}
wss://ws.prod.blockchain.info/mercury-gateway/v1/ws <- 1626993562.7454: {"action":"subscribe","symbol":"XLM-EUR","channel":"l2"}
wss://ws.prod.blockchain.info/mercury-gateway/v1/ws <- 1626993562.745447: {"action":"subscribe","symbol":"AAVE-USDT","channel":"l2"}
wss://ws.prod.blockchain.info/mercury-gateway/v1/ws <- 1626993562.745492: {"action":"subscribe","symbol":"AAVE-USD","channel":"l2"}
wss://ws.prod.blockchain.info/mercury-gateway/v1/ws <- 1626993562.745536: {"action":"subscribe","symbol":"YFI-USDT","channel":"l2"}
wss://ws.prod.blockchain.info/mercury-gateway/v1/ws <- 1626993562.745578: {"action":"subscribe","symbol":"DAI-USDT","channel":"l2"}
wss://ws.prod.blockchain.info/mercury-gateway/v1/ws <- 1626993562.74562: {"action":"subscribe","symbol":"DGLD-USD","channel":"l2"}
wss://ws.prod.blockchain.info/mercury-gateway/v1/ws <- 1626993562.7456691: {"action":"subscribe","symbol":"ENJ-USDT","channel":"l2"}
wss://ws.prod.blockchain.info/mercury-gateway/v1/ws <- 1626993562.745715: {"action":"subscribe","symbol":"ALGO-BTC","channel":"trades"}
wss://ws.prod.blockchain.info/mercury-gateway/v1/ws <- 1626993562.7457569: {"action":"subscribe","symbol":"ENJ-USD","channel":"trades"}
wss://ws.prod.blockchain.info/mercury-gateway/v1/ws <- 1626993562.7457988: {"action":"subscribe","symbol":"USDC-USDT","channel":"trades"}
wss://ws.prod.blockchain.info/mercury-gateway/v1/ws <- 1626993562.7458408: {"action":"subscribe","symbol":"XLM-EUR","channel":"trades"}
wss://ws.prod.blockchain.info/mercury-gateway/v1/ws <- 1626993562.745883: {"action":"subscribe","symbol":"AAVE-USDT","channel":"trades"}
wss://ws.prod.blockchain.info/mercury-gateway/v1/ws <- 1626993562.745924: {"action":"subscribe","symbol":"AAVE-USD","channel":"trades"}
wss://ws.prod.blockchain.info/mercury-gateway/v1/ws <- 1626993562.745965: {"action":"subscribe","symbol":"YFI-USDT","channel":"trades"}
wss://ws.prod.blockchain.info/mercury-gateway/v1/ws <- 1626993562.7460108: {"action":"subscribe","symbol":"DAI-USDT","channel":"trades"}
wss://ws.prod.blockchain.info/mercury-gateway/v1/ws <- 1626993562.746054: {"action":"subscribe","symbol":"DGLD-USD","channel":"trades"}
wss://ws.prod.blockchain.info/mercury-gateway/v1/ws <- 1626993562.7460961: {"action":"subscribe","symbol":"ENJ-USDT","channel":"trades"}
1626993562.845044: {"seqnum":0,"event":"subscribed","channel":"l2","symbol":"ALGO-BTC","batching":false}
1626993562.845098: {"seqnum":1,"event":"snapshot","channel":"l2","symbol":"ALGO-BTC","bids":[{"num":1,"px":1.6E-7,"qty":200.0},{"num":2,"px":1.0E-5,"qty":750.0},{"num":1,"px":1.1E-5,"qty":50.0},{"num":1,"px":1.5E-5,"qty":350.0},{"num":1,"px":2.0E-5,"qty":250.0},{"num":1,"px":2.138E-5,"qty":20.000001},{"num":1,"px":2.178E-5,"qty":20.000001},{"num":1,"px":2.21E-5,"qty":20.000001},{"num":1,"px":2.231E-5,"qty":20.000001},{"num":1,"px":2.443E-5,"qty":6335.03},{"num":1,"px":2.444E-5,"qty":6333.45},{"num":1,"px":2.447E-5,"qty":6335.87},{"num":1,"px":2.448E-5,"qty":8869.04},{"num":1,"px":2.449E-5,"qty":2534.1},{"num":1,"px":2.45E-5,"qty":2533.9}],"asks":[{"num":1,"px":2.454E-5,"qty":2534.63},{"num":1,"px":2.455E-5,"qty":2534.64},{"num":1,"px":2.456E-5,"qty":6336.6},{"num":2,"px":2.457E-5,"qty":6435.045902},{"num":1,"px":2.458E-5,"qty":6336.4},{"num":1,"px":2.463E-5,"qty":6331.88},{"num":1,"px":2.495E-5,"qty":23.945008},{"num":1,"px":2.519E-5,"qty":23.946201},{"num":1,"px":2.555E-5,"qty":23.947948},{"num":1,"px":2.604E-5,"qty":23.941013},{"num":1,"px":2.673E-5,"qty":67.088568},{"num":1,"px":2.8E-5,"qty":258.48169},{"num":1,"px":4.425E-5,"qty":23.947499},{"num":1,"px":7.598E-5,"qty":1923.074793}],"timestamp":"2021-07-22T22:39:22.851917Z"}
1626993562.845603: {"seqnum":2,"event":"subscribed","channel":"l2","symbol":"ENJ-USD","batching":false}
1626993562.845623: {"seqnum":3,"event":"snapshot","channel":"l2","symbol":"ENJ-USD","bids":[{"num":1,"px":0.0025,"qty":22172.669427},{"num":1,"px":0.5929,"qty":2.000001},{"num":1,"px":0.85,"qty":12.25},{"num":1,"px":0.9,"qty":73.596923},{"num":1,"px":0.95,"qty":847.0},{"num":1,"px":1.052,"qty":2.000001},{"num":1,"px":1.072,"qty":470.0}],"asks":[{"num":1,"px":1.1255,"qty":8333.333333},{"num":1,"px":1.1312,"qty":8333.333333},{"num":1,"px":1.1368,"qty":8333.333333},{"num":1,"px":1.1635,"qty":10.096693},{"num":1,"px":1.1748,"qty":10.096283},{"num":1,"px":1.1916,"qty":10.096951},{"num":1,"px":1.214,"qty":10.096982},{"num":1,"px":1.25,"qty":882.89863},{"num":1,"px":1.3,"qty":6.763506},{"num":1,"px":1.34,"qty":59.401192},{"num":1,"px":1.36,"qty":38.452821},{"num":1,"px":1.5,"qty":122.182449},{"num":1,"px":1.615,"qty":79.176057},{"num":1,"px":1.65,"qty":145.0},{"num":1,"px":1.8,"qty":4.2},{"num":1,"px":1.89,"qty":144.740625},{"num":1,"px":1.99,"qty":36.6},{"num":2,"px":2.0,"qty":431.032141},{"num":1,"px":2.0639,"qty":10.096689},{"num":3,"px":2.5,"qty":1279.604615},{"num":1,"px":2.55,"qty":250.0},{"num":1,"px":2.68,"qty":108.0},{"num":1,"px":2.72,"qty":84.031857},{"num":1,"px":2.745,"qty":119.123321},{"num":1,"px":3.0,"qty":7.278601},{"num":1,"px":3.42,"qty":179.968096},{"num":3,"px":3.5,"qty":473.687642},{"num":1,"px":4.9,"qty":102.488786},{"num":1,"px":10.0,"qty":193.564466},{"num":1,"px":100.0,"qty":100.0},{"num":1,"px":1000.0,"qty":100.0}],"timestamp":"2021-07-22T22:39:22.852015Z"}
1626993562.845898: {"seqnum":4,"event":"subscribed","channel":"l2","symbol":"USDC-USDT","batching":false}
1626993562.8459148: {"seqnum":5,"event":"snapshot","channel":"l2","symbol":"USDC-USDT","bids":[{"num":1,"px":0.0029,"qty":37822.0566},{"num":1,"px":0.003,"qty":42145.9028},{"num":1,"px":0.0099,"qty":7792.1741},{"num":1,"px":0.9989,"qty":99.0},{"num":1,"px":0.9992,"qty":50000.0},{"num":1,"px":1.0003,"qty":50000.0}],"asks":[{"num":1,"px":1.0074,"qty":50000.0},{"num":1,"px":1.0075,"qty":59.9},{"num":1,"px":1.0085,"qty":50000.0},{"num":1,"px":1.034,"qty":8.9142},{"num":1,"px":1.044,"qty":8.9142},{"num":1,"px":1.059,"qty":8.9142},{"num":1,"px":1.079,"qty":8.9142},{"num":1,"px":1.8342,"qty":8.9142}],"timestamp":"2021-07-22T22:39:22.852146Z"}
1626993562.84606: {"seqnum":6,"event":"subscribed","channel":"l2","symbol":"XLM-EUR","batching":false}
1626993562.846446: {"seqnum":7,"event":"snapshot","channel":"l2","symbol":"XLM-EUR","bids":[{"num":1,"px":0.0036,"qty":10000.0},{"num":1,"px":0.1546,"qty":30174.1357914},{"num":1,"px":0.17,"qty":1592.4532731},{"num":1,"px":0.17109,"qty":116.1879358},{"num":1,"px":0.2,"qty":1987.6097613},{"num":1,"px":0.203,"qty":2343.6337717},{"num":1,"px":0.21,"qty":248.978882},{"num":1,"px":0.21138,"qty":235.6960794},{"num":1,"px":0.21908,"qty":23199.9},{"num":1,"px":0.21921,"qty":23181.31},{"num":1,"px":0.21947,"qty":40582.46},{"num":1,"px":0.21959,"qty":15461.42}],"asks":[{"num":1,"px":0.22004,"qty":15462.26},{"num":1,"px":0.22007,"qty":40606.41},{"num":1,"px":0.22039,"qty":23189.4},{"num":1,"px":0.22064,"qty":23181.31},{"num":1,"px":0.23999,"qty":282.2068536},{"num":2,"px":0.24,"qty":22403.33063},{"num":1,"px":0.24038,"qty":71.0},{"num":1,"px":0.24039,"qty":78.9549932},{"num":1,"px":0.25,"qty":76.3235003},{"num":1,"px":0.258,"qty":142.5689443},{"num":1,"px":0.2862,"qty":117.0},{"num":2,"px":0.3,"qty":9086.0162962},{"num":1,"px":0.3012,"qty":6885.9805227},{"num":1,"px":0.35,"qty":653.3560639},{"num":1,"px":0.36,"qty":264.0},{"num":1,"px":0.39,"qty":250.3841997},{"num":1,"px":0.43056,"qty":97.65},{"num":1,"px":0.45,"qty":12221.3573183},{"num":1,"px":0.456,"qty":5161.1541813},{"num":1,"px":0.495,"qty":96.3},{"num":1,"px":0.5,"qty":444.878619},{"num":1,"px":0.50999,"qty":75.0},{"num":1,"px":0.52,"qty":72.868836},{"num":4,"px":0.55,"qty":2716.3995287},{"num":1,"px":0.565,"qty":275.0},{"num":4,"px":0.6,"qty":4201.7263105},{"num":1,"px":0.62,"qty":11142.8324285},{"num":1,"px":0.63,"qty":4947.2083223},{"num":1,"px":0.65,"qty":162.5726861},{"num":1,"px":0.67,"qty":665.1747998},{"num":1,"px":0.68,"qty":3921.7105932},{"num":2,"px":0.7,"qty":953.8455996},{"num":1,"px":0.75,"qty":5360.4737884},{"num":1,"px":0.8514,"qty":9523.7166892},{"num":1,"px":1.05432,"qty":7142.7875169},{"num":1,"px":1.546,"qty":10714.1812755},{"num":1,"px":1.8,"qty":5357.0906377},{"num":1,"px":9.68,"qty":367.7586647}],"timestamp":"2021-07-22T22:39:22.852194Z"}
1626993562.846818: {"seqnum":8,"event":"subscribed","channel":"l2","symbol":"AAVE-USDT","batching":false}
1626993562.8468359: {"seqnum":9,"event":"snapshot","channel":"l2","symbol":"AAVE-USDT","bids":[{"num":1,"px":0.1,"qty":10.0},{"num":1,"px":3.27,"qty":5.0},{"num":1,"px":5.28,"qty":18.90536428},{"num":1,"px":5.69,"qty":9.58011934},{"num":1,"px":5.79,"qty":0.96798743},{"num":1,"px":256.66,"qty":0.03500001}],"asks":[{"num":1,"px":414.0,"qty":0.6659007},{"num":1,"px":415.0,"qty":0.09381822}],"timestamp":"2021-07-22T22:39:22.852297Z"}
1626993562.8469388: {"seqnum":10,"event":"subscribed","channel":"l2","symbol":"AAVE-USD","batching":false}
1626993562.846953: {"seqnum":11,"event":"snapshot","channel":"l2","symbol":"AAVE-USD","bids":[{"num":1,"px":2.23,"qty":21.0},{"num":1,"px":2.25,"qty":54.78},{"num":1,"px":36.0,"qty":1.0},{"num":1,"px":37.0,"qty":1.0},{"num":1,"px":190.0,"qty":1.0},{"num":1,"px":200.01,"qty":0.5},{"num":1,"px":259.5,"qty":0.03500001}],"asks":[{"num":1,"px":262.6,"qty":0.0351},{"num":1,"px":280.0,"qty":0.11040943},{"num":2,"px":285.0,"qty":1.20873451},{"num":1,"px":288.6,"qty":0.79587843},{"num":1,"px":299.0,"qty":0.75312723},{"num":1,"px":329.0,"qty":0.3153294},{"num":1,"px":399.0,"qty":0.55616024},{"num":3,"px":400.0,"qty":2.69064277},{"num":1,"px":438.99,"qty":0.47610667},{"num":1,"px":439.0,"qty":0.55616025},{"num":1,"px":440.0,"qty":5.86317273},{"num":1,"px":471.0,"qty":1.11232049},{"num":1,"px":473.89,"qty":1.0},{"num":1,"px":473.9,"qty":0.86050045},{"num":1,"px":503.73,"qty":0.2853},{"num":1,"px":700.0,"qty":1.0},{"num":1,"px":750.0,"qty":0.15961553},{"num":1,"px":2000.0,"qty":5.2591114},{"num":1,"px":6000.0,"qty":0.17},{"num":1,"px":11000.0,"qty":0.2}],"timestamp":"2021-07-22T22:39:22.852320Z"}
1626993562.847143: {"seqnum":12,"event":"subscribed","channel":"l2","symbol":"YFI-USDT","batching":false}
1626993562.847158: {"seqnum":13,"event":"snapshot","channel":"l2","symbol":"YFI-USDT","bids":[{"num":1,"px":58.9,"qty":0.1},{"num":1,"px":159.1,"qty":0.56979607},{"num":1,"px":177.38,"qty":0.05814736},{"num":1,"px":188.79,"qty":0.21503668},{"num":1,"px":196.33,"qty":1.32038262},{"num":1,"px":27683.25,"qty":0.03333333},{"num":1,"px":27737.74,"qty":0.03333333},{"num":1,"px":27792.45,"qty":0.03333333},{"num":1,"px":28244.04,"qty":0.5},{"num":1,"px":28272.32,"qty":0.5}],"asks":[{"num":1,"px":28655.62,"qty":0.03333333},{"num":1,"px":28709.86,"qty":0.03333333},{"num":1,"px":28766.37,"qty":0.03333333}],"timestamp":"2021-07-22T22:39:22.852409Z"}
1626993562.8474162: {"seqnum":14,"event":"subscribed","channel":"l2","symbol":"DAI-USDT","batching":false}
1626993562.847869: {"seqnum":15,"event":"snapshot","channel":"l2","symbol":"DAI-USDT","bids":[{"num":1,"px":0.0025,"qty":24669.4969},{"num":1,"px":0.998,"qty":25000.0},{"num":1,"px":0.999,"qty":25000.0}],"asks":[{"num":1,"px":1.0031,"qty":25000.0},{"num":1,"px":1.0042,"qty":25000.0}],"timestamp":"2021-07-22T22:39:22.852458Z"}
1626993562.847988: {"seqnum":16,"event":"subscribed","channel":"l2","symbol":"DGLD-USD","batching":false}
1626993562.848018: {"seqnum":17,"event":"snapshot","channel":"l2","symbol":"DGLD-USD","bids":[{"num":1,"px":0.01,"qty":4306.76328336},{"num":1,"px":2.1,"qty":30.0},{"num":1,"px":3.45,"qty":15.0},{"num":1,"px":75.1,"qty":1.0},{"num":1,"px":120.0,"qty":0.31538947},{"num":1,"px":137.0,"qty":2.5},{"num":1,"px":148.0,"qty":2.0},{"num":1,"px":163.0,"qty":2.0},{"num":1,"px":173.88,"qty":0.03500001},{"num":1,"px":176.11,"qty":50.0},{"num":1,"px":176.29,"qty":50.0},{"num":1,"px":177.0,"qty":66.0},{"num":1,"px":177.22,"qty":60.0}],"asks":[{"num":1,"px":177.48,"qty":50.0},{"num":1,"px":177.56,"qty":60.0},{"num":1,"px":177.66,"qty":50.0},{"num":1,"px":177.78,"qty":66.0},{"num":1,"px":185.0,"qty":0.12746315},{"num":1,"px":187.62,"qty":0.08047226},{"num":1,"px":189.43,"qty":0.08047417},{"num":1,"px":192.14,"qty":0.08047487},{"num":1,"px":195.77,"qty":0.0804744},{"num":1,"px":201.6,"qty":0.37265429},{"num":1,"px":332.8,"qty":0.08047489},{"num":1,"px":5000.0,"qty":0.036}],"timestamp":"2021-07-22T22:39:22.852505Z"}
1626993562.848177: {"seqnum":18,"event":"subscribed","channel":"l2","symbol":"ENJ-USDT","batching":false}
1626993562.84819: {"seqnum":19,"event":"snapshot","channel":"l2","symbol":"ENJ-USDT","bids":[{"num":1,"px":1.0E-4,"qty":10000.0},{"num":1,"px":0.001,"qty":1000.0},{"num":1,"px":0.0029,"qty":16403.42462},{"num":1,"px":0.01,"qty":100.0},{"num":1,"px":0.041,"qty":1437.337116},{"num":1,"px":0.0411,"qty":1290.455951},{"num":1,"px":0.0451,"qty":69.8274},{"num":1,"px":0.593,"qty":2.000001},{"num":1,"px":0.8973,"qty":16.2},{"num":1,"px":0.9954,"qty":21.046855},{"num":1,"px":1.0421,"qty":2.000001},{"num":1,"px":1.0522,"qty":2.000001},{"num":1,"px":1.062,"qty":18.0},{"num":1,"px":1.0931,"qty":10000.0},{"num":1,"px":1.0952,"qty":10000.0},{"num":1,"px":1.0974,"qty":10000.0}],"asks":[{"num":1,"px":1.1178,"qty":10000.0},{"num":1,"px":1.1197,"qty":10000.0},{"num":1,"px":1.1219,"qty":10000.0},{"num":1,"px":1.1607,"qty":10.096392},{"num":1,"px":1.1709,"qty":19.054241},{"num":1,"px":1.1719,"qty":10.096608},{"num":1,"px":1.1887,"qty":10.096925},{"num":1,"px":1.2111,"qty":10.096501},{"num":1,"px":1.3709,"qty":38.45282},{"num":1,"px":1.45,"qty":38.895646},{"num":1,"px":1.924,"qty":35.917418},{"num":1,"px":2.0588,"qty":10.09704},{"num":2,"px":2.5,"qty":71.345068},{"num":1,"px":3.5,"qty":85.234397}],"timestamp":"2021-07-22T22:39:22.852556Z"}
1626993562.8483782: {"seqnum":20,"event":"subscribed","channel":"trades","symbol":"ALGO-BTC"}
1626993562.8483908: {"seqnum":21,"event":"subscribed","channel":"trades","symbol":"ENJ-USD"}
1626993562.8483992: {"seqnum":22,"event":"subscribed","channel":"trades","symbol":"USDC-USDT"}
1626993562.848407: {"seqnum":23,"event":"subscribed","channel":"trades","symbol":"XLM-EUR"}
1626993562.848414: {"seqnum":24,"event":"subscribed","channel":"trades","symbol":"AAVE-USDT"}
1626993562.848421: {"seqnum":25,"event":"subscribed","channel":"trades","symbol":"AAVE-USD"}
1626993562.848428: {"seqnum":26,"event":"subscribed","channel":"trades","symbol":"YFI-USDT"}
1626993562.848435: {"seqnum":27,"event":"subscribed","channel":"trades","symbol":"DAI-USDT"}
1626993562.848442: {"seqnum":28,"event":"subscribed","channel":"trades","symbol":"DGLD-USD"}
1626993562.848449: {"seqnum":29,"event":"subscribed","channel":"trades","symbol":"ENJ-USDT"}
1626993563.677196: {"seqnum":30,"event":"updated","channel":"l2","symbol":"ENJ-USDT","bids":[{"num":0,"px":1.0952,"qty":0.0}],"asks":[],"timestamp":"2021-07-22T22:39:23.637085Z"}
1626993563.6773498: {"seqnum":31,"event":"updated","channel":"l2","symbol":"ENJ-USDT","bids":[],"asks":[{"num":0,"px":1.1178,"qty":0.0}],"timestamp":"2021-07-22T22:39:23.637113Z"}
1626993563.6774201: {"seqnum":32,"event":"updated","channel":"l2","symbol":"ENJ-USDT","bids":[{"num":0,"px":1.0931,"qty":0.0}],"asks":[],"timestamp":"2021-07-22T22:39:23.637121Z"}
1626993563.6774762: {"seqnum":33,"event":"updated","channel":"l2","symbol":"ENJ-USDT","bids":[],"asks":[{"num":0,"px":1.1219,"qty":0.0}],"timestamp":"2021-07-22T22:39:23.637129Z"}
1626993563.677526: {"seqnum":34,"event":"updated","channel":"l2","symbol":"ENJ-USDT","bids":[],"asks":[{"num":0,"px":1.1197,"qty":0.0}],"timestamp":"2021-07-22T22:39:23.637137Z"}
1626993563.680238: {"seqnum":35,"event":"updated","channel":"l2","symbol":"ENJ-USDT","bids":[{"num":0,"px":1.0974,"qty":0.0}],"asks":[],"timestamp":"2021-07-22T22:39:23.637145Z"}
1626993563.680375: {"seqnum":36,"event":"updated","channel":"l2","symbol":"YFI-USDT","bids":[{"num":0,"px":27683.25,"qty":0.0}],"asks":[],"timestamp":"2021-07-22T22:39:23.637152Z"}
1626993563.68044: {"seqnum":37,"event":"updated","channel":"l2","symbol":"YFI-USDT","bids":[],"asks":[{"num":0,"px":28709.86,"qty":0.0}],"timestamp":"2021-07-22T22:39:23.637163Z"}
1626993563.680495: {"seqnum":38,"event":"updated","channel":"l2","symbol":"YFI-USDT","bids":[],"asks":[{"num":0,"px":28766.37,"qty":0.0}],"timestamp":"2021-07-22T22:39:23.637171Z"}
1626993563.680545: {"seqnum":39,"event":"updated","channel":"l2","symbol":"YFI-USDT","bids":[{"num":0,"px":27737.74,"qty":0.0}],"asks":[],"timestamp":"2021-07-22T22:39:23.637181Z"}
1626993563.6805902: {"seqnum":40,"event":"updated","channel":"l2","symbol":"YFI-USDT","bids":[],"asks":[{"num":0,"px":28655.62,"qty":0.0}],"timestamp":"2021-07-22T22:39:23.637189Z"}
1626993563.680639: {"seqnum":41,"event":"updated","channel":"l2","symbol":"YFI-USDT","bids":[{"num":0,"px":27792.45,"qty":0.0}],"asks":[],"timestamp":"2021-07-22T22:39:23.637198Z"}
1626993564.445784: {"seqnum":42,"event":"updated","channel":"l2","symbol":"XLM-EUR","bids":[{"num":0,"px":0.21959,"qty":0.0}],"asks":[],"timestamp":"2021-07-22T22:39:24.388812Z"}
1626993564.5452101: {"seqnum":43,"event":"updated","channel":"l2","symbol":"XLM-EUR","bids":[{"num":1,"px":0.21966,"qty":15458.47}],"asks":[],"timestamp":"2021-07-22T22:39:24.535788Z"}
1626993564.600677: {"seqnum":44,"event":"updated","channel":"l2","symbol":"XLM-EUR","bids":[],"asks":[{"num":0,"px":0.22007,"qty":0.0}],"timestamp":"2021-07-22T22:39:24.571801Z"}
1626993564.684555: {"seqnum":45,"event":"updated","channel":"l2","symbol":"ENJ-USDT","bids":[{"num":1,"px":1.0956,"qty":10000.0}],"asks":[],"timestamp":"2021-07-22T22:39:24.639797Z"}
1626993564.6846888: {"seqnum":46,"event":"updated","channel":"l2","symbol":"ENJ-USDT","bids":[{"num":1,"px":1.0934,"qty":10000.0}],"asks":[],"timestamp":"2021-07-22T22:39:24.639803Z"}
1626993564.684763: {"seqnum":47,"event":"updated","channel":"l2","symbol":"ENJ-USDT","bids":[{"num":1,"px":1.0913,"qty":10000.0}],"asks":[],"timestamp":"2021-07-22T22:39:24.639810Z"}
1626993564.684819: {"seqnum":48,"event":"updated","channel":"l2","symbol":"ENJ-USDT","bids":[],"asks":[{"num":1,"px":1.1161,"qty":10000.0}],"timestamp":"2021-07-22T22:39:24.659788Z"}
1626993564.68485: {"seqnum":49,"event":"updated","channel":"l2","symbol":"YFI-USDT","bids":[{"num":1,"px":27683.28,"qty":0.03333333}],"asks":[],"timestamp":"2021-07-22T22:39:24.659795Z"}
1626993564.684882: {"seqnum":50,"event":"updated","channel":"l2","symbol":"YFI-USDT","bids":[],"asks":[{"num":1,"px":28655.38,"qty":0.03333333}],"timestamp":"2021-07-22T22:39:24.659803Z"}
1626993564.684909: {"seqnum":51,"event":"updated","channel":"l2","symbol":"YFI-USDT","bids":[{"num":1,"px":27792.49,"qty":0.03333333}],"asks":[],"timestamp":"2021-07-22T22:39:24.659810Z"}
1626993564.6849349: {"seqnum":52,"event":"updated","channel":"l2","symbol":"YFI-USDT","bids":[{"num":1,"px":27737.78,"qty":0.03333333}],"asks":[],"timestamp":"2021-07-22T22:39:24.659932Z"}
1626993565.572685: {"seqnum":53,"event":"updated","channel":"l2","symbol":"ENJ-USDT","bids":[],"asks":[{"num":1,"px":1.118,"qty":10000.0}],"timestamp":"2021-07-22T22:39:25.479809Z"}
1626993565.5728152: {"seqnum":54,"event":"updated","channel":"l2","symbol":"ENJ-USDT","bids":[],"asks":[{"num":1,"px":1.1203,"qty":10000.0}],"timestamp":"2021-07-22T22:39:25.479816Z"}
1626993565.572879: {"seqnum":55,"event":"updated","channel":"l2","symbol":"XLM-EUR","bids":[],"asks":[{"num":1,"px":0.22023,"qty":40576.46}],"timestamp":"2021-07-22T22:39:25.511909Z"}
1626993565.666604: {"seqnum":56,"event":"updated","channel":"l2","symbol":"YFI-USDT","bids":[],"asks":[{"num":1,"px":28711.64,"qty":0.03333333}],"timestamp":"2021-07-22T22:39:25.647858Z"}
1626993565.666692: {"seqnum":57,"event":"updated","channel":"l2","symbol":"YFI-USDT","bids":[],"asks":[{"num":1,"px":28768.16,"qty":0.03333333}],"timestamp":"2021-07-22T22:39:25.647865Z"}
1626993570.960483: {"seqnum":58,"event":"updated","channel":"l2","symbol":"ALGO-BTC","bids":[{"num":0,"px":2.45E-5,"qty":0.0}],"asks":[],"timestamp":"2021-07-22T22:39:30.951809Z"}
1626993571.053985: {"seqnum":59,"event":"updated","channel":"l2","symbol":"ALGO-BTC","bids":[{"num":0,"px":2.443E-5,"qty":0.0}],"asks":[],"timestamp":"2021-07-22T22:39:31.007784Z"}
1626993571.136802: {"seqnum":60,"event":"updated","channel":"l2","symbol":"ALGO-BTC","bids":[{"num":1,"px":2.446E-5,"qty":6337.25}],"asks":[],"timestamp":"2021-07-22T22:39:31.131783Z"}
1626993571.136929: {"seqnum":61,"event":"updated","channel":"l2","symbol":"ALGO-BTC","bids":[{"num":1,"px":2.445E-5,"qty":6337.25}],"asks":[],"timestamp":"2021-07-22T22:39:31.131790Z"}
1626993571.281058: {"seqnum":62,"event":"updated","channel":"l2","symbol":"ALGO-BTC","bids":[],"asks":[{"num":0,"px":2.455E-5,"qty":0.0}],"timestamp":"2021-07-22T22:39:31.271801Z"}
1626993571.4682722: {"seqnum":63,"event":"updated","channel":"l2","symbol":"ALGO-BTC","bids":[],"asks":[{"num":1,"px":2.455E-5,"qty":6337.25}],"timestamp":"2021-07-22T22:39:31.439807Z"}
1626993572.835283: {"seqnum":64,"event":"updated","channel":"l2","symbol":"ALGO-BTC","bids":[{"num":0,"px":2.449E-5,"qty":0.0}],"asks":[],"timestamp":"2021-07-22T22:39:32.831813Z"}
1626993572.835351: {"seqnum":65,"event":"updated","channel":"l2","symbol":"ALGO-BTC","bids":[{"num":0,"px":2.444E-5,"qty":0.0}],"asks":[],"timestamp":"2021-07-22T22:39:32.831821Z"}
1626993572.9859378: {"seqnum":66,"event":"updated","channel":"l2","symbol":"ALGO-BTC","bids":[{"num":1,"px":2.45E-5,"qty":2534.78}],"asks":[],"timestamp":"2021-07-22T22:39:32.971784Z"}
1626993572.9860868: {"seqnum":67,"event":"updated","channel":"l2","symbol":"ALGO-BTC","bids":[{"num":1,"px":2.449E-5,"qty":6336.93}],"asks":[],"timestamp":"2021-07-22T22:39:32.971791Z"}
1626993579.80637: {"seqnum":68,"event":"updated","channel":"l2","symbol":"XLM-EUR","bids":[{"num":0,"px":0.21966,"qty":0.0}],"asks":[],"timestamp":"2021-07-22T22:39:39.795810Z"}
1626993579.934859: {"seqnum":69,"event":"updated","channel":"l2","symbol":"XLM-EUR","bids":[{"num":1,"px":0.21972,"qty":15456.15}],"asks":[],"timestamp":"2021-07-22T22:39:39.923802Z"}
1626993580.522324: {"seqnum":70,"event":"updated","channel":"l2","symbol":"ALGO-BTC","bids":[],"asks":[{"num":0,"px":2.454E-5,"qty":0.0}],"timestamp":"2021-07-22T22:39:40.491799Z"}
1626993580.52242: {"seqnum":71,"event":"updated","channel":"l2","symbol":"ALGO-BTC","bids":[],"asks":[{"num":0,"px":2.456E-5,"qty":0.0}],"timestamp":"2021-07-22T22:39:40.491815Z"}
1626993580.685766: {"seqnum":72,"event":"updated","channel":"l2","symbol":"ALGO-BTC","bids":[],"asks":[{"num":1,"px":2.456E-5,"qty":2534.47}],"timestamp":"2021-07-22T22:39:40.667798Z"}
1626993580.685895: {"seqnum":73,"event":"updated","channel":"l2","symbol":"ALGO-BTC","bids":[],"asks":[{"num":1,"px":2.459E-5,"qty":6335.98}],"timestamp":"2021-07-22T22:39:40.667805Z"}
1626993586.664108: {"seqnum":74,"event":"updated","channel":"l2","symbol":"XLM-EUR","bids":[{"num":0,"px":0.21947,"qty":0.0}],"asks":[],"timestamp":"2021-07-22T22:39:46.615798Z"}
1626993586.795889: {"seqnum":75,"event":"updated","channel":"l2","symbol":"XLM-EUR","bids":[{"num":1,"px":0.21959,"qty":40573.36}],"asks":[],"timestamp":"2021-07-22T22:39:46.787799Z"}
1626993586.880946: {"seqnum":76,"event":"updated","channel":"l2","symbol":"ALGO-BTC","bids":[],"asks":[{"num":0,"px":2.455E-5,"qty":0.0}],"timestamp":"2021-07-22T22:39:46.876964Z"}
1626993586.948073: {"seqnum":77,"event":"updated","channel":"l2","symbol":"ALGO-BTC","bids":[],"asks":[{"num":0,"px":2.463E-5,"qty":0.0}],"timestamp":"2021-07-22T22:39:46.939800Z"}
1626993587.0780602: {"seqnum":78,"event":"updated","channel":"l2","symbol":"ALGO-BTC","bids":[],"asks":[{"num":1,"px":2.46E-5,"qty":6334.89}],"timestamp":"2021-07-22T22:39:47.047798Z"}
1626993587.07819: {"seqnum":79,"event":"updated","channel":"l2","symbol":"ALGO-BTC","bids":[],"asks":[{"num":1,"px":2.461E-5,"qty":6334.89}],"timestamp":"2021-07-22T22:39:47.047805Z"}
1626993587.204654: {"seqnum":80,"event":"updated","channel":"l2","symbol":"ALGO-BTC","bids":[],"asks":[{"num":0,"px":2.461E-5,"qty":0.0}],"timestamp":"2021-07-22T22:39:47.187788Z"}
1626993587.319689: {"seqnum":81,"event":"updated","channel":"l2","symbol":"ALGO-BTC","bids":[],"asks":[{"num":1,"px":2.455E-5,"qty":2533.96}],"timestamp":"2021-07-22T22:39:47.315802Z"}
1626993587.998085: {"seqnum":82,"event":"updated","channel":"l2","symbol":"ALGO-BTC","bids":[{"num":0,"px":2.445E-5,"qty":0.0}],"asks":[],"timestamp":"2021-07-22T22:39:47.951787Z"}
1626993588.1054919: {"seqnum":83,"event":"updated","channel":"l2","symbol":"ALGO-BTC","bids":[{"num":1,"px":2.451E-5,"qty":2533.94}],"asks":[],"timestamp":"2021-07-22T22:39:48.051808Z"}
1626993591.150743: {"seqnum":84,"event":"updated","channel":"l2","symbol":"ALGO-BTC","bids":[],"asks":[{"num":0,"px":2.455E-5,"qty":0.0}],"timestamp":"2021-07-22T22:39:51.119785Z"}
1626993591.200657: {"seqnum":85,"event":"updated","channel":"l2","symbol":"ALGO-BTC","bids":[],"asks":[{"num":0,"px":2.456E-5,"qty":0.0}],"timestamp":"2021-07-22T22:39:51.175845Z"}
1626993591.200752: {"seqnum":86,"event":"updated","channel":"l2","symbol":"ALGO-BTC","bids":[{"num":0,"px":2.448E-5,"qty":0.0}],"asks":[],"timestamp":"2021-07-22T22:39:51.175853Z"}
1626993591.231976: {"seqnum":87,"event":"updated","channel":"l2","symbol":"ALGO-BTC","bids":[],"asks":[{"num":1,"px":2.457E-5,"qty":98.935902}],"timestamp":"2021-07-22T22:39:51.219803Z"}
1626993591.312886: {"seqnum":88,"event":"updated","channel":"l2","symbol":"ALGO-BTC","bids":[],"asks":[{"num":0,"px":2.46E-5,"qty":0.0}],"timestamp":"2021-07-22T22:39:51.283798Z"}
1626993591.418498: {"seqnum":89,"event":"updated","channel":"l2","symbol":"ALGO-BTC","bids":[],"asks":[{"num":2,"px":2.457E-5,"qty":2631.635902}],"timestamp":"2021-07-22T22:39:51.403783Z"}
1626993591.418615: {"seqnum":90,"event":"updated","channel":"l2","symbol":"ALGO-BTC","bids":[{"num":1,"px":2.452E-5,"qty":2531.78}],"asks":[],"timestamp":"2021-07-22T22:39:51.403791Z"}
1626993591.418686: {"seqnum":91,"event":"updated","channel":"l2","symbol":"ALGO-BTC","bids":[],"asks":[{"num":1,"px":2.46E-5,"qty":8861.2}],"timestamp":"2021-07-22T22:39:51.403798Z"}
1626993591.418741: {"seqnum":92,"event":"updated","channel":"l2","symbol":"ALGO-BTC","bids":[],"asks":[{"num":1,"px":2.464E-5,"qty":6331.74}],"timestamp":"2021-07-22T22:39:51.403806Z"}
1626993591.418794: {"seqnum":93,"event":"updated","channel":"l2","symbol":"ALGO-BTC","bids":[],"asks":[{"num":1,"px":2.465E-5,"qty":6329.72}],"timestamp":"2021-07-22T22:39:51.403813Z"}
1626993591.418858: {"seqnum":94,"event":"updated","channel":"l2","symbol":"ALGO-BTC","bids":[],"asks":[{"num":0,"px":2.459E-5,"qty":0.0}],"timestamp":"2021-07-22T22:39:51.403828Z"}
1626993591.604956: {"seqnum":95,"event":"updated","channel":"l2","symbol":"ALGO-BTC","bids":[],"asks":[{"num":1,"px":2.457E-5,"qty":98.935902}],"timestamp":"2021-07-22T22:39:51.599803Z"}
1626993591.7310889: {"seqnum":96,"event":"updated","channel":"l2","symbol":"ALGO-BTC","bids":[],"asks":[{"num":1,"px":2.459E-5,"qty":2532.06}],"timestamp":"2021-07-22T22:39:51.723804Z"}
1626993591.731216: {"seqnum":97,"event":"updated","channel":"l2","symbol":"ALGO-BTC","bids":[],"asks":[{"num":1,"px":2.461E-5,"qty":6329.43}],"timestamp":"2021-07-22T22:39:51.723811Z"}

