wss://ws.prod.blockchain.info/mercury-gateway/v1/ws <-> 1618677753.948361
wss://ws.prod.blockchain.info/mercury-gateway/v1/ws <- 1618677754.1705961: {"action":"subscribe","symbol":"ETH-USDT","channel":"trades"}
wss://ws.prod.blockchain.info/mercury-gateway/v1/ws <- 1618677754.170733: {"action":"subscribe","symbol":"BTC-TRY","channel":"trades"}
wss://ws.prod.blockchain.info/mercury-gateway/v1/ws <- 1618677754.170843: {"action":"subscribe","symbol":"USDT-GBP","channel":"trades"}
wss://ws.prod.blockchain.info/mercury-gateway/v1/ws <- 1618677754.1708858: {"action":"subscribe","symbol":"YFI-USDT","channel":"trades"}
wss://ws.prod.blockchain.info/mercury-gateway/v1/ws <- 1618677754.1709208: {"action":"subscribe","symbol":"XLM-EUR","channel":"trades"}
wss://ws.prod.blockchain.info/mercury-gateway/v1/ws <- 1618677754.170954: {"action":"subscribe","symbol":"DOT-EUR","channel":"trades"}
wss://ws.prod.blockchain.info/mercury-gateway/v1/ws <- 1618677754.170986: {"action":"subscribe","symbol":"DOT-GBP","channel":"trades"}
wss://ws.prod.blockchain.info/mercury-gateway/v1/ws <- 1618677754.171017: {"action":"subscribe","symbol":"ENJ-USD","channel":"trades"}
wss://ws.prod.blockchain.info/mercury-gateway/v1/ws <- 1618677754.17105: {"action":"subscribe","symbol":"YFI-USD","channel":"trades"}
wss://ws.prod.blockchain.info/mercury-gateway/v1/ws <- 1618677754.171081: {"action":"subscribe","symbol":"AAVE-USDT","channel":"trades"}
wss://ws.prod.blockchain.info/mercury-gateway/v1/ws <- 1618677754.171117: {"action":"subscribe","symbol":"ETH-USDT","channel":"l2"}
wss://ws.prod.blockchain.info/mercury-gateway/v1/ws <- 1618677754.17115: {"action":"subscribe","symbol":"BTC-TRY","channel":"l2"}
wss://ws.prod.blockchain.info/mercury-gateway/v1/ws <- 1618677754.1711822: {"action":"subscribe","symbol":"USDT-GBP","channel":"l2"}
wss://ws.prod.blockchain.info/mercury-gateway/v1/ws <- 1618677754.171214: {"action":"subscribe","symbol":"YFI-USDT","channel":"l2"}
wss://ws.prod.blockchain.info/mercury-gateway/v1/ws <- 1618677754.171245: {"action":"subscribe","symbol":"XLM-EUR","channel":"l2"}
wss://ws.prod.blockchain.info/mercury-gateway/v1/ws <- 1618677754.171276: {"action":"subscribe","symbol":"DOT-EUR","channel":"l2"}
wss://ws.prod.blockchain.info/mercury-gateway/v1/ws <- 1618677754.171307: {"action":"subscribe","symbol":"DOT-GBP","channel":"l2"}
wss://ws.prod.blockchain.info/mercury-gateway/v1/ws <- 1618677754.171338: {"action":"subscribe","symbol":"ENJ-USD","channel":"l2"}
wss://ws.prod.blockchain.info/mercury-gateway/v1/ws <- 1618677754.171369: {"action":"subscribe","symbol":"YFI-USD","channel":"l2"}
wss://ws.prod.blockchain.info/mercury-gateway/v1/ws <- 1618677754.1713989: {"action":"subscribe","symbol":"AAVE-USDT","channel":"l2"}
1618677754.27244: {"seqnum":0,"event":"subscribed","channel":"trades","symbol":"ETH-USDT"}
1618677754.278144: {"seqnum":1,"event":"subscribed","channel":"trades","symbol":"BTC-TRY"}
1618677754.278185: {"seqnum":2,"event":"subscribed","channel":"trades","symbol":"USDT-GBP"}
1618677754.278199: {"seqnum":3,"event":"subscribed","channel":"trades","symbol":"YFI-USDT"}
1618677754.2782102: {"seqnum":4,"event":"subscribed","channel":"trades","symbol":"XLM-EUR"}
1618677754.27822: {"seqnum":5,"event":"subscribed","channel":"trades","symbol":"DOT-EUR"}
1618677754.278229: {"seqnum":6,"event":"subscribed","channel":"trades","symbol":"DOT-GBP"}
1618677754.2782369: {"seqnum":7,"event":"subscribed","channel":"trades","symbol":"ENJ-USD"}
1618677754.278246: {"seqnum":8,"event":"subscribed","channel":"trades","symbol":"YFI-USD"}
1618677754.278255: {"seqnum":9,"event":"subscribed","channel":"trades","symbol":"AAVE-USDT"}
1618677754.278263: {"seqnum":10,"event":"subscribed","channel":"l2","symbol":"ETH-USDT"}
1618677754.278273: {"seqnum":11,"event":"snapshot","channel":"l2","symbol":"ETH-USDT","bids":[{"num":1,"px":1.42,"qty":50.0},{"num":1,"px":1.44,"qty":47.85255216},{"num":1,"px":1400.0,"qty":0.63901536},{"num":1,"px":1475.01,"qty":0.03085419},{"num":1,"px":2359.62,"qty":0.8454},{"num":1,"px":2359.71,"qty":6.7644},{"num":1,"px":2360.89,"qty":6.7644},{"num":1,"px":2362.1,"qty":9.3019},{"num":1,"px":2362.34,"qty":6.765}],"asks":[{"num":1,"px":2363.95,"qty":6.765},{"num":1,"px":2364.34,"qty":9.3013},{"num":1,"px":2365.41,"qty":6.7657},{"num":1,"px":2366.12,"qty":10.1},{"num":1,"px":2367.2,"qty":6.7636},{"num":1,"px":2367.91,"qty":0.8455},{"num":1,"px":2500.0,"qty":0.28887658},{"num":1,"px":2523.0,"qty":0.12945815},{"num":1,"px":2574.64,"qty":0.02222001},{"num":1,"px":2642.0,"qty":0.39929675},{"num":1,"px":2800.0,"qty":0.2288168},{"num":1,"px":3015.0,"qty":1.0},{"num":1,"px":39000.0,"qty":0.04},{"num":1,"px":40000.0,"qty":5.07993222},{"num":1,"px":99879.0,"qty":0.15}]}
1618677754.278539: {"seqnum":12,"event":"subscribed","channel":"l2","symbol":"BTC-TRY"}
1618677754.2785869: {"seqnum":13,"event":"snapshot","channel":"l2","symbol":"BTC-TRY","bids":[{"num":1,"px":271.2,"qty":0.52975154},{"num":1,"px":206537.0,"qty":5.0E-4},{"num":1,"px":476960.4,"qty":0.13},{"num":1,"px":477642.9,"qty":0.13},{"num":1,"px":478860.4,"qty":0.13}],"asks":[{"num":1,"px":505438.5,"qty":0.13},{"num":1,"px":506384.9,"qty":0.13},{"num":1,"px":506390.9,"qty":0.13},{"num":1,"px":9119057.0,"qty":0.03240698},{"num":1,"px":9119058.0,"qty":0.2063325}]}
1618677754.278764: {"seqnum":14,"event":"subscribed","channel":"l2","symbol":"USDT-GBP"}
1618677754.2787871: {"seqnum":15,"event":"snapshot","channel":"l2","symbol":"USDT-GBP","bids":[{"num":1,"px":0.6,"qty":5.9828},{"num":1,"px":0.7254,"qty":1998.22},{"num":1,"px":0.7256,"qty":20981.22},{"num":1,"px":0.726,"qty":20981.22},{"num":1,"px":0.7263,"qty":32972.61}],"asks":[{"num":1,"px":0.7269,"qty":32976.42},{"num":1,"px":0.7275,"qty":20981.22},{"num":1,"px":0.7279,"qty":20981.22},{"num":1,"px":0.7281,"qty":1998.22}]}
1618677754.278948: {"seqnum":16,"event":"subscribed","channel":"l2","symbol":"YFI-USDT"}
1618677754.278969: {"seqnum":17,"event":"snapshot","channel":"l2","symbol":"YFI-USDT","bids":[{"num":1,"px":55.29,"qty":1.30089099},{"num":1,"px":55.3,"qty":0.54033414},{"num":1,"px":25000.0,"qty":0.002},{"num":1,"px":39999.0,"qty":0.01221901},{"num":3,"px":49092.79,"qty":1.19999997}],"asks":[{"num":1,"px":50800.07,"qty":0.39999999},{"num":1,"px":50815.83,"qty":0.39999999},{"num":1,"px":51066.67,"qty":0.39999999}]}
1618677754.279129: {"seqnum":18,"event":"subscribed","channel":"l2","symbol":"XLM-EUR"}
1618677754.279142: {"seqnum":19,"event":"snapshot","channel":"l2","symbol":"XLM-EUR","bids":[{"num":1,"px":0.0012,"qty":17328.5438701},{"num":1,"px":0.1,"qty":71.0},{"num":1,"px":0.12,"qty":5000.0},{"num":1,"px":0.1851,"qty":256.0},{"num":1,"px":0.2,"qty":400.0},{"num":1,"px":0.22,"qty":2000.0},{"num":1,"px":0.24,"qty":300.0},{"num":2,"px":0.27,"qty":1250.0},{"num":2,"px":0.3,"qty":456.544213},{"num":2,"px":0.33,"qty":481.0},{"num":1,"px":0.34,"qty":1064.8289196},{"num":5,"px":0.35,"qty":7337.3023601},{"num":1,"px":0.364,"qty":188.4221356},{"num":1,"px":0.39,"qty":653.2587598},{"num":3,"px":0.4,"qty":1610.6890131},{"num":1,"px":0.41,"qty":5048.8194265},{"num":1,"px":0.425,"qty":10764.5532769},{"num":2,"px":0.43,"qty":993.7253064},{"num":1,"px":0.44,"qty":133.8014285},{"num":4,"px":0.45,"qty":2055.5325365},{"num":1,"px":0.466,"qty":1000.0},{"num":1,"px":0.47,"qty":1191.4851157},{"num":2,"px":0.48,"qty":3320.045995},{"num":1,"px":0.49,"qty":672.3055462},{"num":1,"px":0.49524,"qty":40000.0},{"num":1,"px":0.49538,"qty":40000.0},{"num":1,"px":0.49575,"qty":40000.0}],"asks":[{"num":1,"px":0.50427,"qty":6624.52},{"num":1,"px":0.50463,"qty":17388.31},{"num":1,"px":0.50493,"qty":9948.51},{"num":1,"px":0.50521,"qty":9938.24},{"num":1,"px":0.51407,"qty":40000.0},{"num":1,"px":0.51567,"qty":40000.0},{"num":1,"px":0.51575,"qty":40000.0},{"num":1,"px":0.5185,"qty":10000.0},{"num":1,"px":0.5433,"qty":81.7844361},{"num":1,"px":0.553,"qty":1000.0},{"num":1,"px":0.55729,"qty":1176.4942429},{"num":1,"px":0.558,"qty":1843.5161476},{"num":2,"px":0.56,"qty":49893.1202809},{"num":5,"px":0.57,"qty":6518.9366418},{"num":1,"px":0.575,"qty":100.0},{"num":1,"px":0.58,"qty":1707.1110515},{"num":1,"px":0.585,"qty":280.0},{"num":2,"px":0.59,"qty":1340.0},{"num":6,"px":0.6,"qty":15345.3340962},{"num":1,"px":0.612,"qty":104.6228457},{"num":2,"px":0.65,"qty":3224.5430973},{"num":2,"px":0.66,"qty":966.6412187},{"num":1,"px":0.68,"qty":149.935502},{"num":2,"px":0.7,"qty":200.0},{"num":1,"px":0.71,"qty":143.311834},{"num":1,"px":0.75,"qty":715.3912141},{"num":1,"px":0.7894,"qty":6885.9805227},{"num":1,"px":0.7999,"qty":23442.9949274},{"num":1,"px":0.83,"qty":200.0},{"num":1,"px":0.94,"qty":700.0},{"num":1,"px":0.99,"qty":497.6527948},{"num":1,"px":1.0041,"qty":100.0},{"num":1,"px":3.0,"qty":9697.8182744},{"num":1,"px":32.098,"qty":625.5977634}]}
1618677754.279528: {"seqnum":20,"event":"subscribed","channel":"l2","symbol":"DOT-EUR"}
1618677754.279544: {"seqnum":21,"event":"snapshot","channel":"l2","symbol":"DOT-EUR","bids":[{"num":1,"px":0.12,"qty":434.2629482},{"num":1,"px":24.0,"qty":6.22758964},{"num":1,"px":26.0,"qty":3.0},{"num":1,"px":29.5,"qty":5.79373909},{"num":3,"px":30.0,"qty":31.0},{"num":3,"px":31.0,"qty":173.0},{"num":1,"px":32.0,"qty":1.03274402},{"num":1,"px":32.01,"qty":50.0},{"num":1,"px":32.5,"qty":30.0},{"num":3,"px":33.0,"qty":24.73340456},{"num":6,"px":34.0,"qty":85.38081743},{"num":2,"px":34.04,"qty":7.92847436},{"num":1,"px":34.79,"qty":7.80363224},{"num":4,"px":35.0,"qty":53.51777413}],"asks":[{"num":1,"px":36.31,"qty":103.4943},{"num":1,"px":36.33,"qty":183.9954},{"num":1,"px":36.35,"qty":115.0699},{"num":1,"px":36.37,"qty":114.9912},{"num":1,"px":39.8,"qty":3.0},{"num":1,"px":40.0,"qty":0.52509261},{"num":1,"px":40.5,"qty":9.0},{"num":1,"px":41.67,"qty":0.87533728},{"num":1,"px":42.3,"qty":9.0},{"num":1,"px":43.0,"qty":702.7815},{"num":1,"px":44.0,"qty":6.61826378},{"num":1,"px":45.0,"qty":11.62899384},{"num":2,"px":50.0,"qty":11.5},{"num":1,"px":100.0,"qty":1.17186995},{"num":1,"px":150.0,"qty":8.02238225},{"num":1,"px":10000.0,"qty":72.78172467}]}
1618677754.280044: {"seqnum":22,"event":"subscribed","channel":"l2","symbol":"DOT-GBP"}
1618677754.280063: {"seqnum":23,"event":"snapshot","channel":"l2","symbol":"DOT-GBP","bids":[{"num":1,"px":22.0,"qty":5.43},{"num":1,"px":28.5,"qty":2.1},{"num":1,"px":28.6,"qty":20.0},{"num":2,"px":29.0,"qty":104.44772633},{"num":1,"px":31.49,"qty":115.0196},{"num":1,"px":31.51,"qty":114.9912},{"num":1,"px":31.53,"qty":183.9725},{"num":1,"px":31.55,"qty":103.4846}],"asks":[{"num":1,"px":31.59,"qty":103.4908},{"num":1,"px":31.6,"qty":184.0504},{"num":1,"px":31.63,"qty":103.4507},{"num":1,"px":31.65,"qty":114.9566},{"num":1,"px":37.22,"qty":682.18774731},{"num":1,"px":45.0,"qty":8.6534145}]}
1618677754.2801962: {"seqnum":24,"event":"subscribed","channel":"l2","symbol":"ENJ-USD"}
1618677754.280501: {"seqnum":25,"event":"snapshot","channel":"l2","symbol":"ENJ-USD","bids":[{"num":1,"px":0.411,"qty":100.0},{"num":2,"px":2.1,"qty":251.888818},{"num":1,"px":2.15,"qty":250.0},{"num":1,"px":2.2,"qty":100.0},{"num":1,"px":2.45,"qty":248.297718},{"num":2,"px":2.5,"qty":270.885932},{"num":1,"px":2.6,"qty":85.046745},{"num":1,"px":2.6238,"qty":6666.666666},{"num":2,"px":2.6342,"qty":13333.333332},{"num":1,"px":2.749,"qty":69.091551},{"num":1,"px":2.8,"qty":7.541263},{"num":1,"px":2.8101,"qty":76.466123},{"num":1,"px":2.815,"qty":23.992433}],"asks":[{"num":1,"px":3.0613,"qty":6666.666666},{"num":1,"px":3.069,"qty":6666.666666},{"num":1,"px":3.0773,"qty":6666.666666},{"num":1,"px":3.1,"qty":10.5},{"num":1,"px":3.2,"qty":6.0507},{"num":1,"px":3.2745,"qty":87.89925},{"num":1,"px":3.3,"qty":100.0},{"num":1,"px":3.333,"qty":63.812985},{"num":1,"px":3.35,"qty":193.564466},{"num":1,"px":3.39,"qty":450.0},{"num":1,"px":3.4,"qty":68.974743},{"num":2,"px":3.45,"qty":250.141435},{"num":1,"px":3.473,"qty":550.557878},{"num":1,"px":3.5,"qty":150.0},{"num":1,"px":3.56,"qty":249.0},{"num":1,"px":3.644,"qty":600.0},{"num":1,"px":3.67,"qty":12.505045},{"num":1,"px":3.743,"qty":1000.0},{"num":2,"px":3.75,"qty":220.0},{"num":1,"px":3.8,"qty":78.0},{"num":1,"px":3.845,"qty":550.0},{"num":1,"px":3.85,"qty":962.990795},{"num":1,"px":3.9,"qty":200.0},{"num":1,"px":3.99,"qty":148.904151},{"num":4,"px":4.0,"qty":4910.207728},{"num":1,"px":4.0132,"qty":526.144655},{"num":1,"px":4.06,"qty":260.140667},{"num":1,"px":4.09,"qty":350.0},{"num":1,"px":4.24,"qty":10.0},{"num":1,"px":4.3,"qty":8054.01133},{"num":2,"px":4.5,"qty":7868.657316},{"num":1,"px":4.765,"qty":200.0},{"num":1,"px":5.37,"qty":56.0},{"num":1,"px":126.0,"qty":108.0},{"num":1,"px":600.0,"qty":60.0},{"num":2,"px":1000.0,"qty":203.0},{"num":1,"px":1200.0,"qty":4.0},{"num":1,"px":1400.0,"qty":3.0},{"num":1,"px":1500.0,"qty":3.0},{"num":1,"px":11000.0,"qty":3.0},{"num":1,"px":11150.0,"qty":5.0},{"num":1,"px":12190.0,"qty":5.0},{"num":1,"px":15000.0,"qty":3.0},{"num":1,"px":140000.0,"qty":3.121428}]}
1618677754.280889: {"seqnum":26,"event":"subscribed","channel":"l2","symbol":"YFI-USD"}
1618677754.280908: {"seqnum":27,"event":"snapshot","channel":"l2","symbol":"YFI-USD","bids":[{"num":1,"px":277.99,"qty":2.38419324},{"num":1,"px":278.0,"qty":1.49553584},{"num":1,"px":31000.0,"qty":0.00195683},{"num":1,"px":32000.0,"qty":0.00799821},{"num":1,"px":47233.0,"qty":0.2},{"num":1,"px":49107.05,"qty":0.39999999},{"num":2,"px":49132.37,"qty":0.79999998}],"asks":[{"num":1,"px":50720.16,"qty":0.39999999},{"num":1,"px":50758.9,"qty":0.39999999},{"num":1,"px":50867.79,"qty":0.39999999},{"num":1,"px":54900.0,"qty":0.018},{"num":1,"px":65000.0,"qty":0.35236631}]}
1618677754.2810292: {"seqnum":28,"event":"subscribed","channel":"l2","symbol":"AAVE-USDT"}
1618677754.281045: {"seqnum":29,"event":"snapshot","channel":"l2","symbol":"AAVE-USDT","bids":[{"num":1,"px":3.25,"qty":20.0},{"num":1,"px":350.0,"qty":0.11645489},{"num":1,"px":401.4,"qty":0.299368},{"num":1,"px":421.19,"qty":30.0},{"num":1,"px":421.65,"qty":30.0},{"num":1,"px":422.55,"qty":30.0}],"asks":[{"num":1,"px":432.02,"qty":30.0},{"num":1,"px":432.11,"qty":30.0},{"num":1,"px":433.92,"qty":30.0},{"num":1,"px":460.54,"qty":0.03535001},{"num":1,"px":520.0,"qty":17.27841272},{"num":1,"px":525.0,"qty":0.36020873},{"num":1,"px":556.0,"qty":7.83935945},{"num":1,"px":2000.0,"qty":45.92556191}]}
1618677754.3582249: {"seqnum":30,"event":"updated","channel":"l2","symbol":"ETH-USDT","bids":[],"asks":[{"num":1,"px":2363.65,"qty":2.537}]}
1618677754.402962: {"seqnum":31,"event":"updated","channel":"l2","symbol":"ETH-USDT","bids":[{"num":1,"px":2362.56,"qty":2.5369}],"asks":[]}
1618677754.535409: {"seqnum":32,"event":"updated","channel":"l2","symbol":"ETH-USDT","bids":[],"asks":[{"num":0,"px":2366.12,"qty":0.0}]}
1618677754.5355031: {"seqnum":33,"event":"updated","channel":"l2","symbol":"ETH-USDT","bids":[],"asks":[{"num":1,"px":2365.88,"qty":10.1}]}
1618677754.548434: {"seqnum":34,"event":"updated","channel":"l2","symbol":"XLM-EUR","bids":[],"asks":[{"num":0,"px":0.50427,"qty":0.0}]}
1618677754.673578: {"seqnum":35,"event":"updated","channel":"l2","symbol":"XLM-EUR","bids":[],"asks":[{"num":1,"px":0.5044,"qty":6622.39}]}
1618677754.801333: {"seqnum":36,"event":"updated","channel":"l2","symbol":"XLM-EUR","bids":[],"asks":[{"num":0,"px":0.5044,"qty":0.0}]}
1618677754.864738: {"seqnum":37,"event":"updated","channel":"l2","symbol":"ETH-USDT","bids":[],"asks":[{"num":0,"px":2365.88,"qty":0.0}]}
1618677754.864865: {"seqnum":38,"event":"updated","channel":"l2","symbol":"ETH-USDT","bids":[],"asks":[{"num":1,"px":2366.13,"qty":10.1}]}
1618677754.922791: {"seqnum":39,"event":"updated","channel":"l2","symbol":"XLM-EUR","bids":[],"asks":[{"num":0,"px":0.50463,"qty":0.0}]}
1618677754.935533: {"seqnum":40,"event":"updated","channel":"l2","symbol":"XLM-EUR","bids":[],"asks":[{"num":0,"px":0.50493,"qty":0.0}]}
1618677755.042805: {"seqnum":41,"event":"updated","channel":"l2","symbol":"ETH-USDT","bids":[],"asks":[{"num":0,"px":2363.65,"qty":0.0}]}
1618677755.0567849: {"seqnum":42,"event":"updated","channel":"l2","symbol":"XLM-EUR","bids":[],"asks":[{"num":1,"px":0.50454,"qty":6620.49}]}
1618677755.056892: {"seqnum":43,"event":"updated","channel":"l2","symbol":"XLM-EUR","bids":[],"asks":[{"num":1,"px":0.50495,"qty":17375.43}]}
1618677755.089538: {"seqnum":44,"event":"updated","channel":"l2","symbol":"XLM-EUR","bids":[],"asks":[{"num":1,"px":0.50563,"qty":9928.82}]}
1618677755.153238: {"seqnum":45,"event":"updated","channel":"l2","symbol":"ETH-USDT","bids":[],"asks":[{"num":0,"px":2366.13,"qty":0.0}]}
1618677755.153383: {"seqnum":46,"event":"updated","channel":"l2","symbol":"ETH-USDT","bids":[],"asks":[{"num":1,"px":2365.88,"qty":10.1}]}
1618677755.217443: {"seqnum":47,"event":"updated","channel":"l2","symbol":"ETH-USDT","bids":[],"asks":[{"num":1,"px":2363.83,"qty":2.5368}]}
1618677755.239935: {"seqnum":48,"event":"updated","channel":"l2","symbol":"ETH-USDT","bids":[],"asks":[{"num":0,"px":2365.88,"qty":0.0}]}
1618677755.2400699: {"seqnum":49,"event":"updated","channel":"l2","symbol":"ETH-USDT","bids":[],"asks":[{"num":1,"px":2366.1,"qty":10.1}]}
1618677755.358203: {"seqnum":50,"event":"updated","channel":"l2","symbol":"ETH-USDT","bids":[],"asks":[{"num":0,"px":2366.1,"qty":0.0}]}
1618677755.358339: {"seqnum":51,"event":"updated","channel":"l2","symbol":"ETH-USDT","bids":[],"asks":[{"num":1,"px":2366.16,"qty":10.1}]}
1618677755.554214: {"seqnum":52,"event":"updated","channel":"l2","symbol":"XLM-EUR","bids":[],"asks":[{"num":0,"px":0.50454,"qty":0.0}]}
1618677755.567863: {"seqnum":53,"event":"updated","channel":"l2","symbol":"DOT-EUR","bids":[],"asks":[{"num":0,"px":36.31,"qty":0.0}]}
1618677755.567935: {"seqnum":54,"event":"updated","channel":"l2","symbol":"DOT-GBP","bids":[],"asks":[{"num":0,"px":31.59,"qty":0.0}]}
1618677755.567976: {"seqnum":55,"event":"updated","channel":"l2","symbol":"DOT-GBP","bids":[{"num":0,"px":31.55,"qty":0.0}],"asks":[]}
1618677755.568013: {"seqnum":56,"event":"updated","channel":"l2","symbol":"DOT-GBP","bids":[],"asks":[{"num":0,"px":31.6,"qty":0.0}]}
1618677755.568043: {"seqnum":57,"event":"updated","channel":"l2","symbol":"DOT-GBP","bids":[{"num":0,"px":31.53,"qty":0.0}],"asks":[]}
1618677755.6105468: {"seqnum":58,"event":"updated","channel":"l2","symbol":"DOT-EUR","bids":[],"asks":[{"num":0,"px":36.33,"qty":0.0}]}
1618677755.6106508: {"seqnum":59,"event":"updated","channel":"l2","symbol":"DOT-GBP","bids":[{"num":0,"px":31.49,"qty":0.0}],"asks":[]}
1618677755.652477: {"seqnum":60,"event":"updated","channel":"l2","symbol":"ETH-USDT","bids":[],"asks":[{"num":0,"px":2366.16,"qty":0.0}]}
1618677755.652617: {"seqnum":61,"event":"updated","channel":"l2","symbol":"ETH-USDT","bids":[],"asks":[{"num":1,"px":2366.14,"qty":10.1}]}
1618677755.652682: {"seqnum":62,"event":"updated","channel":"l2","symbol":"ETH-USDT","bids":[{"num":0,"px":2362.56,"qty":0.0}],"asks":[]}
1618677755.6527371: {"seqnum":63,"event":"updated","channel":"l2","symbol":"ETH-USDT","bids":[],"asks":[{"num":0,"px":2363.83,"qty":0.0}]}
1618677755.652786: {"seqnum":64,"event":"updated","channel":"l2","symbol":"ETH-USDT","bids":[],"asks":[{"num":0,"px":2363.95,"qty":0.0}]}
1618677755.740736: {"seqnum":65,"event":"updated","channel":"l2","symbol":"XLM-EUR","bids":[],"asks":[{"num":1,"px":0.50442,"qty":6622.06}]}
1618677755.740868: {"seqnum":66,"event":"updated","channel":"l2","symbol":"ENJ-USD","bids":[{"num":1,"px":2.6342,"qty":6666.666666}],"asks":[]}
1618677755.740924: {"seqnum":67,"event":"updated","channel":"l2","symbol":"ENJ-USD","bids":[{"num":0,"px":2.6342,"qty":0.0}],"asks":[]}
1618677755.765004: {"seqnum":68,"event":"updated","channel":"l2","symbol":"DOT-EUR","bids":[],"asks":[{"num":1,"px":36.33,"qty":103.4495}]}
1618677755.765104: {"seqnum":69,"event":"updated","channel":"l2","symbol":"DOT-EUR","bids":[],"asks":[{"num":1,"px":36.34,"qty":183.9101}]}
1618677755.765163: {"seqnum":70,"event":"updated","channel":"l2","symbol":"DOT-GBP","bids":[],"asks":[{"num":1,"px":31.6,"qty":103.4495}]}
1618677755.7652118: {"seqnum":71,"event":"updated","channel":"l2","symbol":"DOT-GBP","bids":[{"num":1,"px":31.56,"qty":103.4315}],"asks":[]}
1618677755.7652612: {"seqnum":72,"event":"updated","channel":"l2","symbol":"DOT-GBP","bids":[],"asks":[{"num":1,"px":31.62,"qty":183.9101}]}
1618677755.765301: {"seqnum":73,"event":"updated","channel":"l2","symbol":"DOT-GBP","bids":[{"num":1,"px":31.55,"qty":183.8782}],"asks":[]}
1618677755.7653399: {"seqnum":74,"event":"updated","channel":"l2","symbol":"DOT-GBP","bids":[{"num":1,"px":31.53,"qty":114.9392}],"asks":[]}
1618677755.765381: {"seqnum":75,"event":"updated","channel":"l2","symbol":"ETH-USDT","bids":[],"asks":[{"num":1,"px":2364.0,"qty":2.5366}]}
1618677755.765434: {"seqnum":76,"event":"updated","channel":"l2","symbol":"ETH-USDT","bids":[{"num":1,"px":2362.73,"qty":2.5367}],"asks":[]}
1618677755.7654982: {"seqnum":77,"event":"updated","channel":"l2","symbol":"ETH-USDT","bids":[],"asks":[{"num":1,"px":2364.24,"qty":6.7643}]}
1618677755.888567: {"seqnum":78,"event":"updated","channel":"l2","symbol":"ENJ-USD","bids":[{"num":1,"px":2.6084,"qty":6666.666666}],"asks":[]}
1618677755.888704: {"seqnum":79,"event":"updated","channel":"l2","symbol":"ENJ-USD","bids":[{"num":2,"px":2.6084,"qty":13333.333332}],"asks":[]}
1618677755.94016: {"seqnum":80,"event":"updated","channel":"l2","symbol":"DOT-GBP","bids":[],"asks":[{"num":0,"px":31.6,"qty":0.0}]}
1618677755.940299: {"seqnum":81,"event":"updated","channel":"l2","symbol":"DOT-GBP","bids":[{"num":0,"px":31.56,"qty":0.0}],"asks":[]}
1618677756.045103: {"seqnum":82,"event":"updated","channel":"l2","symbol":"DOT-GBP","bids":[],"asks":[{"num":1,"px":31.61,"qty":103.4184}]}
1618677756.045202: {"seqnum":83,"event":"updated","channel":"l2","symbol":"DOT-GBP","bids":[{"num":1,"px":31.57,"qty":103.4271}],"asks":[]}
1618677756.065187: {"seqnum":84,"event":"updated","channel":"l2","symbol":"DOT-EUR","bids":[],"asks":[{"num":0,"px":36.34,"qty":0.0}]}
1618677756.0653021: {"seqnum":85,"event":"updated","channel":"l2","symbol":"DOT-EUR","bids":[],"asks":[{"num":0,"px":36.33,"qty":0.0}]}
1618677756.102004: {"seqnum":86,"event":"updated","channel":"l2","symbol":"DOT-EUR","bids":[],"asks":[{"num":0,"px":36.35,"qty":0.0}]}
1618677756.258246: {"seqnum":87,"event":"updated","channel":"l2","symbol":"DOT-EUR","bids":[],"asks":[{"num":1,"px":36.34,"qty":103.4016}]}
1618677756.262193: {"seqnum":88,"event":"updated","channel":"l2","symbol":"DOT-EUR","bids":[],"asks":[{"num":1,"px":36.36,"qty":183.825}]}
1618677756.262322: {"seqnum":89,"event":"updated","channel":"l2","symbol":"DOT-EUR","bids":[],"asks":[{"num":1,"px":36.4,"qty":114.8907}]}
1618677756.8078752: {"seqnum":90,"event":"updated","channel":"l2","symbol":"ENJ-USD","bids":[{"num":0,"px":2.6238,"qty":0.0}],"asks":[]}
1618677756.841654: {"seqnum":91,"event":"updated","channel":"l2","symbol":"ENJ-USD","bids":[{"num":1,"px":2.6033,"qty":6666.666666}],"asks":[]}
1618677757.454537: {"seqnum":92,"event":"updated","channel":"l2","symbol":"ETH-USDT","bids":[],"asks":[{"num":0,"px":2366.14,"qty":0.0}]}
1618677757.454668: {"seqnum":93,"event":"updated","channel":"l2","symbol":"ETH-USDT","bids":[],"asks":[{"num":1,"px":2366.16,"qty":10.1}]}
1618677757.568204: {"seqnum":94,"event":"updated","channel":"l2","symbol":"ETH-USDT","bids":[],"asks":[{"num":0,"px":2365.41,"qty":0.0}]}
1618677757.56834: {"seqnum":95,"event":"updated","channel":"l2","symbol":"ETH-USDT","bids":[{"num":0,"px":2362.73,"qty":0.0}],"asks":[]}
1618677757.568404: {"seqnum":96,"event":"updated","channel":"l2","symbol":"ETH-USDT","bids":[{"num":0,"px":2362.34,"qty":0.0}],"asks":[]}
1618677757.648204: {"seqnum":97,"event":"updated","channel":"l2","symbol":"ETH-USDT","bids":[],"asks":[{"num":0,"px":2364.0,"qty":0.0}]}
1618677757.648309: {"seqnum":98,"event":"updated","channel":"l2","symbol":"ETH-USDT","bids":[{"num":0,"px":2362.1,"qty":0.0}],"asks":[]}
1618677757.776284: {"seqnum":99,"event":"updated","channel":"l2","symbol":"ETH-USDT","bids":[],"asks":[{"num":0,"px":2364.24,"qty":0.0}]}
1618677757.776418: {"seqnum":100,"event":"updated","channel":"l2","symbol":"ETH-USDT","bids":[],"asks":[{"num":0,"px":2364.34,"qty":0.0}]}
1618677757.901088: {"seqnum":101,"event":"updated","channel":"l2","symbol":"XLM-EUR","bids":[],"asks":[{"num":0,"px":0.50442,"qty":0.0}]}
1618677757.9060621: {"seqnum":102,"event":"updated","channel":"l2","symbol":"ETH-USDT","bids":[],"asks":[{"num":1,"px":2364.2,"qty":2.5364}]}
1618677757.9061718: {"seqnum":103,"event":"updated","channel":"l2","symbol":"ETH-USDT","bids":[{"num":1,"px":2363.06,"qty":2.5364}],"asks":[]}
1618677757.906232: {"seqnum":104,"event":"updated","channel":"l2","symbol":"ETH-USDT","bids":[],"asks":[{"num":1,"px":2364.56,"qty":6.7633}]}
1618677757.914418: {"seqnum":105,"event":"updated","channel":"l2","symbol":"ETH-USDT","bids":[{"num":1,"px":2362.65,"qty":6.764}],"asks":[]}
1618677757.914548: {"seqnum":106,"event":"updated","channel":"l2","symbol":"ETH-USDT","bids":[],"asks":[{"num":1,"px":2364.79,"qty":9.2995}]}
1618677757.914609: {"seqnum":107,"event":"updated","channel":"l2","symbol":"ETH-USDT","bids":[{"num":1,"px":2362.5,"qty":9.3001}],"asks":[]}
1618677757.9146628: {"seqnum":108,"event":"updated","channel":"l2","symbol":"ETH-USDT","bids":[],"asks":[{"num":1,"px":2365.97,"qty":6.764}]}
1618677758.052777: {"seqnum":109,"event":"updated","channel":"l2","symbol":"XLM-EUR","bids":[],"asks":[{"num":1,"px":0.50465,"qty":6619.29}]}
1618677758.478764: {"seqnum":110,"event":"updated","channel":"l2","symbol":"ETH-USDT","bids":[],"asks":[{"num":0,"px":2366.16,"qty":0.0}]}
1618677758.4789069: {"seqnum":111,"event":"updated","channel":"l2","symbol":"ETH-USDT","bids":[],"asks":[{"num":1,"px":2365.98,"qty":10.1}]}
1618677758.958137: {"seqnum":112,"event":"updated","channel":"l2","symbol":"ETH-USDT","bids":[],"asks":[{"num":0,"px":2365.98,"qty":0.0}]}
1618677758.9582348: {"seqnum":113,"event":"updated","channel":"l2","symbol":"ETH-USDT","bids":[],"asks":[{"num":1,"px":2366.16,"qty":10.1}]}
1618677759.093481: {"seqnum":114,"event":"updated","channel":"l2","symbol":"XLM-EUR","bids":[],"asks":[{"num":0,"px":0.50465,"qty":0.0}]}
1618677759.21924: {"seqnum":115,"event":"updated","channel":"l2","symbol":"XLM-EUR","bids":[],"asks":[{"num":1,"px":0.50451,"qty":6621.13}]}
1618677759.3944142: {"seqnum":116,"event":"updated","channel":"l2","symbol":"DOT-GBP","bids":[],"asks":[{"num":0,"px":31.61,"qty":0.0}]}
1618677759.394548: {"seqnum":117,"event":"updated","channel":"l2","symbol":"DOT-GBP","bids":[{"num":0,"px":31.55,"qty":0.0}],"asks":[]}
1618677759.452919: {"seqnum":118,"event":"updated","channel":"l2","symbol":"DOT-GBP","bids":[],"asks":[{"num":0,"px":31.62,"qty":0.0}]}
1618677759.453058: {"seqnum":119,"event":"updated","channel":"l2","symbol":"DOT-GBP","bids":[],"asks":[{"num":0,"px":31.63,"qty":0.0}]}
1618677759.58306: {"seqnum":120,"event":"updated","channel":"l2","symbol":"DOT-GBP","bids":[],"asks":[{"num":1,"px":31.62,"qty":103.3941}]}
1618677759.583192: {"seqnum":121,"event":"updated","channel":"l2","symbol":"DOT-GBP","bids":[{"num":1,"px":31.56,"qty":183.8118}],"asks":[]}
1618677759.583252: {"seqnum":122,"event":"updated","channel":"l2","symbol":"DOT-GBP","bids":[],"asks":[{"num":1,"px":31.64,"qty":183.8118}]}
1618677759.660527: {"seqnum":123,"event":"updated","channel":"l2","symbol":"DOT-GBP","bids":[],"asks":[{"num":1,"px":31.67,"qty":114.8824}]}
1618677759.660633: {"seqnum":124,"event":"updated","channel":"l2","symbol":"ETH-USDT","bids":[],"asks":[{"num":0,"px":2366.16,"qty":0.0}]}
1618677759.6606798: {"seqnum":125,"event":"updated","channel":"l2","symbol":"ETH-USDT","bids":[],"asks":[{"num":1,"px":2366.13,"qty":10.1}]}
1618677759.745323: {"seqnum":126,"event":"updated","channel":"l2","symbol":"ETH-USDT","bids":[],"asks":[{"num":0,"px":2366.13,"qty":0.0}]}
1618677759.745468: {"seqnum":127,"event":"updated","channel":"l2","symbol":"ETH-USDT","bids":[],"asks":[{"num":1,"px":2365.88,"qty":10.1}]}
1618677759.8868601: {"seqnum":128,"event":"updated","channel":"l2","symbol":"ETH-USDT","bids":[],"asks":[{"num":0,"px":2365.88,"qty":0.0}]}
1618677759.887001: {"seqnum":129,"event":"updated","channel":"l2","symbol":"ETH-USDT","bids":[],"asks":[{"num":1,"px":2366.13,"qty":10.1}]}
1618677759.9464161: {"seqnum":130,"event":"updated","channel":"l2","symbol":"ETH-USDT","bids":[],"asks":[{"num":0,"px":2366.13,"qty":0.0}]}
1618677759.9464881: {"seqnum":131,"event":"updated","channel":"l2","symbol":"ETH-USDT","bids":[],"asks":[{"num":1,"px":2366.08,"qty":10.1}]}
1618677760.063689: {"seqnum":132,"event":"updated","channel":"l2","symbol":"ETH-USDT","bids":[],"asks":[{"num":0,"px":2366.08,"qty":0.0}]}
1618677760.063787: {"seqnum":133,"event":"updated","channel":"l2","symbol":"ETH-USDT","bids":[],"asks":[{"num":1,"px":2366.1,"qty":10.1}]}
1618677760.1510348: {"seqnum":134,"event":"updated","channel":"l2","symbol":"ETH-USDT","bids":[],"asks":[{"num":0,"px":2366.1,"qty":0.0}]}
1618677760.15117: {"seqnum":135,"event":"updated","channel":"l2","symbol":"ETH-USDT","bids":[],"asks":[{"num":1,"px":2365.88,"qty":10.1}]}
1618677760.206657: {"seqnum":136,"event":"updated","channel":"l2","symbol":"ETH-USDT","bids":[],"asks":[{"num":1,"px":2364.0,"qty":9.97}]}
1618677760.265734: {"seqnum":137,"event":"updated","channel":"l2","symbol":"ETH-USDT","bids":[{"num":0,"px":2363.06,"qty":0.0}],"asks":[]}
1618677760.286149: {"seqnum":138,"event":"updated","channel":"l2","symbol":"ETH-USDT","bids":[],"asks":[{"num":0,"px":2364.0,"qty":0.0}]}
1618677760.299857: {"seqnum":139,"event":"updated","channel":"l2","symbol":"ETH-USDT","bids":[],"asks":[{"num":0,"px":2364.2,"qty":0.0}]}
1618677760.299928: {"seqnum":140,"event":"updated","channel":"l2","symbol":"ETH-USDT","bids":[],"asks":[{"num":0,"px":2364.56,"qty":0.0}]}
1618677760.343214: {"seqnum":141,"event":"updated","channel":"l2","symbol":"ETH-USDT","bids":[],"asks":[{"num":0,"px":2365.88,"qty":0.0}]}
1618677760.343282: {"seqnum":142,"event":"updated","channel":"l2","symbol":"ETH-USDT","bids":[],"asks":[{"num":1,"px":2365.79,"qty":10.1}]}
1618677760.3547058: {"seqnum":143,"event":"updated","channel":"l2","symbol":"ETH-USDT","bids":[],"asks":[{"num":1,"px":2364.0,"qty":9.97}]}
1618677760.3547719: {"seqnum":144,"event":"updated","channel":"l2","symbol":"ETH-USDT","bids":[],"asks":[{"num":0,"px":2364.0,"qty":0.0}]}
1618677760.363188: {"seqnum":145,"event":"updated","channel":"l2","symbol":"ETH-USDT","bids":[],"asks":[{"num":1,"px":2364.0,"qty":9.97}]}
1618677760.432937: {"seqnum":146,"event":"updated","channel":"l2","symbol":"ETH-USDT","bids":[],"asks":[{"num":0,"px":2364.79,"qty":0.0}]}
1618677760.433015: {"seqnum":147,"event":"updated","channel":"l2","symbol":"XLM-EUR","bids":[],"asks":[{"num":0,"px":0.50451,"qty":0.0}]}
1618677760.587142: {"seqnum":148,"event":"updated","channel":"l2","symbol":"ETH-USDT","bids":[],"asks":[{"num":0,"px":2364.0,"qty":0.0}]}
1618677760.587224: {"seqnum":149,"event":"updated","channel":"l2","symbol":"ETH-USDT","bids":[],"asks":[{"num":1,"px":2364.0,"qty":9.97}]}
1618677760.587262: {"seqnum":150,"event":"updated","channel":"l2","symbol":"ETH-USDT","bids":[],"asks":[{"num":0,"px":2364.0,"qty":0.0}]}
1618677760.59543: {"seqnum":151,"event":"updated","channel":"l2","symbol":"ETH-USDT","bids":[],"asks":[{"num":1,"px":2363.85,"qty":2.5368}]}
1618677760.595482: {"seqnum":152,"event":"updated","channel":"l2","symbol":"ETH-USDT","bids":[{"num":1,"px":2362.75,"qty":2.5367}],"asks":[]}
1618677760.5955122: {"seqnum":153,"event":"updated","channel":"l2","symbol":"ETH-USDT","bids":[],"asks":[{"num":1,"px":2364.26,"qty":6.7641}]}
1618677760.5955358: {"seqnum":154,"event":"updated","channel":"l2","symbol":"ETH-USDT","bids":[],"asks":[{"num":1,"px":2364.32,"qty":9.3013}]}
1618677760.595558: {"seqnum":155,"event":"updated","channel":"l2","symbol":"XLM-EUR","bids":[],"asks":[{"num":1,"px":0.50439,"qty":6622.78}]}
1618677760.643578: {"seqnum":156,"event":"updated","channel":"l2","symbol":"ETH-USDT","bids":[],"asks":[{"num":0,"px":2365.79,"qty":0.0}]}
1618677760.6436312: {"seqnum":157,"event":"updated","channel":"l2","symbol":"ETH-USDT","bids":[],"asks":[{"num":1,"px":2365.77,"qty":10.1}]}
1618677760.672523: {"seqnum":158,"event":"updated","channel":"l2","symbol":"ETH-USDT","bids":[],"asks":[{"num":1,"px":2364.0,"qty":9.97}]}
1618677760.672652: {"seqnum":159,"event":"updated","channel":"l2","symbol":"ETH-USDT","bids":[],"asks":[{"num":0,"px":2364.0,"qty":0.0}]}
1618677760.688511: {"seqnum":160,"event":"updated","channel":"l2","symbol":"ETH-USDT","bids":[{"num":0,"px":2362.65,"qty":0.0}],"asks":[]}
1618677760.688607: {"seqnum":161,"event":"updated","channel":"l2","symbol":"ETH-USDT","bids":[{"num":0,"px":2362.5,"qty":0.0}],"asks":[]}
1618677760.7406552: {"seqnum":162,"event":"updated","channel":"l2","symbol":"ETH-USDT","bids":[{"num":0,"px":2362.75,"qty":0.0}],"asks":[]}
1618677760.843039: {"seqnum":163,"event":"updated","channel":"l2","symbol":"ETH-USDT","bids":[],"asks":[{"num":0,"px":2365.77,"qty":0.0}]}
1618677760.843141: {"seqnum":164,"event":"updated","channel":"l2","symbol":"ETH-USDT","bids":[],"asks":[{"num":1,"px":2365.68,"qty":10.1}]}
1618677760.974478: {"seqnum":165,"event":"updated","channel":"l2","symbol":"ETH-USDT","bids":[{"num":1,"px":2362.57,"qty":2.5368}],"asks":[]}
1618677760.974615: {"seqnum":166,"event":"updated","channel":"l2","symbol":"ETH-USDT","bids":[{"num":1,"px":2362.33,"qty":6.7648}],"asks":[]}
1618677760.974675: {"seqnum":167,"event":"updated","channel":"l2","symbol":"ETH-USDT","bids":[{"num":1,"px":2362.09,"qty":9.3016}],"asks":[]}
1618677760.9850812: {"seqnum":168,"event":"updated","channel":"l2","symbol":"ETH-USDT","bids":[],"asks":[{"num":0,"px":2363.85,"qty":0.0}]}
1618677760.9852211: {"seqnum":169,"event":"updated","channel":"l2","symbol":"ETH-USDT","bids":[],"asks":[{"num":0,"px":2364.26,"qty":0.0}]}
1618677761.043757: {"seqnum":170,"event":"updated","channel":"l2","symbol":"ETH-USDT","bids":[],"asks":[{"num":0,"px":2365.68,"qty":0.0}]}
1618677761.048521: {"seqnum":171,"event":"updated","channel":"l2","symbol":"ETH-USDT","bids":[],"asks":[{"num":1,"px":2365.73,"qty":10.1}]}
1618677761.4127371: {"seqnum":172,"event":"updated","channel":"l2","symbol":"ETH-USDT","bids":[],"asks":[{"num":0,"px":2365.73,"qty":0.0}]}
1618677761.4128199: {"seqnum":173,"event":"updated","channel":"l2","symbol":"ETH-USDT","bids":[],"asks":[{"num":1,"px":2365.68,"qty":10.1}]}
1618677761.445149: {"seqnum":174,"event":"updated","channel":"l2","symbol":"ETH-USDT","bids":[],"asks":[{"num":0,"px":2365.68,"qty":0.0}]}
1618677761.449497: {"seqnum":175,"event":"updated","channel":"l2","symbol":"ETH-USDT","bids":[],"asks":[{"num":1,"px":2365.75,"qty":10.1}]}
1618677761.609473: {"seqnum":176,"event":"updated","channel":"l2","symbol":"DOT-GBP","bids":[{"num":0,"px":31.57,"qty":0.0}],"asks":[]}
1618677761.609544: {"seqnum":177,"event":"updated","channel":"l2","symbol":"ETH-USDT","bids":[{"num":0,"px":2362.57,"qty":0.0}],"asks":[]}
1618677761.655621: {"seqnum":178,"event":"updated","channel":"l2","symbol":"ETH-USDT","bids":[],"asks":[{"num":0,"px":2365.75,"qty":0.0}]}
1618677761.655672: {"seqnum":179,"event":"updated","channel":"l2","symbol":"ETH-USDT","bids":[],"asks":[{"num":1,"px":2365.88,"qty":10.1}]}
1618677761.752015: {"seqnum":180,"event":"updated","channel":"l2","symbol":"DOT-GBP","bids":[{"num":1,"px":31.58,"qty":103.3864}],"asks":[]}
1618677761.78455: {"seqnum":181,"event":"updated","channel":"l2","symbol":"ETH-USDT","bids":[],"asks":[{"num":1,"px":2363.91,"qty":2.5367}]}
1618677761.784589: {"seqnum":182,"event":"updated","channel":"l2","symbol":"ETH-USDT","bids":[{"num":1,"px":2362.72,"qty":2.5367}],"asks":[]}
1618677761.784617: {"seqnum":183,"event":"updated","channel":"l2","symbol":"ETH-USDT","bids":[],"asks":[{"num":1,"px":2363.92,"qty":6.765}]}
1618677762.198565: {"seqnum":184,"event":"updated","channel":"l2","symbol":"DOT-GBP","bids":[{"num":0,"px":31.51,"qty":0.0}],"asks":[]}
1618677762.198644: {"seqnum":185,"event":"updated","channel":"l2","symbol":"DOT-EUR","bids":[],"asks":[{"num":0,"px":36.34,"qty":0.0}]}
1618677762.312243: {"seqnum":186,"event":"updated","channel":"l2","symbol":"DOT-GBP","bids":[{"num":1,"px":31.55,"qty":114.8614}],"asks":[]}
1618677762.312375: {"seqnum":187,"event":"updated","channel":"l2","symbol":"DOT-EUR","bids":[],"asks":[{"num":1,"px":36.35,"qty":103.3753}]}
1618677762.450866: {"seqnum":188,"event":"updated","channel":"l2","symbol":"DOT-EUR","bids":[],"asks":[{"num":0,"px":36.35,"qty":0.0}]}
1618677762.611943: {"seqnum":189,"event":"updated","channel":"l2","symbol":"DOT-EUR","bids":[],"asks":[{"num":1,"px":36.34,"qty":103.4006}]}
1618677762.95178: {"seqnum":190,"event":"updated","channel":"l2","symbol":"ENJ-USD","bids":[{"num":1,"px":2.6084,"qty":6666.666666}],"asks":[]}
1618677762.95183: {"seqnum":191,"event":"updated","channel":"l2","symbol":"ENJ-USD","bids":[{"num":0,"px":2.6033,"qty":0.0}],"asks":[]}
1618677762.951859: {"seqnum":192,"event":"updated","channel":"l2","symbol":"ENJ-USD","bids":[{"num":0,"px":2.6084,"qty":0.0}],"asks":[]}
1618677762.999868: {"seqnum":193,"event":"updated","channel":"l2","symbol":"ENJ-USD","bids":[{"num":1,"px":2.6379,"qty":6666.666666}],"asks":[]}
1618677762.999906: {"seqnum":194,"event":"updated","channel":"l2","symbol":"ENJ-USD","bids":[{"num":2,"px":2.6379,"qty":13333.333332}],"asks":[]}
1618677762.999924: {"seqnum":195,"event":"updated","channel":"l2","symbol":"ENJ-USD","bids":[{"num":3,"px":2.6379,"qty":19999.999998}],"asks":[]}
1618677763.464129: {"seqnum":196,"event":"updated","channel":"l2","symbol":"XLM-EUR","bids":[],"asks":[{"num":0,"px":0.50439,"qty":0.0}]}
1618677763.546483: {"seqnum":197,"event":"updated","channel":"l2","symbol":"ETH-USDT","bids":[],"asks":[{"num":0,"px":2365.88,"qty":0.0}]}
1618677763.549679: {"seqnum":198,"event":"updated","channel":"l2","symbol":"ETH-USDT","bids":[],"asks":[{"num":2,"px":2365.97,"qty":16.864}]}
1618677763.570739: {"seqnum":199,"event":"updated","channel":"l2","symbol":"XLM-EUR","bids":[],"asks":[{"num":1,"px":0.50455,"qty":6621.04}]}
1618677763.8703182: {"seqnum":200,"event":"updated","channel":"l2","symbol":"ENJ-USD","bids":[{"num":2,"px":2.6379,"qty":13333.333332}],"asks":[]}
1618677763.870388: {"seqnum":201,"event":"updated","channel":"l2","symbol":"ENJ-USD","bids":[{"num":1,"px":2.6379,"qty":6666.666666}],"asks":[]}
1618677763.8704178: {"seqnum":202,"event":"updated","channel":"l2","symbol":"ENJ-USD","bids":[{"num":0,"px":2.6379,"qty":0.0}],"asks":[]}
1618677763.89437: {"seqnum":203,"event":"updated","channel":"l2","symbol":"XLM-EUR","bids":[],"asks":[{"num":0,"px":0.50455,"qty":0.0}]}
1618677763.9505768: {"seqnum":204,"event":"updated","channel":"l2","symbol":"ETH-USDT","bids":[],"asks":[{"num":1,"px":2365.97,"qty":6.764}]}
1618677763.9506218: {"seqnum":205,"event":"updated","channel":"l2","symbol":"ETH-USDT","bids":[],"asks":[{"num":1,"px":2365.88,"qty":10.1}]}
1618677763.989485: {"seqnum":206,"event":"updated","channel":"l2","symbol":"ENJ-USD","bids":[{"num":1,"px":2.6152,"qty":6666.666666}],"asks":[]}
1618677763.989541: {"seqnum":207,"event":"updated","channel":"l2","symbol":"ENJ-USD","bids":[{"num":2,"px":2.6152,"qty":13333.333332}],"asks":[]}
1618677763.989569: {"seqnum":208,"event":"updated","channel":"l2","symbol":"ENJ-USD","bids":[{"num":3,"px":2.6152,"qty":19999.999998}],"asks":[]}
1618677764.022568: {"seqnum":209,"event":"updated","channel":"l2","symbol":"XLM-EUR","bids":[],"asks":[{"num":1,"px":0.50458,"qty":6620.68}]}
1618677764.590535: {"seqnum":210,"event":"updated","channel":"l2","symbol":"ETH-USDT","bids":[],"asks":[{"num":0,"px":2365.88,"qty":0.0}]}
1618677764.590677: {"seqnum":211,"event":"updated","channel":"l2","symbol":"ETH-USDT","bids":[],"asks":[{"num":1,"px":2365.38,"qty":10.1}]}
1618677765.30465: {"seqnum":212,"event":"updated","channel":"l2","symbol":"ETH-USDT","bids":[],"asks":[{"num":0,"px":2365.38,"qty":0.0}]}
1618677765.304734: {"seqnum":213,"event":"updated","channel":"l2","symbol":"ETH-USDT","bids":[],"asks":[{"num":1,"px":2365.88,"qty":10.1}]}
1618677765.304769: {"seqnum":214,"event":"updated","channel":"l2","symbol":"DOT-GBP","bids":[{"num":0,"px":31.58,"qty":0.0}],"asks":[]}
1618677765.304799: {"seqnum":215,"event":"updated","channel":"l2","symbol":"DOT-GBP","bids":[],"asks":[{"num":0,"px":31.62,"qty":0.0}]}
1618677765.312352: {"seqnum":216,"event":"updated","channel":"l2","symbol":"DOT-GBP","bids":[],"asks":[{"num":0,"px":31.64,"qty":0.0}]}
1618677765.3959181: {"seqnum":217,"event":"updated","channel":"l2","symbol":"DOT-EUR","bids":[],"asks":[{"num":0,"px":36.34,"qty":0.0}]}
1618677765.429816: {"seqnum":218,"event":"updated","channel":"l2","symbol":"DOT-EUR","bids":[],"asks":[{"num":0,"px":36.36,"qty":0.0}]}
1618677765.5175989: {"seqnum":219,"event":"updated","channel":"l2","symbol":"DOT-GBP","bids":[],"asks":[{"num":1,"px":31.61,"qty":103.4183}]}
1618677765.524257: {"seqnum":220,"event":"updated","channel":"l2","symbol":"DOT-GBP","bids":[{"num":1,"px":31.57,"qty":103.4183}],"asks":[]}
1618677765.5243258: {"seqnum":221,"event":"updated","channel":"l2","symbol":"DOT-GBP","bids":[],"asks":[{"num":1,"px":31.63,"qty":183.8547}]}
1618677765.524363: {"seqnum":222,"event":"updated","channel":"l2","symbol":"DOT-GBP","bids":[{"num":0,"px":31.56,"qty":0.0}],"asks":[]}
1618677765.5244002: {"seqnum":223,"event":"updated","channel":"l2","symbol":"DOT-GBP","bids":[],"asks":[{"num":0,"px":31.67,"qty":0.0}]}
1618677765.558197: {"seqnum":224,"event":"updated","channel":"l2","symbol":"DOT-EUR","bids":[],"asks":[{"num":1,"px":36.32,"qty":103.4578}]}
1618677765.5582578: {"seqnum":225,"event":"updated","channel":"l2","symbol":"DOT-EUR","bids":[],"asks":[{"num":1,"px":36.34,"qty":183.962}]}
1618677765.634175: {"seqnum":226,"event":"updated","channel":"l2","symbol":"DOT-GBP","bids":[],"asks":[{"num":0,"px":31.61,"qty":0.0}]}
1618677765.6365209: {"seqnum":227,"event":"updated","channel":"l2","symbol":"DOT-GBP","bids":[{"num":0,"px":31.57,"qty":0.0}],"asks":[]}
1618677765.636657: {"seqnum":228,"event":"updated","channel":"l2","symbol":"DOT-GBP","bids":[],"asks":[{"num":0,"px":31.63,"qty":0.0}]}
1618677765.6576378: {"seqnum":229,"event":"updated","channel":"l2","symbol":"ETH-USDT","bids":[],"asks":[{"num":0,"px":2365.88,"qty":0.0}]}
1618677765.657771: {"seqnum":230,"event":"updated","channel":"l2","symbol":"ETH-USDT","bids":[],"asks":[{"num":1,"px":2365.77,"qty":10.1}]}
1618677765.788247: {"seqnum":231,"event":"updated","channel":"l2","symbol":"DOT-GBP","bids":[],"asks":[{"num":1,"px":31.6,"qty":103.4786}]}
1618677765.788339: {"seqnum":232,"event":"updated","channel":"l2","symbol":"DOT-GBP","bids":[{"num":1,"px":31.54,"qty":183.9249}],"asks":[]}
1618677765.788378: {"seqnum":233,"event":"updated","channel":"l2","symbol":"DOT-GBP","bids":[],"asks":[{"num":1,"px":31.62,"qty":183.9249}]}
1618677765.788408: {"seqnum":234,"event":"updated","channel":"l2","symbol":"DOT-GBP","bids":[{"num":1,"px":31.51,"qty":114.9531}],"asks":[]}
1618677765.788436: {"seqnum":235,"event":"updated","channel":"l2","symbol":"DOT-GBP","bids":[],"asks":[{"num":1,"px":31.63,"qty":114.9763}]}
1618677765.805282: {"seqnum":236,"event":"updated","channel":"l2","symbol":"XLM-EUR","bids":[],"asks":[{"num":0,"px":0.50458,"qty":0.0}]}
1618677765.86352: {"seqnum":237,"event":"updated","channel":"l2","symbol":"ETH-USDT","bids":[],"asks":[{"num":0,"px":2365.77,"qty":0.0}]}
1618677765.86362: {"seqnum":238,"event":"updated","channel":"l2","symbol":"ETH-USDT","bids":[],"asks":[{"num":1,"px":2365.65,"qty":10.1}]}
1618677765.9221141: {"seqnum":239,"event":"updated","channel":"l2","symbol":"XLM-EUR","bids":[],"asks":[{"num":0,"px":0.50495,"qty":0.0}]}
1618677766.0125859: {"seqnum":240,"event":"updated","channel":"l2","symbol":"DOT-GBP","bids":[{"num":0,"px":31.55,"qty":0.0}],"asks":[]}
1618677766.040738: {"seqnum":241,"event":"updated","channel":"l2","symbol":"XLM-EUR","bids":[],"asks":[{"num":1,"px":0.50431,"qty":6623.85}]}
1618677766.040826: {"seqnum":242,"event":"updated","channel":"l2","symbol":"XLM-EUR","bids":[],"asks":[{"num":1,"px":0.50462,"qty":17387.6}]}
1618677766.111923: {"seqnum":243,"event":"updated","channel":"l2","symbol":"DOT-GBP","bids":[{"num":1,"px":31.56,"qty":103.4567}],"asks":[]}
1618677766.177925: {"seqnum":244,"event":"updated","channel":"l2","symbol":"XLM-EUR","bids":[],"asks":[{"num":0,"px":0.50431,"qty":0.0}]}
1618677766.302303: {"seqnum":245,"event":"updated","channel":"l2","symbol":"XLM-EUR","bids":[],"asks":[{"num":1,"px":0.50419,"qty":6625.38}]}
1618677766.640476: {"seqnum":246,"event":"updated","channel":"l2","symbol":"ETH-USDT","bids":[],"asks":[{"num":0,"px":2365.65,"qty":0.0}]}
1618677766.64061: {"seqnum":247,"event":"updated","channel":"l2","symbol":"ETH-USDT","bids":[],"asks":[{"num":1,"px":2365.88,"qty":10.1}]}
1618677766.759321: {"seqnum":248,"event":"updated","channel":"l2","symbol":"ETH-USDT","bids":[],"asks":[{"num":0,"px":2365.88,"qty":0.0}]}
1618677766.7645388: {"seqnum":249,"event":"updated","channel":"l2","symbol":"ETH-USDT","bids":[],"asks":[{"num":1,"px":2366.16,"qty":10.1}]}
1618677767.1503758: {"seqnum":250,"event":"updated","channel":"l2","symbol":"ETH-USDT","bids":[],"asks":[{"num":0,"px":2366.16,"qty":0.0}]}
1618677767.150475: {"seqnum":251,"event":"updated","channel":"l2","symbol":"ETH-USDT","bids":[],"asks":[{"num":1,"px":2365.88,"qty":10.1}]}
1618677767.662456: {"seqnum":252,"event":"updated","channel":"l2","symbol":"ETH-USDT","bids":[],"asks":[{"num":0,"px":2363.91,"qty":0.0}]}
1618677767.7072482: {"seqnum":253,"event":"updated","channel":"l2","symbol":"ETH-USDT","bids":[],"asks":[{"num":1,"px":2363.76,"qty":2.5368}]}
1618677767.727935: {"seqnum":254,"event":"updated","channel":"l2","symbol":"ETH-USDT","bids":[{"num":0,"px":2362.72,"qty":0.0}],"asks":[]}
1618677767.857277: {"seqnum":255,"event":"updated","channel":"l2","symbol":"ETH-USDT","bids":[],"asks":[{"num":0,"px":2365.88,"qty":0.0}]}
1618677767.857374: {"seqnum":256,"event":"updated","channel":"l2","symbol":"ETH-USDT","bids":[],"asks":[{"num":1,"px":2365.92,"qty":10.1}]}
1618677767.958974: {"seqnum":257,"event":"updated","channel":"l2","symbol":"ETH-USDT","bids":[],"asks":[{"num":0,"px":2365.92,"qty":0.0}]}
1618677767.959115: {"seqnum":258,"event":"updated","channel":"l2","symbol":"ETH-USDT","bids":[],"asks":[{"num":1,"px":2365.96,"qty":10.1}]}
1618677768.414461: {"seqnum":259,"event":"updated","channel":"l2","symbol":"DOT-GBP","bids":[{"num":0,"px":31.56,"qty":0.0}],"asks":[]}
1618677768.414598: {"seqnum":260,"event":"updated","channel":"l2","symbol":"DOT-GBP","bids":[],"asks":[{"num":0,"px":31.62,"qty":0.0}]}
1618677768.5605361: {"seqnum":261,"event":"updated","channel":"l2","symbol":"ETH-USDT","bids":[],"asks":[{"num":0,"px":2365.96,"qty":0.0}]}
1618677768.560611: {"seqnum":262,"event":"updated","channel":"l2","symbol":"ETH-USDT","bids":[],"asks":[{"num":1,"px":2365.88,"qty":10.1}]}
1618677768.589747: {"seqnum":263,"event":"updated","channel":"l2","symbol":"DOT-GBP","bids":[],"asks":[{"num":1,"px":31.61,"qty":183.9702}]}
1618677768.589856: {"seqnum":264,"event":"updated","channel":"l2","symbol":"DOT-GBP","bids":[{"num":1,"px":31.55,"qty":103.4832}],"asks":[]}
1618677768.655213: {"seqnum":265,"event":"updated","channel":"l2","symbol":"ETH-USDT","bids":[],"asks":[{"num":0,"px":2365.88,"qty":0.0}]}
1618677768.663742: {"seqnum":266,"event":"updated","channel":"l2","symbol":"ETH-USDT","bids":[],"asks":[{"num":1,"px":2365.72,"qty":10.1}]}
1618677768.6744409: {"seqnum":267,"event":"updated","channel":"l2","symbol":"ETH-USDT","bids":[{"num":1,"px":2362.64,"qty":2.5368}],"asks":[]}
1618677769.09616: {"seqnum":268,"event":"updated","channel":"l2","symbol":"ETH-USDT","bids":[],"asks":[{"num":0,"px":2365.72,"qty":0.0}]}
1618677769.096242: {"seqnum":269,"event":"updated","channel":"l2","symbol":"ETH-USDT","bids":[],"asks":[{"num":1,"px":2365.77,"qty":10.1}]}
1618677769.361152: {"seqnum":270,"event":"updated","channel":"l2","symbol":"ETH-USDT","bids":[],"asks":[{"num":0,"px":2365.77,"qty":0.0}]}
1618677769.3612318: {"seqnum":271,"event":"updated","channel":"l2","symbol":"ETH-USDT","bids":[],"asks":[{"num":1,"px":2365.69,"qty":10.1}]}
1618677769.654369: {"seqnum":272,"event":"updated","channel":"l2","symbol":"ETH-USDT","bids":[],"asks":[{"num":0,"px":2365.69,"qty":0.0}]}
1618677769.654508: {"seqnum":273,"event":"updated","channel":"l2","symbol":"ETH-USDT","bids":[],"asks":[{"num":1,"px":2365.64,"qty":10.1}]}
1618677769.912118: {"seqnum":274,"event":"updated","channel":"l2","symbol":"ETH-USDT","bids":[],"asks":[{"num":0,"px":2363.76,"qty":0.0}]}
1618677769.944524: {"seqnum":275,"event":"updated","channel":"l2","symbol":"ETH-USDT","bids":[],"asks":[{"num":0,"px":2363.92,"qty":0.0}]}
1618677769.954537: {"seqnum":276,"event":"updated","channel":"l2","symbol":"ETH-USDT","bids":[],"asks":[{"num":0,"px":2365.64,"qty":0.0}]}
1618677769.95464: {"seqnum":277,"event":"updated","channel":"l2","symbol":"ETH-USDT","bids":[],"asks":[{"num":1,"px":2366.16,"qty":10.1}]}
1618677770.082446: {"seqnum":278,"event":"updated","channel":"l2","symbol":"ETH-USDT","bids":[],"asks":[{"num":1,"px":2363.94,"qty":2.5366}]}
1618677770.082516: {"seqnum":279,"event":"updated","channel":"l2","symbol":"ETH-USDT","bids":[],"asks":[{"num":1,"px":2364.18,"qty":6.7643}]}
1618677770.2897332: {"seqnum":280,"event":"updated","channel":"l2","symbol":"ETH-USDT","bids":[{"num":0,"px":2362.64,"qty":0.0}],"asks":[]}
1618677770.4531672: {"seqnum":281,"event":"updated","channel":"l2","symbol":"ETH-USDT","bids":[{"num":1,"px":2362.82,"qty":2.5366}],"asks":[]}
1618677770.562031: {"seqnum":282,"event":"updated","channel":"l2","symbol":"ETH-USDT","bids":[],"asks":[{"num":0,"px":2366.16,"qty":0.0}]}
1618677770.562172: {"seqnum":283,"event":"updated","channel":"l2","symbol":"ETH-USDT","bids":[],"asks":[{"num":1,"px":2365.76,"qty":10.1}]}
1618677770.664901: {"seqnum":284,"event":"updated","channel":"l2","symbol":"ETH-USDT","bids":[],"asks":[{"num":0,"px":2365.76,"qty":0.0}]}
1618677770.665035: {"seqnum":285,"event":"updated","channel":"l2","symbol":"ETH-USDT","bids":[],"asks":[{"num":1,"px":2365.88,"qty":10.1}]}
1618677770.803168: {"seqnum":286,"event":"updated","channel":"l2","symbol":"DOT-GBP","bids":[{"num":0,"px":31.55,"qty":0.0}],"asks":[]}
1618677770.983438: {"seqnum":287,"event":"updated","channel":"l2","symbol":"DOT-GBP","bids":[{"num":1,"px":31.56,"qty":103.4551}],"asks":[]}
1618677771.056283: {"seqnum":288,"event":"updated","channel":"l2","symbol":"ENJ-USD","bids":[{"num":2,"px":2.6152,"qty":13333.333332}],"asks":[]}
1618677771.1103601: {"seqnum":289,"event":"updated","channel":"l2","symbol":"ENJ-USD","bids":[{"num":1,"px":2.6004,"qty":6666.666666}],"asks":[]}
1618677771.2897081: {"seqnum":290,"event":"updated","channel":"l2","symbol":"ETH-USDT","bids":[{"num":0,"px":2362.33,"qty":0.0}],"asks":[]}
1618677771.405374: {"seqnum":291,"event":"updated","channel":"l2","symbol":"ETH-USDT","bids":[{"num":1,"px":2362.64,"qty":6.764}],"asks":[]}
1618677771.463833: {"seqnum":292,"event":"updated","channel":"l2","symbol":"ETH-USDT","bids":[],"asks":[{"num":0,"px":2365.88,"qty":0.0}]}
1618677771.463949: {"seqnum":293,"event":"updated","channel":"l2","symbol":"ETH-USDT","bids":[],"asks":[{"num":1,"px":2365.42,"qty":10.1}]}
1618677771.562127: {"seqnum":294,"event":"updated","channel":"l2","symbol":"ETH-USDT","bids":[],"asks":[{"num":0,"px":2365.42,"qty":0.0}]}
1618677771.562243: {"seqnum":295,"event":"updated","channel":"l2","symbol":"ETH-USDT","bids":[],"asks":[{"num":1,"px":2365.48,"qty":10.1}]}
1618677771.6652942: {"seqnum":296,"event":"updated","channel":"l2","symbol":"ETH-USDT","bids":[],"asks":[{"num":0,"px":2365.48,"qty":0.0}]}
1618677771.665364: {"seqnum":297,"event":"updated","channel":"l2","symbol":"ETH-USDT","bids":[],"asks":[{"num":1,"px":2366.16,"qty":10.1}]}
1618677771.6653981: {"seqnum":298,"event":"updated","channel":"l2","symbol":"XLM-EUR","bids":[],"asks":[{"num":0,"px":0.50419,"qty":0.0}]}
1618677771.811326: {"seqnum":299,"event":"updated","channel":"l2","symbol":"XLM-EUR","bids":[],"asks":[{"num":1,"px":0.50434,"qty":6623.21}]}
1618677771.97683: {"seqnum":300,"event":"updated","channel":"l2","symbol":"ETH-USDT","bids":[],"asks":[{"num":0,"px":2366.16,"qty":0.0}]}
1618677771.976971: {"seqnum":301,"event":"updated","channel":"l2","symbol":"ETH-USDT","bids":[],"asks":[{"num":1,"px":2365.88,"qty":10.1}]}
1618677772.0343199: {"seqnum":302,"event":"updated","channel":"l2","symbol":"ENJ-USD","bids":[{"num":1,"px":2.6152,"qty":6666.666666}],"asks":[]}
1618677772.034443: {"seqnum":303,"event":"updated","channel":"l2","symbol":"ENJ-USD","bids":[{"num":0,"px":2.6152,"qty":0.0}],"asks":[]}
1618677772.166846: {"seqnum":304,"event":"updated","channel":"l2","symbol":"ENJ-USD","bids":[{"num":1,"px":2.5908,"qty":6666.666666}],"asks":[]}
1618677772.166977: {"seqnum":305,"event":"updated","channel":"l2","symbol":"ENJ-USD","bids":[{"num":2,"px":2.5908,"qty":13333.333332}],"asks":[]}
1618677772.266569: {"seqnum":306,"event":"updated","channel":"l2","symbol":"ETH-USDT","bids":[],"asks":[{"num":0,"px":2365.88,"qty":0.0}]}
1618677772.268219: {"seqnum":307,"event":"updated","channel":"l2","symbol":"ETH-USDT","bids":[],"asks":[{"num":1,"px":2366.16,"qty":10.1}]}
1618677772.461673: {"seqnum":308,"event":"updated","channel":"l2","symbol":"ETH-USDT","bids":[],"asks":[{"num":0,"px":2366.16,"qty":0.0}]}
1618677772.4623518: {"seqnum":309,"event":"updated","channel":"l2","symbol":"ETH-USDT","bids":[],"asks":[{"num":1,"px":2365.88,"qty":10.1}]}
1618677772.663842: {"seqnum":310,"event":"updated","channel":"l2","symbol":"ETH-USDT","bids":[],"asks":[{"num":0,"px":2365.88,"qty":0.0}]}
1618677772.663925: {"seqnum":311,"event":"updated","channel":"l2","symbol":"ETH-USDT","bids":[],"asks":[{"num":1,"px":2366.16,"qty":10.1}]}
1618677773.0547159: {"seqnum":312,"event":"updated","channel":"l2","symbol":"ENJ-USD","bids":[{"num":1,"px":2.5908,"qty":6666.666666}],"asks":[]}
1618677773.054836: {"seqnum":313,"event":"updated","channel":"l2","symbol":"ENJ-USD","bids":[{"num":0,"px":2.5908,"qty":0.0}],"asks":[]}
1618677773.161424: {"seqnum":314,"event":"updated","channel":"l2","symbol":"ETH-USDT","bids":[],"asks":[{"num":0,"px":2366.16,"qty":0.0}]}
1618677773.161559: {"seqnum":315,"event":"updated","channel":"l2","symbol":"ETH-USDT","bids":[],"asks":[{"num":1,"px":2366.05,"qty":10.1}]}
1618677773.179696: {"seqnum":316,"event":"updated","channel":"l2","symbol":"ENJ-USD","bids":[{"num":1,"px":2.6056,"qty":6666.666666}],"asks":[]}
1618677773.179827: {"seqnum":317,"event":"updated","channel":"l2","symbol":"ENJ-USD","bids":[{"num":2,"px":2.6056,"qty":13333.333332}],"asks":[]}
1618677773.216782: {"seqnum":318,"event":"updated","channel":"l2","symbol":"ETH-USDT","bids":[],"asks":[{"num":1,"px":2364.0,"qty":9.97}]}
1618677773.229557: {"seqnum":319,"event":"updated","channel":"l2","symbol":"ETH-USDT","bids":[],"asks":[{"num":0,"px":2364.0,"qty":0.0}]}
1618677773.46498: {"seqnum":320,"event":"updated","channel":"l2","symbol":"ETH-USDT","bids":[],"asks":[{"num":0,"px":2366.05,"qty":0.0}]}
1618677773.465111: {"seqnum":321,"event":"updated","channel":"l2","symbol":"ETH-USDT","bids":[],"asks":[{"num":1,"px":2366.16,"qty":10.1}]}
1618677774.188971: {"seqnum":322,"event":"updated","channel":"l2","symbol":"DOT-GBP","bids":[{"num":0,"px":31.56,"qty":0.0}],"asks":[]}
1618677774.220721: {"seqnum":323,"event":"updated","channel":"l2","symbol":"DOT-GBP","bids":[],"asks":[{"num":0,"px":31.6,"qty":0.0}]}
1618677774.2340229: {"seqnum":324,"event":"updated","channel":"l2","symbol":"ETH-USDT","bids":[],"asks":[{"num":1,"px":2364.04,"qty":9.97}]}
1618677774.255021: {"seqnum":325,"event":"updated","channel":"l2","symbol":"ETH-USDT","bids":[],"asks":[{"num":0,"px":2364.04,"qty":0.0}]}
1618677774.25509: {"seqnum":326,"event":"updated","channel":"l2","symbol":"ETH-USDT","bids":[],"asks":[{"num":1,"px":2363.97,"qty":9.97}]}
1618677774.276581: {"seqnum":327,"event":"updated","channel":"l2","symbol":"ETH-USDT","bids":[],"asks":[{"num":0,"px":2363.97,"qty":0.0}]}
1618677774.332693: {"seqnum":328,"event":"updated","channel":"l2","symbol":"DOT-GBP","bids":[],"asks":[{"num":1,"px":31.59,"qty":103.4789}]}
1618677774.3328261: {"seqnum":329,"event":"updated","channel":"l2","symbol":"DOT-GBP","bids":[{"num":1,"px":31.55,"qty":103.4789}],"asks":[]}
1618677775.064571: {"seqnum":330,"event":"updated","channel":"l2","symbol":"ENJ-USD","bids":[{"num":1,"px":2.6056,"qty":6666.666666}],"asks":[]}
1618677775.0646589: {"seqnum":331,"event":"updated","channel":"l2","symbol":"ENJ-USD","bids":[{"num":0,"px":2.6056,"qty":0.0}],"asks":[]}
1618677775.064718: {"seqnum":332,"event":"updated","channel":"l2","symbol":"ENJ-USD","bids":[{"num":0,"px":2.6004,"qty":0.0}],"asks":[]}
1618677775.165717: {"seqnum":333,"event":"updated","channel":"l2","symbol":"ENJ-USD","bids":[{"num":1,"px":2.776,"qty":6666.666666}],"asks":[]}
1618677775.1696398: {"seqnum":334,"event":"updated","channel":"l2","symbol":"ENJ-USD","bids":[{"num":2,"px":2.776,"qty":13333.333332}],"asks":[]}
1618677775.169707: {"seqnum":335,"event":"updated","channel":"l2","symbol":"ENJ-USD","bids":[{"num":3,"px":2.776,"qty":19999.999998}],"asks":[]}
1618677775.3909829: {"seqnum":336,"event":"updated","channel":"l2","symbol":"ETH-USDT","bids":[],"asks":[{"num":0,"px":2366.16,"qty":0.0}]}
1618677775.391058: {"seqnum":337,"event":"updated","channel":"l2","symbol":"ETH-USDT","bids":[],"asks":[{"num":1,"px":2365.48,"qty":10.1}]}
1618677775.4662871: {"seqnum":338,"event":"updated","channel":"l2","symbol":"ETH-USDT","bids":[],"asks":[{"num":0,"px":2365.48,"qty":0.0}]}
1618677775.466353: {"seqnum":339,"event":"updated","channel":"l2","symbol":"ETH-USDT","bids":[],"asks":[{"num":1,"px":2365.42,"qty":10.1}]}
1618677775.926503: {"seqnum":340,"event":"updated","channel":"l2","symbol":"XLM-EUR","bids":[{"num":0,"px":0.49575,"qty":0.0}],"asks":[]}
1618677775.926573: {"seqnum":341,"event":"updated","channel":"l2","symbol":"XLM-EUR","bids":[{"num":0,"px":0.49524,"qty":0.0}],"asks":[]}
1618677775.926604: {"seqnum":342,"event":"updated","channel":"l2","symbol":"XLM-EUR","bids":[{"num":0,"px":0.49538,"qty":0.0}],"asks":[]}
1618677776.0139148: {"seqnum":343,"event":"updated","channel":"l2","symbol":"XLM-EUR","bids":[{"num":1,"px":0.49827,"qty":40000.0}],"asks":[]}
1618677776.0140438: {"seqnum":344,"event":"updated","channel":"l2","symbol":"XLM-EUR","bids":[{"num":2,"px":0.49827,"qty":80000.0}],"asks":[]}
1618677776.014098: {"seqnum":345,"event":"updated","channel":"l2","symbol":"XLM-EUR","bids":[{"num":3,"px":0.49827,"qty":120000.0}],"asks":[]}
1618677776.1461818: {"seqnum":346,"event":"updated","channel":"l2","symbol":"ENJ-USD","bids":[{"num":2,"px":2.776,"qty":13333.333332}],"asks":[]}
1618677776.146297: {"seqnum":347,"event":"updated","channel":"l2","symbol":"ENJ-USD","bids":[{"num":1,"px":2.776,"qty":6666.666666}],"asks":[]}
1618677776.146348: {"seqnum":348,"event":"updated","channel":"l2","symbol":"ENJ-USD","bids":[{"num":0,"px":2.776,"qty":0.0}],"asks":[]}
1618677776.247892: {"seqnum":349,"event":"updated","channel":"l2","symbol":"ENJ-USD","bids":[{"num":1,"px":2.7275,"qty":6666.666666}],"asks":[]}
1618677776.250706: {"seqnum":350,"event":"updated","channel":"l2","symbol":"ENJ-USD","bids":[{"num":2,"px":2.7275,"qty":13333.333332}],"asks":[]}
1618677776.2507641: {"seqnum":351,"event":"updated","channel":"l2","symbol":"ENJ-USD","bids":[{"num":3,"px":2.7275,"qty":19999.999998}],"asks":[]}
1618677776.3710551: {"seqnum":352,"event":"updated","channel":"l2","symbol":"ETH-USDT","bids":[],"asks":[{"num":0,"px":2365.42,"qty":0.0}]}
1618677776.3711529: {"seqnum":353,"event":"updated","channel":"l2","symbol":"ETH-USDT","bids":[],"asks":[{"num":1,"px":2365.88,"qty":10.1}]}
1618677776.776083: {"seqnum":354,"event":"updated","channel":"l2","symbol":"ETH-USDT","bids":[],"asks":[{"num":0,"px":2365.88,"qty":0.0}]}
1618677776.776159: {"seqnum":355,"event":"updated","channel":"l2","symbol":"ETH-USDT","bids":[],"asks":[{"num":1,"px":2365.71,"qty":10.1}]}
1618677777.446302: {"seqnum":356,"event":"updated","channel":"l2","symbol":"ENJ-USD","bids":[{"num":2,"px":2.7275,"qty":13333.333332}],"asks":[]}
1618677777.4463518: {"seqnum":357,"event":"updated","channel":"l2","symbol":"ENJ-USD","bids":[{"num":1,"px":2.7275,"qty":6666.666666}],"asks":[]}
1618677777.4463701: {"seqnum":358,"event":"updated","channel":"l2","symbol":"ENJ-USD","bids":[{"num":0,"px":2.7275,"qty":0.0}],"asks":[]}
1618677777.446393: {"seqnum":359,"event":"updated","channel":"l2","symbol":"ENJ-USD","bids":[{"num":1,"px":2.6912,"qty":6666.666666}],"asks":[]}
1618677777.44641: {"seqnum":360,"event":"updated","channel":"l2","symbol":"ENJ-USD","bids":[{"num":2,"px":2.6912,"qty":13333.333332}],"asks":[]}
1618677777.456556: {"seqnum":361,"event":"updated","channel":"l2","symbol":"ENJ-USD","bids":[{"num":3,"px":2.6912,"qty":19999.999998}],"asks":[]}
1618677777.670088: {"seqnum":362,"event":"updated","channel":"l2","symbol":"ETH-USDT","bids":[],"asks":[{"num":0,"px":2365.71,"qty":0.0}]}
1618677777.670225: {"seqnum":363,"event":"updated","channel":"l2","symbol":"ETH-USDT","bids":[],"asks":[{"num":1,"px":2365.77,"qty":10.1}]}
1618677778.1651998: {"seqnum":364,"event":"updated","channel":"l2","symbol":"ENJ-USD","bids":[{"num":2,"px":2.6912,"qty":13333.333332}],"asks":[]}
1618677778.16525: {"seqnum":365,"event":"updated","channel":"l2","symbol":"ENJ-USD","bids":[{"num":1,"px":2.6912,"qty":6666.666666}],"asks":[]}
1618677778.165267: {"seqnum":366,"event":"updated","channel":"l2","symbol":"ENJ-USD","bids":[{"num":0,"px":2.6912,"qty":0.0}],"asks":[]}
1618677778.285829: {"seqnum":367,"event":"updated","channel":"l2","symbol":"ENJ-USD","bids":[{"num":1,"px":2.7421,"qty":6666.666666}],"asks":[]}
1618677778.285963: {"seqnum":368,"event":"updated","channel":"l2","symbol":"ENJ-USD","bids":[{"num":2,"px":2.7421,"qty":13333.333332}],"asks":[]}
1618677778.286019: {"seqnum":369,"event":"updated","channel":"l2","symbol":"ENJ-USD","bids":[{"num":3,"px":2.7421,"qty":19999.999998}],"asks":[]}
1618677778.824002: {"seqnum":370,"event":"updated","channel":"l2","symbol":"DOT-EUR","bids":[],"asks":[{"num":0,"px":36.32,"qty":0.0}]}
1618677778.894669: {"seqnum":371,"event":"updated","channel":"l2","symbol":"DOT-EUR","bids":[],"asks":[{"num":1,"px":36.31,"qty":103.4837}]}
1618677779.375264: {"seqnum":372,"event":"updated","channel":"l2","symbol":"ETH-USDT","bids":[],"asks":[{"num":0,"px":2365.77,"qty":0.0}]}
1618677779.375325: {"seqnum":373,"event":"updated","channel":"l2","symbol":"ETH-USDT","bids":[],"asks":[{"num":1,"px":2365.92,"qty":10.1}]}
1618677779.401647: {"seqnum":374,"event":"updated","channel":"l2","symbol":"DOT-EUR","bids":[],"asks":[{"num":0,"px":36.31,"qty":0.0}]}
1618677779.4016829: {"seqnum":375,"event":"updated","channel":"l2","symbol":"ETH-USDT","bids":[],"asks":[{"num":0,"px":2363.94,"qty":0.0}]}
1618677779.434206: {"seqnum":376,"event":"updated","channel":"l2","symbol":"ETH-USDT","bids":[{"num":0,"px":2362.82,"qty":0.0}],"asks":[]}
1618677779.434242: {"seqnum":377,"event":"updated","channel":"l2","symbol":"ETH-USDT","bids":[{"num":0,"px":2362.09,"qty":0.0}],"asks":[]}
1618677779.468116: {"seqnum":378,"event":"updated","channel":"l2","symbol":"DOT-GBP","bids":[],"asks":[{"num":0,"px":31.59,"qty":0.0}]}
1618677779.4681869: {"seqnum":379,"event":"updated","channel":"l2","symbol":"DOT-GBP","bids":[{"num":0,"px":31.55,"qty":0.0}],"asks":[]}
1618677779.468232: {"seqnum":380,"event":"updated","channel":"l2","symbol":"DOT-GBP","bids":[],"asks":[{"num":0,"px":31.61,"qty":0.0}]}
1618677779.538805: {"seqnum":381,"event":"updated","channel":"l2","symbol":"DOT-EUR","bids":[],"asks":[{"num":1,"px":36.32,"qty":103.4579}]}
1618677779.572104: {"seqnum":382,"event":"updated","channel":"l2","symbol":"ETH-USDT","bids":[],"asks":[{"num":1,"px":2364.11,"qty":2.5364}]}
1618677779.572186: {"seqnum":383,"event":"updated","channel":"l2","symbol":"ETH-USDT","bids":[{"num":1,"px":2363.0,"qty":2.5364}],"asks":[]}
1618677779.572222: {"seqnum":384,"event":"updated","channel":"l2","symbol":"ETH-USDT","bids":[{"num":1,"px":2362.53,"qty":9.3001}],"asks":[]}
1618677779.5735412: {"seqnum":385,"event":"updated","channel":"l2","symbol":"ETH-USDT","bids":[],"asks":[{"num":0,"px":2365.92,"qty":0.0}]}
1618677779.5736032: {"seqnum":386,"event":"updated","channel":"l2","symbol":"ETH-USDT","bids":[],"asks":[{"num":1,"px":2366.02,"qty":10.1}]}
1618677779.6052322: {"seqnum":387,"event":"updated","channel":"l2","symbol":"DOT-GBP","bids":[],"asks":[{"num":1,"px":31.61,"qty":103.4333}]}
1618677779.605293: {"seqnum":388,"event":"updated","channel":"l2","symbol":"DOT-GBP","bids":[{"num":1,"px":31.56,"qty":103.438}],"asks":[]}
1618677779.605332: {"seqnum":389,"event":"updated","channel":"l2","symbol":"DOT-GBP","bids":[],"asks":[{"num":1,"px":31.62,"qty":183.8815}]}
1618677779.63596: {"seqnum":390,"event":"updated","channel":"l2","symbol":"ETH-USDT","bids":[],"asks":[{"num":0,"px":2364.18,"qty":0.0}]}
1618677779.6360278: {"seqnum":391,"event":"updated","channel":"l2","symbol":"ETH-USDT","bids":[{"num":0,"px":2362.64,"qty":0.0}],"asks":[]}
1618677779.636069: {"seqnum":392,"event":"updated","channel":"l2","symbol":"ETH-USDT","bids":[],"asks":[{"num":0,"px":2364.32,"qty":0.0}]}
1618677779.6930912: {"seqnum":393,"event":"updated","channel":"l2","symbol":"DOT-EUR","bids":[],"asks":[{"num":0,"px":36.32,"qty":0.0}]}
1618677779.693182: {"seqnum":394,"event":"updated","channel":"l2","symbol":"ETH-USDT","bids":[],"asks":[{"num":0,"px":2364.11,"qty":0.0}]}
1618677779.693225: {"seqnum":395,"event":"updated","channel":"l2","symbol":"ETH-USDT","bids":[{"num":0,"px":2363.0,"qty":0.0}],"asks":[]}
1618677779.884228: {"seqnum":396,"event":"updated","channel":"l2","symbol":"DOT-EUR","bids":[],"asks":[{"num":1,"px":36.33,"qty":103.4292}]}
1618677779.884358: {"seqnum":397,"event":"updated","channel":"l2","symbol":"ETH-USDT","bids":[],"asks":[{"num":1,"px":2364.28,"qty":2.5363}]}
1618677779.884421: {"seqnum":398,"event":"updated","channel":"l2","symbol":"ETH-USDT","bids":[{"num":1,"px":2363.14,"qty":2.5363}],"asks":[]}
1618677779.884471: {"seqnum":399,"event":"updated","channel":"l2","symbol":"ETH-USDT","bids":[],"asks":[{"num":1,"px":2364.51,"qty":6.7633}]}
1618677779.884515: {"seqnum":400,"event":"updated","channel":"l2","symbol":"ETH-USDT","bids":[{"num":1,"px":2362.9,"qty":6.7633}],"asks":[]}
1618677779.884557: {"seqnum":401,"event":"updated","channel":"l2","symbol":"ETH-USDT","bids":[],"asks":[{"num":1,"px":2364.75,"qty":9.2995}]}
1618677779.921908: {"seqnum":402,"event":"updated","channel":"l2","symbol":"DOT-GBP","bids":[],"asks":[{"num":0,"px":31.61,"qty":0.0}]}
1618677779.971411: {"seqnum":403,"event":"updated","channel":"l2","symbol":"ETH-USDT","bids":[],"asks":[{"num":0,"px":2366.02,"qty":0.0}]}
1618677779.971495: {"seqnum":404,"event":"updated","channel":"l2","symbol":"ETH-USDT","bids":[],"asks":[{"num":1,"px":2366.16,"qty":10.1}]}
1618677780.11436: {"seqnum":405,"event":"updated","channel":"l2","symbol":"DOT-GBP","bids":[],"asks":[{"num":1,"px":31.6,"qty":103.4398}]}
1618677780.461419: {"seqnum":406,"event":"updated","channel":"l2","symbol":"DOT-EUR","bids":[],"asks":[{"num":0,"px":36.33,"qty":0.0}]}
1618677780.4615538: {"seqnum":407,"event":"updated","channel":"l2","symbol":"DOT-GBP","bids":[{"num":0,"px":31.56,"qty":0.0}],"asks":[]}
1618677780.461619: {"seqnum":408,"event":"updated","channel":"l2","symbol":"DOT-GBP","bids":[],"asks":[{"num":0,"px":31.6,"qty":0.0}]}
1618677780.4616709: {"seqnum":409,"event":"updated","channel":"l2","symbol":"DOT-GBP","bids":[],"asks":[{"num":0,"px":31.62,"qty":0.0}]}
1618677780.461717: {"seqnum":410,"event":"updated","channel":"l2","symbol":"ETH-USDT","bids":[],"asks":[{"num":0,"px":2366.16,"qty":0.0}]}
1618677780.461764: {"seqnum":411,"event":"updated","channel":"l2","symbol":"ETH-USDT","bids":[],"asks":[{"num":1,"px":2365.76,"qty":10.1}]}
1618677780.5715468: {"seqnum":412,"event":"updated","channel":"l2","symbol":"DOT-EUR","bids":[],"asks":[{"num":1,"px":36.32,"qty":103.4653}]}
1618677780.5716102: {"seqnum":413,"event":"updated","channel":"l2","symbol":"DOT-GBP","bids":[],"asks":[{"num":1,"px":31.59,"qty":103.4653}]}
1618677780.5716321: {"seqnum":414,"event":"updated","channel":"l2","symbol":"DOT-GBP","bids":[{"num":1,"px":31.55,"qty":103.4653}],"asks":[]}
1618677780.571651: {"seqnum":415,"event":"updated","channel":"l2","symbol":"DOT-GBP","bids":[],"asks":[{"num":1,"px":31.61,"qty":183.9383}]}
1618677781.1759381: {"seqnum":416,"event":"updated","channel":"l2","symbol":"ETH-USDT","bids":[],"asks":[{"num":0,"px":2365.76,"qty":0.0}]}
1618677781.176034: {"seqnum":417,"event":"updated","channel":"l2","symbol":"ETH-USDT","bids":[],"asks":[{"num":1,"px":2365.96,"qty":10.1}]}
1618677781.176646: {"seqnum":418,"event":"updated","channel":"l2","symbol":"ENJ-USD","bids":[{"num":2,"px":2.7421,"qty":13333.333332}],"asks":[]}
1618677781.2036579: {"seqnum":419,"event":"updated","channel":"l2","symbol":"ENJ-USD","bids":[{"num":1,"px":2.7421,"qty":6666.666666}],"asks":[]}
1618677781.203718: {"seqnum":420,"event":"updated","channel":"l2","symbol":"ENJ-USD","bids":[{"num":0,"px":2.7421,"qty":0.0}],"asks":[]}
1618677781.275187: {"seqnum":421,"event":"updated","channel":"l2","symbol":"ENJ-USD","bids":[{"num":1,"px":2.6085,"qty":6666.666666}],"asks":[]}
1618677781.320024: {"seqnum":422,"event":"updated","channel":"l2","symbol":"ENJ-USD","bids":[{"num":2,"px":2.6085,"qty":13333.333332}],"asks":[]}
1618677781.320117: {"seqnum":423,"event":"updated","channel":"l2","symbol":"ENJ-USD","bids":[{"num":3,"px":2.6085,"qty":19999.999998}],"asks":[]}
1618677781.473666: {"seqnum":424,"event":"updated","channel":"l2","symbol":"ETH-USDT","bids":[],"asks":[{"num":0,"px":2365.96,"qty":0.0}]}
1618677781.4737432: {"seqnum":425,"event":"updated","channel":"l2","symbol":"ETH-USDT","bids":[],"asks":[{"num":1,"px":2366.16,"qty":10.1}]}
1618677781.594826: {"seqnum":426,"event":"updated","channel":"l2","symbol":"XLM-EUR","bids":[],"asks":[{"num":0,"px":0.50434,"qty":0.0}]}
1618677781.66854: {"seqnum":427,"event":"updated","channel":"l2","symbol":"XLM-EUR","bids":[],"asks":[{"num":1,"px":0.50446,"qty":6621.37}]}
1618677782.098103: {"seqnum":428,"event":"updated","channel":"l2","symbol":"XLM-EUR","bids":[],"asks":[{"num":0,"px":0.50446,"qty":0.0}]}
1618677782.0982468: {"seqnum":429,"event":"updated","channel":"l2","symbol":"XLM-EUR","bids":[],"asks":[{"num":0,"px":0.50462,"qty":0.0}]}
1618677782.173702: {"seqnum":430,"event":"updated","channel":"l2","symbol":"ETH-USDT","bids":[],"asks":[{"num":0,"px":2366.16,"qty":0.0}]}
1618677782.175793: {"seqnum":431,"event":"updated","channel":"l2","symbol":"ETH-USDT","bids":[],"asks":[{"num":1,"px":2365.96,"qty":10.1}]}
1618677782.191922: {"seqnum":432,"event":"updated","channel":"l2","symbol":"XLM-EUR","bids":[],"asks":[{"num":1,"px":0.5046,"qty":6619.49}]}
1618677782.192024: {"seqnum":433,"event":"updated","channel":"l2","symbol":"XLM-EUR","bids":[],"asks":[{"num":1,"px":0.50491,"qty":17376.16}]}
1618677782.5863512: {"seqnum":434,"event":"updated","channel":"l2","symbol":"ETH-USDT","bids":[],"asks":[{"num":0,"px":2364.28,"qty":0.0}]}
1618677782.687318: {"seqnum":435,"event":"updated","channel":"l2","symbol":"ETH-USDT","bids":[],"asks":[{"num":1,"px":2364.43,"qty":2.5362}]}
1618677782.760336: {"seqnum":436,"event":"updated","channel":"l2","symbol":"ETH-USDT","bids":[],"asks":[{"num":1,"px":2364.24,"qty":9.97}]}
1618677782.760465: {"seqnum":437,"event":"updated","channel":"l2","symbol":"ETH-USDT","bids":[],"asks":[{"num":0,"px":2364.24,"qty":0.0}]}
1618677782.833777: {"seqnum":438,"event":"updated","channel":"l2","symbol":"ETH-USDT","bids":[],"asks":[{"num":1,"px":2364.24,"qty":9.97}]}
1618677782.8339021: {"seqnum":439,"event":"updated","channel":"l2","symbol":"ETH-USDT","bids":[],"asks":[{"num":0,"px":2364.43,"qty":0.0}]}
1618677782.881845: {"seqnum":440,"event":"updated","channel":"l2","symbol":"ETH-USDT","bids":[{"num":0,"px":2363.14,"qty":0.0}],"asks":[]}
1618677782.908119: {"seqnum":441,"event":"updated","channel":"l2","symbol":"ETH-USDT","bids":[],"asks":[{"num":0,"px":2364.24,"qty":0.0}]}
1618677782.908254: {"seqnum":442,"event":"updated","channel":"l2","symbol":"ETH-USDT","bids":[],"asks":[{"num":1,"px":2364.15,"qty":9.97}]}
1618677782.932033: {"seqnum":443,"event":"updated","channel":"l2","symbol":"ETH-USDT","bids":[{"num":0,"px":2362.9,"qty":0.0}],"asks":[]}
1618677782.932142: {"seqnum":444,"event":"updated","channel":"l2","symbol":"ETH-USDT","bids":[],"asks":[{"num":0,"px":2364.51,"qty":0.0}]}
1618677783.035506: {"seqnum":445,"event":"updated","channel":"l2","symbol":"ETH-USDT","bids":[],"asks":[{"num":0,"px":2365.96,"qty":0.0}]}
1618677783.0428622: {"seqnum":446,"event":"updated","channel":"l2","symbol":"ETH-USDT","bids":[],"asks":[{"num":1,"px":2365.67,"qty":10.1}]}
1618677783.0558531: {"seqnum":447,"event":"updated","channel":"l2","symbol":"ETH-USDT","bids":[],"asks":[{"num":1,"px":2364.06,"qty":2.5366}]}
1618677783.055974: {"seqnum":448,"event":"updated","channel":"l2","symbol":"ETH-USDT","bids":[{"num":1,"px":2362.79,"qty":2.5366}],"asks":[]}
1618677783.056034: {"seqnum":449,"event":"updated","channel":"l2","symbol":"ETH-USDT","bids":[],"asks":[{"num":1,"px":2364.21,"qty":6.7643}]}
1618677783.0560799: {"seqnum":450,"event":"updated","channel":"l2","symbol":"ETH-USDT","bids":[{"num":1,"px":2362.56,"qty":6.7643}],"asks":[]}
1618677783.1709719: {"seqnum":451,"event":"updated","channel":"l2","symbol":"ETH-USDT","bids":[],"asks":[{"num":0,"px":2364.15,"qty":0.0}]}
1618677783.1711109: {"seqnum":452,"event":"updated","channel":"l2","symbol":"ETH-USDT","bids":[],"asks":[{"num":1,"px":2363.95,"qty":9.97}]}
1618677783.326556: {"seqnum":453,"event":"updated","channel":"l2","symbol":"ETH-USDT","bids":[],"asks":[{"num":0,"px":2364.06,"qty":0.0}]}
1618677783.326693: {"seqnum":454,"event":"updated","channel":"l2","symbol":"ETH-USDT","bids":[],"asks":[{"num":0,"px":2364.75,"qty":0.0}]}
1618677783.3267572: {"seqnum":455,"event":"updated","channel":"l2","symbol":"ETH-USDT","bids":[],"asks":[{"num":0,"px":2363.95,"qty":0.0}]}
1618677783.3268092: {"seqnum":456,"event":"updated","channel":"l2","symbol":"ETH-USDT","bids":[],"asks":[{"num":1,"px":2363.68,"qty":9.97}]}
1618677783.33127: {"seqnum":457,"event":"updated","channel":"l2","symbol":"ETH-USDT","bids":[{"num":0,"px":2362.79,"qty":0.0}],"asks":[]}
1618677783.331407: {"seqnum":458,"event":"updated","channel":"l2","symbol":"ETH-USDT","bids":[{"num":0,"px":2362.53,"qty":0.0}],"asks":[]}
1618677783.337727: {"seqnum":459,"event":"updated","channel":"l2","symbol":"ETH-USDT","bids":[{"num":0,"px":2362.56,"qty":0.0}],"asks":[]}
1618677783.353295: {"seqnum":460,"event":"updated","channel":"l2","symbol":"ETH-USDT","bids":[],"asks":[{"num":0,"px":2363.68,"qty":0.0}]}
1618677783.353436: {"seqnum":461,"event":"updated","channel":"l2","symbol":"ETH-USDT","bids":[],"asks":[{"num":1,"px":2363.51,"qty":9.97}]}
1618677783.353514: {"seqnum":462,"event":"updated","channel":"l2","symbol":"ETH-USDT","bids":[],"asks":[{"num":0,"px":2364.21,"qty":0.0}]}
1618677783.353547: {"seqnum":463,"event":"updated","channel":"l2","symbol":"ETH-USDT","bids":[],"asks":[{"num":0,"px":2365.97,"qty":0.0}]}
1618677783.353577: {"seqnum":464,"event":"updated","channel":"l2","symbol":"ETH-USDT","bids":[{"num":0,"px":2360.89,"qty":0.0}],"asks":[]}
1618677783.353606: {"seqnum":465,"event":"updated","channel":"l2","symbol":"ETH-USDT","bids":[{"num":0,"px":2359.71,"qty":0.0}],"asks":[]}
1618677783.353633: {"seqnum":466,"event":"updated","channel":"l2","symbol":"ETH-USDT","bids":[{"num":0,"px":2359.62,"qty":0.0}],"asks":[]}
1618677783.3536599: {"seqnum":467,"event":"updated","channel":"l2","symbol":"ETH-USDT","bids":[],"asks":[{"num":0,"px":2363.51,"qty":0.0}]}
1618677783.353686: {"seqnum":468,"event":"updated","channel":"l2","symbol":"ETH-USDT","bids":[],"asks":[{"num":1,"px":2363.43,"qty":9.97}]}
1618677783.353712: {"seqnum":469,"event":"updated","channel":"l2","symbol":"ETH-USDT","bids":[],"asks":[{"num":0,"px":2363.43,"qty":0.0}]}
1618677783.3537369: {"seqnum":470,"event":"updated","channel":"l2","symbol":"ETH-USDT","bids":[],"asks":[{"num":1,"px":2363.43,"qty":9.97}]}
1618677783.376002: {"seqnum":471,"event":"updated","channel":"l2","symbol":"ETH-USDT","bids":[],"asks":[{"num":0,"px":2363.43,"qty":0.0}]}
1618677783.3760488: {"seqnum":472,"event":"updated","channel":"l2","symbol":"ETH-USDT","bids":[],"asks":[{"num":1,"px":2363.24,"qty":9.97}]}
1618677783.390986: {"seqnum":473,"event":"updated","channel":"l2","symbol":"ETH-USDT","bids":[],"asks":[{"num":0,"px":2365.67,"qty":0.0}]}
1618677783.391089: {"seqnum":474,"event":"updated","channel":"l2","symbol":"ETH-USDT","bids":[],"asks":[{"num":1,"px":2365.64,"qty":10.1}]}
1618677783.397644: {"seqnum":475,"event":"updated","channel":"l2","symbol":"ETH-USDT","bids":[],"asks":[{"num":0,"px":2367.2,"qty":0.0}]}
1618677783.464592: {"seqnum":476,"event":"updated","channel":"l2","symbol":"ETH-USDT","bids":[],"asks":[{"num":0,"px":2363.24,"qty":0.0}]}
1618677783.499787: {"seqnum":477,"event":"updated","channel":"l2","symbol":"DOT-EUR","bids":[],"asks":[{"num":0,"px":36.32,"qty":0.0}]}
1618677783.5098119: {"seqnum":478,"event":"updated","channel":"l2","symbol":"ETH-USDT","bids":[],"asks":[{"num":0,"px":2365.64,"qty":0.0}]}
1618677783.5098822: {"seqnum":479,"event":"updated","channel":"l2","symbol":"ETH-USDT","bids":[],"asks":[{"num":1,"px":2364.65,"qty":10.1}]}
1618677783.595018: {"seqnum":480,"event":"updated","channel":"l2","symbol":"ETH-USDT","bids":[{"num":1,"px":2361.44,"qty":2.5378}],"asks":[]}
1618677783.595155: {"seqnum":481,"event":"updated","channel":"l2","symbol":"ETH-USDT","bids":[],"asks":[{"num":1,"px":2362.8,"qty":2.5378}]}
1618677783.595231: {"seqnum":482,"event":"updated","channel":"l2","symbol":"ETH-USDT","bids":[{"num":1,"px":2361.27,"qty":6.7671}],"asks":[]}
1618677783.595262: {"seqnum":483,"event":"updated","channel":"l2","symbol":"ETH-USDT","bids":[],"asks":[{"num":1,"px":2362.96,"qty":6.7676}]}
1618677783.595289: {"seqnum":484,"event":"updated","channel":"l2","symbol":"ETH-USDT","bids":[{"num":1,"px":2361.03,"qty":9.3048}],"asks":[]}
1618677783.595315: {"seqnum":485,"event":"updated","channel":"l2","symbol":"ETH-USDT","bids":[],"asks":[{"num":1,"px":2363.42,"qty":9.3045}]}
1618677783.59534: {"seqnum":486,"event":"updated","channel":"l2","symbol":"ETH-USDT","bids":[{"num":1,"px":2359.7,"qty":6.7669}],"asks":[]}
1618677783.5953631: {"seqnum":487,"event":"updated","channel":"l2","symbol":"ETH-USDT","bids":[],"asks":[{"num":1,"px":2364.95,"qty":6.7667}]}
1618677783.595387: {"seqnum":488,"event":"updated","channel":"l2","symbol":"ETH-USDT","bids":[{"num":1,"px":2358.58,"qty":6.7669}],"asks":[]}
1618677783.595415: {"seqnum":489,"event":"updated","channel":"l2","symbol":"ETH-USDT","bids":[],"asks":[{"num":1,"px":2366.2,"qty":6.7665}]}
1618677783.5954392: {"seqnum":490,"event":"updated","channel":"l2","symbol":"ETH-USDT","bids":[{"num":1,"px":2358.41,"qty":0.8457}],"asks":[]}
1618677783.5954628: {"seqnum":491,"event":"updated","channel":"l2","symbol":"ETH-USDT","bids":[],"asks":[{"num":0,"px":2364.65,"qty":0.0}]}
1618677783.595495: {"seqnum":492,"event":"updated","channel":"l2","symbol":"ETH-USDT","bids":[],"asks":[{"num":1,"px":2364.16,"qty":10.1}]}
1618677783.59552: {"seqnum":493,"event":"updated","channel":"l2","symbol":"ETH-USDT","bids":[],"asks":[{"num":1,"px":2362.83,"qty":9.97}]}
1618677783.645897: {"seqnum":494,"event":"updated","channel":"l2","symbol":"ENJ-USD","bids":[{"num":1,"px":2.85,"qty":21.0}],"asks":[]}
1618677783.668422: {"seqnum":495,"event":"updated","channel":"l2","symbol":"ETH-USDT","bids":[],"asks":[{"num":0,"px":2362.83,"qty":0.0}]}
1618677783.668559: {"seqnum":496,"event":"updated","channel":"l2","symbol":"ETH-USDT","bids":[],"asks":[{"num":1,"px":2362.92,"qty":9.97}]}
1618677783.6686249: {"seqnum":497,"event":"updated","channel":"l2","symbol":"ETH-USDT","bids":[],"asks":[{"num":0,"px":2362.92,"qty":0.0}]}
1618677783.6686778: {"seqnum":498,"event":"updated","channel":"l2","symbol":"DOT-EUR","bids":[],"asks":[{"num":1,"px":36.31,"qty":103.4879}]}
1618677783.668726: {"seqnum":499,"event":"updated","channel":"l2","symbol":"ETH-USDT","bids":[],"asks":[{"num":0,"px":2367.91,"qty":0.0}]}
1618677783.6687832: {"seqnum":500,"event":"updated","channel":"l2","symbol":"DOT-EUR","bids":[],"asks":[{"num":0,"px":36.4,"qty":0.0}]}
1618677783.668834: {"seqnum":501,"event":"updated","channel":"l2","symbol":"DOT-GBP","bids":[],"asks":[{"num":0,"px":31.59,"qty":0.0}]}
1618677783.6688619: {"seqnum":502,"event":"updated","channel":"l2","symbol":"DOT-GBP","bids":[],"asks":[{"num":0,"px":31.61,"qty":0.0}]}
1618677783.6869278: {"seqnum":503,"event":"updated","channel":"l2","symbol":"ETH-USDT","bids":[],"asks":[{"num":1,"px":2362.78,"qty":9.97}]}
1618677783.6870122: {"seqnum":504,"event":"updated","channel":"l2","symbol":"ETH-USDT","bids":[],"asks":[{"num":0,"px":2364.16,"qty":0.0}]}
1618677783.6870558: {"seqnum":505,"event":"updated","channel":"l2","symbol":"ETH-USDT","bids":[],"asks":[{"num":1,"px":2364.26,"qty":10.1}]}
1618677783.73088: {"seqnum":506,"event":"updated","channel":"l2","symbol":"ETH-USDT","bids":[],"asks":[{"num":0,"px":2362.78,"qty":0.0}]}
1618677783.7309551: {"seqnum":507,"event":"updated","channel":"l2","symbol":"ETH-USDT","bids":[],"asks":[{"num":1,"px":2362.62,"qty":9.97}]}
1618677783.781107: {"seqnum":508,"event":"updated","channel":"l2","symbol":"ETH-USDT","bids":[{"num":0,"px":2361.44,"qty":0.0}],"asks":[]}
1618677783.7811751: {"seqnum":509,"event":"updated","channel":"l2","symbol":"ETH-USDT","bids":[],"asks":[{"num":0,"px":2362.8,"qty":0.0}]}
1618677783.781218: {"seqnum":510,"event":"updated","channel":"l2","symbol":"ETH-USDT","bids":[{"num":0,"px":2361.27,"qty":0.0}],"asks":[]}
1618677783.783743: {"seqnum":511,"event":"updated","channel":"l2","symbol":"ETH-USDT","bids":[{"num":0,"px":2361.03,"qty":0.0}],"asks":[]}
1618677783.786861: {"seqnum":512,"event":"updated","channel":"l2","symbol":"ETH-USDT","bids":[],"asks":[{"num":0,"px":2363.42,"qty":0.0}]}
1618677783.7869272: {"seqnum":513,"event":"updated","channel":"l2","symbol":"ETH-USDT","bids":[],"asks":[{"num":0,"px":2364.95,"qty":0.0}]}
1618677783.792564: {"seqnum":514,"event":"updated","channel":"l2","symbol":"ETH-USDT","bids":[],"asks":[{"num":0,"px":2362.62,"qty":0.0}]}
1618677783.792636: {"seqnum":515,"event":"updated","channel":"l2","symbol":"ETH-USDT","bids":[],"asks":[{"num":1,"px":2362.78,"qty":9.97}]}
1618677783.852341: {"seqnum":516,"event":"updated","channel":"l2","symbol":"DOT-GBP","bids":[],"asks":[{"num":1,"px":31.58,"qty":103.4954}]}
1618677783.852406: {"seqnum":517,"event":"updated","channel":"l2","symbol":"DOT-GBP","bids":[],"asks":[{"num":1,"px":31.6,"qty":183.9918}]}
1618677783.863913: {"seqnum":518,"event":"updated","channel":"l2","symbol":"ETH-USDT","bids":[{"num":0,"px":2359.7,"qty":0.0}],"asks":[]}
1618677783.875873: {"seqnum":519,"event":"updated","channel":"l2","symbol":"ETH-USDT","bids":[],"asks":[{"num":0,"px":2362.78,"qty":0.0}]}
1618677783.9320939: {"seqnum":520,"event":"updated","channel":"l2","symbol":"ETH-USDT","bids":[{"num":0,"px":2358.58,"qty":0.0}],"asks":[]}
1618677783.9321458: {"seqnum":521,"event":"updated","channel":"l2","symbol":"ETH-USDT","bids":[{"num":0,"px":2358.41,"qty":0.0}],"asks":[]}
1618677783.961813: {"seqnum":522,"event":"updated","channel":"l2","symbol":"DOT-EUR","bids":[],"asks":[{"num":0,"px":36.34,"qty":0.0}]}
1618677783.961869: {"seqnum":523,"event":"updated","channel":"l2","symbol":"DOT-GBP","bids":[{"num":0,"px":31.55,"qty":0.0}],"asks":[]}
1618677783.9619021: {"seqnum":524,"event":"updated","channel":"l2","symbol":"DOT-GBP","bids":[{"num":0,"px":31.54,"qty":0.0}],"asks":[]}
1618677783.9619288: {"seqnum":525,"event":"updated","channel":"l2","symbol":"DOT-GBP","bids":[{"num":0,"px":31.53,"qty":0.0}],"asks":[]}
1618677783.979899: {"seqnum":526,"event":"updated","channel":"l2","symbol":"ETH-USDT","bids":[],"asks":[{"num":0,"px":2364.26,"qty":0.0}]}
1618677783.9799511: {"seqnum":527,"event":"updated","channel":"l2","symbol":"ETH-USDT","bids":[],"asks":[{"num":1,"px":2364.64,"qty":10.1}]}
1618677784.090622: {"seqnum":528,"event":"updated","channel":"l2","symbol":"ETH-USDT","bids":[{"num":1,"px":2361.08,"qty":2.5381}],"asks":[]}
1618677784.090702: {"seqnum":529,"event":"updated","channel":"l2","symbol":"ETH-USDT","bids":[],"asks":[{"num":1,"px":2362.46,"qty":2.5381}]}
1618677784.0907362: {"seqnum":530,"event":"updated","channel":"l2","symbol":"ETH-USDT","bids":[{"num":1,"px":2361.02,"qty":6.7678}],"asks":[]}
1618677784.09668: {"seqnum":531,"event":"updated","channel":"l2","symbol":"ETH-USDT","bids":[],"asks":[{"num":1,"px":2362.93,"qty":9.3064}]}
1618677784.096738: {"seqnum":532,"event":"updated","channel":"l2","symbol":"ETH-USDT","bids":[{"num":1,"px":2360.69,"qty":9.3061}],"asks":[]}
1618677784.0967731: {"seqnum":533,"event":"updated","channel":"l2","symbol":"ETH-USDT","bids":[],"asks":[{"num":1,"px":2364.43,"qty":6.7681}]}
1618677784.0968: {"seqnum":534,"event":"updated","channel":"l2","symbol":"ETH-USDT","bids":[{"num":1,"px":2359.11,"qty":6.7685}],"asks":[]}
1618677784.096823: {"seqnum":535,"event":"updated","channel":"l2","symbol":"ETH-USDT","bids":[],"asks":[{"num":1,"px":2366.42,"qty":0.846}]}
1618677784.096844: {"seqnum":536,"event":"updated","channel":"l2","symbol":"ETH-USDT","bids":[{"num":1,"px":2357.93,"qty":6.7685}],"asks":[]}
1618677784.096865: {"seqnum":537,"event":"updated","channel":"l2","symbol":"ETH-USDT","bids":[{"num":1,"px":2357.22,"qty":0.8461}],"asks":[]}
1618677784.128938: {"seqnum":538,"event":"updated","channel":"l2","symbol":"DOT-EUR","bids":[],"asks":[{"num":1,"px":36.33,"qty":184.0013}]}
1618677784.129031: {"seqnum":539,"event":"updated","channel":"l2","symbol":"DOT-EUR","bids":[],"asks":[{"num":1,"px":36.35,"qty":114.9949}]}
1618677784.1290612: {"seqnum":540,"event":"updated","channel":"l2","symbol":"DOT-GBP","bids":[{"num":1,"px":31.54,"qty":103.5007}],"asks":[]}
1618677784.129089: {"seqnum":541,"event":"updated","channel":"l2","symbol":"DOT-GBP","bids":[{"num":1,"px":31.52,"qty":184.0013}],"asks":[]}
1618677784.129112: {"seqnum":542,"event":"updated","channel":"l2","symbol":"DOT-GBP","bids":[{"num":1,"px":31.49,"qty":115.0008}],"asks":[]}
1618677784.276614: {"seqnum":543,"event":"updated","channel":"l2","symbol":"ETH-USDT","bids":[],"asks":[{"num":0,"px":2364.64,"qty":0.0}]}
1618677784.280004: {"seqnum":544,"event":"updated","channel":"l2","symbol":"ETH-USDT","bids":[],"asks":[{"num":1,"px":2364.6,"qty":10.1}]}
1618677784.37692: {"seqnum":545,"event":"updated","channel":"l2","symbol":"ETH-USDT","bids":[],"asks":[{"num":0,"px":2364.6,"qty":0.0}]}
1618677784.385449: {"seqnum":546,"event":"updated","channel":"l2","symbol":"ETH-USDT","bids":[],"asks":[{"num":1,"px":2364.49,"qty":10.1}]}
1618677784.562311: {"seqnum":547,"event":"updated","channel":"l2","symbol":"DOT-EUR","bids":[],"asks":[{"num":0,"px":36.31,"qty":0.0}]}
1618677784.562371: {"seqnum":548,"event":"updated","channel":"l2","symbol":"DOT-GBP","bids":[{"num":0,"px":31.54,"qty":0.0}],"asks":[]}
1618677784.562391: {"seqnum":549,"event":"updated","channel":"l2","symbol":"DOT-GBP","bids":[],"asks":[{"num":0,"px":31.65,"qty":0.0}]}
1618677784.586966: {"seqnum":550,"event":"updated","channel":"l2","symbol":"ETH-USDT","bids":[],"asks":[{"num":0,"px":2364.49,"qty":0.0}]}
1618677784.587049: {"seqnum":551,"event":"updated","channel":"l2","symbol":"ETH-USDT","bids":[],"asks":[{"num":1,"px":2364.0,"qty":10.1}]}
1618677784.631964: {"seqnum":552,"event":"updated","channel":"l2","symbol":"DOT-EUR","bids":[],"asks":[{"num":0,"px":36.33,"qty":0.0}]}
1618677784.631992: {"seqnum":553,"event":"updated","channel":"l2","symbol":"DOT-GBP","bids":[{"num":0,"px":31.52,"qty":0.0}],"asks":[]}
1618677784.632011: {"seqnum":554,"event":"updated","channel":"l2","symbol":"DOT-GBP","bids":[],"asks":[{"num":0,"px":31.58,"qty":0.0}]}
1618677784.632045: {"seqnum":555,"event":"updated","channel":"l2","symbol":"DOT-GBP","bids":[{"num":0,"px":31.49,"qty":0.0}],"asks":[]}
1618677784.6945431: {"seqnum":556,"event":"updated","channel":"l2","symbol":"DOT-GBP","bids":[],"asks":[{"num":0,"px":31.6,"qty":0.0}]}
1618677784.6945732: {"seqnum":557,"event":"updated","channel":"l2","symbol":"ETH-USDT","bids":[],"asks":[{"num":1,"px":2362.62,"qty":9.97}]}
1618677784.6946309: {"seqnum":558,"event":"updated","channel":"l2","symbol":"ETH-USDT","bids":[],"asks":[{"num":0,"px":2362.62,"qty":0.0}]}
1618677784.6946611: {"seqnum":559,"event":"updated","channel":"l2","symbol":"ETH-USDT","bids":[],"asks":[{"num":1,"px":2362.51,"qty":9.97}]}
1618677784.694674: {"seqnum":560,"event":"updated","channel":"l2","symbol":"DOT-GBP","bids":[{"num":0,"px":31.51,"qty":0.0}],"asks":[]}
1618677784.694688: {"seqnum":561,"event":"updated","channel":"l2","symbol":"ETH-USDT","bids":[],"asks":[{"num":0,"px":2364.0,"qty":0.0}]}
1618677784.69472: {"seqnum":562,"event":"updated","channel":"l2","symbol":"ETH-USDT","bids":[],"asks":[{"num":1,"px":2364.44,"qty":10.1}]}
1618677784.7531478: {"seqnum":563,"event":"updated","channel":"l2","symbol":"ETH-USDT","bids":[],"asks":[{"num":0,"px":2362.51,"qty":0.0}]}
1618677784.753215: {"seqnum":564,"event":"updated","channel":"l2","symbol":"ETH-USDT","bids":[],"asks":[{"num":1,"px":2362.39,"qty":9.97}]}
1618677784.753233: {"seqnum":565,"event":"updated","channel":"l2","symbol":"ETH-USDT","bids":[],"asks":[{"num":0,"px":2362.39,"qty":0.0}]}
1618677784.753248: {"seqnum":566,"event":"updated","channel":"l2","symbol":"ETH-USDT","bids":[],"asks":[{"num":1,"px":2362.39,"qty":9.97}]}
1618677784.799956: {"seqnum":567,"event":"updated","channel":"l2","symbol":"ETH-USDT","bids":[{"num":0,"px":2361.02,"qty":0.0}],"asks":[]}
1618677784.8270059: {"seqnum":568,"event":"updated","channel":"l2","symbol":"DOT-EUR","bids":[],"asks":[{"num":0,"px":36.37,"qty":0.0}]}
1618677784.82708: {"seqnum":569,"event":"updated","channel":"l2","symbol":"DOT-GBP","bids":[],"asks":[{"num":0,"px":31.63,"qty":0.0}]}
1618677784.909305: {"seqnum":570,"event":"updated","channel":"l2","symbol":"ETH-USDT","bids":[],"asks":[{"num":0,"px":2364.44,"qty":0.0}]}
1618677784.909374: {"seqnum":571,"event":"updated","channel":"l2","symbol":"ETH-USDT","bids":[],"asks":[{"num":1,"px":2364.26,"qty":10.1}]}
1618677784.909406: {"seqnum":572,"event":"updated","channel":"l2","symbol":"ETH-USDT","bids":[],"asks":[{"num":0,"px":2362.39,"qty":0.0}]}
1618677784.909428: {"seqnum":573,"event":"updated","channel":"l2","symbol":"ETH-USDT","bids":[{"num":0,"px":2361.08,"qty":0.0}],"asks":[]}
1618677784.9094489: {"seqnum":574,"event":"updated","channel":"l2","symbol":"ETH-USDT","bids":[{"num":0,"px":2360.69,"qty":0.0}],"asks":[]}
1618677784.926242: {"seqnum":575,"event":"updated","channel":"l2","symbol":"ETH-USDT","bids":[],"asks":[{"num":0,"px":2362.46,"qty":0.0}]}
1618677784.926291: {"seqnum":576,"event":"updated","channel":"l2","symbol":"ETH-USDT","bids":[],"asks":[{"num":0,"px":2362.96,"qty":0.0}]}
1618677785.0106041: {"seqnum":577,"event":"updated","channel":"l2","symbol":"ETH-USDT","bids":[],"asks":[{"num":0,"px":2364.26,"qty":0.0}]}


