1618677789.7985349: {"topic":"orderBookL2_25.BCHUSDT","type":"delta","data":{"delete":[{"price":"1054.90","symbol":"BCHUSDT","id":"10549000","side":"Sell"},{"price":"1055.05","symbol":"BCHUSDT","id":"10550500","side":"Sell"}],"update":[{"price":"1055.00","symbol":"BCHUSDT","id":"10550000","side":"Sell","size":0.01},{"price":"1055.10","symbol":"BCHUSDT","id":"10551000","side":"Sell","size":6.13}],"insert":[{"price":"1054.85","symbol":"BCHUSDT","id":"10548500","side":"Sell","size":14.14},{"price":"1056.10","symbol":"BCHUSDT","id":"10561000","side":"Sell","size":11.670001}]},"cross_seq":"864132355","timestamp_e6":"1618677789588724"}
1618677789.798578: {"topic":"orderBookL2_25.XTZUSDT","type":"delta","data":{"delete":[],"update":[{"price":"7.206","symbol":"XTZUSDT","id":"72060","side":"Buy","size":3863.9}],"insert":[]},"cross_seq":"726228284","timestamp_e6":"1618677789595363"}
1618677789.7985961: {"topic":"orderBookL2_25.DOTUSDT","type":"delta","data":{"delete":[{"price":"43.505","symbol":"DOTUSDT","id":"435050","side":"Buy"},{"price":"43.665","symbol":"DOTUSDT","id":"436650","side":"Sell"},{"price":"43.520","symbol":"DOTUSDT","id":"435200","side":"Buy"}],"update":[{"price":"43.555","symbol":"DOTUSDT","id":"435550","side":"Sell","size":531.10004},{"price":"43.500","symbol":"DOTUSDT","id":"435000","side":"Buy","size":368.40002},{"price":"43.550","symbol":"DOTUSDT","id":"435500","side":"Sell","size":428.4},{"price":"43.540","symbol":"DOTUSDT","id":"435400","side":"Sell","size":1304.5}],"insert":[{"price":"43.410","symbol":"DOTUSDT","id":"434100","side":"Buy","size":252.7},{"price":"43.545","symbol":"DOTUSDT","id":"435450","side":"Sell","size":257.9},{"price":"43.405","symbol":"DOTUSDT","id":"434050","side":"Buy","size":444.5}]},"cross_seq":"916953909","timestamp_e6":"1618677789602533"}
1618677789.7986538: {"topic":"orderBookL2_25.UNIUSDT","type":"delta","data":{"delete":[],"update":[{"price":"35.402","symbol":"UNIUSDT","id":"354020","side":"Sell","size":294.4}],"insert":[]},"cross_seq":"916953909","timestamp_e6":"1618677789602712"}
1618677789.798671: {"topic":"orderBookL2_25.LINKUSDT","type":"delta","data":{"delete":[{"price":"41.061","symbol":"LINKUSDT","id":"410610","side":"Sell"},{"price":"41.049","symbol":"LINKUSDT","id":"410490","side":"Buy"},{"price":"41.055","symbol":"LINKUSDT","id":"410550","side":"Buy"},{"price":"41.047","symbol":"LINKUSDT","id":"410470","side":"Buy"},{"price":"41.059","symbol":"LINKUSDT","id":"410590","side":"Sell"},{"price":"41.050","symbol":"LINKUSDT","id":"410500","side":"Buy"},{"price":"41.052","symbol":"LINKUSDT","id":"410520","side":"Buy"},{"price":"41.054","symbol":"LINKUSDT","id":"410540","side":"Buy"},{"price":"41.051","symbol":"LINKUSDT","id":"410510","side":"Buy"},{"price":"41.053","symbol":"LINKUSDT","id":"410530","side":"Buy"},{"price":"41.056","symbol":"LINKUSDT","id":"410560","side":"Buy"}],"update":[{"price":"41.058","symbol":"LINKUSDT","id":"410580","side":"Sell","size":353.3},{"price":"41.057","symbol":"LINKUSDT","id":"410570","side":"Buy","size":40}],"insert":[{"price":"41.026","symbol":"LINKUSDT","id":"410260","side":"Buy","size":734.10004},{"price":"41.044","symbol":"LINKUSDT","id":"410440","side":"Buy","size":364.4},{"price":"41.062","symbol":"LINKUSDT","id":"410620","side":"Sell","size":59.699997},{"price":"41.027","symbol":"LINKUSDT","id":"410270","side":"Buy","size":336.8},{"price":"41.023","symbol":"LINKUSDT","id":"410230","side":"Buy","size":201.9},{"price":"41.063","symbol":"LINKUSDT","id":"410630","side":"Sell","size":91.3},{"price":"41.028","symbol":"LINKUSDT","id":"410280","side":"Buy","size":425.9},{"price":"41.025","symbol":"LINKUSDT","id":"410250","side":"Buy","size":671.1},{"price":"41.030","symbol":"LINKUSDT","id":"410300","side":"Buy","size":113.6},{"price":"41.029","symbol":"LINKUSDT","id":"410290","side":"Buy","size":417.5},{"price":"41.024","symbol":"LINKUSDT","id":"410240","side":"Buy","size":393.80002}]},"cross_seq":"1970979375","timestamp_e6":"1618677789606554"}
1618677789.798787: {"topic":"orderBookL2_25.LTCUSDT","type":"delta","data":{"delete":[{"price":"313.22","symbol":"LTCUSDT","id":"3132200","side":"Sell"}],"update":[{"price":"313.17","symbol":"LTCUSDT","id":"3131700","side":"Sell","size":115.899994},{"price":"313.18","symbol":"LTCUSDT","id":"3131800","side":"Sell","size":76.1},{"price":"313.21","symbol":"LTCUSDT","id":"3132100","side":"Sell","size":38.6}],"insert":[{"price":"313.42","symbol":"LTCUSDT","id":"3134200","side":"Sell","size":59.399998}]},"cross_seq":"1684522738","timestamp_e6":"1618677789619054"}
1618677789.7988229: {"topic":"orderBookL2_25.LINKUSDT","type":"delta","data":{"delete":[{"price":"41.084","symbol":"LINKUSDT","id":"410840","side":"Sell"},{"price":"41.023","symbol":"LINKUSDT","id":"410230","side":"Buy"},{"price":"41.057","symbol":"LINKUSDT","id":"410570","side":"Buy"}],"update":[{"price":"41.064","symbol":"LINKUSDT","id":"410640","side":"Sell","size":92.7},{"price":"41.067","symbol":"LINKUSDT","id":"410670","side":"Sell","size":228.90001}],"insert":[{"price":"41.053","symbol":"LINKUSDT","id":"410530","side":"Buy","size":1.2},{"price":"41.050","symbol":"LINKUSDT","id":"410500","side":"Buy","size":1.4},{"price":"41.061","symbol":"LINKUSDT","id":"410610","side":"Sell","size":1.2}]},"cross_seq":"1970979383","timestamp_e6":"1618677789627306"}
1618677789.798871: {"topic":"orderBookL2_25.LINKUSDT","type":"delta","data":{"delete":[{"price":"41.024","symbol":"LINKUSDT","id":"410240","side":"Buy"},{"price":"41.060","symbol":"LINKUSDT","id":"410600","side":"Sell"},{"price":"41.082","symbol":"LINKUSDT","id":"410820","side":"Sell"},{"price":"41.083","symbol":"LINKUSDT","id":"410830","side":"Sell"}],"update":[{"price":"41.061","symbol":"LINKUSDT","id":"410610","side":"Sell","size":92.5},{"price":"41.058","symbol":"LINKUSDT","id":"410580","side":"Sell","size":66},{"price":"41.026","symbol":"LINKUSDT","id":"410260","side":"Buy","size":704},{"price":"41.042","symbol":"LINKUSDT","id":"410420","side":"Buy","size":248.1}],"insert":[{"price":"41.057","symbol":"LINKUSDT","id":"410570","side":"Sell","size":226.40001},{"price":"41.056","symbol":"LINKUSDT","id":"410560","side":"Sell","size":287.3},{"price":"41.047","symbol":"LINKUSDT","id":"410470","side":"Buy","size":362.00003},{"price":"41.059","symbol":"LINKUSDT","id":"410590","side":"Sell","size":73.1}]},"cross_seq":"1970979394","timestamp_e6":"1618677789644440"}
1618677789.798933: {"topic":"orderBookL2_25.LINKUSDT","type":"delta","data":{"delete":[{"price":"41.058","symbol":"LINKUSDT","id":"410580","side":"Sell"}],"update":[{"price":"41.053","symbol":"LINKUSDT","id":"410530","side":"Buy","size":47.2}],"insert":[{"price":"41.054","symbol":"LINKUSDT","id":"410540","side":"Sell","size":715.99994}]},"cross_seq":"1970979410","timestamp_e6":"1618677789665156"}
1618677789.7989602: {"topic":"orderBookL2_25.LINKUSDT","type":"delta","data":{"delete":[],"update":[{"price":"41.053","symbol":"LINKUSDT","id":"410530","side":"Buy","size":41.2}],"insert":[]},"cross_seq":"1970979411","timestamp_e6":"1618677789685298"}
1618677789.7989771: {"topic":"orderBookL2_25.XTZUSDT","type":"delta","data":{"delete":[],"update":[{"price":"7.215","symbol":"XTZUSDT","id":"72150","side":"Sell","size":1334.1},{"price":"7.219","symbol":"XTZUSDT","id":"72190","side":"Sell","size":1627.5},{"price":"7.210","symbol":"XTZUSDT","id":"72100","side":"Buy","size":1567.5},{"price":"7.217","symbol":"XTZUSDT","id":"72170","side":"Sell","size":899.89996},{"price":"7.214","symbol":"XTZUSDT","id":"72140","side":"Sell","size":2458.2998},{"price":"7.213","symbol":"XTZUSDT","id":"72130","side":"Sell","size":1311.4}],"insert":[]},"cross_seq":"726228295","timestamp_e6":"1618677789694555"}
1618677789.799009: {"topic":"orderBookL2_25.UNIUSDT","type":"delta","data":{"delete":[],"update":[{"price":"35.373","symbol":"UNIUSDT","id":"353730","side":"Buy","size":18.7}],"insert":[]},"cross_seq":"916953915","timestamp_e6":"1618677789702459"}
1618677789.799026: {"topic":"orderBookL2_25.LINKUSDT","type":"delta","data":{"delete":[{"price":"41.056","symbol":"LINKUSDT","id":"410560","side":"Sell"},{"price":"41.081","symbol":"LINKUSDT","id":"410810","side":"Sell"},{"price":"41.044","symbol":"LINKUSDT","id":"410440","side":"Buy"}],"update":[{"price":"41.057","symbol":"LINKUSDT","id":"410570","side":"Sell","size":1.5},{"price":"41.061","symbol":"LINKUSDT","id":"410610","side":"Sell","size":91.3},{"price":"41.067","symbol":"LINKUSDT","id":"410670","side":"Sell","size":227.7},{"price":"41.053","symbol":"LINKUSDT","id":"410530","side":"Buy","size":40},{"price":"41.043","symbol":"LINKUSDT","id":"410430","side":"Buy","size":340},{"price":"41.040","symbol":"LINKUSDT","id":"410400","side":"Buy","size":438.49997},{"price":"41.042","symbol":"LINKUSDT","id":"410420","side":"Buy","size":377.19998},{"price":"41.041","symbol":"LINKUSDT","id":"410410","side":"Buy","size":434.40002},{"price":"41.064","symbol":"LINKUSDT","id":"410640","side":"Sell","size":91.3},{"price":"41.054","symbol":"LINKUSDT","id":"410540","side":"Sell","size":753.30005}],"insert":[{"price":"41.024","symbol":"LINKUSDT","id":"410240","side":"Buy","size":393.80002},{"price":"41.058","symbol":"LINKUSDT","id":"410580","side":"Sell","size":59.699997},{"price":"41.055","symbol":"LINKUSDT","id":"410550","side":"Sell","size":226.40001}]},"cross_seq":"1970979437","timestamp_e6":"1618677789705430"}
1618677789.7990952: {"topic":"orderBookL2_25.ETHUSDT","type":"delta","data":{"delete":[],"update":[{"price":"2363.40","symbol":"ETHUSDT","id":"23634000","side":"Buy","size":16.98},{"price":"2366.30","symbol":"ETHUSDT","id":"23663000","side":"Sell","size":23.92}],"insert":[]},"cross_seq":"1800546422","timestamp_e6":"1618677789707136"}
1618677789.81149: {"topic":"orderBookL2_25.XTZUSDT","type":"delta","data":{"delete":[],"update":[{"price":"7.212","symbol":"XTZUSDT","id":"72120","side":"Sell","size":2751.1},{"price":"7.211","symbol":"XTZUSDT","id":"72110","side":"Buy","size":1850.6}],"insert":[]},"cross_seq":"726228297","timestamp_e6":"1618677789716837"}
1618677789.815743: {"topic":"orderBookL2_25.LINKUSDT","type":"delta","data":{"delete":[{"price":"41.053","symbol":"LINKUSDT","id":"410530","side":"Buy"}],"update":[],"insert":[{"price":"41.023","symbol":"LINKUSDT","id":"410230","side":"Buy","size":201.9}]},"cross_seq":"1970979442","timestamp_e6":"1618677789725702"}
1618677789.824509: {"topic":"orderBookL2_25.XTZUSDT","type":"delta","data":{"delete":[],"update":[{"price":"7.212","symbol":"XTZUSDT","id":"72120","side":"Sell","size":8162.1},{"price":"7.214","symbol":"XTZUSDT","id":"72140","side":"Sell","size":3057},{"price":"7.217","symbol":"XTZUSDT","id":"72170","side":"Sell","size":354.5},{"price":"7.213","symbol":"XTZUSDT","id":"72130","side":"Sell","size":0.4},{"price":"7.211","symbol":"XTZUSDT","id":"72110","side":"Buy","size":1750.6}],"insert":[]},"cross_seq":"726228330","timestamp_e6":"1618677789735894"}
1618677789.831163: {"topic":"orderBookL2_25.DOTUSDT","type":"delta","data":{"delete":[],"update":[{"price":"43.560","symbol":"DOTUSDT","id":"435600","side":"Sell","size":554.6},{"price":"43.575","symbol":"DOTUSDT","id":"435750","side":"Sell","size":300.8},{"price":"43.465","symbol":"DOTUSDT","id":"434650","side":"Buy","size":501.9},{"price":"43.460","symbol":"DOTUSDT","id":"434600","side":"Buy","size":440.19998},{"price":"43.570","symbol":"DOTUSDT","id":"435700","side":"Sell","size":366.59998}],"insert":[]},"cross_seq":"916953921","timestamp_e6":"1618677789742372"}
1618677789.831213: {"topic":"orderBookL2_25.LINKUSDT","type":"delta","data":{"delete":[{"price":"41.046","symbol":"LINKUSDT","id":"410460","side":"Buy"},{"price":"41.079","symbol":"LINKUSDT","id":"410790","side":"Sell"},{"price":"41.080","symbol":"LINKUSDT","id":"410800","side":"Sell"},{"price":"41.045","symbol":"LINKUSDT","id":"410450","side":"Buy"},{"price":"41.078","symbol":"LINKUSDT","id":"410780","side":"Sell"},{"price":"41.047","symbol":"LINKUSDT","id":"410470","side":"Buy"}],"update":[{"price":"41.038","symbol":"LINKUSDT","id":"410380","side":"Buy","size":488.69998},{"price":"41.039","symbol":"LINKUSDT","id":"410390","side":"Buy","size":216.6},{"price":"41.032","symbol":"LINKUSDT","id":"410320","side":"Buy","size":331.5},{"price":"41.037","symbol":"LINKUSDT","id":"410370","side":"Buy","size":545.2},{"price":"41.054","symbol":"LINKUSDT","id":"410540","side":"Sell","size":940.2},{"price":"41.036","symbol":"LINKUSDT","id":"410360","side":"Buy","size":525.3},{"price":"41.041","symbol":"LINKUSDT","id":"410410","side":"Buy","size":187.40001},{"price":"41.034","symbol":"LINKUSDT","id":"410340","side":"Buy","size":248.1},{"price":"41.033","symbol":"LINKUSDT","id":"410330","side":"Buy","size":909.8},{"price":"41.040","symbol":"LINKUSDT","id":"410400","side":"Buy","size":256.7},{"price":"41.035","symbol":"LINKUSDT","id":"410350","side":"Buy","size":438.49997}],"insert":[{"price":"41.051","symbol":"LINKUSDT","id":"410510","side":"Sell","size":202.1},{"price":"41.022","symbol":"LINKUSDT","id":"410220","side":"Buy","size":260.4},{"price":"41.052","symbol":"LINKUSDT","id":"410520","side":"Sell","size":73.1},{"price":"41.053","symbol":"LINKUSDT","id":"410530","side":"Sell","size":59.699997},{"price":"41.020","symbol":"LINKUSDT","id":"410200","side":"Buy","size":331.5},{"price":"41.021","symbol":"LINKUSDT","id":"410210","side":"Buy","size":86.700005}]},"cross_seq":"1970979488","timestamp_e6":"1618677789744094"}
1618677789.8488472: {"topic":"orderBookL2_25.ADAUSDT","type":"delta","data":{"delete":[{"price":"1.3847","symbol":"ADAUSDT","id":"13847","side":"Buy"},{"price":"1.3846","symbol":"ADAUSDT","id":"13846","side":"Buy"}],"update":[],"insert":[{"price":"1.3861","symbol":"ADAUSDT","id":"13861","side":"Buy","size":2265},{"price":"1.3862","symbol":"ADAUSDT","id":"13862","side":"Buy","size":2879.9998}]},"cross_seq":"916953923","timestamp_e6":"1618677789763743"}
1618677789.8531368: {"topic":"orderBookL2_25.LINKUSDT","type":"delta","data":{"delete":[{"price":"41.041","symbol":"LINKUSDT","id":"410410","side":"Buy"},{"price":"41.043","symbol":"LINKUSDT","id":"410430","side":"Buy"},{"price":"41.055","symbol":"LINKUSDT","id":"410550","side":"Sell"},{"price":"41.042","symbol":"LINKUSDT","id":"410420","side":"Buy"},{"price":"41.040","symbol":"LINKUSDT","id":"410400","side":"Buy"}],"update":[{"price":"41.051","symbol":"LINKUSDT","id":"410510","side":"Sell","size":66},{"price":"41.053","symbol":"LINKUSDT","id":"410530","side":"Sell","size":107.1},{"price":"41.039","symbol":"LINKUSDT","id":"410390","side":"Buy","size":441.00003},{"price":"41.054","symbol":"LINKUSDT","id":"410540","side":"Sell","size":1454.8}],"insert":[{"price":"41.019","symbol":"LINKUSDT","id":"410190","side":"Buy","size":427.1},{"price":"41.017","symbol":"LINKUSDT","id":"410170","side":"Buy","size":329.4},{"price":"41.016","symbol":"LINKUSDT","id":"410160","side":"Buy","size":144.5},{"price":"41.078","symbol":"LINKUSDT","id":"410780","side":"Sell","size":418.9},{"price":"41.018","symbol":"LINKUSDT","id":"410180","side":"Buy","size":391.49997}]},"cross_seq":"1970979524","timestamp_e6":"1618677789764807"}
1618677789.859207: {"topic":"orderBookL2_25.XTZUSDT","type":"delta","data":{"delete":[{"price":"7.209","symbol":"XTZUSDT","id":"72090","side":"Buy"}],"update":[{"price":"7.206","symbol":"XTZUSDT","id":"72060","side":"Buy","size":4438.2},{"price":"7.205","symbol":"XTZUSDT","id":"72050","side":"Buy","size":3986.1},{"price":"7.217","symbol":"XTZUSDT","id":"72170","side":"Sell","size":694.8},{"price":"7.208","symbol":"XTZUSDT","id":"72080","side":"Buy","size":1035.4},{"price":"7.213","symbol":"XTZUSDT","id":"72130","side":"Sell","size":873.3}],"insert":[{"price":"7.186","symbol":"XTZUSDT","id":"71860","side":"Buy","size":387.6}]},"cross_seq":"726228339","timestamp_e6":"1618677789775054"}
1618677789.8728168: {"topic":"orderBookL2_25.LINKUSDT","type":"delta","data":{"delete":[{"price":"41.062","symbol":"LINKUSDT","id":"410620","side":"Sell"},{"price":"41.064","symbol":"LINKUSDT","id":"410640","side":"Sell"}],"update":[{"price":"41.051","symbol":"LINKUSDT","id":"410510","side":"Sell","size":105.99999},{"price":"41.067","symbol":"LINKUSDT","id":"410670","side":"Sell","size":243.2},{"price":"41.058","symbol":"LINKUSDT","id":"410580","side":"Sell","size":109},{"price":"41.057","symbol":"LINKUSDT","id":"410570","side":"Sell","size":329.4},{"price":"41.054","symbol":"LINKUSDT","id":"410540","side":"Sell","size":980.60004},{"price":"41.069","symbol":"LINKUSDT","id":"410690","side":"Sell","size":187.7},{"price":"41.063","symbol":"LINKUSDT","id":"410630","side":"Sell","size":282.1}],"insert":[{"price":"41.056","symbol":"LINKUSDT","id":"410560","side":"Sell","size":18.8},{"price":"41.060","symbol":"LINKUSDT","id":"410600","side":"Sell","size":35.100002}]},"cross_seq":"1970979543","timestamp_e6":"1618677789785309"}
1618677789.8728929: {"topic":"orderBookL2_25.ETHUSDT","type":"delta","data":{"delete":[],"update":[{"price":"2365.00","symbol":"ETHUSDT","id":"23650000","side":"Sell","size":133.68001},{"price":"2366.00","symbol":"ETHUSDT","id":"23660000","side":"Sell","size":46.92}],"insert":[]},"cross_seq":"1800546423","timestamp_e6":"1618677789787209"}
1618677789.877433: {"topic":"orderBookL2_25.BCHUSDT","type":"delta","data":{"delete":[],"update":[{"price":"1053.70","symbol":"BCHUSDT","id":"10537000","side":"Buy","size":27.95},{"price":"1053.50","symbol":"BCHUSDT","id":"10535000","side":"Buy","size":27.32},{"price":"1055.45","symbol":"BCHUSDT","id":"10554500","side":"Sell","size":11.51},{"price":"1055.40","symbol":"BCHUSDT","id":"10554000","side":"Sell","size":13.12},{"price":"1055.50","symbol":"BCHUSDT","id":"10555000","side":"Sell","size":8.34},{"price":"1053.60","symbol":"BCHUSDT","id":"10536000","side":"Buy","size":17.03},{"price":"1055.55","symbol":"BCHUSDT","id":"10555500","side":"Sell","size":2.92}],"insert":[]},"cross_seq":"864132362","timestamp_e6":"1618677789789919"}
1618677789.889298: {"topic":"orderBookL2_25.XTZUSDT","type":"delta","data":{"delete":[],"update":[{"price":"7.203","symbol":"XTZUSDT","id":"72030","side":"Buy","size":1972.8}],"insert":[]},"cross_seq":"726228360","timestamp_e6":"1618677789794867"}
1618677789.89561: {"topic":"orderBookL2_25.LINKUSDT","type":"delta","data":{"delete":[],"update":[{"price":"41.051","symbol":"LINKUSDT","id":"410510","side":"Sell","size":197.3}],"insert":[]},"cross_seq":"1970979550","timestamp_e6":"1618677789804086"}
1618677789.895672: {"topic":"orderBookL2_25.ETHUSDT","type":"delta","data":{"delete":[],"update":[{"price":"2366.30","symbol":"ETHUSDT","id":"23663000","side":"Sell","size":21.07}],"insert":[]},"cross_seq":"1800546425","timestamp_e6":"1618677789807078"}
1618677789.908763: {"topic":"orderBookL2_25.UNIUSDT","type":"delta","data":{"delete":[{"price":"35.360","symbol":"UNIUSDT","id":"353600","side":"Buy"},{"price":"35.384","symbol":"UNIUSDT","id":"353840","side":"Buy"}],"update":[{"price":"35.378","symbol":"UNIUSDT","id":"353780","side":"Buy","size":21.500002},{"price":"35.404","symbol":"UNIUSDT","id":"354040","side":"Sell","size":43.800003}],"insert":[{"price":"35.380","symbol":"UNIUSDT","id":"353800","side":"Buy","size":35.6},{"price":"35.383","symbol":"UNIUSDT","id":"353830","side":"Buy","size":54.4}]},"cross_seq":"916953928","timestamp_e6":"1618677789822445"}
1618677789.9232361: {"topic":"orderBookL2_25.XTZUSDT","type":"delta","data":{"delete":[],"update":[{"price":"7.206","symbol":"XTZUSDT","id":"72060","side":"Buy","size":3167.2}],"insert":[]},"cross_seq":"726228361","timestamp_e6":"1618677789834535"}
1618677789.935462: {"topic":"orderBookL2_25.UNIUSDT","type":"delta","data":{"delete":[],"update":[{"price":"35.411","symbol":"UNIUSDT","id":"354110","side":"Sell","size":79.2}],"insert":[]},"cross_seq":"916953929","timestamp_e6":"1618677789842423"}
1618677789.9383302: {"topic":"orderBookL2_25.BCHUSDT","type":"delta","data":{"delete":[{"price":"1056.10","symbol":"BCHUSDT","id":"10561000","side":"Sell"},{"price":"1056.05","symbol":"BCHUSDT","id":"10560500","side":"Sell"}],"update":[{"price":"1055.00","symbol":"BCHUSDT","id":"10550000","side":"Sell","size":4.73}],"insert":[{"price":"1054.90","symbol":"BCHUSDT","id":"10549000","side":"Sell","size":8.36},{"price":"1055.05","symbol":"BCHUSDT","id":"10550500","side":"Sell","size":4.36}]},"cross_seq":"864132365","timestamp_e6":"1618677789848767"}
1618677789.9445062: {"topic":"orderBookL2_25.LTCUSDT","type":"delta","data":{"delete":[{"price":"313.42","symbol":"LTCUSDT","id":"3134200","side":"Sell"}],"update":[{"price":"313.21","symbol":"LTCUSDT","id":"3132100","side":"Sell","size":58.899998}],"insert":[{"price":"313.22","symbol":"LTCUSDT","id":"3132200","side":"Sell","size":20.5}]},"cross_seq":"1684522740","timestamp_e6":"1618677789858456"}
1618677789.95599: {"topic":"orderBookL2_25.DOTUSDT","type":"delta","data":{"delete":[{"price":"43.495","symbol":"DOTUSDT","id":"434950","side":"Buy"},{"price":"43.525","symbol":"DOTUSDT","id":"435250","side":"Buy"}],"update":[{"price":"43.550","symbol":"DOTUSDT","id":"435500","side":"Sell","size":610.5}],"insert":[{"price":"43.520","symbol":"DOTUSDT","id":"435200","side":"Buy","size":504.00003},{"price":"43.505","symbol":"DOTUSDT","id":"435050","side":"Buy","size":351.90002}]},"cross_seq":"916953935","timestamp_e6":"1618677789862350"}
1618677789.9734132: {"topic":"orderBookL2_25.LINKUSDT","type":"delta","data":{"delete":[],"update":[{"price":"41.026","symbol":"LINKUSDT","id":"410260","side":"Buy","size":734}],"insert":[]},"cross_seq":"1970979561","timestamp_e6":"1618677789863626"}
1618677789.9735382: {"topic":"orderBookL2_25.BCHUSDT","type":"delta","data":{"delete":[],"update":[{"price":"1054.70","symbol":"BCHUSDT","id":"10547000","side":"Buy","size":15.44}],"insert":[]},"cross_seq":"864132366","timestamp_e6":"1618677789870600"}
1618677789.991829: {"topic":"orderBookL2_25.ADAUSDT","type":"delta","data":{"delete":[],"update":[{"price":"1.3855","symbol":"ADAUSDT","id":"13855","side":"Buy","size":4433},{"price":"1.3880","symbol":"ADAUSDT","id":"13880","side":"Sell","size":1594.9999},{"price":"1.3857","symbol":"ADAUSDT","id":"13857","side":"Buy","size":6472},{"price":"1.3856","symbol":"ADAUSDT","id":"13856","side":"Buy","size":10103},{"price":"1.3883","symbol":"ADAUSDT","id":"13883","side":"Sell","size":2722},{"price":"1.3859","symbol":"ADAUSDT","id":"13859","side":"Buy","size":7524},{"price":"1.3882","symbol":"ADAUSDT","id":"13882","side":"Sell","size":2446},{"price":"1.3854","symbol":"ADAUSDT","id":"13854","side":"Buy","size":7710},{"price":"1.3858","symbol":"ADAUSDT","id":"13858","side":"Buy","size":6841.0005}],"insert":[]},"cross_seq":"916953945","timestamp_e6":"1618677789902346"}
1618677789.9919932: {"topic":"orderBookL2_25.LINKUSDT","type":"delta","data":{"delete":[],"update":[{"price":"41.051","symbol":"LINKUSDT","id":"410510","side":"Sell","size":502.6}],"insert":[]},"cross_seq":"1970979562","timestamp_e6":"1618677789904048"}
1618677789.995127: {"topic":"orderBookL2_25.BCHUSDT","type":"delta","data":{"delete":[],"update":[{"price":"1054.20","symbol":"BCHUSDT","id":"10542000","side":"Buy","size":3.03}],"insert":[]},"cross_seq":"864132370","timestamp_e6":"1618677789909007"}
1618677790.033644: {"topic":"orderBookL2_25.DOTUSDT","type":"delta","data":{"delete":[{"price":"43.405","symbol":"DOTUSDT","id":"434050","side":"Buy"}],"update":[{"price":"43.550","symbol":"DOTUSDT","id":"435500","side":"Sell","size":600.5},{"price":"43.490","symbol":"DOTUSDT","id":"434900","side":"Buy","size":368.3},{"price":"43.510","symbol":"DOTUSDT","id":"435100","side":"Buy","size":128},{"price":"43.540","symbol":"DOTUSDT","id":"435400","side":"Sell","size":1314.5}],"insert":[{"price":"43.495","symbol":"DOTUSDT","id":"434950","side":"Buy","size":351.90002}]},"cross_seq":"916953964","timestamp_e6":"1618677789942518"}
1618677790.033818: {"topic":"orderBookL2_25.ADAUSDT","type":"delta","data":{"delete":[],"update":[{"price":"1.3869","symbol":"ADAUSDT","id":"13869","side":"Buy","size":16869}],"insert":[]},"cross_seq":"916953964","timestamp_e6":"1618677789942315"}
1618677790.033878: {"topic":"orderBookL2_25.LINKUSDT","type":"delta","data":{"delete":[],"update":[{"price":"41.029","symbol":"LINKUSDT","id":"410290","side":"Buy","size":275.2},{"price":"41.051","symbol":"LINKUSDT","id":"410510","side":"Sell","size":976.8}],"insert":[]},"cross_seq":"1970979564","timestamp_e6":"1618677789944567"}
1618677790.03904: {"topic":"trade.BCHUSDT","data":[{"symbol":"BCHUSDT","tick_direction":"PlusTick","price":"1054.75","size":0.01,"timestamp":"2021-04-17T16:43:09.000Z","trade_time_ms":"1618677789920","side":"Buy","trade_id":"8b17fa77-b6be-5f4a-babf-afa426d9a51a"}]}
1618677790.0391018: {"topic":"orderBookL2_25.BCHUSDT","type":"delta","data":{"delete":[],"update":[{"price":"1054.75","symbol":"BCHUSDT","id":"10547500","side":"Sell","size":35.36}],"insert":[]},"cross_seq":"864132372","timestamp_e6":"1618677789950619"}
1618677790.050766: {"topic":"orderBookL2_25.XTZUSDT","type":"delta","data":{"delete":[],"update":[{"price":"7.204","symbol":"XTZUSDT","id":"72040","side":"Buy","size":2062.2}],"insert":[]},"cross_seq":"726228362","timestamp_e6":"1618677789954666"}
1618677790.074742: {"topic":"orderBookL2_25.UNIUSDT","type":"delta","data":{"delete":[{"price":"35.378","symbol":"UNIUSDT","id":"353780","side":"Buy"}],"update":[{"price":"35.404","symbol":"UNIUSDT","id":"354040","side":"Sell","size":67.299995},{"price":"35.375","symbol":"UNIUSDT","id":"353750","side":"Buy","size":35.6},{"price":"35.374","symbol":"UNIUSDT","id":"353740","side":"Buy","size":26.6},{"price":"35.377","symbol":"UNIUSDT","id":"353770","side":"Buy","size":44},{"price":"35.376","symbol":"UNIUSDT","id":"353760","side":"Buy","size":38.4}],"insert":[{"price":"35.360","symbol":"UNIUSDT","id":"353600","side":"Buy","size":20.5}]},"cross_seq":"916953973","timestamp_e6":"1618677789982345"}
1618677790.074848: {"topic":"orderBookL2_25.LINKUSDT","type":"delta","data":{"delete":[],"update":[{"price":"41.054","symbol":"LINKUSDT","id":"410540","side":"Sell","size":580.60004},{"price":"41.051","symbol":"LINKUSDT","id":"410510","side":"Sell","size":1376.7999}],"insert":[]},"cross_seq":"1970979566","timestamp_e6":"1618677789984028"}
1618677790.082439: {"topic":"orderBookL2_25.XTZUSDT","type":"delta","data":{"delete":[],"update":[{"price":"7.218","symbol":"XTZUSDT","id":"72180","side":"Sell","size":2228.2002},{"price":"7.201","symbol":"XTZUSDT","id":"72010","side":"Buy","size":1707.8},{"price":"7.217","symbol":"XTZUSDT","id":"72170","side":"Sell","size":799.6},{"price":"7.216","symbol":"XTZUSDT","id":"72160","side":"Sell","size":2603.9},{"price":"7.202","symbol":"XTZUSDT","id":"72020","side":"Buy","size":2373.7},{"price":"7.219","symbol":"XTZUSDT","id":"72190","side":"Sell","size":2033.4}],"insert":[]},"cross_seq":"726228368","timestamp_e6":"1618677789995207"}
1618677790.0880609: {"topic":"orderBookL2_25.DOTUSDT","type":"delta","data":{"delete":[],"update":[{"price":"43.560","symbol":"DOTUSDT","id":"435600","side":"Sell","size":732}],"insert":[]},"cross_seq":"916953996","timestamp_e6":"1618677790002468"}
1618677790.092144: {"topic":"orderBookL2_25.LINKUSDT","type":"delta","data":{"delete":[],"update":[{"price":"41.034","symbol":"LINKUSDT","id":"410340","side":"Buy","size":416.09998},{"price":"41.038","symbol":"LINKUSDT","id":"410380","side":"Buy","size":340},{"price":"41.033","symbol":"LINKUSDT","id":"410330","side":"Buy","size":996.10004},{"price":"41.032","symbol":"LINKUSDT","id":"410320","side":"Buy","size":381.4},{"price":"41.031","symbol":"LINKUSDT","id":"410310","side":"Buy","size":102.1},{"price":"41.077","symbol":"LINKUSDT","id":"410770","side":"Sell","size":339.9},{"price":"41.039","symbol":"LINKUSDT","id":"410390","side":"Buy","size":362.00003},{"price":"41.036","symbol":"LINKUSDT","id":"410360","side":"Buy","size":674},{"price":"41.078","symbol":"LINKUSDT","id":"410780","side":"Sell","size":297.7},{"price":"41.037","symbol":"LINKUSDT","id":"410370","side":"Buy","size":377.19998}],"insert":[]},"cross_seq":"1970979587","timestamp_e6":"1618677790003688"}
1618677790.092233: {"topic":"orderBookL2_25.ADAUSDT","type":"delta","data":{"delete":[],"update":[{"price":"1.3862","symbol":"ADAUSDT","id":"13862","side":"Buy","size":3873},{"price":"1.3863","symbol":"ADAUSDT","id":"13863","side":"Buy","size":6437.9995},{"price":"1.3861","symbol":"ADAUSDT","id":"13861","side":"Buy","size":3203},{"price":"1.3864","symbol":"ADAUSDT","id":"13864","side":"Buy","size":4861},{"price":"1.3860","symbol":"ADAUSDT","id":"13860","side":"Buy","size":2179}],"insert":[]},"cross_seq":"916953996","timestamp_e6":"1618677790002351"}
1618677790.112821: {"topic":"orderBookL2_25.UNIUSDT","type":"delta","data":{"delete":[{"price":"35.374","symbol":"UNIUSDT","id":"353740","side":"Buy"},{"price":"35.377","symbol":"UNIUSDT","id":"353770","side":"Buy"},{"price":"35.376","symbol":"UNIUSDT","id":"353760","side":"Buy"},{"price":"35.375","symbol":"UNIUSDT","id":"353750","side":"Buy"}],"update":[],"insert":[{"price":"35.359","symbol":"UNIUSDT","id":"353590","side":"Buy","size":23.3},{"price":"35.358","symbol":"UNIUSDT","id":"353580","side":"Buy","size":20.4},{"price":"35.357","symbol":"UNIUSDT","id":"353570","side":"Buy","size":37.5},{"price":"35.378","symbol":"UNIUSDT","id":"353780","side":"Buy","size":21.500002}]},"cross_seq":"916954019","timestamp_e6":"1618677790022491"}
1618677790.112905: {"topic":"orderBookL2_25.ADAUSDT","type":"delta","data":{"delete":[],"update":[{"price":"1.3864","symbol":"ADAUSDT","id":"13864","side":"Buy","size":8734},{"price":"1.3862","symbol":"ADAUSDT","id":"13862","side":"Buy","size":993},{"price":"1.3863","symbol":"ADAUSDT","id":"13863","side":"Buy","size":5858},{"price":"1.3861","symbol":"ADAUSDT","id":"13861","side":"Buy","size":938}],"insert":[]},"cross_seq":"916954019","timestamp_e6":"1618677790022338"}
1618677790.1150348: {"topic":"orderBookL2_25.BCHUSDT","type":"delta","data":{"delete":[],"update":[{"price":"1055.45","symbol":"BCHUSDT","id":"10554500","side":"Sell","size":16.84},{"price":"1055.55","symbol":"BCHUSDT","id":"10555500","side":"Sell","size":4.04}],"insert":[]},"cross_seq":"864132374","timestamp_e6":"1618677790028765"}
1618677790.124042: {"topic":"orderBookL2_25.XTZUSDT","type":"delta","data":{"delete":[{"price":"7.210","symbol":"XTZUSDT","id":"72100","side":"Buy"}],"update":[{"price":"7.211","symbol":"XTZUSDT","id":"72110","side":"Buy","size":0.2},{"price":"7.204","symbol":"XTZUSDT","id":"72040","side":"Buy","size":2693.4},{"price":"7.208","symbol":"XTZUSDT","id":"72080","side":"Buy","size":1339.5}],"insert":[{"price":"7.209","symbol":"XTZUSDT","id":"72090","side":"Buy","size":1665.7999}]},"cross_seq":"726228377","timestamp_e6":"1618677790036477"}
1618677790.132837: {"topic":"orderBookL2_25.LINKUSDT","type":"delta","data":{"delete":[{"price":"41.052","symbol":"LINKUSDT","id":"410520","side":"Sell"},{"price":"41.078","symbol":"LINKUSDT","id":"410780","side":"Sell"},{"price":"41.075","symbol":"LINKUSDT","id":"410750","side":"Sell"}],"update":[{"price":"41.051","symbol":"LINKUSDT","id":"410510","side":"Sell","size":1285.5},{"price":"41.076","symbol":"LINKUSDT","id":"410760","side":"Sell","size":223.70001}],"insert":[{"price":"41.064","symbol":"LINKUSDT","id":"410640","side":"Sell","size":43.9},{"price":"41.055","symbol":"LINKUSDT","id":"410550","side":"Sell","size":36},{"price":"41.062","symbol":"LINKUSDT","id":"410620","side":"Sell","size":45.100002}]},"cross_seq":"1970979610","timestamp_e6":"1618677790044723"}
1618677790.1673841: {"topic":"orderBookL2_25.ADAUSDT","type":"delta","data":{"delete":[],"update":[{"price":"1.3861","symbol":"ADAUSDT","id":"13861","side":"Buy","size":2879.9998},{"price":"1.3875","symbol":"ADAUSDT","id":"13875","side":"Buy","size":61685},{"price":"1.3862","symbol":"ADAUSDT","id":"13862","side":"Buy","size":3203},{"price":"1.3865","symbol":"ADAUSDT","id":"13865","side":"Buy","size":1}],"insert":[]},"cross_seq":"916954032","timestamp_e6":"1618677790082404"}
1618677790.1674318: {"topic":"orderBookL2_25.LINKUSDT","type":"delta","data":{"delete":[{"price":"41.077","symbol":"LINKUSDT","id":"410770","side":"Sell"},{"price":"41.039","symbol":"LINKUSDT","id":"410390","side":"Buy"},{"price":"41.038","symbol":"LINKUSDT","id":"410380","side":"Buy"},{"price":"41.037","symbol":"LINKUSDT","id":"410370","side":"Buy"}],"update":[{"price":"41.074","symbol":"LINKUSDT","id":"410740","side":"Sell","size":81.9},{"price":"41.035","symbol":"LINKUSDT","id":"410350","side":"Buy","size":559},{"price":"41.033","symbol":"LINKUSDT","id":"410330","side":"Buy","size":1051.4},{"price":"41.073","symbol":"LINKUSDT","id":"410730","side":"Sell","size":112.7},{"price":"41.051","symbol":"LINKUSDT","id":"410510","side":"Sell","size":1309.5},{"price":"41.036","symbol":"LINKUSDT","id":"410360","side":"Buy","size":247}],"insert":[{"price":"41.015","symbol":"LINKUSDT","id":"410150","side":"Buy","size":444.3},{"price":"41.014","symbol":"LINKUSDT","id":"410140","side":"Buy","size":129},{"price":"41.013","symbol":"LINKUSDT","id":"410130","side":"Buy","size":133.3},{"price":"41.052","symbol":"LINKUSDT","id":"410520","side":"Sell","size":46}]},"cross_seq":"1970979640","timestamp_e6":"1618677790084055"}
1618677790.191843: {"topic":"orderBookL2_25.LINKUSDT","type":"delta","data":{"delete":[],"update":[{"price":"41.032","symbol":"LINKUSDT","id":"410320","side":"Buy","size":479.2},{"price":"41.031","symbol":"LINKUSDT","id":"410310","side":"Buy","size":152.7},{"price":"41.034","symbol":"LINKUSDT","id":"410340","side":"Buy","size":364.4}],"insert":[]},"cross_seq":"1970979663","timestamp_e6":"1618677790103669"}
1618677790.216129: {"topic":"orderBookL2_25.LINKUSDT","type":"delta","data":{"delete":[{"price":"41.050","symbol":"LINKUSDT","id":"410500","side":"Buy"}],"update":[{"price":"41.057","symbol":"LINKUSDT","id":"410570","side":"Sell","size":327.9}],"insert":[{"price":"41.012","symbol":"LINKUSDT","id":"410120","side":"Buy","size":513.2}]},"cross_seq":"1970979665","timestamp_e6":"1618677790125671"}
1618677790.248079: {"topic":"orderBookL2_25.ADAUSDT","type":"delta","data":{"delete":[{"price":"1.3872","symbol":"ADAUSDT","id":"13872","side":"Buy"}],"update":[{"price":"1.3880","symbol":"ADAUSDT","id":"13880","side":"Sell","size":2702}],"insert":[{"price":"1.3847","symbol":"ADAUSDT","id":"13847","side":"Buy","size":4462}]},"cross_seq":"916954034","timestamp_e6":"1618677790162331"}
1618677790.248179: {"topic":"orderBookL2_25.LINKUSDT","type":"delta","data":{"delete":[{"price":"41.076","symbol":"LINKUSDT","id":"410760","side":"Sell"}],"update":[{"price":"41.036","symbol":"LINKUSDT","id":"410360","side":"Buy","size":253.00002},{"price":"41.051","symbol":"LINKUSDT","id":"410510","side":"Sell","size":1203.5}],"insert":[{"price":"41.037","symbol":"LINKUSDT","id":"410370","side":"Sell","size":66}]},"cross_seq":"1970979670","timestamp_e6":"1618677790165161"}
1618677790.252052: {"topic":"orderBookL2_25.ETHUSDT","type":"delta","data":{"delete":[],"update":[{"price":"2364.95","symbol":"ETHUSDT","id":"23649500","side":"Sell","size":372.02002}],"insert":[]},"cross_seq":"1800546426","timestamp_e6":"1618677790167631"}
1618677790.272577: {"topic":"orderBookL2_25.DOTUSDT","type":"delta","data":{"delete":[{"price":"43.520","symbol":"DOTUSDT","id":"435200","side":"Buy"},{"price":"43.515","symbol":"DOTUSDT","id":"435150","side":"Buy"}],"update":[{"price":"43.480","symbol":"DOTUSDT","id":"434800","side":"Buy","size":729.1},{"price":"43.510","symbol":"DOTUSDT","id":"435100","side":"Buy","size":528.7},{"price":"43.555","symbol":"DOTUSDT","id":"435550","side":"Sell","size":576},{"price":"43.485","symbol":"DOTUSDT","id":"434850","side":"Buy","size":303.9},{"price":"43.490","symbol":"DOTUSDT","id":"434900","side":"Buy","size":241},{"price":"43.505","symbol":"DOTUSDT","id":"435050","side":"Buy","size":487.6},{"price":"43.565","symbol":"DOTUSDT","id":"435650","side":"Sell","size":210},{"price":"43.470","symbol":"DOTUSDT","id":"434700","side":"Buy","size":678.9},{"price":"43.500","symbol":"DOTUSDT","id":"435000","side":"Buy","size":494.4}],"insert":[{"price":"43.400","symbol":"DOTUSDT","id":"434000","side":"Buy","size":1.2},{"price":"43.405","symbol":"DOTUSDT","id":"434050","side":"Buy","size":444.5}]},"cross_seq":"916954052","timestamp_e6":"1618677790182471"}
1618677790.277836: {"topic":"orderBookL2_25.LINKUSDT","type":"delta","data":{"delete":[{"price":"41.071","symbol":"LINKUSDT","id":"410710","side":"Sell"},{"price":"41.070","symbol":"LINKUSDT","id":"410700","side":"Sell"},{"price":"41.072","symbol":"LINKUSDT","id":"410720","side":"Sell"},{"price":"41.065","symbol":"LINKUSDT","id":"410650","side":"Sell"},{"price":"41.063","symbol":"LINKUSDT","id":"410630","side":"Sell"},{"price":"41.064","symbol":"LINKUSDT","id":"410640","side":"Sell"},{"price":"41.066","symbol":"LINKUSDT","id":"410660","side":"Sell"},{"price":"41.073","symbol":"LINKUSDT","id":"410730","side":"Sell"},{"price":"41.074","symbol":"LINKUSDT","id":"410740","side":"Sell"},{"price":"41.068","symbol":"LINKUSDT","id":"410680","side":"Sell"},{"price":"41.062","symbol":"LINKUSDT","id":"410620","side":"Sell"},{"price":"41.067","symbol":"LINKUSDT","id":"410670","side":"Sell"},{"price":"41.069","symbol":"LINKUSDT","id":"410690","side":"Sell"}],"update":[{"price":"41.032","symbol":"LINKUSDT","id":"410320","side":"Buy","size":168},{"price":"41.033","symbol":"LINKUSDT","id":"410330","side":"Buy","size":850.00006},{"price":"41.035","symbol":"LINKUSDT","id":"410350","side":"Buy","size":302.3},{"price":"41.036","symbol":"LINKUSDT","id":"410360","side":"Buy","size":474.19998},{"price":"41.034","symbol":"LINKUSDT","id":"410340","side":"Buy","size":116.3}],"insert":[{"price":"41.039","symbol":"LINKUSDT","id":"410390","side":"Sell","size":185.1},{"price":"41.038","symbol":"LINKUSDT","id":"410380","side":"Sell","size":243.90001},{"price":"41.044","symbol":"LINKUSDT","id":"410440","side":"Sell","size":582.4},{"price":"41.050","symbol":"LINKUSDT","id":"410500","side":"Sell","size":74.6},{"price":"41.047","symbol":"LINKUSDT","id":"410470","side":"Sell","size":396.7},{"price":"41.040","symbol":"LINKUSDT","id":"410400","side":"Sell","size":202.2},{"price":"41.046","symbol":"LINKUSDT","id":"410460","side":"Sell","size":103.600006},{"price":"41.041","symbol":"LINKUSDT","id":"410410","side":"Sell","size":115},{"price":"41.042","symbol":"LINKUSDT","id":"410420","side":"Sell","size":129.20001},{"price":"41.045","symbol":"LINKUSDT","id":"410450","side":"Sell","size":50.899998},{"price":"41.048","symbol":"LINKUSDT","id":"410480","side":"Sell","size":83},{"price":"41.049","symbol":"LINKUSDT","id":"410490","side":"Sell","size":144.3},{"price":"41.043","symbol":"LINKUSDT","id":"410430","side":"Sell","size":96.600006}]},"cross_seq":"1970979699","timestamp_e6":"1618677790184948"}
1618677790.286643: {"topic":"orderBookL2_25.ETHUSDT","type":"delta","data":{"delete":[],"update":[{"price":"2365.15","symbol":"ETHUSDT","id":"23651500","side":"Sell","size":130.88},{"price":"2365.00","symbol":"ETHUSDT","id":"23650000","side":"Sell","size":168.69},{"price":"2365.20","symbol":"ETHUSDT","id":"23652000","side":"Sell","size":73.25},{"price":"2365.10","symbol":"ETHUSDT","id":"23651000","side":"Sell","size":155.93},{"price":"2365.05","symbol":"ETHUSDT","id":"23650500","side":"Sell","size":162.11}],"insert":[]},"cross_seq":"1800546434","timestamp_e6":"1618677790187073"}
1618677790.290965: {"topic":"orderBookL2_25.LINKUSDT","type":"delta","data":{"delete":[],"update":[{"price":"41.051","symbol":"LINKUSDT","id":"410510","side":"Sell","size":24},{"price":"41.036","symbol":"LINKUSDT","id":"410360","side":"Buy","size":914.2},{"price":"41.026","symbol":"LINKUSDT","id":"410260","side":"Buy","size":704}],"insert":[]},"cross_seq":"1970979705","timestamp_e6":"1618677790205273"}
1618677790.311595: {"topic":"trade.ETHUSDT","data":[{"symbol":"ETHUSDT","tick_direction":"ZeroMinusTick","price":"2364.95","size":0.01,"timestamp":"2021-04-17T16:43:10.000Z","trade_time_ms":"1618677790150","side":"Buy","trade_id":"8b841db8-c3e0-5943-867b-35ee9a638710"}]}
1618677790.324623: {"topic":"orderBookL2_25.LTCUSDT","type":"delta","data":{"delete":[],"update":[{"price":"313.10","symbol":"LTCUSDT","id":"3131000","side":"Sell","size":1.5}],"insert":[]},"cross_seq":"1684522741","timestamp_e6":"1618677790240746"}
1618677790.330195: {"topic":"orderBookL2_25.ADAUSDT","type":"delta","data":{"delete":[],"update":[{"price":"1.3864","symbol":"ADAUSDT","id":"13864","side":"Buy","size":4861},{"price":"1.3862","symbol":"ADAUSDT","id":"13862","side":"Buy","size":2210},{"price":"1.3867","symbol":"ADAUSDT","id":"13867","side":"Buy","size":6918},{"price":"1.3865","symbol":"ADAUSDT","id":"13865","side":"Buy","size":3874},{"price":"1.3863","symbol":"ADAUSDT","id":"13863","side":"Buy","size":5001}],"insert":[]},"cross_seq":"916954058","timestamp_e6":"1618677790242379"}
1618677790.330322: {"topic":"orderBookL2_25.LINKUSDT","type":"delta","data":{"delete":[{"price":"41.044","symbol":"LINKUSDT","id":"410440","side":"Sell"},{"price":"41.037","symbol":"LINKUSDT","id":"410370","side":"Sell"},{"price":"41.040","symbol":"LINKUSDT","id":"410400","side":"Sell"}],"update":[{"price":"41.032","symbol":"LINKUSDT","id":"410320","side":"Buy","size":244.50002},{"price":"41.035","symbol":"LINKUSDT","id":"410350","side":"Buy","size":371.7},{"price":"41.041","symbol":"LINKUSDT","id":"410410","side":"Sell","size":185.1},{"price":"41.031","symbol":"LINKUSDT","id":"410310","side":"Buy","size":206.2},{"price":"41.033","symbol":"LINKUSDT","id":"410330","side":"Buy","size":917.60004},{"price":"41.042","symbol":"LINKUSDT","id":"410420","side":"Sell","size":202.2}],"insert":[{"price":"41.064","symbol":"LINKUSDT","id":"410640","side":"Sell","size":43.9},{"price":"41.063","symbol":"LINKUSDT","id":"410630","side":"Sell","size":282.1},{"price":"41.062","symbol":"LINKUSDT","id":"410620","side":"Sell","size":45.100002}]},"cross_seq":"1970979716","timestamp_e6":"1618677790244004"}
1618677790.339733: {"topic":"orderBookL2_25.XTZUSDT","type":"delta","data":{"delete":[{"price":"7.209","symbol":"XTZUSDT","id":"72090","side":"Buy"}],"update":[{"price":"7.206","symbol":"XTZUSDT","id":"72060","side":"Buy","size":2832.7},{"price":"7.205","symbol":"XTZUSDT","id":"72050","side":"Buy","size":3501.7}],"insert":[{"price":"7.210","symbol":"XTZUSDT","id":"72100","side":"Buy","size":1665.7999}]},"cross_seq":"726228382","timestamp_e6":"1618677790254590"}
1618677790.351733: {"topic":"orderBookL2_25.ADAUSDT","type":"delta","data":{"delete":[],"update":[{"price":"1.3863","symbol":"ADAUSDT","id":"13863","side":"Buy","size":6172.9995},{"price":"1.3862","symbol":"ADAUSDT","id":"13862","side":"Buy","size":3203},{"price":"1.3864","symbol":"ADAUSDT","id":"13864","side":"Buy","size":8999},{"price":"1.3865","symbol":"ADAUSDT","id":"13865","side":"Buy","size":1045}],"insert":[]},"cross_seq":"916954064","timestamp_e6":"1618677790262341"}
1618677790.3559859: {"topic":"orderBookL2_25.LINKUSDT","type":"delta","data":{"delete":[{"price":"41.038","symbol":"LINKUSDT","id":"410380","side":"Sell"},{"price":"41.041","symbol":"LINKUSDT","id":"410410","side":"Sell"},{"price":"41.039","symbol":"LINKUSDT","id":"410390","side":"Sell"},{"price":"41.013","symbol":"LINKUSDT","id":"410130","side":"Buy"},{"price":"41.012","symbol":"LINKUSDT","id":"410120","side":"Buy"},{"price":"41.034","symbol":"LINKUSDT","id":"410340","side":"Buy"},{"price":"41.042","symbol":"LINKUSDT","id":"410420","side":"Sell"},{"price":"41.045","symbol":"LINKUSDT","id":"410450","side":"Sell"},{"price":"41.043","symbol":"LINKUSDT","id":"410430","side":"Sell"}],"update":[{"price":"41.050","symbol":"LINKUSDT","id":"410500","side":"Sell","size":129.20001},{"price":"41.036","symbol":"LINKUSDT","id":"410360","side":"Buy","size":687},{"price":"41.048","symbol":"LINKUSDT","id":"410480","side":"Sell","size":202.2},{"price":"41.047","symbol":"LINKUSDT","id":"410470","side":"Sell","size":243.90001},{"price":"41.035","symbol":"LINKUSDT","id":"410350","side":"Buy","size":251.2},{"price":"41.046","symbol":"LINKUSDT","id":"410460","side":"Sell","size":140.3},{"price":"41.049","symbol":"LINKUSDT","id":"410490","side":"Sell","size":202.2},{"price":"41.051","symbol":"LINKUSDT","id":"410510","side":"Sell","size":129.20001}],"insert":[{"price":"41.066","symbol":"LINKUSDT","id":"410660","side":"Sell","size":629.60004},{"price":"41.038","symbol":"LINKUSDT","id":"410380","side":"Buy","size":189.9},{"price":"41.070","symbol":"LINKUSDT","id":"410700","side":"Sell","size":195.8},{"price":"41.039","symbol":"LINKUSDT","id":"410390","side":"Buy","size":221.2},{"price":"41.068","symbol":"LINKUSDT","id":"410680","side":"Sell","size":510.8},{"price":"41.069","symbol":"LINKUSDT","id":"410690","side":"Sell","size":187.7},{"price":"41.067","symbol":"LINKUSDT","id":"410670","side":"Sell","size":243.2},{"price":"41.037","symbol":"LINKUSDT","id":"410370","side":"Buy","size":135.3},{"price":"41.065","symbol":"LINKUSDT","id":"410650","side":"Sell","size":438.1}]},"cross_seq":"1970979756","timestamp_e6":"1618677790265251"}
1618677790.356224: {"topic":"orderBookL2_25.ETHUSDT","type":"delta","data":{"delete":[{"price":"2364.40","symbol":"ETHUSDT","id":"23644000","side":"Buy"}],"update":[{"price":"2364.35","symbol":"ETHUSDT","id":"23643500","side":"Buy","size":48.690002},{"price":"2364.20","symbol":"ETHUSDT","id":"23642000","side":"Buy","size":28.550001}],"insert":[{"price":"2363.35","symbol":"ETHUSDT","id":"23633500","side":"Buy","size":23.73}]},"cross_seq":"1800546439","timestamp_e6":"1618677790267098"}
1618677790.3592918: {"topic":"orderBookL2_25.XTZUSDT","type":"delta","data":{"delete":[],"update":[{"price":"7.207","symbol":"XTZUSDT","id":"72070","side":"Buy","size":3081.1},{"price":"7.201","symbol":"XTZUSDT","id":"72010","side":"Buy","size":2196},{"price":"7.203","symbol":"XTZUSDT","id":"72030","side":"Buy","size":1614.1001}],"insert":[]},"cross_seq":"726228386","timestamp_e6":"1618677790274547"}
1618677790.368545: {"topic":"orderBookL2_25.ADAUSDT","type":"delta","data":{"delete":[],"update":[{"price":"1.3875","symbol":"ADAUSDT","id":"13875","side":"Buy","size":75850}],"insert":[]},"cross_seq":"916954065","timestamp_e6":"1618677790282325"}
1618677790.368607: {"topic":"orderBookL2_25.LINKUSDT","type":"delta","data":{"delete":[],"update":[{"price":"41.015","symbol":"LINKUSDT","id":"410150","side":"Buy","size":474.1},{"price":"41.037","symbol":"LINKUSDT","id":"410370","side":"Buy","size":141.3}],"insert":[]},"cross_seq":"1970979758","timestamp_e6":"1618677790284227"}
1618677790.38928: {"topic":"orderBookL2_25.LTCUSDT","type":"delta","data":{"delete":[{"price":"313.24","symbol":"LTCUSDT","id":"3132400","side":"Sell"}],"update":[{"price":"313.06","symbol":"LTCUSDT","id":"3130600","side":"Buy","size":139},{"price":"313.21","symbol":"LTCUSDT","id":"3132100","side":"Sell","size":74.8},{"price":"313.20","symbol":"LTCUSDT","id":"3132000","side":"Sell","size":50.5},{"price":"313.22","symbol":"LTCUSDT","id":"3132200","side":"Sell","size":48.8}],"insert":[{"price":"313.23","symbol":"LTCUSDT","id":"3132300","side":"Sell","size":49.6}]},"cross_seq":"1684522748","timestamp_e6":"1618677790302054"}
1618677790.3909261: {"topic":"orderBookL2_25.LINKUSDT","type":"delta","data":{"delete":[{"price":"41.054","symbol":"LINKUSDT","id":"410540","side":"Sell"},{"price":"41.014","symbol":"LINKUSDT","id":"410140","side":"Buy"},{"price":"41.015","symbol":"LINKUSDT","id":"410150","side":"Buy"}],"update":[{"price":"41.055","symbol":"LINKUSDT","id":"410550","side":"Sell","size":129.20001},{"price":"41.037","symbol":"LINKUSDT","id":"410370","side":"Buy","size":135.3},{"price":"41.053","symbol":"LINKUSDT","id":"410530","side":"Sell","size":202.2},{"price":"41.051","symbol":"LINKUSDT","id":"410510","side":"Sell","size":114.700005},{"price":"41.052","symbol":"LINKUSDT","id":"410520","side":"Sell","size":185.1},{"price":"41.039","symbol":"LINKUSDT","id":"410390","side":"Buy","size":261.19998},{"price":"41.036","symbol":"LINKUSDT","id":"410360","side":"Buy","size":809.9},{"price":"41.046","symbol":"LINKUSDT","id":"410460","side":"Sell","size":66}],"insert":[{"price":"41.045","symbol":"LINKUSDT","id":"410450","side":"Buy","size":6},{"price":"41.034","symbol":"LINKUSDT","id":"410340","side":"Buy","size":57.5},{"price":"41.071","symbol":"LINKUSDT","id":"410710","side":"Sell","size":314.9}]},"cross_seq":"1970979778","timestamp_e6":"1618677790305331"}
1618677790.396256: {"topic":"orderBookL2_25.BCHUSDT","type":"delta","data":{"delete":[{"price":"1054.60","symbol":"BCHUSDT","id":"10546000","side":"Buy"},{"price":"1054.70","symbol":"BCHUSDT","id":"10547000","side":"Buy"},{"price":"1054.45","symbol":"BCHUSDT","id":"10544500","side":"Buy"},{"price":"1054.65","symbol":"BCHUSDT","id":"10546500","side":"Buy"},{"price":"1054.95","symbol":"BCHUSDT","id":"10549500","side":"Sell"}],"update":[{"price":"1055.10","symbol":"BCHUSDT","id":"10551000","side":"Sell","size":1.41},{"price":"1054.55","symbol":"BCHUSDT","id":"10545500","side":"Buy","size":5.19},{"price":"1054.50","symbol":"BCHUSDT","id":"10545000","side":"Buy","size":3.02},{"price":"1055.00","symbol":"BCHUSDT","id":"10550000","side":"Sell","size":8.31},{"price":"1055.15","symbol":"BCHUSDT","id":"10551500","side":"Sell","size":1.77}],"insert":[{"price":"1053.25","symbol":"BCHUSDT","id":"10532500","side":"Buy","size":3.88},{"price":"1056.05","symbol":"BCHUSDT","id":"10560500","side":"Sell","size":4.1},{"price":"1053.20","symbol":"BCHUSDT","id":"10532000","side":"Buy","size":8.37},{"price":"1053.10","symbol":"BCHUSDT","id":"10531000","side":"Buy","size":5.48},{"price":"1053.15","symbol":"BCHUSDT","id":"10531500","side":"Buy","size":17.9}]},"cross_seq":"864132385","timestamp_e6":"1618677790310299"}
1618677790.401679: {"topic":"orderBookL2_25.XTZUSDT","type":"delta","data":{"delete":[],"update":[{"price":"7.186","symbol":"XTZUSDT","id":"71860","side":"Buy","size":663.4}],"insert":[]},"cross_seq":"726228387","timestamp_e6":"1618677790314558"}
1618677790.409937: {"topic":"orderBookL2_25.DOTUSDT","type":"delta","data":{"delete":[{"price":"43.400","symbol":"DOTUSDT","id":"434000","side":"Buy"}],"update":[],"insert":[{"price":"43.515","symbol":"DOTUSDT","id":"435150","side":"Buy","size":1.3}]},"cross_seq":"916954068","timestamp_e6":"1618677790322349"}
1618677790.4151502: {"topic":"orderBookL2_25.LINKUSDT","type":"delta","data":{"delete":[],"update":[{"price":"41.036","symbol":"LINKUSDT","id":"410360","side":"Buy","size":769.89996}],"insert":[]},"cross_seq":"1970979779","timestamp_e6":"1618677790324472"}
1618677790.41522: {"topic":"orderBookL2_25.ETHUSDT","type":"delta","data":{"delete":[],"update":[{"price":"2366.30","symbol":"ETHUSDT","id":"23663000","side":"Sell","size":23.93}],"insert":[]},"cross_seq":"1800546440","timestamp_e6":"1618677790327849"}
1618677790.433392: {"topic":"orderBookL2_25.LINKUSDT","type":"delta","data":{"delete":[],"update":[{"price":"41.036","symbol":"LINKUSDT","id":"410360","side":"Buy","size":369.90002},{"price":"41.026","symbol":"LINKUSDT","id":"410260","side":"Buy","size":846.5}],"insert":[]},"cross_seq":"1970979786","timestamp_e6":"1618677790343690"}
1618677790.438684: {"topic":"orderBookL2_25.BCHUSDT","type":"delta","data":{"delete":[{"price":"1053.25","symbol":"BCHUSDT","id":"10532500","side":"Buy"},{"price":"1053.20","symbol":"BCHUSDT","id":"10532000","side":"Buy"},{"price":"1053.10","symbol":"BCHUSDT","id":"10531000","side":"Buy"},{"price":"1053.15","symbol":"BCHUSDT","id":"10531500","side":"Buy"},{"price":"1054.85","symbol":"BCHUSDT","id":"10548500","side":"Sell"},{"price":"1054.75","symbol":"BCHUSDT","id":"10547500","side":"Sell"},{"price":"1054.90","symbol":"BCHUSDT","id":"10549000","side":"Sell"}],"update":[{"price":"1055.55","symbol":"BCHUSDT","id":"10555500","side":"Sell","size":6.03},{"price":"1055.45","symbol":"BCHUSDT","id":"10554500","side":"Sell","size":13.72},{"price":"1054.50","symbol":"BCHUSDT","id":"10545000","side":"Buy","size":6.13},{"price":"1055.35","symbol":"BCHUSDT","id":"10553500","side":"Sell","size":14.64},{"price":"1055.30","symbol":"BCHUSDT","id":"10553000","side":"Sell","size":21.32},{"price":"1055.50","symbol":"BCHUSDT","id":"10555000","side":"Sell","size":5.23}],"insert":[{"price":"1054.60","symbol":"BCHUSDT","id":"10546000","side":"Buy","size":6.41},{"price":"1056.10","symbol":"BCHUSDT","id":"10561000","side":"Sell","size":11.670001},{"price":"1056.20","symbol":"BCHUSDT","id":"10562000","side":"Sell","size":1},{"price":"1056.15","symbol":"BCHUSDT","id":"10561500","side":"Sell","size":5.33},{"price":"1054.65","symbol":"BCHUSDT","id":"10546500","side":"Buy","size":8.88},{"price":"1054.70","symbol":"BCHUSDT","id":"10547000","side":"Buy","size":37.32},{"price":"1054.45","symbol":"BCHUSDT","id":"10544500","side":"Buy","size":3.08}]},"cross_seq":"864132420","timestamp_e6":"1618677790351492"}
1618677790.451351: {"topic":"orderBookL2_25.ADAUSDT","type":"delta","data":{"delete":[{"price":"1.3866","symbol":"ADAUSDT","id":"13866","side":"Buy"}],"update":[{"price":"1.3879","symbol":"ADAUSDT","id":"13879","side":"Sell","size":2640},{"price":"1.3878","symbol":"ADAUSDT","id":"13878","side":"Sell","size":5313},{"price":"1.3859","symbol":"ADAUSDT","id":"13859","side":"Buy","size":8572},{"price":"1.3863","symbol":"ADAUSDT","id":"13863","side":"Buy","size":2300},{"price":"1.3877","symbol":"ADAUSDT","id":"13877","side":"Sell","size":3381},{"price":"1.3862","symbol":"ADAUSDT","id":"13862","side":"Buy","size":5321},{"price":"1.3860","symbol":"ADAUSDT","id":"13860","side":"Buy","size":4085},{"price":"1.3881","symbol":"ADAUSDT","id":"13881","side":"Sell","size":1685},{"price":"1.3867","symbol":"ADAUSDT","id":"13867","side":"Buy","size":2001},{"price":"1.3880","symbol":"ADAUSDT","id":"13880","side":"Sell","size":3754},{"price":"1.3861","symbol":"ADAUSDT","id":"13861","side":"Buy","size":4619}],"insert":[{"price":"1.3846","symbol":"ADAUSDT","id":"13846","side":"Buy","size":1015}]},"cross_seq":"916954085","timestamp_e6":"1618677790362351"}
1618677790.451562: {"topic":"orderBookL2_25.LINKUSDT","type":"delta","data":{"delete":[],"update":[{"price":"41.034","symbol":"LINKUSDT","id":"410340","side":"Buy","size":304.5},{"price":"41.035","symbol":"LINKUSDT","id":"410350","side":"Buy","size":69.4},{"price":"41.036","symbol":"LINKUSDT","id":"410360","side":"Buy","size":122.9},{"price":"41.029","symbol":"LINKUSDT","id":"410290","side":"Buy","size":44}],"insert":[]},"cross_seq":"1970979802","timestamp_e6":"1618677790364049"}
1618677790.4587991: {"topic":"orderBookL2_25.BCHUSDT","type":"delta","data":{"delete":[{"price":"1053.30","symbol":"BCHUSDT","id":"10533000","side":"Buy"},{"price":"1055.10","symbol":"BCHUSDT","id":"10551000","side":"Sell"},{"price":"1055.05","symbol":"BCHUSDT","id":"10550500","side":"Sell"},{"price":"1055.20","symbol":"BCHUSDT","id":"10552000","side":"Sell"},{"price":"1055.35","symbol":"BCHUSDT","id":"10553500","side":"Sell"},{"price":"1055.25","symbol":"BCHUSDT","id":"10552500","side":"Sell"},{"price":"1055.15","symbol":"BCHUSDT","id":"10551500","side":"Sell"}],"update":[{"price":"1055.00","symbol":"BCHUSDT","id":"10550000","side":"Sell","size":0.01},{"price":"1053.95","symbol":"BCHUSDT","id":"10539500","side":"Buy","size":17.52},{"price":"1055.50","symbol":"BCHUSDT","id":"10555000","side":"Sell","size":8.48},{"price":"1053.90","symbol":"BCHUSDT","id":"10539000","side":"Buy","size":18.08},{"price":"1053.70","symbol":"BCHUSDT","id":"10537000","side":"Buy","size":22.73},{"price":"1055.45","symbol":"BCHUSDT","id":"10554500","side":"Sell","size":18.28},{"price":"1055.40","symbol":"BCHUSDT","id":"10554000","side":"Sell","size":16.74},{"price":"1053.80","symbol":"BCHUSDT","id":"10538000","side":"Buy","size":26.32},{"price":"1053.75","symbol":"BCHUSDT","id":"10537500","side":"Buy","size":14.16}],"insert":[{"price":"1053.85","symbol":"BCHUSDT","id":"10538500","side":"Buy","size":13.6},{"price":"1056.30","symbol":"BCHUSDT","id":"10563000","side":"Sell","size":20.72},{"price":"1056.40","symbol":"BCHUSDT","id":"10564000","side":"Sell","size":1},{"price":"1056.25","symbol":"BCHUSDT","id":"10562500","side":"Sell","size":4.27},{"price":"1056.35","symbol":"BCHUSDT","id":"10563500","side":"Sell","size":15.590001},{"price":"1056.45","symbol":"BCHUSDT","id":"10564500","side":"Sell","size":16.609999},{"price":"1056.50","symbol":"BCHUSDT","id":"10565000","side":"Sell","size":30.32}]},"cross_seq":"864132449","timestamp_e6":"1618677790370553"}
1618677790.469387: {"topic":"orderBookL2_25.ADAUSDT","type":"delta","data":{"delete":[{"price":"1.3860","symbol":"ADAUSDT","id":"13860","side":"Buy"},{"price":"1.3862","symbol":"ADAUSDT","id":"13862","side":"Buy"},{"price":"1.3861","symbol":"ADAUSDT","id":"13861","side":"Buy"}],"update":[{"price":"1.3881","symbol":"ADAUSDT","id":"13881","side":"Sell","size":2351},{"price":"1.3867","symbol":"ADAUSDT","id":"13867","side":"Buy","size":7322},{"price":"1.3859","symbol":"ADAUSDT","id":"13859","side":"Buy","size":5369},{"price":"1.3858","symbol":"ADAUSDT","id":"13858","side":"Buy","size":5892.0005},{"price":"1.3857","symbol":"ADAUSDT","id":"13857","side":"Buy","size":8967},{"price":"1.3878","symbol":"ADAUSDT","id":"13878","side":"Sell","size":7221.0005},{"price":"1.3863","symbol":"ADAUSDT","id":"13863","side":"Buy","size":4905},{"price":"1.3865","symbol":"ADAUSDT","id":"13865","side":"Buy","size":4085.9998},{"price":"1.3879","symbol":"ADAUSDT","id":"13879","side":"Sell","size":3364},{"price":"1.3868","symbol":"ADAUSDT","id":"13868","side":"Buy","size":12921}],"insert":[{"price":"1.3866","symbol":"ADAUSDT","id":"13866","side":"Buy","size":4619},{"price":"1.3845","symbol":"ADAUSDT","id":"13845","side":"Buy","size":4684},{"price":"1.3844","symbol":"ADAUSDT","id":"13844","side":"Buy","size":181.00002}]},"cross_seq":"916954107","timestamp_e6":"1618677790382348"}
1618677790.477896: {"topic":"orderBookL2_25.BCHUSDT","type":"delta","data":{"delete":[{"price":"1054.65","symbol":"BCHUSDT","id":"10546500","side":"Buy"},{"price":"1053.35","symbol":"BCHUSDT","id":"10533500","side":"Buy"},{"price":"1053.45","symbol":"BCHUSDT","id":"10534500","side":"Buy"},{"price":"1053.40","symbol":"BCHUSDT","id":"10534000","side":"Buy"}],"update":[{"price":"1054.70","symbol":"BCHUSDT","id":"10547000","side":"Buy","size":26.48},{"price":"1055.30","symbol":"BCHUSDT","id":"10553000","side":"Sell","size":11.34},{"price":"1055.60","symbol":"BCHUSDT","id":"10556000","side":"Sell","size":7.3},{"price":"1054.25","symbol":"BCHUSDT","id":"10542500","side":"Buy","size":13.68}],"insert":[{"price":"1054.80","symbol":"BCHUSDT","id":"10548000","side":"Buy","size":6.41},{"price":"1054.75","symbol":"BCHUSDT","id":"10547500","side":"Buy","size":4.85},{"price":"1054.90","symbol":"BCHUSDT","id":"10549000","side":"Buy","size":10.84},{"price":"1054.85","symbol":"BCHUSDT","id":"10548500","side":"Buy","size":8.88}]},"cross_seq":"864132474","timestamp_e6":"1618677790389983"}
1618677790.496332: {"topic":"orderBookL2_25.BCHUSDT","type":"delta","data":{"delete":[{"price":"1054.80","symbol":"BCHUSDT","id":"10548000","side":"Buy"},{"price":"1056.50","symbol":"BCHUSDT","id":"10565000","side":"Sell"},{"price":"1054.85","symbol":"BCHUSDT","id":"10548500","side":"Buy"},{"price":"1054.90","symbol":"BCHUSDT","id":"10549000","side":"Buy"}],"update":[{"price":"1054.75","symbol":"BCHUSDT","id":"10547500","side":"Buy","size":6.13},{"price":"1055.45","symbol":"BCHUSDT","id":"10554500","side":"Sell","size":15.51},{"price":"1055.50","symbol":"BCHUSDT","id":"10555000","side":"Sell","size":6.91},{"price":"1055.40","symbol":"BCHUSDT","id":"10554000","side":"Sell","size":13.070001},{"price":"1054.70","symbol":"BCHUSDT","id":"10547000","side":"Buy","size":29.56},{"price":"1055.30","symbol":"BCHUSDT","id":"10553000","side":"Sell","size":21.32}],"insert":[{"price":"1053.45","symbol":"BCHUSDT","id":"10534500","side":"Buy","size":9.02},{"price":"1055.35","symbol":"BCHUSDT","id":"10553500","side":"Sell","size":8.3},{"price":"1053.40","symbol":"BCHUSDT","id":"10534000","side":"Buy","size":18.35},{"price":"1054.95","symbol":"BCHUSDT","id":"10549500","side":"Buy","size":10.84}]},"cross_seq":"864132487","timestamp_e6":"1618677790409926"}
1618677790.513939: {"topic":"orderBookL2_25.LINKUSDT","type":"delta","data":{"delete":[{"price":"41.047","symbol":"LINKUSDT","id":"410470","side":"Sell"},{"price":"41.049","symbol":"LINKUSDT","id":"410490","side":"Sell"}],"update":[{"price":"41.045","symbol":"LINKUSDT","id":"410450","side":"Buy","size":46},{"price":"41.046","symbol":"LINKUSDT","id":"410460","side":"Sell","size":709.89996}],"insert":[{"price":"41.072","symbol":"LINKUSDT","id":"410720","side":"Sell","size":188.3},{"price":"41.073","symbol":"LINKUSDT","id":"410730","side":"Sell","size":132.2}]},"cross_seq":"1970979813","timestamp_e6":"1618677790428423"}
1618677790.514112: {"topic":"orderBookL2_25.BCHUSDT","type":"delta","data":{"delete":[],"update":[{"price":"1054.70","symbol":"BCHUSDT","id":"10547000","side":"Buy","size":3.08}],"insert":[]},"cross_seq":"864132488","timestamp_e6":"1618677790428920"}
1618677790.530231: {"topic":"orderBookL2_25.DOTUSDT","type":"delta","data":{"delete":[],"update":[{"price":"43.565","symbol":"DOTUSDT","id":"435650","side":"Sell","size":266.9}],"insert":[]},"cross_seq":"916954125","timestamp_e6":"1618677790442340"}
1618677790.530293: {"topic":"orderBookL2_25.LINKUSDT","type":"delta","data":{"delete":[{"price":"41.048","symbol":"LINKUSDT","id":"410480","side":"Sell"}],"update":[{"price":"41.052","symbol":"LINKUSDT","id":"410520","side":"Sell","size":139.09999},{"price":"41.050","symbol":"LINKUSDT","id":"410500","side":"Sell","size":202.2},{"price":"41.039","symbol":"LINKUSDT","id":"410390","side":"Buy","size":221.2}],"insert":[{"price":"41.049","symbol":"LINKUSDT","id":"410490","side":"Sell","size":185.1}]},"cross_seq":"1970979819","timestamp_e6":"1618677790445168"}
1618677790.532029: {"topic":"orderBookL2_25.BCHUSDT","type":"delta","data":{"delete":[{"price":"1055.35","symbol":"BCHUSDT","id":"10553500","side":"Sell"},{"price":"1053.40","symbol":"BCHUSDT","id":"10534000","side":"Buy"},{"price":"1053.45","symbol":"BCHUSDT","id":"10534500","side":"Buy"},{"price":"1053.50","symbol":"BCHUSDT","id":"10535000","side":"Buy"},{"price":"1056.45","symbol":"BCHUSDT","id":"10564500","side":"Sell"},{"price":"1056.40","symbol":"BCHUSDT","id":"10564000","side":"Sell"}],"update":[{"price":"1055.30","symbol":"BCHUSDT","id":"10553000","side":"Sell","size":11.34},{"price":"1055.40","symbol":"BCHUSDT","id":"10554000","side":"Sell","size":8.44}],"insert":[{"price":"1054.80","symbol":"BCHUSDT","id":"10548000","side":"Buy","size":4.85},{"price":"1054.90","symbol":"BCHUSDT","id":"10549000","side":"Buy","size":8.88},{"price":"1055.15","symbol":"BCHUSDT","id":"10551500","side":"Sell","size":9.98},{"price":"1055.20","symbol":"BCHUSDT","id":"10552000","side":"Sell","size":8.3},{"price":"1055.25","symbol":"BCHUSDT","id":"10552500","side":"Sell","size":4.22},{"price":"1054.85","symbol":"BCHUSDT","id":"10548500","side":"Buy","size":6.41}]},"cross_seq":"864132506","timestamp_e6":"1618677790448738"}
1618677790.5322082: {"topic":"orderBookL2_25.ETHUSDT","type":"delta","data":{"delete":[],"update":[{"price":"2364.90","symbol":"ETHUSDT","id":"23649000","side":"Buy","size":89}],"insert":[]},"cross_seq":"1800546441","timestamp_e6":"1618677790448238"}
1618677790.56928: {"topic":"orderBookL2_25.LINKUSDT","type":"delta","data":{"delete":[{"price":"41.073","symbol":"LINKUSDT","id":"410730","side":"Sell"},{"price":"41.049","symbol":"LINKUSDT","id":"410490","side":"Sell"}],"update":[{"price":"41.050","symbol":"LINKUSDT","id":"410500","side":"Sell","size":127.600006}],"insert":[{"price":"41.048","symbol":"LINKUSDT","id":"410480","side":"Sell","size":202.2},{"price":"41.047","symbol":"LINKUSDT","id":"410470","side":"Sell","size":185.1}]},"cross_seq":"1970979830","timestamp_e6":"1618677790483675"}
1618677790.594922: {"topic":"orderBookL2_25.BCHUSDT","type":"delta","data":{"delete":[{"price":"1055.30","symbol":"BCHUSDT","id":"10553000","side":"Sell"},{"price":"1055.40","symbol":"BCHUSDT","id":"10554000","side":"Sell"}],"update":[{"price":"1055.50","symbol":"BCHUSDT","id":"10555000","side":"Sell","size":12.66},{"price":"1055.55","symbol":"BCHUSDT","id":"10555500","side":"Sell","size":8.32},{"price":"1055.65","symbol":"BCHUSDT","id":"10556500","side":"Sell","size":16.86},{"price":"1055.45","symbol":"BCHUSDT","id":"10554500","side":"Sell","size":22.36}],"insert":[{"price":"1056.45","symbol":"BCHUSDT","id":"10564500","side":"Sell","size":16.609999},{"price":"1056.40","symbol":"BCHUSDT","id":"10564000","side":"Sell","size":1}]},"cross_seq":"864132528","timestamp_e6":"1618677790508687"}
1618677790.602359: {"topic":"orderBookL2_25.XTZUSDT","type":"delta","data":{"delete":[{"price":"7.186","symbol":"XTZUSDT","id":"71860","side":"Buy"}],"update":[{"price":"7.205","symbol":"XTZUSDT","id":"72050","side":"Buy","size":3711.2002}],"insert":[{"price":"7.209","symbol":"XTZUSDT","id":"72090","side":"Buy","size":1339.5}]},"cross_seq":"726228389","timestamp_e6":"1618677790514898"}
1618677790.614558: {"topic":"orderBookL2_25.ETHUSDT","type":"delta","data":{"delete":[{"price":"2364.00","symbol":"ETHUSDT","id":"23640000","side":"Buy"},{"price":"2364.45","symbol":"ETHUSDT","id":"23644500","side":"Buy"},{"price":"2364.05","symbol":"ETHUSDT","id":"23640500","side":"Buy"}],"update":[{"price":"2363.80","symbol":"ETHUSDT","id":"23638000","side":"Buy","size":95.189995},{"price":"2363.70","symbol":"ETHUSDT","id":"23637000","side":"Buy","size":85.73},{"price":"2363.55","symbol":"ETHUSDT","id":"23635500","side":"Buy","size":35.15},{"price":"2364.95","symbol":"ETHUSDT","id":"23649500","side":"Sell","size":376.97},{"price":"2364.30","symbol":"ETHUSDT","id":"23643000","side":"Buy","size":46.460003},{"price":"2364.15","symbol":"ETHUSDT","id":"23641500","side":"Buy","size":48.210003},{"price":"2365.45","symbol":"ETHUSDT","id":"23654500","side":"Sell","size":39.510002},{"price":"2364.20","symbol":"ETHUSDT","id":"23642000","side":"Buy","size":58.360004},{"price":"2363.95","symbol":"ETHUSDT","id":"23639500","side":"Buy","size":26.35},{"price":"2364.10","symbol":"ETHUSDT","id":"23641000","side":"Buy","size":46.460003},{"price":"2365.20","symbol":"ETHUSDT","id":"23652000","side":"Sell","size":109.37},{"price":"2363.65","symbol":"ETHUSDT","id":"23636500","side":"Buy","size":49.45},{"price":"2365.05","symbol":"ETHUSDT","id":"23650500","side":"Sell","size":190.14},{"price":"2365.00","symbol":"ETHUSDT","id":"23650000","side":"Sell","size":201.17},{"price":"2365.15","symbol":"ETHUSDT","id":"23651500","side":"Sell","size":147.42},{"price":"2363.60","symbol":"ETHUSDT","id":"23636000","side":"Buy","size":51.11},{"price":"2363.75","symbol":"ETHUSDT","id":"23637500","side":"Buy","size":90.33}],"insert":[{"price":"2363.30","symbol":"ETHUSDT","id":"23633000","side":"Buy","size":82.380005},{"price":"2363.25","symbol":"ETHUSDT","id":"23632500","side":"Buy","size":129.70999},{"price":"2364.40","symbol":"ETHUSDT","id":"23644000","side":"Buy","size":86.91}]},"cross_seq":"1800546481","timestamp_e6":"1618677790527466"}
1618677790.6288629: {"topic":"orderBookL2_25.LINKUSDT","type":"delta","data":{"delete":[{"price":"41.072","symbol":"LINKUSDT","id":"410720","side":"Sell"},{"price":"41.037","symbol":"LINKUSDT","id":"410370","side":"Buy"},{"price":"41.038","symbol":"LINKUSDT","id":"410380","side":"Buy"},{"price":"41.039","symbol":"LINKUSDT","id":"410390","side":"Buy"}],"update":[],"insert":[{"price":"41.049","symbol":"LINKUSDT","id":"410490","side":"Sell","size":115},{"price":"41.041","symbol":"LINKUSDT","id":"410410","side":"Buy","size":189.9},{"price":"41.040","symbol":"LINKUSDT","id":"410400","side":"Buy","size":135.3},{"price":"41.042","symbol":"LINKUSDT","id":"410420","side":"Buy","size":221.2}]},"cross_seq":"1970979846","timestamp_e6":"1618677790544312"}
1618677790.635637: {"topic":"orderBookL2_25.BCHUSDT","type":"delta","data":{"delete":[{"price":"1055.15","symbol":"BCHUSDT","id":"10551500","side":"Sell"},{"price":"1055.25","symbol":"BCHUSDT","id":"10552500","side":"Sell"},{"price":"1055.60","symbol":"BCHUSDT","id":"10556000","side":"Sell"},{"price":"1055.20","symbol":"BCHUSDT","id":"10552000","side":"Sell"}],"update":[{"price":"1055.65","symbol":"BCHUSDT","id":"10556500","side":"Sell","size":22.17},{"price":"1055.70","symbol":"BCHUSDT","id":"10557000","side":"Sell","size":7.6},{"price":"1055.80","symbol":"BCHUSDT","id":"10558000","side":"Sell","size":3.53},{"price":"1055.75","symbol":"BCHUSDT","id":"10557500","side":"Sell","size":7.38}],"insert":[{"price":"1056.65","symbol":"BCHUSDT","id":"10566500","side":"Sell","size":12},{"price":"1056.55","symbol":"BCHUSDT","id":"10565500","side":"Sell","size":10.5},{"price":"1056.50","symbol":"BCHUSDT","id":"10565000","side":"Sell","size":30.32},{"price":"1056.60","symbol":"BCHUSDT","id":"10566000","side":"Sell","size":14.3}]},"cross_seq":"864132554","timestamp_e6":"1618677790548700"}
1618677790.647635: {"topic":"orderBookL2_25.LTCUSDT","type":"delta","data":{"delete":[{"price":"313.29","symbol":"LTCUSDT","id":"3132900","side":"Sell"}],"update":[{"price":"313.17","symbol":"LTCUSDT","id":"3131700","side":"Sell","size":1.5},{"price":"313.26","symbol":"LTCUSDT","id":"3132600","side":"Sell","size":42.5},{"price":"313.18","symbol":"LTCUSDT","id":"3131800","side":"Sell","size":1.5},{"price":"313.28","symbol":"LTCUSDT","id":"3132800","side":"Sell","size":49.5},{"price":"313.25","symbol":"LTCUSDT","id":"3132500","side":"Sell","size":164},{"price":"313.19","symbol":"LTCUSDT","id":"3131900","side":"Sell","size":10}],"insert":[{"price":"313.24","symbol":"LTCUSDT","id":"3132400","side":"Sell","size":253.7}]},"cross_seq":"1684522793","timestamp_e6":"1618677790558851"}
1618677790.656075: {"topic":"orderBookL2_25.ETHUSDT","type":"delta","data":{"delete":[],"update":[{"price":"2364.75","symbol":"ETHUSDT","id":"23647500","side":"Buy","size":45.789997}],"insert":[]},"cross_seq":"1800546495","timestamp_e6":"1618677790567649"}
1618677790.694151: {"topic":"orderBookL2_25.UNIUSDT","type":"delta","data":{"delete":[],"update":[{"price":"35.367","symbol":"UNIUSDT","id":"353670","side":"Buy","size":46.6},{"price":"35.365","symbol":"UNIUSDT","id":"353650","side":"Buy","size":31.6},{"price":"35.368","symbol":"UNIUSDT","id":"353680","side":"Buy","size":41.8},{"price":"35.364","symbol":"UNIUSDT","id":"353640","side":"Buy","size":39.9}],"insert":[]},"cross_seq":"916954131","timestamp_e6":"1618677790602369"}
1618677790.694273: {"topic":"orderBookL2_25.LINKUSDT","type":"delta","data":{"delete":[],"update":[{"price":"41.034","symbol":"LINKUSDT","id":"410340","side":"Buy","size":395.7},{"price":"41.069","symbol":"LINKUSDT","id":"410690","side":"Sell","size":345.30002},{"price":"41.032","symbol":"LINKUSDT","id":"410320","side":"Buy","size":314.1},{"price":"41.066","symbol":"LINKUSDT","id":"410660","side":"Sell","size":768.3},{"price":"41.065","symbol":"LINKUSDT","id":"410650","side":"Sell","size":585.2},{"price":"41.070","symbol":"LINKUSDT","id":"410700","side":"Sell","size":336.6},{"price":"41.033","symbol":"LINKUSDT","id":"410330","side":"Buy","size":999.8},{"price":"41.030","symbol":"LINKUSDT","id":"410300","side":"Buy","size":145.7},{"price":"41.067","symbol":"LINKUSDT","id":"410670","side":"Sell","size":424.69998},{"price":"41.068","symbol":"LINKUSDT","id":"410680","side":"Sell","size":777.3},{"price":"41.029","symbol":"LINKUSDT","id":"410290","side":"Buy","size":107.8}],"insert":[]},"cross_seq":"1970979860","timestamp_e6":"1618677790604143"}
1618677790.698097: {"topic":"orderBookL2_25.BCHUSDT","type":"delta","data":{"delete":[{"price":"1056.65","symbol":"BCHUSDT","id":"10566500","side":"Sell"}],"update":[{"price":"1055.80","symbol":"BCHUSDT","id":"10558000","side":"Sell","size":6.52},{"price":"1055.45","symbol":"BCHUSDT","id":"10554500","side":"Sell","size":14.06},{"price":"1055.70","symbol":"BCHUSDT","id":"10557000","side":"Sell","size":10.750001},{"price":"1055.55","symbol":"BCHUSDT","id":"10555500","side":"Sell","size":15.31},{"price":"1055.65","symbol":"BCHUSDT","id":"10556500","side":"Sell","size":13.870001},{"price":"1055.75","symbol":"BCHUSDT","id":"10557500","side":"Sell","size":6.38},{"price":"1055.50","symbol":"BCHUSDT","id":"10555000","side":"Sell","size":8.44}],"insert":[{"price":"1055.60","symbol":"BCHUSDT","id":"10556000","side":"Sell","size":8.3}]},"cross_seq":"864132566","timestamp_e6":"1618677790609346"}
1618677790.728022: {"topic":"orderBookL2_25.DOTUSDT","type":"delta","data":{"delete":[{"price":"43.405","symbol":"DOTUSDT","id":"434050","side":"Buy"}],"update":[{"price":"43.535","symbol":"DOTUSDT","id":"435350","side":"Buy","size":192}],"insert":[{"price":"43.520","symbol":"DOTUSDT","id":"435200","side":"Buy","size":10}]},"cross_seq":"916954132","timestamp_e6":"1618677790642311"}
1618677790.749841: {"topic":"orderBookL2_25.LTCUSDT","type":"delta","data":{"delete":[],"update":[{"price":"313.10","symbol":"LTCUSDT","id":"3131000","side":"Sell","size":0.5}],"insert":[]},"cross_seq":"1684522794","timestamp_e6":"1618677790659689"}
1618677790.752448: {"topic":"orderBookL2_25.DOTUSDT","type":"delta","data":{"delete":[],"update":[{"price":"43.535","symbol":"DOTUSDT","id":"435350","side":"Buy","size":96}],"insert":[]},"cross_seq":"916954133","timestamp_e6":"1618677790662348"}
1618677790.7965922: {"topic":"orderBookL2_25.ETHUSDT","type":"delta","data":{"delete":[],"update":[{"price":"2364.75","symbol":"ETHUSDT","id":"23647500","side":"Buy","size":44.579998},{"price":"2363.35","symbol":"ETHUSDT","id":"23633500","side":"Buy","size":26.6}],"insert":[]},"cross_seq":"1800546497","timestamp_e6":"1618677790707781"}
1618677790.817392: {"topic":"trade.LTCUSDT","data":[{"symbol":"LTCUSDT","tick_direction":"MinusTick","price":"313.10","size":1,"timestamp":"2021-04-17T16:43:10.000Z","trade_time_ms":"1618677790631","side":"Buy","trade_id":"7d10ee80-94a7-501a-adea-a99020f32f77"}]}
1618677790.834898: {"topic":"orderBookL2_25.BCHUSDT","type":"delta","data":{"delete":[],"update":[{"price":"1056.10","symbol":"BCHUSDT","id":"10561000","side":"Sell","size":6.37}],"insert":[]},"cross_seq":"864132567","timestamp_e6":"1618677790749474"}
1618677790.8544042: {"topic":"orderBookL2_25.BCHUSDT","type":"delta","data":{"delete":[{"price":"1055.60","symbol":"BCHUSDT","id":"10556000","side":"Sell"}],"update":[{"price":"1055.50","symbol":"BCHUSDT","id":"10555000","side":"Sell","size":12.66},{"price":"1055.55","symbol":"BCHUSDT","id":"10555500","side":"Sell","size":5.33},{"price":"1055.65","symbol":"BCHUSDT","id":"10556500","side":"Sell","size":16.86},{"price":"1055.45","symbol":"BCHUSDT","id":"10554500","side":"Sell","size":22.36}],"insert":[{"price":"1055.40","symbol":"BCHUSDT","id":"10554000","side":"Sell","size":9.98}]},"cross_seq":"864132579","timestamp_e6":"1618677790769469"}
1618677790.86161: {"topic":"orderBookL2_25.XTZUSDT","type":"delta","data":{"delete":[],"update":[{"price":"7.206","symbol":"XTZUSDT","id":"72060","side":"Buy","size":3189.3},{"price":"7.215","symbol":"XTZUSDT","id":"72150","side":"Sell","size":1554.4},{"price":"7.217","symbol":"XTZUSDT","id":"72170","side":"Sell","size":1154.1},{"price":"7.209","symbol":"XTZUSDT","id":"72090","side":"Buy","size":1707.7001},{"price":"7.216","symbol":"XTZUSDT","id":"72160","side":"Sell","size":2300.4}],"insert":[]},"cross_seq":"726228397","timestamp_e6":"1618677790775191"}
1618677790.87276: {"topic":"orderBookL2_25.DOTUSDT","type":"delta","data":{"delete":[],"update":[{"price":"43.575","symbol":"DOTUSDT","id":"435750","side":"Sell","size":231.29999},{"price":"43.465","symbol":"DOTUSDT","id":"434650","side":"Buy","size":472.50003},{"price":"43.460","symbol":"DOTUSDT","id":"434600","side":"Buy","size":496.7},{"price":"43.455","symbol":"DOTUSDT","id":"434550","side":"Buy","size":534.5}],"insert":[]},"cross_seq":"916954142","timestamp_e6":"1618677790782350"}
1618677790.872823: {"topic":"orderBookL2_25.UNIUSDT","type":"delta","data":{"delete":[],"update":[{"price":"35.406","symbol":"UNIUSDT","id":"354060","side":"Sell","size":141},{"price":"35.407","symbol":"UNIUSDT","id":"354070","side":"Sell","size":121},{"price":"35.382","symbol":"UNIUSDT","id":"353820","side":"Buy","size":19.3},{"price":"35.381","symbol":"UNIUSDT","id":"353810","side":"Buy","size":18.4},{"price":"35.378","symbol":"UNIUSDT","id":"353780","side":"Buy","size":28.9}],"insert":[]},"cross_seq":"916954142","timestamp_e6":"1618677790783722"}
1618677790.876415: {"topic":"orderBookL2_25.ETHUSDT","type":"delta","data":{"delete":[{"price":"2364.40","symbol":"ETHUSDT","id":"23644000","side":"Buy"},{"price":"2364.35","symbol":"ETHUSDT","id":"23643500","side":"Buy"},{"price":"2364.30","symbol":"ETHUSDT","id":"23643000","side":"Buy"},{"price":"2364.25","symbol":"ETHUSDT","id":"23642500","side":"Buy"}],"update":[{"price":"2364.20","symbol":"ETHUSDT","id":"23642000","side":"Buy","size":86.91}],"insert":[{"price":"2364.05","symbol":"ETHUSDT","id":"23640500","side":"Buy","size":24.710001},{"price":"2364.00","symbol":"ETHUSDT","id":"23640000","side":"Buy","size":25.340002},{"price":"2363.15","symbol":"ETHUSDT","id":"23631500","side":"Buy","size":38.06},{"price":"2363.20","symbol":"ETHUSDT","id":"23632000","side":"Buy","size":51.6}]},"cross_seq":"1800546507","timestamp_e6":"1618677790787332"}
1618677790.87653: {"topic":"orderBookL2_25.BCHUSDT","type":"delta","data":{"delete":[],"update":[{"price":"1054.95","symbol":"BCHUSDT","id":"10549500","side":"Buy","size":37.510002}],"insert":[]},"cross_seq":"864132580","timestamp_e6":"1618677790789922"}
1618677790.8825622: {"topic":"orderBookL2_25.LTCUSDT","type":"delta","data":{"delete":[{"price":"313.23","symbol":"LTCUSDT","id":"3132300","side":"Sell"},{"price":"313.21","symbol":"LTCUSDT","id":"3132100","side":"Sell"},{"price":"313.20","symbol":"LTCUSDT","id":"3132000","side":"Sell"},{"price":"313.22","symbol":"LTCUSDT","id":"3132200","side":"Sell"}],"update":[{"price":"313.28","symbol":"LTCUSDT","id":"3132800","side":"Sell","size":74.5},{"price":"313.26","symbol":"LTCUSDT","id":"3132600","side":"Sell","size":95.899994}],"insert":[{"price":"313.43","symbol":"LTCUSDT","id":"3134300","side":"Sell","size":96},{"price":"313.44","symbol":"LTCUSDT","id":"3134400","side":"Sell","size":15.9},{"price":"313.42","symbol":"LTCUSDT","id":"3134200","side":"Sell","size":59.399998},{"price":"313.29","symbol":"LTCUSDT","id":"3132900","side":"Sell","size":18.9}]},"cross_seq":"1684522804","timestamp_e6":"1618677790797920"}
1618677790.888492: {"topic":"orderBookL2_25.DOTUSDT","type":"delta","data":{"delete":[],"update":[{"price":"43.535","symbol":"DOTUSDT","id":"435350","side":"Buy","size":192}],"insert":[]},"cross_seq":"916954143","timestamp_e6":"1618677790802325"}
1618677790.891099: {"topic":"orderBookL2_25.LINKUSDT","type":"delta","data":{"delete":[{"price":"41.016","symbol":"LINKUSDT","id":"410160","side":"Buy"},{"price":"41.018","symbol":"LINKUSDT","id":"410180","side":"Buy"},{"price":"41.017","symbol":"LINKUSDT","id":"410170","side":"Buy"}],"update":[],"insert":[{"price":"41.039","symbol":"LINKUSDT","id":"410390","side":"Buy","size":122.9},{"price":"41.038","symbol":"LINKUSDT","id":"410380","side":"Buy","size":76.5},{"price":"41.037","symbol":"LINKUSDT","id":"410370","side":"Buy","size":57.5}]},"cross_seq":"1970979863","timestamp_e6":"1618677790803844"}
1618677790.895282: {"topic":"orderBookL2_25.BCHUSDT","type":"delta","data":{"delete":[{"price":"1055.55","symbol":"BCHUSDT","id":"10555500","side":"Sell"}],"update":[{"price":"1055.80","symbol":"BCHUSDT","id":"10558000","side":"Sell","size":7.46},{"price":"1055.45","symbol":"BCHUSDT","id":"10554500","side":"Sell","size":8.3},{"price":"1055.70","symbol":"BCHUSDT","id":"10557000","side":"Sell","size":7.55},{"price":"1055.50","symbol":"BCHUSDT","id":"10555000","side":"Sell","size":4.22},{"price":"1055.85","symbol":"BCHUSDT","id":"10558500","side":"Sell","size":16.49},{"price":"1053.70","symbol":"BCHUSDT","id":"10537000","side":"Buy","size":16.7},{"price":"1055.75","symbol":"BCHUSDT","id":"10557500","side":"Sell","size":4.17}],"insert":[{"price":"1055.60","symbol":"BCHUSDT","id":"10556000","side":"Sell","size":11.9}]},"cross_seq":"864132596","timestamp_e6":"1618677790809418"}
1618677790.9069052: {"topic":"orderBookL2_25.LTCUSDT","type":"delta","data":{"delete":[],"update":[{"price":"313.29","symbol":"LTCUSDT","id":"3132900","side":"Sell","size":69.5}],"insert":[]},"cross_seq":"1684522805","timestamp_e6":"1618677790817890"}
1618677790.9104362: {"topic":"orderBookL2_25.DOTUSDT","type":"delta","data":{"delete":[{"price":"43.490","symbol":"DOTUSDT","id":"434900","side":"Buy"},{"price":"43.510","symbol":"DOTUSDT","id":"435100","side":"Buy"},{"price":"43.495","symbol":"DOTUSDT","id":"434950","side":"Buy"}],"update":[{"price":"43.500","symbol":"DOTUSDT","id":"435000","side":"Buy","size":0.1},{"price":"43.515","symbol":"DOTUSDT","id":"435150","side":"Buy","size":434.9},{"price":"43.535","symbol":"DOTUSDT","id":"435350","side":"Buy","size":202},{"price":"43.485","symbol":"DOTUSDT","id":"434850","side":"Buy","size":44.999996},{"price":"43.520","symbol":"DOTUSDT","id":"435200","side":"Buy","size":494.3},{"price":"43.505","symbol":"DOTUSDT","id":"435050","side":"Buy","size":135.7},{"price":"43.530","symbol":"DOTUSDT","id":"435300","side":"Buy","size":538.69995}],"insert":[{"price":"43.400","symbol":"DOTUSDT","id":"434000","side":"Buy","size":1.2},{"price":"43.525","symbol":"DOTUSDT","id":"435250","side":"Buy","size":487.6},{"price":"43.405","symbol":"DOTUSDT","id":"434050","side":"Buy","size":444.5}]},"cross_seq":"916954164","timestamp_e6":"1618677790822350"}
1618677790.910557: {"topic":"orderBookL2_25.LINKUSDT","type":"delta","data":{"delete":[],"update":[{"price":"41.066","symbol":"LINKUSDT","id":"410660","side":"Sell","size":830.49994}],"insert":[]},"cross_seq":"1970979864","timestamp_e6":"1618677790824818"}
1618677790.927207: {"topic":"orderBookL2_25.DOTUSDT","type":"delta","data":{"delete":[],"update":[{"price":"43.530","symbol":"DOTUSDT","id":"435300","side":"Buy","size":528.7},{"price":"43.535","symbol":"DOTUSDT","id":"435350","side":"Buy","size":211.99998}],"insert":[]},"cross_seq":"916954166","timestamp_e6":"1618677790842508"}
1618677790.9272609: {"topic":"orderBookL2_25.ADAUSDT","type":"delta","data":{"delete":[],"update":[{"price":"1.3875","symbol":"ADAUSDT","id":"13875","side":"Buy","size":75851}],"insert":[]},"cross_seq":"916954166","timestamp_e6":"1618677790842327"}
1618677790.938974: {"topic":"orderBookL2_25.XTZUSDT","type":"delta","data":{"delete":[],"update":[{"price":"7.221","symbol":"XTZUSDT","id":"72210","side":"Sell","size":1898.4}],"insert":[]},"cross_seq":"726228398","timestamp_e6":"1618677790854895"}
1618677790.9980931: {"topic":"orderBookL2_25.XTZUSDT","type":"delta","data":{"delete":[],"update":[{"price":"7.204","symbol":"XTZUSDT","id":"72040","side":"Buy","size":2318},{"price":"7.208","symbol":"XTZUSDT","id":"72080","side":"Buy","size":3055.0999},{"price":"7.205","symbol":"XTZUSDT","id":"72050","side":"Buy","size":3326.3},{"price":"7.196","symbol":"XTZUSDT","id":"71960","side":"Buy","size":1617.8},{"price":"7.202","symbol":"XTZUSDT","id":"72020","side":"Buy","size":1743},{"price":"7.209","symbol":"XTZUSDT","id":"72090","side":"Buy","size":3372},{"price":"7.199","symbol":"XTZUSDT","id":"71990","side":"Buy","size":716.39996},{"price":"7.201","symbol":"XTZUSDT","id":"72010","side":"Buy","size":1415.2},{"price":"7.203","symbol":"XTZUSDT","id":"72030","side":"Buy","size":457.6}],"insert":[]},"cross_seq":"726228416","timestamp_e6":"1618677790914551"}
1618677791.026876: {"topic":"orderBookL2_25.ADAUSDT","type":"delta","data":{"delete":[],"update":[{"price":"1.3857","symbol":"ADAUSDT","id":"13857","side":"Buy","size":10983},{"price":"1.3882","symbol":"ADAUSDT","id":"13882","side":"Sell","size":4673},{"price":"1.3858","symbol":"ADAUSDT","id":"13858","side":"Buy","size":8284},{"price":"1.3859","symbol":"ADAUSDT","id":"13859","side":"Buy","size":7188.0005},{"price":"1.3883","symbol":"ADAUSDT","id":"13883","side":"Sell","size":3088},{"price":"1.3879","symbol":"ADAUSDT","id":"13879","side":"Sell","size":4368},{"price":"1.3855","symbol":"ADAUSDT","id":"13855","side":"Buy","size":6658},{"price":"1.3856","symbol":"ADAUSDT","id":"13856","side":"Buy","size":11081},{"price":"1.3878","symbol":"ADAUSDT","id":"13878","side":"Sell","size":8846},{"price":"1.3881","symbol":"ADAUSDT","id":"13881","side":"Sell","size":2924},{"price":"1.3854","symbol":"ADAUSDT","id":"13854","side":"Buy","size":10118}],"insert":[]},"cross_seq":"916954177","timestamp_e6":"1618677790942367"}
1618677791.030586: {"topic":"orderBookL2_25.ETHUSDT","type":"delta","data":{"delete":[{"price":"2363.15","symbol":"ETHUSDT","id":"23631500","side":"Buy"}],"update":[],"insert":[{"price":"2364.40","symbol":"ETHUSDT","id":"23644000","side":"Buy","size":1.19}]},"cross_seq":"1800546508","timestamp_e6":"1618677790947467"}
1618677791.039207: {"topic":"orderBookL2_25.XTZUSDT","type":"delta","data":{"delete":[],"update":[{"price":"7.205","symbol":"XTZUSDT","id":"72050","side":"Buy","size":4597.3}],"insert":[]},"cross_seq":"726228417","timestamp_e6":"1618677790954858"}
1618677791.053109: {"topic":"orderBookL2_25.BCHUSDT","type":"delta","data":{"delete":[{"price":"1055.50","symbol":"BCHUSDT","id":"10555000","side":"Sell"},{"price":"1055.45","symbol":"BCHUSDT","id":"10554500","side":"Sell"},{"price":"1055.40","symbol":"BCHUSDT","id":"10554000","side":"Sell"}],"update":[{"price":"1055.60","symbol":"BCHUSDT","id":"10556000","side":"Sell","size":14.889999}],"insert":[{"price":"1055.35","symbol":"BCHUSDT","id":"10553500","side":"Sell","size":9.98},{"price":"1056.65","symbol":"BCHUSDT","id":"10566500","side":"Sell","size":12},{"price":"1055.55","symbol":"BCHUSDT","id":"10555500","side":"Sell","size":2.52}]},"cross_seq":"864132603","timestamp_e6":"1618677790969304"}
1618677791.0780349: {"topic":"orderBookL2_25.XTZUSDT","type":"delta","data":{"delete":[],"update":[{"price":"7.226","symbol":"XTZUSDT","id":"72260","side":"Sell","size":1219.8}],"insert":[]},"cross_seq":"726228418","timestamp_e6":"1618677790995217"}
1618677791.081224: {"topic":"orderBookL2_25.LTCUSDT","type":"delta","data":{"delete":[{"price":"313.17","symbol":"LTCUSDT","id":"3131700","side":"Sell"}],"update":[{"price":"313.35","symbol":"LTCUSDT","id":"3133500","side":"Sell","size":97.6}],"insert":[{"price":"313.45","symbol":"LTCUSDT","id":"3134500","side":"Sell","size":172.3}]},"cross_seq":"1684522806","timestamp_e6":"1618677790997864"}
1618677791.0944252: {"topic":"orderBookL2_25.BCHUSDT","type":"delta","data":{"delete":[],"update":[{"price":"1054.95","symbol":"BCHUSDT","id":"10549500","side":"Buy","size":10.84}],"insert":[]},"cross_seq":"864132604","timestamp_e6":"1618677791010203"}
1618677791.1016169: {"topic":"orderBookL2_25.LTCUSDT","type":"delta","data":{"delete":[],"update":[{"price":"313.39","symbol":"LTCUSDT","id":"3133900","side":"Sell","size":167.2},{"price":"313.36","symbol":"LTCUSDT","id":"3133600","side":"Sell","size":127.2},{"price":"313.37","symbol":"LTCUSDT","id":"3133700","side":"Sell","size":147},{"price":"313.40","symbol":"LTCUSDT","id":"3134000","side":"Sell","size":58.899998},{"price":"313.38","symbol":"LTCUSDT","id":"3133800","side":"Sell","size":93.49999},{"price":"313.35","symbol":"LTCUSDT","id":"3133500","side":"Sell","size":209.8}],"insert":[]},"cross_seq":"1684522841","timestamp_e6":"1618677791017924"}
1618677791.1086578: {"topic":"orderBookL2_25.LINKUSDT","type":"delta","data":{"delete":[{"price":"41.041","symbol":"LINKUSDT","id":"410410","side":"Buy"},{"price":"41.038","symbol":"LINKUSDT","id":"410380","side":"Buy"},{"price":"41.039","symbol":"LINKUSDT","id":"410390","side":"Buy"}],"update":[],"insert":[{"price":"41.017","symbol":"LINKUSDT","id":"410170","side":"Buy","size":329.4},{"price":"41.043","symbol":"LINKUSDT","id":"410430","side":"Buy","size":221.2},{"price":"41.018","symbol":"LINKUSDT","id":"410180","side":"Buy","size":391.49997}]},"cross_seq":"1970979873","timestamp_e6":"1618677791023751"}
1618677791.114162: {"topic":"orderBookL2_25.BCHUSDT","type":"delta","data":{"delete":[{"price":"1056.60","symbol":"BCHUSDT","id":"10566000","side":"Sell"},{"price":"1056.65","symbol":"BCHUSDT","id":"10566500","side":"Sell"},{"price":"1056.55","symbol":"BCHUSDT","id":"10565500","side":"Sell"},{"price":"1053.55","symbol":"BCHUSDT","id":"10535500","side":"Buy"}],"update":[{"price":"1054.70","symbol":"BCHUSDT","id":"10547000","side":"Buy","size":6.41},{"price":"1054.75","symbol":"BCHUSDT","id":"10547500","side":"Buy","size":8.88},{"price":"1054.80","symbol":"BCHUSDT","id":"10548000","side":"Buy","size":5.99}],"insert":[{"price":"1055.50","symbol":"BCHUSDT","id":"10555000","side":"Sell","size":3.15},{"price":"1055.40","symbol":"BCHUSDT","id":"10554000","side":"Sell","size":8.3},{"price":"1055.45","symbol":"BCHUSDT","id":"10554500","side":"Sell","size":4.22},{"price":"1054.65","symbol":"BCHUSDT","id":"10546500","side":"Buy","size":4.85}]},"cross_seq":"864132616","timestamp_e6":"1618677791028921"}
1618677791.1149492: {"topic":"trade.LTCUSDT","data":[{"symbol":"LTCUSDT","tick_direction":"ZeroMinusTick","price":"313.10","size":0.5,"timestamp":"2021-04-17T16:43:11.000Z","trade_time_ms":"1618677791018","side":"Buy","trade_id":"299de908-3f94-5e0d-88e7-279306b2b79c"}]}
1618677791.1239722: {"topic":"orderBookL2_25.LTCUSDT","type":"delta","data":{"delete":[{"price":"313.18","symbol":"LTCUSDT","id":"3131800","side":"Sell"},{"price":"313.10","symbol":"LTCUSDT","id":"3131000","side":"Sell"}],"update":[{"price":"313.36","symbol":"LTCUSDT","id":"3133600","side":"Sell","size":128.7}],"insert":[{"price":"313.47","symbol":"LTCUSDT","id":"3134700","side":"Sell","size":65.799995},{"price":"313.46","symbol":"LTCUSDT","id":"3134600","side":"Sell","size":38.300003}]},"cross_seq":"1684522855","timestamp_e6":"1618677791039101"}
1618677791.126872: {"topic":"orderBookL2_25.UNIUSDT","type":"delta","data":{"delete":[],"update":[{"price":"35.382","symbol":"UNIUSDT","id":"353820","side":"Buy","size":31.8},{"price":"35.381","symbol":"UNIUSDT","id":"353810","side":"Buy","size":27.6}],"insert":[]},"cross_seq":"916954179","timestamp_e6":"1618677791042338"}
1618677791.136867: {"topic":"orderBookL2_25.BCHUSDT","type":"delta","data":{"delete":[{"price":"1054.95","symbol":"BCHUSDT","id":"10549500","side":"Buy"},{"price":"1053.60","symbol":"BCHUSDT","id":"10536000","side":"Buy"},{"price":"1054.90","symbol":"BCHUSDT","id":"10549000","side":"Buy"}],"update":[{"price":"1054.75","symbol":"BCHUSDT","id":"10547500","side":"Buy","size":4.03},{"price":"1053.70","symbol":"BCHUSDT","id":"10537000","side":"Buy","size":20.42},{"price":"1054.50","symbol":"BCHUSDT","id":"10545000","side":"Buy","size":3.11},{"price":"1053.75","symbol":"BCHUSDT","id":"10537500","side":"Buy","size":15.16},{"price":"1054.85","symbol":"BCHUSDT","id":"10548500","side":"Buy","size":10.84},{"price":"1054.80","symbol":"BCHUSDT","id":"10548000","side":"Buy","size":8.88},{"price":"1054.45","symbol":"BCHUSDT","id":"10544500","side":"Buy","size":5.11},{"price":"1053.85","symbol":"BCHUSDT","id":"10538500","side":"Buy","size":15.590001},{"price":"1054.55","symbol":"BCHUSDT","id":"10545500","side":"Buy","size":19.78},{"price":"1054.05","symbol":"BCHUSDT","id":"10540500","side":"Buy","size":32},{"price":"1055.75","symbol":"BCHUSDT","id":"10557500","side":"Sell","size":5.54}],"insert":[{"price":"1054.10","symbol":"BCHUSDT","id":"10541000","side":"Buy","size":2.15},{"price":"1054.15","symbol":"BCHUSDT","id":"10541500","side":"Buy","size":1},{"price":"1054.35","symbol":"BCHUSDT","id":"10543500","side":"Buy","size":2.22}]},"cross_seq":"864132635","timestamp_e6":"1618677791050065"}
1618677791.1464589: {"topic":"orderBookL2_25.LTCUSDT","type":"delta","data":{"delete":[{"price":"312.79","symbol":"LTCUSDT","id":"3127900","side":"Buy"},{"price":"312.78","symbol":"LTCUSDT","id":"3127800","side":"Buy"},{"price":"312.81","symbol":"LTCUSDT","id":"3128100","side":"Buy"},{"price":"312.83","symbol":"LTCUSDT","id":"3128300","side":"Buy"},{"price":"312.82","symbol":"LTCUSDT","id":"3128200","side":"Buy"},{"price":"312.84","symbol":"LTCUSDT","id":"3128400","side":"Buy"},{"price":"312.80","symbol":"LTCUSDT","id":"3128000","side":"Buy"}],"update":[{"price":"313.25","symbol":"LTCUSDT","id":"3132500","side":"Sell","size":98.200005},{"price":"313.30","symbol":"LTCUSDT","id":"3133000","side":"Sell","size":36.1},{"price":"313.33","symbol":"LTCUSDT","id":"3133300","side":"Sell","size":142.4},{"price":"313.34","symbol":"LTCUSDT","id":"3133400","side":"Sell","size":95.2},{"price":"313.27","symbol":"LTCUSDT","id":"3132700","side":"Sell","size":82},{"price":"313.28","symbol":"LTCUSDT","id":"3132800","side":"Sell","size":25},{"price":"313.36","symbol":"LTCUSDT","id":"3133600","side":"Sell","size":203.49998},{"price":"313.31","symbol":"LTCUSDT","id":"3133100","side":"Sell","size":32.2},{"price":"313.39","symbol":"LTCUSDT","id":"3133900","side":"Sell","size":212.3},{"price":"313.26","symbol":"LTCUSDT","id":"3132600","side":"Sell","size":53.4},{"price":"313.32","symbol":"LTCUSDT","id":"3133200","side":"Sell","size":78.700005},{"price":"313.24","symbol":"LTCUSDT","id":"3132400","side":"Sell","size":135.9},{"price":"313.29","symbol":"LTCUSDT","id":"3132900","side":"Sell","size":18.9},{"price":"313.09","symbol":"LTCUSDT","id":"3130900","side":"Buy","size":473.50003}],"insert":[{"price":"313.10","symbol":"LTCUSDT","id":"3131000","side":"Buy","size":16.2},{"price":"313.13","symbol":"LTCUSDT","id":"3131300","side":"Buy","size":63.800003},{"price":"313.16","symbol":"LTCUSDT","id":"3131600","side":"Buy","size":105.200005},{"price":"313.14","symbol":"LTCUSDT","id":"3131400","side":"Buy","size":77.2},{"price":"313.18","symbol":"LTCUSDT","id":"3131800","side":"Buy","size":147.7},{"price":"313.17","symbol":"LTCUSDT","id":"3131700","side":"Buy","size":141.6},{"price":"313.15","symbol":"LTCUSDT","id":"3131500","side":"Buy","size":139}]},"cross_seq":"1684522885","timestamp_e6":"1618677791059683"}
1618677791.147425: {"topic":"orderBookL2_25.UNIUSDT","type":"delta","data":{"delete":[{"price":"35.358","symbol":"UNIUSDT","id":"353580","side":"Buy"},{"price":"35.357","symbol":"UNIUSDT","id":"353570","side":"Buy"},{"price":"35.359","symbol":"UNIUSDT","id":"353590","side":"Buy"}],"update":[{"price":"35.372","symbol":"UNIUSDT","id":"353720","side":"Buy","size":32.5},{"price":"35.371","symbol":"UNIUSDT","id":"353710","side":"Buy","size":20.3},{"price":"35.373","symbol":"UNIUSDT","id":"353730","side":"Buy","size":45.5}],"insert":[{"price":"35.376","symbol":"UNIUSDT","id":"353760","side":"Buy","size":60},{"price":"35.374","symbol":"UNIUSDT","id":"353740","side":"Buy","size":39.5},{"price":"35.375","symbol":"UNIUSDT","id":"353750","side":"Buy","size":33.699997}]},"cross_seq":"916954188","timestamp_e6":"1618677791062366"}
1618677791.1505651: {"topic":"orderBookL2_25.LINKUSDT","type":"delta","data":{"delete":[],"update":[{"price":"41.046","symbol":"LINKUSDT","id":"410460","side":"Sell","size":959.89996}],"insert":[]},"cross_seq":"1970979874","timestamp_e6":"1618677791064140"}
1618677791.1519659: {"topic":"orderBookL2_25.BCHUSDT","type":"delta","data":{"delete":[{"price":"1054.60","symbol":"BCHUSDT","id":"10546000","side":"Buy"}],"update":[{"price":"1054.65","symbol":"BCHUSDT","id":"10546500","side":"Buy","size":6.13},{"price":"1054.70","symbol":"BCHUSDT","id":"10547000","side":"Buy","size":3.33}],"insert":[{"price":"1053.60","symbol":"BCHUSDT","id":"10536000","side":"Buy","size":17.03}]},"cross_seq":"864132649","timestamp_e6":"1618677791068886"}
1618677791.165334: {"topic":"orderBookL2_25.LTCUSDT","type":"delta","data":{"delete":[],"update":[{"price":"313.13","symbol":"LTCUSDT","id":"3131300","side":"Buy","size":313.80002},{"price":"313.09","symbol":"LTCUSDT","id":"3130900","side":"Buy","size":322},{"price":"313.18","symbol":"LTCUSDT","id":"3131800","side":"Buy","size":374.19998}],"insert":[]},"cross_seq":"1684522900","timestamp_e6":"1618677791079386"}
1618677791.168279: {"topic":"orderBookL2_25.DOTUSDT","type":"delta","data":{"delete":[{"price":"43.515","symbol":"DOTUSDT","id":"435150","side":"Buy"}],"update":[{"price":"43.545","symbol":"DOTUSDT","id":"435450","side":"Sell","size":337.6},{"price":"43.565","symbol":"DOTUSDT","id":"435650","side":"Sell","size":364.8},{"price":"43.555","symbol":"DOTUSDT","id":"435550","side":"Sell","size":473.6},{"price":"43.505","symbol":"DOTUSDT","id":"435050","side":"Buy","size":234.90001},{"price":"43.560","symbol":"DOTUSDT","id":"435600","side":"Sell","size":820.1}],"insert":[{"price":"43.510","symbol":"DOTUSDT","id":"435100","side":"Buy","size":443.9}]},"cross_seq":"916954196","timestamp_e6":"1618677791082376"}
1618677791.174752: {"topic":"orderBookL2_25.BCHUSDT","type":"delta","data":{"delete":[{"price":"1053.60","symbol":"BCHUSDT","id":"10536000","side":"Buy"}],"update":[{"price":"1054.70","symbol":"BCHUSDT","id":"10547000","side":"Buy","size":6.13},{"price":"1054.80","symbol":"BCHUSDT","id":"10548000","side":"Buy","size":2.89},{"price":"1054.85","symbol":"BCHUSDT","id":"10548500","side":"Buy","size":4.43},{"price":"1054.65","symbol":"BCHUSDT","id":"10546500","side":"Buy","size":1.28}],"insert":[{"price":"1054.90","symbol":"BCHUSDT","id":"10549000","side":"Buy","size":10.84}]},"cross_seq":"864132655","timestamp_e6":"1618677791089901"}
1618677791.1857972: {"topic":"orderBookL2_25.LTCUSDT","type":"delta","data":{"delete":[{"price":"313.10","symbol":"LTCUSDT","id":"3131000","side":"Buy"}],"update":[{"price":"313.34","symbol":"LTCUSDT","id":"3133400","side":"Sell","size":213.00002},{"price":"313.35","symbol":"LTCUSDT","id":"3133500","side":"Sell","size":94.799995},{"price":"313.18","symbol":"LTCUSDT","id":"3131800","side":"Buy","size":437.30002},{"price":"313.09","symbol":"LTCUSDT","id":"3130900","side":"Buy","size":133.9},{"price":"313.36","symbol":"LTCUSDT","id":"3133600","side":"Sell","size":128.7},{"price":"313.39","symbol":"LTCUSDT","id":"3133900","side":"Sell","size":161.8},{"price":"313.13","symbol":"LTCUSDT","id":"3131300","side":"Buy","size":63.800003}],"insert":[{"price":"312.84","symbol":"LTCUSDT","id":"3128400","side":"Buy","size":95.3}]},"cross_seq":"1684522909","timestamp_e6":"1618677791099203"}
1618677791.194413: {"topic":"orderBookL2_25.BCHUSDT","type":"delta","data":{"delete":[{"price":"1053.65","symbol":"BCHUSDT","id":"10536500","side":"Buy"}],"update":[],"insert":[{"price":"1054.95","symbol":"BCHUSDT","id":"10549500","side":"Buy","size":13.329999}]},"cross_seq":"864132656","timestamp_e6":"1618677791110039"}
1618677791.205164: {"topic":"orderBookL2_25.LTCUSDT","type":"delta","data":{"delete":[],"update":[{"price":"313.36","symbol":"LTCUSDT","id":"3133600","side":"Sell","size":203.49998},{"price":"313.39","symbol":"LTCUSDT","id":"3133900","side":"Sell","size":111.3},{"price":"313.09","symbol":"LTCUSDT","id":"3130900","side":"Buy","size":132.40001},{"price":"313.18","symbol":"LTCUSDT","id":"3131800","side":"Buy","size":438.80002},{"price":"313.35","symbol":"LTCUSDT","id":"3133500","side":"Sell","size":212.59999}],"insert":[]},"cross_seq":"1684522913","timestamp_e6":"1618677791120246"}
1618677791.212281: {"topic":"orderBookL2_25.BCHUSDT","type":"delta","data":{"delete":[{"price":"1054.95","symbol":"BCHUSDT","id":"10549500","side":"Buy"}],"update":[],"insert":[{"price":"1053.65","symbol":"BCHUSDT","id":"10536500","side":"Buy","size":14.28}]},"cross_seq":"864132664","timestamp_e6":"1618677791129860"}
1618677791.223916: {"topic":"orderBookL2_25.LTCUSDT","type":"delta","data":{"delete":[],"update":[{"price":"313.18","symbol":"LTCUSDT","id":"3131800","side":"Buy","size":454.99997}],"insert":[]},"cross_seq":"1684522914","timestamp_e6":"1618677791139045"}
1618677791.233338: {"topic":"trade.BCHUSDT","data":[{"symbol":"BCHUSDT","tick_direction":"PlusTick","price":"1054.90","size":0.01,"timestamp":"2021-04-17T16:43:11.000Z","trade_time_ms":"1618677791132","side":"Sell","trade_id":"337052e3-9946-5c34-85a6-36dd2aa87937"}]}
1618677791.233407: {"topic":"orderBookL2_25.BCHUSDT","type":"delta","data":{"delete":[],"update":[{"price":"1054.90","symbol":"BCHUSDT","id":"10549000","side":"Buy","size":10.830001}],"insert":[]},"cross_seq":"864132665","timestamp_e6":"1618677791150091"}
1618677791.238492: {"topic":"orderBookL2_25.XTZUSDT","type":"delta","data":{"delete":[],"update":[{"price":"7.204","symbol":"XTZUSDT","id":"72040","side":"Buy","size":2047.7999},{"price":"7.217","symbol":"XTZUSDT","id":"72170","side":"Sell","size":1435.9999},{"price":"7.218","symbol":"XTZUSDT","id":"72180","side":"Sell","size":1479.7999},{"price":"7.216","symbol":"XTZUSDT","id":"72160","side":"Sell","size":2553.6},{"price":"7.205","symbol":"XTZUSDT","id":"72050","side":"Buy","size":5102.7},{"price":"7.215","symbol":"XTZUSDT","id":"72150","side":"Sell","size":1845.4}],"insert":[]},"cross_seq":"726228428","timestamp_e6":"1618677791154714"}
1618677791.2515898: {"topic":"orderBookL2_25.BCHUSDT","type":"delta","data":{"delete":[],"update":[{"price":"1056.15","symbol":"BCHUSDT","id":"10561500","side":"Sell","size":8.73}],"insert":[]},"cross_seq":"864132666","timestamp_e6":"1618677791168746"}
1618677791.2705112: {"topic":"orderBookL2_25.ETHUSDT","type":"delta","data":{"delete":[],"update":[{"price":"2363.50","symbol":"ETHUSDT","id":"23635000","side":"Buy","size":57.34},{"price":"2363.35","symbol":"ETHUSDT","id":"23633500","side":"Buy","size":23.73}],"insert":[]},"cross_seq":"1800546510","timestamp_e6":"1618677791187143"}
1618677791.2779388: {"topic":"orderBookL2_25.XTZUSDT","type":"delta","data":{"delete":[],"update":[{"price":"7.205","symbol":"XTZUSDT","id":"72050","side":"Buy","size":3831.7}],"insert":[]},"cross_seq":"726228429","timestamp_e6":"1618677791194606"}
1618677791.287773: {"topic":"orderBookL2_25.LINKUSDT","type":"delta","data":{"delete":[],"update":[{"price":"41.066","symbol":"LINKUSDT","id":"410660","side":"Sell","size":768.3}],"insert":[]},"cross_seq":"1970979876","timestamp_e6":"1618677791203721"}
1618677791.3013089: {"topic":"orderBookL2_25.LTCUSDT","type":"delta","data":{"delete":[],"update":[{"price":"313.38","symbol":"LTCUSDT","id":"3133800","side":"Sell","size":49.6}],"insert":[]},"cross_seq":"1684522917","timestamp_e6":"1618677791218321"}
1618677791.309886: {"topic":"orderBookL2_25.LINKUSDT","type":"delta","data":{"delete":[],"update":[{"price":"41.046","symbol":"LINKUSDT","id":"410460","side":"Sell","size":893.89996}],"insert":[]},"cross_seq":"1970979877","timestamp_e6":"1618677791224664"}
1618677791.32416: {"topic":"orderBookL2_25.LTCUSDT","type":"delta","data":{"delete":[{"price":"313.29","symbol":"LTCUSDT","id":"3132900","side":"Sell"},{"price":"313.26","symbol":"LTCUSDT","id":"3132600","side":"Sell"},{"price":"313.32","symbol":"LTCUSDT","id":"3133200","side":"Sell"},{"price":"313.27","symbol":"LTCUSDT","id":"3132700","side":"Sell"},{"price":"313.28","symbol":"LTCUSDT","id":"3132800","side":"Sell"},{"price":"313.31","symbol":"LTCUSDT","id":"3133100","side":"Sell"},{"price":"313.24","symbol":"LTCUSDT","id":"3132400","side":"Sell"},{"price":"313.25","symbol":"LTCUSDT","id":"3132500","side":"Sell"},{"price":"313.30","symbol":"LTCUSDT","id":"3133000","side":"Sell"},{"price":"313.33","symbol":"LTCUSDT","id":"3133300","side":"Sell"}],"update":[{"price":"313.38","symbol":"LTCUSDT","id":"3133800","side":"Sell","size":147.8},{"price":"313.40","symbol":"LTCUSDT","id":"3134000","side":"Sell","size":137.5},{"price":"313.39","symbol":"LTCUSDT","id":"3133900","side":"Sell","size":45.100002},{"price":"313.34","symbol":"LTCUSDT","id":"3133400","side":"Sell","size":117.799995},{"price":"313.37","symbol":"LTCUSDT","id":"3133700","side":"Sell","size":86.50001},{"price":"313.35","symbol":"LTCUSDT","id":"3133500","side":"Sell","size":119.3},{"price":"313.41","symbol":"LTCUSDT","id":"3134100","side":"Sell","size":101.2}],"insert":[{"price":"313.53","symbol":"LTCUSDT","id":"3135300","side":"Sell","size":96.9},{"price":"313.52","symbol":"LTCUSDT","id":"3135200","side":"Sell","size":11.3},{"price":"313.50","symbol":"LTCUSDT","id":"3135000","side":"Sell","size":105.49999},{"price":"313.51","symbol":"LTCUSDT","id":"3135100","side":"Sell","size":17.9},{"price":"313.54","symbol":"LTCUSDT","id":"3135400","side":"Sell","size":84.600006},{"price":"313.55","symbol":"LTCUSDT","id":"3135500","side":"Sell","size":37.6},{"price":"313.48","symbol":"LTCUSDT","id":"3134800","side":"Sell","size":47.699997},{"price":"313.56","symbol":"LTCUSDT","id":"3135600","side":"Sell","size":171.8},{"price":"313.57","symbol":"LTCUSDT","id":"3135700","side":"Sell","size":122.8},{"price":"313.49","symbol":"LTCUSDT","id":"3134900","side":"Sell","size":95.600006}]},"cross_seq":"1684522943","timestamp_e6":"1618677791238188"}
1618677791.329952: {"topic":"orderBookL2_25.LINKUSDT","type":"delta","data":{"delete":[{"price":"41.050","symbol":"LINKUSDT","id":"410500","side":"Sell"},{"price":"41.058","symbol":"LINKUSDT","id":"410580","side":"Sell"},{"price":"41.020","symbol":"LINKUSDT","id":"410200","side":"Buy"},{"price":"41.051","symbol":"LINKUSDT","id":"410510","side":"Sell"},{"price":"41.053","symbol":"LINKUSDT","id":"410530","side":"Sell"},{"price":"41.052","symbol":"LINKUSDT","id":"410520","side":"Sell"},{"price":"41.048","symbol":"LINKUSDT","id":"410480","side":"Sell"},{"price":"41.049","symbol":"LINKUSDT","id":"410490","side":"Sell"},{"price":"41.018","symbol":"LINKUSDT","id":"410180","side":"Buy"},{"price":"41.019","symbol":"LINKUSDT","id":"410190","side":"Buy"},{"price":"41.017","symbol":"LINKUSDT","id":"410170","side":"Buy"},{"price":"41.047","symbol":"LINKUSDT","id":"410470","side":"Sell"}],"update":[{"price":"41.056","symbol":"LINKUSDT","id":"410560","side":"Sell","size":353},{"price":"41.037","symbol":"LINKUSDT","id":"410370","side":"Buy","size":242.59999},{"price":"41.059","symbol":"LINKUSDT","id":"410590","side":"Sell","size":413.2},{"price":"41.042","symbol":"LINKUSDT","id":"410420","side":"Buy","size":169.20001},{"price":"41.055","symbol":"LINKUSDT","id":"410550","side":"Sell","size":413.2},{"price":"41.036","symbol":"LINKUSDT","id":"410360","side":"Buy","size":427},{"price":"41.031","symbol":"LINKUSDT","id":"410310","side":"Buy","size":148.7},{"price":"41.061","symbol":"LINKUSDT","id":"410610","side":"Sell","size":336.4},{"price":"41.043","symbol":"LINKUSDT","id":"410430","side":"Buy","size":143.7},{"price":"41.045","symbol":"LINKUSDT","id":"410450","side":"Buy","size":756.39996},{"price":"41.062","symbol":"LINKUSDT","id":"410620","side":"Sell","size":300.3},{"price":"41.060","symbol":"LINKUSDT","id":"410600","side":"Sell","size":353},{"price":"41.046","symbol":"LINKUSDT","id":"410460","side":"Sell","size":250},{"price":"41.032","symbol":"LINKUSDT","id":"410320","side":"Buy","size":548.80005},{"price":"41.034","symbol":"LINKUSDT","id":"410340","side":"Buy","size":338.2},{"price":"41.033","symbol":"LINKUSDT","id":"410330","side":"Buy","size":1078.3}],"insert":[{"price":"41.044","symbol":"LINKUSDT","id":"410440","side":"Buy","size":267.6},{"price":"41.041","symbol":"LINKUSDT","id":"410410","side":"Buy","size":78.8},{"price":"41.073","symbol":"LINKUSDT","id":"410730","side":"Sell","size":132.2},{"price":"41.076","symbol":"LINKUSDT","id":"410760","side":"Sell","size":461.3},{"price":"41.077","symbol":"LINKUSDT","id":"410770","side":"Sell","size":534.9},{"price":"41.039","symbol":"LINKUSDT","id":"410390","side":"Buy","size":198.3},{"price":"41.075","symbol":"LINKUSDT","id":"410750","side":"Sell","size":8.3},{"price":"41.038","symbol":"LINKUSDT","id":"410380","side":"Buy","size":25},{"price":"41.054","symbol":"LINKUSDT","id":"410540","side":"Sell","size":391.6},{"price":"41.074","symbol":"LINKUSDT","id":"410740","side":"Sell","size":180.90001},{"price":"41.072","symbol":"LINKUSDT","id":"410720","side":"Sell","size":188.3},{"price":"41.078","symbol":"LINKUSDT","id":"410780","side":"Sell","size":418.9}]},"cross_seq":"1970979932","timestamp_e6":"1618677791245370"}
1618677791.3319669: {"topic":"orderBookL2_25.ETHUSDT","type":"delta","data":{"delete":[{"price":"2363.25","symbol":"ETHUSDT","id":"23632500","side":"Buy"},{"price":"2363.20","symbol":"ETHUSDT","id":"23632000","side":"Buy"},{"price":"2363.30","symbol":"ETHUSDT","id":"23633000","side":"Buy"}],"update":[{"price":"2364.00","symbol":"ETHUSDT","id":"23640000","side":"Buy","size":69.86},{"price":"2364.10","symbol":"ETHUSDT","id":"23641000","side":"Buy","size":108.990005},{"price":"2365.00","symbol":"ETHUSDT","id":"23650000","side":"Sell","size":239.6},{"price":"2365.20","symbol":"ETHUSDT","id":"23652000","side":"Sell","size":162.31},{"price":"2364.05","symbol":"ETHUSDT","id":"23640500","side":"Buy","size":66.88},{"price":"2365.15","symbol":"ETHUSDT","id":"23651500","side":"Sell","size":175.59},{"price":"2364.20","symbol":"ETHUSDT","id":"23642000","side":"Buy","size":132.18},{"price":"2364.40","symbol":"ETHUSDT","id":"23644000","side":"Buy","size":88.100006},{"price":"2364.15","symbol":"ETHUSDT","id":"23641500","side":"Buy","size":21.859999},{"price":"2363.95","symbol":"ETHUSDT","id":"23639500","side":"Buy","size":54.1},{"price":"2365.10","symbol":"ETHUSDT","id":"23651000","side":"Sell","size":179.95},{"price":"2364.95","symbol":"ETHUSDT","id":"23649500","side":"Sell","size":409.88}],"insert":[{"price":"2364.25","symbol":"ETHUSDT","id":"23642500","side":"Buy","size":24.710001},{"price":"2364.35","symbol":"ETHUSDT","id":"23643500","side":"Buy","size":48.210003},{"price":"2364.30","symbol":"ETHUSDT","id":"23643000","side":"Buy","size":46.460003}]},"cross_seq":"1800546540","timestamp_e6":"1618677791247539"}
1618677791.3390431: {"topic":"orderBookL2_25.XTZUSDT","type":"delta","data":{"delete":[],"update":[{"price":"7.208","symbol":"XTZUSDT","id":"72080","side":"Buy","size":3423.3},{"price":"7.209","symbol":"XTZUSDT","id":"72090","side":"Buy","size":1664.3},{"price":"7.205","symbol":"XTZUSDT","id":"72050","side":"Buy","size":4489.9},{"price":"7.206","symbol":"XTZUSDT","id":"72060","side":"Buy","size":2427.6}],"insert":[]},"cross_seq":"726228434","timestamp_e6":"1618677791255524"}
1618677791.3487082: {"topic":"orderBookL2_25.LINKUSDT","type":"delta","data":{"delete":[{"price":"41.062","symbol":"LINKUSDT","id":"410620","side":"Sell"},{"price":"41.055","symbol":"LINKUSDT","id":"410550","side":"Sell"},{"price":"41.054","symbol":"LINKUSDT","id":"410540","side":"Sell"}],"update":[{"price":"41.039","symbol":"LINKUSDT","id":"410390","side":"Buy","size":199.70001},{"price":"41.036","symbol":"LINKUSDT","id":"410360","side":"Buy","size":427.9},{"price":"41.042","symbol":"LINKUSDT","id":"410420","side":"Buy","size":170.5},{"price":"41.056","symbol":"LINKUSDT","id":"410560","side":"Sell","size":1}],"insert":[{"price":"41.079","symbol":"LINKUSDT","id":"410790","side":"Sell","size":350.5},{"price":"41.050","symbol":"LINKUSDT","id":"410500","side":"Sell","size":1},{"price":"41.053","symbol":"LINKUSDT","id":"410530","side":"Sell","size":1.1}]},"cross_seq":"1970979958","timestamp_e6":"1618677791263678"}
1618677791.351926: {"topic":"orderBookL2_25.ETHUSDT","type":"delta","data":{"delete":[],"update":[{"price":"2364.90","symbol":"ETHUSDT","id":"23649000","side":"Buy","size":121.490005}],"insert":[]},"cross_seq":"1800546541","timestamp_e6":"1618677791268862"}
1618677791.362803: {"topic":"orderBookL2_25.LTCUSDT","type":"delta","data":{"delete":[{"price":"313.34","symbol":"LTCUSDT","id":"3133400","side":"Sell"},{"price":"313.17","symbol":"LTCUSDT","id":"3131700","side":"Buy"},{"price":"313.15","symbol":"LTCUSDT","id":"3131500","side":"Buy"},{"price":"313.14","symbol":"LTCUSDT","id":"3131400","side":"Buy"}],"update":[{"price":"313.39","symbol":"LTCUSDT","id":"3133900","side":"Sell","size":60.5},{"price":"313.36","symbol":"LTCUSDT","id":"3133600","side":"Sell","size":161.1},{"price":"313.37","symbol":"LTCUSDT","id":"3133700","side":"Sell","size":118.00001}],"insert":[{"price":"312.78","symbol":"LTCUSDT","id":"3127800","side":"Buy","size":44.999996},{"price":"313.58","symbol":"LTCUSDT","id":"3135800","side":"Sell","size":185.20001},{"price":"312.75","symbol":"LTCUSDT","id":"3127500","side":"Buy","size":101.49999},{"price":"312.80","symbol":"LTCUSDT","id":"3128000","side":"Buy","size":115.899994}]},"cross_seq":"1684522951","timestamp_e6":"1618677791277938"}
1618677791.368042: {"topic":"orderBookL2_25.LINKUSDT","type":"delta","data":{"delete":[{"price":"41.060","symbol":"LINKUSDT","id":"410600","side":"Sell"},{"price":"41.079","symbol":"LINKUSDT","id":"410790","side":"Sell"}],"update":[{"price":"41.059","symbol":"LINKUSDT","id":"410590","side":"Sell","size":340.1},{"price":"41.056","symbol":"LINKUSDT","id":"410560","side":"Sell","size":414.2}],"insert":[{"price":"41.058","symbol":"LINKUSDT","id":"410580","side":"Sell","size":336.4},{"price":"41.055","symbol":"LINKUSDT","id":"410550","side":"Sell","size":391.6}]},"cross_seq":"1970979964","timestamp_e6":"1618677791283759"}
1618677791.3744671: {"topic":"orderBookL2_25.BCHUSDT","type":"delta","data":{"delete":[{"price":"1055.40","symbol":"BCHUSDT","id":"10554000","side":"Sell"}],"update":[{"price":"1054.90","symbol":"BCHUSDT","id":"10549000","side":"Buy","size":14.53}],"insert":[{"price":"1055.25","symbol":"BCHUSDT","id":"10552500","side":"Sell","size":8.39}]},"cross_seq":"864132674","timestamp_e6":"1618677791289991"}
1618677791.3834429: {"topic":"orderBookL2_25.LTCUSDT","type":"delta","data":{"delete":[{"price":"312.78","symbol":"LTCUSDT","id":"3127800","side":"Buy"},{"price":"312.75","symbol":"LTCUSDT","id":"3127500","side":"Buy"},{"price":"312.80","symbol":"LTCUSDT","id":"3128000","side":"Buy"}],"update":[{"price":"313.37","symbol":"LTCUSDT","id":"3133700","side":"Sell","size":167.4},{"price":"313.39","symbol":"LTCUSDT","id":"3133900","side":"Sell","size":113.9},{"price":"313.41","symbol":"LTCUSDT","id":"3134100","side":"Sell","size":126.200005},{"price":"313.40","symbol":"LTCUSDT","id":"3134000","side":"Sell","size":78.6},{"price":"313.36","symbol":"LTCUSDT","id":"3133600","side":"Sell","size":81.799995}],"insert":[{"price":"313.14","symbol":"LTCUSDT","id":"3131400","side":"Buy","size":54.7},{"price":"313.17","symbol":"LTCUSDT","id":"3131700","side":"Buy","size":108.4},{"price":"313.15","symbol":"LTCUSDT","id":"3131500","side":"Buy","size":101.49999}]},"cross_seq":"1684522969","timestamp_e6":"1618677791297893"}
1618677791.387272: {"topic":"orderBookL2_25.DOTUSDT","type":"delta","data":{"delete":[{"price":"43.510","symbol":"DOTUSDT","id":"435100","side":"Buy"},{"price":"43.520","symbol":"DOTUSDT","id":"435200","side":"Buy"}],"update":[{"price":"43.535","symbol":"DOTUSDT","id":"435350","side":"Buy","size":819.39996},{"price":"43.555","symbol":"DOTUSDT","id":"435550","side":"Sell","size":511.7}],"insert":[{"price":"43.515","symbol":"DOTUSDT","id":"435150","side":"Buy","size":443.9},{"price":"43.395","symbol":"DOTUSDT","id":"433950","side":"Buy","size":308.9}]},"cross_seq":"916954203","timestamp_e6":"1618677791302373"}
1618677791.3873851: {"topic":"orderBookL2_25.LINKUSDT","type":"delta","data":{"delete":[],"update":[{"price":"41.046","symbol":"LINKUSDT","id":"410460","side":"Sell","size":66}],"insert":[]},"cross_seq":"1970979972","timestamp_e6":"1618677791304039"}
1618677791.393578: {"topic":"orderBookL2_25.BCHUSDT","type":"delta","data":{"delete":[{"price":"1056.50","symbol":"BCHUSDT","id":"10565000","side":"Sell"},{"price":"1055.35","symbol":"BCHUSDT","id":"10553500","side":"Sell"},{"price":"1056.45","symbol":"BCHUSDT","id":"10564500","side":"Sell"},{"price":"1053.65","symbol":"BCHUSDT","id":"10536500","side":"Buy"}],"update":[{"price":"1054.80","symbol":"BCHUSDT","id":"10548000","side":"Buy","size":15.150001},{"price":"1054.85","symbol":"BCHUSDT","id":"10548500","side":"Buy","size":14.27},{"price":"1054.75","symbol":"BCHUSDT","id":"10547500","side":"Buy","size":7.84},{"price":"1054.70","symbol":"BCHUSDT","id":"10547000","side":"Buy","size":8.8}],"insert":[{"price":"1055.30","symbol":"BCHUSDT","id":"10553000","side":"Sell","size":5.55},{"price":"1054.95","symbol":"BCHUSDT","id":"10549500","side":"Buy","size":17.02},{"price":"1055.15","symbol":"BCHUSDT","id":"10551500","side":"Sell","size":13.910001},{"price":"1055.20","symbol":"BCHUSDT","id":"10552000","side":"Sell","size":11.96}]},"cross_seq":"864132684","timestamp_e6":"1618677791310026"}
1618677791.397794: {"topic":"orderBookL2_25.XTZUSDT","type":"delta","data":{"delete":[],"update":[{"price":"7.220","symbol":"XTZUSDT","id":"72200","side":"Sell","size":2243.9001}],"insert":[]},"cross_seq":"726228435","timestamp_e6":"1618677791314696"}
1618677791.4042828: {"topic":"orderBookL2_25.LTCUSDT","type":"delta","data":{"delete":[],"update":[{"price":"313.18","symbol":"LTCUSDT","id":"3131800","side":"Buy","size":391.9}],"insert":[]},"cross_seq":"1684522970","timestamp_e6":"1618677791319190"}
1618677791.406431: {"topic":"orderBookL2_25.DOTUSDT","type":"delta","data":{"delete":[],"update":[{"price":"43.540","symbol":"DOTUSDT","id":"435400","side":"Sell","size":1204.5},{"price":"43.555","symbol":"DOTUSDT","id":"435550","side":"Sell","size":521.7}],"insert":[]},"cross_seq":"916954206","timestamp_e6":"1618677791322338"}
1618677791.4065018: {"topic":"orderBookL2_25.LINKUSDT","type":"delta","data":{"delete":[{"price":"41.057","symbol":"LINKUSDT","id":"410570","side":"Sell"},{"price":"41.059","symbol":"LINKUSDT","id":"410590","side":"Sell"},{"price":"41.061","symbol":"LINKUSDT","id":"410610","side":"Sell"},{"price":"41.058","symbol":"LINKUSDT","id":"410580","side":"Sell"}],"update":[{"price":"41.053","symbol":"LINKUSDT","id":"410530","side":"Sell","size":414.3},{"price":"41.056","symbol":"LINKUSDT","id":"410560","side":"Sell","size":1}],"insert":[{"price":"41.054","symbol":"LINKUSDT","id":"410540","side":"Sell","size":353},{"price":"41.060","symbol":"LINKUSDT","id":"410600","side":"Sell","size":35.100002},{"price":"41.062","symbol":"LINKUSDT","id":"410620","side":"Sell","size":45.100002},{"price":"41.052","symbol":"LINKUSDT","id":"410520","side":"Sell","size":391.6}]},"cross_seq":"1970979988","timestamp_e6":"1618677791323663"}
1618677791.40843: {"topic":"orderBookL2_25.UNIUSDT","type":"delta","data":{"delete":[{"price":"35.360","symbol":"UNIUSDT","id":"353600","side":"Buy"}],"update":[],"insert":[{"price":"35.391","symbol":"UNIUSDT","id":"353910","side":"Buy","size":417.09998}]},"cross_seq":"916954206","timestamp_e6":"1618677791322502"}
1618677791.411926: {"topic":"orderBookL2_25.BCHUSDT","type":"delta","data":{"delete":[],"update":[{"price":"1055.65","symbol":"BCHUSDT","id":"10556500","side":"Sell","size":22.03}],"insert":[]},"cross_seq":"864132694","timestamp_e6":"1618677791328714"}
1618677791.426668: {"topic":"orderBookL2_25.DOTUSDT","type":"delta","data":{"delete":[{"price":"43.515","symbol":"DOTUSDT","id":"435150","side":"Buy"},{"price":"43.530","symbol":"DOTUSDT","id":"435300","side":"Buy"}],"update":[{"price":"43.570","symbol":"DOTUSDT","id":"435700","side":"Sell","size":444.9},{"price":"43.555","symbol":"DOTUSDT","id":"435550","side":"Sell","size":709.2},{"price":"43.550","symbol":"DOTUSDT","id":"435500","side":"Sell","size":734.3}],"insert":[{"price":"43.520","symbol":"DOTUSDT","id":"435200","side":"Buy","size":428.4},{"price":"43.510","symbol":"DOTUSDT","id":"435100","side":"Buy","size":443.9}]},"cross_seq":"916954216","timestamp_e6":"1618677791342366"}
1618677791.4306638: {"topic":"orderBookL2_25.LINKUSDT","type":"delta","data":{"delete":[],"update":[{"price":"41.045","symbol":"LINKUSDT","id":"410450","side":"Buy","size":1006.39996}],"insert":[]},"cross_seq":"1970979989","timestamp_e6":"1618677791344895"}
1618677791.431458: {"topic":"orderBookL2_25.BCHUSDT","type":"delta","data":{"delete":[{"price":"1056.35","symbol":"BCHUSDT","id":"10563500","side":"Sell"},{"price":"1056.40","symbol":"BCHUSDT","id":"10564000","side":"Sell"}],"update":[{"price":"1055.50","symbol":"BCHUSDT","id":"10555000","side":"Sell","size":5.55},{"price":"1055.65","symbol":"BCHUSDT","id":"10556500","side":"Sell","size":19.04},{"price":"1055.45","symbol":"BCHUSDT","id":"10554500","side":"Sell","size":8.39},{"price":"1055.60","symbol":"BCHUSDT","id":"10556000","side":"Sell","size":11.9},{"price":"1055.75","symbol":"BCHUSDT","id":"10557500","side":"Sell","size":3.39},{"price":"1055.70","symbol":"BCHUSDT","id":"10557000","side":"Sell","size":11.39}],"insert":[{"price":"1055.35","symbol":"BCHUSDT","id":"10553500","side":"Sell","size":13.910001},{"price":"1055.40","symbol":"BCHUSDT","id":"10554000","side":"Sell","size":11.96}]},"cross_seq":"864132706","timestamp_e6":"1618677791348704"}
1618677791.445098: {"topic":"orderBookL2_25.LTCUSDT","type":"delta","data":{"delete":[],"update":[{"price":"313.51","symbol":"LTCUSDT","id":"3135100","side":"Sell","size":37.4},{"price":"313.42","symbol":"LTCUSDT","id":"3134200","side":"Sell","size":113.99999},{"price":"313.40","symbol":"LTCUSDT","id":"3134000","side":"Sell","size":158.9},{"price":"313.41","symbol":"LTCUSDT","id":"3134100","side":"Sell","size":98.200005},{"price":"313.39","symbol":"LTCUSDT","id":"3133900","side":"Sell","size":100.100006},{"price":"313.43","symbol":"LTCUSDT","id":"3134300","side":"Sell","size":120.9},{"price":"313.18","symbol":"LTCUSDT","id":"3131800","side":"Buy","size":641.9},{"price":"313.44","symbol":"LTCUSDT","id":"3134400","side":"Sell","size":57.8}],"insert":[]},"cross_seq":"1684523025","timestamp_e6":"1618677791360998"}
1618677791.445833: {"topic":"orderBookL2_25.DOTUSDT","type":"delta","data":{"delete":[{"price":"43.395","symbol":"DOTUSDT","id":"433950","side":"Buy"},{"price":"43.400","symbol":"DOTUSDT","id":"434000","side":"Buy"}],"update":[{"price":"43.565","symbol":"DOTUSDT","id":"435650","side":"Sell","size":451.2},{"price":"43.570","symbol":"DOTUSDT","id":"435700","side":"Sell","size":367.3},{"price":"43.555","symbol":"DOTUSDT","id":"435550","side":"Sell","size":642.10004},{"price":"43.560","symbol":"DOTUSDT","id":"435600","side":"Sell","size":667},{"price":"43.540","symbol":"DOTUSDT","id":"435400","side":"Sell","size":450},{"price":"43.535","symbol":"DOTUSDT","id":"435350","side":"Buy","size":211.99998},{"price":"43.545","symbol":"DOTUSDT","id":"435450","side":"Sell","size":498}],"insert":[{"price":"43.515","symbol":"DOTUSDT","id":"435150","side":"Buy","size":356.2},{"price":"43.530","symbol":"DOTUSDT","id":"435300","side":"Buy","size":607.4}]},"cross_seq":"916954227","timestamp_e6":"1618677791362517"}
1618677791.446302: {"topic":"orderBookL2_25.ADAUSDT","type":"delta","data":{"delete":[],"update":[{"price":"1.3876","symbol":"ADAUSDT","id":"13876","side":"Sell","size":4242}],"insert":[]},"cross_seq":"916954227","timestamp_e6":"1618677791362381"}
1618677791.466092: {"topic":"orderBookL2_25.LTCUSDT","type":"delta","data":{"delete":[],"update":[{"price":"313.40","symbol":"LTCUSDT","id":"3134000","side":"Sell","size":137.6}],"insert":[]},"cross_seq":"1684523028","timestamp_e6":"1618677791378823"}
1618677791.4667861: {"topic":"orderBookL2_25.LINKUSDT","type":"delta","data":{"delete":[],"update":[{"price":"41.065","symbol":"LINKUSDT","id":"410650","side":"Sell","size":405.30002},{"price":"41.034","symbol":"LINKUSDT","id":"410340","side":"Buy","size":91.2},{"price":"41.029","symbol":"LINKUSDT","id":"410290","side":"Buy","size":44},{"price":"41.032","symbol":"LINKUSDT","id":"410320","side":"Buy","size":478.59998},{"price":"41.073","symbol":"LINKUSDT","id":"410730","side":"Sell","size":194.40001},{"price":"41.070","symbol":"LINKUSDT","id":"410700","side":"Sell","size":89},{"price":"41.066","symbol":"LINKUSDT","id":"410660","side":"Sell","size":643},{"price":"41.033","symbol":"LINKUSDT","id":"410330","side":"Buy","size":1015.9},{"price":"41.031","symbol":"LINKUSDT","id":"410310","side":"Buy","size":129.9},{"price":"41.068","symbol":"LINKUSDT","id":"410680","side":"Sell","size":348.8},{"price":"41.069","symbol":"LINKUSDT","id":"410690","side":"Sell","size":196.90001},{"price":"41.030","symbol":"LINKUSDT","id":"410300","side":"Buy","size":172.90001},{"price":"41.067","symbol":"LINKUSDT","id":"410670","side":"Sell","size":293}],"insert":[]},"cross_seq":"1970980008","timestamp_e6":"1618677791383686"}
1618677791.468367: {"topic":"orderBookL2_25.DOTUSDT","type":"delta","data":{"delete":[{"price":"43.540","symbol":"DOTUSDT","id":"435400","side":"Sell"}],"update":[{"price":"43.535","symbol":"DOTUSDT","id":"435350","side":"Buy","size":512}],"insert":[{"price":"43.665","symbol":"DOTUSDT","id":"436650","side":"Sell","size":75.1}]},"cross_seq":"916954229","timestamp_e6":"1618677791383611"}
1618677791.483706: {"topic":"orderBookL2_25.LTCUSDT","type":"delta","data":{"delete":[],"update":[{"price":"313.36","symbol":"LTCUSDT","id":"3133600","side":"Sell","size":1.5},{"price":"313.35","symbol":"LTCUSDT","id":"3133500","side":"Sell","size":1.5},{"price":"313.42","symbol":"LTCUSDT","id":"3134200","side":"Sell","size":71.2},{"price":"313.41","symbol":"LTCUSDT","id":"3134100","side":"Sell","size":153.20001},{"price":"313.38","symbol":"LTCUSDT","id":"3133800","side":"Sell","size":178.5},{"price":"313.37","symbol":"LTCUSDT","id":"3133700","side":"Sell","size":243.09999},{"price":"313.40","symbol":"LTCUSDT","id":"3134000","side":"Sell","size":57.3}],"insert":[]},"cross_seq":"1684523047","timestamp_e6":"1618677791400056"}
1618677791.48794: {"topic":"orderBookL2_25.DOTUSDT","type":"delta","data":{"delete":[{"price":"43.510","symbol":"DOTUSDT","id":"435100","side":"Buy"},{"price":"43.520","symbol":"DOTUSDT","id":"435200","side":"Buy"}],"update":[{"price":"43.570","symbol":"DOTUSDT","id":"435700","side":"Sell","size":444.9},{"price":"43.565","symbol":"DOTUSDT","id":"435650","side":"Sell","size":296.4},{"price":"43.550","symbol":"DOTUSDT","id":"435500","side":"Sell","size":418.40002},{"price":"43.535","symbol":"DOTUSDT","id":"435350","side":"Buy","size":1119.4},{"price":"43.560","symbol":"DOTUSDT","id":"435600","side":"Sell","size":805.89996}],"insert":[{"price":"43.395","symbol":"DOTUSDT","id":"433950","side":"Buy","size":308.9},{"price":"43.400","symbol":"DOTUSDT","id":"434000","side":"Buy","size":1.2}]},"cross_seq":"916954254","timestamp_e6":"1618677791402341"}
1618677791.490207: {"topic":"orderBookL2_25.ETHUSDT","type":"delta","data":{"delete":[{"price":"2364.25","symbol":"ETHUSDT","id":"23642500","side":"Buy"}],"update":[{"price":"2365.15","symbol":"ETHUSDT","id":"23651500","side":"Sell","size":191.5},{"price":"2364.40","symbol":"ETHUSDT","id":"23644000","side":"Buy","size":1.19},{"price":"2364.35","symbol":"ETHUSDT","id":"23643500","side":"Buy","size":72.53},{"price":"2365.00","symbol":"ETHUSDT","id":"23650000","side":"Sell","size":267.28},{"price":"2365.10","symbol":"ETHUSDT","id":"23651000","side":"Sell","size":226.20999}],"insert":[{"price":"2364.45","symbol":"ETHUSDT","id":"23644500","side":"Buy","size":95.439995}]},"cross_seq":"1800546557","timestamp_e6":"1618677791407053"}
1618677791.493655: {"topic":"orderBookL2_25.BCHUSDT","type":"delta","data":{"delete":[],"update":[{"price":"1056.15","symbol":"BCHUSDT","id":"10561500","side":"Sell","size":5.33}],"insert":[]},"cross_seq":"864132712","timestamp_e6":"1618677791409413"}
1618677791.497931: {"topic":"orderBookL2_25.XTZUSDT","type":"delta","data":{"delete":[],"update":[{"price":"7.225","symbol":"XTZUSDT","id":"72250","side":"Sell","size":2657.0999},{"price":"7.218","symbol":"XTZUSDT","id":"72180","side":"Sell","size":1737.4999}],"insert":[]},"cross_seq":"726228437","timestamp_e6":"1618677791414655"}
1618677791.507676: {"topic":"orderBookL2_25.ADAUSDT","type":"delta","data":{"delete":[{"price":"1.3866","symbol":"ADAUSDT","id":"13866","side":"Buy"}],"update":[{"price":"1.3878","symbol":"ADAUSDT","id":"13878","side":"Sell","size":9419},{"price":"1.3877","symbol":"ADAUSDT","id":"13877","side":"Sell","size":2055},{"price":"1.3867","symbol":"ADAUSDT","id":"13867","side":"Buy","size":2001},{"price":"1.3881","symbol":"ADAUSDT","id":"13881","side":"Sell","size":3703}],"insert":[{"price":"1.3843","symbol":"ADAUSDT","id":"13843","side":"Buy","size":5092}]},"cross_seq":"916954263","timestamp_e6":"1618677791422405"}
1618677791.507788: {"topic":"orderBookL2_25.DOTUSDT","type":"delta","data":{"delete":[{"price":"43.395","symbol":"DOTUSDT","id":"433950","side":"Buy"}],"update":[{"price":"43.535","symbol":"DOTUSDT","id":"435350","side":"Buy","size":723.39996}],"insert":[{"price":"43.540","symbol":"DOTUSDT","id":"435400","side":"Buy","size":195.99998}]},"cross_seq":"916954263","timestamp_e6":"1618677791423851"}
1618677791.526735: {"topic":"orderBookL2_25.DOTUSDT","type":"delta","data":{"delete":[],"update":[{"price":"43.540","symbol":"DOTUSDT","id":"435400","side":"Buy","size":292},{"price":"43.535","symbol":"DOTUSDT","id":"435350","side":"Buy","size":627.4}],"insert":[]},"cross_seq":"916954265","timestamp_e6":"1618677791442327"}
1618677791.54413: {"topic":"orderBookL2_25.LTCUSDT","type":"delta","data":{"delete":[],"update":[{"price":"313.44","symbol":"LTCUSDT","id":"3134400","side":"Sell","size":133.6},{"price":"313.37","symbol":"LTCUSDT","id":"3133700","side":"Sell","size":107.2},{"price":"313.41","symbol":"LTCUSDT","id":"3134100","side":"Sell","size":118.00001},{"price":"313.39","symbol":"LTCUSDT","id":"3133900","side":"Sell","size":46.7},{"price":"313.42","symbol":"LTCUSDT","id":"3134200","side":"Sell","size":144.6},{"price":"313.45","symbol":"LTCUSDT","id":"3134500","side":"Sell","size":58.5},{"price":"313.40","symbol":"LTCUSDT","id":"3134000","side":"Sell","size":164.5},{"price":"313.38","symbol":"LTCUSDT","id":"3133800","side":"Sell","size":80.3},{"price":"313.43","symbol":"LTCUSDT","id":"3134300","side":"Sell","size":55.000004}],"insert":[]},"cross_seq":"1684523069","timestamp_e6":"1618677791457915"}
1618677791.547505: {"topic":"orderBookL2_25.DOTUSDT","type":"delta","data":{"delete":[],"update":[{"price":"43.580","symbol":"DOTUSDT","id":"435800","side":"Sell","size":34.300003},{"price":"43.540","symbol":"DOTUSDT","id":"435400","side":"Buy","size":302},{"price":"43.535","symbol":"DOTUSDT","id":"435350","side":"Buy","size":617.39996}],"insert":[]},"cross_seq":"916954267","timestamp_e6":"1618677791462322"}
1618677791.5717492: {"topic":"orderBookL2_25.BCHUSDT","type":"delta","data":{"delete":[{"price":"1055.20","symbol":"BCHUSDT","id":"10552000","side":"Sell"},{"price":"1055.15","symbol":"BCHUSDT","id":"10551500","side":"Sell"},{"price":"1055.30","symbol":"BCHUSDT","id":"10553000","side":"Sell"},{"price":"1055.40","symbol":"BCHUSDT","id":"10554000","side":"Sell"},{"price":"1055.25","symbol":"BCHUSDT","id":"10552500","side":"Sell"}],"update":[{"price":"1055.50","symbol":"BCHUSDT","id":"10555000","side":"Sell","size":8.39},{"price":"1055.45","symbol":"BCHUSDT","id":"10554500","side":"Sell","size":11.96},{"price":"1055.60","symbol":"BCHUSDT","id":"10556000","side":"Sell","size":14.26},{"price":"1055.55","symbol":"BCHUSDT","id":"10555500","side":"Sell","size":5.55}],"insert":[{"price":"1056.55","symbol":"BCHUSDT","id":"10565500","side":"Sell","size":10.5},{"price":"1056.40","symbol":"BCHUSDT","id":"10564000","side":"Sell","size":1},{"price":"1056.35","symbol":"BCHUSDT","id":"10563500","side":"Sell","size":15.590001},{"price":"1056.45","symbol":"BCHUSDT","id":"10564500","side":"Sell","size":16.609999},{"price":"1056.50","symbol":"BCHUSDT","id":"10565000","side":"Sell","size":30.32}]},"cross_seq":"864132721","timestamp_e6":"1618677791488738"}
1618677791.581537: {"topic":"orderBookL2_25.LTCUSDT","type":"delta","data":{"delete":[{"price":"313.19","symbol":"LTCUSDT","id":"3131900","side":"Sell"}],"update":[],"insert":[{"price":"313.59","symbol":"LTCUSDT","id":"3135900","side":"Sell","size":30.4}]},"cross_seq":"1684523070","timestamp_e6":"1618677791499079"}
1618677791.5923269: {"topic":"orderBookL2_25.ETHUSDT","type":"delta","data":{"delete":[{"price":"2363.35","symbol":"ETHUSDT","id":"23633500","side":"Buy"}],"update":[{"price":"2364.30","symbol":"ETHUSDT","id":"23643000","side":"Buy","size":48.98},{"price":"2364.20","symbol":"ETHUSDT","id":"23642000","side":"Buy","size":176.15999},{"price":"2364.15","symbol":"ETHUSDT","id":"23641500","side":"Buy","size":43.3},{"price":"2364.95","symbol":"ETHUSDT","id":"23649500","side":"Sell","size":324.05},{"price":"2364.45","symbol":"ETHUSDT","id":"23644500","side":"Buy","size":96.64},{"price":"2364.10","symbol":"ETHUSDT","id":"23641000","side":"Buy","size":62.530003}],"insert":[{"price":"2364.25","symbol":"ETHUSDT","id":"23642500","side":"Buy","size":61.82}]},"cross_seq":"1800546569","timestamp_e6":"1618677791507500"}
1618677791.5995278: {"topic":"orderBookL2_25.XTZUSDT","type":"delta","data":{"delete":[{"price":"7.210","symbol":"XTZUSDT","id":"72100","side":"Buy"}],"update":[{"price":"7.206","symbol":"XTZUSDT","id":"72060","side":"Buy","size":2881.8},{"price":"7.209","symbol":"XTZUSDT","id":"72090","side":"Buy","size":3530.5}],"insert":[{"price":"7.186","symbol":"XTZUSDT","id":"71860","side":"Buy","size":663.4}]},"cross_seq":"726228440","timestamp_e6":"1618677791514562"}
1618677791.607479: {"topic":"orderBookL2_25.ADAUSDT","type":"delta","data":{"delete":[{"price":"1.3843","symbol":"ADAUSDT","id":"13843","side":"Buy"}],"update":[{"price":"1.3878","symbol":"ADAUSDT","id":"13878","side":"Sell","size":8187.0005},{"price":"1.3879","symbol":"ADAUSDT","id":"13879","side":"Sell","size":5356},{"price":"1.3867","symbol":"ADAUSDT","id":"13867","side":"Buy","size":6260}],"insert":[{"price":"1.3866","symbol":"ADAUSDT","id":"13866","side":"Buy","size":3766}]},"cross_seq":"916954273","timestamp_e6":"1618677791522359"}
1618677791.607544: {"topic":"orderBookL2_25.LINKUSDT","type":"delta","data":{"delete":[{"price":"41.055","symbol":"LINKUSDT","id":"410550","side":"Sell"}],"update":[{"price":"41.053","symbol":"LINKUSDT","id":"410530","side":"Sell","size":1.1},{"price":"41.050","symbol":"LINKUSDT","id":"410500","side":"Sell","size":392.6}],"insert":[{"price":"41.051","symbol":"LINKUSDT","id":"410510","side":"Sell","size":413.2}]},"cross_seq":"1970980014","timestamp_e6":"1618677791523898"}
1618677791.612715: {"topic":"orderBookL2_25.ETHUSDT","type":"delta","data":{"delete":[],"update":[{"price":"2364.90","symbol":"ETHUSDT","id":"23649000","side":"Buy","size":89}],"insert":[]},"cross_seq":"1800546570","timestamp_e6":"1618677791528501"}
1618677791.613683: {"topic":"orderBookL2_25.BCHUSDT","type":"delta","data":{"delete":[{"price":"1055.35","symbol":"BCHUSDT","id":"10553500","side":"Sell"},{"price":"1055.50","symbol":"BCHUSDT","id":"10555000","side":"Sell"}],"update":[{"price":"1055.60","symbol":"BCHUSDT","id":"10556000","side":"Sell","size":20.289999},{"price":"1055.70","symbol":"BCHUSDT","id":"10557000","side":"Sell","size":4.4},{"price":"1055.55","symbol":"BCHUSDT","id":"10555500","side":"Sell","size":11.96},{"price":"1054.95","symbol":"BCHUSDT","id":"10549500","side":"Buy","size":34.59},{"price":"1055.65","symbol":"BCHUSDT","id":"10556500","side":"Sell","size":24.59}],"insert":[{"price":"1056.60","symbol":"BCHUSDT","id":"10566000","side":"Sell","size":14.3},{"price":"1056.65","symbol":"BCHUSDT","id":"10566500","side":"Sell","size":12}]},"cross_seq":"864132733","timestamp_e6":"1618677791530278"}
1618677791.616939: {"topic":"trade.LTCUSDT","data":[{"symbol":"LTCUSDT","tick_direction":"PlusTick","price":"313.19","size":10,"timestamp":"2021-04-17T16:43:11.000Z","trade_time_ms":"1618677791484","side":"Buy","trade_id":"608499f0-98bd-5dbf-9ad7-a87340ba829b"}]}
1618677791.62549: {"topic":"orderBookL2_25.LTCUSDT","type":"delta","data":{"delete":[{"price":"312.94","symbol":"LTCUSDT","id":"3129400","side":"Buy"},{"price":"312.90","symbol":"LTCUSDT","id":"3129000","side":"Buy"},{"price":"312.85","symbol":"LTCUSDT","id":"3128500","side":"Buy"},{"price":"312.96","symbol":"LTCUSDT","id":"3129600","side":"Buy"},{"price":"312.88","symbol":"LTCUSDT","id":"3128800","side":"Buy"},{"price":"313.39","symbol":"LTCUSDT","id":"3133900","side":"Sell"},{"price":"312.91","symbol":"LTCUSDT","id":"3129100","side":"Buy"},{"price":"312.97","symbol":"LTCUSDT","id":"3129700","side":"Buy"},{"price":"312.89","symbol":"LTCUSDT","id":"3128900","side":"Buy"},{"price":"312.99","symbol":"LTCUSDT","id":"3129900","side":"Buy"},{"price":"312.84","symbol":"LTCUSDT","id":"3128400","side":"Buy"},{"price":"313.37","symbol":"LTCUSDT","id":"3133700","side":"Sell"},{"price":"313.38","symbol":"LTCUSDT","id":"3133800","side":"Sell"},{"price":"312.98","symbol":"LTCUSDT","id":"3129800","side":"Buy"}],"update":[{"price":"312.95","symbol":"LTCUSDT","id":"3129500","side":"Buy","size":81.6},{"price":"313.35","symbol":"LTCUSDT","id":"3133500","side":"Sell","size":2.1},{"price":"313.18","symbol":"LTCUSDT","id":"3131800","side":"Buy","size":400.7},{"price":"313.45","symbol":"LTCUSDT","id":"3134500","side":"Sell","size":2}],"insert":[{"price":"313.31","symbol":"LTCUSDT","id":"3133100","side":"Buy","size":101.49999},{"price":"312.78","symbol":"LTCUSDT","id":"3127800","side":"Buy","size":44.999996},{"price":"313.33","symbol":"LTCUSDT","id":"3133300","side":"Buy","size":108.4},{"price":"312.74","symbol":"LTCUSDT","id":"3127400","side":"Buy","size":137.40001},{"price":"313.61","symbol":"LTCUSDT","id":"3136100","side":"Sell","size":256.3},{"price":"313.32","symbol":"LTCUSDT","id":"3133200","side":"Buy","size":110.200005},{"price":"313.30","symbol":"LTCUSDT","id":"3133000","side":"Buy","size":54.7},{"price":"312.75","symbol":"LTCUSDT","id":"3127500","side":"Buy","size":50},{"price":"313.60","symbol":"LTCUSDT","id":"3136000","side":"Sell","size":97.299995},{"price":"313.62","symbol":"LTCUSDT","id":"3136200","side":"Sell","size":229.8},{"price":"313.34","symbol":"LTCUSDT","id":"3133400","side":"Buy","size":295.3},{"price":"313.29","symbol":"LTCUSDT","id":"3132900","side":"Buy","size":58},{"price":"312.80","symbol":"LTCUSDT","id":"3128000","side":"Buy","size":115.899994},{"price":"312.76","symbol":"LTCUSDT","id":"3127600","side":"Buy","size":165.3}]},"cross_seq":"1684523103","timestamp_e6":"1618677791540840"}
1618677791.628424: {"topic":"orderBookL2_25.LINKUSDT","type":"delta","data":{"delete":[],"update":[{"price":"41.064","symbol":"LINKUSDT","id":"410640","side":"Sell","size":311.5},{"price":"41.029","symbol":"LINKUSDT","id":"410290","side":"Buy","size":84.5},{"price":"41.067","symbol":"LINKUSDT","id":"410670","side":"Sell","size":197.00002},{"price":"41.023","symbol":"LINKUSDT","id":"410230","side":"Buy","size":231.6},{"price":"41.069","symbol":"LINKUSDT","id":"410690","side":"Sell","size":39.3},{"price":"41.068","symbol":"LINKUSDT","id":"410680","side":"Sell","size":507.9},{"price":"41.034","symbol":"LINKUSDT","id":"410340","side":"Buy","size":235.7}],"insert":[]},"cross_seq":"1970980027","timestamp_e6":"1618677791543746"}
1618677791.632231: {"topic":"orderBookL2_25.ETHUSDT","type":"delta","data":{"delete":[{"price":"2364.25","symbol":"ETHUSDT","id":"23642500","side":"Buy"}],"update":[{"price":"2364.40","symbol":"ETHUSDT","id":"23644000","side":"Buy","size":63.010002},{"price":"2364.20","symbol":"ETHUSDT","id":"23642000","side":"Buy","size":103.63},{"price":"2364.95","symbol":"ETHUSDT","id":"23649500","side":"Sell","size":373.58}],"insert":[{"price":"2363.35","symbol":"ETHUSDT","id":"23633500","side":"Buy","size":23.73}]},"cross_seq":"1800546589","timestamp_e6":"1618677791548220"}
1618677791.64319: {"topic":"orderBookL2_25.LTCUSDT","type":"delta","data":{"delete":[{"price":"312.75","symbol":"LTCUSDT","id":"3127500","side":"Buy"}],"update":[],"insert":[{"price":"312.71","symbol":"LTCUSDT","id":"3127100","side":"Buy","size":81}]},"cross_seq":"1684523116","timestamp_e6":"1618677791557950"}
1618677791.647557: {"topic":"orderBookL2_25.ADAUSDT","type":"delta","data":{"delete":[{"price":"1.3844","symbol":"ADAUSDT","id":"13844","side":"Buy"}],"update":[{"price":"1.3863","symbol":"ADAUSDT","id":"13863","side":"Buy","size":6870},{"price":"1.3879","symbol":"ADAUSDT","id":"13879","side":"Sell","size":4890},{"price":"1.3866","symbol":"ADAUSDT","id":"13866","side":"Buy","size":954},{"price":"1.3878","symbol":"ADAUSDT","id":"13878","side":"Sell","size":9419}],"insert":[{"price":"1.3862","symbol":"ADAUSDT","id":"13862","side":"Buy","size":3564}]},"cross_seq":"916954295","timestamp_e6":"1618677791562436"}
1618677791.652193: {"topic":"orderBookL2_25.LINKUSDT","type":"delta","data":{"delete":[{"price":"41.052","symbol":"LINKUSDT","id":"410520","side":"Sell"},{"price":"41.076","symbol":"LINKUSDT","id":"410760","side":"Sell"},{"price":"41.073","symbol":"LINKUSDT","id":"410730","side":"Sell"},{"price":"41.077","symbol":"LINKUSDT","id":"410770","side":"Sell"},{"price":"41.074","symbol":"LINKUSDT","id":"410740","side":"Sell"},{"price":"41.075","symbol":"LINKUSDT","id":"410750","side":"Sell"},{"price":"41.051","symbol":"LINKUSDT","id":"410510","side":"Sell"},{"price":"41.078","symbol":"LINKUSDT","id":"410780","side":"Sell"}],"update":[{"price":"41.053","symbol":"LINKUSDT","id":"410530","side":"Sell","size":108.2},{"price":"41.054","symbol":"LINKUSDT","id":"410540","side":"Sell","size":580.60004},{"price":"41.045","symbol":"LINKUSDT","id":"410450","side":"Buy","size":606.4},{"price":"41.046","symbol":"LINKUSDT","id":"410460","side":"Sell","size":466},{"price":"41.056","symbol":"LINKUSDT","id":"410560","side":"Sell","size":19.8}],"insert":[{"price":"41.058","symbol":"LINKUSDT","id":"410580","side":"Sell","size":109},{"price":"41.047","symbol":"LINKUSDT","id":"410470","side":"Sell","size":391.6},{"price":"41.049","symbol":"LINKUSDT","id":"410490","side":"Sell","size":353},{"price":"41.055","symbol":"LINKUSDT","id":"410550","side":"Sell","size":36},{"price":"41.061","symbol":"LINKUSDT","id":"410610","side":"Sell","size":92},{"price":"41.048","symbol":"LINKUSDT","id":"410480","side":"Sell","size":413.2},{"price":"41.057","symbol":"LINKUSDT","id":"410570","side":"Sell","size":327.9},{"price":"41.059","symbol":"LINKUSDT","id":"410590","side":"Sell","size":81.6}]},"cross_seq":"1970980045","timestamp_e6":"1618677791566975"}
1618677791.663039: {"topic":"orderBookL2_25.LTCUSDT","type":"delta","data":{"delete":[],"update":[{"price":"313.18","symbol":"LTCUSDT","id":"3131800","side":"Buy","size":399.2},{"price":"313.30","symbol":"LTCUSDT","id":"3133000","side":"Buy","size":56.199997}],"insert":[]},"cross_seq":"1684523117","timestamp_e6":"1618677791578057"}
1618677791.667048: {"topic":"orderBookL2_25.DOTUSDT","type":"delta","data":{"delete":[],"update":[{"price":"43.535","symbol":"DOTUSDT","id":"435350","side":"Buy","size":607.4},{"price":"43.540","symbol":"DOTUSDT","id":"435400","side":"Buy","size":312}],"insert":[]},"cross_seq":"916954301","timestamp_e6":"1618677791582503"}
1618677791.667093: {"topic":"orderBookL2_25.UNIUSDT","type":"delta","data":{"delete":[],"update":[{"price":"35.410","symbol":"UNIUSDT","id":"354100","side":"Sell","size":112.8},{"price":"35.411","symbol":"UNIUSDT","id":"354110","side":"Sell","size":95.3},{"price":"35.371","symbol":"UNIUSDT","id":"353710","side":"Buy","size":34.300003},{"price":"35.373","symbol":"UNIUSDT","id":"353730","side":"Buy","size":61.8},{"price":"35.372","symbol":"UNIUSDT","id":"353720","side":"Buy","size":6.1}],"insert":[]},"cross_seq":"916954301","timestamp_e6":"1618677791582654"}
1618677791.671435: {"topic":"orderBookL2_25.ETHUSDT","type":"delta","data":{"delete":[],"update":[{"price":"2364.55","symbol":"ETHUSDT","id":"23645500","side":"Buy","size":4.46}],"insert":[]},"cross_seq":"1800546593","timestamp_e6":"1618677791587927"}
1618677791.671474: {"topic":"orderBookL2_25.BCHUSDT","type":"delta","data":{"delete":[],"update":[{"price":"1054.00","symbol":"BCHUSDT","id":"10540000","side":"Buy","size":28.659998},{"price":"1054.85","symbol":"BCHUSDT","id":"10548500","side":"Buy","size":19.769999},{"price":"1053.70","symbol":"BCHUSDT","id":"10537000","side":"Buy","size":13.5},{"price":"1053.85","symbol":"BCHUSDT","id":"10538500","side":"Buy","size":1.99},{"price":"1053.95","symbol":"BCHUSDT","id":"10539500","side":"Buy","size":2.71},{"price":"1053.90","symbol":"BCHUSDT","id":"10539000","side":"Buy","size":3.63},{"price":"1054.10","symbol":"BCHUSDT","id":"10541000","side":"Buy","size":17.04},{"price":"1053.80","symbol":"BCHUSDT","id":"10538000","side":"Buy","size":13.64},{"price":"1053.75","symbol":"BCHUSDT","id":"10537500","side":"Buy","size":6.4},{"price":"1054.05","symbol":"BCHUSDT","id":"10540500","side":"Buy","size":44.989998}],"insert":[]},"cross_seq":"864132758","timestamp_e6":"1618677791588722"}
1618677791.67233: {"topic":"orderBookL2_25.LINKUSDT","type":"delta","data":{"delete":[],"update":[{"price":"41.046","symbol":"LINKUSDT","id":"410460","side":"Sell","size":66}],"insert":[]},"cross_seq":"1970980047","timestamp_e6":"1618677791588686"}
1618677791.683087: {"topic":"orderBookL2_25.LTCUSDT","type":"delta","data":{"delete":[{"price":"312.71","symbol":"LTCUSDT","id":"3127100","side":"Buy"},{"price":"312.76","symbol":"LTCUSDT","id":"3127600","side":"Buy"}],"update":[{"price":"313.41","symbol":"LTCUSDT","id":"3134100","side":"Sell","size":206.2},{"price":"313.44","symbol":"LTCUSDT","id":"3134400","side":"Sell","size":55.000004},{"price":"313.18","symbol":"LTCUSDT","id":"3131800","side":"Buy","size":149.2},{"price":"313.35","symbol":"LTCUSDT","id":"3133500","side":"Sell","size":127.1},{"price":"313.40","symbol":"LTCUSDT","id":"3134000","side":"Sell","size":107.2},{"price":"313.43","symbol":"LTCUSDT","id":"3134300","side":"Sell","size":98.299995},{"price":"313.46","symbol":"LTCUSDT","id":"3134600","side":"Sell","size":1},{"price":"313.45","symbol":"LTCUSDT","id":"3134500","side":"Sell","size":50.2}],"insert":[{"price":"312.77","symbol":"LTCUSDT","id":"3127700","side":"Buy","size":158.1},{"price":"312.75","symbol":"LTCUSDT","id":"3127500","side":"Buy","size":165.9}]},"cross_seq":"1684523133","timestamp_e6":"1618677791599078"}
1618677791.702157: {"topic":"orderBookL2_25.LTCUSDT","type":"delta","data":{"delete":[{"price":"312.75","symbol":"LTCUSDT","id":"3127500","side":"Buy"},{"price":"312.74","symbol":"LTCUSDT","id":"3127400","side":"Buy"}],"update":[{"price":"313.44","symbol":"LTCUSDT","id":"3134400","side":"Sell","size":91.1},{"price":"312.78","symbol":"LTCUSDT","id":"3127800","side":"Buy","size":172.3},{"price":"313.46","symbol":"LTCUSDT","id":"3134600","side":"Sell","size":23.6}],"insert":[{"price":"312.76","symbol":"LTCUSDT","id":"3127600","side":"Buy","size":146.3},{"price":"312.79","symbol":"LTCUSDT","id":"3127900","side":"Buy","size":158.1}]},"cross_seq":"1684523142","timestamp_e6":"1618677791617895"}
1618677791.709004: {"topic":"orderBookL2_25.LINKUSDT","type":"delta","data":{"delete":[],"update":[{"price":"41.053","symbol":"LINKUSDT","id":"410530","side":"Sell","size":107.1},{"price":"41.050","symbol":"LINKUSDT","id":"410500","side":"Sell","size":391.6},{"price":"41.042","symbol":"LINKUSDT","id":"410420","side":"Buy","size":169.20001},{"price":"41.056","symbol":"LINKUSDT","id":"410560","side":"Sell","size":18.8},{"price":"41.039","symbol":"LINKUSDT","id":"410390","side":"Buy","size":198.3},{"price":"41.036","symbol":"LINKUSDT","id":"410360","side":"Buy","size":427}],"insert":[]},"cross_seq":"1970980053","timestamp_e6":"1618677791624564"}
1618677791.728982: {"topic":"orderBookL2_25.DOTUSDT","type":"delta","data":{"delete":[{"price":"43.400","symbol":"DOTUSDT","id":"434000","side":"Buy"},{"price":"43.545","symbol":"DOTUSDT","id":"435450","side":"Sell"},{"price":"43.405","symbol":"DOTUSDT","id":"434050","side":"Buy"}],"update":[{"price":"43.565","symbol":"DOTUSDT","id":"435650","side":"Sell","size":360.1},{"price":"43.550","symbol":"DOTUSDT","id":"435500","side":"Sell","size":916.39996}],"insert":[{"price":"43.520","symbol":"DOTUSDT","id":"435200","side":"Buy","size":356.2},{"price":"43.670","symbol":"DOTUSDT","id":"436700","side":"Sell","size":647.5},{"price":"43.510","symbol":"DOTUSDT","id":"435100","side":"Buy","size":234.90001}]},"cross_seq":"916954308","timestamp_e6":"1618677791643622"}
1618677791.732488: {"topic":"orderBookL2_25.BCHUSDT","type":"delta","data":{"delete":[],"update":[{"price":"1056.60","symbol":"BCHUSDT","id":"10566000","side":"Sell","size":10.7}],"insert":[]},"cross_seq":"864132759","timestamp_e6":"1618677791649569"}
1618677791.768076: {"topic":"orderBookL2_25.ADAUSDT","type":"delta","data":{"delete":[],"update":[{"price":"1.3863","symbol":"ADAUSDT","id":"13863","side":"Buy","size":4265},{"price":"1.3866","symbol":"ADAUSDT","id":"13866","side":"Buy","size":3766}],"insert":[]},"cross_seq":"916954319","timestamp_e6":"1618677791682415"}
1618677791.7681348: {"topic":"orderBookL2_25.DOTUSDT","type":"delta","data":{"delete":[{"price":"43.410","symbol":"DOTUSDT","id":"434100","side":"Buy"}],"update":[{"price":"43.550","symbol":"DOTUSDT","id":"435500","side":"Sell","size":1254.9},{"price":"43.540","symbol":"DOTUSDT","id":"435400","side":"Buy","size":120}],"insert":[{"price":"43.545","symbol":"DOTUSDT","id":"435450","side":"Buy","size":292}]},"cross_seq":"916954319","timestamp_e6":"1618677791684019"}
1618677791.787313: {"topic":"orderBookL2_25.DOTUSDT","type":"delta","data":{"delete":[{"price":"43.415","symbol":"DOTUSDT","id":"434150","side":"Buy"},{"price":"43.420","symbol":"DOTUSDT","id":"434200","side":"Buy"}],"update":[{"price":"43.470","symbol":"DOTUSDT","id":"434700","side":"Buy","size":628.9},{"price":"43.460","symbol":"DOTUSDT","id":"434600","side":"Buy","size":239.1},{"price":"43.465","symbol":"DOTUSDT","id":"434650","side":"Buy","size":123.399994},{"price":"43.575","symbol":"DOTUSDT","id":"435750","side":"Sell","size":306.40002},{"price":"43.570","symbol":"DOTUSDT","id":"435700","side":"Sell","size":324.2},{"price":"43.475","symbol":"DOTUSDT","id":"434750","side":"Buy","size":549.2},{"price":"43.485","symbol":"DOTUSDT","id":"434850","side":"Buy","size":538.69995},{"price":"43.440","symbol":"DOTUSDT","id":"434400","side":"Buy","size":268},{"price":"43.455","symbol":"DOTUSDT","id":"434550","side":"Buy","size":289.5},{"price":"43.560","symbol":"DOTUSDT","id":"435600","side":"Sell","size":896}],"insert":[{"price":"43.490","symbol":"DOTUSDT","id":"434900","side":"Buy","size":444.8},{"price":"43.495","symbol":"DOTUSDT","id":"434950","side":"Buy","size":535.6}]},"cross_seq":"916954357","timestamp_e6":"1618677791702421"}
1618677791.791575: {"topic":"orderBookL2_25.ETHUSDT","type":"delta","data":{"delete":[],"update":[{"price":"2364.95","symbol":"ETHUSDT","id":"23649500","side":"Sell","size":324.05}],"insert":[]},"cross_seq":"1800546594","timestamp_e6":"1618677791707461"}
1618677791.8044958: {"topic":"orderBookL2_25.LTCUSDT","type":"delta","data":{"delete":[{"price":"312.76","symbol":"LTCUSDT","id":"3127600","side":"Buy"},{"price":"313.14","symbol":"LTCUSDT","id":"3131400","side":"Buy"},{"price":"312.78","symbol":"LTCUSDT","id":"3127800","side":"Buy"},{"price":"312.93","symbol":"LTCUSDT","id":"3129300","side":"Buy"},{"price":"312.79","symbol":"LTCUSDT","id":"3127900","side":"Buy"},{"price":"313.15","symbol":"LTCUSDT","id":"3131500","side":"Buy"},{"price":"312.77","symbol":"LTCUSDT","id":"3127700","side":"Buy"},{"price":"313.40","symbol":"LTCUSDT","id":"3134000","side":"Sell"},{"price":"313.05","symbol":"LTCUSDT","id":"3130500","side":"Buy"},{"price":"313.04","symbol":"LTCUSDT","id":"3130400","side":"Buy"},{"price":"312.95","symbol":"LTCUSDT","id":"3129500","side":"Buy"},{"price":"313.16","symbol":"LTCUSDT","id":"3131600","side":"Buy"},{"price":"312.80","symbol":"LTCUSDT","id":"3128000","side":"Buy"},{"price":"313.08","symbol":"LTCUSDT","id":"3130800","side":"Buy"}],"update":[{"price":"313.07","symbol":"LTCUSDT","id":"3130700","side":"Buy","size":24.300001},{"price":"313.41","symbol":"LTCUSDT","id":"3134100","side":"Sell","size":151.2},{"price":"313.18","symbol":"LTCUSDT","id":"3131800","side":"Buy","size":1.5},{"price":"313.06","symbol":"LTCUSDT","id":"3130600","side":"Buy","size":59.9},{"price":"313.44","symbol":"LTCUSDT","id":"3134400","side":"Sell","size":58.300003},{"price":"313.42","symbol":"LTCUSDT","id":"3134200","side":"Sell","size":158.79999},{"price":"313.09","symbol":"LTCUSDT","id":"3130900","side":"Buy","size":186.99998},{"price":"313.13","symbol":"LTCUSDT","id":"3131300","side":"Buy","size":87}],"insert":[{"price":"313.12","symbol":"LTCUSDT","id":"3131200","side":"Buy","size":6.4},{"price":"313.24","symbol":"LTCUSDT","id":"3132400","side":"Buy","size":92.4},{"price":"313.23","symbol":"LTCUSDT","id":"3132300","side":"Buy","size":9.4},{"price":"313.20","symbol":"LTCUSDT","id":"3132000","side":"Buy","size":99.399994},{"price":"313.19","symbol":"LTCUSDT","id":"3131900","side":"Buy","size":25.3},{"price":"313.10","symbol":"LTCUSDT","id":"3131000","side":"Buy","size":8.1},{"price":"313.39","symbol":"LTCUSDT","id":"3133900","side":"Sell","size":107.2},{"price":"313.28","symbol":"LTCUSDT","id":"3132800","side":"Buy","size":49.5},{"price":"313.21","symbol":"LTCUSDT","id":"3132100","side":"Buy","size":12.6},{"price":"313.26","symbol":"LTCUSDT","id":"3132600","side":"Buy","size":4.8},{"price":"313.22","symbol":"LTCUSDT","id":"3132200","side":"Buy","size":63.9},{"price":"313.27","symbol":"LTCUSDT","id":"3132700","side":"Buy","size":29.6},{"price":"313.11","symbol":"LTCUSDT","id":"3131100","side":"Buy","size":16.8},{"price":"313.25","symbol":"LTCUSDT","id":"3132500","side":"Buy","size":175.20001}]},"cross_seq":"1684523180","timestamp_e6":"1618677791718326"}
1618677791.806582: {"topic":"orderBookL2_25.DOTUSDT","type":"delta","data":{"delete":[],"update":[{"price":"43.540","symbol":"DOTUSDT","id":"435400","side":"Buy","size":10},{"price":"43.545","symbol":"DOTUSDT","id":"435450","side":"Buy","size":302}],"insert":[]},"cross_seq":"916954359","timestamp_e6":"1618677791722302"}
1618677791.8112051: {"topic":"orderBookL2_25.ETHUSDT","type":"delta","data":{"delete":[],"update":[{"price":"2364.95","symbol":"ETHUSDT","id":"23649500","side":"Sell","size":356.55}],"insert":[]},"cross_seq":"1800546595","timestamp_e6":"1618677791727520"}
1618677791.8126059: {"topic":"orderBookL2_25.BCHUSDT","type":"delta","data":{"delete":[{"price":"1056.65","symbol":"BCHUSDT","id":"10566500","side":"Sell"}],"update":[{"price":"1053.90","symbol":"BCHUSDT","id":"10539000","side":"Buy","size":10.55},{"price":"1055.55","symbol":"BCHUSDT","id":"10555500","side":"Sell","size":9.44},{"price":"1054.00","symbol":"BCHUSDT","id":"10540000","side":"Buy","size":14.8},{"price":"1055.60","symbol":"BCHUSDT","id":"10556000","side":"Sell","size":17.93},{"price":"1055.65","symbol":"BCHUSDT","id":"10556500","side":"Sell","size":19.04},{"price":"1053.95","symbol":"BCHUSDT","id":"10539500","side":"Buy","size":12.6},{"price":"1055.70","symbol":"BCHUSDT","id":"10557000","side":"Sell","size":6.55},{"price":"1054.15","symbol":"BCHUSDT","id":"10541500","side":"Buy","size":15.889999}],"insert":[{"price":"1055.50","symbol":"BCHUSDT","id":"10555000","side":"Sell","size":11.96}]},"cross_seq":"864132769","timestamp_e6":"1618677791728813"}
1618677791.8270888: {"topic":"orderBookL2_25.DOTUSDT","type":"delta","data":{"delete":[],"update":[{"price":"43.545","symbol":"DOTUSDT","id":"435450","side":"Buy","size":202}],"insert":[]},"cross_seq":"916954360","timestamp_e6":"1618677791742402"}
1618677791.831157: {"topic":"orderBookL2_25.ETHUSDT","type":"delta","data":{"delete":[],"update":[{"price":"2364.20","symbol":"ETHUSDT","id":"23642000","side":"Buy","size":165.45},{"price":"2364.15","symbol":"ETHUSDT","id":"23641500","side":"Buy","size":72.53},{"price":"2364.05","symbol":"ETHUSDT","id":"23640500","side":"Buy","size":42.17},{"price":"2364.10","symbol":"ETHUSDT","id":"23641000","side":"Buy","size":105.83},{"price":"2366.30","symbol":"ETHUSDT","id":"23663000","side":"Sell","size":21.07}],"insert":[]},"cross_seq":"1800546602","timestamp_e6":"1618677791747055"}
1618677791.83971: {"topic":"orderBookL2_25.XTZUSDT","type":"delta","data":{"delete":[],"update":[{"price":"7.216","symbol":"XTZUSDT","id":"72160","side":"Sell","size":2693.2},{"price":"7.213","symbol":"XTZUSDT","id":"72130","side":"Sell","size":0.4},{"price":"7.205","symbol":"XTZUSDT","id":"72050","side":"Buy","size":3455.5},{"price":"7.208","symbol":"XTZUSDT","id":"72080","side":"Buy","size":2387.9},{"price":"7.207","symbol":"XTZUSDT","id":"72070","side":"Buy","size":2416.4},{"price":"7.209","symbol":"XTZUSDT","id":"72090","side":"Buy","size":1664.3},{"price":"7.215","symbol":"XTZUSDT","id":"72150","side":"Sell","size":1379.8},{"price":"7.204","symbol":"XTZUSDT","id":"72040","side":"Buy","size":1013.39996},{"price":"7.217","symbol":"XTZUSDT","id":"72170","side":"Sell","size":741.2},{"price":"7.212","symbol":"XTZUSDT","id":"72120","side":"Sell","size":6851.1},{"price":"7.206","symbol":"XTZUSDT","id":"72060","side":"Buy","size":2307.5}],"insert":[]},"cross_seq":"726228456","timestamp_e6":"1618677791755479"}
1618677791.845508: {"topic":"orderBookL2_25.LTCUSDT","type":"delta","data":{"delete":[],"update":[{"price":"313.34","symbol":"LTCUSDT","id":"3133400","side":"Buy","size":145.3},{"price":"313.50","symbol":"LTCUSDT","id":"3135000","side":"Sell","size":152.3}],"insert":[]},"cross_seq":"1684523182","timestamp_e6":"1618677791761393"}
1618677791.8475819: {"topic":"orderBookL2_25.ADAUSDT","type":"delta","data":{"delete":[],"update":[{"price":"1.3867","symbol":"ADAUSDT","id":"13867","side":"Buy","size":2001},{"price":"1.3863","symbol":"ADAUSDT","id":"13863","side":"Buy","size":5864}],"insert":[]},"cross_seq":"916954364","timestamp_e6":"1618677791762367"}
1618677791.8476338: {"topic":"orderBookL2_25.DOTUSDT","type":"delta","data":{"delete":[{"price":"43.530","symbol":"DOTUSDT","id":"435300","side":"Buy"}],"update":[{"price":"43.510","symbol":"DOTUSDT","id":"435100","side":"Buy","size":443.9}],"insert":[{"price":"43.420","symbol":"DOTUSDT","id":"434200","side":"Buy","size":207.1}]},"cross_seq":"916954364","timestamp_e6":"1618677791762505"}
1618677791.850357: {"topic":"orderBookL2_25.LINKUSDT","type":"delta","data":{"delete":[],"update":[{"price":"41.023","symbol":"LINKUSDT","id":"410230","side":"Buy","size":201.9}],"insert":[]},"cross_seq":"1970980055","timestamp_e6":"1618677791764896"}
1618677791.867348: {"topic":"orderBookL2_25.LINKUSDT","type":"delta","data":{"delete":[],"update":[{"price":"41.069","symbol":"LINKUSDT","id":"410690","side":"Sell","size":152.90001}],"insert":[]},"cross_seq":"1970980056","timestamp_e6":"1618677791783681"}
1618677791.87064: {"topic":"orderBookL2_25.ETHUSDT","type":"delta","data":{"delete":[{"price":"2364.30","symbol":"ETHUSDT","id":"23643000","side":"Buy"},{"price":"2364.35","symbol":"ETHUSDT","id":"23643500","side":"Buy"}],"update":[{"price":"2364.05","symbol":"ETHUSDT","id":"23640500","side":"Buy","size":85.47},{"price":"2364.00","symbol":"ETHUSDT","id":"23640000","side":"Buy","size":44.519997},{"price":"2364.40","symbol":"ETHUSDT","id":"23644000","side":"Buy","size":1.19},{"price":"2364.10","symbol":"ETHUSDT","id":"23641000","side":"Buy","size":135.06},{"price":"2364.45","symbol":"ETHUSDT","id":"23644500","side":"Buy","size":1.2},{"price":"2364.20","symbol":"ETHUSDT","id":"23642000","side":"Buy","size":103.63}],"insert":[{"price":"2363.25","symbol":"ETHUSDT","id":"23632500","side":"Buy","size":129.70999},{"price":"2363.30","symbol":"ETHUSDT","id":"23633000","side":"Buy","size":82.380005}]},"cross_seq":"1800546628","timestamp_e6":"1618677791787247"}
1618677791.881873: {"topic":"orderBookL2_25.LTCUSDT","type":"delta","data":{"delete":[{"price":"313.33","symbol":"LTCUSDT","id":"3133300","side":"Buy"},{"price":"313.62","symbol":"LTCUSDT","id":"3136200","side":"Sell"}],"update":[{"price":"313.41","symbol":"LTCUSDT","id":"3134100","side":"Sell","size":172.2},{"price":"313.44","symbol":"LTCUSDT","id":"3134400","side":"Sell","size":68.9},{"price":"313.30","symbol":"LTCUSDT","id":"3133000","side":"Buy","size":103}],"insert":[{"price":"313.05","symbol":"LTCUSDT","id":"3130500","side":"Buy","size":14.6},{"price":"313.40","symbol":"LTCUSDT","id":"3134000","side":"Sell","size":80.3}]},"cross_seq":"1684523188","timestamp_e6":"1618677791797865"}
1618677791.890312: {"topic":"orderBookL2_25.LINKUSDT","type":"delta","data":{"delete":[],"update":[{"price":"41.045","symbol":"LINKUSDT","id":"410450","side":"Buy","size":1006.39996}],"insert":[]},"cross_seq":"1970980057","timestamp_e6":"1618677791804863"}
1618677791.892858: {"topic":"orderBookL2_25.BCHUSDT","type":"delta","data":{"delete":[{"price":"1055.50","symbol":"BCHUSDT","id":"10555000","side":"Sell"}],"update":[{"price":"1055.75","symbol":"BCHUSDT","id":"10557500","side":"Sell","size":4.35},{"price":"1055.60","symbol":"BCHUSDT","id":"10556000","side":"Sell","size":11.9},{"price":"1055.80","symbol":"BCHUSDT","id":"10558000","side":"Sell","size":9.58},{"price":"1054.00","symbol":"BCHUSDT","id":"10540000","side":"Buy","size":22.81},{"price":"1054.20","symbol":"BCHUSDT","id":"10542000","side":"Buy","size":20.24},{"price":"1054.10","symbol":"BCHUSDT","id":"10541000","side":"Buy","size":2.15},{"price":"1055.65","symbol":"BCHUSDT","id":"10556500","side":"Sell","size":23.72},{"price":"1055.70","symbol":"BCHUSDT","id":"10557000","side":"Sell","size":8.55},{"price":"1055.55","symbol":"BCHUSDT","id":"10555500","side":"Sell","size":6.41}],"insert":[{"price":"1055.40","symbol":"BCHUSDT","id":"10554000","side":"Sell","size":13.910001}]},"cross_seq":"864132782","timestamp_e6":"1618677791808765"}
1618677791.908095: {"topic":"orderBookL2_25.LINKUSDT","type":"delta","data":{"delete":[{"price":"41.072","symbol":"LINKUSDT","id":"410720","side":"Sell"},{"price":"41.071","symbol":"LINKUSDT","id":"410710","side":"Sell"}],"update":[],"insert":[{"price":"41.052","symbol":"LINKUSDT","id":"410520","side":"Sell","size":210.40001},{"price":"41.051","symbol":"LINKUSDT","id":"410510","side":"Sell","size":300.3}]},"cross_seq":"1970980059","timestamp_e6":"1618677791823684"}
1618677791.9081569: {"topic":"orderBookL2_25.UNIUSDT","type":"delta","data":{"delete":[{"price":"35.380","symbol":"UNIUSDT","id":"353800","side":"Buy"}],"update":[{"price":"35.382","symbol":"UNIUSDT","id":"353820","side":"Buy","size":56.4},{"price":"35.378","symbol":"UNIUSDT","id":"353780","side":"Buy","size":7.4},{"price":"35.383","symbol":"UNIUSDT","id":"353830","side":"Buy","size":71.9},{"price":"35.405","symbol":"UNIUSDT","id":"354050","side":"Sell","size":86.00001},{"price":"35.407","symbol":"UNIUSDT","id":"354070","side":"Sell","size":131.59999},{"price":"35.381","symbol":"UNIUSDT","id":"353810","side":"Buy","size":43.000004},{"price":"35.406","symbol":"UNIUSDT","id":"354060","side":"Sell","size":160.1}],"insert":[{"price":"35.360","symbol":"UNIUSDT","id":"353600","side":"Buy","size":20.5}]},"cross_seq":"916954373","timestamp_e6":"1618677791822488"}
1618677791.9082189: {"topic":"orderBookL2_25.ADAUSDT","type":"delta","data":{"delete":[],"update":[{"price":"1.3867","symbol":"ADAUSDT","id":"13867","side":"Buy","size":6260}],"insert":[]},"cross_seq":"916954373","timestamp_e6":"1618677791822337"}
1618677791.911194: {"topic":"orderBookL2_25.ETHUSDT","type":"delta","data":{"delete":[{"price":"2363.30","symbol":"ETHUSDT","id":"23633000","side":"Buy"},{"price":"2363.25","symbol":"ETHUSDT","id":"23632500","side":"Buy"}],"update":[{"price":"2364.05","symbol":"ETHUSDT","id":"23640500","side":"Buy","size":42.17},{"price":"2364.10","symbol":"ETHUSDT","id":"23641000","side":"Buy","size":62.530003},{"price":"2364.15","symbol":"ETHUSDT","id":"23641500","side":"Buy","size":50.67},{"price":"2364.20","symbol":"ETHUSDT","id":"23642000","side":"Buy","size":176.15999}],"insert":[{"price":"2364.25","symbol":"ETHUSDT","id":"23642500","side":"Buy","size":61.82},{"price":"2364.30","symbol":"ETHUSDT","id":"23643000","side":"Buy","size":95.439995}]},"cross_seq":"1800546635","timestamp_e6":"1618677791827478"}
1618677791.92833: {"topic":"orderBookL2_25.ADAUSDT","type":"delta","data":{"delete":[],"update":[{"price":"1.3876","symbol":"ADAUSDT","id":"13876","side":"Sell","size":4237}],"insert":[]},"cross_seq":"916954375","timestamp_e6":"1618677791842362"}
1618677791.928368: {"topic":"orderBookL2_25.UNIUSDT","type":"delta","data":{"delete":[],"update":[{"price":"35.372","symbol":"UNIUSDT","id":"353720","side":"Buy","size":19.2}],"insert":[]},"cross_seq":"916954375","timestamp_e6":"1618677791842487"}
1618677791.9303942: {"topic":"orderBookL2_25.ETHUSDT","type":"delta","data":{"delete":[{"price":"2364.15","symbol":"ETHUSDT","id":"23641500","side":"Buy"},{"price":"2364.30","symbol":"ETHUSDT","id":"23643000","side":"Buy"}],"update":[{"price":"2364.10","symbol":"ETHUSDT","id":"23641000","side":"Buy","size":90.16},{"price":"2363.95","symbol":"ETHUSDT","id":"23639500","side":"Buy","size":27.75},{"price":"2364.05","symbol":"ETHUSDT","id":"23640500","side":"Buy","size":86.17},{"price":"2364.20","symbol":"ETHUSDT","id":"23642000","side":"Buy","size":103.63},{"price":"2364.00","symbol":"ETHUSDT","id":"23640000","side":"Buy","size":122.42}],"insert":[{"price":"2364.35","symbol":"ETHUSDT","id":"23643500","side":"Buy","size":95.439995},{"price":"2363.30","symbol":"ETHUSDT","id":"23633000","side":"Buy","size":82.380005}]},"cross_seq":"1800546649","timestamp_e6":"1618677791847137"}
1618677791.931127: {"topic":"trade.ADAUSDT","data":[{"symbol":"ADAUSDT","tick_direction":"PlusTick","price":"1.3876","size":1,"timestamp":"2021-04-17T16:43:11.000Z","trade_time_ms":"1618677791827","side":"Buy","trade_id":"ba0c3438-3cbe-5fef-a813-0e981372ac88"},{"symbol":"ADAUSDT","tick_direction":"ZeroPlusTick","price":"1.3876","size":4,"timestamp":"2021-04-17T16:43:11.000Z","trade_time_ms":"1618677791827","side":"Buy","trade_id":"62068a54-c305-5c88-b2d7-40557b3eed20"}]}
1618677791.932998: {"topic":"orderBookL2_25.BCHUSDT","type":"delta","data":{"delete":[],"update":[{"price":"1054.95","symbol":"BCHUSDT","id":"10549500","side":"Buy","size":17.02}],"insert":[]},"cross_seq":"864132788","timestamp_e6":"1618677791850023"}
1618677791.948543: {"topic":"orderBookL2_25.UNIUSDT","type":"delta","data":{"delete":[{"price":"35.360","symbol":"UNIUSDT","id":"353600","side":"Buy"}],"update":[{"price":"35.378","symbol":"UNIUSDT","id":"353780","side":"Buy","size":56.4},{"price":"35.376","symbol":"UNIUSDT","id":"353760","side":"Buy","size":87.399994},{"price":"35.402","symbol":"UNIUSDT","id":"354020","side":"Sell","size":379.7},{"price":"35.411","symbol":"UNIUSDT","id":"354110","side":"Sell","size":39},{"price":"35.375","symbol":"UNIUSDT","id":"353750","side":"Buy","size":65.799995},{"price":"35.379","symbol":"UNIUSDT","id":"353790","side":"Buy","size":43.3},{"price":"35.412","symbol":"UNIUSDT","id":"354120","side":"Sell","size":25.3},{"price":"35.403","symbol":"UNIUSDT","id":"354030","side":"Sell","size":150.1},{"price":"35.410","symbol":"UNIUSDT","id":"354100","side":"Sell","size":47.100002},{"price":"35.404","symbol":"UNIUSDT","id":"354040","side":"Sell","size":133.6},{"price":"35.406","symbol":"UNIUSDT","id":"354060","side":"Sell","size":78.5},{"price":"35.408","symbol":"UNIUSDT","id":"354080","side":"Sell","size":54.8},{"price":"35.413","symbol":"UNIUSDT","id":"354130","side":"Sell","size":25.6},{"price":"35.405","symbol":"UNIUSDT","id":"354050","side":"Sell","size":141.40001},{"price":"35.407","symbol":"UNIUSDT","id":"354070","side":"Sell","size":49.6},{"price":"35.409","symbol":"UNIUSDT","id":"354090","side":"Sell","size":77.7}],"insert":[{"price":"35.377","symbol":"UNIUSDT","id":"353770","side":"Buy","size":43.000004}]},"cross_seq":"916954404","timestamp_e6":"1618677791862641"}
1618677791.950936: {"topic":"orderBookL2_25.LINKUSDT","type":"delta","data":{"delete":[],"update":[{"price":"41.026","symbol":"LINKUSDT","id":"410260","side":"Buy","size":876.2}],"insert":[]},"cross_seq":"1970980060","timestamp_e6":"1618677791865992"}
1618677791.952479: {"topic":"orderBookL2_25.ETHUSDT","type":"delta","data":{"delete":[],"update":[{"price":"2364.90","symbol":"ETHUSDT","id":"23649000","side":"Buy","size":121.490005},{"price":"2364.95","symbol":"ETHUSDT","id":"23649500","side":"Sell","size":401.55002}],"insert":[]},"cross_seq":"1800546668","timestamp_e6":"1618677791868813"}
1618677791.952524: {"topic":"orderBookL2_25.BCHUSDT","type":"delta","data":{"delete":[],"update":[{"price":"1054.05","symbol":"BCHUSDT","id":"10540500","side":"Buy","size":32},{"price":"1054.20","symbol":"BCHUSDT","id":"10542000","side":"Buy","size":3.03},{"price":"1054.25","symbol":"BCHUSDT","id":"10542500","side":"Buy","size":30.89},{"price":"1054.10","symbol":"BCHUSDT","id":"10541000","side":"Buy","size":13.5},{"price":"1054.15","symbol":"BCHUSDT","id":"10541500","side":"Buy","size":1}],"insert":[]},"cross_seq":"864132794","timestamp_e6":"1618677791868836"}
1618677791.971745: {"topic":"orderBookL2_25.ETHUSDT","type":"delta","data":{"delete":[{"price":"2364.35","symbol":"ETHUSDT","id":"23643500","side":"Buy"},{"price":"2364.25","symbol":"ETHUSDT","id":"23642500","side":"Buy"}],"update":[{"price":"2364.40","symbol":"ETHUSDT","id":"23644000","side":"Buy","size":96.63},{"price":"2364.20","symbol":"ETHUSDT","id":"23642000","side":"Buy","size":120.149994}],"insert":[{"price":"2364.15","symbol":"ETHUSDT","id":"23641500","side":"Buy","size":27.630001},{"price":"2364.30","symbol":"ETHUSDT","id":"23643000","side":"Buy","size":72.53}]},"cross_seq":"1800546675","timestamp_e6":"1618677791887606"}
1618677791.990222: {"topic":"orderBookL2_25.ETHUSDT","type":"delta","data":{"delete":[],"update":[{"price":"2364.00","symbol":"ETHUSDT","id":"23640000","side":"Buy","size":44.519997},{"price":"2364.15","symbol":"ETHUSDT","id":"23641500","side":"Buy","size":61.82},{"price":"2364.20","symbol":"ETHUSDT","id":"23642000","side":"Buy","size":182.55},{"price":"2364.10","symbol":"ETHUSDT","id":"23641000","side":"Buy","size":135.06}],"insert":[]},"cross_seq":"1800546680","timestamp_e6":"1618677791907147"}
1618677791.9928331: {"topic":"orderBookL2_25.BCHUSDT","type":"delta","data":{"delete":[{"price":"1056.60","symbol":"BCHUSDT","id":"10566000","side":"Sell"},{"price":"1055.40","symbol":"BCHUSDT","id":"10554000","side":"Sell"},{"price":"1055.55","symbol":"BCHUSDT","id":"10555500","side":"Sell"}],"update":[{"price":"1055.45","symbol":"BCHUSDT","id":"10554500","side":"Sell","size":3.57},{"price":"1054.85","symbol":"BCHUSDT","id":"10548500","side":"Buy","size":14.27}],"insert":[{"price":"1055.35","symbol":"BCHUSDT","id":"10553500","side":"Sell","size":11.96},{"price":"1055.30","symbol":"BCHUSDT","id":"10553000","side":"Sell","size":13.910001},{"price":"1055.50","symbol":"BCHUSDT","id":"10555000","side":"Sell","size":2.36}]},"cross_seq":"864132804","timestamp_e6":"1618677791909262"}
1618677792.011609: {"topic":"orderBookL2_25.ETHUSDT","type":"delta","data":{"delete":[],"update":[{"price":"2364.90","symbol":"ETHUSDT","id":"23649000","side":"Buy","size":89}],"insert":[]},"cross_seq":"1800546681","timestamp_e6":"1618677791928333"}
1618677792.011648: {"topic":"orderBookL2_25.BCHUSDT","type":"delta","data":{"delete":[{"price":"1055.45","symbol":"BCHUSDT","id":"10554500","side":"Sell"},{"price":"1055.35","symbol":"BCHUSDT","id":"10553500","side":"Sell"}],"update":[],"insert":[{"price":"1055.25","symbol":"BCHUSDT","id":"10552500","side":"Sell","size":13.910001},{"price":"1055.40","symbol":"BCHUSDT","id":"10554000","side":"Sell","size":5.55}]},"cross_seq":"864132815","timestamp_e6":"1618677791928909"}
1618677792.0299342: {"topic":"orderBookL2_25.ETHUSDT","type":"delta","data":{"delete":[{"price":"2364.30","symbol":"ETHUSDT","id":"23643000","side":"Buy"}],"update":[{"price":"2364.05","symbol":"ETHUSDT","id":"23640500","side":"Buy","size":42.17},{"price":"2364.00","symbol":"ETHUSDT","id":"23640000","side":"Buy","size":72.15},{"price":"2364.20","symbol":"ETHUSDT","id":"23642000","side":"Buy","size":103.63},{"price":"2364.10","symbol":"ETHUSDT","id":"23641000","side":"Buy","size":107.43},{"price":"2364.40","symbol":"ETHUSDT","id":"23644000","side":"Buy","size":1.19}],"insert":[{"price":"2364.25","symbol":"ETHUSDT","id":"23642500","side":"Buy","size":95.439995}]},"cross_seq":"1800546688","timestamp_e6":"1618677791947075"}
1618677792.0437398: {"topic":"orderBookL2_25.LTCUSDT","type":"delta","data":{"delete":[{"price":"313.40","symbol":"LTCUSDT","id":"3134000","side":"Sell"},{"price":"313.05","symbol":"LTCUSDT","id":"3130500","side":"Buy"},{"price":"313.39","symbol":"LTCUSDT","id":"3133900","side":"Sell"}],"update":[{"price":"313.56","symbol":"LTCUSDT","id":"3135600","side":"Sell","size":222.3},{"price":"313.34","symbol":"LTCUSDT","id":"3133400","side":"Buy","size":16.2},{"price":"313.43","symbol":"LTCUSDT","id":"3134300","side":"Sell","size":68.2},{"price":"313.41","symbol":"LTCUSDT","id":"3134100","side":"Sell","size":186.4}],"insert":[{"price":"313.33","symbol":"LTCUSDT","id":"3133300","side":"Buy","size":129.1},{"price":"313.38","symbol":"LTCUSDT","id":"3133800","side":"Sell","size":107.2},{"price":"313.62","symbol":"LTCUSDT","id":"3136200","side":"Sell","size":229.8}]},"cross_seq":"1684523199","timestamp_e6":"1618677791959082"}
1618677792.046249: {"topic":"orderBookL2_25.DOTUSDT","type":"delta","data":{"delete":[],"update":[{"price":"43.475","symbol":"DOTUSDT","id":"434750","side":"Buy","size":638.1}],"insert":[]},"cross_seq":"916954425","timestamp_e6":"1618677791962604"}
1618677792.047263: {"topic":"orderBookL2_25.ADAUSDT","type":"delta","data":{"delete":[],"update":[{"price":"1.3882","symbol":"ADAUSDT","id":"13882","side":"Sell","size":1786.9999},{"price":"1.3880","symbol":"ADAUSDT","id":"13880","side":"Sell","size":4492},{"price":"1.3883","symbol":"ADAUSDT","id":"13883","side":"Sell","size":2487}],"insert":[]},"cross_seq":"916954425","timestamp_e6":"1618677791962432"}
1618677792.070703: {"topic":"orderBookL2_25.ETHUSDT","type":"delta","data":{"delete":[{"price":"2364.15","symbol":"ETHUSDT","id":"23641500","side":"Buy"},{"price":"2364.25","symbol":"ETHUSDT","id":"23642500","side":"Buy"}],"update":[{"price":"2364.40","symbol":"ETHUSDT","id":"23644000","side":"Buy","size":96.63},{"price":"2364.20","symbol":"ETHUSDT","id":"23642000","side":"Buy","size":120.149994},{"price":"2364.55","symbol":"ETHUSDT","id":"23645500","side":"Buy","size":1.46}],"insert":[{"price":"2364.35","symbol":"ETHUSDT","id":"23643500","side":"Buy","size":61.82},{"price":"2364.30","symbol":"ETHUSDT","id":"23643000","side":"Buy","size":72.53}]},"cross_seq":"1800546713","timestamp_e6":"1618677791987066"}
1618677792.081247: {"topic":"orderBookL2_25.LTCUSDT","type":"delta","data":{"delete":[],"update":[{"price":"313.56","symbol":"LTCUSDT","id":"3135600","side":"Sell","size":272.3}],"insert":[]},"cross_seq":"1684523211","timestamp_e6":"1618677791997885"}
1618677792.0867279: {"topic":"orderBookL2_25.DOTUSDT","type":"delta","data":{"delete":[],"update":[{"price":"43.550","symbol":"DOTUSDT","id":"435500","side":"Sell","size":1354.9}],"insert":[]},"cross_seq":"916954426","timestamp_e6":"1618677792002346"}
1618677792.0994968: {"topic":"orderBookL2_25.XTZUSDT","type":"delta","data":{"delete":[],"update":[{"price":"7.215","symbol":"XTZUSDT","id":"72150","side":"Sell","size":1522.1},{"price":"7.212","symbol":"XTZUSDT","id":"72120","side":"Sell","size":7805.5},{"price":"7.217","symbol":"XTZUSDT","id":"72170","side":"Sell","size":894.4},{"price":"7.213","symbol":"XTZUSDT","id":"72130","side":"Sell","size":687.2},{"price":"7.209","symbol":"XTZUSDT","id":"72090","side":"Buy","size":2736.2},{"price":"7.204","symbol":"XTZUSDT","id":"72040","side":"Buy","size":1397.5}],"insert":[]},"cross_seq":"726228462","timestamp_e6":"1618677792016423"}
1618677792.107008: {"topic":"orderBookL2_25.DOTUSDT","type":"delta","data":{"delete":[{"price":"43.535","symbol":"DOTUSDT","id":"435350","side":"Buy"}],"update":[],"insert":[{"price":"43.530","symbol":"DOTUSDT","id":"435300","side":"Buy","size":607.4}]},"cross_seq":"916954428","timestamp_e6":"1618677792022339"}
1618677792.12196: {"topic":"orderBookL2_25.LTCUSDT","type":"delta","data":{"delete":[{"price":"313.62","symbol":"LTCUSDT","id":"3136200","side":"Sell"},{"price":"313.61","symbol":"LTCUSDT","id":"3136100","side":"Sell"},{"price":"313.38","symbol":"LTCUSDT","id":"3133800","side":"Sell"}],"update":[{"price":"313.42","symbol":"LTCUSDT","id":"3134200","side":"Sell","size":112.5}],"insert":[{"price":"313.37","symbol":"LTCUSDT","id":"3133700","side":"Sell","size":107.2},{"price":"313.39","symbol":"LTCUSDT","id":"3133900","side":"Sell","size":46.300003},{"price":"313.40","symbol":"LTCUSDT","id":"3134000","side":"Sell","size":60.5}]},"cross_seq":"1684523218","timestamp_e6":"1618677792037839"}
1618677792.16372: {"topic":"orderBookL2_25.LTCUSDT","type":"delta","data":{"delete":[],"update":[{"price":"313.35","symbol":"LTCUSDT","id":"3133500","side":"Sell","size":277.1}],"insert":[]},"cross_seq":"1684523219","timestamp_e6":"1618677792079501"}
1618677792.168861: {"topic":"orderBookL2_25.LINKUSDT","type":"delta","data":{"delete":[],"update":[{"price":"41.046","symbol":"LINKUSDT","id":"410460","side":"Sell","size":466},{"price":"41.045","symbol":"LINKUSDT","id":"410450","side":"Buy","size":356.4}],"insert":[]},"cross_seq":"1970980063","timestamp_e6":"1618677792085841"}
1618677792.188182: {"topic":"orderBookL2_25.LINKUSDT","type":"delta","data":{"delete":[],"update":[{"price":"41.046","symbol":"LINKUSDT","id":"410460","side":"Sell","size":66}],"insert":[]},"cross_seq":"1970980064","timestamp_e6":"1618677792104185"}
1618677792.19029: {"topic":"orderBookL2_25.ETHUSDT","type":"delta","data":{"delete":[],"update":[{"price":"2363.75","symbol":"ETHUSDT","id":"23637500","side":"Buy","size":93.17999}],"insert":[]},"cross_seq":"1800546715","timestamp_e6":"1618677792107081"}
1618677792.192408: {"topic":"orderBookL2_25.BCHUSDT","type":"delta","data":{"delete":[{"price":"1054.90","symbol":"BCHUSDT","id":"10549000","side":"Buy"},{"price":"1056.55","symbol":"BCHUSDT","id":"10565500","side":"Sell"},{"price":"1055.30","symbol":"BCHUSDT","id":"10553000","side":"Sell"},{"price":"1055.40","symbol":"BCHUSDT","id":"10554000","side":"Sell"}],"update":[{"price":"1054.25","symbol":"BCHUSDT","id":"10542500","side":"Buy","size":13.68},{"price":"1054.20","symbol":"BCHUSDT","id":"10542000","side":"Buy","size":15.28},{"price":"1054.10","symbol":"BCHUSDT","id":"10541000","side":"Buy","size":2.15},{"price":"1054.05","symbol":"BCHUSDT","id":"10540500","side":"Buy","size":40.54},{"price":"1054.30","symbol":"BCHUSDT","id":"10543000","side":"Buy","size":18.68},{"price":"1054.15","symbol":"BCHUSDT","id":"10541500","side":"Buy","size":12.35},{"price":"1054.75","symbol":"BCHUSDT","id":"10547500","side":"Buy","size":15.150001}],"insert":[{"price":"1053.65","symbol":"BCHUSDT","id":"10536500","side":"Buy","size":4.55},{"price":"1055.20","symbol":"BCHUSDT","id":"10552000","side":"Sell","size":13.910001},{"price":"1055.35","symbol":"BCHUSDT","id":"10553500","side":"Sell","size":5.55},{"price":"1055.45","symbol":"BCHUSDT","id":"10554500","side":"Sell","size":2.15}]},"cross_seq":"864132836","timestamp_e6":"1618677792108793"}
1618677792.201901: {"topic":"orderBookL2_25.LTCUSDT","type":"delta","data":{"delete":[{"price":"313.40","symbol":"LTCUSDT","id":"3134000","side":"Sell"}],"update":[{"price":"313.39","symbol":"LTCUSDT","id":"3133900","side":"Sell","size":80.3},{"price":"313.42","symbol":"LTCUSDT","id":"3134200","side":"Sell","size":153.3},{"price":"313.34","symbol":"LTCUSDT","id":"3133400","side":"Buy","size":145.3},{"price":"313.30","symbol":"LTCUSDT","id":"3133000","side":"Buy","size":48.300003}],"insert":[{"price":"313.61","symbol":"LTCUSDT","id":"3136100","side":"Sell","size":256.3}]},"cross_seq":"1684523226","timestamp_e6":"1618677792119052"}
1618677792.207104: {"topic":"orderBookL2_25.UNIUSDT","type":"delta","data":{"delete":[{"price":"35.383","symbol":"UNIUSDT","id":"353830","side":"Buy"},{"price":"35.381","symbol":"UNIUSDT","id":"353810","side":"Buy"},{"price":"35.382","symbol":"UNIUSDT","id":"353820","side":"Buy"}],"update":[{"price":"35.407","symbol":"UNIUSDT","id":"354070","side":"Sell","size":105.9},{"price":"35.406","symbol":"UNIUSDT","id":"354060","side":"Sell","size":144.2},{"price":"35.379","symbol":"UNIUSDT","id":"353790","side":"Buy","size":71.9},{"price":"35.374","symbol":"UNIUSDT","id":"353740","side":"Buy","size":49.6}],"insert":[{"price":"35.358","symbol":"UNIUSDT","id":"353580","side":"Buy","size":20.4},{"price":"35.360","symbol":"UNIUSDT","id":"353600","side":"Buy","size":20.5},{"price":"35.359","symbol":"UNIUSDT","id":"353590","side":"Buy","size":579.4}]},"cross_seq":"916954440","timestamp_e6":"1618677792122366"}
1618677792.2094872: {"topic":"orderBookL2_25.LINKUSDT","type":"delta","data":{"delete":[],"update":[{"price":"41.045","symbol":"LINKUSDT","id":"410450","side":"Buy","size":606.4}],"insert":[]},"cross_seq":"1970980065","timestamp_e6":"1618677792126018"}
1618677792.234185: {"topic":"orderBookL2_25.ETHUSDT","type":"delta","data":{"delete":[{"price":"2364.75","symbol":"ETHUSDT","id":"23647500","side":"Buy"}],"update":[],"insert":[{"price":"2363.25","symbol":"ETHUSDT","id":"23632500","side":"Buy","size":129.70999}]},"cross_seq":"1800546717","timestamp_e6":"1618677792150439"}
1618677792.279129: {"topic":"orderBookL2_25.XTZUSDT","type":"delta","data":{"delete":[],"update":[{"price":"7.205","symbol":"XTZUSDT","id":"72050","side":"Buy","size":2328.1},{"price":"7.204","symbol":"XTZUSDT","id":"72040","side":"Buy","size":809.1},{"price":"7.218","symbol":"XTZUSDT","id":"72180","side":"Sell","size":1960.7999},{"price":"7.216","symbol":"XTZUSDT","id":"72160","side":"Sell","size":2266.5},{"price":"7.206","symbol":"XTZUSDT","id":"72060","side":"Buy","size":1375},{"price":"7.219","symbol":"XTZUSDT","id":"72190","side":"Sell","size":1433.6},{"price":"7.217","symbol":"XTZUSDT","id":"72170","side":"Sell","size":540.3},{"price":"7.209","symbol":"XTZUSDT","id":"72090","side":"Buy","size":1071.9},{"price":"7.215","symbol":"XTZUSDT","id":"72150","side":"Sell","size":924.10004},{"price":"7.207","symbol":"XTZUSDT","id":"72070","side":"Buy","size":752.1},{"price":"7.208","symbol":"XTZUSDT","id":"72080","side":"Buy","size":672.3}],"insert":[]},"cross_seq":"726228477","timestamp_e6":"1618677792194847"}
1618677792.306937: {"topic":"orderBookL2_25.ADAUSDT","type":"delta","data":{"delete":[],"update":[{"price":"1.3882","symbol":"ADAUSDT","id":"13882","side":"Sell","size":3144.0002}],"insert":[]},"cross_seq":"916954441","timestamp_e6":"1618677792222352"}
1618677792.3311849: {"topic":"orderBookL2_25.ETHUSDT","type":"delta","data":{"delete":[{"price":"2363.25","symbol":"ETHUSDT","id":"23632500","side":"Buy"}],"update":[{"price":"2364.20","symbol":"ETHUSDT","id":"23642000","side":"Buy","size":146.93001},{"price":"2364.35","symbol":"ETHUSDT","id":"23643500","side":"Buy","size":33.62}],"insert":[{"price":"2364.25","symbol":"ETHUSDT","id":"23642500","side":"Buy","size":72.53}]},"cross_seq":"1800546725","timestamp_e6":"1618677792248249"}
1618677792.354485: {"topic":"orderBookL2_25.BCHUSDT","type":"delta","data":{"delete":[{"price":"1054.95","symbol":"BCHUSDT","id":"10549500","side":"Buy"},{"price":"1056.50","symbol":"BCHUSDT","id":"10565000","side":"Sell"},{"price":"1055.25","symbol":"BCHUSDT","id":"10552500","side":"Sell"}],"update":[{"price":"1055.35","symbol":"BCHUSDT","id":"10553500","side":"Sell","size":8.39},{"price":"1054.65","symbol":"BCHUSDT","id":"10546500","side":"Buy","size":8.8}],"insert":[{"price":"1054.90","symbol":"BCHUSDT","id":"10549000","side":"Buy","size":17.02},{"price":"1055.30","symbol":"BCHUSDT","id":"10553000","side":"Sell","size":11.96},{"price":"1055.40","symbol":"BCHUSDT","id":"10554000","side":"Sell","size":5.55}]},"cross_seq":"864132843","timestamp_e6":"1618677792270930"}
1618677792.358516: {"topic":"orderBookL2_25.XTZUSDT","type":"delta","data":{"delete":[{"price":"7.209","symbol":"XTZUSDT","id":"72090","side":"Buy"}],"update":[{"price":"7.206","symbol":"XTZUSDT","id":"72060","side":"Buy","size":1018.4},{"price":"7.205","symbol":"XTZUSDT","id":"72050","side":"Buy","size":1669.9}],"insert":[{"price":"7.210","symbol":"XTZUSDT","id":"72100","side":"Buy","size":1071.9}]},"cross_seq":"726228481","timestamp_e6":"1618677792274601"}
1618677792.3670862: {"topic":"orderBookL2_25.DOTUSDT","type":"delta","data":{"delete":[],"update":[{"price":"43.575","symbol":"DOTUSDT","id":"435750","side":"Sell","size":202.3},{"price":"43.570","symbol":"DOTUSDT","id":"435700","side":"Sell","size":160.6},{"price":"43.555","symbol":"DOTUSDT","id":"435550","side":"Sell","size":745.9},{"price":"43.515","symbol":"DOTUSDT","id":"435150","side":"Buy","size":472.6},{"price":"43.560","symbol":"DOTUSDT","id":"435600","side":"Sell","size":977.1},{"price":"43.520","symbol":"DOTUSDT","id":"435200","side":"Buy","size":525.6},{"price":"43.510","symbol":"DOTUSDT","id":"435100","side":"Buy","size":209},{"price":"43.565","symbol":"DOTUSDT","id":"435650","side":"Sell","size":273.7}],"insert":[]},"cross_seq":"916954450","timestamp_e6":"1618677792282367"}
1618677792.36813: {"topic":"orderBookL2_25.LINKUSDT","type":"delta","data":{"delete":[{"price":"41.050","symbol":"LINKUSDT","id":"410500","side":"Sell"},{"price":"41.040","symbol":"LINKUSDT","id":"410400","side":"Buy"},{"price":"41.051","symbol":"LINKUSDT","id":"410510","side":"Sell"},{"price":"41.049","symbol":"LINKUSDT","id":"410490","side":"Sell"},{"price":"41.048","symbol":"LINKUSDT","id":"410480","side":"Sell"},{"price":"41.052","symbol":"LINKUSDT","id":"410520","side":"Sell"}],"update":[{"price":"41.042","symbol":"LINKUSDT","id":"410420","side":"Buy","size":235.90001},{"price":"41.041","symbol":"LINKUSDT","id":"410410","side":"Buy","size":125},{"price":"41.043","symbol":"LINKUSDT","id":"410430","side":"Buy","size":214.3}],"insert":[{"price":"41.074","symbol":"LINKUSDT","id":"410740","side":"Sell","size":180.90001},{"price":"41.073","symbol":"LINKUSDT","id":"410730","side":"Sell","size":194.40001},{"price":"41.071","symbol":"LINKUSDT","id":"410710","side":"Sell","size":314.9},{"price":"41.072","symbol":"LINKUSDT","id":"410720","side":"Sell","size":188.3},{"price":"41.075","symbol":"LINKUSDT","id":"410750","side":"Sell","size":8.3},{"price":"41.020","symbol":"LINKUSDT","id":"410200","side":"Buy","size":331.5}]},"cross_seq":"1970980074","timestamp_e6":"1618677792283732"}
1618677792.36926: {"topic":"orderBookL2_25.ETHUSDT","type":"delta","data":{"delete":[],"update":[{"price":"2365.85","symbol":"ETHUSDT","id":"23658500","side":"Sell","size":59.53}],"insert":[]},"cross_seq":"1800546726","timestamp_e6":"1618677792287115"}
1618677792.375231: {"topic":"orderBookL2_25.BCHUSDT","type":"delta","data":{"delete":[{"price":"1055.20","symbol":"BCHUSDT","id":"10552000","side":"Sell"}],"update":[],"insert":[{"price":"1055.25","symbol":"BCHUSDT","id":"10552500","side":"Sell","size":11.54}]},"cross_seq":"864132845","timestamp_e6":"1618677792288836"}
1618677792.382208: {"topic":"orderBookL2_25.LTCUSDT","type":"delta","data":{"delete":[{"price":"313.61","symbol":"LTCUSDT","id":"3136100","side":"Sell"},{"price":"313.37","symbol":"LTCUSDT","id":"3133700","side":"Sell"}],"update":[{"price":"313.41","symbol":"LTCUSDT","id":"3134100","side":"Sell","size":161.1},{"price":"313.30","symbol":"LTCUSDT","id":"3133000","side":"Buy","size":68.5},{"price":"313.39","symbol":"LTCUSDT","id":"3133900","side":"Sell","size":34},{"price":"313.36","symbol":"LTCUSDT","id":"3133600","side":"Sell","size":126.6}],"insert":[{"price":"313.38","symbol":"LTCUSDT","id":"3133800","side":"Sell","size":55.5},{"price":"313.40","symbol":"LTCUSDT","id":"3134000","side":"Sell","size":28.300001}]},"cross_seq":"1684523245","timestamp_e6":"1618677792298813"}
1618677792.3873122: {"topic":"orderBookL2_25.LINKUSDT","type":"delta","data":{"delete":[{"price":"41.047","symbol":"LINKUSDT","id":"410470","side":"Sell"},{"price":"41.020","symbol":"LINKUSDT","id":"410200","side":"Buy"},{"price":"41.073","symbol":"LINKUSDT","id":"410730","side":"Sell"},{"price":"41.074","symbol":"LINKUSDT","id":"410740","side":"Sell"},{"price":"41.072","symbol":"LINKUSDT","id":"410720","side":"Sell"},{"price":"41.075","symbol":"LINKUSDT","id":"410750","side":"Sell"}],"update":[],"insert":[{"price":"41.052","symbol":"LINKUSDT","id":"410520","side":"Sell","size":95.1},{"price":"41.040","symbol":"LINKUSDT","id":"410400","side":"Buy","size":108.8},{"price":"41.050","symbol":"LINKUSDT","id":"410500","side":"Sell","size":120.8},{"price":"41.049","symbol":"LINKUSDT","id":"410490","side":"Sell","size":98.4},{"price":"41.048","symbol":"LINKUSDT","id":"410480","side":"Sell","size":200.6},{"price":"41.051","symbol":"LINKUSDT","id":"410510","side":"Sell","size":48}]},"cross_seq":"1970980081","timestamp_e6":"1618677792303675"}
1618677792.391673: {"topic":"orderBookL2_25.ETHUSDT","type":"delta","data":{"delete":[{"price":"2363.95","symbol":"ETHUSDT","id":"23639500","side":"Buy"}],"update":[{"price":"2364.20","symbol":"ETHUSDT","id":"23642000","side":"Buy","size":155.77},{"price":"2365.00","symbol":"ETHUSDT","id":"23650000","side":"Sell","size":166.37},{"price":"2364.05","symbol":"ETHUSDT","id":"23640500","side":"Buy","size":102.01},{"price":"2365.05","symbol":"ETHUSDT","id":"23650500","side":"Sell","size":123.66},{"price":"2364.10","symbol":"ETHUSDT","id":"23641000","side":"Buy","size":135.06},{"price":"2364.00","symbol":"ETHUSDT","id":"23640000","side":"Buy","size":44.519997},{"price":"2365.10","symbol":"ETHUSDT","id":"23651000","side":"Sell","size":134.63},{"price":"2364.40","symbol":"ETHUSDT","id":"23644000","side":"Buy","size":1.19},{"price":"2364.95","symbol":"ETHUSDT","id":"23649500","side":"Sell","size":303.47998},{"price":"2365.15","symbol":"ETHUSDT","id":"23651500","side":"Sell","size":106.33},{"price":"2365.20","symbol":"ETHUSDT","id":"23652000","side":"Sell","size":60.690002}],"insert":[{"price":"2364.15","symbol":"ETHUSDT","id":"23641500","side":"Buy","size":61.82}]},"cross_seq":"1800546765","timestamp_e6":"1618677792307452"}
1618677792.3917608: {"topic":"orderBookL2_25.BCHUSDT","type":"delta","data":{"delete":[{"price":"1054.80","symbol":"BCHUSDT","id":"10548000","side":"Buy"},{"price":"1055.40","symbol":"BCHUSDT","id":"10554000","side":"Sell"},{"price":"1055.30","symbol":"BCHUSDT","id":"10553000","side":"Sell"}],"update":[{"price":"1055.45","symbol":"BCHUSDT","id":"10554500","side":"Sell","size":5.89},{"price":"1054.75","symbol":"BCHUSDT","id":"10547500","side":"Buy","size":13.870001}],"insert":[{"price":"1056.55","symbol":"BCHUSDT","id":"10565500","side":"Sell","size":10.5},{"price":"1054.60","symbol":"BCHUSDT","id":"10546000","side":"Buy","size":5.47},{"price":"1056.50","symbol":"BCHUSDT","id":"10565000","side":"Sell","size":30.32}]},"cross_seq":"864132852","timestamp_e6":"1618677792309288"}
1618677792.410868: {"topic":"orderBookL2_25.ETHUSDT","type":"delta","data":{"delete":[],"update":[{"price":"2364.10","symbol":"ETHUSDT","id":"23641000","side":"Buy","size":198.92001}],"insert":[]},"cross_seq":"1800546766","timestamp_e6":"1618677792327672"}
1618677792.424792: {"topic":"orderBookL2_25.LTCUSDT","type":"delta","data":{"delete":[{"price":"313.60","symbol":"LTCUSDT","id":"3136000","side":"Sell"}],"update":[{"price":"313.34","symbol":"LTCUSDT","id":"3133400","side":"Buy","size":295.3},{"price":"313.39","symbol":"LTCUSDT","id":"3133900","side":"Sell","size":55.5},{"price":"313.43","symbol":"LTCUSDT","id":"3134300","side":"Sell","size":99.5},{"price":"313.40","symbol":"LTCUSDT","id":"3134000","side":"Sell","size":68.9},{"price":"313.23","symbol":"LTCUSDT","id":"3132300","side":"Buy","size":23.4},{"price":"313.36","symbol":"LTCUSDT","id":"3133600","side":"Sell","size":1.5},{"price":"313.41","symbol":"LTCUSDT","id":"3134100","side":"Sell","size":213.2},{"price":"313.35","symbol":"LTCUSDT","id":"3133500","side":"Sell","size":127.1},{"price":"313.38","symbol":"LTCUSDT","id":"3133800","side":"Sell","size":87.3}],"insert":[{"price":"313.37","symbol":"LTCUSDT","id":"3133700","side":"Sell","size":125.1}]},"cross_seq":"1684523259","timestamp_e6":"1618677792340917"}
1618677792.425905: {"topic":"orderBookL2_25.ADAUSDT","type":"delta","data":{"delete":[],"update":[{"price":"1.3880","symbol":"ADAUSDT","id":"13880","side":"Sell","size":3387},{"price":"1.3865","symbol":"ADAUSDT","id":"13865","side":"Buy","size":5726.9995},{"price":"1.3866","symbol":"ADAUSDT","id":"13866","side":"Buy","size":4937},{"price":"1.3881","symbol":"ADAUSDT","id":"13881","side":"Sell","size":3036.9998},{"price":"1.3864","symbol":"ADAUSDT","id":"13864","side":"Buy","size":4861},{"price":"1.3878","symbol":"ADAUSDT","id":"13878","side":"Sell","size":10236}],"insert":[]},"cross_seq":"916954456","timestamp_e6":"1618677792342360"}
1618677792.451922: {"topic":"orderBookL2_25.BCHUSDT","type":"delta","data":{"delete":[],"update":[{"price":"1054.25","symbol":"BCHUSDT","id":"10542500","side":"Buy","size":27.980001},{"price":"1054.10","symbol":"BCHUSDT","id":"10541000","side":"Buy","size":10.16}],"insert":[]},"cross_seq":"864132855","timestamp_e6":"1618677792368953"}
1618677792.464444: {"topic":"orderBookL2_25.LTCUSDT","type":"delta","data":{"delete":[],"update":[{"price":"313.13","symbol":"LTCUSDT","id":"3131300","side":"Buy","size":150.2}],"insert":[]},"cross_seq":"1684523268","timestamp_e6":"1618677792378534"}
1618677792.484939: {"topic":"orderBookL2_25.LTCUSDT","type":"delta","data":{"delete":[{"price":"313.37","symbol":"LTCUSDT","id":"3133700","side":"Sell"},{"price":"313.39","symbol":"LTCUSDT","id":"3133900","side":"Sell"},{"price":"313.38","symbol":"LTCUSDT","id":"3133800","side":"Sell"}],"update":[{"price":"313.45","symbol":"LTCUSDT","id":"3134500","side":"Sell","size":106.4},{"price":"313.42","symbol":"LTCUSDT","id":"3134200","side":"Sell","size":168.4},{"price":"313.44","symbol":"LTCUSDT","id":"3134400","side":"Sell","size":140.2},{"price":"313.46","symbol":"LTCUSDT","id":"3134600","side":"Sell","size":64.4},{"price":"313.43","symbol":"LTCUSDT","id":"3134300","side":"Sell","size":169.9},{"price":"313.35","symbol":"LTCUSDT","id":"3133500","side":"Sell","size":2.1}],"insert":[{"price":"313.61","symbol":"LTCUSDT","id":"3136100","side":"Sell","size":256.3},{"price":"313.62","symbol":"LTCUSDT","id":"3136200","side":"Sell","size":229.8},{"price":"313.60","symbol":"LTCUSDT","id":"3136000","side":"Sell","size":97.299995}]},"cross_seq":"1684523285","timestamp_e6":"1618677792400544"}
1618677792.48586: {"topic":"orderBookL2_25.ADAUSDT","type":"delta","data":{"delete":[{"price":"1.3846","symbol":"ADAUSDT","id":"13846","side":"Buy"},{"price":"1.3845","symbol":"ADAUSDT","id":"13845","side":"Buy"}],"update":[{"price":"1.3880","symbol":"ADAUSDT","id":"13880","side":"Sell","size":3742.9998},{"price":"1.3865","symbol":"ADAUSDT","id":"13865","side":"Buy","size":1642},{"price":"1.3864","symbol":"ADAUSDT","id":"13864","side":"Buy","size":8027},{"price":"1.3869","symbol":"ADAUSDT","id":"13869","side":"Buy","size":22378.002},{"price":"1.3881","symbol":"ADAUSDT","id":"13881","side":"Sell","size":3327}],"insert":[{"price":"1.3861","symbol":"ADAUSDT","id":"13861","side":"Buy","size":6054},{"price":"1.3860","symbol":"ADAUSDT","id":"13860","side":"Buy","size":6417}]},"cross_seq":"916954465","timestamp_e6":"1618677792402360"}
1618677792.4924438: {"topic":"orderBookL2_25.ETHUSDT","type":"delta","data":{"delete":[{"price":"2364.30","symbol":"ETHUSDT","id":"23643000","side":"Buy"},{"price":"2364.35","symbol":"ETHUSDT","id":"23643500","side":"Buy"},{"price":"2364.25","symbol":"ETHUSDT","id":"23642500","side":"Buy"}],"update":[{"price":"2365.10","symbol":"ETHUSDT","id":"23651000","side":"Sell","size":85.19},{"price":"2364.00","symbol":"ETHUSDT","id":"23640000","side":"Buy","size":133.88},{"price":"2364.10","symbol":"ETHUSDT","id":"23641000","side":"Buy","size":246.04001},{"price":"2365.15","symbol":"ETHUSDT","id":"23651500","side":"Sell","size":44.08},{"price":"2364.90","symbol":"ETHUSDT","id":"23649000","side":"Buy","size":56.42},{"price":"2365.00","symbol":"ETHUSDT","id":"23650000","side":"Sell","size":136.48},{"price":"2365.05","symbol":"ETHUSDT","id":"23650500","side":"Sell","size":78.61},{"price":"2364.95","symbol":"ETHUSDT","id":"23649500","side":"Sell","size":352.43},{"price":"2365.20","symbol":"ETHUSDT","id":"23652000","side":"Sell","size":77.299995},{"price":"2364.05","symbol":"ETHUSDT","id":"23640500","side":"Buy","size":138.7},{"price":"2364.15","symbol":"ETHUSDT","id":"23641500","side":"Buy","size":47.670002}],"insert":[{"price":"2363.20","symbol":"ETHUSDT","id":"23632000","side":"Buy","size":51.6},{"price":"2363.95","symbol":"ETHUSDT","id":"23639500","side":"Buy","size":54.989998},{"price":"2363.25","symbol":"ETHUSDT","id":"23632500","side":"Buy","size":129.70999}]},"cross_seq":"1800546794","timestamp_e6":"1618677792408736"}
1618677792.4925508: {"topic":"orderBookL2_25.BCHUSDT","type":"delta","data":{"delete":[{"price":"1054.90","symbol":"BCHUSDT","id":"10549000","side":"Buy"},{"price":"1054.55","symbol":"BCHUSDT","id":"10545500","side":"Buy"},{"price":"1054.85","symbol":"BCHUSDT","id":"10548500","side":"Buy"},{"price":"1055.45","symbol":"BCHUSDT","id":"10554500","side":"Sell"},{"price":"1056.55","symbol":"BCHUSDT","id":"10565500","side":"Sell"},{"price":"1055.25","symbol":"BCHUSDT","id":"10552500","side":"Sell"}],"update":[{"price":"1054.40","symbol":"BCHUSDT","id":"10544000","side":"Buy","size":20.74},{"price":"1054.15","symbol":"BCHUSDT","id":"10541500","side":"Buy","size":1},{"price":"1054.30","symbol":"BCHUSDT","id":"10543000","side":"Buy","size":1.47},{"price":"1055.35","symbol":"BCHUSDT","id":"10553500","side":"Sell","size":2.84},{"price":"1054.25","symbol":"BCHUSDT","id":"10542500","side":"Buy","size":13.68},{"price":"1054.20","symbol":"BCHUSDT","id":"10542000","side":"Buy","size":3.03},{"price":"1054.35","symbol":"BCHUSDT","id":"10543500","side":"Buy","size":16.52}],"insert":[{"price":"1053.55","symbol":"BCHUSDT","id":"10535500","side":"Buy","size":9.9},{"price":"1053.60","symbol":"BCHUSDT","id":"10536000","side":"Buy","size":4.35},{"price":"1055.30","symbol":"BCHUSDT","id":"10553000","side":"Sell","size":7.36},{"price":"1055.40","symbol":"BCHUSDT","id":"10554000","side":"Sell","size":5.89},{"price":"1054.80","symbol":"BCHUSDT","id":"10548000","side":"Buy","size":13.31},{"price":"1055.20","symbol":"BCHUSDT","id":"10552000","side":"Sell","size":11.54}]},"cross_seq":"864132876","timestamp_e6":"1618677792409930"}
1618677792.498743: {"topic":"orderBookL2_25.XTZUSDT","type":"delta","data":{"delete":[{"price":"7.207","symbol":"XTZUSDT","id":"72070","side":"Buy"},{"price":"7.210","symbol":"XTZUSDT","id":"72100","side":"Buy"}],"update":[{"price":"7.211","symbol":"XTZUSDT","id":"72110","side":"Buy","size":1072.1}],"insert":[{"price":"7.185","symbol":"XTZUSDT","id":"71850","side":"Buy","size":1327.3},{"price":"7.209","symbol":"XTZUSDT","id":"72090","side":"Buy","size":819.30005}]},"cross_seq":"726228501","timestamp_e6":"1618677792415157"}
1618677792.503031: {"topic":"orderBookL2_25.LTCUSDT","type":"delta","data":{"delete":[{"price":"313.40","symbol":"LTCUSDT","id":"3134000","side":"Sell"}],"update":[{"price":"313.34","symbol":"LTCUSDT","id":"3133400","side":"Buy","size":358.4},{"price":"313.43","symbol":"LTCUSDT","id":"3134300","side":"Sell","size":82.6},{"price":"313.46","symbol":"LTCUSDT","id":"3134600","side":"Sell","size":92.3},{"price":"313.48","symbol":"LTCUSDT","id":"3134800","side":"Sell","size":79.1},{"price":"313.41","symbol":"LTCUSDT","id":"3134100","side":"Sell","size":88.2},{"price":"313.44","symbol":"LTCUSDT","id":"3134400","side":"Sell","size":172.00002},{"price":"313.47","symbol":"LTCUSDT","id":"3134700","side":"Sell","size":75.2}],"insert":[{"price":"313.63","symbol":"LTCUSDT","id":"3136300","side":"Sell","size":48.999996}]},"cross_seq":"1684523315","timestamp_e6":"1618677792419571"}
1618677792.5233831: {"topic":"orderBookL2_25.LTCUSDT","type":"delta","data":{"delete":[{"price":"313.41","symbol":"LTCUSDT","id":"3134100","side":"Sell"}],"update":[{"price":"313.44","symbol":"LTCUSDT","id":"3134400","side":"Sell","size":128.5},{"price":"313.45","symbol":"LTCUSDT","id":"3134500","side":"Sell","size":142.9},{"price":"313.42","symbol":"LTCUSDT","id":"3134200","side":"Sell","size":70.200005},{"price":"313.48","symbol":"LTCUSDT","id":"3134800","side":"Sell","size":96.9},{"price":"313.34","symbol":"LTCUSDT","id":"3133400","side":"Buy","size":483.4}],"insert":[{"price":"313.64","symbol":"LTCUSDT","id":"3136400","side":"Sell","size":25.500002}]},"cross_seq":"1684523332","timestamp_e6":"1618677792439005"}
1618677792.532925: {"topic":"orderBookL2_25.BCHUSDT","type":"delta","data":{"delete":[{"price":"1053.55","symbol":"BCHUSDT","id":"10535500","side":"Buy"}],"update":[],"insert":[{"price":"1054.95","symbol":"BCHUSDT","id":"10549500","side":"Buy","size":13.329999}]},"cross_seq":"864132877","timestamp_e6":"1618677792450469"}
