wss://stream.bybit.com/realtime_public <-> 1618677785.4827468
wss://stream.bybit.com/realtime_public <- 1618677786.460905: {"op":"subscribe","args":["trade.BCHUSDT"]}
wss://stream.bybit.com/realtime_public <- 1618677786.461026: {"op":"subscribe","args":["trade.XTZUSDT"]}
wss://stream.bybit.com/realtime_public <- 1618677786.461066: {"op":"subscribe","args":["trade.UNIUSDT"]}
wss://stream.bybit.com/realtime_public <- 1618677786.46112: {"op":"subscribe","args":["trade.LTCUSDT"]}
wss://stream.bybit.com/realtime_public <- 1618677786.461168: {"op":"subscribe","args":["trade.DOTUSDT"]}
wss://stream.bybit.com/realtime_public <- 1618677786.461199: {"op":"subscribe","args":["trade.LINKUSDT"]}
wss://stream.bybit.com/realtime_public <- 1618677786.461229: {"op":"subscribe","args":["trade.ADAUSDT"]}
wss://stream.bybit.com/realtime_public <- 1618677786.4612951: {"op":"subscribe","args":["trade.ETHUSDT"]}
wss://stream.bybit.com/realtime_public <- 1618677786.4613252: {"op":"subscribe","args":["orderBookL2_25.BCHUSDT"]}
wss://stream.bybit.com/realtime_public <- 1618677786.461418: {"op":"subscribe","args":["orderBookL2_25.XTZUSDT"]}
wss://stream.bybit.com/realtime_public <- 1618677786.4614668: {"op":"subscribe","args":["orderBookL2_25.UNIUSDT"]}
wss://stream.bybit.com/realtime_public <- 1618677786.461497: {"op":"subscribe","args":["orderBookL2_25.LTCUSDT"]}
wss://stream.bybit.com/realtime_public <- 1618677786.4615989: {"op":"subscribe","args":["orderBookL2_25.DOTUSDT"]}
wss://stream.bybit.com/realtime_public <- 1618677786.4616818: {"op":"subscribe","args":["orderBookL2_25.LINKUSDT"]}
wss://stream.bybit.com/realtime_public <- 1618677786.4617112: {"op":"subscribe","args":["orderBookL2_25.ADAUSDT"]}
wss://stream.bybit.com/realtime_public <- 1618677786.46174: {"op":"subscribe","args":["orderBookL2_25.ETHUSDT"]}
1618677786.799668: {"topic":"trade.BCHUSDT","data":[{"symbol":"BCHUSDT","tick_direction":"MinusTick","price":"1053.90","size":0.14,"timestamp":"2021-04-17T16:43:05.000Z","trade_time_ms":"1618677785116","side":"Buy","trade_id":"01cacfe9-8d1c-5ee4-995d-d79a43f955a6"}]}
1618677786.799711: {"topic":"trade.BCHUSDT","data":[{"symbol":"BCHUSDT","tick_direction":"PlusTick","price":"1054.45","size":0.82,"timestamp":"2021-04-17T16:43:05.000Z","trade_time_ms":"1618677785948","side":"Sell","trade_id":"a6492be8-54bb-55b2-8b46-69ad3c70a3b5"}]}
1618677786.799724: {"success":true,"ret_msg":"","conn_id":"38cf0ac3-af67-483c-9bbc-b57d45910ecb","request":{"op":"subscribe","args":["trade.BCHUSDT"]}}
1618677786.799731: {"topic":"trade.XTZUSDT","data":[{"symbol":"XTZUSDT","tick_direction":"MinusTick","price":"7.207","size":0.9,"timestamp":"2021-04-17T16:43:04.000Z","trade_time_ms":"1618677784983","side":"Sell","trade_id":"34a0c539-d0f2-5fac-8ceb-0737c5e36a0f"}]}
1618677786.7997398: {"success":true,"ret_msg":"","conn_id":"38cf0ac3-af67-483c-9bbc-b57d45910ecb","request":{"op":"subscribe","args":["trade.XTZUSDT"]}}
1618677786.799745: {"topic":"trade.UNIUSDT","data":[{"symbol":"UNIUSDT","tick_direction":"PlusTick","price":"35.402","size":0.8,"timestamp":"2021-04-17T16:43:01.000Z","trade_time_ms":"1618677781355","side":"Buy","trade_id":"21e82307-f328-5fbc-8566-b3823e847b48"}]}
1618677786.799755: {"success":true,"ret_msg":"","conn_id":"38cf0ac3-af67-483c-9bbc-b57d45910ecb","request":{"op":"subscribe","args":["trade.UNIUSDT"]}}
1618677786.7997591: {"topic":"trade.LTCUSDT","data":[{"symbol":"LTCUSDT","tick_direction":"PlusTick","price":"313.14","size":0.6,"timestamp":"2021-04-17T16:43:00.000Z","trade_time_ms":"1618677780476","side":"Sell","trade_id":"55e1cea6-bef5-5490-ae71-06160f62f99d"}]}
1618677786.799767: {"success":true,"ret_msg":"","conn_id":"38cf0ac3-af67-483c-9bbc-b57d45910ecb","request":{"op":"subscribe","args":["trade.LTCUSDT"]}}
1618677786.7997718: {"topic":"trade.DOTUSDT","data":[{"symbol":"DOTUSDT","tick_direction":"PlusTick","price":"43.550","size":7.9,"timestamp":"2021-04-17T16:42:24.000Z","trade_time_ms":"1618677744728","side":"Buy","trade_id":"095123ba-e427-5230-9977-40f392033898"}]}
1618677786.7997792: {"success":true,"ret_msg":"","conn_id":"38cf0ac3-af67-483c-9bbc-b57d45910ecb","request":{"op":"subscribe","args":["trade.DOTUSDT"]}}
1618677786.8012931: {"topic":"trade.LINKUSDT","data":[{"symbol":"LINKUSDT","tick_direction":"ZeroPlusTick","price":"41.083","size":0.1,"timestamp":"2021-04-17T16:42:37.000Z","trade_time_ms":"1618677757982","side":"Buy","trade_id":"75b52c9f-92bb-57ed-bbed-4c43109358cf"}]}
1618677786.8013172: {"success":true,"ret_msg":"","conn_id":"38cf0ac3-af67-483c-9bbc-b57d45910ecb","request":{"op":"subscribe","args":["trade.LINKUSDT"]}}
1618677786.801325: {"topic":"trade.ADAUSDT","data":[{"symbol":"ADAUSDT","tick_direction":"ZeroPlusTick","price":"1.3873","size":1,"timestamp":"2021-04-17T16:43:00.000Z","trade_time_ms":"1618677780318","side":"Buy","trade_id":"650a9b1c-1b9e-5c28-9a23-9283874f5dde"}]}
1618677786.801336: {"success":true,"ret_msg":"","conn_id":"38cf0ac3-af67-483c-9bbc-b57d45910ecb","request":{"op":"subscribe","args":["trade.ADAUSDT"]}}
1618677786.8013408: {"topic":"trade.ETHUSDT","data":[{"symbol":"ETHUSDT","tick_direction":"ZeroMinusTick","price":"2365.00","size":0.23,"timestamp":"2021-04-17T16:43:04.000Z","trade_time_ms":"1618677784506","side":"Sell","trade_id":"b862869b-24da-5eef-b6fa-bfbe32cbfc69"}]}
1618677786.982359: {"topic":"trade.ETHUSDT","data":[{"symbol":"ETHUSDT","tick_direction":"MinusTick","price":"2364.95","size":0.13,"timestamp":"2021-04-17T16:43:04.000Z","trade_time_ms":"1618677784718","side":"Buy","trade_id":"31bf45b7-a295-52fb-a4f5-274679cb9fe4"}]}
1618677786.9823968: {"success":true,"ret_msg":"","conn_id":"38cf0ac3-af67-483c-9bbc-b57d45910ecb","request":{"op":"subscribe","args":["trade.ETHUSDT"]}}
1618677786.9824052: {"topic":"orderBookL2_25.BCHUSDT","type":"snapshot","data":{"order_book":[{"price":"1053.05","symbol":"BCHUSDT","id":"10530500","side":"Buy","size":2.63},{"price":"1053.10","symbol":"BCHUSDT","id":"10531000","side":"Buy","size":5.48},{"price":"1053.15","symbol":"BCHUSDT","id":"10531500","side":"Buy","size":17.9},{"price":"1053.20","symbol":"BCHUSDT","id":"10532000","side":"Buy","size":8.37},{"price":"1053.25","symbol":"BCHUSDT","id":"10532500","side":"Buy","size":3.88},{"price":"1053.30","symbol":"BCHUSDT","id":"10533000","side":"Buy","size":2.92},{"price":"1053.35","symbol":"BCHUSDT","id":"10533500","side":"Buy","size":6.09},{"price":"1053.40","symbol":"BCHUSDT","id":"10534000","side":"Buy","size":18.35},{"price":"1053.45","symbol":"BCHUSDT","id":"10534500","side":"Buy","size":9.02},{"price":"1053.50","symbol":"BCHUSDT","id":"10535000","side":"Buy","size":19.92},{"price":"1053.55","symbol":"BCHUSDT","id":"10535500","side":"Buy","size":11.31},{"price":"1053.60","symbol":"BCHUSDT","id":"10536000","side":"Buy","size":6.85},{"price":"1053.65","symbol":"BCHUSDT","id":"10536500","side":"Buy","size":4.15},{"price":"1053.70","symbol":"BCHUSDT","id":"10537000","side":"Buy","size":18.72},{"price":"1053.75","symbol":"BCHUSDT","id":"10537500","side":"Buy","size":12.24},{"price":"1053.80","symbol":"BCHUSDT","id":"10538000","side":"Buy","size":13.64},{"price":"1053.85","symbol":"BCHUSDT","id":"10538500","side":"Buy","size":3.63},{"price":"1053.90","symbol":"BCHUSDT","id":"10539000","side":"Buy","size":6.22},{"price":"1053.95","symbol":"BCHUSDT","id":"10539500","side":"Buy","size":7.46},{"price":"1054.00","symbol":"BCHUSDT","id":"10540000","side":"Buy","size":7.5},{"price":"1054.05","symbol":"BCHUSDT","id":"10540500","side":"Buy","size":40.22},{"price":"1054.20","symbol":"BCHUSDT","id":"10542000","side":"Buy","size":3.63},{"price":"1054.25","symbol":"BCHUSDT","id":"10542500","side":"Buy","size":6.22},{"price":"1054.30","symbol":"BCHUSDT","id":"10543000","side":"Buy","size":7.5},{"price":"1054.35","symbol":"BCHUSDT","id":"10543500","side":"Buy","size":8.52},{"price":"1054.50","symbol":"BCHUSDT","id":"10545000","side":"Sell","size":30},{"price":"1054.70","symbol":"BCHUSDT","id":"10547000","side":"Sell","size":5},{"price":"1054.75","symbol":"BCHUSDT","id":"10547500","side":"Sell","size":3.71},{"price":"1054.85","symbol":"BCHUSDT","id":"10548500","side":"Sell","size":1.64},{"price":"1054.95","symbol":"BCHUSDT","id":"10549500","side":"Sell","size":9.25},{"price":"1055.00","symbol":"BCHUSDT","id":"10550000","side":"Sell","size":1.01},{"price":"1055.05","symbol":"BCHUSDT","id":"10550500","side":"Sell","size":9.62},{"price":"1055.10","symbol":"BCHUSDT","id":"10551000","side":"Sell","size":5.54},{"price":"1055.15","symbol":"BCHUSDT","id":"10551500","side":"Sell","size":12.849999},{"price":"1055.20","symbol":"BCHUSDT","id":"10552000","side":"Sell","size":1},{"price":"1055.25","symbol":"BCHUSDT","id":"10552500","side":"Sell","size":1},{"price":"1055.30","symbol":"BCHUSDT","id":"10553000","side":"Sell","size":1},{"price":"1055.35","symbol":"BCHUSDT","id":"10553500","side":"Sell","size":9.6},{"price":"1055.40","symbol":"BCHUSDT","id":"10554000","side":"Sell","size":2.22},{"price":"1055.45","symbol":"BCHUSDT","id":"10554500","side":"Sell","size":3.07},{"price":"1055.50","symbol":"BCHUSDT","id":"10555000","side":"Sell","size":4.42},{"price":"1055.55","symbol":"BCHUSDT","id":"10555500","side":"Sell","size":1},{"price":"1055.60","symbol":"BCHUSDT","id":"10556000","side":"Sell","size":1},{"price":"1055.65","symbol":"BCHUSDT","id":"10556500","side":"Sell","size":7.97},{"price":"1055.70","symbol":"BCHUSDT","id":"10557000","side":"Sell","size":10.990001},{"price":"1055.75","symbol":"BCHUSDT","id":"10557500","side":"Sell","size":4.12},{"price":"1055.80","symbol":"BCHUSDT","id":"10558000","side":"Sell","size":5.83},{"price":"1055.85","symbol":"BCHUSDT","id":"10558500","side":"Sell","size":15.6},{"price":"1055.90","symbol":"BCHUSDT","id":"10559000","side":"Sell","size":2.79},{"price":"1055.95","symbol":"BCHUSDT","id":"10559500","side":"Sell","size":29.04}]},"cross_seq":"864131773","timestamp_e6":"1618677786389362"}
1618677786.98285: {"topic":"orderBookL2_25.BCHUSDT","type":"delta","data":{"delete":[{"price":"1054.30","symbol":"BCHUSDT","id":"10543000","side":"Buy"},{"price":"1054.75","symbol":"BCHUSDT","id":"10547500","side":"Sell"},{"price":"1054.70","symbol":"BCHUSDT","id":"10547000","side":"Sell"},{"price":"1055.95","symbol":"BCHUSDT","id":"10559500","side":"Sell"},{"price":"1055.90","symbol":"BCHUSDT","id":"10559000","side":"Sell"},{"price":"1054.35","symbol":"BCHUSDT","id":"10543500","side":"Buy"},{"price":"1054.20","symbol":"BCHUSDT","id":"10542000","side":"Buy"},{"price":"1054.25","symbol":"BCHUSDT","id":"10542500","side":"Buy"}],"update":[{"price":"1053.90","symbol":"BCHUSDT","id":"10539000","side":"Buy","size":3.66}],"insert":[{"price":"1052.95","symbol":"BCHUSDT","id":"10529500","side":"Buy","size":20.3},{"price":"1054.65","symbol":"BCHUSDT","id":"10546500","side":"Sell","size":5},{"price":"1054.10","symbol":"BCHUSDT","id":"10541000","side":"Buy","size":10.17},{"price":"1054.60","symbol":"BCHUSDT","id":"10546000","side":"Sell","size":6.12},{"price":"1054.15","symbol":"BCHUSDT","id":"10541500","side":"Buy","size":10.969999},{"price":"1054.55","symbol":"BCHUSDT","id":"10545500","side":"Sell","size":9.78},{"price":"1053.00","symbol":"BCHUSDT","id":"10530000","side":"Buy","size":19.42},{"price":"1054.80","symbol":"BCHUSDT","id":"10548000","side":"Sell","size":1.64}]},"cross_seq":"864131802","timestamp_e6":"1618677786430132"}
1618677786.982956: {"topic":"orderBookL2_25.BCHUSDT","type":"delta","data":{"delete":[{"price":"1053.80","symbol":"BCHUSDT","id":"10538000","side":"Buy"},{"price":"1055.85","symbol":"BCHUSDT","id":"10558500","side":"Sell"},{"price":"1055.80","symbol":"BCHUSDT","id":"10558000","side":"Sell"}],"update":[{"price":"1053.75","symbol":"BCHUSDT","id":"10537500","side":"Buy","size":17.46},{"price":"1053.85","symbol":"BCHUSDT","id":"10538500","side":"Buy","size":8.85},{"price":"1053.90","symbol":"BCHUSDT","id":"10539000","side":"Buy","size":10.17},{"price":"1053.95","symbol":"BCHUSDT","id":"10539500","side":"Buy","size":3.51}],"insert":[{"price":"1054.70","symbol":"BCHUSDT","id":"10547000","side":"Sell","size":3.71},{"price":"1054.75","symbol":"BCHUSDT","id":"10547500","side":"Sell","size":1.97},{"price":"1052.90","symbol":"BCHUSDT","id":"10529000","side":"Buy","size":7.93}]},"cross_seq":"864131817","timestamp_e6":"1618677786548764"}
1618677786.982997: {"topic":"orderBookL2_25.BCHUSDT","type":"delta","data":{"delete":[{"price":"1053.90","symbol":"BCHUSDT","id":"10539000","side":"Buy"}],"update":[{"price":"1053.95","symbol":"BCHUSDT","id":"10539500","side":"Buy","size":6.22}],"insert":[{"price":"1054.30","symbol":"BCHUSDT","id":"10543000","side":"Buy","size":13.329999}]},"cross_seq":"864131821","timestamp_e6":"1618677786589984"}
1618677786.9830358: {"success":true,"ret_msg":"","conn_id":"38cf0ac3-af67-483c-9bbc-b57d45910ecb","request":{"op":"subscribe","args":["orderBookL2_25.BCHUSDT"]}}
1618677786.983059: {"topic":"orderBookL2_25.XTZUSDT","type":"snapshot","data":{"order_book":[{"price":"7.183","symbol":"XTZUSDT","id":"71830","side":"Buy","size":1145},{"price":"7.184","symbol":"XTZUSDT","id":"71840","side":"Buy","size":389},{"price":"7.185","symbol":"XTZUSDT","id":"71850","side":"Buy","size":1327.3},{"price":"7.186","symbol":"XTZUSDT","id":"71860","side":"Buy","size":387.6},{"price":"7.187","symbol":"XTZUSDT","id":"71870","side":"Buy","size":1945},{"price":"7.188","symbol":"XTZUSDT","id":"71880","side":"Buy","size":1227.5},{"price":"7.189","symbol":"XTZUSDT","id":"71890","side":"Buy","size":2236.8},{"price":"7.190","symbol":"XTZUSDT","id":"71900","side":"Buy","size":1193.4},{"price":"7.191","symbol":"XTZUSDT","id":"71910","side":"Buy","size":141.5},{"price":"7.192","symbol":"XTZUSDT","id":"71920","side":"Buy","size":2772},{"price":"7.193","symbol":"XTZUSDT","id":"71930","side":"Buy","size":686.39996},{"price":"7.194","symbol":"XTZUSDT","id":"71940","side":"Buy","size":1965.8},{"price":"7.195","symbol":"XTZUSDT","id":"71950","side":"Buy","size":1174.2},{"price":"7.196","symbol":"XTZUSDT","id":"71960","side":"Buy","size":1338},{"price":"7.197","symbol":"XTZUSDT","id":"71970","side":"Buy","size":204.8},{"price":"7.198","symbol":"XTZUSDT","id":"71980","side":"Buy","size":537.1},{"price":"7.199","symbol":"XTZUSDT","id":"71990","side":"Buy","size":1642.1},{"price":"7.200","symbol":"XTZUSDT","id":"72000","side":"Buy","size":1304.7001},{"price":"7.201","symbol":"XTZUSDT","id":"72010","side":"Buy","size":2165.9},{"price":"7.202","symbol":"XTZUSDT","id":"72020","side":"Buy","size":219.49998},{"price":"7.203","symbol":"XTZUSDT","id":"72030","side":"Buy","size":708.80005},{"price":"7.204","symbol":"XTZUSDT","id":"72040","side":"Buy","size":781.1},{"price":"7.205","symbol":"XTZUSDT","id":"72050","side":"Buy","size":1012.39996},{"price":"7.206","symbol":"XTZUSDT","id":"72060","side":"Buy","size":1321},{"price":"7.207","symbol":"XTZUSDT","id":"72070","side":"Buy","size":1851.4},{"price":"7.208","symbol":"XTZUSDT","id":"72080","side":"Sell","size":340},{"price":"7.210","symbol":"XTZUSDT","id":"72100","side":"Sell","size":1075.2},{"price":"7.211","symbol":"XTZUSDT","id":"72110","side":"Sell","size":1018.10004},{"price":"7.212","symbol":"XTZUSDT","id":"72120","side":"Sell","size":1449.2001},{"price":"7.213","symbol":"XTZUSDT","id":"72130","side":"Sell","size":0.4},{"price":"7.214","symbol":"XTZUSDT","id":"72140","side":"Sell","size":1277.4},{"price":"7.215","symbol":"XTZUSDT","id":"72150","side":"Sell","size":1340.7001},{"price":"7.216","symbol":"XTZUSDT","id":"72160","side":"Sell","size":1181.7001},{"price":"7.217","symbol":"XTZUSDT","id":"72170","side":"Sell","size":1050.3},{"price":"7.218","symbol":"XTZUSDT","id":"72180","side":"Sell","size":1927.5},{"price":"7.219","symbol":"XTZUSDT","id":"72190","side":"Sell","size":1706.1},{"price":"7.220","symbol":"XTZUSDT","id":"72200","side":"Sell","size":575.2},{"price":"7.221","symbol":"XTZUSDT","id":"72210","side":"Sell","size":1898.4},{"price":"7.222","symbol":"XTZUSDT","id":"72220","side":"Sell","size":1374.6001},{"price":"7.223","symbol":"XTZUSDT","id":"72230","side":"Sell","size":1582.8},{"price":"7.224","symbol":"XTZUSDT","id":"72240","side":"Sell","size":124.100006},{"price":"7.225","symbol":"XTZUSDT","id":"72250","side":"Sell","size":1142.1},{"price":"7.226","symbol":"XTZUSDT","id":"72260","side":"Sell","size":1219.8},{"price":"7.227","symbol":"XTZUSDT","id":"72270","side":"Sell","size":296.7},{"price":"7.228","symbol":"XTZUSDT","id":"72280","side":"Sell","size":2020.2},{"price":"7.229","symbol":"XTZUSDT","id":"72290","side":"Sell","size":1951.6},{"price":"7.230","symbol":"XTZUSDT","id":"72300","side":"Sell","size":2143.7},{"price":"7.231","symbol":"XTZUSDT","id":"72310","side":"Sell","size":1960.2},{"price":"7.232","symbol":"XTZUSDT","id":"72320","side":"Sell","size":89.799995},{"price":"7.233","symbol":"XTZUSDT","id":"72330","side":"Sell","size":1271.5}]},"cross_seq":"726227740","timestamp_e6":"1618677784976981"}
1618677786.983258: {"topic":"orderBookL2_25.XTZUSDT","type":"delta","data":{"delete":[],"update":[{"price":"7.213","symbol":"XTZUSDT","id":"72130","side":"Sell","size":642.60004},{"price":"7.220","symbol":"XTZUSDT","id":"72200","side":"Sell","size":683.89996},{"price":"7.214","symbol":"XTZUSDT","id":"72140","side":"Sell","size":1654.2001},{"price":"7.216","symbol":"XTZUSDT","id":"72160","side":"Sell","size":1453.2999},{"price":"7.202","symbol":"XTZUSDT","id":"72020","side":"Buy","size":584.6}],"insert":[]},"cross_seq":"726227745","timestamp_e6":"1618677784994654"}
1618677786.9833028: {"topic":"orderBookL2_25.XTZUSDT","type":"delta","data":{"delete":[],"update":[{"price":"7.207","symbol":"XTZUSDT","id":"72070","side":"Buy","size":1850.5},{"price":"7.205","symbol":"XTZUSDT","id":"72050","side":"Buy","size":2176.9}],"insert":[]},"cross_seq":"726227747","timestamp_e6":"1618677785015261"}
1618677786.983335: {"topic":"orderBookL2_25.XTZUSDT","type":"delta","data":{"delete":[{"price":"7.206","symbol":"XTZUSDT","id":"72060","side":"Buy"}],"update":[{"price":"7.204","symbol":"XTZUSDT","id":"72040","side":"Buy","size":920.6},{"price":"7.202","symbol":"XTZUSDT","id":"72020","side":"Buy","size":677.10004},{"price":"7.205","symbol":"XTZUSDT","id":"72050","side":"Buy","size":2397.7},{"price":"7.203","symbol":"XTZUSDT","id":"72030","side":"Buy","size":556.8}],"insert":[{"price":"7.182","symbol":"XTZUSDT","id":"71820","side":"Buy","size":1403.4}]},"cross_seq":"726227762","timestamp_e6":"1618677785034861"}
1618677786.98336: {"topic":"orderBookL2_25.XTZUSDT","type":"delta","data":{"delete":[{"price":"7.182","symbol":"XTZUSDT","id":"71820","side":"Buy"}],"update":[{"price":"7.204","symbol":"XTZUSDT","id":"72040","side":"Buy","size":514.9},{"price":"7.203","symbol":"XTZUSDT","id":"72030","side":"Buy","size":816.30005},{"price":"7.202","symbol":"XTZUSDT","id":"72020","side":"Buy","size":1097.9},{"price":"7.212","symbol":"XTZUSDT","id":"72120","side":"Sell","size":1449},{"price":"7.201","symbol":"XTZUSDT","id":"72010","side":"Buy","size":894.89996}],"insert":[{"price":"7.206","symbol":"XTZUSDT","id":"72060","side":"Buy","size":781.9}]},"cross_seq":"726227769","timestamp_e6":"1618677785074623"}
1618677786.983386: {"topic":"orderBookL2_25.XTZUSDT","type":"delta","data":{"delete":[],"update":[{"price":"7.211","symbol":"XTZUSDT","id":"72110","side":"Sell","size":2289.2}],"insert":[]},"cross_seq":"726227770","timestamp_e6":"1618677785095303"}
1618677786.983396: {"topic":"orderBookL2_25.XTZUSDT","type":"delta","data":{"delete":[{"price":"7.233","symbol":"XTZUSDT","id":"72330","side":"Sell"}],"update":[{"price":"7.202","symbol":"XTZUSDT","id":"72020","side":"Buy","size":1370.5},{"price":"7.212","symbol":"XTZUSDT","id":"72120","side":"Sell","size":360.9},{"price":"7.204","symbol":"XTZUSDT","id":"72040","side":"Buy","size":778.60004},{"price":"7.213","symbol":"XTZUSDT","id":"72130","side":"Sell","size":0.4}],"insert":[{"price":"7.209","symbol":"XTZUSDT","id":"72090","side":"Sell","size":1075.2}]},"cross_seq":"726227776","timestamp_e6":"1618677785114543"}
1618677786.9834409: {"topic":"orderBookL2_25.XTZUSDT","type":"delta","data":{"delete":[],"update":[{"price":"7.195","symbol":"XTZUSDT","id":"71950","side":"Buy","size":4264.2}],"insert":[]},"cross_seq":"726227778","timestamp_e6":"1618677785174570"}
1618677786.9834518: {"topic":"orderBookL2_25.XTZUSDT","type":"delta","data":{"delete":[],"update":[{"price":"7.232","symbol":"XTZUSDT","id":"72320","side":"Sell","size":49.6},{"price":"7.223","symbol":"XTZUSDT","id":"72230","side":"Sell","size":3097.7998},{"price":"7.228","symbol":"XTZUSDT","id":"72280","side":"Sell","size":3520.2}],"insert":[]},"cross_seq":"726227781","timestamp_e6":"1618677785194872"}
1618677786.9834828: {"topic":"orderBookL2_25.XTZUSDT","type":"delta","data":{"delete":[],"update":[{"price":"7.208","symbol":"XTZUSDT","id":"72080","side":"Sell","size":2340}],"insert":[]},"cross_seq":"726227782","timestamp_e6":"1618677785235281"}
1618677786.983493: {"topic":"orderBookL2_25.XTZUSDT","type":"delta","data":{"delete":[],"update":[{"price":"7.206","symbol":"XTZUSDT","id":"72060","side":"Buy","size":1714.4},{"price":"7.201","symbol":"XTZUSDT","id":"72010","side":"Buy","size":741.10004},{"price":"7.207","symbol":"XTZUSDT","id":"72070","side":"Buy","size":1029.7}],"insert":[]},"cross_seq":"726227785","timestamp_e6":"1618677785275400"}
1618677786.983506: {"topic":"orderBookL2_25.XTZUSDT","type":"delta","data":{"delete":[],"update":[{"price":"7.213","symbol":"XTZUSDT","id":"72130","side":"Sell","size":377.19998},{"price":"7.212","symbol":"XTZUSDT","id":"72120","side":"Sell","size":1003.1}],"insert":[]},"cross_seq":"726227787","timestamp_e6":"1618677785374657"}
1618677786.983518: {"topic":"orderBookL2_25.XTZUSDT","type":"delta","data":{"delete":[],"update":[{"price":"7.207","symbol":"XTZUSDT","id":"72070","side":"Buy","size":3779.7},{"price":"7.201","symbol":"XTZUSDT","id":"72010","side":"Buy","size":1255.2999}],"insert":[]},"cross_seq":"726227789","timestamp_e6":"1618677785395833"}
1618677786.9835289: {"topic":"orderBookL2_25.XTZUSDT","type":"delta","data":{"delete":[],"update":[{"price":"7.207","symbol":"XTZUSDT","id":"72070","side":"Buy","size":1029.7}],"insert":[]},"cross_seq":"726227790","timestamp_e6":"1618677785416500"}
1618677786.983538: {"topic":"orderBookL2_25.XTZUSDT","type":"delta","data":{"delete":[],"update":[{"price":"7.212","symbol":"XTZUSDT","id":"72120","side":"Sell","size":1379},{"price":"7.213","symbol":"XTZUSDT","id":"72130","side":"Sell","size":915.8},{"price":"7.211","symbol":"XTZUSDT","id":"72110","side":"Sell","size":1271.1},{"price":"7.215","symbol":"XTZUSDT","id":"72150","side":"Sell","size":1162.2999},{"price":"7.201","symbol":"XTZUSDT","id":"72010","side":"Buy","size":2526.3},{"price":"7.214","symbol":"XTZUSDT","id":"72140","side":"Sell","size":1919.6001}],"insert":[]},"cross_seq":"726227796","timestamp_e6":"1618677785435330"}
1618677786.983579: {"topic":"orderBookL2_25.XTZUSDT","type":"delta","data":{"delete":[],"update":[{"price":"7.208","symbol":"XTZUSDT","id":"72080","side":"Sell","size":340},{"price":"7.212","symbol":"XTZUSDT","id":"72120","side":"Sell","size":1019},{"price":"7.207","symbol":"XTZUSDT","id":"72070","side":"Buy","size":929.7}],"insert":[]},"cross_seq":"726227801","timestamp_e6":"1618677785456194"}
1618677786.9836102: {"topic":"orderBookL2_25.XTZUSDT","type":"delta","data":{"delete":[],"update":[{"price":"7.216","symbol":"XTZUSDT","id":"72160","side":"Sell","size":1813.3},{"price":"7.195","symbol":"XTZUSDT","id":"71950","side":"Buy","size":4265.1997}],"insert":[]},"cross_seq":"726227803","timestamp_e6":"1618677785475295"}
1618677786.9836218: {"topic":"orderBookL2_25.XTZUSDT","type":"delta","data":{"delete":[],"update":[{"price":"7.207","symbol":"XTZUSDT","id":"72070","side":"Buy","size":2929.7}],"insert":[]},"cross_seq":"726227827","timestamp_e6":"1618677785515176"}
1618677786.9836311: {"topic":"orderBookL2_25.XTZUSDT","type":"delta","data":{"delete":[],"update":[{"price":"7.195","symbol":"XTZUSDT","id":"71950","side":"Buy","size":4264.2}],"insert":[]},"cross_seq":"726227828","timestamp_e6":"1618677785535757"}
1618677786.98364: {"topic":"orderBookL2_25.XTZUSDT","type":"delta","data":{"delete":[],"update":[{"price":"7.207","symbol":"XTZUSDT","id":"72070","side":"Buy","size":3029.7002}],"insert":[]},"cross_seq":"726227831","timestamp_e6":"1618677785555890"}
1618677786.983649: {"topic":"orderBookL2_25.XTZUSDT","type":"delta","data":{"delete":[],"update":[{"price":"7.223","symbol":"XTZUSDT","id":"72230","side":"Sell","size":1582.8}],"insert":[]},"cross_seq":"726227832","timestamp_e6":"1618677785574695"}
1618677786.983658: {"topic":"orderBookL2_25.XTZUSDT","type":"delta","data":{"delete":[{"price":"7.210","symbol":"XTZUSDT","id":"72100","side":"Sell"},{"price":"7.209","symbol":"XTZUSDT","id":"72090","side":"Sell"},{"price":"7.208","symbol":"XTZUSDT","id":"72080","side":"Sell"}],"update":[{"price":"7.214","symbol":"XTZUSDT","id":"72140","side":"Sell","size":3248.8},{"price":"7.212","symbol":"XTZUSDT","id":"72120","side":"Sell","size":0.9},{"price":"7.215","symbol":"XTZUSDT","id":"72150","side":"Sell","size":1509},{"price":"7.216","symbol":"XTZUSDT","id":"72160","side":"Sell","size":895.80005},{"price":"7.217","symbol":"XTZUSDT","id":"72170","side":"Sell","size":793.8}],"insert":[{"price":"7.235","symbol":"XTZUSDT","id":"72350","side":"Sell","size":561.3},{"price":"7.233","symbol":"XTZUSDT","id":"72330","side":"Sell","size":1271.5},{"price":"7.234","symbol":"XTZUSDT","id":"72340","side":"Sell","size":55.399998}]},"cross_seq":"726227845","timestamp_e6":"1618677785595549"}
1618677786.983698: {"topic":"orderBookL2_25.XTZUSDT","type":"delta","data":{"delete":[{"price":"7.184","symbol":"XTZUSDT","id":"71840","side":"Buy"},{"price":"7.211","symbol":"XTZUSDT","id":"72110","side":"Sell"},{"price":"7.183","symbol":"XTZUSDT","id":"71830","side":"Buy"}],"update":[{"price":"7.201","symbol":"XTZUSDT","id":"72010","side":"Buy","size":1255.2999},{"price":"7.212","symbol":"XTZUSDT","id":"72120","side":"Sell","size":1076.1},{"price":"7.205","symbol":"XTZUSDT","id":"72050","side":"Buy","size":1760.7},{"price":"7.218","symbol":"XTZUSDT","id":"72180","side":"Sell","size":2615.5999},{"price":"7.207","symbol":"XTZUSDT","id":"72070","side":"Buy","size":2100},{"price":"7.216","symbol":"XTZUSDT","id":"72160","side":"Sell","size":1036.5},{"price":"7.206","symbol":"XTZUSDT","id":"72060","side":"Buy","size":932.5}],"insert":[{"price":"7.209","symbol":"XTZUSDT","id":"72090","side":"Buy","size":930.6},{"price":"7.236","symbol":"XTZUSDT","id":"72360","side":"Sell","size":458.69998},{"price":"7.208","symbol":"XTZUSDT","id":"72080","side":"Buy","size":781.9}]},"cross_seq":"726227883","timestamp_e6":"1618677785615855"}
1618677786.983774: {"topic":"orderBookL2_25.XTZUSDT","type":"delta","data":{"delete":[{"price":"7.185","symbol":"XTZUSDT","id":"71850","side":"Buy"}],"update":[{"price":"7.220","symbol":"XTZUSDT","id":"72200","side":"Sell","size":953.89996}],"insert":[{"price":"7.210","symbol":"XTZUSDT","id":"72100","side":"Buy","size":2750}]},"cross_seq":"726227890","timestamp_e6":"1618677785635178"}
1618677786.983791: {"topic":"orderBookL2_25.XTZUSDT","type":"delta","data":{"delete":[{"price":"7.210","symbol":"XTZUSDT","id":"72100","side":"Buy"},{"price":"7.207","symbol":"XTZUSDT","id":"72070","side":"Buy"}],"update":[{"price":"7.212","symbol":"XTZUSDT","id":"72120","side":"Sell","size":3945.4},{"price":"7.228","symbol":"XTZUSDT","id":"72280","side":"Sell","size":2020.2}],"insert":[{"price":"7.184","symbol":"XTZUSDT","id":"71840","side":"Buy","size":389},{"price":"7.185","symbol":"XTZUSDT","id":"71850","side":"Buy","size":1327.3}]},"cross_seq":"726227896","timestamp_e6":"1618677785656740"}
1618677786.9838169: {"topic":"orderBookL2_25.XTZUSDT","type":"delta","data":{"delete":[],"update":[{"price":"7.231","symbol":"XTZUSDT","id":"72310","side":"Sell","size":2000.4}],"insert":[]},"cross_seq":"726227897","timestamp_e6":"1618677785694754"}
1618677786.98383: {"topic":"orderBookL2_25.XTZUSDT","type":"delta","data":{"delete":[],"update":[{"price":"7.206","symbol":"XTZUSDT","id":"72060","side":"Buy","size":1272.5}],"insert":[]},"cross_seq":"726227899","timestamp_e6":"1618677785714529"}
1618677786.983855: {"topic":"orderBookL2_25.XTZUSDT","type":"delta","data":{"delete":[],"update":[{"price":"7.205","symbol":"XTZUSDT","id":"72050","side":"Buy","size":3031.7}],"insert":[]},"cross_seq":"726227900","timestamp_e6":"1618677785735754"}
1618677786.983864: {"topic":"orderBookL2_25.XTZUSDT","type":"delta","data":{"delete":[],"update":[{"price":"7.216","symbol":"XTZUSDT","id":"72160","side":"Sell","size":2307.6}],"insert":[]},"cross_seq":"726227901","timestamp_e6":"1618677785775158"}
1618677786.983874: {"topic":"orderBookL2_25.XTZUSDT","type":"delta","data":{"delete":[{"price":"7.236","symbol":"XTZUSDT","id":"72360","side":"Sell"},{"price":"7.184","symbol":"XTZUSDT","id":"71840","side":"Buy"}],"update":[],"insert":[{"price":"7.210","symbol":"XTZUSDT","id":"72100","side":"Sell","size":4000},{"price":"7.207","symbol":"XTZUSDT","id":"72070","side":"Buy","size":0.2}]},"cross_seq":"726227903","timestamp_e6":"1618677785815261"}
1618677786.983895: {"topic":"orderBookL2_25.XTZUSDT","type":"delta","data":{"delete":[{"price":"7.210","symbol":"XTZUSDT","id":"72100","side":"Sell"}],"update":[{"price":"7.205","symbol":"XTZUSDT","id":"72050","side":"Buy","size":1760.7},{"price":"7.209","symbol":"XTZUSDT","id":"72090","side":"Buy","size":3780.6}],"insert":[{"price":"7.236","symbol":"XTZUSDT","id":"72360","side":"Sell","size":458.69998}]},"cross_seq":"726227907","timestamp_e6":"1618677785856801"}
1618677786.983915: {"topic":"orderBookL2_25.XTZUSDT","type":"delta","data":{"delete":[],"update":[{"price":"7.216","symbol":"XTZUSDT","id":"72160","side":"Sell","size":2981.7},{"price":"7.214","symbol":"XTZUSDT","id":"72140","side":"Sell","size":4041.7002},{"price":"7.217","symbol":"XTZUSDT","id":"72170","side":"Sell","size":1469.1},{"price":"7.205","symbol":"XTZUSDT","id":"72050","side":"Buy","size":2419.1},{"price":"7.207","symbol":"XTZUSDT","id":"72070","side":"Buy","size":876.60004},{"price":"7.206","symbol":"XTZUSDT","id":"72060","side":"Buy","size":1667.1},{"price":"7.215","symbol":"XTZUSDT","id":"72150","side":"Sell","size":2106.7},{"price":"7.209","symbol":"XTZUSDT","id":"72090","side":"Buy","size":4164.3},{"price":"7.213","symbol":"XTZUSDT","id":"72130","side":"Sell","size":1313.1},{"price":"7.212","symbol":"XTZUSDT","id":"72120","side":"Sell","size":1653.1001}],"insert":[]},"cross_seq":"726227919","timestamp_e6":"1618677785875770"}
1618677786.983946: {"topic":"orderBookL2_25.XTZUSDT","type":"delta","data":{"delete":[],"update":[{"price":"7.209","symbol":"XTZUSDT","id":"72090","side":"Buy","size":1314.2999}],"insert":[]},"cross_seq":"726227921","timestamp_e6":"1618677785895164"}
1618677786.9839768: {"topic":"orderBookL2_25.XTZUSDT","type":"delta","data":{"delete":[],"update":[{"price":"7.216","symbol":"XTZUSDT","id":"72160","side":"Sell","size":1710.6}],"insert":[]},"cross_seq":"726227922","timestamp_e6":"1618677785934734"}
1618677786.984002: {"topic":"orderBookL2_25.XTZUSDT","type":"delta","data":{"delete":[],"update":[{"price":"7.220","symbol":"XTZUSDT","id":"72200","side":"Sell","size":683.89996}],"insert":[]},"cross_seq":"726227923","timestamp_e6":"1618677785956115"}
1618677786.984011: {"topic":"orderBookL2_25.XTZUSDT","type":"delta","data":{"delete":[],"update":[{"price":"7.212","symbol":"XTZUSDT","id":"72120","side":"Sell","size":1753.1},{"price":"7.222","symbol":"XTZUSDT","id":"72220","side":"Sell","size":2919.5999}],"insert":[]},"cross_seq":"726227925","timestamp_e6":"1618677785975422"}
1618677786.984023: {"topic":"orderBookL2_25.XTZUSDT","type":"delta","data":{"delete":[],"update":[{"price":"7.206","symbol":"XTZUSDT","id":"72060","side":"Buy","size":2938.1}],"insert":[]},"cross_seq":"726227926","timestamp_e6":"1618677785994730"}
1618677786.984034: {"topic":"orderBookL2_25.XTZUSDT","type":"delta","data":{"delete":[{"price":"7.236","symbol":"XTZUSDT","id":"72360","side":"Sell"}],"update":[],"insert":[{"price":"7.210","symbol":"XTZUSDT","id":"72100","side":"Sell","size":4000}]},"cross_seq":"726227927","timestamp_e6":"1618677786015360"}
1618677786.984069: {"topic":"orderBookL2_25.XTZUSDT","type":"delta","data":{"delete":[{"price":"7.210","symbol":"XTZUSDT","id":"72100","side":"Sell"}],"update":[],"insert":[{"price":"7.236","symbol":"XTZUSDT","id":"72360","side":"Sell","size":458.69998}]},"cross_seq":"726227928","timestamp_e6":"1618677786055747"}
1618677786.984098: {"topic":"orderBookL2_25.XTZUSDT","type":"delta","data":{"delete":[],"update":[{"price":"7.212","symbol":"XTZUSDT","id":"72120","side":"Sell","size":1653.1001},{"price":"7.227","symbol":"XTZUSDT","id":"72270","side":"Sell","size":1796.7001}],"insert":[]},"cross_seq":"726227930","timestamp_e6":"1618677786075201"}
1618677786.984132: {"topic":"orderBookL2_25.XTZUSDT","type":"delta","data":{"delete":[{"price":"7.236","symbol":"XTZUSDT","id":"72360","side":"Sell"}],"update":[{"price":"7.206","symbol":"XTZUSDT","id":"72060","side":"Buy","size":1667.1},{"price":"7.221","symbol":"XTZUSDT","id":"72210","side":"Sell","size":2258.4001},{"price":"7.212","symbol":"XTZUSDT","id":"72120","side":"Sell","size":4422.4}],"insert":[{"price":"7.210","symbol":"XTZUSDT","id":"72100","side":"Sell","size":2750}]},"cross_seq":"726227934","timestamp_e6":"1618677786095588"}
1618677786.984168: {"topic":"orderBookL2_25.XTZUSDT","type":"delta","data":{"delete":[],"update":[{"price":"7.201","symbol":"XTZUSDT","id":"72010","side":"Buy","size":1364.2},{"price":"7.215","symbol":"XTZUSDT","id":"72150","side":"Sell","size":3738.2},{"price":"7.204","symbol":"XTZUSDT","id":"72040","side":"Buy","size":884.9},{"price":"7.216","symbol":"XTZUSDT","id":"72160","side":"Sell","size":1976.9},{"price":"7.219","symbol":"XTZUSDT","id":"72190","side":"Sell","size":1941.8},{"price":"7.217","symbol":"XTZUSDT","id":"72170","side":"Sell","size":1992.7001},{"price":"7.205","symbol":"XTZUSDT","id":"72050","side":"Buy","size":2771.6},{"price":"7.209","symbol":"XTZUSDT","id":"72090","side":"Buy","size":1414.2999},{"price":"7.203","symbol":"XTZUSDT","id":"72030","side":"Buy","size":1069.6},{"price":"7.214","symbol":"XTZUSDT","id":"72140","side":"Sell","size":4359.9},{"price":"7.218","symbol":"XTZUSDT","id":"72180","side":"Sell","size":2915.0999}],"insert":[]},"cross_seq":"726227946","timestamp_e6":"1618677786116904"}
1618677786.9842188: {"topic":"orderBookL2_25.XTZUSDT","type":"delta","data":{"delete":[{"price":"7.210","symbol":"XTZUSDT","id":"72100","side":"Sell"}],"update":[{"price":"7.209","symbol":"XTZUSDT","id":"72090","side":"Buy","size":1314.2999},{"price":"7.212","symbol":"XTZUSDT","id":"72120","side":"Sell","size":1653.1001}],"insert":[{"price":"7.236","symbol":"XTZUSDT","id":"72360","side":"Sell","size":458.69998}]},"cross_seq":"726227949","timestamp_e6":"1618677786135714"}
1618677786.984274: {"topic":"orderBookL2_25.XTZUSDT","type":"delta","data":{"delete":[],"update":[{"price":"7.204","symbol":"XTZUSDT","id":"72040","side":"Buy","size":2155.9}],"insert":[]},"cross_seq":"726227950","timestamp_e6":"1618677786214921"}
1618677786.9842849: {"topic":"orderBookL2_25.XTZUSDT","type":"delta","data":{"delete":[],"update":[{"price":"7.212","symbol":"XTZUSDT","id":"72120","side":"Sell","size":1753.1}],"insert":[]},"cross_seq":"726227951","timestamp_e6":"1618677786255454"}
1618677786.984309: {"topic":"orderBookL2_25.XTZUSDT","type":"delta","data":{"delete":[{"price":"7.185","symbol":"XTZUSDT","id":"71850","side":"Buy"},{"price":"7.236","symbol":"XTZUSDT","id":"72360","side":"Sell"}],"update":[{"price":"7.209","symbol":"XTZUSDT","id":"72090","side":"Buy","size":383.7},{"price":"7.207","symbol":"XTZUSDT","id":"72070","side":"Buy","size":0.2},{"price":"7.213","symbol":"XTZUSDT","id":"72130","side":"Sell","size":1708.7},{"price":"7.205","symbol":"XTZUSDT","id":"72050","side":"Buy","size":2113.2},{"price":"7.214","symbol":"XTZUSDT","id":"72140","side":"Sell","size":3983.1},{"price":"7.212","symbol":"XTZUSDT","id":"72120","side":"Sell","size":677.9},{"price":"7.206","symbol":"XTZUSDT","id":"72060","side":"Buy","size":1930.8999}],"insert":[{"price":"7.210","symbol":"XTZUSDT","id":"72100","side":"Buy","size":1314.2999},{"price":"7.211","symbol":"XTZUSDT","id":"72110","side":"Sell","size":1652.2001}]},"cross_seq":"726227961","timestamp_e6":"1618677786276787"}
1618677786.98438: {"topic":"orderBookL2_25.XTZUSDT","type":"delta","data":{"delete":[],"update":[{"price":"7.213","symbol":"XTZUSDT","id":"72130","side":"Sell","size":3082.9},{"price":"7.218","symbol":"XTZUSDT","id":"72180","side":"Sell","size":2547.9},{"price":"7.215","symbol":"XTZUSDT","id":"72150","side":"Sell","size":2871.6},{"price":"7.217","symbol":"XTZUSDT","id":"72170","side":"Sell","size":1800.5}],"insert":[]},"cross_seq":"726227966","timestamp_e6":"1618677786294711"}
1618677786.98442: {"topic":"orderBookL2_25.XTZUSDT","type":"delta","data":{"delete":[],"update":[{"price":"7.211","symbol":"XTZUSDT","id":"72110","side":"Sell","size":4402.1997}],"insert":[]},"cross_seq":"726227967","timestamp_e6":"1618677786315111"}
1618677786.9844449: {"topic":"orderBookL2_25.XTZUSDT","type":"delta","data":{"delete":[],"update":[{"price":"7.203","symbol":"XTZUSDT","id":"72030","side":"Buy","size":1489.6}],"insert":[]},"cross_seq":"726227969","timestamp_e6":"1618677786334846"}
1618677786.984478: {"topic":"orderBookL2_25.XTZUSDT","type":"delta","data":{"delete":[],"update":[{"price":"7.211","symbol":"XTZUSDT","id":"72110","side":"Sell","size":4502.2}],"insert":[]},"cross_seq":"726227970","timestamp_e6":"1618677786357592"}
1618677786.984527: {"topic":"orderBookL2_25.XTZUSDT","type":"delta","data":{"delete":[],"update":[{"price":"7.212","symbol":"XTZUSDT","id":"72120","side":"Sell","size":577.9},{"price":"7.211","symbol":"XTZUSDT","id":"72110","side":"Sell","size":1752.2}],"insert":[]},"cross_seq":"726227972","timestamp_e6":"1618677786375585"}
1618677786.9845529: {"topic":"orderBookL2_25.XTZUSDT","type":"delta","data":{"delete":[],"update":[{"price":"7.209","symbol":"XTZUSDT","id":"72090","side":"Buy","size":703.4},{"price":"7.218","symbol":"XTZUSDT","id":"72180","side":"Sell","size":2915.0999},{"price":"7.216","symbol":"XTZUSDT","id":"72160","side":"Sell","size":2634.3},{"price":"7.215","symbol":"XTZUSDT","id":"72150","side":"Sell","size":3738.2},{"price":"7.207","symbol":"XTZUSDT","id":"72070","side":"Buy","size":394.80002},{"price":"7.205","symbol":"XTZUSDT","id":"72050","side":"Buy","size":2597.5999},{"price":"7.214","symbol":"XTZUSDT","id":"72140","side":"Sell","size":1277.4}],"insert":[]},"cross_seq":"726227983","timestamp_e6":"1618677786395286"}
1618677786.984575: {"topic":"orderBookL2_25.XTZUSDT","type":"delta","data":{"delete":[],"update":[{"price":"7.206","symbol":"XTZUSDT","id":"72060","side":"Buy","size":1590.9},{"price":"7.211","symbol":"XTZUSDT","id":"72110","side":"Sell","size":1652.2001}],"insert":[]},"cross_seq":"726228010","timestamp_e6":"1618677786435180"}
1618677786.984612: {"topic":"orderBookL2_25.XTZUSDT","type":"delta","data":{"delete":[],"update":[{"price":"7.204","symbol":"XTZUSDT","id":"72040","side":"Buy","size":884.9}],"insert":[]},"cross_seq":"726228011","timestamp_e6":"1618677786454603"}
1618677786.9846668: {"topic":"orderBookL2_25.XTZUSDT","type":"delta","data":{"delete":[],"update":[{"price":"7.210","symbol":"XTZUSDT","id":"72100","side":"Buy","size":1414.2999}],"insert":[]},"cross_seq":"726228012","timestamp_e6":"1618677786475972"}
1618677786.984679: {"success":true,"ret_msg":"","conn_id":"38cf0ac3-af67-483c-9bbc-b57d45910ecb","request":{"op":"subscribe","args":["orderBookL2_25.XTZUSDT"]}}
1618677786.9846861: {"topic":"orderBookL2_25.UNIUSDT","type":"snapshot","data":{"order_book":[{"price":"35.356","symbol":"UNIUSDT","id":"353560","side":"Buy","size":25.900002},{"price":"35.357","symbol":"UNIUSDT","id":"353570","side":"Buy","size":37.5},{"price":"35.358","symbol":"UNIUSDT","id":"353580","side":"Buy","size":20.4},{"price":"35.359","symbol":"UNIUSDT","id":"353590","side":"Buy","size":23.3},{"price":"35.360","symbol":"UNIUSDT","id":"353600","side":"Buy","size":20.5},{"price":"35.361","symbol":"UNIUSDT","id":"353610","side":"Buy","size":11.4},{"price":"35.362","symbol":"UNIUSDT","id":"353620","side":"Buy","size":66},{"price":"35.363","symbol":"UNIUSDT","id":"353630","side":"Buy","size":692.30005},{"price":"35.364","symbol":"UNIUSDT","id":"353640","side":"Buy","size":20.8},{"price":"35.365","symbol":"UNIUSDT","id":"353650","side":"Buy","size":40.5},{"price":"35.366","symbol":"UNIUSDT","id":"353660","side":"Buy","size":265.7},{"price":"35.367","symbol":"UNIUSDT","id":"353670","side":"Buy","size":35.3},{"price":"35.368","symbol":"UNIUSDT","id":"353680","side":"Buy","size":42.899998},{"price":"35.369","symbol":"UNIUSDT","id":"353690","side":"Buy","size":416.5},{"price":"35.371","symbol":"UNIUSDT","id":"353710","side":"Buy","size":12.4},{"price":"35.372","symbol":"UNIUSDT","id":"353720","side":"Buy","size":14.1},{"price":"35.373","symbol":"UNIUSDT","id":"353730","side":"Buy","size":11.1},{"price":"35.374","symbol":"UNIUSDT","id":"353740","side":"Buy","size":29.8},{"price":"35.375","symbol":"UNIUSDT","id":"353750","side":"Buy","size":17.5},{"price":"35.376","symbol":"UNIUSDT","id":"353760","side":"Buy","size":42.300003},{"price":"35.377","symbol":"UNIUSDT","id":"353770","side":"Buy","size":38.899998},{"price":"35.378","symbol":"UNIUSDT","id":"353780","side":"Buy","size":59.800003},{"price":"35.395","symbol":"UNIUSDT","id":"353950","side":"Buy","size":489.1},{"price":"35.397","symbol":"UNIUSDT","id":"353970","side":"Buy","size":0.9},{"price":"35.401","symbol":"UNIUSDT","id":"354010","side":"Buy","size":0.7},{"price":"35.402","symbol":"UNIUSDT","id":"354020","side":"Sell","size":139.09999},{"price":"35.403","symbol":"UNIUSDT","id":"354030","side":"Sell","size":119.3},{"price":"35.404","symbol":"UNIUSDT","id":"354040","side":"Sell","size":130.9},{"price":"35.405","symbol":"UNIUSDT","id":"354050","side":"Sell","size":109.2},{"price":"35.406","symbol":"UNIUSDT","id":"354060","side":"Sell","size":85.4},{"price":"35.407","symbol":"UNIUSDT","id":"354070","side":"Sell","size":82.9},{"price":"35.408","symbol":"UNIUSDT","id":"354080","side":"Sell","size":91.8},{"price":"35.409","symbol":"UNIUSDT","id":"354090","side":"Sell","size":43.100002},{"price":"35.410","symbol":"UNIUSDT","id":"354100","side":"Sell","size":60.5},{"price":"35.411","symbol":"UNIUSDT","id":"354110","side":"Sell","size":45.2},{"price":"35.412","symbol":"UNIUSDT","id":"354120","side":"Sell","size":36.6},{"price":"35.413","symbol":"UNIUSDT","id":"354130","side":"Sell","size":27.3},{"price":"35.414","symbol":"UNIUSDT","id":"354140","side":"Sell","size":16.9},{"price":"35.415","symbol":"UNIUSDT","id":"354150","side":"Sell","size":27.4},{"price":"35.416","symbol":"UNIUSDT","id":"354160","side":"Sell","size":19.5},{"price":"35.417","symbol":"UNIUSDT","id":"354170","side":"Sell","size":4.8},{"price":"35.418","symbol":"UNIUSDT","id":"354180","side":"Sell","size":32.6},{"price":"35.419","symbol":"UNIUSDT","id":"354190","side":"Sell","size":40.1},{"price":"35.420","symbol":"UNIUSDT","id":"354200","side":"Sell","size":36.2},{"price":"35.421","symbol":"UNIUSDT","id":"354210","side":"Sell","size":16.3},{"price":"35.422","symbol":"UNIUSDT","id":"354220","side":"Sell","size":14.7},{"price":"35.423","symbol":"UNIUSDT","id":"354230","side":"Sell","size":36.2},{"price":"35.424","symbol":"UNIUSDT","id":"354240","side":"Sell","size":55.2},{"price":"35.425","symbol":"UNIUSDT","id":"354250","side":"Sell","size":261.6},{"price":"35.426","symbol":"UNIUSDT","id":"354260","side":"Sell","size":23.699999}]},"cross_seq":"916952241","timestamp_e6":"1618677786242744"}
1618677786.9848971: {"topic":"orderBookL2_25.UNIUSDT","type":"delta","data":{"delete":[],"update":[{"price":"35.363","symbol":"UNIUSDT","id":"353630","side":"Buy","size":40.1}],"insert":[]},"cross_seq":"916952261","timestamp_e6":"1618677786302451"}
1618677786.9849112: {"topic":"orderBookL2_25.UNIUSDT","type":"delta","data":{"delete":[{"price":"35.377","symbol":"UNIUSDT","id":"353770","side":"Buy"}],"update":[{"price":"35.374","symbol":"UNIUSDT","id":"353740","side":"Buy","size":18.7},{"price":"35.373","symbol":"UNIUSDT","id":"353730","side":"Buy","size":29.8},{"price":"35.375","symbol":"UNIUSDT","id":"353750","side":"Buy","size":42.300003}],"insert":[{"price":"35.355","symbol":"UNIUSDT","id":"353550","side":"Buy","size":36.4}]},"cross_seq":"916952334","timestamp_e6":"1618677786402589"}
1618677786.9849348: {"topic":"orderBookL2_25.UNIUSDT","type":"delta","data":{"delete":[{"price":"35.395","symbol":"UNIUSDT","id":"353950","side":"Buy"}],"update":[],"insert":[{"price":"35.354","symbol":"UNIUSDT","id":"353540","side":"Buy","size":40}]},"cross_seq":"916952342","timestamp_e6":"1618677786422552"}
1618677786.984951: {"topic":"orderBookL2_25.UNIUSDT","type":"delta","data":{"delete":[{"price":"35.354","symbol":"UNIUSDT","id":"353540","side":"Buy"},{"price":"35.358","symbol":"UNIUSDT","id":"353580","side":"Buy"},{"price":"35.355","symbol":"UNIUSDT","id":"353550","side":"Buy"},{"price":"35.357","symbol":"UNIUSDT","id":"353570","side":"Buy"},{"price":"35.359","symbol":"UNIUSDT","id":"353590","side":"Buy"},{"price":"35.356","symbol":"UNIUSDT","id":"353560","side":"Buy"}],"update":[{"price":"35.401","symbol":"UNIUSDT","id":"354010","side":"Buy","size":64.700005}],"insert":[{"price":"35.384","symbol":"UNIUSDT","id":"353840","side":"Buy","size":11.1},{"price":"35.388","symbol":"UNIUSDT","id":"353880","side":"Buy","size":38.899998},{"price":"35.389","symbol":"UNIUSDT","id":"353890","side":"Buy","size":59.800003},{"price":"35.386","symbol":"UNIUSDT","id":"353860","side":"Buy","size":17.5},{"price":"35.387","symbol":"UNIUSDT","id":"353870","side":"Buy","size":42.300003},{"price":"35.385","symbol":"UNIUSDT","id":"353850","side":"Buy","size":29.8}]},"cross_seq":"916952388","timestamp_e6":"1618677786482587"}
1618677786.985: {"topic":"orderBookL2_25.UNIUSDT","type":"delta","data":{"delete":[],"update":[{"price":"35.373","symbol":"UNIUSDT","id":"353730","side":"Buy","size":72.8}],"insert":[]},"cross_seq":"916952408","timestamp_e6":"1618677786522325"}
1618677786.985031: {"topic":"orderBookL2_25.UNIUSDT","type":"delta","data":{"delete":[],"update":[{"price":"35.401","symbol":"UNIUSDT","id":"354010","side":"Buy","size":284.69998}],"insert":[]},"cross_seq":"916952412","timestamp_e6":"1618677786563756"}
1618677786.985056: {"success":true,"ret_msg":"","conn_id":"38cf0ac3-af67-483c-9bbc-b57d45910ecb","request":{"op":"subscribe","args":["orderBookL2_25.UNIUSDT"]}}
1618677786.985062: {"topic":"orderBookL2_25.LTCUSDT","type":"snapshot","data":{"order_book":[{"price":"312.53","symbol":"LTCUSDT","id":"3125300","side":"Buy","size":210.1},{"price":"312.54","symbol":"LTCUSDT","id":"3125400","side":"Buy","size":162.2},{"price":"312.55","symbol":"LTCUSDT","id":"3125500","side":"Buy","size":84.8},{"price":"312.56","symbol":"LTCUSDT","id":"3125600","side":"Buy","size":116.600006},{"price":"312.57","symbol":"LTCUSDT","id":"3125700","side":"Buy","size":76.600006},{"price":"312.58","symbol":"LTCUSDT","id":"3125800","side":"Buy","size":27.1},{"price":"312.59","symbol":"LTCUSDT","id":"3125900","side":"Buy","size":74.700005},{"price":"312.60","symbol":"LTCUSDT","id":"3126000","side":"Buy","size":116.7},{"price":"312.61","symbol":"LTCUSDT","id":"3126100","side":"Buy","size":65.299995},{"price":"312.62","symbol":"LTCUSDT","id":"3126200","side":"Buy","size":171.90001},{"price":"312.63","symbol":"LTCUSDT","id":"3126300","side":"Buy","size":114.8},{"price":"312.64","symbol":"LTCUSDT","id":"3126400","side":"Buy","size":103.3},{"price":"312.65","symbol":"LTCUSDT","id":"3126500","side":"Buy","size":66.1},{"price":"312.66","symbol":"LTCUSDT","id":"3126600","side":"Buy","size":82.6},{"price":"312.67","symbol":"LTCUSDT","id":"3126700","side":"Buy","size":136.3},{"price":"312.68","symbol":"LTCUSDT","id":"3126800","side":"Buy","size":170.2},{"price":"312.69","symbol":"LTCUSDT","id":"3126900","side":"Buy","size":129.20001},{"price":"312.70","symbol":"LTCUSDT","id":"3127000","side":"Buy","size":135.4},{"price":"312.71","symbol":"LTCUSDT","id":"3127100","side":"Buy","size":79.6},{"price":"312.72","symbol":"LTCUSDT","id":"3127200","side":"Buy","size":42.5},{"price":"312.73","symbol":"LTCUSDT","id":"3127300","side":"Buy","size":79.1},{"price":"312.74","symbol":"LTCUSDT","id":"3127400","side":"Buy","size":1.5},{"price":"312.75","symbol":"LTCUSDT","id":"3127500","side":"Buy","size":70.4},{"price":"312.76","symbol":"LTCUSDT","id":"3127600","side":"Buy","size":41.6},{"price":"312.81","symbol":"LTCUSDT","id":"3128100","side":"Buy","size":20.6},{"price":"312.83","symbol":"LTCUSDT","id":"3128300","side":"Sell","size":127.3},{"price":"312.84","symbol":"LTCUSDT","id":"3128400","side":"Sell","size":0.3},{"price":"312.85","symbol":"LTCUSDT","id":"3128500","side":"Sell","size":150.1},{"price":"312.86","symbol":"LTCUSDT","id":"3128600","side":"Sell","size":135.2},{"price":"312.87","symbol":"LTCUSDT","id":"3128700","side":"Sell","size":150.1},{"price":"312.89","symbol":"LTCUSDT","id":"3128900","side":"Sell","size":1.5},{"price":"312.90","symbol":"LTCUSDT","id":"3129000","side":"Sell","size":94.9},{"price":"312.92","symbol":"LTCUSDT","id":"3129200","side":"Sell","size":101.799995},{"price":"312.93","symbol":"LTCUSDT","id":"3129300","side":"Sell","size":108.8},{"price":"312.94","symbol":"LTCUSDT","id":"3129400","side":"Sell","size":41.8},{"price":"312.95","symbol":"LTCUSDT","id":"3129500","side":"Sell","size":109.299995},{"price":"312.96","symbol":"LTCUSDT","id":"3129600","side":"Sell","size":145.8},{"price":"312.97","symbol":"LTCUSDT","id":"3129700","side":"Sell","size":104.8},{"price":"312.98","symbol":"LTCUSDT","id":"3129800","side":"Sell","size":93.4},{"price":"312.99","symbol":"LTCUSDT","id":"3129900","side":"Sell","size":70.200005},{"price":"313.00","symbol":"LTCUSDT","id":"3130000","side":"Sell","size":14.4},{"price":"313.01","symbol":"LTCUSDT","id":"3130100","side":"Sell","size":85.799995},{"price":"313.02","symbol":"LTCUSDT","id":"3130200","side":"Sell","size":59.399998},{"price":"313.03","symbol":"LTCUSDT","id":"3130300","side":"Sell","size":152.8},{"price":"313.04","symbol":"LTCUSDT","id":"3130400","side":"Sell","size":37.5},{"price":"313.05","symbol":"LTCUSDT","id":"3130500","side":"Sell","size":10.8},{"price":"313.06","symbol":"LTCUSDT","id":"3130600","side":"Sell","size":56.899998},{"price":"313.07","symbol":"LTCUSDT","id":"3130700","side":"Sell","size":45.9},{"price":"313.08","symbol":"LTCUSDT","id":"3130800","side":"Sell","size":1.3},{"price":"313.09","symbol":"LTCUSDT","id":"3130900","side":"Sell","size":186.99998}]},"cross_seq":"1684521345","timestamp_e6":"1618677785921712"}
1618677786.9852228: {"topic":"orderBookL2_25.LTCUSDT","type":"delta","data":{"delete":[{"price":"312.87","symbol":"LTCUSDT","id":"3128700","side":"Sell"},{"price":"312.75","symbol":"LTCUSDT","id":"3127500","side":"Buy"},{"price":"312.86","symbol":"LTCUSDT","id":"3128600","side":"Sell"},{"price":"312.53","symbol":"LTCUSDT","id":"3125300","side":"Buy"},{"price":"312.54","symbol":"LTCUSDT","id":"3125400","side":"Buy"},{"price":"312.55","symbol":"LTCUSDT","id":"3125500","side":"Buy"}],"update":[{"price":"312.83","symbol":"LTCUSDT","id":"3128300","side":"Sell","size":276.8},{"price":"312.84","symbol":"LTCUSDT","id":"3128400","side":"Sell","size":135.5},{"price":"312.76","symbol":"LTCUSDT","id":"3127600","side":"Buy","size":65.4},{"price":"312.81","symbol":"LTCUSDT","id":"3128100","side":"Buy","size":36.8}],"insert":[{"price":"312.80","symbol":"LTCUSDT","id":"3128000","side":"Buy","size":119.7},{"price":"312.88","symbol":"LTCUSDT","id":"3128800","side":"Sell","size":93.4},{"price":"312.78","symbol":"LTCUSDT","id":"3127800","side":"Buy","size":42.5},{"price":"312.77","symbol":"LTCUSDT","id":"3127700","side":"Buy","size":78.1},{"price":"312.82","symbol":"LTCUSDT","id":"3128200","side":"Sell","size":0.6},{"price":"312.79","symbol":"LTCUSDT","id":"3127900","side":"Buy","size":70.4}]},"cross_seq":"1684521366","timestamp_e6":"1618677785940361"}
1618677786.985307: {"topic":"orderBookL2_25.LTCUSDT","type":"delta","data":{"delete":[],"update":[{"price":"312.83","symbol":"LTCUSDT","id":"3128300","side":"Sell","size":278.3},{"price":"312.90","symbol":"LTCUSDT","id":"3129000","side":"Sell","size":93.4}],"insert":[]},"cross_seq":"1684521376","timestamp_e6":"1618677785959019"}
1618677786.985336: {"topic":"orderBookL2_25.LTCUSDT","type":"delta","data":{"delete":[{"price":"313.09","symbol":"LTCUSDT","id":"3130900","side":"Sell"},{"price":"312.56","symbol":"LTCUSDT","id":"3125600","side":"Buy"},{"price":"312.85","symbol":"LTCUSDT","id":"3128500","side":"Sell"}],"update":[{"price":"312.89","symbol":"LTCUSDT","id":"3128900","side":"Sell","size":110.299995},{"price":"312.83","symbol":"LTCUSDT","id":"3128300","side":"Sell","size":151.6}],"insert":[{"price":"312.87","symbol":"LTCUSDT","id":"3128700","side":"Sell","size":149.9},{"price":"312.86","symbol":"LTCUSDT","id":"3128600","side":"Sell","size":135.2},{"price":"312.75","symbol":"LTCUSDT","id":"3127500","side":"Buy","size":41.9}]},"cross_seq":"1684521382","timestamp_e6":"1618677785977893"}
1618677786.985394: {"topic":"orderBookL2_25.LTCUSDT","type":"delta","data":{"delete":[{"price":"312.87","symbol":"LTCUSDT","id":"3128700","side":"Sell"}],"update":[{"price":"312.83","symbol":"LTCUSDT","id":"3128300","side":"Sell","size":1.5}],"insert":[{"price":"312.85","symbol":"LTCUSDT","id":"3128500","side":"Sell","size":135.2}]},"cross_seq":"1684521394","timestamp_e6":"1618677785997916"}
1618677786.98543: {"topic":"orderBookL2_25.LTCUSDT","type":"delta","data":{"delete":[{"price":"312.86","symbol":"LTCUSDT","id":"3128600","side":"Sell"}],"update":[{"price":"312.88","symbol":"LTCUSDT","id":"3128800","side":"Sell","size":149.9}],"insert":[{"price":"312.87","symbol":"LTCUSDT","id":"3128700","side":"Sell","size":135.2}]},"cross_seq":"1684521397","timestamp_e6":"1618677786077886"}
1618677786.985447: {"topic":"orderBookL2_25.LTCUSDT","type":"delta","data":{"delete":[{"price":"313.08","symbol":"LTCUSDT","id":"3130800","side":"Sell"}],"update":[{"price":"312.84","symbol":"LTCUSDT","id":"3128400","side":"Sell","size":0.3},{"price":"312.88","symbol":"LTCUSDT","id":"3128800","side":"Sell","size":56.5}],"insert":[{"price":"312.86","symbol":"LTCUSDT","id":"3128600","side":"Sell","size":135.2}]},"cross_seq":"1684521400","timestamp_e6":"1618677786097855"}
1618677786.985467: {"topic":"orderBookL2_25.LTCUSDT","type":"delta","data":{"delete":[],"update":[{"price":"312.81","symbol":"LTCUSDT","id":"3128100","side":"Buy","size":20.6}],"insert":[]},"cross_seq":"1684521401","timestamp_e6":"1618677786260134"}
1618677786.9854772: {"topic":"orderBookL2_25.LTCUSDT","type":"delta","data":{"delete":[{"price":"312.74","symbol":"LTCUSDT","id":"3127400","side":"Buy"}],"update":[{"price":"312.82","symbol":"LTCUSDT","id":"3128200","side":"Sell","size":275.6},{"price":"312.65","symbol":"LTCUSDT","id":"3126500","side":"Buy","size":67.6}],"insert":[{"price":"312.56","symbol":"LTCUSDT","id":"3125600","side":"Buy","size":116.600006}]},"cross_seq":"1684521405","timestamp_e6":"1618677786299956"}
1618677786.985497: {"topic":"orderBookL2_25.LTCUSDT","type":"delta","data":{"delete":[{"price":"312.90","symbol":"LTCUSDT","id":"3129000","side":"Sell"},{"price":"312.87","symbol":"LTCUSDT","id":"3128700","side":"Sell"}],"update":[{"price":"312.71","symbol":"LTCUSDT","id":"3127100","side":"Buy","size":1.5},{"price":"312.89","symbol":"LTCUSDT","id":"3128900","side":"Sell","size":1.5},{"price":"312.82","symbol":"LTCUSDT","id":"3128200","side":"Sell","size":150.59999},{"price":"312.70","symbol":"LTCUSDT","id":"3127000","side":"Buy","size":216.20001},{"price":"312.69","symbol":"LTCUSDT","id":"3126900","side":"Buy","size":185.9},{"price":"312.67","symbol":"LTCUSDT","id":"3126700","side":"Buy","size":47.699997}],"insert":[{"price":"313.08","symbol":"LTCUSDT","id":"3130800","side":"Sell","size":1.3},{"price":"312.91","symbol":"LTCUSDT","id":"3129100","side":"Sell","size":41}]},"cross_seq":"1684521428","timestamp_e6":"1618677786320028"}
1618677786.9855318: {"topic":"orderBookL2_25.LTCUSDT","type":"delta","data":{"delete":[{"price":"312.83","symbol":"LTCUSDT","id":"3128300","side":"Sell"},{"price":"312.78","symbol":"LTCUSDT","id":"3127800","side":"Buy"},{"price":"312.85","symbol":"LTCUSDT","id":"3128500","side":"Sell"},{"price":"312.80","symbol":"LTCUSDT","id":"3128000","side":"Buy"},{"price":"312.92","symbol":"LTCUSDT","id":"3129200","side":"Sell"},{"price":"312.95","symbol":"LTCUSDT","id":"3129500","side":"Sell"},{"price":"312.77","symbol":"LTCUSDT","id":"3127700","side":"Buy"},{"price":"312.93","symbol":"LTCUSDT","id":"3129300","side":"Sell"},{"price":"312.94","symbol":"LTCUSDT","id":"3129400","side":"Sell"},{"price":"312.98","symbol":"LTCUSDT","id":"3129800","side":"Sell"},{"price":"312.79","symbol":"LTCUSDT","id":"3127900","side":"Buy"},{"price":"312.76","symbol":"LTCUSDT","id":"3127600","side":"Buy"},{"price":"312.75","symbol":"LTCUSDT","id":"3127500","side":"Buy"},{"price":"312.86","symbol":"LTCUSDT","id":"3128600","side":"Sell"}],"update":[{"price":"312.96","symbol":"LTCUSDT","id":"3129600","side":"Sell","size":43.800003},{"price":"312.91","symbol":"LTCUSDT","id":"3129100","side":"Sell","size":74.200005},{"price":"312.73","symbol":"LTCUSDT","id":"3127300","side":"Buy","size":137.9},{"price":"312.70","symbol":"LTCUSDT","id":"3127000","side":"Buy","size":160.1},{"price":"312.72","symbol":"LTCUSDT","id":"3127200","side":"Buy","size":107.399994},{"price":"312.71","symbol":"LTCUSDT","id":"3127100","side":"Buy","size":109.9},{"price":"312.97","symbol":"LTCUSDT","id":"3129700","side":"Sell","size":182.79999},{"price":"312.69","symbol":"LTCUSDT","id":"3126900","side":"Buy","size":135.2}],"insert":[{"price":"313.10","symbol":"LTCUSDT","id":"3131000","side":"Sell","size":8.1},{"price":"313.14","symbol":"LTCUSDT","id":"3131400","side":"Sell","size":28.2},{"price":"312.53","symbol":"LTCUSDT","id":"3125300","side":"Buy","size":210.1},{"price":"312.55","symbol":"LTCUSDT","id":"3125500","side":"Buy","size":84.8},{"price":"312.90","symbol":"LTCUSDT","id":"3129000","side":"Sell","size":1.5},{"price":"313.11","symbol":"LTCUSDT","id":"3131100","side":"Sell","size":16.8},{"price":"312.54","symbol":"LTCUSDT","id":"3125400","side":"Buy","size":162.2},{"price":"312.52","symbol":"LTCUSDT","id":"3125200","side":"Buy","size":14.6},{"price":"312.74","symbol":"LTCUSDT","id":"3127400","side":"Buy","size":138.1},{"price":"313.15","symbol":"LTCUSDT","id":"3131500","side":"Sell","size":71.9},{"price":"313.09","symbol":"LTCUSDT","id":"3130900","side":"Sell","size":288},{"price":"313.13","symbol":"LTCUSDT","id":"3131300","side":"Sell","size":87},{"price":"312.51","symbol":"LTCUSDT","id":"3125100","side":"Buy","size":184.8},{"price":"313.12","symbol":"LTCUSDT","id":"3131200","side":"Sell","size":6.4}]},"cross_seq":"1684521471","timestamp_e6":"1618677786337921"}
1618677786.985638: {"topic":"orderBookL2_25.LTCUSDT","type":"delta","data":{"delete":[{"price":"313.15","symbol":"LTCUSDT","id":"3131500","side":"Sell"},{"price":"313.13","symbol":"LTCUSDT","id":"3131300","side":"Sell"},{"price":"312.88","symbol":"LTCUSDT","id":"3128800","side":"Sell"},{"price":"312.74","symbol":"LTCUSDT","id":"3127400","side":"Buy"},{"price":"313.14","symbol":"LTCUSDT","id":"3131400","side":"Sell"},{"price":"312.51","symbol":"LTCUSDT","id":"3125100","side":"Buy"}],"update":[{"price":"312.73","symbol":"LTCUSDT","id":"3127300","side":"Buy","size":117.1},{"price":"312.91","symbol":"LTCUSDT","id":"3129100","side":"Sell","size":115.2},{"price":"312.96","symbol":"LTCUSDT","id":"3129600","side":"Sell","size":82.8},{"price":"312.71","symbol":"LTCUSDT","id":"3127100","side":"Buy","size":1.5},{"price":"312.72","symbol":"LTCUSDT","id":"3127200","side":"Buy","size":64.9}],"insert":[{"price":"312.95","symbol":"LTCUSDT","id":"3129500","side":"Sell","size":41},{"price":"312.94","symbol":"LTCUSDT","id":"3129400","side":"Sell","size":31},{"price":"312.92","symbol":"LTCUSDT","id":"3129200","side":"Sell","size":69.2},{"price":"312.75","symbol":"LTCUSDT","id":"3127500","side":"Buy","size":136.90001},{"price":"312.93","symbol":"LTCUSDT","id":"3129300","side":"Sell","size":70.8},{"price":"312.76","symbol":"LTCUSDT","id":"3127600","side":"Buy","size":138.1}]},"cross_seq":"1684521486","timestamp_e6":"1618677786358419"}
1618677786.985697: {"topic":"orderBookL2_25.LTCUSDT","type":"delta","data":{"delete":[{"price":"312.93","symbol":"LTCUSDT","id":"3129300","side":"Sell"},{"price":"312.92","symbol":"LTCUSDT","id":"3129200","side":"Sell"},{"price":"312.75","symbol":"LTCUSDT","id":"3127500","side":"Buy"}],"update":[{"price":"312.89","symbol":"LTCUSDT","id":"3128900","side":"Sell","size":116.7},{"price":"312.72","symbol":"LTCUSDT","id":"3127200","side":"Buy","size":108.4},{"price":"312.94","symbol":"LTCUSDT","id":"3129400","side":"Sell","size":39},{"price":"312.71","symbol":"LTCUSDT","id":"3127100","side":"Buy","size":70.1},{"price":"312.90","symbol":"LTCUSDT","id":"3129000","side":"Sell","size":70.700005},{"price":"312.91","symbol":"LTCUSDT","id":"3129100","side":"Sell","size":41}],"insert":[{"price":"312.74","symbol":"LTCUSDT","id":"3127400","side":"Buy","size":136.90001},{"price":"313.14","symbol":"LTCUSDT","id":"3131400","side":"Sell","size":28.2},{"price":"313.13","symbol":"LTCUSDT","id":"3131300","side":"Sell","size":87}]},"cross_seq":"1684521535","timestamp_e6":"1618677786398471"}
1618677786.985738: {"topic":"orderBookL2_25.LTCUSDT","type":"delta","data":{"delete":[{"price":"313.12","symbol":"LTCUSDT","id":"3131200","side":"Sell"},{"price":"312.76","symbol":"LTCUSDT","id":"3127600","side":"Buy"},{"price":"313.11","symbol":"LTCUSDT","id":"3131100","side":"Sell"},{"price":"313.14","symbol":"LTCUSDT","id":"3131400","side":"Sell"},{"price":"313.13","symbol":"LTCUSDT","id":"3131300","side":"Sell"}],"update":[{"price":"312.84","symbol":"LTCUSDT","id":"3128400","side":"Sell","size":71.1},{"price":"312.82","symbol":"LTCUSDT","id":"3128200","side":"Sell","size":265.80002},{"price":"312.70","symbol":"LTCUSDT","id":"3127000","side":"Buy","size":79.299995}],"insert":[{"price":"312.87","symbol":"LTCUSDT","id":"3128700","side":"Sell","size":39},{"price":"312.83","symbol":"LTCUSDT","id":"3128300","side":"Sell","size":69.2},{"price":"312.86","symbol":"LTCUSDT","id":"3128600","side":"Sell","size":41},{"price":"312.85","symbol":"LTCUSDT","id":"3128500","side":"Sell","size":31},{"price":"312.75","symbol":"LTCUSDT","id":"3127500","side":"Buy","size":138.1}]},"cross_seq":"1684521551","timestamp_e6":"1618677786419333"}
1618677786.985783: {"topic":"orderBookL2_25.LTCUSDT","type":"delta","data":{"delete":[],"update":[{"price":"312.90","symbol":"LTCUSDT","id":"3129000","side":"Sell","size":69.2},{"price":"312.82","symbol":"LTCUSDT","id":"3128200","side":"Sell","size":267.30002}],"insert":[]},"cross_seq":"1684521562","timestamp_e6":"1618677786439166"}
1618677786.9857972: {"topic":"orderBookL2_25.LTCUSDT","type":"delta","data":{"delete":[{"price":"312.74","symbol":"LTCUSDT","id":"3127400","side":"Buy"}],"update":[{"price":"312.71","symbol":"LTCUSDT","id":"3127100","side":"Buy","size":1.5},{"price":"312.72","symbol":"LTCUSDT","id":"3127200","side":"Buy","size":43.5},{"price":"312.81","symbol":"LTCUSDT","id":"3128100","side":"Buy","size":36.8}],"insert":[{"price":"312.76","symbol":"LTCUSDT","id":"3127600","side":"Buy","size":138.1}]},"cross_seq":"1684521567","timestamp_e6":"1618677786499553"}
1618677786.9858189: {"topic":"orderBookL2_25.LTCUSDT","type":"delta","data":{"delete":[],"update":[{"price":"312.81","symbol":"LTCUSDT","id":"3128100","side":"Buy","size":20.6}],"insert":[]},"cross_seq":"1684521568","timestamp_e6":"1618677786519600"}
1618677786.985832: {"topic":"orderBookL2_25.LTCUSDT","type":"delta","data":{"delete":[],"update":[{"price":"312.82","symbol":"LTCUSDT","id":"3128200","side":"Sell","size":473.80002},{"price":"312.65","symbol":"LTCUSDT","id":"3126500","side":"Buy","size":66.1},{"price":"312.73","symbol":"LTCUSDT","id":"3127300","side":"Buy","size":118.6}],"insert":[]},"cross_seq":"1684521570","timestamp_e6":"1618677786539238"}
1618677786.985847: {"topic":"orderBookL2_25.LTCUSDT","type":"delta","data":{"delete":[],"update":[{"price":"312.81","symbol":"LTCUSDT","id":"3128100","side":"Buy","size":36.8}],"insert":[]},"cross_seq":"1684521571","timestamp_e6":"1618677786580507"}
1618677786.985858: {"topic":"orderBookL2_25.LTCUSDT","type":"delta","data":{"delete":[{"price":"312.75","symbol":"LTCUSDT","id":"3127500","side":"Buy"},{"price":"312.52","symbol":"LTCUSDT","id":"3125200","side":"Buy"}],"update":[{"price":"312.70","symbol":"LTCUSDT","id":"3127000","side":"Buy","size":107.2},{"price":"312.73","symbol":"LTCUSDT","id":"3127300","side":"Buy","size":61.3}],"insert":[{"price":"312.74","symbol":"LTCUSDT","id":"3127400","side":"Buy","size":108.4},{"price":"312.77","symbol":"LTCUSDT","id":"3127700","side":"Buy","size":138.1}]},"cross_seq":"1684521582","timestamp_e6":"1618677786598257"}
1618677786.985884: {"success":true,"ret_msg":"","conn_id":"38cf0ac3-af67-483c-9bbc-b57d45910ecb","request":{"op":"subscribe","args":["orderBookL2_25.LTCUSDT"]}}
1618677786.9858902: {"topic":"orderBookL2_25.DOTUSDT","type":"snapshot","data":{"order_book":[{"price":"43.375","symbol":"DOTUSDT","id":"433750","side":"Buy","size":294.69998},{"price":"43.380","symbol":"DOTUSDT","id":"433800","side":"Buy","size":37},{"price":"43.385","symbol":"DOTUSDT","id":"433850","side":"Buy","size":63.100002},{"price":"43.390","symbol":"DOTUSDT","id":"433900","side":"Buy","size":126.1},{"price":"43.395","symbol":"DOTUSDT","id":"433950","side":"Buy","size":308.9},{"price":"43.400","symbol":"DOTUSDT","id":"434000","side":"Buy","size":1.2},{"price":"43.405","symbol":"DOTUSDT","id":"434050","side":"Buy","size":444.5},{"price":"43.410","symbol":"DOTUSDT","id":"434100","side":"Buy","size":252.7},{"price":"43.415","symbol":"DOTUSDT","id":"434150","side":"Buy","size":83.7},{"price":"43.420","symbol":"DOTUSDT","id":"434200","side":"Buy","size":207.1},{"price":"43.425","symbol":"DOTUSDT","id":"434250","side":"Buy","size":332.4},{"price":"43.430","symbol":"DOTUSDT","id":"434300","side":"Buy","size":168.7},{"price":"43.435","symbol":"DOTUSDT","id":"434350","side":"Buy","size":226},{"price":"43.440","symbol":"DOTUSDT","id":"434400","side":"Buy","size":260.1},{"price":"43.445","symbol":"DOTUSDT","id":"434450","side":"Buy","size":97.200005},{"price":"43.450","symbol":"DOTUSDT","id":"434500","side":"Buy","size":99.399994},{"price":"43.455","symbol":"DOTUSDT","id":"434550","side":"Buy","size":353.5},{"price":"43.460","symbol":"DOTUSDT","id":"434600","side":"Buy","size":238.5},{"price":"43.465","symbol":"DOTUSDT","id":"434650","side":"Buy","size":246.79999},{"price":"43.470","symbol":"DOTUSDT","id":"434700","side":"Buy","size":383.7},{"price":"43.475","symbol":"DOTUSDT","id":"434750","side":"Buy","size":526.5},{"price":"43.480","symbol":"DOTUSDT","id":"434800","side":"Buy","size":34.300003},{"price":"43.485","symbol":"DOTUSDT","id":"434850","side":"Buy","size":116},{"price":"43.490","symbol":"DOTUSDT","id":"434900","side":"Buy","size":10},{"price":"43.500","symbol":"DOTUSDT","id":"435000","side":"Buy","size":192.1},{"price":"43.505","symbol":"DOTUSDT","id":"435050","side":"Sell","size":547.4},{"price":"43.510","symbol":"DOTUSDT","id":"435100","side":"Sell","size":330},{"price":"43.515","symbol":"DOTUSDT","id":"435150","side":"Sell","size":10},{"price":"43.530","symbol":"DOTUSDT","id":"435300","side":"Sell","size":245.5},{"price":"43.550","symbol":"DOTUSDT","id":"435500","side":"Sell","size":5.8},{"price":"43.555","symbol":"DOTUSDT","id":"435550","side":"Sell","size":58.4},{"price":"43.560","symbol":"DOTUSDT","id":"435600","side":"Sell","size":461.5},{"price":"43.565","symbol":"DOTUSDT","id":"435650","side":"Sell","size":12.1},{"price":"43.570","symbol":"DOTUSDT","id":"435700","side":"Sell","size":77.6},{"price":"43.580","symbol":"DOTUSDT","id":"435800","side":"Sell","size":192.29999},{"price":"43.585","symbol":"DOTUSDT","id":"435850","side":"Sell","size":281.5},{"price":"43.590","symbol":"DOTUSDT","id":"435900","side":"Sell","size":649.6},{"price":"43.595","symbol":"DOTUSDT","id":"435950","side":"Sell","size":157.5},{"price":"43.600","symbol":"DOTUSDT","id":"436000","side":"Sell","size":51.2},{"price":"43.605","symbol":"DOTUSDT","id":"436050","side":"Sell","size":132},{"price":"43.610","symbol":"DOTUSDT","id":"436100","side":"Sell","size":344.19998},{"price":"43.615","symbol":"DOTUSDT","id":"436150","side":"Sell","size":285.19998},{"price":"43.620","symbol":"DOTUSDT","id":"436200","side":"Sell","size":152.7},{"price":"43.625","symbol":"DOTUSDT","id":"436250","side":"Sell","size":320.2},{"price":"43.630","symbol":"DOTUSDT","id":"436300","side":"Sell","size":301.9},{"price":"43.635","symbol":"DOTUSDT","id":"436350","side":"Sell","size":37},{"price":"43.640","symbol":"DOTUSDT","id":"436400","side":"Sell","size":205.7},{"price":"43.645","symbol":"DOTUSDT","id":"436450","side":"Sell","size":289.4},{"price":"43.650","symbol":"DOTUSDT","id":"436500","side":"Sell","size":151},{"price":"43.655","symbol":"DOTUSDT","id":"436550","side":"Sell","size":420.2}]},"cross_seq":"916952241","timestamp_e6":"1618677786242642"}
1618677786.986058: {"topic":"orderBookL2_25.DOTUSDT","type":"delta","data":{"delete":[{"price":"43.655","symbol":"DOTUSDT","id":"436550","side":"Sell"}],"update":[{"price":"43.505","symbol":"DOTUSDT","id":"435050","side":"Sell","size":937.39996}],"insert":[{"price":"43.520","symbol":"DOTUSDT","id":"435200","side":"Sell","size":172.3}]},"cross_seq":"916952259","timestamp_e6":"1618677786282623"}
1618677786.98608: {"topic":"orderBookL2_25.DOTUSDT","type":"delta","data":{"delete":[{"price":"43.510","symbol":"DOTUSDT","id":"435100","side":"Sell"}],"update":[],"insert":[{"price":"43.655","symbol":"DOTUSDT","id":"436550","side":"Sell","size":420.2}]},"cross_seq":"916952261","timestamp_e6":"1618677786302332"}
1618677786.9860969: {"topic":"orderBookL2_25.DOTUSDT","type":"delta","data":{"delete":[],"update":[{"price":"43.480","symbol":"DOTUSDT","id":"434800","side":"Buy","size":35.4}],"insert":[]},"cross_seq":"916952264","timestamp_e6":"1618677786322332"}
1618677786.98611: {"topic":"orderBookL2_25.DOTUSDT","type":"delta","data":{"delete":[{"price":"43.655","symbol":"DOTUSDT","id":"436550","side":"Sell"},{"price":"43.650","symbol":"DOTUSDT","id":"436500","side":"Sell"}],"update":[{"price":"43.425","symbol":"DOTUSDT","id":"434250","side":"Buy","size":241.9},{"price":"43.470","symbol":"DOTUSDT","id":"434700","side":"Buy","size":433.7},{"price":"43.465","symbol":"DOTUSDT","id":"434650","side":"Buy","size":292.69998},{"price":"43.520","symbol":"DOTUSDT","id":"435200","side":"Sell","size":453.99997},{"price":"43.530","symbol":"DOTUSDT","id":"435300","side":"Sell","size":362.69998},{"price":"43.480","symbol":"DOTUSDT","id":"434800","side":"Buy","size":485.5},{"price":"43.485","symbol":"DOTUSDT","id":"434850","side":"Buy","size":10},{"price":"43.455","symbol":"DOTUSDT","id":"434550","side":"Buy","size":41.3},{"price":"43.515","symbol":"DOTUSDT","id":"435150","side":"Sell","size":283.4}],"insert":[{"price":"43.510","symbol":"DOTUSDT","id":"435100","side":"Sell","size":327.3},{"price":"43.525","symbol":"DOTUSDT","id":"435250","side":"Sell","size":215.70001}]},"cross_seq":"916952294","timestamp_e6":"1618677786362544"}
1618677786.986167: {"topic":"orderBookL2_25.DOTUSDT","type":"delta","data":{"delete":[],"update":[{"price":"43.515","symbol":"DOTUSDT","id":"435150","side":"Sell","size":273.4},{"price":"43.505","symbol":"DOTUSDT","id":"435050","side":"Sell","size":947.39996}],"insert":[]},"cross_seq":"916952311","timestamp_e6":"1618677786382601"}
1618677786.986181: {"topic":"orderBookL2_25.DOTUSDT","type":"delta","data":{"delete":[],"update":[{"price":"43.460","symbol":"DOTUSDT","id":"434600","side":"Buy","size":132},{"price":"43.470","symbol":"DOTUSDT","id":"434700","side":"Buy","size":514.5},{"price":"43.485","symbol":"DOTUSDT","id":"434850","side":"Buy","size":388.4},{"price":"43.475","symbol":"DOTUSDT","id":"434750","side":"Buy","size":240.4},{"price":"43.480","symbol":"DOTUSDT","id":"434800","side":"Buy","size":107.1}],"insert":[]},"cross_seq":"916952334","timestamp_e6":"1618677786402480"}
1618677786.9862: {"topic":"orderBookL2_25.DOTUSDT","type":"delta","data":{"delete":[],"update":[{"price":"43.460","symbol":"DOTUSDT","id":"434600","side":"Buy","size":273.7},{"price":"43.475","symbol":"DOTUSDT","id":"434750","side":"Buy","size":554.89996},{"price":"43.470","symbol":"DOTUSDT","id":"434700","side":"Buy","size":376.1}],"insert":[]},"cross_seq":"916952388","timestamp_e6":"1618677786482459"}
1618677786.986214: {"topic":"orderBookL2_25.DOTUSDT","type":"delta","data":{"delete":[],"update":[{"price":"43.480","symbol":"DOTUSDT","id":"434800","side":"Buy","size":485.5},{"price":"43.485","symbol":"DOTUSDT","id":"434850","side":"Buy","size":10},{"price":"43.530","symbol":"DOTUSDT","id":"435300","side":"Sell","size":461.2},{"price":"43.470","symbol":"DOTUSDT","id":"434700","side":"Buy","size":462.5},{"price":"43.510","symbol":"DOTUSDT","id":"435100","side":"Sell","size":82},{"price":"43.525","symbol":"DOTUSDT","id":"435250","side":"Sell","size":281.7},{"price":"43.455","symbol":"DOTUSDT","id":"434550","side":"Buy","size":116.4}],"insert":[]},"cross_seq":"916952447","timestamp_e6":"1618677786582516"}
1618677786.986238: {"topic":"orderBookL2_25.DOTUSDT","type":"delta","data":{"delete":[],"update":[{"price":"43.505","symbol":"DOTUSDT","id":"435050","side":"Sell","size":799.3},{"price":"43.515","symbol":"DOTUSDT","id":"435150","side":"Sell","size":283.4}],"insert":[]},"cross_seq":"916952464","timestamp_e6":"1618677786602488"}
1618677786.986251: {"success":true,"ret_msg":"","conn_id":"38cf0ac3-af67-483c-9bbc-b57d45910ecb","request":{"op":"subscribe","args":["orderBookL2_25.DOTUSDT"]}}
1618677787.1672902: {"topic":"orderBookL2_25.LINKUSDT","type":"snapshot","data":{"order_book":[{"price":"41.023","symbol":"LINKUSDT","id":"410230","side":"Buy","size":201.9},{"price":"41.024","symbol":"LINKUSDT","id":"410240","side":"Buy","size":423.6},{"price":"41.025","symbol":"LINKUSDT","id":"410250","side":"Buy","size":687.2},{"price":"41.026","symbol":"LINKUSDT","id":"410260","side":"Buy","size":704},{"price":"41.027","symbol":"LINKUSDT","id":"410270","side":"Buy","size":336.8},{"price":"41.028","symbol":"LINKUSDT","id":"410280","side":"Buy","size":425.9},{"price":"41.029","symbol":"LINKUSDT","id":"410290","side":"Buy","size":417.5},{"price":"41.030","symbol":"LINKUSDT","id":"410300","side":"Buy","size":82.5},{"price":"41.031","symbol":"LINKUSDT","id":"410310","side":"Buy","size":163.09999},{"price":"41.032","symbol":"LINKUSDT","id":"410320","side":"Buy","size":399.40002},{"price":"41.033","symbol":"LINKUSDT","id":"410330","side":"Buy","size":1141},{"price":"41.034","symbol":"LINKUSDT","id":"410340","side":"Buy","size":615.6},{"price":"41.035","symbol":"LINKUSDT","id":"410350","side":"Buy","size":180.59999},{"price":"41.036","symbol":"LINKUSDT","id":"410360","side":"Buy","size":434.5},{"price":"41.037","symbol":"LINKUSDT","id":"410370","side":"Buy","size":376.00003},{"price":"41.038","symbol":"LINKUSDT","id":"410380","side":"Buy","size":243.3},{"price":"41.039","symbol":"LINKUSDT","id":"410390","side":"Buy","size":157.40001},{"price":"41.040","symbol":"LINKUSDT","id":"410400","side":"Buy","size":226.8},{"price":"41.041","symbol":"LINKUSDT","id":"410410","side":"Buy","size":376.6},{"price":"41.042","symbol":"LINKUSDT","id":"410420","side":"Buy","size":398.3},{"price":"41.043","symbol":"LINKUSDT","id":"410430","side":"Buy","size":101.700005},{"price":"41.044","symbol":"LINKUSDT","id":"410440","side":"Buy","size":125.700005},{"price":"41.045","symbol":"LINKUSDT","id":"410450","side":"Buy","size":175.29999},{"price":"41.046","symbol":"LINKUSDT","id":"410460","side":"Buy","size":155.8},{"price":"41.047","symbol":"LINKUSDT","id":"410470","side":"Buy","size":1440.7999},{"price":"41.048","symbol":"LINKUSDT","id":"410480","side":"Sell","size":66},{"price":"41.052","symbol":"LINKUSDT","id":"410520","side":"Sell","size":1},{"price":"41.056","symbol":"LINKUSDT","id":"410560","side":"Sell","size":323.2},{"price":"41.057","symbol":"LINKUSDT","id":"410570","side":"Sell","size":299.5},{"price":"41.058","symbol":"LINKUSDT","id":"410580","side":"Sell","size":212.90001},{"price":"41.059","symbol":"LINKUSDT","id":"410590","side":"Sell","size":192.29999},{"price":"41.060","symbol":"LINKUSDT","id":"410600","side":"Sell","size":201.8},{"price":"41.061","symbol":"LINKUSDT","id":"410610","side":"Sell","size":92},{"price":"41.062","symbol":"LINKUSDT","id":"410620","side":"Sell","size":45.100002},{"price":"41.063","symbol":"LINKUSDT","id":"410630","side":"Sell","size":282.1},{"price":"41.064","symbol":"LINKUSDT","id":"410640","side":"Sell","size":43.9},{"price":"41.065","symbol":"LINKUSDT","id":"410650","side":"Sell","size":157.9},{"price":"41.066","symbol":"LINKUSDT","id":"410660","side":"Sell","size":421},{"price":"41.067","symbol":"LINKUSDT","id":"410670","side":"Sell","size":15.5},{"price":"41.068","symbol":"LINKUSDT","id":"410680","side":"Sell","size":348.8},{"price":"41.069","symbol":"LINKUSDT","id":"410690","side":"Sell","size":39.3},{"price":"41.070","symbol":"LINKUSDT","id":"410700","side":"Sell","size":89},{"price":"41.071","symbol":"LINKUSDT","id":"410710","side":"Sell","size":15.4},{"price":"41.072","symbol":"LINKUSDT","id":"410720","side":"Sell","size":35.9},{"price":"41.073","symbol":"LINKUSDT","id":"410730","side":"Sell","size":33.9},{"price":"41.074","symbol":"LINKUSDT","id":"410740","side":"Sell","size":99},{"price":"41.075","symbol":"LINKUSDT","id":"410750","side":"Sell","size":8.3},{"price":"41.076","symbol":"LINKUSDT","id":"410760","side":"Sell","size":237.59999},{"price":"41.077","symbol":"LINKUSDT","id":"410770","side":"Sell","size":194.99998},{"price":"41.078","symbol":"LINKUSDT","id":"410780","side":"Sell","size":121.200005}]},"cross_seq":"1970978233","timestamp_e6":"1618677786224457"}
1618677787.16767: {"topic":"orderBookL2_25.LINKUSDT","type":"delta","data":{"delete":[{"price":"41.048","symbol":"LINKUSDT","id":"410480","side":"Sell"}],"update":[],"insert":[{"price":"41.079","symbol":"LINKUSDT","id":"410790","side":"Sell","size":69.4}]},"cross_seq":"1970978234","timestamp_e6":"1618677786264147"}
1618677787.167715: {"topic":"orderBookL2_25.LINKUSDT","type":"delta","data":{"delete":[{"price":"41.063","symbol":"LINKUSDT","id":"410630","side":"Sell"},{"price":"41.062","symbol":"LINKUSDT","id":"410620","side":"Sell"},{"price":"41.066","symbol":"LINKUSDT","id":"410660","side":"Sell"},{"price":"41.061","symbol":"LINKUSDT","id":"410610","side":"Sell"},{"price":"41.059","symbol":"LINKUSDT","id":"410590","side":"Sell"},{"price":"41.023","symbol":"LINKUSDT","id":"410230","side":"Buy"},{"price":"41.056","symbol":"LINKUSDT","id":"410560","side":"Sell"},{"price":"41.068","symbol":"LINKUSDT","id":"410680","side":"Sell"},{"price":"41.024","symbol":"LINKUSDT","id":"410240","side":"Buy"},{"price":"41.057","symbol":"LINKUSDT","id":"410570","side":"Sell"},{"price":"41.058","symbol":"LINKUSDT","id":"410580","side":"Sell"},{"price":"41.060","symbol":"LINKUSDT","id":"410600","side":"Sell"}],"update":[{"price":"41.067","symbol":"LINKUSDT","id":"410670","side":"Sell","size":114.8},{"price":"41.043","symbol":"LINKUSDT","id":"410430","side":"Buy","size":135.3},{"price":"41.069","symbol":"LINKUSDT","id":"410690","side":"Sell","size":69.1},{"price":"41.046","symbol":"LINKUSDT","id":"410460","side":"Buy","size":198.7},{"price":"41.064","symbol":"LINKUSDT","id":"410640","side":"Sell","size":179.49998}],"insert":[{"price":"41.080","symbol":"LINKUSDT","id":"410800","side":"Sell","size":41.3},{"price":"41.081","symbol":"LINKUSDT","id":"410810","side":"Sell","size":60.8},{"price":"41.085","symbol":"LINKUSDT","id":"410850","side":"Sell","size":123.5},{"price":"41.087","symbol":"LINKUSDT","id":"410870","side":"Sell","size":2.5},{"price":"41.089","symbol":"LINKUSDT","id":"410890","side":"Sell","size":96.8},{"price":"41.051","symbol":"LINKUSDT","id":"410510","side":"Buy","size":134.3},{"price":"41.050","symbol":"LINKUSDT","id":"410500","side":"Buy","size":55.000004},{"price":"41.083","symbol":"LINKUSDT","id":"410830","side":"Sell","size":72.5},{"price":"41.086","symbol":"LINKUSDT","id":"410860","side":"Sell","size":70.1},{"price":"41.088","symbol":"LINKUSDT","id":"410880","side":"Sell","size":72.4},{"price":"41.084","symbol":"LINKUSDT","id":"410840","side":"Sell","size":64.2},{"price":"41.082","symbol":"LINKUSDT","id":"410820","side":"Sell","size":142.79999}]},"cross_seq":"1970978293","timestamp_e6":"1618677786284990"}
1618677787.167933: {"topic":"orderBookL2_25.LINKUSDT","type":"delta","data":{"delete":[{"price":"41.064","symbol":"LINKUSDT","id":"410640","side":"Sell"},{"price":"41.065","symbol":"LINKUSDT","id":"410650","side":"Sell"}],"update":[{"price":"41.047","symbol":"LINKUSDT","id":"410470","side":"Buy","size":1034.8},{"price":"41.051","symbol":"LINKUSDT","id":"410510","side":"Buy","size":1040.3}],"insert":[{"price":"41.068","symbol":"LINKUSDT","id":"410680","side":"Sell","size":69.1},{"price":"41.066","symbol":"LINKUSDT","id":"410660","side":"Sell","size":114.8}]},"cross_seq":"1970978322","timestamp_e6":"1618677786304862"}
1618677787.16802: {"topic":"orderBookL2_25.LINKUSDT","type":"delta","data":{"delete":[{"price":"41.089","symbol":"LINKUSDT","id":"410890","side":"Sell"},{"price":"41.088","symbol":"LINKUSDT","id":"410880","side":"Sell"}],"update":[{"price":"41.068","symbol":"LINKUSDT","id":"410680","side":"Sell","size":103.1},{"price":"41.051","symbol":"LINKUSDT","id":"410510","side":"Buy","size":1554.5},{"price":"41.047","symbol":"LINKUSDT","id":"410470","side":"Buy","size":310.6}],"insert":[{"price":"41.064","symbol":"LINKUSDT","id":"410640","side":"Sell","size":223.4},{"price":"41.065","symbol":"LINKUSDT","id":"410650","side":"Sell","size":142.5}]},"cross_seq":"1970978332","timestamp_e6":"1618677786324870"}
1618677787.168082: {"topic":"orderBookL2_25.LINKUSDT","type":"delta","data":{"delete":[],"update":[{"price":"41.047","symbol":"LINKUSDT","id":"410470","side":"Buy","size":270.6}],"insert":[]},"cross_seq":"1970978338","timestamp_e6":"1618677786343755"}
1618677787.168107: {"topic":"orderBookL2_25.LINKUSDT","type":"delta","data":{"delete":[],"update":[{"price":"41.069","symbol":"LINKUSDT","id":"410690","side":"Sell","size":103.1},{"price":"41.081","symbol":"LINKUSDT","id":"410810","side":"Sell","size":123},{"price":"41.065","symbol":"LINKUSDT","id":"410650","side":"Sell","size":80.9},{"price":"41.051","symbol":"LINKUSDT","id":"410510","side":"Buy","size":1628.5}],"insert":[]},"cross_seq":"1970978366","timestamp_e6":"1618677786364862"}
1618677787.16814: {"topic":"orderBookL2_25.LINKUSDT","type":"delta","data":{"delete":[],"update":[{"price":"41.052","symbol":"LINKUSDT","id":"410520","side":"Sell","size":67}],"insert":[]},"cross_seq":"1970978367","timestamp_e6":"1618677786384713"}
1618677787.168161: {"topic":"orderBookL2_25.LINKUSDT","type":"delta","data":{"delete":[{"price":"41.086","symbol":"LINKUSDT","id":"410860","side":"Sell"},{"price":"41.045","symbol":"LINKUSDT","id":"410450","side":"Buy"},{"price":"41.087","symbol":"LINKUSDT","id":"410870","side":"Sell"},{"price":"41.064","symbol":"LINKUSDT","id":"410640","side":"Sell"},{"price":"41.047","symbol":"LINKUSDT","id":"410470","side":"Buy"},{"price":"41.084","symbol":"LINKUSDT","id":"410840","side":"Sell"},{"price":"41.085","symbol":"LINKUSDT","id":"410850","side":"Sell"}],"update":[{"price":"41.044","symbol":"LINKUSDT","id":"410440","side":"Buy","size":582.4},{"price":"41.040","symbol":"LINKUSDT","id":"410400","side":"Buy","size":258.6},{"price":"41.042","symbol":"LINKUSDT","id":"410420","side":"Buy","size":421.5},{"price":"41.039","symbol":"LINKUSDT","id":"410390","side":"Buy","size":308},{"price":"41.043","symbol":"LINKUSDT","id":"410430","side":"Buy","size":1},{"price":"41.050","symbol":"LINKUSDT","id":"410500","side":"Buy","size":198.7},{"price":"41.046","symbol":"LINKUSDT","id":"410460","side":"Buy","size":42.899998},{"price":"41.041","symbol":"LINKUSDT","id":"410410","side":"Buy","size":793.8},{"price":"41.038","symbol":"LINKUSDT","id":"410380","side":"Buy","size":120.2},{"price":"41.051","symbol":"LINKUSDT","id":"410510","side":"Buy","size":1607.4}],"insert":[{"price":"41.061","symbol":"LINKUSDT","id":"410610","side":"Sell","size":99.7},{"price":"41.063","symbol":"LINKUSDT","id":"410630","side":"Sell","size":103.1},{"price":"41.059","symbol":"LINKUSDT","id":"410590","side":"Sell","size":223.4},{"price":"41.062","symbol":"LINKUSDT","id":"410620","side":"Sell","size":114.8},{"price":"41.049","symbol":"LINKUSDT","id":"410490","side":"Buy","size":210.59999},{"price":"41.048","symbol":"LINKUSDT","id":"410480","side":"Buy","size":114.200005},{"price":"41.060","symbol":"LINKUSDT","id":"410600","side":"Sell","size":142.5}]},"cross_seq":"1970978402","timestamp_e6":"1618677786404899"}
1618677787.168295: {"topic":"orderBookL2_25.LINKUSDT","type":"delta","data":{"delete":[],"update":[{"price":"41.037","symbol":"LINKUSDT","id":"410370","side":"Buy","size":242.59999},{"price":"41.040","symbol":"LINKUSDT","id":"410400","side":"Buy","size":31.8},{"price":"41.041","symbol":"LINKUSDT","id":"410410","side":"Buy","size":737.7},{"price":"41.039","symbol":"LINKUSDT","id":"410390","side":"Buy","size":345.19998},{"price":"41.042","symbol":"LINKUSDT","id":"410420","side":"Buy","size":70.9}],"insert":[]},"cross_seq":"1970978421","timestamp_e6":"1618677786545458"}
1618677787.168334: {"success":true,"ret_msg":"","conn_id":"38cf0ac3-af67-483c-9bbc-b57d45910ecb","request":{"op":"subscribe","args":["orderBookL2_25.LINKUSDT"]}}
1618677787.1683462: {"topic":"orderBookL2_25.ADAUSDT","type":"snapshot","data":{"order_book":[{"price":"1.3850","symbol":"ADAUSDT","id":"13850","side":"Buy","size":12851},{"price":"1.3851","symbol":"ADAUSDT","id":"13851","side":"Buy","size":1334},{"price":"1.3852","symbol":"ADAUSDT","id":"13852","side":"Buy","size":622},{"price":"1.3853","symbol":"ADAUSDT","id":"13853","side":"Buy","size":5103},{"price":"1.3854","symbol":"ADAUSDT","id":"13854","side":"Buy","size":5330},{"price":"1.3855","symbol":"ADAUSDT","id":"13855","side":"Buy","size":1408},{"price":"1.3856","symbol":"ADAUSDT","id":"13856","side":"Buy","size":6468},{"price":"1.3857","symbol":"ADAUSDT","id":"13857","side":"Buy","size":5815},{"price":"1.3858","symbol":"ADAUSDT","id":"13858","side":"Buy","size":3284},{"price":"1.3859","symbol":"ADAUSDT","id":"13859","side":"Buy","size":3770},{"price":"1.3860","symbol":"ADAUSDT","id":"13860","side":"Buy","size":4429},{"price":"1.3861","symbol":"ADAUSDT","id":"13861","side":"Buy","size":4604},{"price":"1.3862","symbol":"ADAUSDT","id":"13862","side":"Buy","size":3527},{"price":"1.3863","symbol":"ADAUSDT","id":"13863","side":"Buy","size":4575},{"price":"1.3864","symbol":"ADAUSDT","id":"13864","side":"Buy","size":2382},{"price":"1.3865","symbol":"ADAUSDT","id":"13865","side":"Buy","size":1547},{"price":"1.3866","symbol":"ADAUSDT","id":"13866","side":"Buy","size":3511},{"price":"1.3867","symbol":"ADAUSDT","id":"13867","side":"Buy","size":6591},{"price":"1.3868","symbol":"ADAUSDT","id":"13868","side":"Buy","size":7911},{"price":"1.3870","symbol":"ADAUSDT","id":"13870","side":"Buy","size":3400.0002},{"price":"1.3871","symbol":"ADAUSDT","id":"13871","side":"Buy","size":15109},{"price":"1.3872","symbol":"ADAUSDT","id":"13872","side":"Buy","size":4661},{"price":"1.3873","symbol":"ADAUSDT","id":"13873","side":"Buy","size":1},{"price":"1.3874","symbol":"ADAUSDT","id":"13874","side":"Buy","size":8000},{"price":"1.3877","symbol":"ADAUSDT","id":"13877","side":"Buy","size":49615},{"price":"1.3878","symbol":"ADAUSDT","id":"13878","side":"Sell","size":4698},{"price":"1.3879","symbol":"ADAUSDT","id":"13879","side":"Sell","size":5621},{"price":"1.3880","symbol":"ADAUSDT","id":"13880","side":"Sell","size":4814},{"price":"1.3881","symbol":"ADAUSDT","id":"13881","side":"Sell","size":7562},{"price":"1.3882","symbol":"ADAUSDT","id":"13882","side":"Sell","size":7018},{"price":"1.3883","symbol":"ADAUSDT","id":"13883","side":"Sell","size":6161},{"price":"1.3884","symbol":"ADAUSDT","id":"13884","side":"Sell","size":2288},{"price":"1.3885","symbol":"ADAUSDT","id":"13885","side":"Sell","size":1850.9999},{"price":"1.3886","symbol":"ADAUSDT","id":"13886","side":"Sell","size":1197},{"price":"1.3887","symbol":"ADAUSDT","id":"13887","side":"Sell","size":1833},{"price":"1.3888","symbol":"ADAUSDT","id":"13888","side":"Sell","size":4925},{"price":"1.3889","symbol":"ADAUSDT","id":"13889","side":"Sell","size":2254},{"price":"1.3890","symbol":"ADAUSDT","id":"13890","side":"Sell","size":939.99994},{"price":"1.3891","symbol":"ADAUSDT","id":"13891","side":"Sell","size":15920},{"price":"1.3892","symbol":"ADAUSDT","id":"13892","side":"Sell","size":12651},{"price":"1.3893","symbol":"ADAUSDT","id":"13893","side":"Sell","size":8698},{"price":"1.3894","symbol":"ADAUSDT","id":"13894","side":"Sell","size":5191},{"price":"1.3895","symbol":"ADAUSDT","id":"13895","side":"Sell","size":3368},{"price":"1.3896","symbol":"ADAUSDT","id":"13896","side":"Sell","size":2824},{"price":"1.3897","symbol":"ADAUSDT","id":"13897","side":"Sell","size":907.99994},{"price":"1.3898","symbol":"ADAUSDT","id":"13898","side":"Sell","size":6790},{"price":"1.3899","symbol":"ADAUSDT","id":"13899","side":"Sell","size":10776},{"price":"1.3900","symbol":"ADAUSDT","id":"13900","side":"Sell","size":7667.0005},{"price":"1.3901","symbol":"ADAUSDT","id":"13901","side":"Sell","size":6684.9995},{"price":"1.3902","symbol":"ADAUSDT","id":"13902","side":"Sell","size":8583}]},"cross_seq":"916952241","timestamp_e6":"1618677786242538"}
1618677787.168662: {"topic":"orderBookL2_25.ADAUSDT","type":"delta","data":{"delete":[],"update":[{"price":"1.3877","symbol":"ADAUSDT","id":"13877","side":"Buy","size":45615},{"price":"1.3874","symbol":"ADAUSDT","id":"13874","side":"Buy","size":11999.999}],"insert":[]},"cross_seq":"916952265","timestamp_e6":"1618677786342343"}
1618677787.168697: {"topic":"orderBookL2_25.ADAUSDT","type":"delta","data":{"delete":[],"update":[{"price":"1.3870","symbol":"ADAUSDT","id":"13870","side":"Buy","size":11400},{"price":"1.3861","symbol":"ADAUSDT","id":"13861","side":"Buy","size":5820},{"price":"1.3874","symbol":"ADAUSDT","id":"13874","side":"Buy","size":4000},{"price":"1.3883","symbol":"ADAUSDT","id":"13883","side":"Sell","size":5533},{"price":"1.3859","symbol":"ADAUSDT","id":"13859","side":"Buy","size":2436},{"price":"1.3877","symbol":"ADAUSDT","id":"13877","side":"Buy","size":39501},{"price":"1.3862","symbol":"ADAUSDT","id":"13862","side":"Buy","size":2795}],"insert":[]},"cross_seq":"916952294","timestamp_e6":"1618677786362388"}
1618677787.16874: {"topic":"orderBookL2_25.ADAUSDT","type":"delta","data":{"delete":[{"price":"1.3874","symbol":"ADAUSDT","id":"13874","side":"Buy"}],"update":[{"price":"1.3870","symbol":"ADAUSDT","id":"13870","side":"Buy","size":15400.001},{"price":"1.3877","symbol":"ADAUSDT","id":"13877","side":"Buy","size":33615}],"insert":[{"price":"1.3849","symbol":"ADAUSDT","id":"13849","side":"Buy","size":2018.0001}]},"cross_seq":"916952311","timestamp_e6":"1618677786382433"}
1618677787.1687832: {"topic":"orderBookL2_25.ADAUSDT","type":"delta","data":{"delete":[{"price":"1.3849","symbol":"ADAUSDT","id":"13849","side":"Buy"},{"price":"1.3866","symbol":"ADAUSDT","id":"13866","side":"Buy"}],"update":[{"price":"1.3870","symbol":"ADAUSDT","id":"13870","side":"Buy","size":7400},{"price":"1.3867","symbol":"ADAUSDT","id":"13867","side":"Buy","size":3080},{"price":"1.3877","symbol":"ADAUSDT","id":"13877","side":"Buy","size":45615},{"price":"1.3863","symbol":"ADAUSDT","id":"13863","side":"Buy","size":2300},{"price":"1.3868","symbol":"ADAUSDT","id":"13868","side":"Buy","size":12400}],"insert":[{"price":"1.3875","symbol":"ADAUSDT","id":"13875","side":"Buy","size":4000},{"price":"1.3874","symbol":"ADAUSDT","id":"13874","side":"Buy","size":4000}]},"cross_seq":"916952334","timestamp_e6":"1618677786402351"}
1618677787.168841: {"topic":"orderBookL2_25.ADAUSDT","type":"delta","data":{"delete":[{"price":"1.3864","symbol":"ADAUSDT","id":"13864","side":"Buy"}],"update":[{"price":"1.3862","symbol":"ADAUSDT","id":"13862","side":"Buy","size":4880},{"price":"1.3861","symbol":"ADAUSDT","id":"13861","side":"Buy","size":3992},{"price":"1.3863","symbol":"ADAUSDT","id":"13863","side":"Buy","size":5344}],"insert":[{"price":"1.3849","symbol":"ADAUSDT","id":"13849","side":"Buy","size":2018.0001}]},"cross_seq":"916952342","timestamp_e6":"1618677786422388"}
1618677787.168882: {"topic":"orderBookL2_25.ADAUSDT","type":"delta","data":{"delete":[],"update":[{"price":"1.3870","symbol":"ADAUSDT","id":"13870","side":"Buy","size":3400.0002},{"price":"1.3877","symbol":"ADAUSDT","id":"13877","side":"Buy","size":59780},{"price":"1.3874","symbol":"ADAUSDT","id":"13874","side":"Buy","size":8000}],"insert":[]},"cross_seq":"916952356","timestamp_e6":"1618677786442327"}
1618677787.16891: {"topic":"orderBookL2_25.ADAUSDT","type":"delta","data":{"delete":[],"update":[{"price":"1.3877","symbol":"ADAUSDT","id":"13877","side":"Buy","size":65924}],"insert":[]},"cross_seq":"916952357","timestamp_e6":"1618677786462489"}
1618677787.168928: {"topic":"orderBookL2_25.ADAUSDT","type":"delta","data":{"delete":[{"price":"1.3849","symbol":"ADAUSDT","id":"13849","side":"Buy"}],"update":[{"price":"1.3862","symbol":"ADAUSDT","id":"13862","side":"Buy","size":2795},{"price":"1.3865","symbol":"ADAUSDT","id":"13865","side":"Buy","size":4489},{"price":"1.3868","symbol":"ADAUSDT","id":"13868","side":"Buy","size":7911},{"price":"1.3867","symbol":"ADAUSDT","id":"13867","side":"Buy","size":2000},{"price":"1.3863","symbol":"ADAUSDT","id":"13863","side":"Buy","size":2300},{"price":"1.3877","symbol":"ADAUSDT","id":"13877","side":"Buy","size":51759},{"price":"1.3860","symbol":"ADAUSDT","id":"13860","side":"Buy","size":2154},{"price":"1.3861","symbol":"ADAUSDT","id":"13861","side":"Buy","size":5077}],"insert":[{"price":"1.3864","symbol":"ADAUSDT","id":"13864","side":"Buy","size":3044}]},"cross_seq":"916952388","timestamp_e6":"1618677786482340"}
1618677787.168983: {"topic":"orderBookL2_25.ADAUSDT","type":"delta","data":{"delete":[],"update":[{"price":"1.3860","symbol":"ADAUSDT","id":"13860","side":"Buy","size":5198},{"price":"1.3858","symbol":"ADAUSDT","id":"13858","side":"Buy","size":1543.0001}],"insert":[]},"cross_seq":"916952412","timestamp_e6":"1618677786563611"}
1618677787.169008: {"topic":"orderBookL2_25.ADAUSDT","type":"delta","data":{"delete":[{"price":"1.3875","symbol":"ADAUSDT","id":"13875","side":"Buy"}],"update":[{"price":"1.3859","symbol":"ADAUSDT","id":"13859","side":"Buy","size":4239},{"price":"1.3877","symbol":"ADAUSDT","id":"13877","side":"Buy","size":39501},{"price":"1.3861","symbol":"ADAUSDT","id":"13861","side":"Buy","size":2188},{"price":"1.3858","symbol":"ADAUSDT","id":"13858","side":"Buy","size":2025},{"price":"1.3857","symbol":"ADAUSDT","id":"13857","side":"Buy","size":1055},{"price":"1.3872","symbol":"ADAUSDT","id":"13872","side":"Buy","size":4000},{"price":"1.3856","symbol":"ADAUSDT","id":"13856","side":"Buy","size":2999.9998}],"insert":[{"price":"1.3849","symbol":"ADAUSDT","id":"13849","side":"Buy","size":2018.0001}]},"cross_seq":"916952447","timestamp_e6":"1618677786582374"}
1618677787.169065: {"topic":"orderBookL2_25.ADAUSDT","type":"delta","data":{"delete":[{"price":"1.3861","symbol":"ADAUSDT","id":"13861","side":"Buy"},{"price":"1.3865","symbol":"ADAUSDT","id":"13865","side":"Buy"}],"update":[{"price":"1.3864","symbol":"ADAUSDT","id":"13864","side":"Buy","size":4489},{"price":"1.3859","symbol":"ADAUSDT","id":"13859","side":"Buy","size":2154},{"price":"1.3877","symbol":"ADAUSDT","id":"13877","side":"Buy","size":45615},{"price":"1.3862","symbol":"ADAUSDT","id":"13862","side":"Buy","size":4880},{"price":"1.3860","symbol":"ADAUSDT","id":"13860","side":"Buy","size":2154},{"price":"1.3863","symbol":"ADAUSDT","id":"13863","side":"Buy","size":5344}],"insert":[{"price":"1.3847","symbol":"ADAUSDT","id":"13847","side":"Buy","size":4462},{"price":"1.3848","symbol":"ADAUSDT","id":"13848","side":"Buy","size":3559}]},"cross_seq":"916952464","timestamp_e6":"1618677786602338"}
1618677787.169138: {"success":true,"ret_msg":"","conn_id":"38cf0ac3-af67-483c-9bbc-b57d45910ecb","request":{"op":"subscribe","args":["orderBookL2_25.ADAUSDT"]}}
1618677787.1691468: {"topic":"orderBookL2_25.ETHUSDT","type":"snapshot","data":{"order_book":[{"price":"2362.65","symbol":"ETHUSDT","id":"23626500","side":"Buy","size":29.51},{"price":"2362.70","symbol":"ETHUSDT","id":"23627000","side":"Buy","size":29.180002},{"price":"2362.75","symbol":"ETHUSDT","id":"23627500","side":"Buy","size":49.250004},{"price":"2362.80","symbol":"ETHUSDT","id":"23628000","side":"Buy","size":88.409996},{"price":"2362.85","symbol":"ETHUSDT","id":"23628500","side":"Buy","size":24.419998},{"price":"2362.90","symbol":"ETHUSDT","id":"23629000","side":"Buy","size":37.88},{"price":"2362.95","symbol":"ETHUSDT","id":"23629500","side":"Buy","size":37.84},{"price":"2363.00","symbol":"ETHUSDT","id":"23630000","side":"Buy","size":56.95},{"price":"2363.05","symbol":"ETHUSDT","id":"23630500","side":"Buy","size":52.48},{"price":"2363.10","symbol":"ETHUSDT","id":"23631000","side":"Buy","size":43.92},{"price":"2363.15","symbol":"ETHUSDT","id":"23631500","side":"Buy","size":41.85},{"price":"2363.20","symbol":"ETHUSDT","id":"23632000","side":"Buy","size":62.989998},{"price":"2363.25","symbol":"ETHUSDT","id":"23632500","side":"Buy","size":133.05},{"price":"2363.30","symbol":"ETHUSDT","id":"23633000","side":"Buy","size":96.37},{"price":"2363.35","symbol":"ETHUSDT","id":"23633500","side":"Buy","size":55.629997},{"price":"2363.40","symbol":"ETHUSDT","id":"23634000","side":"Buy","size":28.609999},{"price":"2363.55","symbol":"ETHUSDT","id":"23635500","side":"Buy","size":55.629997},{"price":"2363.60","symbol":"ETHUSDT","id":"23636000","side":"Buy","size":26.24},{"price":"2363.70","symbol":"ETHUSDT","id":"23637000","side":"Buy","size":85.03},{"price":"2363.80","symbol":"ETHUSDT","id":"23638000","side":"Buy","size":122.54},{"price":"2363.90","symbol":"ETHUSDT","id":"23639000","side":"Buy","size":5},{"price":"2364.05","symbol":"ETHUSDT","id":"23640500","side":"Buy","size":59.97},{"price":"2364.10","symbol":"ETHUSDT","id":"23641000","side":"Buy","size":10},{"price":"2364.55","symbol":"ETHUSDT","id":"23645500","side":"Buy","size":1.46},{"price":"2364.90","symbol":"ETHUSDT","id":"23649000","side":"Buy","size":1.96},{"price":"2364.95","symbol":"ETHUSDT","id":"23649500","side":"Sell","size":396.5},{"price":"2365.00","symbol":"ETHUSDT","id":"23650000","side":"Sell","size":129.19},{"price":"2365.05","symbol":"ETHUSDT","id":"23650500","side":"Sell","size":147.8},{"price":"2365.10","symbol":"ETHUSDT","id":"23651000","side":"Sell","size":140.1},{"price":"2365.15","symbol":"ETHUSDT","id":"23651500","side":"Sell","size":105.1},{"price":"2365.20","symbol":"ETHUSDT","id":"23652000","side":"Sell","size":99.35},{"price":"2365.50","symbol":"ETHUSDT","id":"23655000","side":"Sell","size":27.79},{"price":"2365.55","symbol":"ETHUSDT","id":"23655500","side":"Sell","size":144.01001},{"price":"2365.60","symbol":"ETHUSDT","id":"23656000","side":"Sell","size":142.13},{"price":"2365.65","symbol":"ETHUSDT","id":"23656500","side":"Sell","size":188.25002},{"price":"2365.70","symbol":"ETHUSDT","id":"23657000","side":"Sell","size":116.409996},{"price":"2365.75","symbol":"ETHUSDT","id":"23657500","side":"Sell","size":168.91},{"price":"2365.80","symbol":"ETHUSDT","id":"23658000","side":"Sell","size":101.84},{"price":"2365.85","symbol":"ETHUSDT","id":"23658500","side":"Sell","size":5.78},{"price":"2365.90","symbol":"ETHUSDT","id":"23659000","side":"Sell","size":30.68},{"price":"2365.95","symbol":"ETHUSDT","id":"23659500","side":"Sell","size":28.96},{"price":"2366.00","symbol":"ETHUSDT","id":"23660000","side":"Sell","size":49.149998},{"price":"2366.05","symbol":"ETHUSDT","id":"23660500","side":"Sell","size":33.2},{"price":"2366.10","symbol":"ETHUSDT","id":"23661000","side":"Sell","size":67.07},{"price":"2366.15","symbol":"ETHUSDT","id":"23661500","side":"Sell","size":47.71},{"price":"2366.20","symbol":"ETHUSDT","id":"23662000","side":"Sell","size":13.369999},{"price":"2366.25","symbol":"ETHUSDT","id":"23662500","side":"Sell","size":14.31},{"price":"2366.30","symbol":"ETHUSDT","id":"23663000","side":"Sell","size":21.07},{"price":"2366.35","symbol":"ETHUSDT","id":"23663500","side":"Sell","size":36.41},{"price":"2366.40","symbol":"ETHUSDT","id":"23664000","side":"Sell","size":130.84}]},"cross_seq":"1800545967","timestamp_e6":"1618677785509849"}
1618677787.169386: {"topic":"orderBookL2_25.ETHUSDT","type":"delta","data":{"delete":[],"update":[{"price":"2364.90","symbol":"ETHUSDT","id":"23649000","side":"Buy","size":20.41},{"price":"2365.55","symbol":"ETHUSDT","id":"23655500","side":"Sell","size":140.91},{"price":"2363.00","symbol":"ETHUSDT","id":"23630000","side":"Buy","size":58.04}],"insert":[]},"cross_seq":"1800545971","timestamp_e6":"1618677785648989"}
1618677787.1694138: {"topic":"orderBookL2_25.ETHUSDT","type":"delta","data":{"delete":[{"price":"2362.75","symbol":"ETHUSDT","id":"23627500","side":"Buy"},{"price":"2362.80","symbol":"ETHUSDT","id":"23628000","side":"Buy"},{"price":"2363.80","symbol":"ETHUSDT","id":"23638000","side":"Buy"},{"price":"2362.65","symbol":"ETHUSDT","id":"23626500","side":"Buy"},{"price":"2362.70","symbol":"ETHUSDT","id":"23627000","side":"Buy"}],"update":[{"price":"2364.90","symbol":"ETHUSDT","id":"23649000","side":"Buy","size":41.41},{"price":"2363.90","symbol":"ETHUSDT","id":"23639000","side":"Buy","size":85.03}],"insert":[{"price":"2364.00","symbol":"ETHUSDT","id":"23640000","side":"Buy","size":122.54},{"price":"2363.75","symbol":"ETHUSDT","id":"23637500","side":"Buy","size":55.629997},{"price":"2364.40","symbol":"ETHUSDT","id":"23644000","side":"Buy","size":5},{"price":"2363.85","symbol":"ETHUSDT","id":"23638500","side":"Buy","size":38.489998},{"price":"2363.95","symbol":"ETHUSDT","id":"23639500","side":"Buy","size":64.58}]},"cross_seq":"1800545983","timestamp_e6":"1618677785668325"}
1618677787.169479: {"topic":"orderBookL2_25.ETHUSDT","type":"delta","data":{"delete":[{"price":"2363.75","symbol":"ETHUSDT","id":"23637500","side":"Buy"},{"price":"2364.00","symbol":"ETHUSDT","id":"23640000","side":"Buy"},{"price":"2363.85","symbol":"ETHUSDT","id":"23638500","side":"Buy"},{"price":"2363.55","symbol":"ETHUSDT","id":"23635500","side":"Buy"},{"price":"2363.60","symbol":"ETHUSDT","id":"23636000","side":"Buy"},{"price":"2363.35","symbol":"ETHUSDT","id":"23633500","side":"Buy"},{"price":"2363.90","symbol":"ETHUSDT","id":"23639000","side":"Buy"}],"update":[{"price":"2364.10","symbol":"ETHUSDT","id":"23641000","side":"Buy","size":95.03},{"price":"2363.30","symbol":"ETHUSDT","id":"23633000","side":"Buy","size":101.07},{"price":"2363.10","symbol":"ETHUSDT","id":"23631000","side":"Buy","size":52.95},{"price":"2363.40","symbol":"ETHUSDT","id":"23634000","side":"Buy","size":2.37},{"price":"2363.70","symbol":"ETHUSDT","id":"23637000","side":"Buy","size":20.449999},{"price":"2364.05","symbol":"ETHUSDT","id":"23640500","side":"Buy","size":98.46},{"price":"2363.05","symbol":"ETHUSDT","id":"23630500","side":"Buy","size":69.17},{"price":"2363.15","symbol":"ETHUSDT","id":"23631500","side":"Buy","size":42.4},{"price":"2363.20","symbol":"ETHUSDT","id":"23632000","side":"Buy","size":74.53}],"insert":[{"price":"2362.80","symbol":"ETHUSDT","id":"23628000","side":"Buy","size":88.409996},{"price":"2364.15","symbol":"ETHUSDT","id":"23641500","side":"Buy","size":64.58},{"price":"2363.80","symbol":"ETHUSDT","id":"23638000","side":"Buy","size":0.79},{"price":"2363.50","symbol":"ETHUSDT","id":"23635000","side":"Buy","size":57.34},{"price":"2364.20","symbol":"ETHUSDT","id":"23642000","side":"Buy","size":122.54},{"price":"2363.65","symbol":"ETHUSDT","id":"23636500","side":"Buy","size":14.28},{"price":"2363.45","symbol":"ETHUSDT","id":"23634500","side":"Buy","size":3.87}]},"cross_seq":"1800546024","timestamp_e6":"1618677785687106"}
1618677787.169577: {"topic":"orderBookL2_25.ETHUSDT","type":"delta","data":{"delete":[],"update":[{"price":"2364.90","symbol":"ETHUSDT","id":"23649000","side":"Buy","size":73.99}],"insert":[]},"cross_seq":"1800546025","timestamp_e6":"1618677785708475"}
1618677787.1695948: {"topic":"orderBookL2_25.ETHUSDT","type":"delta","data":{"delete":[],"update":[{"price":"2363.00","symbol":"ETHUSDT","id":"23630000","side":"Buy","size":56.95}],"insert":[]},"cross_seq":"1800546039","timestamp_e6":"1618677785748039"}
1618677787.16961: {"topic":"orderBookL2_25.ETHUSDT","type":"delta","data":{"delete":[],"update":[{"price":"2364.90","symbol":"ETHUSDT","id":"23649000","side":"Buy","size":41.41}],"insert":[]},"cross_seq":"1800546040","timestamp_e6":"1618677785808255"}
1618677787.169625: {"topic":"orderBookL2_25.ETHUSDT","type":"delta","data":{"delete":[],"update":[{"price":"2365.75","symbol":"ETHUSDT","id":"23657500","side":"Sell","size":107.24},{"price":"2364.05","symbol":"ETHUSDT","id":"23640500","side":"Buy","size":38.489998}],"insert":[]},"cross_seq":"1800546044","timestamp_e6":"1618677785827107"}
1618677787.169642: {"topic":"orderBookL2_25.ETHUSDT","type":"delta","data":{"delete":[{"price":"2363.10","symbol":"ETHUSDT","id":"23631000","side":"Buy"},{"price":"2363.00","symbol":"ETHUSDT","id":"23630000","side":"Buy"},{"price":"2362.85","symbol":"ETHUSDT","id":"23628500","side":"Buy"},{"price":"2362.90","symbol":"ETHUSDT","id":"23629000","side":"Buy"},{"price":"2363.05","symbol":"ETHUSDT","id":"23630500","side":"Buy"},{"price":"2362.95","symbol":"ETHUSDT","id":"23629500","side":"Buy"},{"price":"2362.80","symbol":"ETHUSDT","id":"23628000","side":"Buy"}],"update":[{"price":"2363.40","symbol":"ETHUSDT","id":"23634000","side":"Buy","size":15.55},{"price":"2363.70","symbol":"ETHUSDT","id":"23637000","side":"Buy","size":36.64}],"insert":[{"price":"2363.35","symbol":"ETHUSDT","id":"23633500","side":"Buy","size":23.73},{"price":"2363.85","symbol":"ETHUSDT","id":"23638500","side":"Buy","size":22.710001},{"price":"2363.75","symbol":"ETHUSDT","id":"23637500","side":"Buy","size":16.25},{"price":"2363.60","symbol":"ETHUSDT","id":"23636000","side":"Buy","size":0.25},{"price":"2364.00","symbol":"ETHUSDT","id":"23640000","side":"Buy","size":26.24},{"price":"2363.90","symbol":"ETHUSDT","id":"23639000","side":"Buy","size":25.580002},{"price":"2363.55","symbol":"ETHUSDT","id":"23635500","side":"Buy","size":2.51}]},"cross_seq":"1800546055","timestamp_e6":"1618677785947175"}
1618677787.1697211: {"topic":"orderBookL2_25.ETHUSDT","type":"delta","data":{"delete":[{"price":"2363.15","symbol":"ETHUSDT","id":"23631500","side":"Buy"}],"update":[{"price":"2366.30","symbol":"ETHUSDT","id":"23663000","side":"Sell","size":82.72}],"insert":[{"price":"2364.45","symbol":"ETHUSDT","id":"23644500","side":"Buy","size":59.94}]},"cross_seq":"1800546057","timestamp_e6":"1618677785967135"}
1618677787.169748: {"topic":"orderBookL2_25.ETHUSDT","type":"delta","data":{"delete":[],"update":[{"price":"2366.15","symbol":"ETHUSDT","id":"23661500","side":"Sell","size":43.28}],"insert":[]},"cross_seq":"1800546059","timestamp_e6":"1618677786048248"}
1618677787.169763: {"topic":"orderBookL2_25.ETHUSDT","type":"delta","data":{"delete":[],"update":[{"price":"2364.90","symbol":"ETHUSDT","id":"23649000","side":"Buy","size":73.99}],"insert":[]},"cross_seq":"1800546060","timestamp_e6":"1618677786068582"}
1618677787.1697779: {"topic":"orderBookL2_25.ETHUSDT","type":"delta","data":{"delete":[{"price":"2364.45","symbol":"ETHUSDT","id":"23644500","side":"Buy"}],"update":[{"price":"2365.70","symbol":"ETHUSDT","id":"23657000","side":"Sell","size":17.529999},{"price":"2366.30","symbol":"ETHUSDT","id":"23663000","side":"Sell","size":21.07},{"price":"2365.60","symbol":"ETHUSDT","id":"23656000","side":"Sell","size":53.4},{"price":"2365.80","symbol":"ETHUSDT","id":"23658000","side":"Sell","size":41.47},{"price":"2363.25","symbol":"ETHUSDT","id":"23632500","side":"Buy","size":88.05},{"price":"2365.75","symbol":"ETHUSDT","id":"23657500","side":"Sell","size":5.38},{"price":"2365.55","symbol":"ETHUSDT","id":"23655500","side":"Sell","size":53.62},{"price":"2365.65","symbol":"ETHUSDT","id":"23656500","side":"Sell","size":77.42}],"insert":[{"price":"2363.15","symbol":"ETHUSDT","id":"23631500","side":"Buy","size":42.4}]},"cross_seq":"1800546080","timestamp_e6":"1618677786267441"}
1618677787.169825: {"topic":"orderBookL2_25.ETHUSDT","type":"delta","data":{"delete":[],"update":[{"price":"2364.95","symbol":"ETHUSDT","id":"23649500","side":"Sell","size":363.92}],"insert":[]},"cross_seq":"1800546081","timestamp_e6":"1618677786327454"}
1618677787.1698408: {"topic":"orderBookL2_25.ETHUSDT","type":"delta","data":{"delete":[],"update":[{"price":"2364.95","symbol":"ETHUSDT","id":"23649500","side":"Sell","size":396.5}],"insert":[]},"cross_seq":"1800546082","timestamp_e6":"1618677786347406"}
1618677787.1698549: {"topic":"orderBookL2_25.ETHUSDT","type":"delta","data":{"delete":[{"price":"2366.40","symbol":"ETHUSDT","id":"23664000","side":"Sell"}],"update":[{"price":"2363.40","symbol":"ETHUSDT","id":"23634000","side":"Buy","size":60.18}],"insert":[{"price":"2365.30","symbol":"ETHUSDT","id":"23653000","side":"Sell","size":60.760002}]},"cross_seq":"1800546086","timestamp_e6":"1618677786427427"}
1618677787.169881: {"topic":"orderBookL2_25.ETHUSDT","type":"delta","data":{"delete":[{"price":"2365.00","symbol":"ETHUSDT","id":"23650000","side":"Sell"},{"price":"2365.10","symbol":"ETHUSDT","id":"23651000","side":"Sell"},{"price":"2363.95","symbol":"ETHUSDT","id":"23639500","side":"Buy"},{"price":"2365.15","symbol":"ETHUSDT","id":"23651500","side":"Sell"},{"price":"2364.20","symbol":"ETHUSDT","id":"23642000","side":"Buy"}],"update":[{"price":"2364.10","symbol":"ETHUSDT","id":"23641000","side":"Buy","size":10},{"price":"2365.05","symbol":"ETHUSDT","id":"23650500","side":"Sell","size":38.11},{"price":"2364.95","symbol":"ETHUSDT","id":"23649500","side":"Sell","size":260.48},{"price":"2364.00","symbol":"ETHUSDT","id":"23640000","side":"Buy","size":34.83},{"price":"2365.20","symbol":"ETHUSDT","id":"23652000","side":"Sell","size":2.12}],"insert":[{"price":"2366.45","symbol":"ETHUSDT","id":"23664500","side":"Sell","size":78.01},{"price":"2363.10","symbol":"ETHUSDT","id":"23631000","side":"Buy","size":52.95},{"price":"2366.40","symbol":"ETHUSDT","id":"23664000","side":"Sell","size":130.84},{"price":"2366.50","symbol":"ETHUSDT","id":"23665000","side":"Sell","size":44.809998},{"price":"2363.05","symbol":"ETHUSDT","id":"23630500","side":"Buy","size":62.360004}]},"cross_seq":"1800546099","timestamp_e6":"1618677786468028"}
1618677787.169951: {"topic":"orderBookL2_25.ETHUSDT","type":"delta","data":{"delete":[],"update":[{"price":"2363.25","symbol":"ETHUSDT","id":"23632500","side":"Buy","size":118.340004},{"price":"2365.70","symbol":"ETHUSDT","id":"23657000","side":"Sell","size":62.82},{"price":"2365.75","symbol":"ETHUSDT","id":"23657500","side":"Sell","size":28.09},{"price":"2365.65","symbol":"ETHUSDT","id":"23656500","side":"Sell","size":136.06},{"price":"2365.55","symbol":"ETHUSDT","id":"23655500","side":"Sell","size":81.86},{"price":"2365.60","symbol":"ETHUSDT","id":"23656000","side":"Sell","size":106.6}],"insert":[]},"cross_seq":"1800546107","timestamp_e6":"1618677786527074"}
1618677787.169982: {"topic":"orderBookL2_25.ETHUSDT","type":"delta","data":{"delete":[{"price":"2363.05","symbol":"ETHUSDT","id":"23630500","side":"Buy"}],"update":[{"price":"2364.10","symbol":"ETHUSDT","id":"23641000","side":"Buy","size":5}],"insert":[{"price":"2364.60","symbol":"ETHUSDT","id":"23646000","side":"Buy","size":5}]},"cross_seq":"1800546108","timestamp_e6":"1618677786547128"}
1618677787.1700082: {"topic":"orderBookL2_25.ETHUSDT","type":"delta","data":{"delete":[{"price":"2364.10","symbol":"ETHUSDT","id":"23641000","side":"Buy"}],"update":[{"price":"2364.60","symbol":"ETHUSDT","id":"23646000","side":"Buy","size":10}],"insert":[{"price":"2363.05","symbol":"ETHUSDT","id":"23630500","side":"Buy","size":62.360004}]},"cross_seq":"1800546109","timestamp_e6":"1618677786567499"}
1618677787.170032: {"topic":"orderBookL2_25.ETHUSDT","type":"delta","data":{"delete":[{"price":"2366.45","symbol":"ETHUSDT","id":"23664500","side":"Sell"},{"price":"2364.15","symbol":"ETHUSDT","id":"23641500","side":"Buy"},{"price":"2366.50","symbol":"ETHUSDT","id":"23665000","side":"Sell"},{"price":"2366.40","symbol":"ETHUSDT","id":"23664000","side":"Sell"},{"price":"2363.05","symbol":"ETHUSDT","id":"23630500","side":"Buy"},{"price":"2363.10","symbol":"ETHUSDT","id":"23631000","side":"Buy"}],"update":[{"price":"2365.20","symbol":"ETHUSDT","id":"23652000","side":"Sell","size":31.11},{"price":"2364.00","symbol":"ETHUSDT","id":"23640000","side":"Buy","size":8.59},{"price":"2364.95","symbol":"ETHUSDT","id":"23649500","side":"Sell","size":301.84}],"insert":[{"price":"2364.10","symbol":"ETHUSDT","id":"23641000","side":"Buy","size":34.649998},{"price":"2365.00","symbol":"ETHUSDT","id":"23650000","side":"Sell","size":50.91},{"price":"2365.15","symbol":"ETHUSDT","id":"23651500","side":"Sell","size":27.180002},{"price":"2365.10","symbol":"ETHUSDT","id":"23651000","side":"Sell","size":32.04},{"price":"2364.20","symbol":"ETHUSDT","id":"23642000","side":"Buy","size":59.93},{"price":"2364.25","symbol":"ETHUSDT","id":"23642500","side":"Buy","size":79.84}]},"cross_seq":"1800546121","timestamp_e6":"1618677786587438"}
1618677787.170107: {"success":true,"ret_msg":"","conn_id":"38cf0ac3-af67-483c-9bbc-b57d45910ecb","request":{"op":"subscribe","args":["orderBookL2_25.ETHUSDT"]}}
1618677787.1701162: {"topic":"orderBookL2_25.BCHUSDT","type":"delta","data":{"delete":[{"price":"1054.30","symbol":"BCHUSDT","id":"10543000","side":"Buy"}],"update":[],"insert":[{"price":"1052.85","symbol":"BCHUSDT","id":"10528500","side":"Buy","size":3.46}]},"cross_seq":"864131831","timestamp_e6":"1618677786610016"}
1618677787.170141: {"topic":"orderBookL2_25.DOTUSDT","type":"delta","data":{"delete":[{"price":"43.645","symbol":"DOTUSDT","id":"436450","side":"Sell"}],"update":[{"price":"43.465","symbol":"DOTUSDT","id":"434650","side":"Buy","size":119.399994},{"price":"43.510","symbol":"DOTUSDT","id":"435100","side":"Sell","size":409.30002},{"price":"43.475","symbol":"DOTUSDT","id":"434750","side":"Buy","size":240.4},{"price":"43.455","symbol":"DOTUSDT","id":"434550","side":"Buy","size":151},{"price":"43.485","symbol":"DOTUSDT","id":"434850","side":"Buy","size":324.5},{"price":"43.490","symbol":"DOTUSDT","id":"434900","side":"Buy","size":388.4},{"price":"43.480","symbol":"DOTUSDT","id":"434800","side":"Buy","size":107.1},{"price":"43.505","symbol":"DOTUSDT","id":"435050","side":"Sell","size":389.99997}],"insert":[{"price":"43.535","symbol":"DOTUSDT","id":"435350","side":"Sell","size":117.2}]},"cross_seq":"916952477","timestamp_e6":"1618677786622463"}
1618677787.170191: {"topic":"orderBookL2_25.ADAUSDT","type":"delta","data":{"delete":[{"price":"1.3874","symbol":"ADAUSDT","id":"13874","side":"Buy"}],"update":[{"price":"1.3877","symbol":"ADAUSDT","id":"13877","side":"Buy","size":33615},{"price":"1.3871","symbol":"ADAUSDT","id":"13871","side":"Buy","size":23109}],"insert":[{"price":"1.3846","symbol":"ADAUSDT","id":"13846","side":"Buy","size":1015}]},"cross_seq":"916952477","timestamp_e6":"1618677786622330"}
1618677787.1702201: {"topic":"orderBookL2_25.LINKUSDT","type":"delta","data":{"delete":[{"price":"41.061","symbol":"LINKUSDT","id":"410610","side":"Sell"},{"price":"41.043","symbol":"LINKUSDT","id":"410430","side":"Buy"},{"price":"41.060","symbol":"LINKUSDT","id":"410600","side":"Sell"},{"price":"41.063","symbol":"LINKUSDT","id":"410630","side":"Sell"},{"price":"41.059","symbol":"LINKUSDT","id":"410590","side":"Sell"},{"price":"41.052","symbol":"LINKUSDT","id":"410520","side":"Sell"},{"price":"41.062","symbol":"LINKUSDT","id":"410620","side":"Sell"}],"update":[{"price":"41.025","symbol":"LINKUSDT","id":"410250","side":"Buy","size":338.40002},{"price":"41.048","symbol":"LINKUSDT","id":"410480","side":"Buy","size":115.6},{"price":"41.065","symbol":"LINKUSDT","id":"410650","side":"Sell","size":142.5}],"insert":[{"price":"41.084","symbol":"LINKUSDT","id":"410840","side":"Sell","size":64.2},{"price":"41.085","symbol":"LINKUSDT","id":"410850","side":"Sell","size":123.5},{"price":"41.088","symbol":"LINKUSDT","id":"410880","side":"Sell","size":72.4},{"price":"41.086","symbol":"LINKUSDT","id":"410860","side":"Sell","size":70.1},{"price":"41.056","symbol":"LINKUSDT","id":"410560","side":"Sell","size":1.2},{"price":"41.045","symbol":"LINKUSDT","id":"410450","side":"Buy","size":0.9},{"price":"41.087","symbol":"LINKUSDT","id":"410870","side":"Sell","size":2.5}]},"cross_seq":"1970978448","timestamp_e6":"1618677786624197"}
1618677787.1703029: {"topic":"orderBookL2_25.BCHUSDT","type":"delta","data":{"delete":[{"price":"1054.60","symbol":"BCHUSDT","id":"10546000","side":"Sell"},{"price":"1054.10","symbol":"BCHUSDT","id":"10541000","side":"Buy"}],"update":[{"price":"1055.00","symbol":"BCHUSDT","id":"10550000","side":"Sell","size":6.28},{"price":"1054.75","symbol":"BCHUSDT","id":"10547500","side":"Sell","size":3.71},{"price":"1054.70","symbol":"BCHUSDT","id":"10547000","side":"Sell","size":5}],"insert":[{"price":"1053.90","symbol":"BCHUSDT","id":"10539000","side":"Buy","size":6.22},{"price":"1055.80","symbol":"BCHUSDT","id":"10558000","side":"Sell","size":5.83}]},"cross_seq":"864131839","timestamp_e6":"1618677786628998"}
1618677787.170346: {"topic":"orderBookL2_25.LTCUSDT","type":"delta","data":{"delete":[{"price":"312.94","symbol":"LTCUSDT","id":"3129400","side":"Sell"},{"price":"313.10","symbol":"LTCUSDT","id":"3131000","side":"Sell"},{"price":"313.09","symbol":"LTCUSDT","id":"3130900","side":"Sell"},{"price":"312.91","symbol":"LTCUSDT","id":"3129100","side":"Sell"},{"price":"312.76","symbol":"LTCUSDT","id":"3127600","side":"Buy"},{"price":"312.77","symbol":"LTCUSDT","id":"3127700","side":"Buy"},{"price":"312.74","symbol":"LTCUSDT","id":"3127400","side":"Buy"}],"update":[{"price":"312.89","symbol":"LTCUSDT","id":"3128900","side":"Sell","size":1.5},{"price":"312.82","symbol":"LTCUSDT","id":"3128200","side":"Sell","size":267.30002},{"price":"312.96","symbol":"LTCUSDT","id":"3129600","side":"Sell","size":43.800003}],"insert":[{"price":"312.88","symbol":"LTCUSDT","id":"3128800","side":"Sell","size":115.2},{"price":"312.98","symbol":"LTCUSDT","id":"3129800","side":"Sell","size":35.100002},{"price":"312.75","symbol":"LTCUSDT","id":"3127500","side":"Buy","size":68.600006},{"price":"312.78","symbol":"LTCUSDT","id":"3127800","side":"Buy","size":136.90001},{"price":"312.92","symbol":"LTCUSDT","id":"3129200","side":"Sell","size":41},{"price":"312.93","symbol":"LTCUSDT","id":"3129300","side":"Sell","size":39},{"price":"312.79","symbol":"LTCUSDT","id":"3127900","side":"Buy","size":138.1}]},"cross_seq":"1684521623","timestamp_e6":"1618677786639178"}
1618677787.170429: {"topic":"orderBookL2_25.DOTUSDT","type":"delta","data":{"delete":[],"update":[{"price":"43.515","symbol":"DOTUSDT","id":"435150","side":"Sell","size":273.4},{"price":"43.525","symbol":"DOTUSDT","id":"435250","side":"Sell","size":291.7}],"insert":[]},"cross_seq":"916952480","timestamp_e6":"1618677786642439"}
1618677787.17045: {"topic":"orderBookL2_25.ADAUSDT","type":"delta","data":{"delete":[],"update":[{"price":"1.3877","symbol":"ADAUSDT","id":"13877","side":"Buy","size":42990}],"insert":[]},"cross_seq":"916952480","timestamp_e6":"1618677786642334"}
1618677787.170465: {"topic":"orderBookL2_25.LINKUSDT","type":"delta","data":{"delete":[{"price":"41.025","symbol":"LINKUSDT","id":"410250","side":"Buy"}],"update":[],"insert":[{"price":"41.055","symbol":"LINKUSDT","id":"410550","side":"Buy","size":55.000004}]},"cross_seq":"1970978453","timestamp_e6":"1618677786645155"}
1618677787.170487: {"topic":"orderBookL2_25.ETHUSDT","type":"delta","data":{"delete":[{"price":"2364.25","symbol":"ETHUSDT","id":"23642500","side":"Buy"},{"price":"2364.20","symbol":"ETHUSDT","id":"23642000","side":"Buy"},{"price":"2364.10","symbol":"ETHUSDT","id":"23641000","side":"Buy"}],"update":[],"insert":[{"price":"2364.30","symbol":"ETHUSDT","id":"23643000","side":"Buy","size":59.93},{"price":"2364.15","symbol":"ETHUSDT","id":"23641500","side":"Buy","size":34.83},{"price":"2364.35","symbol":"ETHUSDT","id":"23643500","side":"Buy","size":79.84}]},"cross_seq":"1800546129","timestamp_e6":"1618677786647119"}
1618677787.170527: {"topic":"orderBookL2_25.BCHUSDT","type":"delta","data":{"delete":[],"update":[{"price":"1055.10","symbol":"BCHUSDT","id":"10551000","side":"Sell","size":11.129999}],"insert":[]},"cross_seq":"864131851","timestamp_e6":"1618677786650559"}
1618677787.1705432: {"topic":"orderBookL2_25.XTZUSDT","type":"delta","data":{"delete":[{"price":"7.208","symbol":"XTZUSDT","id":"72080","side":"Buy"},{"price":"7.211","symbol":"XTZUSDT","id":"72110","side":"Sell"}],"update":[{"price":"7.212","symbol":"XTZUSDT","id":"72120","side":"Sell","size":1653.1001},{"price":"7.216","symbol":"XTZUSDT","id":"72160","side":"Sell","size":1583.4},{"price":"7.210","symbol":"XTZUSDT","id":"72100","side":"Buy","size":100},{"price":"7.214","symbol":"XTZUSDT","id":"72140","side":"Sell","size":4359.9},{"price":"7.206","symbol":"XTZUSDT","id":"72060","side":"Buy","size":1196.2999},{"price":"7.213","symbol":"XTZUSDT","id":"72130","side":"Sell","size":1331.9},{"price":"7.207","symbol":"XTZUSDT","id":"72070","side":"Buy","size":658.60004}],"insert":[{"price":"7.211","symbol":"XTZUSDT","id":"72110","side":"Buy","size":1314.2999},{"price":"7.236","symbol":"XTZUSDT","id":"72360","side":"Sell","size":458.69998}]},"cross_seq":"726228030","timestamp_e6":"1618677786656008"}
1618677787.170599: {"topic":"orderBookL2_25.DOTUSDT","type":"delta","data":{"delete":[{"price":"43.640","symbol":"DOTUSDT","id":"436400","side":"Sell"}],"update":[{"price":"43.480","symbol":"DOTUSDT","id":"434800","side":"Buy","size":274.30002},{"price":"43.475","symbol":"DOTUSDT","id":"434750","side":"Buy","size":459.6},{"price":"43.530","symbol":"DOTUSDT","id":"435300","side":"Sell","size":518.9},{"price":"43.465","symbol":"DOTUSDT","id":"434650","side":"Buy","size":148.6},{"price":"43.535","symbol":"DOTUSDT","id":"435350","side":"Sell","size":281.7},{"price":"43.520","symbol":"DOTUSDT","id":"435200","side":"Sell","size":172.3}],"insert":[{"price":"43.540","symbol":"DOTUSDT","id":"435400","side":"Sell","size":215.70001}]},"cross_seq":"916952504","timestamp_e6":"1618677786662472"}
1618677787.170641: {"topic":"orderBookL2_25.LINKUSDT","type":"delta","data":{"delete":[],"update":[{"price":"41.051","symbol":"LINKUSDT","id":"410510","side":"Buy","size":1201.4},{"price":"41.056","symbol":"LINKUSDT","id":"410560","side":"Sell","size":67.2},{"price":"41.055","symbol":"LINKUSDT","id":"410550","side":"Buy","size":961}],"insert":[]},"cross_seq":"1970978466","timestamp_e6":"1618677786666493"}
1618677787.1706638: {"topic":"orderBookL2_25.ETHUSDT","type":"delta","data":{"delete":[{"price":"2365.30","symbol":"ETHUSDT","id":"23653000","side":"Sell"}],"update":[{"price":"2364.90","symbol":"ETHUSDT","id":"23649000","side":"Buy","size":106.48},{"price":"2363.40","symbol":"ETHUSDT","id":"23634000","side":"Buy","size":15.55}],"insert":[{"price":"2366.40","symbol":"ETHUSDT","id":"23664000","side":"Sell","size":130.84}]},"cross_seq":"1800546132","timestamp_e6":"1618677786668490"}
1618677787.1706948: {"topic":"orderBookL2_25.XTZUSDT","type":"delta","data":{"delete":[],"update":[{"price":"7.205","symbol":"XTZUSDT","id":"72050","side":"Buy","size":3868.5999}],"insert":[]},"cross_seq":"726228080","timestamp_e6":"1618677786675319"}
1618677787.170712: {"topic":"orderBookL2_25.ADAUSDT","type":"delta","data":{"delete":[{"price":"1.3846","symbol":"ADAUSDT","id":"13846","side":"Buy"},{"price":"1.3847","symbol":"ADAUSDT","id":"13847","side":"Buy"},{"price":"1.3848","symbol":"ADAUSDT","id":"13848","side":"Buy"}],"update":[{"price":"1.3858","symbol":"ADAUSDT","id":"13858","side":"Buy","size":3232},{"price":"1.3857","symbol":"ADAUSDT","id":"13857","side":"Buy","size":5815},{"price":"1.3860","symbol":"ADAUSDT","id":"13860","side":"Buy","size":2528},{"price":"1.3859","symbol":"ADAUSDT","id":"13859","side":"Buy","size":3488},{"price":"1.3864","symbol":"ADAUSDT","id":"13864","side":"Buy","size":1445},{"price":"1.3877","symbol":"ADAUSDT","id":"13877","side":"Buy","size":36876},{"price":"1.3856","symbol":"ADAUSDT","id":"13856","side":"Buy","size":6468},{"price":"1.3863","symbol":"ADAUSDT","id":"13863","side":"Buy","size":2300}],"insert":[{"price":"1.3865","symbol":"ADAUSDT","id":"13865","side":"Buy","size":3044},{"price":"1.3861","symbol":"ADAUSDT","id":"13861","side":"Buy","size":726},{"price":"1.3866","symbol":"ADAUSDT","id":"13866","side":"Buy","size":4489}]},"cross_seq":"916952521","timestamp_e6":"1618677786682530"}
1618677787.170775: {"topic":"orderBookL2_25.DOTUSDT","type":"delta","data":{"delete":[{"price":"43.375","symbol":"DOTUSDT","id":"433750","side":"Buy"}],"update":[{"price":"43.485","symbol":"DOTUSDT","id":"434850","side":"Buy","size":314.5},{"price":"43.525","symbol":"DOTUSDT","id":"435250","side":"Sell","size":281.7},{"price":"43.505","symbol":"DOTUSDT","id":"435050","side":"Sell","size":400}],"insert":[{"price":"43.495","symbol":"DOTUSDT","id":"434950","side":"Buy","size":10}]},"cross_seq":"916952521","timestamp_e6":"1618677786683254"}
1618677787.170808: {"topic":"orderBookL2_25.BCHUSDT","type":"delta","data":{"delete":[{"price":"1053.90","symbol":"BCHUSDT","id":"10539000","side":"Buy"},{"price":"1054.55","symbol":"BCHUSDT","id":"10545500","side":"Sell"},{"price":"1054.65","symbol":"BCHUSDT","id":"10546500","side":"Sell"}],"update":[{"price":"1054.70","symbol":"BCHUSDT","id":"10547000","side":"Sell","size":1.29},{"price":"1054.75","symbol":"BCHUSDT","id":"10547500","side":"Sell","size":1.74},{"price":"1054.50","symbol":"BCHUSDT","id":"10545000","side":"Sell","size":39.78}],"insert":[{"price":"1054.10","symbol":"BCHUSDT","id":"10541000","side":"Buy","size":10.17},{"price":"1055.85","symbol":"BCHUSDT","id":"10558500","side":"Sell","size":15.6},{"price":"1054.60","symbol":"BCHUSDT","id":"10546000","side":"Sell","size":5}]},"cross_seq":"864131859","timestamp_e6":"1618677786690223"}
1618677787.170857: {"topic":"orderBookL2_25.ETHUSDT","type":"delta","data":{"delete":[{"price":"2363.25","symbol":"ETHUSDT","id":"23632500","side":"Buy"},{"price":"2363.20","symbol":"ETHUSDT","id":"23632000","side":"Buy"},{"price":"2363.15","symbol":"ETHUSDT","id":"23631500","side":"Buy"}],"update":[{"price":"2364.90","symbol":"ETHUSDT","id":"23649000","side":"Buy","size":143.98},{"price":"2364.60","symbol":"ETHUSDT","id":"23646000","side":"Buy","size":69.93},{"price":"2364.95","symbol":"ETHUSDT","id":"23649500","side":"Sell","size":269.41998},{"price":"2364.55","symbol":"ETHUSDT","id":"23645500","side":"Buy","size":54.06},{"price":"2364.40","symbol":"ETHUSDT","id":"23644000","side":"Buy","size":17.6}],"insert":[{"price":"2364.50","symbol":"ETHUSDT","id":"23645000","side":"Buy","size":34.649998},{"price":"2364.65","symbol":"ETHUSDT","id":"23646500","side":"Buy","size":79.84},{"price":"2364.45","symbol":"ETHUSDT","id":"23644500","side":"Buy","size":34.83}]},"cross_seq":"1800546151","timestamp_e6":"1618677786688578"}
1618677787.170913: {"topic":"orderBookL2_25.LINKUSDT","type":"delta","data":{"delete":[{"price":"41.028","symbol":"LINKUSDT","id":"410280","side":"Buy"},{"price":"41.088","symbol":"LINKUSDT","id":"410880","side":"Sell"},{"price":"41.027","symbol":"LINKUSDT","id":"410270","side":"Buy"},{"price":"41.026","symbol":"LINKUSDT","id":"410260","side":"Buy"}],"update":[{"price":"41.055","symbol":"LINKUSDT","id":"410550","side":"Buy","size":1420.2001},{"price":"41.051","symbol":"LINKUSDT","id":"410510","side":"Buy","size":227.2},{"price":"41.081","symbol":"LINKUSDT","id":"410810","side":"Sell","size":60.8},{"price":"41.069","symbol":"LINKUSDT","id":"410690","side":"Sell","size":63.800003}],"insert":[{"price":"41.053","symbol":"LINKUSDT","id":"410530","side":"Buy","size":210.59999},{"price":"41.052","symbol":"LINKUSDT","id":"410520","side":"Buy","size":114.200005},{"price":"41.064","symbol":"LINKUSDT","id":"410640","side":"Sell","size":223.4},{"price":"41.054","symbol":"LINKUSDT","id":"410540","side":"Buy","size":198.7}]},"cross_seq":"1970978495","timestamp_e6":"1618677786687405"}
1618677787.170974: {"topic":"orderBookL2_25.XTZUSDT","type":"delta","data":{"delete":[{"price":"7.210","symbol":"XTZUSDT","id":"72100","side":"Buy"}],"update":[{"price":"7.212","symbol":"XTZUSDT","id":"72120","side":"Sell","size":4503.1}],"insert":[{"price":"7.208","symbol":"XTZUSDT","id":"72080","side":"Buy","size":280}]},"cross_seq":"726228084","timestamp_e6":"1618677786695367"}
1618677787.1710012: {"topic":"orderBookL2_25.LTCUSDT","type":"delta","data":{"delete":[{"price":"312.85","symbol":"LTCUSDT","id":"3128500","side":"Sell"},{"price":"312.86","symbol":"LTCUSDT","id":"3128600","side":"Sell"},{"price":"312.78","symbol":"LTCUSDT","id":"3127800","side":"Buy"},{"price":"312.87","symbol":"LTCUSDT","id":"3128700","side":"Sell"},{"price":"312.83","symbol":"LTCUSDT","id":"3128300","side":"Sell"},{"price":"312.75","symbol":"LTCUSDT","id":"3127500","side":"Buy"},{"price":"312.53","symbol":"LTCUSDT","id":"3125300","side":"Buy"}],"update":[{"price":"312.82","symbol":"LTCUSDT","id":"3128200","side":"Sell","size":152.1},{"price":"312.84","symbol":"LTCUSDT","id":"3128400","side":"Sell","size":0.3},{"price":"312.89","symbol":"LTCUSDT","id":"3128900","side":"Sell","size":70.700005}],"insert":[{"price":"313.09","symbol":"LTCUSDT","id":"3130900","side":"Sell","size":288},{"price":"312.91","symbol":"LTCUSDT","id":"3129100","side":"Sell","size":31},{"price":"313.10","symbol":"LTCUSDT","id":"3131000","side":"Sell","size":8.1},{"price":"313.11","symbol":"LTCUSDT","id":"3131100","side":"Sell","size":16.8},{"price":"312.77","symbol":"LTCUSDT","id":"3127700","side":"Buy","size":108.4},{"price":"312.80","symbol":"LTCUSDT","id":"3128000","side":"Buy","size":138.1},{"price":"312.76","symbol":"LTCUSDT","id":"3127600","side":"Buy","size":68.600006}]},"cross_seq":"1684521653","timestamp_e6":"1618677786700453"}
1618677787.171081: {"topic":"orderBookL2_25.DOTUSDT","type":"delta","data":{"delete":[],"update":[{"price":"43.560","symbol":"DOTUSDT","id":"435600","side":"Sell","size":415.5}],"insert":[]},"cross_seq":"916952571","timestamp_e6":"1618677786702561"}
1618677787.171099: {"topic":"orderBookL2_25.ADAUSDT","type":"delta","data":{"delete":[{"price":"1.3866","symbol":"ADAUSDT","id":"13866","side":"Buy"},{"price":"1.3865","symbol":"ADAUSDT","id":"13865","side":"Buy"}],"update":[{"price":"1.3867","symbol":"ADAUSDT","id":"13867","side":"Buy","size":6489},{"price":"1.3862","symbol":"ADAUSDT","id":"13862","side":"Buy","size":2795},{"price":"1.3877","symbol":"ADAUSDT","id":"13877","side":"Buy","size":42990},{"price":"1.3863","symbol":"ADAUSDT","id":"13863","side":"Buy","size":4601}],"insert":[{"price":"1.3848","symbol":"ADAUSDT","id":"13848","side":"Buy","size":3559},{"price":"1.3847","symbol":"ADAUSDT","id":"13847","side":"Buy","size":4462}]},"cross_seq":"916952571","timestamp_e6":"1618677786702400"}
1618677787.1711419: {"topic":"orderBookL2_25.UNIUSDT","type":"delta","data":{"delete":[{"price":"35.385","symbol":"UNIUSDT","id":"353850","side":"Buy"}],"update":[{"price":"35.408","symbol":"UNIUSDT","id":"354080","side":"Sell","size":54.8},{"price":"35.410","symbol":"UNIUSDT","id":"354100","side":"Sell","size":98.4},{"price":"35.386","symbol":"UNIUSDT","id":"353860","side":"Buy","size":24.8},{"price":"35.409","symbol":"UNIUSDT","id":"354090","side":"Sell","size":123.1},{"price":"35.406","symbol":"UNIUSDT","id":"354060","side":"Sell","size":42},{"price":"35.384","symbol":"UNIUSDT","id":"353840","side":"Buy","size":19.5},{"price":"35.411","symbol":"UNIUSDT","id":"354110","side":"Sell","size":96.399994},{"price":"35.407","symbol":"UNIUSDT","id":"354070","side":"Sell","size":100.5},{"price":"35.364","symbol":"UNIUSDT","id":"353640","side":"Buy","size":16.7},{"price":"35.368","symbol":"UNIUSDT","id":"353680","side":"Buy","size":55.2},{"price":"35.366","symbol":"UNIUSDT","id":"353660","side":"Buy","size":258.1},{"price":"35.367","symbol":"UNIUSDT","id":"353670","side":"Buy","size":16.6}],"insert":[{"price":"35.359","symbol":"UNIUSDT","id":"353590","side":"Buy","size":23.3}]},"cross_seq":"916952571","timestamp_e6":"1618677786702695"}
1618677787.171204: {"topic":"orderBookL2_25.LINKUSDT","type":"delta","data":{"delete":[],"update":[{"price":"41.051","symbol":"LINKUSDT","id":"410510","side":"Buy","size":187.2}],"insert":[]},"cross_seq":"1970978497","timestamp_e6":"1618677786703758"}
1618677787.171221: {"topic":"orderBookL2_25.LTCUSDT","type":"delta","data":{"delete":[{"price":"312.84","symbol":"LTCUSDT","id":"3128400","side":"Sell"},{"price":"312.71","symbol":"LTCUSDT","id":"3127100","side":"Buy"}],"update":[{"price":"312.82","symbol":"LTCUSDT","id":"3128200","side":"Sell","size":150},{"price":"312.77","symbol":"LTCUSDT","id":"3127700","side":"Buy","size":109.9},{"price":"312.92","symbol":"LTCUSDT","id":"3129200","side":"Sell","size":41.3},{"price":"312.89","symbol":"LTCUSDT","id":"3128900","side":"Sell","size":72.2}],"insert":[{"price":"313.12","symbol":"LTCUSDT","id":"3131200","side":"Sell","size":6.4},{"price":"312.53","symbol":"LTCUSDT","id":"3125300","side":"Buy","size":210.1}]},"cross_seq":"1684521657","timestamp_e6":"1618677786719065"}
1618677787.171264: {"topic":"orderBookL2_25.DOTUSDT","type":"delta","data":{"delete":[{"price":"43.535","symbol":"DOTUSDT","id":"435350","side":"Sell"},{"price":"43.485","symbol":"DOTUSDT","id":"434850","side":"Buy"}],"update":[{"price":"43.495","symbol":"DOTUSDT","id":"434950","side":"Buy","size":388.4},{"price":"43.530","symbol":"DOTUSDT","id":"435300","side":"Sell","size":401.7},{"price":"43.520","symbol":"DOTUSDT","id":"435200","side":"Sell","size":445.7},{"price":"43.490","symbol":"DOTUSDT","id":"434900","side":"Buy","size":10},{"price":"43.480","symbol":"DOTUSDT","id":"434800","side":"Buy","size":326.3},{"price":"43.505","symbol":"DOTUSDT","id":"435050","side":"Sell","size":389.99997},{"price":"43.525","symbol":"DOTUSDT","id":"435250","side":"Sell","size":291.7},{"price":"43.470","symbol":"DOTUSDT","id":"434700","side":"Buy","size":381.7}],"insert":[{"price":"43.375","symbol":"DOTUSDT","id":"433750","side":"Buy","size":294.69998},{"price":"43.640","symbol":"DOTUSDT","id":"436400","side":"Sell","size":205.7}]},"cross_seq":"916952582","timestamp_e6":"1618677786722450"}
1618677787.171319: {"topic":"orderBookL2_25.ETHUSDT","type":"delta","data":{"delete":[],"update":[{"price":"2364.95","symbol":"ETHUSDT","id":"23649500","side":"Sell","size":224.53}],"insert":[]},"cross_seq":"1800546158","timestamp_e6":"1618677786727441"}
1618677787.171336: {"topic":"orderBookL2_25.BCHUSDT","type":"delta","data":{"delete":[{"price":"1052.85","symbol":"BCHUSDT","id":"10528500","side":"Buy"},{"price":"1054.60","symbol":"BCHUSDT","id":"10546000","side":"Sell"}],"update":[{"price":"1054.70","symbol":"BCHUSDT","id":"10547000","side":"Sell","size":5},{"price":"1054.75","symbol":"BCHUSDT","id":"10547500","side":"Sell","size":3.71}],"insert":[{"price":"1054.65","symbol":"BCHUSDT","id":"10546500","side":"Sell","size":6.12},{"price":"1053.90","symbol":"BCHUSDT","id":"10539000","side":"Buy","size":3.63}]},"cross_seq":"864131877","timestamp_e6":"1618677786728878"}
1618677787.171377: {"topic":"orderBookL2_25.XTZUSDT","type":"delta","data":{"delete":[],"update":[{"price":"7.221","symbol":"XTZUSDT","id":"72210","side":"Sell","size":1898.4}],"insert":[]},"cross_seq":"726228089","timestamp_e6":"1618677786734574"}
1618677787.171394: {"topic":"orderBookL2_25.LTCUSDT","type":"delta","data":{"delete":[{"price":"312.76","symbol":"LTCUSDT","id":"3127600","side":"Buy"},{"price":"312.88","symbol":"LTCUSDT","id":"3128800","side":"Sell"},{"price":"312.82","symbol":"LTCUSDT","id":"3128200","side":"Sell"},{"price":"312.79","symbol":"LTCUSDT","id":"3127900","side":"Buy"},{"price":"312.90","symbol":"LTCUSDT","id":"3129000","side":"Sell"}],"update":[{"price":"312.77","symbol":"LTCUSDT","id":"3127700","side":"Buy","size":1.5},{"price":"312.89","symbol":"LTCUSDT","id":"3128900","side":"Sell","size":70.700005},{"price":"312.91","symbol":"LTCUSDT","id":"3129100","side":"Sell","size":41},{"price":"312.96","symbol":"LTCUSDT","id":"3129600","side":"Sell","size":45.3},{"price":"312.81","symbol":"LTCUSDT","id":"3128100","side":"Buy","size":324.9}],"insert":[{"price":"312.78","symbol":"LTCUSDT","id":"3127800","side":"Buy","size":108.4},{"price":"312.52","symbol":"LTCUSDT","id":"3125200","side":"Buy","size":14.6},{"price":"313.13","symbol":"LTCUSDT","id":"3131300","side":"Sell","size":87},{"price":"312.87","symbol":"LTCUSDT","id":"3128700","side":"Sell","size":115.2},{"price":"313.14","symbol":"LTCUSDT","id":"3131400","side":"Sell","size":28.2}]},"cross_seq":"1684521671","timestamp_e6":"1618677786740184"}
1618677787.171465: {"topic":"orderBookL2_25.DOTUSDT","type":"delta","data":{"delete":[{"price":"43.490","symbol":"DOTUSDT","id":"434900","side":"Buy"}],"update":[{"price":"43.500","symbol":"DOTUSDT","id":"435000","side":"Buy","size":202.1}],"insert":[{"price":"43.370","symbol":"DOTUSDT","id":"433700","side":"Buy","size":309.19998}]},"cross_seq":"916952619","timestamp_e6":"1618677786742256"}
1618677787.1714911: {"topic":"orderBookL2_25.UNIUSDT","type":"delta","data":{"delete":[{"price":"35.359","symbol":"UNIUSDT","id":"353590","side":"Buy"}],"update":[{"price":"35.407","symbol":"UNIUSDT","id":"354070","side":"Sell","size":87.7},{"price":"35.405","symbol":"UNIUSDT","id":"354050","side":"Sell","size":103.1},{"price":"35.406","symbol":"UNIUSDT","id":"354060","side":"Sell","size":89.1}],"insert":[{"price":"35.385","symbol":"UNIUSDT","id":"353850","side":"Buy","size":20.5}]},"cross_seq":"916952619","timestamp_e6":"1618677786742398"}
1618677787.171523: {"topic":"orderBookL2_25.ETHUSDT","type":"delta","data":{"delete":[],"update":[{"price":"2363.40","symbol":"ETHUSDT","id":"23634000","side":"Buy","size":13.18}],"insert":[]},"cross_seq":"1800546160","timestamp_e6":"1618677786747045"}
1618677787.17154: {"topic":"orderBookL2_25.BCHUSDT","type":"delta","data":{"delete":[{"price":"1054.75","symbol":"BCHUSDT","id":"10547500","side":"Sell"},{"price":"1054.95","symbol":"BCHUSDT","id":"10549500","side":"Sell"}],"update":[{"price":"1054.85","symbol":"BCHUSDT","id":"10548500","side":"Sell","size":5},{"price":"1054.80","symbol":"BCHUSDT","id":"10548000","side":"Sell","size":6.12},{"price":"1054.50","symbol":"BCHUSDT","id":"10545000","side":"Sell","size":30}],"insert":[{"price":"1054.90","symbol":"BCHUSDT","id":"10549000","side":"Sell","size":3.71},{"price":"1055.90","symbol":"BCHUSDT","id":"10559000","side":"Sell","size":2.79}]},"cross_seq":"864131890","timestamp_e6":"1618677786749910"}
1618677787.1715782: {"topic":"orderBookL2_25.LTCUSDT","type":"delta","data":{"delete":[],"update":[{"price":"312.81","symbol":"LTCUSDT","id":"3128100","side":"Buy","size":174.9},{"price":"312.73","symbol":"LTCUSDT","id":"3127300","side":"Buy","size":60.300003},{"price":"312.80","symbol":"LTCUSDT","id":"3128000","side":"Buy","size":139.09999}],"insert":[]},"cross_seq":"1684521692","timestamp_e6":"1618677786759131"}
1618677787.1715999: {"topic":"orderBookL2_25.DOTUSDT","type":"delta","data":{"delete":[{"price":"43.505","symbol":"DOTUSDT","id":"435050","side":"Sell"},{"price":"43.370","symbol":"DOTUSDT","id":"433700","side":"Buy"},{"price":"43.375","symbol":"DOTUSDT","id":"433750","side":"Buy"}],"update":[{"price":"43.510","symbol":"DOTUSDT","id":"435100","side":"Sell","size":419.3},{"price":"43.530","symbol":"DOTUSDT","id":"435300","side":"Sell","size":518.9},{"price":"43.520","symbol":"DOTUSDT","id":"435200","side":"Sell","size":172.3},{"price":"43.525","symbol":"DOTUSDT","id":"435250","side":"Sell","size":281.7}],"insert":[{"price":"43.535","symbol":"DOTUSDT","id":"435350","side":"Sell","size":281.7},{"price":"43.485","symbol":"DOTUSDT","id":"434850","side":"Buy","size":167.2},{"price":"43.490","symbol":"DOTUSDT","id":"434900","side":"Buy","size":314.5}]},"cross_seq":"916952650","timestamp_e6":"1618677786764270"}
1618677787.171652: {"topic":"orderBookL2_25.ETHUSDT","type":"delta","data":{"delete":[{"price":"2366.40","symbol":"ETHUSDT","id":"23664000","side":"Sell"}],"update":[{"price":"2364.95","symbol":"ETHUSDT","id":"23649500","side":"Sell","size":129.58},{"price":"2364.90","symbol":"ETHUSDT","id":"23649000","side":"Buy","size":151.98}],"insert":[{"price":"2365.45","symbol":"ETHUSDT","id":"23654500","side":"Sell","size":4.95}]},"cross_seq":"1800546163","timestamp_e6":"1618677786769155"}
1618677787.171681: {"topic":"orderBookL2_25.LTCUSDT","type":"delta","data":{"delete":[{"price":"312.53","symbol":"LTCUSDT","id":"3125300","side":"Buy"},{"price":"312.52","symbol":"LTCUSDT","id":"3125200","side":"Buy"},{"price":"312.78","symbol":"LTCUSDT","id":"3127800","side":"Buy"},{"price":"312.56","symbol":"LTCUSDT","id":"3125600","side":"Buy"},{"price":"312.55","symbol":"LTCUSDT","id":"3125500","side":"Buy"},{"price":"312.99","symbol":"LTCUSDT","id":"3129900","side":"Sell"},{"price":"312.57","symbol":"LTCUSDT","id":"3125700","side":"Buy"},{"price":"312.54","symbol":"LTCUSDT","id":"3125400","side":"Buy"}],"update":[{"price":"313.01","symbol":"LTCUSDT","id":"3130100","side":"Sell","size":44.4},{"price":"312.70","symbol":"LTCUSDT","id":"3127000","side":"Buy","size":228.7},{"price":"313.00","symbol":"LTCUSDT","id":"3130000","side":"Sell","size":41},{"price":"312.77","symbol":"LTCUSDT","id":"3127700","side":"Buy","size":51.000004},{"price":"312.97","symbol":"LTCUSDT","id":"3129700","side":"Sell","size":78},{"price":"312.81","symbol":"LTCUSDT","id":"3128100","side":"Buy","size":158.7},{"price":"312.73","symbol":"LTCUSDT","id":"3127300","side":"Buy","size":1.5},{"price":"312.98","symbol":"LTCUSDT","id":"3129800","side":"Sell","size":70.8},{"price":"312.87","symbol":"LTCUSDT","id":"3128700","side":"Sell","size":115.8},{"price":"312.96","symbol":"LTCUSDT","id":"3129600","side":"Sell","size":160.5},{"price":"312.72","symbol":"LTCUSDT","id":"3127200","side":"Buy","size":123.1},{"price":"312.67","symbol":"LTCUSDT","id":"3126700","side":"Buy","size":136.3},{"price":"312.80","symbol":"LTCUSDT","id":"3128000","side":"Buy","size":1}],"insert":[{"price":"312.86","symbol":"LTCUSDT","id":"3128600","side":"Buy","size":16.2},{"price":"312.71","symbol":"LTCUSDT","id":"3127100","side":"Buy","size":45.6},{"price":"312.82","symbol":"LTCUSDT","id":"3128200","side":"Buy","size":138.1},{"price":"312.75","symbol":"LTCUSDT","id":"3127500","side":"Buy","size":17.4},{"price":"313.15","symbol":"LTCUSDT","id":"3131500","side":"Sell","size":71.9},{"price":"312.76","symbol":"LTCUSDT","id":"3127600","side":"Buy","size":76.600006},{"price":"312.74","symbol":"LTCUSDT","id":"3127400","side":"Buy","size":8.5},{"price":"312.79","symbol":"LTCUSDT","id":"3127900","side":"Buy","size":108.4}]},"cross_seq":"1684521724","timestamp_e6":"1618677786780338"}
1618677787.171797: {"topic":"orderBookL2_25.DOTUSDT","type":"delta","data":{"delete":[],"update":[{"price":"43.510","symbol":"DOTUSDT","id":"435100","side":"Sell","size":409.30002},{"price":"43.520","symbol":"DOTUSDT","id":"435200","side":"Sell","size":182.3}],"insert":[]},"cross_seq":"916952654","timestamp_e6":"1618677786782340"}
1618677787.171818: {"topic":"orderBookL2_25.UNIUSDT","type":"delta","data":{"delete":[],"update":[{"price":"35.407","symbol":"UNIUSDT","id":"354070","side":"Sell","size":100.5},{"price":"35.406","symbol":"UNIUSDT","id":"354060","side":"Sell","size":69.299995}],"insert":[]},"cross_seq":"916952654","timestamp_e6":"1618677786782548"}
1618677787.1718369: {"topic":"orderBookL2_25.BCHUSDT","type":"delta","data":{"delete":[{"price":"1054.65","symbol":"BCHUSDT","id":"10546500","side":"Sell"},{"price":"1055.90","symbol":"BCHUSDT","id":"10559000","side":"Sell"},{"price":"1054.70","symbol":"BCHUSDT","id":"10547000","side":"Sell"}],"update":[{"price":"1054.50","symbol":"BCHUSDT","id":"10545000","side":"Sell","size":39.78}],"insert":[{"price":"1054.55","symbol":"BCHUSDT","id":"10545500","side":"Sell","size":6.12},{"price":"1054.75","symbol":"BCHUSDT","id":"10547500","side":"Sell","size":1.64},{"price":"1054.60","symbol":"BCHUSDT","id":"10546000","side":"Sell","size":5}]},"cross_seq":"864131898","timestamp_e6":"1618677786790011"}
1618677787.1718788: {"topic":"orderBookL2_25.LTCUSDT","type":"delta","data":{"delete":[{"price":"312.91","symbol":"LTCUSDT","id":"3129100","side":"Sell"},{"price":"312.58","symbol":"LTCUSDT","id":"3125800","side":"Buy"},{"price":"312.97","symbol":"LTCUSDT","id":"3129700","side":"Sell"},{"price":"312.93","symbol":"LTCUSDT","id":"3129300","side":"Sell"},{"price":"312.87","symbol":"LTCUSDT","id":"3128700","side":"Sell"},{"price":"312.89","symbol":"LTCUSDT","id":"3128900","side":"Sell"}],"update":[{"price":"312.95","symbol":"LTCUSDT","id":"3129500","side":"Sell","size":1.5},{"price":"312.92","symbol":"LTCUSDT","id":"3129200","side":"Sell","size":0.3},{"price":"313.00","symbol":"LTCUSDT","id":"3130000","side":"Sell","size":26.6},{"price":"312.80","symbol":"LTCUSDT","id":"3128000","side":"Buy","size":108.4}],"insert":[{"price":"312.78","symbol":"LTCUSDT","id":"3127800","side":"Buy","size":68.600006},{"price":"312.99","symbol":"LTCUSDT","id":"3129900","side":"Sell","size":70.8},{"price":"313.17","symbol":"LTCUSDT","id":"3131700","side":"Sell","size":91.6},{"price":"313.16","symbol":"LTCUSDT","id":"3131600","side":"Sell","size":109.299995},{"price":"313.18","symbol":"LTCUSDT","id":"3131800","side":"Sell","size":51.6},{"price":"313.19","symbol":"LTCUSDT","id":"3131900","side":"Sell","size":35.3}]},"cross_seq":"1684521758","timestamp_e6":"1618677786799329"}
1618677787.171954: {"topic":"orderBookL2_25.LINKUSDT","type":"delta","data":{"delete":[],"update":[{"price":"41.042","symbol":"LINKUSDT","id":"410420","side":"Buy","size":308.8},{"price":"41.040","symbol":"LINKUSDT","id":"410400","side":"Buy","size":199.5},{"price":"41.037","symbol":"LINKUSDT","id":"410370","side":"Buy","size":318.1}],"insert":[]},"cross_seq":"1970978504","timestamp_e6":"1618677786803839"}
1618677787.171977: {"topic":"orderBookL2_25.DOTUSDT","type":"delta","data":{"delete":[{"price":"43.380","symbol":"DOTUSDT","id":"433800","side":"Buy"}],"update":[{"price":"43.495","symbol":"DOTUSDT","id":"434950","side":"Buy","size":378.4},{"price":"43.500","symbol":"DOTUSDT","id":"435000","side":"Buy","size":10.1}],"insert":[{"price":"43.505","symbol":"DOTUSDT","id":"435050","side":"Buy","size":302}]},"cross_seq":"916952672","timestamp_e6":"1618677786803503"}
1618677787.1720068: {"topic":"orderBookL2_25.ETHUSDT","type":"delta","data":{"delete":[{"price":"2364.65","symbol":"ETHUSDT","id":"23646500","side":"Buy"},{"price":"2363.30","symbol":"ETHUSDT","id":"23633000","side":"Buy"},{"price":"2363.35","symbol":"ETHUSDT","id":"23633500","side":"Buy"}],"update":[{"price":"2364.90","symbol":"ETHUSDT","id":"23649000","side":"Buy","size":156.98},{"price":"2364.55","symbol":"ETHUSDT","id":"23645500","side":"Buy","size":1.46},{"price":"2364.60","symbol":"ETHUSDT","id":"23646000","side":"Buy","size":5}],"insert":[{"price":"2364.70","symbol":"ETHUSDT","id":"23647000","side":"Buy","size":52.600002},{"price":"2364.75","symbol":"ETHUSDT","id":"23647500","side":"Buy","size":59.93},{"price":"2364.80","symbol":"ETHUSDT","id":"23648000","side":"Buy","size":79.84}]},"cross_seq":"1800546174","timestamp_e6":"1618677786808229"}
1618677787.1720572: {"topic":"orderBookL2_25.LTCUSDT","type":"delta","data":{"delete":[{"price":"313.19","symbol":"LTCUSDT","id":"3131900","side":"Sell"}],"update":[],"insert":[{"price":"312.87","symbol":"LTCUSDT","id":"3128700","side":"Sell","size":0.6}]},"cross_seq":"1684521761","timestamp_e6":"1618677786819997"}
1618677787.172081: {"topic":"orderBookL2_25.ADAUSDT","type":"delta","data":{"delete":[{"price":"1.3862","symbol":"ADAUSDT","id":"13862","side":"Buy"}],"update":[{"price":"1.3885","symbol":"ADAUSDT","id":"13885","side":"Sell","size":852.00006},{"price":"1.3857","symbol":"ADAUSDT","id":"13857","side":"Buy","size":6467},{"price":"1.3858","symbol":"ADAUSDT","id":"13858","side":"Buy","size":3864},{"price":"1.3884","symbol":"ADAUSDT","id":"13884","side":"Sell","size":2805},{"price":"1.3860","symbol":"ADAUSDT","id":"13860","side":"Buy","size":3312},{"price":"1.3886","symbol":"ADAUSDT","id":"13886","side":"Sell","size":1},{"price":"1.3859","symbol":"ADAUSDT","id":"13859","side":"Buy","size":4085.9998},{"price":"1.3856","symbol":"ADAUSDT","id":"13856","side":"Buy","size":7804},{"price":"1.3861","symbol":"ADAUSDT","id":"13861","side":"Buy","size":4353},{"price":"1.3877","symbol":"ADAUSDT","id":"13877","side":"Buy","size":36876}],"insert":[{"price":"1.3846","symbol":"ADAUSDT","id":"13846","side":"Buy","size":1015}]},"cross_seq":"916952704","timestamp_e6":"1618677786822333"}
1618677787.1721332: {"topic":"orderBookL2_25.DOTUSDT","type":"delta","data":{"delete":[{"price":"43.510","symbol":"DOTUSDT","id":"435100","side":"Sell"},{"price":"43.515","symbol":"DOTUSDT","id":"435150","side":"Sell"}],"update":[{"price":"43.540","symbol":"DOTUSDT","id":"435400","side":"Sell","size":281.7},{"price":"43.525","symbol":"DOTUSDT","id":"435250","side":"Sell","size":127.600006},{"price":"43.480","symbol":"DOTUSDT","id":"434800","side":"Buy","size":325.19998}],"insert":[{"price":"43.545","symbol":"DOTUSDT","id":"435450","side":"Sell","size":215.70001},{"price":"43.645","symbol":"DOTUSDT","id":"436450","side":"Sell","size":289.4}]},"cross_seq":"916952704","timestamp_e6":"1618677786823713"}
1618677787.1721768: {"topic":"orderBookL2_25.UNIUSDT","type":"delta","data":{"delete":[],"update":[{"price":"35.406","symbol":"UNIUSDT","id":"354060","side":"Sell","size":101.4},{"price":"35.402","symbol":"UNIUSDT","id":"354020","side":"Sell","size":64.1},{"price":"35.407","symbol":"UNIUSDT","id":"354070","side":"Sell","size":70.3}],"insert":[]},"cross_seq":"916952704","timestamp_e6":"1618677786823831"}
1618677787.172199: {"topic":"orderBookL2_25.BCHUSDT","type":"delta","data":{"delete":[{"price":"1054.00","symbol":"BCHUSDT","id":"10540000","side":"Buy"},{"price":"1054.90","symbol":"BCHUSDT","id":"10549000","side":"Sell"}],"update":[{"price":"1054.80","symbol":"BCHUSDT","id":"10548000","side":"Sell","size":4.48},{"price":"1054.05","symbol":"BCHUSDT","id":"10540500","side":"Buy","size":35.8},{"price":"1054.85","symbol":"BCHUSDT","id":"10548500","side":"Sell","size":3.36},{"price":"1053.95","symbol":"BCHUSDT","id":"10539500","side":"Buy","size":2.71},{"price":"1054.75","symbol":"BCHUSDT","id":"10547500","side":"Sell","size":6.12}],"insert":[{"price":"1054.20","symbol":"BCHUSDT","id":"10542000","side":"Buy","size":10.969999},{"price":"1054.70","symbol":"BCHUSDT","id":"10547000","side":"Sell","size":9.78}]},"cross_seq":"864131920","timestamp_e6":"1618677786829892"}
1618677787.172246: {"topic":"orderBookL2_25.XTZUSDT","type":"delta","data":{"delete":[],"update":[{"price":"7.205","symbol":"XTZUSDT","id":"72050","side":"Buy","size":2597.5999}],"insert":[]},"cross_seq":"726228090","timestamp_e6":"1618677786834603"}
1618677787.172263: {"topic":"orderBookL2_25.LTCUSDT","type":"delta","data":{"delete":[{"price":"312.79","symbol":"LTCUSDT","id":"3127900","side":"Buy"},{"price":"313.15","symbol":"LTCUSDT","id":"3131500","side":"Sell"},{"price":"312.86","symbol":"LTCUSDT","id":"3128600","side":"Buy"},{"price":"312.82","symbol":"LTCUSDT","id":"3128200","side":"Buy"},{"price":"313.17","symbol":"LTCUSDT","id":"3131700","side":"Sell"},{"price":"313.18","symbol":"LTCUSDT","id":"3131800","side":"Sell"},{"price":"313.16","symbol":"LTCUSDT","id":"3131600","side":"Sell"}],"update":[{"price":"312.87","symbol":"LTCUSDT","id":"3128700","side":"Sell","size":250.59999},{"price":"312.92","symbol":"LTCUSDT","id":"3129200","side":"Sell","size":71.1},{"price":"312.81","symbol":"LTCUSDT","id":"3128100","side":"Buy","size":20.6},{"price":"313.09","symbol":"LTCUSDT","id":"3130900","side":"Sell","size":238},{"price":"312.80","symbol":"LTCUSDT","id":"3128000","side":"Buy","size":1},{"price":"312.95","symbol":"LTCUSDT","id":"3129500","side":"Sell","size":40.5}],"insert":[{"price":"312.90","symbol":"LTCUSDT","id":"3129000","side":"Sell","size":115.2},{"price":"312.91","symbol":"LTCUSDT","id":"3129100","side":"Sell","size":69.2},{"price":"312.83","symbol":"LTCUSDT","id":"3128300","side":"Buy","size":136.90001},{"price":"312.58","symbol":"LTCUSDT","id":"3125800","side":"Buy","size":27.1},{"price":"312.94","symbol":"LTCUSDT","id":"3129400","side":"Sell","size":41},{"price":"312.84","symbol":"LTCUSDT","id":"3128400","side":"Buy","size":138.1},{"price":"312.93","symbol":"LTCUSDT","id":"3129300","side":"Sell","size":31}]},"cross_seq":"1684521785","timestamp_e6":"1618677786840437"}
1618677787.17235: {"topic":"orderBookL2_25.DOTUSDT","type":"delta","data":{"delete":[],"update":[{"price":"43.500","symbol":"DOTUSDT","id":"435000","side":"Buy","size":0.1},{"price":"43.505","symbol":"DOTUSDT","id":"435050","side":"Buy","size":312}],"insert":[]},"cross_seq":"916952713","timestamp_e6":"1618677786842672"}
1618677787.172371: {"topic":"orderBookL2_25.UNIUSDT","type":"delta","data":{"delete":[],"update":[{"price":"35.406","symbol":"UNIUSDT","id":"354060","side":"Sell","size":74.1},{"price":"35.407","symbol":"UNIUSDT","id":"354070","side":"Sell","size":87.1},{"price":"35.402","symbol":"UNIUSDT","id":"354020","side":"Sell","size":138.5}],"insert":[]},"cross_seq":"916952713","timestamp_e6":"1618677786842782"}
1618677787.172392: {"topic":"orderBookL2_25.ADAUSDT","type":"delta","data":{"delete":[{"price":"1.3846","symbol":"ADAUSDT","id":"13846","side":"Buy"}],"update":[{"price":"1.3861","symbol":"ADAUSDT","id":"13861","side":"Buy","size":5928},{"price":"1.3864","symbol":"ADAUSDT","id":"13864","side":"Buy","size":3044}],"insert":[{"price":"1.3862","symbol":"ADAUSDT","id":"13862","side":"Buy","size":1508.0001}]},"cross_seq":"916952713","timestamp_e6":"1618677786842507"}
1618677787.1724212: {"topic":"orderBookL2_25.ETHUSDT","type":"delta","data":{"delete":[{"price":"2364.60","symbol":"ETHUSDT","id":"23646000","side":"Buy"}],"update":[{"price":"2364.90","symbol":"ETHUSDT","id":"23649000","side":"Buy","size":161.98}],"insert":[{"price":"2363.35","symbol":"ETHUSDT","id":"23633500","side":"Buy","size":23.73}]},"cross_seq":"1800546178","timestamp_e6":"1618677786848278"}
1618677787.172446: {"topic":"orderBookL2_25.BCHUSDT","type":"delta","data":{"delete":[],"update":[{"price":"1054.50","symbol":"BCHUSDT","id":"10545000","side":"Sell","size":9.78}],"insert":[]},"cross_seq":"864131921","timestamp_e6":"1618677786850164"}
1618677787.172461: {"topic":"orderBookL2_25.LTCUSDT","type":"delta","data":{"delete":[{"price":"312.58","symbol":"LTCUSDT","id":"3125800","side":"Buy"}],"update":[{"price":"313.09","symbol":"LTCUSDT","id":"3130900","side":"Sell","size":186.99998}],"insert":[{"price":"312.86","symbol":"LTCUSDT","id":"3128600","side":"Buy","size":16.2}]},"cross_seq":"1684521809","timestamp_e6":"1618677786859451"}
1618677787.172485: {"topic":"orderBookL2_25.DOTUSDT","type":"delta","data":{"delete":[{"price":"43.385","symbol":"DOTUSDT","id":"433850","side":"Buy"}],"update":[{"price":"43.505","symbol":"DOTUSDT","id":"435050","side":"Buy","size":120}],"insert":[{"price":"43.515","symbol":"DOTUSDT","id":"435150","side":"Buy","size":192}]},"cross_seq":"916952717","timestamp_e6":"1618677786863552"}
1618677787.17251: {"topic":"orderBookL2_25.ETHUSDT","type":"delta","data":{"delete":[],"update":[{"price":"2364.75","symbol":"ETHUSDT","id":"23647500","side":"Buy","size":104.51}],"insert":[]},"cross_seq":"1800546180","timestamp_e6":"1618677786867592"}
1618677787.1725252: {"topic":"orderBookL2_25.DOTUSDT","type":"delta","data":{"delete":[],"update":[{"price":"43.585","symbol":"DOTUSDT","id":"435850","side":"Sell","size":494.5},{"price":"43.460","symbol":"DOTUSDT","id":"434600","side":"Buy","size":386.5},{"price":"43.455","symbol":"DOTUSDT","id":"434550","side":"Buy","size":189.3},{"price":"43.520","symbol":"DOTUSDT","id":"435200","side":"Sell","size":10},{"price":"43.480","symbol":"DOTUSDT","id":"434800","side":"Buy","size":587},{"price":"43.465","symbol":"DOTUSDT","id":"434650","side":"Buy","size":221.00002},{"price":"43.470","symbol":"DOTUSDT","id":"434700","side":"Buy","size":578.3},{"price":"43.595","symbol":"DOTUSDT","id":"435950","side":"Sell","size":355.3},{"price":"43.475","symbol":"DOTUSDT","id":"434750","side":"Buy","size":670.3},{"price":"43.590","symbol":"DOTUSDT","id":"435900","side":"Sell","size":879.9},{"price":"43.600","symbol":"DOTUSDT","id":"436000","side":"Sell","size":215},{"price":"43.605","symbol":"DOTUSDT","id":"436050","side":"Sell","size":189.59999},{"price":"43.580","symbol":"DOTUSDT","id":"435800","side":"Sell","size":477}],"insert":[]},"cross_seq":"916952737","timestamp_e6":"1618677786882566"}
1618677787.172575: {"topic":"orderBookL2_25.ADAUSDT","type":"delta","data":{"delete":[],"update":[{"price":"1.3867","symbol":"ADAUSDT","id":"13867","side":"Buy","size":2000},{"price":"1.3862","symbol":"ADAUSDT","id":"13862","side":"Buy","size":3044},{"price":"1.3860","symbol":"ADAUSDT","id":"13860","side":"Buy","size":4446},{"price":"1.3863","symbol":"ADAUSDT","id":"13863","side":"Buy","size":4488},{"price":"1.3859","symbol":"ADAUSDT","id":"13859","side":"Buy","size":5053}],"insert":[]},"cross_seq":"916952737","timestamp_e6":"1618677786882425"}
1618677787.1726022: {"topic":"orderBookL2_25.LTCUSDT","type":"delta","data":{"delete":[{"price":"312.73","symbol":"LTCUSDT","id":"3127300","side":"Buy"},{"price":"312.84","symbol":"LTCUSDT","id":"3128400","side":"Buy"},{"price":"312.80","symbol":"LTCUSDT","id":"3128000","side":"Buy"}],"update":[{"price":"312.86","symbol":"LTCUSDT","id":"3128600","side":"Buy","size":155.3},{"price":"312.77","symbol":"LTCUSDT","id":"3127700","side":"Buy","size":49.5},{"price":"312.83","symbol":"LTCUSDT","id":"3128300","side":"Buy","size":1.5},{"price":"312.81","symbol":"LTCUSDT","id":"3128100","side":"Buy","size":70.1},{"price":"312.87","symbol":"LTCUSDT","id":"3128700","side":"Sell","size":250}],"insert":[{"price":"312.82","symbol":"LTCUSDT","id":"3128200","side":"Buy","size":68.600006},{"price":"312.79","symbol":"LTCUSDT","id":"3127900","side":"Buy","size":1.5},{"price":"312.85","symbol":"LTCUSDT","id":"3128500","side":"Buy","size":136.90001}]},"cross_seq":"1684521838","timestamp_e6":"1618677786880201"}
1618677787.172657: {"topic":"orderBookL2_25.BCHUSDT","type":"delta","data":{"delete":[{"price":"1054.50","symbol":"BCHUSDT","id":"10545000","side":"Sell"},{"price":"1054.55","symbol":"BCHUSDT","id":"10545500","side":"Sell"},{"price":"1054.15","symbol":"BCHUSDT","id":"10541500","side":"Buy"},{"price":"1054.10","symbol":"BCHUSDT","id":"10541000","side":"Buy"},{"price":"1054.60","symbol":"BCHUSDT","id":"10546000","side":"Sell"}],"update":[{"price":"1053.65","symbol":"BCHUSDT","id":"10536500","side":"Buy","size":10.73},{"price":"1053.60","symbol":"BCHUSDT","id":"10536000","side":"Buy","size":16.17},{"price":"1053.50","symbol":"BCHUSDT","id":"10535000","side":"Buy","size":24.78},{"price":"1055.80","symbol":"BCHUSDT","id":"10558000","side":"Sell","size":10.42},{"price":"1055.70","symbol":"BCHUSDT","id":"10557000","side":"Sell","size":14.190001},{"price":"1055.65","symbol":"BCHUSDT","id":"10556500","side":"Sell","size":14.65},{"price":"1055.85","symbol":"BCHUSDT","id":"10558500","side":"Sell","size":17.81},{"price":"1055.75","symbol":"BCHUSDT","id":"10557500","side":"Sell","size":6.33},{"price":"1053.75","symbol":"BCHUSDT","id":"10537500","side":"Buy","size":26.220001},{"price":"1053.70","symbol":"BCHUSDT","id":"10537000","side":"Buy","size":24.75},{"price":"1053.55","symbol":"BCHUSDT","id":"10535500","side":"Buy","size":18.22}],"insert":[{"price":"1054.00","symbol":"BCHUSDT","id":"10540000","side":"Buy","size":3.63},{"price":"1054.25","symbol":"BCHUSDT","id":"10542500","side":"Buy","size":10.969999},{"price":"1054.95","symbol":"BCHUSDT","id":"10549500","side":"Sell","size":1.64},{"price":"1055.90","symbol":"BCHUSDT","id":"10559000","side":"Sell","size":5.32},{"price":"1054.90","symbol":"BCHUSDT","id":"10549000","side":"Sell","size":1.97}]},"cross_seq":"864131945","timestamp_e6":"1618677786891246"}
1618677787.1727529: {"topic":"orderBookL2_25.XTZUSDT","type":"delta","data":{"delete":[{"price":"7.211","symbol":"XTZUSDT","id":"72110","side":"Buy"},{"price":"7.209","symbol":"XTZUSDT","id":"72090","side":"Buy"}],"update":[{"price":"7.212","symbol":"XTZUSDT","id":"72120","side":"Sell","size":2850.9},{"price":"7.217","symbol":"XTZUSDT","id":"72170","side":"Sell","size":769.80005},{"price":"7.206","symbol":"XTZUSDT","id":"72060","side":"Buy","size":932.5},{"price":"7.215","symbol":"XTZUSDT","id":"72150","side":"Sell","size":2498.3},{"price":"7.208","symbol":"XTZUSDT","id":"72080","side":"Buy","size":412.7},{"price":"7.213","symbol":"XTZUSDT","id":"72130","side":"Sell","size":0.4},{"price":"7.207","symbol":"XTZUSDT","id":"72070","side":"Buy","size":0.2},{"price":"7.216","symbol":"XTZUSDT","id":"72160","side":"Sell","size":926},{"price":"7.214","symbol":"XTZUSDT","id":"72140","side":"Sell","size":2651.6}],"insert":[{"price":"7.210","symbol":"XTZUSDT","id":"72100","side":"Buy","size":230.1},{"price":"7.185","symbol":"XTZUSDT","id":"71850","side":"Buy","size":1327.3}]},"cross_seq":"726228114","timestamp_e6":"1618677786895860"}
1618677787.1728199: {"topic":"orderBookL2_25.LTCUSDT","type":"delta","data":{"delete":[{"price":"312.59","symbol":"LTCUSDT","id":"3125900","side":"Buy"}],"update":[{"price":"312.83","symbol":"LTCUSDT","id":"3128300","side":"Buy","size":109.9},{"price":"313.02","symbol":"LTCUSDT","id":"3130200","side":"Sell","size":74.200005},{"price":"312.87","symbol":"LTCUSDT","id":"3128700","side":"Sell","size":0.6}],"insert":[{"price":"312.84","symbol":"LTCUSDT","id":"3128400","side":"Buy","size":107.399994}]},"cross_seq":"1684521852","timestamp_e6":"1618677786899399"}
1618677787.172854: {"topic":"orderBookL2_25.DOTUSDT","type":"delta","data":{"delete":[],"update":[{"price":"43.505","symbol":"DOTUSDT","id":"435050","side":"Buy","size":20}],"insert":[]},"cross_seq":"916952741","timestamp_e6":"1618677786902328"}
1618677787.17287: {"topic":"orderBookL2_25.LTCUSDT","type":"delta","data":{"delete":[{"price":"312.94","symbol":"LTCUSDT","id":"3129400","side":"Sell"},{"price":"312.90","symbol":"LTCUSDT","id":"3129000","side":"Sell"},{"price":"312.93","symbol":"LTCUSDT","id":"3129300","side":"Sell"},{"price":"312.91","symbol":"LTCUSDT","id":"3129100","side":"Sell"}],"update":[{"price":"312.96","symbol":"LTCUSDT","id":"3129600","side":"Sell","size":45.3},{"price":"312.92","symbol":"LTCUSDT","id":"3129200","side":"Sell","size":0.3},{"price":"312.95","symbol":"LTCUSDT","id":"3129500","side":"Sell","size":1.5}],"insert":[{"price":"313.15","symbol":"LTCUSDT","id":"3131500","side":"Sell","size":71.9},{"price":"312.97","symbol":"LTCUSDT","id":"3129700","side":"Sell","size":115.2},{"price":"313.16","symbol":"LTCUSDT","id":"3131600","side":"Sell","size":3.5},{"price":"313.17","symbol":"LTCUSDT","id":"3131700","side":"Sell","size":91.6}]},"cross_seq":"1684521893","timestamp_e6":"1618677786918169"}
1618677787.172926: {"topic":"orderBookL2_25.BCHUSDT","type":"delta","data":{"delete":[{"price":"1052.95","symbol":"BCHUSDT","id":"10529500","side":"Buy"},{"price":"1052.90","symbol":"BCHUSDT","id":"10529000","side":"Buy"}],"update":[{"price":"1054.75","symbol":"BCHUSDT","id":"10547500","side":"Sell","size":3.66},{"price":"1054.85","symbol":"BCHUSDT","id":"10548500","side":"Sell","size":5},{"price":"1054.90","symbol":"BCHUSDT","id":"10549000","side":"Sell","size":3.71},{"price":"1054.80","symbol":"BCHUSDT","id":"10548000","side":"Sell","size":6.12}],"insert":[{"price":"1054.15","symbol":"BCHUSDT","id":"10541500","side":"Buy","size":8.85},{"price":"1054.10","symbol":"BCHUSDT","id":"10541000","side":"Buy","size":7.46}]},"cross_seq":"864131953","timestamp_e6":"1618677786929090"}
1618677787.17297: {"topic":"orderBookL2_25.XTZUSDT","type":"delta","data":{"delete":[{"price":"7.185","symbol":"XTZUSDT","id":"71850","side":"Buy"}],"update":[{"price":"7.210","symbol":"XTZUSDT","id":"72100","side":"Buy","size":330.1},{"price":"7.212","symbol":"XTZUSDT","id":"72120","side":"Sell","size":0.9}],"insert":[{"price":"7.211","symbol":"XTZUSDT","id":"72110","side":"Buy","size":2750}]},"cross_seq":"726228119","timestamp_e6":"1618677786937493"}
1618677787.1729999: {"topic":"orderBookL2_25.LTCUSDT","type":"delta","data":{"delete":[{"price":"312.99","symbol":"LTCUSDT","id":"3129900","side":"Sell"},{"price":"312.97","symbol":"LTCUSDT","id":"3129700","side":"Sell"},{"price":"312.79","symbol":"LTCUSDT","id":"3127900","side":"Buy"}],"update":[{"price":"312.96","symbol":"LTCUSDT","id":"3129600","side":"Sell","size":160.5},{"price":"312.85","symbol":"LTCUSDT","id":"3128500","side":"Buy","size":138.4},{"price":"313.00","symbol":"LTCUSDT","id":"3130000","side":"Sell","size":41}],"insert":[{"price":"313.19","symbol":"LTCUSDT","id":"3131900","side":"Sell","size":35.3},{"price":"312.59","symbol":"LTCUSDT","id":"3125900","side":"Buy","size":74.700005},{"price":"313.18","symbol":"LTCUSDT","id":"3131800","side":"Sell","size":51.6}]},"cross_seq":"1684521899","timestamp_e6":"1618677786937850"}
1618677787.173048: {"topic":"orderBookL2_25.DOTUSDT","type":"delta","data":{"delete":[],"update":[{"price":"43.505","symbol":"DOTUSDT","id":"435050","side":"Buy","size":80}],"insert":[]},"cross_seq":"916952742","timestamp_e6":"1618677786942345"}
1618677787.173064: {"topic":"orderBookL2_25.LINKUSDT","type":"delta","data":{"delete":[{"price":"41.049","symbol":"LINKUSDT","id":"410490","side":"Buy"},{"price":"41.050","symbol":"LINKUSDT","id":"410500","side":"Buy"}],"update":[{"price":"41.046","symbol":"LINKUSDT","id":"410460","side":"Buy","size":103.600006},{"price":"41.048","symbol":"LINKUSDT","id":"410480","side":"Buy","size":1.4},{"price":"41.038","symbol":"LINKUSDT","id":"410380","side":"Buy","size":145.20001},{"price":"41.055","symbol":"LINKUSDT","id":"410550","side":"Buy","size":1667.7},{"price":"41.045","symbol":"LINKUSDT","id":"410450","side":"Buy","size":51.800003}],"insert":[{"price":"41.043","symbol":"LINKUSDT","id":"410430","side":"Buy","size":2.7},{"price":"41.047","symbol":"LINKUSDT","id":"410470","side":"Buy","size":396.7}]},"cross_seq":"1970978520","timestamp_e6":"1618677786944884"}
1618677787.173111: {"topic":"orderBookL2_25.DOTUSDT","type":"delta","data":{"delete":[],"update":[{"price":"43.505","symbol":"DOTUSDT","id":"435050","side":"Buy","size":70},{"price":"43.515","symbol":"DOTUSDT","id":"435150","side":"Buy","size":202}],"insert":[]},"cross_seq":"916952754","timestamp_e6":"1618677786962357"}
1618677787.17313: {"topic":"orderBookL2_25.UNIUSDT","type":"delta","data":{"delete":[],"update":[{"price":"35.406","symbol":"UNIUSDT","id":"354060","side":"Sell","size":32.1},{"price":"35.403","symbol":"UNIUSDT","id":"354030","side":"Sell","size":63.800003},{"price":"35.404","symbol":"UNIUSDT","id":"354040","side":"Sell","size":70.6},{"price":"35.408","symbol":"UNIUSDT","id":"354080","side":"Sell","size":124.100006},{"price":"35.413","symbol":"UNIUSDT","id":"354130","side":"Sell","size":44.999996},{"price":"35.402","symbol":"UNIUSDT","id":"354020","side":"Sell","size":74.4},{"price":"35.407","symbol":"UNIUSDT","id":"354070","side":"Sell","size":47.2},{"price":"35.405","symbol":"UNIUSDT","id":"354050","side":"Sell","size":66.1}],"insert":[]},"cross_seq":"916952754","timestamp_e6":"1618677786962529"}
1618677787.173166: {"topic":"orderBookL2_25.BCHUSDT","type":"delta","data":{"delete":[{"price":"1055.90","symbol":"BCHUSDT","id":"10559000","side":"Sell"},{"price":"1054.75","symbol":"BCHUSDT","id":"10547500","side":"Sell"},{"price":"1054.70","symbol":"BCHUSDT","id":"10547000","side":"Sell"},{"price":"1055.85","symbol":"BCHUSDT","id":"10558500","side":"Sell"}],"update":[],"insert":[{"price":"1054.60","symbol":"BCHUSDT","id":"10546000","side":"Sell","size":5},{"price":"1054.65","symbol":"BCHUSDT","id":"10546500","side":"Sell","size":3.71},{"price":"1054.50","symbol":"BCHUSDT","id":"10545000","side":"Sell","size":9.78},{"price":"1054.55","symbol":"BCHUSDT","id":"10545500","side":"Sell","size":6.12}]},"cross_seq":"864131972","timestamp_e6":"1618677786970748"}
1618677787.173214: {"topic":"orderBookL2_25.XTZUSDT","type":"delta","data":{"delete":[{"price":"7.211","symbol":"XTZUSDT","id":"72110","side":"Buy"}],"update":[{"price":"7.210","symbol":"XTZUSDT","id":"72100","side":"Buy","size":230.1},{"price":"7.206","symbol":"XTZUSDT","id":"72060","side":"Buy","size":2203.5}],"insert":[{"price":"7.185","symbol":"XTZUSDT","id":"71850","side":"Buy","size":1327.3}]},"cross_seq":"726228122","timestamp_e6":"1618677786976746"}
1618677787.173244: {"topic":"orderBookL2_25.ADAUSDT","type":"delta","data":{"delete":[],"update":[{"price":"1.3856","symbol":"ADAUSDT","id":"13856","side":"Buy","size":8175},{"price":"1.3858","symbol":"ADAUSDT","id":"13858","side":"Buy","size":4493},{"price":"1.3885","symbol":"ADAUSDT","id":"13885","side":"Sell","size":1633},{"price":"1.3862","symbol":"ADAUSDT","id":"13862","side":"Buy","size":1536},{"price":"1.3860","symbol":"ADAUSDT","id":"13860","side":"Buy","size":2301},{"price":"1.3864","symbol":"ADAUSDT","id":"13864","side":"Buy","size":4489},{"price":"1.3863","symbol":"ADAUSDT","id":"13863","side":"Buy","size":5344},{"price":"1.3859","symbol":"ADAUSDT","id":"13859","side":"Buy","size":2752.0002},{"price":"1.3886","symbol":"ADAUSDT","id":"13886","side":"Sell","size":944.00006},{"price":"1.3861","symbol":"ADAUSDT","id":"13861","side":"Buy","size":5202}],"insert":[]},"cross_seq":"916952769","timestamp_e6":"1618677786982352"}
1618677787.173286: {"topic":"orderBookL2_25.LINKUSDT","type":"delta","data":{"delete":[],"update":[{"price":"41.086","symbol":"LINKUSDT","id":"410860","side":"Sell","size":132.3}],"insert":[]},"cross_seq":"1970978521","timestamp_e6":"1618677786984453"}
1618677787.173302: {"topic":"orderBookL2_25.LTCUSDT","type":"delta","data":{"delete":[{"price":"313.19","symbol":"LTCUSDT","id":"3131900","side":"Sell"},{"price":"313.18","symbol":"LTCUSDT","id":"3131800","side":"Sell"}],"update":[{"price":"312.95","symbol":"LTCUSDT","id":"3129500","side":"Sell","size":116.7},{"price":"312.98","symbol":"LTCUSDT","id":"3129800","side":"Sell","size":35.699997},{"price":"312.96","symbol":"LTCUSDT","id":"3129600","side":"Sell","size":45.3}],"insert":[{"price":"312.99","symbol":"LTCUSDT","id":"3129900","side":"Sell","size":41},{"price":"312.97","symbol":"LTCUSDT","id":"3129700","side":"Sell","size":70.8}]},"cross_seq":"1684521924","timestamp_e6":"1618677786997967"}
1618677787.173341: {"topic":"orderBookL2_25.ADAUSDT","type":"delta","data":{"delete":[{"price":"1.3847","symbol":"ADAUSDT","id":"13847","side":"Buy"}],"update":[{"price":"1.3861","symbol":"ADAUSDT","id":"13861","side":"Buy","size":5928},{"price":"1.3860","symbol":"ADAUSDT","id":"13860","side":"Buy","size":793},{"price":"1.3863","symbol":"ADAUSDT","id":"13863","side":"Buy","size":3156},{"price":"1.3864","symbol":"ADAUSDT","id":"13864","side":"Buy","size":3044}],"insert":[{"price":"1.3865","symbol":"ADAUSDT","id":"13865","side":"Buy","size":4489}]},"cross_seq":"916952775","timestamp_e6":"1618677787002352"}
1618677787.173375: {"topic":"orderBookL2_25.BCHUSDT","type":"delta","data":{"delete":[{"price":"1053.00","symbol":"BCHUSDT","id":"10530000","side":"Buy"}],"update":[],"insert":[{"price":"1054.40","symbol":"BCHUSDT","id":"10544000","side":"Buy","size":13.329999}]},"cross_seq":"864131973","timestamp_e6":"1618677787009916"}
1618677787.173401: {"topic":"orderBookL2_25.XTZUSDT","type":"delta","data":{"delete":[],"update":[{"price":"7.215","symbol":"XTZUSDT","id":"72150","side":"Sell","size":1227.2001}],"insert":[]},"cross_seq":"726228125","timestamp_e6":"1618677787014556"}
1618677787.1734169: {"topic":"orderBookL2_25.LTCUSDT","type":"delta","data":{"delete":[{"price":"312.97","symbol":"LTCUSDT","id":"3129700","side":"Sell"}],"update":[{"price":"312.95","symbol":"LTCUSDT","id":"3129500","side":"Sell","size":1.5},{"price":"312.86","symbol":"LTCUSDT","id":"3128600","side":"Buy","size":305.30002},{"price":"312.96","symbol":"LTCUSDT","id":"3129600","side":"Sell","size":116.100006}],"insert":[{"price":"312.94","symbol":"LTCUSDT","id":"3129400","side":"Sell","size":115.2}]},"cross_seq":"1684521937","timestamp_e6":"1618677787040259"}
1618677787.173449: {"topic":"orderBookL2_25.ADAUSDT","type":"delta","data":{"delete":[],"update":[{"price":"1.3861","symbol":"ADAUSDT","id":"13861","side":"Buy","size":3627.0002},{"price":"1.3859","symbol":"ADAUSDT","id":"13859","side":"Buy","size":4837},{"price":"1.3857","symbol":"ADAUSDT","id":"13857","side":"Buy","size":1707},{"price":"1.3860","symbol":"ADAUSDT","id":"13860","side":"Buy","size":3044}],"insert":[]},"cross_seq":"916952808","timestamp_e6":"1618677787042369"}
1618677787.173474: {"topic":"orderBookL2_25.BCHUSDT","type":"delta","data":{"delete":[{"price":"1054.40","symbol":"BCHUSDT","id":"10544000","side":"Buy"}],"update":[],"insert":[{"price":"1053.00","symbol":"BCHUSDT","id":"10530000","side":"Buy","size":19.42}]},"cross_seq":"864131974","timestamp_e6":"1618677787050309"}
1618677787.173495: {"topic":"orderBookL2_25.XTZUSDT","type":"delta","data":{"delete":[],"update":[{"price":"7.210","symbol":"XTZUSDT","id":"72100","side":"Buy","size":330.1}],"insert":[]},"cross_seq":"726228126","timestamp_e6":"1618677787055159"}
1618677787.1735098: {"topic":"orderBookL2_25.LTCUSDT","type":"delta","data":{"delete":[],"update":[{"price":"312.96","symbol":"LTCUSDT","id":"3129600","side":"Sell","size":72.3}],"insert":[]},"cross_seq":"1684521938","timestamp_e6":"1618677787058346"}
1618677787.173524: {"topic":"trade.XTZUSDT","data":[{"symbol":"XTZUSDT","tick_direction":"PlusTick","price":"7.211","size":0.2,"timestamp":"2021-04-17T16:43:06.000Z","trade_time_ms":"1618677786997","side":"Buy","trade_id":"cc447792-0db4-5415-8e6f-6b30aca01326"}]}
1618677787.175467: {"topic":"orderBookL2_25.ADAUSDT","type":"delta","data":{"delete":[{"price":"1.3861","symbol":"ADAUSDT","id":"13861","side":"Buy"},{"price":"1.3865","symbol":"ADAUSDT","id":"13865","side":"Buy"},{"price":"1.3854","symbol":"ADAUSDT","id":"13854","side":"Buy"},{"price":"1.3864","symbol":"ADAUSDT","id":"13864","side":"Buy"},{"price":"1.3862","symbol":"ADAUSDT","id":"13862","side":"Buy"}],"update":[{"price":"1.3859","symbol":"ADAUSDT","id":"13859","side":"Buy","size":2404},{"price":"1.3863","symbol":"ADAUSDT","id":"13863","side":"Buy","size":2300},{"price":"1.3857","symbol":"ADAUSDT","id":"13857","side":"Buy","size":4837},{"price":"1.3855","symbol":"ADAUSDT","id":"13855","side":"Buy","size":4778},{"price":"1.3856","symbol":"ADAUSDT","id":"13856","side":"Buy","size":4707},{"price":"1.3858","symbol":"ADAUSDT","id":"13858","side":"Buy","size":5796}],"insert":[{"price":"1.3844","symbol":"ADAUSDT","id":"13844","side":"Buy","size":181.00002},{"price":"1.3846","symbol":"ADAUSDT","id":"13846","side":"Buy","size":1015},{"price":"1.3845","symbol":"ADAUSDT","id":"13845","side":"Buy","size":4684},{"price":"1.3843","symbol":"ADAUSDT","id":"13843","side":"Buy","size":5092},{"price":"1.3847","symbol":"ADAUSDT","id":"13847","side":"Buy","size":4462}]},"cross_seq":"916952838","timestamp_e6":"1618677787062355"}
1618677787.175564: {"topic":"orderBookL2_25.LINKUSDT","type":"delta","data":{"delete":[],"update":[{"price":"41.055","symbol":"LINKUSDT","id":"410550","side":"Buy","size":1193.5}],"insert":[]},"cross_seq":"1970978522","timestamp_e6":"1618677787064869"}
1618677787.175586: {"topic":"orderBookL2_25.ETHUSDT","type":"delta","data":{"delete":[{"price":"2363.35","symbol":"ETHUSDT","id":"23633500","side":"Buy"},{"price":"2363.40","symbol":"ETHUSDT","id":"23634000","side":"Buy"}],"update":[{"price":"2364.55","symbol":"ETHUSDT","id":"23645500","side":"Buy","size":19.06}],"insert":[{"price":"2364.60","symbol":"ETHUSDT","id":"23646000","side":"Buy","size":34.83},{"price":"2364.65","symbol":"ETHUSDT","id":"23646500","side":"Buy","size":34.649998}]},"cross_seq":"1800546186","timestamp_e6":"1618677787067811"}
1618677787.175621: {"topic":"orderBookL2_25.DOTUSDT","type":"delta","data":{"delete":[{"price":"43.535","symbol":"DOTUSDT","id":"435350","side":"Sell"},{"price":"43.545","symbol":"DOTUSDT","id":"435450","side":"Sell"}],"update":[{"price":"43.525","symbol":"DOTUSDT","id":"435250","side":"Sell","size":363.8},{"price":"43.485","symbol":"DOTUSDT","id":"434850","side":"Buy","size":335.1},{"price":"43.550","symbol":"DOTUSDT","id":"435500","side":"Sell","size":146.8},{"price":"43.540","symbol":"DOTUSDT","id":"435400","side":"Sell","size":66},{"price":"43.470","symbol":"DOTUSDT","id":"434700","side":"Buy","size":639.2},{"price":"43.475","symbol":"DOTUSDT","id":"434750","side":"Buy","size":451.1}],"insert":[{"price":"43.650","symbol":"DOTUSDT","id":"436500","side":"Sell","size":151},{"price":"43.655","symbol":"DOTUSDT","id":"436550","side":"Sell","size":420.2}]},"cross_seq":"916952861","timestamp_e6":"1618677787082461"}
1618677787.175669: {"topic":"orderBookL2_25.ADAUSDT","type":"delta","data":{"delete":[],"update":[{"price":"1.3868","symbol":"ADAUSDT","id":"13868","side":"Buy","size":12886}],"insert":[]},"cross_seq":"916952861","timestamp_e6":"1618677787082321"}
1618677787.1756852: {"topic":"orderBookL2_25.BCHUSDT","type":"delta","data":{"delete":[{"price":"1055.75","symbol":"BCHUSDT","id":"10557500","side":"Sell"},{"price":"1054.20","symbol":"BCHUSDT","id":"10542000","side":"Buy"},{"price":"1055.80","symbol":"BCHUSDT","id":"10558000","side":"Sell"}],"update":[{"price":"1054.05","symbol":"BCHUSDT","id":"10540500","side":"Buy","size":30.05}],"insert":[{"price":"1054.30","symbol":"BCHUSDT","id":"10543000","side":"Buy","size":10.969999},{"price":"1054.75","symbol":"BCHUSDT","id":"10547500","side":"Sell","size":1.64},{"price":"1054.70","symbol":"BCHUSDT","id":"10547000","side":"Sell","size":1.97}]},"cross_seq":"864131987","timestamp_e6":"1618677787089929"}
1618677787.184784: {"topic":"orderBookL2_25.LTCUSDT","type":"delta","data":{"delete":[],"update":[{"price":"312.72","symbol":"LTCUSDT","id":"3127200","side":"Buy","size":222}],"insert":[]},"cross_seq":"1684521940","timestamp_e6":"1618677787097896"}
1618677787.18683: {"topic":"orderBookL2_25.UNIUSDT","type":"delta","data":{"delete":[],"update":[{"price":"35.406","symbol":"UNIUSDT","id":"354060","side":"Sell","size":47.100002}],"insert":[]},"cross_seq":"916952871","timestamp_e6":"1618677787102861"}
1618677787.342853: {"topic":"orderBookL2_25.ADAUSDT","type":"delta","data":{"delete":[],"update":[{"price":"1.3857","symbol":"ADAUSDT","id":"13857","side":"Buy","size":2752.0002},{"price":"1.3859","symbol":"ADAUSDT","id":"13859","side":"Buy","size":3044},{"price":"1.3860","symbol":"ADAUSDT","id":"13860","side":"Buy","size":4489},{"price":"1.3856","symbol":"ADAUSDT","id":"13856","side":"Buy","size":7007.9995},{"price":"1.3855","symbol":"ADAUSDT","id":"13855","side":"Buy","size":2477},{"price":"1.3858","symbol":"ADAUSDT","id":"13858","side":"Buy","size":4055}],"insert":[]},"cross_seq":"916952871","timestamp_e6":"1618677787102342"}
1618677787.342924: {"topic":"orderBookL2_25.LINKUSDT","type":"delta","data":{"delete":[],"update":[{"price":"41.055","symbol":"LINKUSDT","id":"410550","side":"Buy","size":1667.7}],"insert":[]},"cross_seq":"1970978523","timestamp_e6":"1618677787105937"}
1618677787.342957: {"topic":"orderBookL2_25.ETHUSDT","type":"delta","data":{"delete":[],"update":[{"price":"2364.90","symbol":"ETHUSDT","id":"23649000","side":"Buy","size":206.98}],"insert":[]},"cross_seq":"1800546187","timestamp_e6":"1618677787108429"}
1618677787.342983: {"topic":"orderBookL2_25.DOTUSDT","type":"delta","data":{"delete":[],"update":[{"price":"43.520","symbol":"DOTUSDT","id":"435200","side":"Sell","size":125.2}],"insert":[]},"cross_seq":"916952872","timestamp_e6":"1618677787122343"}
1618677787.343008: {"topic":"orderBookL2_25.LINKUSDT","type":"delta","data":{"delete":[{"price":"41.048","symbol":"LINKUSDT","id":"410480","side":"Buy"},{"price":"41.087","symbol":"LINKUSDT","id":"410870","side":"Sell"}],"update":[{"price":"41.056","symbol":"LINKUSDT","id":"410560","side":"Sell","size":66},{"price":"41.045","symbol":"LINKUSDT","id":"410450","side":"Buy","size":50.899998},{"price":"41.052","symbol":"LINKUSDT","id":"410520","side":"Buy","size":115.399994}],"insert":[{"price":"41.028","symbol":"LINKUSDT","id":"410280","side":"Buy","size":425.9},{"price":"41.060","symbol":"LINKUSDT","id":"410600","side":"Sell","size":1.4}]},"cross_seq":"1970978532","timestamp_e6":"1618677787124063"}
1618677787.343092: {"topic":"orderBookL2_25.ETHUSDT","type":"delta","data":{"delete":[],"update":[{"price":"2365.05","symbol":"ETHUSDT","id":"23650500","side":"Sell","size":35.75}],"insert":[]},"cross_seq":"1800546188","timestamp_e6":"1618677787147858"}
1618677787.3431191: {"topic":"orderBookL2_25.XTZUSDT","type":"delta","data":{"delete":[{"price":"7.186","symbol":"XTZUSDT","id":"71860","side":"Buy"},{"price":"7.185","symbol":"XTZUSDT","id":"71850","side":"Buy"}],"update":[{"price":"7.202","symbol":"XTZUSDT","id":"72020","side":"Buy","size":1452.4},{"price":"7.217","symbol":"XTZUSDT","id":"72170","side":"Sell","size":55.800003},{"price":"7.219","symbol":"XTZUSDT","id":"72190","side":"Sell","size":1541.9},{"price":"7.207","symbol":"XTZUSDT","id":"72070","side":"Buy","size":80.700005},{"price":"7.214","symbol":"XTZUSDT","id":"72140","side":"Sell","size":1472.5},{"price":"7.216","symbol":"XTZUSDT","id":"72160","side":"Sell","size":366.90002},{"price":"7.205","symbol":"XTZUSDT","id":"72050","side":"Buy","size":2386.3},{"price":"7.215","symbol":"XTZUSDT","id":"72150","side":"Sell","size":151.2},{"price":"7.204","symbol":"XTZUSDT","id":"72040","side":"Buy","size":1048.7999},{"price":"7.206","symbol":"XTZUSDT","id":"72060","side":"Buy","size":2287.2},{"price":"7.218","symbol":"XTZUSDT","id":"72180","side":"Sell","size":2126.4001},{"price":"7.213","symbol":"XTZUSDT","id":"72130","side":"Sell","size":212.50002},{"price":"7.212","symbol":"XTZUSDT","id":"72120","side":"Sell","size":274.2},{"price":"7.201","symbol":"XTZUSDT","id":"72010","side":"Buy","size":1084.7001}],"insert":[{"price":"7.209","symbol":"XTZUSDT","id":"72090","side":"Buy","size":176},{"price":"7.211","symbol":"XTZUSDT","id":"72110","side":"Buy","size":277.1}]},"cross_seq":"726228153","timestamp_e6":"1618677787155834"}
1618677787.343246: {"topic":"orderBookL2_25.UNIUSDT","type":"delta","data":{"delete":[],"update":[{"price":"35.389","symbol":"UNIUSDT","id":"353890","side":"Buy","size":118.799995}],"insert":[]},"cross_seq":"916952875","timestamp_e6":"1618677787182427"}
1618677787.3432739: {"topic":"orderBookL2_25.XTZUSDT","type":"delta","data":{"delete":[],"update":[{"price":"7.212","symbol":"XTZUSDT","id":"72120","side":"Sell","size":7124.2},{"price":"7.216","symbol":"XTZUSDT","id":"72160","side":"Sell","size":1638.0001},{"price":"7.210","symbol":"XTZUSDT","id":"72100","side":"Buy","size":230.1}],"insert":[]},"cross_seq":"726228158","timestamp_e6":"1618677787195714"}
1618677787.343308: {"topic":"orderBookL2_25.DOTUSDT","type":"delta","data":{"delete":[],"update":[{"price":"43.485","symbol":"DOTUSDT","id":"434850","side":"Buy","size":380.1}],"insert":[]},"cross_seq":"916952877","timestamp_e6":"1618677787202324"}
1618677787.343331: {"topic":"orderBookL2_25.LINKUSDT","type":"delta","data":{"delete":[{"price":"41.028","symbol":"LINKUSDT","id":"410280","side":"Buy"}],"update":[{"price":"41.055","symbol":"LINKUSDT","id":"410550","side":"Buy","size":1736.1},{"price":"41.065","symbol":"LINKUSDT","id":"410650","side":"Sell","size":180.59999},{"price":"41.051","symbol":"LINKUSDT","id":"410510","side":"Buy","size":287.7},{"price":"41.069","symbol":"LINKUSDT","id":"410690","side":"Sell","size":95.1},{"price":"41.067","symbol":"LINKUSDT","id":"410670","side":"Sell","size":99.3},{"price":"41.053","symbol":"LINKUSDT","id":"410530","side":"Buy","size":274},{"price":"41.052","symbol":"LINKUSDT","id":"410520","side":"Buy","size":189.59999},{"price":"41.054","symbol":"LINKUSDT","id":"410540","side":"Buy","size":265.2}],"insert":[{"price":"41.050","symbol":"LINKUSDT","id":"410500","side":"Buy","size":148.40001}]},"cross_seq":"1970978542","timestamp_e6":"1618677787205500"}
1618677787.343406: {"topic":"orderBookL2_25.LTCUSDT","type":"delta","data":{"delete":[],"update":[{"price":"312.86","symbol":"LTCUSDT","id":"3128600","side":"Buy","size":289.1}],"insert":[]},"cross_seq":"1684521942","timestamp_e6":"1618677787239468"}
1618677787.343432: {"topic":"orderBookL2_25.ADAUSDT","type":"delta","data":{"delete":[{"price":"1.3844","symbol":"ADAUSDT","id":"13844","side":"Buy"},{"price":"1.3843","symbol":"ADAUSDT","id":"13843","side":"Buy"},{"price":"1.3845","symbol":"ADAUSDT","id":"13845","side":"Buy"}],"update":[{"price":"1.3856","symbol":"ADAUSDT","id":"13856","side":"Buy","size":8175},{"price":"1.3855","symbol":"ADAUSDT","id":"13855","side":"Buy","size":3115.0002},{"price":"1.3858","symbol":"ADAUSDT","id":"13858","side":"Buy","size":2752.0002},{"price":"1.3860","symbol":"ADAUSDT","id":"13860","side":"Buy","size":1445},{"price":"1.3859","symbol":"ADAUSDT","id":"13859","side":"Buy","size":640},{"price":"1.3857","symbol":"ADAUSDT","id":"13857","side":"Buy","size":7512},{"price":"1.3863","symbol":"ADAUSDT","id":"13863","side":"Buy","size":6789}],"insert":[{"price":"1.3862","symbol":"ADAUSDT","id":"13862","side":"Buy","size":3044},{"price":"1.3854","symbol":"ADAUSDT","id":"13854","side":"Buy","size":5330},{"price":"1.3861","symbol":"ADAUSDT","id":"13861","side":"Buy","size":2085}]},"cross_seq":"916952929","timestamp_e6":"1618677787242313"}
1618677787.343528: {"topic":"orderBookL2_25.UNIUSDT","type":"delta","data":{"delete":[{"price":"35.360","symbol":"UNIUSDT","id":"353600","side":"Buy"},{"price":"35.361","symbol":"UNIUSDT","id":"353610","side":"Buy"},{"price":"35.385","symbol":"UNIUSDT","id":"353850","side":"Buy"}],"update":[{"price":"35.401","symbol":"UNIUSDT","id":"354010","side":"Buy","size":220.7},{"price":"35.384","symbol":"UNIUSDT","id":"353840","side":"Buy","size":35.4}],"insert":[{"price":"35.382","symbol":"UNIUSDT","id":"353820","side":"Buy","size":24.8},{"price":"35.383","symbol":"UNIUSDT","id":"353830","side":"Buy","size":44.7},{"price":"35.381","symbol":"UNIUSDT","id":"353810","side":"Buy","size":20.5}]},"cross_seq":"916952929","timestamp_e6":"1618677787242479"}
1618677787.343603: {"topic":"orderBookL2_25.LINKUSDT","type":"delta","data":{"delete":[],"update":[{"price":"41.055","symbol":"LINKUSDT","id":"410550","side":"Buy","size":1261.9}],"insert":[]},"cross_seq":"1970978543","timestamp_e6":"1618677787244826"}
1618677787.353586: {"topic":"orderBookL2_25.LTCUSDT","type":"delta","data":{"delete":[],"update":[{"price":"312.86","symbol":"LTCUSDT","id":"3128600","side":"Buy","size":305.30002}],"insert":[]},"cross_seq":"1684521943","timestamp_e6":"1618677787259330"}
1618677787.3536808: {"topic":"orderBookL2_25.DOTUSDT","type":"delta","data":{"delete":[],"update":[{"price":"43.505","symbol":"DOTUSDT","id":"435050","side":"Buy","size":10}],"insert":[]},"cross_seq":"916952930","timestamp_e6":"1618677787262356"}
1618677787.35374: {"topic":"orderBookL2_25.BCHUSDT","type":"delta","data":{"delete":[{"price":"1053.00","symbol":"BCHUSDT","id":"10530000","side":"Buy"}],"update":[{"price":"1054.75","symbol":"BCHUSDT","id":"10547500","side":"Sell","size":5},{"price":"1054.05","symbol":"BCHUSDT","id":"10540500","side":"Buy","size":33.68},{"price":"1054.80","symbol":"BCHUSDT","id":"10548000","side":"Sell","size":1.64},{"price":"1054.70","symbol":"BCHUSDT","id":"10547000","side":"Sell","size":6.12},{"price":"1054.85","symbol":"BCHUSDT","id":"10548500","side":"Sell","size":1.64},{"price":"1054.65","symbol":"BCHUSDT","id":"10546500","side":"Sell","size":6.07}],"insert":[{"price":"1054.20","symbol":"BCHUSDT","id":"10542000","side":"Buy","size":8.85}]},"cross_seq":"864131995","timestamp_e6":"1618677787269127"}
1618677787.353865: {"topic":"orderBookL2_25.ETHUSDT","type":"delta","data":{"delete":[],"update":[{"price":"2364.90","symbol":"ETHUSDT","id":"23649000","side":"Buy","size":161.98}],"insert":[]},"cross_seq":"1800546190","timestamp_e6":"1618677787268487"}
1618677787.362161: {"topic":"orderBookL2_25.XTZUSDT","type":"delta","data":{"delete":[],"update":[{"price":"7.208","symbol":"XTZUSDT","id":"72080","side":"Buy","size":132.7}],"insert":[]},"cross_seq":"726228159","timestamp_e6":"1618677787274767"}
1618677787.687694: {"topic":"orderBookL2_25.LTCUSDT","type":"delta","data":{"delete":[{"price":"312.59","symbol":"LTCUSDT","id":"3125900","side":"Buy"}],"update":[{"price":"312.81","symbol":"LTCUSDT","id":"3128100","side":"Buy","size":49.5},{"price":"312.86","symbol":"LTCUSDT","id":"3128600","side":"Buy","size":429.3}],"insert":[{"price":"312.79","symbol":"LTCUSDT","id":"3127900","side":"Buy","size":1}]},"cross_seq":"1684521947","timestamp_e6":"1618677787279793"}
1618677787.687758: {"topic":"orderBookL2_25.ADAUSDT","type":"delta","data":{"delete":[{"price":"1.3861","symbol":"ADAUSDT","id":"13861","side":"Buy"},{"price":"1.3862","symbol":"ADAUSDT","id":"13862","side":"Buy"}],"update":[{"price":"1.3863","symbol":"ADAUSDT","id":"13863","side":"Buy","size":2300},{"price":"1.3860","symbol":"ADAUSDT","id":"13860","side":"Buy","size":2301}],"insert":[{"price":"1.3845","symbol":"ADAUSDT","id":"13845","side":"Buy","size":4684},{"price":"1.3864","symbol":"ADAUSDT","id":"13864","side":"Buy","size":4489}]},"cross_seq":"916952964","timestamp_e6":"1618677787282451"}
1618677787.6896179: {"topic":"orderBookL2_25.UNIUSDT","type":"delta","data":{"delete":[{"price":"35.386","symbol":"UNIUSDT","id":"353860","side":"Buy"},{"price":"35.388","symbol":"UNIUSDT","id":"353880","side":"Buy"},{"price":"35.384","symbol":"UNIUSDT","id":"353840","side":"Buy"},{"price":"35.387","symbol":"UNIUSDT","id":"353870","side":"Buy"},{"price":"35.383","symbol":"UNIUSDT","id":"353830","side":"Buy"}],"update":[{"price":"35.382","symbol":"UNIUSDT","id":"353820","side":"Buy","size":44.7},{"price":"35.389","symbol":"UNIUSDT","id":"353890","side":"Buy","size":59.000004}],"insert":[{"price":"35.380","symbol":"UNIUSDT","id":"353800","side":"Buy","size":20.5},{"price":"35.360","symbol":"UNIUSDT","id":"353600","side":"Buy","size":20.5},{"price":"35.361","symbol":"UNIUSDT","id":"353610","side":"Buy","size":11.4},{"price":"35.358","symbol":"UNIUSDT","id":"353580","side":"Buy","size":20.4},{"price":"35.359","symbol":"UNIUSDT","id":"353590","side":"Buy","size":23.3}]},"cross_seq":"916952964","timestamp_e6":"1618677787282923"}
1618677787.689783: {"topic":"orderBookL2_25.LTCUSDT","type":"delta","data":{"delete":[{"price":"312.98","symbol":"LTCUSDT","id":"3129800","side":"Sell"},{"price":"312.78","symbol":"LTCUSDT","id":"3127800","side":"Buy"},{"price":"312.77","symbol":"LTCUSDT","id":"3127700","side":"Buy"},{"price":"312.99","symbol":"LTCUSDT","id":"3129900","side":"Sell"},{"price":"312.94","symbol":"LTCUSDT","id":"3129400","side":"Sell"}],"update":[{"price":"312.79","symbol":"LTCUSDT","id":"3127900","side":"Buy","size":51.800003},{"price":"312.75","symbol":"LTCUSDT","id":"3127500","side":"Buy","size":18.9},{"price":"312.81","symbol":"LTCUSDT","id":"3128100","side":"Buy","size":95.3},{"price":"312.83","symbol":"LTCUSDT","id":"3128300","side":"Buy","size":133.9},{"price":"312.82","symbol":"LTCUSDT","id":"3128200","side":"Buy","size":117.799995},{"price":"312.85","symbol":"LTCUSDT","id":"3128500","side":"Buy","size":136.90001},{"price":"312.86","symbol":"LTCUSDT","id":"3128600","side":"Buy","size":139.09999},{"price":"312.96","symbol":"LTCUSDT","id":"3129600","side":"Sell","size":64.8}],"insert":[{"price":"312.93","symbol":"LTCUSDT","id":"3129300","side":"Sell","size":112.3},{"price":"313.19","symbol":"LTCUSDT","id":"3131900","side":"Sell","size":35.3},{"price":"312.73","symbol":"LTCUSDT","id":"3127300","side":"Buy","size":20.8},{"price":"312.80","symbol":"LTCUSDT","id":"3128000","side":"Buy","size":71.7},{"price":"313.18","symbol":"LTCUSDT","id":"3131800","side":"Sell","size":51.6}]},"cross_seq":"1684521984","timestamp_e6":"1618677787299288"}
1618677787.689899: {"topic":"orderBookL2_25.UNIUSDT","type":"delta","data":{"delete":[],"update":[{"price":"35.401","symbol":"UNIUSDT","id":"354010","side":"Buy","size":64.700005}],"insert":[]},"cross_seq":"916952979","timestamp_e6":"1618677787302517"}
1618677787.6899252: {"topic":"orderBookL2_25.DOTUSDT","type":"delta","data":{"delete":[{"price":"43.645","symbol":"DOTUSDT","id":"436450","side":"Sell"},{"price":"43.650","symbol":"DOTUSDT","id":"436500","side":"Sell"},{"price":"43.655","symbol":"DOTUSDT","id":"436550","side":"Sell"}],"update":[{"price":"43.475","symbol":"DOTUSDT","id":"434750","side":"Buy","size":575.3},{"price":"43.590","symbol":"DOTUSDT","id":"435900","side":"Sell","size":796.4},{"price":"43.525","symbol":"DOTUSDT","id":"435250","side":"Sell","size":236.2},{"price":"43.530","symbol":"DOTUSDT","id":"435300","side":"Sell","size":420.4},{"price":"43.540","symbol":"DOTUSDT","id":"435400","side":"Sell","size":155.09999},{"price":"43.580","symbol":"DOTUSDT","id":"435800","side":"Sell","size":362.00003},{"price":"43.600","symbol":"DOTUSDT","id":"436000","side":"Sell","size":2},{"price":"43.520","symbol":"DOTUSDT","id":"435200","side":"Sell","size":789}],"insert":[{"price":"43.545","symbol":"DOTUSDT","id":"435450","side":"Sell","size":146.8},{"price":"43.535","symbol":"DOTUSDT","id":"435350","side":"Sell","size":112},{"price":"43.575","symbol":"DOTUSDT","id":"435750","side":"Sell","size":399.7}]},"cross_seq":"916952979","timestamp_e6":"1618677787302369"}
1618677787.6900108: {"topic":"orderBookL2_25.ETHUSDT","type":"delta","data":{"delete":[],"update":[{"price":"2365.80","symbol":"ETHUSDT","id":"23658000","side":"Sell","size":14.62},{"price":"2365.70","symbol":"ETHUSDT","id":"23657000","side":"Sell","size":17.529999},{"price":"2364.90","symbol":"ETHUSDT","id":"23649000","side":"Buy","size":206.98},{"price":"2365.75","symbol":"ETHUSDT","id":"23657500","side":"Sell","size":39.73},{"price":"2365.55","symbol":"ETHUSDT","id":"23655500","side":"Sell","size":101.909996}],"insert":[]},"cross_seq":"1800546201","timestamp_e6":"1618677787308594"}
1618677787.690052: {"topic":"orderBookL2_25.BCHUSDT","type":"delta","data":{"delete":[{"price":"1054.55","symbol":"BCHUSDT","id":"10545500","side":"Sell"},{"price":"1054.60","symbol":"BCHUSDT","id":"10546000","side":"Sell"},{"price":"1054.50","symbol":"BCHUSDT","id":"10545000","side":"Sell"}],"update":[{"price":"1054.80","symbol":"BCHUSDT","id":"10548000","side":"Sell","size":10.21},{"price":"1054.15","symbol":"BCHUSDT","id":"10541500","side":"Buy","size":14.009999},{"price":"1054.05","symbol":"BCHUSDT","id":"10540500","side":"Buy","size":36.34},{"price":"1054.20","symbol":"BCHUSDT","id":"10542000","side":"Buy","size":12.110001},{"price":"1054.90","symbol":"BCHUSDT","id":"10549000","side":"Sell","size":5.89},{"price":"1054.25","symbol":"BCHUSDT","id":"10542500","side":"Buy","size":16.09},{"price":"1054.95","symbol":"BCHUSDT","id":"10549500","side":"Sell","size":6.19},{"price":"1054.75","symbol":"BCHUSDT","id":"10547500","side":"Sell","size":8.48},{"price":"1054.85","symbol":"BCHUSDT","id":"10548500","side":"Sell","size":5.49},{"price":"1054.30","symbol":"BCHUSDT","id":"10543000","side":"Buy","size":16.390001}],"insert":[{"price":"1055.75","symbol":"BCHUSDT","id":"10557500","side":"Sell","size":6.33},{"price":"1055.85","symbol":"BCHUSDT","id":"10558500","side":"Sell","size":17.81},{"price":"1055.80","symbol":"BCHUSDT","id":"10558000","side":"Sell","size":10.42}]},"cross_seq":"864132015","timestamp_e6":"1618677787311753"}
1618677787.6901429: {"topic":"orderBookL2_25.LTCUSDT","type":"delta","data":{"delete":[{"price":"313.19","symbol":"LTCUSDT","id":"3131900","side":"Sell"},{"price":"312.83","symbol":"LTCUSDT","id":"3128300","side":"Buy"},{"price":"312.82","symbol":"LTCUSDT","id":"3128200","side":"Buy"}],"update":[{"price":"312.81","symbol":"LTCUSDT","id":"3128100","side":"Buy","size":45.8},{"price":"312.65","symbol":"LTCUSDT","id":"3126500","side":"Buy","size":83.2},{"price":"312.76","symbol":"LTCUSDT","id":"3127600","side":"Buy","size":78.1},{"price":"312.96","symbol":"LTCUSDT","id":"3129600","side":"Sell","size":63.3},{"price":"312.95","symbol":"LTCUSDT","id":"3129500","side":"Sell","size":57.3}],"insert":[{"price":"312.59","symbol":"LTCUSDT","id":"3125900","side":"Buy","size":74.700005},{"price":"312.58","symbol":"LTCUSDT","id":"3125800","side":"Buy","size":27.1},{"price":"312.89","symbol":"LTCUSDT","id":"3128900","side":"Sell","size":1.5}]},"cross_seq":"1684521996","timestamp_e6":"1618677787317960"}
1618677787.6902132: {"topic":"orderBookL2_25.DOTUSDT","type":"delta","data":{"delete":[],"update":[{"price":"43.495","symbol":"DOTUSDT","id":"434950","side":"Buy","size":379.7},{"price":"43.530","symbol":"DOTUSDT","id":"435300","side":"Sell","size":421.4}],"insert":[]},"cross_seq":"916952983","timestamp_e6":"1618677787322457"}
1618677787.690239: {"topic":"orderBookL2_25.ADAUSDT","type":"delta","data":{"delete":[],"update":[{"price":"1.3859","symbol":"ADAUSDT","id":"13859","side":"Buy","size":4267},{"price":"1.3854","symbol":"ADAUSDT","id":"13854","side":"Buy","size":6666}],"insert":[]},"cross_seq":"916952983","timestamp_e6":"1618677787322339"}
1618677787.690263: {"topic":"orderBookL2_25.ETHUSDT","type":"delta","data":{"delete":[],"update":[{"price":"2365.20","symbol":"ETHUSDT","id":"23652000","side":"Sell","size":2.12},{"price":"2364.60","symbol":"ETHUSDT","id":"23646000","side":"Buy","size":79.13},{"price":"2364.70","symbol":"ETHUSDT","id":"23647000","side":"Buy","size":84.53},{"price":"2365.10","symbol":"ETHUSDT","id":"23651000","side":"Sell","size":40.99},{"price":"2364.75","symbol":"ETHUSDT","id":"23647500","side":"Buy","size":148.77},{"price":"2364.65","symbol":"ETHUSDT","id":"23646500","side":"Buy","size":96.77},{"price":"2364.55","symbol":"ETHUSDT","id":"23645500","side":"Buy","size":42.08},{"price":"2364.80","symbol":"ETHUSDT","id":"23648000","side":"Buy","size":118.28},{"price":"2365.15","symbol":"ETHUSDT","id":"23651500","side":"Sell","size":38.329998},{"price":"2364.95","symbol":"ETHUSDT","id":"23649500","side":"Sell","size":154.24},{"price":"2365.05","symbol":"ETHUSDT","id":"23650500","side":"Sell","size":56.06},{"price":"2365.00","symbol":"ETHUSDT","id":"23650000","side":"Sell","size":65.549995}],"insert":[]},"cross_seq":"1800546214","timestamp_e6":"1618677787327596"}
1618677787.6903229: {"topic":"orderBookL2_25.BCHUSDT","type":"delta","data":{"delete":[{"price":"1054.70","symbol":"BCHUSDT","id":"10547000","side":"Sell"},{"price":"1055.35","symbol":"BCHUSDT","id":"10553500","side":"Sell"},{"price":"1054.65","symbol":"BCHUSDT","id":"10546500","side":"Sell"}],"update":[{"price":"1055.40","symbol":"BCHUSDT","id":"10554000","side":"Sell","size":5.89},{"price":"1055.25","symbol":"BCHUSDT","id":"10552500","side":"Sell","size":12.48},{"price":"1055.45","symbol":"BCHUSDT","id":"10554500","side":"Sell","size":6.19},{"price":"1055.30","symbol":"BCHUSDT","id":"10553000","side":"Sell","size":10.21}],"insert":[{"price":"1055.90","symbol":"BCHUSDT","id":"10559000","side":"Sell","size":5.32},{"price":"1055.95","symbol":"BCHUSDT","id":"10559500","side":"Sell","size":29.04},{"price":"1056.00","symbol":"BCHUSDT","id":"10560000","side":"Sell","size":8.19}]},"cross_seq":"864132039","timestamp_e6":"1618677787330074"}
