1618677813.2414699: {"topic":"orderBookL2_25.EOSUSD","type":"delta","data":{"delete":[],"update":[{"price":"7.973","symbol":"EOSUSD","id":79730,"side":"Buy","size":83466},{"price":"7.971","symbol":"EOSUSD","id":79710,"side":"Buy","size":70842},{"price":"7.969","symbol":"EOSUSD","id":79690,"side":"Buy","size":48737},{"price":"7.974","symbol":"EOSUSD","id":79740,"side":"Buy","size":95994},{"price":"7.968","symbol":"EOSUSD","id":79680,"side":"Buy","size":49731},{"price":"7.970","symbol":"EOSUSD","id":79700,"side":"Buy","size":61898}],"insert":[],"transactTimeE6":0},"cross_seq":1225778903,"timestamp_e6":1618677813158132}
1618677813.262613: {"topic":"orderBookL2_25.BTCUSD","type":"delta","data":{"delete":[],"update":[{"price":"60622.50","symbol":"BTCUSD","id":606225000,"side":"Buy","size":12764313}],"insert":[],"transactTimeE6":0},"cross_seq":5938958502,"timestamp_e6":1618677813178019}
1618677813.262723: {"topic":"orderBookL2_25.EOSUSD","type":"delta","data":{"delete":[],"update":[{"price":"7.982","symbol":"EOSUSD","id":79820,"side":"Sell","size":17295}],"insert":[],"transactTimeE6":0},"cross_seq":1225778904,"timestamp_e6":1618677813178078}
1618677813.283103: {"topic":"orderBookL2_25.EOSUSD","type":"delta","data":{"delete":[],"update":[{"price":"7.988","symbol":"EOSUSD","id":79880,"side":"Sell","size":40254}],"insert":[],"transactTimeE6":0},"cross_seq":1225778907,"timestamp_e6":1618677813198113}
1618677813.3032398: {"topic":"orderBookL2_25.EOSUSD","type":"delta","data":{"delete":[],"update":[{"price":"7.978","symbol":"EOSUSD","id":79780,"side":"Buy","size":79905}],"insert":[],"transactTimeE6":0},"cross_seq":1225778908,"timestamp_e6":1618677813218771}
1618677813.4216058: {"topic":"orderBookL2_25.EOSUSD","type":"delta","data":{"delete":[{"price":"7.977","symbol":"EOSUSD","id":79770,"side":"Buy"}],"update":[],"insert":[{"price":"7.975","symbol":"EOSUSD","id":79750,"side":"Buy","size":1615}],"transactTimeE6":0},"cross_seq":1225778909,"timestamp_e6":1618677813338116}
1618677813.44281: {"topic":"orderBookL2_25.EOSUSD","type":"delta","data":{"delete":[],"update":[{"price":"7.979","symbol":"EOSUSD","id":79790,"side":"Sell","size":10007},{"price":"7.982","symbol":"EOSUSD","id":79820,"side":"Sell","size":16629}],"insert":[],"transactTimeE6":0},"cross_seq":1225778911,"timestamp_e6":1618677813358689}
1618677813.481029: {"topic":"orderBookL2_25.BTCUSD","type":"delta","data":{"delete":[],"update":[{"price":"60622.50","symbol":"BTCUSD","id":606225000,"side":"Buy","size":12774313}],"insert":[],"transactTimeE6":0},"cross_seq":5938958511,"timestamp_e6":1618677813398202}
1618677813.6020968: {"topic":"orderBookL2_25.EOSUSD","type":"delta","data":{"delete":[{"price":"7.984","symbol":"EOSUSD","id":79840,"side":"Sell"}],"update":[{"price":"7.982","symbol":"EOSUSD","id":79820,"side":"Sell","size":22728},{"price":"7.985","symbol":"EOSUSD","id":79850,"side":"Sell","size":95545},{"price":"7.966","symbol":"EOSUSD","id":79660,"side":"Buy","size":19988},{"price":"7.983","symbol":"EOSUSD","id":79830,"side":"Sell","size":71532},{"price":"7.968","symbol":"EOSUSD","id":79680,"side":"Buy","size":34246}],"insert":[{"price":"8.004","symbol":"EOSUSD","id":80040,"side":"Sell","size":146362}],"transactTimeE6":0},"cross_seq":1225778917,"timestamp_e6":1618677813518128}
1618677813.681386: {"topic":"orderBookL2_25.BTCUSD","type":"delta","data":{"delete":[],"update":[{"price":"60611.00","symbol":"BTCUSD","id":606110000,"side":"Buy","size":2127}],"insert":[],"transactTimeE6":0},"cross_seq":5938958513,"timestamp_e6":1618677813597390}
1618677813.720997: {"topic":"orderBookL2_25.EOSUSD","type":"delta","data":{"delete":[{"price":"8.004","symbol":"EOSUSD","id":80040,"side":"Sell"}],"update":[{"price":"7.985","symbol":"EOSUSD","id":79850,"side":"Sell","size":97267},{"price":"7.970","symbol":"EOSUSD","id":79700,"side":"Buy","size":72091},{"price":"7.967","symbol":"EOSUSD","id":79670,"side":"Buy","size":41571},{"price":"7.968","symbol":"EOSUSD","id":79680,"side":"Buy","size":42564},{"price":"7.966","symbol":"EOSUSD","id":79660,"side":"Buy","size":36379}],"insert":[{"price":"7.984","symbol":"EOSUSD","id":79840,"side":"Sell","size":12810}],"transactTimeE6":0},"cross_seq":1225778923,"timestamp_e6":1618677813638106}
1618677813.779613: {"topic":"orderBookL2_25.BTCUSD","type":"delta","data":{"delete":[],"update":[{"price":"60628.00","symbol":"BTCUSD","id":606280000,"side":"Sell","size":190139}],"insert":[],"transactTimeE6":0},"cross_seq":5938958514,"timestamp_e6":1618677813697396}
1618677813.801078: {"topic":"orderBookL2_25.BTCUSD","type":"delta","data":{"delete":[],"update":[{"price":"60622.50","symbol":"BTCUSD","id":606225000,"side":"Buy","size":12764303}],"insert":[],"transactTimeE6":0},"cross_seq":5938958516,"timestamp_e6":1618677813718201}
1618677813.862171: {"topic":"orderBookL2_25.BTCUSD","type":"delta","data":{"delete":[],"update":[{"price":"60624.00","symbol":"BTCUSD","id":606240000,"side":"Sell","size":182042},{"price":"60622.50","symbol":"BTCUSD","id":606225000,"side":"Buy","size":12764299}],"insert":[],"transactTimeE6":0},"cross_seq":5938958519,"timestamp_e6":1618677813777969}
1618677813.863853: {"topic":"orderBookL2_25.EOSUSD","type":"delta","data":{"delete":[],"update":[{"price":"7.967","symbol":"EOSUSD","id":79670,"side":"Buy","size":46816}],"insert":[],"transactTimeE6":0},"cross_seq":1225778925,"timestamp_e6":1618677813778158}
1618677813.885761: {"topic":"orderBookL2_25.BTCUSD","type":"delta","data":{"delete":[],"update":[{"price":"60622.50","symbol":"BTCUSD","id":606225000,"side":"Buy","size":12764309}],"insert":[],"transactTimeE6":0},"cross_seq":5938958520,"timestamp_e6":1618677813798071}
1618677813.907913: {"topic":"orderBookL2_25.BTCUSD","type":"delta","data":{"delete":[],"update":[{"price":"60622.50","symbol":"BTCUSD","id":606225000,"side":"Buy","size":12774309},{"price":"60622.00","symbol":"BTCUSD","id":606220000,"side":"Buy","size":16093}],"insert":[],"transactTimeE6":0},"cross_seq":5938958524,"timestamp_e6":1618677813818010}
1618677813.984638: {"topic":"orderBookL2_25.BTCUSD","type":"delta","data":{"delete":[],"update":[{"price":"60623.00","symbol":"BTCUSD","id":606230000,"side":"Sell","size":1674094},{"price":"60611.50","symbol":"BTCUSD","id":606115000,"side":"Buy","size":25}],"insert":[],"transactTimeE6":0},"cross_seq":5938958526,"timestamp_e6":1618677813898056}
1618677814.075517: {"topic":"trade.BTCUSD","data":[{"trade_time_ms":1618677813877,"timestamp":"2021-04-17T16:43:33.000Z","symbol":"BTCUSD","side":"Buy","size":217,"price":60623,"tick_direction":"ZeroPlusTick","trade_id":"01131948-7340-566f-9367-68d486f87da5","cross_seq":5938958526}]}
1618677814.075594: {"topic":"orderBookL2_25.EOSUSD","type":"delta","data":{"delete":[],"update":[{"price":"7.969","symbol":"EOSUSD","id":79690,"side":"Buy","size":56703},{"price":"7.992","symbol":"EOSUSD","id":79920,"side":"Sell","size":62563},{"price":"7.973","symbol":"EOSUSD","id":79730,"side":"Buy","size":40052},{"price":"7.990","symbol":"EOSUSD","id":79900,"side":"Sell","size":84226}],"insert":[],"transactTimeE6":0},"cross_seq":1225778930,"timestamp_e6":1618677813978112}
1618677814.1899352: {"topic":"orderBookL2_25.EOSUSD","type":"delta","data":{"delete":[],"update":[{"price":"7.992","symbol":"EOSUSD","id":79920,"side":"Sell","size":72289},{"price":"7.973","symbol":"EOSUSD","id":79730,"side":"Buy","size":77928}],"insert":[],"transactTimeE6":0},"cross_seq":1225778932,"timestamp_e6":1618677814098115}
1618677814.208452: {"topic":"orderBookL2_25.EOSUSD","type":"delta","data":{"delete":[],"update":[{"price":"7.978","symbol":"EOSUSD","id":79780,"side":"Buy","size":93238}],"insert":[],"transactTimeE6":0},"cross_seq":1225778933,"timestamp_e6":1618677814118788}
1618677814.224166: {"topic":"orderBookL2_25.BTCUSD","type":"delta","data":{"delete":[],"update":[{"price":"60622.50","symbol":"BTCUSD","id":606225000,"side":"Buy","size":12774313}],"insert":[],"transactTimeE6":0},"cross_seq":5938958531,"timestamp_e6":1618677814138024}
1618677814.245528: {"topic":"orderBookL2_25.BTCUSD","type":"delta","data":{"delete":[],"update":[{"price":"60622.50","symbol":"BTCUSD","id":606225000,"side":"Buy","size":12775759}],"insert":[],"transactTimeE6":0},"cross_seq":5938958533,"timestamp_e6":1618677814157969}
1618677814.2645519: {"topic":"orderBookL2_25.EOSUSD","type":"delta","data":{"delete":[],"update":[{"price":"7.963","symbol":"EOSUSD","id":79630,"side":"Buy","size":41426},{"price":"7.969","symbol":"EOSUSD","id":79690,"side":"Buy","size":26766},{"price":"7.964","symbol":"EOSUSD","id":79640,"side":"Buy","size":33471},{"price":"7.967","symbol":"EOSUSD","id":79670,"side":"Buy","size":69259},{"price":"7.968","symbol":"EOSUSD","id":79680,"side":"Buy","size":57937},{"price":"7.965","symbol":"EOSUSD","id":79650,"side":"Buy","size":26145},{"price":"7.966","symbol":"EOSUSD","id":79660,"side":"Buy","size":54940},{"price":"7.970","symbol":"EOSUSD","id":79700,"side":"Buy","size":27405},{"price":"7.971","symbol":"EOSUSD","id":79710,"side":"Buy","size":27268}],"insert":[],"transactTimeE6":0},"cross_seq":1225778957,"timestamp_e6":1618677814178122}
1618677814.361689: {"topic":"orderBookL2_25.EOSUSD","type":"delta","data":{"delete":[],"update":[{"price":"7.965","symbol":"EOSUSD","id":79650,"side":"Buy","size":48756},{"price":"7.964","symbol":"EOSUSD","id":79640,"side":"Buy","size":52475}],"insert":[],"transactTimeE6":0},"cross_seq":1225778961,"timestamp_e6":1618677814278180}
1618677814.504986: {"topic":"orderBookL2_25.EOSUSD","type":"delta","data":{"delete":[{"price":"7.984","symbol":"EOSUSD","id":79840,"side":"Sell"}],"update":[{"price":"7.985","symbol":"EOSUSD","id":79850,"side":"Sell","size":103420},{"price":"7.967","symbol":"EOSUSD","id":79670,"side":"Buy","size":63529},{"price":"7.963","symbol":"EOSUSD","id":79630,"side":"Buy","size":33396},{"price":"7.983","symbol":"EOSUSD","id":79830,"side":"Sell","size":61701}],"insert":[{"price":"8.004","symbol":"EOSUSD","id":80040,"side":"Sell","size":146362}],"transactTimeE6":0},"cross_seq":1225778966,"timestamp_e6":1618677814418107}
1618677814.550494: {"topic":"orderBookL2_25.BTCUSD","type":"delta","data":{"delete":[],"update":[{"price":"60623.00","symbol":"BTCUSD","id":606230000,"side":"Sell","size":1673374}],"insert":[],"transactTimeE6":0},"cross_seq":5938958543,"timestamp_e6":1618677814458101}
1618677814.56436: {"topic":"trade.BTCUSD","data":[{"trade_time_ms":1618677814450,"timestamp":"2021-04-17T16:43:34.000Z","symbol":"BTCUSD","side":"Buy","size":720,"price":60623,"tick_direction":"ZeroPlusTick","trade_id":"8b794496-fff0-58e8-a2b2-3c981acf43ce","cross_seq":5938958543}]}
1618677814.590108: {"topic":"orderBookL2_25.EOSUSD","type":"delta","data":{"delete":[],"update":[{"price":"7.990","symbol":"EOSUSD","id":79900,"side":"Sell","size":82114},{"price":"7.971","symbol":"EOSUSD","id":79710,"side":"Buy","size":35063}],"insert":[],"transactTimeE6":0},"cross_seq":1225778968,"timestamp_e6":1618677814498131}
1618677814.6029792: {"topic":"orderBookL2_25.BTCUSD","type":"delta","data":{"delete":[],"update":[{"price":"60622.50","symbol":"BTCUSD","id":606225000,"side":"Buy","size":12845759}],"insert":[],"transactTimeE6":0},"cross_seq":5938958544,"timestamp_e6":1618677814518057}
1618677814.6237729: {"topic":"orderBookL2_25.EOSUSD","type":"delta","data":{"delete":[{"price":"8.004","symbol":"EOSUSD","id":80040,"side":"Sell"}],"update":[{"price":"7.983","symbol":"EOSUSD","id":79830,"side":"Sell","size":65602},{"price":"7.963","symbol":"EOSUSD","id":79630,"side":"Buy","size":37731}],"insert":[{"price":"7.984","symbol":"EOSUSD","id":79840,"side":"Sell","size":8113}],"transactTimeE6":0},"cross_seq":1225778971,"timestamp_e6":1618677814538132}
1618677814.7269719: {"topic":"orderBookL2_25.BTCUSD","type":"delta","data":{"delete":[],"update":[{"price":"60623.00","symbol":"BTCUSD","id":606230000,"side":"Sell","size":1656621}],"insert":[],"transactTimeE6":0},"cross_seq":5938958546,"timestamp_e6":1618677814638297}
1618677814.74633: {"topic":"orderBookL2_25.EOSUSD","type":"delta","data":{"delete":[],"update":[{"price":"7.963","symbol":"EOSUSD","id":79630,"side":"Buy","size":27619}],"insert":[],"transactTimeE6":0},"cross_seq":1225778972,"timestamp_e6":1618677814658100}
1618677814.763631: {"topic":"trade.BTCUSD","data":[{"trade_time_ms":1618677814614,"timestamp":"2021-04-17T16:43:34.000Z","symbol":"BTCUSD","side":"Buy","size":16753,"price":60623,"tick_direction":"ZeroPlusTick","trade_id":"e5838c39-b3ae-5c1d-acdf-6c5064e053dc","cross_seq":5938958548}]}
1618677814.7696152: {"topic":"orderBookL2_25.BTCUSD","type":"delta","data":{"delete":[],"update":[{"price":"60618.00","symbol":"BTCUSD","id":606180000,"side":"Buy","size":1393},{"price":"60622.50","symbol":"BTCUSD","id":606225000,"side":"Buy","size":12845763}],"insert":[],"transactTimeE6":0},"cross_seq":5938958548,"timestamp_e6":1618677814678008}
1618677814.8476841: {"topic":"orderBookL2_25.EOSUSD","type":"delta","data":{"delete":[],"update":[{"price":"7.981","symbol":"EOSUSD","id":79810,"side":"Sell","size":20},{"price":"7.969","symbol":"EOSUSD","id":79690,"side":"Buy","size":67200},{"price":"7.964","symbol":"EOSUSD","id":79640,"side":"Buy","size":33471},{"price":"7.966","symbol":"EOSUSD","id":79660,"side":"Buy","size":38549},{"price":"7.968","symbol":"EOSUSD","id":79680,"side":"Buy","size":49743}],"insert":[],"transactTimeE6":0},"cross_seq":1225778977,"timestamp_e6":1618677814758102}
1618677814.8696399: {"topic":"orderBookL2_25.EOSUSD","type":"delta","data":{"delete":[{"price":"7.972","symbol":"EOSUSD","id":79720,"side":"Buy"}],"update":[{"price":"7.968","symbol":"EOSUSD","id":79680,"side":"Buy","size":57478},{"price":"7.973","symbol":"EOSUSD","id":79730,"side":"Buy","size":40052},{"price":"7.970","symbol":"EOSUSD","id":79700,"side":"Buy","size":41289}],"insert":[{"price":"7.951","symbol":"EOSUSD","id":79510,"side":"Buy","size":99333}],"transactTimeE6":0},"cross_seq":1225778982,"timestamp_e6":1618677814778209}
1618677814.8867688: {"topic":"orderBookL2_25.EOSUSD","type":"delta","data":{"delete":[],"update":[{"price":"7.978","symbol":"EOSUSD","id":79780,"side":"Buy","size":90650},{"price":"7.981","symbol":"EOSUSD","id":79810,"side":"Sell","size":19780},{"price":"7.964","symbol":"EOSUSD","id":79640,"side":"Buy","size":46663}],"insert":[],"transactTimeE6":0},"cross_seq":1225778985,"timestamp_e6":1618677814798888}
1618677814.9672709: {"topic":"orderBookL2_25.EOSUSD","type":"delta","data":{"delete":[],"update":[{"price":"7.967","symbol":"EOSUSD","id":79670,"side":"Buy","size":50406},{"price":"7.965","symbol":"EOSUSD","id":79650,"side":"Buy","size":26145},{"price":"7.970","symbol":"EOSUSD","id":79700,"side":"Buy","size":50189},{"price":"7.969","symbol":"EOSUSD","id":79690,"side":"Buy","size":26766}],"insert":[],"transactTimeE6":0},"cross_seq":1225778991,"timestamp_e6":1618677814878136}
1618677815.0031328: {"topic":"orderBookL2_25.BTCUSD","type":"delta","data":{"delete":[],"update":[{"price":"60622.50","symbol":"BTCUSD","id":606225000,"side":"Buy","size":12844567}],"insert":[],"transactTimeE6":0},"cross_seq":5938958552,"timestamp_e6":1618677814917979}
1618677815.003222: {"topic":"orderBookL2_25.EOSUSD","type":"delta","data":{"delete":[],"update":[{"price":"7.969","symbol":"EOSUSD","id":79690,"side":"Buy","size":62273},{"price":"7.965","symbol":"EOSUSD","id":79650,"side":"Buy","size":39886}],"insert":[],"transactTimeE6":0},"cross_seq":1225778993,"timestamp_e6":1618677814918143}
1618677815.062355: {"topic":"orderBookL2_25.BTCUSD","type":"delta","data":{"delete":[],"update":[{"price":"60622.00","symbol":"BTCUSD","id":606220000,"side":"Buy","size":34166},{"price":"60616.00","symbol":"BTCUSD","id":606160000,"side":"Buy","size":10013}],"insert":[],"transactTimeE6":0},"cross_seq":5938958554,"timestamp_e6":1618677814977469}
1618677815.082557: {"topic":"orderBookL2_25.EOSUSD","type":"delta","data":{"delete":[],"update":[{"price":"7.967","symbol":"EOSUSD","id":79670,"side":"Buy","size":42213},{"price":"7.989","symbol":"EOSUSD","id":79890,"side":"Sell","size":97106},{"price":"7.990","symbol":"EOSUSD","id":79900,"side":"Sell","size":77245},{"price":"7.968","symbol":"EOSUSD","id":79680,"side":"Buy","size":47389},{"price":"7.970","symbol":"EOSUSD","id":79700,"side":"Buy","size":64324},{"price":"7.991","symbol":"EOSUSD","id":79910,"side":"Sell","size":83292},{"price":"7.992","symbol":"EOSUSD","id":79920,"side":"Sell","size":76617}],"insert":[],"transactTimeE6":0},"cross_seq":1225779002,"timestamp_e6":1618677814998119}
1618677815.1215549: {"topic":"orderBookL2_25.BTCUSD","type":"delta","data":{"delete":[],"update":[{"price":"60625.50","symbol":"BTCUSD","id":606255000,"side":"Sell","size":43687},{"price":"60624.00","symbol":"BTCUSD","id":606240000,"side":"Sell","size":150508},{"price":"60624.50","symbol":"BTCUSD","id":606245000,"side":"Sell","size":723}],"insert":[],"transactTimeE6":0},"cross_seq":5938958563,"timestamp_e6":1618677815037368}
1618677815.203292: {"topic":"orderBookL2_25.EOSUSD","type":"delta","data":{"delete":[],"update":[{"price":"7.968","symbol":"EOSUSD","id":79680,"side":"Buy","size":54956},{"price":"7.989","symbol":"EOSUSD","id":79890,"side":"Sell","size":105737}],"insert":[],"transactTimeE6":0},"cross_seq":1225779004,"timestamp_e6":1618677815118101}
1618677815.222005: {"topic":"orderBookL2_25.BTCUSD","type":"delta","data":{"delete":[],"update":[{"price":"60623.00","symbol":"BTCUSD","id":606230000,"side":"Sell","size":1656611}],"insert":[],"transactTimeE6":0},"cross_seq":5938958566,"timestamp_e6":1618677815138262}
1618677815.259281: {"topic":"trade.BTCUSD","data":[{"trade_time_ms":1618677815129,"timestamp":"2021-04-17T16:43:35.000Z","symbol":"BTCUSD","side":"Buy","size":1,"price":60623,"tick_direction":"ZeroPlusTick","trade_id":"20b0ae78-8fab-54a3-891d-b8091af62e02","cross_seq":5938958566},{"trade_time_ms":1618677815129,"timestamp":"2021-04-17T16:43:35.000Z","symbol":"BTCUSD","side":"Buy","size":9,"price":60623,"tick_direction":"ZeroPlusTick","trade_id":"f7203d51-1422-5c5a-8e19-348f60fd482b","cross_seq":5938958566}]}
1618677815.288036: {"topic":"orderBookL2_25.BTCUSD","type":"delta","data":{"delete":[],"update":[{"price":"60622.50","symbol":"BTCUSD","id":606225000,"side":"Buy","size":12847106}],"insert":[],"transactTimeE6":0},"cross_seq":5938958570,"timestamp_e6":1618677815197983}
1618677815.34215: {"topic":"orderBookL2_25.BTCUSD","type":"delta","data":{"delete":[],"update":[{"price":"60628.00","symbol":"BTCUSD","id":606280000,"side":"Sell","size":190140}],"insert":[],"transactTimeE6":0},"cross_seq":5938958574,"timestamp_e6":1618677815257516}
1618677815.3638542: {"topic":"orderBookL2_25.BTCUSD","type":"delta","data":{"delete":[],"update":[{"price":"60622.50","symbol":"BTCUSD","id":606225000,"side":"Buy","size":12846383}],"insert":[],"transactTimeE6":0},"cross_seq":5938958575,"timestamp_e6":1618677815278039}
1618677815.421275: {"topic":"orderBookL2_25.EOSUSD","type":"delta","data":{"delete":[],"update":[{"price":"7.966","symbol":"EOSUSD","id":79660,"side":"Buy","size":19988},{"price":"7.971","symbol":"EOSUSD","id":79710,"side":"Buy","size":76667},{"price":"7.968","symbol":"EOSUSD","id":79680,"side":"Buy","size":48888}],"insert":[],"transactTimeE6":0},"cross_seq":1225779007,"timestamp_e6":1618677815338162}
1618677815.4213812: {"topic":"orderBookL2_25.BTCUSD","type":"delta","data":{"delete":[],"update":[{"price":"60622.50","symbol":"BTCUSD","id":606225000,"side":"Buy","size":12846387},{"price":"60618.00","symbol":"BTCUSD","id":606180000,"side":"Buy","size":1396}],"insert":[],"transactTimeE6":0},"cross_seq":5938958579,"timestamp_e6":1618677815338030}
1618677815.46128: {"topic":"orderBookL2_25.BTCUSD","type":"delta","data":{"delete":[],"update":[{"price":"60622.50","symbol":"BTCUSD","id":606225000,"side":"Buy","size":12845664}],"insert":[],"transactTimeE6":0},"cross_seq":5938958580,"timestamp_e6":1618677815378024}
1618677815.481559: {"topic":"orderBookL2_25.EOSUSD","type":"delta","data":{"delete":[],"update":[{"price":"7.978","symbol":"EOSUSD","id":79780,"side":"Buy","size":142081}],"insert":[],"transactTimeE6":0},"cross_seq":1225779008,"timestamp_e6":1618677815398784}
1618677815.501655: {"topic":"orderBookL2_25.BTCUSD","type":"delta","data":{"delete":[],"update":[{"price":"60622.50","symbol":"BTCUSD","id":606225000,"side":"Buy","size":12845659}],"insert":[],"transactTimeE6":0},"cross_seq":5938958583,"timestamp_e6":1618677815418000}
1618677815.5209038: {"topic":"orderBookL2_25.EOSUSD","type":"delta","data":{"delete":[],"update":[{"price":"7.984","symbol":"EOSUSD","id":79840,"side":"Sell","size":14836},{"price":"7.985","symbol":"EOSUSD","id":79850,"side":"Sell","size":97132},{"price":"7.968","symbol":"EOSUSD","id":79680,"side":"Buy","size":40570},{"price":"7.983","symbol":"EOSUSD","id":79830,"side":"Sell","size":69350},{"price":"7.966","symbol":"EOSUSD","id":79660,"side":"Buy","size":36706}],"insert":[],"transactTimeE6":0},"cross_seq":1225779013,"timestamp_e6":1618677815438132}
1618677815.542176: {"topic":"orderBookL2_25.BTCUSD","type":"delta","data":{"delete":[],"update":[{"price":"60622.50","symbol":"BTCUSD","id":606225000,"side":"Buy","size":12835649}],"insert":[],"transactTimeE6":0},"cross_seq":5938958587,"timestamp_e6":1618677815457975}
1618677815.623044: {"topic":"orderBookL2_25.BTCUSD","type":"delta","data":{"delete":[],"update":[{"price":"60623.00","symbol":"BTCUSD","id":606230000,"side":"Sell","size":1656511}],"insert":[],"transactTimeE6":0},"cross_seq":5938958589,"timestamp_e6":1618677815538065}
1618677815.6413271: {"topic":"orderBookL2_25.EOSUSD","type":"delta","data":{"delete":[{"price":"7.980","symbol":"EOSUSD","id":79800,"side":"Sell"}],"update":[{"price":"7.966","symbol":"EOSUSD","id":79660,"side":"Buy","size":19988},{"price":"7.970","symbol":"EOSUSD","id":79700,"side":"Buy","size":28019},{"price":"7.968","symbol":"EOSUSD","id":79680,"side":"Buy","size":46744},{"price":"7.969","symbol":"EOSUSD","id":79690,"side":"Buy","size":26766}],"insert":[{"price":"8.004","symbol":"EOSUSD","id":80040,"side":"Sell","size":146362}],"transactTimeE6":0},"cross_seq":1225779020,"timestamp_e6":1618677815558170}
1618677815.660178: {"topic":"trade.BTCUSD","data":[{"trade_time_ms":1618677815514,"timestamp":"2021-04-17T16:43:35.000Z","symbol":"BTCUSD","side":"Buy","size":100,"price":60623,"tick_direction":"ZeroPlusTick","trade_id":"0c69e41b-fe9d-5796-9c70-69597a070ce8","cross_seq":5938958590}]}
1618677815.782352: {"topic":"orderBookL2_25.EOSUSD","type":"delta","data":{"delete":[{"price":"8.004","symbol":"EOSUSD","id":80040,"side":"Sell"}],"update":[{"price":"7.966","symbol":"EOSUSD","id":79660,"side":"Buy","size":34834},{"price":"7.970","symbol":"EOSUSD","id":79700,"side":"Buy","size":54749},{"price":"7.969","symbol":"EOSUSD","id":79690,"side":"Buy","size":57994},{"price":"7.971","symbol":"EOSUSD","id":79710,"side":"Buy","size":35063},{"price":"7.985","symbol":"EOSUSD","id":79850,"side":"Sell","size":99132}],"insert":[{"price":"7.980","symbol":"EOSUSD","id":79800,"side":"Sell","size":32028}],"transactTimeE6":0},"cross_seq":1225779026,"timestamp_e6":1618677815698140}
1618677815.80214: {"topic":"orderBookL2_25.BTCUSD","type":"delta","data":{"delete":[{"price":"60605.50","symbol":"BTCUSD","id":606055000,"side":"Buy"}],"update":[{"price":"60618.50","symbol":"BTCUSD","id":606185000,"side":"Buy","size":11546},{"price":"60608.00","symbol":"BTCUSD","id":606080000,"side":"Buy","size":200}],"insert":[{"price":"60613.50","symbol":"BTCUSD","id":606135000,"side":"Buy","size":2500}],"transactTimeE6":0},"cross_seq":5938958596,"timestamp_e6":1618677815717371}
1618677815.841815: {"topic":"orderBookL2_25.EOSUSD","type":"delta","data":{"delete":[],"update":[{"price":"7.966","symbol":"EOSUSD","id":79660,"side":"Buy","size":14846}],"insert":[],"transactTimeE6":0},"cross_seq":1225779027,"timestamp_e6":1618677815758111}
1618677815.901808: {"topic":"orderBookL2_25.BTCUSD","type":"delta","data":{"delete":[],"update":[{"price":"60622.50","symbol":"BTCUSD","id":606225000,"side":"Buy","size":12835645},{"price":"60622.00","symbol":"BTCUSD","id":606220000,"side":"Buy","size":34167}],"insert":[],"transactTimeE6":0},"cross_seq":5938958599,"timestamp_e6":1618677815817999}
1618677815.901917: {"topic":"orderBookL2_25.EOSUSD","type":"delta","data":{"delete":[],"update":[{"price":"7.971","symbol":"EOSUSD","id":79710,"side":"Buy","size":68074},{"price":"7.968","symbol":"EOSUSD","id":79680,"side":"Buy","size":31371}],"insert":[],"transactTimeE6":0},"cross_seq":1225779029,"timestamp_e6":1618677815818131}
1618677815.98149: {"topic":"orderBookL2_25.EOSUSD","type":"delta","data":{"delete":[],"update":[{"price":"7.966","symbol":"EOSUSD","id":79660,"side":"Buy","size":30002},{"price":"7.991","symbol":"EOSUSD","id":79910,"side":"Sell","size":91051}],"insert":[],"transactTimeE6":0},"cross_seq":1225779031,"timestamp_e6":1618677815898143}
1618677816.001023: {"topic":"orderBookL2_25.BTCUSD","type":"delta","data":{"delete":[],"update":[{"price":"60622.50","symbol":"BTCUSD","id":606225000,"side":"Buy","size":12836205}],"insert":[],"transactTimeE6":0},"cross_seq":5938958600,"timestamp_e6":1618677815918013}
1618677816.0215712: {"topic":"orderBookL2_25.EOSUSD","type":"delta","data":{"delete":[],"update":[{"price":"7.968","symbol":"EOSUSD","id":79680,"side":"Buy","size":42689}],"insert":[],"transactTimeE6":0},"cross_seq":1225779032,"timestamp_e6":1618677815938126}
1618677816.0418: {"topic":"orderBookL2_25.BTCUSD","type":"delta","data":{"delete":[],"update":[{"price":"60622.50","symbol":"BTCUSD","id":606225000,"side":"Buy","size":12766605}],"insert":[],"transactTimeE6":0},"cross_seq":5938958603,"timestamp_e6":1618677815958051}
1618677816.101948: {"topic":"orderBookL2_25.EOSUSD","type":"delta","data":{"delete":[],"update":[{"price":"7.968","symbol":"EOSUSD","id":79680,"side":"Buy","size":50328},{"price":"7.967","symbol":"EOSUSD","id":79670,"side":"Buy","size":22463}],"insert":[],"transactTimeE6":0},"cross_seq":1225779034,"timestamp_e6":1618677816018137}
1618677816.1020539: {"topic":"orderBookL2_25.BTCUSD","type":"delta","data":{"delete":[],"update":[{"price":"60623.00","symbol":"BTCUSD","id":606230000,"side":"Sell","size":1632511}],"insert":[],"transactTimeE6":0},"cross_seq":5938958604,"timestamp_e6":1618677816018019}
1618677816.1228108: {"topic":"orderBookL2_25.BTCUSD","type":"delta","data":{"delete":[],"update":[{"price":"60623.00","symbol":"BTCUSD","id":606230000,"side":"Sell","size":1632505},{"price":"60625.00","symbol":"BTCUSD","id":606250000,"side":"Sell","size":131902},{"price":"60625.50","symbol":"BTCUSD","id":606255000,"side":"Sell","size":66603},{"price":"60624.50","symbol":"BTCUSD","id":606245000,"side":"Sell","size":55811}],"insert":[],"transactTimeE6":0},"cross_seq":5938958614,"timestamp_e6":1618677816038005}
1618677816.1567738: {"topic":"trade.BTCUSD","data":[{"trade_time_ms":1618677816016,"timestamp":"2021-04-17T16:43:36.000Z","symbol":"BTCUSD","side":"Buy","size":6,"price":60623,"tick_direction":"ZeroPlusTick","trade_id":"adc5699e-2462-56eb-9d22-779d16b38156","cross_seq":5938958615}]}
1618677816.20114: {"topic":"orderBookL2_25.BTCUSD","type":"delta","data":{"delete":[],"update":[{"price":"60623.00","symbol":"BTCUSD","id":606230000,"side":"Sell","size":1656505}],"insert":[],"transactTimeE6":0},"cross_seq":5938958616,"timestamp_e6":1618677816117933}
1618677816.222325: {"topic":"orderBookL2_25.EOSUSD","type":"delta","data":{"delete":[],"update":[{"price":"7.969","symbol":"EOSUSD","id":79690,"side":"Buy","size":26766},{"price":"7.967","symbol":"EOSUSD","id":79670,"side":"Buy","size":38819},{"price":"7.966","symbol":"EOSUSD","id":79660,"side":"Buy","size":14846},{"price":"7.970","symbol":"EOSUSD","id":79700,"side":"Buy","size":62376}],"insert":[],"transactTimeE6":0},"cross_seq":1225779038,"timestamp_e6":1618677816138111}
1618677816.2415202: {"topic":"orderBookL2_25.BTCUSD","type":"delta","data":{"delete":[],"update":[{"price":"60622.50","symbol":"BTCUSD","id":606225000,"side":"Buy","size":12836605}],"insert":[],"transactTimeE6":0},"cross_seq":5938958618,"timestamp_e6":1618677816157963}
1618677816.263613: {"topic":"orderBookL2_25.EOSUSD","type":"delta","data":{"delete":[],"update":[{"price":"7.978","symbol":"EOSUSD","id":79780,"side":"Buy","size":90650},{"price":"7.969","symbol":"EOSUSD","id":79690,"side":"Buy","size":56186}],"insert":[],"transactTimeE6":0},"cross_seq":1225779040,"timestamp_e6":1618677816178722}
1618677816.3417332: {"topic":"orderBookL2_25.BTCUSD","type":"delta","data":{"delete":[],"update":[{"price":"60622.50","symbol":"BTCUSD","id":606225000,"side":"Buy","size":12836609}],"insert":[],"transactTimeE6":0},"cross_seq":5938958623,"timestamp_e6":1618677816258022}
1618677816.360866: {"topic":"orderBookL2_25.EOSUSD","type":"delta","data":{"delete":[],"update":[{"price":"7.966","symbol":"EOSUSD","id":79660,"side":"Buy","size":28737}],"insert":[],"transactTimeE6":0},"cross_seq":1225779041,"timestamp_e6":1618677816278108}
1618677816.3804538: {"topic":"orderBookL2_25.BTCUSD","type":"delta","data":{"delete":[],"update":[{"price":"60622.00","symbol":"BTCUSD","id":606220000,"side":"Buy","size":34166}],"insert":[],"transactTimeE6":0},"cross_seq":5938958624,"timestamp_e6":1618677816297383}
1618677816.4225762: {"topic":"orderBookL2_25.BTCUSD","type":"delta","data":{"delete":[],"update":[{"price":"60622.00","symbol":"BTCUSD","id":606220000,"side":"Buy","size":31166},{"price":"60622.50","symbol":"BTCUSD","id":606225000,"side":"Buy","size":12836512}],"insert":[],"transactTimeE6":0},"cross_seq":5938958626,"timestamp_e6":1618677816338047}
1618677816.460866: {"topic":"trade.BTCUSD","data":[{"trade_time_ms":1618677816319,"timestamp":"2021-04-17T16:43:36.000Z","symbol":"BTCUSD","side":"Sell","size":97,"price":60622.5,"tick_direction":"MinusTick","trade_id":"413bca3a-34a8-50aa-a2ae-47ad720be505","cross_seq":5938958626}]}
1618677816.500978: {"topic":"orderBookL2_25.BTCUSD","type":"delta","data":{"delete":[],"update":[{"price":"60629.50","symbol":"BTCUSD","id":606295000,"side":"Sell","size":152682}],"insert":[],"transactTimeE6":0},"cross_seq":5938958627,"timestamp_e6":1618677816417381}


