wss://stream.bybit.com/realtime <-> 1618677785.489609
wss://stream.bybit.com/realtime <- 1618677786.5112152: {"op":"subscribe","args":["trade.EOSUSD"]}
wss://stream.bybit.com/realtime <- 1618677786.5113149: {"op":"subscribe","args":["trade.BTCUSD"]}
wss://stream.bybit.com/realtime <- 1618677786.51142: {"op":"subscribe","args":["orderBookL2_25.EOSUSD"]}
wss://stream.bybit.com/realtime <- 1618677786.511505: {"op":"subscribe","args":["orderBookL2_25.BTCUSD"]}
1618677786.801375: {"success":true,"ret_msg":"","conn_id":"95a3336b-365a-4fad-9540-ede1104f1260","request":{"op":"subscribe","args":["trade.EOSUSD"]}}
1618677786.801381: {"success":true,"ret_msg":"","conn_id":"95a3336b-365a-4fad-9540-ede1104f1260","request":{"op":"subscribe","args":["trade.BTCUSD"]}}
1618677786.986287: {"topic":"orderBookL2_25.EOSUSD","type":"snapshot","data":[{"price":"7.943","symbol":"EOSUSD","id":79430,"side":"Buy","size":154219},{"price":"7.944","symbol":"EOSUSD","id":79440,"side":"Buy","size":106734},{"price":"7.945","symbol":"EOSUSD","id":79450,"side":"Buy","size":19617},{"price":"7.946","symbol":"EOSUSD","id":79460,"side":"Buy","size":96718},{"price":"7.947","symbol":"EOSUSD","id":79470,"side":"Buy","size":100800},{"price":"7.948","symbol":"EOSUSD","id":79480,"side":"Buy","size":73532},{"price":"7.949","symbol":"EOSUSD","id":79490,"side":"Buy","size":138507},{"price":"7.950","symbol":"EOSUSD","id":79500,"side":"Buy","size":26783},{"price":"7.951","symbol":"EOSUSD","id":79510,"side":"Buy","size":99333},{"price":"7.952","symbol":"EOSUSD","id":79520,"side":"Buy","size":112386},{"price":"7.953","symbol":"EOSUSD","id":79530,"side":"Buy","size":19357},{"price":"7.954","symbol":"EOSUSD","id":79540,"side":"Buy","size":80226},{"price":"7.955","symbol":"EOSUSD","id":79550,"side":"Buy","size":91610},{"price":"7.956","symbol":"EOSUSD","id":79560,"side":"Buy","size":115503},{"price":"7.957","symbol":"EOSUSD","id":79570,"side":"Buy","size":62362},{"price":"7.958","symbol":"EOSUSD","id":79580,"side":"Buy","size":9492},{"price":"7.959","symbol":"EOSUSD","id":79590,"side":"Buy","size":10693},{"price":"7.960","symbol":"EOSUSD","id":79600,"side":"Buy","size":32451},{"price":"7.961","symbol":"EOSUSD","id":79610,"side":"Buy","size":63573},{"price":"7.962","symbol":"EOSUSD","id":79620,"side":"Buy","size":37887},{"price":"7.963","symbol":"EOSUSD","id":79630,"side":"Buy","size":20},{"price":"7.965","symbol":"EOSUSD","id":79650,"side":"Buy","size":20},{"price":"7.967","symbol":"EOSUSD","id":79670,"side":"Buy","size":1615},{"price":"7.968","symbol":"EOSUSD","id":79680,"side":"Buy","size":100},{"price":"7.971","symbol":"EOSUSD","id":79710,"side":"Buy","size":41516},{"price":"7.972","symbol":"EOSUSD","id":79720,"side":"Sell","size":138299},{"price":"7.973","symbol":"EOSUSD","id":79730,"side":"Sell","size":59928},{"price":"7.974","symbol":"EOSUSD","id":79740,"side":"Sell","size":62266},{"price":"7.975","symbol":"EOSUSD","id":79750,"side":"Sell","size":41699},{"price":"7.976","symbol":"EOSUSD","id":79760,"side":"Sell","size":51172},{"price":"7.977","symbol":"EOSUSD","id":79770,"side":"Sell","size":37650},{"price":"7.978","symbol":"EOSUSD","id":79780,"side":"Sell","size":16338},{"price":"7.979","symbol":"EOSUSD","id":79790,"side":"Sell","size":19023},{"price":"7.980","symbol":"EOSUSD","id":79800,"side":"Sell","size":73575},{"price":"7.981","symbol":"EOSUSD","id":79810,"side":"Sell","size":55952},{"price":"7.982","symbol":"EOSUSD","id":79820,"side":"Sell","size":60220},{"price":"7.983","symbol":"EOSUSD","id":79830,"side":"Sell","size":182909},{"price":"7.984","symbol":"EOSUSD","id":79840,"side":"Sell","size":127175},{"price":"7.985","symbol":"EOSUSD","id":79850,"side":"Sell","size":79972},{"price":"7.986","symbol":"EOSUSD","id":79860,"side":"Sell","size":174362},{"price":"7.987","symbol":"EOSUSD","id":79870,"side":"Sell","size":112315},{"price":"7.988","symbol":"EOSUSD","id":79880,"side":"Sell","size":40359},{"price":"7.989","symbol":"EOSUSD","id":79890,"side":"Sell","size":21831},{"price":"7.990","symbol":"EOSUSD","id":79900,"side":"Sell","size":74440},{"price":"7.991","symbol":"EOSUSD","id":79910,"side":"Sell","size":84346},{"price":"7.992","symbol":"EOSUSD","id":79920,"side":"Sell","size":26881},{"price":"7.993","symbol":"EOSUSD","id":79930,"side":"Sell","size":92135},{"price":"7.994","symbol":"EOSUSD","id":79940,"side":"Sell","size":97145},{"price":"7.995","symbol":"EOSUSD","id":79950,"side":"Sell","size":28016},{"price":"7.996","symbol":"EOSUSD","id":79960,"side":"Sell","size":39326}],"cross_seq":1225777224,"timestamp_e6":1618677786558146}
1618677786.9864519: {"topic":"orderBookL2_25.EOSUSD","type":"delta","data":{"delete":[],"update":[{"price":"7.971","symbol":"EOSUSD","id":79710,"side":"Buy","size":47766}],"insert":[],"transactTimeE6":0},"cross_seq":1225777225,"timestamp_e6":1618677786598877}
1618677786.986468: {"topic":"orderBookL2_25.EOSUSD","type":"delta","data":{"delete":[],"update":[{"price":"7.971","symbol":"EOSUSD","id":79710,"side":"Buy","size":41516}],"insert":[],"transactTimeE6":0},"cross_seq":1225777226,"timestamp_e6":1618677786618874}
1618677786.986479: {"success":true,"ret_msg":"","conn_id":"95a3336b-365a-4fad-9540-ede1104f1260","request":{"op":"subscribe","args":["orderBookL2_25.EOSUSD"]}}
1618677786.986486: {"topic":"orderBookL2_25.BTCUSD","type":"snapshot","data":[{"price":"60591.00","symbol":"BTCUSD","id":605910000,"side":"Buy","size":14431},{"price":"60591.50","symbol":"BTCUSD","id":605915000,"side":"Buy","size":6005},{"price":"60593.00","symbol":"BTCUSD","id":605930000,"side":"Buy","size":9733},{"price":"60595.50","symbol":"BTCUSD","id":605955000,"side":"Buy","size":10094},{"price":"60596.00","symbol":"BTCUSD","id":605960000,"side":"Buy","size":15},{"price":"60597.50","symbol":"BTCUSD","id":605975000,"side":"Buy","size":277826},{"price":"60598.00","symbol":"BTCUSD","id":605980000,"side":"Buy","size":56011},{"price":"60600.00","symbol":"BTCUSD","id":606000000,"side":"Buy","size":45},{"price":"60600.50","symbol":"BTCUSD","id":606005000,"side":"Buy","size":827},{"price":"60601.50","symbol":"BTCUSD","id":606015000,"side":"Buy","size":39},{"price":"60602.50","symbol":"BTCUSD","id":606025000,"side":"Buy","size":115},{"price":"60603.00","symbol":"BTCUSD","id":606030000,"side":"Buy","size":5570},{"price":"60604.00","symbol":"BTCUSD","id":606040000,"side":"Buy","size":6074},{"price":"60604.50","symbol":"BTCUSD","id":606045000,"side":"Buy","size":5419},{"price":"60605.00","symbol":"BTCUSD","id":606050000,"side":"Buy","size":183172},{"price":"60605.50","symbol":"BTCUSD","id":606055000,"side":"Buy","size":100098},{"price":"60606.00","symbol":"BTCUSD","id":606060000,"side":"Buy","size":5},{"price":"60608.00","symbol":"BTCUSD","id":606080000,"side":"Buy","size":200},{"price":"60609.00","symbol":"BTCUSD","id":606090000,"side":"Buy","size":2423},{"price":"60611.00","symbol":"BTCUSD","id":606110000,"side":"Buy","size":91487},{"price":"60611.50","symbol":"BTCUSD","id":606115000,"side":"Buy","size":217},{"price":"60614.50","symbol":"BTCUSD","id":606145000,"side":"Buy","size":150},{"price":"60615.50","symbol":"BTCUSD","id":606155000,"side":"Buy","size":7},{"price":"60616.00","symbol":"BTCUSD","id":606160000,"side":"Buy","size":1081392},{"price":"60616.50","symbol":"BTCUSD","id":606165000,"side":"Buy","size":7842400},{"price":"60617.00","symbol":"BTCUSD","id":606170000,"side":"Sell","size":4104899},{"price":"60617.50","symbol":"BTCUSD","id":606175000,"side":"Sell","size":156},{"price":"60618.00","symbol":"BTCUSD","id":606180000,"side":"Sell","size":11},{"price":"60619.00","symbol":"BTCUSD","id":606190000,"side":"Sell","size":4},{"price":"60620.00","symbol":"BTCUSD","id":606200000,"side":"Sell","size":1896},{"price":"60620.50","symbol":"BTCUSD","id":606205000,"side":"Sell","size":64},{"price":"60621.00","symbol":"BTCUSD","id":606210000,"side":"Sell","size":1015},{"price":"60621.50","symbol":"BTCUSD","id":606215000,"side":"Sell","size":272289},{"price":"60622.00","symbol":"BTCUSD","id":606220000,"side":"Sell","size":209718},{"price":"60622.50","symbol":"BTCUSD","id":606225000,"side":"Sell","size":152408},{"price":"60623.00","symbol":"BTCUSD","id":606230000,"side":"Sell","size":148237},{"price":"60623.50","symbol":"BTCUSD","id":606235000,"side":"Sell","size":101441},{"price":"60624.00","symbol":"BTCUSD","id":606240000,"side":"Sell","size":91071},{"price":"60624.50","symbol":"BTCUSD","id":606245000,"side":"Sell","size":67768},{"price":"60625.00","symbol":"BTCUSD","id":606250000,"side":"Sell","size":56648},{"price":"60625.50","symbol":"BTCUSD","id":606255000,"side":"Sell","size":99634},{"price":"60626.00","symbol":"BTCUSD","id":606260000,"side":"Sell","size":27324},{"price":"60626.50","symbol":"BTCUSD","id":606265000,"side":"Sell","size":96958},{"price":"60627.00","symbol":"BTCUSD","id":606270000,"side":"Sell","size":22203},{"price":"60627.50","symbol":"BTCUSD","id":606275000,"side":"Sell","size":112991},{"price":"60628.00","symbol":"BTCUSD","id":606280000,"side":"Sell","size":147838},{"price":"60628.50","symbol":"BTCUSD","id":606285000,"side":"Sell","size":95755},{"price":"60629.00","symbol":"BTCUSD","id":606290000,"side":"Sell","size":65412},{"price":"60629.50","symbol":"BTCUSD","id":606295000,"side":"Sell","size":152678},{"price":"60630.00","symbol":"BTCUSD","id":606300000,"side":"Sell","size":77065}],"cross_seq":5938954538,"timestamp_e6":1618677785357289}
1618677786.986641: {"topic":"orderBookL2_25.BTCUSD","type":"delta","data":{"delete":[],"update":[{"price":"60616.50","symbol":"BTCUSD","id":606165000,"side":"Buy","size":8163986}],"insert":[],"transactTimeE6":0},"cross_seq":5938954547,"timestamp_e6":1618677785397906}
1618677786.986655: {"topic":"orderBookL2_25.BTCUSD","type":"delta","data":{"delete":[],"update":[{"price":"60616.50","symbol":"BTCUSD","id":606165000,"side":"Buy","size":8173486}],"insert":[],"transactTimeE6":0},"cross_seq":5938954549,"timestamp_e6":1618677785417939}
1618677786.986666: {"topic":"orderBookL2_25.BTCUSD","type":"delta","data":{"delete":[],"update":[{"price":"60616.50","symbol":"BTCUSD","id":606165000,"side":"Buy","size":8282486}],"insert":[],"transactTimeE6":0},"cross_seq":5938954553,"timestamp_e6":1618677785438072}
1618677786.986676: {"topic":"orderBookL2_25.BTCUSD","type":"delta","data":{"delete":[],"update":[{"price":"60616.50","symbol":"BTCUSD","id":606165000,"side":"Buy","size":8291486}],"insert":[],"transactTimeE6":0},"cross_seq":5938954554,"timestamp_e6":1618677785478047}
1618677786.986685: {"topic":"orderBookL2_25.BTCUSD","type":"delta","data":{"delete":[],"update":[{"price":"60616.50","symbol":"BTCUSD","id":606165000,"side":"Buy","size":8295636},{"price":"60604.00","symbol":"BTCUSD","id":606040000,"side":"Buy","size":2074}],"insert":[],"transactTimeE6":0},"cross_seq":5938954558,"timestamp_e6":1618677785517930}
1618677786.986697: {"topic":"orderBookL2_25.BTCUSD","type":"delta","data":{"delete":[{"price":"60604.00","symbol":"BTCUSD","id":606040000,"side":"Buy"}],"update":[{"price":"60616.50","symbol":"BTCUSD","id":606165000,"side":"Buy","size":8297714}],"insert":[{"price":"60590.50","symbol":"BTCUSD","id":605905000,"side":"Buy","size":7500}],"transactTimeE6":0},"cross_seq":5938954563,"timestamp_e6":1618677785537926}
1618677786.9867148: {"topic":"orderBookL2_25.BTCUSD","type":"delta","data":{"delete":[{"price":"60590.50","symbol":"BTCUSD","id":605905000,"side":"Buy"}],"update":[{"price":"60617.00","symbol":"BTCUSD","id":606170000,"side":"Sell","size":4100285},{"price":"60616.50","symbol":"BTCUSD","id":606165000,"side":"Buy","size":8301714},{"price":"60604.50","symbol":"BTCUSD","id":606045000,"side":"Buy","size":1419}],"insert":[{"price":"60592.50","symbol":"BTCUSD","id":605925000,"side":"Buy","size":30000}],"transactTimeE6":0},"cross_seq":5938954567,"timestamp_e6":1618677785558635}
1618677786.986738: {"topic":"orderBookL2_25.BTCUSD","type":"delta","data":{"delete":[],"update":[{"price":"60616.50","symbol":"BTCUSD","id":606165000,"side":"Buy","size":8305714}],"insert":[],"transactTimeE6":0},"cross_seq":5938954570,"timestamp_e6":1618677785577934}
1618677786.986749: {"topic":"orderBookL2_25.BTCUSD","type":"delta","data":{"delete":[{"price":"60591.00","symbol":"BTCUSD","id":605910000,"side":"Buy"}],"update":[{"price":"60623.00","symbol":"BTCUSD","id":606230000,"side":"Sell","size":138352},{"price":"60617.50","symbol":"BTCUSD","id":606175000,"side":"Sell","size":926544},{"price":"60617.00","symbol":"BTCUSD","id":606170000,"side":"Sell","size":3118194},{"price":"60616.50","symbol":"BTCUSD","id":606165000,"side":"Buy","size":8319714}],"insert":[{"price":"60613.00","symbol":"BTCUSD","id":606130000,"side":"Buy","size":4394}],"transactTimeE6":0},"cross_seq":5938954578,"timestamp_e6":1618677785618648}
1618677786.9867709: {"topic":"orderBookL2_25.BTCUSD","type":"delta","data":{"delete":[],"update":[{"price":"60617.50","symbol":"BTCUSD","id":606175000,"side":"Sell","size":156},{"price":"60617.00","symbol":"BTCUSD","id":606170000,"side":"Sell","size":3854637},{"price":"60596.00","symbol":"BTCUSD","id":605960000,"side":"Buy","size":15675}],"insert":[],"transactTimeE6":0},"cross_seq":5938954585,"timestamp_e6":1618677785638100}
1618677786.9867861: {"topic":"orderBookL2_25.BTCUSD","type":"delta","data":{"delete":[],"update":[{"price":"60617.00","symbol":"BTCUSD","id":606170000,"side":"Sell","size":3046194},{"price":"60616.50","symbol":"BTCUSD","id":606165000,"side":"Buy","size":8632853}],"insert":[],"transactTimeE6":0},"cross_seq":5938954590,"timestamp_e6":1618677785698583}
1618677786.986797: {"topic":"orderBookL2_25.BTCUSD","type":"delta","data":{"delete":[{"price":"60591.50","symbol":"BTCUSD","id":605915000,"side":"Buy"}],"update":[{"price":"60617.00","symbol":"BTCUSD","id":606170000,"side":"Sell","size":2566194}],"insert":[{"price":"60612.00","symbol":"BTCUSD","id":606120000,"side":"Buy","size":3}],"transactTimeE6":0},"cross_seq":5938954596,"timestamp_e6":1618677785717979}
1618677786.986814: {"topic":"orderBookL2_25.BTCUSD","type":"delta","data":{"delete":[],"update":[{"price":"60616.50","symbol":"BTCUSD","id":606165000,"side":"Buy","size":8632895}],"insert":[],"transactTimeE6":0},"cross_seq":5938954599,"timestamp_e6":1618677785737982}
1618677786.986825: {"topic":"orderBookL2_25.BTCUSD","type":"delta","data":{"delete":[],"update":[{"price":"60617.00","symbol":"BTCUSD","id":606170000,"side":"Sell","size":2086194}],"insert":[],"transactTimeE6":0},"cross_seq":5938954603,"timestamp_e6":1618677785798046}
1618677786.986835: {"topic":"orderBookL2_25.BTCUSD","type":"delta","data":{"delete":[],"update":[{"price":"60606.00","symbol":"BTCUSD","id":606060000,"side":"Buy","size":179205}],"insert":[],"transactTimeE6":0},"cross_seq":5938954607,"timestamp_e6":1618677785817303}
1618677786.9868438: {"topic":"orderBookL2_25.BTCUSD","type":"delta","data":{"delete":[],"update":[{"price":"60616.50","symbol":"BTCUSD","id":606165000,"side":"Buy","size":8745825}],"insert":[],"transactTimeE6":0},"cross_seq":5938954611,"timestamp_e6":1618677785838099}
1618677786.9868531: {"topic":"orderBookL2_25.BTCUSD","type":"delta","data":{"delete":[],"update":[{"price":"60616.50","symbol":"BTCUSD","id":606165000,"side":"Buy","size":8745676},{"price":"60617.00","symbol":"BTCUSD","id":606170000,"side":"Sell","size":2086193}],"insert":[],"transactTimeE6":0},"cross_seq":5938954616,"timestamp_e6":1618677785878563}
1618677786.986864: {"topic":"orderBookL2_25.BTCUSD","type":"delta","data":{"delete":[],"update":[{"price":"60617.00","symbol":"BTCUSD","id":606170000,"side":"Sell","size":2062193}],"insert":[],"transactTimeE6":0},"cross_seq":5938954617,"timestamp_e6":1618677785897974}
1618677786.9868731: {"topic":"orderBookL2_25.BTCUSD","type":"delta","data":{"delete":[],"update":[{"price":"60616.50","symbol":"BTCUSD","id":606165000,"side":"Buy","size":8745703}],"insert":[],"transactTimeE6":0},"cross_seq":5938954619,"timestamp_e6":1618677785917907}
1618677786.986882: {"topic":"orderBookL2_25.BTCUSD","type":"delta","data":{"delete":[],"update":[{"price":"60616.50","symbol":"BTCUSD","id":606165000,"side":"Buy","size":9855703},{"price":"60617.00","symbol":"BTCUSD","id":606170000,"side":"Sell","size":1918179}],"insert":[],"transactTimeE6":0},"cross_seq":5938954628,"timestamp_e6":1618677785938477}
1618677786.986893: {"topic":"orderBookL2_25.BTCUSD","type":"delta","data":{"delete":[],"update":[{"price":"60617.00","symbol":"BTCUSD","id":606170000,"side":"Sell","size":1870179}],"insert":[],"transactTimeE6":0},"cross_seq":5938954632,"timestamp_e6":1618677785958205}
1618677786.986902: {"topic":"orderBookL2_25.BTCUSD","type":"delta","data":{"delete":[],"update":[{"price":"60618.00","symbol":"BTCUSD","id":606180000,"side":"Sell","size":15},{"price":"60617.00","symbol":"BTCUSD","id":606170000,"side":"Sell","size":1866179}],"insert":[],"transactTimeE6":0},"cross_seq":5938954635,"timestamp_e6":1618677785977937}
1618677786.986913: {"topic":"orderBookL2_25.BTCUSD","type":"delta","data":{"delete":[],"update":[{"price":"60617.00","symbol":"BTCUSD","id":606170000,"side":"Sell","size":1890179}],"insert":[],"transactTimeE6":0},"cross_seq":5938954650,"timestamp_e6":1618677786058256}
1618677786.986924: {"topic":"orderBookL2_25.BTCUSD","type":"delta","data":{"delete":[],"update":[{"price":"60611.50","symbol":"BTCUSD","id":606115000,"side":"Buy","size":242},{"price":"60617.00","symbol":"BTCUSD","id":606170000,"side":"Sell","size":2034179}],"insert":[],"transactTimeE6":0},"cross_seq":5938954655,"timestamp_e6":1618677786097983}
1618677786.9869351: {"topic":"orderBookL2_25.BTCUSD","type":"delta","data":{"delete":[],"update":[{"price":"60616.50","symbol":"BTCUSD","id":606165000,"side":"Buy","size":9965703}],"insert":[],"transactTimeE6":0},"cross_seq":5938954662,"timestamp_e6":1618677786158068}
1618677786.986944: {"topic":"orderBookL2_25.BTCUSD","type":"delta","data":{"delete":[{"price":"60592.50","symbol":"BTCUSD","id":605925000,"side":"Buy"}],"update":[],"insert":[{"price":"60594.50","symbol":"BTCUSD","id":605945000,"side":"Buy","size":10761}],"transactTimeE6":0},"cross_seq":5938954664,"timestamp_e6":1618677786237361}
1618677786.9869592: {"topic":"orderBookL2_25.BTCUSD","type":"delta","data":{"delete":[],"update":[{"price":"60616.50","symbol":"BTCUSD","id":606165000,"side":"Buy","size":9674617},{"price":"60597.50","symbol":"BTCUSD","id":605975000,"side":"Buy","size":372826}],"insert":[],"transactTimeE6":0},"cross_seq":5938954672,"timestamp_e6":1618677786298178}
1618677786.9869702: {"topic":"orderBookL2_25.BTCUSD","type":"delta","data":{"delete":[],"update":[{"price":"60617.00","symbol":"BTCUSD","id":606170000,"side":"Sell","size":2538197}],"insert":[],"transactTimeE6":0},"cross_seq":5938954675,"timestamp_e6":1618677786318283}
1618677786.9869812: {"topic":"orderBookL2_25.BTCUSD","type":"delta","data":{"delete":[{"price":"60600.50","symbol":"BTCUSD","id":606005000,"side":"Buy"}],"update":[],"insert":[{"price":"60592.50","symbol":"BTCUSD","id":605925000,"side":"Buy","size":30000}],"transactTimeE6":0},"cross_seq":5938954677,"timestamp_e6":1618677786377321}
1618677786.98701: {"topic":"orderBookL2_25.BTCUSD","type":"delta","data":{"delete":[],"update":[{"price":"60617.00","symbol":"BTCUSD","id":606170000,"side":"Sell","size":3018197}],"insert":[],"transactTimeE6":0},"cross_seq":5938954680,"timestamp_e6":1618677786397959}
1618677786.987019: {"topic":"orderBookL2_25.BTCUSD","type":"delta","data":{"delete":[],"update":[{"price":"60622.00","symbol":"BTCUSD","id":606220000,"side":"Sell","size":332581},{"price":"60624.00","symbol":"BTCUSD","id":606240000,"side":"Sell","size":189244},{"price":"60602.50","symbol":"BTCUSD","id":606025000,"side":"Buy","size":235841},{"price":"60616.50","symbol":"BTCUSD","id":606165000,"side":"Buy","size":9677617},{"price":"60621.50","symbol":"BTCUSD","id":606215000,"side":"Sell","size":336182},{"price":"60623.50","symbol":"BTCUSD","id":606235000,"side":"Sell","size":215157},{"price":"60623.00","symbol":"BTCUSD","id":606230000,"side":"Sell","size":299296},{"price":"60617.00","symbol":"BTCUSD","id":606170000,"side":"Sell","size":1100020},{"price":"60622.50","symbol":"BTCUSD","id":606225000,"side":"Sell","size":257556}],"insert":[],"transactTimeE6":0},"cross_seq":5938954702,"timestamp_e6":1618677786418530}
1618677786.987058: {"topic":"orderBookL2_25.BTCUSD","type":"delta","data":{"delete":[],"update":[{"price":"60617.00","symbol":"BTCUSD","id":606170000,"side":"Sell","size":620020}],"insert":[],"transactTimeE6":0},"cross_seq":5938954709,"timestamp_e6":1618677786438007}
1618677786.987068: {"topic":"orderBookL2_25.BTCUSD","type":"delta","data":{"delete":[],"update":[{"price":"60616.50","symbol":"BTCUSD","id":606165000,"side":"Buy","size":9677649},{"price":"60629.00","symbol":"BTCUSD","id":606290000,"side":"Sell","size":320827},{"price":"60617.00","symbol":"BTCUSD","id":606170000,"side":"Sell","size":200020}],"insert":[],"transactTimeE6":0},"cross_seq":5938954742,"timestamp_e6":1618677786458759}
1618677786.987081: {"topic":"orderBookL2_25.BTCUSD","type":"delta","data":{"delete":[{"price":"60592.50","symbol":"BTCUSD","id":605925000,"side":"Buy"}],"update":[{"price":"60617.00","symbol":"BTCUSD","id":606170000,"side":"Sell","size":176020}],"insert":[{"price":"60609.50","symbol":"BTCUSD","id":606095000,"side":"Buy","size":50000}],"transactTimeE6":0},"cross_seq":5938954766,"timestamp_e6":1618677786498003}
1618677786.987097: {"topic":"orderBookL2_25.BTCUSD","type":"delta","data":{"delete":[],"update":[{"price":"60597.50","symbol":"BTCUSD","id":605975000,"side":"Buy","size":277826},{"price":"60629.00","symbol":"BTCUSD","id":606290000,"side":"Sell","size":65412},{"price":"60617.00","symbol":"BTCUSD","id":606170000,"side":"Sell","size":172020},{"price":"60595.50","symbol":"BTCUSD","id":605955000,"side":"Buy","size":20094},{"price":"60609.00","symbol":"BTCUSD","id":606090000,"side":"Buy","size":97423},{"price":"60622.00","symbol":"BTCUSD","id":606220000,"side":"Sell","size":327581}],"insert":[],"transactTimeE6":0},"cross_seq":5938954771,"timestamp_e6":1618677786517970}
1618677786.987118: {"topic":"orderBookL2_25.BTCUSD","type":"delta","data":{"delete":[],"update":[{"price":"60616.50","symbol":"BTCUSD","id":606165000,"side":"Buy","size":9677680},{"price":"60617.00","symbol":"BTCUSD","id":606170000,"side":"Sell","size":52001},{"price":"60616.00","symbol":"BTCUSD","id":606160000,"side":"Buy","size":1151392}],"insert":[],"transactTimeE6":0},"cross_seq":5938954776,"timestamp_e6":1618677786538607}
1618677786.9871309: {"topic":"orderBookL2_25.BTCUSD","type":"delta","data":{"delete":[{"price":"60598.00","symbol":"BTCUSD","id":605980000,"side":"Buy"},{"price":"60593.00","symbol":"BTCUSD","id":605930000,"side":"Buy"},{"price":"60617.50","symbol":"BTCUSD","id":606175000,"side":"Sell"},{"price":"60621.00","symbol":"BTCUSD","id":606210000,"side":"Sell"},{"price":"60619.00","symbol":"BTCUSD","id":606190000,"side":"Sell"},{"price":"60594.50","symbol":"BTCUSD","id":605945000,"side":"Buy"},{"price":"60614.50","symbol":"BTCUSD","id":606145000,"side":"Buy"},{"price":"60597.50","symbol":"BTCUSD","id":605975000,"side":"Buy"},{"price":"60618.00","symbol":"BTCUSD","id":606180000,"side":"Sell"},{"price":"60620.50","symbol":"BTCUSD","id":606205000,"side":"Sell"},{"price":"60620.00","symbol":"BTCUSD","id":606200000,"side":"Sell"},{"price":"60617.00","symbol":"BTCUSD","id":606170000,"side":"Sell"},{"price":"60595.50","symbol":"BTCUSD","id":605955000,"side":"Buy"},{"price":"60596.00","symbol":"BTCUSD","id":605960000,"side":"Buy"}],"update":[{"price":"60621.50","symbol":"BTCUSD","id":606215000,"side":"Sell","size":211570},{"price":"60616.50","symbol":"BTCUSD","id":606165000,"side":"Buy","size":9667678}],"insert":[{"price":"60631.00","symbol":"BTCUSD","id":606310000,"side":"Sell","size":36290},{"price":"60619.00","symbol":"BTCUSD","id":606190000,"side":"Buy","size":18930},{"price":"60617.50","symbol":"BTCUSD","id":606175000,"side":"Buy","size":1537502},{"price":"60632.00","symbol":"BTCUSD","id":606320000,"side":"Sell","size":40016},{"price":"60618.50","symbol":"BTCUSD","id":606185000,"side":"Buy","size":192015},{"price":"60618.00","symbol":"BTCUSD","id":606180000,"side":"Buy","size":918935},{"price":"60631.50","symbol":"BTCUSD","id":606315000,"side":"Sell","size":134536},{"price":"60633.50","symbol":"BTCUSD","id":606335000,"side":"Sell","size":35053},{"price":"60621.00","symbol":"BTCUSD","id":606210000,"side":"Buy","size":1397228},{"price":"60620.00","symbol":"BTCUSD","id":606200000,"side":"Buy","size":19080},{"price":"60617.00","symbol":"BTCUSD","id":606170000,"side":"Buy","size":1537502},{"price":"60630.50","symbol":"BTCUSD","id":606305000,"side":"Sell","size":148429},{"price":"60632.50","symbol":"BTCUSD","id":606325000,"side":"Sell","size":9918},{"price":"60633.00","symbol":"BTCUSD","id":606330000,"side":"Sell","size":48123}],"transactTimeE6":0},"cross_seq":5938954956,"timestamp_e6":1618677786558995}
1618677786.987221: {"topic":"orderBookL2_25.BTCUSD","type":"delta","data":{"delete":[{"price":"60601.50","symbol":"BTCUSD","id":606015000,"side":"Buy"},{"price":"60600.00","symbol":"BTCUSD","id":606000000,"side":"Buy"},{"price":"60621.50","symbol":"BTCUSD","id":606215000,"side":"Sell"},{"price":"60624.00","symbol":"BTCUSD","id":606240000,"side":"Sell"},{"price":"60626.00","symbol":"BTCUSD","id":606260000,"side":"Sell"}],"update":[{"price":"60618.00","symbol":"BTCUSD","id":606180000,"side":"Buy","size":878935},{"price":"60625.50","symbol":"BTCUSD","id":606255000,"side":"Sell","size":114},{"price":"60620.00","symbol":"BTCUSD","id":606200000,"side":"Buy","size":29082},{"price":"60624.50","symbol":"BTCUSD","id":606245000,"side":"Sell","size":723},{"price":"60602.50","symbol":"BTCUSD","id":606025000,"side":"Buy","size":115},{"price":"60622.00","symbol":"BTCUSD","id":606220000,"side":"Sell","size":719613},{"price":"60616.50","symbol":"BTCUSD","id":606165000,"side":"Buy","size":8431229},{"price":"60627.00","symbol":"BTCUSD","id":606270000,"side":"Sell","size":382753},{"price":"60629.00","symbol":"BTCUSD","id":606290000,"side":"Sell","size":258086},{"price":"60626.50","symbol":"BTCUSD","id":606265000,"side":"Sell","size":404884},{"price":"60628.00","symbol":"BTCUSD","id":606280000,"side":"Sell","size":331165},{"price":"60623.00","symbol":"BTCUSD","id":606230000,"side":"Sell","size":50913},{"price":"60625.00","symbol":"BTCUSD","id":606250000,"side":"Sell","size":15041},{"price":"60617.50","symbol":"BTCUSD","id":606175000,"side":"Buy","size":1495002},{"price":"60628.50","symbol":"BTCUSD","id":606285000,"side":"Sell","size":282205},{"price":"60627.50","symbol":"BTCUSD","id":606275000,"side":"Sell","size":324075},{"price":"60622.50","symbol":"BTCUSD","id":606225000,"side":"Sell","size":1941},{"price":"60621.00","symbol":"BTCUSD","id":606210000,"side":"Buy","size":2436822},{"price":"60623.50","symbol":"BTCUSD","id":606235000,"side":"Sell","size":3}],"insert":[{"price":"60635.00","symbol":"BTCUSD","id":606350000,"side":"Sell","size":73933},{"price":"60619.50","symbol":"BTCUSD","id":606195000,"side":"Buy","size":4464},{"price":"60634.50","symbol":"BTCUSD","id":606345000,"side":"Sell","size":21834},{"price":"60634.00","symbol":"BTCUSD","id":606340000,"side":"Sell","size":69512},{"price":"60620.50","symbol":"BTCUSD","id":606205000,"side":"Buy","size":10002}],"transactTimeE6":0},"cross_seq":5938955078,"timestamp_e6":1618677786578880}
1618677786.987295: {"topic":"orderBookL2_25.BTCUSD","type":"delta","data":{"delete":[{"price":"60602.50","symbol":"BTCUSD","id":606025000,"side":"Buy"}],"update":[{"price":"60622.00","symbol":"BTCUSD","id":606220000,"side":"Sell","size":40077},{"price":"60616.50","symbol":"BTCUSD","id":606165000,"side":"Buy","size":7951229},{"price":"60621.00","symbol":"BTCUSD","id":606210000,"side":"Buy","size":2916822}],"insert":[{"price":"60621.50","symbol":"BTCUSD","id":606215000,"side":"Buy","size":739788}],"transactTimeE6":0},"cross_seq":5938955140,"timestamp_e6":1618677786599046}
1618677786.987317: {"topic":"orderBookL2_25.BTCUSD","type":"delta","data":{"delete":[],"update":[{"price":"60621.50","symbol":"BTCUSD","id":606215000,"side":"Buy","size":929876},{"price":"60616.50","symbol":"BTCUSD","id":606165000,"side":"Buy","size":6532841},{"price":"60619.00","symbol":"BTCUSD","id":606190000,"side":"Buy","size":22995},{"price":"60616.00","symbol":"BTCUSD","id":606160000,"side":"Buy","size":1081392},{"price":"60621.00","symbol":"BTCUSD","id":606210000,"side":"Buy","size":3045342},{"price":"60628.50","symbol":"BTCUSD","id":606285000,"side":"Sell","size":282200}],"insert":[],"transactTimeE6":0},"cross_seq":5938955171,"timestamp_e6":1618677786617858}
1618677786.9873369: {"success":true,"ret_msg":"","conn_id":"95a3336b-365a-4fad-9540-ede1104f1260","request":{"op":"subscribe","args":["orderBookL2_25.BTCUSD"]}}
1618677786.987343: {"topic":"orderBookL2_25.BTCUSD","type":"delta","data":{"delete":[],"update":[{"price":"60616.50","symbol":"BTCUSD","id":606165000,"side":"Buy","size":2729308},{"price":"60621.00","symbol":"BTCUSD","id":606210000,"side":"Buy","size":4267982},{"price":"60618.00","symbol":"BTCUSD","id":606180000,"side":"Buy","size":323811},{"price":"60618.50","symbol":"BTCUSD","id":606185000,"side":"Buy","size":47996},{"price":"60617.00","symbol":"BTCUSD","id":606170000,"side":"Buy","size":402186},{"price":"60617.50","symbol":"BTCUSD","id":606175000,"side":"Buy","size":550516},{"price":"60616.00","symbol":"BTCUSD","id":606160000,"side":"Buy","size":1066764},{"price":"60620.00","symbol":"BTCUSD","id":606200000,"side":"Buy","size":19589},{"price":"60634.00","symbol":"BTCUSD","id":606340000,"side":"Sell","size":69517},{"price":"60609.50","symbol":"BTCUSD","id":606095000,"side":"Buy","size":50005},{"price":"60621.50","symbol":"BTCUSD","id":606215000,"side":"Buy","size":2383632},{"price":"60619.00","symbol":"BTCUSD","id":606190000,"side":"Buy","size":32204}],"insert":[],"transactTimeE6":0},"cross_seq":5938955330,"timestamp_e6":1618677786663266}
1618677786.987375: {"topic":"trade.BTCUSD","data":[{"trade_time_ms":1618677786614,"timestamp":"2021-04-17T16:43:06.000Z","symbol":"BTCUSD","side":"Sell","size":4,"price":60621.5,"tick_direction":"PlusTick","trade_id":"5ffb8b77-900c-507d-97a2-0922557ffe54","cross_seq":5938955347},{"trade_time_ms":1618677786618,"timestamp":"2021-04-17T16:43:06.000Z","symbol":"BTCUSD","side":"Sell","size":1,"price":60621.5,"tick_direction":"ZeroPlusTick","trade_id":"bcd64120-c0c8-587d-94fc-4fa4eaf6086c","cross_seq":5938955347},{"trade_time_ms":1618677786627,"timestamp":"2021-04-17T16:43:06.000Z","symbol":"BTCUSD","side":"Sell","size":3,"price":60621.5,"tick_direction":"ZeroPlusTick","trade_id":"3bb1b726-7038-5c29-8c88-d98aa7c56bdf","cross_seq":5938955347},{"trade_time_ms":1618677786630,"timestamp":"2021-04-17T16:43:06.000Z","symbol":"BTCUSD","side":"Sell","size":1,"price":60621.5,"tick_direction":"ZeroPlusTick","trade_id":"b762cb40-bdfd-586a-82ee-0bde1e48e114","cross_seq":5938955347},{"trade_time_ms":1618677786660,"timestamp":"2021-04-17T16:43:06.000Z","symbol":"BTCUSD","side":"Sell","size":3,"price":60621.5,"tick_direction":"ZeroPlusTick","trade_id":"f61a66d1-cc78-5a6d-9578-a1dd0df995c6","cross_seq":5938955347}]}
1618677786.987401: {"topic":"orderBookL2_25.BTCUSD","type":"delta","data":{"delete":[{"price":"60620.50","symbol":"BTCUSD","id":606205000,"side":"Buy"},{"price":"60619.50","symbol":"BTCUSD","id":606195000,"side":"Buy"}],"update":[{"price":"60617.50","symbol":"BTCUSD","id":606175000,"side":"Buy","size":438019},{"price":"60616.50","symbol":"BTCUSD","id":606165000,"side":"Buy","size":1279638},{"price":"60609.00","symbol":"BTCUSD","id":606090000,"side":"Buy","size":95423},{"price":"60621.50","symbol":"BTCUSD","id":606215000,"side":"Buy","size":2399703},{"price":"60621.00","symbol":"BTCUSD","id":606210000,"side":"Buy","size":3799982},{"price":"60620.00","symbol":"BTCUSD","id":606200000,"side":"Buy","size":9587},{"price":"60622.00","symbol":"BTCUSD","id":606220000,"side":"Sell","size":39827}],"insert":[{"price":"60601.50","symbol":"BTCUSD","id":606015000,"side":"Buy","size":39},{"price":"60602.50","symbol":"BTCUSD","id":606025000,"side":"Buy","size":115}],"transactTimeE6":0},"cross_seq":5938955361,"timestamp_e6":1618677786680821}
1618677786.9874392: {"topic":"orderBookL2_25.BTCUSD","type":"delta","data":{"delete":[],"update":[{"price":"60616.00","symbol":"BTCUSD","id":606160000,"side":"Buy","size":1030764},{"price":"60618.00","symbol":"BTCUSD","id":606180000,"side":"Buy","size":283811},{"price":"60621.50","symbol":"BTCUSD","id":606215000,"side":"Buy","size":2587203},{"price":"60621.00","symbol":"BTCUSD","id":606210000,"side":"Buy","size":3038611},{"price":"60617.50","symbol":"BTCUSD","id":606175000,"side":"Buy","size":414019},{"price":"60619.00","symbol":"BTCUSD","id":606190000,"side":"Buy","size":22711},{"price":"60616.50","symbol":"BTCUSD","id":606165000,"side":"Buy","size":488370}],"insert":[],"transactTimeE6":0},"cross_seq":5938955406,"timestamp_e6":1618677786697963}
1618677786.987463: {"topic":"orderBookL2_25.BTCUSD","type":"delta","data":{"delete":[],"update":[{"price":"60621.50","symbol":"BTCUSD","id":606215000,"side":"Buy","size":3023871},{"price":"60616.50","symbol":"BTCUSD","id":606165000,"side":"Buy","size":471370},{"price":"60621.00","symbol":"BTCUSD","id":606210000,"side":"Buy","size":2815745},{"price":"60620.00","symbol":"BTCUSD","id":606200000,"side":"Buy","size":150}],"insert":[],"transactTimeE6":0},"cross_seq":5938955428,"timestamp_e6":1618677786717940}
1618677786.987479: {"topic":"orderBookL2_25.BTCUSD","type":"delta","data":{"delete":[],"update":[{"price":"60617.00","symbol":"BTCUSD","id":606170000,"side":"Buy","size":362186},{"price":"60611.00","symbol":"BTCUSD","id":606110000,"side":"Buy","size":37487},{"price":"60621.50","symbol":"BTCUSD","id":606215000,"side":"Buy","size":3789674},{"price":"60619.00","symbol":"BTCUSD","id":606190000,"side":"Buy","size":6079},{"price":"60621.00","symbol":"BTCUSD","id":606210000,"side":"Buy","size":2368339}],"insert":[],"transactTimeE6":0},"cross_seq":5938955457,"timestamp_e6":1618677786737834}
1618677786.987496: {"topic":"orderBookL2_25.EOSUSD","type":"delta","data":{"delete":[],"update":[{"price":"7.971","symbol":"EOSUSD","id":79710,"side":"Buy","size":47766}],"insert":[],"transactTimeE6":0},"cross_seq":1225777227,"timestamp_e6":1618677786738891}
1618677786.987506: {"topic":"orderBookL2_25.BTCUSD","type":"delta","data":{"delete":[],"update":[{"price":"60619.00","symbol":"BTCUSD","id":606190000,"side":"Buy","size":3148},{"price":"60618.00","symbol":"BTCUSD","id":606180000,"side":"Buy","size":274318},{"price":"60621.00","symbol":"BTCUSD","id":606210000,"side":"Buy","size":1701442},{"price":"60627.00","symbol":"BTCUSD","id":606270000,"side":"Sell","size":382754},{"price":"60621.50","symbol":"BTCUSD","id":606215000,"side":"Buy","size":3864703},{"price":"60616.50","symbol":"BTCUSD","id":606165000,"side":"Buy","size":296340}],"insert":[],"transactTimeE6":0},"cross_seq":5938955466,"timestamp_e6":1618677786758053}
1618677786.9875252: {"topic":"orderBookL2_25.EOSUSD","type":"delta","data":{"delete":[],"update":[{"price":"7.971","symbol":"EOSUSD","id":79710,"side":"Buy","size":41516},{"price":"7.972","symbol":"EOSUSD","id":79720,"side":"Sell","size":153355}],"insert":[],"transactTimeE6":0},"cross_seq":1225777229,"timestamp_e6":1618677786759579}
1618677786.987537: {"topic":"trade.BTCUSD","data":[{"trade_time_ms":1618677786670,"timestamp":"2021-04-17T16:43:06.000Z","symbol":"BTCUSD","side":"Buy","size":77,"price":60622,"tick_direction":"PlusTick","trade_id":"1d28db3f-725d-5f15-9d9a-22719888546c","cross_seq":5938955471},{"trade_time_ms":1618677786670,"timestamp":"2021-04-17T16:43:06.000Z","symbol":"BTCUSD","side":"Buy","size":173,"price":60622,"tick_direction":"ZeroPlusTick","trade_id":"609f7830-198a-5303-9314-9380625a032c","cross_seq":5938955471},{"trade_time_ms":1618677786695,"timestamp":"2021-04-17T16:43:06.000Z","symbol":"BTCUSD","side":"Sell","size":3,"price":60621.5,"tick_direction":"MinusTick","trade_id":"789dcd09-9432-56f6-ba5c-b91c8596d034","cross_seq":5938955471},{"trade_time_ms":1618677786706,"timestamp":"2021-04-17T16:43:06.000Z","symbol":"BTCUSD","side":"Sell","size":1,"price":60621.5,"tick_direction":"ZeroMinusTick","trade_id":"ffb8c13d-76fc-57cb-9bd3-f4393f4a3eb3","cross_seq":5938955471},{"trade_time_ms":1618677786712,"timestamp":"2021-04-17T16:43:06.000Z","symbol":"BTCUSD","side":"Sell","size":2,"price":60621.5,"tick_direction":"ZeroMinusTick","trade_id":"575ff08f-285c-5148-b14d-05a475fa57c9","cross_seq":5938955471},{"trade_time_ms":1618677786735,"timestamp":"2021-04-17T16:43:06.000Z","symbol":"BTCUSD","side":"Sell","size":1,"price":60621.5,"tick_direction":"ZeroMinusTick","trade_id":"a34d4f99-20ba-5b48-a3b0-4ddad7c32da5","cross_seq":5938955471}]}
1618677786.987566: {"topic":"orderBookL2_25.BTCUSD","type":"delta","data":{"delete":[{"price":"60618.50","symbol":"BTCUSD","id":606185000,"side":"Buy"},{"price":"60619.00","symbol":"BTCUSD","id":606190000,"side":"Buy"}],"update":[{"price":"60621.00","symbol":"BTCUSD","id":606210000,"side":"Buy","size":1603952},{"price":"60611.00","symbol":"BTCUSD","id":606110000,"side":"Buy","size":26},{"price":"60616.50","symbol":"BTCUSD","id":606165000,"side":"Buy","size":295840},{"price":"60621.50","symbol":"BTCUSD","id":606215000,"side":"Buy","size":3961703}],"insert":[{"price":"60598.00","symbol":"BTCUSD","id":605980000,"side":"Buy","size":3},{"price":"60600.00","symbol":"BTCUSD","id":606000000,"side":"Buy","size":45}],"transactTimeE6":0},"cross_seq":5938955476,"timestamp_e6":1618677786777850}
1618677786.987595: {"topic":"orderBookL2_25.EOSUSD","type":"delta","data":{"delete":[],"update":[{"price":"7.959","symbol":"EOSUSD","id":79590,"side":"Buy","size":57345},{"price":"7.956","symbol":"EOSUSD","id":79560,"side":"Buy","size":103543},{"price":"7.957","symbol":"EOSUSD","id":79570,"side":"Buy","size":37796},{"price":"7.958","symbol":"EOSUSD","id":79580,"side":"Buy","size":39681}],"insert":[],"transactTimeE6":0},"cross_seq":1225777236,"timestamp_e6":1618677786778116}
1618677786.987614: {"topic":"orderBookL2_25.BTCUSD","type":"delta","data":{"delete":[],"update":[{"price":"60600.00","symbol":"BTCUSD","id":606000000,"side":"Buy","size":341},{"price":"60621.50","symbol":"BTCUSD","id":606215000,"side":"Buy","size":4266332},{"price":"60621.00","symbol":"BTCUSD","id":606210000,"side":"Buy","size":1368952},{"price":"60618.00","symbol":"BTCUSD","id":606180000,"side":"Buy","size":264881},{"price":"60617.50","symbol":"BTCUSD","id":606175000,"side":"Buy","size":334019},{"price":"60613.00","symbol":"BTCUSD","id":606130000,"side":"Buy","size":4419}],"insert":[],"transactTimeE6":0},"cross_seq":5938955489,"timestamp_e6":1618677786797894}
1618677786.987633: {"topic":"orderBookL2_25.EOSUSD","type":"delta","data":{"delete":[],"update":[{"price":"7.971","symbol":"EOSUSD","id":79710,"side":"Buy","size":47766}],"insert":[],"transactTimeE6":0},"cross_seq":1225777237,"timestamp_e6":1618677786798694}
1618677786.987642: {"topic":"orderBookL2_25.BTCUSD","type":"delta","data":{"delete":[],"update":[{"price":"60616.50","symbol":"BTCUSD","id":606165000,"side":"Buy","size":265840},{"price":"60621.50","symbol":"BTCUSD","id":606215000,"side":"Buy","size":5465435},{"price":"60621.00","symbol":"BTCUSD","id":606210000,"side":"Buy","size":1291455}],"insert":[],"transactTimeE6":0},"cross_seq":5938955501,"timestamp_e6":1618677786817797}
1618677786.987655: {"topic":"orderBookL2_25.EOSUSD","type":"delta","data":{"delete":[],"update":[{"price":"7.971","symbol":"EOSUSD","id":79710,"side":"Buy","size":41516}],"insert":[],"transactTimeE6":0},"cross_seq":1225777238,"timestamp_e6":1618677786818738}
1618677786.987664: {"topic":"orderBookL2_25.EOSUSD","type":"delta","data":{"delete":[],"update":[{"price":"7.971","symbol":"EOSUSD","id":79710,"side":"Buy","size":47766}],"insert":[],"transactTimeE6":0},"cross_seq":1225777239,"timestamp_e6":1618677786838773}
1618677786.987674: {"topic":"orderBookL2_25.BTCUSD","type":"delta","data":{"delete":[],"update":[{"price":"60616.50","symbol":"BTCUSD","id":606165000,"side":"Buy","size":165840},{"price":"60618.00","symbol":"BTCUSD","id":606180000,"side":"Buy","size":225000},{"price":"60621.50","symbol":"BTCUSD","id":606215000,"side":"Buy","size":6208392},{"price":"60609.00","symbol":"BTCUSD","id":606090000,"side":"Buy","size":95420},{"price":"60602.50","symbol":"BTCUSD","id":606025000,"side":"Buy","size":16712}],"insert":[],"transactTimeE6":0},"cross_seq":5938955509,"timestamp_e6":1618677786837891}
1618677786.98769: {"topic":"orderBookL2_25.BTCUSD","type":"delta","data":{"delete":[],"update":[{"price":"60617.00","symbol":"BTCUSD","id":606170000,"side":"Buy","size":319686},{"price":"60621.50","symbol":"BTCUSD","id":606215000,"side":"Buy","size":6352592},{"price":"60621.00","symbol":"BTCUSD","id":606210000,"side":"Buy","size":1181455},{"price":"60617.50","symbol":"BTCUSD","id":606175000,"side":"Buy","size":299019},{"price":"60616.50","symbol":"BTCUSD","id":606165000,"side":"Buy","size":153535}],"insert":[],"transactTimeE6":0},"cross_seq":5938955518,"timestamp_e6":1618677786857965}
1618677786.9877079: {"topic":"orderBookL2_25.BTCUSD","type":"delta","data":{"delete":[],"update":[{"price":"60621.00","symbol":"BTCUSD","id":606210000,"side":"Buy","size":1124890},{"price":"60616.50","symbol":"BTCUSD","id":606165000,"side":"Buy","size":153534},{"price":"60617.50","symbol":"BTCUSD","id":606175000,"side":"Buy","size":195000},{"price":"60617.00","symbol":"BTCUSD","id":606170000,"side":"Buy","size":209686},{"price":"60621.50","symbol":"BTCUSD","id":606215000,"side":"Buy","size":6825593}],"insert":[],"transactTimeE6":0},"cross_seq":5938955542,"timestamp_e6":1618677786877931}
1618677787.1736388: {"topic":"orderBookL2_25.EOSUSD","type":"delta","data":{"delete":[],"update":[{"price":"7.952","symbol":"EOSUSD","id":79520,"side":"Buy","size":100386},{"price":"7.955","symbol":"EOSUSD","id":79550,"side":"Buy","size":103610}],"insert":[],"transactTimeE6":0},"cross_seq":1225777240,"timestamp_e6":1618677786878135}
1618677787.173663: {"topic":"orderBookL2_25.BTCUSD","type":"delta","data":{"delete":[{"price":"60598.00","symbol":"BTCUSD","id":605980000,"side":"Buy"}],"update":[{"price":"60606.00","symbol":"BTCUSD","id":606060000,"side":"Buy","size":5},{"price":"60616.00","symbol":"BTCUSD","id":606160000,"side":"Buy","size":1030763},{"price":"60621.50","symbol":"BTCUSD","id":606215000,"side":"Buy","size":6925593}],"insert":[{"price":"60620.50","symbol":"BTCUSD","id":606205000,"side":"Buy","size":1}],"transactTimeE6":0},"cross_seq":5938955559,"timestamp_e6":1618677786898035}
1618677787.173695: {"topic":"orderBookL2_25.BTCUSD","type":"delta","data":{"delete":[],"update":[{"price":"60600.00","symbol":"BTCUSD","id":606000000,"side":"Buy","size":10341},{"price":"60621.50","symbol":"BTCUSD","id":606215000,"side":"Buy","size":6964593}],"insert":[],"transactTimeE6":0},"cross_seq":5938955567,"timestamp_e6":1618677786917917}
1618677787.173711: {"topic":"orderBookL2_25.BTCUSD","type":"delta","data":{"delete":[],"update":[{"price":"60622.00","symbol":"BTCUSD","id":606220000,"side":"Sell","size":519827},{"price":"60621.50","symbol":"BTCUSD","id":606215000,"side":"Buy","size":7207811}],"insert":[],"transactTimeE6":0},"cross_seq":5938955575,"timestamp_e6":1618677786938825}
1618677787.173727: {"topic":"orderBookL2_25.BTCUSD","type":"delta","data":{"delete":[],"update":[{"price":"60621.50","symbol":"BTCUSD","id":606215000,"side":"Buy","size":7207812},{"price":"60616.00","symbol":"BTCUSD","id":606160000,"side":"Buy","size":1030762},{"price":"60622.00","symbol":"BTCUSD","id":606220000,"side":"Sell","size":459827}],"insert":[],"transactTimeE6":0},"cross_seq":5938955578,"timestamp_e6":1618677786958723}
1618677787.1737442: {"topic":"orderBookL2_25.EOSUSD","type":"delta","data":{"delete":[],"update":[{"price":"7.956","symbol":"EOSUSD","id":79560,"side":"Buy","size":63363}],"insert":[],"transactTimeE6":0},"cross_seq":1225777241,"timestamp_e6":1618677786978156}
1618677787.173756: {"topic":"orderBookL2_25.BTCUSD","type":"delta","data":{"delete":[],"update":[{"price":"60622.00","symbol":"BTCUSD","id":606220000,"side":"Sell","size":39827},{"price":"60621.50","symbol":"BTCUSD","id":606215000,"side":"Buy","size":7227812}],"insert":[],"transactTimeE6":0},"cross_seq":5938955584,"timestamp_e6":1618677786998531}
1618677787.17377: {"topic":"orderBookL2_25.BTCUSD","type":"delta","data":{"delete":[],"update":[{"price":"60621.50","symbol":"BTCUSD","id":606215000,"side":"Buy","size":7432719}],"insert":[],"transactTimeE6":0},"cross_seq":5938955587,"timestamp_e6":1618677787017946}
1618677787.173782: {"topic":"orderBookL2_25.EOSUSD","type":"delta","data":{"delete":[],"update":[{"price":"7.957","symbol":"EOSUSD","id":79570,"side":"Buy","size":14894},{"price":"7.956","symbol":"EOSUSD","id":79560,"side":"Buy","size":46245}],"insert":[],"transactTimeE6":0},"cross_seq":1225777243,"timestamp_e6":1618677787018132}
1618677787.1737962: {"topic":"orderBookL2_25.BTCUSD","type":"delta","data":{"delete":[],"update":[{"price":"60621.00","symbol":"BTCUSD","id":606210000,"side":"Buy","size":885009}],"insert":[],"transactTimeE6":0},"cross_seq":5938955590,"timestamp_e6":1618677787037395}
1618677787.1738071: {"topic":"orderBookL2_25.EOSUSD","type":"delta","data":{"delete":[],"update":[{"price":"7.956","symbol":"EOSUSD","id":79560,"side":"Buy","size":60524},{"price":"7.962","symbol":"EOSUSD","id":79620,"side":"Buy","size":88762},{"price":"7.957","symbol":"EOSUSD","id":79570,"side":"Buy","size":37416}],"insert":[],"transactTimeE6":0},"cross_seq":1225777246,"timestamp_e6":1618677787038189}
1618677787.173824: {"topic":"orderBookL2_25.BTCUSD","type":"delta","data":{"delete":[{"price":"60620.50","symbol":"BTCUSD","id":606205000,"side":"Buy"}],"update":[{"price":"60622.00","symbol":"BTCUSD","id":606220000,"side":"Sell","size":519827},{"price":"60621.00","symbol":"BTCUSD","id":606210000,"side":"Buy","size":884510}],"insert":[{"price":"60598.00","symbol":"BTCUSD","id":605980000,"side":"Buy","size":3}],"transactTimeE6":0},"cross_seq":5938955595,"timestamp_e6":1618677787058051}
1618677787.1738482: {"topic":"orderBookL2_25.BTCUSD","type":"delta","data":{"delete":[],"update":[{"price":"60618.00","symbol":"BTCUSD","id":606180000,"side":"Buy","size":155000},{"price":"60622.50","symbol":"BTCUSD","id":606225000,"side":"Sell","size":707340},{"price":"60621.00","symbol":"BTCUSD","id":606210000,"side":"Buy","size":317010},{"price":"60617.50","symbol":"BTCUSD","id":606175000,"side":"Buy","size":155000},{"price":"60621.50","symbol":"BTCUSD","id":606215000,"side":"Buy","size":7891729},{"price":"60617.00","symbol":"BTCUSD","id":606170000,"side":"Buy","size":114881}],"insert":[],"transactTimeE6":0},"cross_seq":5938955610,"timestamp_e6":1618677787078459}
1618677787.173878: {"topic":"orderBookL2_25.EOSUSD","type":"delta","data":{"delete":[],"update":[{"price":"7.971","symbol":"EOSUSD","id":79710,"side":"Buy","size":73082}],"insert":[],"transactTimeE6":0},"cross_seq":1225777248,"timestamp_e6":1618677787078836}
1618677787.181634: {"topic":"orderBookL2_25.BTCUSD","type":"delta","data":{"delete":[],"update":[{"price":"60622.00","symbol":"BTCUSD","id":606220000,"side":"Sell","size":939827},{"price":"60621.50","symbol":"BTCUSD","id":606215000,"side":"Buy","size":6800675}],"insert":[],"transactTimeE6":0},"cross_seq":5938955616,"timestamp_e6":1618677787098610}
1618677787.342604: {"topic":"orderBookL2_25.EOSUSD","type":"delta","data":{"delete":[],"update":[{"price":"7.955","symbol":"EOSUSD","id":79550,"side":"Buy","size":87430},{"price":"7.972","symbol":"EOSUSD","id":79720,"side":"Sell","size":152355}],"insert":[],"transactTimeE6":0},"cross_seq":1225777251,"timestamp_e6":1618677787138799}
1618677787.342693: {"topic":"orderBookL2_25.BTCUSD","type":"delta","data":{"delete":[],"update":[{"price":"60622.00","symbol":"BTCUSD","id":606220000,"side":"Sell","size":1694710},{"price":"60622.50","symbol":"BTCUSD","id":606225000,"side":"Sell","size":1941}],"insert":[],"transactTimeE6":0},"cross_seq":5938955621,"timestamp_e6":1618677787238048}
1618677787.342734: {"topic":"orderBookL2_25.BTCUSD","type":"delta","data":{"delete":[],"update":[{"price":"60621.50","symbol":"BTCUSD","id":606215000,"side":"Buy","size":7900675},{"price":"60616.50","symbol":"BTCUSD","id":606165000,"side":"Buy","size":113653}],"insert":[],"transactTimeE6":0},"cross_seq":5938955624,"timestamp_e6":1618677787257973}
1618677787.5054238: {"topic":"orderBookL2_25.BTCUSD","type":"delta","data":{"delete":[{"price":"60617.50","symbol":"BTCUSD","id":606175000,"side":"Buy"}],"update":[{"price":"60621.00","symbol":"BTCUSD","id":606210000,"side":"Buy","size":304705},{"price":"60618.00","symbol":"BTCUSD","id":606180000,"side":"Buy","size":80000}],"insert":[{"price":"60597.50","symbol":"BTCUSD","id":605975000,"side":"Buy","size":277826}],"transactTimeE6":0},"cross_seq":5938955633,"timestamp_e6":1618677787277410}
1618677787.505526: {"topic":"orderBookL2_25.EOSUSD","type":"delta","data":{"delete":[],"update":[{"price":"7.955","symbol":"EOSUSD","id":79550,"side":"Buy","size":99365}],"insert":[],"transactTimeE6":0},"cross_seq":1225777253,"timestamp_e6":1618677787278160}
1618677787.505557: {"topic":"orderBookL2_25.BTCUSD","type":"delta","data":{"delete":[],"update":[{"price":"60621.00","symbol":"BTCUSD","id":606210000,"side":"Buy","size":264705},{"price":"60617.00","symbol":"BTCUSD","id":606170000,"side":"Buy","size":74881}],"insert":[],"transactTimeE6":0},"cross_seq":5938955635,"timestamp_e6":1618677787297282}
1618677787.505582: {"topic":"orderBookL2_25.EOSUSD","type":"delta","data":{"delete":[],"update":[{"price":"7.974","symbol":"EOSUSD","id":79740,"side":"Sell","size":54616}],"insert":[],"transactTimeE6":0},"cross_seq":1225777254,"timestamp_e6":1618677787338139}
1618677787.505601: {"topic":"orderBookL2_25.BTCUSD","type":"delta","data":{"delete":[],"update":[{"price":"60627.00","symbol":"BTCUSD","id":606270000,"side":"Sell","size":382753},{"price":"60622.00","symbol":"BTCUSD","id":606220000,"side":"Sell","size":1694711}],"insert":[],"transactTimeE6":0},"cross_seq":5938955636,"timestamp_e6":1618677787337944}
1618677787.505624: {"topic":"orderBookL2_25.BTCUSD","type":"delta","data":{"delete":[{"price":"60597.50","symbol":"BTCUSD","id":605975000,"side":"Buy"}],"update":[{"price":"60609.50","symbol":"BTCUSD","id":606095000,"side":"Buy","size":60005},{"price":"60622.00","symbol":"BTCUSD","id":606220000,"side":"Sell","size":1694712},{"price":"60600.00","symbol":"BTCUSD","id":606000000,"side":"Buy","size":341},{"price":"60609.00","symbol":"BTCUSD","id":606090000,"side":"Buy","size":420}],"insert":[{"price":"60614.00","symbol":"BTCUSD","id":606140000,"side":"Buy","size":95000}],"transactTimeE6":0},"cross_seq":5938955640,"timestamp_e6":1618677787358036}
1618677787.533202: {"topic":"orderBookL2_25.BTCUSD","type":"delta","data":{"delete":[],"update":[{"price":"60604.50","symbol":"BTCUSD","id":606045000,"side":"Buy","size":3919}],"insert":[],"transactTimeE6":0},"cross_seq":5938955641,"timestamp_e6":1618677787377552}
1618677787.53325: {"topic":"orderBookL2_25.BTCUSD","type":"delta","data":{"delete":[],"update":[{"price":"60629.50","symbol":"BTCUSD","id":606295000,"side":"Sell","size":152682},{"price":"60622.00","symbol":"BTCUSD","id":606220000,"side":"Sell","size":1860230}],"insert":[],"transactTimeE6":0},"cross_seq":5938955646,"timestamp_e6":1618677787437921}
1618677787.533282: {"topic":"orderBookL2_25.EOSUSD","type":"delta","data":{"delete":[],"update":[{"price":"7.971","symbol":"EOSUSD","id":79710,"side":"Buy","size":72071}],"insert":[],"transactTimeE6":0},"cross_seq":1225777255,"timestamp_e6":1618677787438806}
1618677787.687253: {"topic":"orderBookL2_25.BTCUSD","type":"delta","data":{"delete":[],"update":[{"price":"60622.00","symbol":"BTCUSD","id":606220000,"side":"Sell","size":1900233},{"price":"60617.00","symbol":"BTCUSD","id":606170000,"side":"Buy","size":35000}],"insert":[],"transactTimeE6":0},"cross_seq":5938955649,"timestamp_e6":1618677787458170}
1618677787.6873431: {"topic":"orderBookL2_25.BTCUSD","type":"delta","data":{"delete":[{"price":"60618.00","symbol":"BTCUSD","id":606180000,"side":"Buy"},{"price":"60617.00","symbol":"BTCUSD","id":606170000,"side":"Buy"}],"update":[{"price":"60621.00","symbol":"BTCUSD","id":606210000,"side":"Buy","size":154705}],"insert":[{"price":"60596.00","symbol":"BTCUSD","id":605960000,"side":"Buy","size":15670},{"price":"60597.50","symbol":"BTCUSD","id":605975000,"side":"Buy","size":277826}],"transactTimeE6":0},"cross_seq":5938955661,"timestamp_e6":1618677787497336}
1618677787.687424: {"topic":"orderBookL2_25.EOSUSD","type":"delta","data":{"delete":[],"update":[{"price":"7.980","symbol":"EOSUSD","id":79800,"side":"Sell","size":117996},{"price":"7.983","symbol":"EOSUSD","id":79830,"side":"Sell","size":157451},{"price":"7.958","symbol":"EOSUSD","id":79580,"side":"Buy","size":42474},{"price":"7.960","symbol":"EOSUSD","id":79600,"side":"Buy","size":59719},{"price":"7.981","symbol":"EOSUSD","id":79810,"side":"Sell","size":93025},{"price":"7.962","symbol":"EOSUSD","id":79620,"side":"Buy","size":61609},{"price":"7.985","symbol":"EOSUSD","id":79850,"side":"Sell","size":66125},{"price":"7.963","symbol":"EOSUSD","id":79630,"side":"Buy","size":36804},{"price":"7.982","symbol":"EOSUSD","id":79820,"side":"Sell","size":98404},{"price":"7.984","symbol":"EOSUSD","id":79840,"side":"Sell","size":101824},{"price":"7.961","symbol":"EOSUSD","id":79610,"side":"Buy","size":57923}],"insert":[],"transactTimeE6":0},"cross_seq":1225777270,"timestamp_e6":1618677787518097}
1618677787.6875038: {"topic":"orderBookL2_25.BTCUSD","type":"delta","data":{"delete":[],"update":[{"price":"60621.50","symbol":"BTCUSD","id":606215000,"side":"Buy","size":7900648}],"insert":[],"transactTimeE6":0},"cross_seq":5938955663,"timestamp_e6":1618677787537958}
1618677787.6875331: {"topic":"orderBookL2_25.EOSUSD","type":"delta","data":{"delete":[],"update":[{"price":"7.972","symbol":"EOSUSD","id":79720,"side":"Sell","size":107176},{"price":"7.955","symbol":"EOSUSD","id":79550,"side":"Buy","size":93988},{"price":"7.956","symbol":"EOSUSD","id":79560,"side":"Buy","size":46245},{"price":"7.959","symbol":"EOSUSD","id":79590,"side":"Buy","size":10693},{"price":"7.954","symbol":"EOSUSD","id":79540,"side":"Buy","size":64941},{"price":"7.973","symbol":"EOSUSD","id":79730,"side":"Sell","size":15292},{"price":"7.976","symbol":"EOSUSD","id":79760,"side":"Sell","size":19992}],"insert":[],"transactTimeE6":0},"cross_seq":1225777277,"timestamp_e6":1618677787538855}
1618677787.687585: {"topic":"orderBookL2_25.BTCUSD","type":"delta","data":{"delete":[],"update":[{"price":"60622.50","symbol":"BTCUSD","id":606225000,"side":"Sell","size":71941}],"insert":[],"transactTimeE6":0},"cross_seq":5938955665,"timestamp_e6":1618677787557311}
1618677787.6876092: {"topic":"orderBookL2_25.EOSUSD","type":"delta","data":{"delete":[],"update":[{"price":"7.972","symbol":"EOSUSD","id":79720,"side":"Sell","size":107722},{"price":"7.976","symbol":"EOSUSD","id":79760,"side":"Sell","size":19488}],"insert":[],"transactTimeE6":0},"cross_seq":1225777279,"timestamp_e6":1618677787558753}
1618677787.87041: {"topic":"orderBookL2_25.EOSUSD","type":"delta","data":{"delete":[],"update":[{"price":"7.984","symbol":"EOSUSD","id":79840,"side":"Sell","size":119740},{"price":"7.962","symbol":"EOSUSD","id":79620,"side":"Buy","size":71695},{"price":"7.983","symbol":"EOSUSD","id":79830,"side":"Sell","size":173790},{"price":"7.960","symbol":"EOSUSD","id":79600,"side":"Buy","size":39217}],"insert":[],"transactTimeE6":0},"cross_seq":1225777283,"timestamp_e6":1618677787598114}
1618677787.8704581: {"topic":"orderBookL2_25.EOSUSD","type":"delta","data":{"delete":[],"update":[{"price":"7.971","symbol":"EOSUSD","id":79710,"side":"Buy","size":87071},{"price":"7.972","symbol":"EOSUSD","id":79720,"side":"Sell","size":51056}],"insert":[],"transactTimeE6":0},"cross_seq":1225777286,"timestamp_e6":1618677787619309}
1618677787.870486: {"topic":"orderBookL2_25.BTCUSD","type":"delta","data":{"delete":[],"update":[{"price":"60616.00","symbol":"BTCUSD","id":606160000,"side":"Buy","size":1030761}],"insert":[],"transactTimeE6":0},"cross_seq":5938955669,"timestamp_e6":1618677787637367}
1618677787.870506: {"topic":"orderBookL2_25.EOSUSD","type":"delta","data":{"delete":[{"price":"7.967","symbol":"EOSUSD","id":79670,"side":"Buy"}],"update":[],"insert":[{"price":"7.969","symbol":"EOSUSD","id":79690,"side":"Buy","size":1615}],"transactTimeE6":0},"cross_seq":1225777287,"timestamp_e6":1618677787638125}
1618677787.870537: {"topic":"orderBookL2_25.EOSUSD","type":"delta","data":{"delete":[],"update":[{"price":"7.976","symbol":"EOSUSD","id":79760,"side":"Sell","size":34952},{"price":"7.959","symbol":"EOSUSD","id":79590,"side":"Buy","size":44897},{"price":"7.956","symbol":"EOSUSD","id":79560,"side":"Buy","size":55337},{"price":"7.973","symbol":"EOSUSD","id":79730,"side":"Sell","size":50744},{"price":"7.954","symbol":"EOSUSD","id":79540,"side":"Buy","size":76569},{"price":"7.977","symbol":"EOSUSD","id":79770,"side":"Sell","size":19894},{"price":"7.972","symbol":"EOSUSD","id":79720,"side":"Sell","size":79509}],"insert":[],"transactTimeE6":0},"cross_seq":1225777295,"timestamp_e6":1618677787658754}
1618677787.8705778: {"topic":"orderBookL2_25.EOSUSD","type":"delta","data":{"delete":[],"update":[{"price":"7.976","symbol":"EOSUSD","id":79760,"side":"Sell","size":35425},{"price":"7.971","symbol":"EOSUSD","id":79710,"side":"Buy","size":88071}],"insert":[],"transactTimeE6":0},"cross_seq":1225777297,"timestamp_e6":1618677787678732}
1618677787.870601: {"topic":"orderBookL2_25.BTCUSD","type":"delta","data":{"delete":[{"price":"60596.00","symbol":"BTCUSD","id":605960000,"side":"Buy"}],"update":[{"price":"60609.50","symbol":"BTCUSD","id":606095000,"side":"Buy","size":50005}],"insert":[{"price":"60602.00","symbol":"BTCUSD","id":606020000,"side":"Buy","size":10000}],"transactTimeE6":0},"cross_seq":5938955671,"timestamp_e6":1618677787717352}
1618677787.870634: {"topic":"orderBookL2_25.EOSUSD","type":"delta","data":{"delete":[],"update":[{"price":"7.972","symbol":"EOSUSD","id":79720,"side":"Sell","size":92842}],"insert":[],"transactTimeE6":0},"cross_seq":1225777298,"timestamp_e6":1618677787718830}
1618677787.870652: {"topic":"orderBookL2_25.BTCUSD","type":"delta","data":{"delete":[],"update":[{"price":"60604.50","symbol":"BTCUSD","id":606045000,"side":"Buy","size":1419}],"insert":[],"transactTimeE6":0},"cross_seq":5938955673,"timestamp_e6":1618677787737341}
1618677787.8706691: {"topic":"orderBookL2_25.EOSUSD","type":"delta","data":{"delete":[],"update":[{"price":"7.960","symbol":"EOSUSD","id":79600,"side":"Buy","size":56221},{"price":"7.985","symbol":"EOSUSD","id":79850,"side":"Sell","size":26990}],"insert":[],"transactTimeE6":0},"cross_seq":1225777300,"timestamp_e6":1618677787738179}
1618677787.87069: {"topic":"orderBookL2_25.BTCUSD","type":"delta","data":{"delete":[],"update":[{"price":"60616.50","symbol":"BTCUSD","id":606165000,"side":"Buy","size":128084}],"insert":[],"transactTimeE6":0},"cross_seq":5938955675,"timestamp_e6":1618677787777319}
1618677787.870707: {"topic":"orderBookL2_25.EOSUSD","type":"delta","data":{"delete":[],"update":[{"price":"7.977","symbol":"EOSUSD","id":79770,"side":"Sell","size":43474},{"price":"7.955","symbol":"EOSUSD","id":79550,"side":"Buy","size":97205}],"insert":[],"transactTimeE6":0},"cross_seq":1225777304,"timestamp_e6":1618677787778110}
1618677787.8823528: {"topic":"orderBookL2_25.EOSUSD","type":"delta","data":{"delete":[],"update":[{"price":"7.971","symbol":"EOSUSD","id":79710,"side":"Buy","size":87071}],"insert":[],"transactTimeE6":0},"cross_seq":1225777305,"timestamp_e6":1618677787798807}
1618677788.047897: {"topic":"orderBookL2_25.BTCUSD","type":"delta","data":{"delete":[],"update":[{"price":"60622.00","symbol":"BTCUSD","id":606220000,"side":"Sell","size":1900029}],"insert":[],"transactTimeE6":0},"cross_seq":5938955677,"timestamp_e6":1618677787817960}
1618677788.047926: {"topic":"orderBookL2_25.BTCUSD","type":"delta","data":{"delete":[{"price":"60612.00","symbol":"BTCUSD","id":606120000,"side":"Buy"}],"update":[],"insert":[{"price":"60597.00","symbol":"BTCUSD","id":605970000,"side":"Buy","size":2500}],"transactTimeE6":0},"cross_seq":5938955687,"timestamp_e6":1618677787857624}
1618677788.047955: {"topic":"orderBookL2_25.EOSUSD","type":"delta","data":{"delete":[],"update":[{"price":"7.974","symbol":"EOSUSD","id":79740,"side":"Sell","size":59616},{"price":"7.972","symbol":"EOSUSD","id":79720,"side":"Sell","size":80523},{"price":"7.985","symbol":"EOSUSD","id":79850,"side":"Sell","size":62039}],"insert":[],"transactTimeE6":0},"cross_seq":1225777309,"timestamp_e6":1618677787858728}
1618677788.047978: {"topic":"trade.BTCUSD","data":[{"trade_time_ms":1618677787811,"timestamp":"2021-04-17T16:43:07.000Z","symbol":"BTCUSD","side":"Buy","size":204,"price":60622,"tick_direction":"PlusTick","trade_id":"ecd3210b-82a0-5ab2-ad17-ef708059923f","cross_seq":5938955688}]}
1618677788.0479941: {"topic":"orderBookL2_25.BTCUSD","type":"delta","data":{"delete":[{"price":"60602.00","symbol":"BTCUSD","id":606020000,"side":"Buy"}],"update":[{"price":"60621.50","symbol":"BTCUSD","id":606215000,"side":"Buy","size":7900647},{"price":"60608.00","symbol":"BTCUSD","id":606080000,"side":"Buy","size":10200}],"insert":[{"price":"60596.00","symbol":"BTCUSD","id":605960000,"side":"Buy","size":15670}],"transactTimeE6":0},"cross_seq":5938955689,"timestamp_e6":1618677787877900}
1618677788.0480251: {"topic":"orderBookL2_25.BTCUSD","type":"delta","data":{"delete":[],"update":[{"price":"60621.00","symbol":"BTCUSD","id":606210000,"side":"Buy","size":154701}],"insert":[],"transactTimeE6":0},"cross_seq":5938955690,"timestamp_e6":1618677787897280}
1618677788.0480409: {"topic":"orderBookL2_25.EOSUSD","type":"delta","data":{"delete":[{"price":"7.969","symbol":"EOSUSD","id":79690,"side":"Buy"}],"update":[{"price":"7.972","symbol":"EOSUSD","id":79720,"side":"Sell","size":87236},{"price":"7.971","symbol":"EOSUSD","id":79710,"side":"Buy","size":92686}],"insert":[{"price":"7.942","symbol":"EOSUSD","id":79420,"side":"Buy","size":100112}],"transactTimeE6":0},"cross_seq":1225777312,"timestamp_e6":1618677787899451}
1618677788.04807: {"topic":"orderBookL2_25.BTCUSD","type":"delta","data":{"delete":[],"update":[{"price":"60621.50","symbol":"BTCUSD","id":606215000,"side":"Buy","size":7909647}],"insert":[],"transactTimeE6":0},"cross_seq":5938955691,"timestamp_e6":1618677787918005}
1618677788.048085: {"topic":"orderBookL2_25.EOSUSD","type":"delta","data":{"delete":[],"update":[{"price":"7.972","symbol":"EOSUSD","id":79720,"side":"Sell","size":92236},{"price":"7.974","symbol":"EOSUSD","id":79740,"side":"Sell","size":54616}],"insert":[],"transactTimeE6":0},"cross_seq":1225777315,"timestamp_e6":1618677787918777}
1618677788.048104: {"topic":"orderBookL2_25.EOSUSD","type":"delta","data":{"delete":[],"update":[{"price":"7.972","symbol":"EOSUSD","id":79720,"side":"Sell","size":77744},{"price":"7.974","symbol":"EOSUSD","id":79740,"side":"Sell","size":63001}],"insert":[],"transactTimeE6":0},"cross_seq":1225777320,"timestamp_e6":1618677787938882}
1618677788.048121: {"topic":"orderBookL2_25.BTCUSD","type":"delta","data":{"delete":[{"price":"60597.00","symbol":"BTCUSD","id":605970000,"side":"Buy"}],"update":[{"price":"60603.00","symbol":"BTCUSD","id":606030000,"side":"Buy","size":8070},{"price":"60621.50","symbol":"BTCUSD","id":606215000,"side":"Buy","size":7922647}],"insert":[{"price":"60595.50","symbol":"BTCUSD","id":605955000,"side":"Buy","size":10097}],"transactTimeE6":0},"cross_seq":5938955695,"timestamp_e6":1618677787958027}
1618677788.048149: {"topic":"orderBookL2_25.EOSUSD","type":"delta","data":{"delete":[],"update":[{"price":"7.972","symbol":"EOSUSD","id":79720,"side":"Sell","size":77138}],"insert":[],"transactTimeE6":0},"cross_seq":1225777321,"timestamp_e6":1618677787958752}
1618677788.071531: {"topic":"orderBookL2_25.EOSUSD","type":"delta","data":{"delete":[],"update":[{"price":"7.985","symbol":"EOSUSD","id":79850,"side":"Sell","size":26990},{"price":"7.971","symbol":"EOSUSD","id":79710,"side":"Buy","size":88686},{"price":"7.972","symbol":"EOSUSD","id":79720,"side":"Sell","size":83851}],"insert":[],"transactTimeE6":0},"cross_seq":1225777324,"timestamp_e6":1618677787979299}
1618677788.081559: {"topic":"orderBookL2_25.BTCUSD","type":"delta","data":{"delete":[],"update":[{"price":"60622.00","symbol":"BTCUSD","id":606220000,"side":"Sell","size":1948029}],"insert":[],"transactTimeE6":0},"cross_seq":5938955696,"timestamp_e6":1618677787997942}
1618677788.230495: {"topic":"orderBookL2_25.EOSUSD","type":"delta","data":{"delete":[],"update":[{"price":"7.984","symbol":"EOSUSD","id":79840,"side":"Sell","size":134606},{"price":"7.981","symbol":"EOSUSD","id":79810,"side":"Sell","size":115411},{"price":"7.972","symbol":"EOSUSD","id":79720,"side":"Sell","size":77138},{"price":"7.962","symbol":"EOSUSD","id":79620,"side":"Buy","size":76997},{"price":"7.958","symbol":"EOSUSD","id":79580,"side":"Buy","size":50250},{"price":"7.961","symbol":"EOSUSD","id":79610,"side":"Buy","size":63067},{"price":"7.959","symbol":"EOSUSD","id":79590,"side":"Buy","size":55924}],"insert":[],"transactTimeE6":0},"cross_seq":1225777331,"timestamp_e6":1618677787998770}
1618677788.230607: {"topic":"orderBookL2_25.EOSUSD","type":"delta","data":{"delete":[],"update":[{"price":"7.958","symbol":"EOSUSD","id":79580,"side":"Buy","size":20061},{"price":"7.957","symbol":"EOSUSD","id":79570,"side":"Buy","size":14894},{"price":"7.962","symbol":"EOSUSD","id":79620,"side":"Buy","size":115619},{"price":"7.961","symbol":"EOSUSD","id":79610,"side":"Buy","size":85410},{"price":"7.974","symbol":"EOSUSD","id":79740,"side":"Sell","size":23501},{"price":"7.972","symbol":"EOSUSD","id":79720,"side":"Sell","size":83851},{"price":"7.959","symbol":"EOSUSD","id":79590,"side":"Buy","size":21720},{"price":"7.960","symbol":"EOSUSD","id":79600,"side":"Buy","size":78629}],"insert":[],"transactTimeE6":0},"cross_seq":1225777341,"timestamp_e6":1618677788038815}
1618677788.2306728: {"topic":"orderBookL2_25.BTCUSD","type":"delta","data":{"delete":[],"update":[{"price":"60621.50","symbol":"BTCUSD","id":606215000,"side":"Buy","size":7922651}],"insert":[],"transactTimeE6":0},"cross_seq":5938955700,"timestamp_e6":1618677788058140}
1618677788.230704: {"topic":"orderBookL2_25.EOSUSD","type":"delta","data":{"delete":[],"update":[{"price":"7.972","symbol":"EOSUSD","id":79720,"side":"Sell","size":77138}],"insert":[],"transactTimeE6":0},"cross_seq":1225777342,"timestamp_e6":1618677788058668}
1618677788.230728: {"topic":"orderBookL2_25.EOSUSD","type":"delta","data":{"delete":[],"update":[{"price":"7.972","symbol":"EOSUSD","id":79720,"side":"Sell","size":83851}],"insert":[],"transactTimeE6":0},"cross_seq":1225777343,"timestamp_e6":1618677788078775}
1618677788.230751: {"topic":"orderBookL2_25.EOSUSD","type":"delta","data":{"delete":[],"update":[{"price":"7.974","symbol":"EOSUSD","id":79740,"side":"Sell","size":18501},{"price":"7.972","symbol":"EOSUSD","id":79720,"side":"Sell","size":88851}],"insert":[],"transactTimeE6":0},"cross_seq":1225777346,"timestamp_e6":1618677788098738}
1618677788.2307782: {"topic":"orderBookL2_25.EOSUSD","type":"delta","data":{"delete":[],"update":[{"price":"7.985","symbol":"EOSUSD","id":79850,"side":"Sell","size":51894},{"price":"7.983","symbol":"EOSUSD","id":79830,"side":"Sell","size":185594}],"insert":[],"transactTimeE6":0},"cross_seq":1225777353,"timestamp_e6":1618677788118112}
1618677788.243467: {"topic":"orderBookL2_25.EOSUSD","type":"delta","data":{"delete":[],"update":[{"price":"7.974","symbol":"EOSUSD","id":79740,"side":"Sell","size":15116},{"price":"7.972","symbol":"EOSUSD","id":79720,"side":"Sell","size":92809},{"price":"7.976","symbol":"EOSUSD","id":79760,"side":"Sell","size":34952}],"insert":[],"transactTimeE6":0},"cross_seq":1225777356,"timestamp_e6":1618677788158744}
1618677788.260313: {"topic":"orderBookL2_25.EOSUSD","type":"delta","data":{"delete":[],"update":[{"price":"7.958","symbol":"EOSUSD","id":79580,"side":"Buy","size":33100},{"price":"7.974","symbol":"EOSUSD","id":79740,"side":"Sell","size":45959},{"price":"7.959","symbol":"EOSUSD","id":79590,"side":"Buy","size":30694},{"price":"7.957","symbol":"EOSUSD","id":79570,"side":"Buy","size":25206}],"insert":[],"transactTimeE6":0},"cross_seq":1225777361,"timestamp_e6":1618677788178119}
1618677788.410465: {"topic":"orderBookL2_25.EOSUSD","type":"delta","data":{"delete":[],"update":[{"price":"7.972","symbol":"EOSUSD","id":79720,"side":"Sell","size":92842},{"price":"7.976","symbol":"EOSUSD","id":79760,"side":"Sell","size":35525}],"insert":[],"transactTimeE6":0},"cross_seq":1225777364,"timestamp_e6":1618677788218738}
1618677788.410505: {"topic":"orderBookL2_25.BTCUSD","type":"delta","data":{"delete":[{"price":"60595.50","symbol":"BTCUSD","id":605955000,"side":"Buy"}],"update":[],"insert":[{"price":"60617.00","symbol":"BTCUSD","id":606170000,"side":"Buy","size":3}],"transactTimeE6":0},"cross_seq":5938955745,"timestamp_e6":1618677788277304}
1618677788.41054: {"topic":"orderBookL2_25.EOSUSD","type":"delta","data":{"delete":[],"update":[{"price":"7.973","symbol":"EOSUSD","id":79730,"side":"Sell","size":36750}],"insert":[],"transactTimeE6":0},"cross_seq":1225777365,"timestamp_e6":1618677788298144}
1618677788.41056: {"topic":"orderBookL2_25.BTCUSD","type":"delta","data":{"delete":[],"update":[{"price":"60621.50","symbol":"BTCUSD","id":606215000,"side":"Buy","size":7931651}],"insert":[],"transactTimeE6":0},"cross_seq":5938955754,"timestamp_e6":1618677788298087}
1618677788.56615: {"topic":"orderBookL2_25.BTCUSD","type":"delta","data":{"delete":[],"update":[{"price":"60621.00","symbol":"BTCUSD","id":606210000,"side":"Buy","size":157701}],"insert":[],"transactTimeE6":0},"cross_seq":5938955756,"timestamp_e6":1618677788357311}
1618677788.566197: {"topic":"orderBookL2_25.BTCUSD","type":"delta","data":{"delete":[],"update":[{"price":"60621.00","symbol":"BTCUSD","id":606210000,"side":"Buy","size":157705}],"insert":[],"transactTimeE6":0},"cross_seq":5938955757,"timestamp_e6":1618677788377311}
1618677788.5662248: {"topic":"orderBookL2_25.EOSUSD","type":"delta","data":{"delete":[],"update":[{"price":"7.975","symbol":"EOSUSD","id":79750,"side":"Sell","size":58650},{"price":"7.959","symbol":"EOSUSD","id":79590,"side":"Buy","size":43375},{"price":"7.961","symbol":"EOSUSD","id":79610,"side":"Buy","size":100713},{"price":"7.973","symbol":"EOSUSD","id":79730,"side":"Sell","size":51261},{"price":"7.957","symbol":"EOSUSD","id":79570,"side":"Buy","size":33599},{"price":"7.976","symbol":"EOSUSD","id":79760,"side":"Sell","size":49433}],"insert":[],"transactTimeE6":0},"cross_seq":1225777371,"timestamp_e6":1618677788418124}
1618677788.566269: {"topic":"trade.BTCUSD","data":[{"trade_time_ms":1618677788464,"timestamp":"2021-04-17T16:43:08.000Z","symbol":"BTCUSD","side":"Buy","size":25,"price":60622,"tick_direction":"ZeroPlusTick","trade_id":"3b864096-6b70-560a-9a63-f19f5c8d6148","cross_seq":5938955761}]}
1618677788.5662951: {"topic":"orderBookL2_25.BTCUSD","type":"delta","data":{"delete":[],"update":[{"price":"60630.50","symbol":"BTCUSD","id":606305000,"side":"Sell","size":144429},{"price":"60622.50","symbol":"BTCUSD","id":606225000,"side":"Sell","size":727108},{"price":"60622.00","symbol":"BTCUSD","id":606220000,"side":"Sell","size":1193121},{"price":"60621.50","symbol":"BTCUSD","id":606215000,"side":"Buy","size":7974161}],"insert":[],"transactTimeE6":0},"cross_seq":5938955764,"timestamp_e6":1618677788478606}
1618677788.58176: {"topic":"orderBookL2_25.BTCUSD","type":"delta","data":{"delete":[],"update":[{"price":"60622.50","symbol":"BTCUSD","id":606225000,"side":"Sell","size":71941},{"price":"60621.50","symbol":"BTCUSD","id":606215000,"side":"Buy","size":7974151}],"insert":[],"transactTimeE6":0},"cross_seq":5938955767,"timestamp_e6":1618677788497950}
1618677788.601666: {"topic":"orderBookL2_25.BTCUSD","type":"delta","data":{"delete":[],"update":[{"price":"60621.50","symbol":"BTCUSD","id":606215000,"side":"Buy","size":7974161}],"insert":[],"transactTimeE6":0},"cross_seq":5938955768,"timestamp_e6":1618677788517951}
1618677788.742877: {"topic":"orderBookL2_25.BTCUSD","type":"delta","data":{"delete":[],"update":[{"price":"60622.50","symbol":"BTCUSD","id":606225000,"side":"Sell","size":1941}],"insert":[],"transactTimeE6":0},"cross_seq":5938955771,"timestamp_e6":1618677788537298}
1618677788.7429152: {"topic":"orderBookL2_25.EOSUSD","type":"delta","data":{"delete":[],"update":[{"price":"7.960","symbol":"EOSUSD","id":79600,"side":"Buy","size":56221}],"insert":[],"transactTimeE6":0},"cross_seq":1225777373,"timestamp_e6":1618677788558142}
1618677788.742938: {"topic":"orderBookL2_25.BTCUSD","type":"delta","data":{"delete":[],"update":[{"price":"60622.00","symbol":"BTCUSD","id":606220000,"side":"Sell","size":507604}],"insert":[],"transactTimeE6":0},"cross_seq":5938955780,"timestamp_e6":1618677788577907}
1618677788.742957: {"topic":"orderBookL2_25.BTCUSD","type":"delta","data":{"delete":[],"update":[{"price":"60621.50","symbol":"BTCUSD","id":606215000,"side":"Buy","size":8934161},{"price":"60628.50","symbol":"BTCUSD","id":606285000,"side":"Sell","size":135584},{"price":"60626.50","symbol":"BTCUSD","id":606265000,"side":"Sell","size":352959},{"price":"60622.00","symbol":"BTCUSD","id":606220000,"side":"Sell","size":459600},{"price":"60628.00","symbol":"BTCUSD","id":606280000,"side":"Sell","size":241855},{"price":"60616.50","symbol":"BTCUSD","id":606165000,"side":"Buy","size":127361},{"price":"60629.00","symbol":"BTCUSD","id":606290000,"side":"Sell","size":128765},{"price":"60627.00","symbol":"BTCUSD","id":606270000,"side":"Sell","size":159584}],"insert":[],"transactTimeE6":0},"cross_seq":5938955818,"timestamp_e6":1618677788618802}
1618677788.7430022: {"topic":"orderBookL2_25.BTCUSD","type":"delta","data":{"delete":[],"update":[{"price":"60621.50","symbol":"BTCUSD","id":606215000,"side":"Buy","size":10062216},{"price":"60622.50","symbol":"BTCUSD","id":606225000,"side":"Sell","size":1942}],"insert":[],"transactTimeE6":0},"cross_seq":5938955852,"timestamp_e6":1618677788637921}
1618677788.743026: {"topic":"orderBookL2_25.EOSUSD","type":"delta","data":{"delete":[],"update":[{"price":"7.986","symbol":"EOSUSD","id":79860,"side":"Sell","size":133882},{"price":"7.987","symbol":"EOSUSD","id":79870,"side":"Sell","size":71155}],"insert":[],"transactTimeE6":0},"cross_seq":1225777375,"timestamp_e6":1618677788658133}
1618677788.762165: {"topic":"orderBookL2_25.BTCUSD","type":"delta","data":{"delete":[],"update":[{"price":"60629.00","symbol":"BTCUSD","id":606290000,"side":"Sell","size":138650}],"insert":[],"transactTimeE6":0},"cross_seq":5938955854,"timestamp_e6":1618677788677577}
1618677788.7686841: {"topic":"orderBookL2_25.EOSUSD","type":"delta","data":{"delete":[],"update":[{"price":"7.983","symbol":"EOSUSD","id":79830,"side":"Sell","size":134779},{"price":"7.960","symbol":"EOSUSD","id":79600,"side":"Buy","size":75484}],"insert":[],"transactTimeE6":0},"cross_seq":1225777377,"timestamp_e6":1618677788678129}
1618677788.921914: {"topic":"orderBookL2_25.BTCUSD","type":"delta","data":{"delete":[],"update":[{"price":"60621.50","symbol":"BTCUSD","id":606215000,"side":"Buy","size":10542216}],"insert":[],"transactTimeE6":0},"cross_seq":5938955858,"timestamp_e6":1618677788717959}
1618677788.9219468: {"topic":"orderBookL2_25.BTCUSD","type":"delta","data":{"delete":[],"update":[{"price":"60622.00","symbol":"BTCUSD","id":606220000,"side":"Sell","size":39600}],"insert":[],"transactTimeE6":0},"cross_seq":5938955859,"timestamp_e6":1618677788738044}
1618677788.921969: {"topic":"orderBookL2_25.EOSUSD","type":"delta","data":{"delete":[],"update":[{"price":"7.971","symbol":"EOSUSD","id":79710,"side":"Buy","size":92686}],"insert":[],"transactTimeE6":0},"cross_seq":1225777378,"timestamp_e6":1618677788738834}
1618677788.9219892: {"topic":"orderBookL2_25.EOSUSD","type":"delta","data":{"delete":[],"update":[{"price":"7.980","symbol":"EOSUSD","id":79800,"side":"Sell","size":129344}],"insert":[],"transactTimeE6":0},"cross_seq":1225777379,"timestamp_e6":1618677788758137}
1618677788.922007: {"topic":"orderBookL2_25.BTCUSD","type":"delta","data":{"delete":[],"update":[{"price":"60626.50","symbol":"BTCUSD","id":606265000,"side":"Sell","size":352960},{"price":"60622.00","symbol":"BTCUSD","id":606220000,"side":"Sell","size":39599},{"price":"60621.50","symbol":"BTCUSD","id":606215000,"side":"Buy","size":10542214}],"insert":[],"transactTimeE6":0},"cross_seq":5938955862,"timestamp_e6":1618677788763332}
1618677788.9220328: {"topic":"trade.BTCUSD","data":[{"trade_time_ms":1618677788749,"timestamp":"2021-04-17T16:43:08.000Z","symbol":"BTCUSD","side":"Sell","size":1,"price":60621.5,"tick_direction":"MinusTick","trade_id":"cebc56fc-b8db-510d-8c5d-c5d527c57310","cross_seq":5938955863},{"trade_time_ms":1618677788749,"timestamp":"2021-04-17T16:43:08.000Z","symbol":"BTCUSD","side":"Sell","size":1,"price":60621.5,"tick_direction":"ZeroMinusTick","trade_id":"3c25ace9-7fb0-5514-85eb-cd82ca046f74","cross_seq":5938955863}]}
1618677788.92207: {"topic":"trade.EOSUSD","data":[{"trade_time_ms":1618677788758,"timestamp":"2021-04-17T16:43:08.000Z","symbol":"EOSUSD","side":"Sell","size":1,"price":7.971,"tick_direction":"MinusTick","trade_id":"2b855a01-c958-5725-806a-d1d3b02a577b","cross_seq":1225777380}]}
1618677788.922088: {"topic":"orderBookL2_25.BTCUSD","type":"delta","data":{"delete":[],"update":[{"price":"60621.50","symbol":"BTCUSD","id":606215000,"side":"Buy","size":10542243}],"insert":[],"transactTimeE6":0},"cross_seq":5938955863,"timestamp_e6":1618677788777928}
1618677788.922108: {"topic":"orderBookL2_25.EOSUSD","type":"delta","data":{"delete":[],"update":[{"price":"7.971","symbol":"EOSUSD","id":79710,"side":"Buy","size":92685}],"insert":[],"transactTimeE6":0},"cross_seq":1225777380,"timestamp_e6":1618677788778763}
1618677788.922126: {"topic":"orderBookL2_25.EOSUSD","type":"delta","data":{"delete":[],"update":[{"price":"7.972","symbol":"EOSUSD","id":79720,"side":"Sell","size":104763},{"price":"7.971","symbol":"EOSUSD","id":79710,"side":"Buy","size":88685}],"insert":[],"transactTimeE6":0},"cross_seq":1225777382,"timestamp_e6":1618677788819509}
1618677788.932512: {"topic":"orderBookL2_25.BTCUSD","type":"delta","data":{"delete":[],"update":[{"price":"60621.50","symbol":"BTCUSD","id":606215000,"side":"Buy","size":10542959},{"price":"60605.50","symbol":"BTCUSD","id":606055000,"side":"Buy","size":116695},{"price":"60602.50","symbol":"BTCUSD","id":606025000,"side":"Buy","size":115}],"insert":[],"transactTimeE6":0},"cross_seq":5938955870,"timestamp_e6":1618677788837914}
1618677788.9550312: {"topic":"trade.BTCUSD","data":[{"trade_time_ms":1618677788821,"timestamp":"2021-04-17T16:43:08.000Z","symbol":"BTCUSD","side":"Sell","size":1,"price":60621.5,"tick_direction":"ZeroMinusTick","trade_id":"823b6903-6ad9-5c55-90de-575c2c4f6136","cross_seq":5938955871},{"trade_time_ms":1618677788830,"timestamp":"2021-04-17T16:43:08.000Z","symbol":"BTCUSD","side":"Sell","size":3,"price":60621.5,"tick_direction":"ZeroMinusTick","trade_id":"fec86e6b-2e96-57d6-8ad0-99ead1f3e42e","cross_seq":5938955871},{"trade_time_ms":1618677788832,"timestamp":"2021-04-17T16:43:08.000Z","symbol":"BTCUSD","side":"Sell","size":3,"price":60621.5,"tick_direction":"ZeroMinusTick","trade_id":"94e16891-6a86-58db-b74e-f79000bb13ad","cross_seq":5938955871}]}
1618677789.101624: {"topic":"orderBookL2_25.BTCUSD","type":"delta","data":{"delete":[],"update":[{"price":"60621.50","symbol":"BTCUSD","id":606215000,"side":"Buy","size":10542960}],"insert":[],"transactTimeE6":0},"cross_seq":5938955873,"timestamp_e6":1618677788877968}
1618677789.101652: {"topic":"orderBookL2_25.EOSUSD","type":"delta","data":{"delete":[],"update":[{"price":"7.985","symbol":"EOSUSD","id":79850,"side":"Sell","size":59840},{"price":"7.960","symbol":"EOSUSD","id":79600,"side":"Buy","size":84264},{"price":"7.983","symbol":"EOSUSD","id":79830,"side":"Sell","size":111909},{"price":"7.958","symbol":"EOSUSD","id":79580,"side":"Buy","size":23608}],"insert":[],"transactTimeE6":0},"cross_seq":1225777386,"timestamp_e6":1618677788878216}
1618677789.101686: {"topic":"orderBookL2_25.BTCUSD","type":"delta","data":{"delete":[],"update":[{"price":"60605.50","symbol":"BTCUSD","id":606055000,"side":"Buy","size":172708}],"insert":[],"transactTimeE6":0},"cross_seq":5938955877,"timestamp_e6":1618677788937268}
1618677789.101705: {"topic":"orderBookL2_25.EOSUSD","type":"delta","data":{"delete":[],"update":[{"price":"7.974","symbol":"EOSUSD","id":79740,"side":"Sell","size":57957}],"insert":[],"transactTimeE6":0},"cross_seq":1225777387,"timestamp_e6":1618677788938165}
1618677789.101723: {"topic":"orderBookL2_25.BTCUSD","type":"delta","data":{"delete":[],"update":[{"price":"60626.50","symbol":"BTCUSD","id":606265000,"side":"Sell","size":352959},{"price":"60627.50","symbol":"BTCUSD","id":606275000,"side":"Sell","size":324076}],"insert":[],"transactTimeE6":0},"cross_seq":5938955880,"timestamp_e6":1618677788977301}
1618677789.1017442: {"topic":"orderBookL2_25.BTCUSD","type":"delta","data":{"delete":[],"update":[{"price":"60621.50","symbol":"BTCUSD","id":606215000,"side":"Buy","size":10590960}],"insert":[],"transactTimeE6":0},"cross_seq":5938955898,"timestamp_e6":1618677788997930}
1618677789.102556: {"topic":"orderBookL2_25.EOSUSD","type":"delta","data":{"delete":[],"update":[{"price":"7.982","symbol":"EOSUSD","id":79820,"side":"Sell","size":112938},{"price":"7.983","symbol":"EOSUSD","id":79830,"side":"Sell","size":126499}],"insert":[],"transactTimeE6":0},"cross_seq":1225777389,"timestamp_e6":1618677789018122}
1618677789.1208692: {"topic":"orderBookL2_25.BTCUSD","type":"delta","data":{"delete":[],"update":[{"price":"60621.50","symbol":"BTCUSD","id":606215000,"side":"Buy","size":10638960}],"insert":[],"transactTimeE6":0},"cross_seq":5938955899,"timestamp_e6":1618677789037949}
1618677789.14096: {"topic":"orderBookL2_25.BTCUSD","type":"delta","data":{"delete":[],"update":[{"price":"60621.50","symbol":"BTCUSD","id":606215000,"side":"Buy","size":10686960}],"insert":[],"transactTimeE6":0},"cross_seq":5938955900,"timestamp_e6":1618677789058169}
1618677789.2813811: {"topic":"orderBookL2_25.BTCUSD","type":"delta","data":{"delete":[],"update":[{"price":"60621.50","symbol":"BTCUSD","id":606215000,"side":"Buy","size":10734963}],"insert":[],"transactTimeE6":0},"cross_seq":5938955902,"timestamp_e6":1618677789117948}
1618677789.281408: {"topic":"orderBookL2_25.BTCUSD","type":"delta","data":{"delete":[],"update":[{"price":"60616.50","symbol":"BTCUSD","id":606165000,"side":"Buy","size":127386},{"price":"60622.00","symbol":"BTCUSD","id":606220000,"side":"Sell","size":24599}],"insert":[],"transactTimeE6":0},"cross_seq":5938955916,"timestamp_e6":1618677789137945}
1618677789.281431: {"topic":"orderBookL2_25.BTCUSD","type":"delta","data":{"delete":[],"update":[{"price":"60629.00","symbol":"BTCUSD","id":606290000,"side":"Sell","size":128765},{"price":"60621.50","symbol":"BTCUSD","id":606215000,"side":"Buy","size":10734961}],"insert":[],"transactTimeE6":0},"cross_seq":5938955919,"timestamp_e6":1618677789158046}
1618677789.28145: {"topic":"trade.BTCUSD","data":[{"trade_time_ms":1618677789114,"timestamp":"2021-04-17T16:43:09.000Z","symbol":"BTCUSD","side":"Buy","size":15000,"price":60622,"tick_direction":"PlusTick","trade_id":"8bc978cf-7932-5156-90b4-d62bd07a79b6","cross_seq":5938955919},{"trade_time_ms":1618677789136,"timestamp":"2021-04-17T16:43:09.000Z","symbol":"BTCUSD","side":"Sell","size":1,"price":60621.5,"tick_direction":"MinusTick","trade_id":"db0c767c-87a8-50fb-8d73-4a1e5c542e52","cross_seq":5938955919},{"trade_time_ms":1618677789138,"timestamp":"2021-04-17T16:43:09.000Z","symbol":"BTCUSD","side":"Sell","size":1,"price":60621.5,"tick_direction":"ZeroMinusTick","trade_id":"ff3b3b73-6f6f-5fe1-b07f-a576e304580b","cross_seq":5938955919}]}
1618677789.282827: {"topic":"orderBookL2_25.BTCUSD","type":"delta","data":{"delete":[],"update":[{"price":"60621.50","symbol":"BTCUSD","id":606215000,"side":"Buy","size":10734957}],"insert":[],"transactTimeE6":0},"cross_seq":5938955920,"timestamp_e6":1618677789197967}
1618677789.283722: {"topic":"orderBookL2_25.EOSUSD","type":"delta","data":{"delete":[],"update":[{"price":"7.960","symbol":"EOSUSD","id":79600,"side":"Buy","size":46047},{"price":"7.982","symbol":"EOSUSD","id":79820,"side":"Sell","size":154140},{"price":"7.981","symbol":"EOSUSD","id":79810,"side":"Sell","size":155786}],"insert":[],"transactTimeE6":0},"cross_seq":1225777393,"timestamp_e6":1618677789198104}
1618677789.300902: {"topic":"orderBookL2_25.EOSUSD","type":"delta","data":{"delete":[],"update":[{"price":"7.979","symbol":"EOSUSD","id":79790,"side":"Sell","size":70442}],"insert":[],"transactTimeE6":0},"cross_seq":1225777394,"timestamp_e6":1618677789218137}
1618677789.459892: {"topic":"orderBookL2_25.BTCUSD","type":"delta","data":{"delete":[],"update":[{"price":"60621.50","symbol":"BTCUSD","id":606215000,"side":"Buy","size":10734950},{"price":"60622.00","symbol":"BTCUSD","id":606220000,"side":"Sell","size":24044}],"insert":[],"transactTimeE6":0},"cross_seq":5938955930,"timestamp_e6":1618677789238529}
1618677789.459945: {"topic":"orderBookL2_25.EOSUSD","type":"delta","data":{"delete":[],"update":[{"price":"7.981","symbol":"EOSUSD","id":79810,"side":"Sell","size":118713},{"price":"7.962","symbol":"EOSUSD","id":79620,"side":"Buy","size":104885}],"insert":[],"transactTimeE6":0},"cross_seq":1225777396,"timestamp_e6":1618677789258164}
1618677789.4599712: {"topic":"orderBookL2_25.BTCUSD","type":"delta","data":{"delete":[],"update":[{"price":"60622.00","symbol":"BTCUSD","id":606220000,"side":"Sell","size":5088},{"price":"60621.50","symbol":"BTCUSD","id":606215000,"side":"Buy","size":10734945}],"insert":[],"transactTimeE6":0},"cross_seq":5938955935,"timestamp_e6":1618677789258587}
1618677789.4599922: {"topic":"trade.BTCUSD","data":[{"trade_time_ms":1618677789212,"timestamp":"2021-04-17T16:43:09.000Z","symbol":"BTCUSD","side":"Buy","size":555,"price":60622,"tick_direction":"PlusTick","trade_id":"72121b45-94c0-55ee-ae83-0280b10cf3ac","cross_seq":5938955937},{"trade_time_ms":1618677789223,"timestamp":"2021-04-17T16:43:09.000Z","symbol":"BTCUSD","side":"Sell","size":4,"price":60621.5,"tick_direction":"MinusTick","trade_id":"dbc7e96e-0dd5-507f-b413-9cecae614fe2","cross_seq":5938955937},{"trade_time_ms":1618677789229,"timestamp":"2021-04-17T16:43:09.000Z","symbol":"BTCUSD","side":"Sell","size":3,"price":60621.5,"tick_direction":"ZeroMinusTick","trade_id":"17e934c1-6dc8-539c-a686-a51f6e904958","cross_seq":5938955937},{"trade_time_ms":1618677789231,"timestamp":"2021-04-17T16:43:09.000Z","symbol":"BTCUSD","side":"Sell","size":3,"price":60621.5,"tick_direction":"ZeroMinusTick","trade_id":"85204917-18de-59c9-ae3a-82fe7a02fcd6","cross_seq":5938955937},{"trade_time_ms":1618677789234,"timestamp":"2021-04-17T16:43:09.000Z","symbol":"BTCUSD","side":"Sell","size":1,"price":60621.5,"tick_direction":"ZeroMinusTick","trade_id":"dde670de-ab0d-58e1-a94d-bd2b85c47781","cross_seq":5938955937},{"trade_time_ms":1618677789236,"timestamp":"2021-04-17T16:43:09.000Z","symbol":"BTCUSD","side":"Sell","size":1,"price":60621.5,"tick_direction":"ZeroMinusTick","trade_id":"a57dcd57-5d9f-5fc5-b73a-753382dd911a","cross_seq":5938955937},{"trade_time_ms":1618677789237,"timestamp":"2021-04-17T16:43:09.000Z","symbol":"BTCUSD","side":"Buy","size":18956,"price":60622,"tick_direction":"PlusTick","trade_id":"7cd14945-a66c-5574-a258-356d244ce563","cross_seq":5938955937},{"trade_time_ms":1618677789254,"timestamp":"2021-04-17T16:43:09.000Z","symbol":"BTCUSD","side":"Sell","size":1,"price":60621.5,"tick_direction":"MinusTick","trade_id":"65c23ab4-a61c-5352-b24e-d25756d62c9b","cross_seq":5938955937},{"trade_time_ms":1618677789260,"timestamp":"2021-04-17T16:43:09.000Z","symbol":"BTCUSD","side":"Sell","size":1,"price":60621.5,"tick_direction":"ZeroMinusTick","trade_id":"acc6e004-6e34-5a86-a181-a0023c56a72d","cross_seq":5938955937}]}
1618677789.460057: {"topic":"orderBookL2_25.BTCUSD","type":"delta","data":{"delete":[],"update":[{"price":"60621.50","symbol":"BTCUSD","id":606215000,"side":"Buy","size":10734943}],"insert":[],"transactTimeE6":0},"cross_seq":5938955938,"timestamp_e6":1618677789277927}
1618677789.460075: {"topic":"orderBookL2_25.BTCUSD","type":"delta","data":{"delete":[],"update":[{"price":"60621.00","symbol":"BTCUSD","id":606210000,"side":"Buy","size":153076}],"insert":[],"transactTimeE6":0},"cross_seq":5938955941,"timestamp_e6":1618677789297283}
1618677789.4608572: {"topic":"orderBookL2_25.BTCUSD","type":"delta","data":{"delete":[],"update":[{"price":"60616.50","symbol":"BTCUSD","id":606165000,"side":"Buy","size":127396}],"insert":[],"transactTimeE6":0},"cross_seq":5938955953,"timestamp_e6":1618677789377326}
1618677789.613512: {"topic":"orderBookL2_25.EOSUSD","type":"delta","data":{"delete":[],"update":[{"price":"7.962","symbol":"EOSUSD","id":79620,"side":"Buy","size":113217},{"price":"7.981","symbol":"EOSUSD","id":79810,"side":"Sell","size":148662}],"insert":[],"transactTimeE6":0},"cross_seq":1225777398,"timestamp_e6":1618677789398170}
1618677789.613578: {"topic":"orderBookL2_25.BTCUSD","type":"delta","data":{"delete":[],"update":[{"price":"60622.00","symbol":"BTCUSD","id":606220000,"side":"Sell","size":5087}],"insert":[],"transactTimeE6":0},"cross_seq":5938955955,"timestamp_e6":1618677789398568}
1618677789.613601: {"topic":"orderBookL2_25.BTCUSD","type":"delta","data":{"delete":[],"update":[{"price":"60621.50","symbol":"BTCUSD","id":606215000,"side":"Buy","size":10737943}],"insert":[],"transactTimeE6":0},"cross_seq":5938955958,"timestamp_e6":1618677789458144}
1618677789.6136189: {"topic":"orderBookL2_25.EOSUSD","type":"delta","data":{"delete":[],"update":[{"price":"7.972","symbol":"EOSUSD","id":79720,"side":"Sell","size":89707},{"price":"7.974","symbol":"EOSUSD","id":79740,"side":"Sell","size":42841},{"price":"7.976","symbol":"EOSUSD","id":79760,"side":"Sell","size":29372},{"price":"7.975","symbol":"EOSUSD","id":79750,"side":"Sell","size":16951},{"price":"7.961","symbol":"EOSUSD","id":79610,"side":"Buy","size":78370},{"price":"7.957","symbol":"EOSUSD","id":79570,"side":"Buy","size":23287},{"price":"7.977","symbol":"EOSUSD","id":79770,"side":"Sell","size":23625},{"price":"7.959","symbol":"EOSUSD","id":79590,"side":"Buy","size":34401}],"insert":[],"transactTimeE6":0},"cross_seq":1225777407,"timestamp_e6":1618677789458866}
1618677789.6136608: {"topic":"orderBookL2_25.BTCUSD","type":"delta","data":{"delete":[],"update":[{"price":"60621.50","symbol":"BTCUSD","id":606215000,"side":"Buy","size":10550217}],"insert":[],"transactTimeE6":0},"cross_seq":5938955962,"timestamp_e6":1618677789517955}
1618677789.798042: {"topic":"orderBookL2_25.EOSUSD","type":"delta","data":{"delete":[{"price":"7.944","symbol":"EOSUSD","id":79440,"side":"Buy"},{"price":"7.943","symbol":"EOSUSD","id":79430,"side":"Buy"},{"price":"7.942","symbol":"EOSUSD","id":79420,"side":"Buy"}],"update":[{"price":"7.963","symbol":"EOSUSD","id":79630,"side":"Buy","size":52624},{"price":"7.962","symbol":"EOSUSD","id":79620,"side":"Buy","size":74595},{"price":"7.965","symbol":"EOSUSD","id":79650,"side":"Buy","size":23520},{"price":"7.977","symbol":"EOSUSD","id":79770,"side":"Sell","size":35068},{"price":"7.975","symbol":"EOSUSD","id":79750,"side":"Sell","size":42079}],"insert":[{"price":"7.967","symbol":"EOSUSD","id":79670,"side":"Buy","size":36656},{"price":"7.966","symbol":"EOSUSD","id":79660,"side":"Buy","size":28755},{"price":"7.964","symbol":"EOSUSD","id":79640,"side":"Buy","size":14092}],"transactTimeE6":0},"cross_seq":1225777415,"timestamp_e6":1618677789578108}
1618677789.798155: {"topic":"orderBookL2_25.BTCUSD","type":"delta","data":{"delete":[],"update":[{"price":"60621.50","symbol":"BTCUSD","id":606215000,"side":"Buy","size":10550227}],"insert":[],"transactTimeE6":0},"cross_seq":5938955964,"timestamp_e6":1618677789597979}
1618677789.798181: {"topic":"orderBookL2_25.BTCUSD","type":"delta","data":{"delete":[],"update":[{"price":"60628.50","symbol":"BTCUSD","id":606285000,"side":"Sell","size":50120},{"price":"60629.00","symbol":"BTCUSD","id":606290000,"side":"Sell","size":63866},{"price":"60628.00","symbol":"BTCUSD","id":606280000,"side":"Sell","size":183327}],"insert":[],"transactTimeE6":0},"cross_seq":5938955997,"timestamp_e6":1618677789617465}
1618677789.7982059: {"topic":"orderBookL2_25.EOSUSD","type":"delta","data":{"delete":[],"update":[{"price":"7.968","symbol":"EOSUSD","id":79680,"side":"Buy","size":37872},{"price":"7.965","symbol":"EOSUSD","id":79650,"side":"Buy","size":48157},{"price":"7.966","symbol":"EOSUSD","id":79660,"side":"Buy","size":55478},{"price":"7.967","symbol":"EOSUSD","id":79670,"side":"Buy","size":59264},{"price":"7.964","symbol":"EOSUSD","id":79640,"side":"Buy","size":33719},{"price":"7.963","symbol":"EOSUSD","id":79630,"side":"Buy","size":15840}],"insert":[],"transactTimeE6":0},"cross_seq":1225777427,"timestamp_e6":1618677789658107}
1618677789.798236: {"topic":"orderBookL2_25.BTCUSD","type":"delta","data":{"delete":[],"update":[{"price":"60621.00","symbol":"BTCUSD","id":606210000,"side":"Buy","size":380078}],"insert":[],"transactTimeE6":0},"cross_seq":5938956028,"timestamp_e6":1618677789697294}
1618677789.798252: {"topic":"orderBookL2_25.EOSUSD","type":"delta","data":{"delete":[],"update":[{"price":"7.966","symbol":"EOSUSD","id":79660,"side":"Buy","size":95219},{"price":"7.962","symbol":"EOSUSD","id":79620,"side":"Buy","size":84338}],"insert":[],"transactTimeE6":0},"cross_seq":1225777429,"timestamp_e6":1618677789698108}
1618677789.8113039: {"topic":"orderBookL2_25.BTCUSD","type":"delta","data":{"delete":[],"update":[{"price":"60617.00","symbol":"BTCUSD","id":606170000,"side":"Buy","size":103},{"price":"60621.50","symbol":"BTCUSD","id":606215000,"side":"Buy","size":10550217}],"insert":[],"transactTimeE6":0},"cross_seq":5938956031,"timestamp_e6":1618677789717953}
1618677789.8453991: {"topic":"orderBookL2_25.BTCUSD","type":"delta","data":{"delete":[],"update":[{"price":"60600.00","symbol":"BTCUSD","id":606000000,"side":"Buy","size":416}],"insert":[],"transactTimeE6":0},"cross_seq":5938956035,"timestamp_e6":1618677789757318}
1618677789.860381: {"topic":"orderBookL2_25.EOSUSD","type":"delta","data":{"delete":[],"update":[{"price":"7.963","symbol":"EOSUSD","id":79630,"side":"Buy","size":27617}],"insert":[],"transactTimeE6":0},"cross_seq":1225777430,"timestamp_e6":1618677789778164}
1618677789.8894668: {"topic":"orderBookL2_25.BTCUSD","type":"delta","data":{"delete":[],"update":[{"price":"60621.50","symbol":"BTCUSD","id":606215000,"side":"Buy","size":10550218}],"insert":[],"transactTimeE6":0},"cross_seq":5938956038,"timestamp_e6":1618677789797972}
1618677789.9290292: {"topic":"orderBookL2_25.EOSUSD","type":"delta","data":{"delete":[],"update":[{"price":"7.971","symbol":"EOSUSD","id":79710,"side":"Buy","size":92685},{"price":"7.962","symbol":"EOSUSD","id":79620,"side":"Buy","size":74595},{"price":"7.976","symbol":"EOSUSD","id":79760,"side":"Sell","size":38131},{"price":"7.965","symbol":"EOSUSD","id":79650,"side":"Buy","size":24657}],"insert":[],"transactTimeE6":0},"cross_seq":1225777434,"timestamp_e6":1618677789838743}
1618677789.9870431: {"topic":"orderBookL2_25.BTCUSD","type":"delta","data":{"delete":[],"update":[{"price":"60621.50","symbol":"BTCUSD","id":606215000,"side":"Buy","size":10550214}],"insert":[],"transactTimeE6":0},"cross_seq":5938956042,"timestamp_e6":1618677789898116}
1618677789.987133: {"topic":"orderBookL2_25.EOSUSD","type":"delta","data":{"delete":[],"update":[{"price":"7.980","symbol":"EOSUSD","id":79800,"side":"Sell","size":84923},{"price":"7.984","symbol":"EOSUSD","id":79840,"side":"Sell","size":119767},{"price":"7.965","symbol":"EOSUSD","id":79650,"side":"Buy","size":20},{"price":"7.964","symbol":"EOSUSD","id":79640,"side":"Buy","size":14092}],"insert":[],"transactTimeE6":0},"cross_seq":1225777438,"timestamp_e6":1618677789898108}
1618677790.011366: {"topic":"orderBookL2_25.BTCUSD","type":"delta","data":{"delete":[],"update":[{"price":"60621.50","symbol":"BTCUSD","id":606215000,"side":"Buy","size":10570214}],"insert":[],"transactTimeE6":0},"cross_seq":5938956044,"timestamp_e6":1618677789917900}
1618677790.011478: {"topic":"orderBookL2_25.EOSUSD","type":"delta","data":{"delete":[],"update":[{"price":"7.971","symbol":"EOSUSD","id":79710,"side":"Buy","size":88685},{"price":"7.963","symbol":"EOSUSD","id":79630,"side":"Buy","size":35106}],"insert":[],"transactTimeE6":0},"cross_seq":1225777440,"timestamp_e6":1618677789918799}
1618677790.0213912: {"topic":"orderBookL2_25.BTCUSD","type":"delta","data":{"delete":[{"price":"60596.00","symbol":"BTCUSD","id":605960000,"side":"Buy"}],"update":[],"insert":[{"price":"60614.50","symbol":"BTCUSD","id":606145000,"side":"Buy","size":30000}],"transactTimeE6":0},"cross_seq":5938956046,"timestamp_e6":1618677789937957}
1618677790.0508559: {"topic":"orderBookL2_25.EOSUSD","type":"delta","data":{"delete":[],"update":[{"price":"7.962","symbol":"EOSUSD","id":79620,"side":"Buy","size":82845},{"price":"7.965","symbol":"EOSUSD","id":79650,"side":"Buy","size":21522}],"insert":[],"transactTimeE6":0},"cross_seq":1225777442,"timestamp_e6":1618677789958170}
1618677790.065249: {"topic":"orderBookL2_25.BTCUSD","type":"delta","data":{"delete":[],"update":[{"price":"60616.50","symbol":"BTCUSD","id":606165000,"side":"Buy","size":127421}],"insert":[],"transactTimeE6":0},"cross_seq":5938956047,"timestamp_e6":1618677789977328}
1618677790.1062741: {"topic":"orderBookL2_25.BTCUSD","type":"delta","data":{"delete":[],"update":[{"price":"60621.50","symbol":"BTCUSD","id":606215000,"side":"Buy","size":10560211}],"insert":[],"transactTimeE6":0},"cross_seq":5938956053,"timestamp_e6":1618677790018145}
1618677790.132736: {"topic":"orderBookL2_25.EOSUSD","type":"delta","data":{"delete":[],"update":[{"price":"7.984","symbol":"EOSUSD","id":79840,"side":"Sell","size":129051},{"price":"7.964","symbol":"EOSUSD","id":79640,"side":"Buy","size":22928},{"price":"7.965","symbol":"EOSUSD","id":79650,"side":"Buy","size":38793},{"price":"7.980","symbol":"EOSUSD","id":79800,"side":"Sell","size":126985},{"price":"7.985","symbol":"EOSUSD","id":79850,"side":"Sell","size":34936}],"insert":[],"transactTimeE6":0},"cross_seq":1225777447,"timestamp_e6":1618677790038119}
1618677790.132786: {"topic":"orderBookL2_25.BTCUSD","type":"delta","data":{"delete":[],"update":[{"price":"60621.50","symbol":"BTCUSD","id":606215000,"side":"Buy","size":10550211}],"insert":[],"transactTimeE6":0},"cross_seq":5938956054,"timestamp_e6":1618677790037967}
1618677790.167318: {"topic":"trade.BTCUSD","data":[{"trade_time_ms":1618677789996,"timestamp":"2021-04-17T16:43:09.000Z","symbol":"BTCUSD","side":"Sell","size":3,"price":60621.5,"tick_direction":"ZeroMinusTick","trade_id":"826ce094-0370-5775-b951-e2373bc46edc","cross_seq":5938956054}]}
1618677790.205729: {"topic":"orderBookL2_25.EOSUSD","type":"delta","data":{"delete":[],"update":[{"price":"7.985","symbol":"EOSUSD","id":79850,"side":"Sell","size":52787},{"price":"7.980","symbol":"EOSUSD","id":79800,"side":"Sell","size":115637}],"insert":[],"transactTimeE6":0},"cross_seq":1225777449,"timestamp_e6":1618677790118119}
1618677790.3091981: {"topic":"orderBookL2_25.EOSUSD","type":"delta","data":{"delete":[],"update":[{"price":"7.963","symbol":"EOSUSD","id":79630,"side":"Buy","size":19286}],"insert":[],"transactTimeE6":0},"cross_seq":1225777450,"timestamp_e6":1618677790218121}
1618677790.324515: {"topic":"orderBookL2_25.EOSUSD","type":"delta","data":{"delete":[],"update":[{"price":"7.980","symbol":"EOSUSD","id":79800,"side":"Sell","size":126164}],"insert":[],"transactTimeE6":0},"cross_seq":1225777451,"timestamp_e6":1618677790238095}
1618677790.361554: {"topic":"orderBookL2_25.EOSUSD","type":"delta","data":{"delete":[],"update":[{"price":"7.962","symbol":"EOSUSD","id":79620,"side":"Buy","size":31970}],"insert":[],"transactTimeE6":0},"cross_seq":1225777452,"timestamp_e6":1618677790278106}
1618677790.3838441: {"topic":"orderBookL2_25.EOSUSD","type":"delta","data":{"delete":[],"update":[{"price":"7.980","symbol":"EOSUSD","id":79800,"side":"Sell","size":84102},{"price":"7.961","symbol":"EOSUSD","id":79610,"side":"Buy","size":38168}],"insert":[],"transactTimeE6":0},"cross_seq":1225777454,"timestamp_e6":1618677790298105}
1618677790.4055119: {"topic":"orderBookL2_25.EOSUSD","type":"delta","data":{"delete":[],"update":[{"price":"7.980","symbol":"EOSUSD","id":79800,"side":"Sell","size":117248}],"insert":[],"transactTimeE6":0},"cross_seq":1225777455,"timestamp_e6":1618677790318108}
1618677790.428354: {"topic":"orderBookL2_25.EOSUSD","type":"delta","data":{"delete":[],"update":[{"price":"7.963","symbol":"EOSUSD","id":79630,"side":"Buy","size":33276}],"insert":[],"transactTimeE6":0},"cross_seq":1225777456,"timestamp_e6":1618677790338130}
1618677790.444151: {"topic":"orderBookL2_25.BTCUSD","type":"delta","data":{"delete":[],"update":[{"price":"60622.00","symbol":"BTCUSD","id":606220000,"side":"Sell","size":87}],"insert":[],"transactTimeE6":0},"cross_seq":5938956068,"timestamp_e6":1618677790358071}
1618677790.464027: {"topic":"trade.BTCUSD","data":[{"trade_time_ms":1618677790342,"timestamp":"2021-04-17T16:43:10.000Z","symbol":"BTCUSD","side":"Buy","size":5000,"price":60622,"tick_direction":"PlusTick","trade_id":"307930dd-08a5-555d-af40-9a69ba6a8808","cross_seq":5938956070},{"trade_time_ms":1618677790363,"timestamp":"2021-04-17T16:43:10.000Z","symbol":"BTCUSD","side":"Sell","size":1,"price":60621.5,"tick_direction":"MinusTick","trade_id":"24f50d43-2f86-5d6a-b99a-04c31a844c9f","cross_seq":5938956070},{"trade_time_ms":1618677790365,"timestamp":"2021-04-17T16:43:10.000Z","symbol":"BTCUSD","side":"Sell","size":1,"price":60621.5,"tick_direction":"ZeroMinusTick","trade_id":"e2d9686c-63e0-5c42-b8a8-28bf18e789b8","cross_seq":5938956070}]}
1618677790.469235: {"topic":"orderBookL2_25.BTCUSD","type":"delta","data":{"delete":[{"price":"60622.00","symbol":"BTCUSD","id":606220000,"side":"Sell"},{"price":"60597.50","symbol":"BTCUSD","id":605975000,"side":"Buy"}],"update":[{"price":"60621.50","symbol":"BTCUSD","id":606215000,"side":"Buy","size":10550209}],"insert":[{"price":"60635.50","symbol":"BTCUSD","id":606355000,"side":"Sell","size":136971},{"price":"60622.00","symbol":"BTCUSD","id":606220000,"side":"Buy","size":6}],"transactTimeE6":0},"cross_seq":5938956071,"timestamp_e6":1618677790378507}
1618677790.485404: {"topic":"orderBookL2_25.BTCUSD","type":"delta","data":{"delete":[],"update":[{"price":"60621.50","symbol":"BTCUSD","id":606215000,"side":"Buy","size":8788610},{"price":"60622.00","symbol":"BTCUSD","id":606220000,"side":"Buy","size":2216198},{"price":"60616.00","symbol":"BTCUSD","id":606160000,"side":"Buy","size":1030758},{"price":"60622.50","symbol":"BTCUSD","id":606225000,"side":"Sell","size":691419}],"insert":[],"transactTimeE6":0},"cross_seq":5938956111,"timestamp_e6":1618677790398697}
1618677790.5051498: {"topic":"orderBookL2_25.BTCUSD","type":"delta","data":{"delete":[],"update":[{"price":"60622.00","symbol":"BTCUSD","id":606220000,"side":"Buy","size":6737459},{"price":"60621.50","symbol":"BTCUSD","id":606215000,"side":"Buy","size":6003978}],"insert":[],"transactTimeE6":0},"cross_seq":5938956176,"timestamp_e6":1618677790417879}
1618677790.5281851: {"topic":"orderBookL2_25.BTCUSD","type":"delta","data":{"delete":[{"price":"60622.50","symbol":"BTCUSD","id":606225000,"side":"Sell"}],"update":[{"price":"60621.50","symbol":"BTCUSD","id":606215000,"side":"Buy","size":5171855},{"price":"60622.00","symbol":"BTCUSD","id":606220000,"side":"Buy","size":7515622}],"insert":[{"price":"60636.00","symbol":"BTCUSD","id":606360000,"side":"Sell","size":146320}],"transactTimeE6":0},"cross_seq":5938956187,"timestamp_e6":1618677790438532}
1618677790.5495832: {"topic":"orderBookL2_25.BTCUSD","type":"delta","data":{"delete":[{"price":"60598.00","symbol":"BTCUSD","id":605980000,"side":"Buy"}],"update":[{"price":"60622.00","symbol":"BTCUSD","id":606220000,"side":"Buy","size":6941753},{"price":"60621.50","symbol":"BTCUSD","id":606215000,"side":"Buy","size":4666355}],"insert":[{"price":"60622.50","symbol":"BTCUSD","id":606225000,"side":"Buy","size":2085677}],"transactTimeE6":0},"cross_seq":5938956229,"timestamp_e6":1618677790458037}
1618677790.574309: {"topic":"trade.BTCUSD","data":[{"trade_time_ms":1618677790370,"timestamp":"2021-04-17T16:43:10.000Z","symbol":"BTCUSD","side":"Buy","size":87,"price":60622,"tick_direction":"PlusTick","trade_id":"97933392-0685-5a03-a9fd-615a9fbc0f7b","cross_seq":5938956271},{"trade_time_ms":1618677790387,"timestamp":"2021-04-17T16:43:10.000Z","symbol":"BTCUSD","side":"Buy","size":30,"price":60622.5,"tick_direction":"PlusTick","trade_id":"8cfcd9f6-65c3-5661-8777-8a30ba359801","cross_seq":5938956271},{"trade_time_ms":1618677790387,"timestamp":"2021-04-17T16:43:10.000Z","symbol":"BTCUSD","side":"Buy","size":153,"price":60622.5,"tick_direction":"ZeroPlusTick","trade_id":"44a579a4-d988-5357-ab14-d198db78d213","cross_seq":5938956271},{"trade_time_ms":1618677790387,"timestamp":"2021-04-17T16:43:10.000Z","symbol":"BTCUSD","side":"Buy","size":153,"price":60622.5,"tick_direction":"ZeroPlusTick","trade_id":"45f59894-6cc3-56b3-997d-d6af3c6fec41","cross_seq":5938956271},{"trade_time_ms":1618677790387,"timestamp":"2021-04-17T16:43:10.000Z","symbol":"BTCUSD","side":"Buy","size":153,"price":60622.5,"tick_direction":"ZeroPlusTick","trade_id":"0d69e82e-3b77-56d4-990b-79ae1edeeb80","cross_seq":5938956271},{"trade_time_ms":1618677790387,"timestamp":"2021-04-17T16:43:10.000Z","symbol":"BTCUSD","side":"Buy","size":153,"price":60622.5,"tick_direction":"ZeroPlusTick","trade_id":"da9d2d21-d199-5646-8d18-af14a18b7bdb","cross_seq":5938956271},{"trade_time_ms":1618677790387,"timestamp":"2021-04-17T16:43:10.000Z","symbol":"BTCUSD","side":"Buy","size":66,"price":60622.5,"tick_direction":"ZeroPlusTick","trade_id":"891e05b0-f3cd-514b-bec4-751dd9aa4daf","cross_seq":5938956271},{"trade_time_ms":1618677790387,"timestamp":"2021-04-17T16:43:10.000Z","symbol":"BTCUSD","side":"Buy","size":153,"price":60622.5,"tick_direction":"ZeroPlusTick","trade_id":"cfbbbc5e-6665-5442-9a4f-3a3af6337d52","cross_seq":5938956271},{"trade_time_ms":1618677790387,"timestamp":"2021-04-17T16:43:10.000Z","symbol":"BTCUSD","side":"Buy","size":153,"price":60622.5,"tick_direction":"ZeroPlusTick","trade_id":"a9d80fac-b412-50b5-8a97-c842432887d7","cross_seq":5938956271},{"trade_time_ms":1618677790387,"timestamp":"2021-04-17T16:43:10.000Z","symbol":"BTCUSD","side":"Buy","size":153,"price":60622.5,"tick_direction":"ZeroPlusTick","trade_id":"91e121c8-f869-549a-a620-46d39f7db515","cross_seq":5938956271},{"trade_time_ms":1618677790387,"timestamp":"2021-04-17T16:43:10.000Z","symbol":"BTCUSD","side":"Buy","size":326,"price":60622.5,"tick_direction":"ZeroPlusTick","trade_id":"425a9a46-28b1-56ee-a2a6-746e7005da23","cross_seq":5938956271},{"trade_time_ms":1618677790387,"timestamp":"2021-04-17T16:43:10.000Z","symbol":"BTCUSD","side":"Buy","size":386,"price":60622.5,"tick_direction":"ZeroPlusTick","trade_id":"5795dc84-f3a4-57cf-9341-8511386366e1","cross_seq":5938956271},{"trade_time_ms":1618677790387,"timestamp":"2021-04-17T16:43:10.000Z","symbol":"BTCUSD","side":"Buy","size":62,"price":60622.5,"tick_direction":"ZeroPlusTick","trade_id":"b38bdc89-0e74-5d8d-8780-be9f1d2cc38a","cross_seq":5938956271},{"trade_time_ms":1618677790387,"timestamp":"2021-04-17T16:43:10.000Z","symbol":"BTCUSD","side":"Buy","size":1,"price":60622.5,"tick_direction":"ZeroPlusTick","trade_id":"a68f2cc9-dcfa-5309-a451-8640a44ae937","cross_seq":5938956271},{"trade_time_ms":1618677790387,"timestamp":"2021-04-17T16:43:10.000Z","symbol":"BTCUSD","side":"Buy","size":1575,"price":60622.5,"tick_direction":"ZeroPlusTick","trade_id":"33a9c518-7b51-540d-896b-e9f36117bdf5","cross_seq":5938956271},{"trade_time_ms":1618677790393,"timestamp":"2021-04-17T16:43:10.000Z","symbol":"BTCUSD","side":"Sell","size":1,"price":60622,"tick_direction":"MinusTick","trade_id":"10a4e834-0ffe-5013-9a70-e7239d901a19","cross_seq":5938956271},{"trade_time_ms":1618677790439,"timestamp":"2021-04-17T16:43:10.000Z","symbol":"BTCUSD","side":"Sell","size":4,"price":60622,"tick_direction":"ZeroMinusTick","trade_id":"ae3a8c78-5c25-53b5-9551-3b0c7f2e6927","cross_seq":5938956271},{"trade_time_ms":1618677790439,"timestamp":"2021-04-17T16:43:10.000Z","symbol":"BTCUSD","side":"Sell","size":1,"price":60622,"tick_direction":"ZeroMinusTick","trade_id":"34f65062-2444-5d1a-bc79-933ef2bfaecf","cross_seq":5938956271},{"trade_time_ms":1618677790439,"timestamp":"2021-04-17T16:43:10.000Z","symbol":"BTCUSD","side":"Sell","size":2,"price":60622,"tick_direction":"ZeroMinusTick","trade_id":"8d19e630-afd4-50a4-941d-93faa3e2f143","cross_seq":5938956271},{"trade_time_ms":1618677790451,"timestamp":"2021-04-17T16:43:10.000Z","symbol":"BTCUSD","side":"Sell","size":1,"price":60622.5,"tick_direction":"PlusTick","trade_id":"d63985d7-9f3c-522e-aad2-700b57f440c2","cross_seq":5938956271}]}
1618677790.5745149: {"topic":"orderBookL2_25.EOSUSD","type":"delta","data":{"delete":[],"update":[{"price":"7.962","symbol":"EOSUSD","id":79620,"side":"Buy","size":37953},{"price":"7.974","symbol":"EOSUSD","id":79740,"side":"Sell","size":56617},{"price":"7.963","symbol":"EOSUSD","id":79630,"side":"Buy","size":44080},{"price":"7.975","symbol":"EOSUSD","id":79750,"side":"Sell","size":52836},{"price":"7.964","symbol":"EOSUSD","id":79640,"side":"Buy","size":28983},{"price":"7.965","symbol":"EOSUSD","id":79650,"side":"Buy","size":45221}],"insert":[],"transactTimeE6":0},"cross_seq":1225777462,"timestamp_e6":1618677790478148}
1618677790.5745878: {"topic":"orderBookL2_25.BTCUSD","type":"delta","data":{"delete":[],"update":[{"price":"60623.00","symbol":"BTCUSD","id":606230000,"side":"Sell","size":530913},{"price":"60621.50","symbol":"BTCUSD","id":606215000,"side":"Buy","size":1814634},{"price":"60622.00","symbol":"BTCUSD","id":606220000,"side":"Buy","size":6398863},{"price":"60622.50","symbol":"BTCUSD","id":606225000,"side":"Buy","size":2569894}],"insert":[],"transactTimeE6":0},"cross_seq":5938956292,"timestamp_e6":1618677790478422}
1618677790.594799: {"topic":"orderBookL2_25.BTCUSD","type":"delta","data":{"delete":[],"update":[{"price":"60623.50","symbol":"BTCUSD","id":606235000,"side":"Sell","size":708411},{"price":"60621.50","symbol":"BTCUSD","id":606215000,"side":"Buy","size":1126706},{"price":"60622.50","symbol":"BTCUSD","id":606225000,"side":"Buy","size":2901886},{"price":"60622.00","symbol":"BTCUSD","id":606220000,"side":"Buy","size":4072863}],"insert":[],"transactTimeE6":0},"cross_seq":5938956318,"timestamp_e6":1618677790498127}
1618677790.614801: {"topic":"orderBookL2_25.BTCUSD","type":"delta","data":{"delete":[],"update":[{"price":"60622.50","symbol":"BTCUSD","id":606225000,"side":"Buy","size":2961074},{"price":"60621.50","symbol":"BTCUSD","id":606215000,"side":"Buy","size":1072147},{"price":"60623.50","symbol":"BTCUSD","id":606235000,"side":"Sell","size":3},{"price":"60622.00","symbol":"BTCUSD","id":606220000,"side":"Buy","size":3797449}],"insert":[],"transactTimeE6":0},"cross_seq":5938956327,"timestamp_e6":1618677790517843}
1618677790.6359339: {"topic":"orderBookL2_25.BTCUSD","type":"delta","data":{"delete":[],"update":[{"price":"60622.50","symbol":"BTCUSD","id":606225000,"side":"Buy","size":3254287},{"price":"60621.50","symbol":"BTCUSD","id":606215000,"side":"Buy","size":997147}],"insert":[],"transactTimeE6":0},"cross_seq":5938956330,"timestamp_e6":1618677790538200}
1618677790.656182: {"topic":"orderBookL2_25.BTCUSD","type":"delta","data":{"delete":[],"update":[{"price":"60622.50","symbol":"BTCUSD","id":606225000,"side":"Buy","size":4297505},{"price":"60621.50","symbol":"BTCUSD","id":606215000,"side":"Buy","size":461071},{"price":"60622.00","symbol":"BTCUSD","id":606220000,"side":"Buy","size":2024713}],"insert":[],"transactTimeE6":0},"cross_seq":5938956362,"timestamp_e6":1618677790558013}
1618677790.674955: {"topic":"trade.BTCUSD","data":[{"trade_time_ms":1618677790491,"timestamp":"2021-04-17T16:43:10.000Z","symbol":"BTCUSD","side":"Sell","size":1,"price":60622.5,"tick_direction":"ZeroPlusTick","trade_id":"c5300459-71d1-5090-9ec7-a8a8e448ec9f","cross_seq":5938956368},{"trade_time_ms":1618677790541,"timestamp":"2021-04-17T16:43:10.000Z","symbol":"BTCUSD","side":"Sell","size":3,"price":60622.5,"tick_direction":"ZeroPlusTick","trade_id":"e56fc1ba-37a0-5b14-a2e9-186137857597","cross_seq":5938956368},{"trade_time_ms":1618677790552,"timestamp":"2021-04-17T16:43:10.000Z","symbol":"BTCUSD","side":"Sell","size":3,"price":60622.5,"tick_direction":"ZeroPlusTick","trade_id":"841548a6-ab93-5b44-a88a-99e7ae82d24a","cross_seq":5938956368}]}
1618677790.6750011: {"topic":"orderBookL2_25.BTCUSD","type":"delta","data":{"delete":[],"update":[{"price":"60622.00","symbol":"BTCUSD","id":606220000,"side":"Buy","size":1944716},{"price":"60621.50","symbol":"BTCUSD","id":606215000,"side":"Buy","size":430571},{"price":"60622.50","symbol":"BTCUSD","id":606225000,"side":"Buy","size":5599898}],"insert":[],"transactTimeE6":0},"cross_seq":5938956370,"timestamp_e6":1618677790577901}
1618677790.682508: {"topic":"orderBookL2_25.BTCUSD","type":"delta","data":{"delete":[],"update":[{"price":"60622.50","symbol":"BTCUSD","id":606225000,"side":"Buy","size":5591601}],"insert":[],"transactTimeE6":0},"cross_seq":5938956372,"timestamp_e6":1618677790597951}
1618677790.7028322: {"topic":"orderBookL2_25.EOSUSD","type":"delta","data":{"delete":[],"update":[{"price":"7.972","symbol":"EOSUSD","id":79720,"side":"Sell","size":105588}],"insert":[],"transactTimeE6":0},"cross_seq":1225777463,"timestamp_e6":1618677790598762}
1618677790.71864: {"topic":"orderBookL2_25.BTCUSD","type":"delta","data":{"delete":[],"update":[{"price":"60621.50","symbol":"BTCUSD","id":606215000,"side":"Buy","size":425942}],"insert":[],"transactTimeE6":0},"cross_seq":5938956375,"timestamp_e6":1618677790617258}
1618677790.7376058: {"topic":"orderBookL2_25.EOSUSD","type":"delta","data":{"delete":[],"update":[{"price":"7.982","symbol":"EOSUSD","id":79820,"side":"Sell","size":112938}],"insert":[],"transactTimeE6":0},"cross_seq":1225777464,"timestamp_e6":1618677790638133}
1618677790.737706: {"topic":"orderBookL2_25.BTCUSD","type":"delta","data":{"delete":[],"update":[{"price":"60626.50","symbol":"BTCUSD","id":606265000,"side":"Sell","size":352960},{"price":"60621.50","symbol":"BTCUSD","id":606215000,"side":"Buy","size":425943},{"price":"60623.00","symbol":"BTCUSD","id":606230000,"side":"Sell","size":530914},{"price":"60621.00","symbol":"BTCUSD","id":606210000,"side":"Buy","size":380077},{"price":"60617.00","symbol":"BTCUSD","id":606170000,"side":"Buy","size":100},{"price":"60622.50","symbol":"BTCUSD","id":606225000,"side":"Buy","size":6071601},{"price":"60622.00","symbol":"BTCUSD","id":606220000,"side":"Buy","size":1413435},{"price":"60627.50","symbol":"BTCUSD","id":606275000,"side":"Sell","size":324075}],"insert":[],"transactTimeE6":0},"cross_seq":5938956384,"timestamp_e6":1618677790638521}
1618677790.749713: {"topic":"orderBookL2_25.EOSUSD","type":"delta","data":{"delete":[],"update":[{"price":"7.972","symbol":"EOSUSD","id":79720,"side":"Sell","size":105587}],"insert":[],"transactTimeE6":0},"cross_seq":1225777465,"timestamp_e6":1618677790658759}
1618677790.762733: {"topic":"trade.BTCUSD","data":[{"trade_time_ms":1618677790572,"timestamp":"2021-04-17T16:43:10.000Z","symbol":"BTCUSD","side":"Sell","size":12926,"price":60622.5,"tick_direction":"ZeroPlusTick","trade_id":"77b894ad-0a32-5637-9438-b9df703bddad","cross_seq":5938956386}]}
1618677790.787889: {"topic":"trade.EOSUSD","data":[{"trade_time_ms":1618677790644,"timestamp":"2021-04-17T16:43:10.000Z","symbol":"EOSUSD","side":"Buy","size":1,"price":7.972,"tick_direction":"PlusTick","trade_id":"771435e4-8f53-5052-ae43-d5b16cc4cbb1","cross_seq":1225777466}]}
1618677790.787945: {"topic":"orderBookL2_25.EOSUSD","type":"delta","data":{"delete":[{"price":"7.946","symbol":"EOSUSD","id":79460,"side":"Buy"},{"price":"7.945","symbol":"EOSUSD","id":79450,"side":"Buy"}],"update":[{"price":"7.966","symbol":"EOSUSD","id":79660,"side":"Buy","size":68496},{"price":"7.968","symbol":"EOSUSD","id":79680,"side":"Buy","size":100}],"insert":[{"price":"7.970","symbol":"EOSUSD","id":79700,"side":"Buy","size":34763},{"price":"7.969","symbol":"EOSUSD","id":79690,"side":"Buy","size":28350}],"transactTimeE6":0},"cross_seq":1225777469,"timestamp_e6":1618677790678337}
1618677790.788033: {"topic":"orderBookL2_25.BTCUSD","type":"delta","data":{"delete":[],"update":[{"price":"60622.50","symbol":"BTCUSD","id":606225000,"side":"Buy","size":6446601},{"price":"60621.50","symbol":"BTCUSD","id":606215000,"side":"Buy","size":350943}],"insert":[],"transactTimeE6":0},"cross_seq":5938956394,"timestamp_e6":1618677790677855}
1618677790.7880661: {"topic":"orderBookL2_25.BTCUSD","type":"delta","data":{"delete":[],"update":[{"price":"60622.50","symbol":"BTCUSD","id":606225000,"side":"Buy","size":6496801},{"price":"60622.00","symbol":"BTCUSD","id":606220000,"side":"Buy","size":1322935}],"insert":[],"transactTimeE6":0},"cross_seq":5938956400,"timestamp_e6":1618677790697972}
1618677790.805019: {"topic":"orderBookL2_25.BTCUSD","type":"delta","data":{"delete":[],"update":[{"price":"60622.00","symbol":"BTCUSD","id":606220000,"side":"Buy","size":1037749},{"price":"60622.50","symbol":"BTCUSD","id":606225000,"side":"Buy","size":6499801}],"insert":[],"transactTimeE6":0},"cross_seq":5938956409,"timestamp_e6":1618677790717895}
1618677790.830453: {"topic":"orderBookL2_25.BTCUSD","type":"delta","data":{"delete":[],"update":[{"price":"60621.50","symbol":"BTCUSD","id":606215000,"side":"Buy","size":350946},{"price":"60622.50","symbol":"BTCUSD","id":606225000,"side":"Buy","size":7579301},{"price":"60622.00","symbol":"BTCUSD","id":606220000,"side":"Buy","size":587749}],"insert":[],"transactTimeE6":0},"cross_seq":5938956421,"timestamp_e6":1618677790737887}
1618677790.8436759: {"topic":"orderBookL2_25.BTCUSD","type":"delta","data":{"delete":[],"update":[{"price":"60622.50","symbol":"BTCUSD","id":606225000,"side":"Buy","size":7612661},{"price":"60622.00","symbol":"BTCUSD","id":606220000,"side":"Buy","size":547749}],"insert":[],"transactTimeE6":0},"cross_seq":5938956426,"timestamp_e6":1618677790758057}
1618677790.872907: {"topic":"orderBookL2_25.BTCUSD","type":"delta","data":{"delete":[],"update":[{"price":"60622.00","symbol":"BTCUSD","id":606220000,"side":"Buy","size":460885}],"insert":[],"transactTimeE6":0},"cross_seq":5938956427,"timestamp_e6":1618677790777336}
1618677790.8823848: {"topic":"orderBookL2_25.EOSUSD","type":"delta","data":{"delete":[],"update":[{"price":"7.967","symbol":"EOSUSD","id":79670,"side":"Buy","size":36656},{"price":"7.966","symbol":"EOSUSD","id":79660,"side":"Buy","size":78258},{"price":"7.968","symbol":"EOSUSD","id":79680,"side":"Buy","size":23947}],"insert":[],"transactTimeE6":0},"cross_seq":1225777472,"timestamp_e6":1618677790798118}
1618677790.900904: {"topic":"orderBookL2_25.BTCUSD","type":"delta","data":{"delete":[],"update":[{"price":"60621.50","symbol":"BTCUSD","id":606215000,"side":"Buy","size":350915},{"price":"60622.00","symbol":"BTCUSD","id":606220000,"side":"Buy","size":460886},{"price":"60623.50","symbol":"BTCUSD","id":606235000,"side":"Sell","size":4},{"price":"60623.00","symbol":"BTCUSD","id":606230000,"side":"Sell","size":530913},{"price":"60622.50","symbol":"BTCUSD","id":606225000,"side":"Buy","size":7612691}],"insert":[],"transactTimeE6":0},"cross_seq":5938956432,"timestamp_e6":1618677790798526}
1618677790.910626: {"topic":"orderBookL2_25.BTCUSD","type":"delta","data":{"delete":[],"update":[{"price":"60622.50","symbol":"BTCUSD","id":606225000,"side":"Buy","size":7632691}],"insert":[],"transactTimeE6":0},"cross_seq":5938956434,"timestamp_e6":1618677790817914}
1618677790.939924: {"topic":"orderBookL2_25.BTCUSD","type":"delta","data":{"delete":[],"update":[{"price":"60622.00","symbol":"BTCUSD","id":606220000,"side":"Buy","size":260886}],"insert":[],"transactTimeE6":0},"cross_seq":5938956436,"timestamp_e6":1618677790857346}
1618677790.943671: {"topic":"orderBookL2_25.EOSUSD","type":"delta","data":{"delete":[],"update":[{"price":"7.975","symbol":"EOSUSD","id":79750,"side":"Sell","size":53474},{"price":"7.967","symbol":"EOSUSD","id":79670,"side":"Buy","size":136619},{"price":"7.966","symbol":"EOSUSD","id":79660,"side":"Buy","size":49503}],"insert":[],"transactTimeE6":0},"cross_seq":1225777477,"timestamp_e6":1618677790858118}
1618677790.974703: {"topic":"orderBookL2_25.BTCUSD","type":"delta","data":{"delete":[],"update":[{"price":"60622.00","symbol":"BTCUSD","id":606220000,"side":"Buy","size":218386},{"price":"60622.50","symbol":"BTCUSD","id":606225000,"side":"Buy","size":7641693},{"price":"60621.50","symbol":"BTCUSD","id":606215000,"side":"Buy","size":350913}],"insert":[],"transactTimeE6":0},"cross_seq":5938956442,"timestamp_e6":1618677790877914}
1618677790.9747572: {"topic":"orderBookL2_25.EOSUSD","type":"delta","data":{"delete":[],"update":[{"price":"7.971","symbol":"EOSUSD","id":79710,"side":"Buy","size":87070},{"price":"7.972","symbol":"EOSUSD","id":79720,"side":"Sell","size":106225},{"price":"7.969","symbol":"EOSUSD","id":79690,"side":"Buy","size":29965}],"insert":[],"transactTimeE6":0},"cross_seq":1225777479,"timestamp_e6":1618677790879383}
1618677790.993833: {"topic":"orderBookL2_25.BTCUSD","type":"delta","data":{"delete":[],"update":[{"price":"60622.00","symbol":"BTCUSD","id":606220000,"side":"Buy","size":143386},{"price":"60622.50","symbol":"BTCUSD","id":606225000,"side":"Buy","size":7646193}],"insert":[],"transactTimeE6":0},"cross_seq":5938956447,"timestamp_e6":1618677790897897}
1618677791.01416: {"topic":"orderBookL2_25.EOSUSD","type":"delta","data":{"delete":[],"update":[{"price":"7.975","symbol":"EOSUSD","id":79750,"side":"Sell","size":52836}],"insert":[],"transactTimeE6":0},"cross_seq":1225777481,"timestamp_e6":1618677790918104}
1618677791.033804: {"topic":"orderBookL2_25.EOSUSD","type":"delta","data":{"delete":[],"update":[{"price":"7.984","symbol":"EOSUSD","id":79840,"side":"Sell","size":111135},{"price":"7.967","symbol":"EOSUSD","id":79670,"side":"Buy","size":147821},{"price":"7.965","symbol":"EOSUSD","id":79650,"side":"Buy","size":27950},{"price":"7.966","symbol":"EOSUSD","id":79660,"side":"Buy","size":57173},{"price":"7.982","symbol":"EOSUSD","id":79820,"side":"Sell","size":74754},{"price":"7.981","symbol":"EOSUSD","id":79810,"side":"Sell","size":126276}],"insert":[],"transactTimeE6":0},"cross_seq":1225777487,"timestamp_e6":1618677790938169}
1618677791.0614522: {"topic":"orderBookL2_25.EOSUSD","type":"delta","data":{"delete":[],"update":[{"price":"7.977","symbol":"EOSUSD","id":79770,"side":"Sell","size":42675},{"price":"7.966","symbol":"EOSUSD","id":79660,"side":"Buy","size":82149}],"insert":[],"transactTimeE6":0},"cross_seq":1225777489,"timestamp_e6":1618677790978109}
1618677791.1206179: {"topic":"orderBookL2_25.BTCUSD","type":"delta","data":{"delete":[],"update":[{"price":"60622.00","symbol":"BTCUSD","id":606220000,"side":"Buy","size":142886}],"insert":[],"transactTimeE6":0},"cross_seq":5938956453,"timestamp_e6":1618677791037283}
1618677791.141257: {"topic":"orderBookL2_25.EOSUSD","type":"delta","data":{"delete":[],"update":[{"price":"7.984","symbol":"EOSUSD","id":79840,"side":"Sell","size":118233},{"price":"7.965","symbol":"EOSUSD","id":79650,"side":"Buy","size":36498},{"price":"7.982","symbol":"EOSUSD","id":79820,"side":"Sell","size":93226},{"price":"7.981","symbol":"EOSUSD","id":79810,"side":"Sell","size":139088},{"price":"7.985","symbol":"EOSUSD","id":79850,"side":"Sell","size":62377}],"insert":[],"transactTimeE6":0},"cross_seq":1225777494,"timestamp_e6":1618677791058215}
1618677791.1606798: {"topic":"orderBookL2_25.BTCUSD","type":"delta","data":{"delete":[],"update":[{"price":"60622.50","symbol":"BTCUSD","id":606225000,"side":"Buy","size":7886692}],"insert":[],"transactTimeE6":0},"cross_seq":5938956455,"timestamp_e6":1618677791077929}
1618677791.1815171: {"topic":"orderBookL2_25.BTCUSD","type":"delta","data":{"delete":[{"price":"60600.00","symbol":"BTCUSD","id":606000000,"side":"Buy"}],"update":[{"price":"60622.50","symbol":"BTCUSD","id":606225000,"side":"Buy","size":8401768}],"insert":[{"price":"60617.50","symbol":"BTCUSD","id":606175000,"side":"Buy","size":3}],"transactTimeE6":0},"cross_seq":5938956457,"timestamp_e6":1618677791097950}
1618677791.2406158: {"topic":"orderBookL2_25.EOSUSD","type":"delta","data":{"delete":[],"update":[{"price":"7.964","symbol":"EOSUSD","id":79640,"side":"Buy","size":8836},{"price":"7.966","symbol":"EOSUSD","id":79660,"side":"Buy","size":57173},{"price":"7.962","symbol":"EOSUSD","id":79620,"side":"Buy","size":47532},{"price":"7.967","symbol":"EOSUSD","id":79670,"side":"Buy","size":100049},{"price":"7.961","symbol":"EOSUSD","id":79610,"side":"Buy","size":54430},{"price":"7.959","symbol":"EOSUSD","id":79590,"side":"Buy","size":47805},{"price":"7.963","symbol":"EOSUSD","id":79630,"side":"Buy","size":63509},{"price":"7.965","symbol":"EOSUSD","id":79650,"side":"Buy","size":8568}],"insert":[],"transactTimeE6":0},"cross_seq":1225777505,"timestamp_e6":1618677791158143}
1618677791.2812061: {"topic":"orderBookL2_25.EOSUSD","type":"delta","data":{"delete":[],"update":[{"price":"7.978","symbol":"EOSUSD","id":79780,"side":"Sell","size":57696}],"insert":[],"transactTimeE6":0},"cross_seq":1225777515,"timestamp_e6":1618677791198158}
1618677791.300343: {"topic":"orderBookL2_25.BTCUSD","type":"delta","data":{"delete":[],"update":[{"price":"60627.00","symbol":"BTCUSD","id":606270000,"side":"Sell","size":159582}],"insert":[],"transactTimeE6":0},"cross_seq":5938956490,"timestamp_e6":1618677791217522}
1618677791.400975: {"topic":"orderBookL2_25.EOSUSD","type":"delta","data":{"delete":[],"update":[{"price":"7.971","symbol":"EOSUSD","id":79710,"side":"Buy","size":80820}],"insert":[],"transactTimeE6":0},"cross_seq":1225777516,"timestamp_e6":1618677791318772}
1618677791.4219992: {"topic":"orderBookL2_25.EOSUSD","type":"delta","data":{"delete":[],"update":[{"price":"7.971","symbol":"EOSUSD","id":79710,"side":"Buy","size":60820}],"insert":[],"transactTimeE6":0},"cross_seq":1225777517,"timestamp_e6":1618677791338747}
1618677791.480841: {"topic":"orderBookL2_25.EOSUSD","type":"delta","data":{"delete":[],"update":[{"price":"7.981","symbol":"EOSUSD","id":79810,"side":"Sell","size":98713},{"price":"7.967","symbol":"EOSUSD","id":79670,"side":"Buy","size":101664},{"price":"7.969","symbol":"EOSUSD","id":79690,"side":"Buy","size":28350}],"insert":[],"transactTimeE6":0},"cross_seq":1225777519,"timestamp_e6":1618677791398151}
1618677791.502326: {"topic":"orderBookL2_25.EOSUSD","type":"delta","data":{"delete":[],"update":[{"price":"7.971","symbol":"EOSUSD","id":79710,"side":"Buy","size":67071}],"insert":[],"transactTimeE6":0},"cross_seq":1225777520,"timestamp_e6":1618677791418865}
1618677791.521448: {"topic":"orderBookL2_25.EOSUSD","type":"delta","data":{"delete":[],"update":[{"price":"7.971","symbol":"EOSUSD","id":79710,"side":"Buy","size":87071}],"insert":[],"transactTimeE6":0},"cross_seq":1225777521,"timestamp_e6":1618677791438767}
1618677791.581456: {"topic":"orderBookL2_25.EOSUSD","type":"delta","data":{"delete":[],"update":[{"price":"7.977","symbol":"EOSUSD","id":79770,"side":"Sell","size":26820},{"price":"7.976","symbol":"EOSUSD","id":79760,"side":"Sell","size":52753},{"price":"7.959","symbol":"EOSUSD","id":79590,"side":"Buy","size":35124},{"price":"7.960","symbol":"EOSUSD","id":79600,"side":"Buy","size":26784}],"insert":[],"transactTimeE6":0},"cross_seq":1225777525,"timestamp_e6":1618677791498184}
1618677791.602017: {"topic":"orderBookL2_25.BTCUSD","type":"delta","data":{"delete":[],"update":[{"price":"60622.50","symbol":"BTCUSD","id":606225000,"side":"Buy","size":8449768}],"insert":[],"transactTimeE6":0},"cross_seq":5938956501,"timestamp_e6":1618677791518201}
1618677791.602057: {"topic":"orderBookL2_25.EOSUSD","type":"delta","data":{"delete":[],"update":[{"price":"7.985","symbol":"EOSUSD","id":79850,"side":"Sell","size":56618},{"price":"7.969","symbol":"EOSUSD","id":79690,"side":"Buy","size":29965},{"price":"7.967","symbol":"EOSUSD","id":79670,"side":"Buy","size":100049}],"insert":[],"transactTimeE6":0},"cross_seq":1225777527,"timestamp_e6":1618677791518222}
1618677791.66288: {"topic":"orderBookL2_25.BTCUSD","type":"delta","data":{"delete":[{"price":"60636.00","symbol":"BTCUSD","id":606360000,"side":"Sell"},{"price":"60604.50","symbol":"BTCUSD","id":606045000,"side":"Buy"},{"price":"60605.00","symbol":"BTCUSD","id":606050000,"side":"Buy"},{"price":"60602.50","symbol":"BTCUSD","id":606025000,"side":"Buy"},{"price":"60601.50","symbol":"BTCUSD","id":606015000,"side":"Buy"},{"price":"60603.00","symbol":"BTCUSD","id":606030000,"side":"Buy"}],"update":[{"price":"60625.00","symbol":"BTCUSD","id":606250000,"side":"Sell","size":47394},{"price":"60620.00","symbol":"BTCUSD","id":606200000,"side":"Buy","size":3176},{"price":"60622.50","symbol":"BTCUSD","id":606225000,"side":"Buy","size":8450346},{"price":"60624.50","symbol":"BTCUSD","id":606245000,"side":"Sell","size":48314},{"price":"60621.00","symbol":"BTCUSD","id":606210000,"side":"Buy","size":382070},{"price":"60616.50","symbol":"BTCUSD","id":606165000,"side":"Buy","size":128618},{"price":"60617.50","symbol":"BTCUSD","id":606175000,"side":"Buy","size":2125},{"price":"60617.00","symbol":"BTCUSD","id":606170000,"side":"Buy","size":3286},{"price":"60623.50","symbol":"BTCUSD","id":606235000,"side":"Sell","size":79698},{"price":"60625.50","symbol":"BTCUSD","id":606255000,"side":"Sell","size":22135},{"price":"60623.00","symbol":"BTCUSD","id":606230000,"side":"Sell","size":630897}],"insert":[{"price":"60618.50","symbol":"BTCUSD","id":606185000,"side":"Buy","size":1153},{"price":"60619.00","symbol":"BTCUSD","id":606190000,"side":"Buy","size":1481},{"price":"60620.50","symbol":"BTCUSD","id":606205000,"side":"Buy","size":1384},{"price":"60618.00","symbol":"BTCUSD","id":606180000,"side":"Buy","size":870},{"price":"60619.50","symbol":"BTCUSD","id":606195000,"side":"Buy","size":2026},{"price":"60624.00","symbol":"BTCUSD","id":606240000,"side":"Sell","size":52874}],"transactTimeE6":0},"cross_seq":5938956568,"timestamp_e6":1618677791578574}
1618677791.70208: {"topic":"orderBookL2_25.EOSUSD","type":"delta","data":{"delete":[],"update":[{"price":"7.977","symbol":"EOSUSD","id":79770,"side":"Sell","size":39475},{"price":"7.960","symbol":"EOSUSD","id":79600,"side":"Buy","size":41524},{"price":"7.961","symbol":"EOSUSD","id":79610,"side":"Buy","size":39127}],"insert":[],"transactTimeE6":0},"cross_seq":1225777530,"timestamp_e6":1618677791618183}
1618677791.761697: {"topic":"orderBookL2_25.EOSUSD","type":"delta","data":{"delete":[],"update":[{"price":"7.971","symbol":"EOSUSD","id":79710,"side":"Buy","size":80820}],"insert":[],"transactTimeE6":0},"cross_seq":1225777531,"timestamp_e6":1618677791678731}
1618677791.781736: {"topic":"orderBookL2_25.EOSUSD","type":"delta","data":{"delete":[],"update":[{"price":"7.971","symbol":"EOSUSD","id":79710,"side":"Buy","size":60820}],"insert":[],"transactTimeE6":0},"cross_seq":1225777533,"timestamp_e6":1618677791698746}
1618677791.800145: {"topic":"orderBookL2_25.BTCUSD","type":"delta","data":{"delete":[],"update":[{"price":"60621.00","symbol":"BTCUSD","id":606210000,"side":"Buy","size":382066}],"insert":[],"transactTimeE6":0},"cross_seq":5938956591,"timestamp_e6":1618677791717309}
1618677791.800859: {"topic":"orderBookL2_25.EOSUSD","type":"delta","data":{"delete":[],"update":[{"price":"7.969","symbol":"EOSUSD","id":79690,"side":"Buy","size":28350},{"price":"7.967","symbol":"EOSUSD","id":79670,"side":"Buy","size":101664}],"insert":[],"transactTimeE6":0},"cross_seq":1225777534,"timestamp_e6":1618677791718114}
1618677791.822552: {"topic":"orderBookL2_25.EOSUSD","type":"delta","data":{"delete":[],"update":[{"price":"7.971","symbol":"EOSUSD","id":79710,"side":"Buy","size":67071},{"price":"7.988","symbol":"EOSUSD","id":79880,"side":"Sell","size":46183},{"price":"7.968","symbol":"EOSUSD","id":79680,"side":"Buy","size":29771}],"insert":[],"transactTimeE6":0},"cross_seq":1225777537,"timestamp_e6":1618677791738748}
1618677791.840888: {"topic":"orderBookL2_25.EOSUSD","type":"delta","data":{"delete":[],"update":[{"price":"7.962","symbol":"EOSUSD","id":79620,"side":"Buy","size":54011},{"price":"7.961","symbol":"EOSUSD","id":79610,"side":"Buy","size":46907},{"price":"7.971","symbol":"EOSUSD","id":79710,"side":"Buy","size":60820}],"insert":[],"transactTimeE6":0},"cross_seq":1225777540,"timestamp_e6":1618677791758883}
1618677791.855696: {"topic":"trade.BTCUSD","data":[{"trade_time_ms":1618677791749,"timestamp":"2021-04-17T16:43:11.000Z","symbol":"BTCUSD","side":"Buy","size":5,"price":60623,"tick_direction":"PlusTick","trade_id":"6c4cd54b-928b-5000-8ae4-d90045b35c87","cross_seq":5938956644},{"trade_time_ms":1618677791749,"timestamp":"2021-04-17T16:43:11.000Z","symbol":"BTCUSD","side":"Buy","size":581,"price":60623,"tick_direction":"ZeroPlusTick","trade_id":"684ce58f-80d7-58ef-8e94-c39a53fd928d","cross_seq":5938956644},{"trade_time_ms":1618677791749,"timestamp":"2021-04-17T16:43:11.000Z","symbol":"BTCUSD","side":"Buy","size":2674,"price":60623,"tick_direction":"ZeroPlusTick","trade_id":"8f145764-bccd-5c09-89a7-ddd58739bf31","cross_seq":5938956644}]}
1618677791.863913: {"topic":"orderBookL2_25.BTCUSD","type":"delta","data":{"delete":[],"update":[{"price":"60625.50","symbol":"BTCUSD","id":606255000,"side":"Sell","size":22136},{"price":"60626.50","symbol":"BTCUSD","id":606265000,"side":"Sell","size":352959},{"price":"60622.50","symbol":"BTCUSD","id":606225000,"side":"Buy","size":10106016},{"price":"60623.00","symbol":"BTCUSD","id":606230000,"side":"Sell","size":627637}],"insert":[],"transactTimeE6":0},"cross_seq":5938956644,"timestamp_e6":1618677791778582}
1618677791.90123: {"topic":"orderBookL2_25.BTCUSD","type":"delta","data":{"delete":[],"update":[{"price":"60622.50","symbol":"BTCUSD","id":606225000,"side":"Buy","size":10266016}],"insert":[],"transactTimeE6":0},"cross_seq":5938956649,"timestamp_e6":1618677791817933}
1618677791.9208179: {"topic":"orderBookL2_25.BTCUSD","type":"delta","data":{"delete":[],"update":[{"price":"60623.00","symbol":"BTCUSD","id":606230000,"side":"Sell","size":627638}],"insert":[],"transactTimeE6":0},"cross_seq":5938956650,"timestamp_e6":1618677791837907}
1618677792.0009332: {"topic":"orderBookL2_25.EOSUSD","type":"delta","data":{"delete":[],"update":[{"price":"7.977","symbol":"EOSUSD","id":79770,"side":"Sell","size":76977}],"insert":[],"transactTimeE6":0},"cross_seq":1225777542,"timestamp_e6":1618677791918115}
1618677792.00097: {"topic":"orderBookL2_25.BTCUSD","type":"delta","data":{"delete":[],"update":[{"price":"60622.50","symbol":"BTCUSD","id":606225000,"side":"Buy","size":9906016}],"insert":[],"transactTimeE6":0},"cross_seq":5938956663,"timestamp_e6":1618677791918028}
1618677792.021183: {"topic":"orderBookL2_25.BTCUSD","type":"delta","data":{"delete":[],"update":[{"price":"60623.00","symbol":"BTCUSD","id":606230000,"side":"Sell","size":623638}],"insert":[],"transactTimeE6":0},"cross_seq":5938956665,"timestamp_e6":1618677791938236}
1618677792.0407941: {"topic":"orderBookL2_25.EOSUSD","type":"delta","data":{"delete":[],"update":[{"price":"7.982","symbol":"EOSUSD","id":79820,"side":"Sell","size":102595},{"price":"7.984","symbol":"EOSUSD","id":79840,"side":"Sell","size":131336},{"price":"7.970","symbol":"EOSUSD","id":79700,"side":"Buy","size":46373},{"price":"7.967","symbol":"EOSUSD","id":79670,"side":"Buy","size":107117},{"price":"7.962","symbol":"EOSUSD","id":79620,"side":"Buy","size":60510},{"price":"7.968","symbol":"EOSUSD","id":79680,"side":"Buy","size":37094},{"price":"7.965","symbol":"EOSUSD","id":79650,"side":"Buy","size":11606}],"insert":[],"transactTimeE6":0},"cross_seq":1225777549,"timestamp_e6":1618677791958111}
1618677792.0579: {"topic":"trade.BTCUSD","data":[{"trade_time_ms":1618677791918,"timestamp":"2021-04-17T16:43:11.000Z","symbol":"BTCUSD","side":"Buy","size":4000,"price":60623,"tick_direction":"ZeroPlusTick","trade_id":"b258713a-7b69-55e3-bfc0-c0e23b595e2b","cross_seq":5938956667}]}
1618677792.0802739: {"topic":"orderBookL2_25.EOSUSD","type":"delta","data":{"delete":[],"update":[{"price":"7.983","symbol":"EOSUSD","id":79830,"side":"Sell","size":132998},{"price":"7.968","symbol":"EOSUSD","id":79680,"side":"Buy","size":31270}],"insert":[],"transactTimeE6":0},"cross_seq":1225777551,"timestamp_e6":1618677791998122}
1618677792.1411881: {"topic":"orderBookL2_25.EOSUSD","type":"delta","data":{"delete":[],"update":[{"price":"7.971","symbol":"EOSUSD","id":79710,"side":"Buy","size":67071}],"insert":[],"transactTimeE6":0},"cross_seq":1225777553,"timestamp_e6":1618677792058756}
1618677792.163788: {"topic":"orderBookL2_25.EOSUSD","type":"delta","data":{"delete":[],"update":[{"price":"7.971","symbol":"EOSUSD","id":79710,"side":"Buy","size":60820}],"insert":[],"transactTimeE6":0},"cross_seq":1225777554,"timestamp_e6":1618677792078779}
1618677792.200897: {"topic":"orderBookL2_25.BTCUSD","type":"delta","data":{"delete":[],"update":[{"price":"60623.00","symbol":"BTCUSD","id":606230000,"side":"Sell","size":619194}],"insert":[],"transactTimeE6":0},"cross_seq":5938956672,"timestamp_e6":1618677792117898}
1618677792.2411299: {"topic":"orderBookL2_25.EOSUSD","type":"delta","data":{"delete":[],"update":[{"price":"7.961","symbol":"EOSUSD","id":79610,"side":"Buy","size":30645},{"price":"7.964","symbol":"EOSUSD","id":79640,"side":"Buy","size":55874},{"price":"7.962","symbol":"EOSUSD","id":79620,"side":"Buy","size":52260},{"price":"7.963","symbol":"EOSUSD","id":79630,"side":"Buy","size":49519}],"insert":[],"transactTimeE6":0},"cross_seq":1225777560,"timestamp_e6":1618677792158131}
1618677792.255323: {"topic":"trade.BTCUSD","data":[{"trade_time_ms":1618677792092,"timestamp":"2021-04-17T16:43:12.000Z","symbol":"BTCUSD","side":"Buy","size":4444,"price":60623,"tick_direction":"ZeroPlusTick","trade_id":"f49c1f99-ed2e-57d3-ba92-0c00edc47336","cross_seq":5938956674}]}
1618677792.302083: {"topic":"orderBookL2_25.EOSUSD","type":"delta","data":{"delete":[],"update":[{"price":"7.972","symbol":"EOSUSD","id":79720,"side":"Sell","size":106111}],"insert":[],"transactTimeE6":0},"cross_seq":1225777561,"timestamp_e6":1618677792218747}
1618677792.320369: {"topic":"orderBookL2_25.BTCUSD","type":"delta","data":{"delete":[],"update":[{"price":"60619.00","symbol":"BTCUSD","id":606190000,"side":"Buy","size":13920}],"insert":[],"transactTimeE6":0},"cross_seq":5938956680,"timestamp_e6":1618677792237253}
1618677792.321321: {"topic":"orderBookL2_25.EOSUSD","type":"delta","data":{"delete":[],"update":[{"price":"7.966","symbol":"EOSUSD","id":79660,"side":"Buy","size":63212}],"insert":[],"transactTimeE6":0},"cross_seq":1225777562,"timestamp_e6":1618677792238162}
1618677792.340292: {"topic":"orderBookL2_25.EOSUSD","type":"delta","data":{"delete":[],"update":[{"price":"7.961","symbol":"EOSUSD","id":79610,"side":"Buy","size":36738}],"insert":[],"transactTimeE6":0},"cross_seq":1225777563,"timestamp_e6":1618677792258108}
1618677792.358604: {"topic":"trade.EOSUSD","data":[{"trade_time_ms":1618677792209,"timestamp":"2021-04-17T16:43:12.000Z","symbol":"EOSUSD","side":"Buy","size":114,"price":7.972,"tick_direction":"ZeroPlusTick","trade_id":"d96060f2-4f0a-5e84-8fc3-2c6e9fbae26d","cross_seq":1225777563}]}
1618677792.381005: {"topic":"orderBookL2_25.EOSUSD","type":"delta","data":{"delete":[],"update":[{"price":"7.971","symbol":"EOSUSD","id":79710,"side":"Buy","size":67185},{"price":"7.983","symbol":"EOSUSD","id":79830,"side":"Sell","size":126499}],"insert":[],"transactTimeE6":0},"cross_seq":1225777565,"timestamp_e6":1618677792298739}
1618677792.40128: {"topic":"orderBookL2_25.EOSUSD","type":"delta","data":{"delete":[],"update":[{"price":"7.971","symbol":"EOSUSD","id":79710,"side":"Buy","size":60820}],"insert":[],"transactTimeE6":0},"cross_seq":1225777566,"timestamp_e6":1618677792318736}
1618677792.4204009: {"topic":"orderBookL2_25.EOSUSD","type":"delta","data":{"delete":[],"update":[{"price":"7.980","symbol":"EOSUSD","id":79800,"side":"Sell","size":134070}],"insert":[],"transactTimeE6":0},"cross_seq":1225777567,"timestamp_e6":1618677792338111}
1618677792.481743: {"topic":"orderBookL2_25.EOSUSD","type":"delta","data":{"delete":[],"update":[{"price":"7.976","symbol":"EOSUSD","id":79760,"side":"Sell","size":37289},{"price":"7.960","symbol":"EOSUSD","id":79600,"side":"Buy","size":26784},{"price":"7.971","symbol":"EOSUSD","id":79710,"side":"Buy","size":67185}],"insert":[],"transactTimeE6":0},"cross_seq":1225777571,"timestamp_e6":1618677792398840}
1618677792.580968: {"topic":"orderBookL2_25.EOSUSD","type":"delta","data":{"delete":[],"update":[{"price":"7.971","symbol":"EOSUSD","id":79710,"side":"Buy","size":60820}],"insert":[],"transactTimeE6":0},"cross_seq":1225777574,"timestamp_e6":1618677792498727}
1618677792.6016939: {"topic":"orderBookL2_25.EOSUSD","type":"delta","data":{"delete":[],"update":[{"price":"7.961","symbol":"EOSUSD","id":79610,"side":"Buy","size":48362},{"price":"7.959","symbol":"EOSUSD","id":79590,"side":"Buy","size":21720},{"price":"7.964","symbol":"EOSUSD","id":79640,"side":"Buy","size":8836},{"price":"7.960","symbol":"EOSUSD","id":79600,"side":"Buy","size":45115},{"price":"7.974","symbol":"EOSUSD","id":79740,"side":"Sell","size":25774},{"price":"7.962","symbol":"EOSUSD","id":79620,"side":"Buy","size":36698}],"insert":[],"transactTimeE6":0},"cross_seq":1225777581,"timestamp_e6":1618677792518150}
1618677792.680009: {"topic":"orderBookL2_25.EOSUSD","type":"delta","data":{"delete":[],"update":[{"price":"7.980","symbol":"EOSUSD","id":79800,"side":"Sell","size":123543}],"insert":[],"transactTimeE6":0},"cross_seq":1225777582,"timestamp_e6":1618677792598113}
1618677792.721747: {"topic":"orderBookL2_25.BTCUSD","type":"delta","data":{"delete":[{"price":"60605.50","symbol":"BTCUSD","id":606055000,"side":"Buy"}],"update":[],"insert":[{"price":"60610.50","symbol":"BTCUSD","id":606105000,"side":"Buy","size":35}],"transactTimeE6":0},"cross_seq":5938956690,"timestamp_e6":1618677792637301}
1618677792.7415638: {"topic":"orderBookL2_25.EOSUSD","type":"delta","data":{"delete":[],"update":[{"price":"7.962","symbol":"EOSUSD","id":79620,"side":"Buy","size":43940},{"price":"7.959","symbol":"EOSUSD","id":79590,"side":"Buy","size":31745},{"price":"7.963","symbol":"EOSUSD","id":79630,"side":"Buy","size":38715},{"price":"7.974","symbol":"EOSUSD","id":79740,"side":"Sell","size":39609},{"price":"7.964","symbol":"EOSUSD","id":79640,"side":"Buy","size":47068}],"insert":[],"transactTimeE6":0},"cross_seq":1225777587,"timestamp_e6":1618677792658101}
1618677792.779922: {"topic":"orderBookL2_25.BTCUSD","type":"delta","data":{"delete":[],"update":[{"price":"60622.00","symbol":"BTCUSD","id":606220000,"side":"Buy","size":142876}],"insert":[],"transactTimeE6":0},"cross_seq":5938956692,"timestamp_e6":1618677792697381}
1618677792.801803: {"topic":"orderBookL2_25.BTCUSD","type":"delta","data":{"delete":[],"update":[{"price":"60622.50","symbol":"BTCUSD","id":606225000,"side":"Buy","size":9906026}],"insert":[],"transactTimeE6":0},"cross_seq":5938956695,"timestamp_e6":1618677792717916}
1618677792.8242612: {"topic":"orderBookL2_25.EOSUSD","type":"delta","data":{"delete":[],"update":[{"price":"7.971","symbol":"EOSUSD","id":79710,"side":"Buy","size":53709}],"insert":[],"transactTimeE6":0},"cross_seq":1225777588,"timestamp_e6":1618677792738760}
1618677792.8418078: {"topic":"orderBookL2_25.BTCUSD","type":"delta","data":{"delete":[],"update":[{"price":"60619.00","symbol":"BTCUSD","id":606190000,"side":"Buy","size":73920}],"insert":[],"transactTimeE6":0},"cross_seq":5938956697,"timestamp_e6":1618677792757305}
1618677792.863652: {"topic":"orderBookL2_25.EOSUSD","type":"delta","data":{"delete":[],"update":[{"price":"7.963","symbol":"EOSUSD","id":79630,"side":"Buy","size":43618},{"price":"7.977","symbol":"EOSUSD","id":79770,"side":"Sell","size":87938}],"insert":[],"transactTimeE6":0},"cross_seq":1225777592,"timestamp_e6":1618677792778280}
1618677792.941082: {"topic":"orderBookL2_25.EOSUSD","type":"delta","data":{"delete":[{"price":"7.970","symbol":"EOSUSD","id":79700,"side":"Buy"},{"price":"7.969","symbol":"EOSUSD","id":79690,"side":"Buy"}],"update":[{"price":"7.968","symbol":"EOSUSD","id":79680,"side":"Buy","size":100},{"price":"7.966","symbol":"EOSUSD","id":79660,"side":"Buy","size":23471},{"price":"7.960","symbol":"EOSUSD","id":79600,"side":"Buy","size":49893},{"price":"7.961","symbol":"EOSUSD","id":79610,"side":"Buy","size":51617},{"price":"7.957","symbol":"EOSUSD","id":79570,"side":"Buy","size":35000},{"price":"7.964","symbol":"EOSUSD","id":79640,"side":"Buy","size":8836},{"price":"7.958","symbol":"EOSUSD","id":79580,"side":"Buy","size":36157},{"price":"7.959","symbol":"EOSUSD","id":79590,"side":"Buy","size":34821},{"price":"7.962","symbol":"EOSUSD","id":79620,"side":"Buy","size":20133},{"price":"7.963","symbol":"EOSUSD","id":79630,"side":"Buy","size":19286},{"price":"7.967","symbol":"EOSUSD","id":79670,"side":"Buy","size":90462}],"insert":[{"price":"7.946","symbol":"EOSUSD","id":79460,"side":"Buy","size":96718},{"price":"7.945","symbol":"EOSUSD","id":79450,"side":"Buy","size":19617}],"transactTimeE6":0},"cross_seq":1225777612,"timestamp_e6":1618677792858164}
1618677792.9603782: {"topic":"orderBookL2_25.EOSUSD","type":"delta","data":{"delete":[],"update":[{"price":"7.965","symbol":"EOSUSD","id":79650,"side":"Buy","size":33997},{"price":"7.964","symbol":"EOSUSD","id":79640,"side":"Buy","size":27710},{"price":"7.963","symbol":"EOSUSD","id":79630,"side":"Buy","size":7509},{"price":"7.966","symbol":"EOSUSD","id":79660,"side":"Buy","size":52944}],"insert":[],"transactTimeE6":0},"cross_seq":1225777618,"timestamp_e6":1618677792878108}
1618677792.981426: {"topic":"orderBookL2_25.EOSUSD","type":"delta","data":{"delete":[],"update":[{"price":"7.960","symbol":"EOSUSD","id":79600,"side":"Buy","size":26784},{"price":"7.961","symbol":"EOSUSD","id":79610,"side":"Buy","size":10077},{"price":"7.954","symbol":"EOSUSD","id":79540,"side":"Buy","size":64941},{"price":"7.959","symbol":"EOSUSD","id":79590,"side":"Buy","size":58260},{"price":"7.971","symbol":"EOSUSD","id":79710,"side":"Buy","size":28393},{"price":"7.956","symbol":"EOSUSD","id":79560,"side":"Buy","size":72454},{"price":"7.955","symbol":"EOSUSD","id":79550,"side":"Buy","size":104659},{"price":"7.957","symbol":"EOSUSD","id":79570,"side":"Buy","size":26607}],"insert":[],"transactTimeE6":0},"cross_seq":1225777630,"timestamp_e6":1618677792898719}
1618677793.0029812: {"topic":"orderBookL2_25.EOSUSD","type":"delta","data":{"delete":[],"update":[{"price":"7.971","symbol":"EOSUSD","id":79710,"side":"Buy","size":13393},{"price":"7.972","symbol":"EOSUSD","id":79720,"side":"Sell","size":131064}],"insert":[],"transactTimeE6":0},"cross_seq":1225777633,"timestamp_e6":1618677792919389}
1618677793.041976: {"topic":"orderBookL2_25.BTCUSD","type":"delta","data":{"delete":[],"update":[{"price":"60615.50","symbol":"BTCUSD","id":606155000,"side":"Buy","size":67}],"insert":[],"transactTimeE6":0},"cross_seq":5938956704,"timestamp_e6":1618677792957325}
1618677793.042018: {"topic":"orderBookL2_25.EOSUSD","type":"delta","data":{"delete":[{"price":"7.971","symbol":"EOSUSD","id":79710,"side":"Buy"}],"update":[{"price":"7.966","symbol":"EOSUSD","id":79660,"side":"Buy","size":46905}],"insert":[{"price":"7.944","symbol":"EOSUSD","id":79440,"side":"Buy","size":106734}],"transactTimeE6":0},"cross_seq":1225777635,"timestamp_e6":1618677792958740}
1618677793.063979: {"topic":"orderBookL2_25.EOSUSD","type":"delta","data":{"delete":[{"price":"7.996","symbol":"EOSUSD","id":79960,"side":"Sell"},{"price":"7.964","symbol":"EOSUSD","id":79640,"side":"Buy"}],"update":[{"price":"7.972","symbol":"EOSUSD","id":79720,"side":"Sell","size":82111},{"price":"7.963","symbol":"EOSUSD","id":79630,"side":"Buy","size":11893},{"price":"7.968","symbol":"EOSUSD","id":79680,"side":"Buy","size":26969},{"price":"7.954","symbol":"EOSUSD","id":79540,"side":"Buy","size":75504},{"price":"7.984","symbol":"EOSUSD","id":79840,"side":"Sell","size":116470}],"insert":[{"price":"7.969","symbol":"EOSUSD","id":79690,"side":"Sell","size":19955},{"price":"7.943","symbol":"EOSUSD","id":79430,"side":"Buy","size":154219}],"transactTimeE6":0},"cross_seq":1225777663,"timestamp_e6":1618677792979548}
1618677793.0812302: {"topic":"orderBookL2_25.EOSUSD","type":"delta","data":{"delete":[{"price":"7.995","symbol":"EOSUSD","id":79950,"side":"Sell"}],"update":[{"price":"7.965","symbol":"EOSUSD","id":79650,"side":"Buy","size":74418},{"price":"7.977","symbol":"EOSUSD","id":79770,"side":"Sell","size":80213}],"insert":[{"price":"7.970","symbol":"EOSUSD","id":79700,"side":"Sell","size":26666}],"transactTimeE6":0},"cross_seq":1225777667,"timestamp_e6":1618677792998098}
1618677793.100342: {"topic":"orderBookL2_25.EOSUSD","type":"delta","data":{"delete":[{"price":"7.970","symbol":"EOSUSD","id":79700,"side":"Sell"}],"update":[{"price":"7.972","symbol":"EOSUSD","id":79720,"side":"Sell","size":78975},{"price":"7.975","symbol":"EOSUSD","id":79750,"side":"Sell","size":35885},{"price":"7.973","symbol":"EOSUSD","id":79730,"side":"Sell","size":15809}],"insert":[{"price":"7.971","symbol":"EOSUSD","id":79710,"side":"Sell","size":51680}],"transactTimeE6":0},"cross_seq":1225777675,"timestamp_e6":1618677793018101}
1618677793.1214788: {"topic":"orderBookL2_25.EOSUSD","type":"delta","data":{"delete":[],"update":[{"price":"7.967","symbol":"EOSUSD","id":79670,"side":"Buy","size":88847},{"price":"7.974","symbol":"EOSUSD","id":79740,"side":"Sell","size":52508},{"price":"7.972","symbol":"EOSUSD","id":79720,"side":"Sell","size":78337},{"price":"7.965","symbol":"EOSUSD","id":79650,"side":"Buy","size":76033},{"price":"7.973","symbol":"EOSUSD","id":79730,"side":"Sell","size":44271},{"price":"7.969","symbol":"EOSUSD","id":79690,"side":"Sell","size":20637}],"insert":[],"transactTimeE6":0},"cross_seq":1225777680,"timestamp_e6":1618677793038702}
1618677793.141338: {"topic":"orderBookL2_25.EOSUSD","type":"delta","data":{"delete":[],"update":[{"price":"7.972","symbol":"EOSUSD","id":79720,"side":"Sell","size":64999},{"price":"7.969","symbol":"EOSUSD","id":79690,"side":"Sell","size":24022}],"insert":[],"transactTimeE6":0},"cross_seq":1225777682,"timestamp_e6":1618677793058847}
1618677793.16064: {"topic":"orderBookL2_25.EOSUSD","type":"delta","data":{"delete":[],"update":[{"price":"7.967","symbol":"EOSUSD","id":79670,"side":"Buy","size":37146}],"insert":[],"transactTimeE6":0},"cross_seq":1225777683,"timestamp_e6":1618677793078103}
1618677793.202325: {"topic":"orderBookL2_25.EOSUSD","type":"delta","data":{"delete":[{"price":"7.943","symbol":"EOSUSD","id":79430,"side":"Buy"}],"update":[{"price":"7.956","symbol":"EOSUSD","id":79560,"side":"Buy","size":63362},{"price":"7.972","symbol":"EOSUSD","id":79720,"side":"Sell","size":63999},{"price":"7.955","symbol":"EOSUSD","id":79550,"side":"Buy","size":92724},{"price":"7.966","symbol":"EOSUSD","id":79660,"side":"Buy","size":37143},{"price":"7.959","symbol":"EOSUSD","id":79590,"side":"Buy","size":48235},{"price":"7.960","symbol":"EOSUSD","id":79600,"side":"Buy","size":64097},{"price":"7.984","symbol":"EOSUSD","id":79840,"side":"Sell","size":129561},{"price":"7.958","symbol":"EOSUSD","id":79580,"side":"Buy","size":23118},{"price":"7.957","symbol":"EOSUSD","id":79570,"side":"Buy","size":42327},{"price":"7.968","symbol":"EOSUSD","id":79680,"side":"Buy","size":46969}],"insert":[{"price":"7.964","symbol":"EOSUSD","id":79640,"side":"Buy","size":14454}],"transactTimeE6":0},"cross_seq":1225777694,"timestamp_e6":1618677793118778}
1618677793.240505: {"topic":"orderBookL2_25.EOSUSD","type":"delta","data":{"delete":[],"update":[{"price":"7.959","symbol":"EOSUSD","id":79590,"side":"Buy","size":45159},{"price":"7.957","symbol":"EOSUSD","id":79570,"side":"Buy","size":30614}],"insert":[],"transactTimeE6":0},"cross_seq":1225777696,"timestamp_e6":1618677793158081}
1618677793.280997: {"topic":"orderBookL2_25.EOSUSD","type":"delta","data":{"delete":[{"price":"7.967","symbol":"EOSUSD","id":79670,"side":"Buy"}],"update":[{"price":"7.968","symbol":"EOSUSD","id":79680,"side":"Buy","size":47969}],"insert":[{"price":"7.943","symbol":"EOSUSD","id":79430,"side":"Buy","size":154219}],"transactTimeE6":0},"cross_seq":1225777698,"timestamp_e6":1618677793198748}
1618677793.301209: {"topic":"orderBookL2_25.EOSUSD","type":"delta","data":{"delete":[],"update":[{"price":"7.979","symbol":"EOSUSD","id":79790,"side":"Sell","size":19023}],"insert":[],"transactTimeE6":0},"cross_seq":1225777699,"timestamp_e6":1618677793218100}
1618677793.320864: {"topic":"orderBookL2_25.BTCUSD","type":"delta","data":{"delete":[],"update":[{"price":"60617.50","symbol":"BTCUSD","id":606175000,"side":"Buy","size":2122}],"insert":[],"transactTimeE6":0},"cross_seq":5938956712,"timestamp_e6":1618677793237323}
1618677793.3219688: {"topic":"orderBookL2_25.EOSUSD","type":"delta","data":{"delete":[],"update":[{"price":"7.983","symbol":"EOSUSD","id":79830,"side":"Sell","size":110160}],"insert":[],"transactTimeE6":0},"cross_seq":1225777711,"timestamp_e6":1618677793238114}
1618677793.362457: {"topic":"orderBookL2_25.EOSUSD","type":"delta","data":{"delete":[],"update":[{"price":"7.968","symbol":"EOSUSD","id":79680,"side":"Buy","size":62969},{"price":"7.969","symbol":"EOSUSD","id":79690,"side":"Sell","size":37355}],"insert":[],"transactTimeE6":0},"cross_seq":1225777713,"timestamp_e6":1618677793279378}
1618677793.380665: {"topic":"orderBookL2_25.BTCUSD","type":"delta","data":{"delete":[],"update":[{"price":"60622.50","symbol":"BTCUSD","id":606225000,"side":"Buy","size":9906023}],"insert":[],"transactTimeE6":0},"cross_seq":5938956715,"timestamp_e6":1618677793297961}
1618677793.380696: {"topic":"orderBookL2_25.EOSUSD","type":"delta","data":{"delete":[],"update":[{"price":"7.957","symbol":"EOSUSD","id":79570,"side":"Buy","size":39488}],"insert":[],"transactTimeE6":0},"cross_seq":1225777715,"timestamp_e6":1618677793298114}
1618677793.401406: {"topic":"orderBookL2_25.EOSUSD","type":"delta","data":{"delete":[],"update":[{"price":"7.968","symbol":"EOSUSD","id":79680,"side":"Buy","size":61969}],"insert":[],"transactTimeE6":0},"cross_seq":1225777716,"timestamp_e6":1618677793318746}
1618677793.4418418: {"topic":"orderBookL2_25.EOSUSD","type":"delta","data":{"delete":[],"update":[{"price":"7.982","symbol":"EOSUSD","id":79820,"side":"Sell","size":113600},{"price":"7.983","symbol":"EOSUSD","id":79830,"side":"Sell","size":122506}],"insert":[],"transactTimeE6":0},"cross_seq":1225777719,"timestamp_e6":1618677793358139}
1618677793.455702: {"topic":"trade.BTCUSD","data":[{"trade_time_ms":1618677793273,"timestamp":"2021-04-17T16:43:13.000Z","symbol":"BTCUSD","side":"Sell","size":3,"price":60622.5,"tick_direction":"MinusTick","trade_id":"4f7dedca-e9ab-506e-bded-554aa313a827","cross_seq":5938956715}]}
1618677793.500876: {"topic":"orderBookL2_25.EOSUSD","type":"delta","data":{"delete":[],"update":[{"price":"7.974","symbol":"EOSUSD","id":79740,"side":"Sell","size":60233},{"price":"7.957","symbol":"EOSUSD","id":79570,"side":"Buy","size":23768},{"price":"7.955","symbol":"EOSUSD","id":79550,"side":"Buy","size":99621}],"insert":[],"transactTimeE6":0},"cross_seq":1225777722,"timestamp_e6":1618677793418160}
1618677793.5406861: {"topic":"orderBookL2_25.BTCUSD","type":"delta","data":{"delete":[],"update":[{"price":"60621.50","symbol":"BTCUSD","id":606215000,"side":"Buy","size":351032}],"insert":[],"transactTimeE6":0},"cross_seq":5938956718,"timestamp_e6":1618677793457272}
1618677793.561986: {"topic":"orderBookL2_25.EOSUSD","type":"delta","data":{"delete":[],"update":[{"price":"7.972","symbol":"EOSUSD","id":79720,"side":"Sell","size":52078},{"price":"7.974","symbol":"EOSUSD","id":79740,"side":"Sell","size":48235}],"insert":[],"transactTimeE6":0},"cross_seq":1225777724,"timestamp_e6":1618677793478116}
1618677793.62286: {"topic":"orderBookL2_25.BTCUSD","type":"delta","data":{"delete":[],"update":[{"price":"60622.50","symbol":"BTCUSD","id":606225000,"side":"Buy","size":9909523}],"insert":[],"transactTimeE6":0},"cross_seq":5938956722,"timestamp_e6":1618677793539179}
1618677793.6413949: {"topic":"orderBookL2_25.BTCUSD","type":"delta","data":{"delete":[],"update":[{"price":"60623.00","symbol":"BTCUSD","id":606230000,"side":"Sell","size":600512}],"insert":[],"transactTimeE6":0},"cross_seq":5938956725,"timestamp_e6":1618677793557959}
1618677793.6586728: {"topic":"trade.BTCUSD","data":[{"trade_time_ms":1618677793538,"timestamp":"2021-04-17T16:43:13.000Z","symbol":"BTCUSD","side":"Buy","size":18682,"price":60623,"tick_direction":"PlusTick","trade_id":"35e84ae6-282c-5fbd-bbfe-8660ad411d85","cross_seq":5938956727}]}
1618677793.70115: {"topic":"orderBookL2_25.EOSUSD","type":"delta","data":{"delete":[],"update":[{"price":"7.958","symbol":"EOSUSD","id":79580,"side":"Buy","size":35017},{"price":"7.956","symbol":"EOSUSD","id":79560,"side":"Buy","size":46245},{"price":"7.960","symbol":"EOSUSD","id":79600,"side":"Buy","size":26784},{"price":"7.959","symbol":"EOSUSD","id":79590,"side":"Buy","size":58710},{"price":"7.961","symbol":"EOSUSD","id":79610,"side":"Buy","size":5164},{"price":"7.957","symbol":"EOSUSD","id":79570,"side":"Buy","size":29707},{"price":"7.954","symbol":"EOSUSD","id":79540,"side":"Buy","size":83007}],"insert":[],"transactTimeE6":0},"cross_seq":1225777731,"timestamp_e6":1618677793618103}
1618677793.740248: {"topic":"orderBookL2_25.EOSUSD","type":"delta","data":{"delete":[],"update":[{"price":"7.964","symbol":"EOSUSD","id":79640,"side":"Buy","size":55156}],"insert":[],"transactTimeE6":0},"cross_seq":1225777732,"timestamp_e6":1618677793658117}
1618677793.763562: {"topic":"orderBookL2_25.EOSUSD","type":"delta","data":{"delete":[],"update":[{"price":"7.956","symbol":"EOSUSD","id":79560,"side":"Buy","size":56239},{"price":"7.968","symbol":"EOSUSD","id":79680,"side":"Buy","size":117280}],"insert":[],"transactTimeE6":0},"cross_seq":1225777734,"timestamp_e6":1618677793678806}
1618677793.7795599: {"topic":"orderBookL2_25.BTCUSD","type":"delta","data":{"delete":[],"update":[{"price":"60617.50","symbol":"BTCUSD","id":606175000,"side":"Buy","size":2125}],"insert":[],"transactTimeE6":0},"cross_seq":5938956733,"timestamp_e6":1618677793697344}
1618677793.800969: {"topic":"orderBookL2_25.EOSUSD","type":"delta","data":{"delete":[],"update":[{"price":"7.969","symbol":"EOSUSD","id":79690,"side":"Sell","size":24022}],"insert":[],"transactTimeE6":0},"cross_seq":1225777735,"timestamp_e6":1618677793718762}
1618677793.841822: {"topic":"orderBookL2_25.EOSUSD","type":"delta","data":{"delete":[],"update":[{"price":"7.968","symbol":"EOSUSD","id":79680,"side":"Buy","size":118280},{"price":"7.961","symbol":"EOSUSD","id":79610,"side":"Buy","size":8109}],"insert":[],"transactTimeE6":0},"cross_seq":1225777737,"timestamp_e6":1618677793759325}
1618677793.9409542: {"topic":"orderBookL2_25.EOSUSD","type":"delta","data":{"delete":[],"update":[{"price":"7.964","symbol":"EOSUSD","id":79640,"side":"Buy","size":106771},{"price":"7.973","symbol":"EOSUSD","id":79730,"side":"Sell","size":96080}],"insert":[],"transactTimeE6":0},"cross_seq":1225777740,"timestamp_e6":1618677793858110}
1618677793.959136: {"topic":"trade.BTCUSD","data":[{"trade_time_ms":1618677793855,"timestamp":"2021-04-17T16:43:13.000Z","symbol":"BTCUSD","side":"Sell","size":2000,"price":60622.5,"tick_direction":"MinusTick","trade_id":"4424073f-b1a2-5047-aab8-00ac4ae75039","cross_seq":5938956737}]}
1618677793.962333: {"topic":"orderBookL2_25.BTCUSD","type":"delta","data":{"delete":[],"update":[{"price":"60622.50","symbol":"BTCUSD","id":606225000,"side":"Buy","size":9907523}],"insert":[],"transactTimeE6":0},"cross_seq":5938956737,"timestamp_e6":1618677793877915}
1618677793.9623628: {"topic":"orderBookL2_25.EOSUSD","type":"delta","data":{"delete":[],"update":[{"price":"7.983","symbol":"EOSUSD","id":79830,"side":"Sell","size":128153},{"price":"7.963","symbol":"EOSUSD","id":79630,"side":"Buy","size":27792},{"price":"7.961","symbol":"EOSUSD","id":79610,"side":"Buy","size":13038},{"price":"7.982","symbol":"EOSUSD","id":79820,"side":"Sell","size":99066},{"price":"7.979","symbol":"EOSUSD","id":79790,"side":"Sell","size":70557}],"insert":[],"transactTimeE6":0},"cross_seq":1225777746,"timestamp_e6":1618677793878097}
1618677794.002548: {"topic":"orderBookL2_25.EOSUSD","type":"delta","data":{"delete":[],"update":[{"price":"7.968","symbol":"EOSUSD","id":79680,"side":"Buy","size":131613}],"insert":[],"transactTimeE6":0},"cross_seq":1225777747,"timestamp_e6":1618677793918793}
1618677794.0803049: {"topic":"orderBookL2_25.EOSUSD","type":"delta","data":{"delete":[],"update":[{"price":"7.962","symbol":"EOSUSD","id":79620,"side":"Buy","size":14831},{"price":"7.982","symbol":"EOSUSD","id":79820,"side":"Sell","size":117616}],"insert":[],"transactTimeE6":0},"cross_seq":1225777749,"timestamp_e6":1618677793998107}
1618677794.22063: {"topic":"orderBookL2_25.EOSUSD","type":"delta","data":{"delete":[],"update":[{"price":"7.962","symbol":"EOSUSD","id":79620,"side":"Buy","size":17709}],"insert":[],"transactTimeE6":0},"cross_seq":1225777750,"timestamp_e6":1618677794138113}
1618677794.2419672: {"topic":"orderBookL2_25.BTCUSD","type":"delta","data":{"delete":[],"update":[{"price":"60623.00","symbol":"BTCUSD","id":606230000,"side":"Sell","size":600513}],"insert":[],"transactTimeE6":0},"cross_seq":5938956743,"timestamp_e6":1618677794159123}
1618677794.256093: {"topic":"trade.BTCUSD","data":[{"trade_time_ms":1618677794165,"timestamp":"2021-04-17T16:43:14.000Z","symbol":"BTCUSD","side":"Sell","size":341,"price":60622.5,"tick_direction":"ZeroMinusTick","trade_id":"4714208b-069c-5930-a64a-fbb24461b4b0","cross_seq":5938956745}]}
1618677794.261051: {"topic":"orderBookL2_25.BTCUSD","type":"delta","data":{"delete":[],"update":[{"price":"60622.50","symbol":"BTCUSD","id":606225000,"side":"Buy","size":9907182}],"insert":[],"transactTimeE6":0},"cross_seq":5938956745,"timestamp_e6":1618677794178055}
1618677794.301541: {"topic":"orderBookL2_25.BTCUSD","type":"delta","data":{"delete":[],"update":[{"price":"60634.50","symbol":"BTCUSD","id":606345000,"side":"Sell","size":21870}],"insert":[],"transactTimeE6":0},"cross_seq":5938956746,"timestamp_e6":1618677794217304}
1618677794.441817: {"topic":"orderBookL2_25.BTCUSD","type":"delta","data":{"delete":[],"update":[{"price":"60622.50","symbol":"BTCUSD","id":606225000,"side":"Buy","size":9907186}],"insert":[],"transactTimeE6":0},"cross_seq":5938956749,"timestamp_e6":1618677794357982}
1618677794.4809291: {"topic":"orderBookL2_25.EOSUSD","type":"delta","data":{"delete":[],"update":[{"price":"7.984","symbol":"EOSUSD","id":79840,"side":"Sell","size":120277}],"insert":[],"transactTimeE6":0},"cross_seq":1225777752,"timestamp_e6":1618677794398118}
1618677794.5206468: {"topic":"orderBookL2_25.EOSUSD","type":"delta","data":{"delete":[{"price":"7.971","symbol":"EOSUSD","id":79710,"side":"Sell"}],"update":[{"price":"7.957","symbol":"EOSUSD","id":79570,"side":"Buy","size":20833},{"price":"7.974","symbol":"EOSUSD","id":79740,"side":"Sell","size":34459},{"price":"7.954","symbol":"EOSUSD","id":79540,"side":"Buy","size":72444},{"price":"7.976","symbol":"EOSUSD","id":79760,"side":"Sell","size":23381}],"insert":[{"price":"7.995","symbol":"EOSUSD","id":79950,"side":"Sell","size":28016}],"transactTimeE6":0},"cross_seq":1225777757,"timestamp_e6":1618677794438121}
1618677794.601194: {"topic":"orderBookL2_25.EOSUSD","type":"delta","data":{"delete":[],"update":[{"price":"7.969","symbol":"EOSUSD","id":79690,"side":"Sell","size":23415}],"insert":[],"transactTimeE6":0},"cross_seq":1225777758,"timestamp_e6":1618677794518714}
1618677794.662813: {"topic":"orderBookL2_25.EOSUSD","type":"delta","data":{"delete":[{"price":"7.995","symbol":"EOSUSD","id":79950,"side":"Sell"}],"update":[{"price":"7.957","symbol":"EOSUSD","id":79570,"side":"Buy","size":26851},{"price":"7.969","symbol":"EOSUSD","id":79690,"side":"Sell","size":24022},{"price":"7.973","symbol":"EOSUSD","id":79730,"side":"Sell","size":81569}],"insert":[{"price":"7.971","symbol":"EOSUSD","id":79710,"side":"Sell","size":45009}],"transactTimeE6":0},"cross_seq":1225777763,"timestamp_e6":1618677794578750}
1618677794.720217: {"topic":"orderBookL2_25.EOSUSD","type":"delta","data":{"delete":[],"update":[{"price":"7.959","symbol":"EOSUSD","id":79590,"side":"Buy","size":21720},{"price":"7.957","symbol":"EOSUSD","id":79570,"side":"Buy","size":20912},{"price":"7.961","symbol":"EOSUSD","id":79610,"side":"Buy","size":44156},{"price":"7.958","symbol":"EOSUSD","id":79580,"side":"Buy","size":22468},{"price":"7.960","symbol":"EOSUSD","id":79600,"side":"Buy","size":38943},{"price":"7.962","symbol":"EOSUSD","id":79620,"side":"Buy","size":53813}],"insert":[],"transactTimeE6":0},"cross_seq":1225777770,"timestamp_e6":1618677794638132}
1618677794.780303: {"topic":"orderBookL2_25.EOSUSD","type":"delta","data":{"delete":[],"update":[{"price":"7.958","symbol":"EOSUSD","id":79580,"side":"Buy","size":30679},{"price":"7.957","symbol":"EOSUSD","id":79570,"side":"Buy","size":23734},{"price":"7.959","symbol":"EOSUSD","id":79590,"side":"Buy","size":30901}],"insert":[],"transactTimeE6":0},"cross_seq":1225777773,"timestamp_e6":1618677794698121}
1618677794.8223848: {"topic":"orderBookL2_25.BTCUSD","type":"delta","data":{"delete":[],"update":[{"price":"60622.50","symbol":"BTCUSD","id":606225000,"side":"Buy","size":9916186}],"insert":[],"transactTimeE6":0},"cross_seq":5938956753,"timestamp_e6":1618677794737887}
1618677794.841711: {"topic":"orderBookL2_25.BTCUSD","type":"delta","data":{"delete":[],"update":[{"price":"60622.50","symbol":"BTCUSD","id":606225000,"side":"Buy","size":9934186}],"insert":[],"transactTimeE6":0},"cross_seq":5938956756,"timestamp_e6":1618677794757943}
1618677794.881983: {"topic":"orderBookL2_25.BTCUSD","type":"delta","data":{"delete":[],"update":[{"price":"60622.50","symbol":"BTCUSD","id":606225000,"side":"Buy","size":9943186}],"insert":[],"transactTimeE6":0},"cross_seq":5938956761,"timestamp_e6":1618677794797958}
1618677794.9009469: {"topic":"orderBookL2_25.EOSUSD","type":"delta","data":{"delete":[],"update":[{"price":"7.973","symbol":"EOSUSD","id":79730,"side":"Sell","size":90424}],"insert":[],"transactTimeE6":0},"cross_seq":1225777774,"timestamp_e6":1618677794818120}
1618677794.900995: {"topic":"orderBookL2_25.BTCUSD","type":"delta","data":{"delete":[],"update":[{"price":"60621.00","symbol":"BTCUSD","id":606210000,"side":"Buy","size":155064},{"price":"60622.50","symbol":"BTCUSD","id":606225000,"side":"Buy","size":9946186}],"insert":[],"transactTimeE6":0},"cross_seq":5938956763,"timestamp_e6":1618677794818012}
1618677794.9220102: {"topic":"orderBookL2_25.BTCUSD","type":"delta","data":{"delete":[],"update":[{"price":"60622.50","symbol":"BTCUSD","id":606225000,"side":"Buy","size":9962186}],"insert":[],"transactTimeE6":0},"cross_seq":5938956766,"timestamp_e6":1618677794837931}
1618677794.940491: {"topic":"orderBookL2_25.BTCUSD","type":"delta","data":{"delete":[],"update":[{"price":"60622.50","symbol":"BTCUSD","id":606225000,"side":"Buy","size":9985186}],"insert":[],"transactTimeE6":0},"cross_seq":5938956770,"timestamp_e6":1618677794857981}
1618677794.9561758: {"topic":"trade.EOSUSD","data":[{"trade_time_ms":1618677794864,"timestamp":"2021-04-17T16:43:14.000Z","symbol":"EOSUSD","side":"Buy","size":1011,"price":7.969,"tick_direction":"MinusTick","trade_id":"dc1e538d-7006-59c8-b65c-090537455120","cross_seq":1225777775}]}
1618677794.961747: {"topic":"orderBookL2_25.BTCUSD","type":"delta","data":{"delete":[],"update":[{"price":"60622.50","symbol":"BTCUSD","id":606225000,"side":"Buy","size":10019686}],"insert":[],"transactTimeE6":0},"cross_seq":5938956776,"timestamp_e6":1618677794877874}
1618677794.9627311: {"topic":"orderBookL2_25.EOSUSD","type":"delta","data":{"delete":[],"update":[{"price":"7.969","symbol":"EOSUSD","id":79690,"side":"Sell","size":23011}],"insert":[],"transactTimeE6":0},"cross_seq":1225777775,"timestamp_e6":1618677794878726}
1618677794.980931: {"topic":"orderBookL2_25.BTCUSD","type":"delta","data":{"delete":[],"update":[{"price":"60622.50","symbol":"BTCUSD","id":606225000,"side":"Buy","size":10023186}],"insert":[],"transactTimeE6":0},"cross_seq":5938956777,"timestamp_e6":1618677794897907}
1618677794.981847: {"topic":"orderBookL2_25.EOSUSD","type":"delta","data":{"delete":[],"update":[{"price":"7.981","symbol":"EOSUSD","id":79810,"side":"Sell","size":68764},{"price":"7.982","symbol":"EOSUSD","id":79820,"side":"Sell","size":99144},{"price":"7.963","symbol":"EOSUSD","id":79630,"side":"Buy","size":20303},{"price":"7.983","symbol":"EOSUSD","id":79830,"side":"Sell","size":113563},{"price":"7.965","symbol":"EOSUSD","id":79650,"side":"Buy","size":67485},{"price":"7.961","symbol":"EOSUSD","id":79610,"side":"Buy","size":39012},{"price":"7.980","symbol":"EOSUSD","id":79800,"side":"Sell","size":90397}],"insert":[],"transactTimeE6":0},"cross_seq":1225777782,"timestamp_e6":1618677794898153}
1618677795.0014238: {"topic":"orderBookL2_25.BTCUSD","type":"delta","data":{"delete":[],"update":[{"price":"60622.50","symbol":"BTCUSD","id":606225000,"side":"Buy","size":10027186}],"insert":[],"transactTimeE6":0},"cross_seq":5938956778,"timestamp_e6":1618677794917952}
1618677795.080451: {"topic":"orderBookL2_25.BTCUSD","type":"delta","data":{"delete":[],"update":[{"price":"60627.00","symbol":"BTCUSD","id":606270000,"side":"Sell","size":423407}],"insert":[],"transactTimeE6":0},"cross_seq":5938956783,"timestamp_e6":1618677794997354}
1618677795.101064: {"topic":"orderBookL2_25.EOSUSD","type":"delta","data":{"delete":[],"update":[{"price":"7.981","symbol":"EOSUSD","id":79810,"side":"Sell","size":88003},{"price":"7.980","symbol":"EOSUSD","id":79800,"side":"Sell","size":115613},{"price":"7.979","symbol":"EOSUSD","id":79790,"side":"Sell","size":19023}],"insert":[],"transactTimeE6":0},"cross_seq":1225777785,"timestamp_e6":1618677795018133}
1618677795.12464: {"topic":"orderBookL2_25.BTCUSD","type":"delta","data":{"delete":[],"update":[{"price":"60625.00","symbol":"BTCUSD","id":606250000,"side":"Sell","size":114776},{"price":"60624.50","symbol":"BTCUSD","id":606245000,"side":"Sell","size":118303},{"price":"60624.00","symbol":"BTCUSD","id":606240000,"side":"Sell","size":137260},{"price":"60625.50","symbol":"BTCUSD","id":606255000,"side":"Sell","size":48855},{"price":"60623.00","symbol":"BTCUSD","id":606230000,"side":"Sell","size":739827},{"price":"60623.50","symbol":"BTCUSD","id":606235000,"side":"Sell","size":155015}],"insert":[],"transactTimeE6":0},"cross_seq":5938956808,"timestamp_e6":1618677795038095}
1618677795.161682: {"topic":"orderBookL2_25.BTCUSD","type":"delta","data":{"delete":[],"update":[{"price":"60622.50","symbol":"BTCUSD","id":606225000,"side":"Buy","size":10027155},{"price":"60621.50","symbol":"BTCUSD","id":606215000,"side":"Buy","size":351300}],"insert":[],"transactTimeE6":0},"cross_seq":5938956815,"timestamp_e6":1618677795077999}
1618677795.1639922: {"topic":"orderBookL2_25.EOSUSD","type":"delta","data":{"delete":[{"price":"7.966","symbol":"EOSUSD","id":79660,"side":"Buy"}],"update":[{"price":"7.961","symbol":"EOSUSD","id":79610,"side":"Buy","size":51011},{"price":"7.962","symbol":"EOSUSD","id":79620,"side":"Buy","size":17709},{"price":"7.965","symbol":"EOSUSD","id":79650,"side":"Buy","size":42056},{"price":"7.959","symbol":"EOSUSD","id":79590,"side":"Buy","size":13160},{"price":"7.960","symbol":"EOSUSD","id":79600,"side":"Buy","size":37865},{"price":"7.957","symbol":"EOSUSD","id":79570,"side":"Buy","size":35364},{"price":"7.985","symbol":"EOSUSD","id":79850,"side":"Sell","size":48672},{"price":"7.958","symbol":"EOSUSD","id":79580,"side":"Buy","size":18780},{"price":"7.964","symbol":"EOSUSD","id":79640,"side":"Buy","size":123831},{"price":"7.983","symbol":"EOSUSD","id":79830,"side":"Sell","size":125234}],"insert":[{"price":"7.942","symbol":"EOSUSD","id":79420,"side":"Buy","size":100112}],"transactTimeE6":0},"cross_seq":1225777802,"timestamp_e6":1618677795078158}
1618677795.1823528: {"topic":"orderBookL2_25.EOSUSD","type":"delta","data":{"delete":[],"update":[{"price":"7.968","symbol":"EOSUSD","id":79680,"side":"Buy","size":76302}],"insert":[],"transactTimeE6":0},"cross_seq":1225777803,"timestamp_e6":1618677795098754}
1618677795.201365: {"topic":"orderBookL2_25.EOSUSD","type":"delta","data":{"delete":[],"update":[{"price":"7.960","symbol":"EOSUSD","id":79600,"side":"Buy","size":9780},{"price":"7.958","symbol":"EOSUSD","id":79580,"side":"Buy","size":27465},{"price":"7.962","symbol":"EOSUSD","id":79620,"side":"Buy","size":50308},{"price":"7.957","symbol":"EOSUSD","id":79570,"side":"Buy","size":14894}],"insert":[],"transactTimeE6":0},"cross_seq":1225777810,"timestamp_e6":1618677795118104}
1618677795.2220402: {"topic":"orderBookL2_25.BTCUSD","type":"delta","data":{"delete":[],"update":[{"price":"60629.50","symbol":"BTCUSD","id":606295000,"side":"Sell","size":162567}],"insert":[],"transactTimeE6":0},"cross_seq":5938956818,"timestamp_e6":1618677795137308}
1618677795.240919: {"topic":"orderBookL2_25.EOSUSD","type":"delta","data":{"delete":[],"update":[{"price":"7.963","symbol":"EOSUSD","id":79630,"side":"Buy","size":26031},{"price":"7.959","symbol":"EOSUSD","id":79590,"side":"Buy","size":22219},{"price":"7.981","symbol":"EOSUSD","id":79810,"side":"Sell","size":98449}],"insert":[],"transactTimeE6":0},"cross_seq":1225777813,"timestamp_e6":1618677795158262}
1618677795.281579: {"topic":"orderBookL2_25.BTCUSD","type":"delta","data":{"delete":[],"update":[{"price":"60624.00","symbol":"BTCUSD","id":606240000,"side":"Sell","size":137261}],"insert":[],"transactTimeE6":0},"cross_seq":5938956822,"timestamp_e6":1618677795197327}
1618677795.3002539: {"topic":"orderBookL2_25.EOSUSD","type":"delta","data":{"delete":[],"update":[{"price":"7.960","symbol":"EOSUSD","id":79600,"side":"Buy","size":21215},{"price":"7.976","symbol":"EOSUSD","id":79760,"side":"Sell","size":29839},{"price":"7.957","symbol":"EOSUSD","id":79570,"side":"Buy","size":23910}],"insert":[],"transactTimeE6":0},"cross_seq":1225777816,"timestamp_e6":1618677795218105}
1618677795.3203788: {"topic":"orderBookL2_25.BTCUSD","type":"delta","data":{"delete":[],"update":[{"price":"60624.00","symbol":"BTCUSD","id":606240000,"side":"Sell","size":137262},{"price":"60616.50","symbol":"BTCUSD","id":606165000,"side":"Buy","size":130570},{"price":"60625.50","symbol":"BTCUSD","id":606255000,"side":"Sell","size":48854}],"insert":[],"transactTimeE6":0},"cross_seq":5938956826,"timestamp_e6":1618677795237351}
1618677795.341353: {"topic":"orderBookL2_25.BTCUSD","type":"delta","data":{"delete":[],"update":[{"price":"60622.50","symbol":"BTCUSD","id":606225000,"side":"Buy","size":10033655}],"insert":[],"transactTimeE6":0},"cross_seq":5938956827,"timestamp_e6":1618677795258039}
1618677795.362745: {"topic":"orderBookL2_25.BTCUSD","type":"delta","data":{"delete":[],"update":[{"price":"60622.50","symbol":"BTCUSD","id":606225000,"side":"Buy","size":10048155}],"insert":[],"transactTimeE6":0},"cross_seq":5938956832,"timestamp_e6":1618677795277919}
1618677795.3676999: {"topic":"orderBookL2_25.EOSUSD","type":"delta","data":{"delete":[],"update":[{"price":"7.982","symbol":"EOSUSD","id":79820,"side":"Sell","size":89775}],"insert":[],"transactTimeE6":0},"cross_seq":1225777817,"timestamp_e6":1618677795278132}
1618677795.381999: {"topic":"orderBookL2_25.BTCUSD","type":"delta","data":{"delete":[],"update":[{"price":"60622.50","symbol":"BTCUSD","id":606225000,"side":"Buy","size":10059155}],"insert":[],"transactTimeE6":0},"cross_seq":5938956834,"timestamp_e6":1618677795298012}
1618677795.4010901: {"topic":"orderBookL2_25.BTCUSD","type":"delta","data":{"delete":[],"update":[{"price":"60622.50","symbol":"BTCUSD","id":606225000,"side":"Buy","size":10078155}],"insert":[],"transactTimeE6":0},"cross_seq":5938956837,"timestamp_e6":1618677795317931}
1618677795.4011269: {"topic":"orderBookL2_25.EOSUSD","type":"delta","data":{"delete":[],"update":[{"price":"7.969","symbol":"EOSUSD","id":79690,"side":"Sell","size":22404}],"insert":[],"transactTimeE6":0},"cross_seq":1225777818,"timestamp_e6":1618677795318797}
1618677795.421508: {"topic":"orderBookL2_25.EOSUSD","type":"delta","data":{"delete":[],"update":[{"price":"7.976","symbol":"EOSUSD","id":79760,"side":"Sell","size":21080},{"price":"7.961","symbol":"EOSUSD","id":79610,"side":"Buy","size":19893},{"price":"7.963","symbol":"EOSUSD","id":79630,"side":"Buy","size":59598},{"price":"7.958","symbol":"EOSUSD","id":79580,"side":"Buy","size":19254},{"price":"7.959","symbol":"EOSUSD","id":79590,"side":"Buy","size":28586}],"insert":[],"transactTimeE6":0},"cross_seq":1225777823,"timestamp_e6":1618677795338110}
1618677795.422445: {"topic":"orderBookL2_25.BTCUSD","type":"delta","data":{"delete":[],"update":[{"price":"60622.50","symbol":"BTCUSD","id":606225000,"side":"Buy","size":10084155},{"price":"60622.00","symbol":"BTCUSD","id":606220000,"side":"Buy","size":142880},{"price":"60623.00","symbol":"BTCUSD","id":606230000,"side":"Sell","size":739826}],"insert":[],"transactTimeE6":0},"cross_seq":5938956841,"timestamp_e6":1618677795338588}
1618677795.441671: {"topic":"orderBookL2_25.BTCUSD","type":"delta","data":{"delete":[],"update":[{"price":"60619.00","symbol":"BTCUSD","id":606190000,"side":"Buy","size":61481},{"price":"60622.50","symbol":"BTCUSD","id":606225000,"side":"Buy","size":10099095}],"insert":[],"transactTimeE6":0},"cross_seq":5938956844,"timestamp_e6":1618677795358108}
1618677795.442948: {"topic":"orderBookL2_25.EOSUSD","type":"delta","data":{"delete":[],"update":[{"price":"7.969","symbol":"EOSUSD","id":79690,"side":"Sell","size":21722}],"insert":[],"transactTimeE6":0},"cross_seq":1225777824,"timestamp_e6":1618677795359131}
1618677795.46093: {"topic":"orderBookL2_25.BTCUSD","type":"delta","data":{"delete":[],"update":[{"price":"60627.00","symbol":"BTCUSD","id":606270000,"side":"Sell","size":159582}],"insert":[],"transactTimeE6":0},"cross_seq":5938956846,"timestamp_e6":1618677795377343}
1618677795.4800808: {"topic":"orderBookL2_25.BTCUSD","type":"delta","data":{"delete":[],"update":[{"price":"60629.50","symbol":"BTCUSD","id":606295000,"side":"Sell","size":152682}],"insert":[],"transactTimeE6":0},"cross_seq":5938956847,"timestamp_e6":1618677795397315}
1618677795.481099: {"topic":"orderBookL2_25.EOSUSD","type":"delta","data":{"delete":[{"price":"7.942","symbol":"EOSUSD","id":79420,"side":"Buy"}],"update":[{"price":"7.971","symbol":"EOSUSD","id":79710,"side":"Sell","size":50009},{"price":"7.965","symbol":"EOSUSD","id":79650,"side":"Buy","size":40441},{"price":"7.969","symbol":"EOSUSD","id":79690,"side":"Sell","size":11020}],"insert":[{"price":"7.967","symbol":"EOSUSD","id":79670,"side":"Buy","size":1615}],"transactTimeE6":0},"cross_seq":1225777827,"timestamp_e6":1618677795398761}
1618677795.502366: {"topic":"orderBookL2_25.BTCUSD","type":"delta","data":{"delete":[],"update":[{"price":"60623.00","symbol":"BTCUSD","id":606230000,"side":"Sell","size":714826}],"insert":[],"transactTimeE6":0},"cross_seq":5938956849,"timestamp_e6":1618677795417972}
1618677795.5024042: {"topic":"orderBookL2_25.EOSUSD","type":"delta","data":{"delete":[],"update":[{"price":"7.981","symbol":"EOSUSD","id":79810,"side":"Sell","size":85637}],"insert":[],"transactTimeE6":0},"cross_seq":1225777828,"timestamp_e6":1618677795418105}
1618677795.521962: {"topic":"orderBookL2_25.BTCUSD","type":"delta","data":{"delete":[],"update":[{"price":"60622.50","symbol":"BTCUSD","id":606225000,"side":"Buy","size":10579095}],"insert":[],"transactTimeE6":0},"cross_seq":5938956850,"timestamp_e6":1618677795437909}
1618677795.5219982: {"topic":"orderBookL2_25.EOSUSD","type":"delta","data":{"delete":[],"update":[{"price":"7.974","symbol":"EOSUSD","id":79740,"side":"Sell","size":51570},{"price":"7.958","symbol":"EOSUSD","id":79580,"side":"Buy","size":28576},{"price":"7.973","symbol":"EOSUSD","id":79730,"side":"Sell","size":100343},{"price":"7.976","symbol":"EOSUSD","id":79760,"side":"Sell","size":27115},{"price":"7.961","symbol":"EOSUSD","id":79610,"side":"Buy","size":49374},{"price":"7.963","symbol":"EOSUSD","id":79630,"side":"Buy","size":26031},{"price":"7.960","symbol":"EOSUSD","id":79600,"side":"Buy","size":30350}],"insert":[],"transactTimeE6":0},"cross_seq":1225777835,"timestamp_e6":1618677795438165}
1618677795.5410292: {"topic":"orderBookL2_25.EOSUSD","type":"delta","data":{"delete":[],"update":[{"price":"7.974","symbol":"EOSUSD","id":79740,"side":"Sell","size":43845}],"insert":[],"transactTimeE6":0},"cross_seq":1225777836,"timestamp_e6":1618677795458144}
1618677795.556968: {"topic":"trade.BTCUSD","data":[{"trade_time_ms":1618677795394,"timestamp":"2021-04-17T16:43:15.000Z","symbol":"BTCUSD","side":"Buy","size":20200,"price":60623,"tick_direction":"PlusTick","trade_id":"a7ddf8ca-1a10-57a0-8756-d39658109901","cross_seq":5938956852},{"trade_time_ms":1618677795394,"timestamp":"2021-04-17T16:43:15.000Z","symbol":"BTCUSD","side":"Buy","size":326,"price":60623,"tick_direction":"ZeroPlusTick","trade_id":"eb403f8e-1688-5025-bcfb-ec2329223130","cross_seq":5938956852},{"trade_time_ms":1618677795394,"timestamp":"2021-04-17T16:43:15.000Z","symbol":"BTCUSD","side":"Buy","size":1,"price":60623,"tick_direction":"ZeroPlusTick","trade_id":"0cb42cbe-7550-552d-a007-506c770f231e","cross_seq":5938956852},{"trade_time_ms":1618677795394,"timestamp":"2021-04-17T16:43:15.000Z","symbol":"BTCUSD","side":"Buy","size":4473,"price":60623,"tick_direction":"ZeroPlusTick","trade_id":"776abdcd-5283-5114-bb57-3bead6ff56b2","cross_seq":5938956852}]}
1618677795.564065: {"topic":"orderBookL2_25.EOSUSD","type":"delta","data":{"delete":[],"update":[{"price":"7.968","symbol":"EOSUSD","id":79680,"side":"Buy","size":132045},{"price":"7.981","symbol":"EOSUSD","id":79810,"side":"Sell","size":94974},{"price":"7.969","symbol":"EOSUSD","id":79690,"side":"Sell","size":7635},{"price":"7.971","symbol":"EOSUSD","id":79710,"side":"Sell","size":53394}],"insert":[],"transactTimeE6":0},"cross_seq":1225777839,"timestamp_e6":1618677795479313}
1618677795.580651: {"topic":"orderBookL2_25.EOSUSD","type":"delta","data":{"delete":[],"update":[{"price":"7.963","symbol":"EOSUSD","id":79630,"side":"Buy","size":21647},{"price":"7.975","symbol":"EOSUSD","id":79750,"side":"Sell","size":47885},{"price":"7.972","symbol":"EOSUSD","id":79720,"side":"Sell","size":40078}],"insert":[],"transactTimeE6":0},"cross_seq":1225777841,"timestamp_e6":1618677795498156}
1618677795.621708: {"topic":"orderBookL2_25.BTCUSD","type":"delta","data":{"delete":[],"update":[{"price":"60619.50","symbol":"BTCUSD","id":606195000,"side":"Buy","size":233226}],"insert":[],"transactTimeE6":0},"cross_seq":5938956856,"timestamp_e6":1618677795537337}
1618677795.621739: {"topic":"orderBookL2_25.EOSUSD","type":"delta","data":{"delete":[],"update":[{"price":"7.982","symbol":"EOSUSD","id":79820,"side":"Sell","size":98868}],"insert":[],"transactTimeE6":0},"cross_seq":1225777843,"timestamp_e6":1618677795538151}
1618677795.641143: {"topic":"orderBookL2_25.BTCUSD","type":"delta","data":{"delete":[],"update":[{"price":"60622.50","symbol":"BTCUSD","id":606225000,"side":"Buy","size":10579091}],"insert":[],"transactTimeE6":0},"cross_seq":5938956860,"timestamp_e6":1618677795557936}
1618677795.642037: {"topic":"orderBookL2_25.EOSUSD","type":"delta","data":{"delete":[{"price":"7.967","symbol":"EOSUSD","id":79670,"side":"Buy"}],"update":[{"price":"7.968","symbol":"EOSUSD","id":79680,"side":"Buy","size":133660},{"price":"7.962","symbol":"EOSUSD","id":79620,"side":"Buy","size":53438}],"insert":[{"price":"7.942","symbol":"EOSUSD","id":79420,"side":"Buy","size":100112}],"transactTimeE6":0},"cross_seq":1225777845,"timestamp_e6":1618677795559133}
1618677795.682385: {"topic":"orderBookL2_25.EOSUSD","type":"delta","data":{"delete":[],"update":[{"price":"7.958","symbol":"EOSUSD","id":79580,"side":"Buy","size":40576},{"price":"7.955","symbol":"EOSUSD","id":79550,"side":"Buy","size":87621},{"price":"7.975","symbol":"EOSUSD","id":79750,"side":"Sell","size":57041}],"insert":[],"transactTimeE6":0},"cross_seq":1225777847,"timestamp_e6":1618677795598110}
1618677795.746463: {"topic":"orderBookL2_25.BTCUSD","type":"delta","data":{"delete":[],"update":[{"price":"60623.00","symbol":"BTCUSD","id":606230000,"side":"Sell","size":714825}],"insert":[],"transactTimeE6":0},"cross_seq":5938956865,"timestamp_e6":1618677795658046}
1618677795.8406222: {"topic":"orderBookL2_25.BTCUSD","type":"delta","data":{"delete":[],"update":[{"price":"60622.50","symbol":"BTCUSD","id":606225000,"side":"Buy","size":10589165},{"price":"60621.50","symbol":"BTCUSD","id":606215000,"side":"Buy","size":341226}],"insert":[],"transactTimeE6":0},"cross_seq":5938956873,"timestamp_e6":1618677795757937}
1618677795.861741: {"topic":"orderBookL2_25.BTCUSD","type":"delta","data":{"delete":[],"update":[{"price":"60622.50","symbol":"BTCUSD","id":606225000,"side":"Buy","size":10595674}],"insert":[],"transactTimeE6":0},"cross_seq":5938956875,"timestamp_e6":1618677795777965}
1618677795.900351: {"topic":"orderBookL2_25.BTCUSD","type":"delta","data":{"delete":[{"price":"60606.00","symbol":"BTCUSD","id":606060000,"side":"Buy"}],"update":[],"insert":[{"price":"60612.00","symbol":"BTCUSD","id":606120000,"side":"Buy","size":6}],"transactTimeE6":0},"cross_seq":5938956876,"timestamp_e6":1618677795817319}
1618677795.941153: {"topic":"orderBookL2_25.EOSUSD","type":"delta","data":{"delete":[],"update":[{"price":"7.973","symbol":"EOSUSD","id":79730,"side":"Sell","size":101870},{"price":"7.975","symbol":"EOSUSD","id":79750,"side":"Sell","size":58285},{"price":"7.974","symbol":"EOSUSD","id":79740,"side":"Sell","size":46309},{"price":"7.976","symbol":"EOSUSD","id":79760,"side":"Sell","size":29732},{"price":"7.972","symbol":"EOSUSD","id":79720,"side":"Sell","size":42005}],"insert":[],"transactTimeE6":0},"cross_seq":1225777853,"timestamp_e6":1618677795858102}
1618677795.961497: {"topic":"orderBookL2_25.BTCUSD","type":"delta","data":{"delete":[],"update":[{"price":"60617.50","symbol":"BTCUSD","id":606175000,"side":"Buy","size":2122},{"price":"60622.50","symbol":"BTCUSD","id":606225000,"side":"Buy","size":10604674}],"insert":[],"transactTimeE6":0},"cross_seq":5938956880,"timestamp_e6":1618677795877969}
1618677796.0003788: {"topic":"orderBookL2_25.EOSUSD","type":"delta","data":{"delete":[],"update":[{"price":"7.984","symbol":"EOSUSD","id":79840,"side":"Sell","size":134658},{"price":"7.959","symbol":"EOSUSD","id":79590,"side":"Buy","size":37915},{"price":"7.963","symbol":"EOSUSD","id":79630,"side":"Buy","size":30661},{"price":"7.961","symbol":"EOSUSD","id":79610,"side":"Buy","size":56499},{"price":"7.960","symbol":"EOSUSD","id":79600,"side":"Buy","size":43574}],"insert":[],"transactTimeE6":0},"cross_seq":1225777858,"timestamp_e6":1618677795918093}
1618677796.021751: {"topic":"orderBookL2_25.BTCUSD","type":"delta","data":{"delete":[],"update":[{"price":"60622.50","symbol":"BTCUSD","id":606225000,"side":"Buy","size":10613674}],"insert":[],"transactTimeE6":0},"cross_seq":5938956883,"timestamp_e6":1618677795938079}
1618677796.021777: {"topic":"orderBookL2_25.EOSUSD","type":"delta","data":{"delete":[],"update":[{"price":"7.973","symbol":"EOSUSD","id":79730,"side":"Sell","size":50061}],"insert":[],"transactTimeE6":0},"cross_seq":1225777859,"timestamp_e6":1618677795938155}
1618677796.042072: {"topic":"orderBookL2_25.BTCUSD","type":"delta","data":{"delete":[],"update":[{"price":"60623.00","symbol":"BTCUSD","id":606230000,"side":"Sell","size":715825}],"insert":[],"transactTimeE6":0},"cross_seq":5938956884,"timestamp_e6":1618677795957958}
1618677796.042101: {"topic":"orderBookL2_25.EOSUSD","type":"delta","data":{"delete":[],"update":[{"price":"7.943","symbol":"EOSUSD","id":79430,"side":"Buy","size":161719}],"insert":[],"transactTimeE6":0},"cross_seq":1225777860,"timestamp_e6":1618677795958154}
1618677796.061342: {"topic":"orderBookL2_25.BTCUSD","type":"delta","data":{"delete":[],"update":[{"price":"60628.00","symbol":"BTCUSD","id":606280000,"side":"Sell","size":188450}],"insert":[],"transactTimeE6":0},"cross_seq":5938956886,"timestamp_e6":1618677795977319}
1618677796.100975: {"topic":"orderBookL2_25.BTCUSD","type":"delta","data":{"delete":[],"update":[{"price":"60622.50","symbol":"BTCUSD","id":606225000,"side":"Buy","size":10614183}],"insert":[],"transactTimeE6":0},"cross_seq":5938956888,"timestamp_e6":1618677795997962}
1618677796.1224031: {"topic":"orderBookL2_25.EOSUSD","type":"delta","data":{"delete":[],"update":[{"price":"7.985","symbol":"EOSUSD","id":79850,"side":"Sell","size":49072}],"insert":[],"transactTimeE6":0},"cross_seq":1225777862,"timestamp_e6":1618677796038118}
1618677796.1434062: {"topic":"orderBookL2_25.EOSUSD","type":"delta","data":{"delete":[],"update":[{"price":"7.964","symbol":"EOSUSD","id":79640,"side":"Buy","size":137998},{"price":"7.980","symbol":"EOSUSD","id":79800,"side":"Sell","size":127051}],"insert":[],"transactTimeE6":0},"cross_seq":1225777864,"timestamp_e6":1618677796058223}
1618677796.202111: {"topic":"orderBookL2_25.EOSUSD","type":"delta","data":{"delete":[],"update":[{"price":"7.972","symbol":"EOSUSD","id":79720,"side":"Sell","size":40078},{"price":"7.975","symbol":"EOSUSD","id":79750,"side":"Sell","size":57041},{"price":"7.973","symbol":"EOSUSD","id":79730,"side":"Sell","size":48534},{"price":"7.976","symbol":"EOSUSD","id":79760,"side":"Sell","size":27115},{"price":"7.943","symbol":"EOSUSD","id":79430,"side":"Buy","size":154219},{"price":"7.974","symbol":"EOSUSD","id":79740,"side":"Sell","size":43845}],"insert":[],"transactTimeE6":0},"cross_seq":1225777870,"timestamp_e6":1618677796118108}
1618677796.240948: {"topic":"orderBookL2_25.BTCUSD","type":"delta","data":{"delete":[],"update":[{"price":"60633.50","symbol":"BTCUSD","id":606335000,"side":"Sell","size":35054}],"insert":[],"transactTimeE6":0},"cross_seq":5938956901,"timestamp_e6":1618677796157325}
1618677796.261198: {"topic":"orderBookL2_25.BTCUSD","type":"delta","data":{"delete":[],"update":[{"price":"60623.00","symbol":"BTCUSD","id":606230000,"side":"Sell","size":707553}],"insert":[],"transactTimeE6":0},"cross_seq":5938956904,"timestamp_e6":1618677796177938}
1618677796.261906: {"topic":"orderBookL2_25.EOSUSD","type":"delta","data":{"delete":[],"update":[{"price":"7.964","symbol":"EOSUSD","id":79640,"side":"Buy","size":123544},{"price":"7.985","symbol":"EOSUSD","id":79850,"side":"Sell","size":56216}],"insert":[],"transactTimeE6":0},"cross_seq":1225777872,"timestamp_e6":1618677796178090}
1618677796.326582: {"topic":"orderBookL2_25.BTCUSD","type":"delta","data":{"delete":[],"update":[{"price":"60623.50","symbol":"BTCUSD","id":606235000,"side":"Sell","size":155016}],"insert":[],"transactTimeE6":0},"cross_seq":5938956909,"timestamp_e6":1618677796237338}
1618677796.356742: {"topic":"trade.BTCUSD","data":[{"trade_time_ms":1618677796167,"timestamp":"2021-04-17T16:43:16.000Z","symbol":"BTCUSD","side":"Buy","size":8272,"price":60623,"tick_direction":"ZeroPlusTick","trade_id":"aa6076af-51b6-5e7a-937c-1c7fa2cd25ee","cross_seq":5938956911}]}
1618677796.401648: {"topic":"orderBookL2_25.EOSUSD","type":"delta","data":{"delete":[],"update":[{"price":"7.964","symbol":"EOSUSD","id":79640,"side":"Buy","size":136874}],"insert":[],"transactTimeE6":0},"cross_seq":1225777873,"timestamp_e6":1618677796318124}
1618677796.426789: {"topic":"orderBookL2_25.BTCUSD","type":"delta","data":{"delete":[],"update":[{"price":"60618.00","symbol":"BTCUSD","id":606180000,"side":"Buy","size":873}],"insert":[],"transactTimeE6":0},"cross_seq":5938956915,"timestamp_e6":1618677796337328}
1618677796.5016499: {"topic":"orderBookL2_25.EOSUSD","type":"delta","data":{"delete":[],"update":[{"price":"7.968","symbol":"EOSUSD","id":79680,"side":"Buy","size":137660}],"insert":[],"transactTimeE6":0},"cross_seq":1225777874,"timestamp_e6":1618677796418753}
1618677796.520732: {"topic":"orderBookL2_25.EOSUSD","type":"delta","data":{"delete":[],"update":[{"price":"7.982","symbol":"EOSUSD","id":79820,"side":"Sell","size":110089}],"insert":[],"transactTimeE6":0},"cross_seq":1225777875,"timestamp_e6":1618677796438100}
1618677796.582391: {"topic":"orderBookL2_25.EOSUSD","type":"delta","data":{"delete":[],"update":[{"price":"7.968","symbol":"EOSUSD","id":79680,"side":"Buy","size":137740}],"insert":[],"transactTimeE6":0},"cross_seq":1225777877,"timestamp_e6":1618677796498776}
1618677796.621502: {"topic":"orderBookL2_25.BTCUSD","type":"delta","data":{"delete":[],"update":[{"price":"60623.00","symbol":"BTCUSD","id":606230000,"side":"Sell","size":707486}],"insert":[],"transactTimeE6":0},"cross_seq":5938956937,"timestamp_e6":1618677796537973}
1618677796.640629: {"topic":"orderBookL2_25.EOSUSD","type":"delta","data":{"delete":[],"update":[{"price":"7.944","symbol":"EOSUSD","id":79440,"side":"Buy","size":114534}],"insert":[],"transactTimeE6":0},"cross_seq":1225777878,"timestamp_e6":1618677796558151}
1618677796.655721: {"topic":"trade.BTCUSD","data":[{"trade_time_ms":1618677796518,"timestamp":"2021-04-17T16:43:16.000Z","symbol":"BTCUSD","side":"Buy","size":67,"price":60623,"tick_direction":"ZeroPlusTick","trade_id":"b3fb222f-b3c4-5f84-8e9f-dd42eba4ae59","cross_seq":5938956937}]}
1618677796.681132: {"topic":"orderBookL2_25.BTCUSD","type":"delta","data":{"delete":[],"update":[{"price":"60622.50","symbol":"BTCUSD","id":606225000,"side":"Buy","size":10613674}],"insert":[],"transactTimeE6":0},"cross_seq":5938956938,"timestamp_e6":1618677796598038}
1618677796.7207801: {"topic":"orderBookL2_25.EOSUSD","type":"delta","data":{"delete":[{"price":"7.974","symbol":"EOSUSD","id":79740,"side":"Sell"},{"price":"7.972","symbol":"EOSUSD","id":79720,"side":"Sell"}],"update":[{"price":"7.978","symbol":"EOSUSD","id":79780,"side":"Sell","size":96958},{"price":"7.981","symbol":"EOSUSD","id":79810,"side":"Sell","size":70459},{"price":"7.980","symbol":"EOSUSD","id":79800,"side":"Sell","size":53476},{"price":"7.979","symbol":"EOSUSD","id":79790,"side":"Sell","size":41775},{"price":"7.961","symbol":"EOSUSD","id":79610,"side":"Buy","size":27018},{"price":"7.962","symbol":"EOSUSD","id":79620,"side":"Buy","size":20839},{"price":"7.973","symbol":"EOSUSD","id":79730,"side":"Sell","size":1298},{"price":"7.976","symbol":"EOSUSD","id":79760,"side":"Sell","size":45982},{"price":"7.975","symbol":"EOSUSD","id":79750,"side":"Sell","size":12000},{"price":"7.958","symbol":"EOSUSD","id":79580,"side":"Buy","size":31891},{"price":"7.963","symbol":"EOSUSD","id":79630,"side":"Buy","size":66956},{"price":"7.971","symbol":"EOSUSD","id":79710,"side":"Sell","size":8385}],"insert":[{"price":"7.995","symbol":"EOSUSD","id":79950,"side":"Sell","size":27616},{"price":"7.996","symbol":"EOSUSD","id":79960,"side":"Sell","size":39326}],"transactTimeE6":0},"cross_seq":1225777903,"timestamp_e6":1618677796638153}
1618677796.741111: {"topic":"orderBookL2_25.EOSUSD","type":"delta","data":{"delete":[],"update":[{"price":"7.975","symbol":"EOSUSD","id":79750,"side":"Sell","size":64258}],"insert":[],"transactTimeE6":0},"cross_seq":1225777904,"timestamp_e6":1618677796658098}
1618677796.780669: {"topic":"orderBookL2_25.EOSUSD","type":"delta","data":{"delete":[],"update":[{"price":"7.982","symbol":"EOSUSD","id":79820,"side":"Sell","size":99084}],"insert":[],"transactTimeE6":0},"cross_seq":1225777905,"timestamp_e6":1618677796698204}
1618677796.820995: {"topic":"orderBookL2_25.BTCUSD","type":"delta","data":{"delete":[],"update":[{"price":"60629.00","symbol":"BTCUSD","id":606290000,"side":"Sell","size":73751}],"insert":[],"transactTimeE6":0},"cross_seq":5938956946,"timestamp_e6":1618677796737321}
1618677796.8210409: {"topic":"orderBookL2_25.EOSUSD","type":"delta","data":{"delete":[],"update":[{"price":"7.958","symbol":"EOSUSD","id":79580,"side":"Buy","size":37635},{"price":"7.980","symbol":"EOSUSD","id":79800,"side":"Sell","size":94183},{"price":"7.961","symbol":"EOSUSD","id":79610,"side":"Buy","size":52064},{"price":"7.977","symbol":"EOSUSD","id":79770,"side":"Sell","size":91227},{"price":"7.962","symbol":"EOSUSD","id":79620,"side":"Buy","size":43210}],"insert":[],"transactTimeE6":0},"cross_seq":1225777910,"timestamp_e6":1618677796738191}
1618677796.9017558: {"topic":"orderBookL2_25.EOSUSD","type":"delta","data":{"delete":[],"update":[{"price":"7.964","symbol":"EOSUSD","id":79640,"side":"Buy","size":119814}],"insert":[],"transactTimeE6":0},"cross_seq":1225777918,"timestamp_e6":1618677796818259}
1618677796.941977: {"topic":"orderBookL2_25.BTCUSD","type":"delta","data":{"delete":[],"update":[{"price":"60622.50","symbol":"BTCUSD","id":606225000,"side":"Buy","size":10622674}],"insert":[],"transactTimeE6":0},"cross_seq":5938956948,"timestamp_e6":1618677796857973}
1618677796.9610188: {"topic":"orderBookL2_25.EOSUSD","type":"delta","data":{"delete":[],"update":[{"price":"7.959","symbol":"EOSUSD","id":79590,"side":"Buy","size":42915}],"insert":[],"transactTimeE6":0},"cross_seq":1225777919,"timestamp_e6":1618677796878150}
1618677796.980361: {"topic":"orderBookL2_25.BTCUSD","type":"delta","data":{"delete":[],"update":[{"price":"60621.50","symbol":"BTCUSD","id":606215000,"side":"Buy","size":341225}],"insert":[],"transactTimeE6":0},"cross_seq":5938956951,"timestamp_e6":1618677796897299}
1618677797.021732: {"topic":"orderBookL2_25.EOSUSD","type":"delta","data":{"delete":[],"update":[{"price":"7.960","symbol":"EOSUSD","id":79600,"side":"Buy","size":34794},{"price":"7.959","symbol":"EOSUSD","id":79590,"side":"Buy","size":33856}],"insert":[],"transactTimeE6":0},"cross_seq":1225777921,"timestamp_e6":1618677796938114}
1618677797.0406349: {"topic":"orderBookL2_25.EOSUSD","type":"delta","data":{"delete":[],"update":[{"price":"7.962","symbol":"EOSUSD","id":79620,"side":"Buy","size":48394},{"price":"7.964","symbol":"EOSUSD","id":79640,"side":"Buy","size":140343}],"insert":[],"transactTimeE6":0},"cross_seq":1225777923,"timestamp_e6":1618677796958087}
1618677797.0817962: {"topic":"orderBookL2_25.BTCUSD","type":"delta","data":{"delete":[],"update":[{"price":"60622.50","symbol":"BTCUSD","id":606225000,"side":"Buy","size":10622165}],"insert":[],"transactTimeE6":0},"cross_seq":5938956954,"timestamp_e6":1618677796998030}
1618677797.141682: {"topic":"orderBookL2_25.BTCUSD","type":"delta","data":{"delete":[],"update":[{"price":"60623.00","symbol":"BTCUSD","id":606230000,"side":"Sell","size":705486}],"insert":[],"transactTimeE6":0},"cross_seq":5938956958,"timestamp_e6":1618677797057974}
1618677797.1591418: {"topic":"trade.BTCUSD","data":[{"trade_time_ms":1618677797045,"timestamp":"2021-04-17T16:43:17.000Z","symbol":"BTCUSD","side":"Buy","size":2000,"price":60623,"tick_direction":"ZeroPlusTick","trade_id":"a5eff8f3-6cff-5636-a172-7ecb36a3a582","cross_seq":5938956958}]}
1618677797.1622322: {"topic":"orderBookL2_25.EOSUSD","type":"delta","data":{"delete":[],"update":[{"price":"7.960","symbol":"EOSUSD","id":79600,"side":"Buy","size":40768},{"price":"7.959","symbol":"EOSUSD","id":79590,"side":"Buy","size":40322},{"price":"7.964","symbol":"EOSUSD","id":79640,"side":"Buy","size":126176},{"price":"7.981","symbol":"EOSUSD","id":79810,"side":"Sell","size":86218},{"price":"7.968","symbol":"EOSUSD","id":79680,"side":"Buy","size":141740},{"price":"7.985","symbol":"EOSUSD","id":79850,"side":"Sell","size":65400}],"insert":[],"transactTimeE6":0},"cross_seq":1225777929,"timestamp_e6":1618677797078730}
1618677797.182292: {"topic":"orderBookL2_25.BTCUSD","type":"delta","data":{"delete":[],"update":[{"price":"60623.00","symbol":"BTCUSD","id":606230000,"side":"Sell","size":240298}],"insert":[],"transactTimeE6":0},"cross_seq":5938956962,"timestamp_e6":1618677797097955}
1618677797.2808902: {"topic":"orderBookL2_25.EOSUSD","type":"delta","data":{"delete":[],"update":[{"price":"7.985","symbol":"EOSUSD","id":79850,"side":"Sell","size":47549}],"insert":[],"transactTimeE6":0},"cross_seq":1225777931,"timestamp_e6":1618677797198116}
