1618677787.690387: {"topic":"orderBookL2_25.LTCUSDT","type":"delta","data":{"delete":[{"price":"312.85","symbol":"LTCUSDT","id":"3128500","side":"Buy"},{"price":"312.86","symbol":"LTCUSDT","id":"3128600","side":"Buy"},{"price":"313.15","symbol":"LTCUSDT","id":"3131500","side":"Sell"},{"price":"313.16","symbol":"LTCUSDT","id":"3131600","side":"Sell"},{"price":"312.79","symbol":"LTCUSDT","id":"3127900","side":"Buy"},{"price":"313.17","symbol":"LTCUSDT","id":"3131700","side":"Sell"},{"price":"312.96","symbol":"LTCUSDT","id":"3129600","side":"Sell"},{"price":"313.18","symbol":"LTCUSDT","id":"3131800","side":"Sell"},{"price":"312.84","symbol":"LTCUSDT","id":"3128400","side":"Buy"}],"update":[{"price":"312.81","symbol":"LTCUSDT","id":"3128100","side":"Buy","size":117.799995},{"price":"312.75","symbol":"LTCUSDT","id":"3127500","side":"Buy","size":53.3},{"price":"312.89","symbol":"LTCUSDT","id":"3128900","side":"Sell","size":78.3},{"price":"312.93","symbol":"LTCUSDT","id":"3129300","side":"Sell","size":19},{"price":"312.80","symbol":"LTCUSDT","id":"3128000","side":"Buy","size":95.3},{"price":"312.74","symbol":"LTCUSDT","id":"3127400","side":"Buy","size":44.5}],"insert":[{"price":"312.78","symbol":"LTCUSDT","id":"3127800","side":"Buy","size":117.799995},{"price":"312.57","symbol":"LTCUSDT","id":"3125700","side":"Buy","size":76.600006},{"price":"312.94","symbol":"LTCUSDT","id":"3129400","side":"Sell","size":55.800003},{"price":"312.97","symbol":"LTCUSDT","id":"3129700","side":"Sell","size":19},{"price":"312.90","symbol":"LTCUSDT","id":"3129000","side":"Sell","size":55.800003},{"price":"312.56","symbol":"LTCUSDT","id":"3125600","side":"Buy","size":116.600006},{"price":"312.88","symbol":"LTCUSDT","id":"3128800","side":"Sell","size":112.3},{"price":"312.91","symbol":"LTCUSDT","id":"3129100","side":"Sell","size":63.3},{"price":"312.77","symbol":"LTCUSDT","id":"3127700","side":"Buy","size":96.3}]},"cross_seq":"1684522034","timestamp_e6":"1618677787339131"}
1618677787.6905222: {"topic":"orderBookL2_25.ADAUSDT","type":"delta","data":{"delete":[],"update":[{"price":"1.3883","symbol":"ADAUSDT","id":"13883","side":"Sell","size":3155},{"price":"1.3884","symbol":"ADAUSDT","id":"13884","side":"Sell","size":1470.9999}],"insert":[]},"cross_seq":"916952986","timestamp_e6":"1618677787342584"}
1618677787.690548: {"topic":"orderBookL2_25.ETHUSDT","type":"delta","data":{"delete":[],"update":[{"price":"2364.75","symbol":"ETHUSDT","id":"23647500","side":"Buy","size":149.98}],"insert":[]},"cross_seq":"1800546215","timestamp_e6":"1618677787347061"}
1618677787.690567: {"topic":"orderBookL2_25.BCHUSDT","type":"delta","data":{"delete":[{"price":"1053.10","symbol":"BCHUSDT","id":"10531000","side":"Buy"},{"price":"1054.75","symbol":"BCHUSDT","id":"10547500","side":"Sell"},{"price":"1055.05","symbol":"BCHUSDT","id":"10550500","side":"Sell"},{"price":"1055.20","symbol":"BCHUSDT","id":"10552000","side":"Sell"},{"price":"1055.15","symbol":"BCHUSDT","id":"10551500","side":"Sell"},{"price":"1054.85","symbol":"BCHUSDT","id":"10548500","side":"Sell"},{"price":"1054.95","symbol":"BCHUSDT","id":"10549500","side":"Sell"},{"price":"1054.90","symbol":"BCHUSDT","id":"10549000","side":"Sell"},{"price":"1053.05","symbol":"BCHUSDT","id":"10530500","side":"Buy"},{"price":"1054.80","symbol":"BCHUSDT","id":"10548000","side":"Sell"}],"update":[{"price":"1054.15","symbol":"BCHUSDT","id":"10541500","side":"Buy","size":5.16},{"price":"1054.25","symbol":"BCHUSDT","id":"10542500","side":"Buy","size":5.12},{"price":"1055.10","symbol":"BCHUSDT","id":"10551000","side":"Sell","size":5.59},{"price":"1055.00","symbol":"BCHUSDT","id":"10550000","side":"Sell","size":5.28}],"insert":[{"price":"1056.10","symbol":"BCHUSDT","id":"10561000","side":"Sell","size":6.37},{"price":"1056.15","symbol":"BCHUSDT","id":"10561500","side":"Sell","size":5.33},{"price":"1056.20","symbol":"BCHUSDT","id":"10562000","side":"Sell","size":1},{"price":"1056.05","symbol":"BCHUSDT","id":"10560500","side":"Sell","size":4.1},{"price":"1056.30","symbol":"BCHUSDT","id":"10563000","side":"Sell","size":20.72},{"price":"1054.35","symbol":"BCHUSDT","id":"10543500","side":"Buy","size":16.390001},{"price":"1054.45","symbol":"BCHUSDT","id":"10544500","side":"Buy","size":13.329999},{"price":"1056.35","symbol":"BCHUSDT","id":"10563500","side":"Sell","size":15.590001},{"price":"1056.25","symbol":"BCHUSDT","id":"10562500","side":"Sell","size":4.27},{"price":"1055.35","symbol":"BCHUSDT","id":"10553500","side":"Sell","size":5.49}]},"cross_seq":"864132071","timestamp_e6":"1618677787351224"}
1618677787.690699: {"topic":"orderBookL2_25.LTCUSDT","type":"delta","data":{"delete":[],"update":[{"price":"312.95","symbol":"LTCUSDT","id":"3129500","side":"Sell","size":55.800003},{"price":"312.87","symbol":"LTCUSDT","id":"3128700","side":"Sell","size":2.1}],"insert":[]},"cross_seq":"1684522057","timestamp_e6":"1618677787360198"}
1618677787.6907241: {"topic":"orderBookL2_25.ADAUSDT","type":"delta","data":{"delete":[],"update":[{"price":"1.3881","symbol":"ADAUSDT","id":"13881","side":"Sell","size":5147},{"price":"1.3879","symbol":"ADAUSDT","id":"13879","side":"Sell","size":8833},{"price":"1.3882","symbol":"ADAUSDT","id":"13882","side":"Sell","size":5228},{"price":"1.3880","symbol":"ADAUSDT","id":"13880","side":"Sell","size":7454}],"insert":[]},"cross_seq":"916952990","timestamp_e6":"1618677787362322"}
1618677787.690754: {"topic":"orderBookL2_25.BCHUSDT","type":"delta","data":{"delete":[{"price":"1055.30","symbol":"BCHUSDT","id":"10553000","side":"Sell"},{"price":"1053.15","symbol":"BCHUSDT","id":"10531500","side":"Buy"},{"price":"1055.25","symbol":"BCHUSDT","id":"10552500","side":"Sell"}],"update":[{"price":"1054.30","symbol":"BCHUSDT","id":"10543000","side":"Buy","size":5.42},{"price":"1055.45","symbol":"BCHUSDT","id":"10554500","side":"Sell","size":3.12},{"price":"1054.25","symbol":"BCHUSDT","id":"10542500","side":"Buy","size":14.009999},{"price":"1054.20","symbol":"BCHUSDT","id":"10542000","side":"Buy","size":3.26}],"insert":[{"price":"1056.40","symbol":"BCHUSDT","id":"10564000","side":"Sell","size":1},{"price":"1055.20","symbol":"BCHUSDT","id":"10552000","side":"Sell","size":13.48},{"price":"1054.40","symbol":"BCHUSDT","id":"10544000","side":"Buy","size":16.390001}]},"cross_seq":"864132082","timestamp_e6":"1618677787368709"}
1618677787.690819: {"topic":"orderBookL2_25.XTZUSDT","type":"delta","data":{"delete":[],"update":[{"price":"7.207","symbol":"XTZUSDT","id":"72070","side":"Buy","size":80.5}],"insert":[]},"cross_seq":"726228160","timestamp_e6":"1618677787374623"}
1618677787.69084: {"topic":"orderBookL2_25.LTCUSDT","type":"delta","data":{"delete":[{"price":"313.14","symbol":"LTCUSDT","id":"3131400","side":"Sell"}],"update":[{"price":"312.87","symbol":"LTCUSDT","id":"3128700","side":"Sell","size":1.5},{"price":"312.81","symbol":"LTCUSDT","id":"3128100","side":"Buy","size":134}],"insert":[{"price":"312.82","symbol":"LTCUSDT","id":"3128200","side":"Sell","size":0.6}]},"cross_seq":"1684522061","timestamp_e6":"1618677787381365"}
1618677787.6908748: {"topic":"orderBookL2_25.BCHUSDT","type":"delta","data":{"delete":[{"price":"1054.45","symbol":"BCHUSDT","id":"10544500","side":"Buy"}],"update":[],"insert":[{"price":"1053.15","symbol":"BCHUSDT","id":"10531500","side":"Buy","size":17.9}]},"cross_seq":"864132098","timestamp_e6":"1618677787390182"}
1618677787.690902: {"topic":"orderBookL2_25.XTZUSDT","type":"delta","data":{"delete":[],"update":[{"price":"7.214","symbol":"XTZUSDT","id":"72140","side":"Sell","size":2309},{"price":"7.201","symbol":"XTZUSDT","id":"72010","side":"Buy","size":1210.7999},{"price":"7.215","symbol":"XTZUSDT","id":"72150","side":"Sell","size":749.2},{"price":"7.218","symbol":"XTZUSDT","id":"72180","side":"Sell","size":2352.2},{"price":"7.216","symbol":"XTZUSDT","id":"72160","side":"Sell","size":1798.3999},{"price":"7.217","symbol":"XTZUSDT","id":"72170","side":"Sell","size":335.1}],"insert":[]},"cross_seq":"726228166","timestamp_e6":"1618677787414575"}
1618677787.690942: {"topic":"orderBookL2_25.UNIUSDT","type":"delta","data":{"delete":[{"price":"35.389","symbol":"UNIUSDT","id":"353890","side":"Buy"}],"update":[],"insert":[{"price":"35.357","symbol":"UNIUSDT","id":"353570","side":"Buy","size":37.5}]},"cross_seq":"916952998","timestamp_e6":"1618677787422470"}
1618677787.6909702: {"topic":"orderBookL2_25.ADAUSDT","type":"delta","data":{"delete":[{"price":"1.3845","symbol":"ADAUSDT","id":"13845","side":"Buy"}],"update":[{"price":"1.3879","symbol":"ADAUSDT","id":"13879","side":"Sell","size":7213.9995},{"price":"1.3857","symbol":"ADAUSDT","id":"13857","side":"Buy","size":2752.0002},{"price":"1.3882","symbol":"ADAUSDT","id":"13882","side":"Sell","size":4844},{"price":"1.3883","symbol":"ADAUSDT","id":"13883","side":"Sell","size":922},{"price":"1.3859","symbol":"ADAUSDT","id":"13859","side":"Buy","size":5272},{"price":"1.3858","symbol":"ADAUSDT","id":"13858","side":"Buy","size":3701}],"insert":[{"price":"1.3861","symbol":"ADAUSDT","id":"13861","side":"Buy","size":3970.0002}]},"cross_seq":"916952998","timestamp_e6":"1618677787422335"}
1618677787.69102: {"topic":"orderBookL2_25.LTCUSDT","type":"delta","data":{"delete":[{"price":"312.56","symbol":"LTCUSDT","id":"3125600","side":"Buy"}],"update":[{"price":"312.77","symbol":"LTCUSDT","id":"3127700","side":"Buy","size":1},{"price":"312.78","symbol":"LTCUSDT","id":"3127800","side":"Buy","size":66},{"price":"312.92","symbol":"LTCUSDT","id":"3129200","side":"Sell","size":33.5},{"price":"312.76","symbol":"LTCUSDT","id":"3127600","side":"Buy","size":1.5}],"insert":[{"price":"312.79","symbol":"LTCUSDT","id":"3127900","side":"Buy","size":95.3}]},"cross_seq":"1684522073","timestamp_e6":"1618677787437821"}
1618677787.691063: {"topic":"orderBookL2_25.BCHUSDT","type":"delta","data":{"delete":[{"price":"1054.35","symbol":"BCHUSDT","id":"10543500","side":"Buy"},{"price":"1056.40","symbol":"BCHUSDT","id":"10564000","side":"Sell"}],"update":[{"price":"1054.20","symbol":"BCHUSDT","id":"10542000","side":"Buy","size":6.29},{"price":"1054.25","symbol":"BCHUSDT","id":"10542500","side":"Buy","size":8.89},{"price":"1055.50","symbol":"BCHUSDT","id":"10555000","side":"Sell","size":6.19},{"price":"1054.30","symbol":"BCHUSDT","id":"10543000","side":"Buy","size":14.009999},{"price":"1055.45","symbol":"BCHUSDT","id":"10554500","side":"Sell","size":5.89},{"price":"1055.35","symbol":"BCHUSDT","id":"10553500","side":"Sell","size":10.21}],"insert":[{"price":"1055.30","symbol":"BCHUSDT","id":"10553000","side":"Sell","size":13.48},{"price":"1054.45","symbol":"BCHUSDT","id":"10544500","side":"Buy","size":16.390001}]},"cross_seq":"864132117","timestamp_e6":"1618677787449968"}
1618677787.691124: {"topic":"orderBookL2_25.XTZUSDT","type":"delta","data":{"delete":[],"update":[{"price":"7.201","symbol":"XTZUSDT","id":"72010","side":"Buy","size":696.6}],"insert":[]},"cross_seq":"726228167","timestamp_e6":"1618677787454539"}
1618677787.691145: {"topic":"orderBookL2_25.UNIUSDT","type":"delta","data":{"delete":[],"update":[{"price":"35.401","symbol":"UNIUSDT","id":"354010","side":"Buy","size":284.69998}],"insert":[]},"cross_seq":"916953000","timestamp_e6":"1618677787462367"}
1618677787.6911628: {"topic":"orderBookL2_25.BCHUSDT","type":"delta","data":{"delete":[{"price":"1055.20","symbol":"BCHUSDT","id":"10552000","side":"Sell"},{"price":"1055.30","symbol":"BCHUSDT","id":"10553000","side":"Sell"},{"price":"1053.15","symbol":"BCHUSDT","id":"10531500","side":"Buy"}],"update":[{"price":"1055.50","symbol":"BCHUSDT","id":"10555000","side":"Sell","size":3.11},{"price":"1055.35","symbol":"BCHUSDT","id":"10553500","side":"Sell","size":4.72}],"insert":[{"price":"1055.25","symbol":"BCHUSDT","id":"10552500","side":"Sell","size":13.48},{"price":"1054.35","symbol":"BCHUSDT","id":"10543500","side":"Buy","size":12.110001},{"price":"1056.40","symbol":"BCHUSDT","id":"10564000","side":"Sell","size":1}]},"cross_seq":"864132123","timestamp_e6":"1618677787469292"}
1618677787.691218: {"topic":"orderBookL2_25.XTZUSDT","type":"delta","data":{"delete":[],"update":[{"price":"7.222","symbol":"XTZUSDT","id":"72220","side":"Sell","size":1374.6001}],"insert":[]},"cross_seq":"726228168","timestamp_e6":"1618677787494819"}
1618677787.6912389: {"topic":"orderBookL2_25.BCHUSDT","type":"delta","data":{"delete":[{"price":"1056.40","symbol":"BCHUSDT","id":"10564000","side":"Sell"},{"price":"1054.40","symbol":"BCHUSDT","id":"10544000","side":"Buy"},{"price":"1054.25","symbol":"BCHUSDT","id":"10542500","side":"Buy"}],"update":[{"price":"1054.30","symbol":"BCHUSDT","id":"10543000","side":"Buy","size":8.59},{"price":"1055.00","symbol":"BCHUSDT","id":"10550000","side":"Sell","size":0.01},{"price":"1055.50","symbol":"BCHUSDT","id":"10555000","side":"Sell","size":4.68}],"insert":[{"price":"1055.30","symbol":"BCHUSDT","id":"10553000","side":"Sell","size":10.21},{"price":"1053.15","symbol":"BCHUSDT","id":"10531500","side":"Buy","size":17.9},{"price":"1054.50","symbol":"BCHUSDT","id":"10545000","side":"Buy","size":16.390001}]},"cross_seq":"864132131","timestamp_e6":"1618677787511619"}
1618677787.691298: {"topic":"orderBookL2_25.ADAUSDT","type":"delta","data":{"delete":[],"update":[{"price":"1.3878","symbol":"ADAUSDT","id":"13878","side":"Sell","size":18448},{"price":"1.3877","symbol":"ADAUSDT","id":"13877","side":"Buy","size":1}],"insert":[]},"cross_seq":"916953006","timestamp_e6":"1618677787522325"}
1618677787.691322: {"topic":"orderBookL2_25.UNIUSDT","type":"delta","data":{"delete":[{"price":"35.357","symbol":"UNIUSDT","id":"353570","side":"Buy"},{"price":"35.359","symbol":"UNIUSDT","id":"353590","side":"Buy"},{"price":"35.358","symbol":"UNIUSDT","id":"353580","side":"Buy"}],"update":[],"insert":[{"price":"35.384","symbol":"UNIUSDT","id":"353840","side":"Buy","size":58.8},{"price":"35.383","symbol":"UNIUSDT","id":"353830","side":"Buy","size":35.4},{"price":"35.379","symbol":"UNIUSDT","id":"353790","side":"Buy","size":19.5}]},"cross_seq":"916953006","timestamp_e6":"1618677787522450"}
1618677787.69137: {"topic":"orderBookL2_25.LTCUSDT","type":"delta","data":{"delete":[{"price":"313.13","symbol":"LTCUSDT","id":"3131300","side":"Sell"}],"update":[{"price":"312.92","symbol":"LTCUSDT","id":"3129200","side":"Sell","size":33.2}],"insert":[{"price":"312.85","symbol":"LTCUSDT","id":"3128500","side":"Sell","size":0.3}]},"cross_seq":"1684522089","timestamp_e6":"1618677787538331"}
1618677787.691401: {"topic":"orderBookL2_25.LTCUSDT","type":"delta","data":{"delete":[{"price":"312.82","symbol":"LTCUSDT","id":"3128200","side":"Sell"}],"update":[],"insert":[{"price":"313.13","symbol":"LTCUSDT","id":"3131300","side":"Sell","size":87}]},"cross_seq":"1684522090","timestamp_e6":"1618677787559039"}
1618677787.691427: {"topic":"orderBookL2_25.DOTUSDT","type":"delta","data":{"delete":[],"update":[{"price":"43.525","symbol":"DOTUSDT","id":"435250","side":"Sell","size":299.6},{"price":"43.600","symbol":"DOTUSDT","id":"436000","side":"Sell","size":85.6}],"insert":[]},"cross_seq":"916953017","timestamp_e6":"1618677787562472"}
1618677787.6914492: {"topic":"orderBookL2_25.ADAUSDT","type":"delta","data":{"delete":[{"price":"1.3873","symbol":"ADAUSDT","id":"13873","side":"Buy"},{"price":"1.3861","symbol":"ADAUSDT","id":"13861","side":"Buy"}],"update":[{"price":"1.3877","symbol":"ADAUSDT","id":"13877","side":"Buy","size":5999.9995},{"price":"1.3860","symbol":"ADAUSDT","id":"13860","side":"Buy","size":856},{"price":"1.3859","symbol":"ADAUSDT","id":"13859","side":"Buy","size":4632},{"price":"1.3872","symbol":"ADAUSDT","id":"13872","side":"Buy","size":1927.0001},{"price":"1.3883","symbol":"ADAUSDT","id":"13883","side":"Sell","size":1707},{"price":"1.3878","symbol":"ADAUSDT","id":"13878","side":"Sell","size":4698},{"price":"1.3863","symbol":"ADAUSDT","id":"13863","side":"Buy","size":5058}],"insert":[{"price":"1.3862","symbol":"ADAUSDT","id":"13862","side":"Buy","size":1645},{"price":"1.3845","symbol":"ADAUSDT","id":"13845","side":"Buy","size":4684}]},"cross_seq":"916953017","timestamp_e6":"1618677787562348"}
1618677787.691513: {"topic":"orderBookL2_25.LINKUSDT","type":"delta","data":{"delete":[],"update":[{"price":"41.040","symbol":"LINKUSDT","id":"410400","side":"Buy","size":377.6},{"price":"41.038","symbol":"LINKUSDT","id":"410380","side":"Buy","size":210.3},{"price":"41.039","symbol":"LINKUSDT","id":"410390","side":"Buy","size":502.80002},{"price":"41.042","symbol":"LINKUSDT","id":"410420","side":"Buy","size":405.1},{"price":"41.037","symbol":"LINKUSDT","id":"410370","side":"Buy","size":394.30002}],"insert":[]},"cross_seq":"1970978555","timestamp_e6":"1618677787563736"}
1618677787.69155: {"topic":"orderBookL2_25.ETHUSDT","type":"delta","data":{"delete":[],"update":[{"price":"2365.80","symbol":"ETHUSDT","id":"23658000","side":"Sell","size":33.699997},{"price":"2365.70","symbol":"ETHUSDT","id":"23657000","side":"Sell","size":51.789997}],"insert":[]},"cross_seq":"1800546217","timestamp_e6":"1618677787567066"}
1618677787.691573: {"topic":"orderBookL2_25.XTZUSDT","type":"delta","data":{"delete":[],"update":[{"price":"7.206","symbol":"XTZUSDT","id":"72060","side":"Buy","size":1016.2}],"insert":[]},"cross_seq":"726228169","timestamp_e6":"1618677787574532"}
1618677787.691591: {"topic":"orderBookL2_25.LINKUSDT","type":"delta","data":{"delete":[{"price":"41.086","symbol":"LINKUSDT","id":"410860","side":"Sell"},{"price":"41.085","symbol":"LINKUSDT","id":"410850","side":"Sell"},{"price":"41.064","symbol":"LINKUSDT","id":"410640","side":"Sell"}],"update":[{"price":"41.060","symbol":"LINKUSDT","id":"410600","side":"Sell","size":260.5},{"price":"41.065","symbol":"LINKUSDT","id":"410650","side":"Sell","size":99.7}],"insert":[{"price":"41.061","symbol":"LINKUSDT","id":"410610","side":"Sell","size":180.59999},{"price":"41.062","symbol":"LINKUSDT","id":"410620","side":"Sell","size":133.2},{"price":"41.063","symbol":"LINKUSDT","id":"410630","side":"Sell","size":85.4}]},"cross_seq":"1970978566","timestamp_e6":"1618677787583824"}
1618677787.691649: {"topic":"orderBookL2_25.DOTUSDT","type":"delta","data":{"delete":[],"update":[{"price":"43.545","symbol":"DOTUSDT","id":"435450","side":"Sell","size":315}],"insert":[]},"cross_seq":"916953025","timestamp_e6":"1618677787583600"}
1618677787.691668: {"topic":"orderBookL2_25.ADAUSDT","type":"delta","data":{"delete":[{"price":"1.3877","symbol":"ADAUSDT","id":"13877","side":"Buy"}],"update":[{"price":"1.3858","symbol":"ADAUSDT","id":"13858","side":"Buy","size":3965.9998},{"price":"1.3860","symbol":"ADAUSDT","id":"13860","side":"Buy","size":1645},{"price":"1.3862","symbol":"ADAUSDT","id":"13862","side":"Buy","size":2325},{"price":"1.3878","symbol":"ADAUSDT","id":"13878","side":"Sell","size":6771}],"insert":[{"price":"1.3861","symbol":"ADAUSDT","id":"13861","side":"Buy","size":2758}]},"cross_seq":"916953025","timestamp_e6":"1618677787583447"}
1618677787.691709: {"topic":"orderBookL2_25.LTCUSDT","type":"delta","data":{"delete":[{"price":"312.76","symbol":"LTCUSDT","id":"3127600","side":"Buy"},{"price":"312.85","symbol":"LTCUSDT","id":"3128500","side":"Sell"},{"price":"312.77","symbol":"LTCUSDT","id":"3127700","side":"Buy"}],"update":[{"price":"312.89","symbol":"LTCUSDT","id":"3128900","side":"Sell","size":76.8},{"price":"312.81","symbol":"LTCUSDT","id":"3128100","side":"Buy","size":436.5}],"insert":[{"price":"312.55","symbol":"LTCUSDT","id":"3125500","side":"Buy","size":84.8},{"price":"313.14","symbol":"LTCUSDT","id":"3131400","side":"Sell","size":28.2},{"price":"312.56","symbol":"LTCUSDT","id":"3125600","side":"Buy","size":116.600006}]},"cross_seq":"1684522096","timestamp_e6":"1618677787585681"}
1618677787.691766: {"topic":"orderBookL2_25.ETHUSDT","type":"delta","data":{"delete":[],"update":[{"price":"2365.20","symbol":"ETHUSDT","id":"23652000","side":"Sell","size":15.150001}],"insert":[]},"cross_seq":"1800546218","timestamp_e6":"1618677787587160"}
1618677787.691786: {"topic":"orderBookL2_25.LTCUSDT","type":"delta","data":{"delete":[{"price":"312.88","symbol":"LTCUSDT","id":"3128800","side":"Sell"},{"price":"312.87","symbol":"LTCUSDT","id":"3128700","side":"Sell"},{"price":"312.91","symbol":"LTCUSDT","id":"3129100","side":"Sell"},{"price":"312.92","symbol":"LTCUSDT","id":"3129200","side":"Sell"},{"price":"312.94","symbol":"LTCUSDT","id":"3129400","side":"Sell"},{"price":"312.90","symbol":"LTCUSDT","id":"3129000","side":"Sell"},{"price":"312.95","symbol":"LTCUSDT","id":"3129500","side":"Sell"},{"price":"312.89","symbol":"LTCUSDT","id":"3128900","side":"Sell"},{"price":"312.79","symbol":"LTCUSDT","id":"3127900","side":"Buy"},{"price":"312.55","symbol":"LTCUSDT","id":"3125500","side":"Buy"},{"price":"312.97","symbol":"LTCUSDT","id":"3129700","side":"Sell"},{"price":"312.56","symbol":"LTCUSDT","id":"3125600","side":"Buy"},{"price":"312.93","symbol":"LTCUSDT","id":"3129300","side":"Sell"}],"update":[{"price":"313.00","symbol":"LTCUSDT","id":"3130000","side":"Sell","size":63.3},{"price":"312.67","symbol":"LTCUSDT","id":"3126700","side":"Buy","size":201.5},{"price":"313.02","symbol":"LTCUSDT","id":"3130200","side":"Sell","size":50},{"price":"313.01","symbol":"LTCUSDT","id":"3130100","side":"Sell","size":24.099998},{"price":"313.06","symbol":"LTCUSDT","id":"3130600","side":"Sell","size":58.4},{"price":"312.80","symbol":"LTCUSDT","id":"3128000","side":"Buy","size":23.6},{"price":"313.03","symbol":"LTCUSDT","id":"3130300","side":"Sell","size":154.3},{"price":"312.81","symbol":"LTCUSDT","id":"3128100","side":"Buy","size":316.2}],"insert":[{"price":"313.20","symbol":"LTCUSDT","id":"3132000","side":"Sell","size":118.200005},{"price":"313.15","symbol":"LTCUSDT","id":"3131500","side":"Sell","size":71.9},{"price":"313.17","symbol":"LTCUSDT","id":"3131700","side":"Sell","size":91.6},{"price":"313.19","symbol":"LTCUSDT","id":"3131900","side":"Sell","size":35.3},{"price":"312.84","symbol":"LTCUSDT","id":"3128400","side":"Buy","size":267.2},{"price":"313.22","symbol":"LTCUSDT","id":"3132200","side":"Sell","size":171.5},{"price":"313.18","symbol":"LTCUSDT","id":"3131800","side":"Sell","size":51.6},{"price":"313.21","symbol":"LTCUSDT","id":"3132100","side":"Sell","size":135},{"price":"312.99","symbol":"LTCUSDT","id":"3129900","side":"Sell","size":55.800003},{"price":"312.86","symbol":"LTCUSDT","id":"3128600","side":"Buy","size":132.40001},{"price":"312.85","symbol":"LTCUSDT","id":"3128500","side":"Buy","size":117.799995},{"price":"312.98","symbol":"LTCUSDT","id":"3129800","side":"Sell","size":76.8},{"price":"313.16","symbol":"LTCUSDT","id":"3131600","side":"Sell","size":3.5}]},"cross_seq":"1684522154","timestamp_e6":"1618677787601651"}
1618677787.708695: {"topic":"orderBookL2_25.ADAUSDT","type":"delta","data":{"delete":[{"price":"1.3901","symbol":"ADAUSDT","id":"13901","side":"Sell"},{"price":"1.3902","symbol":"ADAUSDT","id":"13902","side":"Sell"},{"price":"1.3898","symbol":"ADAUSDT","id":"13898","side":"Sell"},{"price":"1.3899","symbol":"ADAUSDT","id":"13899","side":"Sell"},{"price":"1.3900","symbol":"ADAUSDT","id":"13900","side":"Sell"},{"price":"1.3870","symbol":"ADAUSDT","id":"13870","side":"Buy"},{"price":"1.3864","symbol":"ADAUSDT","id":"13864","side":"Buy"}],"update":[{"price":"1.3881","symbol":"ADAUSDT","id":"13881","side":"Sell","size":5991.0005},{"price":"1.3884","symbol":"ADAUSDT","id":"13884","side":"Sell","size":1897},{"price":"1.3883","symbol":"ADAUSDT","id":"13883","side":"Sell","size":2488},{"price":"1.3857","symbol":"ADAUSDT","id":"13857","side":"Buy","size":3858.9998},{"price":"1.3878","symbol":"ADAUSDT","id":"13878","side":"Sell","size":2104},{"price":"1.3863","symbol":"ADAUSDT","id":"13863","side":"Buy","size":2300},{"price":"1.3882","symbol":"ADAUSDT","id":"13882","side":"Sell","size":5801.0005}],"insert":[{"price":"1.3844","symbol":"ADAUSDT","id":"13844","side":"Buy","size":181.00002},{"price":"1.3876","symbol":"ADAUSDT","id":"13876","side":"Sell","size":4304},{"price":"1.3843","symbol":"ADAUSDT","id":"13843","side":"Buy","size":5092},{"price":"1.3874","symbol":"ADAUSDT","id":"13874","side":"Sell","size":4585},{"price":"1.3877","symbol":"ADAUSDT","id":"13877","side":"Sell","size":3453},{"price":"1.3875","symbol":"ADAUSDT","id":"13875","side":"Sell","size":4531},{"price":"1.3873","symbol":"ADAUSDT","id":"13873","side":"Sell","size":4849}]},"cross_seq":"916953060","timestamp_e6":"1618677787603679"}
1618677787.708905: {"topic":"orderBookL2_25.UNIUSDT","type":"delta","data":{"delete":[],"update":[{"price":"35.401","symbol":"UNIUSDT","id":"354010","side":"Buy","size":220.7}],"insert":[]},"cross_seq":"916953060","timestamp_e6":"1618677787605071"}
1618677787.7089448: {"topic":"orderBookL2_25.BCHUSDT","type":"delta","data":{"delete":[{"price":"1055.30","symbol":"BCHUSDT","id":"10553000","side":"Sell"},{"price":"1054.45","symbol":"BCHUSDT","id":"10544500","side":"Buy"},{"price":"1055.25","symbol":"BCHUSDT","id":"10552500","side":"Sell"},{"price":"1054.30","symbol":"BCHUSDT","id":"10543000","side":"Buy"},{"price":"1054.35","symbol":"BCHUSDT","id":"10543500","side":"Buy"}],"update":[{"price":"1055.35","symbol":"BCHUSDT","id":"10553500","side":"Sell","size":6.19},{"price":"1055.40","symbol":"BCHUSDT","id":"10554000","side":"Sell","size":3.67}],"insert":[{"price":"1054.55","symbol":"BCHUSDT","id":"10545500","side":"Buy","size":16.390001},{"price":"1055.15","symbol":"BCHUSDT","id":"10551500","side":"Sell","size":13.48},{"price":"1054.40","symbol":"BCHUSDT","id":"10544000","side":"Buy","size":14.009999},{"price":"1055.20","symbol":"BCHUSDT","id":"10552000","side":"Sell","size":10.21},{"price":"1053.10","symbol":"BCHUSDT","id":"10531000","side":"Buy","size":5.48}]},"cross_seq":"864132144","timestamp_e6":"1618677787610094"}
1618677787.718328: {"topic":"orderBookL2_25.LTCUSDT","type":"delta","data":{"delete":[{"price":"313.09","symbol":"LTCUSDT","id":"3130900","side":"Sell"},{"price":"312.99","symbol":"LTCUSDT","id":"3129900","side":"Sell"},{"price":"312.98","symbol":"LTCUSDT","id":"3129800","side":"Sell"},{"price":"313.05","symbol":"LTCUSDT","id":"3130500","side":"Sell"},{"price":"312.58","symbol":"LTCUSDT","id":"3125800","side":"Buy"},{"price":"312.57","symbol":"LTCUSDT","id":"3125700","side":"Buy"},{"price":"313.01","symbol":"LTCUSDT","id":"3130100","side":"Sell"},{"price":"313.04","symbol":"LTCUSDT","id":"3130400","side":"Sell"}],"update":[{"price":"313.02","symbol":"LTCUSDT","id":"3130200","side":"Sell","size":35.2},{"price":"312.69","symbol":"LTCUSDT","id":"3126900","side":"Buy","size":157.2},{"price":"313.20","symbol":"LTCUSDT","id":"3132000","side":"Sell","size":99.399994},{"price":"313.08","symbol":"LTCUSDT","id":"3130800","side":"Sell","size":63.3},{"price":"313.00","symbol":"LTCUSDT","id":"3130000","side":"Sell","size":44.999996},{"price":"312.68","symbol":"LTCUSDT","id":"3126800","side":"Buy","size":203.40001},{"price":"312.80","symbol":"LTCUSDT","id":"3128000","side":"Buy","size":41.4},{"price":"313.10","symbol":"LTCUSDT","id":"3131000","side":"Sell","size":19},{"price":"312.81","symbol":"LTCUSDT","id":"3128100","side":"Buy","size":346.00003},{"price":"312.84","symbol":"LTCUSDT","id":"3128400","side":"Buy","size":359.99997},{"price":"313.22","symbol":"LTCUSDT","id":"3132200","side":"Sell","size":95.600006},{"price":"312.86","symbol":"LTCUSDT","id":"3128600","side":"Buy","size":134.9},{"price":"312.59","symbol":"LTCUSDT","id":"3125900","side":"Buy","size":37.2},{"price":"312.75","symbol":"LTCUSDT","id":"3127500","side":"Buy","size":51.800003},{"price":"313.03","symbol":"LTCUSDT","id":"3130300","side":"Sell","size":1.5},{"price":"313.06","symbol":"LTCUSDT","id":"3130600","side":"Sell","size":78.3}],"insert":[{"price":"313.23","symbol":"LTCUSDT","id":"3132300","side":"Sell","size":86.6},{"price":"312.83","symbol":"LTCUSDT","id":"3128300","side":"Buy","size":71.7},{"price":"312.82","symbol":"LTCUSDT","id":"3128200","side":"Buy","size":51.800003},{"price":"313.26","symbol":"LTCUSDT","id":"3132600","side":"Sell","size":4.8},{"price":"312.87","symbol":"LTCUSDT","id":"3128700","side":"Sell","size":0.6},{"price":"313.24","symbol":"LTCUSDT","id":"3132400","side":"Sell","size":135.7},{"price":"313.27","symbol":"LTCUSDT","id":"3132700","side":"Sell","size":57.8},{"price":"313.25","symbol":"LTCUSDT","id":"3132500","side":"Sell","size":212.59999}]},"cross_seq":"1684522232","timestamp_e6":"1618677787620372"}
1618677787.718594: {"topic":"orderBookL2_25.ADAUSDT","type":"delta","data":{"delete":[{"price":"1.3861","symbol":"ADAUSDT","id":"13861","side":"Buy"},{"price":"1.3862","symbol":"ADAUSDT","id":"13862","side":"Buy"}],"update":[{"price":"1.3873","symbol":"ADAUSDT","id":"13873","side":"Sell","size":4879},{"price":"1.3863","symbol":"ADAUSDT","id":"13863","side":"Buy","size":5058},{"price":"1.3872","symbol":"ADAUSDT","id":"13872","side":"Buy","size":28350},{"price":"1.3860","symbol":"ADAUSDT","id":"13860","side":"Buy","size":789},{"price":"1.3874","symbol":"ADAUSDT","id":"13874","side":"Sell","size":6658},{"price":"1.3878","symbol":"ADAUSDT","id":"13878","side":"Sell","size":1708}],"insert":[{"price":"1.3864","symbol":"ADAUSDT","id":"13864","side":"Buy","size":3970.0002},{"price":"1.3842","symbol":"ADAUSDT","id":"13842","side":"Buy","size":2042.9999}]},"cross_seq":"916953086","timestamp_e6":"1618677787622325"}
1618677787.718689: {"topic":"orderBookL2_25.BCHUSDT","type":"delta","data":{"delete":[{"price":"1055.10","symbol":"BCHUSDT","id":"10551000","side":"Sell"}],"update":[{"price":"1055.65","symbol":"BCHUSDT","id":"10556500","side":"Sell","size":8.9},{"price":"1055.75","symbol":"BCHUSDT","id":"10557500","side":"Sell","size":8.35},{"price":"1055.60","symbol":"BCHUSDT","id":"10556000","side":"Sell","size":13.43},{"price":"1055.70","symbol":"BCHUSDT","id":"10557000","side":"Sell","size":10.19},{"price":"1055.80","symbol":"BCHUSDT","id":"10558000","side":"Sell","size":7.66}],"insert":[{"price":"1056.40","symbol":"BCHUSDT","id":"10564000","side":"Sell","size":1}]},"cross_seq":"864132159","timestamp_e6":"1618677787628722"}
1618677787.7211242: {"topic":"orderBookL2_25.XTZUSDT","type":"delta","data":{"delete":[],"update":[{"price":"7.227","symbol":"XTZUSDT","id":"72270","side":"Sell","size":296.7}],"insert":[]},"cross_seq":"726228170","timestamp_e6":"1618677787635037"}
1618677787.868458: {"topic":"orderBookL2_25.LTCUSDT","type":"delta","data":{"delete":[{"price":"312.74","symbol":"LTCUSDT","id":"3127400","side":"Buy"},{"price":"312.78","symbol":"LTCUSDT","id":"3127800","side":"Buy"},{"price":"312.87","symbol":"LTCUSDT","id":"3128700","side":"Sell"},{"price":"313.03","symbol":"LTCUSDT","id":"3130300","side":"Sell"},{"price":"312.75","symbol":"LTCUSDT","id":"3127500","side":"Buy"},{"price":"313.27","symbol":"LTCUSDT","id":"3132700","side":"Sell"}],"update":[{"price":"313.06","symbol":"LTCUSDT","id":"3130600","side":"Sell","size":76.8},{"price":"312.84","symbol":"LTCUSDT","id":"3128400","side":"Buy","size":343.80002},{"price":"312.59","symbol":"LTCUSDT","id":"3125900","side":"Buy","size":74.700005},{"price":"312.81","symbol":"LTCUSDT","id":"3128100","side":"Buy","size":46}],"insert":[{"price":"312.79","symbol":"LTCUSDT","id":"3127900","side":"Buy","size":77.2},{"price":"312.76","symbol":"LTCUSDT","id":"3127600","side":"Buy","size":76.600006},{"price":"312.97","symbol":"LTCUSDT","id":"3129700","side":"Sell","size":1.5},{"price":"312.77","symbol":"LTCUSDT","id":"3127700","side":"Buy","size":1},{"price":"312.94","symbol":"LTCUSDT","id":"3129400","side":"Sell","size":1.5},{"price":"313.09","symbol":"LTCUSDT","id":"3130900","side":"Sell","size":33.2}]},"cross_seq":"1684522252","timestamp_e6":"1618677787639107"}
1618677787.868675: {"topic":"trade.ADAUSDT","data":[{"symbol":"ADAUSDT","tick_direction":"PlusTick","price":"1.3877","size":1,"timestamp":"2021-04-17T16:43:07.000Z","trade_time_ms":"1618677787538","side":"Sell","trade_id":"45eb82c5-8675-5a57-853c-41818bff5db8"},{"symbol":"ADAUSDT","tick_direction":"MinusTick","price":"1.3873","size":1,"timestamp":"2021-04-17T16:43:07.000Z","trade_time_ms":"1618677787538","side":"Sell","trade_id":"f962cf71-63dd-5449-a234-8ce5fe0efdae"},{"symbol":"ADAUSDT","tick_direction":"MinusTick","price":"1.3872","size":2073,"timestamp":"2021-04-17T16:43:07.000Z","trade_time_ms":"1618677787538","side":"Sell","trade_id":"93c61926-9762-5e1e-a881-e707f27741ae"}]}
1618677787.868735: {"topic":"orderBookL2_25.LTCUSDT","type":"delta","data":{"delete":[{"price":"312.94","symbol":"LTCUSDT","id":"3129400","side":"Sell"},{"price":"312.59","symbol":"LTCUSDT","id":"3125900","side":"Buy"},{"price":"312.97","symbol":"LTCUSDT","id":"3129700","side":"Sell"},{"price":"312.60","symbol":"LTCUSDT","id":"3126000","side":"Buy"},{"price":"312.63","symbol":"LTCUSDT","id":"3126300","side":"Buy"},{"price":"312.64","symbol":"LTCUSDT","id":"3126400","side":"Buy"},{"price":"312.61","symbol":"LTCUSDT","id":"3126100","side":"Buy"},{"price":"312.62","symbol":"LTCUSDT","id":"3126200","side":"Buy"}],"update":[{"price":"313.10","symbol":"LTCUSDT","id":"3131000","side":"Sell","size":20.5},{"price":"312.86","symbol":"LTCUSDT","id":"3128600","side":"Buy","size":17.7},{"price":"312.84","symbol":"LTCUSDT","id":"3128400","side":"Buy","size":95.3},{"price":"313.07","symbol":"LTCUSDT","id":"3130700","side":"Sell","size":47.399998}],"insert":[{"price":"312.91","symbol":"LTCUSDT","id":"3129100","side":"Buy","size":95.3},{"price":"313.05","symbol":"LTCUSDT","id":"3130500","side":"Sell","size":112.3},{"price":"312.93","symbol":"LTCUSDT","id":"3129300","side":"Buy","size":132.40001},{"price":"312.88","symbol":"LTCUSDT","id":"3128800","side":"Buy","size":44.5},{"price":"313.27","symbol":"LTCUSDT","id":"3132700","side":"Sell","size":57.8},{"price":"312.90","symbol":"LTCUSDT","id":"3129000","side":"Buy","size":71.7},{"price":"312.89","symbol":"LTCUSDT","id":"3128900","side":"Buy","size":51.800003},{"price":"312.92","symbol":"LTCUSDT","id":"3129200","side":"Buy","size":117.799995}]},"cross_seq":"1684522277","timestamp_e6":"1618677787660593"}
1618677787.868901: {"topic":"orderBookL2_25.BCHUSDT","type":"delta","data":{"delete":[{"price":"1056.40","symbol":"BCHUSDT","id":"10564000","side":"Sell"},{"price":"1056.35","symbol":"BCHUSDT","id":"10563500","side":"Sell"},{"price":"1053.10","symbol":"BCHUSDT","id":"10531000","side":"Buy"},{"price":"1054.40","symbol":"BCHUSDT","id":"10544000","side":"Buy"},{"price":"1054.50","symbol":"BCHUSDT","id":"10545000","side":"Buy"}],"update":[{"price":"1055.40","symbol":"BCHUSDT","id":"10554000","side":"Sell","size":4.68}],"insert":[{"price":"1055.25","symbol":"BCHUSDT","id":"10552500","side":"Sell","size":5.49},{"price":"1055.30","symbol":"BCHUSDT","id":"10553000","side":"Sell","size":5.89},{"price":"1054.60","symbol":"BCHUSDT","id":"10546000","side":"Buy","size":16.390001},{"price":"1054.45","symbol":"BCHUSDT","id":"10544500","side":"Buy","size":14.009999},{"price":"1054.35","symbol":"BCHUSDT","id":"10543500","side":"Buy","size":6.29}]},"cross_seq":"864132168","timestamp_e6":"1618677787670592"}
1618677787.8690062: {"topic":"orderBookL2_25.XTZUSDT","type":"delta","data":{"delete":[],"update":[{"price":"7.217","symbol":"XTZUSDT","id":"72170","side":"Sell","size":563.7},{"price":"7.206","symbol":"XTZUSDT","id":"72060","side":"Buy","size":1267},{"price":"7.207","symbol":"XTZUSDT","id":"72070","side":"Buy","size":664.7},{"price":"7.215","symbol":"XTZUSDT","id":"72150","side":"Sell","size":976.69995},{"price":"7.212","symbol":"XTZUSDT","id":"72120","side":"Sell","size":7889.8},{"price":"7.208","symbol":"XTZUSDT","id":"72080","side":"Buy","size":794.6},{"price":"7.213","symbol":"XTZUSDT","id":"72130","side":"Sell","size":881.1},{"price":"7.209","symbol":"XTZUSDT","id":"72090","side":"Buy","size":1013.39996},{"price":"7.214","symbol":"XTZUSDT","id":"72140","side":"Sell","size":2529},{"price":"7.210","symbol":"XTZUSDT","id":"72100","side":"Buy","size":1159.5},{"price":"7.211","symbol":"XTZUSDT","id":"72110","side":"Buy","size":1197.3},{"price":"7.216","symbol":"XTZUSDT","id":"72160","side":"Sell","size":2001.9}],"insert":[]},"cross_seq":"726228182","timestamp_e6":"1618677787675804"}
1618677787.869101: {"topic":"orderBookL2_25.LTCUSDT","type":"delta","data":{"delete":[{"price":"312.68","symbol":"LTCUSDT","id":"3126800","side":"Buy"},{"price":"313.09","symbol":"LTCUSDT","id":"3130900","side":"Sell"},{"price":"312.92","symbol":"LTCUSDT","id":"3129200","side":"Buy"},{"price":"312.66","symbol":"LTCUSDT","id":"3126600","side":"Buy"},{"price":"312.65","symbol":"LTCUSDT","id":"3126500","side":"Buy"},{"price":"312.67","symbol":"LTCUSDT","id":"3126700","side":"Buy"},{"price":"313.13","symbol":"LTCUSDT","id":"3131300","side":"Sell"}],"update":[{"price":"313.10","symbol":"LTCUSDT","id":"3131000","side":"Sell","size":78.3},{"price":"312.93","symbol":"LTCUSDT","id":"3129300","side":"Buy","size":3},{"price":"313.11","symbol":"LTCUSDT","id":"3131100","side":"Sell","size":55.800003},{"price":"313.12","symbol":"LTCUSDT","id":"3131200","side":"Sell","size":63.3},{"price":"312.86","symbol":"LTCUSDT","id":"3128600","side":"Buy","size":16.2},{"price":"313.08","symbol":"LTCUSDT","id":"3130800","side":"Sell","size":64.8},{"price":"313.25","symbol":"LTCUSDT","id":"3132500","side":"Sell","size":263.6}],"insert":[{"price":"313.28","symbol":"LTCUSDT","id":"3132800","side":"Sell","size":60.5},{"price":"312.94","symbol":"LTCUSDT","id":"3129400","side":"Buy","size":71.7},{"price":"313.04","symbol":"LTCUSDT","id":"3130400","side":"Sell","size":0.1},{"price":"312.95","symbol":"LTCUSDT","id":"3129500","side":"Buy","size":95.3},{"price":"312.97","symbol":"LTCUSDT","id":"3129700","side":"Buy","size":132.40001},{"price":"312.96","symbol":"LTCUSDT","id":"3129600","side":"Buy","size":117.799995},{"price":"312.75","symbol":"LTCUSDT","id":"3127500","side":"Buy","size":50}]},"cross_seq":"1684522301","timestamp_e6":"1618677787679084"}
1618677787.8692532: {"topic":"orderBookL2_25.LTCUSDT","type":"delta","data":{"delete":[{"price":"312.86","symbol":"LTCUSDT","id":"3128600","side":"Buy"}],"update":[{"price":"313.17","symbol":"LTCUSDT","id":"3131700","side":"Sell","size":93.1},{"price":"312.90","symbol":"LTCUSDT","id":"3129000","side":"Buy","size":73.2},{"price":"312.81","symbol":"LTCUSDT","id":"3128100","side":"Buy","size":44.5},{"price":"313.07","symbol":"LTCUSDT","id":"3130700","side":"Sell","size":45.9}],"insert":[{"price":"312.99","symbol":"LTCUSDT","id":"3129900","side":"Buy","size":16.2}]},"cross_seq":"1684522331","timestamp_e6":"1618677787699058"}
1618677787.869312: {"topic":"orderBookL2_25.DOTUSDT","type":"delta","data":{"delete":[{"price":"43.490","symbol":"DOTUSDT","id":"434900","side":"Buy"}],"update":[{"price":"43.500","symbol":"DOTUSDT","id":"435000","side":"Buy","size":316.6},{"price":"43.530","symbol":"DOTUSDT","id":"435300","side":"Sell","size":246.5},{"price":"43.485","symbol":"DOTUSDT","id":"434850","side":"Buy","size":44.999996},{"price":"43.480","symbol":"DOTUSDT","id":"434800","side":"Buy","size":419.8},{"price":"43.535","symbol":"DOTUSDT","id":"435350","side":"Sell","size":299.6},{"price":"43.545","symbol":"DOTUSDT","id":"435450","side":"Sell","size":168.2},{"price":"43.505","symbol":"DOTUSDT","id":"435050","side":"Buy","size":408.69998}],"insert":[{"price":"43.385","symbol":"DOTUSDT","id":"433850","side":"Buy","size":63.100002}]},"cross_seq":"916953100","timestamp_e6":"1618677787702358"}
1618677787.869386: {"topic":"orderBookL2_25.BCHUSDT","type":"delta","data":{"delete":[{"price":"1054.60","symbol":"BCHUSDT","id":"10546000","side":"Buy"},{"price":"1053.20","symbol":"BCHUSDT","id":"10532000","side":"Buy"},{"price":"1054.45","symbol":"BCHUSDT","id":"10544500","side":"Buy"},{"price":"1053.15","symbol":"BCHUSDT","id":"10531500","side":"Buy"}],"update":[],"insert":[{"price":"1054.65","symbol":"BCHUSDT","id":"10546500","side":"Buy","size":16.09},{"price":"1054.50","symbol":"BCHUSDT","id":"10545000","side":"Buy","size":7.95},{"price":"1054.70","symbol":"BCHUSDT","id":"10547000","side":"Buy","size":16.390001},{"price":"1054.75","symbol":"BCHUSDT","id":"10547500","side":"Buy","size":13.329999}]},"cross_seq":"864132176","timestamp_e6":"1618677787709962"}
1618677787.8694642: {"topic":"orderBookL2_25.LTCUSDT","type":"delta","data":{"delete":[{"price":"312.95","symbol":"LTCUSDT","id":"3129500","side":"Buy"},{"price":"313.05","symbol":"LTCUSDT","id":"3130500","side":"Sell"},{"price":"313.20","symbol":"LTCUSDT","id":"3132000","side":"Sell"},{"price":"312.94","symbol":"LTCUSDT","id":"3129400","side":"Buy"},{"price":"313.06","symbol":"LTCUSDT","id":"3130600","side":"Sell"},{"price":"313.07","symbol":"LTCUSDT","id":"3130700","side":"Sell"},{"price":"312.96","symbol":"LTCUSDT","id":"3129600","side":"Buy"},{"price":"312.97","symbol":"LTCUSDT","id":"3129700","side":"Buy"}],"update":[{"price":"313.23","symbol":"LTCUSDT","id":"3132300","side":"Sell","size":96.2},{"price":"313.21","symbol":"LTCUSDT","id":"3132100","side":"Sell","size":185.7},{"price":"313.19","symbol":"LTCUSDT","id":"3131900","side":"Sell","size":86.799995},{"price":"312.75","symbol":"LTCUSDT","id":"3127500","side":"Buy","size":101.49999},{"price":"312.93","symbol":"LTCUSDT","id":"3129300","side":"Buy","size":16.7},{"price":"313.22","symbol":"LTCUSDT","id":"3132200","side":"Sell","size":31.699999},{"price":"312.99","symbol":"LTCUSDT","id":"3129900","side":"Buy","size":150.1},{"price":"313.08","symbol":"LTCUSDT","id":"3130800","side":"Sell","size":1.5},{"price":"313.18","symbol":"LTCUSDT","id":"3131800","side":"Sell","size":60.7}],"insert":[{"price":"313.31","symbol":"LTCUSDT","id":"3133100","side":"Sell","size":40.8},{"price":"312.66","symbol":"LTCUSDT","id":"3126600","side":"Buy","size":82.6},{"price":"313.32","symbol":"LTCUSDT","id":"3133200","side":"Sell","size":224.70001},{"price":"313.29","symbol":"LTCUSDT","id":"3132900","side":"Sell","size":180.7},{"price":"313.30","symbol":"LTCUSDT","id":"3133000","side":"Sell","size":56.600002},{"price":"312.68","symbol":"LTCUSDT","id":"3126800","side":"Buy","size":203.40001},{"price":"312.67","symbol":"LTCUSDT","id":"3126700","side":"Buy","size":201.5},{"price":"312.98","symbol":"LTCUSDT","id":"3129800","side":"Buy","size":117.799995}]},"cross_seq":"1684522372","timestamp_e6":"1618677787719733"}
1618677787.869635: {"topic":"orderBookL2_25.LTCUSDT","type":"delta","data":{"delete":[{"price":"313.08","symbol":"LTCUSDT","id":"3130800","side":"Sell"}],"update":[{"price":"313.18","symbol":"LTCUSDT","id":"3131800","side":"Sell","size":62.2}],"insert":[{"price":"313.33","symbol":"LTCUSDT","id":"3133300","side":"Sell","size":171.59999}]},"cross_seq":"1684522374","timestamp_e6":"1618677787738920"}
1618677787.8696818: {"topic":"orderBookL2_25.DOTUSDT","type":"delta","data":{"delete":[{"price":"43.385","symbol":"DOTUSDT","id":"433850","side":"Buy"},{"price":"43.505","symbol":"DOTUSDT","id":"435050","side":"Buy"},{"price":"43.525","symbol":"DOTUSDT","id":"435250","side":"Sell"}],"update":[{"price":"43.530","symbol":"DOTUSDT","id":"435300","side":"Sell","size":610.3},{"price":"43.535","symbol":"DOTUSDT","id":"435350","side":"Sell","size":309.6},{"price":"43.520","symbol":"DOTUSDT","id":"435200","side":"Sell","size":300},{"price":"43.485","symbol":"DOTUSDT","id":"434850","side":"Buy","size":192.29999},{"price":"43.515","symbol":"DOTUSDT","id":"435150","side":"Buy","size":211.99998},{"price":"43.495","symbol":"DOTUSDT","id":"434950","side":"Buy","size":1.3},{"price":"43.555","symbol":"DOTUSDT","id":"435550","side":"Sell","size":146.8},{"price":"43.545","symbol":"DOTUSDT","id":"435450","side":"Sell","size":280.2}],"insert":[{"price":"43.510","symbol":"DOTUSDT","id":"435100","side":"Buy","size":398.7},{"price":"43.490","symbol":"DOTUSDT","id":"434900","side":"Buy","size":124.2},{"price":"43.645","symbol":"DOTUSDT","id":"436450","side":"Sell","size":289.4}]},"cross_seq":"916953142","timestamp_e6":"1618677787742431"}
1618677787.869786: {"topic":"orderBookL2_25.UNIUSDT","type":"delta","data":{"delete":[],"update":[{"price":"35.364","symbol":"UNIUSDT","id":"353640","side":"Buy","size":24.2},{"price":"35.365","symbol":"UNIUSDT","id":"353650","side":"Buy","size":38.8},{"price":"35.411","symbol":"UNIUSDT","id":"354110","side":"Sell","size":90.200005},{"price":"35.413","symbol":"UNIUSDT","id":"354130","side":"Sell","size":39},{"price":"35.412","symbol":"UNIUSDT","id":"354120","side":"Sell","size":57.100002},{"price":"35.366","symbol":"UNIUSDT","id":"353660","side":"Buy","size":272.4},{"price":"35.367","symbol":"UNIUSDT","id":"353670","side":"Buy","size":31.3}],"insert":[]},"cross_seq":"916953142","timestamp_e6":"1618677787742641"}
1618677787.8698418: {"topic":"orderBookL2_25.BCHUSDT","type":"delta","data":{"delete":[{"price":"1054.75","symbol":"BCHUSDT","id":"10547500","side":"Buy"}],"update":[],"insert":[{"price":"1053.20","symbol":"BCHUSDT","id":"10532000","side":"Buy","size":8.37}]},"cross_seq":"864132179","timestamp_e6":"1618677787750126"}
1618677787.86988: {"topic":"orderBookL2_25.XTZUSDT","type":"delta","data":{"delete":[],"update":[{"price":"7.211","symbol":"XTZUSDT","id":"72110","side":"Buy","size":1195.2001}],"insert":[]},"cross_seq":"726228183","timestamp_e6":"1618677787755525"}
1618677787.869905: {"topic":"orderBookL2_25.LTCUSDT","type":"delta","data":{"delete":[{"price":"312.68","symbol":"LTCUSDT","id":"3126800","side":"Buy"},{"price":"313.15","symbol":"LTCUSDT","id":"3131500","side":"Sell"},{"price":"312.69","symbol":"LTCUSDT","id":"3126900","side":"Buy"},{"price":"313.16","symbol":"LTCUSDT","id":"3131600","side":"Sell"},{"price":"312.67","symbol":"LTCUSDT","id":"3126700","side":"Buy"},{"price":"313.11","symbol":"LTCUSDT","id":"3131100","side":"Sell"},{"price":"313.14","symbol":"LTCUSDT","id":"3131400","side":"Sell"},{"price":"312.66","symbol":"LTCUSDT","id":"3126600","side":"Buy"},{"price":"313.12","symbol":"LTCUSDT","id":"3131200","side":"Sell"}],"update":[{"price":"313.25","symbol":"LTCUSDT","id":"3132500","side":"Sell","size":123.8},{"price":"313.24","symbol":"LTCUSDT","id":"3132400","side":"Sell","size":43.3},{"price":"313.28","symbol":"LTCUSDT","id":"3132800","side":"Sell","size":112.5},{"price":"312.90","symbol":"LTCUSDT","id":"3129000","side":"Buy","size":71.7},{"price":"313.17","symbol":"LTCUSDT","id":"3131700","side":"Sell","size":1.5},{"price":"312.99","symbol":"LTCUSDT","id":"3129900","side":"Buy","size":151.6},{"price":"313.29","symbol":"LTCUSDT","id":"3132900","side":"Sell","size":218.5},{"price":"313.22","symbol":"LTCUSDT","id":"3132200","side":"Sell","size":144},{"price":"313.27","symbol":"LTCUSDT","id":"3132700","side":"Sell","size":64.700005},{"price":"313.23","symbol":"LTCUSDT","id":"3132300","side":"Sell","size":154},{"price":"313.10","symbol":"LTCUSDT","id":"3131000","side":"Sell","size":1.5},{"price":"313.26","symbol":"LTCUSDT","id":"3132600","side":"Sell","size":107.2}],"insert":[{"price":"313.36","symbol":"LTCUSDT","id":"3133600","side":"Sell","size":117.9},{"price":"313.34","symbol":"LTCUSDT","id":"3133400","side":"Sell","size":126.299995},{"price":"313.38","symbol":"LTCUSDT","id":"3133800","side":"Sell","size":110.50001},{"price":"313.35","symbol":"LTCUSDT","id":"3133500","side":"Sell","size":96.100006},{"price":"312.96","symbol":"LTCUSDT","id":"3129600","side":"Buy","size":71.7},{"price":"313.37","symbol":"LTCUSDT","id":"3133700","side":"Sell","size":27.6},{"price":"312.94","symbol":"LTCUSDT","id":"3129400","side":"Buy","size":44.5},{"price":"312.97","symbol":"LTCUSDT","id":"3129700","side":"Buy","size":95.3},{"price":"312.95","symbol":"LTCUSDT","id":"3129500","side":"Buy","size":51.800003}]},"cross_seq":"1684522429","timestamp_e6":"1618677787759159"}
1618677787.870102: {"topic":"trade.XTZUSDT","data":[{"symbol":"XTZUSDT","tick_direction":"ZeroPlusTick","price":"7.211","size":2.1,"timestamp":"2021-04-17T16:43:07.000Z","trade_time_ms":"1618677787740","side":"Sell","trade_id":"d4941534-27e4-5061-a286-7c232179c7a5"}]}
1618677787.870125: {"topic":"orderBookL2_25.ADAUSDT","type":"delta","data":{"delete":[{"price":"1.3843","symbol":"ADAUSDT","id":"13843","side":"Buy"},{"price":"1.3864","symbol":"ADAUSDT","id":"13864","side":"Buy"},{"price":"1.3842","symbol":"ADAUSDT","id":"13842","side":"Buy"}],"update":[{"price":"1.3860","symbol":"ADAUSDT","id":"13860","side":"Buy","size":1107},{"price":"1.3863","symbol":"ADAUSDT","id":"13863","side":"Buy","size":2300},{"price":"1.3868","symbol":"ADAUSDT","id":"13868","side":"Buy","size":7911}],"insert":[{"price":"1.3865","symbol":"ADAUSDT","id":"13865","side":"Buy","size":3970.0002},{"price":"1.3861","symbol":"ADAUSDT","id":"13861","side":"Buy","size":1214},{"price":"1.3862","symbol":"ADAUSDT","id":"13862","side":"Buy","size":949}]},"cross_seq":"916953153","timestamp_e6":"1618677787762392"}
1618677787.8701901: {"topic":"orderBookL2_25.DOTUSDT","type":"delta","data":{"delete":[{"price":"43.520","symbol":"DOTUSDT","id":"435200","side":"Sell"}],"update":[{"price":"43.515","symbol":"DOTUSDT","id":"435150","side":"Buy","size":512},{"price":"43.590","symbol":"DOTUSDT","id":"435900","side":"Sell","size":582.3}],"insert":[{"price":"43.650","symbol":"DOTUSDT","id":"436500","side":"Sell","size":151}]},"cross_seq":"916953153","timestamp_e6":"1618677787763807"}
1618677787.870229: {"topic":"orderBookL2_25.BCHUSDT","type":"delta","data":{"delete":[],"update":[{"price":"1054.20","symbol":"BCHUSDT","id":"10542000","side":"Buy","size":10.19}],"insert":[]},"cross_seq":"864132180","timestamp_e6":"1618677787768649"}
1618677787.87025: {"topic":"orderBookL2_25.LTCUSDT","type":"delta","data":{"delete":[{"price":"313.02","symbol":"LTCUSDT","id":"3130200","side":"Sell"}],"update":[{"price":"313.18","symbol":"LTCUSDT","id":"3131800","side":"Sell","size":113.799995},{"price":"313.23","symbol":"LTCUSDT","id":"3132300","side":"Sell","size":77.2},{"price":"313.22","symbol":"LTCUSDT","id":"3132200","side":"Sell","size":31.699999}],"insert":[{"price":"313.20","symbol":"LTCUSDT","id":"3132000","side":"Sell","size":55.800003}]},"cross_seq":"1684522440","timestamp_e6":"1618677787777939"}
1618677787.870911: {"topic":"orderBookL2_25.UNIUSDT","type":"delta","data":{"delete":[{"price":"35.380","symbol":"UNIUSDT","id":"353800","side":"Buy"}],"update":[{"price":"35.401","symbol":"UNIUSDT","id":"354010","side":"Buy","size":0.7},{"price":"35.383","symbol":"UNIUSDT","id":"353830","side":"Buy","size":45.699997},{"price":"35.404","symbol":"UNIUSDT","id":"354040","side":"Sell","size":43.9},{"price":"35.381","symbol":"UNIUSDT","id":"353810","side":"Buy","size":36.4},{"price":"35.382","symbol":"UNIUSDT","id":"353820","side":"Buy","size":19.9},{"price":"35.407","symbol":"UNIUSDT","id":"354070","side":"Sell","size":29.6}],"insert":[{"price":"35.359","symbol":"UNIUSDT","id":"353590","side":"Buy","size":23.3}]},"cross_seq":"916953175","timestamp_e6":"1618677787782516"}
1618677787.870986: {"topic":"orderBookL2_25.ADAUSDT","type":"delta","data":{"delete":[],"update":[{"price":"1.3872","symbol":"ADAUSDT","id":"13872","side":"Buy","size":54475},{"price":"1.3871","symbol":"ADAUSDT","id":"13871","side":"Buy","size":8000}],"insert":[]},"cross_seq":"916953175","timestamp_e6":"1618677787782336"}
1618677787.8844302: {"topic":"orderBookL2_25.LTCUSDT","type":"delta","data":{"delete":[],"update":[{"price":"313.29","symbol":"LTCUSDT","id":"3132900","side":"Sell","size":154.1},{"price":"312.99","symbol":"LTCUSDT","id":"3129900","side":"Buy","size":376.6},{"price":"313.25","symbol":"LTCUSDT","id":"3132500","side":"Sell","size":72.8}],"insert":[]},"cross_seq":"1684522443","timestamp_e6":"1618677787799886"}
1618677787.888574: {"topic":"orderBookL2_25.ADAUSDT","type":"delta","data":{"delete":[{"price":"1.3861","symbol":"ADAUSDT","id":"13861","side":"Buy"}],"update":[{"price":"1.3858","symbol":"ADAUSDT","id":"13858","side":"Buy","size":2957},{"price":"1.3880","symbol":"ADAUSDT","id":"13880","side":"Sell","size":4814},{"price":"1.3859","symbol":"ADAUSDT","id":"13859","side":"Buy","size":1004.99994},{"price":"1.3881","symbol":"ADAUSDT","id":"13881","side":"Sell","size":4761},{"price":"1.3855","symbol":"ADAUSDT","id":"13855","side":"Buy","size":1408},{"price":"1.3854","symbol":"ADAUSDT","id":"13854","side":"Buy","size":5330},{"price":"1.3883","symbol":"ADAUSDT","id":"13883","side":"Sell","size":1707},{"price":"1.3862","symbol":"ADAUSDT","id":"13862","side":"Buy","size":1645},{"price":"1.3882","symbol":"ADAUSDT","id":"13882","side":"Sell","size":4907},{"price":"1.3863","symbol":"ADAUSDT","id":"13863","side":"Buy","size":5058},{"price":"1.3857","symbol":"ADAUSDT","id":"13857","side":"Buy","size":2804},{"price":"1.3878","symbol":"ADAUSDT","id":"13878","side":"Sell","size":4645},{"price":"1.3872","symbol":"ADAUSDT","id":"13872","side":"Buy","size":66475},{"price":"1.3879","symbol":"ADAUSDT","id":"13879","side":"Sell","size":4002}],"insert":[{"price":"1.3843","symbol":"ADAUSDT","id":"13843","side":"Buy","size":5092}]},"cross_seq":"916953198","timestamp_e6":"1618677787802366"}
1618677787.888829: {"topic":"orderBookL2_25.DOTUSDT","type":"delta","data":{"delete":[{"price":"43.390","symbol":"DOTUSDT","id":"433900","side":"Buy"},{"price":"43.395","symbol":"DOTUSDT","id":"433950","side":"Buy"}],"update":[{"price":"43.515","symbol":"DOTUSDT","id":"435150","side":"Buy","size":20}],"insert":[{"price":"43.525","symbol":"DOTUSDT","id":"435250","side":"Buy","size":192},{"price":"43.520","symbol":"DOTUSDT","id":"435200","side":"Buy","size":100}]},"cross_seq":"916953198","timestamp_e6":"1618677787803709"}
1618677787.8925061: {"topic":"orderBookL2_25.BCHUSDT","type":"delta","data":{"delete":[],"update":[{"price":"1056.00","symbol":"BCHUSDT","id":"10560000","side":"Sell","size":2.89}],"insert":[]},"cross_seq":"864132181","timestamp_e6":"1618677787809087"}
1618677787.903488: {"topic":"orderBookL2_25.LTCUSDT","type":"delta","data":{"delete":[{"price":"313.04","symbol":"LTCUSDT","id":"3130400","side":"Sell"}],"update":[],"insert":[{"price":"313.39","symbol":"LTCUSDT","id":"3133900","side":"Sell","size":178.90001}]},"cross_seq":"1684522444","timestamp_e6":"1618677787818492"}
1618677787.9066129: {"topic":"orderBookL2_25.DOTUSDT","type":"delta","data":{"delete":[{"price":"43.495","symbol":"DOTUSDT","id":"434950","side":"Buy"}],"update":[{"price":"43.475","symbol":"DOTUSDT","id":"434750","side":"Buy","size":653.7},{"price":"43.460","symbol":"DOTUSDT","id":"434600","side":"Buy","size":351.90002},{"price":"43.585","symbol":"DOTUSDT","id":"435850","side":"Sell","size":401.5},{"price":"43.525","symbol":"DOTUSDT","id":"435250","side":"Buy","size":202},{"price":"43.515","symbol":"DOTUSDT","id":"435150","side":"Buy","size":10},{"price":"43.595","symbol":"DOTUSDT","id":"435950","side":"Sell","size":303.5},{"price":"43.465","symbol":"DOTUSDT","id":"434650","side":"Buy","size":365.8},{"price":"43.530","symbol":"DOTUSDT","id":"435300","side":"Sell","size":609.3},{"price":"43.455","symbol":"DOTUSDT","id":"434550","side":"Buy","size":255.1}],"insert":[{"price":"43.395","symbol":"DOTUSDT","id":"433950","side":"Buy","size":308.9}]},"cross_seq":"916953207","timestamp_e6":"1618677787822320"}
1618677788.0466402: {"topic":"orderBookL2_25.ETHUSDT","type":"delta","data":{"delete":[{"price":"2366.30","symbol":"ETHUSDT","id":"23663000","side":"Sell"},{"price":"2366.20","symbol":"ETHUSDT","id":"23662000","side":"Sell"},{"price":"2366.35","symbol":"ETHUSDT","id":"23663500","side":"Sell"},{"price":"2366.25","symbol":"ETHUSDT","id":"23662500","side":"Sell"}],"update":[{"price":"2365.45","symbol":"ETHUSDT","id":"23654500","side":"Sell","size":24.03},{"price":"2365.20","symbol":"ETHUSDT","id":"23652000","side":"Sell","size":113.22}],"insert":[{"price":"2365.30","symbol":"ETHUSDT","id":"23653000","side":"Sell","size":53.170002},{"price":"2365.35","symbol":"ETHUSDT","id":"23653500","side":"Sell","size":34.26},{"price":"2365.40","symbol":"ETHUSDT","id":"23654000","side":"Sell","size":34.350002},{"price":"2365.25","symbol":"ETHUSDT","id":"23652500","side":"Sell","size":63.239998}]},"cross_seq":"1800546231","timestamp_e6":"1618677787827450"}
1618677788.046758: {"topic":"orderBookL2_25.XTZUSDT","type":"delta","data":{"delete":[],"update":[{"price":"7.211","symbol":"XTZUSDT","id":"72110","side":"Buy","size":921.89996}],"insert":[]},"cross_seq":"726228184","timestamp_e6":"1618677787835246"}
1618677788.046784: {"topic":"orderBookL2_25.DOTUSDT","type":"delta","data":{"delete":[{"price":"43.510","symbol":"DOTUSDT","id":"435100","side":"Buy"},{"price":"43.520","symbol":"DOTUSDT","id":"435200","side":"Buy"}],"update":[{"price":"43.515","symbol":"DOTUSDT","id":"435150","side":"Buy","size":408.69998},{"price":"43.500","symbol":"DOTUSDT","id":"435000","side":"Buy","size":0.1}],"insert":[{"price":"43.495","symbol":"DOTUSDT","id":"434950","side":"Buy","size":124.2},{"price":"43.505","symbol":"DOTUSDT","id":"435050","side":"Buy","size":335.1}]},"cross_seq":"916953214","timestamp_e6":"1618677787842640"}
1618677788.0468311: {"topic":"orderBookL2_25.LINKUSDT","type":"delta","data":{"delete":[{"price":"41.084","symbol":"LINKUSDT","id":"410840","side":"Sell"}],"update":[],"insert":[{"price":"41.064","symbol":"LINKUSDT","id":"410640","side":"Sell","size":111.7}]},"cross_seq":"1970978586","timestamp_e6":"1618677787843761"}
1618677788.04686: {"topic":"orderBookL2_25.DOTUSDT","type":"delta","data":{"delete":[],"update":[{"price":"43.545","symbol":"DOTUSDT","id":"435450","side":"Sell","size":290.2},{"price":"43.535","symbol":"DOTUSDT","id":"435350","side":"Sell","size":299.6}],"insert":[]},"cross_seq":"916953215","timestamp_e6":"1618677787862393"}
1618677788.0468822: {"topic":"trade.XTZUSDT","data":[{"symbol":"XTZUSDT","tick_direction":"ZeroPlusTick","price":"7.211","size":273.30002,"timestamp":"2021-04-17T16:43:07.000Z","trade_time_ms":"1618677787818","side":"Sell","trade_id":"68661959-4a8c-5fe9-abbe-1c46d0a6c176"}]}
1618677788.046902: {"topic":"orderBookL2_25.LTCUSDT","type":"delta","data":{"delete":[],"update":[{"price":"313.24","symbol":"LTCUSDT","id":"3132400","side":"Sell","size":135.7},{"price":"312.99","symbol":"LTCUSDT","id":"3129900","side":"Buy","size":501.6},{"price":"313.17","symbol":"LTCUSDT","id":"3131700","side":"Sell","size":113.799995},{"price":"313.27","symbol":"LTCUSDT","id":"3132700","side":"Sell","size":94.299995},{"price":"313.19","symbol":"LTCUSDT","id":"3131900","side":"Sell","size":61.5},{"price":"313.23","symbol":"LTCUSDT","id":"3132300","side":"Sell","size":86.6},{"price":"313.18","symbol":"LTCUSDT","id":"3131800","side":"Sell","size":53.100002},{"price":"313.21","symbol":"LTCUSDT","id":"3132100","side":"Sell","size":122.4},{"price":"313.22","symbol":"LTCUSDT","id":"3132200","side":"Sell","size":50.7},{"price":"313.26","symbol":"LTCUSDT","id":"3132600","side":"Sell","size":74},{"price":"313.25","symbol":"LTCUSDT","id":"3132500","side":"Sell","size":248}],"insert":[]},"cross_seq":"1684522459","timestamp_e6":"1618677787861496"}
1618677788.046952: {"topic":"orderBookL2_25.ETHUSDT","type":"delta","data":{"delete":[{"price":"2363.50","symbol":"ETHUSDT","id":"23635000","side":"Buy"},{"price":"2364.45","symbol":"ETHUSDT","id":"23644500","side":"Buy"},{"price":"2363.45","symbol":"ETHUSDT","id":"23634500","side":"Buy"},{"price":"2364.15","symbol":"ETHUSDT","id":"23641500","side":"Buy"}],"update":[{"price":"2364.40","symbol":"ETHUSDT","id":"23644000","side":"Buy","size":102.95},{"price":"2364.30","symbol":"ETHUSDT","id":"23643000","side":"Buy","size":96.77},{"price":"2364.00","symbol":"ETHUSDT","id":"23640000","side":"Buy","size":77.9}],"insert":[{"price":"2364.25","symbol":"ETHUSDT","id":"23642500","side":"Buy","size":79.13},{"price":"2363.95","symbol":"ETHUSDT","id":"23639500","side":"Buy","size":4.86},{"price":"2364.20","symbol":"ETHUSDT","id":"23642000","side":"Buy","size":40.620003},{"price":"2364.10","symbol":"ETHUSDT","id":"23641000","side":"Buy","size":8.52}]},"cross_seq":"1800546249","timestamp_e6":"1618677787867409"}
1618677788.047014: {"topic":"orderBookL2_25.BCHUSDT","type":"delta","data":{"delete":[{"price":"1056.30","symbol":"BCHUSDT","id":"10563000","side":"Sell"}],"update":[{"price":"1055.80","symbol":"BCHUSDT","id":"10558000","side":"Sell","size":3.07},{"price":"1053.55","symbol":"BCHUSDT","id":"10535500","side":"Buy","size":16.81},{"price":"1053.60","symbol":"BCHUSDT","id":"10536000","side":"Buy","size":13.670001},{"price":"1055.70","symbol":"BCHUSDT","id":"10557000","side":"Sell","size":14.590001},{"price":"1055.65","symbol":"BCHUSDT","id":"10556500","side":"Sell","size":10.750001},{"price":"1055.85","symbol":"BCHUSDT","id":"10558500","side":"Sell","size":13.44}],"insert":[{"price":"1054.75","symbol":"BCHUSDT","id":"10547500","side":"Sell","size":30}]},"cross_seq":"864132189","timestamp_e6":"1618677787870243"}
1618677788.0470579: {"topic":"orderBookL2_25.LTCUSDT","type":"delta","data":{"delete":[],"update":[{"price":"313.24","symbol":"LTCUSDT","id":"3132400","side":"Sell","size":43.3},{"price":"313.22","symbol":"LTCUSDT","id":"3132200","side":"Sell","size":87.5},{"price":"313.23","symbol":"LTCUSDT","id":"3132300","side":"Sell","size":140.5},{"price":"313.20","symbol":"LTCUSDT","id":"3132000","side":"Sell","size":56.5},{"price":"313.21","symbol":"LTCUSDT","id":"3132100","side":"Sell","size":199.2}],"insert":[]},"cross_seq":"1684522471","timestamp_e6":"1618677787878069"}
1618677788.0470872: {"topic":"orderBookL2_25.ADAUSDT","type":"delta","data":{"delete":[{"price":"1.3865","symbol":"ADAUSDT","id":"13865","side":"Buy"}],"update":[{"price":"1.3862","symbol":"ADAUSDT","id":"13862","side":"Buy","size":2758},{"price":"1.3863","symbol":"ADAUSDT","id":"13863","side":"Buy","size":2300}],"insert":[{"price":"1.3861","symbol":"ADAUSDT","id":"13861","side":"Buy","size":1645}]},"cross_seq":"916953251","timestamp_e6":"1618677787882336"}
1618677788.0471191: {"topic":"orderBookL2_25.DOTUSDT","type":"delta","data":{"delete":[{"price":"43.395","symbol":"DOTUSDT","id":"433950","side":"Buy"},{"price":"43.560","symbol":"DOTUSDT","id":"435600","side":"Sell"}],"update":[{"price":"43.555","symbol":"DOTUSDT","id":"435550","side":"Sell","size":88.399994},{"price":"43.565","symbol":"DOTUSDT","id":"435650","side":"Sell","size":146.8},{"price":"43.515","symbol":"DOTUSDT","id":"435150","side":"Buy","size":398.7},{"price":"43.545","symbol":"DOTUSDT","id":"435450","side":"Sell","size":477.8},{"price":"43.525","symbol":"DOTUSDT","id":"435250","side":"Buy","size":211.99998},{"price":"43.575","symbol":"DOTUSDT","id":"435750","side":"Sell","size":503.80002},{"price":"43.500","symbol":"DOTUSDT","id":"435000","side":"Buy","size":261.1},{"price":"43.540","symbol":"DOTUSDT","id":"435400","side":"Sell","size":208.70001},{"price":"43.550","symbol":"DOTUSDT","id":"435500","side":"Sell","size":190}],"insert":[{"price":"43.510","symbol":"DOTUSDT","id":"435100","side":"Buy","size":316.5},{"price":"43.655","symbol":"DOTUSDT","id":"436550","side":"Sell","size":420.2}]},"cross_seq":"916953251","timestamp_e6":"1618677787882483"}
1618677788.047183: {"topic":"orderBookL2_25.ETHUSDT","type":"delta","data":{"delete":[],"update":[{"price":"2364.95","symbol":"ETHUSDT","id":"23649500","side":"Sell","size":186.74},{"price":"2364.90","symbol":"ETHUSDT","id":"23649000","side":"Buy","size":129.48}],"insert":[]},"cross_seq":"1800546265","timestamp_e6":"1618677787890077"}
1618677788.047203: {"topic":"orderBookL2_25.BCHUSDT","type":"delta","data":{"delete":[{"price":"1054.65","symbol":"BCHUSDT","id":"10546500","side":"Buy"},{"price":"1055.15","symbol":"BCHUSDT","id":"10551500","side":"Sell"},{"price":"1054.70","symbol":"BCHUSDT","id":"10547000","side":"Buy"},{"price":"1055.20","symbol":"BCHUSDT","id":"10552000","side":"Sell"},{"price":"1055.30","symbol":"BCHUSDT","id":"10553000","side":"Sell"}],"update":[],"insert":[{"price":"1053.15","symbol":"BCHUSDT","id":"10531500","side":"Buy","size":12.31},{"price":"1056.30","symbol":"BCHUSDT","id":"10563000","side":"Sell","size":20.72},{"price":"1054.60","symbol":"BCHUSDT","id":"10546000","side":"Buy","size":12.110001},{"price":"1055.05","symbol":"BCHUSDT","id":"10550500","side":"Sell","size":13.48},{"price":"1055.10","symbol":"BCHUSDT","id":"10551000","side":"Sell","size":10.21}]},"cross_seq":"864132210","timestamp_e6":"1618677787890217"}
1618677788.047263: {"topic":"orderBookL2_25.BCHUSDT","type":"delta","data":{"delete":[{"price":"1053.85","symbol":"BCHUSDT","id":"10538500","side":"Buy"},{"price":"1055.10","symbol":"BCHUSDT","id":"10551000","side":"Sell"},{"price":"1053.15","symbol":"BCHUSDT","id":"10531500","side":"Buy"},{"price":"1053.25","symbol":"BCHUSDT","id":"10532500","side":"Buy"},{"price":"1053.20","symbol":"BCHUSDT","id":"10532000","side":"Buy"},{"price":"1054.35","symbol":"BCHUSDT","id":"10543500","side":"Buy"},{"price":"1054.15","symbol":"BCHUSDT","id":"10541500","side":"Buy"},{"price":"1054.10","symbol":"BCHUSDT","id":"10541000","side":"Buy"},{"price":"1055.05","symbol":"BCHUSDT","id":"10550500","side":"Sell"}],"update":[{"price":"1053.75","symbol":"BCHUSDT","id":"10537500","side":"Buy","size":20},{"price":"1054.05","symbol":"BCHUSDT","id":"10540500","side":"Buy","size":30.05},{"price":"1054.20","symbol":"BCHUSDT","id":"10542000","side":"Buy","size":6.93},{"price":"1055.00","symbol":"BCHUSDT","id":"10550000","side":"Sell","size":13.49},{"price":"1054.00","symbol":"BCHUSDT","id":"10540000","side":"Buy","size":14.8}],"insert":[{"price":"1054.30","symbol":"BCHUSDT","id":"10543000","side":"Buy","size":1.47},{"price":"1053.80","symbol":"BCHUSDT","id":"10538000","side":"Buy","size":13.64},{"price":"1055.15","symbol":"BCHUSDT","id":"10551500","side":"Sell","size":5.89},{"price":"1055.20","symbol":"BCHUSDT","id":"10552000","side":"Sell","size":6.19},{"price":"1054.70","symbol":"BCHUSDT","id":"10547000","side":"Buy","size":16.390001},{"price":"1054.65","symbol":"BCHUSDT","id":"10546500","side":"Buy","size":16.09},{"price":"1054.45","symbol":"BCHUSDT","id":"10544500","side":"Buy","size":6.29},{"price":"1054.25","symbol":"BCHUSDT","id":"10542500","side":"Buy","size":8.88},{"price":"1054.40","symbol":"BCHUSDT","id":"10544000","side":"Buy","size":3.53}]},"cross_seq":"864132238","timestamp_e6":"1618677787912500"}
1618677788.04737: {"topic":"orderBookL2_25.XTZUSDT","type":"delta","data":{"delete":[],"update":[{"price":"7.212","symbol":"XTZUSDT","id":"72120","side":"Sell","size":1139.7999},{"price":"7.211","symbol":"XTZUSDT","id":"72110","side":"Buy","size":3671.9001}],"insert":[]},"cross_seq":"726228189","timestamp_e6":"1618677787916065"}
1618677788.047392: {"topic":"orderBookL2_25.ETHUSDT","type":"delta","data":{"delete":[],"update":[{"price":"2364.95","symbol":"ETHUSDT","id":"23649500","side":"Sell","size":186.81999}],"insert":[]},"cross_seq":"1800546267","timestamp_e6":"1618677787927475"}
1618677788.047408: {"topic":"orderBookL2_25.BCHUSDT","type":"delta","data":{"delete":[],"update":[{"price":"1055.45","symbol":"BCHUSDT","id":"10554500","side":"Sell","size":11.51}],"insert":[]},"cross_seq":"864132240","timestamp_e6":"1618677787928731"}
1618677788.047423: {"topic":"orderBookL2_25.XTZUSDT","type":"delta","data":{"delete":[],"update":[{"price":"7.217","symbol":"XTZUSDT","id":"72170","side":"Sell","size":658.2},{"price":"7.204","symbol":"XTZUSDT","id":"72040","side":"Buy","size":1525.7001},{"price":"7.214","symbol":"XTZUSDT","id":"72140","side":"Sell","size":2113.9001},{"price":"7.221","symbol":"XTZUSDT","id":"72210","side":"Sell","size":3413.4},{"price":"7.216","symbol":"XTZUSDT","id":"72160","side":"Sell","size":2113.5},{"price":"7.211","symbol":"XTZUSDT","id":"72110","side":"Buy","size":3947.3},{"price":"7.215","symbol":"XTZUSDT","id":"72150","side":"Sell","size":1478.8999},{"price":"7.218","symbol":"XTZUSDT","id":"72180","side":"Sell","size":1421.6}],"insert":[]},"cross_seq":"726228201","timestamp_e6":"1618677787935419"}
1618677788.04746: {"topic":"orderBookL2_25.LTCUSDT","type":"delta","data":{"delete":[{"price":"313.00","symbol":"LTCUSDT","id":"3130000","side":"Sell"}],"update":[],"insert":[{"price":"313.40","symbol":"LTCUSDT","id":"3134000","side":"Sell","size":104.100006}]},"cross_seq":"1684522474","timestamp_e6":"1618677787940170"}
1618677788.047484: {"topic":"orderBookL2_25.ADAUSDT","type":"delta","data":{"delete":[{"price":"1.3843","symbol":"ADAUSDT","id":"13843","side":"Buy"}],"update":[{"price":"1.3868","symbol":"ADAUSDT","id":"13868","side":"Buy","size":7912},{"price":"1.3880","symbol":"ADAUSDT","id":"13880","side":"Sell","size":4813},{"price":"1.3876","symbol":"ADAUSDT","id":"13876","side":"Sell","size":4305}],"insert":[{"price":"1.3865","symbol":"ADAUSDT","id":"13865","side":"Buy","size":1}]},"cross_seq":"916953257","timestamp_e6":"1618677787942681"}
1618677788.0475168: {"topic":"orderBookL2_25.ETHUSDT","type":"delta","data":{"delete":[{"price":"2365.30","symbol":"ETHUSDT","id":"23653000","side":"Sell"},{"price":"2364.25","symbol":"ETHUSDT","id":"23642500","side":"Buy"},{"price":"2365.25","symbol":"ETHUSDT","id":"23652500","side":"Sell"},{"price":"2364.30","symbol":"ETHUSDT","id":"23643000","side":"Buy"},{"price":"2364.80","symbol":"ETHUSDT","id":"23648000","side":"Buy"},{"price":"2364.20","symbol":"ETHUSDT","id":"23642000","side":"Buy"},{"price":"2365.40","symbol":"ETHUSDT","id":"23654000","side":"Sell"},{"price":"2364.40","symbol":"ETHUSDT","id":"23644000","side":"Buy"},{"price":"2365.35","symbol":"ETHUSDT","id":"23653500","side":"Sell"},{"price":"2364.35","symbol":"ETHUSDT","id":"23643500","side":"Buy"}],"update":[{"price":"2365.15","symbol":"ETHUSDT","id":"23651500","side":"Sell","size":91.5},{"price":"2365.05","symbol":"ETHUSDT","id":"23650500","side":"Sell","size":154.13},{"price":"2365.10","symbol":"ETHUSDT","id":"23651000","side":"Sell","size":104.23},{"price":"2364.55","symbol":"ETHUSDT","id":"23645500","side":"Buy","size":80.59},{"price":"2365.20","symbol":"ETHUSDT","id":"23652000","side":"Sell","size":15.150001},{"price":"2365.45","symbol":"ETHUSDT","id":"23654500","side":"Sell","size":44.460003},{"price":"2365.50","symbol":"ETHUSDT","id":"23655000","side":"Sell","size":32.670002},{"price":"2365.55","symbol":"ETHUSDT","id":"23655500","side":"Sell","size":3.84},{"price":"2365.80","symbol":"ETHUSDT","id":"23658000","side":"Sell","size":14.62},{"price":"2365.70","symbol":"ETHUSDT","id":"23657000","side":"Sell","size":17.529999},{"price":"2365.75","symbol":"ETHUSDT","id":"23657500","side":"Sell","size":17.02}],"insert":[{"price":"2364.15","symbol":"ETHUSDT","id":"23641500","side":"Buy","size":4.44},{"price":"2364.45","symbol":"ETHUSDT","id":"23644500","side":"Buy","size":37.66},{"price":"2366.35","symbol":"ETHUSDT","id":"23663500","side":"Sell","size":36.41},{"price":"2363.45","symbol":"ETHUSDT","id":"23634500","side":"Buy","size":3.87},{"price":"2366.25","symbol":"ETHUSDT","id":"23662500","side":"Sell","size":14.31},{"price":"2366.20","symbol":"ETHUSDT","id":"23662000","side":"Sell","size":13.369999},{"price":"2363.40","symbol":"ETHUSDT","id":"23634000","side":"Buy","size":14.27},{"price":"2363.35","symbol":"ETHUSDT","id":"23633500","side":"Buy","size":23.73},{"price":"2366.30","symbol":"ETHUSDT","id":"23663000","side":"Sell","size":21.07},{"price":"2363.50","symbol":"ETHUSDT","id":"23635000","side":"Buy","size":57.34}]},"cross_seq":"1800546304","timestamp_e6":"1618677787947464"}
1618677788.047648: {"topic":"orderBookL2_25.BCHUSDT","type":"delta","data":{"delete":[{"price":"1056.25","symbol":"BCHUSDT","id":"10562500","side":"Sell"},{"price":"1055.20","symbol":"BCHUSDT","id":"10552000","side":"Sell"},{"price":"1056.30","symbol":"BCHUSDT","id":"10563000","side":"Sell"}],"update":[{"price":"1055.00","symbol":"BCHUSDT","id":"10550000","side":"Sell","size":0.01}],"insert":[{"price":"1055.10","symbol":"BCHUSDT","id":"10551000","side":"Sell","size":5.89},{"price":"1054.95","symbol":"BCHUSDT","id":"10549500","side":"Sell","size":13.48},{"price":"1055.05","symbol":"BCHUSDT","id":"10550500","side":"Sell","size":5.49}]},"cross_seq":"864132252","timestamp_e6":"1618677787948876"}
1618677788.047693: {"topic":"orderBookL2_25.XTZUSDT","type":"delta","data":{"delete":[],"update":[{"price":"7.211","symbol":"XTZUSDT","id":"72110","side":"Buy","size":4047.2998},{"price":"7.212","symbol":"XTZUSDT","id":"72120","side":"Sell","size":1039.8}],"insert":[]},"cross_seq":"726228203","timestamp_e6":"1618677787955921"}
1618677788.047714: {"topic":"orderBookL2_25.LTCUSDT","type":"delta","data":{"delete":[{"price":"312.75","symbol":"LTCUSDT","id":"3127500","side":"Buy"},{"price":"312.73","symbol":"LTCUSDT","id":"3127300","side":"Buy"},{"price":"312.71","symbol":"LTCUSDT","id":"3127100","side":"Buy"},{"price":"312.76","symbol":"LTCUSDT","id":"3127600","side":"Buy"},{"price":"312.70","symbol":"LTCUSDT","id":"3127000","side":"Buy"},{"price":"312.72","symbol":"LTCUSDT","id":"3127200","side":"Buy"}],"update":[{"price":"313.25","symbol":"LTCUSDT","id":"3132500","side":"Sell","size":72.8},{"price":"313.18","symbol":"LTCUSDT","id":"3131800","side":"Sell","size":1.5},{"price":"313.17","symbol":"LTCUSDT","id":"3131700","side":"Sell","size":1.5},{"price":"313.19","symbol":"LTCUSDT","id":"3131900","side":"Sell","size":10},{"price":"313.24","symbol":"LTCUSDT","id":"3132400","side":"Sell","size":76.5},{"price":"313.20","symbol":"LTCUSDT","id":"3132000","side":"Sell","size":112.3}],"insert":[{"price":"313.09","symbol":"LTCUSDT","id":"3130900","side":"Buy","size":132.40001},{"price":"313.05","symbol":"LTCUSDT","id":"3130500","side":"Buy","size":51.800003},{"price":"313.06","symbol":"LTCUSDT","id":"3130600","side":"Buy","size":71.7},{"price":"313.08","symbol":"LTCUSDT","id":"3130800","side":"Buy","size":117.799995},{"price":"313.07","symbol":"LTCUSDT","id":"3130700","side":"Buy","size":95.3},{"price":"313.04","symbol":"LTCUSDT","id":"3130400","side":"Buy","size":44.5}]},"cross_seq":"1684522500","timestamp_e6":"1618677787959512"}
1618677788.048365: {"topic":"orderBookL2_25.ADAUSDT","type":"delta","data":{"delete":[],"update":[{"price":"1.3878","symbol":"ADAUSDT","id":"13878","side":"Sell","size":4644}],"insert":[]},"cross_seq":"916953260","timestamp_e6":"1618677787962467"}
1618677788.048395: {"topic":"orderBookL2_25.DOTUSDT","type":"delta","data":{"delete":[],"update":[{"price":"43.590","symbol":"DOTUSDT","id":"435900","side":"Sell","size":575.9},{"price":"43.530","symbol":"DOTUSDT","id":"435300","side":"Sell","size":363.8}],"insert":[]},"cross_seq":"916953260","timestamp_e6":"1618677787962631"}
1618677788.0486798: {"topic":"orderBookL2_25.LINKUSDT","type":"delta","data":{"delete":[],"update":[{"price":"41.073","symbol":"LINKUSDT","id":"410730","side":"Sell","size":48.300003}],"insert":[]},"cross_seq":"1970978587","timestamp_e6":"1618677787963710"}
1618677788.052269: {"topic":"orderBookL2_25.BCHUSDT","type":"delta","data":{"delete":[],"update":[{"price":"1056.10","symbol":"BCHUSDT","id":"10561000","side":"Sell","size":11.670001}],"insert":[]},"cross_seq":"864132253","timestamp_e6":"1618677787968845"}
1618677788.0523012: {"topic":"orderBookL2_25.ETHUSDT","type":"delta","data":{"delete":[],"update":[{"price":"2363.40","symbol":"ETHUSDT","id":"23634000","side":"Buy","size":13.18}],"insert":[]},"cross_seq":"1800546306","timestamp_e6":"1618677787967042"}
1618677788.064024: {"topic":"orderBookL2_25.LTCUSDT","type":"delta","data":{"delete":[],"update":[{"price":"312.99","symbol":"LTCUSDT","id":"3129900","side":"Buy","size":483.9},{"price":"313.07","symbol":"LTCUSDT","id":"3130700","side":"Buy","size":96.8},{"price":"313.09","symbol":"LTCUSDT","id":"3130900","side":"Buy","size":148.6}],"insert":[]},"cross_seq":"1684522526","timestamp_e6":"1618677787979410"}
1618677788.0660532: {"topic":"orderBookL2_25.ADAUSDT","type":"delta","data":{"delete":[{"price":"1.3861","symbol":"ADAUSDT","id":"13861","side":"Buy"}],"update":[{"price":"1.3863","symbol":"ADAUSDT","id":"13863","side":"Buy","size":5058},{"price":"1.3862","symbol":"ADAUSDT","id":"13862","side":"Buy","size":1809}],"insert":[{"price":"1.3864","symbol":"ADAUSDT","id":"13864","side":"Buy","size":3970.0002}]},"cross_seq":"916953264","timestamp_e6":"1618677787982320"}
1618677788.071445: {"topic":"orderBookL2_25.ETHUSDT","type":"delta","data":{"delete":[],"update":[{"price":"2364.90","symbol":"ETHUSDT","id":"23649000","side":"Buy","size":174.48}],"insert":[]},"cross_seq":"1800546307","timestamp_e6":"1618677787988368"}
1618677788.072289: {"topic":"orderBookL2_25.BCHUSDT","type":"delta","data":{"delete":[{"price":"1054.95","symbol":"BCHUSDT","id":"10549500","side":"Sell"},{"price":"1055.15","symbol":"BCHUSDT","id":"10551500","side":"Sell"}],"update":[{"price":"1055.00","symbol":"BCHUSDT","id":"10550000","side":"Sell","size":5.5},{"price":"1055.65","symbol":"BCHUSDT","id":"10556500","side":"Sell","size":16.09}],"insert":[{"price":"1054.90","symbol":"BCHUSDT","id":"10549000","side":"Sell","size":13.48},{"price":"1056.25","symbol":"BCHUSDT","id":"10562500","side":"Sell","size":4.27}]},"cross_seq":"864132259","timestamp_e6":"1618677787989089"}
1618677788.081616: {"topic":"orderBookL2_25.LTCUSDT","type":"delta","data":{"delete":[],"update":[{"price":"312.99","symbol":"LTCUSDT","id":"3129900","side":"Buy","size":358.9},{"price":"313.25","symbol":"LTCUSDT","id":"3132500","side":"Sell","size":110.200005},{"price":"313.22","symbol":"LTCUSDT","id":"3132200","side":"Sell","size":55.800003},{"price":"313.24","symbol":"LTCUSDT","id":"3132400","side":"Sell","size":33.2},{"price":"313.23","symbol":"LTCUSDT","id":"3132300","side":"Sell","size":63.3},{"price":"313.30","symbol":"LTCUSDT","id":"3133000","side":"Sell","size":16.4},{"price":"313.21","symbol":"LTCUSDT","id":"3132100","side":"Sell","size":76.8}],"insert":[]},"cross_seq":"1684522534","timestamp_e6":"1618677787997885"}
1618677788.2308931: {"topic":"orderBookL2_25.LTCUSDT","type":"delta","data":{"delete":[],"update":[{"price":"312.99","symbol":"LTCUSDT","id":"3129900","side":"Buy","size":132.40001},{"price":"313.09","symbol":"LTCUSDT","id":"3130900","side":"Buy","size":298.6},{"price":"313.05","symbol":"LTCUSDT","id":"3130500","side":"Buy","size":53.3}],"insert":[]},"cross_seq":"1684522537","timestamp_e6":"1618677788019385"}
1618677788.230947: {"topic":"orderBookL2_25.UNIUSDT","type":"delta","data":{"delete":[],"update":[{"price":"35.401","symbol":"UNIUSDT","id":"354010","side":"Buy","size":64.700005}],"insert":[]},"cross_seq":"916953270","timestamp_e6":"1618677788022400"}
1618677788.230975: {"topic":"orderBookL2_25.BCHUSDT","type":"delta","data":{"delete":[],"update":[{"price":"1054.70","symbol":"BCHUSDT","id":"10547000","side":"Buy","size":15.44}],"insert":[]},"cross_seq":"864132260","timestamp_e6":"1618677788029950"}
1618677788.231: {"topic":"orderBookL2_25.ADAUSDT","type":"delta","data":{"delete":[],"update":[{"price":"1.3859","symbol":"ADAUSDT","id":"13859","side":"Buy","size":3763},{"price":"1.3882","symbol":"ADAUSDT","id":"13882","side":"Sell","size":5210},{"price":"1.3855","symbol":"ADAUSDT","id":"13855","side":"Buy","size":2006},{"price":"1.3883","symbol":"ADAUSDT","id":"13883","side":"Sell","size":2308},{"price":"1.3881","symbol":"ADAUSDT","id":"13881","side":"Sell","size":5602},{"price":"1.3854","symbol":"ADAUSDT","id":"13854","side":"Buy","size":6239.9995},{"price":"1.3880","symbol":"ADAUSDT","id":"13880","side":"Sell","size":6846},{"price":"1.3879","symbol":"ADAUSDT","id":"13879","side":"Sell","size":6175}],"insert":[]},"cross_seq":"916953282","timestamp_e6":"1618677788042320"}
1618677788.23106: {"topic":"orderBookL2_25.UNIUSDT","type":"delta","data":{"delete":[{"price":"35.359","symbol":"UNIUSDT","id":"353590","side":"Buy"}],"update":[{"price":"35.407","symbol":"UNIUSDT","id":"354070","side":"Sell","size":38.2},{"price":"35.382","symbol":"UNIUSDT","id":"353820","side":"Buy","size":36.6},{"price":"35.404","symbol":"UNIUSDT","id":"354040","side":"Sell","size":55.399998}],"insert":[{"price":"35.380","symbol":"UNIUSDT","id":"353800","side":"Buy","size":13}]},"cross_seq":"916953282","timestamp_e6":"1618677788042454"}
1618677788.231127: {"topic":"trade.BCHUSDT","data":[{"symbol":"BCHUSDT","tick_direction":"PlusTick","price":"1054.70","size":0.95,"timestamp":"2021-04-17T16:43:08.000Z","trade_time_ms":"1618677788013","side":"Sell","trade_id":"4e6393b8-012c-5451-88c3-eae00f81ee5a"}]}
1618677788.231158: {"topic":"orderBookL2_25.XTZUSDT","type":"delta","data":{"delete":[],"update":[{"price":"7.218","symbol":"XTZUSDT","id":"72180","side":"Sell","size":1705.6},{"price":"7.226","symbol":"XTZUSDT","id":"72260","side":"Sell","size":2764.8},{"price":"7.215","symbol":"XTZUSDT","id":"72150","side":"Sell","size":598.2},{"price":"7.212","symbol":"XTZUSDT","id":"72120","side":"Sell","size":0.9},{"price":"7.217","symbol":"XTZUSDT","id":"72170","side":"Sell","size":602.8},{"price":"7.214","symbol":"XTZUSDT","id":"72140","side":"Sell","size":2994.6},{"price":"7.211","symbol":"XTZUSDT","id":"72110","side":"Buy","size":4047.5}],"insert":[]},"cross_seq":"726228236","timestamp_e6":"1618677788056277"}
1618677788.231214: {"topic":"orderBookL2_25.ADAUSDT","type":"delta","data":{"delete":[],"update":[{"price":"1.3878","symbol":"ADAUSDT","id":"13878","side":"Sell","size":1707},{"price":"1.3877","symbol":"ADAUSDT","id":"13877","side":"Sell","size":6390},{"price":"1.3881","symbol":"ADAUSDT","id":"13881","side":"Sell","size":4758},{"price":"1.3880","symbol":"ADAUSDT","id":"13880","side":"Sell","size":4813},{"price":"1.3882","symbol":"ADAUSDT","id":"13882","side":"Sell","size":4253}],"insert":[]},"cross_seq":"916953289","timestamp_e6":"1618677788062489"}
1618677788.231256: {"topic":"orderBookL2_25.UNIUSDT","type":"delta","data":{"delete":[],"update":[{"price":"35.401","symbol":"UNIUSDT","id":"354010","side":"Buy","size":284.69998}],"insert":[]},"cross_seq":"916953289","timestamp_e6":"1618677788062616"}
1618677788.2312791: {"topic":"orderBookL2_25.DOTUSDT","type":"delta","data":{"delete":[],"update":[{"price":"43.580","symbol":"DOTUSDT","id":"435800","side":"Sell","size":77.299995},{"price":"43.575","symbol":"DOTUSDT","id":"435750","side":"Sell","size":104.100006},{"price":"43.570","symbol":"DOTUSDT","id":"435700","side":"Sell","size":439.19998},{"price":"43.590","symbol":"DOTUSDT","id":"435900","side":"Sell","size":345.6},{"price":"43.595","symbol":"DOTUSDT","id":"435950","side":"Sell","size":105.700005}],"insert":[]},"cross_seq":"916953294","timestamp_e6":"1618677788082347"}
1618677788.2313228: {"topic":"orderBookL2_25.ETHUSDT","type":"delta","data":{"delete":[],"update":[{"price":"2364.90","symbol":"ETHUSDT","id":"23649000","side":"Buy","size":129.48}],"insert":[]},"cross_seq":"1800546308","timestamp_e6":"1618677788088219"}
1618677788.2313468: {"topic":"orderBookL2_25.XTZUSDT","type":"delta","data":{"delete":[],"update":[{"price":"7.205","symbol":"XTZUSDT","id":"72050","side":"Buy","size":3657.3},{"price":"7.212","symbol":"XTZUSDT","id":"72120","side":"Sell","size":2000.8999}],"insert":[]},"cross_seq":"726228238","timestamp_e6":"1618677788095758"}
1618677788.2313752: {"topic":"orderBookL2_25.LTCUSDT","type":"delta","data":{"delete":[],"update":[{"price":"313.07","symbol":"LTCUSDT","id":"3130700","side":"Buy","size":95.3},{"price":"313.09","symbol":"LTCUSDT","id":"3130900","side":"Buy","size":300.1}],"insert":[]},"cross_seq":"1684522540","timestamp_e6":"1618677788100016"}
1618677788.231403: {"topic":"orderBookL2_25.ETHUSDT","type":"delta","data":{"delete":[{"price":"2363.35","symbol":"ETHUSDT","id":"23633500","side":"Buy"},{"price":"2363.55","symbol":"ETHUSDT","id":"23635500","side":"Buy"},{"price":"2363.40","symbol":"ETHUSDT","id":"23634000","side":"Buy"},{"price":"2363.45","symbol":"ETHUSDT","id":"23634500","side":"Buy"},{"price":"2363.50","symbol":"ETHUSDT","id":"23635000","side":"Buy"}],"update":[{"price":"2364.95","symbol":"ETHUSDT","id":"23649500","side":"Sell","size":284.89},{"price":"2365.00","symbol":"ETHUSDT","id":"23650000","side":"Sell","size":128.79},{"price":"2364.45","symbol":"ETHUSDT","id":"23644500","side":"Buy","size":80.62},{"price":"2365.20","symbol":"ETHUSDT","id":"23652000","side":"Sell","size":34.23},{"price":"2365.15","symbol":"ETHUSDT","id":"23651500","side":"Sell","size":38.329998},{"price":"2365.10","symbol":"ETHUSDT","id":"23651000","side":"Sell","size":40.99},{"price":"2365.05","symbol":"ETHUSDT","id":"23650500","side":"Sell","size":56.06}],"insert":[{"price":"2364.20","symbol":"ETHUSDT","id":"23642000","side":"Buy","size":40.620003},{"price":"2364.30","symbol":"ETHUSDT","id":"23643000","side":"Buy","size":96.77},{"price":"2364.25","symbol":"ETHUSDT","id":"23642500","side":"Buy","size":79.13},{"price":"2364.40","symbol":"ETHUSDT","id":"23644000","side":"Buy","size":102.95},{"price":"2364.35","symbol":"ETHUSDT","id":"23643500","side":"Buy","size":84.53}]},"cross_seq":"1800546329","timestamp_e6":"1618677788107664"}
1618677788.231532: {"topic":"orderBookL2_25.DOTUSDT","type":"delta","data":{"delete":[],"update":[{"price":"43.590","symbol":"DOTUSDT","id":"435900","side":"Sell","size":432.59998},{"price":"43.580","symbol":"DOTUSDT","id":"435800","side":"Sell","size":285.5},{"price":"43.565","symbol":"DOTUSDT","id":"435650","side":"Sell","size":508.4},{"price":"43.525","symbol":"DOTUSDT","id":"435250","side":"Buy","size":329.6},{"price":"43.575","symbol":"DOTUSDT","id":"435750","side":"Sell","size":291.7},{"price":"43.585","symbol":"DOTUSDT","id":"435850","side":"Sell","size":188.50002},{"price":"43.570","symbol":"DOTUSDT","id":"435700","side":"Sell","size":77.6},{"price":"43.545","symbol":"DOTUSDT","id":"435450","side":"Sell","size":309.6}],"insert":[]},"cross_seq":"916953304","timestamp_e6":"1618677788122341"}
1618677788.231593: {"topic":"orderBookL2_25.ETHUSDT","type":"delta","data":{"delete":[],"update":[{"price":"2364.95","symbol":"ETHUSDT","id":"23649500","side":"Sell","size":317.39}],"insert":[]},"cross_seq":"1800546331","timestamp_e6":"1618677788127461"}
1618677788.2316182: {"topic":"orderBookL2_25.BCHUSDT","type":"delta","data":{"delete":[],"update":[{"price":"1055.80","symbol":"BCHUSDT","id":"10558000","side":"Sell","size":6.6},{"price":"1055.85","symbol":"BCHUSDT","id":"10558500","side":"Sell","size":15.2300005}],"insert":[]},"cross_seq":"864132262","timestamp_e6":"1618677788128755"}
1618677788.2316532: {"topic":"orderBookL2_25.LTCUSDT","type":"delta","data":{"delete":[],"update":[{"price":"313.09","symbol":"LTCUSDT","id":"3130900","side":"Buy","size":469.1},{"price":"313.05","symbol":"LTCUSDT","id":"3130500","side":"Buy","size":51.800003}],"insert":[]},"cross_seq":"1684522542","timestamp_e6":"1618677788139062"}
1618677788.231703: {"topic":"orderBookL2_25.DOTUSDT","type":"delta","data":{"delete":[{"price":"43.535","symbol":"DOTUSDT","id":"435350","side":"Sell"},{"price":"43.530","symbol":"DOTUSDT","id":"435300","side":"Sell"}],"update":[{"price":"43.490","symbol":"DOTUSDT","id":"434900","side":"Buy","size":171.8},{"price":"43.565","symbol":"DOTUSDT","id":"435650","side":"Sell","size":361.6},{"price":"43.510","symbol":"DOTUSDT","id":"435100","side":"Buy","size":435.5},{"price":"43.500","symbol":"DOTUSDT","id":"435000","side":"Buy","size":365.7},{"price":"43.540","symbol":"DOTUSDT","id":"435400","side":"Sell","size":405.30002},{"price":"43.555","symbol":"DOTUSDT","id":"435550","side":"Sell","size":190.79999},{"price":"43.495","symbol":"DOTUSDT","id":"434950","side":"Buy","size":251.49998}],"insert":[{"price":"43.660","symbol":"DOTUSDT","id":"436600","side":"Sell","size":444.2},{"price":"43.560","symbol":"DOTUSDT","id":"435600","side":"Sell","size":153.1}]},"cross_seq":"916953316","timestamp_e6":"1618677788143605"}
1618677788.2677891: {"topic":"orderBookL2_25.DOTUSDT","type":"delta","data":{"delete":[{"price":"43.400","symbol":"DOTUSDT","id":"434000","side":"Buy"}],"update":[{"price":"43.525","symbol":"DOTUSDT","id":"435250","side":"Buy","size":137.6}],"insert":[{"price":"43.535","symbol":"DOTUSDT","id":"435350","side":"Buy","size":192}]},"cross_seq":"916953321","timestamp_e6":"1618677788183522"}
1618677788.4094899: {"topic":"orderBookL2_25.XTZUSDT","type":"delta","data":{"delete":[],"update":[{"price":"7.204","symbol":"XTZUSDT","id":"72040","side":"Buy","size":2114.0999},{"price":"7.206","symbol":"XTZUSDT","id":"72060","side":"Buy","size":1831.2001},{"price":"7.218","symbol":"XTZUSDT","id":"72180","side":"Sell","size":1769.2001},{"price":"7.201","symbol":"XTZUSDT","id":"72010","side":"Buy","size":1242.4},{"price":"7.215","symbol":"XTZUSDT","id":"72150","side":"Sell","size":868.5},{"price":"7.203","symbol":"XTZUSDT","id":"72030","side":"Buy","size":2044.3},{"price":"7.202","symbol":"XTZUSDT","id":"72020","side":"Buy","size":2001.2},{"price":"7.205","symbol":"XTZUSDT","id":"72050","side":"Buy","size":4432.2},{"price":"7.217","symbol":"XTZUSDT","id":"72170","side":"Sell","size":1073},{"price":"7.214","symbol":"XTZUSDT","id":"72140","side":"Sell","size":3339},{"price":"7.219","symbol":"XTZUSDT","id":"72190","side":"Sell","size":1677.2}],"insert":[]},"cross_seq":"726228249","timestamp_e6":"1618677788194631"}
1618677788.4096189: {"topic":"orderBookL2_25.LTCUSDT","type":"delta","data":{"delete":[],"update":[{"price":"312.95","symbol":"LTCUSDT","id":"3129500","side":"Buy","size":133.40001}],"insert":[]},"cross_seq":"1684522546","timestamp_e6":"1618677788198675"}
1618677788.409652: {"topic":"orderBookL2_25.LTCUSDT","type":"delta","data":{"delete":[],"update":[{"price":"313.25","symbol":"LTCUSDT","id":"3132500","side":"Sell","size":129.20001}],"insert":[]},"cross_seq":"1684522547","timestamp_e6":"1618677788217974"}
1618677788.409676: {"topic":"orderBookL2_25.DOTUSDT","type":"delta","data":{"delete":[],"update":[{"price":"43.535","symbol":"DOTUSDT","id":"435350","side":"Buy","size":202},{"price":"43.525","symbol":"DOTUSDT","id":"435250","side":"Buy","size":10}],"insert":[]},"cross_seq":"916953323","timestamp_e6":"1618677788222329"}
1618677788.4097018: {"topic":"orderBookL2_25.LTCUSDT","type":"delta","data":{"delete":[],"update":[{"price":"313.09","symbol":"LTCUSDT","id":"3130900","side":"Buy","size":301.59998}],"insert":[]},"cross_seq":"1684522548","timestamp_e6":"1618677788239211"}
1618677788.409722: {"topic":"orderBookL2_25.ADAUSDT","type":"delta","data":{"delete":[{"price":"1.3844","symbol":"ADAUSDT","id":"13844","side":"Buy"}],"update":[],"insert":[{"price":"1.3861","symbol":"ADAUSDT","id":"13861","side":"Buy","size":949}]},"cross_seq":"916953324","timestamp_e6":"1618677788242338"}
1618677788.40977: {"topic":"orderBookL2_25.BCHUSDT","type":"delta","data":{"delete":[{"price":"1056.25","symbol":"BCHUSDT","id":"10562500","side":"Sell"},{"price":"1056.20","symbol":"BCHUSDT","id":"10562000","side":"Sell"}],"update":[],"insert":[{"price":"1054.95","symbol":"BCHUSDT","id":"10549500","side":"Sell","size":10.21},{"price":"1055.15","symbol":"BCHUSDT","id":"10551500","side":"Sell","size":4.68}]},"cross_seq":"864132264","timestamp_e6":"1618677788248819"}
1618677788.409819: {"topic":"orderBookL2_25.LTCUSDT","type":"delta","data":{"delete":[{"price":"313.26","symbol":"LTCUSDT","id":"3132600","side":"Sell"}],"update":[{"price":"313.39","symbol":"LTCUSDT","id":"3133900","side":"Sell","size":229.40001},{"price":"313.30","symbol":"LTCUSDT","id":"3133000","side":"Sell","size":71.1}],"insert":[{"price":"313.41","symbol":"LTCUSDT","id":"3134100","side":"Sell","size":132.2}]},"cross_seq":"1684522553","timestamp_e6":"1618677788257944"}
1618677788.4098601: {"topic":"orderBookL2_25.LTCUSDT","type":"delta","data":{"delete":[{"price":"313.41","symbol":"LTCUSDT","id":"3134100","side":"Sell"}],"update":[{"price":"313.24","symbol":"LTCUSDT","id":"3132400","side":"Sell","size":91.3},{"price":"313.06","symbol":"LTCUSDT","id":"3130600","side":"Buy","size":118.200005},{"price":"313.07","symbol":"LTCUSDT","id":"3130700","side":"Buy","size":119.600006},{"price":"313.27","symbol":"LTCUSDT","id":"3132700","side":"Sell","size":104.5},{"price":"313.23","symbol":"LTCUSDT","id":"3132300","side":"Sell","size":64.8},{"price":"313.25","symbol":"LTCUSDT","id":"3132500","side":"Sell","size":176},{"price":"313.04","symbol":"LTCUSDT","id":"3130400","side":"Buy","size":62.7},{"price":"313.08","symbol":"LTCUSDT","id":"3130800","side":"Buy","size":152.5},{"price":"313.05","symbol":"LTCUSDT","id":"3130500","side":"Buy","size":66.4}],"insert":[{"price":"313.26","symbol":"LTCUSDT","id":"3132600","side":"Sell","size":42.5}]},"cross_seq":"1684522571","timestamp_e6":"1618677788277900"}
1618677788.4099321: {"topic":"orderBookL2_25.BCHUSDT","type":"delta","data":{"delete":[],"update":[{"price":"1054.70","symbol":"BCHUSDT","id":"10547000","side":"Buy","size":35.57}],"insert":[]},"cross_seq":"864132265","timestamp_e6":"1618677788290291"}
1618677788.409954: {"topic":"orderBookL2_25.ADAUSDT","type":"delta","data":{"delete":[],"update":[{"price":"1.3881","symbol":"ADAUSDT","id":"13881","side":"Sell","size":5177},{"price":"1.3878","symbol":"ADAUSDT","id":"13878","side":"Sell","size":3880},{"price":"1.3882","symbol":"ADAUSDT","id":"13882","side":"Sell","size":4551},{"price":"1.3880","symbol":"ADAUSDT","id":"13880","side":"Sell","size":6498}],"insert":[]},"cross_seq":"916953336","timestamp_e6":"1618677788302373"}
1618677788.409985: {"topic":"orderBookL2_25.UNIUSDT","type":"delta","data":{"delete":[],"update":[{"price":"35.364","symbol":"UNIUSDT","id":"353640","side":"Buy","size":627.4}],"insert":[]},"cross_seq":"916953336","timestamp_e6":"1618677788302843"}
1618677788.410005: {"topic":"orderBookL2_25.DOTUSDT","type":"delta","data":{"delete":[{"price":"43.510","symbol":"DOTUSDT","id":"435100","side":"Buy"}],"update":[{"price":"43.565","symbol":"DOTUSDT","id":"435650","side":"Sell","size":423.99997},{"price":"43.495","symbol":"DOTUSDT","id":"434950","side":"Buy","size":365.59998},{"price":"43.505","symbol":"DOTUSDT","id":"435050","side":"Buy","size":435.5},{"price":"43.490","symbol":"DOTUSDT","id":"434900","side":"Buy","size":251.49998}],"insert":[{"price":"43.400","symbol":"DOTUSDT","id":"434000","side":"Buy","size":1.2}]},"cross_seq":"916953336","timestamp_e6":"1618677788302673"}
1618677788.410059: {"topic":"orderBookL2_25.LTCUSDT","type":"delta","data":{"delete":[],"update":[{"price":"313.10","symbol":"LTCUSDT","id":"3131000","side":"Sell","size":2.1}],"insert":[]},"cross_seq":"1684522572","timestamp_e6":"1618677788303439"}
1618677788.41008: {"topic":"orderBookL2_25.LINKUSDT","type":"delta","data":{"delete":[{"price":"41.044","symbol":"LINKUSDT","id":"410440","side":"Buy"}],"update":[{"price":"41.038","symbol":"LINKUSDT","id":"410380","side":"Buy","size":329.5},{"price":"41.040","symbol":"LINKUSDT","id":"410400","side":"Buy","size":209.9},{"price":"41.061","symbol":"LINKUSDT","id":"410610","side":"Sell","size":295},{"price":"41.060","symbol":"LINKUSDT","id":"410600","side":"Sell","size":347.4},{"price":"41.079","symbol":"LINKUSDT","id":"410790","side":"Sell","size":140.5},{"price":"41.046","symbol":"LINKUSDT","id":"410460","side":"Buy","size":417},{"price":"41.063","symbol":"LINKUSDT","id":"410630","side":"Sell","size":144},{"price":"41.055","symbol":"LINKUSDT","id":"410550","side":"Buy","size":861.89996},{"price":"41.081","symbol":"LINKUSDT","id":"410810","side":"Sell","size":187.8},{"price":"41.076","symbol":"LINKUSDT","id":"410760","side":"Sell","size":461.3},{"price":"41.041","symbol":"LINKUSDT","id":"410410","side":"Buy","size":505.4},{"price":"41.080","symbol":"LINKUSDT","id":"410800","side":"Sell","size":166},{"price":"41.065","symbol":"LINKUSDT","id":"410650","side":"Sell","size":38.1},{"price":"41.077","symbol":"LINKUSDT","id":"410770","side":"Sell","size":299.30002},{"price":"41.083","symbol":"LINKUSDT","id":"410830","side":"Sell","size":92},{"price":"41.078","symbol":"LINKUSDT","id":"410780","side":"Sell","size":259.8},{"price":"41.056","symbol":"LINKUSDT","id":"410560","side":"Sell","size":466},{"price":"41.075","symbol":"LINKUSDT","id":"410750","side":"Sell","size":275.7},{"price":"41.082","symbol":"LINKUSDT","id":"410820","side":"Sell","size":204.00002},{"price":"41.045","symbol":"LINKUSDT","id":"410450","side":"Buy","size":318}],"insert":[{"price":"41.028","symbol":"LINKUSDT","id":"410280","side":"Buy","size":425.9}]},"cross_seq":"1970978641","timestamp_e6":"1618677788305363"}
1618677788.410193: {"topic":"orderBookL2_25.BCHUSDT","type":"delta","data":{"delete":[{"price":"1056.15","symbol":"BCHUSDT","id":"10561500","side":"Sell"},{"price":"1054.55","symbol":"BCHUSDT","id":"10545500","side":"Buy"}],"update":[{"price":"1054.50","symbol":"BCHUSDT","id":"10545000","side":"Buy","size":10.969999},{"price":"1055.00","symbol":"BCHUSDT","id":"10550000","side":"Sell","size":7.14},{"price":"1055.15","symbol":"BCHUSDT","id":"10551500","side":"Sell","size":6.14},{"price":"1055.05","symbol":"BCHUSDT","id":"10550500","side":"Sell","size":9.04}],"insert":[{"price":"1055.20","symbol":"BCHUSDT","id":"10552000","side":"Sell","size":6.54},{"price":"1053.25","symbol":"BCHUSDT","id":"10532500","side":"Buy","size":3.88}]},"cross_seq":"864132276","timestamp_e6":"1618677788308680"}
1618677788.4102569: {"topic":"orderBookL2_25.XTZUSDT","type":"delta","data":{"delete":[],"update":[{"price":"7.215","symbol":"XTZUSDT","id":"72150","side":"Sell","size":1283.6}],"insert":[]},"cross_seq":"726228250","timestamp_e6":"1618677788314723"}
1618677788.410281: {"topic":"orderBookL2_25.LTCUSDT","type":"delta","data":{"delete":[{"price":"313.21","symbol":"LTCUSDT","id":"3132100","side":"Sell"},{"price":"313.23","symbol":"LTCUSDT","id":"3132300","side":"Sell"}],"update":[{"price":"313.18","symbol":"LTCUSDT","id":"3131800","side":"Sell","size":129.6},{"price":"313.20","symbol":"LTCUSDT","id":"3132000","side":"Sell","size":55.800003},{"price":"313.19","symbol":"LTCUSDT","id":"3131900","side":"Sell","size":101.299995},{"price":"313.22","symbol":"LTCUSDT","id":"3132200","side":"Sell","size":36.8}],"insert":[{"price":"313.41","symbol":"LTCUSDT","id":"3134100","side":"Sell","size":132.2},{"price":"313.42","symbol":"LTCUSDT","id":"3134200","side":"Sell","size":59.399998}]},"cross_seq":"1684522589","timestamp_e6":"1618677788318196"}
1618677788.410336: {"topic":"orderBookL2_25.DOTUSDT","type":"delta","data":{"delete":[],"update":[{"price":"43.515","symbol":"DOTUSDT","id":"435150","side":"Buy","size":399.59998}],"insert":[]},"cross_seq":"916953339","timestamp_e6":"1618677788322337"}
1618677788.410356: {"topic":"orderBookL2_25.LINKUSDT","type":"delta","data":{"delete":[],"update":[{"price":"41.056","symbol":"LINKUSDT","id":"410560","side":"Sell","size":66}],"insert":[]},"cross_seq":"1970978653","timestamp_e6":"1618677788325738"}
1618677788.561594: {"topic":"orderBookL2_25.DOTUSDT","type":"delta","data":{"delete":[],"update":[{"price":"43.540","symbol":"DOTUSDT","id":"435400","side":"Sell","size":743.8}],"insert":[]},"cross_seq":"916953340","timestamp_e6":"1618677788342344"}
1618677788.561704: {"topic":"orderBookL2_25.LINKUSDT","type":"delta","data":{"delete":[{"price":"41.083","symbol":"LINKUSDT","id":"410830","side":"Sell"},{"price":"41.054","symbol":"LINKUSDT","id":"410540","side":"Buy"},{"price":"41.062","symbol":"LINKUSDT","id":"410620","side":"Sell"},{"price":"41.050","symbol":"LINKUSDT","id":"410500","side":"Buy"},{"price":"41.053","symbol":"LINKUSDT","id":"410530","side":"Buy"}],"update":[{"price":"41.042","symbol":"LINKUSDT","id":"410420","side":"Buy","size":70.9},{"price":"41.040","symbol":"LINKUSDT","id":"410400","side":"Buy","size":305.4},{"price":"41.068","symbol":"LINKUSDT","id":"410680","side":"Sell","size":207.4},{"price":"41.067","symbol":"LINKUSDT","id":"410670","side":"Sell","size":323},{"price":"41.061","symbol":"LINKUSDT","id":"410610","side":"Sell","size":114.4},{"price":"41.046","symbol":"LINKUSDT","id":"410460","side":"Buy","size":374.1},{"price":"41.066","symbol":"LINKUSDT","id":"410660","side":"Sell","size":382.2},{"price":"41.069","symbol":"LINKUSDT","id":"410690","side":"Sell","size":233.7},{"price":"41.045","symbol":"LINKUSDT","id":"410450","side":"Buy","size":267.1},{"price":"41.036","symbol":"LINKUSDT","id":"410360","side":"Buy","size":578.7},{"price":"41.063","symbol":"LINKUSDT","id":"410630","side":"Sell","size":58.6},{"price":"41.070","symbol":"LINKUSDT","id":"410700","side":"Sell","size":160.1},{"price":"41.052","symbol":"LINKUSDT","id":"410520","side":"Buy","size":1.2},{"price":"41.041","symbol":"LINKUSDT","id":"410410","side":"Buy","size":839.6},{"price":"41.055","symbol":"LINKUSDT","id":"410550","side":"Buy","size":40},{"price":"41.051","symbol":"LINKUSDT","id":"410510","side":"Buy","size":74},{"price":"41.060","symbol":"LINKUSDT","id":"410600","side":"Sell","size":88.3},{"price":"41.071","symbol":"LINKUSDT","id":"410710","side":"Sell","size":140.1}],"insert":[{"price":"41.044","symbol":"LINKUSDT","id":"410440","side":"Buy","size":272.1},{"price":"41.058","symbol":"LINKUSDT","id":"410580","side":"Sell","size":346.00003},{"price":"41.049","symbol":"LINKUSDT","id":"410490","side":"Buy","size":432.3},{"price":"41.059","symbol":"LINKUSDT","id":"410590","side":"Sell","size":295},{"price":"41.048","symbol":"LINKUSDT","id":"410480","side":"Buy","size":447.3}]},"cross_seq":"1970978717","timestamp_e6":"1618677788345174"}
1618677788.56203: {"topic":"orderBookL2_25.BCHUSDT","type":"delta","data":{"delete":[{"price":"1053.25","symbol":"BCHUSDT","id":"10532500","side":"Buy"}],"update":[{"price":"1055.15","symbol":"BCHUSDT","id":"10551500","side":"Sell","size":1.46},{"price":"1055.00","symbol":"BCHUSDT","id":"10550000","side":"Sell","size":0.01},{"price":"1055.05","symbol":"BCHUSDT","id":"10550500","side":"Sell","size":3.55}],"insert":[{"price":"1054.55","symbol":"BCHUSDT","id":"10545500","side":"Buy","size":9.27}]},"cross_seq":"864132284","timestamp_e6":"1618677788348666"}
1618677788.564571: {"topic":"orderBookL2_25.ETHUSDT","type":"delta","data":{"delete":[],"update":[{"price":"2364.90","symbol":"ETHUSDT","id":"23649000","side":"Buy","size":121.479996}],"insert":[]},"cross_seq":"1800546333","timestamp_e6":"1618677788348272"}
1618677788.564646: {"topic":"orderBookL2_25.LTCUSDT","type":"delta","data":{"delete":[],"update":[{"price":"313.09","symbol":"LTCUSDT","id":"3130900","side":"Buy","size":426.6}],"insert":[]},"cross_seq":"1684522590","timestamp_e6":"1618677788358998"}
1618677788.564684: {"topic":"orderBookL2_25.DOTUSDT","type":"delta","data":{"delete":[],"update":[{"price":"43.540","symbol":"DOTUSDT","id":"435400","side":"Sell","size":1403.7999},{"price":"43.545","symbol":"DOTUSDT","id":"435450","side":"Sell","size":299.6}],"insert":[]},"cross_seq":"916953344","timestamp_e6":"1618677788363006"}
1618677788.5647209: {"topic":"orderBookL2_25.ADAUSDT","type":"delta","data":{"delete":[],"update":[{"price":"1.3878","symbol":"ADAUSDT","id":"13878","side":"Sell","size":5953},{"price":"1.3874","symbol":"ADAUSDT","id":"13874","side":"Sell","size":4585}],"insert":[]},"cross_seq":"916953344","timestamp_e6":"1618677788362836"}
1618677788.564754: {"topic":"orderBookL2_25.ETHUSDT","type":"delta","data":{"delete":[{"price":"2364.60","symbol":"ETHUSDT","id":"23646000","side":"Buy"},{"price":"2364.70","symbol":"ETHUSDT","id":"23647000","side":"Buy"},{"price":"2364.50","symbol":"ETHUSDT","id":"23645000","side":"Buy"},{"price":"2364.65","symbol":"ETHUSDT","id":"23646500","side":"Buy"}],"update":[{"price":"2364.95","symbol":"ETHUSDT","id":"23649500","side":"Sell","size":318.69998},{"price":"2365.00","symbol":"ETHUSDT","id":"23650000","side":"Sell","size":65.549995},{"price":"2365.15","symbol":"ETHUSDT","id":"23651500","side":"Sell","size":51.320004},{"price":"2364.55","symbol":"ETHUSDT","id":"23645500","side":"Buy","size":1.46},{"price":"2364.75","symbol":"ETHUSDT","id":"23647500","side":"Buy","size":47.03},{"price":"2364.35","symbol":"ETHUSDT","id":"23643500","side":"Buy","size":109.729996},{"price":"2365.20","symbol":"ETHUSDT","id":"23652000","side":"Sell","size":61.21},{"price":"2365.05","symbol":"ETHUSDT","id":"23650500","side":"Sell","size":89.380005},{"price":"2364.45","symbol":"ETHUSDT","id":"23644500","side":"Buy","size":112.100006},{"price":"2365.10","symbol":"ETHUSDT","id":"23651000","side":"Sell","size":36.899998}],"insert":[{"price":"2363.50","symbol":"ETHUSDT","id":"23635000","side":"Buy","size":58.429996},{"price":"2363.45","symbol":"ETHUSDT","id":"23634500","side":"Buy","size":3.87},{"price":"2363.40","symbol":"ETHUSDT","id":"23634000","side":"Buy","size":13.18},{"price":"2363.55","symbol":"ETHUSDT","id":"23635500","side":"Buy","size":2.51}]},"cross_seq":"1800546357","timestamp_e6":"1618677788367894"}
1618677788.564903: {"topic":"orderBookL2_25.LTCUSDT","type":"delta","data":{"delete":[{"price":"313.20","symbol":"LTCUSDT","id":"3132000","side":"Sell"}],"update":[{"price":"313.17","symbol":"LTCUSDT","id":"3131700","side":"Sell","size":129.6},{"price":"313.19","symbol":"LTCUSDT","id":"3131900","side":"Sell","size":10},{"price":"313.10","symbol":"LTCUSDT","id":"3131000","side":"Sell","size":152.1},{"price":"313.18","symbol":"LTCUSDT","id":"3131800","side":"Sell","size":1.5},{"price":"313.09","symbol":"LTCUSDT","id":"3130900","side":"Buy","size":151.6}],"insert":[{"price":"313.21","symbol":"LTCUSDT","id":"3132100","side":"Sell","size":39.8}]},"cross_seq":"1684522599","timestamp_e6":"1618677788380182"}
1618677788.5649788: {"topic":"orderBookL2_25.DOTUSDT","type":"delta","data":{"delete":[],"update":[{"price":"43.585","symbol":"DOTUSDT","id":"435850","side":"Sell","size":354.40002},{"price":"43.570","symbol":"DOTUSDT","id":"435700","side":"Sell","size":351.2}],"insert":[]},"cross_seq":"916953356","timestamp_e6":"1618677788382464"}
1618677788.5650141: {"topic":"orderBookL2_25.ADAUSDT","type":"delta","data":{"delete":[{"price":"1.3864","symbol":"ADAUSDT","id":"13864","side":"Buy"},{"price":"1.3874","symbol":"ADAUSDT","id":"13874","side":"Sell"},{"price":"1.3875","symbol":"ADAUSDT","id":"13875","side":"Sell"}],"update":[{"price":"1.3863","symbol":"ADAUSDT","id":"13863","side":"Buy","size":2300},{"price":"1.3877","symbol":"ADAUSDT","id":"13877","side":"Sell","size":2937},{"price":"1.3876","symbol":"ADAUSDT","id":"13876","side":"Sell","size":1},{"price":"1.3861","symbol":"ADAUSDT","id":"13861","side":"Buy","size":1437},{"price":"1.3865","symbol":"ADAUSDT","id":"13865","side":"Buy","size":3596},{"price":"1.3860","symbol":"ADAUSDT","id":"13860","side":"Buy","size":318},{"price":"1.3872","symbol":"ADAUSDT","id":"13872","side":"Buy","size":70475},{"price":"1.3871","symbol":"ADAUSDT","id":"13871","side":"Buy","size":4000}],"insert":[{"price":"1.3899","symbol":"ADAUSDT","id":"13899","side":"Sell","size":10776},{"price":"1.3898","symbol":"ADAUSDT","id":"13898","side":"Sell","size":6790},{"price":"1.3844","symbol":"ADAUSDT","id":"13844","side":"Buy","size":181.00002}]},"cross_seq":"916953356","timestamp_e6":"1618677788382349"}
1618677788.5651178: {"topic":"orderBookL2_25.LINKUSDT","type":"delta","data":{"delete":[{"price":"41.044","symbol":"LINKUSDT","id":"410440","side":"Buy"},{"price":"41.055","symbol":"LINKUSDT","id":"410550","side":"Buy"},{"price":"41.061","symbol":"LINKUSDT","id":"410610","side":"Sell"},{"price":"41.064","symbol":"LINKUSDT","id":"410640","side":"Sell"},{"price":"41.051","symbol":"LINKUSDT","id":"410510","side":"Buy"},{"price":"41.059","symbol":"LINKUSDT","id":"410590","side":"Sell"},{"price":"41.058","symbol":"LINKUSDT","id":"410580","side":"Sell"}],"update":[{"price":"41.056","symbol":"LINKUSDT","id":"410560","side":"Sell","size":926.19995},{"price":"41.039","symbol":"LINKUSDT","id":"410390","side":"Buy","size":576.6},{"price":"41.068","symbol":"LINKUSDT","id":"410680","side":"Sell","size":453.1},{"price":"41.041","symbol":"LINKUSDT","id":"410410","side":"Buy","size":334.19998},{"price":"41.043","symbol":"LINKUSDT","id":"410430","side":"Buy","size":447.3},{"price":"41.040","symbol":"LINKUSDT","id":"410400","side":"Buy","size":535.10004},{"price":"41.065","symbol":"LINKUSDT","id":"410650","side":"Sell","size":157.9},{"price":"41.067","symbol":"LINKUSDT","id":"410670","side":"Sell","size":223.70001},{"price":"41.063","symbol":"LINKUSDT","id":"410630","side":"Sell","size":282.1},{"price":"41.066","symbol":"LINKUSDT","id":"410660","side":"Sell","size":688.39996},{"price":"41.042","symbol":"LINKUSDT","id":"410420","side":"Buy","size":417},{"price":"41.069","symbol":"LINKUSDT","id":"410690","side":"Sell","size":169.9}],"insert":[{"price":"41.083","symbol":"LINKUSDT","id":"410830","side":"Sell","size":92},{"price":"41.084","symbol":"LINKUSDT","id":"410840","side":"Sell","size":365.59998},{"price":"41.062","symbol":"LINKUSDT","id":"410620","side":"Sell","size":45.100002},{"price":"41.026","symbol":"LINKUSDT","id":"410260","side":"Buy","size":704},{"price":"41.025","symbol":"LINKUSDT","id":"410250","side":"Buy","size":687.2},{"price":"41.057","symbol":"LINKUSDT","id":"410570","side":"Sell","size":295},{"price":"41.027","symbol":"LINKUSDT","id":"410270","side":"Buy","size":336.8}]},"cross_seq":"1970978771","timestamp_e6":"1618677788385258"}
1618677788.5652978: {"topic":"orderBookL2_25.ETHUSDT","type":"delta","data":{"delete":[],"update":[{"price":"2364.95","symbol":"ETHUSDT","id":"23649500","side":"Sell","size":372.03}],"insert":[]},"cross_seq":"1800546358","timestamp_e6":"1618677788387678"}
1618677788.565326: {"topic":"orderBookL2_25.LTCUSDT","type":"delta","data":{"delete":[],"update":[{"price":"313.10","symbol":"LTCUSDT","id":"3131000","side":"Sell","size":2.1}],"insert":[]},"cross_seq":"1684522600","timestamp_e6":"1618677788399853"}
1618677788.565351: {"topic":"orderBookL2_25.DOTUSDT","type":"delta","data":{"delete":[],"update":[{"price":"43.560","symbol":"DOTUSDT","id":"435600","side":"Sell","size":382.5}],"insert":[]},"cross_seq":"916953367","timestamp_e6":"1618677788403900"}
1618677788.565375: {"topic":"orderBookL2_25.ADAUSDT","type":"delta","data":{"delete":[{"price":"1.3899","symbol":"ADAUSDT","id":"13899","side":"Sell"},{"price":"1.3898","symbol":"ADAUSDT","id":"13898","side":"Sell"}],"update":[{"price":"1.3860","symbol":"ADAUSDT","id":"13860","side":"Buy","size":1693.9999},{"price":"1.3876","symbol":"ADAUSDT","id":"13876","side":"Sell","size":2097},{"price":"1.3862","symbol":"ADAUSDT","id":"13862","side":"Buy","size":2274},{"price":"1.3877","symbol":"ADAUSDT","id":"13877","side":"Sell","size":4741},{"price":"1.3859","symbol":"ADAUSDT","id":"13859","side":"Buy","size":4195}],"insert":[{"price":"1.3875","symbol":"ADAUSDT","id":"13875","side":"Sell","size":2877},{"price":"1.3874","symbol":"ADAUSDT","id":"13874","side":"Sell","size":3130}]},"cross_seq":"916953367","timestamp_e6":"1618677788403430"}
1618677788.565453: {"topic":"orderBookL2_25.LINKUSDT","type":"delta","data":{"delete":[{"price":"41.046","symbol":"LINKUSDT","id":"410460","side":"Buy"},{"price":"41.048","symbol":"LINKUSDT","id":"410480","side":"Buy"},{"price":"41.047","symbol":"LINKUSDT","id":"410470","side":"Buy"},{"price":"41.057","symbol":"LINKUSDT","id":"410570","side":"Sell"},{"price":"41.045","symbol":"LINKUSDT","id":"410450","side":"Buy"},{"price":"41.049","symbol":"LINKUSDT","id":"410490","side":"Buy"}],"update":[{"price":"41.056","symbol":"LINKUSDT","id":"410560","side":"Sell","size":599},{"price":"41.041","symbol":"LINKUSDT","id":"410410","side":"Buy","size":652.2}],"insert":[{"price":"41.054","symbol":"LINKUSDT","id":"410540","side":"Sell","size":580.60004},{"price":"41.021","symbol":"LINKUSDT","id":"410210","side":"Buy","size":86.700005},{"price":"41.024","symbol":"LINKUSDT","id":"410240","side":"Buy","size":423.6},{"price":"41.044","symbol":"LINKUSDT","id":"410440","side":"Buy","size":432.3},{"price":"41.023","symbol":"LINKUSDT","id":"410230","side":"Buy","size":201.9},{"price":"41.022","symbol":"LINKUSDT","id":"410220","side":"Buy","size":260.4}]},"cross_seq":"1970978801","timestamp_e6":"1618677788405224"}
1618677788.56557: {"topic":"orderBookL2_25.LTCUSDT","type":"delta","data":{"delete":[{"price":"313.41","symbol":"LTCUSDT","id":"3134100","side":"Sell"},{"price":"313.42","symbol":"LTCUSDT","id":"3134200","side":"Sell"}],"update":[{"price":"313.17","symbol":"LTCUSDT","id":"3131700","side":"Sell","size":1.5},{"price":"313.18","symbol":"LTCUSDT","id":"3131800","side":"Sell","size":67.299995},{"price":"313.19","symbol":"LTCUSDT","id":"3131900","side":"Sell","size":52.5}],"insert":[{"price":"313.16","symbol":"LTCUSDT","id":"3131600","side":"Sell","size":128.1},{"price":"313.20","symbol":"LTCUSDT","id":"3132000","side":"Sell","size":39.8}]},"cross_seq":"1684522613","timestamp_e6":"1618677788418015"}
1618677788.565621: {"topic":"orderBookL2_25.ADAUSDT","type":"delta","data":{"delete":[{"price":"1.3871","symbol":"ADAUSDT","id":"13871","side":"Buy"}],"update":[{"price":"1.3872","symbol":"ADAUSDT","id":"13872","side":"Buy","size":74475}],"insert":[{"price":"1.3843","symbol":"ADAUSDT","id":"13843","side":"Buy","size":5092}]},"cross_seq":"916953368","timestamp_e6":"1618677788422333"}
1618677788.565654: {"topic":"orderBookL2_25.LINKUSDT","type":"delta","data":{"delete":[{"price":"41.079","symbol":"LINKUSDT","id":"410790","side":"Sell"},{"price":"41.042","symbol":"LINKUSDT","id":"410420","side":"Buy"},{"price":"41.043","symbol":"LINKUSDT","id":"410430","side":"Buy"},{"price":"41.083","symbol":"LINKUSDT","id":"410830","side":"Sell"},{"price":"41.080","symbol":"LINKUSDT","id":"410800","side":"Sell"},{"price":"41.082","symbol":"LINKUSDT","id":"410820","side":"Sell"},{"price":"41.084","symbol":"LINKUSDT","id":"410840","side":"Sell"},{"price":"41.081","symbol":"LINKUSDT","id":"410810","side":"Sell"}],"update":[{"price":"41.067","symbol":"LINKUSDT","id":"410670","side":"Sell","size":15.5},{"price":"41.041","symbol":"LINKUSDT","id":"410410","side":"Buy","size":318},{"price":"41.060","symbol":"LINKUSDT","id":"410600","side":"Sell","size":1.4},{"price":"41.066","symbol":"LINKUSDT","id":"410660","side":"Sell","size":421},{"price":"41.038","symbol":"LINKUSDT","id":"410380","side":"Buy","size":25},{"price":"41.065","symbol":"LINKUSDT","id":"410650","side":"Sell","size":337.80002},{"price":"41.078","symbol":"LINKUSDT","id":"410780","side":"Sell","size":418.9},{"price":"41.056","symbol":"LINKUSDT","id":"410560","side":"Sell","size":58.8},{"price":"41.052","symbol":"LINKUSDT","id":"410520","side":"Buy","size":7.2},{"price":"41.074","symbol":"LINKUSDT","id":"410740","side":"Sell","size":180.90001},{"price":"41.037","symbol":"LINKUSDT","id":"410370","side":"Buy","size":242.59999},{"price":"41.072","symbol":"LINKUSDT","id":"410720","side":"Sell","size":188.3},{"price":"41.036","symbol":"LINKUSDT","id":"410360","side":"Buy","size":427},{"price":"41.071","symbol":"LINKUSDT","id":"410710","side":"Sell","size":314.9},{"price":"41.069","symbol":"LINKUSDT","id":"410690","side":"Sell","size":39.3},{"price":"41.068","symbol":"LINKUSDT","id":"410680","side":"Sell","size":348.8},{"price":"41.077","symbol":"LINKUSDT","id":"410770","side":"Sell","size":534.9},{"price":"41.040","symbol":"LINKUSDT","id":"410400","side":"Buy","size":357},{"price":"41.075","symbol":"LINKUSDT","id":"410750","side":"Sell","size":8.3},{"price":"41.073","symbol":"LINKUSDT","id":"410730","side":"Sell","size":146.59999},{"price":"41.039","symbol":"LINKUSDT","id":"410390","side":"Buy","size":272.1}],"insert":[{"price":"41.064","symbol":"LINKUSDT","id":"410640","side":"Sell","size":43.9},{"price":"41.053","symbol":"LINKUSDT","id":"410530","side":"Sell","size":493.1},{"price":"41.059","symbol":"LINKUSDT","id":"410590","side":"Sell","size":81.6},{"price":"41.046","symbol":"LINKUSDT","id":"410460","side":"Buy","size":432.3},{"price":"41.045","symbol":"LINKUSDT","id":"410450","side":"Buy","size":447.3},{"price":"41.057","symbol":"LINKUSDT","id":"410570","side":"Sell","size":327.9},{"price":"41.061","symbol":"LINKUSDT","id":"410610","side":"Sell","size":92},{"price":"41.058","symbol":"LINKUSDT","id":"410580","side":"Sell","size":109}]},"cross_seq":"1970978883","timestamp_e6":"1618677788425989"}
1618677788.5658329: {"topic":"orderBookL2_25.DOTUSDT","type":"delta","data":{"delete":[],"update":[{"price":"43.560","symbol":"DOTUSDT","id":"435600","side":"Sell","size":554.6},{"price":"43.610","symbol":"DOTUSDT","id":"436100","side":"Sell","size":350.59998}],"insert":[]},"cross_seq":"916953378","timestamp_e6":"1618677788442474"}
1618677788.5658581: {"topic":"orderBookL2_25.LINKUSDT","type":"delta","data":{"delete":[{"price":"41.021","symbol":"LINKUSDT","id":"410210","side":"Buy"},{"price":"41.022","symbol":"LINKUSDT","id":"410220","side":"Buy"}],"update":[{"price":"41.058","symbol":"LINKUSDT","id":"410580","side":"Sell","size":159.3},{"price":"41.060","symbol":"LINKUSDT","id":"410600","side":"Sell","size":94.799995},{"price":"41.056","symbol":"LINKUSDT","id":"410560","side":"Sell","size":40},{"price":"41.059","symbol":"LINKUSDT","id":"410590","side":"Sell","size":144}],"insert":[{"price":"41.043","symbol":"LINKUSDT","id":"410430","side":"Buy","size":318},{"price":"41.042","symbol":"LINKUSDT","id":"410420","side":"Buy","size":261.5}]},"cross_seq":"1970978904","timestamp_e6":"1618677788444533"}
1618677788.5659132: {"topic":"orderBookL2_25.ADAUSDT","type":"delta","data":{"delete":[{"price":"1.3844","symbol":"ADAUSDT","id":"13844","side":"Buy"},{"price":"1.3843","symbol":"ADAUSDT","id":"13843","side":"Buy"}],"update":[{"price":"1.3861","symbol":"ADAUSDT","id":"13861","side":"Buy","size":487.99997},{"price":"1.3865","symbol":"ADAUSDT","id":"13865","side":"Buy","size":1},{"price":"1.3863","symbol":"ADAUSDT","id":"13863","side":"Buy","size":3994},{"price":"1.3873","symbol":"ADAUSDT","id":"13873","side":"Sell","size":4849},{"price":"1.3862","symbol":"ADAUSDT","id":"13862","side":"Buy","size":1578}],"insert":[{"price":"1.3864","symbol":"ADAUSDT","id":"13864","side":"Buy","size":1749},{"price":"1.3866","symbol":"ADAUSDT","id":"13866","side":"Buy","size":3595}]},"cross_seq":"916953378","timestamp_e6":"1618677788442350"}
1618677788.56597: {"topic":"orderBookL2_25.DOTUSDT","type":"delta","data":{"delete":[],"update":[{"price":"43.535","symbol":"DOTUSDT","id":"435350","side":"Buy","size":105.99999}],"insert":[]},"cross_seq":"916953392","timestamp_e6":"1618677788462392"}
1618677788.56599: {"topic":"orderBookL2_25.LINKUSDT","type":"delta","data":{"delete":[{"price":"41.056","symbol":"LINKUSDT","id":"410560","side":"Sell"}],"update":[{"price":"41.053","symbol":"LINKUSDT","id":"410530","side":"Sell","size":66}],"insert":[{"price":"41.079","symbol":"LINKUSDT","id":"410790","side":"Sell","size":349.1}]},"cross_seq":"1970978906","timestamp_e6":"1618677788464488"}
1618677788.56602: {"topic":"orderBookL2_25.LTCUSDT","type":"delta","data":{"delete":[{"price":"313.40","symbol":"LTCUSDT","id":"3134000","side":"Sell"},{"price":"313.16","symbol":"LTCUSDT","id":"3131600","side":"Sell"}],"update":[{"price":"313.18","symbol":"LTCUSDT","id":"3131800","side":"Sell","size":1.5},{"price":"313.17","symbol":"LTCUSDT","id":"3131700","side":"Sell","size":44}],"insert":[{"price":"313.15","symbol":"LTCUSDT","id":"3131500","side":"Sell","size":91.3},{"price":"313.14","symbol":"LTCUSDT","id":"3131400","side":"Sell","size":128.1}]},"cross_seq":"1684522627","timestamp_e6":"1618677788477905"}
1618677788.5675719: {"topic":"orderBookL2_25.DOTUSDT","type":"delta","data":{"delete":[{"price":"43.505","symbol":"DOTUSDT","id":"435050","side":"Buy"}],"update":[{"price":"43.475","symbol":"DOTUSDT","id":"434750","side":"Buy","size":724.00006},{"price":"43.485","symbol":"DOTUSDT","id":"434850","side":"Buy","size":296.5},{"price":"43.470","symbol":"DOTUSDT","id":"434700","side":"Buy","size":491.9},{"price":"43.480","symbol":"DOTUSDT","id":"434800","side":"Buy","size":539.6},{"price":"43.455","symbol":"DOTUSDT","id":"434550","side":"Buy","size":428.2},{"price":"43.515","symbol":"DOTUSDT","id":"435150","side":"Buy","size":0.9},{"price":"43.465","symbol":"DOTUSDT","id":"434650","side":"Buy","size":403.5},{"price":"43.580","symbol":"DOTUSDT","id":"435800","side":"Sell","size":77.299995},{"price":"43.570","symbol":"DOTUSDT","id":"435700","side":"Sell","size":77.6},{"price":"43.490","symbol":"DOTUSDT","id":"434900","side":"Buy","size":365.59998},{"price":"43.555","symbol":"DOTUSDT","id":"435550","side":"Sell","size":552.4},{"price":"43.565","symbol":"DOTUSDT","id":"435650","side":"Sell","size":62.4},{"price":"43.560","symbol":"DOTUSDT","id":"435600","side":"Sell","size":828.19995}],"insert":[{"price":"43.395","symbol":"DOTUSDT","id":"433950","side":"Buy","size":308.9}]},"cross_seq":"916953412","timestamp_e6":"1618677788482412"}
1618677788.5721622: {"topic":"orderBookL2_25.LINKUSDT","type":"delta","data":{"delete":[{"price":"41.057","symbol":"LINKUSDT","id":"410570","side":"Sell"},{"price":"41.044","symbol":"LINKUSDT","id":"410440","side":"Buy"},{"price":"41.043","symbol":"LINKUSDT","id":"410430","side":"Buy"},{"price":"41.054","symbol":"LINKUSDT","id":"410540","side":"Sell"}],"update":[{"price":"41.052","symbol":"LINKUSDT","id":"410520","side":"Buy","size":47.2},{"price":"41.059","symbol":"LINKUSDT","id":"410590","side":"Sell","size":62.4}],"insert":[{"price":"41.055","symbol":"LINKUSDT","id":"410550","side":"Sell","size":346.00003},{"price":"41.022","symbol":"LINKUSDT","id":"410220","side":"Buy","size":260.4},{"price":"41.047","symbol":"LINKUSDT","id":"410470","side":"Buy","size":432.3},{"price":"41.056","symbol":"LINKUSDT","id":"410560","side":"Sell","size":295}]},"cross_seq":"1970978918","timestamp_e6":"1618677788487123"}
1618677788.581662: {"topic":"orderBookL2_25.XTZUSDT","type":"delta","data":{"delete":[],"update":[{"price":"7.212","symbol":"XTZUSDT","id":"72120","side":"Sell","size":0.9}],"insert":[]},"cross_seq":"726228251","timestamp_e6":"1618677788496680"}
1618677788.5870972: {"topic":"orderBookL2_25.DOTUSDT","type":"delta","data":{"delete":[{"price":"43.395","symbol":"DOTUSDT","id":"433950","side":"Buy"}],"update":[{"price":"43.535","symbol":"DOTUSDT","id":"435350","side":"Buy","size":96}],"insert":[{"price":"43.520","symbol":"DOTUSDT","id":"435200","side":"Buy","size":10}]},"cross_seq":"916953430","timestamp_e6":"1618677788502452"}
1618677788.5871649: {"topic":"orderBookL2_25.ADAUSDT","type":"delta","data":{"delete":[{"price":"1.3866","symbol":"ADAUSDT","id":"13866","side":"Buy"}],"update":[{"price":"1.3865","symbol":"ADAUSDT","id":"13865","side":"Buy","size":1750},{"price":"1.3867","symbol":"ADAUSDT","id":"13867","side":"Buy","size":5594.9995},{"price":"1.3864","symbol":"ADAUSDT","id":"13864","side":"Buy","size":6609},{"price":"1.3862","symbol":"ADAUSDT","id":"13862","side":"Buy","size":465}],"insert":[{"price":"1.3844","symbol":"ADAUSDT","id":"13844","side":"Buy","size":181.00002}]},"cross_seq":"916953430","timestamp_e6":"1618677788502338"}
1618677788.587938: {"topic":"orderBookL2_25.LINKUSDT","type":"delta","data":{"delete":[],"update":[{"price":"41.031","symbol":"LINKUSDT","id":"410310","side":"Buy","size":22.8}],"insert":[]},"cross_seq":"1970978919","timestamp_e6":"1618677788503727"}
1618677788.601557: {"topic":"orderBookL2_25.XTZUSDT","type":"delta","data":{"delete":[],"update":[{"price":"7.215","symbol":"XTZUSDT","id":"72150","side":"Sell","size":1749.2001},{"price":"7.214","symbol":"XTZUSDT","id":"72140","side":"Sell","size":2458.2998}],"insert":[]},"cross_seq":"726228253","timestamp_e6":"1618677788514996"}
1618677788.741876: {"topic":"orderBookL2_25.UNIUSDT","type":"delta","data":{"delete":[],"update":[{"price":"35.364","symbol":"UNIUSDT","id":"353640","side":"Buy","size":610.7},{"price":"35.369","symbol":"UNIUSDT","id":"353690","side":"Buy","size":429.7},{"price":"35.409","symbol":"UNIUSDT","id":"354090","side":"Sell","size":141.40001},{"price":"35.413","symbol":"UNIUSDT","id":"354130","side":"Sell","size":55.000004},{"price":"35.410","symbol":"UNIUSDT","id":"354100","side":"Sell","size":125.299995}],"insert":[]},"cross_seq":"916953450","timestamp_e6":"1618677788522487"}
1618677788.741986: {"topic":"orderBookL2_25.LTCUSDT","type":"delta","data":{"delete":[],"update":[{"price":"313.25","symbol":"LTCUSDT","id":"3132500","side":"Sell","size":65.799995},{"price":"313.31","symbol":"LTCUSDT","id":"3133100","side":"Sell","size":48.899998},{"price":"313.26","symbol":"LTCUSDT","id":"3132600","side":"Sell","size":152.7}],"insert":[]},"cross_seq":"1684522632","timestamp_e6":"1618677788522083"}
1618677788.742039: {"topic":"orderBookL2_25.LINKUSDT","type":"delta","data":{"delete":[{"price":"41.056","symbol":"LINKUSDT","id":"410560","side":"Sell"},{"price":"41.023","symbol":"LINKUSDT","id":"410230","side":"Buy"},{"price":"41.022","symbol":"LINKUSDT","id":"410220","side":"Buy"},{"price":"41.079","symbol":"LINKUSDT","id":"410790","side":"Sell"}],"update":[{"price":"41.058","symbol":"LINKUSDT","id":"410580","side":"Sell","size":50.300003},{"price":"41.059","symbol":"LINKUSDT","id":"410590","side":"Sell","size":81.7}],"insert":[{"price":"41.057","symbol":"LINKUSDT","id":"410570","side":"Sell","size":144},{"price":"41.043","symbol":"LINKUSDT","id":"410430","side":"Buy","size":261.5},{"price":"41.044","symbol":"LINKUSDT","id":"410440","side":"Buy","size":318},{"price":"41.054","symbol":"LINKUSDT","id":"410540","side":"Sell","size":346.00003}]},"cross_seq":"1970978927","timestamp_e6":"1618677788523917"}
1618677788.7421582: {"topic":"orderBookL2_25.ADAUSDT","type":"delta","data":{"delete":[],"update":[{"price":"1.3892","symbol":"ADAUSDT","id":"13892","side":"Sell","size":4603}],"insert":[]},"cross_seq":"916953450","timestamp_e6":"1618677788522323"}
1618677788.7422001: {"topic":"orderBookL2_25.ETHUSDT","type":"delta","data":{"delete":[],"update":[{"price":"2365.20","symbol":"ETHUSDT","id":"23652000","side":"Sell","size":60.359997}],"insert":[]},"cross_seq":"1800546361","timestamp_e6":"1618677788547511"}
1618677788.742229: {"topic":"orderBookL2_25.BCHUSDT","type":"delta","data":{"delete":[],"update":[{"price":"1055.55","symbol":"BCHUSDT","id":"10555500","side":"Sell","size":4.53},{"price":"1055.40","symbol":"BCHUSDT","id":"10554000","side":"Sell","size":13.209999},{"price":"1055.15","symbol":"BCHUSDT","id":"10551500","side":"Sell","size":6.14},{"price":"1055.00","symbol":"BCHUSDT","id":"10550000","side":"Sell","size":12.630001},{"price":"1055.60","symbol":"BCHUSDT","id":"10556000","side":"Sell","size":1},{"price":"1055.35","symbol":"BCHUSDT","id":"10553500","side":"Sell","size":16.56},{"price":"1055.50","symbol":"BCHUSDT","id":"10555000","side":"Sell","size":11.110001},{"price":"1055.05","symbol":"BCHUSDT","id":"10550500","side":"Sell","size":9.04},{"price":"1055.45","symbol":"BCHUSDT","id":"10554500","side":"Sell","size":19.11}],"insert":[]},"cross_seq":"864132298","timestamp_e6":"1618677788548712"}
1618677788.742295: {"topic":"orderBookL2_25.LINKUSDT","type":"delta","data":{"delete":[],"update":[{"price":"41.053","symbol":"LINKUSDT","id":"410530","side":"Sell","size":466}],"insert":[]},"cross_seq":"1970978941","timestamp_e6":"1618677788564005"}
1618677788.742321: {"topic":"orderBookL2_25.ETHUSDT","type":"delta","data":{"delete":[],"update":[{"price":"2363.55","symbol":"ETHUSDT","id":"23635500","side":"Buy","size":5.49}],"insert":[]},"cross_seq":"1800546362","timestamp_e6":"1618677788567061"}
1618677788.74235: {"topic":"orderBookL2_25.XTZUSDT","type":"delta","data":{"delete":[],"update":[{"price":"7.212","symbol":"XTZUSDT","id":"72120","side":"Sell","size":1.1},{"price":"7.205","symbol":"XTZUSDT","id":"72050","side":"Buy","size":3161.2}],"insert":[]},"cross_seq":"726228255","timestamp_e6":"1618677788576386"}
1618677788.7423801: {"topic":"orderBookL2_25.LTCUSDT","type":"delta","data":{"delete":[{"price":"313.39","symbol":"LTCUSDT","id":"3133900","side":"Sell"}],"update":[{"price":"313.17","symbol":"LTCUSDT","id":"3131700","side":"Sell","size":92.8},{"price":"313.18","symbol":"LTCUSDT","id":"3131800","side":"Sell","size":67.299995}],"insert":[{"price":"313.16","symbol":"LTCUSDT","id":"3131600","side":"Sell","size":128.1}]},"cross_seq":"1684522635","timestamp_e6":"1618677788598855"}
1618677788.742429: {"topic":"orderBookL2_25.LINKUSDT","type":"delta","data":{"delete":[{"price":"41.057","symbol":"LINKUSDT","id":"410570","side":"Sell"},{"price":"41.046","symbol":"LINKUSDT","id":"410460","side":"Buy"},{"price":"41.045","symbol":"LINKUSDT","id":"410450","side":"Buy"},{"price":"41.055","symbol":"LINKUSDT","id":"410550","side":"Sell"}],"update":[{"price":"41.053","symbol":"LINKUSDT","id":"410530","side":"Sell","size":811.99994},{"price":"41.058","symbol":"LINKUSDT","id":"410580","side":"Sell","size":81.7}],"insert":[{"price":"41.056","symbol":"LINKUSDT","id":"410560","side":"Sell","size":144},{"price":"41.049","symbol":"LINKUSDT","id":"410490","side":"Buy","size":432.3},{"price":"41.048","symbol":"LINKUSDT","id":"410480","side":"Buy","size":447.3},{"price":"41.079","symbol":"LINKUSDT","id":"410790","side":"Sell","size":349.1}]},"cross_seq":"1970978966","timestamp_e6":"1618677788605706"}
1618677788.742534: {"topic":"orderBookL2_25.ADAUSDT","type":"delta","data":{"delete":[{"price":"1.3844","symbol":"ADAUSDT","id":"13844","side":"Buy"}],"update":[{"price":"1.3882","symbol":"ADAUSDT","id":"13882","side":"Sell","size":2171},{"price":"1.3879","symbol":"ADAUSDT","id":"13879","side":"Sell","size":3420},{"price":"1.3881","symbol":"ADAUSDT","id":"13881","side":"Sell","size":4080},{"price":"1.3878","symbol":"ADAUSDT","id":"13878","side":"Sell","size":5340},{"price":"1.3880","symbol":"ADAUSDT","id":"13880","side":"Sell","size":4814},{"price":"1.3862","symbol":"ADAUSDT","id":"13862","side":"Buy","size":726}],"insert":[{"price":"1.3866","symbol":"ADAUSDT","id":"13866","side":"Buy","size":2274}]},"cross_seq":"916953465","timestamp_e6":"1618677788622366"}
1618677788.742589: {"topic":"orderBookL2_25.LINKUSDT","type":"delta","data":{"delete":[{"price":"41.025","symbol":"LINKUSDT","id":"410250","side":"Buy"},{"price":"41.079","symbol":"LINKUSDT","id":"410790","side":"Sell"},{"price":"41.024","symbol":"LINKUSDT","id":"410240","side":"Buy"},{"price":"41.054","symbol":"LINKUSDT","id":"410540","side":"Sell"}],"update":[{"price":"41.052","symbol":"LINKUSDT","id":"410520","side":"Buy","size":46},{"price":"41.060","symbol":"LINKUSDT","id":"410600","side":"Sell","size":93.4}],"insert":[{"price":"41.055","symbol":"LINKUSDT","id":"410550","side":"Sell","size":295},{"price":"41.057","symbol":"LINKUSDT","id":"410570","side":"Sell","size":144},{"price":"41.046","symbol":"LINKUSDT","id":"410460","side":"Buy","size":318},{"price":"41.045","symbol":"LINKUSDT","id":"410450","side":"Buy","size":261.5}]},"cross_seq":"1970978973","timestamp_e6":"1618677788624884"}
1618677788.742663: {"topic":"orderBookL2_25.ETHUSDT","type":"delta","data":{"delete":[],"update":[{"price":"2365.10","symbol":"ETHUSDT","id":"23651000","side":"Sell","size":53.99},{"price":"2365.15","symbol":"ETHUSDT","id":"23651500","side":"Sell","size":59.719997},{"price":"2365.00","symbol":"ETHUSDT","id":"23650000","side":"Sell","size":117.34}],"insert":[]},"cross_seq":"1800546366","timestamp_e6":"1618677788627425"}
1618677788.7426932: {"topic":"orderBookL2_25.ADAUSDT","type":"delta","data":{"delete":[{"price":"1.3866","symbol":"ADAUSDT","id":"13866","side":"Buy"}],"update":[{"price":"1.3868","symbol":"ADAUSDT","id":"13868","side":"Buy","size":10186},{"price":"1.3865","symbol":"ADAUSDT","id":"13865","side":"Buy","size":1},{"price":"1.3867","symbol":"ADAUSDT","id":"13867","side":"Buy","size":2000},{"price":"1.3878","symbol":"ADAUSDT","id":"13878","side":"Sell","size":2837},{"price":"1.3864","symbol":"ADAUSDT","id":"13864","side":"Buy","size":4860}],"insert":[{"price":"1.3869","symbol":"ADAUSDT","id":"13869","side":"Buy","size":3595}]},"cross_seq":"916953487","timestamp_e6":"1618677788642401"}
1618677788.74274: {"topic":"orderBookL2_25.LINKUSDT","type":"delta","data":{"delete":[],"update":[{"price":"41.053","symbol":"LINKUSDT","id":"410530","side":"Sell","size":412}],"insert":[]},"cross_seq":"1970978974","timestamp_e6":"1618677788644136"}
1618677788.743217: {"topic":"orderBookL2_25.LTCUSDT","type":"delta","data":{"delete":[],"update":[{"price":"312.80","symbol":"LTCUSDT","id":"3128000","side":"Buy","size":104.399994},{"price":"313.38","symbol":"LTCUSDT","id":"3133800","side":"Sell","size":154.4}],"insert":[]},"cross_seq":"1684522645","timestamp_e6":"1618677788657915"}
1618677788.748941: {"topic":"orderBookL2_25.ADAUSDT","type":"delta","data":{"delete":[],"update":[{"price":"1.3872","symbol":"ADAUSDT","id":"13872","side":"Buy","size":74476}],"insert":[]},"cross_seq":"916953489","timestamp_e6":"1618677788662334"}
1618677788.748986: {"topic":"orderBookL2_25.LINKUSDT","type":"delta","data":{"delete":[{"price":"41.058","symbol":"LINKUSDT","id":"410580","side":"Sell"}],"update":[{"price":"41.066","symbol":"LINKUSDT","id":"410660","side":"Sell","size":546.3},{"price":"41.038","symbol":"LINKUSDT","id":"410380","side":"Buy","size":105.4},{"price":"41.060","symbol":"LINKUSDT","id":"410600","side":"Sell","size":159.3},{"price":"41.067","symbol":"LINKUSDT","id":"410670","side":"Sell","size":147.2},{"price":"41.068","symbol":"LINKUSDT","id":"410680","side":"Sell","size":419.7},{"price":"41.037","symbol":"LINKUSDT","id":"410370","side":"Buy","size":282.2},{"price":"41.053","symbol":"LINKUSDT","id":"410530","side":"Sell","size":66},{"price":"41.062","symbol":"LINKUSDT","id":"410620","side":"Sell","size":93.4},{"price":"41.036","symbol":"LINKUSDT","id":"410360","side":"Buy","size":487.4},{"price":"41.059","symbol":"LINKUSDT","id":"410590","side":"Sell","size":295},{"price":"41.039","symbol":"LINKUSDT","id":"410390","side":"Buy","size":357.5},{"price":"41.061","symbol":"LINKUSDT","id":"410610","side":"Sell","size":144},{"price":"41.041","symbol":"LINKUSDT","id":"410410","side":"Buy","size":490.19998},{"price":"41.069","symbol":"LINKUSDT","id":"410690","side":"Sell","size":131.59999}],"insert":[{"price":"41.079","symbol":"LINKUSDT","id":"410790","side":"Sell","size":349.1}]},"cross_seq":"1970978995","timestamp_e6":"1618677788664093"}
1618677788.759557: {"topic":"orderBookL2_25.XTZUSDT","type":"delta","data":{"delete":[],"update":[{"price":"7.197","symbol":"XTZUSDT","id":"71970","side":"Buy","size":205.8}],"insert":[]},"cross_seq":"726228256","timestamp_e6":"1618677788675072"}
1618677788.763076: {"topic":"orderBookL2_25.LTCUSDT","type":"delta","data":{"delete":[{"price":"313.14","symbol":"LTCUSDT","id":"3131400","side":"Sell"},{"price":"313.16","symbol":"LTCUSDT","id":"3131600","side":"Sell"}],"update":[{"price":"313.10","symbol":"LTCUSDT","id":"3131000","side":"Sell","size":152.1},{"price":"313.17","symbol":"LTCUSDT","id":"3131700","side":"Sell","size":50.300003},{"price":"313.15","symbol":"LTCUSDT","id":"3131500","side":"Sell","size":128.1},{"price":"313.18","symbol":"LTCUSDT","id":"3131800","side":"Sell","size":1.5}],"insert":[{"price":"313.40","symbol":"LTCUSDT","id":"3134000","side":"Sell","size":104.100006},{"price":"313.39","symbol":"LTCUSDT","id":"3133900","side":"Sell","size":229.40001}]},"cross_seq":"1684522651","timestamp_e6":"1618677788680083"}
1618677788.766561: {"topic":"orderBookL2_25.ADAUSDT","type":"delta","data":{"delete":[{"price":"1.3845","symbol":"ADAUSDT","id":"13845","side":"Buy"}],"update":[{"price":"1.3881","symbol":"ADAUSDT","id":"13881","side":"Sell","size":1685},{"price":"1.3867","symbol":"ADAUSDT","id":"13867","side":"Buy","size":4274},{"price":"1.3877","symbol":"ADAUSDT","id":"13877","side":"Sell","size":5343},{"price":"1.3879","symbol":"ADAUSDT","id":"13879","side":"Sell","size":5050},{"price":"1.3868","symbol":"ADAUSDT","id":"13868","side":"Buy","size":7912},{"price":"1.3864","symbol":"ADAUSDT","id":"13864","side":"Buy","size":6296.9995},{"price":"1.3878","symbol":"ADAUSDT","id":"13878","side":"Sell","size":5966.9995},{"price":"1.3865","symbol":"ADAUSDT","id":"13865","side":"Buy","size":1695},{"price":"1.3880","symbol":"ADAUSDT","id":"13880","side":"Sell","size":2676}],"insert":[{"price":"1.3866","symbol":"ADAUSDT","id":"13866","side":"Buy","size":1749}]},"cross_seq":"916953515","timestamp_e6":"1618677788682437"}
1618677788.7834282: {"topic":"orderBookL2_25.LTCUSDT","type":"delta","data":{"delete":[],"update":[{"price":"313.20","symbol":"LTCUSDT","id":"3132000","side":"Sell","size":65.799995},{"price":"313.18","symbol":"LTCUSDT","id":"3131800","side":"Sell","size":129.6},{"price":"313.19","symbol":"LTCUSDT","id":"3131900","side":"Sell","size":101.299995}],"insert":[]},"cross_seq":"1684522660","timestamp_e6":"1618677788697854"}
1618677788.919091: {"topic":"orderBookL2_25.DOTUSDT","type":"delta","data":{"delete":[],"update":[{"price":"43.550","symbol":"DOTUSDT","id":"435500","side":"Sell","size":608.4},{"price":"43.570","symbol":"DOTUSDT","id":"435700","side":"Sell","size":198.3},{"price":"43.575","symbol":"DOTUSDT","id":"435750","side":"Sell","size":104.100006},{"price":"43.470","symbol":"DOTUSDT","id":"434700","side":"Buy","size":674.60004},{"price":"43.475","symbol":"DOTUSDT","id":"434750","side":"Buy","size":831.6},{"price":"43.480","symbol":"DOTUSDT","id":"434800","side":"Buy","size":662.9},{"price":"43.565","symbol":"DOTUSDT","id":"435650","side":"Sell","size":272.4},{"price":"43.460","symbol":"DOTUSDT","id":"434600","side":"Buy","size":553}],"insert":[]},"cross_seq":"916953524","timestamp_e6":"1618677788702347"}
1618677788.919281: {"topic":"orderBookL2_25.LINKUSDT","type":"delta","data":{"delete":[{"price":"41.046","symbol":"LINKUSDT","id":"410460","side":"Buy"},{"price":"41.047","symbol":"LINKUSDT","id":"410470","side":"Buy"},{"price":"41.055","symbol":"LINKUSDT","id":"410550","side":"Sell"},{"price":"41.056","symbol":"LINKUSDT","id":"410560","side":"Sell"},{"price":"41.059","symbol":"LINKUSDT","id":"410590","side":"Sell"}],"update":[{"price":"41.061","symbol":"LINKUSDT","id":"410610","side":"Sell","size":52},{"price":"41.057","symbol":"LINKUSDT","id":"410570","side":"Sell","size":347}],"insert":[{"price":"41.058","symbol":"LINKUSDT","id":"410580","side":"Sell","size":295},{"price":"41.050","symbol":"LINKUSDT","id":"410500","side":"Buy","size":432.3},{"price":"41.080","symbol":"LINKUSDT","id":"410800","side":"Sell","size":39},{"price":"41.025","symbol":"LINKUSDT","id":"410250","side":"Buy","size":687.2},{"price":"41.081","symbol":"LINKUSDT","id":"410810","side":"Sell","size":187.8}]},"cross_seq":"1970979016","timestamp_e6":"1618677788704256"}
1618677788.91947: {"topic":"orderBookL2_25.XTZUSDT","type":"delta","data":{"delete":[],"update":[{"price":"7.211","symbol":"XTZUSDT","id":"72110","side":"Buy","size":6047.5}],"insert":[]},"cross_seq":"726228257","timestamp_e6":"1618677788715203"}
1618677788.920725: {"topic":"orderBookL2_25.DOTUSDT","type":"delta","data":{"delete":[{"price":"43.400","symbol":"DOTUSDT","id":"434000","side":"Buy"}],"update":[],"insert":[{"price":"43.505","symbol":"DOTUSDT","id":"435050","side":"Buy","size":477.7}]},"cross_seq":"916953536","timestamp_e6":"1618677788726399"}
1618677788.9208121: {"topic":"orderBookL2_25.ADAUSDT","type":"delta","data":{"delete":[{"price":"1.3875","symbol":"ADAUSDT","id":"13875","side":"Sell"},{"price":"1.3874","symbol":"ADAUSDT","id":"13874","side":"Sell"},{"price":"1.3873","symbol":"ADAUSDT","id":"13873","side":"Sell"}],"update":[{"price":"1.3864","symbol":"ADAUSDT","id":"13864","side":"Buy","size":4860},{"price":"1.3881","symbol":"ADAUSDT","id":"13881","side":"Sell","size":3489},{"price":"1.3867","symbol":"ADAUSDT","id":"13867","side":"Buy","size":2000},{"price":"1.3880","symbol":"ADAUSDT","id":"13880","side":"Sell","size":3781},{"price":"1.3877","symbol":"ADAUSDT","id":"13877","side":"Sell","size":7147.0005},{"price":"1.3868","symbol":"ADAUSDT","id":"13868","side":"Buy","size":10186},{"price":"1.3882","symbol":"ADAUSDT","id":"13882","side":"Sell","size":3047},{"price":"1.3876","symbol":"ADAUSDT","id":"13876","side":"Sell","size":1}],"insert":[{"price":"1.3900","symbol":"ADAUSDT","id":"13900","side":"Sell","size":7667.0005},{"price":"1.3898","symbol":"ADAUSDT","id":"13898","side":"Sell","size":6790},{"price":"1.3899","symbol":"ADAUSDT","id":"13899","side":"Sell","size":10776}]},"cross_seq":"916953536","timestamp_e6":"1618677788726238"}
1618677788.920941: {"topic":"orderBookL2_25.XTZUSDT","type":"delta","data":{"delete":[],"update":[{"price":"7.197","symbol":"XTZUSDT","id":"71970","side":"Buy","size":204.8}],"insert":[]},"cross_seq":"726228258","timestamp_e6":"1618677788755715"}
1618677788.920976: {"topic":"orderBookL2_25.LTCUSDT","type":"delta","data":{"delete":[],"update":[{"price":"313.30","symbol":"LTCUSDT","id":"3133000","side":"Sell","size":16.4},{"price":"313.31","symbol":"LTCUSDT","id":"3133100","side":"Sell","size":61.2}],"insert":[]},"cross_seq":"1684522667","timestamp_e6":"1618677788757859"}
1618677788.92101: {"topic":"orderBookL2_25.ADAUSDT","type":"delta","data":{"delete":[{"price":"1.3846","symbol":"ADAUSDT","id":"13846","side":"Buy"},{"price":"1.3847","symbol":"ADAUSDT","id":"13847","side":"Buy"}],"update":[{"price":"1.3876","symbol":"ADAUSDT","id":"13876","side":"Sell","size":31},{"price":"1.3872","symbol":"ADAUSDT","id":"13872","side":"Buy","size":26166}],"insert":[{"price":"1.3875","symbol":"ADAUSDT","id":"13875","side":"Buy","size":22185},{"price":"1.3874","symbol":"ADAUSDT","id":"13874","side":"Buy","size":11999.999}]},"cross_seq":"916953547","timestamp_e6":"1618677788762816"}
1618677788.921077: {"topic":"orderBookL2_25.LINKUSDT","type":"delta","data":{"delete":[{"price":"41.058","symbol":"LINKUSDT","id":"410580","side":"Sell"},{"price":"41.081","symbol":"LINKUSDT","id":"410810","side":"Sell"},{"price":"41.025","symbol":"LINKUSDT","id":"410250","side":"Buy"}],"update":[{"price":"41.044","symbol":"LINKUSDT","id":"410440","side":"Buy","size":417},{"price":"41.045","symbol":"LINKUSDT","id":"410450","side":"Buy","size":447.3},{"price":"41.060","symbol":"LINKUSDT","id":"410600","side":"Sell","size":65.9},{"price":"41.061","symbol":"LINKUSDT","id":"410610","side":"Sell","size":81.7}],"insert":[{"price":"41.056","symbol":"LINKUSDT","id":"410560","side":"Sell","size":346.00003},{"price":"41.046","symbol":"LINKUSDT","id":"410460","side":"Buy","size":432.3},{"price":"41.059","symbol":"LINKUSDT","id":"410590","side":"Sell","size":144}]},"cross_seq":"1970979031","timestamp_e6":"1618677788764398"}
1618677788.9211679: {"topic":"orderBookL2_25.XTZUSDT","type":"delta","data":{"delete":[],"update":[{"price":"7.211","symbol":"XTZUSDT","id":"72110","side":"Buy","size":6600.5996},{"price":"7.210","symbol":"XTZUSDT","id":"72100","side":"Buy","size":1797.6001},{"price":"7.216","symbol":"XTZUSDT","id":"72160","side":"Sell","size":2251.7998},{"price":"7.208","symbol":"XTZUSDT","id":"72080","side":"Buy","size":1830.0001},{"price":"7.214","symbol":"XTZUSDT","id":"72140","side":"Sell","size":3842.4},{"price":"7.206","symbol":"XTZUSDT","id":"72060","side":"Buy","size":2592.9001},{"price":"7.209","symbol":"XTZUSDT","id":"72090","side":"Buy","size":1709.7001},{"price":"7.207","symbol":"XTZUSDT","id":"72070","side":"Buy","size":1416.8},{"price":"7.213","symbol":"XTZUSDT","id":"72130","side":"Sell","size":0.4},{"price":"7.219","symbol":"XTZUSDT","id":"72190","side":"Sell","size":371.4},{"price":"7.217","symbol":"XTZUSDT","id":"72170","side":"Sell","size":1523.8999}],"insert":[]},"cross_seq":"726228271","timestamp_e6":"1618677788775944"}
1618677788.9212549: {"topic":"orderBookL2_25.UNIUSDT","type":"delta","data":{"delete":[],"update":[{"price":"35.364","symbol":"UNIUSDT","id":"353640","side":"Buy","size":616.8}],"insert":[]},"cross_seq":"916953563","timestamp_e6":"1618677788782437"}
1618677788.921283: {"topic":"orderBookL2_25.ADAUSDT","type":"delta","data":{"delete":[],"update":[{"price":"1.3875","symbol":"ADAUSDT","id":"13875","side":"Buy","size":49685}],"insert":[]},"cross_seq":"916953563","timestamp_e6":"1618677788782325"}
1618677788.9213068: {"topic":"orderBookL2_25.LINKUSDT","type":"delta","data":{"delete":[{"price":"41.049","symbol":"LINKUSDT","id":"410490","side":"Buy"},{"price":"41.050","symbol":"LINKUSDT","id":"410500","side":"Buy"},{"price":"41.057","symbol":"LINKUSDT","id":"410570","side":"Sell"},{"price":"41.048","symbol":"LINKUSDT","id":"410480","side":"Buy"}],"update":[{"price":"41.044","symbol":"LINKUSDT","id":"410440","side":"Buy","size":99},{"price":"41.060","symbol":"LINKUSDT","id":"410600","side":"Sell","size":144}],"insert":[{"price":"41.024","symbol":"LINKUSDT","id":"410240","side":"Buy","size":423.6},{"price":"41.058","symbol":"LINKUSDT","id":"410580","side":"Sell","size":295},{"price":"41.047","symbol":"LINKUSDT","id":"410470","side":"Buy","size":432.3},{"price":"41.025","symbol":"LINKUSDT","id":"410250","side":"Buy","size":687.2}]},"cross_seq":"1970979045","timestamp_e6":"1618677788784034"}
1618677788.9214: {"topic":"orderBookL2_25.ADAUSDT","type":"delta","data":{"delete":[{"price":"1.3874","symbol":"ADAUSDT","id":"13874","side":"Buy"}],"update":[{"price":"1.3875","symbol":"ADAUSDT","id":"13875","side":"Buy","size":63850},{"price":"1.3867","symbol":"ADAUSDT","id":"13867","side":"Buy","size":3749},{"price":"1.3864","symbol":"ADAUSDT","id":"13864","side":"Buy","size":5586.0005},{"price":"1.3879","symbol":"ADAUSDT","id":"13879","side":"Sell","size":3803},{"price":"1.3872","symbol":"ADAUSDT","id":"13872","side":"Buy","size":1},{"price":"1.3876","symbol":"ADAUSDT","id":"13876","side":"Sell","size":4241},{"price":"1.3877","symbol":"ADAUSDT","id":"13877","side":"Sell","size":4741}],"insert":[{"price":"1.3847","symbol":"ADAUSDT","id":"13847","side":"Buy","size":4462}]},"cross_seq":"916953571","timestamp_e6":"1618677788802347"}
1618677788.9214761: {"topic":"orderBookL2_25.BCHUSDT","type":"delta","data":{"delete":[{"price":"1055.25","symbol":"BCHUSDT","id":"10552500","side":"Sell"},{"price":"1054.90","symbol":"BCHUSDT","id":"10549000","side":"Sell"},{"price":"1054.95","symbol":"BCHUSDT","id":"10549500","side":"Sell"}],"update":[{"price":"1055.55","symbol":"BCHUSDT","id":"10555500","side":"Sell","size":1},{"price":"1055.40","symbol":"BCHUSDT","id":"10554000","side":"Sell","size":4.68},{"price":"1055.60","symbol":"BCHUSDT","id":"10556000","side":"Sell","size":5.31},{"price":"1053.65","symbol":"BCHUSDT","id":"10536500","side":"Buy","size":14.28}],"insert":[{"price":"1056.20","symbol":"BCHUSDT","id":"10562000","side":"Sell","size":1},{"price":"1056.15","symbol":"BCHUSDT","id":"10561500","side":"Sell","size":5.33},{"price":"1056.25","symbol":"BCHUSDT","id":"10562500","side":"Sell","size":4.27}]},"cross_seq":"864132308","timestamp_e6":"1618677788809489"}
1618677788.921567: {"topic":"orderBookL2_25.UNIUSDT","type":"delta","data":{"delete":[{"price":"35.380","symbol":"UNIUSDT","id":"353800","side":"Buy"},{"price":"35.376","symbol":"UNIUSDT","id":"353760","side":"Buy"},{"price":"35.375","symbol":"UNIUSDT","id":"353750","side":"Buy"},{"price":"35.374","symbol":"UNIUSDT","id":"353740","side":"Buy"},{"price":"35.379","symbol":"UNIUSDT","id":"353790","side":"Buy"},{"price":"35.378","symbol":"UNIUSDT","id":"353780","side":"Buy"},{"price":"35.384","symbol":"UNIUSDT","id":"353840","side":"Buy"},{"price":"35.372","symbol":"UNIUSDT","id":"353720","side":"Buy"},{"price":"35.382","symbol":"UNIUSDT","id":"353820","side":"Buy"}],"update":[{"price":"35.368","symbol":"UNIUSDT","id":"353680","side":"Buy","size":42.8},{"price":"35.383","symbol":"UNIUSDT","id":"353830","side":"Buy","size":10.3},{"price":"35.364","symbol":"UNIUSDT","id":"353640","side":"Buy","size":649.3},{"price":"35.367","symbol":"UNIUSDT","id":"353670","side":"Buy","size":38.4},{"price":"35.407","symbol":"UNIUSDT","id":"354070","side":"Sell","size":51.800003},{"price":"35.369","symbol":"UNIUSDT","id":"353690","side":"Buy","size":434.9},{"price":"35.373","symbol":"UNIUSDT","id":"353730","side":"Buy","size":61.699997},{"price":"35.365","symbol":"UNIUSDT","id":"353650","side":"Buy","size":26.4},{"price":"35.366","symbol":"UNIUSDT","id":"353660","side":"Buy","size":283.2},{"price":"35.381","symbol":"UNIUSDT","id":"353810","side":"Buy","size":56.999996},{"price":"35.404","symbol":"UNIUSDT","id":"354040","side":"Sell","size":87.7}],"insert":[{"price":"35.389","symbol":"UNIUSDT","id":"353890","side":"Buy","size":64.2},{"price":"35.377","symbol":"UNIUSDT","id":"353770","side":"Buy","size":9.4},{"price":"35.386","symbol":"UNIUSDT","id":"353860","side":"Buy","size":14.8},{"price":"35.385","symbol":"UNIUSDT","id":"353850","side":"Buy","size":34.2},{"price":"35.359","symbol":"UNIUSDT","id":"353590","side":"Buy","size":23.3},{"price":"35.388","symbol":"UNIUSDT","id":"353880","side":"Buy","size":52.5},{"price":"35.387","symbol":"UNIUSDT","id":"353870","side":"Buy","size":33.2},{"price":"35.370","symbol":"UNIUSDT","id":"353700","side":"Buy","size":14.5},{"price":"35.358","symbol":"UNIUSDT","id":"353580","side":"Buy","size":20.4}]},"cross_seq":"916953603","timestamp_e6":"1618677788822497"}
1618677788.921777: {"topic":"orderBookL2_25.LINKUSDT","type":"delta","data":{"delete":[{"price":"41.024","symbol":"LINKUSDT","id":"410240","side":"Buy"},{"price":"41.056","symbol":"LINKUSDT","id":"410560","side":"Sell"}],"update":[{"price":"41.044","symbol":"LINKUSDT","id":"410440","side":"Buy","size":261.5},{"price":"41.045","symbol":"LINKUSDT","id":"410450","side":"Buy","size":185.8},{"price":"41.053","symbol":"LINKUSDT","id":"410530","side":"Sell","size":466}],"insert":[{"price":"41.057","symbol":"LINKUSDT","id":"410570","side":"Sell","size":346.00003},{"price":"41.048","symbol":"LINKUSDT","id":"410480","side":"Buy","size":432.3}]},"cross_seq":"1970979065","timestamp_e6":"1618677788825263"}
1618677788.929332: {"topic":"orderBookL2_25.LINKUSDT","type":"delta","data":{"delete":[],"update":[{"price":"41.072","symbol":"LINKUSDT","id":"410720","side":"Sell","size":250.5}],"insert":[]},"cross_seq":"1970979066","timestamp_e6":"1618677788844692"}
1618677788.94855: {"topic":"orderBookL2_25.ADAUSDT","type":"delta","data":{"delete":[],"update":[{"price":"1.3868","symbol":"ADAUSDT","id":"13868","side":"Buy","size":7912},{"price":"1.3867","symbol":"ADAUSDT","id":"13867","side":"Buy","size":4274},{"price":"1.3877","symbol":"ADAUSDT","id":"13877","side":"Sell","size":3130},{"price":"1.3855","symbol":"ADAUSDT","id":"13855","side":"Buy","size":2568},{"price":"1.3856","symbol":"ADAUSDT","id":"13856","side":"Buy","size":6839},{"price":"1.3879","symbol":"ADAUSDT","id":"13879","side":"Sell","size":4269},{"price":"1.3878","symbol":"ADAUSDT","id":"13878","side":"Sell","size":8443},{"price":"1.3880","symbol":"ADAUSDT","id":"13880","side":"Sell","size":4271},{"price":"1.3864","symbol":"ADAUSDT","id":"13864","side":"Buy","size":6296.9995},{"price":"1.3858","symbol":"ADAUSDT","id":"13858","side":"Buy","size":3744}],"insert":[]},"cross_seq":"916953633","timestamp_e6":"1618677788862337"}
1618677789.1008: {"topic":"orderBookL2_25.DOTUSDT","type":"delta","data":{"delete":[],"update":[{"price":"43.535","symbol":"DOTUSDT","id":"435350","side":"Buy","size":192}],"insert":[]},"cross_seq":"916953634","timestamp_e6":"1618677788882384"}
1618677789.100875: {"topic":"orderBookL2_25.LTCUSDT","type":"delta","data":{"delete":[{"price":"313.39","symbol":"LTCUSDT","id":"3133900","side":"Sell"},{"price":"313.40","symbol":"LTCUSDT","id":"3134000","side":"Sell"}],"update":[{"price":"313.19","symbol":"LTCUSDT","id":"3131900","side":"Sell","size":58.8},{"price":"313.18","symbol":"LTCUSDT","id":"3131800","side":"Sell","size":1.5},{"price":"313.15","symbol":"LTCUSDT","id":"3131500","side":"Sell","size":36.8}],"insert":[{"price":"313.14","symbol":"LTCUSDT","id":"3131400","side":"Sell","size":128.1},{"price":"313.16","symbol":"LTCUSDT","id":"3131600","side":"Sell","size":65.799995}]},"cross_seq":"1684522672","timestamp_e6":"1618677788898387"}
1618677789.10096: {"topic":"orderBookL2_25.DOTUSDT","type":"delta","data":{"delete":[{"price":"43.505","symbol":"DOTUSDT","id":"435050","side":"Buy"}],"update":[{"price":"43.515","symbol":"DOTUSDT","id":"435150","side":"Buy","size":436.4},{"price":"43.500","symbol":"DOTUSDT","id":"435000","side":"Buy","size":104.7},{"price":"43.520","symbol":"DOTUSDT","id":"435200","side":"Buy","size":487.69998},{"price":"43.495","symbol":"DOTUSDT","id":"434950","side":"Buy","size":114.1}],"insert":[{"price":"43.510","symbol":"DOTUSDT","id":"435100","side":"Buy","size":376.00003}]},"cross_seq":"916953650","timestamp_e6":"1618677788902492"}
1618677789.101015: {"topic":"orderBookL2_25.ADAUSDT","type":"delta","data":{"delete":[{"price":"1.3869","symbol":"ADAUSDT","id":"13869","side":"Buy"}],"update":[{"price":"1.3862","symbol":"ADAUSDT","id":"13862","side":"Buy","size":1437},{"price":"1.3865","symbol":"ADAUSDT","id":"13865","side":"Buy","size":2275},{"price":"1.3866","symbol":"ADAUSDT","id":"13866","side":"Buy","size":1846}],"insert":[{"price":"1.3846","symbol":"ADAUSDT","id":"13846","side":"Buy","size":1015}]},"cross_seq":"916953650","timestamp_e6":"1618677788902326"}
1618677789.1010618: {"topic":"orderBookL2_25.ADAUSDT","type":"delta","data":{"delete":[],"update":[{"price":"1.3861","symbol":"ADAUSDT","id":"13861","side":"Buy","size":1693.9999},{"price":"1.3864","symbol":"ADAUSDT","id":"13864","side":"Buy","size":7018},{"price":"1.3867","symbol":"ADAUSDT","id":"13867","side":"Buy","size":2000},{"price":"1.3863","symbol":"ADAUSDT","id":"13863","side":"Buy","size":4574}],"insert":[]},"cross_seq":"916953657","timestamp_e6":"1618677788922339"}
1618677789.101096: {"topic":"orderBookL2_25.LTCUSDT","type":"delta","data":{"delete":[],"update":[{"price":"313.10","symbol":"LTCUSDT","id":"3131000","side":"Sell","size":277.1}],"insert":[]},"cross_seq":"1684522679","timestamp_e6":"1618677788939074"}
1618677789.101116: {"topic":"orderBookL2_25.ADAUSDT","type":"delta","data":{"delete":[{"price":"1.3846","symbol":"ADAUSDT","id":"13846","side":"Buy"}],"update":[{"price":"1.3867","symbol":"ADAUSDT","id":"13867","side":"Buy","size":2001},{"price":"1.3864","symbol":"ADAUSDT","id":"13864","side":"Buy","size":7019},{"price":"1.3879","symbol":"ADAUSDT","id":"13879","side":"Sell","size":4270},{"price":"1.3883","symbol":"ADAUSDT","id":"13883","side":"Sell","size":2309}],"insert":[{"price":"1.3870","symbol":"ADAUSDT","id":"13870","side":"Buy","size":1}]},"cross_seq":"916953676","timestamp_e6":"1618677788942334"}
1618677789.10116: {"topic":"orderBookL2_25.LINKUSDT","type":"delta","data":{"delete":[],"update":[{"price":"41.053","symbol":"LINKUSDT","id":"410530","side":"Sell","size":66}],"insert":[]},"cross_seq":"1970979068","timestamp_e6":"1618677788944387"}
1618677789.101181: {"topic":"orderBookL2_25.DOTUSDT","type":"delta","data":{"delete":[],"update":[{"price":"43.575","symbol":"DOTUSDT","id":"435750","side":"Sell","size":173.59999}],"insert":[]},"cross_seq":"916953695","timestamp_e6":"1618677788962448"}
1618677789.1011999: {"topic":"orderBookL2_25.ADAUSDT","type":"delta","data":{"delete":[{"price":"1.3861","symbol":"ADAUSDT","id":"13861","side":"Buy"}],"update":[{"price":"1.3866","symbol":"ADAUSDT","id":"13866","side":"Buy","size":3595},{"price":"1.3864","symbol":"ADAUSDT","id":"13864","side":"Buy","size":4861},{"price":"1.3863","symbol":"ADAUSDT","id":"13863","side":"Buy","size":2879.9998}],"insert":[{"price":"1.3846","symbol":"ADAUSDT","id":"13846","side":"Buy","size":1015}]},"cross_seq":"916953695","timestamp_e6":"1618677788962327"}
1618677789.101239: {"topic":"orderBookL2_25.LINKUSDT","type":"delta","data":{"delete":[{"price":"41.048","symbol":"LINKUSDT","id":"410480","side":"Buy"},{"price":"41.057","symbol":"LINKUSDT","id":"410570","side":"Sell"},{"price":"41.047","symbol":"LINKUSDT","id":"410470","side":"Buy"},{"price":"41.053","symbol":"LINKUSDT","id":"410530","side":"Sell"},{"price":"41.046","symbol":"LINKUSDT","id":"410460","side":"Buy"},{"price":"41.059","symbol":"LINKUSDT","id":"410590","side":"Sell"},{"price":"41.058","symbol":"LINKUSDT","id":"410580","side":"Sell"}],"update":[{"price":"41.026","symbol":"LINKUSDT","id":"410260","side":"Buy","size":734.10004}],"insert":[{"price":"41.054","symbol":"LINKUSDT","id":"410540","side":"Sell","size":346.00003},{"price":"41.049","symbol":"LINKUSDT","id":"410490","side":"Buy","size":417},{"price":"41.055","symbol":"LINKUSDT","id":"410550","side":"Sell","size":295},{"price":"41.050","symbol":"LINKUSDT","id":"410500","side":"Buy","size":447.3},{"price":"41.081","symbol":"LINKUSDT","id":"410810","side":"Sell","size":187.8},{"price":"41.056","symbol":"LINKUSDT","id":"410560","side":"Sell","size":159.3},{"price":"41.051","symbol":"LINKUSDT","id":"410510","side":"Buy","size":432.3}]},"cross_seq":"1970979085","timestamp_e6":"1618677788964051"}
1618677789.101341: {"topic":"orderBookL2_25.XTZUSDT","type":"delta","data":{"delete":[],"update":[{"price":"7.216","symbol":"XTZUSDT","id":"72160","side":"Sell","size":2428.0999},{"price":"7.204","symbol":"XTZUSDT","id":"72040","side":"Buy","size":2539.1},{"price":"7.202","symbol":"XTZUSDT","id":"72020","side":"Buy","size":2593.2},{"price":"7.203","symbol":"XTZUSDT","id":"72030","side":"Buy","size":2392.8},{"price":"7.217","symbol":"XTZUSDT","id":"72170","side":"Sell","size":774.4},{"price":"7.219","symbol":"XTZUSDT","id":"72190","side":"Sell","size":135.7},{"price":"7.218","symbol":"XTZUSDT","id":"72180","side":"Sell","size":1881.3999}],"insert":[]},"cross_seq":"726228279","timestamp_e6":"1618677788975297"}
1618677789.101387: {"topic":"orderBookL2_25.LTCUSDT","type":"delta","data":{"delete":[],"update":[{"price":"313.09","symbol":"LTCUSDT","id":"3130900","side":"Buy","size":214.7}],"insert":[]},"cross_seq":"1684522680","timestamp_e6":"1618677788979839"}
1618677789.101408: {"topic":"orderBookL2_25.LINKUSDT","type":"delta","data":{"delete":[{"price":"41.081","symbol":"LINKUSDT","id":"410810","side":"Sell"}],"update":[{"price":"41.052","symbol":"LINKUSDT","id":"410520","side":"Buy","size":296}],"insert":[{"price":"41.053","symbol":"LINKUSDT","id":"410530","side":"Sell","size":66}]},"cross_seq":"1970979091","timestamp_e6":"1618677788985197"}
1618677789.10144: {"topic":"orderBookL2_25.ADAUSDT","type":"delta","data":{"delete":[{"price":"1.3846","symbol":"ADAUSDT","id":"13846","side":"Buy"}],"update":[{"price":"1.3890","symbol":"ADAUSDT","id":"13890","side":"Sell","size":9232}],"insert":[{"price":"1.3869","symbol":"ADAUSDT","id":"13869","side":"Buy","size":14697}]},"cross_seq":"916953697","timestamp_e6":"1618677789002335"}
1618677789.101472: {"topic":"orderBookL2_25.LINKUSDT","type":"delta","data":{"delete":[{"price":"41.053","symbol":"LINKUSDT","id":"410530","side":"Sell"},{"price":"41.079","symbol":"LINKUSDT","id":"410790","side":"Sell"},{"price":"41.025","symbol":"LINKUSDT","id":"410250","side":"Buy"},{"price":"41.049","symbol":"LINKUSDT","id":"410490","side":"Buy"},{"price":"41.080","symbol":"LINKUSDT","id":"410800","side":"Sell"}],"update":[{"price":"41.052","symbol":"LINKUSDT","id":"410520","side":"Buy","size":722.30005}],"insert":[{"price":"41.048","symbol":"LINKUSDT","id":"410480","side":"Buy","size":261.5},{"price":"41.057","symbol":"LINKUSDT","id":"410570","side":"Sell","size":144},{"price":"41.047","symbol":"LINKUSDT","id":"410470","side":"Buy","size":272.1},{"price":"41.058","symbol":"LINKUSDT","id":"410580","side":"Sell","size":93.4},{"price":"41.059","symbol":"LINKUSDT","id":"410590","side":"Sell","size":81.7}]},"cross_seq":"1970979102","timestamp_e6":"1618677789005830"}
1618677789.101547: {"topic":"orderBookL2_25.ETHUSDT","type":"delta","data":{"delete":[],"update":[{"price":"2364.95","symbol":"ETHUSDT","id":"23649500","side":"Sell","size":286.19998},{"price":"2364.90","symbol":"ETHUSDT","id":"23649000","side":"Buy","size":153.98}],"insert":[]},"cross_seq":"1800546369","timestamp_e6":"1618677789009274"}
1618677789.102628: {"topic":"orderBookL2_25.LTCUSDT","type":"delta","data":{"delete":[],"update":[{"price":"313.30","symbol":"LTCUSDT","id":"3133000","side":"Sell","size":41.2}],"insert":[]},"cross_seq":"1684522681","timestamp_e6":"1618677789017868"}
1618677789.1068711: {"topic":"orderBookL2_25.DOTUSDT","type":"delta","data":{"delete":[{"price":"43.410","symbol":"DOTUSDT","id":"434100","side":"Buy"},{"price":"43.405","symbol":"DOTUSDT","id":"434050","side":"Buy"}],"update":[{"price":"43.490","symbol":"DOTUSDT","id":"434900","side":"Buy","size":241.4},{"price":"43.510","symbol":"DOTUSDT","id":"435100","side":"Buy","size":101.700005},{"price":"43.520","symbol":"DOTUSDT","id":"435200","side":"Buy","size":477.7},{"price":"43.500","symbol":"DOTUSDT","id":"435000","side":"Buy","size":376.1},{"price":"43.495","symbol":"DOTUSDT","id":"434950","side":"Buy","size":365.59998}],"insert":[{"price":"43.505","symbol":"DOTUSDT","id":"435050","side":"Buy","size":435.5},{"price":"43.530","symbol":"DOTUSDT","id":"435300","side":"Buy","size":10}]},"cross_seq":"916953705","timestamp_e6":"1618677789022380"}
1618677789.106975: {"topic":"orderBookL2_25.UNIUSDT","type":"delta","data":{"delete":[],"update":[{"price":"35.401","symbol":"UNIUSDT","id":"354010","side":"Buy","size":220.7}],"insert":[]},"cross_seq":"916953705","timestamp_e6":"1618677789022556"}
1618677789.107708: {"topic":"orderBookL2_25.LINKUSDT","type":"delta","data":{"delete":[],"update":[{"price":"41.052","symbol":"LINKUSDT","id":"410520","side":"Buy","size":728.3}],"insert":[]},"cross_seq":"1970979115","timestamp_e6":"1618677789024879"}
1618677789.1112692: {"topic":"orderBookL2_25.ETHUSDT","type":"delta","data":{"delete":[{"price":"2364.30","symbol":"ETHUSDT","id":"23643000","side":"Buy"},{"price":"2364.25","symbol":"ETHUSDT","id":"23642500","side":"Buy"}],"update":[],"insert":[{"price":"2364.50","symbol":"ETHUSDT","id":"23645000","side":"Buy","size":112.100006},{"price":"2363.35","symbol":"ETHUSDT","id":"23633500","side":"Buy","size":23.73}]},"cross_seq":"1800546373","timestamp_e6":"1618677789027232"}
1618677789.1187809: {"topic":"orderBookL2_25.XTZUSDT","type":"delta","data":{"delete":[],"update":[{"price":"7.219","symbol":"XTZUSDT","id":"72190","side":"Sell","size":499}],"insert":[]},"cross_seq":"726228280","timestamp_e6":"1618677789035593"}
1618677789.1243122: {"topic":"orderBookL2_25.LTCUSDT","type":"delta","data":{"delete":[],"update":[{"price":"313.09","symbol":"LTCUSDT","id":"3130900","side":"Buy","size":364.7},{"price":"313.10","symbol":"LTCUSDT","id":"3131000","side":"Sell","size":1.5}],"insert":[]},"cross_seq":"1684522685","timestamp_e6":"1618677789040234"}
1618677789.127854: {"topic":"orderBookL2_25.UNIUSDT","type":"delta","data":{"delete":[],"update":[{"price":"35.401","symbol":"UNIUSDT","id":"354010","side":"Buy","size":0.7}],"insert":[]},"cross_seq":"916953717","timestamp_e6":"1618677789042390"}
1618677789.131167: {"topic":"orderBookL2_25.LINKUSDT","type":"delta","data":{"delete":[{"price":"41.050","symbol":"LINKUSDT","id":"410500","side":"Buy"},{"price":"41.062","symbol":"LINKUSDT","id":"410620","side":"Sell"},{"price":"41.026","symbol":"LINKUSDT","id":"410260","side":"Buy"}],"update":[{"price":"41.054","symbol":"LINKUSDT","id":"410540","side":"Sell","size":412},{"price":"41.066","symbol":"LINKUSDT","id":"410660","side":"Sell","size":125.299995},{"price":"41.064","symbol":"LINKUSDT","id":"410640","side":"Sell","size":159.3},{"price":"41.052","symbol":"LINKUSDT","id":"410520","side":"Buy","size":722.30005},{"price":"41.067","symbol":"LINKUSDT","id":"410670","side":"Sell","size":213.40001}],"insert":[{"price":"41.079","symbol":"LINKUSDT","id":"410790","side":"Sell","size":349.1},{"price":"41.053","symbol":"LINKUSDT","id":"410530","side":"Buy","size":438.30002},{"price":"41.049","symbol":"LINKUSDT","id":"410490","side":"Buy","size":261.5}]},"cross_seq":"1970979138","timestamp_e6":"1618677789045269"}
1618677789.131279: {"topic":"orderBookL2_25.ETHUSDT","type":"delta","data":{"delete":[],"update":[{"price":"2364.90","symbol":"ETHUSDT","id":"23649000","side":"Buy","size":121.479996}],"insert":[]},"cross_seq":"1800546374","timestamp_e6":"1618677789048457"}
1618677789.279875: {"topic":"orderBookL2_25.LTCUSDT","type":"delta","data":{"delete":[],"update":[{"price":"313.10","symbol":"LTCUSDT","id":"3131000","side":"Sell","size":2.1},{"price":"313.09","symbol":"LTCUSDT","id":"3130900","side":"Buy","size":214.7}],"insert":[]},"cross_seq":"1684522687","timestamp_e6":"1618677789060276"}
1618677789.279954: {"topic":"orderBookL2_25.DOTUSDT","type":"delta","data":{"delete":[{"price":"43.520","symbol":"DOTUSDT","id":"435200","side":"Buy"},{"price":"43.545","symbol":"DOTUSDT","id":"435450","side":"Sell"}],"update":[{"price":"43.485","symbol":"DOTUSDT","id":"434850","side":"Buy","size":149.2},{"price":"43.565","symbol":"DOTUSDT","id":"435650","side":"Sell","size":363.1},{"price":"43.540","symbol":"DOTUSDT","id":"435400","side":"Sell","size":855.3},{"price":"43.510","symbol":"DOTUSDT","id":"435100","side":"Buy","size":477.7},{"price":"43.550","symbol":"DOTUSDT","id":"435500","side":"Sell","size":731.3},{"price":"43.515","symbol":"DOTUSDT","id":"435150","side":"Buy","size":0.9}],"insert":[{"price":"43.665","symbol":"DOTUSDT","id":"436650","side":"Sell","size":75.1},{"price":"43.410","symbol":"DOTUSDT","id":"434100","side":"Buy","size":252.7}]},"cross_seq":"916953762","timestamp_e6":"1618677789062337"}
1618677789.2800488: {"topic":"orderBookL2_25.UNIUSDT","type":"delta","data":{"delete":[{"price":"35.364","symbol":"UNIUSDT","id":"353640","side":"Buy"},{"price":"35.360","symbol":"UNIUSDT","id":"353600","side":"Buy"},{"price":"35.362","symbol":"UNIUSDT","id":"353620","side":"Buy"},{"price":"35.361","symbol":"UNIUSDT","id":"353610","side":"Buy"},{"price":"35.359","symbol":"UNIUSDT","id":"353590","side":"Buy"},{"price":"35.381","symbol":"UNIUSDT","id":"353810","side":"Buy"},{"price":"35.363","symbol":"UNIUSDT","id":"353630","side":"Buy"},{"price":"35.358","symbol":"UNIUSDT","id":"353580","side":"Buy"}],"update":[{"price":"35.406","symbol":"UNIUSDT","id":"354060","side":"Sell","size":128.7},{"price":"35.365","symbol":"UNIUSDT","id":"353650","side":"Buy","size":30.6},{"price":"35.407","symbol":"UNIUSDT","id":"354070","side":"Sell","size":133.8},{"price":"35.368","symbol":"UNIUSDT","id":"353680","side":"Buy","size":48.999996},{"price":"35.383","symbol":"UNIUSDT","id":"353830","side":"Buy","size":52.5},{"price":"35.410","symbol":"UNIUSDT","id":"354100","side":"Sell","size":115.3},{"price":"35.409","symbol":"UNIUSDT","id":"354090","side":"Sell","size":124.5}],"insert":[{"price":"35.375","symbol":"UNIUSDT","id":"353750","side":"Buy","size":8.8},{"price":"35.382","symbol":"UNIUSDT","id":"353820","side":"Buy","size":33.2},{"price":"35.379","symbol":"UNIUSDT","id":"353790","side":"Buy","size":28.6},{"price":"35.376","symbol":"UNIUSDT","id":"353760","side":"Buy","size":7.6},{"price":"35.374","symbol":"UNIUSDT","id":"353740","side":"Buy","size":5.2},{"price":"35.378","symbol":"UNIUSDT","id":"353780","side":"Buy","size":8.9},{"price":"35.380","symbol":"UNIUSDT","id":"353800","side":"Buy","size":34.2},{"price":"35.372","symbol":"UNIUSDT","id":"353720","side":"Buy","size":6.1}]},"cross_seq":"916953762","timestamp_e6":"1618677789062475"}
1618677789.280201: {"topic":"orderBookL2_25.ETHUSDT","type":"delta","data":{"delete":[{"price":"2364.45","symbol":"ETHUSDT","id":"23644500","side":"Buy"},{"price":"2363.35","symbol":"ETHUSDT","id":"23633500","side":"Buy"}],"update":[],"insert":[{"price":"2364.25","symbol":"ETHUSDT","id":"23642500","side":"Buy","size":67.15},{"price":"2364.30","symbol":"ETHUSDT","id":"23643000","side":"Buy","size":101.21}]},"cross_seq":"1800546378","timestamp_e6":"1618677789067162"}
1618677789.28025: {"topic":"orderBookL2_25.BCHUSDT","type":"delta","data":{"delete":[{"price":"1056.25","symbol":"BCHUSDT","id":"10562500","side":"Sell"}],"update":[{"price":"1055.55","symbol":"BCHUSDT","id":"10555500","side":"Sell","size":3.39},{"price":"1055.40","symbol":"BCHUSDT","id":"10554000","side":"Sell","size":11.02}],"insert":[{"price":"1055.25","symbol":"BCHUSDT","id":"10552500","side":"Sell","size":3.86}]},"cross_seq":"864132311","timestamp_e6":"1618677789068879"}
1618677789.2802932: {"topic":"orderBookL2_25.LINKUSDT","type":"delta","data":{"delete":[],"update":[{"price":"41.053","symbol":"LINKUSDT","id":"410530","side":"Buy","size":878.30005}],"insert":[]},"cross_seq":"1970979150","timestamp_e6":"1618677789084829"}
1618677789.2803159: {"topic":"orderBookL2_25.ETHUSDT","type":"delta","data":{"delete":[],"update":[{"price":"2364.90","symbol":"ETHUSDT","id":"23649000","side":"Buy","size":88.990005}],"insert":[]},"cross_seq":"1800546379","timestamp_e6":"1618677789088560"}
1618677789.280341: {"topic":"orderBookL2_25.ADAUSDT","type":"delta","data":{"delete":[],"update":[{"price":"1.3866","symbol":"ADAUSDT","id":"13866","side":"Buy","size":1749},{"price":"1.3862","symbol":"ADAUSDT","id":"13862","side":"Buy","size":711},{"price":"1.3865","symbol":"ADAUSDT","id":"13865","side":"Buy","size":581},{"price":"1.3864","symbol":"ADAUSDT","id":"13864","side":"Buy","size":6555},{"price":"1.3863","symbol":"ADAUSDT","id":"13863","side":"Buy","size":3737},{"price":"1.3867","symbol":"ADAUSDT","id":"13867","side":"Buy","size":5596}],"insert":[]},"cross_seq":"916953769","timestamp_e6":"1618677789102329"}
1618677789.28038: {"topic":"orderBookL2_25.LINKUSDT","type":"delta","data":{"delete":[],"update":[{"price":"41.072","symbol":"LINKUSDT","id":"410720","side":"Sell","size":188.3},{"price":"41.052","symbol":"LINKUSDT","id":"410520","side":"Buy","size":432.3}],"insert":[]},"cross_seq":"1970979154","timestamp_e6":"1618677789104489"}
1618677789.280406: {"topic":"orderBookL2_25.ADAUSDT","type":"delta","data":{"delete":[],"update":[{"price":"1.3856","symbol":"ADAUSDT","id":"13856","side":"Buy","size":7372}],"insert":[]},"cross_seq":"916953770","timestamp_e6":"1618677789122326"}
1618677789.280426: {"topic":"orderBookL2_25.LINKUSDT","type":"delta","data":{"delete":[{"price":"41.027","symbol":"LINKUSDT","id":"410270","side":"Buy"},{"price":"41.028","symbol":"LINKUSDT","id":"410280","side":"Buy"}],"update":[{"price":"41.058","symbol":"LINKUSDT","id":"410580","side":"Sell","size":94.299995}],"insert":[{"price":"41.046","symbol":"LINKUSDT","id":"410460","side":"Buy","size":1.3},{"price":"41.050","symbol":"LINKUSDT","id":"410500","side":"Buy","size":1.3}]},"cross_seq":"1970979159","timestamp_e6":"1618677789123835"}
1618677789.280478: {"topic":"orderBookL2_25.ADAUSDT","type":"delta","data":{"delete":[],"update":[{"price":"1.3875","symbol":"ADAUSDT","id":"13875","side":"Buy","size":75850}],"insert":[]},"cross_seq":"916953771","timestamp_e6":"1618677789142315"}
1618677789.281309: {"topic":"orderBookL2_25.LTCUSDT","type":"delta","data":{"delete":[],"update":[{"price":"313.18","symbol":"LTCUSDT","id":"3131800","side":"Sell","size":41.3},{"price":"313.15","symbol":"LTCUSDT","id":"3131500","side":"Sell","size":91.3}],"insert":[]},"cross_seq":"1684522689","timestamp_e6":"1618677789158207"}
1618677789.283794: {"topic":"orderBookL2_25.LTCUSDT","type":"delta","data":{"delete":[],"update":[{"price":"313.10","symbol":"LTCUSDT","id":"3131000","side":"Sell","size":127.1}],"insert":[]},"cross_seq":"1684522690","timestamp_e6":"1618677789199510"}
1618677789.318057: {"topic":"orderBookL2_25.XTZUSDT","type":"delta","data":{"delete":[],"update":[{"price":"7.219","symbol":"XTZUSDT","id":"72190","side":"Sell","size":557.6},{"price":"7.217","symbol":"XTZUSDT","id":"72170","side":"Sell","size":1128.5}],"insert":[]},"cross_seq":"726228282","timestamp_e6":"1618677789234572"}
1618677789.460195: {"topic":"orderBookL2_25.BCHUSDT","type":"delta","data":{"delete":[{"price":"1055.15","symbol":"BCHUSDT","id":"10551500","side":"Sell"},{"price":"1056.15","symbol":"BCHUSDT","id":"10561500","side":"Sell"},{"price":"1056.20","symbol":"BCHUSDT","id":"10562000","side":"Sell"}],"update":[{"price":"1055.00","symbol":"BCHUSDT","id":"10550000","side":"Sell","size":0.01},{"price":"1055.50","symbol":"BCHUSDT","id":"10555000","side":"Sell","size":4.68},{"price":"1055.35","symbol":"BCHUSDT","id":"10553500","side":"Sell","size":6.19},{"price":"1055.55","symbol":"BCHUSDT","id":"10555500","side":"Sell","size":5.31},{"price":"1055.05","symbol":"BCHUSDT","id":"10550500","side":"Sell","size":5.49}],"insert":[{"price":"1055.30","symbol":"BCHUSDT","id":"10553000","side":"Sell","size":11.34},{"price":"1054.95","symbol":"BCHUSDT","id":"10549500","side":"Sell","size":9.04},{"price":"1054.90","symbol":"BCHUSDT","id":"10549000","side":"Sell","size":12.62}]},"cross_seq":"864132325","timestamp_e6":"1618677789269302"}
1618677789.460278: {"topic":"orderBookL2_25.ADAUSDT","type":"delta","data":{"delete":[],"update":[{"price":"1.3865","symbol":"ADAUSDT","id":"13865","side":"Buy","size":2275},{"price":"1.3862","symbol":"ADAUSDT","id":"13862","side":"Buy","size":1437},{"price":"1.3866","symbol":"ADAUSDT","id":"13866","side":"Buy","size":1846}],"insert":[]},"cross_seq":"916953796","timestamp_e6":"1618677789282415"}
1618677789.460306: {"topic":"orderBookL2_25.DOTUSDT","type":"delta","data":{"delete":[{"price":"43.410","symbol":"DOTUSDT","id":"434100","side":"Buy"}],"update":[{"price":"43.550","symbol":"DOTUSDT","id":"435500","side":"Sell","size":541.5},{"price":"43.540","symbol":"DOTUSDT","id":"435400","side":"Sell","size":450},{"price":"43.500","symbol":"DOTUSDT","id":"435000","side":"Buy","size":0.1},{"price":"43.525","symbol":"DOTUSDT","id":"435250","side":"Buy","size":514},{"price":"43.510","symbol":"DOTUSDT","id":"435100","side":"Buy","size":376.00003},{"price":"43.570","symbol":"DOTUSDT","id":"435700","side":"Sell","size":283.6},{"price":"43.555","symbol":"DOTUSDT","id":"435550","side":"Sell","size":619.5},{"price":"43.515","symbol":"DOTUSDT","id":"435150","side":"Buy","size":456.9}],"insert":[{"price":"43.520","symbol":"DOTUSDT","id":"435200","side":"Buy","size":428.7}]},"cross_seq":"916953796","timestamp_e6":"1618677789283832"}
1618677789.460358: {"topic":"orderBookL2_25.BCHUSDT","type":"delta","data":{"delete":[{"price":"1055.10","symbol":"BCHUSDT","id":"10551000","side":"Sell"},{"price":"1054.90","symbol":"BCHUSDT","id":"10549000","side":"Sell"}],"update":[{"price":"1054.55","symbol":"BCHUSDT","id":"10545500","side":"Buy","size":14.46},{"price":"1054.45","symbol":"BCHUSDT","id":"10544500","side":"Buy","size":11.22},{"price":"1054.95","symbol":"BCHUSDT","id":"10549500","side":"Sell","size":5.1},{"price":"1055.05","symbol":"BCHUSDT","id":"10550500","side":"Sell","size":2.85}],"insert":[{"price":"1055.15","symbol":"BCHUSDT","id":"10551500","side":"Sell","size":4.36},{"price":"1054.85","symbol":"BCHUSDT","id":"10548500","side":"Sell","size":14.14}]},"cross_seq":"864132338","timestamp_e6":"1618677789288870"}
1618677789.460404: {"topic":"orderBookL2_25.LTCUSDT","type":"delta","data":{"delete":[{"price":"312.77","symbol":"LTCUSDT","id":"3127700","side":"Buy"}],"update":[],"insert":[{"price":"312.78","symbol":"LTCUSDT","id":"3127800","side":"Buy","size":44.999996}]},"cross_seq":"1684522691","timestamp_e6":"1618677789298614"}
1618677789.460429: {"topic":"orderBookL2_25.LINKUSDT","type":"delta","data":{"delete":[{"price":"41.059","symbol":"LINKUSDT","id":"410590","side":"Sell"},{"price":"41.055","symbol":"LINKUSDT","id":"410550","side":"Sell"},{"price":"41.057","symbol":"LINKUSDT","id":"410570","side":"Sell"},{"price":"41.060","symbol":"LINKUSDT","id":"410600","side":"Sell"},{"price":"41.056","symbol":"LINKUSDT","id":"410560","side":"Sell"},{"price":"41.061","symbol":"LINKUSDT","id":"410610","side":"Sell"},{"price":"41.052","symbol":"LINKUSDT","id":"410520","side":"Buy"}],"update":[{"price":"41.054","symbol":"LINKUSDT","id":"410540","side":"Sell","size":66},{"price":"41.066","symbol":"LINKUSDT","id":"410660","side":"Sell","size":185},{"price":"41.050","symbol":"LINKUSDT","id":"410500","side":"Buy","size":365.7},{"price":"41.058","symbol":"LINKUSDT","id":"410580","side":"Sell","size":0.9},{"price":"41.079","symbol":"LINKUSDT","id":"410790","side":"Sell","size":411.30002},{"price":"41.065","symbol":"LINKUSDT","id":"410650","side":"Sell","size":179.90001},{"price":"41.063","symbol":"LINKUSDT","id":"410630","side":"Sell","size":223.5},{"price":"41.064","symbol":"LINKUSDT","id":"410640","side":"Sell","size":202.1}],"insert":[{"price":"41.082","symbol":"LINKUSDT","id":"410820","side":"Sell","size":204.00002},{"price":"41.084","symbol":"LINKUSDT","id":"410840","side":"Sell","size":365.59998},{"price":"41.083","symbol":"LINKUSDT","id":"410830","side":"Sell","size":190},{"price":"41.062","symbol":"LINKUSDT","id":"410620","side":"Sell","size":287.3},{"price":"41.028","symbol":"LINKUSDT","id":"410280","side":"Buy","size":425.9},{"price":"41.080","symbol":"LINKUSDT","id":"410800","side":"Sell","size":39},{"price":"41.081","symbol":"LINKUSDT","id":"410810","side":"Sell","size":187.8}]},"cross_seq":"1970979181","timestamp_e6":"1618677789304095"}
1618677789.460534: {"topic":"orderBookL2_25.LTCUSDT","type":"delta","data":{"delete":[],"update":[{"price":"312.80","symbol":"LTCUSDT","id":"3128000","side":"Buy","size":139.5}],"insert":[]},"cross_seq":"1684522692","timestamp_e6":"1618677789320770"}
1618677789.460552: {"topic":"orderBookL2_25.DOTUSDT","type":"delta","data":{"delete":[],"update":[{"price":"43.515","symbol":"DOTUSDT","id":"435150","side":"Buy","size":455.99997},{"price":"43.540","symbol":"DOTUSDT","id":"435400","side":"Sell","size":550}],"insert":[]},"cross_seq":"916953805","timestamp_e6":"1618677789322335"}
1618677789.46057: {"topic":"orderBookL2_25.UNIUSDT","type":"delta","data":{"delete":[{"price":"35.389","symbol":"UNIUSDT","id":"353890","side":"Buy"},{"price":"35.387","symbol":"UNIUSDT","id":"353870","side":"Buy"},{"price":"35.385","symbol":"UNIUSDT","id":"353850","side":"Buy"},{"price":"35.386","symbol":"UNIUSDT","id":"353860","side":"Buy"},{"price":"35.388","symbol":"UNIUSDT","id":"353880","side":"Buy"}],"update":[],"insert":[{"price":"35.363","symbol":"UNIUSDT","id":"353630","side":"Buy","size":40.1},{"price":"35.384","symbol":"UNIUSDT","id":"353840","side":"Buy","size":64.2},{"price":"35.381","symbol":"UNIUSDT","id":"353810","side":"Buy","size":14.8},{"price":"35.362","symbol":"UNIUSDT","id":"353620","side":"Buy","size":66},{"price":"35.364","symbol":"UNIUSDT","id":"353640","side":"Buy","size":649.3}]},"cross_seq":"916953805","timestamp_e6":"1618677789322484"}
1618677789.460628: {"topic":"orderBookL2_25.ETHUSDT","type":"delta","data":{"delete":[{"price":"2364.20","symbol":"ETHUSDT","id":"23642000","side":"Buy"},{"price":"2364.25","symbol":"ETHUSDT","id":"23642500","side":"Buy"},{"price":"2364.40","symbol":"ETHUSDT","id":"23644000","side":"Buy"},{"price":"2364.30","symbol":"ETHUSDT","id":"23643000","side":"Buy"},{"price":"2364.50","symbol":"ETHUSDT","id":"23645000","side":"Buy"}],"update":[{"price":"2365.20","symbol":"ETHUSDT","id":"23652000","side":"Sell","size":47.33},{"price":"2364.35","symbol":"ETHUSDT","id":"23643500","side":"Buy","size":25.2},{"price":"2365.15","symbol":"ETHUSDT","id":"23651500","side":"Sell","size":85.880005},{"price":"2365.05","symbol":"ETHUSDT","id":"23650500","side":"Sell","size":106.14},{"price":"2365.10","symbol":"ETHUSDT","id":"23651000","side":"Sell","size":92.3}],"insert":[{"price":"2364.45","symbol":"ETHUSDT","id":"23644500","side":"Buy","size":78.27},{"price":"2363.35","symbol":"ETHUSDT","id":"23633500","side":"Buy","size":23.73},{"price":"2363.20","symbol":"ETHUSDT","id":"23632000","side":"Buy","size":114.590004},{"price":"2363.25","symbol":"ETHUSDT","id":"23632500","side":"Buy","size":171.42},{"price":"2363.30","symbol":"ETHUSDT","id":"23633000","side":"Buy","size":126.119995}]},"cross_seq":"1800546391","timestamp_e6":"1618677789327789"}
1618677789.460703: {"topic":"orderBookL2_25.DOTUSDT","type":"delta","data":{"delete":[],"update":[{"price":"43.525","symbol":"DOTUSDT","id":"435250","side":"Buy","size":504.00003},{"price":"43.535","symbol":"DOTUSDT","id":"435350","side":"Buy","size":202}],"insert":[]},"cross_seq":"916953806","timestamp_e6":"1618677789342316"}
1618677789.4607239: {"topic":"orderBookL2_25.LINKUSDT","type":"delta","data":{"delete":[],"update":[{"price":"41.053","symbol":"LINKUSDT","id":"410530","side":"Buy","size":1378.3}],"insert":[]},"cross_seq":"1970979182","timestamp_e6":"1618677789345841"}
1618677789.4607391: {"topic":"orderBookL2_25.LTCUSDT","type":"delta","data":{"delete":[],"update":[{"price":"313.10","symbol":"LTCUSDT","id":"3131000","side":"Sell","size":1.5}],"insert":[]},"cross_seq":"1684522694","timestamp_e6":"1618677789359082"}
1618677789.460754: {"topic":"orderBookL2_25.ETHUSDT","type":"delta","data":{"delete":[],"update":[{"price":"2364.95","symbol":"ETHUSDT","id":"23649500","side":"Sell","size":339.53}],"insert":[]},"cross_seq":"1800546392","timestamp_e6":"1618677789367474"}
1618677789.468767: {"topic":"orderBookL2_25.LTCUSDT","type":"delta","data":{"delete":[{"price":"313.20","symbol":"LTCUSDT","id":"3132000","side":"Sell"}],"update":[{"price":"313.06","symbol":"LTCUSDT","id":"3130600","side":"Buy","size":46.5},{"price":"313.24","symbol":"LTCUSDT","id":"3132400","side":"Sell","size":58.1},{"price":"313.21","symbol":"LTCUSDT","id":"3132100","side":"Sell","size":78.4},{"price":"313.04","symbol":"LTCUSDT","id":"3130400","side":"Buy","size":18.2},{"price":"313.22","symbol":"LTCUSDT","id":"3132200","side":"Sell","size":67.299995}],"insert":[{"price":"313.23","symbol":"LTCUSDT","id":"3132300","side":"Sell","size":68.4}]},"cross_seq":"1684522704","timestamp_e6":"1618677789378305"}
1618677789.6137412: {"topic":"orderBookL2_25.DOTUSDT","type":"delta","data":{"delete":[],"update":[{"price":"43.540","symbol":"DOTUSDT","id":"435400","side":"Sell","size":888.5}],"insert":[]},"cross_seq":"916953808","timestamp_e6":"1618677789402324"}
1618677789.61377: {"topic":"orderBookL2_25.LINKUSDT","type":"delta","data":{"delete":[{"price":"41.064","symbol":"LINKUSDT","id":"410640","side":"Sell"},{"price":"41.054","symbol":"LINKUSDT","id":"410540","side":"Sell"},{"price":"41.028","symbol":"LINKUSDT","id":"410280","side":"Buy"}],"update":[{"price":"41.065","symbol":"LINKUSDT","id":"410650","side":"Sell","size":406.30002},{"price":"41.066","symbol":"LINKUSDT","id":"410660","side":"Sell","size":327.4},{"price":"41.068","symbol":"LINKUSDT","id":"410680","side":"Sell","size":70.9}],"insert":[{"price":"41.052","symbol":"LINKUSDT","id":"410520","side":"Buy","size":340},{"price":"41.085","symbol":"LINKUSDT","id":"410850","side":"Sell","size":240.5},{"price":"41.086","symbol":"LINKUSDT","id":"410860","side":"Sell","size":480.3}]},"cross_seq":"1970979196","timestamp_e6":"1618677789404037"}
1618677789.613843: {"topic":"orderBookL2_25.ETHUSDT","type":"delta","data":{"delete":[],"update":[{"price":"2365.05","symbol":"ETHUSDT","id":"23650500","side":"Sell","size":139.3},{"price":"2365.10","symbol":"ETHUSDT","id":"23651000","side":"Sell","size":103.72},{"price":"2363.30","symbol":"ETHUSDT","id":"23633000","side":"Buy","size":29.75},{"price":"2363.25","symbol":"ETHUSDT","id":"23632500","side":"Buy","size":108.71},{"price":"2365.00","symbol":"ETHUSDT","id":"23650000","side":"Sell","size":131.45},{"price":"2363.20","symbol":"ETHUSDT","id":"23632000","side":"Buy","size":51.6}],"insert":[]},"cross_seq":"1800546407","timestamp_e6":"1618677789407528"}
1618677789.613879: {"topic":"orderBookL2_25.LINKUSDT","type":"delta","data":{"delete":[{"price":"41.051","symbol":"LINKUSDT","id":"410510","side":"Buy"},{"price":"41.052","symbol":"LINKUSDT","id":"410520","side":"Buy"},{"price":"41.042","symbol":"LINKUSDT","id":"410420","side":"Buy"},{"price":"41.063","symbol":"LINKUSDT","id":"410630","side":"Sell"},{"price":"41.048","symbol":"LINKUSDT","id":"410480","side":"Buy"},{"price":"41.049","symbol":"LINKUSDT","id":"410490","side":"Buy"},{"price":"41.043","symbol":"LINKUSDT","id":"410430","side":"Buy"},{"price":"41.045","symbol":"LINKUSDT","id":"410450","side":"Buy"},{"price":"41.062","symbol":"LINKUSDT","id":"410620","side":"Sell"}],"update":[{"price":"41.069","symbol":"LINKUSDT","id":"410690","side":"Sell","size":183.6},{"price":"41.046","symbol":"LINKUSDT","id":"410460","side":"Buy","size":104.9},{"price":"41.047","symbol":"LINKUSDT","id":"410470","side":"Buy","size":396.7},{"price":"41.053","symbol":"LINKUSDT","id":"410530","side":"Buy","size":946.00006},{"price":"41.068","symbol":"LINKUSDT","id":"410680","side":"Sell","size":130.59999},{"price":"41.040","symbol":"LINKUSDT","id":"410400","side":"Buy","size":95.5},{"price":"41.041","symbol":"LINKUSDT","id":"410410","side":"Buy","size":677.60004},{"price":"41.050","symbol":"LINKUSDT","id":"410500","side":"Buy","size":1.3},{"price":"41.039","symbol":"LINKUSDT","id":"410390","side":"Buy","size":309.8},{"price":"41.044","symbol":"LINKUSDT","id":"410440","side":"Buy","size":582.4}],"insert":[{"price":"41.057","symbol":"LINKUSDT","id":"410570","side":"Buy","size":256.7},{"price":"41.064","symbol":"LINKUSDT","id":"410640","side":"Sell","size":287.3},{"price":"41.028","symbol":"LINKUSDT","id":"410280","side":"Buy","size":425.9},{"price":"41.027","symbol":"LINKUSDT","id":"410270","side":"Buy","size":336.8},{"price":"41.055","symbol":"LINKUSDT","id":"410550","side":"Buy","size":36},{"price":"41.054","symbol":"LINKUSDT","id":"410540","side":"Buy","size":580.60004},{"price":"41.026","symbol":"LINKUSDT","id":"410260","side":"Buy","size":144.1},{"price":"41.056","symbol":"LINKUSDT","id":"410560","side":"Buy","size":248.1},{"price":"41.087","symbol":"LINKUSDT","id":"410870","side":"Sell","size":141.5}]},"cross_seq":"1970979233","timestamp_e6":"1618677789424940"}
1618677789.614013: {"topic":"orderBookL2_25.LTCUSDT","type":"delta","data":{"delete":[],"update":[{"price":"313.09","symbol":"LTCUSDT","id":"3130900","side":"Buy","size":364.7}],"insert":[]},"cross_seq":"1684522706","timestamp_e6":"1618677789439035"}
1618677789.614033: {"topic":"orderBookL2_25.LINKUSDT","type":"delta","data":{"delete":[{"price":"41.050","symbol":"LINKUSDT","id":"410500","side":"Buy"}],"update":[{"price":"41.040","symbol":"LINKUSDT","id":"410400","side":"Buy","size":181.8},{"price":"41.036","symbol":"LINKUSDT","id":"410360","side":"Buy","size":525.1},{"price":"41.039","symbol":"LINKUSDT","id":"410390","side":"Buy","size":392.4},{"price":"41.068","symbol":"LINKUSDT","id":"410680","side":"Sell","size":221.7},{"price":"41.069","symbol":"LINKUSDT","id":"410690","side":"Sell","size":239.70001},{"price":"41.041","symbol":"LINKUSDT","id":"410410","side":"Buy","size":752.39996},{"price":"41.030","symbol":"LINKUSDT","id":"410300","side":"Buy","size":113.6},{"price":"41.070","symbol":"LINKUSDT","id":"410700","side":"Sell","size":195.8},{"price":"41.046","symbol":"LINKUSDT","id":"410460","side":"Buy","size":103.600006},{"price":"41.058","symbol":"LINKUSDT","id":"410580","side":"Sell","size":66},{"price":"41.066","symbol":"LINKUSDT","id":"410660","side":"Sell","size":410.69998},{"price":"41.065","symbol":"LINKUSDT","id":"410650","side":"Sell","size":506.6},{"price":"41.067","symbol":"LINKUSDT","id":"410670","side":"Sell","size":309.4},{"price":"41.038","symbol":"LINKUSDT","id":"410380","side":"Buy","size":173.7},{"price":"41.053","symbol":"LINKUSDT","id":"410530","side":"Buy","size":40},{"price":"41.037","symbol":"LINKUSDT","id":"410370","side":"Buy","size":312.80002},{"price":"41.057","symbol":"LINKUSDT","id":"410570","side":"Buy","size":662.7}],"insert":[{"price":"41.025","symbol":"LINKUSDT","id":"410250","side":"Buy","size":322.30002}]},"cross_seq":"1970979266","timestamp_e6":"1618677789445241"}
1618677789.61411: {"topic":"orderBookL2_25.LTCUSDT","type":"delta","data":{"delete":[{"price":"313.15","symbol":"LTCUSDT","id":"3131500","side":"Sell"},{"price":"313.23","symbol":"LTCUSDT","id":"3132300","side":"Sell"},{"price":"313.14","symbol":"LTCUSDT","id":"3131400","side":"Sell"},{"price":"313.16","symbol":"LTCUSDT","id":"3131600","side":"Sell"}],"update":[{"price":"313.18","symbol":"LTCUSDT","id":"3131800","side":"Sell","size":115.899994},{"price":"313.19","symbol":"LTCUSDT","id":"3131900","side":"Sell","size":88.399994},{"price":"313.10","symbol":"LTCUSDT","id":"3131000","side":"Sell","size":2.1},{"price":"313.06","symbol":"LTCUSDT","id":"3130600","side":"Buy","size":79.1},{"price":"313.04","symbol":"LTCUSDT","id":"3130400","side":"Buy","size":51.9},{"price":"313.17","symbol":"LTCUSDT","id":"3131700","side":"Sell","size":1.5}],"insert":[{"price":"313.41","symbol":"LTCUSDT","id":"3134100","side":"Sell","size":132.2},{"price":"313.40","symbol":"LTCUSDT","id":"3134000","side":"Sell","size":104.100006},{"price":"313.20","symbol":"LTCUSDT","id":"3132000","side":"Sell","size":67.299995},{"price":"313.39","symbol":"LTCUSDT","id":"3133900","side":"Sell","size":229.40001}]},"cross_seq":"1684522718","timestamp_e6":"1618677789459295"}
1618677789.614181: {"topic":"orderBookL2_25.ADAUSDT","type":"delta","data":{"delete":[{"price":"1.3847","symbol":"ADAUSDT","id":"13847","side":"Buy"}],"update":[{"price":"1.3867","symbol":"ADAUSDT","id":"13867","side":"Buy","size":2001},{"price":"1.3857","symbol":"ADAUSDT","id":"13857","side":"Buy","size":3961.9998},{"price":"1.3878","symbol":"ADAUSDT","id":"13878","side":"Sell","size":5313},{"price":"1.3880","symbol":"ADAUSDT","id":"13880","side":"Sell","size":3280.0002},{"price":"1.3862","symbol":"ADAUSDT","id":"13862","side":"Buy","size":3480},{"price":"1.3851","symbol":"ADAUSDT","id":"13851","side":"Buy","size":3722.0002},{"price":"1.3858","symbol":"ADAUSDT","id":"13858","side":"Buy","size":5410},{"price":"1.3877","symbol":"ADAUSDT","id":"13877","side":"Sell","size":1326},{"price":"1.3860","symbol":"ADAUSDT","id":"13860","side":"Buy","size":3873},{"price":"1.3859","symbol":"ADAUSDT","id":"13859","side":"Buy","size":5961}],"insert":[{"price":"1.3861","symbol":"ADAUSDT","id":"13861","side":"Buy","size":4138}]},"cross_seq":"916953828","timestamp_e6":"1618677789462374"}
1618677789.614239: {"topic":"orderBookL2_25.LINKUSDT","type":"delta","data":{"delete":[{"price":"41.030","symbol":"LINKUSDT","id":"410300","side":"Buy"},{"price":"41.027","symbol":"LINKUSDT","id":"410270","side":"Buy"},{"price":"41.064","symbol":"LINKUSDT","id":"410640","side":"Sell"},{"price":"41.032","symbol":"LINKUSDT","id":"410320","side":"Buy"},{"price":"41.029","symbol":"LINKUSDT","id":"410290","side":"Buy"},{"price":"41.031","symbol":"LINKUSDT","id":"410310","side":"Buy"},{"price":"41.028","symbol":"LINKUSDT","id":"410280","side":"Buy"},{"price":"41.087","symbol":"LINKUSDT","id":"410870","side":"Sell"},{"price":"41.025","symbol":"LINKUSDT","id":"410250","side":"Buy"},{"price":"41.026","symbol":"LINKUSDT","id":"410260","side":"Buy"}],"update":[{"price":"41.065","symbol":"LINKUSDT","id":"410650","side":"Sell","size":280.2},{"price":"41.057","symbol":"LINKUSDT","id":"410570","side":"Buy","size":408.00003},{"price":"41.053","symbol":"LINKUSDT","id":"410530","side":"Buy","size":296.7},{"price":"41.055","symbol":"LINKUSDT","id":"410550","side":"Buy","size":377.19998},{"price":"41.066","symbol":"LINKUSDT","id":"410660","side":"Sell","size":208.6},{"price":"41.056","symbol":"LINKUSDT","id":"410560","side":"Buy","size":340},{"price":"41.054","symbol":"LINKUSDT","id":"410540","side":"Buy","size":364.4},{"price":"41.040","symbol":"LINKUSDT","id":"410400","side":"Buy","size":213.6}],"insert":[{"price":"41.045","symbol":"LINKUSDT","id":"410450","side":"Buy","size":50.899998},{"price":"41.062","symbol":"LINKUSDT","id":"410620","side":"Sell","size":287.3},{"price":"41.052","symbol":"LINKUSDT","id":"410520","side":"Buy","size":248.1},{"price":"41.049","symbol":"LINKUSDT","id":"410490","side":"Buy","size":144.3},{"price":"41.063","symbol":"LINKUSDT","id":"410630","side":"Sell","size":226.40001},{"price":"41.051","symbol":"LINKUSDT","id":"410510","side":"Buy","size":24},{"price":"41.043","symbol":"LINKUSDT","id":"410430","side":"Buy","size":2.7},{"price":"41.042","symbol":"LINKUSDT","id":"410420","side":"Buy","size":70.9},{"price":"41.050","symbol":"LINKUSDT","id":"410500","side":"Buy","size":74.6},{"price":"41.048","symbol":"LINKUSDT","id":"410480","side":"Buy","size":83}]},"cross_seq":"1970979306","timestamp_e6":"1618677789464932"}
1618677789.614363: {"topic":"orderBookL2_25.LTCUSDT","type":"delta","data":{"delete":[],"update":[{"price":"313.09","symbol":"LTCUSDT","id":"3130900","side":"Buy","size":489.69998}],"insert":[]},"cross_seq":"1684522727","timestamp_e6":"1618677789479021"}
1618677789.614381: {"topic":"orderBookL2_25.LINKUSDT","type":"delta","data":{"delete":[],"update":[{"price":"41.053","symbol":"LINKUSDT","id":"410530","side":"Buy","size":256.7}],"insert":[]},"cross_seq":"1970979307","timestamp_e6":"1618677789483725"}
1618677789.6143968: {"topic":"orderBookL2_25.ETHUSDT","type":"delta","data":{"delete":[],"update":[{"price":"2363.55","symbol":"ETHUSDT","id":"23635500","side":"Buy","size":2.51}],"insert":[]},"cross_seq":"1800546408","timestamp_e6":"1618677789487494"}
1618677789.614412: {"topic":"orderBookL2_25.BCHUSDT","type":"delta","data":{"delete":[{"price":"1056.10","symbol":"BCHUSDT","id":"10561000","side":"Sell"}],"update":[{"price":"1054.95","symbol":"BCHUSDT","id":"10549500","side":"Sell","size":9.04},{"price":"1055.05","symbol":"BCHUSDT","id":"10550500","side":"Sell","size":8.34},{"price":"1055.00","symbol":"BCHUSDT","id":"10550000","side":"Sell","size":8.37}],"insert":[{"price":"1055.10","symbol":"BCHUSDT","id":"10551000","side":"Sell","size":4.72}]},"cross_seq":"864132343","timestamp_e6":"1618677789488707"}
1618677789.6144462: {"topic":"orderBookL2_25.ADAUSDT","type":"delta","data":{"delete":[{"price":"1.3862","symbol":"ADAUSDT","id":"13862","side":"Buy"},{"price":"1.3861","symbol":"ADAUSDT","id":"13861","side":"Buy"}],"update":[{"price":"1.3866","symbol":"ADAUSDT","id":"13866","side":"Buy","size":4917},{"price":"1.3878","symbol":"ADAUSDT","id":"13878","side":"Sell","size":7787},{"price":"1.3865","symbol":"ADAUSDT","id":"13865","side":"Buy","size":4139},{"price":"1.3863","symbol":"ADAUSDT","id":"13863","side":"Buy","size":5503.0005},{"price":"1.3864","symbol":"ADAUSDT","id":"13864","side":"Buy","size":8734},{"price":"1.3877","symbol":"ADAUSDT","id":"13877","side":"Sell","size":2291}],"insert":[{"price":"1.3847","symbol":"ADAUSDT","id":"13847","side":"Buy","size":4462},{"price":"1.3846","symbol":"ADAUSDT","id":"13846","side":"Buy","size":1015}]},"cross_seq":"916953856","timestamp_e6":"1618677789502394"}
1618677789.614497: {"topic":"orderBookL2_25.BCHUSDT","type":"delta","data":{"delete":[{"price":"1054.85","symbol":"BCHUSDT","id":"10548500","side":"Sell"}],"update":[{"price":"1055.05","symbol":"BCHUSDT","id":"10550500","side":"Sell","size":5.49},{"price":"1055.15","symbol":"BCHUSDT","id":"10551500","side":"Sell","size":6.13}],"insert":[{"price":"1054.90","symbol":"BCHUSDT","id":"10549000","side":"Sell","size":14.14}]},"cross_seq":"864132347","timestamp_e6":"1618677789508743"}
1618677789.614527: {"topic":"orderBookL2_25.XTZUSDT","type":"delta","data":{"delete":[],"update":[{"price":"7.211","symbol":"XTZUSDT","id":"72110","side":"Buy","size":4600.6}],"insert":[]},"cross_seq":"726228283","timestamp_e6":"1618677789515444"}
1618677789.614544: {"topic":"orderBookL2_25.DOTUSDT","type":"delta","data":{"delete":[],"update":[{"price":"43.575","symbol":"DOTUSDT","id":"435750","side":"Sell","size":247},{"price":"43.500","symbol":"DOTUSDT","id":"435000","side":"Buy","size":163},{"price":"43.550","symbol":"DOTUSDT","id":"435500","side":"Sell","size":844.39996}],"insert":[]},"cross_seq":"916953875","timestamp_e6":"1618677789522777"}
1618677789.6145658: {"topic":"orderBookL2_25.ETHUSDT","type":"delta","data":{"delete":[],"update":[{"price":"2364.95","symbol":"ETHUSDT","id":"23649500","side":"Sell","size":372.03}],"insert":[]},"cross_seq":"1800546409","timestamp_e6":"1618677789527498"}
1618677789.614978: {"topic":"orderBookL2_25.BCHUSDT","type":"delta","data":{"delete":[],"update":[{"price":"1055.50","symbol":"BCHUSDT","id":"10555000","side":"Sell","size":7.07},{"price":"1054.75","symbol":"BCHUSDT","id":"10547500","side":"Sell","size":35.37},{"price":"1055.35","symbol":"BCHUSDT","id":"10553500","side":"Sell","size":12.53}],"insert":[]},"cross_seq":"864132350","timestamp_e6":"1618677789530479"}
1618677789.623308: {"topic":"orderBookL2_25.LTCUSDT","type":"delta","data":{"delete":[],"update":[{"price":"313.30","symbol":"LTCUSDT","id":"3133000","side":"Sell","size":52.5},{"price":"313.29","symbol":"LTCUSDT","id":"3132900","side":"Sell","size":177.9},{"price":"313.27","symbol":"LTCUSDT","id":"3132700","side":"Sell","size":121.799995}],"insert":[]},"cross_seq":"1684522733","timestamp_e6":"1618677789539547"}
1618677789.6480541: {"topic":"orderBookL2_25.UNIUSDT","type":"delta","data":{"delete":[{"price":"35.380","symbol":"UNIUSDT","id":"353800","side":"Buy"},{"price":"35.383","symbol":"UNIUSDT","id":"353830","side":"Buy"}],"update":[{"price":"35.381","symbol":"UNIUSDT","id":"353810","side":"Buy","size":33.2},{"price":"35.382","symbol":"UNIUSDT","id":"353820","side":"Buy","size":52.5}],"insert":[{"price":"35.361","symbol":"UNIUSDT","id":"353610","side":"Buy","size":11.4},{"price":"35.360","symbol":"UNIUSDT","id":"353600","side":"Buy","size":20.5}]},"cross_seq":"916953880","timestamp_e6":"1618677789562492"}
1618677789.648171: {"topic":"orderBookL2_25.LINKUSDT","type":"delta","data":{"delete":[],"update":[{"price":"41.057","symbol":"LINKUSDT","id":"410570","side":"Buy","size":402}],"insert":[]},"cross_seq":"1970979309","timestamp_e6":"1618677789564832"}
1618677789.798312: {"topic":"orderBookL2_25.UNIUSDT","type":"delta","data":{"delete":[],"update":[{"price":"35.364","symbol":"UNIUSDT","id":"353640","side":"Buy","size":53.5},{"price":"35.411","symbol":"UNIUSDT","id":"354110","side":"Sell","size":39},{"price":"35.410","symbol":"UNIUSDT","id":"354100","side":"Sell","size":88.9},{"price":"35.365","symbol":"UNIUSDT","id":"353650","side":"Buy","size":37.6},{"price":"35.368","symbol":"UNIUSDT","id":"353680","side":"Buy","size":61.699997}],"insert":[]},"cross_seq":"916953886","timestamp_e6":"1618677789582314"}
1618677789.798351: {"topic":"orderBookL2_25.LINKUSDT","type":"delta","data":{"delete":[{"price":"41.044","symbol":"LINKUSDT","id":"410440","side":"Buy"},{"price":"41.062","symbol":"LINKUSDT","id":"410620","side":"Sell"},{"price":"41.086","symbol":"LINKUSDT","id":"410860","side":"Sell"},{"price":"41.063","symbol":"LINKUSDT","id":"410630","side":"Sell"},{"price":"41.048","symbol":"LINKUSDT","id":"410480","side":"Buy"},{"price":"41.085","symbol":"LINKUSDT","id":"410850","side":"Sell"}],"update":[{"price":"41.065","symbol":"LINKUSDT","id":"410650","side":"Sell","size":438.1},{"price":"41.043","symbol":"LINKUSDT","id":"410430","side":"Buy","size":248.1},{"price":"41.068","symbol":"LINKUSDT","id":"410680","side":"Sell","size":510.8},{"price":"41.035","symbol":"LINKUSDT","id":"410350","side":"Buy","size":62.5},{"price":"41.036","symbol":"LINKUSDT","id":"410360","side":"Buy","size":575.7},{"price":"41.066","symbol":"LINKUSDT","id":"410660","side":"Sell","size":629.60004},{"price":"41.037","symbol":"LINKUSDT","id":"410370","side":"Buy","size":410.6},{"price":"41.045","symbol":"LINKUSDT","id":"410450","side":"Buy","size":364.4},{"price":"41.046","symbol":"LINKUSDT","id":"410460","side":"Buy","size":377.19998},{"price":"41.067","symbol":"LINKUSDT","id":"410670","side":"Sell","size":227.7},{"price":"41.069","symbol":"LINKUSDT","id":"410690","side":"Sell","size":148.40001},{"price":"41.039","symbol":"LINKUSDT","id":"410390","side":"Buy","size":303.4}],"insert":[{"price":"41.031","symbol":"LINKUSDT","id":"410310","side":"Buy","size":22.8},{"price":"41.064","symbol":"LINKUSDT","id":"410640","side":"Sell","size":91.3},{"price":"41.059","symbol":"LINKUSDT","id":"410590","side":"Sell","size":287.3},{"price":"41.060","symbol":"LINKUSDT","id":"410600","side":"Sell","size":226.40001},{"price":"41.032","symbol":"LINKUSDT","id":"410320","side":"Buy","size":399.40002},{"price":"41.061","symbol":"LINKUSDT","id":"410610","side":"Sell","size":202.1}]},"cross_seq":"1970979350","timestamp_e6":"1618677789584374"}
1618677789.798472: {"topic":"orderBookL2_25.ETHUSDT","type":"delta","data":{"delete":[{"price":"2363.20","symbol":"ETHUSDT","id":"23632000","side":"Buy"},{"price":"2363.30","symbol":"ETHUSDT","id":"23633000","side":"Buy"},{"price":"2363.25","symbol":"ETHUSDT","id":"23632500","side":"Buy"},{"price":"2363.35","symbol":"ETHUSDT","id":"23633500","side":"Buy"}],"update":[{"price":"2365.20","symbol":"ETHUSDT","id":"23652000","side":"Sell","size":54.940002},{"price":"2364.35","symbol":"ETHUSDT","id":"23643500","side":"Buy","size":37.44}],"insert":[{"price":"2364.40","symbol":"ETHUSDT","id":"23644000","side":"Buy","size":48.690002},{"price":"2364.20","symbol":"ETHUSDT","id":"23642000","side":"Buy","size":17.369999},{"price":"2364.30","symbol":"ETHUSDT","id":"23643000","side":"Buy","size":32.95},{"price":"2364.25","symbol":"ETHUSDT","id":"23642500","side":"Buy","size":28.550001}]},"cross_seq":"1800546416","timestamp_e6":"1618677789587256"}
