1618677792.5394812: {"topic":"orderBookL2_25.XTZUSDT","type":"delta","data":{"delete":[{"price":"7.185","symbol":"XTZUSDT","id":"71850","side":"Buy"}],"update":[{"price":"7.206","symbol":"XTZUSDT","id":"72060","side":"Buy","size":1189},{"price":"7.209","symbol":"XTZUSDT","id":"72090","side":"Buy","size":2029.5},{"price":"7.208","symbol":"XTZUSDT","id":"72080","side":"Buy","size":1673.7},{"price":"7.219","symbol":"XTZUSDT","id":"72190","side":"Sell","size":1580.3},{"price":"7.215","symbol":"XTZUSDT","id":"72150","side":"Sell","size":1194.8},{"price":"7.204","symbol":"XTZUSDT","id":"72040","side":"Buy","size":932.89996}],"insert":[{"price":"7.207","symbol":"XTZUSDT","id":"72070","side":"Buy","size":786.5}]},"cross_seq":"726228512","timestamp_e6":"1618677792454977"}
1618677792.5401149: {"topic":"orderBookL2_25.LTCUSDT","type":"delta","data":{"delete":[],"update":[{"price":"313.43","symbol":"LTCUSDT","id":"3134300","side":"Sell","size":87.3},{"price":"313.47","symbol":"LTCUSDT","id":"3134700","side":"Sell","size":95.600006},{"price":"313.42","symbol":"LTCUSDT","id":"3134200","side":"Sell","size":125.2},{"price":"313.49","symbol":"LTCUSDT","id":"3134900","side":"Sell","size":30.2},{"price":"313.44","symbol":"LTCUSDT","id":"3134400","side":"Sell","size":191},{"price":"313.46","symbol":"LTCUSDT","id":"3134600","side":"Sell","size":64}],"insert":[]},"cross_seq":"1684523364","timestamp_e6":"1618677792457867"}
1618677792.54689: {"topic":"orderBookL2_25.ADAUSDT","type":"delta","data":{"delete":[],"update":[{"price":"1.3881","symbol":"ADAUSDT","id":"13881","side":"Sell","size":3666},{"price":"1.3878","symbol":"ADAUSDT","id":"13878","side":"Sell","size":8987},{"price":"1.3877","symbol":"ADAUSDT","id":"13877","side":"Sell","size":2301},{"price":"1.3880","symbol":"ADAUSDT","id":"13880","side":"Sell","size":4114},{"price":"1.3879","symbol":"ADAUSDT","id":"13879","side":"Sell","size":6476},{"price":"1.3865","symbol":"ADAUSDT","id":"13865","side":"Buy","size":3407}],"insert":[]},"cross_seq":"916954473","timestamp_e6":"1618677792462344"}
1618677792.5542989: {"topic":"orderBookL2_25.BCHUSDT","type":"delta","data":{"delete":[{"price":"1056.45","symbol":"BCHUSDT","id":"10564500","side":"Sell"},{"price":"1053.60","symbol":"BCHUSDT","id":"10536000","side":"Buy"},{"price":"1056.50","symbol":"BCHUSDT","id":"10565000","side":"Sell"},{"price":"1054.65","symbol":"BCHUSDT","id":"10546500","side":"Buy"}],"update":[{"price":"1054.75","symbol":"BCHUSDT","id":"10547500","side":"Buy","size":7.31},{"price":"1054.50","symbol":"BCHUSDT","id":"10545000","side":"Buy","size":4.86},{"price":"1055.35","symbol":"BCHUSDT","id":"10553500","side":"Sell","size":3.67}],"insert":[{"price":"1054.55","symbol":"BCHUSDT","id":"10545500","side":"Buy","size":19.78},{"price":"1055.25","symbol":"BCHUSDT","id":"10552500","side":"Sell","size":9.37},{"price":"1055.45","symbol":"BCHUSDT","id":"10554500","side":"Sell","size":2.41},{"price":"1054.85","symbol":"BCHUSDT","id":"10548500","side":"Buy","size":13.31}]},"cross_seq":"864132895","timestamp_e6":"1618677792468686"}
1618677792.564041: {"topic":"orderBookL2_25.LTCUSDT","type":"delta","data":{"delete":[],"update":[{"price":"313.34","symbol":"LTCUSDT","id":"3133400","side":"Buy","size":358.4}],"insert":[]},"cross_seq":"1684523365","timestamp_e6":"1618677792480209"}
1618677792.574517: {"topic":"orderBookL2_25.BCHUSDT","type":"delta","data":{"delete":[{"price":"1054.95","symbol":"BCHUSDT","id":"10549500","side":"Buy"}],"update":[{"price":"1054.30","symbol":"BCHUSDT","id":"10543000","side":"Buy","size":9.48},{"price":"1054.25","symbol":"BCHUSDT","id":"10542500","side":"Buy","size":22.220001},{"price":"1054.45","symbol":"BCHUSDT","id":"10544500","side":"Buy","size":19.41},{"price":"1054.50","symbol":"BCHUSDT","id":"10545000","side":"Buy","size":22.07},{"price":"1054.40","symbol":"BCHUSDT","id":"10544000","side":"Buy","size":3.53},{"price":"1054.35","symbol":"BCHUSDT","id":"10543500","side":"Buy","size":2.22}],"insert":[{"price":"1053.60","symbol":"BCHUSDT","id":"10536000","side":"Buy","size":4.35}]},"cross_seq":"864132904","timestamp_e6":"1618677792489968"}
1618677792.5862741: {"topic":"orderBookL2_25.ADAUSDT","type":"delta","data":{"delete":[],"update":[{"price":"1.3881","symbol":"ADAUSDT","id":"13881","side":"Sell","size":2887},{"price":"1.3879","symbol":"ADAUSDT","id":"13879","side":"Sell","size":4764},{"price":"1.3880","symbol":"ADAUSDT","id":"13880","side":"Sell","size":3061.9998},{"price":"1.3878","symbol":"ADAUSDT","id":"13878","side":"Sell","size":10236}],"insert":[]},"cross_seq":"916954478","timestamp_e6":"1618677792502352"}
1618677792.594388: {"topic":"orderBookL2_25.BCHUSDT","type":"delta","data":{"delete":[{"price":"1055.40","symbol":"BCHUSDT","id":"10554000","side":"Sell"},{"price":"1055.20","symbol":"BCHUSDT","id":"10552000","side":"Sell"},{"price":"1055.30","symbol":"BCHUSDT","id":"10553000","side":"Sell"},{"price":"1054.80","symbol":"BCHUSDT","id":"10548000","side":"Buy"},{"price":"1055.25","symbol":"BCHUSDT","id":"10552500","side":"Sell"}],"update":[{"price":"1054.75","symbol":"BCHUSDT","id":"10547500","side":"Buy","size":12.14},{"price":"1055.35","symbol":"BCHUSDT","id":"10553500","side":"Sell","size":5.89}],"insert":[{"price":"1056.55","symbol":"BCHUSDT","id":"10565500","side":"Sell","size":10.5},{"price":"1054.65","symbol":"BCHUSDT","id":"10546500","side":"Buy","size":9.4},{"price":"1055.15","symbol":"BCHUSDT","id":"10551500","side":"Sell","size":11.54},{"price":"1056.50","symbol":"BCHUSDT","id":"10565000","side":"Sell","size":30.32},{"price":"1056.45","symbol":"BCHUSDT","id":"10564500","side":"Sell","size":16.609999}]},"cross_seq":"864132921","timestamp_e6":"1618677792509593"}
1618677792.627512: {"topic":"orderBookL2_25.LINKUSDT","type":"delta","data":{"delete":[{"price":"41.071","symbol":"LINKUSDT","id":"410710","side":"Sell"}],"update":[{"price":"41.033","symbol":"LINKUSDT","id":"410330","side":"Buy","size":1067.7},{"price":"41.029","symbol":"LINKUSDT","id":"410290","side":"Buy","size":144},{"price":"41.065","symbol":"LINKUSDT","id":"410650","side":"Sell","size":305},{"price":"41.069","symbol":"LINKUSDT","id":"410690","side":"Sell","size":39.3},{"price":"41.068","symbol":"LINKUSDT","id":"410680","side":"Sell","size":348.8},{"price":"41.031","symbol":"LINKUSDT","id":"410310","side":"Buy","size":50.6},{"price":"41.030","symbol":"LINKUSDT","id":"410300","side":"Buy","size":113.299995},{"price":"41.066","symbol":"LINKUSDT","id":"410660","side":"Sell","size":559.7},{"price":"41.067","symbol":"LINKUSDT","id":"410670","side":"Sell","size":15.5}],"insert":[{"price":"41.047","symbol":"LINKUSDT","id":"410470","side":"Sell","size":243.90001}]},"cross_seq":"1970980091","timestamp_e6":"1618677792543762"}
1618677792.627604: {"topic":"orderBookL2_25.DOTUSDT","type":"delta","data":{"delete":[],"update":[{"price":"43.510","symbol":"DOTUSDT","id":"435100","side":"Buy","size":339.4},{"price":"43.565","symbol":"DOTUSDT","id":"435650","side":"Sell","size":334.19998},{"price":"43.570","symbol":"DOTUSDT","id":"435700","side":"Sell","size":196.40001}],"insert":[]},"cross_seq":"916954481","timestamp_e6":"1618677792543636"}
1618677792.633972: {"topic":"orderBookL2_25.BCHUSDT","type":"delta","data":{"delete":[{"price":"1056.50","symbol":"BCHUSDT","id":"10565000","side":"Sell"},{"price":"1054.55","symbol":"BCHUSDT","id":"10545500","side":"Buy"},{"price":"1056.55","symbol":"BCHUSDT","id":"10565500","side":"Sell"},{"price":"1054.85","symbol":"BCHUSDT","id":"10548500","side":"Buy"},{"price":"1056.45","symbol":"BCHUSDT","id":"10564500","side":"Sell"},{"price":"1055.15","symbol":"BCHUSDT","id":"10551500","side":"Sell"}],"update":[{"price":"1055.35","symbol":"BCHUSDT","id":"10553500","side":"Sell","size":2.22}],"insert":[{"price":"1055.20","symbol":"BCHUSDT","id":"10552000","side":"Sell","size":7.36},{"price":"1054.80","symbol":"BCHUSDT","id":"10548000","side":"Buy","size":13.31},{"price":"1053.55","symbol":"BCHUSDT","id":"10535500","side":"Buy","size":9.9},{"price":"1055.10","symbol":"BCHUSDT","id":"10551000","side":"Sell","size":11.54},{"price":"1055.25","symbol":"BCHUSDT","id":"10552500","side":"Sell","size":3.67},{"price":"1055.30","symbol":"BCHUSDT","id":"10553000","side":"Sell","size":5.89}]},"cross_seq":"864132932","timestamp_e6":"1618677792549927"}
1618677792.6417239: {"topic":"orderBookL2_25.LTCUSDT","type":"delta","data":{"delete":[],"update":[{"price":"313.47","symbol":"LTCUSDT","id":"3134700","side":"Sell","size":122.4},{"price":"313.48","symbol":"LTCUSDT","id":"3134800","side":"Sell","size":66.5},{"price":"313.46","symbol":"LTCUSDT","id":"3134600","side":"Sell","size":108.2},{"price":"313.49","symbol":"LTCUSDT","id":"3134900","side":"Sell","size":79.6}],"insert":[]},"cross_seq":"1684523383","timestamp_e6":"1618677792557966"}
1618677792.6682508: {"topic":"orderBookL2_25.LINKUSDT","type":"delta","data":{"delete":[],"update":[{"price":"41.045","symbol":"LINKUSDT","id":"410450","side":"Buy","size":1006.39996}],"insert":[]},"cross_seq":"1970980092","timestamp_e6":"1618677792584883"}
1618677792.681036: {"topic":"orderBookL2_25.LTCUSDT","type":"delta","data":{"delete":[],"update":[{"price":"313.46","symbol":"LTCUSDT","id":"3134600","side":"Sell","size":136.5},{"price":"313.43","symbol":"LTCUSDT","id":"3134300","side":"Sell","size":37.8},{"price":"313.47","symbol":"LTCUSDT","id":"3134700","side":"Sell","size":103.5},{"price":"313.44","symbol":"LTCUSDT","id":"3134400","side":"Sell","size":213.2},{"price":"313.48","symbol":"LTCUSDT","id":"3134800","side":"Sell","size":76.600006}],"insert":[]},"cross_seq":"1684523392","timestamp_e6":"1618677792597914"}
1618677792.694454: {"topic":"orderBookL2_25.BCHUSDT","type":"delta","data":{"delete":[{"price":"1055.30","symbol":"BCHUSDT","id":"10553000","side":"Sell"},{"price":"1053.55","symbol":"BCHUSDT","id":"10535500","side":"Buy"}],"update":[{"price":"1054.50","symbol":"BCHUSDT","id":"10545000","side":"Buy","size":4.86},{"price":"1054.40","symbol":"BCHUSDT","id":"10544000","side":"Buy","size":14.88},{"price":"1054.35","symbol":"BCHUSDT","id":"10543500","side":"Buy","size":10.23},{"price":"1055.25","symbol":"BCHUSDT","id":"10552500","side":"Sell","size":7.36},{"price":"1055.35","symbol":"BCHUSDT","id":"10553500","side":"Sell","size":5.89},{"price":"1055.20","symbol":"BCHUSDT","id":"10552000","side":"Sell","size":9.37}],"insert":[{"price":"1054.55","symbol":"BCHUSDT","id":"10545500","side":"Buy","size":21.81},{"price":"1054.95","symbol":"BCHUSDT","id":"10549500","side":"Sell","size":5.37}]},"cross_seq":"864132957","timestamp_e6":"1618677792609943"}
1618677792.701493: {"topic":"orderBookL2_25.LTCUSDT","type":"delta","data":{"delete":[],"update":[{"price":"313.44","symbol":"LTCUSDT","id":"3134400","side":"Sell","size":125.9},{"price":"313.48","symbol":"LTCUSDT","id":"3134800","side":"Sell","size":100.100006},{"price":"313.47","symbol":"LTCUSDT","id":"3134700","side":"Sell","size":129.9},{"price":"313.42","symbol":"LTCUSDT","id":"3134200","side":"Sell","size":0.1},{"price":"313.45","symbol":"LTCUSDT","id":"3134500","side":"Sell","size":120.399994},{"price":"313.49","symbol":"LTCUSDT","id":"3134900","side":"Sell","size":30.2}],"insert":[]},"cross_seq":"1684523409","timestamp_e6":"1618677792618252"}
1618677792.7218208: {"topic":"orderBookL2_25.LTCUSDT","type":"delta","data":{"delete":[{"price":"313.36","symbol":"LTCUSDT","id":"3133600","side":"Sell"}],"update":[{"price":"313.43","symbol":"LTCUSDT","id":"3134300","side":"Sell","size":39.3}],"insert":[{"price":"313.65","symbol":"LTCUSDT","id":"3136500","side":"Sell","size":41.9}]},"cross_seq":"1684523414","timestamp_e6":"1618677792637868"}
1618677792.726938: {"topic":"orderBookL2_25.UNIUSDT","type":"delta","data":{"delete":[{"price":"35.377","symbol":"UNIUSDT","id":"353770","side":"Buy"}],"update":[{"price":"35.378","symbol":"UNIUSDT","id":"353780","side":"Buy","size":48.999996},{"price":"35.402","symbol":"UNIUSDT","id":"354020","side":"Sell","size":294.4},{"price":"35.374","symbol":"UNIUSDT","id":"353740","side":"Buy","size":10.1},{"price":"35.372","symbol":"UNIUSDT","id":"353720","side":"Buy","size":33.699997},{"price":"35.403","symbol":"UNIUSDT","id":"354030","side":"Sell","size":63.800003},{"price":"35.407","symbol":"UNIUSDT","id":"354070","side":"Sell","size":32.8},{"price":"35.406","symbol":"UNIUSDT","id":"354060","side":"Sell","size":46.4},{"price":"35.405","symbol":"UNIUSDT","id":"354050","side":"Sell","size":19.9},{"price":"35.379","symbol":"UNIUSDT","id":"353790","side":"Buy","size":28.6},{"price":"35.373","symbol":"UNIUSDT","id":"353730","side":"Buy","size":35},{"price":"35.375","symbol":"UNIUSDT","id":"353750","side":"Buy","size":33.699997},{"price":"35.404","symbol":"UNIUSDT","id":"354040","side":"Sell","size":67.299995}],"insert":[{"price":"35.357","symbol":"UNIUSDT","id":"353570","side":"Buy","size":37.5}]},"cross_seq":"916954499","timestamp_e6":"1618677792642360"}
1618677792.730644: {"topic":"orderBookL2_25.ETHUSDT","type":"delta","data":{"delete":[{"price":"2364.20","symbol":"ETHUSDT","id":"23642000","side":"Buy"}],"update":[{"price":"2363.90","symbol":"ETHUSDT","id":"23639000","side":"Buy","size":56.31},{"price":"2364.15","symbol":"ETHUSDT","id":"23641500","side":"Buy","size":109.490005},{"price":"2365.15","symbol":"ETHUSDT","id":"23651500","side":"Sell","size":50.22}],"insert":[{"price":"2363.15","symbol":"ETHUSDT","id":"23631500","side":"Buy","size":38.06}]},"cross_seq":"1800546801","timestamp_e6":"1618677792647195"}
1618677792.733283: {"topic":"orderBookL2_25.BCHUSDT","type":"delta","data":{"delete":[],"update":[{"price":"1054.60","symbol":"BCHUSDT","id":"10546000","side":"Buy","size":22.68},{"price":"1054.55","symbol":"BCHUSDT","id":"10545500","side":"Buy","size":4.6},{"price":"1054.45","symbol":"BCHUSDT","id":"10544500","side":"Buy","size":5.11},{"price":"1054.50","symbol":"BCHUSDT","id":"10545000","side":"Buy","size":17.11},{"price":"1054.40","symbol":"BCHUSDT","id":"10544000","side":"Buy","size":3.53}],"insert":[]},"cross_seq":"864132963","timestamp_e6":"1618677792649231"}
1618677792.743616: {"topic":"orderBookL2_25.LTCUSDT","type":"delta","data":{"delete":[{"price":"313.65","symbol":"LTCUSDT","id":"3136500","side":"Sell"}],"update":[{"price":"313.43","symbol":"LTCUSDT","id":"3134300","side":"Sell","size":56.999996},{"price":"313.50","symbol":"LTCUSDT","id":"3135000","side":"Sell","size":72.4},{"price":"313.42","symbol":"LTCUSDT","id":"3134200","side":"Sell","size":87.399994},{"price":"313.44","symbol":"LTCUSDT","id":"3134400","side":"Sell","size":56.199997},{"price":"313.45","symbol":"LTCUSDT","id":"3134500","side":"Sell","size":148.90001},{"price":"313.49","symbol":"LTCUSDT","id":"3134900","side":"Sell","size":58.1}],"insert":[{"price":"313.41","symbol":"LTCUSDT","id":"3134100","side":"Sell","size":125.1}]},"cross_seq":"1684523434","timestamp_e6":"1618677792659340"}
1618677792.746847: {"topic":"orderBookL2_25.DOTUSDT","type":"delta","data":{"delete":[],"update":[{"price":"43.550","symbol":"DOTUSDT","id":"435500","side":"Sell","size":1654.9}],"insert":[]},"cross_seq":"916954500","timestamp_e6":"1618677792662349"}
1618677792.759563: {"topic":"orderBookL2_25.XTZUSDT","type":"delta","data":{"delete":[{"price":"7.186","symbol":"XTZUSDT","id":"71860","side":"Buy"}],"update":[{"price":"7.206","symbol":"XTZUSDT","id":"72060","side":"Buy","size":734.80005},{"price":"7.213","symbol":"XTZUSDT","id":"72130","side":"Sell","size":0.4},{"price":"7.217","symbol":"XTZUSDT","id":"72170","side":"Sell","size":662.4},{"price":"7.209","symbol":"XTZUSDT","id":"72090","side":"Buy","size":1210.2},{"price":"7.216","symbol":"XTZUSDT","id":"72160","side":"Sell","size":2154.9001},{"price":"7.207","symbol":"XTZUSDT","id":"72070","side":"Buy","size":1028.2001},{"price":"7.211","symbol":"XTZUSDT","id":"72110","side":"Buy","size":0.2}],"insert":[{"price":"7.210","symbol":"XTZUSDT","id":"72100","side":"Buy","size":601.89996}]},"cross_seq":"726228520","timestamp_e6":"1618677792675660"}
1618677792.7670982: {"topic":"orderBookL2_25.DOTUSDT","type":"delta","data":{"delete":[{"price":"43.530","symbol":"DOTUSDT","id":"435300","side":"Buy"},{"price":"43.510","symbol":"DOTUSDT","id":"435100","side":"Buy"},{"price":"43.525","symbol":"DOTUSDT","id":"435250","side":"Buy"},{"price":"43.515","symbol":"DOTUSDT","id":"435150","side":"Buy"}],"update":[{"price":"43.555","symbol":"DOTUSDT","id":"435550","side":"Sell","size":735.89996},{"price":"43.485","symbol":"DOTUSDT","id":"434850","side":"Buy","size":54.4},{"price":"43.565","symbol":"DOTUSDT","id":"435650","side":"Sell","size":667.7},{"price":"43.575","symbol":"DOTUSDT","id":"435750","side":"Sell","size":253.09999},{"price":"43.505","symbol":"DOTUSDT","id":"435050","side":"Buy","size":660.60004},{"price":"43.495","symbol":"DOTUSDT","id":"434950","side":"Buy","size":5},{"price":"43.550","symbol":"DOTUSDT","id":"435500","side":"Sell","size":916.39996},{"price":"43.475","symbol":"DOTUSDT","id":"434750","side":"Buy","size":513.9},{"price":"43.540","symbol":"DOTUSDT","id":"435400","side":"Buy","size":464.8},{"price":"43.500","symbol":"DOTUSDT","id":"435000","side":"Buy","size":575.2},{"price":"43.490","symbol":"DOTUSDT","id":"434900","side":"Buy","size":517.10004},{"price":"43.570","symbol":"DOTUSDT","id":"435700","side":"Sell","size":476.5},{"price":"43.520","symbol":"DOTUSDT","id":"435200","side":"Buy","size":169.40001},{"price":"43.480","symbol":"DOTUSDT","id":"434800","side":"Buy","size":361.30002},{"price":"43.545","symbol":"DOTUSDT","id":"435450","side":"Buy","size":782.69995},{"price":"43.580","symbol":"DOTUSDT","id":"435800","side":"Sell","size":232.70001},{"price":"43.560","symbol":"DOTUSDT","id":"435600","side":"Sell","size":591.3}],"insert":[{"price":"43.410","symbol":"DOTUSDT","id":"434100","side":"Buy","size":252.7},{"price":"43.415","symbol":"DOTUSDT","id":"434150","side":"Buy","size":83.7},{"price":"43.535","symbol":"DOTUSDT","id":"435350","side":"Buy","size":525.6},{"price":"43.405","symbol":"DOTUSDT","id":"434050","side":"Buy","size":444.5}]},"cross_seq":"916954563","timestamp_e6":"1618677792682334"}
1618677792.772439: {"topic":"orderBookL2_25.BCHUSDT","type":"delta","data":{"delete":[{"price":"1056.35","symbol":"BCHUSDT","id":"10563500","side":"Sell"},{"price":"1054.75","symbol":"BCHUSDT","id":"10547500","side":"Buy"},{"price":"1055.10","symbol":"BCHUSDT","id":"10551000","side":"Sell"},{"price":"1056.40","symbol":"BCHUSDT","id":"10564000","side":"Sell"}],"update":[{"price":"1054.65","symbol":"BCHUSDT","id":"10546500","side":"Buy","size":23.699999},{"price":"1054.45","symbol":"BCHUSDT","id":"10544500","side":"Buy","size":13.65},{"price":"1054.60","symbol":"BCHUSDT","id":"10546000","side":"Buy","size":9.4},{"price":"1054.50","symbol":"BCHUSDT","id":"10545000","side":"Buy","size":4.86},{"price":"1054.70","symbol":"BCHUSDT","id":"10547000","side":"Buy","size":29.35},{"price":"1054.55","symbol":"BCHUSDT","id":"10545500","side":"Buy","size":15.950001}],"insert":[{"price":"1053.55","symbol":"BCHUSDT","id":"10535500","side":"Buy","size":9.9},{"price":"1055.30","symbol":"BCHUSDT","id":"10553000","side":"Sell","size":3.67},{"price":"1055.40","symbol":"BCHUSDT","id":"10554000","side":"Sell","size":2.41},{"price":"1055.15","symbol":"BCHUSDT","id":"10551500","side":"Sell","size":11.54}]},"cross_seq":"864132979","timestamp_e6":"1618677792688694"}
1618677792.786318: {"topic":"orderBookL2_25.DOTUSDT","type":"delta","data":{"delete":[],"update":[{"price":"43.610","symbol":"DOTUSDT","id":"436100","side":"Sell","size":344.19998}],"insert":[]},"cross_seq":"916954564","timestamp_e6":"1618677792702346"}
1618677792.7928052: {"topic":"orderBookL2_25.BCHUSDT","type":"delta","data":{"delete":[{"price":"1053.55","symbol":"BCHUSDT","id":"10535500","side":"Buy"}],"update":[{"price":"1054.70","symbol":"BCHUSDT","id":"10547000","side":"Buy","size":26.019999},{"price":"1054.60","symbol":"BCHUSDT","id":"10546000","side":"Buy","size":3.93}],"insert":[{"price":"1054.75","symbol":"BCHUSDT","id":"10547500","side":"Buy","size":12.14}]},"cross_seq":"864132982","timestamp_e6":"1618677792708680"}
1618677792.80724: {"topic":"orderBookL2_25.DOTUSDT","type":"delta","data":{"delete":[],"update":[{"price":"43.545","symbol":"DOTUSDT","id":"435450","side":"Buy","size":882.69995}],"insert":[]},"cross_seq":"916954566","timestamp_e6":"1618677792722275"}
1618677792.828083: {"topic":"orderBookL2_25.DOTUSDT","type":"delta","data":{"delete":[],"update":[{"price":"43.545","symbol":"DOTUSDT","id":"435450","side":"Buy","size":782.69995}],"insert":[]},"cross_seq":"916954567","timestamp_e6":"1618677792742333"}
1618677792.833914: {"topic":"orderBookL2_25.BCHUSDT","type":"delta","data":{"delete":[{"price":"1054.75","symbol":"BCHUSDT","id":"10547500","side":"Buy"}],"update":[{"price":"1054.65","symbol":"BCHUSDT","id":"10546500","side":"Buy","size":14.3}],"insert":[{"price":"1054.85","symbol":"BCHUSDT","id":"10548500","side":"Buy","size":13.31}]},"cross_seq":"864132986","timestamp_e6":"1618677792749886"}
1618677792.842738: {"topic":"orderBookL2_25.LTCUSDT","type":"delta","data":{"delete":[],"update":[{"price":"313.49","symbol":"LTCUSDT","id":"3134900","side":"Sell","size":122.8},{"price":"313.51","symbol":"LTCUSDT","id":"3135100","side":"Sell","size":154.5},{"price":"313.50","symbol":"LTCUSDT","id":"3135000","side":"Sell","size":249.9},{"price":"313.53","symbol":"LTCUSDT","id":"3135300","side":"Sell","size":68.700005},{"price":"313.52","symbol":"LTCUSDT","id":"3135200","side":"Sell","size":136.5},{"price":"313.35","symbol":"LTCUSDT","id":"3133500","side":"Sell","size":1.5}],"insert":[]},"cross_seq":"1684523468","timestamp_e6":"1618677792759067"}
1618677792.8471081: {"topic":"orderBookL2_25.DOTUSDT","type":"delta","data":{"delete":[],"update":[{"price":"43.540","symbol":"DOTUSDT","id":"435400","side":"Buy","size":454.80002},{"price":"43.545","symbol":"DOTUSDT","id":"435450","side":"Buy","size":792.7}],"insert":[]},"cross_seq":"916954570","timestamp_e6":"1618677792762683"}
1618677792.847148: {"topic":"orderBookL2_25.ADAUSDT","type":"delta","data":{"delete":[],"update":[{"price":"1.3881","symbol":"ADAUSDT","id":"13881","side":"Sell","size":3327},{"price":"1.3880","symbol":"ADAUSDT","id":"13880","side":"Sell","size":3742.9998}],"insert":[]},"cross_seq":"916954570","timestamp_e6":"1618677792762390"}
1618677792.868327: {"topic":"orderBookL2_25.DOTUSDT","type":"delta","data":{"delete":[{"price":"43.405","symbol":"DOTUSDT","id":"434050","side":"Buy"},{"price":"43.535","symbol":"DOTUSDT","id":"435350","side":"Buy"},{"price":"43.410","symbol":"DOTUSDT","id":"434100","side":"Buy"}],"update":[{"price":"43.520","symbol":"DOTUSDT","id":"435200","side":"Buy","size":472.6},{"price":"43.560","symbol":"DOTUSDT","id":"435600","side":"Sell","size":1073.7999},{"price":"43.555","symbol":"DOTUSDT","id":"435550","side":"Sell","size":361.6},{"price":"43.550","symbol":"DOTUSDT","id":"435500","side":"Sell","size":418.40002},{"price":"43.585","symbol":"DOTUSDT","id":"435850","side":"Sell","size":165.9}],"insert":[{"price":"43.530","symbol":"DOTUSDT","id":"435300","side":"Buy","size":454.80002},{"price":"43.525","symbol":"DOTUSDT","id":"435250","side":"Buy","size":525.6},{"price":"43.515","symbol":"DOTUSDT","id":"435150","side":"Buy","size":339.4}]},"cross_seq":"916954594","timestamp_e6":"1618677792782418"}
1618677792.8773792: {"topic":"orderBookL2_25.BCHUSDT","type":"delta","data":{"delete":[{"price":"1053.65","symbol":"BCHUSDT","id":"10536500","side":"Buy"},{"price":"1053.60","symbol":"BCHUSDT","id":"10536000","side":"Buy"}],"update":[{"price":"1055.35","symbol":"BCHUSDT","id":"10553500","side":"Sell","size":9.37},{"price":"1055.45","symbol":"BCHUSDT","id":"10554500","side":"Sell","size":3.67},{"price":"1055.40","symbol":"BCHUSDT","id":"10554000","side":"Sell","size":7.36},{"price":"1055.50","symbol":"BCHUSDT","id":"10555000","side":"Sell","size":5.89},{"price":"1054.65","symbol":"BCHUSDT","id":"10546500","side":"Buy","size":19.769999},{"price":"1055.30","symbol":"BCHUSDT","id":"10553000","side":"Sell","size":7.87}],"insert":[{"price":"1054.90","symbol":"BCHUSDT","id":"10549000","side":"Buy","size":13.329999},{"price":"1054.75","symbol":"BCHUSDT","id":"10547500","side":"Buy","size":9.08}]},"cross_seq":"864133008","timestamp_e6":"1618677792791837"}
1618677792.887476: {"topic":"orderBookL2_25.LINKUSDT","type":"delta","data":{"delete":[],"update":[{"price":"41.069","symbol":"LINKUSDT","id":"410690","side":"Sell","size":122.50001},{"price":"41.067","symbol":"LINKUSDT","id":"410670","side":"Sell","size":128.7},{"price":"41.068","symbol":"LINKUSDT","id":"410680","side":"Sell","size":460},{"price":"41.031","symbol":"LINKUSDT","id":"410310","side":"Buy","size":104.600006}],"insert":[]},"cross_seq":"1970980096","timestamp_e6":"1618677792803734"}
1618677792.9070961: {"topic":"orderBookL2_25.DOTUSDT","type":"delta","data":{"delete":[{"price":"43.515","symbol":"DOTUSDT","id":"435150","side":"Buy"}],"update":[{"price":"43.545","symbol":"DOTUSDT","id":"435450","side":"Buy","size":211.99998},{"price":"43.520","symbol":"DOTUSDT","id":"435200","side":"Buy","size":303.2},{"price":"43.585","symbol":"DOTUSDT","id":"435850","side":"Sell","size":249.1},{"price":"43.540","symbol":"DOTUSDT","id":"435400","side":"Buy","size":580.7}],"insert":[{"price":"43.535","symbol":"DOTUSDT","id":"435350","side":"Buy","size":454.80002}]},"cross_seq":"916954600","timestamp_e6":"1618677792822345"}
1618677792.9134579: {"topic":"orderBookL2_25.BCHUSDT","type":"delta","data":{"delete":[{"price":"1055.15","symbol":"BCHUSDT","id":"10551500","side":"Sell"},{"price":"1055.20","symbol":"BCHUSDT","id":"10552000","side":"Sell"},{"price":"1054.80","symbol":"BCHUSDT","id":"10548000","side":"Buy"},{"price":"1055.25","symbol":"BCHUSDT","id":"10552500","side":"Sell"}],"update":[{"price":"1055.30","symbol":"BCHUSDT","id":"10553000","side":"Sell","size":11.54},{"price":"1054.70","symbol":"BCHUSDT","id":"10547000","side":"Buy","size":23.22},{"price":"1055.75","symbol":"BCHUSDT","id":"10557500","side":"Sell","size":5.35},{"price":"1055.70","symbol":"BCHUSDT","id":"10557000","side":"Sell","size":13.39},{"price":"1054.90","symbol":"BCHUSDT","id":"10549000","side":"Buy","size":26.64},{"price":"1055.60","symbol":"BCHUSDT","id":"10556000","side":"Sell","size":12.9}],"insert":[{"price":"1055.55","symbol":"BCHUSDT","id":"10555500","side":"Sell","size":2.41},{"price":"1056.35","symbol":"BCHUSDT","id":"10563500","side":"Sell","size":15.590001},{"price":"1056.40","symbol":"BCHUSDT","id":"10564000","side":"Sell","size":1},{"price":"1053.65","symbol":"BCHUSDT","id":"10536500","side":"Buy","size":4.55}]},"cross_seq":"864133031","timestamp_e6":"1618677792829949"}
1618677792.934714: {"topic":"orderBookL2_25.LTCUSDT","type":"delta","data":{"delete":[],"update":[{"price":"313.30","symbol":"LTCUSDT","id":"3133000","side":"Buy","size":67},{"price":"313.34","symbol":"LTCUSDT","id":"3133400","side":"Buy","size":359.9}],"insert":[]},"cross_seq":"1684523479","timestamp_e6":"1618677792838984"}
1618677792.963496: {"topic":"orderBookL2_25.LTCUSDT","type":"delta","data":{"delete":[],"update":[{"price":"313.34","symbol":"LTCUSDT","id":"3133400","side":"Buy","size":526.5}],"insert":[]},"cross_seq":"1684523480","timestamp_e6":"1618677792880711"}
1618677792.967032: {"topic":"orderBookL2_25.DOTUSDT","type":"delta","data":{"delete":[],"update":[{"price":"43.560","symbol":"DOTUSDT","id":"435600","side":"Sell","size":844.39996}],"insert":[]},"cross_seq":"916954602","timestamp_e6":"1618677792882534"}
1618677792.9844742: {"topic":"orderBookL2_25.LTCUSDT","type":"delta","data":{"delete":[{"price":"313.49","symbol":"LTCUSDT","id":"3134900","side":"Sell"},{"price":"313.46","symbol":"LTCUSDT","id":"3134600","side":"Sell"},{"price":"313.41","symbol":"LTCUSDT","id":"3134100","side":"Sell"},{"price":"313.44","symbol":"LTCUSDT","id":"3134400","side":"Sell"}],"update":[{"price":"313.55","symbol":"LTCUSDT","id":"3135500","side":"Sell","size":54.899998},{"price":"313.45","symbol":"LTCUSDT","id":"3134500","side":"Sell","size":2},{"price":"313.43","symbol":"LTCUSDT","id":"3134300","side":"Sell","size":1.5},{"price":"313.42","symbol":"LTCUSDT","id":"3134200","side":"Sell","size":0.1},{"price":"313.48","symbol":"LTCUSDT","id":"3134800","side":"Sell","size":87.3},{"price":"313.53","symbol":"LTCUSDT","id":"3135300","side":"Sell","size":140.5},{"price":"313.47","symbol":"LTCUSDT","id":"3134700","side":"Sell","size":130.1},{"price":"313.51","symbol":"LTCUSDT","id":"3135100","side":"Sell","size":99},{"price":"313.34","symbol":"LTCUSDT","id":"3133400","side":"Buy","size":359.9},{"price":"313.50","symbol":"LTCUSDT","id":"3135000","side":"Sell","size":224.29999}],"insert":[{"price":"313.66","symbol":"LTCUSDT","id":"3136600","side":"Sell","size":237.9},{"price":"313.65","symbol":"LTCUSDT","id":"3136500","side":"Sell","size":41.9},{"price":"313.68","symbol":"LTCUSDT","id":"3136800","side":"Sell","size":59.5},{"price":"313.67","symbol":"LTCUSDT","id":"3136700","side":"Sell","size":133.5}]},"cross_seq":"1684523547","timestamp_e6":"1618677792899117"}
1618677792.988925: {"topic":"orderBookL2_25.UNIUSDT","type":"delta","data":{"delete":[{"price":"35.357","symbol":"UNIUSDT","id":"353570","side":"Buy"}],"update":[{"price":"35.402","symbol":"UNIUSDT","id":"354020","side":"Sell","size":357.9},{"price":"35.405","symbol":"UNIUSDT","id":"354050","side":"Sell","size":99.3},{"price":"35.407","symbol":"UNIUSDT","id":"354070","side":"Sell","size":56.4},{"price":"35.404","symbol":"UNIUSDT","id":"354040","side":"Sell","size":121.4},{"price":"35.379","symbol":"UNIUSDT","id":"353790","side":"Buy","size":56.7},{"price":"35.375","symbol":"UNIUSDT","id":"353750","side":"Buy","size":59.2},{"price":"35.403","symbol":"UNIUSDT","id":"354030","side":"Sell","size":114.4},{"price":"35.373","symbol":"UNIUSDT","id":"353730","side":"Buy","size":45.6},{"price":"35.406","symbol":"UNIUSDT","id":"354060","side":"Sell","size":75},{"price":"35.374","symbol":"UNIUSDT","id":"353740","side":"Buy","size":35.5}],"insert":[{"price":"35.377","symbol":"UNIUSDT","id":"353770","side":"Buy","size":24.2}]},"cross_seq":"916954633","timestamp_e6":"1618677792904185"}
1618677792.988998: {"topic":"orderBookL2_25.ADAUSDT","type":"delta","data":{"delete":[{"price":"1.3861","symbol":"ADAUSDT","id":"13861","side":"Buy"},{"price":"1.3860","symbol":"ADAUSDT","id":"13860","side":"Buy"}],"update":[{"price":"1.3859","symbol":"ADAUSDT","id":"13859","side":"Buy","size":4430},{"price":"1.3879","symbol":"ADAUSDT","id":"13879","side":"Sell","size":2591},{"price":"1.3882","symbol":"ADAUSDT","id":"13882","side":"Sell","size":3602.9998},{"price":"1.3881","symbol":"ADAUSDT","id":"13881","side":"Sell","size":2486},{"price":"1.3856","symbol":"ADAUSDT","id":"13856","side":"Buy","size":7446},{"price":"1.3858","symbol":"ADAUSDT","id":"13858","side":"Buy","size":4323},{"price":"1.3857","symbol":"ADAUSDT","id":"13857","side":"Buy","size":6775.9995},{"price":"1.3878","symbol":"ADAUSDT","id":"13878","side":"Sell","size":9472},{"price":"1.3883","symbol":"ADAUSDT","id":"13883","side":"Sell","size":2721}],"insert":[{"price":"1.3845","symbol":"ADAUSDT","id":"13845","side":"Buy","size":4684},{"price":"1.3846","symbol":"ADAUSDT","id":"13846","side":"Buy","size":1015}]},"cross_seq":"916954633","timestamp_e6":"1618677792904017"}
1618677792.990162: {"topic":"orderBookL2_25.ETHUSDT","type":"delta","data":{"delete":[],"update":[{"price":"2363.90","symbol":"ETHUSDT","id":"23639000","side":"Buy","size":77.92},{"price":"2364.00","symbol":"ETHUSDT","id":"23640000","side":"Buy","size":148.07},{"price":"2363.95","symbol":"ETHUSDT","id":"23639500","side":"Buy","size":105.03}],"insert":[]},"cross_seq":"1800546804","timestamp_e6":"1618677792907064"}
1618677792.9994361: {"topic":"orderBookL2_25.XTZUSDT","type":"delta","data":{"delete":[],"update":[{"price":"7.213","symbol":"XTZUSDT","id":"72130","side":"Sell","size":540.5},{"price":"7.209","symbol":"XTZUSDT","id":"72090","side":"Buy","size":1864.4},{"price":"7.211","symbol":"XTZUSDT","id":"72110","side":"Buy","size":859.4},{"price":"7.206","symbol":"XTZUSDT","id":"72060","side":"Buy","size":1094.2999}],"insert":[]},"cross_seq":"726228524","timestamp_e6":"1618677792915172"}
1618677793.003042: {"topic":"orderBookL2_25.LTCUSDT","type":"delta","data":{"delete":[],"update":[{"price":"313.53","symbol":"LTCUSDT","id":"3135300","side":"Sell","size":68.700005},{"price":"313.09","symbol":"LTCUSDT","id":"3130900","side":"Buy","size":328.1},{"price":"313.50","symbol":"LTCUSDT","id":"3135000","side":"Sell","size":249.9},{"price":"313.51","symbol":"LTCUSDT","id":"3135100","side":"Sell","size":154.5}],"insert":[]},"cross_seq":"1684523581","timestamp_e6":"1618677792918658"}
1618677793.006977: {"topic":"orderBookL2_25.DOTUSDT","type":"delta","data":{"delete":[],"update":[{"price":"43.545","symbol":"DOTUSDT","id":"435450","side":"Buy","size":512}],"insert":[]},"cross_seq":"916954634","timestamp_e6":"1618677792922333"}
1618677793.0125902: {"topic":"orderBookL2_25.BCHUSDT","type":"delta","data":{"delete":[{"price":"1053.65","symbol":"BCHUSDT","id":"10536500","side":"Buy"}],"update":[{"price":"1054.55","symbol":"BCHUSDT","id":"10545500","side":"Buy","size":4.6},{"price":"1054.45","symbol":"BCHUSDT","id":"10544500","side":"Buy","size":5.11},{"price":"1054.70","symbol":"BCHUSDT","id":"10547000","side":"Buy","size":6.01},{"price":"1054.65","symbol":"BCHUSDT","id":"10546500","side":"Buy","size":5.47},{"price":"1055.55","symbol":"BCHUSDT","id":"10555500","side":"Sell","size":7.36},{"price":"1055.65","symbol":"BCHUSDT","id":"10556500","side":"Sell","size":27.46},{"price":"1055.85","symbol":"BCHUSDT","id":"10558500","side":"Sell","size":18.25},{"price":"1054.50","symbol":"BCHUSDT","id":"10545000","side":"Buy","size":8.98},{"price":"1055.70","symbol":"BCHUSDT","id":"10557000","side":"Sell","size":15.830001},{"price":"1054.60","symbol":"BCHUSDT","id":"10546000","side":"Buy","size":9.95},{"price":"1055.60","symbol":"BCHUSDT","id":"10556000","side":"Sell","size":15.57},{"price":"1055.45","symbol":"BCHUSDT","id":"10554500","side":"Sell","size":7.87},{"price":"1055.50","symbol":"BCHUSDT","id":"10555000","side":"Sell","size":9.37}],"insert":[{"price":"1054.80","symbol":"BCHUSDT","id":"10548000","side":"Buy","size":9.08}]},"cross_seq":"864133047","timestamp_e6":"1618677792928758"}
1618677793.022988: {"topic":"orderBookL2_25.LTCUSDT","type":"delta","data":{"delete":[{"price":"313.06","symbol":"LTCUSDT","id":"3130600","side":"Buy"}],"update":[{"price":"313.35","symbol":"LTCUSDT","id":"3133500","side":"Sell","size":2.1},{"price":"313.22","symbol":"LTCUSDT","id":"3132200","side":"Buy","size":101.700005},{"price":"313.07","symbol":"LTCUSDT","id":"3130700","side":"Buy","size":159.09999}],"insert":[{"price":"313.08","symbol":"LTCUSDT","id":"3130800","side":"Buy","size":142.5}]},"cross_seq":"1684523599","timestamp_e6":"1618677792939046"}
1618677793.029463: {"topic":"orderBookL2_25.DOTUSDT","type":"delta","data":{"delete":[{"price":"43.550","symbol":"DOTUSDT","id":"435500","side":"Sell"},{"price":"43.555","symbol":"DOTUSDT","id":"435550","side":"Sell"}],"update":[{"price":"43.560","symbol":"DOTUSDT","id":"435600","side":"Sell","size":1111.9},{"price":"43.485","symbol":"DOTUSDT","id":"434850","side":"Buy","size":427.9},{"price":"43.495","symbol":"DOTUSDT","id":"434950","side":"Buy","size":408.9},{"price":"43.480","symbol":"DOTUSDT","id":"434800","side":"Buy","size":516.9}],"insert":[{"price":"43.680","symbol":"DOTUSDT","id":"436800","side":"Sell","size":156.5},{"price":"43.675","symbol":"DOTUSDT","id":"436750","side":"Sell","size":239}]},"cross_seq":"916954640","timestamp_e6":"1618677792943558"}
1618677793.042089: {"topic":"orderBookL2_25.LTCUSDT","type":"delta","data":{"delete":[{"price":"313.68","symbol":"LTCUSDT","id":"3136800","side":"Sell"},{"price":"313.66","symbol":"LTCUSDT","id":"3136600","side":"Sell"},{"price":"313.67","symbol":"LTCUSDT","id":"3136700","side":"Sell"}],"update":[{"price":"313.42","symbol":"LTCUSDT","id":"3134200","side":"Sell","size":87.399994},{"price":"313.45","symbol":"LTCUSDT","id":"3134500","side":"Sell","size":30.300001},{"price":"313.43","symbol":"LTCUSDT","id":"3134300","side":"Sell","size":56.999996}],"insert":[{"price":"313.41","symbol":"LTCUSDT","id":"3134100","side":"Sell","size":125.1},{"price":"313.46","symbol":"LTCUSDT","id":"3134600","side":"Sell","size":48.7},{"price":"313.44","symbol":"LTCUSDT","id":"3134400","side":"Sell","size":56.199997}]},"cross_seq":"1684523622","timestamp_e6":"1618677792958290"}
1618677793.047691: {"topic":"orderBookL2_25.DOTUSDT","type":"delta","data":{"delete":[],"update":[{"price":"43.545","symbol":"DOTUSDT","id":"435450","side":"Buy","size":712}],"insert":[]},"cross_seq":"916954641","timestamp_e6":"1618677792962369"}
1618677793.0598981: {"topic":"orderBookL2_25.XTZUSDT","type":"delta","data":{"delete":[],"update":[{"price":"7.216","symbol":"XTZUSDT","id":"72160","side":"Sell","size":1978.6},{"price":"7.219","symbol":"XTZUSDT","id":"72190","side":"Sell","size":1711.1001},{"price":"7.214","symbol":"XTZUSDT","id":"72140","side":"Sell","size":2220.5},{"price":"7.206","symbol":"XTZUSDT","id":"72060","side":"Buy","size":530.10004},{"price":"7.204","symbol":"XTZUSDT","id":"72040","side":"Buy","size":507.9},{"price":"7.209","symbol":"XTZUSDT","id":"72090","side":"Buy","size":654.2},{"price":"7.215","symbol":"XTZUSDT","id":"72150","side":"Sell","size":924.49994},{"price":"7.217","symbol":"XTZUSDT","id":"72170","side":"Sell","size":557.6},{"price":"7.208","symbol":"XTZUSDT","id":"72080","side":"Buy","size":672.3}],"insert":[]},"cross_seq":"726228533","timestamp_e6":"1618677792975154"}
1618677793.068249: {"topic":"orderBookL2_25.DOTUSDT","type":"delta","data":{"delete":[{"price":"43.525","symbol":"DOTUSDT","id":"435250","side":"Buy"}],"update":[{"price":"43.545","symbol":"DOTUSDT","id":"435450","side":"Buy","size":790.7},{"price":"43.560","symbol":"DOTUSDT","id":"435600","side":"Sell","size":1450.4},{"price":"43.540","symbol":"DOTUSDT","id":"435400","side":"Buy","size":125.9}],"insert":[{"price":"43.555","symbol":"DOTUSDT","id":"435550","side":"Buy","size":202}]},"cross_seq":"916954651","timestamp_e6":"1618677792983537"}
1618677793.106066: {"topic":"orderBookL2_25.DOTUSDT","type":"delta","data":{"delete":[],"update":[{"price":"43.555","symbol":"DOTUSDT","id":"435550","side":"Buy","size":211.99998},{"price":"43.545","symbol":"DOTUSDT","id":"435450","side":"Buy","size":580.7}],"insert":[]},"cross_seq":"916954664","timestamp_e6":"1618677793022329"}
1618677793.1117241: {"topic":"orderBookL2_25.BCHUSDT","type":"delta","data":{"delete":[{"price":"1055.30","symbol":"BCHUSDT","id":"10553000","side":"Sell"},{"price":"1055.35","symbol":"BCHUSDT","id":"10553500","side":"Sell"},{"price":"1055.55","symbol":"BCHUSDT","id":"10555500","side":"Sell"},{"price":"1055.40","symbol":"BCHUSDT","id":"10554000","side":"Sell"}],"update":[{"price":"1055.70","symbol":"BCHUSDT","id":"10557000","side":"Sell","size":8.84},{"price":"1055.75","symbol":"BCHUSDT","id":"10557500","side":"Sell","size":10.24},{"price":"1055.60","symbol":"BCHUSDT","id":"10556000","side":"Sell","size":21.27}],"insert":[{"price":"1056.45","symbol":"BCHUSDT","id":"10564500","side":"Sell","size":16.609999},{"price":"1056.55","symbol":"BCHUSDT","id":"10565500","side":"Sell","size":10.5},{"price":"1056.50","symbol":"BCHUSDT","id":"10565000","side":"Sell","size":30.32},{"price":"1056.60","symbol":"BCHUSDT","id":"10566000","side":"Sell","size":10.7}]},"cross_seq":"864133063","timestamp_e6":"1618677793028798"}
1618677793.1414132: {"topic":"orderBookL2_25.LTCUSDT","type":"delta","data":{"delete":[{"price":"313.41","symbol":"LTCUSDT","id":"3134100","side":"Sell"},{"price":"313.44","symbol":"LTCUSDT","id":"3134400","side":"Sell"}],"update":[{"price":"313.42","symbol":"LTCUSDT","id":"3134200","side":"Sell","size":0.1},{"price":"313.45","symbol":"LTCUSDT","id":"3134500","side":"Sell","size":50.7}],"insert":[{"price":"313.40","symbol":"LTCUSDT","id":"3134000","side":"Sell","size":125.1},{"price":"313.66","symbol":"LTCUSDT","id":"3136600","side":"Sell","size":237.9}]},"cross_seq":"1684523628","timestamp_e6":"1618677793058557"}
1618677793.167781: {"topic":"orderBookL2_25.ADAUSDT","type":"delta","data":{"delete":[{"price":"1.3846","symbol":"ADAUSDT","id":"13846","side":"Buy"},{"price":"1.3845","symbol":"ADAUSDT","id":"13845","side":"Buy"}],"update":[{"price":"1.3882","symbol":"ADAUSDT","id":"13882","side":"Sell","size":2692},{"price":"1.3886","symbol":"ADAUSDT","id":"13886","side":"Sell","size":3017},{"price":"1.3862","symbol":"ADAUSDT","id":"13862","side":"Buy","size":7874.9995},{"price":"1.3878","symbol":"ADAUSDT","id":"13878","side":"Sell","size":5159},{"price":"1.3881","symbol":"ADAUSDT","id":"13881","side":"Sell","size":3196},{"price":"1.3888","symbol":"ADAUSDT","id":"13888","side":"Sell","size":262},{"price":"1.3880","symbol":"ADAUSDT","id":"13880","side":"Sell","size":5633},{"price":"1.3859","symbol":"ADAUSDT","id":"13859","side":"Buy","size":2867},{"price":"1.3879","symbol":"ADAUSDT","id":"13879","side":"Sell","size":4532},{"price":"1.3876","symbol":"ADAUSDT","id":"13876","side":"Sell","size":4211}],"insert":[{"price":"1.3860","symbol":"ADAUSDT","id":"13860","side":"Buy","size":3550},{"price":"1.3861","symbol":"ADAUSDT","id":"13861","side":"Buy","size":3651}]},"cross_seq":"916954680","timestamp_e6":"1618677793082354"}
1618677793.1846058: {"topic":"orderBookL2_25.LTCUSDT","type":"delta","data":{"delete":[],"update":[{"price":"313.35","symbol":"LTCUSDT","id":"3133500","side":"Sell","size":127.1}],"insert":[]},"cross_seq":"1684523629","timestamp_e6":"1618677793099734"}
1618677793.187619: {"topic":"orderBookL2_25.LINKUSDT","type":"delta","data":{"delete":[{"price":"41.048","symbol":"LINKUSDT","id":"410480","side":"Sell"},{"price":"41.052","symbol":"LINKUSDT","id":"410520","side":"Sell"},{"price":"41.050","symbol":"LINKUSDT","id":"410500","side":"Sell"}],"update":[{"price":"41.051","symbol":"LINKUSDT","id":"410510","side":"Sell","size":120.8},{"price":"41.049","symbol":"LINKUSDT","id":"410490","side":"Sell","size":200.6}],"insert":[{"price":"41.073","symbol":"LINKUSDT","id":"410730","side":"Sell","size":194.40001},{"price":"41.072","symbol":"LINKUSDT","id":"410720","side":"Sell","size":188.3},{"price":"41.071","symbol":"LINKUSDT","id":"410710","side":"Sell","size":314.9}]},"cross_seq":"1970980101","timestamp_e6":"1618677793104283"}
1618677793.2029219: {"topic":"orderBookL2_25.LTCUSDT","type":"delta","data":{"delete":[],"update":[{"price":"313.35","symbol":"LTCUSDT","id":"3133500","side":"Sell","size":2.1}],"insert":[]},"cross_seq":"1684523630","timestamp_e6":"1618677793119515"}
1618677793.2084951: {"topic":"orderBookL2_25.ADAUSDT","type":"delta","data":{"delete":[{"price":"1.3848","symbol":"ADAUSDT","id":"13848","side":"Buy"},{"price":"1.3877","symbol":"ADAUSDT","id":"13877","side":"Sell"},{"price":"1.3847","symbol":"ADAUSDT","id":"13847","side":"Buy"}],"update":[{"price":"1.3867","symbol":"ADAUSDT","id":"13867","side":"Buy","size":2001},{"price":"1.3888","symbol":"ADAUSDT","id":"13888","side":"Sell","size":3129},{"price":"1.3897","symbol":"ADAUSDT","id":"13897","side":"Sell","size":1144},{"price":"1.3883","symbol":"ADAUSDT","id":"13883","side":"Sell","size":1799.0001},{"price":"1.3882","symbol":"ADAUSDT","id":"13882","side":"Sell","size":3224},{"price":"1.3868","symbol":"ADAUSDT","id":"13868","side":"Buy","size":7912},{"price":"1.3876","symbol":"ADAUSDT","id":"13876","side":"Sell","size":1},{"price":"1.3878","symbol":"ADAUSDT","id":"13878","side":"Sell","size":8457},{"price":"1.3890","symbol":"ADAUSDT","id":"13890","side":"Sell","size":13835},{"price":"1.3885","symbol":"ADAUSDT","id":"13885","side":"Sell","size":1312},{"price":"1.3886","symbol":"ADAUSDT","id":"13886","side":"Sell","size":6581},{"price":"1.3870","symbol":"ADAUSDT","id":"13870","side":"Buy","size":4938}],"insert":[{"price":"1.3901","symbol":"ADAUSDT","id":"13901","side":"Sell","size":6684.9995},{"price":"1.3871","symbol":"ADAUSDT","id":"13871","side":"Buy","size":4689},{"price":"1.3872","symbol":"ADAUSDT","id":"13872","side":"Buy","size":5509}]},"cross_seq":"916954722","timestamp_e6":"1618677793122362"}
1618677793.2426: {"topic":"orderBookL2_25.LTCUSDT","type":"delta","data":{"delete":[],"update":[{"price":"313.20","symbol":"LTCUSDT","id":"3132000","side":"Buy","size":145.6}],"insert":[]},"cross_seq":"1684523631","timestamp_e6":"1618677793158156"}
1618677793.2510872: {"topic":"orderBookL2_25.ETHUSDT","type":"delta","data":{"delete":[],"update":[{"price":"2365.20","symbol":"ETHUSDT","id":"23652000","side":"Sell","size":97.03},{"price":"2363.95","symbol":"ETHUSDT","id":"23639500","side":"Buy","size":54.989998},{"price":"2365.05","symbol":"ETHUSDT","id":"23650500","side":"Sell","size":130.88},{"price":"2365.10","symbol":"ETHUSDT","id":"23651000","side":"Sell","size":121.34},{"price":"2365.15","symbol":"ETHUSDT","id":"23651500","side":"Sell","size":62.24},{"price":"2364.00","symbol":"ETHUSDT","id":"23640000","side":"Buy","size":103.55},{"price":"2363.90","symbol":"ETHUSDT","id":"23639000","side":"Buy","size":56.31},{"price":"2364.10","symbol":"ETHUSDT","id":"23641000","side":"Buy","size":183.51},{"price":"2365.00","symbol":"ETHUSDT","id":"23650000","side":"Sell","size":160.12999}],"insert":[]},"cross_seq":"1800546814","timestamp_e6":"1618677793167696"}
1618677793.2713962: {"topic":"orderBookL2_25.BCHUSDT","type":"delta","data":{"delete":[],"update":[{"price":"1054.70","symbol":"BCHUSDT","id":"10547000","side":"Buy","size":16.17},{"price":"1054.55","symbol":"BCHUSDT","id":"10545500","side":"Buy","size":8.27},{"price":"1054.65","symbol":"BCHUSDT","id":"10546500","side":"Buy","size":12.049999},{"price":"1054.45","symbol":"BCHUSDT","id":"10544500","side":"Buy","size":8.5}],"insert":[]},"cross_seq":"864133073","timestamp_e6":"1618677793188844"}
1618677793.286238: {"topic":"orderBookL2_25.DOTUSDT","type":"delta","data":{"delete":[],"update":[{"price":"43.560","symbol":"DOTUSDT","id":"435600","side":"Sell","size":1278.3}],"insert":[]},"cross_seq":"916954724","timestamp_e6":"1618677793202383"}
1618677793.3065128: {"topic":"orderBookL2_25.DOTUSDT","type":"delta","data":{"delete":[],"update":[{"price":"43.640","symbol":"DOTUSDT","id":"436400","side":"Sell","size":212.09999},{"price":"43.585","symbol":"DOTUSDT","id":"435850","side":"Sell","size":495.40002}],"insert":[]},"cross_seq":"916954740","timestamp_e6":"1618677793223074"}
1618677793.308307: {"topic":"orderBookL2_25.LINKUSDT","type":"delta","data":{"delete":[{"price":"41.071","symbol":"LINKUSDT","id":"410710","side":"Sell"},{"price":"41.073","symbol":"LINKUSDT","id":"410730","side":"Sell"},{"price":"41.072","symbol":"LINKUSDT","id":"410720","side":"Sell"}],"update":[{"price":"41.040","symbol":"LINKUSDT","id":"410400","side":"Buy","size":167.6},{"price":"41.049","symbol":"LINKUSDT","id":"410490","side":"Sell","size":102.200005},{"price":"41.043","symbol":"LINKUSDT","id":"410430","side":"Buy","size":372.8},{"price":"41.041","symbol":"LINKUSDT","id":"410410","side":"Buy","size":263.7}],"insert":[{"price":"41.048","symbol":"LINKUSDT","id":"410480","side":"Sell","size":202.3},{"price":"41.052","symbol":"LINKUSDT","id":"410520","side":"Sell","size":122.4},{"price":"41.050","symbol":"LINKUSDT","id":"410500","side":"Sell","size":153.3}]},"cross_seq":"1970980108","timestamp_e6":"1618677793224255"}
1618677793.310112: {"topic":"orderBookL2_25.ADAUSDT","type":"delta","data":{"delete":[{"price":"1.3901","symbol":"ADAUSDT","id":"13901","side":"Sell"}],"update":[{"price":"1.3878","symbol":"ADAUSDT","id":"13878","side":"Sell","size":7399},{"price":"1.3900","symbol":"ADAUSDT","id":"13900","side":"Sell","size":7455},{"price":"1.3880","symbol":"ADAUSDT","id":"13880","side":"Sell","size":2335},{"price":"1.3867","symbol":"ADAUSDT","id":"13867","side":"Buy","size":5167},{"price":"1.3868","symbol":"ADAUSDT","id":"13868","side":"Buy","size":11318},{"price":"1.3881","symbol":"ADAUSDT","id":"13881","side":"Sell","size":2567}],"insert":[{"price":"1.3877","symbol":"ADAUSDT","id":"13877","side":"Sell","size":2333}]},"cross_seq":"916954740","timestamp_e6":"1618677793222806"}
1618677793.320749: {"topic":"orderBookL2_25.XTZUSDT","type":"delta","data":{"delete":[],"update":[{"price":"7.214","symbol":"XTZUSDT","id":"72140","side":"Sell","size":2759},{"price":"7.206","symbol":"XTZUSDT","id":"72060","side":"Buy","size":589.6},{"price":"7.208","symbol":"XTZUSDT","id":"72080","side":"Buy","size":1428.8999},{"price":"7.210","symbol":"XTZUSDT","id":"72100","side":"Buy","size":257.30002},{"price":"7.207","symbol":"XTZUSDT","id":"72070","side":"Buy","size":1371.1001},{"price":"7.209","symbol":"XTZUSDT","id":"72090","side":"Buy","size":1628.7001},{"price":"7.204","symbol":"XTZUSDT","id":"72040","side":"Buy","size":742.8}],"insert":[]},"cross_seq":"726228542","timestamp_e6":"1618677793234694"}
1618677793.323921: {"topic":"orderBookL2_25.LTCUSDT","type":"delta","data":{"delete":[],"update":[{"price":"313.35","symbol":"LTCUSDT","id":"3133500","side":"Sell","size":1.5}],"insert":[]},"cross_seq":"1684523632","timestamp_e6":"1618677793239078"}
1618677793.326268: {"topic":"orderBookL2_25.ADAUSDT","type":"delta","data":{"delete":[],"update":[{"price":"1.3879","symbol":"ADAUSDT","id":"13879","side":"Sell","size":5497},{"price":"1.3866","symbol":"ADAUSDT","id":"13866","side":"Buy","size":3983},{"price":"1.3867","symbol":"ADAUSDT","id":"13867","side":"Buy","size":7727},{"price":"1.3878","symbol":"ADAUSDT","id":"13878","side":"Sell","size":4101},{"price":"1.3880","symbol":"ADAUSDT","id":"13880","side":"Sell","size":4114},{"price":"1.3886","symbol":"ADAUSDT","id":"13886","side":"Sell","size":4508},{"price":"1.3882","symbol":"ADAUSDT","id":"13882","side":"Sell","size":4421},{"price":"1.3868","symbol":"ADAUSDT","id":"13868","side":"Buy","size":12849},{"price":"1.3877","symbol":"ADAUSDT","id":"13877","side":"Sell","size":2023},{"price":"1.3870","symbol":"ADAUSDT","id":"13870","side":"Buy","size":1}],"insert":[]},"cross_seq":"916954764","timestamp_e6":"1618677793242358"}
1618677793.327507: {"topic":"orderBookL2_25.DOTUSDT","type":"delta","data":{"delete":[{"price":"43.530","symbol":"DOTUSDT","id":"435300","side":"Buy"},{"price":"43.535","symbol":"DOTUSDT","id":"435350","side":"Buy"}],"update":[{"price":"43.580","symbol":"DOTUSDT","id":"435800","side":"Sell","size":198.4},{"price":"43.585","symbol":"DOTUSDT","id":"435850","side":"Sell","size":573.7},{"price":"43.575","symbol":"DOTUSDT","id":"435750","side":"Sell","size":363.2},{"price":"43.540","symbol":"DOTUSDT","id":"435400","side":"Buy","size":532.60004},{"price":"43.560","symbol":"DOTUSDT","id":"435600","side":"Sell","size":1578.3},{"price":"43.555","symbol":"DOTUSDT","id":"435550","side":"Buy","size":312}],"insert":[{"price":"43.410","symbol":"DOTUSDT","id":"434100","side":"Buy","size":252.7},{"price":"43.525","symbol":"DOTUSDT","id":"435250","side":"Buy","size":317.3}]},"cross_seq":"916954764","timestamp_e6":"1618677793242486"}
1618677793.3379571: {"topic":"orderBookL2_25.XTZUSDT","type":"delta","data":{"delete":[],"update":[{"price":"7.206","symbol":"XTZUSDT","id":"72060","side":"Buy","size":949.1},{"price":"7.210","symbol":"XTZUSDT","id":"72100","side":"Buy","size":601.89996},{"price":"7.207","symbol":"XTZUSDT","id":"72070","side":"Buy","size":786.5}],"insert":[]},"cross_seq":"726228546","timestamp_e6":"1618677793254607"}
1618677793.3422809: {"topic":"orderBookL2_25.LTCUSDT","type":"delta","data":{"delete":[{"price":"313.29","symbol":"LTCUSDT","id":"3132900","side":"Buy"},{"price":"313.65","symbol":"LTCUSDT","id":"3136500","side":"Sell"},{"price":"313.66","symbol":"LTCUSDT","id":"3136600","side":"Sell"}],"update":[{"price":"313.42","symbol":"LTCUSDT","id":"3134200","side":"Sell","size":75},{"price":"313.30","symbol":"LTCUSDT","id":"3133000","side":"Buy","size":97.6},{"price":"313.32","symbol":"LTCUSDT","id":"3133200","side":"Buy","size":148.2}],"insert":[{"price":"313.06","symbol":"LTCUSDT","id":"3130600","side":"Buy","size":176.1},{"price":"313.44","symbol":"LTCUSDT","id":"3134400","side":"Sell","size":47.000004},{"price":"313.41","symbol":"LTCUSDT","id":"3134100","side":"Sell","size":131}]},"cross_seq":"1684523638","timestamp_e6":"1618677793258617"}
1618677793.3541372: {"topic":"orderBookL2_25.BCHUSDT","type":"delta","data":{"delete":[{"price":"1055.50","symbol":"BCHUSDT","id":"10555000","side":"Sell"},{"price":"1055.45","symbol":"BCHUSDT","id":"10554500","side":"Sell"}],"update":[{"price":"1054.80","symbol":"BCHUSDT","id":"10548000","side":"Buy","size":4.23},{"price":"1054.75","symbol":"BCHUSDT","id":"10547500","side":"Buy","size":12.14},{"price":"1055.80","symbol":"BCHUSDT","id":"10558000","side":"Sell","size":6.59},{"price":"1055.70","symbol":"BCHUSDT","id":"10557000","side":"Sell","size":12.51},{"price":"1054.90","symbol":"BCHUSDT","id":"10549000","side":"Buy","size":13.31},{"price":"1054.60","symbol":"BCHUSDT","id":"10546000","side":"Buy","size":11.49},{"price":"1054.65","symbol":"BCHUSDT","id":"10546500","side":"Buy","size":15.98},{"price":"1054.70","symbol":"BCHUSDT","id":"10547000","side":"Buy","size":19.24}],"insert":[{"price":"1055.55","symbol":"BCHUSDT","id":"10555500","side":"Sell","size":11.54},{"price":"1056.65","symbol":"BCHUSDT","id":"10566500","side":"Sell","size":16.9}]},"cross_seq":"864133096","timestamp_e6":"1618677793269911"}
1618677793.361575: {"topic":"orderBookL2_25.LTCUSDT","type":"delta","data":{"delete":[{"price":"313.40","symbol":"LTCUSDT","id":"3134000","side":"Sell"},{"price":"313.48","symbol":"LTCUSDT","id":"3134800","side":"Sell"},{"price":"313.06","symbol":"LTCUSDT","id":"3130600","side":"Buy"}],"update":[{"price":"313.53","symbol":"LTCUSDT","id":"3135300","side":"Sell","size":111.399994},{"price":"313.50","symbol":"LTCUSDT","id":"3135000","side":"Sell","size":188.2}],"insert":[{"price":"313.29","symbol":"LTCUSDT","id":"3132900","side":"Buy","size":47.100002},{"price":"313.49","symbol":"LTCUSDT","id":"3134900","side":"Sell","size":74.9},{"price":"313.65","symbol":"LTCUSDT","id":"3136500","side":"Sell","size":41.9}]},"cross_seq":"1684523666","timestamp_e6":"1618677793277920"}
1618677793.366911: {"topic":"orderBookL2_25.DOTUSDT","type":"delta","data":{"delete":[{"price":"43.410","symbol":"DOTUSDT","id":"434100","side":"Buy"}],"update":[],"insert":[{"price":"43.530","symbol":"DOTUSDT","id":"435300","side":"Buy","size":59.000004}]},"cross_seq":"916954789","timestamp_e6":"1618677793282485"}
1618677793.366954: {"topic":"orderBookL2_25.ADAUSDT","type":"delta","data":{"delete":[{"price":"1.3849","symbol":"ADAUSDT","id":"13849","side":"Buy"}],"update":[{"price":"1.3859","symbol":"ADAUSDT","id":"13859","side":"Buy","size":3152.9998},{"price":"1.3865","symbol":"ADAUSDT","id":"13865","side":"Buy","size":1},{"price":"1.3863","symbol":"ADAUSDT","id":"13863","side":"Buy","size":3899},{"price":"1.3882","symbol":"ADAUSDT","id":"13882","side":"Sell","size":4958},{"price":"1.3864","symbol":"ADAUSDT","id":"13864","side":"Buy","size":4861},{"price":"1.3868","symbol":"ADAUSDT","id":"13868","side":"Buy","size":9443},{"price":"1.3862","symbol":"ADAUSDT","id":"13862","side":"Buy","size":4311},{"price":"1.3869","symbol":"ADAUSDT","id":"13869","side":"Buy","size":16869},{"price":"1.3861","symbol":"ADAUSDT","id":"13861","side":"Buy","size":4593},{"price":"1.3860","symbol":"ADAUSDT","id":"13860","side":"Buy","size":3924},{"price":"1.3870","symbol":"ADAUSDT","id":"13870","side":"Buy","size":5726.9995},{"price":"1.3878","symbol":"ADAUSDT","id":"13878","side":"Sell","size":6434},{"price":"1.3866","symbol":"ADAUSDT","id":"13866","side":"Buy","size":1171},{"price":"1.3867","symbol":"ADAUSDT","id":"13867","side":"Buy","size":4561},{"price":"1.3877","symbol":"ADAUSDT","id":"13877","side":"Sell","size":4356}],"insert":[{"price":"1.3873","symbol":"ADAUSDT","id":"13873","side":"Buy","size":5509}]},"cross_seq":"916954789","timestamp_e6":"1618677793282371"}
1618677793.374283: {"topic":"orderBookL2_25.BCHUSDT","type":"delta","data":{"delete":[{"price":"1055.55","symbol":"BCHUSDT","id":"10555500","side":"Sell"},{"price":"1054.85","symbol":"BCHUSDT","id":"10548500","side":"Buy"},{"price":"1054.90","symbol":"BCHUSDT","id":"10549000","side":"Buy"}],"update":[{"price":"1055.60","symbol":"BCHUSDT","id":"10556000","side":"Sell","size":17.6},{"price":"1055.75","symbol":"BCHUSDT","id":"10557500","side":"Sell","size":4.35},{"price":"1054.60","symbol":"BCHUSDT","id":"10546000","side":"Buy","size":7.56},{"price":"1054.65","symbol":"BCHUSDT","id":"10546500","side":"Buy","size":6.58},{"price":"1054.80","symbol":"BCHUSDT","id":"10548000","side":"Buy","size":10.07},{"price":"1055.65","symbol":"BCHUSDT","id":"10556500","side":"Sell","size":28.98},{"price":"1054.70","symbol":"BCHUSDT","id":"10547000","side":"Buy","size":13.2300005},{"price":"1054.75","symbol":"BCHUSDT","id":"10547500","side":"Buy","size":3.06},{"price":"1055.70","symbol":"BCHUSDT","id":"10557000","side":"Sell","size":13.51},{"price":"1054.55","symbol":"BCHUSDT","id":"10545500","side":"Buy","size":3.67}],"insert":[{"price":"1053.60","symbol":"BCHUSDT","id":"10536000","side":"Buy","size":4.35},{"price":"1055.50","symbol":"BCHUSDT","id":"10555000","side":"Sell","size":10.910001},{"price":"1053.65","symbol":"BCHUSDT","id":"10536500","side":"Buy","size":4.55}]},"cross_seq":"864133114","timestamp_e6":"1618677793290483"}
1618677793.381888: {"topic":"orderBookL2_25.LTCUSDT","type":"delta","data":{"delete":[{"price":"313.44","symbol":"LTCUSDT","id":"3134400","side":"Sell"},{"price":"313.49","symbol":"LTCUSDT","id":"3134900","side":"Sell"},{"price":"313.41","symbol":"LTCUSDT","id":"3134100","side":"Sell"},{"price":"313.46","symbol":"LTCUSDT","id":"3134600","side":"Sell"}],"update":[{"price":"313.43","symbol":"LTCUSDT","id":"3134300","side":"Sell","size":1.5},{"price":"313.42","symbol":"LTCUSDT","id":"3134200","side":"Sell","size":0.1},{"price":"313.45","symbol":"LTCUSDT","id":"3134500","side":"Sell","size":2},{"price":"313.52","symbol":"LTCUSDT","id":"3135200","side":"Sell","size":80.3},{"price":"313.50","symbol":"LTCUSDT","id":"3135000","side":"Sell","size":209.6}],"insert":[{"price":"313.68","symbol":"LTCUSDT","id":"3136800","side":"Sell","size":59.5},{"price":"313.67","symbol":"LTCUSDT","id":"3136700","side":"Sell","size":133.5},{"price":"313.66","symbol":"LTCUSDT","id":"3136600","side":"Sell","size":237.9},{"price":"313.48","symbol":"LTCUSDT","id":"3134800","side":"Sell","size":74.9}]},"cross_seq":"1684523679","timestamp_e6":"1618677793297904"}
1618677793.4048471: {"topic":"orderBookL2_25.LTCUSDT","type":"delta","data":{"delete":[],"update":[{"price":"313.34","symbol":"LTCUSDT","id":"3133400","side":"Buy","size":486.6}],"insert":[]},"cross_seq":"1684523680","timestamp_e6":"1618677793320388"}
1618677793.405837: {"topic":"orderBookL2_25.ADAUSDT","type":"delta","data":{"delete":[],"update":[{"price":"1.3890","symbol":"ADAUSDT","id":"13890","side":"Sell","size":5543}],"insert":[]},"cross_seq":"916954791","timestamp_e6":"1618677793322340"}
1618677793.408006: {"topic":"orderBookL2_25.LINKUSDT","type":"delta","data":{"delete":[],"update":[{"price":"41.063","symbol":"LINKUSDT","id":"410630","side":"Sell","size":292.3}],"insert":[]},"cross_seq":"1970980109","timestamp_e6":"1618677793324063"}
1618677793.413574: {"topic":"orderBookL2_25.BCHUSDT","type":"delta","data":{"delete":[{"price":"1053.65","symbol":"BCHUSDT","id":"10536500","side":"Buy"},{"price":"1053.60","symbol":"BCHUSDT","id":"10536000","side":"Buy"},{"price":"1056.65","symbol":"BCHUSDT","id":"10566500","side":"Sell"}],"update":[{"price":"1054.60","symbol":"BCHUSDT","id":"10546000","side":"Buy","size":9.63},{"price":"1054.65","symbol":"BCHUSDT","id":"10546500","side":"Buy","size":8.78},{"price":"1054.75","symbol":"BCHUSDT","id":"10547500","side":"Buy","size":5.19},{"price":"1055.75","symbol":"BCHUSDT","id":"10557500","side":"Sell","size":7.1},{"price":"1054.80","symbol":"BCHUSDT","id":"10548000","side":"Buy","size":5.84}],"insert":[{"price":"1054.90","symbol":"BCHUSDT","id":"10549000","side":"Buy","size":13.329999},{"price":"1054.85","symbol":"BCHUSDT","id":"10548500","side":"Buy","size":10.07},{"price":"1055.55","symbol":"BCHUSDT","id":"10555500","side":"Sell","size":8.76}]},"cross_seq":"864133123","timestamp_e6":"1618677793329970"}
1618677793.421133: {"topic":"orderBookL2_25.LTCUSDT","type":"delta","data":{"delete":[],"update":[{"price":"313.67","symbol":"LTCUSDT","id":"3136700","side":"Sell","size":19.6}],"insert":[]},"cross_seq":"1684523682","timestamp_e6":"1618677793337874"}
1618677793.426356: {"topic":"orderBookL2_25.ADAUSDT","type":"delta","data":{"delete":[],"update":[{"price":"1.3859","symbol":"ADAUSDT","id":"13859","side":"Buy","size":4039}],"insert":[]},"cross_seq":"916954792","timestamp_e6":"1618677793342332"}
1618677793.438606: {"topic":"orderBookL2_25.XTZUSDT","type":"delta","data":{"delete":[],"update":[{"price":"7.207","symbol":"XTZUSDT","id":"72070","side":"Buy","size":1371.1001},{"price":"7.210","symbol":"XTZUSDT","id":"72100","side":"Buy","size":257.30002},{"price":"7.206","symbol":"XTZUSDT","id":"72060","side":"Buy","size":589.6}],"insert":[]},"cross_seq":"726228551","timestamp_e6":"1618677793354763"}
1618677793.452589: {"topic":"orderBookL2_25.BCHUSDT","type":"delta","data":{"delete":[{"price":"1054.90","symbol":"BCHUSDT","id":"10549000","side":"Buy"}],"update":[],"insert":[{"price":"1053.65","symbol":"BCHUSDT","id":"10536500","side":"Buy","size":4.55}]},"cross_seq":"864133131","timestamp_e6":"1618677793370045"}
1618677793.466424: {"topic":"orderBookL2_25.DOTUSDT","type":"delta","data":{"delete":[],"update":[{"price":"43.560","symbol":"DOTUSDT","id":"435600","side":"Sell","size":1239.7999}],"insert":[]},"cross_seq":"916954793","timestamp_e6":"1618677793382585"}
1618677793.493073: {"topic":"orderBookL2_25.BCHUSDT","type":"delta","data":{"delete":[{"price":"1055.50","symbol":"BCHUSDT","id":"10555000","side":"Sell"},{"price":"1055.55","symbol":"BCHUSDT","id":"10555500","side":"Sell"},{"price":"1054.85","symbol":"BCHUSDT","id":"10548500","side":"Buy"}],"update":[{"price":"1055.70","symbol":"BCHUSDT","id":"10557000","side":"Sell","size":9.84},{"price":"1054.75","symbol":"BCHUSDT","id":"10547500","side":"Buy","size":2.13},{"price":"1054.70","symbol":"BCHUSDT","id":"10547000","side":"Buy","size":10.16},{"price":"1055.65","symbol":"BCHUSDT","id":"10556500","side":"Sell","size":26.83},{"price":"1054.65","symbol":"BCHUSDT","id":"10546500","side":"Buy","size":10.19},{"price":"1055.60","symbol":"BCHUSDT","id":"10556000","side":"Sell","size":19.310001}],"insert":[{"price":"1056.65","symbol":"BCHUSDT","id":"10566500","side":"Sell","size":16.9},{"price":"1054.90","symbol":"BCHUSDT","id":"10549000","side":"Buy","size":10.07},{"price":"1055.45","symbol":"BCHUSDT","id":"10554500","side":"Sell","size":10.910001}]},"cross_seq":"864133142","timestamp_e6":"1618677793409951"}
1618677793.510893: {"topic":"orderBookL2_25.ADAUSDT","type":"delta","data":{"delete":[],"update":[{"price":"1.3866","symbol":"ADAUSDT","id":"13866","side":"Buy","size":3662},{"price":"1.3867","symbol":"ADAUSDT","id":"13867","side":"Buy","size":6758},{"price":"1.3868","symbol":"ADAUSDT","id":"13868","side":"Buy","size":11965.999},{"price":"1.3869","symbol":"ADAUSDT","id":"13869","side":"Buy","size":21504},{"price":"1.3880","symbol":"ADAUSDT","id":"13880","side":"Sell","size":2335},{"price":"1.3870","symbol":"ADAUSDT","id":"13870","side":"Buy","size":1},{"price":"1.3879","symbol":"ADAUSDT","id":"13879","side":"Sell","size":4750},{"price":"1.3881","symbol":"ADAUSDT","id":"13881","side":"Sell","size":3390}],"insert":[]},"cross_seq":"916954803","timestamp_e6":"1618677793422336"}
1618677793.511858: {"topic":"orderBookL2_25.ETHUSDT","type":"delta","data":{"delete":[],"update":[{"price":"2364.15","symbol":"ETHUSDT","id":"23641500","side":"Buy","size":194},{"price":"2364.05","symbol":"ETHUSDT","id":"23640500","side":"Buy","size":95.399994},{"price":"2364.00","symbol":"ETHUSDT","id":"23640000","side":"Buy","size":38.61},{"price":"2365.10","symbol":"ETHUSDT","id":"23651000","side":"Sell","size":160.96},{"price":"2365.20","symbol":"ETHUSDT","id":"23652000","side":"Sell","size":89.42},{"price":"2364.10","symbol":"ETHUSDT","id":"23641000","side":"Buy","size":166.89},{"price":"2365.05","symbol":"ETHUSDT","id":"23650500","side":"Sell","size":160.27},{"price":"2365.15","symbol":"ETHUSDT","id":"23651500","side":"Sell","size":112.170006},{"price":"2363.90","symbol":"ETHUSDT","id":"23639000","side":"Buy","size":13.08},{"price":"2363.95","symbol":"ETHUSDT","id":"23639500","side":"Buy","size":38.87}],"insert":[]},"cross_seq":"1800546829","timestamp_e6":"1618677793427652"}
1618677793.527916: {"topic":"orderBookL2_25.ADAUSDT","type":"delta","data":{"delete":[{"price":"1.3873","symbol":"ADAUSDT","id":"13873","side":"Buy"},{"price":"1.3865","symbol":"ADAUSDT","id":"13865","side":"Buy"}],"update":[{"price":"1.3868","symbol":"ADAUSDT","id":"13868","side":"Buy","size":11965.001},{"price":"1.3880","symbol":"ADAUSDT","id":"13880","side":"Sell","size":3321.9998},{"price":"1.3870","symbol":"ADAUSDT","id":"13870","side":"Buy","size":4054},{"price":"1.3867","symbol":"ADAUSDT","id":"13867","side":"Buy","size":4197},{"price":"1.3864","symbol":"ADAUSDT","id":"13864","side":"Buy","size":4860},{"price":"1.3879","symbol":"ADAUSDT","id":"13879","side":"Sell","size":4749},{"price":"1.3883","symbol":"ADAUSDT","id":"13883","side":"Sell","size":1798}],"insert":[{"price":"1.3849","symbol":"ADAUSDT","id":"13849","side":"Buy","size":2018.0001},{"price":"1.3848","symbol":"ADAUSDT","id":"13848","side":"Buy","size":3559}]},"cross_seq":"916954820","timestamp_e6":"1618677793442346"}
1618677793.532799: {"topic":"orderBookL2_25.BCHUSDT","type":"delta","data":{"delete":[{"price":"1053.65","symbol":"BCHUSDT","id":"10536500","side":"Buy"},{"price":"1055.45","symbol":"BCHUSDT","id":"10554500","side":"Sell"},{"price":"1056.50","symbol":"BCHUSDT","id":"10565000","side":"Sell"},{"price":"1056.65","symbol":"BCHUSDT","id":"10566500","side":"Sell"},{"price":"1056.55","symbol":"BCHUSDT","id":"10565500","side":"Sell"},{"price":"1056.60","symbol":"BCHUSDT","id":"10566000","side":"Sell"}],"update":[{"price":"1054.70","symbol":"BCHUSDT","id":"10547000","side":"Buy","size":12.36},{"price":"1054.75","symbol":"BCHUSDT","id":"10547500","side":"Buy","size":2.92}],"insert":[{"price":"1055.35","symbol":"BCHUSDT","id":"10553500","side":"Sell","size":7.41},{"price":"1055.40","symbol":"BCHUSDT","id":"10554000","side":"Sell","size":4.67},{"price":"1054.85","symbol":"BCHUSDT","id":"10548500","side":"Buy","size":6.7},{"price":"1055.20","symbol":"BCHUSDT","id":"10552000","side":"Sell","size":10.910001},{"price":"1055.25","symbol":"BCHUSDT","id":"10552500","side":"Sell","size":8.76},{"price":"1055.30","symbol":"BCHUSDT","id":"10553000","side":"Sell","size":6.86}]},"cross_seq":"864133154","timestamp_e6":"1618677793449494"}
1618677793.55256: {"topic":"orderBookL2_25.BCHUSDT","type":"delta","data":{"delete":[{"price":"1056.40","symbol":"BCHUSDT","id":"10564000","side":"Sell"},{"price":"1056.45","symbol":"BCHUSDT","id":"10564500","side":"Sell"},{"price":"1056.35","symbol":"BCHUSDT","id":"10563500","side":"Sell"}],"update":[],"insert":[{"price":"1055.50","symbol":"BCHUSDT","id":"10555000","side":"Sell","size":8.76},{"price":"1055.55","symbol":"BCHUSDT","id":"10555500","side":"Sell","size":6.86},{"price":"1055.45","symbol":"BCHUSDT","id":"10554500","side":"Sell","size":10.910001}]},"cross_seq":"864133165","timestamp_e6":"1618677793469303"}
1618677793.567152: {"topic":"orderBookL2_25.ADAUSDT","type":"delta","data":{"delete":[{"price":"1.3871","symbol":"ADAUSDT","id":"13871","side":"Buy"}],"update":[{"price":"1.3885","symbol":"ADAUSDT","id":"13885","side":"Sell","size":3385},{"price":"1.3867","symbol":"ADAUSDT","id":"13867","side":"Buy","size":5662},{"price":"1.3882","symbol":"ADAUSDT","id":"13882","side":"Sell","size":2885}],"insert":[{"price":"1.3847","symbol":"ADAUSDT","id":"13847","side":"Buy","size":4462}]},"cross_seq":"916954824","timestamp_e6":"1618677793482326"}
1618677793.582881: {"topic":"orderBookL2_25.LTCUSDT","type":"delta","data":{"delete":[],"update":[{"price":"313.56","symbol":"LTCUSDT","id":"3135600","side":"Sell","size":221.8}],"insert":[]},"cross_seq":"1684523683","timestamp_e6":"1618677793497916"}
1618677793.5873559: {"topic":"orderBookL2_25.DOTUSDT","type":"delta","data":{"delete":[{"price":"43.415","symbol":"DOTUSDT","id":"434150","side":"Buy"}],"update":[{"price":"43.530","symbol":"DOTUSDT","id":"435300","side":"Buy","size":424.50003}],"insert":[{"price":"43.535","symbol":"DOTUSDT","id":"435350","side":"Buy","size":371.7}]},"cross_seq":"916954836","timestamp_e6":"1618677793502391"}
1618677793.587404: {"topic":"orderBookL2_25.ADAUSDT","type":"delta","data":{"delete":[{"price":"1.3872","symbol":"ADAUSDT","id":"13872","side":"Buy"}],"update":[{"price":"1.3883","symbol":"ADAUSDT","id":"13883","side":"Sell","size":3216},{"price":"1.3884","symbol":"ADAUSDT","id":"13884","side":"Sell","size":3182},{"price":"1.3882","symbol":"ADAUSDT","id":"13882","side":"Sell","size":1815.9999},{"price":"1.3885","symbol":"ADAUSDT","id":"13885","side":"Sell","size":3841},{"price":"1.3886","symbol":"ADAUSDT","id":"13886","side":"Sell","size":944.00006}],"insert":[{"price":"1.3871","symbol":"ADAUSDT","id":"13871","side":"Buy","size":5070}]},"cross_seq":"916954836","timestamp_e6":"1618677793502274"}
1618677793.607487: {"topic":"orderBookL2_25.ADAUSDT","type":"delta","data":{"delete":[],"update":[{"price":"1.3883","symbol":"ADAUSDT","id":"13883","side":"Sell","size":4401},{"price":"1.3884","symbol":"ADAUSDT","id":"13884","side":"Sell","size":4481},{"price":"1.3882","symbol":"ADAUSDT","id":"13882","side":"Sell","size":1653},{"price":"1.3886","symbol":"ADAUSDT","id":"13886","side":"Sell","size":1817},{"price":"1.3885","symbol":"ADAUSDT","id":"13885","side":"Sell","size":4718}],"insert":[]},"cross_seq":"916954858","timestamp_e6":"1618677793522378"}
1618677793.622916: {"topic":"orderBookL2_25.LTCUSDT","type":"delta","data":{"delete":[],"update":[{"price":"313.56","symbol":"LTCUSDT","id":"3135600","side":"Sell","size":171.8}],"insert":[]},"cross_seq":"1684523684","timestamp_e6":"1618677793537908"}
1618677793.6279511: {"topic":"orderBookL2_25.ADAUSDT","type":"delta","data":{"delete":[{"price":"1.3847","symbol":"ADAUSDT","id":"13847","side":"Buy"},{"price":"1.3877","symbol":"ADAUSDT","id":"13877","side":"Sell"}],"update":[{"price":"1.3887","symbol":"ADAUSDT","id":"13887","side":"Sell","size":2113},{"price":"1.3879","symbol":"ADAUSDT","id":"13879","side":"Sell","size":2198},{"price":"1.3882","symbol":"ADAUSDT","id":"13882","side":"Sell","size":5665},{"price":"1.3880","symbol":"ADAUSDT","id":"13880","side":"Sell","size":2335},{"price":"1.3881","symbol":"ADAUSDT","id":"13881","side":"Sell","size":1417},{"price":"1.3886","symbol":"ADAUSDT","id":"13886","side":"Sell","size":3790},{"price":"1.3878","symbol":"ADAUSDT","id":"13878","side":"Sell","size":4101}],"insert":[{"price":"1.3901","symbol":"ADAUSDT","id":"13901","side":"Sell","size":6684.9995},{"price":"1.3872","symbol":"ADAUSDT","id":"13872","side":"Buy","size":5070}]},"cross_seq":"916954871","timestamp_e6":"1618677793542444"}
1618677793.63278: {"topic":"orderBookL2_25.BCHUSDT","type":"delta","data":{"delete":[{"price":"1055.20","symbol":"BCHUSDT","id":"10552000","side":"Sell"},{"price":"1055.45","symbol":"BCHUSDT","id":"10554500","side":"Sell"},{"price":"1055.50","symbol":"BCHUSDT","id":"10555000","side":"Sell"}],"update":[{"price":"1055.30","symbol":"BCHUSDT","id":"10553000","side":"Sell","size":8.76},{"price":"1055.40","symbol":"BCHUSDT","id":"10554000","side":"Sell","size":7.41}],"insert":[{"price":"1056.35","symbol":"BCHUSDT","id":"10563500","side":"Sell","size":15.590001},{"price":"1056.45","symbol":"BCHUSDT","id":"10564500","side":"Sell","size":16.609999},{"price":"1056.40","symbol":"BCHUSDT","id":"10564000","side":"Sell","size":1}]},"cross_seq":"864133178","timestamp_e6":"1618677793549377"}
1618677793.644869: {"topic":"orderBookL2_25.LTCUSDT","type":"delta","data":{"delete":[{"price":"313.68","symbol":"LTCUSDT","id":"3136800","side":"Sell"}],"update":[{"price":"313.50","symbol":"LTCUSDT","id":"3135000","side":"Sell","size":162.8},{"price":"313.52","symbol":"LTCUSDT","id":"3135200","side":"Sell","size":123},{"price":"313.35","symbol":"LTCUSDT","id":"3133500","side":"Sell","size":2.1}],"insert":[{"price":"313.49","symbol":"LTCUSDT","id":"3134900","side":"Sell","size":51.6}]},"cross_seq":"1684523688","timestamp_e6":"1618677793559092"}
1618677793.652076: {"topic":"orderBookL2_25.ETHUSDT","type":"delta","data":{"delete":[],"update":[{"price":"2364.40","symbol":"ETHUSDT","id":"23644000","side":"Buy","size":6.19},{"price":"2364.90","symbol":"ETHUSDT","id":"23649000","side":"Buy","size":51.420002}],"insert":[]},"cross_seq":"1800546830","timestamp_e6":"1618677793568258"}
1618677793.658609: {"topic":"orderBookL2_25.XTZUSDT","type":"delta","data":{"delete":[],"update":[{"price":"7.205","symbol":"XTZUSDT","id":"72050","side":"Buy","size":505.4},{"price":"7.201","symbol":"XTZUSDT","id":"72010","side":"Buy","size":927}],"insert":[]},"cross_seq":"726228553","timestamp_e6":"1618677793574639"}
1618677793.662766: {"topic":"orderBookL2_25.LTCUSDT","type":"delta","data":{"delete":[{"price":"313.48","symbol":"LTCUSDT","id":"3134800","side":"Sell"},{"price":"313.67","symbol":"LTCUSDT","id":"3136700","side":"Sell"}],"update":[{"price":"313.47","symbol":"LTCUSDT","id":"3134700","side":"Sell","size":73.9},{"price":"313.43","symbol":"LTCUSDT","id":"3134300","side":"Sell","size":132.5},{"price":"313.45","symbol":"LTCUSDT","id":"3134500","side":"Sell","size":53.6}],"insert":[{"price":"313.46","symbol":"LTCUSDT","id":"3134600","side":"Sell","size":47.000004},{"price":"313.44","symbol":"LTCUSDT","id":"3134400","side":"Sell","size":74.9}]},"cross_seq":"1684523711","timestamp_e6":"1618677793577878"}
1618677793.667454: {"topic":"orderBookL2_25.ADAUSDT","type":"delta","data":{"delete":[{"price":"1.3870","symbol":"ADAUSDT","id":"13870","side":"Buy"}],"update":[{"price":"1.3867","symbol":"ADAUSDT","id":"13867","side":"Buy","size":6757}],"insert":[{"price":"1.3847","symbol":"ADAUSDT","id":"13847","side":"Buy","size":4462}]},"cross_seq":"916954877","timestamp_e6":"1618677793582363"}
1618677793.667503: {"topic":"orderBookL2_25.LINKUSDT","type":"delta","data":{"delete":[],"update":[{"price":"41.031","symbol":"LINKUSDT","id":"410310","side":"Buy","size":221.00002},{"price":"41.034","symbol":"LINKUSDT","id":"410340","side":"Buy","size":312},{"price":"41.068","symbol":"LINKUSDT","id":"410680","side":"Sell","size":348.8},{"price":"41.066","symbol":"LINKUSDT","id":"410660","side":"Sell","size":610.5},{"price":"41.030","symbol":"LINKUSDT","id":"410300","side":"Buy","size":193.7},{"price":"41.032","symbol":"LINKUSDT","id":"410320","side":"Buy","size":559.7}],"insert":[]},"cross_seq":"1970980115","timestamp_e6":"1618677793583830"}
1618677793.679519: {"topic":"orderBookL2_25.XTZUSDT","type":"delta","data":{"delete":[],"update":[{"price":"7.211","symbol":"XTZUSDT","id":"72110","side":"Buy","size":853.39996},{"price":"7.212","symbol":"XTZUSDT","id":"72120","side":"Sell","size":10574.8}],"insert":[]},"cross_seq":"726228556","timestamp_e6":"1618677793595896"}
1618677793.683959: {"topic":"orderBookL2_25.LTCUSDT","type":"delta","data":{"delete":[{"price":"313.44","symbol":"LTCUSDT","id":"3134400","side":"Sell"}],"update":[{"price":"313.45","symbol":"LTCUSDT","id":"3134500","side":"Sell","size":76.9},{"price":"313.47","symbol":"LTCUSDT","id":"3134700","side":"Sell","size":5}],"insert":[{"price":"313.48","symbol":"LTCUSDT","id":"3134800","side":"Sell","size":59.699997}]},"cross_seq":"1684523717","timestamp_e6":"1618677793598745"}
1618677793.701018: {"topic":"orderBookL2_25.XTZUSDT","type":"delta","data":{"delete":[{"price":"7.205","symbol":"XTZUSDT","id":"72050","side":"Buy"},{"price":"7.210","symbol":"XTZUSDT","id":"72100","side":"Buy"},{"price":"7.211","symbol":"XTZUSDT","id":"72110","side":"Buy"},{"price":"7.236","symbol":"XTZUSDT","id":"72360","side":"Sell"}],"update":[{"price":"7.202","symbol":"XTZUSDT","id":"72020","side":"Buy","size":1962.4999},{"price":"7.196","symbol":"XTZUSDT","id":"71960","side":"Buy","size":2087.9},{"price":"7.199","symbol":"XTZUSDT","id":"71990","side":"Buy","size":1908.4},{"price":"7.215","symbol":"XTZUSDT","id":"72150","side":"Sell","size":837.2},{"price":"7.212","symbol":"XTZUSDT","id":"72120","side":"Sell","size":10144.8},{"price":"7.206","symbol":"XTZUSDT","id":"72060","side":"Buy","size":831.3},{"price":"7.201","symbol":"XTZUSDT","id":"72010","side":"Buy","size":749.2},{"price":"7.214","symbol":"XTZUSDT","id":"72140","side":"Sell","size":2444.5999},{"price":"7.213","symbol":"XTZUSDT","id":"72130","side":"Sell","size":0.4},{"price":"7.204","symbol":"XTZUSDT","id":"72040","side":"Buy","size":1358.5},{"price":"7.203","symbol":"XTZUSDT","id":"72030","side":"Buy","size":1451.2001}],"insert":[{"price":"7.210","symbol":"XTZUSDT","id":"72100","side":"Sell","size":817.30005},{"price":"7.186","symbol":"XTZUSDT","id":"71860","side":"Buy","size":663.4},{"price":"7.184","symbol":"XTZUSDT","id":"71840","side":"Buy","size":389},{"price":"7.185","symbol":"XTZUSDT","id":"71850","side":"Buy","size":1327.3}]},"cross_seq":"726228631","timestamp_e6":"1618677793615814"}
1618677793.708287: {"topic":"orderBookL2_25.ADAUSDT","type":"delta","data":{"delete":[{"price":"1.3847","symbol":"ADAUSDT","id":"13847","side":"Buy"},{"price":"1.3871","symbol":"ADAUSDT","id":"13871","side":"Buy"}],"update":[{"price":"1.3869","symbol":"ADAUSDT","id":"13869","side":"Buy","size":16869},{"price":"1.3881","symbol":"ADAUSDT","id":"13881","side":"Sell","size":5429},{"price":"1.3868","symbol":"ADAUSDT","id":"13868","side":"Buy","size":10434},{"price":"1.3882","symbol":"ADAUSDT","id":"13882","side":"Sell","size":1653},{"price":"1.3886","symbol":"ADAUSDT","id":"13886","side":"Sell","size":1817},{"price":"1.3885","symbol":"ADAUSDT","id":"13885","side":"Sell","size":5704},{"price":"1.3884","symbol":"ADAUSDT","id":"13884","side":"Sell","size":2242}],"insert":[{"price":"1.3873","symbol":"ADAUSDT","id":"13873","side":"Buy","size":5070},{"price":"1.3870","symbol":"ADAUSDT","id":"13870","side":"Buy","size":4757}]},"cross_seq":"916954888","timestamp_e6":"1618677793622373"}
1618677793.7225878: {"topic":"orderBookL2_25.LTCUSDT","type":"delta","data":{"delete":[{"price":"313.48","symbol":"LTCUSDT","id":"3134800","side":"Sell"}],"update":[{"price":"313.45","symbol":"LTCUSDT","id":"3134500","side":"Sell","size":25.3},{"price":"313.47","symbol":"LTCUSDT","id":"3134700","side":"Sell","size":64.700005}],"insert":[{"price":"313.44","symbol":"LTCUSDT","id":"3134400","side":"Sell","size":74.9}]},"cross_seq":"1684523721","timestamp_e6":"1618677793637978"}
1618677793.728339: {"topic":"orderBookL2_25.UNIUSDT","type":"delta","data":{"delete":[],"update":[{"price":"35.376","symbol":"UNIUSDT","id":"353760","side":"Buy","size":108.2},{"price":"35.373","symbol":"UNIUSDT","id":"353730","side":"Buy","size":59.699997},{"price":"35.374","symbol":"UNIUSDT","id":"353740","side":"Buy","size":41.699997},{"price":"35.375","symbol":"UNIUSDT","id":"353750","side":"Buy","size":76.600006},{"price":"35.404","symbol":"UNIUSDT","id":"354040","side":"Sell","size":109.9},{"price":"35.377","symbol":"UNIUSDT","id":"353770","side":"Buy","size":37.2}],"insert":[]},"cross_seq":"916954927","timestamp_e6":"1618677793642464"}
1618677793.740119: {"topic":"orderBookL2_25.XTZUSDT","type":"delta","data":{"delete":[{"price":"7.235","symbol":"XTZUSDT","id":"72350","side":"Sell"},{"price":"7.184","symbol":"XTZUSDT","id":"71840","side":"Buy"}],"update":[{"price":"7.212","symbol":"XTZUSDT","id":"72120","side":"Sell","size":4625.5},{"price":"7.206","symbol":"XTZUSDT","id":"72060","side":"Buy","size":1256.5},{"price":"7.209","symbol":"XTZUSDT","id":"72090","side":"Buy","size":974.5},{"price":"7.203","symbol":"XTZUSDT","id":"72030","side":"Buy","size":1253.1},{"price":"7.213","symbol":"XTZUSDT","id":"72130","side":"Sell","size":427.4},{"price":"7.202","symbol":"XTZUSDT","id":"72020","side":"Buy","size":1597.4},{"price":"7.207","symbol":"XTZUSDT","id":"72070","side":"Buy","size":1675.7},{"price":"7.210","symbol":"XTZUSDT","id":"72100","side":"Sell","size":7667.3},{"price":"7.208","symbol":"XTZUSDT","id":"72080","side":"Buy","size":756.60004}],"insert":[{"price":"7.211","symbol":"XTZUSDT","id":"72110","side":"Sell","size":718.30005},{"price":"7.205","symbol":"XTZUSDT","id":"72050","side":"Buy","size":543.6}]},"cross_seq":"726228672","timestamp_e6":"1618677793655824"}
1618677793.7460659: {"topic":"trade.XTZUSDT","data":[{"symbol":"XTZUSDT","tick_direction":"ZeroPlusTick","price":"7.211","size":0.2,"timestamp":"2021-04-17T16:43:13.000Z","trade_time_ms":"1618677793569","side":"Sell","trade_id":"549eb6c6-0fce-56b8-b5fe-002573afd929"},{"symbol":"XTZUSDT","tick_direction":"ZeroPlusTick","price":"7.211","size":5,"timestamp":"2021-04-17T16:43:13.000Z","trade_time_ms":"1618677793569","side":"Sell","trade_id":"36acefc0-f385-5626-9100-250540395b4c"},{"symbol":"XTZUSDT","tick_direction":"ZeroPlusTick","price":"7.211","size":0.8,"timestamp":"2021-04-17T16:43:13.000Z","trade_time_ms":"1618677793570","side":"Sell","trade_id":"9bc9600a-cf61-5349-9a5c-89041ef9a029"}]}
1618677793.7581959: {"topic":"orderBookL2_25.XTZUSDT","type":"delta","data":{"delete":[],"update":[{"price":"7.212","symbol":"XTZUSDT","id":"72120","side":"Sell","size":4001.0999},{"price":"7.213","symbol":"XTZUSDT","id":"72130","side":"Sell","size":0.4}],"insert":[]},"cross_seq":"726228722","timestamp_e6":"1618677793674506"}
1618677793.761374: {"topic":"orderBookL2_25.LTCUSDT","type":"delta","data":{"delete":[{"price":"313.66","symbol":"LTCUSDT","id":"3136600","side":"Sell"}],"update":[{"price":"313.44","symbol":"LTCUSDT","id":"3134400","side":"Sell","size":56.1},{"price":"313.47","symbol":"LTCUSDT","id":"3134700","side":"Sell","size":5},{"price":"313.45","symbol":"LTCUSDT","id":"3134500","side":"Sell","size":76.9}],"insert":[{"price":"313.48","symbol":"LTCUSDT","id":"3134800","side":"Sell","size":59.699997}]},"cross_seq":"1684523726","timestamp_e6":"1618677793677868"}
1618677793.766686: {"topic":"orderBookL2_25.ADAUSDT","type":"delta","data":{"delete":[{"price":"1.3872","symbol":"ADAUSDT","id":"13872","side":"Buy"}],"update":[{"price":"1.3881","symbol":"ADAUSDT","id":"13881","side":"Sell","size":1417},{"price":"1.3882","symbol":"ADAUSDT","id":"13882","side":"Sell","size":3891.9998},{"price":"1.3883","symbol":"ADAUSDT","id":"13883","side":"Sell","size":2198},{"price":"1.3885","symbol":"ADAUSDT","id":"13885","side":"Sell","size":5173},{"price":"1.3869","symbol":"ADAUSDT","id":"13869","side":"Buy","size":21626},{"price":"1.3868","symbol":"ADAUSDT","id":"13868","side":"Buy","size":11573},{"price":"1.3884","symbol":"ADAUSDT","id":"13884","side":"Sell","size":4215},{"price":"1.3880","symbol":"ADAUSDT","id":"13880","side":"Sell","size":6346.9995}],"insert":[{"price":"1.3871","symbol":"ADAUSDT","id":"13871","side":"Buy","size":4635}]},"cross_seq":"916954947","timestamp_e6":"1618677793682605"}
1618677793.769093: {"topic":"orderBookL2_25.UNIUSDT","type":"delta","data":{"delete":[],"update":[{"price":"35.403","symbol":"UNIUSDT","id":"354030","side":"Sell","size":143.7},{"price":"35.402","symbol":"UNIUSDT","id":"354020","side":"Sell","size":376.4},{"price":"35.406","symbol":"UNIUSDT","id":"354060","side":"Sell","size":102.4},{"price":"35.407","symbol":"UNIUSDT","id":"354070","side":"Sell","size":75.7},{"price":"35.405","symbol":"UNIUSDT","id":"354050","side":"Sell","size":129.40001},{"price":"35.404","symbol":"UNIUSDT","id":"354040","side":"Sell","size":125},{"price":"35.371","symbol":"UNIUSDT","id":"353710","side":"Buy","size":40.4},{"price":"35.372","symbol":"UNIUSDT","id":"353720","side":"Buy","size":20.6}],"insert":[]},"cross_seq":"916954947","timestamp_e6":"1618677793682781"}
1618677793.7699358: {"topic":"orderBookL2_25.ETHUSDT","type":"delta","data":{"delete":[],"update":[{"price":"2363.95","symbol":"ETHUSDT","id":"23639500","side":"Buy","size":71.65},{"price":"2364.00","symbol":"ETHUSDT","id":"23640000","side":"Buy","size":73.67},{"price":"2363.90","symbol":"ETHUSDT","id":"23639000","side":"Buy","size":31.660002}],"insert":[]},"cross_seq":"1800546833","timestamp_e6":"1618677793687114"}
1618677793.7804701: {"topic":"orderBookL2_25.XTZUSDT","type":"delta","data":{"delete":[],"update":[{"price":"7.212","symbol":"XTZUSDT","id":"72120","side":"Sell","size":1.1}],"insert":[]},"cross_seq":"726228723","timestamp_e6":"1618677793694892"}
1618677793.7838058: {"topic":"orderBookL2_25.LTCUSDT","type":"delta","data":{"delete":[],"update":[{"price":"313.34","symbol":"LTCUSDT","id":"3133400","side":"Buy","size":482.40002},{"price":"313.55","symbol":"LTCUSDT","id":"3135500","side":"Sell","size":22.8},{"price":"313.51","symbol":"LTCUSDT","id":"3135100","side":"Sell","size":137.6},{"price":"313.53","symbol":"LTCUSDT","id":"3135300","side":"Sell","size":86.299995},{"price":"313.54","symbol":"LTCUSDT","id":"3135400","side":"Sell","size":92.2}],"insert":[]},"cross_seq":"1684523732","timestamp_e6":"1618677793699130"}
1618677793.7977312: {"topic":"orderBookL2_25.XTZUSDT","type":"delta","data":{"delete":[],"update":[{"price":"7.212","symbol":"XTZUSDT","id":"72120","side":"Sell","size":428.1},{"price":"7.202","symbol":"XTZUSDT","id":"72020","side":"Buy","size":1899.7001},{"price":"7.231","symbol":"XTZUSDT","id":"72310","side":"Sell","size":1960.2},{"price":"7.205","symbol":"XTZUSDT","id":"72050","side":"Buy","size":345.6},{"price":"7.213","symbol":"XTZUSDT","id":"72130","side":"Sell","size":251.09999},{"price":"7.201","symbol":"XTZUSDT","id":"72010","side":"Buy","size":887.1}],"insert":[]},"cross_seq":"726228732","timestamp_e6":"1618677793714579"}
1618677793.806253: {"topic":"orderBookL2_25.DOTUSDT","type":"delta","data":{"delete":[],"update":[{"price":"43.585","symbol":"DOTUSDT","id":"435850","side":"Sell","size":407.80002},{"price":"43.580","symbol":"DOTUSDT","id":"435800","side":"Sell","size":289.5},{"price":"43.575","symbol":"DOTUSDT","id":"435750","side":"Sell","size":487.1},{"price":"43.480","symbol":"DOTUSDT","id":"434800","side":"Buy","size":393.6},{"price":"43.485","symbol":"DOTUSDT","id":"434850","side":"Buy","size":54.4}],"insert":[]},"cross_seq":"916954954","timestamp_e6":"1618677793722669"}
1618677793.8160908: {"topic":"trade.LTCUSDT","data":[{"symbol":"LTCUSDT","tick_direction":"PlusTick","price":"313.34","size":4.2,"timestamp":"2021-04-17T16:43:13.000Z","trade_time_ms":"1618677793684","side":"Sell","trade_id":"9f0d43ad-bc61-5b97-bbeb-c507c16f55ba"}]}
1618677793.826412: {"topic":"orderBookL2_25.ADAUSDT","type":"delta","data":{"delete":[{"price":"1.3873","symbol":"ADAUSDT","id":"13873","side":"Buy"},{"price":"1.3870","symbol":"ADAUSDT","id":"13870","side":"Buy"},{"price":"1.3901","symbol":"ADAUSDT","id":"13901","side":"Sell"}],"update":[{"price":"1.3880","symbol":"ADAUSDT","id":"13880","side":"Sell","size":2335},{"price":"1.3879","symbol":"ADAUSDT","id":"13879","side":"Sell","size":3185},{"price":"1.3881","symbol":"ADAUSDT","id":"13881","side":"Sell","size":2732},{"price":"1.3878","symbol":"ADAUSDT","id":"13878","side":"Sell","size":6340},{"price":"1.3876","symbol":"ADAUSDT","id":"13876","side":"Sell","size":4013}],"insert":[{"price":"1.3846","symbol":"ADAUSDT","id":"13846","side":"Buy","size":1015},{"price":"1.3877","symbol":"ADAUSDT","id":"13877","side":"Sell","size":2203},{"price":"1.3847","symbol":"ADAUSDT","id":"13847","side":"Buy","size":4462}]},"cross_seq":"916954962","timestamp_e6":"1618677793742344"}
1618677793.840885: {"topic":"orderBookL2_25.LTCUSDT","type":"delta","data":{"delete":[{"price":"313.48","symbol":"LTCUSDT","id":"3134800","side":"Sell"}],"update":[{"price":"313.44","symbol":"LTCUSDT","id":"3134400","side":"Sell","size":74.9},{"price":"313.47","symbol":"LTCUSDT","id":"3134700","side":"Sell","size":64.700005},{"price":"313.45","symbol":"LTCUSDT","id":"3134500","side":"Sell","size":53.6}],"insert":[{"price":"313.66","symbol":"LTCUSDT","id":"3136600","side":"Sell","size":237.9}]},"cross_seq":"1684523736","timestamp_e6":"1618677793757900"}
1618677793.84623: {"topic":"orderBookL2_25.DOTUSDT","type":"delta","data":{"delete":[],"update":[{"price":"43.575","symbol":"DOTUSDT","id":"435750","side":"Sell","size":655.9}],"insert":[]},"cross_seq":"916954982","timestamp_e6":"1618677793762452"}
1618677793.847209: {"topic":"orderBookL2_25.ADAUSDT","type":"delta","data":{"delete":[{"price":"1.3880","symbol":"ADAUSDT","id":"13880","side":"Sell"}],"update":[{"price":"1.3859","symbol":"ADAUSDT","id":"13859","side":"Buy","size":5707},{"price":"1.3885","symbol":"ADAUSDT","id":"13885","side":"Sell","size":6491},{"price":"1.3860","symbol":"ADAUSDT","id":"13860","side":"Buy","size":6408},{"price":"1.3878","symbol":"ADAUSDT","id":"13878","side":"Sell","size":2239},{"price":"1.3887","symbol":"ADAUSDT","id":"13887","side":"Sell","size":2945},{"price":"1.3857","symbol":"ADAUSDT","id":"13857","side":"Buy","size":9092},{"price":"1.3879","symbol":"ADAUSDT","id":"13879","side":"Sell","size":987},{"price":"1.3883","symbol":"ADAUSDT","id":"13883","side":"Sell","size":3304},{"price":"1.3881","symbol":"ADAUSDT","id":"13881","side":"Sell","size":1315},{"price":"1.3858","symbol":"ADAUSDT","id":"13858","side":"Buy","size":7565},{"price":"1.3861","symbol":"ADAUSDT","id":"13861","side":"Buy","size":6192},{"price":"1.3882","symbol":"ADAUSDT","id":"13882","side":"Sell","size":7163.9995}],"insert":[{"price":"1.3901","symbol":"ADAUSDT","id":"13901","side":"Sell","size":6684.9995}]},"cross_seq":"916954982","timestamp_e6":"1618677793762339"}
1618677793.8601868: {"topic":"orderBookL2_25.XTZUSDT","type":"delta","data":{"delete":[],"update":[{"price":"7.216","symbol":"XTZUSDT","id":"72160","side":"Sell","size":707.50006}],"insert":[]},"cross_seq":"726228777","timestamp_e6":"1618677793775374"}
1618677793.8667252: {"topic":"orderBookL2_25.ADAUSDT","type":"delta","data":{"delete":[],"update":[{"price":"1.3862","symbol":"ADAUSDT","id":"13862","side":"Buy","size":6222.9995}],"insert":[]},"cross_seq":"916954983","timestamp_e6":"1618677793782321"}
1618677793.879053: {"topic":"orderBookL2_25.XTZUSDT","type":"delta","data":{"delete":[],"update":[{"price":"7.202","symbol":"XTZUSDT","id":"72020","side":"Buy","size":1113.7999}],"insert":[]},"cross_seq":"726228778","timestamp_e6":"1618677793794537"}
1618677793.896278: {"topic":"orderBookL2_25.BCHUSDT","type":"delta","data":{"delete":[{"price":"1056.45","symbol":"BCHUSDT","id":"10564500","side":"Sell"},{"price":"1056.40","symbol":"BCHUSDT","id":"10564000","side":"Sell"}],"update":[],"insert":[{"price":"1055.50","symbol":"BCHUSDT","id":"10555000","side":"Sell","size":2.75},{"price":"1055.45","symbol":"BCHUSDT","id":"10554500","side":"Sell","size":4.67}]},"cross_seq":"864133185","timestamp_e6":"1618677793808871"}
1618677793.8987699: {"topic":"orderBookL2_25.XTZUSDT","type":"delta","data":{"delete":[{"price":"7.211","symbol":"XTZUSDT","id":"72110","side":"Sell"}],"update":[{"price":"7.207","symbol":"XTZUSDT","id":"72070","side":"Buy","size":786.5},{"price":"7.205","symbol":"XTZUSDT","id":"72050","side":"Buy","size":889.2},{"price":"7.212","symbol":"XTZUSDT","id":"72120","side":"Sell","size":1.1},{"price":"7.200","symbol":"XTZUSDT","id":"72000","side":"Buy","size":1083.6},{"price":"7.206","symbol":"XTZUSDT","id":"72060","side":"Buy","size":589.6},{"price":"7.210","symbol":"XTZUSDT","id":"72100","side":"Sell","size":6850.0005}],"insert":[{"price":"7.235","symbol":"XTZUSDT","id":"72350","side":"Sell","size":561.3}]},"cross_seq":"726228791","timestamp_e6":"1618677793815166"}
1618677793.92909: {"topic":"orderBookL2_25.LINKUSDT","type":"delta","data":{"delete":[],"update":[{"price":"41.068","symbol":"LINKUSDT","id":"410680","side":"Sell","size":427.5}],"insert":[]},"cross_seq":"1970980116","timestamp_e6":"1618677793843715"}
1618677793.933394: {"topic":"orderBookL2_25.BCHUSDT","type":"delta","data":{"delete":[],"update":[{"price":"1054.90","symbol":"BCHUSDT","id":"10549000","side":"Buy","size":33.97}],"insert":[]},"cross_seq":"864133186","timestamp_e6":"1618677793850273"}
1618677793.9410088: {"topic":"orderBookL2_25.LTCUSDT","type":"delta","data":{"delete":[],"update":[{"price":"313.21","symbol":"LTCUSDT","id":"3132100","side":"Buy","size":97.4}],"insert":[]},"cross_seq":"1684523738","timestamp_e6":"1618677793857877"}
1618677793.959191: {"topic":"orderBookL2_25.XTZUSDT","type":"delta","data":{"delete":[{"price":"7.207","symbol":"XTZUSDT","id":"72070","side":"Buy"},{"price":"7.208","symbol":"XTZUSDT","id":"72080","side":"Buy"},{"price":"7.206","symbol":"XTZUSDT","id":"72060","side":"Buy"},{"price":"7.209","symbol":"XTZUSDT","id":"72090","side":"Buy"}],"update":[{"price":"7.200","symbol":"XTZUSDT","id":"72000","side":"Buy","size":189.40001},{"price":"7.205","symbol":"XTZUSDT","id":"72050","side":"Buy","size":1863.7}],"insert":[{"price":"7.181","symbol":"XTZUSDT","id":"71810","side":"Buy","size":493.2},{"price":"7.183","symbol":"XTZUSDT","id":"71830","side":"Buy","size":1145},{"price":"7.182","symbol":"XTZUSDT","id":"71820","side":"Buy","size":1127.6},{"price":"7.184","symbol":"XTZUSDT","id":"71840","side":"Buy","size":389}]},"cross_seq":"726228801","timestamp_e6":"1618677793875578"}
1618677793.976133: {"topic":"orderBookL2_25.BCHUSDT","type":"delta","data":{"delete":[],"update":[{"price":"1054.95","symbol":"BCHUSDT","id":"10549500","side":"Sell","size":5.36}],"insert":[]},"cross_seq":"864133187","timestamp_e6":"1618677793889924"}
1618677793.9875531: {"topic":"orderBookL2_25.LTCUSDT","type":"delta","data":{"delete":[],"update":[{"price":"313.34","symbol":"LTCUSDT","id":"3133400","side":"Buy","size":483.9}],"insert":[]},"cross_seq":"1684523739","timestamp_e6":"1618677793901166"}
1618677793.987587: {"topic":"orderBookL2_25.UNIUSDT","type":"delta","data":{"delete":[{"price":"35.378","symbol":"UNIUSDT","id":"353780","side":"Buy"},{"price":"35.379","symbol":"UNIUSDT","id":"353790","side":"Buy"}],"update":[{"price":"35.377","symbol":"UNIUSDT","id":"353770","side":"Buy","size":61.4},{"price":"35.372","symbol":"UNIUSDT","id":"353720","side":"Buy","size":24.099998}],"insert":[{"price":"35.357","symbol":"UNIUSDT","id":"353570","side":"Buy","size":37.5},{"price":"35.356","symbol":"UNIUSDT","id":"353560","side":"Buy","size":25.900002}]},"cross_seq":"916954989","timestamp_e6":"1618677793903590"}
1618677794.0024629: {"topic":"orderBookL2_25.XTZUSDT","type":"delta","data":{"delete":[{"price":"7.235","symbol":"XTZUSDT","id":"72350","side":"Sell"},{"price":"7.234","symbol":"XTZUSDT","id":"72340","side":"Sell"}],"update":[{"price":"7.214","symbol":"XTZUSDT","id":"72140","side":"Sell","size":1935.3},{"price":"7.210","symbol":"XTZUSDT","id":"72100","side":"Sell","size":4100}],"insert":[{"price":"7.206","symbol":"XTZUSDT","id":"72060","side":"Sell","size":2750},{"price":"7.208","symbol":"XTZUSDT","id":"72080","side":"Sell","size":4000}]},"cross_seq":"726228805","timestamp_e6":"1618677793915158"}
1618677794.007895: {"topic":"orderBookL2_25.ADAUSDT","type":"delta","data":{"delete":[{"price":"1.3871","symbol":"ADAUSDT","id":"13871","side":"Buy"},{"price":"1.3846","symbol":"ADAUSDT","id":"13846","side":"Buy"},{"price":"1.3901","symbol":"ADAUSDT","id":"13901","side":"Sell"}],"update":[{"price":"1.3881","symbol":"ADAUSDT","id":"13881","side":"Sell","size":2203},{"price":"1.3883","symbol":"ADAUSDT","id":"13883","side":"Sell","size":4291}],"insert":[{"price":"1.3870","symbol":"ADAUSDT","id":"13870","side":"Buy","size":5070},{"price":"1.3865","symbol":"ADAUSDT","id":"13865","side":"Buy","size":3337},{"price":"1.3880","symbol":"ADAUSDT","id":"13880","side":"Sell","size":4012}]},"cross_seq":"916954995","timestamp_e6":"1618677793922331"}
1618677794.018568: {"topic":"orderBookL2_25.XTZUSDT","type":"delta","data":{"delete":[],"update":[{"price":"7.214","symbol":"XTZUSDT","id":"72140","side":"Sell","size":1167.6}],"insert":[]},"cross_seq":"726228807","timestamp_e6":"1618677793934897"}
1618677794.028501: {"topic":"orderBookL2_25.UNIUSDT","type":"delta","data":{"delete":[],"update":[{"price":"35.372","symbol":"UNIUSDT","id":"353720","side":"Buy","size":32.4}],"insert":[]},"cross_seq":"916955000","timestamp_e6":"1618677793942441"}
1618677794.028575: {"topic":"orderBookL2_25.ADAUSDT","type":"delta","data":{"delete":[],"update":[{"price":"1.3880","symbol":"ADAUSDT","id":"13880","side":"Sell","size":4013},{"price":"1.3890","symbol":"ADAUSDT","id":"13890","side":"Sell","size":14149}],"insert":[]},"cross_seq":"916955000","timestamp_e6":"1618677793942329"}
1618677794.032759: {"topic":"trade.BCHUSDT","data":[{"symbol":"BCHUSDT","tick_direction":"PlusTick","price":"1054.95","size":0.01,"timestamp":"2021-04-17T16:43:13.000Z","trade_time_ms":"1618677793875","side":"Buy","trade_id":"b304ee48-0fcb-5e93-a5a2-9c757d1bcd68"}]}
1618677794.0395021: {"topic":"orderBookL2_25.XTZUSDT","type":"delta","data":{"delete":[{"price":"7.210","symbol":"XTZUSDT","id":"72100","side":"Sell"},{"price":"7.206","symbol":"XTZUSDT","id":"72060","side":"Sell"},{"price":"7.208","symbol":"XTZUSDT","id":"72080","side":"Sell"}],"update":[{"price":"7.205","symbol":"XTZUSDT","id":"72050","side":"Buy","size":1963.7001},{"price":"7.218","symbol":"XTZUSDT","id":"72180","side":"Sell","size":2436.4}],"insert":[{"price":"7.234","symbol":"XTZUSDT","id":"72340","side":"Sell","size":55.399998},{"price":"7.236","symbol":"XTZUSDT","id":"72360","side":"Sell","size":458.69998},{"price":"7.235","symbol":"XTZUSDT","id":"72350","side":"Sell","size":561.3}]},"cross_seq":"726228813","timestamp_e6":"1618677793955818"}
1618677794.042658: {"topic":"orderBookL2_25.LTCUSDT","type":"delta","data":{"delete":[],"update":[{"price":"313.55","symbol":"LTCUSDT","id":"3135500","side":"Sell","size":32.8}],"insert":[]},"cross_seq":"1684523742","timestamp_e6":"1618677793958862"}
1618677794.046897: {"topic":"orderBookL2_25.ADAUSDT","type":"delta","data":{"delete":[{"price":"1.3847","symbol":"ADAUSDT","id":"13847","side":"Buy"},{"price":"1.3870","symbol":"ADAUSDT","id":"13870","side":"Buy"}],"update":[{"price":"1.3867","symbol":"ADAUSDT","id":"13867","side":"Buy","size":4560},{"price":"1.3881","symbol":"ADAUSDT","id":"13881","side":"Sell","size":888},{"price":"1.3880","symbol":"ADAUSDT","id":"13880","side":"Sell","size":1}],"insert":[{"price":"1.3872","symbol":"ADAUSDT","id":"13872","side":"Buy","size":5070},{"price":"1.3871","symbol":"ADAUSDT","id":"13871","side":"Buy","size":4635}]},"cross_seq":"916955008","timestamp_e6":"1618677793962337"}
1618677794.051214: {"topic":"orderBookL2_25.BCHUSDT","type":"delta","data":{"delete":[],"update":[{"price":"1054.50","symbol":"BCHUSDT","id":"10545000","side":"Buy","size":12.150001},{"price":"1054.65","symbol":"BCHUSDT","id":"10546500","side":"Buy","size":16.56},{"price":"1055.65","symbol":"BCHUSDT","id":"10556500","side":"Sell","size":20.150002},{"price":"1054.55","symbol":"BCHUSDT","id":"10545500","side":"Buy","size":7.45},{"price":"1054.60","symbol":"BCHUSDT","id":"10546000","side":"Buy","size":14.88},{"price":"1054.45","symbol":"BCHUSDT","id":"10544500","side":"Buy","size":10.59},{"price":"1055.85","symbol":"BCHUSDT","id":"10558500","side":"Sell","size":16.46},{"price":"1054.70","symbol":"BCHUSDT","id":"10547000","side":"Buy","size":15.409999},{"price":"1055.80","symbol":"BCHUSDT","id":"10558000","side":"Sell","size":3.06},{"price":"1055.70","symbol":"BCHUSDT","id":"10557000","side":"Sell","size":5.44}],"insert":[]},"cross_seq":"864133197","timestamp_e6":"1618677793968917"}
1618677794.067229: {"topic":"orderBookL2_25.DOTUSDT","type":"delta","data":{"delete":[],"update":[{"price":"43.480","symbol":"DOTUSDT","id":"434800","side":"Buy","size":453.5},{"price":"43.585","symbol":"DOTUSDT","id":"435850","side":"Sell","size":465.09998},{"price":"43.485","symbol":"DOTUSDT","id":"434850","side":"Buy","size":301.59998}],"insert":[]},"cross_seq":"916955012","timestamp_e6":"1618677793982455"}
1618677794.0672698: {"topic":"orderBookL2_25.ADAUSDT","type":"delta","data":{"delete":[],"update":[{"price":"1.3882","symbol":"ADAUSDT","id":"13882","side":"Sell","size":9237},{"price":"1.3885","symbol":"ADAUSDT","id":"13885","side":"Sell","size":4418}],"insert":[]},"cross_seq":"916955012","timestamp_e6":"1618677793982331"}
1618677794.0802078: {"topic":"orderBookL2_25.XTZUSDT","type":"delta","data":{"delete":[{"price":"7.235","symbol":"XTZUSDT","id":"72350","side":"Sell"},{"price":"7.236","symbol":"XTZUSDT","id":"72360","side":"Sell"}],"update":[{"price":"7.205","symbol":"XTZUSDT","id":"72050","side":"Buy","size":1863.7}],"insert":[{"price":"7.209","symbol":"XTZUSDT","id":"72090","side":"Sell","size":1271.1},{"price":"7.211","symbol":"XTZUSDT","id":"72110","side":"Sell","size":2769.3}]},"cross_seq":"726228816","timestamp_e6":"1618677793996905"}
1618677794.083178: {"topic":"orderBookL2_25.LTCUSDT","type":"delta","data":{"delete":[{"price":"313.66","symbol":"LTCUSDT","id":"3136600","side":"Sell"}],"update":[{"price":"313.35","symbol":"LTCUSDT","id":"3133500","side":"Sell","size":1.5}],"insert":[{"price":"313.48","symbol":"LTCUSDT","id":"3134800","side":"Sell","size":42.7}]},"cross_seq":"1684523744","timestamp_e6":"1618677793999736"}
1618677794.0874429: {"topic":"orderBookL2_25.DOTUSDT","type":"delta","data":{"delete":[{"price":"43.425","symbol":"DOTUSDT","id":"434250","side":"Buy"},{"price":"43.420","symbol":"DOTUSDT","id":"434200","side":"Buy"}],"update":[{"price":"43.465","symbol":"DOTUSDT","id":"434650","side":"Buy","size":191.20001},{"price":"43.490","symbol":"DOTUSDT","id":"434900","side":"Buy","size":72.3},{"price":"43.570","symbol":"DOTUSDT","id":"435700","side":"Sell","size":646.60004},{"price":"43.505","symbol":"DOTUSDT","id":"435050","side":"Buy","size":99.2},{"price":"43.565","symbol":"DOTUSDT","id":"435650","side":"Sell","size":132.90001},{"price":"43.500","symbol":"DOTUSDT","id":"435000","side":"Buy","size":100.100006},{"price":"43.575","symbol":"DOTUSDT","id":"435750","side":"Sell","size":697.2},{"price":"43.480","symbol":"DOTUSDT","id":"434800","side":"Buy","size":297.9},{"price":"43.540","symbol":"DOTUSDT","id":"435400","side":"Buy","size":406.69998},{"price":"43.475","symbol":"DOTUSDT","id":"434750","side":"Buy","size":239},{"price":"43.470","symbol":"DOTUSDT","id":"434700","side":"Buy","size":249.6},{"price":"43.455","symbol":"DOTUSDT","id":"434550","side":"Buy","size":353.5},{"price":"43.580","symbol":"DOTUSDT","id":"435800","side":"Sell","size":444.7},{"price":"43.585","symbol":"DOTUSDT","id":"435850","side":"Sell","size":535},{"price":"43.460","symbol":"DOTUSDT","id":"434600","side":"Buy","size":253.09999}],"insert":[{"price":"43.510","symbol":"DOTUSDT","id":"435100","side":"Buy","size":485.6},{"price":"43.550","symbol":"DOTUSDT","id":"435500","side":"Buy","size":540.1}]},"cross_seq":"916955059","timestamp_e6":"1618677794002369"}
1618677794.1013272: {"topic":"orderBookL2_25.LTCUSDT","type":"delta","data":{"delete":[{"price":"313.08","symbol":"LTCUSDT","id":"3130800","side":"Buy"}],"update":[{"price":"313.09","symbol":"LTCUSDT","id":"3130900","side":"Buy","size":186.99998},{"price":"313.47","symbol":"LTCUSDT","id":"3134700","side":"Sell","size":5},{"price":"313.07","symbol":"LTCUSDT","id":"3130700","side":"Buy","size":24.300001},{"price":"313.48","symbol":"LTCUSDT","id":"3134800","side":"Sell","size":74.9}],"insert":[{"price":"313.06","symbol":"LTCUSDT","id":"3130600","side":"Buy","size":59.9}]},"cross_seq":"1684523768","timestamp_e6":"1618677794017938"}
1618677794.119508: {"topic":"orderBookL2_25.XTZUSDT","type":"delta","data":{"delete":[{"price":"7.211","symbol":"XTZUSDT","id":"72110","side":"Sell"}],"update":[{"price":"7.220","symbol":"XTZUSDT","id":"72200","side":"Sell","size":683.89996},{"price":"7.225","symbol":"XTZUSDT","id":"72250","side":"Sell","size":1142.1}],"insert":[{"price":"7.235","symbol":"XTZUSDT","id":"72350","side":"Sell","size":561.3}]},"cross_seq":"726228819","timestamp_e6":"1618677794035968"}
1618677794.1419678: {"topic":"orderBookL2_25.XTZUSDT","type":"delta","data":{"delete":[{"price":"7.235","symbol":"XTZUSDT","id":"72350","side":"Sell"},{"price":"7.233","symbol":"XTZUSDT","id":"72330","side":"Sell"},{"price":"7.234","symbol":"XTZUSDT","id":"72340","side":"Sell"}],"update":[{"price":"7.212","symbol":"XTZUSDT","id":"72120","side":"Sell","size":251.8},{"price":"7.199","symbol":"XTZUSDT","id":"71990","side":"Buy","size":3179.4001},{"price":"7.209","symbol":"XTZUSDT","id":"72090","side":"Sell","size":1989.4},{"price":"7.215","symbol":"XTZUSDT","id":"72150","side":"Sell","size":1043.4},{"price":"7.218","symbol":"XTZUSDT","id":"72180","side":"Sell","size":3083},{"price":"7.213","symbol":"XTZUSDT","id":"72130","side":"Sell","size":463.90002},{"price":"7.216","symbol":"XTZUSDT","id":"72160","side":"Sell","size":429.59998},{"price":"7.214","symbol":"XTZUSDT","id":"72140","side":"Sell","size":883.30005},{"price":"7.200","symbol":"XTZUSDT","id":"72000","side":"Buy","size":268.1},{"price":"7.223","symbol":"XTZUSDT","id":"72230","side":"Sell","size":2481}],"insert":[{"price":"7.211","symbol":"XTZUSDT","id":"72110","side":"Sell","size":427},{"price":"7.207","symbol":"XTZUSDT","id":"72070","side":"Sell","size":980.30005},{"price":"7.208","symbol":"XTZUSDT","id":"72080","side":"Sell","size":743.8}]},"cross_seq":"726228835","timestamp_e6":"1618677794055628"}
1618677794.142797: {"topic":"orderBookL2_25.LTCUSDT","type":"delta","data":{"delete":[{"price":"313.46","symbol":"LTCUSDT","id":"3134600","side":"Sell"},{"price":"313.44","symbol":"LTCUSDT","id":"3134400","side":"Sell"}],"update":[{"price":"313.45","symbol":"LTCUSDT","id":"3134500","side":"Sell","size":2},{"price":"313.51","symbol":"LTCUSDT","id":"3135100","side":"Sell","size":157},{"price":"313.43","symbol":"LTCUSDT","id":"3134300","side":"Sell","size":1.5},{"price":"313.50","symbol":"LTCUSDT","id":"3135000","side":"Sell","size":199.79999}],"insert":[{"price":"313.67","symbol":"LTCUSDT","id":"3136700","side":"Sell","size":19.6},{"price":"313.66","symbol":"LTCUSDT","id":"3136600","side":"Sell","size":237.9}]},"cross_seq":"1684523777","timestamp_e6":"1618677794058439"}
1618677794.151476: {"topic":"orderBookL2_25.BCHUSDT","type":"delta","data":{"delete":[{"price":"1055.45","symbol":"BCHUSDT","id":"10554500","side":"Sell"}],"update":[{"price":"1055.50","symbol":"BCHUSDT","id":"10555000","side":"Sell","size":8.76}],"insert":[{"price":"1056.40","symbol":"BCHUSDT","id":"10564000","side":"Sell","size":1}]},"cross_seq":"864133201","timestamp_e6":"1618677794068666"}
1618677794.160029: {"topic":"orderBookL2_25.XTZUSDT","type":"delta","data":{"delete":[{"price":"7.211","symbol":"XTZUSDT","id":"72110","side":"Sell"},{"price":"7.207","symbol":"XTZUSDT","id":"72070","side":"Sell"}],"update":[{"price":"7.216","symbol":"XTZUSDT","id":"72160","side":"Sell","size":766.10004},{"price":"7.215","symbol":"XTZUSDT","id":"72150","side":"Sell","size":1286.8},{"price":"7.204","symbol":"XTZUSDT","id":"72040","side":"Buy","size":287.3},{"price":"7.200","symbol":"XTZUSDT","id":"72000","side":"Buy","size":628},{"price":"7.217","symbol":"XTZUSDT","id":"72170","side":"Sell","size":827.5},{"price":"7.219","symbol":"XTZUSDT","id":"72190","side":"Sell","size":1564.4},{"price":"7.209","symbol":"XTZUSDT","id":"72090","side":"Sell","size":2089.4001},{"price":"7.203","symbol":"XTZUSDT","id":"72030","side":"Buy","size":666.89996},{"price":"7.202","symbol":"XTZUSDT","id":"72020","side":"Buy","size":521.8}],"insert":[{"price":"7.233","symbol":"XTZUSDT","id":"72330","side":"Sell","size":1271.5},{"price":"7.206","symbol":"XTZUSDT","id":"72060","side":"Sell","size":980.30005}]},"cross_seq":"726228857","timestamp_e6":"1618677794075387"}
1618677794.163242: {"topic":"orderBookL2_25.LTCUSDT","type":"delta","data":{"delete":[{"price":"313.06","symbol":"LTCUSDT","id":"3130600","side":"Buy"}],"update":[{"price":"313.54","symbol":"LTCUSDT","id":"3135400","side":"Sell","size":107.899994},{"price":"313.53","symbol":"LTCUSDT","id":"3135300","side":"Sell","size":131.8},{"price":"313.13","symbol":"LTCUSDT","id":"3131300","side":"Buy","size":297.80002},{"price":"313.11","symbol":"LTCUSDT","id":"3131100","side":"Buy","size":134.9},{"price":"313.55","symbol":"LTCUSDT","id":"3135500","side":"Sell","size":41.5},{"price":"313.12","symbol":"LTCUSDT","id":"3131200","side":"Buy","size":130},{"price":"313.51","symbol":"LTCUSDT","id":"3135100","side":"Sell","size":113.99999},{"price":"313.10","symbol":"LTCUSDT","id":"3131000","side":"Buy","size":135.4},{"price":"313.09","symbol":"LTCUSDT","id":"3130900","side":"Buy","size":271.3}],"insert":[{"price":"313.08","symbol":"LTCUSDT","id":"3130800","side":"Buy","size":68.5}]},"cross_seq":"1684523789","timestamp_e6":"1618677794077923"}
1618677794.166441: {"topic":"orderBookL2_25.ADAUSDT","type":"delta","data":{"delete":[],"update":[{"price":"1.3880","symbol":"ADAUSDT","id":"13880","side":"Sell","size":1974},{"price":"1.3867","symbol":"ADAUSDT","id":"13867","side":"Buy","size":6757},{"price":"1.3881","symbol":"ADAUSDT","id":"13881","side":"Sell","size":1315}],"insert":[]},"cross_seq":"916955075","timestamp_e6":"1618677794082424"}
1618677794.179426: {"topic":"orderBookL2_25.XTZUSDT","type":"delta","data":{"delete":[],"update":[{"price":"7.212","symbol":"XTZUSDT","id":"72120","side":"Sell","size":251.59999}],"insert":[]},"cross_seq":"726228858","timestamp_e6":"1618677794095222"}
1618677794.1856809: {"topic":"orderBookL2_25.LTCUSDT","type":"delta","data":{"delete":[{"price":"313.35","symbol":"LTCUSDT","id":"3133500","side":"Sell"}],"update":[],"insert":[{"price":"313.68","symbol":"LTCUSDT","id":"3136800","side":"Sell","size":59.5}]},"cross_seq":"1684523791","timestamp_e6":"1618677794101022"}
1618677794.185725: {"topic":"orderBookL2_25.ADAUSDT","type":"delta","data":{"delete":[{"price":"1.3848","symbol":"ADAUSDT","id":"13848","side":"Buy"},{"price":"1.3849","symbol":"ADAUSDT","id":"13849","side":"Buy"}],"update":[{"price":"1.3869","symbol":"ADAUSDT","id":"13869","side":"Buy","size":16869}],"insert":[{"price":"1.3870","symbol":"ADAUSDT","id":"13870","side":"Buy","size":4757},{"price":"1.3873","symbol":"ADAUSDT","id":"13873","side":"Buy","size":5070}]},"cross_seq":"916955083","timestamp_e6":"1618677794102300"}
1618677794.192044: {"topic":"orderBookL2_25.BCHUSDT","type":"delta","data":{"delete":[{"price":"1055.50","symbol":"BCHUSDT","id":"10555000","side":"Sell"}],"update":[],"insert":[{"price":"1055.45","symbol":"BCHUSDT","id":"10554500","side":"Sell","size":4.67}]},"cross_seq":"864133208","timestamp_e6":"1618677794108663"}
1618677794.19917: {"topic":"orderBookL2_25.XTZUSDT","type":"delta","data":{"delete":[],"update":[{"price":"7.206","symbol":"XTZUSDT","id":"72060","side":"Sell","size":4980.3}],"insert":[]},"cross_seq":"726228859","timestamp_e6":"1618677794115191"}
1618677794.205194: {"topic":"orderBookL2_25.LTCUSDT","type":"delta","data":{"delete":[{"price":"313.09","symbol":"LTCUSDT","id":"3130900","side":"Buy"},{"price":"313.10","symbol":"LTCUSDT","id":"3131000","side":"Buy"},{"price":"313.11","symbol":"LTCUSDT","id":"3131100","side":"Buy"},{"price":"313.49","symbol":"LTCUSDT","id":"3134900","side":"Sell"},{"price":"313.12","symbol":"LTCUSDT","id":"3131200","side":"Buy"},{"price":"313.08","symbol":"LTCUSDT","id":"3130800","side":"Buy"},{"price":"313.07","symbol":"LTCUSDT","id":"3130700","side":"Buy"},{"price":"313.48","symbol":"LTCUSDT","id":"3134800","side":"Sell"}],"update":[{"price":"313.50","symbol":"LTCUSDT","id":"3135000","side":"Sell","size":246.79999},{"price":"313.55","symbol":"LTCUSDT","id":"3135500","side":"Sell","size":78.700005}],"insert":[{"price":"313.39","symbol":"LTCUSDT","id":"3133900","side":"Buy","size":148.2},{"price":"313.37","symbol":"LTCUSDT","id":"3133700","side":"Buy","size":97.6},{"price":"313.69","symbol":"LTCUSDT","id":"3136900","side":"Sell","size":214.2},{"price":"313.40","symbol":"LTCUSDT","id":"3134000","side":"Buy","size":138.3},{"price":"313.38","symbol":"LTCUSDT","id":"3133800","side":"Buy","size":120.2},{"price":"313.41","symbol":"LTCUSDT","id":"3134100","side":"Buy","size":156.40001},{"price":"313.36","symbol":"LTCUSDT","id":"3133600","side":"Buy","size":47.100002},{"price":"313.70","symbol":"LTCUSDT","id":"3137000","side":"Sell","size":142.4}]},"cross_seq":"1684523809","timestamp_e6":"1618677794119574"}
1618677794.216162: {"topic":"trade.LTCUSDT","data":[{"symbol":"LTCUSDT","tick_direction":"PlusTick","price":"313.35","size":1.5,"timestamp":"2021-04-17T16:43:14.000Z","trade_time_ms":"1618677794088","side":"Buy","trade_id":"fb4a5046-7f7d-5869-acac-2548367ef8c3"}]}
1618677794.219389: {"topic":"orderBookL2_25.XTZUSDT","type":"delta","data":{"delete":[],"update":[{"price":"7.195","symbol":"XTZUSDT","id":"71950","side":"Buy","size":5094.0996}],"insert":[]},"cross_seq":"726228860","timestamp_e6":"1618677794134665"}
1618677794.225101: {"topic":"orderBookL2_25.LTCUSDT","type":"delta","data":{"delete":[],"update":[{"price":"313.42","symbol":"LTCUSDT","id":"3134200","side":"Sell","size":4.9},{"price":"313.38","symbol":"LTCUSDT","id":"3133800","side":"Buy","size":370.2},{"price":"313.41","symbol":"LTCUSDT","id":"3134100","side":"Buy","size":334.9},{"price":"313.34","symbol":"LTCUSDT","id":"3133400","side":"Buy","size":320.4}],"insert":[]},"cross_seq":"1684523816","timestamp_e6":"1618677794140531"}
1618677794.241889: {"topic":"orderBookL2_25.LTCUSDT","type":"delta","data":{"delete":[],"update":[{"price":"313.34","symbol":"LTCUSDT","id":"3133400","side":"Buy","size":130.59999},{"price":"313.38","symbol":"LTCUSDT","id":"3133800","side":"Buy","size":120.2}],"insert":[]},"cross_seq":"1684523835","timestamp_e6":"1618677794157875"}
1618677794.260524: {"topic":"orderBookL2_25.XTZUSDT","type":"delta","data":{"delete":[],"update":[{"price":"7.199","symbol":"XTZUSDT","id":"71990","side":"Buy","size":1908.4}],"insert":[]},"cross_seq":"726228905","timestamp_e6":"1618677794175134"}
1618677794.263577: {"topic":"orderBookL2_25.LTCUSDT","type":"delta","data":{"delete":[],"update":[{"price":"313.34","symbol":"LTCUSDT","id":"3133400","side":"Buy","size":129.1},{"price":"313.41","symbol":"LTCUSDT","id":"3134100","side":"Buy","size":336.4}],"insert":[]},"cross_seq":"1684523836","timestamp_e6":"1618677794179032"}
1618677794.292642: {"topic":"orderBookL2_25.ETHUSDT","type":"delta","data":{"delete":[],"update":[{"price":"2363.90","symbol":"ETHUSDT","id":"23639000","side":"Buy","size":42.14},{"price":"2365.00","symbol":"ETHUSDT","id":"23650000","side":"Sell","size":181.14001},{"price":"2364.95","symbol":"ETHUSDT","id":"23649500","side":"Sell","size":382.38998},{"price":"2365.15","symbol":"ETHUSDT","id":"23651500","side":"Sell","size":148.71},{"price":"2363.95","symbol":"ETHUSDT","id":"23639500","side":"Buy","size":32.780003}],"insert":[]},"cross_seq":"1800546838","timestamp_e6":"1618677794208370"}
1618677794.301725: {"topic":"orderBookL2_25.XTZUSDT","type":"delta","data":{"delete":[],"update":[{"price":"7.225","symbol":"XTZUSDT","id":"72250","side":"Sell","size":1182.3},{"price":"7.206","symbol":"XTZUSDT","id":"72060","side":"Sell","size":5080.3}],"insert":[]},"cross_seq":"726228907","timestamp_e6":"1618677794215870"}
1618677794.309212: {"topic":"orderBookL2_25.LINKUSDT","type":"delta","data":{"delete":[{"price":"41.044","symbol":"LINKUSDT","id":"410440","side":"Buy"},{"price":"41.041","symbol":"LINKUSDT","id":"410410","side":"Buy"},{"price":"41.053","symbol":"LINKUSDT","id":"410530","side":"Sell"},{"price":"41.049","symbol":"LINKUSDT","id":"410490","side":"Sell"}],"update":[{"price":"41.043","symbol":"LINKUSDT","id":"410430","side":"Buy","size":158.5},{"price":"41.040","symbol":"LINKUSDT","id":"410400","side":"Buy","size":58.8},{"price":"41.045","symbol":"LINKUSDT","id":"410450","side":"Buy","size":696},{"price":"41.042","symbol":"LINKUSDT","id":"410420","side":"Buy","size":66.700005}],"insert":[{"price":"41.019","symbol":"LINKUSDT","id":"410190","side":"Buy","size":427.1},{"price":"41.071","symbol":"LINKUSDT","id":"410710","side":"Sell","size":314.9},{"price":"41.072","symbol":"LINKUSDT","id":"410720","side":"Sell","size":188.3},{"price":"41.020","symbol":"LINKUSDT","id":"410200","side":"Buy","size":331.5}]},"cross_seq":"1970980131","timestamp_e6":"1618677794224905"}
1618677794.3127308: {"topic":"orderBookL2_25.BCHUSDT","type":"delta","data":{"delete":[],"update":[{"price":"1055.80","symbol":"BCHUSDT","id":"10558000","side":"Sell","size":5.22},{"price":"1055.65","symbol":"BCHUSDT","id":"10556500","side":"Sell","size":24.060001},{"price":"1054.70","symbol":"BCHUSDT","id":"10547000","side":"Buy","size":18.81}],"insert":[]},"cross_seq":"864133215","timestamp_e6":"1618677794228749"}
1618677794.3182771: {"topic":"orderBookL2_25.XTZUSDT","type":"delta","data":{"delete":[],"update":[{"price":"7.209","symbol":"XTZUSDT","id":"72090","side":"Sell","size":1989.4}],"insert":[]},"cross_seq":"726228908","timestamp_e6":"1618677794234566"}
1618677794.33202: {"topic":"orderBookL2_25.BCHUSDT","type":"delta","data":{"delete":[{"price":"1056.40","symbol":"BCHUSDT","id":"10564000","side":"Sell"}],"update":[{"price":"1055.45","symbol":"BCHUSDT","id":"10554500","side":"Sell","size":6.24}],"insert":[{"price":"1055.50","symbol":"BCHUSDT","id":"10555000","side":"Sell","size":8.76}]},"cross_seq":"864133218","timestamp_e6":"1618677794248689"}
1618677794.338368: {"topic":"orderBookL2_25.XTZUSDT","type":"delta","data":{"delete":[],"update":[{"price":"7.218","symbol":"XTZUSDT","id":"72180","side":"Sell","size":3904.2}],"insert":[]},"cross_seq":"726228909","timestamp_e6":"1618677794254583"}
1618677794.348403: {"topic":"orderBookL2_25.DOTUSDT","type":"delta","data":{"delete":[{"price":"43.545","symbol":"DOTUSDT","id":"435450","side":"Buy"},{"price":"43.590","symbol":"DOTUSDT","id":"435900","side":"Sell"},{"price":"43.525","symbol":"DOTUSDT","id":"435250","side":"Buy"}],"update":[{"price":"43.560","symbol":"DOTUSDT","id":"435600","side":"Sell","size":300},{"price":"43.565","symbol":"DOTUSDT","id":"435650","side":"Sell","size":898.4},{"price":"43.505","symbol":"DOTUSDT","id":"435050","side":"Buy","size":528.3},{"price":"43.490","symbol":"DOTUSDT","id":"434900","side":"Buy","size":319.5},{"price":"43.530","symbol":"DOTUSDT","id":"435300","side":"Buy","size":59.000004},{"price":"43.500","symbol":"DOTUSDT","id":"435000","side":"Buy","size":446.90002}],"insert":[{"price":"43.425","symbol":"DOTUSDT","id":"434250","side":"Buy","size":241.9},{"price":"43.420","symbol":"DOTUSDT","id":"434200","side":"Buy","size":101.299995},{"price":"43.685","symbol":"DOTUSDT","id":"436850","side":"Sell","size":94.00001}]},"cross_seq":"916955098","timestamp_e6":"1618677794262357"}
1618677794.348625: {"topic":"orderBookL2_25.LINKUSDT","type":"delta","data":{"delete":[{"price":"41.020","symbol":"LINKUSDT","id":"410200","side":"Buy"},{"price":"41.054","symbol":"LINKUSDT","id":"410540","side":"Sell"},{"price":"41.048","symbol":"LINKUSDT","id":"410480","side":"Sell"},{"price":"41.047","symbol":"LINKUSDT","id":"410470","side":"Sell"},{"price":"41.050","symbol":"LINKUSDT","id":"410500","side":"Sell"},{"price":"41.019","symbol":"LINKUSDT","id":"410190","side":"Buy"}],"update":[{"price":"41.051","symbol":"LINKUSDT","id":"410510","side":"Sell","size":173.5},{"price":"41.045","symbol":"LINKUSDT","id":"410450","side":"Buy","size":927.80005},{"price":"41.040","symbol":"LINKUSDT","id":"410400","side":"Buy","size":89},{"price":"41.042","symbol":"LINKUSDT","id":"410420","side":"Buy","size":155.5}],"insert":[{"price":"41.053","symbol":"LINKUSDT","id":"410530","side":"Sell","size":110.799995},{"price":"41.044","symbol":"LINKUSDT","id":"410440","side":"Buy","size":173.09999},{"price":"41.041","symbol":"LINKUSDT","id":"410410","side":"Buy","size":66.9},{"price":"41.075","symbol":"LINKUSDT","id":"410750","side":"Sell","size":8.3},{"price":"41.074","symbol":"LINKUSDT","id":"410740","side":"Sell","size":180.90001},{"price":"41.073","symbol":"LINKUSDT","id":"410730","side":"Sell","size":194.40001}]},"cross_seq":"1970980151","timestamp_e6":"1618677794264906"}
1618677794.351598: {"topic":"orderBookL2_25.BCHUSDT","type":"delta","data":{"delete":[{"price":"1055.40","symbol":"BCHUSDT","id":"10554000","side":"Sell"},{"price":"1055.25","symbol":"BCHUSDT","id":"10552500","side":"Sell"},{"price":"1055.30","symbol":"BCHUSDT","id":"10553000","side":"Sell"},{"price":"1055.50","symbol":"BCHUSDT","id":"10555000","side":"Sell"},{"price":"1055.35","symbol":"BCHUSDT","id":"10553500","side":"Sell"}],"update":[{"price":"1055.80","symbol":"BCHUSDT","id":"10558000","side":"Sell","size":8.29},{"price":"1055.55","symbol":"BCHUSDT","id":"10555500","side":"Sell","size":8.76},{"price":"1055.70","symbol":"BCHUSDT","id":"10557000","side":"Sell","size":9.11},{"price":"1055.65","symbol":"BCHUSDT","id":"10556500","side":"Sell","size":26.21}],"insert":[{"price":"1056.40","symbol":"BCHUSDT","id":"10564000","side":"Sell","size":1},{"price":"1056.60","symbol":"BCHUSDT","id":"10566000","side":"Sell","size":10.7},{"price":"1056.45","symbol":"BCHUSDT","id":"10564500","side":"Sell","size":16.609999},{"price":"1056.50","symbol":"BCHUSDT","id":"10565000","side":"Sell","size":30.32},{"price":"1056.55","symbol":"BCHUSDT","id":"10565500","side":"Sell","size":10.5}]},"cross_seq":"864133239","timestamp_e6":"1618677794268718"}
1618677794.365639: {"topic":"orderBookL2_25.LTCUSDT","type":"delta","data":{"delete":[],"update":[{"price":"313.52","symbol":"LTCUSDT","id":"3135200","side":"Sell","size":168.1},{"price":"313.54","symbol":"LTCUSDT","id":"3135400","side":"Sell","size":160.1},{"price":"313.56","symbol":"LTCUSDT","id":"3135600","side":"Sell","size":51.699997},{"price":"313.55","symbol":"LTCUSDT","id":"3135500","side":"Sell","size":131.8},{"price":"313.36","symbol":"LTCUSDT","id":"3133600","side":"Buy","size":74.700005},{"price":"313.57","symbol":"LTCUSDT","id":"3135700","side":"Sell","size":135.8},{"price":"313.50","symbol":"LTCUSDT","id":"3135000","side":"Sell","size":131},{"price":"313.53","symbol":"LTCUSDT","id":"3135300","side":"Sell","size":114.200005}],"insert":[]},"cross_seq":"1684523851","timestamp_e6":"1618677794279266"}
1618677794.3805969: {"topic":"orderBookL2_25.LTCUSDT","type":"delta","data":{"delete":[{"price":"313.43","symbol":"LTCUSDT","id":"3134300","side":"Sell"}],"update":[{"price":"313.51","symbol":"LTCUSDT","id":"3135100","side":"Sell","size":115.5}],"insert":[{"price":"313.71","symbol":"LTCUSDT","id":"3137100","side":"Sell","size":64.2}]},"cross_seq":"1684523852","timestamp_e6":"1618677794297922"}
1618677794.4017391: {"topic":"orderBookL2_25.XTZUSDT","type":"delta","data":{"delete":[{"price":"7.233","symbol":"XTZUSDT","id":"72330","side":"Sell"},{"price":"7.232","symbol":"XTZUSDT","id":"72320","side":"Sell"},{"price":"7.205","symbol":"XTZUSDT","id":"72050","side":"Buy"}],"update":[{"price":"7.209","symbol":"XTZUSDT","id":"72090","side":"Sell","size":1271.1},{"price":"7.206","symbol":"XTZUSDT","id":"72060","side":"Sell","size":4100},{"price":"7.202","symbol":"XTZUSDT","id":"72020","side":"Buy","size":938},{"price":"7.199","symbol":"XTZUSDT","id":"71990","side":"Buy","size":1449.8999},{"price":"7.187","symbol":"XTZUSDT","id":"71870","side":"Buy","size":1267.4},{"price":"7.193","symbol":"XTZUSDT","id":"71930","side":"Buy","size":724.9},{"price":"7.204","symbol":"XTZUSDT","id":"72040","side":"Buy","size":1728.7},{"price":"7.219","symbol":"XTZUSDT","id":"72190","side":"Sell","size":1653.2},{"price":"7.185","symbol":"XTZUSDT","id":"71850","side":"Buy","size":1140.6},{"price":"7.203","symbol":"XTZUSDT","id":"72030","side":"Buy","size":1258.6001}],"insert":[{"price":"7.207","symbol":"XTZUSDT","id":"72070","side":"Sell","size":718.30005},{"price":"7.180","symbol":"XTZUSDT","id":"71800","side":"Buy","size":151.2},{"price":"7.210","symbol":"XTZUSDT","id":"72100","side":"Sell","size":250.7}]},"cross_seq":"726228939","timestamp_e6":"1618677794315823"}
1618677794.411008: {"topic":"orderBookL2_25.ETHUSDT","type":"delta","data":{"delete":[],"update":[{"price":"2363.75","symbol":"ETHUSDT","id":"23637500","side":"Buy","size":90.33},{"price":"2366.10","symbol":"ETHUSDT","id":"23661000","side":"Sell","size":69.93}],"insert":[]},"cross_seq":"1800546840","timestamp_e6":"1618677794327083"}
1618677794.421203: {"topic":"orderBookL2_25.XTZUSDT","type":"delta","data":{"delete":[],"update":[{"price":"7.210","symbol":"XTZUSDT","id":"72100","side":"Sell","size":427},{"price":"7.209","symbol":"XTZUSDT","id":"72090","side":"Sell","size":1893.1},{"price":"7.206","symbol":"XTZUSDT","id":"72060","side":"Sell","size":5080.3},{"price":"7.199","symbol":"XTZUSDT","id":"71990","side":"Buy","size":1718}],"insert":[]},"cross_seq":"726228943","timestamp_e6":"1618677794335122"}
1618677794.424046: {"topic":"orderBookL2_25.LTCUSDT","type":"delta","data":{"delete":[],"update":[{"price":"313.42","symbol":"LTCUSDT","id":"3134200","side":"Sell","size":0.1}],"insert":[]},"cross_seq":"1684523865","timestamp_e6":"1618677794339037"}
1618677794.439111: {"topic":"orderBookL2_25.XTZUSDT","type":"delta","data":{"delete":[{"price":"7.231","symbol":"XTZUSDT","id":"72310","side":"Sell"}],"update":[],"insert":[{"price":"7.205","symbol":"XTZUSDT","id":"72050","side":"Sell","size":6750.0005}]},"cross_seq":"726228945","timestamp_e6":"1618677794355190"}
1618677794.452012: {"topic":"orderBookL2_25.ADAUSDT","type":"delta","data":{"delete":[],"update":[{"price":"1.3879","symbol":"ADAUSDT","id":"13879","side":"Sell","size":2626},{"price":"1.3869","symbol":"ADAUSDT","id":"13869","side":"Buy","size":20610},{"price":"1.3881","symbol":"ADAUSDT","id":"13881","side":"Sell","size":427},{"price":"1.3880","symbol":"ADAUSDT","id":"13880","side":"Sell","size":1}],"insert":[]},"cross_seq":"916955103","timestamp_e6":"1618677794362325"}
1618677794.4661162: {"topic":"orderBookL2_25.LTCUSDT","type":"delta","data":{"delete":[{"price":"313.50","symbol":"LTCUSDT","id":"3135000","side":"Sell"}],"update":[{"price":"313.59","symbol":"LTCUSDT","id":"3135900","side":"Sell","size":75.5},{"price":"313.51","symbol":"LTCUSDT","id":"3135100","side":"Sell","size":40.6},{"price":"313.53","symbol":"LTCUSDT","id":"3135300","side":"Sell","size":80.5},{"price":"313.55","symbol":"LTCUSDT","id":"3135500","side":"Sell","size":174.9},{"price":"313.57","symbol":"LTCUSDT","id":"3135700","side":"Sell","size":71.7},{"price":"313.56","symbol":"LTCUSDT","id":"3135600","side":"Sell","size":91.3}],"insert":[{"price":"313.72","symbol":"LTCUSDT","id":"3137200","side":"Sell","size":108.100006}]},"cross_seq":"1684523876","timestamp_e6":"1618677794378454"}
1618677794.469064: {"topic":"orderBookL2_25.DOTUSDT","type":"delta","data":{"delete":[{"price":"43.420","symbol":"DOTUSDT","id":"434200","side":"Buy"},{"price":"43.425","symbol":"DOTUSDT","id":"434250","side":"Buy"},{"price":"43.685","symbol":"DOTUSDT","id":"436850","side":"Sell"}],"update":[{"price":"43.530","symbol":"DOTUSDT","id":"435300","side":"Buy","size":505.6}],"insert":[{"price":"43.525","symbol":"DOTUSDT","id":"435250","side":"Buy","size":301.3},{"price":"43.590","symbol":"DOTUSDT","id":"435900","side":"Sell","size":85.7},{"price":"43.545","symbol":"DOTUSDT","id":"435450","side":"Buy","size":577.3}]},"cross_seq":"916955107","timestamp_e6":"1618677794382544"}
1618677794.4746711: {"topic":"orderBookL2_25.ETHUSDT","type":"delta","data":{"delete":[],"update":[{"price":"2364.90","symbol":"ETHUSDT","id":"23649000","side":"Buy","size":84}],"insert":[]},"cross_seq":"1800546841","timestamp_e6":"1618677794388589"}
1618677794.479164: {"topic":"orderBookL2_25.XTZUSDT","type":"delta","data":{"delete":[],"update":[{"price":"7.204","symbol":"XTZUSDT","id":"72040","side":"Buy","size":1828.7},{"price":"7.205","symbol":"XTZUSDT","id":"72050","side":"Sell","size":4000},{"price":"7.206","symbol":"XTZUSDT","id":"72060","side":"Sell","size":980.30005}],"insert":[]},"cross_seq":"726228949","timestamp_e6":"1618677794396042"}
1618677794.4813771: {"topic":"orderBookL2_25.LTCUSDT","type":"delta","data":{"delete":[],"update":[{"price":"313.58","symbol":"LTCUSDT","id":"3135800","side":"Sell","size":89.200005},{"price":"313.54","symbol":"LTCUSDT","id":"3135400","side":"Sell","size":85.799995},{"price":"313.52","symbol":"LTCUSDT","id":"3135200","side":"Sell","size":87.8},{"price":"313.51","symbol":"LTCUSDT","id":"3135100","side":"Sell","size":1.5},{"price":"313.57","symbol":"LTCUSDT","id":"3135700","side":"Sell","size":87.399994},{"price":"313.56","symbol":"LTCUSDT","id":"3135600","side":"Sell","size":128.7}],"insert":[]},"cross_seq":"1684523897","timestamp_e6":"1618677794397851"}
1618677794.4880152: {"topic":"orderBookL2_25.DOTUSDT","type":"delta","data":{"delete":[{"price":"43.560","symbol":"DOTUSDT","id":"435600","side":"Sell"}],"update":[{"price":"43.555","symbol":"DOTUSDT","id":"435550","side":"Buy","size":612},{"price":"43.575","symbol":"DOTUSDT","id":"435750","side":"Sell","size":707.19995},{"price":"43.565","symbol":"DOTUSDT","id":"435650","side":"Sell","size":888.4}],"insert":[{"price":"43.685","symbol":"DOTUSDT","id":"436850","side":"Sell","size":94.00001}]},"cross_seq":"916955110","timestamp_e6":"1618677794403708"}
1618677794.503674: {"topic":"orderBookL2_25.LTCUSDT","type":"delta","data":{"delete":[{"price":"313.13","symbol":"LTCUSDT","id":"3131300","side":"Buy"}],"update":[{"price":"313.41","symbol":"LTCUSDT","id":"3134100","side":"Buy","size":502.69998},{"price":"313.53","symbol":"LTCUSDT","id":"3135300","side":"Sell","size":48.4},{"price":"313.58","symbol":"LTCUSDT","id":"3135800","side":"Sell","size":125.2},{"price":"313.59","symbol":"LTCUSDT","id":"3135900","side":"Sell","size":100.4},{"price":"313.54","symbol":"LTCUSDT","id":"3135400","side":"Sell","size":207}],"insert":[{"price":"313.15","symbol":"LTCUSDT","id":"3131500","side":"Buy","size":147.59999}]},"cross_seq":"1684523907","timestamp_e6":"1618677794419379"}
1618677794.5077581: {"topic":"orderBookL2_25.ADAUSDT","type":"delta","data":{"delete":[{"price":"1.3878","symbol":"ADAUSDT","id":"13878","side":"Sell"}],"update":[{"price":"1.3881","symbol":"ADAUSDT","id":"13881","side":"Sell","size":2626},{"price":"1.3880","symbol":"ADAUSDT","id":"13880","side":"Sell","size":2570},{"price":"1.3882","symbol":"ADAUSDT","id":"13882","side":"Sell","size":6998.0005}],"insert":[{"price":"1.3901","symbol":"ADAUSDT","id":"13901","side":"Sell","size":6684.9995}]},"cross_seq":"916955122","timestamp_e6":"1618677794422288"}
1618677794.518549: {"topic":"orderBookL2_25.XTZUSDT","type":"delta","data":{"delete":[],"update":[{"price":"7.219","symbol":"XTZUSDT","id":"72190","side":"Sell","size":3168.2}],"insert":[]},"cross_seq":"726228952","timestamp_e6":"1618677794434878"}
1618677794.528588: {"topic":"orderBookL2_25.ADAUSDT","type":"delta","data":{"delete":[],"update":[{"price":"1.3880","symbol":"ADAUSDT","id":"13880","side":"Sell","size":2569}],"insert":[]},"cross_seq":"916955136","timestamp_e6":"1618677794442334"}
1618677794.5286279: {"topic":"orderBookL2_25.DOTUSDT","type":"delta","data":{"delete":[{"price":"43.545","symbol":"DOTUSDT","id":"435450","side":"Buy"}],"update":[{"price":"43.530","symbol":"DOTUSDT","id":"435300","side":"Buy","size":59.000004},{"price":"43.570","symbol":"DOTUSDT","id":"435700","side":"Sell","size":512.5},{"price":"43.580","symbol":"DOTUSDT","id":"435800","side":"Sell","size":549.7},{"price":"43.555","symbol":"DOTUSDT","id":"435550","side":"Buy","size":420},{"price":"43.585","symbol":"DOTUSDT","id":"435850","side":"Sell","size":655.9}],"insert":[{"price":"43.560","symbol":"DOTUSDT","id":"435600","side":"Buy","size":332.1}]},"cross_seq":"916955136","timestamp_e6":"1618677794443677"}
1618677794.538173: {"topic":"orderBookL2_25.XTZUSDT","type":"delta","data":{"delete":[],"update":[{"price":"7.224","symbol":"XTZUSDT","id":"72240","side":"Sell","size":1624.1001}],"insert":[]},"cross_seq":"726228953","timestamp_e6":"1618677794454500"}
1618677794.54672: {"topic":"orderBookL2_25.DOTUSDT","type":"delta","data":{"delete":[],"update":[{"price":"43.575","symbol":"DOTUSDT","id":"435750","side":"Sell","size":846.69995},{"price":"43.570","symbol":"DOTUSDT","id":"435700","side":"Sell","size":174},{"price":"43.590","symbol":"DOTUSDT","id":"435900","side":"Sell","size":296.1}],"insert":[]},"cross_seq":"916955145","timestamp_e6":"1618677794462454"}
1618677794.546763: {"topic":"orderBookL2_25.ADAUSDT","type":"delta","data":{"delete":[{"price":"1.3881","symbol":"ADAUSDT","id":"13881","side":"Sell"},{"price":"1.3880","symbol":"ADAUSDT","id":"13880","side":"Sell"}],"update":[],"insert":[{"price":"1.3878","symbol":"ADAUSDT","id":"13878","side":"Sell","size":2569},{"price":"1.3902","symbol":"ADAUSDT","id":"13902","side":"Sell","size":5183}]},"cross_seq":"916955145","timestamp_e6":"1618677794462336"}
1618677794.5509892: {"topic":"orderBookL2_25.ETHUSDT","type":"delta","data":{"delete":[],"update":[{"price":"2363.90","symbol":"ETHUSDT","id":"23639000","side":"Buy","size":23.56},{"price":"2365.20","symbol":"ETHUSDT","id":"23652000","side":"Sell","size":116.5},{"price":"2364.10","symbol":"ETHUSDT","id":"23641000","side":"Buy","size":187.87001},{"price":"2365.00","symbol":"ETHUSDT","id":"23650000","side":"Sell","size":217.71999},{"price":"2364.05","symbol":"ETHUSDT","id":"23640500","side":"Buy","size":119.94},{"price":"2364.00","symbol":"ETHUSDT","id":"23640000","side":"Buy","size":91.32},{"price":"2365.05","symbol":"ETHUSDT","id":"23650500","side":"Sell","size":184.46}],"insert":[]},"cross_seq":"1800546848","timestamp_e6":"1618677794467666"}
1618677794.566016: {"topic":"orderBookL2_25.DOTUSDT","type":"delta","data":{"delete":[{"price":"43.555","symbol":"DOTUSDT","id":"435550","side":"Buy"}],"update":[{"price":"43.560","symbol":"DOTUSDT","id":"435600","side":"Buy","size":352.09998}],"insert":[{"price":"43.425","symbol":"DOTUSDT","id":"434250","side":"Buy","size":241.9}]},"cross_seq":"916955149","timestamp_e6":"1618677794482327"}
1618677794.608068: {"topic":"orderBookL2_25.LINKUSDT","type":"delta","data":{"delete":[{"price":"41.074","symbol":"LINKUSDT","id":"410740","side":"Sell"},{"price":"41.075","symbol":"LINKUSDT","id":"410750","side":"Sell"}],"update":[{"price":"41.055","symbol":"LINKUSDT","id":"410550","side":"Sell","size":70.8}],"insert":[{"price":"41.050","symbol":"LINKUSDT","id":"410500","side":"Sell","size":215.79999},{"price":"41.054","symbol":"LINKUSDT","id":"410540","side":"Sell","size":43.800003}]},"cross_seq":"1970980154","timestamp_e6":"1618677794523972"}
1618677794.612405: {"topic":"orderBookL2_25.BCHUSDT","type":"delta","data":{"delete":[{"price":"1055.45","symbol":"BCHUSDT","id":"10554500","side":"Sell"}],"update":[{"price":"1054.75","symbol":"BCHUSDT","id":"10547500","side":"Buy","size":4.2},{"price":"1055.75","symbol":"BCHUSDT","id":"10557500","side":"Sell","size":4.35},{"price":"1055.70","symbol":"BCHUSDT","id":"10557000","side":"Sell","size":4.44},{"price":"1055.60","symbol":"BCHUSDT","id":"10556000","side":"Sell","size":13.61},{"price":"1054.65","symbol":"BCHUSDT","id":"10546500","side":"Buy","size":14.36},{"price":"1055.65","symbol":"BCHUSDT","id":"10556500","side":"Sell","size":22.470001},{"price":"1054.70","symbol":"BCHUSDT","id":"10547000","side":"Buy","size":21.779999},{"price":"1054.85","symbol":"BCHUSDT","id":"10548500","side":"Buy","size":8.61}],"insert":[{"price":"1055.50","symbol":"BCHUSDT","id":"10555000","side":"Sell","size":9.22}]},"cross_seq":"864133250","timestamp_e6":"1618677794529586"}
1618677794.627616: {"topic":"orderBookL2_25.DOTUSDT","type":"delta","data":{"delete":[{"price":"43.425","symbol":"DOTUSDT","id":"434250","side":"Buy"},{"price":"43.565","symbol":"DOTUSDT","id":"435650","side":"Sell"}],"update":[{"price":"43.530","symbol":"DOTUSDT","id":"435300","side":"Buy","size":360.30002},{"price":"43.590","symbol":"DOTUSDT","id":"435900","side":"Sell","size":409.6},{"price":"43.580","symbol":"DOTUSDT","id":"435800","side":"Sell","size":677.8},{"price":"43.595","symbol":"DOTUSDT","id":"435950","side":"Sell","size":210.40001},{"price":"43.585","symbol":"DOTUSDT","id":"435850","side":"Sell","size":796},{"price":"43.575","symbol":"DOTUSDT","id":"435750","side":"Sell","size":331.5}],"insert":[{"price":"43.690","symbol":"DOTUSDT","id":"436900","side":"Sell","size":141},{"price":"43.545","symbol":"DOTUSDT","id":"435450","side":"Buy","size":447.7}]},"cross_seq":"916955167","timestamp_e6":"1618677794543617"}
1618677794.632517: {"topic":"orderBookL2_25.BCHUSDT","type":"delta","data":{"delete":[{"price":"1056.60","symbol":"BCHUSDT","id":"10566000","side":"Sell"},{"price":"1055.50","symbol":"BCHUSDT","id":"10555000","side":"Sell"}],"update":[{"price":"1055.65","symbol":"BCHUSDT","id":"10556500","side":"Sell","size":18.8},{"price":"1055.55","symbol":"BCHUSDT","id":"10555500","side":"Sell","size":1.9},{"price":"1054.65","symbol":"BCHUSDT","id":"10546500","side":"Buy","size":15.22}],"insert":[{"price":"1055.40","symbol":"BCHUSDT","id":"10554000","side":"Sell","size":9.22},{"price":"1055.45","symbol":"BCHUSDT","id":"10554500","side":"Sell","size":8.02}]},"cross_seq":"864133259","timestamp_e6":"1618677794549601"}
1618677794.6670651: {"topic":"orderBookL2_25.ADAUSDT","type":"delta","data":{"delete":[{"price":"1.3902","symbol":"ADAUSDT","id":"13902","side":"Sell"},{"price":"1.3872","symbol":"ADAUSDT","id":"13872","side":"Buy"},{"price":"1.3901","symbol":"ADAUSDT","id":"13901","side":"Sell"}],"update":[{"price":"1.3860","symbol":"ADAUSDT","id":"13860","side":"Buy","size":2858},{"price":"1.3856","symbol":"ADAUSDT","id":"13856","side":"Buy","size":6468},{"price":"1.3859","symbol":"ADAUSDT","id":"13859","side":"Buy","size":6968},{"price":"1.3852","symbol":"ADAUSDT","id":"13852","side":"Buy","size":766},{"price":"1.3869","symbol":"ADAUSDT","id":"13869","side":"Buy","size":22161.002},{"price":"1.3851","symbol":"ADAUSDT","id":"13851","side":"Buy","size":4235},{"price":"1.3858","symbol":"ADAUSDT","id":"13858","side":"Buy","size":5173},{"price":"1.3855","symbol":"ADAUSDT","id":"13855","side":"Buy","size":1408},{"price":"1.3854","symbol":"ADAUSDT","id":"13854","side":"Buy","size":5330},{"price":"1.3857","symbol":"ADAUSDT","id":"13857","side":"Buy","size":4760},{"price":"1.3863","symbol":"ADAUSDT","id":"13863","side":"Buy","size":10122}],"insert":[{"price":"1.3881","symbol":"ADAUSDT","id":"13881","side":"Sell","size":605},{"price":"1.3849","symbol":"ADAUSDT","id":"13849","side":"Buy","size":2018.0001},{"price":"1.3880","symbol":"ADAUSDT","id":"13880","side":"Sell","size":1023}]},"cross_seq":"916955207","timestamp_e6":"1618677794582366"}
1618677794.6671638: {"topic":"orderBookL2_25.DOTUSDT","type":"delta","data":{"delete":[{"price":"43.430","symbol":"DOTUSDT","id":"434300","side":"Buy"}],"update":[{"price":"43.560","symbol":"DOTUSDT","id":"435600","side":"Buy","size":160.1}],"insert":[{"price":"43.565","symbol":"DOTUSDT","id":"435650","side":"Buy","size":192}]},"cross_seq":"916955207","timestamp_e6":"1618677794583704"}
1618677794.679837: {"topic":"orderBookL2_25.XTZUSDT","type":"delta","data":{"delete":[{"price":"7.205","symbol":"XTZUSDT","id":"72050","side":"Sell"},{"price":"7.180","symbol":"XTZUSDT","id":"71800","side":"Buy"}],"update":[{"price":"7.203","symbol":"XTZUSDT","id":"72030","side":"Buy","size":999.10004},{"price":"7.200","symbol":"XTZUSDT","id":"72000","side":"Buy","size":438.6},{"price":"7.204","symbol":"XTZUSDT","id":"72040","side":"Buy","size":1541.4}],"insert":[{"price":"7.205","symbol":"XTZUSDT","id":"72050","side":"Buy","size":889.2},{"price":"7.211","symbol":"XTZUSDT","id":"72110","side":"Sell","size":250.7}]},"cross_seq":"726228960","timestamp_e6":"1618677794596296"}
1618677794.698129: {"topic":"orderBookL2_25.XTZUSDT","type":"delta","data":{"delete":[],"update":[{"price":"7.207","symbol":"XTZUSDT","id":"72070","side":"Sell","size":262},{"price":"7.210","symbol":"XTZUSDT","id":"72100","side":"Sell","size":622},{"price":"7.203","symbol":"XTZUSDT","id":"72030","side":"Buy","size":1135.3},{"price":"7.211","symbol":"XTZUSDT","id":"72110","side":"Sell","size":427}],"insert":[]},"cross_seq":"726228965","timestamp_e6":"1618677794614594"}
1618677794.706471: {"topic":"orderBookL2_25.DOTUSDT","type":"delta","data":{"delete":[],"update":[{"price":"43.595","symbol":"DOTUSDT","id":"435950","side":"Sell","size":296.1},{"price":"43.585","symbol":"DOTUSDT","id":"435850","side":"Sell","size":596.8},{"price":"43.565","symbol":"DOTUSDT","id":"435650","side":"Buy","size":202},{"price":"43.570","symbol":"DOTUSDT","id":"435700","side":"Sell","size":1120.6},{"price":"43.590","symbol":"DOTUSDT","id":"435900","side":"Sell","size":210.40001},{"price":"43.575","symbol":"DOTUSDT","id":"435750","side":"Sell","size":489.00003},{"price":"43.560","symbol":"DOTUSDT","id":"435600","side":"Buy","size":10}],"insert":[]},"cross_seq":"916955218","timestamp_e6":"1618677794622361"}
1618677794.708174: {"topic":"orderBookL2_25.LINKUSDT","type":"delta","data":{"delete":[{"price":"41.034","symbol":"LINKUSDT","id":"410340","side":"Buy"}],"update":[{"price":"41.062","symbol":"LINKUSDT","id":"410620","side":"Sell","size":102.799995},{"price":"41.037","symbol":"LINKUSDT","id":"410370","side":"Buy","size":352.8},{"price":"41.036","symbol":"LINKUSDT","id":"410360","side":"Buy","size":525.2},{"price":"41.061","symbol":"LINKUSDT","id":"410610","side":"Sell","size":162},{"price":"41.035","symbol":"LINKUSDT","id":"410350","side":"Buy","size":131.4},{"price":"41.033","symbol":"LINKUSDT","id":"410330","side":"Buy","size":899.19995},{"price":"41.058","symbol":"LINKUSDT","id":"410580","side":"Sell","size":219.90001},{"price":"41.059","symbol":"LINKUSDT","id":"410590","side":"Sell","size":178.40001},{"price":"41.032","symbol":"LINKUSDT","id":"410320","side":"Buy","size":311.19998},{"price":"41.042","symbol":"LINKUSDT","id":"410420","side":"Buy","size":156.40001},{"price":"41.060","symbol":"LINKUSDT","id":"410600","side":"Sell","size":100.600006},{"price":"41.063","symbol":"LINKUSDT","id":"410630","side":"Sell","size":327.1}],"insert":[{"price":"41.020","symbol":"LINKUSDT","id":"410200","side":"Buy","size":331.5}]},"cross_seq":"1970980183","timestamp_e6":"1618677794623782"}
1618677794.71931: {"topic":"orderBookL2_25.XTZUSDT","type":"delta","data":{"delete":[],"update":[{"price":"7.205","symbol":"XTZUSDT","id":"72050","side":"Buy","size":3739.2}],"insert":[]},"cross_seq":"726228968","timestamp_e6":"1618677794635410"}
1618677794.7225118: {"topic":"orderBookL2_25.LTCUSDT","type":"delta","data":{"delete":[{"price":"313.52","symbol":"LTCUSDT","id":"3135200","side":"Sell"}],"update":[{"price":"313.57","symbol":"LTCUSDT","id":"3135700","side":"Sell","size":129.7},{"price":"313.58","symbol":"LTCUSDT","id":"3135800","side":"Sell","size":36},{"price":"313.53","symbol":"LTCUSDT","id":"3135300","side":"Sell","size":130.5}],"insert":[{"price":"313.73","symbol":"LTCUSDT","id":"3137300","side":"Sell","size":137.8}]},"cross_seq":"1684523922","timestamp_e6":"1618677794638215"}
1618677794.740831: {"topic":"orderBookL2_25.XTZUSDT","type":"delta","data":{"delete":[{"price":"7.206","symbol":"XTZUSDT","id":"72060","side":"Sell"}],"update":[{"price":"7.209","symbol":"XTZUSDT","id":"72090","side":"Sell","size":2434.0999},{"price":"7.210","symbol":"XTZUSDT","id":"72100","side":"Sell","size":782.5},{"price":"7.200","symbol":"XTZUSDT","id":"72000","side":"Buy","size":526.7},{"price":"7.208","symbol":"XTZUSDT","id":"72080","side":"Sell","size":460.8},{"price":"7.211","symbol":"XTZUSDT","id":"72110","side":"Sell","size":965.2},{"price":"7.212","symbol":"XTZUSDT","id":"72120","side":"Sell","size":516.60004},{"price":"7.204","symbol":"XTZUSDT","id":"72040","side":"Buy","size":1441.3999}],"insert":[{"price":"7.231","symbol":"XTZUSDT","id":"72310","side":"Sell","size":1960.2}]},"cross_seq":"726228994","timestamp_e6":"1618677794655232"}
1618677794.758889: {"topic":"orderBookL2_25.XTZUSDT","type":"delta","data":{"delete":[],"update":[{"price":"7.209","symbol":"XTZUSDT","id":"72090","side":"Sell","size":1812.1001},{"price":"7.211","symbol":"XTZUSDT","id":"72110","side":"Sell","size":538.2},{"price":"7.207","symbol":"XTZUSDT","id":"72070","side":"Sell","size":1204.6},{"price":"7.208","symbol":"XTZUSDT","id":"72080","side":"Sell","size":1163}],"insert":[]},"cross_seq":"726229026","timestamp_e6":"1618677794675067"}
1618677794.7631109: {"topic":"orderBookL2_25.LTCUSDT","type":"delta","data":{"delete":[],"update":[{"price":"313.57","symbol":"LTCUSDT","id":"3135700","side":"Sell","size":150.1},{"price":"313.56","symbol":"LTCUSDT","id":"3135600","side":"Sell","size":95.5},{"price":"313.58","symbol":"LTCUSDT","id":"3135800","side":"Sell","size":58.300003}],"insert":[]},"cross_seq":"1684523929","timestamp_e6":"1618677794678596"}
1618677794.7673202: {"topic":"orderBookL2_25.UNIUSDT","type":"delta","data":{"delete":[],"update":[{"price":"35.372","symbol":"UNIUSDT","id":"353720","side":"Buy","size":53.4},{"price":"35.404","symbol":"UNIUSDT","id":"354040","side":"Sell","size":140},{"price":"35.405","symbol":"UNIUSDT","id":"354050","side":"Sell","size":150.2},{"price":"35.407","symbol":"UNIUSDT","id":"354070","side":"Sell","size":94.299995},{"price":"35.375","symbol":"UNIUSDT","id":"353750","side":"Buy","size":51.100002},{"price":"35.374","symbol":"UNIUSDT","id":"353740","side":"Buy","size":63.3},{"price":"35.406","symbol":"UNIUSDT","id":"354060","side":"Sell","size":126.700005}],"insert":[]},"cross_seq":"916955225","timestamp_e6":"1618677794682359"}
1618677794.780234: {"topic":"orderBookL2_25.XTZUSDT","type":"delta","data":{"delete":[],"update":[{"price":"7.205","symbol":"XTZUSDT","id":"72050","side":"Buy","size":889.2},{"price":"7.216","symbol":"XTZUSDT","id":"72160","side":"Sell","size":590.3},{"price":"7.218","symbol":"XTZUSDT","id":"72180","side":"Sell","size":3646.5},{"price":"7.213","symbol":"XTZUSDT","id":"72130","side":"Sell","size":1373.1}],"insert":[]},"cross_seq":"726229031","timestamp_e6":"1618677794695840"}
1618677794.79257: {"topic":"orderBookL2_25.ETHUSDT","type":"delta","data":{"delete":[],"update":[{"price":"2364.90","symbol":"ETHUSDT","id":"23649000","side":"Buy","size":51.420002}],"insert":[]},"cross_seq":"1800546849","timestamp_e6":"1618677794708982"}
1618677794.806964: {"topic":"orderBookL2_25.UNIUSDT","type":"delta","data":{"delete":[],"update":[{"price":"35.372","symbol":"UNIUSDT","id":"353720","side":"Buy","size":38.899998},{"price":"35.375","symbol":"UNIUSDT","id":"353750","side":"Buy","size":63.800003},{"price":"35.405","symbol":"UNIUSDT","id":"354050","side":"Sell","size":107.8},{"price":"35.373","symbol":"UNIUSDT","id":"353730","side":"Buy","size":43.399998},{"price":"35.371","symbol":"UNIUSDT","id":"353710","side":"Buy","size":18.5}],"insert":[]},"cross_seq":"916955240","timestamp_e6":"1618677794722555"}
1618677794.807071: {"topic":"orderBookL2_25.DOTUSDT","type":"delta","data":{"delete":[],"update":[{"price":"43.570","symbol":"DOTUSDT","id":"435700","side":"Sell","size":782.1}],"insert":[]},"cross_seq":"916955240","timestamp_e6":"1618677794722451"}
1618677794.807091: {"topic":"orderBookL2_25.ADAUSDT","type":"delta","data":{"delete":[{"price":"1.3871","symbol":"ADAUSDT","id":"13871","side":"Buy"},{"price":"1.3873","symbol":"ADAUSDT","id":"13873","side":"Buy"}],"update":[{"price":"1.3867","symbol":"ADAUSDT","id":"13867","side":"Buy","size":5292},{"price":"1.3868","symbol":"ADAUSDT","id":"13868","side":"Buy","size":13203.001}],"insert":[{"price":"1.3848","symbol":"ADAUSDT","id":"13848","side":"Buy","size":3559},{"price":"1.3847","symbol":"ADAUSDT","id":"13847","side":"Buy","size":4462}]},"cross_seq":"916955240","timestamp_e6":"1618677794722341"}
1618677794.814076: {"topic":"orderBookL2_25.ETHUSDT","type":"delta","data":{"delete":[],"update":[{"price":"2364.90","symbol":"ETHUSDT","id":"23649000","side":"Buy","size":11.969999},{"price":"2363.90","symbol":"ETHUSDT","id":"23639000","side":"Buy","size":37.72}],"insert":[]},"cross_seq":"1800546852","timestamp_e6":"1618677794729792"}
1618677794.822442: {"topic":"orderBookL2_25.LTCUSDT","type":"delta","data":{"delete":[{"price":"313.15","symbol":"LTCUSDT","id":"3131500","side":"Buy"}],"update":[{"price":"313.56","symbol":"LTCUSDT","id":"3135600","side":"Sell","size":112.9}],"insert":[{"price":"313.14","symbol":"LTCUSDT","id":"3131400","side":"Buy","size":119.399994}]},"cross_seq":"1684523934","timestamp_e6":"1618677794737890"}
1618677794.832101: {"topic":"orderBookL2_25.ETHUSDT","type":"delta","data":{"delete":[],"update":[{"price":"2364.90","symbol":"ETHUSDT","id":"23649000","side":"Buy","size":1.97},{"price":"2364.10","symbol":"ETHUSDT","id":"23641000","side":"Buy","size":197.87}],"insert":[]},"cross_seq":"1800546854","timestamp_e6":"1618677794748694"}
1618677794.841641: {"topic":"orderBookL2_25.XTZUSDT","type":"delta","data":{"delete":[],"update":[{"price":"7.205","symbol":"XTZUSDT","id":"72050","side":"Buy","size":889.4},{"price":"7.207","symbol":"XTZUSDT","id":"72070","side":"Sell","size":1304.6}],"insert":[]},"cross_seq":"726229034","timestamp_e6":"1618677794756078"}
1618677794.84366: {"topic":"orderBookL2_25.LTCUSDT","type":"delta","data":{"delete":[],"update":[{"price":"313.41","symbol":"LTCUSDT","id":"3134100","side":"Buy","size":336.4}],"insert":[]},"cross_seq":"1684523935","timestamp_e6":"1618677794759009"}
1618677794.848342: {"topic":"orderBookL2_25.UNIUSDT","type":"delta","data":{"delete":[{"price":"35.356","symbol":"UNIUSDT","id":"353560","side":"Buy"}],"update":[{"price":"35.375","symbol":"UNIUSDT","id":"353750","side":"Buy","size":84.3},{"price":"35.377","symbol":"UNIUSDT","id":"353770","side":"Buy","size":24.2},{"price":"35.376","symbol":"UNIUSDT","id":"353760","side":"Buy","size":80.8}],"insert":[{"price":"35.378","symbol":"UNIUSDT","id":"353780","side":"Buy","size":66.6}]},"cross_seq":"916955245","timestamp_e6":"1618677794762907"}
1618677794.855007: {"topic":"orderBookL2_25.ETHUSDT","type":"delta","data":{"delete":[{"price":"2363.45","symbol":"ETHUSDT","id":"23634500","side":"Buy"}],"update":[{"price":"2363.30","symbol":"ETHUSDT","id":"23633000","side":"Buy","size":116.28},{"price":"2364.40","symbol":"ETHUSDT","id":"23644000","side":"Buy","size":5},{"price":"2363.35","symbol":"ETHUSDT","id":"23633500","side":"Buy","size":61.23},{"price":"2364.90","symbol":"ETHUSDT","id":"23649000","side":"Buy","size":0.02},{"price":"2363.25","symbol":"ETHUSDT","id":"23632500","side":"Buy","size":29.390001},{"price":"2363.40","symbol":"ETHUSDT","id":"23634000","side":"Buy","size":64.34}],"insert":[{"price":"2363.10","symbol":"ETHUSDT","id":"23631000","side":"Buy","size":59.890003}]},"cross_seq":"1800546909","timestamp_e6":"1618677794768271"}
1618677794.860051: {"topic":"orderBookL2_25.XTZUSDT","type":"delta","data":{"delete":[],"update":[{"price":"7.207","symbol":"XTZUSDT","id":"72070","side":"Sell","size":1204.6}],"insert":[]},"cross_seq":"726229035","timestamp_e6":"1618677794775281"}
1618677794.867785: {"topic":"orderBookL2_25.ADAUSDT","type":"delta","data":{"delete":[{"price":"1.3848","symbol":"ADAUSDT","id":"13848","side":"Buy"},{"price":"1.3847","symbol":"ADAUSDT","id":"13847","side":"Buy"}],"update":[{"price":"1.3868","symbol":"ADAUSDT","id":"13868","side":"Buy","size":10680}],"insert":[{"price":"1.3871","symbol":"ADAUSDT","id":"13871","side":"Buy","size":5190},{"price":"1.3872","symbol":"ADAUSDT","id":"13872","side":"Buy","size":5024}]},"cross_seq":"916955249","timestamp_e6":"1618677794782442"}
1618677794.8710122: {"topic":"orderBookL2_25.ETHUSDT","type":"delta","data":{"delete":[{"price":"2363.95","symbol":"ETHUSDT","id":"23639500","side":"Buy"},{"price":"2364.40","symbol":"ETHUSDT","id":"23644000","side":"Buy"},{"price":"2363.50","symbol":"ETHUSDT","id":"23635000","side":"Buy"}],"update":[{"price":"2364.10","symbol":"ETHUSDT","id":"23641000","side":"Buy","size":71.79},{"price":"2363.60","symbol":"ETHUSDT","id":"23636000","side":"Buy","size":50.86},{"price":"2363.70","symbol":"ETHUSDT","id":"23637000","side":"Buy","size":49.09},{"price":"2363.85","symbol":"ETHUSDT","id":"23638500","side":"Buy","size":5},{"price":"2363.90","symbol":"ETHUSDT","id":"23639000","side":"Buy","size":23.56},{"price":"2363.15","symbol":"ETHUSDT","id":"23631500","side":"Buy","size":76.11},{"price":"2364.05","symbol":"ETHUSDT","id":"23640500","side":"Buy","size":58.71},{"price":"2363.75","symbol":"ETHUSDT","id":"23637500","side":"Buy","size":74.08},{"price":"2363.20","symbol":"ETHUSDT","id":"23632000","side":"Buy","size":101.29},{"price":"2364.15","symbol":"ETHUSDT","id":"23641500","side":"Buy","size":84.509995},{"price":"2363.80","symbol":"ETHUSDT","id":"23638000","side":"Buy","size":94.4},{"price":"2363.30","symbol":"ETHUSDT","id":"23633000","side":"Buy","size":133.61},{"price":"2363.25","symbol":"ETHUSDT","id":"23632500","side":"Buy","size":60.54},{"price":"2363.55","symbol":"ETHUSDT","id":"23635500","side":"Buy","size":42.64},{"price":"2363.10","symbol":"ETHUSDT","id":"23631000","side":"Buy","size":85.75},{"price":"2364.00","symbol":"ETHUSDT","id":"23640000","side":"Buy","size":56.26},{"price":"2363.65","symbol":"ETHUSDT","id":"23636500","side":"Buy","size":35.17}],"insert":[{"price":"2363.05","symbol":"ETHUSDT","id":"23630500","side":"Buy","size":64.61},{"price":"2363.00","symbol":"ETHUSDT","id":"23630000","side":"Buy","size":56.95},{"price":"2362.95","symbol":"ETHUSDT","id":"23629500","side":"Buy","size":37.84}]},"cross_seq":"1800546938","timestamp_e6":"1618677794787169"}
1618677794.879518: {"topic":"orderBookL2_25.XTZUSDT","type":"delta","data":{"delete":[{"price":"7.208","symbol":"XTZUSDT","id":"72080","side":"Sell"}],"update":[{"price":"7.211","symbol":"XTZUSDT","id":"72110","side":"Sell","size":965.2},{"price":"7.215","symbol":"XTZUSDT","id":"72150","side":"Sell","size":995.80005},{"price":"7.216","symbol":"XTZUSDT","id":"72160","side":"Sell","size":337.1},{"price":"7.209","symbol":"XTZUSDT","id":"72090","side":"Sell","size":2434.0999},{"price":"7.217","symbol":"XTZUSDT","id":"72170","side":"Sell","size":275.7},{"price":"7.212","symbol":"XTZUSDT","id":"72120","side":"Sell","size":1425.8}],"insert":[{"price":"7.232","symbol":"XTZUSDT","id":"72320","side":"Sell","size":49.6}]},"cross_seq":"726229045","timestamp_e6":"1618677794794673"}
1618677794.888164: {"topic":"orderBookL2_25.DOTUSDT","type":"delta","data":{"delete":[{"price":"43.590","symbol":"DOTUSDT","id":"435900","side":"Sell"}],"update":[{"price":"43.500","symbol":"DOTUSDT","id":"435000","side":"Buy","size":546.7},{"price":"43.585","symbol":"DOTUSDT","id":"435850","side":"Sell","size":683.3},{"price":"43.475","symbol":"DOTUSDT","id":"434750","side":"Buy","size":70.3},{"price":"43.575","symbol":"DOTUSDT","id":"435750","side":"Sell","size":765.3},{"price":"43.580","symbol":"DOTUSDT","id":"435800","side":"Sell","size":558.5},{"price":"43.595","symbol":"DOTUSDT","id":"435950","side":"Sell","size":85.7}],"insert":[{"price":"43.695","symbol":"DOTUSDT","id":"436950","side":"Sell","size":371.6}]},"cross_seq":"916955267","timestamp_e6":"1618677794802376"}
1618677794.891414: {"topic":"orderBookL2_25.ETHUSDT","type":"delta","data":{"delete":[],"update":[{"price":"2364.55","symbol":"ETHUSDT","id":"23645500","side":"Buy","size":0.01},{"price":"2363.80","symbol":"ETHUSDT","id":"23638000","side":"Buy","size":95.61},{"price":"2365.85","symbol":"ETHUSDT","id":"23658500","side":"Sell","size":5.78}],"insert":[]},"cross_seq":"1800546942","timestamp_e6":"1618677794807032"}
1618677794.8914921: {"topic":"orderBookL2_25.BCHUSDT","type":"delta","data":{"delete":[{"price":"1056.55","symbol":"BCHUSDT","id":"10565500","side":"Sell"}],"update":[{"price":"1055.55","symbol":"BCHUSDT","id":"10555500","side":"Sell","size":3.4},{"price":"1055.65","symbol":"BCHUSDT","id":"10556500","side":"Sell","size":20.52}],"insert":[{"price":"1055.50","symbol":"BCHUSDT","id":"10555000","side":"Sell","size":4.79}]},"cross_seq":"864133263","timestamp_e6":"1618677794808832"}
1618677794.8987231: {"topic":"orderBookL2_25.XTZUSDT","type":"delta","data":{"delete":[],"update":[{"price":"7.219","symbol":"XTZUSDT","id":"72190","side":"Sell","size":1653.2}],"insert":[]},"cross_seq":"726229046","timestamp_e6":"1618677794814697"}
1618677794.906268: {"topic":"orderBookL2_25.UNIUSDT","type":"delta","data":{"delete":[],"update":[{"price":"35.359","symbol":"UNIUSDT","id":"353590","side":"Buy","size":23.3},{"price":"35.402","symbol":"UNIUSDT","id":"354020","side":"Sell","size":156.40001}],"insert":[]},"cross_seq":"916955271","timestamp_e6":"1618677794822410"}
1618677794.907567: {"topic":"trade.ETHUSDT","data":[{"symbol":"ETHUSDT","tick_direction":"MinusTick","price":"2364.90","size":0.01,"timestamp":"2021-04-17T16:43:14.000Z","trade_time_ms":"1618677794812","side":"Sell","trade_id":"8653a00a-c526-5486-b69c-5c8da4f0ff6a"},{"symbol":"ETHUSDT","tick_direction":"ZeroMinusTick","price":"2364.90","size":0.01,"timestamp":"2021-04-17T16:43:14.000Z","trade_time_ms":"1618677794812","side":"Sell","trade_id":"36c78359-90fd-5b39-ae6e-9796d062e3c7"}]}
1618677794.9138: {"topic":"orderBookL2_25.ETHUSDT","type":"delta","data":{"delete":[{"price":"2364.10","symbol":"ETHUSDT","id":"23641000","side":"Buy"},{"price":"2363.70","symbol":"ETHUSDT","id":"23637000","side":"Buy"},{"price":"2363.75","symbol":"ETHUSDT","id":"23637500","side":"Buy"},{"price":"2364.00","symbol":"ETHUSDT","id":"23640000","side":"Buy"},{"price":"2364.05","symbol":"ETHUSDT","id":"23640500","side":"Buy"},{"price":"2363.90","symbol":"ETHUSDT","id":"23639000","side":"Buy"},{"price":"2363.65","symbol":"ETHUSDT","id":"23636500","side":"Buy"},{"price":"2364.15","symbol":"ETHUSDT","id":"23641500","side":"Buy"},{"price":"2366.35","symbol":"ETHUSDT","id":"23663500","side":"Sell"},{"price":"2363.60","symbol":"ETHUSDT","id":"23636000","side":"Buy"},{"price":"2364.90","symbol":"ETHUSDT","id":"23649000","side":"Buy"}],"update":[{"price":"2363.55","symbol":"ETHUSDT","id":"23635500","side":"Buy","size":10},{"price":"2363.30","symbol":"ETHUSDT","id":"23633000","side":"Buy","size":55.93},{"price":"2363.10","symbol":"ETHUSDT","id":"23631000","side":"Buy","size":34.89},{"price":"2363.80","symbol":"ETHUSDT","id":"23638000","side":"Buy","size":1.21},{"price":"2363.05","symbol":"ETHUSDT","id":"23630500","side":"Buy","size":103.759995}],"insert":[{"price":"2362.65","symbol":"ETHUSDT","id":"23626500","side":"Buy","size":29.51},{"price":"2362.55","symbol":"ETHUSDT","id":"23625500","side":"Buy","size":60.829998},{"price":"2362.90","symbol":"ETHUSDT","id":"23629000","side":"Buy","size":37.88},{"price":"2362.70","symbol":"ETHUSDT","id":"23627000","side":"Buy","size":29.180002},{"price":"2364.60","symbol":"ETHUSDT","id":"23646000","side":"Sell","size":1.95},{"price":"2362.50","symbol":"ETHUSDT","id":"23625000","side":"Buy","size":66.28},{"price":"2362.75","symbol":"ETHUSDT","id":"23627500","side":"Buy","size":49.250004},{"price":"2362.60","symbol":"ETHUSDT","id":"23626000","side":"Buy","size":62.71},{"price":"2362.85","symbol":"ETHUSDT","id":"23628500","side":"Buy","size":24.419998},{"price":"2362.45","symbol":"ETHUSDT","id":"23624500","side":"Buy","size":11.2},{"price":"2362.80","symbol":"ETHUSDT","id":"23628000","side":"Buy","size":88.409996}]},"cross_seq":"1800546967","timestamp_e6":"1618677794828917"}
1618677794.919015: {"topic":"orderBookL2_25.XTZUSDT","type":"delta","data":{"delete":[],"update":[{"price":"7.224","symbol":"XTZUSDT","id":"72240","side":"Sell","size":124.100006}],"insert":[]},"cross_seq":"726229047","timestamp_e6":"1618677794834888"}
1618677794.929804: {"topic":"orderBookL2_25.ADAUSDT","type":"delta","data":{"delete":[],"update":[{"price":"1.3859","symbol":"ADAUSDT","id":"13859","side":"Buy","size":5149},{"price":"1.3860","symbol":"ADAUSDT","id":"13860","side":"Buy","size":5155},{"price":"1.3885","symbol":"ADAUSDT","id":"13885","side":"Sell","size":2760.0002},{"price":"1.3886","symbol":"ADAUSDT","id":"13886","side":"Sell","size":874}],"insert":[]},"cross_seq":"916955280","timestamp_e6":"1618677794842343"}
1618677794.929866: {"topic":"orderBookL2_25.UNIUSDT","type":"delta","data":{"delete":[{"price":"35.378","symbol":"UNIUSDT","id":"353780","side":"Buy"}],"update":[{"price":"35.376","symbol":"UNIUSDT","id":"353760","side":"Buy","size":97.9},{"price":"35.374","symbol":"UNIUSDT","id":"353740","side":"Buy","size":53.2}],"insert":[{"price":"35.379","symbol":"UNIUSDT","id":"353790","side":"Buy","size":66.6}]},"cross_seq":"916955280","timestamp_e6":"1618677794842461"}
1618677794.93068: {"topic":"orderBookL2_25.ETHUSDT","type":"delta","data":{"delete":[{"price":"2366.30","symbol":"ETHUSDT","id":"23663000","side":"Sell"},{"price":"2363.35","symbol":"ETHUSDT","id":"23633500","side":"Buy"}],"update":[{"price":"2364.60","symbol":"ETHUSDT","id":"23646000","side":"Sell","size":116.33},{"price":"2363.40","symbol":"ETHUSDT","id":"23634000","side":"Buy","size":3.8},{"price":"2364.95","symbol":"ETHUSDT","id":"23649500","side":"Sell","size":364.24}],"insert":[{"price":"2362.40","symbol":"ETHUSDT","id":"23624000","side":"Buy","size":27.2},{"price":"2364.90","symbol":"ETHUSDT","id":"23649000","side":"Sell","size":18.150002}]},"cross_seq":"1800546976","timestamp_e6":"1618677794847591"}
1618677794.9405692: {"topic":"orderBookL2_25.XTZUSDT","type":"delta","data":{"delete":[],"update":[{"price":"7.205","symbol":"XTZUSDT","id":"72050","side":"Buy","size":989.4}],"insert":[]},"cross_seq":"726229048","timestamp_e6":"1618677794855941"}
1618677794.943669: {"topic":"orderBookL2_25.LTCUSDT","type":"delta","data":{"delete":[{"price":"313.42","symbol":"LTCUSDT","id":"3134200","side":"Sell"}],"update":[{"price":"313.45","symbol":"LTCUSDT","id":"3134500","side":"Sell","size":1.1}],"insert":[{"price":"313.74","symbol":"LTCUSDT","id":"3137400","side":"Sell","size":283.7}]},"cross_seq":"1684523936","timestamp_e6":"1618677794859109"}
1618677794.947968: {"topic":"orderBookL2_25.UNIUSDT","type":"delta","data":{"delete":[{"price":"35.357","symbol":"UNIUSDT","id":"353570","side":"Buy"},{"price":"35.358","symbol":"UNIUSDT","id":"353580","side":"Buy"},{"price":"35.379","symbol":"UNIUSDT","id":"353790","side":"Buy"}],"update":[{"price":"35.376","symbol":"UNIUSDT","id":"353760","side":"Buy","size":77.1},{"price":"35.377","symbol":"UNIUSDT","id":"353770","side":"Buy","size":31.8}],"insert":[{"price":"35.380","symbol":"UNIUSDT","id":"353800","side":"Buy","size":44.5},{"price":"35.378","symbol":"UNIUSDT","id":"353780","side":"Buy","size":37.9},{"price":"35.381","symbol":"UNIUSDT","id":"353810","side":"Buy","size":66.6}]},"cross_seq":"916955331","timestamp_e6":"1618677794862467"}
1618677794.948069: {"topic":"orderBookL2_25.ADAUSDT","type":"delta","data":{"delete":[{"price":"1.3878","symbol":"ADAUSDT","id":"13878","side":"Sell"}],"update":[{"price":"1.3869","symbol":"ADAUSDT","id":"13869","side":"Buy","size":16869},{"price":"1.3866","symbol":"ADAUSDT","id":"13866","side":"Buy","size":5292},{"price":"1.3868","symbol":"ADAUSDT","id":"13868","side":"Buy","size":13101},{"price":"1.3882","symbol":"ADAUSDT","id":"13882","side":"Sell","size":8021},{"price":"1.3880","symbol":"ADAUSDT","id":"13880","side":"Sell","size":2569},{"price":"1.3881","symbol":"ADAUSDT","id":"13881","side":"Sell","size":2626},{"price":"1.3867","symbol":"ADAUSDT","id":"13867","side":"Buy","size":6536.9995}],"insert":[{"price":"1.3901","symbol":"ADAUSDT","id":"13901","side":"Sell","size":6684.9995}]},"cross_seq":"916955331","timestamp_e6":"1618677794862326"}
1618677794.948138: {"topic":"orderBookL2_25.LINKUSDT","type":"delta","data":{"delete":[{"price":"41.020","symbol":"LINKUSDT","id":"410200","side":"Buy"}],"update":[{"price":"41.032","symbol":"LINKUSDT","id":"410320","side":"Buy","size":353.3}],"insert":[{"price":"41.034","symbol":"LINKUSDT","id":"410340","side":"Buy","size":51.000004}]},"cross_seq":"1970980188","timestamp_e6":"1618677794863912"}
1618677794.952172: {"topic":"orderBookL2_25.ETHUSDT","type":"delta","data":{"delete":[{"price":"2366.00","symbol":"ETHUSDT","id":"23660000","side":"Sell"},{"price":"2365.90","symbol":"ETHUSDT","id":"23659000","side":"Sell"},{"price":"2366.20","symbol":"ETHUSDT","id":"23662000","side":"Sell"},{"price":"2366.05","symbol":"ETHUSDT","id":"23660500","side":"Sell"},{"price":"2366.10","symbol":"ETHUSDT","id":"23661000","side":"Sell"},{"price":"2365.95","symbol":"ETHUSDT","id":"23659500","side":"Sell"},{"price":"2365.85","symbol":"ETHUSDT","id":"23658500","side":"Sell"},{"price":"2363.25","symbol":"ETHUSDT","id":"23632500","side":"Buy"},{"price":"2366.25","symbol":"ETHUSDT","id":"23662500","side":"Sell"},{"price":"2366.15","symbol":"ETHUSDT","id":"23661500","side":"Sell"}],"update":[{"price":"2365.05","symbol":"ETHUSDT","id":"23650500","side":"Sell","size":63.28},{"price":"2363.15","symbol":"ETHUSDT","id":"23631500","side":"Buy","size":61.23},{"price":"2362.85","symbol":"ETHUSDT","id":"23628500","side":"Buy","size":38.84},{"price":"2365.45","symbol":"ETHUSDT","id":"23654500","side":"Sell","size":41.699997},{"price":"2364.90","symbol":"ETHUSDT","id":"23649000","side":"Sell","size":99.22},{"price":"2362.90","symbol":"ETHUSDT","id":"23629000","side":"Buy","size":59.66},{"price":"2365.00","symbol":"ETHUSDT","id":"23650000","side":"Sell","size":67.91},{"price":"2364.60","symbol":"ETHUSDT","id":"23646000","side":"Sell","size":276.28},{"price":"2362.95","symbol":"ETHUSDT","id":"23629500","side":"Buy","size":75.13},{"price":"2363.20","symbol":"ETHUSDT","id":"23632000","side":"Buy","size":61.23},{"price":"2364.95","symbol":"ETHUSDT","id":"23649500","side":"Sell","size":150.28},{"price":"2365.10","symbol":"ETHUSDT","id":"23651000","side":"Sell","size":75.079994},{"price":"2363.00","symbol":"ETHUSDT","id":"23630000","side":"Buy","size":115.53001},{"price":"2363.05","symbol":"ETHUSDT","id":"23630500","side":"Buy","size":51.02},{"price":"2365.15","symbol":"ETHUSDT","id":"23651500","side":"Sell","size":76.729996},{"price":"2365.20","symbol":"ETHUSDT","id":"23652000","side":"Sell","size":53.3}],"insert":[{"price":"2364.75","symbol":"ETHUSDT","id":"23647500","side":"Sell","size":79.38},{"price":"2365.30","symbol":"ETHUSDT","id":"23653000","side":"Sell","size":9.53},{"price":"2364.80","symbol":"ETHUSDT","id":"23648000","side":"Sell","size":173.36},{"price":"2362.35","symbol":"ETHUSDT","id":"23623500","side":"Buy","size":14.190001},{"price":"2364.85","symbol":"ETHUSDT","id":"23648500","side":"Sell","size":167.31},{"price":"2365.25","symbol":"ETHUSDT","id":"23652500","side":"Sell","size":7.87},{"price":"2365.35","symbol":"ETHUSDT","id":"23653500","side":"Sell","size":6.91},{"price":"2364.70","symbol":"ETHUSDT","id":"23647000","side":"Sell","size":98.369995},{"price":"2364.65","symbol":"ETHUSDT","id":"23646500","side":"Sell","size":111.38},{"price":"2365.40","symbol":"ETHUSDT","id":"23654000","side":"Sell","size":14.409999}]},"cross_seq":"1800547048","timestamp_e6":"1618677794867667"}
1618677794.9640489: {"topic":"orderBookL2_25.LTCUSDT","type":"delta","data":{"delete":[{"price":"313.31","symbol":"LTCUSDT","id":"3133100","side":"Buy"},{"price":"313.39","symbol":"LTCUSDT","id":"3133900","side":"Buy"},{"price":"313.34","symbol":"LTCUSDT","id":"3133400","side":"Buy"},{"price":"313.30","symbol":"LTCUSDT","id":"3133000","side":"Buy"},{"price":"313.40","symbol":"LTCUSDT","id":"3134000","side":"Buy"},{"price":"313.38","symbol":"LTCUSDT","id":"3133800","side":"Buy"},{"price":"313.37","symbol":"LTCUSDT","id":"3133700","side":"Buy"},{"price":"313.33","symbol":"LTCUSDT","id":"3133300","side":"Buy"}],"update":[{"price":"313.58","symbol":"LTCUSDT","id":"3135800","side":"Sell","size":86.00001},{"price":"313.29","symbol":"LTCUSDT","id":"3132900","side":"Buy","size":99.399994},{"price":"313.18","symbol":"LTCUSDT","id":"3131800","side":"Buy","size":53.100002},{"price":"313.14","symbol":"LTCUSDT","id":"3131400","side":"Buy","size":147.59999},{"price":"313.36","symbol":"LTCUSDT","id":"3133600","side":"Buy","size":109.2},{"price":"313.41","symbol":"LTCUSDT","id":"3134100","side":"Buy","size":179.99998}],"insert":[{"price":"313.13","symbol":"LTCUSDT","id":"3131300","side":"Buy","size":150.2},{"price":"313.16","symbol":"LTCUSDT","id":"3131600","side":"Buy","size":3.5},{"price":"313.43","symbol":"LTCUSDT","id":"3134300","side":"Buy","size":160.3},{"price":"313.15","symbol":"LTCUSDT","id":"3131500","side":"Buy","size":71.9},{"price":"313.35","symbol":"LTCUSDT","id":"3133500","side":"Buy","size":2.8},{"price":"313.42","symbol":"LTCUSDT","id":"3134200","side":"Buy","size":140.90001},{"price":"313.12","symbol":"LTCUSDT","id":"3131200","side":"Buy","size":85.2},{"price":"313.44","symbol":"LTCUSDT","id":"3134400","side":"Buy","size":160.2}]},"cross_seq":"1684523962","timestamp_e6":"1618677794879297"}
1618677794.9671822: {"topic":"orderBookL2_25.DOTUSDT","type":"delta","data":{"delete":[{"price":"43.695","symbol":"DOTUSDT","id":"436950","side":"Sell"}],"update":[{"price":"43.585","symbol":"DOTUSDT","id":"435850","side":"Sell","size":742.4}],"insert":[{"price":"43.590","symbol":"DOTUSDT","id":"435900","side":"Sell","size":87.899994}]},"cross_seq":"916955343","timestamp_e6":"1618677794882462"}
1618677794.967249: {"topic":"orderBookL2_25.ADAUSDT","type":"delta","data":{"delete":[{"price":"1.3881","symbol":"ADAUSDT","id":"13881","side":"Sell"}],"update":[{"price":"1.3867","symbol":"ADAUSDT","id":"13867","side":"Buy","size":5442},{"price":"1.3868","symbol":"ADAUSDT","id":"13868","side":"Buy","size":11962},{"price":"1.3876","symbol":"ADAUSDT","id":"13876","side":"Sell","size":1},{"price":"1.3877","symbol":"ADAUSDT","id":"13877","side":"Sell","size":3974.0002},{"price":"1.3869","symbol":"ADAUSDT","id":"13869","side":"Buy","size":22161.002},{"price":"1.3882","symbol":"ADAUSDT","id":"13882","side":"Sell","size":6998.0005}],"insert":[{"price":"1.3878","symbol":"ADAUSDT","id":"13878","side":"Sell","size":2413}]},"cross_seq":"916955343","timestamp_e6":"1618677794882346"}
1618677794.971305: {"topic":"orderBookL2_25.ETHUSDT","type":"delta","data":{"delete":[],"update":[{"price":"2364.90","symbol":"ETHUSDT","id":"23649000","side":"Sell","size":91.42},{"price":"2364.95","symbol":"ETHUSDT","id":"23649500","side":"Sell","size":85.21},{"price":"2364.60","symbol":"ETHUSDT","id":"23646000","side":"Sell","size":341.34998}],"insert":[]},"cross_seq":"1800547064","timestamp_e6":"1618677794887456"}
1618677794.984118: {"topic":"orderBookL2_25.LTCUSDT","type":"delta","data":{"delete":[],"update":[{"price":"313.41","symbol":"LTCUSDT","id":"3134100","side":"Buy","size":1.5},{"price":"313.45","symbol":"LTCUSDT","id":"3134500","side":"Sell","size":5.9},{"price":"313.44","symbol":"LTCUSDT","id":"3134400","side":"Buy","size":448.7}],"insert":[]},"cross_seq":"1684523980","timestamp_e6":"1618677794900424"}
1618677794.986662: {"topic":"orderBookL2_25.DOTUSDT","type":"delta","data":{"delete":[],"update":[{"price":"43.570","symbol":"DOTUSDT","id":"435700","side":"Sell","size":1120.6}],"insert":[]},"cross_seq":"916955363","timestamp_e6":"1618677794902322"}
1618677794.9905071: {"topic":"orderBookL2_25.ETHUSDT","type":"delta","data":{"delete":[],"update":[{"price":"2364.95","symbol":"ETHUSDT","id":"23649500","side":"Sell","size":82.909996},{"price":"2364.60","symbol":"ETHUSDT","id":"23646000","side":"Sell","size":366.63}],"insert":[]},"cross_seq":"1800547070","timestamp_e6":"1618677794907371"}
1618677795.001321: {"topic":"orderBookL2_25.XTZUSDT","type":"delta","data":{"delete":[{"price":"7.232","symbol":"XTZUSDT","id":"72320","side":"Sell"}],"update":[{"price":"7.205","symbol":"XTZUSDT","id":"72050","side":"Buy","size":889.4},{"price":"7.211","symbol":"XTZUSDT","id":"72110","side":"Sell","size":427},{"price":"7.209","symbol":"XTZUSDT","id":"72090","side":"Sell","size":1893.1}],"insert":[{"price":"7.208","symbol":"XTZUSDT","id":"72080","side":"Sell","size":1163}]},"cross_seq":"726229052","timestamp_e6":"1618677794916451"}
1618677795.0044339: {"topic":"orderBookL2_25.LTCUSDT","type":"delta","data":{"delete":[],"update":[{"price":"313.44","symbol":"LTCUSDT","id":"3134400","side":"Buy","size":323.7}],"insert":[]},"cross_seq":"1684523984","timestamp_e6":"1618677794919378"}
1618677795.007442: {"topic":"orderBookL2_25.DOTUSDT","type":"delta","data":{"delete":[],"update":[{"price":"43.570","symbol":"DOTUSDT","id":"435700","side":"Sell","size":882.1}],"insert":[]},"cross_seq":"916955368","timestamp_e6":"1618677794922325"}
1618677795.007479: {"topic":"orderBookL2_25.UNIUSDT","type":"delta","data":{"delete":[{"price":"35.391","symbol":"UNIUSDT","id":"353910","side":"Buy"}],"update":[],"insert":[{"price":"35.358","symbol":"UNIUSDT","id":"353580","side":"Buy","size":20.4}]},"cross_seq":"916955368","timestamp_e6":"1618677794922434"}
1618677795.011893: {"topic":"orderBookL2_25.ETHUSDT","type":"delta","data":{"delete":[{"price":"2363.30","symbol":"ETHUSDT","id":"23633000","side":"Buy"},{"price":"2363.85","symbol":"ETHUSDT","id":"23638500","side":"Buy"}],"update":[{"price":"2365.55","symbol":"ETHUSDT","id":"23655500","side":"Sell","size":2.89},{"price":"2362.70","symbol":"ETHUSDT","id":"23627000","side":"Buy","size":71.79},{"price":"2362.75","symbol":"ETHUSDT","id":"23627500","side":"Buy","size":98.450005},{"price":"2362.55","symbol":"ETHUSDT","id":"23625500","side":"Buy","size":12.049999},{"price":"2362.80","symbol":"ETHUSDT","id":"23628000","side":"Buy","size":21.19},{"price":"2362.85","symbol":"ETHUSDT","id":"23628500","side":"Buy","size":92.7},{"price":"2362.95","symbol":"ETHUSDT","id":"23629500","side":"Buy","size":148.7},{"price":"2362.65","symbol":"ETHUSDT","id":"23626500","side":"Buy","size":90.049995},{"price":"2364.60","symbol":"ETHUSDT","id":"23646000","side":"Sell","size":422.91},{"price":"2365.50","symbol":"ETHUSDT","id":"23655000","side":"Sell","size":32.52},{"price":"2362.90","symbol":"ETHUSDT","id":"23629000","side":"Buy","size":116.8}],"insert":[{"price":"2362.30","symbol":"ETHUSDT","id":"23623000","side":"Buy","size":60.87},{"price":"2363.25","symbol":"ETHUSDT","id":"23632500","side":"Buy","size":5}]},"cross_seq":"1800547110","timestamp_e6":"1618677794927761"}
1618677795.01776: {"topic":"trade.LTCUSDT","data":[{"symbol":"LTCUSDT","tick_direction":"PlusTick","price":"313.42","size":0.1,"timestamp":"2021-04-17T16:43:14.000Z","trade_time_ms":"1618677794837","side":"Buy","trade_id":"45a58a28-c0b2-5ef9-b094-2da53e9b65e2"},{"symbol":"LTCUSDT","tick_direction":"PlusTick","price":"313.45","size":0.9,"timestamp":"2021-04-17T16:43:14.000Z","trade_time_ms":"1618677794837","side":"Buy","trade_id":"85462d0c-1c8c-524d-8021-ee4851b350ba"}]}
1618677795.0198689: {"topic":"orderBookL2_25.XTZUSDT","type":"delta","data":{"delete":[{"price":"7.208","symbol":"XTZUSDT","id":"72080","side":"Sell"}],"update":[{"price":"7.209","symbol":"XTZUSDT","id":"72090","side":"Sell","size":2434.0999},{"price":"7.211","symbol":"XTZUSDT","id":"72110","side":"Sell","size":965.2}],"insert":[{"price":"7.232","symbol":"XTZUSDT","id":"72320","side":"Sell","size":49.6}]},"cross_seq":"726229055","timestamp_e6":"1618677794934636"}
1618677795.024092: {"topic":"orderBookL2_25.LTCUSDT","type":"delta","data":{"delete":[{"price":"313.74","symbol":"LTCUSDT","id":"3137400","side":"Sell"},{"price":"313.13","symbol":"LTCUSDT","id":"3131300","side":"Buy"},{"price":"313.12","symbol":"LTCUSDT","id":"3131200","side":"Buy"}],"update":[{"price":"313.54","symbol":"LTCUSDT","id":"3135400","side":"Sell","size":150.79999},{"price":"313.41","symbol":"LTCUSDT","id":"3134100","side":"Buy","size":103.8},{"price":"313.56","symbol":"LTCUSDT","id":"3135600","side":"Sell","size":73.299995},{"price":"313.55","symbol":"LTCUSDT","id":"3135500","side":"Sell","size":132.2},{"price":"313.51","symbol":"LTCUSDT","id":"3135100","side":"Sell","size":132},{"price":"313.53","symbol":"LTCUSDT","id":"3135300","side":"Sell","size":82.1}],"insert":[{"price":"313.40","symbol":"LTCUSDT","id":"3134000","side":"Buy","size":102.00001},{"price":"313.52","symbol":"LTCUSDT","id":"3135200","side":"Sell","size":82.1},{"price":"313.39","symbol":"LTCUSDT","id":"3133900","side":"Buy","size":74.700005}]},"cross_seq":"1684523996","timestamp_e6":"1618677794937886"}
1618677795.027522: {"topic":"orderBookL2_25.UNIUSDT","type":"delta","data":{"delete":[{"price":"35.381","symbol":"UNIUSDT","id":"353810","side":"Buy"},{"price":"35.378","symbol":"UNIUSDT","id":"353780","side":"Buy"},{"price":"35.380","symbol":"UNIUSDT","id":"353800","side":"Buy"},{"price":"35.359","symbol":"UNIUSDT","id":"353590","side":"Buy"},{"price":"35.358","symbol":"UNIUSDT","id":"353580","side":"Buy"}],"update":[{"price":"35.372","symbol":"UNIUSDT","id":"353720","side":"Buy","size":8.3},{"price":"35.414","symbol":"UNIUSDT","id":"354140","side":"Sell","size":423.1},{"price":"35.374","symbol":"UNIUSDT","id":"353740","side":"Buy","size":25.4},{"price":"35.375","symbol":"UNIUSDT","id":"353750","side":"Buy","size":46.4},{"price":"35.373","symbol":"UNIUSDT","id":"353730","side":"Buy","size":24.7},{"price":"35.376","symbol":"UNIUSDT","id":"353760","side":"Buy","size":60},{"price":"35.377","symbol":"UNIUSDT","id":"353770","side":"Buy","size":7.6}],"insert":[{"price":"35.383","symbol":"UNIUSDT","id":"353830","side":"Buy","size":28.8},{"price":"35.385","symbol":"UNIUSDT","id":"353850","side":"Buy","size":66.6},{"price":"35.382","symbol":"UNIUSDT","id":"353820","side":"Buy","size":37.9},{"price":"35.379","symbol":"UNIUSDT","id":"353790","side":"Buy","size":7.3},{"price":"35.384","symbol":"UNIUSDT","id":"353840","side":"Buy","size":44.5}]},"cross_seq":"916955389","timestamp_e6":"1618677794942427"}
1618677795.031135: {"topic":"orderBookL2_25.ETHUSDT","type":"delta","data":{"delete":[{"price":"2363.40","symbol":"ETHUSDT","id":"23634000","side":"Buy"}],"update":[{"price":"2362.45","symbol":"ETHUSDT","id":"23624500","side":"Buy","size":15.3}],"insert":[{"price":"2362.25","symbol":"ETHUSDT","id":"23622500","side":"Buy","size":48.88}]},"cross_seq":"1800547112","timestamp_e6":"1618677794947616"}
1618677795.038993: {"topic":"orderBookL2_25.XTZUSDT","type":"delta","data":{"delete":[{"price":"7.232","symbol":"XTZUSDT","id":"72320","side":"Sell"}],"update":[{"price":"7.207","symbol":"XTZUSDT","id":"72070","side":"Sell","size":1304.6}],"insert":[{"price":"7.206","symbol":"XTZUSDT","id":"72060","side":"Sell","size":2000}]},"cross_seq":"726229057","timestamp_e6":"1618677794955220"}
1618677795.0474792: {"topic":"orderBookL2_25.ADAUSDT","type":"delta","data":{"delete":[{"price":"1.3871","symbol":"ADAUSDT","id":"13871","side":"Buy"},{"price":"1.3901","symbol":"ADAUSDT","id":"13901","side":"Sell"}],"update":[{"price":"1.3868","symbol":"ADAUSDT","id":"13868","side":"Buy","size":13203.001},{"price":"1.3882","symbol":"ADAUSDT","id":"13882","side":"Sell","size":7603}],"insert":[{"price":"1.3848","symbol":"ADAUSDT","id":"13848","side":"Buy","size":3559},{"price":"1.3881","symbol":"ADAUSDT","id":"13881","side":"Sell","size":1023}]},"cross_seq":"916955424","timestamp_e6":"1618677794962331"}
1618677795.047581: {"topic":"orderBookL2_25.UNIUSDT","type":"delta","data":{"delete":[{"price":"35.361","symbol":"UNIUSDT","id":"353610","side":"Buy"},{"price":"35.385","symbol":"UNIUSDT","id":"353850","side":"Buy"},{"price":"35.360","symbol":"UNIUSDT","id":"353600","side":"Buy"},{"price":"35.362","symbol":"UNIUSDT","id":"353620","side":"Buy"},{"price":"35.382","symbol":"UNIUSDT","id":"353820","side":"Buy"}],"update":[{"price":"35.372","symbol":"UNIUSDT","id":"353720","side":"Buy","size":14.4},{"price":"35.376","symbol":"UNIUSDT","id":"353760","side":"Buy","size":67.6},{"price":"35.373","symbol":"UNIUSDT","id":"353730","side":"Buy","size":31},{"price":"35.375","symbol":"UNIUSDT","id":"353750","side":"Buy","size":55.2},{"price":"35.374","symbol":"UNIUSDT","id":"353740","side":"Buy","size":30.6}],"insert":[{"price":"35.380","symbol":"UNIUSDT","id":"353800","side":"Buy","size":8.5},{"price":"35.387","symbol":"UNIUSDT","id":"353870","side":"Buy","size":66.6},{"price":"35.386","symbol":"UNIUSDT","id":"353860","side":"Buy","size":44.5},{"price":"35.381","symbol":"UNIUSDT","id":"353810","side":"Buy","size":56.999996},{"price":"35.378","symbol":"UNIUSDT","id":"353780","side":"Buy","size":8.9}]},"cross_seq":"916955424","timestamp_e6":"1618677794962486"}
1618677795.050739: {"topic":"orderBookL2_25.ETHUSDT","type":"delta","data":{"delete":[{"price":"2363.20","symbol":"ETHUSDT","id":"23632000","side":"Buy"}],"update":[{"price":"2363.05","symbol":"ETHUSDT","id":"23630500","side":"Buy","size":80.28},{"price":"2362.50","symbol":"ETHUSDT","id":"23625000","side":"Buy","size":124.37},{"price":"2362.90","symbol":"ETHUSDT","id":"23629000","side":"Buy","size":56.26},{"price":"2363.15","symbol":"ETHUSDT","id":"23631500","side":"Buy","size":94.53},{"price":"2363.10","symbol":"ETHUSDT","id":"23631000","side":"Buy","size":60.54},{"price":"2362.95","symbol":"ETHUSDT","id":"23629500","side":"Buy","size":64.65}],"insert":[{"price":"2362.20","symbol":"ETHUSDT","id":"23622000","side":"Buy","size":24.28}]},"cross_seq":"1800547144","timestamp_e6":"1618677794967037"}
1618677795.058402: {"topic":"orderBookL2_25.XTZUSDT","type":"delta","data":{"delete":[],"update":[{"price":"7.207","symbol":"XTZUSDT","id":"72070","side":"Sell","size":1204.6}],"insert":[]},"cross_seq":"726229058","timestamp_e6":"1618677794974483"}
1618677795.0640981: {"topic":"orderBookL2_25.LTCUSDT","type":"delta","data":{"delete":[],"update":[{"price":"313.16","symbol":"LTCUSDT","id":"3131600","side":"Buy","size":156.40001},{"price":"313.15","symbol":"LTCUSDT","id":"3131500","side":"Buy","size":191.29999}],"insert":[]},"cross_seq":"1684524009","timestamp_e6":"1618677794978018"}
1618677795.066335: {"topic":"orderBookL2_25.UNIUSDT","type":"delta","data":{"delete":[],"update":[{"price":"35.370","symbol":"UNIUSDT","id":"353700","side":"Buy","size":23.6},{"price":"35.374","symbol":"UNIUSDT","id":"353740","side":"Buy","size":5.2},{"price":"35.376","symbol":"UNIUSDT","id":"353760","side":"Buy","size":7.6},{"price":"35.401","symbol":"UNIUSDT","id":"354010","side":"Buy","size":220.7},{"price":"35.367","symbol":"UNIUSDT","id":"353670","side":"Buy","size":443.19998},{"price":"35.377","symbol":"UNIUSDT","id":"353770","side":"Buy","size":69.5},{"price":"35.375","symbol":"UNIUSDT","id":"353750","side":"Buy","size":21.500002},{"price":"35.365","symbol":"UNIUSDT","id":"353650","side":"Buy","size":4.2},{"price":"35.368","symbol":"UNIUSDT","id":"353680","side":"Buy","size":52},{"price":"35.364","symbol":"UNIUSDT","id":"353640","side":"Buy","size":32.5},{"price":"35.405","symbol":"UNIUSDT","id":"354050","side":"Sell","size":133},{"price":"35.373","symbol":"UNIUSDT","id":"353730","side":"Buy","size":36},{"price":"35.372","symbol":"UNIUSDT","id":"353720","side":"Buy","size":19.3},{"price":"35.371","symbol":"UNIUSDT","id":"353710","side":"Buy","size":12.4},{"price":"35.366","symbol":"UNIUSDT","id":"353660","side":"Buy","size":252.8},{"price":"35.369","symbol":"UNIUSDT","id":"353690","side":"Buy","size":397.9}],"insert":[]},"cross_seq":"916955476","timestamp_e6":"1618677794982398"}
1618677795.066439: {"topic":"orderBookL2_25.DOTUSDT","type":"delta","data":{"delete":[],"update":[{"price":"43.585","symbol":"DOTUSDT","id":"435850","side":"Sell","size":882.5},{"price":"43.570","symbol":"DOTUSDT","id":"435700","side":"Sell","size":782.1},{"price":"43.590","symbol":"DOTUSDT","id":"435900","side":"Sell","size":199.2},{"price":"43.575","symbol":"DOTUSDT","id":"435750","side":"Sell","size":455.1},{"price":"43.530","symbol":"DOTUSDT","id":"435300","side":"Buy","size":505.6},{"price":"43.545","symbol":"DOTUSDT","id":"435450","side":"Buy","size":129.6}],"insert":[]},"cross_seq":"916955476","timestamp_e6":"1618677794982270"}
1618677795.070773: {"topic":"orderBookL2_25.BCHUSDT","type":"delta","data":{"delete":[],"update":[{"price":"1055.85","symbol":"BCHUSDT","id":"10558500","side":"Sell","size":15.2},{"price":"1054.50","symbol":"BCHUSDT","id":"10545000","side":"Buy","size":14.31},{"price":"1055.80","symbol":"BCHUSDT","id":"10558000","side":"Sell","size":5.23},{"price":"1055.70","symbol":"BCHUSDT","id":"10557000","side":"Sell","size":7.82},{"price":"1054.55","symbol":"BCHUSDT","id":"10545500","side":"Buy","size":12.34}],"insert":[]},"cross_seq":"864133269","timestamp_e6":"1618677794988723"}
1618677795.08052: {"topic":"orderBookL2_25.XTZUSDT","type":"delta","data":{"delete":[{"price":"7.206","symbol":"XTZUSDT","id":"72060","side":"Sell"}],"update":[{"price":"7.205","symbol":"XTZUSDT","id":"72050","side":"Buy","size":3639.4}],"insert":[{"price":"7.232","symbol":"XTZUSDT","id":"72320","side":"Sell","size":49.6}]},"cross_seq":"726229061","timestamp_e6":"1618677794995759"}
1618677795.0868502: {"topic":"orderBookL2_25.UNIUSDT","type":"delta","data":{"delete":[],"update":[{"price":"35.401","symbol":"UNIUSDT","id":"354010","side":"Buy","size":284.69998}],"insert":[]},"cross_seq":"916955477","timestamp_e6":"1618677795002323"}
1618677795.098567: {"topic":"orderBookL2_25.XTZUSDT","type":"delta","data":{"delete":[{"price":"7.232","symbol":"XTZUSDT","id":"72320","side":"Sell"}],"update":[{"price":"7.209","symbol":"XTZUSDT","id":"72090","side":"Sell","size":1812.1001},{"price":"7.211","symbol":"XTZUSDT","id":"72110","side":"Sell","size":538.2}],"insert":[{"price":"7.208","symbol":"XTZUSDT","id":"72080","side":"Sell","size":1163}]},"cross_seq":"726229066","timestamp_e6":"1618677795014894"}
1618677795.107727: {"topic":"orderBookL2_25.ADAUSDT","type":"delta","data":{"delete":[{"price":"1.3872","symbol":"ADAUSDT","id":"13872","side":"Buy"}],"update":[{"price":"1.3869","symbol":"ADAUSDT","id":"13869","side":"Buy","size":16869},{"price":"1.3876","symbol":"ADAUSDT","id":"13876","side":"Sell","size":27},{"price":"1.3867","symbol":"ADAUSDT","id":"13867","side":"Buy","size":6536.9995}],"insert":[{"price":"1.3847","symbol":"ADAUSDT","id":"13847","side":"Buy","size":4462}]},"cross_seq":"916955482","timestamp_e6":"1618677795022327"}
1618677795.110794: {"topic":"orderBookL2_25.ETHUSDT","type":"delta","data":{"delete":[{"price":"2364.45","symbol":"ETHUSDT","id":"23644500","side":"Buy"}],"update":[],"insert":[{"price":"2362.15","symbol":"ETHUSDT","id":"23621500","side":"Buy","size":91.36}]},"cross_seq":"1800547146","timestamp_e6":"1618677795027396"}
1618677795.122247: {"topic":"orderBookL2_25.XTZUSDT","type":"delta","data":{"delete":[],"update":[{"price":"7.205","symbol":"XTZUSDT","id":"72050","side":"Buy","size":889.4}],"insert":[]},"cross_seq":"726229067","timestamp_e6":"1618677795036282"}
1618677795.127384: {"topic":"orderBookL2_25.UNIUSDT","type":"delta","data":{"delete":[{"price":"35.387","symbol":"UNIUSDT","id":"353870","side":"Buy"},{"price":"35.384","symbol":"UNIUSDT","id":"353840","side":"Buy"},{"price":"35.363","symbol":"UNIUSDT","id":"353630","side":"Buy"}],"update":[],"insert":[{"price":"35.388","symbol":"UNIUSDT","id":"353880","side":"Buy","size":44.5},{"price":"35.389","symbol":"UNIUSDT","id":"353890","side":"Buy","size":66.6},{"price":"35.385","symbol":"UNIUSDT","id":"353850","side":"Buy","size":31.8}]},"cross_seq":"916955489","timestamp_e6":"1618677795042347"}
1618677795.1380448: {"topic":"orderBookL2_25.XTZUSDT","type":"delta","data":{"delete":[],"update":[{"price":"7.202","symbol":"XTZUSDT","id":"72020","side":"Buy","size":1340.1},{"price":"7.203","symbol":"XTZUSDT","id":"72030","side":"Buy","size":1371.2},{"price":"7.200","symbol":"XTZUSDT","id":"72000","side":"Buy","size":978.9},{"price":"7.212","symbol":"XTZUSDT","id":"72120","side":"Sell","size":2174.8},{"price":"7.214","symbol":"XTZUSDT","id":"72140","side":"Sell","size":1553.6},{"price":"7.204","symbol":"XTZUSDT","id":"72040","side":"Buy","size":1942.4},{"price":"7.216","symbol":"XTZUSDT","id":"72160","side":"Sell","size":1222.2001},{"price":"7.201","symbol":"XTZUSDT","id":"72010","side":"Buy","size":1143.1},{"price":"7.215","symbol":"XTZUSDT","id":"72150","side":"Sell","size":1502.7},{"price":"7.217","symbol":"XTZUSDT","id":"72170","side":"Sell","size":1202.5},{"price":"7.213","symbol":"XTZUSDT","id":"72130","side":"Sell","size":1905.1001}],"insert":[]},"cross_seq":"726229078","timestamp_e6":"1618677795054566"}
1618677795.147787: {"topic":"orderBookL2_25.DOTUSDT","type":"delta","data":{"delete":[],"update":[{"price":"43.590","symbol":"DOTUSDT","id":"435900","side":"Sell","size":303.2},{"price":"43.595","symbol":"DOTUSDT","id":"435950","side":"Sell","size":251.8}],"insert":[]},"cross_seq":"916955513","timestamp_e6":"1618677795062447"}
1618677795.147829: {"topic":"orderBookL2_25.ADAUSDT","type":"delta","data":{"delete":[],"update":[{"price":"1.3869","symbol":"ADAUSDT","id":"13869","side":"Buy","size":22059},{"price":"1.3866","symbol":"ADAUSDT","id":"13866","side":"Buy","size":4121}],"insert":[]},"cross_seq":"916955513","timestamp_e6":"1618677795062332"}
1618677795.152236: {"topic":"orderBookL2_25.BCHUSDT","type":"delta","data":{"delete":[{"price":"1055.50","symbol":"BCHUSDT","id":"10555000","side":"Sell"},{"price":"1055.45","symbol":"BCHUSDT","id":"10554500","side":"Sell"}],"update":[{"price":"1055.55","symbol":"BCHUSDT","id":"10555500","side":"Sell","size":1.5}],"insert":[{"price":"1055.35","symbol":"BCHUSDT","id":"10553500","side":"Sell","size":9.22},{"price":"1056.55","symbol":"BCHUSDT","id":"10565500","side":"Sell","size":10.5}]},"cross_seq":"864133279","timestamp_e6":"1618677795068775"}
1618677795.16046: {"topic":"orderBookL2_25.XTZUSDT","type":"delta","data":{"delete":[],"update":[{"price":"7.207","symbol":"XTZUSDT","id":"72070","side":"Sell","size":1304.6}],"insert":[]},"cross_seq":"726229079","timestamp_e6":"1618677795075407"}
1618677795.167938: {"topic":"orderBookL2_25.DOTUSDT","type":"delta","data":{"delete":[],"update":[{"price":"43.570","symbol":"DOTUSDT","id":"435700","side":"Sell","size":1120.6}],"insert":[]},"cross_seq":"916955516","timestamp_e6":"1618677795082479"}
1618677795.167976: {"topic":"orderBookL2_25.UNIUSDT","type":"delta","data":{"delete":[],"update":[{"price":"35.401","symbol":"UNIUSDT","id":"354010","side":"Buy","size":220.7}],"insert":[]},"cross_seq":"916955516","timestamp_e6":"1618677795082605"}
1618677795.167999: {"topic":"orderBookL2_25.ADAUSDT","type":"delta","data":{"delete":[],"update":[{"price":"1.3876","symbol":"ADAUSDT","id":"13876","side":"Sell","size":1}],"insert":[]},"cross_seq":"916955516","timestamp_e6":"1618677795082338"}
1618677795.179949: {"topic":"orderBookL2_25.XTZUSDT","type":"delta","data":{"delete":[{"price":"7.208","symbol":"XTZUSDT","id":"72080","side":"Sell"}],"update":[{"price":"7.209","symbol":"XTZUSDT","id":"72090","side":"Sell","size":2434.0999},{"price":"7.211","symbol":"XTZUSDT","id":"72110","side":"Sell","size":965.2}],"insert":[{"price":"7.232","symbol":"XTZUSDT","id":"72320","side":"Sell","size":49.6}]},"cross_seq":"726229082","timestamp_e6":"1618677795094552"}
1618677795.187725: {"topic":"orderBookL2_25.UNIUSDT","type":"delta","data":{"delete":[{"price":"35.365","symbol":"UNIUSDT","id":"353650","side":"Buy"},{"price":"35.364","symbol":"UNIUSDT","id":"353640","side":"Buy"}],"update":[],"insert":[{"price":"35.387","symbol":"UNIUSDT","id":"353870","side":"Buy","size":66.6},{"price":"35.384","symbol":"UNIUSDT","id":"353840","side":"Buy","size":37.9}]},"cross_seq":"916955525","timestamp_e6":"1618677795102511"}
1618677795.187786: {"topic":"orderBookL2_25.ADAUSDT","type":"delta","data":{"delete":[{"price":"1.3880","symbol":"ADAUSDT","id":"13880","side":"Sell"},{"price":"1.3881","symbol":"ADAUSDT","id":"13881","side":"Sell"}],"update":[{"price":"1.3885","symbol":"ADAUSDT","id":"13885","side":"Sell","size":3168},{"price":"1.3877","symbol":"ADAUSDT","id":"13877","side":"Sell","size":1771},{"price":"1.3876","symbol":"ADAUSDT","id":"13876","side":"Sell","size":3975},{"price":"1.3886","symbol":"ADAUSDT","id":"13886","side":"Sell","size":1224}],"insert":[{"price":"1.3901","symbol":"ADAUSDT","id":"13901","side":"Sell","size":6684.9995},{"price":"1.3902","symbol":"ADAUSDT","id":"13902","side":"Sell","size":5183}]},"cross_seq":"916955525","timestamp_e6":"1618677795102352"}
1618677795.19354: {"topic":"orderBookL2_25.BCHUSDT","type":"delta","data":{"delete":[{"price":"1056.55","symbol":"BCHUSDT","id":"10565500","side":"Sell"},{"price":"1055.40","symbol":"BCHUSDT","id":"10554000","side":"Sell"},{"price":"1056.50","symbol":"BCHUSDT","id":"10565000","side":"Sell"}],"update":[],"insert":[{"price":"1055.30","symbol":"BCHUSDT","id":"10553000","side":"Sell","size":9.22},{"price":"1055.45","symbol":"BCHUSDT","id":"10554500","side":"Sell","size":3.4},{"price":"1055.50","symbol":"BCHUSDT","id":"10555000","side":"Sell","size":1.92}]},"cross_seq":"864133284","timestamp_e6":"1618677795109439"}
1618677795.199244: {"topic":"orderBookL2_25.XTZUSDT","type":"delta","data":{"delete":[],"update":[{"price":"7.207","symbol":"XTZUSDT","id":"72070","side":"Sell","size":1204.6}],"insert":[]},"cross_seq":"726229085","timestamp_e6":"1618677795115368"}
1618677795.2078989: {"topic":"orderBookL2_25.UNIUSDT","type":"delta","data":{"delete":[],"update":[{"price":"35.401","symbol":"UNIUSDT","id":"354010","side":"Buy","size":284.69998}],"insert":[]},"cross_seq":"916955543","timestamp_e6":"1618677795122361"}
1618677795.212011: {"topic":"orderBookL2_25.ETHUSDT","type":"delta","data":{"delete":[],"update":[{"price":"2364.60","symbol":"ETHUSDT","id":"23646000","side":"Sell","size":423.86002}],"insert":[]},"cross_seq":"1800547148","timestamp_e6":"1618677795127403"}
1618677795.226442: {"topic":"orderBookL2_25.UNIUSDT","type":"delta","data":{"delete":[],"update":[{"price":"35.425","symbol":"UNIUSDT","id":"354250","side":"Sell","size":5.9}],"insert":[]},"cross_seq":"916955544","timestamp_e6":"1618677795142311"}
1618677795.231078: {"topic":"orderBookL2_25.ETHUSDT","type":"delta","data":{"delete":[],"update":[{"price":"2362.40","symbol":"ETHUSDT","id":"23624000","side":"Buy","size":30.09}],"insert":[]},"cross_seq":"1800547149","timestamp_e6":"1618677795147417"}
1618677795.2720482: {"topic":"orderBookL2_25.ETHUSDT","type":"delta","data":{"delete":[{"price":"2362.80","symbol":"ETHUSDT","id":"23628000","side":"Buy"},{"price":"2362.90","symbol":"ETHUSDT","id":"23629000","side":"Buy"},{"price":"2362.95","symbol":"ETHUSDT","id":"23629500","side":"Buy"}],"update":[{"price":"2362.60","symbol":"ETHUSDT","id":"23626000","side":"Buy","size":9.84},{"price":"2363.00","symbol":"ETHUSDT","id":"23630000","side":"Buy","size":43.74},{"price":"2365.00","symbol":"ETHUSDT","id":"23650000","side":"Sell","size":94.14},{"price":"2362.55","symbol":"ETHUSDT","id":"23625500","side":"Buy","size":42.84},{"price":"2364.90","symbol":"ETHUSDT","id":"23649000","side":"Sell","size":136.31},{"price":"2362.50","symbol":"ETHUSDT","id":"23625000","side":"Buy","size":106.130005},{"price":"2362.85","symbol":"ETHUSDT","id":"23628500","side":"Buy","size":61.23},{"price":"2364.95","symbol":"ETHUSDT","id":"23649500","side":"Sell","size":108.95},{"price":"2362.75","symbol":"ETHUSDT","id":"23627500","side":"Buy","size":137.83},{"price":"2363.05","symbol":"ETHUSDT","id":"23630500","side":"Buy","size":61.23}],"insert":[{"price":"2362.05","symbol":"ETHUSDT","id":"23620500","side":"Buy","size":12.129999},{"price":"2362.10","symbol":"ETHUSDT","id":"23621000","side":"Buy","size":53.730003},{"price":"2362.00","symbol":"ETHUSDT","id":"23620000","side":"Buy","size":109.1}]},"cross_seq":"1800547168","timestamp_e6":"1618677795187287"}
1618677795.281642: {"topic":"orderBookL2_25.LTCUSDT","type":"delta","data":{"delete":[],"update":[{"price":"313.56","symbol":"LTCUSDT","id":"3135600","side":"Sell","size":101},{"price":"313.54","symbol":"LTCUSDT","id":"3135400","side":"Sell","size":160.8}],"insert":[]},"cross_seq":"1684524011","timestamp_e6":"1618677795197930"}
1618677795.306964: {"topic":"orderBookL2_25.UNIUSDT","type":"delta","data":{"delete":[],"update":[{"price":"35.375","symbol":"UNIUSDT","id":"353750","side":"Buy","size":39.3},{"price":"35.374","symbol":"UNIUSDT","id":"353740","side":"Buy","size":19.9},{"price":"35.376","symbol":"UNIUSDT","id":"353760","side":"Buy","size":54}],"insert":[]},"cross_seq":"916955547","timestamp_e6":"1618677795222344"}
1618677795.310305: {"topic":"orderBookL2_25.ETHUSDT","type":"delta","data":{"delete":[{"price":"2362.00","symbol":"ETHUSDT","id":"23620000","side":"Buy"},{"price":"2362.05","symbol":"ETHUSDT","id":"23620500","side":"Buy"}],"update":[{"price":"2362.40","symbol":"ETHUSDT","id":"23624000","side":"Buy","size":27.2}],"insert":[{"price":"2362.95","symbol":"ETHUSDT","id":"23629500","side":"Buy","size":34.89},{"price":"2362.90","symbol":"ETHUSDT","id":"23629000","side":"Buy","size":14.16}]},"cross_seq":"1800547171","timestamp_e6":"1618677795227182"}
1618677795.3192341: {"topic":"orderBookL2_25.XTZUSDT","type":"delta","data":{"delete":[],"update":[{"price":"7.218","symbol":"XTZUSDT","id":"72180","side":"Sell","size":5206.5}],"insert":[]},"cross_seq":"726229086","timestamp_e6":"1618677795234789"}
1618677795.327589: {"topic":"orderBookL2_25.ADAUSDT","type":"delta","data":{"delete":[{"price":"1.3901","symbol":"ADAUSDT","id":"13901","side":"Sell"},{"price":"1.3847","symbol":"ADAUSDT","id":"13847","side":"Buy"},{"price":"1.3902","symbol":"ADAUSDT","id":"13902","side":"Sell"}],"update":[{"price":"1.3877","symbol":"ADAUSDT","id":"13877","side":"Sell","size":2413},{"price":"1.3866","symbol":"ADAUSDT","id":"13866","side":"Buy","size":1629.9999},{"price":"1.3867","symbol":"ADAUSDT","id":"13867","side":"Buy","size":4340}],"insert":[{"price":"1.3881","symbol":"ADAUSDT","id":"13881","side":"Sell","size":605},{"price":"1.3871","symbol":"ADAUSDT","id":"13871","side":"Buy","size":5024},{"price":"1.3880","symbol":"ADAUSDT","id":"13880","side":"Sell","size":1023}]},"cross_seq":"916955554","timestamp_e6":"1618677795242395"}
1618677795.331949: {"topic":"orderBookL2_25.BCHUSDT","type":"delta","data":{"delete":[],"update":[{"price":"1055.80","symbol":"BCHUSDT","id":"10558000","side":"Sell","size":6.01},{"price":"1055.85","symbol":"BCHUSDT","id":"10558500","side":"Sell","size":15.7}],"insert":[]},"cross_seq":"864133286","timestamp_e6":"1618677795248808"}
1618677795.3435378: {"topic":"orderBookL2_25.LTCUSDT","type":"delta","data":{"delete":[],"update":[{"price":"313.16","symbol":"LTCUSDT","id":"3131600","side":"Buy","size":3.5},{"price":"313.14","symbol":"LTCUSDT","id":"3131400","side":"Buy","size":28.2},{"price":"313.15","symbol":"LTCUSDT","id":"3131500","side":"Buy","size":71.9}],"insert":[]},"cross_seq":"1684524017","timestamp_e6":"1618677795258533"}
1618677795.347727: {"topic":"orderBookL2_25.DOTUSDT","type":"delta","data":{"delete":[{"price":"43.520","symbol":"DOTUSDT","id":"435200","side":"Buy"},{"price":"43.550","symbol":"DOTUSDT","id":"435500","side":"Buy"}],"update":[{"price":"43.575","symbol":"DOTUSDT","id":"435750","side":"Sell","size":942.39996},{"price":"43.540","symbol":"DOTUSDT","id":"435400","side":"Buy","size":550.7},{"price":"43.570","symbol":"DOTUSDT","id":"435700","side":"Sell","size":638.5},{"price":"43.595","symbol":"DOTUSDT","id":"435950","side":"Sell","size":393.9},{"price":"43.545","symbol":"DOTUSDT","id":"435450","side":"Buy","size":588.3},{"price":"43.600","symbol":"DOTUSDT","id":"436000","side":"Sell","size":155.4}],"insert":[{"price":"43.425","symbol":"DOTUSDT","id":"434250","side":"Buy","size":241.9},{"price":"43.430","symbol":"DOTUSDT","id":"434300","side":"Buy","size":168.7}]},"cross_seq":"916955563","timestamp_e6":"1618677795262346"}
1618677795.352164: {"topic":"orderBookL2_25.BCHUSDT","type":"delta","data":{"delete":[{"price":"1055.35","symbol":"BCHUSDT","id":"10553500","side":"Sell"},{"price":"1055.45","symbol":"BCHUSDT","id":"10554500","side":"Sell"}],"update":[],"insert":[{"price":"1055.25","symbol":"BCHUSDT","id":"10552500","side":"Sell","size":9.22},{"price":"1055.40","symbol":"BCHUSDT","id":"10554000","side":"Sell","size":3.4}]},"cross_seq":"864133291","timestamp_e6":"1618677795268919"}
1618677795.361395: {"topic":"orderBookL2_25.XTZUSDT","type":"delta","data":{"delete":[{"price":"7.232","symbol":"XTZUSDT","id":"72320","side":"Sell"}],"update":[{"price":"7.205","symbol":"XTZUSDT","id":"72050","side":"Buy","size":989.4}],"insert":[{"price":"7.206","symbol":"XTZUSDT","id":"72060","side":"Sell","size":2000.2}]},"cross_seq":"726229089","timestamp_e6":"1618677795276339"}
