1618677797.362496: {"topic":"orderBookL2_25.BTCUSD","type":"delta","data":{"delete":[],"update":[{"price":"60624.00","symbol":"BTCUSD","id":606240000,"side":"Sell","size":137261},{"price":"60625.50","symbol":"BTCUSD","id":606255000,"side":"Sell","size":48855},{"price":"60622.50","symbol":"BTCUSD","id":606225000,"side":"Buy","size":10622187}],"insert":[],"transactTimeE6":0},"cross_seq":5938956968,"timestamp_e6":1618677797278090}
1618677797.420802: {"topic":"orderBookL2_25.EOSUSD","type":"delta","data":{"delete":[],"update":[{"price":"7.982","symbol":"EOSUSD","id":79820,"side":"Sell","size":111151},{"price":"7.985","symbol":"EOSUSD","id":79850,"side":"Sell","size":63923}],"insert":[],"transactTimeE6":0},"cross_seq":1225777933,"timestamp_e6":1618677797338199}
1618677797.541031: {"topic":"orderBookL2_25.EOSUSD","type":"delta","data":{"delete":[],"update":[{"price":"7.961","symbol":"EOSUSD","id":79610,"side":"Buy","size":49119}],"insert":[],"transactTimeE6":0},"cross_seq":1225777934,"timestamp_e6":1618677797458113}
1618677797.601971: {"topic":"orderBookL2_25.EOSUSD","type":"delta","data":{"delete":[],"update":[{"price":"7.961","symbol":"EOSUSD","id":79610,"side":"Buy","size":55615},{"price":"7.958","symbol":"EOSUSD","id":79580,"side":"Buy","size":42306},{"price":"7.959","symbol":"EOSUSD","id":79590,"side":"Buy","size":31141},{"price":"7.978","symbol":"EOSUSD","id":79780,"side":"Sell","size":80641}],"insert":[],"transactTimeE6":0},"cross_seq":1225777938,"timestamp_e6":1618677797518122}
1618677797.682869: {"topic":"orderBookL2_25.EOSUSD","type":"delta","data":{"delete":[{"price":"7.969","symbol":"EOSUSD","id":79690,"side":"Sell"}],"update":[],"insert":[{"price":"7.997","symbol":"EOSUSD","id":79970,"side":"Sell","size":152052}],"transactTimeE6":0},"cross_seq":1225777939,"timestamp_e6":1618677797598824}
1618677797.7030349: {"topic":"orderBookL2_25.EOSUSD","type":"delta","data":{"delete":[{"price":"7.997","symbol":"EOSUSD","id":79970,"side":"Sell"}],"update":[{"price":"7.971","symbol":"EOSUSD","id":79710,"side":"Sell","size":14087},{"price":"7.968","symbol":"EOSUSD","id":79680,"side":"Buy","size":114871}],"insert":[{"price":"7.969","symbol":"EOSUSD","id":79690,"side":"Sell","size":7635}],"transactTimeE6":0},"cross_seq":1225777947,"timestamp_e6":1618677797619317}
1618677797.721824: {"topic":"orderBookL2_25.EOSUSD","type":"delta","data":{"delete":[{"price":"7.969","symbol":"EOSUSD","id":79690,"side":"Sell"}],"update":[{"price":"7.971","symbol":"EOSUSD","id":79710,"side":"Sell","size":8385},{"price":"7.963","symbol":"EOSUSD","id":79630,"side":"Buy","size":30661},{"price":"7.965","symbol":"EOSUSD","id":79650,"side":"Buy","size":79434},{"price":"7.961","symbol":"EOSUSD","id":79610,"side":"Buy","size":30569},{"price":"7.968","symbol":"EOSUSD","id":79680,"side":"Buy","size":127751},{"price":"7.964","symbol":"EOSUSD","id":79640,"side":"Buy","size":152742}],"insert":[{"price":"7.997","symbol":"EOSUSD","id":79970,"side":"Sell","size":152052}],"transactTimeE6":0},"cross_seq":1225777961,"timestamp_e6":1618677797639347}
1618677797.744151: {"topic":"orderBookL2_25.EOSUSD","type":"delta","data":{"delete":[{"price":"7.996","symbol":"EOSUSD","id":79960,"side":"Sell"},{"price":"7.943","symbol":"EOSUSD","id":79430,"side":"Buy"},{"price":"7.997","symbol":"EOSUSD","id":79970,"side":"Sell"},{"price":"7.942","symbol":"EOSUSD","id":79420,"side":"Buy"}],"update":[{"price":"7.968","symbol":"EOSUSD","id":79680,"side":"Buy","size":99871},{"price":"7.973","symbol":"EOSUSD","id":79730,"side":"Sell","size":4346},{"price":"7.975","symbol":"EOSUSD","id":79750,"side":"Sell","size":66132},{"price":"7.971","symbol":"EOSUSD","id":79710,"side":"Sell","size":21722}],"insert":[{"price":"7.974","symbol":"EOSUSD","id":79740,"side":"Sell","size":5205},{"price":"7.972","symbol":"EOSUSD","id":79720,"side":"Sell","size":3805},{"price":"7.969","symbol":"EOSUSD","id":79690,"side":"Buy","size":58598},{"price":"7.970","symbol":"EOSUSD","id":79700,"side":"Buy","size":27880}],"transactTimeE6":0},"cross_seq":1225777975,"timestamp_e6":1618677797660140}
1618677797.758822: {"topic":"trade.BTCUSD","data":[{"trade_time_ms":1618677797663,"timestamp":"2021-04-17T16:43:17.000Z","symbol":"BTCUSD","side":"Buy","size":2222,"price":60623,"tick_direction":"ZeroPlusTick","trade_id":"b30f0ae9-3746-55d6-9c65-2e4420fc25a1","cross_seq":5938956980}]}
1618677797.764384: {"topic":"orderBookL2_25.BTCUSD","type":"delta","data":{"delete":[],"update":[{"price":"60623.00","symbol":"BTCUSD","id":606230000,"side":"Sell","size":238076}],"insert":[],"transactTimeE6":0},"cross_seq":5938956980,"timestamp_e6":1618677797677982}
1618677797.789461: {"topic":"orderBookL2_25.EOSUSD","type":"delta","data":{"delete":[],"update":[{"price":"7.971","symbol":"EOSUSD","id":79710,"side":"Sell","size":22329}],"insert":[],"transactTimeE6":0},"cross_seq":1225777976,"timestamp_e6":1618677797678755}
1618677797.7931561: {"topic":"orderBookL2_25.EOSUSD","type":"delta","data":{"delete":[],"update":[{"price":"7.970","symbol":"EOSUSD","id":79700,"side":"Buy","size":47880},{"price":"7.968","symbol":"EOSUSD","id":79680,"side":"Buy","size":66538}],"insert":[],"transactTimeE6":0},"cross_seq":1225777979,"timestamp_e6":1618677797698746}
1618677797.803454: {"topic":"orderBookL2_25.EOSUSD","type":"delta","data":{"delete":[],"update":[{"price":"7.977","symbol":"EOSUSD","id":79770,"side":"Sell","size":53725},{"price":"7.975","symbol":"EOSUSD","id":79750,"side":"Sell","size":71132},{"price":"7.971","symbol":"EOSUSD","id":79710,"side":"Sell","size":3385},{"price":"7.970","symbol":"EOSUSD","id":79700,"side":"Buy","size":48880},{"price":"7.964","symbol":"EOSUSD","id":79640,"side":"Buy","size":164588},{"price":"7.974","symbol":"EOSUSD","id":79740,"side":"Sell","size":4551}],"insert":[],"transactTimeE6":0},"cross_seq":1225777989,"timestamp_e6":1618677797719315}
1618677797.821552: {"topic":"orderBookL2_25.BTCUSD","type":"delta","data":{"delete":[],"update":[{"price":"60621.00","symbol":"BTCUSD","id":606210000,"side":"Buy","size":152064}],"insert":[],"transactTimeE6":0},"cross_seq":5938956985,"timestamp_e6":1618677797737359}
1618677797.8216121: {"topic":"orderBookL2_25.EOSUSD","type":"delta","data":{"delete":[],"update":[{"price":"7.978","symbol":"EOSUSD","id":79780,"side":"Sell","size":39283}],"insert":[],"transactTimeE6":0},"cross_seq":1225777990,"timestamp_e6":1618677797738129}
1618677797.841859: {"topic":"orderBookL2_25.EOSUSD","type":"delta","data":{"delete":[],"update":[{"price":"7.968","symbol":"EOSUSD","id":79680,"side":"Buy","size":62538},{"price":"7.973","symbol":"EOSUSD","id":79730,"side":"Sell","size":9346},{"price":"7.975","symbol":"EOSUSD","id":79750,"side":"Sell","size":66132},{"price":"7.971","symbol":"EOSUSD","id":79710,"side":"Sell","size":11020}],"insert":[],"transactTimeE6":0},"cross_seq":1225777993,"timestamp_e6":1618677797758733}
1618677797.861252: {"topic":"orderBookL2_25.EOSUSD","type":"delta","data":{"delete":[{"price":"7.969","symbol":"EOSUSD","id":79690,"side":"Buy"}],"update":[{"price":"7.968","symbol":"EOSUSD","id":79680,"side":"Buy","size":2795},{"price":"7.962","symbol":"EOSUSD","id":79620,"side":"Buy","size":26023},{"price":"7.963","symbol":"EOSUSD","id":79630,"side":"Buy","size":52947},{"price":"7.961","symbol":"EOSUSD","id":79610,"side":"Buy","size":42545},{"price":"7.965","symbol":"EOSUSD","id":79650,"side":"Buy","size":40441}],"insert":[{"price":"7.966","symbol":"EOSUSD","id":79660,"side":"Buy","size":39956}],"transactTimeE6":0},"cross_seq":1225778001,"timestamp_e6":1618677797778095}
1618677797.8816068: {"topic":"orderBookL2_25.EOSUSD","type":"delta","data":{"delete":[],"update":[{"price":"7.975","symbol":"EOSUSD","id":79750,"side":"Sell","size":69517},{"price":"7.971","symbol":"EOSUSD","id":79710,"side":"Sell","size":7635}],"insert":[],"transactTimeE6":0},"cross_seq":1225778002,"timestamp_e6":1618677797798747}
1618677797.92309: {"topic":"orderBookL2_25.BTCUSD","type":"delta","data":{"delete":[],"update":[{"price":"60622.00","symbol":"BTCUSD","id":606220000,"side":"Buy","size":145880}],"insert":[],"transactTimeE6":0},"cross_seq":5938956988,"timestamp_e6":1618677797837329}
1618677797.923147: {"topic":"orderBookL2_25.EOSUSD","type":"delta","data":{"delete":[],"update":[{"price":"7.968","symbol":"EOSUSD","id":79680,"side":"Buy","size":1795}],"insert":[],"transactTimeE6":0},"cross_seq":1225778005,"timestamp_e6":1618677797838182}
1618677797.9432042: {"topic":"orderBookL2_25.EOSUSD","type":"delta","data":{"delete":[],"update":[{"price":"7.970","symbol":"EOSUSD","id":79700,"side":"Buy","size":107478},{"price":"7.971","symbol":"EOSUSD","id":79710,"side":"Sell","size":13337}],"insert":[],"transactTimeE6":0},"cross_seq":1225778009,"timestamp_e6":1618677797859929}
1618677797.980972: {"topic":"orderBookL2_25.BTCUSD","type":"delta","data":{"delete":[],"update":[{"price":"60616.00","symbol":"BTCUSD","id":606160000,"side":"Buy","size":1029758}],"insert":[],"transactTimeE6":0},"cross_seq":5938956991,"timestamp_e6":1618677797897325}
1618677797.9810162: {"topic":"orderBookL2_25.EOSUSD","type":"delta","data":{"delete":[],"update":[{"price":"7.973","symbol":"EOSUSD","id":79730,"side":"Sell","size":12731},{"price":"7.975","symbol":"EOSUSD","id":79750,"side":"Sell","size":66132},{"price":"7.962","symbol":"EOSUSD","id":79620,"side":"Buy","size":41696},{"price":"7.965","symbol":"EOSUSD","id":79650,"side":"Buy","size":62313}],"insert":[],"transactTimeE6":0},"cross_seq":1225778012,"timestamp_e6":1618677797898103}
1618677798.0043058: {"topic":"orderBookL2_25.EOSUSD","type":"delta","data":{"delete":[{"price":"7.972","symbol":"EOSUSD","id":79720,"side":"Sell"},{"price":"7.974","symbol":"EOSUSD","id":79740,"side":"Sell"}],"update":[{"price":"7.973","symbol":"EOSUSD","id":79730,"side":"Sell","size":9683},{"price":"7.975","symbol":"EOSUSD","id":79750,"side":"Sell","size":64258},{"price":"7.970","symbol":"EOSUSD","id":79700,"side":"Buy","size":109093},{"price":"7.968","symbol":"EOSUSD","id":79680,"side":"Buy","size":180}],"insert":[{"price":"7.997","symbol":"EOSUSD","id":79970,"side":"Sell","size":152052},{"price":"7.996","symbol":"EOSUSD","id":79960,"side":"Sell","size":39326}],"transactTimeE6":0},"cross_seq":1225778017,"timestamp_e6":1618677797918704}
1618677798.0287309: {"topic":"orderBookL2_25.EOSUSD","type":"delta","data":{"delete":[],"update":[{"price":"7.970","symbol":"EOSUSD","id":79700,"side":"Buy","size":135759}],"insert":[],"transactTimeE6":0},"cross_seq":1225778018,"timestamp_e6":1618677797938814}
1618677798.042621: {"topic":"orderBookL2_25.EOSUSD","type":"delta","data":{"delete":[],"update":[{"price":"7.975","symbol":"EOSUSD","id":79750,"side":"Sell","size":12000}],"insert":[],"transactTimeE6":0},"cross_seq":1225778019,"timestamp_e6":1618677797958157}
1618677798.0639439: {"topic":"orderBookL2_25.EOSUSD","type":"delta","data":{"delete":[],"update":[{"price":"7.985","symbol":"EOSUSD","id":79850,"side":"Sell","size":54333},{"price":"7.984","symbol":"EOSUSD","id":79840,"side":"Sell","size":114457},{"price":"7.964","symbol":"EOSUSD","id":79640,"side":"Buy","size":151258},{"price":"7.980","symbol":"EOSUSD","id":79800,"side":"Sell","size":77361},{"price":"7.981","symbol":"EOSUSD","id":79810,"side":"Sell","size":66979},{"price":"7.982","symbol":"EOSUSD","id":79820,"side":"Sell","size":92601},{"price":"7.961","symbol":"EOSUSD","id":79610,"side":"Buy","size":25617},{"price":"7.959","symbol":"EOSUSD","id":79590,"side":"Buy","size":21812},{"price":"7.960","symbol":"EOSUSD","id":79600,"side":"Buy","size":27544},{"price":"7.970","symbol":"EOSUSD","id":79700,"side":"Buy","size":152259}],"insert":[],"transactTimeE6":0},"cross_seq":1225778031,"timestamp_e6":1618677797978880}
1618677798.106828: {"topic":"orderBookL2_25.EOSUSD","type":"delta","data":{"delete":[],"update":[{"price":"7.988","symbol":"EOSUSD","id":79880,"side":"Sell","size":40359}],"insert":[],"transactTimeE6":0},"cross_seq":1225778032,"timestamp_e6":1618677798018188}
1618677798.124825: {"topic":"orderBookL2_25.BTCUSD","type":"delta","data":{"delete":[],"update":[{"price":"60622.00","symbol":"BTCUSD","id":606220000,"side":"Buy","size":145883}],"insert":[],"transactTimeE6":0},"cross_seq":5938956996,"timestamp_e6":1618677798037394}
1618677798.192138: {"topic":"orderBookL2_25.EOSUSD","type":"delta","data":{"delete":[],"update":[{"price":"7.959","symbol":"EOSUSD","id":79590,"side":"Buy","size":25021},{"price":"7.980","symbol":"EOSUSD","id":79800,"side":"Sell","size":87500},{"price":"7.961","symbol":"EOSUSD","id":79610,"side":"Buy","size":34077},{"price":"7.960","symbol":"EOSUSD","id":79600,"side":"Buy","size":34590},{"price":"7.982","symbol":"EOSUSD","id":79820,"side":"Sell","size":100901}],"insert":[],"transactTimeE6":0},"cross_seq":1225778037,"timestamp_e6":1618677798098128}
1618677798.4228292: {"topic":"orderBookL2_25.BTCUSD","type":"delta","data":{"delete":[],"update":[{"price":"60629.00","symbol":"BTCUSD","id":606290000,"side":"Sell","size":63866}],"insert":[],"transactTimeE6":0},"cross_seq":5938957004,"timestamp_e6":1618677798317332}
1618677798.422867: {"topic":"orderBookL2_25.EOSUSD","type":"delta","data":{"delete":[{"price":"7.971","symbol":"EOSUSD","id":79710,"side":"Sell"}],"update":[],"insert":[{"price":"7.998","symbol":"EOSUSD","id":79980,"side":"Sell","size":106121}],"transactTimeE6":0},"cross_seq":1225778040,"timestamp_e6":1618677798318820}
1618677798.425032: {"topic":"orderBookL2_25.EOSUSD","type":"delta","data":{"delete":[{"price":"7.944","symbol":"EOSUSD","id":79440,"side":"Buy"}],"update":[{"price":"7.973","symbol":"EOSUSD","id":79730,"side":"Sell","size":23627},{"price":"7.970","symbol":"EOSUSD","id":79700,"side":"Buy","size":124379}],"insert":[{"price":"7.972","symbol":"EOSUSD","id":79720,"side":"Buy","size":27880}],"transactTimeE6":0},"cross_seq":1225778049,"timestamp_e6":1618677798339344}
1618677798.44701: {"topic":"orderBookL2_25.EOSUSD","type":"delta","data":{"delete":[{"price":"7.945","symbol":"EOSUSD","id":79450,"side":"Buy"}],"update":[{"price":"7.982","symbol":"EOSUSD","id":79820,"side":"Sell","size":182002},{"price":"7.970","symbol":"EOSUSD","id":79700,"side":"Buy","size":107879},{"price":"7.972","symbol":"EOSUSD","id":79720,"side":"Buy","size":42880}],"insert":[{"price":"7.971","symbol":"EOSUSD","id":79710,"side":"Buy","size":26666}],"transactTimeE6":0},"cross_seq":1225778054,"timestamp_e6":1618677798358765}
1618677798.464406: {"topic":"orderBookL2_25.EOSUSD","type":"delta","data":{"delete":[],"update":[{"price":"7.971","symbol":"EOSUSD","id":79710,"side":"Buy","size":58598},{"price":"7.970","symbol":"EOSUSD","id":79700,"side":"Buy","size":61213},{"price":"7.972","symbol":"EOSUSD","id":79720,"side":"Buy","size":62880},{"price":"7.966","symbol":"EOSUSD","id":79660,"side":"Buy","size":40611}],"insert":[],"transactTimeE6":0},"cross_seq":1225778060,"timestamp_e6":1618677798378729}
1618677798.483829: {"topic":"orderBookL2_25.EOSUSD","type":"delta","data":{"delete":[],"update":[{"price":"7.972","symbol":"EOSUSD","id":79720,"side":"Buy","size":63880}],"insert":[],"transactTimeE6":0},"cross_seq":1225778061,"timestamp_e6":1618677798398725}
1618677798.506355: {"topic":"orderBookL2_25.EOSUSD","type":"delta","data":{"delete":[],"update":[{"price":"7.972","symbol":"EOSUSD","id":79720,"side":"Buy","size":65495},{"price":"7.963","symbol":"EOSUSD","id":79630,"side":"Buy","size":30661},{"price":"7.975","symbol":"EOSUSD","id":79750,"side":"Sell","size":17000},{"price":"7.970","symbol":"EOSUSD","id":79700,"side":"Buy","size":63598},{"price":"7.979","symbol":"EOSUSD","id":79790,"side":"Sell","size":52452},{"price":"7.964","symbol":"EOSUSD","id":79640,"side":"Buy","size":124692},{"price":"7.965","symbol":"EOSUSD","id":79650,"side":"Buy","size":71648},{"price":"7.978","symbol":"EOSUSD","id":79780,"side":"Sell","size":56275},{"price":"7.961","symbol":"EOSUSD","id":79610,"side":"Buy","size":15605},{"price":"7.973","symbol":"EOSUSD","id":79730,"side":"Sell","size":18020}],"insert":[],"transactTimeE6":0},"cross_seq":1225778072,"timestamp_e6":1618677798419299}
1618677798.524281: {"topic":"orderBookL2_25.EOSUSD","type":"delta","data":{"delete":[],"update":[{"price":"7.971","symbol":"EOSUSD","id":79710,"side":"Buy","size":78598}],"insert":[],"transactTimeE6":0},"cross_seq":1225778073,"timestamp_e6":1618677798438119}
1618677798.547126: {"topic":"orderBookL2_25.EOSUSD","type":"delta","data":{"delete":[],"update":[{"price":"7.971","symbol":"EOSUSD","id":79710,"side":"Buy","size":58598},{"price":"7.973","symbol":"EOSUSD","id":79730,"side":"Sell","size":14635},{"price":"7.975","symbol":"EOSUSD","id":79750,"side":"Sell","size":20385}],"insert":[],"transactTimeE6":0},"cross_seq":1225778075,"timestamp_e6":1618677798458739}
1618677798.562716: {"topic":"orderBookL2_25.EOSUSD","type":"delta","data":{"delete":[],"update":[{"price":"7.979","symbol":"EOSUSD","id":79790,"side":"Sell","size":64452},{"price":"7.975","symbol":"EOSUSD","id":79750,"side":"Sell","size":8385}],"insert":[],"transactTimeE6":0},"cross_seq":1225778076,"timestamp_e6":1618677798478093}
1618677798.583565: {"topic":"orderBookL2_25.BTCUSD","type":"delta","data":{"delete":[],"update":[{"price":"60623.00","symbol":"BTCUSD","id":606230000,"side":"Sell","size":237946}],"insert":[],"transactTimeE6":0},"cross_seq":5938957010,"timestamp_e6":1618677798497957}
1618677798.5836558: {"topic":"orderBookL2_25.EOSUSD","type":"delta","data":{"delete":[{"price":"7.971","symbol":"EOSUSD","id":79710,"side":"Buy"}],"update":[{"price":"7.970","symbol":"EOSUSD","id":79700,"side":"Buy","size":5000}],"insert":[{"price":"7.945","symbol":"EOSUSD","id":79450,"side":"Buy","size":19617}],"transactTimeE6":0},"cross_seq":1225778078,"timestamp_e6":1618677798498098}
1618677798.60966: {"topic":"orderBookL2_25.BTCUSD","type":"delta","data":{"delete":[],"update":[{"price":"60623.00","symbol":"BTCUSD","id":606230000,"side":"Sell","size":237493},{"price":"60618.00","symbol":"BTCUSD","id":606180000,"side":"Buy","size":870}],"insert":[],"transactTimeE6":0},"cross_seq":5938957012,"timestamp_e6":1618677798517937}
1618677798.60976: {"topic":"orderBookL2_25.EOSUSD","type":"delta","data":{"delete":[{"price":"7.970","symbol":"EOSUSD","id":79700,"side":"Buy"}],"update":[],"insert":[{"price":"7.944","symbol":"EOSUSD","id":79440,"side":"Buy","size":114534}],"transactTimeE6":0},"cross_seq":1225778080,"timestamp_e6":1618677798518111}
1618677798.623517: {"topic":"orderBookL2_25.EOSUSD","type":"delta","data":{"delete":[],"update":[{"price":"7.963","symbol":"EOSUSD","id":79630,"side":"Buy","size":43154},{"price":"7.964","symbol":"EOSUSD","id":79640,"side":"Buy","size":146290},{"price":"7.961","symbol":"EOSUSD","id":79610,"side":"Buy","size":23623}],"insert":[],"transactTimeE6":0},"cross_seq":1225778083,"timestamp_e6":1618677798538099}
1618677798.6620018: {"topic":"trade.BTCUSD","data":[{"trade_time_ms":1618677798489,"timestamp":"2021-04-17T16:43:18.000Z","symbol":"BTCUSD","side":"Buy","size":130,"price":60623,"tick_direction":"ZeroPlusTick","trade_id":"a65924c8-baf9-5b03-9994-1a350b79e2e4","cross_seq":5938957014},{"trade_time_ms":1618677798499,"timestamp":"2021-04-17T16:43:18.000Z","symbol":"BTCUSD","side":"Buy","size":453,"price":60623,"tick_direction":"ZeroPlusTick","trade_id":"e7130007-d84c-50b6-8cd5-1aa94b8df942","cross_seq":5938957014}]}
1618677798.667962: {"topic":"orderBookL2_25.EOSUSD","type":"delta","data":{"delete":[],"update":[{"price":"7.980","symbol":"EOSUSD","id":79800,"side":"Sell","size":139491}],"insert":[],"transactTimeE6":0},"cross_seq":1225778084,"timestamp_e6":1618677798578134}
1618677798.683983: {"topic":"orderBookL2_25.EOSUSD","type":"delta","data":{"delete":[],"update":[{"price":"7.972","symbol":"EOSUSD","id":79720,"side":"Buy","size":121430}],"insert":[],"transactTimeE6":0},"cross_seq":1225778085,"timestamp_e6":1618677798598732}
1618677798.705688: {"topic":"orderBookL2_25.EOSUSD","type":"delta","data":{"delete":[],"update":[{"price":"7.982","symbol":"EOSUSD","id":79820,"side":"Sell","size":172909},{"price":"7.972","symbol":"EOSUSD","id":79720,"side":"Buy","size":134763}],"insert":[],"transactTimeE6":0},"cross_seq":1225778087,"timestamp_e6":1618677798618770}
1618677798.727799: {"topic":"orderBookL2_25.BTCUSD","type":"delta","data":{"delete":[],"update":[{"price":"60623.00","symbol":"BTCUSD","id":606230000,"side":"Sell","size":227703}],"insert":[],"transactTimeE6":0},"cross_seq":5938957015,"timestamp_e6":1618677798638434}
1618677798.7589471: {"topic":"trade.BTCUSD","data":[{"trade_time_ms":1618677798613,"timestamp":"2021-04-17T16:43:18.000Z","symbol":"BTCUSD","side":"Buy","size":9790,"price":60623,"tick_direction":"ZeroPlusTick","trade_id":"b267c39e-f52d-55e3-9cc7-0b8b16c584ea","cross_seq":5938957016}]}
1618677798.767873: {"topic":"orderBookL2_25.BTCUSD","type":"delta","data":{"delete":[],"update":[{"price":"60622.00","symbol":"BTCUSD","id":606220000,"side":"Buy","size":148105}],"insert":[],"transactTimeE6":0},"cross_seq":5938957016,"timestamp_e6":1618677798677325}
1618677798.789952: {"topic":"orderBookL2_25.BTCUSD","type":"delta","data":{"delete":[],"update":[{"price":"60623.00","symbol":"BTCUSD","id":606230000,"side":"Sell","size":227595}],"insert":[],"transactTimeE6":0},"cross_seq":5938957017,"timestamp_e6":1618677798698046}
1618677798.806632: {"topic":"orderBookL2_25.BTCUSD","type":"delta","data":{"delete":[],"update":[{"price":"60623.00","symbol":"BTCUSD","id":606230000,"side":"Sell","size":227352}],"insert":[],"transactTimeE6":0},"cross_seq":5938957018,"timestamp_e6":1618677798717964}
1618677798.847125: {"topic":"orderBookL2_25.BTCUSD","type":"delta","data":{"delete":[],"update":[{"price":"60622.50","symbol":"BTCUSD","id":606225000,"side":"Buy","size":10622191}],"insert":[],"transactTimeE6":0},"cross_seq":5938957021,"timestamp_e6":1618677798758002}
1618677798.865603: {"topic":"trade.BTCUSD","data":[{"trade_time_ms":1618677798674,"timestamp":"2021-04-17T16:43:18.000Z","symbol":"BTCUSD","side":"Buy","size":108,"price":60623,"tick_direction":"ZeroPlusTick","trade_id":"8cc6d49c-d3d2-5117-81dc-a41a2fb3d9da","cross_seq":5938957021},{"trade_time_ms":1618677798706,"timestamp":"2021-04-17T16:43:18.000Z","symbol":"BTCUSD","side":"Buy","size":243,"price":60623,"tick_direction":"ZeroPlusTick","trade_id":"fab9aeb0-f01f-5f86-b7c8-e3930e4997e2","cross_seq":5938957021}]}
1618677798.883032: {"topic":"orderBookL2_25.BTCUSD","type":"delta","data":{"delete":[],"update":[{"price":"60623.00","symbol":"BTCUSD","id":606230000,"side":"Sell","size":227158}],"insert":[],"transactTimeE6":0},"cross_seq":5938957024,"timestamp_e6":1618677798798049}
1618677798.902503: {"topic":"orderBookL2_25.BTCUSD","type":"delta","data":{"delete":[],"update":[{"price":"60624.00","symbol":"BTCUSD","id":606240000,"side":"Sell","size":137273}],"insert":[],"transactTimeE6":0},"cross_seq":5938957025,"timestamp_e6":1618677798817378}
1618677798.933404: {"topic":"orderBookL2_25.EOSUSD","type":"delta","data":{"delete":[{"price":"7.944","symbol":"EOSUSD","id":79440,"side":"Buy"}],"update":[{"price":"7.968","symbol":"EOSUSD","id":79680,"side":"Buy","size":80}],"insert":[{"price":"7.969","symbol":"EOSUSD","id":79690,"side":"Buy","size":100}],"transactTimeE6":0},"cross_seq":1225778089,"timestamp_e6":1618677798838111}
1618677798.961788: {"topic":"trade.BTCUSD","data":[{"trade_time_ms":1618677798788,"timestamp":"2021-04-17T16:43:18.000Z","symbol":"BTCUSD","side":"Buy","size":194,"price":60623,"tick_direction":"ZeroPlusTick","trade_id":"b771ef50-93c9-5fe6-8b75-510abb63c1d6","cross_seq":5938957025}]}
1618677798.9692311: {"topic":"orderBookL2_25.EOSUSD","type":"delta","data":{"delete":[],"update":[{"price":"7.982","symbol":"EOSUSD","id":79820,"side":"Sell","size":181598},{"price":"7.972","symbol":"EOSUSD","id":79720,"side":"Buy","size":138763}],"insert":[],"transactTimeE6":0},"cross_seq":1225778091,"timestamp_e6":1618677798878815}
1618677798.987742: {"topic":"orderBookL2_25.EOSUSD","type":"delta","data":{"delete":[],"update":[{"price":"7.972","symbol":"EOSUSD","id":79720,"side":"Buy","size":142763}],"insert":[],"transactTimeE6":0},"cross_seq":1225778092,"timestamp_e6":1618677798898780}
1618677799.043454: {"topic":"orderBookL2_25.EOSUSD","type":"delta","data":{"delete":[],"update":[{"price":"7.972","symbol":"EOSUSD","id":79720,"side":"Buy","size":138763}],"insert":[],"transactTimeE6":0},"cross_seq":1225778093,"timestamp_e6":1618677798958757}
1618677799.082318: {"topic":"orderBookL2_25.EOSUSD","type":"delta","data":{"delete":[],"update":[{"price":"7.972","symbol":"EOSUSD","id":79720,"side":"Buy","size":134763},{"price":"7.984","symbol":"EOSUSD","id":79840,"side":"Sell","size":122428},{"price":"7.962","symbol":"EOSUSD","id":79620,"side":"Buy","size":33364},{"price":"7.960","symbol":"EOSUSD","id":79600,"side":"Buy","size":44824},{"price":"7.959","symbol":"EOSUSD","id":79590,"side":"Buy","size":32246},{"price":"7.981","symbol":"EOSUSD","id":79810,"side":"Sell","size":83193}],"insert":[],"transactTimeE6":0},"cross_seq":1225778099,"timestamp_e6":1618677798998697}
1618677799.122422: {"topic":"orderBookL2_25.BTCUSD","type":"delta","data":{"delete":[],"update":[{"price":"60624.00","symbol":"BTCUSD","id":606240000,"side":"Sell","size":182911},{"price":"60623.00","symbol":"BTCUSD","id":606230000,"side":"Sell","size":316985},{"price":"60625.00","symbol":"BTCUSD","id":606250000,"side":"Sell","size":169313},{"price":"60625.50","symbol":"BTCUSD","id":606255000,"side":"Sell","size":133494}],"insert":[],"transactTimeE6":0},"cross_seq":5938957047,"timestamp_e6":1618677799038113}
1618677799.146642: {"topic":"orderBookL2_25.BTCUSD","type":"delta","data":{"delete":[],"update":[{"price":"60622.50","symbol":"BTCUSD","id":606225000,"side":"Buy","size":10622192}],"insert":[],"transactTimeE6":0},"cross_seq":5938957049,"timestamp_e6":1618677799058021}
1618677799.186107: {"topic":"orderBookL2_25.BTCUSD","type":"delta","data":{"delete":[],"update":[{"price":"60618.00","symbol":"BTCUSD","id":606180000,"side":"Buy","size":873},{"price":"60623.00","symbol":"BTCUSD","id":606230000,"side":"Sell","size":316738}],"insert":[],"transactTimeE6":0},"cross_seq":5938957052,"timestamp_e6":1618677799097952}
1618677799.2012742: {"topic":"orderBookL2_25.EOSUSD","type":"delta","data":{"delete":[],"update":[{"price":"7.964","symbol":"EOSUSD","id":79640,"side":"Buy","size":155796},{"price":"7.962","symbol":"EOSUSD","id":79620,"side":"Buy","size":37965}],"insert":[],"transactTimeE6":0},"cross_seq":1225778101,"timestamp_e6":1618677799118111}
1618677799.201376: {"topic":"orderBookL2_25.BTCUSD","type":"delta","data":{"delete":[],"update":[{"price":"60623.00","symbol":"BTCUSD","id":606230000,"side":"Sell","size":316544}],"insert":[],"transactTimeE6":0},"cross_seq":5938957054,"timestamp_e6":1618677799117940}
1618677799.242115: {"topic":"orderBookL2_25.BTCUSD","type":"delta","data":{"delete":[],"update":[{"price":"60623.00","symbol":"BTCUSD","id":606230000,"side":"Sell","size":316277}],"insert":[],"transactTimeE6":0},"cross_seq":5938957057,"timestamp_e6":1618677799157953}
1618677799.24223: {"topic":"orderBookL2_25.EOSUSD","type":"delta","data":{"delete":[{"price":"7.969","symbol":"EOSUSD","id":79690,"side":"Buy"}],"update":[{"price":"7.972","symbol":"EOSUSD","id":79720,"side":"Buy","size":134863}],"insert":[{"price":"7.944","symbol":"EOSUSD","id":79440,"side":"Buy","size":114534}],"transactTimeE6":0},"cross_seq":1225778102,"timestamp_e6":1618677799158733}
1618677799.2560298: {"topic":"trade.BTCUSD","data":[{"trade_time_ms":1618677799089,"timestamp":"2021-04-17T16:43:19.000Z","symbol":"BTCUSD","side":"Buy","size":247,"price":60623,"tick_direction":"ZeroPlusTick","trade_id":"aed8b109-343c-579f-b01a-7841c0f4c37c","cross_seq":5938957057},{"trade_time_ms":1618677799105,"timestamp":"2021-04-17T16:43:19.000Z","symbol":"BTCUSD","side":"Buy","size":194,"price":60623,"tick_direction":"ZeroPlusTick","trade_id":"feb92431-5ce1-50f8-a0b6-9b33e6083a2f","cross_seq":5938957057},{"trade_time_ms":1618677799142,"timestamp":"2021-04-17T16:43:19.000Z","symbol":"BTCUSD","side":"Buy","size":267,"price":60623,"tick_direction":"ZeroPlusTick","trade_id":"0398aa0b-322c-595d-bc5c-18b385a82bd3","cross_seq":5938957057}]}
1618677799.261194: {"topic":"orderBookL2_25.BTCUSD","type":"delta","data":{"delete":[],"update":[{"price":"60623.00","symbol":"BTCUSD","id":606230000,"side":"Sell","size":316094}],"insert":[],"transactTimeE6":0},"cross_seq":5938957058,"timestamp_e6":1618677799178001}
1618677799.301085: {"topic":"orderBookL2_25.BTCUSD","type":"delta","data":{"delete":[],"update":[{"price":"60630.50","symbol":"BTCUSD","id":606305000,"side":"Sell","size":154314}],"insert":[],"transactTimeE6":0},"cross_seq":5938957063,"timestamp_e6":1618677799217335}
1618677799.321655: {"topic":"orderBookL2_25.BTCUSD","type":"delta","data":{"delete":[],"update":[{"price":"60623.00","symbol":"BTCUSD","id":606230000,"side":"Sell","size":315994}],"insert":[],"transactTimeE6":0},"cross_seq":5938957065,"timestamp_e6":1618677799237966}
1618677799.357588: {"topic":"trade.BTCUSD","data":[{"trade_time_ms":1618677799167,"timestamp":"2021-04-17T16:43:19.000Z","symbol":"BTCUSD","side":"Buy","size":183,"price":60623,"tick_direction":"ZeroPlusTick","trade_id":"c6f32c8f-25fb-5f80-8d4b-85a49931ccf6","cross_seq":5938957067},{"trade_time_ms":1618677799217,"timestamp":"2021-04-17T16:43:19.000Z","symbol":"BTCUSD","side":"Buy","size":100,"price":60623,"tick_direction":"ZeroPlusTick","trade_id":"16c5197e-044a-5d03-bbdb-cf441d6668e1","cross_seq":5938957067},{"trade_time_ms":1618677799261,"timestamp":"2021-04-17T16:43:19.000Z","symbol":"BTCUSD","side":"Buy","size":139,"price":60623,"tick_direction":"ZeroPlusTick","trade_id":"1ae55203-14dd-5644-8f0a-c94972471142","cross_seq":5938957067}]}
1618677799.3613598: {"topic":"orderBookL2_25.BTCUSD","type":"delta","data":{"delete":[],"update":[{"price":"60623.00","symbol":"BTCUSD","id":606230000,"side":"Sell","size":315855}],"insert":[],"transactTimeE6":0},"cross_seq":5938957067,"timestamp_e6":1618677799277958}
1618677799.4214048: {"topic":"orderBookL2_25.BTCUSD","type":"delta","data":{"delete":[],"update":[{"price":"60622.50","symbol":"BTCUSD","id":606225000,"side":"Buy","size":10622196}],"insert":[],"transactTimeE6":0},"cross_seq":5938957068,"timestamp_e6":1618677799337910}
1618677799.441673: {"topic":"orderBookL2_25.BTCUSD","type":"delta","data":{"delete":[],"update":[{"price":"60634.50","symbol":"BTCUSD","id":606345000,"side":"Sell","size":21834},{"price":"60623.00","symbol":"BTCUSD","id":606230000,"side":"Sell","size":315672}],"insert":[],"transactTimeE6":0},"cross_seq":5938957070,"timestamp_e6":1618677799357958}
1618677799.4583611: {"topic":"trade.BTCUSD","data":[{"trade_time_ms":1618677799338,"timestamp":"2021-04-17T16:43:19.000Z","symbol":"BTCUSD","side":"Buy","size":183,"price":60623,"tick_direction":"ZeroPlusTick","trade_id":"714bc229-8ee4-55dd-9e28-41ae8231f2cf","cross_seq":5938957071}]}
1618677799.4812841: {"topic":"orderBookL2_25.BTCUSD","type":"delta","data":{"delete":[],"update":[{"price":"60623.00","symbol":"BTCUSD","id":606230000,"side":"Sell","size":315478}],"insert":[],"transactTimeE6":0},"cross_seq":5938957072,"timestamp_e6":1618677799397937}
1618677799.521926: {"topic":"orderBookL2_25.EOSUSD","type":"delta","data":{"delete":[],"update":[{"price":"7.980","symbol":"EOSUSD","id":79800,"side":"Sell","size":98784},{"price":"7.978","symbol":"EOSUSD","id":79780,"side":"Sell","size":17013},{"price":"7.977","symbol":"EOSUSD","id":79770,"side":"Sell","size":42282}],"insert":[],"transactTimeE6":0},"cross_seq":1225778106,"timestamp_e6":1618677799438110}
1618677799.542015: {"topic":"orderBookL2_25.BTCUSD","type":"delta","data":{"delete":[],"update":[{"price":"60623.00","symbol":"BTCUSD","id":606230000,"side":"Sell","size":315310}],"insert":[],"transactTimeE6":0},"cross_seq":5938957073,"timestamp_e6":1618677799457968}
1618677799.5589042: {"topic":"trade.BTCUSD","data":[{"trade_time_ms":1618677799373,"timestamp":"2021-04-17T16:43:19.000Z","symbol":"BTCUSD","side":"Buy","size":194,"price":60623,"tick_direction":"ZeroPlusTick","trade_id":"f3723e71-925a-5041-a851-4d6ebad3662e","cross_seq":5938957073},{"trade_time_ms":1618677799444,"timestamp":"2021-04-17T16:43:19.000Z","symbol":"BTCUSD","side":"Buy","size":168,"price":60623,"tick_direction":"ZeroPlusTick","trade_id":"59daa286-a72b-57af-9742-45a24f5dac8e","cross_seq":5938957073}]}
1618677799.601311: {"topic":"orderBookL2_25.EOSUSD","type":"delta","data":{"delete":[],"update":[{"price":"7.966","symbol":"EOSUSD","id":79660,"side":"Buy","size":39956}],"insert":[],"transactTimeE6":0},"cross_seq":1225778107,"timestamp_e6":1618677799518123}
1618677799.64155: {"topic":"orderBookL2_25.EOSUSD","type":"delta","data":{"delete":[],"update":[{"price":"7.980","symbol":"EOSUSD","id":79800,"side":"Sell","size":128721},{"price":"7.979","symbol":"EOSUSD","id":79790,"side":"Sell","size":45794},{"price":"7.978","symbol":"EOSUSD","id":79780,"side":"Sell","size":42662},{"price":"7.964","symbol":"EOSUSD","id":79640,"side":"Buy","size":161614}],"insert":[],"transactTimeE6":0},"cross_seq":1225778111,"timestamp_e6":1618677799558119}
1618677799.7614279: {"topic":"orderBookL2_25.EOSUSD","type":"delta","data":{"delete":[{"price":"7.966","symbol":"EOSUSD","id":79660,"side":"Buy"}],"update":[{"price":"7.979","symbol":"EOSUSD","id":79790,"side":"Sell","size":61516},{"price":"7.963","symbol":"EOSUSD","id":79630,"side":"Buy","size":47433},{"price":"7.962","symbol":"EOSUSD","id":79620,"side":"Buy","size":22292},{"price":"7.981","symbol":"EOSUSD","id":79810,"side":"Sell","size":73655},{"price":"7.965","symbol":"EOSUSD","id":79650,"side":"Buy","size":49776},{"price":"7.964","symbol":"EOSUSD","id":79640,"side":"Buy","size":140016}],"insert":[{"price":"7.967","symbol":"EOSUSD","id":79670,"side":"Buy","size":42105}],"transactTimeE6":0},"cross_seq":1225778119,"timestamp_e6":1618677799678222}
1618677799.780612: {"topic":"orderBookL2_25.EOSUSD","type":"delta","data":{"delete":[{"price":"7.944","symbol":"EOSUSD","id":79440,"side":"Buy"}],"update":[{"price":"7.979","symbol":"EOSUSD","id":79790,"side":"Sell","size":38764},{"price":"7.964","symbol":"EOSUSD","id":79640,"side":"Buy","size":144254},{"price":"7.962","symbol":"EOSUSD","id":79620,"side":"Buy","size":31474},{"price":"7.965","symbol":"EOSUSD","id":79650,"side":"Buy","size":65896}],"insert":[{"price":"7.966","symbol":"EOSUSD","id":79660,"side":"Buy","size":32471}],"transactTimeE6":0},"cross_seq":1225778124,"timestamp_e6":1618677799698056}
1618677799.800954: {"topic":"orderBookL2_25.BTCUSD","type":"delta","data":{"delete":[],"update":[{"price":"60623.00","symbol":"BTCUSD","id":606230000,"side":"Sell","size":314727}],"insert":[],"transactTimeE6":0},"cross_seq":5938957078,"timestamp_e6":1618677799717980}
1618677799.85677: {"topic":"trade.BTCUSD","data":[{"trade_time_ms":1618677799706,"timestamp":"2021-04-17T16:43:19.000Z","symbol":"BTCUSD","side":"Buy","size":98,"price":60623,"tick_direction":"ZeroPlusTick","trade_id":"ac4151f6-941d-56c9-922a-1c0b90e84c3a","cross_seq":5938957080},{"trade_time_ms":1618677799706,"timestamp":"2021-04-17T16:43:19.000Z","symbol":"BTCUSD","side":"Buy","size":485,"price":60623,"tick_direction":"ZeroPlusTick","trade_id":"b2dad654-5106-5eaf-923f-463b2af4797f","cross_seq":5938957080}]}
1618677799.9017768: {"topic":"orderBookL2_25.EOSUSD","type":"delta","data":{"delete":[],"update":[{"price":"7.979","symbol":"EOSUSD","id":79790,"side":"Sell","size":54577}],"insert":[],"transactTimeE6":0},"cross_seq":1225778125,"timestamp_e6":1618677799818142}
1618677799.923628: {"topic":"orderBookL2_25.BTCUSD","type":"delta","data":{"delete":[],"update":[{"price":"60623.00","symbol":"BTCUSD","id":606230000,"side":"Sell","size":314545}],"insert":[],"transactTimeE6":0},"cross_seq":5938957083,"timestamp_e6":1618677799837945}
1618677799.941335: {"topic":"orderBookL2_25.BTCUSD","type":"delta","data":{"delete":[],"update":[{"price":"60623.00","symbol":"BTCUSD","id":606230000,"side":"Sell","size":288652}],"insert":[],"transactTimeE6":0},"cross_seq":5938957084,"timestamp_e6":1618677799857931}
1618677799.9574971: {"topic":"trade.BTCUSD","data":[{"trade_time_ms":1618677799828,"timestamp":"2021-04-17T16:43:19.000Z","symbol":"BTCUSD","side":"Buy","size":182,"price":60623,"tick_direction":"ZeroPlusTick","trade_id":"0ab431da-3f23-574b-a96b-2f794f08d6fe","cross_seq":5938957085},{"trade_time_ms":1618677799840,"timestamp":"2021-04-17T16:43:19.000Z","symbol":"BTCUSD","side":"Buy","size":25893,"price":60623,"tick_direction":"ZeroPlusTick","trade_id":"f0702366-ce9a-5d53-82cb-6fcee2bb0ec4","cross_seq":5938957085}]}
1618677799.981087: {"topic":"orderBookL2_25.EOSUSD","type":"delta","data":{"delete":[],"update":[{"price":"7.964","symbol":"EOSUSD","id":79640,"side":"Buy","size":123725},{"price":"7.960","symbol":"EOSUSD","id":79600,"side":"Buy","size":21570},{"price":"7.963","symbol":"EOSUSD","id":79630,"side":"Buy","size":31534},{"price":"7.984","symbol":"EOSUSD","id":79840,"side":"Sell","size":109337},{"price":"7.983","symbol":"EOSUSD","id":79830,"side":"Sell","size":112888},{"price":"7.985","symbol":"EOSUSD","id":79850,"side":"Sell","size":47189}],"insert":[],"transactTimeE6":0},"cross_seq":1225778133,"timestamp_e6":1618677799898173}
1618677800.043071: {"topic":"orderBookL2_25.BTCUSD","type":"delta","data":{"delete":[],"update":[{"price":"60622.50","symbol":"BTCUSD","id":606225000,"side":"Buy","size":10622192}],"insert":[],"transactTimeE6":0},"cross_seq":5938957093,"timestamp_e6":1618677799958059}
1618677800.080773: {"topic":"orderBookL2_25.BTCUSD","type":"delta","data":{"delete":[],"update":[{"price":"60630.00","symbol":"BTCUSD","id":606300000,"side":"Sell","size":77086}],"insert":[],"transactTimeE6":0},"cross_seq":5938957096,"timestamp_e6":1618677799997376}
1618677800.101087: {"topic":"orderBookL2_25.EOSUSD","type":"delta","data":{"delete":[],"update":[{"price":"7.960","symbol":"EOSUSD","id":79600,"side":"Buy","size":30880},{"price":"7.963","symbol":"EOSUSD","id":79630,"side":"Buy","size":41842},{"price":"7.983","symbol":"EOSUSD","id":79830,"side":"Sell","size":122103},{"price":"7.964","symbol":"EOSUSD","id":79640,"side":"Buy","size":141306}],"insert":[],"transactTimeE6":0},"cross_seq":1225778138,"timestamp_e6":1618677800018103}
1618677800.1417248: {"topic":"orderBookL2_25.EOSUSD","type":"delta","data":{"delete":[],"update":[{"price":"7.982","symbol":"EOSUSD","id":79820,"side":"Sell","size":142824},{"price":"7.964","symbol":"EOSUSD","id":79640,"side":"Buy","size":100604}],"insert":[],"transactTimeE6":0},"cross_seq":1225778140,"timestamp_e6":1618677800058145}
1618677800.2221272: {"topic":"orderBookL2_25.BTCUSD","type":"delta","data":{"delete":[],"update":[{"price":"60623.00","symbol":"BTCUSD","id":606230000,"side":"Sell","size":288480}],"insert":[],"transactTimeE6":0},"cross_seq":5938957106,"timestamp_e6":1618677800138015}
1618677800.241239: {"topic":"orderBookL2_25.EOSUSD","type":"delta","data":{"delete":[],"update":[{"price":"7.984","symbol":"EOSUSD","id":79840,"side":"Sell","size":116026}],"insert":[],"transactTimeE6":0},"cross_seq":1225778141,"timestamp_e6":1618677800158111}
1618677800.2559319: {"topic":"trade.BTCUSD","data":[{"trade_time_ms":1618677800118,"timestamp":"2021-04-17T16:43:20.000Z","symbol":"BTCUSD","side":"Buy","size":172,"price":60623,"tick_direction":"ZeroPlusTick","trade_id":"25e52141-fa3e-5d72-aaee-10300e2c5ffa","cross_seq":5938957108}]}
1618677800.3419368: {"topic":"orderBookL2_25.BTCUSD","type":"delta","data":{"delete":[],"update":[{"price":"60623.00","symbol":"BTCUSD","id":606230000,"side":"Sell","size":288481}],"insert":[],"transactTimeE6":0},"cross_seq":5938957117,"timestamp_e6":1618677800257945}
1618677800.36094: {"topic":"orderBookL2_25.EOSUSD","type":"delta","data":{"delete":[],"update":[{"price":"7.964","symbol":"EOSUSD","id":79640,"side":"Buy","size":48989}],"insert":[],"transactTimeE6":0},"cross_seq":1225778142,"timestamp_e6":1618677800278113}
1618677800.402275: {"topic":"orderBookL2_25.BTCUSD","type":"delta","data":{"delete":[],"update":[{"price":"60623.50","symbol":"BTCUSD","id":606235000,"side":"Sell","size":857452},{"price":"60622.50","symbol":"BTCUSD","id":606225000,"side":"Buy","size":10622692}],"insert":[],"transactTimeE6":0},"cross_seq":5938957125,"timestamp_e6":1618677800317891}
1618677800.402375: {"topic":"orderBookL2_25.EOSUSD","type":"delta","data":{"delete":[],"update":[{"price":"7.972","symbol":"EOSUSD","id":79720,"side":"Buy","size":142863}],"insert":[],"transactTimeE6":0},"cross_seq":1225778144,"timestamp_e6":1618677800318740}
1618677800.4328709: {"topic":"orderBookL2_25.BTCUSD","type":"delta","data":{"delete":[],"update":[{"price":"60623.00","symbol":"BTCUSD","id":606230000,"side":"Sell","size":1086077},{"price":"60623.50","symbol":"BTCUSD","id":606235000,"side":"Sell","size":155016}],"insert":[],"transactTimeE6":0},"cross_seq":5938957130,"timestamp_e6":1618677800337978}
1618677800.451377: {"topic":"orderBookL2_25.BTCUSD","type":"delta","data":{"delete":[],"update":[{"price":"60616.50","symbol":"BTCUSD","id":606165000,"side":"Buy","size":17640},{"price":"60622.00","symbol":"BTCUSD","id":606220000,"side":"Buy","size":5230},{"price":"60621.00","symbol":"BTCUSD","id":606210000,"side":"Buy","size":21208}],"insert":[],"transactTimeE6":0},"cross_seq":5938957133,"timestamp_e6":1618677800357278}
1618677800.501809: {"topic":"orderBookL2_25.BTCUSD","type":"delta","data":{"delete":[],"update":[{"price":"60623.00","symbol":"BTCUSD","id":606230000,"side":"Sell","size":1086090},{"price":"60622.50","symbol":"BTCUSD","id":606225000,"side":"Buy","size":10190693}],"insert":[],"transactTimeE6":0},"cross_seq":5938957157,"timestamp_e6":1618677800418600}
1618677800.503834: {"topic":"orderBookL2_25.EOSUSD","type":"delta","data":{"delete":[],"update":[{"price":"7.972","symbol":"EOSUSD","id":79720,"side":"Buy","size":138863}],"insert":[],"transactTimeE6":0},"cross_seq":1225778145,"timestamp_e6":1618677800418744}
1618677800.522551: {"topic":"orderBookL2_25.BTCUSD","type":"delta","data":{"delete":[],"update":[{"price":"60622.50","symbol":"BTCUSD","id":606225000,"side":"Buy","size":10118693}],"insert":[],"transactTimeE6":0},"cross_seq":5938957160,"timestamp_e6":1618677800437931}
1618677800.522641: {"topic":"orderBookL2_25.EOSUSD","type":"delta","data":{"delete":[],"update":[{"price":"7.972","symbol":"EOSUSD","id":79720,"side":"Buy","size":134863}],"insert":[],"transactTimeE6":0},"cross_seq":1225778146,"timestamp_e6":1618677800438760}
1618677800.5432708: {"topic":"orderBookL2_25.EOSUSD","type":"delta","data":{"delete":[],"update":[{"price":"7.981","symbol":"EOSUSD","id":79810,"side":"Sell","size":84515},{"price":"7.964","symbol":"EOSUSD","id":79640,"side":"Buy","size":69580},{"price":"7.977","symbol":"EOSUSD","id":79770,"side":"Sell","size":55548},{"price":"7.965","symbol":"EOSUSD","id":79650,"side":"Buy","size":56561}],"insert":[],"transactTimeE6":0},"cross_seq":1225778150,"timestamp_e6":1618677800458167}
1618677800.581428: {"topic":"orderBookL2_25.BTCUSD","type":"delta","data":{"delete":[],"update":[{"price":"60623.00","symbol":"BTCUSD","id":606230000,"side":"Sell","size":1086091},{"price":"60625.50","symbol":"BTCUSD","id":606255000,"side":"Sell","size":133493}],"insert":[],"transactTimeE6":0},"cross_seq":5938957165,"timestamp_e6":1618677800498099}
1618677800.62274: {"topic":"orderBookL2_25.EOSUSD","type":"delta","data":{"delete":[],"update":[{"price":"7.982","symbol":"EOSUSD","id":79820,"side":"Sell","size":131603}],"insert":[],"transactTimeE6":0},"cross_seq":1225778151,"timestamp_e6":1618677800538125}
1618677800.62349: {"topic":"orderBookL2_25.BTCUSD","type":"delta","data":{"delete":[],"update":[{"price":"60623.00","symbol":"BTCUSD","id":606230000,"side":"Sell","size":2082303},{"price":"60622.50","symbol":"BTCUSD","id":606225000,"side":"Buy","size":10286696}],"insert":[],"transactTimeE6":0},"cross_seq":5938957196,"timestamp_e6":1618677800538565}
1618677800.6450372: {"topic":"orderBookL2_25.BTCUSD","type":"delta","data":{"delete":[],"update":[{"price":"60623.00","symbol":"BTCUSD","id":606230000,"side":"Sell","size":2165303},{"price":"60622.50","symbol":"BTCUSD","id":606225000,"side":"Buy","size":10334696}],"insert":[],"transactTimeE6":0},"cross_seq":5938957200,"timestamp_e6":1618677800558893}
1618677800.6612842: {"topic":"orderBookL2_25.EOSUSD","type":"delta","data":{"delete":[],"update":[{"price":"7.968","symbol":"EOSUSD","id":79680,"side":"Buy","size":38611},{"price":"7.979","symbol":"EOSUSD","id":79790,"side":"Sell","size":106554},{"price":"7.978","symbol":"EOSUSD","id":79780,"side":"Sell","size":56221}],"insert":[],"transactTimeE6":0},"cross_seq":1225778155,"timestamp_e6":1618677800578112}
1618677800.661393: {"topic":"orderBookL2_25.BTCUSD","type":"delta","data":{"delete":[],"update":[{"price":"60622.50","symbol":"BTCUSD","id":606225000,"side":"Buy","size":10334666}],"insert":[],"transactTimeE6":0},"cross_seq":5938957203,"timestamp_e6":1618677800578003}
1618677800.702979: {"topic":"orderBookL2_25.EOSUSD","type":"delta","data":{"delete":[],"update":[{"price":"7.972","symbol":"EOSUSD","id":79720,"side":"Buy","size":142863}],"insert":[],"transactTimeE6":0},"cross_seq":1225778157,"timestamp_e6":1618677800618785}
1618677800.741031: {"topic":"orderBookL2_25.EOSUSD","type":"delta","data":{"delete":[],"update":[{"price":"7.982","symbol":"EOSUSD","id":79820,"side":"Sell","size":139210}],"insert":[],"transactTimeE6":0},"cross_seq":1225778158,"timestamp_e6":1618677800658114}
1618677800.782806: {"topic":"orderBookL2_25.BTCUSD","type":"delta","data":{"delete":[],"update":[{"price":"60623.00","symbol":"BTCUSD","id":606230000,"side":"Sell","size":2213307}],"insert":[],"transactTimeE6":0},"cross_seq":5938957212,"timestamp_e6":1618677800697973}
1618677800.782924: {"topic":"orderBookL2_25.EOSUSD","type":"delta","data":{"delete":[{"price":"7.967","symbol":"EOSUSD","id":79670,"side":"Buy"}],"update":[{"price":"7.964","symbol":"EOSUSD","id":79640,"side":"Buy","size":38933},{"price":"7.965","symbol":"EOSUSD","id":79650,"side":"Buy","size":61295},{"price":"7.972","symbol":"EOSUSD","id":79720,"side":"Buy","size":138863},{"price":"7.968","symbol":"EOSUSD","id":79680,"side":"Buy","size":72246}],"insert":[{"price":"7.969","symbol":"EOSUSD","id":79690,"side":"Buy","size":47378}],"transactTimeE6":0},"cross_seq":1225778166,"timestamp_e6":1618677800698765}
1618677800.803045: {"topic":"orderBookL2_25.BTCUSD","type":"delta","data":{"delete":[],"update":[{"price":"60623.00","symbol":"BTCUSD","id":606230000,"side":"Sell","size":2261307},{"price":"60622.50","symbol":"BTCUSD","id":606225000,"side":"Buy","size":10382666}],"insert":[],"transactTimeE6":0},"cross_seq":5938957216,"timestamp_e6":1618677800718595}
1618677800.803154: {"topic":"orderBookL2_25.EOSUSD","type":"delta","data":{"delete":[{"price":"7.945","symbol":"EOSUSD","id":79450,"side":"Buy"}],"update":[{"price":"7.976","symbol":"EOSUSD","id":79760,"side":"Sell","size":60140},{"price":"7.972","symbol":"EOSUSD","id":79720,"side":"Buy","size":134863},{"price":"7.964","symbol":"EOSUSD","id":79640,"side":"Buy","size":50681}],"insert":[{"price":"7.967","symbol":"EOSUSD","id":79670,"side":"Buy","size":16342}],"transactTimeE6":0},"cross_seq":1225778170,"timestamp_e6":1618677800718721}
1618677800.820941: {"topic":"orderBookL2_25.BTCUSD","type":"delta","data":{"delete":[],"update":[{"price":"60623.00","symbol":"BTCUSD","id":606230000,"side":"Sell","size":2309307}],"insert":[],"transactTimeE6":0},"cross_seq":5938957218,"timestamp_e6":1618677800737984}
1618677800.8420758: {"topic":"orderBookL2_25.BTCUSD","type":"delta","data":{"delete":[],"update":[{"price":"60623.00","symbol":"BTCUSD","id":606230000,"side":"Sell","size":2357307},{"price":"60622.50","symbol":"BTCUSD","id":606225000,"side":"Buy","size":10478662}],"insert":[],"transactTimeE6":0},"cross_seq":5938957221,"timestamp_e6":1618677800758628}
1618677800.861726: {"topic":"orderBookL2_25.EOSUSD","type":"delta","data":{"delete":[],"update":[{"price":"7.983","symbol":"EOSUSD","id":79830,"side":"Sell","size":104652}],"insert":[],"transactTimeE6":0},"cross_seq":1225778171,"timestamp_e6":1618677800778099}
1618677800.882206: {"topic":"orderBookL2_25.EOSUSD","type":"delta","data":{"delete":[],"update":[{"price":"7.968","symbol":"EOSUSD","id":79680,"side":"Buy","size":121610}],"insert":[],"transactTimeE6":0},"cross_seq":1225778172,"timestamp_e6":1618677800798096}
1618677800.921816: {"topic":"orderBookL2_25.EOSUSD","type":"delta","data":{"delete":[{"price":"7.969","symbol":"EOSUSD","id":79690,"side":"Buy"}],"update":[],"insert":[{"price":"7.945","symbol":"EOSUSD","id":79450,"side":"Buy","size":19617}],"transactTimeE6":0},"cross_seq":1225778173,"timestamp_e6":1618677800838107}
1618677801.001133: {"topic":"orderBookL2_25.EOSUSD","type":"delta","data":{"delete":[],"update":[{"price":"7.960","symbol":"EOSUSD","id":79600,"side":"Buy","size":33465},{"price":"7.981","symbol":"EOSUSD","id":79810,"side":"Sell","size":74069},{"price":"7.961","symbol":"EOSUSD","id":79610,"side":"Buy","size":16498},{"price":"7.983","symbol":"EOSUSD","id":79830,"side":"Sell","size":118300},{"price":"7.959","symbol":"EOSUSD","id":79590,"side":"Buy","size":25780},{"price":"7.985","symbol":"EOSUSD","id":79850,"side":"Sell","size":38005}],"insert":[],"transactTimeE6":0},"cross_seq":1225778182,"timestamp_e6":1618677800918111}
1618677801.0416708: {"topic":"orderBookL2_25.BTCUSD","type":"delta","data":{"delete":[],"update":[{"price":"60622.50","symbol":"BTCUSD","id":606225000,"side":"Buy","size":10478652}],"insert":[],"transactTimeE6":0},"cross_seq":5938957233,"timestamp_e6":1618677800957965}
1618677801.0610518: {"topic":"orderBookL2_25.EOSUSD","type":"delta","data":{"delete":[{"price":"7.945","symbol":"EOSUSD","id":79450,"side":"Buy"}],"update":[],"insert":[{"price":"7.969","symbol":"EOSUSD","id":79690,"side":"Buy","size":41196}],"transactTimeE6":0},"cross_seq":1225778183,"timestamp_e6":1618677800978162}
1618677801.121702: {"topic":"orderBookL2_25.EOSUSD","type":"delta","data":{"delete":[],"update":[{"price":"7.961","symbol":"EOSUSD","id":79610,"side":"Buy","size":18830},{"price":"7.959","symbol":"EOSUSD","id":79590,"side":"Buy","size":30654},{"price":"7.982","symbol":"EOSUSD","id":79820,"side":"Sell","size":150495},{"price":"7.962","symbol":"EOSUSD","id":79620,"side":"Buy","size":28596}],"insert":[],"transactTimeE6":0},"cross_seq":1225778187,"timestamp_e6":1618677801038102}
1618677801.182527: {"topic":"orderBookL2_25.BTCUSD","type":"delta","data":{"delete":[],"update":[{"price":"60622.50","symbol":"BTCUSD","id":606225000,"side":"Buy","size":10627016}],"insert":[],"transactTimeE6":0},"cross_seq":5938957244,"timestamp_e6":1618677801098444}
1618677801.2017012: {"topic":"orderBookL2_25.BTCUSD","type":"delta","data":{"delete":[],"update":[{"price":"60622.50","symbol":"BTCUSD","id":606225000,"side":"Buy","size":10478652}],"insert":[],"transactTimeE6":0},"cross_seq":5938957247,"timestamp_e6":1618677801118038}
1618677801.3009448: {"topic":"orderBookL2_25.EOSUSD","type":"delta","data":{"delete":[{"price":"7.966","symbol":"EOSUSD","id":79660,"side":"Buy"}],"update":[],"insert":[{"price":"7.945","symbol":"EOSUSD","id":79450,"side":"Buy","size":19617}],"transactTimeE6":0},"cross_seq":1225778188,"timestamp_e6":1618677801218163}
1618677801.320412: {"topic":"orderBookL2_25.BTCUSD","type":"delta","data":{"delete":[],"update":[{"price":"60618.00","symbol":"BTCUSD","id":606180000,"side":"Buy","size":870}],"insert":[],"transactTimeE6":0},"cross_seq":5938957285,"timestamp_e6":1618677801237356}
1618677801.341412: {"topic":"orderBookL2_25.BTCUSD","type":"delta","data":{"delete":[{"price":"60609.00","symbol":"BTCUSD","id":606090000,"side":"Buy"}],"update":[],"insert":[{"price":"60605.50","symbol":"BTCUSD","id":606055000,"side":"Buy","size":116695}],"transactTimeE6":0},"cross_seq":5938957298,"timestamp_e6":1618677801257331}
1618677801.4224179: {"topic":"orderBookL2_25.BTCUSD","type":"delta","data":{"delete":[],"update":[{"price":"60622.50","symbol":"BTCUSD","id":606225000,"side":"Buy","size":10478648}],"insert":[],"transactTimeE6":0},"cross_seq":5938957536,"timestamp_e6":1618677801337938}
1618677801.442485: {"topic":"orderBookL2_25.EOSUSD","type":"delta","data":{"delete":[{"price":"7.945","symbol":"EOSUSD","id":79450,"side":"Buy"}],"update":[],"insert":[{"price":"7.966","symbol":"EOSUSD","id":79660,"side":"Buy","size":30191}],"transactTimeE6":0},"cross_seq":1225778189,"timestamp_e6":1618677801358268}
1618677801.562455: {"topic":"orderBookL2_25.BTCUSD","type":"delta","data":{"delete":[{"price":"60605.50","symbol":"BTCUSD","id":606055000,"side":"Buy"}],"update":[],"insert":[{"price":"60606.00","symbol":"BTCUSD","id":606060000,"side":"Buy","size":56014}],"transactTimeE6":0},"cross_seq":5938957571,"timestamp_e6":1618677801477364}
1618677801.5625331: {"topic":"orderBookL2_25.EOSUSD","type":"delta","data":{"delete":[{"price":"7.966","symbol":"EOSUSD","id":79660,"side":"Buy"}],"update":[{"price":"7.977","symbol":"EOSUSD","id":79770,"side":"Sell","size":35286},{"price":"7.979","symbol":"EOSUSD","id":79790,"side":"Sell","size":80155},{"price":"7.980","symbol":"EOSUSD","id":79800,"side":"Sell","size":140863},{"price":"7.968","symbol":"EOSUSD","id":79680,"side":"Buy","size":87975},{"price":"7.965","symbol":"EOSUSD","id":79650,"side":"Buy","size":45175},{"price":"7.976","symbol":"EOSUSD","id":79760,"side":"Sell","size":45518},{"price":"7.981","symbol":"EOSUSD","id":79810,"side":"Sell","size":52190},{"price":"7.967","symbol":"EOSUSD","id":79670,"side":"Buy","size":28667}],"insert":[{"price":"7.945","symbol":"EOSUSD","id":79450,"side":"Buy","size":19617}],"transactTimeE6":0},"cross_seq":1225778200,"timestamp_e6":1618677801478115}
1618677801.622525: {"topic":"orderBookL2_25.BTCUSD","type":"delta","data":{"delete":[],"update":[{"price":"60622.50","symbol":"BTCUSD","id":606225000,"side":"Buy","size":10526648}],"insert":[],"transactTimeE6":0},"cross_seq":5938957573,"timestamp_e6":1618677801537965}
1618677801.6459641: {"topic":"orderBookL2_25.BTCUSD","type":"delta","data":{"delete":[],"update":[{"price":"60623.00","symbol":"BTCUSD","id":606230000,"side":"Sell","size":2381307},{"price":"60622.50","symbol":"BTCUSD","id":606225000,"side":"Buy","size":10574648}],"insert":[],"transactTimeE6":0},"cross_seq":5938957576,"timestamp_e6":1618677801558568}
1618677801.646016: {"topic":"orderBookL2_25.EOSUSD","type":"delta","data":{"delete":[],"update":[{"price":"7.973","symbol":"EOSUSD","id":79730,"side":"Sell","size":14628}],"insert":[],"transactTimeE6":0},"cross_seq":1225778201,"timestamp_e6":1618677801558750}
1618677801.657294: {"topic":"trade.EOSUSD","data":[{"trade_time_ms":1618677801539,"timestamp":"2021-04-17T16:43:21.000Z","symbol":"EOSUSD","side":"Buy","size":7,"price":7.973,"tick_direction":"PlusTick","trade_id":"6ac9f7fe-eb9e-5285-9440-a54a0692311d","cross_seq":1225778201}]}
1618677801.681515: {"topic":"orderBookL2_25.BTCUSD","type":"delta","data":{"delete":[],"update":[{"price":"60622.50","symbol":"BTCUSD","id":606225000,"side":"Buy","size":10710983}],"insert":[],"transactTimeE6":0},"cross_seq":5938957580,"timestamp_e6":1618677801598215}
1618677801.7003891: {"topic":"orderBookL2_25.BTCUSD","type":"delta","data":{"delete":[],"update":[{"price":"60622.50","symbol":"BTCUSD","id":606225000,"side":"Buy","size":10739568}],"insert":[],"transactTimeE6":0},"cross_seq":5938957585,"timestamp_e6":1618677801617966}
1618677801.703061: {"topic":"orderBookL2_25.EOSUSD","type":"delta","data":{"delete":[{"price":"7.945","symbol":"EOSUSD","id":79450,"side":"Buy"}],"update":[{"price":"7.965","symbol":"EOSUSD","id":79650,"side":"Buy","size":57944},{"price":"7.979","symbol":"EOSUSD","id":79790,"side":"Sell","size":88772},{"price":"7.964","symbol":"EOSUSD","id":79640,"side":"Buy","size":53833},{"price":"7.981","symbol":"EOSUSD","id":79810,"side":"Sell","size":64735},{"price":"7.968","symbol":"EOSUSD","id":79680,"side":"Buy","size":112005},{"price":"7.977","symbol":"EOSUSD","id":79770,"side":"Sell","size":44551}],"insert":[{"price":"7.966","symbol":"EOSUSD","id":79660,"side":"Buy","size":20754}],"transactTimeE6":0},"cross_seq":1225778208,"timestamp_e6":1618677801618146}
1618677801.780805: {"topic":"orderBookL2_25.BTCUSD","type":"delta","data":{"delete":[{"price":"60606.00","symbol":"BTCUSD","id":606060000,"side":"Buy"}],"update":[],"insert":[{"price":"60605.50","symbol":"BTCUSD","id":606055000,"side":"Buy","size":116695}],"transactTimeE6":0},"cross_seq":5938957590,"timestamp_e6":1618677801697359}
1618677801.801034: {"topic":"orderBookL2_25.EOSUSD","type":"delta","data":{"delete":[],"update":[{"price":"7.978","symbol":"EOSUSD","id":79780,"side":"Sell","size":39229}],"insert":[],"transactTimeE6":0},"cross_seq":1225778211,"timestamp_e6":1618677801718111}
1618677801.80108: {"topic":"orderBookL2_25.BTCUSD","type":"delta","data":{"delete":[],"update":[{"price":"60622.50","symbol":"BTCUSD","id":606225000,"side":"Buy","size":10749568}],"insert":[],"transactTimeE6":0},"cross_seq":5938957592,"timestamp_e6":1618677801717981}
1618677801.821331: {"topic":"orderBookL2_25.EOSUSD","type":"delta","data":{"delete":[],"update":[{"price":"7.978","symbol":"EOSUSD","id":79780,"side":"Sell","size":52960}],"insert":[],"transactTimeE6":0},"cross_seq":1225778212,"timestamp_e6":1618677801738110}
1618677801.8213792: {"topic":"orderBookL2_25.BTCUSD","type":"delta","data":{"delete":[],"update":[{"price":"60618.00","symbol":"BTCUSD","id":606180000,"side":"Buy","size":873},{"price":"60622.50","symbol":"BTCUSD","id":606225000,"side":"Buy","size":10613233}],"insert":[],"transactTimeE6":0},"cross_seq":5938957594,"timestamp_e6":1618677801737968}
1618677801.9026718: {"topic":"orderBookL2_25.EOSUSD","type":"delta","data":{"delete":[],"update":[{"price":"7.982","symbol":"EOSUSD","id":79820,"side":"Sell","size":138428},{"price":"7.981","symbol":"EOSUSD","id":79810,"side":"Sell","size":55398}],"insert":[],"transactTimeE6":0},"cross_seq":1225778214,"timestamp_e6":1618677801818109}
1618677801.9407492: {"topic":"orderBookL2_25.BTCUSD","type":"delta","data":{"delete":[],"update":[{"price":"60623.00","symbol":"BTCUSD","id":606230000,"side":"Sell","size":2477304}],"insert":[],"transactTimeE6":0},"cross_seq":5938957598,"timestamp_e6":1618677801858008}
1618677802.0218801: {"topic":"orderBookL2_25.EOSUSD","type":"delta","data":{"delete":[],"update":[{"price":"7.959","symbol":"EOSUSD","id":79590,"side":"Buy","size":20220},{"price":"7.985","symbol":"EOSUSD","id":79850,"side":"Sell","size":43848},{"price":"7.961","symbol":"EOSUSD","id":79610,"side":"Buy","size":10370},{"price":"7.962","symbol":"EOSUSD","id":79620,"side":"Buy","size":39457},{"price":"7.983","symbol":"EOSUSD","id":79830,"side":"Sell","size":106629}],"insert":[],"transactTimeE6":0},"cross_seq":1225778220,"timestamp_e6":1618677801938146}
1618677802.061565: {"topic":"orderBookL2_25.BTCUSD","type":"delta","data":{"delete":[],"update":[{"price":"60622.50","symbol":"BTCUSD","id":606225000,"side":"Buy","size":10613243}],"insert":[],"transactTimeE6":0},"cross_seq":5938957600,"timestamp_e6":1618677801978032}
1618677802.10169: {"topic":"orderBookL2_25.BTCUSD","type":"delta","data":{"delete":[],"update":[{"price":"60622.50","symbol":"BTCUSD","id":606225000,"side":"Buy","size":10613233}],"insert":[],"transactTimeE6":0},"cross_seq":5938957602,"timestamp_e6":1618677802017974}
1618677802.161825: {"topic":"orderBookL2_25.EOSUSD","type":"delta","data":{"delete":[],"update":[{"price":"7.961","symbol":"EOSUSD","id":79610,"side":"Buy","size":18016},{"price":"7.972","symbol":"EOSUSD","id":79720,"side":"Buy","size":138863},{"price":"7.960","symbol":"EOSUSD","id":79600,"side":"Buy","size":37686},{"price":"7.959","symbol":"EOSUSD","id":79590,"side":"Buy","size":24674}],"insert":[],"transactTimeE6":0},"cross_seq":1225778224,"timestamp_e6":1618677802078716}
1618677802.202136: {"topic":"orderBookL2_25.EOSUSD","type":"delta","data":{"delete":[],"update":[{"price":"7.978","symbol":"EOSUSD","id":79780,"side":"Sell","size":27311}],"insert":[],"transactTimeE6":0},"cross_seq":1225778225,"timestamp_e6":1618677802118211}
1618677802.2419572: {"topic":"orderBookL2_25.EOSUSD","type":"delta","data":{"delete":[],"update":[{"price":"7.972","symbol":"EOSUSD","id":79720,"side":"Buy","size":134863}],"insert":[],"transactTimeE6":0},"cross_seq":1225778226,"timestamp_e6":1618677802159039}
1618677802.2622259: {"topic":"orderBookL2_25.BTCUSD","type":"delta","data":{"delete":[{"price":"60605.50","symbol":"BTCUSD","id":606055000,"side":"Buy"}],"update":[],"insert":[{"price":"60606.50","symbol":"BTCUSD","id":606065000,"side":"Buy","size":4394}],"transactTimeE6":0},"cross_seq":5938957607,"timestamp_e6":1618677802177364}
1618677802.341363: {"topic":"orderBookL2_25.EOSUSD","type":"delta","data":{"delete":[],"update":[{"price":"7.978","symbol":"EOSUSD","id":79780,"side":"Sell","size":54229},{"price":"7.964","symbol":"EOSUSD","id":79640,"side":"Buy","size":42085}],"insert":[],"transactTimeE6":0},"cross_seq":1225778228,"timestamp_e6":1618677802258176}
1618677802.401698: {"topic":"orderBookL2_25.BTCUSD","type":"delta","data":{"delete":[],"update":[{"price":"60623.00","symbol":"BTCUSD","id":606230000,"side":"Sell","size":2476227}],"insert":[],"transactTimeE6":0},"cross_seq":5938957612,"timestamp_e6":1618677802318000}
1618677802.4214442: {"topic":"orderBookL2_25.BTCUSD","type":"delta","data":{"delete":[],"update":[{"price":"60622.50","symbol":"BTCUSD","id":606225000,"side":"Buy","size":10613243}],"insert":[],"transactTimeE6":0},"cross_seq":5938957613,"timestamp_e6":1618677802338128}
1618677802.4564748: {"topic":"trade.BTCUSD","data":[{"trade_time_ms":1618677802294,"timestamp":"2021-04-17T16:43:22.000Z","symbol":"BTCUSD","side":"Buy","size":1077,"price":60623,"tick_direction":"ZeroPlusTick","trade_id":"7c83693a-bd0e-589c-8a38-16946bf6eed2","cross_seq":5938957613}]}
1618677802.461602: {"topic":"orderBookL2_25.EOSUSD","type":"delta","data":{"delete":[],"update":[{"price":"7.964","symbol":"EOSUSD","id":79640,"side":"Buy","size":51516},{"price":"7.978","symbol":"EOSUSD","id":79780,"side":"Sell","size":40670}],"insert":[],"transactTimeE6":0},"cross_seq":1225778231,"timestamp_e6":1618677802378116}
1618677802.4811368: {"topic":"orderBookL2_25.BTCUSD","type":"delta","data":{"delete":[],"update":[{"price":"60622.50","symbol":"BTCUSD","id":606225000,"side":"Buy","size":10738880}],"insert":[],"transactTimeE6":0},"cross_seq":5938957616,"timestamp_e6":1618677802398094}
1618677802.541058: {"topic":"orderBookL2_25.EOSUSD","type":"delta","data":{"delete":[],"update":[{"price":"7.964","symbol":"EOSUSD","id":79640,"side":"Buy","size":39670}],"insert":[],"transactTimeE6":0},"cross_seq":1225778232,"timestamp_e6":1618677802458112}
1618677802.5835772: {"topic":"orderBookL2_25.EOSUSD","type":"delta","data":{"delete":[{"price":"7.966","symbol":"EOSUSD","id":79660,"side":"Buy"}],"update":[{"price":"7.978","symbol":"EOSUSD","id":79780,"side":"Sell","size":26939},{"price":"7.967","symbol":"EOSUSD","id":79670,"side":"Buy","size":12325},{"price":"7.981","symbol":"EOSUSD","id":79810,"side":"Sell","size":44538},{"price":"7.965","symbol":"EOSUSD","id":79650,"side":"Buy","size":53210},{"price":"7.980","symbol":"EOSUSD","id":79800,"side":"Sell","size":110926},{"price":"7.964","symbol":"EOSUSD","id":79640,"side":"Buy","size":36518}],"insert":[{"price":"7.945","symbol":"EOSUSD","id":79450,"side":"Buy","size":19617}],"transactTimeE6":0},"cross_seq":1225778239,"timestamp_e6":1618677802498106}
1618677802.602371: {"topic":"orderBookL2_25.BTCUSD","type":"delta","data":{"delete":[],"update":[{"price":"60623.00","symbol":"BTCUSD","id":606230000,"side":"Sell","size":2476137}],"insert":[],"transactTimeE6":0},"cross_seq":5938957631,"timestamp_e6":1618677802518048}
1618677802.659339: {"topic":"trade.BTCUSD","data":[{"trade_time_ms":1618677802493,"timestamp":"2021-04-17T16:43:22.000Z","symbol":"BTCUSD","side":"Buy","size":90,"price":60623,"tick_direction":"ZeroPlusTick","trade_id":"08ef255d-8011-58c0-8631-bc16434a6ec9","cross_seq":5938957642}]}
1618677802.6612759: {"topic":"orderBookL2_25.BTCUSD","type":"delta","data":{"delete":[],"update":[{"price":"60622.50","symbol":"BTCUSD","id":606225000,"side":"Buy","size":10738870}],"insert":[],"transactTimeE6":0},"cross_seq":5938957642,"timestamp_e6":1618677802578143}
1618677802.681694: {"topic":"orderBookL2_25.BTCUSD","type":"delta","data":{"delete":[],"update":[{"price":"60623.00","symbol":"BTCUSD","id":606230000,"side":"Sell","size":2485437}],"insert":[],"transactTimeE6":0},"cross_seq":5938957643,"timestamp_e6":1618677802597954}
1618677802.722241: {"topic":"orderBookL2_25.EOSUSD","type":"delta","data":{"delete":[{"price":"7.969","symbol":"EOSUSD","id":79690,"side":"Buy"}],"update":[{"price":"7.967","symbol":"EOSUSD","id":79670,"side":"Buy","size":17029},{"price":"7.965","symbol":"EOSUSD","id":79650,"side":"Buy","size":56440},{"price":"7.980","symbol":"EOSUSD","id":79800,"side":"Sell","size":127012},{"price":"7.981","symbol":"EOSUSD","id":79810,"side":"Sell","size":48069},{"price":"7.978","symbol":"EOSUSD","id":79780,"side":"Sell","size":37421},{"price":"7.968","symbol":"EOSUSD","id":79680,"side":"Buy","size":87975}],"insert":[{"price":"7.966","symbol":"EOSUSD","id":79660,"side":"Buy","size":8464}],"transactTimeE6":0},"cross_seq":1225778248,"timestamp_e6":1618677802638103}
1618677802.722304: {"topic":"orderBookL2_25.BTCUSD","type":"delta","data":{"delete":[],"update":[{"price":"60623.00","symbol":"BTCUSD","id":606230000,"side":"Sell","size":2442647}],"insert":[],"transactTimeE6":0},"cross_seq":5938957644,"timestamp_e6":1618677802638036}
1618677802.7572448: {"topic":"trade.BTCUSD","data":[{"trade_time_ms":1618677802613,"timestamp":"2021-04-17T16:43:22.000Z","symbol":"BTCUSD","side":"Buy","size":6482,"price":60623,"tick_direction":"ZeroPlusTick","trade_id":"5be93c0c-6b5a-5456-b17a-c20f45d56188","cross_seq":5938957645},{"trade_time_ms":1618677802613,"timestamp":"2021-04-17T16:43:22.000Z","symbol":"BTCUSD","side":"Buy","size":36308,"price":60623,"tick_direction":"ZeroPlusTick","trade_id":"89c4f27e-9978-52a3-a166-0019c03877f4","cross_seq":5938957645}]}
1618677802.80169: {"topic":"orderBookL2_25.EOSUSD","type":"delta","data":{"delete":[],"update":[{"price":"7.964","symbol":"EOSUSD","id":79640,"side":"Buy","size":47855}],"insert":[],"transactTimeE6":0},"cross_seq":1225778249,"timestamp_e6":1618677802718124}
1618677802.841553: {"topic":"orderBookL2_25.EOSUSD","type":"delta","data":{"delete":[{"price":"7.945","symbol":"EOSUSD","id":79450,"side":"Buy"}],"update":[{"price":"7.968","symbol":"EOSUSD","id":79680,"side":"Buy","size":108077},{"price":"7.972","symbol":"EOSUSD","id":79720,"side":"Buy","size":138863}],"insert":[{"price":"7.969","symbol":"EOSUSD","id":79690,"side":"Buy","size":36416}],"transactTimeE6":0},"cross_seq":1225778252,"timestamp_e6":1618677802758902}
1618677802.880974: {"topic":"orderBookL2_25.EOSUSD","type":"delta","data":{"delete":[],"update":[{"price":"7.981","symbol":"EOSUSD","id":79810,"side":"Sell","size":35524},{"price":"7.977","symbol":"EOSUSD","id":79770,"side":"Sell","size":33590}],"insert":[],"transactTimeE6":0},"cross_seq":1225778254,"timestamp_e6":1618677802798119}
1618677802.901361: {"topic":"orderBookL2_25.EOSUSD","type":"delta","data":{"delete":[],"update":[{"price":"7.959","symbol":"EOSUSD","id":79590,"side":"Buy","size":24687}],"insert":[],"transactTimeE6":0},"cross_seq":1225778255,"timestamp_e6":1618677802818109}
1618677802.921865: {"topic":"orderBookL2_25.EOSUSD","type":"delta","data":{"delete":[],"update":[{"price":"7.972","symbol":"EOSUSD","id":79720,"side":"Buy","size":134863}],"insert":[],"transactTimeE6":0},"cross_seq":1225778256,"timestamp_e6":1618677802838735}
1618677802.980447: {"topic":"orderBookL2_25.EOSUSD","type":"delta","data":{"delete":[],"update":[{"price":"7.981","symbol":"EOSUSD","id":79810,"side":"Sell","size":45173},{"price":"7.977","symbol":"EOSUSD","id":79770,"side":"Sell","size":43315}],"insert":[],"transactTimeE6":0},"cross_seq":1225778258,"timestamp_e6":1618677802898151}
1618677803.0022058: {"topic":"orderBookL2_25.BTCUSD","type":"delta","data":{"delete":[],"update":[{"price":"60623.00","symbol":"BTCUSD","id":606230000,"side":"Sell","size":2442450}],"insert":[],"transactTimeE6":0},"cross_seq":5938957655,"timestamp_e6":1618677802918075}
1618677803.041069: {"topic":"orderBookL2_25.EOSUSD","type":"delta","data":{"delete":[],"update":[{"price":"7.982","symbol":"EOSUSD","id":79820,"side":"Sell","size":102547},{"price":"7.981","symbol":"EOSUSD","id":79810,"side":"Sell","size":13200},{"price":"7.962","symbol":"EOSUSD","id":79620,"side":"Buy","size":15681},{"price":"7.964","symbol":"EOSUSD","id":79640,"side":"Buy","size":20768},{"price":"7.963","symbol":"EOSUSD","id":79630,"side":"Buy","size":16792},{"price":"7.983","symbol":"EOSUSD","id":79830,"side":"Sell","size":83766},{"price":"7.980","symbol":"EOSUSD","id":79800,"side":"Sell","size":90358},{"price":"7.984","symbol":"EOSUSD","id":79840,"side":"Sell","size":93674},{"price":"7.985","symbol":"EOSUSD","id":79850,"side":"Sell","size":27474},{"price":"7.960","symbol":"EOSUSD","id":79600,"side":"Buy","size":28376}],"insert":[],"transactTimeE6":0},"cross_seq":1225778281,"timestamp_e6":1618677802958103}
1618677803.064988: {"topic":"trade.BTCUSD","data":[{"trade_time_ms":1618677802911,"timestamp":"2021-04-17T16:43:22.000Z","symbol":"BTCUSD","side":"Buy","size":197,"price":60623,"tick_direction":"ZeroPlusTick","trade_id":"4d528a7a-e662-5843-a61d-75193d055291","cross_seq":5938957656}]}
1618677803.121536: {"topic":"orderBookL2_25.BTCUSD","type":"delta","data":{"delete":[],"update":[{"price":"60624.50","symbol":"BTCUSD","id":606245000,"side":"Sell","size":109974},{"price":"60623.00","symbol":"BTCUSD","id":606230000,"side":"Sell","size":2499428},{"price":"60623.50","symbol":"BTCUSD","id":606235000,"side":"Sell","size":234565},{"price":"60625.50","symbol":"BTCUSD","id":606255000,"side":"Sell","size":80438},{"price":"60625.00","symbol":"BTCUSD","id":606250000,"side":"Sell","size":155050},{"price":"60624.00","symbol":"BTCUSD","id":606240000,"side":"Sell","size":118209}],"insert":[],"transactTimeE6":0},"cross_seq":5938957675,"timestamp_e6":1618677803038045}
1618677803.1609669: {"topic":"orderBookL2_25.BTCUSD","type":"delta","data":{"delete":[],"update":[{"price":"60623.00","symbol":"BTCUSD","id":606230000,"side":"Sell","size":2509447}],"insert":[],"transactTimeE6":0},"cross_seq":5938957676,"timestamp_e6":1618677803077902}
1618677803.1813629: {"topic":"orderBookL2_25.EOSUSD","type":"delta","data":{"delete":[],"update":[{"price":"7.962","symbol":"EOSUSD","id":79620,"side":"Buy","size":24553},{"price":"7.984","symbol":"EOSUSD","id":79840,"side":"Sell","size":95850},{"price":"7.985","symbol":"EOSUSD","id":79850,"side":"Sell","size":29880},{"price":"7.981","symbol":"EOSUSD","id":79810,"side":"Sell","size":22683},{"price":"7.964","symbol":"EOSUSD","id":79640,"side":"Buy","size":9431},{"price":"7.983","symbol":"EOSUSD","id":79830,"side":"Sell","size":92852},{"price":"7.982","symbol":"EOSUSD","id":79820,"side":"Sell","size":111571},{"price":"7.960","symbol":"EOSUSD","id":79600,"side":"Buy","size":31283},{"price":"7.961","symbol":"EOSUSD","id":79610,"side":"Buy","size":15684},{"price":"7.963","symbol":"EOSUSD","id":79630,"side":"Buy","size":26122}],"insert":[],"transactTimeE6":0},"cross_seq":1225778292,"timestamp_e6":1618677803098157}
1618677803.26193: {"topic":"orderBookL2_25.BTCUSD","type":"delta","data":{"delete":[],"update":[{"price":"60623.00","symbol":"BTCUSD","id":606230000,"side":"Sell","size":2499428}],"insert":[],"transactTimeE6":0},"cross_seq":5938957681,"timestamp_e6":1618677803177972}
1618677803.300234: {"topic":"orderBookL2_25.EOSUSD","type":"delta","data":{"delete":[],"update":[{"price":"7.964","symbol":"EOSUSD","id":79640,"side":"Buy","size":19214}],"insert":[],"transactTimeE6":0},"cross_seq":1225778293,"timestamp_e6":1618677803218086}
1618677803.421422: {"topic":"orderBookL2_25.BTCUSD","type":"delta","data":{"delete":[],"update":[{"price":"60622.50","symbol":"BTCUSD","id":606225000,"side":"Buy","size":10740870}],"insert":[],"transactTimeE6":0},"cross_seq":5938957691,"timestamp_e6":1618677803338036}
1618677803.5814981: {"topic":"orderBookL2_25.EOSUSD","type":"delta","data":{"delete":[],"update":[{"price":"7.973","symbol":"EOSUSD","id":79730,"side":"Sell","size":2535}],"insert":[],"transactTimeE6":0},"cross_seq":1225778296,"timestamp_e6":1618677803498750}
1618677803.6205812: {"topic":"orderBookL2_25.EOSUSD","type":"delta","data":{"delete":[{"price":"7.969","symbol":"EOSUSD","id":79690,"side":"Buy"}],"update":[{"price":"7.980","symbol":"EOSUSD","id":79800,"side":"Sell","size":62130},{"price":"7.979","symbol":"EOSUSD","id":79790,"side":"Sell","size":61072},{"price":"7.976","symbol":"EOSUSD","id":79760,"side":"Sell","size":14158},{"price":"7.968","symbol":"EOSUSD","id":79680,"side":"Buy","size":87975},{"price":"7.978","symbol":"EOSUSD","id":79780,"side":"Sell","size":10503},{"price":"7.981","symbol":"EOSUSD","id":79810,"side":"Sell","size":19152},{"price":"7.965","symbol":"EOSUSD","id":79650,"side":"Buy","size":43671},{"price":"7.977","symbol":"EOSUSD","id":79770,"side":"Sell","size":19035},{"price":"7.967","symbol":"EOSUSD","id":79670,"side":"Buy","size":4704}],"insert":[{"price":"7.945","symbol":"EOSUSD","id":79450,"side":"Buy","size":19617}],"transactTimeE6":0},"cross_seq":1225778312,"timestamp_e6":1618677803538180}
1618677803.640791: {"topic":"orderBookL2_25.BTCUSD","type":"delta","data":{"delete":[],"update":[{"price":"60623.00","symbol":"BTCUSD","id":606230000,"side":"Sell","size":2499418}],"insert":[],"transactTimeE6":0},"cross_seq":5938957696,"timestamp_e6":1618677803558028}
1618677803.659084: {"topic":"trade.BTCUSD","data":[{"trade_time_ms":1618677803532,"timestamp":"2021-04-17T16:43:23.000Z","symbol":"BTCUSD","side":"Buy","size":10,"price":60623,"tick_direction":"ZeroPlusTick","trade_id":"b1cad3bf-c6bf-5e11-9da7-dcbcaccbe8a2","cross_seq":5938957696}]}
1618677803.6610901: {"topic":"trade.EOSUSD","data":[{"trade_time_ms":1618677803486,"timestamp":"2021-04-17T16:43:23.000Z","symbol":"EOSUSD","side":"Buy","size":1291,"price":7.973,"tick_direction":"ZeroPlusTick","trade_id":"958f857f-c0bc-5c86-af76-d3558a0e5443","cross_seq":1225778312},{"trade_time_ms":1618677803486,"timestamp":"2021-04-17T16:43:23.000Z","symbol":"EOSUSD","side":"Buy","size":5702,"price":7.973,"tick_direction":"ZeroPlusTick","trade_id":"b4972fbf-eecf-56c9-90c4-b70251183ff9","cross_seq":1225778312},{"trade_time_ms":1618677803486,"timestamp":"2021-04-17T16:43:23.000Z","symbol":"EOSUSD","side":"Buy","size":5100,"price":7.973,"tick_direction":"ZeroPlusTick","trade_id":"2428175b-3f51-5d73-a195-a73f08792fe2","cross_seq":1225778312}]}
1618677803.6631858: {"topic":"orderBookL2_25.BTCUSD","type":"delta","data":{"delete":[],"update":[{"price":"60623.00","symbol":"BTCUSD","id":606230000,"side":"Sell","size":2491418}],"insert":[],"transactTimeE6":0},"cross_seq":5938957697,"timestamp_e6":1618677803578044}
1618677803.680832: {"topic":"orderBookL2_25.EOSUSD","type":"delta","data":{"delete":[],"update":[{"price":"7.980","symbol":"EOSUSD","id":79800,"side":"Sell","size":51991}],"insert":[],"transactTimeE6":0},"cross_seq":1225778313,"timestamp_e6":1618677803598178}
1618677803.7411258: {"topic":"orderBookL2_25.EOSUSD","type":"delta","data":{"delete":[{"price":"7.945","symbol":"EOSUSD","id":79450,"side":"Buy"}],"update":[{"price":"7.965","symbol":"EOSUSD","id":79650,"side":"Buy","size":50706},{"price":"7.977","symbol":"EOSUSD","id":79770,"side":"Sell","size":9770},{"price":"7.980","symbol":"EOSUSD","id":79800,"side":"Sell","size":61460},{"price":"7.968","symbol":"EOSUSD","id":79680,"side":"Buy","size":102043},{"price":"7.976","symbol":"EOSUSD","id":79760,"side":"Sell","size":23090},{"price":"7.967","symbol":"EOSUSD","id":79670,"side":"Buy","size":12232}],"insert":[{"price":"7.969","symbol":"EOSUSD","id":79690,"side":"Buy","size":20743}],"transactTimeE6":0},"cross_seq":1225778320,"timestamp_e6":1618677803658088}
1618677803.755923: {"topic":"trade.BTCUSD","data":[{"trade_time_ms":1618677803569,"timestamp":"2021-04-17T16:43:23.000Z","symbol":"BTCUSD","side":"Buy","size":8000,"price":60623,"tick_direction":"ZeroPlusTick","trade_id":"cee75f3d-e319-538e-b717-66b2d6f22dd5","cross_seq":5938957699},{"trade_time_ms":1618677803652,"timestamp":"2021-04-17T16:43:23.000Z","symbol":"BTCUSD","side":"Buy","size":6175,"price":60623,"tick_direction":"ZeroPlusTick","trade_id":"1ab91f89-103c-55bf-a894-6516bd4670b2","cross_seq":5938957699},{"trade_time_ms":1618677803652,"timestamp":"2021-04-17T16:43:23.000Z","symbol":"BTCUSD","side":"Buy","size":13930,"price":60623,"tick_direction":"ZeroPlusTick","trade_id":"b984a6ca-bec0-56bb-a9a8-24f3c4b9ee61","cross_seq":5938957699}]}
1618677803.761367: {"topic":"orderBookL2_25.BTCUSD","type":"delta","data":{"delete":[],"update":[{"price":"60623.00","symbol":"BTCUSD","id":606230000,"side":"Sell","size":2471313}],"insert":[],"transactTimeE6":0},"cross_seq":5938957699,"timestamp_e6":1618677803678279}
1618677803.8205209: {"topic":"orderBookL2_25.EOSUSD","type":"delta","data":{"delete":[],"update":[{"price":"7.980","symbol":"EOSUSD","id":79800,"side":"Sell","size":71026}],"insert":[],"transactTimeE6":0},"cross_seq":1225778321,"timestamp_e6":1618677803738139}
1618677803.840914: {"topic":"orderBookL2_25.EOSUSD","type":"delta","data":{"delete":[],"update":[{"price":"7.972","symbol":"EOSUSD","id":79720,"side":"Buy","size":134665}],"insert":[],"transactTimeE6":0},"cross_seq":1225778322,"timestamp_e6":1618677803758896}
1618677803.85703: {"topic":"trade.EOSUSD","data":[{"trade_time_ms":1618677803739,"timestamp":"2021-04-17T16:43:23.000Z","symbol":"EOSUSD","side":"Sell","size":198,"price":7.972,"tick_direction":"MinusTick","trade_id":"cf67d616-04b6-59fe-8937-45da842e0164","cross_seq":1225778322}]}
1618677803.861255: {"topic":"orderBookL2_25.BTCUSD","type":"delta","data":{"delete":[],"update":[{"price":"60622.50","symbol":"BTCUSD","id":606225000,"side":"Buy","size":10740874}],"insert":[],"transactTimeE6":0},"cross_seq":5938957702,"timestamp_e6":1618677803778017}
1618677803.8612852: {"topic":"orderBookL2_25.EOSUSD","type":"delta","data":{"delete":[],"update":[{"price":"7.966","symbol":"EOSUSD","id":79660,"side":"Buy","size":10962},{"price":"7.977","symbol":"EOSUSD","id":79770,"side":"Sell","size":18091}],"insert":[],"transactTimeE6":0},"cross_seq":1225778324,"timestamp_e6":1618677803778128}
1618677803.881542: {"topic":"orderBookL2_25.BTCUSD","type":"delta","data":{"delete":[],"update":[{"price":"60623.00","symbol":"BTCUSD","id":606230000,"side":"Sell","size":2470754}],"insert":[],"transactTimeE6":0},"cross_seq":5938957703,"timestamp_e6":1618677803798094}
1618677803.882474: {"topic":"orderBookL2_25.EOSUSD","type":"delta","data":{"delete":[{"price":"7.967","symbol":"EOSUSD","id":79670,"side":"Buy"},{"price":"7.969","symbol":"EOSUSD","id":79690,"side":"Buy"}],"update":[{"price":"7.968","symbol":"EOSUSD","id":79680,"side":"Buy","size":87975},{"price":"7.963","symbol":"EOSUSD","id":79630,"side":"Buy","size":13629},{"price":"7.964","symbol":"EOSUSD","id":79640,"side":"Buy","size":23235},{"price":"7.972","symbol":"EOSUSD","id":79720,"side":"Buy","size":133050},{"price":"7.966","symbol":"EOSUSD","id":79660,"side":"Buy","size":21719},{"price":"7.965","symbol":"EOSUSD","id":79650,"side":"Buy","size":54902}],"insert":[{"price":"7.945","symbol":"EOSUSD","id":79450,"side":"Buy","size":19617},{"price":"7.970","symbol":"EOSUSD","id":79700,"side":"Buy","size":1615}],"transactTimeE6":0},"cross_seq":1225778333,"timestamp_e6":1618677803798700}
1618677803.901002: {"topic":"orderBookL2_25.BTCUSD","type":"delta","data":{"delete":[],"update":[{"price":"60632.50","symbol":"BTCUSD","id":606325000,"side":"Sell","size":8251}],"insert":[],"transactTimeE6":0},"cross_seq":5938957706,"timestamp_e6":1618677803817434}
1618677803.901032: {"topic":"orderBookL2_25.EOSUSD","type":"delta","data":{"delete":[],"update":[{"price":"7.975","symbol":"EOSUSD","id":79750,"side":"Sell","size":3385},{"price":"7.973","symbol":"EOSUSD","id":79730,"side":"Sell","size":8142}],"insert":[],"transactTimeE6":0},"cross_seq":1225778336,"timestamp_e6":1618677803818764}
1618677803.921785: {"topic":"orderBookL2_25.BTCUSD","type":"delta","data":{"delete":[],"update":[{"price":"60623.00","symbol":"BTCUSD","id":606230000,"side":"Sell","size":2461404}],"insert":[],"transactTimeE6":0},"cross_seq":5938957707,"timestamp_e6":1618677803838030}
1618677803.95606: {"topic":"trade.BTCUSD","data":[{"trade_time_ms":1618677803777,"timestamp":"2021-04-17T16:43:23.000Z","symbol":"BTCUSD","side":"Buy","size":559,"price":60623,"tick_direction":"ZeroPlusTick","trade_id":"de78e660-4153-51c0-b591-074194b94761","cross_seq":5938957711},{"trade_time_ms":1618677803810,"timestamp":"2021-04-17T16:43:23.000Z","symbol":"BTCUSD","side":"Buy","size":9350,"price":60623,"tick_direction":"ZeroPlusTick","trade_id":"af43e36e-bc07-518a-acf9-00c79ab7d987","cross_seq":5938957711}]}
1618677803.961761: {"topic":"orderBookL2_25.BTCUSD","type":"delta","data":{"delete":[],"update":[{"price":"60618.00","symbol":"BTCUSD","id":606180000,"side":"Buy","size":870}],"insert":[],"transactTimeE6":0},"cross_seq":5938957711,"timestamp_e6":1618677803877453}
1618677803.982272: {"topic":"orderBookL2_25.EOSUSD","type":"delta","data":{"delete":[{"price":"7.975","symbol":"EOSUSD","id":79750,"side":"Sell"}],"update":[{"price":"7.973","symbol":"EOSUSD","id":79730,"side":"Sell","size":11527}],"insert":[{"price":"7.999","symbol":"EOSUSD","id":79990,"side":"Sell","size":103799}],"transactTimeE6":0},"cross_seq":1225778337,"timestamp_e6":1618677803898764}
1618677804.000302: {"topic":"orderBookL2_25.EOSUSD","type":"delta","data":{"delete":[],"update":[{"price":"7.963","symbol":"EOSUSD","id":79630,"side":"Buy","size":20317}],"insert":[],"transactTimeE6":0},"cross_seq":1225778338,"timestamp_e6":1618677803918118}
1618677804.081496: {"topic":"orderBookL2_25.EOSUSD","type":"delta","data":{"delete":[],"update":[{"price":"7.982","symbol":"EOSUSD","id":79820,"side":"Sell","size":119592},{"price":"7.980","symbol":"EOSUSD","id":79800,"side":"Sell","size":91969},{"price":"7.983","symbol":"EOSUSD","id":79830,"side":"Sell","size":102011},{"price":"7.981","symbol":"EOSUSD","id":79810,"side":"Sell","size":35677},{"price":"7.961","symbol":"EOSUSD","id":79610,"side":"Buy","size":22229},{"price":"7.963","symbol":"EOSUSD","id":79630,"side":"Buy","size":34251},{"price":"7.964","symbol":"EOSUSD","id":79640,"side":"Buy","size":46923},{"price":"7.962","symbol":"EOSUSD","id":79620,"side":"Buy","size":35146}],"insert":[],"transactTimeE6":0},"cross_seq":1225778348,"timestamp_e6":1618677803998095}
1618677804.22193: {"topic":"orderBookL2_25.BTCUSD","type":"delta","data":{"delete":[],"update":[{"price":"60623.00","symbol":"BTCUSD","id":606230000,"side":"Sell","size":2448756}],"insert":[],"transactTimeE6":0},"cross_seq":5938957728,"timestamp_e6":1618677804138031}
1618677804.2219992: {"topic":"orderBookL2_25.EOSUSD","type":"delta","data":{"delete":[],"update":[{"price":"7.981","symbol":"EOSUSD","id":79810,"side":"Sell","size":26194}],"insert":[],"transactTimeE6":0},"cross_seq":1225778350,"timestamp_e6":1618677804138117}
1618677804.2577689: {"topic":"trade.BTCUSD","data":[{"trade_time_ms":1618677804112,"timestamp":"2021-04-17T16:43:24.000Z","symbol":"BTCUSD","side":"Buy","size":12648,"price":60623,"tick_direction":"ZeroPlusTick","trade_id":"6bc7d0b5-f24b-5d74-8cb7-bf77584ab176","cross_seq":5938957728}]}
1618677804.2628942: {"topic":"orderBookL2_25.EOSUSD","type":"delta","data":{"delete":[{"price":"7.970","symbol":"EOSUSD","id":79700,"side":"Buy"}],"update":[{"price":"7.972","symbol":"EOSUSD","id":79720,"side":"Buy","size":134665}],"insert":[{"price":"7.944","symbol":"EOSUSD","id":79440,"side":"Buy","size":114534}],"transactTimeE6":0},"cross_seq":1225778351,"timestamp_e6":1618677804178741}
1618677804.320931: {"topic":"orderBookL2_25.EOSUSD","type":"delta","data":{"delete":[],"update":[{"price":"7.981","symbol":"EOSUSD","id":79810,"side":"Sell","size":35705},{"price":"7.980","symbol":"EOSUSD","id":79800,"side":"Sell","size":82403},{"price":"7.960","symbol":"EOSUSD","id":79600,"side":"Buy","size":34074}],"insert":[],"transactTimeE6":0},"cross_seq":1225778354,"timestamp_e6":1618677804238106}
1618677804.341457: {"topic":"orderBookL2_25.EOSUSD","type":"delta","data":{"delete":[],"update":[{"price":"7.972","symbol":"EOSUSD","id":79720,"side":"Buy","size":138665}],"insert":[],"transactTimeE6":0},"cross_seq":1225778355,"timestamp_e6":1618677804258727}
1618677804.360944: {"topic":"orderBookL2_25.EOSUSD","type":"delta","data":{"delete":[],"update":[{"price":"7.973","symbol":"EOSUSD","id":79730,"side":"Sell","size":10920}],"insert":[],"transactTimeE6":0},"cross_seq":1225778356,"timestamp_e6":1618677804278746}
1618677804.401472: {"topic":"orderBookL2_25.BTCUSD","type":"delta","data":{"delete":[],"update":[{"price":"60618.00","symbol":"BTCUSD","id":606180000,"side":"Buy","size":873}],"insert":[],"transactTimeE6":0},"cross_seq":5938957738,"timestamp_e6":1618677804317331}
1618677804.424535: {"topic":"orderBookL2_25.EOSUSD","type":"delta","data":{"delete":[{"price":"7.999","symbol":"EOSUSD","id":79990,"side":"Sell"}],"update":[{"price":"7.973","symbol":"EOSUSD","id":79730,"side":"Sell","size":5920}],"insert":[{"price":"7.975","symbol":"EOSUSD","id":79750,"side":"Sell","size":5000}],"transactTimeE6":0},"cross_seq":1225778358,"timestamp_e6":1618677804338763}
1618677804.441507: {"topic":"orderBookL2_25.EOSUSD","type":"delta","data":{"delete":[],"update":[{"price":"7.975","symbol":"EOSUSD","id":79750,"side":"Sell","size":8385},{"price":"7.973","symbol":"EOSUSD","id":79730,"side":"Sell","size":2535}],"insert":[],"transactTimeE6":0},"cross_seq":1225778359,"timestamp_e6":1618677804358721}
1618677804.521724: {"topic":"orderBookL2_25.EOSUSD","type":"delta","data":{"delete":[],"update":[{"price":"7.962","symbol":"EOSUSD","id":79620,"side":"Buy","size":41906},{"price":"7.963","symbol":"EOSUSD","id":79630,"side":"Buy","size":42281},{"price":"7.961","symbol":"EOSUSD","id":79610,"side":"Buy","size":27795},{"price":"7.965","symbol":"EOSUSD","id":79650,"side":"Buy","size":66971},{"price":"7.964","symbol":"EOSUSD","id":79640,"side":"Buy","size":52220},{"price":"7.966","symbol":"EOSUSD","id":79660,"side":"Buy","size":32294},{"price":"7.979","symbol":"EOSUSD","id":79790,"side":"Sell","size":67635},{"price":"7.976","symbol":"EOSUSD","id":79760,"side":"Sell","size":30863},{"price":"7.978","symbol":"EOSUSD","id":79780,"side":"Sell","size":14362}],"insert":[],"transactTimeE6":0},"cross_seq":1225778368,"timestamp_e6":1618677804438120}
1618677804.560408: {"topic":"orderBookL2_25.EOSUSD","type":"delta","data":{"delete":[],"update":[{"price":"7.968","symbol":"EOSUSD","id":79680,"side":"Buy","size":87895}],"insert":[],"transactTimeE6":0},"cross_seq":1225778369,"timestamp_e6":1618677804478111}
1618677804.621669: {"topic":"orderBookL2_25.BTCUSD","type":"delta","data":{"delete":[],"update":[{"price":"60623.00","symbol":"BTCUSD","id":606230000,"side":"Sell","size":2448746}],"insert":[],"transactTimeE6":0},"cross_seq":5938957742,"timestamp_e6":1618677804538356}
1618677804.6411982: {"topic":"orderBookL2_25.EOSUSD","type":"delta","data":{"delete":[],"update":[{"price":"7.977","symbol":"EOSUSD","id":79770,"side":"Sell","size":23946}],"insert":[],"transactTimeE6":0},"cross_seq":1225778371,"timestamp_e6":1618677804558113}
1618677804.65521: {"topic":"trade.BTCUSD","data":[{"trade_time_ms":1618677804529,"timestamp":"2021-04-17T16:43:24.000Z","symbol":"BTCUSD","side":"Buy","size":10,"price":60623,"tick_direction":"ZeroPlusTick","trade_id":"2d7a6d61-8cd4-569c-b981-61602bde0cb1","cross_seq":5938957743}]}
1618677804.7810361: {"topic":"orderBookL2_25.EOSUSD","type":"delta","data":{"delete":[],"update":[{"price":"7.958","symbol":"EOSUSD","id":79580,"side":"Buy","size":30306},{"price":"7.962","symbol":"EOSUSD","id":79620,"side":"Buy","size":53906}],"insert":[],"transactTimeE6":0},"cross_seq":1225778375,"timestamp_e6":1618677804698169}
1618677804.800162: {"topic":"orderBookL2_25.EOSUSD","type":"delta","data":{"delete":[],"update":[{"price":"7.944","symbol":"EOSUSD","id":79440,"side":"Buy","size":106734}],"insert":[],"transactTimeE6":0},"cross_seq":1225778377,"timestamp_e6":1618677804718055}
1618677804.863147: {"topic":"orderBookL2_25.EOSUSD","type":"delta","data":{"delete":[{"price":"7.973","symbol":"EOSUSD","id":79730,"side":"Sell"}],"update":[],"insert":[{"price":"7.999","symbol":"EOSUSD","id":79990,"side":"Sell","size":103799}],"transactTimeE6":0},"cross_seq":1225778378,"timestamp_e6":1618677804778794}
1618677804.882453: {"topic":"orderBookL2_25.EOSUSD","type":"delta","data":{"delete":[{"price":"7.944","symbol":"EOSUSD","id":79440,"side":"Buy"}],"update":[{"price":"7.975","symbol":"EOSUSD","id":79750,"side":"Sell","size":11725},{"price":"7.972","symbol":"EOSUSD","id":79720,"side":"Buy","size":110983}],"insert":[{"price":"7.974","symbol":"EOSUSD","id":79740,"side":"Buy","size":38484}],"transactTimeE6":0},"cross_seq":1225778386,"timestamp_e6":1618677804799374}
1618677804.901858: {"topic":"orderBookL2_25.EOSUSD","type":"delta","data":{"delete":[{"price":"7.945","symbol":"EOSUSD","id":79450,"side":"Buy"}],"update":[{"price":"7.974","symbol":"EOSUSD","id":79740,"side":"Buy","size":53484},{"price":"7.972","symbol":"EOSUSD","id":79720,"side":"Buy","size":95983}],"insert":[{"price":"7.973","symbol":"EOSUSD","id":79730,"side":"Buy","size":13333}],"transactTimeE6":0},"cross_seq":1225778389,"timestamp_e6":1618677804818696}
1618677804.921344: {"topic":"orderBookL2_25.BTCUSD","type":"delta","data":{"delete":[],"update":[{"price":"60623.00","symbol":"BTCUSD","id":606230000,"side":"Sell","size":2518010},{"price":"60624.00","symbol":"BTCUSD","id":606240000,"side":"Sell","size":168546},{"price":"60625.00","symbol":"BTCUSD","id":606250000,"side":"Sell","size":136960},{"price":"60624.50","symbol":"BTCUSD","id":606245000,"side":"Sell","size":167203},{"price":"60625.50","symbol":"BTCUSD","id":606255000,"side":"Sell","size":131963}],"insert":[],"transactTimeE6":0},"cross_seq":5938957784,"timestamp_e6":1618677804837974}
1618677804.922719: {"topic":"orderBookL2_25.EOSUSD","type":"delta","data":{"delete":[],"update":[{"price":"7.972","symbol":"EOSUSD","id":79720,"side":"Buy","size":61035},{"price":"7.974","symbol":"EOSUSD","id":79740,"side":"Buy","size":60099},{"price":"7.973","symbol":"EOSUSD","id":79730,"side":"Buy","size":58598}],"insert":[],"transactTimeE6":0},"cross_seq":1225778395,"timestamp_e6":1618677804838685}
1618677804.940814: {"topic":"orderBookL2_25.EOSUSD","type":"delta","data":{"delete":[],"update":[{"price":"7.972","symbol":"EOSUSD","id":79720,"side":"Buy","size":60035}],"insert":[],"transactTimeE6":0},"cross_seq":1225778396,"timestamp_e6":1618677804858131}
1618677804.944711: {"topic":"orderBookL2_25.BTCUSD","type":"delta","data":{"delete":[{"price":"60617.50","symbol":"BTCUSD","id":606175000,"side":"Buy"}],"update":[{"price":"60621.00","symbol":"BTCUSD","id":606210000,"side":"Buy","size":22819},{"price":"60617.00","symbol":"BTCUSD","id":606170000,"side":"Buy","size":100},{"price":"60623.00","symbol":"BTCUSD","id":606230000,"side":"Sell","size":1720414},{"price":"60618.50","symbol":"BTCUSD","id":606185000,"side":"Buy","size":1546},{"price":"60620.00","symbol":"BTCUSD","id":606200000,"side":"Buy","size":150},{"price":"60622.50","symbol":"BTCUSD","id":606225000,"side":"Buy","size":11220874},{"price":"60619.50","symbol":"BTCUSD","id":606195000,"side":"Buy","size":231200},{"price":"60623.50","symbol":"BTCUSD","id":606235000,"side":"Sell","size":896254},{"price":"60620.50","symbol":"BTCUSD","id":606205000,"side":"Buy","size":18},{"price":"60618.00","symbol":"BTCUSD","id":606180000,"side":"Buy","size":1396},{"price":"60616.50","symbol":"BTCUSD","id":606165000,"side":"Buy","size":19677},{"price":"60619.00","symbol":"BTCUSD","id":606190000,"side":"Buy","size":60000}],"insert":[{"price":"60605.50","symbol":"BTCUSD","id":606055000,"side":"Buy","size":116695}],"transactTimeE6":0},"cross_seq":5938957827,"timestamp_e6":1618677804858704}
1618677804.962222: {"topic":"orderBookL2_25.BTCUSD","type":"delta","data":{"delete":[],"update":[{"price":"60616.00","symbol":"BTCUSD","id":606160000,"side":"Buy","size":29758},{"price":"60623.50","symbol":"BTCUSD","id":606235000,"side":"Sell","size":234565}],"insert":[],"transactTimeE6":0},"cross_seq":5938957830,"timestamp_e6":1618677804877349}
1618677804.965447: {"topic":"orderBookL2_25.EOSUSD","type":"delta","data":{"delete":[],"update":[{"price":"7.972","symbol":"EOSUSD","id":79720,"side":"Buy","size":59935},{"price":"7.973","symbol":"EOSUSD","id":79730,"side":"Buy","size":58698}],"insert":[],"transactTimeE6":0},"cross_seq":1225778397,"timestamp_e6":1618677804878134}
1618677804.983084: {"topic":"orderBookL2_25.BTCUSD","type":"delta","data":{"delete":[],"update":[{"price":"60622.50","symbol":"BTCUSD","id":606225000,"side":"Buy","size":11700874}],"insert":[],"transactTimeE6":0},"cross_seq":5938957832,"timestamp_e6":1618677804898016}
1618677804.983124: {"topic":"orderBookL2_25.EOSUSD","type":"delta","data":{"delete":[],"update":[{"price":"7.972","symbol":"EOSUSD","id":79720,"side":"Buy","size":55935},{"price":"7.973","symbol":"EOSUSD","id":79730,"side":"Buy","size":78698}],"insert":[],"transactTimeE6":0},"cross_seq":1225778399,"timestamp_e6":1618677804898122}
1618677805.0019069: {"topic":"orderBookL2_25.BTCUSD","type":"delta","data":{"delete":[],"update":[{"price":"60622.50","symbol":"BTCUSD","id":606225000,"side":"Buy","size":12180874}],"insert":[],"transactTimeE6":0},"cross_seq":5938957834,"timestamp_e6":1618677804917962}
1618677805.001943: {"topic":"orderBookL2_25.EOSUSD","type":"delta","data":{"delete":[],"update":[{"price":"7.973","symbol":"EOSUSD","id":79730,"side":"Buy","size":58698},{"price":"7.980","symbol":"EOSUSD","id":79800,"side":"Sell","size":90128}],"insert":[],"transactTimeE6":0},"cross_seq":1225778401,"timestamp_e6":1618677804918116}
1618677805.042944: {"topic":"orderBookL2_25.BTCUSD","type":"delta","data":{"delete":[],"update":[{"price":"60623.00","symbol":"BTCUSD","id":606230000,"side":"Sell","size":1720415}],"insert":[],"transactTimeE6":0},"cross_seq":5938957835,"timestamp_e6":1618677804958013}
1618677805.043013: {"topic":"orderBookL2_25.EOSUSD","type":"delta","data":{"delete":[{"price":"7.972","symbol":"EOSUSD","id":79720,"side":"Buy"}],"update":[{"price":"7.973","symbol":"EOSUSD","id":79730,"side":"Buy","size":100}],"insert":[{"price":"7.945","symbol":"EOSUSD","id":79450,"side":"Buy","size":19617}],"transactTimeE6":0},"cross_seq":1225778404,"timestamp_e6":1618677804958130}
1618677805.063156: {"topic":"orderBookL2_25.EOSUSD","type":"delta","data":{"delete":[{"price":"7.973","symbol":"EOSUSD","id":79730,"side":"Buy"}],"update":[{"price":"7.974","symbol":"EOSUSD","id":79740,"side":"Buy","size":60199}],"insert":[{"price":"7.944","symbol":"EOSUSD","id":79440,"side":"Buy","size":106734}],"transactTimeE6":0},"cross_seq":1225778405,"timestamp_e6":1618677804978695}
1618677805.102825: {"topic":"orderBookL2_25.EOSUSD","type":"delta","data":{"delete":[],"update":[{"price":"7.974","symbol":"EOSUSD","id":79740,"side":"Buy","size":61199}],"insert":[],"transactTimeE6":0},"cross_seq":1225778406,"timestamp_e6":1618677805019017}
1618677805.126584: {"topic":"orderBookL2_25.EOSUSD","type":"delta","data":{"delete":[],"update":[{"price":"7.965","symbol":"EOSUSD","id":79650,"side":"Buy","size":26550},{"price":"7.974","symbol":"EOSUSD","id":79740,"side":"Buy","size":114641}],"insert":[],"transactTimeE6":0},"cross_seq":1225778408,"timestamp_e6":1618677805038773}
1618677805.141056: {"topic":"orderBookL2_25.BTCUSD","type":"delta","data":{"delete":[{"price":"60605.50","symbol":"BTCUSD","id":606055000,"side":"Buy"}],"update":[{"price":"60621.50","symbol":"BTCUSD","id":606215000,"side":"Buy","size":341222}],"insert":[{"price":"60606.00","symbol":"BTCUSD","id":606060000,"side":"Buy","size":56014}],"transactTimeE6":0},"cross_seq":5938957850,"timestamp_e6":1618677805057352}
1618677805.163472: {"topic":"orderBookL2_25.EOSUSD","type":"delta","data":{"delete":[],"update":[{"price":"7.974","symbol":"EOSUSD","id":79740,"side":"Buy","size":127974}],"insert":[],"transactTimeE6":0},"cross_seq":1225778409,"timestamp_e6":1618677805078739}
1618677805.20261: {"topic":"orderBookL2_25.EOSUSD","type":"delta","data":{"delete":[],"update":[{"price":"7.974","symbol":"EOSUSD","id":79740,"side":"Buy","size":131974},{"price":"7.948","symbol":"EOSUSD","id":79480,"side":"Buy","size":81257}],"insert":[],"transactTimeE6":0},"cross_seq":1225778411,"timestamp_e6":1618677805118722}
1618677805.221395: {"topic":"orderBookL2_25.BTCUSD","type":"delta","data":{"delete":[],"update":[{"price":"60630.00","symbol":"BTCUSD","id":606300000,"side":"Sell","size":77065}],"insert":[],"transactTimeE6":0},"cross_seq":5938957854,"timestamp_e6":1618677805137363}
1618677805.2414021: {"topic":"orderBookL2_25.EOSUSD","type":"delta","data":{"delete":[],"update":[{"price":"7.979","symbol":"EOSUSD","id":79790,"side":"Sell","size":27545}],"insert":[],"transactTimeE6":0},"cross_seq":1225778412,"timestamp_e6":1618677805158123}
1618677805.262354: {"topic":"orderBookL2_25.BTCUSD","type":"delta","data":{"delete":[],"update":[{"price":"60623.00","symbol":"BTCUSD","id":606230000,"side":"Sell","size":1720414}],"insert":[],"transactTimeE6":0},"cross_seq":5938957856,"timestamp_e6":1618677805178042}
1618677805.2823281: {"topic":"orderBookL2_25.EOSUSD","type":"delta","data":{"delete":[],"update":[{"price":"7.974","symbol":"EOSUSD","id":79740,"side":"Buy","size":146974}],"insert":[],"transactTimeE6":0},"cross_seq":1225778413,"timestamp_e6":1618677805198958}
1618677805.32201: {"topic":"orderBookL2_25.EOSUSD","type":"delta","data":{"delete":[],"update":[{"price":"7.975","symbol":"EOSUSD","id":79750,"side":"Sell","size":8385}],"insert":[],"transactTimeE6":0},"cross_seq":1225778415,"timestamp_e6":1618677805238743}
1618677805.3420548: {"topic":"orderBookL2_25.EOSUSD","type":"delta","data":{"delete":[],"update":[{"price":"7.975","symbol":"EOSUSD","id":79750,"side":"Sell","size":11118},{"price":"7.974","symbol":"EOSUSD","id":79740,"side":"Buy","size":142974},{"price":"7.980","symbol":"EOSUSD","id":79800,"side":"Sell","size":82403}],"insert":[],"transactTimeE6":0},"cross_seq":1225778418,"timestamp_e6":1618677805259285}
1618677805.361921: {"topic":"orderBookL2_25.BTCUSD","type":"delta","data":{"delete":[],"update":[{"price":"60622.50","symbol":"BTCUSD","id":606225000,"side":"Buy","size":12055237}],"insert":[],"transactTimeE6":0},"cross_seq":5938957872,"timestamp_e6":1618677805278056}
1618677805.3640268: {"topic":"orderBookL2_25.EOSUSD","type":"delta","data":{"delete":[],"update":[{"price":"7.975","symbol":"EOSUSD","id":79750,"side":"Sell","size":6118},{"price":"7.977","symbol":"EOSUSD","id":79770,"side":"Sell","size":28946}],"insert":[],"transactTimeE6":0},"cross_seq":1225778419,"timestamp_e6":1618677805278760}
1618677805.3817651: {"topic":"orderBookL2_25.BTCUSD","type":"delta","data":{"delete":[],"update":[{"price":"60622.50","symbol":"BTCUSD","id":606225000,"side":"Buy","size":12055247}],"insert":[],"transactTimeE6":0},"cross_seq":5938957874,"timestamp_e6":1618677805297916}
1618677805.40137: {"topic":"orderBookL2_25.BTCUSD","type":"delta","data":{"delete":[{"price":"60606.00","symbol":"BTCUSD","id":606060000,"side":"Buy"}],"update":[{"price":"60622.50","symbol":"BTCUSD","id":606225000,"side":"Buy","size":12055237}],"insert":[{"price":"60605.50","symbol":"BTCUSD","id":606055000,"side":"Buy","size":116695}],"transactTimeE6":0},"cross_seq":5938957877,"timestamp_e6":1618677805317965}
1618677805.403597: {"topic":"orderBookL2_25.EOSUSD","type":"delta","data":{"delete":[],"update":[{"price":"7.977","symbol":"EOSUSD","id":79770,"side":"Sell","size":32331},{"price":"7.975","symbol":"EOSUSD","id":79750,"side":"Sell","size":2733}],"insert":[],"transactTimeE6":0},"cross_seq":1225778420,"timestamp_e6":1618677805319298}
1618677805.421772: {"topic":"orderBookL2_25.EOSUSD","type":"delta","data":{"delete":[],"update":[{"price":"7.948","symbol":"EOSUSD","id":79480,"side":"Buy","size":73532}],"insert":[],"transactTimeE6":0},"cross_seq":1225778421,"timestamp_e6":1618677805338102}
1618677805.441335: {"topic":"orderBookL2_25.BTCUSD","type":"delta","data":{"delete":[],"update":[{"price":"60620.00","symbol":"BTCUSD","id":606200000,"side":"Buy","size":153}],"insert":[],"transactTimeE6":0},"cross_seq":5938957879,"timestamp_e6":1618677805357353}
1618677805.46149: {"topic":"orderBookL2_25.BTCUSD","type":"delta","data":{"delete":[],"update":[{"price":"60622.50","symbol":"BTCUSD","id":606225000,"side":"Buy","size":12062737}],"insert":[],"transactTimeE6":0},"cross_seq":5938957881,"timestamp_e6":1618677805377953}
1618677805.5022779: {"topic":"orderBookL2_25.BTCUSD","type":"delta","data":{"delete":[],"update":[{"price":"60622.50","symbol":"BTCUSD","id":606225000,"side":"Buy","size":12063537}],"insert":[],"transactTimeE6":0},"cross_seq":5938957893,"timestamp_e6":1618677805418118}
1618677805.542212: {"topic":"orderBookL2_25.BTCUSD","type":"delta","data":{"delete":[],"update":[{"price":"60623.00","symbol":"BTCUSD","id":606230000,"side":"Sell","size":1720334}],"insert":[],"transactTimeE6":0},"cross_seq":5938957895,"timestamp_e6":1618677805457951}
1618677805.563738: {"topic":"trade.BTCUSD","data":[{"trade_time_ms":1618677805443,"timestamp":"2021-04-17T16:43:25.000Z","symbol":"BTCUSD","side":"Buy","size":80,"price":60623,"tick_direction":"ZeroPlusTick","trade_id":"37c3dc1d-ecfe-5918-a4b8-094d02c5cfe8","cross_seq":5938957896}]}
1618677805.5822878: {"topic":"orderBookL2_25.BTCUSD","type":"delta","data":{"delete":[],"update":[{"price":"60622.50","symbol":"BTCUSD","id":606225000,"side":"Buy","size":12194571}],"insert":[],"transactTimeE6":0},"cross_seq":5938957897,"timestamp_e6":1618677805497984}
1618677805.602127: {"topic":"orderBookL2_25.BTCUSD","type":"delta","data":{"delete":[],"update":[{"price":"60623.00","symbol":"BTCUSD","id":606230000,"side":"Sell","size":1720249}],"insert":[],"transactTimeE6":0},"cross_seq":5938957898,"timestamp_e6":1618677805518007}
1618677805.640853: {"topic":"orderBookL2_25.EOSUSD","type":"delta","data":{"delete":[{"price":"7.944","symbol":"EOSUSD","id":79440,"side":"Buy"}],"update":[],"insert":[{"price":"7.969","symbol":"EOSUSD","id":79690,"side":"Buy","size":40942}],"transactTimeE6":0},"cross_seq":1225778422,"timestamp_e6":1618677805558114}
1618677805.641688: {"topic":"orderBookL2_25.BTCUSD","type":"delta","data":{"delete":[],"update":[{"price":"60623.00","symbol":"BTCUSD","id":606230000,"side":"Sell","size":1708736}],"insert":[],"transactTimeE6":0},"cross_seq":5938957901,"timestamp_e6":1618677805558046}
1618677805.654561: {"topic":"trade.BTCUSD","data":[{"trade_time_ms":1618677805509,"timestamp":"2021-04-17T16:43:25.000Z","symbol":"BTCUSD","side":"Buy","size":85,"price":60623,"tick_direction":"ZeroPlusTick","trade_id":"7af75b30-450b-5354-bd2a-5a174c61a7d1","cross_seq":5938957905},{"trade_time_ms":1618677805546,"timestamp":"2021-04-17T16:43:25.000Z","symbol":"BTCUSD","side":"Buy","size":11513,"price":60623,"tick_direction":"ZeroPlusTick","trade_id":"7392727e-9e70-5927-be5f-6d8a22bf8229","cross_seq":5938957905}]}
1618677805.701741: {"topic":"orderBookL2_25.BTCUSD","type":"delta","data":{"delete":[],"update":[{"price":"60623.00","symbol":"BTCUSD","id":606230000,"side":"Sell","size":1708737}],"insert":[],"transactTimeE6":0},"cross_seq":5938957912,"timestamp_e6":1618677805618015}
1618677805.742645: {"topic":"orderBookL2_25.BTCUSD","type":"delta","data":{"delete":[],"update":[{"price":"60622.50","symbol":"BTCUSD","id":606225000,"side":"Buy","size":12194575}],"insert":[],"transactTimeE6":0},"cross_seq":5938957913,"timestamp_e6":1618677805658063}
1618677805.762631: {"topic":"orderBookL2_25.BTCUSD","type":"delta","data":{"delete":[],"update":[{"price":"60623.00","symbol":"BTCUSD","id":606230000,"side":"Sell","size":1708736}],"insert":[],"transactTimeE6":0},"cross_seq":5938957915,"timestamp_e6":1618677805678050}
1618677805.780628: {"topic":"orderBookL2_25.BTCUSD","type":"delta","data":{"delete":[],"update":[{"price":"60623.50","symbol":"BTCUSD","id":606235000,"side":"Sell","size":954868}],"insert":[],"transactTimeE6":0},"cross_seq":5938957916,"timestamp_e6":1618677805697355}
1618677805.8006558: {"topic":"orderBookL2_25.BTCUSD","type":"delta","data":{"delete":[],"update":[{"price":"60622.50","symbol":"BTCUSD","id":606225000,"side":"Buy","size":12063541}],"insert":[],"transactTimeE6":0},"cross_seq":5938957918,"timestamp_e6":1618677805717967}
1618677805.822069: {"topic":"orderBookL2_25.BTCUSD","type":"delta","data":{"delete":[],"update":[{"price":"60622.50","symbol":"BTCUSD","id":606225000,"side":"Buy","size":12123541}],"insert":[],"transactTimeE6":0},"cross_seq":5938957922,"timestamp_e6":1618677805737971}
1618677805.8405068: {"topic":"orderBookL2_25.BTCUSD","type":"delta","data":{"delete":[{"price":"60605.50","symbol":"BTCUSD","id":606055000,"side":"Buy"}],"update":[],"insert":[{"price":"60606.00","symbol":"BTCUSD","id":606060000,"side":"Buy","size":56014}],"transactTimeE6":0},"cross_seq":5938957931,"timestamp_e6":1618677805757354}
1618677805.861578: {"topic":"orderBookL2_25.BTCUSD","type":"delta","data":{"delete":[],"update":[{"price":"60630.00","symbol":"BTCUSD","id":606300000,"side":"Sell","size":77086}],"insert":[],"transactTimeE6":0},"cross_seq":5938957934,"timestamp_e6":1618677805777388}
1618677805.861639: {"topic":"orderBookL2_25.EOSUSD","type":"delta","data":{"delete":[],"update":[{"price":"7.946","symbol":"EOSUSD","id":79460,"side":"Buy","size":104518}],"insert":[],"transactTimeE6":0},"cross_seq":1225778423,"timestamp_e6":1618677805778111}
1618677805.943647: {"topic":"orderBookL2_25.BTCUSD","type":"delta","data":{"delete":[],"update":[{"price":"60623.50","symbol":"BTCUSD","id":606235000,"side":"Sell","size":234565},{"price":"60623.00","symbol":"BTCUSD","id":606230000,"side":"Sell","size":2694394}],"insert":[],"transactTimeE6":0},"cross_seq":5938957937,"timestamp_e6":1618677805857984}
1618677806.0075462: {"topic":"orderBookL2_25.BTCUSD","type":"delta","data":{"delete":[{"price":"60635.50","symbol":"BTCUSD","id":606355000,"side":"Sell"}],"update":[],"insert":[{"price":"60626.00","symbol":"BTCUSD","id":606260000,"side":"Sell","size":60000}],"transactTimeE6":0},"cross_seq":5938957941,"timestamp_e6":1618677805917339}
1618677806.025438: {"topic":"orderBookL2_25.BTCUSD","type":"delta","data":{"delete":[{"price":"60606.00","symbol":"BTCUSD","id":606060000,"side":"Buy"}],"update":[],"insert":[{"price":"60605.50","symbol":"BTCUSD","id":606055000,"side":"Buy","size":116695}],"transactTimeE6":0},"cross_seq":5938957943,"timestamp_e6":1618677805937352}
1618677806.0442162: {"topic":"orderBookL2_25.BTCUSD","type":"delta","data":{"delete":[],"update":[{"price":"60634.00","symbol":"BTCUSD","id":606340000,"side":"Sell","size":69512}],"insert":[],"transactTimeE6":0},"cross_seq":5938957952,"timestamp_e6":1618677805957340}
1618677806.243594: {"topic":"orderBookL2_25.BTCUSD","type":"delta","data":{"delete":[],"update":[{"price":"60622.50","symbol":"BTCUSD","id":606225000,"side":"Buy","size":12123540}],"insert":[],"transactTimeE6":0},"cross_seq":5938957965,"timestamp_e6":1618677806158049}
1618677806.446413: {"topic":"orderBookL2_25.BTCUSD","type":"delta","data":{"delete":[],"update":[{"price":"60623.00","symbol":"BTCUSD","id":606230000,"side":"Sell","size":1708736},{"price":"60623.50","symbol":"BTCUSD","id":606235000,"side":"Sell","size":1147845}],"insert":[],"transactTimeE6":0},"cross_seq":5938957973,"timestamp_e6":1618677806357980}
1618677806.508897: {"topic":"orderBookL2_25.BTCUSD","type":"delta","data":{"delete":[],"update":[{"price":"60623.50","symbol":"BTCUSD","id":606235000,"side":"Sell","size":234565}],"insert":[],"transactTimeE6":0},"cross_seq":5938957974,"timestamp_e6":1618677806417401}
1618677806.568128: {"topic":"orderBookL2_25.BTCUSD","type":"delta","data":{"delete":[{"price":"60605.50","symbol":"BTCUSD","id":606055000,"side":"Buy"}],"update":[],"insert":[{"price":"60606.00","symbol":"BTCUSD","id":606060000,"side":"Buy","size":56014}],"transactTimeE6":0},"cross_seq":5938957977,"timestamp_e6":1618677806477377}
1618677806.6456351: {"topic":"orderBookL2_25.BTCUSD","type":"delta","data":{"delete":[],"update":[{"price":"60622.50","symbol":"BTCUSD","id":606225000,"side":"Buy","size":12053540}],"insert":[],"transactTimeE6":0},"cross_seq":5938957980,"timestamp_e6":1618677806557984}
1618677806.665039: {"topic":"orderBookL2_25.BTCUSD","type":"delta","data":{"delete":[{"price":"60606.00","symbol":"BTCUSD","id":606060000,"side":"Buy"}],"update":[],"insert":[{"price":"60615.00","symbol":"BTCUSD","id":606150000,"side":"Buy","size":420}],"transactTimeE6":0},"cross_seq":5938957983,"timestamp_e6":1618677806577362}
1618677806.6818938: {"topic":"orderBookL2_25.BTCUSD","type":"delta","data":{"delete":[],"update":[{"price":"60618.00","symbol":"BTCUSD","id":606180000,"side":"Buy","size":1393}],"insert":[],"transactTimeE6":0},"cross_seq":5938957984,"timestamp_e6":1618677806597327}
1618677806.723729: {"topic":"orderBookL2_25.BTCUSD","type":"delta","data":{"delete":[],"update":[{"price":"60623.00","symbol":"BTCUSD","id":606230000,"side":"Sell","size":1687539}],"insert":[],"transactTimeE6":0},"cross_seq":5938957987,"timestamp_e6":1618677806638006}
1618677806.761122: {"topic":"trade.BTCUSD","data":[{"trade_time_ms":1618677806613,"timestamp":"2021-04-17T16:43:26.000Z","symbol":"BTCUSD","side":"Buy","size":21197,"price":60623,"tick_direction":"ZeroPlusTick","trade_id":"aee73a3d-acbc-5067-8715-aa9f8a6a961d","cross_seq":5938957987}]}
1618677806.8072178: {"topic":"orderBookL2_25.BTCUSD","type":"delta","data":{"delete":[],"update":[{"price":"60622.50","symbol":"BTCUSD","id":606225000,"side":"Buy","size":12053536}],"insert":[],"transactTimeE6":0},"cross_seq":5938957990,"timestamp_e6":1618677806717982}
1618677806.826713: {"topic":"orderBookL2_25.BTCUSD","type":"delta","data":{"delete":[],"update":[{"price":"60622.50","symbol":"BTCUSD","id":606225000,"side":"Buy","size":12173868},{"price":"60623.50","symbol":"BTCUSD","id":606235000,"side":"Sell","size":923906}],"insert":[],"transactTimeE6":0},"cross_seq":5938957993,"timestamp_e6":1618677806737966}
1618677806.8484118: {"topic":"orderBookL2_25.BTCUSD","type":"delta","data":{"delete":[],"update":[{"price":"60622.50","symbol":"BTCUSD","id":606225000,"side":"Buy","size":12243868}],"insert":[],"transactTimeE6":0},"cross_seq":5938957994,"timestamp_e6":1618677806758029}
1618677806.924354: {"topic":"orderBookL2_25.BTCUSD","type":"delta","data":{"delete":[],"update":[{"price":"60622.50","symbol":"BTCUSD","id":606225000,"side":"Buy","size":12243872}],"insert":[],"transactTimeE6":0},"cross_seq":5938957998,"timestamp_e6":1618677806837982}
1618677806.946223: {"topic":"orderBookL2_25.BTCUSD","type":"delta","data":{"delete":[],"update":[{"price":"60623.50","symbol":"BTCUSD","id":606235000,"side":"Sell","size":234565}],"insert":[],"transactTimeE6":0},"cross_seq":5938957999,"timestamp_e6":1618677806857359}
1618677806.946311: {"topic":"orderBookL2_25.EOSUSD","type":"delta","data":{"delete":[{"price":"7.975","symbol":"EOSUSD","id":79750,"side":"Sell"}],"update":[{"price":"7.976","symbol":"EOSUSD","id":79760,"side":"Sell","size":30155}],"insert":[{"price":"8.000","symbol":"EOSUSD","id":80000,"side":"Sell","size":68599}],"transactTimeE6":0},"cross_seq":1225778425,"timestamp_e6":1618677806858793}
1618677806.958046: {"topic":"trade.EOSUSD","data":[{"trade_time_ms":1618677806841,"timestamp":"2021-04-17T16:43:26.000Z","symbol":"EOSUSD","side":"Buy","size":2733,"price":7.975,"tick_direction":"PlusTick","trade_id":"5db8badf-b360-5501-a784-7ada008a2c2b","cross_seq":1225778425},{"trade_time_ms":1618677806841,"timestamp":"2021-04-17T16:43:26.000Z","symbol":"EOSUSD","side":"Buy","size":708,"price":7.976,"tick_direction":"PlusTick","trade_id":"dc669b79-d843-537d-8dfe-52c3d5019c28","cross_seq":1225778425}]}
1618677806.9666681: {"topic":"orderBookL2_25.EOSUSD","type":"delta","data":{"delete":[{"price":"7.945","symbol":"EOSUSD","id":79450,"side":"Buy"}],"update":[{"price":"7.974","symbol":"EOSUSD","id":79740,"side":"Buy","size":104490}],"insert":[{"price":"7.975","symbol":"EOSUSD","id":79750,"side":"Buy","size":41217}],"transactTimeE6":0},"cross_seq":1225778431,"timestamp_e6":1618677806878763}
1618677806.9829628: {"topic":"orderBookL2_25.EOSUSD","type":"delta","data":{"delete":[],"update":[{"price":"7.975","symbol":"EOSUSD","id":79750,"side":"Buy","size":82883},{"price":"7.974","symbol":"EOSUSD","id":79740,"side":"Buy","size":89490}],"insert":[],"transactTimeE6":0},"cross_seq":1225778434,"timestamp_e6":1618677806898752}
1618677807.0018072: {"topic":"orderBookL2_25.BTCUSD","type":"delta","data":{"delete":[],"update":[{"price":"60622.00","symbol":"BTCUSD","id":606220000,"side":"Buy","size":2230}],"insert":[],"transactTimeE6":0},"cross_seq":5938958012,"timestamp_e6":1618677806917378}
1618677807.0018592: {"topic":"orderBookL2_25.EOSUSD","type":"delta","data":{"delete":[],"update":[{"price":"7.974","symbol":"EOSUSD","id":79740,"side":"Buy","size":56157},{"price":"7.975","symbol":"EOSUSD","id":79750,"side":"Buy","size":156331}],"insert":[],"transactTimeE6":0},"cross_seq":1225778437,"timestamp_e6":1618677806918764}
1618677807.023826: {"topic":"orderBookL2_25.EOSUSD","type":"delta","data":{"delete":[],"update":[{"price":"7.975","symbol":"EOSUSD","id":79750,"side":"Buy","size":157331},{"price":"7.976","symbol":"EOSUSD","id":79760,"side":"Sell","size":30762}],"insert":[],"transactTimeE6":0},"cross_seq":1225778439,"timestamp_e6":1618677806939317}
1618677807.041993: {"topic":"orderBookL2_25.EOSUSD","type":"delta","data":{"delete":[],"update":[{"price":"7.974","symbol":"EOSUSD","id":79740,"side":"Buy","size":56057},{"price":"7.975","symbol":"EOSUSD","id":79750,"side":"Buy","size":157431},{"price":"7.980","symbol":"EOSUSD","id":79800,"side":"Sell","size":82970}],"insert":[],"transactTimeE6":0},"cross_seq":1225778441,"timestamp_e6":1618677806958784}
1618677807.12219: {"topic":"orderBookL2_25.BTCUSD","type":"delta","data":{"delete":[],"update":[{"price":"60630.00","symbol":"BTCUSD","id":606300000,"side":"Sell","size":147317},{"price":"60623.50","symbol":"BTCUSD","id":606235000,"side":"Sell","size":966007},{"price":"60626.00","symbol":"BTCUSD","id":606260000,"side":"Sell","size":60327},{"price":"60627.00","symbol":"BTCUSD","id":606270000,"side":"Sell","size":126},{"price":"60633.50","symbol":"BTCUSD","id":606335000,"side":"Sell","size":105686},{"price":"60630.50","symbol":"BTCUSD","id":606305000,"side":"Sell","size":66902},{"price":"60622.00","symbol":"BTCUSD","id":606220000,"side":"Buy","size":2993},{"price":"60627.50","symbol":"BTCUSD","id":606275000,"side":"Sell","size":177874},{"price":"60631.00","symbol":"BTCUSD","id":606310000,"side":"Sell","size":94031},{"price":"60628.50","symbol":"BTCUSD","id":606285000,"side":"Sell","size":977},{"price":"60628.00","symbol":"BTCUSD","id":606280000,"side":"Sell","size":116611},{"price":"60626.50","symbol":"BTCUSD","id":606265000,"side":"Sell","size":161630},{"price":"60625.00","symbol":"BTCUSD","id":606250000,"side":"Sell","size":60509},{"price":"60625.50","symbol":"BTCUSD","id":606255000,"side":"Sell","size":113146}],"insert":[],"transactTimeE6":0},"cross_seq":5938958045,"timestamp_e6":1618677807037349}
1618677807.1224031: {"topic":"orderBookL2_25.EOSUSD","type":"delta","data":{"delete":[],"update":[{"price":"7.974","symbol":"EOSUSD","id":79740,"side":"Buy","size":2615}],"insert":[],"transactTimeE6":0},"cross_seq":1225778442,"timestamp_e6":1618677807038125}
1618677807.141978: {"topic":"orderBookL2_25.BTCUSD","type":"delta","data":{"delete":[],"update":[{"price":"60622.50","symbol":"BTCUSD","id":606225000,"side":"Buy","size":12123540}],"insert":[],"transactTimeE6":0},"cross_seq":5938958046,"timestamp_e6":1618677807058004}
1618677807.142036: {"topic":"orderBookL2_25.EOSUSD","type":"delta","data":{"delete":[],"update":[{"price":"7.980","symbol":"EOSUSD","id":79800,"side":"Sell","size":82403},{"price":"7.974","symbol":"EOSUSD","id":79740,"side":"Buy","size":1615}],"insert":[],"transactTimeE6":0},"cross_seq":1225778444,"timestamp_e6":1618677807058147}
1618677807.1607838: {"topic":"orderBookL2_25.BTCUSD","type":"delta","data":{"delete":[],"update":[{"price":"60623.50","symbol":"BTCUSD","id":606235000,"side":"Sell","size":198287}],"insert":[],"transactTimeE6":0},"cross_seq":5938958054,"timestamp_e6":1618677807077379}
1618677807.182186: {"topic":"orderBookL2_25.BTCUSD","type":"delta","data":{"delete":[],"update":[{"price":"60622.50","symbol":"BTCUSD","id":606225000,"side":"Buy","size":12123571}],"insert":[],"transactTimeE6":0},"cross_seq":5938958056,"timestamp_e6":1618677807098031}
1618677807.2017221: {"topic":"orderBookL2_25.BTCUSD","type":"delta","data":{"delete":[],"update":[{"price":"60623.50","symbol":"BTCUSD","id":606235000,"side":"Sell","size":888383}],"insert":[],"transactTimeE6":0},"cross_seq":5938958059,"timestamp_e6":1618677807117338}
1618677807.222938: {"topic":"orderBookL2_25.BTCUSD","type":"delta","data":{"delete":[],"update":[{"price":"60622.00","symbol":"BTCUSD","id":606220000,"side":"Buy","size":5993}],"insert":[],"transactTimeE6":0},"cross_seq":5938958060,"timestamp_e6":1618677807137426}
1618677807.261059: {"topic":"orderBookL2_25.BTCUSD","type":"delta","data":{"delete":[],"update":[{"price":"60616.00","symbol":"BTCUSD","id":606160000,"side":"Buy","size":29199}],"insert":[],"transactTimeE6":0},"cross_seq":5938958062,"timestamp_e6":1618677807177379}
1618677807.2806091: {"topic":"orderBookL2_25.BTCUSD","type":"delta","data":{"delete":[],"update":[{"price":"60622.00","symbol":"BTCUSD","id":606220000,"side":"Buy","size":15993}],"insert":[],"transactTimeE6":0},"cross_seq":5938958065,"timestamp_e6":1618677807197357}
1618677807.301385: {"topic":"orderBookL2_25.BTCUSD","type":"delta","data":{"delete":[],"update":[{"price":"60618.00","symbol":"BTCUSD","id":606180000,"side":"Buy","size":1396}],"insert":[],"transactTimeE6":0},"cross_seq":5938958067,"timestamp_e6":1618677807217389}
1618677807.341581: {"topic":"orderBookL2_25.BTCUSD","type":"delta","data":{"delete":[{"price":"60619.50","symbol":"BTCUSD","id":606195000,"side":"Buy"}],"update":[],"insert":[{"price":"60605.50","symbol":"BTCUSD","id":606055000,"side":"Buy","size":116695}],"transactTimeE6":0},"cross_seq":5938958069,"timestamp_e6":1618677807257403}
1618677807.461407: {"topic":"orderBookL2_25.BTCUSD","type":"delta","data":{"delete":[],"update":[{"price":"60623.50","symbol":"BTCUSD","id":606235000,"side":"Sell","size":198287},{"price":"60628.00","symbol":"BTCUSD","id":606280000,"side":"Sell","size":341417},{"price":"60622.50","symbol":"BTCUSD","id":606225000,"side":"Buy","size":12123581}],"insert":[],"transactTimeE6":0},"cross_seq":5938958083,"timestamp_e6":1618677807378395}
1618677807.48108: {"topic":"orderBookL2_25.BTCUSD","type":"delta","data":{"delete":[],"update":[{"price":"60622.50","symbol":"BTCUSD","id":606225000,"side":"Buy","size":12133571}],"insert":[],"transactTimeE6":0},"cross_seq":5938958085,"timestamp_e6":1618677807398006}
1618677807.52112: {"topic":"orderBookL2_25.BTCUSD","type":"delta","data":{"delete":[{"price":"60605.50","symbol":"BTCUSD","id":606055000,"side":"Buy"}],"update":[],"insert":[{"price":"60610.00","symbol":"BTCUSD","id":606100000,"side":"Buy","size":244219}],"transactTimeE6":0},"cross_seq":5938958086,"timestamp_e6":1618677807437362}
1618677807.561057: {"topic":"orderBookL2_25.BTCUSD","type":"delta","data":{"delete":[],"update":[{"price":"60622.50","symbol":"BTCUSD","id":606225000,"side":"Buy","size":12123581}],"insert":[],"transactTimeE6":0},"cross_seq":5938958090,"timestamp_e6":1618677807478336}
1618677807.582138: {"topic":"orderBookL2_25.BTCUSD","type":"delta","data":{"delete":[],"update":[{"price":"60628.00","symbol":"BTCUSD","id":606280000,"side":"Sell","size":116611}],"insert":[],"transactTimeE6":0},"cross_seq":5938958096,"timestamp_e6":1618677807497354}
1618677807.601398: {"topic":"orderBookL2_25.BTCUSD","type":"delta","data":{"delete":[],"update":[{"price":"60623.00","symbol":"BTCUSD","id":606230000,"side":"Sell","size":1697539}],"insert":[],"transactTimeE6":0},"cross_seq":5938958097,"timestamp_e6":1618677807517963}
1618677807.62082: {"topic":"orderBookL2_25.BTCUSD","type":"delta","data":{"delete":[{"price":"60610.00","symbol":"BTCUSD","id":606100000,"side":"Buy"}],"update":[],"insert":[{"price":"60606.00","symbol":"BTCUSD","id":606060000,"side":"Buy","size":56014}],"transactTimeE6":0},"cross_seq":5938958098,"timestamp_e6":1618677807537405}
1618677807.6409888: {"topic":"orderBookL2_25.EOSUSD","type":"delta","data":{"delete":[],"update":[{"price":"7.980","symbol":"EOSUSD","id":79800,"side":"Sell","size":82970}],"insert":[],"transactTimeE6":0},"cross_seq":1225778445,"timestamp_e6":1618677807558127}
1618677807.64179: {"topic":"orderBookL2_25.BTCUSD","type":"delta","data":{"delete":[],"update":[{"price":"60622.50","symbol":"BTCUSD","id":606225000,"side":"Buy","size":12133581}],"insert":[],"transactTimeE6":0},"cross_seq":5938958106,"timestamp_e6":1618677807558006}
1618677807.662366: {"topic":"orderBookL2_25.BTCUSD","type":"delta","data":{"delete":[],"update":[{"price":"60622.50","symbol":"BTCUSD","id":606225000,"side":"Buy","size":12063581}],"insert":[],"transactTimeE6":0},"cross_seq":5938958107,"timestamp_e6":1618677807577949}
1618677807.7016: {"topic":"orderBookL2_25.BTCUSD","type":"delta","data":{"delete":[{"price":"60606.00","symbol":"BTCUSD","id":606060000,"side":"Buy"}],"update":[{"price":"60622.50","symbol":"BTCUSD","id":606225000,"side":"Buy","size":12183920}],"insert":[{"price":"60605.50","symbol":"BTCUSD","id":606055000,"side":"Buy","size":116695}],"transactTimeE6":0},"cross_seq":5938958110,"timestamp_e6":1618677807617978}
1618677807.72062: {"topic":"orderBookL2_25.BTCUSD","type":"delta","data":{"delete":[],"update":[{"price":"60623.00","symbol":"BTCUSD","id":606230000,"side":"Sell","size":1697538}],"insert":[],"transactTimeE6":0},"cross_seq":5938958113,"timestamp_e6":1618677807637961}
1618677807.761253: {"topic":"orderBookL2_25.EOSUSD","type":"delta","data":{"delete":[],"update":[{"price":"7.946","symbol":"EOSUSD","id":79460,"side":"Buy","size":96718}],"insert":[],"transactTimeE6":0},"cross_seq":1225778446,"timestamp_e6":1618677807678117}
1618677807.801169: {"topic":"orderBookL2_25.BTCUSD","type":"delta","data":{"delete":[],"update":[{"price":"60622.50","symbol":"BTCUSD","id":606225000,"side":"Buy","size":12297790}],"insert":[],"transactTimeE6":0},"cross_seq":5938958122,"timestamp_e6":1618677807718399}
1618677807.841702: {"topic":"orderBookL2_25.BTCUSD","type":"delta","data":{"delete":[],"update":[{"price":"60623.00","symbol":"BTCUSD","id":606230000,"side":"Sell","size":1697539}],"insert":[],"transactTimeE6":0},"cross_seq":5938958132,"timestamp_e6":1618677807757973}
1618677807.861774: {"topic":"orderBookL2_25.BTCUSD","type":"delta","data":{"delete":[],"update":[{"price":"60622.50","symbol":"BTCUSD","id":606225000,"side":"Buy","size":12367790},{"price":"60623.50","symbol":"BTCUSD","id":606235000,"side":"Sell","size":859988}],"insert":[],"transactTimeE6":0},"cross_seq":5938958134,"timestamp_e6":1618677807778112}
1618677807.901917: {"topic":"orderBookL2_25.BTCUSD","type":"delta","data":{"delete":[],"update":[{"price":"60623.50","symbol":"BTCUSD","id":606235000,"side":"Sell","size":198287}],"insert":[],"transactTimeE6":0},"cross_seq":5938958137,"timestamp_e6":1618677807817430}
1618677807.9202812: {"topic":"orderBookL2_25.BTCUSD","type":"delta","data":{"delete":[],"update":[{"price":"60623.50","symbol":"BTCUSD","id":606235000,"side":"Sell","size":1074490}],"insert":[],"transactTimeE6":0},"cross_seq":5938958138,"timestamp_e6":1618677807837318}
1618677807.984638: {"topic":"orderBookL2_25.BTCUSD","type":"delta","data":{"delete":[],"update":[{"price":"60623.50","symbol":"BTCUSD","id":606235000,"side":"Sell","size":1118965},{"price":"60625.00","symbol":"BTCUSD","id":606250000,"side":"Sell","size":110253},{"price":"60625.50","symbol":"BTCUSD","id":606255000,"side":"Sell","size":129838},{"price":"60624.50","symbol":"BTCUSD","id":606245000,"side":"Sell","size":110176},{"price":"60626.50","symbol":"BTCUSD","id":606265000,"side":"Sell","size":206663},{"price":"60627.50","symbol":"BTCUSD","id":606275000,"side":"Sell","size":223457},{"price":"60628.00","symbol":"BTCUSD","id":606280000,"side":"Sell","size":175139},{"price":"60628.50","symbol":"BTCUSD","id":606285000,"side":"Sell","size":41621},{"price":"60627.00","symbol":"BTCUSD","id":606270000,"side":"Sell","size":84112},{"price":"60630.50","symbol":"BTCUSD","id":606305000,"side":"Sell","size":113426}],"insert":[],"transactTimeE6":0},"cross_seq":5938958176,"timestamp_e6":1618677807897362}
1618677808.042067: {"topic":"orderBookL2_25.EOSUSD","type":"delta","data":{"delete":[],"update":[{"price":"7.976","symbol":"EOSUSD","id":79760,"side":"Sell","size":29722}],"insert":[],"transactTimeE6":0},"cross_seq":1225778447,"timestamp_e6":1618677807958778}
1618677808.0582411: {"topic":"trade.EOSUSD","data":[{"trade_time_ms":1618677807934,"timestamp":"2021-04-17T16:43:27.000Z","symbol":"EOSUSD","side":"Buy","size":1040,"price":7.976,"tick_direction":"ZeroPlusTick","trade_id":"7b1527e1-88a6-5729-8db2-1f63dfa3340e","cross_seq":1225778448}]}
1618677808.060989: {"topic":"orderBookL2_25.EOSUSD","type":"delta","data":{"delete":[],"update":[{"price":"7.980","symbol":"EOSUSD","id":79800,"side":"Sell","size":82403}],"insert":[],"transactTimeE6":0},"cross_seq":1225778448,"timestamp_e6":1618677807978138}
1618677808.082264: {"topic":"orderBookL2_25.EOSUSD","type":"delta","data":{"delete":[],"update":[{"price":"7.976","symbol":"EOSUSD","id":79760,"side":"Sell","size":29115},{"price":"7.977","symbol":"EOSUSD","id":79770,"side":"Sell","size":27331},{"price":"7.979","symbol":"EOSUSD","id":79790,"side":"Sell","size":32545}],"insert":[],"transactTimeE6":0},"cross_seq":1225778450,"timestamp_e6":1618677807998769}
1618677808.1209211: {"topic":"orderBookL2_25.BTCUSD","type":"delta","data":{"delete":[],"update":[{"price":"60624.00","symbol":"BTCUSD","id":606240000,"side":"Sell","size":122908},{"price":"60623.50","symbol":"BTCUSD","id":606235000,"side":"Sell","size":1075549},{"price":"60624.50","symbol":"BTCUSD","id":606245000,"side":"Sell","size":80259}],"insert":[],"transactTimeE6":0},"cross_seq":5938958184,"timestamp_e6":1618677808037368}
1618677808.122709: {"topic":"orderBookL2_25.EOSUSD","type":"delta","data":{"delete":[],"update":[{"price":"7.975","symbol":"EOSUSD","id":79750,"side":"Buy","size":165431}],"insert":[],"transactTimeE6":0},"cross_seq":1225778452,"timestamp_e6":1618677808038749}
1618677808.14272: {"topic":"orderBookL2_25.BTCUSD","type":"delta","data":{"delete":[],"update":[{"price":"60623.00","symbol":"BTCUSD","id":606230000,"side":"Sell","size":1672384},{"price":"60622.50","symbol":"BTCUSD","id":606225000,"side":"Buy","size":12367786}],"insert":[],"transactTimeE6":0},"cross_seq":5938958186,"timestamp_e6":1618677808058709}
1618677808.154465: {"topic":"trade.BTCUSD","data":[{"trade_time_ms":1618677808045,"timestamp":"2021-04-17T16:43:28.000Z","symbol":"BTCUSD","side":"Buy","size":9552,"price":60623,"tick_direction":"ZeroPlusTick","trade_id":"2a71ba01-b508-5a9d-ad5b-b2947810fde2","cross_seq":5938958186},{"trade_time_ms":1618677808045,"timestamp":"2021-04-17T16:43:28.000Z","symbol":"BTCUSD","side":"Buy","size":15603,"price":60623,"tick_direction":"ZeroPlusTick","trade_id":"67f22203-6575-548d-a7ff-cb161d28414d","cross_seq":5938958186}]}
1618677808.162355: {"topic":"orderBookL2_25.EOSUSD","type":"delta","data":{"delete":[{"price":"7.974","symbol":"EOSUSD","id":79740,"side":"Buy"},{"price":"7.946","symbol":"EOSUSD","id":79460,"side":"Buy"}],"update":[{"price":"7.988","symbol":"EOSUSD","id":79880,"side":"Sell","size":29589},{"price":"7.986","symbol":"EOSUSD","id":79860,"side":"Sell","size":118945},{"price":"7.977","symbol":"EOSUSD","id":79770,"side":"Sell","size":23946},{"price":"7.991","symbol":"EOSUSD","id":79910,"side":"Sell","size":80649},{"price":"7.975","symbol":"EOSUSD","id":79750,"side":"Buy","size":167046},{"price":"7.966","symbol":"EOSUSD","id":79660,"side":"Buy","size":57881},{"price":"7.981","symbol":"EOSUSD","id":79810,"side":"Sell","size":9669},{"price":"7.984","symbol":"EOSUSD","id":79840,"side":"Sell","size":86985},{"price":"7.982","symbol":"EOSUSD","id":79820,"side":"Sell","size":102547},{"price":"7.985","symbol":"EOSUSD","id":79850,"side":"Sell","size":21631},{"price":"7.979","symbol":"EOSUSD","id":79790,"side":"Sell","size":35930},{"price":"7.969","symbol":"EOSUSD","id":79690,"side":"Buy","size":73398},{"price":"7.983","symbol":"EOSUSD","id":79830,"side":"Sell","size":83766},{"price":"7.965","symbol":"EOSUSD","id":79650,"side":"Buy","size":43880},{"price":"7.989","symbol":"EOSUSD","id":79890,"side":"Sell","size":10729},{"price":"7.968","symbol":"EOSUSD","id":79680,"side":"Buy","size":109226},{"price":"7.980","symbol":"EOSUSD","id":79800,"side":"Sell","size":61460}],"insert":[{"price":"7.970","symbol":"EOSUSD","id":79700,"side":"Buy","size":39851},{"price":"7.967","symbol":"EOSUSD","id":79670,"side":"Buy","size":22988}],"transactTimeE6":0},"cross_seq":1225778477,"timestamp_e6":1618677808078701}
1618677808.1811259: {"topic":"orderBookL2_25.BTCUSD","type":"delta","data":{"delete":[],"update":[{"price":"60622.50","symbol":"BTCUSD","id":606225000,"side":"Buy","size":12511506}],"insert":[],"transactTimeE6":0},"cross_seq":5938958189,"timestamp_e6":1618677808098030}
1618677808.200407: {"topic":"orderBookL2_25.BTCUSD","type":"delta","data":{"delete":[],"update":[{"price":"60623.50","symbol":"BTCUSD","id":606235000,"side":"Sell","size":199346}],"insert":[],"transactTimeE6":0},"cross_seq":5938958191,"timestamp_e6":1618677808117330}
1618677808.223393: {"topic":"orderBookL2_25.EOSUSD","type":"delta","data":{"delete":[{"price":"7.947","symbol":"EOSUSD","id":79470,"side":"Buy"},{"price":"7.984","symbol":"EOSUSD","id":79840,"side":"Sell"},{"price":"7.976","symbol":"EOSUSD","id":79760,"side":"Sell"}],"update":[{"price":"7.957","symbol":"EOSUSD","id":79570,"side":"Buy","size":45335},{"price":"7.970","symbol":"EOSUSD","id":79700,"side":"Buy","size":69534},{"price":"7.977","symbol":"EOSUSD","id":79770,"side":"Sell","size":45},{"price":"7.954","symbol":"EOSUSD","id":79540,"side":"Buy","size":97638},{"price":"7.958","symbol":"EOSUSD","id":79580,"side":"Buy","size":89313},{"price":"7.955","symbol":"EOSUSD","id":79550,"side":"Buy","size":159304},{"price":"7.980","symbol":"EOSUSD","id":79800,"side":"Sell","size":51991},{"price":"7.986","symbol":"EOSUSD","id":79860,"side":"Sell","size":29565},{"price":"7.963","symbol":"EOSUSD","id":79630,"side":"Buy","size":52393},{"price":"7.952","symbol":"EOSUSD","id":79520,"side":"Buy","size":104870},{"price":"7.966","symbol":"EOSUSD","id":79660,"side":"Buy","size":36162},{"price":"7.985","symbol":"EOSUSD","id":79850,"side":"Sell","size":12036},{"price":"7.968","symbol":"EOSUSD","id":79680,"side":"Buy","size":127848},{"price":"7.960","symbol":"EOSUSD","id":79600,"side":"Buy","size":81409},{"price":"7.979","symbol":"EOSUSD","id":79790,"side":"Sell","size":20750},{"price":"7.978","symbol":"EOSUSD","id":79780,"side":"Sell","size":21},{"price":"7.987","symbol":"EOSUSD","id":79870,"side":"Sell","size":28600},{"price":"7.948","symbol":"EOSUSD","id":79480,"side":"Buy","size":81032},{"price":"7.956","symbol":"EOSUSD","id":79560,"side":"Buy","size":67191},{"price":"7.961","symbol":"EOSUSD","id":79610,"side":"Buy","size":19777},{"price":"7.981","symbol":"EOSUSD","id":79810,"side":"Sell","size":20},{"price":"7.983","symbol":"EOSUSD","id":79830,"side":"Sell","size":20},{"price":"7.962","symbol":"EOSUSD","id":79620,"side":"Buy","size":125322},{"price":"7.964","symbol":"EOSUSD","id":79640,"side":"Buy","size":118032},{"price":"7.969","symbol":"EOSUSD","id":79690,"side":"Buy","size":103450},{"price":"7.959","symbol":"EOSUSD","id":79590,"side":"Buy","size":15543},{"price":"7.967","symbol":"EOSUSD","id":79670,"side":"Buy","size":45968},{"price":"7.965","symbol":"EOSUSD","id":79650,"side":"Buy","size":87580},{"price":"7.982","symbol":"EOSUSD","id":79820,"side":"Sell","size":78764}],"insert":[{"price":"7.971","symbol":"EOSUSD","id":79710,"side":"Buy","size":36543},{"price":"8.001","symbol":"EOSUSD","id":80010,"side":"Sell","size":109591},{"price":"8.002","symbol":"EOSUSD","id":80020,"side":"Sell","size":88702}],"transactTimeE6":0},"cross_seq":1225778531,"timestamp_e6":1618677808138743}
1618677808.2421849: {"topic":"orderBookL2_25.EOSUSD","type":"delta","data":{"delete":[{"price":"7.948","symbol":"EOSUSD","id":79480,"side":"Buy"}],"update":[{"price":"7.975","symbol":"EOSUSD","id":79750,"side":"Buy","size":125829}],"insert":[{"price":"7.976","symbol":"EOSUSD","id":79760,"side":"Buy","size":41217}],"transactTimeE6":0},"cross_seq":1225778537,"timestamp_e6":1618677808158705}
1618677808.2618392: {"topic":"orderBookL2_25.EOSUSD","type":"delta","data":{"delete":[],"update":[{"price":"7.975","symbol":"EOSUSD","id":79750,"side":"Buy","size":110829},{"price":"7.976","symbol":"EOSUSD","id":79760,"side":"Buy","size":82883},{"price":"7.982","symbol":"EOSUSD","id":79820,"side":"Sell","size":90764},{"price":"7.979","symbol":"EOSUSD","id":79790,"side":"Sell","size":8750},{"price":"7.968","symbol":"EOSUSD","id":79680,"side":"Buy","size":89317}],"insert":[],"transactTimeE6":0},"cross_seq":1225778542,"timestamp_e6":1618677808178694}
1618677808.282492: {"topic":"orderBookL2_25.BTCUSD","type":"delta","data":{"delete":[{"price":"60605.50","symbol":"BTCUSD","id":606055000,"side":"Buy"}],"update":[{"price":"60622.50","symbol":"BTCUSD","id":606225000,"side":"Buy","size":12456506}],"insert":[{"price":"60606.00","symbol":"BTCUSD","id":606060000,"side":"Buy","size":56014}],"transactTimeE6":0},"cross_seq":5938958200,"timestamp_e6":1618677808197978}
1618677808.282609: {"topic":"orderBookL2_25.EOSUSD","type":"delta","data":{"delete":[],"update":[{"price":"7.975","symbol":"EOSUSD","id":79750,"side":"Buy","size":64163},{"price":"7.976","symbol":"EOSUSD","id":79760,"side":"Buy","size":139061}],"insert":[],"transactTimeE6":0},"cross_seq":1225778545,"timestamp_e6":1618677808198741}
1618677808.3025138: {"topic":"orderBookL2_25.BTCUSD","type":"delta","data":{"delete":[],"update":[{"price":"60622.50","symbol":"BTCUSD","id":606225000,"side":"Buy","size":12466506}],"insert":[],"transactTimeE6":0},"cross_seq":5938958203,"timestamp_e6":1618677808218039}
1618677808.3025699: {"topic":"orderBookL2_25.EOSUSD","type":"delta","data":{"delete":[{"price":"7.980","symbol":"EOSUSD","id":79800,"side":"Sell"}],"update":[{"price":"7.985","symbol":"EOSUSD","id":79850,"side":"Sell","size":20464},{"price":"7.989","symbol":"EOSUSD","id":79890,"side":"Sell","size":15254},{"price":"7.986","symbol":"EOSUSD","id":79860,"side":"Sell","size":43689},{"price":"7.982","symbol":"EOSUSD","id":79820,"side":"Sell","size":56712},{"price":"7.987","symbol":"EOSUSD","id":79870,"side":"Sell","size":40563},{"price":"7.983","symbol":"EOSUSD","id":79830,"side":"Sell","size":27576},{"price":"7.988","symbol":"EOSUSD","id":79880,"side":"Sell","size":21391},{"price":"7.976","symbol":"EOSUSD","id":79760,"side":"Buy","size":140061}],"insert":[{"price":"7.984","symbol":"EOSUSD","id":79840,"side":"Sell","size":22377}],"transactTimeE6":0},"cross_seq":1225778555,"timestamp_e6":1618677808218732}
1618677808.3214028: {"topic":"orderBookL2_25.EOSUSD","type":"delta","data":{"delete":[],"update":[{"price":"7.976","symbol":"EOSUSD","id":79760,"side":"Buy","size":140161},{"price":"7.981","symbol":"EOSUSD","id":79810,"side":"Sell","size":587},{"price":"7.975","symbol":"EOSUSD","id":79750,"side":"Buy","size":64063}],"insert":[],"transactTimeE6":0},"cross_seq":1225778557,"timestamp_e6":1618677808238701}
1618677808.3426309: {"topic":"orderBookL2_25.EOSUSD","type":"delta","data":{"delete":[],"update":[{"price":"7.975","symbol":"EOSUSD","id":79750,"side":"Buy","size":60063},{"price":"7.976","symbol":"EOSUSD","id":79760,"side":"Buy","size":160161},{"price":"7.988","symbol":"EOSUSD","id":79880,"side":"Sell","size":25771}],"insert":[],"transactTimeE6":0},"cross_seq":1225778560,"timestamp_e6":1618677808258818}
1618677808.3609989: {"topic":"orderBookL2_25.EOSUSD","type":"delta","data":{"delete":[],"update":[{"price":"7.975","symbol":"EOSUSD","id":79750,"side":"Buy","size":56063},{"price":"7.979","symbol":"EOSUSD","id":79790,"side":"Sell","size":365},{"price":"7.981","symbol":"EOSUSD","id":79810,"side":"Sell","size":8972}],"insert":[],"transactTimeE6":0},"cross_seq":1225778563,"timestamp_e6":1618677808278137}
1618677808.382069: {"topic":"orderBookL2_25.EOSUSD","type":"delta","data":{"delete":[],"update":[{"price":"7.975","symbol":"EOSUSD","id":79750,"side":"Buy","size":54448},{"price":"7.976","symbol":"EOSUSD","id":79760,"side":"Buy","size":161776}],"insert":[],"transactTimeE6":0},"cross_seq":1225778564,"timestamp_e6":1618677808299024}
1618677808.402435: {"topic":"orderBookL2_25.EOSUSD","type":"delta","data":{"delete":[{"price":"7.949","symbol":"EOSUSD","id":79490,"side":"Buy"},{"price":"7.977","symbol":"EOSUSD","id":79770,"side":"Sell"}],"update":[{"price":"7.975","symbol":"EOSUSD","id":79750,"side":"Buy","size":1000},{"price":"7.976","symbol":"EOSUSD","id":79760,"side":"Buy","size":141776}],"insert":[{"price":"7.977","symbol":"EOSUSD","id":79770,"side":"Buy","size":19955},{"price":"8.003","symbol":"EOSUSD","id":80030,"side":"Sell","size":60901}],"transactTimeE6":0},"cross_seq":1225778567,"timestamp_e6":1618677808319308}
1618677808.422241: {"topic":"orderBookL2_25.BTCUSD","type":"delta","data":{"delete":[],"update":[{"price":"60622.50","symbol":"BTCUSD","id":606225000,"side":"Buy","size":12466507}],"insert":[],"transactTimeE6":0},"cross_seq":5938958209,"timestamp_e6":1618677808338021}
1618677808.422299: {"topic":"orderBookL2_25.EOSUSD","type":"delta","data":{"delete":[{"price":"7.975","symbol":"EOSUSD","id":79750,"side":"Buy"}],"update":[{"price":"7.981","symbol":"EOSUSD","id":79810,"side":"Sell","size":8405},{"price":"7.976","symbol":"EOSUSD","id":79760,"side":"Buy","size":100559},{"price":"7.977","symbol":"EOSUSD","id":79770,"side":"Buy","size":61172}],"insert":[{"price":"7.949","symbol":"EOSUSD","id":79490,"side":"Buy","size":138507}],"transactTimeE6":0},"cross_seq":1225778591,"timestamp_e6":1618677808338759}
1618677808.44239: {"topic":"orderBookL2_25.EOSUSD","type":"delta","data":{"delete":[],"update":[{"price":"7.977","symbol":"EOSUSD","id":79770,"side":"Buy","size":62172},{"price":"7.976","symbol":"EOSUSD","id":79760,"side":"Buy","size":99559}],"insert":[],"transactTimeE6":0},"cross_seq":1225778593,"timestamp_e6":1618677808358705}
1618677808.465255: {"topic":"trade.EOSUSD","data":[{"trade_time_ms":1618677808310,"timestamp":"2021-04-17T16:43:28.000Z","symbol":"EOSUSD","side":"Buy","size":20,"price":7.977,"tick_direction":"PlusTick","trade_id":"0e57f326-76cf-57fe-9a2a-ac01edf8f313","cross_seq":1225778597},{"trade_time_ms":1618677808310,"timestamp":"2021-04-17T16:43:28.000Z","symbol":"EOSUSD","side":"Buy","size":25,"price":7.977,"tick_direction":"ZeroPlusTick","trade_id":"6485e27a-739b-56d9-bbfe-13e97bf213f6","cross_seq":1225778597}]}
1618677808.4699352: {"topic":"orderBookL2_25.EOSUSD","type":"delta","data":{"delete":[{"price":"7.984","symbol":"EOSUSD","id":79840,"side":"Sell"}],"update":[{"price":"7.982","symbol":"EOSUSD","id":79820,"side":"Sell","size":14385},{"price":"7.976","symbol":"EOSUSD","id":79760,"side":"Buy","size":36715}],"insert":[{"price":"8.004","symbol":"EOSUSD","id":80040,"side":"Sell","size":146362}],"transactTimeE6":0},"cross_seq":1225778597,"timestamp_e6":1618677808378115}
1618677808.482348: {"topic":"orderBookL2_25.BTCUSD","type":"delta","data":{"delete":[],"update":[{"price":"60623.00","symbol":"BTCUSD","id":606230000,"side":"Sell","size":1672371}],"insert":[],"transactTimeE6":0},"cross_seq":5938958211,"timestamp_e6":1618677808398036}
1618677808.482959: {"topic":"orderBookL2_25.EOSUSD","type":"delta","data":{"delete":[{"price":"8.004","symbol":"EOSUSD","id":80040,"side":"Sell"}],"update":[{"price":"7.965","symbol":"EOSUSD","id":79650,"side":"Buy","size":99580},{"price":"7.962","symbol":"EOSUSD","id":79620,"side":"Buy","size":113322},{"price":"7.978","symbol":"EOSUSD","id":79780,"side":"Sell","size":588},{"price":"7.967","symbol":"EOSUSD","id":79670,"side":"Buy","size":45988}],"insert":[{"price":"7.984","symbol":"EOSUSD","id":79840,"side":"Sell","size":20102}],"transactTimeE6":0},"cross_seq":1225778601,"timestamp_e6":1618677808398771}
1618677808.501156: {"topic":"orderBookL2_25.BTCUSD","type":"delta","data":{"delete":[{"price":"60606.00","symbol":"BTCUSD","id":606060000,"side":"Buy"}],"update":[],"insert":[{"price":"60605.50","symbol":"BTCUSD","id":606055000,"side":"Buy","size":116695}],"transactTimeE6":0},"cross_seq":5938958214,"timestamp_e6":1618677808417363}
1618677808.502133: {"topic":"orderBookL2_25.EOSUSD","type":"delta","data":{"delete":[],"update":[{"price":"7.976","symbol":"EOSUSD","id":79760,"side":"Buy","size":15100},{"price":"7.977","symbol":"EOSUSD","id":79770,"side":"Buy","size":63787}],"insert":[],"transactTimeE6":0},"cross_seq":1225778604,"timestamp_e6":1618677808418729}
1618677808.520559: {"topic":"orderBookL2_25.EOSUSD","type":"delta","data":{"delete":[{"price":"7.971","symbol":"EOSUSD","id":79710,"side":"Buy"},{"price":"7.984","symbol":"EOSUSD","id":79840,"side":"Sell"}],"update":[{"price":"7.986","symbol":"EOSUSD","id":79860,"side":"Sell","size":51189},{"price":"7.983","symbol":"EOSUSD","id":79830,"side":"Sell","size":20},{"price":"7.969","symbol":"EOSUSD","id":79690,"side":"Buy","size":73398},{"price":"7.988","symbol":"EOSUSD","id":79880,"side":"Sell","size":30122},{"price":"7.967","symbol":"EOSUSD","id":79670,"side":"Buy","size":23008},{"price":"7.990","symbol":"EOSUSD","id":79900,"side":"Sell","size":11985},{"price":"7.985","symbol":"EOSUSD","id":79850,"side":"Sell","size":32800},{"price":"7.989","symbol":"EOSUSD","id":79890,"side":"Sell","size":22198},{"price":"7.968","symbol":"EOSUSD","id":79680,"side":"Buy","size":70695}],"insert":[{"price":"8.004","symbol":"EOSUSD","id":80040,"side":"Sell","size":146362},{"price":"7.972","symbol":"EOSUSD","id":79720,"side":"Buy","size":33046}],"transactTimeE6":0},"cross_seq":1225778617,"timestamp_e6":1618677808438067}
1618677808.5428631: {"topic":"orderBookL2_25.EOSUSD","type":"delta","data":{"delete":[],"update":[{"price":"7.977","symbol":"EOSUSD","id":79770,"side":"Buy","size":67887},{"price":"7.978","symbol":"EOSUSD","id":79780,"side":"Sell","size":21},{"price":"7.976","symbol":"EOSUSD","id":79760,"side":"Buy","size":15000}],"insert":[],"transactTimeE6":0},"cross_seq":1225778620,"timestamp_e6":1618677808459329}
1618677808.562985: {"topic":"orderBookL2_25.EOSUSD","type":"delta","data":{"delete":[],"update":[{"price":"7.982","symbol":"EOSUSD","id":79820,"side":"Sell","size":2385},{"price":"7.977","symbol":"EOSUSD","id":79770,"side":"Buy","size":98553},{"price":"7.985","symbol":"EOSUSD","id":79850,"side":"Sell","size":44800}],"insert":[],"transactTimeE6":0},"cross_seq":1225778623,"timestamp_e6":1618677808478711}
1618677808.601372: {"topic":"orderBookL2_25.EOSUSD","type":"delta","data":{"delete":[{"price":"7.949","symbol":"EOSUSD","id":79490,"side":"Buy"}],"update":[{"price":"7.968","symbol":"EOSUSD","id":79680,"side":"Buy","size":83351},{"price":"7.969","symbol":"EOSUSD","id":79690,"side":"Buy","size":93233},{"price":"7.990","symbol":"EOSUSD","id":79900,"side":"Sell","size":21764},{"price":"7.967","symbol":"EOSUSD","id":79670,"side":"Buy","size":37463}],"insert":[{"price":"7.971","symbol":"EOSUSD","id":79710,"side":"Buy","size":28243}],"transactTimeE6":0},"cross_seq":1225778628,"timestamp_e6":1618677808518122}
1618677808.655309: {"topic":"trade.EOSUSD","data":[{"trade_time_ms":1618677808557,"timestamp":"2021-04-17T16:43:28.000Z","symbol":"EOSUSD","side":"Buy","size":20,"price":7.978,"tick_direction":"PlusTick","trade_id":"42d5a5cd-f8c2-5d54-a562-06f18dadc455","cross_seq":1225778630},{"trade_time_ms":1618677808557,"timestamp":"2021-04-17T16:43:28.000Z","symbol":"EOSUSD","side":"Buy","size":1,"price":7.978,"tick_direction":"ZeroPlusTick","trade_id":"5c2f7d75-2f4c-5377-9a69-0d3fe49d5dbd","cross_seq":1225778630}]}
1618677808.661833: {"topic":"orderBookL2_25.BTCUSD","type":"delta","data":{"delete":[],"update":[{"price":"60622.50","symbol":"BTCUSD","id":606225000,"side":"Buy","size":12465707}],"insert":[],"transactTimeE6":0},"cross_seq":5938958227,"timestamp_e6":1618677808577963}
1618677808.662535: {"topic":"orderBookL2_25.EOSUSD","type":"delta","data":{"delete":[{"price":"7.978","symbol":"EOSUSD","id":79780,"side":"Sell"},{"price":"7.950","symbol":"EOSUSD","id":79500,"side":"Buy"}],"update":[{"price":"7.983","symbol":"EOSUSD","id":79830,"side":"Sell","size":52536}],"insert":[{"price":"7.978","symbol":"EOSUSD","id":79780,"side":"Buy","size":11},{"price":"8.005","symbol":"EOSUSD","id":80050,"side":"Sell","size":150304}],"transactTimeE6":0},"cross_seq":1225778631,"timestamp_e6":1618677808579291}
1618677808.681994: {"topic":"orderBookL2_25.EOSUSD","type":"delta","data":{"delete":[],"update":[{"price":"7.977","symbol":"EOSUSD","id":79770,"side":"Buy","size":57336},{"price":"7.978","symbol":"EOSUSD","id":79780,"side":"Buy","size":41228},{"price":"7.965","symbol":"EOSUSD","id":79650,"side":"Buy","size":82250}],"insert":[],"transactTimeE6":0},"cross_seq":1225778638,"timestamp_e6":1618677808598848}
1618677808.701899: {"topic":"orderBookL2_25.EOSUSD","type":"delta","data":{"delete":[{"price":"7.976","symbol":"EOSUSD","id":79760,"side":"Buy"}],"update":[{"price":"7.978","symbol":"EOSUSD","id":79780,"side":"Buy","size":76228},{"price":"7.977","symbol":"EOSUSD","id":79770,"side":"Buy","size":37381}],"insert":[{"price":"7.950","symbol":"EOSUSD","id":79500,"side":"Buy","size":26783}],"transactTimeE6":0},"cross_seq":1225778642,"timestamp_e6":1618677808618724}
1618677808.726762: {"topic":"orderBookL2_25.EOSUSD","type":"delta","data":{"delete":[{"price":"7.950","symbol":"EOSUSD","id":79500,"side":"Buy"}],"update":[{"price":"7.985","symbol":"EOSUSD","id":79850,"side":"Sell","size":81611},{"price":"7.977","symbol":"EOSUSD","id":79770,"side":"Buy","size":10715},{"price":"7.978","symbol":"EOSUSD","id":79780,"side":"Buy","size":77228}],"insert":[{"price":"7.973","symbol":"EOSUSD","id":79730,"side":"Buy","size":40052}],"transactTimeE6":0},"cross_seq":1225778646,"timestamp_e6":1618677808638752}
1618677808.742132: {"topic":"orderBookL2_25.EOSUSD","type":"delta","data":{"delete":[],"update":[{"price":"7.978","symbol":"EOSUSD","id":79780,"side":"Buy","size":77217}],"insert":[],"transactTimeE6":0},"cross_seq":1225778647,"timestamp_e6":1618677808658694}
1618677808.763444: {"topic":"orderBookL2_25.EOSUSD","type":"delta","data":{"delete":[],"update":[{"price":"7.981","symbol":"EOSUSD","id":79810,"side":"Sell","size":3405},{"price":"7.979","symbol":"EOSUSD","id":79790,"side":"Sell","size":5972},{"price":"7.977","symbol":"EOSUSD","id":79770,"side":"Buy","size":6715}],"insert":[],"transactTimeE6":0},"cross_seq":1225778650,"timestamp_e6":1618677808678729}
1618677808.780761: {"topic":"orderBookL2_25.EOSUSD","type":"delta","data":{"delete":[],"update":[{"price":"7.978","symbol":"EOSUSD","id":79780,"side":"Buy","size":77317},{"price":"7.977","symbol":"EOSUSD","id":79770,"side":"Buy","size":2615}],"insert":[],"transactTimeE6":0},"cross_seq":1225778652,"timestamp_e6":1618677808698690}
1618677808.802227: {"topic":"orderBookL2_25.EOSUSD","type":"delta","data":{"delete":[],"update":[{"price":"7.965","symbol":"EOSUSD","id":79650,"side":"Buy","size":96741}],"insert":[],"transactTimeE6":0},"cross_seq":1225778653,"timestamp_e6":1618677808718067}
1618677808.821635: {"topic":"orderBookL2_25.EOSUSD","type":"delta","data":{"delete":[],"update":[{"price":"7.978","symbol":"EOSUSD","id":79780,"side":"Buy","size":90650}],"insert":[],"transactTimeE6":0},"cross_seq":1225778654,"timestamp_e6":1618677808738722}
1618677808.840148: {"topic":"orderBookL2_25.BTCUSD","type":"delta","data":{"delete":[],"update":[{"price":"60616.50","symbol":"BTCUSD","id":606165000,"side":"Buy","size":5246}],"insert":[],"transactTimeE6":0},"cross_seq":5938958241,"timestamp_e6":1618677808757365}
1618677808.841145: {"topic":"orderBookL2_25.EOSUSD","type":"delta","data":{"delete":[],"update":[{"price":"7.979","symbol":"EOSUSD","id":79790,"side":"Sell","size":9357},{"price":"7.977","symbol":"EOSUSD","id":79770,"side":"Buy","size":1615},{"price":"7.981","symbol":"EOSUSD","id":79810,"side":"Sell","size":20}],"insert":[],"transactTimeE6":0},"cross_seq":1225778656,"timestamp_e6":1618677808758730}
1618677808.861687: {"topic":"orderBookL2_25.EOSUSD","type":"delta","data":{"delete":[],"update":[{"price":"7.982","symbol":"EOSUSD","id":79820,"side":"Sell","size":2952}],"insert":[],"transactTimeE6":0},"cross_seq":1225778657,"timestamp_e6":1618677808778115}
1618677808.9022799: {"topic":"orderBookL2_25.BTCUSD","type":"delta","data":{"delete":[],"update":[{"price":"60622.50","symbol":"BTCUSD","id":606225000,"side":"Buy","size":12466507}],"insert":[],"transactTimeE6":0},"cross_seq":5938958244,"timestamp_e6":1618677808818008}
1618677808.9023612: {"topic":"orderBookL2_25.EOSUSD","type":"delta","data":{"delete":[],"update":[{"price":"7.951","symbol":"EOSUSD","id":79510,"side":"Buy","size":107133}],"insert":[],"transactTimeE6":0},"cross_seq":1225778658,"timestamp_e6":1618677808818126}
1618677808.922252: {"topic":"orderBookL2_25.EOSUSD","type":"delta","data":{"delete":[],"update":[{"price":"7.979","symbol":"EOSUSD","id":79790,"side":"Sell","size":9924},{"price":"7.982","symbol":"EOSUSD","id":79820,"side":"Sell","size":2385}],"insert":[],"transactTimeE6":0},"cross_seq":1225778660,"timestamp_e6":1618677808838893}
1618677808.944771: {"topic":"orderBookL2_25.BTCUSD","type":"delta","data":{"delete":[],"update":[{"price":"60622.50","symbol":"BTCUSD","id":606225000,"side":"Buy","size":12467125}],"insert":[],"transactTimeE6":0},"cross_seq":5938958248,"timestamp_e6":1618677808858019}
1618677808.9448268: {"topic":"orderBookL2_25.EOSUSD","type":"delta","data":{"delete":[],"update":[{"price":"7.969","symbol":"EOSUSD","id":79690,"side":"Buy","size":52291},{"price":"7.968","symbol":"EOSUSD","id":79680,"side":"Buy","size":33987}],"insert":[],"transactTimeE6":0},"cross_seq":1225778662,"timestamp_e6":1618677808858073}
1618677808.9604118: {"topic":"orderBookL2_25.BTCUSD","type":"delta","data":{"delete":[],"update":[{"price":"60623.00","symbol":"BTCUSD","id":606230000,"side":"Sell","size":1672343}],"insert":[],"transactTimeE6":0},"cross_seq":5938958252,"timestamp_e6":1618677808877944}
1618677809.00122: {"topic":"orderBookL2_25.BTCUSD","type":"delta","data":{"delete":[{"price":"60605.50","symbol":"BTCUSD","id":606055000,"side":"Buy"}],"update":[],"insert":[{"price":"60606.00","symbol":"BTCUSD","id":606060000,"side":"Buy","size":56014}],"transactTimeE6":0},"cross_seq":5938958261,"timestamp_e6":1618677808917315}
1618677809.001295: {"topic":"orderBookL2_25.EOSUSD","type":"delta","data":{"delete":[],"update":[{"price":"7.982","symbol":"EOSUSD","id":79820,"side":"Sell","size":619},{"price":"7.990","symbol":"EOSUSD","id":79900,"side":"Sell","size":23530}],"insert":[],"transactTimeE6":0},"cross_seq":1225778663,"timestamp_e6":1618677808918117}
1618677809.042711: {"topic":"orderBookL2_25.EOSUSD","type":"delta","data":{"delete":[{"price":"7.977","symbol":"EOSUSD","id":79770,"side":"Buy"}],"update":[],"insert":[{"price":"7.975","symbol":"EOSUSD","id":79750,"side":"Buy","size":1615}],"transactTimeE6":0},"cross_seq":1225778664,"timestamp_e6":1618677808958122}
1618677809.055443: {"topic":"trade.BTCUSD","data":[{"trade_time_ms":1618677808866,"timestamp":"2021-04-17T16:43:28.000Z","symbol":"BTCUSD","side":"Buy","size":28,"price":60623,"tick_direction":"ZeroPlusTick","trade_id":"b3a07d32-096c-592c-bb2e-10a8d44b29b5","cross_seq":5938958261}]}
1618677809.061276: {"topic":"orderBookL2_25.EOSUSD","type":"delta","data":{"delete":[],"update":[{"price":"7.989","symbol":"EOSUSD","id":79890,"side":"Sell","size":25211},{"price":"7.968","symbol":"EOSUSD","id":79680,"side":"Buy","size":41355},{"price":"7.965","symbol":"EOSUSD","id":79650,"side":"Buy","size":82250},{"price":"7.966","symbol":"EOSUSD","id":79660,"side":"Buy","size":10575},{"price":"7.969","symbol":"EOSUSD","id":79690,"side":"Buy","size":19835},{"price":"7.990","symbol":"EOSUSD","id":79900,"side":"Sell","size":19619}],"insert":[],"transactTimeE6":0},"cross_seq":1225778670,"timestamp_e6":1618677808978101}
1618677809.2014232: {"topic":"orderBookL2_25.EOSUSD","type":"delta","data":{"delete":[],"update":[{"price":"7.967","symbol":"EOSUSD","id":79670,"side":"Buy","size":45656},{"price":"7.965","symbol":"EOSUSD","id":79650,"side":"Buy","size":92101},{"price":"7.969","symbol":"EOSUSD","id":79690,"side":"Buy","size":48360},{"price":"7.966","symbol":"EOSUSD","id":79660,"side":"Buy","size":30563},{"price":"7.991","symbol":"EOSUSD","id":79910,"side":"Sell","size":83032}],"insert":[],"transactTimeE6":0},"cross_seq":1225778675,"timestamp_e6":1618677809118111}
1618677809.242995: {"topic":"orderBookL2_25.BTCUSD","type":"delta","data":{"delete":[{"price":"60606.00","symbol":"BTCUSD","id":606060000,"side":"Buy"}],"update":[{"price":"60622.50","symbol":"BTCUSD","id":606225000,"side":"Buy","size":12333415}],"insert":[{"price":"60605.50","symbol":"BTCUSD","id":606055000,"side":"Buy","size":116695}],"transactTimeE6":0},"cross_seq":5938958280,"timestamp_e6":1618677809158036}
1618677809.321281: {"topic":"orderBookL2_25.EOSUSD","type":"delta","data":{"delete":[],"update":[{"price":"7.979","symbol":"EOSUSD","id":79790,"side":"Sell","size":9914}],"insert":[],"transactTimeE6":0},"cross_seq":1225778676,"timestamp_e6":1618677809238828}
1618677809.359332: {"topic":"trade.EOSUSD","data":[{"trade_time_ms":1618677809218,"timestamp":"2021-04-17T16:43:29.000Z","symbol":"EOSUSD","side":"Buy","size":10,"price":7.979,"tick_direction":"PlusTick","trade_id":"b6360c14-0a40-5936-b921-78d7f58249d8","cross_seq":1225778676}]}
1618677809.441607: {"topic":"orderBookL2_25.EOSUSD","type":"delta","data":{"delete":[],"update":[{"price":"7.987","symbol":"EOSUSD","id":79870,"side":"Sell","size":30301}],"insert":[],"transactTimeE6":0},"cross_seq":1225778677,"timestamp_e6":1618677809358108}
1618677809.461238: {"topic":"orderBookL2_25.BTCUSD","type":"delta","data":{"delete":[],"update":[{"price":"60618.00","symbol":"BTCUSD","id":606180000,"side":"Buy","size":1393}],"insert":[],"transactTimeE6":0},"cross_seq":5938958299,"timestamp_e6":1618677809377374}
1618677809.5022411: {"topic":"orderBookL2_25.EOSUSD","type":"delta","data":{"delete":[],"update":[{"price":"7.987","symbol":"EOSUSD","id":79870,"side":"Sell","size":39667},{"price":"7.967","symbol":"EOSUSD","id":79670,"side":"Buy","size":61458},{"price":"7.969","symbol":"EOSUSD","id":79690,"side":"Buy","size":75957},{"price":"7.968","symbol":"EOSUSD","id":79680,"side":"Buy","size":77013},{"price":"7.972","symbol":"EOSUSD","id":79720,"side":"Buy","size":54183},{"price":"7.989","symbol":"EOSUSD","id":79890,"side":"Sell","size":30973},{"price":"7.986","symbol":"EOSUSD","id":79860,"side":"Sell","size":57123},{"price":"7.971","symbol":"EOSUSD","id":79710,"side":"Buy","size":53405},{"price":"7.970","symbol":"EOSUSD","id":79700,"side":"Buy","size":82997},{"price":"7.988","symbol":"EOSUSD","id":79880,"side":"Sell","size":39471}],"insert":[],"transactTimeE6":0},"cross_seq":1225778687,"timestamp_e6":1618677809418149}
1618677809.5418072: {"topic":"orderBookL2_25.EOSUSD","type":"delta","data":{"delete":[{"price":"8.005","symbol":"EOSUSD","id":80050,"side":"Sell"},{"price":"7.972","symbol":"EOSUSD","id":79720,"side":"Buy"}],"update":[{"price":"7.987","symbol":"EOSUSD","id":79870,"side":"Sell","size":27704},{"price":"7.983","symbol":"EOSUSD","id":79830,"side":"Sell","size":89200},{"price":"7.988","symbol":"EOSUSD","id":79880,"side":"Sell","size":26808},{"price":"7.966","symbol":"EOSUSD","id":79660,"side":"Buy","size":50863},{"price":"7.985","symbol":"EOSUSD","id":79850,"side":"Sell","size":69995},{"price":"7.967","symbol":"EOSUSD","id":79670,"side":"Buy","size":75293}],"insert":[{"price":"7.950","symbol":"EOSUSD","id":79500,"side":"Buy","size":26783},{"price":"7.984","symbol":"EOSUSD","id":79840,"side":"Sell","size":30663}],"transactTimeE6":0},"cross_seq":1225778698,"timestamp_e6":1618677809458128}
1618677809.561854: {"topic":"orderBookL2_25.EOSUSD","type":"delta","data":{"delete":[{"price":"7.950","symbol":"EOSUSD","id":79500,"side":"Buy"}],"update":[],"insert":[{"price":"7.974","symbol":"EOSUSD","id":79740,"side":"Buy","size":54135}],"transactTimeE6":0},"cross_seq":1225778699,"timestamp_e6":1618677809478113}
1618677809.580786: {"topic":"orderBookL2_25.EOSUSD","type":"delta","data":{"delete":[],"update":[{"price":"7.987","symbol":"EOSUSD","id":79870,"side":"Sell","size":35260},{"price":"7.988","symbol":"EOSUSD","id":79880,"side":"Sell","size":31614}],"insert":[],"transactTimeE6":0},"cross_seq":1225778701,"timestamp_e6":1618677809498115}
1618677809.6212769: {"topic":"orderBookL2_25.EOSUSD","type":"delta","data":{"delete":[],"update":[{"price":"7.987","symbol":"EOSUSD","id":79870,"side":"Sell","size":38797}],"insert":[],"transactTimeE6":0},"cross_seq":1225778702,"timestamp_e6":1618677809538117}
1618677809.641744: {"topic":"orderBookL2_25.EOSUSD","type":"delta","data":{"delete":[],"update":[{"price":"7.987","symbol":"EOSUSD","id":79870,"side":"Sell","size":20499},{"price":"7.989","symbol":"EOSUSD","id":79890,"side":"Sell","size":25876},{"price":"7.985","symbol":"EOSUSD","id":79850,"side":"Sell","size":99449},{"price":"7.988","symbol":"EOSUSD","id":79880,"side":"Sell","size":14496}],"insert":[],"transactTimeE6":0},"cross_seq":1225778706,"timestamp_e6":1618677809558118}
1618677809.702544: {"topic":"orderBookL2_25.BTCUSD","type":"delta","data":{"delete":[{"price":"60605.50","symbol":"BTCUSD","id":606055000,"side":"Buy"}],"update":[],"insert":[{"price":"60606.00","symbol":"BTCUSD","id":606060000,"side":"Buy","size":56014}],"transactTimeE6":0},"cross_seq":5938958314,"timestamp_e6":1618677809617353}
1618677809.702658: {"topic":"orderBookL2_25.EOSUSD","type":"delta","data":{"delete":[],"update":[{"price":"7.988","symbol":"EOSUSD","id":79880,"side":"Sell","size":22784},{"price":"7.987","symbol":"EOSUSD","id":79870,"side":"Sell","size":34877},{"price":"7.990","symbol":"EOSUSD","id":79900,"side":"Sell","size":21731}],"insert":[],"transactTimeE6":0},"cross_seq":1225778709,"timestamp_e6":1618677809618092}
1618677809.762122: {"topic":"orderBookL2_25.EOSUSD","type":"delta","data":{"delete":[],"update":[{"price":"7.970","symbol":"EOSUSD","id":79700,"side":"Buy","size":96221}],"insert":[],"transactTimeE6":0},"cross_seq":1225778710,"timestamp_e6":1618677809678274}
1618677809.802272: {"topic":"orderBookL2_25.BTCUSD","type":"delta","data":{"delete":[],"update":[{"price":"60623.00","symbol":"BTCUSD","id":606230000,"side":"Sell","size":1672593}],"insert":[],"transactTimeE6":0},"cross_seq":5938958315,"timestamp_e6":1618677809717984}
1618677809.82102: {"topic":"orderBookL2_25.EOSUSD","type":"delta","data":{"delete":[],"update":[{"price":"7.986","symbol":"EOSUSD","id":79860,"side":"Sell","size":28142}],"insert":[],"transactTimeE6":0},"cross_seq":1225778711,"timestamp_e6":1618677809738294}
1618677809.902165: {"topic":"orderBookL2_25.BTCUSD","type":"delta","data":{"delete":[{"price":"60606.00","symbol":"BTCUSD","id":606060000,"side":"Buy"}],"update":[{"price":"60623.00","symbol":"BTCUSD","id":606230000,"side":"Sell","size":1627834}],"insert":[{"price":"60605.50","symbol":"BTCUSD","id":606055000,"side":"Buy","size":116695}],"transactTimeE6":0},"cross_seq":5938958318,"timestamp_e6":1618677809818016}
1618677809.955791: {"topic":"trade.BTCUSD","data":[{"trade_time_ms":1618677809810,"timestamp":"2021-04-17T16:43:29.000Z","symbol":"BTCUSD","side":"Buy","size":44759,"price":60623,"tick_direction":"ZeroPlusTick","trade_id":"e0f5366b-5081-524c-83eb-a59781b9065d","cross_seq":5938958321}]}
1618677809.962225: {"topic":"orderBookL2_25.BTCUSD","type":"delta","data":{"delete":[],"update":[{"price":"60618.00","symbol":"BTCUSD","id":606180000,"side":"Buy","size":1396}],"insert":[],"transactTimeE6":0},"cross_seq":5938958321,"timestamp_e6":1618677809877447}
1618677809.962285: {"topic":"orderBookL2_25.EOSUSD","type":"delta","data":{"delete":[],"update":[{"price":"7.989","symbol":"EOSUSD","id":79890,"side":"Sell","size":35409},{"price":"7.986","symbol":"EOSUSD","id":79860,"side":"Sell","size":52132},{"price":"7.969","symbol":"EOSUSD","id":79690,"side":"Buy","size":87375},{"price":"7.965","symbol":"EOSUSD","id":79650,"side":"Buy","size":101800}],"insert":[],"transactTimeE6":0},"cross_seq":1225778715,"timestamp_e6":1618677809878163}
1618677809.980523: {"topic":"orderBookL2_25.BTCUSD","type":"delta","data":{"delete":[],"update":[{"price":"60622.50","symbol":"BTCUSD","id":606225000,"side":"Buy","size":12467140}],"insert":[],"transactTimeE6":0},"cross_seq":5938958322,"timestamp_e6":1618677809898025}
1618677810.021549: {"topic":"orderBookL2_25.EOSUSD","type":"delta","data":{"delete":[],"update":[{"price":"7.986","symbol":"EOSUSD","id":79860,"side":"Sell","size":38008}],"insert":[],"transactTimeE6":0},"cross_seq":1225778716,"timestamp_e6":1618677809938112}
1618677810.0610151: {"topic":"orderBookL2_25.EOSUSD","type":"delta","data":{"delete":[],"update":[{"price":"7.951","symbol":"EOSUSD","id":79510,"side":"Buy","size":99333}],"insert":[],"transactTimeE6":0},"cross_seq":1225778717,"timestamp_e6":1618677809978116}
1618677810.0811489: {"topic":"orderBookL2_25.EOSUSD","type":"delta","data":{"delete":[],"update":[{"price":"7.990","symbol":"EOSUSD","id":79900,"side":"Sell","size":16155}],"insert":[],"transactTimeE6":0},"cross_seq":1225778718,"timestamp_e6":1618677809998147}
1618677810.141432: {"topic":"orderBookL2_25.EOSUSD","type":"delta","data":{"delete":[],"update":[{"price":"7.986","symbol":"EOSUSD","id":79860,"side":"Sell","size":46871}],"insert":[],"transactTimeE6":0},"cross_seq":1225778719,"timestamp_e6":1618677810058109}
1618677810.222125: {"topic":"orderBookL2_25.EOSUSD","type":"delta","data":{"delete":[],"update":[{"price":"7.990","symbol":"EOSUSD","id":79900,"side":"Sell","size":21024}],"insert":[],"transactTimeE6":0},"cross_seq":1225778720,"timestamp_e6":1618677810138123}
1618677810.259338: {"topic":"trade.EOSUSD","data":[{"trade_time_ms":1618677810155,"timestamp":"2021-04-17T16:43:30.000Z","symbol":"EOSUSD","side":"Buy","size":10,"price":7.979,"tick_direction":"ZeroPlusTick","trade_id":"8bf4384b-36b6-5d39-a329-f3b3c6e54a3a","cross_seq":1225778721},{"trade_time_ms":1618677810155,"timestamp":"2021-04-17T16:43:30.000Z","symbol":"EOSUSD","side":"Buy","size":70,"price":7.979,"tick_direction":"ZeroPlusTick","trade_id":"ba37241b-36ec-5d78-803c-bdf88e1d8e18","cross_seq":1225778721}]}
1618677810.262617: {"topic":"orderBookL2_25.EOSUSD","type":"delta","data":{"delete":[],"update":[{"price":"7.979","symbol":"EOSUSD","id":79790,"side":"Sell","size":9834}],"insert":[],"transactTimeE6":0},"cross_seq":1225778721,"timestamp_e6":1618677810178787}
1618677810.381013: {"topic":"orderBookL2_25.EOSUSD","type":"delta","data":{"delete":[],"update":[{"price":"7.969","symbol":"EOSUSD","id":79690,"side":"Buy","size":87395}],"insert":[],"transactTimeE6":0},"cross_seq":1225778722,"timestamp_e6":1618677810298136}
1618677810.399976: {"topic":"orderBookL2_25.BTCUSD","type":"delta","data":{"delete":[{"price":"60605.50","symbol":"BTCUSD","id":606055000,"side":"Buy"}],"update":[],"insert":[{"price":"60606.00","symbol":"BTCUSD","id":606060000,"side":"Buy","size":56014}],"transactTimeE6":0},"cross_seq":5938958345,"timestamp_e6":1618677810317445}
1618677810.5218072: {"topic":"orderBookL2_25.EOSUSD","type":"delta","data":{"delete":[],"update":[{"price":"7.970","symbol":"EOSUSD","id":79700,"side":"Buy","size":66538},{"price":"7.985","symbol":"EOSUSD","id":79850,"side":"Sell","size":91021},{"price":"7.987","symbol":"EOSUSD","id":79870,"side":"Sell","size":39510},{"price":"7.986","symbol":"EOSUSD","id":79860,"side":"Sell","size":39371},{"price":"7.969","symbol":"EOSUSD","id":79690,"side":"Buy","size":67560},{"price":"7.971","symbol":"EOSUSD","id":79710,"side":"Buy","size":25162}],"insert":[],"transactTimeE6":0},"cross_seq":1225778730,"timestamp_e6":1618677810438174}
1618677810.5606232: {"topic":"orderBookL2_25.EOSUSD","type":"delta","data":{"delete":[],"update":[{"price":"7.969","symbol":"EOSUSD","id":79690,"side":"Buy","size":81366},{"price":"7.968","symbol":"EOSUSD","id":79680,"side":"Buy","size":64357},{"price":"7.971","symbol":"EOSUSD","id":79710,"side":"Buy","size":50192},{"price":"7.970","symbol":"EOSUSD","id":79700,"side":"Buy","size":75348}],"insert":[],"transactTimeE6":0},"cross_seq":1225778734,"timestamp_e6":1618677810478122}
1618677810.621908: {"topic":"orderBookL2_25.BTCUSD","type":"delta","data":{"delete":[{"price":"60606.00","symbol":"BTCUSD","id":606060000,"side":"Buy"}],"update":[],"insert":[{"price":"60605.50","symbol":"BTCUSD","id":606055000,"side":"Buy","size":116695}],"transactTimeE6":0},"cross_seq":5938958362,"timestamp_e6":1618677810537348}
1618677810.6413782: {"topic":"orderBookL2_25.EOSUSD","type":"delta","data":{"delete":[],"update":[{"price":"7.988","symbol":"EOSUSD","id":79880,"side":"Sell","size":26690},{"price":"7.987","symbol":"EOSUSD","id":79870,"side":"Sell","size":31954},{"price":"7.989","symbol":"EOSUSD","id":79890,"side":"Sell","size":27871},{"price":"7.984","symbol":"EOSUSD","id":79840,"side":"Sell","size":66426}],"insert":[],"transactTimeE6":0},"cross_seq":1225778739,"timestamp_e6":1618677810558111}
1618677810.662397: {"topic":"orderBookL2_25.EOSUSD","type":"delta","data":{"delete":[],"update":[{"price":"7.968","symbol":"EOSUSD","id":79680,"side":"Buy","size":74477},{"price":"7.985","symbol":"EOSUSD","id":79850,"side":"Sell","size":94267},{"price":"7.967","symbol":"EOSUSD","id":79670,"side":"Buy","size":60838}],"insert":[],"transactTimeE6":0},"cross_seq":1225778742,"timestamp_e6":1618677810578164}
1618677810.899982: {"topic":"orderBookL2_25.EOSUSD","type":"delta","data":{"delete":[],"update":[{"price":"7.967","symbol":"EOSUSD","id":79670,"side":"Buy","size":68310}],"insert":[],"transactTimeE6":0},"cross_seq":1225778743,"timestamp_e6":1618677810818103}
1618677810.960854: {"topic":"orderBookL2_25.BTCUSD","type":"delta","data":{"delete":[],"update":[{"price":"60630.00","symbol":"BTCUSD","id":606300000,"side":"Sell","size":147296}],"insert":[],"transactTimeE6":0},"cross_seq":5938958375,"timestamp_e6":1618677810877362}
1618677810.981588: {"topic":"orderBookL2_25.EOSUSD","type":"delta","data":{"delete":[],"update":[{"price":"7.988","symbol":"EOSUSD","id":79880,"side":"Sell","size":21884},{"price":"7.978","symbol":"EOSUSD","id":79780,"side":"Buy","size":94650},{"price":"7.969","symbol":"EOSUSD","id":79690,"side":"Buy","size":52841},{"price":"7.967","symbol":"EOSUSD","id":79670,"side":"Buy","size":45322},{"price":"7.986","symbol":"EOSUSD","id":79860,"side":"Sell","size":15381},{"price":"7.965","symbol":"EOSUSD","id":79650,"side":"Buy","size":91949}],"insert":[],"transactTimeE6":0},"cross_seq":1225778749,"timestamp_e6":1618677810898756}
1618677811.0231948: {"topic":"orderBookL2_25.BTCUSD","type":"delta","data":{"delete":[],"update":[{"price":"60623.00","symbol":"BTCUSD","id":606230000,"side":"Sell","size":1617021}],"insert":[],"transactTimeE6":0},"cross_seq":5938958377,"timestamp_e6":1618677810938122}
1618677811.042175: {"topic":"orderBookL2_25.EOSUSD","type":"delta","data":{"delete":[{"price":"7.975","symbol":"EOSUSD","id":79750,"side":"Buy"}],"update":[],"insert":[{"price":"7.977","symbol":"EOSUSD","id":79770,"side":"Buy","size":1615}],"transactTimeE6":0},"cross_seq":1225778750,"timestamp_e6":1618677810958112}
1618677811.042284: {"topic":"orderBookL2_25.BTCUSD","type":"delta","data":{"delete":[],"update":[{"price":"60622.50","symbol":"BTCUSD","id":606225000,"side":"Buy","size":12457140}],"insert":[],"transactTimeE6":0},"cross_seq":5938958378,"timestamp_e6":1618677810958007}
1618677811.056499: {"topic":"trade.BTCUSD","data":[{"trade_time_ms":1618677810914,"timestamp":"2021-04-17T16:43:30.000Z","symbol":"BTCUSD","side":"Buy","size":1000,"price":60623,"tick_direction":"ZeroPlusTick","trade_id":"46b3a822-4967-58ed-b403-a92037d9750e","cross_seq":5938958379},{"trade_time_ms":1618677810914,"timestamp":"2021-04-17T16:43:30.000Z","symbol":"BTCUSD","side":"Buy","size":9813,"price":60623,"tick_direction":"ZeroPlusTick","trade_id":"a1ef4df9-9b9f-50c6-91d2-0591c1b984b0","cross_seq":5938958379}]}
1618677811.08161: {"topic":"orderBookL2_25.EOSUSD","type":"delta","data":{"delete":[],"update":[{"price":"7.978","symbol":"EOSUSD","id":79780,"side":"Buy","size":90650}],"insert":[],"transactTimeE6":0},"cross_seq":1225778751,"timestamp_e6":1618677810998776}
1618677811.121154: {"topic":"orderBookL2_25.BTCUSD","type":"delta","data":{"delete":[{"price":"60605.50","symbol":"BTCUSD","id":606055000,"side":"Buy"}],"update":[{"price":"60623.00","symbol":"BTCUSD","id":606230000,"side":"Sell","size":1683549},{"price":"60624.50","symbol":"BTCUSD","id":606245000,"side":"Sell","size":158526},{"price":"60623.50","symbol":"BTCUSD","id":606235000,"side":"Sell","size":159567},{"price":"60625.50","symbol":"BTCUSD","id":606255000,"side":"Sell","size":68331},{"price":"60624.00","symbol":"BTCUSD","id":606240000,"side":"Sell","size":155566}],"insert":[{"price":"60606.00","symbol":"BTCUSD","id":606060000,"side":"Buy","size":56014}],"transactTimeE6":0},"cross_seq":5938958388,"timestamp_e6":1618677811038028}
1618677811.1213179: {"topic":"orderBookL2_25.EOSUSD","type":"delta","data":{"delete":[],"update":[{"price":"7.986","symbol":"EOSUSD","id":79860,"side":"Sell","size":33682},{"price":"7.967","symbol":"EOSUSD","id":79670,"side":"Buy","size":65072},{"price":"7.969","symbol":"EOSUSD","id":79690,"side":"Buy","size":81111},{"price":"7.965","symbol":"EOSUSD","id":79650,"side":"Buy","size":96375}],"insert":[],"transactTimeE6":0},"cross_seq":1225778755,"timestamp_e6":1618677811038110}
1618677811.182695: {"topic":"orderBookL2_25.BTCUSD","type":"delta","data":{"delete":[],"update":[{"price":"60622.50","symbol":"BTCUSD","id":606225000,"side":"Buy","size":12467140}],"insert":[],"transactTimeE6":0},"cross_seq":5938958392,"timestamp_e6":1618677811098285}
1618677811.182761: {"topic":"orderBookL2_25.EOSUSD","type":"delta","data":{"delete":[],"update":[{"price":"7.985","symbol":"EOSUSD","id":79850,"side":"Sell","size":109874},{"price":"7.983","symbol":"EOSUSD","id":79830,"side":"Sell","size":52536},{"price":"7.989","symbol":"EOSUSD","id":79890,"side":"Sell","size":18325},{"price":"7.988","symbol":"EOSUSD","id":79880,"side":"Sell","size":31894}],"insert":[],"transactTimeE6":0},"cross_seq":1225778760,"timestamp_e6":1618677811098162}
1618677811.241944: {"topic":"orderBookL2_25.EOSUSD","type":"delta","data":{"delete":[],"update":[{"price":"7.969","symbol":"EOSUSD","id":79690,"side":"Buy","size":69693}],"insert":[],"transactTimeE6":0},"cross_seq":1225778761,"timestamp_e6":1618677811158236}
1618677811.262743: {"topic":"orderBookL2_25.BTCUSD","type":"delta","data":{"delete":[],"update":[{"price":"60622.50","symbol":"BTCUSD","id":606225000,"side":"Buy","size":12466340}],"insert":[],"transactTimeE6":0},"cross_seq":5938958394,"timestamp_e6":1618677811178003}
1618677811.302321: {"topic":"orderBookL2_25.EOSUSD","type":"delta","data":{"delete":[],"update":[{"price":"7.989","symbol":"EOSUSD","id":79890,"side":"Sell","size":22704},{"price":"7.971","symbol":"EOSUSD","id":79710,"side":"Buy","size":25030}],"insert":[],"transactTimeE6":0},"cross_seq":1225778763,"timestamp_e6":1618677811218126}
1618677811.302451: {"topic":"orderBookL2_25.BTCUSD","type":"delta","data":{"delete":[],"update":[{"price":"60623.00","symbol":"BTCUSD","id":606230000,"side":"Sell","size":1683548}],"insert":[],"transactTimeE6":0},"cross_seq":5938958396,"timestamp_e6":1618677811218051}
1618677811.323828: {"topic":"orderBookL2_25.BTCUSD","type":"delta","data":{"delete":[{"price":"60606.00","symbol":"BTCUSD","id":606060000,"side":"Buy"}],"update":[],"insert":[{"price":"60605.50","symbol":"BTCUSD","id":606055000,"side":"Buy","size":116695}],"transactTimeE6":0},"cross_seq":5938958398,"timestamp_e6":1618677811237359}
1618677811.363768: {"topic":"orderBookL2_25.EOSUSD","type":"delta","data":{"delete":[],"update":[{"price":"7.979","symbol":"EOSUSD","id":79790,"side":"Sell","size":9267},{"price":"7.969","symbol":"EOSUSD","id":79690,"side":"Buy","size":78998}],"insert":[],"transactTimeE6":0},"cross_seq":1225778765,"timestamp_e6":1618677811278792}
1618677811.421494: {"topic":"orderBookL2_25.EOSUSD","type":"delta","data":{"delete":[],"update":[{"price":"7.971","symbol":"EOSUSD","id":79710,"side":"Buy","size":44895},{"price":"7.987","symbol":"EOSUSD","id":79870,"side":"Sell","size":22588}],"insert":[],"transactTimeE6":0},"cross_seq":1225778767,"timestamp_e6":1618677811338119}
1618677811.44303: {"topic":"orderBookL2_25.EOSUSD","type":"delta","data":{"delete":[],"update":[{"price":"7.981","symbol":"EOSUSD","id":79810,"side":"Sell","size":763}],"insert":[],"transactTimeE6":0},"cross_seq":1225778768,"timestamp_e6":1618677811358103}
1618677811.460117: {"topic":"orderBookL2_25.BTCUSD","type":"delta","data":{"delete":[],"update":[{"price":"60621.50","symbol":"BTCUSD","id":606215000,"side":"Buy","size":149315}],"insert":[],"transactTimeE6":0},"cross_seq":5938958411,"timestamp_e6":1618677811377390}
1618677811.501817: {"topic":"orderBookL2_25.EOSUSD","type":"delta","data":{"delete":[],"update":[{"price":"7.968","symbol":"EOSUSD","id":79680,"side":"Buy","size":84566},{"price":"7.984","symbol":"EOSUSD","id":79840,"side":"Sell","size":30663}],"insert":[],"transactTimeE6":0},"cross_seq":1225778770,"timestamp_e6":1618677811418122}
1618677811.542092: {"topic":"orderBookL2_25.EOSUSD","type":"delta","data":{"delete":[],"update":[{"price":"7.987","symbol":"EOSUSD","id":79870,"side":"Sell","size":33378},{"price":"7.967","symbol":"EOSUSD","id":79670,"side":"Buy","size":49270},{"price":"7.986","symbol":"EOSUSD","id":79860,"side":"Sell","size":41597},{"price":"7.979","symbol":"EOSUSD","id":79790,"side":"Sell","size":10010},{"price":"7.985","symbol":"EOSUSD","id":79850,"side":"Sell","size":97538},{"price":"7.988","symbol":"EOSUSD","id":79880,"side":"Sell","size":22545},{"price":"7.966","symbol":"EOSUSD","id":79660,"side":"Buy","size":40288}],"insert":[],"transactTimeE6":0},"cross_seq":1225778777,"timestamp_e6":1618677811458754}
1618677811.561823: {"topic":"orderBookL2_25.EOSUSD","type":"delta","data":{"delete":[],"update":[{"price":"7.981","symbol":"EOSUSD","id":79810,"side":"Sell","size":20}],"insert":[],"transactTimeE6":0},"cross_seq":1225778778,"timestamp_e6":1618677811478114}
1618677811.5813508: {"topic":"orderBookL2_25.BTCUSD","type":"delta","data":{"delete":[],"update":[{"price":"60629.50","symbol":"BTCUSD","id":606295000,"side":"Sell","size":152702},{"price":"60622.50","symbol":"BTCUSD","id":606225000,"side":"Buy","size":12772868}],"insert":[],"transactTimeE6":0},"cross_seq":5938958414,"timestamp_e6":1618677811498049}
1618677811.600592: {"topic":"orderBookL2_25.BTCUSD","type":"delta","data":{"delete":[],"update":[{"price":"60616.00","symbol":"BTCUSD","id":606160000,"side":"Buy","size":28086}],"insert":[],"transactTimeE6":0},"cross_seq":5938958415,"timestamp_e6":1618677811517352}
1618677811.620804: {"topic":"orderBookL2_25.BTCUSD","type":"delta","data":{"delete":[],"update":[{"price":"60612.00","symbol":"BTCUSD","id":606120000,"side":"Buy","size":373}],"insert":[],"transactTimeE6":0},"cross_seq":5938958416,"timestamp_e6":1618677811537371}
1618677811.6225028: {"topic":"orderBookL2_25.EOSUSD","type":"delta","data":{"delete":[],"update":[{"price":"7.984","symbol":"EOSUSD","id":79840,"side":"Sell","size":61362}],"insert":[],"transactTimeE6":0},"cross_seq":1225778779,"timestamp_e6":1618677811538127}
1618677811.641739: {"topic":"orderBookL2_25.EOSUSD","type":"delta","data":{"delete":[{"price":"7.951","symbol":"EOSUSD","id":79510,"side":"Buy"}],"update":[{"price":"7.968","symbol":"EOSUSD","id":79680,"side":"Buy","size":55867},{"price":"7.969","symbol":"EOSUSD","id":79690,"side":"Buy","size":50728},{"price":"7.971","symbol":"EOSUSD","id":79710,"side":"Buy","size":83871},{"price":"7.973","symbol":"EOSUSD","id":79730,"side":"Buy","size":83466},{"price":"7.970","symbol":"EOSUSD","id":79700,"side":"Buy","size":35497}],"insert":[{"price":"7.972","symbol":"EOSUSD","id":79720,"side":"Buy","size":35400}],"transactTimeE6":0},"cross_seq":1225778786,"timestamp_e6":1618677811558099}
1618677811.6810791: {"topic":"orderBookL2_25.EOSUSD","type":"delta","data":{"delete":[],"update":[{"price":"7.967","symbol":"EOSUSD","id":79670,"side":"Buy","size":55000}],"insert":[],"transactTimeE6":0},"cross_seq":1225778787,"timestamp_e6":1618677811598113}
1618677811.761316: {"topic":"orderBookL2_25.BTCUSD","type":"delta","data":{"delete":[],"update":[{"price":"60610.50","symbol":"BTCUSD","id":606105000,"side":"Buy","size":38}],"insert":[],"transactTimeE6":0},"cross_seq":5938958420,"timestamp_e6":1618677811677370}
1618677811.761395: {"topic":"orderBookL2_25.EOSUSD","type":"delta","data":{"delete":[],"update":[{"price":"7.970","symbol":"EOSUSD","id":79700,"side":"Buy","size":62902},{"price":"7.968","symbol":"EOSUSD","id":79680,"side":"Buy","size":60002},{"price":"7.969","symbol":"EOSUSD","id":79690,"side":"Buy","size":63693}],"insert":[],"transactTimeE6":0},"cross_seq":1225778790,"timestamp_e6":1618677811678098}
1618677811.781566: {"topic":"orderBookL2_25.EOSUSD","type":"delta","data":{"delete":[],"update":[{"price":"7.974","symbol":"EOSUSD","id":79740,"side":"Buy","size":95994},{"price":"7.972","symbol":"EOSUSD","id":79720,"side":"Buy","size":77833},{"price":"7.985","symbol":"EOSUSD","id":79850,"side":"Sell","size":137564},{"price":"7.968","symbol":"EOSUSD","id":79680,"side":"Buy","size":24344},{"price":"7.967","symbol":"EOSUSD","id":79670,"side":"Buy","size":41165}],"insert":[],"transactTimeE6":0},"cross_seq":1225778795,"timestamp_e6":1618677811698098}
1618677811.802389: {"topic":"orderBookL2_25.BTCUSD","type":"delta","data":{"delete":[],"update":[{"price":"60622.50","symbol":"BTCUSD","id":606225000,"side":"Buy","size":12762868}],"insert":[],"transactTimeE6":0},"cross_seq":5938958421,"timestamp_e6":1618677811717976}
1618677811.802457: {"topic":"orderBookL2_25.EOSUSD","type":"delta","data":{"delete":[],"update":[{"price":"7.968","symbol":"EOSUSD","id":79680,"side":"Buy","size":39829},{"price":"7.967","symbol":"EOSUSD","id":79670,"side":"Buy","size":49043},{"price":"7.986","symbol":"EOSUSD","id":79860,"side":"Sell","size":35663},{"price":"7.971","symbol":"EOSUSD","id":79710,"side":"Buy","size":58841}],"insert":[],"transactTimeE6":0},"cross_seq":1225778799,"timestamp_e6":1618677811718114}
1618677811.821416: {"topic":"orderBookL2_25.EOSUSD","type":"delta","data":{"delete":[],"update":[{"price":"7.978","symbol":"EOSUSD","id":79780,"side":"Buy","size":93238}],"insert":[],"transactTimeE6":0},"cross_seq":1225778800,"timestamp_e6":1618677811738739}
1618677811.841811: {"topic":"orderBookL2_25.BTCUSD","type":"delta","data":{"delete":[{"price":"60605.50","symbol":"BTCUSD","id":606055000,"side":"Buy"}],"update":[],"insert":[{"price":"60606.00","symbol":"BTCUSD","id":606060000,"side":"Buy","size":56014}],"transactTimeE6":0},"cross_seq":5938958424,"timestamp_e6":1618677811757356}
1618677811.8615081: {"topic":"orderBookL2_25.BTCUSD","type":"delta","data":{"delete":[],"update":[{"price":"60623.00","symbol":"BTCUSD","id":606230000,"side":"Sell","size":1674248}],"insert":[],"transactTimeE6":0},"cross_seq":5938958426,"timestamp_e6":1618677811777960}
1618677811.9223669: {"topic":"orderBookL2_25.BTCUSD","type":"delta","data":{"delete":[],"update":[{"price":"60623.00","symbol":"BTCUSD","id":606230000,"side":"Sell","size":1664359}],"insert":[],"transactTimeE6":0},"cross_seq":5938958429,"timestamp_e6":1618677811837999}
1618677811.9405608: {"topic":"orderBookL2_25.EOSUSD","type":"delta","data":{"delete":[],"update":[{"price":"7.971","symbol":"EOSUSD","id":79710,"side":"Buy","size":78749}],"insert":[],"transactTimeE6":0},"cross_seq":1225778801,"timestamp_e6":1618677811858125}
1618677811.941024: {"topic":"orderBookL2_25.BTCUSD","type":"delta","data":{"delete":[],"update":[{"price":"60622.50","symbol":"BTCUSD","id":606225000,"side":"Buy","size":12762858}],"insert":[],"transactTimeE6":0},"cross_seq":5938958430,"timestamp_e6":1618677811858023}
1618677811.956057: {"topic":"trade.BTCUSD","data":[{"trade_time_ms":1618677811814,"timestamp":"2021-04-17T16:43:31.000Z","symbol":"BTCUSD","side":"Buy","size":9889,"price":60623,"tick_direction":"ZeroPlusTick","trade_id":"882140c9-03a1-521f-80ba-dbd9679147b2","cross_seq":5938958431}]}
1618677812.001487: {"topic":"orderBookL2_25.EOSUSD","type":"delta","data":{"delete":[],"update":[{"price":"7.968","symbol":"EOSUSD","id":79680,"side":"Buy","size":45589},{"price":"7.988","symbol":"EOSUSD","id":79880,"side":"Sell","size":14257},{"price":"7.986","symbol":"EOSUSD","id":79860,"side":"Sell","size":40624},{"price":"7.987","symbol":"EOSUSD","id":79870,"side":"Sell","size":37839}],"insert":[],"transactTimeE6":0},"cross_seq":1225778805,"timestamp_e6":1618677811918118}
1618677812.001568: {"topic":"orderBookL2_25.BTCUSD","type":"delta","data":{"delete":[],"update":[{"price":"60622.50","symbol":"BTCUSD","id":606225000,"side":"Buy","size":12762868}],"insert":[],"transactTimeE6":0},"cross_seq":5938958433,"timestamp_e6":1618677811918069}
1618677812.0223072: {"topic":"orderBookL2_25.BTCUSD","type":"delta","data":{"delete":[],"update":[{"price":"60622.50","symbol":"BTCUSD","id":606225000,"side":"Buy","size":12762858}],"insert":[],"transactTimeE6":0},"cross_seq":5938958434,"timestamp_e6":1618677811938028}
1618677812.040573: {"topic":"orderBookL2_25.BTCUSD","type":"delta","data":{"delete":[{"price":"60606.00","symbol":"BTCUSD","id":606060000,"side":"Buy"}],"update":[],"insert":[{"price":"60605.50","symbol":"BTCUSD","id":606055000,"side":"Buy","size":116695}],"transactTimeE6":0},"cross_seq":5938958435,"timestamp_e6":1618677811957396}
1618677812.0562: {"topic":"trade.BTCUSD","data":[{"trade_time_ms":1618677811956,"timestamp":"2021-04-17T16:43:31.000Z","symbol":"BTCUSD","side":"Buy","size":35360,"price":60623,"tick_direction":"ZeroPlusTick","trade_id":"118093d4-40c1-5b11-a111-9e2cfbeda2e6","cross_seq":5938958436},{"trade_time_ms":1618677811956,"timestamp":"2021-04-17T16:43:31.000Z","symbol":"BTCUSD","side":"Buy","size":12186,"price":60623,"tick_direction":"ZeroPlusTick","trade_id":"4d4ea708-db1d-5cea-a2d6-9f5d53ef8776","cross_seq":5938958436}]}
1618677812.0617468: {"topic":"orderBookL2_25.EOSUSD","type":"delta","data":{"delete":[],"update":[{"price":"7.984","symbol":"EOSUSD","id":79840,"side":"Sell","size":70025}],"insert":[],"transactTimeE6":0},"cross_seq":1225778806,"timestamp_e6":1618677811978072}
1618677812.0618281: {"topic":"orderBookL2_25.BTCUSD","type":"delta","data":{"delete":[],"update":[{"price":"60623.00","symbol":"BTCUSD","id":606230000,"side":"Sell","size":1616813}],"insert":[],"transactTimeE6":0},"cross_seq":5938958437,"timestamp_e6":1618677811978046}
1618677812.081291: {"topic":"orderBookL2_25.BTCUSD","type":"delta","data":{"delete":[],"update":[{"price":"60622.50","symbol":"BTCUSD","id":606225000,"side":"Buy","size":12762868}],"insert":[],"transactTimeE6":0},"cross_seq":5938958438,"timestamp_e6":1618677811997982}
1618677812.100542: {"topic":"orderBookL2_25.BTCUSD","type":"delta","data":{"delete":[],"update":[{"price":"60618.00","symbol":"BTCUSD","id":606180000,"side":"Buy","size":1393}],"insert":[],"transactTimeE6":0},"cross_seq":5938958439,"timestamp_e6":1618677812017356}
1618677812.122087: {"topic":"orderBookL2_25.BTCUSD","type":"delta","data":{"delete":[],"update":[{"price":"60625.00","symbol":"BTCUSD","id":606250000,"side":"Sell","size":64785},{"price":"60625.50","symbol":"BTCUSD","id":606255000,"side":"Sell","size":16806},{"price":"60623.00","symbol":"BTCUSD","id":606230000,"side":"Sell","size":1679199},{"price":"60624.00","symbol":"BTCUSD","id":606240000,"side":"Sell","size":182040},{"price":"60624.50","symbol":"BTCUSD","id":606245000,"side":"Sell","size":101297},{"price":"60622.50","symbol":"BTCUSD","id":606225000,"side":"Buy","size":12762872},{"price":"60623.50","symbol":"BTCUSD","id":606235000,"side":"Sell","size":187818}],"insert":[],"transactTimeE6":0},"cross_seq":5938958452,"timestamp_e6":1618677812038637}
1618677812.140594: {"topic":"orderBookL2_25.EOSUSD","type":"delta","data":{"delete":[],"update":[{"price":"7.988","symbol":"EOSUSD","id":79880,"side":"Sell","size":19865}],"insert":[],"transactTimeE6":0},"cross_seq":1225778807,"timestamp_e6":1618677812058141}
1618677812.142743: {"topic":"orderBookL2_25.BTCUSD","type":"delta","data":{"delete":[],"update":[{"price":"60622.50","symbol":"BTCUSD","id":606225000,"side":"Buy","size":12762862}],"insert":[],"transactTimeE6":0},"cross_seq":5938958453,"timestamp_e6":1618677812057998}
1618677812.1818619: {"topic":"orderBookL2_25.EOSUSD","type":"delta","data":{"delete":[],"update":[{"price":"7.984","symbol":"EOSUSD","id":79840,"side":"Sell","size":39362}],"insert":[],"transactTimeE6":0},"cross_seq":1225778808,"timestamp_e6":1618677812098134}
1618677812.181921: {"topic":"orderBookL2_25.BTCUSD","type":"delta","data":{"delete":[],"update":[{"price":"60623.00","symbol":"BTCUSD","id":606230000,"side":"Sell","size":1679200}],"insert":[],"transactTimeE6":0},"cross_seq":5938958454,"timestamp_e6":1618677812098039}
1618677812.2612338: {"topic":"orderBookL2_25.EOSUSD","type":"delta","data":{"delete":[],"update":[{"price":"7.972","symbol":"EOSUSD","id":79720,"side":"Buy","size":42433}],"insert":[],"transactTimeE6":0},"cross_seq":1225778810,"timestamp_e6":1618677812178155}
1618677812.321335: {"topic":"orderBookL2_25.EOSUSD","type":"delta","data":{"delete":[],"update":[{"price":"7.984","symbol":"EOSUSD","id":79840,"side":"Sell","size":64477}],"insert":[],"transactTimeE6":0},"cross_seq":1225778811,"timestamp_e6":1618677812238116}
1618677812.382402: {"topic":"orderBookL2_25.EOSUSD","type":"delta","data":{"delete":[],"update":[{"price":"7.985","symbol":"EOSUSD","id":79850,"side":"Sell","size":108110},{"price":"7.972","symbol":"EOSUSD","id":79720,"side":"Buy","size":72005}],"insert":[],"transactTimeE6":0},"cross_seq":1225778813,"timestamp_e6":1618677812298175}
1618677812.401933: {"topic":"orderBookL2_25.EOSUSD","type":"delta","data":{"delete":[],"update":[{"price":"7.972","symbol":"EOSUSD","id":79720,"side":"Buy","size":29572},{"price":"7.969","symbol":"EOSUSD","id":79690,"side":"Buy","size":36096},{"price":"7.973","symbol":"EOSUSD","id":79730,"side":"Buy","size":124520},{"price":"7.986","symbol":"EOSUSD","id":79860,"side":"Sell","size":46600}],"insert":[],"transactTimeE6":0},"cross_seq":1225778817,"timestamp_e6":1618677812318173}
1618677812.441726: {"topic":"orderBookL2_25.EOSUSD","type":"delta","data":{"delete":[],"update":[{"price":"7.969","symbol":"EOSUSD","id":79690,"side":"Buy","size":47263},{"price":"7.986","symbol":"EOSUSD","id":79860,"side":"Sell","size":37737},{"price":"7.972","symbol":"EOSUSD","id":79720,"side":"Buy","size":69932}],"insert":[],"transactTimeE6":0},"cross_seq":1225778820,"timestamp_e6":1618677812358128}
1618677812.481576: {"topic":"orderBookL2_25.BTCUSD","type":"delta","data":{"delete":[],"update":[{"price":"60623.00","symbol":"BTCUSD","id":606230000,"side":"Sell","size":1679147}],"insert":[],"transactTimeE6":0},"cross_seq":5938958459,"timestamp_e6":1618677812398016}
1618677812.522064: {"topic":"orderBookL2_25.EOSUSD","type":"delta","data":{"delete":[],"update":[{"price":"7.985","symbol":"EOSUSD","id":79850,"side":"Sell","size":134678}],"insert":[],"transactTimeE6":0},"cross_seq":1225778821,"timestamp_e6":1618677812438106}
1618677812.5431309: {"topic":"orderBookL2_25.BTCUSD","type":"delta","data":{"delete":[{"price":"60605.50","symbol":"BTCUSD","id":606055000,"side":"Buy"}],"update":[{"price":"60622.50","symbol":"BTCUSD","id":606225000,"side":"Buy","size":12772872}],"insert":[{"price":"60606.00","symbol":"BTCUSD","id":606060000,"side":"Buy","size":56014}],"transactTimeE6":0},"cross_seq":5938958463,"timestamp_e6":1618677812458112}
1618677812.557893: {"topic":"trade.BTCUSD","data":[{"trade_time_ms":1618677812382,"timestamp":"2021-04-17T16:43:32.000Z","symbol":"BTCUSD","side":"Buy","size":53,"price":60623,"tick_direction":"ZeroPlusTick","trade_id":"d21bac41-b803-5d8b-871a-d3fea0053afc","cross_seq":5938958463}]}
1618677812.560878: {"topic":"orderBookL2_25.BTCUSD","type":"delta","data":{"delete":[],"update":[{"price":"60618.00","symbol":"BTCUSD","id":606180000,"side":"Buy","size":1396}],"insert":[],"transactTimeE6":0},"cross_seq":5938958464,"timestamp_e6":1618677812477342}
1618677812.581393: {"topic":"orderBookL2_25.BTCUSD","type":"delta","data":{"delete":[],"update":[{"price":"60622.50","symbol":"BTCUSD","id":606225000,"side":"Buy","size":12772862}],"insert":[],"transactTimeE6":0},"cross_seq":5938958466,"timestamp_e6":1618677812497953}
1618677812.5834649: {"topic":"orderBookL2_25.EOSUSD","type":"delta","data":{"delete":[],"update":[{"price":"7.985","symbol":"EOSUSD","id":79850,"side":"Sell","size":141649},{"price":"7.989","symbol":"EOSUSD","id":79890,"side":"Sell","size":25951},{"price":"7.987","symbol":"EOSUSD","id":79870,"side":"Sell","size":29669},{"price":"7.972","symbol":"EOSUSD","id":79720,"side":"Buy","size":29572},{"price":"7.988","symbol":"EOSUSD","id":79880,"side":"Sell","size":27027},{"price":"7.969","symbol":"EOSUSD","id":79690,"side":"Buy","size":33457},{"price":"7.968","symbol":"EOSUSD","id":79680,"side":"Buy","size":35469}],"insert":[],"transactTimeE6":0},"cross_seq":1225778829,"timestamp_e6":1618677812498094}
1618677812.622061: {"topic":"orderBookL2_25.BTCUSD","type":"delta","data":{"delete":[],"update":[{"price":"60622.50","symbol":"BTCUSD","id":606225000,"side":"Buy","size":12762862}],"insert":[],"transactTimeE6":0},"cross_seq":5938958467,"timestamp_e6":1618677812538130}
1618677812.702469: {"topic":"orderBookL2_25.EOSUSD","type":"delta","data":{"delete":[],"update":[{"price":"7.969","symbol":"EOSUSD","id":79690,"side":"Buy","size":43482},{"price":"7.968","symbol":"EOSUSD","id":79680,"side":"Buy","size":43663},{"price":"7.972","symbol":"EOSUSD","id":79720,"side":"Buy","size":70473},{"price":"7.971","symbol":"EOSUSD","id":79710,"side":"Buy","size":58884}],"insert":[],"transactTimeE6":0},"cross_seq":1225778833,"timestamp_e6":1618677812618107}
1618677812.762073: {"topic":"orderBookL2_25.BTCUSD","type":"delta","data":{"delete":[],"update":[{"price":"60622.50","symbol":"BTCUSD","id":606225000,"side":"Buy","size":12762866}],"insert":[],"transactTimeE6":0},"cross_seq":5938958468,"timestamp_e6":1618677812677920}
1618677812.780788: {"topic":"orderBookL2_25.BTCUSD","type":"delta","data":{"delete":[{"price":"60606.00","symbol":"BTCUSD","id":606060000,"side":"Buy"}],"update":[],"insert":[{"price":"60605.50","symbol":"BTCUSD","id":606055000,"side":"Buy","size":116695}],"transactTimeE6":0},"cross_seq":5938958469,"timestamp_e6":1618677812697365}
1618677812.801097: {"topic":"orderBookL2_25.BTCUSD","type":"delta","data":{"delete":[],"update":[{"price":"60605.50","symbol":"BTCUSD","id":606055000,"side":"Buy","size":100098},{"price":"60622.50","symbol":"BTCUSD","id":606225000,"side":"Buy","size":12762836}],"insert":[],"transactTimeE6":0},"cross_seq":5938958474,"timestamp_e6":1618677812718014}
1618677812.82153: {"topic":"orderBookL2_25.EOSUSD","type":"delta","data":{"delete":[],"update":[{"price":"7.971","symbol":"EOSUSD","id":79710,"side":"Buy","size":74547}],"insert":[],"transactTimeE6":0},"cross_seq":1225778834,"timestamp_e6":1618677812738165}
1618677812.8223: {"topic":"orderBookL2_25.BTCUSD","type":"delta","data":{"delete":[],"update":[{"price":"60622.50","symbol":"BTCUSD","id":606225000,"side":"Buy","size":12772836}],"insert":[],"transactTimeE6":0},"cross_seq":5938958477,"timestamp_e6":1618677812738773}
1618677812.842717: {"topic":"orderBookL2_25.BTCUSD","type":"delta","data":{"delete":[],"update":[{"price":"60622.50","symbol":"BTCUSD","id":606225000,"side":"Buy","size":12774399}],"insert":[],"transactTimeE6":0},"cross_seq":5938958480,"timestamp_e6":1618677812757937}
1618677812.861826: {"topic":"orderBookL2_25.BTCUSD","type":"delta","data":{"delete":[],"update":[{"price":"60622.50","symbol":"BTCUSD","id":606225000,"side":"Buy","size":12778619}],"insert":[],"transactTimeE6":0},"cross_seq":5938958483,"timestamp_e6":1618677812778005}
1618677812.8819609: {"topic":"orderBookL2_25.EOSUSD","type":"delta","data":{"delete":[],"update":[{"price":"7.978","symbol":"EOSUSD","id":79780,"side":"Buy","size":97238}],"insert":[],"transactTimeE6":0},"cross_seq":1225778835,"timestamp_e6":1618677812798872}
1618677812.903471: {"topic":"orderBookL2_25.BTCUSD","type":"delta","data":{"delete":[],"update":[{"price":"60622.50","symbol":"BTCUSD","id":606225000,"side":"Buy","size":12768619}],"insert":[],"transactTimeE6":0},"cross_seq":5938958484,"timestamp_e6":1618677812818045}
1618677812.903559: {"topic":"orderBookL2_25.EOSUSD","type":"delta","data":{"delete":[],"update":[{"price":"7.987","symbol":"EOSUSD","id":79870,"side":"Sell","size":15291}],"insert":[],"transactTimeE6":0},"cross_seq":1225778836,"timestamp_e6":1618677812818134}
1618677812.9232168: {"topic":"orderBookL2_25.EOSUSD","type":"delta","data":{"delete":[],"update":[{"price":"7.978","symbol":"EOSUSD","id":79780,"side":"Buy","size":101238}],"insert":[],"transactTimeE6":0},"cross_seq":1225778837,"timestamp_e6":1618677812838749}
1618677812.941175: {"topic":"orderBookL2_25.EOSUSD","type":"delta","data":{"delete":[{"price":"8.004","symbol":"EOSUSD","id":80040,"side":"Sell"}],"update":[{"price":"7.988","symbol":"EOSUSD","id":79880,"side":"Sell","size":17017},{"price":"7.989","symbol":"EOSUSD","id":79890,"side":"Sell","size":96408},{"price":"7.984","symbol":"EOSUSD","id":79840,"side":"Sell","size":30699},{"price":"7.987","symbol":"EOSUSD","id":79870,"side":"Sell","size":47056},{"price":"7.983","symbol":"EOSUSD","id":79830,"side":"Sell","size":62367},{"price":"7.981","symbol":"EOSUSD","id":79810,"side":"Sell","size":29533},{"price":"7.990","symbol":"EOSUSD","id":79900,"side":"Sell","size":73700},{"price":"7.970","symbol":"EOSUSD","id":79700,"side":"Buy","size":49439},{"price":"7.982","symbol":"EOSUSD","id":79820,"side":"Sell","size":16629},{"price":"7.992","symbol":"EOSUSD","id":79920,"side":"Sell","size":80011},{"price":"7.985","symbol":"EOSUSD","id":79850,"side":"Sell","size":122796},{"price":"7.986","symbol":"EOSUSD","id":79860,"side":"Sell","size":113226},{"price":"7.974","symbol":"EOSUSD","id":79740,"side":"Buy","size":140698}],"insert":[{"price":"7.980","symbol":"EOSUSD","id":79800,"side":"Sell","size":33239}],"transactTimeE6":0},"cross_seq":1225778854,"timestamp_e6":1618677812858100}
1618677812.9634109: {"topic":"orderBookL2_25.EOSUSD","type":"delta","data":{"delete":[],"update":[{"price":"7.974","symbol":"EOSUSD","id":79740,"side":"Buy","size":95994},{"price":"7.985","symbol":"EOSUSD","id":79850,"side":"Sell","size":129084},{"price":"7.979","symbol":"EOSUSD","id":79790,"side":"Sell","size":9267},{"price":"7.973","symbol":"EOSUSD","id":79730,"side":"Buy","size":83466},{"price":"7.971","symbol":"EOSUSD","id":79710,"side":"Buy","size":54639},{"price":"7.984","symbol":"EOSUSD","id":79840,"side":"Sell","size":49047},{"price":"7.981","symbol":"EOSUSD","id":79810,"side":"Sell","size":20},{"price":"7.983","symbol":"EOSUSD","id":79830,"side":"Sell","size":63033}],"insert":[],"transactTimeE6":0},"cross_seq":1225778862,"timestamp_e6":1618677812878785}
1618677813.001896: {"topic":"orderBookL2_25.BTCUSD","type":"delta","data":{"delete":[],"update":[{"price":"60622.50","symbol":"BTCUSD","id":606225000,"side":"Buy","size":12778619}],"insert":[],"transactTimeE6":0},"cross_seq":5938958493,"timestamp_e6":1618677812918061}
1618677813.0019991: {"topic":"orderBookL2_25.EOSUSD","type":"delta","data":{"delete":[],"update":[{"price":"7.989","symbol":"EOSUSD","id":79890,"side":"Sell","size":106639},{"price":"7.987","symbol":"EOSUSD","id":79870,"side":"Sell","size":42595},{"price":"7.985","symbol":"EOSUSD","id":79850,"side":"Sell","size":102516},{"price":"7.990","symbol":"EOSUSD","id":79900,"side":"Sell","size":86624},{"price":"7.988","symbol":"EOSUSD","id":79880,"side":"Sell","size":44160},{"price":"7.971","symbol":"EOSUSD","id":79710,"side":"Buy","size":15663},{"price":"7.969","symbol":"EOSUSD","id":79690,"side":"Buy","size":34177},{"price":"7.991","symbol":"EOSUSD","id":79910,"side":"Sell","size":91127},{"price":"7.984","symbol":"EOSUSD","id":79840,"side":"Sell","size":18348},{"price":"7.986","symbol":"EOSUSD","id":79860,"side":"Sell","size":89964},{"price":"7.992","symbol":"EOSUSD","id":79920,"side":"Sell","size":62563},{"price":"7.993","symbol":"EOSUSD","id":79930,"side":"Sell","size":12185}],"insert":[],"transactTimeE6":0},"cross_seq":1225778877,"timestamp_e6":1618677812918123}
1618677813.0209558: {"topic":"orderBookL2_25.EOSUSD","type":"delta","data":{"delete":[],"update":[{"price":"7.993","symbol":"EOSUSD","id":79930,"side":"Sell","size":20776},{"price":"7.992","symbol":"EOSUSD","id":79920,"side":"Sell","size":79209},{"price":"7.971","symbol":"EOSUSD","id":79710,"side":"Buy","size":42931},{"price":"7.972","symbol":"EOSUSD","id":79720,"side":"Buy","size":79632},{"price":"7.983","symbol":"EOSUSD","id":79830,"side":"Sell","size":62367},{"price":"7.969","symbol":"EOSUSD","id":79690,"side":"Buy","size":39992}],"insert":[],"transactTimeE6":0},"cross_seq":1225778888,"timestamp_e6":1618677812938132}
1618677813.082322: {"topic":"orderBookL2_25.BTCUSD","type":"delta","data":{"delete":[],"update":[{"price":"60623.00","symbol":"BTCUSD","id":606230000,"side":"Sell","size":1674311}],"insert":[],"transactTimeE6":0},"cross_seq":5938958495,"timestamp_e6":1618677812998025}
1618677813.0824142: {"topic":"orderBookL2_25.EOSUSD","type":"delta","data":{"delete":[],"update":[{"price":"7.978","symbol":"EOSUSD","id":79780,"side":"Buy","size":93238},{"price":"7.971","symbol":"EOSUSD","id":79710,"side":"Buy","size":60959},{"price":"7.973","symbol":"EOSUSD","id":79730,"side":"Buy","size":117824},{"price":"7.974","symbol":"EOSUSD","id":79740,"side":"Buy","size":136671},{"price":"7.981","symbol":"EOSUSD","id":79810,"side":"Sell","size":25314}],"insert":[],"transactTimeE6":0},"cross_seq":1225778894,"timestamp_e6":1618677812999022}
1618677813.10206: {"topic":"orderBookL2_25.BTCUSD","type":"delta","data":{"delete":[],"update":[{"price":"60622.50","symbol":"BTCUSD","id":606225000,"side":"Buy","size":12768619}],"insert":[],"transactTimeE6":0},"cross_seq":5938958498,"timestamp_e6":1618677813018011}
1618677813.102151: {"topic":"orderBookL2_25.EOSUSD","type":"delta","data":{"delete":[],"update":[{"price":"7.992","symbol":"EOSUSD","id":79920,"side":"Sell","size":62563}],"insert":[],"transactTimeE6":0},"cross_seq":1225778895,"timestamp_e6":1618677813018117}
1618677813.122699: {"topic":"orderBookL2_25.EOSUSD","type":"delta","data":{"delete":[],"update":[{"price":"7.992","symbol":"EOSUSD","id":79920,"side":"Sell","size":77044}],"insert":[],"transactTimeE6":0},"cross_seq":1225778896,"timestamp_e6":1618677813038131}
1618677813.160668: {"topic":"trade.BTCUSD","data":[{"trade_time_ms":1618677812971,"timestamp":"2021-04-17T16:43:32.000Z","symbol":"BTCUSD","side":"Buy","size":4836,"price":60623,"tick_direction":"ZeroPlusTick","trade_id":"adc90c47-babc-513e-896f-5c44faa37c08","cross_seq":5938958498}]}
1618677813.183532: {"topic":"orderBookL2_25.BTCUSD","type":"delta","data":{"delete":[],"update":[{"price":"60622.50","symbol":"BTCUSD","id":606225000,"side":"Buy","size":12768615}],"insert":[],"transactTimeE6":0},"cross_seq":5938958499,"timestamp_e6":1618677813097971}
1618677813.221782: {"topic":"orderBookL2_25.EOSUSD","type":"delta","data":{"delete":[],"update":[{"price":"7.972","symbol":"EOSUSD","id":79720,"side":"Buy","size":38731}],"insert":[],"transactTimeE6":0},"cross_seq":1225778897,"timestamp_e6":1618677813138106}
1618677813.2414029: {"topic":"orderBookL2_25.BTCUSD","type":"delta","data":{"delete":[],"update":[{"price":"60622.50","symbol":"BTCUSD","id":606225000,"side":"Buy","size":12767062}],"insert":[],"transactTimeE6":0},"cross_seq":5938958501,"timestamp_e6":1618677813158009}
