1618677830.5296772: {"type":"l2update","product_id":"SKL-USD","changes":[["buy","0.7888","2065.5"]],"time":"2021-04-17T16:43:50.529628Z"}
1618677830.536205: {"type":"l2update","product_id":"DASH-BTC","changes":[["sell","0.00619812","0.82500000"]],"time":"2021-04-17T16:43:50.530949Z"}
1618677830.536255: {"type":"l2update","product_id":"DASH-BTC","changes":[["buy","0.00618583","0.00000000"]],"time":"2021-04-17T16:43:50.531367Z"}
1618677830.5418959: {"type":"l2update","product_id":"SKL-USD","changes":[["sell","0.7915","0.0"]],"time":"2021-04-17T16:43:50.545170Z"}
1618677830.541949: {"type":"l2update","product_id":"NMR-EUR","changes":[["buy","66.9225","0.000"]],"time":"2021-04-17T16:43:50.545895Z"}
1618677830.541975: {"type":"l2update","product_id":"DASH-BTC","changes":[["buy","0.00618543","1.41600000"]],"time":"2021-04-17T16:43:50.545246Z"}
1618677830.541994: {"type":"l2update","product_id":"CRV-EUR","changes":[["sell","3.3200","1416.00"]],"time":"2021-04-17T16:43:50.546173Z"}
1618677830.542016: {"type":"l2update","product_id":"CRV-EUR","changes":[["sell","3.3112","424.00"]],"time":"2021-04-17T16:43:50.546173Z"}
1618677830.547544: {"type":"l2update","product_id":"NMR-EUR","changes":[["buy","66.8896","1.322"]],"time":"2021-04-17T16:43:50.549287Z"}
1618677830.547588: {"type":"l2update","product_id":"BAND-GBP","changes":[["sell","14.7941","0.00"]],"time":"2021-04-17T16:43:50.549778Z"}
1618677830.547617: {"type":"l2update","product_id":"BAND-GBP","changes":[["buy","14.7500","0.00"]],"time":"2021-04-17T16:43:50.550580Z"}
1618677830.5476391: {"type":"l2update","product_id":"DASH-BTC","changes":[["buy","0.00618543","0.29500000"]],"time":"2021-04-17T16:43:50.554387Z"}
1618677830.574966: {"type":"l2update","product_id":"SKL-USD","changes":[["buy","0.7896","867.4"]],"time":"2021-04-17T16:43:50.560874Z"}
1618677830.5750358: {"type":"l2update","product_id":"NMR-EUR","changes":[["buy","66.8896","2.644"]],"time":"2021-04-17T16:43:50.563649Z"}
1618677830.588345: {"type":"l2update","product_id":"SKL-USD","changes":[["sell","0.7917","1344.7"]],"time":"2021-04-17T16:43:50.567418Z"}
1618677830.588398: {"type":"l2update","product_id":"SKL-BTC","changes":[["sell","0.00001307","7909.4"]],"time":"2021-04-17T16:43:50.567480Z"}
1618677830.594413: {"type":"l2update","product_id":"BAND-BTC","changes":[["buy","0.00033239","19.15"]],"time":"2021-04-17T16:43:50.574687Z"}
1618677830.594456: {"type":"l2update","product_id":"DASH-BTC","changes":[["buy","0.00618470","1.54400000"]],"time":"2021-04-17T16:43:50.578221Z"}
1618677830.594483: {"type":"l2update","product_id":"SKL-GBP","changes":[["sell","0.5772","2527.2"]],"time":"2021-04-17T16:43:50.578436Z"}
1618677830.597333: {"type":"l2update","product_id":"YFI-BTC","changes":[["buy","0.82550","0.000464"]],"time":"2021-04-17T16:43:50.588952Z"}
1618677830.5973709: {"type":"l2update","product_id":"SKL-BTC","changes":[["sell","0.00001310","610.0"]],"time":"2021-04-17T16:43:50.590349Z"}
1618677830.597394: {"type":"l2update","product_id":"BAND-GBP","changes":[["sell","14.7999","0.00"]],"time":"2021-04-17T16:43:50.592090Z"}
1618677830.5974212: {"type":"l2update","product_id":"SKL-USD","changes":[["buy","0.7862","5.0"]],"time":"2021-04-17T16:43:50.593049Z"}
1618677830.5974379: {"type":"l2update","product_id":"SKL-USD","changes":[["buy","0.7872","3247.6"]],"time":"2021-04-17T16:43:50.596421Z"}
1618677830.597453: {"type":"l2update","product_id":"SKL-USD","changes":[["buy","0.7872","126.7"]],"time":"2021-04-17T16:43:50.596421Z"}
1618677830.5974662: {"type":"l2update","product_id":"SKL-USD","changes":[["sell","0.7923","0.0"]],"time":"2021-04-17T16:43:50.596421Z"}
1618677830.597486: {"type":"l2update","product_id":"SKL-USD","changes":[["sell","0.7996","5.0"]],"time":"2021-04-17T16:43:50.596421Z"}
1618677830.597503: {"type":"l2update","product_id":"BAND-BTC","changes":[["sell","0.00033490","0.00"]],"time":"2021-04-17T16:43:50.597286Z"}
1618677830.60203: {"type":"l2update","product_id":"SKL-USD","changes":[["buy","0.7898","0.0"]],"time":"2021-04-17T16:43:50.601130Z"}
1618677830.602068: {"type":"l2update","product_id":"DASH-BTC","changes":[["buy","0.00618188","1.12100000"]],"time":"2021-04-17T16:43:50.603512Z"}
1618677830.6047318: {"type":"l2update","product_id":"SKL-USD","changes":[["buy","0.7903","0.0"]],"time":"2021-04-17T16:43:50.610928Z"}
1618677830.60477: {"type":"l2update","product_id":"SKL-GBP","changes":[["buy","0.5747","3556.3"]],"time":"2021-04-17T16:43:50.611424Z"}
1618677830.60479: {"type":"l2update","product_id":"BAND-BTC","changes":[["sell","0.00033506","36.74"]],"time":"2021-04-17T16:43:50.615378Z"}
1618677830.604813: {"type":"l2update","product_id":"SKL-USD","changes":[["sell","0.7941","2728.4"]],"time":"2021-04-17T16:43:50.615802Z"}
1618677830.6122031: {"type":"l2update","product_id":"SKL-BTC","changes":[["buy","0.00001300","5584.3"]],"time":"2021-04-17T16:43:50.618159Z"}
1618677830.612233: {"type":"l2update","product_id":"SKL-BTC","changes":[["sell","0.00001307","11049.9"]],"time":"2021-04-17T16:43:50.618159Z"}
1618677830.619359: {"type":"l2update","product_id":"SKL-USD","changes":[["sell","0.7925","2527.2"]],"time":"2021-04-17T16:43:50.621072Z"}
1618677830.6193988: {"type":"l2update","product_id":"SKL-BTC","changes":[["buy","0.00001302","4416.1"]],"time":"2021-04-17T16:43:50.624288Z"}
1618677830.619423: {"type":"l2update","product_id":"BAND-GBP","changes":[["sell","14.8033","12.58"]],"time":"2021-04-17T16:43:50.625413Z"}
1618677830.61945: {"type":"l2update","product_id":"SKL-USD","changes":[["buy","0.7904","0.0"]],"time":"2021-04-17T16:43:50.625433Z"}
1618677830.623337: {"type":"l2update","product_id":"SKL-BTC","changes":[["sell","0.00001307","8411.8"]],"time":"2021-04-17T16:43:50.627981Z"}
1618677830.625819: {"type":"l2update","product_id":"SKL-GBP","changes":[["sell","0.5775","6319.1"]],"time":"2021-04-17T16:43:50.628357Z"}
1618677830.625868: {"type":"l2update","product_id":"DASH-BTC","changes":[["sell","0.00619718","2.50900000"]],"time":"2021-04-17T16:43:50.628416Z"}
1618677830.625899: {"type":"l2update","product_id":"SKL-USD","changes":[["buy","0.7902","450.0"]],"time":"2021-04-17T16:43:50.628799Z"}
1618677830.630891: {"type":"l2update","product_id":"SKL-USD","changes":[["buy","0.7867","25513.9"]],"time":"2021-04-17T16:43:50.631270Z"}
1618677830.6456509: {"type":"l2update","product_id":"NMR-EUR","changes":[["buy","66.8896","1.322"]],"time":"2021-04-17T16:43:50.641171Z"}
1618677830.645696: {"type":"l2update","product_id":"NMR-EUR","changes":[["buy","66.8896","0.000"]],"time":"2021-04-17T16:43:50.641352Z"}
1618677830.64573: {"type":"l2update","product_id":"SKL-USD","changes":[["sell","0.7924","0.0"]],"time":"2021-04-17T16:43:50.643209Z"}
1618677830.650353: {"type":"l2update","product_id":"SKL-GBP","changes":[["buy","0.5740","6318.5"]],"time":"2021-04-17T16:43:50.647629Z"}
1618677830.686521: {"type":"l2update","product_id":"SKL-USD","changes":[["sell","0.7914","2075.0"]],"time":"2021-04-17T16:43:50.673426Z"}
1618677830.686583: {"type":"match","trade_id":1568282,"maker_order_id":"103763b5-c234-4319-bb70-26e60e9bbe0c","taker_order_id":"a68e9c67-f287-4e16-8fba-3ec9c28413bf","side":"sell","size":"310.5","price":"0.7914","product_id":"SKL-USD","sequence":201391692,"time":"2021-04-17T16:43:50.673426Z"}
1618677830.686612: {"type":"ticker","sequence":201391692,"product_id":"SKL-USD","price":"0.7914","open_24h":"0.7055","volume_24h":"34259575.00000000","low_24h":"0.6915","high_24h":"0.8098","volume_30d":"948686927.70000000","best_bid":"0.7902","best_ask":"0.7914","side":"buy","time":"2021-04-17T16:43:50.673426Z","trade_id":1568282,"last_size":"310.5"}
1618677830.686635: {"type":"l2update","product_id":"SKL-USD","changes":[["sell","0.7942","29765.1"]],"time":"2021-04-17T16:43:50.677842Z"}
1618677830.686659: {"type":"l2update","product_id":"NMR-EUR","changes":[["buy","66.8949","1.322"]],"time":"2021-04-17T16:43:50.677668Z"}
1618677830.6866891: {"type":"l2update","product_id":"DASH-BTC","changes":[["sell","0.00620476","1.62300000"]],"time":"2021-04-17T16:43:50.679580Z"}
1618677830.686709: {"type":"l2update","product_id":"SKL-USD","changes":[["sell","0.7916","6908.0"]],"time":"2021-04-17T16:43:50.686973Z"}
1618677830.692529: {"type":"l2update","product_id":"YFI-BTC","changes":[["buy","0.82409","0.000000"]],"time":"2021-04-17T16:43:50.688603Z"}
1618677830.692586: {"type":"l2update","product_id":"NMR-EUR","changes":[["buy","66.8949","2.644"]],"time":"2021-04-17T16:43:50.690241Z"}
1618677830.6979442: {"type":"l2update","product_id":"NMR-EUR","changes":[["buy","66.8948","0.000"]],"time":"2021-04-17T16:43:50.704147Z"}
1618677830.697995: {"type":"l2update","product_id":"SKL-BTC","changes":[["buy","0.00001303","1004.4"]],"time":"2021-04-17T16:43:50.708238Z"}
1618677830.704671: {"type":"l2update","product_id":"NMR-EUR","changes":[["buy","66.8992","4.776"]],"time":"2021-04-17T16:43:50.711496Z"}
1618677830.704718: {"type":"l2update","product_id":"BAND-BTC","changes":[["sell","0.00033481","31.74"]],"time":"2021-04-17T16:43:50.711521Z"}
1618677830.704751: {"type":"l2update","product_id":"YFI-BTC","changes":[["buy","0.82437","0.053028"]],"time":"2021-04-17T16:43:50.711551Z"}
1618677830.704777: {"type":"l2update","product_id":"SKL-BTC","changes":[["buy","0.00001300","4602.7"]],"time":"2021-04-17T16:43:50.712615Z"}
1618677830.710199: {"type":"l2update","product_id":"DASH-BTC","changes":[["sell","0.00620259","2.23600000"]],"time":"2021-04-17T16:43:50.722418Z"}
1618677830.713748: {"type":"l2update","product_id":"DASH-BTC","changes":[["buy","0.00614340","0.00000000"]],"time":"2021-04-17T16:43:50.725385Z"}
1618677830.7138612: {"type":"l2update","product_id":"DASH-BTC","changes":[["buy","0.00614341","0.54000000"]],"time":"2021-04-17T16:43:50.725385Z"}
1618677830.733367: {"type":"l2update","product_id":"DASH-BTC","changes":[["buy","0.00615250","4.12000000"]],"time":"2021-04-17T16:43:50.733900Z"}
1618677830.7334552: {"type":"l2update","product_id":"DASH-BTC","changes":[["buy","0.00615251","0.46000000"]],"time":"2021-04-17T16:43:50.733900Z"}
1618677830.7335198: {"type":"l2update","product_id":"DASH-BTC","changes":[["buy","0.00618071","1.39100000"]],"time":"2021-04-17T16:43:50.737475Z"}
1618677830.7381709: {"type":"l2update","product_id":"DASH-BTC","changes":[["sell","0.00619614","2.64300000"]],"time":"2021-04-17T16:43:50.745119Z"}
1618677830.7475798: {"type":"l2update","product_id":"DASH-BTC","changes":[["sell","0.00619412","0.00000000"]],"time":"2021-04-17T16:43:50.760545Z"}
1618677830.7645462: {"type":"l2update","product_id":"SKL-USD","changes":[["buy","0.7872","3300.7"]],"time":"2021-04-17T16:43:50.768428Z"}
1618677830.7646039: {"type":"l2update","product_id":"SKL-USD","changes":[["sell","0.7918","26064.6"]],"time":"2021-04-17T16:43:50.768428Z"}
1618677830.764639: {"type":"l2update","product_id":"SKL-USD","changes":[["sell","0.7996","23899.8"]],"time":"2021-04-17T16:43:50.768428Z"}
1618677830.7646668: {"type":"l2update","product_id":"NMR-EUR","changes":[["buy","66.8949","1.322"]],"time":"2021-04-17T16:43:50.772031Z"}
1618677830.764692: {"type":"l2update","product_id":"NMR-EUR","changes":[["buy","66.8949","0.000"]],"time":"2021-04-17T16:43:50.772369Z"}
1618677830.7647328: {"type":"l2update","product_id":"SKL-USD","changes":[["buy","0.7796","8459.5"]],"time":"2021-04-17T16:43:50.772573Z"}
1618677830.764758: {"type":"l2update","product_id":"SKL-USD","changes":[["buy","0.7796","5.0"]],"time":"2021-04-17T16:43:50.772573Z"}
1618677830.7656698: {"type":"l2update","product_id":"DASH-BTC","changes":[["sell","0.00620260","0.00000000"]],"time":"2021-04-17T16:43:50.775863Z"}
1618677830.7657259: {"type":"l2update","product_id":"SKL-BTC","changes":[["buy","0.00001300","1219.1"]],"time":"2021-04-17T16:43:50.777082Z"}
1618677830.765756: {"type":"l2update","product_id":"SKL-BTC","changes":[["sell","0.00001307","5271.3"]],"time":"2021-04-17T16:43:50.777082Z"}
1618677830.775111: {"type":"l2update","product_id":"SKL-USD","changes":[["buy","0.7807","8456.3"]],"time":"2021-04-17T16:43:50.782018Z"}
1618677830.776663: {"type":"l2update","product_id":"BAND-BTC","changes":[["buy","0.00033244","0.00"]],"time":"2021-04-17T16:43:50.789326Z"}
1618677830.776721: {"type":"l2update","product_id":"BAND-BTC","changes":[["buy","0.00033094","0.10"]],"time":"2021-04-17T16:43:50.789326Z"}
1618677830.7767522: {"type":"l2update","product_id":"BAND-BTC","changes":[["buy","0.00032746","0.00"]],"time":"2021-04-17T16:43:50.789326Z"}
1618677830.784771: {"type":"l2update","product_id":"DASH-BTC","changes":[["sell","0.00620174","0.00000000"]],"time":"2021-04-17T16:43:50.796998Z"}
1618677830.784828: {"type":"l2update","product_id":"BAND-BTC","changes":[["buy","0.00033324","148.31"]],"time":"2021-04-17T16:43:50.799687Z"}
1618677830.7848692: {"type":"l2update","product_id":"BAND-BTC","changes":[["buy","0.00033294","177.97"]],"time":"2021-04-17T16:43:50.799687Z"}
1618677830.784895: {"type":"l2update","product_id":"BAND-BTC","changes":[["buy","0.00033170","464.28"]],"time":"2021-04-17T16:43:50.799687Z"}
1618677830.7849169: {"type":"l2update","product_id":"BAND-BTC","changes":[["buy","0.00033144","307.53"]],"time":"2021-04-17T16:43:50.799687Z"}
1618677830.784939: {"type":"l2update","product_id":"NMR-EUR","changes":[["buy","66.8993","1.322"]],"time":"2021-04-17T16:43:50.799936Z"}
1618677830.787967: {"type":"l2update","product_id":"YFI-BTC","changes":[["sell","0.82692","0.030222"]],"time":"2021-04-17T16:43:50.803619Z"}
1618677830.788023: {"type":"l2update","product_id":"NMR-EUR","changes":[["buy","66.8993","2.644"]],"time":"2021-04-17T16:43:50.803751Z"}
1618677830.7903569: {"type":"l2update","product_id":"NMR-EUR","changes":[["buy","66.8992","0.000"]],"time":"2021-04-17T16:43:50.806289Z"}
1618677830.792431: {"type":"l2update","product_id":"YFI-BTC","changes":[["sell","0.82854","0.000000"]],"time":"2021-04-17T16:43:50.809148Z"}
1618677830.792495: {"type":"l2update","product_id":"YFI-BTC","changes":[["buy","0.82405","0.000000"]],"time":"2021-04-17T16:43:50.809148Z"}
1618677830.797363: {"type":"l2update","product_id":"NMR-EUR","changes":[["buy","66.9027","4.775"]],"time":"2021-04-17T16:43:50.812559Z"}
1618677830.7974641: {"type":"l2update","product_id":"SKL-USD","changes":[["sell","0.7914","0.0"]],"time":"2021-04-17T16:43:50.812965Z"}
1618677830.804655: {"type":"l2update","product_id":"DASH-BTC","changes":[["sell","0.00619970","1.62300000"]],"time":"2021-04-17T16:43:50.819065Z"}
1618677830.81023: {"type":"l2update","product_id":"YFI-BTC","changes":[["sell","0.82691","0.030000"]],"time":"2021-04-17T16:43:50.819506Z"}
1618677830.810286: {"type":"l2update","product_id":"YFI-BTC","changes":[["sell","0.82899","0.015100"]],"time":"2021-04-17T16:43:50.823000Z"}
1618677830.810316: {"type":"l2update","product_id":"YFI-BTC","changes":[["buy","0.82450","0.019100"]],"time":"2021-04-17T16:43:50.823000Z"}
1618677830.818979: {"type":"l2update","product_id":"SKL-BTC","changes":[["sell","0.00001308","15756.7"]],"time":"2021-04-17T16:43:50.834045Z"}
1618677830.828618: {"type":"l2update","product_id":"BAND-BTC","changes":[["sell","0.00033507","0.00"]],"time":"2021-04-17T16:43:50.834181Z"}
1618677830.8286788: {"type":"l2update","product_id":"BAND-BTC","changes":[["sell","0.00033474","49.04"]],"time":"2021-04-17T16:43:50.837817Z"}
1618677830.8287091: {"type":"l2update","product_id":"BAND-GBP","changes":[["sell","14.7876","27.80"]],"time":"2021-04-17T16:43:50.842021Z"}
1618677830.828738: {"type":"l2update","product_id":"SKL-USD","changes":[["sell","0.7931","10279.2"]],"time":"2021-04-17T16:43:50.842054Z"}
1618677830.8361459: {"type":"l2update","product_id":"YFI-BTC","changes":[["buy","0.82192","0.000000"]],"time":"2021-04-17T16:43:50.851521Z"}
1618677830.841117: {"type":"l2update","product_id":"DASH-BTC","changes":[["sell","0.00619812","0.00000000"]],"time":"2021-04-17T16:43:50.855287Z"}
1618677830.843572: {"type":"l2update","product_id":"SKL-USD","changes":[["sell","0.7916","9539.9"]],"time":"2021-04-17T16:43:50.858228Z"}
1618677830.843615: {"type":"l2update","product_id":"BAND-BTC","changes":[["buy","0.00033323","49.46"]],"time":"2021-04-17T16:43:50.858973Z"}
1618677830.843642: {"type":"l2update","product_id":"SKL-GBP","changes":[["sell","0.5770","0.0"]],"time":"2021-04-17T16:43:50.860237Z"}
1618677830.8489769: {"type":"l2update","product_id":"SKL-BTC","changes":[["sell","0.00001307","4448.5"]],"time":"2021-04-17T16:43:50.862403Z"}
1618677830.8514712: {"type":"l2update","product_id":"YFI-BTC","changes":[["sell","0.82692","0.000000"]],"time":"2021-04-17T16:43:50.864103Z"}
1618677830.8515258: {"type":"l2update","product_id":"YFI-BTC","changes":[["buy","0.82239","0.095700"]],"time":"2021-04-17T16:43:50.866037Z"}
1618677830.8515599: {"type":"l2update","product_id":"SKL-BTC","changes":[["buy","0.00001303","2144.3"]],"time":"2021-04-17T16:43:50.866187Z"}
1618677830.854435: {"type":"l2update","product_id":"SKL-BTC","changes":[["sell","0.00001337","10.9"]],"time":"2021-04-17T16:43:50.869060Z"}
1618677830.854481: {"type":"l2update","product_id":"SKL-BTC","changes":[["sell","0.00001330","0.0"]],"time":"2021-04-17T16:43:50.869060Z"}
1618677830.854516: {"type":"l2update","product_id":"SKL-BTC","changes":[["sell","0.00001325","5.0"]],"time":"2021-04-17T16:43:50.869060Z"}
1618677830.854537: {"type":"l2update","product_id":"SKL-BTC","changes":[["sell","0.00001322","0.0"]],"time":"2021-04-17T16:43:50.869060Z"}
1618677830.85456: {"type":"l2update","product_id":"SKL-BTC","changes":[["sell","0.00001309","4533.4"]],"time":"2021-04-17T16:43:50.869060Z"}
1618677830.854578: {"type":"l2update","product_id":"SKL-GBP","changes":[["sell","0.5781","0.0"]],"time":"2021-04-17T16:43:50.870662Z"}
1618677830.8592892: {"type":"l2update","product_id":"YFI-BTC","changes":[["sell","0.82691","0.000000"]],"time":"2021-04-17T16:43:50.874138Z"}
1618677830.863714: {"type":"l2update","product_id":"DASH-BTC","changes":[["sell","0.00619613","0.82500000"]],"time":"2021-04-17T16:43:50.878040Z"}
1618677830.8637729: {"type":"l2update","product_id":"SKL-BTC","changes":[["sell","0.00001309","5356.2"]],"time":"2021-04-17T16:43:50.878084Z"}
1618677830.864953: {"type":"l2update","product_id":"BAND-BTC","changes":[["sell","0.00033676","0.00"]],"time":"2021-04-17T16:43:50.881365Z"}
1618677830.8650072: {"type":"l2update","product_id":"SKL-BTC","changes":[["buy","0.00001302","3434.5"]],"time":"2021-04-17T16:43:50.882295Z"}
1618677830.869924: {"type":"l2update","product_id":"SKL-GBP","changes":[["sell","0.5774","5788.0"]],"time":"2021-04-17T16:43:50.885307Z"}
1618677830.878528: {"type":"l2update","product_id":"SKL-BTC","changes":[["sell","0.00001309","5185.4"]],"time":"2021-04-17T16:43:50.892903Z"}
1618677830.878576: {"type":"l2update","product_id":"SKL-GBP","changes":[["buy","0.5705","365.0"]],"time":"2021-04-17T16:43:50.892892Z"}
1618677830.878604: {"type":"l2update","product_id":"SKL-GBP","changes":[["buy","0.5689","440.0"]],"time":"2021-04-17T16:43:50.893173Z"}
1618677830.878624: {"type":"l2update","product_id":"YFI-BTC","changes":[["sell","0.82694","0.000000"]],"time":"2021-04-17T16:43:50.893190Z"}
1618677830.879599: {"type":"l2update","product_id":"SKL-GBP","changes":[["buy","0.5738","0.0"]],"time":"2021-04-17T16:43:50.893173Z"}
1618677830.88395: {"type":"l2update","product_id":"BAND-BTC","changes":[["sell","0.00033618","20.00"]],"time":"2021-04-17T16:43:50.893540Z"}
1618677830.884001: {"type":"l2update","product_id":"SKL-GBP","changes":[["buy","0.5705","815.0"]],"time":"2021-04-17T16:43:50.894064Z"}
1618677830.884026: {"type":"l2update","product_id":"SKL-BTC","changes":[["sell","0.00001352","2900.2"]],"time":"2021-04-17T16:43:50.899228Z"}
1618677830.884048: {"type":"l2update","product_id":"BAND-BTC","changes":[["buy","0.00033323","20.81"]],"time":"2021-04-17T16:43:50.900102Z"}
1618677830.885484: {"type":"l2update","product_id":"SKL-BTC","changes":[["sell","0.00001312","1941.3"]],"time":"2021-04-17T16:43:50.903407Z"}
1618677830.895633: {"type":"l2update","product_id":"NMR-EUR","changes":[["buy","66.8993","1.322"]],"time":"2021-04-17T16:43:50.910031Z"}
1618677830.8956769: {"type":"l2update","product_id":"NMR-EUR","changes":[["buy","66.8993","0.000"]],"time":"2021-04-17T16:43:50.910303Z"}
1618677830.895713: {"type":"l2update","product_id":"SKL-USD","changes":[["buy","0.7896","0.0"]],"time":"2021-04-17T16:43:50.912052Z"}
1618677830.902137: {"type":"l2update","product_id":"BAND-BTC","changes":[["sell","0.00033481","0.00"]],"time":"2021-04-17T16:43:50.917565Z"}
1618677830.903616: {"type":"l2update","product_id":"BAND-GBP","changes":[["buy","14.7609","0.00"]],"time":"2021-04-17T16:43:50.921289Z"}
1618677830.911979: {"type":"l2update","product_id":"NMR-EUR","changes":[["buy","66.9028","1.322"]],"time":"2021-04-17T16:43:50.922670Z"}
1618677830.912029: {"type":"l2update","product_id":"SKL-USD","changes":[["buy","0.7872","126.7"]],"time":"2021-04-17T16:43:50.922757Z"}
1618677830.912056: {"type":"l2update","product_id":"SKL-USD","changes":[["sell","0.7996","5.0"]],"time":"2021-04-17T16:43:50.922757Z"}
1618677830.912077: {"type":"l2update","product_id":"BAND-BTC","changes":[["buy","0.00033325","20.80"]],"time":"2021-04-17T16:43:50.926426Z"}
1618677830.912106: {"type":"l2update","product_id":"DASH-BTC","changes":[["sell","0.00621229","0.00000000"]],"time":"2021-04-17T16:43:50.927980Z"}
1618677830.916329: {"type":"l2update","product_id":"NMR-EUR","changes":[["buy","66.9027","0.000"]],"time":"2021-04-17T16:43:50.929220Z"}
1618677830.931443: {"type":"l2update","product_id":"SKL-BTC","changes":[["sell","0.00001338","4866.0"]],"time":"2021-04-17T16:43:50.930692Z"}
1618677830.931487: {"type":"l2update","product_id":"SKL-BTC","changes":[["sell","0.00001334","37322.9"]],"time":"2021-04-17T16:43:50.930692Z"}
1618677830.931513: {"type":"l2update","product_id":"BAND-GBP","changes":[["buy","14.7652","0.00"]],"time":"2021-04-17T16:43:50.930761Z"}
1618677830.931543: {"type":"l2update","product_id":"SKL-BTC","changes":[["sell","0.00001327","1367.7"]],"time":"2021-04-17T16:43:50.930692Z"}
1618677830.931563: {"type":"l2update","product_id":"SKL-BTC","changes":[["sell","0.00001323","1675.8"]],"time":"2021-04-17T16:43:50.930692Z"}
1618677830.931586: {"type":"l2update","product_id":"SKL-BTC","changes":[["sell","0.00001319","1470.5"]],"time":"2021-04-17T16:43:50.930692Z"}
1618677830.931603: {"type":"l2update","product_id":"SKL-BTC","changes":[["sell","0.00001316","3073.2"]],"time":"2021-04-17T16:43:50.930692Z"}
1618677830.931621: {"type":"l2update","product_id":"NMR-EUR","changes":[["buy","66.9055","4.775"]],"time":"2021-04-17T16:43:50.935112Z"}
1618677830.931642: {"type":"l2update","product_id":"SKL-USD","changes":[["buy","0.7900","9134.3"]],"time":"2021-04-17T16:43:50.935169Z"}
1618677830.93166: {"type":"l2update","product_id":"SKL-BTC","changes":[["sell","0.00001352","1603.3"]],"time":"2021-04-17T16:43:50.935483Z"}
1618677830.931676: {"type":"l2update","product_id":"SKL-BTC","changes":[["sell","0.00001348","865.5"]],"time":"2021-04-17T16:43:50.935483Z"}
1618677830.9316921: {"type":"l2update","product_id":"SKL-BTC","changes":[["sell","0.00001344","10.0"]],"time":"2021-04-17T16:43:50.935483Z"}
1618677830.9317088: {"type":"l2update","product_id":"SKL-BTC","changes":[["sell","0.00001338","3479.5"]],"time":"2021-04-17T16:43:50.935483Z"}
1618677830.931725: {"type":"l2update","product_id":"SKL-BTC","changes":[["sell","0.00001338","1888.5"]],"time":"2021-04-17T16:43:50.935483Z"}
1618677830.9317398: {"type":"l2update","product_id":"BAND-BTC","changes":[["buy","0.00033324","0.00"]],"time":"2021-04-17T16:43:50.937921Z"}
1618677830.931763: {"type":"l2update","product_id":"NMR-EUR","changes":[["buy","66.9028","2.644"]],"time":"2021-04-17T16:43:50.938216Z"}
1618677830.93178: {"type":"l2update","product_id":"SKL-BTC","changes":[["buy","0.00001299","14861.1"]],"time":"2021-04-17T16:43:50.938381Z"}
1618677830.931797: {"type":"l2update","product_id":"SKL-BTC","changes":[["sell","0.00001307","7589.0"]],"time":"2021-04-17T16:43:50.938381Z"}
1618677830.931813: {"type":"l2update","product_id":"BAND-GBP","changes":[["buy","14.7575","0.00"]],"time":"2021-04-17T16:43:50.939261Z"}
1618677830.9318368: {"type":"l2update","product_id":"DASH-BTC","changes":[["sell","0.00621377","0.00000000"]],"time":"2021-04-17T16:43:50.938947Z"}
1618677830.93186: {"type":"l2update","product_id":"BAND-GBP","changes":[["buy","14.7614","40.11"]],"time":"2021-04-17T16:43:50.941874Z"}
1618677830.937919: {"type":"l2update","product_id":"BAND-BTC","changes":[["buy","0.00033325","49.45"]],"time":"2021-04-17T16:43:50.953355Z"}
1618677830.952446: {"type":"l2update","product_id":"SKL-BTC","changes":[["sell","0.00001315","25495.7"]],"time":"2021-04-17T16:43:50.961227Z"}
1618677830.952491: {"type":"l2update","product_id":"SKL-BTC","changes":[["sell","0.00001329","26.6"]],"time":"2021-04-17T16:43:50.961227Z"}
1618677830.952517: {"type":"l2update","product_id":"SKL-BTC","changes":[["sell","0.00001309","3285.4"]],"time":"2021-04-17T16:43:50.964733Z"}
1618677830.961056: {"type":"l2update","product_id":"SKL-BTC","changes":[["sell","0.00001339","1741.8"]],"time":"2021-04-17T16:43:50.976164Z"}
1618677830.961102: {"type":"l2update","product_id":"SKL-BTC","changes":[["sell","0.00001334","38893.1"]],"time":"2021-04-17T16:43:50.976164Z"}
1618677830.961132: {"type":"l2update","product_id":"SKL-BTC","changes":[["sell","0.00001329","1915.1"]],"time":"2021-04-17T16:43:50.976164Z"}
1618677830.961154: {"type":"l2update","product_id":"SKL-BTC","changes":[["sell","0.00001326","1296.9"]],"time":"2021-04-17T16:43:50.976164Z"}
1618677830.961181: {"type":"l2update","product_id":"SKL-BTC","changes":[["sell","0.00001312","3532.3"]],"time":"2021-04-17T16:43:50.976164Z"}
1618677830.964159: {"type":"l2update","product_id":"YFI-BTC","changes":[["sell","0.83215","0.000000"]],"time":"2021-04-17T16:43:50.979077Z"}
1618677830.964206: {"type":"l2update","product_id":"YFI-BTC","changes":[["sell","0.83214","0.000000"]],"time":"2021-04-17T16:43:50.979077Z"}
1618677830.9642339: {"type":"l2update","product_id":"YFI-BTC","changes":[["buy","0.82315","0.001300"]],"time":"2021-04-17T16:43:50.979077Z"}
1618677830.964255: {"type":"l2update","product_id":"SKL-BTC","changes":[["sell","0.00001352","33.1"]],"time":"2021-04-17T16:43:50.980800Z"}
1618677830.964275: {"type":"l2update","product_id":"SKL-BTC","changes":[["sell","0.00001338","0.0"]],"time":"2021-04-17T16:43:50.980800Z"}
1618677830.964297: {"type":"l2update","product_id":"SKL-BTC","changes":[["sell","0.00001334","37596.2"]],"time":"2021-04-17T16:43:50.980800Z"}
1618677830.9643142: {"type":"l2update","product_id":"SKL-BTC","changes":[["sell","0.00001316","1482.2"]],"time":"2021-04-17T16:43:50.980800Z"}
1618677830.9679308: {"type":"l2update","product_id":"DASH-BTC","changes":[["buy","0.00618470","0.00000000"]],"time":"2021-04-17T16:43:50.983045Z"}
1618677830.970021: {"type":"l2update","product_id":"BAND-GBP","changes":[["buy","14.7576","36.00"]],"time":"2021-04-17T16:43:50.987217Z"}
1618677830.973258: {"type":"l2update","product_id":"YFI-BTC","changes":[["buy","0.82586","0.019261"]],"time":"2021-04-17T16:43:50.987512Z"}
1618677830.9733078: {"type":"l2update","product_id":"YFI-BTC","changes":[["sell","0.83212","0.027280"]],"time":"2021-04-17T16:43:50.987795Z"}
1618677830.973335: {"type":"l2update","product_id":"YFI-BTC","changes":[["buy","0.82063","0.009520"]],"time":"2021-04-17T16:43:50.987795Z"}
1618677830.97336: {"type":"l2update","product_id":"YFI-BTC","changes":[["sell","0.83211","0.012570"]],"time":"2021-04-17T16:43:50.987795Z"}
1618677830.981727: {"type":"l2update","product_id":"DASH-BTC","changes":[["buy","0.00618782","0.00000000"]],"time":"2021-04-17T16:43:50.994998Z"}
1618677830.9893389: {"type":"l2update","product_id":"YFI-BTC","changes":[["buy","0.82585","0.015600"]],"time":"2021-04-17T16:43:51.001747Z"}
1618677830.989395: {"type":"l2update","product_id":"BAND-BTC","changes":[["sell","0.00033474","19.39"]],"time":"2021-04-17T16:43:51.006148Z"}
1618677830.989425: {"type":"l2update","product_id":"BAND-GBP","changes":[["sell","14.7876","0.00"]],"time":"2021-04-17T16:43:51.006713Z"}
1618677830.992724: {"type":"l2update","product_id":"DASH-BTC","changes":[["sell","0.00620245","1.10000000"]],"time":"2021-04-17T16:43:51.009187Z"}
1618677830.9993012: {"type":"l2update","product_id":"SKL-BTC","changes":[["buy","0.00001300","2200.7"]],"time":"2021-04-17T16:43:51.012871Z"}
1618677830.999337: {"type":"l2update","product_id":"CRV-EUR","changes":[["buy","3.2894","0.00"]],"time":"2021-04-17T16:43:51.013310Z"}
1618677831.0087008: {"type":"l2update","product_id":"BAND-BTC","changes":[["buy","0.00033404","18.00"]],"time":"2021-04-17T16:43:51.020998Z"}
1618677831.008738: {"type":"l2update","product_id":"BAND-GBP","changes":[["buy","14.6491","0.00"]],"time":"2021-04-17T16:43:51.023662Z"}
1618677831.0087612: {"type":"l2update","product_id":"BAND-GBP","changes":[["buy","14.6492","4.60"]],"time":"2021-04-17T16:43:51.023662Z"}
1618677831.008776: {"type":"l2update","product_id":"SKL-BTC","changes":[["sell","0.00001344","1717.8"]],"time":"2021-04-17T16:43:51.024644Z"}
1618677831.021357: {"type":"l2update","product_id":"BAND-GBP","changes":[["buy","14.6496","11.20"]],"time":"2021-04-17T16:43:51.031686Z"}
1618677831.021388: {"type":"l2update","product_id":"BAND-GBP","changes":[["buy","14.6495","8.50"]],"time":"2021-04-17T16:43:51.031686Z"}
1618677831.02987: {"type":"l2update","product_id":"DASH-BTC","changes":[["buy","0.00618543","1.83800000"]],"time":"2021-04-17T16:43:51.042943Z"}
1618677831.029898: {"type":"l2update","product_id":"DASH-BTC","changes":[["buy","0.00618543","4.41200000"]],"time":"2021-04-17T16:43:51.042968Z"}
1618677831.037326: {"type":"l2update","product_id":"NMR-EUR","changes":[["buy","66.9028","1.322"]],"time":"2021-04-17T16:43:51.048244Z"}
1618677831.0373561: {"type":"l2update","product_id":"NMR-EUR","changes":[["buy","66.9028","0.000"]],"time":"2021-04-17T16:43:51.048463Z"}
1618677831.0373812: {"type":"l2update","product_id":"SKL-BTC","changes":[["sell","0.00001348","2386.6"]],"time":"2021-04-17T16:43:51.049793Z"}
1618677831.0503948: {"type":"l2update","product_id":"NMR-EUR","changes":[["buy","66.9056","1.322"]],"time":"2021-04-17T16:43:51.061092Z"}
1618677831.057763: {"type":"l2update","product_id":"NMR-EUR","changes":[["buy","66.9056","2.644"]],"time":"2021-04-17T16:43:51.065068Z"}
1618677831.057823: {"type":"l2update","product_id":"NMR-EUR","changes":[["buy","66.9055","0.000"]],"time":"2021-04-17T16:43:51.067399Z"}
1618677831.057854: {"type":"l2update","product_id":"DASH-BTC","changes":[["sell","0.00620269","0.00000000"]],"time":"2021-04-17T16:43:51.068923Z"}
1618677831.057875: {"type":"l2update","product_id":"DASH-BTC","changes":[["sell","0.00620259","0.00000000"]],"time":"2021-04-17T16:43:51.071201Z"}
1618677831.063043: {"type":"l2update","product_id":"NMR-EUR","changes":[["buy","66.9077","4.775"]],"time":"2021-04-17T16:43:51.072355Z"}
1618677831.063085: {"type":"l2update","product_id":"SKL-USD","changes":[["sell","0.7918","23012.0"]],"time":"2021-04-17T16:43:51.076059Z"}
1618677831.063106: {"type":"l2update","product_id":"SKL-BTC","changes":[["sell","0.00001354","1245.4"]],"time":"2021-04-17T16:43:51.076339Z"}
1618677831.0726411: {"type":"l2update","product_id":"CRV-EUR","changes":[["buy","3.2961","400.00"]],"time":"2021-04-17T16:43:51.080140Z"}
1618677831.0779572: {"type":"l2update","product_id":"SKL-BTC","changes":[["buy","0.00001303","5934.3"]],"time":"2021-04-17T16:43:51.091382Z"}
1618677831.077992: {"type":"l2update","product_id":"BAND-GBP","changes":[["sell","14.7990","12.70"]],"time":"2021-04-17T16:43:51.091457Z"}
1618677831.0780191: {"type":"l2update","product_id":"SKL-BTC","changes":[["buy","0.00001299","11253.9"]],"time":"2021-04-17T16:43:51.092674Z"}
1618677831.087611: {"type":"l2update","product_id":"BAND-BTC","changes":[["sell","0.00033810","0.00"]],"time":"2021-04-17T16:43:51.097574Z"}
1618677831.087656: {"type":"l2update","product_id":"BAND-BTC","changes":[["sell","0.00033809","0.00"]],"time":"2021-04-17T16:43:51.097574Z"}
1618677831.087682: {"type":"l2update","product_id":"BAND-BTC","changes":[["buy","0.00033170","462.78"]],"time":"2021-04-17T16:43:51.097574Z"}
1618677831.097493: {"type":"l2update","product_id":"BAND-BTC","changes":[["sell","0.00033682","24.70"]],"time":"2021-04-17T16:43:51.105830Z"}
1618677831.0975292: {"type":"l2update","product_id":"BAND-BTC","changes":[["buy","0.00033170","464.28"]],"time":"2021-04-17T16:43:51.105830Z"}
1618677831.0975502: {"type":"l2update","product_id":"BAND-BTC","changes":[["sell","0.00033681","5.40"]],"time":"2021-04-17T16:43:51.105830Z"}
1618677831.097574: {"type":"l2update","product_id":"DASH-BTC","changes":[["sell","0.00620476","0.00000000"]],"time":"2021-04-17T16:43:51.106899Z"}
1618677831.100437: {"type":"l2update","product_id":"SKL-BTC","changes":[["sell","0.00001311","2070.8"]],"time":"2021-04-17T16:43:51.114029Z"}
1618677831.117043: {"type":"l2update","product_id":"DASH-BTC","changes":[["sell","0.00620174","2.23600000"]],"time":"2021-04-17T16:43:51.129128Z"}
1618677831.1372092: {"type":"l2update","product_id":"DASH-BTC","changes":[["sell","0.00620174","3.85900000"]],"time":"2021-04-17T16:43:51.144311Z"}
1618677831.137245: {"type":"l2update","product_id":"DASH-BTC","changes":[["buy","0.00617110","0.00000000"]],"time":"2021-04-17T16:43:51.147019Z"}
1618677831.14022: {"type":"l2update","product_id":"NMR-EUR","changes":[["buy","66.9056","1.322"]],"time":"2021-04-17T16:43:51.152349Z"}
1618677831.1402519: {"type":"l2update","product_id":"NMR-EUR","changes":[["buy","66.9056","0.000"]],"time":"2021-04-17T16:43:51.152645Z"}
1618677831.14209: {"type":"l2update","product_id":"DASH-BTC","changes":[["sell","0.00620095","14.63200000"]],"time":"2021-04-17T16:43:51.155049Z"}
1618677831.142127: {"type":"l2update","product_id":"DASH-BTC","changes":[["sell","0.00619970","0.00000000"]],"time":"2021-04-17T16:43:51.155244Z"}
1618677831.1560042: {"type":"l2update","product_id":"DASH-BTC","changes":[["buy","0.00618014","1.88000000"]],"time":"2021-04-17T16:43:51.162303Z"}
1618677831.156042: {"type":"l2update","product_id":"SKL-BTC","changes":[["sell","0.00001309","2462.6"]],"time":"2021-04-17T16:43:51.163285Z"}
1618677831.16146: {"type":"l2update","product_id":"SKL-BTC","changes":[["buy","0.00001302","4416.1"]],"time":"2021-04-17T16:43:51.173060Z"}
1618677831.167645: {"type":"l2update","product_id":"NMR-EUR","changes":[["buy","66.8895","1.322"]],"time":"2021-04-17T16:43:51.180474Z"}
1618677831.1676888: {"type":"l2update","product_id":"SKL-USD","changes":[["buy","0.7903","989.7"]],"time":"2021-04-17T16:43:51.180640Z"}
1618677831.169311: {"type":"l2update","product_id":"NMR-EUR","changes":[["buy","66.8895","2.644"]],"time":"2021-04-17T16:43:51.184082Z"}
1618677831.174751: {"type":"l2update","product_id":"SKL-USD","changes":[["buy","0.7902","0.0"]],"time":"2021-04-17T16:43:51.189354Z"}
1618677831.17788: {"type":"l2update","product_id":"SKL-BTC","changes":[["buy","0.00001304","110.0"]],"time":"2021-04-17T16:43:51.191749Z"}
1618677831.1801732: {"type":"l2update","product_id":"BAND-GBP","changes":[["sell","14.7944","12.53"]],"time":"2021-04-17T16:43:51.195519Z"}
1618677831.185545: {"type":"l2update","product_id":"BAND-GBP","changes":[["buy","14.7648","12.79"]],"time":"2021-04-17T16:43:51.195656Z"}
1618677831.185587: {"type":"l2update","product_id":"SKL-USD","changes":[["buy","0.7904","450.0"]],"time":"2021-04-17T16:43:51.195713Z"}
1618677831.193495: {"type":"l2update","product_id":"SKL-USD","changes":[["sell","0.7916","2631.9"]],"time":"2021-04-17T16:43:51.206910Z"}
1618677831.199763: {"type":"l2update","product_id":"NMR-EUR","changes":[["buy","66.8895","1.322"]],"time":"2021-04-17T16:43:51.214752Z"}
1618677831.199826: {"type":"l2update","product_id":"NMR-EUR","changes":[["buy","66.8895","0.000"]],"time":"2021-04-17T16:43:51.214791Z"}
1618677831.206335: {"type":"l2update","product_id":"DASH-BTC","changes":[["sell","0.00619717","1.62300000"]],"time":"2021-04-17T16:43:51.217356Z"}
1618677831.20641: {"type":"l2update","product_id":"DASH-BTC","changes":[["sell","0.00619612","1.39200000"]],"time":"2021-04-17T16:43:51.217510Z"}
1618677831.2064488: {"type":"l2update","product_id":"DASH-BTC","changes":[["sell","0.00619612","6.95800000"]],"time":"2021-04-17T16:43:51.221705Z"}
1618677831.2128232: {"type":"l2update","product_id":"SKL-USD","changes":[["sell","0.7924","6908.0"]],"time":"2021-04-17T16:43:51.224977Z"}
1618677831.2174342: {"type":"l2update","product_id":"SKL-USD","changes":[["sell","0.8078","12000.0"]],"time":"2021-04-17T16:43:51.228627Z"}
1618677831.217553: {"type":"l2update","product_id":"SKL-USD","changes":[["buy","0.7856","7131.3"]],"time":"2021-04-17T16:43:51.231539Z"}
1618677831.217608: {"type":"l2update","product_id":"DASH-BTC","changes":[["buy","0.00618188","0.00000000"]],"time":"2021-04-17T16:43:51.231733Z"}
1618677831.220299: {"type":"l2update","product_id":"SKL-USD","changes":[["buy","0.7855","1020.0"]],"time":"2021-04-17T16:43:51.235872Z"}
1618677831.2247229: {"type":"l2update","product_id":"NMR-EUR","changes":[["buy","66.9078","1.322"]],"time":"2021-04-17T16:43:51.238990Z"}
1618677831.224855: {"type":"l2update","product_id":"SKL-USD","changes":[["buy","0.7879","2870.6"]],"time":"2021-04-17T16:43:51.239004Z"}
1618677831.224919: {"type":"l2update","product_id":"SKL-USD","changes":[["sell","0.7922","3732.1"]],"time":"2021-04-17T16:43:51.239004Z"}
1618677831.2249742: {"type":"l2update","product_id":"SKL-USD","changes":[["sell","0.8002","22896.6"]],"time":"2021-04-17T16:43:51.239004Z"}
1618677831.22669: {"type":"l2update","product_id":"NMR-EUR","changes":[["buy","66.9078","2.644"]],"time":"2021-04-17T16:43:51.242452Z"}
1618677831.236192: {"type":"l2update","product_id":"SKL-USD","changes":[["sell","0.7942","5.0"]],"time":"2021-04-17T16:43:51.245649Z"}
1618677831.236284: {"type":"l2update","product_id":"SKL-BTC","changes":[["buy","0.00001300","5828.9"]],"time":"2021-04-17T16:43:51.249861Z"}
1618677831.24031: {"type":"l2update","product_id":"DASH-BTC","changes":[["buy","0.00618470","1.12100000"]],"time":"2021-04-17T16:43:51.254385Z"}
1618677831.249991: {"type":"l2update","product_id":"SKL-USD","changes":[["buy","0.7901","0.0"]],"time":"2021-04-17T16:43:51.259513Z"}
1618677831.250113: {"type":"l2update","product_id":"BAND-BTC","changes":[["buy","0.00033325","28.65"]],"time":"2021-04-17T16:43:51.264474Z"}
1618677831.250171: {"type":"l2update","product_id":"SKL-USD","changes":[["sell","0.7927","30868.4"]],"time":"2021-04-17T16:43:51.264968Z"}
1618677831.261444: {"type":"l2update","product_id":"SKL-USD","changes":[["buy","0.7854","2175.0"]],"time":"2021-04-17T16:43:51.277854Z"}
1618677831.261529: {"type":"l2update","product_id":"SKL-USD","changes":[["buy","0.7854","1080.0"]],"time":"2021-04-17T16:43:51.277854Z"}
1618677831.268032: {"type":"l2update","product_id":"BAND-BTC","changes":[["buy","0.00033323","41.62"]],"time":"2021-04-17T16:43:51.283377Z"}
1618677831.2693472: {"type":"l2update","product_id":"SKL-USD","changes":[["buy","0.7857","960.0"]],"time":"2021-04-17T16:43:51.283411Z"}
1618677831.269429: {"type":"l2update","product_id":"SKL-USD","changes":[["buy","0.7827","994.2"]],"time":"2021-04-17T16:43:51.283411Z"}
1618677831.269484: {"type":"l2update","product_id":"SKL-USD","changes":[["buy","0.7828","155.0"]],"time":"2021-04-17T16:43:51.283411Z"}
1618677831.26954: {"type":"l2update","product_id":"DASH-BTC","changes":[["sell","0.00619613","0.00000000"]],"time":"2021-04-17T16:43:51.284878Z"}
1618677831.274341: {"type":"l2update","product_id":"BAND-BTC","changes":[["buy","0.00033325","0.00"]],"time":"2021-04-17T16:43:51.288279Z"}
1618677831.287456: {"type":"l2update","product_id":"SKL-BTC","changes":[["buy","0.00001299","8617.4"]],"time":"2021-04-17T16:43:51.301435Z"}
1618677831.293094: {"type":"l2update","product_id":"DASH-BTC","changes":[["sell","0.00619611","0.82500000"]],"time":"2021-04-17T16:43:51.305190Z"}
1618677831.293151: {"type":"l2update","product_id":"BAND-BTC","changes":[["buy","0.00033323","70.27"]],"time":"2021-04-17T16:43:51.308830Z"}
1618677831.297308: {"type":"l2update","product_id":"SKL-BTC","changes":[["buy","0.00001300","4847.3"]],"time":"2021-04-17T16:43:51.313309Z"}
1618677831.3204758: {"type":"l2update","product_id":"NMR-EUR","changes":[["buy","66.9077","0.000"]],"time":"2021-04-17T16:43:51.334280Z"}
1618677831.32386: {"type":"l2update","product_id":"NMR-EUR","changes":[["buy","66.9095","4.775"]],"time":"2021-04-17T16:43:51.337752Z"}
1618677831.358634: {"type":"l2update","product_id":"DASH-BTC","changes":[["buy","0.00618543","2.86900000"]],"time":"2021-04-17T16:43:51.370423Z"}
1618677831.358679: {"type":"l2update","product_id":"SKL-USD","changes":[["sell","0.8083","6050.5"]],"time":"2021-04-17T16:43:51.370355Z"}
1618677831.3603032: {"type":"l2update","product_id":"SKL-USD","changes":[["sell","0.8078","6000.0"]],"time":"2021-04-17T16:43:51.374301Z"}
1618677831.365751: {"type":"l2update","product_id":"SKL-USD","changes":[["sell","0.8083","12050.5"]],"time":"2021-04-17T16:43:51.381126Z"}
1618677831.376727: {"type":"l2update","product_id":"CRV-EUR","changes":[["buy","3.2960","0.00"]],"time":"2021-04-17T16:43:51.389031Z"}
1618677831.378853: {"type":"l2update","product_id":"SKL-USD","changes":[["sell","0.7922","0.0"]],"time":"2021-04-17T16:43:51.392575Z"}
1618677831.37891: {"type":"l2update","product_id":"SKL-USD","changes":[["sell","0.8002","24.2"]],"time":"2021-04-17T16:43:51.392575Z"}
1618677831.390062: {"type":"l2update","product_id":"CRV-EUR","changes":[["buy","3.2955","5000.00"]],"time":"2021-04-17T16:43:51.395904Z"}
1618677831.3901162: {"type":"l2update","product_id":"DASH-BTC","changes":[["buy","0.00618544","1.54300000"]],"time":"2021-04-17T16:43:51.395988Z"}
1618677831.390147: {"type":"l2update","product_id":"SKL-USD","changes":[["sell","0.7927","1108.3"]],"time":"2021-04-17T16:43:51.399893Z"}
1618677831.3901691: {"type":"l2update","product_id":"DASH-BTC","changes":[["sell","0.00619614","0.00000000"]],"time":"2021-04-17T16:43:51.404231Z"}
1618677831.401598: {"type":"l2update","product_id":"SKL-BTC","changes":[["buy","0.00001300","4880.6"]],"time":"2021-04-17T16:43:51.414437Z"}
1618677831.401644: {"type":"l2update","product_id":"DASH-BTC","changes":[["sell","0.00864891","2.16000000"]],"time":"2021-04-17T16:43:51.415458Z"}
1618677831.401669: {"type":"l2update","product_id":"SKL-USD","changes":[["sell","0.7930","29765.1"]],"time":"2021-04-17T16:43:51.418600Z"}
1618677831.406901: {"type":"l2update","product_id":"DASH-BTC","changes":[["sell","0.00864891","4.80000000"]],"time":"2021-04-17T16:43:51.421921Z"}
1618677831.406945: {"type":"l2update","product_id":"SKL-USD","changes":[["sell","0.7935","5.0"]],"time":"2021-04-17T16:43:51.423314Z"}
1618677831.4197729: {"type":"l2update","product_id":"SKL-USD","changes":[["sell","0.7952","1262.5"]],"time":"2021-04-17T16:43:51.434711Z"}
1618677831.427479: {"type":"l2update","product_id":"BAND-BTC","changes":[["buy","0.00033423","0.00"]],"time":"2021-04-17T16:43:51.442026Z"}
1618677831.4392729: {"type":"l2update","product_id":"NMR-EUR","changes":[["buy","66.9078","1.322"]],"time":"2021-04-17T16:43:51.453307Z"}
1618677831.439362: {"type":"l2update","product_id":"NMR-EUR","changes":[["buy","66.9078","0.000"]],"time":"2021-04-17T16:43:51.453416Z"}
1618677831.439878: {"type":"l2update","product_id":"SKL-BTC","changes":[["buy","0.00001302","4926.1"]],"time":"2021-04-17T16:43:51.456153Z"}
1618677831.447603: {"type":"l2update","product_id":"DASH-BTC","changes":[["sell","0.00620174","1.62300000"]],"time":"2021-04-17T16:43:51.462402Z"}
1618677831.450975: {"type":"l2update","product_id":"SKL-USD","changes":[["buy","0.7904","900.0"]],"time":"2021-04-17T16:43:51.467163Z"}
1618677831.458428: {"type":"l2update","product_id":"NMR-EUR","changes":[["buy","66.9096","1.322"]],"time":"2021-04-17T16:43:51.471260Z"}
1618677831.458532: {"type":"l2update","product_id":"YFI-BTC","changes":[["sell","0.82739","0.000000"]],"time":"2021-04-17T16:43:51.473426Z"}
1618677831.458605: {"type":"l2update","product_id":"NMR-EUR","changes":[["buy","66.9096","2.644"]],"time":"2021-04-17T16:43:51.474714Z"}
1618677831.4614809: {"type":"l2update","product_id":"NMR-EUR","changes":[["buy","66.9095","0.000"]],"time":"2021-04-17T16:43:51.477345Z"}
1618677831.4693031: {"type":"l2update","product_id":"DASH-BTC","changes":[["sell","0.00619970","2.23600000"]],"time":"2021-04-17T16:43:51.482388Z"}
1618677831.4694169: {"type":"l2update","product_id":"NMR-EUR","changes":[["buy","66.9107","4.775"]],"time":"2021-04-17T16:43:51.482473Z"}
1618677831.475649: {"type":"l2update","product_id":"BAND-BTC","changes":[["sell","0.00033480","0.00"]],"time":"2021-04-17T16:43:51.488969Z"}
1618677831.4757178: {"type":"l2update","product_id":"BAND-BTC","changes":[["buy","0.00033425","36.75"]],"time":"2021-04-17T16:43:51.489205Z"}
1618677831.4766731: {"type":"l2update","product_id":"BAND-GBP","changes":[["buy","14.7648","0.00"]],"time":"2021-04-17T16:43:51.493167Z"}
1618677831.479776: {"type":"l2update","product_id":"BAND-BTC","changes":[["buy","0.00033424","0.00"]],"time":"2021-04-17T16:43:51.496052Z"}
1618677831.480819: {"type":"l2update","product_id":"BAND-BTC","changes":[["sell","0.00033474","0.00"]],"time":"2021-04-17T16:43:51.497993Z"}
1618677831.4905548: {"type":"l2update","product_id":"SKL-USD","changes":[["buy","0.7899","0.0"]],"time":"2021-04-17T16:43:51.502957Z"}
1618677831.49064: {"type":"l2update","product_id":"BAND-BTC","changes":[["buy","0.00033426","29.62"]],"time":"2021-04-17T16:43:51.503662Z"}
1618677831.490679: {"type":"l2update","product_id":"BAND-BTC","changes":[["sell","0.00033538","0.00"]],"time":"2021-04-17T16:43:51.504654Z"}
1618677831.4907131: {"type":"l2update","product_id":"SKL-BTC","changes":[["sell","0.00001306","894.1"]],"time":"2021-04-17T16:43:51.505018Z"}
1618677831.501138: {"type":"l2update","product_id":"SKL-USD","changes":[["sell","0.7927","0.0"]],"time":"2021-04-17T16:43:51.517231Z"}
1618677831.5012102: {"type":"l2update","product_id":"BAND-BTC","changes":[["sell","0.00033478","18.94"]],"time":"2021-04-17T16:43:51.518437Z"}
1618677831.507668: {"type":"l2update","product_id":"SKL-USD","changes":[["buy","0.7877","1317.4"]],"time":"2021-04-17T16:43:51.520169Z"}
1618677831.5077262: {"type":"l2update","product_id":"DASH-BTC","changes":[["sell","0.00619637","0.00000000"]],"time":"2021-04-17T16:43:51.521765Z"}
1618677831.507769: {"type":"l2update","product_id":"YFI-BTC","changes":[["sell","0.82714","0.000000"]],"time":"2021-04-17T16:43:51.524561Z"}
1618677831.507802: {"type":"l2update","product_id":"SKL-USD","changes":[["sell","0.7930","5.0"]],"time":"2021-04-17T16:43:51.524885Z"}
1618677831.513916: {"type":"l2update","product_id":"SKL-USD","changes":[["sell","0.8078","0.0"]],"time":"2021-04-17T16:43:51.529224Z"}
1618677831.5170891: {"type":"l2update","product_id":"YFI-BTC","changes":[["buy","0.82063","0.010490"]],"time":"2021-04-17T16:43:51.533145Z"}
1618677831.518316: {"type":"l2update","product_id":"SKL-BTC","changes":[["sell","0.00001307","8657.0"]],"time":"2021-04-17T16:43:51.533279Z"}
1618677831.518373: {"type":"l2update","product_id":"YFI-BTC","changes":[["buy","0.82553","0.000000"]],"time":"2021-04-17T16:43:51.533600Z"}
1618677831.5205052: {"type":"l2update","product_id":"YFI-BTC","changes":[["sell","0.82693","0.000000"]],"time":"2021-04-17T16:43:51.536281Z"}
1618677831.520559: {"type":"l2update","product_id":"SKL-USD","changes":[["sell","0.8083","18050.5"]],"time":"2021-04-17T16:43:51.536827Z"}
1618677831.524663: {"type":"l2update","product_id":"YFI-BTC","changes":[["sell","0.82714","0.030000"]],"time":"2021-04-17T16:43:51.540437Z"}
1618677831.524719: {"type":"l2update","product_id":"SKL-USD","changes":[["buy","0.7701","2094.0"]],"time":"2021-04-17T16:43:51.540598Z"}
1618677831.524748: {"type":"l2update","product_id":"SKL-USD","changes":[["buy","0.7618","2888.0"]],"time":"2021-04-17T16:43:51.540598Z"}
1618677831.528843: {"type":"l2update","product_id":"SKL-USD","changes":[["sell","0.7943","29765.1"]],"time":"2021-04-17T16:43:51.544266Z"}
1618677831.5322921: {"type":"l2update","product_id":"SKL-USD","changes":[["buy","0.7715","0.0"]],"time":"2021-04-17T16:43:51.546625Z"}
1618677831.532345: {"type":"l2update","product_id":"SKL-USD","changes":[["buy","0.7896","2631.6"]],"time":"2021-04-17T16:43:51.547956Z"}
1618677831.556121: {"type":"l2update","product_id":"DASH-BTC","changes":[["sell","0.00619610","2.57400000"]],"time":"2021-04-17T16:43:51.570302Z"}
1618677831.556173: {"type":"l2update","product_id":"SKL-USD","changes":[["buy","0.7900","8267.3"]],"time":"2021-04-17T16:43:51.570878Z"}
1618677831.560256: {"type":"l2update","product_id":"CRV-EUR","changes":[["sell","3.3112","0.00"]],"time":"2021-04-17T16:43:51.575560Z"}
1618677831.560309: {"type":"l2update","product_id":"CRV-EUR","changes":[["sell","3.3200","0.00"]],"time":"2021-04-17T16:43:51.575560Z"}
1618677831.565656: {"type":"l2update","product_id":"YFI-BTC","changes":[["buy","0.82570","0.017058"]],"time":"2021-04-17T16:43:51.581265Z"}
1618677831.5794508: {"type":"l2update","product_id":"CRV-EUR","changes":[["sell","3.3074","424.00"]],"time":"2021-04-17T16:43:51.592718Z"}
1618677831.579499: {"type":"l2update","product_id":"CRV-EUR","changes":[["sell","3.3112","1416.00"]],"time":"2021-04-17T16:43:51.592718Z"}
1618677831.580865: {"type":"l2update","product_id":"SKL-BTC","changes":[["buy","0.00001299","11255.2"]],"time":"2021-04-17T16:43:51.596727Z"}
1618677831.5902379: {"type":"l2update","product_id":"SKL-USD","changes":[["buy","0.7888","2933.8"]],"time":"2021-04-17T16:43:51.604361Z"}
1618677831.590281: {"type":"l2update","product_id":"BAND-BTC","changes":[["buy","0.00033170","217.49"]],"time":"2021-04-17T16:43:51.605587Z"}
1618677831.590306: {"type":"l2update","product_id":"BAND-BTC","changes":[["sell","0.00033625","0.00"]],"time":"2021-04-17T16:43:51.605587Z"}
1618677831.6052768: {"type":"l2update","product_id":"YFI-BTC","changes":[["buy","0.82316","0.009940"]],"time":"2021-04-17T16:43:51.618522Z"}
1618677831.605322: {"type":"l2update","product_id":"BAND-BTC","changes":[["buy","0.00033324","148.28"]],"time":"2021-04-17T16:43:51.619036Z"}
1618677831.6053581: {"type":"l2update","product_id":"BAND-BTC","changes":[["buy","0.00033218","213.52"]],"time":"2021-04-17T16:43:51.619036Z"}
1618677831.6053839: {"type":"l2update","product_id":"BAND-BTC","changes":[["buy","0.00033170","269.13"]],"time":"2021-04-17T16:43:51.619036Z"}
1618677831.605404: {"type":"l2update","product_id":"BAND-BTC","changes":[["sell","0.00033598","0.94"]],"time":"2021-04-17T16:43:51.619036Z"}
1618677831.605427: {"type":"l2update","product_id":"NMR-EUR","changes":[["buy","66.9096","1.322"]],"time":"2021-04-17T16:43:51.619699Z"}
1618677831.6054459: {"type":"l2update","product_id":"NMR-EUR","changes":[["buy","66.9096","0.000"]],"time":"2021-04-17T16:43:51.619956Z"}
1618677831.609165: {"type":"l2update","product_id":"BAND-BTC","changes":[["sell","0.00033560","47.10"]],"time":"2021-04-17T16:43:51.622635Z"}
1618677831.609212: {"type":"l2update","product_id":"SKL-USD","changes":[["buy","0.7879","4770.6"]],"time":"2021-04-17T16:43:51.622699Z"}
1618677831.609239: {"type":"l2update","product_id":"SKL-USD","changes":[["buy","0.7888","1737.2"]],"time":"2021-04-17T16:43:51.625610Z"}
1618677831.62223: {"type":"l2update","product_id":"DASH-BTC","changes":[["sell","0.00619611","0.00000000"]],"time":"2021-04-17T16:43:51.636889Z"}
1618677831.626613: {"type":"l2update","product_id":"BAND-BTC","changes":[["buy","0.00033323","49.46"]],"time":"2021-04-17T16:43:51.643754Z"}
1618677831.6285791: {"type":"l2update","product_id":"NMR-EUR","changes":[["buy","66.9108","1.322"]],"time":"2021-04-17T16:43:51.644821Z"}
1618677831.630819: {"type":"l2update","product_id":"BAND-BTC","changes":[["sell","0.00033506","0.00"]],"time":"2021-04-17T16:43:51.646957Z"}
1618677831.63087: {"type":"l2update","product_id":"BAND-BTC","changes":[["buy","0.00033323","20.81"]],"time":"2021-04-17T16:43:51.648165Z"}
1618677831.6317608: {"type":"l2update","product_id":"SKL-USD","changes":[["buy","0.7897","1195.2"]],"time":"2021-04-17T16:43:51.648359Z"}
1618677831.63181: {"type":"l2update","product_id":"NMR-EUR","changes":[["buy","66.9108","2.644"]],"time":"2021-04-17T16:43:51.648395Z"}
1618677831.6350899: {"type":"l2update","product_id":"BAND-BTC","changes":[["buy","0.00033323","0.00"]],"time":"2021-04-17T16:43:51.650995Z"}
1618677831.635137: {"type":"l2update","product_id":"NMR-EUR","changes":[["buy","66.9107","0.000"]],"time":"2021-04-17T16:43:51.651613Z"}
1618677831.6414762: {"type":"l2update","product_id":"DASH-BTC","changes":[["sell","0.00619609","0.82500000"]],"time":"2021-04-17T16:43:51.655810Z"}
1618677831.641568: {"type":"l2update","product_id":"NMR-EUR","changes":[["buy","66.9110","4.775"]],"time":"2021-04-17T16:43:51.655822Z"}
1618677831.6478798: {"type":"l2update","product_id":"BAND-BTC","changes":[["buy","0.00033325","20.80"]],"time":"2021-04-17T16:43:51.662885Z"}
1618677831.654033: {"type":"l2update","product_id":"DASH-BTC","changes":[["sell","0.00619718","0.00000000"]],"time":"2021-04-17T16:43:51.667213Z"}
1618677831.660289: {"type":"l2update","product_id":"BAND-BTC","changes":[["buy","0.00033325","49.45"]],"time":"2021-04-17T16:43:51.674310Z"}
1618677831.660337: {"type":"l2update","product_id":"DASH-BTC","changes":[["sell","0.00619360","2.50900000"]],"time":"2021-04-17T16:43:51.674347Z"}
1618677831.669117: {"type":"l2update","product_id":"BAND-BTC","changes":[["buy","0.00033325","70.25"]],"time":"2021-04-17T16:43:51.685328Z"}
1618677831.670343: {"type":"l2update","product_id":"BAND-BTC","changes":[["buy","0.00033419","35.88"]],"time":"2021-04-17T16:43:51.685823Z"}
1618677831.671018: {"type":"l2update","product_id":"SKL-USD","changes":[["sell","0.7953","5.0"]],"time":"2021-04-17T16:43:51.686977Z"}
1618677831.671058: {"type":"l2update","product_id":"SKL-USD","changes":[["buy","0.7826","8443.3"]],"time":"2021-04-17T16:43:51.686977Z"}
1618677831.679043: {"type":"l2update","product_id":"DASH-BTC","changes":[["sell","0.00619717","0.00000000"]],"time":"2021-04-17T16:43:51.692485Z"}
1618677831.6790988: {"type":"l2update","product_id":"BAND-GBP","changes":[["buy","14.7648","12.90"]],"time":"2021-04-17T16:43:51.693085Z"}
1618677831.6791308: {"type":"l2update","product_id":"BAND-BTC","changes":[["sell","0.00033498","36.74"]],"time":"2021-04-17T16:43:51.693117Z"}
1618677831.684593: {"type":"l2update","product_id":"SKL-USD","changes":[["buy","0.7843","8456.3"]],"time":"2021-04-17T16:43:51.696834Z"}
1618677831.68464: {"type":"l2update","product_id":"SKL-USD","changes":[["sell","0.7951","175.8"]],"time":"2021-04-17T16:43:51.696834Z"}
1618677831.6920729: {"type":"l2update","product_id":"SKL-USD","changes":[["buy","0.7715","58335.9"]],"time":"2021-04-17T16:43:51.707607Z"}
1618677831.6921248: {"type":"l2update","product_id":"BAND-BTC","changes":[["sell","0.00033492","28.21"]],"time":"2021-04-17T16:43:51.707643Z"}
1618677831.6921542: {"type":"l2update","product_id":"SKL-USD","changes":[["sell","0.7921","3678.2"]],"time":"2021-04-17T16:43:51.707607Z"}
1618677831.69218: {"type":"l2update","product_id":"SKL-USD","changes":[["sell","0.8001","19642.9"]],"time":"2021-04-17T16:43:51.707607Z"}
1618677831.698549: {"type":"l2update","product_id":"SKL-USD","changes":[["sell","0.7943","5.0"]],"time":"2021-04-17T16:43:51.714377Z"}
1618677831.699518: {"type":"l2update","product_id":"YFI-BTC","changes":[["buy","0.82549","0.029837"]],"time":"2021-04-17T16:43:51.715556Z"}
1618677831.699571: {"type":"l2update","product_id":"DASH-BTC","changes":[["sell","0.00619812","1.62300000"]],"time":"2021-04-17T16:43:51.715587Z"}
1618677831.705987: {"type":"l2update","product_id":"DASH-BTC","changes":[["buy","0.00618544","0.00000000"]],"time":"2021-04-17T16:43:51.720062Z"}
1618677831.724101: {"type":"l2update","product_id":"NMR-EUR","changes":[["buy","66.9108","1.322"]],"time":"2021-04-17T16:43:51.735824Z"}
1618677831.724143: {"type":"l2update","product_id":"NMR-EUR","changes":[["buy","66.9108","0.000"]],"time":"2021-04-17T16:43:51.735923Z"}
1618677831.724181: {"type":"l2update","product_id":"SKL-USD","changes":[["sell","0.7916","32392.0"]],"time":"2021-04-17T16:43:51.737319Z"}
1618677831.727254: {"type":"l2update","product_id":"DASH-BTC","changes":[["buy","0.00618150","1.54400000"]],"time":"2021-04-17T16:43:51.740934Z"}
1618677831.730431: {"type":"l2update","product_id":"YFI-BTC","changes":[["buy","0.82549","0.000000"]],"time":"2021-04-17T16:43:51.744782Z"}
1618677831.7313962: {"type":"l2update","product_id":"NMR-EUR","changes":[["buy","66.9111","1.322"]],"time":"2021-04-17T16:43:51.748416Z"}
1618677831.733887: {"type":"l2update","product_id":"SKL-USD","changes":[["buy","0.7877","0.0"]],"time":"2021-04-17T16:43:51.748835Z"}
1618677831.7456331: {"type":"l2update","product_id":"NMR-EUR","changes":[["buy","66.9111","2.644"]],"time":"2021-04-17T16:43:51.752363Z"}
1618677831.746608: {"type":"l2update","product_id":"NMR-EUR","changes":[["buy","66.9110","0.000"]],"time":"2021-04-17T16:43:51.759292Z"}
1618677831.751961: {"type":"l2update","product_id":"NMR-EUR","changes":[["buy","66.9113","4.775"]],"time":"2021-04-17T16:43:51.768572Z"}
1618677831.758241: {"type":"l2update","product_id":"SKL-BTC","changes":[["sell","0.00001309","3285.4"]],"time":"2021-04-17T16:43:51.774469Z"}
1618677831.814081: {"type":"l2update","product_id":"SKL-USD","changes":[["buy","0.7843","0.0"]],"time":"2021-04-17T16:43:51.817193Z"}
1618677831.835998: {"type":"l2update","product_id":"DASH-BTC","changes":[["buy","0.00618149","0.00000000"]],"time":"2021-04-17T16:43:51.847651Z"}
1618677831.864877: {"type":"l2update","product_id":"SKL-USD","changes":[["sell","0.7916","29760.1"]],"time":"2021-04-17T16:43:51.870200Z"}
1618677831.864993: {"type":"l2update","product_id":"SKL-USD","changes":[["buy","0.7793","160.5"]],"time":"2021-04-17T16:43:51.871246Z"}
1618677831.869987: {"type":"l2update","product_id":"SKL-USD","changes":[["sell","0.7916","0.0"]],"time":"2021-04-17T16:43:51.882632Z"}
1618677831.9088361: {"type":"l2update","product_id":"DASH-BTC","changes":[["buy","0.00618470","0.00000000"]],"time":"2021-04-17T16:43:51.892015Z"}
1618677831.90898: {"type":"l2update","product_id":"CRV-EUR","changes":[["buy","3.2970","5120.00"]],"time":"2021-04-17T16:43:51.894038Z"}
1618677831.9090612: {"type":"l2update","product_id":"SKL-USD","changes":[["buy","0.7888","868.3"]],"time":"2021-04-17T16:43:51.897816Z"}
1618677831.90909: {"type":"l2update","product_id":"NMR-EUR","changes":[["buy","66.9111","1.322"]],"time":"2021-04-17T16:43:51.903411Z"}
1618677831.9091141: {"type":"l2update","product_id":"NMR-EUR","changes":[["buy","66.9111","0.000"]],"time":"2021-04-17T16:43:51.903593Z"}
1618677831.909145: {"type":"l2update","product_id":"SKL-USD","changes":[["sell","0.7943","29765.1"]],"time":"2021-04-17T16:43:51.905809Z"}
1618677831.9091682: {"type":"l2update","product_id":"BAND-BTC","changes":[["sell","0.00034991","0.00"]],"time":"2021-04-17T16:43:51.911687Z"}
1618677831.909199: {"type":"l2update","product_id":"DASH-BTC","changes":[["buy","0.00618072","1.12100000"]],"time":"2021-04-17T16:43:51.913998Z"}
1618677831.909229: {"type":"l2update","product_id":"SKL-USD","changes":[["buy","0.7897","2063.1"]],"time":"2021-04-17T16:43:51.920668Z"}
1618677831.9092522: {"type":"l2update","product_id":"SKL-USD","changes":[["buy","0.7888","0.0"]],"time":"2021-04-17T16:43:51.923987Z"}
1618677831.9676201: {"type":"l2update","product_id":"NMR-EUR","changes":[["buy","66.9114","1.322"]],"time":"2021-04-17T16:43:51.924755Z"}
1618677831.967753: {"type":"l2update","product_id":"SKL-BTC","changes":[["sell","0.00001309","2462.6"]],"time":"2021-04-17T16:43:51.925167Z"}
1618677831.967807: {"type":"l2update","product_id":"DASH-BTC","changes":[["sell","0.00864891","2.93000000"]],"time":"2021-04-17T16:43:51.925927Z"}
1618677831.96785: {"type":"l2update","product_id":"NMR-EUR","changes":[["buy","66.9114","2.644"]],"time":"2021-04-17T16:43:51.928467Z"}
1618677831.967886: {"type":"l2update","product_id":"SKL-USD","changes":[["sell","0.7917","3976.1"]],"time":"2021-04-17T16:43:51.928480Z"}
1618677831.967922: {"type":"l2update","product_id":"DASH-BTC","changes":[["sell","0.00864891","4.80000000"]],"time":"2021-04-17T16:43:51.932030Z"}
1618677831.9679549: {"type":"l2update","product_id":"NMR-EUR","changes":[["buy","66.9113","0.000"]],"time":"2021-04-17T16:43:51.932432Z"}
1618677831.968022: {"type":"l2update","product_id":"NMR-EUR","changes":[["buy","66.9116","4.775"]],"time":"2021-04-17T16:43:51.936305Z"}
1618677831.9680462: {"type":"l2update","product_id":"SKL-USD","changes":[["buy","0.7901","866.9"]],"time":"2021-04-17T16:43:51.947514Z"}
1618677831.968074: {"type":"l2update","product_id":"SKL-USD","changes":[["buy","0.7828","8611.3"]],"time":"2021-04-17T16:43:51.961869Z"}
1618677831.968096: {"type":"l2update","product_id":"SKL-USD","changes":[["buy","0.7883","1389.1"]],"time":"2021-04-17T16:43:51.979864Z"}
1618677831.968116: {"type":"l2update","product_id":"DASH-BTC","changes":[["sell","0.00619609","0.00000000"]],"time":"2021-04-17T16:43:51.980746Z"}
1618677831.9681458: {"type":"l2update","product_id":"SKL-USD","changes":[["buy","0.7828","155.0"]],"time":"2021-04-17T16:43:51.981252Z"}
1618677831.968168: {"type":"l2update","product_id":"BAND-BTC","changes":[["buy","0.00033419","0.00"]],"time":"2021-04-17T16:43:51.981948Z"}
1618677831.9744442: {"type":"l2update","product_id":"CRV-EUR","changes":[["buy","3.2969","0.00"]],"time":"2021-04-17T16:43:51.982355Z"}
1618677831.9745789: {"type":"l2update","product_id":"BAND-GBP","changes":[["sell","14.7944","0.00"]],"time":"2021-04-17T16:43:51.988623Z"}
1618677831.974644: {"type":"l2update","product_id":"CRV-EUR","changes":[["buy","3.2970","120.00"]],"time":"2021-04-17T16:43:51.989273Z"}
1618677831.978237: {"type":"l2update","product_id":"BAND-GBP","changes":[["buy","14.7679","12.17"]],"time":"2021-04-17T16:43:51.990901Z"}
1618677831.9849741: {"type":"l2update","product_id":"DASH-BTC","changes":[["sell","0.00620282","0.00000000"]],"time":"2021-04-17T16:43:52.001114Z"}
1618677831.989032: {"type":"l2update","product_id":"DASH-BTC","changes":[["sell","0.00619359","0.82500000"]],"time":"2021-04-17T16:43:52.003628Z"}
1618677831.9991648: {"type":"l2update","product_id":"SKL-USD","changes":[["sell","0.7917","2631.4"]],"time":"2021-04-17T16:43:52.008873Z"}
1618677831.9992828: {"type":"l2update","product_id":"BAND-GBP","changes":[["sell","14.7954","12.26"]],"time":"2021-04-17T16:43:52.010640Z"}
1618677831.9993548: {"type":"l2update","product_id":"DASH-BTC","changes":[["sell","0.00621210","0.00000000"]],"time":"2021-04-17T16:43:52.011137Z"}
1618677832.0183308: {"type":"l2update","product_id":"DASH-BTC","changes":[["sell","0.00619949","0.80000000"]],"time":"2021-04-17T16:43:52.018242Z"}
1618677832.01849: {"type":"l2update","product_id":"NU-GBP","changes":[["sell","0.4400","81501.605060"]],"time":"2021-04-17T16:43:52.019009Z"}
1618677832.0185258: {"type":"l2update","product_id":"DASH-BTC","changes":[["buy","0.00618469","0.00000000"]],"time":"2021-04-17T16:43:52.024177Z"}
1618677832.0185652: {"type":"l2update","product_id":"BAND-BTC","changes":[["sell","0.00033481","22.00"]],"time":"2021-04-17T16:43:52.025988Z"}
1618677832.0186: {"type":"l2update","product_id":"SKL-USD","changes":[["buy","0.7801","73109.2"]],"time":"2021-04-17T16:43:52.029611Z"}
1618677832.018629: {"type":"l2update","product_id":"SKL-USD","changes":[["sell","0.7918","24355.9"]],"time":"2021-04-17T16:43:52.029630Z"}
1618677832.0285661: {"type":"l2update","product_id":"DASH-BTC","changes":[["sell","0.00619970","0.00000000"]],"time":"2021-04-17T16:43:52.036377Z"}
1618677832.042608: {"type":"l2update","product_id":"YFI-BTC","changes":[["buy","0.81897","0.000000"]],"time":"2021-04-17T16:43:52.055096Z"}
1618677832.046046: {"type":"l2update","product_id":"DASH-BTC","changes":[["sell","0.00619948","2.23600000"]],"time":"2021-04-17T16:43:52.059318Z"}
1618677832.060189: {"type":"l2update","product_id":"DASH-BTC","changes":[["buy","0.00618150","0.00000000"]],"time":"2021-04-17T16:43:52.075666Z"}
1618677832.06033: {"type":"l2update","product_id":"DASH-BTC","changes":[["buy","0.00617109","0.00000000"]],"time":"2021-04-17T16:43:52.076375Z"}
1618677832.0603929: {"type":"l2update","product_id":"BAND-BTC","changes":[["buy","0.00033324","0.00"]],"time":"2021-04-17T16:43:52.076835Z"}
1618677832.069739: {"type":"l2update","product_id":"NMR-EUR","changes":[["buy","66.9114","1.322"]],"time":"2021-04-17T16:43:52.079071Z"}
1618677832.0698612: {"type":"l2update","product_id":"NMR-EUR","changes":[["buy","66.9114","0.000"]],"time":"2021-04-17T16:43:52.079539Z"}
1618677832.0699341: {"type":"l2update","product_id":"BAND-GBP","changes":[["buy","14.7679","0.00"]],"time":"2021-04-17T16:43:52.084135Z"}
1618677832.077429: {"type":"l2update","product_id":"DASH-BTC","changes":[["buy","0.00618543","0.29500000"]],"time":"2021-04-17T16:43:52.089027Z"}
1618677832.0840802: {"type":"l2update","product_id":"BAND-BTC","changes":[["buy","0.00033325","49.45"]],"time":"2021-04-17T16:43:52.096025Z"}
1618677832.084197: {"type":"l2update","product_id":"DASH-BTC","changes":[["buy","0.00618072","2.66600000"]],"time":"2021-04-17T16:43:52.097008Z"}
1618677832.084251: {"type":"l2update","product_id":"NMR-EUR","changes":[["buy","66.9117","1.322"]],"time":"2021-04-17T16:43:52.097297Z"}
1618677832.08431: {"type":"l2update","product_id":"BAND-BTC","changes":[["buy","0.00033325","20.80"]],"time":"2021-04-17T16:43:52.100002Z"}
1618677832.090474: {"type":"l2update","product_id":"NMR-EUR","changes":[["buy","66.9117","2.644"]],"time":"2021-04-17T16:43:52.100949Z"}
1618677832.0932338: {"type":"l2update","product_id":"NMR-EUR","changes":[["buy","66.9116","0.000"]],"time":"2021-04-17T16:43:52.105113Z"}
1618677832.096843: {"type":"l2update","product_id":"SKL-GBP","changes":[["sell","0.5772","3535.4"]],"time":"2021-04-17T16:43:52.108038Z"}
1618677832.0988538: {"type":"l2update","product_id":"NMR-EUR","changes":[["buy","66.9119","4.775"]],"time":"2021-04-17T16:43:52.111434Z"}
1618677832.099689: {"type":"l2update","product_id":"BAND-BTC","changes":[["buy","0.00033323","20.81"]],"time":"2021-04-17T16:43:52.115283Z"}
1618677832.1014569: {"type":"l2update","product_id":"SKL-USD","changes":[["sell","0.7952","5.0"]],"time":"2021-04-17T16:43:52.116229Z"}
1618677832.116565: {"type":"l2update","product_id":"BAND-BTC","changes":[["buy","0.00033323","49.46"]],"time":"2021-04-17T16:43:52.126673Z"}
1618677832.129914: {"type":"l2update","product_id":"DASH-BTC","changes":[["buy","0.00618543","2.86900000"]],"time":"2021-04-17T16:43:52.138072Z"}
1618677832.130003: {"type":"l2update","product_id":"SKL-BTC","changes":[["sell","0.00001307","7997.4"]],"time":"2021-04-17T16:43:52.138543Z"}
1618677832.1338098: {"type":"l2update","product_id":"DASH-BTC","changes":[["buy","0.00618542","0.00000000"]],"time":"2021-04-17T16:43:52.146054Z"}
1618677832.143172: {"type":"l2update","product_id":"SKL-GBP","changes":[["sell","0.5772","2527.2"]],"time":"2021-04-17T16:43:52.156762Z"}
1618677832.150574: {"type":"l2update","product_id":"DASH-BTC","changes":[["buy","0.00618543","2.57400000"]],"time":"2021-04-17T16:43:52.162692Z"}
1618677832.163558: {"type":"l2update","product_id":"SKL-GBP","changes":[["sell","0.5772","3535.4"]],"time":"2021-04-17T16:43:52.171317Z"}
1618677832.168525: {"type":"l2update","product_id":"DASH-BTC","changes":[["buy","0.00618072","2.96100000"]],"time":"2021-04-17T16:43:52.183037Z"}
1618677832.177404: {"type":"l2update","product_id":"NMR-EUR","changes":[["buy","66.9117","1.322"]],"time":"2021-04-17T16:43:52.185424Z"}
1618677832.1775239: {"type":"l2update","product_id":"NMR-EUR","changes":[["buy","66.9117","0.000"]],"time":"2021-04-17T16:43:52.186108Z"}
1618677832.188208: {"type":"l2update","product_id":"NMR-EUR","changes":[["buy","66.9120","1.322"]],"time":"2021-04-17T16:43:52.201159Z"}
1618677832.194519: {"type":"l2update","product_id":"NMR-EUR","changes":[["buy","66.9120","2.644"]],"time":"2021-04-17T16:43:52.205529Z"}
1618677832.1946392: {"type":"l2update","product_id":"NMR-EUR","changes":[["buy","66.9119","0.000"]],"time":"2021-04-17T16:43:52.208273Z"}
1618677832.207283: {"type":"l2update","product_id":"SKL-BTC","changes":[["sell","0.00001307","4208.5"]],"time":"2021-04-17T16:43:52.213033Z"}
1618677832.207401: {"type":"l2update","product_id":"NMR-EUR","changes":[["buy","66.4658","0.000"]],"time":"2021-04-17T16:43:52.214507Z"}
1618677832.207478: {"type":"l2update","product_id":"SKL-GBP","changes":[["sell","0.5772","1008.2"]],"time":"2021-04-17T16:43:52.213871Z"}
1618677832.2075222: {"type":"l2update","product_id":"SKL-USD","changes":[["sell","0.7925","0.0"]],"time":"2021-04-17T16:43:52.213140Z"}
1618677832.2095518: {"type":"l2update","product_id":"BAND-GBP","changes":[["buy","14.7576","0.00"]],"time":"2021-04-17T16:43:52.213599Z"}
1618677832.210863: {"type":"l2update","product_id":"NMR-EUR","changes":[["buy","66.9122","4.775"]],"time":"2021-04-17T16:43:52.216220Z"}
1618677832.212779: {"type":"l2update","product_id":"SKL-GBP","changes":[["buy","0.5740","0.0"]],"time":"2021-04-17T16:43:52.219252Z"}
1618677832.2150779: {"type":"l2update","product_id":"DASH-BTC","changes":[["buy","0.00617543","0.00000000"]],"time":"2021-04-17T16:43:52.221475Z"}
1618677832.2152178: {"type":"l2update","product_id":"SKL-GBP","changes":[["sell","0.5775","0.0"]],"time":"2021-04-17T16:43:52.222271Z"}
1618677832.2156842: {"type":"l2update","product_id":"BAND-BTC","changes":[["buy","0.00033404","0.00"]],"time":"2021-04-17T16:43:52.222382Z"}
1618677832.219177: {"type":"l2update","product_id":"NMR-EUR","changes":[["buy","66.7001","18.850"]],"time":"2021-04-17T16:43:52.231851Z"}
1618677832.2193122: {"type":"l2update","product_id":"SKL-BTC","changes":[["sell","0.00001309","3285.4"]],"time":"2021-04-17T16:43:52.232134Z"}
1618677832.240566: {"type":"l2update","product_id":"SKL-BTC","changes":[["buy","0.00001302","7444.0"]],"time":"2021-04-17T16:43:52.250605Z"}
1618677832.240683: {"type":"l2update","product_id":"CRV-EUR","changes":[["buy","3.2971","0.00"]],"time":"2021-04-17T16:43:52.252862Z"}
1618677832.240757: {"type":"l2update","product_id":"DASH-BTC","changes":[["buy","0.00616179","5.72000000"]],"time":"2021-04-17T16:43:52.254372Z"}
1618677832.254412: {"type":"l2update","product_id":"CRV-EUR","changes":[["buy","3.2961","919.50"]],"time":"2021-04-17T16:43:52.269101Z"}
1618677832.261918: {"type":"l2update","product_id":"CRV-EUR","changes":[["buy","3.2961","519.50"]],"time":"2021-04-17T16:43:52.272823Z"}
1618677832.2670238: {"type":"l2update","product_id":"BAND-GBP","changes":[["buy","14.7615","36.00"]],"time":"2021-04-17T16:43:52.280492Z"}
1618677832.270397: {"type":"l2update","product_id":"CRV-EUR","changes":[["sell","3.3019","534.73"]],"time":"2021-04-17T16:43:52.284146Z"}
1618677832.274055: {"type":"l2update","product_id":"SKL-USD","changes":[["buy","0.7895","0.0"]],"time":"2021-04-17T16:43:52.285772Z"}
1618677832.286696: {"type":"l2update","product_id":"CRV-EUR","changes":[["buy","3.2955","0.00"]],"time":"2021-04-17T16:43:52.296256Z"}
1618677832.28679: {"type":"l2update","product_id":"CRV-EUR","changes":[["sell","3.3059","0.00"]],"time":"2021-04-17T16:43:52.298478Z"}
1618677832.2868311: {"type":"l2update","product_id":"BAND-GBP","changes":[["buy","14.7648","0.00"]],"time":"2021-04-17T16:43:52.300390Z"}
1618677832.2868638: {"type":"l2update","product_id":"DASH-BTC","changes":[["buy","0.00618389","0.00000000"]],"time":"2021-04-17T16:43:52.301162Z"}
1618677832.2918541: {"type":"l2update","product_id":"BAND-GBP","changes":[["sell","14.7892","12.85"]],"time":"2021-04-17T16:43:52.302963Z"}
1618677832.291949: {"type":"l2update","product_id":"CRV-EUR","changes":[["sell","3.3018","5000.00"]],"time":"2021-04-17T16:43:52.303025Z"}
1618677832.29199: {"type":"l2update","product_id":"CRV-EUR","changes":[["buy","3.2947","5000.00"]],"time":"2021-04-17T16:43:52.303310Z"}
1618677832.29977: {"type":"l2update","product_id":"BAND-GBP","changes":[["buy","14.7614","12.58"]],"time":"2021-04-17T16:43:52.308277Z"}
1618677832.299885: {"type":"l2update","product_id":"SKL-USD","changes":[["buy","0.7897","867.9"]],"time":"2021-04-17T16:43:52.309963Z"}
1618677832.299938: {"type":"l2update","product_id":"BAND-BTC","changes":[["buy","0.00033325","0.00"]],"time":"2021-04-17T16:43:52.310828Z"}
1618677832.3010108: {"type":"l2update","product_id":"DASH-BTC","changes":[["buy","0.00617764","2.64600000"]],"time":"2021-04-17T16:43:52.314498Z"}
1618677832.3011148: {"type":"l2update","product_id":"BAND-GBP","changes":[["buy","14.7617","27.53"]],"time":"2021-04-17T16:43:52.314527Z"}
1618677832.307643: {"type":"l2update","product_id":"CRV-EUR","changes":[["buy","3.2961","0.00"]],"time":"2021-04-17T16:43:52.316301Z"}
1618677832.307738: {"type":"l2update","product_id":"BAND-BTC","changes":[["sell","0.00033492","0.00"]],"time":"2021-04-17T16:43:52.316571Z"}
1618677832.307783: {"type":"l2update","product_id":"NMR-EUR","changes":[["buy","66.4816","24.451"]],"time":"2021-04-17T16:43:52.317677Z"}
1618677832.307814: {"type":"l2update","product_id":"NMR-EUR","changes":[["buy","66.4814","0.000"]],"time":"2021-04-17T16:43:52.317677Z"}
1618677832.3078458: {"type":"l2update","product_id":"NMR-EUR","changes":[["buy","66.4816","1.231"]],"time":"2021-04-17T16:43:52.317677Z"}
1618677832.30787: {"type":"l2update","product_id":"DASH-BTC","changes":[["buy","0.00618365","2.63900000"]],"time":"2021-04-17T16:43:52.318346Z"}
1618677832.3079019: {"type":"l2update","product_id":"DASH-BTC","changes":[["sell","0.00619360","0.00000000"]],"time":"2021-04-17T16:43:52.319860Z"}
1618677832.3079329: {"type":"l2update","product_id":"DASH-BTC","changes":[["buy","0.00618365","0.00000000"]],"time":"2021-04-17T16:43:52.322381Z"}
1618677832.30796: {"type":"l2update","product_id":"CRV-EUR","changes":[["sell","3.3011","502.42"]],"time":"2021-04-17T16:43:52.322391Z"}
1618677832.307988: {"type":"l2update","product_id":"DASH-BTC","changes":[["buy","0.00618032","2.66200000"]],"time":"2021-04-17T16:43:52.322418Z"}
1618677832.313761: {"type":"l2update","product_id":"NMR-EUR","changes":[["buy","66.4821","23.350"]],"time":"2021-04-17T16:43:52.326756Z"}
1618677832.313877: {"type":"l2update","product_id":"NMR-EUR","changes":[["buy","66.4818","23.410"]],"time":"2021-04-17T16:43:52.326756Z"}
1618677832.313928: {"type":"l2update","product_id":"NMR-EUR","changes":[["buy","66.4819","4.750"]],"time":"2021-04-17T16:43:52.326756Z"}
1618677832.317114: {"type":"l2update","product_id":"SKL-USD","changes":[["buy","0.7888","1196.6"]],"time":"2021-04-17T16:43:52.330047Z"}
1618677832.317239: {"type":"l2update","product_id":"BAND-BTC","changes":[["buy","0.00033323","70.27"]],"time":"2021-04-17T16:43:52.330104Z"}
1618677832.320099: {"type":"l2update","product_id":"CRV-EUR","changes":[["buy","3.2938","541.03"]],"time":"2021-04-17T16:43:52.333810Z"}
1618677832.320201: {"type":"l2update","product_id":"DASH-BTC","changes":[["buy","0.00618073","10.74600000"]],"time":"2021-04-17T16:43:52.334061Z"}
1618677832.320263: {"type":"l2update","product_id":"CRV-EUR","changes":[["sell","3.3050","0.00"]],"time":"2021-04-17T16:43:52.334981Z"}
1618677832.326431: {"type":"l2update","product_id":"CRV-EUR","changes":[["buy","3.2919","1619.88"]],"time":"2021-04-17T16:43:52.338006Z"}
1618677832.336202: {"type":"l2update","product_id":"YFI-BTC","changes":[["buy","0.82064","0.001860"]],"time":"2021-04-17T16:43:52.350213Z"}
1618677832.336297: {"type":"l2update","product_id":"SKL-USD","changes":[["buy","0.7855","1015.0"]],"time":"2021-04-17T16:43:52.350469Z"}
1618677832.336332: {"type":"l2update","product_id":"SKL-USD","changes":[["buy","0.7854","5.0"]],"time":"2021-04-17T16:43:52.350469Z"}
1618677832.341964: {"type":"l2update","product_id":"DASH-BTC","changes":[["sell","0.00619359","0.00000000"]],"time":"2021-04-17T16:43:52.358143Z"}
1618677832.3427782: {"type":"l2update","product_id":"SKL-USD","changes":[["buy","0.7868","1015.0"]],"time":"2021-04-17T16:43:52.358870Z"}
1618677832.342883: {"type":"l2update","product_id":"SKL-USD","changes":[["buy","0.7872","216.7"]],"time":"2021-04-17T16:43:52.358870Z"}
1618677832.342935: {"type":"l2update","product_id":"YFI-BTC","changes":[["buy","0.81917","0.010430"]],"time":"2021-04-17T16:43:52.358895Z"}
1618677832.3429859: {"type":"l2update","product_id":"SKL-USD","changes":[["buy","0.7873","10.0"]],"time":"2021-04-17T16:43:52.358870Z"}
1618677832.346105: {"type":"l2update","product_id":"SKL-BTC","changes":[["sell","0.00001308","16416.1"]],"time":"2021-04-17T16:43:52.361675Z"}
1618677832.357416: {"type":"l2update","product_id":"NMR-EUR","changes":[["buy","66.9120","1.322"]],"time":"2021-04-17T16:43:52.368431Z"}
1618677832.357533: {"type":"l2update","product_id":"NMR-EUR","changes":[["buy","66.9120","0.000"]],"time":"2021-04-17T16:43:52.369173Z"}
1618677832.358158: {"type":"l2update","product_id":"YFI-BTC","changes":[["buy","0.82585","0.000000"]],"time":"2021-04-17T16:43:52.373693Z"}
1618677832.365746: {"type":"l2update","product_id":"DASH-BTC","changes":[["sell","0.00619609","0.82500000"]],"time":"2021-04-17T16:43:52.379268Z"}
1618677832.3691661: {"type":"l2update","product_id":"CRV-EUR","changes":[["buy","3.2919","400.00"]],"time":"2021-04-17T16:43:52.384682Z"}
1618677832.369281: {"type":"l2update","product_id":"DASH-BTC","changes":[["sell","0.00620889","0.00000000"]],"time":"2021-04-17T16:43:52.385222Z"}
1618677832.36936: {"type":"l2update","product_id":"CRV-EUR","changes":[["buy","3.2918","0.00"]],"time":"2021-04-17T16:43:52.385990Z"}
1618677832.372042: {"type":"l2update","product_id":"DASH-BTC","changes":[["buy","0.00617587","0.90000000"]],"time":"2021-04-17T16:43:52.386924Z"}
1618677832.3757792: {"type":"l2update","product_id":"DASH-BTC","changes":[["sell","0.00619609","1.82500000"]],"time":"2021-04-17T16:43:52.390763Z"}
1618677832.379858: {"type":"l2update","product_id":"NMR-EUR","changes":[["buy","66.9123","1.322"]],"time":"2021-04-17T16:43:52.394771Z"}
1618677832.3804889: {"type":"l2update","product_id":"CRV-EUR","changes":[["sell","3.3027","0.00"]],"time":"2021-04-17T16:43:52.396161Z"}
1618677832.380598: {"type":"l2update","product_id":"DASH-BTC","changes":[["buy","0.00618013","0.00000000"]],"time":"2021-04-17T16:43:52.397264Z"}
1618677832.393501: {"type":"l2update","product_id":"NMR-EUR","changes":[["buy","66.9123","2.644"]],"time":"2021-04-17T16:43:52.399212Z"}
1618677832.393617: {"type":"l2update","product_id":"NMR-EUR","changes":[["buy","66.9122","0.000"]],"time":"2021-04-17T16:43:52.404410Z"}
1618677832.3936908: {"type":"l2update","product_id":"DASH-BTC","changes":[["buy","0.00618032","0.00000000"]],"time":"2021-04-17T16:43:52.404964Z"}
1618677832.395821: {"type":"l2update","product_id":"DASH-BTC","changes":[["buy","0.00616179","0.00000000"]],"time":"2021-04-17T16:43:52.406872Z"}
1618677832.3978298: {"type":"l2update","product_id":"DASH-BTC","changes":[["sell","0.00620095","0.00000000"]],"time":"2021-04-17T16:43:52.412538Z"}
1618677832.4032362: {"type":"l2update","product_id":"DASH-BTC","changes":[["buy","0.00618072","1.41600000"]],"time":"2021-04-17T16:43:52.416417Z"}
1618677832.407528: {"type":"l2update","product_id":"DASH-BTC","changes":[["buy","0.00617588","5.72000000"]],"time":"2021-04-17T16:43:52.421484Z"}
1618677832.413829: {"type":"l2update","product_id":"NMR-EUR","changes":[["buy","66.9125","4.775"]],"time":"2021-04-17T16:43:52.424739Z"}
1618677832.41396: {"type":"l2update","product_id":"DASH-BTC","changes":[["sell","0.00619640","2.64400000"]],"time":"2021-04-17T16:43:52.424815Z"}
1618677832.421817: {"type":"l2update","product_id":"DASH-BTC","changes":[["buy","0.00618074","1.54500000"]],"time":"2021-04-17T16:43:52.436300Z"}
1618677832.4224: {"type":"l2update","product_id":"CRV-EUR","changes":[["buy","3.2830","0.00"]],"time":"2021-04-17T16:43:52.439093Z"}
1618677832.435717: {"type":"l2update","product_id":"DASH-BTC","changes":[["buy","0.00618071","0.00000000"]],"time":"2021-04-17T16:43:52.447419Z"}
1618677832.435861: {"type":"l2update","product_id":"DASH-BTC","changes":[["buy","0.00618009","0.00000000"]],"time":"2021-04-17T16:43:52.448010Z"}
1618677832.4359229: {"type":"l2update","product_id":"CRV-EUR","changes":[["sell","3.3045","0.00"]],"time":"2021-04-17T16:43:52.449950Z"}
1618677832.440532: {"type":"l2update","product_id":"CRV-EUR","changes":[["buy","3.2806","256.82"]],"time":"2021-04-17T16:43:52.450866Z"}
1618677832.440665: {"type":"l2update","product_id":"CRV-EUR","changes":[["sell","3.3113","0.00"]],"time":"2021-04-17T16:43:52.454060Z"}
1618677832.4464362: {"type":"l2update","product_id":"DASH-BTC","changes":[["sell","0.00618989","2.50900000"]],"time":"2021-04-17T16:43:52.462007Z"}
1618677832.451953: {"type":"l2update","product_id":"SKL-USD","changes":[["sell","0.7924","0.0"]],"time":"2021-04-17T16:43:52.465744Z"}
1618677832.464872: {"type":"l2update","product_id":"NMR-EUR","changes":[["buy","66.4817","1.520"]],"time":"2021-04-17T16:43:52.468897Z"}
1618677832.464948: {"type":"l2update","product_id":"CRV-EUR","changes":[["sell","3.3028","753.34"]],"time":"2021-04-17T16:43:52.469303Z"}
1618677832.464982: {"type":"l2update","product_id":"DASH-BTC","changes":[["sell","0.00620622","0.00000000"]],"time":"2021-04-17T16:43:52.470363Z"}
1618677832.4650261: {"type":"l2update","product_id":"DASH-BTC","changes":[["buy","0.00617587","0.00000000"]],"time":"2021-04-17T16:43:52.470491Z"}
1618677832.46506: {"type":"l2update","product_id":"CRV-EUR","changes":[["buy","3.2806","0.00"]],"time":"2021-04-17T16:43:52.470863Z"}
1618677832.46509: {"type":"l2update","product_id":"NMR-EUR","changes":[["buy","66.4822","0.250"]],"time":"2021-04-17T16:43:52.479070Z"}
1618677832.465121: {"type":"l2update","product_id":"NMR-EUR","changes":[["buy","66.4821","23.370"]],"time":"2021-04-17T16:43:52.479070Z"}
1618677832.4651442: {"type":"l2update","product_id":"DASH-BTC","changes":[["sell","0.00619083","1.10000000"]],"time":"2021-04-17T16:43:52.479186Z"}
1618677832.469097: {"type":"l2update","product_id":"SKL-USD","changes":[["sell","0.7917","9539.4"]],"time":"2021-04-17T16:43:52.480560Z"}
1618677832.469159: {"type":"l2update","product_id":"CRV-EUR","changes":[["sell","3.3077","1414.55"]],"time":"2021-04-17T16:43:52.480646Z"}
1618677832.469193: {"type":"l2update","product_id":"DASH-BTC","changes":[["sell","0.00620175","0.00000000"]],"time":"2021-04-17T16:43:52.483051Z"}
1618677832.4692328: {"type":"l2update","product_id":"DASH-BTC","changes":[["buy","0.00617737","32.84700000"]],"time":"2021-04-17T16:43:52.484074Z"}
1618677832.475958: {"type":"l2update","product_id":"DASH-BTC","changes":[["buy","0.00618543","0.00000000"]],"time":"2021-04-17T16:43:52.488743Z"}
1618677832.4850528: {"type":"l2update","product_id":"BAND-BTC","changes":[["buy","0.00033425","0.00"]],"time":"2021-04-17T16:43:52.498165Z"}
1618677832.485152: {"type":"l2update","product_id":"DASH-BTC","changes":[["sell","0.00619798","14.63200000"]],"time":"2021-04-17T16:43:52.498972Z"}
1618677832.4852: {"type":"l2update","product_id":"NMR-EUR","changes":[["buy","66.9123","1.322"]],"time":"2021-04-17T16:43:52.500408Z"}
1618677832.4872708: {"type":"l2update","product_id":"NMR-EUR","changes":[["buy","66.9123","0.000"]],"time":"2021-04-17T16:43:52.501139Z"}
1618677832.487335: {"type":"l2update","product_id":"DASH-BTC","changes":[["buy","0.00618072","1.12100000"]],"time":"2021-04-17T16:43:52.502399Z"}
1618677832.487372: {"type":"l2update","product_id":"SKL-USD","changes":[["sell","0.7948","1263.2"]],"time":"2021-04-17T16:43:52.502672Z"}
1618677832.49202: {"type":"l2update","product_id":"SKL-USD","changes":[["buy","0.7681","2042.0"]],"time":"2021-04-17T16:43:52.506402Z"}
1618677832.49216: {"type":"l2update","product_id":"SKL-USD","changes":[["buy","0.7578","2888.0"]],"time":"2021-04-17T16:43:52.506402Z"}
1618677832.5000188: {"type":"l2update","product_id":"SKL-GBP","changes":[["sell","0.5779","0.0"]],"time":"2021-04-17T16:43:52.512306Z"}
1618677832.5001578: {"type":"l2update","product_id":"DASH-BTC","changes":[["sell","0.00618668","2.50900000"]],"time":"2021-04-17T16:43:52.513467Z"}
1618677832.503547: {"type":"l2update","product_id":"SKL-GBP","changes":[["sell","0.5771","285.0"]],"time":"2021-04-17T16:43:52.517437Z"}
1618677832.511786: {"type":"l2update","product_id":"DASH-BTC","changes":[["buy","0.00618074","1.84000000"]],"time":"2021-04-17T16:43:52.521758Z"}
1618677832.511909: {"type":"l2update","product_id":"NMR-EUR","changes":[["buy","66.9126","1.322"]],"time":"2021-04-17T16:43:52.525077Z"}
1618677832.5119739: {"type":"l2update","product_id":"CRV-EUR","changes":[["buy","3.2706","0.50"]],"time":"2021-04-17T16:43:52.525440Z"}
1618677832.512017: {"type":"l2update","product_id":"CRV-EUR","changes":[["buy","3.2706","0.00"]],"time":"2021-04-17T16:43:52.525440Z"}
1618677832.515156: {"type":"l2update","product_id":"NMR-EUR","changes":[["buy","66.9126","2.644"]],"time":"2021-04-17T16:43:52.529214Z"}
1618677832.515243: {"type":"l2update","product_id":"DASH-BTC","changes":[["buy","0.00618072","0.00000000"]],"time":"2021-04-17T16:43:52.531142Z"}
1618677832.515313: {"type":"l2update","product_id":"NMR-EUR","changes":[["buy","66.9125","0.000"]],"time":"2021-04-17T16:43:52.531783Z"}
1618677832.520763: {"type":"l2update","product_id":"CRV-EUR","changes":[["sell","3.3200","9.00"]],"time":"2021-04-17T16:43:52.532535Z"}
1618677832.520902: {"type":"l2update","product_id":"CRV-EUR","changes":[["buy","3.2697","103.50"]],"time":"2021-04-17T16:43:52.532535Z"}
1618677832.5209558: {"type":"l2update","product_id":"YFI-BTC","changes":[["sell","0.82744","0.016000"]],"time":"2021-04-17T16:43:52.532614Z"}
1618677832.523392: {"type":"l2update","product_id":"BAND-BTC","changes":[["buy","0.00033380","0.00"]],"time":"2021-04-17T16:43:52.534417Z"}
1618677832.523499: {"type":"l2update","product_id":"DASH-BTC","changes":[["sell","0.00619812","0.00000000"]],"time":"2021-04-17T16:43:52.535273Z"}
1618677832.523566: {"type":"l2update","product_id":"NMR-EUR","changes":[["buy","66.9128","4.775"]],"time":"2021-04-17T16:43:52.536184Z"}
1618677832.523621: {"type":"l2update","product_id":"SKL-USD","changes":[["buy","0.7897","0.0"]],"time":"2021-04-17T16:43:52.536437Z"}
1618677832.5236712: {"type":"l2update","product_id":"DASH-BTC","changes":[["sell","0.00619948","0.00000000"]],"time":"2021-04-17T16:43:52.537846Z"}
1618677832.525011: {"type":"l2update","product_id":"YFI-BTC","changes":[["sell","0.82718","0.030343"]],"time":"2021-04-17T16:43:52.539911Z"}
1618677832.52513: {"type":"l2update","product_id":"DASH-BTC","changes":[["buy","0.00618075","2.57600000"]],"time":"2021-04-17T16:43:52.540069Z"}
1618677832.527427: {"type":"l2update","product_id":"DASH-BTC","changes":[["sell","0.00620174","0.00000000"]],"time":"2021-04-17T16:43:52.540632Z"}
1618677832.531574: {"type":"l2update","product_id":"BAND-BTC","changes":[["buy","0.00033427","36.75"]],"time":"2021-04-17T16:43:52.545613Z"}
1618677832.539329: {"type":"l2update","product_id":"DASH-BTC","changes":[["buy","0.00617765","1.12200000"]],"time":"2021-04-17T16:43:52.552060Z"}
1618677832.5426571: {"type":"l2update","product_id":"CRV-EUR","changes":[["buy","3.2964","140.93"]],"time":"2021-04-17T16:43:52.558148Z"}
1618677832.54582: {"type":"l2update","product_id":"CRV-EUR","changes":[["buy","3.2964","0.00"]],"time":"2021-04-17T16:43:52.558203Z"}
1618677832.545911: {"type":"l2update","product_id":"CRV-EUR","changes":[["sell","3.3077","1273.62"]],"time":"2021-04-17T16:43:52.558553Z"}
1618677832.5459478: {"type":"l2update","product_id":"BAND-BTC","changes":[["buy","0.00033361","27.00"]],"time":"2021-04-17T16:43:52.558656Z"}
1618677832.545986: {"type":"l2update","product_id":"SKL-USD","changes":[["buy","0.7888","2065.5"]],"time":"2021-04-17T16:43:52.558818Z"}
1618677832.546012: {"type":"l2update","product_id":"BAND-BTC","changes":[["buy","0.00033428","29.62"]],"time":"2021-04-17T16:43:52.558887Z"}
1618677832.546039: {"type":"l2update","product_id":"BAND-BTC","changes":[["buy","0.00033426","0.00"]],"time":"2021-04-17T16:43:52.559825Z"}
1618677832.547147: {"type":"l2update","product_id":"SKL-USD","changes":[["buy","0.7896","0.0"]],"time":"2021-04-17T16:43:52.561799Z"}
1618677832.547203: {"type":"l2update","product_id":"DASH-BTC","changes":[["sell","0.00619608","1.62300000"]],"time":"2021-04-17T16:43:52.562167Z"}
1618677832.54955: {"type":"l2update","product_id":"SKL-BTC","changes":[["buy","0.00001299","9938.0"]],"time":"2021-04-17T16:43:52.563994Z"}
1618677832.558489: {"type":"l2update","product_id":"DASH-BTC","changes":[["sell","0.00619971","0.00000000"]],"time":"2021-04-17T16:43:52.569931Z"}
1618677832.55859: {"type":"l2update","product_id":"SKL-BTC","changes":[["buy","0.00001297","0.0"]],"time":"2021-04-17T16:43:52.570260Z"}
1618677832.558635: {"type":"l2update","product_id":"DASH-BTC","changes":[["sell","0.00619608","3.85900000"]],"time":"2021-04-17T16:43:52.573141Z"}
1618677832.564706: {"type":"l2update","product_id":"DASH-BTC","changes":[["sell","0.00619610","0.00000000"]],"time":"2021-04-17T16:43:52.576664Z"}
1618677832.583856: {"type":"l2update","product_id":"CRV-EUR","changes":[["buy","3.2938","681.96"]],"time":"2021-04-17T16:43:52.583825Z"}
1618677832.583974: {"type":"l2update","product_id":"SKL-USD","changes":[["buy","0.7901","0.0"]],"time":"2021-04-17T16:43:52.585562Z"}
1618677832.584051: {"type":"l2update","product_id":"CRV-EUR","changes":[["sell","3.3044","140.93"]],"time":"2021-04-17T16:43:52.584090Z"}
1618677832.58411: {"type":"l2update","product_id":"CRV-EUR","changes":[["buy","3.2938","822.89"]],"time":"2021-04-17T16:43:52.587652Z"}
1618677832.584147: {"type":"l2update","product_id":"DASH-BTC","changes":[["sell","0.00619797","1.62300000"]],"time":"2021-04-17T16:43:52.587663Z"}
1618677832.5973198: {"type":"l2update","product_id":"SKL-USD","changes":[["buy","0.7901","2631.4"]],"time":"2021-04-17T16:43:52.606258Z"}
1618677832.597418: {"type":"l2update","product_id":"SKL-USD","changes":[["buy","0.7888","2933.8"]],"time":"2021-04-17T16:43:52.606617Z"}
1618677832.601789: {"type":"l2update","product_id":"DASH-BTC","changes":[["buy","0.00617737","0.00000000"]],"time":"2021-04-17T16:43:52.617024Z"}
1618677832.607101: {"type":"l2update","product_id":"DASH-BTC","changes":[["sell","0.00618988","2.57600000"]],"time":"2021-04-17T16:43:52.621623Z"}
1618677832.607171: {"type":"l2update","product_id":"SKL-USD","changes":[["buy","0.7843","8456.3"]],"time":"2021-04-17T16:43:52.621670Z"}
1618677832.607219: {"type":"l2update","product_id":"CRV-EUR","changes":[["buy","3.2938","681.96"]],"time":"2021-04-17T16:43:52.623689Z"}
1618677832.612366: {"type":"l2update","product_id":"NMR-EUR","changes":[["buy","66.9126","1.322"]],"time":"2021-04-17T16:43:52.624276Z"}
1618677832.612417: {"type":"l2update","product_id":"NMR-EUR","changes":[["buy","66.9126","0.000"]],"time":"2021-04-17T16:43:52.624427Z"}
1618677832.612458: {"type":"l2update","product_id":"CRV-EUR","changes":[["buy","3.2938","541.03"]],"time":"2021-04-17T16:43:52.624663Z"}
1618677832.612484: {"type":"l2update","product_id":"DASH-BTC","changes":[["sell","0.00623662","0.01000000"]],"time":"2021-04-17T16:43:52.627359Z"}
1618677832.612509: {"type":"l2update","product_id":"DASH-BTC","changes":[["sell","0.00630284","0.00000000"]],"time":"2021-04-17T16:43:52.627359Z"}
1618677832.612544: {"type":"l2update","product_id":"DASH-BTC","changes":[["buy","0.00616178","4.27800000"]],"time":"2021-04-17T16:43:52.627359Z"}
1618677832.612569: {"type":"l2update","product_id":"DASH-BTC","changes":[["buy","0.00615249","8.56500000"]],"time":"2021-04-17T16:43:52.627359Z"}
1618677832.61259: {"type":"l2update","product_id":"DASH-BTC","changes":[["buy","0.00614322","0.01000000"]],"time":"2021-04-17T16:43:52.627359Z"}
1618677832.612611: {"type":"l2update","product_id":"DASH-BTC","changes":[["buy","0.00613395","0.01000000"]],"time":"2021-04-17T16:43:52.627359Z"}
1618677832.614892: {"type":"l2update","product_id":"SKL-GBP","changes":[["buy","0.5705","1315.0"]],"time":"2021-04-17T16:43:52.628974Z"}
1618677832.623151: {"type":"l2update","product_id":"YFI-BTC","changes":[["buy","0.82570","0.000000"]],"time":"2021-04-17T16:43:52.637307Z"}
1618677832.6232152: {"type":"l2update","product_id":"CRV-EUR","changes":[["sell","3.3044","0.00"]],"time":"2021-04-17T16:43:52.640540Z"}
1618677832.625299: {"type":"l2update","product_id":"DASH-BTC","changes":[["sell","0.00618544","2.50900000"]],"time":"2021-04-17T16:43:52.641085Z"}
1618677832.629078: {"type":"l2update","product_id":"DASH-BTC","changes":[["buy","0.00616178","11.33000000"]],"time":"2021-04-17T16:43:52.641716Z"}
1618677832.62913: {"type":"l2update","product_id":"DASH-BTC","changes":[["buy","0.00615249","13.59600000"]],"time":"2021-04-17T16:43:52.641716Z"}
1618677832.629161: {"type":"l2update","product_id":"DASH-BTC","changes":[["buy","0.00614322","16.31500000"]],"time":"2021-04-17T16:43:52.641716Z"}
1618677832.629191: {"type":"l2update","product_id":"DASH-BTC","changes":[["buy","0.00613395","19.57800000"]],"time":"2021-04-17T16:43:52.641716Z"}
1618677832.629215: {"type":"l2update","product_id":"DASH-BTC","changes":[["buy","0.00612470","23.49400000"]],"time":"2021-04-17T16:43:52.641716Z"}
1618677832.629237: {"type":"l2update","product_id":"DASH-BTC","changes":[["buy","0.00606036","0.01000000"]],"time":"2021-04-17T16:43:52.641716Z"}
1618677832.629268: {"type":"l2update","product_id":"DASH-BTC","changes":[["sell","0.00620845","1.06000000"]],"time":"2021-04-17T16:43:52.641716Z"}
1618677832.6345322: {"type":"l2update","product_id":"BAND-BTC","changes":[["buy","0.00033428","0.00"]],"time":"2021-04-17T16:43:52.645323Z"}
1618677832.634602: {"type":"l2update","product_id":"NMR-EUR","changes":[["buy","66.9129","1.322"]],"time":"2021-04-17T16:43:52.647899Z"}
1618677832.634646: {"type":"l2update","product_id":"CRV-EUR","changes":[["buy","3.2967","140.93"]],"time":"2021-04-17T16:43:52.648241Z"}
1618677832.634679: {"type":"l2update","product_id":"DASH-BTC","changes":[["buy","0.00618073","0.00000000"]],"time":"2021-04-17T16:43:52.648275Z"}
1618677832.6347132: {"type":"l2update","product_id":"YFI-BTC","changes":[["buy","0.82586","0.000000"]],"time":"2021-04-17T16:43:52.649333Z"}
1618677832.634743: {"type":"l2update","product_id":"CRV-EUR","changes":[["sell","3.3112","0.00"]],"time":"2021-04-17T16:43:52.650211Z"}
1618677832.6461859: {"type":"l2update","product_id":"BAND-BTC","changes":[["buy","0.00033345","148.30"]],"time":"2021-04-17T16:43:52.652243Z"}
1618677832.646247: {"type":"l2update","product_id":"NMR-EUR","changes":[["buy","66.9129","2.644"]],"time":"2021-04-17T16:43:52.652280Z"}
1618677832.6462789: {"type":"l2update","product_id":"CRV-EUR","changes":[["buy","3.2967","281.86"]],"time":"2021-04-17T16:43:52.652255Z"}
1618677832.65262: {"type":"l2update","product_id":"DASH-BTC","changes":[["buy","0.00617507","5.56900000"]],"time":"2021-04-17T16:43:52.658789Z"}
1618677832.660461: {"type":"l2update","product_id":"NMR-EUR","changes":[["buy","66.9128","0.000"]],"time":"2021-04-17T16:43:52.662482Z"}
1618677832.66056: {"type":"l2update","product_id":"SKL-BTC","changes":[["buy","0.00001300","4221.5"]],"time":"2021-04-17T16:43:52.667580Z"}
1618677832.660615: {"type":"l2update","product_id":"NMR-EUR","changes":[["buy","66.9131","4.775"]],"time":"2021-04-17T16:43:52.670575Z"}
1618677832.6606662: {"type":"l2update","product_id":"CRV-EUR","changes":[["sell","3.3199","1416.00"]],"time":"2021-04-17T16:43:52.670710Z"}
1618677832.6616929: {"type":"l2update","product_id":"DASH-BTC","changes":[["buy","0.00617815","1.39200000"]],"time":"2021-04-17T16:43:52.673980Z"}
1618677832.6660109: {"type":"l2update","product_id":"CRV-EUR","changes":[["buy","3.2970","0.00"]],"time":"2021-04-17T16:43:52.676603Z"}
1618677832.6679978: {"type":"l2update","product_id":"CRV-EUR","changes":[["sell","3.3073","140.93"]],"time":"2021-04-17T16:43:52.678075Z"}
1618677832.670014: {"type":"l2update","product_id":"CRV-EUR","changes":[["buy","3.2967","140.93"]],"time":"2021-04-17T16:43:52.683660Z"}
1618677832.673588: {"type":"l2update","product_id":"DASH-BTC","changes":[["sell","0.00618989","0.00000000"]],"time":"2021-04-17T16:43:52.684907Z"}
1618677832.6736908: {"type":"l2update","product_id":"DASH-BTC","changes":[["buy","0.00617589","10.76000000"]],"time":"2021-04-17T16:43:52.685862Z"}
1618677832.6737401: {"type":"l2update","product_id":"YFI-BTC","changes":[["buy","0.82570","0.017057"]],"time":"2021-04-17T16:43:52.685950Z"}
1618677832.677685: {"type":"l2update","product_id":"DASH-BTC","changes":[["sell","0.00620477","0.00000000"]],"time":"2021-04-17T16:43:52.691273Z"}
1618677832.67778: {"type":"l2update","product_id":"DASH-BTC","changes":[["sell","0.00619609","1.00000000"]],"time":"2021-04-17T16:43:52.691973Z"}
1618677832.685663: {"type":"l2update","product_id":"DASH-BTC","changes":[["buy","0.00617613","32.84700000"]],"time":"2021-04-17T16:43:52.700422Z"}
1618677832.68573: {"type":"l2update","product_id":"DASH-BTC","changes":[["sell","0.00618179","2.50900000"]],"time":"2021-04-17T16:43:52.701277Z"}
1618677832.689141: {"type":"l2update","product_id":"DASH-BTC","changes":[["sell","0.00618668","0.00000000"]],"time":"2021-04-17T16:43:52.705967Z"}
1618677832.6933389: {"type":"l2update","product_id":"CRV-EUR","changes":[["buy","3.2967","0.00"]],"time":"2021-04-17T16:43:52.709149Z"}
1618677832.698844: {"type":"l2update","product_id":"DASH-BTC","changes":[["sell","0.00618543","0.82500000"]],"time":"2021-04-17T16:43:52.712885Z"}
1618677832.70211: {"type":"l2update","product_id":"DASH-BTC","changes":[["sell","0.00619607","10.34100000"]],"time":"2021-04-17T16:43:52.715280Z"}
1618677832.7021708: {"type":"l2update","product_id":"SKL-BTC","changes":[["buy","0.00001302","6934.0"]],"time":"2021-04-17T16:43:52.718108Z"}
1618677832.725327: {"type":"l2update","product_id":"CRV-EUR","changes":[["buy","3.2940","140.93"]],"time":"2021-04-17T16:43:52.734016Z"}
1618677832.7317: {"type":"l2update","product_id":"CRV-EUR","changes":[["buy","3.2968","120.00"]],"time":"2021-04-17T16:43:52.745088Z"}
1618677832.7318022: {"type":"l2update","product_id":"DASH-BTC","changes":[["buy","0.00618074","0.29500000"]],"time":"2021-04-17T16:43:52.747806Z"}
1618677832.7862332: {"type":"l2update","product_id":"CRV-EUR","changes":[["buy","3.2940","281.86"]],"time":"2021-04-17T16:43:52.752787Z"}
1618677832.786303: {"type":"l2update","product_id":"DASH-BTC","changes":[["sell","0.00619798","0.00000000"]],"time":"2021-04-17T16:43:52.754810Z"}
1618677832.786345: {"type":"l2update","product_id":"CRV-EUR","changes":[["sell","3.3073","0.00"]],"time":"2021-04-17T16:43:52.760577Z"}
1618677832.7863748: {"type":"l2update","product_id":"YFI-BTC","changes":[["buy","0.82549","0.030355"]],"time":"2021-04-17T16:43:52.763726Z"}
1618677832.7864041: {"type":"l2update","product_id":"DASH-BTC","changes":[["buy","0.00616719","1.54800000"]],"time":"2021-04-17T16:43:52.768624Z"}
1618677832.786428: {"type":"l2update","product_id":"CRV-EUR","changes":[["sell","3.3046","140.93"]],"time":"2021-04-17T16:43:52.768797Z"}
1618677832.786449: {"type":"l2update","product_id":"CRV-EUR","changes":[["buy","3.2940","140.93"]],"time":"2021-04-17T16:43:52.779219Z"}
1618677832.7864661: {"type":"l2update","product_id":"NMR-EUR","changes":[["buy","66.9129","1.322"]],"time":"2021-04-17T16:43:52.779683Z"}
1618677832.786484: {"type":"l2update","product_id":"CRV-EUR","changes":[["buy","3.2940","0.00"]],"time":"2021-04-17T16:43:52.779845Z"}
1618677832.786506: {"type":"l2update","product_id":"DASH-BTC","changes":[["buy","0.00617613","0.00000000"]],"time":"2021-04-17T16:43:52.779898Z"}
1618677832.786528: {"type":"l2update","product_id":"NMR-EUR","changes":[["buy","66.9129","0.000"]],"time":"2021-04-17T16:43:52.780103Z"}
1618677832.78655: {"type":"l2update","product_id":"CRV-EUR","changes":[["sell","3.3010","5000.00"]],"time":"2021-04-17T16:43:52.794871Z"}
1618677832.7885811: {"type":"l2update","product_id":"BAND-BTC","changes":[["buy","0.00033412","151.87"]],"time":"2021-04-17T16:43:52.797919Z"}
1618677832.788634: {"type":"l2update","product_id":"YFI-BTC","changes":[["sell","0.83213","0.017040"]],"time":"2021-04-17T16:43:52.802569Z"}
1618677832.788662: {"type":"l2update","product_id":"BAND-BTC","changes":[["buy","0.00033345","0.00"]],"time":"2021-04-17T16:43:52.802549Z"}
1618677832.791992: {"type":"l2update","product_id":"YFI-BTC","changes":[["buy","0.82315","0.000000"]],"time":"2021-04-17T16:43:52.802569Z"}
1618677832.7966468: {"type":"l2update","product_id":"BAND-GBP","changes":[["sell","14.7892","0.00"]],"time":"2021-04-17T16:43:52.809429Z"}
1618677832.796698: {"type":"l2update","product_id":"CRV-EUR","changes":[["buy","3.2830","1129.25"]],"time":"2021-04-17T16:43:52.809934Z"}
1618677832.796732: {"type":"l2update","product_id":"YFI-BTC","changes":[["sell","0.83210","0.005190"]],"time":"2021-04-17T16:43:52.810134Z"}
1618677832.7967591: {"type":"l2update","product_id":"YFI-BTC","changes":[["buy","0.82064","0.004380"]],"time":"2021-04-17T16:43:52.810134Z"}
1618677832.801673: {"type":"l2update","product_id":"BAND-BTC","changes":[["buy","0.00033345","148.30"]],"time":"2021-04-17T16:43:52.812594Z"}
1618677832.801724: {"type":"l2update","product_id":"CRV-EUR","changes":[["buy","3.2894","1150.38"]],"time":"2021-04-17T16:43:52.812722Z"}
1618677832.811187: {"type":"l2update","product_id":"CRV-EUR","changes":[["sell","3.3046","0.00"]],"time":"2021-04-17T16:43:52.824789Z"}
1618677832.8165178: {"type":"l2update","product_id":"NMR-EUR","changes":[["buy","66.9132","1.322"]],"time":"2021-04-17T16:43:52.831312Z"}
1618677832.820828: {"type":"l2update","product_id":"NMR-EUR","changes":[["buy","66.9132","2.644"]],"time":"2021-04-17T16:43:52.835480Z"}
1618677832.820875: {"type":"l2update","product_id":"CRV-EUR","changes":[["buy","3.2967","140.93"]],"time":"2021-04-17T16:43:52.835618Z"}
1618677832.8284001: {"type":"l2update","product_id":"DASH-BTC","changes":[["buy","0.00618074","0.00000000"]],"time":"2021-04-17T16:43:52.842202Z"}
1618677832.832534: {"type":"l2update","product_id":"DASH-BTC","changes":[["sell","0.00618544","0.00000000"]],"time":"2021-04-17T16:43:52.844694Z"}
1618677832.832582: {"type":"l2update","product_id":"DASH-BTC","changes":[["sell","0.00619811","14.63200000"]],"time":"2021-04-17T16:43:52.846656Z"}
1618677832.8334851: {"type":"l2update","product_id":"SKL-BTC","changes":[["buy","0.00001298","9652.3"]],"time":"2021-04-17T16:43:52.846797Z"}
1618677832.8335328: {"type":"l2update","product_id":"SKL-USD","changes":[["sell","0.7951","5.0"]],"time":"2021-04-17T16:43:52.848833Z"}
1618677832.8367202: {"type":"l2update","product_id":"DASH-BTC","changes":[["buy","0.00617507","0.00000000"]],"time":"2021-04-17T16:43:52.851247Z"}
1618677832.8367739: {"type":"l2update","product_id":"SKL-USD","changes":[["buy","0.7866","0.0"]],"time":"2021-04-17T16:43:52.851939Z"}
1618677832.837444: {"type":"l2update","product_id":"SKL-BTC","changes":[["buy","0.00001300","5539.5"]],"time":"2021-04-17T16:43:52.853825Z"}
1618677832.8538089: {"type":"l2update","product_id":"CRV-EUR","changes":[["buy","3.2967","281.86"]],"time":"2021-04-17T16:43:52.862235Z"}
1618677832.853847: {"type":"l2update","product_id":"DASH-BTC","changes":[["buy","0.00616719","1.84400000"]],"time":"2021-04-17T16:43:52.864797Z"}
1618677832.857034: {"type":"l2update","product_id":"DASH-BTC","changes":[["buy","0.00617310","32.84700000"]],"time":"2021-04-17T16:43:52.868588Z"}
1618677832.872555: {"type":"l2update","product_id":"CRV-EUR","changes":[["sell","3.3073","140.93"]],"time":"2021-04-17T16:43:52.879658Z"}
1618677832.8900092: {"type":"l2update","product_id":"CRV-EUR","changes":[["sell","3.3018","0.00"]],"time":"2021-04-17T16:43:52.897780Z"}
1618677832.890143: {"type":"l2update","product_id":"CRV-EUR","changes":[["buy","3.2967","140.93"]],"time":"2021-04-17T16:43:52.898872Z"}
1618677832.8958578: {"type":"l2update","product_id":"BAND-BTC","changes":[["sell","0.00033498","0.00"]],"time":"2021-04-17T16:43:52.906029Z"}
1618677832.895929: {"type":"l2update","product_id":"DASH-BTC","changes":[["sell","0.00619608","2.23600000"]],"time":"2021-04-17T16:43:52.909068Z"}
1618677832.9046028: {"type":"l2update","product_id":"DASH-BTC","changes":[["sell","0.00619608","0.00000000"]],"time":"2021-04-17T16:43:52.918724Z"}
1618677832.9107368: {"type":"l2update","product_id":"DASH-BTC","changes":[["sell","0.00619811","0.00000000"]],"time":"2021-04-17T16:43:52.926867Z"}
1618677832.918093: {"type":"l2update","product_id":"YFI-BTC","changes":[["buy","0.82549","0.000000"]],"time":"2021-04-17T16:43:52.930490Z"}
1618677832.9265862: {"type":"l2update","product_id":"DASH-BTC","changes":[["sell","0.00618179","0.00000000"]],"time":"2021-04-17T16:43:52.936268Z"}
1618677832.926666: {"type":"l2update","product_id":"CRV-EUR","changes":[["buy","3.2967","0.00"]],"time":"2021-04-17T16:43:52.936741Z"}
1618677832.9394429: {"type":"l2update","product_id":"DASH-BTC","changes":[["sell","0.00619607","0.00000000"]],"time":"2021-04-17T16:43:52.945962Z"}
1618677832.9395058: {"type":"l2update","product_id":"BAND-BTC","changes":[["sell","0.00033514","36.74"]],"time":"2021-04-17T16:43:52.952220Z"}
1618677832.9395552: {"type":"l2update","product_id":"DASH-BTC","changes":[["sell","0.00619606","1.62300000"]],"time":"2021-04-17T16:43:52.952514Z"}
1618677832.9525702: {"type":"l2update","product_id":"DASH-BTC","changes":[["sell","0.00619606","3.85900000"]],"time":"2021-04-17T16:43:52.967065Z"}
1618677832.952626: {"type":"l2update","product_id":"CRV-EUR","changes":[["sell","3.3073","0.00"]],"time":"2021-04-17T16:43:52.968041Z"}
1618677832.9526699: {"type":"l2update","product_id":"SKL-USD","changes":[["sell","0.7917","6908.0"]],"time":"2021-04-17T16:43:52.968097Z"}
1618677832.955809: {"type":"l2update","product_id":"BAND-GBP","changes":[["buy","14.7661","12.57"]],"time":"2021-04-17T16:43:52.971355Z"}
1618677832.9634318: {"type":"l2update","product_id":"SKL-USD","changes":[["sell","0.7943","5.0"]],"time":"2021-04-17T16:43:52.976709Z"}
1618677832.967648: {"type":"l2update","product_id":"SKL-USD","changes":[["sell","0.7948","5.0"]],"time":"2021-04-17T16:43:52.982240Z"}
1618677832.970877: {"type":"l2update","product_id":"SKL-BTC","changes":[["sell","0.00001306","0.0"]],"time":"2021-04-17T16:43:52.985280Z"}
1618677832.990186: {"type":"l2update","product_id":"BAND-GBP","changes":[["sell","14.7954","0.00"]],"time":"2021-04-17T16:43:52.998588Z"}
1618677832.990253: {"type":"l2update","product_id":"SKL-BTC","changes":[["buy","0.00001303","2144.3"]],"time":"2021-04-17T16:43:52.998985Z"}
1618677832.99029: {"type":"l2update","product_id":"SKL-GBP","changes":[["buy","0.5719","0.0"]],"time":"2021-04-17T16:43:52.999180Z"}
1618677832.990326: {"type":"l2update","product_id":"SKL-USD","changes":[["sell","0.7930","29765.1"]],"time":"2021-04-17T16:43:53.001925Z"}
1618677832.9955552: {"type":"l2update","product_id":"DASH-BTC","changes":[["sell","0.00619650","14.63200000"]],"time":"2021-04-17T16:43:53.009315Z"}
1618677833.0149498: {"type":"l2update","product_id":"SKL-BTC","changes":[["buy","0.00001302","6271.5"]],"time":"2021-04-17T16:43:53.011726Z"}
1618677833.015006: {"type":"l2update","product_id":"SKL-USD","changes":[["sell","0.7920","2631.1"]],"time":"2021-04-17T16:43:53.013133Z"}
1618677833.015052: {"type":"l2update","product_id":"SKL-GBP","changes":[["sell","0.5775","2525.9"]],"time":"2021-04-17T16:43:53.013233Z"}
1618677833.0150862: {"type":"l2update","product_id":"SKL-USD","changes":[["buy","0.7903","0.0"]],"time":"2021-04-17T16:43:53.014027Z"}
1618677833.0151198: {"type":"l2update","product_id":"SKL-BTC","changes":[["buy","0.00001301","10136.2"]],"time":"2021-04-17T16:43:53.015277Z"}
1618677833.015145: {"type":"l2update","product_id":"SKL-BTC","changes":[["buy","0.00001301","9470.0"]],"time":"2021-04-17T16:43:53.017857Z"}
1618677833.015167: {"type":"l2update","product_id":"SKL-BTC","changes":[["buy","0.00001302","5289.9"]],"time":"2021-04-17T16:43:53.017913Z"}
1618677833.015188: {"type":"l2update","product_id":"SKL-BTC","changes":[["sell","0.00001309","2462.6"]],"time":"2021-04-17T16:43:53.017913Z"}
1618677833.015209: {"type":"l2update","product_id":"SKL-USD","changes":[["buy","0.7879","1900.0"]],"time":"2021-04-17T16:43:53.021503Z"}
1618677833.01523: {"type":"l2update","product_id":"CRV-EUR","changes":[["buy","3.2942","140.93"]],"time":"2021-04-17T16:43:53.022695Z"}
1618677833.015255: {"type":"l2update","product_id":"SKL-GBP","changes":[["sell","0.5781","6314.7"]],"time":"2021-04-17T16:43:53.025895Z"}
1618677833.018333: {"type":"l2update","product_id":"SKL-BTC","changes":[["buy","0.00001300","6521.1"]],"time":"2021-04-17T16:43:53.028743Z"}
1618677833.018393: {"type":"l2update","product_id":"SKL-BTC","changes":[["sell","0.00001307","5031.3"]],"time":"2021-04-17T16:43:53.028743Z"}
1618677833.0226712: {"type":"l2update","product_id":"SKL-BTC","changes":[["sell","0.00001307","5925.4"]],"time":"2021-04-17T16:43:53.036125Z"}
1618677833.022728: {"type":"l2update","product_id":"CRV-EUR","changes":[["buy","3.2942","281.86"]],"time":"2021-04-17T16:43:53.036311Z"}
1618677833.026827: {"type":"l2update","product_id":"SKL-BTC","changes":[["buy","0.00001303","2806.3"]],"time":"2021-04-17T16:43:53.040195Z"}
1618677833.034388: {"type":"l2update","product_id":"SKL-USD","changes":[["buy","0.7905","1044.5"]],"time":"2021-04-17T16:43:53.043559Z"}
1618677833.034453: {"type":"l2update","product_id":"SKL-BTC","changes":[["sell","0.00001307","7034.5"]],"time":"2021-04-17T16:43:53.043648Z"}
1618677833.041791: {"type":"l2update","product_id":"SKL-USD","changes":[["buy","0.7904","450.0"]],"time":"2021-04-17T16:43:53.050506Z"}
1618677833.045054: {"type":"l2update","product_id":"CRV-EUR","changes":[["sell","3.3048","140.93"]],"time":"2021-04-17T16:43:53.056980Z"}
1618677833.045124: {"type":"l2update","product_id":"DASH-BTC","changes":[["sell","0.00619461","2.65600000"]],"time":"2021-04-17T16:43:53.057135Z"}
1618677833.045165: {"type":"l2update","product_id":"SKL-BTC","changes":[["buy","0.00001302","6206.7"]],"time":"2021-04-17T16:43:53.057159Z"}
1618677833.045195: {"type":"l2update","product_id":"SKL-USD","changes":[["buy","0.7905","1494.5"]],"time":"2021-04-17T16:43:53.057532Z"}
1618677833.050352: {"type":"l2update","product_id":"BAND-BTC","changes":[["buy","0.00033412","25.74"]],"time":"2021-04-17T16:43:53.062877Z"}
1618677833.050407: {"type":"l2update","product_id":"SKL-BTC","changes":[["sell","0.00001307","3894.0"]],"time":"2021-04-17T16:43:53.065437Z"}
1618677833.055605: {"type":"l2update","product_id":"SKL-BTC","changes":[["buy","0.00001302","6872.4"]],"time":"2021-04-17T16:43:53.066854Z"}
1618677833.064214: {"type":"l2update","product_id":"SKL-USD","changes":[["sell","0.7936","5.0"]],"time":"2021-04-17T16:43:53.079968Z"}
1618677833.0642612: {"type":"l2update","product_id":"DASH-BTC","changes":[["sell","0.00618543","0.00000000"]],"time":"2021-04-17T16:43:53.081480Z"}
1618677833.077062: {"type":"l2update","product_id":"SKL-USD","changes":[["sell","0.7931","3961.7"]],"time":"2021-04-17T16:43:53.084711Z"}
1618677833.077108: {"type":"l2update","product_id":"BAND-BTC","changes":[["buy","0.00033412","88.81"]],"time":"2021-04-17T16:43:53.086108Z"}
1618677833.0887198: {"type":"l2update","product_id":"SKL-USD","changes":[["sell","0.7929","2530.9"]],"time":"2021-04-17T16:43:53.104499Z"}
1618677833.0962062: {"type":"l2update","product_id":"SKL-USD","changes":[["buy","0.7898","2525.6"]],"time":"2021-04-17T16:43:53.112043Z"}
1618677833.096257: {"type":"l2update","product_id":"SKL-USD","changes":[["sell","0.7930","5.0"]],"time":"2021-04-17T16:43:53.113022Z"}
1618677833.105899: {"type":"l2update","product_id":"SKL-USD","changes":[["sell","0.7939","6312.8"]],"time":"2021-04-17T16:43:53.119689Z"}
1618677833.11112: {"type":"l2update","product_id":"DASH-BTC","changes":[["sell","0.00619650","0.00000000"]],"time":"2021-04-17T16:43:53.127899Z"}
1618677833.114516: {"type":"l2update","product_id":"SKL-USD","changes":[["sell","0.7944","29765.1"]],"time":"2021-04-17T16:43:53.130129Z"}
1618677833.119675: {"type":"l2update","product_id":"SKL-USD","changes":[["buy","0.7904","0.0"]],"time":"2021-04-17T16:43:53.134445Z"}
1618677833.129334: {"type":"l2update","product_id":"BAND-BTC","changes":[["buy","0.00033428","29.62"]],"time":"2021-04-17T16:43:53.138168Z"}
1618677833.129385: {"type":"l2update","product_id":"DASH-BTC","changes":[["sell","0.00618987","0.82500000"]],"time":"2021-04-17T16:43:53.139054Z"}
1618677833.129418: {"type":"l2update","product_id":"SKL-USD","changes":[["sell","0.8084","5.0"]],"time":"2021-04-17T16:43:53.139937Z"}
1618677833.12944: {"type":"l2update","product_id":"SKL-USD","changes":[["sell","0.8079","5.0"]],"time":"2021-04-17T16:43:53.139937Z"}
1618677833.129459: {"type":"l2update","product_id":"SKL-USD","changes":[["buy","0.7888","2065.5"]],"time":"2021-04-17T16:43:53.142580Z"}
1618677833.131219: {"type":"l2update","product_id":"SKL-USD","changes":[["sell","0.8082","825.0"]],"time":"2021-04-17T16:43:53.145268Z"}
1618677833.131262: {"type":"l2update","product_id":"SKL-USD","changes":[["sell","0.8081","35.0"]],"time":"2021-04-17T16:43:53.145268Z"}
1618677833.134906: {"type":"l2update","product_id":"BAND-BTC","changes":[["buy","0.00033379","24.00"]],"time":"2021-04-17T16:43:53.149257Z"}
1618677833.1380968: {"type":"l2update","product_id":"SKL-BTC","changes":[["buy","0.00001301","10129.2"]],"time":"2021-04-17T16:43:53.154071Z"}
1618677833.147394: {"type":"l2update","product_id":"SKL-USD","changes":[["buy","0.7901","3498.3"]],"time":"2021-04-17T16:43:53.163299Z"}
1618677833.1474402: {"type":"l2update","product_id":"DASH-BTC","changes":[["buy","0.00617225","5.57100000"]],"time":"2021-04-17T16:43:53.163594Z"}
1618677833.153017: {"type":"l2update","product_id":"CRV-EUR","changes":[["sell","3.3048","0.00"]],"time":"2021-04-17T16:43:53.165711Z"}
1618677833.1530712: {"type":"l2update","product_id":"CRV-EUR","changes":[["buy","3.2942","140.93"]],"time":"2021-04-17T16:43:53.166418Z"}
1618677833.153097: {"type":"l2update","product_id":"SKL-USD","changes":[["sell","0.7918","23012.0"]],"time":"2021-04-17T16:43:53.166504Z"}
1618677833.157225: {"type":"l2update","product_id":"CRV-EUR","changes":[["buy","3.2942","0.00"]],"time":"2021-04-17T16:43:53.167627Z"}
1618677833.1619: {"type":"l2update","product_id":"DASH-BTC","changes":[["buy","0.00616719","0.29600000"]],"time":"2021-04-17T16:43:53.177672Z"}
1618677833.1640892: {"type":"l2update","product_id":"SKL-BTC","changes":[["buy","0.00001303","1666.4"]],"time":"2021-04-17T16:43:53.179610Z"}
1618677833.167506: {"type":"l2update","product_id":"SKL-USD","changes":[["buy","0.7883","4464.8"]],"time":"2021-04-17T16:43:53.181555Z"}
1618677833.169993: {"type":"l2update","product_id":"SKL-USD","changes":[["buy","0.7898","0.0"]],"time":"2021-04-17T16:43:53.186457Z"}
1618677833.170044: {"type":"l2update","product_id":"SKL-BTC","changes":[["buy","0.00001304","1249.0"]],"time":"2021-04-17T16:43:53.186965Z"}
1618677833.172155: {"type":"l2update","product_id":"SKL-GBP","changes":[["sell","0.5793","0.0"]],"time":"2021-04-17T16:43:53.187045Z"}
1618677833.1743731: {"type":"l2update","product_id":"SKL-USD","changes":[["sell","0.7942","1905.0"]],"time":"2021-04-17T16:43:53.189565Z"}
1618677833.17443: {"type":"l2update","product_id":"SKL-USD","changes":[["buy","0.7867","0.0"]],"time":"2021-04-17T16:43:53.190445Z"}
1618677833.174474: {"type":"l2update","product_id":"SKL-USD","changes":[["buy","0.7853","23017.0"]],"time":"2021-04-17T16:43:53.191668Z"}
1618677833.18001: {"type":"l2update","product_id":"BAND-GBP","changes":[["sell","14.7932","12.17"]],"time":"2021-04-17T16:43:53.195789Z"}
1618677833.1832619: {"type":"l2update","product_id":"SKL-BTC","changes":[["buy","0.00001302","7854.0"]],"time":"2021-04-17T16:43:53.196964Z"}
1618677833.183351: {"type":"l2update","product_id":"SKL-BTC","changes":[["sell","0.00001310","1432.8"]],"time":"2021-04-17T16:43:53.196964Z"}
1618677833.183999: {"type":"l2update","product_id":"CRV-EUR","changes":[["buy","3.2963","140.93"]],"time":"2021-04-17T16:43:53.200238Z"}
1618677833.1866372: {"type":"l2update","product_id":"SKL-USD","changes":[["sell","0.7919","1343.9"]],"time":"2021-04-17T16:43:53.200775Z"}
1618677833.188668: {"type":"l2update","product_id":"SKL-BTC","changes":[["sell","0.00001308","20203.9"]],"time":"2021-04-17T16:43:53.203900Z"}
1618677833.1887581: {"type":"l2update","product_id":"DASH-BTC","changes":[["buy","0.00617816","1.54500000"]],"time":"2021-04-17T16:43:53.203931Z"}
1618677833.189336: {"type":"l2update","product_id":"SKL-USD","changes":[["buy","0.7872","2852.5"]],"time":"2021-04-17T16:43:53.203962Z"}
1618677833.189426: {"type":"l2update","product_id":"SKL-USD","changes":[["sell","0.8074","100.4"]],"time":"2021-04-17T16:43:53.203999Z"}
1618677833.191902: {"type":"l2update","product_id":"SKL-USD","changes":[["buy","0.7901","4488.0"]],"time":"2021-04-17T16:43:53.207559Z"}
1618677833.191988: {"type":"l2update","product_id":"DASH-BTC","changes":[["buy","0.00616719","0.00000000"]],"time":"2021-04-17T16:43:53.208651Z"}
1618677833.195169: {"type":"l2update","product_id":"SKL-BTC","changes":[["buy","0.00001300","5539.5"]],"time":"2021-04-17T16:43:53.210874Z"}
1618677833.195256: {"type":"l2update","product_id":"SKL-USD","changes":[["buy","0.7862","25518.9"]],"time":"2021-04-17T16:43:53.211040Z"}
1618677833.195307: {"type":"l2update","product_id":"DASH-BTC","changes":[["sell","0.00619506","14.63200000"]],"time":"2021-04-17T16:43:53.211208Z"}
1618677833.197283: {"type":"l2update","product_id":"DASH-BTC","changes":[["buy","0.00617765","0.00000000"]],"time":"2021-04-17T16:43:53.211479Z"}
1618677833.1993752: {"type":"l2update","product_id":"SKL-BTC","changes":[["sell","0.00001307","3071.2"]],"time":"2021-04-17T16:43:53.214451Z"}
1618677833.1994612: {"type":"l2update","product_id":"DASH-BTC","changes":[["buy","0.00617764","0.00000000"]],"time":"2021-04-17T16:43:53.214675Z"}
1618677833.199529: {"type":"l2update","product_id":"SKL-BTC","changes":[["buy","0.00001304","5036.9"]],"time":"2021-04-17T16:43:53.214737Z"}
1618677833.202819: {"type":"l2update","product_id":"DASH-BTC","changes":[["sell","0.00619797","0.00000000"]],"time":"2021-04-17T16:43:53.215316Z"}
1618677833.202958: {"type":"l2update","product_id":"BAND-GBP","changes":[["buy","14.7615","0.00"]],"time":"2021-04-17T16:43:53.217417Z"}
1618677833.205033: {"type":"l2update","product_id":"SKL-BTC","changes":[["buy","0.00001299","2637.8"]],"time":"2021-04-17T16:43:53.221714Z"}
1618677833.208031: {"type":"l2update","product_id":"CRV-EUR","changes":[["sell","3.3070","140.93"]],"time":"2021-04-17T16:43:53.222215Z"}
1618677833.208689: {"type":"l2update","product_id":"CRV-EUR","changes":[["buy","3.2963","281.86"]],"time":"2021-04-17T16:43:53.222534Z"}
1618677833.21469: {"type":"l2update","product_id":"SKL-BTC","changes":[["sell","0.00001308","23966.8"]],"time":"2021-04-17T16:43:53.226281Z"}
1618677833.2147782: {"type":"l2update","product_id":"DASH-BTC","changes":[["sell","0.00620844","10.27200000"]],"time":"2021-04-17T16:43:53.229772Z"}
1618677833.214847: {"type":"l2update","product_id":"SKL-GBP","changes":[["sell","0.5770","1008.2"]],"time":"2021-04-17T16:43:53.229965Z"}
1618677833.227597: {"type":"l2update","product_id":"BAND-BTC","changes":[["buy","0.00033412","25.74"]],"time":"2021-04-17T16:43:53.240170Z"}
1618677833.227712: {"type":"l2update","product_id":"DASH-BTC","changes":[["buy","0.00617229","2.65500000"]],"time":"2021-04-17T16:43:53.240638Z"}
1618677833.227784: {"type":"l2update","product_id":"BAND-BTC","changes":[["sell","0.00033485","28.21"]],"time":"2021-04-17T16:43:53.240707Z"}
1618677833.231824: {"type":"l2update","product_id":"DASH-BTC","changes":[["buy","0.00617816","1.84000000"]],"time":"2021-04-17T16:43:53.247710Z"}
1618677833.239305: {"type":"l2update","product_id":"CRV-EUR","changes":[["buy","3.2963","140.93"]],"time":"2021-04-17T16:43:53.254946Z"}
1618677833.2512388: {"type":"l2update","product_id":"DASH-BTC","changes":[["buy","0.00617588","0.00000000"]],"time":"2021-04-17T16:43:53.258292Z"}
1618677833.2513769: {"type":"l2update","product_id":"DASH-BTC","changes":[["buy","0.00616718","0.00000000"]],"time":"2021-04-17T16:43:53.258292Z"}
1618677833.251439: {"type":"l2update","product_id":"DASH-BTC","changes":[["buy","0.00618014","0.00000000"]],"time":"2021-04-17T16:43:53.258292Z"}
1618677833.251488: {"type":"l2update","product_id":"CRV-EUR","changes":[["sell","3.3070","0.00"]],"time":"2021-04-17T16:43:53.260772Z"}
1618677833.251539: {"type":"l2update","product_id":"BAND-BTC","changes":[["buy","0.00033345","0.00"]],"time":"2021-04-17T16:43:53.262518Z"}
1618677833.254258: {"type":"l2update","product_id":"DASH-BTC","changes":[["sell","0.00620844","0.00000000"]],"time":"2021-04-17T16:43:53.268416Z"}
1618677833.255928: {"type":"l2update","product_id":"DASH-BTC","changes":[["buy","0.00617590","1.12200000"]],"time":"2021-04-17T16:43:53.269986Z"}
1618677833.2560298: {"type":"l2update","product_id":"SKL-GBP","changes":[["sell","0.5772","0.0"]],"time":"2021-04-17T16:43:53.272911Z"}
1618677833.2575328: {"type":"l2update","product_id":"DASH-BTC","changes":[["buy","0.00616179","5.72000000"]],"time":"2021-04-17T16:43:53.273076Z"}
1618677833.266195: {"type":"l2update","product_id":"DASH-BTC","changes":[["buy","0.00616179","7.60000000"]],"time":"2021-04-17T16:43:53.276456Z"}
1618677833.266311: {"type":"l2update","product_id":"CRV-EUR","changes":[["buy","3.2943","140.93"]],"time":"2021-04-17T16:43:53.276685Z"}
1618677833.266382: {"type":"l2update","product_id":"CRV-EUR","changes":[["buy","3.2963","0.00"]],"time":"2021-04-17T16:43:53.277148Z"}
1618677833.278363: {"type":"l2update","product_id":"BAND-GBP","changes":[["buy","14.7543","36.00"]],"time":"2021-04-17T16:43:53.280308Z"}
1618677833.278458: {"type":"l2update","product_id":"DASH-BTC","changes":[["buy","0.00615252","18.77000000"]],"time":"2021-04-17T16:43:53.280346Z"}
1618677833.2785: {"type":"l2update","product_id":"CRV-EUR","changes":[["sell","3.3050","140.93"]],"time":"2021-04-17T16:43:53.283636Z"}
1618677833.278535: {"type":"l2update","product_id":"SKL-USD","changes":[["sell","0.7944","5.0"]],"time":"2021-04-17T16:43:53.284463Z"}
1618677833.278561: {"type":"l2update","product_id":"BAND-GBP","changes":[["buy","14.7661","0.00"]],"time":"2021-04-17T16:43:53.288008Z"}
1618677833.280638: {"type":"l2update","product_id":"CRV-EUR","changes":[["buy","3.2943","281.86"]],"time":"2021-04-17T16:43:53.295674Z"}
1618677833.28708: {"type":"l2update","product_id":"SKL-USD","changes":[["sell","0.7938","29765.1"]],"time":"2021-04-17T16:43:53.303174Z"}
1618677833.3005598: {"type":"l2update","product_id":"DASH-BTC","changes":[["sell","0.00619812","1.62300000"]],"time":"2021-04-17T16:43:53.306910Z"}
1618677833.303894: {"type":"l2update","product_id":"DASH-BTC","changes":[["sell","0.00619606","2.23600000"]],"time":"2021-04-17T16:43:53.316106Z"}
1618677833.303982: {"type":"l2update","product_id":"CRV-EUR","changes":[["buy","3.2943","140.93"]],"time":"2021-04-17T16:43:53.318618Z"}
1618677833.304033: {"type":"l2update","product_id":"SKL-USD","changes":[["sell","0.7919","0.0"]],"time":"2021-04-17T16:43:53.318879Z"}
1618677833.309193: {"type":"l2update","product_id":"CRV-EUR","changes":[["sell","3.3050","0.00"]],"time":"2021-04-17T16:43:53.319364Z"}
1618677833.3092961: {"type":"l2update","product_id":"DASH-BTC","changes":[["sell","0.00619606","0.00000000"]],"time":"2021-04-17T16:43:53.319722Z"}
1618677833.3160682: {"type":"l2update","product_id":"DASH-BTC","changes":[["buy","0.00617497","2.70000000"]],"time":"2021-04-17T16:43:53.325074Z"}
1618677833.321763: {"type":"l2update","product_id":"SKL-USD","changes":[["buy","0.7883","1389.1"]],"time":"2021-04-17T16:43:53.334344Z"}
1618677833.32188: {"type":"l2update","product_id":"SKL-GBP","changes":[["sell","0.5770","0.0"]],"time":"2021-04-17T16:43:53.334784Z"}
1618677833.3223748: {"type":"l2update","product_id":"DASH-BTC","changes":[["buy","0.00605695","0.00000000"]],"time":"2021-04-17T16:43:53.337642Z"}
1618677833.322436: {"type":"l2update","product_id":"DASH-BTC","changes":[["sell","0.00619460","1.62300000"]],"time":"2021-04-17T16:43:53.337933Z"}
1618677833.331006: {"type":"l2update","product_id":"DASH-BTC","changes":[["buy","0.00614341","0.00000000"]],"time":"2021-04-17T16:43:53.344997Z"}
1618677833.3311439: {"type":"l2update","product_id":"DASH-BTC","changes":[["buy","0.00614342","1.91000000"]],"time":"2021-04-17T16:43:53.344997Z"}
1618677833.331201: {"type":"l2update","product_id":"SKL-USD","changes":[["sell","0.7921","5022.1"]],"time":"2021-04-17T16:43:53.344928Z"}
1618677833.331244: {"type":"l2update","product_id":"SKL-USD","changes":[["buy","0.7905","1979.5"]],"time":"2021-04-17T16:43:53.344950Z"}
1618677833.337573: {"type":"l2update","product_id":"CRV-EUR","changes":[["buy","3.2964","140.93"]],"time":"2021-04-17T16:43:53.348708Z"}
1618677833.337667: {"type":"l2update","product_id":"SKL-BTC","changes":[["sell","0.00001307","1962.1"]],"time":"2021-04-17T16:43:53.350879Z"}
1618677833.3377018: {"type":"l2update","product_id":"SKL-USD","changes":[["buy","0.7905","1529.5"]],"time":"2021-04-17T16:43:53.353051Z"}
1618677833.3432388: {"type":"l2update","product_id":"DASH-BTC","changes":[["sell","0.00619505","2.23600000"]],"time":"2021-04-17T16:43:53.358272Z"}
1618677833.3455832: {"type":"l2update","product_id":"DASH-BTC","changes":[["buy","0.00616719","2.84000000"]],"time":"2021-04-17T16:43:53.358573Z"}
1618677833.345649: {"type":"l2update","product_id":"DASH-BTC","changes":[["buy","0.00614344","0.14000000"]],"time":"2021-04-17T16:43:53.358573Z"}
1618677833.345688: {"type":"l2update","product_id":"DASH-BTC","changes":[["buy","0.00613941","0.01000000"]],"time":"2021-04-17T16:43:53.358573Z"}
1618677833.351479: {"type":"l2update","product_id":"SKL-USD","changes":[["buy","0.7906","450.0"]],"time":"2021-04-17T16:43:53.366135Z"}
1618677833.354861: {"type":"l2update","product_id":"SKL-BTC","changes":[["buy","0.00001301","17334.9"]],"time":"2021-04-17T16:43:53.370143Z"}
1618677833.360469: {"type":"l2update","product_id":"CRV-EUR","changes":[["buy","3.2943","0.00"]],"time":"2021-04-17T16:43:53.374770Z"}
1618677833.3605728: {"type":"l2update","product_id":"CRV-EUR","changes":[["buy","3.2964","0.00"]],"time":"2021-04-17T16:43:53.375544Z"}
1618677833.365298: {"type":"l2update","product_id":"SKL-BTC","changes":[["sell","0.00001308","20203.9"]],"time":"2021-04-17T16:43:53.379978Z"}
1618677833.372942: {"type":"l2update","product_id":"NMR-EUR","changes":[["buy","66.9131","0.000"]],"time":"2021-04-17T16:43:53.386925Z"}
1618677833.3743749: {"type":"l2update","product_id":"DASH-BTC","changes":[["sell","0.00618853","2.50900000"]],"time":"2021-04-17T16:43:53.389106Z"}
1618677833.3746822: {"type":"l2update","product_id":"SKL-GBP","changes":[["buy","0.5720","0.0"]],"time":"2021-04-17T16:43:53.389952Z"}
1618677833.37752: {"type":"l2update","product_id":"NMR-EUR","changes":[["buy","66.9133","4.775"]],"time":"2021-04-17T16:43:53.393235Z"}
1618677833.377619: {"type":"l2update","product_id":"SKL-USD","changes":[["buy","0.7901","3498.3"]],"time":"2021-04-17T16:43:53.393628Z"}
1618677833.383223: {"type":"l2update","product_id":"CRV-EUR","changes":[["buy","3.2933","0.00"]],"time":"2021-04-17T16:43:53.397501Z"}
1618677833.3875399: {"type":"l2update","product_id":"SKL-BTC","changes":[["buy","0.00001302","6872.4"]],"time":"2021-04-17T16:43:53.403257Z"}
1618677833.3876622: {"type":"l2update","product_id":"SKL-BTC","changes":[["sell","0.00001310","610.0"]],"time":"2021-04-17T16:43:53.403257Z"}
1618677833.3979578: {"type":"l2update","product_id":"SKL-GBP","changes":[["buy","0.5706","5788.0"]],"time":"2021-04-17T16:43:53.408968Z"}
1618677833.4078279: {"type":"l2update","product_id":"CRV-EUR","changes":[["buy","3.2944","140.93"]],"time":"2021-04-17T16:43:53.423176Z"}
1618677833.4174058: {"type":"l2update","product_id":"DASH-BTC","changes":[["buy","0.00617681","2.68500000"]],"time":"2021-04-17T16:43:53.426736Z"}
1618677833.4175448: {"type":"l2update","product_id":"CRV-EUR","changes":[["buy","3.2944","0.00"]],"time":"2021-04-17T16:43:53.432038Z"}
1618677833.4215791: {"type":"l2update","product_id":"SKL-USD","changes":[["buy","0.7906","1494.3"]],"time":"2021-04-17T16:43:53.434575Z"}
1618677833.4217: {"type":"l2update","product_id":"SKL-USD","changes":[["buy","0.7905","485.0"]],"time":"2021-04-17T16:43:53.434657Z"}
1618677833.4279091: {"type":"l2update","product_id":"CRV-EUR","changes":[["buy","3.2831","256.63"]],"time":"2021-04-17T16:43:53.441732Z"}
1618677833.430079: {"type":"l2update","product_id":"DASH-BTC","changes":[["buy","0.00616179","5.72000000"]],"time":"2021-04-17T16:43:53.442160Z"}
1618677833.443182: {"type":"l2update","product_id":"DASH-BTC","changes":[["buy","0.00616720","1.88000000"]],"time":"2021-04-17T16:43:53.457436Z"}
1618677833.443317: {"type":"l2update","product_id":"CRV-EUR","changes":[["buy","3.2964","140.93"]],"time":"2021-04-17T16:43:53.457689Z"}
1618677833.449724: {"type":"l2update","product_id":"SKL-USD","changes":[["buy","0.7901","3548.8"]],"time":"2021-04-17T16:43:53.465017Z"}
1618677833.454087: {"type":"l2update","product_id":"SKL-BTC","changes":[["buy","0.00001300","6521.1"]],"time":"2021-04-17T16:43:53.468527Z"}
1618677833.454174: {"type":"l2update","product_id":"SKL-BTC","changes":[["sell","0.00001308","21026.7"]],"time":"2021-04-17T16:43:53.468527Z"}
1618677833.4542248: {"type":"l2update","product_id":"DASH-BTC","changes":[["sell","0.00618987","0.00000000"]],"time":"2021-04-17T16:43:53.470631Z"}
1618677833.456185: {"type":"l2update","product_id":"BAND-BTC","changes":[["buy","0.00033379","0.00"]],"time":"2021-04-17T16:43:53.472039Z"}
1618677833.461586: {"type":"l2update","product_id":"CRV-EUR","changes":[["buy","3.2964","281.86"]],"time":"2021-04-17T16:43:53.476693Z"}
1618677833.461674: {"type":"l2update","product_id":"CRV-EUR","changes":[["sell","3.3071","140.93"]],"time":"2021-04-17T16:43:53.476827Z"}
1618677833.461741: {"type":"l2update","product_id":"SKL-BTC","changes":[["buy","0.00001295","875.0"]],"time":"2021-04-17T16:43:53.477191Z"}
1618677833.4617841: {"type":"l2update","product_id":"SKL-BTC","changes":[["buy","0.00001295","400.0"]],"time":"2021-04-17T16:43:53.477191Z"}
1618677833.467256: {"type":"l2update","product_id":"SKL-GBP","changes":[["buy","0.5725","0.0"]],"time":"2021-04-17T16:43:53.483457Z"}
1618677833.467391: {"type":"l2update","product_id":"SKL-GBP","changes":[["buy","0.5689","0.0"]],"time":"2021-04-17T16:43:53.483457Z"}
1618677833.467453: {"type":"l2update","product_id":"SKL-GBP","changes":[["buy","0.5724","0.0"]],"time":"2021-04-17T16:43:53.483457Z"}
1618677833.4722009: {"type":"l2update","product_id":"SKL-BTC","changes":[["buy","0.00001302","7322.4"]],"time":"2021-04-17T16:43:53.484706Z"}
1618677833.476595: {"type":"l2update","product_id":"DASH-BTC","changes":[["sell","0.00618852","0.82500000"]],"time":"2021-04-17T16:43:53.491868Z"}
1618677833.476714: {"type":"l2update","product_id":"SKL-USD","changes":[["buy","0.7855","770.0"]],"time":"2021-04-17T16:43:53.492183Z"}
1618677833.4767702: {"type":"l2update","product_id":"SKL-GBP","changes":[["buy","0.5705","1770.0"]],"time":"2021-04-17T16:43:53.492265Z"}
1618677833.4768121: {"type":"l2update","product_id":"SKL-GBP","changes":[["buy","0.5706","5853.0"]],"time":"2021-04-17T16:43:53.492265Z"}
1618677833.4768481: {"type":"l2update","product_id":"SKL-GBP","changes":[["buy","0.5738","15.0"]],"time":"2021-04-17T16:43:53.492265Z"}
1618677833.4819021: {"type":"l2update","product_id":"SKL-USD","changes":[["buy","0.7882","2935.5"]],"time":"2021-04-17T16:43:53.495751Z"}
1618677833.482653: {"type":"l2update","product_id":"SKL-USD","changes":[["buy","0.7901","2681.9"]],"time":"2021-04-17T16:43:53.498550Z"}
1618677833.482744: {"type":"l2update","product_id":"BAND-BTC","changes":[["buy","0.00033428","0.00"]],"time":"2021-04-17T16:43:53.498818Z"}
1618677833.486233: {"type":"l2update","product_id":"SKL-USD","changes":[["buy","0.7827","1239.2"]],"time":"2021-04-17T16:43:53.500644Z"}
1618677833.486321: {"type":"l2update","product_id":"CRV-EUR","changes":[["buy","3.2964","140.93"]],"time":"2021-04-17T16:43:53.502488Z"}
1618677833.4863732: {"type":"l2update","product_id":"CRV-EUR","changes":[["buy","3.2964","0.00"]],"time":"2021-04-17T16:43:53.502799Z"}
1618677833.486433: {"type":"l2update","product_id":"CRV-EUR","changes":[["sell","3.3071","0.00"]],"time":"2021-04-17T16:43:53.502813Z"}
1618677833.4864829: {"type":"l2update","product_id":"NMR-EUR","changes":[["buy","66.9132","1.322"]],"time":"2021-04-17T16:43:53.502917Z"}
1618677833.486523: {"type":"l2update","product_id":"NMR-EUR","changes":[["buy","66.9132","0.000"]],"time":"2021-04-17T16:43:53.503211Z"}
1618677833.491528: {"type":"l2update","product_id":"SKL-GBP","changes":[["buy","0.5726","0.0"]],"time":"2021-04-17T16:43:53.507172Z"}
1618677833.4973109: {"type":"l2update","product_id":"DASH-BTC","changes":[["sell","0.00619197","2.64900000"]],"time":"2021-04-17T16:43:53.509680Z"}
1618677833.505735: {"type":"l2update","product_id":"SKL-GBP","changes":[["buy","0.5707","1735.0"]],"time":"2021-04-17T16:43:53.520992Z"}
1618677833.507633: {"type":"l2update","product_id":"DASH-BTC","changes":[["buy","0.00617681","0.00000000"]],"time":"2021-04-17T16:43:53.523573Z"}
1618677833.515092: {"type":"l2update","product_id":"SKL-USD","changes":[["buy","0.7888","2933.8"]],"time":"2021-04-17T16:43:53.528894Z"}
1618677833.5151749: {"type":"l2update","product_id":"DASH-BTC","changes":[["sell","0.00619504","10.31400000"]],"time":"2021-04-17T16:43:53.528942Z"}
1618677833.521918: {"type":"l2update","product_id":"SKL-BTC","changes":[["buy","0.00001300","6487.8"]],"time":"2021-04-17T16:43:53.532760Z"}
1618677833.522035: {"type":"l2update","product_id":"SKL-BTC","changes":[["buy","0.00001300","2859.6"]],"time":"2021-04-17T16:43:53.532760Z"}
1618677833.522086: {"type":"l2update","product_id":"BAND-BTC","changes":[["sell","0.00033485","0.00"]],"time":"2021-04-17T16:43:53.533991Z"}
1618677833.522152: {"type":"l2update","product_id":"DASH-BTC","changes":[["buy","0.00617310","0.00000000"]],"time":"2021-04-17T16:43:53.535064Z"}
1618677833.5222049: {"type":"l2update","product_id":"DASH-BTC","changes":[["buy","0.00618075","0.00000000"]],"time":"2021-04-17T16:43:53.535760Z"}
1618677833.522249: {"type":"l2update","product_id":"NMR-EUR","changes":[["buy","66.9134","1.322"]],"time":"2021-04-17T16:43:53.535929Z"}
1618677833.522294: {"type":"l2update","product_id":"CRV-EUR","changes":[["buy","3.2945","140.93"]],"time":"2021-04-17T16:43:53.536037Z"}
1618677833.5223382: {"type":"l2update","product_id":"DASH-BTC","changes":[["sell","0.00619813","0.00000000"]],"time":"2021-04-17T16:43:53.536082Z"}
1618677833.524727: {"type":"l2update","product_id":"NMR-EUR","changes":[["buy","66.9134","2.644"]],"time":"2021-04-17T16:43:53.540237Z"}
1618677833.528608: {"type":"l2update","product_id":"NMR-EUR","changes":[["buy","66.9133","0.000"]],"time":"2021-04-17T16:43:53.544123Z"}
1618677833.528679: {"type":"l2update","product_id":"DASH-BTC","changes":[["buy","0.00617816","0.29500000"]],"time":"2021-04-17T16:43:53.545386Z"}
1618677833.5333278: {"type":"l2update","product_id":"NMR-EUR","changes":[["buy","66.9135","4.775"]],"time":"2021-04-17T16:43:53.547359Z"}
1618677833.541213: {"type":"l2update","product_id":"DASH-BTC","changes":[["buy","0.00617817","2.57800000"]],"time":"2021-04-17T16:43:53.555133Z"}
1618677833.541291: {"type":"l2update","product_id":"SKL-USD","changes":[["sell","0.8083","12050.5"]],"time":"2021-04-17T16:43:53.555187Z"}
1618677833.550724: {"type":"l2update","product_id":"DASH-BTC","changes":[["buy","0.00617590","2.66800000"]],"time":"2021-04-17T16:43:53.565856Z"}
1618677833.550845: {"type":"l2update","product_id":"CRV-EUR","changes":[["sell","3.3052","140.93"]],"time":"2021-04-17T16:43:53.566015Z"}
1618677833.55092: {"type":"l2update","product_id":"CRV-EUR","changes":[["buy","3.2945","281.86"]],"time":"2021-04-17T16:43:53.566302Z"}
1618677833.577278: {"type":"l2update","product_id":"DASH-BTC","changes":[["buy","0.00617225","0.00000000"]],"time":"2021-04-17T16:43:53.590293Z"}
1618677833.577419: {"type":"l2update","product_id":"DASH-BTC","changes":[["sell","0.00618986","2.63900000"]],"time":"2021-04-17T16:43:53.591572Z"}
1618677833.5778391: {"type":"l2update","product_id":"DASH-BTC","changes":[["buy","0.00607253","1.97800000"]],"time":"2021-04-17T16:43:53.595050Z"}
1618677833.5887702: {"type":"l2update","product_id":"CRV-EUR","changes":[["buy","3.2945","140.93"]],"time":"2021-04-17T16:43:53.604037Z"}
1618677833.588835: {"type":"l2update","product_id":"CRV-EUR","changes":[["buy","3.2945","0.00"]],"time":"2021-04-17T16:43:53.604155Z"}
1618677833.588882: {"type":"l2update","product_id":"CRV-EUR","changes":[["sell","3.3052","0.00"]],"time":"2021-04-17T16:43:53.604280Z"}
1618677833.588919: {"type":"l2update","product_id":"DASH-BTC","changes":[["buy","0.00617816","0.00000000"]],"time":"2021-04-17T16:43:53.604633Z"}
1618677833.5954628: {"type":"l2update","product_id":"CRV-EUR","changes":[["buy","3.2919","0.00"]],"time":"2021-04-17T16:43:53.611887Z"}
1618677833.6060941: {"type":"l2update","product_id":"DASH-BTC","changes":[["buy","0.00617147","32.84700000"]],"time":"2021-04-17T16:43:53.618059Z"}
1618677833.606234: {"type":"l2update","product_id":"SKL-USD","changes":[["sell","0.8500","172494.1"]],"time":"2021-04-17T16:43:53.621690Z"}
1618677833.6086311: {"type":"l2update","product_id":"YFI-BTC","changes":[["buy","0.82521","0.000000"]],"time":"2021-04-17T16:43:53.624682Z"}
1618677833.608771: {"type":"l2update","product_id":"CRV-EUR","changes":[["buy","3.2964","140.93"]],"time":"2021-04-17T16:43:53.625313Z"}
1618677833.610375: {"type":"l2update","product_id":"DASH-BTC","changes":[["buy","0.00617818","0.29500000"]],"time":"2021-04-17T16:43:53.625464Z"}
1618677833.6155488: {"type":"l2update","product_id":"CRV-EUR","changes":[["buy","3.2964","281.86"]],"time":"2021-04-17T16:43:53.629248Z"}
1618677833.615637: {"type":"l2update","product_id":"SKL-USD","changes":[["buy","0.7856","5.0"]],"time":"2021-04-17T16:43:53.631301Z"}
1618677833.615691: {"type":"l2update","product_id":"DASH-BTC","changes":[["sell","0.00618988","0.00000000"]],"time":"2021-04-17T16:43:53.631596Z"}
1618677833.6176572: {"type":"l2update","product_id":"YFI-BTC","changes":[["buy","0.82511","0.030000"]],"time":"2021-04-17T16:43:53.632926Z"}
1618677833.617756: {"type":"l2update","product_id":"NMR-EUR","changes":[["buy","66.4820","0.000"]],"time":"2021-04-17T16:43:53.633018Z"}
1618677833.624307: {"type":"l2update","product_id":"SKL-BTC","changes":[["buy","0.00001303","2648.0"]],"time":"2021-04-17T16:43:53.640388Z"}
1618677833.624429: {"type":"l2update","product_id":"SKL-BTC","changes":[["sell","0.00001310","1432.8"]],"time":"2021-04-17T16:43:53.640388Z"}
1618677833.6284852: {"type":"l2update","product_id":"SKL-USD","changes":[["buy","0.7879","0.0"]],"time":"2021-04-17T16:43:53.644730Z"}
1618677833.628622: {"type":"l2update","product_id":"CRV-EUR","changes":[["sell","3.3071","140.93"]],"time":"2021-04-17T16:43:53.644956Z"}
1618677833.6336331: {"type":"l2update","product_id":"SKL-USD","changes":[["buy","0.7882","0.0"]],"time":"2021-04-17T16:43:53.649323Z"}
1618677833.6475399: {"type":"l2update","product_id":"DASH-BTC","changes":[["buy","0.00614342","0.87000000"]],"time":"2021-04-17T16:43:53.661898Z"}
1618677833.6554601: {"type":"l2update","product_id":"DASH-BTC","changes":[["buy","0.00615252","19.63000000"]],"time":"2021-04-17T16:43:53.669342Z"}
1618677833.655574: {"type":"l2update","product_id":"DASH-BTC","changes":[["buy","0.00615251","0.63000000"]],"time":"2021-04-17T16:43:53.669342Z"}
1618677833.6556091: {"type":"l2update","product_id":"BAND-BTC","changes":[["buy","0.00033170","217.49"]],"time":"2021-04-17T16:43:53.669838Z"}
1618677833.6623812: {"type":"l2update","product_id":"DASH-BTC","changes":[["sell","0.00618851","2.57700000"]],"time":"2021-04-17T16:43:53.676914Z"}
1618677833.6635861: {"type":"l2update","product_id":"CRV-EUR","changes":[["buy","3.2894","1550.38"]],"time":"2021-04-17T16:43:53.680359Z"}
1618677833.6645482: {"type":"l2update","product_id":"BAND-BTC","changes":[["buy","0.00033324","148.30"]],"time":"2021-04-17T16:43:53.680632Z"}
1618677833.665795: {"type":"l2update","product_id":"BAND-BTC","changes":[["buy","0.00033170","255.98"]],"time":"2021-04-17T16:43:53.680632Z"}
1618677833.6658812: {"type":"l2update","product_id":"SKL-USD","changes":[["sell","0.8081","6035.0"]],"time":"2021-04-17T16:43:53.680768Z"}
1618677833.671198: {"type":"l2update","product_id":"SKL-USD","changes":[["sell","0.8083","6050.5"]],"time":"2021-04-17T16:43:53.685051Z"}
1618677833.675491: {"type":"l2update","product_id":"DASH-BTC","changes":[["sell","0.00619505","0.00000000"]],"time":"2021-04-17T16:43:53.689191Z"}
1618677833.67563: {"type":"l2update","product_id":"SKL-BTC","changes":[["buy","0.00001301","20243.4"]],"time":"2021-04-17T16:43:53.691352Z"}
1618677833.678335: {"type":"l2update","product_id":"SKL-BTC","changes":[["sell","0.00001308","24789.6"]],"time":"2021-04-17T16:43:53.691352Z"}
1618677833.678456: {"type":"l2update","product_id":"BAND-BTC","changes":[["sell","0.00033560","39.00"]],"time":"2021-04-17T16:43:53.692981Z"}
1618677833.678509: {"type":"l2update","product_id":"BAND-BTC","changes":[["buy","0.00033170","244.58"]],"time":"2021-04-17T16:43:53.692981Z"}
1618677833.6796238: {"type":"l2update","product_id":"SKL-USD","changes":[["sell","0.8081","12035.0"]],"time":"2021-04-17T16:43:53.695048Z"}
1618677833.679713: {"type":"l2update","product_id":"SKL-USD","changes":[["sell","0.7929","5.0"]],"time":"2021-04-17T16:43:53.695238Z"}
1618677833.68714: {"type":"l2update","product_id":"BAND-BTC","changes":[["sell","0.00033681","16.10"]],"time":"2021-04-17T16:43:53.698974Z"}
1618677833.6872268: {"type":"l2update","product_id":"BAND-BTC","changes":[["buy","0.00033170","255.98"]],"time":"2021-04-17T16:43:53.698974Z"}
1618677833.687278: {"type":"l2update","product_id":"SKL-USD","changes":[["sell","0.8083","50.5"]],"time":"2021-04-17T16:43:53.699600Z"}
1618677833.687318: {"type":"l2update","product_id":"NMR-EUR","changes":[["buy","66.7003","13.000"]],"time":"2021-04-17T16:43:53.698994Z"}
1618677833.687375: {"type":"l2update","product_id":"SKL-USD","changes":[["buy","0.7887","0.0"]],"time":"2021-04-17T16:43:53.700884Z"}
1618677833.690146: {"type":"l2update","product_id":"SKL-USD","changes":[["sell","0.7938","5.0"]],"time":"2021-04-17T16:43:53.704162Z"}
1618677833.694587: {"type":"l2update","product_id":"DASH-BTC","changes":[["sell","0.00619460","3.85900000"]],"time":"2021-04-17T16:43:53.709968Z"}
1618677833.694676: {"type":"l2update","product_id":"SKL-USD","changes":[["sell","0.8081","18035.0"]],"time":"2021-04-17T16:43:53.709995Z"}
1618677833.695334: {"type":"l2update","product_id":"BAND-GBP","changes":[["buy","14.6492","0.00"]],"time":"2021-04-17T16:43:53.711430Z"}
1618677833.6982908: {"type":"l2update","product_id":"BAND-GBP","changes":[["buy","14.6493","1.40"]],"time":"2021-04-17T16:43:53.711430Z"}
1618677833.698845: {"type":"l2update","product_id":"CRV-EUR","changes":[["buy","3.2964","140.93"]],"time":"2021-04-17T16:43:53.715258Z"}
1618677833.698921: {"type":"l2update","product_id":"NMR-EUR","changes":[["buy","66.9134","1.322"]],"time":"2021-04-17T16:43:53.715344Z"}
1618677833.69897: {"type":"l2update","product_id":"CRV-EUR","changes":[["buy","3.2964","0.00"]],"time":"2021-04-17T16:43:53.715370Z"}
1618677833.699035: {"type":"l2update","product_id":"NMR-EUR","changes":[["buy","66.9134","0.000"]],"time":"2021-04-17T16:43:53.715385Z"}
1618677833.6998432: {"type":"l2update","product_id":"NMR-EUR","changes":[["sell","71.9126","0.000"]],"time":"2021-04-17T16:43:53.715828Z"}
1618677833.699948: {"type":"l2update","product_id":"NMR-EUR","changes":[["sell","71.9125","0.000"]],"time":"2021-04-17T16:43:53.715828Z"}
1618677833.7000089: {"type":"l2update","product_id":"NMR-EUR","changes":[["buy","66.4817","0.000"]],"time":"2021-04-17T16:43:53.715828Z"}
1618677833.700062: {"type":"l2update","product_id":"NMR-EUR","changes":[["buy","66.4818","3.410"]],"time":"2021-04-17T16:43:53.715828Z"}
1618677833.7001028: {"type":"l2update","product_id":"DASH-BTC","changes":[["sell","0.00619460","2.23600000"]],"time":"2021-04-17T16:43:53.716537Z"}
1618677833.701001: {"type":"l2update","product_id":"BAND-BTC","changes":[["buy","0.00033323","49.46"]],"time":"2021-04-17T16:43:53.717166Z"}
1618677833.7068522: {"type":"l2update","product_id":"BAND-BTC","changes":[["buy","0.00033323","20.81"]],"time":"2021-04-17T16:43:53.721100Z"}
1618677833.7112892: {"type":"l2update","product_id":"SKL-USD","changes":[["sell","0.7943","29765.1"]],"time":"2021-04-17T16:43:53.724851Z"}
1618677833.711377: {"type":"l2update","product_id":"BAND-BTC","changes":[["buy","0.00033323","0.00"]],"time":"2021-04-17T16:43:53.725539Z"}
1618677833.715822: {"type":"l2update","product_id":"DASH-BTC","changes":[["sell","0.00619506","0.00000000"]],"time":"2021-04-17T16:43:53.727570Z"}
1618677833.715966: {"type":"l2update","product_id":"NMR-EUR","changes":[["buy","66.4823","18.950"]],"time":"2021-04-17T16:43:53.728581Z"}
1618677833.716036: {"type":"l2update","product_id":"NMR-EUR","changes":[["sell","72.0975","24.000"]],"time":"2021-04-17T16:43:53.728581Z"}
1618677833.716087: {"type":"l2update","product_id":"NMR-EUR","changes":[["sell","71.9761","2.190"]],"time":"2021-04-17T16:43:53.728581Z"}
1618677833.716131: {"type":"l2update","product_id":"SKL-USD","changes":[["buy","0.7888","1737.2"]],"time":"2021-04-17T16:43:53.729992Z"}
1618677833.71617: {"type":"l2update","product_id":"NMR-EUR","changes":[["buy","66.4822","2.820"]],"time":"2021-04-17T16:43:53.728581Z"}
1618677833.718307: {"type":"l2update","product_id":"SKL-USD","changes":[["buy","0.7888","868.3"]],"time":"2021-04-17T16:43:53.733248Z"}
1618677833.721427: {"type":"l2update","product_id":"DASH-BTC","changes":[["sell","0.00618985","1.62300000"]],"time":"2021-04-17T16:43:53.735599Z"}
1618677833.7240808: {"type":"l2update","product_id":"BAND-GBP","changes":[["buy","14.6497","12.40"]],"time":"2021-04-17T16:43:53.739169Z"}
1618677833.7241468: {"type":"l2update","product_id":"BAND-BTC","changes":[["buy","0.00033325","20.80"]],"time":"2021-04-17T16:43:53.739185Z"}
1618677833.724189: {"type":"l2update","product_id":"BAND-GBP","changes":[["buy","14.6496","14.20"]],"time":"2021-04-17T16:43:53.739169Z"}
1618677833.7344298: {"type":"l2update","product_id":"YFI-BTC","changes":[["buy","0.82570","0.000000"]],"time":"2021-04-17T16:43:53.744437Z"}
1618677833.734525: {"type":"l2update","product_id":"CRV-EUR","changes":[["sell","3.3071","0.00"]],"time":"2021-04-17T16:43:53.743210Z"}
1618677833.734567: {"type":"l2update","product_id":"DASH-BTC","changes":[["buy","0.00617589","0.00000000"]],"time":"2021-04-17T16:43:53.745321Z"}
1618677833.734602: {"type":"l2update","product_id":"NMR-EUR","changes":[["buy","66.9136","1.322"]],"time":"2021-04-17T16:43:53.746510Z"}
1618677833.744475: {"type":"l2update","product_id":"SKL-USD","changes":[["buy","0.7884","1197.2"]],"time":"2021-04-17T16:43:53.750295Z"}
1618677833.74461: {"type":"l2update","product_id":"SKL-USD","changes":[["buy","0.7882","1900.0"]],"time":"2021-04-17T16:43:53.750593Z"}
1618677833.74467: {"type":"l2update","product_id":"BAND-BTC","changes":[["buy","0.00033325","49.45"]],"time":"2021-04-17T16:43:53.750627Z"}
1618677833.744715: {"type":"l2update","product_id":"NMR-EUR","changes":[["buy","66.9136","2.644"]],"time":"2021-04-17T16:43:53.750645Z"}
1618677833.744755: {"type":"l2update","product_id":"CRV-EUR","changes":[["buy","3.2947","5140.93"]],"time":"2021-04-17T16:43:53.750659Z"}
1618677833.749255: {"type":"l2update","product_id":"SKL-BTC","changes":[["buy","0.00001295","390.0"]],"time":"2021-04-17T16:43:53.756558Z"}
1618677833.749342: {"type":"l2update","product_id":"SKL-BTC","changes":[["buy","0.00001295","320.0"]],"time":"2021-04-17T16:43:53.756558Z"}
1618677833.7493918: {"type":"l2update","product_id":"DASH-BTC","changes":[["buy","0.00617230","10.30200000"]],"time":"2021-04-17T16:43:53.757854Z"}
1618677833.749449: {"type":"l2update","product_id":"SKL-BTC","changes":[["buy","0.00001302","7627.4"]],"time":"2021-04-17T16:43:53.761317Z"}
1618677833.7494888: {"type":"l2update","product_id":"NMR-EUR","changes":[["buy","66.9135","0.000"]],"time":"2021-04-17T16:43:53.763621Z"}
1618677833.758234: {"type":"l2update","product_id":"BAND-BTC","changes":[["buy","0.00033325","70.25"]],"time":"2021-04-17T16:43:53.769201Z"}
1618677833.7582989: {"type":"l2update","product_id":"NMR-EUR","changes":[["buy","66.9137","4.775"]],"time":"2021-04-17T16:43:53.769233Z"}
1618677833.758344: {"type":"l2update","product_id":"SKL-USD","changes":[["buy","0.7884","2066.5"]],"time":"2021-04-17T16:43:53.769275Z"}
1618677833.758372: {"type":"l2update","product_id":"SKL-BTC","changes":[["buy","0.00001300","1878.0"]],"time":"2021-04-17T16:43:53.769586Z"}
1618677833.7583969: {"type":"l2update","product_id":"BAND-BTC","changes":[["sell","0.00033562","0.00"]],"time":"2021-04-17T16:43:53.769888Z"}
1618677833.7632241: {"type":"l2update","product_id":"SKL-BTC","changes":[["sell","0.00001308","23966.8"]],"time":"2021-04-17T16:43:53.773429Z"}
1618677833.763312: {"type":"l2update","product_id":"SKL-USD","changes":[["buy","0.7807","0.0"]],"time":"2021-04-17T16:43:53.774331Z"}
1618677833.7633832: {"type":"l2update","product_id":"SKL-USD","changes":[["buy","0.7725","0.0"]],"time":"2021-04-17T16:43:53.774331Z"}
1618677833.763432: {"type":"l2update","product_id":"CRV-EUR","changes":[["buy","3.2947","5000.00"]],"time":"2021-04-17T16:43:53.779391Z"}
1618677833.76912: {"type":"l2update","product_id":"BAND-BTC","changes":[["buy","0.00033324","0.00"]],"time":"2021-04-17T16:43:53.780431Z"}
1618677833.769187: {"type":"l2update","product_id":"BAND-BTC","changes":[["buy","0.00033170","217.49"]],"time":"2021-04-17T16:43:53.780431Z"}
1618677833.769223: {"type":"l2update","product_id":"YFI-BTC","changes":[["buy","0.81917","0.000000"]],"time":"2021-04-17T16:43:53.780644Z"}
1618677833.769259: {"type":"l2update","product_id":"DASH-BTC","changes":[["buy","0.00616687","5.57300000"]],"time":"2021-04-17T16:43:53.784078Z"}
1618677833.779361: {"type":"l2update","product_id":"SKL-USD","changes":[["buy","0.7854","8454.8"]],"time":"2021-04-17T16:43:53.784349Z"}
1618677833.779419: {"type":"l2update","product_id":"SKL-USD","changes":[["buy","0.7807","5.0"]],"time":"2021-04-17T16:43:53.784349Z"}
1618677833.7794619: {"type":"l2update","product_id":"SKL-USD","changes":[["sell","0.7951","175.8"]],"time":"2021-04-17T16:43:53.784349Z"}
1618677833.77949: {"type":"l2update","product_id":"BAND-BTC","changes":[["buy","0.00033323","148.30"]],"time":"2021-04-17T16:43:53.792464Z"}
1618677833.779522: {"type":"l2update","product_id":"YFI-BTC","changes":[["buy","0.82570","0.017059"]],"time":"2021-04-17T16:43:53.792489Z"}
1618677833.787008: {"type":"l2update","product_id":"CRV-EUR","changes":[["buy","3.2964","140.93"]],"time":"2021-04-17T16:43:53.802614Z"}
1618677833.794461: {"type":"l2update","product_id":"BAND-GBP","changes":[["buy","14.7657","12.46"]],"time":"2021-04-17T16:43:53.809489Z"}
1618677833.797864: {"type":"l2update","product_id":"SKL-USD","changes":[["buy","0.7883","4577.1"]],"time":"2021-04-17T16:43:53.812985Z"}
1618677833.797921: {"type":"l2update","product_id":"DASH-BTC","changes":[["sell","0.00619382","14.63200000"]],"time":"2021-04-17T16:43:53.813064Z"}
1618677833.8020191: {"type":"l2update","product_id":"NMR-EUR","changes":[["buy","66.9136","1.322"]],"time":"2021-04-17T16:43:53.816874Z"}
1618677833.802078: {"type":"l2update","product_id":"NMR-EUR","changes":[["buy","66.9136","0.000"]],"time":"2021-04-17T16:43:53.817161Z"}
1618677833.806529: {"type":"l2update","product_id":"DASH-BTC","changes":[["sell","0.00618852","0.00000000"]],"time":"2021-04-17T16:43:53.820961Z"}
1618677833.8099: {"type":"l2update","product_id":"CRV-EUR","changes":[["buy","3.2948","140.93"]],"time":"2021-04-17T16:43:53.824342Z"}
1618677833.80997: {"type":"l2update","product_id":"CRV-EUR","changes":[["buy","3.2964","0.00"]],"time":"2021-04-17T16:43:53.824412Z"}
1618677833.813171: {"type":"l2update","product_id":"CRV-EUR","changes":[["buy","3.2948","281.86"]],"time":"2021-04-17T16:43:53.828190Z"}
1618677833.8248372: {"type":"l2update","product_id":"NMR-EUR","changes":[["buy","66.8895","1.322"]],"time":"2021-04-17T16:43:53.831752Z"}
1618677833.824975: {"type":"l2update","product_id":"NMR-EUR","changes":[["buy","66.8895","2.644"]],"time":"2021-04-17T16:43:53.835257Z"}
1618677833.827428: {"type":"l2update","product_id":"CRV-EUR","changes":[["sell","3.3054","140.93"]],"time":"2021-04-17T16:43:53.842589Z"}
1618677833.827533: {"type":"l2update","product_id":"DASH-BTC","changes":[["sell","0.00618850","0.82500000"]],"time":"2021-04-17T16:43:53.842969Z"}
1618677833.8393338: {"type":"l2update","product_id":"YFI-BTC","changes":[["sell","0.82937","0.000000"]],"time":"2021-04-17T16:43:53.847842Z"}
1618677833.8394701: {"type":"l2update","product_id":"SKL-USD","changes":[["buy","0.7888","0.0"]],"time":"2021-04-17T16:43:53.850438Z"}
1618677833.8398888: {"type":"l2update","product_id":"DASH-BTC","changes":[["buy","0.00617815","0.00000000"]],"time":"2021-04-17T16:43:53.854955Z"}
1618677833.8592331: {"type":"l2update","product_id":"DASH-BTC","changes":[["buy","0.00617818","0.00000000"]],"time":"2021-04-17T16:43:53.864119Z"}
1618677833.859373: {"type":"match","trade_id":923562,"maker_order_id":"09f226c2-2a0a-45a2-8a4f-50ba71e664b5","taker_order_id":"bebc5bd6-50c1-491a-954c-8f27cc93c990","side":"buy","size":"0.295","price":"0.00617818","product_id":"DASH-BTC","sequence":2040406553,"time":"2021-04-17T16:43:53.864119Z"}
1618677833.8594298: {"type":"ticker","sequence":2040406553,"product_id":"DASH-BTC","price":"0.00617818","open_24h":"0.00602352","volume_24h":"10364.64917066","low_24h":"0.0058755","high_24h":"0.00663815","volume_30d":"117700.84365811","best_bid":"0.00617817","best_ask":"0.00618850","side":"sell","time":"2021-04-17T16:43:53.864119Z","trade_id":923562,"last_size":"0.295"}
1618677833.859474: {"type":"l2update","product_id":"DASH-BTC","changes":[["buy","0.00617817","0.00000000"]],"time":"2021-04-17T16:43:53.864119Z"}
1618677833.859529: {"type":"match","trade_id":923563,"maker_order_id":"c38e5257-5c8c-4853-9cb9-82b49792bb76","taker_order_id":"bebc5bd6-50c1-491a-954c-8f27cc93c990","side":"buy","size":"2.578","price":"0.00617817","product_id":"DASH-BTC","sequence":2040406555,"time":"2021-04-17T16:43:53.864119Z"}
1618677833.863533: {"type":"ticker","sequence":2040406555,"product_id":"DASH-BTC","price":"0.00617817","open_24h":"0.00602352","volume_24h":"10367.22717066","low_24h":"0.0058755","high_24h":"0.00663815","volume_30d":"117703.42165811","best_bid":"0.00617590","best_ask":"0.00618850","side":"sell","time":"2021-04-17T16:43:53.864119Z","trade_id":923563,"last_size":"2.578"}
1618677833.863602: {"type":"l2update","product_id":"DASH-BTC","changes":[["buy","0.00617590","1.67400000"]],"time":"2021-04-17T16:43:53.864119Z"}
1618677833.863651: {"type":"match","trade_id":923564,"maker_order_id":"0a51039b-bf51-4450-af63-5b487ee9cfb2","taker_order_id":"bebc5bd6-50c1-491a-954c-8f27cc93c990","side":"buy","size":"0.994","price":"0.0061759","product_id":"DASH-BTC","sequence":2040406557,"time":"2021-04-17T16:43:53.864119Z"}
1618677833.863681: {"type":"ticker","sequence":2040406557,"product_id":"DASH-BTC","price":"0.0061759","open_24h":"0.00602352","volume_24h":"10368.22117066","low_24h":"0.0058755","high_24h":"0.00663815","volume_30d":"117704.41565811","best_bid":"0.00617590","best_ask":"0.00618850","side":"sell","time":"2021-04-17T16:43:53.864119Z","trade_id":923564,"last_size":"0.994"}
1618677833.8637052: {"type":"l2update","product_id":"SKL-USD","changes":[["buy","0.7884","2935.2"]],"time":"2021-04-17T16:43:53.871999Z"}
1618677833.863734: {"type":"l2update","product_id":"CRV-EUR","changes":[["buy","3.2948","140.93"]],"time":"2021-04-17T16:43:53.872904Z"}
1618677833.863758: {"type":"l2update","product_id":"CRV-EUR","changes":[["buy","3.2948","0.00"]],"time":"2021-04-17T16:43:53.873180Z"}
1618677833.863798: {"type":"l2update","product_id":"NMR-EUR","changes":[["buy","66.8895","1.322"]],"time":"2021-04-17T16:43:53.873019Z"}
1618677833.863822: {"type":"l2update","product_id":"NMR-EUR","changes":[["buy","66.8895","0.000"]],"time":"2021-04-17T16:43:53.873349Z"}
1618677833.8638499: {"type":"l2update","product_id":"DASH-BTC","changes":[["buy","0.00617590","0.12800000"]],"time":"2021-04-17T16:43:53.878614Z"}
1618677833.8829708: {"type":"l2update","product_id":"CRV-EUR","changes":[["buy","3.2964","140.93"]],"time":"2021-04-17T16:43:53.898364Z"}
1618677833.887551: {"type":"l2update","product_id":"NMR-EUR","changes":[["buy","66.9138","1.322"]],"time":"2021-04-17T16:43:53.898432Z"}
1618677833.8876522: {"type":"l2update","product_id":"YFI-BTC","changes":[["sell","0.82937","0.000493"]],"time":"2021-04-17T16:43:53.898505Z"}
1618677833.887718: {"type":"l2update","product_id":"CRV-EUR","changes":[["sell","3.3054","0.00"]],"time":"2021-04-17T16:43:53.900918Z"}
1618677833.887785: {"type":"l2update","product_id":"DASH-BTC","changes":[["buy","0.00617231","1.54700000"]],"time":"2021-04-17T16:43:53.902282Z"}
1618677833.8878489: {"type":"l2update","product_id":"NMR-EUR","changes":[["buy","66.9138","2.644"]],"time":"2021-04-17T16:43:53.902446Z"}
1618677833.887873: {"type":"l2update","product_id":"DASH-BTC","changes":[["buy","0.00617147","0.00000000"]],"time":"2021-04-17T16:43:53.903525Z"}
1618677833.8904262: {"type":"l2update","product_id":"CRV-EUR","changes":[["buy","3.2964","281.86"]],"time":"2021-04-17T16:43:53.905294Z"}
1618677833.89469: {"type":"l2update","product_id":"DASH-BTC","changes":[["buy","0.00617590","0.00000000"]],"time":"2021-04-17T16:43:53.907846Z"}
1618677833.894793: {"type":"l2update","product_id":"NMR-EUR","changes":[["buy","66.9137","0.000"]],"time":"2021-04-17T16:43:53.910312Z"}
1618677833.898585: {"type":"l2update","product_id":"NMR-EUR","changes":[["buy","66.9139","4.775"]],"time":"2021-04-17T16:43:53.912885Z"}
1618677833.9029791: {"type":"l2update","product_id":"DASH-BTC","changes":[["sell","0.00618850","1.81000000"]],"time":"2021-04-17T16:43:53.916733Z"}
1618677833.9128: {"type":"l2update","product_id":"CRV-EUR","changes":[["buy","3.2968","0.00"]],"time":"2021-04-17T16:43:53.927455Z"}
1618677833.916807: {"type":"l2update","product_id":"CRV-EUR","changes":[["sell","3.3071","140.93"]],"time":"2021-04-17T16:43:53.932030Z"}
1618677833.916943: {"type":"l2update","product_id":"DASH-BTC","changes":[["buy","0.00617231","2.67000000"]],"time":"2021-04-17T16:43:53.932003Z"}
1618677833.9210129: {"type":"l2update","product_id":"DASH-BTC","changes":[["sell","0.00619812","0.00000000"]],"time":"2021-04-17T16:43:53.935963Z"}
1618677833.934025: {"type":"l2update","product_id":"CRV-EUR","changes":[["buy","3.2964","140.93"]],"time":"2021-04-17T16:43:53.948707Z"}
1618677833.934143: {"type":"l2update","product_id":"CRV-EUR","changes":[["buy","3.2964","0.00"]],"time":"2021-04-17T16:43:53.949605Z"}
1618677833.937268: {"type":"l2update","product_id":"CRV-EUR","changes":[["sell","3.3057","140.93"]],"time":"2021-04-17T16:43:53.953103Z"}
1618677833.937372: {"type":"l2update","product_id":"YFI-BTC","changes":[["buy","0.82549","0.030259"]],"time":"2021-04-17T16:43:53.953260Z"}
1618677833.943892: {"type":"l2update","product_id":"DASH-BTC","changes":[["sell","0.00619381","1.62300000"]],"time":"2021-04-17T16:43:53.957154Z"}
1618677833.9506738: {"type":"l2update","product_id":"CRV-EUR","changes":[["buy","3.2953","96.96"]],"time":"2021-04-17T16:43:53.964510Z"}
1618677833.9625: {"type":"l2update","product_id":"CRV-EUR","changes":[["sell","3.3071","0.00"]],"time":"2021-04-17T16:43:53.978816Z"}
1618677833.970743: {"type":"l2update","product_id":"CRV-EUR","changes":[["buy","3.2950","140.93"]],"time":"2021-04-17T16:43:53.980778Z"}
1618677833.970798: {"type":"l2update","product_id":"DASH-BTC","changes":[["buy","0.00616934","32.84700000"]],"time":"2021-04-17T16:43:53.986353Z"}
1618677833.974098: {"type":"l2update","product_id":"SKL-BTC","changes":[["buy","0.00001303","1666.4"]],"time":"2021-04-17T16:43:53.990462Z"}
1618677833.974187: {"type":"l2update","product_id":"SKL-BTC","changes":[["sell","0.00001310","610.0"]],"time":"2021-04-17T16:43:53.990462Z"}
1618677833.978081: {"type":"l2update","product_id":"CRV-EUR","changes":[["buy","3.2965","120.00"]],"time":"2021-04-17T16:43:53.991078Z"}
1618677833.988288: {"type":"l2update","product_id":"CRV-EUR","changes":[["buy","3.2950","281.86"]],"time":"2021-04-17T16:43:54.001723Z"}
1618677833.9883819: {"type":"l2update","product_id":"DASH-BTC","changes":[["sell","0.00618853","0.00000000"]],"time":"2021-04-17T16:43:54.002552Z"}
1618677833.9987268: {"type":"l2update","product_id":"BAND-BTC","changes":[["sell","0.00033485","28.21"]],"time":"2021-04-17T16:43:54.013350Z"}
1618677833.998867: {"type":"l2update","product_id":"DASH-BTC","changes":[["buy","0.00617498","2.57800000"]],"time":"2021-04-17T16:43:54.013502Z"}
1618677834.0046332: {"type":"l2update","product_id":"DASH-BTC","changes":[["sell","0.00619460","0.00000000"]],"time":"2021-04-17T16:43:54.019689Z"}
1618677834.0172281: {"type":"l2update","product_id":"BAND-BTC","changes":[["sell","0.00033513","338.64"]],"time":"2021-04-17T16:43:54.032143Z"}
1618677834.022249: {"type":"l2update","product_id":"SKL-BTC","changes":[["sell","0.00001307","3071.2"]],"time":"2021-04-17T16:43:54.035650Z"}
1618677834.024599: {"type":"l2update","product_id":"DASH-BTC","changes":[["sell","0.00619381","3.85900000"]],"time":"2021-04-17T16:43:54.039495Z"}
1618677834.035417: {"type":"l2update","product_id":"BAND-BTC","changes":[["sell","0.00033514","0.00"]],"time":"2021-04-17T16:43:54.044939Z"}
1618677834.035559: {"type":"l2update","product_id":"DASH-BTC","changes":[["sell","0.00618985","0.00000000"]],"time":"2021-04-17T16:43:54.045929Z"}
1618677834.052186: {"type":"l2update","product_id":"DASH-BTC","changes":[["sell","0.00619381","5.48200000"]],"time":"2021-04-17T16:43:54.065999Z"}
1618677834.0628061: {"type":"l2update","product_id":"BAND-BTC","changes":[["buy","0.00033325","49.45"]],"time":"2021-04-17T16:43:54.072634Z"}
1618677834.062925: {"type":"l2update","product_id":"YFI-BTC","changes":[["buy","0.81906","0.010432"]],"time":"2021-04-17T16:43:54.073045Z"}
1618677834.062998: {"type":"l2update","product_id":"BAND-BTC","changes":[["buy","0.00033325","20.80"]],"time":"2021-04-17T16:43:54.076062Z"}
1618677834.066443: {"type":"l2update","product_id":"DASH-BTC","changes":[["buy","0.00616566","1.39300000"]],"time":"2021-04-17T16:43:54.077307Z"}
1618677834.06658: {"type":"l2update","product_id":"CRV-EUR","changes":[["buy","3.2950","140.93"]],"time":"2021-04-17T16:43:54.079275Z"}
1618677834.066635: {"type":"l2update","product_id":"NMR-EUR","changes":[["buy","66.9138","1.322"]],"time":"2021-04-17T16:43:54.079443Z"}
1618677834.066678: {"type":"l2update","product_id":"CRV-EUR","changes":[["buy","3.2950","0.00"]],"time":"2021-04-17T16:43:54.079472Z"}
1618677834.066732: {"type":"l2update","product_id":"CRV-EUR","changes":[["sell","3.3057","0.00"]],"time":"2021-04-17T16:43:54.079593Z"}
1618677834.0667782: {"type":"l2update","product_id":"NMR-EUR","changes":[["buy","66.9138","0.000"]],"time":"2021-04-17T16:43:54.079584Z"}
1618677834.080348: {"type":"l2update","product_id":"BAND-BTC","changes":[["sell","0.00033498","36.75"]],"time":"2021-04-17T16:43:54.092107Z"}
1618677834.0822961: {"type":"l2update","product_id":"BAND-BTC","changes":[["buy","0.00033324","20.81"]],"time":"2021-04-17T16:43:54.096042Z"}
1618677834.0965388: {"type":"l2update","product_id":"CRV-EUR","changes":[["sell","3.3071","140.93"]],"time":"2021-04-17T16:43:54.104183Z"}
1618677834.096674: {"type":"l2update","product_id":"NMR-EUR","changes":[["buy","66.9140","1.322"]],"time":"2021-04-17T16:43:54.105497Z"}
1618677834.096737: {"type":"l2update","product_id":"CRV-EUR","changes":[["buy","3.2964","140.93"]],"time":"2021-04-17T16:43:54.105591Z"}
1618677834.096789: {"type":"l2update","product_id":"NMR-EUR","changes":[["buy","66.9140","2.644"]],"time":"2021-04-17T16:43:54.108125Z"}
1618677834.096826: {"type":"l2update","product_id":"BAND-BTC","changes":[["buy","0.00033324","49.46"]],"time":"2021-04-17T16:43:54.108326Z"}
1618677834.096863: {"type":"l2update","product_id":"CRV-EUR","changes":[["buy","3.2964","281.86"]],"time":"2021-04-17T16:43:54.108797Z"}
1618677834.0968971: {"type":"l2update","product_id":"NMR-EUR","changes":[["buy","66.9139","0.000"]],"time":"2021-04-17T16:43:54.111575Z"}
1618677834.1048179: {"type":"l2update","product_id":"NMR-EUR","changes":[["buy","66.9141","4.775"]],"time":"2021-04-17T16:43:54.115742Z"}
1618677834.10495: {"type":"l2update","product_id":"BAND-BTC","changes":[["buy","0.00033427","66.37"]],"time":"2021-04-17T16:43:54.115775Z"}
1618677834.136169: {"type":"l2update","product_id":"DASH-BTC","changes":[["sell","0.00619382","0.00000000"]],"time":"2021-04-17T16:43:54.142601Z"}
1618677834.13814: {"type":"l2update","product_id":"SKL-BTC","changes":[["buy","0.00001300","2847.2"]],"time":"2021-04-17T16:43:54.146223Z"}
1618677834.138227: {"type":"l2update","product_id":"SKL-BTC","changes":[["sell","0.00001307","3906.4"]],"time":"2021-04-17T16:43:54.146223Z"}
1618677834.1382778: {"type":"l2update","product_id":"CRV-EUR","changes":[["sell","3.3071","0.00"]],"time":"2021-04-17T16:43:54.151402Z"}
1618677834.138339: {"type":"l2update","product_id":"CRV-EUR","changes":[["buy","3.2964","140.93"]],"time":"2021-04-17T16:43:54.151502Z"}
1618677834.138379: {"type":"l2update","product_id":"DASH-BTC","changes":[["sell","0.00618850","0.98500000"]],"time":"2021-04-17T16:43:54.152192Z"}
1618677834.138416: {"type":"l2update","product_id":"CRV-EUR","changes":[["buy","3.2964","0.00"]],"time":"2021-04-17T16:43:54.153916Z"}
1618677834.138763: {"type":"l2update","product_id":"BAND-BTC","changes":[["buy","0.00033323","0.00"]],"time":"2021-04-17T16:43:54.154965Z"}
1618677834.14758: {"type":"l2update","product_id":"BAND-BTC","changes":[["buy","0.00033345","148.30"]],"time":"2021-04-17T16:43:54.162076Z"}
1618677834.1477141: {"type":"l2update","product_id":"BAND-BTC","changes":[["buy","0.00033170","269.16"]],"time":"2021-04-17T16:43:54.162076Z"}
1618677834.157082: {"type":"l2update","product_id":"CRV-EUR","changes":[["buy","3.2952","646.75"]],"time":"2021-04-17T16:43:54.172755Z"}
1618677834.165932: {"type":"l2update","product_id":"CRV-EUR","changes":[["sell","3.3058","140.93"]],"time":"2021-04-17T16:43:54.173307Z"}
1618677834.166068: {"type":"l2update","product_id":"DASH-BTC","changes":[["sell","0.00618850","2.11300000"]],"time":"2021-04-17T16:43:54.176703Z"}
1618677834.166126: {"type":"l2update","product_id":"CRV-EUR","changes":[["buy","3.2952","787.68"]],"time":"2021-04-17T16:43:54.176750Z"}
1618677834.177223: {"type":"l2update","product_id":"BAND-GBP","changes":[["buy","14.7657","0.00"]],"time":"2021-04-17T16:43:54.191329Z"}
1618677834.189106: {"type":"l2update","product_id":"NMR-EUR","changes":[["buy","66.9140","1.322"]],"time":"2021-04-17T16:43:54.205404Z"}
1618677834.1892219: {"type":"l2update","product_id":"CRV-EUR","changes":[["buy","3.2952","646.75"]],"time":"2021-04-17T16:43:54.205831Z"}
1618677834.189276: {"type":"l2update","product_id":"NMR-EUR","changes":[["buy","66.9140","0.000"]],"time":"2021-04-17T16:43:54.205935Z"}
1618677834.189339: {"type":"l2update","product_id":"CRV-EUR","changes":[["buy","3.2952","505.82"]],"time":"2021-04-17T16:43:54.206189Z"}
1618677834.1969972: {"type":"l2update","product_id":"CRV-EUR","changes":[["buy","3.2960","140.93"]],"time":"2021-04-17T16:43:54.210889Z"}
1618677834.197133: {"type":"l2update","product_id":"CRV-EUR","changes":[["sell","3.3201","265.00"]],"time":"2021-04-17T16:43:54.212319Z"}
1618677834.197186: {"type":"l2update","product_id":"CRV-EUR","changes":[["buy","3.2698","81.50"]],"time":"2021-04-17T16:43:54.212319Z"}
1618677834.197227: {"type":"l2update","product_id":"CRV-EUR","changes":[["buy","3.2697","96.50"]],"time":"2021-04-17T16:43:54.212319Z"}
1618677834.197263: {"type":"l2update","product_id":"CRV-EUR","changes":[["buy","3.2698","0.00"]],"time":"2021-04-17T16:43:54.212319Z"}
1618677834.197313: {"type":"l2update","product_id":"CRV-EUR","changes":[["buy","3.2697","1.00"]],"time":"2021-04-17T16:43:54.212319Z"}
1618677834.206472: {"type":"l2update","product_id":"CRV-EUR","changes":[["buy","3.2960","281.86"]],"time":"2021-04-17T16:43:54.219094Z"}
1618677834.206559: {"type":"l2update","product_id":"CRV-EUR","changes":[["sell","3.3198","90.00"]],"time":"2021-04-17T16:43:54.219198Z"}
1618677834.206624: {"type":"l2update","product_id":"CRV-EUR","changes":[["buy","3.2697","96.50"]],"time":"2021-04-17T16:43:54.219198Z"}
1618677834.206665: {"type":"l2update","product_id":"CRV-EUR","changes":[["buy","3.2706","92.00"]],"time":"2021-04-17T16:43:54.219198Z"}
1618677834.206708: {"type":"l2update","product_id":"DASH-BTC","changes":[["buy","0.00617231","1.12300000"]],"time":"2021-04-17T16:43:54.219854Z"}
1618677834.2067468: {"type":"l2update","product_id":"NMR-EUR","changes":[["buy","66.9142","1.322"]],"time":"2021-04-17T16:43:54.222517Z"}
1618677834.2128892: {"type":"l2update","product_id":"DASH-BTC","changes":[["sell","0.00619220","14.63200000"]],"time":"2021-04-17T16:43:54.225825Z"}
1618677834.21701: {"type":"l2update","product_id":"NMR-EUR","changes":[["buy","66.9142","2.644"]],"time":"2021-04-17T16:43:54.233409Z"}
1618677834.225865: {"type":"l2update","product_id":"DASH-BTC","changes":[["buy","0.00617318","2.67200000"]],"time":"2021-04-17T16:43:54.240678Z"}
1618677834.226002: {"type":"l2update","product_id":"DASH-BTC","changes":[["buy","0.00617499","0.55300000"]],"time":"2021-04-17T16:43:54.240710Z"}
1618677834.2387059: {"type":"l2update","product_id":"CRV-EUR","changes":[["buy","3.2960","140.93"]],"time":"2021-04-17T16:43:54.250353Z"}
1618677834.238822: {"type":"l2update","product_id":"CRV-EUR","changes":[["buy","3.2960","0.00"]],"time":"2021-04-17T16:43:54.250487Z"}
1618677834.2388968: {"type":"l2update","product_id":"SKL-GBP","changes":[["sell","0.5771","1293.2"]],"time":"2021-04-17T16:43:54.251865Z"}
1618677834.252867: {"type":"l2update","product_id":"SKL-USD","changes":[["buy","0.7845","0.0"]],"time":"2021-04-17T16:43:54.266849Z"}
1618677834.2529678: {"type":"l2update","product_id":"SKL-USD","changes":[["sell","0.7948","1263.2"]],"time":"2021-04-17T16:43:54.266849Z"}
1618677834.259414: {"type":"l2update","product_id":"CRV-EUR","changes":[["buy","3.2953","237.89"]],"time":"2021-04-17T16:43:54.270711Z"}
1618677834.259531: {"type":"l2update","product_id":"CRV-EUR","changes":[["buy","3.2953","378.82"]],"time":"2021-04-17T16:43:54.274346Z"}
1618677834.267543: {"type":"l2update","product_id":"SKL-USD","changes":[["buy","0.7882","0.0"]],"time":"2021-04-17T16:43:54.284015Z"}
1618677834.269877: {"type":"l2update","product_id":"SKL-USD","changes":[["buy","0.7866","7497.0"]],"time":"2021-04-17T16:43:54.285373Z"}
1618677834.274097: {"type":"l2update","product_id":"BAND-BTC","changes":[["buy","0.00033345","0.00"]],"time":"2021-04-17T16:43:54.288713Z"}
1618677834.289359: {"type":"l2update","product_id":"SKL-USD","changes":[["buy","0.7883","1389.1"]],"time":"2021-04-17T16:43:54.293820Z"}
1618677834.28948: {"type":"l2update","product_id":"SKL-BTC","changes":[["buy","0.00001301","17334.9"]],"time":"2021-04-17T16:43:54.296289Z"}
1618677834.2895339: {"type":"l2update","product_id":"SKL-BTC","changes":[["sell","0.00001308","20203.9"]],"time":"2021-04-17T16:43:54.296289Z"}
1618677834.2895749: {"type":"l2update","product_id":"SKL-USD","changes":[["buy","0.7862","5.0"]],"time":"2021-04-17T16:43:54.301221Z"}
1618677834.28961: {"type":"l2update","product_id":"SKL-BTC","changes":[["buy","0.00001302","8596.6"]],"time":"2021-04-17T16:43:54.301706Z"}
1618677834.289645: {"type":"l2update","product_id":"CRV-EUR","changes":[["buy","3.2953","237.89"]],"time":"2021-04-17T16:43:54.302193Z"}
1618677834.289679: {"type":"l2update","product_id":"CRV-EUR","changes":[["buy","3.2953","96.96"]],"time":"2021-04-17T16:43:54.302693Z"}
1618677834.2897332: {"type":"l2update","product_id":"BAND-GBP","changes":[["buy","14.7614","0.00"]],"time":"2021-04-17T16:43:54.303425Z"}
1618677834.2944891: {"type":"l2update","product_id":"BAND-GBP","changes":[["sell","14.7879","12.52"]],"time":"2021-04-17T16:43:54.308819Z"}
1618677834.297073: {"type":"l2update","product_id":"DASH-BTC","changes":[["sell","0.00618637","2.49400000"]],"time":"2021-04-17T16:43:54.312835Z"}
1618677834.2979672: {"type":"l2update","product_id":"SKL-BTC","changes":[["sell","0.00001310","1445.2"]],"time":"2021-04-17T16:43:54.313228Z"}
1618677834.301055: {"type":"l2update","product_id":"CRV-EUR","changes":[["buy","3.2961","140.93"]],"time":"2021-04-17T16:43:54.316243Z"}
1618677834.304422: {"type":"l2update","product_id":"SKL-USD","changes":[["buy","0.7867","25513.9"]],"time":"2021-04-17T16:43:54.320053Z"}
1618677834.30914: {"type":"l2update","product_id":"CRV-EUR","changes":[["sell","3.3058","0.00"]],"time":"2021-04-17T16:43:54.323475Z"}
1618677834.309244: {"type":"l2update","product_id":"BAND-GBP","changes":[["buy","14.7516","12.82"]],"time":"2021-04-17T16:43:54.323706Z"}
1618677834.312563: {"type":"l2update","product_id":"CRV-EUR","changes":[["buy","3.2831","0.00"]],"time":"2021-04-17T16:43:54.326301Z"}
1618677834.3126621: {"type":"l2update","product_id":"CRV-EUR","changes":[["buy","3.2961","281.86"]],"time":"2021-04-17T16:43:54.327463Z"}
1618677834.324058: {"type":"l2update","product_id":"DASH-BTC","changes":[["sell","0.00618258","2.49400000"]],"time":"2021-04-17T16:43:54.331352Z"}
1618677834.3241978: {"type":"l2update","product_id":"BAND-BTC","changes":[["sell","0.00033485","0.00"]],"time":"2021-04-17T16:43:54.336054Z"}
1618677834.326036: {"type":"l2update","product_id":"DASH-BTC","changes":[["sell","0.00619640","0.00000000"]],"time":"2021-04-17T16:43:54.340392Z"}
1618677834.326804: {"type":"l2update","product_id":"SKL-USD","changes":[["buy","0.7905","0.0"]],"time":"2021-04-17T16:43:54.342494Z"}
1618677834.3348942: {"type":"l2update","product_id":"DASH-BTC","changes":[["sell","0.00618850","1.12800000"]],"time":"2021-04-17T16:43:54.350080Z"}
1618677834.336205: {"type":"l2update","product_id":"CRV-EUR","changes":[["sell","3.3068","140.93"]],"time":"2021-04-17T16:43:54.350140Z"}
1618677834.339555: {"type":"l2update","product_id":"NMR-EUR","changes":[["buy","66.9141","0.000"]],"time":"2021-04-17T16:43:54.353438Z"}
1618677834.339691: {"type":"l2update","product_id":"BAND-GBP","changes":[["buy","14.6494","10.60"]],"time":"2021-04-17T16:43:54.354099Z"}
1618677834.339749: {"type":"l2update","product_id":"BAND-GBP","changes":[["buy","14.6493","0.00"]],"time":"2021-04-17T16:43:54.354099Z"}
1618677834.339801: {"type":"l2update","product_id":"BAND-GBP","changes":[["buy","14.6495","2.90"]],"time":"2021-04-17T16:43:54.354099Z"}
1618677834.339839: {"type":"l2update","product_id":"DASH-BTC","changes":[["sell","0.00619381","3.24600000"]],"time":"2021-04-17T16:43:54.354455Z"}
1618677834.3398771: {"type":"l2update","product_id":"BAND-GBP","changes":[["buy","14.7061","0.00"]],"time":"2021-04-17T16:43:54.354099Z"}
1618677834.344623: {"type":"l2update","product_id":"BAND-GBP","changes":[["buy","14.6494","0.00"]],"time":"2021-04-17T16:43:54.354099Z"}
1618677834.344724: {"type":"l2update","product_id":"NMR-EUR","changes":[["buy","66.9143","4.775"]],"time":"2021-04-17T16:43:54.357247Z"}
1618677834.34479: {"type":"l2update","product_id":"DASH-BTC","changes":[["sell","0.00619461","0.00000000"]],"time":"2021-04-17T16:43:54.359057Z"}
1618677834.344848: {"type":"l2update","product_id":"CRV-EUR","changes":[["buy","3.2830","0.00"]],"time":"2021-04-17T16:43:54.358631Z"}
1618677834.344897: {"type":"l2update","product_id":"BAND-GBP","changes":[["buy","14.6497","27.50"]],"time":"2021-04-17T16:43:54.361237Z"}
1618677834.344936: {"type":"l2update","product_id":"BAND-GBP","changes":[["buy","14.6498","15.70"]],"time":"2021-04-17T16:43:54.361237Z"}
1618677834.348393: {"type":"l2update","product_id":"NMR-EUR","changes":[["sell","71.9762","0.000"]],"time":"2021-04-17T16:43:54.364204Z"}
1618677834.348511: {"type":"l2update","product_id":"NMR-EUR","changes":[["sell","71.9763","0.000"]],"time":"2021-04-17T16:43:54.364204Z"}
1618677834.348573: {"type":"l2update","product_id":"NMR-EUR","changes":[["sell","72.0976","0.000"]],"time":"2021-04-17T16:43:54.364204Z"}
1618677834.3511848: {"type":"l2update","product_id":"DASH-BTC","changes":[["sell","0.00619197","0.00000000"]],"time":"2021-04-17T16:43:54.368060Z"}
1618677834.361126: {"type":"l2update","product_id":"NMR-EUR","changes":[["sell","72.0974","24.150"]],"time":"2021-04-17T16:43:54.372693Z"}
1618677834.3612642: {"type":"l2update","product_id":"NMR-EUR","changes":[["sell","71.9760","21.270"]],"time":"2021-04-17T16:43:54.372693Z"}
1618677834.361321: {"type":"l2update","product_id":"NMR-EUR","changes":[["sell","71.9128","11.680"]],"time":"2021-04-17T16:43:54.372693Z"}
1618677834.3687968: {"type":"l2update","product_id":"DASH-BTC","changes":[["sell","0.00618636","0.98500000"]],"time":"2021-04-17T16:43:54.383045Z"}
1618677834.3735402: {"type":"l2update","product_id":"DASH-BTC","changes":[["sell","0.00619381","1.62300000"]],"time":"2021-04-17T16:43:54.387447Z"}
1618677834.382533: {"type":"l2update","product_id":"BAND-BTC","changes":[["buy","0.00033325","0.00"]],"time":"2021-04-17T16:43:54.394284Z"}
1618677834.382671: {"type":"l2update","product_id":"BAND-GBP","changes":[["buy","14.7609","12.26"]],"time":"2021-04-17T16:43:54.394998Z"}
1618677834.3827388: {"type":"l2update","product_id":"DASH-BTC","changes":[["sell","0.00619196","2.23600000"]],"time":"2021-04-17T16:43:54.398251Z"}
1618677834.382794: {"type":"l2update","product_id":"SKL-USD","changes":[["sell","0.7920","0.0"]],"time":"2021-04-17T16:43:54.398531Z"}
1618677834.388895: {"type":"l2update","product_id":"DASH-BTC","changes":[["sell","0.00619220","0.00000000"]],"time":"2021-04-17T16:43:54.403522Z"}
1618677834.395603: {"type":"l2update","product_id":"DASH-BTC","changes":[["sell","0.00618985","1.62300000"]],"time":"2021-04-17T16:43:54.409655Z"}
1618677834.404116: {"type":"l2update","product_id":"CRV-EUR","changes":[["buy","3.2961","140.93"]],"time":"2021-04-17T16:43:54.416839Z"}
1618677834.404233: {"type":"l2update","product_id":"SKL-USD","changes":[["buy","0.7873","1910.0"]],"time":"2021-04-17T16:43:54.417452Z"}
1618677834.406071: {"type":"l2update","product_id":"BAND-BTC","changes":[["buy","0.00033323","20.81"]],"time":"2021-04-17T16:43:54.421432Z"}
1618677834.410613: {"type":"l2update","product_id":"BAND-BTC","changes":[["buy","0.00033324","28.65"]],"time":"2021-04-17T16:43:54.425138Z"}
1618677834.412076: {"type":"l2update","product_id":"BAND-BTC","changes":[["buy","0.00033324","0.00"]],"time":"2021-04-17T16:43:54.428937Z"}
1618677834.4204118: {"type":"l2update","product_id":"CRV-EUR","changes":[["buy","3.2961","0.00"]],"time":"2021-04-17T16:43:54.436110Z"}
1618677834.4267268: {"type":"l2update","product_id":"CRV-EUR","changes":[["buy","3.2953","237.89"]],"time":"2021-04-17T16:43:54.441078Z"}
1618677834.426816: {"type":"l2update","product_id":"SKL-USD","changes":[["sell","0.7917","9539.4"]],"time":"2021-04-17T16:43:54.441406Z"}
1618677834.431969: {"type":"l2update","product_id":"SKL-USD","changes":[["buy","0.7715","0.0"]],"time":"2021-04-17T16:43:54.446675Z"}
1618677834.4331892: {"type":"l2update","product_id":"SKL-USD","changes":[["sell","0.7943","5.0"]],"time":"2021-04-17T16:43:54.448629Z"}
1618677834.433277: {"type":"l2update","product_id":"BAND-BTC","changes":[["buy","0.00033323","41.62"]],"time":"2021-04-17T16:43:54.448639Z"}
1618677834.435245: {"type":"l2update","product_id":"SKL-BTC","changes":[["buy","0.00001300","1878.0"]],"time":"2021-04-17T16:43:54.452223Z"}
1618677834.4375172: {"type":"l2update","product_id":"DASH-BTC","changes":[["buy","0.00615250","2.33000000"]],"time":"2021-04-17T16:43:54.454197Z"}
1618677834.4376068: {"type":"l2update","product_id":"DASH-BTC","changes":[["buy","0.00616719","0.00000000"]],"time":"2021-04-17T16:43:54.454197Z"}
1618677834.437678: {"type":"l2update","product_id":"DASH-BTC","changes":[["sell","0.00864891","4.51000000"]],"time":"2021-04-17T16:43:54.454197Z"}
1618677834.4383202: {"type":"l2update","product_id":"SKL-BTC","changes":[["sell","0.00001307","3071.2"]],"time":"2021-04-17T16:43:54.455326Z"}
1618677834.4431942: {"type":"l2update","product_id":"SKL-BTC","changes":[["buy","0.00001300","5449.1"]],"time":"2021-04-17T16:43:54.456753Z"}
1618677834.4433138: {"type":"l2update","product_id":"SKL-BTC","changes":[["sell","0.00001307","6320.5"]],"time":"2021-04-17T16:43:54.456753Z"}
1618677834.4524758: {"type":"l2update","product_id":"CRV-EUR","changes":[["buy","3.2953","378.82"]],"time":"2021-04-17T16:43:54.460661Z"}
1618677834.4525938: {"type":"l2update","product_id":"BAND-BTC","changes":[["buy","0.00033323","70.27"]],"time":"2021-04-17T16:43:54.460778Z"}
1618677834.4526489: {"type":"l2update","product_id":"SKL-GBP","changes":[["buy","0.5705","1270.0"]],"time":"2021-04-17T16:43:54.461309Z"}
1618677834.45269: {"type":"l2update","product_id":"DASH-BTC","changes":[["buy","0.00614344","2.26000000"]],"time":"2021-04-17T16:43:54.460747Z"}
1618677834.452729: {"type":"l2update","product_id":"CRV-EUR","changes":[["buy","3.2830","256.63"]],"time":"2021-04-17T16:43:54.460850Z"}
1618677834.452799: {"type":"l2update","product_id":"DASH-BTC","changes":[["sell","0.00864891","4.80000000"]],"time":"2021-04-17T16:43:54.460747Z"}
1618677834.452823: {"type":"l2update","product_id":"DASH-BTC","changes":[["buy","0.00614345","2.53000000"]],"time":"2021-04-17T16:43:54.460747Z"}
1618677834.4528499: {"type":"l2update","product_id":"NMR-EUR","changes":[["buy","66.9142","1.322"]],"time":"2021-04-17T16:43:54.465204Z"}
1618677834.452872: {"type":"l2update","product_id":"CRV-EUR","changes":[["buy","3.2953","237.89"]],"time":"2021-04-17T16:43:54.465744Z"}
1618677834.452893: {"type":"l2update","product_id":"SKL-BTC","changes":[["sell","0.00001309","3297.8"]],"time":"2021-04-17T16:43:54.468477Z"}
1618677834.452914: {"type":"l2update","product_id":"SKL-USD","changes":[["sell","0.7942","31665.1"]],"time":"2021-04-17T16:43:54.468618Z"}
1618677834.462124: {"type":"l2update","product_id":"CRV-EUR","changes":[["buy","3.2962","140.93"]],"time":"2021-04-17T16:43:54.472500Z"}
1618677834.4726222: {"type":"l2update","product_id":"DASH-BTC","changes":[["sell","0.00619048","14.63200000"]],"time":"2021-04-17T16:43:54.487068Z"}
1618677834.474796: {"type":"l2update","product_id":"BAND-GBP","changes":[["sell","14.7879","0.00"]],"time":"2021-04-17T16:43:54.489574Z"}
1618677834.474901: {"type":"l2update","product_id":"NMR-EUR","changes":[["buy","66.9144","1.322"]],"time":"2021-04-17T16:43:54.490799Z"}
1618677834.478146: {"type":"l2update","product_id":"CRV-EUR","changes":[["buy","3.2953","96.96"]],"time":"2021-04-17T16:43:54.494391Z"}
1618677834.478261: {"type":"l2update","product_id":"NMR-EUR","changes":[["buy","66.9142","0.000"]],"time":"2021-04-17T16:43:54.494520Z"}
1618677834.483314: {"type":"l2update","product_id":"NMR-EUR","changes":[["buy","66.9143","0.000"]],"time":"2021-04-17T16:43:54.499309Z"}
1618677834.489751: {"type":"l2update","product_id":"CRV-EUR","changes":[["buy","3.2962","281.86"]],"time":"2021-04-17T16:43:54.502329Z"}
1618677834.492023: {"type":"l2update","product_id":"NMR-EUR","changes":[["buy","66.9145","4.775"]],"time":"2021-04-17T16:43:54.506374Z"}
1618677834.497308: {"type":"l2update","product_id":"DASH-BTC","changes":[["sell","0.00618850","0.00000000"]],"time":"2021-04-17T16:43:54.513496Z"}
1618677834.502688: {"type":"l2update","product_id":"SKL-USD","changes":[["buy","0.7901","50.5"]],"time":"2021-04-17T16:43:54.518340Z"}
1618677834.50278: {"type":"l2update","product_id":"NMR-EUR","changes":[["buy","66.9144","2.644"]],"time":"2021-04-17T16:43:54.518225Z"}
1618677834.5134258: {"type":"l2update","product_id":"CRV-EUR","changes":[["sell","3.3201","181.50"]],"time":"2021-04-17T16:43:54.526981Z"}
1618677834.513543: {"type":"l2update","product_id":"CRV-EUR","changes":[["sell","3.3201","84.00"]],"time":"2021-04-17T16:43:54.526981Z"}
1618677834.5135932: {"type":"l2update","product_id":"SKL-GBP","changes":[["buy","0.5707","2235.0"]],"time":"2021-04-17T16:43:54.529265Z"}
1618677834.517236: {"type":"l2update","product_id":"CRV-EUR","changes":[["buy","3.2962","140.93"]],"time":"2021-04-17T16:43:54.531337Z"}
1618677834.517324: {"type":"l2update","product_id":"DASH-BTC","changes":[["sell","0.00618257","1.12800000"]],"time":"2021-04-17T16:43:54.532541Z"}
1618677834.522872: {"type":"l2update","product_id":"CRV-EUR","changes":[["sell","3.3198","194.50"]],"time":"2021-04-17T16:43:54.536543Z"}
1618677834.522965: {"type":"l2update","product_id":"CRV-EUR","changes":[["sell","3.3197","83.00"]],"time":"2021-04-17T16:43:54.536543Z"}
1618677834.523536: {"type":"l2update","product_id":"DASH-BTC","changes":[["buy","0.00617231","0.00000000"]],"time":"2021-04-17T16:43:54.539238Z"}
1618677834.528071: {"type":"l2update","product_id":"CRV-EUR","changes":[["buy","3.2962","0.00"]],"time":"2021-04-17T16:43:54.541656Z"}
1618677834.53143: {"type":"l2update","product_id":"CRV-EUR","changes":[["buy","3.2954","140.93"]],"time":"2021-04-17T16:43:54.547498Z"}
1618677834.534372: {"type":"l2update","product_id":"SKL-USD","changes":[["buy","0.7906","1849.3"]],"time":"2021-04-17T16:43:54.549229Z"}
1618677834.546338: {"type":"l2update","product_id":"DASH-BTC","changes":[["sell","0.00618851","5.27100000"]],"time":"2021-04-17T16:43:54.558228Z"}
1618677834.54644: {"type":"l2update","product_id":"DASH-BTC","changes":[["buy","0.00616935","1.12400000"]],"time":"2021-04-17T16:43:54.558239Z"}
1618677834.5494568: {"type":"l2update","product_id":"CRV-EUR","changes":[["buy","3.2962","140.93"]],"time":"2021-04-17T16:43:54.562127Z"}
1618677834.54955: {"type":"l2update","product_id":"DASH-BTC","changes":[["buy","0.00617499","0.00000000"]],"time":"2021-04-17T16:43:54.565333Z"}
1618677834.551883: {"type":"l2update","product_id":"CRV-EUR","changes":[["buy","3.2954","281.86"]],"time":"2021-04-17T16:43:54.566818Z"}
1618677834.553961: {"type":"l2update","product_id":"SKL-USD","changes":[["buy","0.7885","2631.8"]],"time":"2021-04-17T16:43:54.566829Z"}
1618677834.554037: {"type":"l2update","product_id":"DASH-BTC","changes":[["sell","0.00619381","0.00000000"]],"time":"2021-04-17T16:43:54.568091Z"}
1618677834.563148: {"type":"l2update","product_id":"SKL-USD","changes":[["sell","0.7942","1905.0"]],"time":"2021-04-17T16:43:54.574481Z"}
1618677834.5632699: {"type":"l2update","product_id":"CRV-EUR","changes":[["sell","3.3011","0.00"]],"time":"2021-04-17T16:43:54.574732Z"}
1618677834.569213: {"type":"l2update","product_id":"CRV-EUR","changes":[["sell","3.3010","0.00"]],"time":"2021-04-17T16:43:54.585077Z"}
1618677834.569974: {"type":"l2update","product_id":"NMR-EUR","changes":[["buy","66.9144","1.322"]],"time":"2021-04-17T16:43:54.587483Z"}
1618677834.574564: {"type":"l2update","product_id":"DASH-BTC","changes":[["buy","0.00617231","0.55300000"]],"time":"2021-04-17T16:43:54.588462Z"}
1618677834.574634: {"type":"l2update","product_id":"SKL-GBP","changes":[["sell","0.5771","285.0"]],"time":"2021-04-17T16:43:54.588595Z"}
1618677834.574668: {"type":"l2update","product_id":"SKL-BTC","changes":[["sell","0.00001307","5211.4"]],"time":"2021-04-17T16:43:54.588871Z"}
1618677834.576837: {"type":"l2update","product_id":"CRV-EUR","changes":[["sell","3.3018","5000.00"]],"time":"2021-04-17T16:43:54.592526Z"}
1618677834.581374: {"type":"l2update","product_id":"SKL-USD","changes":[["sell","0.7944","29765.1"]],"time":"2021-04-17T16:43:54.596200Z"}
1618677834.5814579: {"type":"l2update","product_id":"BAND-GBP","changes":[["buy","14.7643","12.45"]],"time":"2021-04-17T16:43:54.596219Z"}
1618677834.585215: {"type":"l2update","product_id":"CRV-EUR","changes":[["buy","3.2963","508.87"]],"time":"2021-04-17T16:43:54.599655Z"}
1618677834.585282: {"type":"l2update","product_id":"CRV-EUR","changes":[["buy","3.2895","1087.99"]],"time":"2021-04-17T16:43:54.599676Z"}
1618677834.58532: {"type":"l2update","product_id":"CRV-EUR","changes":[["buy","3.2954","140.93"]],"time":"2021-04-17T16:43:54.602052Z"}
1618677834.5853481: {"type":"l2update","product_id":"SKL-BTC","changes":[["buy","0.00001302","7627.4"]],"time":"2021-04-17T16:43:54.602198Z"}
1618677834.585373: {"type":"l2update","product_id":"CRV-EUR","changes":[["buy","3.2954","0.00"]],"time":"2021-04-17T16:43:54.602581Z"}
1618677834.5879512: {"type":"l2update","product_id":"SKL-BTC","changes":[["sell","0.00001310","610.0"]],"time":"2021-04-17T16:43:54.605053Z"}
1618677834.588008: {"type":"l2update","product_id":"DASH-BTC","changes":[["sell","0.00619503","1.62300000"]],"time":"2021-04-17T16:43:54.605300Z"}
1618677834.593636: {"type":"l2update","product_id":"SKL-USD","changes":[["buy","0.7884","2066.5"]],"time":"2021-04-17T16:43:54.606113Z"}
1618677834.593724: {"type":"l2update","product_id":"NMR-EUR","changes":[["buy","66.9146","1.322"]],"time":"2021-04-17T16:43:54.607638Z"}
1618677834.5937889: {"type":"l2update","product_id":"SKL-USD","changes":[["buy","0.7880","3206.2"]],"time":"2021-04-17T16:43:54.608007Z"}
1618677834.593842: {"type":"l2update","product_id":"SKL-USD","changes":[["buy","0.7715","58335.9"]],"time":"2021-04-17T16:43:54.608007Z"}
1618677834.598005: {"type":"l2update","product_id":"SKL-BTC","changes":[["sell","0.00001311","170.8"]],"time":"2021-04-17T16:43:54.611182Z"}
1618677834.601689: {"type":"l2update","product_id":"SKL-USD","changes":[["buy","0.7884","869.3"]],"time":"2021-04-17T16:43:54.612597Z"}
1618677834.601778: {"type":"l2update","product_id":"SKL-BTC","changes":[["buy","0.00001300","1878.0"]],"time":"2021-04-17T16:43:54.612694Z"}
1618677834.601831: {"type":"l2update","product_id":"SKL-BTC","changes":[["sell","0.00001307","1962.1"]],"time":"2021-04-17T16:43:54.612694Z"}
1618677834.601872: {"type":"l2update","product_id":"DASH-BTC","changes":[["sell","0.00618637","0.00000000"]],"time":"2021-04-17T16:43:54.613650Z"}
1618677834.601939: {"type":"l2update","product_id":"NMR-EUR","changes":[["buy","66.9145","0.000"]],"time":"2021-04-17T16:43:54.613866Z"}
1618677834.601988: {"type":"l2update","product_id":"SKL-USD","changes":[["buy","0.7884","0.0"]],"time":"2021-04-17T16:43:54.615900Z"}
1618677834.60399: {"type":"l2update","product_id":"DASH-BTC","changes":[["sell","0.00618258","0.00000000"]],"time":"2021-04-17T16:43:54.619813Z"}
1618677834.608116: {"type":"l2update","product_id":"NMR-EUR","changes":[["buy","66.9147","4.775"]],"time":"2021-04-17T16:43:54.620628Z"}
1618677834.608216: {"type":"l2update","product_id":"BAND-BTC","changes":[["buy","0.00033345","148.30"]],"time":"2021-04-17T16:43:54.622029Z"}
1618677834.610446: {"type":"l2update","product_id":"NMR-EUR","changes":[["buy","66.9144","0.000"]],"time":"2021-04-17T16:43:54.625761Z"}
1618677834.619029: {"type":"l2update","product_id":"NU-GBP","changes":[["sell","0.4750","21451.075802"]],"time":"2021-04-17T16:43:54.631638Z"}
1618677834.6191518: {"type":"l2update","product_id":"SKL-USD","changes":[["buy","0.7886","868.5"]],"time":"2021-04-17T16:43:54.633871Z"}
1618677834.627423: {"type":"l2update","product_id":"BAND-BTC","changes":[["sell","0.00033484","28.21"]],"time":"2021-04-17T16:43:54.640886Z"}
1618677834.627529: {"type":"l2update","product_id":"CRV-EUR","changes":[["buy","3.2962","0.00"]],"time":"2021-04-17T16:43:54.644662Z"}
1618677834.6298912: {"type":"l2update","product_id":"SKL-USD","changes":[["buy","0.7886","2065.4"]],"time":"2021-04-17T16:43:54.645145Z"}
1618677834.632731: {"type":"l2update","product_id":"NMR-EUR","changes":[["buy","66.9146","2.644"]],"time":"2021-04-17T16:43:54.648514Z"}
1618677834.6449668: {"type":"l2update","product_id":"CRV-EUR","changes":[["buy","3.2956","140.93"]],"time":"2021-04-17T16:43:54.657499Z"}
1618677834.645073: {"type":"l2update","product_id":"SKL-USD","changes":[["buy","0.7886","2934.5"]],"time":"2021-04-17T16:43:54.657632Z"}
1618677834.6520069: {"type":"l2update","product_id":"SKL-USD","changes":[["sell","0.7995","5.0"]],"time":"2021-04-17T16:43:54.665271Z"}
1618677834.658344: {"type":"l2update","product_id":"SKL-USD","changes":[["sell","0.8084","880.0"]],"time":"2021-04-17T16:43:54.673054Z"}
1618677834.6679308: {"type":"l2update","product_id":"CRV-EUR","changes":[["buy","3.2956","0.00"]],"time":"2021-04-17T16:43:54.683032Z"}
1618677834.672193: {"type":"l2update","product_id":"NMR-EUR","changes":[["buy","66.9146","1.322"]],"time":"2021-04-17T16:43:54.683252Z"}
1618677834.672249: {"type":"l2update","product_id":"NMR-EUR","changes":[["buy","66.9146","0.000"]],"time":"2021-04-17T16:43:54.683603Z"}
1618677834.672294: {"type":"l2update","product_id":"DASH-BTC","changes":[["sell","0.00618851","2.69400000"]],"time":"2021-04-17T16:43:54.684687Z"}
1618677834.6723242: {"type":"l2update","product_id":"CRV-EUR","changes":[["buy","3.2962","140.93"]],"time":"2021-04-17T16:43:54.687609Z"}
1618677834.691466: {"type":"l2update","product_id":"SKL-BTC","changes":[["sell","0.00001307","2801.0"]],"time":"2021-04-17T16:43:54.704950Z"}
1618677834.697589: {"type":"l2update","product_id":"SKL-BTC","changes":[["sell","0.00001307","3910.1"]],"time":"2021-04-17T16:43:54.708417Z"}
1618677834.6976352: {"type":"l2update","product_id":"SKL-BTC","changes":[["sell","0.00001309","2462.6"]],"time":"2021-04-17T16:43:54.710419Z"}
1618677834.6976562: {"type":"l2update","product_id":"DASH-BTC","changes":[["sell","0.00618636","0.00000000"]],"time":"2021-04-17T16:43:54.711551Z"}
1618677834.697685: {"type":"l2update","product_id":"CRV-EUR","changes":[["buy","3.2962","281.86"]],"time":"2021-04-17T16:43:54.711807Z"}
1618677834.697702: {"type":"l2update","product_id":"NMR-EUR","changes":[["buy","66.9148","1.322"]],"time":"2021-04-17T16:43:54.712157Z"}
1618677834.70352: {"type":"l2update","product_id":"NMR-EUR","changes":[["buy","66.9148","2.644"]],"time":"2021-04-17T16:43:54.716611Z"}
1618677834.703567: {"type":"l2update","product_id":"DASH-BTC","changes":[["sell","0.00619196","0.00000000"]],"time":"2021-04-17T16:43:54.717508Z"}
1618677834.7036061: {"type":"l2update","product_id":"NMR-EUR","changes":[["buy","66.9147","0.000"]],"time":"2021-04-17T16:43:54.720229Z"}
1618677834.713181: {"type":"l2update","product_id":"NMR-EUR","changes":[["buy","66.9149","4.775"]],"time":"2021-04-17T16:43:54.726269Z"}
1618677834.713221: {"type":"l2update","product_id":"DASH-BTC","changes":[["sell","0.00618850","2.57800000"]],"time":"2021-04-17T16:43:54.729283Z"}
1618677834.713244: {"type":"l2update","product_id":"SKL-BTC","changes":[["buy","0.00001300","2843.6"]],"time":"2021-04-17T16:43:54.729575Z"}
1618677834.7184262: {"type":"l2update","product_id":"DASH-BTC","changes":[["sell","0.00618850","3.56300000"]],"time":"2021-04-17T16:43:54.733174Z"}
1618677834.722686: {"type":"l2update","product_id":"DASH-BTC","changes":[["buy","0.00614342","0.00000000"]],"time":"2021-04-17T16:43:54.739262Z"}
1618677834.7227252: {"type":"l2update","product_id":"DASH-BTC","changes":[["buy","0.00614343","0.00000000"]],"time":"2021-04-17T16:43:54.739262Z"}
1618677834.7312489: {"type":"l2update","product_id":"SKL-BTC","changes":[["sell","0.00001311","2070.8"]],"time":"2021-04-17T16:43:54.744248Z"}
1618677834.7312782: {"type":"l2update","product_id":"DASH-BTC","changes":[["buy","0.00614346","2.27000000"]],"time":"2021-04-17T16:43:54.744285Z"}
1618677834.7312992: {"type":"l2update","product_id":"DASH-BTC","changes":[["buy","0.00614345","2.69000000"]],"time":"2021-04-17T16:43:54.744285Z"}
1618677834.735546: {"type":"l2update","product_id":"SKL-BTC","changes":[["buy","0.00001294","127341.2"]],"time":"2021-04-17T16:43:54.748830Z"}
1618677834.7355719: {"type":"l2update","product_id":"SKL-BTC","changes":[["buy","0.00001294","125283.5"]],"time":"2021-04-17T16:43:54.748830Z"}
1618677834.7355862: {"type":"l2update","product_id":"SKL-BTC","changes":[["buy","0.00001292","12346.3"]],"time":"2021-04-17T16:43:54.748830Z"}
1618677834.744071: {"type":"l2update","product_id":"DASH-BTC","changes":[["sell","0.00619047","2.23600000"]],"time":"2021-04-17T16:43:54.752116Z"}
1618677834.747596: {"type":"l2update","product_id":"SKL-BTC","changes":[["buy","0.00001290","16249.2"]],"time":"2021-04-17T16:43:54.759981Z"}
1618677834.7476401: {"type":"l2update","product_id":"SKL-BTC","changes":[["buy","0.00001273","204.1"]],"time":"2021-04-17T16:43:54.759981Z"}
1618677834.7476668: {"type":"l2update","product_id":"SKL-USD","changes":[["buy","0.7880","0.0"]],"time":"2021-04-17T16:43:54.762145Z"}
1618677834.747699: {"type":"l2update","product_id":"SKL-USD","changes":[["buy","0.7715","0.0"]],"time":"2021-04-17T16:43:54.762145Z"}
1618677834.754944: {"type":"l2update","product_id":"SKL-BTC","changes":[["buy","0.00001300","6276.1"]],"time":"2021-04-17T16:43:54.770727Z"}
1618677834.7550342: {"type":"l2update","product_id":"SKL-BTC","changes":[["sell","0.00001307","6994.7"]],"time":"2021-04-17T16:43:54.770727Z"}
1618677834.7599192: {"type":"l2update","product_id":"BAND-GBP","changes":[["buy","14.6499","3.70"]],"time":"2021-04-17T16:43:54.775470Z"}
1618677834.76002: {"type":"l2update","product_id":"BAND-GBP","changes":[["buy","14.6498","15.80"]],"time":"2021-04-17T16:43:54.775470Z"}
1618677834.769116: {"type":"l2update","product_id":"DASH-BTC","changes":[["sell","0.00618985","0.00000000"]],"time":"2021-04-17T16:43:54.780521Z"}
1618677834.7895522: {"type":"l2update","product_id":"DASH-BTC","changes":[["sell","0.00618849","1.62300000"]],"time":"2021-04-17T16:43:54.801605Z"}
1618677834.796413: {"type":"l2update","product_id":"BAND-BTC","changes":[["buy","0.00033345","0.00"]],"time":"2021-04-17T16:43:54.805925Z"}
1618677834.796514: {"type":"l2update","product_id":"BAND-BTC","changes":[["buy","0.00033294","148.32"]],"time":"2021-04-17T16:43:54.805925Z"}
1618677834.796569: {"type":"l2update","product_id":"BAND-BTC","changes":[["buy","0.00033218","0.00"]],"time":"2021-04-17T16:43:54.805925Z"}
1618677834.796619: {"type":"l2update","product_id":"BAND-BTC","changes":[["buy","0.00033170","217.49"]],"time":"2021-04-17T16:43:54.805925Z"}
1618677834.796658: {"type":"l2update","product_id":"BAND-BTC","changes":[["buy","0.00033144","256.19"]],"time":"2021-04-17T16:43:54.805925Z"}
1618677834.796693: {"type":"l2update","product_id":"BAND-GBP","changes":[["buy","14.7643","0.00"]],"time":"2021-04-17T16:43:54.806482Z"}
1618677834.807907: {"type":"l2update","product_id":"BAND-BTC","changes":[["buy","0.00033232","177.96"]],"time":"2021-04-17T16:43:54.820353Z"}
1618677834.8079722: {"type":"l2update","product_id":"BAND-BTC","changes":[["buy","0.00033094","307.51"]],"time":"2021-04-17T16:43:54.820353Z"}
1618677834.808007: {"type":"l2update","product_id":"BAND-BTC","changes":[["buy","0.00032746","0.10"]],"time":"2021-04-17T16:43:54.820353Z"}
1618677834.8113348: {"type":"l2update","product_id":"DASH-BTC","changes":[["buy","0.00616934","0.00000000"]],"time":"2021-04-17T16:43:54.824367Z"}
1618677834.8325078: {"type":"l2update","product_id":"YFI-BTC","changes":[["buy","0.82570","0.000000"]],"time":"2021-04-17T16:43:54.848062Z"}
1618677834.839933: {"type":"l2update","product_id":"SKL-BTC","changes":[["sell","0.00001307","5885.6"]],"time":"2021-04-17T16:43:54.852541Z"}
1618677834.8475032: {"type":"l2update","product_id":"DASH-BTC","changes":[["sell","0.00618257","0.00000000"]],"time":"2021-04-17T16:43:54.861328Z"}
1618677834.858017: {"type":"l2update","product_id":"DASH-BTC","changes":[["sell","0.00619083","0.00000000"]],"time":"2021-04-17T16:43:54.871279Z"}
1618677834.8587258: {"type":"l2update","product_id":"YFI-BTC","changes":[["buy","0.82550","0.010464"]],"time":"2021-04-17T16:43:54.874770Z"}
1618677834.858779: {"type":"l2update","product_id":"CRV-EUR","changes":[["buy","3.2894","1150.38"]],"time":"2021-04-17T16:43:54.875575Z"}
1618677834.86559: {"type":"l2update","product_id":"SKL-BTC","changes":[["sell","0.00001307","6994.7"]],"time":"2021-04-17T16:43:54.878822Z"}
1618677834.868736: {"type":"l2update","product_id":"DASH-BTC","changes":[["sell","0.00618849","2.75100000"]],"time":"2021-04-17T16:43:54.884053Z"}
1618677834.869511: {"type":"l2update","product_id":"NMR-EUR","changes":[["buy","66.9148","1.322"]],"time":"2021-04-17T16:43:54.885656Z"}
1618677834.8695989: {"type":"l2update","product_id":"NMR-EUR","changes":[["buy","66.9148","0.000"]],"time":"2021-04-17T16:43:54.886053Z"}
1618677834.8848588: {"type":"l2update","product_id":"SKL-BTC","changes":[["buy","0.00001302","8593.0"]],"time":"2021-04-17T16:43:54.893484Z"}
1618677834.884948: {"type":"l2update","product_id":"DASH-BTC","changes":[["sell","0.00618851","0.00000000"]],"time":"2021-04-17T16:43:54.899173Z"}
