1618677826.6292522: {"type":"l2update","product_id":"DASH-BTC","changes":[["buy","0.00618953","0.29500000"]],"time":"2021-04-17T16:43:46.642767Z"}
1618677826.6335769: {"type":"l2update","product_id":"BAND-GBP","changes":[["sell","14.7999","12.53"]],"time":"2021-04-17T16:43:46.645839Z"}
1618677826.6336188: {"type":"l2update","product_id":"SKL-USD","changes":[["buy","0.7888","27413.9"]],"time":"2021-04-17T16:43:46.645697Z"}
1618677826.6377668: {"type":"l2update","product_id":"NU-GBP","changes":[["buy","0.4365","2450.000000"]],"time":"2021-04-17T16:43:46.646349Z"}
1618677826.637802: {"type":"l2update","product_id":"NU-GBP","changes":[["buy","0.4350","0.000000"]],"time":"2021-04-17T16:43:46.646349Z"}
1618677826.6378298: {"type":"l2update","product_id":"NU-GBP","changes":[["buy","0.4366","0.000000"]],"time":"2021-04-17T16:43:46.646349Z"}
1618677826.63785: {"type":"l2update","product_id":"NU-GBP","changes":[["buy","0.4365","0.000000"]],"time":"2021-04-17T16:43:46.646349Z"}
1618677826.639914: {"type":"l2update","product_id":"NU-GBP","changes":[["buy","0.4368","2220.000000"]],"time":"2021-04-17T16:43:46.653839Z"}
1618677826.6399539: {"type":"l2update","product_id":"BAND-GBP","changes":[["sell","14.8031","0.00"]],"time":"2021-04-17T16:43:46.654600Z"}
1618677826.64324: {"type":"l2update","product_id":"BAND-BTC","changes":[["sell","0.00033499","19.15"]],"time":"2021-04-17T16:43:46.657931Z"}
1618677826.646393: {"type":"l2update","product_id":"DASH-BTC","changes":[["buy","0.00618777","1.54300000"]],"time":"2021-04-17T16:43:46.661278Z"}
1618677826.6464598: {"type":"l2update","product_id":"YFI-BTC","changes":[["buy","0.82572","0.017059"]],"time":"2021-04-17T16:43:46.661364Z"}
1618677826.646501: {"type":"l2update","product_id":"BAND-GBP","changes":[["sell","14.7998","27.80"]],"time":"2021-04-17T16:43:46.661411Z"}
1618677826.650584: {"type":"l2update","product_id":"DASH-BTC","changes":[["sell","0.00622496","0.00000000"]],"time":"2021-04-17T16:43:46.665495Z"}
1618677826.654928: {"type":"l2update","product_id":"SKL-BTC","changes":[["buy","0.00001306","1006.5"]],"time":"2021-04-17T16:43:46.665510Z"}
1618677826.654977: {"type":"l2update","product_id":"BAND-BTC","changes":[["sell","0.00033539","28.00"]],"time":"2021-04-17T16:43:46.667824Z"}
1618677826.655005: {"type":"l2update","product_id":"YFI-BTC","changes":[["sell","0.83217","0.021640"]],"time":"2021-04-17T16:43:46.668500Z"}
1618677826.655027: {"type":"l2update","product_id":"YFI-BTC","changes":[["sell","0.83217","0.006700"]],"time":"2021-04-17T16:43:46.668500Z"}
1618677826.655045: {"type":"l2update","product_id":"YFI-BTC","changes":[["buy","0.82063","0.013910"]],"time":"2021-04-17T16:43:46.668500Z"}
1618677826.65989: {"type":"l2update","product_id":"YFI-BTC","changes":[["buy","0.82063","0.010980"]],"time":"2021-04-17T16:43:46.668500Z"}
1618677826.659936: {"type":"l2update","product_id":"YFI-BTC","changes":[["buy","0.82063","0.000000"]],"time":"2021-04-17T16:43:46.668500Z"}
1618677826.6599722: {"type":"l2update","product_id":"BAND-BTC","changes":[["sell","0.00033499","36.15"]],"time":"2021-04-17T16:43:46.668893Z"}
1618677826.6599958: {"type":"l2update","product_id":"BAND-BTC","changes":[["buy","0.00033349","49.42"]],"time":"2021-04-17T16:43:46.673527Z"}
1618677826.662526: {"type":"l2update","product_id":"YFI-BTC","changes":[["sell","0.83214","0.014020"]],"time":"2021-04-17T16:43:46.676147Z"}
1618677826.662579: {"type":"l2update","product_id":"YFI-BTC","changes":[["buy","0.82315","0.010450"]],"time":"2021-04-17T16:43:46.676147Z"}
1618677826.6626089: {"type":"l2update","product_id":"YFI-BTC","changes":[["sell","0.83215","0.021900"]],"time":"2021-04-17T16:43:46.676147Z"}
1618677826.6728: {"type":"l2update","product_id":"DASH-BTC","changes":[["sell","0.00621069","5.48200000"]],"time":"2021-04-17T16:43:46.686999Z"}
1618677826.6746528: {"type":"l2update","product_id":"BAND-BTC","changes":[["buy","0.00033267","0.00"]],"time":"2021-04-17T16:43:46.688940Z"}
1618677826.674706: {"type":"l2update","product_id":"BAND-GBP","changes":[["buy","14.7709","0.00"]],"time":"2021-04-17T16:43:46.690320Z"}
1618677826.676657: {"type":"l2update","product_id":"BAND-BTC","changes":[["buy","0.00033416","102.89"]],"time":"2021-04-17T16:43:46.690671Z"}
1618677826.679929: {"type":"l2update","product_id":"BAND-BTC","changes":[["buy","0.00033346","20.79"]],"time":"2021-04-17T16:43:46.695036Z"}
1618677826.683878: {"type":"l2update","product_id":"BAND-GBP","changes":[["sell","14.7941","12.61"]],"time":"2021-04-17T16:43:46.695208Z"}
1618677826.683927: {"type":"l2update","product_id":"BAND-GBP","changes":[["buy","14.7660","0.00"]],"time":"2021-04-17T16:43:46.696318Z"}
1618677826.685864: {"type":"l2update","product_id":"DASH-BTC","changes":[["sell","0.00621069","3.85900000"]],"time":"2021-04-17T16:43:46.701027Z"}
1618677826.6893299: {"type":"l2update","product_id":"SKL-BTC","changes":[["buy","0.00001296","310.0"]],"time":"2021-04-17T16:43:46.704954Z"}
1618677826.6893709: {"type":"l2update","product_id":"BAND-BTC","changes":[["buy","0.00033243","15.54"]],"time":"2021-04-17T16:43:46.705948Z"}
1618677826.689408: {"type":"l2update","product_id":"BAND-BTC","changes":[["sell","0.00033509","32.19"]],"time":"2021-04-17T16:43:46.706103Z"}
1618677826.692173: {"type":"l2update","product_id":"YFI-BTC","changes":[["buy","0.82452","0.000000"]],"time":"2021-04-17T16:43:46.708243Z"}
1618677826.693526: {"type":"l2update","product_id":"SKL-BTC","changes":[["buy","0.00001295","770.0"]],"time":"2021-04-17T16:43:46.709397Z"}
1618677826.6984022: {"type":"l2update","product_id":"SKL-USD","changes":[["buy","0.7915","0.0"]],"time":"2021-04-17T16:43:46.714112Z"}
1618677826.698451: {"type":"l2update","product_id":"BAND-GBP","changes":[["buy","14.7320","0.00"]],"time":"2021-04-17T16:43:46.714157Z"}
1618677826.7010171: {"type":"l2update","product_id":"SKL-USD","changes":[["buy","0.7857","5.0"]],"time":"2021-04-17T16:43:46.714474Z"}
1618677826.701055: {"type":"l2update","product_id":"SKL-USD","changes":[["buy","0.7866","2634.8"]],"time":"2021-04-17T16:43:46.714474Z"}
1618677826.701078: {"type":"l2update","product_id":"SKL-USD","changes":[["buy","0.7856","10.0"]],"time":"2021-04-17T16:43:46.714474Z"}
1618677826.707148: {"type":"l2update","product_id":"DASH-BTC","changes":[["sell","0.00620823","1.62300000"]],"time":"2021-04-17T16:43:46.720726Z"}
1618677826.7072: {"type":"l2update","product_id":"SKL-USD","changes":[["buy","0.7903","2390.4"]],"time":"2021-04-17T16:43:46.720697Z"}
1618677826.7094111: {"type":"l2update","product_id":"BAND-GBP","changes":[["buy","14.7060","49.51"]],"time":"2021-04-17T16:43:46.724713Z"}
1618677826.70946: {"type":"l2update","product_id":"YFI-BTC","changes":[["buy","0.82413","0.044700"]],"time":"2021-04-17T16:43:46.724736Z"}
1618677826.713623: {"type":"l2update","product_id":"CRV-EUR","changes":[["sell","3.3199","100.00"]],"time":"2021-04-17T16:43:46.729709Z"}
1618677826.713668: {"type":"l2update","product_id":"CRV-EUR","changes":[["buy","3.2697","102.50"]],"time":"2021-04-17T16:43:46.729709Z"}
1618677826.727492: {"type":"l2update","product_id":"BAND-BTC","changes":[["sell","0.00033491","18.31"]],"time":"2021-04-17T16:43:46.732236Z"}
1618677826.727548: {"type":"l2update","product_id":"DASH-BTC","changes":[["sell","0.00620491","2.50900000"]],"time":"2021-04-17T16:43:46.736204Z"}
1618677826.7275798: {"type":"l2update","product_id":"CRV-EUR","changes":[["sell","3.3201","193.50"]],"time":"2021-04-17T16:43:46.736323Z"}
1618677826.727602: {"type":"l2update","product_id":"CRV-EUR","changes":[["buy","3.2706","1.00"]],"time":"2021-04-17T16:43:46.736323Z"}
1618677826.727621: {"type":"l2update","product_id":"DASH-BTC","changes":[["buy","0.00616178","16.27700000"]],"time":"2021-04-17T16:43:46.736451Z"}
1618677826.7276402: {"type":"l2update","product_id":"DASH-BTC","changes":[["buy","0.00615249","3.89600000"]],"time":"2021-04-17T16:43:46.736451Z"}
1618677826.7276611: {"type":"l2update","product_id":"BAND-BTC","changes":[["buy","0.00033405","0.00"]],"time":"2021-04-17T16:43:46.738442Z"}
1618677826.727686: {"type":"l2update","product_id":"BAND-GBP","changes":[["sell","14.8088","0.00"]],"time":"2021-04-17T16:43:46.744169Z"}
1618677826.744829: {"type":"l2update","product_id":"BAND-BTC","changes":[["sell","0.00033672","0.00"]],"time":"2021-04-17T16:43:46.749539Z"}
1618677826.744881: {"type":"l2update","product_id":"SKL-USD","changes":[["buy","0.7856","775.0"]],"time":"2021-04-17T16:43:46.751645Z"}
1618677826.744909: {"type":"l2update","product_id":"BAND-GBP","changes":[["sell","14.7984","123.18"]],"time":"2021-04-17T16:43:46.755368Z"}
1618677826.74494: {"type":"l2update","product_id":"BAND-BTC","changes":[["buy","0.00033407","0.00"]],"time":"2021-04-17T16:43:46.756700Z"}
1618677826.7449658: {"type":"l2update","product_id":"BAND-GBP","changes":[["buy","14.7472","128.42"]],"time":"2021-04-17T16:43:46.759168Z"}
1618677826.744988: {"type":"l2update","product_id":"BAND-BTC","changes":[["sell","0.00033526","0.00"]],"time":"2021-04-17T16:43:46.760159Z"}
1618677826.751554: {"type":"l2update","product_id":"BAND-BTC","changes":[["sell","0.00033597","0.00"]],"time":"2021-04-17T16:43:46.764608Z"}
1618677826.7516081: {"type":"l2update","product_id":"DASH-BTC","changes":[["buy","0.00618704","0.00000000"]],"time":"2021-04-17T16:43:46.767362Z"}
1618677826.758983: {"type":"l2update","product_id":"BAND-BTC","changes":[["sell","0.00033626","127.50"]],"time":"2021-04-17T16:43:46.774034Z"}
1618677826.762144: {"type":"l2update","product_id":"BAND-GBP","changes":[["buy","14.7060","0.00"]],"time":"2021-04-17T16:43:46.778760Z"}
1618677826.768596: {"type":"l2update","product_id":"BAND-BTC","changes":[["sell","0.00033538","0.00"]],"time":"2021-04-17T16:43:46.784081Z"}
1618677826.782076: {"type":"l2update","product_id":"BAND-BTC","changes":[["sell","0.00033516","165.56"]],"time":"2021-04-17T16:43:46.795569Z"}
1618677826.7821288: {"type":"l2update","product_id":"BAND-GBP","changes":[["buy","14.7670","0.00"]],"time":"2021-04-17T16:43:46.795759Z"}
1618677826.78465: {"type":"l2update","product_id":"DASH-BTC","changes":[["sell","0.00621069","1.62300000"]],"time":"2021-04-17T16:43:46.799755Z"}
1618677826.787748: {"type":"l2update","product_id":"BAND-BTC","changes":[["buy","0.00033399","0.00"]],"time":"2021-04-17T16:43:46.804732Z"}
1618677826.79878: {"type":"l2update","product_id":"BAND-BTC","changes":[["buy","0.00032774","0.00"]],"time":"2021-04-17T16:43:46.813678Z"}
1618677826.802777: {"type":"l2update","product_id":"DASH-BTC","changes":[["buy","0.00618952","0.00000000"]],"time":"2021-04-17T16:43:46.814276Z"}
1618677826.802838: {"type":"l2update","product_id":"BAND-BTC","changes":[["buy","0.00033349","20.79"]],"time":"2021-04-17T16:43:46.815804Z"}
1618677826.8117602: {"type":"l2update","product_id":"DASH-BTC","changes":[["buy","0.00618040","0.00000000"]],"time":"2021-04-17T16:43:46.825350Z"}
1618677826.8118138: {"type":"l2update","product_id":"DASH-BTC","changes":[["buy","0.00617109","11.31000000"]],"time":"2021-04-17T16:43:46.825350Z"}
1618677826.811842: {"type":"l2update","product_id":"DASH-BTC","changes":[["buy","0.00616178","4.40500000"]],"time":"2021-04-17T16:43:46.825350Z"}
1618677826.811863: {"type":"l2update","product_id":"DASH-BTC","changes":[["buy","0.00615249","0.00000000"]],"time":"2021-04-17T16:43:46.825350Z"}
1618677826.811886: {"type":"l2update","product_id":"DASH-BTC","changes":[["buy","0.00614322","0.01000000"]],"time":"2021-04-17T16:43:46.825350Z"}
1618677826.826192: {"type":"l2update","product_id":"DASH-BTC","changes":[["buy","0.00616178","13.56400000"]],"time":"2021-04-17T16:43:46.841206Z"}
1618677826.826315: {"type":"l2update","product_id":"DASH-BTC","changes":[["buy","0.00615249","3.75000000"]],"time":"2021-04-17T16:43:46.841206Z"}
1618677826.830367: {"type":"l2update","product_id":"DASH-BTC","changes":[["buy","0.00614322","19.53200000"]],"time":"2021-04-17T16:43:46.841206Z"}
1618677826.83049: {"type":"l2update","product_id":"DASH-BTC","changes":[["buy","0.00613395","23.43900000"]],"time":"2021-04-17T16:43:46.841206Z"}
1618677826.83054: {"type":"l2update","product_id":"DASH-BTC","changes":[["buy","0.00606951","0.01000000"]],"time":"2021-04-17T16:43:46.841206Z"}
1618677826.8305979: {"type":"l2update","product_id":"SKL-USD","changes":[["buy","0.7903","1044.7"]],"time":"2021-04-17T16:43:46.842557Z"}
1618677826.836674: {"type":"l2update","product_id":"DASH-BTC","changes":[["buy","0.00618490","32.84700000"]],"time":"2021-04-17T16:43:46.852277Z"}
1618677826.838763: {"type":"l2update","product_id":"BAND-BTC","changes":[["sell","0.00033536","0.00"]],"time":"2021-04-17T16:43:46.855325Z"}
1618677826.83887: {"type":"l2update","product_id":"DASH-BTC","changes":[["sell","0.00621070","0.00000000"]],"time":"2021-04-17T16:43:46.855584Z"}
1618677826.838937: {"type":"l2update","product_id":"DASH-BTC","changes":[["sell","0.00620823","3.85900000"]],"time":"2021-04-17T16:43:46.855907Z"}
1618677826.848295: {"type":"l2update","product_id":"BAND-BTC","changes":[["buy","0.00033346","49.42"]],"time":"2021-04-17T16:43:46.864008Z"}
1618677826.852567: {"type":"l2update","product_id":"SKL-BTC","changes":[["sell","0.00001310","10601.7"]],"time":"2021-04-17T16:43:46.865703Z"}
1618677826.876108: {"type":"l2update","product_id":"YFI-BTC","changes":[["buy","0.82462","0.000000"]],"time":"2021-04-17T16:43:46.868419Z"}
1618677826.876215: {"type":"l2update","product_id":"YFI-BTC","changes":[["sell","0.83027","0.000000"]],"time":"2021-04-17T16:43:46.869287Z"}
1618677826.8762822: {"type":"l2update","product_id":"SKL-USD","changes":[["buy","0.7904","2539.9"]],"time":"2021-04-17T16:43:46.871929Z"}
1618677826.87633: {"type":"l2update","product_id":"BAND-BTC","changes":[["buy","0.00033375","39.00"]],"time":"2021-04-17T16:43:46.872016Z"}
1618677826.87638: {"type":"l2update","product_id":"BAND-GBP","changes":[["buy","14.6487","0.00"]],"time":"2021-04-17T16:43:46.874821Z"}
1618677826.876429: {"type":"l2update","product_id":"BAND-GBP","changes":[["buy","14.6488","0.00"]],"time":"2021-04-17T16:43:46.874821Z"}
1618677826.87647: {"type":"l2update","product_id":"BAND-BTC","changes":[["sell","0.00033561","39.00"]],"time":"2021-04-17T16:43:46.882991Z"}
1618677826.8765152: {"type":"l2update","product_id":"BAND-GBP","changes":[["buy","14.6492","13.50"]],"time":"2021-04-17T16:43:46.883214Z"}
1618677826.876555: {"type":"l2update","product_id":"BAND-GBP","changes":[["buy","14.6491","7.30"]],"time":"2021-04-17T16:43:46.883214Z"}
1618677826.876589: {"type":"l2update","product_id":"DASH-BTC","changes":[["sell","0.00620689","2.63900000"]],"time":"2021-04-17T16:43:46.886269Z"}
1618677826.876631: {"type":"l2update","product_id":"YFI-BTC","changes":[["sell","0.82976","0.035300"]],"time":"2021-04-17T16:43:46.889909Z"}
1618677826.881361: {"type":"l2update","product_id":"BAND-BTC","changes":[["sell","0.00033509","0.00"]],"time":"2021-04-17T16:43:46.894450Z"}
1618677826.881462: {"type":"l2update","product_id":"SKL-USD","changes":[["buy","0.7904","1345.7"]],"time":"2021-04-17T16:43:46.894148Z"}
1618677826.884931: {"type":"l2update","product_id":"DASH-BTC","changes":[["sell","0.00622497","6.01700000"]],"time":"2021-04-17T16:43:46.896497Z"}
1618677826.888893: {"type":"l2update","product_id":"BAND-BTC","changes":[["sell","0.00033506","36.74"]],"time":"2021-04-17T16:43:46.901026Z"}
1618677826.888993: {"type":"l2update","product_id":"SKL-BTC","changes":[["buy","0.00001306","0.0"]],"time":"2021-04-17T16:43:46.901716Z"}
1618677826.889622: {"type":"l2update","product_id":"DASH-BTC","changes":[["buy","0.00618300","2.65100000"]],"time":"2021-04-17T16:43:46.904570Z"}
1618677826.892046: {"type":"l2update","product_id":"SKL-BTC","changes":[["sell","0.00001309","7321.6"]],"time":"2021-04-17T16:43:46.907332Z"}
1618677826.892141: {"type":"l2update","product_id":"SKL-USD","changes":[["buy","0.7905","0.0"]],"time":"2021-04-17T16:43:46.907444Z"}
1618677826.892216: {"type":"l2update","product_id":"SKL-USD","changes":[["buy","0.7903","2390.4"]],"time":"2021-04-17T16:43:46.908414Z"}
1618677826.9013062: {"type":"l2update","product_id":"SKL-USD","changes":[["buy","0.7905","1194.0"]],"time":"2021-04-17T16:43:46.915920Z"}
1618677826.901407: {"type":"l2update","product_id":"SKL-USD","changes":[["buy","0.7888","1900.0"]],"time":"2021-04-17T16:43:46.917512Z"}
1618677826.9047732: {"type":"l2update","product_id":"DASH-BTC","changes":[["buy","0.00617811","0.00000000"]],"time":"2021-04-17T16:43:46.921581Z"}
1618677826.923987: {"type":"l2update","product_id":"BAND-GBP","changes":[["sell","14.7998","0.00"]],"time":"2021-04-17T16:43:46.928480Z"}
1618677826.9240599: {"type":"l2update","product_id":"BAND-GBP","changes":[["sell","14.7940","27.80"]],"time":"2021-04-17T16:43:46.934487Z"}
1618677826.9241018: {"type":"l2update","product_id":"SKL-USD","changes":[["buy","0.7904","0.0"]],"time":"2021-04-17T16:43:46.937590Z"}
1618677826.924144: {"type":"l2update","product_id":"SKL-USD","changes":[["buy","0.7903","1044.7"]],"time":"2021-04-17T16:43:46.937680Z"}
1618677826.92417: {"type":"l2update","product_id":"DASH-BTC","changes":[["buy","0.00617110","1.88000000"]],"time":"2021-04-17T16:43:46.938045Z"}
1618677826.9241998: {"type":"l2update","product_id":"SKL-USD","changes":[["buy","0.7888","27413.9"]],"time":"2021-04-17T16:43:46.938365Z"}
1618677826.924222: {"type":"l2update","product_id":"DASH-BTC","changes":[["sell","0.00620699","14.63200000"]],"time":"2021-04-17T16:43:46.938395Z"}
1618677826.929124: {"type":"l2update","product_id":"SKL-USD","changes":[["buy","0.7906","0.0"]],"time":"2021-04-17T16:43:46.946480Z"}
1618677826.931573: {"type":"l2update","product_id":"SKL-USD","changes":[["sell","0.8080","12005.0"]],"time":"2021-04-17T16:43:46.948112Z"}
1618677826.9316201: {"type":"l2update","product_id":"SKL-USD","changes":[["buy","0.7855","250.0"]],"time":"2021-04-17T16:43:46.948127Z"}
1618677826.933717: {"type":"l2update","product_id":"BAND-GBP","changes":[["buy","14.7787","0.00"]],"time":"2021-04-17T16:43:46.949884Z"}
1618677826.938926: {"type":"l2update","product_id":"SKL-USD","changes":[["buy","0.7906","2629.5"]],"time":"2021-04-17T16:43:46.952475Z"}
1618677826.938987: {"type":"l2update","product_id":"SKL-USD","changes":[["buy","0.7854","11531.5"]],"time":"2021-04-17T16:43:46.952568Z"}
1618677826.939986: {"type":"l2update","product_id":"DASH-BTC","changes":[["sell","0.00621376","10.32200000"]],"time":"2021-04-17T16:43:46.956133Z"}
1618677826.945428: {"type":"l2update","product_id":"BAND-GBP","changes":[["buy","14.7644","27.52"]],"time":"2021-04-17T16:43:46.959955Z"}
1618677826.9534621: {"type":"l2update","product_id":"SKL-USD","changes":[["sell","0.8082","6005.0"]],"time":"2021-04-17T16:43:46.963659Z"}
1618677826.95352: {"type":"l2update","product_id":"BAND-BTC","changes":[["buy","0.00033416","0.00"]],"time":"2021-04-17T16:43:46.966430Z"}
1618677826.953567: {"type":"l2update","product_id":"SKL-USD","changes":[["buy","0.7905","2060.4"]],"time":"2021-04-17T16:43:46.966985Z"}
1618677826.961029: {"type":"l2update","product_id":"BAND-BTC","changes":[["buy","0.00033255","0.00"]],"time":"2021-04-17T16:43:46.970390Z"}
1618677826.9610949: {"type":"l2update","product_id":"SKL-USD","changes":[["buy","0.7904","1345.7"]],"time":"2021-04-17T16:43:46.970881Z"}
1618677826.961136: {"type":"l2update","product_id":"BAND-BTC","changes":[["buy","0.00033342","0.00"]],"time":"2021-04-17T16:43:46.973844Z"}
1618677826.969492: {"type":"l2update","product_id":"DASH-BTC","changes":[["buy","0.00618541","19.23900000"]],"time":"2021-04-17T16:43:46.979376Z"}
1618677826.969582: {"type":"l2update","product_id":"SKL-USD","changes":[["buy","0.7904","0.0"]],"time":"2021-04-17T16:43:46.980438Z"}
1618677826.969654: {"type":"l2update","product_id":"DASH-BTC","changes":[["buy","0.00619214","0.00000000"]],"time":"2021-04-17T16:43:46.983195Z"}
1618677826.970992: {"type":"l2update","product_id":"SKL-BTC","changes":[["buy","0.00001305","1116.5"]],"time":"2021-04-17T16:43:46.986720Z"}
1618677826.9710479: {"type":"l2update","product_id":"DASH-BTC","changes":[["sell","0.00620498","2.64400000"]],"time":"2021-04-17T16:43:46.986821Z"}
1618677826.972082: {"type":"l2update","product_id":"BAND-GBP","changes":[["buy","14.7642","0.00"]],"time":"2021-04-17T16:43:46.986993Z"}
1618677826.975528: {"type":"l2update","product_id":"BAND-BTC","changes":[["buy","0.00033448","0.00"]],"time":"2021-04-17T16:43:46.992493Z"}
1618677826.986471: {"type":"l2update","product_id":"BAND-GBP","changes":[["sell","14.8072","0.00"]],"time":"2021-04-17T16:43:46.998801Z"}
1618677826.9865348: {"type":"l2update","product_id":"SKL-USD","changes":[["buy","0.7903","2390.4"]],"time":"2021-04-17T16:43:47.002011Z"}
1618677826.988828: {"type":"l2update","product_id":"DASH-BTC","changes":[["buy","0.00618777","2.66300000"]],"time":"2021-04-17T16:43:47.005432Z"}
1618677826.991848: {"type":"l2update","product_id":"BAND-BTC","changes":[["buy","0.00033376","339.81"]],"time":"2021-04-17T16:43:47.005668Z"}
1618677826.9919062: {"type":"l2update","product_id":"DASH-BTC","changes":[["buy","0.00618953","0.00000000"]],"time":"2021-04-17T16:43:47.008321Z"}
1618677826.996168: {"type":"l2update","product_id":"DASH-BTC","changes":[["buy","0.00618777","1.12000000"]],"time":"2021-04-17T16:43:47.010703Z"}
1618677827.001386: {"type":"l2update","product_id":"BAND-GBP","changes":[["buy","14.7473","36.00"]],"time":"2021-04-17T16:43:47.016930Z"}
1618677827.004558: {"type":"l2update","product_id":"SKL-USD","changes":[["buy","0.7916","0.0"]],"time":"2021-04-17T16:43:47.020657Z"}
1618677827.0184681: {"type":"l2update","product_id":"DASH-BTC","changes":[["sell","0.00864891","2.16000000"]],"time":"2021-04-17T16:43:47.033932Z"}
1618677827.0281658: {"type":"l2update","product_id":"DASH-BTC","changes":[["buy","0.00619287","0.29500000"]],"time":"2021-04-17T16:43:47.039300Z"}
1618677827.028233: {"type":"l2update","product_id":"DASH-BTC","changes":[["sell","0.00864891","4.80000000"]],"time":"2021-04-17T16:43:47.039397Z"}
1618677827.0282729: {"type":"l2update","product_id":"SKL-USD","changes":[["buy","0.7903","1044.7"]],"time":"2021-04-17T16:43:47.043297Z"}
1618677827.0283022: {"type":"l2update","product_id":"DASH-BTC","changes":[["sell","0.00620823","2.23600000"]],"time":"2021-04-17T16:43:47.044111Z"}
1618677827.03459: {"type":"l2update","product_id":"DASH-BTC","changes":[["buy","0.00619284","0.00000000"]],"time":"2021-04-17T16:43:47.049578Z"}
1618677827.034656: {"type":"l2update","product_id":"BAND-BTC","changes":[["sell","0.00033486","32.19"]],"time":"2021-04-17T16:43:47.050358Z"}
1618677827.034701: {"type":"l2update","product_id":"SKL-USD","changes":[["buy","0.7888","1900.0"]],"time":"2021-04-17T16:43:47.050613Z"}
1618677827.034729: {"type":"l2update","product_id":"DASH-BTC","changes":[["sell","0.00620368","0.00000000"]],"time":"2021-04-17T16:43:47.051935Z"}
1618677827.038917: {"type":"l2update","product_id":"DASH-BTC","changes":[["buy","0.00619287","1.83700000"]],"time":"2021-04-17T16:43:47.054190Z"}
1618677827.038978: {"type":"l2update","product_id":"DASH-BTC","changes":[["buy","0.00618776","0.00000000"]],"time":"2021-04-17T16:43:47.055672Z"}
1618677827.039016: {"type":"l2update","product_id":"DASH-BTC","changes":[["buy","0.00618541","13.67800000"]],"time":"2021-04-17T16:43:47.055872Z"}
1618677827.0475788: {"type":"l2update","product_id":"DASH-BTC","changes":[["buy","0.00618542","10.52200000"]],"time":"2021-04-17T16:43:47.061397Z"}
1618677827.048686: {"type":"l2update","product_id":"DASH-BTC","changes":[["buy","0.00618300","0.00000000"]],"time":"2021-04-17T16:43:47.063673Z"}
1618677827.048738: {"type":"l2update","product_id":"SKL-USD","changes":[["buy","0.7904","1345.7"]],"time":"2021-04-17T16:43:47.065035Z"}
1618677827.059756: {"type":"l2update","product_id":"DASH-BTC","changes":[["sell","0.00620490","1.62300000"]],"time":"2021-04-17T16:43:47.068418Z"}
1618677827.0648692: {"type":"l2update","product_id":"BAND-BTC","changes":[["buy","0.00032763","57.62"]],"time":"2021-04-17T16:43:47.072483Z"}
1618677827.064936: {"type":"l2update","product_id":"SKL-USD","changes":[["buy","0.7867","25513.9"]],"time":"2021-04-17T16:43:47.072510Z"}
1618677827.069268: {"type":"l2update","product_id":"BAND-GBP","changes":[["sell","14.8033","0.00"]],"time":"2021-04-17T16:43:47.083387Z"}
1618677827.080958: {"type":"l2update","product_id":"SKL-USD","changes":[["buy","0.7904","0.0"]],"time":"2021-04-17T16:43:47.091436Z"}
1618677827.081027: {"type":"l2update","product_id":"DASH-BTC","changes":[["sell","0.00620367","0.00000000"]],"time":"2021-04-17T16:43:47.094814Z"}
1618677827.086266: {"type":"l2update","product_id":"BAND-BTC","changes":[["buy","0.00033449","0.00"]],"time":"2021-04-17T16:43:47.099541Z"}
1618677827.086334: {"type":"l2update","product_id":"DASH-BTC","changes":[["sell","0.00620366","2.57200000"]],"time":"2021-04-17T16:43:47.102063Z"}
1618677827.090496: {"type":"l2update","product_id":"SKL-USD","changes":[["sell","0.8079","6005.0"]],"time":"2021-04-17T16:43:47.105279Z"}
1618677827.0958238: {"type":"l2update","product_id":"YFI-BTC","changes":[["buy","0.82467","0.020846"]],"time":"2021-04-17T16:43:47.108857Z"}
1618677827.0958889: {"type":"l2update","product_id":"SKL-USD","changes":[["buy","0.7903","2390.4"]],"time":"2021-04-17T16:43:47.108922Z"}
1618677827.095923: {"type":"l2update","product_id":"BAND-BTC","changes":[["sell","0.00033516","147.18"]],"time":"2021-04-17T16:43:47.110547Z"}
1618677827.1023848: {"type":"l2update","product_id":"BAND-BTC","changes":[["buy","0.00033434","29.61"]],"time":"2021-04-17T16:43:47.116585Z"}
1618677827.105901: {"type":"l2update","product_id":"DASH-BTC","changes":[["sell","0.00620490","2.44800000"]],"time":"2021-04-17T16:43:47.119986Z"}
1618677827.1147258: {"type":"l2update","product_id":"YFI-BTC","changes":[["buy","0.82529","0.000000"]],"time":"2021-04-17T16:43:47.128087Z"}
1618677827.11675: {"type":"l2update","product_id":"YFI-BTC","changes":[["buy","0.82512","0.030000"]],"time":"2021-04-17T16:43:47.131546Z"}
1618677827.12529: {"type":"l2update","product_id":"DASH-BTC","changes":[["buy","0.00618490","0.00000000"]],"time":"2021-04-17T16:43:47.138055Z"}
1618677827.134913: {"type":"l2update","product_id":"DASH-BTC","changes":[["sell","0.00620491","0.00000000"]],"time":"2021-04-17T16:43:47.143369Z"}
1618677827.134979: {"type":"l2update","product_id":"BAND-BTC","changes":[["buy","0.00033435","36.75"]],"time":"2021-04-17T16:43:47.146073Z"}
1618677827.13502: {"type":"l2update","product_id":"YFI-BTC","changes":[["buy","0.82409","0.000000"]],"time":"2021-04-17T16:43:47.148846Z"}
1618677827.140713: {"type":"l2update","product_id":"DASH-BTC","changes":[["sell","0.00620179","2.50900000"]],"time":"2021-04-17T16:43:47.153433Z"}
1618677827.140773: {"type":"l2update","product_id":"BAND-BTC","changes":[["buy","0.00033434","0.00"]],"time":"2021-04-17T16:43:47.153565Z"}
1618677827.1417332: {"type":"l2update","product_id":"YFI-BTC","changes":[["buy","0.82414","0.053010"]],"time":"2021-04-17T16:43:47.157611Z"}
1618677827.147157: {"type":"l2update","product_id":"BAND-BTC","changes":[["buy","0.00033436","29.61"]],"time":"2021-04-17T16:43:47.161276Z"}
1618677827.1542568: {"type":"l2update","product_id":"DASH-BTC","changes":[["sell","0.00622500","0.00000000"]],"time":"2021-04-17T16:43:47.168132Z"}
1618677827.1543229: {"type":"l2update","product_id":"DASH-BTC","changes":[["sell","0.00621225","0.00000000"]],"time":"2021-04-17T16:43:47.169849Z"}
1618677827.165587: {"type":"l2update","product_id":"SKL-BTC","changes":[["sell","0.00001310","11359.3"]],"time":"2021-04-17T16:43:47.176205Z"}
1618677827.165644: {"type":"l2update","product_id":"BAND-BTC","changes":[["buy","0.00033346","20.79"]],"time":"2021-04-17T16:43:47.181571Z"}
1618677827.16957: {"type":"l2update","product_id":"DASH-BTC","changes":[["sell","0.00621854","5.72000000"]],"time":"2021-04-17T16:43:47.183186Z"}
1618677827.177832: {"type":"l2update","product_id":"DASH-BTC","changes":[["sell","0.00620823","0.00000000"]],"time":"2021-04-17T16:43:47.188083Z"}
1618677827.186334: {"type":"l2update","product_id":"BAND-BTC","changes":[["buy","0.00033323","28.65"]],"time":"2021-04-17T16:43:47.202064Z"}
1618677827.1902761: {"type":"l2update","product_id":"DASH-BTC","changes":[["sell","0.00619848","2.50900000"]],"time":"2021-04-17T16:43:47.206759Z"}
1618677827.193799: {"type":"l2update","product_id":"DASH-BTC","changes":[["sell","0.00620688","2.23600000"]],"time":"2021-04-17T16:43:47.209300Z"}
1618677827.206591: {"type":"l2update","product_id":"DASH-BTC","changes":[["sell","0.00620622","1.20000000"]],"time":"2021-04-17T16:43:47.220746Z"}
1618677827.2066538: {"type":"l2update","product_id":"DASH-BTC","changes":[["buy","0.00618256","32.84700000"]],"time":"2021-04-17T16:43:47.220777Z"}
1618677827.216208: {"type":"l2update","product_id":"DASH-BTC","changes":[["sell","0.00620972","0.00000000"]],"time":"2021-04-17T16:43:47.231954Z"}
1618677827.2270238: {"type":"l2update","product_id":"YFI-BTC","changes":[["sell","0.83216","0.012580"]],"time":"2021-04-17T16:43:47.239992Z"}
1618677827.2270799: {"type":"l2update","product_id":"YFI-BTC","changes":[["buy","0.82314","0.009940"]],"time":"2021-04-17T16:43:47.239992Z"}
1618677827.23887: {"type":"l2update","product_id":"BAND-BTC","changes":[["buy","0.00033410","102.92"]],"time":"2021-04-17T16:43:47.246605Z"}
1618677827.2389371: {"type":"l2update","product_id":"DASH-BTC","changes":[["sell","0.00624604","0.01000000"]],"time":"2021-04-17T16:43:47.247810Z"}
1618677827.2390149: {"type":"l2update","product_id":"DASH-BTC","changes":[["sell","0.00631236","0.00000000"]],"time":"2021-04-17T16:43:47.247810Z"}
1618677827.2390678: {"type":"l2update","product_id":"DASH-BTC","changes":[["buy","0.00616178","4.40500000"]],"time":"2021-04-17T16:43:47.247810Z"}
1618677827.239098: {"type":"l2update","product_id":"DASH-BTC","changes":[["buy","0.00616178","0.00000000"]],"time":"2021-04-17T16:43:47.247810Z"}
1618677827.239129: {"type":"l2update","product_id":"DASH-BTC","changes":[["buy","0.00615249","0.00000000"]],"time":"2021-04-17T16:43:47.247810Z"}
1618677827.239156: {"type":"l2update","product_id":"DASH-BTC","changes":[["buy","0.00613395","0.01000000"]],"time":"2021-04-17T16:43:47.247810Z"}
1618677827.239179: {"type":"l2update","product_id":"DASH-BTC","changes":[["buy","0.00606951","0.00000000"]],"time":"2021-04-17T16:43:47.247810Z"}
1618677827.2392051: {"type":"l2update","product_id":"SKL-USD","changes":[["sell","0.8082","5.0"]],"time":"2021-04-17T16:43:47.250374Z"}
1618677827.239477: {"type":"l2update","product_id":"YFI-BTC","changes":[["sell","0.83213","0.006960"]],"time":"2021-04-17T16:43:47.254186Z"}
1618677827.239529: {"type":"l2update","product_id":"YFI-BTC","changes":[["buy","0.82316","0.003070"]],"time":"2021-04-17T16:43:47.254186Z"}
1618677827.2553349: {"type":"l2update","product_id":"DASH-BTC","changes":[["sell","0.00620699","0.00000000"]],"time":"2021-04-17T16:43:47.257442Z"}
1618677827.2553868: {"type":"l2update","product_id":"SKL-USD","changes":[["buy","0.7905","866.4"]],"time":"2021-04-17T16:43:47.261072Z"}
1618677827.2554162: {"type":"l2update","product_id":"DASH-BTC","changes":[["buy","0.00617544","11.30500000"]],"time":"2021-04-17T16:43:47.262228Z"}
1618677827.2554429: {"type":"l2update","product_id":"DASH-BTC","changes":[["buy","0.00617109","13.56600000"]],"time":"2021-04-17T16:43:47.262228Z"}
1618677827.255462: {"type":"l2update","product_id":"DASH-BTC","changes":[["buy","0.00616178","4.27800000"]],"time":"2021-04-17T16:43:47.262228Z"}
1618677827.255483: {"type":"l2update","product_id":"DASH-BTC","changes":[["buy","0.00615249","1.32500000"]],"time":"2021-04-17T16:43:47.262228Z"}
1618677827.2555032: {"type":"l2update","product_id":"DASH-BTC","changes":[["buy","0.00614322","23.44200000"]],"time":"2021-04-17T16:43:47.262228Z"}
1618677827.25552: {"type":"l2update","product_id":"DASH-BTC","changes":[["sell","0.00621783","1.06000000"]],"time":"2021-04-17T16:43:47.262228Z"}
1618677827.255541: {"type":"l2update","product_id":"DASH-BTC","changes":[["buy","0.00619286","0.00000000"]],"time":"2021-04-17T16:43:47.262418Z"}
1618677827.255563: {"type":"l2update","product_id":"BAND-BTC","changes":[["buy","0.00033294","0.00"]],"time":"2021-04-17T16:43:47.266352Z"}
1618677827.267414: {"type":"l2update","product_id":"BAND-BTC","changes":[["buy","0.00033170","566.04"]],"time":"2021-04-17T16:43:47.273791Z"}
1618677827.285119: {"type":"l2update","product_id":"SKL-USD","changes":[["buy","0.7904","1194.2"]],"time":"2021-04-17T16:43:47.296162Z"}
1618677827.285255: {"type":"l2update","product_id":"DASH-BTC","changes":[["buy","0.00618778","2.57300000"]],"time":"2021-04-17T16:43:47.299655Z"}
1618677827.2913358: {"type":"l2update","product_id":"SKL-USD","changes":[["buy","0.7867","0.0"]],"time":"2021-04-17T16:43:47.303278Z"}
1618677827.291432: {"type":"l2update","product_id":"BAND-BTC","changes":[["buy","0.00033346","0.00"]],"time":"2021-04-17T16:43:47.306238Z"}
1618677827.291476: {"type":"l2update","product_id":"BAND-BTC","changes":[["sell","0.00033486","0.00"]],"time":"2021-04-17T16:43:47.307013Z"}
1618677827.295647: {"type":"l2update","product_id":"DASH-BTC","changes":[["buy","0.00616178","16.28300000"]],"time":"2021-04-17T16:43:47.311232Z"}
1618677827.295707: {"type":"l2update","product_id":"DASH-BTC","changes":[["buy","0.00615249","4.45200000"]],"time":"2021-04-17T16:43:47.311232Z"}
1618677827.3043442: {"type":"l2update","product_id":"DASH-BTC","changes":[["sell","0.00621069","0.00000000"]],"time":"2021-04-17T16:43:47.317868Z"}
1618677827.3087208: {"type":"l2update","product_id":"SKL-USD","changes":[["buy","0.7868","25513.9"]],"time":"2021-04-17T16:43:47.322278Z"}
1618677827.308871: {"type":"l2update","product_id":"SKL-USD","changes":[["buy","0.7905","0.0"]],"time":"2021-04-17T16:43:47.323600Z"}
1618677827.3092842: {"type":"l2update","product_id":"BAND-BTC","changes":[["buy","0.00033171","20.90"]],"time":"2021-04-17T16:43:47.326648Z"}
1618677827.320557: {"type":"l2update","product_id":"SKL-USD","changes":[["buy","0.7910","880.0"]],"time":"2021-04-17T16:43:47.333256Z"}
1618677827.324678: {"type":"l2update","product_id":"BAND-BTC","changes":[["buy","0.00033360","102.87"]],"time":"2021-04-17T16:43:47.337293Z"}
1618677827.324783: {"type":"l2update","product_id":"DASH-BTC","changes":[["sell","0.00621209","1.62300000"]],"time":"2021-04-17T16:43:47.337459Z"}
1618677827.3248482: {"type":"l2update","product_id":"DASH-BTC","changes":[["buy","0.00618309","1.39100000"]],"time":"2021-04-17T16:43:47.337506Z"}
1618677827.3300831: {"type":"l2update","product_id":"DASH-BTC","changes":[["sell","0.00620526","14.63200000"]],"time":"2021-04-17T16:43:47.340894Z"}
1618677827.330183: {"type":"l2update","product_id":"DASH-BTC","changes":[["buy","0.00618271","5.56200000"]],"time":"2021-04-17T16:43:47.340932Z"}
1618677827.330243: {"type":"l2update","product_id":"SKL-USD","changes":[["buy","0.7910","1869.7"]],"time":"2021-04-17T16:43:47.341091Z"}
1618677827.330959: {"type":"l2update","product_id":"DASH-BTC","changes":[["sell","0.00620179","0.00000000"]],"time":"2021-04-17T16:43:47.344799Z"}
1618677827.334207: {"type":"l2update","product_id":"DASH-BTC","changes":[["buy","0.00617544","0.00000000"]],"time":"2021-04-17T16:43:47.349626Z"}
1618677827.3560882: {"type":"l2update","product_id":"DASH-BTC","changes":[["buy","0.00619287","1.54200000"]],"time":"2021-04-17T16:43:47.370572Z"}
1618677827.3606029: {"type":"l2update","product_id":"DASH-BTC","changes":[["buy","0.00619287","0.00000000"]],"time":"2021-04-17T16:43:47.374964Z"}
1618677827.367109: {"type":"l2update","product_id":"DASH-BTC","changes":[["sell","0.00621592","0.00000000"]],"time":"2021-04-17T16:43:47.381930Z"}
1618677827.367212: {"type":"l2update","product_id":"DASH-BTC","changes":[["buy","0.00618760","0.00000000"]],"time":"2021-04-17T16:43:47.381943Z"}
1618677827.367868: {"type":"l2update","product_id":"SKL-USD","changes":[["buy","0.7907","866.2"]],"time":"2021-04-17T16:43:47.384817Z"}
1618677827.373541: {"type":"l2update","product_id":"DASH-BTC","changes":[["sell","0.00620304","1.20000000"]],"time":"2021-04-17T16:43:47.388180Z"}
1618677827.373646: {"type":"l2update","product_id":"SKL-GBP","changes":[["buy","0.5734","0.0"]],"time":"2021-04-17T16:43:47.388423Z"}
1618677827.378732: {"type":"l2update","product_id":"DASH-BTC","changes":[["buy","0.00618779","0.29500000"]],"time":"2021-04-17T16:43:47.391779Z"}
1618677827.390578: {"type":"l2update","product_id":"DASH-BTC","changes":[["buy","0.00618779","1.83800000"]],"time":"2021-04-17T16:43:47.402850Z"}
1618677827.390702: {"type":"l2update","product_id":"DASH-BTC","changes":[["sell","0.00620824","0.00000000"]],"time":"2021-04-17T16:43:47.402910Z"}
1618677827.3916092: {"type":"l2update","product_id":"DASH-BTC","changes":[["sell","0.00620490","0.82500000"]],"time":"2021-04-17T16:43:47.408045Z"}
1618677827.3949041: {"type":"l2update","product_id":"SKL-GBP","changes":[["buy","0.5725","1735.0"]],"time":"2021-04-17T16:43:47.409978Z"}
1618677827.409125: {"type":"l2update","product_id":"SKL-BTC","changes":[["sell","0.00001604","0.0"]],"time":"2021-04-17T16:43:47.423067Z"}
1618677827.4092648: {"type":"l2update","product_id":"DASH-BTC","changes":[["buy","0.00618256","0.00000000"]],"time":"2021-04-17T16:43:47.424233Z"}
1618677827.409333: {"type":"l2update","product_id":"SKL-USD","changes":[["buy","0.7868","0.0"]],"time":"2021-04-17T16:43:47.424734Z"}
1618677827.414878: {"type":"l2update","product_id":"DASH-BTC","changes":[["sell","0.00620497","1.62300000"]],"time":"2021-04-17T16:43:47.428488Z"}
1618677827.415019: {"type":"l2update","product_id":"SKL-BTC","changes":[["sell","0.00001314","7030.6"]],"time":"2021-04-17T16:43:47.428512Z"}
1618677827.4175858: {"type":"l2update","product_id":"DASH-BTC","changes":[["sell","0.00620490","0.00000000"]],"time":"2021-04-17T16:43:47.432506Z"}
1618677827.430031: {"type":"l2update","product_id":"SKL-USD","changes":[["buy","0.7888","27413.9"]],"time":"2021-04-17T16:43:47.443364Z"}
1618677827.430111: {"type":"l2update","product_id":"SKL-BTC","changes":[["sell","0.00001306","1109.1"]],"time":"2021-04-17T16:43:47.443614Z"}
1618677827.430159: {"type":"l2update","product_id":"NU-GBP","changes":[["sell","0.4397","7078.380151"]],"time":"2021-04-17T16:43:47.443624Z"}
1618677827.4373288: {"type":"l2update","product_id":"SKL-USD","changes":[["sell","0.7922","1017.5"]],"time":"2021-04-17T16:43:47.450628Z"}
1618677827.4420512: {"type":"l2update","product_id":"NU-GBP","changes":[["buy","0.4362","0.000000"]],"time":"2021-04-17T16:43:47.452684Z"}
1618677827.4421859: {"type":"l2update","product_id":"SKL-GBP","changes":[["sell","0.5770","1008.2"]],"time":"2021-04-17T16:43:47.454255Z"}
1618677827.442256: {"type":"l2update","product_id":"DASH-BTC","changes":[["sell","0.00619847","0.82500000"]],"time":"2021-04-17T16:43:47.454482Z"}
1618677827.4451: {"type":"l2update","product_id":"SKL-GBP","changes":[["buy","0.5738","275.0"]],"time":"2021-04-17T16:43:47.461432Z"}
1618677827.4474208: {"type":"l2update","product_id":"DASH-BTC","changes":[["sell","0.00864891","2.93000000"]],"time":"2021-04-17T16:43:47.462241Z"}
1618677827.45529: {"type":"l2update","product_id":"DASH-BTC","changes":[["sell","0.00864891","4.80000000"]],"time":"2021-04-17T16:43:47.469929Z"}
1618677827.455411: {"type":"l2update","product_id":"SKL-BTC","changes":[["buy","0.00001303","10537.8"]],"time":"2021-04-17T16:43:47.472393Z"}
1618677827.462222: {"type":"l2update","product_id":"SKL-BTC","changes":[["buy","0.00001302","5159.0"]],"time":"2021-04-17T16:43:47.476667Z"}
1618677827.462338: {"type":"l2update","product_id":"SKL-USD","changes":[["buy","0.7909","80.2"]],"time":"2021-04-17T16:43:47.477119Z"}
1618677827.46239: {"type":"l2update","product_id":"SKL-BTC","changes":[["buy","0.00001305","1006.5"]],"time":"2021-04-17T16:43:47.477191Z"}
1618677827.466698: {"type":"l2update","product_id":"SKL-BTC","changes":[["buy","0.00001302","4493.3"]],"time":"2021-04-17T16:43:47.479552Z"}
1618677827.466816: {"type":"l2update","product_id":"SKL-GBP","changes":[["buy","0.5747","1266.9"]],"time":"2021-04-17T16:43:47.479474Z"}
1618677827.4709508: {"type":"l2update","product_id":"CRV-EUR","changes":[["buy","3.2830","256.63"]],"time":"2021-04-17T16:43:47.480262Z"}
1618677827.471085: {"type":"l2update","product_id":"SKL-BTC","changes":[["sell","0.00001310","10601.7"]],"time":"2021-04-17T16:43:47.484280Z"}
1618677827.477144: {"type":"l2update","product_id":"CRV-EUR","changes":[["buy","3.2877","1153.42"]],"time":"2021-04-17T16:43:47.489825Z"}
1618677827.477261: {"type":"l2update","product_id":"CRV-EUR","changes":[["sell","3.3075","254.73"]],"time":"2021-04-17T16:43:47.490824Z"}
1618677827.479637: {"type":"l2update","product_id":"CRV-EUR","changes":[["buy","3.2878","0.00"]],"time":"2021-04-17T16:43:47.495896Z"}
1618677827.4832268: {"type":"l2update","product_id":"DASH-BTC","changes":[["sell","0.00619848","0.00000000"]],"time":"2021-04-17T16:43:47.499275Z"}
1618677827.4997709: {"type":"l2update","product_id":"SKL-BTC","changes":[["buy","0.00001302","5155.8"]],"time":"2021-04-17T16:43:47.501690Z"}
1618677827.499858: {"type":"l2update","product_id":"SKL-USD","changes":[["buy","0.7886","0.0"]],"time":"2021-04-17T16:43:47.502417Z"}
1618677827.4999099: {"type":"l2update","product_id":"CRV-EUR","changes":[["buy","3.2971","120.00"]],"time":"2021-04-17T16:43:47.504038Z"}
1618677827.499939: {"type":"l2update","product_id":"SKL-BTC","changes":[["buy","0.00001301","16498.2"]],"time":"2021-04-17T16:43:47.505651Z"}
1618677827.499964: {"type":"l2update","product_id":"NMR-EUR","changes":[["buy","66.9380","0.000"]],"time":"2021-04-17T16:43:47.509016Z"}
1618677827.499995: {"type":"l2update","product_id":"SKL-BTC","changes":[["buy","0.00001301","17415.7"]],"time":"2021-04-17T16:43:47.512516Z"}
1618677827.514539: {"type":"l2update","product_id":"BAND-BTC","changes":[["sell","0.00033490","35.71"]],"time":"2021-04-17T16:43:47.515756Z"}
1618677827.5146172: {"type":"l2update","product_id":"DASH-BTC","changes":[["buy","0.00618576","2.64400000"]],"time":"2021-04-17T16:43:47.516030Z"}
1618677827.5146592: {"type":"l2update","product_id":"DASH-BTC","changes":[["buy","0.00618147","32.84700000"]],"time":"2021-04-17T16:43:47.516048Z"}
1618677827.514691: {"type":"l2update","product_id":"BAND-BTC","changes":[["buy","0.00033410","0.00"]],"time":"2021-04-17T16:43:47.516121Z"}
1618677827.5147269: {"type":"l2update","product_id":"SKL-USD","changes":[["sell","0.7923","0.0"]],"time":"2021-04-17T16:43:47.516530Z"}
1618677827.51476: {"type":"l2update","product_id":"CRV-EUR","changes":[["sell","3.3026","238.59"]],"time":"2021-04-17T16:43:47.519456Z"}
1618677827.514786: {"type":"l2update","product_id":"CRV-EUR","changes":[["sell","3.3040","500.62"]],"time":"2021-04-17T16:43:47.523621Z"}
1618677827.5148082: {"type":"l2update","product_id":"NMR-EUR","changes":[["buy","66.4816","1.231"]],"time":"2021-04-17T16:43:47.523973Z"}
1618677827.514836: {"type":"l2update","product_id":"SKL-BTC","changes":[["buy","0.00001301","18081.9"]],"time":"2021-04-17T16:43:47.524012Z"}
1618677827.514858: {"type":"l2update","product_id":"BAND-BTC","changes":[["buy","0.00033323","0.00"]],"time":"2021-04-17T16:43:47.529110Z"}
1618677827.5148852: {"type":"l2update","product_id":"DASH-BTC","changes":[["buy","0.00618576","0.00000000"]],"time":"2021-04-17T16:43:47.529291Z"}
1618677827.531453: {"type":"l2update","product_id":"DASH-BTC","changes":[["sell","0.00620688","0.00000000"]],"time":"2021-04-17T16:43:47.536633Z"}
1618677827.531523: {"type":"l2update","product_id":"SKL-USD","changes":[["buy","0.7903","1044.7"]],"time":"2021-04-17T16:43:47.539038Z"}
1618677827.5315661: {"type":"l2update","product_id":"CRV-EUR","changes":[["buy","3.2971","0.00"]],"time":"2021-04-17T16:43:47.543910Z"}
1618677827.531602: {"type":"l2update","product_id":"NMR-EUR","changes":[["buy","66.4807","0.000"]],"time":"2021-04-17T16:43:47.545627Z"}
1618677827.532468: {"type":"l2update","product_id":"BAND-BTC","changes":[["buy","0.00033436","0.00"]],"time":"2021-04-17T16:43:47.548503Z"}
1618677827.532535: {"type":"l2update","product_id":"SKL-USD","changes":[["buy","0.7888","1900.0"]],"time":"2021-04-17T16:43:47.548087Z"}
1618677827.533587: {"type":"l2update","product_id":"BAND-BTC","changes":[["buy","0.00033346","28.63"]],"time":"2021-04-17T16:43:47.551172Z"}
1618677827.538819: {"type":"l2update","product_id":"BAND-BTC","changes":[["buy","0.00033433","0.00"]],"time":"2021-04-17T16:43:47.553644Z"}
1618677827.5442848: {"type":"l2update","product_id":"BAND-GBP","changes":[["buy","14.7644","0.00"]],"time":"2021-04-17T16:43:47.557762Z"}
1618677827.5443609: {"type":"l2update","product_id":"DASH-BTC","changes":[["sell","0.00620497","3.85900000"]],"time":"2021-04-17T16:43:47.558797Z"}
1618677827.544406: {"type":"l2update","product_id":"BAND-BTC","changes":[["buy","0.00033376","0.00"]],"time":"2021-04-17T16:43:47.560296Z"}
1618677827.546422: {"type":"l2update","product_id":"DASH-BTC","changes":[["buy","0.00617109","11.31000000"]],"time":"2021-04-17T16:43:47.563085Z"}
1618677827.5464692: {"type":"l2update","product_id":"DASH-BTC","changes":[["buy","0.00616178","4.27800000"]],"time":"2021-04-17T16:43:47.563085Z"}
1618677827.5464902: {"type":"l2update","product_id":"DASH-BTC","changes":[["buy","0.00614322","19.53200000"]],"time":"2021-04-17T16:43:47.563085Z"}
1618677827.546506: {"type":"l2update","product_id":"BAND-BTC","changes":[["buy","0.00033243","0.00"]],"time":"2021-04-17T16:43:47.563909Z"}
1618677827.547592: {"type":"l2update","product_id":"CRV-EUR","changes":[["buy","3.2894","481.00"]],"time":"2021-04-17T16:43:47.564619Z"}
1618677827.5476348: {"type":"l2update","product_id":"SKL-USD","changes":[["sell","0.7921","2630.1"]],"time":"2021-04-17T16:43:47.564631Z"}
1618677827.5539289: {"type":"l2update","product_id":"SKL-USD","changes":[["buy","0.7901","0.0"]],"time":"2021-04-17T16:43:47.565914Z"}
1618677827.553982: {"type":"l2update","product_id":"SKL-USD","changes":[["buy","0.7898","1345.7"]],"time":"2021-04-17T16:43:47.566012Z"}
1618677827.556948: {"type":"l2update","product_id":"SKL-USD","changes":[["buy","0.7875","25513.9"]],"time":"2021-04-17T16:43:47.570075Z"}
1618677827.558242: {"type":"l2update","product_id":"DASH-BTC","changes":[["buy","0.00616178","13.57500000"]],"time":"2021-04-17T16:43:47.574892Z"}
1618677827.5593019: {"type":"l2update","product_id":"DASH-BTC","changes":[["buy","0.00615249","8.56500000"]],"time":"2021-04-17T16:43:47.574892Z"}
1618677827.559339: {"type":"l2update","product_id":"DASH-BTC","changes":[["buy","0.00613395","23.45800000"]],"time":"2021-04-17T16:43:47.574892Z"}
1618677827.559361: {"type":"l2update","product_id":"DASH-BTC","changes":[["buy","0.00606951","0.01000000"]],"time":"2021-04-17T16:43:47.574892Z"}
1618677827.559385: {"type":"l2update","product_id":"SKL-GBP","changes":[["buy","0.5747","0.0"]],"time":"2021-04-17T16:43:47.574956Z"}
1618677827.559409: {"type":"l2update","product_id":"SKL-USD","changes":[["sell","0.7922","0.0"]],"time":"2021-04-17T16:43:47.576599Z"}
1618677827.562701: {"type":"l2update","product_id":"BAND-GBP","changes":[["buy","14.7488","27.55"]],"time":"2021-04-17T16:43:47.578633Z"}
1618677827.5668092: {"type":"l2update","product_id":"BAND-GBP","changes":[["sell","14.7984","0.00"]],"time":"2021-04-17T16:43:47.580396Z"}
1618677827.566853: {"type":"l2update","product_id":"SKL-USD","changes":[["sell","0.7920","1017.5"]],"time":"2021-04-17T16:43:47.582921Z"}
1618677827.572505: {"type":"l2update","product_id":"SKL-BTC","changes":[["buy","0.00001304","1099.7"]],"time":"2021-04-17T16:43:47.583953Z"}
1618677827.572542: {"type":"l2update","product_id":"SKL-USD","changes":[["buy","0.7889","868.8"]],"time":"2021-04-17T16:43:47.586304Z"}
1618677827.6026251: {"type":"l2update","product_id":"NMR-EUR","changes":[["buy","66.9369","0.000"]],"time":"2021-04-17T16:43:47.605929Z"}
1618677827.6026912: {"type":"l2update","product_id":"CRV-EUR","changes":[["buy","3.2970","120.00"]],"time":"2021-04-17T16:43:47.609093Z"}
1618677827.602719: {"type":"l2update","product_id":"SKL-USD","changes":[["buy","0.7904","0.0"]],"time":"2021-04-17T16:43:47.612509Z"}
1618677827.6027431: {"type":"l2update","product_id":"NMR-EUR","changes":[["buy","66.8895","1.303"]],"time":"2021-04-17T16:43:47.612882Z"}
1618677827.605653: {"type":"l2update","product_id":"DASH-BTC","changes":[["buy","0.00618777","0.00000000"]],"time":"2021-04-17T16:43:47.620945Z"}
1618677827.6065469: {"type":"l2update","product_id":"SKL-BTC","changes":[["buy","0.00001298","0.0"]],"time":"2021-04-17T16:43:47.622286Z"}
1618677827.607594: {"type":"l2update","product_id":"NMR-EUR","changes":[["buy","66.8972","4.776"]],"time":"2021-04-17T16:43:47.623775Z"}
1618677827.6076312: {"type":"l2update","product_id":"SKL-USD","changes":[["sell","0.8079","5.0"]],"time":"2021-04-17T16:43:47.624559Z"}
1618677827.623373: {"type":"l2update","product_id":"SKL-BTC","changes":[["buy","0.00001304","110.0"]],"time":"2021-04-17T16:43:47.634300Z"}
1618677827.62341: {"type":"l2update","product_id":"SKL-BTC","changes":[["buy","0.00001304","1003.6"]],"time":"2021-04-17T16:43:47.635128Z"}
1618677827.623431: {"type":"l2update","product_id":"SKL-USD","changes":[["buy","0.7901","1194.6"]],"time":"2021-04-17T16:43:47.635013Z"}
1618677827.623456: {"type":"l2update","product_id":"NMR-EUR","changes":[["buy","66.8895","2.606"]],"time":"2021-04-17T16:43:47.639053Z"}
1618677827.62853: {"type":"l2update","product_id":"SKL-BTC","changes":[["buy","0.00001303","11527.5"]],"time":"2021-04-17T16:43:47.642583Z"}
1618677827.628567: {"type":"l2update","product_id":"DASH-BTC","changes":[["buy","0.00618543","1.12100000"]],"time":"2021-04-17T16:43:47.642603Z"}
1618677827.6426399: {"type":"l2update","product_id":"SKL-USD","changes":[["buy","0.7910","880.0"]],"time":"2021-04-17T16:43:47.645942Z"}
1618677827.6426759: {"type":"l2update","product_id":"SKL-BTC","changes":[["sell","0.00001308","4210.4"]],"time":"2021-04-17T16:43:47.654173Z"}
1618677827.642698: {"type":"l2update","product_id":"NMR-EUR","changes":[["buy","66.4808","0.000"]],"time":"2021-04-17T16:43:47.655330Z"}
1618677827.642724: {"type":"l2update","product_id":"NMR-EUR","changes":[["buy","66.4809","0.000"]],"time":"2021-04-17T16:43:47.655330Z"}
1618677827.642744: {"type":"l2update","product_id":"NMR-EUR","changes":[["buy","66.4812","1.540"]],"time":"2021-04-17T16:43:47.655330Z"}
1618677827.643836: {"type":"l2update","product_id":"DASH-BTC","changes":[["sell","0.00620526","0.00000000"]],"time":"2021-04-17T16:43:47.661777Z"}
1618677827.646189: {"type":"l2update","product_id":"SKL-USD","changes":[["buy","0.7881","10695.7"]],"time":"2021-04-17T16:43:47.661793Z"}
1618677827.646234: {"type":"l2update","product_id":"NMR-EUR","changes":[["buy","66.4816","24.451"]],"time":"2021-04-17T16:43:47.661878Z"}
1618677827.646261: {"type":"l2update","product_id":"NMR-EUR","changes":[["buy","66.4814","8.230"]],"time":"2021-04-17T16:43:47.661878Z"}
1618677827.6502779: {"type":"l2update","product_id":"BAND-BTC","changes":[["buy","0.00033345","0.00"]],"time":"2021-04-17T16:43:47.667290Z"}
1618677827.653041: {"type":"l2update","product_id":"SKL-BTC","changes":[["buy","0.00001300","11894.5"]],"time":"2021-04-17T16:43:47.668516Z"}
1618677827.657006: {"type":"l2update","product_id":"SKL-GBP","changes":[["buy","0.5689","610.0"]],"time":"2021-04-17T16:43:47.671123Z"}
1618677827.657061: {"type":"l2update","product_id":"SKL-GBP","changes":[["buy","0.5689","175.0"]],"time":"2021-04-17T16:43:47.671123Z"}
1618677827.657092: {"type":"l2update","product_id":"SKL-GBP","changes":[["sell","0.5771","0.0"]],"time":"2021-04-17T16:43:47.671123Z"}
1618677827.661488: {"type":"l2update","product_id":"SKL-GBP","changes":[["sell","0.5779","340.0"]],"time":"2021-04-17T16:43:47.676135Z"}
1618677827.661555: {"type":"l2update","product_id":"SKL-GBP","changes":[["buy","0.5689","615.0"]],"time":"2021-04-17T16:43:47.676135Z"}
1618677827.681185: {"type":"l2update","product_id":"BAND-GBP","changes":[["sell","14.7867","12.61"]],"time":"2021-04-17T16:43:47.694367Z"}
1618677827.681252: {"type":"l2update","product_id":"BAND-BTC","changes":[["buy","0.00033231","19.38"]],"time":"2021-04-17T16:43:47.694507Z"}
1618677827.681292: {"type":"l2update","product_id":"BAND-GBP","changes":[["buy","14.7561","12.26"]],"time":"2021-04-17T16:43:47.694495Z"}
1618677827.681322: {"type":"l2update","product_id":"BAND-BTC","changes":[["buy","0.00033417","0.00"]],"time":"2021-04-17T16:43:47.696009Z"}
1618677827.683438: {"type":"l2update","product_id":"BAND-GBP","changes":[["buy","14.7500","13.13"]],"time":"2021-04-17T16:43:47.697831Z"}
1618677827.69059: {"type":"l2update","product_id":"BAND-BTC","changes":[["buy","0.00033394","253.70"]],"time":"2021-04-17T16:43:47.705425Z"}
1618677827.6936588: {"type":"l2update","product_id":"DASH-BTC","changes":[["buy","0.00618779","1.54300000"]],"time":"2021-04-17T16:43:47.708356Z"}
1618677827.69371: {"type":"l2update","product_id":"BAND-BTC","changes":[["buy","0.00033350","336.78"]],"time":"2021-04-17T16:43:47.708744Z"}
1618677827.694632: {"type":"l2update","product_id":"BAND-BTC","changes":[["buy","0.00033170","448.08"]],"time":"2021-04-17T16:43:47.710078Z"}
1618677827.694678: {"type":"l2update","product_id":"BAND-BTC","changes":[["buy","0.00033144","0.10"]],"time":"2021-04-17T16:43:47.710078Z"}
1618677827.69698: {"type":"l2update","product_id":"SKL-USD","changes":[["buy","0.7907","0.0"]],"time":"2021-04-17T16:43:47.713321Z"}
1618677827.6970298: {"type":"l2update","product_id":"DASH-BTC","changes":[["sell","0.00620304","0.00000000"]],"time":"2021-04-17T16:43:47.714283Z"}
1618677827.7054222: {"type":"l2update","product_id":"BAND-GBP","changes":[["buy","14.7060","49.51"]],"time":"2021-04-17T16:43:47.720597Z"}
1618677827.707556: {"type":"l2update","product_id":"BAND-BTC","changes":[["buy","0.00033144","256.19"]],"time":"2021-04-17T16:43:47.720644Z"}
1618677827.7075999: {"type":"l2update","product_id":"BAND-BTC","changes":[["buy","0.00033094","307.43"]],"time":"2021-04-17T16:43:47.720644Z"}
1618677827.707627: {"type":"l2update","product_id":"BAND-BTC","changes":[["buy","0.00032746","0.10"]],"time":"2021-04-17T16:43:47.720644Z"}
1618677827.707654: {"type":"l2update","product_id":"BAND-BTC","changes":[["sell","0.00033516","24.00"]],"time":"2021-04-17T16:43:47.721950Z"}
1618677827.712275: {"type":"l2update","product_id":"DASH-BTC","changes":[["buy","0.00618543","1.41600000"]],"time":"2021-04-17T16:43:47.727912Z"}
1618677827.71822: {"type":"l2update","product_id":"DASH-BTC","changes":[["buy","0.00618779","0.00000000"]],"time":"2021-04-17T16:43:47.734562Z"}
1618677827.721521: {"type":"l2update","product_id":"BAND-BTC","changes":[["buy","0.00033349","0.00"]],"time":"2021-04-17T16:43:47.736889Z"}
1618677827.721573: {"type":"l2update","product_id":"BAND-BTC","changes":[["buy","0.00033217","17.85"]],"time":"2021-04-17T16:43:47.736919Z"}
1618677827.721605: {"type":"l2update","product_id":"SKL-USD","changes":[["buy","0.7901","2061.5"]],"time":"2021-04-17T16:43:47.736943Z"}
1618677827.721627: {"type":"l2update","product_id":"BAND-BTC","changes":[["sell","0.00033474","18.36"]],"time":"2021-04-17T16:43:47.737017Z"}
1618677827.721657: {"type":"l2update","product_id":"DASH-BTC","changes":[["sell","0.00620497","2.23600000"]],"time":"2021-04-17T16:43:47.738194Z"}
1618677827.732214: {"type":"l2update","product_id":"SKL-BTC","changes":[["sell","0.00001309","7841.6"]],"time":"2021-04-17T16:43:47.747374Z"}
1618677827.7322612: {"type":"l2update","product_id":"SKL-USD","changes":[["buy","0.7910","430.0"]],"time":"2021-04-17T16:43:47.747442Z"}
1618677827.733411: {"type":"l2update","product_id":"BAND-BTC","changes":[["sell","0.00033478","25.00"]],"time":"2021-04-17T16:43:47.747557Z"}
1618677827.733463: {"type":"l2update","product_id":"SKL-USD","changes":[["buy","0.7875","0.0"]],"time":"2021-04-17T16:43:47.748830Z"}
1618677827.733495: {"type":"l2update","product_id":"DASH-BTC","changes":[["sell","0.00620283","14.63200000"]],"time":"2021-04-17T16:43:47.747574Z"}
1618677827.740706: {"type":"l2update","product_id":"SKL-USD","changes":[["buy","0.7907","450.0"]],"time":"2021-04-17T16:43:47.750933Z"}
1618677827.741417: {"type":"l2update","product_id":"DASH-BTC","changes":[["buy","0.00618543","2.95900000"]],"time":"2021-04-17T16:43:47.754551Z"}
1618677827.745043: {"type":"l2update","product_id":"SKL-BTC","changes":[["buy","0.00001305","0.5"]],"time":"2021-04-17T16:43:47.750922Z"}
1618677827.745085: {"type":"match","trade_id":280236,"maker_order_id":"dad6f9f7-f55d-4708-aaae-ce16d71a9dee","taker_order_id":"4d301c11-c69a-4830-b912-176af07e5047","side":"buy","size":"1006","price":"0.00001305","product_id":"SKL-BTC","sequence":177100796,"time":"2021-04-17T16:43:47.750922Z"}
1618677827.7451122: {"type":"ticker","sequence":177100796,"product_id":"SKL-BTC","price":"0.00001305","open_24h":"0.00001144","volume_24h":"7370981.40000000","low_24h":"0.00001122","high_24h":"0.00001337","volume_30d":"137084563.50000000","best_bid":"0.00001305","best_ask":"0.00001306","side":"sell","time":"2021-04-17T16:43:47.750922Z","trade_id":280236,"last_size":"1006"}
1618677827.749374: {"type":"l2update","product_id":"BAND-BTC","changes":[["buy","0.00033351","20.79"]],"time":"2021-04-17T16:43:47.758519Z"}
1618677827.749422: {"type":"l2update","product_id":"BAND-BTC","changes":[["sell","0.00033507","29.65"]],"time":"2021-04-17T16:43:47.758982Z"}
1618677827.749453: {"type":"l2update","product_id":"SKL-USD","changes":[["buy","0.7907","0.0"]],"time":"2021-04-17T16:43:47.763977Z"}
1618677827.749482: {"type":"l2update","product_id":"BAND-BTC","changes":[["sell","0.00033465","18.14"]],"time":"2021-04-17T16:43:47.764083Z"}
1618677827.7509341: {"type":"l2update","product_id":"SKL-USD","changes":[["buy","0.7909","530.2"]],"time":"2021-04-17T16:43:47.767686Z"}
1618677827.7519958: {"type":"l2update","product_id":"SKL-USD","changes":[["buy","0.7866","28148.7"]],"time":"2021-04-17T16:43:47.767784Z"}
1618677827.752034: {"type":"l2update","product_id":"NU-GBP","changes":[["buy","0.4318","0.000000"]],"time":"2021-04-17T16:43:47.768049Z"}
1618677827.7579699: {"type":"l2update","product_id":"DASH-BTC","changes":[["sell","0.00620621","1.62300000"]],"time":"2021-04-17T16:43:47.771520Z"}
1618677827.758966: {"type":"l2update","product_id":"SKL-USD","changes":[["buy","0.7906","0.0"]],"time":"2021-04-17T16:43:47.775939Z"}
1618677827.7602508: {"type":"l2update","product_id":"DASH-BTC","changes":[["sell","0.00619847","0.00000000"]],"time":"2021-04-17T16:43:47.777000Z"}
1618677827.765645: {"type":"l2update","product_id":"SKL-GBP","changes":[["buy","0.5751","0.0"]],"time":"2021-04-17T16:43:47.781918Z"}
1618677827.765694: {"type":"l2update","product_id":"SKL-USD","changes":[["buy","0.7896","0.0"]],"time":"2021-04-17T16:43:47.781909Z"}
1618677827.7698848: {"type":"l2update","product_id":"SKL-USD","changes":[["sell","0.8082","6005.0"]],"time":"2021-04-17T16:43:47.785710Z"}
1618677827.772259: {"type":"l2update","product_id":"DASH-BTC","changes":[["buy","0.00618271","0.00000000"]],"time":"2021-04-17T16:43:47.789053Z"}
1618677827.7744489: {"type":"l2update","product_id":"NMR-EUR","changes":[["buy","66.4817","0.270"]],"time":"2021-04-17T16:43:47.789854Z"}
1618677827.774498: {"type":"l2update","product_id":"NMR-EUR","changes":[["buy","66.4816","24.511"]],"time":"2021-04-17T16:43:47.789854Z"}
1618677827.7797172: {"type":"l2update","product_id":"BAND-BTC","changes":[["buy","0.00033397","102.94"]],"time":"2021-04-17T16:43:47.794011Z"}
1618677827.780715: {"type":"l2update","product_id":"NU-GBP","changes":[["buy","0.4300","9182.000000"]],"time":"2021-04-17T16:43:47.794063Z"}
1618677827.785845: {"type":"l2update","product_id":"SKL-USD","changes":[["buy","0.7892","2526.5"]],"time":"2021-04-17T16:43:47.797764Z"}
1618677827.786316: {"type":"l2update","product_id":"DASH-BTC","changes":[["sell","0.00620365","0.82500000"]],"time":"2021-04-17T16:43:47.797980Z"}
1618677827.787321: {"type":"l2update","product_id":"SKL-USD","changes":[["buy","0.7909","80.2"]],"time":"2021-04-17T16:43:47.801598Z"}
1618677827.78736: {"type":"l2update","product_id":"SKL-BTC","changes":[["sell","0.00001307","3788.9"]],"time":"2021-04-17T16:43:47.804778Z"}
1618677827.79312: {"type":"l2update","product_id":"SKL-USD","changes":[["buy","0.7904","450.0"]],"time":"2021-04-17T16:43:47.805526Z"}
1618677827.793165: {"type":"l2update","product_id":"SKL-BTC","changes":[["buy","0.00001303","10537.8"]],"time":"2021-04-17T16:43:47.806207Z"}
1618677827.79319: {"type":"l2update","product_id":"SKL-USD","changes":[["buy","0.7902","2630.9"]],"time":"2021-04-17T16:43:47.809154Z"}
1618677827.7988532: {"type":"l2update","product_id":"SKL-USD","changes":[["sell","0.7921","3819.6"]],"time":"2021-04-17T16:43:47.812946Z"}
1618677827.798898: {"type":"l2update","product_id":"BAND-BTC","changes":[["sell","0.00033490","0.00"]],"time":"2021-04-17T16:43:47.813825Z"}
1618677827.798934: {"type":"l2update","product_id":"SKL-USD","changes":[["buy","0.7856","770.0"]],"time":"2021-04-17T16:43:47.813678Z"}
1618677827.798958: {"type":"l2update","product_id":"SKL-USD","changes":[["sell","0.8088","185.0"]],"time":"2021-04-17T16:43:47.813678Z"}
1618677827.799528: {"type":"l2update","product_id":"SKL-USD","changes":[["buy","0.7881","7252.8"]],"time":"2021-04-17T16:43:47.816472Z"}
1618677827.799571: {"type":"l2update","product_id":"SKL-USD","changes":[["buy","0.7807","5.0"]],"time":"2021-04-17T16:43:47.816472Z"}
1618677827.803013: {"type":"l2update","product_id":"NU-GBP","changes":[["buy","0.4367","0.000000"]],"time":"2021-04-17T16:43:47.816947Z"}
1618677827.8030632: {"type":"l2update","product_id":"CRV-EUR","changes":[["sell","3.3198","56.00"]],"time":"2021-04-17T16:43:47.819532Z"}
1618677827.803091: {"type":"l2update","product_id":"CRV-EUR","changes":[["sell","3.3199","0.00"]],"time":"2021-04-17T16:43:47.819532Z"}
1618677827.803118: {"type":"l2update","product_id":"CRV-EUR","changes":[["buy","3.2697","7.00"]],"time":"2021-04-17T16:43:47.819532Z"}
1618677827.803138: {"type":"l2update","product_id":"SKL-BTC","changes":[["sell","0.00001307","4740.2"]],"time":"2021-04-17T16:43:47.820510Z"}
1618677827.804233: {"type":"l2update","product_id":"SKL-USD","changes":[["sell","0.8079","505.0"]],"time":"2021-04-17T16:43:47.820604Z"}
1618677827.804279: {"type":"l2update","product_id":"SKL-USD","changes":[["buy","0.7855","255.0"]],"time":"2021-04-17T16:43:47.820604Z"}
1618677827.8043048: {"type":"l2update","product_id":"SKL-BTC","changes":[["buy","0.00001300","8162.6"]],"time":"2021-04-17T16:43:47.821582Z"}
1618677827.809278: {"type":"l2update","product_id":"SKL-BTC","changes":[["sell","0.00001308","3452.8"]],"time":"2021-04-17T16:43:47.823921Z"}
1618677827.8093219: {"type":"l2update","product_id":"CRV-EUR","changes":[["buy","3.2697","102.50"]],"time":"2021-04-17T16:43:47.824486Z"}
1618677827.809348: {"type":"l2update","product_id":"CRV-EUR","changes":[["sell","3.3201","291.00"]],"time":"2021-04-17T16:43:47.824486Z"}
1618677827.8102322: {"type":"l2update","product_id":"SKL-USD","changes":[["buy","0.7903","0.0"]],"time":"2021-04-17T16:43:47.827304Z"}
1618677827.8128262: {"type":"l2update","product_id":"NU-GBP","changes":[["buy","0.4365","9779.553835"]],"time":"2021-04-17T16:43:47.828840Z"}
1618677827.8159392: {"type":"l2update","product_id":"SKL-BTC","changes":[["buy","0.00001301","18967.0"]],"time":"2021-04-17T16:43:47.832261Z"}
1618677827.820256: {"type":"l2update","product_id":"DASH-BTC","changes":[["buy","0.00618389","2.62800000"]],"time":"2021-04-17T16:43:47.835951Z"}
1618677827.820311: {"type":"l2update","product_id":"SKL-USD","changes":[["buy","0.7904","0.0"]],"time":"2021-04-17T16:43:47.836590Z"}
1618677827.826936: {"type":"l2update","product_id":"SKL-USD","changes":[["buy","0.7910","0.0"]],"time":"2021-04-17T16:43:47.839396Z"}
1618677827.826987: {"type":"match","trade_id":1568275,"maker_order_id":"4d7f8cc2-5993-41d8-b86b-f4a8161c5610","taker_order_id":"bcf814bf-168b-44f9-b7aa-43425f854a2c","side":"buy","size":"430","price":"0.791","product_id":"SKL-USD","sequence":201391279,"time":"2021-04-17T16:43:47.839396Z"}
1618677827.827015: {"type":"ticker","sequence":201391279,"product_id":"SKL-USD","price":"0.791","open_24h":"0.7055","volume_24h":"34258383.00000000","low_24h":"0.6915","high_24h":"0.8098","volume_30d":"948685735.70000000","best_bid":"0.7909","best_ask":"0.7920","side":"sell","time":"2021-04-17T16:43:47.839396Z","trade_id":1568275,"last_size":"430"}
1618677827.827039: {"type":"l2update","product_id":"SKL-USD","changes":[["buy","0.7903","450.0"]],"time":"2021-04-17T16:43:47.839427Z"}
1618677827.8270679: {"type":"l2update","product_id":"SKL-USD","changes":[["sell","0.7927","3634.0"]],"time":"2021-04-17T16:43:47.843247Z"}
1618677827.834174: {"type":"l2update","product_id":"SKL-USD","changes":[["buy","0.7874","0.0"]],"time":"2021-04-17T16:43:47.850857Z"}
1618677827.843863: {"type":"l2update","product_id":"SKL-BTC","changes":[["sell","0.00001306","2003.2"]],"time":"2021-04-17T16:43:47.854876Z"}
1618677827.843907: {"type":"l2update","product_id":"SKL-USD","changes":[["buy","0.7909","0.2"]],"time":"2021-04-17T16:43:47.854954Z"}
1618677827.843934: {"type":"match","trade_id":1568276,"maker_order_id":"d38df598-50d8-43d4-a669-98f87188ec0a","taker_order_id":"572dade7-6400-4ff7-9f84-be175c6510ec","side":"buy","size":"80","price":"0.7909","product_id":"SKL-USD","sequence":201391288,"time":"2021-04-17T16:43:47.854954Z"}
1618677827.8439622: {"type":"ticker","sequence":201391288,"product_id":"SKL-USD","price":"0.7909","open_24h":"0.7055","volume_24h":"34258463.00000000","low_24h":"0.6915","high_24h":"0.8098","volume_30d":"948685815.70000000","best_bid":"0.7909","best_ask":"0.7920","side":"sell","time":"2021-04-17T16:43:47.854954Z","trade_id":1568276,"last_size":"80"}
1618677827.843984: {"type":"l2update","product_id":"BAND-GBP","changes":[["buy","14.7591","27.53"]],"time":"2021-04-17T16:43:47.858138Z"}
1618677827.844012: {"type":"l2update","product_id":"BAND-BTC","changes":[["buy","0.00033436","29.61"]],"time":"2021-04-17T16:43:47.858199Z"}
1618677827.8508642: {"type":"l2update","product_id":"BAND-GBP","changes":[["buy","14.7488","0.00"]],"time":"2021-04-17T16:43:47.862684Z"}
1618677827.850911: {"type":"l2update","product_id":"SKL-BTC","changes":[["buy","0.00001303","9397.5"]],"time":"2021-04-17T16:43:47.862592Z"}
1618677827.8509362: {"type":"l2update","product_id":"SKL-GBP","changes":[["buy","0.5752","0.0"]],"time":"2021-04-17T16:43:47.863059Z"}
1618677827.850962: {"type":"l2update","product_id":"SKL-BTC","changes":[["buy","0.00001303","3897.5"]],"time":"2021-04-17T16:43:47.864141Z"}
1618677827.8555698: {"type":"l2update","product_id":"DASH-BTC","changes":[["sell","0.00620497","0.00000000"]],"time":"2021-04-17T16:43:47.870562Z"}
1618677827.863034: {"type":"l2update","product_id":"BAND-GBP","changes":[["buy","14.7594","12.64"]],"time":"2021-04-17T16:43:47.876334Z"}
1618677827.863081: {"type":"l2update","product_id":"BAND-BTC","changes":[["buy","0.00033346","0.00"]],"time":"2021-04-17T16:43:47.878938Z"}
1618677827.865185: {"type":"l2update","product_id":"DASH-BTC","changes":[["buy","0.00618541","0.00000000"]],"time":"2021-04-17T16:43:47.879838Z"}
1618677827.865234: {"type":"l2update","product_id":"SKL-GBP","changes":[["buy","0.5747","1028.6"]],"time":"2021-04-17T16:43:47.879818Z"}
1618677827.865265: {"type":"l2update","product_id":"BAND-GBP","changes":[["sell","14.7867","0.00"]],"time":"2021-04-17T16:43:47.881425Z"}
1618677827.87042: {"type":"l2update","product_id":"NU-GBP","changes":[["buy","0.4369","3000.000000"]],"time":"2021-04-17T16:43:47.883072Z"}
1618677827.870472: {"type":"l2update","product_id":"SKL-USD","changes":[["buy","0.7888","0.0"]],"time":"2021-04-17T16:43:47.883477Z"}
1618677827.872923: {"type":"l2update","product_id":"SKL-BTC","changes":[["buy","0.00001303","110.0"]],"time":"2021-04-17T16:43:47.886464Z"}
1618677827.872968: {"type":"l2update","product_id":"SKL-GBP","changes":[["sell","0.5773","1735.0"]],"time":"2021-04-17T16:43:47.886586Z"}
1618677827.872994: {"type":"l2update","product_id":"BAND-GBP","changes":[["buy","14.7591","0.00"]],"time":"2021-04-17T16:43:47.887338Z"}
1618677827.873024: {"type":"l2update","product_id":"SKL-USD","changes":[["sell","0.7927","1108.3"]],"time":"2021-04-17T16:43:47.886958Z"}
1618677827.8808131: {"type":"l2update","product_id":"DASH-BTC","changes":[["sell","0.00620282","2.23600000"]],"time":"2021-04-17T16:43:47.890374Z"}
1618677827.880864: {"type":"l2update","product_id":"BAND-GBP","changes":[["buy","14.7617","27.53"]],"time":"2021-04-17T16:43:47.893686Z"}
1618677827.880894: {"type":"l2update","product_id":"SKL-USD","changes":[["sell","0.7936","1905.0"]],"time":"2021-04-17T16:43:47.893731Z"}
1618677827.880917: {"type":"l2update","product_id":"SKL-BTC","changes":[["buy","0.00001300","1219.1"]],"time":"2021-04-17T16:43:47.895601Z"}
1618677827.885343: {"type":"l2update","product_id":"BAND-GBP","changes":[["sell","14.7904","12.30"]],"time":"2021-04-17T16:43:47.897432Z"}
1618677827.885393: {"type":"l2update","product_id":"BAND-GBP","changes":[["buy","14.7594","0.00"]],"time":"2021-04-17T16:43:47.897630Z"}
1618677827.8854232: {"type":"l2update","product_id":"BAND-GBP","changes":[["buy","14.7561","0.00"]],"time":"2021-04-17T16:43:47.897971Z"}
1618677827.90111: {"type":"l2update","product_id":"BAND-BTC","changes":[["buy","0.00033232","28.73"]],"time":"2021-04-17T16:43:47.900681Z"}
1618677827.9011788: {"type":"l2update","product_id":"SKL-GBP","changes":[["sell","0.5771","2526.7"]],"time":"2021-04-17T16:43:47.900784Z"}
1618677827.901221: {"type":"l2update","product_id":"SKL-BTC","changes":[["buy","0.00001302","8945.8"]],"time":"2021-04-17T16:43:47.901062Z"}
1618677827.901249: {"type":"l2update","product_id":"SKL-BTC","changes":[["buy","0.00001304","110.0"]],"time":"2021-04-17T16:43:47.902714Z"}
1618677827.901272: {"type":"l2update","product_id":"SKL-BTC","changes":[["sell","0.00001311","2113.4"]],"time":"2021-04-17T16:43:47.903737Z"}
1618677827.9012952: {"type":"l2update","product_id":"BAND-BTC","changes":[["sell","0.00033506","0.00"]],"time":"2021-04-17T16:43:47.910005Z"}
1618677827.9013288: {"type":"l2update","product_id":"NMR-EUR","changes":[["buy","66.4815","0.000"]],"time":"2021-04-17T16:43:47.910724Z"}
1618677827.90136: {"type":"l2update","product_id":"BAND-BTC","changes":[["sell","0.00033465","0.00"]],"time":"2021-04-17T16:43:47.911786Z"}
1618677827.918527: {"type":"l2update","product_id":"SKL-USD","changes":[["sell","0.8080","6005.0"]],"time":"2021-04-17T16:43:47.928108Z"}
1618677827.9226298: {"type":"l2update","product_id":"SKL-USD","changes":[["sell","0.8082","12005.0"]],"time":"2021-04-17T16:43:47.935807Z"}
1618677827.9317691: {"type":"l2update","product_id":"SKL-GBP","changes":[["buy","0.5690","385.0"]],"time":"2021-04-17T16:43:47.942120Z"}
1618677827.93189: {"type":"l2update","product_id":"SKL-GBP","changes":[["buy","0.5690","0.0"]],"time":"2021-04-17T16:43:47.942120Z"}
1618677827.931975: {"type":"l2update","product_id":"SKL-BTC","changes":[["sell","0.00001310","11431.1"]],"time":"2021-04-17T16:43:47.945636Z"}
1618677827.935062: {"type":"l2update","product_id":"SKL-GBP","changes":[["buy","0.5705","365.0"]],"time":"2021-04-17T16:43:47.949338Z"}
1618677827.9351249: {"type":"l2update","product_id":"SKL-GBP","changes":[["buy","0.5724","590.0"]],"time":"2021-04-17T16:43:47.949338Z"}
1618677827.935158: {"type":"l2update","product_id":"SKL-GBP","changes":[["buy","0.5725","1740.0"]],"time":"2021-04-17T16:43:47.949338Z"}
1618677827.9351838: {"type":"l2update","product_id":"SKL-BTC","changes":[["buy","0.00001294","127341.2"]],"time":"2021-04-17T16:43:47.949567Z"}
1618677827.935209: {"type":"l2update","product_id":"SKL-BTC","changes":[["buy","0.00001292","12346.3"]],"time":"2021-04-17T16:43:47.949567Z"}
1618677827.935231: {"type":"l2update","product_id":"SKL-BTC","changes":[["buy","0.00001288","0.0"]],"time":"2021-04-17T16:43:47.949567Z"}
1618677827.93957: {"type":"l2update","product_id":"BAND-BTC","changes":[["buy","0.00033171","0.00"]],"time":"2021-04-17T16:43:47.951904Z"}
1618677827.939667: {"type":"l2update","product_id":"SKL-USD","changes":[["sell","0.7916","1258.8"]],"time":"2021-04-17T16:43:47.953090Z"}
1618677827.9397151: {"type":"l2update","product_id":"DASH-BTC","changes":[["sell","0.00619904","2.50900000"]],"time":"2021-04-17T16:43:47.953132Z"}
1618677827.939749: {"type":"l2update","product_id":"DASH-BTC","changes":[["sell","0.00621209","0.00000000"]],"time":"2021-04-17T16:43:47.955199Z"}
1618677827.940625: {"type":"l2update","product_id":"BAND-BTC","changes":[["sell","0.00033490","36.76"]],"time":"2021-04-17T16:43:47.956750Z"}
1618677827.9497118: {"type":"l2update","product_id":"SKL-USD","changes":[["sell","0.7920","0.0"]],"time":"2021-04-17T16:43:47.962211Z"}
1618677827.949813: {"type":"l2update","product_id":"SKL-BTC","changes":[["buy","0.00001294","137638.5"]],"time":"2021-04-17T16:43:47.960670Z"}
1618677827.94985: {"type":"l2update","product_id":"SKL-BTC","changes":[["buy","0.00001292","14821.3"]],"time":"2021-04-17T16:43:47.960670Z"}
1618677827.949877: {"type":"l2update","product_id":"SKL-BTC","changes":[["buy","0.00001286","74142.4"]],"time":"2021-04-17T16:43:47.960670Z"}
1618677827.949902: {"type":"l2update","product_id":"SKL-BTC","changes":[["buy","0.00001275","252.1"]],"time":"2021-04-17T16:43:47.960670Z"}
1618677827.949923: {"type":"l2update","product_id":"NMR-EUR","changes":[["buy","66.8895","1.303"]],"time":"2021-04-17T16:43:47.964821Z"}
1618677827.9513931: {"type":"l2update","product_id":"NMR-EUR","changes":[["buy","66.8895","0.000"]],"time":"2021-04-17T16:43:47.964961Z"}
1618677827.951471: {"type":"l2update","product_id":"SKL-USD","changes":[["buy","0.7898","0.0"]],"time":"2021-04-17T16:43:47.965270Z"}
1618677827.95238: {"type":"l2update","product_id":"SKL-USD","changes":[["sell","0.7915","1017.5"]],"time":"2021-04-17T16:43:47.968104Z"}
1618677827.957943: {"type":"l2update","product_id":"SKL-BTC","changes":[["buy","0.00001286","91931.2"]],"time":"2021-04-17T16:43:47.971517Z"}
1618677827.958014: {"type":"l2update","product_id":"BAND-BTC","changes":[["buy","0.00033232","49.59"]],"time":"2021-04-17T16:43:47.971723Z"}
1618677827.9580412: {"type":"l2update","product_id":"SKL-USD","changes":[["buy","0.7856","7896.3"]],"time":"2021-04-17T16:43:47.971821Z"}
1618677827.9580631: {"type":"l2update","product_id":"SKL-USD","changes":[["buy","0.7901","866.9"]],"time":"2021-04-17T16:43:47.972570Z"}
1618677827.958081: {"type":"l2update","product_id":"SKL-BTC","changes":[["sell","0.00001309","6733.3"]],"time":"2021-04-17T16:43:47.972606Z"}
1618677827.9581: {"type":"l2update","product_id":"BAND-BTC","changes":[["sell","0.00033543","0.00"]],"time":"2021-04-17T16:43:47.974561Z"}
1618677827.958132: {"type":"l2update","product_id":"SKL-USD","changes":[["buy","0.7854","3085.0"]],"time":"2021-04-17T16:43:47.974877Z"}
1618677827.959382: {"type":"l2update","product_id":"NMR-EUR","changes":[["buy","66.4818","13.000"]],"time":"2021-04-17T16:43:47.975524Z"}
1618677827.959442: {"type":"l2update","product_id":"DASH-BTC","changes":[["sell","0.00620497","1.62300000"]],"time":"2021-04-17T16:43:47.975605Z"}
1618677827.959477: {"type":"l2update","product_id":"SKL-USD","changes":[["buy","0.7874","3026.1"]],"time":"2021-04-17T16:43:47.975617Z"}
1618677827.9604092: {"type":"l2update","product_id":"SKL-USD","changes":[["buy","0.7795","174342.7"]],"time":"2021-04-17T16:43:47.975617Z"}
1618677827.962828: {"type":"l2update","product_id":"BAND-BTC","changes":[["buy","0.00033412","25.74"]],"time":"2021-04-17T16:43:47.978956Z"}
1618677827.9698792: {"type":"l2update","product_id":"SKL-BTC","changes":[["sell","0.00001308","4561.1"]],"time":"2021-04-17T16:43:47.982529Z"}
1618677827.9699252: {"type":"l2update","product_id":"SKL-BTC","changes":[["buy","0.00001299","7657.1"]],"time":"2021-04-17T16:43:47.982554Z"}
1618677827.974659: {"type":"l2update","product_id":"SKL-USD","changes":[["buy","0.7877","3217.4"]],"time":"2021-04-17T16:43:47.986055Z"}
1618677827.9747462: {"type":"l2update","product_id":"NMR-EUR","changes":[["buy","66.8973","1.303"]],"time":"2021-04-17T16:43:47.986739Z"}
1618677827.9748092: {"type":"l2update","product_id":"BAND-BTC","changes":[["buy","0.00033442","28.38"]],"time":"2021-04-17T16:43:47.990348Z"}
1618677827.979127: {"type":"l2update","product_id":"NMR-EUR","changes":[["buy","66.8972","0.000"]],"time":"2021-04-17T16:43:47.994216Z"}
1618677827.981178: {"type":"l2update","product_id":"SKL-USD","changes":[["buy","0.7893","1195.8"]],"time":"2021-04-17T16:43:47.997143Z"}
1618677827.98128: {"type":"l2update","product_id":"SKL-BTC","changes":[["sell","0.00001309","8633.3"]],"time":"2021-04-17T16:43:47.997224Z"}
1618677827.9835122: {"type":"l2update","product_id":"SKL-BTC","changes":[["buy","0.00001304","0.0"]],"time":"2021-04-17T16:43:47.999009Z"}
1618677827.987827: {"type":"l2update","product_id":"DASH-BTC","changes":[["sell","0.00620330","2.50900000"]],"time":"2021-04-17T16:43:48.001310Z"}
1618677827.987942: {"type":"l2update","product_id":"NMR-EUR","changes":[["buy","66.9035","4.775"]],"time":"2021-04-17T16:43:48.001332Z"}
1618677827.988001: {"type":"l2update","product_id":"BAND-BTC","changes":[["sell","0.00033478","0.00"]],"time":"2021-04-17T16:43:48.002460Z"}
1618677827.9891741: {"type":"l2update","product_id":"BAND-BTC","changes":[["buy","0.00033443","29.60"]],"time":"2021-04-17T16:43:48.004900Z"}
1618677827.990456: {"type":"l2update","product_id":"SKL-BTC","changes":[["buy","0.00001302","9055.8"]],"time":"2021-04-17T16:43:48.005051Z"}
1618677827.9905448: {"type":"l2update","product_id":"NMR-EUR","changes":[["buy","66.8973","2.606"]],"time":"2021-04-17T16:43:48.005069Z"}
1618677827.990597: {"type":"l2update","product_id":"SKL-USD","changes":[["buy","0.7898","417.9"]],"time":"2021-04-17T16:43:48.005120Z"}
1618677827.9906502: {"type":"l2update","product_id":"BAND-BTC","changes":[["buy","0.00033436","0.00"]],"time":"2021-04-17T16:43:48.005319Z"}
1618677827.997934: {"type":"l2update","product_id":"BAND-BTC","changes":[["sell","0.00033474","0.00"]],"time":"2021-04-17T16:43:48.011889Z"}
1618677828.005037: {"type":"l2update","product_id":"SKL-USD","changes":[["buy","0.7902","0.0"]],"time":"2021-04-17T16:43:48.020642Z"}
1618677828.0078778: {"type":"l2update","product_id":"BAND-BTC","changes":[["buy","0.00033397","120.94"]],"time":"2021-04-17T16:43:48.022614Z"}
1618677828.020253: {"type":"l2update","product_id":"SKL-USD","changes":[["buy","0.7903","0.0"]],"time":"2021-04-17T16:43:48.035617Z"}
1618677828.0256362: {"type":"l2update","product_id":"SKL-USD","changes":[["buy","0.7902","450.0"]],"time":"2021-04-17T16:43:48.041194Z"}
1618677828.0317461: {"type":"l2update","product_id":"BAND-BTC","changes":[["sell","0.00033563","0.00"]],"time":"2021-04-17T16:43:48.042871Z"}
1618677828.041294: {"type":"l2update","product_id":"BAND-BTC","changes":[["sell","0.00033539","83.42"]],"time":"2021-04-17T16:43:48.055565Z"}
1618677828.0413702: {"type":"l2update","product_id":"SKL-USD","changes":[["buy","0.7901","0.0"]],"time":"2021-04-17T16:43:48.055655Z"}
1618677828.05181: {"type":"l2update","product_id":"SKL-USD","changes":[["buy","0.7902","0.0"]],"time":"2021-04-17T16:43:48.065290Z"}
1618677828.054058: {"type":"l2update","product_id":"SKL-USD","changes":[["buy","0.7901","450.0"]],"time":"2021-04-17T16:43:48.069851Z"}
1618677828.0541172: {"type":"l2update","product_id":"DASH-BTC","changes":[["buy","0.00618149","5.56400000"]],"time":"2021-04-17T16:43:48.069937Z"}
1618677828.065492: {"type":"l2update","product_id":"SKL-BTC","changes":[["buy","0.00001303","1004.3"]],"time":"2021-04-17T16:43:48.073733Z"}
1618677828.06555: {"type":"l2update","product_id":"SKL-BTC","changes":[["sell","0.00001309","7974.3"]],"time":"2021-04-17T16:43:48.077243Z"}
1618677828.0655842: {"type":"l2update","product_id":"SKL-USD","changes":[["buy","0.7893","2063.5"]],"time":"2021-04-17T16:43:48.077947Z"}
1618677828.07218: {"type":"l2update","product_id":"SKL-BTC","changes":[["buy","0.00001298","7016.3"]],"time":"2021-04-17T16:43:48.084881Z"}
1618677828.072244: {"type":"l2update","product_id":"SKL-USD","changes":[["sell","0.8080","5.0"]],"time":"2021-04-17T16:43:48.088491Z"}
1618677828.08279: {"type":"l2update","product_id":"DASH-BTC","changes":[["sell","0.00620621","0.00000000"]],"time":"2021-04-17T16:43:48.098241Z"}
1618677828.082891: {"type":"l2update","product_id":"SKL-USD","changes":[["sell","0.7921","2630.1"]],"time":"2021-04-17T16:43:48.099370Z"}
1618677828.08725: {"type":"l2update","product_id":"SKL-BTC","changes":[["sell","0.00001307","3788.9"]],"time":"2021-04-17T16:43:48.102813Z"}
1618677828.0925272: {"type":"l2update","product_id":"SKL-BTC","changes":[["buy","0.00001302","8635.8"]],"time":"2021-04-17T16:43:48.105247Z"}
1618677828.092572: {"type":"l2update","product_id":"SKL-BTC","changes":[["buy","0.00001301","18081.9"]],"time":"2021-04-17T16:43:48.106225Z"}
1618677828.0951118: {"type":"l2update","product_id":"DASH-BTC","changes":[["sell","0.00620366","0.00000000"]],"time":"2021-04-17T16:43:48.110454Z"}
1618677828.095165: {"type":"l2update","product_id":"SKL-BTC","changes":[["buy","0.00001305","0.0"]],"time":"2021-04-17T16:43:48.110445Z"}
1618677828.1012402: {"type":"l2update","product_id":"SKL-USD","changes":[["buy","0.7855","8714.5"]],"time":"2021-04-17T16:43:48.114897Z"}
1618677828.101286: {"type":"l2update","product_id":"SKL-BTC","changes":[["sell","0.00001309","8981.0"]],"time":"2021-04-17T16:43:48.114935Z"}
1618677828.107098: {"type":"l2update","product_id":"DASH-BTC","changes":[["sell","0.00620282","3.85900000"]],"time":"2021-04-17T16:43:48.118819Z"}
1618677828.107141: {"type":"l2update","product_id":"BAND-BTC","changes":[["buy","0.00033170","385.09"]],"time":"2021-04-17T16:43:48.119884Z"}
1618677828.107166: {"type":"l2update","product_id":"BAND-BTC","changes":[["buy","0.00033170","338.28"]],"time":"2021-04-17T16:43:48.119884Z"}
1618677828.1071858: {"type":"l2update","product_id":"BAND-BTC","changes":[["buy","0.00033170","226.15"]],"time":"2021-04-17T16:43:48.119884Z"}
1618677828.1072052: {"type":"l2update","product_id":"BAND-BTC","changes":[["buy","0.00033094","0.10"]],"time":"2021-04-17T16:43:48.119884Z"}
1618677828.107223: {"type":"l2update","product_id":"BAND-BTC","changes":[["buy","0.00032746","0.00"]],"time":"2021-04-17T16:43:48.119884Z"}
1618677828.10725: {"type":"l2update","product_id":"SKL-USD","changes":[["buy","0.7898","0.0"]],"time":"2021-04-17T16:43:48.122106Z"}
1618677828.107275: {"type":"l2update","product_id":"SKL-BTC","changes":[["sell","0.00001308","5011.1"]],"time":"2021-04-17T16:43:48.123768Z"}
1618677828.113608: {"type":"l2update","product_id":"SKL-BTC","changes":[["sell","0.00001307","4856.9"]],"time":"2021-04-17T16:43:48.126818Z"}
1618677828.113655: {"type":"l2update","product_id":"DASH-BTC","changes":[["buy","0.00618149","19.25100000"]],"time":"2021-04-17T16:43:48.126842Z"}
1618677828.114638: {"type":"l2update","product_id":"BAND-BTC","changes":[["buy","0.00033345","148.24"]],"time":"2021-04-17T16:43:48.129776Z"}
1618677828.1146948: {"type":"l2update","product_id":"BAND-BTC","changes":[["buy","0.00033294","177.89"]],"time":"2021-04-17T16:43:48.129776Z"}
1618677828.1147258: {"type":"l2update","product_id":"SKL-USD","changes":[["buy","0.7874","0.0"]],"time":"2021-04-17T16:43:48.129833Z"}
1618677828.114754: {"type":"l2update","product_id":"BAND-BTC","changes":[["buy","0.00033244","213.47"]],"time":"2021-04-17T16:43:48.129776Z"}
1618677828.114777: {"type":"l2update","product_id":"SKL-USD","changes":[["sell","0.7925","0.0"]],"time":"2021-04-17T16:43:48.129833Z"}
1618677828.114804: {"type":"l2update","product_id":"SKL-USD","changes":[["sell","0.8008","5.0"]],"time":"2021-04-17T16:43:48.129833Z"}
1618677828.114822: {"type":"l2update","product_id":"BAND-BTC","changes":[["buy","0.00033170","269.07"]],"time":"2021-04-17T16:43:48.129776Z"}
1618677828.11484: {"type":"l2update","product_id":"BAND-BTC","changes":[["buy","0.00033144","307.40"]],"time":"2021-04-17T16:43:48.129776Z"}
1618677828.116849: {"type":"l2update","product_id":"SKL-USD","changes":[["sell","0.7925","1345.8"]],"time":"2021-04-17T16:43:48.131237Z"}
1618677828.1169019: {"type":"l2update","product_id":"DASH-BTC","changes":[["sell","0.00619904","0.00000000"]],"time":"2021-04-17T16:43:48.131569Z"}
1618677828.121166: {"type":"l2update","product_id":"DASH-BTC","changes":[["sell","0.00620365","0.00000000"]],"time":"2021-04-17T16:43:48.135170Z"}
1618677828.121218: {"type":"l2update","product_id":"SKL-BTC","changes":[["buy","0.00001299","3953.7"]],"time":"2021-04-17T16:43:48.136239Z"}
1618677828.1212459: {"type":"l2update","product_id":"SKL-BTC","changes":[["sell","0.00001308","1558.3"]],"time":"2021-04-17T16:43:48.136239Z"}
1618677828.13088: {"type":"l2update","product_id":"BAND-BTC","changes":[["buy","0.00033443","0.00"]],"time":"2021-04-17T16:43:48.145832Z"}
1618677828.13093: {"type":"l2update","product_id":"BAND-GBP","changes":[["buy","14.7617","0.00"]],"time":"2021-04-17T16:43:48.146508Z"}
1618677828.1374788: {"type":"l2update","product_id":"BAND-BTC","changes":[["buy","0.00033435","0.00"]],"time":"2021-04-17T16:43:48.153245Z"}
1618677828.140631: {"type":"l2update","product_id":"DASH-BTC","changes":[["buy","0.00618309","0.00000000"]],"time":"2021-04-17T16:43:48.156182Z"}
1618677828.141979: {"type":"l2update","product_id":"DASH-BTC","changes":[["sell","0.00619903","0.82500000"]],"time":"2021-04-17T16:43:48.157460Z"}
1618677828.144035: {"type":"l2update","product_id":"DASH-BTC","changes":[["buy","0.00618778","3.97300000"]],"time":"2021-04-17T16:43:48.157619Z"}
1618677828.146351: {"type":"l2update","product_id":"DASH-BTC","changes":[["sell","0.00620281","2.57300000"]],"time":"2021-04-17T16:43:48.161487Z"}
1618677828.1464021: {"type":"l2update","product_id":"BAND-BTC","changes":[["buy","0.00033442","0.00"]],"time":"2021-04-17T16:43:48.162174Z"}
1618677828.148777: {"type":"l2update","product_id":"BAND-GBP","changes":[["buy","14.7516","27.55"]],"time":"2021-04-17T16:43:48.165108Z"}
1618677828.151853: {"type":"l2update","product_id":"DASH-BTC","changes":[["sell","0.00620330","0.00000000"]],"time":"2021-04-17T16:43:48.166051Z"}
1618677828.1561759: {"type":"l2update","product_id":"NMR-EUR","changes":[["buy","66.8973","1.303"]],"time":"2021-04-17T16:43:48.172143Z"}
1618677828.156238: {"type":"l2update","product_id":"NMR-EUR","changes":[["buy","66.8973","0.000"]],"time":"2021-04-17T16:43:48.172172Z"}
1618677828.1562822: {"type":"l2update","product_id":"SKL-BTC","changes":[["sell","0.00001307","3788.9"]],"time":"2021-04-17T16:43:48.172664Z"}
1618677828.1614919: {"type":"l2update","product_id":"BAND-BTC","changes":[["buy","0.00033413","29.63"]],"time":"2021-04-17T16:43:48.176522Z"}
1618677828.163657: {"type":"l2update","product_id":"DASH-BTC","changes":[["sell","0.00620283","0.00000000"]],"time":"2021-04-17T16:43:48.177521Z"}
1618677828.175479: {"type":"l2update","product_id":"DASH-BTC","changes":[["sell","0.00620282","6.53400000"]],"time":"2021-04-17T16:43:48.190726Z"}
1618677828.175534: {"type":"l2update","product_id":"SKL-USD","changes":[["sell","0.7938","5.0"]],"time":"2021-04-17T16:43:48.190971Z"}
1618677828.182892: {"type":"l2update","product_id":"BAND-BTC","changes":[["buy","0.00033414","36.76"]],"time":"2021-04-17T16:43:48.198097Z"}
1618677828.18296: {"type":"l2update","product_id":"SKL-USD","changes":[["sell","0.7925","0.0"]],"time":"2021-04-17T16:43:48.199426Z"}
1618677828.18821: {"type":"l2update","product_id":"BAND-BTC","changes":[["buy","0.00033413","0.00"]],"time":"2021-04-17T16:43:48.205182Z"}
1618677828.1930811: {"type":"l2update","product_id":"SKL-BTC","changes":[["sell","0.00001306","3071.2"]],"time":"2021-04-17T16:43:48.206022Z"}
1618677828.193133: {"type":"l2update","product_id":"NMR-EUR","changes":[["buy","66.9036","1.303"]],"time":"2021-04-17T16:43:48.206036Z"}
1618677828.197236: {"type":"l2update","product_id":"DASH-BTC","changes":[["sell","0.00622497","0.00000000"]],"time":"2021-04-17T16:43:48.206578Z"}
1618677828.1972978: {"type":"l2update","product_id":"SKL-USD","changes":[["buy","0.7889","0.0"]],"time":"2021-04-17T16:43:48.206868Z"}
1618677828.1973372: {"type":"l2update","product_id":"BAND-BTC","changes":[["buy","0.00033415","29.63"]],"time":"2021-04-17T16:43:48.209532Z"}
1618677828.197369: {"type":"l2update","product_id":"NMR-EUR","changes":[["buy","66.9036","2.606"]],"time":"2021-04-17T16:43:48.209658Z"}
1618677828.19975: {"type":"l2update","product_id":"DASH-BTC","changes":[["buy","0.00618748","2.70400000"]],"time":"2021-04-17T16:43:48.212570Z"}
1618677828.199853: {"type":"l2update","product_id":"BAND-BTC","changes":[["buy","0.00033232","20.86"]],"time":"2021-04-17T16:43:48.213783Z"}
1618677828.199908: {"type":"l2update","product_id":"NMR-EUR","changes":[["buy","66.9035","0.000"]],"time":"2021-04-17T16:43:48.214111Z"}
1618677828.199966: {"type":"l2update","product_id":"SKL-USD","changes":[["buy","0.7894","2632.7"]],"time":"2021-04-17T16:43:48.216287Z"}
1618677828.200015: {"type":"l2update","product_id":"DASH-BTC","changes":[["sell","0.00620282","4.29800000"]],"time":"2021-04-17T16:43:48.217714Z"}
1618677828.206081: {"type":"l2update","product_id":"NMR-EUR","changes":[["buy","66.9086","4.775"]],"time":"2021-04-17T16:43:48.220106Z"}
1618677828.2061892: {"type":"l2update","product_id":"DASH-BTC","changes":[["sell","0.00621376","16.33900000"]],"time":"2021-04-17T16:43:48.220186Z"}
1618677828.206253: {"type":"l2update","product_id":"YFI-BTC","changes":[["buy","0.82572","0.000000"]],"time":"2021-04-17T16:43:48.222775Z"}
1618677828.210295: {"type":"l2update","product_id":"SKL-USD","changes":[["sell","0.7917","1345.8"]],"time":"2021-04-17T16:43:48.224044Z"}
1618677828.210399: {"type":"l2update","product_id":"DASH-BTC","changes":[["buy","0.00615249","16.28400000"]],"time":"2021-04-17T16:43:48.224447Z"}
1618677828.211581: {"type":"l2update","product_id":"SKL-USD","changes":[["buy","0.7888","868.9"]],"time":"2021-04-17T16:43:48.227874Z"}
1618677828.224419: {"type":"l2update","product_id":"BAND-BTC","changes":[["buy","0.00033346","28.63"]],"time":"2021-04-17T16:43:48.235259Z"}
1618677828.224482: {"type":"l2update","product_id":"DASH-BTC","changes":[["sell","0.00619537","2.50900000"]],"time":"2021-04-17T16:43:48.235304Z"}
1618677828.2245288: {"type":"l2update","product_id":"DASH-BTC","changes":[["sell","0.00620280","2.23600000"]],"time":"2021-04-17T16:43:48.238499Z"}
1618677828.224561: {"type":"l2update","product_id":"NMR-EUR","changes":[["sell","71.7339","0.000"]],"time":"2021-04-17T16:43:48.238591Z"}
1618677828.2245948: {"type":"l2update","product_id":"NMR-EUR","changes":[["sell","71.7840","0.000"]],"time":"2021-04-17T16:43:48.238591Z"}
1618677828.2246242: {"type":"l2update","product_id":"NMR-EUR","changes":[["sell","71.9126","0.000"]],"time":"2021-04-17T16:43:48.238591Z"}
1618677828.22465: {"type":"l2update","product_id":"NMR-EUR","changes":[["buy","66.4812","0.000"]],"time":"2021-04-17T16:43:48.238591Z"}
1618677828.2246778: {"type":"l2update","product_id":"NMR-EUR","changes":[["buy","66.4813","0.000"]],"time":"2021-04-17T16:43:48.238591Z"}
1618677828.227987: {"type":"l2update","product_id":"SKL-USD","changes":[["sell","0.8078","6000.0"]],"time":"2021-04-17T16:43:48.242859Z"}
1618677828.2281: {"type":"l2update","product_id":"BAND-BTC","changes":[["buy","0.00033374","0.00"]],"time":"2021-04-17T16:43:48.244317Z"}
1618677828.232895: {"type":"l2update","product_id":"SKL-USD","changes":[["sell","0.8082","6005.0"]],"time":"2021-04-17T16:43:48.246070Z"}
1618677828.232951: {"type":"l2update","product_id":"DASH-BTC","changes":[["buy","0.00618543","2.66400000"]],"time":"2021-04-17T16:43:48.246823Z"}
1618677828.232985: {"type":"l2update","product_id":"SKL-BTC","changes":[["sell","0.00001310","10601.7"]],"time":"2021-04-17T16:43:48.246545Z"}
1618677828.2350001: {"type":"l2update","product_id":"SKL-USD","changes":[["sell","0.7916","0.0"]],"time":"2021-04-17T16:43:48.250310Z"}
1618677828.2350569: {"type":"l2update","product_id":"DASH-BTC","changes":[["buy","0.00618543","1.12100000"]],"time":"2021-04-17T16:43:48.251366Z"}
1618677828.2371142: {"type":"l2update","product_id":"DASH-BTC","changes":[["sell","0.00620175","2.63700000"]],"time":"2021-04-17T16:43:48.253542Z"}
1618677828.242812: {"type":"l2update","product_id":"BAND-BTC","changes":[["sell","0.00033510","25.74"]],"time":"2021-04-17T16:43:48.257292Z"}
1618677828.2428648: {"type":"l2update","product_id":"SKL-USD","changes":[["sell","0.8078","12000.0"]],"time":"2021-04-17T16:43:48.257356Z"}
1618677828.244883: {"type":"l2update","product_id":"SKL-BTC","changes":[["buy","0.00001302","9617.4"]],"time":"2021-04-17T16:43:48.260995Z"}
1618677828.2482822: {"type":"l2update","product_id":"DASH-BTC","changes":[["sell","0.00620479","14.63200000"]],"time":"2021-04-17T16:43:48.264498Z"}
1618677828.248332: {"type":"l2update","product_id":"DASH-BTC","changes":[["buy","0.00618149","13.68700000"]],"time":"2021-04-17T16:43:48.264823Z"}
1618677828.2516322: {"type":"l2update","product_id":"SKL-USD","changes":[["sell","0.8078","18000.0"]],"time":"2021-04-17T16:43:48.268348Z"}
1618677828.253823: {"type":"l2update","product_id":"DASH-BTC","changes":[["buy","0.00618779","0.29500000"]],"time":"2021-04-17T16:43:48.268617Z"}
1618677828.256311: {"type":"l2update","product_id":"YFI-BTC","changes":[["buy","0.82583","0.017057"]],"time":"2021-04-17T16:43:48.271993Z"}
1618677828.26271: {"type":"l2update","product_id":"BAND-BTC","changes":[["buy","0.00033394","127.50"]],"time":"2021-04-17T16:43:48.278997Z"}
1618677828.269422: {"type":"l2update","product_id":"DASH-BTC","changes":[["buy","0.00618779","1.83800000"]],"time":"2021-04-17T16:43:48.283411Z"}
1618677828.272877: {"type":"l2update","product_id":"DASH-BTC","changes":[["buy","0.00618543","0.00000000"]],"time":"2021-04-17T16:43:48.287913Z"}
1618677828.275112: {"type":"l2update","product_id":"BAND-BTC","changes":[["buy","0.00033397","184.04"]],"time":"2021-04-17T16:43:48.290177Z"}
1618677828.2815979: {"type":"l2update","product_id":"SKL-USD","changes":[["buy","0.7874","3026.1"]],"time":"2021-04-17T16:43:48.290561Z"}
1618677828.281698: {"type":"l2update","product_id":"DASH-BTC","changes":[["buy","0.00618748","0.00000000"]],"time":"2021-04-17T16:43:48.290836Z"}
1618677828.281745: {"type":"l2update","product_id":"SKL-USD","changes":[["sell","0.7916","3643.0"]],"time":"2021-04-17T16:43:48.290561Z"}
1618677828.281782: {"type":"l2update","product_id":"SKL-USD","changes":[["sell","0.7996","23899.8"]],"time":"2021-04-17T16:43:48.290561Z"}
1618677828.28923: {"type":"l2update","product_id":"BAND-GBP","changes":[["buy","14.7473","0.00"]],"time":"2021-04-17T16:43:48.299281Z"}
1618677828.28929: {"type":"l2update","product_id":"SKL-USD","changes":[["sell","0.7943","5.0"]],"time":"2021-04-17T16:43:48.301995Z"}
1618677828.2893188: {"type":"l2update","product_id":"SKL-BTC","changes":[["buy","0.00001299","7657.1"]],"time":"2021-04-17T16:43:48.301879Z"}
1618677828.289342: {"type":"l2update","product_id":"SKL-BTC","changes":[["sell","0.00001306","6700.4"]],"time":"2021-04-17T16:43:48.301879Z"}
1618677828.29364: {"type":"l2update","product_id":"SKL-USD","changes":[["buy","0.7893","867.7"]],"time":"2021-04-17T16:43:48.307890Z"}
1618677828.29702: {"type":"l2update","product_id":"NMR-EUR","changes":[["buy","66.9036","1.303"]],"time":"2021-04-17T16:43:48.309707Z"}
1618677828.297108: {"type":"l2update","product_id":"NMR-EUR","changes":[["buy","66.9036","0.000"]],"time":"2021-04-17T16:43:48.309940Z"}
1618677828.297157: {"type":"l2update","product_id":"DASH-BTC","changes":[["buy","0.00618778","1.40000000"]],"time":"2021-04-17T16:43:48.313266Z"}
1618677828.302114: {"type":"l2update","product_id":"DASH-BTC","changes":[["buy","0.00618150","1.12100000"]],"time":"2021-04-17T16:43:48.313881Z"}
1618677828.307858: {"type":"l2update","product_id":"SKL-BTC","changes":[["buy","0.00001274","10554.9"]],"time":"2021-04-17T16:43:48.319029Z"}
1618677828.317903: {"type":"l2update","product_id":"NMR-EUR","changes":[["buy","66.9087","1.303"]],"time":"2021-04-17T16:43:48.328539Z"}
1618677828.317997: {"type":"l2update","product_id":"NMR-EUR","changes":[["buy","66.9087","2.606"]],"time":"2021-04-17T16:43:48.331965Z"}
1618677828.322315: {"type":"l2update","product_id":"NMR-EUR","changes":[["buy","66.9086","0.000"]],"time":"2021-04-17T16:43:48.337149Z"}
1618677828.322826: {"type":"l2update","product_id":"SKL-USD","changes":[["buy","0.7895","1195.5"]],"time":"2021-04-17T16:43:48.339393Z"}
1618677828.333995: {"type":"l2update","product_id":"NMR-EUR","changes":[["buy","66.9127","4.775"]],"time":"2021-04-17T16:43:48.343379Z"}
1618677828.33987: {"type":"l2update","product_id":"SKL-BTC","changes":[["sell","0.00001306","7359.9"]],"time":"2021-04-17T16:43:48.354982Z"}
1618677828.341231: {"type":"l2update","product_id":"DASH-BTC","changes":[["buy","0.00618187","1.39100000"]],"time":"2021-04-17T16:43:48.357799Z"}
1618677828.3412962: {"type":"l2update","product_id":"DASH-BTC","changes":[["buy","0.00618780","2.57300000"]],"time":"2021-04-17T16:43:48.358198Z"}
1618677828.3469172: {"type":"l2update","product_id":"SKL-GBP","changes":[["buy","0.5723","0.0"]],"time":"2021-04-17T16:43:48.363211Z"}
1618677828.347021: {"type":"l2update","product_id":"SKL-GBP","changes":[["buy","0.5725","5.0"]],"time":"2021-04-17T16:43:48.363211Z"}
1618677828.348852: {"type":"l2update","product_id":"BAND-GBP","changes":[["buy","14.7501","36.00"]],"time":"2021-04-17T16:43:48.364924Z"}
1618677828.351329: {"type":"l2update","product_id":"YFI-BTC","changes":[["buy","0.82336","0.000000"]],"time":"2021-04-17T16:43:48.368177Z"}
1618677828.356844: {"type":"l2update","product_id":"YFI-BTC","changes":[["buy","0.82315","0.011750"]],"time":"2021-04-17T16:43:48.373355Z"}
1618677828.364384: {"type":"l2update","product_id":"SKL-USD","changes":[["sell","0.8088","5.0"]],"time":"2021-04-17T16:43:48.379809Z"}
1618677828.366869: {"type":"l2update","product_id":"SKL-GBP","changes":[["buy","0.5720","1735.0"]],"time":"2021-04-17T16:43:48.380925Z"}
1618677828.36697: {"type":"l2update","product_id":"SKL-GBP","changes":[["buy","0.5706","5788.0"]],"time":"2021-04-17T16:43:48.380925Z"}
1618677828.37318: {"type":"l2update","product_id":"SKL-USD","changes":[["sell","0.8084","1350.0"]],"time":"2021-04-17T16:43:48.387928Z"}
1618677828.376121: {"type":"l2update","product_id":"SKL-GBP","changes":[["buy","0.5746","0.0"]],"time":"2021-04-17T16:43:48.393435Z"}
1618677828.378329: {"type":"l2update","product_id":"SKL-USD","changes":[["sell","0.8082","5.0"]],"time":"2021-04-17T16:43:48.394442Z"}
1618677828.383264: {"type":"l2update","product_id":"SKL-BTC","changes":[["sell","0.00001309","7974.3"]],"time":"2021-04-17T16:43:48.397328Z"}
1618677828.390988: {"type":"l2update","product_id":"SKL-USD","changes":[["buy","0.7893","0.0"]],"time":"2021-04-17T16:43:48.405988Z"}
1618677828.412801: {"type":"l2update","product_id":"SKL-USD","changes":[["buy","0.7895","2063.0"]],"time":"2021-04-17T16:43:48.426280Z"}
1618677828.4248269: {"type":"l2update","product_id":"BAND-BTC","changes":[["sell","0.00033510","0.00"]],"time":"2021-04-17T16:43:48.439847Z"}
1618677828.426912: {"type":"l2update","product_id":"DASH-BTC","changes":[["sell","0.00620282","2.67500000"]],"time":"2021-04-17T16:43:48.442345Z"}
1618677828.431179: {"type":"l2update","product_id":"SKL-USD","changes":[["buy","0.7874","0.0"]],"time":"2021-04-17T16:43:48.445029Z"}
1618677828.431248: {"type":"l2update","product_id":"SKL-USD","changes":[["buy","0.7795","117155.0"]],"time":"2021-04-17T16:43:48.445029Z"}
1618677828.431283: {"type":"l2update","product_id":"SKL-USD","changes":[["sell","0.7916","0.0"]],"time":"2021-04-17T16:43:48.445029Z"}
1618677828.441032: {"type":"l2update","product_id":"SKL-BTC","changes":[["buy","0.00001299","3953.7"]],"time":"2021-04-17T16:43:48.456284Z"}
1618677828.441098: {"type":"l2update","product_id":"SKL-BTC","changes":[["sell","0.00001306","3730.7"]],"time":"2021-04-17T16:43:48.456284Z"}
1618677828.4496288: {"type":"l2update","product_id":"SKL-USD","changes":[["sell","0.7928","7070.8"]],"time":"2021-04-17T16:43:48.463827Z"}
1618677828.449697: {"type":"l2update","product_id":"DASH-BTC","changes":[["sell","0.00620280","3.85900000"]],"time":"2021-04-17T16:43:48.464026Z"}
1618677828.452839: {"type":"l2update","product_id":"NMR-EUR","changes":[["buy","66.9087","1.303"]],"time":"2021-04-17T16:43:48.467545Z"}
1618677828.4528909: {"type":"l2update","product_id":"NMR-EUR","changes":[["buy","66.9087","0.000"]],"time":"2021-04-17T16:43:48.467951Z"}
1618677828.452935: {"type":"l2update","product_id":"DASH-BTC","changes":[["sell","0.00619903","0.00000000"]],"time":"2021-04-17T16:43:48.468330Z"}
1618677828.461338: {"type":"l2update","product_id":"BAND-BTC","changes":[["buy","0.00033381","51.44"]],"time":"2021-04-17T16:43:48.477037Z"}
1618677828.461403: {"type":"l2update","product_id":"SKL-GBP","changes":[["buy","0.5739","1268.6"]],"time":"2021-04-17T16:43:48.476800Z"}
1618677828.4773068: {"type":"l2update","product_id":"DASH-BTC","changes":[["sell","0.00619536","0.82500000"]],"time":"2021-04-17T16:43:48.489305Z"}
1618677828.479146: {"type":"l2update","product_id":"NMR-EUR","changes":[["buy","66.9128","1.303"]],"time":"2021-04-17T16:43:48.493696Z"}
1618677828.481817: {"type":"l2update","product_id":"NMR-EUR","changes":[["buy","66.9128","2.606"]],"time":"2021-04-17T16:43:48.496879Z"}
1618677828.485495: {"type":"l2update","product_id":"NMR-EUR","changes":[["buy","66.9127","0.000"]],"time":"2021-04-17T16:43:48.502198Z"}
1618677828.4949062: {"type":"l2update","product_id":"NMR-EUR","changes":[["buy","66.9159","4.774"]],"time":"2021-04-17T16:43:48.507856Z"}
1618677828.50085: {"type":"l2update","product_id":"DASH-BTC","changes":[["buy","0.00614337","0.00000000"]],"time":"2021-04-17T16:43:48.515164Z"}
1618677828.5009532: {"type":"l2update","product_id":"DASH-BTC","changes":[["buy","0.00614338","0.11000000"]],"time":"2021-04-17T16:43:48.515164Z"}
1618677828.5080478: {"type":"l2update","product_id":"DASH-BTC","changes":[["buy","0.00614342","2.46000000"]],"time":"2021-04-17T16:43:48.522662Z"}
1618677828.508112: {"type":"l2update","product_id":"DASH-BTC","changes":[["buy","0.00614341","3.19000000"]],"time":"2021-04-17T16:43:48.522662Z"}
1618677828.51866: {"type":"l2update","product_id":"DASH-BTC","changes":[["buy","0.00618009","5.56400000"]],"time":"2021-04-17T16:43:48.534474Z"}
1618677828.53511: {"type":"l2update","product_id":"DASH-BTC","changes":[["buy","0.00618595","2.66200000"]],"time":"2021-04-17T16:43:48.552012Z"}
1618677828.5403378: {"type":"l2update","product_id":"BAND-BTC","changes":[["sell","0.00033598","0.00"]],"time":"2021-04-17T16:43:48.554969Z"}
1618677828.541845: {"type":"l2update","product_id":"DASH-BTC","changes":[["sell","0.00619930","2.68300000"]],"time":"2021-04-17T16:43:48.557128Z"}
1618677828.541897: {"type":"l2update","product_id":"NMR-EUR","changes":[["buy","66.9128","1.303"]],"time":"2021-04-17T16:43:48.557290Z"}
1618677828.541924: {"type":"l2update","product_id":"NMR-EUR","changes":[["buy","66.9128","0.000"]],"time":"2021-04-17T16:43:48.557394Z"}
1618677828.551518: {"type":"l2update","product_id":"YFI-BTC","changes":[["sell","0.82731","0.000000"]],"time":"2021-04-17T16:43:48.566918Z"}
1618677828.5566: {"type":"l2update","product_id":"SKL-BTC","changes":[["sell","0.00001309","6657.1"]],"time":"2021-04-17T16:43:48.571653Z"}
1618677828.556677: {"type":"l2update","product_id":"SKL-USD","changes":[["sell","0.7937","5.0"]],"time":"2021-04-17T16:43:48.571989Z"}
1618677828.556705: {"type":"l2update","product_id":"SKL-GBP","changes":[["buy","0.5724","90.0"]],"time":"2021-04-17T16:43:48.573554Z"}
1618677828.556727: {"type":"l2update","product_id":"SKL-USD","changes":[["sell","0.7921","0.0"]],"time":"2021-04-17T16:43:48.574107Z"}
1618677828.5616949: {"type":"l2update","product_id":"SKL-BTC","changes":[["buy","0.00001279","439.5"]],"time":"2021-04-17T16:43:48.577240Z"}
1618677828.569161: {"type":"l2update","product_id":"YFI-BTC","changes":[["buy","0.82524","0.030000"]],"time":"2021-04-17T16:43:48.583124Z"}
1618677828.571284: {"type":"l2update","product_id":"DASH-BTC","changes":[["buy","0.00618779","1.54300000"]],"time":"2021-04-17T16:43:48.586613Z"}
1618677828.572329: {"type":"l2update","product_id":"NMR-EUR","changes":[["buy","66.8895","1.303"]],"time":"2021-04-17T16:43:48.587992Z"}
1618677828.572733: {"type":"l2update","product_id":"BAND-BTC","changes":[["buy","0.00033232","0.00"]],"time":"2021-04-17T16:43:48.588968Z"}
1618677828.572783: {"type":"l2update","product_id":"DASH-BTC","changes":[["sell","0.00620497","0.00000000"]],"time":"2021-04-17T16:43:48.590343Z"}
1618677828.577549: {"type":"l2update","product_id":"NMR-EUR","changes":[["buy","66.8895","2.606"]],"time":"2021-04-17T16:43:48.592753Z"}
1618677828.591476: {"type":"l2update","product_id":"SKL-USD","changes":[["buy","0.7875","3708.6"]],"time":"2021-04-17T16:43:48.605992Z"}
1618677828.591531: {"type":"l2update","product_id":"SKL-USD","changes":[["buy","0.7796","76103.8"]],"time":"2021-04-17T16:43:48.605992Z"}
1618677828.591557: {"type":"l2update","product_id":"SKL-USD","changes":[["sell","0.7916","3628.9"]],"time":"2021-04-17T16:43:48.605992Z"}
1618677828.591585: {"type":"l2update","product_id":"SKL-USD","changes":[["sell","0.7996","24317.6"]],"time":"2021-04-17T16:43:48.605992Z"}
1618677828.591604: {"type":"l2update","product_id":"DASH-BTC","changes":[["buy","0.00618596","0.29500000"]],"time":"2021-04-17T16:43:48.606192Z"}
1618677828.5916271: {"type":"l2update","product_id":"SKL-BTC","changes":[["sell","0.00001315","26900.1"]],"time":"2021-04-17T16:43:48.607505Z"}
1618677828.591646: {"type":"l2update","product_id":"SKL-BTC","changes":[["sell","0.00001329","21.6"]],"time":"2021-04-17T16:43:48.607505Z"}
1618677828.594934: {"type":"l2update","product_id":"DASH-BTC","changes":[["buy","0.00618779","0.00000000"]],"time":"2021-04-17T16:43:48.612036Z"}
1618677828.594978: {"type":"l2update","product_id":"NMR-EUR","changes":[["buy","66.8895","1.303"]],"time":"2021-04-17T16:43:48.612410Z"}
1618677828.598104: {"type":"l2update","product_id":"NMR-EUR","changes":[["buy","66.8895","0.000"]],"time":"2021-04-17T16:43:48.613113Z"}
1618677828.6044118: {"type":"l2update","product_id":"BAND-BTC","changes":[["buy","0.00033323","20.81"]],"time":"2021-04-17T16:43:48.617698Z"}
1618677828.604461: {"type":"l2update","product_id":"SKL-BTC","changes":[["buy","0.00001299","6880.8"]],"time":"2021-04-17T16:43:48.618109Z"}
1618677828.604488: {"type":"l2update","product_id":"SKL-BTC","changes":[["sell","0.00001306","7228.8"]],"time":"2021-04-17T16:43:48.618109Z"}
1618677828.604508: {"type":"l2update","product_id":"SKL-BTC","changes":[["sell","0.00001309","6827.9"]],"time":"2021-04-17T16:43:48.618244Z"}
1618677828.6053681: {"type":"l2update","product_id":"YFI-BTC","changes":[["buy","0.82512","0.000000"]],"time":"2021-04-17T16:43:48.621380Z"}
1618677828.612909: {"type":"l2update","product_id":"DASH-BTC","changes":[["sell","0.00620478","1.62300000"]],"time":"2021-04-17T16:43:48.621695Z"}
1618677828.61296: {"type":"l2update","product_id":"SKL-USD","changes":[["sell","0.7914","2632.8"]],"time":"2021-04-17T16:43:48.625780Z"}
1618677828.615863: {"type":"l2update","product_id":"SKL-BTC","changes":[["buy","0.00001303","110.0"]],"time":"2021-04-17T16:43:48.632603Z"}
1618677828.6168709: {"type":"l2update","product_id":"DASH-BTC","changes":[["buy","0.00618596","1.83800000"]],"time":"2021-04-17T16:43:48.632975Z"}
1618677828.627404: {"type":"l2update","product_id":"SKL-GBP","changes":[["buy","0.5720","2235.0"]],"time":"2021-04-17T16:43:48.642972Z"}
1618677828.627449: {"type":"l2update","product_id":"SKL-USD","changes":[["sell","0.7915","0.0"]],"time":"2021-04-17T16:43:48.643335Z"}
1618677828.6330812: {"type":"l2update","product_id":"NMR-EUR","changes":[["buy","66.9160","1.303"]],"time":"2021-04-17T16:43:48.647061Z"}
1618677828.641852: {"type":"l2update","product_id":"SKL-USD","changes":[["sell","0.7913","1017.5"]],"time":"2021-04-17T16:43:48.650486Z"}
1618677828.641902: {"type":"l2update","product_id":"SKL-BTC","changes":[["buy","0.00001302","10512.1"]],"time":"2021-04-17T16:43:48.650388Z"}
1618677828.641929: {"type":"l2update","product_id":"NMR-EUR","changes":[["buy","66.9160","2.606"]],"time":"2021-04-17T16:43:48.650567Z"}
1618677828.642772: {"type":"l2update","product_id":"NMR-EUR","changes":[["buy","66.9159","0.000"]],"time":"2021-04-17T16:43:48.658535Z"}
1618677828.649538: {"type":"l2update","product_id":"NMR-EUR","changes":[["buy","66.9185","4.774"]],"time":"2021-04-17T16:43:48.665084Z"}
1618677828.6608179: {"type":"l2update","product_id":"BAND-BTC","changes":[["buy","0.00033239","18.59"]],"time":"2021-04-17T16:43:48.676567Z"}
1618677828.660883: {"type":"l2update","product_id":"YFI-BTC","changes":[["sell","0.82732","0.000000"]],"time":"2021-04-17T16:43:48.678406Z"}
1618677828.667199: {"type":"l2update","product_id":"YFI-BTC","changes":[["buy","0.82615","0.019261"]],"time":"2021-04-17T16:43:48.683758Z"}
1618677828.675885: {"type":"l2update","product_id":"YFI-BTC","changes":[["buy","0.82533","0.030000"]],"time":"2021-04-17T16:43:48.692197Z"}
1618677828.6832142: {"type":"l2update","product_id":"YFI-BTC","changes":[["sell","0.82792","0.020558"]],"time":"2021-04-17T16:43:48.699337Z"}
1618677828.6899981: {"type":"l2update","product_id":"SKL-BTC","changes":[["sell","0.00001310","11424.5"]],"time":"2021-04-17T16:43:48.702908Z"}
1618677828.696803: {"type":"l2update","product_id":"SKL-BTC","changes":[["sell","0.00001306","6569.3"]],"time":"2021-04-17T16:43:48.712195Z"}
1618677828.702283: {"type":"l2update","product_id":"BAND-BTC","changes":[["sell","0.00033515","25.74"]],"time":"2021-04-17T16:43:48.717405Z"}
1618677828.726597: {"type":"l2update","product_id":"BAND-BTC","changes":[["buy","0.00033170","226.15"]],"time":"2021-04-17T16:43:48.739695Z"}
1618677828.730346: {"type":"l2update","product_id":"BAND-BTC","changes":[["sell","0.00033625","0.94"]],"time":"2021-04-17T16:43:48.746313Z"}
1618677828.747123: {"type":"l2update","product_id":"DASH-BTC","changes":[["sell","0.00619930","0.00000000"]],"time":"2021-04-17T16:43:48.749485Z"}
1618677828.7472398: {"type":"l2update","product_id":"DASH-BTC","changes":[["sell","0.00619537","0.00000000"]],"time":"2021-04-17T16:43:48.755420Z"}
1618677828.747303: {"type":"l2update","product_id":"NMR-EUR","changes":[["buy","66.4818","33.000"]],"time":"2021-04-17T16:43:48.757452Z"}
1618677828.74735: {"type":"l2update","product_id":"NMR-EUR","changes":[["sell","72.0976","19.820"]],"time":"2021-04-17T16:43:48.757452Z"}
1618677828.747398: {"type":"l2update","product_id":"NMR-EUR","changes":[["buy","66.4817","1.790"]],"time":"2021-04-17T16:43:48.757452Z"}
1618677828.747434: {"type":"l2update","product_id":"NMR-EUR","changes":[["sell","71.9763","19.150"]],"time":"2021-04-17T16:43:48.757452Z"}
1618677828.747473: {"type":"l2update","product_id":"NMR-EUR","changes":[["sell","71.9126","2.300"]],"time":"2021-04-17T16:43:48.757452Z"}
1618677828.74751: {"type":"l2update","product_id":"SKL-USD","changes":[["buy","0.7875","0.0"]],"time":"2021-04-17T16:43:48.760870Z"}
1618677828.7475579: {"type":"l2update","product_id":"SKL-USD","changes":[["buy","0.7796","5.0"]],"time":"2021-04-17T16:43:48.760870Z"}
1618677828.747592: {"type":"l2update","product_id":"SKL-USD","changes":[["sell","0.7916","0.0"]],"time":"2021-04-17T16:43:48.760870Z"}
1618677828.7476559: {"type":"l2update","product_id":"SKL-USD","changes":[["sell","0.7996","23899.8"]],"time":"2021-04-17T16:43:48.760870Z"}
1618677828.753917: {"type":"l2update","product_id":"YFI-BTC","changes":[["buy","0.82314","0.000000"]],"time":"2021-04-17T16:43:48.768947Z"}
1618677828.762729: {"type":"l2update","product_id":"YFI-BTC","changes":[["buy","0.82316","0.013010"]],"time":"2021-04-17T16:43:48.775686Z"}
1618677828.764093: {"type":"l2update","product_id":"SKL-BTC","changes":[["buy","0.00001299","7011.5"]],"time":"2021-04-17T16:43:48.779356Z"}
1618677828.7641358: {"type":"l2update","product_id":"SKL-BTC","changes":[["sell","0.00001306","6767.6"]],"time":"2021-04-17T16:43:48.779356Z"}
1618677828.77562: {"type":"l2update","product_id":"NMR-EUR","changes":[["buy","66.9160","1.303"]],"time":"2021-04-17T16:43:48.791348Z"}
1618677828.775734: {"type":"l2update","product_id":"SKL-USD","changes":[["sell","0.7917","0.0"]],"time":"2021-04-17T16:43:48.791674Z"}
1618677828.775784: {"type":"l2update","product_id":"NMR-EUR","changes":[["buy","66.9160","0.000"]],"time":"2021-04-17T16:43:48.791995Z"}
1618677828.7832031: {"type":"l2update","product_id":"SKL-BTC","changes":[["sell","0.00001307","5107.8"]],"time":"2021-04-17T16:43:48.797896Z"}
1618677828.7863061: {"type":"l2update","product_id":"SKL-USD","changes":[["sell","0.7919","1318.9"]],"time":"2021-04-17T16:43:48.801650Z"}
1618677828.806467: {"type":"l2update","product_id":"SKL-USD","changes":[["sell","0.7916","1344.8"]],"time":"2021-04-17T16:43:48.816104Z"}
1618677828.806581: {"type":"l2update","product_id":"NMR-EUR","changes":[["buy","66.9186","1.303"]],"time":"2021-04-17T16:43:48.816312Z"}
1618677828.806645: {"type":"l2update","product_id":"NMR-EUR","changes":[["buy","66.9186","2.606"]],"time":"2021-04-17T16:43:48.819793Z"}
1618677828.811341: {"type":"l2update","product_id":"NMR-EUR","changes":[["buy","66.9185","0.000"]],"time":"2021-04-17T16:43:48.826932Z"}
1618677828.824529: {"type":"l2update","product_id":"NMR-EUR","changes":[["buy","66.9206","4.774"]],"time":"2021-04-17T16:43:48.834566Z"}
1618677828.828703: {"type":"l2update","product_id":"DASH-BTC","changes":[["sell","0.00619536","0.00000000"]],"time":"2021-04-17T16:43:48.844736Z"}
1618677828.828778: {"type":"l2update","product_id":"SKL-BTC","changes":[["sell","0.00001312","3069.2"]],"time":"2021-04-17T16:43:48.845499Z"}
1618677828.83407: {"type":"l2update","product_id":"NMR-EUR","changes":[["sell","71.9764","0.000"]],"time":"2021-04-17T16:43:48.846429Z"}
1618677828.8341382: {"type":"l2update","product_id":"NMR-EUR","changes":[["sell","71.9127","0.000"]],"time":"2021-04-17T16:43:48.846429Z"}
1618677828.839297: {"type":"l2update","product_id":"SKL-BTC","changes":[["sell","0.00001315","25329.9"]],"time":"2021-04-17T16:43:48.850626Z"}
1618677828.842637: {"type":"l2update","product_id":"NMR-EUR","changes":[["sell","71.9762","18.390"]],"time":"2021-04-17T16:43:48.852826Z"}
1618677828.84269: {"type":"l2update","product_id":"NMR-EUR","changes":[["sell","71.9125","14.500"]],"time":"2021-04-17T16:43:48.852826Z"}
1618677828.8446589: {"type":"l2update","product_id":"YFI-BTC","changes":[["sell","0.82738","0.019435"]],"time":"2021-04-17T16:43:48.860873Z"}
1618677828.847834: {"type":"l2update","product_id":"SKL-USD","changes":[["buy","0.7909","425.2"]],"time":"2021-04-17T16:43:48.864056Z"}
1618677828.8508742: {"type":"l2update","product_id":"SKL-USD","changes":[["sell","0.7944","5.0"]],"time":"2021-04-17T16:43:48.866539Z"}
1618677828.850915: {"type":"l2update","product_id":"DASH-BTC","changes":[["sell","0.00621783","0.00000000"]],"time":"2021-04-17T16:43:48.866595Z"}
1618677828.8509572: {"type":"l2update","product_id":"DASH-BTC","changes":[["sell","0.00620174","0.82500000"]],"time":"2021-04-17T16:43:48.867904Z"}
1618677828.8560588: {"type":"l2update","product_id":"YFI-BTC","changes":[["buy","0.82548","0.030056"]],"time":"2021-04-17T16:43:48.871445Z"}
1618677828.856575: {"type":"l2update","product_id":"SKL-BTC","changes":[["sell","0.00001355","3483.8"]],"time":"2021-04-17T16:43:48.871663Z"}
1618677828.8588128: {"type":"l2update","product_id":"BAND-BTC","changes":[["sell","0.00033491","54.02"]],"time":"2021-04-17T16:43:48.875135Z"}
1618677828.858853: {"type":"l2update","product_id":"SKL-USD","changes":[["sell","0.7952","1262.5"]],"time":"2021-04-17T16:43:48.875210Z"}
1618677828.858876: {"type":"l2update","product_id":"SKL-BTC","changes":[["sell","0.00001319","84.0"]],"time":"2021-04-17T16:43:48.876579Z"}
1618677828.8607528: {"type":"l2update","product_id":"SKL-USD","changes":[["buy","0.7909","425.0"]],"time":"2021-04-17T16:43:48.875223Z"}
1618677828.860798: {"type":"match","trade_id":1568277,"maker_order_id":"d38df598-50d8-43d4-a669-98f87188ec0a","taker_order_id":"39d1f7b4-3221-425f-af5b-6f7d97bc5abe","side":"buy","size":"0.2","price":"0.7909","product_id":"SKL-USD","sequence":201391406,"time":"2021-04-17T16:43:48.875223Z"}
1618677828.860828: {"type":"ticker","sequence":201391406,"product_id":"SKL-USD","price":"0.7909","open_24h":"0.7055","volume_24h":"34258463.20000000","low_24h":"0.6915","high_24h":"0.8098","volume_30d":"948685815.90000000","best_bid":"0.7909","best_ask":"0.7913","side":"sell","time":"2021-04-17T16:43:48.875223Z","trade_id":1568277,"last_size":"0.2"}
1618677828.863223: {"type":"l2update","product_id":"SKL-USD","changes":[["buy","0.7909","0.2"]],"time":"2021-04-17T16:43:48.875223Z"}
1618677828.8632698: {"type":"match","trade_id":1568278,"maker_order_id":"2a7e8558-8fb4-440d-88b7-81bddb88228b","taker_order_id":"39d1f7b4-3221-425f-af5b-6f7d97bc5abe","side":"buy","size":"424.8","price":"0.7909","product_id":"SKL-USD","sequence":201391408,"time":"2021-04-17T16:43:48.875223Z"}
1618677828.8632991: {"type":"ticker","sequence":201391408,"product_id":"SKL-USD","price":"0.7909","open_24h":"0.7055","volume_24h":"34258888.00000000","low_24h":"0.6915","high_24h":"0.8098","volume_30d":"948686240.70000000","best_bid":"0.7909","best_ask":"0.7913","side":"sell","time":"2021-04-17T16:43:48.875223Z","trade_id":1568278,"last_size":"424.8"}
1618677828.8694332: {"type":"l2update","product_id":"SKL-USD","changes":[["sell","0.7952","5.0"]],"time":"2021-04-17T16:43:48.882803Z"}
1618677828.870836: {"type":"l2update","product_id":"SKL-GBP","changes":[["sell","0.5784","0.0"]],"time":"2021-04-17T16:43:48.886292Z"}
1618677828.8708868: {"type":"l2update","product_id":"YFI-BTC","changes":[["buy","0.82524","0.000000"]],"time":"2021-04-17T16:43:48.887331Z"}
1618677828.876003: {"type":"l2update","product_id":"BAND-BTC","changes":[["sell","0.00033474","19.39"]],"time":"2021-04-17T16:43:48.890629Z"}
1618677828.894306: {"type":"l2update","product_id":"BAND-BTC","changes":[["sell","0.00033480","20.00"]],"time":"2021-04-17T16:43:48.908410Z"}
1618677828.895085: {"type":"l2update","product_id":"BAND-GBP","changes":[["buy","14.7542","123.22"]],"time":"2021-04-17T16:43:48.911962Z"}
1618677828.899755: {"type":"l2update","product_id":"SKL-USD","changes":[["sell","0.7913","895.7"]],"time":"2021-04-17T16:43:48.915339Z"}
1618677828.8998442: {"type":"ticker","sequence":201391412,"product_id":"SKL-USD","price":"0.7913","open_24h":"0.7055","volume_24h":"34259009.80000000","low_24h":"0.6915","high_24h":"0.8098","volume_30d":"948686362.50000000","best_bid":"0.7909","best_ask":"0.7913","side":"buy","time":"2021-04-17T16:43:48.915339Z","trade_id":1568279,"last_size":"121.8"}
1618677828.899894: {"type":"match","trade_id":1568279,"maker_order_id":"3394aa6c-938a-4a81-8c70-fe288cc7a94d","taker_order_id":"8e02ba52-96b6-44a4-9083-46144008e98b","side":"sell","size":"121.8","price":"0.7913","product_id":"SKL-USD","sequence":201391412,"time":"2021-04-17T16:43:48.915339Z"}
1618677828.902926: {"type":"l2update","product_id":"SKL-BTC","changes":[["sell","0.00001307","5767.4"]],"time":"2021-04-17T16:43:48.919069Z"}
1618677828.9030132: {"type":"l2update","product_id":"BAND-GBP","changes":[["buy","14.7516","0.00"]],"time":"2021-04-17T16:43:48.919486Z"}
1618677828.903082: {"type":"l2update","product_id":"YFI-BTC","changes":[["sell","0.82937","0.000000"]],"time":"2021-04-17T16:43:48.919466Z"}
1618677828.909174: {"type":"l2update","product_id":"BAND-GBP","changes":[["sell","14.7886","123.26"]],"time":"2021-04-17T16:43:48.922876Z"}
1618677828.912549: {"type":"l2update","product_id":"BAND-GBP","changes":[["buy","14.7544","27.54"]],"time":"2021-04-17T16:43:48.926375Z"}
1618677828.9126458: {"type":"l2update","product_id":"SKL-USD","changes":[["buy","0.7871","7672.1"]],"time":"2021-04-17T16:43:48.926402Z"}
1618677828.9127: {"type":"l2update","product_id":"SKL-USD","changes":[["buy","0.7796","76103.8"]],"time":"2021-04-17T16:43:48.926402Z"}
1618677828.9127412: {"type":"l2update","product_id":"BAND-GBP","changes":[["buy","14.7608","12.37"]],"time":"2021-04-17T16:43:48.926428Z"}
1618677828.9127831: {"type":"l2update","product_id":"SKL-USD","changes":[["sell","0.7916","4973.7"]],"time":"2021-04-17T16:43:48.926402Z"}
1618677828.912821: {"type":"l2update","product_id":"SKL-USD","changes":[["sell","0.7996","24317.6"]],"time":"2021-04-17T16:43:48.926402Z"}
1618677828.916628: {"type":"l2update","product_id":"SKL-USD","changes":[["sell","0.7916","3628.9"]],"time":"2021-04-17T16:43:48.930370Z"}
1618677828.916713: {"type":"l2update","product_id":"NMR-EUR","changes":[["buy","66.9186","1.303"]],"time":"2021-04-17T16:43:48.930396Z"}
1618677828.916764: {"type":"l2update","product_id":"NMR-EUR","changes":[["buy","66.9186","0.000"]],"time":"2021-04-17T16:43:48.930814Z"}
1618677828.916822: {"type":"l2update","product_id":"SKL-BTC","changes":[["buy","0.00001299","6880.8"]],"time":"2021-04-17T16:43:48.933195Z"}
1618677828.916862: {"type":"l2update","product_id":"SKL-BTC","changes":[["buy","0.00001299","3953.7"]],"time":"2021-04-17T16:43:48.933195Z"}
1618677828.916896: {"type":"l2update","product_id":"SKL-BTC","changes":[["sell","0.00001306","6569.3"]],"time":"2021-04-17T16:43:48.933195Z"}
1618677828.920034: {"type":"l2update","product_id":"SKL-BTC","changes":[["sell","0.00001334","36026.0"]],"time":"2021-04-17T16:43:48.934431Z"}
1618677828.9201229: {"type":"l2update","product_id":"SKL-BTC","changes":[["sell","0.00001333","0.0"]],"time":"2021-04-17T16:43:48.934431Z"}
1618677828.9201941: {"type":"l2update","product_id":"SKL-BTC","changes":[["sell","0.00001327","5.0"]],"time":"2021-04-17T16:43:48.934431Z"}
1618677828.9325252: {"type":"l2update","product_id":"NMR-EUR","changes":[["buy","66.9207","1.303"]],"time":"2021-04-17T16:43:48.944962Z"}
1618677828.932621: {"type":"l2update","product_id":"SKL-USD","changes":[["buy","0.7855","8469.5"]],"time":"2021-04-17T16:43:48.946368Z"}
1618677828.933898: {"type":"l2update","product_id":"NMR-EUR","changes":[["buy","66.9207","2.606"]],"time":"2021-04-17T16:43:48.948503Z"}
1618677828.933986: {"type":"l2update","product_id":"SKL-USD","changes":[["sell","0.7915","1344.8"]],"time":"2021-04-17T16:43:48.948564Z"}
1618677828.9356859: {"type":"l2update","product_id":"SKL-USD","changes":[["buy","0.7855","8714.5"]],"time":"2021-04-17T16:43:48.952034Z"}
1618677828.938439: {"type":"l2update","product_id":"NMR-EUR","changes":[["buy","66.9206","0.000"]],"time":"2021-04-17T16:43:48.953785Z"}
1618677828.9385412: {"type":"l2update","product_id":"BAND-BTC","changes":[["buy","0.00033351","0.00"]],"time":"2021-04-17T16:43:48.954211Z"}
1618677828.9406111: {"type":"l2update","product_id":"SKL-USD","changes":[["sell","0.7942","5.0"]],"time":"2021-04-17T16:43:48.956668Z"}
1618677828.9406972: {"type":"l2update","product_id":"YFI-BTC","changes":[["buy","0.82548","0.000000"]],"time":"2021-04-17T16:43:48.957275Z"}
1618677828.948305: {"type":"l2update","product_id":"BAND-BTC","changes":[["buy","0.00033346","0.00"]],"time":"2021-04-17T16:43:48.958315Z"}
1618677828.9484: {"type":"l2update","product_id":"DASH-BTC","changes":[["buy","0.00618596","1.54300000"]],"time":"2021-04-17T16:43:48.958852Z"}
1618677828.948438: {"type":"l2update","product_id":"NMR-EUR","changes":[["buy","66.9223","4.774"]],"time":"2021-04-17T16:43:48.959597Z"}
1618677828.948472: {"type":"l2update","product_id":"DASH-BTC","changes":[["buy","0.00618596","0.00000000"]],"time":"2021-04-17T16:43:48.961771Z"}
1618677828.9485052: {"type":"l2update","product_id":"SKL-BTC","changes":[["sell","0.00001354","1588.8"]],"time":"2021-04-17T16:43:48.963017Z"}
1618677828.948537: {"type":"l2update","product_id":"BAND-BTC","changes":[["sell","0.00033490","0.00"]],"time":"2021-04-17T16:43:48.963423Z"}
1618677828.948568: {"type":"l2update","product_id":"SKL-BTC","changes":[["sell","0.00001309","8770.5"]],"time":"2021-04-17T16:43:48.963017Z"}
1618677828.948591: {"type":"l2update","product_id":"DASH-BTC","changes":[["buy","0.00618150","0.00000000"]],"time":"2021-04-17T16:43:48.964049Z"}
1618677828.9515252: {"type":"l2update","product_id":"SKL-BTC","changes":[["sell","0.00001311","170.8"]],"time":"2021-04-17T16:43:48.967172Z"}
1618677828.959711: {"type":"l2update","product_id":"BAND-BTC","changes":[["buy","0.00033323","41.62"]],"time":"2021-04-17T16:43:48.974372Z"}
1618677828.961895: {"type":"l2update","product_id":"SKL-USD","changes":[["sell","0.7927","30868.4"]],"time":"2021-04-17T16:43:48.977960Z"}
1618677828.969394: {"type":"l2update","product_id":"BAND-BTC","changes":[["buy","0.00033323","70.27"]],"time":"2021-04-17T16:43:48.985176Z"}
1618677828.96948: {"type":"l2update","product_id":"YFI-BTC","changes":[["buy","0.82615","0.000000"]],"time":"2021-04-17T16:43:48.985959Z"}
1618677828.9741702: {"type":"l2update","product_id":"YFI-BTC","changes":[["sell","0.82715","0.019834"]],"time":"2021-04-17T16:43:48.988918Z"}
1618677828.974272: {"type":"l2update","product_id":"SKL-BTC","changes":[["sell","0.00001355","2064.1"]],"time":"2021-04-17T16:43:48.989633Z"}
1618677828.9743261: {"type":"l2update","product_id":"SKL-BTC","changes":[["sell","0.00001355","889.0"]],"time":"2021-04-17T16:43:48.989633Z"}
1618677828.974365: {"type":"l2update","product_id":"SKL-BTC","changes":[["sell","0.00001349","0.0"]],"time":"2021-04-17T16:43:48.989633Z"}
1618677828.974415: {"type":"l2update","product_id":"SKL-BTC","changes":[["sell","0.00001342","300.0"]],"time":"2021-04-17T16:43:48.989633Z"}
1618677828.9744499: {"type":"l2update","product_id":"SKL-BTC","changes":[["sell","0.00001338","0.0"]],"time":"2021-04-17T16:43:48.989633Z"}
1618677828.9744902: {"type":"l2update","product_id":"SKL-BTC","changes":[["sell","0.00001312","1570.2"]],"time":"2021-04-17T16:43:48.989633Z"}
1618677828.978376: {"type":"l2update","product_id":"YFI-BTC","changes":[["buy","0.82582","0.000000"]],"time":"2021-04-17T16:43:48.994418Z"}
1618677828.984958: {"type":"l2update","product_id":"SKL-USD","changes":[["sell","0.7978","2790.8"]],"time":"2021-04-17T16:43:49.001070Z"}
1618677828.991083: {"type":"l2update","product_id":"SKL-BTC","changes":[["buy","0.00001302","9530.5"]],"time":"2021-04-17T16:43:49.003224Z"}
1618677828.991173: {"type":"l2update","product_id":"SKL-BTC","changes":[["sell","0.00001310","10601.7"]],"time":"2021-04-17T16:43:49.003224Z"}
1618677828.9912262: {"type":"l2update","product_id":"DASH-BTC","changes":[["sell","0.00619641","2.50900000"]],"time":"2021-04-17T16:43:49.004128Z"}
1618677828.991286: {"type":"l2update","product_id":"YFI-BTC","changes":[["buy","0.82588","0.000000"]],"time":"2021-04-17T16:43:49.006807Z"}
1618677828.9965959: {"type":"l2update","product_id":"BAND-BTC","changes":[["sell","0.00033498","36.75"]],"time":"2021-04-17T16:43:49.007981Z"}
1618677828.996734: {"type":"l2update","product_id":"SKL-BTC","changes":[["buy","0.00001301","19063.5"]],"time":"2021-04-17T16:43:49.011427Z"}
1618677828.99679: {"type":"l2update","product_id":"SKL-BTC","changes":[["sell","0.00001308","2381.1"]],"time":"2021-04-17T16:43:49.011427Z"}
1618677828.996831: {"type":"l2update","product_id":"DASH-BTC","changes":[["buy","0.00618781","0.29500000"]],"time":"2021-04-17T16:43:49.011583Z"}
1618677828.9968781: {"type":"l2update","product_id":"SKL-BTC","changes":[["sell","0.00001344","1392.8"]],"time":"2021-04-17T16:43:49.012570Z"}
1618677828.998492: {"type":"l2update","product_id":"SKL-BTC","changes":[["sell","0.00001332","1634.4"]],"time":"2021-04-17T16:43:49.012570Z"}
1618677828.9986172: {"type":"l2update","product_id":"DASH-BTC","changes":[["buy","0.00614338","0.00000000"]],"time":"2021-04-17T16:43:49.013828Z"}
1618677828.998702: {"type":"l2update","product_id":"DASH-BTC","changes":[["buy","0.00614339","2.08000000"]],"time":"2021-04-17T16:43:49.013828Z"}
1618677828.999167: {"type":"l2update","product_id":"SKL-BTC","changes":[["sell","0.00001354","0.0"]],"time":"2021-04-17T16:43:49.016339Z"}
1618677828.99924: {"type":"l2update","product_id":"DASH-BTC","changes":[["sell","0.00620307","0.90000000"]],"time":"2021-04-17T16:43:49.015348Z"}
1618677829.002659: {"type":"l2update","product_id":"DASH-BTC","changes":[["buy","0.00614342","3.50000000"]],"time":"2021-04-17T16:43:49.018794Z"}
1618677829.002721: {"type":"l2update","product_id":"YFI-BTC","changes":[["sell","0.82739","0.016700"]],"time":"2021-04-17T16:43:49.018957Z"}
1618677829.004609: {"type":"l2update","product_id":"YFI-BTC","changes":[["sell","0.82714","0.029843"]],"time":"2021-04-17T16:43:49.019643Z"}
1618677829.013739: {"type":"l2update","product_id":"NMR-EUR","changes":[["buy","66.9207","1.303"]],"time":"2021-04-17T16:43:49.028148Z"}
1618677829.01382: {"type":"l2update","product_id":"NMR-EUR","changes":[["buy","66.9207","0.000"]],"time":"2021-04-17T16:43:49.028446Z"}
1618677829.018641: {"type":"l2update","product_id":"SKL-BTC","changes":[["sell","0.00001326","1667.5"]],"time":"2021-04-17T16:43:49.034185Z"}
1618677829.0187461: {"type":"l2update","product_id":"SKL-BTC","changes":[["sell","0.00001312","3511.5"]],"time":"2021-04-17T16:43:49.034185Z"}
1618677829.0188: {"type":"l2update","product_id":"YFI-BTC","changes":[["sell","0.82694","0.019952"]],"time":"2021-04-17T16:43:49.034436Z"}
1618677829.022902: {"type":"l2update","product_id":"SKL-BTC","changes":[["sell","0.00001318","0.0"]],"time":"2021-04-17T16:43:49.038496Z"}
1618677829.0230038: {"type":"l2update","product_id":"DASH-BTC","changes":[["sell","0.00621863","0.00000000"]],"time":"2021-04-17T16:43:49.038851Z"}
1618677829.0269802: {"type":"l2update","product_id":"YFI-BTC","changes":[["buy","0.82533","0.000000"]],"time":"2021-04-17T16:43:49.044080Z"}
1618677829.030155: {"type":"l2update","product_id":"YFI-BTC","changes":[["buy","0.82413","0.000000"]],"time":"2021-04-17T16:43:49.045824Z"}
1618677829.030262: {"type":"l2update","product_id":"YFI-BTC","changes":[["buy","0.82447","0.000000"]],"time":"2021-04-17T16:43:49.045824Z"}
1618677829.032402: {"type":"l2update","product_id":"DASH-BTC","changes":[["buy","0.00618781","1.83800000"]],"time":"2021-04-17T16:43:49.046678Z"}
1618677829.032492: {"type":"l2update","product_id":"YFI-BTC","changes":[["sell","0.82792","0.000000"]],"time":"2021-04-17T16:43:49.046725Z"}
1618677829.03256: {"type":"l2update","product_id":"YFI-BTC","changes":[["buy","0.82521","0.030000"]],"time":"2021-04-17T16:43:49.048766Z"}
1618677829.032613: {"type":"l2update","product_id":"DASH-BTC","changes":[["sell","0.00621353","1.88000000"]],"time":"2021-04-17T16:43:49.049052Z"}
1618677829.0358331: {"type":"l2update","product_id":"BAND-BTC","changes":[["sell","0.00033537","0.00"]],"time":"2021-04-17T16:43:49.049985Z"}
1618677829.035944: {"type":"l2update","product_id":"BAND-BTC","changes":[["buy","0.00033170","214.75"]],"time":"2021-04-17T16:43:49.049985Z"}
1618677829.041059: {"type":"l2update","product_id":"NMR-EUR","changes":[["buy","66.9224","1.303"]],"time":"2021-04-17T16:43:49.053013Z"}
1618677829.041138: {"type":"l2update","product_id":"BAND-BTC","changes":[["sell","0.00033491","18.31"]],"time":"2021-04-17T16:43:49.053248Z"}
1618677829.0411751: {"type":"l2update","product_id":"NMR-EUR","changes":[["buy","66.9224","2.606"]],"time":"2021-04-17T16:43:49.056330Z"}
1618677829.0412018: {"type":"l2update","product_id":"SKL-BTC","changes":[["sell","0.00001331","1523.5"]],"time":"2021-04-17T16:43:49.056494Z"}
1618677829.0412512: {"type":"l2update","product_id":"SKL-BTC","changes":[["sell","0.00001327","1387.8"]],"time":"2021-04-17T16:43:49.056494Z"}
1618677829.041271: {"type":"l2update","product_id":"SKL-BTC","changes":[["sell","0.00001323","1593.8"]],"time":"2021-04-17T16:43:49.056494Z"}
1618677829.041288: {"type":"l2update","product_id":"BAND-BTC","changes":[["sell","0.00033560","8.10"]],"time":"2021-04-17T16:43:49.056580Z"}
1618677829.041312: {"type":"l2update","product_id":"BAND-BTC","changes":[["buy","0.00033170","226.15"]],"time":"2021-04-17T16:43:49.056580Z"}
1618677829.04531: {"type":"l2update","product_id":"DASH-BTC","changes":[["buy","0.00618781","2.95800000"]],"time":"2021-04-17T16:43:49.060043Z"}
1618677829.045347: {"type":"l2update","product_id":"YFI-BTC","changes":[["buy","0.82375","0.044700"]],"time":"2021-04-17T16:43:49.060236Z"}
1618677829.045376: {"type":"l2update","product_id":"YFI-BTC","changes":[["buy","0.82405","0.019100"]],"time":"2021-04-17T16:43:49.060236Z"}
1618677829.0453959: {"type":"l2update","product_id":"SKL-BTC","changes":[["sell","0.00001344","10.0"]],"time":"2021-04-17T16:43:49.061105Z"}
1618677829.045412: {"type":"l2update","product_id":"SKL-BTC","changes":[["sell","0.00001332","45.6"]],"time":"2021-04-17T16:43:49.061105Z"}
1618677829.0454268: {"type":"l2update","product_id":"BAND-GBP","changes":[["buy","14.6489","15.20"]],"time":"2021-04-17T16:43:49.061923Z"}
1618677829.051521: {"type":"l2update","product_id":"NMR-EUR","changes":[["buy","66.9223","0.000"]],"time":"2021-04-17T16:43:49.067150Z"}
1618677829.0515919: {"type":"l2update","product_id":"BAND-GBP","changes":[["buy","14.6493","10.80"]],"time":"2021-04-17T16:43:49.067677Z"}
1618677829.053799: {"type":"l2update","product_id":"BAND-GBP","changes":[["buy","14.6492","18.10"]],"time":"2021-04-17T16:43:49.067677Z"}
1618677829.056973: {"type":"l2update","product_id":"SKL-USD","changes":[["sell","0.8127","13813.2"]],"time":"2021-04-17T16:43:49.070200Z"}
1618677829.057012: {"type":"l2update","product_id":"SKL-USD","changes":[["sell","0.8117","405.0"]],"time":"2021-04-17T16:43:49.070200Z"}
1618677829.057034: {"type":"l2update","product_id":"SKL-USD","changes":[["sell","0.8070","0.0"]],"time":"2021-04-17T16:43:49.070200Z"}
1618677829.0570612: {"type":"l2update","product_id":"SKL-USD","changes":[["sell","0.8053","5.0"]],"time":"2021-04-17T16:43:49.070200Z"}
1618677829.057077: {"type":"l2update","product_id":"SKL-USD","changes":[["sell","0.8029","0.0"]],"time":"2021-04-17T16:43:49.070200Z"}
1618677829.057096: {"type":"l2update","product_id":"SKL-USD","changes":[["sell","0.8002","24.2"]],"time":"2021-04-17T16:43:49.070200Z"}
1618677829.05711: {"type":"l2update","product_id":"SKL-USD","changes":[["buy","0.7829","0.0"]],"time":"2021-04-17T16:43:49.070200Z"}
1618677829.05713: {"type":"l2update","product_id":"YFI-BTC","changes":[["sell","0.82899","0.000000"]],"time":"2021-04-17T16:43:49.071128Z"}
1618677829.05715: {"type":"l2update","product_id":"YFI-BTC","changes":[["buy","0.82238","0.000000"]],"time":"2021-04-17T16:43:49.071128Z"}
1618677829.057169: {"type":"l2update","product_id":"NMR-EUR","changes":[["buy","66.9236","4.774"]],"time":"2021-04-17T16:43:49.071227Z"}
1618677829.061195: {"type":"l2update","product_id":"SKL-BTC","changes":[["sell","0.00001338","1753.1"]],"time":"2021-04-17T16:43:49.076369Z"}
1618677829.061239: {"type":"l2update","product_id":"SKL-BTC","changes":[["sell","0.00001319","1751.5"]],"time":"2021-04-17T16:43:49.076369Z"}
1618677829.063543: {"type":"l2update","product_id":"SKL-USD","changes":[["buy","0.7871","3913.2"]],"time":"2021-04-17T16:43:49.080515Z"}
1618677829.063573: {"type":"l2update","product_id":"SKL-USD","changes":[["buy","0.7796","5.0"]],"time":"2021-04-17T16:43:49.080515Z"}
1618677829.063591: {"type":"l2update","product_id":"SKL-BTC","changes":[["sell","0.00001326","0.0"]],"time":"2021-04-17T16:43:49.080713Z"}
1618677829.063614: {"type":"l2update","product_id":"SKL-USD","changes":[["buy","0.7727","0.0"]],"time":"2021-04-17T16:43:49.080515Z"}
1618677829.063634: {"type":"l2update","product_id":"SKL-USD","changes":[["sell","0.7916","0.0"]],"time":"2021-04-17T16:43:49.080515Z"}
1618677829.0636532: {"type":"l2update","product_id":"SKL-USD","changes":[["sell","0.7996","23899.8"]],"time":"2021-04-17T16:43:49.080515Z"}
1618677829.0717728: {"type":"l2update","product_id":"YFI-BTC","changes":[["sell","0.82854","0.015100"]],"time":"2021-04-17T16:43:49.087848Z"}
1618677829.07182: {"type":"l2update","product_id":"YFI-BTC","changes":[["buy","0.82192","0.095700"]],"time":"2021-04-17T16:43:49.087848Z"}
1618677829.078153: {"type":"l2update","product_id":"SKL-BTC","changes":[["buy","0.00001298","10451.0"]],"time":"2021-04-17T16:43:49.095025Z"}
1618677829.078186: {"type":"l2update","product_id":"SKL-BTC","changes":[["sell","0.00001306","6767.6"]],"time":"2021-04-17T16:43:49.095025Z"}
1618677829.083526: {"type":"l2update","product_id":"SKL-BTC","changes":[["sell","0.00001339","1952.1"]],"time":"2021-04-17T16:43:49.098547Z"}
1618677829.0835578: {"type":"l2update","product_id":"SKL-USD","changes":[["sell","0.8193","2655.5"]],"time":"2021-04-17T16:43:49.098668Z"}
1618677829.0899022: {"type":"l2update","product_id":"YFI-BTC","changes":[["sell","0.82693","0.030201"]],"time":"2021-04-17T16:43:49.106165Z"}
1618677829.10466: {"type":"l2update","product_id":"BAND-GBP","changes":[["buy","14.7544","0.00"]],"time":"2021-04-17T16:43:49.121079Z"}
1618677829.10686: {"type":"l2update","product_id":"SKL-BTC","changes":[["sell","0.00001340","1680.4"]],"time":"2021-04-17T16:43:49.122156Z"}
1618677829.1068952: {"type":"l2update","product_id":"SKL-BTC","changes":[["sell","0.00001315","26997.4"]],"time":"2021-04-17T16:43:49.122156Z"}
1618677829.111742: {"type":"l2update","product_id":"SKL-BTC","changes":[["sell","0.00001319","84.0"]],"time":"2021-04-17T16:43:49.127523Z"}
1618677829.112958: {"type":"l2update","product_id":"BAND-GBP","changes":[["buy","14.7609","27.53"]],"time":"2021-04-17T16:43:49.129596Z"}
1618677829.115707: {"type":"l2update","product_id":"SKL-USD","changes":[["sell","0.8053","2850.2"]],"time":"2021-04-17T16:43:49.129860Z"}
1618677829.1157382: {"type":"l2update","product_id":"SKL-USD","changes":[["sell","0.8037","2283.6"]],"time":"2021-04-17T16:43:49.129860Z"}
1618677829.115757: {"type":"l2update","product_id":"SKL-USD","changes":[["sell","0.8022","2539.7"]],"time":"2021-04-17T16:43:49.129860Z"}
1618677829.115777: {"type":"l2update","product_id":"SKL-USD","changes":[["sell","0.7983","5764.0"]],"time":"2021-04-17T16:43:49.129860Z"}
1618677829.115791: {"type":"l2update","product_id":"SKL-USD","changes":[["sell","0.7967","3461.9"]],"time":"2021-04-17T16:43:49.129860Z"}
1618677829.1158028: {"type":"l2update","product_id":"SKL-USD","changes":[["sell","0.7941","2728.4"]],"time":"2021-04-17T16:43:49.131852Z"}
1618677829.1178398: {"type":"l2update","product_id":"SKL-USD","changes":[["sell","0.8224","0.0"]],"time":"2021-04-17T16:43:49.135492Z"}
1618677829.1178749: {"type":"l2update","product_id":"SKL-USD","changes":[["sell","0.8205","0.0"]],"time":"2021-04-17T16:43:49.135492Z"}
1618677829.117897: {"type":"l2update","product_id":"SKL-USD","changes":[["sell","0.8181","58.2"]],"time":"2021-04-17T16:43:49.135492Z"}
1618677829.117913: {"type":"l2update","product_id":"SKL-USD","changes":[["sell","0.8148","5.0"]],"time":"2021-04-17T16:43:49.135492Z"}
1618677829.128417: {"type":"l2update","product_id":"SKL-BTC","changes":[["sell","0.00001350","2029.7"]],"time":"2021-04-17T16:43:49.144741Z"}
1618677829.1359942: {"type":"l2update","product_id":"SKL-USD","changes":[["sell","0.8170","4442.4"]],"time":"2021-04-17T16:43:49.152362Z"}
1618677829.1360261: {"type":"l2update","product_id":"SKL-USD","changes":[["sell","0.8107","2660.5"]],"time":"2021-04-17T16:43:49.152362Z"}
1618677829.140181: {"type":"l2update","product_id":"SKL-USD","changes":[["sell","0.8193","0.0"]],"time":"2021-04-17T16:43:49.157572Z"}
1618677829.158499: {"type":"l2update","product_id":"SKL-BTC","changes":[["sell","0.00001339","92.5"]],"time":"2021-04-17T16:43:49.173332Z"}
1618677829.158554: {"type":"l2update","product_id":"SKL-BTC","changes":[["sell","0.00001338","0.0"]],"time":"2021-04-17T16:43:49.173332Z"}
1618677829.158584: {"type":"l2update","product_id":"SKL-BTC","changes":[["sell","0.00001331","0.0"]],"time":"2021-04-17T16:43:49.173332Z"}
1618677829.158602: {"type":"l2update","product_id":"SKL-BTC","changes":[["sell","0.00001327","5.0"]],"time":"2021-04-17T16:43:49.173332Z"}
1618677829.158617: {"type":"l2update","product_id":"SKL-BTC","changes":[["sell","0.00001323","5.0"]],"time":"2021-04-17T16:43:49.173332Z"}
1618677829.1586292: {"type":"l2update","product_id":"SKL-BTC","changes":[["sell","0.00001315","25329.9"]],"time":"2021-04-17T16:43:49.173332Z"}
1618677829.1590452: {"type":"l2update","product_id":"SKL-USD","changes":[["sell","0.8127","16746.8"]],"time":"2021-04-17T16:43:49.175449Z"}
1618677829.16843: {"type":"l2update","product_id":"NMR-EUR","changes":[["buy","66.9224","1.303"]],"time":"2021-04-17T16:43:49.184631Z"}
1618677829.17803: {"type":"l2update","product_id":"DASH-BTC","changes":[["sell","0.00620174","0.00000000"]],"time":"2021-04-17T16:43:49.195406Z"}
1618677829.1812391: {"type":"l2update","product_id":"YFI-BTC","changes":[["buy","0.82503","0.030139"]],"time":"2021-04-17T16:43:49.197319Z"}
1618677829.1812701: {"type":"l2update","product_id":"SKL-BTC","changes":[["sell","0.00001348","2299.6"]],"time":"2021-04-17T16:43:49.197534Z"}
1618677829.1887639: {"type":"l2update","product_id":"DASH-BTC","changes":[["sell","0.00620281","0.00000000"]],"time":"2021-04-17T16:43:49.203721Z"}
1618677829.191967: {"type":"l2update","product_id":"NMR-EUR","changes":[["buy","66.9237","1.303"]],"time":"2021-04-17T16:43:49.205953Z"}
1618677829.1920068: {"type":"l2update","product_id":"BAND-BTC","changes":[["buy","0.00033414","0.00"]],"time":"2021-04-17T16:43:49.208599Z"}
1618677829.192035: {"type":"l2update","product_id":"YFI-BTC","changes":[["buy","0.82527","0.064869"]],"time":"2021-04-17T16:43:49.208939Z"}
1618677829.192906: {"type":"l2update","product_id":"SKL-USD","changes":[["sell","0.8127","20047.2"]],"time":"2021-04-17T16:43:49.209107Z"}
1618677829.192937: {"type":"l2update","product_id":"SKL-USD","changes":[["sell","0.8088","3711.4"]],"time":"2021-04-17T16:43:49.209107Z"}
1618677829.199331: {"type":"l2update","product_id":"SKL-USD","changes":[["sell","0.8053","5505.7"]],"time":"2021-04-17T16:43:49.209107Z"}
1618677829.199361: {"type":"l2update","product_id":"SKL-USD","changes":[["sell","0.8170","736.0"]],"time":"2021-04-17T16:43:49.214808Z"}
1618677829.19938: {"type":"l2update","product_id":"SKL-USD","changes":[["sell","0.8107","5.0"]],"time":"2021-04-17T16:43:49.214808Z"}
1618677829.199394: {"type":"l2update","product_id":"DASH-BTC","changes":[["sell","0.00619640","0.82500000"]],"time":"2021-04-17T16:43:49.216203Z"}
1618677829.206893: {"type":"l2update","product_id":"SKL-BTC","changes":[["sell","0.00001325","1708.4"]],"time":"2021-04-17T16:43:49.220177Z"}
1618677829.206924: {"type":"l2update","product_id":"SKL-BTC","changes":[["sell","0.00001322","1368.1"]],"time":"2021-04-17T16:43:49.220177Z"}
1618677829.206947: {"type":"l2update","product_id":"SKL-BTC","changes":[["sell","0.00001316","1482.2"]],"time":"2021-04-17T16:43:49.220177Z"}
1618677829.209572: {"type":"l2update","product_id":"NMR-EUR","changes":[["buy","66.9236","0.000"]],"time":"2021-04-17T16:43:49.223803Z"}
1618677829.209609: {"type":"l2update","product_id":"SKL-BTC","changes":[["sell","0.00001350","661.6"]],"time":"2021-04-17T16:43:49.225068Z"}
1618677829.2096288: {"type":"l2update","product_id":"NMR-EUR","changes":[["buy","66.9239","4.774"]],"time":"2021-04-17T16:43:49.224641Z"}
1618677829.209646: {"type":"l2update","product_id":"SKL-BTC","changes":[["sell","0.00001340","198.2"]],"time":"2021-04-17T16:43:49.225068Z"}
1618677829.2096598: {"type":"l2update","product_id":"DASH-BTC","changes":[["sell","0.00620280","2.23600000"]],"time":"2021-04-17T16:43:49.225644Z"}
1618677829.215029: {"type":"l2update","product_id":"DASH-BTC","changes":[["sell","0.00620280","0.00000000"]],"time":"2021-04-17T16:43:49.229092Z"}
1618677829.221142: {"type":"l2update","product_id":"SKL-USD","changes":[["sell","0.8205","2247.6"]],"time":"2021-04-17T16:43:49.235380Z"}
1618677829.222323: {"type":"l2update","product_id":"YFI-BTC","changes":[["buy","0.82414","0.000000"]],"time":"2021-04-17T16:43:49.236149Z"}
1618677829.222362: {"type":"l2update","product_id":"SKL-GBP","changes":[["sell","0.5771","0.0"]],"time":"2021-04-17T16:43:49.235899Z"}
1618677829.227801: {"type":"l2update","product_id":"SKL-GBP","changes":[["sell","0.5780","0.0"]],"time":"2021-04-17T16:43:49.242393Z"}
1618677829.238245: {"type":"l2update","product_id":"SKL-BTC","changes":[["sell","0.00001337","1789.9"]],"time":"2021-04-17T16:43:49.243279Z"}
1618677829.238276: {"type":"l2update","product_id":"SKL-BTC","changes":[["sell","0.00001330","1434.1"]],"time":"2021-04-17T16:43:49.243279Z"}
1618677829.238299: {"type":"l2update","product_id":"YFI-BTC","changes":[["buy","0.82409","0.053023"]],"time":"2021-04-17T16:43:49.247057Z"}
1618677829.238318: {"type":"l2update","product_id":"YFI-BTC","changes":[["sell","0.82937","0.000493"]],"time":"2021-04-17T16:43:49.247057Z"}
1618677829.238335: {"type":"l2update","product_id":"DASH-BTC","changes":[["sell","0.00620281","1.62300000"]],"time":"2021-04-17T16:43:49.247100Z"}
1618677829.238351: {"type":"l2update","product_id":"SKL-USD","changes":[["buy","0.7868","3075.0"]],"time":"2021-04-17T16:43:49.247175Z"}
1618677829.238368: {"type":"l2update","product_id":"SKL-BTC","changes":[["sell","0.00001348","865.5"]],"time":"2021-04-17T16:43:49.247818Z"}
1618677829.23838: {"type":"l2update","product_id":"SKL-USD","changes":[["buy","0.7789","64223.1"]],"time":"2021-04-17T16:43:49.247175Z"}
1618677829.238392: {"type":"l2update","product_id":"SKL-USD","changes":[["buy","0.7711","59322.6"]],"time":"2021-04-17T16:43:49.247175Z"}
1618677829.238406: {"type":"l2update","product_id":"SKL-USD","changes":[["sell","0.7915","4322.1"]],"time":"2021-04-17T16:43:49.247175Z"}
1618677829.2384179: {"type":"l2update","product_id":"BAND-GBP","changes":[["sell","14.7940","0.00"]],"time":"2021-04-17T16:43:49.249762Z"}
1618677829.2384372: {"type":"l2update","product_id":"DASH-BTC","changes":[["sell","0.00619639","2.57300000"]],"time":"2021-04-17T16:43:49.250704Z"}
1618677829.238452: {"type":"l2update","product_id":"SKL-BTC","changes":[["buy","0.00001298","7016.3"]],"time":"2021-04-17T16:43:49.251674Z"}
1618677829.238464: {"type":"l2update","product_id":"SKL-BTC","changes":[["sell","0.00001306","6569.3"]],"time":"2021-04-17T16:43:49.251674Z"}
1618677829.245891: {"type":"l2update","product_id":"BAND-BTC","changes":[["buy","0.00033416","36.75"]],"time":"2021-04-17T16:43:49.254577Z"}
1618677829.2459252: {"type":"l2update","product_id":"BAND-GBP","changes":[["sell","14.7885","27.80"]],"time":"2021-04-17T16:43:49.259013Z"}
1618677829.246847: {"type":"l2update","product_id":"DASH-BTC","changes":[["sell","0.00620281","3.85900000"]],"time":"2021-04-17T16:43:49.259162Z"}
1618677829.246878: {"type":"l2update","product_id":"SKL-BTC","changes":[["sell","0.00001338","1386.5"]],"time":"2021-04-17T16:43:49.262043Z"}
1618677829.246901: {"type":"l2update","product_id":"BAND-BTC","changes":[["buy","0.00033415","0.00"]],"time":"2021-04-17T16:43:49.263074Z"}
1618677829.254878: {"type":"l2update","product_id":"BAND-BTC","changes":[["buy","0.00033417","29.63"]],"time":"2021-04-17T16:43:49.266219Z"}
1618677829.254913: {"type":"l2update","product_id":"SKL-USD","changes":[["sell","0.8170","3638.5"]],"time":"2021-04-17T16:43:49.266136Z"}
1618677829.258417: {"type":"l2update","product_id":"DASH-BTC","changes":[["sell","0.00620689","0.00000000"]],"time":"2021-04-17T16:43:49.274837Z"}
1618677829.262352: {"type":"l2update","product_id":"BAND-GBP","changes":[["sell","14.7885","0.00"]],"time":"2021-04-17T16:43:49.276559Z"}
1618677829.27133: {"type":"l2update","product_id":"SKL-BTC","changes":[["sell","0.00001338","2977.5"]],"time":"2021-04-17T16:43:49.285001Z"}
1618677829.273451: {"type":"l2update","product_id":"DASH-BTC","changes":[["sell","0.00621783","1.06000000"]],"time":"2021-04-17T16:43:49.288901Z"}
1618677829.275863: {"type":"l2update","product_id":"BAND-BTC","changes":[["sell","0.00033479","35.71"]],"time":"2021-04-17T16:43:49.292729Z"}
1618677829.281183: {"type":"l2update","product_id":"BAND-BTC","changes":[["buy","0.00033170","12.90"]],"time":"2021-04-17T16:43:49.296117Z"}
1618677829.281214: {"type":"l2update","product_id":"SKL-USD","changes":[["sell","0.8193","2879.2"]],"time":"2021-04-17T16:43:49.296225Z"}
1618677829.282475: {"type":"l2update","product_id":"YFI-BTC","changes":[["buy","0.82583","0.000000"]],"time":"2021-04-17T16:43:49.296980Z"}
1618677829.28764: {"type":"l2update","product_id":"BAND-BTC","changes":[["buy","0.00033170","217.49"]],"time":"2021-04-17T16:43:49.303508Z"}
1618677829.28767: {"type":"l2update","product_id":"SKL-USD","changes":[["buy","0.7894","0.0"]],"time":"2021-04-17T16:43:49.305879Z"}
1618677829.297399: {"type":"l2update","product_id":"DASH-BTC","changes":[["buy","0.00617110","0.00000000"]],"time":"2021-04-17T16:43:49.309508Z"}
1618677829.2975051: {"type":"l2update","product_id":"SKL-BTC","changes":[["sell","0.00001344","1680.8"]],"time":"2021-04-17T16:43:49.310574Z"}
1618677829.297565: {"type":"l2update","product_id":"YFI-BTC","changes":[["buy","0.82571","0.000000"]],"time":"2021-04-17T16:43:49.311641Z"}
1618677829.311137: {"type":"l2update","product_id":"DASH-BTC","changes":[["buy","0.00618010","1.88000000"]],"time":"2021-04-17T16:43:49.325097Z"}
1618677829.311174: {"type":"l2update","product_id":"SKL-USD","changes":[["buy","0.7830","0.0"]],"time":"2021-04-17T16:43:49.327482Z"}
1618677829.316431: {"type":"l2update","product_id":"YFI-BTC","changes":[["buy","0.82553","0.017061"]],"time":"2021-04-17T16:43:49.332769Z"}
1618677829.3164659: {"type":"l2update","product_id":"NMR-EUR","changes":[["buy","66.9237","0.000"]],"time":"2021-04-17T16:43:49.333254Z"}
1618677829.3260171: {"type":"l2update","product_id":"SKL-BTC","changes":[["sell","0.00001348","2228.2"]],"time":"2021-04-17T16:43:49.339797Z"}
1618677829.326045: {"type":"l2update","product_id":"SKL-USD","changes":[["buy","0.7826","16902.8"]],"time":"2021-04-17T16:43:49.339893Z"}
1618677829.332632: {"type":"l2update","product_id":"NMR-EUR","changes":[["buy","66.9240","1.303"]],"time":"2021-04-17T16:43:49.346906Z"}
1618677829.334985: {"type":"l2update","product_id":"NMR-EUR","changes":[["buy","66.9239","0.000"]],"time":"2021-04-17T16:43:49.352461Z"}
1618677829.341401: {"type":"l2update","product_id":"SKL-USD","changes":[["buy","0.7896","2632.7"]],"time":"2021-04-17T16:43:49.355677Z"}
1618677829.3414369: {"type":"l2update","product_id":"SKL-USD","changes":[["sell","0.7931","2643.3"]],"time":"2021-04-17T16:43:49.357819Z"}
1618677829.3414552: {"type":"l2update","product_id":"NMR-EUR","changes":[["buy","66.9242","4.774"]],"time":"2021-04-17T16:43:49.357626Z"}
1618677829.351169: {"type":"l2update","product_id":"DASH-BTC","changes":[["buy","0.00618780","0.00000000"]],"time":"2021-04-17T16:43:49.367563Z"}
1618677829.35988: {"type":"l2update","product_id":"SKL-USD","changes":[["buy","0.7895","1195.5"]],"time":"2021-04-17T16:43:49.371834Z"}
1618677829.359912: {"type":"l2update","product_id":"BAND-BTC","changes":[["buy","0.00033397","120.94"]],"time":"2021-04-17T16:43:49.374608Z"}
1618677829.359932: {"type":"l2update","product_id":"SKL-USD","changes":[["buy","0.7895","0.0"]],"time":"2021-04-17T16:43:49.377355Z"}
1618677829.365154: {"type":"l2update","product_id":"DASH-BTC","changes":[["buy","0.00618781","1.41500000"]],"time":"2021-04-17T16:43:49.379804Z"}
1618677829.3678489: {"type":"l2update","product_id":"DASH-BTC","changes":[["buy","0.00618595","0.00000000"]],"time":"2021-04-17T16:43:49.383500Z"}
1618677829.367884: {"type":"l2update","product_id":"SKL-USD","changes":[["buy","0.7892","0.0"]],"time":"2021-04-17T16:43:49.384602Z"}
1618677829.37221: {"type":"l2update","product_id":"SKL-BTC","changes":[["buy","0.00001302","5740.5"]],"time":"2021-04-17T16:43:49.384783Z"}
1618677829.372239: {"type":"l2update","product_id":"DASH-BTC","changes":[["sell","0.00620307","0.00000000"]],"time":"2021-04-17T16:43:49.388921Z"}
1618677829.376205: {"type":"l2update","product_id":"CRV-EUR","changes":[["buy","3.2955","5000.00"]],"time":"2021-04-17T16:43:49.390638Z"}
1618677829.3805282: {"type":"l2update","product_id":"CRV-EUR","changes":[["buy","3.2877","0.00"]],"time":"2021-04-17T16:43:49.397324Z"}
1618677829.3805618: {"type":"l2update","product_id":"SKL-BTC","changes":[["sell","0.00001310","3244.9"]],"time":"2021-04-17T16:43:49.397901Z"}
1618677829.385149: {"type":"l2update","product_id":"CRV-EUR","changes":[["buy","3.2951","0.00"]],"time":"2021-04-17T16:43:49.400879Z"}
1618677829.385184: {"type":"l2update","product_id":"CRV-EUR","changes":[["buy","3.2971","96.90"]],"time":"2021-04-17T16:43:49.401526Z"}
1618677829.385206: {"type":"l2update","product_id":"DASH-BTC","changes":[["buy","0.00618596","1.54300000"]],"time":"2021-04-17T16:43:49.401695Z"}
1618677829.3852239: {"type":"l2update","product_id":"CRV-EUR","changes":[["buy","3.2918","1133.36"]],"time":"2021-04-17T16:43:49.401732Z"}
1618677829.38524: {"type":"l2update","product_id":"DASH-BTC","changes":[["sell","0.00621376","6.01700000"]],"time":"2021-04-17T16:43:49.401793Z"}
1618677829.3852549: {"type":"l2update","product_id":"SKL-USD","changes":[["buy","0.7868","0.0"]],"time":"2021-04-17T16:43:49.402046Z"}
1618677829.385272: {"type":"l2update","product_id":"SKL-USD","changes":[["buy","0.7789","98.1"]],"time":"2021-04-17T16:43:49.402046Z"}
1618677829.385864: {"type":"l2update","product_id":"SKL-USD","changes":[["buy","0.7711","0.0"]],"time":"2021-04-17T16:43:49.402046Z"}
1618677829.3859: {"type":"l2update","product_id":"SKL-USD","changes":[["sell","0.7915","1344.8"]],"time":"2021-04-17T16:43:49.402046Z"}
1618677829.395762: {"type":"l2update","product_id":"DASH-BTC","changes":[["buy","0.00618781","1.12000000"]],"time":"2021-04-17T16:43:49.407327Z"}
1618677829.399231: {"type":"l2update","product_id":"DASH-BTC","changes":[["buy","0.00618782","2.57300000"]],"time":"2021-04-17T16:43:49.413175Z"}
1618677829.399304: {"type":"l2update","product_id":"SKL-BTC","changes":[["buy","0.00001299","7114.7"]],"time":"2021-04-17T16:43:49.413341Z"}
1618677829.399324: {"type":"l2update","product_id":"SKL-BTC","changes":[["sell","0.00001306","6767.6"]],"time":"2021-04-17T16:43:49.413341Z"}
1618677829.407649: {"type":"l2update","product_id":"SKL-USD","changes":[["buy","0.7893","867.7"]],"time":"2021-04-17T16:43:49.420779Z"}
1618677829.407684: {"type":"l2update","product_id":"BAND-BTC","changes":[["buy","0.00033345","0.00"]],"time":"2021-04-17T16:43:49.421806Z"}
1618677829.407709: {"type":"l2update","product_id":"BAND-BTC","changes":[["buy","0.00033294","0.00"]],"time":"2021-04-17T16:43:49.421806Z"}
1618677829.407726: {"type":"l2update","product_id":"BAND-BTC","changes":[["buy","0.00033244","0.00"]],"time":"2021-04-17T16:43:49.421806Z"}
1618677829.407742: {"type":"l2update","product_id":"BAND-BTC","changes":[["buy","0.00033144","256.19"]],"time":"2021-04-17T16:43:49.421806Z"}
1618677829.407755: {"type":"l2update","product_id":"SKL-USD","changes":[["buy","0.7855","255.0"]],"time":"2021-04-17T16:43:49.422241Z"}
1618677829.41672: {"type":"l2update","product_id":"DASH-BTC","changes":[["sell","0.00620477","10.73200000"]],"time":"2021-04-17T16:43:49.427962Z"}
1618677829.4167838: {"type":"l2update","product_id":"DASH-BTC","changes":[["buy","0.00618543","0.29500000"]],"time":"2021-04-17T16:43:49.428015Z"}
1618677829.4178739: {"type":"l2update","product_id":"SKL-USD","changes":[["buy","0.7888","2065.5"]],"time":"2021-04-17T16:43:49.431845Z"}
1618677829.422443: {"type":"l2update","product_id":"SKL-USD","changes":[["sell","0.7929","5.0"]],"time":"2021-04-17T16:43:49.434281Z"}
1618677829.422527: {"type":"l2update","product_id":"DASH-BTC","changes":[["sell","0.00620498","0.00000000"]],"time":"2021-04-17T16:43:49.435155Z"}
1618677829.4225779: {"type":"l2update","product_id":"BAND-BTC","changes":[["buy","0.00033294","148.32"]],"time":"2021-04-17T16:43:49.435479Z"}
1618677829.422616: {"type":"l2update","product_id":"BAND-BTC","changes":[["buy","0.00033244","177.99"]],"time":"2021-04-17T16:43:49.435479Z"}
1618677829.422644: {"type":"l2update","product_id":"BAND-BTC","changes":[["buy","0.00033094","307.57"]],"time":"2021-04-17T16:43:49.435479Z"}
1618677829.422667: {"type":"l2update","product_id":"BAND-BTC","changes":[["buy","0.00032746","0.10"]],"time":"2021-04-17T16:43:49.435479Z"}
1618677829.422693: {"type":"l2update","product_id":"NMR-EUR","changes":[["buy","66.9240","0.000"]],"time":"2021-04-17T16:43:49.437742Z"}
1618677829.427731: {"type":"l2update","product_id":"SKL-USD","changes":[["sell","0.7927","1108.3"]],"time":"2021-04-17T16:43:49.444214Z"}
1618677829.441608: {"type":"l2update","product_id":"SKL-USD","changes":[["sell","0.7918","23012.0"]],"time":"2021-04-17T16:43:49.455317Z"}
1618677829.441695: {"type":"l2update","product_id":"NMR-EUR","changes":[["buy","66.9243","1.303"]],"time":"2021-04-17T16:43:49.455408Z"}
1618677829.4425228: {"type":"l2update","product_id":"YFI-BTC","changes":[["sell","0.82693","0.000000"]],"time":"2021-04-17T16:43:49.458400Z"}
1618677829.4468732: {"type":"l2update","product_id":"YFI-BTC","changes":[["buy","0.82467","0.000000"]],"time":"2021-04-17T16:43:49.460389Z"}
1618677829.4469278: {"type":"l2update","product_id":"SKL-USD","changes":[["sell","0.7942","29765.1"]],"time":"2021-04-17T16:43:49.461725Z"}
1618677829.446957: {"type":"l2update","product_id":"NMR-EUR","changes":[["buy","66.9242","0.000"]],"time":"2021-04-17T16:43:49.461823Z"}
1618677829.450525: {"type":"l2update","product_id":"DASH-BTC","changes":[["sell","0.00620478","0.00000000"]],"time":"2021-04-17T16:43:49.462212Z"}
1618677829.454783: {"type":"l2update","product_id":"NMR-EUR","changes":[["buy","66.9245","4.774"]],"time":"2021-04-17T16:43:49.469905Z"}
1618677829.472474: {"type":"l2update","product_id":"DASH-BTC","changes":[["sell","0.00620476","1.62300000"]],"time":"2021-04-17T16:43:49.484709Z"}
1618677829.488928: {"type":"l2update","product_id":"SKL-USD","changes":[["sell","0.7949","3321.8"]],"time":"2021-04-17T16:43:49.495843Z"}
1618677829.489048: {"type":"l2update","product_id":"SKL-USD","changes":[["sell","0.7963","175.8"]],"time":"2021-04-17T16:43:49.500512Z"}
1618677829.49198: {"type":"l2update","product_id":"SKL-USD","changes":[["buy","0.7807","0.0"]],"time":"2021-04-17T16:43:49.508238Z"}
1618677829.501287: {"type":"l2update","product_id":"BAND-BTC","changes":[["sell","0.00033479","0.00"]],"time":"2021-04-17T16:43:49.515893Z"}
1618677829.511308: {"type":"l2update","product_id":"SKL-USD","changes":[["buy","0.7796","10.0"]],"time":"2021-04-17T16:43:49.522202Z"}
1618677829.511395: {"type":"l2update","product_id":"SKL-USD","changes":[["buy","0.7725","5.0"]],"time":"2021-04-17T16:43:49.522202Z"}
1618677829.511463: {"type":"l2update","product_id":"SKL-USD","changes":[["sell","0.7983","2515.2"]],"time":"2021-04-17T16:43:49.524243Z"}
1618677829.517955: {"type":"l2update","product_id":"SKL-USD","changes":[["buy","0.7796","8464.5"]],"time":"2021-04-17T16:43:49.533476Z"}
1618677829.527576: {"type":"l2update","product_id":"DASH-BTC","changes":[["sell","0.00864891","4.51000000"]],"time":"2021-04-17T16:43:49.544507Z"}
1618677829.539705: {"type":"l2update","product_id":"DASH-BTC","changes":[["sell","0.00864891","4.80000000"]],"time":"2021-04-17T16:43:49.548835Z"}
1618677829.5397718: {"type":"l2update","product_id":"DASH-BTC","changes":[["sell","0.00619640","0.00000000"]],"time":"2021-04-17T16:43:49.549464Z"}
1618677829.550082: {"type":"l2update","product_id":"BAND-GBP","changes":[["buy","14.7501","0.00"]],"time":"2021-04-17T16:43:49.556347Z"}
1618677829.554215: {"type":"l2update","product_id":"SKL-USD","changes":[["sell","0.8127","16746.8"]],"time":"2021-04-17T16:43:49.563165Z"}
1618677829.554262: {"type":"l2update","product_id":"SKL-USD","changes":[["sell","0.8053","2850.2"]],"time":"2021-04-17T16:43:49.563165Z"}
1618677829.5542881: {"type":"l2update","product_id":"SKL-USD","changes":[["sell","0.8037","37.9"]],"time":"2021-04-17T16:43:49.563165Z"}
1618677829.5543091: {"type":"l2update","product_id":"SKL-USD","changes":[["sell","0.8022","0.0"]],"time":"2021-04-17T16:43:49.563165Z"}
1618677829.554345: {"type":"l2update","product_id":"SKL-BTC","changes":[["sell","0.00001309","6134.3"]],"time":"2021-04-17T16:43:49.565050Z"}
1618677829.557976: {"type":"l2update","product_id":"BAND-GBP","changes":[["buy","14.7609","0.00"]],"time":"2021-04-17T16:43:49.566843Z"}
1618677829.5580359: {"type":"l2update","product_id":"SKL-USD","changes":[["buy","0.7872","3247.6"]],"time":"2021-04-17T16:43:49.567268Z"}
1618677829.558066: {"type":"l2update","product_id":"CRV-EUR","changes":[["sell","3.3026","140.93"]],"time":"2021-04-17T16:43:49.567493Z"}
1618677829.55809: {"type":"l2update","product_id":"SKL-USD","changes":[["buy","0.7789","64223.1"]],"time":"2021-04-17T16:43:49.567268Z"}
1618677829.55811: {"type":"l2update","product_id":"SKL-USD","changes":[["buy","0.7711","59322.6"]],"time":"2021-04-17T16:43:49.567268Z"}
1618677829.558135: {"type":"l2update","product_id":"SKL-USD","changes":[["sell","0.7915","4322.1"]],"time":"2021-04-17T16:43:49.567268Z"}
1618677829.5581539: {"type":"l2update","product_id":"SKL-USD","changes":[["sell","0.7919","0.0"]],"time":"2021-04-17T16:43:49.570221Z"}
1618677829.560163: {"type":"l2update","product_id":"DASH-BTC","changes":[["sell","0.00619638","0.82500000"]],"time":"2021-04-17T16:43:49.570970Z"}
1618677829.560216: {"type":"l2update","product_id":"SKL-BTC","changes":[["sell","0.00001306","6569.3"]],"time":"2021-04-17T16:43:49.571824Z"}
1618677829.560242: {"type":"l2update","product_id":"SKL-BTC","changes":[["sell","0.00001307","4448.5"]],"time":"2021-04-17T16:43:49.572057Z"}
1618677829.562325: {"type":"l2update","product_id":"DASH-BTC","changes":[["sell","0.00620281","2.23600000"]],"time":"2021-04-17T16:43:49.577419Z"}
1618677829.572563: {"type":"l2update","product_id":"SKL-USD","changes":[["sell","0.7942","5.0"]],"time":"2021-04-17T16:43:49.579261Z"}
1618677829.572604: {"type":"l2update","product_id":"DASH-BTC","changes":[["sell","0.00620281","0.00000000"]],"time":"2021-04-17T16:43:49.580970Z"}
1618677829.5781918: {"type":"l2update","product_id":"BAND-BTC","changes":[["buy","0.00033239","0.00"]],"time":"2021-04-17T16:43:49.591234Z"}
1618677829.5782468: {"type":"l2update","product_id":"BAND-GBP","changes":[["buy","14.7608","0.00"]],"time":"2021-04-17T16:43:49.591601Z"}
1618677829.58027: {"type":"l2update","product_id":"BAND-BTC","changes":[["buy","0.00033397","102.94"]],"time":"2021-04-17T16:43:49.593868Z"}
1618677829.5803142: {"type":"l2update","product_id":"SKL-USD","changes":[["sell","0.8193","6044.7"]],"time":"2021-04-17T16:43:49.595418Z"}
1618677829.58034: {"type":"l2update","product_id":"SKL-USD","changes":[["buy","0.7623","6064.4"]],"time":"2021-04-17T16:43:49.595418Z"}
1618677829.580362: {"type":"l2update","product_id":"SKL-USD","changes":[["buy","0.7800","2181.3"]],"time":"2021-04-17T16:43:49.595418Z"}
1618677829.619884: {"type":"l2update","product_id":"BAND-GBP","changes":[["sell","14.7871","12.94"]],"time":"2021-04-17T16:43:49.597100Z"}
1618677829.620039: {"type":"l2update","product_id":"SKL-USD","changes":[["sell","0.7941","32488.5"]],"time":"2021-04-17T16:43:49.597182Z"}
1618677829.620075: {"type":"l2update","product_id":"DASH-BTC","changes":[["sell","0.00620174","1.62300000"]],"time":"2021-04-17T16:43:49.597453Z"}
1618677829.620111: {"type":"l2update","product_id":"SKL-USD","changes":[["buy","0.7794","40.1"]],"time":"2021-04-17T16:43:49.600379Z"}
1618677829.620137: {"type":"l2update","product_id":"BAND-GBP","changes":[["buy","14.7544","27.54"]],"time":"2021-04-17T16:43:49.601144Z"}
1618677829.6201642: {"type":"l2update","product_id":"DASH-BTC","changes":[["sell","0.00620479","0.00000000"]],"time":"2021-04-17T16:43:49.604966Z"}
1618677829.620197: {"type":"l2update","product_id":"BAND-GBP","changes":[["buy","14.7471","0.00"]],"time":"2021-04-17T16:43:49.606932Z"}
1618677829.620224: {"type":"l2update","product_id":"DASH-BTC","changes":[["sell","0.00620476","3.85900000"]],"time":"2021-04-17T16:43:49.608710Z"}
1618677829.6202471: {"type":"l2update","product_id":"BAND-GBP","changes":[["buy","14.7574","12.28"]],"time":"2021-04-17T16:43:49.611624Z"}
1618677829.6202712: {"type":"l2update","product_id":"BAND-GBP","changes":[["buy","14.7544","0.00"]],"time":"2021-04-17T16:43:49.621502Z"}
1618677829.620296: {"type":"l2update","product_id":"BAND-GBP","changes":[["buy","14.7609","36.00"]],"time":"2021-04-17T16:43:49.623779Z"}
1618677829.62032: {"type":"l2update","product_id":"BAND-GBP","changes":[["buy","14.7575","27.54"]],"time":"2021-04-17T16:43:49.623797Z"}
1618677829.620343: {"type":"l2update","product_id":"SKL-USD","changes":[["sell","0.7916","1028.9"]],"time":"2021-04-17T16:43:49.627639Z"}
1618677829.620373: {"type":"l2update","product_id":"SKL-USD","changes":[["sell","0.8205","0.0"]],"time":"2021-04-17T16:43:49.628372Z"}
1618677829.620401: {"type":"l2update","product_id":"SKL-USD","changes":[["sell","0.8193","3165.5"]],"time":"2021-04-17T16:43:49.628372Z"}
1618677829.6204228: {"type":"l2update","product_id":"SKL-USD","changes":[["sell","0.8170","736.0"]],"time":"2021-04-17T16:43:49.628372Z"}
1618677829.6204429: {"type":"l2update","product_id":"SKL-USD","changes":[["sell","0.8127","13813.2"]],"time":"2021-04-17T16:43:49.628372Z"}
1618677829.6204631: {"type":"l2update","product_id":"SKL-USD","changes":[["sell","0.8088","5.0"]],"time":"2021-04-17T16:43:49.628372Z"}
1618677829.620482: {"type":"l2update","product_id":"SKL-USD","changes":[["sell","0.8053","5.0"]],"time":"2021-04-17T16:43:49.628372Z"}
1618677829.620502: {"type":"l2update","product_id":"SKL-BTC","changes":[["buy","0.00001301","18081.9"]],"time":"2021-04-17T16:43:49.632465Z"}
1618677829.620523: {"type":"l2update","product_id":"SKL-BTC","changes":[["sell","0.00001308","1558.3"]],"time":"2021-04-17T16:43:49.632465Z"}
1618677829.620544: {"type":"l2update","product_id":"BAND-GBP","changes":[["buy","14.7061","146.83"]],"time":"2021-04-17T16:43:49.634833Z"}
1618677829.640385: {"type":"l2update","product_id":"SKL-BTC","changes":[["sell","0.00001306","7392.1"]],"time":"2021-04-17T16:43:49.642570Z"}
1618677829.640471: {"type":"l2update","product_id":"DASH-BTC","changes":[["sell","0.00619641","0.00000000"]],"time":"2021-04-17T16:43:49.648420Z"}
1618677829.6661272: {"type":"l2update","product_id":"SKL-USD","changes":[["sell","0.7914","0.0"]],"time":"2021-04-17T16:43:49.671333Z"}
1618677829.6662662: {"type":"l2update","product_id":"SKL-USD","changes":[["sell","0.8008","3262.5"]],"time":"2021-04-17T16:43:49.672919Z"}
1618677829.666323: {"type":"l2update","product_id":"SKL-USD","changes":[["sell","0.7983","5680.7"]],"time":"2021-04-17T16:43:49.672919Z"}
1618677829.666364: {"type":"l2update","product_id":"SKL-USD","changes":[["sell","0.8193","0.0"]],"time":"2021-04-17T16:43:49.677918Z"}
1618677829.780098: {"type":"l2update","product_id":"YFI-BTC","changes":[["buy","0.82375","0.000000"]],"time":"2021-04-17T16:43:49.691151Z"}
1618677829.780183: {"type":"l2update","product_id":"DASH-BTC","changes":[["sell","0.00620321","14.63200000"]],"time":"2021-04-17T16:43:49.691636Z"}
1618677829.780221: {"type":"l2update","product_id":"DASH-BTC","changes":[["buy","0.00618781","0.00000000"]],"time":"2021-04-17T16:43:49.693642Z"}
1618677829.78025: {"type":"l2update","product_id":"YFI-BTC","changes":[["buy","0.82454","0.020851"]],"time":"2021-04-17T16:43:49.695381Z"}
1618677829.780274: {"type":"l2update","product_id":"SKL-USD","changes":[["sell","0.8045","3216.6"]],"time":"2021-04-17T16:43:49.699206Z"}
1618677829.7803001: {"type":"l2update","product_id":"YFI-BTC","changes":[["buy","0.82413","0.044700"]],"time":"2021-04-17T16:43:49.706343Z"}
1618677829.7803211: {"type":"l2update","product_id":"BAND-GBP","changes":[["buy","14.6490","0.20"]],"time":"2021-04-17T16:43:49.711695Z"}
1618677829.780339: {"type":"l2update","product_id":"BAND-GBP","changes":[["buy","14.6489","0.00"]],"time":"2021-04-17T16:43:49.711695Z"}
1618677829.780361: {"type":"l2update","product_id":"DASH-BTC","changes":[["buy","0.00618543","1.41600000"]],"time":"2021-04-17T16:43:49.714319Z"}
1618677829.7803788: {"type":"l2update","product_id":"SKL-USD","changes":[["sell","0.7941","2728.4"]],"time":"2021-04-17T16:43:49.718167Z"}
1618677829.780396: {"type":"l2update","product_id":"SKL-USD","changes":[["sell","0.7914","2632.9"]],"time":"2021-04-17T16:43:49.718181Z"}
1618677829.7804182: {"type":"l2update","product_id":"BAND-GBP","changes":[["buy","14.7061","162.43"]],"time":"2021-04-17T16:43:49.718376Z"}
1618677829.7804348: {"type":"l2update","product_id":"BAND-GBP","changes":[["buy","14.6494","10.60"]],"time":"2021-04-17T16:43:49.718376Z"}
1618677829.7804532: {"type":"l2update","product_id":"DASH-BTC","changes":[["buy","0.00618596","0.00000000"]],"time":"2021-04-17T16:43:49.718940Z"}
1618677829.7804742: {"type":"l2update","product_id":"BAND-GBP","changes":[["buy","14.6493","12.20"]],"time":"2021-04-17T16:43:49.718376Z"}
1618677829.780491: {"type":"l2update","product_id":"SKL-USD","changes":[["sell","0.8045","6060.8"]],"time":"2021-04-17T16:43:49.721939Z"}
1618677829.7805068: {"type":"l2update","product_id":"SKL-USD","changes":[["buy","0.7789","98.1"]],"time":"2021-04-17T16:43:49.722099Z"}
1618677829.780523: {"type":"l2update","product_id":"SKL-USD","changes":[["buy","0.7711","0.0"]],"time":"2021-04-17T16:43:49.722099Z"}
1618677829.780546: {"type":"l2update","product_id":"SKL-USD","changes":[["sell","0.7915","1344.8"]],"time":"2021-04-17T16:43:49.722099Z"}
1618677829.780562: {"type":"l2update","product_id":"NMR-EUR","changes":[["buy","66.9243","0.000"]],"time":"2021-04-17T16:43:49.728987Z"}
1618677829.780586: {"type":"l2update","product_id":"SKL-BTC","changes":[["buy","0.00001299","7474.1"]],"time":"2021-04-17T16:43:49.730430Z"}
1618677829.780603: {"type":"l2update","product_id":"SKL-USD","changes":[["sell","0.7941","32488.5"]],"time":"2021-04-17T16:43:49.736994Z"}
1618677829.780619: {"type":"l2update","product_id":"DASH-BTC","changes":[["buy","0.00618543","2.95900000"]],"time":"2021-04-17T16:43:49.740844Z"}
1618677829.7806349: {"type":"l2update","product_id":"DASH-BTC","changes":[["buy","0.00618543","2.66400000"]],"time":"2021-04-17T16:43:49.745039Z"}
1618677829.78065: {"type":"l2update","product_id":"SKL-USD","changes":[["buy","0.7893","0.0"]],"time":"2021-04-17T16:43:49.748944Z"}
1618677829.78067: {"type":"l2update","product_id":"SKL-USD","changes":[["sell","0.8061","3622.7"]],"time":"2021-04-17T16:43:49.751710Z"}
1618677829.7806861: {"type":"l2update","product_id":"SKL-USD","changes":[["sell","0.7913","888.4"]],"time":"2021-04-17T16:43:49.759227Z"}
1618677829.7807019: {"type":"ticker","sequence":201391580,"product_id":"SKL-USD","price":"0.7913","open_24h":"0.7055","volume_24h":"34259017.10000000","low_24h":"0.6915","high_24h":"0.8098","volume_30d":"948686369.80000000","best_bid":"0.7909","best_ask":"0.7913","side":"buy","time":"2021-04-17T16:43:49.759227Z","trade_id":1568280,"last_size":"7.3"}
1618677829.780724: {"type":"match","trade_id":1568280,"maker_order_id":"3394aa6c-938a-4a81-8c70-fe288cc7a94d","taker_order_id":"6eac45c8-cf27-47da-944a-beef68e109a1","side":"sell","size":"7.3","price":"0.7913","product_id":"SKL-USD","sequence":201391580,"time":"2021-04-17T16:43:49.759227Z"}
1618677829.780745: {"type":"l2update","product_id":"CRV-EUR","changes":[["sell","3.3198","0.00"]],"time":"2021-04-17T16:43:49.766664Z"}
1618677829.780769: {"type":"l2update","product_id":"CRV-EUR","changes":[["buy","3.2894","400.00"]],"time":"2021-04-17T16:43:49.766664Z"}
1618677829.780787: {"type":"l2update","product_id":"DASH-BTC","changes":[["buy","0.00618783","0.29500000"]],"time":"2021-04-17T16:43:49.766851Z"}
1618677829.780807: {"type":"l2update","product_id":"NMR-EUR","changes":[["buy","66.9246","1.303"]],"time":"2021-04-17T16:43:49.767101Z"}
1618677829.7808251: {"type":"l2update","product_id":"SKL-USD","changes":[["buy","0.7888","2933.8"]],"time":"2021-04-17T16:43:49.770481Z"}
1618677829.780842: {"type":"l2update","product_id":"CRV-EUR","changes":[["sell","3.3201","375.00"]],"time":"2021-04-17T16:43:49.773851Z"}
1618677829.780857: {"type":"l2update","product_id":"CRV-EUR","changes":[["buy","3.2698","85.00"]],"time":"2021-04-17T16:43:49.773851Z"}
1618677829.780874: {"type":"l2update","product_id":"SKL-USD","changes":[["buy","0.7866","2634.8"]],"time":"2021-04-17T16:43:49.776901Z"}
1618677829.780889: {"type":"l2update","product_id":"SKL-USD","changes":[["sell","0.8088","3700.6"]],"time":"2021-04-17T16:43:49.777827Z"}
1618677829.780905: {"type":"l2update","product_id":"DASH-BTC","changes":[["sell","0.00619971","2.66800000"]],"time":"2021-04-17T16:43:49.777862Z"}
1618677829.7809238: {"type":"l2update","product_id":"NMR-EUR","changes":[["buy","66.9248","4.774"]],"time":"2021-04-17T16:43:49.785509Z"}
1618677829.780942: {"type":"l2update","product_id":"NMR-EUR","changes":[["buy","66.9245","0.000"]],"time":"2021-04-17T16:43:49.785910Z"}
1618677829.780962: {"type":"l2update","product_id":"YFI-BTC","changes":[["buy","0.82569","0.019553"]],"time":"2021-04-17T16:43:49.788890Z"}
1618677829.780981: {"type":"l2update","product_id":"BAND-BTC","changes":[["buy","0.00033422","123.20"]],"time":"2021-04-17T16:43:49.792677Z"}
1618677829.806572: {"type":"l2update","product_id":"SKL-USD","changes":[["buy","0.7862","25518.9"]],"time":"2021-04-17T16:43:49.797564Z"}
1618677829.806664: {"type":"l2update","product_id":"BAND-BTC","changes":[["sell","0.00033493","123.27"]],"time":"2021-04-17T16:43:49.804529Z"}
1618677829.806735: {"type":"l2update","product_id":"SKL-USD","changes":[["sell","0.8127","17026.2"]],"time":"2021-04-17T16:43:49.808303Z"}
1618677829.81382: {"type":"l2update","product_id":"SKL-USD","changes":[["sell","0.7925","1318.9"]],"time":"2021-04-17T16:43:49.823097Z"}
1618677829.813965: {"type":"l2update","product_id":"SKL-BTC","changes":[["sell","0.00001308","2877.2"]],"time":"2021-04-17T16:43:49.827108Z"}
1618677829.8374112: {"type":"l2update","product_id":"SKL-USD","changes":[["sell","0.7941","2728.4"]],"time":"2021-04-17T16:43:49.850735Z"}
1618677829.846699: {"type":"l2update","product_id":"SKL-USD","changes":[["buy","0.7909","0.0"]],"time":"2021-04-17T16:43:49.861499Z"}
1618677829.853508: {"type":"l2update","product_id":"SKL-BTC","changes":[["sell","0.00001307","7087.5"]],"time":"2021-04-17T16:43:49.865299Z"}
1618677829.859679: {"type":"l2update","product_id":"NMR-EUR","changes":[["buy","66.9246","0.000"]],"time":"2021-04-17T16:43:49.869286Z"}
1618677829.86836: {"type":"l2update","product_id":"SKL-USD","changes":[["sell","0.7940","29765.1"]],"time":"2021-04-17T16:43:49.872832Z"}
1618677829.8684149: {"type":"l2update","product_id":"SKL-BTC","changes":[["buy","0.00001302","4329.2"]],"time":"2021-04-17T16:43:49.874229Z"}
1618677829.8773582: {"type":"l2update","product_id":"SKL-BTC","changes":[["buy","0.00001301","11053.7"]],"time":"2021-04-17T16:43:49.880381Z"}
1618677829.8774579: {"type":"l2update","product_id":"SKL-USD","changes":[["sell","0.7935","1265.2"]],"time":"2021-04-17T16:43:49.884292Z"}
1618677829.877509: {"type":"l2update","product_id":"SKL-USD","changes":[["buy","0.7872","3300.7"]],"time":"2021-04-17T16:43:49.884307Z"}
1618677829.877552: {"type":"l2update","product_id":"SKL-USD","changes":[["buy","0.7793","64851.1"]],"time":"2021-04-17T16:43:49.884307Z"}
1618677829.87759: {"type":"l2update","product_id":"SKL-USD","changes":[["buy","0.7715","58335.9"]],"time":"2021-04-17T16:43:49.884307Z"}
1618677829.877641: {"type":"l2update","product_id":"SKL-USD","changes":[["sell","0.7914","5723.1"]],"time":"2021-04-17T16:43:49.884307Z"}
1618677829.877677: {"type":"l2update","product_id":"SKL-USD","changes":[["sell","0.7924","0.0"]],"time":"2021-04-17T16:43:49.884425Z"}
1618677829.885468: {"type":"l2update","product_id":"NMR-EUR","changes":[["buy","66.9249","1.303"]],"time":"2021-04-17T16:43:49.891936Z"}
1618677829.88558: {"type":"l2update","product_id":"SKL-BTC","changes":[["sell","0.00001352","1330.0"]],"time":"2021-04-17T16:43:49.891972Z"}
1618677829.895421: {"type":"l2update","product_id":"CRV-EUR","changes":[["buy","3.2964","5281.86"]],"time":"2021-04-17T16:43:49.895698Z"}
1618677829.895515: {"type":"l2update","product_id":"NMR-EUR","changes":[["buy","66.9248","0.000"]],"time":"2021-04-17T16:43:49.898887Z"}
1618677829.8955882: {"type":"l2update","product_id":"NMR-EUR","changes":[["buy","66.9251","4.774"]],"time":"2021-04-17T16:43:49.906135Z"}
1618677829.8956401: {"type":"l2update","product_id":"SKL-GBP","changes":[["sell","0.5778","1260.1"]],"time":"2021-04-17T16:43:49.906319Z"}
1618677829.909722: {"type":"l2update","product_id":"CRV-EUR","changes":[["buy","3.2919","1219.88"]],"time":"2021-04-17T16:43:49.910331Z"}
1618677829.9098198: {"type":"l2update","product_id":"SKL-USD","changes":[["sell","0.7914","12631.1"]],"time":"2021-04-17T16:43:49.917646Z"}
1618677829.909871: {"type":"l2update","product_id":"DASH-BTC","changes":[["sell","0.00620321","0.00000000"]],"time":"2021-04-17T16:43:49.920558Z"}
1618677829.909929: {"type":"l2update","product_id":"CRV-EUR","changes":[["buy","3.2955","0.00"]],"time":"2021-04-17T16:43:49.920797Z"}
1618677829.918879: {"type":"l2update","product_id":"SKL-BTC","changes":[["sell","0.00001310","610.0"]],"time":"2021-04-17T16:43:49.935038Z"}
1618677829.924549: {"type":"l2update","product_id":"SKL-USD","changes":[["sell","0.7916","0.0"]],"time":"2021-04-17T16:43:49.936503Z"}
1618677829.924659: {"type":"l2update","product_id":"DASH-BTC","changes":[["sell","0.00620476","1.62300000"]],"time":"2021-04-17T16:43:49.938814Z"}
1618677829.933372: {"type":"l2update","product_id":"SKL-BTC","changes":[["sell","0.00001306","6569.3"]],"time":"2021-04-17T16:43:49.940162Z"}
1618677829.9389539: {"type":"l2update","product_id":"SKL-USD","changes":[["sell","0.8084","270.0"]],"time":"2021-04-17T16:43:49.949104Z"}
1618677829.948874: {"type":"l2update","product_id":"SKL-BTC","changes":[["buy","0.00001301","12035.3"]],"time":"2021-04-17T16:43:49.952343Z"}
1618677829.9489632: {"type":"l2update","product_id":"SKL-BTC","changes":[["sell","0.00001308","3700.0"]],"time":"2021-04-17T16:43:49.952343Z"}
1618677829.949016: {"type":"l2update","product_id":"SKL-USD","changes":[["sell","0.7995","1000.0"]],"time":"2021-04-17T16:43:49.956156Z"}
1618677829.957338: {"type":"l2update","product_id":"DASH-BTC","changes":[["sell","0.00620281","2.23600000"]],"time":"2021-04-17T16:43:49.959937Z"}
1618677829.962623: {"type":"l2update","product_id":"DASH-BTC","changes":[["sell","0.00619731","2.50900000"]],"time":"2021-04-17T16:43:49.963832Z"}
1618677829.969356: {"type":"l2update","product_id":"SKL-USD","changes":[["sell","0.7940","5.0"]],"time":"2021-04-17T16:43:49.976846Z"}
1618677829.9755971: {"type":"l2update","product_id":"SKL-GBP","changes":[["buy","0.5720","1735.0"]],"time":"2021-04-17T16:43:49.990250Z"}
1618677829.9896052: {"type":"l2update","product_id":"SKL-USD","changes":[["sell","0.7927","30868.4"]],"time":"2021-04-17T16:43:49.994868Z"}
1618677829.9897249: {"type":"l2update","product_id":"DASH-BTC","changes":[["buy","0.00618147","0.00000000"]],"time":"2021-04-17T16:43:49.995255Z"}
1618677829.9926221: {"type":"l2update","product_id":"DASH-BTC","changes":[["sell","0.00620497","14.63200000"]],"time":"2021-04-17T16:43:50.006006Z"}
1618677830.011542: {"type":"l2update","product_id":"BAND-BTC","changes":[["sell","0.00033498","0.00"]],"time":"2021-04-17T16:43:50.020503Z"}
1618677830.025847: {"type":"l2update","product_id":"NMR-EUR","changes":[["buy","66.9249","0.000"]],"time":"2021-04-17T16:43:50.040543Z"}
1618677830.030915: {"type":"l2update","product_id":"SKL-BTC","changes":[["sell","0.00001307","4448.5"]],"time":"2021-04-17T16:43:50.043633Z"}
1618677830.035021: {"type":"l2update","product_id":"SKL-USD","changes":[["sell","0.8151","3826.9"]],"time":"2021-04-17T16:43:50.044631Z"}
1618677830.0410612: {"type":"l2update","product_id":"SKL-GBP","changes":[["buy","0.5705","865.0"]],"time":"2021-04-17T16:43:50.052065Z"}
1618677830.050294: {"type":"l2update","product_id":"NMR-EUR","changes":[["buy","66.9252","1.303"]],"time":"2021-04-17T16:43:50.062866Z"}
1618677830.062015: {"type":"l2update","product_id":"BAND-BTC","changes":[["sell","0.00033490","36.76"]],"time":"2021-04-17T16:43:50.066869Z"}
1618677830.062119: {"type":"l2update","product_id":"NMR-EUR","changes":[["buy","66.9251","0.000"]],"time":"2021-04-17T16:43:50.068131Z"}
1618677830.064857: {"type":"l2update","product_id":"NMR-EUR","changes":[["buy","66.9254","4.774"]],"time":"2021-04-17T16:43:50.073681Z"}
1618677830.064961: {"type":"l2update","product_id":"DASH-BTC","changes":[["buy","0.00614339","0.00000000"]],"time":"2021-04-17T16:43:50.076106Z"}
1618677830.0650282: {"type":"l2update","product_id":"DASH-BTC","changes":[["buy","0.00614340","0.14000000"]],"time":"2021-04-17T16:43:50.076106Z"}
1618677830.07349: {"type":"l2update","product_id":"DASH-BTC","changes":[["buy","0.00618013","32.84700000"]],"time":"2021-04-17T16:43:50.081787Z"}
1618677830.073555: {"type":"l2update","product_id":"DASH-BTC","changes":[["buy","0.00615250","1.79000000"]],"time":"2021-04-17T16:43:50.085346Z"}
1618677830.0735931: {"type":"l2update","product_id":"DASH-BTC","changes":[["buy","0.00614343","1.56000000"]],"time":"2021-04-17T16:43:50.085346Z"}
1618677830.0736241: {"type":"l2update","product_id":"DASH-BTC","changes":[["buy","0.00614342","4.37000000"]],"time":"2021-04-17T16:43:50.085346Z"}
1618677830.073649: {"type":"l2update","product_id":"BAND-GBP","changes":[["sell","14.7871","0.00"]],"time":"2021-04-17T16:43:50.087077Z"}
1618677830.0798888: {"type":"l2update","product_id":"BAND-GBP","changes":[["buy","14.7614","12.58"]],"time":"2021-04-17T16:43:50.092809Z"}
1618677830.0799491: {"type":"l2update","product_id":"BAND-BTC","changes":[["buy","0.00033417","0.00"]],"time":"2021-04-17T16:43:50.094195Z"}
1618677830.07999: {"type":"l2update","product_id":"BAND-GBP","changes":[["buy","14.7061","15.60"]],"time":"2021-04-17T16:43:50.095200Z"}
1618677830.087937: {"type":"l2update","product_id":"BAND-BTC","changes":[["buy","0.00033422","152.82"]],"time":"2021-04-17T16:43:50.100282Z"}
1618677830.099301: {"type":"l2update","product_id":"SKL-USD","changes":[["sell","0.8185","3098.5"]],"time":"2021-04-17T16:43:50.107314Z"}
1618677830.121552: {"type":"l2update","product_id":"BAND-BTC","changes":[["sell","0.00033477","35.71"]],"time":"2021-04-17T16:43:50.129459Z"}
1618677830.131526: {"type":"l2update","product_id":"SKL-USD","changes":[["sell","0.8209","3327.5"]],"time":"2021-04-17T16:43:50.136971Z"}
1618677830.131573: {"type":"l2update","product_id":"YFI-BTC","changes":[["sell","0.82693","0.030000"]],"time":"2021-04-17T16:43:50.140533Z"}
1618677830.15151: {"type":"l2update","product_id":"BAND-GBP","changes":[["buy","14.6490","0.00"]],"time":"2021-04-17T16:43:50.154357Z"}
1618677830.151562: {"type":"l2update","product_id":"BAND-GBP","changes":[["buy","14.6491","0.60"]],"time":"2021-04-17T16:43:50.154357Z"}
1618677830.1515892: {"type":"l2update","product_id":"BAND-BTC","changes":[["buy","0.00033375","0.00"]],"time":"2021-04-17T16:43:50.156292Z"}
1618677830.151617: {"type":"l2update","product_id":"BAND-GBP","changes":[["buy","14.6495","5.60"]],"time":"2021-04-17T16:43:50.159497Z"}
1618677830.151645: {"type":"l2update","product_id":"BAND-GBP","changes":[["buy","14.6494","11.90"]],"time":"2021-04-17T16:43:50.159497Z"}
1618677830.151665: {"type":"l2update","product_id":"BAND-BTC","changes":[["sell","0.00033561","0.00"]],"time":"2021-04-17T16:43:50.161262Z"}
1618677830.151689: {"type":"l2update","product_id":"DASH-BTC","changes":[["buy","0.00618010","0.00000000"]],"time":"2021-04-17T16:43:50.160867Z"}
1618677830.15856: {"type":"l2update","product_id":"SKL-BTC","changes":[["sell","0.00001308","6337.5"]],"time":"2021-04-17T16:43:50.163467Z"}
1618677830.167901: {"type":"l2update","product_id":"DASH-BTC","changes":[["buy","0.00617110","1.88000000"]],"time":"2021-04-17T16:43:50.174398Z"}
1618677830.167951: {"type":"l2update","product_id":"DASH-BTC","changes":[["buy","0.00618778","0.00000000"]],"time":"2021-04-17T16:43:50.176407Z"}
1618677830.194866: {"type":"l2update","product_id":"SKL-USD","changes":[["sell","0.7913","0.0"]],"time":"2021-04-17T16:43:50.191501Z"}
1618677830.194921: {"type":"l2update","product_id":"BAND-GBP","changes":[["sell","14.7904","0.00"]],"time":"2021-04-17T16:43:50.191983Z"}
1618677830.194955: {"type":"l2update","product_id":"SKL-BTC","changes":[["sell","0.00001306","5460.2"]],"time":"2021-04-17T16:43:50.191834Z"}
1618677830.1949792: {"type":"l2update","product_id":"BAND-GBP","changes":[["buy","14.7652","12.04"]],"time":"2021-04-17T16:43:50.197072Z"}
1618677830.1950028: {"type":"l2update","product_id":"SKL-BTC","changes":[["buy","0.00001299","14774.3"]],"time":"2021-04-17T16:43:50.204512Z"}
1618677830.195023: {"type":"l2update","product_id":"BAND-GBP","changes":[["buy","14.7320","138.80"]],"time":"2021-04-17T16:43:50.204679Z"}
1618677830.199649: {"type":"l2update","product_id":"SKL-BTC","changes":[["sell","0.00001306","6569.3"]],"time":"2021-04-17T16:43:50.205033Z"}
1618677830.199688: {"type":"l2update","product_id":"SKL-BTC","changes":[["sell","0.00001308","13941.3"]],"time":"2021-04-17T16:43:50.205044Z"}
1618677830.2051258: {"type":"l2update","product_id":"SKL-USD","changes":[["sell","0.7914","9540.9"]],"time":"2021-04-17T16:43:50.207109Z"}
1618677830.205174: {"type":"l2update","product_id":"SKL-USD","changes":[["sell","0.7996","5.0"]],"time":"2021-04-17T16:43:50.207109Z"}
1618677830.2052: {"type":"l2update","product_id":"DASH-BTC","changes":[["buy","0.00618783","0.00000000"]],"time":"2021-04-17T16:43:50.215296Z"}
1618677830.2052321: {"type":"l2update","product_id":"SKL-BTC","changes":[["sell","0.00001308","13118.5"]],"time":"2021-04-17T16:43:50.215727Z"}
1618677830.211134: {"type":"l2update","product_id":"SKL-USD","changes":[["sell","0.7914","10558.4"]],"time":"2021-04-17T16:43:50.219103Z"}
1618677830.211176: {"type":"l2update","product_id":"SKL-BTC","changes":[["sell","0.00001306","3071.2"]],"time":"2021-04-17T16:43:50.219725Z"}
1618677830.259135: {"type":"l2update","product_id":"DASH-BTC","changes":[["sell","0.00620260","0.80000000"]],"time":"2021-04-17T16:43:50.251300Z"}
1618677830.2592351: {"type":"l2update","product_id":"SKL-BTC","changes":[["sell","0.00001306","1962.1"]],"time":"2021-04-17T16:43:50.251403Z"}
1618677830.259287: {"type":"l2update","product_id":"SKL-USD","changes":[["sell","0.7914","9540.9"]],"time":"2021-04-17T16:43:50.251855Z"}
1618677830.267264: {"type":"l2update","product_id":"NMR-EUR","changes":[["buy","66.9252","0.000"]],"time":"2021-04-17T16:43:50.264821Z"}
1618677830.278629: {"type":"l2update","product_id":"SKL-BTC","changes":[["sell","0.00001307","7086.6"]],"time":"2021-04-17T16:43:50.266810Z"}
1618677830.278674: {"type":"l2update","product_id":"DASH-BTC","changes":[["buy","0.00618543","2.95900000"]],"time":"2021-04-17T16:43:50.267408Z"}
1618677830.2787: {"type":"l2update","product_id":"DASH-BTC","changes":[["sell","0.00620497","0.00000000"]],"time":"2021-04-17T16:43:50.268411Z"}
1618677830.278731: {"type":"l2update","product_id":"SKL-USD","changes":[["buy","0.7901","915.0"]],"time":"2021-04-17T16:43:50.268740Z"}
1618677830.278752: {"type":"l2update","product_id":"BAND-BTC","changes":[["sell","0.00033810","9.50"]],"time":"2021-04-17T16:43:50.269013Z"}
1618677830.27877: {"type":"l2update","product_id":"BAND-BTC","changes":[["sell","0.00033682","7.90"]],"time":"2021-04-17T16:43:50.269080Z"}
1618677830.298253: {"type":"l2update","product_id":"SKL-BTC","changes":[["buy","0.00001302","3434.5"]],"time":"2021-04-17T16:43:50.280271Z"}
1618677830.298302: {"type":"l2update","product_id":"NMR-EUR","changes":[["buy","66.9254","3.009"]],"time":"2021-04-17T16:43:50.270671Z"}
1618677830.29833: {"type":"match","trade_id":868606,"maker_order_id":"04688f64-29b5-4ca1-8e16-e9cfa4497b0f","taker_order_id":"94793429-fff5-4ebf-a33f-d9fef19b9a8c","side":"buy","size":"1.765","price":"66.9254","product_id":"NMR-EUR","sequence":471057306,"time":"2021-04-17T16:43:50.270671Z"}
1618677830.298356: {"type":"ticker","sequence":471057306,"product_id":"NMR-EUR","price":"66.9254","open_24h":"60.9288","volume_24h":"25749.42800000","low_24h":"60.4695","high_24h":"74.5","volume_30d":"552589.72100000","best_bid":"66.9254","best_ask":"67.0210","side":"sell","time":"2021-04-17T16:43:50.270671Z","trade_id":868606,"last_size":"1.765"}
1618677830.298378: {"type":"l2update","product_id":"SKL-USD","changes":[["sell","0.7927","1108.3"]],"time":"2021-04-17T16:43:50.281009Z"}
1618677830.298401: {"type":"l2update","product_id":"SKL-BTC","changes":[["sell","0.00001310","1432.8"]],"time":"2021-04-17T16:43:50.290049Z"}
1618677830.298419: {"type":"l2update","product_id":"YFI-BTC","changes":[["sell","0.83217","0.000000"]],"time":"2021-04-17T16:43:50.290886Z"}
1618677830.298456: {"type":"l2update","product_id":"YFI-BTC","changes":[["sell","0.83216","0.000000"]],"time":"2021-04-17T16:43:50.290886Z"}
1618677830.29848: {"type":"l2update","product_id":"YFI-BTC","changes":[["sell","0.83215","0.008280"]],"time":"2021-04-17T16:43:50.290886Z"}
1618677830.298497: {"type":"l2update","product_id":"SKL-BTC","changes":[["sell","0.00001309","4234.3"]],"time":"2021-04-17T16:43:50.291227Z"}
1618677830.2985148: {"type":"l2update","product_id":"DASH-BTC","changes":[["sell","0.00619813","2.69600000"]],"time":"2021-04-17T16:43:50.293511Z"}
1618677830.298538: {"type":"l2update","product_id":"DASH-BTC","changes":[["sell","0.00620281","0.00000000"]],"time":"2021-04-17T16:43:50.293597Z"}
1618677830.29856: {"type":"l2update","product_id":"NMR-EUR","changes":[["buy","66.4818","20.000"]],"time":"2021-04-17T16:43:50.294239Z"}
1618677830.298578: {"type":"l2update","product_id":"DASH-BTC","changes":[["sell","0.00619731","0.00000000"]],"time":"2021-04-17T16:43:50.296359Z"}
1618677830.301053: {"type":"l2update","product_id":"NMR-EUR","changes":[["buy","66.9254","0.000"]],"time":"2021-04-17T16:43:50.300250Z"}
1618677830.301106: {"type":"l2update","product_id":"NMR-EUR","changes":[["buy","66.9255","1.303"]],"time":"2021-04-17T16:43:50.302051Z"}
1618677830.301138: {"type":"l2update","product_id":"YFI-BTC","changes":[["sell","0.83213","0.024000"]],"time":"2021-04-17T16:43:50.302359Z"}
1618677830.301161: {"type":"l2update","product_id":"YFI-BTC","changes":[["sell","0.83212","0.012740"]],"time":"2021-04-17T16:43:50.302359Z"}
1618677830.3011851: {"type":"l2update","product_id":"YFI-BTC","changes":[["sell","0.83186","0.002520"]],"time":"2021-04-17T16:43:50.302359Z"}
1618677830.311838: {"type":"l2update","product_id":"SKL-USD","changes":[["buy","0.7898","989.7"]],"time":"2021-04-17T16:43:50.309079Z"}
1618677830.318069: {"type":"l2update","product_id":"BAND-BTC","changes":[["buy","0.00033416","0.00"]],"time":"2021-04-17T16:43:50.315241Z"}
1618677830.348622: {"type":"l2update","product_id":"SKL-USD","changes":[["sell","0.7943","29765.1"]],"time":"2021-04-17T16:43:50.316134Z"}
1618677830.34867: {"type":"l2update","product_id":"DASH-BTC","changes":[["sell","0.00620476","3.85900000"]],"time":"2021-04-17T16:43:50.330726Z"}
1618677830.3486981: {"type":"l2update","product_id":"NMR-EUR","changes":[["buy","66.4820","13.000"]],"time":"2021-04-17T16:43:50.330538Z"}
1618677830.348727: {"type":"l2update","product_id":"SKL-USD","changes":[["buy","0.7903","989.7"]],"time":"2021-04-17T16:43:50.330571Z"}
1618677830.348751: {"type":"l2update","product_id":"BAND-BTC","changes":[["buy","0.00033381","90.44"]],"time":"2021-04-17T16:43:50.334829Z"}
1618677830.3487701: {"type":"l2update","product_id":"SKL-BTC","changes":[["buy","0.00001301","11053.7"]],"time":"2021-04-17T16:43:50.343693Z"}
1618677830.348788: {"type":"l2update","product_id":"SKL-USD","changes":[["buy","0.7901","465.0"]],"time":"2021-04-17T16:43:50.350640Z"}
1618677830.3488052: {"type":"l2update","product_id":"SKL-USD","changes":[["sell","0.7914","2632.9"]],"time":"2021-04-17T16:43:50.353840Z"}
1618677830.348821: {"type":"l2update","product_id":"SKL-USD","changes":[["buy","0.7679","0.0"]],"time":"2021-04-17T16:43:50.359792Z"}
1618677830.355687: {"type":"l2update","product_id":"SKL-USD","changes":[["buy","0.7576","0.0"]],"time":"2021-04-17T16:43:50.359792Z"}
1618677830.355743: {"type":"l2update","product_id":"SKL-USD","changes":[["buy","0.7896","0.0"]],"time":"2021-04-17T16:43:50.367502Z"}
1618677830.383625: {"type":"l2update","product_id":"NMR-EUR","changes":[["buy","66.9255","0.000"]],"time":"2021-04-17T16:43:50.387110Z"}
1618677830.383679: {"type":"l2update","product_id":"BAND-BTC","changes":[["sell","0.00033477","0.00"]],"time":"2021-04-17T16:43:50.390102Z"}
1618677830.395308: {"type":"l2update","product_id":"YFI-BTC","changes":[["buy","0.82553","0.000000"]],"time":"2021-04-17T16:43:50.391109Z"}
1618677830.400857: {"type":"l2update","product_id":"SKL-USD","changes":[["buy","0.7675","0.0"]],"time":"2021-04-17T16:43:50.391574Z"}
1618677830.400906: {"type":"l2update","product_id":"SKL-USD","changes":[["buy","0.7569","22756.0"]],"time":"2021-04-17T16:43:50.391574Z"}
1618677830.417595: {"type":"l2update","product_id":"BAND-BTC","changes":[["buy","0.00033423","36.75"]],"time":"2021-04-17T16:43:50.414248Z"}
1618677830.4176419: {"type":"l2update","product_id":"SKL-USD","changes":[["sell","0.7924","6908.0"]],"time":"2021-04-17T16:43:50.414591Z"}
1618677830.417674: {"type":"l2update","product_id":"SKL-BTC","changes":[["buy","0.00001303","1091.6"]],"time":"2021-04-17T16:43:50.414952Z"}
1618677830.4176939: {"type":"l2update","product_id":"DASH-BTC","changes":[["sell","0.00620269","14.63200000"]],"time":"2021-04-17T16:43:50.415826Z"}
1618677830.417718: {"type":"l2update","product_id":"BAND-BTC","changes":[["sell","0.00033538","39.00"]],"time":"2021-04-17T16:43:50.416139Z"}
1618677830.428471: {"type":"l2update","product_id":"SKL-USD","changes":[["buy","0.7903","1439.7"]],"time":"2021-04-17T16:43:50.419241Z"}
1618677830.428554: {"type":"l2update","product_id":"NMR-EUR","changes":[["buy","66.8895","1.322"]],"time":"2021-04-17T16:43:50.419897Z"}
1618677830.42862: {"type":"l2update","product_id":"SKL-GBP","changes":[["buy","0.5720","0.0"]],"time":"2021-04-17T16:43:50.419935Z"}
1618677830.428649: {"type":"l2update","product_id":"SKL-GBP","changes":[["buy","0.5706","0.0"]],"time":"2021-04-17T16:43:50.419935Z"}
1618677830.430603: {"type":"l2update","product_id":"SKL-USD","changes":[["sell","0.7914","2385.5"]],"time":"2021-04-17T16:43:50.420805Z"}
1618677830.430648: {"type":"match","trade_id":1568281,"maker_order_id":"103763b5-c234-4319-bb70-26e60e9bbe0c","taker_order_id":"1d5e1272-be58-4100-9ba2-4906ccca092a","side":"sell","size":"247.4","price":"0.7914","product_id":"SKL-USD","sequence":201391650,"time":"2021-04-17T16:43:50.420805Z"}
1618677830.430681: {"type":"ticker","sequence":201391650,"product_id":"SKL-USD","price":"0.7914","open_24h":"0.7055","volume_24h":"34259264.50000000","low_24h":"0.6915","high_24h":"0.8098","volume_30d":"948686617.20000000","best_bid":"0.7903","best_ask":"0.7914","side":"buy","time":"2021-04-17T16:43:50.420805Z","trade_id":1568281,"last_size":"247.4"}
1618677830.430704: {"type":"l2update","product_id":"DASH-BTC","changes":[["sell","0.00619639","0.00000000"]],"time":"2021-04-17T16:43:50.428368Z"}
1618677830.430738: {"type":"l2update","product_id":"SKL-USD","changes":[["sell","0.7923","2944.2"]],"time":"2021-04-17T16:43:50.428966Z"}
1618677830.4307652: {"type":"l2update","product_id":"SKL-USD","changes":[["sell","0.7996","23899.8"]],"time":"2021-04-17T16:43:50.428966Z"}
1618677830.430785: {"type":"l2update","product_id":"SKL-USD","changes":[["buy","0.7904","450.0"]],"time":"2021-04-17T16:43:50.429013Z"}
1618677830.4358091: {"type":"l2update","product_id":"SKL-USD","changes":[["sell","0.7925","3846.1"]],"time":"2021-04-17T16:43:50.431009Z"}
1618677830.435851: {"type":"l2update","product_id":"NMR-EUR","changes":[["buy","66.9224","0.000"]],"time":"2021-04-17T16:43:50.432043Z"}
1618677830.435884: {"type":"l2update","product_id":"SKL-BTC","changes":[["sell","0.00001309","6134.3"]],"time":"2021-04-17T16:43:50.431146Z"}
1618677830.4414651: {"type":"l2update","product_id":"BAND-BTC","changes":[["buy","0.00033422","123.20"]],"time":"2021-04-17T16:43:50.436735Z"}
1618677830.441509: {"type":"l2update","product_id":"SKL-USD","changes":[["sell","0.7943","5.0"]],"time":"2021-04-17T16:43:50.437817Z"}
1618677830.445494: {"type":"l2update","product_id":"CRV-EUR","changes":[["buy","3.2964","281.86"]],"time":"2021-04-17T16:43:50.444119Z"}
1618677830.445538: {"type":"l2update","product_id":"BAND-BTC","changes":[["buy","0.00033424","29.62"]],"time":"2021-04-17T16:43:50.440333Z"}
1618677830.445568: {"type":"l2update","product_id":"SKL-BTC","changes":[["buy","0.00001300","2200.7"]],"time":"2021-04-17T16:43:50.440529Z"}
1618677830.445589: {"type":"l2update","product_id":"SKL-USD","changes":[["buy","0.7903","989.7"]],"time":"2021-04-17T16:43:50.445427Z"}
1618677830.445608: {"type":"l2update","product_id":"SKL-BTC","changes":[["buy","0.00001299","14414.9"]],"time":"2021-04-17T16:43:50.446468Z"}
1618677830.445625: {"type":"l2update","product_id":"SKL-BTC","changes":[["buy","0.00001299","11253.9"]],"time":"2021-04-17T16:43:50.446468Z"}
1618677830.454404: {"type":"l2update","product_id":"CRV-EUR","changes":[["buy","3.2960","5000.00"]],"time":"2021-04-17T16:43:50.458104Z"}
1618677830.454457: {"type":"l2update","product_id":"SKL-BTC","changes":[["buy","0.00001303","1986.0"]],"time":"2021-04-17T16:43:50.458570Z"}
1618677830.454483: {"type":"l2update","product_id":"SKL-GBP","changes":[["buy","0.5726","1735.0"]],"time":"2021-04-17T16:43:50.458667Z"}
1618677830.454507: {"type":"l2update","product_id":"SKL-GBP","changes":[["buy","0.5720","5788.0"]],"time":"2021-04-17T16:43:50.458667Z"}
1618677830.457906: {"type":"l2update","product_id":"YFI-BTC","changes":[["buy","0.82550","0.030555"]],"time":"2021-04-17T16:43:50.460426Z"}
1618677830.457943: {"type":"l2update","product_id":"SKL-USD","changes":[["buy","0.7895","2526.7"]],"time":"2021-04-17T16:43:50.460577Z"}
1618677830.457973: {"type":"l2update","product_id":"SKL-BTC","changes":[["buy","0.00001296","0.0"]],"time":"2021-04-17T16:43:50.462768Z"}
1618677830.458005: {"type":"l2update","product_id":"SKL-BTC","changes":[["sell","0.00001649","0.0"]],"time":"2021-04-17T16:43:50.462768Z"}
1618677830.4580312: {"type":"l2update","product_id":"SKL-BTC","changes":[["sell","0.00001654","0.0"]],"time":"2021-04-17T16:43:50.462768Z"}
1618677830.463611: {"type":"l2update","product_id":"NMR-EUR","changes":[["buy","66.8948","4.776"]],"time":"2021-04-17T16:43:50.463923Z"}
1618677830.463656: {"type":"l2update","product_id":"YFI-BTC","changes":[["buy","0.82553","0.017060"]],"time":"2021-04-17T16:43:50.464382Z"}
1618677830.463684: {"type":"l2update","product_id":"NMR-EUR","changes":[["buy","66.8895","0.000"]],"time":"2021-04-17T16:43:50.464664Z"}
1618677830.4796522: {"type":"l2update","product_id":"SKL-USD","changes":[["buy","0.7899","2632.1"]],"time":"2021-04-17T16:43:50.483512Z"}
1618677830.479699: {"type":"l2update","product_id":"DASH-BTC","changes":[["sell","0.00619412","2.50900000"]],"time":"2021-04-17T16:43:50.483533Z"}
1618677830.479729: {"type":"l2update","product_id":"BAND-BTC","changes":[["buy","0.00033380","24.00"]],"time":"2021-04-17T16:43:50.483847Z"}
1618677830.479754: {"type":"l2update","product_id":"SKL-USD","changes":[["sell","0.7941","32488.5"]],"time":"2021-04-17T16:43:50.483892Z"}
1618677830.494008: {"type":"l2update","product_id":"SKL-BTC","changes":[["sell","0.00001314","7490.6"]],"time":"2021-04-17T16:43:50.485872Z"}
1618677830.4940538: {"type":"l2update","product_id":"SKL-BTC","changes":[["sell","0.00001313","360.8"]],"time":"2021-04-17T16:43:50.485872Z"}
1618677830.49408: {"type":"l2update","product_id":"SKL-BTC","changes":[["buy","0.00001295","1080.0"]],"time":"2021-04-17T16:43:50.485872Z"}
1618677830.4940999: {"type":"l2update","product_id":"SKL-USD","changes":[["sell","0.7931","8960.8"]],"time":"2021-04-17T16:43:50.486928Z"}
1618677830.494118: {"type":"l2update","product_id":"DASH-BTC","changes":[["sell","0.00619638","0.00000000"]],"time":"2021-04-17T16:43:50.489194Z"}
1618677830.5036201: {"type":"l2update","product_id":"DASH-BTC","changes":[["sell","0.00619637","2.57400000"]],"time":"2021-04-17T16:43:50.498131Z"}
1618677830.503674: {"type":"l2update","product_id":"NMR-EUR","changes":[["buy","66.9225","1.322"]],"time":"2021-04-17T16:43:50.501745Z"}
1618677830.516352: {"type":"l2update","product_id":"DASH-BTC","changes":[["buy","0.00618583","2.68300000"]],"time":"2021-04-17T16:43:50.520912Z"}
1618677830.524259: {"type":"l2update","product_id":"CRV-EUR","changes":[["sell","3.3111","0.00"]],"time":"2021-04-17T16:43:50.525323Z"}
1618677830.5243142: {"type":"l2update","product_id":"CRV-EUR","changes":[["sell","3.3076","0.00"]],"time":"2021-04-17T16:43:50.525323Z"}
1618677830.524344: {"type":"l2update","product_id":"DASH-BTC","changes":[["buy","0.00618187","0.00000000"]],"time":"2021-04-17T16:43:50.526700Z"}
