1618677817.130411: {"type":"l2update","product_id":"YFI-BTC","changes":[["sell","0.82754","0.000000"]],"time":"2021-04-17T16:43:37.132926Z"}
1618677817.130431: {"type":"l2update","product_id":"SKL-BTC","changes":[["sell","0.00001307","13048.0"]],"time":"2021-04-17T16:43:37.133700Z"}
1618677817.130444: {"type":"l2update","product_id":"SKL-USD","changes":[["buy","0.7828","110.0"]],"time":"2021-04-17T16:43:37.132833Z"}
1618677817.130458: {"type":"l2update","product_id":"SKL-BTC","changes":[["buy","0.00001294","27886.6"]],"time":"2021-04-17T16:43:37.133700Z"}
1618677817.1304698: {"type":"l2update","product_id":"BAND-BTC","changes":[["sell","0.00033531","0.00"]],"time":"2021-04-17T16:43:37.135599Z"}
1618677817.130487: {"type":"l2update","product_id":"SKL-BTC","changes":[["buy","0.00001292","11129.4"]],"time":"2021-04-17T16:43:37.133700Z"}
1618677817.1304991: {"type":"l2update","product_id":"SKL-BTC","changes":[["buy","0.00001290","12379.5"]],"time":"2021-04-17T16:43:37.133700Z"}
1618677817.130511: {"type":"l2update","product_id":"SKL-BTC","changes":[["buy","0.00001286","50158.6"]],"time":"2021-04-17T16:43:37.133700Z"}
1618677817.130522: {"type":"l2update","product_id":"SKL-USD","changes":[["sell","0.7911","0.0"]],"time":"2021-04-17T16:43:37.136871Z"}
1618677817.1305358: {"type":"l2update","product_id":"SKL-BTC","changes":[["buy","0.00001301","5045.6"]],"time":"2021-04-17T16:43:37.137137Z"}
1618677817.13055: {"type":"l2update","product_id":"SKL-BTC","changes":[["buy","0.00001299","1586.2"]],"time":"2021-04-17T16:43:37.137313Z"}
1618677817.135234: {"type":"l2update","product_id":"SKL-USD","changes":[["sell","0.7912","5121.0"]],"time":"2021-04-17T16:43:37.140491Z"}
1618677817.135267: {"type":"match","trade_id":1568269,"maker_order_id":"c693fab4-fc61-4b10-97e8-28b7cf4478d4","taker_order_id":"97d525bb-9bf4-43e4-8942-c47f50cd52a1","side":"sell","size":"1787","price":"0.7912","product_id":"SKL-USD","sequence":201390097,"time":"2021-04-17T16:43:37.140491Z"}
1618677817.135285: {"type":"ticker","sequence":201390097,"product_id":"SKL-USD","price":"0.7912","open_24h":"0.7055","volume_24h":"34222265.50000000","low_24h":"0.6915","high_24h":"0.8098","volume_30d":"948649618.20000000","best_bid":"0.7902","best_ask":"0.7912","side":"buy","time":"2021-04-17T16:43:37.140491Z","trade_id":1568269,"last_size":"1787"}
1618677817.1353018: {"type":"l2update","product_id":"SKL-BTC","changes":[["buy","0.00001299","8902.1"]],"time":"2021-04-17T16:43:37.144057Z"}
1618677817.135318: {"type":"l2update","product_id":"SKL-USD","changes":[["sell","0.7912","0.0"]],"time":"2021-04-17T16:43:37.146522Z"}
1618677817.135339: {"type":"l2update","product_id":"SKL-BTC","changes":[["buy","0.00001285","22717.7"]],"time":"2021-04-17T16:43:37.147930Z"}
1618677817.1353521: {"type":"l2update","product_id":"SKL-BTC","changes":[["buy","0.00001271","5.0"]],"time":"2021-04-17T16:43:37.147930Z"}
1618677817.1353679: {"type":"l2update","product_id":"SKL-BTC","changes":[["sell","0.00001313","9160.8"]],"time":"2021-04-17T16:43:37.147930Z"}
1618677817.13538: {"type":"l2update","product_id":"SKL-BTC","changes":[["sell","0.00001327","5.0"]],"time":"2021-04-17T16:43:37.147930Z"}
1618677817.135395: {"type":"l2update","product_id":"SKL-USD","changes":[["buy","0.7886","868.5"]],"time":"2021-04-17T16:43:37.148082Z"}
1618677817.1354089: {"type":"l2update","product_id":"SKL-USD","changes":[["sell","0.7926","0.0"]],"time":"2021-04-17T16:43:37.148789Z"}
1618677817.135425: {"type":"l2update","product_id":"SKL-USD","changes":[["buy","0.7854","5.0"]],"time":"2021-04-17T16:43:37.149500Z"}
1618677817.141662: {"type":"l2update","product_id":"SKL-USD","changes":[["buy","0.7871","10237.7"]],"time":"2021-04-17T16:43:37.151543Z"}
1618677817.141706: {"type":"l2update","product_id":"SKL-USD","changes":[["buy","0.7873","0.0"]],"time":"2021-04-17T16:43:37.154259Z"}
1618677817.1417432: {"type":"l2update","product_id":"SKL-USD","changes":[["buy","0.7901","450.0"]],"time":"2021-04-17T16:43:37.154802Z"}
1618677817.141765: {"type":"l2update","product_id":"BAND-BTC","changes":[["buy","0.00033395","25.73"]],"time":"2021-04-17T16:43:37.155363Z"}
1618677817.14179: {"type":"l2update","product_id":"SKL-USD","changes":[["sell","0.7937","5.0"]],"time":"2021-04-17T16:43:37.156103Z"}
1618677817.150399: {"type":"l2update","product_id":"YFI-BTC","changes":[["buy","0.81813","0.000000"]],"time":"2021-04-17T16:43:37.159235Z"}
1618677817.150503: {"type":"l2update","product_id":"SKL-BTC","changes":[["sell","0.00001312","215.0"]],"time":"2021-04-17T16:43:37.159409Z"}
1618677817.150558: {"type":"l2update","product_id":"SKL-USD","changes":[["buy","0.7903","450.0"]],"time":"2021-04-17T16:43:37.159419Z"}
1618677817.15061: {"type":"l2update","product_id":"SKL-USD","changes":[["sell","0.7963","175.8"]],"time":"2021-04-17T16:43:37.159683Z"}
1618677817.150648: {"type":"l2update","product_id":"SKL-USD","changes":[["sell","0.8048","57.0"]],"time":"2021-04-17T16:43:37.159683Z"}
1618677817.152412: {"type":"l2update","product_id":"SKL-USD","changes":[["buy","0.7874","7206.8"]],"time":"2021-04-17T16:43:37.162443Z"}
1618677817.152477: {"type":"l2update","product_id":"SKL-USD","changes":[["sell","0.7924","0.0"]],"time":"2021-04-17T16:43:37.164472Z"}
1618677817.152519: {"type":"l2update","product_id":"SKL-USD","changes":[["sell","0.7916","2631.4"]],"time":"2021-04-17T16:43:37.166332Z"}
1618677817.154506: {"type":"l2update","product_id":"SKL-USD","changes":[["sell","0.7940","5.0"]],"time":"2021-04-17T16:43:37.169526Z"}
1618677817.160979: {"type":"l2update","product_id":"SKL-USD","changes":[["buy","0.7860","1277.3"]],"time":"2021-04-17T16:43:37.176676Z"}
1618677817.1655822: {"type":"l2update","product_id":"SKL-USD","changes":[["sell","0.7916","25643.4"]],"time":"2021-04-17T16:43:37.177604Z"}
1618677817.1657028: {"type":"l2update","product_id":"SKL-USD","changes":[["buy","0.7884","3726.1"]],"time":"2021-04-17T16:43:37.177686Z"}
1618677817.165757: {"type":"l2update","product_id":"SKL-USD","changes":[["sell","0.7939","29930.9"]],"time":"2021-04-17T16:43:37.177704Z"}
1618677817.1657972: {"type":"l2update","product_id":"SKL-USD","changes":[["sell","0.8198","2907.4"]],"time":"2021-04-17T16:43:37.177766Z"}
1618677817.165855: {"type":"l2update","product_id":"SKL-USD","changes":[["buy","0.7871","3913.2"]],"time":"2021-04-17T16:43:37.179553Z"}
1618677817.165878: {"type":"l2update","product_id":"SKL-GBP","changes":[["sell","0.5767","0.0"]],"time":"2021-04-17T16:43:37.179891Z"}
1618677817.1689448: {"type":"l2update","product_id":"SKL-BTC","changes":[["sell","0.00001309","4609.8"]],"time":"2021-04-17T16:43:37.181626Z"}
1618677817.169035: {"type":"l2update","product_id":"SKL-BTC","changes":[["sell","0.00001307","14438.0"]],"time":"2021-04-17T16:43:37.181626Z"}
1618677817.1690712: {"type":"l2update","product_id":"SKL-BTC","changes":[["sell","0.00001306","6054.9"]],"time":"2021-04-17T16:43:37.181626Z"}
1618677817.1742542: {"type":"l2update","product_id":"SKL-USD","changes":[["buy","0.7861","5.0"]],"time":"2021-04-17T16:43:37.184270Z"}
1618677817.17434: {"type":"l2update","product_id":"SKL-USD","changes":[["sell","0.7961","7074.4"]],"time":"2021-04-17T16:43:37.185110Z"}
1618677817.1743731: {"type":"l2update","product_id":"SKL-BTC","changes":[["buy","0.00001301","1253.0"]],"time":"2021-04-17T16:43:37.185327Z"}
1618677817.1744: {"type":"l2update","product_id":"SKL-GBP","changes":[["sell","0.5766","0.0"]],"time":"2021-04-17T16:43:37.185367Z"}
1618677817.174439: {"type":"l2update","product_id":"SKL-BTC","changes":[["buy","0.00001297","6174.9"]],"time":"2021-04-17T16:43:37.185417Z"}
1618677817.174463: {"type":"l2update","product_id":"SKL-BTC","changes":[["buy","0.00001297","2672.0"]],"time":"2021-04-17T16:43:37.185417Z"}
1618677817.174485: {"type":"l2update","product_id":"SKL-BTC","changes":[["sell","0.00001319","84.0"]],"time":"2021-04-17T16:43:37.185417Z"}
1618677817.174506: {"type":"l2update","product_id":"SKL-BTC","changes":[["sell","0.00001352","33.1"]],"time":"2021-04-17T16:43:37.185859Z"}
1618677817.174526: {"type":"l2update","product_id":"SKL-BTC","changes":[["sell","0.00001348","865.5"]],"time":"2021-04-17T16:43:37.185859Z"}
1618677817.174547: {"type":"l2update","product_id":"SKL-USD","changes":[["sell","0.7939","29760.1"]],"time":"2021-04-17T16:43:37.185963Z"}
1618677817.174568: {"type":"l2update","product_id":"SKL-BTC","changes":[["sell","0.00001344","10.0"]],"time":"2021-04-17T16:43:37.185859Z"}
1618677817.174589: {"type":"l2update","product_id":"SKL-BTC","changes":[["sell","0.00001337","10.9"]],"time":"2021-04-17T16:43:37.185859Z"}
1618677817.1746078: {"type":"l2update","product_id":"SKL-GBP","changes":[["sell","0.5787","0.0"]],"time":"2021-04-17T16:43:37.186904Z"}
1618677817.174634: {"type":"l2update","product_id":"SKL-BTC","changes":[["sell","0.00001333","0.0"]],"time":"2021-04-17T16:43:37.185859Z"}
1618677817.174664: {"type":"l2update","product_id":"SKL-BTC","changes":[["sell","0.00001329","21.6"]],"time":"2021-04-17T16:43:37.185859Z"}
1618677817.174685: {"type":"l2update","product_id":"SKL-BTC","changes":[["sell","0.00001325","5.0"]],"time":"2021-04-17T16:43:37.185859Z"}
1618677817.1747048: {"type":"l2update","product_id":"SKL-BTC","changes":[["sell","0.00001321","5.0"]],"time":"2021-04-17T16:43:37.185859Z"}
1618677817.174725: {"type":"l2update","product_id":"SKL-BTC","changes":[["sell","0.00001317","5.0"]],"time":"2021-04-17T16:43:37.185859Z"}
1618677817.174745: {"type":"l2update","product_id":"SKL-BTC","changes":[["sell","0.00001311","2932.8"]],"time":"2021-04-17T16:43:37.185859Z"}
1618677817.1769722: {"type":"l2update","product_id":"SKL-BTC","changes":[["buy","0.00001303","7644.4"]],"time":"2021-04-17T16:43:37.189044Z"}
1618677817.1770182: {"type":"l2update","product_id":"SKL-BTC","changes":[["sell","0.00001309","3219.8"]],"time":"2021-04-17T16:43:37.190023Z"}
1618677817.177044: {"type":"l2update","product_id":"SKL-BTC","changes":[["sell","0.00001307","12672.0"]],"time":"2021-04-17T16:43:37.190023Z"}
1618677817.1770701: {"type":"l2update","product_id":"SKL-GBP","changes":[["buy","0.5735","0.0"]],"time":"2021-04-17T16:43:37.192053Z"}
1618677817.1911738: {"type":"l2update","product_id":"SKL-GBP","changes":[["buy","0.5720","0.0"]],"time":"2021-04-17T16:43:37.195022Z"}
1618677817.191314: {"type":"l2update","product_id":"SKL-USD","changes":[["buy","0.7862","7232.3"]],"time":"2021-04-17T16:43:37.196366Z"}
1618677817.191373: {"type":"l2update","product_id":"SKL-GBP","changes":[["buy","0.5736","8976.6"]],"time":"2021-04-17T16:43:37.196427Z"}
1618677817.1955452: {"type":"l2update","product_id":"SKL-BTC","changes":[["sell","0.00001354","1499.0"]],"time":"2021-04-17T16:43:37.200029Z"}
1618677817.195689: {"type":"l2update","product_id":"CRV-EUR","changes":[["buy","3.2970","0.00"]],"time":"2021-04-17T16:43:37.200251Z"}
1618677817.1957362: {"type":"l2update","product_id":"CRV-EUR","changes":[["buy","3.2952","0.00"]],"time":"2021-04-17T16:43:37.200260Z"}
1618677817.195767: {"type":"l2update","product_id":"SKL-USD","changes":[["buy","0.7889","2631.7"]],"time":"2021-04-17T16:43:37.203404Z"}
1618677817.1958022: {"type":"l2update","product_id":"CRV-EUR","changes":[["buy","3.2873","0.00"]],"time":"2021-04-17T16:43:37.200885Z"}
1618677817.195831: {"type":"l2update","product_id":"SKL-USD","changes":[["buy","0.7859","25513.9"]],"time":"2021-04-17T16:43:37.203668Z"}
1618677817.1958568: {"type":"l2update","product_id":"SKL-BTC","changes":[["sell","0.00001309","1771.7"]],"time":"2021-04-17T16:43:37.204327Z"}
1618677817.19588: {"type":"l2update","product_id":"SKL-GBP","changes":[["sell","0.5811","7800.4"]],"time":"2021-04-17T16:43:37.207304Z"}
1618677817.198671: {"type":"l2update","product_id":"NMR-EUR","changes":[["sell","67.0210","12.248"]],"time":"2021-04-17T16:43:37.207503Z"}
1618677817.198792: {"type":"match","trade_id":868599,"maker_order_id":"d177e4c4-64cb-4904-aca0-9aca4b1ec7c6","taker_order_id":"dc5fb742-69f7-49c9-ae8b-95d399398f7a","side":"sell","size":"0.148","price":"67.021","product_id":"NMR-EUR","sequence":471056965,"time":"2021-04-17T16:43:37.207503Z"}
1618677817.198859: {"type":"ticker","sequence":471056965,"product_id":"NMR-EUR","price":"67.021","open_24h":"60.9288","volume_24h":"25744.81500000","low_24h":"60.4695","high_24h":"74.5","volume_30d":"552585.10800000","best_bid":"66.9082","best_ask":"67.0210","side":"buy","time":"2021-04-17T16:43:37.207503Z","trade_id":868599,"last_size":"0.148"}
1618677817.1988878: {"type":"l2update","product_id":"SKL-GBP","changes":[["buy","0.5723","9620.6"]],"time":"2021-04-17T16:43:37.211297Z"}
1618677817.198931: {"type":"l2update","product_id":"SKL-USD","changes":[["sell","0.7946","5.0"]],"time":"2021-04-17T16:43:37.213698Z"}
1618677817.203829: {"type":"l2update","product_id":"SKL-BTC","changes":[["sell","0.00001309","1600.9"]],"time":"2021-04-17T16:43:37.216141Z"}
1618677817.203914: {"type":"l2update","product_id":"SKL-BTC","changes":[["sell","0.00001320","1942.6"]],"time":"2021-04-17T16:43:37.218337Z"}
1618677817.2135098: {"type":"l2update","product_id":"SKL-USD","changes":[["buy","0.7860","5.0"]],"time":"2021-04-17T16:43:37.220775Z"}
1618677817.213598: {"type":"l2update","product_id":"DASH-BTC","changes":[["buy","0.00618761","1.54300000"]],"time":"2021-04-17T16:43:37.221696Z"}
1618677817.213651: {"type":"l2update","product_id":"CRV-EUR","changes":[["buy","3.2964","140.93"]],"time":"2021-04-17T16:43:37.222018Z"}
1618677817.213707: {"type":"l2update","product_id":"SKL-USD","changes":[["sell","0.7919","0.0"]],"time":"2021-04-17T16:43:37.223095Z"}
1618677817.2137651: {"type":"l2update","product_id":"CRV-EUR","changes":[["buy","3.2935","140.93"]],"time":"2021-04-17T16:43:37.225547Z"}
1618677817.21381: {"type":"l2update","product_id":"SKL-USD","changes":[["buy","0.7884","1197.2"]],"time":"2021-04-17T16:43:37.227150Z"}
1618677817.213845: {"type":"l2update","product_id":"SKL-USD","changes":[["sell","0.7917","0.0"]],"time":"2021-04-17T16:43:37.230443Z"}
1618677817.22013: {"type":"l2update","product_id":"SKL-BTC","changes":[["sell","0.00001314","2073.6"]],"time":"2021-04-17T16:43:37.234123Z"}
1618677817.220219: {"type":"l2update","product_id":"SKL-BTC","changes":[["sell","0.00001312","1714.0"]],"time":"2021-04-17T16:43:37.234123Z"}
1618677817.2339919: {"type":"l2update","product_id":"SKL-BTC","changes":[["sell","0.00001354","0.0"]],"time":"2021-04-17T16:43:37.238703Z"}
1618677817.234046: {"type":"l2update","product_id":"SKL-BTC","changes":[["buy","0.00001302","1117.2"]],"time":"2021-04-17T16:43:37.241117Z"}
1618677817.234076: {"type":"l2update","product_id":"DASH-BTC","changes":[["buy","0.00618956","0.03000000"]],"time":"2021-04-17T16:43:37.242167Z"}
1618677817.234105: {"type":"l2update","product_id":"CRV-EUR","changes":[["buy","3.2857","140.93"]],"time":"2021-04-17T16:43:37.242188Z"}
1618677817.23413: {"type":"l2update","product_id":"DASH-BTC","changes":[["buy","0.00618761","0.00000000"]],"time":"2021-04-17T16:43:37.248176Z"}
1618677817.240582: {"type":"l2update","product_id":"SKL-BTC","changes":[["sell","0.00001307","11686.9"]],"time":"2021-04-17T16:43:37.252865Z"}
1618677817.254535: {"type":"l2update","product_id":"SKL-BTC","changes":[["sell","0.00001321","1575.2"]],"time":"2021-04-17T16:43:37.259417Z"}
1618677817.2545931: {"type":"l2update","product_id":"SKL-USD","changes":[["buy","0.7884","2066.5"]],"time":"2021-04-17T16:43:37.259443Z"}
1618677817.254626: {"type":"l2update","product_id":"SKL-BTC","changes":[["sell","0.00001314","4016.2"]],"time":"2021-04-17T16:43:37.259417Z"}
1618677817.254653: {"type":"l2update","product_id":"SKL-USD","changes":[["buy","0.7898","989.7"]],"time":"2021-04-17T16:43:37.263419Z"}
1618677817.254687: {"type":"l2update","product_id":"SKL-BTC","changes":[["sell","0.00001320","0.0"]],"time":"2021-04-17T16:43:37.263564Z"}
1618677817.254719: {"type":"l2update","product_id":"SKL-USD","changes":[["buy","0.7783","0.0"]],"time":"2021-04-17T16:43:37.264230Z"}
1618677817.254747: {"type":"l2update","product_id":"SKL-USD","changes":[["buy","0.7705","0.0"]],"time":"2021-04-17T16:43:37.264230Z"}
1618677817.254773: {"type":"l2update","product_id":"DASH-BTC","changes":[["buy","0.00618956","1.57200000"]],"time":"2021-04-17T16:43:37.270629Z"}
1618677817.261442: {"type":"l2update","product_id":"SKL-GBP","changes":[["sell","0.5762","0.0"]],"time":"2021-04-17T16:43:37.270697Z"}
1618677817.261507: {"type":"ticker","sequence":27883501,"product_id":"SKL-GBP","price":"0.5762","open_24h":"0.5102","volume_24h":"3480196.10000000","low_24h":"0.5","high_24h":"0.588","volume_30d":"76124009.10000000","best_bid":"0.5742","best_ask":"0.5771","side":"buy","time":"2021-04-17T16:43:37.270697Z","trade_id":82008,"last_size":"335"}
1618677817.2615418: {"type":"match","trade_id":82008,"maker_order_id":"f71dd5c4-b316-4869-83db-ff328a7379a6","taker_order_id":"d30ea30a-c805-4f05-ba7e-28020dfc52b3","side":"sell","size":"335","price":"0.5762","product_id":"SKL-GBP","sequence":27883501,"time":"2021-04-17T16:43:37.270697Z"}
1618677817.264043: {"type":"l2update","product_id":"SKL-BTC","changes":[["buy","0.00001302","2106.9"]],"time":"2021-04-17T16:43:37.274424Z"}
1618677817.264102: {"type":"l2update","product_id":"SKL-USD","changes":[["buy","0.7855","1025.0"]],"time":"2021-04-17T16:43:37.276819Z"}
1618677817.2641332: {"type":"l2update","product_id":"SKL-USD","changes":[["buy","0.7826","1800.0"]],"time":"2021-04-17T16:43:37.276819Z"}
1618677817.2641559: {"type":"l2update","product_id":"SKL-BTC","changes":[["sell","0.00001325","1933.5"]],"time":"2021-04-17T16:43:37.277785Z"}
1618677817.266183: {"type":"l2update","product_id":"BAND-GBP","changes":[["buy","14.7472","0.00"]],"time":"2021-04-17T16:43:37.281838Z"}
1618677817.266251: {"type":"l2update","product_id":"SKL-BTC","changes":[["buy","0.00001302","1099.7"]],"time":"2021-04-17T16:43:37.283499Z"}
1618677817.266284: {"type":"l2update","product_id":"SKL-GBP","changes":[["buy","0.5723","0.0"]],"time":"2021-04-17T16:43:37.284293Z"}
1618677817.272176: {"type":"l2update","product_id":"SKL-BTC","changes":[["sell","0.00001306","2261.6"]],"time":"2021-04-17T16:43:37.285033Z"}
1618677817.2722318: {"type":"l2update","product_id":"SKL-USD","changes":[["buy","0.7862","7257.3"]],"time":"2021-04-17T16:43:37.285345Z"}
1618677817.272266: {"type":"l2update","product_id":"SKL-USD","changes":[["buy","0.7898","1692.3"]],"time":"2021-04-17T16:43:37.285468Z"}
1618677817.2722921: {"type":"l2update","product_id":"BAND-GBP","changes":[["sell","14.8024","0.00"]],"time":"2021-04-17T16:43:37.287488Z"}
1618677817.272328: {"type":"l2update","product_id":"SKL-USD","changes":[["sell","0.7939","0.0"]],"time":"2021-04-17T16:43:37.288247Z"}
1618677817.282869: {"type":"l2update","product_id":"SKL-USD","changes":[["sell","0.8096","754.7"]],"time":"2021-04-17T16:43:37.291801Z"}
1618677817.282958: {"type":"l2update","product_id":"SKL-USD","changes":[["sell","0.8024","0.0"]],"time":"2021-04-17T16:43:37.291801Z"}
1618677817.283028: {"type":"l2update","product_id":"SKL-USD","changes":[["sell","0.7994","5.0"]],"time":"2021-04-17T16:43:37.291801Z"}
1618677817.283077: {"type":"l2update","product_id":"BAND-GBP","changes":[["sell","14.8143","0.00"]],"time":"2021-04-17T16:43:37.293056Z"}
1618677817.283127: {"type":"l2update","product_id":"SKL-GBP","changes":[["sell","0.5770","1008.2"]],"time":"2021-04-17T16:43:37.293041Z"}
1618677817.2831738: {"type":"l2update","product_id":"SKL-BTC","changes":[["buy","0.00001302","1519.7"]],"time":"2021-04-17T16:43:37.296403Z"}
1618677817.283211: {"type":"l2update","product_id":"SKL-USD","changes":[["buy","0.7910","450.0"]],"time":"2021-04-17T16:43:37.296491Z"}
1618677817.283252: {"type":"l2update","product_id":"SKL-USD","changes":[["buy","0.7909","539.7"]],"time":"2021-04-17T16:43:37.296491Z"}
1618677817.2832918: {"type":"l2update","product_id":"BAND-GBP","changes":[["sell","14.8067","27.80"]],"time":"2021-04-17T16:43:37.296575Z"}
1618677817.283355: {"type":"l2update","product_id":"SKL-BTC","changes":[["buy","0.00001301","1143.0"]],"time":"2021-04-17T16:43:37.296914Z"}
1618677817.283377: {"type":"l2update","product_id":"SKL-USD","changes":[["sell","0.8059","12005.0"]],"time":"2021-04-17T16:43:37.297827Z"}
1618677817.288929: {"type":"l2update","product_id":"SKL-BTC","changes":[["buy","0.00001304","110.0"]],"time":"2021-04-17T16:43:37.299884Z"}
1618677817.2890282: {"type":"l2update","product_id":"SKL-BTC","changes":[["sell","0.00001314","10861.8"]],"time":"2021-04-17T16:43:37.300177Z"}
1618677817.289081: {"type":"l2update","product_id":"SKL-BTC","changes":[["sell","0.00001325","3874.8"]],"time":"2021-04-17T16:43:37.303675Z"}
1618677817.289121: {"type":"l2update","product_id":"SKL-BTC","changes":[["sell","0.00001311","4875.4"]],"time":"2021-04-17T16:43:37.303675Z"}
1618677817.2891572: {"type":"l2update","product_id":"BAND-GBP","changes":[["buy","14.7320","49.42"]],"time":"2021-04-17T16:43:37.304585Z"}
1618677817.2921548: {"type":"l2update","product_id":"SKL-BTC","changes":[["buy","0.00001304","1099.7"]],"time":"2021-04-17T16:43:37.304628Z"}
1618677817.292244: {"type":"l2update","product_id":"SKL-BTC","changes":[["sell","0.00001314","8919.2"]],"time":"2021-04-17T16:43:37.307967Z"}
1618677817.292296: {"type":"l2update","product_id":"SKL-GBP","changes":[["buy","0.5737","8969.9"]],"time":"2021-04-17T16:43:37.307943Z"}
1618677817.2923489: {"type":"l2update","product_id":"SKL-USD","changes":[["sell","0.7946","29765.1"]],"time":"2021-04-17T16:43:37.307982Z"}
1618677817.305463: {"type":"l2update","product_id":"SKL-BTC","changes":[["sell","0.00001306","1601.1"]],"time":"2021-04-17T16:43:37.308069Z"}
1618677817.3055518: {"type":"ticker","sequence":177100140,"product_id":"SKL-BTC","price":"0.00001306","open_24h":"0.00001144","volume_24h":"7368374.90000000","low_24h":"0.00001122","high_24h":"0.00001337","volume_30d":"137081957.00000000","best_bid":"0.00001304","best_ask":"0.00001306","side":"buy","time":"2021-04-17T16:43:37.308069Z","trade_id":280233,"last_size":"660.5"}
1618677817.305606: {"type":"match","trade_id":280233,"maker_order_id":"b084fd3f-4b3a-4c6b-be52-ea1467d6bcae","taker_order_id":"ed06e5e6-f849-485e-9089-f78c02937aee","side":"sell","size":"660.5","price":"0.00001306","product_id":"SKL-BTC","sequence":177100140,"time":"2021-04-17T16:43:37.308069Z"}
1618677817.3056588: {"type":"l2update","product_id":"SKL-BTC","changes":[["sell","0.00001306","706.4"]],"time":"2021-04-17T16:43:37.308069Z"}
1618677817.305706: {"type":"match","trade_id":280234,"maker_order_id":"152d2d4e-d21d-46a3-b2ae-a85622292197","taker_order_id":"ed06e5e6-f849-485e-9089-f78c02937aee","side":"sell","size":"894.7","price":"0.00001306","product_id":"SKL-BTC","sequence":177100142,"time":"2021-04-17T16:43:37.308069Z"}
1618677817.305748: {"type":"ticker","sequence":177100142,"product_id":"SKL-BTC","price":"0.00001306","open_24h":"0.00001144","volume_24h":"7369269.60000000","low_24h":"0.00001122","high_24h":"0.00001337","volume_30d":"137082851.70000000","best_bid":"0.00001304","best_ask":"0.00001306","side":"buy","time":"2021-04-17T16:43:37.308069Z","trade_id":280234,"last_size":"894.7"}
1618677817.3057878: {"type":"l2update","product_id":"SKL-BTC","changes":[["sell","0.00001306","0.6"]],"time":"2021-04-17T16:43:37.308069Z"}
1618677817.305814: {"type":"match","trade_id":280235,"maker_order_id":"8137619a-9fef-485d-b2ec-7163132cd480","taker_order_id":"ed06e5e6-f849-485e-9089-f78c02937aee","side":"sell","size":"705.8","price":"0.00001306","product_id":"SKL-BTC","sequence":177100144,"time":"2021-04-17T16:43:37.308069Z"}
1618677817.305834: {"type":"ticker","sequence":177100144,"product_id":"SKL-BTC","price":"0.00001306","open_24h":"0.00001144","volume_24h":"7369975.40000000","low_24h":"0.00001122","high_24h":"0.00001337","volume_30d":"137083557.50000000","best_bid":"0.00001304","best_ask":"0.00001306","side":"buy","time":"2021-04-17T16:43:37.308069Z","trade_id":280235,"last_size":"705.8"}
1618677817.3058538: {"type":"l2update","product_id":"SKL-USD","changes":[["buy","0.7859","0.0"]],"time":"2021-04-17T16:43:37.313742Z"}
1618677817.30589: {"type":"l2update","product_id":"SKL-GBP","changes":[["sell","0.5770","0.0"]],"time":"2021-04-17T16:43:37.314076Z"}
1618677817.30592: {"type":"l2update","product_id":"SKL-BTC","changes":[["buy","0.00001303","8651.6"]],"time":"2021-04-17T16:43:37.314484Z"}
1618677817.305944: {"type":"l2update","product_id":"SKL-USD","changes":[["sell","0.7916","23012.0"]],"time":"2021-04-17T16:43:37.314473Z"}
1618677817.305967: {"type":"match","trade_id":1568270,"maker_order_id":"0fd64770-e14e-4114-9e6d-f397f26f22f5","taker_order_id":"6dbf680c-7bf3-478d-8841-350d20ea8ae5","side":"sell","size":"2631.4","price":"0.7916","product_id":"SKL-USD","sequence":201390173,"time":"2021-04-17T16:43:37.314473Z"}
1618677817.305988: {"type":"ticker","sequence":201390173,"product_id":"SKL-USD","price":"0.7916","open_24h":"0.7055","volume_24h":"34224896.90000000","low_24h":"0.6915","high_24h":"0.8098","volume_30d":"948652249.60000000","best_bid":"0.7910","best_ask":"0.7916","side":"buy","time":"2021-04-17T16:43:37.314473Z","trade_id":1568270,"last_size":"2631.4"}
1618677817.306008: {"type":"l2update","product_id":"SKL-USD","changes":[["sell","0.7916","0.4"]],"time":"2021-04-17T16:43:37.314473Z"}
1618677817.30603: {"type":"match","trade_id":1568271,"maker_order_id":"c81761dd-24b3-4479-a6c7-dded79e98665","taker_order_id":"6dbf680c-7bf3-478d-8841-350d20ea8ae5","side":"sell","size":"23011.6","price":"0.7916","product_id":"SKL-USD","sequence":201390175,"time":"2021-04-17T16:43:37.314473Z"}
1618677817.306049: {"type":"ticker","sequence":201390175,"product_id":"SKL-USD","price":"0.7916","open_24h":"0.7055","volume_24h":"34247908.50000000","low_24h":"0.6915","high_24h":"0.8098","volume_30d":"948675261.20000000","best_bid":"0.7910","best_ask":"0.7916","side":"buy","time":"2021-04-17T16:43:37.314473Z","trade_id":1568271,"last_size":"23011.6"}
1618677817.32461: {"type":"l2update","product_id":"SKL-BTC","changes":[["sell","0.00001308","1900.0"]],"time":"2021-04-17T16:43:37.318299Z"}
1618677817.3247292: {"type":"l2update","product_id":"SKL-USD","changes":[["sell","0.7916","0.0"]],"time":"2021-04-17T16:43:37.320230Z"}
1618677817.324817: {"type":"l2update","product_id":"SKL-BTC","changes":[["sell","0.00001331","1972.3"]],"time":"2021-04-17T16:43:37.321628Z"}
1618677817.3248682: {"type":"l2update","product_id":"NMR-EUR","changes":[["buy","66.3780","12.693"]],"time":"2021-04-17T16:43:37.321782Z"}
1618677817.324905: {"type":"l2update","product_id":"SKL-USD","changes":[["sell","0.7933","5.0"]],"time":"2021-04-17T16:43:37.322072Z"}
1618677817.32493: {"type":"l2update","product_id":"SKL-USD","changes":[["sell","0.8198","5630.8"]],"time":"2021-04-17T16:43:37.325182Z"}
1618677817.3249521: {"type":"l2update","product_id":"SKL-BTC","changes":[["sell","0.00001314","7340.6"]],"time":"2021-04-17T16:43:37.325427Z"}
1618677817.324973: {"type":"l2update","product_id":"SKL-BTC","changes":[["sell","0.00001307","4032.1"]],"time":"2021-04-17T16:43:37.326106Z"}
1618677817.324994: {"type":"l2update","product_id":"SKL-USD","changes":[["buy","0.7891","1340.9"]],"time":"2021-04-17T16:43:37.328720Z"}
1618677817.325022: {"type":"l2update","product_id":"SKL-GBP","changes":[["sell","0.5780","0.0"]],"time":"2021-04-17T16:43:37.329766Z"}
1618677817.325052: {"type":"l2update","product_id":"DASH-BTC","changes":[["buy","0.00614331","36.84500000"]],"time":"2021-04-17T16:43:37.330358Z"}
1618677817.3250759: {"type":"l2update","product_id":"DASH-BTC","changes":[["buy","0.00614332","0.00000000"]],"time":"2021-04-17T16:43:37.330358Z"}
1618677817.325103: {"type":"l2update","product_id":"SKL-USD","changes":[["buy","0.7863","26839.5"]],"time":"2021-04-17T16:43:37.332581Z"}
1618677817.3251252: {"type":"l2update","product_id":"DASH-BTC","changes":[["buy","0.00450007","5.13000000"]],"time":"2021-04-17T16:43:37.336039Z"}
1618677817.3251462: {"type":"l2update","product_id":"DASH-BTC","changes":[["buy","0.00450008","0.71000000"]],"time":"2021-04-17T16:43:37.336039Z"}
1618677817.3351371: {"type":"l2update","product_id":"DASH-BTC","changes":[["buy","0.00451008","4.82000000"]],"time":"2021-04-17T16:43:37.336039Z"}
1618677817.3352551: {"type":"l2update","product_id":"SKL-BTC","changes":[["buy","0.00001284","0.0"]],"time":"2021-04-17T16:43:37.339986Z"}
1618677817.33533: {"type":"l2update","product_id":"SKL-USD","changes":[["sell","0.7920","6908.0"]],"time":"2021-04-17T16:43:37.347293Z"}
1618677817.3426602: {"type":"l2update","product_id":"SKL-BTC","changes":[["sell","0.00001332","1645.3"]],"time":"2021-04-17T16:43:37.352007Z"}
1618677817.342776: {"type":"l2update","product_id":"SKL-BTC","changes":[["sell","0.00001318","1941.3"]],"time":"2021-04-17T16:43:37.352007Z"}
1618677817.342849: {"type":"l2update","product_id":"SKL-BTC","changes":[["sell","0.00001315","26900.1"]],"time":"2021-04-17T16:43:37.352007Z"}
1618677817.342892: {"type":"l2update","product_id":"SKL-BTC","changes":[["buy","0.00001261","1414.8"]],"time":"2021-04-17T16:43:37.352007Z"}
1618677817.342931: {"type":"l2update","product_id":"SKL-BTC","changes":[["buy","0.00001274","10804.7"]],"time":"2021-04-17T16:43:37.352007Z"}
1618677817.342967: {"type":"l2update","product_id":"SKL-BTC","changes":[["buy","0.00001282","2897.9"]],"time":"2021-04-17T16:43:37.352007Z"}
1618677817.343034: {"type":"l2update","product_id":"SKL-BTC","changes":[["buy","0.00001287","1849.5"]],"time":"2021-04-17T16:43:37.352007Z"}
1618677817.343062: {"type":"l2update","product_id":"SKL-BTC","changes":[["buy","0.00001290","13813.1"]],"time":"2021-04-17T16:43:37.352007Z"}
1618677817.343084: {"type":"l2update","product_id":"SKL-BTC","changes":[["buy","0.00001293","1382.2"]],"time":"2021-04-17T16:43:37.352007Z"}
1618677817.343105: {"type":"l2update","product_id":"SKL-BTC","changes":[["buy","0.00001294","28345.2"]],"time":"2021-04-17T16:43:37.352007Z"}
1618677817.348862: {"type":"l2update","product_id":"SKL-BTC","changes":[["sell","0.00001325","1933.5"]],"time":"2021-04-17T16:43:37.357870Z"}
1618677817.3489249: {"type":"l2update","product_id":"SKL-BTC","changes":[["sell","0.00001321","5.0"]],"time":"2021-04-17T16:43:37.357870Z"}
1618677817.348959: {"type":"l2update","product_id":"SKL-BTC","changes":[["sell","0.00001307","2642.1"]],"time":"2021-04-17T16:43:37.357870Z"}
1618677817.3489861: {"type":"l2update","product_id":"SKL-BTC","changes":[["sell","0.00001306","0.0"]],"time":"2021-04-17T16:43:37.357870Z"}
1618677817.349025: {"type":"l2update","product_id":"SKL-BTC","changes":[["buy","0.00001259","1683.9"]],"time":"2021-04-17T16:43:37.357870Z"}
1618677817.349049: {"type":"l2update","product_id":"SKL-BTC","changes":[["buy","0.00001273","204.1"]],"time":"2021-04-17T16:43:37.357870Z"}
1618677817.349071: {"type":"l2update","product_id":"SKL-BTC","changes":[["buy","0.00001278","0.0"]],"time":"2021-04-17T16:43:37.357870Z"}
1618677817.349098: {"type":"l2update","product_id":"SKL-BTC","changes":[["buy","0.00001282","1464.3"]],"time":"2021-04-17T16:43:37.357870Z"}
1618677817.349121: {"type":"l2update","product_id":"SKL-BTC","changes":[["buy","0.00001285","21375.5"]],"time":"2021-04-17T16:43:37.357870Z"}
1618677817.349142: {"type":"l2update","product_id":"SKL-BTC","changes":[["buy","0.00001288","0.0"]],"time":"2021-04-17T16:43:37.357870Z"}
1618677817.354292: {"type":"l2update","product_id":"SKL-BTC","changes":[["sell","0.00001311","5983.7"]],"time":"2021-04-17T16:43:37.365266Z"}
1618677817.3543801: {"type":"l2update","product_id":"SKL-BTC","changes":[["sell","0.00001340","10574.4"]],"time":"2021-04-17T16:43:37.367605Z"}
1618677817.354431: {"type":"l2update","product_id":"SKL-BTC","changes":[["sell","0.00001308","0.0"]],"time":"2021-04-17T16:43:37.367984Z"}
1618677817.3544939: {"type":"l2update","product_id":"SKL-BTC","changes":[["buy","0.00001298","4913.0"]],"time":"2021-04-17T16:43:37.369577Z"}
1618677817.3545349: {"type":"l2update","product_id":"SKL-USD","changes":[["buy","0.7796","20220.9"]],"time":"2021-04-17T16:43:37.371260Z"}
1618677817.369291: {"type":"l2update","product_id":"SKL-BTC","changes":[["sell","0.00001325","5.0"]],"time":"2021-04-17T16:43:37.372022Z"}
1618677817.369379: {"type":"l2update","product_id":"SKL-BTC","changes":[["buy","0.00001269","10.9"]],"time":"2021-04-17T16:43:37.372022Z"}
1618677817.369431: {"type":"l2update","product_id":"SKL-USD","changes":[["sell","0.8208","142.7"]],"time":"2021-04-17T16:43:37.375394Z"}
1618677817.369474: {"type":"l2update","product_id":"SKL-USD","changes":[["sell","0.8198","2723.4"]],"time":"2021-04-17T16:43:37.375394Z"}
1618677817.36951: {"type":"l2update","product_id":"SKL-USD","changes":[["sell","0.8184","0.0"]],"time":"2021-04-17T16:43:37.375394Z"}
1618677817.369565: {"type":"l2update","product_id":"SKL-USD","changes":[["sell","0.8149","3430.1"]],"time":"2021-04-17T16:43:37.375394Z"}
1618677817.3696: {"type":"l2update","product_id":"SKL-USD","changes":[["sell","0.8127","13813.2"]],"time":"2021-04-17T16:43:37.375394Z"}
1618677817.369632: {"type":"l2update","product_id":"SKL-USD","changes":[["sell","0.8067","0.0"]],"time":"2021-04-17T16:43:37.375394Z"}
1618677817.369674: {"type":"l2update","product_id":"SKL-USD","changes":[["sell","0.8040","0.0"]],"time":"2021-04-17T16:43:37.375394Z"}
1618677817.3697321: {"type":"l2update","product_id":"SKL-USD","changes":[["sell","0.7980","5.0"]],"time":"2021-04-17T16:43:37.375394Z"}
1618677817.369754: {"type":"l2update","product_id":"SKL-USD","changes":[["sell","0.7956","5.0"]],"time":"2021-04-17T16:43:37.375394Z"}
1618677817.369774: {"type":"l2update","product_id":"SKL-USD","changes":[["sell","0.7921","0.0"]],"time":"2021-04-17T16:43:37.375394Z"}
1618677817.369799: {"type":"l2update","product_id":"SKL-BTC","changes":[["sell","0.00001310","7356.8"]],"time":"2021-04-17T16:43:37.379073Z"}
1618677817.369828: {"type":"l2update","product_id":"SKL-USD","changes":[["buy","0.7747","0.0"]],"time":"2021-04-17T16:43:37.379781Z"}
1618677817.370123: {"type":"l2update","product_id":"YFI-BTC","changes":[["buy","0.82613","0.000000"]],"time":"2021-04-17T16:43:37.382441Z"}
1618677817.370174: {"type":"l2update","product_id":"SKL-BTC","changes":[["buy","0.00001299","1586.2"]],"time":"2021-04-17T16:43:37.384731Z"}
1618677817.370202: {"type":"l2update","product_id":"YFI-BTC","changes":[["sell","0.82732","0.020369"]],"time":"2021-04-17T16:43:37.386708Z"}
1618677817.373405: {"type":"l2update","product_id":"SKL-BTC","changes":[["sell","0.00001345","1438.4"]],"time":"2021-04-17T16:43:37.387165Z"}
1618677817.378718: {"type":"l2update","product_id":"SKL-BTC","changes":[["buy","0.00001300","7503.5"]],"time":"2021-04-17T16:43:37.392301Z"}
1618677817.378806: {"type":"l2update","product_id":"SKL-BTC","changes":[["buy","0.00001274","9386.0"]],"time":"2021-04-17T16:43:37.392359Z"}
1618677817.378857: {"type":"l2update","product_id":"SKL-BTC","changes":[["buy","0.00001282","21.9"]],"time":"2021-04-17T16:43:37.392359Z"}
1618677817.378898: {"type":"l2update","product_id":"SKL-USD","changes":[["sell","0.7948","5.0"]],"time":"2021-04-17T16:43:37.393939Z"}
1618677817.384087: {"type":"l2update","product_id":"SKL-BTC","changes":[["buy","0.00001296","1319.9"]],"time":"2021-04-17T16:43:37.395413Z"}
1618677817.384177: {"type":"l2update","product_id":"SKL-BTC","changes":[["buy","0.00001297","10.0"]],"time":"2021-04-17T16:43:37.395413Z"}
1618677817.38423: {"type":"l2update","product_id":"SKL-GBP","changes":[["buy","0.5690","1735.0"]],"time":"2021-04-17T16:43:37.395712Z"}
1618677817.3842711: {"type":"l2update","product_id":"SKL-GBP","changes":[["buy","0.5690","0.0"]],"time":"2021-04-17T16:43:37.395712Z"}
1618677817.384327: {"type":"l2update","product_id":"SKL-USD","changes":[["sell","0.7945","1905.0"]],"time":"2021-04-17T16:43:37.399124Z"}
1618677817.38642: {"type":"l2update","product_id":"YFI-BTC","changes":[["buy","0.82580","0.000000"]],"time":"2021-04-17T16:43:37.400929Z"}
1618677817.392689: {"type":"l2update","product_id":"SKL-USD","changes":[["buy","0.7909","1529.4"]],"time":"2021-04-17T16:43:37.402617Z"}
1618677817.392779: {"type":"l2update","product_id":"SKL-GBP","changes":[["sell","0.5771","0.0"]],"time":"2021-04-17T16:43:37.405219Z"}
1618677817.392849: {"type":"l2update","product_id":"YFI-BTC","changes":[["sell","0.82737","0.016900"]],"time":"2021-04-17T16:43:37.405958Z"}
1618677817.409454: {"type":"l2update","product_id":"SKL-USD","changes":[["buy","0.7903","880.0"]],"time":"2021-04-17T16:43:37.409788Z"}
1618677817.409544: {"type":"l2update","product_id":"SKL-GBP","changes":[["buy","0.5723","5788.0"]],"time":"2021-04-17T16:43:37.409981Z"}
1618677817.409608: {"type":"l2update","product_id":"SKL-BTC","changes":[["buy","0.00001298","13903.0"]],"time":"2021-04-17T16:43:37.410172Z"}
1618677817.409649: {"type":"l2update","product_id":"SKL-BTC","changes":[["buy","0.00001299","4248.2"]],"time":"2021-04-17T16:43:37.410172Z"}
1618677817.409684: {"type":"l2update","product_id":"SKL-USD","changes":[["sell","0.7946","5.0"]],"time":"2021-04-17T16:43:37.411357Z"}
1618677817.409717: {"type":"l2update","product_id":"SKL-USD","changes":[["sell","0.7954","2850.4"]],"time":"2021-04-17T16:43:37.413331Z"}
1618677817.409749: {"type":"l2update","product_id":"DASH-BTC","changes":[["buy","0.00618954","0.00000000"]],"time":"2021-04-17T16:43:37.413437Z"}
1618677817.409798: {"type":"l2update","product_id":"SKL-USD","changes":[["sell","0.7941","3804.4"]],"time":"2021-04-17T16:43:37.413331Z"}
1618677817.409832: {"type":"l2update","product_id":"SKL-GBP","changes":[["buy","0.5723","7523.0"]],"time":"2021-04-17T16:43:37.413743Z"}
1618677817.409864: {"type":"l2update","product_id":"SKL-USD","changes":[["sell","0.7938","1303.8"]],"time":"2021-04-17T16:43:37.413331Z"}
1618677817.409895: {"type":"l2update","product_id":"SKL-USD","changes":[["sell","0.7928","23012.0"]],"time":"2021-04-17T16:43:37.413943Z"}
1618677817.409945: {"type":"l2update","product_id":"SKL-GBP","changes":[["sell","0.5780","350.0"]],"time":"2021-04-17T16:43:37.414234Z"}
1618677817.409984: {"type":"l2update","product_id":"SKL-GBP","changes":[["buy","0.5743","145.0"]],"time":"2021-04-17T16:43:37.414234Z"}
1618677817.410021: {"type":"l2update","product_id":"SKL-GBP","changes":[["buy","0.5722","540.0"]],"time":"2021-04-17T16:43:37.414234Z"}
1618677817.410054: {"type":"l2update","product_id":"SKL-GBP","changes":[["buy","0.5723","7533.0"]],"time":"2021-04-17T16:43:37.414234Z"}
1618677817.4100852: {"type":"l2update","product_id":"SKL-USD","changes":[["buy","0.7891","0.0"]],"time":"2021-04-17T16:43:37.416814Z"}
1618677817.4101272: {"type":"l2update","product_id":"SKL-BTC","changes":[["buy","0.00001303","7644.4"]],"time":"2021-04-17T16:43:37.417401Z"}
1618677817.4101608: {"type":"l2update","product_id":"SKL-BTC","changes":[["sell","0.00001334","37819.6"]],"time":"2021-04-17T16:43:37.417432Z"}
1618677817.410194: {"type":"l2update","product_id":"SKL-BTC","changes":[["sell","0.00001327","1388.2"]],"time":"2021-04-17T16:43:37.417432Z"}
1618677817.410225: {"type":"l2update","product_id":"SKL-BTC","changes":[["sell","0.00001323","1604.7"]],"time":"2021-04-17T16:43:37.417432Z"}
1618677817.410256: {"type":"l2update","product_id":"SKL-BTC","changes":[["sell","0.00001319","1856.3"]],"time":"2021-04-17T16:43:37.417432Z"}
1618677817.4102871: {"type":"l2update","product_id":"SKL-BTC","changes":[["buy","0.00001261","2967.8"]],"time":"2021-04-17T16:43:37.417432Z"}
1618677817.4103181: {"type":"l2update","product_id":"SKL-BTC","changes":[["buy","0.00001274","10779.6"]],"time":"2021-04-17T16:43:37.417432Z"}
1618677817.4103491: {"type":"l2update","product_id":"SKL-USD","changes":[["sell","0.8198","0.0"]],"time":"2021-04-17T16:43:37.418643Z"}
1618677817.410388: {"type":"l2update","product_id":"SKL-USD","changes":[["sell","0.7962","5.0"]],"time":"2021-04-17T16:43:37.418643Z"}
1618677817.4104471: {"type":"l2update","product_id":"YFI-BTC","changes":[["buy","0.82518","0.000000"]],"time":"2021-04-17T16:43:37.420176Z"}
1618677817.410474: {"type":"l2update","product_id":"SKL-BTC","changes":[["sell","0.00001307","0.0"]],"time":"2021-04-17T16:43:37.420715Z"}
1618677817.4105: {"type":"l2update","product_id":"SKL-GBP","changes":[["sell","0.5780","1358.2"]],"time":"2021-04-17T16:43:37.420928Z"}
1618677817.410521: {"type":"l2update","product_id":"SKL-BTC","changes":[["sell","0.00001340","9191.2"]],"time":"2021-04-17T16:43:37.423616Z"}
1618677817.410541: {"type":"l2update","product_id":"SKL-BTC","changes":[["sell","0.00001332","45.6"]],"time":"2021-04-17T16:43:37.423616Z"}
1618677817.410561: {"type":"l2update","product_id":"SKL-BTC","changes":[["sell","0.00001331","200.0"]],"time":"2021-04-17T16:43:37.423616Z"}
1618677817.4105809: {"type":"l2update","product_id":"SKL-BTC","changes":[["buy","0.00001261","1574.2"]],"time":"2021-04-17T16:43:37.423616Z"}
1618677817.413805: {"type":"l2update","product_id":"YFI-BTC","changes":[["buy","0.81870","0.010429"]],"time":"2021-04-17T16:43:37.425114Z"}
1618677817.413907: {"type":"l2update","product_id":"SKL-GBP","changes":[["buy","0.5742","2528.9"]],"time":"2021-04-17T16:43:37.425807Z"}
1618677817.417325: {"type":"l2update","product_id":"SKL-BTC","changes":[["sell","0.00001311","4875.4"]],"time":"2021-04-17T16:43:37.429261Z"}
1618677817.417415: {"type":"l2update","product_id":"YFI-BTC","changes":[["buy","0.82547","0.000000"]],"time":"2021-04-17T16:43:37.430514Z"}
1618677817.417496: {"type":"l2update","product_id":"YFI-BTC","changes":[["sell","0.82711","0.019505"]],"time":"2021-04-17T16:43:37.431605Z"}
1618677817.417553: {"type":"l2update","product_id":"SKL-USD","changes":[["buy","0.7877","3451.6"]],"time":"2021-04-17T16:43:37.431690Z"}
1618677817.417602: {"type":"l2update","product_id":"SKL-USD","changes":[["buy","0.7798","59176.6"]],"time":"2021-04-17T16:43:37.431690Z"}
1618677817.417644: {"type":"l2update","product_id":"SKL-USD","changes":[["buy","0.7705","75015.6"]],"time":"2021-04-17T16:43:37.431690Z"}
1618677817.417683: {"type":"l2update","product_id":"SKL-USD","changes":[["sell","0.7928","26530.3"]],"time":"2021-04-17T16:43:37.431690Z"}
1618677817.417717: {"type":"l2update","product_id":"SKL-USD","changes":[["sell","0.8008","20979.7"]],"time":"2021-04-17T16:43:37.431690Z"}
1618677817.4177501: {"type":"l2update","product_id":"SKL-USD","changes":[["sell","0.8089","39033.1"]],"time":"2021-04-17T16:43:37.431690Z"}
1618677817.417791: {"type":"l2update","product_id":"SKL-USD","changes":[["sell","0.7927","29760.1"]],"time":"2021-04-17T16:43:37.433821Z"}
1618677817.418124: {"type":"l2update","product_id":"SKL-GBP","changes":[["buy","0.5744","1029.1"]],"time":"2021-04-17T16:43:37.433971Z"}
1618677817.418175: {"type":"l2update","product_id":"SKL-BTC","changes":[["buy","0.00001301","8171.2"]],"time":"2021-04-17T16:43:37.433896Z"}
1618677817.4182022: {"type":"l2update","product_id":"SKL-BTC","changes":[["sell","0.00001308","1109.1"]],"time":"2021-04-17T16:43:37.433988Z"}
1618677817.418232: {"type":"l2update","product_id":"DASH-BTC","changes":[["buy","0.00618956","2.69200000"]],"time":"2021-04-17T16:43:37.434001Z"}
1618677817.4182558: {"type":"l2update","product_id":"SKL-BTC","changes":[["sell","0.00001353","1259.1"]],"time":"2021-04-17T16:43:37.434258Z"}
1618677817.418282: {"type":"l2update","product_id":"SKL-BTC","changes":[["buy","0.00001261","3041.7"]],"time":"2021-04-17T16:43:37.434258Z"}
1618677817.419185: {"type":"l2update","product_id":"SKL-USD","changes":[["sell","0.7978","2790.8"]],"time":"2021-04-17T16:43:37.434509Z"}
1618677817.4259999: {"type":"l2update","product_id":"YFI-BTC","changes":[["buy","0.82525","0.000000"]],"time":"2021-04-17T16:43:37.438561Z"}
1618677817.4316108: {"type":"l2update","product_id":"SKL-USD","changes":[["buy","0.7896","1345.1"]],"time":"2021-04-17T16:43:37.441218Z"}
1618677817.4317482: {"type":"l2update","product_id":"SKL-BTC","changes":[["sell","0.00001310","8465.1"]],"time":"2021-04-17T16:43:37.441422Z"}
1618677817.431805: {"type":"l2update","product_id":"SKL-BTC","changes":[["buy","0.00001304","2107.1"]],"time":"2021-04-17T16:43:37.441515Z"}
1618677817.431846: {"type":"l2update","product_id":"SKL-GBP","changes":[["buy","0.5742","0.0"]],"time":"2021-04-17T16:43:37.442757Z"}
1618677817.4318998: {"type":"l2update","product_id":"SKL-BTC","changes":[["buy","0.00001301","7508.2"]],"time":"2021-04-17T16:43:37.443086Z"}
1618677817.431936: {"type":"l2update","product_id":"YFI-BTC","changes":[["buy","0.82584","0.000000"]],"time":"2021-04-17T16:43:37.444196Z"}
1618677817.4320068: {"type":"l2update","product_id":"YFI-BTC","changes":[["sell","0.82731","0.030000"]],"time":"2021-04-17T16:43:37.444913Z"}
1618677817.432041: {"type":"l2update","product_id":"SKL-BTC","changes":[["buy","0.00001299","3329.3"]],"time":"2021-04-17T16:43:37.448106Z"}
1618677817.441519: {"type":"l2update","product_id":"SKL-USD","changes":[["sell","0.8095","6005.0"]],"time":"2021-04-17T16:43:37.448713Z"}
1618677817.441637: {"type":"l2update","product_id":"YFI-BTC","changes":[["buy","0.82450","0.030063"]],"time":"2021-04-17T16:43:37.448939Z"}
1618677817.441707: {"type":"l2update","product_id":"SKL-USD","changes":[["sell","0.8059","6005.0"]],"time":"2021-04-17T16:43:37.452070Z"}
1618677817.441748: {"type":"l2update","product_id":"YFI-BTC","changes":[["buy","0.82585","0.000000"]],"time":"2021-04-17T16:43:37.455148Z"}
1618677817.4417999: {"type":"l2update","product_id":"YFI-BTC","changes":[["sell","0.82710","0.029500"]],"time":"2021-04-17T16:43:37.456446Z"}
1618677817.441874: {"type":"l2update","product_id":"SKL-BTC","changes":[["sell","0.00001343","1531.8"]],"time":"2021-04-17T16:43:37.456502Z"}
1618677817.441903: {"type":"l2update","product_id":"SKL-BTC","changes":[["buy","0.00001261","4435.3"]],"time":"2021-04-17T16:43:37.456502Z"}
1618677817.441926: {"type":"l2update","product_id":"SKL-BTC","changes":[["buy","0.00001274","12332.6"]],"time":"2021-04-17T16:43:37.456502Z"}
1618677817.453154: {"type":"l2update","product_id":"SKL-USD","changes":[["sell","0.7963","3492.6"]],"time":"2021-04-17T16:43:37.459962Z"}
1618677817.4532428: {"type":"l2update","product_id":"SKL-USD","changes":[["sell","0.8095","12005.0"]],"time":"2021-04-17T16:43:37.460098Z"}
1618677817.4532769: {"type":"l2update","product_id":"YFI-BTC","changes":[["buy","0.82529","0.020605"]],"time":"2021-04-17T16:43:37.460174Z"}
1618677817.453305: {"type":"l2update","product_id":"YFI-BTC","changes":[["sell","0.82686","0.020705"]],"time":"2021-04-17T16:43:37.460419Z"}
1618677817.453343: {"type":"l2update","product_id":"SKL-BTC","changes":[["buy","0.00001261","2882.3"]],"time":"2021-04-17T16:43:37.460965Z"}
1618677817.453367: {"type":"l2update","product_id":"SKL-BTC","changes":[["buy","0.00001303","8306.4"]],"time":"2021-04-17T16:43:37.463593Z"}
1618677817.4533892: {"type":"l2update","product_id":"YFI-BTC","changes":[["sell","0.82913","0.000000"]],"time":"2021-04-17T16:43:37.464867Z"}
1618677817.453421: {"type":"l2update","product_id":"YFI-BTC","changes":[["buy","0.82260","0.000000"]],"time":"2021-04-17T16:43:37.464867Z"}
1618677817.45345: {"type":"l2update","product_id":"SKL-USD","changes":[["sell","0.8059","5.0"]],"time":"2021-04-17T16:43:37.464899Z"}
1618677817.453472: {"type":"l2update","product_id":"YFI-BTC","changes":[["buy","0.82436","0.000000"]],"time":"2021-04-17T16:43:37.464867Z"}
1618677817.4534972: {"type":"l2update","product_id":"YFI-BTC","changes":[["buy","0.82468","0.000000"]],"time":"2021-04-17T16:43:37.464867Z"}
1618677817.453522: {"type":"l2update","product_id":"YFI-BTC","changes":[["sell","0.82775","0.000000"]],"time":"2021-04-17T16:43:37.465574Z"}
1618677817.459389: {"type":"l2update","product_id":"SKL-USD","changes":[["buy","0.7896","0.0"]],"time":"2021-04-17T16:43:37.469277Z"}
1618677817.459548: {"type":"l2update","product_id":"YFI-BTC","changes":[["sell","0.82739","0.000000"]],"time":"2021-04-17T16:43:37.471237Z"}
1618677817.459594: {"type":"l2update","product_id":"YFI-BTC","changes":[["buy","0.82416","0.000000"]],"time":"2021-04-17T16:43:37.474035Z"}
1618677817.459628: {"type":"l2update","product_id":"YFI-BTC","changes":[["buy","0.82542","0.018700"]],"time":"2021-04-17T16:43:37.474764Z"}
1618677817.459656: {"type":"l2update","product_id":"SKL-USD","changes":[["sell","0.8095","18005.0"]],"time":"2021-04-17T16:43:37.474806Z"}
1618677817.462257: {"type":"l2update","product_id":"YFI-BTC","changes":[["sell","0.82757","0.000000"]],"time":"2021-04-17T16:43:37.476129Z"}
1618677817.462322: {"type":"l2update","product_id":"SKL-BTC","changes":[["buy","0.00001302","2436.5"]],"time":"2021-04-17T16:43:37.474965Z"}
1618677817.471064: {"type":"l2update","product_id":"SKL-BTC","changes":[["sell","0.00001311","6775.4"]],"time":"2021-04-17T16:43:37.477272Z"}
1618677817.471165: {"type":"l2update","product_id":"YFI-BTC","changes":[["sell","0.82685","0.030000"]],"time":"2021-04-17T16:43:37.479052Z"}
1618677817.4712052: {"type":"l2update","product_id":"YFI-BTC","changes":[["sell","0.82669","0.019844"]],"time":"2021-04-17T16:43:37.479104Z"}
1618677817.471232: {"type":"l2update","product_id":"SKL-BTC","changes":[["sell","0.00001349","1555.5"]],"time":"2021-04-17T16:43:37.482475Z"}
1618677817.471256: {"type":"l2update","product_id":"YFI-BTC","changes":[["sell","0.82853","0.015100"]],"time":"2021-04-17T16:43:37.482713Z"}
1618677817.4712782: {"type":"l2update","product_id":"YFI-BTC","changes":[["buy","0.82191","0.095800"]],"time":"2021-04-17T16:43:37.482713Z"}
1618677817.4713001: {"type":"l2update","product_id":"YFI-BTC","changes":[["buy","0.82374","0.044700"]],"time":"2021-04-17T16:43:37.482713Z"}
1618677817.4713202: {"type":"l2update","product_id":"YFI-BTC","changes":[["buy","0.82404","0.019200"]],"time":"2021-04-17T16:43:37.482713Z"}
1618677817.47134: {"type":"l2update","product_id":"YFI-BTC","changes":[["buy","0.82542","0.000000"]],"time":"2021-04-17T16:43:37.484536Z"}
1618677817.4713652: {"type":"l2update","product_id":"SKL-USD","changes":[["buy","0.7898","702.6"]],"time":"2021-04-17T16:43:37.484710Z"}
1618677817.471384: {"type":"l2update","product_id":"SKL-USD","changes":[["sell","0.7955","5.0"]],"time":"2021-04-17T16:43:37.486312Z"}
1618677817.471402: {"type":"l2update","product_id":"YFI-BTC","changes":[["buy","0.82334","0.072200"]],"time":"2021-04-17T16:43:37.486322Z"}
1618677817.471422: {"type":"l2update","product_id":"YFI-BTC","changes":[["buy","0.82543","0.000670"]],"time":"2021-04-17T16:43:37.486643Z"}
1618677817.4714391: {"type":"l2update","product_id":"SKL-USD","changes":[["sell","0.7978","6630.4"]],"time":"2021-04-17T16:43:37.486333Z"}
1618677817.4780061: {"type":"l2update","product_id":"SKL-BTC","changes":[["buy","0.00001302","1446.8"]],"time":"2021-04-17T16:43:37.487762Z"}
1618677817.478106: {"type":"l2update","product_id":"SKL-BTC","changes":[["buy","0.00001304","1099.7"]],"time":"2021-04-17T16:43:37.488675Z"}
1618677817.4781592: {"type":"l2update","product_id":"YFI-BTC","changes":[["buy","0.82529","0.000000"]],"time":"2021-04-17T16:43:37.490328Z"}
1618677817.47822: {"type":"l2update","product_id":"SKL-USD","changes":[["buy","0.7898","0.0"]],"time":"2021-04-17T16:43:37.490620Z"}
1618677817.478272: {"type":"l2update","product_id":"SKL-USD","changes":[["buy","0.7910","0.0"]],"time":"2021-04-17T16:43:37.493419Z"}
1618677817.482605: {"type":"l2update","product_id":"SKL-USD","changes":[["buy","0.7909","989.7"]],"time":"2021-04-17T16:43:37.496290Z"}
1618677817.482694: {"type":"l2update","product_id":"YFI-BTC","changes":[["buy","0.82544","0.017064"]],"time":"2021-04-17T16:43:37.497818Z"}
1618677817.4827578: {"type":"l2update","product_id":"YFI-BTC","changes":[["sell","0.82701","0.014200"]],"time":"2021-04-17T16:43:37.498176Z"}
1618677817.4883149: {"type":"l2update","product_id":"SKL-BTC","changes":[["buy","0.00001304","110.0"]],"time":"2021-04-17T16:43:37.500368Z"}
1618677817.488404: {"type":"l2update","product_id":"SKL-BTC","changes":[["buy","0.00001305","1007.2"]],"time":"2021-04-17T16:43:37.502079Z"}
1618677817.502101: {"type":"l2update","product_id":"YFI-BTC","changes":[["buy","0.82478","0.187984"]],"time":"2021-04-17T16:43:37.505644Z"}
1618677817.502191: {"type":"l2update","product_id":"SKL-BTC","changes":[["sell","0.00001353","2789.8"]],"time":"2021-04-17T16:43:37.509197Z"}
1618677817.502228: {"type":"l2update","product_id":"SKL-BTC","changes":[["buy","0.00001274","13726.2"]],"time":"2021-04-17T16:43:37.509197Z"}
1618677817.5022552: {"type":"l2update","product_id":"SKL-BTC","changes":[["buy","0.00001299","6923.8"]],"time":"2021-04-17T16:43:37.509225Z"}
1618677817.502282: {"type":"l2update","product_id":"SKL-BTC","changes":[["buy","0.00001286","85454.8"]],"time":"2021-04-17T16:43:37.509225Z"}
1618677817.502306: {"type":"l2update","product_id":"SKL-BTC","changes":[["sell","0.00001309","5356.6"]],"time":"2021-04-17T16:43:37.509225Z"}
1618677817.5023282: {"type":"l2update","product_id":"SKL-BTC","changes":[["sell","0.00001323","23726.8"]],"time":"2021-04-17T16:43:37.509225Z"}
1618677817.50235: {"type":"l2update","product_id":"SKL-USD","changes":[["sell","0.8002","3772.3"]],"time":"2021-04-17T16:43:37.512761Z"}
1618677817.502371: {"type":"l2update","product_id":"SKL-BTC","changes":[["buy","0.00001261","1488.7"]],"time":"2021-04-17T16:43:37.513304Z"}
1618677817.502392: {"type":"l2update","product_id":"SKL-USD","changes":[["buy","0.7886","0.0"]],"time":"2021-04-17T16:43:37.515448Z"}
1618677817.5115478: {"type":"l2update","product_id":"SKL-USD","changes":[["buy","0.7897","1345.1"]],"time":"2021-04-17T16:43:37.524003Z"}
1618677817.5116491: {"type":"l2update","product_id":"NMR-EUR","changes":[["buy","66.4806","0.000"]],"time":"2021-04-17T16:43:37.527007Z"}
1618677817.512185: {"type":"l2update","product_id":"SKL-BTC","changes":[["sell","0.00001308","1768.7"]],"time":"2021-04-17T16:43:37.527644Z"}
1618677817.5264919: {"type":"l2update","product_id":"NMR-EUR","changes":[["sell","67.0210","12.100"]],"time":"2021-04-17T16:43:37.531550Z"}
1618677817.526592: {"type":"match","trade_id":868600,"maker_order_id":"d177e4c4-64cb-4904-aca0-9aca4b1ec7c6","taker_order_id":"dc7c1288-76bc-464d-800b-d3f0e0ee833a","side":"sell","size":"0.148","price":"67.021","product_id":"NMR-EUR","sequence":471056971,"time":"2021-04-17T16:43:37.531550Z"}
1618677817.526646: {"type":"ticker","sequence":471056971,"product_id":"NMR-EUR","price":"67.021","open_24h":"60.9288","volume_24h":"25744.96300000","low_24h":"60.4695","high_24h":"74.5","volume_30d":"552585.25600000","best_bid":"66.9082","best_ask":"67.0210","side":"buy","time":"2021-04-17T16:43:37.531550Z","trade_id":868600,"last_size":"0.148"}
1618677817.526688: {"type":"l2update","product_id":"SKL-USD","changes":[["sell","0.8029","3454.5"]],"time":"2021-04-17T16:43:37.539290Z"}
1618677817.533532: {"type":"l2update","product_id":"SKL-USD","changes":[["buy","0.7903","2224.9"]],"time":"2021-04-17T16:43:37.543135Z"}
1618677817.533613: {"type":"l2update","product_id":"SKL-USD","changes":[["buy","0.7904","866.5"]],"time":"2021-04-17T16:43:37.543235Z"}
1618677817.533673: {"type":"l2update","product_id":"SKL-USD","changes":[["buy","0.7903","1774.9"]],"time":"2021-04-17T16:43:37.545696Z"}
1618677817.541045: {"type":"l2update","product_id":"SKL-BTC","changes":[["sell","0.00001307","893.8"]],"time":"2021-04-17T16:43:37.551375Z"}
1618677817.5411258: {"type":"l2update","product_id":"SKL-USD","changes":[["buy","0.7897","0.0"]],"time":"2021-04-17T16:43:37.552234Z"}
1618677817.541166: {"type":"l2update","product_id":"SKL-USD","changes":[["buy","0.7909","1439.7"]],"time":"2021-04-17T16:43:37.555137Z"}
1618677817.544448: {"type":"l2update","product_id":"SKL-BTC","changes":[["sell","0.00001310","9302.7"]],"time":"2021-04-17T16:43:37.559272Z"}
1618677817.557017: {"type":"l2update","product_id":"SKL-USD","changes":[["sell","0.8053","3663.4"]],"time":"2021-04-17T16:43:37.566931Z"}
1618677817.5570922: {"type":"l2update","product_id":"SKL-USD","changes":[["sell","0.7922","2629.9"]],"time":"2021-04-17T16:43:37.570899Z"}
1618677817.575604: {"type":"l2update","product_id":"SKL-USD","changes":[["buy","0.7877","0.0"]],"time":"2021-04-17T16:43:37.586862Z"}
1618677817.575687: {"type":"l2update","product_id":"SKL-USD","changes":[["buy","0.7798","0.0"]],"time":"2021-04-17T16:43:37.586862Z"}
1618677817.5757198: {"type":"l2update","product_id":"SKL-USD","changes":[["buy","0.7705","0.0"]],"time":"2021-04-17T16:43:37.586862Z"}
1618677817.575746: {"type":"l2update","product_id":"SKL-USD","changes":[["sell","0.7928","23012.0"]],"time":"2021-04-17T16:43:37.586862Z"}
1618677817.5757692: {"type":"l2update","product_id":"SKL-USD","changes":[["sell","0.8008","5.0"]],"time":"2021-04-17T16:43:37.586862Z"}
1618677817.575788: {"type":"l2update","product_id":"SKL-USD","changes":[["buy","0.7884","869.3"]],"time":"2021-04-17T16:43:37.589467Z"}
1618677817.5813131: {"type":"l2update","product_id":"NMR-EUR","changes":[["buy","66.4807","14.231"]],"time":"2021-04-17T16:43:37.594571Z"}
1618677817.581364: {"type":"l2update","product_id":"SKL-USD","changes":[["sell","0.8070","3882.8"]],"time":"2021-04-17T16:43:37.594816Z"}
1618677817.581404: {"type":"l2update","product_id":"YFI-BTC","changes":[["buy","0.82543","0.000000"]],"time":"2021-04-17T16:43:37.595000Z"}
1618677817.5838048: {"type":"l2update","product_id":"YFI-BTC","changes":[["sell","0.82691","0.030084"]],"time":"2021-04-17T16:43:37.598731Z"}
1618677817.58386: {"type":"l2update","product_id":"SKL-USD","changes":[["sell","0.7941","2728.4"]],"time":"2021-04-17T16:43:37.600482Z"}
1618677817.5892212: {"type":"l2update","product_id":"YFI-BTC","changes":[["sell","0.82691","0.000000"]],"time":"2021-04-17T16:43:37.602811Z"}
1618677817.589273: {"type":"l2update","product_id":"YFI-BTC","changes":[["buy","0.82064","0.000670"]],"time":"2021-04-17T16:43:37.602819Z"}
1618677817.589312: {"type":"l2update","product_id":"SKL-USD","changes":[["buy","0.7903","430.0"]],"time":"2021-04-17T16:43:37.605729Z"}
1618677817.590046: {"type":"l2update","product_id":"SKL-BTC","changes":[["buy","0.00001305","0.0"]],"time":"2021-04-17T16:43:37.606474Z"}
1618677817.595737: {"type":"l2update","product_id":"SKL-USD","changes":[["buy","0.7902","2239.4"]],"time":"2021-04-17T16:43:37.610180Z"}
1618677817.6101: {"type":"l2update","product_id":"SKL-BTC","changes":[["sell","0.00001308","4405.2"]],"time":"2021-04-17T16:43:37.618190Z"}
1618677817.610145: {"type":"l2update","product_id":"YFI-BTC","changes":[["sell","0.82731","0.000000"]],"time":"2021-04-17T16:43:37.622309Z"}
1618677817.610181: {"type":"l2update","product_id":"SKL-USD","changes":[["sell","0.8117","3197.4"]],"time":"2021-04-17T16:43:37.625824Z"}
1618677817.6111171: {"type":"l2update","product_id":"SKL-USD","changes":[["buy","0.7897","1344.9"]],"time":"2021-04-17T16:43:37.625907Z"}
1618677817.6111639: {"type":"l2update","product_id":"SKL-BTC","changes":[["buy","0.00001304","1117.2"]],"time":"2021-04-17T16:43:37.626941Z"}
1618677817.61687: {"type":"l2update","product_id":"YFI-BTC","changes":[["sell","0.82668","0.030000"]],"time":"2021-04-17T16:43:37.629573Z"}
1618677817.6169221: {"type":"l2update","product_id":"SKL-BTC","changes":[["sell","0.00001311","4113.4"]],"time":"2021-04-17T16:43:37.629968Z"}
1618677817.61695: {"type":"l2update","product_id":"SKL-BTC","changes":[["buy","0.00001298","4913.0"]],"time":"2021-04-17T16:43:37.629977Z"}
1618677817.616972: {"type":"l2update","product_id":"SKL-BTC","changes":[["buy","0.00001299","4261.8"]],"time":"2021-04-17T16:43:37.629977Z"}
1618677817.616991: {"type":"l2update","product_id":"SKL-BTC","changes":[["buy","0.00001289","46.4"]],"time":"2021-04-17T16:43:37.629977Z"}
1618677817.617009: {"type":"l2update","product_id":"SKL-BTC","changes":[["buy","0.00001298","3497.3"]],"time":"2021-04-17T16:43:37.630183Z"}
1618677817.6361222: {"type":"l2update","product_id":"YFI-BTC","changes":[["buy","0.82479","0.046386"]],"time":"2021-04-17T16:43:37.644325Z"}
1618677817.636173: {"type":"l2update","product_id":"SKL-BTC","changes":[["buy","0.00001302","2858.1"]],"time":"2021-04-17T16:43:37.644414Z"}
1618677817.639104: {"type":"l2update","product_id":"SKL-USD","changes":[["sell","0.8127","17008.6"]],"time":"2021-04-17T16:43:37.655368Z"}
1618677817.639145: {"type":"l2update","product_id":"SKL-USD","changes":[["buy","0.7777","2845.8"]],"time":"2021-04-17T16:43:37.655368Z"}
1618677817.6413922: {"type":"l2update","product_id":"SKL-USD","changes":[["buy","0.7897","0.0"]],"time":"2021-04-17T16:43:37.655820Z"}
1618677817.6444108: {"type":"l2update","product_id":"SKL-USD","changes":[["buy","0.7729","13.6"]],"time":"2021-04-17T16:43:37.659844Z"}
1618677817.6483579: {"type":"l2update","product_id":"SKL-USD","changes":[["buy","0.7909","989.7"]],"time":"2021-04-17T16:43:37.662790Z"}
1618677817.648404: {"type":"l2update","product_id":"SKL-BTC","changes":[["buy","0.00001299","667.3"]],"time":"2021-04-17T16:43:37.663152Z"}
1618677817.64843: {"type":"l2update","product_id":"SKL-BTC","changes":[["buy","0.00001286","50158.6"]],"time":"2021-04-17T16:43:37.663152Z"}
1618677817.6484501: {"type":"l2update","product_id":"SKL-BTC","changes":[["sell","0.00001309","1600.9"]],"time":"2021-04-17T16:43:37.663152Z"}
1618677817.64847: {"type":"l2update","product_id":"SKL-BTC","changes":[["sell","0.00001323","1604.7"]],"time":"2021-04-17T16:43:37.663152Z"}
1618677817.648488: {"type":"l2update","product_id":"SKL-USD","changes":[["buy","0.7903","1774.9"]],"time":"2021-04-17T16:43:37.663334Z"}
1618677817.651365: {"type":"l2update","product_id":"SKL-USD","changes":[["buy","0.7905","450.0"]],"time":"2021-04-17T16:43:37.667056Z"}
1618677817.655781: {"type":"l2update","product_id":"SKL-USD","changes":[["buy","0.7909","1439.7"]],"time":"2021-04-17T16:43:37.670923Z"}
1618677817.659034: {"type":"l2update","product_id":"SKL-BTC","changes":[["buy","0.00001301","16498.2"]],"time":"2021-04-17T16:43:37.670957Z"}
1618677817.6590788: {"type":"l2update","product_id":"SKL-BTC","changes":[["buy","0.00001294","118093.2"]],"time":"2021-04-17T16:43:37.670957Z"}
1618677817.659103: {"type":"l2update","product_id":"SKL-BTC","changes":[["buy","0.00001302","5520.1"]],"time":"2021-04-17T16:43:37.670957Z"}
1618677817.659124: {"type":"l2update","product_id":"SKL-USD","changes":[["buy","0.7905","0.0"]],"time":"2021-04-17T16:43:37.673804Z"}
1618677817.6707358: {"type":"l2update","product_id":"BAND-GBP","changes":[["sell","14.7995","12.49"]],"time":"2021-04-17T16:43:37.686019Z"}
1618677817.6707861: {"type":"l2update","product_id":"BAND-GBP","changes":[["buy","14.7698","12.65"]],"time":"2021-04-17T16:43:37.686057Z"}
1618677817.673833: {"type":"l2update","product_id":"SKL-USD","changes":[["sell","0.8148","3461.9"]],"time":"2021-04-17T16:43:37.689626Z"}
1618677817.678293: {"type":"l2update","product_id":"BAND-GBP","changes":[["buy","14.7693","0.00"]],"time":"2021-04-17T16:43:37.694965Z"}
1618677817.6838531: {"type":"l2update","product_id":"BAND-GBP","changes":[["buy","14.7699","27.51"]],"time":"2021-04-17T16:43:37.700687Z"}
1618677817.69077: {"type":"l2update","product_id":"YFI-BTC","changes":[["buy","0.82478","0.170000"]],"time":"2021-04-17T16:43:37.706487Z"}
1618677817.694122: {"type":"l2update","product_id":"SKL-USD","changes":[["buy","0.7903","430.0"]],"time":"2021-04-17T16:43:37.709507Z"}
1618677817.694179: {"type":"l2update","product_id":"SKL-USD","changes":[["buy","0.7909","450.0"]],"time":"2021-04-17T16:43:37.710657Z"}
1618677817.698407: {"type":"l2update","product_id":"SKL-USD","changes":[["sell","0.8095","12005.0"]],"time":"2021-04-17T16:43:37.715265Z"}
1618677817.7008572: {"type":"l2update","product_id":"SKL-USD","changes":[["buy","0.7909","0.0"]],"time":"2021-04-17T16:43:37.716790Z"}
1618677817.7018409: {"type":"l2update","product_id":"YFI-BTC","changes":[["buy","0.82479","0.064369"]],"time":"2021-04-17T16:43:37.718992Z"}
1618677817.7049322: {"type":"l2update","product_id":"SKL-USD","changes":[["sell","0.8181","3307.0"]],"time":"2021-04-17T16:43:37.719202Z"}
1618677817.707082: {"type":"l2update","product_id":"SKL-USD","changes":[["buy","0.7905","450.0"]],"time":"2021-04-17T16:43:37.723187Z"}
1618677817.7116742: {"type":"l2update","product_id":"SKL-BTC","changes":[["buy","0.00001301","17399.5"]],"time":"2021-04-17T16:43:37.726806Z"}
1618677817.722559: {"type":"l2update","product_id":"SKL-BTC","changes":[["buy","0.00001258","1450.9"]],"time":"2021-04-17T16:43:37.738039Z"}
1618677817.722618: {"type":"l2update","product_id":"SKL-BTC","changes":[["buy","0.00001283","1698.6"]],"time":"2021-04-17T16:43:37.738039Z"}
1618677817.7268312: {"type":"l2update","product_id":"SKL-BTC","changes":[["sell","0.00001309","2504.0"]],"time":"2021-04-17T16:43:37.738209Z"}
1618677817.726878: {"type":"l2update","product_id":"SKL-BTC","changes":[["buy","0.00001274","12332.6"]],"time":"2021-04-17T16:43:37.742595Z"}
1618677817.726905: {"type":"l2update","product_id":"SKL-BTC","changes":[["buy","0.00001294","117634.6"]],"time":"2021-04-17T16:43:37.742595Z"}
1618677817.726926: {"type":"l2update","product_id":"DASH-BTC","changes":[["sell","0.00620126","0.00000000"]],"time":"2021-04-17T16:43:37.743863Z"}
1618677817.7419798: {"type":"l2update","product_id":"SKL-USD","changes":[["buy","0.7885","3782.3"]],"time":"2021-04-17T16:43:37.749347Z"}
1618677817.742033: {"type":"l2update","product_id":"SKL-USD","changes":[["buy","0.7806","74248.1"]],"time":"2021-04-17T16:43:37.749347Z"}
1618677817.7420642: {"type":"l2update","product_id":"SKL-USD","changes":[["buy","0.7727","62795.8"]],"time":"2021-04-17T16:43:37.749347Z"}
1618677817.7420878: {"type":"l2update","product_id":"SKL-USD","changes":[["sell","0.7928","26530.3"]],"time":"2021-04-17T16:43:37.749347Z"}
1618677817.7421088: {"type":"l2update","product_id":"SKL-USD","changes":[["sell","0.8008","20979.7"]],"time":"2021-04-17T16:43:37.749347Z"}
1618677817.7421272: {"type":"l2update","product_id":"SKL-USD","changes":[["buy","0.7858","0.0"]],"time":"2021-04-17T16:43:37.749597Z"}
1618677817.742152: {"type":"l2update","product_id":"SKL-USD","changes":[["buy","0.7849","5.0"]],"time":"2021-04-17T16:43:37.749665Z"}
1618677817.74217: {"type":"l2update","product_id":"SKL-USD","changes":[["sell","0.7928","3518.3"]],"time":"2021-04-17T16:43:37.749665Z"}
1618677817.742187: {"type":"l2update","product_id":"SKL-USD","changes":[["sell","0.7920","0.0"]],"time":"2021-04-17T16:43:37.749665Z"}
1618677817.742212: {"type":"l2update","product_id":"SKL-USD","changes":[["buy","0.7897","1344.9"]],"time":"2021-04-17T16:43:37.752966Z"}
1618677817.742233: {"type":"l2update","product_id":"SKL-USD","changes":[["sell","0.8205","2539.7"]],"time":"2021-04-17T16:43:37.753238Z"}
1618677817.744809: {"type":"l2update","product_id":"SKL-BTC","changes":[["buy","0.00001274","10939.0"]],"time":"2021-04-17T16:43:37.762166Z"}
1618677817.749362: {"type":"l2update","product_id":"SKL-USD","changes":[["sell","0.7927","0.0"]],"time":"2021-04-17T16:43:37.764802Z"}
1618677817.7537549: {"type":"l2update","product_id":"CRV-EUR","changes":[["buy","3.2878","0.00"]],"time":"2021-04-17T16:43:37.766139Z"}
1618677817.756843: {"type":"l2update","product_id":"DASH-BTC","changes":[["sell","0.00620125","1.62300000"]],"time":"2021-04-17T16:43:37.771423Z"}
1618677817.759058: {"type":"l2update","product_id":"DASH-BTC","changes":[["sell","0.00620125","0.00000000"]],"time":"2021-04-17T16:43:37.775878Z"}
1618677817.765764: {"type":"l2update","product_id":"SKL-USD","changes":[["sell","0.7921","6908.0"]],"time":"2021-04-17T16:43:37.778748Z"}
1618677817.7658188: {"type":"l2update","product_id":"SKL-USD","changes":[["sell","0.7926","23012.0"]],"time":"2021-04-17T16:43:37.778748Z"}
1618677817.76585: {"type":"l2update","product_id":"SKL-USD","changes":[["buy","0.7806","97260.1"]],"time":"2021-04-17T16:43:37.778748Z"}
1618677817.769332: {"type":"l2update","product_id":"SKL-USD","changes":[["buy","0.7830","6908.0"]],"time":"2021-04-17T16:43:37.782938Z"}
1618677817.774218: {"type":"l2update","product_id":"DASH-BTC","changes":[["sell","0.00621305","0.00000000"]],"time":"2021-04-17T16:43:37.788313Z"}
1618677817.774274: {"type":"l2update","product_id":"BAND-BTC","changes":[["sell","0.00033538","0.00"]],"time":"2021-04-17T16:43:37.788419Z"}
1618677817.7752: {"type":"l2update","product_id":"DASH-BTC","changes":[["sell","0.00620124","2.57100000"]],"time":"2021-04-17T16:43:37.789916Z"}
1618677817.775302: {"type":"l2update","product_id":"SKL-BTC","changes":[["buy","0.00001298","2836.8"]],"time":"2021-04-17T16:43:37.791010Z"}
1618677817.7785559: {"type":"l2update","product_id":"YFI-BTC","changes":[["sell","0.83797","0.000000"]],"time":"2021-04-17T16:43:37.792970Z"}
1618677817.7786088: {"type":"l2update","product_id":"YFI-BTC","changes":[["sell","0.83275","0.426624"]],"time":"2021-04-17T16:43:37.792970Z"}
1618677817.7786372: {"type":"l2update","product_id":"YFI-BTC","changes":[["sell","0.82996","0.000000"]],"time":"2021-04-17T16:43:37.792970Z"}
1618677817.778663: {"type":"l2update","product_id":"YFI-BTC","changes":[["buy","0.81745","0.000000"]],"time":"2021-04-17T16:43:37.792970Z"}
1618677817.778687: {"type":"l2update","product_id":"DASH-BTC","changes":[["sell","0.00620127","1.09000000"]],"time":"2021-04-17T16:43:37.793774Z"}
1618677817.778713: {"type":"l2update","product_id":"SKL-USD","changes":[["sell","0.7925","29760.1"]],"time":"2021-04-17T16:43:37.793854Z"}
1618677817.780533: {"type":"l2update","product_id":"DASH-BTC","changes":[["sell","0.00621782","1.88000000"]],"time":"2021-04-17T16:43:37.797323Z"}
1618677817.7829561: {"type":"l2update","product_id":"SKL-BTC","changes":[["buy","0.00001258","2638.3"]],"time":"2021-04-17T16:43:37.797552Z"}
1618677817.7830029: {"type":"l2update","product_id":"SKL-BTC","changes":[["buy","0.00001271","1495.1"]],"time":"2021-04-17T16:43:37.797552Z"}
1618677817.783036: {"type":"l2update","product_id":"SKL-BTC","changes":[["buy","0.00001276","1467.5"]],"time":"2021-04-17T16:43:37.797552Z"}
1618677817.787185: {"type":"l2update","product_id":"SKL-BTC","changes":[["buy","0.00001259","193.8"]],"time":"2021-04-17T16:43:37.802353Z"}
1618677817.7872288: {"type":"l2update","product_id":"SKL-BTC","changes":[["buy","0.00001261","21.2"]],"time":"2021-04-17T16:43:37.802353Z"}
1618677817.787255: {"type":"l2update","product_id":"SKL-BTC","changes":[["buy","0.00001299","0.0"]],"time":"2021-04-17T16:43:37.803913Z"}
1618677817.7947872: {"type":"l2update","product_id":"YFI-BTC","changes":[["sell","0.83695","0.100900"]],"time":"2021-04-17T16:43:37.809417Z"}
1618677817.794833: {"type":"l2update","product_id":"YFI-BTC","changes":[["sell","0.83213","0.075600"]],"time":"2021-04-17T16:43:37.809417Z"}
1618677817.8003561: {"type":"l2update","product_id":"YFI-BTC","changes":[["sell","0.82924","0.035300"]],"time":"2021-04-17T16:43:37.809417Z"}
1618677817.800415: {"type":"l2update","product_id":"YFI-BTC","changes":[["buy","0.81667","0.127700"]],"time":"2021-04-17T16:43:37.809417Z"}
1618677817.8004491: {"type":"l2update","product_id":"DASH-BTC","changes":[["sell","0.00620127","2.71300000"]],"time":"2021-04-17T16:43:37.812412Z"}
1618677817.800477: {"type":"l2update","product_id":"YFI-BTC","changes":[["buy","0.82374","0.000000"]],"time":"2021-04-17T16:43:37.815057Z"}
1618677817.805216: {"type":"l2update","product_id":"SKL-USD","changes":[["buy","0.7672","0.0"]],"time":"2021-04-17T16:43:37.820240Z"}
1618677817.805283: {"type":"l2update","product_id":"SKL-USD","changes":[["buy","0.7711","0.0"]],"time":"2021-04-17T16:43:37.820240Z"}
1618677817.8053231: {"type":"l2update","product_id":"SKL-USD","changes":[["buy","0.7796","17803.1"]],"time":"2021-04-17T16:43:37.820240Z"}
1618677817.81145: {"type":"l2update","product_id":"SKL-BTC","changes":[["buy","0.00001301","20630.9"]],"time":"2021-04-17T16:43:37.823595Z"}
1618677817.8115442: {"type":"l2update","product_id":"SKL-BTC","changes":[["buy","0.00001286","85454.8"]],"time":"2021-04-17T16:43:37.823595Z"}
1618677817.811594: {"type":"l2update","product_id":"SKL-BTC","changes":[["sell","0.00001309","6259.7"]],"time":"2021-04-17T16:43:37.823595Z"}
1618677817.8116422: {"type":"l2update","product_id":"SKL-BTC","changes":[["sell","0.00001323","23726.8"]],"time":"2021-04-17T16:43:37.823595Z"}
1618677817.8164139: {"type":"l2update","product_id":"CRV-EUR","changes":[["buy","3.2894","400.00"]],"time":"2021-04-17T16:43:37.830855Z"}
1618677817.8189719: {"type":"l2update","product_id":"BAND-BTC","changes":[["sell","0.00033524","36.72"]],"time":"2021-04-17T16:43:37.834356Z"}
1618677817.819113: {"type":"l2update","product_id":"YFI-BTC","changes":[["buy","0.82335","0.044700"]],"time":"2021-04-17T16:43:37.834657Z"}
1618677817.8191779: {"type":"l2update","product_id":"BAND-GBP","changes":[["buy","14.7474","0.00"]],"time":"2021-04-17T16:43:37.835682Z"}
1618677817.829257: {"type":"l2update","product_id":"SKL-BTC","changes":[["sell","0.00001310","8194.4"]],"time":"2021-04-17T16:43:37.844850Z"}
1618677817.837622: {"type":"l2update","product_id":"SKL-USD","changes":[["sell","0.7938","5.0"]],"time":"2021-04-17T16:43:37.852863Z"}
1618677817.837715: {"type":"l2update","product_id":"SKL-USD","changes":[["buy","0.7605","0.0"]],"time":"2021-04-17T16:43:37.852863Z"}
1618677817.837791: {"type":"l2update","product_id":"SKL-USD","changes":[["buy","0.7612","0.0"]],"time":"2021-04-17T16:43:37.852863Z"}
1618677817.837842: {"type":"l2update","product_id":"SKL-USD","changes":[["buy","0.7619","0.0"]],"time":"2021-04-17T16:43:37.852863Z"}
1618677817.837885: {"type":"l2update","product_id":"SKL-USD","changes":[["buy","0.7652","0.0"]],"time":"2021-04-17T16:43:37.852863Z"}
1618677817.837943: {"type":"l2update","product_id":"SKL-USD","changes":[["buy","0.7692","546.1"]],"time":"2021-04-17T16:43:37.852863Z"}
1618677817.8379672: {"type":"l2update","product_id":"SKL-USD","changes":[["buy","0.7796","16924.5"]],"time":"2021-04-17T16:43:37.852863Z"}
1618677817.84171: {"type":"l2update","product_id":"SKL-BTC","changes":[["sell","0.00001309","7368.0"]],"time":"2021-04-17T16:43:37.856249Z"}
1618677817.8424761: {"type":"l2update","product_id":"SKL-BTC","changes":[["sell","0.00001310","7356.8"]],"time":"2021-04-17T16:43:37.860448Z"}
1618677817.857381: {"type":"l2update","product_id":"SKL-BTC","changes":[["buy","0.00001302","6185.8"]],"time":"2021-04-17T16:43:37.867473Z"}
1618677817.857468: {"type":"l2update","product_id":"CRV-EUR","changes":[["buy","3.2971","0.00"]],"time":"2021-04-17T16:43:37.868730Z"}
1618677817.8575401: {"type":"l2update","product_id":"SKL-USD","changes":[["sell","0.8082","6005.0"]],"time":"2021-04-17T16:43:37.870714Z"}
1618677817.861964: {"type":"l2update","product_id":"NMR-EUR","changes":[["sell","67.0210","11.952"]],"time":"2021-04-17T16:43:37.870988Z"}
1618677817.862039: {"type":"match","trade_id":868601,"maker_order_id":"d177e4c4-64cb-4904-aca0-9aca4b1ec7c6","taker_order_id":"c8e97b26-4903-466c-b26e-444a4fb5a790","side":"sell","size":"0.148","price":"67.021","product_id":"NMR-EUR","sequence":471056976,"time":"2021-04-17T16:43:37.870988Z"}
1618677817.8620968: {"type":"ticker","sequence":471056976,"product_id":"NMR-EUR","price":"67.021","open_24h":"60.9288","volume_24h":"25745.11100000","low_24h":"60.4695","high_24h":"74.5","volume_30d":"552585.40400000","best_bid":"66.9082","best_ask":"67.0210","side":"buy","time":"2021-04-17T16:43:37.870988Z","trade_id":868601,"last_size":"0.148"}
1618677817.862126: {"type":"l2update","product_id":"SKL-USD","changes":[["buy","0.7904","0.0"]],"time":"2021-04-17T16:43:37.873477Z"}
1618677817.862164: {"type":"l2update","product_id":"SKL-USD","changes":[["sell","0.8095","6005.0"]],"time":"2021-04-17T16:43:37.873766Z"}
1618677817.873364: {"type":"l2update","product_id":"SKL-BTC","changes":[["sell","0.00001343","0.0"]],"time":"2021-04-17T16:43:37.874281Z"}
1618677817.8735008: {"type":"l2update","product_id":"SKL-BTC","changes":[["sell","0.00001323","22127.1"]],"time":"2021-04-17T16:43:37.874281Z"}
1618677817.8735812: {"type":"l2update","product_id":"BAND-BTC","changes":[["buy","0.00033348","432.10"]],"time":"2021-04-17T16:43:37.874418Z"}
1618677817.874249: {"type":"l2update","product_id":"DASH-BTC","changes":[["sell","0.00620703","0.56400000"]],"time":"2021-04-17T16:43:37.879274Z"}
1618677817.877397: {"type":"l2update","product_id":"CRV-EUR","changes":[["buy","3.2967","604.97"]],"time":"2021-04-17T16:43:37.882881Z"}
1618677817.8774881: {"type":"l2update","product_id":"CRV-EUR","changes":[["buy","3.2830","0.00"]],"time":"2021-04-17T16:43:37.882959Z"}
1618677817.877557: {"type":"l2update","product_id":"SKL-USD","changes":[["sell","0.8082","12005.0"]],"time":"2021-04-17T16:43:37.883005Z"}
1618677817.8776: {"type":"l2update","product_id":"DASH-BTC","changes":[["sell","0.00620703","0.00000000"]],"time":"2021-04-17T16:43:37.885364Z"}
1618677817.8776488: {"type":"l2update","product_id":"SKL-USD","changes":[["sell","0.8095","5.0"]],"time":"2021-04-17T16:43:37.887364Z"}
1618677817.8816772: {"type":"l2update","product_id":"CRV-EUR","changes":[["sell","3.3024","5097.66"]],"time":"2021-04-17T16:43:37.892925Z"}
1618677817.8817332: {"type":"l2update","product_id":"CRV-EUR","changes":[["buy","3.2858","256.42"]],"time":"2021-04-17T16:43:37.892936Z"}
1618677817.881776: {"type":"l2update","product_id":"SKL-USD","changes":[["sell","0.8082","18005.0"]],"time":"2021-04-17T16:43:37.896561Z"}
1618677817.881804: {"type":"l2update","product_id":"SKL-USD","changes":[["buy","0.7903","1296.6"]],"time":"2021-04-17T16:43:37.896697Z"}
1618677817.881829: {"type":"l2update","product_id":"SKL-USD","changes":[["buy","0.7905","0.0"]],"time":"2021-04-17T16:43:37.897914Z"}
1618677817.885449: {"type":"l2update","product_id":"SKL-BTC","changes":[["sell","0.00001349","0.0"]],"time":"2021-04-17T16:43:37.902129Z"}
1618677817.885518: {"type":"l2update","product_id":"SKL-BTC","changes":[["sell","0.00001345","88.8"]],"time":"2021-04-17T16:43:37.902129Z"}
1618677817.886092: {"type":"l2update","product_id":"SKL-USD","changes":[["buy","0.7884","0.0"]],"time":"2021-04-17T16:43:37.903159Z"}
1618677817.888507: {"type":"l2update","product_id":"SKL-USD","changes":[["buy","0.7904","450.0"]],"time":"2021-04-17T16:43:37.904187Z"}
1618677817.888581: {"type":"l2update","product_id":"SKL-USD","changes":[["buy","0.7902","1194.5"]],"time":"2021-04-17T16:43:37.904314Z"}
1618677817.888617: {"type":"l2update","product_id":"SKL-USD","changes":[["buy","0.7777","48.1"]],"time":"2021-04-17T16:43:37.905095Z"}
1618677817.8886452: {"type":"l2update","product_id":"BAND-GBP","changes":[["buy","14.7699","63.51"]],"time":"2021-04-17T16:43:37.904221Z"}
1618677817.88867: {"type":"l2update","product_id":"DASH-BTC","changes":[["buy","0.00618955","0.00000000"]],"time":"2021-04-17T16:43:37.906125Z"}
1618677817.896109: {"type":"l2update","product_id":"SKL-USD","changes":[["buy","0.7903","2341.3"]],"time":"2021-04-17T16:43:37.911632Z"}
1618677817.900942: {"type":"l2update","product_id":"BAND-GBP","changes":[["buy","14.7642","123.12"]],"time":"2021-04-17T16:43:37.915315Z"}
1618677817.910615: {"type":"l2update","product_id":"BAND-GBP","changes":[["sell","14.7981","123.19"]],"time":"2021-04-17T16:43:37.925607Z"}
1618677817.91075: {"type":"l2update","product_id":"SKL-USD","changes":[["buy","0.7901","1317.5"]],"time":"2021-04-17T16:43:37.925584Z"}
1618677817.9111402: {"type":"l2update","product_id":"SKL-BTC","changes":[["sell","0.00001353","1530.7"]],"time":"2021-04-17T16:43:37.927072Z"}
1618677817.911188: {"type":"l2update","product_id":"SKL-BTC","changes":[["sell","0.00001353","0.0"]],"time":"2021-04-17T16:43:37.927072Z"}
1618677817.9158368: {"type":"l2update","product_id":"SKL-USD","changes":[["buy","0.7902","0.0"]],"time":"2021-04-17T16:43:37.930988Z"}
1618677817.9260402: {"type":"l2update","product_id":"CRV-EUR","changes":[["buy","3.2968","120.00"]],"time":"2021-04-17T16:43:37.940396Z"}
1618677817.934994: {"type":"l2update","product_id":"DASH-BTC","changes":[["buy","0.00618957","2.57200000"]],"time":"2021-04-17T16:43:37.951590Z"}
1618677817.935091: {"type":"l2update","product_id":"YFI-BTC","changes":[["buy","0.82550","0.000360"]],"time":"2021-04-17T16:43:37.951606Z"}
1618677817.9423811: {"type":"l2update","product_id":"SKL-USD","changes":[["buy","0.7901","2512.1"]],"time":"2021-04-17T16:43:37.955285Z"}
1618677817.956088: {"type":"l2update","product_id":"DASH-BTC","changes":[["buy","0.00618956","2.66200000"]],"time":"2021-04-17T16:43:37.970718Z"}
1618677817.960308: {"type":"l2update","product_id":"DASH-BTC","changes":[["buy","0.00618956","1.12000000"]],"time":"2021-04-17T16:43:37.975395Z"}
1618677817.965729: {"type":"l2update","product_id":"DASH-BTC","changes":[["buy","0.00618575","0.00000000"]],"time":"2021-04-17T16:43:37.981455Z"}
1618677817.965801: {"type":"l2update","product_id":"DASH-BTC","changes":[["buy","0.00618890","1.97100000"]],"time":"2021-04-17T16:43:37.981981Z"}
1618677817.97747: {"type":"l2update","product_id":"DASH-BTC","changes":[["buy","0.00618761","0.03000000"]],"time":"2021-04-17T16:43:37.992937Z"}
1618677817.996423: {"type":"l2update","product_id":"SKL-USD","changes":[["buy","0.7897","0.0"]],"time":"2021-04-17T16:43:38.010711Z"}
1618677817.99649: {"type":"l2update","product_id":"DASH-BTC","changes":[["buy","0.00618761","1.57300000"]],"time":"2021-04-17T16:43:38.011116Z"}
1618677818.005326: {"type":"l2update","product_id":"DASH-BTC","changes":[["sell","0.00620797","0.00000000"]],"time":"2021-04-17T16:43:38.021360Z"}
1618677818.028377: {"type":"l2update","product_id":"SKL-USD","changes":[["buy","0.7900","9612.2"]],"time":"2021-04-17T16:43:38.038632Z"}
1618677818.0307221: {"type":"l2update","product_id":"SKL-USD","changes":[["buy","0.7796","8458.5"]],"time":"2021-04-17T16:43:38.046097Z"}
1618677818.030777: {"type":"l2update","product_id":"SKL-USD","changes":[["buy","0.7796","10.0"]],"time":"2021-04-17T16:43:38.046097Z"}
1618677818.03081: {"type":"l2update","product_id":"SKL-USD","changes":[["buy","0.7796","5.0"]],"time":"2021-04-17T16:43:38.046097Z"}
1618677818.0308359: {"type":"l2update","product_id":"SKL-USD","changes":[["buy","0.7725","0.0"]],"time":"2021-04-17T16:43:38.046097Z"}
1618677818.030872: {"type":"l2update","product_id":"SKL-USD","changes":[["buy","0.7714","0.0"]],"time":"2021-04-17T16:43:38.046097Z"}
1618677818.055899: {"type":"l2update","product_id":"SKL-USD","changes":[["buy","0.7855","9474.8"]],"time":"2021-04-17T16:43:38.058959Z"}
1618677818.055969: {"type":"l2update","product_id":"SKL-USD","changes":[["buy","0.7831","16899.6"]],"time":"2021-04-17T16:43:38.058959Z"}
1618677818.055996: {"type":"l2update","product_id":"SKL-USD","changes":[["buy","0.7807","5.0"]],"time":"2021-04-17T16:43:38.058959Z"}
1618677818.05603: {"type":"l2update","product_id":"SKL-USD","changes":[["sell","0.7951","175.8"]],"time":"2021-04-17T16:43:38.058959Z"}
1618677818.0560498: {"type":"l2update","product_id":"SKL-USD","changes":[["sell","0.7975","175.8"]],"time":"2021-04-17T16:43:38.058959Z"}
1618677818.0560691: {"type":"l2update","product_id":"SKL-USD","changes":[["sell","0.8060","295.7"]],"time":"2021-04-17T16:43:38.058959Z"}
1618677818.056087: {"type":"l2update","product_id":"DASH-BTC","changes":[["buy","0.00618520","32.84700000"]],"time":"2021-04-17T16:43:38.066098Z"}
1618677818.0561101: {"type":"l2update","product_id":"DASH-BTC","changes":[["buy","0.00618956","0.00000000"]],"time":"2021-04-17T16:43:38.066698Z"}
1618677818.056136: {"type":"l2update","product_id":"SKL-BTC","changes":[["buy","0.00001299","659.0"]],"time":"2021-04-17T16:43:38.070074Z"}
1618677818.058837: {"type":"l2update","product_id":"SKL-BTC","changes":[["buy","0.00001285","5.0"]],"time":"2021-04-17T16:43:38.074240Z"}
1618677818.0588942: {"type":"l2update","product_id":"SKL-BTC","changes":[["buy","0.00001271","1490.1"]],"time":"2021-04-17T16:43:38.074240Z"}
1618677818.0652611: {"type":"l2update","product_id":"YFI-BTC","changes":[["sell","0.82755","0.000000"]],"time":"2021-04-17T16:43:38.081777Z"}
1618677818.07383: {"type":"l2update","product_id":"DASH-BTC","changes":[["buy","0.00618958","1.12000000"]],"time":"2021-04-17T16:43:38.088973Z"}
1618677818.073893: {"type":"l2update","product_id":"SKL-BTC","changes":[["buy","0.00001294","127923.2"]],"time":"2021-04-17T16:43:38.088996Z"}
1618677818.073913: {"type":"l2update","product_id":"SKL-BTC","changes":[["buy","0.00001292","13171.3"]],"time":"2021-04-17T16:43:38.088996Z"}
1618677818.0739279: {"type":"l2update","product_id":"SKL-BTC","changes":[["buy","0.00001290","16249.2"]],"time":"2021-04-17T16:43:38.088996Z"}
1618677818.073941: {"type":"l2update","product_id":"SKL-BTC","changes":[["buy","0.00001286","91911.1"]],"time":"2021-04-17T16:43:38.088996Z"}
1618677818.073953: {"type":"l2update","product_id":"SKL-BTC","changes":[["sell","0.00001315","27065.9"]],"time":"2021-04-17T16:43:38.088996Z"}
1618677818.073965: {"type":"l2update","product_id":"SKL-BTC","changes":[["sell","0.00001329","26.6"]],"time":"2021-04-17T16:43:38.088996Z"}
1618677818.075862: {"type":"l2update","product_id":"BAND-BTC","changes":[["buy","0.00033425","0.00"]],"time":"2021-04-17T16:43:38.091821Z"}
1618677818.078301: {"type":"l2update","product_id":"DASH-BTC","changes":[["sell","0.00620747","0.00000000"]],"time":"2021-04-17T16:43:38.094136Z"}
1618677818.08108: {"type":"l2update","product_id":"YFI-BTC","changes":[["sell","0.82717","0.029983"]],"time":"2021-04-17T16:43:38.096992Z"}
1618677818.084377: {"type":"l2update","product_id":"BAND-BTC","changes":[["buy","0.00033374","51.39"]],"time":"2021-04-17T16:43:38.100305Z"}
1618677818.0933561: {"type":"l2update","product_id":"DASH-BTC","changes":[["sell","0.00621042","14.63200000"]],"time":"2021-04-17T16:43:38.108516Z"}
1618677818.1000829: {"type":"l2update","product_id":"SKL-USD","changes":[["buy","0.7900","8267.3"]],"time":"2021-04-17T16:43:38.110274Z"}
1618677818.10524: {"type":"l2update","product_id":"NU-GBP","changes":[["buy","0.4379","0.000000"]],"time":"2021-04-17T16:43:38.112479Z"}
1618677818.120554: {"type":"l2update","product_id":"DASH-BTC","changes":[["sell","0.00620127","1.62300000"]],"time":"2021-04-17T16:43:38.122384Z"}
1618677818.1206112: {"type":"l2update","product_id":"DASH-BTC","changes":[["sell","0.00620127","0.00000000"]],"time":"2021-04-17T16:43:38.126227Z"}
1618677818.124647: {"type":"l2update","product_id":"YFI-BTC","changes":[["sell","0.82685","0.000000"]],"time":"2021-04-17T16:43:38.128828Z"}
1618677818.124691: {"type":"l2update","product_id":"SKL-USD","changes":[["sell","0.8082","12005.0"]],"time":"2021-04-17T16:43:38.134226Z"}
1618677818.124715: {"type":"l2update","product_id":"SKL-BTC","changes":[["sell","0.00001333","1846.8"]],"time":"2021-04-17T16:43:38.134280Z"}
1618677818.125373: {"type":"l2update","product_id":"SKL-USD","changes":[["sell","0.8224","2245.7"]],"time":"2021-04-17T16:43:38.134659Z"}
1618677818.125411: {"type":"l2update","product_id":"SKL-USD","changes":[["buy","0.7829","1077.9"]],"time":"2021-04-17T16:43:38.134659Z"}
1618677818.128737: {"type":"l2update","product_id":"BAND-BTC","changes":[["buy","0.00033349","49.42"]],"time":"2021-04-17T16:43:38.139062Z"}
1618677818.130303: {"type":"l2update","product_id":"SKL-USD","changes":[["buy","0.7901","3857.0"]],"time":"2021-04-17T16:43:38.143267Z"}
1618677818.1333382: {"type":"l2update","product_id":"DASH-BTC","changes":[["sell","0.00620123","1.09000000"]],"time":"2021-04-17T16:43:38.143454Z"}
1618677818.133388: {"type":"l2update","product_id":"BAND-BTC","changes":[["buy","0.00033349","20.79"]],"time":"2021-04-17T16:43:38.143714Z"}
1618677818.1334138: {"type":"l2update","product_id":"DASH-BTC","changes":[["buy","0.00618520","0.00000000"]],"time":"2021-04-17T16:43:38.145640Z"}
1618677818.135859: {"type":"l2update","product_id":"DASH-BTC","changes":[["sell","0.00864891","1.96000000"]],"time":"2021-04-17T16:43:38.149158Z"}
1618677818.142111: {"type":"l2update","product_id":"DASH-BTC","changes":[["sell","0.00864891","4.53000000"]],"time":"2021-04-17T16:43:38.153551Z"}
1618677818.142167: {"type":"l2update","product_id":"DASH-BTC","changes":[["buy","0.00619213","1.97100000"]],"time":"2021-04-17T16:43:38.154054Z"}
1618677818.1422038: {"type":"l2update","product_id":"NU-GBP","changes":[["sell","0.4399","0.000000"]],"time":"2021-04-17T16:43:38.158879Z"}
1618677818.145175: {"type":"l2update","product_id":"DASH-BTC","changes":[["buy","0.00617810","0.00000000"]],"time":"2021-04-17T16:43:38.160941Z"}
1618677818.151775: {"type":"l2update","product_id":"BAND-BTC","changes":[["buy","0.00033375","20.77"]],"time":"2021-04-17T16:43:38.161587Z"}
1618677818.1518452: {"type":"l2update","product_id":"DASH-BTC","changes":[["sell","0.00621544","0.00000000"]],"time":"2021-04-17T16:43:38.161950Z"}
1618677818.151891: {"type":"l2update","product_id":"DASH-BTC","changes":[["sell","0.00620123","2.71300000"]],"time":"2021-04-17T16:43:38.162889Z"}
1618677818.15192: {"type":"l2update","product_id":"DASH-BTC","changes":[["buy","0.00619213","3.27100000"]],"time":"2021-04-17T16:43:38.168915Z"}
1618677818.1572502: {"type":"l2update","product_id":"BAND-BTC","changes":[["buy","0.00033375","49.38"]],"time":"2021-04-17T16:43:38.172497Z"}
1618677818.1605902: {"type":"l2update","product_id":"NU-GBP","changes":[["buy","0.4363","3000.000000"]],"time":"2021-04-17T16:43:38.176013Z"}
1618677818.160693: {"type":"l2update","product_id":"DASH-BTC","changes":[["sell","0.00622502","18.77000000"]],"time":"2021-04-17T16:43:38.176306Z"}
1618677818.160758: {"type":"l2update","product_id":"SKL-USD","changes":[["buy","0.7864","1276.6"]],"time":"2021-04-17T16:43:38.176439Z"}
1618677818.167973: {"type":"l2update","product_id":"DASH-BTC","changes":[["buy","0.00618218","0.00000000"]],"time":"2021-04-17T16:43:38.181866Z"}
1618677818.1680782: {"type":"l2update","product_id":"DASH-BTC","changes":[["sell","0.00620531","0.00000000"]],"time":"2021-04-17T16:43:38.182429Z"}
1618677818.177572: {"type":"l2update","product_id":"DASH-BTC","changes":[["sell","0.00620621","0.00000000"]],"time":"2021-04-17T16:43:38.186113Z"}
1618677818.177676: {"type":"l2update","product_id":"SKL-USD","changes":[["sell","0.7944","1263.8"]],"time":"2021-04-17T16:43:38.187386Z"}
1618677818.177732: {"type":"l2update","product_id":"DASH-BTC","changes":[["buy","0.00613941","16.90800000"]],"time":"2021-04-17T16:43:38.188661Z"}
1618677818.1777768: {"type":"l2update","product_id":"DASH-BTC","changes":[["buy","0.00613941","14.50300000"]],"time":"2021-04-17T16:43:38.188661Z"}
1618677818.1880472: {"type":"l2update","product_id":"SKL-GBP","changes":[["sell","0.5782","1259.2"]],"time":"2021-04-17T16:43:38.194709Z"}
1618677818.190607: {"type":"l2update","product_id":"DASH-BTC","changes":[["buy","0.00613941","16.37500000"]],"time":"2021-04-17T16:43:38.198697Z"}
1618677818.1961112: {"type":"l2update","product_id":"DASH-BTC","changes":[["sell","0.00620621","2.23600000"]],"time":"2021-04-17T16:43:38.202462Z"}
1618677818.1962109: {"type":"l2update","product_id":"SKL-BTC","changes":[["sell","0.00001338","1618.8"]],"time":"2021-04-17T16:43:38.206419Z"}
1618677818.201199: {"type":"l2update","product_id":"SKL-USD","changes":[["buy","0.7794","2743.4"]],"time":"2021-04-17T16:43:38.210800Z"}
1618677818.2012439: {"type":"l2update","product_id":"NMR-EUR","changes":[["sell","67.0310","0.000"]],"time":"2021-04-17T16:43:38.213783Z"}
1618677818.2035131: {"type":"l2update","product_id":"SKL-USD","changes":[["buy","0.7889","0.0"]],"time":"2021-04-17T16:43:38.215461Z"}
1618677818.206008: {"type":"l2update","product_id":"DASH-BTC","changes":[["sell","0.00621011","1.62300000"]],"time":"2021-04-17T16:43:38.218434Z"}
1618677818.211503: {"type":"l2update","product_id":"SKL-USD","changes":[["buy","0.7903","1474.7"]],"time":"2021-04-17T16:43:38.220579Z"}
1618677818.214849: {"type":"l2update","product_id":"NMR-EUR","changes":[["sell","67.1072","0.000"]],"time":"2021-04-17T16:43:38.230292Z"}
1618677818.2193851: {"type":"l2update","product_id":"SKL-BTC","changes":[["sell","0.00001342","2236.2"]],"time":"2021-04-17T16:43:38.232194Z"}
1618677818.2195032: {"type":"l2update","product_id":"DASH-BTC","changes":[["buy","0.00618736","32.84700000"]],"time":"2021-04-17T16:43:38.234844Z"}
1618677818.222646: {"type":"l2update","product_id":"SKL-USD","changes":[["buy","0.7778","3908.3"]],"time":"2021-04-17T16:43:38.238827Z"}
1618677818.229963: {"type":"l2update","product_id":"SKL-USD","changes":[["buy","0.7902","866.7"]],"time":"2021-04-17T16:43:38.242350Z"}
1618677818.239698: {"type":"l2update","product_id":"SKL-BTC","changes":[["sell","0.00001349","1858.2"]],"time":"2021-04-17T16:43:38.253411Z"}
1618677818.254098: {"type":"l2update","product_id":"NMR-EUR","changes":[["sell","67.0209","1.275"]],"time":"2021-04-17T16:43:38.260728Z"}
1618677818.2542322: {"type":"l2update","product_id":"SKL-USD","changes":[["buy","0.7905","2630.0"]],"time":"2021-04-17T16:43:38.264689Z"}
1618677818.261497: {"type":"l2update","product_id":"DASH-BTC","changes":[["sell","0.00621042","0.00000000"]],"time":"2021-04-17T16:43:38.269795Z"}
1618677818.261615: {"type":"l2update","product_id":"SKL-USD","changes":[["buy","0.7901","2662.4"]],"time":"2021-04-17T16:43:38.271374Z"}
1618677818.261674: {"type":"l2update","product_id":"SKL-USD","changes":[["buy","0.7853","15280.5"]],"time":"2021-04-17T16:43:38.273786Z"}
1618677818.261717: {"type":"l2update","product_id":"SKL-USD","changes":[["buy","0.7904","0.0"]],"time":"2021-04-17T16:43:38.274334Z"}
1618677818.265701: {"type":"l2update","product_id":"SKL-USD","changes":[["buy","0.7906","450.0"]],"time":"2021-04-17T16:43:38.279738Z"}
1618677818.265802: {"type":"l2update","product_id":"NMR-EUR","changes":[["sell","67.0877","1.275"]],"time":"2021-04-17T16:43:38.279860Z"}
1618677818.265862: {"type":"l2update","product_id":"SKL-BTC","changes":[["sell","0.00001355","2308.7"]],"time":"2021-04-17T16:43:38.279919Z"}
1618677818.2659059: {"type":"l2update","product_id":"DASH-BTC","changes":[["buy","0.00618890","0.00000000"]],"time":"2021-04-17T16:43:38.282876Z"}
1618677818.2785752: {"type":"l2update","product_id":"SKL-BTC","changes":[["buy","0.00001303","7412.3"]],"time":"2021-04-17T16:43:38.287732Z"}
1618677818.278666: {"type":"l2update","product_id":"NU-GBP","changes":[["buy","0.4381","0.000000"]],"time":"2021-04-17T16:43:38.288317Z"}
1618677818.2787452: {"type":"l2update","product_id":"SKL-USD","changes":[["sell","0.8088","6005.0"]],"time":"2021-04-17T16:43:38.291877Z"}
1618677818.2787762: {"type":"l2update","product_id":"SKL-USD","changes":[["sell","0.8082","6005.0"]],"time":"2021-04-17T16:43:38.295452Z"}
1618677818.288054: {"type":"l2update","product_id":"DASH-BTC","changes":[["sell","0.00621012","0.00000000"]],"time":"2021-04-17T16:43:38.301488Z"}
1618677818.288119: {"type":"l2update","product_id":"SKL-USD","changes":[["sell","0.8088","12005.0"]],"time":"2021-04-17T16:43:38.302229Z"}
1618677818.2881541: {"type":"l2update","product_id":"YFI-BTC","changes":[["sell","0.82767","0.000000"]],"time":"2021-04-17T16:43:38.302176Z"}
1618677818.288189: {"type":"l2update","product_id":"SKL-USD","changes":[["buy","0.7902","2061.2"]],"time":"2021-04-17T16:43:38.302711Z"}
1618677818.291074: {"type":"l2update","product_id":"SKL-USD","changes":[["sell","0.8082","5.0"]],"time":"2021-04-17T16:43:38.305756Z"}
1618677818.291157: {"type":"l2update","product_id":"NU-GBP","changes":[["sell","0.4393","9013.344533"]],"time":"2021-04-17T16:43:38.306316Z"}
1618677818.2935739: {"type":"l2update","product_id":"NU-GBP","changes":[["buy","0.4386","1659.979400"]],"time":"2021-04-17T16:43:38.309597Z"}
1618677818.297054: {"type":"l2update","product_id":"SKL-USD","changes":[["sell","0.8088","18005.0"]],"time":"2021-04-17T16:43:38.313236Z"}
1618677818.301808: {"type":"l2update","product_id":"NU-GBP","changes":[["buy","0.4385","413.994955"]],"time":"2021-04-17T16:43:38.315903Z"}
1618677818.3076968: {"type":"l2update","product_id":"NU-GBP","changes":[["buy","0.4387","243.001000"]],"time":"2021-04-17T16:43:38.321242Z"}
1618677818.310113: {"type":"l2update","product_id":"SKL-USD","changes":[["buy","0.7744","2605.3"]],"time":"2021-04-17T16:43:38.326146Z"}
1618677818.3234482: {"type":"l2update","product_id":"NU-GBP","changes":[["buy","0.4386","0.000000"]],"time":"2021-04-17T16:43:38.337775Z"}
1618677818.327989: {"type":"l2update","product_id":"SKL-BTC","changes":[["buy","0.00001304","2010.8"]],"time":"2021-04-17T16:43:38.340956Z"}
1618677818.328073: {"type":"l2update","product_id":"CRV-EUR","changes":[["sell","3.3025","0.00"]],"time":"2021-04-17T16:43:38.341340Z"}
1618677818.3389492: {"type":"l2update","product_id":"CRV-EUR","changes":[["buy","3.2967","508.05"]],"time":"2021-04-17T16:43:38.350403Z"}
1618677818.3390698: {"type":"l2update","product_id":"CRV-EUR","changes":[["sell","3.3024","97.66"]],"time":"2021-04-17T16:43:38.351318Z"}
1618677818.3391209: {"type":"l2update","product_id":"SKL-USD","changes":[["buy","0.7726","3804.9"]],"time":"2021-04-17T16:43:38.351197Z"}
1618677818.3391821: {"type":"l2update","product_id":"DASH-BTC","changes":[["buy","0.00619213","1.30000000"]],"time":"2021-04-17T16:43:38.354650Z"}
1618677818.3392231: {"type":"l2update","product_id":"DASH-BTC","changes":[["sell","0.00620846","14.63200000"]],"time":"2021-04-17T16:43:38.354717Z"}
1618677818.3392699: {"type":"l2update","product_id":"CRV-EUR","changes":[["sell","3.3031","5000.00"]],"time":"2021-04-17T16:43:38.355129Z"}
1618677818.340273: {"type":"l2update","product_id":"CRV-EUR","changes":[["buy","3.2969","96.91"]],"time":"2021-04-17T16:43:38.355315Z"}
1618677818.343047: {"type":"l2update","product_id":"CRV-EUR","changes":[["buy","3.2961","5000.00"]],"time":"2021-04-17T16:43:38.358307Z"}
1618677818.347308: {"type":"l2update","product_id":"DASH-BTC","changes":[["buy","0.00618761","1.54300000"]],"time":"2021-04-17T16:43:38.359585Z"}
1618677818.3473961: {"type":"l2update","product_id":"DASH-BTC","changes":[["sell","0.00864891","4.80000000"]],"time":"2021-04-17T16:43:38.362700Z"}
1618677818.3474472: {"type":"l2update","product_id":"DASH-BTC","changes":[["buy","0.00618761","0.00000000"]],"time":"2021-04-17T16:43:38.364365Z"}
1618677818.350919: {"type":"l2update","product_id":"CRV-EUR","changes":[["buy","3.2974","532.81"]],"time":"2021-04-17T16:43:38.366255Z"}
1618677818.356653: {"type":"l2update","product_id":"NMR-EUR","changes":[["buy","66.8975","0.000"]],"time":"2021-04-17T16:43:38.370625Z"}
1618677818.356791: {"type":"l2update","product_id":"SKL-USD","changes":[["buy","0.7901","1317.5"]],"time":"2021-04-17T16:43:38.370724Z"}
1618677818.358655: {"type":"l2update","product_id":"CRV-EUR","changes":[["buy","3.2969","0.00"]],"time":"2021-04-17T16:43:38.373626Z"}
1618677818.363263: {"type":"l2update","product_id":"CRV-EUR","changes":[["buy","3.2975","96.89"]],"time":"2021-04-17T16:43:38.377957Z"}
1618677818.374261: {"type":"l2update","product_id":"DASH-BTC","changes":[["buy","0.00618958","1.15000000"]],"time":"2021-04-17T16:43:38.385949Z"}
1618677818.374382: {"type":"l2update","product_id":"SKL-BTC","changes":[["sell","0.00001313","170.8"]],"time":"2021-04-17T16:43:38.386740Z"}
1618677818.3744378: {"type":"l2update","product_id":"SKL-BTC","changes":[["sell","0.00001340","198.2"]],"time":"2021-04-17T16:43:38.386740Z"}
1618677818.376384: {"type":"l2update","product_id":"SKL-USD","changes":[["buy","0.7872","126.7"]],"time":"2021-04-17T16:43:38.390492Z"}
1618677818.381236: {"type":"l2update","product_id":"NMR-EUR","changes":[["buy","66.8225","0.000"]],"time":"2021-04-17T16:43:38.391326Z"}
1618677818.3813062: {"type":"l2update","product_id":"CRV-EUR","changes":[["buy","3.2953","524.75"]],"time":"2021-04-17T16:43:38.395152Z"}
1618677818.385977: {"type":"l2update","product_id":"DASH-BTC","changes":[["buy","0.00618958","2.69200000"]],"time":"2021-04-17T16:43:38.396823Z"}
1618677818.386034: {"type":"l2update","product_id":"SKL-USD","changes":[["buy","0.7902","3406.1"]],"time":"2021-04-17T16:43:38.397235Z"}
1618677818.3860679: {"type":"l2update","product_id":"NMR-EUR","changes":[["sell","67.0877","0.000"]],"time":"2021-04-17T16:43:38.403205Z"}
1618677818.387821: {"type":"l2update","product_id":"SKL-USD","changes":[["buy","0.7903","1044.7"]],"time":"2021-04-17T16:43:38.404702Z"}
1618677818.3987358: {"type":"l2update","product_id":"SKL-USD","changes":[["buy","0.7697","26425.0"]],"time":"2021-04-17T16:43:38.412418Z"}
1618677818.409187: {"type":"l2update","product_id":"SKL-BTC","changes":[["sell","0.00001309","10002.3"]],"time":"2021-04-17T16:43:38.423787Z"}
1618677818.410047: {"type":"l2update","product_id":"YFI-BTC","changes":[["buy","0.82335","0.000000"]],"time":"2021-04-17T16:43:38.425468Z"}
1618677818.414138: {"type":"l2update","product_id":"NMR-EUR","changes":[["buy","66.9083","1.275"]],"time":"2021-04-17T16:43:38.427518Z"}
1618677818.414603: {"type":"l2update","product_id":"SKL-USD","changes":[["sell","0.7942","2639.3"]],"time":"2021-04-17T16:43:38.427597Z"}
1618677818.420508: {"type":"l2update","product_id":"SKL-BTC","changes":[["sell","0.00001309","11319.5"]],"time":"2021-04-17T16:43:38.430953Z"}
1618677818.420628: {"type":"l2update","product_id":"SKL-USD","changes":[["sell","0.7937","1322.2"]],"time":"2021-04-17T16:43:38.434242Z"}
1618677818.422548: {"type":"l2update","product_id":"CRV-EUR","changes":[["buy","3.2857","0.00"]],"time":"2021-04-17T16:43:38.435060Z"}
1618677818.4226592: {"type":"l2update","product_id":"CRV-EUR","changes":[["buy","3.2935","0.00"]],"time":"2021-04-17T16:43:38.435112Z"}
1618677818.422721: {"type":"l2update","product_id":"CRV-EUR","changes":[["buy","3.2964","0.00"]],"time":"2021-04-17T16:43:38.435225Z"}
1618677818.424597: {"type":"l2update","product_id":"YFI-BTC","changes":[["buy","0.82374","0.044700"]],"time":"2021-04-17T16:43:38.438305Z"}
1618677818.4277902: {"type":"l2update","product_id":"NMR-EUR","changes":[["buy","66.9082","0.000"]],"time":"2021-04-17T16:43:38.440375Z"}
1618677818.427893: {"type":"l2update","product_id":"SKL-USD","changes":[["buy","0.7677","3212.4"]],"time":"2021-04-17T16:43:38.442516Z"}
1618677818.430979: {"type":"l2update","product_id":"YFI-BTC","changes":[["buy","0.82503","0.030139"]],"time":"2021-04-17T16:43:38.445733Z"}
1618677818.43529: {"type":"l2update","product_id":"SKL-USD","changes":[["sell","0.8081","6005.0"]],"time":"2021-04-17T16:43:38.449456Z"}
1618677818.435379: {"type":"l2update","product_id":"NMR-EUR","changes":[["buy","66.9195","4.774"]],"time":"2021-04-17T16:43:38.449610Z"}
1618677818.444135: {"type":"l2update","product_id":"YFI-BTC","changes":[["buy","0.82474","0.029572"]],"time":"2021-04-17T16:43:38.456829Z"}
1618677818.444275: {"type":"l2update","product_id":"CRV-EUR","changes":[["buy","3.2953","665.68"]],"time":"2021-04-17T16:43:38.456849Z"}
1618677818.44433: {"type":"l2update","product_id":"NMR-EUR","changes":[["buy","66.8799","1.275"]],"time":"2021-04-17T16:43:38.457069Z"}
1618677818.444381: {"type":"l2update","product_id":"NMR-EUR","changes":[["sell","67.0418","1.275"]],"time":"2021-04-17T16:43:38.457082Z"}
1618677818.444427: {"type":"l2update","product_id":"SKL-USD","changes":[["sell","0.8081","12005.0"]],"time":"2021-04-17T16:43:38.460655Z"}
1618677818.455596: {"type":"l2update","product_id":"DASH-BTC","changes":[["sell","0.00620123","1.09000000"]],"time":"2021-04-17T16:43:38.471260Z"}
1618677818.4557152: {"type":"l2update","product_id":"SKL-USD","changes":[["sell","0.8081","18005.0"]],"time":"2021-04-17T16:43:38.471888Z"}
1618677818.4587069: {"type":"l2update","product_id":"NU-GBP","changes":[["buy","0.4364","710.000000"]],"time":"2021-04-17T16:43:38.471980Z"}
1618677818.4588108: {"type":"l2update","product_id":"NU-GBP","changes":[["buy","0.4363","3160.000000"]],"time":"2021-04-17T16:43:38.471980Z"}
1618677818.4588642: {"type":"l2update","product_id":"NU-GBP","changes":[["buy","0.4350","60.000000"]],"time":"2021-04-17T16:43:38.471980Z"}
1618677818.458912: {"type":"l2update","product_id":"SKL-GBP","changes":[["buy","0.5691","0.0"]],"time":"2021-04-17T16:43:38.473664Z"}
1618677818.458967: {"type":"l2update","product_id":"SKL-GBP","changes":[["buy","0.5721","480.0"]],"time":"2021-04-17T16:43:38.473664Z"}
1618677818.4590049: {"type":"l2update","product_id":"SKL-GBP","changes":[["buy","0.5722","255.0"]],"time":"2021-04-17T16:43:38.473664Z"}
1618677818.4607491: {"type":"l2update","product_id":"CRV-EUR","changes":[["buy","3.2875","140.93"]],"time":"2021-04-17T16:43:38.475717Z"}
1618677818.4653: {"type":"l2update","product_id":"SKL-USD","changes":[["buy","0.7645","3002.2"]],"time":"2021-04-17T16:43:38.476012Z"}
1618677818.4654038: {"type":"l2update","product_id":"CRV-EUR","changes":[["buy","3.2970","140.93"]],"time":"2021-04-17T16:43:38.479371Z"}
1618677818.465464: {"type":"l2update","product_id":"SKL-GBP","changes":[["buy","0.5745","380.0"]],"time":"2021-04-17T16:43:38.479467Z"}
1618677818.465513: {"type":"l2update","product_id":"SKL-USD","changes":[["buy","0.7855","9469.8"]],"time":"2021-04-17T16:43:38.480813Z"}
1618677818.4655519: {"type":"l2update","product_id":"SKL-USD","changes":[["sell","0.7981","5.0"]],"time":"2021-04-17T16:43:38.480813Z"}
1618677818.474049: {"type":"l2update","product_id":"SKL-GBP","changes":[["buy","0.5744","0.0"]],"time":"2021-04-17T16:43:38.487185Z"}
1618677818.4762182: {"type":"l2update","product_id":"DASH-BTC","changes":[["sell","0.00620531","1.62300000"]],"time":"2021-04-17T16:43:38.490994Z"}
1618677818.4814599: {"type":"l2update","product_id":"SKL-GBP","changes":[["buy","0.5746","1028.8"]],"time":"2021-04-17T16:43:38.494692Z"}
1618677818.485086: {"type":"l2update","product_id":"YFI-BTC","changes":[["buy","0.82533","0.020754"]],"time":"2021-04-17T16:43:38.498019Z"}
1618677818.489161: {"type":"l2update","product_id":"YFI-BTC","changes":[["buy","0.82495","0.019900"]],"time":"2021-04-17T16:43:38.502109Z"}
1618677818.4950662: {"type":"l2update","product_id":"SKL-USD","changes":[["buy","0.7623","3088.7"]],"time":"2021-04-17T16:43:38.510186Z"}
1618677818.499982: {"type":"l2update","product_id":"SKL-USD","changes":[["buy","0.7875","1900.0"]],"time":"2021-04-17T16:43:38.513369Z"}
1618677818.500741: {"type":"l2update","product_id":"SKL-USD","changes":[["sell","0.7997","750.0"]],"time":"2021-04-17T16:43:38.517134Z"}
1618677818.50194: {"type":"l2update","product_id":"SKL-USD","changes":[["buy","0.7832","51.2"]],"time":"2021-04-17T16:43:38.517134Z"}
1618677818.5030122: {"type":"l2update","product_id":"CRV-EUR","changes":[["sell","3.3042","0.00"]],"time":"2021-04-17T16:43:38.520290Z"}
1618677818.506475: {"type":"l2update","product_id":"CRV-EUR","changes":[["buy","3.2931","0.00"]],"time":"2021-04-17T16:43:38.523605Z"}
1618677818.5164852: {"type":"l2update","product_id":"CRV-EUR","changes":[["sell","3.3032","0.00"]],"time":"2021-04-17T16:43:38.527392Z"}
1618677818.516584: {"type":"l2update","product_id":"SKL-BTC","changes":[["sell","0.00001309","7563.8"]],"time":"2021-04-17T16:43:38.528123Z"}
1618677818.5326378: {"type":"l2update","product_id":"CRV-EUR","changes":[["sell","3.3031","0.00"]],"time":"2021-04-17T16:43:38.537009Z"}
1618677818.542923: {"type":"l2update","product_id":"SKL-USD","changes":[["sell","0.8750","4201.1"]],"time":"2021-04-17T16:43:38.542449Z"}
1618677818.5429919: {"type":"l2update","product_id":"SKL-USD","changes":[["buy","0.7901","450.0"]],"time":"2021-04-17T16:43:38.543008Z"}
1618677818.543027: {"type":"l2update","product_id":"CRV-EUR","changes":[["sell","3.3043","5000.00"]],"time":"2021-04-17T16:43:38.544197Z"}
1618677818.549433: {"type":"l2update","product_id":"YFI-BTC","changes":[["buy","0.82544","0.000000"]],"time":"2021-04-17T16:43:38.552561Z"}
1618677818.54956: {"type":"l2update","product_id":"CRV-EUR","changes":[["sell","3.3059","531.50"]],"time":"2021-04-17T16:43:38.555163Z"}
1618677818.5496268: {"type":"l2update","product_id":"CRV-EUR","changes":[["buy","3.2982","505.59"]],"time":"2021-04-17T16:43:38.555299Z"}
1618677818.5547142: {"type":"l2update","product_id":"DASH-BTC","changes":[["sell","0.00620353","0.00000000"]],"time":"2021-04-17T16:43:38.561335Z"}
1618677818.55559: {"type":"l2update","product_id":"SKL-USD","changes":[["buy","0.7889","868.8"]],"time":"2021-04-17T16:43:38.566547Z"}
1618677818.555661: {"type":"l2update","product_id":"CRV-EUR","changes":[["buy","3.2953","140.93"]],"time":"2021-04-17T16:43:38.566711Z"}
1618677818.555696: {"type":"l2update","product_id":"SKL-USD","changes":[["buy","0.7902","2539.4"]],"time":"2021-04-17T16:43:38.571098Z"}
1618677818.560113: {"type":"l2update","product_id":"NMR-EUR","changes":[["buy","66.9083","0.000"]],"time":"2021-04-17T16:43:38.573693Z"}
1618677818.60155: {"type":"l2update","product_id":"CRV-EUR","changes":[["sell","3.3043","0.00"]],"time":"2021-04-17T16:43:38.590874Z"}
1618677818.601695: {"type":"l2update","product_id":"NMR-EUR","changes":[["sell","72.0964","0.000"]],"time":"2021-04-17T16:43:38.596177Z"}
1618677818.60176: {"type":"l2update","product_id":"NMR-EUR","changes":[["sell","72.0968","0.000"]],"time":"2021-04-17T16:43:38.596177Z"}
1618677818.6018062: {"type":"l2update","product_id":"NMR-EUR","changes":[["sell","72.0966","0.000"]],"time":"2021-04-17T16:43:38.596177Z"}
1618677818.6018481: {"type":"l2update","product_id":"NMR-EUR","changes":[["buy","66.4787","0.000"]],"time":"2021-04-17T16:43:38.596177Z"}
1618677818.601894: {"type":"l2update","product_id":"NMR-EUR","changes":[["sell","72.0965","0.000"]],"time":"2021-04-17T16:43:38.596177Z"}
1618677818.601933: {"type":"l2update","product_id":"NMR-EUR","changes":[["sell","72.0967","0.000"]],"time":"2021-04-17T16:43:38.596177Z"}
1618677818.601973: {"type":"l2update","product_id":"SKL-USD","changes":[["buy","0.7904","866.5"]],"time":"2021-04-17T16:43:38.598535Z"}
1618677818.6020238: {"type":"l2update","product_id":"YFI-BTC","changes":[["buy","0.82541","0.017064"]],"time":"2021-04-17T16:43:38.598698Z"}
1618677818.6021178: {"type":"l2update","product_id":"SKL-USD","changes":[["sell","0.8088","12005.0"]],"time":"2021-04-17T16:43:38.601702Z"}
1618677818.602144: {"type":"l2update","product_id":"SKL-USD","changes":[["sell","0.8088","6005.0"]],"time":"2021-04-17T16:43:38.604792Z"}
1618677818.602179: {"type":"l2update","product_id":"DASH-BTC","changes":[["buy","0.00619149","1.97100000"]],"time":"2021-04-17T16:43:38.605848Z"}
1618677818.602218: {"type":"l2update","product_id":"SKL-USD","changes":[["sell","0.8088","5.0"]],"time":"2021-04-17T16:43:38.607373Z"}
1618677818.60224: {"type":"l2update","product_id":"NMR-EUR","changes":[["buy","66.4808","17.660"]],"time":"2021-04-17T16:43:38.610364Z"}
1618677818.602266: {"type":"l2update","product_id":"NMR-EUR","changes":[["sell","71.7841","23.800"]],"time":"2021-04-17T16:43:38.610364Z"}
1618677818.602292: {"type":"l2update","product_id":"NMR-EUR","changes":[["sell","71.7340","23.060"]],"time":"2021-04-17T16:43:38.610364Z"}
1618677818.6023161: {"type":"l2update","product_id":"NMR-EUR","changes":[["buy","66.4806","3.450"]],"time":"2021-04-17T16:43:38.610364Z"}
1618677818.602347: {"type":"l2update","product_id":"NMR-EUR","changes":[["sell","71.9128","19.420"]],"time":"2021-04-17T16:43:38.610364Z"}
1618677818.6023722: {"type":"l2update","product_id":"NMR-EUR","changes":[["sell","71.7246","12.350"]],"time":"2021-04-17T16:43:38.610364Z"}
1618677818.602397: {"type":"l2update","product_id":"NMR-EUR","changes":[["sell","71.6465","4.630"]],"time":"2021-04-17T16:43:38.610364Z"}
1618677818.602421: {"type":"l2update","product_id":"NMR-EUR","changes":[["buy","66.4805","11.620"]],"time":"2021-04-17T16:43:38.610364Z"}
1618677818.610368: {"type":"l2update","product_id":"SKL-USD","changes":[["sell","0.7921","3.0"]],"time":"2021-04-17T16:43:38.615125Z"}
1618677818.6104152: {"type":"match","trade_id":1568272,"maker_order_id":"247759c4-144c-45dd-be16-a2957a5a9f9a","taker_order_id":"3ce66370-76d2-4571-a3e5-9c9b74175683","side":"sell","size":"6905","price":"0.7921","product_id":"SKL-USD","sequence":201390480,"time":"2021-04-17T16:43:38.615125Z"}
1618677818.610444: {"type":"ticker","sequence":201390480,"product_id":"SKL-USD","price":"0.7921","open_24h":"0.7055","volume_24h":"34254813.50000000","low_24h":"0.6915","high_24h":"0.8098","volume_30d":"948682166.20000000","best_bid":"0.7906","best_ask":"0.7921","side":"buy","time":"2021-04-17T16:43:38.615125Z","trade_id":1568272,"last_size":"6905"}
1618677818.610466: {"type":"l2update","product_id":"SKL-USD","changes":[["buy","0.7902","1344.9"]],"time":"2021-04-17T16:43:38.620571Z"}
1618677818.61049: {"type":"l2update","product_id":"SKL-USD","changes":[["sell","0.7921","0.0"]],"time":"2021-04-17T16:43:38.620995Z"}
1618677818.610522: {"type":"l2update","product_id":"YFI-BTC","changes":[["sell","0.82691","0.029644"]],"time":"2021-04-17T16:43:38.621764Z"}
1618677818.61055: {"type":"l2update","product_id":"NMR-EUR","changes":[["buy","66.9196","1.275"]],"time":"2021-04-17T16:43:38.624793Z"}
1618677818.614959: {"type":"l2update","product_id":"YFI-BTC","changes":[["sell","0.82924","0.000000"]],"time":"2021-04-17T16:43:38.627225Z"}
1618677818.615075: {"type":"l2update","product_id":"SKL-USD","changes":[["buy","0.7907","7500.0"]],"time":"2021-04-17T16:43:38.628592Z"}
1618677818.621514: {"type":"l2update","product_id":"YFI-BTC","changes":[["sell","0.82691","0.000000"]],"time":"2021-04-17T16:43:38.633369Z"}
1618677818.621598: {"type":"l2update","product_id":"SKL-USD","changes":[["buy","0.7906","0.0"]],"time":"2021-04-17T16:43:38.635424Z"}
1618677818.621632: {"type":"l2update","product_id":"NMR-EUR","changes":[["buy","66.9195","0.000"]],"time":"2021-04-17T16:43:38.635475Z"}
1618677818.6220522: {"type":"l2update","product_id":"SKL-USD","changes":[["buy","0.7865","7292.4"]],"time":"2021-04-17T16:43:38.636007Z"}
1618677818.629544: {"type":"l2update","product_id":"NMR-EUR","changes":[["buy","66.9290","4.774"]],"time":"2021-04-17T16:43:38.639546Z"}
1618677818.6296089: {"type":"l2update","product_id":"YFI-BTC","changes":[["sell","0.82976","0.035300"]],"time":"2021-04-17T16:43:38.639703Z"}
1618677818.629644: {"type":"l2update","product_id":"SKL-USD","changes":[["buy","0.7908","450.0"]],"time":"2021-04-17T16:43:38.639749Z"}
1618677818.6296692: {"type":"l2update","product_id":"SKL-GBP","changes":[["buy","0.5741","0.0"]],"time":"2021-04-17T16:43:38.641215Z"}
1618677818.633694: {"type":"l2update","product_id":"SKL-USD","changes":[["buy","0.7903","2239.0"]],"time":"2021-04-17T16:43:38.643593Z"}
1618677818.633794: {"type":"l2update","product_id":"SKL-USD","changes":[["sell","0.7923","0.0"]],"time":"2021-04-17T16:43:38.647410Z"}
1618677818.637698: {"type":"l2update","product_id":"SKL-USD","changes":[["sell","0.8174","24915.4"]],"time":"2021-04-17T16:43:38.650563Z"}
1618677818.6377878: {"type":"l2update","product_id":"SKL-USD","changes":[["sell","0.7925","0.0"]],"time":"2021-04-17T16:43:38.653875Z"}
1618677818.640408: {"type":"l2update","product_id":"SKL-USD","changes":[["buy","0.7863","1325.6"]],"time":"2021-04-17T16:43:38.655902Z"}
1618677818.64346: {"type":"l2update","product_id":"NU-GBP","changes":[["buy","0.4348","1590.000000"]],"time":"2021-04-17T16:43:38.658311Z"}
1618677818.647358: {"type":"l2update","product_id":"SKL-USD","changes":[["sell","0.7922","0.0"]],"time":"2021-04-17T16:43:38.659386Z"}
1618677818.64743: {"type":"l2update","product_id":"SKL-BTC","changes":[["buy","0.00001302","6075.8"]],"time":"2021-04-17T16:43:38.658707Z"}
1618677818.647467: {"type":"l2update","product_id":"SKL-USD","changes":[["sell","0.7942","5.0"]],"time":"2021-04-17T16:43:38.661868Z"}
1618677818.647855: {"type":"l2update","product_id":"SKL-BTC","changes":[["buy","0.00001305","110.0"]],"time":"2021-04-17T16:43:38.662477Z"}
1618677818.650153: {"type":"l2update","product_id":"NU-GBP","changes":[["buy","0.4365","10.000000"]],"time":"2021-04-17T16:43:38.665974Z"}
1618677818.654468: {"type":"l2update","product_id":"SKL-BTC","changes":[["sell","0.00001309","6455.5"]],"time":"2021-04-17T16:43:38.669050Z"}
1618677818.659051: {"type":"l2update","product_id":"SKL-USD","changes":[["sell","0.7943","7072.1"]],"time":"2021-04-17T16:43:38.673525Z"}
1618677818.6666229: {"type":"l2update","product_id":"SKL-USD","changes":[["buy","0.7875","27413.9"]],"time":"2021-04-17T16:43:38.680915Z"}
1618677818.671113: {"type":"l2update","product_id":"SKL-USD","changes":[["sell","0.7940","29765.1"]],"time":"2021-04-17T16:43:38.684741Z"}
1618677818.6712: {"type":"l2update","product_id":"SKL-BTC","changes":[["sell","0.00001311","4013.4"]],"time":"2021-04-17T16:43:38.684976Z"}
1618677818.671901: {"type":"l2update","product_id":"SKL-BTC","changes":[["sell","0.00001308","7250.4"]],"time":"2021-04-17T16:43:38.688398Z"}
1618677818.673002: {"type":"l2update","product_id":"YFI-BTC","changes":[["buy","0.82479","0.046386"]],"time":"2021-04-17T16:43:38.688998Z"}
1618677818.677262: {"type":"l2update","product_id":"SKL-BTC","changes":[["sell","0.00001314","7535.6"]],"time":"2021-04-17T16:43:38.692315Z"}
1618677818.6826482: {"type":"l2update","product_id":"YFI-BTC","changes":[["sell","0.82865","0.007917"]],"time":"2021-04-17T16:43:38.698889Z"}
1618677818.688022: {"type":"l2update","product_id":"YFI-BTC","changes":[["buy","0.82503","0.048117"]],"time":"2021-04-17T16:43:38.703056Z"}
1618677818.68811: {"type":"l2update","product_id":"DASH-BTC","changes":[["sell","0.00620532","0.00000000"]],"time":"2021-04-17T16:43:38.705365Z"}
1618677818.6912498: {"type":"l2update","product_id":"SKL-USD","changes":[["sell","0.7925","2629.2"]],"time":"2021-04-17T16:43:38.707028Z"}
1618677818.692155: {"type":"l2update","product_id":"CRV-EUR","changes":[["sell","3.3198","0.00"]],"time":"2021-04-17T16:43:38.709335Z"}
1618677818.692259: {"type":"l2update","product_id":"CRV-EUR","changes":[["buy","3.2707","0.00"]],"time":"2021-04-17T16:43:38.709335Z"}
1618677818.696398: {"type":"l2update","product_id":"BAND-BTC","changes":[["buy","0.00033434","22.00"]],"time":"2021-04-17T16:43:38.710967Z"}
1618677818.696501: {"type":"l2update","product_id":"DASH-BTC","changes":[["sell","0.00620702","0.00000000"]],"time":"2021-04-17T16:43:38.713764Z"}
1618677818.704036: {"type":"l2update","product_id":"CRV-EUR","changes":[["buy","3.2698","100.50"]],"time":"2021-04-17T16:43:38.718074Z"}
1618677818.7041228: {"type":"l2update","product_id":"CRV-EUR","changes":[["buy","3.2699","2.50"]],"time":"2021-04-17T16:43:38.718074Z"}
1618677818.704185: {"type":"l2update","product_id":"CRV-EUR","changes":[["buy","3.2697","74.50"]],"time":"2021-04-17T16:43:38.718074Z"}
1618677818.704227: {"type":"l2update","product_id":"CRV-EUR","changes":[["sell","3.3201","384.50"]],"time":"2021-04-17T16:43:38.718074Z"}
1618677818.7286022: {"type":"l2update","product_id":"DASH-BTC","changes":[["sell","0.00620124","0.00000000"]],"time":"2021-04-17T16:43:38.745803Z"}
1618677818.74455: {"type":"l2update","product_id":"DASH-BTC","changes":[["buy","0.00618212","5.56400000"]],"time":"2021-04-17T16:43:38.752571Z"}
1618677818.753047: {"type":"l2update","product_id":"DASH-BTC","changes":[["sell","0.00620530","2.57100000"]],"time":"2021-04-17T16:43:38.768096Z"}
1618677818.771174: {"type":"l2update","product_id":"DASH-BTC","changes":[["sell","0.00621781","10.41900000"]],"time":"2021-04-17T16:43:38.772113Z"}
1618677818.771311: {"type":"l2update","product_id":"YFI-BTC","changes":[["sell","0.82937","0.000000"]],"time":"2021-04-17T16:43:38.775823Z"}
1618677818.771382: {"type":"l2update","product_id":"SKL-USD","changes":[["buy","0.7904","1856.2"]],"time":"2021-04-17T16:43:38.779014Z"}
1618677818.771428: {"type":"l2update","product_id":"SKL-BTC","changes":[["sell","0.00001309","5552.4"]],"time":"2021-04-17T16:43:38.782958Z"}
1618677818.771466: {"type":"l2update","product_id":"SKL-BTC","changes":[["buy","0.00001301","19729.6"]],"time":"2021-04-17T16:43:38.782958Z"}
1618677818.771785: {"type":"l2update","product_id":"SKL-USD","changes":[["sell","0.7940","5.0"]],"time":"2021-04-17T16:43:38.789604Z"}
1618677818.778909: {"type":"l2update","product_id":"CRV-EUR","changes":[["buy","3.2953","0.00"]],"time":"2021-04-17T16:43:38.792248Z"}
1618677818.779019: {"type":"l2update","product_id":"DASH-BTC","changes":[["buy","0.00619149","0.00000000"]],"time":"2021-04-17T16:43:38.792552Z"}
1618677818.7790852: {"type":"l2update","product_id":"BAND-BTC","changes":[["sell","0.00033538","123.14"]],"time":"2021-04-17T16:43:38.793705Z"}
1618677818.779145: {"type":"l2update","product_id":"SKL-BTC","changes":[["buy","0.00001303","8397.8"]],"time":"2021-04-17T16:43:38.794036Z"}
1618677818.779186: {"type":"l2update","product_id":"DASH-BTC","changes":[["sell","0.00620621","0.00000000"]],"time":"2021-04-17T16:43:38.794488Z"}
1618677818.779232: {"type":"l2update","product_id":"SKL-BTC","changes":[["sell","0.00001310","8175.7"]],"time":"2021-04-17T16:43:38.794036Z"}
1618677818.785248: {"type":"l2update","product_id":"BAND-GBP","changes":[["sell","14.7995","0.00"]],"time":"2021-04-17T16:43:38.798519Z"}
1618677818.788547: {"type":"l2update","product_id":"DASH-BTC","changes":[["sell","0.00620128","0.00000000"]],"time":"2021-04-17T16:43:38.804287Z"}
1618677818.788682: {"type":"l2update","product_id":"BAND-GBP","changes":[["buy","14.7731","12.27"]],"time":"2021-04-17T16:43:38.804812Z"}
1618677818.788749: {"type":"l2update","product_id":"YFI-BTC","changes":[["sell","0.83213","0.000000"]],"time":"2021-04-17T16:43:38.804929Z"}
1618677818.788806: {"type":"l2update","product_id":"DASH-BTC","changes":[["buy","0.00618761","10.38400000"]],"time":"2021-04-17T16:43:38.805004Z"}
1618677818.790336: {"type":"l2update","product_id":"CRV-EUR","changes":[["sell","3.3040","0.00"]],"time":"2021-04-17T16:43:38.807189Z"}
1618677818.790402: {"type":"l2update","product_id":"CRV-EUR","changes":[["buy","3.2875","0.00"]],"time":"2021-04-17T16:43:38.807352Z"}
1618677818.7937868: {"type":"l2update","product_id":"DASH-BTC","changes":[["sell","0.00620622","0.00000000"]],"time":"2021-04-17T16:43:38.809324Z"}
1618677818.793896: {"type":"l2update","product_id":"SKL-USD","changes":[["sell","0.7942","29765.1"]],"time":"2021-04-17T16:43:38.809312Z"}
1618677818.799948: {"type":"l2update","product_id":"CRV-EUR","changes":[["buy","3.2966","140.93"]],"time":"2021-04-17T16:43:38.812092Z"}
1618677818.800087: {"type":"l2update","product_id":"CRV-EUR","changes":[["buy","3.2975","0.00"]],"time":"2021-04-17T16:43:38.815608Z"}
1618677818.8001559: {"type":"l2update","product_id":"BAND-GBP","changes":[["sell","14.8027","12.25"]],"time":"2021-04-17T16:43:38.815309Z"}
1618677818.800211: {"type":"l2update","product_id":"CRV-EUR","changes":[["buy","3.2983","96.87"]],"time":"2021-04-17T16:43:38.815773Z"}
1618677818.8023329: {"type":"l2update","product_id":"DASH-BTC","changes":[["sell","0.00621157","2.62500000"]],"time":"2021-04-17T16:43:38.819076Z"}
1618677818.8054342: {"type":"l2update","product_id":"YFI-BTC","changes":[["sell","0.83278","0.075600"]],"time":"2021-04-17T16:43:38.819411Z"}
1618677818.805571: {"type":"l2update","product_id":"SKL-BTC","changes":[["buy","0.00001305","0.0"]],"time":"2021-04-17T16:43:38.819488Z"}
1618677818.8120809: {"type":"l2update","product_id":"CRV-EUR","changes":[["sell","3.3118","0.00"]],"time":"2021-04-17T16:43:38.822997Z"}
1618677818.8121831: {"type":"l2update","product_id":"CRV-EUR","changes":[["buy","3.2858","0.00"]],"time":"2021-04-17T16:43:38.823542Z"}
1618677818.812245: {"type":"l2update","product_id":"CRV-EUR","changes":[["buy","3.2903","140.93"]],"time":"2021-04-17T16:43:38.826231Z"}
1618677818.819711: {"type":"l2update","product_id":"CRV-EUR","changes":[["sell","3.3027","140.93"]],"time":"2021-04-17T16:43:38.830605Z"}
1618677818.830647: {"type":"l2update","product_id":"DASH-BTC","changes":[["sell","0.00621781","12.65500000"]],"time":"2021-04-17T16:43:38.841682Z"}
1618677818.830768: {"type":"l2update","product_id":"CRV-EUR","changes":[["sell","3.3091","140.93"]],"time":"2021-04-17T16:43:38.845023Z"}
1618677818.834773: {"type":"l2update","product_id":"SKL-BTC","changes":[["sell","0.00001308","7354.3"]],"time":"2021-04-17T16:43:38.848898Z"}
1618677818.844595: {"type":"l2update","product_id":"DASH-BTC","changes":[["sell","0.00620123","0.00000000"]],"time":"2021-04-17T16:43:38.854166Z"}
1618677818.913603: {"type":"l2update","product_id":"CRV-EUR","changes":[["buy","3.2965","5000.00"]],"time":"2021-04-17T16:43:38.871556Z"}
1618677818.913743: {"type":"l2update","product_id":"DASH-BTC","changes":[["sell","0.00620531","0.00000000"]],"time":"2021-04-17T16:43:38.875725Z"}
1618677818.913815: {"type":"l2update","product_id":"DASH-BTC","changes":[["sell","0.00621011","0.00000000"]],"time":"2021-04-17T16:43:38.888140Z"}
1618677818.913866: {"type":"l2update","product_id":"CRV-EUR","changes":[["buy","3.2961","0.00"]],"time":"2021-04-17T16:43:38.894138Z"}
1618677818.913912: {"type":"l2update","product_id":"CRV-EUR","changes":[["buy","3.2878","256.26"]],"time":"2021-04-17T16:43:38.896703Z"}
1618677818.9139562: {"type":"l2update","product_id":"DASH-BTC","changes":[["sell","0.00620127","1.09000000"]],"time":"2021-04-17T16:43:38.896796Z"}
1618677818.914031: {"type":"l2update","product_id":"SKL-BTC","changes":[["sell","0.00001308","4717.8"]],"time":"2021-04-17T16:43:38.902029Z"}
1618677818.9140549: {"type":"l2update","product_id":"DASH-BTC","changes":[["sell","0.00621780","1.62300000"]],"time":"2021-04-17T16:43:38.907357Z"}
1618677818.914081: {"type":"l2update","product_id":"DASH-BTC","changes":[["sell","0.00621368","0.90000000"]],"time":"2021-04-17T16:43:38.907522Z"}
1618677818.9141061: {"type":"l2update","product_id":"SKL-USD","changes":[["sell","0.7941","5363.1"]],"time":"2021-04-17T16:43:38.914468Z"}
1618677818.9141278: {"type":"l2update","product_id":"DASH-BTC","changes":[["sell","0.00621780","3.24600000"]],"time":"2021-04-17T16:43:38.918343Z"}
1618677818.918058: {"type":"l2update","product_id":"SKL-USD","changes":[["buy","0.7904","989.7"]],"time":"2021-04-17T16:43:38.933581Z"}
1618677818.930965: {"type":"l2update","product_id":"SKL-USD","changes":[["sell","0.7929","1029.1"]],"time":"2021-04-17T16:43:38.946969Z"}
1618677818.942631: {"type":"l2update","product_id":"SKL-USD","changes":[["sell","0.8081","12005.0"]],"time":"2021-04-17T16:43:38.957616Z"}
1618677818.94272: {"type":"l2update","product_id":"SKL-USD","changes":[["buy","0.7908","1316.1"]],"time":"2021-04-17T16:43:38.957810Z"}
1618677818.945987: {"type":"l2update","product_id":"YFI-BTC","changes":[["buy","0.82550","0.000464"]],"time":"2021-04-17T16:43:38.961629Z"}
1618677818.950901: {"type":"l2update","product_id":"DASH-BTC","changes":[["buy","0.00618957","0.00000000"]],"time":"2021-04-17T16:43:38.965621Z"}
1618677818.957608: {"type":"l2update","product_id":"SKL-USD","changes":[["buy","0.7903","1044.7"]],"time":"2021-04-17T16:43:38.973379Z"}
1618677818.966364: {"type":"l2update","product_id":"DASH-BTC","changes":[["sell","0.00621368","6.91700000"]],"time":"2021-04-17T16:43:38.976899Z"}
1618677818.966482: {"type":"l2update","product_id":"DASH-BTC","changes":[["buy","0.00618958","2.66200000"]],"time":"2021-04-17T16:43:38.981635Z"}
1618677818.97061: {"type":"l2update","product_id":"DASH-BTC","changes":[["buy","0.00618958","1.12000000"]],"time":"2021-04-17T16:43:38.984797Z"}
1618677818.9712698: {"type":"l2update","product_id":"DASH-BTC","changes":[["buy","0.00618958","0.00000000"]],"time":"2021-04-17T16:43:38.988305Z"}
1618677818.982342: {"type":"l2update","product_id":"SKL-USD","changes":[["buy","0.7906","1193.9"]],"time":"2021-04-17T16:43:38.998369Z"}
1618677818.989563: {"type":"l2update","product_id":"DASH-BTC","changes":[["buy","0.00618762","0.03000000"]],"time":"2021-04-17T16:43:39.002281Z"}
1618677818.98963: {"type":"l2update","product_id":"DASH-BTC","changes":[["sell","0.00620277","5.56100000"]],"time":"2021-04-17T16:43:39.005623Z"}
1618677818.9916391: {"type":"l2update","product_id":"SKL-BTC","changes":[["sell","0.00001308","4058.2"]],"time":"2021-04-17T16:43:39.008780Z"}
1618677818.997491: {"type":"l2update","product_id":"DASH-BTC","changes":[["buy","0.00619214","2.57100000"]],"time":"2021-04-17T16:43:39.012789Z"}
1618677818.997558: {"type":"l2update","product_id":"DASH-BTC","changes":[["buy","0.00618762","1.57300000"]],"time":"2021-04-17T16:43:39.012837Z"}
1618677818.997586: {"type":"l2update","product_id":"YFI-BTC","changes":[["buy","0.82314","0.000000"]],"time":"2021-04-17T16:43:39.013975Z"}
1618677819.0047739: {"type":"l2update","product_id":"YFI-BTC","changes":[["buy","0.82192","0.009950"]],"time":"2021-04-17T16:43:39.019664Z"}
1618677819.009251: {"type":"l2update","product_id":"DASH-BTC","changes":[["buy","0.00618762","2.69300000"]],"time":"2021-04-17T16:43:39.024433Z"}
1618677819.0099368: {"type":"l2update","product_id":"SKL-BTC","changes":[["sell","0.00001309","2918.1"]],"time":"2021-04-17T16:43:39.027391Z"}
1618677819.020066: {"type":"l2update","product_id":"SKL-USD","changes":[["buy","0.7885","0.0"]],"time":"2021-04-17T16:43:39.036305Z"}
1618677819.022409: {"type":"l2update","product_id":"SKL-BTC","changes":[["buy","0.00001301","16498.2"]],"time":"2021-04-17T16:43:39.038878Z"}
1618677819.022959: {"type":"l2update","product_id":"SKL-BTC","changes":[["sell","0.00001312","1499.0"]],"time":"2021-04-17T16:43:39.040737Z"}
1618677819.029678: {"type":"l2update","product_id":"SKL-BTC","changes":[["sell","0.00001739","215.9"]],"time":"2021-04-17T16:43:39.045986Z"}
1618677819.047874: {"type":"l2update","product_id":"SKL-GBP","changes":[["buy","0.5747","55.0"]],"time":"2021-04-17T16:43:39.060959Z"}
1618677819.047971: {"type":"l2update","product_id":"SKL-GBP","changes":[["buy","0.5743","165.0"]],"time":"2021-04-17T16:43:39.060959Z"}
1618677819.051191: {"type":"l2update","product_id":"SKL-GBP","changes":[["buy","0.5746","0.0"]],"time":"2021-04-17T16:43:39.067422Z"}
1618677819.059726: {"type":"l2update","product_id":"SKL-GBP","changes":[["buy","0.5748","1028.4"]],"time":"2021-04-17T16:43:39.071731Z"}
1618677819.071968: {"type":"l2update","product_id":"SKL-USD","changes":[["buy","0.7904","0.0"]],"time":"2021-04-17T16:43:39.087313Z"}
1618677819.076233: {"type":"l2update","product_id":"BAND-BTC","changes":[["buy","0.00033448","189.09"]],"time":"2021-04-17T16:43:39.090174Z"}
1618677819.076328: {"type":"l2update","product_id":"BAND-BTC","changes":[["buy","0.00033398","0.00"]],"time":"2021-04-17T16:43:39.090335Z"}
1618677819.0763981: {"type":"l2update","product_id":"BAND-BTC","changes":[["sell","0.00033524","0.00"]],"time":"2021-04-17T16:43:39.090616Z"}
1618677819.0764532: {"type":"l2update","product_id":"SKL-BTC","changes":[["buy","0.00001303","7412.3"]],"time":"2021-04-17T16:43:39.090803Z"}
1618677819.0815392: {"type":"l2update","product_id":"BAND-GBP","changes":[["sell","14.8027","0.00"]],"time":"2021-04-17T16:43:39.092271Z"}
1618677819.081666: {"type":"l2update","product_id":"BAND-GBP","changes":[["buy","14.7594","0.00"]],"time":"2021-04-17T16:43:39.093276Z"}
1618677819.0817091: {"type":"l2update","product_id":"SKL-USD","changes":[["sell","0.7925","3646.7"]],"time":"2021-04-17T16:43:39.094031Z"}
1618677819.0817401: {"type":"l2update","product_id":"SKL-BTC","changes":[["sell","0.00001309","5554.3"]],"time":"2021-04-17T16:43:39.094329Z"}
1618677819.081766: {"type":"l2update","product_id":"BAND-GBP","changes":[["sell","14.8069","0.00"]],"time":"2021-04-17T16:43:39.094366Z"}
1618677819.081793: {"type":"l2update","product_id":"SKL-BTC","changes":[["sell","0.00001310","7356.8"]],"time":"2021-04-17T16:43:39.095337Z"}
1618677819.0886679: {"type":"l2update","product_id":"BAND-GBP","changes":[["buy","14.7473","0.00"]],"time":"2021-04-17T16:43:39.099205Z"}
1618677819.0887702: {"type":"l2update","product_id":"BAND-GBP","changes":[["buy","14.7772","12.67"]],"time":"2021-04-17T16:43:39.100530Z"}
1618677819.095281: {"type":"l2update","product_id":"SKL-BTC","changes":[["sell","0.00001308","4877.1"]],"time":"2021-04-17T16:43:39.105943Z"}
1618677819.0985348: {"type":"l2update","product_id":"SKL-USD","changes":[["sell","0.8082","6005.0"]],"time":"2021-04-17T16:43:39.112584Z"}
1618677819.107907: {"type":"l2update","product_id":"BAND-GBP","changes":[["sell","14.8174","11.78"]],"time":"2021-04-17T16:43:39.117219Z"}
1618677819.10802: {"type":"l2update","product_id":"CRV-EUR","changes":[["buy","3.2968","0.00"]],"time":"2021-04-17T16:43:39.119394Z"}
1618677819.1080902: {"type":"l2update","product_id":"SKL-BTC","changes":[["buy","0.00001301","17483.7"]],"time":"2021-04-17T16:43:39.120347Z"}
1618677819.108136: {"type":"l2update","product_id":"DASH-BTC","changes":[["buy","0.00451008","3.26000000"]],"time":"2021-04-17T16:43:39.121188Z"}
1618677819.108177: {"type":"l2update","product_id":"DASH-BTC","changes":[["buy","0.00450006","0.00000000"]],"time":"2021-04-17T16:43:39.121188Z"}
1618677819.108224: {"type":"l2update","product_id":"DASH-BTC","changes":[["sell","0.00864891","2.84000000"]],"time":"2021-04-17T16:43:39.121188Z"}
1618677819.1210501: {"type":"l2update","product_id":"BAND-BTC","changes":[["sell","0.00033537","36.72"]],"time":"2021-04-17T16:43:39.136230Z"}
1618677819.121154: {"type":"l2update","product_id":"BAND-GBP","changes":[["buy","14.7660","123.72"]],"time":"2021-04-17T16:43:39.136325Z"}
1618677819.142368: {"type":"l2update","product_id":"SKL-BTC","changes":[["sell","0.00001308","8664.6"]],"time":"2021-04-17T16:43:39.157581Z"}
1618677819.150761: {"type":"l2update","product_id":"DASH-BTC","changes":[["sell","0.00621781","10.41900000"]],"time":"2021-04-17T16:43:39.165859Z"}
1618677819.1522691: {"type":"l2update","product_id":"SKL-BTC","changes":[["buy","0.00001303","11199.8"]],"time":"2021-04-17T16:43:39.168476Z"}
1618677819.152359: {"type":"l2update","product_id":"SKL-BTC","changes":[["sell","0.00001307","2002.9"]],"time":"2021-04-17T16:43:39.168512Z"}
1618677819.1770282: {"type":"l2update","product_id":"BAND-GBP","changes":[["buy","14.7066","7.70"]],"time":"2021-04-17T16:43:39.177133Z"}
1618677819.1771462: {"type":"l2update","product_id":"BAND-GBP","changes":[["buy","14.7067","16.80"]],"time":"2021-04-17T16:43:39.177133Z"}
1618677819.1771991: {"type":"l2update","product_id":"SKL-BTC","changes":[["sell","0.00001308","7555.5"]],"time":"2021-04-17T16:43:39.176048Z"}
1618677819.1772501: {"type":"l2update","product_id":"BAND-GBP","changes":[["buy","14.7065","0.00"]],"time":"2021-04-17T16:43:39.177133Z"}
1618677819.177313: {"type":"l2update","product_id":"BAND-GBP","changes":[["buy","14.7068","0.00"]],"time":"2021-04-17T16:43:39.177133Z"}
1618677819.177341: {"type":"l2update","product_id":"BAND-GBP","changes":[["buy","14.7066","0.00"]],"time":"2021-04-17T16:43:39.177133Z"}
1618677819.177366: {"type":"l2update","product_id":"BAND-GBP","changes":[["buy","14.7067","0.00"]],"time":"2021-04-17T16:43:39.177133Z"}
1618677819.177391: {"type":"l2update","product_id":"BAND-GBP","changes":[["buy","14.6701","0.00"]],"time":"2021-04-17T16:43:39.177133Z"}
1618677819.1774158: {"type":"l2update","product_id":"BAND-GBP","changes":[["buy","14.7699","27.51"]],"time":"2021-04-17T16:43:39.180467Z"}
1618677819.177438: {"type":"l2update","product_id":"SKL-GBP","changes":[["buy","0.5744","1267.5"]],"time":"2021-04-17T16:43:39.183758Z"}
1618677819.1774678: {"type":"l2update","product_id":"BAND-GBP","changes":[["buy","14.7474","14.00"]],"time":"2021-04-17T16:43:39.186899Z"}
1618677819.177494: {"type":"l2update","product_id":"BAND-GBP","changes":[["buy","14.6484","16.20"]],"time":"2021-04-17T16:43:39.186899Z"}
1618677819.177515: {"type":"l2update","product_id":"BAND-GBP","changes":[["buy","14.6485","13.00"]],"time":"2021-04-17T16:43:39.186899Z"}
1618677819.1775382: {"type":"l2update","product_id":"BAND-GBP","changes":[["buy","14.6483","20.80"]],"time":"2021-04-17T16:43:39.186899Z"}
1618677819.1864388: {"type":"l2update","product_id":"CRV-EUR","changes":[["buy","3.2983","216.87"]],"time":"2021-04-17T16:43:39.190525Z"}
1618677819.18656: {"type":"l2update","product_id":"DASH-BTC","changes":[["sell","0.00621156","2.23600000"]],"time":"2021-04-17T16:43:39.191169Z"}
1618677819.186635: {"type":"l2update","product_id":"YFI-BTC","changes":[["sell","0.82701","0.000000"]],"time":"2021-04-17T16:43:39.197871Z"}
1618677819.186696: {"type":"l2update","product_id":"YFI-BTC","changes":[["buy","0.81817","0.000010"]],"time":"2021-04-17T16:43:39.198724Z"}
1618677819.1867352: {"type":"l2update","product_id":"YFI-BTC","changes":[["buy","0.80957","0.000000"]],"time":"2021-04-17T16:43:39.198724Z"}
1618677819.18678: {"type":"l2update","product_id":"SKL-USD","changes":[["buy","0.7878","3777.0"]],"time":"2021-04-17T16:43:39.200058Z"}
1618677819.21897: {"type":"l2update","product_id":"YFI-BTC","changes":[["buy","0.82540","0.112016"]],"time":"2021-04-17T16:43:39.205990Z"}
1618677819.219091: {"type":"l2update","product_id":"DASH-BTC","changes":[["buy","0.00619187","2.70000000"]],"time":"2021-04-17T16:43:39.206007Z"}
1618677819.2191648: {"type":"l2update","product_id":"SKL-BTC","changes":[["sell","0.00001307","893.8"]],"time":"2021-04-17T16:43:39.208212Z"}
1618677819.2192278: {"type":"l2update","product_id":"SKL-BTC","changes":[["buy","0.00001300","10470.1"]],"time":"2021-04-17T16:43:39.209558Z"}
1618677819.219254: {"type":"l2update","product_id":"YFI-BTC","changes":[["buy","0.82437","0.053045"]],"time":"2021-04-17T16:43:39.213042Z"}
1618677819.2192829: {"type":"l2update","product_id":"YFI-BTC","changes":[["buy","0.82274","0.063654"]],"time":"2021-04-17T16:43:39.213042Z"}
1618677819.219305: {"type":"l2update","product_id":"YFI-BTC","changes":[["buy","0.82188","0.076385"]],"time":"2021-04-17T16:43:39.213042Z"}
1618677819.219326: {"type":"l2update","product_id":"YFI-BTC","changes":[["buy","0.82062","0.091662"]],"time":"2021-04-17T16:43:39.213042Z"}
1618677819.2193458: {"type":"l2update","product_id":"YFI-BTC","changes":[["buy","0.81941","0.109994"]],"time":"2021-04-17T16:43:39.213042Z"}
1618677819.2193658: {"type":"l2update","product_id":"SKL-USD","changes":[["buy","0.7889","0.0"]],"time":"2021-04-17T16:43:39.214176Z"}
1618677819.219399: {"type":"l2update","product_id":"YFI-BTC","changes":[["sell","0.82937","0.000493"]],"time":"2021-04-17T16:43:39.213042Z"}
1618677819.219428: {"type":"l2update","product_id":"DASH-BTC","changes":[["sell","0.00620127","0.00000000"]],"time":"2021-04-17T16:43:39.219362Z"}
1618677819.219459: {"type":"l2update","product_id":"BAND-BTC","changes":[["buy","0.00033449","62.73"]],"time":"2021-04-17T16:43:39.220663Z"}
1618677819.219481: {"type":"l2update","product_id":"DASH-BTC","changes":[["sell","0.00621780","1.62300000"]],"time":"2021-04-17T16:43:39.222893Z"}
1618677819.2195032: {"type":"l2update","product_id":"DASH-BTC","changes":[["sell","0.00621781","0.00000000"]],"time":"2021-04-17T16:43:39.226727Z"}
1618677819.2232351: {"type":"l2update","product_id":"DASH-BTC","changes":[["sell","0.00620180","1.09000000"]],"time":"2021-04-17T16:43:39.238325Z"}
1618677819.2233: {"type":"l2update","product_id":"BAND-GBP","changes":[["sell","14.7981","0.00"]],"time":"2021-04-17T16:43:39.239334Z"}
1618677819.236358: {"type":"l2update","product_id":"BAND-GBP","changes":[["buy","14.7661","36.00"]],"time":"2021-04-17T16:43:39.245894Z"}
1618677819.236494: {"type":"l2update","product_id":"SKL-USD","changes":[["sell","0.7929","5.0"]],"time":"2021-04-17T16:43:39.246660Z"}
1618677819.2365482: {"type":"l2update","product_id":"DASH-BTC","changes":[["sell","0.00620845","1.62300000"]],"time":"2021-04-17T16:43:39.249249Z"}
1618677819.238902: {"type":"l2update","product_id":"SKL-USD","changes":[["buy","0.7904","867.1"]],"time":"2021-04-17T16:43:39.253544Z"}
1618677819.241211: {"type":"l2update","product_id":"DASH-BTC","changes":[["buy","0.00618736","0.00000000"]],"time":"2021-04-17T16:43:39.255272Z"}
1618677819.2432861: {"type":"l2update","product_id":"SKL-BTC","changes":[["sell","0.00001310","9991.7"]],"time":"2021-04-17T16:43:39.256916Z"}
1618677819.246895: {"type":"l2update","product_id":"SKL-USD","changes":[["sell","0.8081","6005.0"]],"time":"2021-04-17T16:43:39.261304Z"}
1618677819.246984: {"type":"l2update","product_id":"DASH-BTC","changes":[["sell","0.00620427","2.68900000"]],"time":"2021-04-17T16:43:39.261898Z"}
1618677819.257431: {"type":"l2update","product_id":"SKL-USD","changes":[["sell","0.8082","12005.0"]],"time":"2021-04-17T16:43:39.269437Z"}
1618677819.257515: {"type":"l2update","product_id":"NMR-EUR","changes":[["buy","66.4807","1.231"]],"time":"2021-04-17T16:43:39.273222Z"}
1618677819.269071: {"type":"l2update","product_id":"DASH-BTC","changes":[["sell","0.00621781","10.45600000"]],"time":"2021-04-17T16:43:39.276838Z"}
1618677819.2692149: {"type":"l2update","product_id":"BAND-BTC","changes":[["buy","0.00033406","102.88"]],"time":"2021-04-17T16:43:39.284616Z"}
1618677819.278791: {"type":"l2update","product_id":"SKL-BTC","changes":[["sell","0.00001308","8214.5"]],"time":"2021-04-17T16:43:39.289962Z"}
1618677819.292543: {"type":"l2update","product_id":"SKL-USD","changes":[["buy","0.7905","0.0"]],"time":"2021-04-17T16:43:39.307379Z"}
1618677819.292654: {"type":"l2update","product_id":"SKL-USD","changes":[["sell","0.8057","99.8"]],"time":"2021-04-17T16:43:39.308721Z"}
1618677819.2927082: {"type":"l2update","product_id":"SKL-USD","changes":[["sell","0.8058","5.0"]],"time":"2021-04-17T16:43:39.308721Z"}
1618677819.2988338: {"type":"l2update","product_id":"SKL-USD","changes":[["sell","0.7997","1830.0"]],"time":"2021-04-17T16:43:39.314194Z"}
1618677819.29892: {"type":"l2update","product_id":"SKL-USD","changes":[["sell","0.7996","15.0"]],"time":"2021-04-17T16:43:39.314194Z"}
1618677819.303352: {"type":"l2update","product_id":"SKL-USD","changes":[["buy","0.7875","1900.0"]],"time":"2021-04-17T16:43:39.314853Z"}
1618677819.303474: {"type":"l2update","product_id":"DASH-BTC","changes":[["sell","0.00622592","0.00000000"]],"time":"2021-04-17T16:43:39.314674Z"}
1618677819.303553: {"type":"l2update","product_id":"DASH-BTC","changes":[["buy","0.00614331","29.85800000"]],"time":"2021-04-17T16:43:39.319144Z"}
1618677819.321443: {"type":"l2update","product_id":"SKL-USD","changes":[["buy","0.7866","25513.9"]],"time":"2021-04-17T16:43:39.336091Z"}
1618677819.323869: {"type":"l2update","product_id":"DASH-BTC","changes":[["buy","0.00618762","2.66300000"]],"time":"2021-04-17T16:43:39.338479Z"}
1618677819.323959: {"type":"l2update","product_id":"CRV-EUR","changes":[["buy","3.2708","0.00"]],"time":"2021-04-17T16:43:39.339464Z"}
1618677819.32403: {"type":"l2update","product_id":"CRV-EUR","changes":[["buy","3.2697","0.50"]],"time":"2021-04-17T16:43:39.339464Z"}
1618677819.324074: {"type":"l2update","product_id":"NMR-EUR","changes":[["buy","66.4810","13.000"]],"time":"2021-04-17T16:43:39.339555Z"}
1618677819.330949: {"type":"l2update","product_id":"DASH-BTC","changes":[["buy","0.00618880","32.84700000"]],"time":"2021-04-17T16:43:39.340094Z"}
1618677819.331052: {"type":"l2update","product_id":"DASH-BTC","changes":[["buy","0.00618762","1.12000000"]],"time":"2021-04-17T16:43:39.342002Z"}
1618677819.3311071: {"type":"l2update","product_id":"CRV-EUR","changes":[["buy","3.2699","87.50"]],"time":"2021-04-17T16:43:39.343292Z"}
1618677819.335927: {"type":"l2update","product_id":"NU-GBP","changes":[["buy","0.4388","1659.222800"]],"time":"2021-04-17T16:43:39.347006Z"}
1618677819.336027: {"type":"l2update","product_id":"SKL-USD","changes":[["buy","0.7878","0.0"]],"time":"2021-04-17T16:43:39.353080Z"}
1618677819.33729: {"type":"l2update","product_id":"SKL-USD","changes":[["buy","0.7907","10129.3"]],"time":"2021-04-17T16:43:39.354202Z"}
1618677819.3445911: {"type":"l2update","product_id":"BAND-BTC","changes":[["buy","0.00033388","0.92"]],"time":"2021-04-17T16:43:39.358151Z"}
1618677819.344694: {"type":"l2update","product_id":"DASH-BTC","changes":[["buy","0.00619215","0.03000000"]],"time":"2021-04-17T16:43:39.358479Z"}
1618677819.3447511: {"type":"l2update","product_id":"BAND-BTC","changes":[["buy","0.00033405","21.00"]],"time":"2021-04-17T16:43:39.360846Z"}
1618677819.3447921: {"type":"l2update","product_id":"DASH-BTC","changes":[["sell","0.00620427","0.00000000"]],"time":"2021-04-17T16:43:39.360999Z"}
1618677819.348928: {"type":"l2update","product_id":"SKL-BTC","changes":[["buy","0.00001305","110.0"]],"time":"2021-04-17T16:43:39.361778Z"}
1618677819.349029: {"type":"l2update","product_id":"NU-GBP","changes":[["buy","0.4387","0.000000"]],"time":"2021-04-17T16:43:39.363496Z"}
1618677819.3545861: {"type":"l2update","product_id":"NU-GBP","changes":[["buy","0.4389","242.890000"]],"time":"2021-04-17T16:43:39.369117Z"}
1618677819.354687: {"type":"l2update","product_id":"SKL-BTC","changes":[["buy","0.00001300","10919.0"]],"time":"2021-04-17T16:43:39.369183Z"}
1618677819.357601: {"type":"l2update","product_id":"DASH-BTC","changes":[["buy","0.00619215","1.57200000"]],"time":"2021-04-17T16:43:39.372867Z"}
1618677819.362376: {"type":"l2update","product_id":"SKL-BTC","changes":[["buy","0.00001303","11759.8"]],"time":"2021-04-17T16:43:39.376899Z"}
1618677819.362466: {"type":"l2update","product_id":"SKL-USD","changes":[["buy","0.7906","0.0"]],"time":"2021-04-17T16:43:39.377639Z"}
1618677819.3625338: {"type":"l2update","product_id":"BAND-BTC","changes":[["buy","0.00033448","152.72"]],"time":"2021-04-17T16:43:39.377016Z"}
1618677819.36258: {"type":"l2update","product_id":"NU-GBP","changes":[["buy","0.4388","0.000000"]],"time":"2021-04-17T16:43:39.378242Z"}
1618677819.374681: {"type":"l2update","product_id":"SKL-BTC","changes":[["sell","0.00001308","7395.6"]],"time":"2021-04-17T16:43:39.388088Z"}
1618677819.38549: {"type":"l2update","product_id":"SKL-BTC","changes":[["buy","0.00001303","12745.3"]],"time":"2021-04-17T16:43:39.400121Z"}
1618677819.385609: {"type":"l2update","product_id":"SKL-BTC","changes":[["sell","0.00001310","10810.6"]],"time":"2021-04-17T16:43:39.400121Z"}
1618677819.3928409: {"type":"l2update","product_id":"SKL-BTC","changes":[["buy","0.00001301","16498.2"]],"time":"2021-04-17T16:43:39.405203Z"}
1618677819.398245: {"type":"l2update","product_id":"SKL-USD","changes":[["sell","0.8082","6005.0"]],"time":"2021-04-17T16:43:39.412950Z"}
1618677819.401963: {"type":"l2update","product_id":"SKL-USD","changes":[["buy","0.7905","989.7"]],"time":"2021-04-17T16:43:39.414593Z"}
1618677819.405914: {"type":"l2update","product_id":"SKL-USD","changes":[["buy","0.7904","2061.3"]],"time":"2021-04-17T16:43:39.421954Z"}
1618677819.4209762: {"type":"l2update","product_id":"DASH-BTC","changes":[["buy","0.00614334","2.80000000"]],"time":"2021-04-17T16:43:39.434098Z"}
1618677819.42108: {"type":"l2update","product_id":"DASH-BTC","changes":[["buy","0.00614333","1.24000000"]],"time":"2021-04-17T16:43:39.434098Z"}
1618677819.421134: {"type":"l2update","product_id":"DASH-BTC","changes":[["sell","0.00621781","12.25600000"]],"time":"2021-04-17T16:43:39.434098Z"}
1618677819.4310899: {"type":"l2update","product_id":"NMR-EUR","changes":[["sell","67.0475","0.000"]],"time":"2021-04-17T16:43:39.442902Z"}
1618677819.4412081: {"type":"l2update","product_id":"DASH-BTC","changes":[["sell","0.00620846","0.00000000"]],"time":"2021-04-17T16:43:39.453356Z"}
1618677819.445566: {"type":"l2update","product_id":"SKL-USD","changes":[["sell","0.7927","2525.7"]],"time":"2021-04-17T16:43:39.460176Z"}
1618677819.445674: {"type":"l2update","product_id":"BAND-BTC","changes":[["buy","0.00033290","19.15"]],"time":"2021-04-17T16:43:39.460603Z"}
1618677819.445737: {"type":"l2update","product_id":"DASH-BTC","changes":[["sell","0.00621781","1.80000000"]],"time":"2021-04-17T16:43:39.461475Z"}
1618677819.445781: {"type":"l2update","product_id":"SKL-USD","changes":[["sell","0.7926","0.0"]],"time":"2021-04-17T16:43:39.462328Z"}
1618677819.445834: {"type":"l2update","product_id":"SKL-USD","changes":[["buy","0.7830","0.0"]],"time":"2021-04-17T16:43:39.462328Z"}
1618677819.4458811: {"type":"l2update","product_id":"SKL-USD","changes":[["buy","0.7806","74248.1"]],"time":"2021-04-17T16:43:39.462328Z"}
1618677819.4496262: {"type":"l2update","product_id":"NMR-EUR","changes":[["sell","67.0228","6.274"]],"time":"2021-04-17T16:43:39.464413Z"}
1618677819.449729: {"type":"l2update","product_id":"DASH-BTC","changes":[["sell","0.00622922","29.91800000"]],"time":"2021-04-17T16:43:39.464524Z"}
1618677819.450443: {"type":"l2update","product_id":"BAND-GBP","changes":[["buy","14.6483","6.70"]],"time":"2021-04-17T16:43:39.466341Z"}
1618677819.451073: {"type":"l2update","product_id":"SKL-USD","changes":[["buy","0.7898","2524.8"]],"time":"2021-04-17T16:43:39.468127Z"}
1618677819.452964: {"type":"l2update","product_id":"NMR-EUR","changes":[["buy","66.3780","0.000"]],"time":"2021-04-17T16:43:39.468315Z"}
1618677819.4582348: {"type":"l2update","product_id":"BAND-GBP","changes":[["buy","14.6486","10.00"]],"time":"2021-04-17T16:43:39.472005Z"}
1618677819.458343: {"type":"l2update","product_id":"BAND-GBP","changes":[["buy","14.6485","17.10"]],"time":"2021-04-17T16:43:39.472005Z"}
1618677819.458394: {"type":"l2update","product_id":"BAND-BTC","changes":[["sell","0.00033526","18.13"]],"time":"2021-04-17T16:43:39.472718Z"}
1618677819.4605372: {"type":"l2update","product_id":"SKL-USD","changes":[["sell","0.7938","6316.9"]],"time":"2021-04-17T16:43:39.475627Z"}
1618677819.465133: {"type":"l2update","product_id":"SKL-USD","changes":[["sell","0.7929","23017.0"]],"time":"2021-04-17T16:43:39.475821Z"}
1618677819.465249: {"type":"l2update","product_id":"SKL-USD","changes":[["buy","0.7853","38292.5"]],"time":"2021-04-17T16:43:39.475821Z"}
1618677819.465301: {"type":"l2update","product_id":"SKL-USD","changes":[["buy","0.7861","6913.0"]],"time":"2021-04-17T16:43:39.475821Z"}
1618677819.469426: {"type":"l2update","product_id":"NMR-EUR","changes":[["buy","66.9196","0.000"]],"time":"2021-04-17T16:43:39.483944Z"}
1618677819.469564: {"type":"l2update","product_id":"NMR-EUR","changes":[["sell","67.0418","0.000"]],"time":"2021-04-17T16:43:39.483993Z"}
1618677819.469627: {"type":"l2update","product_id":"BAND-BTC","changes":[["sell","0.00033519","0.00"]],"time":"2021-04-17T16:43:39.484082Z"}
1618677819.4748778: {"type":"l2update","product_id":"DASH-BTC","changes":[["buy","0.00614334","9.78700000"]],"time":"2021-04-17T16:43:39.484458Z"}
1618677819.47497: {"type":"l2update","product_id":"NMR-EUR","changes":[["buy","66.4811","12.673"]],"time":"2021-04-17T16:43:39.484491Z"}
1618677819.475034: {"type":"l2update","product_id":"SKL-USD","changes":[["buy","0.7887","6313.7"]],"time":"2021-04-17T16:43:39.485042Z"}
1618677819.475085: {"type":"l2update","product_id":"SKL-BTC","changes":[["sell","0.00001307","0.0"]],"time":"2021-04-17T16:43:39.485396Z"}
1618677819.48133: {"type":"l2update","product_id":"BAND-BTC","changes":[["buy","0.00033448","123.11"]],"time":"2021-04-17T16:43:39.495541Z"}
1618677819.4855082: {"type":"l2update","product_id":"SKL-BTC","changes":[["sell","0.00001308","6736.6"]],"time":"2021-04-17T16:43:39.499105Z"}
1618677819.4855978: {"type":"l2update","product_id":"BAND-BTC","changes":[["buy","0.00033449","92.33"]],"time":"2021-04-17T16:43:39.498891Z"}
1618677819.485652: {"type":"l2update","product_id":"SKL-USD","changes":[["sell","0.7962","12635.2"]],"time":"2021-04-17T16:43:39.499238Z"}
1618677819.486343: {"type":"l2update","product_id":"BAND-BTC","changes":[["buy","0.00033407","39.00"]],"time":"2021-04-17T16:43:39.503946Z"}
1618677819.489175: {"type":"l2update","product_id":"SKL-BTC","changes":[["sell","0.00001308","7845.7"]],"time":"2021-04-17T16:43:39.504074Z"}
1618677819.490081: {"type":"l2update","product_id":"SKL-BTC","changes":[["buy","0.00001303","12083.3"]],"time":"2021-04-17T16:43:39.505935Z"}
1618677819.49017: {"type":"l2update","product_id":"NMR-EUR","changes":[["sell","67.0209","2.550"]],"time":"2021-04-17T16:43:39.506278Z"}
1618677819.494612: {"type":"l2update","product_id":"SKL-BTC","changes":[["buy","0.00001302","5159.0"]],"time":"2021-04-17T16:43:39.510224Z"}
1618677819.496862: {"type":"l2update","product_id":"SKL-USD","changes":[["buy","0.7880","3525.3"]],"time":"2021-04-17T16:43:39.510845Z"}
1618677819.496997: {"type":"l2update","product_id":"DASH-BTC","changes":[["sell","0.00621156","0.00000000"]],"time":"2021-04-17T16:43:39.511092Z"}
1618677819.49707: {"type":"l2update","product_id":"SKL-BTC","changes":[["buy","0.00001302","4493.3"]],"time":"2021-04-17T16:43:39.513539Z"}
1618677819.5098722: {"type":"l2update","product_id":"SKL-USD","changes":[["buy","0.7826","1660.0"]],"time":"2021-04-17T16:43:39.525458Z"}
1618677819.509961: {"type":"l2update","product_id":"SKL-USD","changes":[["buy","0.7855","8454.8"]],"time":"2021-04-17T16:43:39.525458Z"}
1618677819.5106618: {"type":"l2update","product_id":"SKL-BTC","changes":[["buy","0.00001304","2672.3"]],"time":"2021-04-17T16:43:39.526807Z"}
1618677819.5107489: {"type":"l2update","product_id":"NMR-EUR","changes":[["buy","66.8687","1.275"]],"time":"2021-04-17T16:43:39.526844Z"}
1618677819.51771: {"type":"l2update","product_id":"DASH-BTC","changes":[["sell","0.00621780","3.85900000"]],"time":"2021-04-17T16:43:39.532895Z"}
1618677819.517799: {"type":"l2update","product_id":"SKL-BTC","changes":[["sell","0.00001308","8739.1"]],"time":"2021-04-17T16:43:39.533135Z"}
1618677819.5178509: {"type":"l2update","product_id":"SKL-USD","changes":[["buy","0.7854","915.0"]],"time":"2021-04-17T16:43:39.533176Z"}
1618677819.5178938: {"type":"l2update","product_id":"SKL-USD","changes":[["buy","0.7832","296.2"]],"time":"2021-04-17T16:43:39.533176Z"}
1618677819.520801: {"type":"l2update","product_id":"SKL-BTC","changes":[["buy","0.00001303","12999.4"]],"time":"2021-04-17T16:43:39.536672Z"}
1618677819.520889: {"type":"l2update","product_id":"DASH-BTC","changes":[["sell","0.00621319","14.63200000"]],"time":"2021-04-17T16:43:39.536755Z"}
1618677819.534653: {"type":"l2update","product_id":"SKL-BTC","changes":[["buy","0.00001303","13664.6"]],"time":"2021-04-17T16:43:39.548153Z"}
1618677819.535192: {"type":"l2update","product_id":"SKL-BTC","changes":[["buy","0.00001303","12679.1"]],"time":"2021-04-17T16:43:39.551653Z"}
1618677819.544585: {"type":"l2update","product_id":"BAND-BTC","changes":[["sell","0.00033563","41.57"]],"time":"2021-04-17T16:43:39.561045Z"}
1618677819.55443: {"type":"l2update","product_id":"SKL-USD","changes":[["sell","0.7951","5.0"]],"time":"2021-04-17T16:43:39.566068Z"}
1618677819.5545118: {"type":"l2update","product_id":"DASH-BTC","changes":[["sell","0.00620845","0.00000000"]],"time":"2021-04-17T16:43:39.567511Z"}
1618677819.556362: {"type":"l2update","product_id":"SKL-USD","changes":[["sell","0.8080","6005.0"]],"time":"2021-04-17T16:43:39.569751Z"}
1618677819.556422: {"type":"l2update","product_id":"DASH-BTC","changes":[["sell","0.00621780","2.23600000"]],"time":"2021-04-17T16:43:39.571019Z"}
1618677819.5564559: {"type":"l2update","product_id":"NMR-EUR","changes":[["buy","66.8687","0.000"]],"time":"2021-04-17T16:43:39.570278Z"}
1618677819.5620108: {"type":"l2update","product_id":"SKL-GBP","changes":[["sell","0.5774","2526.1"]],"time":"2021-04-17T16:43:39.577547Z"}
1618677819.5669498: {"type":"l2update","product_id":"SKL-USD","changes":[["sell","0.8080","12005.0"]],"time":"2021-04-17T16:43:39.581246Z"}
1618677819.567005: {"type":"l2update","product_id":"SKL-GBP","changes":[["sell","0.5780","350.0"]],"time":"2021-04-17T16:43:39.583406Z"}
1618677819.5701308: {"type":"l2update","product_id":"DASH-BTC","changes":[["sell","0.00620710","2.62900000"]],"time":"2021-04-17T16:43:39.584785Z"}
1618677819.570197: {"type":"l2update","product_id":"YFI-BTC","changes":[["buy","0.81667","0.000000"]],"time":"2021-04-17T16:43:39.585190Z"}
1618677819.570241: {"type":"l2update","product_id":"YFI-BTC","changes":[["sell","0.82710","0.000000"]],"time":"2021-04-17T16:43:39.585307Z"}
1618677819.573421: {"type":"l2update","product_id":"DASH-BTC","changes":[["sell","0.00621156","1.62300000"]],"time":"2021-04-17T16:43:39.588618Z"}
1618677819.573486: {"type":"l2update","product_id":"SKL-GBP","changes":[["sell","0.5780","6663.7"]],"time":"2021-04-17T16:43:39.588702Z"}
1618677819.573519: {"type":"l2update","product_id":"SKL-GBP","changes":[["sell","0.5774","3534.3"]],"time":"2021-04-17T16:43:39.588735Z"}
1618677819.57756: {"type":"l2update","product_id":"SKL-GBP","changes":[["sell","0.5783","0.0"]],"time":"2021-04-17T16:43:39.595125Z"}
1618677819.584036: {"type":"l2update","product_id":"SKL-GBP","changes":[["buy","0.5689","0.0"]],"time":"2021-04-17T16:43:39.596552Z"}
1618677819.584137: {"type":"l2update","product_id":"YFI-BTC","changes":[["sell","0.82669","0.000000"]],"time":"2021-04-17T16:43:39.596603Z"}
1618677819.584202: {"type":"l2update","product_id":"DASH-BTC","changes":[["sell","0.00620710","0.00000000"]],"time":"2021-04-17T16:43:39.597123Z"}
1618677819.584255: {"type":"l2update","product_id":"YFI-BTC","changes":[["buy","0.82552","0.019696"]],"time":"2021-04-17T16:43:39.599622Z"}
1618677819.584304: {"type":"l2update","product_id":"YFI-BTC","changes":[["buy","0.81739","0.127700"]],"time":"2021-04-17T16:43:39.599877Z"}
1618677819.584346: {"type":"l2update","product_id":"DASH-BTC","changes":[["sell","0.00621318","1.62300000"]],"time":"2021-04-17T16:43:39.599913Z"}
1618677819.599385: {"type":"l2update","product_id":"NMR-EUR","changes":[["buy","66.8885","1.275"]],"time":"2021-04-17T16:43:39.614294Z"}
1618677819.599521: {"type":"l2update","product_id":"SKL-GBP","changes":[["sell","0.5773","1735.0"]],"time":"2021-04-17T16:43:39.614665Z"}
1618677819.6215942: {"type":"l2update","product_id":"YFI-BTC","changes":[["sell","0.82668","0.000000"]],"time":"2021-04-17T16:43:39.637670Z"}
1618677819.623741: {"type":"l2update","product_id":"SKL-USD","changes":[["buy","0.7908","1686.1"]],"time":"2021-04-17T16:43:39.640207Z"}
1618677819.630183: {"type":"l2update","product_id":"YFI-BTC","changes":[["sell","0.82685","0.030000"]],"time":"2021-04-17T16:43:39.643714Z"}
1618677819.6334689: {"type":"l2update","product_id":"YFI-BTC","changes":[["buy","0.82479","0.000000"]],"time":"2021-04-17T16:43:39.646825Z"}
1618677819.633573: {"type":"l2update","product_id":"DASH-BTC","changes":[["buy","0.00618762","0.00000000"]],"time":"2021-04-17T16:43:39.647894Z"}
1618677819.63364: {"type":"l2update","product_id":"YFI-BTC","changes":[["sell","0.82686","0.000000"]],"time":"2021-04-17T16:43:39.647616Z"}
1618677819.6336918: {"type":"l2update","product_id":"SKL-GBP","changes":[["sell","0.5782","0.0"]],"time":"2021-04-17T16:43:39.649436Z"}
1618677819.6995862: {"type":"l2update","product_id":"YFI-BTC","changes":[["buy","0.82571","0.020214"]],"time":"2021-04-17T16:43:39.650668Z"}
1618677819.713784: {"type":"l2update","product_id":"YFI-BTC","changes":[["buy","0.82541","0.000000"]],"time":"2021-04-17T16:43:39.657018Z"}
1618677819.713921: {"type":"l2update","product_id":"YFI-BTC","changes":[["sell","0.82837","0.045869"]],"time":"2021-04-17T16:43:39.657377Z"}
1618677819.7218828: {"type":"l2update","product_id":"SKL-GBP","changes":[["buy","0.5720","500.0"]],"time":"2021-04-17T16:43:39.686904Z"}
1618677819.761678: {"type":"l2update","product_id":"SKL-USD","changes":[["buy","0.7880","0.0"]],"time":"2021-04-17T16:43:39.713562Z"}
1618677819.761813: {"type":"l2update","product_id":"DASH-BTC","changes":[["buy","0.00618953","1.12000000"]],"time":"2021-04-17T16:43:39.717009Z"}
1618677819.820669: {"type":"l2update","product_id":"NMR-EUR","changes":[["buy","66.8885","0.000"]],"time":"2021-04-17T16:43:39.759287Z"}
1618677819.842635: {"type":"l2update","product_id":"SKL-USD","changes":[["buy","0.7902","0.0"]],"time":"2021-04-17T16:43:39.774877Z"}
1618677819.878638: {"type":"l2update","product_id":"BAND-BTC","changes":[["sell","0.00033595","0.00"]],"time":"2021-04-17T16:43:39.804493Z"}
1618677819.87878: {"type":"l2update","product_id":"BAND-BTC","changes":[["buy","0.00033195","0.00"]],"time":"2021-04-17T16:43:39.804493Z"}
1618677819.878845: {"type":"l2update","product_id":"BAND-BTC","changes":[["buy","0.00033170","470.56"]],"time":"2021-04-17T16:43:39.804493Z"}
1618677819.878892: {"type":"l2update","product_id":"SKL-BTC","changes":[["sell","0.00001310","9991.7"]],"time":"2021-04-17T16:43:39.831691Z"}
1618677819.878933: {"type":"l2update","product_id":"BAND-BTC","changes":[["sell","0.00033560","9.70"]],"time":"2021-04-17T16:43:39.807788Z"}
1618677819.8789818: {"type":"l2update","product_id":"BAND-BTC","changes":[["buy","0.00033197","10.80"]],"time":"2021-04-17T16:43:39.807788Z"}
1618677819.879061: {"type":"l2update","product_id":"BAND-BTC","changes":[["buy","0.00033170","471.16"]],"time":"2021-04-17T16:43:39.807788Z"}
1618677819.8921971: {"type":"l2update","product_id":"CRV-EUR","changes":[["sell","3.3112","0.00"]],"time":"2021-04-17T16:43:39.856543Z"}
1618677819.955322: {"type":"l2update","product_id":"YFI-BTC","changes":[["sell","0.82685","0.000000"]],"time":"2021-04-17T16:43:39.858328Z"}
1618677819.966507: {"type":"l2update","product_id":"SKL-BTC","changes":[["sell","0.00001309","6213.3"]],"time":"2021-04-17T16:43:39.882165Z"}
1618677819.966609: {"type":"l2update","product_id":"YFI-BTC","changes":[["sell","0.82710","0.030000"]],"time":"2021-04-17T16:43:39.863996Z"}
1618677819.9922502: {"type":"l2update","product_id":"YFI-BTC","changes":[["buy","0.82553","0.017062"]],"time":"2021-04-17T16:43:39.913147Z"}
1618677819.992388: {"type":"l2update","product_id":"SKL-USD","changes":[["buy","0.7904","867.1"]],"time":"2021-04-17T16:43:39.938019Z"}
1618677819.992445: {"type":"l2update","product_id":"YFI-BTC","changes":[["buy","0.82507","0.046004"]],"time":"2021-04-17T16:43:39.937989Z"}
1618677820.0005682: {"type":"l2update","product_id":"DASH-BTC","changes":[["sell","0.00620530","0.00000000"]],"time":"2021-04-17T16:43:40.000205Z"}
1618677820.0037818: {"type":"l2update","product_id":"DASH-BTC","changes":[["sell","0.00620889","2.62100000"]],"time":"2021-04-17T16:43:40.000980Z"}
1618677820.0133839: {"type":"l2update","product_id":"DASH-BTC","changes":[["sell","0.00621780","0.00000000"]],"time":"2021-04-17T16:43:40.002984Z"}
1618677820.0216231: {"type":"l2update","product_id":"SKL-USD","changes":[["buy","0.7905","0.0"]],"time":"2021-04-17T16:43:40.004679Z"}
1618677820.021759: {"type":"l2update","product_id":"SKL-USD","changes":[["sell","0.8082","5.0"]],"time":"2021-04-17T16:43:40.004689Z"}
1618677820.021816: {"type":"l2update","product_id":"SKL-USD","changes":[["buy","0.7904","2213.0"]],"time":"2021-04-17T16:43:40.004742Z"}
1618677820.021858: {"type":"l2update","product_id":"YFI-BTC","changes":[["sell","0.82865","0.000000"]],"time":"2021-04-17T16:43:40.004059Z"}
1618677820.021909: {"type":"l2update","product_id":"CRV-EUR","changes":[["sell","3.3064","254.47"]],"time":"2021-04-17T16:43:40.005285Z"}
1618677820.0219588: {"type":"l2update","product_id":"CRV-EUR","changes":[["sell","3.3200","1416.00"]],"time":"2021-04-17T16:43:40.005560Z"}
1618677820.028173: {"type":"l2update","product_id":"SKL-BTC","changes":[["buy","0.00001304","3657.8"]],"time":"2021-04-17T16:43:40.028031Z"}
1618677820.028289: {"type":"l2update","product_id":"SKL-USD","changes":[["buy","0.7906","1193.9"]],"time":"2021-04-17T16:43:40.030247Z"}
1618677820.028836: {"type":"l2update","product_id":"CRV-EUR","changes":[["buy","3.2953","254.47"]],"time":"2021-04-17T16:43:40.034089Z"}
1618677820.031174: {"type":"l2update","product_id":"CRV-EUR","changes":[["sell","3.3043","5000.00"]],"time":"2021-04-17T16:43:40.040062Z"}
1618677820.031756: {"type":"l2update","product_id":"YFI-BTC","changes":[["sell","0.82837","0.053786"]],"time":"2021-04-17T16:43:40.040470Z"}
1618677820.031869: {"type":"l2update","product_id":"DASH-BTC","changes":[["sell","0.00620529","2.57000000"]],"time":"2021-04-17T16:43:40.041039Z"}
1618677820.036555: {"type":"l2update","product_id":"YFI-BTC","changes":[["buy","0.82063","0.013910"]],"time":"2021-04-17T16:43:40.044929Z"}
1618677820.03726: {"type":"l2update","product_id":"SKL-USD","changes":[["buy","0.7904","1345.9"]],"time":"2021-04-17T16:43:40.048711Z"}
1618677820.038802: {"type":"l2update","product_id":"YFI-BTC","changes":[["sell","0.82693","0.029935"]],"time":"2021-04-17T16:43:40.049696Z"}
1618677820.038883: {"type":"l2update","product_id":"DASH-BTC","changes":[["sell","0.00621318","3.85900000"]],"time":"2021-04-17T16:43:40.049712Z"}
1618677820.045206: {"type":"l2update","product_id":"SKL-USD","changes":[["sell","0.7929","24041.1"]],"time":"2021-04-17T16:43:40.056507Z"}
1618677820.045297: {"type":"l2update","product_id":"YFI-BTC","changes":[["buy","0.82315","0.000000"]],"time":"2021-04-17T16:43:40.056939Z"}
1618677820.047324: {"type":"l2update","product_id":"DASH-BTC","changes":[["sell","0.00621068","2.65200000"]],"time":"2021-04-17T16:43:40.057296Z"}
1618677820.0509849: {"type":"l2update","product_id":"YFI-BTC","changes":[["sell","0.82693","0.000000"]],"time":"2021-04-17T16:43:40.060697Z"}
1618677820.057156: {"type":"l2update","product_id":"SKL-USD","changes":[["buy","0.7882","3363.1"]],"time":"2021-04-17T16:43:40.072264Z"}
1618677820.057759: {"type":"l2update","product_id":"SKL-BTC","changes":[["sell","0.00001308","9558.0"]],"time":"2021-04-17T16:43:40.072588Z"}
1618677820.068506: {"type":"l2update","product_id":"SKL-USD","changes":[["buy","0.7905","867.0"]],"time":"2021-04-17T16:43:40.079981Z"}
1618677820.072868: {"type":"l2update","product_id":"YFI-BTC","changes":[["sell","0.82692","0.030000"]],"time":"2021-04-17T16:43:40.085408Z"}
1618677820.073001: {"type":"l2update","product_id":"YFI-BTC","changes":[["buy","0.82500","0.040000"]],"time":"2021-04-17T16:43:40.085427Z"}
1618677820.0758662: {"type":"l2update","product_id":"SKL-BTC","changes":[["buy","0.00001301","17483.7"]],"time":"2021-04-17T16:43:40.090317Z"}
1618677820.081182: {"type":"l2update","product_id":"DASH-BTC","changes":[["buy","0.00619092","1.97100000"]],"time":"2021-04-17T16:43:40.094266Z"}
1618677820.086571: {"type":"l2update","product_id":"SKL-USD","changes":[["sell","0.8080","6005.0"]],"time":"2021-04-17T16:43:40.095998Z"}
1618677820.09538: {"type":"l2update","product_id":"SKL-USD","changes":[["sell","0.8081","12005.0"]],"time":"2021-04-17T16:43:40.107228Z"}
1618677820.095501: {"type":"l2update","product_id":"DASH-BTC","changes":[["sell","0.00621156","0.00000000"]],"time":"2021-04-17T16:43:40.110672Z"}
1618677820.114228: {"type":"l2update","product_id":"DASH-BTC","changes":[["buy","0.00619214","0.00000000"]],"time":"2021-04-17T16:43:40.125945Z"}
1618677820.114369: {"type":"l2update","product_id":"YFI-BTC","changes":[["sell","0.82692","0.000000"]],"time":"2021-04-17T16:43:40.130442Z"}
1618677820.117533: {"type":"l2update","product_id":"DASH-BTC","changes":[["sell","0.00620888","1.62300000"]],"time":"2021-04-17T16:43:40.132420Z"}
1618677820.1243331: {"type":"l2update","product_id":"DASH-BTC","changes":[["buy","0.00619216","2.57000000"]],"time":"2021-04-17T16:43:40.138867Z"}
1618677820.136962: {"type":"l2update","product_id":"DASH-BTC","changes":[["sell","0.00621317","10.76500000"]],"time":"2021-04-17T16:43:40.151589Z"}
1618677820.153922: {"type":"l2update","product_id":"SKL-USD","changes":[["buy","0.7855","5.0"]],"time":"2021-04-17T16:43:40.164694Z"}
1618677820.154012: {"type":"l2update","product_id":"SKL-USD","changes":[["buy","0.7831","8472.5"]],"time":"2021-04-17T16:43:40.164694Z"}
1618677820.154064: {"type":"l2update","product_id":"SKL-USD","changes":[["buy","0.7831","0.0"]],"time":"2021-04-17T16:43:40.164694Z"}
1618677820.1616142: {"type":"l2update","product_id":"SKL-USD","changes":[["buy","0.7854","9361.5"]],"time":"2021-04-17T16:43:40.177439Z"}
1618677820.161731: {"type":"l2update","product_id":"SKL-USD","changes":[["buy","0.7830","8446.5"]],"time":"2021-04-17T16:43:40.177439Z"}
1618677820.165676: {"type":"l2update","product_id":"SKL-USD","changes":[["buy","0.7828","8556.5"]],"time":"2021-04-17T16:43:40.177439Z"}
1618677820.165764: {"type":"l2update","product_id":"SKL-USD","changes":[["sell","0.7987","175.8"]],"time":"2021-04-17T16:43:40.177439Z"}
1618677820.165816: {"type":"l2update","product_id":"SKL-USD","changes":[["sell","0.8072","5.0"]],"time":"2021-04-17T16:43:40.177439Z"}
1618677820.180738: {"type":"l2update","product_id":"SKL-BTC","changes":[["sell","0.00001311","4832.3"]],"time":"2021-04-17T16:43:40.188055Z"}
1618677820.180834: {"type":"l2update","product_id":"DASH-BTC","changes":[["buy","0.00619215","1.54200000"]],"time":"2021-04-17T16:43:40.195857Z"}
1618677820.1832068: {"type":"l2update","product_id":"SKL-BTC","changes":[["buy","0.00001303","13664.6"]],"time":"2021-04-17T16:43:40.198942Z"}
1618677820.183296: {"type":"l2update","product_id":"DASH-BTC","changes":[["buy","0.00619215","0.00000000"]],"time":"2021-04-17T16:43:40.200922Z"}
1618677820.19997: {"type":"l2update","product_id":"YFI-BTC","changes":[["sell","0.83180","0.000000"]],"time":"2021-04-17T16:43:40.212121Z"}
1618677820.200098: {"type":"l2update","product_id":"YFI-BTC","changes":[["sell","0.83187","0.000493"]],"time":"2021-04-17T16:43:40.212121Z"}
1618677820.205172: {"type":"l2update","product_id":"DASH-BTC","changes":[["buy","0.00619217","0.03000000"]],"time":"2021-04-17T16:43:40.217197Z"}
1618677820.2052748: {"type":"l2update","product_id":"YFI-BTC","changes":[["sell","0.83176","0.014570"]],"time":"2021-04-17T16:43:40.217224Z"}
1618677820.205338: {"type":"l2update","product_id":"YFI-BTC","changes":[["buy","0.82063","0.014210"]],"time":"2021-04-17T16:43:40.217224Z"}
1618677820.210633: {"type":"l2update","product_id":"SKL-USD","changes":[["buy","0.7882","0.0"]],"time":"2021-04-17T16:43:40.227216Z"}
1618677820.216179: {"type":"l2update","product_id":"DASH-BTC","changes":[["sell","0.00624132","0.00000000"]],"time":"2021-04-17T16:43:40.230910Z"}
1618677820.216913: {"type":"l2update","product_id":"DASH-BTC","changes":[["buy","0.00619217","1.57200000"]],"time":"2021-04-17T16:43:40.231752Z"}
1618677820.217003: {"type":"l2update","product_id":"BAND-BTC","changes":[["buy","0.00033196","0.00"]],"time":"2021-04-17T16:43:40.231989Z"}
1618677820.22035: {"type":"l2update","product_id":"DASH-BTC","changes":[["sell","0.00621318","2.23600000"]],"time":"2021-04-17T16:43:40.236866Z"}
1618677820.2272158: {"type":"l2update","product_id":"DASH-BTC","changes":[["sell","0.00626625","75.85000000"]],"time":"2021-04-17T16:43:40.243571Z"}
1618677820.2288792: {"type":"l2update","product_id":"BAND-BTC","changes":[["buy","0.00033294","177.78"]],"time":"2021-04-17T16:43:40.243620Z"}
1618677820.235233: {"type":"l2update","product_id":"BAND-BTC","changes":[["buy","0.00033449","155.33"]],"time":"2021-04-17T16:43:40.246383Z"}
1618677820.250696: {"type":"l2update","product_id":"DASH-BTC","changes":[["sell","0.00621067","1.62300000"]],"time":"2021-04-17T16:43:40.260933Z"}
1618677820.250828: {"type":"l2update","product_id":"CRV-EUR","changes":[["sell","3.3037","517.70"]],"time":"2021-04-17T16:43:40.261145Z"}
1618677820.2550871: {"type":"l2update","product_id":"BAND-BTC","changes":[["sell","0.00033537","0.00"]],"time":"2021-04-17T16:43:40.269513Z"}
1618677820.2622669: {"type":"l2update","product_id":"CRV-EUR","changes":[["sell","3.3036","5000.00"]],"time":"2021-04-17T16:43:40.276396Z"}
1618677820.271032: {"type":"l2update","product_id":"CRV-EUR","changes":[["buy","3.2982","0.00"]],"time":"2021-04-17T16:43:40.286343Z"}
1618677820.292314: {"type":"l2update","product_id":"DASH-BTC","changes":[["buy","0.00614333","0.20000000"]],"time":"2021-04-17T16:43:40.306171Z"}
1618677820.292431: {"type":"l2update","product_id":"DASH-BTC","changes":[["sell","0.00621781","0.00000000"]],"time":"2021-04-17T16:43:40.306171Z"}
1618677820.297652: {"type":"l2update","product_id":"DASH-BTC","changes":[["sell","0.00695376","1.87000000"]],"time":"2021-04-17T16:43:40.313199Z"}
1618677820.3011808: {"type":"l2update","product_id":"DASH-BTC","changes":[["buy","0.00614335","0.99000000"]],"time":"2021-04-17T16:43:40.313199Z"}
1618677820.3012831: {"type":"l2update","product_id":"DASH-BTC","changes":[["buy","0.00614333","0.25000000"]],"time":"2021-04-17T16:43:40.313199Z"}
1618677820.301335: {"type":"l2update","product_id":"BAND-BTC","changes":[["sell","0.00033537","36.71"]],"time":"2021-04-17T16:43:40.316930Z"}
1618677820.3226812: {"type":"l2update","product_id":"SKL-BTC","changes":[["buy","0.00001304","2672.3"]],"time":"2021-04-17T16:43:40.338812Z"}
1618677820.328663: {"type":"l2update","product_id":"SKL-USD","changes":[["sell","0.7929","23017.0"]],"time":"2021-04-17T16:43:40.341947Z"}
1618677820.330448: {"type":"l2update","product_id":"SKL-USD","changes":[["sell","0.8081","6005.0"]],"time":"2021-04-17T16:43:40.344597Z"}
1618677820.330563: {"type":"l2update","product_id":"SKL-BTC","changes":[["sell","0.00001308","8739.1"]],"time":"2021-04-17T16:43:40.344935Z"}
1618677820.335714: {"type":"l2update","product_id":"SKL-BTC","changes":[["buy","0.00001301","16498.2"]],"time":"2021-04-17T16:43:40.348223Z"}
1618677820.336373: {"type":"l2update","product_id":"SKL-USD","changes":[["sell","0.8079","6005.0"]],"time":"2021-04-17T16:43:40.353590Z"}
1618677820.360192: {"type":"l2update","product_id":"SKL-USD","changes":[["buy","0.7906","0.0"]],"time":"2021-04-17T16:43:40.365083Z"}
1618677820.3602629: {"type":"l2update","product_id":"DASH-BTC","changes":[["sell","0.00621318","0.00000000"]],"time":"2021-04-17T16:43:40.366320Z"}
1618677820.373085: {"type":"l2update","product_id":"CRV-EUR","changes":[["sell","3.3043","0.00"]],"time":"2021-04-17T16:43:40.389293Z"}
1618677820.3732212: {"type":"l2update","product_id":"SKL-USD","changes":[["sell","0.7925","2629.2"]],"time":"2021-04-17T16:43:40.389515Z"}
1618677820.3735948: {"type":"l2update","product_id":"SKL-GBP","changes":[["sell","0.5774","2526.1"]],"time":"2021-04-17T16:43:40.389771Z"}
1618677820.374057: {"type":"l2update","product_id":"SKL-USD","changes":[["sell","0.8174","1816.4"]],"time":"2021-04-17T16:43:40.391787Z"}
1618677820.387983: {"type":"l2update","product_id":"SKL-USD","changes":[["sell","0.7925","0.0"]],"time":"2021-04-17T16:43:40.403613Z"}
1618677820.396186: {"type":"l2update","product_id":"YFI-BTC","changes":[["buy","0.82374","0.000000"]],"time":"2021-04-17T16:43:40.411611Z"}
1618677820.4099789: {"type":"l2update","product_id":"SKL-USD","changes":[["sell","0.8079","12005.0"]],"time":"2021-04-17T16:43:40.424471Z"}
1618677820.4185421: {"type":"l2update","product_id":"NU-GBP","changes":[["buy","0.4386","1659.979400"]],"time":"2021-04-17T16:43:40.431116Z"}
1618677820.418636: {"type":"l2update","product_id":"DASH-BTC","changes":[["sell","0.00620475","2.68600000"]],"time":"2021-04-17T16:43:40.431550Z"}
1618677820.4205198: {"type":"l2update","product_id":"SKL-USD","changes":[["sell","0.7927","3543.2"]],"time":"2021-04-17T16:43:40.433269Z"}
1618677820.420579: {"type":"l2update","product_id":"YFI-BTC","changes":[["buy","0.82413","0.044700"]],"time":"2021-04-17T16:43:40.433346Z"}
1618677820.430138: {"type":"l2update","product_id":"DASH-BTC","changes":[["sell","0.00621067","3.85900000"]],"time":"2021-04-17T16:43:40.434156Z"}
1618677820.430202: {"type":"l2update","product_id":"SKL-USD","changes":[["sell","0.7924","6908.0"]],"time":"2021-04-17T16:43:40.434589Z"}
1618677820.430248: {"type":"l2update","product_id":"BAND-GBP","changes":[["buy","14.7661","0.00"]],"time":"2021-04-17T16:43:40.437546Z"}
1618677820.4302871: {"type":"l2update","product_id":"SKL-USD","changes":[["buy","0.7905","2061.0"]],"time":"2021-04-17T16:43:40.434731Z"}
1618677820.435322: {"type":"l2update","product_id":"SKL-GBP","changes":[["sell","0.5787","1258.1"]],"time":"2021-04-17T16:43:40.441995Z"}
1618677820.435393: {"type":"l2update","product_id":"CRV-EUR","changes":[["buy","3.2983","96.87"]],"time":"2021-04-17T16:43:40.444524Z"}
1618677820.4377868: {"type":"l2update","product_id":"SKL-USD","changes":[["buy","0.7880","3424.1"]],"time":"2021-04-17T16:43:40.448479Z"}
1618677820.43786: {"type":"l2update","product_id":"NMR-EUR","changes":[["sell","67.0209","1.275"]],"time":"2021-04-17T16:43:40.448296Z"}
1618677820.437896: {"type":"match","trade_id":868602,"maker_order_id":"4f92aadc-221c-40c5-80d4-1837c44040bc","taker_order_id":"0dc4a6e8-2107-411f-9511-b857b2c469da","side":"sell","size":"1.275","price":"67.0209","product_id":"NMR-EUR","sequence":471057044,"time":"2021-04-17T16:43:40.448296Z"}
1618677820.437928: {"type":"ticker","sequence":471057044,"product_id":"NMR-EUR","price":"67.0209","open_24h":"60.9288","volume_24h":"25746.38600000","low_24h":"60.4695","high_24h":"74.5","volume_30d":"552586.67900000","best_bid":"66.9290","best_ask":"67.0209","side":"buy","time":"2021-04-17T16:43:40.448296Z","trade_id":868602,"last_size":"1.275"}
1618677820.439677: {"type":"l2update","product_id":"NMR-EUR","changes":[["sell","67.0209","0.742"]],"time":"2021-04-17T16:43:40.448296Z"}
1618677820.439731: {"type":"ticker","sequence":471057046,"product_id":"NMR-EUR","price":"67.0209","open_24h":"60.9288","volume_24h":"25746.91900000","low_24h":"60.4695","high_24h":"74.5","volume_30d":"552587.21200000","best_bid":"66.9290","best_ask":"67.0209","side":"buy","time":"2021-04-17T16:43:40.448296Z","trade_id":868603,"last_size":"0.533"}
1618677820.439765: {"type":"match","trade_id":868603,"maker_order_id":"03ec6e32-84b6-4207-929e-fe73710d39b1","taker_order_id":"0dc4a6e8-2107-411f-9511-b857b2c469da","side":"sell","size":"0.533","price":"67.0209","product_id":"NMR-EUR","sequence":471057046,"time":"2021-04-17T16:43:40.448296Z"}
1618677820.4397922: {"type":"l2update","product_id":"SKL-USD","changes":[["sell","0.7926","2629.1"]],"time":"2021-04-17T16:43:40.449507Z"}
1618677820.443118: {"type":"l2update","product_id":"YFI-BTC","changes":[["buy","0.82526","0.030425"]],"time":"2021-04-17T16:43:40.456632Z"}
1618677820.471509: {"type":"l2update","product_id":"DASH-BTC","changes":[["sell","0.00620888","0.00000000"]],"time":"2021-04-17T16:43:40.478629Z"}
1618677820.471649: {"type":"l2update","product_id":"SKL-USD","changes":[["buy","0.7907","7500.0"]],"time":"2021-04-17T16:43:40.484917Z"}
1618677820.474578: {"type":"l2update","product_id":"SKL-BTC","changes":[["sell","0.00001311","4013.4"]],"time":"2021-04-17T16:43:40.489078Z"}
1618677820.478729: {"type":"l2update","product_id":"SKL-BTC","changes":[["buy","0.00001303","12679.1"]],"time":"2021-04-17T16:43:40.493516Z"}
1618677820.4821: {"type":"l2update","product_id":"DASH-BTC","changes":[["sell","0.00620474","1.62300000"]],"time":"2021-04-17T16:43:40.498067Z"}
1618677820.4935522: {"type":"l2update","product_id":"SKL-USD","changes":[["sell","0.8081","5.0"]],"time":"2021-04-17T16:43:40.499622Z"}
1618677820.495584: {"type":"l2update","product_id":"BAND-GBP","changes":[["buy","14.7700","36.00"]],"time":"2021-04-17T16:43:40.505357Z"}
1618677820.505632: {"type":"l2update","product_id":"CRV-EUR","changes":[["buy","3.2975","120.00"]],"time":"2021-04-17T16:43:40.518079Z"}
1618677820.5057678: {"type":"l2update","product_id":"BAND-BTC","changes":[["sell","0.00033526","45.85"]],"time":"2021-04-17T16:43:40.521038Z"}
1618677820.5061471: {"type":"l2update","product_id":"BAND-GBP","changes":[["buy","14.7773","12.18"]],"time":"2021-04-17T16:43:40.521099Z"}
1618677820.5100029: {"type":"l2update","product_id":"SKL-USD","changes":[["buy","0.7905","3050.7"]],"time":"2021-04-17T16:43:40.524779Z"}
1618677820.510093: {"type":"l2update","product_id":"DASH-BTC","changes":[["buy","0.00619092","0.00000000"]],"time":"2021-04-17T16:43:40.524903Z"}
1618677820.516763: {"type":"l2update","product_id":"DASH-BTC","changes":[["sell","0.00695376","0.00000000"]],"time":"2021-04-17T16:43:40.528764Z"}
1618677820.5168672: {"type":"l2update","product_id":"BAND-BTC","changes":[["buy","0.00033449","92.33"]],"time":"2021-04-17T16:43:40.531284Z"}
1618677820.516923: {"type":"l2update","product_id":"SKL-USD","changes":[["buy","0.7864","5.0"]],"time":"2021-04-17T16:43:40.533085Z"}
1618677820.5169652: {"type":"l2update","product_id":"SKL-USD","changes":[["buy","0.7906","2629.2"]],"time":"2021-04-17T16:43:40.533303Z"}
1618677820.5247428: {"type":"l2update","product_id":"DASH-BTC","changes":[["sell","0.00784571","0.29000000"]],"time":"2021-04-17T16:43:40.536464Z"}
1618677820.530079: {"type":"l2update","product_id":"SKL-USD","changes":[["buy","0.7876","1269.7"]],"time":"2021-04-17T16:43:40.543685Z"}
1618677820.563404: {"type":"l2update","product_id":"BAND-GBP","changes":[["buy","14.7699","0.00"]],"time":"2021-04-17T16:43:40.578696Z"}
1618677820.573092: {"type":"l2update","product_id":"BAND-GBP","changes":[["buy","14.7774","27.50"]],"time":"2021-04-17T16:43:40.584463Z"}
1618677820.573226: {"type":"l2update","product_id":"BAND-GBP","changes":[["buy","14.7659","0.00"]],"time":"2021-04-17T16:43:40.586323Z"}
1618677820.577434: {"type":"l2update","product_id":"BAND-GBP","changes":[["sell","14.8095","0.00"]],"time":"2021-04-17T16:43:40.586991Z"}
1618677820.577536: {"type":"l2update","product_id":"BAND-BTC","changes":[["sell","0.00033564","0.00"]],"time":"2021-04-17T16:43:40.587786Z"}
1618677820.5873501: {"type":"l2update","product_id":"BAND-GBP","changes":[["buy","14.7832","12.94"]],"time":"2021-04-17T16:43:40.599158Z"}
1618677820.5919008: {"type":"l2update","product_id":"SKL-USD","changes":[["buy","0.7880","0.0"]],"time":"2021-04-17T16:43:40.602693Z"}
1618677820.596063: {"type":"l2update","product_id":"YFI-BTC","changes":[["sell","0.82714","0.029510"]],"time":"2021-04-17T16:43:40.603219Z"}
1618677820.60093: {"type":"l2update","product_id":"BAND-GBP","changes":[["buy","14.7698","0.00"]],"time":"2021-04-17T16:43:40.611737Z"}
1618677820.601036: {"type":"l2update","product_id":"YFI-BTC","changes":[["sell","0.82714","0.000000"]],"time":"2021-04-17T16:43:40.612531Z"}
1618677820.6011: {"type":"l2update","product_id":"NMR-EUR","changes":[["buy","66.9228","0.857"]],"time":"2021-04-17T16:43:40.613858Z"}
1618677820.604011: {"type":"l2update","product_id":"DASH-BTC","changes":[["sell","0.00620650","2.68600000"]],"time":"2021-04-17T16:43:40.617526Z"}
1618677820.6041589: {"type":"l2update","product_id":"BAND-GBP","changes":[["sell","14.8129","12.08"]],"time":"2021-04-17T16:43:40.617623Z"}
1618677820.620171: {"type":"l2update","product_id":"YFI-BTC","changes":[["sell","0.83695","0.000000"]],"time":"2021-04-17T16:43:40.630688Z"}
1618677820.6203089: {"type":"l2update","product_id":"YFI-BTC","changes":[["sell","0.82853","0.000000"]],"time":"2021-04-17T16:43:40.630688Z"}
1618677820.6203709: {"type":"l2update","product_id":"YFI-BTC","changes":[["buy","0.82404","0.000000"]],"time":"2021-04-17T16:43:40.630688Z"}
1618677820.629952: {"type":"l2update","product_id":"NU-GBP","changes":[["buy","0.4363","160.000000"]],"time":"2021-04-17T16:43:40.643555Z"}
1618677820.637731: {"type":"l2update","product_id":"YFI-BTC","changes":[["sell","0.83780","0.100800"]],"time":"2021-04-17T16:43:40.648929Z"}
1618677820.6378329: {"type":"l2update","product_id":"YFI-BTC","changes":[["sell","0.82899","0.015100"]],"time":"2021-04-17T16:43:40.648929Z"}
1618677820.6378932: {"type":"l2update","product_id":"YFI-BTC","changes":[["buy","0.82447","0.019100"]],"time":"2021-04-17T16:43:40.648929Z"}
1618677820.647159: {"type":"l2update","product_id":"SKL-BTC","changes":[["buy","0.00001303","13664.6"]],"time":"2021-04-17T16:43:40.659863Z"}
1618677820.647275: {"type":"l2update","product_id":"SKL-BTC","changes":[["sell","0.00001311","4832.3"]],"time":"2021-04-17T16:43:40.659863Z"}
1618677820.676966: {"type":"l2update","product_id":"YFI-BTC","changes":[["buy","0.82191","0.000000"]],"time":"2021-04-17T16:43:40.691024Z"}
1618677820.694976: {"type":"l2update","product_id":"YFI-BTC","changes":[["buy","0.82238","0.095700"]],"time":"2021-04-17T16:43:40.706526Z"}
1618677820.69508: {"type":"l2update","product_id":"SKL-USD","changes":[["buy","0.7905","2183.7"]],"time":"2021-04-17T16:43:40.708982Z"}
1618677820.7001972: {"type":"l2update","product_id":"NU-GBP","changes":[["buy","0.4365","3010.000000"]],"time":"2021-04-17T16:43:40.712940Z"}
1618677820.716973: {"type":"l2update","product_id":"SKL-USD","changes":[["buy","0.7904","2213.0"]],"time":"2021-04-17T16:43:40.732142Z"}
1618677820.7295969: {"type":"l2update","product_id":"BAND-GBP","changes":[["buy","14.7774","0.00"]],"time":"2021-04-17T16:43:40.742305Z"}
1618677820.74581: {"type":"l2update","product_id":"BAND-GBP","changes":[["buy","14.6484","16.00"]],"time":"2021-04-17T16:43:40.756219Z"}
1618677820.7459252: {"type":"l2update","product_id":"SKL-USD","changes":[["buy","0.7905","989.7"]],"time":"2021-04-17T16:43:40.759410Z"}
1618677820.752243: {"type":"l2update","product_id":"BAND-GBP","changes":[["buy","14.6486","10.10"]],"time":"2021-04-17T16:43:40.761582Z"}
1618677820.7523708: {"type":"l2update","product_id":"BAND-GBP","changes":[["buy","14.6487","0.10"]],"time":"2021-04-17T16:43:40.761582Z"}
1618677820.752445: {"type":"l2update","product_id":"SKL-USD","changes":[["buy","0.7880","3067.6"]],"time":"2021-04-17T16:43:40.761645Z"}
1618677820.7614222: {"type":"l2update","product_id":"DASH-BTC","changes":[["sell","0.00621067","1.62300000"]],"time":"2021-04-17T16:43:40.778345Z"}
1618677820.7690592: {"type":"l2update","product_id":"SKL-USD","changes":[["buy","0.7906","3823.1"]],"time":"2021-04-17T16:43:40.784323Z"}
1618677820.770616: {"type":"l2update","product_id":"YFI-BTC","changes":[["sell","0.82976","0.000000"]],"time":"2021-04-17T16:43:40.784568Z"}
1618677820.7844381: {"type":"l2update","product_id":"YFI-BTC","changes":[["sell","0.83027","0.035300"]],"time":"2021-04-17T16:43:40.798317Z"}
1618677820.789783: {"type":"l2update","product_id":"BAND-GBP","changes":[["buy","14.7832","0.00"]],"time":"2021-04-17T16:43:40.806129Z"}
1618677820.795535: {"type":"l2update","product_id":"BAND-BTC","changes":[["buy","0.00033290","0.00"]],"time":"2021-04-17T16:43:40.806417Z"}
1618677820.8072162: {"type":"l2update","product_id":"BAND-BTC","changes":[["sell","0.00033517","18.70"]],"time":"2021-04-17T16:43:40.810929Z"}
1618677820.8087292: {"type":"l2update","product_id":"BAND-BTC","changes":[["sell","0.00033539","47.05"]],"time":"2021-04-17T16:43:40.822209Z"}
1618677820.811587: {"type":"l2update","product_id":"DASH-BTC","changes":[["buy","0.00619274","1.97100000"]],"time":"2021-04-17T16:43:40.826269Z"}
1618677820.8173282: {"type":"l2update","product_id":"DASH-BTC","changes":[["sell","0.00620888","2.23600000"]],"time":"2021-04-17T16:43:40.830327Z"}
1618677820.817445: {"type":"l2update","product_id":"BAND-BTC","changes":[["sell","0.00033526","18.13"]],"time":"2021-04-17T16:43:40.830501Z"}
1618677820.8174999: {"type":"l2update","product_id":"NU-GBP","changes":[["buy","0.4324","0.000000"]],"time":"2021-04-17T16:43:40.833103Z"}
1618677820.817557: {"type":"l2update","product_id":"NU-GBP","changes":[["buy","0.4323","0.000000"]],"time":"2021-04-17T16:43:40.833103Z"}
1618677820.8176022: {"type":"l2update","product_id":"NU-GBP","changes":[["buy","0.4348","0.000000"]],"time":"2021-04-17T16:43:40.833103Z"}
1618677820.8176441: {"type":"l2update","product_id":"NU-GBP","changes":[["buy","0.4349","0.000000"]],"time":"2021-04-17T16:43:40.833103Z"}
1618677820.8282712: {"type":"l2update","product_id":"NU-GBP","changes":[["buy","0.4363","2410.000000"]],"time":"2021-04-17T16:43:40.841639Z"}
1618677820.828358: {"type":"l2update","product_id":"NU-GBP","changes":[["buy","0.4365","5460.000000"]],"time":"2021-04-17T16:43:40.841639Z"}
1618677820.8284101: {"type":"l2update","product_id":"NU-GBP","changes":[["buy","0.4364","2180.000000"]],"time":"2021-04-17T16:43:40.841639Z"}
1618677820.8284512: {"type":"l2update","product_id":"NU-GBP","changes":[["buy","0.4366","1920.000000"]],"time":"2021-04-17T16:43:40.841639Z"}
1618677820.8284988: {"type":"l2update","product_id":"BAND-BTC","changes":[["buy","0.00033375","20.77"]],"time":"2021-04-17T16:43:40.842712Z"}
1618677820.8480608: {"type":"l2update","product_id":"BAND-BTC","changes":[["buy","0.00033349","49.42"]],"time":"2021-04-17T16:43:40.864024Z"}
1618677820.854574: {"type":"l2update","product_id":"SKL-BTC","changes":[["buy","0.00001293","1342.2"]],"time":"2021-04-17T16:43:40.867867Z"}
1618677820.854663: {"type":"l2update","product_id":"SKL-BTC","changes":[["buy","0.00001292","12766.3"]],"time":"2021-04-17T16:43:40.867867Z"}
1618677820.8547149: {"type":"l2update","product_id":"SKL-BTC","changes":[["buy","0.00001292","12346.3"]],"time":"2021-04-17T16:43:40.867867Z"}
1618677820.854756: {"type":"l2update","product_id":"SKL-BTC","changes":[["buy","0.00001298","2641.8"]],"time":"2021-04-17T16:43:40.867867Z"}
1618677820.854793: {"type":"l2update","product_id":"BAND-BTC","changes":[["sell","0.00033543","25.72"]],"time":"2021-04-17T16:43:40.871339Z"}
1618677820.861011: {"type":"l2update","product_id":"SKL-BTC","changes":[["buy","0.00001304","3107.3"]],"time":"2021-04-17T16:43:40.875117Z"}
1618677820.861109: {"type":"l2update","product_id":"SKL-BTC","changes":[["buy","0.00001302","4833.3"]],"time":"2021-04-17T16:43:40.875117Z"}
1618677820.861162: {"type":"l2update","product_id":"SKL-BTC","changes":[["buy","0.00001295","215.0"]],"time":"2021-04-17T16:43:40.875117Z"}
1618677820.8611898: {"type":"l2update","product_id":"SKL-BTC","changes":[["buy","0.00001296","1389.9"]],"time":"2021-04-17T16:43:40.875117Z"}
1618677820.861213: {"type":"l2update","product_id":"SKL-BTC","changes":[["buy","0.00001297","15.0"]],"time":"2021-04-17T16:43:40.875117Z"}
1618677820.87922: {"type":"l2update","product_id":"BAND-GBP","changes":[["sell","14.8096","12.74"]],"time":"2021-04-17T16:43:40.892968Z"}
1618677820.8973298: {"type":"l2update","product_id":"BAND-GBP","changes":[["sell","14.8088","123.10"]],"time":"2021-04-17T16:43:40.911779Z"}
1618677820.911149: {"type":"l2update","product_id":"SKL-USD","changes":[["buy","0.7880","3366.7"]],"time":"2021-04-17T16:43:40.926402Z"}
1618677820.91361: {"type":"l2update","product_id":"YFI-BTC","changes":[["buy","0.82413","0.000000"]],"time":"2021-04-17T16:43:40.929631Z"}
1618677820.9287438: {"type":"l2update","product_id":"YFI-BTC","changes":[["buy","0.82452","0.044700"]],"time":"2021-04-17T16:43:40.944992Z"}
1618677820.9424121: {"type":"l2update","product_id":"SKL-USD","changes":[["sell","0.8079","6005.0"]],"time":"2021-04-17T16:43:40.954424Z"}
1618677820.950169: {"type":"l2update","product_id":"SKL-USD","changes":[["buy","0.7862","30.0"]],"time":"2021-04-17T16:43:40.966570Z"}
1618677820.9589682: {"type":"l2update","product_id":"SKL-USD","changes":[["sell","0.8080","12005.0"]],"time":"2021-04-17T16:43:40.971074Z"}
1618677820.97297: {"type":"l2update","product_id":"DASH-BTC","changes":[["sell","0.00621319","0.00000000"]],"time":"2021-04-17T16:43:40.990208Z"}
1618677820.9859798: {"type":"l2update","product_id":"DASH-BTC","changes":[["buy","0.00618880","0.00000000"]],"time":"2021-04-17T16:43:41.002916Z"}
1618677821.008369: {"type":"l2update","product_id":"DASH-BTC","changes":[["buy","0.00618953","0.00000000"]],"time":"2021-04-17T16:43:41.022402Z"}
1618677821.026371: {"type":"l2update","product_id":"NMR-EUR","changes":[["sell","67.0878","0.000"]],"time":"2021-04-17T16:43:41.040544Z"}
1618677821.027253: {"type":"l2update","product_id":"DASH-BTC","changes":[["buy","0.00618762","1.12000000"]],"time":"2021-04-17T16:43:41.043925Z"}
1618677821.0360498: {"type":"l2update","product_id":"YFI-BTC","changes":[["buy","0.82553","0.000000"]],"time":"2021-04-17T16:43:41.053177Z"}
1618677821.063919: {"type":"l2update","product_id":"DASH-BTC","changes":[["sell","0.00620946","14.63200000"]],"time":"2021-04-17T16:43:41.075292Z"}
1618677821.0640562: {"type":"l2update","product_id":"DASH-BTC","changes":[["sell","0.00620529","0.00000000"]],"time":"2021-04-17T16:43:41.075717Z"}
1618677821.0641248: {"type":"l2update","product_id":"BAND-BTC","changes":[["buy","0.00033449","66.33"]],"time":"2021-04-17T16:43:41.077946Z"}
1618677821.0764549: {"type":"l2update","product_id":"DASH-BTC","changes":[["buy","0.00619036","32.84700000"]],"time":"2021-04-17T16:43:41.086417Z"}
1618677821.076524: {"type":"l2update","product_id":"BAND-BTC","changes":[["sell","0.00033522","25.00"]],"time":"2021-04-17T16:43:41.086316Z"}
1618677821.103586: {"type":"l2update","product_id":"BAND-BTC","changes":[["sell","0.00033673","0.00"]],"time":"2021-04-17T16:43:41.089740Z"}
1618677821.1037261: {"type":"l2update","product_id":"BAND-BTC","changes":[["buy","0.00033171","0.00"]],"time":"2021-04-17T16:43:41.089740Z"}
1618677821.1037881: {"type":"l2update","product_id":"BAND-BTC","changes":[["sell","0.00033614","0.00"]],"time":"2021-04-17T16:43:41.093456Z"}
1618677821.1038349: {"type":"l2update","product_id":"BAND-BTC","changes":[["sell","0.00033674","20.70"]],"time":"2021-04-17T16:43:41.096933Z"}
1618677821.1038752: {"type":"l2update","product_id":"BAND-BTC","changes":[["buy","0.00033170","471.26"]],"time":"2021-04-17T16:43:41.096933Z"}
1618677821.10391: {"type":"l2update","product_id":"BAND-GBP","changes":[["buy","14.6484","14.40"]],"time":"2021-04-17T16:43:41.100963Z"}
1618677821.1039438: {"type":"l2update","product_id":"YFI-BTC","changes":[["buy","0.82572","0.017058"]],"time":"2021-04-17T16:43:41.104489Z"}
1618677821.103988: {"type":"l2update","product_id":"BAND-GBP","changes":[["buy","14.6487","1.70"]],"time":"2021-04-17T16:43:41.108034Z"}
1618677821.104022: {"type":"l2update","product_id":"SKL-USD","changes":[["sell","0.8080","6005.0"]],"time":"2021-04-17T16:43:41.109441Z"}
1618677821.113966: {"type":"l2update","product_id":"DASH-BTC","changes":[["sell","0.00620474","0.00000000"]],"time":"2021-04-17T16:43:41.120163Z"}
1618677821.1201558: {"type":"l2update","product_id":"DASH-BTC","changes":[["sell","0.00621067","0.00000000"]],"time":"2021-04-17T16:43:41.125127Z"}
1618677821.120268: {"type":"l2update","product_id":"DASH-BTC","changes":[["sell","0.00620473","2.57000000"]],"time":"2021-04-17T16:43:41.127828Z"}
1618677821.1203341: {"type":"l2update","product_id":"YFI-BTC","changes":[["buy","0.82450","0.000000"]],"time":"2021-04-17T16:43:41.130944Z"}
1618677821.1203892: {"type":"l2update","product_id":"BAND-BTC","changes":[["buy","0.00033448","249.11"]],"time":"2021-04-17T16:43:41.131090Z"}
1618677821.127887: {"type":"l2update","product_id":"SKL-USD","changes":[["sell","0.8078","6000.0"]],"time":"2021-04-17T16:43:41.139243Z"}
1618677821.1364942: {"type":"l2update","product_id":"SKL-USD","changes":[["sell","0.8078","12000.0"]],"time":"2021-04-17T16:43:41.149663Z"}
1618677821.136589: {"type":"l2update","product_id":"DASH-BTC","changes":[["sell","0.00620888","3.85900000"]],"time":"2021-04-17T16:43:41.149793Z"}
1618677821.148267: {"type":"l2update","product_id":"DASH-BTC","changes":[["buy","0.00619216","0.00000000"]],"time":"2021-04-17T16:43:41.158276Z"}
1618677821.148403: {"type":"l2update","product_id":"DASH-BTC","changes":[["sell","0.00620945","1.62300000"]],"time":"2021-04-17T16:43:41.160320Z"}
1618677821.148471: {"type":"l2update","product_id":"BAND-BTC","changes":[["sell","0.00033613","0.00"]],"time":"2021-04-17T16:43:41.162068Z"}
1618677821.150558: {"type":"l2update","product_id":"NMR-EUR","changes":[["buy","66.9228","0.000"]],"time":"2021-04-17T16:43:41.166915Z"}
1618677821.165777: {"type":"l2update","product_id":"YFI-BTC","changes":[["sell","0.82711","0.000000"]],"time":"2021-04-17T16:43:41.182592Z"}
1618677821.172226: {"type":"l2update","product_id":"NMR-EUR","changes":[["buy","66.9291","0.857"]],"time":"2021-04-17T16:43:41.186653Z"}
1618677821.176509: {"type":"l2update","product_id":"YFI-BTC","changes":[["buy","0.82588","0.019999"]],"time":"2021-04-17T16:43:41.190397Z"}
1618677821.181995: {"type":"l2update","product_id":"YFI-BTC","changes":[["sell","0.82710","0.000000"]],"time":"2021-04-17T16:43:41.194337Z"}
1618677821.182137: {"type":"l2update","product_id":"NMR-EUR","changes":[["buy","66.9290","0.000"]],"time":"2021-04-17T16:43:41.195059Z"}
1618677821.186027: {"type":"l2update","product_id":"YFI-BTC","changes":[["buy","0.82507","0.000000"]],"time":"2021-04-17T16:43:41.201211Z"}
1618677821.186131: {"type":"l2update","product_id":"YFI-BTC","changes":[["buy","0.82582","0.014100"]],"time":"2021-04-17T16:43:41.201345Z"}
1618677821.1861959: {"type":"l2update","product_id":"YFI-BTC","changes":[["buy","0.82495","0.000000"]],"time":"2021-04-17T16:43:41.201660Z"}
1618677821.191644: {"type":"l2update","product_id":"YFI-BTC","changes":[["sell","0.82716","0.030000"]],"time":"2021-04-17T16:43:41.203067Z"}
1618677821.191776: {"type":"l2update","product_id":"NMR-EUR","changes":[["buy","66.9293","4.774"]],"time":"2021-04-17T16:43:41.203273Z"}
1618677821.1918359: {"type":"l2update","product_id":"YFI-BTC","changes":[["sell","0.82766","0.019212"]],"time":"2021-04-17T16:43:41.205978Z"}
1618677821.1918871: {"type":"l2update","product_id":"BAND-BTC","changes":[["sell","0.00033597","39.00"]],"time":"2021-04-17T16:43:41.206192Z"}
1618677821.191935: {"type":"l2update","product_id":"DASH-BTC","changes":[["buy","0.00619275","2.57000000"]],"time":"2021-04-17T16:43:41.206320Z"}
1618677821.191978: {"type":"l2update","product_id":"DASH-BTC","changes":[["buy","0.00619217","1.54200000"]],"time":"2021-04-17T16:43:41.208106Z"}
1618677821.193706: {"type":"l2update","product_id":"BAND-BTC","changes":[["sell","0.00033673","0.94"]],"time":"2021-04-17T16:43:41.208829Z"}
1618677821.1956632: {"type":"l2update","product_id":"DASH-BTC","changes":[["buy","0.00619217","0.00000000"]],"time":"2021-04-17T16:43:41.212685Z"}
1618677821.207577: {"type":"l2update","product_id":"YFI-BTC","changes":[["buy","0.82527","0.046896"]],"time":"2021-04-17T16:43:41.224103Z"}
1618677821.2170181: {"type":"l2update","product_id":"DASH-BTC","changes":[["buy","0.00619214","0.03000000"]],"time":"2021-04-17T16:43:41.231142Z"}
1618677821.217153: {"type":"l2update","product_id":"NMR-EUR","changes":[["sell","67.1738","47.400"]],"time":"2021-04-17T16:43:41.231465Z"}
1618677821.2362182: {"type":"l2update","product_id":"DASH-BTC","changes":[["buy","0.00619214","1.57200000"]],"time":"2021-04-17T16:43:41.246335Z"}
1618677821.242485: {"type":"l2update","product_id":"SKL-USD","changes":[["sell","0.8080","5.0"]],"time":"2021-04-17T16:43:41.257717Z"}
1618677821.2542982: {"type":"l2update","product_id":"BAND-BTC","changes":[["sell","0.00033649","0.00"]],"time":"2021-04-17T16:43:41.268524Z"}
1618677821.2662332: {"type":"l2update","product_id":"SKL-USD","changes":[["buy","0.7875","0.0"]],"time":"2021-04-17T16:43:41.282307Z"}
1618677821.2719722: {"type":"l2update","product_id":"NMR-EUR","changes":[["buy","66.4810","0.000"]],"time":"2021-04-17T16:43:41.286818Z"}
1618677821.272088: {"type":"l2update","product_id":"BAND-GBP","changes":[["buy","14.7731","0.00"]],"time":"2021-04-17T16:43:41.287163Z"}
1618677821.291873: {"type":"l2update","product_id":"SKL-USD","changes":[["buy","0.7863","5.0"]],"time":"2021-04-17T16:43:41.306990Z"}
1618677821.291975: {"type":"l2update","product_id":"NMR-EUR","changes":[["buy","66.9291","0.000"]],"time":"2021-04-17T16:43:41.307575Z"}
1618677821.316969: {"type":"l2update","product_id":"NMR-EUR","changes":[["buy","66.9294","0.857"]],"time":"2021-04-17T16:43:41.330141Z"}
1618677821.3246331: {"type":"l2update","product_id":"NMR-EUR","changes":[["buy","66.9293","0.000"]],"time":"2021-04-17T16:43:41.339109Z"}
1618677821.33761: {"type":"l2update","product_id":"NMR-EUR","changes":[["buy","66.9296","4.773"]],"time":"2021-04-17T16:43:41.346344Z"}
1618677821.338973: {"type":"l2update","product_id":"YFI-BTC","changes":[["sell","0.83178","0.003170"]],"time":"2021-04-17T16:43:41.350362Z"}
1618677821.3390179: {"type":"l2update","product_id":"YFI-BTC","changes":[["sell","0.83177","0.000000"]],"time":"2021-04-17T16:43:41.350362Z"}
1618677821.3500621: {"type":"l2update","product_id":"NMR-EUR","changes":[["buy","66.4813","13.000"]],"time":"2021-04-17T16:43:41.353584Z"}
1618677821.3502028: {"type":"l2update","product_id":"YFI-BTC","changes":[["sell","0.82717","0.000000"]],"time":"2021-04-17T16:43:41.354946Z"}
1618677821.350276: {"type":"l2update","product_id":"YFI-BTC","changes":[["sell","0.82838","0.000000"]],"time":"2021-04-17T16:43:41.360374Z"}
1618677821.350327: {"type":"l2update","product_id":"YFI-BTC","changes":[["sell","0.83217","0.014940"]],"time":"2021-04-17T16:43:41.361008Z"}
1618677821.350373: {"type":"l2update","product_id":"YFI-BTC","changes":[["sell","0.83175","0.013360"]],"time":"2021-04-17T16:43:41.361008Z"}
1618677821.350422: {"type":"l2update","product_id":"YFI-BTC","changes":[["sell","0.83178","0.008140"]],"time":"2021-04-17T16:43:41.361008Z"}
1618677821.359596: {"type":"l2update","product_id":"YFI-BTC","changes":[["sell","0.82716","0.000000"]],"time":"2021-04-17T16:43:41.369901Z"}
1618677821.363783: {"type":"l2update","product_id":"YFI-BTC","changes":[["sell","0.82731","0.030000"]],"time":"2021-04-17T16:43:41.375504Z"}
1618677821.363888: {"type":"l2update","product_id":"YFI-BTC","changes":[["sell","0.82737","0.000000"]],"time":"2021-04-17T16:43:41.378773Z"}
1618677821.3679621: {"type":"l2update","product_id":"YFI-BTC","changes":[["sell","0.82751","0.019982"]],"time":"2021-04-17T16:43:41.382728Z"}
1618677821.378656: {"type":"l2update","product_id":"YFI-BTC","changes":[["sell","0.82833","0.019982"]],"time":"2021-04-17T16:43:41.394479Z"}
1618677821.387648: {"type":"l2update","product_id":"BAND-GBP","changes":[["buy","14.7320","0.00"]],"time":"2021-04-17T16:43:41.403934Z"}
1618677821.394239: {"type":"l2update","product_id":"BAND-BTC","changes":[["sell","0.00033537","0.00"]],"time":"2021-04-17T16:43:41.406340Z"}
1618677821.398359: {"type":"l2update","product_id":"BAND-GBP","changes":[["buy","14.7475","49.37"]],"time":"2021-04-17T16:43:41.413309Z"}
1618677821.445813: {"type":"l2update","product_id":"BAND-BTC","changes":[["sell","0.00033537","36.72"]],"time":"2021-04-17T16:43:41.461687Z"}
