1618677821.449134: {"type":"l2update","product_id":"BAND-BTC","changes":[["sell","0.00033525","0.00"]],"time":"2021-04-17T16:43:41.463939Z"}
1618677821.449276: {"type":"l2update","product_id":"DASH-BTC","changes":[["sell","0.00620888","2.23600000"]],"time":"2021-04-17T16:43:41.465183Z"}
1618677821.45338: {"type":"l2update","product_id":"BAND-BTC","changes":[["sell","0.00033516","29.65"]],"time":"2021-04-17T16:43:41.468740Z"}
1618677821.474078: {"type":"l2update","product_id":"BAND-BTC","changes":[["buy","0.00033448","123.11"]],"time":"2021-04-17T16:43:41.484626Z"}
1618677821.474198: {"type":"l2update","product_id":"DASH-BTC","changes":[["sell","0.00620472","1.62300000"]],"time":"2021-04-17T16:43:41.487511Z"}
1618677821.482687: {"type":"l2update","product_id":"DASH-BTC","changes":[["buy","0.00451419","0.00000000"]],"time":"2021-04-17T16:43:41.497600Z"}
1618677821.4828238: {"type":"l2update","product_id":"DASH-BTC","changes":[["buy","0.00451009","0.00000000"]],"time":"2021-04-17T16:43:41.497600Z"}
1618677821.4828851: {"type":"l2update","product_id":"DASH-BTC","changes":[["buy","0.00450007","3.05000000"]],"time":"2021-04-17T16:43:41.497600Z"}
1618677821.48293: {"type":"l2update","product_id":"DASH-BTC","changes":[["buy","0.00451008","0.05000000"]],"time":"2021-04-17T16:43:41.497600Z"}
1618677821.490017: {"type":"l2update","product_id":"DASH-BTC","changes":[["buy","0.00614336","2.37000000"]],"time":"2021-04-17T16:43:41.505993Z"}
1618677821.490137: {"type":"l2update","product_id":"DASH-BTC","changes":[["buy","0.00614335","2.84000000"]],"time":"2021-04-17T16:43:41.505993Z"}
1618677821.494115: {"type":"l2update","product_id":"BAND-BTC","changes":[["sell","0.00033521","31.74"]],"time":"2021-04-17T16:43:41.509983Z"}
1618677821.5360188: {"type":"l2update","product_id":"SKL-USD","changes":[["buy","0.7880","5266.7"]],"time":"2021-04-17T16:43:41.539380Z"}
1618677821.564322: {"type":"l2update","product_id":"SKL-USD","changes":[["buy","0.7877","1317.4"]],"time":"2021-04-17T16:43:41.542769Z"}
1618677821.564464: {"type":"l2update","product_id":"NMR-EUR","changes":[["buy","66.4805","0.410"]],"time":"2021-04-17T16:43:41.550795Z"}
1618677821.564519: {"type":"l2update","product_id":"NMR-EUR","changes":[["buy","66.4804","0.000"]],"time":"2021-04-17T16:43:41.550795Z"}
1618677821.564576: {"type":"l2update","product_id":"DASH-BTC","changes":[["buy","0.00619214","1.54200000"]],"time":"2021-04-17T16:43:41.553642Z"}
1618677821.5646179: {"type":"l2update","product_id":"DASH-BTC","changes":[["sell","0.00620475","0.00000000"]],"time":"2021-04-17T16:43:41.560800Z"}
1618677821.564668: {"type":"l2update","product_id":"NMR-EUR","changes":[["buy","66.4812","23.360"]],"time":"2021-04-17T16:43:41.563081Z"}
1618677821.564712: {"type":"l2update","product_id":"NMR-EUR","changes":[["buy","66.4809","7.690"]],"time":"2021-04-17T16:43:41.563081Z"}
1618677821.575281: {"type":"l2update","product_id":"NMR-EUR","changes":[["buy","66.4808","18.390"]],"time":"2021-04-17T16:43:41.563081Z"}
1618677821.575404: {"type":"l2update","product_id":"BAND-BTC","changes":[["buy","0.00033434","0.00"]],"time":"2021-04-17T16:43:41.568599Z"}
1618677821.5754821: {"type":"l2update","product_id":"DASH-BTC","changes":[["buy","0.00619276","0.03000000"]],"time":"2021-04-17T16:43:41.573050Z"}
1618677821.575541: {"type":"l2update","product_id":"YFI-BTC","changes":[["buy","0.82437","0.000000"]],"time":"2021-04-17T16:43:41.573245Z"}
1618677821.575594: {"type":"l2update","product_id":"YFI-BTC","changes":[["sell","0.83178","0.004970"]],"time":"2021-04-17T16:43:41.574063Z"}
1618677821.5756311: {"type":"l2update","product_id":"YFI-BTC","changes":[["sell","0.83179","0.000000"]],"time":"2021-04-17T16:43:41.574063Z"}
1618677821.575677: {"type":"l2update","product_id":"YFI-BTC","changes":[["buy","0.82063","0.013340"]],"time":"2021-04-17T16:43:41.574063Z"}
1618677821.5757298: {"type":"l2update","product_id":"YFI-BTC","changes":[["buy","0.82063","0.003230"]],"time":"2021-04-17T16:43:41.574063Z"}
1618677821.578905: {"type":"l2update","product_id":"BAND-GBP","changes":[["buy","14.7773","0.00"]],"time":"2021-04-17T16:43:41.583826Z"}
1618677821.5790431: {"type":"l2update","product_id":"YFI-BTC","changes":[["sell","0.83216","0.011170"]],"time":"2021-04-17T16:43:41.584028Z"}
1618677821.579115: {"type":"l2update","product_id":"YFI-BTC","changes":[["buy","0.82063","0.014210"]],"time":"2021-04-17T16:43:41.584028Z"}
1618677821.579158: {"type":"l2update","product_id":"YFI-BTC","changes":[["sell","0.83217","0.022300"]],"time":"2021-04-17T16:43:41.584028Z"}
1618677821.579196: {"type":"l2update","product_id":"BAND-BTC","changes":[["buy","0.00033279","0.00"]],"time":"2021-04-17T16:43:41.585152Z"}
1618677821.579246: {"type":"l2update","product_id":"BAND-GBP","changes":[["sell","14.8174","0.00"]],"time":"2021-04-17T16:43:41.585861Z"}
1618677821.579298: {"type":"l2update","product_id":"BAND-GBP","changes":[["buy","14.7772","0.00"]],"time":"2021-04-17T16:43:41.585965Z"}
1618677821.5793478: {"type":"l2update","product_id":"SKL-USD","changes":[["buy","0.7881","7252.8"]],"time":"2021-04-17T16:43:41.591882Z"}
1618677821.579377: {"type":"l2update","product_id":"BAND-BTC","changes":[["sell","0.00033507","19.33"]],"time":"2021-04-17T16:43:41.592311Z"}
1618677821.583838: {"type":"l2update","product_id":"DASH-BTC","changes":[["sell","0.00620946","0.00000000"]],"time":"2021-04-17T16:43:41.596075Z"}
1618677821.591594: {"type":"l2update","product_id":"SKL-USD","changes":[["buy","0.7866","0.0"]],"time":"2021-04-17T16:43:41.607079Z"}
1618677821.594754: {"type":"l2update","product_id":"BAND-BTC","changes":[["sell","0.00033675","0.00"]],"time":"2021-04-17T16:43:41.607752Z"}
1618677821.594823: {"type":"l2update","product_id":"BAND-BTC","changes":[["sell","0.00033548","0.00"]],"time":"2021-04-17T16:43:41.608216Z"}
1618677821.594862: {"type":"l2update","product_id":"BAND-BTC","changes":[["buy","0.00033255","21.34"]],"time":"2021-04-17T16:43:41.610914Z"}
1618677821.606356: {"type":"l2update","product_id":"BAND-BTC","changes":[["buy","0.00033375","0.00"]],"time":"2021-04-17T16:43:41.621504Z"}
1618677821.606456: {"type":"l2update","product_id":"BAND-BTC","changes":[["sell","0.00033640","127.50"]],"time":"2021-04-17T16:43:41.622980Z"}
1618677821.608761: {"type":"l2update","product_id":"BAND-GBP","changes":[["buy","14.7702","27.51"]],"time":"2021-04-17T16:43:41.623067Z"}
1618677821.612193: {"type":"l2update","product_id":"SKL-USD","changes":[["buy","0.7882","25513.9"]],"time":"2021-04-17T16:43:41.626698Z"}
1618677821.619765: {"type":"l2update","product_id":"BAND-GBP","changes":[["buy","14.7475","0.00"]],"time":"2021-04-17T16:43:41.632060Z"}
1618677821.619883: {"type":"l2update","product_id":"DASH-BTC","changes":[["sell","0.00620888","0.00000000"]],"time":"2021-04-17T16:43:41.636339Z"}
1618677821.6260748: {"type":"l2update","product_id":"BAND-GBP","changes":[["sell","14.7993","12.68"]],"time":"2021-04-17T16:43:41.637965Z"}
1618677821.627303: {"type":"l2update","product_id":"BAND-GBP","changes":[["buy","14.7696","12.52"]],"time":"2021-04-17T16:43:41.637985Z"}
1618677821.627414: {"type":"l2update","product_id":"SKL-USD","changes":[["sell","0.8078","6000.0"]],"time":"2021-04-17T16:43:41.640180Z"}
1618677821.63167: {"type":"l2update","product_id":"BAND-BTC","changes":[["buy","0.00033349","70.21"]],"time":"2021-04-17T16:43:41.645185Z"}
1618677821.6462379: {"type":"l2update","product_id":"SKL-USD","changes":[["sell","0.7926","0.0"]],"time":"2021-04-17T16:43:41.661053Z"}
1618677821.646349: {"type":"l2update","product_id":"DASH-BTC","changes":[["sell","0.00621067","2.23600000"]],"time":"2021-04-17T16:43:41.660493Z"}
1618677821.646419: {"type":"l2update","product_id":"BAND-GBP","changes":[["sell","14.8067","0.00"]],"time":"2021-04-17T16:43:41.662759Z"}
1618677821.651526: {"type":"l2update","product_id":"DASH-BTC","changes":[["buy","0.00618762","0.00000000"]],"time":"2021-04-17T16:43:41.666518Z"}
1618677821.656796: {"type":"l2update","product_id":"BAND-GBP","changes":[["sell","14.7992","27.80"]],"time":"2021-04-17T16:43:41.668881Z"}
1618677821.669205: {"type":"l2update","product_id":"DASH-BTC","changes":[["sell","0.00621131","14.63200000"]],"time":"2021-04-17T16:43:41.682722Z"}
1618677821.669307: {"type":"l2update","product_id":"DASH-BTC","changes":[["buy","0.00619037","1.12000000"]],"time":"2021-04-17T16:43:41.686326Z"}
1618677821.6812868: {"type":"l2update","product_id":"SKL-USD","changes":[["sell","0.7927","2525.7"]],"time":"2021-04-17T16:43:41.694171Z"}
1618677821.683012: {"type":"l2update","product_id":"SKL-GBP","changes":[["sell","0.5772","1008.2"]],"time":"2021-04-17T16:43:41.697780Z"}
1618677821.6864681: {"type":"l2update","product_id":"SKL-USD","changes":[["sell","0.7923","1017.5"]],"time":"2021-04-17T16:43:41.701478Z"}
1618677821.691835: {"type":"l2update","product_id":"SKL-USD","changes":[["sell","0.7923","3647.5"]],"time":"2021-04-17T16:43:41.708652Z"}
1618677821.697194: {"type":"l2update","product_id":"SKL-USD","changes":[["buy","0.7901","0.0"]],"time":"2021-04-17T16:43:41.713572Z"}
1618677821.6972601: {"type":"l2update","product_id":"SKL-USD","changes":[["sell","0.7928","0.0"]],"time":"2021-04-17T16:43:41.714240Z"}
1618677821.698687: {"type":"l2update","product_id":"SKL-BTC","changes":[["buy","0.00001305","0.0"]],"time":"2021-04-17T16:43:41.715579Z"}
1618677821.699927: {"type":"l2update","product_id":"YFI-BTC","changes":[["buy","0.82335","0.053010"]],"time":"2021-04-17T16:43:41.715797Z"}
1618677821.7143738: {"type":"l2update","product_id":"BAND-BTC","changes":[["sell","0.00033561","0.00"]],"time":"2021-04-17T16:43:41.727888Z"}
1618677821.714442: {"type":"l2update","product_id":"SKL-USD","changes":[["buy","0.7905","0.0"]],"time":"2021-04-17T16:43:41.728199Z"}
1618677821.714491: {"type":"l2update","product_id":"BAND-BTC","changes":[["buy","0.00033170","469.86"]],"time":"2021-04-17T16:43:41.727888Z"}
1618677821.7145221: {"type":"l2update","product_id":"SKL-GBP","changes":[["sell","0.5787","0.0"]],"time":"2021-04-17T16:43:41.729395Z"}
1618677821.71558: {"type":"l2update","product_id":"SKL-BTC","changes":[["buy","0.00001303","12679.1"]],"time":"2021-04-17T16:43:41.731071Z"}
1618677821.715627: {"type":"l2update","product_id":"SKL-BTC","changes":[["sell","0.00001311","4013.4"]],"time":"2021-04-17T16:43:41.731071Z"}
1618677821.7156549: {"type":"l2update","product_id":"BAND-BTC","changes":[["sell","0.00033521","0.00"]],"time":"2021-04-17T16:43:41.732390Z"}
1618677821.7196229: {"type":"l2update","product_id":"BAND-BTC","changes":[["sell","0.00033673","10.34"]],"time":"2021-04-17T16:43:41.734052Z"}
1618677821.719672: {"type":"l2update","product_id":"SKL-USD","changes":[["buy","0.7882","0.0"]],"time":"2021-04-17T16:43:41.734655Z"}
1618677821.719711: {"type":"l2update","product_id":"BAND-BTC","changes":[["buy","0.00033170","471.26"]],"time":"2021-04-17T16:43:41.734052Z"}
1618677821.719738: {"type":"l2update","product_id":"SKL-USD","changes":[["buy","0.7908","820.0"]],"time":"2021-04-17T16:43:41.735372Z"}
1618677821.724427: {"type":"l2update","product_id":"SKL-GBP","changes":[["sell","0.5784","1258.8"]],"time":"2021-04-17T16:43:41.738035Z"}
1618677821.7244842: {"type":"l2update","product_id":"SKL-USD","changes":[["buy","0.7906","2629.2"]],"time":"2021-04-17T16:43:41.740652Z"}
1618677821.7266262: {"type":"l2update","product_id":"SKL-BTC","changes":[["sell","0.00001309","7032.2"]],"time":"2021-04-17T16:43:41.741441Z"}
1618677821.7350569: {"type":"l2update","product_id":"SKL-USD","changes":[["buy","0.7904","1345.9"]],"time":"2021-04-17T16:43:41.743481Z"}
1618677821.735112: {"type":"l2update","product_id":"SKL-USD","changes":[["buy","0.7906","0.0"]],"time":"2021-04-17T16:43:41.743826Z"}
1618677821.745973: {"type":"l2update","product_id":"SKL-USD","changes":[["buy","0.7866","25513.9"]],"time":"2021-04-17T16:43:41.756309Z"}
1618677821.7460759: {"type":"l2update","product_id":"SKL-USD","changes":[["buy","0.7907","8366.2"]],"time":"2021-04-17T16:43:41.759975Z"}
1618677821.752345: {"type":"l2update","product_id":"SKL-USD","changes":[["buy","0.7904","0.0"]],"time":"2021-04-17T16:43:41.768777Z"}
1618677821.7577631: {"type":"l2update","product_id":"SKL-USD","changes":[["buy","0.7905","1194.0"]],"time":"2021-04-17T16:43:41.771022Z"}
1618677821.760999: {"type":"l2update","product_id":"DASH-BTC","changes":[["sell","0.00620945","0.00000000"]],"time":"2021-04-17T16:43:41.777083Z"}
1618677821.766175: {"type":"l2update","product_id":"SKL-USD","changes":[["buy","0.7903","2390.2"]],"time":"2021-04-17T16:43:41.781572Z"}
1618677821.766232: {"type":"l2update","product_id":"SKL-USD","changes":[["buy","0.7901","867.5"]],"time":"2021-04-17T16:43:41.781688Z"}
1618677821.7718: {"type":"l2update","product_id":"SKL-USD","changes":[["buy","0.7898","0.0"]],"time":"2021-04-17T16:43:41.785392Z"}
1618677821.7740512: {"type":"l2update","product_id":"SKL-USD","changes":[["buy","0.7904","2630.0"]],"time":"2021-04-17T16:43:41.788781Z"}
1618677821.7784991: {"type":"l2update","product_id":"SKL-USD","changes":[["buy","0.7704","0.0"]],"time":"2021-04-17T16:43:41.795772Z"}
1618677821.78178: {"type":"l2update","product_id":"DASH-BTC","changes":[["sell","0.00621067","3.85900000"]],"time":"2021-04-17T16:43:41.796282Z"}
1618677821.783316: {"type":"l2update","product_id":"SKL-USD","changes":[["buy","0.7893","2526.1"]],"time":"2021-04-17T16:43:41.800042Z"}
1618677821.783381: {"type":"l2update","product_id":"SKL-USD","changes":[["sell","0.8082","6005.0"]],"time":"2021-04-17T16:43:41.800179Z"}
1618677821.7874188: {"type":"l2update","product_id":"DASH-BTC","changes":[["sell","0.00621131","0.00000000"]],"time":"2021-04-17T16:43:41.803350Z"}
1618677821.7874932: {"type":"l2update","product_id":"SKL-USD","changes":[["sell","0.8078","0.0"]],"time":"2021-04-17T16:43:41.803434Z"}
1618677821.787536: {"type":"l2update","product_id":"SKL-GBP","changes":[["sell","0.5774","0.0"]],"time":"2021-04-17T16:43:41.803588Z"}
1618677821.7960992: {"type":"l2update","product_id":"BAND-GBP","changes":[["sell","14.7992","0.00"]],"time":"2021-04-17T16:43:41.808292Z"}
1618677821.7961621: {"type":"l2update","product_id":"BAND-GBP","changes":[["buy","14.7700","0.00"]],"time":"2021-04-17T16:43:41.809819Z"}
1618677821.802641: {"type":"l2update","product_id":"DASH-BTC","changes":[["sell","0.00620472","0.00000000"]],"time":"2021-04-17T16:43:41.810010Z"}
1618677821.8027442: {"type":"l2update","product_id":"SKL-USD","changes":[["sell","0.8082","12005.0"]],"time":"2021-04-17T16:43:41.811471Z"}
1618677821.8167858: {"type":"l2update","product_id":"BAND-GBP","changes":[["sell","14.7993","0.00"]],"time":"2021-04-17T16:43:41.819720Z"}
1618677821.8168561: {"type":"l2update","product_id":"SKL-GBP","changes":[["sell","0.5772","3534.5"]],"time":"2021-04-17T16:43:41.823072Z"}
1618677821.816892: {"type":"l2update","product_id":"BAND-GBP","changes":[["sell","14.8076","27.80"]],"time":"2021-04-17T16:43:41.830590Z"}
1618677821.816923: {"type":"l2update","product_id":"DASH-BTC","changes":[["sell","0.00620888","1.62300000"]],"time":"2021-04-17T16:43:41.830666Z"}
1618677821.8185852: {"type":"l2update","product_id":"SKL-BTC","changes":[["buy","0.00001303","12119.1"]],"time":"2021-04-17T16:43:41.831363Z"}
1618677821.8186328: {"type":"l2update","product_id":"SKL-USD","changes":[["sell","0.7923","2630.0"]],"time":"2021-04-17T16:43:41.835484Z"}
1618677821.828653: {"type":"l2update","product_id":"SKL-GBP","changes":[["sell","0.5772","2526.3"]],"time":"2021-04-17T16:43:41.843181Z"}
1618677821.8287208: {"type":"l2update","product_id":"SKL-GBP","changes":[["sell","0.5784","0.0"]],"time":"2021-04-17T16:43:41.843507Z"}
1618677821.856182: {"type":"l2update","product_id":"SKL-BTC","changes":[["sell","0.00001311","2113.4"]],"time":"2021-04-17T16:43:41.856848Z"}
1618677821.856276: {"type":"l2update","product_id":"DASH-BTC","changes":[["buy","0.00451008","0.00000000"]],"time":"2021-04-17T16:43:41.860352Z"}
1618677821.856332: {"type":"l2update","product_id":"DASH-BTC","changes":[["buy","0.00450008","0.00000000"]],"time":"2021-04-17T16:43:41.860352Z"}
1618677821.856367: {"type":"l2update","product_id":"DASH-BTC","changes":[["buy","0.00450007","0.00000000"]],"time":"2021-04-17T16:43:41.860352Z"}
1618677821.856396: {"type":"l2update","product_id":"SKL-USD","changes":[["sell","0.7945","5.0"]],"time":"2021-04-17T16:43:41.861181Z"}
1618677821.8564212: {"type":"l2update","product_id":"DASH-BTC","changes":[["buy","0.00614337","2.34000000"]],"time":"2021-04-17T16:43:41.865145Z"}
1618677821.856451: {"type":"l2update","product_id":"DASH-BTC","changes":[["buy","0.00614336","2.82000000"]],"time":"2021-04-17T16:43:41.865145Z"}
1618677821.859526: {"type":"l2update","product_id":"SKL-USD","changes":[["sell","0.7924","10198.0"]],"time":"2021-04-17T16:43:41.872770Z"}
1618677821.863654: {"type":"l2update","product_id":"BAND-GBP","changes":[["buy","14.7697","36.00"]],"time":"2021-04-17T16:43:41.875959Z"}
1618677821.878779: {"type":"l2update","product_id":"DASH-BTC","changes":[["sell","0.00621141","14.63200000"]],"time":"2021-04-17T16:43:41.886762Z"}
1618677821.878923: {"type":"l2update","product_id":"SKL-USD","changes":[["buy","0.7911","989.7"]],"time":"2021-04-17T16:43:41.890812Z"}
1618677821.878986: {"type":"l2update","product_id":"SKL-USD","changes":[["sell","0.8079","5.0"]],"time":"2021-04-17T16:43:41.893113Z"}
1618677821.87903: {"type":"l2update","product_id":"SKL-BTC","changes":[["buy","0.00001305","110.0"]],"time":"2021-04-17T16:43:41.894288Z"}
1618677821.88901: {"type":"l2update","product_id":"SKL-USD","changes":[["buy","0.7908","370.0"]],"time":"2021-04-17T16:43:41.896600Z"}
1618677821.88911: {"type":"l2update","product_id":"SKL-USD","changes":[["buy","0.7866","0.0"]],"time":"2021-04-17T16:43:41.898212Z"}
1618677821.889195: {"type":"l2update","product_id":"SKL-USD","changes":[["buy","0.7911","1439.7"]],"time":"2021-04-17T16:43:41.901307Z"}
1618677821.889243: {"type":"l2update","product_id":"SKL-BTC","changes":[["buy","0.00001304","4092.8"]],"time":"2021-04-17T16:43:41.901453Z"}
1618677821.8969789: {"type":"l2update","product_id":"BAND-GBP","changes":[["buy","14.7474","0.00"]],"time":"2021-04-17T16:43:41.905520Z"}
1618677821.903519: {"type":"l2update","product_id":"BAND-GBP","changes":[["buy","14.6488","13.40"]],"time":"2021-04-17T16:43:41.912802Z"}
1618677821.903619: {"type":"l2update","product_id":"BAND-GBP","changes":[["buy","14.6487","2.40"]],"time":"2021-04-17T16:43:41.912802Z"}
1618677821.905956: {"type":"l2update","product_id":"SKL-USD","changes":[["buy","0.7882","25513.9"]],"time":"2021-04-17T16:43:41.917335Z"}
1618677821.939138: {"type":"l2update","product_id":"SKL-USD","changes":[["sell","0.8077","6000.0"]],"time":"2021-04-17T16:43:41.946700Z"}
1618677821.943815: {"type":"l2update","product_id":"SKL-BTC","changes":[["buy","0.00001297","5.0"]],"time":"2021-04-17T16:43:41.950310Z"}
1618677821.943941: {"type":"l2update","product_id":"SKL-USD","changes":[["sell","0.8077","12000.0"]],"time":"2021-04-17T16:43:41.954775Z"}
1618677821.9534469: {"type":"l2update","product_id":"BAND-BTC","changes":[["sell","0.00033598","0.94"]],"time":"2021-04-17T16:43:41.962048Z"}
1618677821.953516: {"type":"l2update","product_id":"SKL-USD","changes":[["sell","0.8077","18000.0"]],"time":"2021-04-17T16:43:41.962455Z"}
1618677821.95355: {"type":"l2update","product_id":"SKL-BTC","changes":[["buy","0.00001302","4843.3"]],"time":"2021-04-17T16:43:41.962478Z"}
1618677821.962945: {"type":"l2update","product_id":"SKL-BTC","changes":[["sell","0.00001309","8140.5"]],"time":"2021-04-17T16:43:41.973106Z"}
1618677821.9673522: {"type":"l2update","product_id":"SKL-USD","changes":[["buy","0.7893","0.0"]],"time":"2021-04-17T16:43:41.978761Z"}
1618677821.9674501: {"type":"l2update","product_id":"SKL-USD","changes":[["buy","0.7908","0.0"]],"time":"2021-04-17T16:43:41.979771Z"}
1618677821.9750872: {"type":"l2update","product_id":"SKL-GBP","changes":[["buy","0.5722","10.0"]],"time":"2021-04-17T16:43:41.983356Z"}
1618677821.975151: {"type":"l2update","product_id":"SKL-GBP","changes":[["buy","0.5721","0.0"]],"time":"2021-04-17T16:43:41.983356Z"}
1618677821.975198: {"type":"l2update","product_id":"SKL-GBP","changes":[["sell","0.5780","6313.7"]],"time":"2021-04-17T16:43:41.983356Z"}
1618677821.988332: {"type":"l2update","product_id":"SKL-BTC","changes":[["sell","0.00001311","4013.4"]],"time":"2021-04-17T16:43:41.991736Z"}
1618677821.988393: {"type":"l2update","product_id":"SKL-GBP","changes":[["sell","0.5771","305.0"]],"time":"2021-04-17T16:43:41.991853Z"}
1618677821.9884381: {"type":"l2update","product_id":"SKL-GBP","changes":[["buy","0.5720","950.0"]],"time":"2021-04-17T16:43:41.991853Z"}
1618677821.988466: {"type":"l2update","product_id":"SKL-BTC","changes":[["buy","0.00001304","3085.6"]],"time":"2021-04-17T16:43:41.991929Z"}
1618677821.9884899: {"type":"l2update","product_id":"SKL-GBP","changes":[["buy","0.5689","5.0"]],"time":"2021-04-17T16:43:41.991853Z"}
1618677821.988517: {"type":"l2update","product_id":"SKL-USD","changes":[["buy","0.7862","5.0"]],"time":"2021-04-17T16:43:41.992990Z"}
1618677821.988539: {"type":"l2update","product_id":"SKL-USD","changes":[["buy","0.7828","8446.5"]],"time":"2021-04-17T16:43:41.992990Z"}
1618677821.98856: {"type":"l2update","product_id":"SKL-USD","changes":[["buy","0.7826","1235.0"]],"time":"2021-04-17T16:43:41.992990Z"}
1618677821.98858: {"type":"l2update","product_id":"SKL-USD","changes":[["buy","0.7827","134.2"]],"time":"2021-04-17T16:43:41.992990Z"}
1618677821.9886: {"type":"l2update","product_id":"SKL-USD","changes":[["buy","0.7826","0.0"]],"time":"2021-04-17T16:43:41.992990Z"}
1618677821.988629: {"type":"l2update","product_id":"SKL-USD","changes":[["buy","0.7903","1044.7"]],"time":"2021-04-17T16:43:41.995843Z"}
1618677821.993739: {"type":"l2update","product_id":"SKL-USD","changes":[["sell","0.8028","1000.0"]],"time":"2021-04-17T16:43:42.003379Z"}
1618677822.001756: {"type":"l2update","product_id":"SKL-USD","changes":[["buy","0.7854","10456.5"]],"time":"2021-04-17T16:43:42.010741Z"}
1618677822.001815: {"type":"l2update","product_id":"SKL-USD","changes":[["buy","0.7855","1080.0"]],"time":"2021-04-17T16:43:42.010741Z"}
1618677822.001847: {"type":"l2update","product_id":"SKL-USD","changes":[["buy","0.7856","740.0"]],"time":"2021-04-17T16:43:42.010741Z"}
1618677822.0018718: {"type":"l2update","product_id":"SKL-USD","changes":[["buy","0.7866","25.0"]],"time":"2021-04-17T16:43:42.010741Z"}
1618677822.001903: {"type":"l2update","product_id":"SKL-USD","changes":[["buy","0.7857","10.0"]],"time":"2021-04-17T16:43:42.010741Z"}
1618677822.005405: {"type":"l2update","product_id":"SKL-BTC","changes":[["buy","0.00001305","1117.2"]],"time":"2021-04-17T16:43:42.018222Z"}
1618677822.047458: {"type":"l2update","product_id":"SKL-USD","changes":[["sell","0.7924","6908.0"]],"time":"2021-04-17T16:43:42.043960Z"}
1618677822.0475788: {"type":"l2update","product_id":"CRV-EUR","changes":[["sell","3.3024","0.00"]],"time":"2021-04-17T16:43:42.044016Z"}
1618677822.055864: {"type":"l2update","product_id":"SKL-USD","changes":[["buy","0.7906","989.7"]],"time":"2021-04-17T16:43:42.045389Z"}
1618677822.063232: {"type":"l2update","product_id":"SKL-USD","changes":[["buy","0.7904","3975.5"]],"time":"2021-04-17T16:43:42.046272Z"}
1618677822.06333: {"type":"l2update","product_id":"SKL-USD","changes":[["buy","0.7903","2390.2"]],"time":"2021-04-17T16:43:42.052516Z"}
1618677822.06338: {"type":"l2update","product_id":"SKL-USD","changes":[["buy","0.7748","330.0"]],"time":"2021-04-17T16:43:42.052753Z"}
1618677822.063434: {"type":"l2update","product_id":"SKL-BTC","changes":[["buy","0.00001296","70.0"]],"time":"2021-04-17T16:43:42.054632Z"}
1618677822.063473: {"type":"l2update","product_id":"SKL-BTC","changes":[["buy","0.00001294","125283.5"]],"time":"2021-04-17T16:43:42.055717Z"}
1618677822.068309: {"type":"l2update","product_id":"SKL-USD","changes":[["buy","0.7634","0.0"]],"time":"2021-04-17T16:43:42.061922Z"}
1618677822.068424: {"type":"l2update","product_id":"SKL-USD","changes":[["buy","0.7487","0.0"]],"time":"2021-04-17T16:43:42.061922Z"}
1618677822.068486: {"type":"l2update","product_id":"SKL-BTC","changes":[["sell","0.00001311","4729.9"]],"time":"2021-04-17T16:43:42.068931Z"}
1618677822.0715961: {"type":"l2update","product_id":"SKL-USD","changes":[["buy","0.7882","0.0"]],"time":"2021-04-17T16:43:42.070573Z"}
1618677822.075785: {"type":"l2update","product_id":"SKL-BTC","changes":[["sell","0.00001309","7321.6"]],"time":"2021-04-17T16:43:42.073987Z"}
1618677822.087661: {"type":"l2update","product_id":"SKL-USD","changes":[["buy","0.7904","2630.0"]],"time":"2021-04-17T16:43:42.089373Z"}
1618677822.108816: {"type":"l2update","product_id":"SKL-USD","changes":[["buy","0.7883","25584.9"]],"time":"2021-04-17T16:43:42.104686Z"}
1618677822.123893: {"type":"l2update","product_id":"SKL-USD","changes":[["sell","0.8082","6005.0"]],"time":"2021-04-17T16:43:42.118008Z"}
1618677822.123981: {"type":"l2update","product_id":"SKL-USD","changes":[["buy","0.7660","4085.0"]],"time":"2021-04-17T16:43:42.118133Z"}
1618677822.124053: {"type":"l2update","product_id":"SKL-USD","changes":[["buy","0.7538","5777.0"]],"time":"2021-04-17T16:43:42.118133Z"}
1618677822.124104: {"type":"l2update","product_id":"CRV-EUR","changes":[["buy","3.2966","0.00"]],"time":"2021-04-17T16:43:42.118963Z"}
1618677822.125: {"type":"l2update","product_id":"CRV-EUR","changes":[["sell","3.3027","0.00"]],"time":"2021-04-17T16:43:42.119039Z"}
1618677822.125105: {"type":"l2update","product_id":"CRV-EUR","changes":[["sell","3.3091","0.00"]],"time":"2021-04-17T16:43:42.119123Z"}
1618677822.125165: {"type":"l2update","product_id":"SKL-USD","changes":[["buy","0.7903","1044.7"]],"time":"2021-04-17T16:43:42.119504Z"}
1618677822.1615942: {"type":"l2update","product_id":"YFI-BTC","changes":[["buy","0.82548","0.030174"]],"time":"2021-04-17T16:43:42.144179Z"}
1618677822.161702: {"type":"l2update","product_id":"BAND-BTC","changes":[["sell","0.00033516","0.00"]],"time":"2021-04-17T16:43:42.146238Z"}
1618677822.163248: {"type":"l2update","product_id":"CRV-EUR","changes":[["buy","3.2903","0.00"]],"time":"2021-04-17T16:43:42.152141Z"}
1618677822.173743: {"type":"l2update","product_id":"CRV-EUR","changes":[["buy","3.2955","140.93"]],"time":"2021-04-17T16:43:42.160928Z"}
1618677822.173877: {"type":"l2update","product_id":"CRV-EUR","changes":[["sell","3.3039","140.93"]],"time":"2021-04-17T16:43:42.161225Z"}
1618677822.173938: {"type":"l2update","product_id":"CRV-EUR","changes":[["sell","3.3116","140.93"]],"time":"2021-04-17T16:43:42.161817Z"}
1618677822.176882: {"type":"l2update","product_id":"BAND-BTC","changes":[["sell","0.00033674","10.90"]],"time":"2021-04-17T16:43:42.162665Z"}
1618677822.184111: {"type":"l2update","product_id":"BAND-BTC","changes":[["sell","0.00033682","9.30"]],"time":"2021-04-17T16:43:42.169494Z"}
1618677822.201866: {"type":"l2update","product_id":"SKL-GBP","changes":[["sell","0.5772","0.0"]],"time":"2021-04-17T16:43:42.183843Z"}
1618677822.2110562: {"type":"l2update","product_id":"BAND-BTC","changes":[["buy","0.00033275","19.01"]],"time":"2021-04-17T16:43:42.184804Z"}
1618677822.211157: {"type":"l2update","product_id":"BAND-GBP","changes":[["sell","14.8016","12.11"]],"time":"2021-04-17T16:43:42.188175Z"}
1618677822.2112179: {"type":"l2update","product_id":"SKL-USD","changes":[["buy","0.7911","1804.7"]],"time":"2021-04-17T16:43:42.188264Z"}
1618677822.222846: {"type":"l2update","product_id":"YFI-BTC","changes":[["buy","0.82572","0.000000"]],"time":"2021-04-17T16:43:42.197322Z"}
1618677822.233614: {"type":"l2update","product_id":"CRV-EUR","changes":[["buy","3.2878","397.19"]],"time":"2021-04-17T16:43:42.214623Z"}
1618677822.234348: {"type":"l2update","product_id":"SKL-USD","changes":[["buy","0.7911","815.0"]],"time":"2021-04-17T16:43:42.215766Z"}
1618677822.2344372: {"type":"l2update","product_id":"DASH-BTC","changes":[["buy","0.00619275","0.00000000"]],"time":"2021-04-17T16:43:42.216497Z"}
1618677822.2472231: {"type":"l2update","product_id":"SKL-GBP","changes":[["buy","0.5723","7523.0"]],"time":"2021-04-17T16:43:42.220151Z"}
1618677822.247342: {"type":"l2update","product_id":"SKL-GBP","changes":[["buy","0.5722","0.0"]],"time":"2021-04-17T16:43:42.220151Z"}
1618677822.247417: {"type":"l2update","product_id":"SKL-GBP","changes":[["buy","0.5743","20.0"]],"time":"2021-04-17T16:43:42.220151Z"}
1618677822.252479: {"type":"l2update","product_id":"SKL-USD","changes":[["sell","0.7924","9770.1"]],"time":"2021-04-17T16:43:42.222858Z"}
1618677822.2525818: {"type":"l2update","product_id":"SKL-GBP","changes":[["buy","0.5689","440.0"]],"time":"2021-04-17T16:43:42.228301Z"}
1618677822.256822: {"type":"l2update","product_id":"SKL-USD","changes":[["sell","0.8082","5.0"]],"time":"2021-04-17T16:43:42.239744Z"}
1618677822.261029: {"type":"l2update","product_id":"SKL-USD","changes":[["buy","0.7883","71.0"]],"time":"2021-04-17T16:43:42.241883Z"}
1618677822.261119: {"type":"l2update","product_id":"SKL-USD","changes":[["buy","0.7853","35651.7"]],"time":"2021-04-17T16:43:42.245031Z"}
1618677822.278455: {"type":"l2update","product_id":"DASH-BTC","changes":[["buy","0.00618212","0.00000000"]],"time":"2021-04-17T16:43:42.266351Z"}
1618677822.278541: {"type":"l2update","product_id":"DASH-BTC","changes":[["buy","0.00618444","0.00000000"]],"time":"2021-04-17T16:43:42.267141Z"}
1618677822.294504: {"type":"l2update","product_id":"DASH-BTC","changes":[["buy","0.00619275","2.57000000"]],"time":"2021-04-17T16:43:42.278410Z"}
1618677822.294572: {"type":"l2update","product_id":"DASH-BTC","changes":[["buy","0.00619276","0.00000000"]],"time":"2021-04-17T16:43:42.279324Z"}
1618677822.294614: {"type":"l2update","product_id":"SKL-USD","changes":[["buy","0.7828","0.0"]],"time":"2021-04-17T16:43:42.285524Z"}
1618677822.299445: {"type":"l2update","product_id":"SKL-USD","changes":[["buy","0.7866","25538.9"]],"time":"2021-04-17T16:43:42.291177Z"}
1618677822.3028271: {"type":"l2update","product_id":"BAND-GBP","changes":[["buy","14.7635","12.96"]],"time":"2021-04-17T16:43:42.295287Z"}
1618677822.3029: {"type":"l2update","product_id":"YFI-BTC","changes":[["buy","0.82589","0.017057"]],"time":"2021-04-17T16:43:42.295945Z"}
1618677822.322407: {"type":"l2update","product_id":"BAND-GBP","changes":[["sell","14.8076","0.00"]],"time":"2021-04-17T16:43:42.308387Z"}
1618677822.327411: {"type":"l2update","product_id":"BAND-GBP","changes":[["sell","14.8014","27.80"]],"time":"2021-04-17T16:43:42.313368Z"}
1618677822.332685: {"type":"l2update","product_id":"SKL-USD","changes":[["buy","0.7826","8443.3"]],"time":"2021-04-17T16:43:42.326015Z"}
1618677822.332751: {"type":"l2update","product_id":"SKL-USD","changes":[["sell","0.7923","3647.5"]],"time":"2021-04-17T16:43:42.328913Z"}
1618677822.3327858: {"type":"l2update","product_id":"DASH-BTC","changes":[["buy","0.00619214","1.57200000"]],"time":"2021-04-17T16:43:42.329084Z"}
1618677822.353643: {"type":"l2update","product_id":"YFI-BTC","changes":[["buy","0.82548","0.000000"]],"time":"2021-04-17T16:43:42.346052Z"}
1618677822.3635619: {"type":"l2update","product_id":"SKL-BTC","changes":[["buy","0.00001297","2639.3"]],"time":"2021-04-17T16:43:42.355278Z"}
1618677822.3726468: {"type":"l2update","product_id":"SKL-BTC","changes":[["buy","0.00001299","1976.2"]],"time":"2021-04-17T16:43:42.363109Z"}
1618677822.3836238: {"type":"l2update","product_id":"SKL-USD","changes":[["buy","0.7860","505.0"]],"time":"2021-04-17T16:43:42.366821Z"}
1618677822.391986: {"type":"l2update","product_id":"SKL-GBP","changes":[["sell","0.5771","1313.2"]],"time":"2021-04-17T16:43:42.385206Z"}
1618677822.400424: {"type":"l2update","product_id":"CRV-EUR","changes":[["buy","3.2981","508.97"]],"time":"2021-04-17T16:43:42.389790Z"}
1618677822.400558: {"type":"l2update","product_id":"SKL-USD","changes":[["sell","0.7942","31665.1"]],"time":"2021-04-17T16:43:42.393795Z"}
1618677822.4087849: {"type":"l2update","product_id":"CRV-EUR","changes":[["sell","3.3039","0.00"]],"time":"2021-04-17T16:43:42.401661Z"}
1618677822.4215171: {"type":"l2update","product_id":"SKL-USD","changes":[["sell","0.7924","6908.0"]],"time":"2021-04-17T16:43:42.408443Z"}
1618677822.426482: {"type":"l2update","product_id":"CRV-EUR","changes":[["buy","3.2970","0.00"]],"time":"2021-04-17T16:43:42.416643Z"}
1618677822.430368: {"type":"l2update","product_id":"BAND-BTC","changes":[["sell","0.00033507","45.33"]],"time":"2021-04-17T16:43:42.417918Z"}
1618677822.430449: {"type":"l2update","product_id":"BAND-BTC","changes":[["sell","0.00033506","31.74"]],"time":"2021-04-17T16:43:42.418111Z"}
1618677822.430515: {"type":"l2update","product_id":"SKL-USD","changes":[["buy","0.7901","0.0"]],"time":"2021-04-17T16:43:42.423757Z"}
1618677822.438498: {"type":"l2update","product_id":"SKL-BTC","changes":[["buy","0.00001305","1007.2"]],"time":"2021-04-17T16:43:42.429352Z"}
1618677822.4535549: {"type":"l2update","product_id":"SKL-USD","changes":[["buy","0.7911","365.0"]],"time":"2021-04-17T16:43:42.433439Z"}
1618677822.453612: {"type":"l2update","product_id":"SKL-USD","changes":[["buy","0.7908","450.0"]],"time":"2021-04-17T16:43:42.436549Z"}
1618677822.454476: {"type":"l2update","product_id":"BAND-GBP","changes":[["buy","14.7320","49.42"]],"time":"2021-04-17T16:43:42.440370Z"}
1618677822.454541: {"type":"l2update","product_id":"CRV-EUR","changes":[["sell","3.3045","140.93"]],"time":"2021-04-17T16:43:42.440795Z"}
1618677822.454582: {"type":"l2update","product_id":"BAND-BTC","changes":[["sell","0.00033506","61.39"]],"time":"2021-04-17T16:43:42.443469Z"}
1618677822.4546099: {"type":"l2update","product_id":"CRV-EUR","changes":[["buy","3.2976","140.93"]],"time":"2021-04-17T16:43:42.456270Z"}
1618677822.465253: {"type":"l2update","product_id":"SKL-USD","changes":[["sell","0.7923","2630.0"]],"time":"2021-04-17T16:43:42.465248Z"}
1618677822.465307: {"type":"l2update","product_id":"SKL-USD","changes":[["buy","0.7889","868.8"]],"time":"2021-04-17T16:43:42.474317Z"}
1618677822.465347: {"type":"l2update","product_id":"SKL-GBP","changes":[["sell","0.5771","305.0"]],"time":"2021-04-17T16:43:42.474744Z"}
1618677822.465374: {"type":"l2update","product_id":"SKL-USD","changes":[["buy","0.7908","0.0"]],"time":"2021-04-17T16:43:42.476059Z"}
1618677822.469849: {"type":"l2update","product_id":"BAND-GBP","changes":[["sell","14.8014","0.00"]],"time":"2021-04-17T16:43:42.479661Z"}
1618677822.469909: {"type":"l2update","product_id":"BAND-GBP","changes":[["sell","14.8016","0.00"]],"time":"2021-04-17T16:43:42.481886Z"}
1618677822.469943: {"type":"l2update","product_id":"SKL-USD","changes":[["buy","0.7911","815.0"]],"time":"2021-04-17T16:43:42.483185Z"}
1618677822.479451: {"type":"l2update","product_id":"BAND-BTC","changes":[["sell","0.00033506","31.74"]],"time":"2021-04-17T16:43:42.484830Z"}
1618677822.479542: {"type":"l2update","product_id":"DASH-BTC","changes":[["sell","0.00621141","0.00000000"]],"time":"2021-04-17T16:43:42.488387Z"}
1618677822.479615: {"type":"l2update","product_id":"SKL-USD","changes":[["buy","0.7911","365.0"]],"time":"2021-04-17T16:43:42.492992Z"}
1618677822.4921112: {"type":"l2update","product_id":"SKL-USD","changes":[["sell","0.7922","1017.5"]],"time":"2021-04-17T16:43:42.497082Z"}
1618677822.492249: {"type":"l2update","product_id":"SKL-USD","changes":[["buy","0.7908","450.0"]],"time":"2021-04-17T16:43:42.497096Z"}
1618677822.492312: {"type":"l2update","product_id":"BAND-GBP","changes":[["sell","14.8086","27.80"]],"time":"2021-04-17T16:43:42.497477Z"}
1618677822.492364: {"type":"l2update","product_id":"BAND-BTC","changes":[["sell","0.00033507","19.33"]],"time":"2021-04-17T16:43:42.500684Z"}
1618677822.492405: {"type":"l2update","product_id":"SKL-BTC","changes":[["sell","0.00001308","8635.2"]],"time":"2021-04-17T16:43:42.501575Z"}
1618677822.492449: {"type":"l2update","product_id":"SKL-BTC","changes":[["sell","0.00001308","5790.0"]],"time":"2021-04-17T16:43:42.501575Z"}
1618677822.49249: {"type":"l2update","product_id":"SKL-BTC","changes":[["sell","0.00001323","5.0"]],"time":"2021-04-17T16:43:42.501575Z"}
1618677822.492918: {"type":"l2update","product_id":"SKL-GBP","changes":[["sell","0.5771","1313.2"]],"time":"2021-04-17T16:43:42.507442Z"}
1618677822.500854: {"type":"l2update","product_id":"SKL-USD","changes":[["sell","0.7922","0.0"]],"time":"2021-04-17T16:43:42.513650Z"}
1618677822.515614: {"type":"l2update","product_id":"CRV-EUR","changes":[["sell","3.3201","315.50"]],"time":"2021-04-17T16:43:42.521673Z"}
1618677822.515737: {"type":"l2update","product_id":"CRV-EUR","changes":[["sell","3.3201","223.50"]],"time":"2021-04-17T16:43:42.521673Z"}
1618677822.515788: {"type":"l2update","product_id":"CRV-EUR","changes":[["sell","3.3201","126.50"]],"time":"2021-04-17T16:43:42.521673Z"}
1618677822.515828: {"type":"l2update","product_id":"CRV-EUR","changes":[["buy","3.2698","100.00"]],"time":"2021-04-17T16:43:42.521673Z"}
1618677822.515866: {"type":"l2update","product_id":"SKL-GBP","changes":[["sell","0.5771","305.0"]],"time":"2021-04-17T16:43:42.523426Z"}
1618677822.515906: {"type":"l2update","product_id":"CRV-EUR","changes":[["sell","3.3199","83.50"]],"time":"2021-04-17T16:43:42.526341Z"}
1618677822.515969: {"type":"l2update","product_id":"CRV-EUR","changes":[["buy","3.2697","1.00"]],"time":"2021-04-17T16:43:42.526341Z"}
1618677822.516014: {"type":"l2update","product_id":"CRV-EUR","changes":[["sell","3.3201","236.50"]],"time":"2021-04-17T16:43:42.526341Z"}
1618677822.516036: {"type":"l2update","product_id":"SKL-USD","changes":[["sell","0.7922","1017.5"]],"time":"2021-04-17T16:43:42.526551Z"}
1618677822.516628: {"type":"l2update","product_id":"SKL-USD","changes":[["sell","0.7922","0.0"]],"time":"2021-04-17T16:43:42.531315Z"}
1618677822.526888: {"type":"l2update","product_id":"SKL-USD","changes":[["buy","0.7906","0.0"]],"time":"2021-04-17T16:43:42.540587Z"}
1618677822.5299919: {"type":"l2update","product_id":"SKL-BTC","changes":[["buy","0.00001304","2100.1"]],"time":"2021-04-17T16:43:42.543495Z"}
1618677822.535594: {"type":"l2update","product_id":"DASH-BTC","changes":[["buy","0.00618541","5.56100000"]],"time":"2021-04-17T16:43:42.545069Z"}
1618677822.541554: {"type":"l2update","product_id":"DASH-BTC","changes":[["buy","0.00618776","1.39000000"]],"time":"2021-04-17T16:43:42.552505Z"}
1618677822.541611: {"type":"l2update","product_id":"SKL-BTC","changes":[["buy","0.00001302","5833.0"]],"time":"2021-04-17T16:43:42.552701Z"}
1618677822.541651: {"type":"l2update","product_id":"SKL-USD","changes":[["sell","0.8077","12000.0"]],"time":"2021-04-17T16:43:42.555046Z"}
1618677822.546421: {"type":"l2update","product_id":"SKL-BTC","changes":[["sell","0.00001311","4013.4"]],"time":"2021-04-17T16:43:42.557151Z"}
1618677822.546487: {"type":"l2update","product_id":"SKL-USD","changes":[["buy","0.7907","7500.0"]],"time":"2021-04-17T16:43:42.559785Z"}
1618677822.5516832: {"type":"l2update","product_id":"SKL-USD","changes":[["sell","0.8082","6005.0"]],"time":"2021-04-17T16:43:42.563489Z"}
1618677822.555747: {"type":"l2update","product_id":"BAND-BTC","changes":[["sell","0.00033507","0.00"]],"time":"2021-04-17T16:43:42.567753Z"}
1618677822.555804: {"type":"l2update","product_id":"SKL-BTC","changes":[["sell","0.00001309","8038.1"]],"time":"2021-04-17T16:43:42.567279Z"}
1618677822.555834: {"type":"l2update","product_id":"SKL-USD","changes":[["sell","0.8077","6000.0"]],"time":"2021-04-17T16:43:42.568376Z"}
1618677822.5577118: {"type":"l2update","product_id":"BAND-GBP","changes":[["sell","14.8096","0.00"]],"time":"2021-04-17T16:43:42.572067Z"}
1618677822.557767: {"type":"l2update","product_id":"NMR-EUR","changes":[["buy","66.4813","0.000"]],"time":"2021-04-17T16:43:42.572139Z"}
1618677822.557802: {"type":"l2update","product_id":"DASH-BTC","changes":[["sell","0.00620870","14.63200000"]],"time":"2021-04-17T16:43:42.574236Z"}
1618677822.571569: {"type":"l2update","product_id":"SKL-USD","changes":[["buy","0.7806","0.0"]],"time":"2021-04-17T16:43:42.576299Z"}
1618677822.572875: {"type":"l2update","product_id":"SKL-USD","changes":[["sell","0.8082","12005.0"]],"time":"2021-04-17T16:43:42.578149Z"}
1618677822.572921: {"type":"l2update","product_id":"SKL-USD","changes":[["buy","0.7905","2060.4"]],"time":"2021-04-17T16:43:42.581721Z"}
1618677822.572947: {"type":"l2update","product_id":"DASH-BTC","changes":[["sell","0.00620479","2.66700000"]],"time":"2021-04-17T16:43:42.581857Z"}
1618677822.575116: {"type":"l2update","product_id":"DASH-BTC","changes":[["sell","0.00620479","0.00000000"]],"time":"2021-04-17T16:43:42.588267Z"}
1618677822.5808299: {"type":"l2update","product_id":"BAND-GBP","changes":[["sell","14.8224","12.67"]],"time":"2021-04-17T16:43:42.593070Z"}
1618677822.580877: {"type":"l2update","product_id":"SKL-USD","changes":[["buy","0.7866","28173.7"]],"time":"2021-04-17T16:43:42.593141Z"}
1618677822.593589: {"type":"l2update","product_id":"DASH-BTC","changes":[["sell","0.00620888","0.00000000"]],"time":"2021-04-17T16:43:42.604465Z"}
1618677822.595883: {"type":"l2update","product_id":"DASH-BTC","changes":[["sell","0.00621067","1.62300000"]],"time":"2021-04-17T16:43:42.608882Z"}
1618677822.6098182: {"type":"l2update","product_id":"BAND-BTC","changes":[["sell","0.00033537","0.00"]],"time":"2021-04-17T16:43:42.626103Z"}
1618677822.614468: {"type":"l2update","product_id":"YFI-BTC","changes":[["buy","0.82510","0.030000"]],"time":"2021-04-17T16:43:42.626283Z"}
1618677822.614571: {"type":"l2update","product_id":"DASH-BTC","changes":[["sell","0.00620472","1.62300000"]],"time":"2021-04-17T16:43:42.626324Z"}
1618677822.621981: {"type":"l2update","product_id":"NMR-EUR","changes":[["buy","66.4814","13.000"]],"time":"2021-04-17T16:43:42.637576Z"}
1618677822.622085: {"type":"l2update","product_id":"DASH-BTC","changes":[["sell","0.00620869","2.23600000"]],"time":"2021-04-17T16:43:42.637663Z"}
1618677822.6490052: {"type":"l2update","product_id":"SKL-BTC","changes":[["buy","0.00001300","10470.1"]],"time":"2021-04-17T16:43:42.654665Z"}
1618677822.649099: {"type":"l2update","product_id":"SKL-BTC","changes":[["buy","0.00001300","7503.5"]],"time":"2021-04-17T16:43:42.654665Z"}
1618677822.6527941: {"type":"l2update","product_id":"DASH-BTC","changes":[["buy","0.00619214","1.54200000"]],"time":"2021-04-17T16:43:42.662285Z"}
1618677822.6528928: {"type":"l2update","product_id":"DASH-BTC","changes":[["sell","0.00620473","0.00000000"]],"time":"2021-04-17T16:43:42.663150Z"}
1618677822.659285: {"type":"l2update","product_id":"BAND-BTC","changes":[["sell","0.00033542","36.70"]],"time":"2021-04-17T16:43:42.672427Z"}
1618677822.662613: {"type":"l2update","product_id":"NU-GBP","changes":[["buy","0.4325","0.000000"]],"time":"2021-04-17T16:43:42.677598Z"}
1618677822.672182: {"type":"l2update","product_id":"DASH-BTC","changes":[["buy","0.00619276","0.03000000"]],"time":"2021-04-17T16:43:42.684394Z"}
1618677822.681941: {"type":"l2update","product_id":"YFI-BTC","changes":[["buy","0.82064","0.000000"]],"time":"2021-04-17T16:43:42.695553Z"}
1618677822.6820512: {"type":"l2update","product_id":"NU-GBP","changes":[["buy","0.4318","9182.000000"]],"time":"2021-04-17T16:43:42.695886Z"}
1618677822.6830962: {"type":"l2update","product_id":"SKL-USD","changes":[["buy","0.7908","0.0"]],"time":"2021-04-17T16:43:42.699004Z"}
1618677822.6832058: {"type":"l2update","product_id":"YFI-BTC","changes":[["buy","0.82314","0.000540"]],"time":"2021-04-17T16:43:42.699511Z"}
1618677822.684117: {"type":"l2update","product_id":"SKL-BTC","changes":[["buy","0.00001303","13108.8"]],"time":"2021-04-17T16:43:42.699775Z"}
1618677822.689203: {"type":"l2update","product_id":"SKL-USD","changes":[["buy","0.7911","815.0"]],"time":"2021-04-17T16:43:42.703173Z"}
1618677822.695661: {"type":"l2update","product_id":"SKL-USD","changes":[["buy","0.7911","365.0"]],"time":"2021-04-17T16:43:42.705036Z"}
1618677822.69755: {"type":"l2update","product_id":"DASH-BTC","changes":[["sell","0.00620471","2.57100000"]],"time":"2021-04-17T16:43:42.710971Z"}
1618677822.6976159: {"type":"l2update","product_id":"SKL-USD","changes":[["buy","0.7908","450.0"]],"time":"2021-04-17T16:43:42.711325Z"}
1618677822.7165198: {"type":"l2update","product_id":"SKL-USD","changes":[["sell","0.7923","3647.5"]],"time":"2021-04-17T16:43:42.726157Z"}
1618677822.716577: {"type":"l2update","product_id":"SKL-GBP","changes":[["sell","0.5771","1313.2"]],"time":"2021-04-17T16:43:42.726548Z"}
1618677822.71661: {"type":"l2update","product_id":"SKL-USD","changes":[["sell","0.8076","6000.0"]],"time":"2021-04-17T16:43:42.726526Z"}
1618677822.717925: {"type":"l2update","product_id":"BAND-BTC","changes":[["buy","0.00033449","192.32"]],"time":"2021-04-17T16:43:42.734967Z"}
1618677822.723264: {"type":"l2update","product_id":"SKL-USD","changes":[["buy","0.7806","74248.1"]],"time":"2021-04-17T16:43:42.737806Z"}
1618677822.7233229: {"type":"l2update","product_id":"SKL-USD","changes":[["sell","0.7922","3252.6"]],"time":"2021-04-17T16:43:42.737806Z"}
1618677822.726602: {"type":"l2update","product_id":"SKL-GBP","changes":[["sell","0.5784","1258.8"]],"time":"2021-04-17T16:43:42.741514Z"}
1618677822.731127: {"type":"l2update","product_id":"SKL-USD","changes":[["sell","0.7923","2630.0"]],"time":"2021-04-17T16:43:42.743794Z"}
1618677822.731176: {"type":"l2update","product_id":"BAND-BTC","changes":[["sell","0.00033506","0.00"]],"time":"2021-04-17T16:43:42.743618Z"}
1618677822.7312179: {"type":"l2update","product_id":"BAND-BTC","changes":[["sell","0.00033522","0.00"]],"time":"2021-04-17T16:43:42.745197Z"}
1618677822.73541: {"type":"l2update","product_id":"SKL-USD","changes":[["sell","0.7922","4270.1"]],"time":"2021-04-17T16:43:42.748739Z"}
1618677822.7454631: {"type":"l2update","product_id":"SKL-USD","changes":[["buy","0.7905","866.4"]],"time":"2021-04-17T16:43:42.753350Z"}
1618677822.745518: {"type":"l2update","product_id":"BAND-BTC","changes":[["sell","0.00033517","0.00"]],"time":"2021-04-17T16:43:42.754803Z"}
1618677822.745562: {"type":"l2update","product_id":"DASH-BTC","changes":[["buy","0.00619274","0.00000000"]],"time":"2021-04-17T16:43:42.755969Z"}
1618677822.745606: {"type":"l2update","product_id":"BAND-BTC","changes":[["buy","0.00033449","215.32"]],"time":"2021-04-17T16:43:42.756099Z"}
1618677822.746345: {"type":"l2update","product_id":"BAND-BTC","changes":[["buy","0.00033287","18.29"]],"time":"2021-04-17T16:43:42.760278Z"}
1618677822.75387: {"type":"l2update","product_id":"SKL-USD","changes":[["sell","0.7923","0.0"]],"time":"2021-04-17T16:43:42.767209Z"}
1618677822.76074: {"type":"l2update","product_id":"BAND-BTC","changes":[["sell","0.00033525","29.65"]],"time":"2021-04-17T16:43:42.775682Z"}
1618677822.7661388: {"type":"l2update","product_id":"BAND-BTC","changes":[["buy","0.00033349","49.42"]],"time":"2021-04-17T16:43:42.780688Z"}
1618677822.766198: {"type":"l2update","product_id":"SKL-USD","changes":[["buy","0.7904","3824.2"]],"time":"2021-04-17T16:43:42.782797Z"}
1618677822.767492: {"type":"l2update","product_id":"BAND-BTC","changes":[["buy","0.00033349","20.79"]],"time":"2021-04-17T16:43:42.785368Z"}
1618677822.774941: {"type":"l2update","product_id":"BAND-BTC","changes":[["buy","0.00033349","0.00"]],"time":"2021-04-17T16:43:42.788269Z"}
1618677822.779213: {"type":"l2update","product_id":"DASH-BTC","changes":[["sell","0.00864891","0.27000000"]],"time":"2021-04-17T16:43:42.794055Z"}
1618677822.7880452: {"type":"l2update","product_id":"DASH-BTC","changes":[["sell","0.00864891","2.91000000"]],"time":"2021-04-17T16:43:42.801478Z"}
1618677822.7881489: {"type":"l2update","product_id":"BAND-BTC","changes":[["buy","0.00033375","20.77"]],"time":"2021-04-17T16:43:42.801552Z"}
1618677822.788223: {"type":"l2update","product_id":"BAND-GBP","changes":[["sell","14.8129","0.00"]],"time":"2021-04-17T16:43:42.803737Z"}
1618677822.791111: {"type":"l2update","product_id":"SKL-USD","changes":[["sell","0.7923","2629.9"]],"time":"2021-04-17T16:43:42.805271Z"}
1618677822.79637: {"type":"l2update","product_id":"BAND-GBP","changes":[["buy","14.7775","12.75"]],"time":"2021-04-17T16:43:42.808964Z"}
1618677822.8028212: {"type":"l2update","product_id":"BAND-BTC","changes":[["buy","0.00033375","49.38"]],"time":"2021-04-17T16:43:42.816368Z"}
1618677822.802924: {"type":"l2update","product_id":"SKL-BTC","changes":[["buy","0.00001300","10919.0"]],"time":"2021-04-17T16:43:42.816382Z"}
1618677822.8029802: {"type":"l2update","product_id":"SKL-BTC","changes":[["sell","0.00001307","3223.7"]],"time":"2021-04-17T16:43:42.816382Z"}
1618677822.803042: {"type":"l2update","product_id":"SKL-BTC","changes":[["sell","0.00001321","22310.6"]],"time":"2021-04-17T16:43:42.816382Z"}
1618677822.807214: {"type":"l2update","product_id":"DASH-BTC","changes":[["sell","0.00620277","0.00000000"]],"time":"2021-04-17T16:43:42.822421Z"}
1618677822.811347: {"type":"l2update","product_id":"SKL-BTC","changes":[["sell","0.00001308","4680.9"]],"time":"2021-04-17T16:43:42.826992Z"}
1618677822.8114: {"type":"l2update","product_id":"BAND-BTC","changes":[["buy","0.00033375","70.15"]],"time":"2021-04-17T16:43:42.827660Z"}
1618677822.811428: {"type":"l2update","product_id":"SKL-BTC","changes":[["sell","0.00001307","4332.8"]],"time":"2021-04-17T16:43:42.827634Z"}
1618677822.812402: {"type":"l2update","product_id":"DASH-BTC","changes":[["sell","0.00620870","0.00000000"]],"time":"2021-04-17T16:43:42.829472Z"}
1618677822.814226: {"type":"l2update","product_id":"CRV-EUR","changes":[["sell","3.3037","0.00"]],"time":"2021-04-17T16:43:42.831441Z"}
1618677822.8191822: {"type":"l2update","product_id":"SKL-BTC","changes":[["sell","0.00001308","893.4"]],"time":"2021-04-17T16:43:42.834168Z"}
1618677822.822701: {"type":"l2update","product_id":"BAND-GBP","changes":[["buy","14.7702","0.00"]],"time":"2021-04-17T16:43:42.837928Z"}
1618677822.824854: {"type":"l2update","product_id":"CRV-EUR","changes":[["sell","3.3036","0.00"]],"time":"2021-04-17T16:43:42.840277Z"}
1618677822.828327: {"type":"l2update","product_id":"BAND-GBP","changes":[["buy","14.7775","40.25"]],"time":"2021-04-17T16:43:42.844156Z"}
1618677822.828358: {"type":"l2update","product_id":"SKL-BTC","changes":[["sell","0.00001310","10601.7"]],"time":"2021-04-17T16:43:42.844195Z"}
1618677822.832625: {"type":"l2update","product_id":"SKL-BTC","changes":[["sell","0.00001307","8121.7"]],"time":"2021-04-17T16:43:42.847546Z"}
1618677822.8326569: {"type":"l2update","product_id":"CRV-EUR","changes":[["sell","3.3043","5000.00"]],"time":"2021-04-17T16:43:42.847659Z"}
1618677822.840287: {"type":"l2update","product_id":"SKL-BTC","changes":[["buy","0.00001302","4843.3"]],"time":"2021-04-17T16:43:42.850849Z"}
1618677822.840317: {"type":"l2update","product_id":"SKL-BTC","changes":[["sell","0.00001308","0.0"]],"time":"2021-04-17T16:43:42.854477Z"}
1618677822.840342: {"type":"l2update","product_id":"CRV-EUR","changes":[["buy","3.2988","524.58"]],"time":"2021-04-17T16:43:42.855138Z"}
1618677822.840364: {"type":"l2update","product_id":"CRV-EUR","changes":[["sell","3.3043","5097.66"]],"time":"2021-04-17T16:43:42.855178Z"}
1618677822.841532: {"type":"l2update","product_id":"SKL-BTC","changes":[["sell","0.00001311","4729.9"]],"time":"2021-04-17T16:43:42.858622Z"}
1618677822.845609: {"type":"l2update","product_id":"SKL-BTC","changes":[["sell","0.00001309","7321.6"]],"time":"2021-04-17T16:43:42.861492Z"}
1618677822.8456361: {"type":"l2update","product_id":"SKL-BTC","changes":[["buy","0.00001304","1438.6"]],"time":"2021-04-17T16:43:42.861918Z"}
1618677822.854252: {"type":"l2update","product_id":"CRV-EUR","changes":[["buy","3.2983","0.00"]],"time":"2021-04-17T16:43:42.863929Z"}
1618677822.8542879: {"type":"l2update","product_id":"CRV-EUR","changes":[["buy","3.2960","0.00"]],"time":"2021-04-17T16:43:42.866536Z"}
1618677822.8543098: {"type":"l2update","product_id":"SKL-USD","changes":[["sell","0.8076","12000.0"]],"time":"2021-04-17T16:43:42.866583Z"}
1618677822.854327: {"type":"l2update","product_id":"SKL-BTC","changes":[["buy","0.00001303","12192.7"]],"time":"2021-04-17T16:43:42.866937Z"}
1618677822.8543448: {"type":"l2update","product_id":"CRV-EUR","changes":[["sell","3.3043","5000.00"]],"time":"2021-04-17T16:43:42.868865Z"}
1618677822.854358: {"type":"l2update","product_id":"DASH-BTC","changes":[["buy","0.00619036","0.00000000"]],"time":"2021-04-17T16:43:42.869256Z"}
1618677822.854377: {"type":"l2update","product_id":"CRV-EUR","changes":[["buy","3.2989","96.85"]],"time":"2021-04-17T16:43:42.870042Z"}
1618677822.854392: {"type":"l2update","product_id":"SKL-BTC","changes":[["buy","0.00001303","11527.5"]],"time":"2021-04-17T16:43:42.870678Z"}
1618677822.8670762: {"type":"l2update","product_id":"DASH-BTC","changes":[["sell","0.00620650","0.00000000"]],"time":"2021-04-17T16:43:42.882007Z"}
1618677822.873461: {"type":"l2update","product_id":"YFI-BTC","changes":[["buy","0.82608","0.019863"]],"time":"2021-04-17T16:43:42.884963Z"}
1618677822.878686: {"type":"l2update","product_id":"SKL-BTC","changes":[["buy","0.00001303","12189.5"]],"time":"2021-04-17T16:43:42.889000Z"}
1618677822.878758: {"type":"l2update","product_id":"BAND-BTC","changes":[["buy","0.00033449","341.31"]],"time":"2021-04-17T16:43:42.889069Z"}
1618677822.878777: {"type":"l2update","product_id":"BAND-GBP","changes":[["buy","14.7635","0.00"]],"time":"2021-04-17T16:43:42.889122Z"}
1618677822.8788: {"type":"l2update","product_id":"SKL-USD","changes":[["buy","0.7806","0.0"]],"time":"2021-04-17T16:43:42.892338Z"}
1618677822.878819: {"type":"l2update","product_id":"SKL-USD","changes":[["sell","0.7922","1017.5"]],"time":"2021-04-17T16:43:42.892338Z"}
1618677822.8788328: {"type":"l2update","product_id":"CRV-EUR","changes":[["buy","3.2974","5532.81"]],"time":"2021-04-17T16:43:42.892569Z"}
1618677822.878846: {"type":"l2update","product_id":"BAND-GBP","changes":[["buy","14.7843","12.99"]],"time":"2021-04-17T16:43:42.892680Z"}
1618677822.87886: {"type":"l2update","product_id":"YFI-BTC","changes":[["buy","0.82533","0.000000"]],"time":"2021-04-17T16:43:42.894223Z"}
1618677822.888421: {"type":"l2update","product_id":"SKL-BTC","changes":[["sell","0.00001308","893.7"]],"time":"2021-04-17T16:43:42.896228Z"}
1618677822.888459: {"type":"l2update","product_id":"SKL-BTC","changes":[["buy","0.00001302","5760.1"]],"time":"2021-04-17T16:43:42.900183Z"}
1618677822.890919: {"type":"l2update","product_id":"DASH-BTC","changes":[["buy","0.00619644","2.15500000"]],"time":"2021-04-17T16:43:42.903634Z"}
1618677822.896878: {"type":"l2update","product_id":"DASH-BTC","changes":[["buy","0.00618188","0.00000000"]],"time":"2021-04-17T16:43:42.910351Z"}
1618677822.896915: {"type":"l2update","product_id":"DASH-BTC","changes":[["sell","0.00621368","6.01700000"]],"time":"2021-04-17T16:43:42.910585Z"}
1618677822.8969338: {"type":"l2update","product_id":"SKL-BTC","changes":[["buy","0.00001302","6425.8"]],"time":"2021-04-17T16:43:42.910975Z"}
1618677822.896949: {"type":"l2update","product_id":"CRV-EUR","changes":[["sell","3.3065","0.00"]],"time":"2021-04-17T16:43:42.912734Z"}
1618677822.901068: {"type":"l2update","product_id":"DASH-BTC","changes":[["buy","0.00619644","3.25500000"]],"time":"2021-04-17T16:43:42.915047Z"}
1618677822.901098: {"type":"l2update","product_id":"DASH-BTC","changes":[["sell","0.00621120","14.63200000"]],"time":"2021-04-17T16:43:42.915107Z"}
1618677822.901123: {"type":"l2update","product_id":"DASH-BTC","changes":[["sell","0.00620181","0.00000000"]],"time":"2021-04-17T16:43:42.916005Z"}
1618677822.9042702: {"type":"l2update","product_id":"CRV-EUR","changes":[["buy","3.2894","0.00"]],"time":"2021-04-17T16:43:42.921537Z"}
1618677822.930024: {"type":"l2update","product_id":"CRV-EUR","changes":[["sell","3.3112","254.45"]],"time":"2021-04-17T16:43:42.922278Z"}
1618677822.930059: {"type":"l2update","product_id":"DASH-BTC","changes":[["buy","0.00618472","0.00000000"]],"time":"2021-04-17T16:43:42.924022Z"}
1618677822.930084: {"type":"l2update","product_id":"DASH-BTC","changes":[["buy","0.00618746","0.00000000"]],"time":"2021-04-17T16:43:42.924134Z"}
1618677822.930102: {"type":"l2update","product_id":"DASH-BTC","changes":[["buy","0.00618587","0.00000000"]],"time":"2021-04-17T16:43:42.924183Z"}
1618677822.9301171: {"type":"l2update","product_id":"DASH-BTC","changes":[["sell","0.00621783","0.00000000"]],"time":"2021-04-17T16:43:42.929331Z"}
1618677822.930133: {"type":"l2update","product_id":"DASH-BTC","changes":[["sell","0.00621368","0.00000000"]],"time":"2021-04-17T16:43:42.930227Z"}
1618677822.9301481: {"type":"l2update","product_id":"DASH-BTC","changes":[["sell","0.00620472","0.00000000"]],"time":"2021-04-17T16:43:42.939085Z"}
1618677822.930163: {"type":"l2update","product_id":"DASH-BTC","changes":[["sell","0.00621067","0.00000000"]],"time":"2021-04-17T16:43:42.942520Z"}
1618677822.930181: {"type":"l2update","product_id":"DASH-BTC","changes":[["sell","0.00864891","2.64000000"]],"time":"2021-04-17T16:43:42.944701Z"}
1618677822.9384909: {"type":"l2update","product_id":"DASH-BTC","changes":[["sell","0.00864891","4.51000000"]],"time":"2021-04-17T16:43:42.949746Z"}
1618677822.9385228: {"type":"l2update","product_id":"DASH-BTC","changes":[["buy","0.00619170","32.84700000"]],"time":"2021-04-17T16:43:42.953044Z"}
1618677822.944932: {"type":"l2update","product_id":"BAND-GBP","changes":[["buy","14.7775","12.75"]],"time":"2021-04-17T16:43:42.960761Z"}
1618677822.9558442: {"type":"l2update","product_id":"SKL-BTC","changes":[["buy","0.00001300","7503.5"]],"time":"2021-04-17T16:43:42.970493Z"}
1618677822.9583192: {"type":"l2update","product_id":"NU-GBP","changes":[["sell","0.4566","0.000000"]],"time":"2021-04-17T16:43:42.975278Z"}
1618677822.958356: {"type":"l2update","product_id":"NU-GBP","changes":[["sell","0.4594","0.000000"]],"time":"2021-04-17T16:43:42.975278Z"}
1618677822.964606: {"type":"l2update","product_id":"SKL-USD","changes":[["buy","0.7908","0.0"]],"time":"2021-04-17T16:43:42.977722Z"}
1618677822.9723892: {"type":"l2update","product_id":"SKL-USD","changes":[["buy","0.7911","815.0"]],"time":"2021-04-17T16:43:42.986372Z"}
1618677822.9724228: {"type":"l2update","product_id":"BAND-GBP","changes":[["buy","14.7843","0.00"]],"time":"2021-04-17T16:43:42.988162Z"}
1618677822.97245: {"type":"l2update","product_id":"BAND-GBP","changes":[["buy","14.7775","0.00"]],"time":"2021-04-17T16:43:42.988809Z"}
1618677822.97661: {"type":"l2update","product_id":"CRV-EUR","changes":[["buy","3.2697","401.00"]],"time":"2021-04-17T16:43:42.990165Z"}
1618677822.979885: {"type":"l2update","product_id":"SKL-BTC","changes":[["sell","0.00001314","7040.6"]],"time":"2021-04-17T16:43:42.993844Z"}
1618677822.9799218: {"type":"l2update","product_id":"DASH-BTC","changes":[["sell","0.00621067","1.62300000"]],"time":"2021-04-17T16:43:42.993824Z"}
1618677822.9799511: {"type":"l2update","product_id":"DASH-BTC","changes":[["sell","0.00621120","0.00000000"]],"time":"2021-04-17T16:43:42.994708Z"}
1618677822.984311: {"type":"l2update","product_id":"SKL-USD","changes":[["buy","0.7832","291.2"]],"time":"2021-04-17T16:43:42.996927Z"}
1618677822.9843478: {"type":"l2update","product_id":"SKL-USD","changes":[["sell","0.7997","1080.0"]],"time":"2021-04-17T16:43:42.996927Z"}
1618677822.984371: {"type":"l2update","product_id":"SKL-BTC","changes":[["sell","0.00001604","250.0"]],"time":"2021-04-17T16:43:42.997798Z"}
1618677822.984395: {"type":"l2update","product_id":"DASH-BTC","changes":[["buy","0.00619037","0.00000000"]],"time":"2021-04-17T16:43:42.998099Z"}
1618677822.984419: {"type":"l2update","product_id":"SKL-BTC","changes":[["buy","0.00001303","11199.8"]],"time":"2021-04-17T16:43:43.001202Z"}
1618677822.9844348: {"type":"l2update","product_id":"DASH-BTC","changes":[["sell","0.00620180","0.00000000"]],"time":"2021-04-17T16:43:43.001580Z"}
1618677822.9856188: {"type":"l2update","product_id":"NU-GBP","changes":[["sell","0.4605","9238.000000"]],"time":"2021-04-17T16:43:43.001835Z"}
1618677822.985663: {"type":"l2update","product_id":"NU-GBP","changes":[["sell","0.4650","10248.235185"]],"time":"2021-04-17T16:43:43.001835Z"}
1618677822.985684: {"type":"l2update","product_id":"BAND-GBP","changes":[["buy","14.7712","27.51"]],"time":"2021-04-17T16:43:43.002001Z"}
1618677822.98767: {"type":"l2update","product_id":"DASH-BTC","changes":[["sell","0.00620869","0.00000000"]],"time":"2021-04-17T16:43:43.004279Z"}
1618677822.989538: {"type":"l2update","product_id":"SKL-USD","changes":[["sell","0.8088","590.0"]],"time":"2021-04-17T16:43:43.005835Z"}
1618677822.989571: {"type":"l2update","product_id":"SKL-USD","changes":[["buy","0.7856","745.0"]],"time":"2021-04-17T16:43:43.005835Z"}
1618677822.990506: {"type":"l2update","product_id":"BAND-BTC","changes":[["buy","0.00033449","215.32"]],"time":"2021-04-17T16:43:43.007726Z"}
1618677822.997331: {"type":"l2update","product_id":"DASH-BTC","changes":[["sell","0.00621316","1.62300000"]],"time":"2021-04-17T16:43:43.013493Z"}
1618677823.004002: {"type":"l2update","product_id":"BAND-BTC","changes":[["sell","0.00033524","32.19"]],"time":"2021-04-17T16:43:43.017783Z"}
1618677823.004045: {"type":"l2update","product_id":"SKL-USD","changes":[["sell","0.8082","6005.0"]],"time":"2021-04-17T16:43:43.018580Z"}
1618677823.013355: {"type":"l2update","product_id":"NU-GBP","changes":[["buy","0.4365","2460.000000"]],"time":"2021-04-17T16:43:43.027604Z"}
1618677823.0207648: {"type":"l2update","product_id":"DASH-BTC","changes":[["buy","0.00619154","2.15500000"]],"time":"2021-04-17T16:43:43.029485Z"}
1618677823.020879: {"type":"l2update","product_id":"DASH-BTC","changes":[["buy","0.00618777","1.12000000"]],"time":"2021-04-17T16:43:43.029749Z"}
1618677823.0209029: {"type":"l2update","product_id":"SKL-USD","changes":[["sell","0.8082","5.0"]],"time":"2021-04-17T16:43:43.032401Z"}
1618677823.03575: {"type":"l2update","product_id":"BAND-BTC","changes":[["sell","0.00033525","0.00"]],"time":"2021-04-17T16:43:43.039049Z"}
1618677823.035794: {"type":"l2update","product_id":"DASH-BTC","changes":[["sell","0.00620470","1.09000000"]],"time":"2021-04-17T16:43:43.041252Z"}
1618677823.035821: {"type":"l2update","product_id":"BAND-BTC","changes":[["sell","0.00033523","29.65"]],"time":"2021-04-17T16:43:43.048371Z"}
1618677823.035842: {"type":"l2update","product_id":"CRV-EUR","changes":[["buy","3.2976","0.00"]],"time":"2021-04-17T16:43:43.050153Z"}
1618677823.035864: {"type":"l2update","product_id":"CRV-EUR","changes":[["sell","3.3116","0.00"]],"time":"2021-04-17T16:43:43.050424Z"}
1618677823.041964: {"type":"l2update","product_id":"BAND-BTC","changes":[["buy","0.00033449","89.33"]],"time":"2021-04-17T16:43:43.052255Z"}
1618677823.042015: {"type":"l2update","product_id":"SKL-USD","changes":[["buy","0.7798","74487.0"]],"time":"2021-04-17T16:43:43.052653Z"}
1618677823.0420449: {"type":"l2update","product_id":"SKL-USD","changes":[["sell","0.7922","4270.1"]],"time":"2021-04-17T16:43:43.052653Z"}
1618677823.052875: {"type":"l2update","product_id":"DASH-BTC","changes":[["buy","0.00619170","0.00000000"]],"time":"2021-04-17T16:43:43.058909Z"}
1618677823.053032: {"type":"l2update","product_id":"DASH-BTC","changes":[["sell","0.00621067","3.85900000"]],"time":"2021-04-17T16:43:43.063735Z"}
1618677823.060271: {"type":"l2update","product_id":"CRV-EUR","changes":[["sell","3.3127","140.93"]],"time":"2021-04-17T16:43:43.067400Z"}
1618677823.060323: {"type":"l2update","product_id":"BAND-BTC","changes":[["sell","0.00033516","18.38"]],"time":"2021-04-17T16:43:43.067459Z"}
1618677823.067894: {"type":"l2update","product_id":"BAND-BTC","changes":[["sell","0.00033516","42.38"]],"time":"2021-04-17T16:43:43.079035Z"}
1618677823.0679328: {"type":"l2update","product_id":"DASH-BTC","changes":[["sell","0.00621358","14.63200000"]],"time":"2021-04-17T16:43:43.079114Z"}
1618677823.067961: {"type":"l2update","product_id":"CRV-EUR","changes":[["buy","3.2981","649.90"]],"time":"2021-04-17T16:43:43.079222Z"}
1618677823.067979: {"type":"l2update","product_id":"DASH-BTC","changes":[["sell","0.00620471","0.00000000"]],"time":"2021-04-17T16:43:43.080222Z"}
1618677823.068001: {"type":"l2update","product_id":"CRV-EUR","changes":[["sell","3.3044","0.00"]],"time":"2021-04-17T16:43:43.083145Z"}
1618677823.085542: {"type":"l2update","product_id":"YFI-BTC","changes":[["buy","0.82474","0.000000"]],"time":"2021-04-17T16:43:43.088555Z"}
1618677823.085692: {"type":"l2update","product_id":"BAND-BTC","changes":[["buy","0.00033287","0.00"]],"time":"2021-04-17T16:43:43.089123Z"}
1618677823.085758: {"type":"l2update","product_id":"SKL-GBP","changes":[["sell","0.5771","305.0"]],"time":"2021-04-17T16:43:43.089653Z"}
1618677823.085805: {"type":"l2update","product_id":"SKL-USD","changes":[["buy","0.7911","365.0"]],"time":"2021-04-17T16:43:43.090477Z"}
1618677823.0858428: {"type":"l2update","product_id":"SKL-BTC","changes":[["sell","0.00001307","7012.6"]],"time":"2021-04-17T16:43:43.093550Z"}
1618677823.085879: {"type":"l2update","product_id":"SKL-USD","changes":[["buy","0.7908","450.0"]],"time":"2021-04-17T16:43:43.093679Z"}
1618677823.085925: {"type":"l2update","product_id":"NU-GBP","changes":[["buy","0.4367","3000.000000"]],"time":"2021-04-17T16:43:43.093764Z"}
1618677823.105854: {"type":"l2update","product_id":"SKL-BTC","changes":[["sell","0.00001309","7861.6"]],"time":"2021-04-17T16:43:43.105833Z"}
1618677823.105948: {"type":"l2update","product_id":"SKL-BTC","changes":[["sell","0.00001331","0.0"]],"time":"2021-04-17T16:43:43.109073Z"}
1618677823.1060228: {"type":"l2update","product_id":"DASH-BTC","changes":[["sell","0.00620607","5.56000000"]],"time":"2021-04-17T16:43:43.109420Z"}
1618677823.106084: {"type":"l2update","product_id":"DASH-BTC","changes":[["sell","0.00620888","2.56900000"]],"time":"2021-04-17T16:43:43.116849Z"}
1618677823.10653: {"type":"l2update","product_id":"YFI-BTC","changes":[["buy","0.82336","0.000120"]],"time":"2021-04-17T16:43:43.120477Z"}
1618677823.110157: {"type":"l2update","product_id":"YFI-BTC","changes":[["buy","0.82500","0.010000"]],"time":"2021-04-17T16:43:43.121396Z"}
1618677823.117871: {"type":"l2update","product_id":"SKL-USD","changes":[["buy","0.7904","1194.2"]],"time":"2021-04-17T16:43:43.130321Z"}
1618677823.1179872: {"type":"l2update","product_id":"SKL-BTC","changes":[["buy","0.00001299","5344.0"]],"time":"2021-04-17T16:43:43.132517Z"}
1618677823.118041: {"type":"l2update","product_id":"SKL-BTC","changes":[["sell","0.00001307","7480.3"]],"time":"2021-04-17T16:43:43.132517Z"}
1618677823.118082: {"type":"l2update","product_id":"SKL-BTC","changes":[["sell","0.00001321","24403.2"]],"time":"2021-04-17T16:43:43.132517Z"}
1618677823.1223319: {"type":"l2update","product_id":"BAND-BTC","changes":[["buy","0.00033375","41.54"]],"time":"2021-04-17T16:43:43.137696Z"}
1618677823.1224551: {"type":"l2update","product_id":"CRV-EUR","changes":[["buy","3.2988","0.00"]],"time":"2021-04-17T16:43:43.137878Z"}
1618677823.124465: {"type":"l2update","product_id":"CRV-EUR","changes":[["sell","3.3050","504.82"]],"time":"2021-04-17T16:43:43.139860Z"}
1618677823.125651: {"type":"l2update","product_id":"DASH-BTC","changes":[["buy","0.00610569","0.00000000"]],"time":"2021-04-17T16:43:43.141447Z"}
1618677823.127264: {"type":"l2update","product_id":"CRV-EUR","changes":[["sell","3.3200","0.00"]],"time":"2021-04-17T16:43:43.144735Z"}
1618677823.131562: {"type":"l2update","product_id":"SKL-BTC","changes":[["sell","0.00001307","8589.4"]],"time":"2021-04-17T16:43:43.146183Z"}
1618677823.131655: {"type":"l2update","product_id":"CRV-EUR","changes":[["sell","3.3040","500.62"]],"time":"2021-04-17T16:43:43.146202Z"}
1618677823.131722: {"type":"l2update","product_id":"DASH-BTC","changes":[["buy","0.00619285","32.84700000"]],"time":"2021-04-17T16:43:43.146244Z"}
1618677823.135822: {"type":"l2update","product_id":"SKL-GBP","changes":[["sell","0.5771","1313.2"]],"time":"2021-04-17T16:43:43.150832Z"}
1618677823.1379158: {"type":"l2update","product_id":"SKL-BTC","changes":[["sell","0.00001311","4013.4"]],"time":"2021-04-17T16:43:43.151793Z"}
1618677823.142189: {"type":"l2update","product_id":"DASH-BTC","changes":[["buy","0.00618761","24.05700000"]],"time":"2021-04-17T16:43:43.154339Z"}
1618677823.142287: {"type":"l2update","product_id":"BAND-BTC","changes":[["buy","0.00033349","28.63"]],"time":"2021-04-17T16:43:43.158174Z"}
1618677823.147462: {"type":"l2update","product_id":"DASH-BTC","changes":[["buy","0.00613020","74.79000000"]],"time":"2021-04-17T16:43:43.161919Z"}
1618677823.147563: {"type":"l2update","product_id":"CRV-EUR","changes":[["sell","3.3126","1416.00"]],"time":"2021-04-17T16:43:43.161993Z"}
1618677823.1476219: {"type":"l2update","product_id":"SKL-BTC","changes":[["sell","0.00001308","1610.2"]],"time":"2021-04-17T16:43:43.162042Z"}
1618677823.1563: {"type":"l2update","product_id":"SKL-USD","changes":[["buy","0.7888","0.0"]],"time":"2021-04-17T16:43:43.169984Z"}
1618677823.1631181: {"type":"l2update","product_id":"SKL-USD","changes":[["buy","0.7904","3824.3"]],"time":"2021-04-17T16:43:43.174610Z"}
1618677823.1632352: {"type":"l2update","product_id":"SKL-USD","changes":[["sell","0.7987","10.0"]],"time":"2021-04-17T16:43:43.175343Z"}
1618677823.163287: {"type":"l2update","product_id":"SKL-USD","changes":[["sell","0.8072","0.0"]],"time":"2021-04-17T16:43:43.175343Z"}
1618677823.1653702: {"type":"l2update","product_id":"CRV-EUR","changes":[["sell","3.3045","0.00"]],"time":"2021-04-17T16:43:43.180709Z"}
1618677823.1654751: {"type":"l2update","product_id":"CRV-EUR","changes":[["sell","3.3201","162.50"]],"time":"2021-04-17T16:43:43.180975Z"}
1618677823.165529: {"type":"l2update","product_id":"CRV-EUR","changes":[["buy","3.2699","85.00"]],"time":"2021-04-17T16:43:43.180975Z"}
1618677823.16557: {"type":"l2update","product_id":"CRV-EUR","changes":[["buy","3.2698","0.00"]],"time":"2021-04-17T16:43:43.180975Z"}
1618677823.168308: {"type":"l2update","product_id":"SKL-USD","changes":[["sell","0.7953","175.8"]],"time":"2021-04-17T16:43:43.184704Z"}
1618677823.1745741: {"type":"l2update","product_id":"CRV-EUR","changes":[["sell","3.3199","183.50"]],"time":"2021-04-17T16:43:43.189128Z"}
1618677823.174638: {"type":"l2update","product_id":"CRV-EUR","changes":[["buy","3.2697","496.50"]],"time":"2021-04-17T16:43:43.189128Z"}
1618677823.174672: {"type":"l2update","product_id":"CRV-EUR","changes":[["sell","3.3198","35.00"]],"time":"2021-04-17T16:43:43.189128Z"}
1618677823.174709: {"type":"l2update","product_id":"CRV-EUR","changes":[["buy","3.2974","532.81"]],"time":"2021-04-17T16:43:43.190131Z"}
1618677823.177071: {"type":"l2update","product_id":"DASH-BTC","changes":[["buy","0.00619644","1.10000000"]],"time":"2021-04-17T16:43:43.192761Z"}
1618677823.177121: {"type":"l2update","product_id":"DASH-BTC","changes":[["buy","0.00619276","0.00000000"]],"time":"2021-04-17T16:43:43.194567Z"}
1618677823.181998: {"type":"l2update","product_id":"CRV-EUR","changes":[["sell","3.3039","5000.00"]],"time":"2021-04-17T16:43:43.196610Z"}
1618677823.182069: {"type":"l2update","product_id":"DASH-BTC","changes":[["buy","0.00619214","0.00000000"]],"time":"2021-04-17T16:43:43.198103Z"}
1618677823.18301: {"type":"l2update","product_id":"CRV-EUR","changes":[["sell","3.3040","598.28"]],"time":"2021-04-17T16:43:43.200023Z"}
1618677823.1894898: {"type":"l2update","product_id":"CRV-EUR","changes":[["buy","3.2967","0.00"]],"time":"2021-04-17T16:43:43.204767Z"}
1618677823.189568: {"type":"l2update","product_id":"CRV-EUR","changes":[["sell","3.3052","140.93"]],"time":"2021-04-17T16:43:43.204949Z"}
1618677823.192734: {"type":"l2update","product_id":"DASH-BTC","changes":[["sell","0.00620565","1.39000000"]],"time":"2021-04-17T16:43:43.208451Z"}
1618677823.192806: {"type":"l2update","product_id":"SKL-USD","changes":[["buy","0.7798","0.0"]],"time":"2021-04-17T16:43:43.208776Z"}
1618677823.192852: {"type":"l2update","product_id":"SKL-USD","changes":[["sell","0.7922","1017.5"]],"time":"2021-04-17T16:43:43.208776Z"}
1618677823.193654: {"type":"l2update","product_id":"CRV-EUR","changes":[["buy","3.2981","140.93"]],"time":"2021-04-17T16:43:43.210905Z"}
1618677823.201486: {"type":"l2update","product_id":"DASH-BTC","changes":[["buy","0.00619286","0.03000000"]],"time":"2021-04-17T16:43:43.216928Z"}
1618677823.20159: {"type":"l2update","product_id":"BAND-BTC","changes":[["sell","0.00033524","0.00"]],"time":"2021-04-17T16:43:43.218190Z"}
1618677823.2016609: {"type":"l2update","product_id":"SKL-USD","changes":[["buy","0.7908","0.0"]],"time":"2021-04-17T16:43:43.219278Z"}
1618677823.206943: {"type":"l2update","product_id":"DASH-BTC","changes":[["buy","0.00619154","0.00000000"]],"time":"2021-04-17T16:43:43.221224Z"}
1618677823.207604: {"type":"l2update","product_id":"SKL-USD","changes":[["buy","0.7911","815.0"]],"time":"2021-04-17T16:43:43.224720Z"}
1618677823.216344: {"type":"l2update","product_id":"DASH-BTC","changes":[["buy","0.00619286","1.57200000"]],"time":"2021-04-17T16:43:43.232310Z"}
1618677823.2195048: {"type":"l2update","product_id":"SKL-USD","changes":[["buy","0.7905","0.0"]],"time":"2021-04-17T16:43:43.234479Z"}
1618677823.275431: {"type":"l2update","product_id":"SKL-BTC","changes":[["sell","0.00001307","8121.7"]],"time":"2021-04-17T16:43:43.286039Z"}
1618677823.275558: {"type":"l2update","product_id":"SKL-BTC","changes":[["sell","0.00001321","22310.6"]],"time":"2021-04-17T16:43:43.286039Z"}
1618677823.276219: {"type":"l2update","product_id":"SKL-BTC","changes":[["sell","0.00001307","7012.6"]],"time":"2021-04-17T16:43:43.288358Z"}
1618677823.283929: {"type":"l2update","product_id":"BAND-BTC","changes":[["buy","0.00033449","152.33"]],"time":"2021-04-17T16:43:43.294769Z"}
1618677823.286088: {"type":"l2update","product_id":"DASH-BTC","changes":[["sell","0.00621317","0.00000000"]],"time":"2021-04-17T16:43:43.299429Z"}
1618677823.289267: {"type":"l2update","product_id":"SKL-GBP","changes":[["sell","0.5771","305.0"]],"time":"2021-04-17T16:43:43.304268Z"}
1618677823.289363: {"type":"l2update","product_id":"SKL-USD","changes":[["sell","0.7922","0.0"]],"time":"2021-04-17T16:43:43.304821Z"}
1618677823.291359: {"type":"l2update","product_id":"SKL-USD","changes":[["buy","0.7904","4690.8"]],"time":"2021-04-17T16:43:43.306209Z"}
1618677823.294751: {"type":"l2update","product_id":"SKL-BTC","changes":[["buy","0.00001303","12189.5"]],"time":"2021-04-17T16:43:43.309793Z"}
1618677823.29484: {"type":"l2update","product_id":"DASH-BTC","changes":[["sell","0.00621067","2.23600000"]],"time":"2021-04-17T16:43:43.310504Z"}
1618677823.294892: {"type":"l2update","product_id":"SKL-USD","changes":[["buy","0.7889","0.0"]],"time":"2021-04-17T16:43:43.312248Z"}
1618677823.2978199: {"type":"l2update","product_id":"SKL-GBP","changes":[["sell","0.5784","0.0"]],"time":"2021-04-17T16:43:43.313072Z"}
1618677823.2979252: {"type":"l2update","product_id":"DASH-BTC","changes":[["buy","0.00619275","0.00000000"]],"time":"2021-04-17T16:43:43.313877Z"}
1618677823.304447: {"type":"l2update","product_id":"SKL-BTC","changes":[["sell","0.00001309","8578.1"]],"time":"2021-04-17T16:43:43.320798Z"}
1618677823.3119202: {"type":"l2update","product_id":"NMR-EUR","changes":[["buy","66.9294","0.000"]],"time":"2021-04-17T16:43:43.327402Z"}
1618677823.316227: {"type":"l2update","product_id":"SKL-BTC","changes":[["buy","0.00001302","7415.5"]],"time":"2021-04-17T16:43:43.331919Z"}
1618677823.3163211: {"type":"l2update","product_id":"DASH-BTC","changes":[["sell","0.00620887","1.62300000"]],"time":"2021-04-17T16:43:43.331956Z"}
1618677823.3212721: {"type":"l2update","product_id":"SKL-USD","changes":[["buy","0.7911","365.0"]],"time":"2021-04-17T16:43:43.336583Z"}
1618677823.3235881: {"type":"l2update","product_id":"SKL-USD","changes":[["buy","0.7908","450.0"]],"time":"2021-04-17T16:43:43.339599Z"}
1618677823.3353548: {"type":"l2update","product_id":"NMR-EUR","changes":[["buy","66.9297","0.857"]],"time":"2021-04-17T16:43:43.351440Z"}
1618677823.341362: {"type":"l2update","product_id":"SKL-USD","changes":[["sell","0.8076","6000.0"]],"time":"2021-04-17T16:43:43.355178Z"}
1618677823.344728: {"type":"l2update","product_id":"SKL-BTC","changes":[["sell","0.00001307","8121.7"]],"time":"2021-04-17T16:43:43.358726Z"}
1618677823.344809: {"type":"l2update","product_id":"SKL-USD","changes":[["buy","0.7908","0.0"]],"time":"2021-04-17T16:43:43.360060Z"}
1618677823.3510468: {"type":"l2update","product_id":"DASH-BTC","changes":[["buy","0.00619645","2.56900000"]],"time":"2021-04-17T16:43:43.366505Z"}
1618677823.353569: {"type":"l2update","product_id":"SKL-USD","changes":[["buy","0.7911","815.0"]],"time":"2021-04-17T16:43:43.366589Z"}
1618677823.353656: {"type":"l2update","product_id":"DASH-BTC","changes":[["sell","0.00620470","0.00000000"]],"time":"2021-04-17T16:43:43.368267Z"}
1618677823.3567: {"type":"l2update","product_id":"SKL-USD","changes":[["buy","0.7798","64606.6"]],"time":"2021-04-17T16:43:43.370455Z"}
1618677823.3568041: {"type":"l2update","product_id":"SKL-USD","changes":[["sell","0.7921","2979.9"]],"time":"2021-04-17T16:43:43.370455Z"}
1618677823.362114: {"type":"l2update","product_id":"NMR-EUR","changes":[["buy","66.9296","0.000"]],"time":"2021-04-17T16:43:43.377322Z"}
1618677823.362216: {"type":"l2update","product_id":"NMR-EUR","changes":[["buy","66.9310","4.773"]],"time":"2021-04-17T16:43:43.377628Z"}
1618677823.364535: {"type":"l2update","product_id":"SKL-BTC","changes":[["buy","0.00001305","1117.2"]],"time":"2021-04-17T16:43:43.377736Z"}
1618677823.36658: {"type":"l2update","product_id":"YFI-BTC","changes":[["buy","0.82548","0.030081"]],"time":"2021-04-17T16:43:43.381746Z"}
1618677823.366682: {"type":"l2update","product_id":"DASH-BTC","changes":[["sell","0.00622501","11.27800000"]],"time":"2021-04-17T16:43:43.381766Z"}
1618677823.366743: {"type":"l2update","product_id":"SKL-BTC","changes":[["buy","0.00001305","1007.2"]],"time":"2021-04-17T16:43:43.382975Z"}
1618677823.3686469: {"type":"l2update","product_id":"CRV-EUR","changes":[["sell","3.3064","0.00"]],"time":"2021-04-17T16:43:43.384006Z"}
1618677823.372685: {"type":"l2update","product_id":"CRV-EUR","changes":[["sell","3.3043","0.00"]],"time":"2021-04-17T16:43:43.388620Z"}
1618677823.376256: {"type":"l2update","product_id":"CRV-EUR","changes":[["buy","3.2965","0.00"]],"time":"2021-04-17T16:43:43.390211Z"}
1618677823.3763578: {"type":"l2update","product_id":"SKL-GBP","changes":[["buy","0.5745","0.0"]],"time":"2021-04-17T16:43:43.392644Z"}
1618677823.380664: {"type":"l2update","product_id":"DASH-BTC","changes":[["sell","0.00620564","1.09000000"]],"time":"2021-04-17T16:43:43.396826Z"}
1618677823.384301: {"type":"l2update","product_id":"CRV-EUR","changes":[["sell","3.3045","254.60"]],"time":"2021-04-17T16:43:43.396851Z"}
1618677823.384394: {"type":"l2update","product_id":"SKL-GBP","changes":[["buy","0.5690","385.0"]],"time":"2021-04-17T16:43:43.397213Z"}
1618677823.387651: {"type":"l2update","product_id":"CRV-EUR","changes":[["buy","3.2953","5254.47"]],"time":"2021-04-17T16:43:43.400570Z"}
1618677823.387744: {"type":"l2update","product_id":"CRV-EUR","changes":[["buy","3.2974","0.00"]],"time":"2021-04-17T16:43:43.400789Z"}
1618677823.3878138: {"type":"l2update","product_id":"SKL-USD","changes":[["buy","0.7888","868.9"]],"time":"2021-04-17T16:43:43.404163Z"}
1618677823.393045: {"type":"l2update","product_id":"SKL-USD","changes":[["buy","0.7904","3496.6"]],"time":"2021-04-17T16:43:43.407965Z"}
1618677823.402837: {"type":"l2update","product_id":"DASH-BTC","changes":[["sell","0.00622923","0.00000000"]],"time":"2021-04-17T16:43:43.412122Z"}
1618677823.4029481: {"type":"l2update","product_id":"DASH-BTC","changes":[["buy","0.00614331","16.28600000"]],"time":"2021-04-17T16:43:43.412122Z"}
1618677823.403002: {"type":"l2update","product_id":"DASH-BTC","changes":[["buy","0.00614331","0.00000000"]],"time":"2021-04-17T16:43:43.412122Z"}
1618677823.403053: {"type":"l2update","product_id":"DASH-BTC","changes":[["buy","0.00613941","14.50300000"]],"time":"2021-04-17T16:43:43.412122Z"}
1618677823.4030972: {"type":"l2update","product_id":"DASH-BTC","changes":[["buy","0.00613941","0.00000000"]],"time":"2021-04-17T16:43:43.412122Z"}
1618677823.4031239: {"type":"l2update","product_id":"DASH-BTC","changes":[["buy","0.00611157","0.00000000"]],"time":"2021-04-17T16:43:43.412122Z"}
1618677823.40315: {"type":"l2update","product_id":"DASH-BTC","changes":[["buy","0.00607867","0.00000000"]],"time":"2021-04-17T16:43:43.412122Z"}
1618677823.403177: {"type":"l2update","product_id":"DASH-BTC","changes":[["buy","0.00606951","0.00000000"]],"time":"2021-04-17T16:43:43.412122Z"}
1618677823.403201: {"type":"l2update","product_id":"CRV-EUR","changes":[["buy","3.2989","0.00"]],"time":"2021-04-17T16:43:43.414487Z"}
1618677823.403628: {"type":"l2update","product_id":"NMR-EUR","changes":[["buy","66.9297","0.000"]],"time":"2021-04-17T16:43:43.419746Z"}
1618677823.414199: {"type":"l2update","product_id":"SKL-USD","changes":[["buy","0.7911","365.0"]],"time":"2021-04-17T16:43:43.426263Z"}
1618677823.4142542: {"type":"l2update","product_id":"SKL-USD","changes":[["buy","0.7908","450.0"]],"time":"2021-04-17T16:43:43.430296Z"}
1618677823.4204218: {"type":"l2update","product_id":"DASH-BTC","changes":[["buy","0.00618953","11.29800000"]],"time":"2021-04-17T16:43:43.434190Z"}
1618677823.420487: {"type":"l2update","product_id":"DASH-BTC","changes":[["buy","0.00618040","13.55700000"]],"time":"2021-04-17T16:43:43.434190Z"}
1618677823.420525: {"type":"l2update","product_id":"DASH-BTC","changes":[["buy","0.00617109","16.26900000"]],"time":"2021-04-17T16:43:43.434190Z"}
1618677823.423223: {"type":"l2update","product_id":"DASH-BTC","changes":[["buy","0.00614337","17.68200000"]],"time":"2021-04-17T16:43:43.434190Z"}
1618677823.423263: {"type":"l2update","product_id":"DASH-BTC","changes":[["buy","0.00614322","0.01000000"]],"time":"2021-04-17T16:43:43.434190Z"}
1618677823.4232929: {"type":"l2update","product_id":"DASH-BTC","changes":[["buy","0.00613395","0.01000000"]],"time":"2021-04-17T16:43:43.434190Z"}
1618677823.423317: {"type":"l2update","product_id":"DASH-BTC","changes":[["sell","0.00622722","1.06000000"]],"time":"2021-04-17T16:43:43.434190Z"}
1618677823.423339: {"type":"l2update","product_id":"DASH-BTC","changes":[["sell","0.00624604","1.06000000"]],"time":"2021-04-17T16:43:43.434190Z"}
1618677823.423361: {"type":"l2update","product_id":"DASH-BTC","changes":[["sell","0.00631236","0.01000000"]],"time":"2021-04-17T16:43:43.434190Z"}
1618677823.423383: {"type":"l2update","product_id":"NMR-EUR","changes":[["buy","66.9311","0.857"]],"time":"2021-04-17T16:43:43.437797Z"}
1618677823.428027: {"type":"l2update","product_id":"SKL-BTC","changes":[["buy","0.00001299","1976.2"]],"time":"2021-04-17T16:43:43.440871Z"}
1618677823.428113: {"type":"l2update","product_id":"BAND-BTC","changes":[["buy","0.00033375","20.77"]],"time":"2021-04-17T16:43:43.444194Z"}
1618677823.4408278: {"type":"l2update","product_id":"SKL-USD","changes":[["buy","0.7905","1194.0"]],"time":"2021-04-17T16:43:43.456623Z"}
1618677823.442084: {"type":"l2update","product_id":"SKL-GBP","changes":[["sell","0.5771","1313.2"]],"time":"2021-04-17T16:43:43.456911Z"}
1618677823.4483562: {"type":"l2update","product_id":"CRV-EUR","changes":[["buy","3.2878","140.93"]],"time":"2021-04-17T16:43:43.461545Z"}
1618677823.448401: {"type":"l2update","product_id":"SKL-BTC","changes":[["sell","0.00001308","893.7"]],"time":"2021-04-17T16:43:43.461846Z"}
1618677823.448426: {"type":"l2update","product_id":"BAND-BTC","changes":[["buy","0.00033349","49.42"]],"time":"2021-04-17T16:43:43.464514Z"}
1618677823.454677: {"type":"l2update","product_id":"SKL-USD","changes":[["buy","0.7911","0.0"]],"time":"2021-04-17T16:43:43.468421Z"}
1618677823.4577081: {"type":"l2update","product_id":"SKL-BTC","changes":[["sell","0.00001311","4729.9"]],"time":"2021-04-17T16:43:43.471732Z"}
1618677823.4668338: {"type":"l2update","product_id":"SKL-USD","changes":[["sell","0.8082","6005.0"]],"time":"2021-04-17T16:43:43.483673Z"}
1618677823.4754481: {"type":"l2update","product_id":"SKL-USD","changes":[["sell","0.8076","0.0"]],"time":"2021-04-17T16:43:43.487633Z"}
1618677823.4839182: {"type":"l2update","product_id":"CRV-EUR","changes":[["buy","3.2981","0.00"]],"time":"2021-04-17T16:43:43.494648Z"}
1618677823.483968: {"type":"l2update","product_id":"SKL-USD","changes":[["sell","0.8082","12005.0"]],"time":"2021-04-17T16:43:43.494904Z"}
1618677823.483995: {"type":"l2update","product_id":"BAND-BTC","changes":[["sell","0.00033517","32.19"]],"time":"2021-04-17T16:43:43.494923Z"}
1618677823.484024: {"type":"l2update","product_id":"DASH-BTC","changes":[["sell","0.00620889","0.00000000"]],"time":"2021-04-17T16:43:43.495771Z"}
1618677823.490273: {"type":"l2update","product_id":"DASH-BTC","changes":[["sell","0.00620607","0.00000000"]],"time":"2021-04-17T16:43:43.506408Z"}
1618677823.506969: {"type":"l2update","product_id":"CRV-EUR","changes":[["buy","3.2976","140.93"]],"time":"2021-04-17T16:43:43.514038Z"}
1618677823.510536: {"type":"l2update","product_id":"SKL-USD","changes":[["buy","0.7798","0.0"]],"time":"2021-04-17T16:43:43.524379Z"}
1618677823.5105898: {"type":"l2update","product_id":"SKL-USD","changes":[["sell","0.7921","0.0"]],"time":"2021-04-17T16:43:43.524379Z"}
1618677823.5202591: {"type":"l2update","product_id":"DASH-BTC","changes":[["sell","0.00621358","0.00000000"]],"time":"2021-04-17T16:43:43.527771Z"}
1618677823.534881: {"type":"l2update","product_id":"DASH-BTC","changes":[["buy","0.00619286","1.54200000"]],"time":"2021-04-17T16:43:43.540082Z"}
1618677823.5349288: {"type":"l2update","product_id":"BAND-BTC","changes":[["buy","0.00033449","89.33"]],"time":"2021-04-17T16:43:43.540647Z"}
1618677823.534956: {"type":"l2update","product_id":"NMR-EUR","changes":[["sell","71.6465","0.000"]],"time":"2021-04-17T16:43:43.541207Z"}
1618677823.534987: {"type":"l2update","product_id":"NMR-EUR","changes":[["sell","71.7246","0.000"]],"time":"2021-04-17T16:43:43.541207Z"}
1618677823.535011: {"type":"l2update","product_id":"NMR-EUR","changes":[["sell","71.7340","0.000"]],"time":"2021-04-17T16:43:43.541207Z"}
1618677823.5350342: {"type":"l2update","product_id":"NMR-EUR","changes":[["buy","66.4805","0.000"]],"time":"2021-04-17T16:43:43.541207Z"}
1618677823.53506: {"type":"l2update","product_id":"NMR-EUR","changes":[["buy","66.4806","0.000"]],"time":"2021-04-17T16:43:43.541207Z"}
1618677823.535081: {"type":"l2update","product_id":"NMR-EUR","changes":[["buy","66.4808","0.730"]],"time":"2021-04-17T16:43:43.541207Z"}
1618677823.5350988: {"type":"l2update","product_id":"NMR-EUR","changes":[["sell","71.7841","0.000"]],"time":"2021-04-17T16:43:43.541207Z"}
1618677823.535119: {"type":"l2update","product_id":"DASH-BTC","changes":[["sell","0.00621067","0.00000000"]],"time":"2021-04-17T16:43:43.543547Z"}
1618677823.537672: {"type":"l2update","product_id":"SKL-USD","changes":[["sell","0.7922","1017.5"]],"time":"2021-04-17T16:43:43.549665Z"}
1618677823.537729: {"type":"l2update","product_id":"NMR-EUR","changes":[["buy","66.4813","19.980"]],"time":"2021-04-17T16:43:43.549709Z"}
1618677823.537761: {"type":"l2update","product_id":"NMR-EUR","changes":[["sell","71.9127","21.390"]],"time":"2021-04-17T16:43:43.549709Z"}
1618677823.537786: {"type":"l2update","product_id":"NMR-EUR","changes":[["sell","71.9764","20.480"]],"time":"2021-04-17T16:43:43.549709Z"}
1618677823.537807: {"type":"l2update","product_id":"NMR-EUR","changes":[["buy","66.4812","24.900"]],"time":"2021-04-17T16:43:43.549709Z"}
1618677823.53833: {"type":"l2update","product_id":"DASH-BTC","changes":[["buy","0.00618953","0.00000000"]],"time":"2021-04-17T16:43:43.553398Z"}
1618677823.53839: {"type":"l2update","product_id":"DASH-BTC","changes":[["buy","0.00618040","0.00000000"]],"time":"2021-04-17T16:43:43.553398Z"}
1618677823.538421: {"type":"l2update","product_id":"DASH-BTC","changes":[["buy","0.00617109","11.31000000"]],"time":"2021-04-17T16:43:43.553398Z"}
1618677823.5463: {"type":"l2update","product_id":"DASH-BTC","changes":[["buy","0.00619646","0.03000000"]],"time":"2021-04-17T16:43:43.562623Z"}
1618677823.553857: {"type":"l2update","product_id":"DASH-BTC","changes":[["buy","0.00618040","11.29800000"]],"time":"2021-04-17T16:43:43.568807Z"}
1618677823.55392: {"type":"l2update","product_id":"DASH-BTC","changes":[["buy","0.00617109","13.55800000"]],"time":"2021-04-17T16:43:43.568807Z"}
1618677823.553948: {"type":"l2update","product_id":"DASH-BTC","changes":[["buy","0.00614337","33.02300000"]],"time":"2021-04-17T16:43:43.568807Z"}
1618677823.553969: {"type":"l2update","product_id":"DASH-BTC","changes":[["buy","0.00614322","23.42800000"]],"time":"2021-04-17T16:43:43.568807Z"}
1618677823.553987: {"type":"l2update","product_id":"DASH-BTC","changes":[["buy","0.00607867","0.01000000"]],"time":"2021-04-17T16:43:43.568807Z"}
1618677823.555849: {"type":"l2update","product_id":"DASH-BTC","changes":[["sell","0.00621781","2.23600000"]],"time":"2021-04-17T16:43:43.572569Z"}
1618677823.572895: {"type":"l2update","product_id":"DASH-BTC","changes":[["buy","0.00618233","0.00000000"]],"time":"2021-04-17T16:43:43.580625Z"}
1618677823.572953: {"type":"l2update","product_id":"DASH-BTC","changes":[["sell","0.00621862","0.00000000"]],"time":"2021-04-17T16:43:43.582840Z"}
1618677823.5729861: {"type":"l2update","product_id":"SKL-USD","changes":[["buy","0.7902","1345.5"]],"time":"2021-04-17T16:43:43.588011Z"}
1618677823.5730162: {"type":"l2update","product_id":"DASH-BTC","changes":[["sell","0.00620565","0.00000000"]],"time":"2021-04-17T16:43:43.589204Z"}
1618677823.575636: {"type":"l2update","product_id":"DASH-BTC","changes":[["sell","0.00621157","0.00000000"]],"time":"2021-04-17T16:43:43.589806Z"}
1618677823.575691: {"type":"l2update","product_id":"DASH-BTC","changes":[["sell","0.00621068","0.00000000"]],"time":"2021-04-17T16:43:43.590057Z"}
1618677823.5757241: {"type":"l2update","product_id":"SKL-BTC","changes":[["sell","0.00001309","8038.1"]],"time":"2021-04-17T16:43:43.590589Z"}
1618677823.5757492: {"type":"l2update","product_id":"YFI-BTC","changes":[["buy","0.82334","0.000000"]],"time":"2021-04-17T16:43:43.591109Z"}
1618677823.576401: {"type":"l2update","product_id":"DASH-BTC","changes":[["buy","0.00619286","6.69400000"]],"time":"2021-04-17T16:43:43.591782Z"}
1618677823.576441: {"type":"l2update","product_id":"CRV-EUR","changes":[["buy","3.2953","5000.00"]],"time":"2021-04-17T16:43:43.593639Z"}
1618677823.583153: {"type":"l2update","product_id":"YFI-BTC","changes":[["buy","0.82589","0.000000"]],"time":"2021-04-17T16:43:43.596121Z"}
1618677823.584456: {"type":"l2update","product_id":"DASH-BTC","changes":[["sell","0.00622500","5.72000000"]],"time":"2021-04-17T16:43:43.600252Z"}
1618677823.58867: {"type":"l2update","product_id":"DASH-BTC","changes":[["buy","0.00618761","13.67300000"]],"time":"2021-04-17T16:43:43.600655Z"}
1618677823.5887182: {"type":"l2update","product_id":"SKL-BTC","changes":[["buy","0.00001300","11039.2"]],"time":"2021-04-17T16:43:43.600790Z"}
1618677823.588744: {"type":"l2update","product_id":"SKL-BTC","changes":[["buy","0.00001305","0.0"]],"time":"2021-04-17T16:43:43.604694Z"}
1618677823.590726: {"type":"l2update","product_id":"BAND-GBP","changes":[["sell","14.8113","12.87"]],"time":"2021-04-17T16:43:43.607495Z"}
1618677823.590773: {"type":"l2update","product_id":"BAND-GBP","changes":[["buy","14.7785","12.08"]],"time":"2021-04-17T16:43:43.607631Z"}
1618677823.596009: {"type":"l2update","product_id":"YFI-BTC","changes":[["buy","0.82408","0.072200"]],"time":"2021-04-17T16:43:43.611097Z"}
1618677823.5960588: {"type":"l2update","product_id":"DASH-BTC","changes":[["sell","0.00621693","2.69200000"]],"time":"2021-04-17T16:43:43.611179Z"}
1618677823.597013: {"type":"l2update","product_id":"SKL-BTC","changes":[["buy","0.00001303","11199.8"]],"time":"2021-04-17T16:43:43.612255Z"}
1618677823.60031: {"type":"l2update","product_id":"SKL-BTC","changes":[["sell","0.00001309","7321.6"]],"time":"2021-04-17T16:43:43.616265Z"}
1618677823.600352: {"type":"l2update","product_id":"DASH-BTC","changes":[["buy","0.00619286","5.15200000"]],"time":"2021-04-17T16:43:43.616904Z"}
1618677823.606853: {"type":"l2update","product_id":"DASH-BTC","changes":[["sell","0.00621871","14.63200000"]],"time":"2021-04-17T16:43:43.619164Z"}
1618677823.6079092: {"type":"l2update","product_id":"SKL-USD","changes":[["sell","0.8077","0.0"]],"time":"2021-04-17T16:43:43.625596Z"}
1618677823.610946: {"type":"l2update","product_id":"SKL-BTC","changes":[["buy","0.00001304","2445.8"]],"time":"2021-04-17T16:43:43.626616Z"}
1618677823.610987: {"type":"l2update","product_id":"YFI-BTC","changes":[["buy","0.82548","0.000000"]],"time":"2021-04-17T16:43:43.627555Z"}
1618677823.618499: {"type":"l2update","product_id":"YFI-BTC","changes":[["buy","0.82520","0.030000"]],"time":"2021-04-17T16:43:43.630487Z"}
1618677823.618549: {"type":"l2update","product_id":"YFI-BTC","changes":[["buy","0.82273","0.000000"]],"time":"2021-04-17T16:43:43.630950Z"}
1618677823.620526: {"type":"l2update","product_id":"DASH-BTC","changes":[["buy","0.00619646","10.81100000"]],"time":"2021-04-17T16:43:43.634252Z"}
1618677823.622773: {"type":"l2update","product_id":"DASH-BTC","changes":[["buy","0.00619287","1.54200000"]],"time":"2021-04-17T16:43:43.638422Z"}
1618677823.622825: {"type":"l2update","product_id":"DASH-BTC","changes":[["sell","0.00622501","0.00000000"]],"time":"2021-04-17T16:43:43.639077Z"}
1618677823.622859: {"type":"l2update","product_id":"SKL-GBP","changes":[["buy","0.5747","0.0"]],"time":"2021-04-17T16:43:43.639019Z"}
1618677823.622887: {"type":"l2update","product_id":"SKL-GBP","changes":[["buy","0.5743","0.0"]],"time":"2021-04-17T16:43:43.639019Z"}
1618677823.628306: {"type":"l2update","product_id":"SKL-USD","changes":[["sell","0.8075","6000.0"]],"time":"2021-04-17T16:43:43.641386Z"}
1618677823.628404: {"type":"l2update","product_id":"SKL-GBP","changes":[["buy","0.5690","460.0"]],"time":"2021-04-17T16:43:43.645130Z"}
1618677823.628448: {"type":"l2update","product_id":"YFI-BTC","changes":[["buy","0.82583","0.017057"]],"time":"2021-04-17T16:43:43.645149Z"}
1618677823.628833: {"type":"l2update","product_id":"DASH-BTC","changes":[["buy","0.00618777","0.00000000"]],"time":"2021-04-17T16:43:43.645493Z"}
1618677823.634515: {"type":"l2update","product_id":"SKL-USD","changes":[["buy","0.7904","2630.1"]],"time":"2021-04-17T16:43:43.647987Z"}
1618677823.6345558: {"type":"l2update","product_id":"SKL-BTC","changes":[["buy","0.00001304","1552.2"]],"time":"2021-04-17T16:43:43.648912Z"}
1618677823.634586: {"type":"l2update","product_id":"DASH-BTC","changes":[["sell","0.00620887","0.00000000"]],"time":"2021-04-17T16:43:43.649204Z"}
1618677823.6346161: {"type":"l2update","product_id":"SKL-USD","changes":[["sell","0.8075","12000.0"]],"time":"2021-04-17T16:43:43.649684Z"}
1618677823.636789: {"type":"l2update","product_id":"DASH-BTC","changes":[["sell","0.00621316","0.00000000"]],"time":"2021-04-17T16:43:43.651626Z"}
1618677823.636843: {"type":"l2update","product_id":"SKL-USD","changes":[["sell","0.7996","5.0"]],"time":"2021-04-17T16:43:43.652714Z"}
1618677823.636872: {"type":"l2update","product_id":"SKL-USD","changes":[["sell","0.7997","0.0"]],"time":"2021-04-17T16:43:43.652714Z"}
1618677823.6419148: {"type":"l2update","product_id":"CRV-EUR","changes":[["buy","3.2976","0.00"]],"time":"2021-04-17T16:43:43.657616Z"}
1618677823.6483681: {"type":"l2update","product_id":"SKL-USD","changes":[["sell","0.8084","1085.0"]],"time":"2021-04-17T16:43:43.661643Z"}
1618677823.648417: {"type":"l2update","product_id":"SKL-USD","changes":[["sell","0.8088","770.0"]],"time":"2021-04-17T16:43:43.661643Z"}
1618677823.649338: {"type":"l2update","product_id":"CRV-EUR","changes":[["buy","3.2955","0.00"]],"time":"2021-04-17T16:43:43.666362Z"}
1618677823.649396: {"type":"l2update","product_id":"CRV-EUR","changes":[["sell","3.3052","0.00"]],"time":"2021-04-17T16:43:43.667088Z"}
1618677823.654811: {"type":"l2update","product_id":"SKL-USD","changes":[["buy","0.7905","2060.4"]],"time":"2021-04-17T16:43:43.669546Z"}
1618677823.6548538: {"type":"l2update","product_id":"CRV-EUR","changes":[["buy","3.2975","216.89"]],"time":"2021-04-17T16:43:43.669681Z"}
1618677823.654881: {"type":"l2update","product_id":"DASH-BTC","changes":[["buy","0.00619287","2.66100000"]],"time":"2021-04-17T16:43:43.669918Z"}
1618677823.657141: {"type":"l2update","product_id":"CRV-EUR","changes":[["buy","3.2697","503.50"]],"time":"2021-04-17T16:43:43.673573Z"}
1618677823.659418: {"type":"l2update","product_id":"CRV-EUR","changes":[["buy","3.2939","140.93"]],"time":"2021-04-17T16:43:43.673683Z"}
1618677823.6668339: {"type":"l2update","product_id":"DASH-BTC","changes":[["sell","0.00620564","0.82500000"]],"time":"2021-04-17T16:43:43.677370Z"}
1618677823.666877: {"type":"match","trade_id":923561,"maker_order_id":"872ec3e5-8c3d-4091-a7ce-ffb0b959ef8a","taker_order_id":"000057d3-4782-4218-9c06-ffcdc75693b5","side":"sell","size":"0.265","price":"0.00620564","product_id":"DASH-BTC","sequence":2040405455,"time":"2021-04-17T16:43:43.677370Z"}
1618677823.6669052: {"type":"ticker","sequence":2040405455,"product_id":"DASH-BTC","price":"0.00620564","open_24h":"0.00602352","volume_24h":"10364.35417066","low_24h":"0.0058755","high_24h":"0.00663815","volume_30d":"117700.54865811","best_bid":"0.00619646","best_ask":"0.00620564","side":"buy","time":"2021-04-17T16:43:43.677370Z","trade_id":923561,"last_size":"0.265"}
1618677823.666928: {"type":"l2update","product_id":"BAND-GBP","changes":[["buy","14.7712","0.00"]],"time":"2021-04-17T16:43:43.681531Z"}
1618677823.6669598: {"type":"l2update","product_id":"DASH-BTC","changes":[["sell","0.00621781","3.85900000"]],"time":"2021-04-17T16:43:43.681676Z"}
1618677823.666982: {"type":"l2update","product_id":"BAND-BTC","changes":[["sell","0.00033542","0.00"]],"time":"2021-04-17T16:43:43.682982Z"}
1618677823.669099: {"type":"l2update","product_id":"BAND-GBP","changes":[["buy","14.7786","27.50"]],"time":"2021-04-17T16:43:43.685823Z"}
1618677823.6785212: {"type":"l2update","product_id":"CRV-EUR","changes":[["sell","3.3038","140.93"]],"time":"2021-04-17T16:43:43.689564Z"}
1618677823.678574: {"type":"l2update","product_id":"CRV-EUR","changes":[["buy","3.2939","281.86"]],"time":"2021-04-17T16:43:43.689723Z"}
1618677823.678601: {"type":"l2update","product_id":"SKL-USD","changes":[["buy","0.7801","68535.2"]],"time":"2021-04-17T16:43:43.689883Z"}
1618677823.6786282: {"type":"l2update","product_id":"SKL-USD","changes":[["sell","0.7920","3743.0"]],"time":"2021-04-17T16:43:43.689883Z"}
1618677823.6827378: {"type":"l2update","product_id":"DASH-BTC","changes":[["sell","0.00621692","10.32100000"]],"time":"2021-04-17T16:43:43.693901Z"}
1618677823.682783: {"type":"l2update","product_id":"DASH-BTC","changes":[["sell","0.00622499","1.62300000"]],"time":"2021-04-17T16:43:43.693926Z"}
1618677823.686751: {"type":"l2update","product_id":"CRV-EUR","changes":[["sell","3.3127","0.00"]],"time":"2021-04-17T16:43:43.698716Z"}
1618677823.686816: {"type":"l2update","product_id":"SKL-BTC","changes":[["buy","0.00001304","2445.9"]],"time":"2021-04-17T16:43:43.699305Z"}
1618677823.6878452: {"type":"l2update","product_id":"CRV-EUR","changes":[["buy","3.2975","96.89"]],"time":"2021-04-17T16:43:43.700269Z"}
1618677823.694359: {"type":"l2update","product_id":"CRV-EUR","changes":[["buy","3.2953","0.00"]],"time":"2021-04-17T16:43:43.709077Z"}
1618677823.694401: {"type":"l2update","product_id":"CRV-EUR","changes":[["sell","3.3126","0.00"]],"time":"2021-04-17T16:43:43.710085Z"}
1618677823.700022: {"type":"l2update","product_id":"CRV-EUR","changes":[["buy","3.2940","5000.00"]],"time":"2021-04-17T16:43:43.715312Z"}
1618677823.7302551: {"type":"l2update","product_id":"DASH-BTC","changes":[["sell","0.00620564","0.00000000"]],"time":"2021-04-17T16:43:43.730334Z"}
1618677823.730301: {"type":"l2update","product_id":"CRV-EUR","changes":[["sell","3.3084","140.93"]],"time":"2021-04-17T16:43:43.730984Z"}
1618677823.730332: {"type":"l2update","product_id":"BAND-BTC","changes":[["sell","0.00033537","36.71"]],"time":"2021-04-17T16:43:43.731523Z"}
1618677823.730355: {"type":"l2update","product_id":"CRV-EUR","changes":[["buy","3.2939","140.93"]],"time":"2021-04-17T16:43:43.739669Z"}
1618677823.764645: {"type":"l2update","product_id":"CRV-EUR","changes":[["sell","3.3197","1416.00"]],"time":"2021-04-17T16:43:43.746786Z"}
1618677823.7647018: {"type":"l2update","product_id":"CRV-EUR","changes":[["buy","3.2940","0.00"]],"time":"2021-04-17T16:43:43.746977Z"}
1618677823.764731: {"type":"l2update","product_id":"CRV-EUR","changes":[["buy","3.2894","5000.00"]],"time":"2021-04-17T16:43:43.754959Z"}
1618677823.7647512: {"type":"l2update","product_id":"SKL-BTC","changes":[["buy","0.00001300","7503.5"]],"time":"2021-04-17T16:43:43.755453Z"}
1618677823.764768: {"type":"l2update","product_id":"SKL-BTC","changes":[["sell","0.00001311","4013.4"]],"time":"2021-04-17T16:43:43.763182Z"}
1618677823.7647831: {"type":"l2update","product_id":"CRV-EUR","changes":[["buy","3.2939","0.00"]],"time":"2021-04-17T16:43:43.763913Z"}
1618677823.764801: {"type":"l2update","product_id":"CRV-EUR","changes":[["buy","3.2954","120.00"]],"time":"2021-04-17T16:43:43.767852Z"}
1618677823.764817: {"type":"l2update","product_id":"NMR-EUR","changes":[["sell","67.0209","0.000"]],"time":"2021-04-17T16:43:43.767768Z"}
1618677823.764836: {"type":"ticker","sequence":471057104,"product_id":"NMR-EUR","price":"67.0209","open_24h":"60.9288","volume_24h":"25747.66100000","low_24h":"60.4695","high_24h":"74.5","volume_30d":"552587.95400000","best_bid":"66.9311","best_ask":"67.0210","side":"buy","time":"2021-04-17T16:43:43.767768Z","trade_id":868604,"last_size":"0.742"}
1618677823.764856: {"type":"match","trade_id":868604,"maker_order_id":"03ec6e32-84b6-4207-929e-fe73710d39b1","taker_order_id":"3d79344d-58bd-4c82-a03a-8b51cc34ed4a","side":"sell","size":"0.742","price":"67.0209","product_id":"NMR-EUR","sequence":471057104,"time":"2021-04-17T16:43:43.767768Z"}
1618677823.764873: {"type":"l2update","product_id":"NMR-EUR","changes":[["sell","67.0210","11.950"]],"time":"2021-04-17T16:43:43.767768Z"}
1618677823.764888: {"type":"match","trade_id":868605,"maker_order_id":"d177e4c4-64cb-4904-aca0-9aca4b1ec7c6","taker_order_id":"3d79344d-58bd-4c82-a03a-8b51cc34ed4a","side":"sell","size":"0.002","price":"67.021","product_id":"NMR-EUR","sequence":471057106,"time":"2021-04-17T16:43:43.767768Z"}
1618677823.7649019: {"type":"ticker","sequence":471057106,"product_id":"NMR-EUR","price":"67.021","open_24h":"60.9288","volume_24h":"25747.66300000","low_24h":"60.4695","high_24h":"74.5","volume_30d":"552587.95600000","best_bid":"66.9311","best_ask":"67.0210","side":"buy","time":"2021-04-17T16:43:43.767768Z","trade_id":868605,"last_size":"0.002"}
1618677823.764916: {"type":"l2update","product_id":"DASH-BTC","changes":[["sell","0.00620887","0.82500000"]],"time":"2021-04-17T16:43:43.771582Z"}
1618677823.764936: {"type":"l2update","product_id":"CRV-EUR","changes":[["buy","3.2972","140.93"]],"time":"2021-04-17T16:43:43.771686Z"}
1618677823.7649522: {"type":"l2update","product_id":"SKL-USD","changes":[["buy","0.7905","866.4"]],"time":"2021-04-17T16:43:43.772969Z"}
1618677823.7649658: {"type":"l2update","product_id":"SKL-USD","changes":[["sell","0.8082","6005.0"]],"time":"2021-04-17T16:43:43.776720Z"}
1618677823.769676: {"type":"l2update","product_id":"NMR-EUR","changes":[["sell","67.9392","3.111"]],"time":"2021-04-17T16:43:43.785555Z"}
1618677823.7740102: {"type":"l2update","product_id":"CRV-EUR","changes":[["sell","3.3112","0.00"]],"time":"2021-04-17T16:43:43.787237Z"}
1618677823.77715: {"type":"l2update","product_id":"DASH-BTC","changes":[["sell","0.00621377","5.55700000"]],"time":"2021-04-17T16:43:43.788325Z"}
1618677823.777193: {"type":"l2update","product_id":"CRV-EUR","changes":[["buy","3.2972","0.00"]],"time":"2021-04-17T16:43:43.789772Z"}
1618677823.7772212: {"type":"l2update","product_id":"CRV-EUR","changes":[["sell","3.3084","0.00"]],"time":"2021-04-17T16:43:43.790053Z"}
1618677823.777243: {"type":"l2update","product_id":"NMR-EUR","changes":[["buy","66.9310","0.000"]],"time":"2021-04-17T16:43:43.790215Z"}
1618677823.783623: {"type":"l2update","product_id":"SKL-USD","changes":[["buy","0.7908","910.0"]],"time":"2021-04-17T16:43:43.796505Z"}
1618677823.78366: {"type":"l2update","product_id":"SKL-USD","changes":[["buy","0.7888","2065.5"]],"time":"2021-04-17T16:43:43.796601Z"}
1618677823.78368: {"type":"l2update","product_id":"NMR-EUR","changes":[["buy","66.9334","4.773"]],"time":"2021-04-17T16:43:43.796803Z"}
1618677823.7837021: {"type":"l2update","product_id":"BAND-BTC","changes":[["sell","0.00033517","0.00"]],"time":"2021-04-17T16:43:43.796968Z"}
1618677823.788867: {"type":"l2update","product_id":"DASH-BTC","changes":[["sell","0.00621229","1.38900000"]],"time":"2021-04-17T16:43:43.805189Z"}
1618677823.795351: {"type":"l2update","product_id":"DASH-BTC","changes":[["sell","0.00621692","0.00000000"]],"time":"2021-04-17T16:43:43.807629Z"}
1618677823.795393: {"type":"l2update","product_id":"DASH-BTC","changes":[["buy","0.00619522","1.91400000"]],"time":"2021-04-17T16:43:43.808906Z"}
1618677823.7954218: {"type":"l2update","product_id":"DASH-BTC","changes":[["buy","0.00619285","0.00000000"]],"time":"2021-04-17T16:43:43.812283Z"}
1618677823.801673: {"type":"l2update","product_id":"CRV-EUR","changes":[["buy","3.2957","140.93"]],"time":"2021-04-17T16:43:43.817158Z"}
1618677823.803874: {"type":"l2update","product_id":"SKL-GBP","changes":[["sell","0.5784","1258.8"]],"time":"2021-04-17T16:43:43.817452Z"}
1618677823.80806: {"type":"l2update","product_id":"SKL-USD","changes":[["sell","0.7923","0.0"]],"time":"2021-04-17T16:43:43.819496Z"}
1618677823.8148339: {"type":"l2update","product_id":"CRV-EUR","changes":[["buy","3.2963","140.93"]],"time":"2021-04-17T16:43:43.830632Z"}
1618677823.8299048: {"type":"l2update","product_id":"SKL-USD","changes":[["buy","0.7801","0.0"]],"time":"2021-04-17T16:43:43.843802Z"}
1618677823.829946: {"type":"l2update","product_id":"SKL-USD","changes":[["sell","0.7920","0.0"]],"time":"2021-04-17T16:43:43.843802Z"}
1618677823.8331: {"type":"l2update","product_id":"DASH-BTC","changes":[["sell","0.00620888","0.00000000"]],"time":"2021-04-17T16:43:43.847286Z"}
1618677823.8420448: {"type":"l2update","product_id":"SKL-GBP","changes":[["sell","0.5784","0.0"]],"time":"2021-04-17T16:43:43.855227Z"}
1618677823.8420858: {"type":"l2update","product_id":"DASH-BTC","changes":[["sell","0.00621228","2.56800000"]],"time":"2021-04-17T16:43:43.855559Z"}
1618677823.842114: {"type":"l2update","product_id":"DASH-BTC","changes":[["sell","0.00622722","0.00000000"]],"time":"2021-04-17T16:43:43.856728Z"}
1618677823.8448918: {"type":"l2update","product_id":"NMR-EUR","changes":[["buy","66.9311","0.000"]],"time":"2021-04-17T16:43:43.861599Z"}
1618677823.8523898: {"type":"l2update","product_id":"YFI-BTC","changes":[["buy","0.82266","0.041684"]],"time":"2021-04-17T16:43:43.868352Z"}
1618677823.8524292: {"type":"l2update","product_id":"BAND-GBP","changes":[["buy","14.7844","12.25"]],"time":"2021-04-17T16:43:43.868369Z"}
1618677823.852452: {"type":"l2update","product_id":"NMR-EUR","changes":[["sell","71.9128","0.000"]],"time":"2021-04-17T16:43:43.869009Z"}
1618677823.856591: {"type":"l2update","product_id":"DASH-BTC","changes":[["buy","0.00619646","10.78100000"]],"time":"2021-04-17T16:43:43.873682Z"}
1618677823.8609521: {"type":"l2update","product_id":"NMR-EUR","changes":[["sell","71.9126","25.150"]],"time":"2021-04-17T16:43:43.876713Z"}
1618677823.8609889: {"type":"l2update","product_id":"NMR-EUR","changes":[["sell","71.7840","13.990"]],"time":"2021-04-17T16:43:43.876713Z"}
1618677823.861011: {"type":"l2update","product_id":"NMR-EUR","changes":[["sell","71.7339","2.420"]],"time":"2021-04-17T16:43:43.876713Z"}
1618677823.8610291: {"type":"l2update","product_id":"NMR-EUR","changes":[["buy","66.9322","1.303"]],"time":"2021-04-17T16:43:43.876888Z"}
1618677823.861047: {"type":"l2update","product_id":"SKL-USD","changes":[["sell","0.7921","2630.0"]],"time":"2021-04-17T16:43:43.877159Z"}
1618677823.868343: {"type":"l2update","product_id":"BAND-BTC","changes":[["buy","0.00033449","66.33"]],"time":"2021-04-17T16:43:43.882341Z"}
1618677823.877984: {"type":"l2update","product_id":"DASH-BTC","changes":[["buy","0.00619646","11.07600000"]],"time":"2021-04-17T16:43:43.893754Z"}
1618677823.8830059: {"type":"l2update","product_id":"DASH-BTC","changes":[["buy","0.00619510","32.84700000"]],"time":"2021-04-17T16:43:43.897689Z"}
1618677823.887536: {"type":"l2update","product_id":"BAND-GBP","changes":[["sell","14.8113","0.00"]],"time":"2021-04-17T16:43:43.904472Z"}
1618677823.901082: {"type":"l2update","product_id":"SKL-BTC","changes":[["sell","0.00001307","7012.6"]],"time":"2021-04-17T16:43:43.916883Z"}
1618677823.90112: {"type":"l2update","product_id":"SKL-GBP","changes":[["sell","0.5771","305.0"]],"time":"2021-04-17T16:43:43.917162Z"}
1618677823.9011421: {"type":"l2update","product_id":"DASH-BTC","changes":[["sell","0.00621781","1.62300000"]],"time":"2021-04-17T16:43:43.919067Z"}
1618677823.904253: {"type":"l2update","product_id":"SKL-BTC","changes":[["buy","0.00001299","5770.2"]],"time":"2021-04-17T16:43:43.919785Z"}
1618677823.908301: {"type":"l2update","product_id":"SKL-BTC","changes":[["sell","0.00001308","1610.2"]],"time":"2021-04-17T16:43:43.919869Z"}
1618677823.916884: {"type":"l2update","product_id":"SKL-USD","changes":[["sell","0.7922","0.0"]],"time":"2021-04-17T16:43:43.932110Z"}
1618677823.9190578: {"type":"l2update","product_id":"NMR-EUR","changes":[["buy","66.9322","0.000"]],"time":"2021-04-17T16:43:43.934323Z"}
1618677823.927876: {"type":"l2update","product_id":"DASH-BTC","changes":[["sell","0.00621227","2.23600000"]],"time":"2021-04-17T16:43:43.943632Z"}
1618677823.927916: {"type":"l2update","product_id":"DASH-BTC","changes":[["buy","0.00619282","2.68300000"]],"time":"2021-04-17T16:43:43.944004Z"}
1618677823.931124: {"type":"l2update","product_id":"DASH-BTC","changes":[["buy","0.00619645","5.27000000"]],"time":"2021-04-17T16:43:43.947696Z"}
1618677823.9399412: {"type":"l2update","product_id":"DASH-BTC","changes":[["buy","0.00619460","2.64000000"]],"time":"2021-04-17T16:43:43.951786Z"}
1618677823.939979: {"type":"l2update","product_id":"YFI-BTC","changes":[["buy","0.82192","0.000000"]],"time":"2021-04-17T16:43:43.956218Z"}
1618677823.9498749: {"type":"l2update","product_id":"NMR-EUR","changes":[["buy","66.9335","1.303"]],"time":"2021-04-17T16:43:43.964574Z"}
1618677823.9499142: {"type":"l2update","product_id":"YFI-BTC","changes":[["buy","0.82314","0.010480"]],"time":"2021-04-17T16:43:43.964682Z"}
1618677823.965238: {"type":"l2update","product_id":"DASH-BTC","changes":[["buy","0.00619287","1.11900000"]],"time":"2021-04-17T16:43:43.976986Z"}
1618677823.9652731: {"type":"l2update","product_id":"SKL-BTC","changes":[["buy","0.00001298","0.0"]],"time":"2021-04-17T16:43:43.977595Z"}
1618677823.977608: {"type":"l2update","product_id":"CRV-EUR","changes":[["sell","3.3028","498.61"]],"time":"2021-04-17T16:43:43.987584Z"}
1618677823.981073: {"type":"l2update","product_id":"NMR-EUR","changes":[["buy","66.9334","0.000"]],"time":"2021-04-17T16:43:43.994727Z"}
1618677823.985332: {"type":"l2update","product_id":"DASH-BTC","changes":[["buy","0.00619647","1.54100000"]],"time":"2021-04-17T16:43:43.999255Z"}
1618677823.985378: {"type":"l2update","product_id":"SKL-BTC","changes":[["sell","0.00001308","716.5"]],"time":"2021-04-17T16:43:43.999461Z"}
1618677823.9906251: {"type":"l2update","product_id":"CRV-EUR","changes":[["buy","3.2806","256.82"]],"time":"2021-04-17T16:43:44.004499Z"}
1618677823.990659: {"type":"l2update","product_id":"DASH-BTC","changes":[["sell","0.00621781","0.00000000"]],"time":"2021-04-17T16:43:44.007092Z"}
1618677823.99404: {"type":"l2update","product_id":"NMR-EUR","changes":[["buy","66.9353","4.773"]],"time":"2021-04-17T16:43:44.008176Z"}
1618677823.997619: {"type":"l2update","product_id":"SKL-BTC","changes":[["sell","0.00001314","6845.6"]],"time":"2021-04-17T16:43:44.011336Z"}
1618677823.997649: {"type":"l2update","product_id":"SKL-BTC","changes":[["sell","0.00001739","10.9"]],"time":"2021-04-17T16:43:44.011336Z"}
1618677823.9976661: {"type":"l2update","product_id":"CRV-EUR","changes":[["buy","3.2955","5000.00"]],"time":"2021-04-17T16:43:44.013753Z"}
1618677823.997685: {"type":"l2update","product_id":"SKL-USD","changes":[["buy","0.7798","71313.0"]],"time":"2021-04-17T16:43:44.013828Z"}
1618677823.997702: {"type":"l2update","product_id":"SKL-USD","changes":[["sell","0.7920","3141.6"]],"time":"2021-04-17T16:43:44.013828Z"}
1618677824.00338: {"type":"l2update","product_id":"CRV-EUR","changes":[["sell","3.3112","254.45"]],"time":"2021-04-17T16:43:44.018128Z"}
1618677824.0089111: {"type":"l2update","product_id":"SKL-BTC","changes":[["sell","0.00001654","325.0"]],"time":"2021-04-17T16:43:44.018364Z"}
1618677824.008949: {"type":"l2update","product_id":"SKL-BTC","changes":[["sell","0.00001649","315.0"]],"time":"2021-04-17T16:43:44.018364Z"}
1618677824.008971: {"type":"l2update","product_id":"BAND-BTC","changes":[["sell","0.00033516","74.57"]],"time":"2021-04-17T16:43:44.022446Z"}
1618677824.008986: {"type":"l2update","product_id":"DASH-BTC","changes":[["buy","0.00619522","0.00000000"]],"time":"2021-04-17T16:43:44.025969Z"}
1618677824.013563: {"type":"l2update","product_id":"DASH-BTC","changes":[["sell","0.00621227","3.85900000"]],"time":"2021-04-17T16:43:44.026551Z"}
1618677824.0177732: {"type":"l2update","product_id":"SKL-USD","changes":[["buy","0.7905","0.0"]],"time":"2021-04-17T16:43:44.032377Z"}
1618677824.034636: {"type":"l2update","product_id":"CRV-EUR","changes":[["buy","3.2699","0.00"]],"time":"2021-04-17T16:43:44.048586Z"}
1618677824.034672: {"type":"l2update","product_id":"SKL-BTC","changes":[["sell","0.00001307","7906.2"]],"time":"2021-04-17T16:43:44.051129Z"}
1618677824.049695: {"type":"l2update","product_id":"SKL-BTC","changes":[["sell","0.00001309","7721.6"]],"time":"2021-04-17T16:43:44.063942Z"}
1618677824.0497699: {"type":"l2update","product_id":"SKL-USD","changes":[["buy","0.7904","3496.6"]],"time":"2021-04-17T16:43:44.063979Z"}
1618677824.0588212: {"type":"l2update","product_id":"SKL-BTC","changes":[["buy","0.00001299","1976.2"]],"time":"2021-04-17T16:43:44.073209Z"}
1618677824.064578: {"type":"l2update","product_id":"SKL-BTC","changes":[["sell","0.00001310","11318.2"]],"time":"2021-04-17T16:43:44.080296Z"}
1618677824.078157: {"type":"l2update","product_id":"DASH-BTC","changes":[["sell","0.00620887","0.00000000"]],"time":"2021-04-17T16:43:44.092508Z"}
1618677824.082446: {"type":"l2update","product_id":"DASH-BTC","changes":[["buy","0.00619510","0.00000000"]],"time":"2021-04-17T16:43:44.097810Z"}
1618677824.086964: {"type":"l2update","product_id":"CRV-EUR","changes":[["buy","3.2969","526.79"]],"time":"2021-04-17T16:43:44.101110Z"}
1618677824.1065652: {"type":"l2update","product_id":"DASH-BTC","changes":[["sell","0.00621227","4.68400000"]],"time":"2021-04-17T16:43:44.122360Z"}
1618677824.1097531: {"type":"l2update","product_id":"YFI-BTC","changes":[["buy","0.82510","0.000000"]],"time":"2021-04-17T16:43:44.125723Z"}
1618677824.1248121: {"type":"l2update","product_id":"NMR-EUR","changes":[["buy","66.4814","0.000"]],"time":"2021-04-17T16:43:44.140646Z"}
1618677824.130071: {"type":"l2update","product_id":"DASH-BTC","changes":[["buy","0.00614333","0.05000000"]],"time":"2021-04-17T16:43:44.144300Z"}
1618677824.1301: {"type":"l2update","product_id":"DASH-BTC","changes":[["buy","0.00614334","6.98700000"]],"time":"2021-04-17T16:43:44.144300Z"}
1618677824.1301172: {"type":"l2update","product_id":"DASH-BTC","changes":[["sell","0.00621782","0.00000000"]],"time":"2021-04-17T16:43:44.144533Z"}
1618677824.13694: {"type":"l2update","product_id":"DASH-BTC","changes":[["buy","0.00618761","0.00000000"]],"time":"2021-04-17T16:43:44.148792Z"}
1618677824.136974: {"type":"l2update","product_id":"DASH-BTC","changes":[["buy","0.00614338","2.69000000"]],"time":"2021-04-17T16:43:44.152416Z"}
1618677824.136995: {"type":"l2update","product_id":"DASH-BTC","changes":[["buy","0.00614337","33.33300000"]],"time":"2021-04-17T16:43:44.152416Z"}
1618677824.1370099: {"type":"l2update","product_id":"NMR-EUR","changes":[["buy","66.9335","0.000"]],"time":"2021-04-17T16:43:44.152814Z"}
1618677824.142199: {"type":"l2update","product_id":"SKL-BTC","changes":[["sell","0.00001307","9015.3"]],"time":"2021-04-17T16:43:44.156030Z"}
1618677824.145262: {"type":"l2update","product_id":"DASH-BTC","changes":[["sell","0.00622498","1.88000000"]],"time":"2021-04-17T16:43:44.160697Z"}
1618677824.1495512: {"type":"l2update","product_id":"DASH-BTC","changes":[["buy","0.00619647","15.19400000"]],"time":"2021-04-17T16:43:44.164375Z"}
1618677824.156178: {"type":"l2update","product_id":"SKL-USD","changes":[["buy","0.7798","0.0"]],"time":"2021-04-17T16:43:44.167509Z"}
1618677824.157143: {"type":"l2update","product_id":"SKL-USD","changes":[["sell","0.8075","6000.0"]],"time":"2021-04-17T16:43:44.174944Z"}
1618677824.168939: {"type":"l2update","product_id":"SKL-BTC","changes":[["buy","0.00001299","4612.7"]],"time":"2021-04-17T16:43:44.183152Z"}
1618677824.1689768: {"type":"l2update","product_id":"NMR-EUR","changes":[["buy","66.9354","1.303"]],"time":"2021-04-17T16:43:44.183324Z"}
1618677824.169003: {"type":"l2update","product_id":"DASH-BTC","changes":[["buy","0.00619624","32.84700000"]],"time":"2021-04-17T16:43:44.183370Z"}
1618677824.1721249: {"type":"l2update","product_id":"DASH-BTC","changes":[["sell","0.00621871","0.00000000"]],"time":"2021-04-17T16:43:44.187403Z"}
1618677824.191915: {"type":"l2update","product_id":"DASH-BTC","changes":[["sell","0.00622497","10.24200000"]],"time":"2021-04-17T16:43:44.201640Z"}
1618677824.1920571: {"type":"l2update","product_id":"NMR-EUR","changes":[["buy","66.9353","0.000"]],"time":"2021-04-17T16:43:44.205583Z"}
1618677824.194656: {"type":"l2update","product_id":"NMR-EUR","changes":[["buy","66.4815","13.000"]],"time":"2021-04-17T16:43:44.209013Z"}
1618677824.203864: {"type":"l2update","product_id":"NMR-EUR","changes":[["buy","66.9368","4.773"]],"time":"2021-04-17T16:43:44.216784Z"}
1618677824.209724: {"type":"l2update","product_id":"SKL-BTC","changes":[["sell","0.00001308","0.0"]],"time":"2021-04-17T16:43:44.221505Z"}
1618677824.223393: {"type":"l2update","product_id":"SKL-BTC","changes":[["buy","0.00001299","8141.1"]],"time":"2021-04-17T16:43:44.231690Z"}
1618677824.223511: {"type":"l2update","product_id":"DASH-BTC","changes":[["sell","0.00622497","16.25900000"]],"time":"2021-04-17T16:43:44.231761Z"}
1618677824.223565: {"type":"l2update","product_id":"BAND-BTC","changes":[["sell","0.00033560","0.00"]],"time":"2021-04-17T16:43:44.238709Z"}
1618677824.2236319: {"type":"l2update","product_id":"BAND-BTC","changes":[["buy","0.00033170","470.66"]],"time":"2021-04-17T16:43:44.238709Z"}
1618677824.2236722: {"type":"l2update","product_id":"BAND-BTC","changes":[["buy","0.00033197","0.00"]],"time":"2021-04-17T16:43:44.238709Z"}
1618677824.233543: {"type":"l2update","product_id":"BAND-GBP","changes":[["buy","14.6486","0.10"]],"time":"2021-04-17T16:43:44.242740Z"}
1618677824.233661: {"type":"l2update","product_id":"BAND-GBP","changes":[["buy","14.6485","4.10"]],"time":"2021-04-17T16:43:44.242740Z"}
1618677824.2337139: {"type":"l2update","product_id":"SKL-USD","changes":[["buy","0.7905","989.7"]],"time":"2021-04-17T16:43:44.242819Z"}
1618677824.233778: {"type":"l2update","product_id":"DASH-BTC","changes":[["buy","0.00619646","10.78100000"]],"time":"2021-04-17T16:43:44.243015Z"}
1618677824.23382: {"type":"l2update","product_id":"BAND-BTC","changes":[["sell","0.00033537","47.71"]],"time":"2021-04-17T16:43:44.246277Z"}
1618677824.233857: {"type":"l2update","product_id":"BAND-BTC","changes":[["buy","0.00033170","482.06"]],"time":"2021-04-17T16:43:44.246277Z"}
1618677824.233899: {"type":"l2update","product_id":"SKL-BTC","changes":[["buy","0.00001302","6425.8"]],"time":"2021-04-17T16:43:44.246858Z"}
1618677824.239938: {"type":"l2update","product_id":"BAND-GBP","changes":[["buy","14.6489","15.40"]],"time":"2021-04-17T16:43:44.251682Z"}
1618677824.2400692: {"type":"l2update","product_id":"SKL-BTC","changes":[["buy","0.00001303","12189.5"]],"time":"2021-04-17T16:43:44.254959Z"}
1618677824.249946: {"type":"l2update","product_id":"YFI-BTC","changes":[["buy","0.82335","0.000000"]],"time":"2021-04-17T16:43:44.266169Z"}
1618677824.250082: {"type":"l2update","product_id":"YFI-BTC","changes":[["buy","0.82274","0.053074"]],"time":"2021-04-17T16:43:44.266169Z"}
1618677824.250137: {"type":"l2update","product_id":"YFI-BTC","changes":[["buy","0.82274","0.000000"]],"time":"2021-04-17T16:43:44.266169Z"}
1618677824.2532558: {"type":"l2update","product_id":"DASH-BTC","changes":[["buy","0.00619648","0.29500000"]],"time":"2021-04-17T16:43:44.266819Z"}
1618677824.2533581: {"type":"l2update","product_id":"CRV-EUR","changes":[["buy","3.2952","505.82"]],"time":"2021-04-17T16:43:44.266837Z"}
1618677824.255361: {"type":"l2update","product_id":"CRV-EUR","changes":[["buy","3.2697","103.50"]],"time":"2021-04-17T16:43:44.269763Z"}
1618677824.2606862: {"type":"l2update","product_id":"SKL-USD","changes":[["buy","0.7880","3366.7"]],"time":"2021-04-17T16:43:44.270985Z"}
1618677824.2607749: {"type":"l2update","product_id":"DASH-BTC","changes":[["sell","0.00622051","14.63200000"]],"time":"2021-04-17T16:43:44.274663Z"}
1618677824.264064: {"type":"l2update","product_id":"YFI-BTC","changes":[["buy","0.82409","0.053003"]],"time":"2021-04-17T16:43:44.277610Z"}
1618677824.26413: {"type":"l2update","product_id":"YFI-BTC","changes":[["buy","0.82267","0.063604"]],"time":"2021-04-17T16:43:44.277610Z"}
1618677824.266324: {"type":"l2update","product_id":"SKL-GBP","changes":[["sell","0.5771","1313.2"]],"time":"2021-04-17T16:43:44.281533Z"}
1618677824.281446: {"type":"l2update","product_id":"BAND-GBP","changes":[["sell","14.8147","12.96"]],"time":"2021-04-17T16:43:44.296266Z"}
1618677824.286515: {"type":"l2update","product_id":"DASH-BTC","changes":[["buy","0.00619287","0.00000000"]],"time":"2021-04-17T16:43:44.302359Z"}
1618677824.290008: {"type":"l2update","product_id":"DASH-BTC","changes":[["sell","0.00622499","0.00000000"]],"time":"2021-04-17T16:43:44.305736Z"}
1618677824.2954361: {"type":"l2update","product_id":"BAND-BTC","changes":[["buy","0.00033395","0.00"]],"time":"2021-04-17T16:43:44.308406Z"}
1618677824.3039832: {"type":"l2update","product_id":"SKL-USD","changes":[["sell","0.8082","12005.0"]],"time":"2021-04-17T16:43:44.319269Z"}
1618677824.309312: {"type":"l2update","product_id":"SKL-USD","changes":[["sell","0.8075","0.0"]],"time":"2021-04-17T16:43:44.322805Z"}
1618677824.309377: {"type":"l2update","product_id":"DASH-BTC","changes":[["buy","0.00619648","1.41400000"]],"time":"2021-04-17T16:43:44.323010Z"}
1618677824.315735: {"type":"l2update","product_id":"SKL-USD","changes":[["sell","0.8082","18005.0"]],"time":"2021-04-17T16:43:44.331495Z"}
1618677824.315789: {"type":"l2update","product_id":"SKL-USD","changes":[["buy","0.7799","61109.7"]],"time":"2021-04-17T16:43:44.331623Z"}
1618677824.3158212: {"type":"l2update","product_id":"SKL-USD","changes":[["sell","0.7920","3191.3"]],"time":"2021-04-17T16:43:44.331623Z"}
1618677824.318801: {"type":"l2update","product_id":"CRV-EUR","changes":[["buy","3.2895","400.00"]],"time":"2021-04-17T16:43:44.334183Z"}
1618677824.3188648: {"type":"l2update","product_id":"DASH-BTC","changes":[["sell","0.00622496","1.62300000"]],"time":"2021-04-17T16:43:44.334282Z"}
1618677824.346557: {"type":"l2update","product_id":"SKL-USD","changes":[["buy","0.7832","46.2"]],"time":"2021-04-17T16:43:44.361091Z"}
1618677824.3504589: {"type":"l2update","product_id":"SKL-USD","changes":[["buy","0.7855","1325.0"]],"time":"2021-04-17T16:43:44.364932Z"}
1618677824.350516: {"type":"l2update","product_id":"DASH-BTC","changes":[["buy","0.00619286","0.00000000"]],"time":"2021-04-17T16:43:44.366045Z"}
1618677824.355516: {"type":"l2update","product_id":"DASH-BTC","changes":[["buy","0.00619647","1.54100000"]],"time":"2021-04-17T16:43:44.371541Z"}
1618677824.3604228: {"type":"l2update","product_id":"SKL-BTC","changes":[["sell","0.00001310","10601.7"]],"time":"2021-04-17T16:43:44.372448Z"}
1618677824.374988: {"type":"l2update","product_id":"DASH-BTC","changes":[["buy","0.00619648","15.06700000"]],"time":"2021-04-17T16:43:44.383747Z"}
1618677824.375051: {"type":"l2update","product_id":"SKL-USD","changes":[["buy","0.7904","866.5"]],"time":"2021-04-17T16:43:44.388295Z"}
1618677824.380107: {"type":"l2update","product_id":"SKL-BTC","changes":[["buy","0.00001299","8373.9"]],"time":"2021-04-17T16:43:44.391753Z"}
1618677824.395307: {"type":"l2update","product_id":"CRV-EUR","changes":[["sell","3.3027","5000.00"]],"time":"2021-04-17T16:43:44.410774Z"}
1618677824.400703: {"type":"l2update","product_id":"DASH-BTC","changes":[["buy","0.00619647","0.00000000"]],"time":"2021-04-17T16:43:44.414738Z"}
1618677824.400811: {"type":"l2update","product_id":"SKL-USD","changes":[["buy","0.7882","1900.0"]],"time":"2021-04-17T16:43:44.415108Z"}
1618677824.4008791: {"type":"l2update","product_id":"DASH-BTC","changes":[["buy","0.00619645","2.70100000"]],"time":"2021-04-17T16:43:44.415146Z"}
1618677824.4057071: {"type":"l2update","product_id":"DASH-BTC","changes":[["sell","0.00621302","1.61100000"]],"time":"2021-04-17T16:43:44.418484Z"}
1618677824.4058099: {"type":"l2update","product_id":"CRV-EUR","changes":[["buy","3.2894","0.00"]],"time":"2021-04-17T16:43:44.419153Z"}
1618677824.4161642: {"type":"l2update","product_id":"CRV-EUR","changes":[["sell","3.3039","0.00"]],"time":"2021-04-17T16:43:44.430693Z"}
1618677824.416266: {"type":"l2update","product_id":"SKL-USD","changes":[["buy","0.7896","2525.2"]],"time":"2021-04-17T16:43:44.432087Z"}
1618677824.418296: {"type":"l2update","product_id":"SKL-USD","changes":[["buy","0.7905","3619.5"]],"time":"2021-04-17T16:43:44.433958Z"}
1618677824.42706: {"type":"l2update","product_id":"CRV-EUR","changes":[["buy","3.2894","81.00"]],"time":"2021-04-17T16:43:44.441767Z"}
1618677824.4271622: {"type":"l2update","product_id":"CRV-EUR","changes":[["buy","3.2698","3.50"]],"time":"2021-04-17T16:43:44.441767Z"}
1618677824.4366488: {"type":"l2update","product_id":"DASH-BTC","changes":[["buy","0.00619648","28.72000000"]],"time":"2021-04-17T16:43:44.450238Z"}
1618677824.436743: {"type":"l2update","product_id":"SKL-USD","changes":[["buy","0.7713","0.0"]],"time":"2021-04-17T16:43:44.451548Z"}
1618677824.436815: {"type":"l2update","product_id":"SKL-USD","changes":[["buy","0.7888","868.9"]],"time":"2021-04-17T16:43:44.451926Z"}
1618677824.444149: {"type":"l2update","product_id":"DASH-BTC","changes":[["buy","0.00619649","2.56700000"]],"time":"2021-04-17T16:43:44.458494Z"}
1618677824.446221: {"type":"l2update","product_id":"DASH-BTC","changes":[["buy","0.00619649","4.10800000"]],"time":"2021-04-17T16:43:44.462429Z"}
1618677824.460958: {"type":"l2update","product_id":"SKL-USD","changes":[["sell","0.8082","12005.0"]],"time":"2021-04-17T16:43:44.471187Z"}
1618677824.461047: {"type":"l2update","product_id":"SKL-USD","changes":[["buy","0.7901","1194.6"]],"time":"2021-04-17T16:43:44.474570Z"}
1618677824.464421: {"type":"l2update","product_id":"SKL-USD","changes":[["buy","0.7866","2659.8"]],"time":"2021-04-17T16:43:44.481491Z"}
1618677824.468601: {"type":"l2update","product_id":"SKL-USD","changes":[["sell","0.7920","3161.8"]],"time":"2021-04-17T16:43:44.481792Z"}
1618677824.468687: {"type":"match","trade_id":1568273,"maker_order_id":"dfb5a42f-5844-46a5-a35d-78fbf64defd2","taker_order_id":"55ce27c2-1ece-4420-9ab0-07ec1651647d","side":"sell","size":"29.5","price":"0.792","product_id":"SKL-USD","sequence":201390997,"time":"2021-04-17T16:43:44.481792Z"}
1618677824.468742: {"type":"ticker","sequence":201390997,"product_id":"SKL-USD","price":"0.792","open_24h":"0.7055","volume_24h":"34254843.00000000","low_24h":"0.6915","high_24h":"0.8098","volume_30d":"948682195.70000000","best_bid":"0.7908","best_ask":"0.7920","side":"buy","time":"2021-04-17T16:43:44.481792Z","trade_id":1568273,"last_size":"29.5"}
1618677824.468784: {"type":"l2update","product_id":"SKL-USD","changes":[["sell","0.8074","6009.9"]],"time":"2021-04-17T16:43:44.482187Z"}
1618677824.470721: {"type":"l2update","product_id":"SKL-USD","changes":[["buy","0.7799","115.4"]],"time":"2021-04-17T16:43:44.486073Z"}
1618677824.470809: {"type":"l2update","product_id":"SKL-USD","changes":[["sell","0.7920","3112.1"]],"time":"2021-04-17T16:43:44.486073Z"}
1618677824.473014: {"type":"l2update","product_id":"SKL-USD","changes":[["sell","0.8074","12009.9"]],"time":"2021-04-17T16:43:44.489758Z"}
1618677824.487544: {"type":"l2update","product_id":"SKL-USD","changes":[["buy","0.7882","27413.9"]],"time":"2021-04-17T16:43:44.501494Z"}
1618677824.512419: {"type":"l2update","product_id":"SKL-BTC","changes":[["sell","0.00001308","716.5"]],"time":"2021-04-17T16:43:44.528336Z"}
1618677824.5162659: {"type":"l2update","product_id":"SKL-USD","changes":[["buy","0.7905","2629.8"]],"time":"2021-04-17T16:43:44.532223Z"}
1618677824.519849: {"type":"l2update","product_id":"SKL-BTC","changes":[["buy","0.00001303","11199.8"]],"time":"2021-04-17T16:43:44.536158Z"}
1618677824.528783: {"type":"l2update","product_id":"SKL-BTC","changes":[["buy","0.00001301","17487.9"]],"time":"2021-04-17T16:43:44.544502Z"}
1618677824.528872: {"type":"l2update","product_id":"SKL-BTC","changes":[["buy","0.00001299","8141.1"]],"time":"2021-04-17T16:43:44.545323Z"}
1618677824.528925: {"type":"l2update","product_id":"SKL-BTC","changes":[["buy","0.00001299","4612.7"]],"time":"2021-04-17T16:43:44.545323Z"}
1618677824.563009: {"type":"l2update","product_id":"DASH-BTC","changes":[["buy","0.00619648","28.42500000"]],"time":"2021-04-17T16:43:44.575314Z"}
1618677824.5683682: {"type":"l2update","product_id":"SKL-GBP","changes":[["sell","0.5773","4261.0"]],"time":"2021-04-17T16:43:44.581097Z"}
1618677824.5720909: {"type":"l2update","product_id":"SKL-BTC","changes":[["sell","0.00001307","7906.2"]],"time":"2021-04-17T16:43:44.589515Z"}
1618677824.572845: {"type":"l2update","product_id":"SKL-GBP","changes":[["sell","0.5771","305.0"]],"time":"2021-04-17T16:43:44.590496Z"}
1618677824.585122: {"type":"l2update","product_id":"DASH-BTC","changes":[["buy","0.00619650","0.29500000"]],"time":"2021-04-17T16:43:44.596182Z"}
1618677824.5852249: {"type":"l2update","product_id":"SKL-GBP","changes":[["buy","0.5751","2525.0"]],"time":"2021-04-17T16:43:44.596403Z"}
1618677824.592345: {"type":"l2update","product_id":"SKL-GBP","changes":[["buy","0.5748","0.0"]],"time":"2021-04-17T16:43:44.606241Z"}
1618677824.592449: {"type":"l2update","product_id":"BAND-BTC","changes":[["buy","0.00033417","25.72"]],"time":"2021-04-17T16:43:44.606842Z"}
1618677824.596834: {"type":"l2update","product_id":"SKL-GBP","changes":[["buy","0.5752","1027.7"]],"time":"2021-04-17T16:43:44.609406Z"}
1618677824.596906: {"type":"l2update","product_id":"SKL-GBP","changes":[["buy","0.5746","6311.9"]],"time":"2021-04-17T16:43:44.609418Z"}
1618677824.6012712: {"type":"l2update","product_id":"DASH-BTC","changes":[["sell","0.00621603","2.67800000"]],"time":"2021-04-17T16:43:44.612892Z"}
1618677824.6013398: {"type":"l2update","product_id":"DASH-BTC","changes":[["buy","0.00614333","0.00000000"]],"time":"2021-04-17T16:43:44.615233Z"}
1618677824.601384: {"type":"l2update","product_id":"DASH-BTC","changes":[["buy","0.00614335","1.85000000"]],"time":"2021-04-17T16:43:44.615233Z"}
1618677824.601414: {"type":"l2update","product_id":"YFI-BTC","changes":[["buy","0.81870","0.000000"]],"time":"2021-04-17T16:43:44.617183Z"}
1618677824.606295: {"type":"l2update","product_id":"DASH-BTC","changes":[["buy","0.00614339","0.93000000"]],"time":"2021-04-17T16:43:44.620879Z"}
1618677824.60636: {"type":"l2update","product_id":"DASH-BTC","changes":[["buy","0.00614338","2.80000000"]],"time":"2021-04-17T16:43:44.620879Z"}
1618677824.631169: {"type":"l2update","product_id":"YFI-BTC","changes":[["buy","0.82556","0.029966"]],"time":"2021-04-17T16:43:44.644583Z"}
1618677824.631249: {"type":"l2update","product_id":"SKL-USD","changes":[["buy","0.7798","61636.1"]],"time":"2021-04-17T16:43:44.644672Z"}
1618677824.637354: {"type":"l2update","product_id":"DASH-BTC","changes":[["buy","0.00619648","14.77200000"]],"time":"2021-04-17T16:43:44.652200Z"}
1618677824.637405: {"type":"l2update","product_id":"CRV-EUR","changes":[["sell","3.3197","0.00"]],"time":"2021-04-17T16:43:44.654575Z"}
1618677824.638325: {"type":"l2update","product_id":"SKL-USD","changes":[["sell","0.8082","6005.0"]],"time":"2021-04-17T16:43:44.655659Z"}
1618677824.6426728: {"type":"l2update","product_id":"DASH-BTC","changes":[["buy","0.00619648","1.11900000"]],"time":"2021-04-17T16:43:44.657343Z"}
1618677824.652569: {"type":"l2update","product_id":"CRV-EUR","changes":[["sell","3.3111","1416.00"]],"time":"2021-04-17T16:43:44.667813Z"}
1618677824.65787: {"type":"l2update","product_id":"DASH-BTC","changes":[["buy","0.00619650","13.94800000"]],"time":"2021-04-17T16:43:44.671726Z"}
1618677824.682375: {"type":"l2update","product_id":"BAND-GBP","changes":[["buy","14.7697","0.00"]],"time":"2021-04-17T16:43:44.697364Z"}
1618677824.6834571: {"type":"l2update","product_id":"YFI-BTC","changes":[["buy","0.82583","0.000000"]],"time":"2021-04-17T16:43:44.700403Z"}
1618677824.687634: {"type":"l2update","product_id":"SKL-BTC","changes":[["sell","0.00001310","11191.3"]],"time":"2021-04-17T16:43:44.702843Z"}
1618677824.687692: {"type":"l2update","product_id":"SKL-BTC","changes":[["buy","0.00001300","11292.1"]],"time":"2021-04-17T16:43:44.703333Z"}
1618677824.73145: {"type":"l2update","product_id":"BAND-BTC","changes":[["sell","0.00033537","11.00"]],"time":"2021-04-17T16:43:44.738752Z"}
1618677824.731509: {"type":"l2update","product_id":"DASH-BTC","changes":[["buy","0.00619650","27.60100000"]],"time":"2021-04-17T16:43:44.738913Z"}
1618677824.741749: {"type":"l2update","product_id":"YFI-BTC","changes":[["buy","0.82583","0.017056"]],"time":"2021-04-17T16:43:44.749863Z"}
1618677824.749105: {"type":"l2update","product_id":"BAND-GBP","changes":[["buy","14.7787","36.00"]],"time":"2021-04-17T16:43:44.765333Z"}
1618677824.770186: {"type":"l2update","product_id":"BAND-BTC","changes":[["sell","0.00033542","36.70"]],"time":"2021-04-17T16:43:44.784447Z"}
1618677824.770258: {"type":"l2update","product_id":"DASH-BTC","changes":[["sell","0.00621372","2.62200000"]],"time":"2021-04-17T16:43:44.784639Z"}
1618677824.778403: {"type":"l2update","product_id":"DASH-BTC","changes":[["buy","0.00619649","2.56700000"]],"time":"2021-04-17T16:43:44.791574Z"}
1618677824.778456: {"type":"l2update","product_id":"SKL-USD","changes":[["buy","0.7908","450.0"]],"time":"2021-04-17T16:43:44.792754Z"}
1618677824.7951639: {"type":"l2update","product_id":"SKL-USD","changes":[["buy","0.7798","73306.3"]],"time":"2021-04-17T16:43:44.803616Z"}
1618677824.819623: {"type":"l2update","product_id":"SKL-BTC","changes":[["sell","0.00001308","0.0"]],"time":"2021-04-17T16:43:44.836957Z"}
1618677824.827154: {"type":"l2update","product_id":"SKL-BTC","changes":[["buy","0.00001301","16498.2"]],"time":"2021-04-17T16:43:44.839972Z"}
1618677824.8302982: {"type":"l2update","product_id":"DASH-BTC","changes":[["buy","0.00619651","1.54100000"]],"time":"2021-04-17T16:43:44.845371Z"}
1618677824.8367622: {"type":"l2update","product_id":"SKL-BTC","changes":[["buy","0.00001302","7415.5"]],"time":"2021-04-17T16:43:44.852838Z"}
1618677824.840929: {"type":"l2update","product_id":"SKL-BTC","changes":[["buy","0.00001300","7503.5"]],"time":"2021-04-17T16:43:44.857207Z"}
1618677824.8580081: {"type":"l2update","product_id":"YFI-BTC","changes":[["buy","0.81897","0.010429"]],"time":"2021-04-17T16:43:44.872881Z"}
1618677824.882656: {"type":"l2update","product_id":"CRV-EUR","changes":[["buy","3.2951","5000.00"]],"time":"2021-04-17T16:43:44.897897Z"}
1618677824.8834188: {"type":"l2update","product_id":"DASH-BTC","changes":[["sell","0.00621228","0.00000000"]],"time":"2021-04-17T16:43:44.901395Z"}
1618677824.885083: {"type":"l2update","product_id":"YFI-BTC","changes":[["buy","0.82579","0.029660"]],"time":"2021-04-17T16:43:44.901749Z"}
1618677824.8932421: {"type":"l2update","product_id":"CRV-EUR","changes":[["buy","3.2955","0.00"]],"time":"2021-04-17T16:43:44.906533Z"}
1618677824.9007869: {"type":"l2update","product_id":"SKL-USD","changes":[["sell","0.7921","0.0"]],"time":"2021-04-17T16:43:44.914927Z"}
1618677824.900842: {"type":"l2update","product_id":"CRV-EUR","changes":[["sell","3.3201","110.00"]],"time":"2021-04-17T16:43:44.915585Z"}
1618677824.907234: {"type":"l2update","product_id":"CRV-EUR","changes":[["sell","3.3198","91.00"]],"time":"2021-04-17T16:43:44.920930Z"}
1618677824.923109: {"type":"l2update","product_id":"SKL-USD","changes":[["sell","0.8074","6009.9"]],"time":"2021-04-17T16:43:44.939769Z"}
1618677824.931381: {"type":"l2update","product_id":"DASH-BTC","changes":[["sell","0.00621226","2.56700000"]],"time":"2021-04-17T16:43:44.944717Z"}
1618677824.940011: {"type":"l2update","product_id":"YFI-BTC","changes":[["buy","0.82579","0.000000"]],"time":"2021-04-17T16:43:44.952930Z"}
1618677824.9400609: {"type":"l2update","product_id":"CRV-EUR","changes":[["buy","3.2954","0.00"]],"time":"2021-04-17T16:43:44.953781Z"}
1618677824.940093: {"type":"l2update","product_id":"DASH-BTC","changes":[["buy","0.00619648","0.00000000"]],"time":"2021-04-17T16:43:44.954229Z"}
1618677824.942703: {"type":"l2update","product_id":"DASH-BTC","changes":[["sell","0.00621227","3.85900000"]],"time":"2021-04-17T16:43:44.957592Z"}
1618677824.942744: {"type":"l2update","product_id":"DASH-BTC","changes":[["sell","0.00621227","2.23600000"]],"time":"2021-04-17T16:43:44.959914Z"}
1618677824.950005: {"type":"l2update","product_id":"DASH-BTC","changes":[["sell","0.00621227","0.00000000"]],"time":"2021-04-17T16:43:44.962949Z"}
1618677824.950057: {"type":"l2update","product_id":"DASH-BTC","changes":[["sell","0.00622496","0.00000000"]],"time":"2021-04-17T16:43:44.965442Z"}
1618677824.958524: {"type":"l2update","product_id":"SKL-USD","changes":[["sell","0.7923","2629.7"]],"time":"2021-04-17T16:43:44.970800Z"}
1618677824.9585779: {"type":"l2update","product_id":"SKL-USD","changes":[["buy","0.7675","2043.0"]],"time":"2021-04-17T16:43:44.971845Z"}
1618677824.958604: {"type":"l2update","product_id":"SKL-USD","changes":[["buy","0.7569","25645.0"]],"time":"2021-04-17T16:43:44.971845Z"}
1618677824.961186: {"type":"l2update","product_id":"DASH-BTC","changes":[["buy","0.00619651","2.66000000"]],"time":"2021-04-17T16:43:44.975021Z"}
1618677824.9735591: {"type":"l2update","product_id":"DASH-BTC","changes":[["sell","0.00621228","0.82500000"]],"time":"2021-04-17T16:43:44.986452Z"}
1618677824.974564: {"type":"l2update","product_id":"SKL-BTC","changes":[["sell","0.00001310","10601.7"]],"time":"2021-04-17T16:43:44.990991Z"}
1618677824.9859881: {"type":"l2update","product_id":"DASH-BTC","changes":[["sell","0.00621371","1.62300000"]],"time":"2021-04-17T16:43:44.998288Z"}
1618677824.9869351: {"type":"l2update","product_id":"SKL-USD","changes":[["sell","0.7920","2.1"]],"time":"2021-04-17T16:43:45.001820Z"}
1618677824.986969: {"type":"match","trade_id":1568274,"maker_order_id":"dfb5a42f-5844-46a5-a35d-78fbf64defd2","taker_order_id":"9d25ce81-97e3-4505-93db-78a74030aca4","side":"sell","size":"3110","price":"0.792","product_id":"SKL-USD","sequence":201391021,"time":"2021-04-17T16:43:45.001820Z"}
1618677824.9869921: {"type":"ticker","sequence":201391021,"product_id":"SKL-USD","price":"0.792","open_24h":"0.7055","volume_24h":"34257953.00000000","low_24h":"0.6915","high_24h":"0.8098","volume_30d":"948685305.70000000","best_bid":"0.7908","best_ask":"0.7920","side":"buy","time":"2021-04-17T16:43:45.001820Z","trade_id":1568274,"last_size":"3110"}
1618677824.998736: {"type":"l2update","product_id":"DASH-BTC","changes":[["sell","0.00621371","3.85900000"]],"time":"2021-04-17T16:43:45.009523Z"}
1618677824.998774: {"type":"l2update","product_id":"DASH-BTC","changes":[["buy","0.00619650","27.30600000"]],"time":"2021-04-17T16:43:45.012935Z"}
1618677824.9987998: {"type":"l2update","product_id":"SKL-USD","changes":[["buy","0.7909","7500.0"]],"time":"2021-04-17T16:43:45.013607Z"}
1618677825.0023391: {"type":"l2update","product_id":"NMR-EUR","changes":[["buy","66.9354","0.000"]],"time":"2021-04-17T16:43:45.017551Z"}
1618677825.0042481: {"type":"l2update","product_id":"DASH-BTC","changes":[["sell","0.00622051","0.00000000"]],"time":"2021-04-17T16:43:45.018149Z"}
1618677825.006444: {"type":"l2update","product_id":"DASH-BTC","changes":[["sell","0.00621371","5.48200000"]],"time":"2021-04-17T16:43:45.021819Z"}
1618677825.006479: {"type":"l2update","product_id":"SKL-BTC","changes":[["buy","0.00001299","7599.6"]],"time":"2021-04-17T16:43:45.021800Z"}
1618677825.006506: {"type":"l2update","product_id":"SKL-USD","changes":[["buy","0.7908","0.0"]],"time":"2021-04-17T16:43:45.022522Z"}
1618677825.0149581: {"type":"l2update","product_id":"CRV-EUR","changes":[["buy","3.2970","120.00"]],"time":"2021-04-17T16:43:45.025816Z"}
1618677825.0149918: {"type":"l2update","product_id":"SKL-GBP","changes":[["buy","0.5744","0.0"]],"time":"2021-04-17T16:43:45.027310Z"}
1618677825.0150201: {"type":"l2update","product_id":"SKL-USD","changes":[["buy","0.7910","450.0"]],"time":"2021-04-17T16:43:45.029068Z"}
1618677825.021996: {"type":"l2update","product_id":"NMR-EUR","changes":[["buy","66.9369","1.303"]],"time":"2021-04-17T16:43:45.033024Z"}
1618677825.022055: {"type":"l2update","product_id":"DASH-BTC","changes":[["buy","0.00619652","0.29500000"]],"time":"2021-04-17T16:43:45.036616Z"}
1618677825.0220768: {"type":"l2update","product_id":"NMR-EUR","changes":[["buy","66.9368","0.000"]],"time":"2021-04-17T16:43:45.039167Z"}
1618677825.029254: {"type":"l2update","product_id":"NMR-EUR","changes":[["buy","66.9380","4.773"]],"time":"2021-04-17T16:43:45.043889Z"}
1618677825.029289: {"type":"l2update","product_id":"SKL-GBP","changes":[["buy","0.5747","1266.9"]],"time":"2021-04-17T16:43:45.043900Z"}
1618677825.03659: {"type":"l2update","product_id":"SKL-GBP","changes":[["sell","0.5784","1258.8"]],"time":"2021-04-17T16:43:45.051628Z"}
1618677825.04352: {"type":"l2update","product_id":"DASH-BTC","changes":[["sell","0.00621225","2.69400000"]],"time":"2021-04-17T16:43:45.055469Z"}
1618677825.068631: {"type":"l2update","product_id":"SKL-USD","changes":[["buy","0.7907","0.0"]],"time":"2021-04-17T16:43:45.078269Z"}
1618677825.0885: {"type":"l2update","product_id":"SKL-USD","changes":[["sell","0.8082","12005.0"]],"time":"2021-04-17T16:43:45.095217Z"}
1618677825.088541: {"type":"l2update","product_id":"SKL-USD","changes":[["sell","0.8074","9.9"]],"time":"2021-04-17T16:43:45.099156Z"}
1618677825.0972888: {"type":"l2update","product_id":"SKL-BTC","changes":[["sell","0.00001307","9015.3"]],"time":"2021-04-17T16:43:45.103704Z"}
1618677825.0973198: {"type":"l2update","product_id":"DASH-BTC","changes":[["sell","0.00621911","14.63200000"]],"time":"2021-04-17T16:43:45.103732Z"}
1618677825.097352: {"type":"l2update","product_id":"SKL-USD","changes":[["sell","0.8082","18005.0"]],"time":"2021-04-17T16:43:45.107533Z"}
1618677825.105224: {"type":"l2update","product_id":"SKL-USD","changes":[["buy","0.7902","0.0"]],"time":"2021-04-17T16:43:45.121272Z"}
1618677825.111745: {"type":"l2update","product_id":"SKL-BTC","changes":[["buy","0.00001290","13813.1"]],"time":"2021-04-17T16:43:45.128059Z"}
1618677825.111775: {"type":"l2update","product_id":"SKL-BTC","changes":[["buy","0.00001290","1433.6"]],"time":"2021-04-17T16:43:45.128059Z"}
1618677825.111792: {"type":"l2update","product_id":"SKL-BTC","changes":[["buy","0.00001286","85454.8"]],"time":"2021-04-17T16:43:45.128059Z"}
1618677825.111806: {"type":"l2update","product_id":"SKL-BTC","changes":[["buy","0.00001286","67641.9"]],"time":"2021-04-17T16:43:45.128059Z"}
1618677825.111819: {"type":"l2update","product_id":"SKL-BTC","changes":[["buy","0.00001275","247.1"]],"time":"2021-04-17T16:43:45.128059Z"}
1618677825.1124742: {"type":"l2update","product_id":"SKL-BTC","changes":[["buy","0.00001273","199.1"]],"time":"2021-04-17T16:43:45.128059Z"}
1618677825.126208: {"type":"l2update","product_id":"SKL-BTC","changes":[["buy","0.00001298","10288.6"]],"time":"2021-04-17T16:43:45.139766Z"}
1618677825.126244: {"type":"l2update","product_id":"SKL-BTC","changes":[["buy","0.00001294","140099.1"]],"time":"2021-04-17T16:43:45.139766Z"}
1618677825.1262631: {"type":"l2update","product_id":"SKL-BTC","changes":[["buy","0.00001292","17778.7"]],"time":"2021-04-17T16:43:45.139766Z"}
1618677825.1262772: {"type":"l2update","product_id":"SKL-BTC","changes":[["buy","0.00001288","5.0"]],"time":"2021-04-17T16:43:45.139766Z"}
1618677825.126297: {"type":"l2update","product_id":"SKL-BTC","changes":[["buy","0.00001286","67646.9"]],"time":"2021-04-17T16:43:45.139766Z"}
1618677825.137843: {"type":"l2update","product_id":"SKL-BTC","changes":[["sell","0.00001307","8121.7"]],"time":"2021-04-17T16:43:45.150383Z"}
1618677825.137872: {"type":"l2update","product_id":"SKL-USD","changes":[["buy","0.7903","2390.6"]],"time":"2021-04-17T16:43:45.151109Z"}
1618677825.13789: {"type":"l2update","product_id":"SKL-BTC","changes":[["buy","0.00001294","142156.8"]],"time":"2021-04-17T16:43:45.151148Z"}
1618677825.1379042: {"type":"l2update","product_id":"SKL-BTC","changes":[["buy","0.00001286","74137.4"]],"time":"2021-04-17T16:43:45.151148Z"}
1618677825.1396291: {"type":"l2update","product_id":"SKL-BTC","changes":[["sell","0.00001309","8311.2"]],"time":"2021-04-17T16:43:45.154860Z"}
1618677825.1396601: {"type":"l2update","product_id":"SKL-BTC","changes":[["buy","0.00001298","0.0"]],"time":"2021-04-17T16:43:45.155958Z"}
1618677825.1414819: {"type":"l2update","product_id":"SKL-BTC","changes":[["buy","0.00001302","6425.8"]],"time":"2021-04-17T16:43:45.158359Z"}
1618677825.1461172: {"type":"l2update","product_id":"SKL-USD","changes":[["sell","0.7923","3647.2"]],"time":"2021-04-17T16:43:45.158734Z"}
1618677825.153625: {"type":"l2update","product_id":"SKL-USD","changes":[["sell","0.7923","2629.7"]],"time":"2021-04-17T16:43:45.167109Z"}
1618677825.153653: {"type":"l2update","product_id":"SKL-BTC","changes":[["buy","0.00001300","8493.2"]],"time":"2021-04-17T16:43:45.168813Z"}
1618677825.1536698: {"type":"l2update","product_id":"SKL-USD","changes":[["sell","0.7920","0.0"]],"time":"2021-04-17T16:43:45.169552Z"}
1618677825.1568441: {"type":"l2update","product_id":"SKL-USD","changes":[["buy","0.7909","7580.2"]],"time":"2021-04-17T16:43:45.172680Z"}
1618677825.156873: {"type":"l2update","product_id":"DASH-BTC","changes":[["sell","0.00621302","0.00000000"]],"time":"2021-04-17T16:43:45.172843Z"}
1618677825.162338: {"type":"l2update","product_id":"SKL-BTC","changes":[["buy","0.00001299","4612.7"]],"time":"2021-04-17T16:43:45.175128Z"}
1618677825.162365: {"type":"l2update","product_id":"SKL-GBP","changes":[["sell","0.5771","1313.2"]],"time":"2021-04-17T16:43:45.176534Z"}
1618677825.16864: {"type":"l2update","product_id":"SKL-GBP","changes":[["buy","0.5747","0.0"]],"time":"2021-04-17T16:43:45.180125Z"}
1618677825.168672: {"type":"l2update","product_id":"DASH-BTC","changes":[["sell","0.00620974","1.61100000"]],"time":"2021-04-17T16:43:45.180447Z"}
1618677825.168693: {"type":"l2update","product_id":"SKL-USD","changes":[["sell","0.7922","1017.5"]],"time":"2021-04-17T16:43:45.180462Z"}
1618677825.1687171: {"type":"l2update","product_id":"SKL-GBP","changes":[["sell","0.5784","0.0"]],"time":"2021-04-17T16:43:45.182597Z"}
1618677825.168739: {"type":"l2update","product_id":"SKL-GBP","changes":[["sell","0.5771","305.0"]],"time":"2021-04-17T16:43:45.185350Z"}
1618677825.173135: {"type":"l2update","product_id":"SKL-USD","changes":[["sell","0.7922","0.0"]],"time":"2021-04-17T16:43:45.185735Z"}
1618677825.1796281: {"type":"l2update","product_id":"YFI-BTC","changes":[["buy","0.82266","0.000000"]],"time":"2021-04-17T16:43:45.191804Z"}
1618677825.1820002: {"type":"l2update","product_id":"SKL-BTC","changes":[["buy","0.00001299","3953.7"]],"time":"2021-04-17T16:43:45.196683Z"}
1618677825.198955: {"type":"l2update","product_id":"SKL-BTC","changes":[["sell","0.00001308","893.6"]],"time":"2021-04-17T16:43:45.200211Z"}
1618677825.20381: {"type":"l2update","product_id":"SKL-BTC","changes":[["buy","0.00001304","1438.7"]],"time":"2021-04-17T16:43:45.214230Z"}
1618677825.221969: {"type":"l2update","product_id":"SKL-BTC","changes":[["buy","0.00001305","1007.2"]],"time":"2021-04-17T16:43:45.235798Z"}
1618677825.2344298: {"type":"l2update","product_id":"SKL-BTC","changes":[["buy","0.00001298","10288.6"]],"time":"2021-04-17T16:43:45.246575Z"}
1618677825.2344651: {"type":"l2update","product_id":"SKL-USD","changes":[["buy","0.7904","0.0"]],"time":"2021-04-17T16:43:45.248396Z"}
1618677825.237746: {"type":"l2update","product_id":"SKL-USD","changes":[["buy","0.7901","0.0"]],"time":"2021-04-17T16:43:45.253416Z"}
1618677825.2377799: {"type":"l2update","product_id":"SKL-USD","changes":[["sell","0.8082","12005.0"]],"time":"2021-04-17T16:43:45.253870Z"}
1618677825.249509: {"type":"l2update","product_id":"SKL-USD","changes":[["sell","0.8086","6005.0"]],"time":"2021-04-17T16:43:45.262791Z"}
1618677825.249538: {"type":"l2update","product_id":"BAND-GBP","changes":[["buy","14.7786","0.00"]],"time":"2021-04-17T16:43:45.264433Z"}
1618677825.249565: {"type":"l2update","product_id":"YFI-BTC","changes":[["buy","0.82267","0.000000"]],"time":"2021-04-17T16:43:45.265991Z"}
1618677825.253941: {"type":"l2update","product_id":"BAND-GBP","changes":[["buy","14.7854","27.48"]],"time":"2021-04-17T16:43:45.270301Z"}
1618677825.256323: {"type":"l2update","product_id":"SKL-USD","changes":[["buy","0.7888","0.0"]],"time":"2021-04-17T16:43:45.272070Z"}
1618677825.258663: {"type":"l2update","product_id":"YFI-BTC","changes":[["buy","0.82312","0.063604"]],"time":"2021-04-17T16:43:45.274207Z"}
1618677825.2784529: {"type":"l2update","product_id":"BAND-BTC","changes":[["buy","0.00033170","389.65"]],"time":"2021-04-17T16:43:45.293788Z"}
1618677825.2784839: {"type":"l2update","product_id":"BAND-BTC","changes":[["buy","0.00033170","338.28"]],"time":"2021-04-17T16:43:45.293788Z"}
1618677825.278504: {"type":"l2update","product_id":"BAND-BTC","changes":[["buy","0.00033144","0.10"]],"time":"2021-04-17T16:43:45.293788Z"}
1618677825.2785192: {"type":"l2update","product_id":"BAND-BTC","changes":[["buy","0.00032796","0.00"]],"time":"2021-04-17T16:43:45.293788Z"}
1618677825.287037: {"type":"l2update","product_id":"BAND-GBP","changes":[["sell","14.8147","0.00"]],"time":"2021-04-17T16:43:45.300498Z"}
1618677825.292442: {"type":"l2update","product_id":"BAND-GBP","changes":[["buy","14.7696","0.00"]],"time":"2021-04-17T16:43:45.301268Z"}
1618677825.29249: {"type":"l2update","product_id":"SKL-USD","changes":[["buy","0.7906","866.3"]],"time":"2021-04-17T16:43:45.301927Z"}
1618677825.306339: {"type":"l2update","product_id":"DASH-BTC","changes":[["sell","0.00621228","0.00000000"]],"time":"2021-04-17T16:43:45.322246Z"}
1618677825.306398: {"type":"l2update","product_id":"SKL-USD","changes":[["buy","0.7880","3067.6"]],"time":"2021-04-17T16:43:45.322931Z"}
1618677825.3064268: {"type":"l2update","product_id":"SKL-USD","changes":[["buy","0.7880","0.0"]],"time":"2021-04-17T16:43:45.322931Z"}
1618677825.306468: {"type":"l2update","product_id":"SKL-USD","changes":[["buy","0.7798","61636.1"]],"time":"2021-04-17T16:43:45.322931Z"}
1618677825.3064818: {"type":"l2update","product_id":"SKL-USD","changes":[["buy","0.7798","0.0"]],"time":"2021-04-17T16:43:45.322931Z"}
1618677825.307313: {"type":"l2update","product_id":"DASH-BTC","changes":[["sell","0.00621911","0.00000000"]],"time":"2021-04-17T16:43:45.325007Z"}
1618677825.311591: {"type":"l2update","product_id":"YFI-BTC","changes":[["buy","0.82556","0.000000"]],"time":"2021-04-17T16:43:45.326534Z"}
1618677825.311627: {"type":"l2update","product_id":"DASH-BTC","changes":[["sell","0.00621371","3.85900000"]],"time":"2021-04-17T16:43:45.327108Z"}
1618677825.311647: {"type":"l2update","product_id":"SKL-BTC","changes":[["sell","0.00001307","4898.0"]],"time":"2021-04-17T16:43:45.328046Z"}
1618677825.3147619: {"type":"l2update","product_id":"DASH-BTC","changes":[["sell","0.00621371","1.62300000"]],"time":"2021-04-17T16:43:45.330049Z"}
1618677825.32012: {"type":"l2update","product_id":"DASH-BTC","changes":[["buy","0.00614337","17.99200000"]],"time":"2021-04-17T16:43:45.335802Z"}
1618677825.326324: {"type":"l2update","product_id":"BAND-GBP","changes":[["buy","14.7886","12.74"]],"time":"2021-04-17T16:43:45.341695Z"}
1618677825.326354: {"type":"l2update","product_id":"SKL-BTC","changes":[["sell","0.00001310","11325.6"]],"time":"2021-04-17T16:43:45.341900Z"}
1618677825.3266208: {"type":"l2update","product_id":"BAND-BTC","changes":[["buy","0.00033395","148.17"]],"time":"2021-04-17T16:43:45.342072Z"}
1618677825.3266518: {"type":"l2update","product_id":"BAND-BTC","changes":[["buy","0.00033345","177.80"]],"time":"2021-04-17T16:43:45.342072Z"}
1618677825.327477: {"type":"l2update","product_id":"BAND-BTC","changes":[["buy","0.00033294","213.37"]],"time":"2021-04-17T16:43:45.342072Z"}
1618677825.327502: {"type":"l2update","product_id":"BAND-BTC","changes":[["buy","0.00033170","385.09"]],"time":"2021-04-17T16:43:45.342072Z"}
1618677825.328854: {"type":"l2update","product_id":"BAND-GBP","changes":[["buy","14.7854","0.00"]],"time":"2021-04-17T16:43:45.345825Z"}
1618677825.340666: {"type":"l2update","product_id":"BAND-GBP","changes":[["sell","14.8179","12.58"]],"time":"2021-04-17T16:43:45.355686Z"}
1618677825.3458781: {"type":"l2update","product_id":"SKL-USD","changes":[["buy","0.7904","1194.2"]],"time":"2021-04-17T16:43:45.357218Z"}
1618677825.3459141: {"type":"l2update","product_id":"BAND-GBP","changes":[["buy","14.7886","0.00"]],"time":"2021-04-17T16:43:45.357524Z"}
1618677825.3459358: {"type":"l2update","product_id":"DASH-BTC","changes":[["sell","0.00620973","0.82500000"]],"time":"2021-04-17T16:43:45.357565Z"}
1618677825.3459551: {"type":"l2update","product_id":"BAND-GBP","changes":[["buy","14.7844","0.00"]],"time":"2021-04-17T16:43:45.357944Z"}
1618677825.3471339: {"type":"l2update","product_id":"SKL-USD","changes":[["buy","0.7882","1900.0"]],"time":"2021-04-17T16:43:45.363219Z"}
1618677825.3471591: {"type":"l2update","product_id":"DASH-BTC","changes":[["buy","0.00619624","0.00000000"]],"time":"2021-04-17T16:43:45.363380Z"}
1618677825.3520021: {"type":"l2update","product_id":"SKL-BTC","changes":[["buy","0.00001305","1117.2"]],"time":"2021-04-17T16:43:45.367464Z"}
1618677825.352036: {"type":"l2update","product_id":"DASH-BTC","changes":[["buy","0.00616178","16.26100000"]],"time":"2021-04-17T16:43:45.367549Z"}
1618677825.3520598: {"type":"l2update","product_id":"DASH-BTC","changes":[["buy","0.00614337","22.16300000"]],"time":"2021-04-17T16:43:45.367549Z"}
1618677825.352076: {"type":"l2update","product_id":"DASH-BTC","changes":[["sell","0.00622722","1.06000000"]],"time":"2021-04-17T16:43:45.367549Z"}
1618677825.353369: {"type":"l2update","product_id":"BAND-GBP","changes":[["sell","14.8072","12.48"]],"time":"2021-04-17T16:43:45.369063Z"}
1618677825.357585: {"type":"l2update","product_id":"DASH-BTC","changes":[["sell","0.00784571","0.00000000"]],"time":"2021-04-17T16:43:45.370549Z"}
1618677825.357619: {"type":"l2update","product_id":"DASH-BTC","changes":[["buy","0.00619652","0.00000000"]],"time":"2021-04-17T16:43:45.370724Z"}
1618677825.362823: {"type":"l2update","product_id":"SKL-USD","changes":[["sell","0.7942","29765.1"]],"time":"2021-04-17T16:43:45.378023Z"}
1618677825.3628511: {"type":"l2update","product_id":"SKL-USD","changes":[["buy","0.7901","867.5"]],"time":"2021-04-17T16:43:45.378132Z"}
1618677825.364979: {"type":"l2update","product_id":"DASH-BTC","changes":[["sell","0.00620370","1.83700000"]],"time":"2021-04-17T16:43:45.381645Z"}
1618677825.365012: {"type":"l2update","product_id":"BAND-GBP","changes":[["buy","14.7709","13.20"]],"time":"2021-04-17T16:43:45.381782Z"}
1618677825.367158: {"type":"l2update","product_id":"DASH-BTC","changes":[["sell","0.00864891","4.80000000"]],"time":"2021-04-17T16:43:45.381953Z"}
1618677825.3703191: {"type":"l2update","product_id":"BAND-GBP","changes":[["buy","14.7785","0.00"]],"time":"2021-04-17T16:43:45.387261Z"}
1618677825.373492: {"type":"l2update","product_id":"BAND-GBP","changes":[["sell","14.8224","0.00"]],"time":"2021-04-17T16:43:45.387861Z"}
1618677825.377409: {"type":"l2update","product_id":"BAND-GBP","changes":[["buy","14.7789","27.50"]],"time":"2021-04-17T16:43:45.389738Z"}
1618677825.37744: {"type":"l2update","product_id":"SKL-USD","changes":[["buy","0.7867","25513.9"]],"time":"2021-04-17T16:43:45.389764Z"}
1618677825.377461: {"type":"l2update","product_id":"DASH-BTC","changes":[["sell","0.00621224","1.62300000"]],"time":"2021-04-17T16:43:45.389823Z"}
1618677825.377478: {"type":"l2update","product_id":"BAND-GBP","changes":[["sell","14.8071","27.80"]],"time":"2021-04-17T16:43:45.390310Z"}
1618677825.3791811: {"type":"l2update","product_id":"BAND-GBP","changes":[["sell","14.8086","0.00"]],"time":"2021-04-17T16:43:45.393747Z"}
1618677825.3810759: {"type":"l2update","product_id":"DASH-BTC","changes":[["sell","0.00621592","0.90000000"]],"time":"2021-04-17T16:43:45.397395Z"}
1618677825.385329: {"type":"l2update","product_id":"DASH-BTC","changes":[["sell","0.00621224","3.85900000"]],"time":"2021-04-17T16:43:45.401683Z"}
1618677825.390652: {"type":"l2update","product_id":"YFI-BTC","changes":[["buy","0.82255","0.041685"]],"time":"2021-04-17T16:43:45.405171Z"}
1618677825.394953: {"type":"l2update","product_id":"DASH-BTC","changes":[["sell","0.00621655","14.63200000"]],"time":"2021-04-17T16:43:45.408403Z"}
1618677825.3981981: {"type":"l2update","product_id":"DASH-BTC","changes":[["buy","0.00619651","2.95500000"]],"time":"2021-04-17T16:43:45.412928Z"}
1618677825.403517: {"type":"l2update","product_id":"DASH-BTC","changes":[["sell","0.00620972","2.65700000"]],"time":"2021-04-17T16:43:45.416313Z"}
1618677825.40883: {"type":"l2update","product_id":"BAND-BTC","changes":[["buy","0.00033395","0.00"]],"time":"2021-04-17T16:43:45.424131Z"}
1618677825.408863: {"type":"l2update","product_id":"DASH-BTC","changes":[["buy","0.00619651","1.41400000"]],"time":"2021-04-17T16:43:45.425985Z"}
1618677825.418015: {"type":"l2update","product_id":"SKL-USD","changes":[["sell","0.8081","6005.0"]],"time":"2021-04-17T16:43:45.431128Z"}
1618677825.432908: {"type":"l2update","product_id":"DASH-BTC","changes":[["buy","0.00619435","32.84700000"]],"time":"2021-04-17T16:43:45.449145Z"}
1618677825.432944: {"type":"l2update","product_id":"DASH-BTC","changes":[["buy","0.00619283","1.54200000"]],"time":"2021-04-17T16:43:45.449321Z"}
1618677825.4573991: {"type":"l2update","product_id":"DASH-BTC","changes":[["buy","0.00619649","0.00000000"]],"time":"2021-04-17T16:43:45.470793Z"}
1618677825.478318: {"type":"l2update","product_id":"DASH-BTC","changes":[["sell","0.00620974","0.00000000"]],"time":"2021-04-17T16:43:45.480970Z"}
1618677825.4783528: {"type":"l2update","product_id":"SKL-USD","changes":[["buy","0.7886","3713.6"]],"time":"2021-04-17T16:43:45.482916Z"}
1618677825.478376: {"type":"l2update","product_id":"SKL-USD","changes":[["buy","0.7807","73644.2"]],"time":"2021-04-17T16:43:45.482916Z"}
1618677825.4783921: {"type":"l2update","product_id":"SKL-USD","changes":[["sell","0.7925","3113.2"]],"time":"2021-04-17T16:43:45.482916Z"}
1618677825.47841: {"type":"l2update","product_id":"SKL-USD","changes":[["buy","0.7909","8569.9"]],"time":"2021-04-17T16:43:45.486748Z"}
1618677825.478424: {"type":"l2update","product_id":"SKL-BTC","changes":[["buy","0.00001300","9152.3"]],"time":"2021-04-17T16:43:45.486736Z"}
1618677825.4784372: {"type":"l2update","product_id":"BAND-BTC","changes":[["sell","0.00033516","42.38"]],"time":"2021-04-17T16:43:45.486982Z"}
1618677825.4784489: {"type":"l2update","product_id":"SKL-BTC","changes":[["buy","0.00001304","1003.7"]],"time":"2021-04-17T16:43:45.490289Z"}
1618677825.478461: {"type":"l2update","product_id":"SKL-BTC","changes":[["buy","0.00001297","2634.3"]],"time":"2021-04-17T16:43:45.490289Z"}
1618677825.478473: {"type":"l2update","product_id":"SKL-BTC","changes":[["buy","0.00001302","6085.8"]],"time":"2021-04-17T16:43:45.490289Z"}
1618677825.478485: {"type":"l2update","product_id":"SKL-BTC","changes":[["buy","0.00001301","20202.1"]],"time":"2021-04-17T16:43:45.493780Z"}
1618677825.478496: {"type":"l2update","product_id":"SKL-BTC","changes":[["sell","0.00001308","4346.4"]],"time":"2021-04-17T16:43:45.493780Z"}
1618677825.478508: {"type":"l2update","product_id":"SKL-USD","changes":[["buy","0.7867","0.0"]],"time":"2021-04-17T16:43:45.493831Z"}
1618677825.481575: {"type":"l2update","product_id":"SKL-BTC","changes":[["buy","0.00001304","1993.4"]],"time":"2021-04-17T16:43:45.497304Z"}
1618677825.481601: {"type":"l2update","product_id":"SKL-BTC","changes":[["buy","0.00001295","690.0"]],"time":"2021-04-17T16:43:45.497547Z"}
1618677825.481619: {"type":"l2update","product_id":"SKL-BTC","changes":[["buy","0.00001296","380.0"]],"time":"2021-04-17T16:43:45.497547Z"}
1618677825.482838: {"type":"l2update","product_id":"SKL-BTC","changes":[["sell","0.00001309","7721.6"]],"time":"2021-04-17T16:43:45.500924Z"}
1618677825.490168: {"type":"l2update","product_id":"DASH-BTC","changes":[["sell","0.00621693","0.00000000"]],"time":"2021-04-17T16:43:45.503229Z"}
1618677825.4902039: {"type":"l2update","product_id":"SKL-BTC","changes":[["buy","0.00001300","8162.6"]],"time":"2021-04-17T16:43:45.504593Z"}
1618677825.490226: {"type":"l2update","product_id":"BAND-BTC","changes":[["sell","0.00033640","0.00"]],"time":"2021-04-17T16:43:45.506455Z"}
1618677825.497607: {"type":"l2update","product_id":"SKL-USD","changes":[["buy","0.7868","25513.9"]],"time":"2021-04-17T16:43:45.512392Z"}
1618677825.4976408: {"type":"l2update","product_id":"DASH-BTC","changes":[["buy","0.00619652","2.56800000"]],"time":"2021-04-17T16:43:45.512476Z"}
1618677825.497662: {"type":"l2update","product_id":"DASH-BTC","changes":[["buy","0.00619650","13.65300000"]],"time":"2021-04-17T16:43:45.512983Z"}
1618677825.50412: {"type":"l2update","product_id":"DASH-BTC","changes":[["sell","0.00621655","0.00000000"]],"time":"2021-04-17T16:43:45.519587Z"}
1618677825.5041869: {"type":"l2update","product_id":"DASH-BTC","changes":[["buy","0.00619650","0.00000000"]],"time":"2021-04-17T16:43:45.519618Z"}
1618677825.504229: {"type":"l2update","product_id":"BAND-BTC","changes":[["sell","0.00033672","127.50"]],"time":"2021-04-17T16:43:45.519893Z"}
1618677825.514316: {"type":"l2update","product_id":"CRV-EUR","changes":[["buy","3.2806","0.00"]],"time":"2021-04-17T16:43:45.531541Z"}
1618677825.520545: {"type":"l2update","product_id":"BAND-BTC","changes":[["buy","0.00033395","148.17"]],"time":"2021-04-17T16:43:45.535583Z"}
1618677825.525884: {"type":"l2update","product_id":"CRV-EUR","changes":[["buy","3.2830","256.63"]],"time":"2021-04-17T16:43:45.539406Z"}
1618677825.560815: {"type":"l2update","product_id":"SKL-USD","changes":[["sell","0.8086","5.0"]],"time":"2021-04-17T16:43:45.567222Z"}
1618677825.591467: {"type":"l2update","product_id":"BAND-BTC","changes":[["sell","0.00033674","0.00"]],"time":"2021-04-17T16:43:45.603868Z"}
1618677825.591577: {"type":"l2update","product_id":"DASH-BTC","changes":[["sell","0.00621769","14.63200000"]],"time":"2021-04-17T16:43:45.605860Z"}
1618677825.595814: {"type":"l2update","product_id":"BAND-BTC","changes":[["sell","0.00033810","10.60"]],"time":"2021-04-17T16:43:45.609364Z"}
1618677825.601611: {"type":"l2update","product_id":"BAND-GBP","changes":[["buy","14.6487","2.30"]],"time":"2021-04-17T16:43:45.612887Z"}
1618677825.601641: {"type":"l2update","product_id":"BAND-GBP","changes":[["buy","14.6486","0.00"]],"time":"2021-04-17T16:43:45.612887Z"}
1618677825.601665: {"type":"l2update","product_id":"BAND-GBP","changes":[["buy","14.6487","0.70"]],"time":"2021-04-17T16:43:45.612887Z"}
1618677825.601681: {"type":"l2update","product_id":"BAND-GBP","changes":[["buy","14.6485","0.00"]],"time":"2021-04-17T16:43:45.612887Z"}
1618677825.601697: {"type":"l2update","product_id":"BAND-GBP","changes":[["buy","14.6484","0.00"]],"time":"2021-04-17T16:43:45.612887Z"}
1618677825.6091788: {"type":"l2update","product_id":"CRV-EUR","changes":[["buy","3.2963","0.00"]],"time":"2021-04-17T16:43:45.620035Z"}
1618677825.609216: {"type":"l2update","product_id":"BAND-GBP","changes":[["buy","14.6489","30.60"]],"time":"2021-04-17T16:43:45.620275Z"}
1618677825.609235: {"type":"l2update","product_id":"BAND-GBP","changes":[["buy","14.6490","12.50"]],"time":"2021-04-17T16:43:45.620275Z"}
1618677825.6092532: {"type":"l2update","product_id":"DASH-BTC","changes":[["buy","0.00619651","0.29500000"]],"time":"2021-04-17T16:43:45.624718Z"}
1618677825.618551: {"type":"l2update","product_id":"SKL-BTC","changes":[["sell","0.00001310","10601.7"]],"time":"2021-04-17T16:43:45.628608Z"}
1618677825.6282501: {"type":"l2update","product_id":"CRV-EUR","changes":[["buy","3.2968","140.93"]],"time":"2021-04-17T16:43:45.644395Z"}
1618677825.628285: {"type":"l2update","product_id":"DASH-BTC","changes":[["buy","0.00619283","2.66100000"]],"time":"2021-04-17T16:43:45.644512Z"}
1618677825.6427531: {"type":"l2update","product_id":"DASH-BTC","changes":[["sell","0.00620370","0.00000000"]],"time":"2021-04-17T16:43:45.659076Z"}
1618677825.661946: {"type":"l2update","product_id":"DASH-BTC","changes":[["sell","0.00620973","0.00000000"]],"time":"2021-04-17T16:43:45.679083Z"}
1618677825.679352: {"type":"l2update","product_id":"SKL-BTC","changes":[["buy","0.00001301","16498.2"]],"time":"2021-04-17T16:43:45.692462Z"}
1618677825.6826088: {"type":"l2update","product_id":"DASH-BTC","changes":[["buy","0.00614335","0.00000000"]],"time":"2021-04-17T16:43:45.698751Z"}
1618677825.682645: {"type":"l2update","product_id":"DASH-BTC","changes":[["buy","0.00614336","0.45000000"]],"time":"2021-04-17T16:43:45.698751Z"}
1618677825.686891: {"type":"l2update","product_id":"DASH-BTC","changes":[["sell","0.00620369","0.82500000"]],"time":"2021-04-17T16:43:45.699951Z"}
1618677825.693318: {"type":"l2update","product_id":"DASH-BTC","changes":[["buy","0.00614339","3.01000000"]],"time":"2021-04-17T16:43:45.707876Z"}
1618677825.693346: {"type":"l2update","product_id":"DASH-BTC","changes":[["buy","0.00614340","2.14000000"]],"time":"2021-04-17T16:43:45.707876Z"}
1618677825.699879: {"type":"l2update","product_id":"BAND-GBP","changes":[["buy","14.6483","0.00"]],"time":"2021-04-17T16:43:45.715729Z"}
1618677825.711125: {"type":"l2update","product_id":"BAND-GBP","changes":[["buy","14.6491","6.70"]],"time":"2021-04-17T16:43:45.726686Z"}
1618677825.7111602: {"type":"l2update","product_id":"BAND-GBP","changes":[["buy","14.6490","12.70"]],"time":"2021-04-17T16:43:45.726686Z"}
1618677825.716853: {"type":"l2update","product_id":"DASH-BTC","changes":[["buy","0.00619651","0.00000000"]],"time":"2021-04-17T16:43:45.733199Z"}
1618677825.735691: {"type":"l2update","product_id":"DASH-BTC","changes":[["buy","0.00619435","0.00000000"]],"time":"2021-04-17T16:43:45.748935Z"}
1618677825.742789: {"type":"l2update","product_id":"DASH-BTC","changes":[["buy","0.00619461","0.29500000"]],"time":"2021-04-17T16:43:45.753350Z"}
1618677825.745755: {"type":"l2update","product_id":"DASH-BTC","changes":[["buy","0.00619283","1.11900000"]],"time":"2021-04-17T16:43:45.762614Z"}
1618677825.767211: {"type":"l2update","product_id":"DASH-BTC","changes":[["buy","0.00619436","1.54100000"]],"time":"2021-04-17T16:43:45.783112Z"}
1618677825.783135: {"type":"l2update","product_id":"BAND-BTC","changes":[["sell","0.00033542","0.00"]],"time":"2021-04-17T16:43:45.798851Z"}
1618677825.818382: {"type":"l2update","product_id":"DASH-BTC","changes":[["buy","0.00619219","32.84700000"]],"time":"2021-04-17T16:43:45.833975Z"}
1618677825.835755: {"type":"l2update","product_id":"YFI-BTC","changes":[["buy","0.82583","0.000000"]],"time":"2021-04-17T16:43:45.846122Z"}
1618677825.839092: {"type":"l2update","product_id":"BAND-BTC","changes":[["sell","0.00033536","36.71"]],"time":"2021-04-17T16:43:45.846388Z"}
1618677825.845525: {"type":"l2update","product_id":"SKL-BTC","changes":[["buy","0.00001300","11445.7"]],"time":"2021-04-17T16:43:45.851099Z"}
1618677825.845581: {"type":"l2update","product_id":"DASH-BTC","changes":[["buy","0.00619646","0.00000000"]],"time":"2021-04-17T16:43:45.856043Z"}
1618677825.8456268: {"type":"l2update","product_id":"DASH-BTC","changes":[["sell","0.00621210","1.20000000"]],"time":"2021-04-17T16:43:45.858384Z"}
1618677825.845663: {"type":"l2update","product_id":"SKL-USD","changes":[["buy","0.7905","0.0"]],"time":"2021-04-17T16:43:45.859177Z"}
1618677825.851499: {"type":"l2update","product_id":"DASH-BTC","changes":[["sell","0.00621603","0.00000000"]],"time":"2021-04-17T16:43:45.862653Z"}
1618677825.864198: {"type":"l2update","product_id":"DASH-BTC","changes":[["buy","0.00619284","10.88900000"]],"time":"2021-04-17T16:43:45.877293Z"}
1618677825.869246: {"type":"l2update","product_id":"DASH-BTC","changes":[["buy","0.00619645","0.00000000"]],"time":"2021-04-17T16:43:45.884891Z"}
1618677825.8838952: {"type":"l2update","product_id":"YFI-BTC","changes":[["buy","0.82589","0.017055"]],"time":"2021-04-17T16:43:45.893718Z"}
1618677825.883968: {"type":"l2update","product_id":"SKL-USD","changes":[["buy","0.7906","0.0"]],"time":"2021-04-17T16:43:45.894013Z"}
1618677825.8840058: {"type":"l2update","product_id":"SKL-USD","changes":[["buy","0.7905","2629.6"]],"time":"2021-04-17T16:43:45.896507Z"}
1618677825.884813: {"type":"l2update","product_id":"DASH-BTC","changes":[["sell","0.00621224","2.23600000"]],"time":"2021-04-17T16:43:45.898821Z"}
1618677825.884876: {"type":"l2update","product_id":"DASH-BTC","changes":[["sell","0.00621769","0.00000000"]],"time":"2021-04-17T16:43:45.899257Z"}
1618677825.8912861: {"type":"l2update","product_id":"DASH-BTC","changes":[["sell","0.00621224","0.00000000"]],"time":"2021-04-17T16:43:45.901203Z"}
1618677825.8913379: {"type":"l2update","product_id":"CRV-EUR","changes":[["buy","3.2933","254.63"]],"time":"2021-04-17T16:43:45.904312Z"}
1618677825.8990972: {"type":"l2update","product_id":"DASH-BTC","changes":[["buy","0.00619219","0.00000000"]],"time":"2021-04-17T16:43:45.913419Z"}
1618677825.9042811: {"type":"l2update","product_id":"SKL-USD","changes":[["buy","0.7904","2060.7"]],"time":"2021-04-17T16:43:45.919414Z"}
1618677825.904326: {"type":"l2update","product_id":"DASH-BTC","changes":[["sell","0.00621209","1.62300000"]],"time":"2021-04-17T16:43:45.919505Z"}
1618677825.9185762: {"type":"l2update","product_id":"DASH-BTC","changes":[["sell","0.00621209","3.85900000"]],"time":"2021-04-17T16:43:45.934441Z"}
1618677825.925226: {"type":"l2update","product_id":"SKL-USD","changes":[["buy","0.7909","7580.2"]],"time":"2021-04-17T16:43:45.938279Z"}
1618677825.937999: {"type":"l2update","product_id":"SKL-USD","changes":[["buy","0.7916","989.7"]],"time":"2021-04-17T16:43:45.949399Z"}
1618677825.9392982: {"type":"l2update","product_id":"SKL-USD","changes":[["buy","0.7868","0.0"]],"time":"2021-04-17T16:43:45.956018Z"}
1618677825.9435148: {"type":"l2update","product_id":"DASH-BTC","changes":[["sell","0.00621226","0.00000000"]],"time":"2021-04-17T16:43:45.959610Z"}
1618677825.943569: {"type":"l2update","product_id":"SKL-BTC","changes":[["sell","0.00001310","11325.6"]],"time":"2021-04-17T16:43:45.960151Z"}
1618677825.95434: {"type":"l2update","product_id":"DASH-BTC","changes":[["sell","0.00621372","0.00000000"]],"time":"2021-04-17T16:43:45.965087Z"}
1618677825.954394: {"type":"l2update","product_id":"YFI-BTC","changes":[["buy","0.82573","0.030096"]],"time":"2021-04-17T16:43:45.967569Z"}
1618677825.960829: {"type":"l2update","product_id":"SKL-USD","changes":[["buy","0.7869","25513.9"]],"time":"2021-04-17T16:43:45.975190Z"}
1618677825.96088: {"type":"l2update","product_id":"DASH-BTC","changes":[["sell","0.00620688","2.33200000"]],"time":"2021-04-17T16:43:45.975156Z"}
1618677825.967201: {"type":"l2update","product_id":"DASH-BTC","changes":[["sell","0.00621587","14.63200000"]],"time":"2021-04-17T16:43:45.982288Z"}
1618677825.984929: {"type":"l2update","product_id":"DASH-BTC","changes":[["sell","0.00621371","0.00000000"]],"time":"2021-04-17T16:43:45.994957Z"}
1618677825.9859872: {"type":"l2update","product_id":"DASH-BTC","changes":[["buy","0.00618933","32.84700000"]],"time":"2021-04-17T16:43:46.000532Z"}
1618677825.989541: {"type":"l2update","product_id":"SKL-BTC","changes":[["buy","0.00001300","8162.6"]],"time":"2021-04-17T16:43:46.004748Z"}
1618677825.993836: {"type":"l2update","product_id":"DASH-BTC","changes":[["sell","0.00620368","2.57000000"]],"time":"2021-04-17T16:43:46.008296Z"}
1618677825.996963: {"type":"l2update","product_id":"DASH-BTC","changes":[["buy","0.00619644","0.00000000"]],"time":"2021-04-17T16:43:46.013942Z"}
1618677825.999028: {"type":"l2update","product_id":"DASH-BTC","changes":[["sell","0.00622496","1.62300000"]],"time":"2021-04-17T16:43:46.015645Z"}
1618677826.009012: {"type":"l2update","product_id":"SKL-USD","changes":[["buy","0.7916","1374.7"]],"time":"2021-04-17T16:43:46.022911Z"}
1618677826.0090702: {"type":"l2update","product_id":"DASH-BTC","changes":[["sell","0.00620369","0.00000000"]],"time":"2021-04-17T16:43:46.025513Z"}
1618677826.022793: {"type":"l2update","product_id":"BAND-BTC","changes":[["buy","0.00033449","192.32"]],"time":"2021-04-17T16:43:46.037895Z"}
1618677826.022838: {"type":"l2update","product_id":"SKL-USD","changes":[["sell","0.8081","5.0"]],"time":"2021-04-17T16:43:46.038050Z"}
1618677826.0264719: {"type":"l2update","product_id":"SKL-GBP","changes":[["buy","0.5738","1268.9"]],"time":"2021-04-17T16:43:46.042018Z"}
1618677826.030122: {"type":"l2update","product_id":"DASH-BTC","changes":[["sell","0.00620687","0.82500000"]],"time":"2021-04-17T16:43:46.045623Z"}
1618677826.0310771: {"type":"l2update","product_id":"SKL-USD","changes":[["sell","0.8082","18005.0"]],"time":"2021-04-17T16:43:46.045741Z"}
1618677826.032203: {"type":"l2update","product_id":"SKL-GBP","changes":[["sell","0.5784","1258.8"]],"time":"2021-04-17T16:43:46.049225Z"}
1618677826.044745: {"type":"l2update","product_id":"DASH-BTC","changes":[["sell","0.00621587","0.00000000"]],"time":"2021-04-17T16:43:46.061830Z"}
1618677826.0598452: {"type":"l2update","product_id":"SKL-USD","changes":[["buy","0.7903","1044.7"]],"time":"2021-04-17T16:43:46.074431Z"}
1618677826.068269: {"type":"l2update","product_id":"DASH-BTC","changes":[["buy","0.00619461","0.00000000"]],"time":"2021-04-17T16:43:46.082449Z"}
1618677826.068331: {"type":"l2update","product_id":"SKL-USD","changes":[["buy","0.7869","0.0"]],"time":"2021-04-17T16:43:46.084259Z"}
1618677826.078221: {"type":"l2update","product_id":"SKL-USD","changes":[["buy","0.7904","3406.4"]],"time":"2021-04-17T16:43:46.094547Z"}
1618677826.084047: {"type":"l2update","product_id":"SKL-USD","changes":[["buy","0.7916","385.0"]],"time":"2021-04-17T16:43:46.100130Z"}
1618677826.086865: {"type":"l2update","product_id":"DASH-BTC","changes":[["buy","0.00619285","0.29500000"]],"time":"2021-04-17T16:43:46.102070Z"}
1618677826.08692: {"type":"l2update","product_id":"SKL-USD","changes":[["buy","0.7866","28173.7"]],"time":"2021-04-17T16:43:46.101977Z"}
1618677826.0952902: {"type":"l2update","product_id":"DASH-BTC","changes":[["buy","0.00619436","0.00000000"]],"time":"2021-04-17T16:43:46.112015Z"}
1618677826.1007302: {"type":"l2update","product_id":"SKL-USD","changes":[["buy","0.7904","2212.2"]],"time":"2021-04-17T16:43:46.116492Z"}
1618677826.10609: {"type":"l2update","product_id":"SKL-USD","changes":[["sell","0.9990","11275.5"]],"time":"2021-04-17T16:43:46.121347Z"}
1618677826.1125052: {"type":"l2update","product_id":"YFI-BTC","changes":[["buy","0.82529","0.030000"]],"time":"2021-04-17T16:43:46.128688Z"}
1618677826.115617: {"type":"l2update","product_id":"DASH-BTC","changes":[["buy","0.00619285","1.83700000"]],"time":"2021-04-17T16:43:46.131465Z"}
1618677826.121202: {"type":"l2update","product_id":"SKL-USD","changes":[["buy","0.7904","866.5"]],"time":"2021-04-17T16:43:46.135645Z"}
1618677826.1212459: {"type":"l2update","product_id":"CRV-EUR","changes":[["buy","3.2957","0.00"]],"time":"2021-04-17T16:43:46.135827Z"}
1618677826.121282: {"type":"l2update","product_id":"CRV-EUR","changes":[["buy","3.2878","0.00"]],"time":"2021-04-17T16:43:46.135841Z"}
1618677826.123101: {"type":"l2update","product_id":"SKL-USD","changes":[["buy","0.7905","3823.6"]],"time":"2021-04-17T16:43:46.138904Z"}
1618677826.1302102: {"type":"l2update","product_id":"CRV-EUR","changes":[["sell","3.3077","140.93"]],"time":"2021-04-17T16:43:46.142850Z"}
1618677826.134389: {"type":"l2update","product_id":"DASH-BTC","changes":[["sell","0.00621271","14.63200000"]],"time":"2021-04-17T16:43:46.146156Z"}
1618677826.138064: {"type":"l2update","product_id":"CRV-EUR","changes":[["sell","3.3038","0.00"]],"time":"2021-04-17T16:43:46.152765Z"}
1618677826.14342: {"type":"l2update","product_id":"CRV-EUR","changes":[["buy","3.2917","140.93"]],"time":"2021-04-17T16:43:46.157641Z"}
1618677826.143473: {"type":"l2update","product_id":"SKL-USD","changes":[["buy","0.7903","2390.4"]],"time":"2021-04-17T16:43:46.157730Z"}
1618677826.148638: {"type":"l2update","product_id":"CRV-EUR","changes":[["buy","3.2895","0.00"]],"time":"2021-04-17T16:43:46.160948Z"}
1618677826.148705: {"type":"l2update","product_id":"CRV-EUR","changes":[["buy","3.2970","260.93"]],"time":"2021-04-17T16:43:46.161319Z"}
1618677826.1520572: {"type":"l2update","product_id":"YFI-BTC","changes":[["sell","0.83178","0.000000"]],"time":"2021-04-17T16:43:46.164595Z"}
1618677826.152128: {"type":"l2update","product_id":"YFI-BTC","changes":[["sell","0.83175","0.000000"]],"time":"2021-04-17T16:43:46.164595Z"}
1618677826.1521668: {"type":"l2update","product_id":"YFI-BTC","changes":[["sell","0.83176","0.000000"]],"time":"2021-04-17T16:43:46.164595Z"}
1618677826.1521971: {"type":"l2update","product_id":"SKL-BTC","changes":[["buy","0.00001301","19810.4"]],"time":"2021-04-17T16:43:46.164901Z"}
1618677826.1685572: {"type":"l2update","product_id":"SKL-GBP","changes":[["buy","0.5720","500.0"]],"time":"2021-04-17T16:43:46.176112Z"}
1618677826.16862: {"type":"l2update","product_id":"YFI-BTC","changes":[["sell","0.83215","0.013620"]],"time":"2021-04-17T16:43:46.175769Z"}
1618677826.168664: {"type":"l2update","product_id":"YFI-BTC","changes":[["sell","0.83216","0.023750"]],"time":"2021-04-17T16:43:46.175769Z"}
1618677826.168691: {"type":"l2update","product_id":"YFI-BTC","changes":[["sell","0.83217","0.029000"]],"time":"2021-04-17T16:43:46.175769Z"}
1618677826.170072: {"type":"l2update","product_id":"SKL-USD","changes":[["buy","0.7903","1044.7"]],"time":"2021-04-17T16:43:46.182420Z"}
1618677826.1701329: {"type":"l2update","product_id":"CRV-EUR","changes":[["sell","3.3026","140.93"]],"time":"2021-04-17T16:43:46.182833Z"}
1618677826.170177: {"type":"l2update","product_id":"SKL-GBP","changes":[["buy","0.5738","1543.9"]],"time":"2021-04-17T16:43:46.183093Z"}
1618677826.1702049: {"type":"l2update","product_id":"SKL-GBP","changes":[["buy","0.5689","615.0"]],"time":"2021-04-17T16:43:46.183093Z"}
1618677826.178289: {"type":"l2update","product_id":"DASH-BTC","changes":[["sell","0.00622498","0.00000000"]],"time":"2021-04-17T16:43:46.192253Z"}
1618677826.1783628: {"type":"l2update","product_id":"CRV-EUR","changes":[["sell","3.3112","0.00"]],"time":"2021-04-17T16:43:46.193113Z"}
1618677826.193043: {"type":"l2update","product_id":"SKL-USD","changes":[["buy","0.7904","2212.2"]],"time":"2021-04-17T16:43:46.202509Z"}
1618677826.1973288: {"type":"l2update","product_id":"DASH-BTC","changes":[["sell","0.00621863","1.88000000"]],"time":"2021-04-17T16:43:46.209925Z"}
1618677826.197394: {"type":"l2update","product_id":"CRV-EUR","changes":[["sell","3.3117","0.00"]],"time":"2021-04-17T16:43:46.210797Z"}
1618677826.2026: {"type":"l2update","product_id":"BAND-BTC","changes":[["sell","0.00033673","9.40"]],"time":"2021-04-17T16:43:46.215665Z"}
1618677826.204662: {"type":"l2update","product_id":"CRV-EUR","changes":[["sell","3.3076","424.00"]],"time":"2021-04-17T16:43:46.221182Z"}
1618677826.211006: {"type":"l2update","product_id":"CRV-EUR","changes":[["buy","3.2878","400.00"]],"time":"2021-04-17T16:43:46.224833Z"}
1618677826.2110589: {"type":"l2update","product_id":"DASH-BTC","changes":[["sell","0.00621271","0.00000000"]],"time":"2021-04-17T16:43:46.225174Z"}
1618677826.213154: {"type":"l2update","product_id":"BAND-BTC","changes":[["buy","0.00033170","448.08"]],"time":"2021-04-17T16:43:46.228336Z"}
1618677826.213194: {"type":"l2update","product_id":"BAND-BTC","changes":[["sell","0.00033649","0.94"]],"time":"2021-04-17T16:43:46.228336Z"}
1618677826.2326531: {"type":"l2update","product_id":"SKL-USD","changes":[["buy","0.7904","1345.7"]],"time":"2021-04-17T16:43:46.247498Z"}
1618677826.233407: {"type":"l2update","product_id":"SKL-USD","changes":[["buy","0.7904","0.0"]],"time":"2021-04-17T16:43:46.250161Z"}
1618677826.235792: {"type":"l2update","product_id":"SKL-BTC","changes":[["sell","0.00001310","10601.7"]],"time":"2021-04-17T16:43:46.250376Z"}
1618677826.249542: {"type":"l2update","product_id":"SKL-BTC","changes":[["buy","0.00001302","6075.8"]],"time":"2021-04-17T16:43:46.263562Z"}
1618677826.249599: {"type":"l2update","product_id":"BAND-GBP","changes":[["buy","14.7789","0.00"]],"time":"2021-04-17T16:43:46.264927Z"}
1618677826.249645: {"type":"l2update","product_id":"SKL-USD","changes":[["buy","0.7903","2390.4"]],"time":"2021-04-17T16:43:46.266101Z"}
1618677826.253723: {"type":"l2update","product_id":"SKL-BTC","changes":[["buy","0.00001295","700.0"]],"time":"2021-04-17T16:43:46.269594Z"}
1618677826.256974: {"type":"l2update","product_id":"SKL-USD","changes":[["buy","0.7906","866.3"]],"time":"2021-04-17T16:43:46.269884Z"}
1618677826.258042: {"type":"l2update","product_id":"CRV-EUR","changes":[["buy","3.2975","0.00"]],"time":"2021-04-17T16:43:46.273861Z"}
1618677826.259542: {"type":"l2update","product_id":"DASH-BTC","changes":[["buy","0.00619283","0.00000000"]],"time":"2021-04-17T16:43:46.274793Z"}
1618677826.270025: {"type":"l2update","product_id":"DASH-BTC","changes":[["sell","0.00620688","0.00000000"]],"time":"2021-04-17T16:43:46.285214Z"}
1618677826.277545: {"type":"l2update","product_id":"DASH-BTC","changes":[["buy","0.00619460","0.00000000"]],"time":"2021-04-17T16:43:46.293466Z"}
1618677826.282612: {"type":"l2update","product_id":"CRV-EUR","changes":[["buy","3.2970","140.93"]],"time":"2021-04-17T16:43:46.294417Z"}
1618677826.282657: {"type":"l2update","product_id":"DASH-BTC","changes":[["buy","0.00619214","1.11900000"]],"time":"2021-04-17T16:43:46.295667Z"}
1618677826.282691: {"type":"l2update","product_id":"YFI-BTC","changes":[["buy","0.82573","0.000000"]],"time":"2021-04-17T16:43:46.296131Z"}
1618677826.285621: {"type":"l2update","product_id":"SKL-GBP","changes":[["buy","0.5720","0.0"]],"time":"2021-04-17T16:43:46.299577Z"}
1618677826.285686: {"type":"l2update","product_id":"CRV-EUR","changes":[["buy","3.2830","0.00"]],"time":"2021-04-17T16:43:46.303038Z"}
1618677826.295153: {"type":"l2update","product_id":"DASH-BTC","changes":[["sell","0.00621070","14.63200000"]],"time":"2021-04-17T16:43:46.310851Z"}
1618677826.299683: {"type":"l2update","product_id":"BAND-BTC","changes":[["buy","0.00033395","0.00"]],"time":"2021-04-17T16:43:46.316149Z"}
1618677826.299736: {"type":"l2update","product_id":"BAND-BTC","changes":[["buy","0.00033345","148.15"]],"time":"2021-04-17T16:43:46.316149Z"}
1618677826.299765: {"type":"l2update","product_id":"BAND-BTC","changes":[["buy","0.00033294","177.78"]],"time":"2021-04-17T16:43:46.316149Z"}
1618677826.3191879: {"type":"l2update","product_id":"BAND-BTC","changes":[["buy","0.00033144","307.25"]],"time":"2021-04-17T16:43:46.325546Z"}
1618677826.319233: {"type":"l2update","product_id":"BAND-BTC","changes":[["buy","0.00032796","0.10"]],"time":"2021-04-17T16:43:46.325546Z"}
1618677826.3266501: {"type":"l2update","product_id":"SKL-USD","changes":[["sell","0.8082","12005.0"]],"time":"2021-04-17T16:43:46.331253Z"}
1618677826.330312: {"type":"l2update","product_id":"SKL-USD","changes":[["sell","0.8080","6005.0"]],"time":"2021-04-17T16:43:46.340849Z"}
1618677826.330357: {"type":"l2update","product_id":"SKL-USD","changes":[["buy","0.7903","1044.7"]],"time":"2021-04-17T16:43:46.342346Z"}
1618677826.332722: {"type":"l2update","product_id":"SKL-USD","changes":[["sell","0.8082","6005.0"]],"time":"2021-04-17T16:43:46.344744Z"}
1618677826.332766: {"type":"l2update","product_id":"BAND-GBP","changes":[["buy","14.7788","27.50"]],"time":"2021-04-17T16:43:46.344757Z"}
1618677826.332799: {"type":"l2update","product_id":"SKL-BTC","changes":[["sell","0.00001308","3452.8"]],"time":"2021-04-17T16:43:46.344779Z"}
1618677826.332822: {"type":"l2update","product_id":"YFI-BTC","changes":[["buy","0.82550","0.030189"]],"time":"2021-04-17T16:43:46.344787Z"}
1618677826.3328419: {"type":"l2update","product_id":"SKL-BTC","changes":[["sell","0.00001307","3788.9"]],"time":"2021-04-17T16:43:46.345203Z"}
1618677826.340003: {"type":"l2update","product_id":"NU-GBP","changes":[["sell","0.4393","8208.213533"]],"time":"2021-04-17T16:43:46.345172Z"}
1618677826.3400478: {"type":"match","trade_id":563679,"maker_order_id":"bec21123-3a5b-429a-958b-2e4f659c7e3f","taker_order_id":"cdec6759-641f-4bec-833c-1b9580da9046","side":"sell","size":"805.131","price":"0.4393","product_id":"NU-GBP","sequence":108779633,"time":"2021-04-17T16:43:46.345172Z"}
1618677826.340078: {"type":"ticker","sequence":108779633,"product_id":"NU-GBP","price":"0.4393","open_24h":"0.4041","volume_24h":"2611586.51676400","low_24h":"0.4026","high_24h":"0.4395","volume_30d":"70068108.17864700","best_bid":"0.4389","best_ask":"0.4393","side":"buy","time":"2021-04-17T16:43:46.345172Z","trade_id":563679,"last_size":"805.131"}
1618677826.3401: {"type":"l2update","product_id":"BAND-BTC","changes":[["buy","0.00033449","66.33"]],"time":"2021-04-17T16:43:46.346640Z"}
1618677826.340124: {"type":"l2update","product_id":"NU-GBP","changes":[["buy","0.4387","59.847987"]],"time":"2021-04-17T16:43:46.348938Z"}
1618677826.340152: {"type":"l2update","product_id":"NU-GBP","changes":[["sell","0.4396","0.000000"]],"time":"2021-04-17T16:43:46.350378Z"}
1618677826.340179: {"type":"l2update","product_id":"DASH-BTC","changes":[["sell","0.00621209","2.23600000"]],"time":"2021-04-17T16:43:46.353959Z"}
1618677826.34178: {"type":"l2update","product_id":"DASH-BTC","changes":[["sell","0.00621209","0.00000000"]],"time":"2021-04-17T16:43:46.357747Z"}
1618677826.341831: {"type":"l2update","product_id":"CRV-EUR","changes":[["buy","3.2697","103.00"]],"time":"2021-04-17T16:43:46.358429Z"}
1618677826.3427598: {"type":"l2update","product_id":"NU-GBP","changes":[["buy","0.4384","0.000000"]],"time":"2021-04-17T16:43:46.360213Z"}
1618677826.3468318: {"type":"l2update","product_id":"CRV-EUR","changes":[["buy","3.2971","96.90"]],"time":"2021-04-17T16:43:46.360966Z"}
1618677826.346882: {"type":"l2update","product_id":"SKL-USD","changes":[["sell","0.8080","12005.0"]],"time":"2021-04-17T16:43:46.361048Z"}
1618677826.346909: {"type":"l2update","product_id":"NU-GBP","changes":[["sell","0.4416","0.000000"]],"time":"2021-04-17T16:43:46.361614Z"}
1618677826.350239: {"type":"l2update","product_id":"CRV-EUR","changes":[["buy","3.2706","0.50"]],"time":"2021-04-17T16:43:46.364488Z"}
1618677826.3502898: {"type":"l2update","product_id":"BAND-GBP","changes":[["sell","14.8033","12.10"]],"time":"2021-04-17T16:43:46.364759Z"}
1618677826.350323: {"type":"l2update","product_id":"SKL-USD","changes":[["buy","0.7904","1345.7"]],"time":"2021-04-17T16:43:46.364770Z"}
1618677826.350349: {"type":"l2update","product_id":"CRV-EUR","changes":[["buy","3.2971","216.90"]],"time":"2021-04-17T16:43:46.364848Z"}
1618677826.350368: {"type":"l2update","product_id":"BAND-GBP","changes":[["buy","14.7670","12.27"]],"time":"2021-04-17T16:43:46.365020Z"}
1618677826.350389: {"type":"l2update","product_id":"NU-GBP","changes":[["buy","0.4386","0.000000"]],"time":"2021-04-17T16:43:46.365524Z"}
1618677826.357929: {"type":"l2update","product_id":"SKL-USD","changes":[["sell","0.8080","18005.0"]],"time":"2021-04-17T16:43:46.371079Z"}
1618677826.35797: {"type":"l2update","product_id":"SKL-GBP","changes":[["buy","0.5724","500.0"]],"time":"2021-04-17T16:43:46.371092Z"}
1618677826.358001: {"type":"l2update","product_id":"SKL-USD","changes":[["buy","0.7866","2659.8"]],"time":"2021-04-17T16:43:46.373700Z"}
1618677826.368948: {"type":"l2update","product_id":"DASH-BTC","changes":[["sell","0.00621069","1.62300000"]],"time":"2021-04-17T16:43:46.375034Z"}
1618677826.3709881: {"type":"l2update","product_id":"DASH-BTC","changes":[["sell","0.00621069","3.85900000"]],"time":"2021-04-17T16:43:46.386826Z"}
1618677826.3751051: {"type":"l2update","product_id":"DASH-BTC","changes":[["sell","0.00620687","0.00000000"]],"time":"2021-04-17T16:43:46.390166Z"}
1618677826.3752441: {"type":"l2update","product_id":"DASH-BTC","changes":[["buy","0.00619282","0.00000000"]],"time":"2021-04-17T16:43:46.391532Z"}
1618677826.3786721: {"type":"l2update","product_id":"SKL-USD","changes":[["buy","0.7872","25640.6"]],"time":"2021-04-17T16:43:46.394292Z"}
1618677826.378755: {"type":"l2update","product_id":"SKL-BTC","changes":[["sell","0.00001307","4682.5"]],"time":"2021-04-17T16:43:46.394439Z"}
1618677826.389337: {"type":"l2update","product_id":"DASH-BTC","changes":[["buy","0.00614336","0.00000000"]],"time":"2021-04-17T16:43:46.401406Z"}
1618677826.3894331: {"type":"l2update","product_id":"DASH-BTC","changes":[["buy","0.00614337","19.82300000"]],"time":"2021-04-17T16:43:46.401406Z"}
1618677826.3894699: {"type":"l2update","product_id":"NU-GBP","changes":[["buy","0.4387","1719.449087"]],"time":"2021-04-17T16:43:46.402626Z"}
1618677826.393483: {"type":"l2update","product_id":"SKL-USD","changes":[["buy","0.7915","989.7"]],"time":"2021-04-17T16:43:46.405782Z"}
1618677826.3935518: {"type":"l2update","product_id":"DASH-BTC","changes":[["buy","0.00614341","2.65000000"]],"time":"2021-04-17T16:43:46.409529Z"}
1618677826.393594: {"type":"l2update","product_id":"DASH-BTC","changes":[["buy","0.00614340","2.28000000"]],"time":"2021-04-17T16:43:46.409529Z"}
1618677826.3976161: {"type":"l2update","product_id":"DASH-BTC","changes":[["sell","0.00620367","0.82500000"]],"time":"2021-04-17T16:43:46.412821Z"}
1618677826.397692: {"type":"l2update","product_id":"BAND-BTC","changes":[["buy","0.00033406","0.00"]],"time":"2021-04-17T16:43:46.412901Z"}
1618677826.397737: {"type":"l2update","product_id":"NU-GBP","changes":[["sell","0.4415","1649.075800"]],"time":"2021-04-17T16:43:46.413010Z"}
1618677826.425608: {"type":"l2update","product_id":"CRV-EUR","changes":[["buy","3.2968","0.00"]],"time":"2021-04-17T16:43:46.435325Z"}
1618677826.43604: {"type":"l2update","product_id":"CRV-EUR","changes":[["buy","3.2970","0.00"]],"time":"2021-04-17T16:43:46.451966Z"}
1618677826.436095: {"type":"l2update","product_id":"BAND-BTC","changes":[["sell","0.00033523","0.00"]],"time":"2021-04-17T16:43:46.453775Z"}
1618677826.438168: {"type":"l2update","product_id":"BAND-GBP","changes":[["sell","14.8071","0.00"]],"time":"2021-04-17T16:43:46.454482Z"}
1618677826.444751: {"type":"l2update","product_id":"CRV-EUR","changes":[["buy","3.2963","140.93"]],"time":"2021-04-17T16:43:46.456057Z"}
1618677826.4448042: {"type":"l2update","product_id":"BAND-BTC","changes":[["sell","0.00033515","29.65"]],"time":"2021-04-17T16:43:46.459517Z"}
1618677826.445859: {"type":"l2update","product_id":"BAND-GBP","changes":[["sell","14.8031","27.80"]],"time":"2021-04-17T16:43:46.463132Z"}
1618677826.458567: {"type":"l2update","product_id":"SKL-USD","changes":[["buy","0.7904","0.0"]],"time":"2021-04-17T16:43:46.471130Z"}
1618677826.458622: {"type":"l2update","product_id":"CRV-EUR","changes":[["buy","3.2963","281.86"]],"time":"2021-04-17T16:43:46.473896Z"}
1618677826.461664: {"type":"l2update","product_id":"BAND-BTC","changes":[["sell","0.00033507","19.18"]],"time":"2021-04-17T16:43:46.474830Z"}
1618677826.461712: {"type":"l2update","product_id":"BAND-GBP","changes":[["buy","14.7739","12.54"]],"time":"2021-04-17T16:43:46.477648Z"}
1618677826.4640179: {"type":"l2update","product_id":"YFI-BTC","changes":[["buy","0.82608","0.000000"]],"time":"2021-04-17T16:43:46.480195Z"}
1618677826.464073: {"type":"l2update","product_id":"SKL-USD","changes":[["sell","0.8082","5.0"]],"time":"2021-04-17T16:43:46.480688Z"}
1618677826.46929: {"type":"l2update","product_id":"SKL-USD","changes":[["buy","0.7882","0.0"]],"time":"2021-04-17T16:43:46.485999Z"}
1618677826.469341: {"type":"l2update","product_id":"BAND-BTC","changes":[["buy","0.00033375","0.00"]],"time":"2021-04-17T16:43:46.486232Z"}
1618677826.478878: {"type":"l2update","product_id":"SKL-USD","changes":[["buy","0.7872","126.7"]],"time":"2021-04-17T16:43:46.492761Z"}
1618677826.4789178: {"type":"l2update","product_id":"DASH-BTC","changes":[["buy","0.00619187","0.00000000"]],"time":"2021-04-17T16:43:46.493722Z"}
1618677826.479819: {"type":"l2update","product_id":"SKL-USD","changes":[["buy","0.7905","2629.6"]],"time":"2021-04-17T16:43:46.496358Z"}
1618677826.48338: {"type":"l2update","product_id":"CRV-EUR","changes":[["buy","3.2963","140.93"]],"time":"2021-04-17T16:43:46.497433Z"}
1618677826.483417: {"type":"l2update","product_id":"SKL-BTC","changes":[["buy","0.00001305","110.0"]],"time":"2021-04-17T16:43:46.497881Z"}
1618677826.4834402: {"type":"l2update","product_id":"CRV-EUR","changes":[["buy","3.2963","0.00"]],"time":"2021-04-17T16:43:46.498495Z"}
1618677826.4888058: {"type":"l2update","product_id":"YFI-BTC","changes":[["buy","0.82550","0.000464"]],"time":"2021-04-17T16:43:46.504015Z"}
1618677826.495538: {"type":"l2update","product_id":"BAND-BTC","changes":[["buy","0.00033349","70.21"]],"time":"2021-04-17T16:43:46.511662Z"}
1618677826.495583: {"type":"l2update","product_id":"SKL-GBP","changes":[["buy","0.5723","5788.0"]],"time":"2021-04-17T16:43:46.511695Z"}
1618677826.495611: {"type":"l2update","product_id":"SKL-GBP","changes":[["buy","0.5688","0.0"]],"time":"2021-04-17T16:43:46.511695Z"}
1618677826.5000708: {"type":"l2update","product_id":"SKL-USD","changes":[["buy","0.7866","28173.7"]],"time":"2021-04-17T16:43:46.515518Z"}
1618677826.502602: {"type":"l2update","product_id":"SKL-BTC","changes":[["buy","0.00001306","1006.5"]],"time":"2021-04-17T16:43:46.518698Z"}
1618677826.502653: {"type":"l2update","product_id":"CRV-EUR","changes":[["buy","3.2970","140.93"]],"time":"2021-04-17T16:43:46.518614Z"}
1618677826.5026839: {"type":"l2update","product_id":"SKL-USD","changes":[["buy","0.7904","1194.2"]],"time":"2021-04-17T16:43:46.519086Z"}
1618677826.5044632: {"type":"l2update","product_id":"DASH-BTC","changes":[["buy","0.00618933","0.00000000"]],"time":"2021-04-17T16:43:46.520710Z"}
1618677826.505425: {"type":"l2update","product_id":"CRV-EUR","changes":[["buy","3.2970","281.86"]],"time":"2021-04-17T16:43:46.522514Z"}
1618677826.509763: {"type":"l2update","product_id":"DASH-BTC","changes":[["sell","0.00620824","2.66600000"]],"time":"2021-04-17T16:43:46.526330Z"}
1618677826.509813: {"type":"l2update","product_id":"SKL-GBP","changes":[["buy","0.5704","57755.0"]],"time":"2021-04-17T16:43:46.526348Z"}
1618677826.509848: {"type":"l2update","product_id":"SKL-GBP","changes":[["buy","0.5734","1735.0"]],"time":"2021-04-17T16:43:46.526348Z"}
1618677826.549868: {"type":"l2update","product_id":"SKL-BTC","changes":[["sell","0.00001310","11359.3"]],"time":"2021-04-17T16:43:46.563676Z"}
1618677826.5499442: {"type":"l2update","product_id":"CRV-EUR","changes":[["buy","3.2970","140.93"]],"time":"2021-04-17T16:43:46.567017Z"}
1618677826.555398: {"type":"l2update","product_id":"CRV-EUR","changes":[["buy","3.2970","0.00"]],"time":"2021-04-17T16:43:46.567693Z"}
1618677826.555462: {"type":"l2update","product_id":"SKL-BTC","changes":[["buy","0.00001306","0.0"]],"time":"2021-04-17T16:43:46.567758Z"}
1618677826.5672362: {"type":"l2update","product_id":"BAND-BTC","changes":[["sell","0.00033673","0.00"]],"time":"2021-04-17T16:43:46.581726Z"}
1618677826.56729: {"type":"l2update","product_id":"BAND-BTC","changes":[["sell","0.00033682","0.00"]],"time":"2021-04-17T16:43:46.581726Z"}
1618677826.56732: {"type":"l2update","product_id":"BAND-BTC","changes":[["buy","0.00033170","447.98"]],"time":"2021-04-17T16:43:46.581726Z"}
1618677826.5673442: {"type":"l2update","product_id":"BAND-BTC","changes":[["buy","0.00033170","446.58"]],"time":"2021-04-17T16:43:46.581726Z"}
1618677826.570724: {"type":"l2update","product_id":"DASH-BTC","changes":[["buy","0.00616178","0.00000000"]],"time":"2021-04-17T16:43:46.586034Z"}
1618677826.570773: {"type":"l2update","product_id":"DASH-BTC","changes":[["buy","0.00614337","15.65200000"]],"time":"2021-04-17T16:43:46.586034Z"}
1618677826.570799: {"type":"l2update","product_id":"DASH-BTC","changes":[["buy","0.00614337","0.31000000"]],"time":"2021-04-17T16:43:46.586034Z"}
1618677826.570818: {"type":"l2update","product_id":"DASH-BTC","changes":[["buy","0.00619652","0.00000000"]],"time":"2021-04-17T16:43:46.586883Z"}
1618677826.575413: {"type":"l2update","product_id":"BAND-BTC","changes":[["sell","0.00033810","20.10"]],"time":"2021-04-17T16:43:46.589143Z"}
1618677826.575456: {"type":"l2update","product_id":"BAND-BTC","changes":[["buy","0.00033170","448.08"]],"time":"2021-04-17T16:43:46.589143Z"}
1618677826.5754812: {"type":"l2update","product_id":"BAND-BTC","changes":[["sell","0.00033809","9.70"]],"time":"2021-04-17T16:43:46.589143Z"}
1618677826.582998: {"type":"l2update","product_id":"DASH-BTC","changes":[["buy","0.00619213","0.00000000"]],"time":"2021-04-17T16:43:46.594287Z"}
1618677826.583049: {"type":"l2update","product_id":"DASH-BTC","changes":[["buy","0.00616178","4.40500000"]],"time":"2021-04-17T16:43:46.596505Z"}
1618677826.583081: {"type":"l2update","product_id":"SKL-BTC","changes":[["buy","0.00001305","1116.5"]],"time":"2021-04-17T16:43:46.596668Z"}
1618677826.583104: {"type":"l2update","product_id":"CRV-EUR","changes":[["buy","3.2964","140.93"]],"time":"2021-04-17T16:43:46.596657Z"}
1618677826.585097: {"type":"l2update","product_id":"DASH-BTC","changes":[["sell","0.00620889","1.00000000"]],"time":"2021-04-17T16:43:46.600012Z"}
1618677826.585144: {"type":"l2update","product_id":"CRV-EUR","changes":[["buy","3.2964","281.86"]],"time":"2021-04-17T16:43:46.600328Z"}
1618677826.59714: {"type":"l2update","product_id":"DASH-BTC","changes":[["buy","0.00618704","32.84700000"]],"time":"2021-04-17T16:43:46.603965Z"}
1618677826.5981529: {"type":"l2update","product_id":"DASH-BTC","changes":[["buy","0.00619286","2.57100000"]],"time":"2021-04-17T16:43:46.611852Z"}
1618677826.602565: {"type":"l2update","product_id":"SKL-USD","changes":[["buy","0.7888","1900.0"]],"time":"2021-04-17T16:43:46.616057Z"}
1618677826.6079118: {"type":"l2update","product_id":"DASH-BTC","changes":[["buy","0.00619285","1.54200000"]],"time":"2021-04-17T16:43:46.620446Z"}
1618677826.607956: {"type":"l2update","product_id":"YFI-BTC","changes":[["buy","0.82589","0.000000"]],"time":"2021-04-17T16:43:46.623817Z"}
1618677826.607998: {"type":"l2update","product_id":"DASH-BTC","changes":[["buy","0.00619285","0.00000000"]],"time":"2021-04-17T16:43:46.624571Z"}
1618677826.609994: {"type":"l2update","product_id":"SKL-USD","changes":[["buy","0.7866","2659.8"]],"time":"2021-04-17T16:43:46.626269Z"}
1618677826.619634: {"type":"l2update","product_id":"YFI-BTC","changes":[["buy","0.82520","0.000000"]],"time":"2021-04-17T16:43:46.631492Z"}
1618677826.6196768: {"type":"l2update","product_id":"SKL-BTC","changes":[["buy","0.00001305","110.0"]],"time":"2021-04-17T16:43:46.632554Z"}
1618677826.621832: {"type":"l2update","product_id":"BAND-BTC","changes":[["sell","0.00033515","0.00"]],"time":"2021-04-17T16:43:46.633287Z"}
1618677826.6218922: {"type":"l2update","product_id":"BAND-GBP","changes":[["buy","14.7788","0.00"]],"time":"2021-04-17T16:43:46.636990Z"}
1618677826.622463: {"type":"l2update","product_id":"BAND-BTC","changes":[["sell","0.00033507","48.83"]],"time":"2021-04-17T16:43:46.638475Z"}
1618677826.622495: {"type":"l2update","product_id":"BAND-BTC","changes":[["buy","0.00033275","0.00"]],"time":"2021-04-17T16:43:46.639008Z"}
1618677826.624945: {"type":"l2update","product_id":"BAND-GBP","changes":[["buy","14.7739","0.00"]],"time":"2021-04-17T16:43:46.640878Z"}
1618677826.625945: {"type":"l2update","product_id":"BAND-GBP","changes":[["sell","14.8179","0.00"]],"time":"2021-04-17T16:43:46.641957Z"}
1618677826.625988: {"type":"l2update","product_id":"BAND-BTC","changes":[["buy","0.00033449","36.73"]],"time":"2021-04-17T16:43:46.642252Z"}
