1635444230.86049: {"type":"subscribed","connection_id":"60a4fc71-1312-4830-86f4-9eb98be106ac","message_id":14,"channel":"v3_trades","id":"UMA-USD","contents":{"trades":[{"side":"SELL","size":"134.1","price":"11.3","createdAt":"2021-10-28T17:53:52.150Z"},{"side":"SELL","size":"151.3","price":"11.3","createdAt":"2021-10-28T17:53:51.164Z"},{"side":"BUY","size":"2.8","price":"11.33","createdAt":"2021-10-28T17:27:04.499Z"},{"side":"BUY","size":"97.2","price":"11.33","createdAt":"2021-10-28T17:27:04.499Z"},{"side":"BUY","size":"10","price":"11.37","createdAt":"2021-10-28T17:00:17.717Z"},{"side":"BUY","size":"223.6","price":"11.37","createdAt":"2021-10-28T16:46:13.547Z"},{"side":"SELL","size":"76.3","price":"11.35","createdAt":"2021-10-28T16:46:00.184Z"},{"side":"SELL","size":"96.8","price":"11.35","createdAt":"2021-10-28T16:46:00.184Z"},{"side":"BUY","size":"127.7","price":"11.28","createdAt":"2021-10-28T16:02:36.137Z"},{"side":"BUY","size":"2.6","price":"11.26","createdAt":"2021-10-28T16:00:05.606Z"},{"side":"SELL","size":"150.2","price":"11.35","createdAt":"2021-10-28T15:45:10.835Z"},{"side":"SELL","size":"183.3","price":"11.35","createdAt":"2021-10-28T15:45:10.708Z"},{"side":"SELL","size":"206.2","price":"11.35","createdAt":"2021-10-28T15:45:09.805Z"},{"side":"BUY","size":"93.4","price":"11.33","createdAt":"2021-10-28T15:45:08.536Z"},{"side":"BUY","size":"82.2","price":"11.32","createdAt":"2021-10-28T15:45:08.441Z"},{"side":"BUY","size":"15.1","price":"11.32","createdAt":"2021-10-28T15:45:08.351Z"},{"side":"BUY","size":"97.4","price":"11.32","createdAt":"2021-10-28T15:45:08.351Z"},{"side":"BUY","size":"440.5","price":"11.3","createdAt":"2021-10-28T15:45:08.112Z"},{"side":"BUY","size":"46.6","price":"11.3","createdAt":"2021-10-28T15:45:08.087Z"},{"side":"BUY","size":"98.4","price":"11.3","createdAt":"2021-10-28T15:45:08.087Z"},{"side":"BUY","size":"163.1","price":"11.3","createdAt":"2021-10-28T15:45:07.992Z"},{"side":"BUY","size":"94.7","price":"11.3","createdAt":"2021-10-28T15:45:07.899Z"},{"side":"BUY","size":"88.8","price":"11.3","createdAt":"2021-10-28T15:45:07.899Z"},{"side":"BUY","size":"94.2","price":"11.29","createdAt":"2021-10-28T15:45:07.707Z"},{"side":"BUY","size":"97.6","price":"11.28","createdAt":"2021-10-28T15:45:07.609Z"},{"side":"SELL","size":"85.2","price":"11.3","createdAt":"2021-10-28T15:39:19.974Z"},{"side":"BUY","size":"125.1","price":"11.32","createdAt":"2021-10-28T15:24:31.562Z"},{"side":"BUY","size":"140.7","price":"11.32","createdAt":"2021-10-28T15:24:31.464Z"},{"side":"BUY","size":"2353.1","price":"11.32","createdAt":"2021-10-28T14:46:18.531Z"},{"side":"BUY","size":"97.3","price":"11.32","createdAt":"2021-10-28T14:46:18.531Z"},{"side":"BUY","size":"97.4","price":"11.32","createdAt":"2021-10-28T14:46:18.531Z"},{"side":"BUY","size":"156.7","price":"11.3","createdAt":"2021-10-28T14:36:21.050Z"},{"side":"SELL","size":"70.7","price":"11.26","createdAt":"2021-10-28T14:12:06.467Z"},{"side":"SELL","size":"151.3","price":"11.27","createdAt":"2021-10-28T14:12:06.467Z"},{"side":"BUY","size":"100","price":"11.23","createdAt":"2021-10-28T14:02:06.332Z"},{"side":"BUY","size":"140.3","price":"11.28","createdAt":"2021-10-28T14:01:10.202Z"},{"side":"BUY","size":"157.8","price":"11.28","createdAt":"2021-10-28T14:01:10.098Z"},{"side":"BUY","size":"177.5","price":"11.28","createdAt":"2021-10-28T14:01:10.008Z"},{"side":"SELL","size":"97.3","price":"11.29","createdAt":"2021-10-28T14:01:07.914Z"},{"side":"SELL","size":"87.5","price":"11.3","createdAt":"2021-10-28T14:01:07.344Z"},{"side":"SELL","size":"24.8","price":"11.3","createdAt":"2021-10-28T14:01:07.344Z"},{"side":"SELL","size":"126.4","price":"11.3","createdAt":"2021-10-28T14:01:07.147Z"},{"side":"SELL","size":"125.2","price":"11.3","createdAt":"2021-10-28T14:01:06.679Z"},{"side":"SELL","size":"43","price":"11.29","createdAt":"2021-10-28T14:01:06.570Z"},{"side":"SELL","size":"97.9","price":"11.3","createdAt":"2021-10-28T14:01:06.570Z"},{"side":"SELL","size":"78.5","price":"11.3","createdAt":"2021-10-28T14:01:06.470Z"},{"side":"SELL","size":"98.2","price":"11.3","createdAt":"2021-10-28T14:01:06.470Z"},{"side":"SELL","size":"83.8","price":"11.3","createdAt":"2021-10-28T14:01:06.281Z"},{"side":"SELL","size":"93.5","price":"11.31","createdAt":"2021-10-28T14:01:06.281Z"},{"side":"SELL","size":"43.3","price":"11.35","createdAt":"2021-10-28T13:59:50.413Z"},{"side":"SELL","size":"96.7","price":"11.36","createdAt":"2021-10-28T13:59:50.413Z"},{"side":"BUY","size":"44.2","price":"11.31","createdAt":"2021-10-28T13:10:54.027Z"},{"side":"SELL","size":"106.8","price":"11.24","createdAt":"2021-10-28T13:00:52.771Z"},{"side":"SELL","size":"70.8","price":"11.24","createdAt":"2021-10-28T13:00:52.472Z"},{"side":"SELL","size":"49.4","price":"11.24","createdAt":"2021-10-28T13:00:52.472Z"},{"side":"SELL","size":"40.8","price":"11.24","createdAt":"2021-10-28T13:00:52.352Z"},{"side":"SELL","size":"87.2","price":"11.24","createdAt":"2021-10-28T13:00:52.352Z"},{"side":"SELL","size":"44.4","price":"11.24","createdAt":"2021-10-28T13:00:52.134Z"},{"side":"SELL","size":"97.6","price":"11.24","createdAt":"2021-10-28T13:00:52.134Z"},{"side":"SELL","size":"1","price":"11.24","createdAt":"2021-10-28T13:00:52.134Z"},{"side":"SELL","size":"1","price":"11.25","createdAt":"2021-10-28T13:00:52.134Z"},{"side":"BUY","size":"11","price":"11.26","createdAt":"2021-10-28T12:57:19.783Z"},{"side":"BUY","size":"3","price":"11.26","createdAt":"2021-10-28T12:52:19.264Z"},{"side":"SELL","size":"8","price":"11.25","createdAt":"2021-10-28T12:48:52.515Z"},{"side":"BUY","size":"11","price":"11.27","createdAt":"2021-10-28T12:47:41.055Z"},{"side":"BUY","size":"144.1","price":"11.27","createdAt":"2021-10-28T12:44:26.854Z"},{"side":"BUY","size":"12","price":"11.27","createdAt":"2021-10-28T12:42:43.059Z"},{"side":"SELL","size":"20.5","price":"11.24","createdAt":"2021-10-28T12:39:40.237Z"},{"side":"BUY","size":"20.5","price":"11.27","createdAt":"2021-10-28T12:39:33.167Z"},{"side":"BUY","size":"11","price":"11.26","createdAt":"2021-10-28T12:37:38.486Z"},{"side":"BUY","size":"8","price":"11.26","createdAt":"2021-10-28T12:33:13.343Z"},{"side":"BUY","size":"10","price":"11.27","createdAt":"2021-10-28T11:51:28.495Z"},{"side":"SELL","size":"80","price":"11.26","createdAt":"2021-10-28T11:49:07.737Z"},{"side":"SELL","size":"59","price":"11.26","createdAt":"2021-10-28T11:48:47.822Z"},{"side":"BUY","size":"222","price":"11.37","createdAt":"2021-10-28T09:49:56.911Z"},{"side":"BUY","size":"97.6","price":"11.29","createdAt":"2021-10-28T09:39:20.661Z"},{"side":"SELL","size":"145.1","price":"11.29","createdAt":"2021-10-28T09:26:03.344Z"},{"side":"SELL","size":"300","price":"11.29","createdAt":"2021-10-28T09:22:15.250Z"},{"side":"BUY","size":"131.3","price":"11.3","createdAt":"2021-10-28T09:04:07.167Z"},{"side":"BUY","size":"200","price":"11.27","createdAt":"2021-10-28T08:53:14.342Z"},{"side":"BUY","size":"97.8","price":"11.26","createdAt":"2021-10-28T08:52:56.792Z"},{"side":"SELL","size":"97.6","price":"11.26","createdAt":"2021-10-28T08:51:32.720Z"},{"side":"SELL","size":"97","price":"11.33","createdAt":"2021-10-28T08:50:17.937Z"},{"side":"BUY","size":"108.4","price":"11.36","createdAt":"2021-10-28T08:49:55.485Z"},{"side":"SELL","size":"3336.6","price":"11.34","createdAt":"2021-10-28T08:48:54.219Z"},{"side":"SELL","size":"142.2","price":"11.34","createdAt":"2021-10-28T08:48:33.207Z"},{"side":"BUY","size":"3336.6","price":"11.22","createdAt":"2021-10-28T08:47:14.851Z"},{"side":"BUY","size":"3336.6","price":"11.22","createdAt":"2021-10-28T08:47:14.838Z"},{"side":"BUY","size":"137.5","price":"11.23","createdAt":"2021-10-28T08:46:52.579Z"},{"side":"BUY","size":"25.3","price":"11.23","createdAt":"2021-10-28T08:45:51.551Z"},{"side":"SELL","size":"97.3","price":"11.28","createdAt":"2021-10-28T08:45:43.361Z"},{"side":"SELL","size":"97.2","price":"11.29","createdAt":"2021-10-28T08:45:42.338Z"},{"side":"SELL","size":"3336.6","price":"11.33","createdAt":"2021-10-28T08:45:37.119Z"},{"side":"SELL","size":"3336.6","price":"11.33","createdAt":"2021-10-28T08:45:37.084Z"},{"side":"SELL","size":"116.4","price":"11.29","createdAt":"2021-10-28T08:43:32.486Z"},{"side":"SELL","size":"150.5","price":"11.21","createdAt":"2021-10-28T08:42:28.304Z"},{"side":"BUY","size":"3238.3","price":"11.21","createdAt":"2021-10-28T08:42:27.762Z"},{"side":"BUY","size":"98.3","price":"11.21","createdAt":"2021-10-28T08:42:27.762Z"},{"side":"BUY","size":"300","price":"11.17","createdAt":"2021-10-28T08:32:13.123Z"},{"side":"BUY","size":"137.3","price":"11.16","createdAt":"2021-10-28T08:27:43.255Z"}]}}
1635444230.860785: {"type":"subscribed","connection_id":"60a4fc71-1312-4830-86f4-9eb98be106ac","message_id":11,"channel":"v3_trades","id":"ETH-USD","contents":{"trades":[{"side":"BUY","size":"0.1","price":"4215.6","createdAt":"2021-10-28T18:03:50.076Z"},{"side":"SELL","size":"0.02","price":"4215.5","createdAt":"2021-10-28T18:03:48.672Z"},{"side":"SELL","size":"0.03","price":"4215.5","createdAt":"2021-10-28T18:03:45.036Z"},{"side":"SELL","size":"0.02","price":"4215.5","createdAt":"2021-10-28T18:03:42.647Z"},{"side":"SELL","size":"0.2","price":"4215.5","createdAt":"2021-10-28T18:03:41.587Z"},{"side":"BUY","size":"0.1","price":"4215.6","createdAt":"2021-10-28T18:03:38.491Z"},{"side":"BUY","size":"0.1","price":"4215.6","createdAt":"2021-10-28T18:03:38.241Z"},{"side":"BUY","size":"0.1","price":"4215.6","createdAt":"2021-10-28T18:03:36.607Z"},{"side":"SELL","size":"0.1","price":"4215.5","createdAt":"2021-10-28T18:03:35.686Z"},{"side":"SELL","size":"0.02","price":"4215.5","createdAt":"2021-10-28T18:03:35.387Z"},{"side":"SELL","size":"0.03","price":"4215.5","createdAt":"2021-10-28T18:03:35.015Z"},{"side":"SELL","size":"0.1","price":"4215.5","createdAt":"2021-10-28T18:03:34.933Z"},{"side":"SELL","size":"2.372","price":"4215.5","createdAt":"2021-10-28T18:03:34.423Z"},{"side":"BUY","size":"0.1","price":"4215.6","createdAt":"2021-10-28T18:03:34.048Z"},{"side":"BUY","size":"0.1","price":"4215.6","createdAt":"2021-10-28T18:03:33.825Z"},{"side":"BUY","size":"2.372","price":"4215.6","createdAt":"2021-10-28T18:03:33.372Z"},{"side":"BUY","size":"0.1","price":"4215.9","createdAt":"2021-10-28T18:03:32.302Z"},{"side":"BUY","size":"30.035","price":"4215","createdAt":"2021-10-28T18:03:30.028Z"},{"side":"BUY","size":"23.749","price":"4215","createdAt":"2021-10-28T18:03:30.028Z"},{"side":"BUY","size":"22.496","price":"4214.7","createdAt":"2021-10-28T18:03:30.028Z"},{"side":"BUY","size":"0.02","price":"4214.7","createdAt":"2021-10-28T18:03:30.028Z"},{"side":"BUY","size":"40.51","price":"4214.4","createdAt":"2021-10-28T18:03:30.028Z"},{"side":"BUY","size":"22.496","price":"4214.3","createdAt":"2021-10-28T18:03:30.028Z"},{"side":"BUY","size":"58.61","price":"4214.2","createdAt":"2021-10-28T18:03:30.028Z"},{"side":"BUY","size":"9.797","price":"4214.2","createdAt":"2021-10-28T18:03:30.028Z"},{"side":"BUY","size":"57.648","price":"4214.2","createdAt":"2021-10-28T18:03:30.028Z"},{"side":"BUY","size":"4.807","price":"4214.1","createdAt":"2021-10-28T18:03:30.028Z"},{"side":"BUY","size":"293.595","price":"4214.1","createdAt":"2021-10-28T18:03:30.028Z"},{"side":"SELL","size":"4.3","price":"4214.9","createdAt":"2021-10-28T18:03:27.647Z"},{"side":"SELL","size":"0.1","price":"4214.9","createdAt":"2021-10-28T18:03:27.378Z"},{"side":"SELL","size":"0.5","price":"4215","createdAt":"2021-10-28T18:03:27.118Z"},{"side":"SELL","size":"0.4","price":"4215","createdAt":"2021-10-28T18:03:27.093Z"},{"side":"SELL","size":"22.496","price":"4215.9","createdAt":"2021-10-28T18:03:26.756Z"},{"side":"SELL","size":"0.02","price":"4215.9","createdAt":"2021-10-28T18:03:26.632Z"},{"side":"SELL","size":"0.03","price":"4215.9","createdAt":"2021-10-28T18:03:26.566Z"},{"side":"BUY","size":"0.5","price":"4215.9","createdAt":"2021-10-28T18:03:21.805Z"},{"side":"BUY","size":"3.206","price":"4215.9","createdAt":"2021-10-28T18:03:21.648Z"},{"side":"BUY","size":"0.107","price":"4215.3","createdAt":"2021-10-28T18:03:21.648Z"},{"side":"BUY","size":"0.014","price":"4215.3","createdAt":"2021-10-28T18:03:21.854Z"},{"side":"BUY","size":"0.391","price":"4215.3","createdAt":"2021-10-28T18:03:21.685Z"},{"side":"BUY","size":"0.2","price":"4215","createdAt":"2021-10-28T18:03:21.685Z"},{"side":"BUY","size":"9.186","price":"4214","createdAt":"2021-10-28T18:03:21.270Z"},{"side":"BUY","size":"0.5","price":"4214","createdAt":"2021-10-28T18:03:21.240Z"},{"side":"BUY","size":"0.49","price":"4214.9","createdAt":"2021-10-28T18:03:20.986Z"},{"side":"BUY","size":"0.01","price":"4214.4","createdAt":"2021-10-28T18:03:20.986Z"},{"side":"BUY","size":"17.11","price":"4214.1","createdAt":"2021-10-28T18:03:20.939Z"},{"side":"BUY","size":"0.5","price":"4214.1","createdAt":"2021-10-28T18:03:20.910Z"},{"side":"BUY","size":"0.5","price":"4214.1","createdAt":"2021-10-28T18:03:20.853Z"},{"side":"BUY","size":"0.3","price":"4214.1","createdAt":"2021-10-28T18:03:20.866Z"},{"side":"BUY","size":"0.2","price":"4214","createdAt":"2021-10-28T18:03:20.866Z"},{"side":"BUY","size":"0.4","price":"4213","createdAt":"2021-10-28T18:03:20.310Z"},{"side":"BUY","size":"0.1","price":"4213","createdAt":"2021-10-28T18:03:20.310Z"},{"side":"BUY","size":"0.1","price":"4213","createdAt":"2021-10-28T18:03:19.683Z"},{"side":"BUY","size":"0.1","price":"4212.8","createdAt":"2021-10-28T18:03:18.454Z"},{"side":"BUY","size":"0.1","price":"4212.8","createdAt":"2021-10-28T18:03:17.962Z"},{"side":"SELL","size":"0.1","price":"4212.7","createdAt":"2021-10-28T18:03:17.169Z"},{"side":"SELL","size":"0.1","price":"4212.7","createdAt":"2021-10-28T18:03:17.028Z"},{"side":"BUY","size":"0.1","price":"4212.8","createdAt":"2021-10-28T18:03:16.162Z"},{"side":"BUY","size":"0.1","price":"4212.8","createdAt":"2021-10-28T18:03:16.092Z"},{"side":"SELL","size":"0.1","price":"4212.7","createdAt":"2021-10-28T18:03:15.019Z"},{"side":"BUY","size":"0.1","price":"4212.8","createdAt":"2021-10-28T18:03:14.433Z"},{"side":"SELL","size":"0.085","price":"4212.5","createdAt":"2021-10-28T18:03:01.335Z"},{"side":"BUY","size":"0.1","price":"4212.6","createdAt":"2021-10-28T18:03:00.934Z"},{"side":"BUY","size":"0.1","price":"4212.6","createdAt":"2021-10-28T18:03:00.498Z"},{"side":"SELL","size":"0.1","price":"4212.5","createdAt":"2021-10-28T18:02:59.852Z"},{"side":"SELL","size":"0.1","price":"4212.5","createdAt":"2021-10-28T18:02:59.570Z"},{"side":"BUY","size":"0.1","price":"4212.6","createdAt":"2021-10-28T18:02:58.811Z"},{"side":"BUY","size":"0.1","price":"4212.6","createdAt":"2021-10-28T18:02:58.770Z"},{"side":"BUY","size":"0.1","price":"4212.6","createdAt":"2021-10-28T18:02:58.679Z"},{"side":"SELL","size":"0.02","price":"4212.5","createdAt":"2021-10-28T18:02:58.553Z"},{"side":"SELL","size":"0.1","price":"4212.5","createdAt":"2021-10-28T18:02:57.984Z"},{"side":"BUY","size":"0.06","price":"4212.6","createdAt":"2021-10-28T18:02:56.941Z"},{"side":"BUY","size":"0.01","price":"4212.6","createdAt":"2021-10-28T18:02:56.941Z"},{"side":"BUY","size":"0.03","price":"4212.6","createdAt":"2021-10-28T18:02:56.941Z"},{"side":"SELL","size":"0.02","price":"4212.5","createdAt":"2021-10-28T18:02:54.008Z"},{"side":"BUY","size":"0.1","price":"4212","createdAt":"2021-10-28T18:02:44.136Z"},{"side":"SELL","size":"0.1","price":"4211.9","createdAt":"2021-10-28T18:02:43.088Z"},{"side":"SELL","size":"0.1","price":"4211.9","createdAt":"2021-10-28T18:02:42.029Z"},{"side":"BUY","size":"0.1","price":"4212","createdAt":"2021-10-28T18:02:42.030Z"},{"side":"BUY","size":"0.1","price":"4212","createdAt":"2021-10-28T18:02:41.732Z"},{"side":"BUY","size":"0.1","price":"4212","createdAt":"2021-10-28T18:02:41.194Z"},{"side":"SELL","size":"0.1","price":"4211.9","createdAt":"2021-10-28T18:02:41.024Z"},{"side":"BUY","size":"0.1","price":"4212","createdAt":"2021-10-28T18:02:40.013Z"},{"side":"BUY","size":"0.1","price":"4212","createdAt":"2021-10-28T18:02:39.361Z"},{"side":"BUY","size":"0.061","price":"4211.8","createdAt":"2021-10-28T18:02:37.838Z"},{"side":"BUY","size":"0.438","price":"4211.9","createdAt":"2021-10-28T18:02:37.259Z"},{"side":"BUY","size":"0.062","price":"4211.7","createdAt":"2021-10-28T18:02:37.259Z"},{"side":"BUY","size":"9.823","price":"4210.7","createdAt":"2021-10-28T18:02:36.881Z"},{"side":"BUY","size":"85.386","price":"4210.6","createdAt":"2021-10-28T18:02:36.881Z"},{"side":"BUY","size":"0.2","price":"4210.6","createdAt":"2021-10-28T18:02:36.723Z"},{"side":"SELL","size":"0.06","price":"4210.5","createdAt":"2021-10-28T18:02:36.279Z"},{"side":"BUY","size":"0.1","price":"4210.6","createdAt":"2021-10-28T18:02:26.872Z"},{"side":"SELL","size":"0.1","price":"4210.5","createdAt":"2021-10-28T18:02:25.823Z"},{"side":"SELL","size":"32.588","price":"4210.5","createdAt":"2021-10-28T18:02:25.194Z"},{"side":"SELL","size":"1.604","price":"4210.5","createdAt":"2021-10-28T18:02:25.194Z"},{"side":"SELL","size":"58.849","price":"4210.5","createdAt":"2021-10-28T18:02:25.194Z"},{"side":"SELL","size":"39.98","price":"4210.5","createdAt":"2021-10-28T18:02:25.194Z"},{"side":"SELL","size":"9.451","price":"4210.5","createdAt":"2021-10-28T18:02:25.194Z"},{"side":"SELL","size":"0.1","price":"4210.5","createdAt":"2021-10-28T18:02:24.279Z"},{"side":"BUY","size":"0.1","price":"4210.6","createdAt":"2021-10-28T18:02:23.790Z"}]}}
1635444230.8610802: {"type":"subscribed","connection_id":"60a4fc71-1312-4830-86f4-9eb98be106ac","message_id":15,"channel":"v3_trades","id":"SUSHI-USD","contents":{"trades":[{"side":"SELL","size":"9","price":"10.788","createdAt":"2021-10-28T18:03:41.575Z"},{"side":"BUY","size":"186","price":"10.792","createdAt":"2021-10-28T18:03:40.322Z"},{"side":"BUY","size":"217","price":"10.792","createdAt":"2021-10-28T18:03:40.322Z"},{"side":"BUY","size":"15","price":"10.789","createdAt":"2021-10-28T18:03:40.322Z"},{"side":"SELL","size":"9","price":"10.784","createdAt":"2021-10-28T18:03:26.826Z"},{"side":"BUY","size":"189","price":"10.785","createdAt":"2021-10-28T18:03:24.404Z"},{"side":"BUY","size":"55","price":"10.785","createdAt":"2021-10-28T18:03:24.374Z"},{"side":"BUY","size":"279","price":"10.783","createdAt":"2021-10-28T18:03:23.343Z"},{"side":"BUY","size":"233","price":"10.783","createdAt":"2021-10-28T18:03:23.274Z"},{"side":"BUY","size":"68","price":"10.783","createdAt":"2021-10-28T18:03:23.214Z"},{"side":"BUY","size":"48","price":"10.783","createdAt":"2021-10-28T18:03:22.257Z"},{"side":"BUY","size":"61","price":"10.783","createdAt":"2021-10-28T18:03:21.610Z"},{"side":"BUY","size":"30","price":"10.783","createdAt":"2021-10-28T18:03:21.610Z"},{"side":"BUY","size":"214","price":"10.774","createdAt":"2021-10-28T18:03:14.608Z"},{"side":"BUY","size":"228","price":"10.774","createdAt":"2021-10-28T18:03:14.594Z"},{"side":"BUY","size":"15","price":"10.774","createdAt":"2021-10-28T18:03:14.594Z"},{"side":"SELL","size":"9","price":"10.769","createdAt":"2021-10-28T18:03:12.956Z"},{"side":"BUY","size":"214","price":"10.767","createdAt":"2021-10-28T18:03:02.436Z"},{"side":"BUY","size":"186","price":"10.763","createdAt":"2021-10-28T18:02:56.292Z"},{"side":"BUY","size":"234","price":"10.763","createdAt":"2021-10-28T18:02:56.283Z"},{"side":"SELL","size":"9","price":"10.757","createdAt":"2021-10-28T18:02:53.280Z"},{"side":"BUY","size":"201","price":"10.762","createdAt":"2021-10-28T18:02:50.792Z"},{"side":"BUY","size":"13","price":"10.76","createdAt":"2021-10-28T18:02:50.792Z"},{"side":"BUY","size":"306.6","price":"10.758","createdAt":"2021-10-28T18:02:45.872Z"},{"side":"BUY","size":"3695.7","price":"10.758","createdAt":"2021-10-28T18:02:45.808Z"},{"side":"BUY","size":"210","price":"10.755","createdAt":"2021-10-28T18:02:45.275Z"},{"side":"BUY","size":"233","price":"10.755","createdAt":"2021-10-28T18:02:45.265Z"},{"side":"BUY","size":"180","price":"10.755","createdAt":"2021-10-28T18:02:44.898Z"},{"side":"SELL","size":"9","price":"10.744","createdAt":"2021-10-28T18:02:39.758Z"},{"side":"SELL","size":"93.5","price":"10.745","createdAt":"2021-10-28T18:02:39.674Z"},{"side":"SELL","size":"170","price":"10.751","createdAt":"2021-10-28T18:02:39.491Z"},{"side":"SELL","size":"210","price":"10.751","createdAt":"2021-10-28T18:02:39.382Z"},{"side":"SELL","size":"214","price":"10.755","createdAt":"2021-10-28T18:02:39.299Z"},{"side":"SELL","size":"120.5","price":"10.755","createdAt":"2021-10-28T18:02:39.257Z"},{"side":"SELL","size":"175.1","price":"10.756","createdAt":"2021-10-28T18:02:39.257Z"},{"side":"SELL","size":"199.1","price":"10.756","createdAt":"2021-10-28T18:02:39.246Z"},{"side":"SELL","size":"14.9","price":"10.759","createdAt":"2021-10-28T18:02:39.246Z"},{"side":"SELL","size":"267.2","price":"10.76","createdAt":"2021-10-28T18:02:39.084Z"},{"side":"SELL","size":"4002.3","price":"10.763","createdAt":"2021-10-28T18:02:39.084Z"},{"side":"SELL","size":"0.1","price":"10.759","createdAt":"2021-10-28T18:02:35.380Z"},{"side":"SELL","size":"26.9","price":"10.76","createdAt":"2021-10-28T18:02:35.380Z"},{"side":"SELL","size":"3.1","price":"10.76","createdAt":"2021-10-28T18:02:20.877Z"},{"side":"SELL","size":"7.3","price":"10.763","createdAt":"2021-10-28T18:02:13.169Z"},{"side":"SELL","size":"14","price":"10.762","createdAt":"2021-10-28T18:02:02.835Z"},{"side":"BUY","size":"213","price":"10.763","createdAt":"2021-10-28T18:02:01.999Z"},{"side":"SELL","size":"1209.2","price":"10.764","createdAt":"2021-10-28T18:01:53.428Z"},{"side":"BUY","size":"284.2","price":"10.773","createdAt":"2021-10-28T18:01:43.909Z"},{"side":"SELL","size":"142.1","price":"10.772","createdAt":"2021-10-28T18:01:41.791Z"},{"side":"BUY","size":"261.9","price":"10.773","createdAt":"2021-10-28T18:01:41.768Z"},{"side":"BUY","size":"13","price":"10.773","createdAt":"2021-10-28T18:01:41.768Z"},{"side":"SELL","size":"172","price":"10.773","createdAt":"2021-10-28T18:01:40.657Z"},{"side":"SELL","size":"15","price":"10.774","createdAt":"2021-10-28T18:01:40.657Z"},{"side":"SELL","size":"30","price":"10.783","createdAt":"2021-10-28T18:01:40.657Z"},{"side":"SELL","size":"15","price":"10.789","createdAt":"2021-10-28T18:01:40.657Z"},{"side":"SELL","size":"86.5","price":"10.793","createdAt":"2021-10-28T18:01:40.633Z"},{"side":"SELL","size":"63","price":"10.793","createdAt":"2021-10-28T18:01:40.612Z"},{"side":"SELL","size":"73","price":"10.793","createdAt":"2021-10-28T18:01:40.515Z"},{"side":"SELL","size":"13","price":"10.793","createdAt":"2021-10-28T18:01:40.467Z"},{"side":"SELL","size":"274.1","price":"10.793","createdAt":"2021-10-28T18:01:40.446Z"},{"side":"SELL","size":"108","price":"10.793","createdAt":"2021-10-28T18:01:40.387Z"},{"side":"SELL","size":"283.2","price":"10.793","createdAt":"2021-10-28T18:01:40.297Z"},{"side":"SELL","size":"13","price":"10.793","createdAt":"2021-10-28T18:01:40.248Z"},{"side":"SELL","size":"236","price":"10.793","createdAt":"2021-10-28T18:01:40.212Z"},{"side":"SELL","size":"256","price":"10.793","createdAt":"2021-10-28T18:01:40.175Z"},{"side":"SELL","size":"318.6","price":"10.793","createdAt":"2021-10-28T18:01:40.084Z"},{"side":"SELL","size":"9","price":"10.793","createdAt":"2021-10-28T18:01:40.048Z"},{"side":"SELL","size":"349.7","price":"10.793","createdAt":"2021-10-28T18:01:39.984Z"},{"side":"SELL","size":"10944.8","price":"10.793","createdAt":"2021-10-28T18:01:39.976Z"},{"side":"SELL","size":"93","price":"10.793","createdAt":"2021-10-28T18:01:39.947Z"},{"side":"SELL","size":"62","price":"10.793","createdAt":"2021-10-28T18:01:39.873Z"},{"side":"SELL","size":"120","price":"10.793","createdAt":"2021-10-28T18:01:39.861Z"},{"side":"SELL","size":"106","price":"10.793","createdAt":"2021-10-28T18:01:39.847Z"},{"side":"SELL","size":"119","price":"10.793","createdAt":"2021-10-28T18:01:39.847Z"},{"side":"SELL","size":"253","price":"10.793","createdAt":"2021-10-28T18:01:39.849Z"},{"side":"SELL","size":"52","price":"10.793","createdAt":"2021-10-28T18:01:39.848Z"},{"side":"SELL","size":"372.9","price":"10.796","createdAt":"2021-10-28T18:01:39.804Z"},{"side":"SELL","size":"185.2","price":"10.797","createdAt":"2021-10-28T18:01:39.804Z"},{"side":"SELL","size":"81.9","price":"10.797","createdAt":"2021-10-28T18:01:39.804Z"},{"side":"SELL","size":"290.9","price":"10.797","createdAt":"2021-10-28T18:01:39.766Z"},{"side":"SELL","size":"9","price":"10.801","createdAt":"2021-10-28T18:01:26.158Z"},{"side":"SELL","size":"9","price":"10.805","createdAt":"2021-10-28T18:01:19.902Z"},{"side":"SELL","size":"9","price":"10.805","createdAt":"2021-10-28T18:01:16.427Z"},{"side":"BUY","size":"9","price":"10.805","createdAt":"2021-10-28T18:01:10.599Z"},{"side":"SELL","size":"9","price":"10.805","createdAt":"2021-10-28T18:01:04.026Z"},{"side":"SELL","size":"3","price":"10.804","createdAt":"2021-10-28T18:01:02.818Z"},{"side":"SELL","size":"15","price":"10.804","createdAt":"2021-10-28T18:01:02.818Z"},{"side":"SELL","size":"21","price":"10.806","createdAt":"2021-10-28T18:01:02.818Z"},{"side":"SELL","size":"9","price":"10.806","createdAt":"2021-10-28T18:01:02.491Z"},{"side":"SELL","size":"9","price":"10.809","createdAt":"2021-10-28T18:01:01.575Z"},{"side":"SELL","size":"9","price":"10.811","createdAt":"2021-10-28T18:00:57.325Z"},{"side":"BUY","size":"9","price":"10.812","createdAt":"2021-10-28T18:00:54.575Z"},{"side":"SELL","size":"9","price":"10.809","createdAt":"2021-10-28T18:00:51.159Z"},{"side":"SELL","size":"176","price":"10.81","createdAt":"2021-10-28T18:00:35.119Z"},{"side":"SELL","size":"9","price":"10.81","createdAt":"2021-10-28T18:00:33.457Z"},{"side":"SELL","size":"9","price":"10.815","createdAt":"2021-10-28T18:00:27.234Z"},{"side":"SELL","size":"9","price":"10.817","createdAt":"2021-10-28T18:00:26.075Z"},{"side":"SELL","size":"27","price":"10.816","createdAt":"2021-10-28T18:00:02.204Z"},{"side":"BUY","size":"138","price":"10.821","createdAt":"2021-10-28T17:59:57.177Z"},{"side":"BUY","size":"68","price":"10.821","createdAt":"2021-10-28T17:59:57.159Z"},{"side":"BUY","size":"49","price":"10.821","createdAt":"2021-10-28T17:59:57.129Z"}]}}
1635444230.868233: {"type":"subscribed","connection_id":"60a4fc71-1312-4830-86f4-9eb98be106ac","message_id":16,"channel":"v3_trades","id":"UNI-USD","contents":{"trades":[{"side":"BUY","size":"10","price":"25.03","createdAt":"2021-10-28T18:02:48.076Z"},{"side":"BUY","size":"91","price":"25.03","createdAt":"2021-10-28T18:01:57.147Z"},{"side":"BUY","size":"97","price":"25.046","createdAt":"2021-10-28T18:00:41.102Z"},{"side":"BUY","size":"10","price":"25.077","createdAt":"2021-10-28T18:00:13.003Z"},{"side":"BUY","size":"10","price":"25.085","createdAt":"2021-10-28T17:59:36.503Z"},{"side":"SELL","size":"3","price":"25.131","createdAt":"2021-10-28T17:57:41.548Z"},{"side":"SELL","size":"3","price":"25.136","createdAt":"2021-10-28T17:57:20.739Z"},{"side":"SELL","size":"3","price":"25.127","createdAt":"2021-10-28T17:57:13.673Z"},{"side":"SELL","size":"3","price":"25.127","createdAt":"2021-10-28T17:57:06.342Z"},{"side":"SELL","size":"5","price":"25.127","createdAt":"2021-10-28T17:57:06.300Z"},{"side":"SELL","size":"1.9","price":"25.127","createdAt":"2021-10-28T17:57:04.999Z"},{"side":"SELL","size":"2.7","price":"25.132","createdAt":"2021-10-28T17:56:55.812Z"},{"side":"SELL","size":"5","price":"25.138","createdAt":"2021-10-28T17:56:51.363Z"},{"side":"SELL","size":"3","price":"25.138","createdAt":"2021-10-28T17:56:49.126Z"},{"side":"BUY","size":"3","price":"25.134","createdAt":"2021-10-28T17:55:51.050Z"},{"side":"BUY","size":"3","price":"25.083","createdAt":"2021-10-28T17:54:42.752Z"},{"side":"SELL","size":"3","price":"25.113","createdAt":"2021-10-28T17:51:55.441Z"},{"side":"SELL","size":"3","price":"25.116","createdAt":"2021-10-28T17:50:17.302Z"},{"side":"SELL","size":"3","price":"25.127","createdAt":"2021-10-28T17:49:16.553Z"},{"side":"SELL","size":"3","price":"25.138","createdAt":"2021-10-28T17:49:05.587Z"},{"side":"SELL","size":"3","price":"25.171","createdAt":"2021-10-28T17:48:25.215Z"},{"side":"SELL","size":"156.4","price":"25.171","createdAt":"2021-10-28T17:48:22.478Z"},{"side":"SELL","size":"3","price":"25.166","createdAt":"2021-10-28T17:47:44.472Z"},{"side":"SELL","size":"2.7","price":"25.182","createdAt":"2021-10-28T17:43:57.432Z"},{"side":"BUY","size":"6.4","price":"25.179","createdAt":"2021-10-28T17:43:54.079Z"},{"side":"BUY","size":"39","price":"25.171","createdAt":"2021-10-28T17:43:54.034Z"},{"side":"BUY","size":"59.6","price":"25.171","createdAt":"2021-10-28T17:43:53.753Z"},{"side":"BUY","size":"8.7","price":"25.171","createdAt":"2021-10-28T17:43:53.720Z"},{"side":"BUY","size":"7","price":"25.171","createdAt":"2021-10-28T17:43:53.641Z"},{"side":"BUY","size":"125.4","price":"25.174","createdAt":"2021-10-28T17:41:24.112Z"},{"side":"SELL","size":"73.2","price":"25.153","createdAt":"2021-10-28T17:39:43.934Z"},{"side":"SELL","size":"5","price":"25.174","createdAt":"2021-10-28T17:39:27.654Z"},{"side":"SELL","size":"5","price":"25.174","createdAt":"2021-10-28T17:39:26.462Z"},{"side":"SELL","size":"3","price":"25.167","createdAt":"2021-10-28T17:35:21.610Z"},{"side":"BUY","size":"3","price":"25.154","createdAt":"2021-10-28T17:33:22.487Z"},{"side":"BUY","size":"5","price":"25.125","createdAt":"2021-10-28T17:33:00.953Z"},{"side":"BUY","size":"3","price":"25.125","createdAt":"2021-10-28T17:33:00.977Z"},{"side":"BUY","size":"5","price":"25.125","createdAt":"2021-10-28T17:33:00.885Z"},{"side":"BUY","size":"114","price":"25.15","createdAt":"2021-10-28T17:32:38.931Z"},{"side":"SELL","size":"4","price":"25.196","createdAt":"2021-10-28T17:31:54.591Z"},{"side":"SELL","size":"1","price":"25.196","createdAt":"2021-10-28T17:31:14.558Z"},{"side":"BUY","size":"6","price":"25.257","createdAt":"2021-10-28T17:29:37.056Z"},{"side":"SELL","size":"4","price":"25.245","createdAt":"2021-10-28T17:27:58.836Z"},{"side":"BUY","size":"15","price":"25.246","createdAt":"2021-10-28T17:27:50.371Z"},{"side":"BUY","size":"1","price":"25.226","createdAt":"2021-10-28T17:27:43.208Z"},{"side":"BUY","size":"3","price":"25.226","createdAt":"2021-10-28T17:27:43.026Z"},{"side":"SELL","size":"3.8","price":"25.221","createdAt":"2021-10-28T17:27:37.957Z"},{"side":"SELL","size":"4","price":"25.226","createdAt":"2021-10-28T17:27:04.125Z"},{"side":"SELL","size":"120","price":"25.234","createdAt":"2021-10-28T17:27:01.714Z"},{"side":"SELL","size":"1","price":"25.234","createdAt":"2021-10-28T17:26:58.241Z"},{"side":"SELL","size":"3","price":"25.242","createdAt":"2021-10-28T17:26:58.241Z"},{"side":"BUY","size":"3","price":"25.232","createdAt":"2021-10-28T17:26:54.859Z"},{"side":"BUY","size":"21.7","price":"25.232","createdAt":"2021-10-28T17:26:54.742Z"},{"side":"BUY","size":"101.8","price":"25.224","createdAt":"2021-10-28T17:26:54.401Z"},{"side":"BUY","size":"4","price":"25.186","createdAt":"2021-10-28T17:26:34.998Z"},{"side":"BUY","size":"1","price":"25.181","createdAt":"2021-10-28T17:26:32.210Z"},{"side":"BUY","size":"3","price":"25.181","createdAt":"2021-10-28T17:26:32.044Z"},{"side":"SELL","size":"4","price":"25.193","createdAt":"2021-10-28T17:26:05.185Z"},{"side":"SELL","size":"4","price":"25.179","createdAt":"2021-10-28T17:24:38.260Z"},{"side":"SELL","size":"2.6","price":"25.184","createdAt":"2021-10-28T17:24:06.323Z"},{"side":"SELL","size":"91","price":"25.166","createdAt":"2021-10-28T17:22:48.870Z"},{"side":"SELL","size":"31.4","price":"25.151","createdAt":"2021-10-28T17:22:37.266Z"},{"side":"SELL","size":"59.6","price":"25.151","createdAt":"2021-10-28T17:22:37.266Z"},{"side":"SELL","size":"4","price":"25.151","createdAt":"2021-10-28T17:22:17.425Z"},{"side":"SELL","size":"3.8","price":"25.151","createdAt":"2021-10-28T17:22:12.791Z"},{"side":"BUY","size":"4","price":"25.133","createdAt":"2021-10-28T17:21:57.907Z"},{"side":"SELL","size":"4","price":"25.147","createdAt":"2021-10-28T17:21:48.036Z"},{"side":"SELL","size":"4","price":"25.147","createdAt":"2021-10-28T17:21:44.721Z"},{"side":"SELL","size":"4","price":"25.147","createdAt":"2021-10-28T17:21:30.343Z"},{"side":"SELL","size":"5","price":"25.144","createdAt":"2021-10-28T17:20:56.025Z"},{"side":"SELL","size":"5","price":"25.144","createdAt":"2021-10-28T17:20:40.450Z"},{"side":"SELL","size":"5","price":"25.144","createdAt":"2021-10-28T17:20:35.731Z"},{"side":"SELL","size":"4","price":"25.108","createdAt":"2021-10-28T17:20:06.292Z"},{"side":"BUY","size":"4","price":"25.109","createdAt":"2021-10-28T17:19:58.966Z"},{"side":"BUY","size":"2.8","price":"25.105","createdAt":"2021-10-28T17:19:56.240Z"},{"side":"BUY","size":"1.2","price":"25.105","createdAt":"2021-10-28T17:19:45.111Z"},{"side":"BUY","size":"4","price":"25.109","createdAt":"2021-10-28T17:18:36.099Z"},{"side":"SELL","size":"4","price":"25.098","createdAt":"2021-10-28T17:17:37.278Z"},{"side":"SELL","size":"4","price":"25.099","createdAt":"2021-10-28T17:17:29.573Z"},{"side":"SELL","size":"4","price":"25.111","createdAt":"2021-10-28T17:17:27.472Z"},{"side":"BUY","size":"5","price":"25.121","createdAt":"2021-10-28T17:17:15.423Z"},{"side":"SELL","size":"4","price":"25.098","createdAt":"2021-10-28T17:17:01.370Z"},{"side":"SELL","size":"4","price":"25.098","createdAt":"2021-10-28T17:16:25.774Z"},{"side":"BUY","size":"6","price":"25.095","createdAt":"2021-10-28T17:16:17.843Z"},{"side":"BUY","size":"11","price":"25.093","createdAt":"2021-10-28T17:15:53.425Z"},{"side":"SELL","size":"4","price":"25.085","createdAt":"2021-10-28T17:15:42.428Z"},{"side":"BUY","size":"69","price":"25.102","createdAt":"2021-10-28T17:15:30.316Z"},{"side":"BUY","size":"73.4","price":"25.102","createdAt":"2021-10-28T17:15:30.081Z"},{"side":"BUY","size":"25.1","price":"25.11","createdAt":"2021-10-28T17:15:29.641Z"},{"side":"BUY","size":"69","price":"25.11","createdAt":"2021-10-28T17:15:29.627Z"},{"side":"BUY","size":"53.9","price":"25.085","createdAt":"2021-10-28T17:15:24.755Z"},{"side":"BUY","size":"31.2","price":"25.075","createdAt":"2021-10-28T17:15:23.911Z"},{"side":"BUY","size":"36.3","price":"25.075","createdAt":"2021-10-28T17:15:23.891Z"},{"side":"BUY","size":"4","price":"25.066","createdAt":"2021-10-28T17:15:23.891Z"},{"side":"BUY","size":"2","price":"25.066","createdAt":"2021-10-28T17:15:23.891Z"},{"side":"BUY","size":"1","price":"25.065","createdAt":"2021-10-28T17:15:21.364Z"},{"side":"BUY","size":"4","price":"25.052","createdAt":"2021-10-28T17:15:21.364Z"},{"side":"BUY","size":"1","price":"25.052","createdAt":"2021-10-28T17:15:21.148Z"},{"side":"BUY","size":"4","price":"25.052","createdAt":"2021-10-28T17:15:21.148Z"},{"side":"SELL","size":"5","price":"25.049","createdAt":"2021-10-28T17:15:13.631Z"}]}}
1635444230.868547: {"type":"subscribed","connection_id":"60a4fc71-1312-4830-86f4-9eb98be106ac","message_id":17,"channel":"v3_trades","id":"CRV-USD","contents":{"trades":[{"side":"BUY","size":"1000","price":"4.849","createdAt":"2021-10-28T18:03:32.294Z"},{"side":"BUY","size":"246","price":"4.849","createdAt":"2021-10-28T18:03:32.294Z"},{"side":"BUY","size":"286","price":"4.85","createdAt":"2021-10-28T18:03:20.761Z"},{"side":"BUY","size":"402","price":"4.85","createdAt":"2021-10-28T18:03:20.696Z"},{"side":"BUY","size":"189","price":"4.85","createdAt":"2021-10-28T18:03:20.680Z"},{"side":"BUY","size":"824","price":"4.85","createdAt":"2021-10-28T18:03:20.675Z"},{"side":"BUY","size":"246","price":"4.844","createdAt":"2021-10-28T18:03:20.477Z"},{"side":"BUY","size":"474","price":"4.843","createdAt":"2021-10-28T18:02:39.202Z"},{"side":"BUY","size":"246","price":"4.843","createdAt":"2021-10-28T18:02:39.141Z"},{"side":"BUY","size":"280","price":"4.843","createdAt":"2021-10-28T18:02:38.580Z"},{"side":"BUY","size":"246","price":"4.843","createdAt":"2021-10-28T18:02:38.162Z"},{"side":"SELL","size":"335","price":"4.851","createdAt":"2021-10-28T18:02:07.744Z"},{"side":"BUY","size":"51","price":"4.851","createdAt":"2021-10-28T18:02:01.050Z"},{"side":"SELL","size":"476","price":"4.846","createdAt":"2021-10-28T18:01:47.477Z"},{"side":"BUY","size":"340","price":"4.846","createdAt":"2021-10-28T18:01:35.090Z"},{"side":"BUY","size":"195","price":"4.851","createdAt":"2021-10-28T18:01:16.787Z"},{"side":"BUY","size":"280","price":"4.846","createdAt":"2021-10-28T18:01:16.787Z"},{"side":"BUY","size":"200","price":"4.846","createdAt":"2021-10-28T18:01:16.704Z"},{"side":"BUY","size":"245","price":"4.846","createdAt":"2021-10-28T18:01:16.692Z"},{"side":"BUY","size":"275","price":"4.846","createdAt":"2021-10-28T18:01:15.513Z"},{"side":"BUY","size":"307","price":"4.846","createdAt":"2021-10-28T18:01:10.774Z"},{"side":"BUY","size":"475","price":"4.846","createdAt":"2021-10-28T18:01:10.164Z"},{"side":"BUY","size":"218","price":"4.846","createdAt":"2021-10-28T18:01:10.151Z"},{"side":"BUY","size":"101","price":"4.846","createdAt":"2021-10-28T18:01:10.151Z"},{"side":"BUY","size":"145","price":"4.846","createdAt":"2021-10-28T18:01:10.137Z"},{"side":"BUY","size":"246","price":"4.846","createdAt":"2021-10-28T18:00:56.464Z"},{"side":"BUY","size":"1000","price":"4.846","createdAt":"2021-10-28T18:00:56.464Z"},{"side":"BUY","size":"754","price":"4.846","createdAt":"2021-10-28T18:00:56.009Z"},{"side":"BUY","size":"246","price":"4.846","createdAt":"2021-10-28T18:00:55.952Z"},{"side":"BUY","size":"1000","price":"4.846","createdAt":"2021-10-28T18:00:55.028Z"},{"side":"BUY","size":"246","price":"4.846","createdAt":"2021-10-28T18:00:55.028Z"},{"side":"BUY","size":"1000","price":"4.846","createdAt":"2021-10-28T18:00:54.205Z"},{"side":"BUY","size":"268","price":"4.851","createdAt":"2021-10-28T18:00:54.049Z"},{"side":"BUY","size":"181","price":"4.851","createdAt":"2021-10-28T18:00:54.049Z"},{"side":"BUY","size":"46","price":"4.851","createdAt":"2021-10-28T18:00:54.038Z"},{"side":"BUY","size":"227","price":"4.848","createdAt":"2021-10-28T18:00:54.038Z"},{"side":"BUY","size":"246","price":"4.846","createdAt":"2021-10-28T18:00:54.038Z"},{"side":"BUY","size":"378","price":"4.847","createdAt":"2021-10-28T18:00:53.002Z"},{"side":"BUY","size":"163","price":"4.847","createdAt":"2021-10-28T18:00:52.874Z"},{"side":"BUY","size":"28","price":"4.847","createdAt":"2021-10-28T18:00:52.840Z"},{"side":"BUY","size":"97","price":"4.841","createdAt":"2021-10-28T18:00:52.840Z"},{"side":"BUY","size":"149","price":"4.841","createdAt":"2021-10-28T18:00:52.823Z"},{"side":"BUY","size":"297","price":"4.843","createdAt":"2021-10-28T18:00:34.304Z"},{"side":"BUY","size":"1034","price":"4.843","createdAt":"2021-10-28T18:00:34.304Z"},{"side":"BUY","size":"149","price":"4.842","createdAt":"2021-10-28T18:00:34.304Z"},{"side":"BUY","size":"2095","price":"4.842","createdAt":"2021-10-28T18:00:34.304Z"},{"side":"BUY","size":"682","price":"4.842","createdAt":"2021-10-28T18:00:34.304Z"},{"side":"BUY","size":"620","price":"4.842","createdAt":"2021-10-28T18:00:34.304Z"},{"side":"BUY","size":"1000","price":"4.841","createdAt":"2021-10-28T18:00:34.304Z"},{"side":"BUY","size":"475","price":"4.847","createdAt":"2021-10-28T18:00:18.773Z"},{"side":"BUY","size":"6","price":"4.847","createdAt":"2021-10-28T18:00:18.773Z"},{"side":"BUY","size":"145","price":"4.846","createdAt":"2021-10-28T18:00:18.773Z"},{"side":"SELL","size":"27","price":"4.837","createdAt":"2021-10-28T17:59:52.562Z"},{"side":"SELL","size":"310","price":"4.838","createdAt":"2021-10-28T17:59:52.562Z"},{"side":"SELL","size":"227","price":"4.838","createdAt":"2021-10-28T17:59:52.562Z"},{"side":"BUY","size":"477","price":"4.837","createdAt":"2021-10-28T17:59:37.249Z"},{"side":"BUY","size":"38","price":"4.837","createdAt":"2021-10-28T17:59:37.233Z"},{"side":"BUY","size":"483","price":"4.836","createdAt":"2021-10-28T17:59:37.233Z"},{"side":"BUY","size":"133","price":"4.836","createdAt":"2021-10-28T17:59:37.207Z"},{"side":"BUY","size":"348","price":"4.836","createdAt":"2021-10-28T17:59:37.192Z"},{"side":"BUY","size":"36","price":"4.836","createdAt":"2021-10-28T17:59:37.181Z"},{"side":"BUY","size":"246","price":"4.836","createdAt":"2021-10-28T17:59:37.181Z"},{"side":"BUY","size":"490","price":"4.835","createdAt":"2021-10-28T17:59:26.256Z"},{"side":"SELL","size":"520","price":"4.833","createdAt":"2021-10-28T17:59:21.390Z"},{"side":"SELL","size":"381","price":"4.834","createdAt":"2021-10-28T17:59:21.332Z"},{"side":"SELL","size":"227","price":"4.838","createdAt":"2021-10-28T17:59:21.332Z"},{"side":"SELL","size":"226","price":"4.849","createdAt":"2021-10-28T17:59:04.999Z"},{"side":"SELL","size":"684","price":"4.85","createdAt":"2021-10-28T17:59:03.416Z"},{"side":"SELL","size":"347","price":"4.85","createdAt":"2021-10-28T17:59:03.202Z"},{"side":"SELL","size":"264","price":"4.853","createdAt":"2021-10-28T17:59:03.074Z"},{"side":"SELL","size":"355","price":"4.853","createdAt":"2021-10-28T17:59:03.004Z"},{"side":"BUY","size":"7","price":"4.861","createdAt":"2021-10-28T17:59:02.248Z"},{"side":"BUY","size":"169","price":"4.859","createdAt":"2021-10-28T17:59:02.248Z"},{"side":"SELL","size":"572","price":"4.859","createdAt":"2021-10-28T17:58:40.444Z"},{"side":"SELL","size":"680","price":"4.859","createdAt":"2021-10-28T17:58:40.444Z"},{"side":"SELL","size":"226","price":"4.862","createdAt":"2021-10-28T17:58:40.403Z"},{"side":"SELL","size":"1445","price":"4.863","createdAt":"2021-10-28T17:58:21.354Z"},{"side":"SELL","size":"560","price":"4.871","createdAt":"2021-10-28T17:57:02.863Z"},{"side":"SELL","size":"604","price":"4.871","createdAt":"2021-10-28T17:57:02.849Z"},{"side":"SELL","size":"406","price":"4.871","createdAt":"2021-10-28T17:57:02.851Z"},{"side":"SELL","size":"154","price":"4.873","createdAt":"2021-10-28T17:57:02.851Z"},{"side":"BUY","size":"189","price":"4.883","createdAt":"2021-10-28T17:56:07.959Z"},{"side":"BUY","size":"23","price":"4.883","createdAt":"2021-10-28T17:56:07.929Z"},{"side":"BUY","size":"139","price":"4.877","createdAt":"2021-10-28T17:56:07.929Z"},{"side":"BUY","size":"107","price":"4.877","createdAt":"2021-10-28T17:56:05.820Z"},{"side":"SELL","size":"553","price":"4.877","createdAt":"2021-10-28T17:55:55.350Z"},{"side":"SELL","size":"472","price":"4.877","createdAt":"2021-10-28T17:55:54.949Z"},{"side":"BUY","size":"447","price":"4.884","createdAt":"2021-10-28T17:54:59.146Z"},{"side":"BUY","size":"246","price":"4.883","createdAt":"2021-10-28T17:54:59.096Z"},{"side":"BUY","size":"226","price":"4.883","createdAt":"2021-10-28T17:54:59.096Z"},{"side":"BUY","size":"138","price":"4.881","createdAt":"2021-10-28T17:54:59.058Z"},{"side":"BUY","size":"290","price":"4.88","createdAt":"2021-10-28T17:54:58.995Z"},{"side":"BUY","size":"411","price":"4.88","createdAt":"2021-10-28T17:54:58.990Z"},{"side":"BUY","size":"57","price":"4.88","createdAt":"2021-10-28T17:54:58.983Z"},{"side":"BUY","size":"152","price":"4.879","createdAt":"2021-10-28T17:54:58.983Z"},{"side":"BUY","size":"5","price":"4.877","createdAt":"2021-10-28T17:54:53.974Z"},{"side":"BUY","size":"161","price":"4.877","createdAt":"2021-10-28T17:54:53.974Z"},{"side":"BUY","size":"118","price":"4.874","createdAt":"2021-10-28T17:54:53.974Z"},{"side":"BUY","size":"128","price":"4.874","createdAt":"2021-10-28T17:54:53.761Z"},{"side":"SELL","size":"378","price":"4.873","createdAt":"2021-10-28T17:54:45.417Z"}]}}
1635444230.86885: {"type":"subscribed","connection_id":"60a4fc71-1312-4830-86f4-9eb98be106ac","message_id":18,"channel":"v3_trades","id":"BCH-USD","contents":{"trades":[{"side":"SELL","size":"0.2","price":"574.7","createdAt":"2021-10-28T18:03:27.172Z"},{"side":"SELL","size":"0.1","price":"574.7","createdAt":"2021-10-28T18:03:27.063Z"},{"side":"BUY","size":"3.51","price":"574.6","createdAt":"2021-10-28T18:03:20.955Z"},{"side":"SELL","size":"0.2","price":"573.7","createdAt":"2021-10-28T18:02:35.360Z"},{"side":"SELL","size":"0.2","price":"573.7","createdAt":"2021-10-28T18:02:26.000Z"},{"side":"SELL","size":"1.12","price":"574.4","createdAt":"2021-10-28T18:01:48.012Z"},{"side":"SELL","size":"0.1","price":"574.4","createdAt":"2021-10-28T18:01:47.889Z"},{"side":"SELL","size":"2.37","price":"574.4","createdAt":"2021-10-28T18:01:47.811Z"},{"side":"SELL","size":"1.3","price":"574.4","createdAt":"2021-10-28T18:01:47.736Z"},{"side":"SELL","size":"0.27","price":"574.4","createdAt":"2021-10-28T18:01:47.447Z"},{"side":"SELL","size":"0.1","price":"574.5","createdAt":"2021-10-28T18:01:27.578Z"},{"side":"SELL","size":"0.1","price":"574.5","createdAt":"2021-10-28T18:00:50.246Z"},{"side":"SELL","size":"0.1","price":"574.5","createdAt":"2021-10-28T18:00:47.972Z"},{"side":"SELL","size":"1.78","price":"574.8","createdAt":"2021-10-28T18:00:42.002Z"},{"side":"SELL","size":"0.1","price":"574.8","createdAt":"2021-10-28T18:00:41.957Z"},{"side":"SELL","size":"0.1","price":"574.8","createdAt":"2021-10-28T18:00:40.180Z"},{"side":"SELL","size":"0.1","price":"574.8","createdAt":"2021-10-28T18:00:30.078Z"},{"side":"SELL","size":"0.1","price":"574.9","createdAt":"2021-10-28T18:00:26.072Z"},{"side":"SELL","size":"1.02","price":"575","createdAt":"2021-10-28T18:00:25.355Z"},{"side":"SELL","size":"0.2","price":"575.5","createdAt":"2021-10-28T18:00:24.926Z"},{"side":"SELL","size":"0.1","price":"575.5","createdAt":"2021-10-28T18:00:24.860Z"},{"side":"SELL","size":"0.2","price":"575.5","createdAt":"2021-10-28T18:00:23.082Z"},{"side":"SELL","size":"1.74","price":"575.7","createdAt":"2021-10-28T18:00:19.932Z"},{"side":"SELL","size":"0.1","price":"575.7","createdAt":"2021-10-28T18:00:15.094Z"},{"side":"SELL","size":"0.24","price":"575.7","createdAt":"2021-10-28T18:00:14.889Z"},{"side":"SELL","size":"0.1","price":"575.8","createdAt":"2021-10-28T17:59:43.070Z"},{"side":"SELL","size":"1","price":"576.1","createdAt":"2021-10-28T17:59:32.382Z"},{"side":"SELL","size":"0.1","price":"576.1","createdAt":"2021-10-28T17:59:32.263Z"},{"side":"SELL","size":"1.12","price":"576.1","createdAt":"2021-10-28T17:59:31.953Z"},{"side":"SELL","size":"0.1","price":"576.4","createdAt":"2021-10-28T17:59:18.916Z"},{"side":"SELL","size":"0.86","price":"576.5","createdAt":"2021-10-28T17:59:15.852Z"},{"side":"SELL","size":"0.1","price":"576.5","createdAt":"2021-10-28T17:59:12.750Z"},{"side":"SELL","size":"1.12","price":"576.5","createdAt":"2021-10-28T17:59:12.527Z"},{"side":"SELL","size":"0.18","price":"576.4","createdAt":"2021-10-28T17:57:15.754Z"},{"side":"SELL","size":"0.1","price":"576.4","createdAt":"2021-10-28T17:56:02.140Z"},{"side":"SELL","size":"0.1","price":"576.5","createdAt":"2021-10-28T17:55:54.788Z"},{"side":"SELL","size":"0.1","price":"576.2","createdAt":"2021-10-28T17:55:37.963Z"},{"side":"SELL","size":"0.1","price":"576.3","createdAt":"2021-10-28T17:55:33.130Z"},{"side":"SELL","size":"0.1","price":"575.9","createdAt":"2021-10-28T17:55:05.172Z"},{"side":"SELL","size":"0.1","price":"576","createdAt":"2021-10-28T17:55:02.118Z"},{"side":"BUY","size":"0.1","price":"575.8","createdAt":"2021-10-28T17:55:00.674Z"},{"side":"SELL","size":"0.2","price":"575.6","createdAt":"2021-10-28T17:54:48.711Z"},{"side":"SELL","size":"0.1","price":"575.2","createdAt":"2021-10-28T17:54:24.544Z"},{"side":"BUY","size":"50.06","price":"575.1","createdAt":"2021-10-28T17:53:55.977Z"},{"side":"BUY","size":"49.76","price":"575.1","createdAt":"2021-10-28T17:53:55.019Z"},{"side":"BUY","size":"0.1","price":"575.1","createdAt":"2021-10-28T17:53:55.019Z"},{"side":"BUY","size":"0.2","price":"575.1","createdAt":"2021-10-28T17:53:55.019Z"},{"side":"SELL","size":"6.07","price":"575.2","createdAt":"2021-10-28T17:53:52.194Z"},{"side":"SELL","size":"0.1","price":"575.4","createdAt":"2021-10-28T17:53:50.646Z"},{"side":"SELL","size":"0.1","price":"575.4","createdAt":"2021-10-28T17:53:35.853Z"},{"side":"SELL","size":"0.1","price":"575.6","createdAt":"2021-10-28T17:53:15.090Z"},{"side":"SELL","size":"0.1","price":"575.6","createdAt":"2021-10-28T17:53:12.657Z"},{"side":"SELL","size":"0.1","price":"575.6","createdAt":"2021-10-28T17:52:58.860Z"},{"side":"SELL","size":"0.1","price":"575.7","createdAt":"2021-10-28T17:52:57.063Z"},{"side":"SELL","size":"0.1","price":"576.1","createdAt":"2021-10-28T17:52:39.465Z"},{"side":"SELL","size":"0.1","price":"576.1","createdAt":"2021-10-28T17:52:39.476Z"},{"side":"SELL","size":"0.2","price":"576.1","createdAt":"2021-10-28T17:52:39.497Z"},{"side":"SELL","size":"0.2","price":"575.8","createdAt":"2021-10-28T17:52:07.441Z"},{"side":"SELL","size":"0.1","price":"575.8","createdAt":"2021-10-28T17:52:07.107Z"},{"side":"SELL","size":"0.2","price":"575.8","createdAt":"2021-10-28T17:51:56.134Z"},{"side":"SELL","size":"0.1","price":"575.9","createdAt":"2021-10-28T17:51:55.169Z"},{"side":"SELL","size":"0.1","price":"575.9","createdAt":"2021-10-28T17:51:43.607Z"},{"side":"BUY","size":"3.65","price":"575.7","createdAt":"2021-10-28T17:51:17.052Z"},{"side":"SELL","size":"0.1","price":"575.4","createdAt":"2021-10-28T17:50:55.833Z"},{"side":"SELL","size":"0.1","price":"575.2","createdAt":"2021-10-28T17:50:36.335Z"},{"side":"SELL","size":"0.1","price":"574.8","createdAt":"2021-10-28T17:49:37.553Z"},{"side":"SELL","size":"0.1","price":"574.9","createdAt":"2021-10-28T17:49:25.931Z"},{"side":"SELL","size":"31.6","price":"575.3","createdAt":"2021-10-28T17:49:16.695Z"},{"side":"SELL","size":"3.16","price":"575.3","createdAt":"2021-10-28T17:49:16.656Z"},{"side":"SELL","size":"0.2","price":"575.3","createdAt":"2021-10-28T17:49:16.517Z"},{"side":"SELL","size":"0.1","price":"575.3","createdAt":"2021-10-28T17:49:16.477Z"},{"side":"SELL","size":"0.77","price":"575.4","createdAt":"2021-10-28T17:49:10.219Z"},{"side":"SELL","size":"0.79","price":"575.5","createdAt":"2021-10-28T17:49:03.023Z"},{"side":"SELL","size":"0.1","price":"575.5","createdAt":"2021-10-28T17:49:02.583Z"},{"side":"SELL","size":"0.1","price":"575.6","createdAt":"2021-10-28T17:48:55.896Z"},{"side":"SELL","size":"0.1","price":"575.8","createdAt":"2021-10-28T17:48:53.962Z"},{"side":"SELL","size":"1.12","price":"575.8","createdAt":"2021-10-28T17:48:53.876Z"},{"side":"SELL","size":"0.1","price":"575.8","createdAt":"2021-10-28T17:48:53.184Z"},{"side":"SELL","size":"0.2","price":"575.8","createdAt":"2021-10-28T17:48:53.038Z"},{"side":"SELL","size":"0.85","price":"576.1","createdAt":"2021-10-28T17:48:52.993Z"},{"side":"SELL","size":"1.12","price":"576.1","createdAt":"2021-10-28T17:48:52.622Z"},{"side":"SELL","size":"0.1","price":"576.1","createdAt":"2021-10-28T17:48:40.054Z"},{"side":"SELL","size":"0.95","price":"576.2","createdAt":"2021-10-28T17:48:13.799Z"},{"side":"SELL","size":"1.12","price":"576.2","createdAt":"2021-10-28T17:48:13.484Z"},{"side":"SELL","size":"0.65","price":"576.4","createdAt":"2021-10-28T17:48:11.162Z"},{"side":"SELL","size":"1.12","price":"576.4","createdAt":"2021-10-28T17:47:52.772Z"},{"side":"SELL","size":"0.1","price":"576.4","createdAt":"2021-10-28T17:47:44.425Z"},{"side":"SELL","size":"0.2","price":"576.4","createdAt":"2021-10-28T17:47:44.276Z"},{"side":"SELL","size":"0.2","price":"576.8","createdAt":"2021-10-28T17:47:02.895Z"},{"side":"SELL","size":"0.1","price":"576.9","createdAt":"2021-10-28T17:47:02.856Z"},{"side":"SELL","size":"0.2","price":"576.9","createdAt":"2021-10-28T17:46:52.978Z"},{"side":"SELL","size":"0.1","price":"576.9","createdAt":"2021-10-28T17:46:26.872Z"},{"side":"SELL","size":"0.2","price":"576.9","createdAt":"2021-10-28T17:46:26.817Z"},{"side":"SELL","size":"0.2","price":"576.4","createdAt":"2021-10-28T17:45:58.557Z"},{"side":"SELL","size":"0.1","price":"576.4","createdAt":"2021-10-28T17:45:58.350Z"},{"side":"SELL","size":"0.1","price":"576.6","createdAt":"2021-10-28T17:45:36.215Z"},{"side":"SELL","size":"50","price":"576.1","createdAt":"2021-10-28T17:44:02.042Z"},{"side":"SELL","size":"2.07","price":"575.8","createdAt":"2021-10-28T17:42:56.052Z"},{"side":"BUY","size":"50","price":"576","createdAt":"2021-10-28T17:42:48.244Z"},{"side":"BUY","size":"0.2","price":"576.2","createdAt":"2021-10-28T17:39:23.009Z"}]}}
1635444230.869139: {"type":"channel_data","connection_id":"60a4fc71-1312-4830-86f4-9eb98be106ac","message_id":32,"id":"ETH-USD","channel":"v3_orderbook","contents":{"offset":"2693988265","bids":[],"asks":[["4219.5","1.511"]]}}
1635444230.8691661: {"type":"subscribed","connection_id":"60a4fc71-1312-4830-86f4-9eb98be106ac","message_id":20,"channel":"v3_trades","id":"XMR-USD","contents":{"trades":[{"side":"SELL","size":"0.12","price":"265.2","createdAt":"2021-10-28T18:00:47.339Z"},{"side":"BUY","size":"6.18","price":"265.3","createdAt":"2021-10-28T18:00:15.350Z"},{"side":"BUY","size":"6.89","price":"265.3","createdAt":"2021-10-28T17:39:23.020Z"},{"side":"BUY","size":"6.02","price":"265.8","createdAt":"2021-10-28T17:34:42.900Z"},{"side":"BUY","size":"7.76","price":"265.3","createdAt":"2021-10-28T17:34:23.471Z"},{"side":"SELL","size":"2.86","price":"265.5","createdAt":"2021-10-28T17:34:07.258Z"},{"side":"SELL","size":"65.8","price":"265.8","createdAt":"2021-10-28T17:34:07.161Z"},{"side":"SELL","size":"5.41","price":"265.8","createdAt":"2021-10-28T17:34:07.129Z"},{"side":"SELL","size":"4.01","price":"265.8","createdAt":"2021-10-28T17:34:07.068Z"},{"side":"SELL","size":"2.92","price":"265.8","createdAt":"2021-10-28T17:34:07.068Z"},{"side":"SELL","size":"6.09","price":"265.8","createdAt":"2021-10-28T17:34:07.037Z"},{"side":"SELL","size":"266.28","price":"265.8","createdAt":"2021-10-28T17:34:06.975Z"},{"side":"SELL","size":"6.84","price":"265.8","createdAt":"2021-10-28T17:34:06.918Z"},{"side":"SELL","size":"0.01","price":"265.9","createdAt":"2021-10-28T17:34:06.918Z"},{"side":"SELL","size":"6","price":"265.9","createdAt":"2021-10-28T17:34:06.815Z"},{"side":"SELL","size":"0.18","price":"266.2","createdAt":"2021-10-28T17:32:32.555Z"},{"side":"SELL","size":"4.57","price":"266.8","createdAt":"2021-10-28T17:31:22.970Z"},{"side":"SELL","size":"7.88","price":"266.8","createdAt":"2021-10-28T17:31:22.958Z"},{"side":"SELL","size":"2.91","price":"266.8","createdAt":"2021-10-28T17:31:22.944Z"},{"side":"SELL","size":"0.45","price":"267.2","createdAt":"2021-10-28T17:27:53.499Z"},{"side":"SELL","size":"0.12","price":"267.3","createdAt":"2021-10-28T17:26:52.086Z"},{"side":"SELL","size":"57","price":"266.8","createdAt":"2021-10-28T17:20:23.487Z"},{"side":"SELL","size":"75.02","price":"266.6","createdAt":"2021-10-28T17:20:14.350Z"},{"side":"BUY","size":"3.75","price":"266.4","createdAt":"2021-10-28T17:13:50.524Z"},{"side":"BUY","size":"4.14","price":"266.3","createdAt":"2021-10-28T17:13:50.524Z"},{"side":"BUY","size":"6.66","price":"266","createdAt":"2021-10-28T17:13:50.445Z"},{"side":"BUY","size":"111.27","price":"266","createdAt":"2021-10-28T17:13:50.278Z"},{"side":"BUY","size":"101.65","price":"266","createdAt":"2021-10-28T17:13:49.602Z"},{"side":"BUY","size":"0.38","price":"265.9","createdAt":"2021-10-28T17:12:42.347Z"},{"side":"BUY","size":"0.38","price":"265.8","createdAt":"2021-10-28T17:11:09.353Z"},{"side":"BUY","size":"0.38","price":"265.8","createdAt":"2021-10-28T17:11:08.897Z"},{"side":"SELL","size":"7.11","price":"265.6","createdAt":"2021-10-28T17:11:07.595Z"},{"side":"BUY","size":"0.38","price":"265.7","createdAt":"2021-10-28T17:11:06.818Z"},{"side":"BUY","size":"3.08","price":"265.4","createdAt":"2021-10-28T17:11:06.556Z"},{"side":"BUY","size":"6.93","price":"265.4","createdAt":"2021-10-28T17:11:06.365Z"},{"side":"BUY","size":"3.39","price":"265.4","createdAt":"2021-10-28T17:11:06.378Z"},{"side":"BUY","size":"8.88","price":"265.4","createdAt":"2021-10-28T17:11:06.358Z"},{"side":"BUY","size":"7.91","price":"265.4","createdAt":"2021-10-28T17:11:06.354Z"},{"side":"BUY","size":"5.86","price":"265.3","createdAt":"2021-10-28T17:11:06.249Z"},{"side":"BUY","size":"6.04","price":"265.3","createdAt":"2021-10-28T17:11:06.155Z"},{"side":"BUY","size":"282.86","price":"265.1","createdAt":"2021-10-28T17:11:06.101Z"},{"side":"BUY","size":"68.68","price":"265","createdAt":"2021-10-28T17:11:06.101Z"},{"side":"BUY","size":"6.79","price":"265","createdAt":"2021-10-28T17:11:06.059Z"},{"side":"BUY","size":"0.38","price":"264.9","createdAt":"2021-10-28T17:09:38.932Z"},{"side":"BUY","size":"0.38","price":"264.9","createdAt":"2021-10-28T17:09:36.932Z"},{"side":"BUY","size":"0.38","price":"264.9","createdAt":"2021-10-28T17:09:34.831Z"},{"side":"BUY","size":"0.38","price":"264.9","createdAt":"2021-10-28T17:09:09.732Z"},{"side":"BUY","size":"0.38","price":"264.9","createdAt":"2021-10-28T17:08:58.540Z"},{"side":"BUY","size":"0.38","price":"265.3","createdAt":"2021-10-28T17:08:51.403Z"},{"side":"SELL","size":"4.75","price":"264.9","createdAt":"2021-10-28T17:08:36.202Z"},{"side":"SELL","size":"4.15","price":"264.9","createdAt":"2021-10-28T17:08:36.202Z"},{"side":"BUY","size":"0.38","price":"265.7","createdAt":"2021-10-28T17:08:21.729Z"},{"side":"BUY","size":"0.1","price":"265.9","createdAt":"2021-10-28T17:07:15.488Z"},{"side":"SELL","size":"6.84","price":"265.2","createdAt":"2021-10-28T17:03:47.239Z"},{"side":"SELL","size":"0.1","price":"265.3","createdAt":"2021-10-28T17:03:47.239Z"},{"side":"SELL","size":"6.12","price":"265.5","createdAt":"2021-10-28T17:03:47.053Z"},{"side":"SELL","size":"96.13","price":"265.5","createdAt":"2021-10-28T17:03:47.006Z"},{"side":"SELL","size":"1.17","price":"265.5","createdAt":"2021-10-28T17:03:46.945Z"},{"side":"SELL","size":"4.53","price":"265.5","createdAt":"2021-10-28T17:03:46.945Z"},{"side":"SELL","size":"6.47","price":"264.7","createdAt":"2021-10-28T16:59:23.912Z"},{"side":"SELL","size":"0.2","price":"264.7","createdAt":"2021-10-28T16:59:23.912Z"},{"side":"BUY","size":"0.09","price":"264.8","createdAt":"2021-10-28T16:58:39.612Z"},{"side":"BUY","size":"0.29","price":"264.8","createdAt":"2021-10-28T16:58:39.612Z"},{"side":"SELL","size":"0.06","price":"265","createdAt":"2021-10-28T16:55:40.015Z"},{"side":"SELL","size":"0.24","price":"265","createdAt":"2021-10-28T16:55:39.655Z"},{"side":"SELL","size":"0.4","price":"265.1","createdAt":"2021-10-28T16:53:57.629Z"},{"side":"BUY","size":"0.5","price":"265.3","createdAt":"2021-10-28T16:52:28.308Z"},{"side":"BUY","size":"0.4","price":"265.2","createdAt":"2021-10-28T16:47:36.621Z"},{"side":"SELL","size":"6","price":"265.1","createdAt":"2021-10-28T16:46:42.202Z"},{"side":"BUY","size":"0.5","price":"265.2","createdAt":"2021-10-28T16:42:32.871Z"},{"side":"BUY","size":"0.2","price":"264.8","createdAt":"2021-10-28T16:37:31.191Z"},{"side":"BUY","size":"0.24","price":"265.1","createdAt":"2021-10-28T16:32:51.918Z"},{"side":"BUY","size":"0.48","price":"265.3","createdAt":"2021-10-28T16:31:51.885Z"},{"side":"SELL","size":"0.29","price":"265.4","createdAt":"2021-10-28T16:30:13.164Z"},{"side":"SELL","size":"102.21","price":"265.5","createdAt":"2021-10-28T16:29:15.661Z"},{"side":"SELL","size":"7.92","price":"265.5","createdAt":"2021-10-28T16:29:15.614Z"},{"side":"BUY","size":"6.9","price":"266.2","createdAt":"2021-10-28T16:16:32.684Z"},{"side":"BUY","size":"6.06","price":"264","createdAt":"2021-10-28T16:00:17.155Z"},{"side":"BUY","size":"0.38","price":"263.8","createdAt":"2021-10-28T15:55:13.199Z"},{"side":"BUY","size":"0.38","price":"263.9","createdAt":"2021-10-28T15:55:00.453Z"},{"side":"SELL","size":"0.14","price":"263.8","createdAt":"2021-10-28T15:23:52.479Z"},{"side":"SELL","size":"70","price":"263.8","createdAt":"2021-10-28T15:22:31.659Z"},{"side":"BUY","size":"25.93","price":"264.1","createdAt":"2021-10-28T15:22:29.510Z"},{"side":"BUY","size":"38","price":"264.1","createdAt":"2021-10-28T15:22:29.510Z"},{"side":"BUY","size":"6.07","price":"263.8","createdAt":"2021-10-28T15:22:29.510Z"},{"side":"BUY","size":"0.19","price":"264","createdAt":"2021-10-28T15:15:51.798Z"},{"side":"SELL","size":"0.14","price":"264.4","createdAt":"2021-10-28T15:10:52.579Z"},{"side":"SELL","size":"0.23","price":"264.2","createdAt":"2021-10-28T15:05:52.053Z"},{"side":"SELL","size":"0.1","price":"264","createdAt":"2021-10-28T14:57:51.810Z"},{"side":"SELL","size":"0.37","price":"264","createdAt":"2021-10-28T14:26:36.155Z"},{"side":"SELL","size":"6.81","price":"263.8","createdAt":"2021-10-28T14:26:17.616Z"},{"side":"BUY","size":"22.36","price":"264.2","createdAt":"2021-10-28T14:20:01.644Z"},{"side":"BUY","size":"158.12","price":"264.2","createdAt":"2021-10-28T14:19:51.497Z"},{"side":"BUY","size":"7.52","price":"264.2","createdAt":"2021-10-28T14:19:47.164Z"},{"side":"BUY","size":"6.83","price":"264.2","createdAt":"2021-10-28T14:15:21.294Z"},{"side":"SELL","size":"124.96","price":"264.3","createdAt":"2021-10-28T14:15:10.725Z"},{"side":"SELL","size":"7.95","price":"264.3","createdAt":"2021-10-28T14:15:10.669Z"},{"side":"SELL","size":"3.56","price":"264.3","createdAt":"2021-10-28T14:15:10.647Z"},{"side":"SELL","size":"4.15","price":"264.3","createdAt":"2021-10-28T14:15:10.647Z"},{"side":"SELL","size":"6.96","price":"264.4","createdAt":"2021-10-28T14:15:10.601Z"}]}}
1635444230.869457: {"type":"channel_data","connection_id":"60a4fc71-1312-4830-86f4-9eb98be106ac","message_id":33,"id":"ETH-USD","channel":"v3_orderbook","contents":{"offset":"2693988269","bids":[],"asks":[["4219.5","0"]]}}
1635444230.869479: {"type":"channel_data","connection_id":"60a4fc71-1312-4830-86f4-9eb98be106ac","message_id":34,"id":"ETH-USD","channel":"v3_orderbook","contents":{"offset":"2693988272","bids":[["4213.5","7.216"]],"asks":[]}}
1635444230.869497: {"type":"channel_data","connection_id":"60a4fc71-1312-4830-86f4-9eb98be106ac","message_id":35,"id":"ETH-USD","channel":"v3_orderbook","contents":{"offset":"2693988276","bids":[],"asks":[["4217.3","1908.604"]]}}
1635444230.869513: {"type":"channel_data","connection_id":"60a4fc71-1312-4830-86f4-9eb98be106ac","message_id":36,"id":"ETH-USD","channel":"v3_orderbook","contents":{"offset":"2693988273","bids":[],"asks":[["4221.7","0"]]}}
1635444230.869529: {"type":"channel_data","connection_id":"60a4fc71-1312-4830-86f4-9eb98be106ac","message_id":37,"id":"ETH-USD","channel":"v3_orderbook","contents":{"offset":"2693988278","bids":[],"asks":[["4216.1","10"]]}}
1635444230.8695428: {"type":"channel_data","connection_id":"60a4fc71-1312-4830-86f4-9eb98be106ac","message_id":38,"id":"ETH-USD","channel":"v3_orderbook","contents":{"offset":"2693988285","bids":[],"asks":[["4217.8","3.556"]]}}
1635444230.869557: {"type":"channel_data","connection_id":"60a4fc71-1312-4830-86f4-9eb98be106ac","message_id":39,"id":"UNI-USD","channel":"v3_orderbook","contents":{"offset":"2693988287","bids":[],"asks":[["25.068","0"]]}}
1635444230.870778: {"type":"channel_data","connection_id":"60a4fc71-1312-4830-86f4-9eb98be106ac","message_id":40,"id":"ETH-USD","channel":"v3_orderbook","contents":{"offset":"2693988291","bids":[],"asks":[["4215.6","9.5"]]}}
1635444230.870815: {"type":"channel_data","connection_id":"60a4fc71-1312-4830-86f4-9eb98be106ac","message_id":41,"id":"LTC-USD","channel":"v3_orderbook","contents":{"offset":"2693988296","bids":[["186.8","798.1"],["186.7","133.01"]],"asks":[]}}
1635444230.8713758: {"type":"channel_data","connection_id":"60a4fc71-1312-4830-86f4-9eb98be106ac","message_id":42,"id":"ETH-USD","channel":"v3_orderbook","contents":{"offset":"2693988294","bids":[["4213.7","0"]],"asks":[]}}
1635444230.876229: {"type":"channel_data","connection_id":"60a4fc71-1312-4830-86f4-9eb98be106ac","message_id":43,"id":"ETH-USD","channel":"v3_orderbook","contents":{"offset":"2693988297","bids":[],"asks":[["4218.5","4462.23"]]}}
1635444230.8814342: {"type":"channel_data","connection_id":"60a4fc71-1312-4830-86f4-9eb98be106ac","message_id":44,"id":"SUSHI-USD","channel":"v3_orderbook","contents":{"offset":"2693988309","bids":[],"asks":[["10.793","4141.3"]]}}
1635444230.887282: {"type":"channel_data","connection_id":"60a4fc71-1312-4830-86f4-9eb98be106ac","message_id":45,"id":"SUSHI-USD","channel":"v3_orderbook","contents":{"offset":"2693988310","bids":[["10.781","0"]],"asks":[]}}
1635444230.905192: {"type":"channel_data","connection_id":"60a4fc71-1312-4830-86f4-9eb98be106ac","message_id":46,"id":"UMA-USD","channel":"v3_orderbook","contents":{"offset":"2693988318","bids":[],"asks":[["11.31","13443.8"]]}}
1635444230.909428: {"type":"channel_data","connection_id":"60a4fc71-1312-4830-86f4-9eb98be106ac","message_id":47,"id":"SUSHI-USD","channel":"v3_orderbook","contents":{"offset":"2693988316","bids":[],"asks":[["10.791","3707"]]}}
1635444230.917633: {"type":"channel_data","connection_id":"60a4fc71-1312-4830-86f4-9eb98be106ac","message_id":48,"id":"ETH-USD","channel":"v3_orderbook","contents":{"offset":"2693988330","bids":[],"asks":[["4227.3","0.8"]]}}
1635444230.917712: {"type":"channel_data","connection_id":"60a4fc71-1312-4830-86f4-9eb98be106ac","message_id":49,"id":"ETH-USD","channel":"v3_orderbook","contents":{"offset":"2693988328","bids":[],"asks":[["4216.7","58.403"]]}}
1635444230.918273: {"type":"channel_data","connection_id":"60a4fc71-1312-4830-86f4-9eb98be106ac","message_id":50,"id":"ETH-USD","channel":"v3_orderbook","contents":{"offset":"2693988336","bids":[],"asks":[["4216.1","33.736"]]}}
1635444230.93089: {"type":"channel_data","connection_id":"60a4fc71-1312-4830-86f4-9eb98be106ac","message_id":51,"id":"ETH-USD","channel":"v3_orderbook","contents":{"offset":"2693988349","bids":[],"asks":[["4216.4","47.471"]]}}
1635444230.93096: {"type":"channel_data","connection_id":"60a4fc71-1312-4830-86f4-9eb98be106ac","message_id":52,"id":"UMA-USD","channel":"v3_orderbook","contents":{"offset":"2693988355","bids":[],"asks":[["11.34","529.9"]]}}
1635444230.930988: {"type":"channel_data","connection_id":"60a4fc71-1312-4830-86f4-9eb98be106ac","message_id":53,"id":"ETH-USD","channel":"v3_orderbook","contents":{"offset":"2693988352","bids":[["4208.7","11.25"]],"asks":[]}}
1635444230.9328058: {"type":"channel_data","connection_id":"60a4fc71-1312-4830-86f4-9eb98be106ac","message_id":54,"id":"ETH-USD","channel":"v3_orderbook","contents":{"offset":"2693988356","bids":[],"asks":[["4215.8","0"]]}}
1635444230.936825: {"type":"channel_data","connection_id":"60a4fc71-1312-4830-86f4-9eb98be106ac","message_id":55,"id":"ETH-USD","channel":"v3_orderbook","contents":{"offset":"2693988362","bids":[],"asks":[["4216.1","10"]]}}
1635444230.936896: {"type":"channel_data","connection_id":"60a4fc71-1312-4830-86f4-9eb98be106ac","message_id":56,"id":"ETH-USD","channel":"v3_orderbook","contents":{"offset":"2693988359","bids":[["4214.5","0"]],"asks":[]}}
1635444230.936927: {"type":"channel_data","connection_id":"60a4fc71-1312-4830-86f4-9eb98be106ac","message_id":57,"id":"ETH-USD","channel":"v3_orderbook","contents":{"offset":"2693988363","bids":[],"asks":[["4216","2.45"]]}}
1635444230.936949: {"type":"channel_data","connection_id":"60a4fc71-1312-4830-86f4-9eb98be106ac","message_id":58,"id":"UNI-USD","channel":"v3_orderbook","contents":{"offset":"2693988360","bids":[["25.018","0"]],"asks":[]}}
1635444230.9399948: {"type":"channel_data","connection_id":"60a4fc71-1312-4830-86f4-9eb98be106ac","message_id":59,"id":"ETH-USD","channel":"v3_orderbook","contents":{"offset":"2693988364","bids":[["4212.7","0"]],"asks":[]}}
1635444230.940066: {"type":"channel_data","connection_id":"60a4fc71-1312-4830-86f4-9eb98be106ac","message_id":60,"id":"UNI-USD","channel":"v3_orderbook","contents":{"offset":"2693988367","bids":[],"asks":[["25.068","399.5"]]}}
1635444230.95972: {"type":"channel_data","connection_id":"60a4fc71-1312-4830-86f4-9eb98be106ac","message_id":61,"id":"EOS-USD","channel":"v3_orderbook","contents":{"offset":"2693988368","bids":[["4.398","28918"]],"asks":[]}}
1635444230.9598022: {"type":"channel_data","connection_id":"60a4fc71-1312-4830-86f4-9eb98be106ac","message_id":62,"id":"SUSHI-USD","channel":"v3_orderbook","contents":{"offset":"2693988369","bids":[],"asks":[["10.793","4002.3"]]}}
1635444230.9598389: {"type":"channel_data","connection_id":"60a4fc71-1312-4830-86f4-9eb98be106ac","message_id":63,"id":"ETH-USD","channel":"v3_orderbook","contents":{"offset":"2693988373","bids":[],"asks":[["4216.2","112.52"]]}}
1635444230.9598699: {"type":"channel_data","connection_id":"60a4fc71-1312-4830-86f4-9eb98be106ac","message_id":64,"id":"ETH-USD","channel":"v3_orderbook","contents":{"offset":"2693988374","bids":[["4213.2","1352.162"]],"asks":[]}}
1635444230.959897: {"type":"channel_data","connection_id":"60a4fc71-1312-4830-86f4-9eb98be106ac","message_id":65,"id":"LTC-USD","channel":"v3_orderbook","contents":{"offset":"2693988376","bids":[["187.7","733.59"]],"asks":[]}}
1635444230.959921: {"type":"channel_data","connection_id":"60a4fc71-1312-4830-86f4-9eb98be106ac","message_id":66,"id":"EOS-USD","channel":"v3_orderbook","contents":{"offset":"2693988377","bids":[],"asks":[["4.403","4542"]]}}
1635444230.959946: {"type":"channel_data","connection_id":"60a4fc71-1312-4830-86f4-9eb98be106ac","message_id":67,"id":"SUSHI-USD","channel":"v3_orderbook","contents":{"offset":"2693988378","bids":[],"asks":[["10.797","1413.2"]]}}
1635444230.959969: {"type":"channel_data","connection_id":"60a4fc71-1312-4830-86f4-9eb98be106ac","message_id":68,"id":"SUSHI-USD","channel":"v3_orderbook","contents":{"offset":"2693988381","bids":[["10.779","526.6"]],"asks":[]}}
1635444230.9599922: {"type":"channel_data","connection_id":"60a4fc71-1312-4830-86f4-9eb98be106ac","message_id":69,"id":"UMA-USD","channel":"v3_orderbook","contents":{"offset":"2693988386","bids":[["11.27","29150.7"]],"asks":[]}}
1635444230.960015: {"type":"channel_data","connection_id":"60a4fc71-1312-4830-86f4-9eb98be106ac","message_id":70,"id":"ETH-USD","channel":"v3_orderbook","contents":{"offset":"2693988382","bids":[],"asks":[["4216.7","0"]]}}
1635444230.960038: {"type":"channel_data","connection_id":"60a4fc71-1312-4830-86f4-9eb98be106ac","message_id":71,"id":"ETH-USD","channel":"v3_orderbook","contents":{"offset":"2693988380","bids":[],"asks":[["4217.8","13.34"]]}}
1635444230.9727879: {"type":"channel_data","connection_id":"60a4fc71-1312-4830-86f4-9eb98be106ac","message_id":72,"id":"EOS-USD","channel":"v3_orderbook","contents":{"offset":"2693988391","bids":[["4.396","1172"]],"asks":[]}}
1635444230.9728692: {"type":"channel_data","connection_id":"60a4fc71-1312-4830-86f4-9eb98be106ac","message_id":73,"id":"UNI-USD","channel":"v3_orderbook","contents":{"offset":"2693988389","bids":[],"asks":[["25.068","0"]]}}
1635444230.972908: {"type":"channel_data","connection_id":"60a4fc71-1312-4830-86f4-9eb98be106ac","message_id":74,"id":"LTC-USD","channel":"v3_orderbook","contents":{"offset":"2693988395","bids":[["187.7","714.69"]],"asks":[]}}
1635444230.972938: {"type":"channel_data","connection_id":"60a4fc71-1312-4830-86f4-9eb98be106ac","message_id":75,"id":"SUSHI-USD","channel":"v3_orderbook","contents":{"offset":"2693988390","bids":[],"asks":[["10.799","13068.4"]]}}
1635444230.972964: {"type":"channel_data","connection_id":"60a4fc71-1312-4830-86f4-9eb98be106ac","message_id":76,"id":"UNI-USD","channel":"v3_orderbook","contents":{"offset":"2693988392","bids":[],"asks":[["25.083","0"]]}}
1635444230.9729888: {"type":"channel_data","connection_id":"60a4fc71-1312-4830-86f4-9eb98be106ac","message_id":77,"id":"ETH-USD","channel":"v3_orderbook","contents":{"offset":"2693988388","bids":[["4213.5","0"]],"asks":[]}}
1635444230.973015: {"type":"channel_data","connection_id":"60a4fc71-1312-4830-86f4-9eb98be106ac","message_id":78,"id":"SUSHI-USD","channel":"v3_orderbook","contents":{"offset":"2693988393","bids":[],"asks":[["10.791","0"]]}}
1635444230.9730392: {"type":"channel_data","connection_id":"60a4fc71-1312-4830-86f4-9eb98be106ac","message_id":79,"id":"SUSHI-USD","channel":"v3_orderbook","contents":{"offset":"2693988397","bids":[],"asks":[["10.79","4002.3"]]}}
1635444230.973061: {"type":"channel_data","connection_id":"60a4fc71-1312-4830-86f4-9eb98be106ac","message_id":80,"id":"EOS-USD","channel":"v3_orderbook","contents":{"offset":"2693988396","bids":[],"asks":[["4.402","11205"]]}}
1635444230.978668: {"type":"channel_data","connection_id":"60a4fc71-1312-4830-86f4-9eb98be106ac","message_id":81,"id":"ETH-USD","channel":"v3_orderbook","contents":{"offset":"2693988405","bids":[["4214.1","17.839"]],"asks":[]}}
1635444230.978749: {"type":"channel_data","connection_id":"60a4fc71-1312-4830-86f4-9eb98be106ac","message_id":82,"id":"SUSHI-USD","channel":"v3_orderbook","contents":{"offset":"2693988404","bids":[],"asks":[["10.797","1135.3"]]}}
1635444230.9805708: {"type":"channel_data","connection_id":"60a4fc71-1312-4830-86f4-9eb98be106ac","message_id":83,"id":"ETH-USD","channel":"v3_orderbook","contents":{"offset":"2693988401","bids":[],"asks":[["4217.3","1898.821"]]}}
1635444230.992349: {"type":"channel_data","connection_id":"60a4fc71-1312-4830-86f4-9eb98be106ac","message_id":84,"id":"UMA-USD","channel":"v3_orderbook","contents":{"offset":"2693988413","bids":[["11.27","29416.2"]],"asks":[]}}
1635444230.992407: {"type":"channel_data","connection_id":"60a4fc71-1312-4830-86f4-9eb98be106ac","message_id":85,"id":"EOS-USD","channel":"v3_orderbook","contents":{"offset":"2693988412","bids":[],"asks":[["4.404","5023"]]}}
1635444230.999243: {"type":"channel_data","connection_id":"60a4fc71-1312-4830-86f4-9eb98be106ac","message_id":86,"id":"UNI-USD","channel":"v3_orderbook","contents":{"offset":"2693988417","bids":[],"asks":[["25.053","109.1"]]}}
1635444230.999295: {"type":"channel_data","connection_id":"60a4fc71-1312-4830-86f4-9eb98be106ac","message_id":87,"id":"SUSHI-USD","channel":"v3_orderbook","contents":{"offset":"2693988419","bids":[["10.773","727.7"]],"asks":[]}}
1635444230.9993222: {"type":"channel_data","connection_id":"60a4fc71-1312-4830-86f4-9eb98be106ac","message_id":88,"id":"LTC-USD","channel":"v3_orderbook","contents":{"offset":"2693988421","bids":[["187.8","2528.52"]],"asks":[]}}
1635444230.999342: {"type":"channel_data","connection_id":"60a4fc71-1312-4830-86f4-9eb98be106ac","message_id":89,"id":"ETH-USD","channel":"v3_orderbook","contents":{"offset":"2693988423","bids":[["4214.1","18.691"]],"asks":[]}}
1635444231.000685: {"type":"channel_data","connection_id":"60a4fc71-1312-4830-86f4-9eb98be106ac","message_id":90,"id":"ETH-USD","channel":"v3_orderbook","contents":{"offset":"2693988424","bids":[["4215.1","0"]],"asks":[]}}
1635444231.000726: {"type":"channel_data","connection_id":"60a4fc71-1312-4830-86f4-9eb98be106ac","message_id":91,"id":"UMA-USD","channel":"v3_orderbook","contents":{"offset":"2693988420","bids":[["11.28","2077.9"]],"asks":[]}}
1635444231.004585: {"type":"channel_data","connection_id":"60a4fc71-1312-4830-86f4-9eb98be106ac","message_id":92,"id":"SUSHI-USD","channel":"v3_orderbook","contents":{"offset":"2693988425","bids":[],"asks":[["10.796","5555.3"]]}}
1635444231.004631: {"type":"channel_data","connection_id":"60a4fc71-1312-4830-86f4-9eb98be106ac","message_id":93,"id":"ETH-USD","channel":"v3_orderbook","contents":{"offset":"2693988426","bids":[["4214","109.572"]],"asks":[]}}
1635444231.0046551: {"type":"channel_data","connection_id":"60a4fc71-1312-4830-86f4-9eb98be106ac","message_id":94,"id":"SUSHI-USD","channel":"v3_orderbook","contents":{"offset":"2693988428","bids":[["10.784","334.7"]],"asks":[]}}
1635444231.0112529: {"type":"channel_data","connection_id":"60a4fc71-1312-4830-86f4-9eb98be106ac","message_id":95,"id":"SUSHI-USD","channel":"v3_orderbook","contents":{"offset":"2693988437","bids":[["10.783","13236.4"]],"asks":[]}}
1635444231.018796: {"type":"channel_data","connection_id":"60a4fc71-1312-4830-86f4-9eb98be106ac","message_id":96,"id":"ETH-USD","channel":"v3_orderbook","contents":{"offset":"2693988442","bids":[],"asks":[["4219","0.2"]]}}
1635444231.0188549: {"type":"channel_data","connection_id":"60a4fc71-1312-4830-86f4-9eb98be106ac","message_id":97,"id":"SUSHI-USD","channel":"v3_orderbook","contents":{"offset":"2693988443","bids":[],"asks":[["10.8","0"]]}}
1635444231.018881: {"type":"channel_data","connection_id":"60a4fc71-1312-4830-86f4-9eb98be106ac","message_id":98,"id":"ETH-USD","channel":"v3_orderbook","contents":{"offset":"2693988444","bids":[["4214","109.762"]],"asks":[]}}
1635444231.018902: {"type":"channel_data","connection_id":"60a4fc71-1312-4830-86f4-9eb98be106ac","message_id":99,"id":"ETH-USD","channel":"v3_orderbook","contents":{"offset":"2693988441","bids":[],"asks":[["4220.2","0"]]}}
1635444231.01892: {"type":"channel_data","connection_id":"60a4fc71-1312-4830-86f4-9eb98be106ac","message_id":100,"id":"UMA-USD","channel":"v3_orderbook","contents":{"offset":"2693988450","bids":[["11.27","29150.7"]],"asks":[]}}
1635444231.0255208: {"type":"channel_data","connection_id":"60a4fc71-1312-4830-86f4-9eb98be106ac","message_id":101,"id":"SUSHI-USD","channel":"v3_orderbook","contents":{"offset":"2693988451","bids":[],"asks":[["10.797","626"]]}}
1635444231.026567: {"type":"channel_data","connection_id":"60a4fc71-1312-4830-86f4-9eb98be106ac","message_id":102,"id":"SUSHI-USD","channel":"v3_orderbook","contents":{"offset":"2693988449","bids":[],"asks":[["10.797","1013"]]}}
1635444231.028115: {"type":"channel_data","connection_id":"60a4fc71-1312-4830-86f4-9eb98be106ac","message_id":103,"id":"LTC-USD","channel":"v3_orderbook","contents":{"offset":"2693988447","bids":[["187.8","2533.28"]],"asks":[]}}
1635444231.028178: {"type":"channel_data","connection_id":"60a4fc71-1312-4830-86f4-9eb98be106ac","message_id":104,"id":"ETH-USD","channel":"v3_orderbook","contents":{"offset":"2693988453","bids":[],"asks":[["4217.9","4.655"]]}}
1635444231.030922: {"type":"channel_data","connection_id":"60a4fc71-1312-4830-86f4-9eb98be106ac","message_id":105,"id":"ETH-USD","channel":"v3_orderbook","contents":{"offset":"2693988459","bids":[["4212.9","0"]],"asks":[]}}
1635444231.030973: {"type":"channel_data","connection_id":"60a4fc71-1312-4830-86f4-9eb98be106ac","message_id":106,"id":"SUSHI-USD","channel":"v3_orderbook","contents":{"offset":"2693988456","bids":[["10.783","8752.8"]],"asks":[]}}
1635444231.0365388: {"type":"channel_data","connection_id":"60a4fc71-1312-4830-86f4-9eb98be106ac","message_id":107,"id":"ETH-USD","channel":"v3_orderbook","contents":{"offset":"2693988467","bids":[],"asks":[["4217.8","9.784"]]}}
1635444231.036586: {"type":"channel_data","connection_id":"60a4fc71-1312-4830-86f4-9eb98be106ac","message_id":108,"id":"ETH-USD","channel":"v3_orderbook","contents":{"offset":"2693988462","bids":[],"asks":[["4217.9","0.355"]]}}
1635444231.037575: {"type":"channel_data","connection_id":"60a4fc71-1312-4830-86f4-9eb98be106ac","message_id":109,"id":"UNI-USD","channel":"v3_orderbook","contents":{"offset":"2693988460","bids":[],"asks":[["25.068","399.5"]]}}
1635444231.0376189: {"type":"channel_data","connection_id":"60a4fc71-1312-4830-86f4-9eb98be106ac","message_id":110,"id":"SUSHI-USD","channel":"v3_orderbook","contents":{"offset":"2693988469","bids":[],"asks":[["10.799","254.4"]]}}
1635444231.040014: {"type":"channel_data","connection_id":"60a4fc71-1312-4830-86f4-9eb98be106ac","message_id":111,"id":"SUSHI-USD","channel":"v3_orderbook","contents":{"offset":"2693988465","bids":[["10.775","1210.7"]],"asks":[]}}
1635444231.042447: {"type":"channel_data","connection_id":"60a4fc71-1312-4830-86f4-9eb98be106ac","message_id":112,"id":"SUSHI-USD","channel":"v3_orderbook","contents":{"offset":"2693988468","bids":[["10.755","102"]],"asks":[]}}
1635444231.044319: {"type":"channel_data","connection_id":"60a4fc71-1312-4830-86f4-9eb98be106ac","message_id":113,"id":"ETH-USD","channel":"v3_orderbook","contents":{"offset":"2693988475","bids":[],"asks":[["4216","0.2"]]}}
1635444231.04438: {"type":"channel_data","connection_id":"60a4fc71-1312-4830-86f4-9eb98be106ac","message_id":114,"id":"SUSHI-USD","channel":"v3_orderbook","contents":{"offset":"2693988471","bids":[["10.784","0"]],"asks":[]}}
1635444231.044412: {"type":"channel_data","connection_id":"60a4fc71-1312-4830-86f4-9eb98be106ac","message_id":115,"id":"ETH-USD","channel":"v3_orderbook","contents":{"offset":"2693988477","bids":[],"asks":[["4216.8","24.496"]]}}
1635444231.046419: {"type":"channel_data","connection_id":"60a4fc71-1312-4830-86f4-9eb98be106ac","message_id":116,"id":"UNI-USD","channel":"v3_orderbook","contents":{"offset":"2693988476","bids":[["25.036","399.4"]],"asks":[]}}
1635444231.046477: {"type":"channel_data","connection_id":"60a4fc71-1312-4830-86f4-9eb98be106ac","message_id":117,"id":"SUSHI-USD","channel":"v3_orderbook","contents":{"offset":"2693988473","bids":[["10.783","4269"]],"asks":[]}}
1635444231.0470679: {"type":"channel_data","connection_id":"60a4fc71-1312-4830-86f4-9eb98be106ac","message_id":118,"id":"ETH-USD","channel":"v3_orderbook","contents":{"offset":"2693988482","bids":[["4214.4","1.763"]],"asks":[]}}
1635444231.0516322: {"type":"channel_data","connection_id":"60a4fc71-1312-4830-86f4-9eb98be106ac","message_id":119,"id":"ETH-USD","channel":"v3_orderbook","contents":{"offset":"2693988487","bids":[["4214","102.547"]],"asks":[]}}
1635444231.0531242: {"type":"channel_data","connection_id":"60a4fc71-1312-4830-86f4-9eb98be106ac","message_id":120,"id":"ETH-USD","channel":"v3_orderbook","contents":{"offset":"2693988484","bids":[["4215.5","495.807"]],"asks":[]}}
1635444231.0603259: {"type":"channel_data","connection_id":"60a4fc71-1312-4830-86f4-9eb98be106ac","message_id":121,"id":"ETH-USD","channel":"v3_orderbook","contents":{"offset":"2693988495","bids":[],"asks":[["4217.8","0"]]}}
1635444231.060399: {"type":"channel_data","connection_id":"60a4fc71-1312-4830-86f4-9eb98be106ac","message_id":122,"id":"ETH-USD","channel":"v3_orderbook","contents":{"offset":"2693988490","bids":[],"asks":[["4216.7","114.21"]]}}
1635444231.0609438: {"type":"channel_data","connection_id":"60a4fc71-1312-4830-86f4-9eb98be106ac","message_id":123,"id":"UNI-USD","channel":"v3_orderbook","contents":{"offset":"2693988489","bids":[["25.025","7563.9"]],"asks":[]}}
1635444231.0616808: {"type":"channel_data","connection_id":"60a4fc71-1312-4830-86f4-9eb98be106ac","message_id":124,"id":"ETH-USD","channel":"v3_orderbook","contents":{"offset":"2693988503","bids":[],"asks":[["4220.9","1.6"]]}}
1635444231.0691059: {"type":"channel_data","connection_id":"60a4fc71-1312-4830-86f4-9eb98be106ac","message_id":125,"id":"CRV-USD","channel":"v3_orderbook","contents":{"offset":"2693988498","bids":[["4.839","4557"],["4.837","0"]],"asks":[]}}
1635444231.069237: {"type":"channel_data","connection_id":"60a4fc71-1312-4830-86f4-9eb98be106ac","message_id":126,"id":"SUSHI-USD","channel":"v3_orderbook","contents":{"offset":"2693988504","bids":[],"asks":[["10.796","1071.7"]]}}
1635444231.069271: {"type":"channel_data","connection_id":"60a4fc71-1312-4830-86f4-9eb98be106ac","message_id":127,"id":"SUSHI-USD","channel":"v3_orderbook","contents":{"offset":"2693988502","bids":[],"asks":[["10.794","4483.6"]]}}
1635444231.073466: {"type":"channel_data","connection_id":"60a4fc71-1312-4830-86f4-9eb98be106ac","message_id":128,"id":"SUSHI-USD","channel":"v3_orderbook","contents":{"offset":"2693988506","bids":[["10.789","334.7"]],"asks":[]}}
1635444231.073518: {"type":"channel_data","connection_id":"60a4fc71-1312-4830-86f4-9eb98be106ac","message_id":129,"id":"SUSHI-USD","channel":"v3_orderbook","contents":{"offset":"2693988509","bids":[],"asks":[["10.796","0"]]}}
1635444231.07355: {"type":"channel_data","connection_id":"60a4fc71-1312-4830-86f4-9eb98be106ac","message_id":130,"id":"SUSHI-USD","channel":"v3_orderbook","contents":{"offset":"2693988511","bids":[],"asks":[["10.79","0"]]}}
1635444231.073578: {"type":"channel_data","connection_id":"60a4fc71-1312-4830-86f4-9eb98be106ac","message_id":131,"id":"ETH-USD","channel":"v3_orderbook","contents":{"offset":"2693988505","bids":[],"asks":[["4220.9","0"]]}}
1635444231.073605: {"type":"channel_data","connection_id":"60a4fc71-1312-4830-86f4-9eb98be106ac","message_id":132,"id":"SUSHI-USD","channel":"v3_orderbook","contents":{"offset":"2693988508","bids":[["10.775","139"]],"asks":[]}}
1635444231.073631: {"type":"channel_data","connection_id":"60a4fc71-1312-4830-86f4-9eb98be106ac","message_id":133,"id":"ETH-USD","channel":"v3_orderbook","contents":{"offset":"2693988517","bids":[],"asks":[["4216.6","46.23"]]}}
1635444231.077065: {"type":"channel_data","connection_id":"60a4fc71-1312-4830-86f4-9eb98be106ac","message_id":134,"id":"SUSHI-USD","channel":"v3_orderbook","contents":{"offset":"2693988519","bids":[],"asks":[["10.864","15"],["10.866","2319.7"]]}}
1635444231.077122: {"type":"channel_data","connection_id":"60a4fc71-1312-4830-86f4-9eb98be106ac","message_id":135,"id":"SUSHI-USD","channel":"v3_orderbook","contents":{"offset":"2693988514","bids":[],"asks":[["10.794","0"]]}}
1635444231.0771499: {"type":"channel_data","connection_id":"60a4fc71-1312-4830-86f4-9eb98be106ac","message_id":136,"id":"SUSHI-USD","channel":"v3_orderbook","contents":{"offset":"2693988518","bids":[],"asks":[["10.817","428.7"]]}}
1635444231.0805178: {"type":"channel_data","connection_id":"60a4fc71-1312-4830-86f4-9eb98be106ac","message_id":137,"id":"EOS-USD","channel":"v3_orderbook","contents":{"offset":"2693988513","bids":[],"asks":[["4.425","0"],["4.426","44311"]]}}
1635444231.0856478: {"type":"channel_data","connection_id":"60a4fc71-1312-4830-86f4-9eb98be106ac","message_id":138,"id":"SUSHI-USD","channel":"v3_orderbook","contents":{"offset":"2693988522","bids":[],"asks":[["11.164","0"]]}}
1635444231.085726: {"type":"channel_data","connection_id":"60a4fc71-1312-4830-86f4-9eb98be106ac","message_id":139,"id":"UNI-USD","channel":"v3_orderbook","contents":{"offset":"2693988526","bids":[["25.03","399.5"]],"asks":[]}}
1635444231.0857642: {"type":"channel_data","connection_id":"60a4fc71-1312-4830-86f4-9eb98be106ac","message_id":140,"id":"SUSHI-USD","channel":"v3_orderbook","contents":{"offset":"2693988524","bids":[["10.408","0"]],"asks":[]}}
1635444231.085793: {"type":"channel_data","connection_id":"60a4fc71-1312-4830-86f4-9eb98be106ac","message_id":141,"id":"ETH-USD","channel":"v3_orderbook","contents":{"offset":"2693988528","bids":[],"asks":[["4218.3","64.896"]]}}
1635444231.093143: {"type":"channel_data","connection_id":"60a4fc71-1312-4830-86f4-9eb98be106ac","message_id":142,"id":"EOS-USD","channel":"v3_orderbook","contents":{"offset":"2693988535","bids":[["4.397","37983"]],"asks":[]}}
1635444231.0932212: {"type":"channel_data","connection_id":"60a4fc71-1312-4830-86f4-9eb98be106ac","message_id":143,"id":"SUSHI-USD","channel":"v3_orderbook","contents":{"offset":"2693988534","bids":[],"asks":[["10.797","487"]]}}
1635444231.093259: {"type":"channel_data","connection_id":"60a4fc71-1312-4830-86f4-9eb98be106ac","message_id":144,"id":"EOS-USD","channel":"v3_orderbook","contents":{"offset":"2693988532","bids":[],"asks":[["4.404","16303"]]}}
1635444231.095422: {"type":"channel_data","connection_id":"60a4fc71-1312-4830-86f4-9eb98be106ac","message_id":145,"id":"UNI-USD","channel":"v3_orderbook","contents":{"offset":"2693988538","bids":[],"asks":[["25.073","399.4"]]}}
1635444231.0954728: {"type":"channel_data","connection_id":"60a4fc71-1312-4830-86f4-9eb98be106ac","message_id":146,"id":"SUSHI-USD","channel":"v3_orderbook","contents":{"offset":"2693988539","bids":[["10.754","3891.4"]],"asks":[]}}
1635444231.10375: {"type":"channel_data","connection_id":"60a4fc71-1312-4830-86f4-9eb98be106ac","message_id":147,"id":"ETH-USD","channel":"v3_orderbook","contents":{"offset":"2693988543","bids":[["4215","1007.07"]],"asks":[]}}
1635444231.103821: {"type":"channel_data","connection_id":"60a4fc71-1312-4830-86f4-9eb98be106ac","message_id":148,"id":"ETH-USD","channel":"v3_orderbook","contents":{"offset":"2693988547","bids":[["4215.2","114.21"]],"asks":[]}}
1635444231.118811: {"type":"channel_data","connection_id":"60a4fc71-1312-4830-86f4-9eb98be106ac","message_id":149,"id":"SUSHI-USD","channel":"v3_orderbook","contents":{"offset":"2693988548","bids":[],"asks":[["10.859","0"],["10.86","1372.2"]]}}
1635444231.132015: {"type":"channel_data","connection_id":"60a4fc71-1312-4830-86f4-9eb98be106ac","message_id":150,"id":"SUSHI-USD","channel":"v3_orderbook","contents":{"offset":"2693988557","bids":[["10.775","0"]],"asks":[]}}
1635444231.132088: {"type":"channel_data","connection_id":"60a4fc71-1312-4830-86f4-9eb98be106ac","message_id":151,"id":"ETH-USD","channel":"v3_orderbook","contents":{"offset":"2693988562","bids":[["4215.5","501.741"]],"asks":[]}}
1635444231.132121: {"type":"channel_data","connection_id":"60a4fc71-1312-4830-86f4-9eb98be106ac","message_id":152,"id":"UNI-USD","channel":"v3_orderbook","contents":{"offset":"2693988565","bids":[],"asks":[["25.06","2836.2"]]}}
1635444231.1325572: {"type":"channel_data","connection_id":"60a4fc71-1312-4830-86f4-9eb98be106ac","message_id":153,"id":"UNI-USD","channel":"v3_orderbook","contents":{"offset":"2693988561","bids":[],"asks":[["25.079","399.5"]]}}
1635444231.1397388: {"type":"channel_data","connection_id":"60a4fc71-1312-4830-86f4-9eb98be106ac","message_id":154,"id":"ETH-USD","channel":"v3_orderbook","contents":{"offset":"2693988578","bids":[["4213.6","30.611"]],"asks":[]}}
1635444231.142823: {"type":"channel_data","connection_id":"60a4fc71-1312-4830-86f4-9eb98be106ac","message_id":155,"id":"ETH-USD","channel":"v3_orderbook","contents":{"offset":"2693988569","bids":[["4214.5","7.215"]],"asks":[]}}
1635444231.15225: {"type":"channel_data","connection_id":"60a4fc71-1312-4830-86f4-9eb98be106ac","message_id":156,"id":"ETH-USD","channel":"v3_orderbook","contents":{"offset":"2693988582","bids":[],"asks":[["4219.6","0"]]}}
1635444231.1523242: {"type":"channel_data","connection_id":"60a4fc71-1312-4830-86f4-9eb98be106ac","message_id":157,"id":"SUSHI-USD","channel":"v3_orderbook","contents":{"offset":"2693988584","bids":[],"asks":[["10.802","4154.5"]]}}
1635444231.1597471: {"type":"channel_data","connection_id":"60a4fc71-1312-4830-86f4-9eb98be106ac","message_id":158,"id":"ETH-USD","channel":"v3_orderbook","contents":{"offset":"2693988594","bids":[["4214.6","0"]],"asks":[]}}
1635444231.1624079: {"type":"channel_data","connection_id":"60a4fc71-1312-4830-86f4-9eb98be106ac","message_id":159,"id":"ETH-USD","channel":"v3_orderbook","contents":{"offset":"2693988592","bids":[["4215.3","23.003"]],"asks":[]}}
1635444231.1741068: {"type":"channel_data","connection_id":"60a4fc71-1312-4830-86f4-9eb98be106ac","message_id":160,"id":"SUSHI-USD","channel":"v3_orderbook","contents":{"offset":"2693988604","bids":[["10.78","5210.4"]],"asks":[]}}
1635444231.176351: {"type":"channel_data","connection_id":"60a4fc71-1312-4830-86f4-9eb98be106ac","message_id":161,"id":"SUSHI-USD","channel":"v3_orderbook","contents":{"offset":"2693988605","bids":[["10.749","3291.2"],["10.747","445.7"]],"asks":[]}}
1635444231.176476: {"type":"channel_data","connection_id":"60a4fc71-1312-4830-86f4-9eb98be106ac","message_id":162,"id":"EOS-USD","channel":"v3_orderbook","contents":{"offset":"2693988608","bids":[],"asks":[["4.423","31994"],["4.424","7957"]]}}
1635444231.181343: {"type":"channel_data","connection_id":"60a4fc71-1312-4830-86f4-9eb98be106ac","message_id":163,"id":"ETH-USD","channel":"v3_orderbook","contents":{"offset":"2693988610","bids":[],"asks":[["4219","4.5"]]}}
1635444231.184917: {"type":"channel_data","connection_id":"60a4fc71-1312-4830-86f4-9eb98be106ac","message_id":164,"id":"UNI-USD","channel":"v3_orderbook","contents":{"offset":"2693988612","bids":[],"asks":[["25.095","378152.9"]]}}
1635444231.185034: {"type":"channel_data","connection_id":"60a4fc71-1312-4830-86f4-9eb98be106ac","message_id":165,"id":"ETH-USD","channel":"v3_orderbook","contents":{"offset":"2693988611","bids":[],"asks":[["4216.6","22.496"]]}}
1635444231.185091: {"type":"channel_data","connection_id":"60a4fc71-1312-4830-86f4-9eb98be106ac","message_id":166,"id":"SUSHI-USD","channel":"v3_orderbook","contents":{"offset":"2693988615","bids":[],"asks":[["10.798","3704.6"]]}}
1635444231.1851368: {"type":"channel_data","connection_id":"60a4fc71-1312-4830-86f4-9eb98be106ac","message_id":167,"id":"SUSHI-USD","channel":"v3_orderbook","contents":{"offset":"2693988613","bids":[],"asks":[["10.799","4736.7"]]}}
1635444231.185175: {"type":"channel_data","connection_id":"60a4fc71-1312-4830-86f4-9eb98be106ac","message_id":168,"id":"SUSHI-USD","channel":"v3_orderbook","contents":{"offset":"2693988609","bids":[["10.786","3708.3"]],"asks":[]}}
1635444231.1931221: {"type":"channel_data","connection_id":"60a4fc71-1312-4830-86f4-9eb98be106ac","message_id":169,"id":"ETH-USD","channel":"v3_orderbook","contents":{"offset":"2693988621","bids":[["4215.1","17.8"]],"asks":[]}}
1635444231.1936681: {"type":"channel_data","connection_id":"60a4fc71-1312-4830-86f4-9eb98be106ac","message_id":170,"id":"ETH-USD","channel":"v3_orderbook","contents":{"offset":"2693988616","bids":[["4214.1","0.852"]],"asks":[]}}
1635444231.195589: {"type":"channel_data","connection_id":"60a4fc71-1312-4830-86f4-9eb98be106ac","message_id":171,"id":"ETH-USD","channel":"v3_orderbook","contents":{"offset":"2693988617","bids":[["4215.5","495.807"]],"asks":[]}}
1635444231.1979399: {"type":"channel_data","connection_id":"60a4fc71-1312-4830-86f4-9eb98be106ac","message_id":172,"id":"SUSHI-USD","channel":"v3_orderbook","contents":{"offset":"2693988624","bids":[],"asks":[["10.828","110.8"],["10.83","101.9"]]}}
1635444231.204046: {"type":"channel_data","connection_id":"60a4fc71-1312-4830-86f4-9eb98be106ac","message_id":173,"id":"SUSHI-USD","channel":"v3_orderbook","contents":{"offset":"2693988626","bids":[],"asks":[["10.804","13897.2"]]}}
1635444231.206285: {"type":"channel_data","connection_id":"60a4fc71-1312-4830-86f4-9eb98be106ac","message_id":174,"id":"ETH-USD","channel":"v3_orderbook","contents":{"offset":"2693988630","bids":[],"asks":[["4217.9","0"]]}}
1635444231.206368: {"type":"channel_data","connection_id":"60a4fc71-1312-4830-86f4-9eb98be106ac","message_id":175,"id":"SUSHI-USD","channel":"v3_orderbook","contents":{"offset":"2693988627","bids":[["10.762","448492.7"]],"asks":[]}}
1635444231.214775: {"type":"channel_data","connection_id":"60a4fc71-1312-4830-86f4-9eb98be106ac","message_id":176,"id":"SUSHI-USD","channel":"v3_orderbook","contents":{"offset":"2693988637","bids":[["10.78","5073.5"]],"asks":[]}}
1635444231.214854: {"type":"channel_data","connection_id":"60a4fc71-1312-4830-86f4-9eb98be106ac","message_id":177,"id":"SUSHI-USD","channel":"v3_orderbook","contents":{"offset":"2693988635","bids":[],"asks":[["10.804","13563.9"]]}}
1635444231.218091: {"type":"channel_data","connection_id":"60a4fc71-1312-4830-86f4-9eb98be106ac","message_id":178,"id":"EOS-USD","channel":"v3_orderbook","contents":{"offset":"2693988636","bids":[["4.39","1138784"]],"asks":[]}}
1635444231.218175: {"type":"channel_data","connection_id":"60a4fc71-1312-4830-86f4-9eb98be106ac","message_id":179,"id":"ETH-USD","channel":"v3_orderbook","contents":{"offset":"2693988633","bids":[["4215.3","22.496"]],"asks":[]}}
1635444231.228554: {"type":"channel_data","connection_id":"60a4fc71-1312-4830-86f4-9eb98be106ac","message_id":180,"id":"ETH-USD","channel":"v3_orderbook","contents":{"offset":"2693988643","bids":[],"asks":[["4219.8","0"]]}}
1635444231.229882: {"type":"channel_data","connection_id":"60a4fc71-1312-4830-86f4-9eb98be106ac","message_id":181,"id":"ETH-USD","channel":"v3_orderbook","contents":{"offset":"2693988644","bids":[["4209.5","0"]],"asks":[]}}
1635444231.229982: {"type":"channel_data","connection_id":"60a4fc71-1312-4830-86f4-9eb98be106ac","message_id":182,"id":"ETH-USD","channel":"v3_orderbook","contents":{"offset":"2693988641","bids":[["4215.5","496.162"]],"asks":[]}}
1635444231.237528: {"type":"channel_data","connection_id":"60a4fc71-1312-4830-86f4-9eb98be106ac","message_id":183,"id":"ETH-USD","channel":"v3_orderbook","contents":{"offset":"2693988647","bids":[["4214.5","0"]],"asks":[]}}
1635444231.239359: {"type":"channel_data","connection_id":"60a4fc71-1312-4830-86f4-9eb98be106ac","message_id":184,"id":"ETH-USD","channel":"v3_orderbook","contents":{"offset":"2693988649","bids":[],"asks":[["4218.3","55.112"]]}}
1635444231.251338: {"type":"channel_data","connection_id":"60a4fc71-1312-4830-86f4-9eb98be106ac","message_id":185,"id":"SUSHI-USD","channel":"v3_orderbook","contents":{"offset":"2693988650","bids":[["10.78","18520.4"]],"asks":[]}}
1635444231.252384: {"type":"channel_data","connection_id":"60a4fc71-1312-4830-86f4-9eb98be106ac","message_id":186,"id":"SUSHI-USD","channel":"v3_orderbook","contents":{"offset":"2693988654","bids":[["10.785","1531.5"]],"asks":[]}}
1635444231.2627919: {"type":"channel_data","connection_id":"60a4fc71-1312-4830-86f4-9eb98be106ac","message_id":187,"id":"SUSHI-USD","channel":"v3_orderbook","contents":{"offset":"2693988661","bids":[["10.682","13393.6"],["10.669","0"]],"asks":[]}}
1635444231.262879: {"type":"channel_data","connection_id":"60a4fc71-1312-4830-86f4-9eb98be106ac","message_id":188,"id":"ETH-USD","channel":"v3_orderbook","contents":{"offset":"2693988658","bids":[],"asks":[["4219.1","0"]]}}
1635444231.262916: {"type":"channel_data","connection_id":"60a4fc71-1312-4830-86f4-9eb98be106ac","message_id":189,"id":"SUSHI-USD","channel":"v3_orderbook","contents":{"offset":"2693988655","bids":[],"asks":[["10.797","4969.3"]]}}
1635444231.262944: {"type":"channel_data","connection_id":"60a4fc71-1312-4830-86f4-9eb98be106ac","message_id":190,"id":"ETH-USD","channel":"v3_orderbook","contents":{"offset":"2693988659","bids":[],"asks":[["4217.6","58.428"]]}}
1635444231.2629702: {"type":"channel_data","connection_id":"60a4fc71-1312-4830-86f4-9eb98be106ac","message_id":191,"id":"ETH-USD","channel":"v3_orderbook","contents":{"offset":"2693988656","bids":[],"asks":[["4239.8","0"],["4240","81.898"]]}}
1635444231.262999: {"type":"channel_data","connection_id":"60a4fc71-1312-4830-86f4-9eb98be106ac","message_id":192,"id":"UNI-USD","channel":"v3_orderbook","contents":{"offset":"2693988660","bids":[],"asks":[["25.191","0"],["25.192","1997.7"]]}}
1635444231.263031: {"type":"channel_data","connection_id":"60a4fc71-1312-4830-86f4-9eb98be106ac","message_id":193,"id":"UNI-USD","channel":"v3_orderbook","contents":{"offset":"2693988657","bids":[],"asks":[["25.204","0"],["25.206","998.8"]]}}
1635444231.2704: {"type":"channel_data","connection_id":"60a4fc71-1312-4830-86f4-9eb98be106ac","message_id":194,"id":"LTC-USD","channel":"v3_orderbook","contents":{"offset":"2693988663","bids":[],"asks":[["189.2","1188.96"],["189.3","783.02"]]}}
1635444231.271382: {"type":"channel_data","connection_id":"60a4fc71-1312-4830-86f4-9eb98be106ac","message_id":195,"id":"ETH-USD","channel":"v3_orderbook","contents":{"offset":"2693988662","bids":[["4214.3","7.215"]],"asks":[]}}
1635444231.272445: {"type":"channel_data","connection_id":"60a4fc71-1312-4830-86f4-9eb98be106ac","message_id":196,"id":"SUSHI-USD","channel":"v3_orderbook","contents":{"offset":"2693988665","bids":[],"asks":[["10.909","15"],["10.921","927.4"]]}}
1635444231.282594: {"type":"channel_data","connection_id":"60a4fc71-1312-4830-86f4-9eb98be106ac","message_id":197,"id":"SUSHI-USD","channel":"v3_orderbook","contents":{"offset":"2693988666","bids":[["10.758","92771"]],"asks":[]}}
1635444231.286303: {"type":"channel_data","connection_id":"60a4fc71-1312-4830-86f4-9eb98be106ac","message_id":198,"id":"ETH-USD","channel":"v3_orderbook","contents":{"offset":"2693988673","bids":[],"asks":[["4219.5","19.578"]]}}
1635444231.299414: {"type":"channel_data","connection_id":"60a4fc71-1312-4830-86f4-9eb98be106ac","message_id":199,"id":"ETH-USD","channel":"v3_orderbook","contents":{"offset":"2693988675","bids":[],"asks":[["4218.1","24.195"]]}}
1635444231.304678: {"type":"channel_data","connection_id":"60a4fc71-1312-4830-86f4-9eb98be106ac","message_id":200,"id":"SUSHI-USD","channel":"v3_orderbook","contents":{"offset":"2693988676","bids":[["10.785","1346.1"]],"asks":[]}}
1635444231.30476: {"type":"channel_data","connection_id":"60a4fc71-1312-4830-86f4-9eb98be106ac","message_id":201,"id":"EOS-USD","channel":"v3_orderbook","contents":{"offset":"2693988681","bids":[],"asks":[["4.404","16101"]]}}
1635444231.304797: {"type":"channel_data","connection_id":"60a4fc71-1312-4830-86f4-9eb98be106ac","message_id":202,"id":"SUSHI-USD","channel":"v3_orderbook","contents":{"offset":"2693988687","bids":[["10.757","3414.5"]],"asks":[]}}
1635444231.304825: {"type":"channel_data","connection_id":"60a4fc71-1312-4830-86f4-9eb98be106ac","message_id":203,"id":"CRV-USD","channel":"v3_orderbook","contents":{"offset":"2693988683","bids":[["4.851","11617"]],"asks":[]}}
1635444231.304852: {"type":"channel_data","connection_id":"60a4fc71-1312-4830-86f4-9eb98be106ac","message_id":204,"id":"ETH-USD","channel":"v3_orderbook","contents":{"offset":"2693988684","bids":[["4214.4","0.355"]],"asks":[]}}
1635444231.312726: {"type":"channel_data","connection_id":"60a4fc71-1312-4830-86f4-9eb98be106ac","message_id":205,"id":"UNI-USD","channel":"v3_orderbook","contents":{"offset":"2693988703","bids":[],"asks":[["25.166","0"],["25.168","1067.1"]]}}
1635444231.3157492: {"type":"channel_data","connection_id":"60a4fc71-1312-4830-86f4-9eb98be106ac","message_id":206,"id":"UNI-USD","channel":"v3_orderbook","contents":{"offset":"2693988696","bids":[],"asks":[["25.051","2836.2"]]}}
1635444231.315834: {"type":"channel_data","connection_id":"60a4fc71-1312-4830-86f4-9eb98be106ac","message_id":207,"id":"EOS-USD","channel":"v3_orderbook","contents":{"offset":"2693988699","bids":[],"asks":[["4.419","0"],["4.42","7957"]]}}
1635444231.3189068: {"type":"channel_data","connection_id":"60a4fc71-1312-4830-86f4-9eb98be106ac","message_id":208,"id":"SUSHI-USD","channel":"v3_orderbook","contents":{"offset":"2693988711","bids":[["10.769","110.8"]],"asks":[]}}
1635444231.318965: {"type":"channel_data","connection_id":"60a4fc71-1312-4830-86f4-9eb98be106ac","message_id":209,"id":"EOS-USD","channel":"v3_orderbook","contents":{"offset":"2693988707","bids":[["4.398","28666"]],"asks":[]}}
1635444231.3289118: {"type":"channel_data","connection_id":"60a4fc71-1312-4830-86f4-9eb98be106ac","message_id":210,"id":"UNI-USD","channel":"v3_orderbook","contents":{"offset":"2693988715","bids":[["25.009","0"]],"asks":[]}}
1635444231.332991: {"type":"channel_data","connection_id":"60a4fc71-1312-4830-86f4-9eb98be106ac","message_id":211,"id":"ETH-USD","channel":"v3_orderbook","contents":{"offset":"2693988723","bids":[["4215.1","0"]],"asks":[]}}
1635444231.3330402: {"type":"channel_data","connection_id":"60a4fc71-1312-4830-86f4-9eb98be106ac","message_id":212,"id":"UNI-USD","channel":"v3_orderbook","contents":{"offset":"2693988725","bids":[["25.019","16270.6"]],"asks":[]}}
1635444231.34082: {"type":"channel_data","connection_id":"60a4fc71-1312-4830-86f4-9eb98be106ac","message_id":213,"id":"ETH-USD","channel":"v3_orderbook","contents":{"offset":"2693988730","bids":[],"asks":[["4218.1","14.411"]]}}
1635444231.3408818: {"type":"channel_data","connection_id":"60a4fc71-1312-4830-86f4-9eb98be106ac","message_id":214,"id":"ETH-USD","channel":"v3_orderbook","contents":{"offset":"2693988733","bids":[["4211.2","11.42"]],"asks":[]}}
1635444231.3432262: {"type":"channel_data","connection_id":"60a4fc71-1312-4830-86f4-9eb98be106ac","message_id":215,"id":"ETH-USD","channel":"v3_orderbook","contents":{"offset":"2693988726","bids":[["4214.5","17.617"]],"asks":[]}}
1635444231.356569: {"type":"channel_data","connection_id":"60a4fc71-1312-4830-86f4-9eb98be106ac","message_id":216,"id":"ETH-USD","channel":"v3_orderbook","contents":{"offset":"2693988738","bids":[["4214.6","7.215"]],"asks":[]}}
1635444231.3710341: {"type":"channel_data","connection_id":"60a4fc71-1312-4830-86f4-9eb98be106ac","message_id":217,"id":"ETH-USD","channel":"v3_orderbook","contents":{"offset":"2693988742","bids":[["4214.3","0"]],"asks":[]}}
1635444231.371132: {"type":"channel_data","connection_id":"60a4fc71-1312-4830-86f4-9eb98be106ac","message_id":218,"id":"SUSHI-USD","channel":"v3_orderbook","contents":{"offset":"2693988747","bids":[["10.785","136.9"]],"asks":[]}}
1635444231.381886: {"type":"channel_data","connection_id":"60a4fc71-1312-4830-86f4-9eb98be106ac","message_id":219,"id":"SUSHI-USD","channel":"v3_orderbook","contents":{"offset":"2693988751","bids":[["10.789","1543.9"]],"asks":[]}}
1635444231.381969: {"type":"channel_data","connection_id":"60a4fc71-1312-4830-86f4-9eb98be106ac","message_id":220,"id":"ETH-USD","channel":"v3_orderbook","contents":{"offset":"2693988753","bids":[["4214.5","0"]],"asks":[]}}
1635444231.38872: {"type":"channel_data","connection_id":"60a4fc71-1312-4830-86f4-9eb98be106ac","message_id":221,"id":"CRV-USD","channel":"v3_orderbook","contents":{"offset":"2693988762","bids":[],"asks":[["4.854","246"]]}}
1635444231.3971589: {"type":"channel_data","connection_id":"60a4fc71-1312-4830-86f4-9eb98be106ac","message_id":222,"id":"ETH-USD","channel":"v3_orderbook","contents":{"offset":"2693988769","bids":[],"asks":[["4217.6","0"]]}}
1635444231.400615: {"type":"channel_data","connection_id":"60a4fc71-1312-4830-86f4-9eb98be106ac","message_id":223,"id":"SUSHI-USD","channel":"v3_orderbook","contents":{"offset":"2693988775","bids":[["10.779","139"]],"asks":[]}}
1635444231.400683: {"type":"channel_data","connection_id":"60a4fc71-1312-4830-86f4-9eb98be106ac","message_id":224,"id":"SUSHI-USD","channel":"v3_orderbook","contents":{"offset":"2693988774","bids":[],"asks":[["10.8","1071.2"]]}}
1635444231.410114: {"type":"channel_data","connection_id":"60a4fc71-1312-4830-86f4-9eb98be106ac","message_id":225,"id":"ETH-USD","channel":"v3_orderbook","contents":{"offset":"2693988778","bids":[],"asks":[["4220","730.526"]]}}
1635444231.413313: {"type":"channel_data","connection_id":"60a4fc71-1312-4830-86f4-9eb98be106ac","message_id":226,"id":"ETH-USD","channel":"v3_orderbook","contents":{"offset":"2693988777","bids":[],"asks":[["4222.2","0"]]}}
1635444231.420893: {"type":"channel_data","connection_id":"60a4fc71-1312-4830-86f4-9eb98be106ac","message_id":227,"id":"ETH-USD","channel":"v3_orderbook","contents":{"offset":"2693988786","bids":[],"asks":[["4219","8.055"]]}}
1635444231.4285922: {"type":"channel_data","connection_id":"60a4fc71-1312-4830-86f4-9eb98be106ac","message_id":228,"id":"CRV-USD","channel":"v3_orderbook","contents":{"offset":"2693988783","bids":[],"asks":[["4.862","1841"]]}}
1635444231.4286919: {"type":"channel_data","connection_id":"60a4fc71-1312-4830-86f4-9eb98be106ac","message_id":229,"id":"ETH-USD","channel":"v3_orderbook","contents":{"offset":"2693988782","bids":[],"asks":[["4221.1","0"]]}}
1635444231.43389: {"type":"channel_data","connection_id":"60a4fc71-1312-4830-86f4-9eb98be106ac","message_id":230,"id":"ETH-USD","channel":"v3_orderbook","contents":{"offset":"2693988794","bids":[["4211.8","0"]],"asks":[]}}
1635444231.433972: {"type":"channel_data","connection_id":"60a4fc71-1312-4830-86f4-9eb98be106ac","message_id":231,"id":"CRV-USD","channel":"v3_orderbook","contents":{"offset":"2693988789","bids":[],"asks":[["4.854","1246"]]}}
1635444231.435067: {"type":"channel_data","connection_id":"60a4fc71-1312-4830-86f4-9eb98be106ac","message_id":232,"id":"SUSHI-USD","channel":"v3_orderbook","contents":{"offset":"2693988791","bids":[],"asks":[["11.167","1000"]]}}
1635444231.435149: {"type":"channel_data","connection_id":"60a4fc71-1312-4830-86f4-9eb98be106ac","message_id":233,"id":"SUSHI-USD","channel":"v3_orderbook","contents":{"offset":"2693988790","bids":[["10.773","325.6"]],"asks":[]}}
1635444231.43791: {"type":"channel_data","connection_id":"60a4fc71-1312-4830-86f4-9eb98be106ac","message_id":234,"id":"ETH-USD","channel":"v3_orderbook","contents":{"offset":"2693988793","bids":[["4214.6","0"]],"asks":[]}}
1635444231.444869: {"type":"channel_data","connection_id":"60a4fc71-1312-4830-86f4-9eb98be106ac","message_id":235,"id":"ETH-USD","channel":"v3_orderbook","contents":{"offset":"2693988797","bids":[["4208.9","0"]],"asks":[]}}
1635444231.444951: {"type":"channel_data","connection_id":"60a4fc71-1312-4830-86f4-9eb98be106ac","message_id":236,"id":"SUSHI-USD","channel":"v3_orderbook","contents":{"offset":"2693988798","bids":[["10.785","0"]],"asks":[]}}
1635444231.4449868: {"type":"channel_data","connection_id":"60a4fc71-1312-4830-86f4-9eb98be106ac","message_id":237,"id":"ETH-USD","channel":"v3_orderbook","contents":{"offset":"2693988800","bids":[],"asks":[["4220.5","5623.691"]]}}
1635444231.457862: {"type":"channel_data","connection_id":"60a4fc71-1312-4830-86f4-9eb98be106ac","message_id":238,"id":"ETH-USD","channel":"v3_orderbook","contents":{"offset":"2693988801","bids":[["4214.7","1.691"]],"asks":[]}}
1635444231.468339: {"type":"channel_data","connection_id":"60a4fc71-1312-4830-86f4-9eb98be106ac","message_id":239,"id":"ETH-USD","channel":"v3_orderbook","contents":{"offset":"2693988805","bids":[],"asks":[["4218","0.2"]]}}
1635444231.482568: {"type":"channel_data","connection_id":"60a4fc71-1312-4830-86f4-9eb98be106ac","message_id":240,"id":"ETH-USD","channel":"v3_orderbook","contents":{"offset":"2693988814","bids":[["4214.1","19.178"]],"asks":[]}}
1635444231.496145: {"type":"channel_data","connection_id":"60a4fc71-1312-4830-86f4-9eb98be106ac","message_id":241,"id":"ETH-USD","channel":"v3_orderbook","contents":{"offset":"2693988818","bids":[],"asks":[["4218.1","24.195"]]}}
1635444231.4962292: {"type":"channel_data","connection_id":"60a4fc71-1312-4830-86f4-9eb98be106ac","message_id":242,"id":"ETH-USD","channel":"v3_orderbook","contents":{"offset":"2693988822","bids":[["4214.3","7.215"]],"asks":[]}}
1635444231.497702: {"type":"channel_data","connection_id":"60a4fc71-1312-4830-86f4-9eb98be106ac","message_id":243,"id":"SUSHI-USD","channel":"v3_orderbook","contents":{"offset":"2693988823","bids":[],"asks":[["10.822","91676"]]}}
1635444231.507261: {"type":"channel_data","connection_id":"60a4fc71-1312-4830-86f4-9eb98be106ac","message_id":244,"id":"SUSHI-USD","channel":"v3_orderbook","contents":{"offset":"2693988825","bids":[],"asks":[["10.802","440.6"]]}}
1635444231.5073762: {"type":"channel_data","connection_id":"60a4fc71-1312-4830-86f4-9eb98be106ac","message_id":245,"id":"SUSHI-USD","channel":"v3_orderbook","contents":{"offset":"2693988826","bids":[["10.766","0"]],"asks":[]}}
1635444231.50948: {"type":"channel_data","connection_id":"60a4fc71-1312-4830-86f4-9eb98be106ac","message_id":246,"id":"CRV-USD","channel":"v3_orderbook","contents":{"offset":"2693988827","bids":[["4.846","2176"]],"asks":[]}}
1635444231.514605: {"type":"channel_data","connection_id":"60a4fc71-1312-4830-86f4-9eb98be106ac","message_id":247,"id":"CRV-USD","channel":"v3_orderbook","contents":{"offset":"2693988834","bids":[],"asks":[["4.854","246"]]}}
1635444231.524359: {"type":"channel_data","connection_id":"60a4fc71-1312-4830-86f4-9eb98be106ac","message_id":248,"id":"CRV-USD","channel":"v3_orderbook","contents":{"offset":"2693988836","bids":[["4.847","22511"]],"asks":[]}}
1635444231.527425: {"type":"channel_data","connection_id":"60a4fc71-1312-4830-86f4-9eb98be106ac","message_id":249,"id":"SUSHI-USD","channel":"v3_orderbook","contents":{"offset":"2693988837","bids":[["10.77","3713.9"]],"asks":[]}}
1635444231.527487: {"type":"channel_data","connection_id":"60a4fc71-1312-4830-86f4-9eb98be106ac","message_id":250,"id":"UMA-USD","channel":"v3_orderbook","contents":{"offset":"2693988840","bids":[["11.27","29416.2"]],"asks":[]}}
1635444231.540489: {"type":"channel_data","connection_id":"60a4fc71-1312-4830-86f4-9eb98be106ac","message_id":251,"id":"ETH-USD","channel":"v3_orderbook","contents":{"offset":"2693988844","bids":[],"asks":[["4219","10.668"]]}}
1635444231.552075: {"type":"channel_data","connection_id":"60a4fc71-1312-4830-86f4-9eb98be106ac","message_id":252,"id":"CRV-USD","channel":"v3_orderbook","contents":{"offset":"2693988850","bids":[],"asks":[["4.865","33465"]]}}
1635444231.552194: {"type":"channel_data","connection_id":"60a4fc71-1312-4830-86f4-9eb98be106ac","message_id":253,"id":"ETH-USD","channel":"v3_orderbook","contents":{"offset":"2693988851","bids":[],"asks":[["4220.4","1.511"]]}}
1635444231.5522492: {"type":"channel_data","connection_id":"60a4fc71-1312-4830-86f4-9eb98be106ac","message_id":254,"id":"UMA-USD","channel":"v3_orderbook","contents":{"offset":"2693988852","bids":[["11.27","29150.7"]],"asks":[]}}
1635444231.552295: {"type":"channel_data","connection_id":"60a4fc71-1312-4830-86f4-9eb98be106ac","message_id":255,"id":"SUSHI-USD","channel":"v3_orderbook","contents":{"offset":"2693988849","bids":[],"asks":[["10.866","0"],["10.871","2319.7"]]}}
1635444231.5641012: {"type":"channel_data","connection_id":"60a4fc71-1312-4830-86f4-9eb98be106ac","message_id":256,"id":"ETH-USD","channel":"v3_orderbook","contents":{"offset":"2693988858","bids":[],"asks":[["4217.5","56.581"]]}}
1635444231.564182: {"type":"channel_data","connection_id":"60a4fc71-1312-4830-86f4-9eb98be106ac","message_id":257,"id":"CRV-USD","channel":"v3_orderbook","contents":{"offset":"2693988853","bids":[],"asks":[["4.854","1246"]]}}
1635444231.576899: {"type":"channel_data","connection_id":"60a4fc71-1312-4830-86f4-9eb98be106ac","message_id":258,"id":"SUSHI-USD","channel":"v3_orderbook","contents":{"offset":"2693988861","bids":[],"asks":[["10.799","4482.3"]]}}
1635444231.589908: {"type":"channel_data","connection_id":"60a4fc71-1312-4830-86f4-9eb98be106ac","message_id":259,"id":"SUSHI-USD","channel":"v3_orderbook","contents":{"offset":"2693988863","bids":[["10.788","185.4"]],"asks":[]}}
1635444231.61257: {"type":"channel_data","connection_id":"60a4fc71-1312-4830-86f4-9eb98be106ac","message_id":260,"id":"ETH-USD","channel":"v3_orderbook","contents":{"offset":"2693988871","bids":[],"asks":[["4223.7","1.687"]]}}
1635444231.61549: {"type":"channel_data","connection_id":"60a4fc71-1312-4830-86f4-9eb98be106ac","message_id":261,"id":"ETH-USD","channel":"v3_orderbook","contents":{"offset":"2693988870","bids":[["4213","19.41"]],"asks":[]}}
1635444231.6155689: {"type":"channel_data","connection_id":"60a4fc71-1312-4830-86f4-9eb98be106ac","message_id":262,"id":"SUSHI-USD","channel":"v3_orderbook","contents":{"offset":"2693988872","bids":[],"asks":[["10.86","0"],["10.865","1372.2"]]}}
1635444231.615616: {"type":"channel_data","connection_id":"60a4fc71-1312-4830-86f4-9eb98be106ac","message_id":263,"id":"ETH-USD","channel":"v3_orderbook","contents":{"offset":"2693988873","bids":[],"asks":[["4220","731.948"]]}}
1635444231.6260421: {"type":"channel_data","connection_id":"60a4fc71-1312-4830-86f4-9eb98be106ac","message_id":264,"id":"ETH-USD","channel":"v3_orderbook","contents":{"offset":"2693988877","bids":[],"asks":[["4226.6","1.775"]]}}
1635444231.6408699: {"type":"channel_data","connection_id":"60a4fc71-1312-4830-86f4-9eb98be106ac","message_id":265,"id":"ETH-USD","channel":"v3_orderbook","contents":{"offset":"2693988882","bids":[],"asks":[["4220.2","1.541"]]}}
1635444231.640939: {"type":"channel_data","connection_id":"60a4fc71-1312-4830-86f4-9eb98be106ac","message_id":266,"id":"CRV-USD","channel":"v3_orderbook","contents":{"offset":"2693988884","bids":[["4.842","10251"]],"asks":[]}}
1635444231.6505868: {"type":"channel_data","connection_id":"60a4fc71-1312-4830-86f4-9eb98be106ac","message_id":267,"id":"ETH-USD","channel":"v3_orderbook","contents":{"offset":"2693988890","bids":[],"asks":[["4219.1","1.897"]]}}
1635444231.650649: {"type":"channel_data","connection_id":"60a4fc71-1312-4830-86f4-9eb98be106ac","message_id":268,"id":"CRV-USD","channel":"v3_orderbook","contents":{"offset":"2693988887","bids":[["4.847","14498"]],"asks":[]}}
1635444231.6506848: {"type":"channel_data","connection_id":"60a4fc71-1312-4830-86f4-9eb98be106ac","message_id":269,"id":"ETH-USD","channel":"v3_orderbook","contents":{"offset":"2693988891","bids":[],"asks":[["4219.9","2.727"]]}}
1635444231.6541069: {"type":"channel_data","connection_id":"60a4fc71-1312-4830-86f4-9eb98be106ac","message_id":270,"id":"ETH-USD","channel":"v3_orderbook","contents":{"offset":"2693988889","bids":[],"asks":[["4221.2","0"]]}}
1635444231.665066: {"type":"channel_data","connection_id":"60a4fc71-1312-4830-86f4-9eb98be106ac","message_id":271,"id":"ETH-USD","channel":"v3_orderbook","contents":{"offset":"2693988894","bids":[],"asks":[["4225","0.2"]]}}
1635444231.676034: {"type":"channel_data","connection_id":"60a4fc71-1312-4830-86f4-9eb98be106ac","message_id":272,"id":"ETH-USD","channel":"v3_orderbook","contents":{"offset":"2693988900","bids":[],"asks":[["4219.3","1.94"]]}}
1635444231.6761248: {"type":"channel_data","connection_id":"60a4fc71-1312-4830-86f4-9eb98be106ac","message_id":273,"id":"ETH-USD","channel":"v3_orderbook","contents":{"offset":"2693988899","bids":[],"asks":[["4219.9","4.71"]]}}
1635444231.7019699: {"type":"channel_data","connection_id":"60a4fc71-1312-4830-86f4-9eb98be106ac","message_id":274,"id":"SUSHI-USD","channel":"v3_orderbook","contents":{"offset":"2693988905","bids":[["10.765","1811.6"],["10.759","15"]],"asks":[]}}
1635444231.7226691: {"type":"channel_data","connection_id":"60a4fc71-1312-4830-86f4-9eb98be106ac","message_id":275,"id":"ETH-USD","channel":"v3_orderbook","contents":{"offset":"2693988910","bids":[["4214.8","64.017"]],"asks":[]}}
1635444231.729056: {"type":"channel_data","connection_id":"60a4fc71-1312-4830-86f4-9eb98be106ac","message_id":276,"id":"SUSHI-USD","channel":"v3_orderbook","contents":{"offset":"2693988914","bids":[["10.684","940.9"],["10.682","12467.4"]],"asks":[]}}
1635444231.732615: {"type":"channel_data","connection_id":"60a4fc71-1312-4830-86f4-9eb98be106ac","message_id":277,"id":"ETH-USD","channel":"v3_orderbook","contents":{"offset":"2693988918","bids":[["4214.1","0.852"]],"asks":[]}}
1635444231.7326982: {"type":"channel_data","connection_id":"60a4fc71-1312-4830-86f4-9eb98be106ac","message_id":278,"id":"SUSHI-USD","channel":"v3_orderbook","contents":{"offset":"2693988913","bids":[],"asks":[["10.815","1099.7"]]}}
1635444231.7430851: {"type":"channel_data","connection_id":"60a4fc71-1312-4830-86f4-9eb98be106ac","message_id":279,"id":"ETH-USD","channel":"v3_orderbook","contents":{"offset":"2693988922","bids":[],"asks":[["4240","70.03"],["4240.1","14.227"]]}}
1635444231.743179: {"type":"channel_data","connection_id":"60a4fc71-1312-4830-86f4-9eb98be106ac","message_id":280,"id":"UNI-USD","channel":"v3_orderbook","contents":{"offset":"2693988923","bids":[],"asks":[["25.206","0"],["25.208","998.8"]]}}
1635444231.765677: {"type":"channel_data","connection_id":"60a4fc71-1312-4830-86f4-9eb98be106ac","message_id":281,"id":"SUSHI-USD","channel":"v3_orderbook","contents":{"offset":"2693988926","bids":[],"asks":[["10.813","333"]]}}
1635444231.765783: {"type":"channel_data","connection_id":"60a4fc71-1312-4830-86f4-9eb98be106ac","message_id":282,"id":"SUSHI-USD","channel":"v3_orderbook","contents":{"offset":"2693988927","bids":[["10.79","266.5"]],"asks":[]}}
1635444231.779582: {"type":"channel_data","connection_id":"60a4fc71-1312-4830-86f4-9eb98be106ac","message_id":283,"id":"ETH-USD","channel":"v3_orderbook","contents":{"offset":"2693988935","bids":[],"asks":[["4224.3","17.755"]]}}
1635444231.779652: {"type":"channel_data","connection_id":"60a4fc71-1312-4830-86f4-9eb98be106ac","message_id":284,"id":"UNI-USD","channel":"v3_orderbook","contents":{"offset":"2693988936","bids":[],"asks":[["25.168","0"],["25.17","1067.1"]]}}
1635444231.791004: {"type":"channel_data","connection_id":"60a4fc71-1312-4830-86f4-9eb98be106ac","message_id":285,"id":"SUSHI-USD","channel":"v3_orderbook","contents":{"offset":"2693988939","bids":[],"asks":[["10.811","400.7"]]}}
1635444231.7944179: {"type":"channel_data","connection_id":"60a4fc71-1312-4830-86f4-9eb98be106ac","message_id":286,"id":"SUSHI-USD","channel":"v3_orderbook","contents":{"offset":"2693988942","bids":[],"asks":[["10.809","295.3"]]}}
1635444231.794484: {"type":"channel_data","connection_id":"60a4fc71-1312-4830-86f4-9eb98be106ac","message_id":287,"id":"ETH-USD","channel":"v3_orderbook","contents":{"offset":"2693988937","bids":[],"asks":[["4215.6","9.4"]]}}
1635444231.805207: {"type":"channel_data","connection_id":"60a4fc71-1312-4830-86f4-9eb98be106ac","message_id":288,"id":"ETH-USD","channel":"v3_orderbook","contents":{"offset":"2693988949","bids":[],"asks":[["4219.7","1.422"]]}}
1635444231.805266: {"type":"channel_data","connection_id":"60a4fc71-1312-4830-86f4-9eb98be106ac","message_id":289,"id":"ETH-USD","channel":"v3_orderbook","contents":{"offset":"2693988951","bids":[],"asks":[["4221.8","1.599"]]}}
1635444231.8053: {"type":"channel_data","connection_id":"60a4fc71-1312-4830-86f4-9eb98be106ac","message_id":290,"id":"ETH-USD","channel":"v3_orderbook","contents":{"offset":"2693988950","bids":[],"asks":[["4223.5","1.776"]]}}
1635444231.807113: {"type":"channel_data","connection_id":"60a4fc71-1312-4830-86f4-9eb98be106ac","message_id":291,"id":"ETH-USD","channel":"v3_trades","contents":{"trades":[{"size":"0.1","side":"BUY","price":"4215.6","createdAt":"2021-10-28T18:03:51.833Z"}]}}
1635444231.817356: {"type":"channel_data","connection_id":"60a4fc71-1312-4830-86f4-9eb98be106ac","message_id":292,"id":"CRV-USD","channel":"v3_orderbook","contents":{"offset":"2693988955","bids":[["4.819","8152"],["4.818","947"]],"asks":[]}}
1635444231.83313: {"type":"channel_data","connection_id":"60a4fc71-1312-4830-86f4-9eb98be106ac","message_id":293,"id":"CRV-USD","channel":"v3_orderbook","contents":{"offset":"2693988957","bids":[["4.824","8160"],["4.823","0"]],"asks":[]}}
1635444231.843754: {"type":"channel_data","connection_id":"60a4fc71-1312-4830-86f4-9eb98be106ac","message_id":294,"id":"ETH-USD","channel":"v3_orderbook","contents":{"offset":"2693988965","bids":[["4212.5","56.304"]],"asks":[]}}
1635444231.848657: {"type":"channel_data","connection_id":"60a4fc71-1312-4830-86f4-9eb98be106ac","message_id":295,"id":"ETH-USD","channel":"v3_orderbook","contents":{"offset":"2693988961","bids":[["4214.4","17.523"]],"asks":[]}}
1635444231.85986: {"type":"channel_data","connection_id":"60a4fc71-1312-4830-86f4-9eb98be106ac","message_id":296,"id":"ETH-USD","channel":"v3_orderbook","contents":{"offset":"2693988975","bids":[],"asks":[["4221.7","1.599"]]}}
1635444231.85993: {"type":"channel_data","connection_id":"60a4fc71-1312-4830-86f4-9eb98be106ac","message_id":297,"id":"SUSHI-USD","channel":"v3_orderbook","contents":{"offset":"2693988974","bids":[["10.789","334.7"]],"asks":[]}}
1635444231.85996: {"type":"channel_data","connection_id":"60a4fc71-1312-4830-86f4-9eb98be106ac","message_id":298,"id":"ETH-USD","channel":"v3_orderbook","contents":{"offset":"2693988972","bids":[],"asks":[["4219.1","0"]]}}
1635444231.859984: {"type":"channel_data","connection_id":"60a4fc71-1312-4830-86f4-9eb98be106ac","message_id":299,"id":"ETH-USD","channel":"v3_orderbook","contents":{"offset":"2693988976","bids":[],"asks":[["4216.7","137.943"]]}}
1635444231.869649: {"type":"channel_data","connection_id":"60a4fc71-1312-4830-86f4-9eb98be106ac","message_id":300,"id":"SUSHI-USD","channel":"v3_orderbook","contents":{"offset":"2693988978","bids":[["10.791","1209.2"]],"asks":[]}}
1635444231.86974: {"type":"channel_data","connection_id":"60a4fc71-1312-4830-86f4-9eb98be106ac","message_id":301,"id":"XMR-USD","channel":"v3_orderbook","contents":{"offset":"2693988981","bids":[["265","75.75"]],"asks":[]}}
1635444231.869833: {"type":"channel_data","connection_id":"60a4fc71-1312-4830-86f4-9eb98be106ac","message_id":302,"id":"XMR-USD","channel":"v3_orderbook","contents":{"offset":"2693988980","bids":[["264.7","434.34"]],"asks":[]}}
1635444231.8812668: {"type":"channel_data","connection_id":"60a4fc71-1312-4830-86f4-9eb98be106ac","message_id":303,"id":"XMR-USD","channel":"v3_orderbook","contents":{"offset":"2693988984","bids":[],"asks":[["265.7","2833.41"]]}}
1635444231.890898: {"type":"channel_data","connection_id":"60a4fc71-1312-4830-86f4-9eb98be106ac","message_id":304,"id":"XMR-USD","channel":"v3_orderbook","contents":{"offset":"2693988992","bids":[],"asks":[["265.3","0"]]}}
1635444231.890961: {"type":"channel_data","connection_id":"60a4fc71-1312-4830-86f4-9eb98be106ac","message_id":305,"id":"ETH-USD","channel":"v3_orderbook","contents":{"offset":"2693988993","bids":[],"asks":[["4219.6","78.38"]]}}
1635444231.9004831: {"type":"channel_data","connection_id":"60a4fc71-1312-4830-86f4-9eb98be106ac","message_id":306,"id":"ETH-USD","channel":"v3_orderbook","contents":{"offset":"2693988999","bids":[],"asks":[["4219.5","0"]]}}
1635444231.900543: {"type":"channel_data","connection_id":"60a4fc71-1312-4830-86f4-9eb98be106ac","message_id":307,"id":"ETH-USD","channel":"v3_orderbook","contents":{"offset":"2693988995","bids":[["4214.4","0.355"]],"asks":[]}}
1635444231.910197: {"type":"channel_data","connection_id":"60a4fc71-1312-4830-86f4-9eb98be106ac","message_id":308,"id":"ETH-USD","channel":"v3_orderbook","contents":{"offset":"2693989002","bids":[],"asks":[["4225.5","2.152"]]}}
1635444231.9677958: {"type":"channel_data","connection_id":"60a4fc71-1312-4830-86f4-9eb98be106ac","message_id":309,"id":"ETH-USD","channel":"v3_orderbook","contents":{"offset":"2693989026","bids":[["4215.5","502.095"]],"asks":[]}}
1635444231.968394: {"type":"channel_data","connection_id":"60a4fc71-1312-4830-86f4-9eb98be106ac","message_id":310,"id":"SUSHI-USD","channel":"v3_orderbook","contents":{"offset":"2693989029","bids":[],"asks":[["10.921","927.3"]]}}
1635444231.988582: {"type":"channel_data","connection_id":"60a4fc71-1312-4830-86f4-9eb98be106ac","message_id":311,"id":"ETH-USD","channel":"v3_orderbook","contents":{"offset":"2693989041","bids":[["4210.5","1.817"],["4209","0"]],"asks":[]}}
1635444231.9996412: {"type":"channel_data","connection_id":"60a4fc71-1312-4830-86f4-9eb98be106ac","message_id":312,"id":"SUSHI-USD","channel":"v3_orderbook","contents":{"offset":"2693989046","bids":[],"asks":[["10.807","11944.2"]]}}
1635444232.023903: {"type":"channel_data","connection_id":"60a4fc71-1312-4830-86f4-9eb98be106ac","message_id":313,"id":"UMA-USD","channel":"v3_orderbook","contents":{"offset":"2693989056","bids":[["11.27","29416.2"]],"asks":[]}}
1635444232.033563: {"type":"channel_data","connection_id":"60a4fc71-1312-4830-86f4-9eb98be106ac","message_id":314,"id":"ETH-USD","channel":"v3_orderbook","contents":{"offset":"2693989059","bids":[],"asks":[["4219","28.275"]]}}
1635444232.0534909: {"type":"channel_data","connection_id":"60a4fc71-1312-4830-86f4-9eb98be106ac","message_id":315,"id":"UMA-USD","channel":"v3_orderbook","contents":{"offset":"2693989061","bids":[["11.27","29150.7"]],"asks":[]}}
1635444232.065139: {"type":"channel_data","connection_id":"60a4fc71-1312-4830-86f4-9eb98be106ac","message_id":316,"id":"ETH-USD","channel":"v3_orderbook","contents":{"offset":"2693989069","bids":[["4214.1","19.868"]],"asks":[]}}
1635444232.0771399: {"type":"channel_data","connection_id":"60a4fc71-1312-4830-86f4-9eb98be106ac","message_id":317,"id":"EOS-USD","channel":"v3_orderbook","contents":{"offset":"2693989075","bids":[["4.394","1267"]],"asks":[]}}
1635444232.077209: {"type":"channel_data","connection_id":"60a4fc71-1312-4830-86f4-9eb98be106ac","message_id":318,"id":"UMA-USD","channel":"v3_orderbook","contents":{"offset":"2693989076","bids":[],"asks":[["11.34","389"]]}}
1635444232.101514: {"type":"channel_data","connection_id":"60a4fc71-1312-4830-86f4-9eb98be106ac","message_id":319,"id":"UMA-USD","channel":"v3_orderbook","contents":{"offset":"2693989082","bids":[],"asks":[["11.33","28317.9"]]}}
1635444232.120587: {"type":"channel_data","connection_id":"60a4fc71-1312-4830-86f4-9eb98be106ac","message_id":320,"id":"ETH-USD","channel":"v3_orderbook","contents":{"offset":"2693989087","bids":[],"asks":[["4218.8","0"]]}}
1635444232.154718: {"type":"channel_data","connection_id":"60a4fc71-1312-4830-86f4-9eb98be106ac","message_id":321,"id":"ETH-USD","channel":"v3_orderbook","contents":{"offset":"2693989093","bids":[["4214.1","0.852"]],"asks":[]}}
1635444232.2208378: {"type":"channel_data","connection_id":"60a4fc71-1312-4830-86f4-9eb98be106ac","message_id":322,"id":"ETH-USD","channel":"v3_orderbook","contents":{"offset":"2693989118","bids":[["4210","0.21"]],"asks":[]}}
1635444232.220924: {"type":"channel_data","connection_id":"60a4fc71-1312-4830-86f4-9eb98be106ac","message_id":323,"id":"ETH-USD","channel":"v3_orderbook","contents":{"offset":"2693989122","bids":[["4214.4","17.492"]],"asks":[]}}
1635444232.2347572: {"type":"channel_data","connection_id":"60a4fc71-1312-4830-86f4-9eb98be106ac","message_id":324,"id":"ETH-USD","channel":"v3_orderbook","contents":{"offset":"2693989127","bids":[["4215.5","524.591"]],"asks":[]}}
1635444232.2348852: {"type":"channel_data","connection_id":"60a4fc71-1312-4830-86f4-9eb98be106ac","message_id":325,"id":"ETH-USD","channel":"v3_orderbook","contents":{"offset":"2693989126","bids":[],"asks":[["4222.2","0.2"]]}}
1635444232.2707179: {"type":"channel_data","connection_id":"60a4fc71-1312-4830-86f4-9eb98be106ac","message_id":326,"id":"ETH-USD","channel":"v3_orderbook","contents":{"offset":"2693989131","bids":[["4214.4","0.355"]],"asks":[]}}
1635444232.2708101: {"type":"channel_data","connection_id":"60a4fc71-1312-4830-86f4-9eb98be106ac","message_id":327,"id":"CRV-USD","channel":"v3_orderbook","contents":{"offset":"2693989130","bids":[["4.82","7227"],["4.819","925"]],"asks":[]}}
1635444232.270852: {"type":"channel_data","connection_id":"60a4fc71-1312-4830-86f4-9eb98be106ac","message_id":328,"id":"SUSHI-USD","channel":"v3_orderbook","contents":{"offset":"2693989128","bids":[["10.779","540.8"]],"asks":[]}}
1635444232.270883: {"type":"channel_data","connection_id":"60a4fc71-1312-4830-86f4-9eb98be106ac","message_id":329,"id":"SUSHI-USD","channel":"v3_orderbook","contents":{"offset":"2693989129","bids":[],"asks":[["10.807","12330.9"]]}}
1635444232.2709088: {"type":"channel_data","connection_id":"60a4fc71-1312-4830-86f4-9eb98be106ac","message_id":330,"id":"SUSHI-USD","channel":"v3_orderbook","contents":{"offset":"2693989133","bids":[["10.783","4656.5"]],"asks":[]}}
1635444232.273613: {"type":"channel_data","connection_id":"60a4fc71-1312-4830-86f4-9eb98be106ac","message_id":331,"id":"ETH-USD","channel":"v3_orderbook","contents":{"offset":"2693989132","bids":[],"asks":[["4217.9","22.496"]]}}
1635444232.2927449: {"type":"channel_data","connection_id":"60a4fc71-1312-4830-86f4-9eb98be106ac","message_id":332,"id":"CRV-USD","channel":"v3_orderbook","contents":{"offset":"2693989134","bids":[["4.825","7227"],["4.824","933"]],"asks":[]}}
1635444232.292834: {"type":"channel_data","connection_id":"60a4fc71-1312-4830-86f4-9eb98be106ac","message_id":333,"id":"XMR-USD","channel":"v3_orderbook","contents":{"offset":"2693989136","bids":[["265","151.22"]],"asks":[]}}
1635444232.2928698: {"type":"channel_data","connection_id":"60a4fc71-1312-4830-86f4-9eb98be106ac","message_id":334,"id":"XMR-USD","channel":"v3_orderbook","contents":{"offset":"2693989137","bids":[],"asks":[["265.3","75.39"]]}}
1635444232.3034198: {"type":"channel_data","connection_id":"60a4fc71-1312-4830-86f4-9eb98be106ac","message_id":335,"id":"ETH-USD","channel":"v3_orderbook","contents":{"offset":"2693989141","bids":[["4213.2","1350.09"]],"asks":[]}}
1635444232.303505: {"type":"channel_data","connection_id":"60a4fc71-1312-4830-86f4-9eb98be106ac","message_id":336,"id":"XMR-USD","channel":"v3_orderbook","contents":{"offset":"2693989143","bids":[["264.7","736.22"]],"asks":[]}}
1635444232.308737: {"type":"channel_data","connection_id":"60a4fc71-1312-4830-86f4-9eb98be106ac","message_id":337,"id":"ETH-USD","channel":"v3_orderbook","contents":{"offset":"2693989142","bids":[["4214","80.051"]],"asks":[]}}
1635444232.308824: {"type":"channel_data","connection_id":"60a4fc71-1312-4830-86f4-9eb98be106ac","message_id":338,"id":"XMR-USD","channel":"v3_orderbook","contents":{"offset":"2693989140","bids":[],"asks":[["265.6","339.58"]]}}
1635444232.312042: {"type":"channel_data","connection_id":"60a4fc71-1312-4830-86f4-9eb98be106ac","message_id":339,"id":"ETH-USD","channel":"v3_orderbook","contents":{"offset":"2693989146","bids":[["4214.9","0"]],"asks":[]}}
1635444232.3583748: {"type":"channel_data","connection_id":"60a4fc71-1312-4830-86f4-9eb98be106ac","message_id":340,"id":"ETH-USD","channel":"v3_orderbook","contents":{"offset":"2693989151","bids":[["4214.1","20.332"]],"asks":[]}}
1635444232.358508: {"type":"channel_data","connection_id":"60a4fc71-1312-4830-86f4-9eb98be106ac","message_id":341,"id":"BCH-USD","channel":"v3_orderbook","contents":{"offset":"2693989153","bids":[["571.7","0"],["571.6","60.93"]],"asks":[]}}
1635444232.369236: {"type":"channel_data","connection_id":"60a4fc71-1312-4830-86f4-9eb98be106ac","message_id":342,"id":"ETH-USD","channel":"v3_orderbook","contents":{"offset":"2693989155","bids":[],"asks":[["4240","81.898"],["4240.1","2.359"]]}}
1635444232.404076: {"type":"channel_data","connection_id":"60a4fc71-1312-4830-86f4-9eb98be106ac","message_id":343,"id":"ETH-USD","channel":"v3_orderbook","contents":{"offset":"2693989166","bids":[],"asks":[["4220.8","2.025"]]}}
1635444232.417171: {"type":"channel_data","connection_id":"60a4fc71-1312-4830-86f4-9eb98be106ac","message_id":344,"id":"ETH-USD","channel":"v3_orderbook","contents":{"offset":"2693989167","bids":[],"asks":[["4222.1","6.764"]]}}
1635444232.41821: {"type":"channel_data","connection_id":"60a4fc71-1312-4830-86f4-9eb98be106ac","message_id":345,"id":"ETH-USD","channel":"v3_orderbook","contents":{"offset":"2693989171","bids":[["4215.5","521.752"]],"asks":[]}}
1635444232.448355: {"type":"channel_data","connection_id":"60a4fc71-1312-4830-86f4-9eb98be106ac","message_id":346,"id":"ETH-USD","channel":"v3_orderbook","contents":{"offset":"2693989178","bids":[["4214.9","2.839"]],"asks":[]}}
1635444232.46: {"type":"channel_data","connection_id":"60a4fc71-1312-4830-86f4-9eb98be106ac","message_id":347,"id":"CRV-USD","channel":"v3_orderbook","contents":{"offset":"2693989181","bids":[["4.842","2238"]],"asks":[]}}
1635444232.460083: {"type":"channel_data","connection_id":"60a4fc71-1312-4830-86f4-9eb98be106ac","message_id":348,"id":"SUSHI-USD","channel":"v3_orderbook","contents":{"offset":"2693989180","bids":[],"asks":[["10.803","278.5"]]}}
1635444232.483694: {"type":"channel_data","connection_id":"60a4fc71-1312-4830-86f4-9eb98be106ac","message_id":349,"id":"CRV-USD","channel":"v3_orderbook","contents":{"offset":"2693989184","bids":[["4.847","22511"]],"asks":[]}}
1635444232.488244: {"type":"channel_data","connection_id":"60a4fc71-1312-4830-86f4-9eb98be106ac","message_id":350,"id":"CRV-USD","channel":"v3_orderbook","contents":{"offset":"2693989188","bids":[],"asks":[["4.854","246"]]}}
1635444232.501899: {"type":"channel_data","connection_id":"60a4fc71-1312-4830-86f4-9eb98be106ac","message_id":351,"id":"CRV-USD","channel":"v3_orderbook","contents":{"offset":"2693989193","bids":[],"asks":[["4.854","1246"]]}}
1635444232.5092149: {"type":"channel_data","connection_id":"60a4fc71-1312-4830-86f4-9eb98be106ac","message_id":352,"id":"SUSHI-USD","channel":"v3_orderbook","contents":{"offset":"2693989194","bids":[],"asks":[["10.921","927.2"]]}}
1635444232.535926: {"type":"channel_data","connection_id":"60a4fc71-1312-4830-86f4-9eb98be106ac","message_id":353,"id":"UMA-USD","channel":"v3_orderbook","contents":{"offset":"2693989200","bids":[["11.27","29416.1"]],"asks":[]}}
1635444232.556118: {"type":"channel_data","connection_id":"60a4fc71-1312-4830-86f4-9eb98be106ac","message_id":354,"id":"ETH-USD","channel":"v3_orderbook","contents":{"offset":"2693989208","bids":[],"asks":[["4219.3","0"]]}}
1635444232.5724711: {"type":"channel_data","connection_id":"60a4fc71-1312-4830-86f4-9eb98be106ac","message_id":355,"id":"XMR-USD","channel":"v3_orderbook","contents":{"offset":"2693989214","bids":[["265","75.47"]],"asks":[]}}
1635444232.572557: {"type":"channel_data","connection_id":"60a4fc71-1312-4830-86f4-9eb98be106ac","message_id":356,"id":"UMA-USD","channel":"v3_orderbook","contents":{"offset":"2693989212","bids":[["11.27","29150.7"]],"asks":[]}}
1635444232.5829408: {"type":"channel_data","connection_id":"60a4fc71-1312-4830-86f4-9eb98be106ac","message_id":357,"id":"XMR-USD","channel":"v3_orderbook","contents":{"offset":"2693989216","bids":[],"asks":[["265.3","0"]]}}
1635444232.5928268: {"type":"channel_data","connection_id":"60a4fc71-1312-4830-86f4-9eb98be106ac","message_id":358,"id":"LTC-USD","channel":"v3_orderbook","contents":{"offset":"2693989221","bids":[["187.4","423.83"],["187.3","53379.88"]],"asks":[]}}
1635444232.608022: {"type":"channel_data","connection_id":"60a4fc71-1312-4830-86f4-9eb98be106ac","message_id":359,"id":"CRV-USD","channel":"v3_orderbook","contents":{"offset":"2693989226","bids":[["4.842","0"]],"asks":[]}}
1635444232.61097: {"type":"channel_data","connection_id":"60a4fc71-1312-4830-86f4-9eb98be106ac","message_id":360,"id":"CRV-USD","channel":"v3_orderbook","contents":{"offset":"2693989230","bids":[],"asks":[["4.862","1249"]]}}
1635444232.6110148: {"type":"channel_data","connection_id":"60a4fc71-1312-4830-86f4-9eb98be106ac","message_id":361,"id":"ETH-USD","channel":"v3_orderbook","contents":{"offset":"2693989225","bids":[],"asks":[["4218.8","1.897"]]}}
1635444232.6427991: {"type":"channel_data","connection_id":"60a4fc71-1312-4830-86f4-9eb98be106ac","message_id":362,"id":"CRV-USD","channel":"v3_orderbook","contents":{"offset":"2693989243","bids":[["4.834","1055"]],"asks":[]}}
1635444232.654644: {"type":"channel_data","connection_id":"60a4fc71-1312-4830-86f4-9eb98be106ac","message_id":363,"id":"CRV-USD","channel":"v3_orderbook","contents":{"offset":"2693989251","bids":[],"asks":[["4.865","30964"]]}}
1635444232.6562839: {"type":"channel_data","connection_id":"60a4fc71-1312-4830-86f4-9eb98be106ac","message_id":364,"id":"CRV-USD","channel":"v3_orderbook","contents":{"offset":"2693989252","bids":[["4.831","0"]],"asks":[]}}
1635444232.667089: {"type":"channel_data","connection_id":"60a4fc71-1312-4830-86f4-9eb98be106ac","message_id":365,"id":"CRV-USD","channel":"v3_orderbook","contents":{"offset":"2693989254","bids":[["4.85","1124"]],"asks":[]}}
1635444232.6788402: {"type":"channel_data","connection_id":"60a4fc71-1312-4830-86f4-9eb98be106ac","message_id":366,"id":"ETH-USD","channel":"v3_orderbook","contents":{"offset":"2693989259","bids":[["4213.9","57.11"]],"asks":[]}}
1635444232.678947: {"type":"channel_data","connection_id":"60a4fc71-1312-4830-86f4-9eb98be106ac","message_id":367,"id":"CRV-USD","channel":"v3_orderbook","contents":{"offset":"2693989256","bids":[["4.848","2838"]],"asks":[]}}
1635444232.703933: {"type":"channel_data","connection_id":"60a4fc71-1312-4830-86f4-9eb98be106ac","message_id":368,"id":"ETH-USD","channel":"v3_orderbook","contents":{"offset":"2693989267","bids":[["4215.5","521.652"]],"asks":[]}}
1635444232.7040482: {"type":"channel_data","connection_id":"60a4fc71-1312-4830-86f4-9eb98be106ac","message_id":369,"id":"ETH-USD","channel":"v3_orderbook","contents":{"offset":"2693989278","bids":[["4215.5","522.534"]],"asks":[]}}
1635444232.7083972: {"type":"channel_data","connection_id":"60a4fc71-1312-4830-86f4-9eb98be106ac","message_id":370,"id":"SUSHI-USD","channel":"v3_orderbook","contents":{"offset":"2693989274","bids":[["10.786","8190.6"]],"asks":[]}}
1635444232.711431: {"type":"channel_data","connection_id":"60a4fc71-1312-4830-86f4-9eb98be106ac","message_id":371,"id":"SUSHI-USD","channel":"v3_orderbook","contents":{"offset":"2693989280","bids":[["10.787","4482.3"]],"asks":[]}}
1635444232.713491: {"type":"channel_data","connection_id":"60a4fc71-1312-4830-86f4-9eb98be106ac","message_id":372,"id":"ETH-USD","channel":"v3_orderbook","contents":{"offset":"2693989285","bids":[],"asks":[["4218.4","1399.754"]]}}
1635444232.713537: {"type":"channel_data","connection_id":"60a4fc71-1312-4830-86f4-9eb98be106ac","message_id":373,"id":"CRV-USD","channel":"v3_orderbook","contents":{"offset":"2693989288","bids":[["4.821","97885"],["4.82","0"]],"asks":[]}}
1635444232.717509: {"type":"channel_data","connection_id":"60a4fc71-1312-4830-86f4-9eb98be106ac","message_id":374,"id":"SUSHI-USD","channel":"v3_orderbook","contents":{"offset":"2693989289","bids":[["10.411","1000"]],"asks":[]}}
1635444232.717576: {"type":"channel_data","connection_id":"60a4fc71-1312-4830-86f4-9eb98be106ac","message_id":375,"id":"ETH-USD","channel":"v3_trades","contents":{"trades":[{"size":"0.1","side":"SELL","price":"4215.5","createdAt":"2021-10-28T18:03:52.741Z"}]}}
1635444232.720908: {"type":"channel_data","connection_id":"60a4fc71-1312-4830-86f4-9eb98be106ac","message_id":376,"id":"ETH-USD","channel":"v3_orderbook","contents":{"offset":"2693989276","bids":[],"asks":[["4217.5","115.461"]]}}
1635444232.729643: {"type":"channel_data","connection_id":"60a4fc71-1312-4830-86f4-9eb98be106ac","message_id":377,"id":"ETH-USD","channel":"v3_orderbook","contents":{"offset":"2693989284","bids":[],"asks":[["4216.7","114.21"]]}}
1635444232.729695: {"type":"channel_data","connection_id":"60a4fc71-1312-4830-86f4-9eb98be106ac","message_id":378,"id":"SUSHI-USD","channel":"v3_orderbook","contents":{"offset":"2693989303","bids":[],"asks":[["10.806","3743.9"]]}}
1635444232.7350888: {"type":"channel_data","connection_id":"60a4fc71-1312-4830-86f4-9eb98be106ac","message_id":379,"id":"SUSHI-USD","channel":"v3_orderbook","contents":{"offset":"2693989313","bids":[],"asks":[["10.809","600.7"]]}}
1635444232.7380438: {"type":"channel_data","connection_id":"60a4fc71-1312-4830-86f4-9eb98be106ac","message_id":380,"id":"SUSHI-USD","channel":"v3_orderbook","contents":{"offset":"2693989300","bids":[["10.786","3708.3"]],"asks":[]}}
1635444232.7437031: {"type":"channel_data","connection_id":"60a4fc71-1312-4830-86f4-9eb98be106ac","message_id":381,"id":"SUSHI-USD","channel":"v3_orderbook","contents":{"offset":"2693989317","bids":[["10.787","4778.1"]],"asks":[]}}
1635444232.754508: {"type":"channel_data","connection_id":"60a4fc71-1312-4830-86f4-9eb98be106ac","message_id":382,"id":"CRV-USD","channel":"v3_orderbook","contents":{"offset":"2693989323","bids":[["4.839","100049"]],"asks":[]}}
1635444232.754591: {"type":"channel_data","connection_id":"60a4fc71-1312-4830-86f4-9eb98be106ac","message_id":383,"id":"CRV-USD","channel":"v3_orderbook","contents":{"offset":"2693989324","bids":[["4.851","6856"]],"asks":[]}}
1635444232.754626: {"type":"channel_data","connection_id":"60a4fc71-1312-4830-86f4-9eb98be106ac","message_id":384,"id":"ETH-USD","channel":"v3_orderbook","contents":{"offset":"2693989327","bids":[],"asks":[["4218.4","1389.97"]]}}
1635444232.754657: {"type":"channel_data","connection_id":"60a4fc71-1312-4830-86f4-9eb98be106ac","message_id":385,"id":"ETH-USD","channel":"v3_orderbook","contents":{"offset":"2693989325","bids":[["4207.3","1.305"]],"asks":[]}}
1635444232.756624: {"type":"channel_data","connection_id":"60a4fc71-1312-4830-86f4-9eb98be106ac","message_id":386,"id":"XMR-USD","channel":"v3_orderbook","contents":{"offset":"2693989322","bids":[],"asks":[["265.4","362.11"]]}}
1635444232.768518: {"type":"channel_data","connection_id":"60a4fc71-1312-4830-86f4-9eb98be106ac","message_id":387,"id":"CRV-USD","channel":"v3_orderbook","contents":{"offset":"2693989329","bids":[["4.826","7227"],["4.825","0"]],"asks":[]}}
1635444232.78126: {"type":"channel_data","connection_id":"60a4fc71-1312-4830-86f4-9eb98be106ac","message_id":388,"id":"ETH-USD","channel":"v3_orderbook","contents":{"offset":"2693989339","bids":[["4215.5","516.601"]],"asks":[]}}
1635444232.793679: {"type":"channel_data","connection_id":"60a4fc71-1312-4830-86f4-9eb98be106ac","message_id":389,"id":"CRV-USD","channel":"v3_orderbook","contents":{"offset":"2693989349","bids":[],"asks":[["4.862","657"]]}}
1635444232.800995: {"type":"channel_data","connection_id":"60a4fc71-1312-4830-86f4-9eb98be106ac","message_id":390,"id":"UNI-USD","channel":"v3_orderbook","contents":{"offset":"2693989358","bids":[],"asks":[["25.192","0"],["25.195","1997.7"]]}}
1635444232.8031518: {"type":"channel_data","connection_id":"60a4fc71-1312-4830-86f4-9eb98be106ac","message_id":391,"id":"ETH-USD","channel":"v3_orderbook","contents":{"offset":"2693989359","bids":[],"asks":[["4218.8","58.997"]]}}
1635444232.803786: {"type":"channel_data","connection_id":"60a4fc71-1312-4830-86f4-9eb98be106ac","message_id":392,"id":"EOS-USD","channel":"v3_orderbook","contents":{"offset":"2693989361","bids":[],"asks":[["4.404","14965"]]}}
1635444232.813618: {"type":"channel_data","connection_id":"60a4fc71-1312-4830-86f4-9eb98be106ac","message_id":393,"id":"EOS-USD","channel":"v3_orderbook","contents":{"offset":"2693989364","bids":[["4.398","27529"]],"asks":[]}}
1635444232.815547: {"type":"channel_data","connection_id":"60a4fc71-1312-4830-86f4-9eb98be106ac","message_id":394,"id":"EOS-USD","channel":"v3_orderbook","contents":{"offset":"2693989367","bids":[],"asks":[["4.402","0"]]}}
1635444232.815596: {"type":"channel_data","connection_id":"60a4fc71-1312-4830-86f4-9eb98be106ac","message_id":395,"id":"CRV-USD","channel":"v3_orderbook","contents":{"offset":"2693989369","bids":[["4.817","16713"],["4.816","0"]],"asks":[]}}
1635444232.8156302: {"type":"channel_data","connection_id":"60a4fc71-1312-4830-86f4-9eb98be106ac","message_id":396,"id":"XMR-USD","channel":"v3_orderbook","contents":{"offset":"2693989365","bids":[["265","151.22"]],"asks":[]}}
1635444232.8156538: {"type":"channel_data","connection_id":"60a4fc71-1312-4830-86f4-9eb98be106ac","message_id":397,"id":"EOS-USD","channel":"v3_orderbook","contents":{"offset":"2693989370","bids":[["4.397","36846"]],"asks":[]}}
1635444232.8241549: {"type":"channel_data","connection_id":"60a4fc71-1312-4830-86f4-9eb98be106ac","message_id":398,"id":"ETH-USD","channel":"v3_orderbook","contents":{"offset":"2693989372","bids":[],"asks":[["4240","70.03"],["4240.1","14.227"]]}}
1635444232.833173: {"type":"channel_data","connection_id":"60a4fc71-1312-4830-86f4-9eb98be106ac","message_id":399,"id":"EOS-USD","channel":"v3_orderbook","contents":{"offset":"2693989381","bids":[],"asks":[["4.405","43413"]]}}
1635444232.844958: {"type":"channel_data","connection_id":"60a4fc71-1312-4830-86f4-9eb98be106ac","message_id":400,"id":"UNI-USD","channel":"v3_orderbook","contents":{"offset":"2693989385","bids":[["24.86","998.8"],["24.859","0"]],"asks":[]}}
1635444232.8539221: {"type":"channel_data","connection_id":"60a4fc71-1312-4830-86f4-9eb98be106ac","message_id":401,"id":"ETH-USD","channel":"v3_orderbook","contents":{"offset":"2693989390","bids":[["4211","5623.34"]],"asks":[]}}
1635444232.854999: {"type":"channel_data","connection_id":"60a4fc71-1312-4830-86f4-9eb98be106ac","message_id":402,"id":"UNI-USD","channel":"v3_orderbook","contents":{"offset":"2693989393","bids":[["24.898","1997.7"],["24.897","0"]],"asks":[]}}
1635444232.855036: {"type":"channel_data","connection_id":"60a4fc71-1312-4830-86f4-9eb98be106ac","message_id":403,"id":"UNI-USD","channel":"v3_orderbook","contents":{"offset":"2693989389","bids":[["24.873","1997.7"],["24.872","0"]],"asks":[]}}
1635444232.855058: {"type":"channel_data","connection_id":"60a4fc71-1312-4830-86f4-9eb98be106ac","message_id":404,"id":"SUSHI-USD","channel":"v3_orderbook","contents":{"offset":"2693989394","bids":[["10.788","4635.1"]],"asks":[]}}
1635444232.8807418: {"type":"channel_data","connection_id":"60a4fc71-1312-4830-86f4-9eb98be106ac","message_id":405,"id":"EOS-USD","channel":"v3_orderbook","contents":{"offset":"2693989399","bids":[],"asks":[["4.416","9035"],["4.417","249"]]}}
1635444232.8808022: {"type":"channel_data","connection_id":"60a4fc71-1312-4830-86f4-9eb98be106ac","message_id":406,"id":"EOS-USD","channel":"v3_orderbook","contents":{"offset":"2693989401","bids":[],"asks":[["4.405","44549"]]}}
1635444232.880822: {"type":"channel_data","connection_id":"60a4fc71-1312-4830-86f4-9eb98be106ac","message_id":407,"id":"CRV-USD","channel":"v3_orderbook","contents":{"offset":"2693989402","bids":[["4.852","4775"]],"asks":[]}}
1635444232.896538: {"type":"channel_data","connection_id":"60a4fc71-1312-4830-86f4-9eb98be106ac","message_id":408,"id":"EOS-USD","channel":"v3_orderbook","contents":{"offset":"2693989405","bids":[["4.384","249"]],"asks":[]}}
1635444232.910012: {"type":"channel_data","connection_id":"60a4fc71-1312-4830-86f4-9eb98be106ac","message_id":409,"id":"EOS-USD","channel":"v3_orderbook","contents":{"offset":"2693989410","bids":[["4.401","1136"]],"asks":[]}}
1635444232.918897: {"type":"channel_data","connection_id":"60a4fc71-1312-4830-86f4-9eb98be106ac","message_id":410,"id":"CRV-USD","channel":"v3_orderbook","contents":{"offset":"2693989414","bids":[["4.851","2095"]],"asks":[]}}
1635444232.937233: {"type":"channel_data","connection_id":"60a4fc71-1312-4830-86f4-9eb98be106ac","message_id":411,"id":"EOS-USD","channel":"v3_orderbook","contents":{"offset":"2693989422","bids":[],"asks":[["4.405","43413"]]}}
1635444232.941555: {"type":"channel_data","connection_id":"60a4fc71-1312-4830-86f4-9eb98be106ac","message_id":412,"id":"EOS-USD","channel":"v3_orderbook","contents":{"offset":"2693989421","bids":[["4.401","0"]],"asks":[]}}
1635444232.9415948: {"type":"channel_data","connection_id":"60a4fc71-1312-4830-86f4-9eb98be106ac","message_id":413,"id":"ETH-USD","channel":"v3_orderbook","contents":{"offset":"2693989417","bids":[["4212","2.613"]],"asks":[]}}
1635444232.956297: {"type":"channel_data","connection_id":"60a4fc71-1312-4830-86f4-9eb98be106ac","message_id":414,"id":"EOS-USD","channel":"v3_orderbook","contents":{"offset":"2693989430","bids":[],"asks":[["4.405","43163"]]}}
1635444232.956356: {"type":"channel_data","connection_id":"60a4fc71-1312-4830-86f4-9eb98be106ac","message_id":415,"id":"EOS-USD","channel":"v3_orderbook","contents":{"offset":"2693989424","bids":[["4.389","0"]],"asks":[]}}
1635444232.9563782: {"type":"channel_data","connection_id":"60a4fc71-1312-4830-86f4-9eb98be106ac","message_id":416,"id":"EOS-USD","channel":"v3_orderbook","contents":{"offset":"2693989428","bids":[],"asks":[["4.406","2529"]]}}
1635444232.956394: {"type":"channel_data","connection_id":"60a4fc71-1312-4830-86f4-9eb98be106ac","message_id":417,"id":"EOS-USD","channel":"v3_orderbook","contents":{"offset":"2693989425","bids":[],"asks":[["4.403","15738"]]}}
1635444232.961478: {"type":"channel_data","connection_id":"60a4fc71-1312-4830-86f4-9eb98be106ac","message_id":418,"id":"EOS-USD","channel":"v3_orderbook","contents":{"offset":"2693989435","bids":[["4.4","1137"]],"asks":[]}}
1635444232.962594: {"type":"channel_data","connection_id":"60a4fc71-1312-4830-86f4-9eb98be106ac","message_id":419,"id":"EOS-USD","channel":"v3_orderbook","contents":{"offset":"2693989433","bids":[["4.398","16164"]],"asks":[]}}
1635444232.963843: {"type":"channel_data","connection_id":"60a4fc71-1312-4830-86f4-9eb98be106ac","message_id":420,"id":"CRV-USD","channel":"v3_orderbook","contents":{"offset":"2693989434","bids":[["4.835","2727"]],"asks":[]}}
1635444232.9717991: {"type":"channel_data","connection_id":"60a4fc71-1312-4830-86f4-9eb98be106ac","message_id":421,"id":"EOS-USD","channel":"v3_orderbook","contents":{"offset":"2693989438","bids":[],"asks":[["4.406","1393"]]}}
1635444232.985229: {"type":"channel_data","connection_id":"60a4fc71-1312-4830-86f4-9eb98be106ac","message_id":422,"id":"CRV-USD","channel":"v3_orderbook","contents":{"offset":"2693989441","bids":[],"asks":[["4.87","850"],["4.871","3004"]]}}
1635444232.9949179: {"type":"channel_data","connection_id":"60a4fc71-1312-4830-86f4-9eb98be106ac","message_id":423,"id":"EOS-USD","channel":"v3_orderbook","contents":{"offset":"2693989443","bids":[["4.4","0"]],"asks":[]}}
1635444232.995001: {"type":"channel_data","connection_id":"60a4fc71-1312-4830-86f4-9eb98be106ac","message_id":424,"id":"EOS-USD","channel":"v3_orderbook","contents":{"offset":"2693989446","bids":[],"asks":[["4.41","250"]]}}
1635444233.008666: {"type":"channel_data","connection_id":"60a4fc71-1312-4830-86f4-9eb98be106ac","message_id":425,"id":"SUSHI-USD","channel":"v3_orderbook","contents":{"offset":"2693989451","bids":[["10.78","14518.1"]],"asks":[]}}
1635444233.012225: {"type":"channel_data","connection_id":"60a4fc71-1312-4830-86f4-9eb98be106ac","message_id":426,"id":"EOS-USD","channel":"v3_orderbook","contents":{"offset":"2693989450","bids":[["4.394","1517"]],"asks":[]}}
1635444233.023263: {"type":"channel_data","connection_id":"60a4fc71-1312-4830-86f4-9eb98be106ac","message_id":427,"id":"SUSHI-USD","channel":"v3_orderbook","contents":{"offset":"2693989456","bids":[["10.786","7710.6"]],"asks":[]}}
1635444233.031065: {"type":"channel_data","connection_id":"60a4fc71-1312-4830-86f4-9eb98be106ac","message_id":428,"id":"SUSHI-USD","channel":"v3_orderbook","contents":{"offset":"2693989459","bids":[],"asks":[["10.796","4002.3"]]}}
1635444233.031152: {"type":"channel_data","connection_id":"60a4fc71-1312-4830-86f4-9eb98be106ac","message_id":429,"id":"SUSHI-USD","channel":"v3_orderbook","contents":{"offset":"2693989452","bids":[["10.788","8637.4"]],"asks":[]}}
1635444233.031188: {"type":"channel_data","connection_id":"60a4fc71-1312-4830-86f4-9eb98be106ac","message_id":430,"id":"CRV-USD","channel":"v3_orderbook","contents":{"offset":"2693989453","bids":[["4.851","0"]],"asks":[]}}
1635444233.031221: {"type":"channel_data","connection_id":"60a4fc71-1312-4830-86f4-9eb98be106ac","message_id":431,"id":"SUSHI-USD","channel":"v3_orderbook","contents":{"offset":"2693989457","bids":[["10.782","0"]],"asks":[]}}
1635444233.033141: {"type":"channel_data","connection_id":"60a4fc71-1312-4830-86f4-9eb98be106ac","message_id":432,"id":"SUSHI-USD","channel":"v3_orderbook","contents":{"offset":"2693989458","bids":[["10.783","654.2"]],"asks":[]}}
1635444233.033206: {"type":"channel_data","connection_id":"60a4fc71-1312-4830-86f4-9eb98be106ac","message_id":433,"id":"SUSHI-USD","channel":"v3_orderbook","contents":{"offset":"2693989460","bids":[["10.79","4268.8"]],"asks":[]}}
1635444233.03324: {"type":"channel_data","connection_id":"60a4fc71-1312-4830-86f4-9eb98be106ac","message_id":434,"id":"CRV-USD","channel":"v3_orderbook","contents":{"offset":"2693989461","bids":[],"asks":[["4.869","5092"]]}}
1635444233.03789: {"type":"channel_data","connection_id":"60a4fc71-1312-4830-86f4-9eb98be106ac","message_id":435,"id":"CRV-USD","channel":"v3_orderbook","contents":{"offset":"2693989464","bids":[["4.852","11660"]],"asks":[]}}
1635444233.037942: {"type":"channel_data","connection_id":"60a4fc71-1312-4830-86f4-9eb98be106ac","message_id":436,"id":"CRV-USD","channel":"v3_orderbook","contents":{"offset":"2693989463","bids":[["4.852","9565"]],"asks":[]}}
1635444233.0379672: {"type":"channel_data","connection_id":"60a4fc71-1312-4830-86f4-9eb98be106ac","message_id":437,"id":"EOS-USD","channel":"v3_orderbook","contents":{"offset":"2693989465","bids":[["4.401","1136"]],"asks":[]}}
1635444233.054036: {"type":"channel_data","connection_id":"60a4fc71-1312-4830-86f4-9eb98be106ac","message_id":438,"id":"SUSHI-USD","channel":"v3_orderbook","contents":{"offset":"2693989466","bids":[],"asks":[["10.798","7706.9"]]}}
1635444233.063071: {"type":"channel_data","connection_id":"60a4fc71-1312-4830-86f4-9eb98be106ac","message_id":439,"id":"EOS-USD","channel":"v3_orderbook","contents":{"offset":"2693989470","bids":[],"asks":[["4.405","44299"]]}}
1635444233.06563: {"type":"channel_data","connection_id":"60a4fc71-1312-4830-86f4-9eb98be106ac","message_id":440,"id":"ETH-USD","channel":"v3_orderbook","contents":{"offset":"2693989469","bids":[["4214.6","2.071"]],"asks":[]}}
1635444233.065711: {"type":"channel_data","connection_id":"60a4fc71-1312-4830-86f4-9eb98be106ac","message_id":441,"id":"ETH-USD","channel":"v3_orderbook","contents":{"offset":"2693989471","bids":[],"asks":[["4216.8","48.228"]]}}
1635444233.07956: {"type":"channel_data","connection_id":"60a4fc71-1312-4830-86f4-9eb98be106ac","message_id":442,"id":"EOS-USD","channel":"v3_orderbook","contents":{"offset":"2693989478","bids":[["4.4","11196"]],"asks":[]}}
1635444233.079644: {"type":"channel_data","connection_id":"60a4fc71-1312-4830-86f4-9eb98be106ac","message_id":443,"id":"EOS-USD","channel":"v3_orderbook","contents":{"offset":"2693989480","bids":[["4.4","12333"]],"asks":[]}}
1635444233.100348: {"type":"channel_data","connection_id":"60a4fc71-1312-4830-86f4-9eb98be106ac","message_id":444,"id":"EOS-USD","channel":"v3_orderbook","contents":{"offset":"2693989494","bids":[["4.401","0"]],"asks":[]}}
1635444233.1004338: {"type":"channel_data","connection_id":"60a4fc71-1312-4830-86f4-9eb98be106ac","message_id":445,"id":"EOS-USD","channel":"v3_orderbook","contents":{"offset":"2693989491","bids":[],"asks":[["4.405","43163"]]}}
1635444233.1048782: {"type":"channel_data","connection_id":"60a4fc71-1312-4830-86f4-9eb98be106ac","message_id":446,"id":"EOS-USD","channel":"v3_orderbook","contents":{"offset":"2693989496","bids":[["4.4","11196"]],"asks":[]}}
1635444233.122592: {"type":"channel_data","connection_id":"60a4fc71-1312-4830-86f4-9eb98be106ac","message_id":447,"id":"EOS-USD","channel":"v3_orderbook","contents":{"offset":"2693989511","bids":[],"asks":[["4.406","2529"]]}}
1635444233.132977: {"type":"channel_data","connection_id":"60a4fc71-1312-4830-86f4-9eb98be106ac","message_id":448,"id":"UMA-USD","channel":"v3_orderbook","contents":{"offset":"2693989513","bids":[["11.27","29416.1"]],"asks":[]}}
1635444233.144969: {"type":"channel_data","connection_id":"60a4fc71-1312-4830-86f4-9eb98be106ac","message_id":449,"id":"ETH-USD","channel":"v3_orderbook","contents":{"offset":"2693989519","bids":[],"asks":[["4219.9","2.727"]]}}
1635444233.1450508: {"type":"channel_data","connection_id":"60a4fc71-1312-4830-86f4-9eb98be106ac","message_id":450,"id":"EOS-USD","channel":"v3_orderbook","contents":{"offset":"2693989520","bids":[["4.396","832"]],"asks":[]}}
1635444233.145088: {"type":"channel_data","connection_id":"60a4fc71-1312-4830-86f4-9eb98be106ac","message_id":451,"id":"ETH-USD","channel":"v3_orderbook","contents":{"offset":"2693989516","bids":[],"asks":[["4218.8","57.1"]]}}
1635444233.158529: {"type":"channel_data","connection_id":"60a4fc71-1312-4830-86f4-9eb98be106ac","message_id":452,"id":"UMA-USD","channel":"v3_orderbook","contents":{"offset":"2693989524","bids":[["11.27","29150.7"]],"asks":[]}}
1635444233.1883562: {"type":"channel_data","connection_id":"60a4fc71-1312-4830-86f4-9eb98be106ac","message_id":453,"id":"EOS-USD","channel":"v3_orderbook","contents":{"offset":"2693989528","bids":[],"asks":[["4.406","1393"]]}}
1635444233.232564: {"type":"channel_data","connection_id":"60a4fc71-1312-4830-86f4-9eb98be106ac","message_id":454,"id":"EOS-USD","channel":"v3_orderbook","contents":{"offset":"2693989543","bids":[],"asks":[["4.404","16101"]]}}
1635444233.242398: {"type":"channel_data","connection_id":"60a4fc71-1312-4830-86f4-9eb98be106ac","message_id":455,"id":"ETH-USD","channel":"v3_orderbook","contents":{"offset":"2693989548","bids":[["4209.7","0"]],"asks":[]}}
1635444233.255925: {"type":"channel_data","connection_id":"60a4fc71-1312-4830-86f4-9eb98be106ac","message_id":456,"id":"EOS-USD","channel":"v3_orderbook","contents":{"offset":"2693989551","bids":[],"asks":[["4.404","14965"]]}}
1635444233.2656488: {"type":"channel_data","connection_id":"60a4fc71-1312-4830-86f4-9eb98be106ac","message_id":457,"id":"SUSHI-USD","channel":"v3_orderbook","contents":{"offset":"2693989552","bids":[["10.768","253.2"]],"asks":[]}}
1635444233.282867: {"type":"channel_data","connection_id":"60a4fc71-1312-4830-86f4-9eb98be106ac","message_id":458,"id":"UNI-USD","channel":"v3_orderbook","contents":{"offset":"2693989556","bids":[["24.899","1997.7"],["24.898","0"]],"asks":[]}}
1635444233.295475: {"type":"channel_data","connection_id":"60a4fc71-1312-4830-86f4-9eb98be106ac","message_id":459,"id":"ETH-USD","channel":"v3_orderbook","contents":{"offset":"2693989558","bids":[],"asks":[["4240","81.898"],["4240.1","2.359"]]}}
1635444233.295562: {"type":"channel_data","connection_id":"60a4fc71-1312-4830-86f4-9eb98be106ac","message_id":460,"id":"EOS-USD","channel":"v3_orderbook","contents":{"offset":"2693989564","bids":[],"asks":[["4.404","16101"]]}}
1635444233.316384: {"type":"channel_data","connection_id":"60a4fc71-1312-4830-86f4-9eb98be106ac","message_id":461,"id":"SUSHI-USD","channel":"v3_orderbook","contents":{"offset":"2693989565","bids":[["10.781","138.9"]],"asks":[]}}
1635444233.3164742: {"type":"channel_data","connection_id":"60a4fc71-1312-4830-86f4-9eb98be106ac","message_id":462,"id":"CRV-USD","channel":"v3_orderbook","contents":{"offset":"2693989562","bids":[["4.819","17638"],["4.817","0"]],"asks":[]}}
1635444233.316519: {"type":"channel_data","connection_id":"60a4fc71-1312-4830-86f4-9eb98be106ac","message_id":463,"id":"UNI-USD","channel":"v3_orderbook","contents":{"offset":"2693989566","bids":[["24.862","998.8"],["24.86","0"]],"asks":[]}}
1635444233.316556: {"type":"channel_data","connection_id":"60a4fc71-1312-4830-86f4-9eb98be106ac","message_id":464,"id":"SUSHI-USD","channel":"v3_orderbook","contents":{"offset":"2693989573","bids":[],"asks":[["10.804","13702.8"]]}}
1635444233.3165839: {"type":"channel_data","connection_id":"60a4fc71-1312-4830-86f4-9eb98be106ac","message_id":465,"id":"SUSHI-USD","channel":"v3_orderbook","contents":{"offset":"2693989578","bids":[["10.785","138.9"]],"asks":[]}}
1635444233.327553: {"type":"channel_data","connection_id":"60a4fc71-1312-4830-86f4-9eb98be106ac","message_id":466,"id":"ETH-USD","channel":"v3_orderbook","contents":{"offset":"2693989582","bids":[],"asks":[["4219","30.215"]]}}
1635444233.327629: {"type":"channel_data","connection_id":"60a4fc71-1312-4830-86f4-9eb98be106ac","message_id":467,"id":"SUSHI-USD","channel":"v3_orderbook","contents":{"offset":"2693989583","bids":[],"asks":[["10.8","1210.1"]]}}
1635444233.334282: {"type":"channel_data","connection_id":"60a4fc71-1312-4830-86f4-9eb98be106ac","message_id":468,"id":"UNI-USD","channel":"v3_orderbook","contents":{"offset":"2693989588","bids":[["24.874","1997.7"],["24.873","0"]],"asks":[]}}
1635444233.3343701: {"type":"channel_data","connection_id":"60a4fc71-1312-4830-86f4-9eb98be106ac","message_id":469,"id":"EOS-USD","channel":"v3_orderbook","contents":{"offset":"2693989591","bids":[],"asks":[["4.404","14965"]]}}
1635444233.3388858: {"type":"channel_data","connection_id":"60a4fc71-1312-4830-86f4-9eb98be106ac","message_id":470,"id":"UMA-USD","channel":"v3_orderbook","contents":{"offset":"2693989596","bids":[],"asks":[["11.33","28177"]]}}
1635444233.364258: {"type":"channel_data","connection_id":"60a4fc71-1312-4830-86f4-9eb98be106ac","message_id":471,"id":"UMA-USD","channel":"v3_orderbook","contents":{"offset":"2693989599","bids":[],"asks":[["11.32","10966.1"]]}}
1635444233.374176: {"type":"channel_data","connection_id":"60a4fc71-1312-4830-86f4-9eb98be106ac","message_id":472,"id":"EOS-USD","channel":"v3_orderbook","contents":{"offset":"2693989611","bids":[],"asks":[["4.404","16101"]]}}
1635444233.374264: {"type":"channel_data","connection_id":"60a4fc71-1312-4830-86f4-9eb98be106ac","message_id":473,"id":"UNI-USD","channel":"v3_orderbook","contents":{"offset":"2693989606","bids":[["24.949","544.9"],["24.947","0"]],"asks":[]}}
1635444233.391584: {"type":"channel_data","connection_id":"60a4fc71-1312-4830-86f4-9eb98be106ac","message_id":474,"id":"ETH-USD","channel":"v3_orderbook","contents":{"offset":"2693989618","bids":[],"asks":[["4215.6","0"]]}}
1635444233.398619: {"type":"channel_data","connection_id":"60a4fc71-1312-4830-86f4-9eb98be106ac","message_id":475,"id":"CRV-USD","channel":"v3_orderbook","contents":{"offset":"2693989624","bids":[["4.842","1997"]],"asks":[]}}
1635444233.4100192: {"type":"channel_data","connection_id":"60a4fc71-1312-4830-86f4-9eb98be106ac","message_id":476,"id":"EOS-USD","channel":"v3_orderbook","contents":{"offset":"2693989630","bids":[],"asks":[["4.404","14965"]]}}
1635444233.410613: {"type":"channel_data","connection_id":"60a4fc71-1312-4830-86f4-9eb98be106ac","message_id":477,"id":"UNI-USD","channel":"v3_orderbook","contents":{"offset":"2693989628","bids":[],"asks":[["25.136","0"],["25.138","43.9"]]}}
1635444233.411063: {"type":"channel_data","connection_id":"60a4fc71-1312-4830-86f4-9eb98be106ac","message_id":478,"id":"UMA-USD","channel":"v3_orderbook","contents":{"offset":"2693989629","bids":[["11.27","29416.1"]],"asks":[]}}
1635444233.426121: {"type":"channel_data","connection_id":"60a4fc71-1312-4830-86f4-9eb98be106ac","message_id":479,"id":"ETH-USD","channel":"v3_orderbook","contents":{"offset":"2693989633","bids":[["4214.1","0.852"]],"asks":[]}}
1635444233.4261901: {"type":"channel_data","connection_id":"60a4fc71-1312-4830-86f4-9eb98be106ac","message_id":480,"id":"ETH-USD","channel":"v3_orderbook","contents":{"offset":"2693989637","bids":[["4213.6","5.991"]],"asks":[]}}
1635444233.445666: {"type":"channel_data","connection_id":"60a4fc71-1312-4830-86f4-9eb98be106ac","message_id":481,"id":"CRV-USD","channel":"v3_orderbook","contents":{"offset":"2693989644","bids":[],"asks":[["4.888","7136"]]}}
1635444233.446177: {"type":"channel_data","connection_id":"60a4fc71-1312-4830-86f4-9eb98be106ac","message_id":482,"id":"ETH-USD","channel":"v3_orderbook","contents":{"offset":"2693989645","bids":[],"asks":[["4218.9","87.56"]]}}
1635444233.4462872: {"type":"channel_data","connection_id":"60a4fc71-1312-4830-86f4-9eb98be106ac","message_id":483,"id":"ETH-USD","channel":"v3_orderbook","contents":{"offset":"2693989642","bids":[["4215.5","515.719"]],"asks":[]}}
1635444233.4565718: {"type":"channel_data","connection_id":"60a4fc71-1312-4830-86f4-9eb98be106ac","message_id":484,"id":"ETH-USD","channel":"v3_orderbook","contents":{"offset":"2693989646","bids":[["4215.5","456.52"]],"asks":[]}}
1635444233.4566798: {"type":"channel_data","connection_id":"60a4fc71-1312-4830-86f4-9eb98be106ac","message_id":485,"id":"UMA-USD","channel":"v3_orderbook","contents":{"offset":"2693989648","bids":[["11.27","29150.7"]],"asks":[]}}
1635444233.456718: {"type":"channel_data","connection_id":"60a4fc71-1312-4830-86f4-9eb98be106ac","message_id":486,"id":"ETH-USD","channel":"v3_orderbook","contents":{"offset":"2693989647","bids":[["4215.5","399.813"]],"asks":[]}}
1635444233.468013: {"type":"channel_data","connection_id":"60a4fc71-1312-4830-86f4-9eb98be106ac","message_id":487,"id":"ETH-USD","channel":"v3_orderbook","contents":{"offset":"2693989651","bids":[["4208.2","1.304"],["4208","0"]],"asks":[]}}
1635444233.471909: {"type":"channel_data","connection_id":"60a4fc71-1312-4830-86f4-9eb98be106ac","message_id":488,"id":"ETH-USD","channel":"v3_orderbook","contents":{"offset":"2693989653","bids":[],"asks":[["4217.4","43.702"]]}}
1635444233.471967: {"type":"channel_data","connection_id":"60a4fc71-1312-4830-86f4-9eb98be106ac","message_id":489,"id":"ETH-USD","channel":"v3_orderbook","contents":{"offset":"2693989650","bids":[["4215","1007.795"]],"asks":[]}}
1635444233.478243: {"type":"channel_data","connection_id":"60a4fc71-1312-4830-86f4-9eb98be106ac","message_id":490,"id":"ETH-USD","channel":"v3_orderbook","contents":{"offset":"2693989656","bids":[],"asks":[["4223.1","0"],["4223.3","1.304"]]}}
1635444233.5146089: {"type":"channel_data","connection_id":"60a4fc71-1312-4830-86f4-9eb98be106ac","message_id":491,"id":"ETH-USD","channel":"v3_orderbook","contents":{"offset":"2693989660","bids":[["4213.1","1930.603"]],"asks":[]}}
1635444233.514688: {"type":"channel_data","connection_id":"60a4fc71-1312-4830-86f4-9eb98be106ac","message_id":492,"id":"ETH-USD","channel":"v3_orderbook","contents":{"offset":"2693989661","bids":[],"asks":[["4219","28.275"]]}}
1635444233.524943: {"type":"channel_data","connection_id":"60a4fc71-1312-4830-86f4-9eb98be106ac","message_id":493,"id":"ETH-USD","channel":"v3_orderbook","contents":{"offset":"2693989662","bids":[["4213.7","21.863"]],"asks":[]}}
1635444233.525022: {"type":"channel_data","connection_id":"60a4fc71-1312-4830-86f4-9eb98be106ac","message_id":494,"id":"ETH-USD","channel":"v3_orderbook","contents":{"offset":"2693989664","bids":[["4215.4","0"]],"asks":[]}}
1635444233.535765: {"type":"channel_data","connection_id":"60a4fc71-1312-4830-86f4-9eb98be106ac","message_id":495,"id":"ETH-USD","channel":"v3_orderbook","contents":{"offset":"2693989670","bids":[],"asks":[["4217.5","0"]]}}
1635444233.537487: {"type":"channel_data","connection_id":"60a4fc71-1312-4830-86f4-9eb98be106ac","message_id":496,"id":"ETH-USD","channel":"v3_orderbook","contents":{"offset":"2693989668","bids":[],"asks":[["4217.5","58.88"]]}}
1635444233.5375721: {"type":"channel_data","connection_id":"60a4fc71-1312-4830-86f4-9eb98be106ac","message_id":497,"id":"EOS-USD","channel":"v3_orderbook","contents":{"offset":"2693989671","bids":[],"asks":[["4.404","16101"]]}}
1635444233.5712268: {"type":"channel_data","connection_id":"60a4fc71-1312-4830-86f4-9eb98be106ac","message_id":498,"id":"EOS-USD","channel":"v3_orderbook","contents":{"offset":"2693989680","bids":[],"asks":[["4.404","14965"]]}}
1635444233.577277: {"type":"channel_data","connection_id":"60a4fc71-1312-4830-86f4-9eb98be106ac","message_id":499,"id":"ETH-USD","channel":"v3_orderbook","contents":{"offset":"2693989677","bids":[["4215.6","2.738"]],"asks":[]}}
1635444233.586519: {"type":"channel_data","connection_id":"60a4fc71-1312-4830-86f4-9eb98be106ac","message_id":500,"id":"ETH-USD","channel":"v3_orderbook","contents":{"offset":"2693989686","bids":[["4213.7","0"]],"asks":[]}}
1635444233.5893602: {"type":"channel_data","connection_id":"60a4fc71-1312-4830-86f4-9eb98be106ac","message_id":501,"id":"SUSHI-USD","channel":"v3_orderbook","contents":{"offset":"2693989685","bids":[],"asks":[["10.8","1071.2"]]}}
1635444233.595082: {"type":"channel_data","connection_id":"60a4fc71-1312-4830-86f4-9eb98be106ac","message_id":502,"id":"ETH-USD","channel":"v3_orderbook","contents":{"offset":"2693989691","bids":[["4196","11.852"]],"asks":[]}}
1635444233.604007: {"type":"channel_data","connection_id":"60a4fc71-1312-4830-86f4-9eb98be106ac","message_id":503,"id":"ETH-USD","channel":"v3_orderbook","contents":{"offset":"2693989696","bids":[],"asks":[["4216.2","0"]]}}
1635444233.6040509: {"type":"channel_data","connection_id":"60a4fc71-1312-4830-86f4-9eb98be106ac","message_id":504,"id":"ETH-USD","channel":"v3_orderbook","contents":{"offset":"2693989703","bids":[["4214.1","0"]],"asks":[]}}
1635444233.606226: {"type":"channel_data","connection_id":"60a4fc71-1312-4830-86f4-9eb98be106ac","message_id":505,"id":"CRV-USD","channel":"v3_orderbook","contents":{"offset":"2693989697","bids":[],"asks":[["4.868","707"]]}}
1635444233.608184: {"type":"channel_data","connection_id":"60a4fc71-1312-4830-86f4-9eb98be106ac","message_id":506,"id":"ETH-USD","channel":"v3_orderbook","contents":{"offset":"2693989705","bids":[["4215.5","397.175"]],"asks":[]}}
1635444233.630224: {"type":"channel_data","connection_id":"60a4fc71-1312-4830-86f4-9eb98be106ac","message_id":507,"id":"ETH-USD","channel":"v3_orderbook","contents":{"offset":"2693989707","bids":[["4215.9","56.475"]],"asks":[]}}
1635444233.6302788: {"type":"channel_data","connection_id":"60a4fc71-1312-4830-86f4-9eb98be106ac","message_id":508,"id":"ETH-USD","channel":"v3_orderbook","contents":{"offset":"2693989706","bids":[["4215.5","396.475"]],"asks":[]}}
1635444233.6302989: {"type":"channel_data","connection_id":"60a4fc71-1312-4830-86f4-9eb98be106ac","message_id":509,"id":"ETH-USD","channel":"v3_orderbook","contents":{"offset":"2693989710","bids":[["4215.9","113.078"]],"asks":[]}}
1635444233.6303139: {"type":"channel_data","connection_id":"60a4fc71-1312-4830-86f4-9eb98be106ac","message_id":510,"id":"EOS-USD","channel":"v3_orderbook","contents":{"offset":"2693989711","bids":[["4.401","1136"]],"asks":[]}}
1635444233.63033: {"type":"channel_data","connection_id":"60a4fc71-1312-4830-86f4-9eb98be106ac","message_id":511,"id":"EOS-USD","channel":"v3_orderbook","contents":{"offset":"2693989713","bids":[],"asks":[["4.405","44299"]]}}
1635444233.6403542: {"type":"channel_data","connection_id":"60a4fc71-1312-4830-86f4-9eb98be106ac","message_id":512,"id":"ETH-USD","channel":"v3_orderbook","contents":{"offset":"2693989715","bids":[["4215.5","386.962"]],"asks":[]}}
1635444233.642807: {"type":"channel_data","connection_id":"60a4fc71-1312-4830-86f4-9eb98be106ac","message_id":513,"id":"ETH-USD","channel":"v3_orderbook","contents":{"offset":"2693989717","bids":[["4215.7","0.7"]],"asks":[]}}
1635444233.6515388: {"type":"channel_data","connection_id":"60a4fc71-1312-4830-86f4-9eb98be106ac","message_id":514,"id":"ETH-USD","channel":"v3_orderbook","contents":{"offset":"2693989723","bids":[],"asks":[["4218.8","0"]]}}
1635444233.652591: {"type":"channel_data","connection_id":"60a4fc71-1312-4830-86f4-9eb98be106ac","message_id":515,"id":"ETH-USD","channel":"v3_orderbook","contents":{"offset":"2693989724","bids":[["4215.9","170.178"]],"asks":[]}}
1635444233.654855: {"type":"channel_data","connection_id":"60a4fc71-1312-4830-86f4-9eb98be106ac","message_id":516,"id":"ETH-USD","channel":"v3_orderbook","contents":{"offset":"2693989727","bids":[["4215.6","0"]],"asks":[]}}
1635444233.6548858: {"type":"channel_data","connection_id":"60a4fc71-1312-4830-86f4-9eb98be106ac","message_id":517,"id":"EOS-USD","channel":"v3_orderbook","contents":{"offset":"2693989725","bids":[],"asks":[["4.405","43163"]]}}
1635444233.654907: {"type":"channel_data","connection_id":"60a4fc71-1312-4830-86f4-9eb98be106ac","message_id":518,"id":"EOS-USD","channel":"v3_orderbook","contents":{"offset":"2693989722","bids":[["4.401","0"]],"asks":[]}}
1635444233.667853: {"type":"channel_data","connection_id":"60a4fc71-1312-4830-86f4-9eb98be106ac","message_id":519,"id":"ETH-USD","channel":"v3_orderbook","contents":{"offset":"2693989731","bids":[["4214.1","19.341"]],"asks":[]}}
1635444233.667897: {"type":"channel_data","connection_id":"60a4fc71-1312-4830-86f4-9eb98be106ac","message_id":520,"id":"ETH-USD","channel":"v3_orderbook","contents":{"offset":"2693989734","bids":[["4214.9","0"]],"asks":[]}}
1635444233.667917: {"type":"channel_data","connection_id":"60a4fc71-1312-4830-86f4-9eb98be106ac","message_id":521,"id":"XMR-USD","channel":"v3_orderbook","contents":{"offset":"2693989736","bids":[["264.7","434.34"]],"asks":[]}}
1635444233.667935: {"type":"channel_data","connection_id":"60a4fc71-1312-4830-86f4-9eb98be106ac","message_id":522,"id":"XMR-USD","channel":"v3_orderbook","contents":{"offset":"2693989732","bids":[],"asks":[["265.4","286.73"]]}}
1635444233.6679502: {"type":"channel_data","connection_id":"60a4fc71-1312-4830-86f4-9eb98be106ac","message_id":523,"id":"ETH-USD","channel":"v3_orderbook","contents":{"offset":"2693989735","bids":[],"asks":[["4220","730.526"]]}}
1635444233.6679869: {"type":"channel_data","connection_id":"60a4fc71-1312-4830-86f4-9eb98be106ac","message_id":524,"id":"XMR-USD","channel":"v3_orderbook","contents":{"offset":"2693989733","bids":[],"asks":[["265.6","38"]]}}
1635444233.6680162: {"type":"channel_data","connection_id":"60a4fc71-1312-4830-86f4-9eb98be106ac","message_id":525,"id":"ETH-USD","channel":"v3_orderbook","contents":{"offset":"2693989730","bids":[],"asks":[["4219.9","1.305"]]}}
1635444233.680469: {"type":"channel_data","connection_id":"60a4fc71-1312-4830-86f4-9eb98be106ac","message_id":526,"id":"ETH-USD","channel":"v3_orderbook","contents":{"offset":"2693989742","bids":[["4214.3","0"]],"asks":[]}}
1635444233.680504: {"type":"channel_data","connection_id":"60a4fc71-1312-4830-86f4-9eb98be106ac","message_id":527,"id":"XMR-USD","channel":"v3_orderbook","contents":{"offset":"2693989740","bids":[["265","75.75"]],"asks":[]}}
1635444233.680523: {"type":"channel_data","connection_id":"60a4fc71-1312-4830-86f4-9eb98be106ac","message_id":528,"id":"ETH-USD","channel":"v3_orderbook","contents":{"offset":"2693989737","bids":[["4215.5","382.155"]],"asks":[]}}
1635444233.688691: {"type":"channel_data","connection_id":"60a4fc71-1312-4830-86f4-9eb98be106ac","message_id":529,"id":"ETH-USD","channel":"v3_orderbook","contents":{"offset":"2693989750","bids":[["4215.5","92.77"]],"asks":[]}}
1635444233.692183: {"type":"channel_data","connection_id":"60a4fc71-1312-4830-86f4-9eb98be106ac","message_id":530,"id":"ETH-USD","channel":"v3_orderbook","contents":{"offset":"2693989745","bids":[],"asks":[["4218.1","14.411"]]}}
1635444233.6922219: {"type":"channel_data","connection_id":"60a4fc71-1312-4830-86f4-9eb98be106ac","message_id":531,"id":"ETH-USD","channel":"v3_orderbook","contents":{"offset":"2693989743","bids":[["4215.7","5.507"]],"asks":[]}}
1635444233.692241: {"type":"channel_data","connection_id":"60a4fc71-1312-4830-86f4-9eb98be106ac","message_id":532,"id":"SUSHI-USD","channel":"v3_orderbook","contents":{"offset":"2693989749","bids":[["10.749","3226.2"]],"asks":[]}}
1635444233.693365: {"type":"channel_data","connection_id":"60a4fc71-1312-4830-86f4-9eb98be106ac","message_id":533,"id":"ETH-USD","channel":"v3_orderbook","contents":{"offset":"2693989746","bids":[["4215.5","93.384"]],"asks":[]}}
1635444233.695928: {"type":"channel_data","connection_id":"60a4fc71-1312-4830-86f4-9eb98be106ac","message_id":534,"id":"ETH-USD","channel":"v3_orderbook","contents":{"offset":"2693989751","bids":[["4213.9","64.325"]],"asks":[]}}
1635444233.7015328: {"type":"channel_data","connection_id":"60a4fc71-1312-4830-86f4-9eb98be106ac","message_id":535,"id":"ETH-USD","channel":"v3_orderbook","contents":{"offset":"2693989755","bids":[],"asks":[["4217.7","28.404"]]}}
1635444233.701566: {"type":"channel_data","connection_id":"60a4fc71-1312-4830-86f4-9eb98be106ac","message_id":536,"id":"ETH-USD","channel":"v3_orderbook","contents":{"offset":"2693989758","bids":[],"asks":[["4219.7","0"]]}}
1635444233.702791: {"type":"channel_data","connection_id":"60a4fc71-1312-4830-86f4-9eb98be106ac","message_id":537,"id":"ETH-USD","channel":"v3_orderbook","contents":{"offset":"2693989756","bids":[],"asks":[["4220.2","0"]]}}
1635444233.705387: {"type":"channel_data","connection_id":"60a4fc71-1312-4830-86f4-9eb98be106ac","message_id":538,"id":"ETH-USD","channel":"v3_orderbook","contents":{"offset":"2693989757","bids":[],"asks":[["4220.4","0"]]}}
1635444233.70542: {"type":"channel_data","connection_id":"60a4fc71-1312-4830-86f4-9eb98be106ac","message_id":539,"id":"ETH-USD","channel":"v3_orderbook","contents":{"offset":"2693989754","bids":[],"asks":[["4220.5","5622.18"]]}}
1635444233.705439: {"type":"channel_data","connection_id":"60a4fc71-1312-4830-86f4-9eb98be106ac","message_id":540,"id":"ETH-USD","channel":"v3_orderbook","contents":{"offset":"2693989759","bids":[["4215.7","29.112"]],"asks":[]}}
1635444233.711741: {"type":"channel_data","connection_id":"60a4fc71-1312-4830-86f4-9eb98be106ac","message_id":541,"id":"ETH-USD","channel":"v3_orderbook","contents":{"offset":"2693989763","bids":[],"asks":[["4217.4","40.78"]]}}
1635444233.716224: {"type":"channel_data","connection_id":"60a4fc71-1312-4830-86f4-9eb98be106ac","message_id":542,"id":"ETH-USD","channel":"v3_orderbook","contents":{"offset":"2693989766","bids":[["4215.7","329.112"]],"asks":[]}}
1635444233.7162828: {"type":"channel_data","connection_id":"60a4fc71-1312-4830-86f4-9eb98be106ac","message_id":543,"id":"ETH-USD","channel":"v3_orderbook","contents":{"offset":"2693989760","bids":[["4215.9","170.878"]],"asks":[]}}
1635444233.716307: {"type":"channel_data","connection_id":"60a4fc71-1312-4830-86f4-9eb98be106ac","message_id":544,"id":"ETH-USD","channel":"v3_orderbook","contents":{"offset":"2693989765","bids":[],"asks":[["4221.9","1.41"]]}}
1635444233.716326: {"type":"channel_data","connection_id":"60a4fc71-1312-4830-86f4-9eb98be106ac","message_id":545,"id":"EOS-USD","channel":"v3_orderbook","contents":{"offset":"2693989762","bids":[],"asks":[["4.404","16101"]]}}
1635444233.72768: {"type":"channel_data","connection_id":"60a4fc71-1312-4830-86f4-9eb98be106ac","message_id":546,"id":"ETH-USD","channel":"v3_orderbook","contents":{"offset":"2693989772","bids":[["4214.1","0"]],"asks":[]}}
1635444233.727807: {"type":"channel_data","connection_id":"60a4fc71-1312-4830-86f4-9eb98be106ac","message_id":547,"id":"ETH-USD","channel":"v3_orderbook","contents":{"offset":"2693989769","bids":[["4213.1","1899.176"]],"asks":[]}}
1635444233.729505: {"type":"channel_data","connection_id":"60a4fc71-1312-4830-86f4-9eb98be106ac","message_id":548,"id":"ETH-USD","channel":"v3_orderbook","contents":{"offset":"2693989773","bids":[["4215.9","113.778"]],"asks":[]}}
1635444233.730716: {"type":"channel_data","connection_id":"60a4fc71-1312-4830-86f4-9eb98be106ac","message_id":549,"id":"ETH-USD","channel":"v3_orderbook","contents":{"offset":"2693989770","bids":[],"asks":[["4216.4","50.393"]]}}
1635444233.7392142: {"type":"channel_data","connection_id":"60a4fc71-1312-4830-86f4-9eb98be106ac","message_id":550,"id":"ETH-USD","channel":"v3_orderbook","contents":{"offset":"2693989776","bids":[["4215.7","305.507"]],"asks":[]}}
1635444233.74123: {"type":"channel_data","connection_id":"60a4fc71-1312-4830-86f4-9eb98be106ac","message_id":551,"id":"EOS-USD","channel":"v3_orderbook","contents":{"offset":"2693989781","bids":[],"asks":[["4.404","14965"]]}}
1635444233.7490618: {"type":"channel_data","connection_id":"60a4fc71-1312-4830-86f4-9eb98be106ac","message_id":552,"id":"ETH-USD","channel":"v3_orderbook","contents":{"offset":"2693989784","bids":[["4215.7","5.507"]],"asks":[]}}
1635444233.749181: {"type":"channel_data","connection_id":"60a4fc71-1312-4830-86f4-9eb98be106ac","message_id":553,"id":"ETH-USD","channel":"v3_orderbook","contents":{"offset":"2693989785","bids":[],"asks":[["4239.8","11.868"],["4240","70.03"]]}}
1635444233.758803: {"type":"channel_data","connection_id":"60a4fc71-1312-4830-86f4-9eb98be106ac","message_id":554,"id":"UNI-USD","channel":"v3_orderbook","contents":{"offset":"2693989790","bids":[["24.901","1997.7"],["24.899","0"]],"asks":[]}}
1635444233.758892: {"type":"channel_data","connection_id":"60a4fc71-1312-4830-86f4-9eb98be106ac","message_id":555,"id":"BCH-USD","channel":"v3_orderbook","contents":{"offset":"2693989791","bids":[["574","0"]],"asks":[]}}
1635444233.7589319: {"type":"channel_data","connection_id":"60a4fc71-1312-4830-86f4-9eb98be106ac","message_id":556,"id":"ETH-USD","channel":"v3_orderbook","contents":{"offset":"2693989792","bids":[],"asks":[["4216.5","23.734"]]}}
1635444233.758964: {"type":"channel_data","connection_id":"60a4fc71-1312-4830-86f4-9eb98be106ac","message_id":557,"id":"UMA-USD","channel":"v3_orderbook","contents":{"offset":"2693989793","bids":[["11.28","1935.1"]],"asks":[]}}
1635444233.759735: {"type":"channel_data","connection_id":"60a4fc71-1312-4830-86f4-9eb98be106ac","message_id":558,"id":"UNI-USD","channel":"v3_orderbook","contents":{"offset":"2693989789","bids":[["24.863","998.8"],["24.862","0"]],"asks":[]}}
1635444233.7682939: {"type":"channel_data","connection_id":"60a4fc71-1312-4830-86f4-9eb98be106ac","message_id":559,"id":"UNI-USD","channel":"v3_orderbook","contents":{"offset":"2693989798","bids":[["25.009","1585.8"]],"asks":[]}}
1635444233.77807: {"type":"channel_data","connection_id":"60a4fc71-1312-4830-86f4-9eb98be106ac","message_id":560,"id":"ETH-USD","channel":"v3_orderbook","contents":{"offset":"2693989806","bids":[],"asks":[["4216","57.31"]]}}
1635444233.7800908: {"type":"channel_data","connection_id":"60a4fc71-1312-4830-86f4-9eb98be106ac","message_id":561,"id":"ETH-USD","channel":"v3_orderbook","contents":{"offset":"2693989800","bids":[],"asks":[["4217.1","58.632"]]}}
1635444233.7801569: {"type":"channel_data","connection_id":"60a4fc71-1312-4830-86f4-9eb98be106ac","message_id":562,"id":"ETH-USD","channel":"v3_orderbook","contents":{"offset":"2693989804","bids":[["4215.7","0.7"]],"asks":[]}}
1635444233.780192: {"type":"channel_data","connection_id":"60a4fc71-1312-4830-86f4-9eb98be106ac","message_id":563,"id":"ETH-USD","channel":"v3_orderbook","contents":{"offset":"2693989801","bids":[["4215","1007.07"]],"asks":[]}}
1635444233.78377: {"type":"channel_data","connection_id":"60a4fc71-1312-4830-86f4-9eb98be106ac","message_id":564,"id":"ETH-USD","channel":"v3_orderbook","contents":{"offset":"2693989802","bids":[],"asks":[["4218","57.31"]]}}
1635444233.783843: {"type":"channel_data","connection_id":"60a4fc71-1312-4830-86f4-9eb98be106ac","message_id":565,"id":"ETH-USD","channel":"v3_orderbook","contents":{"offset":"2693989807","bids":[],"asks":[["4217.7","18.62"]]}}
1635444233.791779: {"type":"channel_data","connection_id":"60a4fc71-1312-4830-86f4-9eb98be106ac","message_id":566,"id":"UNI-USD","channel":"v3_orderbook","contents":{"offset":"2693989808","bids":[["25.019","14684.8"]],"asks":[]}}
1635444233.791847: {"type":"channel_data","connection_id":"60a4fc71-1312-4830-86f4-9eb98be106ac","message_id":567,"id":"ETH-USD","channel":"v3_orderbook","contents":{"offset":"2693989811","bids":[],"asks":[["4216.5","0"]]}}
1635444233.791886: {"type":"channel_data","connection_id":"60a4fc71-1312-4830-86f4-9eb98be106ac","message_id":568,"id":"BCH-USD","channel":"v3_orderbook","contents":{"offset":"2693989812","bids":[["574.2","83.21"]],"asks":[]}}
1635444233.79233: {"type":"channel_data","connection_id":"60a4fc71-1312-4830-86f4-9eb98be106ac","message_id":569,"id":"ETH-USD","channel":"v3_orderbook","contents":{"offset":"2693989810","bids":[["4213.9","57.11"]],"asks":[]}}
1635444233.801858: {"type":"channel_data","connection_id":"60a4fc71-1312-4830-86f4-9eb98be106ac","message_id":570,"id":"ETH-USD","channel":"v3_orderbook","contents":{"offset":"2693989819","bids":[["4215.9","118.585"]],"asks":[]}}
1635444233.80194: {"type":"channel_data","connection_id":"60a4fc71-1312-4830-86f4-9eb98be106ac","message_id":571,"id":"UNI-USD","channel":"v3_orderbook","contents":{"offset":"2693989814","bids":[["24.876","1997.7"],["24.874","0"]],"asks":[]}}
1635444233.803639: {"type":"channel_data","connection_id":"60a4fc71-1312-4830-86f4-9eb98be106ac","message_id":572,"id":"ETH-USD","channel":"v3_orderbook","contents":{"offset":"2693989816","bids":[],"asks":[["4217.1","116.165"]]}}
1635444233.8036962: {"type":"channel_data","connection_id":"60a4fc71-1312-4830-86f4-9eb98be106ac","message_id":573,"id":"XMR-USD","channel":"v3_orderbook","contents":{"offset":"2693989815","bids":[["264.1","88.86"]],"asks":[]}}
1635444233.803733: {"type":"channel_data","connection_id":"60a4fc71-1312-4830-86f4-9eb98be106ac","message_id":574,"id":"ETH-USD","channel":"v3_orderbook","contents":{"offset":"2693989821","bids":[],"asks":[["4217.5","9.784"]]}}
1635444233.815014: {"type":"channel_data","connection_id":"60a4fc71-1312-4830-86f4-9eb98be106ac","message_id":575,"id":"SUSHI-USD","channel":"v3_orderbook","contents":{"offset":"2693989822","bids":[["10.728","31083.7"],["10.702","0"]],"asks":[]}}
1635444233.828279: {"type":"channel_data","connection_id":"60a4fc71-1312-4830-86f4-9eb98be106ac","message_id":576,"id":"ETH-USD","channel":"v3_orderbook","contents":{"offset":"2693989827","bids":[["4215.2","0"]],"asks":[]}}
1635444233.828403: {"type":"channel_data","connection_id":"60a4fc71-1312-4830-86f4-9eb98be106ac","message_id":577,"id":"EOS-USD","channel":"v3_orderbook","contents":{"offset":"2693989830","bids":[],"asks":[["4.404","16101"]]}}
1635444233.8284621: {"type":"channel_data","connection_id":"60a4fc71-1312-4830-86f4-9eb98be106ac","message_id":578,"id":"ETH-USD","channel":"v3_orderbook","contents":{"offset":"2693989828","bids":[["4213.7","7.215"]],"asks":[]}}
1635444233.828506: {"type":"channel_data","connection_id":"60a4fc71-1312-4830-86f4-9eb98be106ac","message_id":579,"id":"ETH-USD","channel":"v3_orderbook","contents":{"offset":"2693989831","bids":[["4215.9","121.323"]],"asks":[]}}
1635444233.8290508: {"type":"channel_data","connection_id":"60a4fc71-1312-4830-86f4-9eb98be106ac","message_id":580,"id":"ETH-USD","channel":"v3_orderbook","contents":{"offset":"2693989829","bids":[],"asks":[["4217.5","10.219"]]}}
1635444233.8291242: {"type":"channel_data","connection_id":"60a4fc71-1312-4830-86f4-9eb98be106ac","message_id":581,"id":"ETH-USD","channel":"v3_orderbook","contents":{"offset":"2693989826","bids":[],"asks":[["4216.7","149.91"]]}}
1635444233.8428621: {"type":"channel_data","connection_id":"60a4fc71-1312-4830-86f4-9eb98be106ac","message_id":582,"id":"ETH-USD","channel":"v3_orderbook","contents":{"offset":"2693989832","bids":[],"asks":[["4216.5","23.734"]]}}
1635444233.8650649: {"type":"channel_data","connection_id":"60a4fc71-1312-4830-86f4-9eb98be106ac","message_id":583,"id":"ETH-USD","channel":"v3_orderbook","contents":{"offset":"2693989838","bids":[],"asks":[["4217.1","57.563"]]}}
1635444233.865181: {"type":"channel_data","connection_id":"60a4fc71-1312-4830-86f4-9eb98be106ac","message_id":584,"id":"ETH-USD","channel":"v3_orderbook","contents":{"offset":"2693989840","bids":[],"asks":[["4217.1","0.03"]]}}
1635444233.865233: {"type":"channel_data","connection_id":"60a4fc71-1312-4830-86f4-9eb98be106ac","message_id":585,"id":"EOS-USD","channel":"v3_orderbook","contents":{"offset":"2693989836","bids":[],"asks":[["4.404","14965"]]}}
1635444233.865302: {"type":"channel_data","connection_id":"60a4fc71-1312-4830-86f4-9eb98be106ac","message_id":586,"id":"ETH-USD","channel":"v3_orderbook","contents":{"offset":"2693989839","bids":[],"asks":[["4216.5","0"]]}}
1635444233.86533: {"type":"channel_data","connection_id":"60a4fc71-1312-4830-86f4-9eb98be106ac","message_id":587,"id":"ETH-USD","channel":"v3_orderbook","contents":{"offset":"2693989841","bids":[["4212.6","32.216"]],"asks":[]}}
1635444233.865354: {"type":"channel_data","connection_id":"60a4fc71-1312-4830-86f4-9eb98be106ac","message_id":588,"id":"ETH-USD","channel":"v3_orderbook","contents":{"offset":"2693989842","bids":[],"asks":[["4218","57.665"]]}}
1635444233.872409: {"type":"channel_data","connection_id":"60a4fc71-1312-4830-86f4-9eb98be106ac","message_id":589,"id":"ETH-USD","channel":"v3_orderbook","contents":{"offset":"2693989843","bids":[["4213.1","1898.821"]],"asks":[]}}
1635444233.87907: {"type":"channel_data","connection_id":"60a4fc71-1312-4830-86f4-9eb98be106ac","message_id":590,"id":"ETH-USD","channel":"v3_orderbook","contents":{"offset":"2693989844","bids":[["4213.3","26.104"]],"asks":[]}}
1635444233.885118: {"type":"channel_data","connection_id":"60a4fc71-1312-4830-86f4-9eb98be106ac","message_id":591,"id":"ETH-USD","channel":"v3_orderbook","contents":{"offset":"2693989851","bids":[],"asks":[["4219.3","0.355"]]}}
1635444233.885201: {"type":"channel_data","connection_id":"60a4fc71-1312-4830-86f4-9eb98be106ac","message_id":592,"id":"ETH-USD","channel":"v3_orderbook","contents":{"offset":"2693989849","bids":[["4215.9","131.156"]],"asks":[]}}
1635444233.893915: {"type":"channel_data","connection_id":"60a4fc71-1312-4830-86f4-9eb98be106ac","message_id":593,"id":"ETH-USD","channel":"v3_orderbook","contents":{"offset":"2693989856","bids":[],"asks":[["4218.5","4464.127"]]}}
1635444233.894482: {"type":"channel_data","connection_id":"60a4fc71-1312-4830-86f4-9eb98be106ac","message_id":594,"id":"ETH-USD","channel":"v3_orderbook","contents":{"offset":"2693989859","bids":[],"asks":[["4219.4","1.983"]]}}
1635444233.90479: {"type":"channel_data","connection_id":"60a4fc71-1312-4830-86f4-9eb98be106ac","message_id":595,"id":"ETH-USD","channel":"v3_orderbook","contents":{"offset":"2693989863","bids":[["4214.7","115.911"]],"asks":[]}}
1635444233.905243: {"type":"channel_data","connection_id":"60a4fc71-1312-4830-86f4-9eb98be106ac","message_id":596,"id":"ETH-USD","channel":"v3_orderbook","contents":{"offset":"2693989861","bids":[["4210.4","2.7"]],"asks":[]}}
1635444233.919096: {"type":"channel_data","connection_id":"60a4fc71-1312-4830-86f4-9eb98be106ac","message_id":597,"id":"XMR-USD","channel":"v3_orderbook","contents":{"offset":"2693989872","bids":[["264.3","3585.35"]],"asks":[]}}
1635444233.919647: {"type":"channel_data","connection_id":"60a4fc71-1312-4830-86f4-9eb98be106ac","message_id":598,"id":"ETH-USD","channel":"v3_orderbook","contents":{"offset":"2693989869","bids":[],"asks":[["4216.5","23.734"]]}}
1635444233.927573: {"type":"channel_data","connection_id":"60a4fc71-1312-4830-86f4-9eb98be106ac","message_id":599,"id":"EOS-USD","channel":"v3_orderbook","contents":{"offset":"2693989875","bids":[],"asks":[["4.404","16101"]]}}
1635444233.9294238: {"type":"channel_data","connection_id":"60a4fc71-1312-4830-86f4-9eb98be106ac","message_id":600,"id":"CRV-USD","channel":"v3_orderbook","contents":{"offset":"2693989873","bids":[["4.822","7227"],["4.821","90658"]],"asks":[]}}
1635444233.9436579: {"type":"channel_data","connection_id":"60a4fc71-1312-4830-86f4-9eb98be106ac","message_id":601,"id":"ETH-USD","channel":"v3_orderbook","contents":{"offset":"2693989882","bids":[],"asks":[["4216.5","0"]]}}
1635444233.9530728: {"type":"channel_data","connection_id":"60a4fc71-1312-4830-86f4-9eb98be106ac","message_id":602,"id":"EOS-USD","channel":"v3_orderbook","contents":{"offset":"2693989886","bids":[],"asks":[["4.404","14965"]]}}
1635444233.9744189: {"type":"channel_data","connection_id":"60a4fc71-1312-4830-86f4-9eb98be106ac","message_id":603,"id":"XMR-USD","channel":"v3_orderbook","contents":{"offset":"2693989891","bids":[["265","151.21"]],"asks":[]}}
1635444233.9902232: {"type":"channel_data","connection_id":"60a4fc71-1312-4830-86f4-9eb98be106ac","message_id":604,"id":"ETH-USD","channel":"v3_orderbook","contents":{"offset":"2693989896","bids":[["4213.7","0"]],"asks":[]}}
1635444233.990348: {"type":"channel_data","connection_id":"60a4fc71-1312-4830-86f4-9eb98be106ac","message_id":605,"id":"ETH-USD","channel":"v3_orderbook","contents":{"offset":"2693989900","bids":[],"asks":[["4217.5","0.435"]]}}
1635444233.990401: {"type":"channel_data","connection_id":"60a4fc71-1312-4830-86f4-9eb98be106ac","message_id":606,"id":"XMR-USD","channel":"v3_orderbook","contents":{"offset":"2693989895","bids":[],"asks":[["265.4","362.11"]]}}
1635444233.99723: {"type":"channel_data","connection_id":"60a4fc71-1312-4830-86f4-9eb98be106ac","message_id":607,"id":"LTC-USD","channel":"v3_orderbook","contents":{"offset":"2693989902","bids":[["187.7","332.8"]],"asks":[]}}
1635444233.997312: {"type":"channel_data","connection_id":"60a4fc71-1312-4830-86f4-9eb98be106ac","message_id":608,"id":"ETH-USD","channel":"v3_orderbook","contents":{"offset":"2693989903","bids":[],"asks":[["4217.6","9.784"]]}}
1635444234.0071099: {"type":"channel_data","connection_id":"60a4fc71-1312-4830-86f4-9eb98be106ac","message_id":609,"id":"ETH-USD","channel":"v3_orderbook","contents":{"offset":"2693989911","bids":[],"asks":[["4219.6","78.4"]]}}
1635444234.007194: {"type":"channel_data","connection_id":"60a4fc71-1312-4830-86f4-9eb98be106ac","message_id":610,"id":"XMR-USD","channel":"v3_orderbook","contents":{"offset":"2693989905","bids":[],"asks":[["265.7","3134.93"]]}}
1635444234.007232: {"type":"channel_data","connection_id":"60a4fc71-1312-4830-86f4-9eb98be106ac","message_id":611,"id":"XMR-USD","channel":"v3_orderbook","contents":{"offset":"2693989908","bids":[["264.7","736.16"]],"asks":[]}}
1635444234.012112: {"type":"channel_data","connection_id":"60a4fc71-1312-4830-86f4-9eb98be106ac","message_id":612,"id":"CRV-USD","channel":"v3_orderbook","contents":{"offset":"2693989913","bids":[["4.827","7227"],["4.826","0"]],"asks":[]}}
1635444234.017897: {"type":"channel_data","connection_id":"60a4fc71-1312-4830-86f4-9eb98be106ac","message_id":613,"id":"EOS-USD","channel":"v3_orderbook","contents":{"offset":"2693989918","bids":[],"asks":[["4.405","44299"]]}}
1635444234.018014: {"type":"channel_data","connection_id":"60a4fc71-1312-4830-86f4-9eb98be106ac","message_id":614,"id":"ETH-USD","channel":"v3_orderbook","contents":{"offset":"2693989914","bids":[],"asks":[["4216.5","23.734"]]}}
1635444234.0311658: {"type":"channel_data","connection_id":"60a4fc71-1312-4830-86f4-9eb98be106ac","message_id":615,"id":"ETH-USD","channel":"v3_orderbook","contents":{"offset":"2693989919","bids":[["4213.8","7.215"]],"asks":[]}}
1635444234.042193: {"type":"channel_data","connection_id":"60a4fc71-1312-4830-86f4-9eb98be106ac","message_id":616,"id":"ETH-USD","channel":"v3_orderbook","contents":{"offset":"2693989925","bids":[["4215.4","57.11"]],"asks":[]}}
1635444234.0422761: {"type":"channel_data","connection_id":"60a4fc71-1312-4830-86f4-9eb98be106ac","message_id":617,"id":"EOS-USD","channel":"v3_orderbook","contents":{"offset":"2693989927","bids":[["4.401","1136"]],"asks":[]}}
1635444234.0483809: {"type":"channel_data","connection_id":"60a4fc71-1312-4830-86f4-9eb98be106ac","message_id":618,"id":"ETH-USD","channel":"v3_orderbook","contents":{"offset":"2693989935","bids":[["4215.4","0"]],"asks":[]}}
1635444234.048992: {"type":"channel_data","connection_id":"60a4fc71-1312-4830-86f4-9eb98be106ac","message_id":619,"id":"ETH-USD","channel":"v3_orderbook","contents":{"offset":"2693989934","bids":[],"asks":[["4216.5","0"]]}}
1635444234.060062: {"type":"channel_data","connection_id":"60a4fc71-1312-4830-86f4-9eb98be106ac","message_id":620,"id":"EOS-USD","channel":"v3_orderbook","contents":{"offset":"2693989937","bids":[],"asks":[["4.405","43163"]]}}
1635444234.06416: {"type":"channel_data","connection_id":"60a4fc71-1312-4830-86f4-9eb98be106ac","message_id":621,"id":"SUSHI-USD","channel":"v3_orderbook","contents":{"offset":"2693989938","bids":[["10.791","0"]],"asks":[]}}
1635444234.0742888: {"type":"channel_data","connection_id":"60a4fc71-1312-4830-86f4-9eb98be106ac","message_id":622,"id":"EOS-USD","channel":"v3_orderbook","contents":{"offset":"2693989941","bids":[["4.401","0"]],"asks":[]}}
1635444234.0842938: {"type":"channel_data","connection_id":"60a4fc71-1312-4830-86f4-9eb98be106ac","message_id":623,"id":"UNI-USD","channel":"v3_orderbook","contents":{"offset":"2693989943","bids":[],"asks":[["25.194","1997.7"],["25.195","0"]]}}
1635444234.093994: {"type":"channel_data","connection_id":"60a4fc71-1312-4830-86f4-9eb98be106ac","message_id":624,"id":"SUSHI-USD","channel":"v3_orderbook","contents":{"offset":"2693989951","bids":[["10.79","266.5"]],"asks":[]}}
1635444234.0964532: {"type":"channel_data","connection_id":"60a4fc71-1312-4830-86f4-9eb98be106ac","message_id":625,"id":"SUSHI-USD","channel":"v3_orderbook","contents":{"offset":"2693989949","bids":[],"asks":[["10.807","12053.2"]]}}
1635444234.096537: {"type":"channel_data","connection_id":"60a4fc71-1312-4830-86f4-9eb98be106ac","message_id":626,"id":"UNI-USD","channel":"v3_orderbook","contents":{"offset":"2693989946","bids":[],"asks":[["25.169","1067.1"],["25.17","0"]]}}
1635444234.0965838: {"type":"channel_data","connection_id":"60a4fc71-1312-4830-86f4-9eb98be106ac","message_id":627,"id":"SUSHI-USD","channel":"v3_orderbook","contents":{"offset":"2693989952","bids":[["10.788","185.4"]],"asks":[]}}
1635444234.0966148: {"type":"channel_data","connection_id":"60a4fc71-1312-4830-86f4-9eb98be106ac","message_id":628,"id":"SUSHI-USD","channel":"v3_orderbook","contents":{"offset":"2693989947","bids":[["10.788","4635.1"]],"asks":[]}}
1635444234.106932: {"type":"channel_data","connection_id":"60a4fc71-1312-4830-86f4-9eb98be106ac","message_id":629,"id":"ETH-USD","channel":"v3_orderbook","contents":{"offset":"2693989956","bids":[["4215.9","146.113"]],"asks":[]}}
1635444234.107051: {"type":"channel_data","connection_id":"60a4fc71-1312-4830-86f4-9eb98be106ac","message_id":630,"id":"LTC-USD","channel":"v3_orderbook","contents":{"offset":"2693989957","bids":[["187.8","2927.98"]],"asks":[]}}
1635444234.107108: {"type":"channel_data","connection_id":"60a4fc71-1312-4830-86f4-9eb98be106ac","message_id":631,"id":"ETH-USD","channel":"v3_orderbook","contents":{"offset":"2693989954","bids":[],"asks":[["4216.4","47.471"]]}}
1635444234.120518: {"type":"channel_data","connection_id":"60a4fc71-1312-4830-86f4-9eb98be106ac","message_id":632,"id":"ETH-USD","channel":"v3_orderbook","contents":{"offset":"2693989958","bids":[["4215.9","446.113"]],"asks":[]}}
1635444234.1283069: {"type":"channel_data","connection_id":"60a4fc71-1312-4830-86f4-9eb98be106ac","message_id":633,"id":"UMA-USD","channel":"v3_orderbook","contents":{"offset":"2693989964","bids":[["11.27","29416.1"]],"asks":[]}}
1635444234.128373: {"type":"channel_data","connection_id":"60a4fc71-1312-4830-86f4-9eb98be106ac","message_id":634,"id":"EOS-USD","channel":"v3_orderbook","contents":{"offset":"2693989967","bids":[],"asks":[["4.404","16101"]]}}
1635444234.131476: {"type":"channel_data","connection_id":"60a4fc71-1312-4830-86f4-9eb98be106ac","message_id":635,"id":"BCH-USD","channel":"v3_orderbook","contents":{"offset":"2693989961","bids":[["574.3","154.88"]],"asks":[]}}
1635444234.131537: {"type":"channel_data","connection_id":"60a4fc71-1312-4830-86f4-9eb98be106ac","message_id":636,"id":"MKR-USD","channel":"v3_orderbook","contents":{"offset":"2693989965","bids":[],"asks":[["2384","25.302"]]}}
1635444234.138057: {"type":"channel_data","connection_id":"60a4fc71-1312-4830-86f4-9eb98be106ac","message_id":637,"id":"ETH-USD","channel":"v3_orderbook","contents":{"offset":"2693989970","bids":[],"asks":[["4216.5","23.734"]]}}
1635444234.150263: {"type":"channel_data","connection_id":"60a4fc71-1312-4830-86f4-9eb98be106ac","message_id":638,"id":"ETH-USD","channel":"v3_orderbook","contents":{"offset":"2693989980","bids":[],"asks":[["4217","2.922"]]}}
1635444234.150344: {"type":"channel_data","connection_id":"60a4fc71-1312-4830-86f4-9eb98be106ac","message_id":639,"id":"BCH-USD","channel":"v3_orderbook","contents":{"offset":"2693989975","bids":[["574.2","13.62"]],"asks":[]}}
1635444234.150382: {"type":"channel_data","connection_id":"60a4fc71-1312-4830-86f4-9eb98be106ac","message_id":640,"id":"MKR-USD","channel":"v3_orderbook","contents":{"offset":"2693989977","bids":[],"asks":[["2386","0.966"]]}}
1635444234.15248: {"type":"channel_data","connection_id":"60a4fc71-1312-4830-86f4-9eb98be106ac","message_id":641,"id":"ETH-USD","channel":"v3_orderbook","contents":{"offset":"2693989976","bids":[],"asks":[["4216.8","105.05"]]}}
