1635444240.13148: {"type":"channel_data","connection_id":"60a4fc71-1312-4830-86f4-9eb98be106ac","message_id":1513,"id":"ETH-USD","channel":"v3_orderbook","contents":{"offset":"2693992346","bids":[],"asks":[["4216.2","23.735"]]}}
1635444240.151989: {"type":"channel_data","connection_id":"60a4fc71-1312-4830-86f4-9eb98be106ac","message_id":1514,"id":"EOS-USD","channel":"v3_orderbook","contents":{"offset":"2693992351","bids":[["4.397","37241"]],"asks":[]}}
1635444240.1520698: {"type":"channel_data","connection_id":"60a4fc71-1312-4830-86f4-9eb98be106ac","message_id":1515,"id":"EOS-USD","channel":"v3_orderbook","contents":{"offset":"2693992350","bids":[],"asks":[["4.404","4821"]]}}
1635444240.164747: {"type":"channel_data","connection_id":"60a4fc71-1312-4830-86f4-9eb98be106ac","message_id":1516,"id":"ETH-USD","channel":"v3_orderbook","contents":{"offset":"2693992356","bids":[],"asks":[["4216.2","0"]]}}
1635444240.164841: {"type":"channel_data","connection_id":"60a4fc71-1312-4830-86f4-9eb98be106ac","message_id":1517,"id":"ETH-USD","channel":"v3_orderbook","contents":{"offset":"2693992357","bids":[],"asks":[["4217","0"]]}}
1635444240.165231: {"type":"channel_data","connection_id":"60a4fc71-1312-4830-86f4-9eb98be106ac","message_id":1518,"id":"SUSHI-USD","channel":"v3_orderbook","contents":{"offset":"2693992353","bids":[],"asks":[["10.909","15"],["10.921","927.4"]]}}
1635444240.1743202: {"type":"channel_data","connection_id":"60a4fc71-1312-4830-86f4-9eb98be106ac","message_id":1519,"id":"ETH-USD","channel":"v3_orderbook","contents":{"offset":"2693992359","bids":[["4213.4","0"]],"asks":[]}}
1635444240.177161: {"type":"channel_data","connection_id":"60a4fc71-1312-4830-86f4-9eb98be106ac","message_id":1520,"id":"ETH-USD","channel":"v3_orderbook","contents":{"offset":"2693992360","bids":[],"asks":[["4217.1","9.813"]]}}
1635444240.177221: {"type":"channel_data","connection_id":"60a4fc71-1312-4830-86f4-9eb98be106ac","message_id":1521,"id":"ETH-USD","channel":"v3_orderbook","contents":{"offset":"2693992361","bids":[["4213.5","7.216"]],"asks":[]}}
1635444240.1772559: {"type":"channel_data","connection_id":"60a4fc71-1312-4830-86f4-9eb98be106ac","message_id":1522,"id":"ETH-USD","channel":"v3_orderbook","contents":{"offset":"2693992358","bids":[],"asks":[["4216","57.91"]]}}
1635444240.190599: {"type":"channel_data","connection_id":"60a4fc71-1312-4830-86f4-9eb98be106ac","message_id":1523,"id":"ETH-USD","channel":"v3_trades","contents":{"trades":[{"size":"0.1","side":"BUY","price":"4216","createdAt":"2021-10-28T18:04:00.217Z"}]}}
1635444240.209072: {"type":"channel_data","connection_id":"60a4fc71-1312-4830-86f4-9eb98be106ac","message_id":1524,"id":"ETH-USD","channel":"v3_orderbook","contents":{"offset":"2693992363","bids":[],"asks":[["4218.8","21.946"]]}}
1635444240.218271: {"type":"channel_data","connection_id":"60a4fc71-1312-4830-86f4-9eb98be106ac","message_id":1525,"id":"ETH-USD","channel":"v3_orderbook","contents":{"offset":"2693992366","bids":[],"asks":[["4216.2","23.735"]]}}
1635444240.228949: {"type":"channel_data","connection_id":"60a4fc71-1312-4830-86f4-9eb98be106ac","message_id":1526,"id":"CRV-USD","channel":"v3_orderbook","contents":{"offset":"2693992368","bids":[["4.825","7227"],["4.824","0"]],"asks":[]}}
1635444240.236487: {"type":"channel_data","connection_id":"60a4fc71-1312-4830-86f4-9eb98be106ac","message_id":1527,"id":"ETH-USD","channel":"v3_orderbook","contents":{"offset":"2693992369","bids":[],"asks":[["4216.2","0"]]}}
1635444240.25038: {"type":"channel_data","connection_id":"60a4fc71-1312-4830-86f4-9eb98be106ac","message_id":1528,"id":"ETH-USD","channel":"v3_orderbook","contents":{"offset":"2693992370","bids":[],"asks":[["4216","57.01"]]}}
1635444240.2633758: {"type":"channel_data","connection_id":"60a4fc71-1312-4830-86f4-9eb98be106ac","message_id":1529,"id":"CRV-USD","channel":"v3_orderbook","contents":{"offset":"2693992376","bids":[],"asks":[["4.861","5463"]]}}
1635444240.2716968: {"type":"channel_data","connection_id":"60a4fc71-1312-4830-86f4-9eb98be106ac","message_id":1530,"id":"EOS-USD","channel":"v3_orderbook","contents":{"offset":"2693992378","bids":[],"asks":[["4.403","15738"]]}}
1635444240.271779: {"type":"channel_data","connection_id":"60a4fc71-1312-4830-86f4-9eb98be106ac","message_id":1531,"id":"ETH-USD","channel":"v3_orderbook","contents":{"offset":"2693992379","bids":[],"asks":[["4216.2","23.735"]]}}
1635444240.273669: {"type":"channel_data","connection_id":"60a4fc71-1312-4830-86f4-9eb98be106ac","message_id":1532,"id":"CRV-USD","channel":"v3_orderbook","contents":{"offset":"2693992381","bids":[["4.85","154"]],"asks":[]}}
1635444240.27372: {"type":"channel_data","connection_id":"60a4fc71-1312-4830-86f4-9eb98be106ac","message_id":1533,"id":"EOS-USD","channel":"v3_orderbook","contents":{"offset":"2693992382","bids":[],"asks":[["4.403","26935"]]}}
1635444240.2974179: {"type":"channel_data","connection_id":"60a4fc71-1312-4830-86f4-9eb98be106ac","message_id":1534,"id":"ETH-USD","channel":"v3_orderbook","contents":{"offset":"2693992386","bids":[],"asks":[["4216.2","0"]]}}
1635444240.313003: {"type":"channel_data","connection_id":"60a4fc71-1312-4830-86f4-9eb98be106ac","message_id":1535,"id":"CRV-USD","channel":"v3_orderbook","contents":{"offset":"2693992391","bids":[],"asks":[["4.86","592"]]}}
1635444240.313067: {"type":"channel_data","connection_id":"60a4fc71-1312-4830-86f4-9eb98be106ac","message_id":1536,"id":"CRV-USD","channel":"v3_orderbook","contents":{"offset":"2693992392","bids":[],"asks":[["4.861","4784"]]}}
1635444240.313091: {"type":"channel_data","connection_id":"60a4fc71-1312-4830-86f4-9eb98be106ac","message_id":1537,"id":"ETH-USD","channel":"v3_orderbook","contents":{"offset":"2693992389","bids":[],"asks":[["4218.8","0"]]}}
1635444240.323781: {"type":"channel_data","connection_id":"60a4fc71-1312-4830-86f4-9eb98be106ac","message_id":1538,"id":"CRV-USD","channel":"v3_orderbook","contents":{"offset":"2693992394","bids":[["4.848","2812"]],"asks":[]}}
1635444240.323843: {"type":"channel_data","connection_id":"60a4fc71-1312-4830-86f4-9eb98be106ac","message_id":1539,"id":"SUSHI-USD","channel":"v3_orderbook","contents":{"offset":"2693992395","bids":[],"asks":[["10.801","372.7"]]}}
1635444240.348232: {"type":"channel_data","connection_id":"60a4fc71-1312-4830-86f4-9eb98be106ac","message_id":1540,"id":"ETH-USD","channel":"v3_orderbook","contents":{"offset":"2693992401","bids":[],"asks":[["4216.2","23.735"]]}}
1635444240.371731: {"type":"channel_data","connection_id":"60a4fc71-1312-4830-86f4-9eb98be106ac","message_id":1541,"id":"LTC-USD","channel":"v3_orderbook","contents":{"offset":"2693992407","bids":[["181.3","60"]],"asks":[]}}
1635444240.3718: {"type":"channel_data","connection_id":"60a4fc71-1312-4830-86f4-9eb98be106ac","message_id":1542,"id":"ETH-USD","channel":"v3_orderbook","contents":{"offset":"2693992408","bids":[],"asks":[["4216.2","0"]]}}
1635444240.375772: {"type":"channel_data","connection_id":"60a4fc71-1312-4830-86f4-9eb98be106ac","message_id":1543,"id":"EOS-USD","channel":"v3_orderbook","contents":{"offset":"2693992411","bids":[["4.398","17010"]],"asks":[]}}
1635444240.37583: {"type":"channel_data","connection_id":"60a4fc71-1312-4830-86f4-9eb98be106ac","message_id":1544,"id":"LTC-USD","channel":"v3_orderbook","contents":{"offset":"2693992409","bids":[],"asks":[["194.5","60"]]}}
1635444240.3856158: {"type":"channel_data","connection_id":"60a4fc71-1312-4830-86f4-9eb98be106ac","message_id":1545,"id":"ETH-USD","channel":"v3_orderbook","contents":{"offset":"2693992415","bids":[],"asks":[["4217.1","0.03"]]}}
1635444240.388385: {"type":"channel_data","connection_id":"60a4fc71-1312-4830-86f4-9eb98be106ac","message_id":1546,"id":"ETH-USD","channel":"v3_orderbook","contents":{"offset":"2693992413","bids":[["4213.5","0"]],"asks":[]}}
1635444240.388443: {"type":"channel_data","connection_id":"60a4fc71-1312-4830-86f4-9eb98be106ac","message_id":1547,"id":"SUSHI-USD","channel":"v3_orderbook","contents":{"offset":"2693992414","bids":[["10.752","101.9"]],"asks":[]}}
1635444240.3989792: {"type":"channel_data","connection_id":"60a4fc71-1312-4830-86f4-9eb98be106ac","message_id":1548,"id":"ETH-USD","channel":"v3_orderbook","contents":{"offset":"2693992416","bids":[],"asks":[["4217.2","32.279"]]}}
1635444240.424552: {"type":"channel_data","connection_id":"60a4fc71-1312-4830-86f4-9eb98be106ac","message_id":1549,"id":"ETH-USD","channel":"v3_orderbook","contents":{"offset":"2693992423","bids":[],"asks":[["4216.2","23.735"]]}}
1635444240.424617: {"type":"channel_data","connection_id":"60a4fc71-1312-4830-86f4-9eb98be106ac","message_id":1550,"id":"LTC-USD","channel":"v3_orderbook","contents":{"offset":"2693992424","bids":[["187.2","83.71"]],"asks":[]}}
1635444240.43426: {"type":"channel_data","connection_id":"60a4fc71-1312-4830-86f4-9eb98be106ac","message_id":1551,"id":"CRV-USD","channel":"v3_orderbook","contents":{"offset":"2693992427","bids":[["4.848","2161"]],"asks":[]}}
1635444240.437354: {"type":"channel_data","connection_id":"60a4fc71-1312-4830-86f4-9eb98be106ac","message_id":1552,"id":"ETH-USD","channel":"v3_orderbook","contents":{"offset":"2693992431","bids":[],"asks":[["4218.3","75.249"]]}}
1635444240.4374342: {"type":"channel_data","connection_id":"60a4fc71-1312-4830-86f4-9eb98be106ac","message_id":1553,"id":"ETH-USD","channel":"v3_orderbook","contents":{"offset":"2693992432","bids":[["4213.6","31.657"]],"asks":[]}}
1635444240.437463: {"type":"channel_data","connection_id":"60a4fc71-1312-4830-86f4-9eb98be106ac","message_id":1554,"id":"CRV-USD","channel":"v3_orderbook","contents":{"offset":"2693992430","bids":[],"asks":[["4.86","5457"]]}}
1635444240.4515: {"type":"channel_data","connection_id":"60a4fc71-1312-4830-86f4-9eb98be106ac","message_id":1555,"id":"ETH-USD","channel":"v3_orderbook","contents":{"offset":"2693992434","bids":[],"asks":[["4216.2","0"]]}}
1635444240.4515631: {"type":"channel_data","connection_id":"60a4fc71-1312-4830-86f4-9eb98be106ac","message_id":1556,"id":"ETH-USD","channel":"v3_orderbook","contents":{"offset":"2693992435","bids":[],"asks":[["4219.2","12.727"]]}}
1635444240.473662: {"type":"channel_data","connection_id":"60a4fc71-1312-4830-86f4-9eb98be106ac","message_id":1557,"id":"LTC-USD","channel":"v3_orderbook","contents":{"offset":"2693992444","bids":[],"asks":[["188.6","66.85"]]}}
1635444240.48444: {"type":"channel_data","connection_id":"60a4fc71-1312-4830-86f4-9eb98be106ac","message_id":1558,"id":"ETH-USD","channel":"v3_orderbook","contents":{"offset":"2693992450","bids":[],"asks":[["4216.2","23.735"]]}}
1635444240.4987671: {"type":"channel_data","connection_id":"60a4fc71-1312-4830-86f4-9eb98be106ac","message_id":1559,"id":"ETH-USD","channel":"v3_orderbook","contents":{"offset":"2693992457","bids":[],"asks":[["4219.1","1.423"]]}}
1635444240.498841: {"type":"channel_data","connection_id":"60a4fc71-1312-4830-86f4-9eb98be106ac","message_id":1560,"id":"UNI-USD","channel":"v3_orderbook","contents":{"offset":"2693992454","bids":[["24.865","998.8"],["24.864","0"]],"asks":[]}}
1635444240.512064: {"type":"channel_data","connection_id":"60a4fc71-1312-4830-86f4-9eb98be106ac","message_id":1561,"id":"ETH-USD","channel":"v3_orderbook","contents":{"offset":"2693992459","bids":[],"asks":[["4216.2","0"]]}}
1635444240.578036: {"type":"channel_data","connection_id":"60a4fc71-1312-4830-86f4-9eb98be106ac","message_id":1562,"id":"ETH-USD","channel":"v3_orderbook","contents":{"offset":"2693992460","bids":[],"asks":[["4218.8","1.423"]]}}
1635444240.578111: {"type":"channel_data","connection_id":"60a4fc71-1312-4830-86f4-9eb98be106ac","message_id":1563,"id":"ETH-USD","channel":"v3_orderbook","contents":{"offset":"2693992461","bids":[["4213.6","13.207"]],"asks":[]}}
1635444240.578649: {"type":"channel_data","connection_id":"60a4fc71-1312-4830-86f4-9eb98be106ac","message_id":1564,"id":"ETH-USD","channel":"v3_orderbook","contents":{"offset":"2693992462","bids":[],"asks":[["4216.5","9.4"]]}}
1635444240.590304: {"type":"channel_data","connection_id":"60a4fc71-1312-4830-86f4-9eb98be106ac","message_id":1565,"id":"CRV-USD","channel":"v3_orderbook","contents":{"offset":"2693992468","bids":[["4.818","17660"],["4.817","0"]],"asks":[]}}
1635444240.62566: {"type":"channel_data","connection_id":"60a4fc71-1312-4830-86f4-9eb98be106ac","message_id":1566,"id":"ETH-USD","channel":"v3_orderbook","contents":{"offset":"2693992479","bids":[],"asks":[["4217.2","22.496"]]}}
1635444240.63642: {"type":"channel_data","connection_id":"60a4fc71-1312-4830-86f4-9eb98be106ac","message_id":1567,"id":"ETH-USD","channel":"v3_orderbook","contents":{"offset":"2693992487","bids":[],"asks":[["4216.2","23.735"]]}}
1635444240.636543: {"type":"channel_data","connection_id":"60a4fc71-1312-4830-86f4-9eb98be106ac","message_id":1568,"id":"ETH-USD","channel":"v3_orderbook","contents":{"offset":"2693992484","bids":[["4213.5","7.216"]],"asks":[]}}
1635444240.6404: {"type":"channel_data","connection_id":"60a4fc71-1312-4830-86f4-9eb98be106ac","message_id":1569,"id":"ETH-USD","channel":"v3_orderbook","contents":{"offset":"2693992486","bids":[["4213.6","5.991"]],"asks":[]}}
1635444240.640482: {"type":"channel_data","connection_id":"60a4fc71-1312-4830-86f4-9eb98be106ac","message_id":1570,"id":"ETH-USD","channel":"v3_orderbook","contents":{"offset":"2693992489","bids":[["4213.3","19.79"]],"asks":[]}}
1635444240.658795: {"type":"channel_data","connection_id":"60a4fc71-1312-4830-86f4-9eb98be106ac","message_id":1571,"id":"ETH-USD","channel":"v3_orderbook","contents":{"offset":"2693992492","bids":[],"asks":[["4216.2","0"]]}}
1635444240.6711712: {"type":"channel_data","connection_id":"60a4fc71-1312-4830-86f4-9eb98be106ac","message_id":1572,"id":"ETH-USD","channel":"v3_orderbook","contents":{"offset":"2693992498","bids":[],"asks":[["4217.1","9.813"]]}}
1635444240.700887: {"type":"channel_data","connection_id":"60a4fc71-1312-4830-86f4-9eb98be106ac","message_id":1573,"id":"ETH-USD","channel":"v3_orderbook","contents":{"offset":"2693992503","bids":[],"asks":[["4216.8","24.496"]]}}
1635444240.701525: {"type":"channel_data","connection_id":"60a4fc71-1312-4830-86f4-9eb98be106ac","message_id":1574,"id":"ETH-USD","channel":"v3_orderbook","contents":{"offset":"2693992504","bids":[],"asks":[["4216.4","113.38"]]}}
1635444240.702344: {"type":"channel_data","connection_id":"60a4fc71-1312-4830-86f4-9eb98be106ac","message_id":1575,"id":"ETH-USD","channel":"v3_orderbook","contents":{"offset":"2693992507","bids":[["4215.5","69.031"]],"asks":[]}}
1635444240.7067368: {"type":"channel_data","connection_id":"60a4fc71-1312-4830-86f4-9eb98be106ac","message_id":1576,"id":"ETH-USD","channel":"v3_orderbook","contents":{"offset":"2693992502","bids":[["4213.1","0"]],"asks":[]}}
1635444240.70993: {"type":"channel_data","connection_id":"60a4fc71-1312-4830-86f4-9eb98be106ac","message_id":1577,"id":"ETH-USD","channel":"v3_orderbook","contents":{"offset":"2693992511","bids":[],"asks":[["4217.3","2.922"]]}}
1635444240.7143419: {"type":"channel_data","connection_id":"60a4fc71-1312-4830-86f4-9eb98be106ac","message_id":1578,"id":"ETH-USD","channel":"v3_orderbook","contents":{"offset":"2693992514","bids":[],"asks":[["4218.5","0"]]}}
1635444240.714412: {"type":"channel_data","connection_id":"60a4fc71-1312-4830-86f4-9eb98be106ac","message_id":1579,"id":"ETH-USD","channel":"v3_orderbook","contents":{"offset":"2693992517","bids":[["4211.9","0"]],"asks":[]}}
1635444240.7239838: {"type":"channel_data","connection_id":"60a4fc71-1312-4830-86f4-9eb98be106ac","message_id":1580,"id":"ETH-USD","channel":"v3_orderbook","contents":{"offset":"2693992520","bids":[["4215.9","468.489"]],"asks":[]}}
1635444240.7274282: {"type":"channel_data","connection_id":"60a4fc71-1312-4830-86f4-9eb98be106ac","message_id":1581,"id":"ETH-USD","channel":"v3_orderbook","contents":{"offset":"2693992524","bids":[["4214.7","1.691"]],"asks":[]}}
1635444240.727494: {"type":"channel_data","connection_id":"60a4fc71-1312-4830-86f4-9eb98be106ac","message_id":1582,"id":"UMA-USD","channel":"v3_orderbook","contents":{"offset":"2693992527","bids":[["11.27","29416.1"]],"asks":[]}}
1635444240.737932: {"type":"channel_data","connection_id":"60a4fc71-1312-4830-86f4-9eb98be106ac","message_id":1583,"id":"ETH-USD","channel":"v3_orderbook","contents":{"offset":"2693992528","bids":[],"asks":[["4216.2","23.735"]]}}
1635444240.7481852: {"type":"channel_data","connection_id":"60a4fc71-1312-4830-86f4-9eb98be106ac","message_id":1584,"id":"ETH-USD","channel":"v3_orderbook","contents":{"offset":"2693992536","bids":[["4215.9","492.221"]],"asks":[]}}
1635444240.7482738: {"type":"channel_data","connection_id":"60a4fc71-1312-4830-86f4-9eb98be106ac","message_id":1585,"id":"ETH-USD","channel":"v3_orderbook","contents":{"offset":"2693992537","bids":[],"asks":[["4216.2","0"]]}}
1635444240.767425: {"type":"channel_data","connection_id":"60a4fc71-1312-4830-86f4-9eb98be106ac","message_id":1586,"id":"ETH-USD","channel":"v3_orderbook","contents":{"offset":"2693992540","bids":[["4213.5","0"]],"asks":[]}}
1635444240.767509: {"type":"channel_data","connection_id":"60a4fc71-1312-4830-86f4-9eb98be106ac","message_id":1587,"id":"ETH-USD","channel":"v3_orderbook","contents":{"offset":"2693992541","bids":[],"asks":[["4217.1","0.03"]]}}
1635444240.767545: {"type":"channel_data","connection_id":"60a4fc71-1312-4830-86f4-9eb98be106ac","message_id":1588,"id":"XMR-USD","channel":"v3_orderbook","contents":{"offset":"2693992542","bids":[],"asks":[["265.3","0"]]}}
1635444240.774847: {"type":"channel_data","connection_id":"60a4fc71-1312-4830-86f4-9eb98be106ac","message_id":1589,"id":"SUSHI-USD","channel":"v3_orderbook","contents":{"offset":"2693992546","bids":[],"asks":[["10.807","11971.9"]]}}
1635444240.774915: {"type":"channel_data","connection_id":"60a4fc71-1312-4830-86f4-9eb98be106ac","message_id":1590,"id":"ETH-USD","channel":"v3_orderbook","contents":{"offset":"2693992545","bids":[["4213.6","13.207"]],"asks":[]}}
1635444240.7782679: {"type":"channel_data","connection_id":"60a4fc71-1312-4830-86f4-9eb98be106ac","message_id":1591,"id":"XMR-USD","channel":"v3_orderbook","contents":{"offset":"2693992544","bids":[["264.9","75.75"]],"asks":[]}}
1635444240.795466: {"type":"channel_data","connection_id":"60a4fc71-1312-4830-86f4-9eb98be106ac","message_id":1592,"id":"XMR-USD","channel":"v3_orderbook","contents":{"offset":"2693992554","bids":[["264.1","88.86"],["264","45"]],"asks":[]}}
1635444240.795561: {"type":"channel_data","connection_id":"60a4fc71-1312-4830-86f4-9eb98be106ac","message_id":1593,"id":"MKR-USD","channel":"v3_orderbook","contents":{"offset":"2693992552","bids":[["2382","0"]],"asks":[]}}
1635444240.795601: {"type":"channel_data","connection_id":"60a4fc71-1312-4830-86f4-9eb98be106ac","message_id":1594,"id":"UMA-USD","channel":"v3_orderbook","contents":{"offset":"2693992553","bids":[["11.27","29150.7"]],"asks":[]}}
1635444240.795628: {"type":"channel_data","connection_id":"60a4fc71-1312-4830-86f4-9eb98be106ac","message_id":1595,"id":"MKR-USD","channel":"v3_orderbook","contents":{"offset":"2693992549","bids":[["2379","51.779"]],"asks":[]}}
1635444240.795649: {"type":"channel_data","connection_id":"60a4fc71-1312-4830-86f4-9eb98be106ac","message_id":1596,"id":"MKR-USD","channel":"v3_orderbook","contents":{"offset":"2693992550","bids":[],"asks":[["2388","415.402"]]}}
1635444240.80436: {"type":"channel_data","connection_id":"60a4fc71-1312-4830-86f4-9eb98be106ac","message_id":1597,"id":"XMR-USD","channel":"v3_orderbook","contents":{"offset":"2693992562","bids":[["264.7","434.34"]],"asks":[]}}
1635444240.804429: {"type":"channel_data","connection_id":"60a4fc71-1312-4830-86f4-9eb98be106ac","message_id":1598,"id":"XMR-USD","channel":"v3_orderbook","contents":{"offset":"2693992561","bids":[],"asks":[["265.7","2833.41"]]}}
1635444240.8044538: {"type":"channel_data","connection_id":"60a4fc71-1312-4830-86f4-9eb98be106ac","message_id":1599,"id":"ETH-USD","channel":"v3_orderbook","contents":{"offset":"2693992558","bids":[["4214","992.139"]],"asks":[]}}
1635444240.811858: {"type":"channel_data","connection_id":"60a4fc71-1312-4830-86f4-9eb98be106ac","message_id":1600,"id":"ETH-USD","channel":"v3_orderbook","contents":{"offset":"2693992564","bids":[],"asks":[["4217.2","32.279"]]}}
1635444240.814496: {"type":"channel_data","connection_id":"60a4fc71-1312-4830-86f4-9eb98be106ac","message_id":1601,"id":"SUSHI-USD","channel":"v3_orderbook","contents":{"offset":"2693992565","bids":[["10.759","3139.3"],["10.749","0"]],"asks":[]}}
1635444240.8240519: {"type":"channel_data","connection_id":"60a4fc71-1312-4830-86f4-9eb98be106ac","message_id":1602,"id":"MKR-USD","channel":"v3_orderbook","contents":{"offset":"2693992570","bids":[["2380","11.498"]],"asks":[]}}
1635444240.8241239: {"type":"channel_data","connection_id":"60a4fc71-1312-4830-86f4-9eb98be106ac","message_id":1603,"id":"MKR-USD","channel":"v3_orderbook","contents":{"offset":"2693992568","bids":[["2380","13.704"]],"asks":[]}}
1635444240.827369: {"type":"channel_data","connection_id":"60a4fc71-1312-4830-86f4-9eb98be106ac","message_id":1604,"id":"MKR-USD","channel":"v3_orderbook","contents":{"offset":"2693992569","bids":[],"asks":[["2385","91.727"]]}}
1635444240.827439: {"type":"channel_data","connection_id":"60a4fc71-1312-4830-86f4-9eb98be106ac","message_id":1605,"id":"ETH-USD","channel":"v3_orderbook","contents":{"offset":"2693992566","bids":[],"asks":[["4216.6","82.479"]]}}
1635444240.8341591: {"type":"channel_data","connection_id":"60a4fc71-1312-4830-86f4-9eb98be106ac","message_id":1606,"id":"MKR-USD","channel":"v3_orderbook","contents":{"offset":"2693992578","bids":[],"asks":[["2384","10.29"]]}}
1635444240.834223: {"type":"channel_data","connection_id":"60a4fc71-1312-4830-86f4-9eb98be106ac","message_id":1607,"id":"UMA-USD","channel":"v3_orderbook","contents":{"offset":"2693992576","bids":[["11.26","10032.2"]],"asks":[]}}
1635444240.834252: {"type":"channel_data","connection_id":"60a4fc71-1312-4830-86f4-9eb98be106ac","message_id":1608,"id":"ETH-USD","channel":"v3_orderbook","contents":{"offset":"2693992572","bids":[["4215.8","0"]],"asks":[]}}
1635444240.8367481: {"type":"channel_data","connection_id":"60a4fc71-1312-4830-86f4-9eb98be106ac","message_id":1609,"id":"MKR-USD","channel":"v3_orderbook","contents":{"offset":"2693992577","bids":[["2378","12.25"]],"asks":[]}}
1635444240.848782: {"type":"channel_data","connection_id":"60a4fc71-1312-4830-86f4-9eb98be106ac","message_id":1610,"id":"ETH-USD","channel":"v3_orderbook","contents":{"offset":"2693992581","bids":[["4214.5","47.465"]],"asks":[]}}
1635444240.8488479: {"type":"channel_data","connection_id":"60a4fc71-1312-4830-86f4-9eb98be106ac","message_id":1611,"id":"ETH-USD","channel":"v3_orderbook","contents":{"offset":"2693992582","bids":[["4215.3","141.814"]],"asks":[]}}
1635444240.8488698: {"type":"channel_data","connection_id":"60a4fc71-1312-4830-86f4-9eb98be106ac","message_id":1612,"id":"MKR-USD","channel":"v3_orderbook","contents":{"offset":"2693992575","bids":[["2377","69.424"]],"asks":[]}}
1635444240.859091: {"type":"channel_data","connection_id":"60a4fc71-1312-4830-86f4-9eb98be106ac","message_id":1613,"id":"UMA-USD","channel":"v3_orderbook","contents":{"offset":"2693992588","bids":[["11.27","29293.5"]],"asks":[]}}
1635444240.8591611: {"type":"channel_data","connection_id":"60a4fc71-1312-4830-86f4-9eb98be106ac","message_id":1614,"id":"ETH-USD","channel":"v3_orderbook","contents":{"offset":"2693992585","bids":[],"asks":[["4217.5","0.875"]]}}
1635444240.8613079: {"type":"channel_data","connection_id":"60a4fc71-1312-4830-86f4-9eb98be106ac","message_id":1615,"id":"ETH-USD","channel":"v3_orderbook","contents":{"offset":"2693992589","bids":[["4215.3","24.524"]],"asks":[]}}
1635444240.87185: {"type":"channel_data","connection_id":"60a4fc71-1312-4830-86f4-9eb98be106ac","message_id":1616,"id":"SUSHI-USD","channel":"v3_orderbook","contents":{"offset":"2693992596","bids":[],"asks":[["10.805","602.3"]]}}
1635444240.8719418: {"type":"channel_data","connection_id":"60a4fc71-1312-4830-86f4-9eb98be106ac","message_id":1617,"id":"UMA-USD","channel":"v3_orderbook","contents":{"offset":"2693992593","bids":[["11.29","10009.8"]],"asks":[]}}
1635444240.871968: {"type":"channel_data","connection_id":"60a4fc71-1312-4830-86f4-9eb98be106ac","message_id":1618,"id":"SUSHI-USD","channel":"v3_orderbook","contents":{"offset":"2693992597","bids":[],"asks":[["10.807","12267.2"]]}}
1635444240.882284: {"type":"channel_data","connection_id":"60a4fc71-1312-4830-86f4-9eb98be106ac","message_id":1619,"id":"UMA-USD","channel":"v3_orderbook","contents":{"offset":"2693992600","bids":[["11.29","6673.2"]],"asks":[]}}
1635444240.8823638: {"type":"channel_data","connection_id":"60a4fc71-1312-4830-86f4-9eb98be106ac","message_id":1620,"id":"MKR-USD","channel":"v3_orderbook","contents":{"offset":"2693992601","bids":[["2374","433.75"],["2373","2.146"]],"asks":[]}}
1635444240.890989: {"type":"channel_data","connection_id":"60a4fc71-1312-4830-86f4-9eb98be106ac","message_id":1621,"id":"ETH-USD","channel":"v3_orderbook","contents":{"offset":"2693992605","bids":[["4215","22.873"]],"asks":[]}}
1635444240.8918872: {"type":"channel_data","connection_id":"60a4fc71-1312-4830-86f4-9eb98be106ac","message_id":1622,"id":"MKR-USD","channel":"v3_orderbook","contents":{"offset":"2693992606","bids":[["2380","13.704"]],"asks":[]}}
1635444240.903666: {"type":"channel_data","connection_id":"60a4fc71-1312-4830-86f4-9eb98be106ac","message_id":1623,"id":"MKR-USD","channel":"v3_orderbook","contents":{"offset":"2693992611","bids":[["2377","52.703"]],"asks":[]}}
1635444240.9037251: {"type":"channel_data","connection_id":"60a4fc71-1312-4830-86f4-9eb98be106ac","message_id":1624,"id":"MKR-USD","channel":"v3_orderbook","contents":{"offset":"2693992609","bids":[["2375","74.981"]],"asks":[]}}
1635444240.935271: {"type":"channel_data","connection_id":"60a4fc71-1312-4830-86f4-9eb98be106ac","message_id":1625,"id":"UMA-USD","channel":"v3_orderbook","contents":{"offset":"2693992615","bids":[],"asks":[["11.31","13443.8"]]}}
1635444240.9353411: {"type":"channel_data","connection_id":"60a4fc71-1312-4830-86f4-9eb98be106ac","message_id":1626,"id":"ETH-USD","channel":"v3_orderbook","contents":{"offset":"2693992614","bids":[],"asks":[["4216.6","84.729"]]}}
1635444240.960295: {"type":"channel_data","connection_id":"60a4fc71-1312-4830-86f4-9eb98be106ac","message_id":1627,"id":"MKR-USD","channel":"v3_orderbook","contents":{"offset":"2693992621","bids":[["2373","14.749"]],"asks":[]}}
1635444240.9603572: {"type":"channel_data","connection_id":"60a4fc71-1312-4830-86f4-9eb98be106ac","message_id":1628,"id":"UMA-USD","channel":"v3_orderbook","contents":{"offset":"2693992622","bids":[],"asks":[["11.33","28348.5"]]}}
1635444240.966966: {"type":"channel_data","connection_id":"60a4fc71-1312-4830-86f4-9eb98be106ac","message_id":1629,"id":"UMA-USD","channel":"v3_orderbook","contents":{"offset":"2693992625","bids":[["11.27","29559"]],"asks":[]}}
1635444240.967941: {"type":"channel_data","connection_id":"60a4fc71-1312-4830-86f4-9eb98be106ac","message_id":1630,"id":"UMA-USD","channel":"v3_orderbook","contents":{"offset":"2693992623","bids":[["11.28","1824.3"]],"asks":[]}}
1635444240.990002: {"type":"channel_data","connection_id":"60a4fc71-1312-4830-86f4-9eb98be106ac","message_id":1631,"id":"ETH-USD","channel":"v3_orderbook","contents":{"offset":"2693992628","bids":[["4213.7","1898.587"]],"asks":[]}}
1635444240.990072: {"type":"channel_data","connection_id":"60a4fc71-1312-4830-86f4-9eb98be106ac","message_id":1632,"id":"ETH-USD","channel":"v3_orderbook","contents":{"offset":"2693992630","bids":[["4215.7","58.65"]],"asks":[]}}
1635444240.990099: {"type":"channel_data","connection_id":"60a4fc71-1312-4830-86f4-9eb98be106ac","message_id":1633,"id":"ETH-USD","channel":"v3_orderbook","contents":{"offset":"2693992626","bids":[["4214.9","117.31"]],"asks":[]}}
1635444240.992789: {"type":"channel_data","connection_id":"60a4fc71-1312-4830-86f4-9eb98be106ac","message_id":1634,"id":"UNI-USD","channel":"v3_orderbook","contents":{"offset":"2693992629","bids":[],"asks":[["25.077","0"]]}}
1635444241.007464: {"type":"channel_data","connection_id":"60a4fc71-1312-4830-86f4-9eb98be106ac","message_id":1635,"id":"UMA-USD","channel":"v3_orderbook","contents":{"offset":"2693992633","bids":[["11.27","29293.5"]],"asks":[]}}
1635444241.007533: {"type":"channel_data","connection_id":"60a4fc71-1312-4830-86f4-9eb98be106ac","message_id":1636,"id":"UMA-USD","channel":"v3_orderbook","contents":{"offset":"2693992636","bids":[],"asks":[["11.33","28207.6"]]}}
1635444241.007561: {"type":"channel_data","connection_id":"60a4fc71-1312-4830-86f4-9eb98be106ac","message_id":1637,"id":"MKR-USD","channel":"v3_orderbook","contents":{"offset":"2693992634","bids":[["2378","14.247"]],"asks":[]}}
1635444241.007585: {"type":"channel_data","connection_id":"60a4fc71-1312-4830-86f4-9eb98be106ac","message_id":1638,"id":"UNI-USD","channel":"v3_orderbook","contents":{"offset":"2693992631","bids":[],"asks":[["25.087","1585.8"]]}}
1635444241.01732: {"type":"channel_data","connection_id":"60a4fc71-1312-4830-86f4-9eb98be106ac","message_id":1639,"id":"SUSHI-USD","channel":"v3_orderbook","contents":{"offset":"2693992640","bids":[["10.789","5812.7"]],"asks":[]}}
1635444241.017385: {"type":"channel_data","connection_id":"60a4fc71-1312-4830-86f4-9eb98be106ac","message_id":1640,"id":"MKR-USD","channel":"v3_orderbook","contents":{"offset":"2693992641","bids":[],"asks":[["2391","21.223"]]}}
1635444241.017419: {"type":"channel_data","connection_id":"60a4fc71-1312-4830-86f4-9eb98be106ac","message_id":1641,"id":"MKR-USD","channel":"v3_orderbook","contents":{"offset":"2693992638","bids":[["2374","427.75"]],"asks":[]}}
1635444241.017445: {"type":"channel_data","connection_id":"60a4fc71-1312-4830-86f4-9eb98be106ac","message_id":1642,"id":"SUSHI-USD","channel":"v3_orderbook","contents":{"offset":"2693992639","bids":[["10.784","4375.6"]],"asks":[]}}
1635444241.030488: {"type":"channel_data","connection_id":"60a4fc71-1312-4830-86f4-9eb98be106ac","message_id":1643,"id":"UMA-USD","channel":"v3_orderbook","contents":{"offset":"2693992645","bids":[],"asks":[["11.31","13584.7"]]}}
1635444241.0603058: {"type":"channel_data","connection_id":"60a4fc71-1312-4830-86f4-9eb98be106ac","message_id":1644,"id":"ETH-USD","channel":"v3_orderbook","contents":{"offset":"2693992650","bids":[],"asks":[["4216.6","60.996"]]}}
1635444241.072177: {"type":"channel_data","connection_id":"60a4fc71-1312-4830-86f4-9eb98be106ac","message_id":1645,"id":"ETH-USD","channel":"v3_orderbook","contents":{"offset":"2693992652","bids":[["4212.4","4463.708"]],"asks":[]}}
1635444241.072247: {"type":"channel_data","connection_id":"60a4fc71-1312-4830-86f4-9eb98be106ac","message_id":1646,"id":"MKR-USD","channel":"v3_orderbook","contents":{"offset":"2693992654","bids":[],"asks":[["2384","18.574"]]}}
1635444241.072277: {"type":"channel_data","connection_id":"60a4fc71-1312-4830-86f4-9eb98be106ac","message_id":1647,"id":"SUSHI-USD","channel":"v3_orderbook","contents":{"offset":"2693992655","bids":[["10.752","0"],["10.75","101.9"]],"asks":[]}}
1635444241.090304: {"type":"channel_data","connection_id":"60a4fc71-1312-4830-86f4-9eb98be106ac","message_id":1648,"id":"XMR-USD","channel":"v3_orderbook","contents":{"offset":"2693992659","bids":[],"asks":[["265.6","339.57"]]}}
1635444241.090383: {"type":"channel_data","connection_id":"60a4fc71-1312-4830-86f4-9eb98be106ac","message_id":1649,"id":"ETH-USD","channel":"v3_orderbook","contents":{"offset":"2693992658","bids":[["4215.7","0"]],"asks":[]}}
1635444241.090421: {"type":"channel_data","connection_id":"60a4fc71-1312-4830-86f4-9eb98be106ac","message_id":1650,"id":"SUSHI-USD","channel":"v3_orderbook","contents":{"offset":"2693992657","bids":[],"asks":[["10.832","101.9"],["10.833","0"]]}}
1635444241.099781: {"type":"channel_data","connection_id":"60a4fc71-1312-4830-86f4-9eb98be106ac","message_id":1651,"id":"CRV-USD","channel":"v3_orderbook","contents":{"offset":"2693992661","bids":[["4.836","1696"]],"asks":[]}}
1635444241.103967: {"type":"channel_data","connection_id":"60a4fc71-1312-4830-86f4-9eb98be106ac","message_id":1652,"id":"ETH-USD","channel":"v3_orderbook","contents":{"offset":"2693992660","bids":[],"asks":[["4216.1","127.82"]]}}
1635444241.1040242: {"type":"channel_data","connection_id":"60a4fc71-1312-4830-86f4-9eb98be106ac","message_id":1653,"id":"CRV-USD","channel":"v3_orderbook","contents":{"offset":"2693992662","bids":[],"asks":[["4.86","6137"]]}}
1635444241.118751: {"type":"channel_data","connection_id":"60a4fc71-1312-4830-86f4-9eb98be106ac","message_id":1654,"id":"MKR-USD","channel":"v3_orderbook","contents":{"offset":"2693992664","bids":[["2381","18.6"]],"asks":[]}}
1635444241.118819: {"type":"channel_data","connection_id":"60a4fc71-1312-4830-86f4-9eb98be106ac","message_id":1655,"id":"CRV-USD","channel":"v3_orderbook","contents":{"offset":"2693992663","bids":[],"asks":[["4.859","6515"]]}}
1635444241.128278: {"type":"channel_data","connection_id":"60a4fc71-1312-4830-86f4-9eb98be106ac","message_id":1656,"id":"MKR-USD","channel":"v3_orderbook","contents":{"offset":"2693992667","bids":[],"asks":[["2383","17.488"]]}}
1635444241.128374: {"type":"channel_data","connection_id":"60a4fc71-1312-4830-86f4-9eb98be106ac","message_id":1657,"id":"UMA-USD","channel":"v3_orderbook","contents":{"offset":"2693992668","bids":[["11.27","29404.4"]],"asks":[]}}
1635444241.152286: {"type":"channel_data","connection_id":"60a4fc71-1312-4830-86f4-9eb98be106ac","message_id":1658,"id":"ETH-USD","channel":"v3_orderbook","contents":{"offset":"2693992677","bids":[],"asks":[["4216.6","58.746"]]}}
1635444241.1617322: {"type":"channel_data","connection_id":"60a4fc71-1312-4830-86f4-9eb98be106ac","message_id":1659,"id":"UNI-USD","channel":"v3_orderbook","contents":{"offset":"2693992683","bids":[],"asks":[["25.087","0"]]}}
1635444241.16435: {"type":"channel_data","connection_id":"60a4fc71-1312-4830-86f4-9eb98be106ac","message_id":1660,"id":"ETH-USD","channel":"v3_orderbook","contents":{"offset":"2693992684","bids":[["4214.4","0.355"]],"asks":[]}}
1635444241.174242: {"type":"channel_data","connection_id":"60a4fc71-1312-4830-86f4-9eb98be106ac","message_id":1661,"id":"ETH-USD","channel":"v3_orderbook","contents":{"offset":"2693992688","bids":[],"asks":[["4219.1","0"]]}}
1635444241.174303: {"type":"channel_data","connection_id":"60a4fc71-1312-4830-86f4-9eb98be106ac","message_id":1662,"id":"XMR-USD","channel":"v3_orderbook","contents":{"offset":"2693992689","bids":[["264.7","736.22"]],"asks":[]}}
1635444241.17433: {"type":"channel_data","connection_id":"60a4fc71-1312-4830-86f4-9eb98be106ac","message_id":1663,"id":"ETH-USD","channel":"v3_orderbook","contents":{"offset":"2693992686","bids":[],"asks":[["4219.2","11.304"]]}}
1635444241.187933: {"type":"channel_data","connection_id":"60a4fc71-1312-4830-86f4-9eb98be106ac","message_id":1664,"id":"ETH-USD","channel":"v3_orderbook","contents":{"offset":"2693992691","bids":[],"asks":[["4217","47.465"]]}}
1635444241.1880052: {"type":"channel_data","connection_id":"60a4fc71-1312-4830-86f4-9eb98be106ac","message_id":1665,"id":"MKR-USD","channel":"v3_orderbook","contents":{"offset":"2693992690","bids":[["2378","72.426"]],"asks":[]}}
1635444241.208391: {"type":"channel_data","connection_id":"60a4fc71-1312-4830-86f4-9eb98be106ac","message_id":1666,"id":"ETH-USD","channel":"v3_orderbook","contents":{"offset":"2693992699","bids":[["4215.9","548.133"]],"asks":[]}}
1635444241.2084532: {"type":"channel_data","connection_id":"60a4fc71-1312-4830-86f4-9eb98be106ac","message_id":1667,"id":"XMR-USD","channel":"v3_orderbook","contents":{"offset":"2693992693","bids":[["265","75.47"]],"asks":[]}}
1635444241.208478: {"type":"channel_data","connection_id":"60a4fc71-1312-4830-86f4-9eb98be106ac","message_id":1668,"id":"ETH-USD","channel":"v3_orderbook","contents":{"offset":"2693992697","bids":[["4215.9","489.483"]],"asks":[]}}
1635444241.2084951: {"type":"channel_data","connection_id":"60a4fc71-1312-4830-86f4-9eb98be106ac","message_id":1669,"id":"CRV-USD","channel":"v3_orderbook","contents":{"offset":"2693992698","bids":[["4.851","377"]],"asks":[]}}
1635444241.208514: {"type":"channel_data","connection_id":"60a4fc71-1312-4830-86f4-9eb98be106ac","message_id":1670,"id":"ETH-USD","channel":"v3_orderbook","contents":{"offset":"2693992694","bids":[],"asks":[["4217.3","0"]]}}
1635444241.208533: {"type":"channel_data","connection_id":"60a4fc71-1312-4830-86f4-9eb98be106ac","message_id":1671,"id":"UNI-USD","channel":"v3_orderbook","contents":{"offset":"2693992695","bids":[],"asks":[["25.077","1585.8"]]}}
1635444241.213384: {"type":"channel_data","connection_id":"60a4fc71-1312-4830-86f4-9eb98be106ac","message_id":1672,"id":"ETH-USD","channel":"v3_orderbook","contents":{"offset":"2693992701","bids":[["4215.2","2.839"]],"asks":[]}}
1635444241.213446: {"type":"channel_data","connection_id":"60a4fc71-1312-4830-86f4-9eb98be106ac","message_id":1673,"id":"CRV-USD","channel":"v3_orderbook","contents":{"offset":"2693992700","bids":[["4.799","1126"]],"asks":[]}}
1635444241.222223: {"type":"channel_data","connection_id":"60a4fc71-1312-4830-86f4-9eb98be106ac","message_id":1674,"id":"SUSHI-USD","channel":"v3_orderbook","contents":{"offset":"2693992704","bids":[],"asks":[["10.798","12158.3"]]}}
1635444241.2222872: {"type":"channel_data","connection_id":"60a4fc71-1312-4830-86f4-9eb98be106ac","message_id":1675,"id":"ETH-USD","channel":"v3_orderbook","contents":{"offset":"2693992705","bids":[["4215.9","548.033"]],"asks":[]}}
1635444241.238133: {"type":"channel_data","connection_id":"60a4fc71-1312-4830-86f4-9eb98be106ac","message_id":1676,"id":"ETH-USD","channel":"v3_trades","contents":{"trades":[{"size":"0.1","side":"SELL","price":"4215.9","createdAt":"2021-10-28T18:04:01.261Z"}]}}
1635444241.244427: {"type":"channel_data","connection_id":"60a4fc71-1312-4830-86f4-9eb98be106ac","message_id":1677,"id":"ETH-USD","channel":"v3_orderbook","contents":{"offset":"2693992709","bids":[],"asks":[["4216.1","125.57"]]}}
1635444241.253073: {"type":"channel_data","connection_id":"60a4fc71-1312-4830-86f4-9eb98be106ac","message_id":1678,"id":"CRV-USD","channel":"v3_orderbook","contents":{"offset":"2693992712","bids":[["4.821","89712"]],"asks":[]}}
1635444241.255321: {"type":"channel_data","connection_id":"60a4fc71-1312-4830-86f4-9eb98be106ac","message_id":1679,"id":"CRV-USD","channel":"v3_orderbook","contents":{"offset":"2693992713","bids":[["4.851","0"]],"asks":[]}}
1635444241.255381: {"type":"channel_data","connection_id":"60a4fc71-1312-4830-86f4-9eb98be106ac","message_id":1680,"id":"MKR-USD","channel":"v3_orderbook","contents":{"offset":"2693992711","bids":[],"asks":[["2385","93.724"]]}}
1635444241.2647521: {"type":"channel_data","connection_id":"60a4fc71-1312-4830-86f4-9eb98be106ac","message_id":1681,"id":"ETH-USD","channel":"v3_orderbook","contents":{"offset":"2693992716","bids":[],"asks":[["4217.8","1916.378"]]}}
1635444241.279731: {"type":"channel_data","connection_id":"60a4fc71-1312-4830-86f4-9eb98be106ac","message_id":1682,"id":"MKR-USD","channel":"v3_orderbook","contents":{"offset":"2693992721","bids":[],"asks":[["2387","59.078"]]}}
1635444241.279814: {"type":"channel_data","connection_id":"60a4fc71-1312-4830-86f4-9eb98be106ac","message_id":1683,"id":"XMR-USD","channel":"v3_orderbook","contents":{"offset":"2693992718","bids":[],"asks":[["265.3","75.39"]]}}
1635444241.291448: {"type":"channel_data","connection_id":"60a4fc71-1312-4830-86f4-9eb98be106ac","message_id":1684,"id":"XMR-USD","channel":"v3_orderbook","contents":{"offset":"2693992724","bids":[],"asks":[["266","70"],["266.1","23.39"]]}}
1635444241.392405: {"type":"channel_data","connection_id":"60a4fc71-1312-4830-86f4-9eb98be106ac","message_id":1685,"id":"CRV-USD","channel":"v3_orderbook","contents":{"offset":"2693992749","bids":[["4.842","1282"]],"asks":[]}}
1635444241.3995788: {"type":"channel_data","connection_id":"60a4fc71-1312-4830-86f4-9eb98be106ac","message_id":1686,"id":"ETH-USD","channel":"v3_orderbook","contents":{"offset":"2693992755","bids":[],"asks":[["4219.1","4461.679"]]}}
1635444241.411972: {"type":"channel_data","connection_id":"60a4fc71-1312-4830-86f4-9eb98be106ac","message_id":1687,"id":"CRV-USD","channel":"v3_orderbook","contents":{"offset":"2693992763","bids":[["4.843","8834"]],"asks":[]}}
1635444241.4130912: {"type":"channel_data","connection_id":"60a4fc71-1312-4830-86f4-9eb98be106ac","message_id":1688,"id":"ETH-USD","channel":"v3_orderbook","contents":{"offset":"2693992759","bids":[],"asks":[["4217","71.196"]]}}
1635444241.4464908: {"type":"channel_data","connection_id":"60a4fc71-1312-4830-86f4-9eb98be106ac","message_id":1689,"id":"MKR-USD","channel":"v3_orderbook","contents":{"offset":"2693992776","bids":[["2373","20.749"]],"asks":[]}}
1635444241.447127: {"type":"channel_data","connection_id":"60a4fc71-1312-4830-86f4-9eb98be106ac","message_id":1690,"id":"MKR-USD","channel":"v3_orderbook","contents":{"offset":"2693992777","bids":[],"asks":[["2383","25.942"]]}}
1635444241.475395: {"type":"channel_data","connection_id":"60a4fc71-1312-4830-86f4-9eb98be106ac","message_id":1691,"id":"MKR-USD","channel":"v3_orderbook","contents":{"offset":"2693992789","bids":[],"asks":[["2390","2118.12"]]}}
1635444241.5070841: {"type":"channel_data","connection_id":"60a4fc71-1312-4830-86f4-9eb98be106ac","message_id":1692,"id":"MKR-USD","channel":"v3_orderbook","contents":{"offset":"2693992800","bids":[],"asks":[["2383","17.488"]]}}
1635444241.5281012: {"type":"channel_data","connection_id":"60a4fc71-1312-4830-86f4-9eb98be106ac","message_id":1693,"id":"UMA-USD","channel":"v3_orderbook","contents":{"offset":"2693992810","bids":[["11.27","29669.9"]],"asks":[]}}
1635444241.555252: {"type":"channel_data","connection_id":"60a4fc71-1312-4830-86f4-9eb98be106ac","message_id":1694,"id":"UMA-USD","channel":"v3_orderbook","contents":{"offset":"2693992822","bids":[["11.27","29404.4"]],"asks":[]}}
1635444241.5757592: {"type":"channel_data","connection_id":"60a4fc71-1312-4830-86f4-9eb98be106ac","message_id":1695,"id":"UNI-USD","channel":"v3_orderbook","contents":{"offset":"2693992829","bids":[],"asks":[["25.077","0"]]}}
1635444241.575823: {"type":"channel_data","connection_id":"60a4fc71-1312-4830-86f4-9eb98be106ac","message_id":1696,"id":"ETH-USD","channel":"v3_orderbook","contents":{"offset":"2693992830","bids":[],"asks":[["4216","59.26"]]}}
1635444241.5833988: {"type":"channel_data","connection_id":"60a4fc71-1312-4830-86f4-9eb98be106ac","message_id":1697,"id":"UNI-USD","channel":"v3_orderbook","contents":{"offset":"2693992833","bids":[],"asks":[["25.087","1585.8"]]}}
1635444241.607851: {"type":"channel_data","connection_id":"60a4fc71-1312-4830-86f4-9eb98be106ac","message_id":1698,"id":"MKR-USD","channel":"v3_orderbook","contents":{"offset":"2693992849","bids":[["2286","0"]],"asks":[]}}
1635444241.642393: {"type":"channel_data","connection_id":"60a4fc71-1312-4830-86f4-9eb98be106ac","message_id":1699,"id":"UMA-USD","channel":"v3_orderbook","contents":{"offset":"2693992880","bids":[],"asks":[["11.31","10248.1"]]}}
1635444241.6497002: {"type":"channel_data","connection_id":"60a4fc71-1312-4830-86f4-9eb98be106ac","message_id":1700,"id":"UMA-USD","channel":"v3_orderbook","contents":{"offset":"2693992888","bids":[["11.29","3336.6"]],"asks":[]}}
1635444241.6624792: {"type":"channel_data","connection_id":"60a4fc71-1312-4830-86f4-9eb98be106ac","message_id":1701,"id":"MKR-USD","channel":"v3_orderbook","contents":{"offset":"2693992895","bids":[["2285","0"]],"asks":[]}}
1635444241.6656718: {"type":"channel_data","connection_id":"60a4fc71-1312-4830-86f4-9eb98be106ac","message_id":1702,"id":"UMA-USD","channel":"v3_orderbook","contents":{"offset":"2693992897","bids":[["11.28","5160.9"]],"asks":[]}}
1635444241.670943: {"type":"channel_data","connection_id":"60a4fc71-1312-4830-86f4-9eb98be106ac","message_id":1703,"id":"MKR-USD","channel":"v3_orderbook","contents":{"offset":"2693992905","bids":[["2284","2.757"]],"asks":[]}}
1635444241.6710012: {"type":"channel_data","connection_id":"60a4fc71-1312-4830-86f4-9eb98be106ac","message_id":1704,"id":"UMA-USD","channel":"v3_orderbook","contents":{"offset":"2693992901","bids":[["11.28","8497.5"]],"asks":[]}}
1635444241.674397: {"type":"channel_data","connection_id":"60a4fc71-1312-4830-86f4-9eb98be106ac","message_id":1705,"id":"UMA-USD","channel":"v3_orderbook","contents":{"offset":"2693992904","bids":[],"asks":[["11.3","3336.6"]]}}
1635444241.68089: {"type":"channel_data","connection_id":"60a4fc71-1312-4830-86f4-9eb98be106ac","message_id":1706,"id":"UMA-USD","channel":"v3_orderbook","contents":{"offset":"2693992908","bids":[["11.28","11834.1"]],"asks":[]}}
1635444241.704449: {"type":"channel_data","connection_id":"60a4fc71-1312-4830-86f4-9eb98be106ac","message_id":1707,"id":"CRV-USD","channel":"v3_orderbook","contents":{"offset":"2693992914","bids":[["4.848","1624"]],"asks":[]}}
1635444241.733501: {"type":"channel_data","connection_id":"60a4fc71-1312-4830-86f4-9eb98be106ac","message_id":1708,"id":"UMA-USD","channel":"v3_orderbook","contents":{"offset":"2693992927","bids":[["11.27","29261.6"]],"asks":[]}}
1635444241.752854: {"type":"channel_data","connection_id":"60a4fc71-1312-4830-86f4-9eb98be106ac","message_id":1709,"id":"UMA-USD","channel":"v3_orderbook","contents":{"offset":"2693992934","bids":[],"asks":[["11.31","10107.2"]]}}
1635444241.7575989: {"type":"channel_data","connection_id":"60a4fc71-1312-4830-86f4-9eb98be106ac","message_id":1710,"id":"ETH-USD","channel":"v3_orderbook","contents":{"offset":"2693992939","bids":[["4215.5","71.769"]],"asks":[]}}
1635444241.774839: {"type":"channel_data","connection_id":"60a4fc71-1312-4830-86f4-9eb98be106ac","message_id":1711,"id":"MKR-USD","channel":"v3_orderbook","contents":{"offset":"2693992944","bids":[["2284","0"]],"asks":[]}}
1635444241.7809842: {"type":"channel_data","connection_id":"60a4fc71-1312-4830-86f4-9eb98be106ac","message_id":1712,"id":"UMA-USD","channel":"v3_orderbook","contents":{"offset":"2693992956","bids":[["11.27","29527.1"]],"asks":[]}}
1635444241.782059: {"type":"channel_data","connection_id":"60a4fc71-1312-4830-86f4-9eb98be106ac","message_id":1713,"id":"UMA-USD","channel":"v3_orderbook","contents":{"offset":"2693992951","bids":[["11.28","11976.9"]],"asks":[]}}
1635444241.816585: {"type":"channel_data","connection_id":"60a4fc71-1312-4830-86f4-9eb98be106ac","message_id":1714,"id":"UMA-USD","channel":"v3_orderbook","contents":{"offset":"2693992976","bids":[["11.27","29261.6"]],"asks":[]}}
1635444241.851134: {"type":"channel_data","connection_id":"60a4fc71-1312-4830-86f4-9eb98be106ac","message_id":1715,"id":"CRV-USD","channel":"v3_orderbook","contents":{"offset":"2693992989","bids":[["4.851","377"]],"asks":[]}}
1635444241.900919: {"type":"channel_data","connection_id":"60a4fc71-1312-4830-86f4-9eb98be106ac","message_id":1716,"id":"UMA-USD","channel":"v3_orderbook","contents":{"offset":"2693992998","bids":[],"asks":[["11.3","1836.6"]]}}
1635444241.918237: {"type":"channel_data","connection_id":"60a4fc71-1312-4830-86f4-9eb98be106ac","message_id":1717,"id":"UMA-USD","channel":"v3_trades","contents":{"trades":[{"size":"1500","side":"BUY","price":"11.3","createdAt":"2021-10-28T18:04:01.937Z"}]}}
1635444241.92441: {"type":"channel_data","connection_id":"60a4fc71-1312-4830-86f4-9eb98be106ac","message_id":1718,"id":"CRV-USD","channel":"v3_orderbook","contents":{"offset":"2693993026","bids":[["4.845","594"]],"asks":[]}}
1635444241.925243: {"type":"channel_data","connection_id":"60a4fc71-1312-4830-86f4-9eb98be106ac","message_id":1719,"id":"CRV-USD","channel":"v3_orderbook","contents":{"offset":"2693993029","bids":[],"asks":[["4.854","246"]]}}
1635444241.937242: {"type":"channel_data","connection_id":"60a4fc71-1312-4830-86f4-9eb98be106ac","message_id":1720,"id":"ETH-USD","channel":"v3_orderbook","contents":{"offset":"2693993032","bids":[],"asks":[["4219.2","12.727"]]}}
1635444241.9489532: {"type":"channel_data","connection_id":"60a4fc71-1312-4830-86f4-9eb98be106ac","message_id":1721,"id":"SUSHI-USD","channel":"v3_orderbook","contents":{"offset":"2693993036","bids":[["10.772","8588.4"]],"asks":[]}}
1635444241.968883: {"type":"channel_data","connection_id":"60a4fc71-1312-4830-86f4-9eb98be106ac","message_id":1722,"id":"SUSHI-USD","channel":"v3_orderbook","contents":{"offset":"2693993043","bids":[["10.767","4130.4"]],"asks":[]}}
1635444241.994912: {"type":"channel_data","connection_id":"60a4fc71-1312-4830-86f4-9eb98be106ac","message_id":1723,"id":"MKR-USD","channel":"v3_orderbook","contents":{"offset":"2693993049","bids":[["2377","10.632"]],"asks":[]}}
1635444242.016462: {"type":"channel_data","connection_id":"60a4fc71-1312-4830-86f4-9eb98be106ac","message_id":1724,"id":"CRV-USD","channel":"v3_orderbook","contents":{"offset":"2693993053","bids":[["4.851","0"]],"asks":[]}}
1635444242.016546: {"type":"channel_data","connection_id":"60a4fc71-1312-4830-86f4-9eb98be106ac","message_id":1725,"id":"XMR-USD","channel":"v3_orderbook","contents":{"offset":"2693993055","bids":[],"asks":[["265.3","0"]]}}
1635444242.025223: {"type":"channel_data","connection_id":"60a4fc71-1312-4830-86f4-9eb98be106ac","message_id":1726,"id":"CRV-USD","channel":"v3_orderbook","contents":{"offset":"2693993066","bids":[],"asks":[["4.854","1246"]]}}
1635444242.063492: {"type":"channel_data","connection_id":"60a4fc71-1312-4830-86f4-9eb98be106ac","message_id":1727,"id":"CRV-USD","channel":"v3_orderbook","contents":{"offset":"2693993088","bids":[],"asks":[["4.854","246"]]}}
1635444242.063573: {"type":"channel_data","connection_id":"60a4fc71-1312-4830-86f4-9eb98be106ac","message_id":1728,"id":"ETH-USD","channel":"v3_orderbook","contents":{"offset":"2693993091","bids":[],"asks":[["4219.1","4463.102"]]}}
1635444242.091157: {"type":"channel_data","connection_id":"60a4fc71-1312-4830-86f4-9eb98be106ac","message_id":1729,"id":"ETH-USD","channel":"v3_orderbook","contents":{"offset":"2693993108","bids":[["4215.6","2.738"]],"asks":[]}}
1635444242.094792: {"type":"channel_data","connection_id":"60a4fc71-1312-4830-86f4-9eb98be106ac","message_id":1730,"id":"XMR-USD","channel":"v3_orderbook","contents":{"offset":"2693993112","bids":[["264.9","0"]],"asks":[]}}
1635444242.104975: {"type":"channel_data","connection_id":"60a4fc71-1312-4830-86f4-9eb98be106ac","message_id":1731,"id":"CRV-USD","channel":"v3_orderbook","contents":{"offset":"2693993120","bids":[["4.847","15313"]],"asks":[]}}
1635444242.1310048: {"type":"channel_data","connection_id":"60a4fc71-1312-4830-86f4-9eb98be106ac","message_id":1732,"id":"ETH-USD","channel":"v3_orderbook","contents":{"offset":"2693993129","bids":[["4215.9","553.966"]],"asks":[]}}
1635444242.131082: {"type":"channel_data","connection_id":"60a4fc71-1312-4830-86f4-9eb98be106ac","message_id":1733,"id":"XMR-USD","channel":"v3_orderbook","contents":{"offset":"2693993135","bids":[["265","151.22"]],"asks":[]}}
1635444242.170342: {"type":"channel_data","connection_id":"60a4fc71-1312-4830-86f4-9eb98be106ac","message_id":1734,"id":"CRV-USD","channel":"v3_orderbook","contents":{"offset":"2693993155","bids":[["4.844","8757"]],"asks":[]}}
1635444242.170411: {"type":"channel_data","connection_id":"60a4fc71-1312-4830-86f4-9eb98be106ac","message_id":1735,"id":"CRV-USD","channel":"v3_orderbook","contents":{"offset":"2693993158","bids":[["4.843","821"]],"asks":[]}}
1635444242.1704378: {"type":"channel_data","connection_id":"60a4fc71-1312-4830-86f4-9eb98be106ac","message_id":1736,"id":"CRV-USD","channel":"v3_orderbook","contents":{"offset":"2693993161","bids":[["4.85","531"]],"asks":[]}}
1635444242.188461: {"type":"channel_data","connection_id":"60a4fc71-1312-4830-86f4-9eb98be106ac","message_id":1737,"id":"ETH-USD","channel":"v3_orderbook","contents":{"offset":"2693993173","bids":[["4215.5","69.031"]],"asks":[]}}
1635444242.18853: {"type":"channel_data","connection_id":"60a4fc71-1312-4830-86f4-9eb98be106ac","message_id":1738,"id":"XMR-USD","channel":"v3_orderbook","contents":{"offset":"2693993178","bids":[],"asks":[["265.4","362.11"]]}}
1635444242.189724: {"type":"channel_data","connection_id":"60a4fc71-1312-4830-86f4-9eb98be106ac","message_id":1739,"id":"MKR-USD","channel":"v3_orderbook","contents":{"offset":"2693993183","bids":[["2282","2.649"]],"asks":[]}}
1635444242.239661: {"type":"channel_data","connection_id":"60a4fc71-1312-4830-86f4-9eb98be106ac","message_id":1740,"id":"UMA-USD","channel":"v3_orderbook","contents":{"offset":"2693993213","bids":[["11.27","29527.1"]],"asks":[]}}
1635444242.2504792: {"type":"channel_data","connection_id":"60a4fc71-1312-4830-86f4-9eb98be106ac","message_id":1741,"id":"SUSHI-USD","channel":"v3_orderbook","contents":{"offset":"2693993231","bids":[],"asks":[["10.805","324.6"]]}}
1635444242.251881: {"type":"channel_data","connection_id":"60a4fc71-1312-4830-86f4-9eb98be106ac","message_id":1742,"id":"SUSHI-USD","channel":"v3_orderbook","contents":{"offset":"2693993237","bids":[],"asks":[["10.795","0"]]}}
1635444242.254606: {"type":"channel_data","connection_id":"60a4fc71-1312-4830-86f4-9eb98be106ac","message_id":1743,"id":"SUSHI-USD","channel":"v3_orderbook","contents":{"offset":"2693993242","bids":[["10.786","8748.8"]],"asks":[]}}
1635444242.25529: {"type":"channel_data","connection_id":"60a4fc71-1312-4830-86f4-9eb98be106ac","message_id":1744,"id":"SUSHI-USD","channel":"v3_orderbook","contents":{"offset":"2693993244","bids":[],"asks":[["10.798","8453.7"]]}}
1635444242.2581902: {"type":"channel_data","connection_id":"60a4fc71-1312-4830-86f4-9eb98be106ac","message_id":1745,"id":"SUSHI-USD","channel":"v3_orderbook","contents":{"offset":"2693993245","bids":[["10.772","0"]],"asks":[]}}
1635444242.258247: {"type":"channel_data","connection_id":"60a4fc71-1312-4830-86f4-9eb98be106ac","message_id":1746,"id":"CRV-USD","channel":"v3_orderbook","contents":{"offset":"2693993243","bids":[],"asks":[["4.854","1246"]]}}
1635444242.2625768: {"type":"channel_data","connection_id":"60a4fc71-1312-4830-86f4-9eb98be106ac","message_id":1747,"id":"SUSHI-USD","channel":"v3_orderbook","contents":{"offset":"2693993241","bids":[],"asks":[["10.807","2267.2"]]}}
1635444242.262639: {"type":"channel_data","connection_id":"60a4fc71-1312-4830-86f4-9eb98be106ac","message_id":1748,"id":"SUSHI-USD","channel":"v3_orderbook","contents":{"offset":"2693993246","bids":[],"asks":[["10.805","0"]]}}
1635444242.266728: {"type":"channel_data","connection_id":"60a4fc71-1312-4830-86f4-9eb98be106ac","message_id":1749,"id":"ETH-USD","channel":"v3_orderbook","contents":{"offset":"2693993255","bids":[],"asks":[["4216.6","22.496"]]}}
1635444242.277005: {"type":"channel_data","connection_id":"60a4fc71-1312-4830-86f4-9eb98be106ac","message_id":1750,"id":"ETH-USD","channel":"v3_orderbook","contents":{"offset":"2693993258","bids":[],"asks":[["4216.4","56.396"]]}}
1635444242.277112: {"type":"channel_data","connection_id":"60a4fc71-1312-4830-86f4-9eb98be106ac","message_id":1751,"id":"SUSHI-USD","channel":"v3_orderbook","contents":{"offset":"2693993257","bids":[["10.767","416.5"]],"asks":[]}}
1635444242.287175: {"type":"channel_data","connection_id":"60a4fc71-1312-4830-86f4-9eb98be106ac","message_id":1752,"id":"UMA-USD","channel":"v3_orderbook","contents":{"offset":"2693993265","bids":[["11.27","29261.6"]],"asks":[]}}
1635444242.302588: {"type":"channel_data","connection_id":"60a4fc71-1312-4830-86f4-9eb98be106ac","message_id":1753,"id":"SUSHI-USD","channel":"v3_orderbook","contents":{"offset":"2693993270","bids":[["10.772","3713.9"]],"asks":[]}}
1635444242.302675: {"type":"channel_data","connection_id":"60a4fc71-1312-4830-86f4-9eb98be106ac","message_id":1754,"id":"ETH-USD","channel":"v3_orderbook","contents":{"offset":"2693993276","bids":[],"asks":[["4216","59.16"]]}}
1635444242.303091: {"type":"channel_data","connection_id":"60a4fc71-1312-4830-86f4-9eb98be106ac","message_id":1755,"id":"UNI-USD","channel":"v3_orderbook","contents":{"offset":"2693993283","bids":[],"asks":[["25.204","998.8"],["25.205","0"]]}}
1635444242.3053281: {"type":"channel_data","connection_id":"60a4fc71-1312-4830-86f4-9eb98be106ac","message_id":1756,"id":"MKR-USD","channel":"v3_orderbook","contents":{"offset":"2693993280","bids":[],"asks":[["2385","78.712"]]}}
1635444242.308749: {"type":"channel_data","connection_id":"60a4fc71-1312-4830-86f4-9eb98be106ac","message_id":1757,"id":"SUSHI-USD","channel":"v3_orderbook","contents":{"offset":"2693993290","bids":[["10.685","0"],["10.682","13393.3"]],"asks":[]}}
1635444242.308807: {"type":"channel_data","connection_id":"60a4fc71-1312-4830-86f4-9eb98be106ac","message_id":1758,"id":"MKR-USD","channel":"v3_orderbook","contents":{"offset":"2693993285","bids":[],"asks":[["2385","63.7"]]}}
1635444242.314304: {"type":"channel_data","connection_id":"60a4fc71-1312-4830-86f4-9eb98be106ac","message_id":1759,"id":"ETH-USD","channel":"v3_trades","contents":{"trades":[{"size":"0.1","side":"BUY","price":"4216","createdAt":"2021-10-28T18:04:02.339Z"}]}}
1635444242.3143501: {"type":"channel_data","connection_id":"60a4fc71-1312-4830-86f4-9eb98be106ac","message_id":1760,"id":"CRV-USD","channel":"v3_orderbook","contents":{"offset":"2693993284","bids":[["4.803","1059"]],"asks":[]}}
1635444242.320833: {"type":"channel_data","connection_id":"60a4fc71-1312-4830-86f4-9eb98be106ac","message_id":1761,"id":"MKR-USD","channel":"v3_orderbook","contents":{"offset":"2693993298","bids":[],"asks":[["2383","32.5"]]}}
1635444242.3209028: {"type":"channel_data","connection_id":"60a4fc71-1312-4830-86f4-9eb98be106ac","message_id":1762,"id":"MKR-USD","channel":"v3_orderbook","contents":{"offset":"2693993299","bids":[],"asks":[["2384","48.598"]]}}
1635444242.320936: {"type":"channel_data","connection_id":"60a4fc71-1312-4830-86f4-9eb98be106ac","message_id":1763,"id":"SUSHI-USD","channel":"v3_orderbook","contents":{"offset":"2693993292","bids":[["10.789","5546.2"]],"asks":[]}}
1635444242.320968: {"type":"channel_data","connection_id":"60a4fc71-1312-4830-86f4-9eb98be106ac","message_id":1764,"id":"MKR-USD","channel":"v3_orderbook","contents":{"offset":"2693993294","bids":[],"asks":[["2384","33.586"]]}}
1635444242.326561: {"type":"channel_data","connection_id":"60a4fc71-1312-4830-86f4-9eb98be106ac","message_id":1765,"id":"UNI-USD","channel":"v3_orderbook","contents":{"offset":"2693993300","bids":[],"asks":[["25.167","1067.1"],["25.168","0"]]}}
1635444242.332928: {"type":"channel_data","connection_id":"60a4fc71-1312-4830-86f4-9eb98be106ac","message_id":1766,"id":"MKR-USD","channel":"v3_orderbook","contents":{"offset":"2693993301","bids":[],"asks":[["2384","63.61"]]}}
1635444242.332982: {"type":"channel_data","connection_id":"60a4fc71-1312-4830-86f4-9eb98be106ac","message_id":1767,"id":"MKR-USD","channel":"v3_orderbook","contents":{"offset":"2693993302","bids":[],"asks":[["2385","48.688"]]}}
1635444242.336579: {"type":"channel_data","connection_id":"60a4fc71-1312-4830-86f4-9eb98be106ac","message_id":1768,"id":"SUSHI-USD","channel":"v3_orderbook","contents":{"offset":"2693993304","bids":[["10.786","4298.2"]],"asks":[]}}
1635444242.336632: {"type":"channel_data","connection_id":"60a4fc71-1312-4830-86f4-9eb98be106ac","message_id":1769,"id":"SUSHI-USD","channel":"v3_orderbook","contents":{"offset":"2693993307","bids":[],"asks":[["10.798","4002.3"]]}}
1635444242.3366542: {"type":"channel_data","connection_id":"60a4fc71-1312-4830-86f4-9eb98be106ac","message_id":1770,"id":"SUSHI-USD","channel":"v3_orderbook","contents":{"offset":"2693993305","bids":[["10.785","138.9"]],"asks":[]}}
1635444242.346287: {"type":"channel_data","connection_id":"60a4fc71-1312-4830-86f4-9eb98be106ac","message_id":1771,"id":"SUSHI-USD","channel":"v3_orderbook","contents":{"offset":"2693993318","bids":[["10.786","4002.3"]],"asks":[]}}
1635444242.346376: {"type":"channel_data","connection_id":"60a4fc71-1312-4830-86f4-9eb98be106ac","message_id":1772,"id":"MKR-USD","channel":"v3_orderbook","contents":{"offset":"2693993323","bids":[["2380","28.716"]],"asks":[]}}
1635444242.346446: {"type":"channel_data","connection_id":"60a4fc71-1312-4830-86f4-9eb98be106ac","message_id":1773,"id":"UNI-USD","channel":"v3_orderbook","contents":{"offset":"2693993321","bids":[],"asks":[["25.192","1997.7"],["25.193","0"]]}}
1635444242.3484511: {"type":"channel_data","connection_id":"60a4fc71-1312-4830-86f4-9eb98be106ac","message_id":1774,"id":"ETH-USD","channel":"v3_orderbook","contents":{"offset":"2693993324","bids":[],"asks":[["4217.2","22.496"]]}}
1635444242.3547058: {"type":"channel_data","connection_id":"60a4fc71-1312-4830-86f4-9eb98be106ac","message_id":1775,"id":"ETH-USD","channel":"v3_orderbook","contents":{"offset":"2693993334","bids":[],"asks":[["4217.4","0"]]}}
1635444242.354781: {"type":"channel_data","connection_id":"60a4fc71-1312-4830-86f4-9eb98be106ac","message_id":1776,"id":"ETH-USD","channel":"v3_orderbook","contents":{"offset":"2693993332","bids":[["4213.6","5.991"]],"asks":[]}}
1635444242.356621: {"type":"channel_data","connection_id":"60a4fc71-1312-4830-86f4-9eb98be106ac","message_id":1777,"id":"SUSHI-USD","channel":"v3_orderbook","contents":{"offset":"2693993340","bids":[],"asks":[["10.818","3124.3"]]}}
1635444242.359901: {"type":"channel_data","connection_id":"60a4fc71-1312-4830-86f4-9eb98be106ac","message_id":1778,"id":"SUSHI-USD","channel":"v3_orderbook","contents":{"offset":"2693993343","bids":[],"asks":[["10.87","0"],["10.872","2319.7"]]}}
1635444242.375604: {"type":"channel_data","connection_id":"60a4fc71-1312-4830-86f4-9eb98be106ac","message_id":1779,"id":"ETH-USD","channel":"v3_orderbook","contents":{"offset":"2693993359","bids":[["4213.8","7.215"]],"asks":[]}}
1635444242.38467: {"type":"channel_data","connection_id":"60a4fc71-1312-4830-86f4-9eb98be106ac","message_id":1780,"id":"ETH-USD","channel":"v3_orderbook","contents":{"offset":"2693993366","bids":[],"asks":[["4217.4","9.784"]]}}
1635444242.3855722: {"type":"channel_data","connection_id":"60a4fc71-1312-4830-86f4-9eb98be106ac","message_id":1781,"id":"SUSHI-USD","channel":"v3_orderbook","contents":{"offset":"2693993361","bids":[["10.789","5211.5"]],"asks":[]}}
1635444242.388392: {"type":"channel_data","connection_id":"60a4fc71-1312-4830-86f4-9eb98be106ac","message_id":1782,"id":"SUSHI-USD","channel":"v3_orderbook","contents":{"offset":"2693993368","bids":[],"asks":[["10.798","8452.7"]]}}
1635444242.409199: {"type":"channel_data","connection_id":"60a4fc71-1312-4830-86f4-9eb98be106ac","message_id":1783,"id":"SUSHI-USD","channel":"v3_orderbook","contents":{"offset":"2693993383","bids":[],"asks":[["10.865","0"],["10.866","1372.2"]]}}
1635444242.420635: {"type":"channel_data","connection_id":"60a4fc71-1312-4830-86f4-9eb98be106ac","message_id":1784,"id":"MKR-USD","channel":"v3_orderbook","contents":{"offset":"2693993390","bids":[["2377","52.707"]],"asks":[]}}
1635444242.420699: {"type":"channel_data","connection_id":"60a4fc71-1312-4830-86f4-9eb98be106ac","message_id":1785,"id":"BCH-USD","channel":"v3_orderbook","contents":{"offset":"2693993400","bids":[["574.6","71.81"]],"asks":[]}}
1635444242.4207292: {"type":"channel_data","connection_id":"60a4fc71-1312-4830-86f4-9eb98be106ac","message_id":1786,"id":"SUSHI-USD","channel":"v3_orderbook","contents":{"offset":"2693993396","bids":[],"asks":[["10.801","0"]]}}
1635444242.441283: {"type":"channel_data","connection_id":"60a4fc71-1312-4830-86f4-9eb98be106ac","message_id":1787,"id":"SUSHI-USD","channel":"v3_orderbook","contents":{"offset":"2693993417","bids":[["10.792","334.7"]],"asks":[]}}
1635444242.450907: {"type":"channel_data","connection_id":"60a4fc71-1312-4830-86f4-9eb98be106ac","message_id":1788,"id":"ETH-USD","channel":"v3_orderbook","contents":{"offset":"2693993430","bids":[],"asks":[["4218.8","0"]]}}
1635444242.453534: {"type":"channel_data","connection_id":"60a4fc71-1312-4830-86f4-9eb98be106ac","message_id":1789,"id":"SUSHI-USD","channel":"v3_orderbook","contents":{"offset":"2693993432","bids":[],"asks":[["10.804","13702.8"]]}}
1635444242.460144: {"type":"channel_data","connection_id":"60a4fc71-1312-4830-86f4-9eb98be106ac","message_id":1790,"id":"UMA-USD","channel":"v3_orderbook","contents":{"offset":"2693993439","bids":[],"asks":[["11.3","0"]]}}
1635444242.4602098: {"type":"channel_data","connection_id":"60a4fc71-1312-4830-86f4-9eb98be106ac","message_id":1791,"id":"SUSHI-USD","channel":"v3_orderbook","contents":{"offset":"2693993435","bids":[],"asks":[["10.817","0"]]}}
1635444242.470614: {"type":"channel_data","connection_id":"60a4fc71-1312-4830-86f4-9eb98be106ac","message_id":1792,"id":"SUSHI-USD","channel":"v3_orderbook","contents":{"offset":"2693993447","bids":[["10.788","4635.1"]],"asks":[]}}
1635444242.471589: {"type":"channel_data","connection_id":"60a4fc71-1312-4830-86f4-9eb98be106ac","message_id":1793,"id":"ETH-USD","channel":"v3_orderbook","contents":{"offset":"2693993450","bids":[["4213.3","0"]],"asks":[]}}
1635444242.472519: {"type":"channel_data","connection_id":"60a4fc71-1312-4830-86f4-9eb98be106ac","message_id":1794,"id":"SUSHI-USD","channel":"v3_orderbook","contents":{"offset":"2693993444","bids":[],"asks":[["10.802","5029.3"]]}}
1635444242.4761229: {"type":"channel_data","connection_id":"60a4fc71-1312-4830-86f4-9eb98be106ac","message_id":1795,"id":"UMA-USD","channel":"v3_orderbook","contents":{"offset":"2693993451","bids":[["11.27","29527"]],"asks":[]}}
1635444242.482487: {"type":"channel_data","connection_id":"60a4fc71-1312-4830-86f4-9eb98be106ac","message_id":1796,"id":"SUSHI-USD","channel":"v3_orderbook","contents":{"offset":"2693993454","bids":[],"asks":[["10.808","0"]]}}
1635444242.483747: {"type":"channel_data","connection_id":"60a4fc71-1312-4830-86f4-9eb98be106ac","message_id":1797,"id":"SUSHI-USD","channel":"v3_orderbook","contents":{"offset":"2693993461","bids":[],"asks":[["10.804","13600.8"]]}}
1635444242.484013: {"type":"channel_data","connection_id":"60a4fc71-1312-4830-86f4-9eb98be106ac","message_id":1798,"id":"SUSHI-USD","channel":"v3_orderbook","contents":{"offset":"2693993459","bids":[["10.736","3247.6"],["10.735","0"]],"asks":[]}}
1635444242.487829: {"type":"channel_data","connection_id":"60a4fc71-1312-4830-86f4-9eb98be106ac","message_id":1799,"id":"SUSHI-USD","channel":"v3_orderbook","contents":{"offset":"2693993466","bids":[],"asks":[["10.813","10333"]]}}
1635444242.487894: {"type":"channel_data","connection_id":"60a4fc71-1312-4830-86f4-9eb98be106ac","message_id":1800,"id":"SUSHI-USD","channel":"v3_orderbook","contents":{"offset":"2693993464","bids":[["10.79","3706.8"]],"asks":[]}}
1635444242.489505: {"type":"channel_data","connection_id":"60a4fc71-1312-4830-86f4-9eb98be106ac","message_id":1801,"id":"SUSHI-USD","channel":"v3_orderbook","contents":{"offset":"2693993467","bids":[["10.725","3247.6"],["10.724","0"]],"asks":[]}}
1635444242.4957418: {"type":"channel_data","connection_id":"60a4fc71-1312-4830-86f4-9eb98be106ac","message_id":1802,"id":"SUSHI-USD","channel":"v3_orderbook","contents":{"offset":"2693993472","bids":[["10.761","0"]],"asks":[]}}
1635444242.4958029: {"type":"channel_data","connection_id":"60a4fc71-1312-4830-86f4-9eb98be106ac","message_id":1803,"id":"SUSHI-USD","channel":"v3_orderbook","contents":{"offset":"2693993477","bids":[["10.755","0"]],"asks":[]}}
1635444242.498699: {"type":"channel_data","connection_id":"60a4fc71-1312-4830-86f4-9eb98be106ac","message_id":1804,"id":"UMA-USD","channel":"v3_orderbook","contents":{"offset":"2693993478","bids":[["11.27","29261.6"]],"asks":[]}}
1635444242.505743: {"type":"channel_data","connection_id":"60a4fc71-1312-4830-86f4-9eb98be106ac","message_id":1805,"id":"ETH-USD","channel":"v3_orderbook","contents":{"offset":"2693993486","bids":[],"asks":[["4216.9","56.342"]]}}
1635444242.512408: {"type":"channel_data","connection_id":"60a4fc71-1312-4830-86f4-9eb98be106ac","message_id":1806,"id":"SUSHI-USD","channel":"v3_orderbook","contents":{"offset":"2693993492","bids":[],"asks":[["10.816","1358.4"]]}}
1635444242.51751: {"type":"channel_data","connection_id":"60a4fc71-1312-4830-86f4-9eb98be106ac","message_id":1807,"id":"SUSHI-USD","channel":"v3_orderbook","contents":{"offset":"2693993506","bids":[["10.789","9661.2"]],"asks":[]}}
1635444242.5298219: {"type":"channel_data","connection_id":"60a4fc71-1312-4830-86f4-9eb98be106ac","message_id":1808,"id":"ETH-USD","channel":"v3_orderbook","contents":{"offset":"2693993517","bids":[["4202.2","0"]],"asks":[]}}
1635444242.5401359: {"type":"channel_data","connection_id":"60a4fc71-1312-4830-86f4-9eb98be106ac","message_id":1809,"id":"SUSHI-USD","channel":"v3_orderbook","contents":{"offset":"2693993523","bids":[],"asks":[["10.826","445585.7"]]}}
1635444242.5402: {"type":"channel_data","connection_id":"60a4fc71-1312-4830-86f4-9eb98be106ac","message_id":1810,"id":"CRV-USD","channel":"v3_orderbook","contents":{"offset":"2693993521","bids":[],"asks":[["4.854","246"]]}}
1635444242.543683: {"type":"channel_data","connection_id":"60a4fc71-1312-4830-86f4-9eb98be106ac","message_id":1811,"id":"ETH-USD","channel":"v3_orderbook","contents":{"offset":"2693993524","bids":[["4215.6","0"]],"asks":[]}}
1635444242.5625432: {"type":"channel_data","connection_id":"60a4fc71-1312-4830-86f4-9eb98be106ac","message_id":1812,"id":"SUSHI-USD","channel":"v3_orderbook","contents":{"offset":"2693993540","bids":[],"asks":[["10.814","101.9"]]}}
1635444242.56822: {"type":"channel_data","connection_id":"60a4fc71-1312-4830-86f4-9eb98be106ac","message_id":1813,"id":"SUSHI-USD","channel":"v3_orderbook","contents":{"offset":"2693993552","bids":[],"asks":[["10.819","116.9"]]}}
1635444242.571285: {"type":"channel_data","connection_id":"60a4fc71-1312-4830-86f4-9eb98be106ac","message_id":1814,"id":"SUSHI-USD","channel":"v3_orderbook","contents":{"offset":"2693993547","bids":[["10.766","101.9"]],"asks":[]}}
1635444242.575787: {"type":"channel_data","connection_id":"60a4fc71-1312-4830-86f4-9eb98be106ac","message_id":1815,"id":"UMA-USD","channel":"v3_orderbook","contents":{"offset":"2693993554","bids":[],"asks":[["11.33","29390.6"],["11.35","1779.7"]]}}
1635444242.575849: {"type":"channel_data","connection_id":"60a4fc71-1312-4830-86f4-9eb98be106ac","message_id":1816,"id":"SUSHI-USD","channel":"v3_orderbook","contents":{"offset":"2693993556","bids":[["10.771","794.1"]],"asks":[]}}
1635444242.586545: {"type":"channel_data","connection_id":"60a4fc71-1312-4830-86f4-9eb98be106ac","message_id":1817,"id":"MKR-USD","channel":"v3_orderbook","contents":{"offset":"2693993563","bids":[["2281","1.619"]],"asks":[]}}
1635444242.5996008: {"type":"channel_data","connection_id":"60a4fc71-1312-4830-86f4-9eb98be106ac","message_id":1818,"id":"ETH-USD","channel":"v3_orderbook","contents":{"offset":"2693993571","bids":[["4213.8","26.221"]],"asks":[]}}
1635444242.608486: {"type":"channel_data","connection_id":"60a4fc71-1312-4830-86f4-9eb98be106ac","message_id":1819,"id":"BCH-USD","channel":"v3_orderbook","contents":{"offset":"2693993580","bids":[["574.5","545.24"]],"asks":[]}}
1635444242.608545: {"type":"channel_data","connection_id":"60a4fc71-1312-4830-86f4-9eb98be106ac","message_id":1820,"id":"SUSHI-USD","channel":"v3_orderbook","contents":{"offset":"2693993578","bids":[["10.779","9315.6"]],"asks":[]}}
1635444242.60857: {"type":"channel_data","connection_id":"60a4fc71-1312-4830-86f4-9eb98be106ac","message_id":1821,"id":"SUSHI-USD","channel":"v3_orderbook","contents":{"offset":"2693993579","bids":[],"asks":[["10.802","8732.4"]]}}
1635444242.685399: {"type":"channel_data","connection_id":"60a4fc71-1312-4830-86f4-9eb98be106ac","message_id":1822,"id":"BCH-USD","channel":"v3_orderbook","contents":{"offset":"2693993601","bids":[],"asks":[["576.8","2.08"]]}}
1635444242.685492: {"type":"channel_data","connection_id":"60a4fc71-1312-4830-86f4-9eb98be106ac","message_id":1823,"id":"SUSHI-USD","channel":"v3_orderbook","contents":{"offset":"2693993602","bids":[],"asks":[["10.798","4002.3"]]}}
1635444242.685534: {"type":"channel_data","connection_id":"60a4fc71-1312-4830-86f4-9eb98be106ac","message_id":1824,"id":"UMA-USD","channel":"v3_orderbook","contents":{"offset":"2693993600","bids":[],"asks":[["11.34","529.9"]]}}
1635444242.685565: {"type":"channel_data","connection_id":"60a4fc71-1312-4830-86f4-9eb98be106ac","message_id":1825,"id":"BCH-USD","channel":"v3_orderbook","contents":{"offset":"2693993595","bids":[["554.6","0"]],"asks":[]}}
1635444242.6855931: {"type":"channel_data","connection_id":"60a4fc71-1312-4830-86f4-9eb98be106ac","message_id":1826,"id":"BCH-USD","channel":"v3_orderbook","contents":{"offset":"2693993607","bids":[["572.7","0"]],"asks":[]}}
1635444242.68562: {"type":"channel_data","connection_id":"60a4fc71-1312-4830-86f4-9eb98be106ac","message_id":1827,"id":"SUSHI-USD","channel":"v3_orderbook","contents":{"offset":"2693993610","bids":[["10.784","4002.3"]],"asks":[]}}
1635444242.685645: {"type":"channel_data","connection_id":"60a4fc71-1312-4830-86f4-9eb98be106ac","message_id":1828,"id":"CRV-USD","channel":"v3_orderbook","contents":{"offset":"2693993606","bids":[["4.835","5533"]],"asks":[]}}
1635444242.68567: {"type":"channel_data","connection_id":"60a4fc71-1312-4830-86f4-9eb98be106ac","message_id":1829,"id":"ETH-USD","channel":"v3_orderbook","contents":{"offset":"2693993617","bids":[],"asks":[["4218.3","57.052"]]}}
1635444242.685697: {"type":"channel_data","connection_id":"60a4fc71-1312-4830-86f4-9eb98be106ac","message_id":1830,"id":"BCH-USD","channel":"v3_orderbook","contents":{"offset":"2693993622","bids":[["574.5","539.63"]],"asks":[]}}
1635444242.6857212: {"type":"channel_data","connection_id":"60a4fc71-1312-4830-86f4-9eb98be106ac","message_id":1831,"id":"CRV-USD","channel":"v3_orderbook","contents":{"offset":"2693993629","bids":[["4.848","2243"]],"asks":[]}}
1635444242.685744: {"type":"channel_data","connection_id":"60a4fc71-1312-4830-86f4-9eb98be106ac","message_id":1832,"id":"ETH-USD","channel":"v3_orderbook","contents":{"offset":"2693993633","bids":[["4215.9","548.033"]],"asks":[]}}
1635444242.68577: {"type":"channel_data","connection_id":"60a4fc71-1312-4830-86f4-9eb98be106ac","message_id":1833,"id":"SUSHI-USD","channel":"v3_orderbook","contents":{"offset":"2693993638","bids":[],"asks":[["10.921","927.1"]]}}
1635444242.68618: {"type":"channel_data","connection_id":"60a4fc71-1312-4830-86f4-9eb98be106ac","message_id":1834,"id":"SUSHI-USD","channel":"v3_orderbook","contents":{"offset":"2693993644","bids":[],"asks":[["10.83","3534.5"]]}}
1635444242.687126: {"type":"channel_data","connection_id":"60a4fc71-1312-4830-86f4-9eb98be106ac","message_id":1835,"id":"SUSHI-USD","channel":"v3_orderbook","contents":{"offset":"2693993646","bids":[["10.72","5123"],["10.719","0"]],"asks":[]}}
1635444242.7169201: {"type":"channel_data","connection_id":"60a4fc71-1312-4830-86f4-9eb98be106ac","message_id":1836,"id":"SUSHI-USD","channel":"v3_orderbook","contents":{"offset":"2693993663","bids":[["10.789","8452"]],"asks":[]}}
1635444242.72438: {"type":"channel_data","connection_id":"60a4fc71-1312-4830-86f4-9eb98be106ac","message_id":1837,"id":"ETH-USD","channel":"v3_orderbook","contents":{"offset":"2693993667","bids":[],"asks":[["4239","21.5"],["4239.8","11.866"]]}}
1635444242.731822: {"type":"channel_data","connection_id":"60a4fc71-1312-4830-86f4-9eb98be106ac","message_id":1838,"id":"UMA-USD","channel":"v3_orderbook","contents":{"offset":"2693993674","bids":[["11.27","29527"]],"asks":[]}}
1635444242.74262: {"type":"channel_data","connection_id":"60a4fc71-1312-4830-86f4-9eb98be106ac","message_id":1839,"id":"SUSHI-USD","channel":"v3_orderbook","contents":{"offset":"2693993687","bids":[["10.792","1543.9"]],"asks":[]}}
1635444242.760829: {"type":"channel_data","connection_id":"60a4fc71-1312-4830-86f4-9eb98be106ac","message_id":1840,"id":"ETH-USD","channel":"v3_orderbook","contents":{"offset":"2693993692","bids":[],"asks":[["4218.8","20.384"]]}}
1635444242.767977: {"type":"channel_data","connection_id":"60a4fc71-1312-4830-86f4-9eb98be106ac","message_id":1841,"id":"UMA-USD","channel":"v3_orderbook","contents":{"offset":"2693993697","bids":[["11.27","29261.6"]],"asks":[]}}
1635444242.768098: {"type":"channel_data","connection_id":"60a4fc71-1312-4830-86f4-9eb98be106ac","message_id":1842,"id":"UNI-USD","channel":"v3_orderbook","contents":{"offset":"2693993695","bids":[["24.878","1997.7"],["24.877","0"]],"asks":[]}}
1635444242.773: {"type":"channel_data","connection_id":"60a4fc71-1312-4830-86f4-9eb98be106ac","message_id":1843,"id":"SUSHI-USD","channel":"v3_orderbook","contents":{"offset":"2693993701","bids":[["10.685","925.9"],["10.682","12467.4"]],"asks":[]}}
1635444242.7832582: {"type":"channel_data","connection_id":"60a4fc71-1312-4830-86f4-9eb98be106ac","message_id":1844,"id":"BCH-USD","channel":"v3_orderbook","contents":{"offset":"2693993707","bids":[["573.9","44.69"],["573.3","0"]],"asks":[]}}
1635444242.783349: {"type":"channel_data","connection_id":"60a4fc71-1312-4830-86f4-9eb98be106ac","message_id":1845,"id":"UNI-USD","channel":"v3_orderbook","contents":{"offset":"2693993713","bids":[["24.903","1997.7"],["24.902","0"]],"asks":[]}}
1635444242.789612: {"type":"channel_data","connection_id":"60a4fc71-1312-4830-86f4-9eb98be106ac","message_id":1846,"id":"ETH-USD","channel":"v3_orderbook","contents":{"offset":"2693993718","bids":[["4215.7","2.738"]],"asks":[]}}
1635444242.798691: {"type":"channel_data","connection_id":"60a4fc71-1312-4830-86f4-9eb98be106ac","message_id":1847,"id":"SUSHI-USD","channel":"v3_orderbook","contents":{"offset":"2693993725","bids":[],"asks":[["10.801","4417.9"]]}}
1635444242.8134248: {"type":"channel_data","connection_id":"60a4fc71-1312-4830-86f4-9eb98be106ac","message_id":1848,"id":"MKR-USD","channel":"v3_orderbook","contents":{"offset":"2693993732","bids":[["2280","2.321"]],"asks":[]}}
1635444242.8135092: {"type":"channel_data","connection_id":"60a4fc71-1312-4830-86f4-9eb98be106ac","message_id":1849,"id":"BCH-USD","channel":"v3_orderbook","contents":{"offset":"2693993726","bids":[],"asks":[["594.9","0"]]}}
1635444242.823044: {"type":"channel_data","connection_id":"60a4fc71-1312-4830-86f4-9eb98be106ac","message_id":1850,"id":"ETH-USD","channel":"v3_orderbook","contents":{"offset":"2693993740","bids":[["4213.8","7.215"]],"asks":[]}}
1635444242.855571: {"type":"channel_data","connection_id":"60a4fc71-1312-4830-86f4-9eb98be106ac","message_id":1851,"id":"CRV-USD","channel":"v3_orderbook","contents":{"offset":"2693993765","bids":[["4.815","0"]],"asks":[]}}
1635444242.855655: {"type":"channel_data","connection_id":"60a4fc71-1312-4830-86f4-9eb98be106ac","message_id":1852,"id":"CRV-USD","channel":"v3_orderbook","contents":{"offset":"2693993762","bids":[["4.838","5586"]],"asks":[]}}
1635444242.896207: {"type":"channel_data","connection_id":"60a4fc71-1312-4830-86f4-9eb98be106ac","message_id":1853,"id":"MKR-USD","channel":"v3_orderbook","contents":{"offset":"2693993791","bids":[["2377","10.632"]],"asks":[]}}
1635444242.908885: {"type":"channel_data","connection_id":"60a4fc71-1312-4830-86f4-9eb98be106ac","message_id":1854,"id":"ETH-USD","channel":"v3_orderbook","contents":{"offset":"2693993800","bids":[["4213.3","22.124"]],"asks":[]}}
1635444242.933743: {"type":"channel_data","connection_id":"60a4fc71-1312-4830-86f4-9eb98be106ac","message_id":1855,"id":"BCH-USD","channel":"v3_orderbook","contents":{"offset":"2693993825","bids":[["572.7","21"]],"asks":[]}}
1635444242.97304: {"type":"channel_data","connection_id":"60a4fc71-1312-4830-86f4-9eb98be106ac","message_id":1856,"id":"ETH-USD","channel":"v3_orderbook","contents":{"offset":"2693993857","bids":[["4213.3","0"]],"asks":[]}}
1635444242.983053: {"type":"channel_data","connection_id":"60a4fc71-1312-4830-86f4-9eb98be106ac","message_id":1857,"id":"BCH-USD","channel":"v3_orderbook","contents":{"offset":"2693993868","bids":[["574.5","545.24"]],"asks":[]}}
1635444242.9944088: {"type":"channel_data","connection_id":"60a4fc71-1312-4830-86f4-9eb98be106ac","message_id":1858,"id":"BCH-USD","channel":"v3_orderbook","contents":{"offset":"2693993884","bids":[],"asks":[["576.8","23.08"]]}}
1635444242.9944901: {"type":"channel_data","connection_id":"60a4fc71-1312-4830-86f4-9eb98be106ac","message_id":1859,"id":"ETH-USD","channel":"v3_orderbook","contents":{"offset":"2693993885","bids":[],"asks":[["4223.4","0"]]}}
1635444243.0288918: {"type":"channel_data","connection_id":"60a4fc71-1312-4830-86f4-9eb98be106ac","message_id":1860,"id":"EOS-USD","channel":"v3_orderbook","contents":{"offset":"2693993908","bids":[["4.398","5728"]],"asks":[]}}
1635444243.028967: {"type":"channel_data","connection_id":"60a4fc71-1312-4830-86f4-9eb98be106ac","message_id":1861,"id":"SUSHI-USD","channel":"v3_orderbook","contents":{"offset":"2693993914","bids":[],"asks":[["10.81","295.2"]]}}
1635444243.039592: {"type":"channel_data","connection_id":"60a4fc71-1312-4830-86f4-9eb98be106ac","message_id":1862,"id":"ETH-USD","channel":"v3_orderbook","contents":{"offset":"2693993919","bids":[["4213.7","1917.004"]],"asks":[]}}
1635444243.039658: {"type":"channel_data","connection_id":"60a4fc71-1312-4830-86f4-9eb98be106ac","message_id":1863,"id":"MKR-USD","channel":"v3_orderbook","contents":{"offset":"2693993923","bids":[["2279","2.825"]],"asks":[]}}
1635444243.051384: {"type":"channel_data","connection_id":"60a4fc71-1312-4830-86f4-9eb98be106ac","message_id":1864,"id":"EOS-USD","channel":"v3_orderbook","contents":{"offset":"2693993929","bids":[],"asks":[["4.419","0"],["4.42","7957"]]}}
1635444243.0635352: {"type":"channel_data","connection_id":"60a4fc71-1312-4830-86f4-9eb98be106ac","message_id":1865,"id":"CRV-USD","channel":"v3_orderbook","contents":{"offset":"2693993932","bids":[["4.848","2768"]],"asks":[]}}
1635444243.063596: {"type":"channel_data","connection_id":"60a4fc71-1312-4830-86f4-9eb98be106ac","message_id":1866,"id":"CRV-USD","channel":"v3_orderbook","contents":{"offset":"2693993937","bids":[["4.841","6035"]],"asks":[]}}
1635444243.067491: {"type":"channel_data","connection_id":"60a4fc71-1312-4830-86f4-9eb98be106ac","message_id":1867,"id":"SUSHI-USD","channel":"v3_orderbook","contents":{"offset":"2693993936","bids":[["10.791","266.5"]],"asks":[]}}
1635444243.067553: {"type":"channel_data","connection_id":"60a4fc71-1312-4830-86f4-9eb98be106ac","message_id":1868,"id":"SUSHI-USD","channel":"v3_orderbook","contents":{"offset":"2693993931","bids":[],"asks":[["10.81","600.5"]]}}
1635444243.067589: {"type":"channel_data","connection_id":"60a4fc71-1312-4830-86f4-9eb98be106ac","message_id":1869,"id":"UNI-USD","channel":"v3_orderbook","contents":{"offset":"2693993940","bids":[],"asks":[["25.204","0"],["25.205","998.8"]]}}
1635444243.087872: {"type":"channel_data","connection_id":"60a4fc71-1312-4830-86f4-9eb98be106ac","message_id":1870,"id":"ETH-USD","channel":"v3_orderbook","contents":{"offset":"2693993950","bids":[["4213.7","1898.587"]],"asks":[]}}
1635444243.098667: {"type":"channel_data","connection_id":"60a4fc71-1312-4830-86f4-9eb98be106ac","message_id":1871,"id":"SUSHI-USD","channel":"v3_orderbook","contents":{"offset":"2693993955","bids":[["10.789","8747.8"]],"asks":[]}}
1635444243.1210501: {"type":"channel_data","connection_id":"60a4fc71-1312-4830-86f4-9eb98be106ac","message_id":1872,"id":"BCH-USD","channel":"v3_orderbook","contents":{"offset":"2693993979","bids":[["574.5","539.63"]],"asks":[]}}
1635444243.134801: {"type":"channel_data","connection_id":"60a4fc71-1312-4830-86f4-9eb98be106ac","message_id":1873,"id":"CRV-USD","channel":"v3_orderbook","contents":{"offset":"2693993996","bids":[["4.844","744"]],"asks":[]}}
1635444243.1348622: {"type":"channel_data","connection_id":"60a4fc71-1312-4830-86f4-9eb98be106ac","message_id":1874,"id":"CRV-USD","channel":"v3_orderbook","contents":{"offset":"2693993994","bids":[["4.852","11749"]],"asks":[]}}
1635444243.1457222: {"type":"channel_data","connection_id":"60a4fc71-1312-4830-86f4-9eb98be106ac","message_id":1875,"id":"EOS-USD","channel":"v3_orderbook","contents":{"offset":"2693993998","bids":[["4.399","12473"]],"asks":[]}}
1635444243.150848: {"type":"channel_data","connection_id":"60a4fc71-1312-4830-86f4-9eb98be106ac","message_id":1876,"id":"CRV-USD","channel":"v3_orderbook","contents":{"offset":"2693994010","bids":[["4.847","23326"]],"asks":[]}}
1635444243.177142: {"type":"channel_data","connection_id":"60a4fc71-1312-4830-86f4-9eb98be106ac","message_id":1877,"id":"ETH-USD","channel":"v3_orderbook","contents":{"offset":"2693994032","bids":[["4213.3","21.171"]],"asks":[]}}
1635444243.2994602: {"type":"channel_data","connection_id":"60a4fc71-1312-4830-86f4-9eb98be106ac","message_id":1878,"id":"MKR-USD","channel":"v3_orderbook","contents":{"offset":"2693994039","bids":[["2381","27.054"]],"asks":[]}}
1635444243.302274: {"type":"channel_data","connection_id":"60a4fc71-1312-4830-86f4-9eb98be106ac","message_id":1879,"id":"ETH-USD","channel":"v3_orderbook","contents":{"offset":"2693994041","bids":[],"asks":[["4239","33.366"],["4239.8","0"]]}}
1635444243.324887: {"type":"channel_data","connection_id":"60a4fc71-1312-4830-86f4-9eb98be106ac","message_id":1880,"id":"SUSHI-USD","channel":"v3_orderbook","contents":{"offset":"2693994057","bids":[],"asks":[["10.808","386.6"]]}}
1635444243.32557: {"type":"channel_data","connection_id":"60a4fc71-1312-4830-86f4-9eb98be106ac","message_id":1881,"id":"BCH-USD","channel":"v3_orderbook","contents":{"offset":"2693994061","bids":[["554.6","20"]],"asks":[]}}
1635444243.3303099: {"type":"channel_data","connection_id":"60a4fc71-1312-4830-86f4-9eb98be106ac","message_id":1882,"id":"EOS-USD","channel":"v3_orderbook","contents":{"offset":"2693994066","bids":[],"asks":[["4.414","3418"]]}}
1635444243.332335: {"type":"channel_data","connection_id":"60a4fc71-1312-4830-86f4-9eb98be106ac","message_id":1883,"id":"EOS-USD","channel":"v3_orderbook","contents":{"offset":"2693994069","bids":[],"asks":[["4.552","0"]]}}
1635444243.334472: {"type":"channel_data","connection_id":"60a4fc71-1312-4830-86f4-9eb98be106ac","message_id":1884,"id":"SUSHI-USD","channel":"v3_orderbook","contents":{"offset":"2693994073","bids":[],"asks":[["10.806","4116.4"]]}}
1635444243.3351061: {"type":"channel_data","connection_id":"60a4fc71-1312-4830-86f4-9eb98be106ac","message_id":1885,"id":"EOS-USD","channel":"v3_orderbook","contents":{"offset":"2693994074","bids":[["4.383","8804"]],"asks":[]}}
1635444243.33516: {"type":"channel_data","connection_id":"60a4fc71-1312-4830-86f4-9eb98be106ac","message_id":1886,"id":"SUSHI-USD","channel":"v3_orderbook","contents":{"offset":"2693994070","bids":[],"asks":[["10.898","525.6"]]}}
1635444243.339345: {"type":"channel_data","connection_id":"60a4fc71-1312-4830-86f4-9eb98be106ac","message_id":1887,"id":"ETH-USD","channel":"v3_orderbook","contents":{"offset":"2693994081","bids":[["4213.3","0"]],"asks":[]}}
1635444243.355136: {"type":"channel_data","connection_id":"60a4fc71-1312-4830-86f4-9eb98be106ac","message_id":1888,"id":"ETH-USD","channel":"v3_orderbook","contents":{"offset":"2693994079","bids":[],"asks":[["4219.3","1.798"]]}}
1635444243.355756: {"type":"channel_data","connection_id":"60a4fc71-1312-4830-86f4-9eb98be106ac","message_id":1889,"id":"MKR-USD","channel":"v3_orderbook","contents":{"offset":"2693994090","bids":[["2376","2138.115"]],"asks":[]}}
1635444243.355793: {"type":"channel_data","connection_id":"60a4fc71-1312-4830-86f4-9eb98be106ac","message_id":1890,"id":"ETH-USD","channel":"v3_orderbook","contents":{"offset":"2693994091","bids":[["4215.9","553.966"]],"asks":[]}}
1635444243.3573592: {"type":"channel_data","connection_id":"60a4fc71-1312-4830-86f4-9eb98be106ac","message_id":1891,"id":"UMA-USD","channel":"v3_orderbook","contents":{"offset":"2693994087","bids":[],"asks":[["11.33","29481.1"]]}}
1635444243.362514: {"type":"channel_data","connection_id":"60a4fc71-1312-4830-86f4-9eb98be106ac","message_id":1892,"id":"BCH-USD","channel":"v3_orderbook","contents":{"offset":"2693994103","bids":[],"asks":[["594.9","20"]]}}
1635444243.368762: {"type":"channel_data","connection_id":"60a4fc71-1312-4830-86f4-9eb98be106ac","message_id":1893,"id":"ETH-USD","channel":"v3_orderbook","contents":{"offset":"2693994117","bids":[],"asks":[["4219.2","11.304"]]}}
1635444243.368803: {"type":"channel_data","connection_id":"60a4fc71-1312-4830-86f4-9eb98be106ac","message_id":1894,"id":"UNI-USD","channel":"v3_orderbook","contents":{"offset":"2693994111","bids":[],"asks":[["25.192","0"],["25.193","1997.7"]]}}
1635444243.372083: {"type":"channel_data","connection_id":"60a4fc71-1312-4830-86f4-9eb98be106ac","message_id":1895,"id":"ETH-USD","channel":"v3_orderbook","contents":{"offset":"2693994124","bids":[],"asks":[["4219.1","4461.679"]]}}
1635444243.37685: {"type":"channel_data","connection_id":"60a4fc71-1312-4830-86f4-9eb98be106ac","message_id":1896,"id":"CRV-USD","channel":"v3_orderbook","contents":{"offset":"2693994119","bids":[["4.848","1737"]],"asks":[]}}
1635444243.3768861: {"type":"channel_data","connection_id":"60a4fc71-1312-4830-86f4-9eb98be106ac","message_id":1897,"id":"UNI-USD","channel":"v3_orderbook","contents":{"offset":"2693994122","bids":[["25.036","0"]],"asks":[]}}
1635444243.37691: {"type":"channel_data","connection_id":"60a4fc71-1312-4830-86f4-9eb98be106ac","message_id":1898,"id":"CRV-USD","channel":"v3_orderbook","contents":{"offset":"2693994118","bids":[["4.846","1145"]],"asks":[]}}
1635444243.379798: {"type":"channel_data","connection_id":"60a4fc71-1312-4830-86f4-9eb98be106ac","message_id":1899,"id":"CRV-USD","channel":"v3_orderbook","contents":{"offset":"2693994123","bids":[],"asks":[["4.859","5484"]]}}
1635444243.379833: {"type":"channel_data","connection_id":"60a4fc71-1312-4830-86f4-9eb98be106ac","message_id":1900,"id":"CRV-USD","channel":"v3_orderbook","contents":{"offset":"2693994129","bids":[],"asks":[["4.857","227"]]}}
1635444243.380807: {"type":"channel_data","connection_id":"60a4fc71-1312-4830-86f4-9eb98be106ac","message_id":1901,"id":"ETH-USD","channel":"v3_orderbook","contents":{"offset":"2693994127","bids":[],"asks":[["4216.4","0"]]}}
1635444243.382824: {"type":"channel_data","connection_id":"60a4fc71-1312-4830-86f4-9eb98be106ac","message_id":1902,"id":"UNI-USD","channel":"v3_orderbook","contents":{"offset":"2693994133","bids":[["25.03","2991.6"]],"asks":[]}}
1635444243.3838358: {"type":"channel_data","connection_id":"60a4fc71-1312-4830-86f4-9eb98be106ac","message_id":1903,"id":"UNI-USD","channel":"v3_orderbook","contents":{"offset":"2693994130","bids":[],"asks":[["25.073","0"]]}}
1635444243.390007: {"type":"channel_data","connection_id":"60a4fc71-1312-4830-86f4-9eb98be106ac","message_id":1904,"id":"ETH-USD","channel":"v3_orderbook","contents":{"offset":"2693994128","bids":[["4215.5","86.831"]],"asks":[]}}
1635444243.390039: {"type":"channel_data","connection_id":"60a4fc71-1312-4830-86f4-9eb98be106ac","message_id":1905,"id":"UNI-USD","channel":"v3_orderbook","contents":{"offset":"2693994131","bids":[],"asks":[["25.079","0"]]}}
1635444243.391932: {"type":"channel_data","connection_id":"60a4fc71-1312-4830-86f4-9eb98be106ac","message_id":1906,"id":"CRV-USD","channel":"v3_orderbook","contents":{"offset":"2693994134","bids":[],"asks":[["4.854","1246"]]}}
1635444243.395464: {"type":"channel_data","connection_id":"60a4fc71-1312-4830-86f4-9eb98be106ac","message_id":1907,"id":"ETH-USD","channel":"v3_orderbook","contents":{"offset":"2693994136","bids":[["4213.7","1916.8"]],"asks":[]}}
1635444243.3978539: {"type":"channel_data","connection_id":"60a4fc71-1312-4830-86f4-9eb98be106ac","message_id":1908,"id":"ETH-USD","channel":"v3_orderbook","contents":{"offset":"2693994149","bids":[],"asks":[["4219.2","1.304"]]}}
1635444243.400057: {"type":"channel_data","connection_id":"60a4fc71-1312-4830-86f4-9eb98be106ac","message_id":1909,"id":"ETH-USD","channel":"v3_orderbook","contents":{"offset":"2693994146","bids":[["4215.5","69.031"]],"asks":[]}}
1635444243.407465: {"type":"channel_data","connection_id":"60a4fc71-1312-4830-86f4-9eb98be106ac","message_id":1910,"id":"UNI-USD","channel":"v3_orderbook","contents":{"offset":"2693994161","bids":[],"asks":[["25.167","0"],["25.168","1067.1"]]}}
1635444243.4075022: {"type":"channel_data","connection_id":"60a4fc71-1312-4830-86f4-9eb98be106ac","message_id":1911,"id":"ETH-USD","channel":"v3_orderbook","contents":{"offset":"2693994165","bids":[],"asks":[["4217.4","0"]]}}
1635444243.407522: {"type":"channel_data","connection_id":"60a4fc71-1312-4830-86f4-9eb98be106ac","message_id":1912,"id":"BCH-USD","channel":"v3_orderbook","contents":{"offset":"2693994154","bids":[["574.5","545.24"]],"asks":[]}}
1635444243.40754: {"type":"channel_data","connection_id":"60a4fc71-1312-4830-86f4-9eb98be106ac","message_id":1913,"id":"ETH-USD","channel":"v3_orderbook","contents":{"offset":"2693994152","bids":[["4215.9","548.033"]],"asks":[]}}
1635444243.4143429: {"type":"channel_data","connection_id":"60a4fc71-1312-4830-86f4-9eb98be106ac","message_id":1914,"id":"ETH-USD","channel":"v3_orderbook","contents":{"offset":"2693994169","bids":[["4213.8","0"]],"asks":[]}}
1635444243.426643: {"type":"channel_data","connection_id":"60a4fc71-1312-4830-86f4-9eb98be106ac","message_id":1915,"id":"ETH-USD","channel":"v3_orderbook","contents":{"offset":"2693994173","bids":[["4214.1","7.215"]],"asks":[]}}
1635444243.4267058: {"type":"channel_data","connection_id":"60a4fc71-1312-4830-86f4-9eb98be106ac","message_id":1916,"id":"EOS-USD","channel":"v3_orderbook","contents":{"offset":"2693994168","bids":[["4.244","0"]],"asks":[]}}
1635444243.426732: {"type":"channel_data","connection_id":"60a4fc71-1312-4830-86f4-9eb98be106ac","message_id":1917,"id":"ETH-USD","channel":"v3_orderbook","contents":{"offset":"2693994178","bids":[],"asks":[["4217.7","28.404"]]}}
1635444243.426751: {"type":"channel_data","connection_id":"60a4fc71-1312-4830-86f4-9eb98be106ac","message_id":1918,"id":"SUSHI-USD","channel":"v3_orderbook","contents":{"offset":"2693994182","bids":[["10.786","4375.5"]],"asks":[]}}
1635444243.445112: {"type":"channel_data","connection_id":"60a4fc71-1312-4830-86f4-9eb98be106ac","message_id":1919,"id":"UNI-USD","channel":"v3_orderbook","contents":{"offset":"2693994195","bids":[],"asks":[["25.073","399.4"]]}}
1635444243.445239: {"type":"channel_data","connection_id":"60a4fc71-1312-4830-86f4-9eb98be106ac","message_id":1920,"id":"UNI-USD","channel":"v3_orderbook","contents":{"offset":"2693994201","bids":[["25.036","399.4"]],"asks":[]}}
1635444243.4591858: {"type":"channel_data","connection_id":"60a4fc71-1312-4830-86f4-9eb98be106ac","message_id":1921,"id":"CRV-USD","channel":"v3_orderbook","contents":{"offset":"2693994210","bids":[["4.852","12779"]],"asks":[]}}
1635444243.468538: {"type":"channel_data","connection_id":"60a4fc71-1312-4830-86f4-9eb98be106ac","message_id":1922,"id":"ETH-USD","channel":"v3_orderbook","contents":{"offset":"2693994214","bids":[["4214.1","0"]],"asks":[]}}
1635444243.4686341: {"type":"channel_data","connection_id":"60a4fc71-1312-4830-86f4-9eb98be106ac","message_id":1923,"id":"EOS-USD","channel":"v3_orderbook","contents":{"offset":"2693994218","bids":[],"asks":[["4.407","1553"]]}}
1635444243.4686751: {"type":"channel_data","connection_id":"60a4fc71-1312-4830-86f4-9eb98be106ac","message_id":1924,"id":"ETH-USD","channel":"v3_orderbook","contents":{"offset":"2693994219","bids":[["4214","999.354"]],"asks":[]}}
1635444243.474833: {"type":"channel_data","connection_id":"60a4fc71-1312-4830-86f4-9eb98be106ac","message_id":1925,"id":"ETH-USD","channel":"v3_orderbook","contents":{"offset":"2693994223","bids":[["4195.9","2.056"]],"asks":[]}}
1635444243.478225: {"type":"channel_data","connection_id":"60a4fc71-1312-4830-86f4-9eb98be106ac","message_id":1926,"id":"UNI-USD","channel":"v3_orderbook","contents":{"offset":"2693994224","bids":[],"asks":[["25.079","399.5"]]}}
1635444243.495251: {"type":"channel_data","connection_id":"60a4fc71-1312-4830-86f4-9eb98be106ac","message_id":1927,"id":"ETH-USD","channel":"v3_orderbook","contents":{"offset":"2693994231","bids":[],"asks":[["4217.7","18.62"]]}}
1635444243.497238: {"type":"channel_data","connection_id":"60a4fc71-1312-4830-86f4-9eb98be106ac","message_id":1928,"id":"UNI-USD","channel":"v3_orderbook","contents":{"offset":"2693994227","bids":[["25.03","3391.1"]],"asks":[]}}
1635444243.510331: {"type":"channel_data","connection_id":"60a4fc71-1312-4830-86f4-9eb98be106ac","message_id":1929,"id":"CRV-USD","channel":"v3_orderbook","contents":{"offset":"2693994234","bids":[["4.835","2727"]],"asks":[]}}
1635444243.517857: {"type":"channel_data","connection_id":"60a4fc71-1312-4830-86f4-9eb98be106ac","message_id":1930,"id":"ETH-USD","channel":"v3_orderbook","contents":{"offset":"2693994237","bids":[],"asks":[["4217.6","9.784"]]}}
1635444243.527931: {"type":"channel_data","connection_id":"60a4fc71-1312-4830-86f4-9eb98be106ac","message_id":1931,"id":"SUSHI-USD","channel":"v3_orderbook","contents":{"offset":"2693994244","bids":[["10.781","0"]],"asks":[]}}
1635444243.5369248: {"type":"channel_data","connection_id":"60a4fc71-1312-4830-86f4-9eb98be106ac","message_id":1932,"id":"ETH-USD","channel":"v3_orderbook","contents":{"offset":"2693994249","bids":[],"asks":[["4217.1","58.008"]]}}
1635444243.537517: {"type":"channel_data","connection_id":"60a4fc71-1312-4830-86f4-9eb98be106ac","message_id":1933,"id":"UMA-USD","channel":"v3_orderbook","contents":{"offset":"2693994248","bids":[["11.27","29527"]],"asks":[]}}
1635444243.540077: {"type":"channel_data","connection_id":"60a4fc71-1312-4830-86f4-9eb98be106ac","message_id":1934,"id":"UNI-USD","channel":"v3_orderbook","contents":{"offset":"2693994251","bids":[],"asks":[["25.205","0"],["25.206","998.8"]]}}
1635444243.561558: {"type":"channel_data","connection_id":"60a4fc71-1312-4830-86f4-9eb98be106ac","message_id":1935,"id":"UMA-USD","channel":"v3_orderbook","contents":{"offset":"2693994260","bids":[["11.27","29261.6"]],"asks":[]}}
1635444243.609545: {"type":"channel_data","connection_id":"60a4fc71-1312-4830-86f4-9eb98be106ac","message_id":1936,"id":"UMA-USD","channel":"v3_orderbook","contents":{"offset":"2693994294","bids":[["11.28","8640.3"]],"asks":[]}}
1635444243.609618: {"type":"channel_data","connection_id":"60a4fc71-1312-4830-86f4-9eb98be106ac","message_id":1937,"id":"CRV-USD","channel":"v3_orderbook","contents":{"offset":"2693994291","bids":[["4.848","2418"]],"asks":[]}}
1635444243.621551: {"type":"channel_data","connection_id":"60a4fc71-1312-4830-86f4-9eb98be106ac","message_id":1938,"id":"UMA-USD","channel":"v3_orderbook","contents":{"offset":"2693994296","bids":[["11.29","6673.2"]],"asks":[]}}
1635444243.63463: {"type":"channel_data","connection_id":"60a4fc71-1312-4830-86f4-9eb98be106ac","message_id":1939,"id":"UMA-USD","channel":"v3_orderbook","contents":{"offset":"2693994301","bids":[],"asks":[["11.32","14161.8"]]}}
1635444243.661382: {"type":"channel_data","connection_id":"60a4fc71-1312-4830-86f4-9eb98be106ac","message_id":1940,"id":"CRV-USD","channel":"v3_orderbook","contents":{"offset":"2693994318","bids":[["4.849","1031"]],"asks":[]}}
1635444243.706197: {"type":"channel_data","connection_id":"60a4fc71-1312-4830-86f4-9eb98be106ac","message_id":1941,"id":"SUSHI-USD","channel":"v3_orderbook","contents":{"offset":"2693994329","bids":[],"asks":[["10.853","0"]]}}
1635444243.706272: {"type":"channel_data","connection_id":"60a4fc71-1312-4830-86f4-9eb98be106ac","message_id":1942,"id":"EOS-USD","channel":"v3_orderbook","contents":{"offset":"2693994333","bids":[["4.385","16366"]],"asks":[]}}
1635444243.71727: {"type":"channel_data","connection_id":"60a4fc71-1312-4830-86f4-9eb98be106ac","message_id":1943,"id":"ETH-USD","channel":"v3_orderbook","contents":{"offset":"2693994340","bids":[["4209.9","0"]],"asks":[]}}
1635444243.752967: {"type":"channel_data","connection_id":"60a4fc71-1312-4830-86f4-9eb98be106ac","message_id":1944,"id":"CRV-USD","channel":"v3_orderbook","contents":{"offset":"2693994350","bids":[["4.838","6455"]],"asks":[]}}
1635444243.7616158: {"type":"channel_data","connection_id":"60a4fc71-1312-4830-86f4-9eb98be106ac","message_id":1945,"id":"EOS-USD","channel":"v3_orderbook","contents":{"offset":"2693994359","bids":[],"asks":[["4.416","12045"]]}}
1635444243.775716: {"type":"channel_data","connection_id":"60a4fc71-1312-4830-86f4-9eb98be106ac","message_id":1946,"id":"ETH-USD","channel":"v3_orderbook","contents":{"offset":"2693994358","bids":[],"asks":[["4239","21.5"],["4239.8","11.866"]]}}
1635444243.775789: {"type":"channel_data","connection_id":"60a4fc71-1312-4830-86f4-9eb98be106ac","message_id":1947,"id":"BCH-USD","channel":"v3_orderbook","contents":{"offset":"2693994361","bids":[["574.5","539.63"]],"asks":[]}}
1635444243.821449: {"type":"channel_data","connection_id":"60a4fc71-1312-4830-86f4-9eb98be106ac","message_id":1948,"id":"ETH-USD","channel":"v3_orderbook","contents":{"offset":"2693994375","bids":[],"asks":[["4217.4","2.922"]]}}
1635444243.8445172: {"type":"channel_data","connection_id":"60a4fc71-1312-4830-86f4-9eb98be106ac","message_id":1949,"id":"ETH-USD","channel":"v3_orderbook","contents":{"offset":"2693994388","bids":[],"asks":[["4217.1","0.03"]]}}
1635444243.877792: {"type":"channel_data","connection_id":"60a4fc71-1312-4830-86f4-9eb98be106ac","message_id":1950,"id":"CRV-USD","channel":"v3_orderbook","contents":{"offset":"2693994401","bids":[],"asks":[["4.86","7167"]]}}
1635444243.8942132: {"type":"channel_data","connection_id":"60a4fc71-1312-4830-86f4-9eb98be106ac","message_id":1951,"id":"ETH-USD","channel":"v3_orderbook","contents":{"offset":"2693994402","bids":[],"asks":[["4217.6","0"]]}}
1635444243.894283: {"type":"channel_data","connection_id":"60a4fc71-1312-4830-86f4-9eb98be106ac","message_id":1952,"id":"ETH-USD","channel":"v3_orderbook","contents":{"offset":"2693994406","bids":[["4214","992.139"]],"asks":[]}}
1635444243.8990579: {"type":"channel_data","connection_id":"60a4fc71-1312-4830-86f4-9eb98be106ac","message_id":1953,"id":"ETH-USD","channel":"v3_orderbook","contents":{"offset":"2693994413","bids":[["4213.9","64.325"]],"asks":[]}}
1635444243.912823: {"type":"channel_data","connection_id":"60a4fc71-1312-4830-86f4-9eb98be106ac","message_id":1954,"id":"ETH-USD","channel":"v3_orderbook","contents":{"offset":"2693994415","bids":[],"asks":[["4222.1","6.764"]]}}
1635444243.937292: {"type":"channel_data","connection_id":"60a4fc71-1312-4830-86f4-9eb98be106ac","message_id":1955,"id":"ETH-USD","channel":"v3_orderbook","contents":{"offset":"2693994416","bids":[],"asks":[["4217.5","10.659"]]}}
1635444243.948996: {"type":"channel_data","connection_id":"60a4fc71-1312-4830-86f4-9eb98be106ac","message_id":1956,"id":"UMA-USD","channel":"v3_orderbook","contents":{"offset":"2693994420","bids":[],"asks":[["11.35","1687.9"]]}}
1635444243.963525: {"type":"channel_data","connection_id":"60a4fc71-1312-4830-86f4-9eb98be106ac","message_id":1957,"id":"ETH-USD","channel":"v3_orderbook","contents":{"offset":"2693994424","bids":[],"asks":[["4229.8","2.236"]]}}
1635444243.976384: {"type":"channel_data","connection_id":"60a4fc71-1312-4830-86f4-9eb98be106ac","message_id":1958,"id":"EOS-USD","channel":"v3_orderbook","contents":{"offset":"2693994426","bids":[["4.246","3000"]],"asks":[]}}
1635444244.022906: {"type":"channel_data","connection_id":"60a4fc71-1312-4830-86f4-9eb98be106ac","message_id":1959,"id":"ETH-USD","channel":"v3_orderbook","contents":{"offset":"2693994444","bids":[],"asks":[["4217","128.472"]]}}
1635444244.045494: {"type":"channel_data","connection_id":"60a4fc71-1312-4830-86f4-9eb98be106ac","message_id":1960,"id":"ETH-USD","channel":"v3_orderbook","contents":{"offset":"2693994452","bids":[],"asks":[["4217.4","48.022"]]}}
1635444244.0564458: {"type":"channel_data","connection_id":"60a4fc71-1312-4830-86f4-9eb98be106ac","message_id":1961,"id":"EOS-USD","channel":"v3_orderbook","contents":{"offset":"2693994456","bids":[],"asks":[["4.555","3000"]]}}
1635444244.056512: {"type":"channel_data","connection_id":"60a4fc71-1312-4830-86f4-9eb98be106ac","message_id":1962,"id":"MKR-USD","channel":"v3_orderbook","contents":{"offset":"2693994458","bids":[],"asks":[["2383","17.488"]]}}
1635444244.0640068: {"type":"channel_data","connection_id":"60a4fc71-1312-4830-86f4-9eb98be106ac","message_id":1963,"id":"MKR-USD","channel":"v3_orderbook","contents":{"offset":"2693994460","bids":[["2380","13.704"]],"asks":[]}}
1635444244.0919309: {"type":"channel_data","connection_id":"60a4fc71-1312-4830-86f4-9eb98be106ac","message_id":1964,"id":"ETH-USD","channel":"v3_orderbook","contents":{"offset":"2693994471","bids":[],"asks":[["4220.1","94.411"]]}}
1635444244.096627: {"type":"channel_data","connection_id":"60a4fc71-1312-4830-86f4-9eb98be106ac","message_id":1965,"id":"EOS-USD","channel":"v3_orderbook","contents":{"offset":"2693994468","bids":[],"asks":[["4.416","16749"]]}}
1635444244.096683: {"type":"channel_data","connection_id":"60a4fc71-1312-4830-86f4-9eb98be106ac","message_id":1966,"id":"ETH-USD","channel":"v3_orderbook","contents":{"offset":"2693994472","bids":[],"asks":[["4216.5","0"]]}}
1635444244.096738: {"type":"channel_data","connection_id":"60a4fc71-1312-4830-86f4-9eb98be106ac","message_id":1967,"id":"CRV-USD","channel":"v3_orderbook","contents":{"offset":"2693994474","bids":[],"asks":[["4.863","16241"]]}}
1635444244.0967932: {"type":"channel_data","connection_id":"60a4fc71-1312-4830-86f4-9eb98be106ac","message_id":1968,"id":"ETH-USD","channel":"v3_orderbook","contents":{"offset":"2693994470","bids":[],"asks":[["4217.5","0.875"]]}}
1635444244.103306: {"type":"channel_data","connection_id":"60a4fc71-1312-4830-86f4-9eb98be106ac","message_id":1969,"id":"ETH-USD","channel":"v3_orderbook","contents":{"offset":"2693994479","bids":[["4213.9","57.11"]],"asks":[]}}
1635444244.105441: {"type":"channel_data","connection_id":"60a4fc71-1312-4830-86f4-9eb98be106ac","message_id":1970,"id":"ETH-USD","channel":"v3_orderbook","contents":{"offset":"2693994477","bids":[["4214","999.354"]],"asks":[]}}
1635444244.111834: {"type":"channel_data","connection_id":"60a4fc71-1312-4830-86f4-9eb98be106ac","message_id":1971,"id":"ETH-USD","channel":"v3_orderbook","contents":{"offset":"2693994481","bids":[],"asks":[["4217.6","9.784"]]}}
1635444244.146566: {"type":"channel_data","connection_id":"60a4fc71-1312-4830-86f4-9eb98be106ac","message_id":1972,"id":"ETH-USD","channel":"v3_orderbook","contents":{"offset":"2693994494","bids":[],"asks":[["4220","732.037"]]}}
1635444244.211731: {"type":"channel_data","connection_id":"60a4fc71-1312-4830-86f4-9eb98be106ac","message_id":1973,"id":"SUSHI-USD","channel":"v3_orderbook","contents":{"offset":"2693994516","bids":[],"asks":[["10.806","3743.9"]]}}
1635444244.323597: {"type":"channel_data","connection_id":"60a4fc71-1312-4830-86f4-9eb98be106ac","message_id":1974,"id":"ETH-USD","channel":"v3_orderbook","contents":{"offset":"2693994536","bids":[],"asks":[["4217","71.196"]]}}
1635444244.366563: {"type":"channel_data","connection_id":"60a4fc71-1312-4830-86f4-9eb98be106ac","message_id":1975,"id":"MKR-USD","channel":"v3_orderbook","contents":{"offset":"2693994545","bids":[["2376","2096.031"]],"asks":[]}}
1635444244.366648: {"type":"channel_data","connection_id":"60a4fc71-1312-4830-86f4-9eb98be106ac","message_id":1976,"id":"SUSHI-USD","channel":"v3_orderbook","contents":{"offset":"2693994546","bids":[["10.752","101.9"],["10.75","0"]],"asks":[]}}
1635444244.375595: {"type":"channel_data","connection_id":"60a4fc71-1312-4830-86f4-9eb98be106ac","message_id":1977,"id":"SUSHI-USD","channel":"v3_orderbook","contents":{"offset":"2693994548","bids":[],"asks":[["10.832","0"],["10.833","101.9"]]}}
1635444244.3761091: {"type":"channel_data","connection_id":"60a4fc71-1312-4830-86f4-9eb98be106ac","message_id":1978,"id":"ETH-USD","channel":"v3_orderbook","contents":{"offset":"2693994549","bids":[],"asks":[["4217.5","10.659"]]}}
1635444244.37617: {"type":"channel_data","connection_id":"60a4fc71-1312-4830-86f4-9eb98be106ac","message_id":1979,"id":"ETH-USD","channel":"v3_orderbook","contents":{"offset":"2693994550","bids":[],"asks":[["4217.6","0"]]}}
1635444244.390465: {"type":"channel_data","connection_id":"60a4fc71-1312-4830-86f4-9eb98be106ac","message_id":1980,"id":"ETH-USD","channel":"v3_orderbook","contents":{"offset":"2693994552","bids":[["4214","992.139"]],"asks":[]}}
1635444244.399189: {"type":"channel_data","connection_id":"60a4fc71-1312-4830-86f4-9eb98be106ac","message_id":1981,"id":"CRV-USD","channel":"v3_orderbook","contents":{"offset":"2693994554","bids":[["4.847","15313"]],"asks":[]}}
1635444244.4290931: {"type":"channel_data","connection_id":"60a4fc71-1312-4830-86f4-9eb98be106ac","message_id":1982,"id":"CRV-USD","channel":"v3_orderbook","contents":{"offset":"2693994556","bids":[["4.844","8757"]],"asks":[]}}
1635444244.4291651: {"type":"channel_data","connection_id":"60a4fc71-1312-4830-86f4-9eb98be106ac","message_id":1983,"id":"ETH-USD","channel":"v3_orderbook","contents":{"offset":"2693994561","bids":[],"asks":[["4217.5","0.875"]]}}
1635444244.4291961: {"type":"channel_data","connection_id":"60a4fc71-1312-4830-86f4-9eb98be106ac","message_id":1984,"id":"ETH-USD","channel":"v3_orderbook","contents":{"offset":"2693994562","bids":[],"asks":[["4217.6","9.784"]]}}
1635444244.4316642: {"type":"channel_data","connection_id":"60a4fc71-1312-4830-86f4-9eb98be106ac","message_id":1985,"id":"ETH-USD","channel":"v3_orderbook","contents":{"offset":"2693994564","bids":[["4213.9","64.325"]],"asks":[]}}
1635444244.437717: {"type":"channel_data","connection_id":"60a4fc71-1312-4830-86f4-9eb98be106ac","message_id":1986,"id":"SUSHI-USD","channel":"v3_orderbook","contents":{"offset":"2693994565","bids":[["10.771","2314.1"],["10.765","291.6"]],"asks":[]}}
1635444244.451113: {"type":"channel_data","connection_id":"60a4fc71-1312-4830-86f4-9eb98be106ac","message_id":1987,"id":"ETH-USD","channel":"v3_orderbook","contents":{"offset":"2693994566","bids":[["4214","999.354"]],"asks":[]}}
1635444244.4511821: {"type":"channel_data","connection_id":"60a4fc71-1312-4830-86f4-9eb98be106ac","message_id":1988,"id":"BCH-USD","channel":"v3_orderbook","contents":{"offset":"2693994568","bids":[["572.6","0"]],"asks":[["576.9","0"]]}}
1635444244.4515772: {"type":"channel_data","connection_id":"60a4fc71-1312-4830-86f4-9eb98be106ac","message_id":1989,"id":"LTC-USD","channel":"v3_orderbook","contents":{"offset":"2693994568","bids":[["187.4","70.59"],["187.2","77.86"]],"asks":[["188.6","61"],["189.2","390.86"]]}}
1635444244.4539149: {"type":"channel_data","connection_id":"60a4fc71-1312-4830-86f4-9eb98be106ac","message_id":1990,"id":"UMA-USD","channel":"v3_orderbook","contents":{"offset":"2693994568","bids":[["11.25","2546.7"]],"asks":[["11.35","838.1"]]}}
1635444244.4539762: {"type":"channel_data","connection_id":"60a4fc71-1312-4830-86f4-9eb98be106ac","message_id":1991,"id":"XMR-USD","channel":"v3_orderbook","contents":{"offset":"2693994568","bids":[["263.9","15.15"]],"asks":[]}}
1635444244.462543: {"type":"channel_data","connection_id":"60a4fc71-1312-4830-86f4-9eb98be106ac","message_id":1992,"id":"XMR-USD","channel":"v3_orderbook","contents":{"offset":"2693994569","bids":[["264.1","18.86"]],"asks":[["266","0"]]}}
1635444244.4626062: {"type":"channel_data","connection_id":"60a4fc71-1312-4830-86f4-9eb98be106ac","message_id":1993,"id":"UNI-USD","channel":"v3_orderbook","contents":{"offset":"2693994569","bids":[["24.989","0"]],"asks":[]}}
1635444244.471246: {"type":"channel_data","connection_id":"60a4fc71-1312-4830-86f4-9eb98be106ac","message_id":1994,"id":"ETH-USD","channel":"v3_orderbook","contents":{"offset":"2693994575","bids":[],"asks":[["4216.9","114.773"]]}}
1635444244.4713511: {"type":"channel_data","connection_id":"60a4fc71-1312-4830-86f4-9eb98be106ac","message_id":1995,"id":"SUSHI-USD","channel":"v3_orderbook","contents":{"offset":"2693994573","bids":[],"asks":[["10.828","539.1"]]}}
1635444244.492349: {"type":"channel_data","connection_id":"60a4fc71-1312-4830-86f4-9eb98be106ac","message_id":1996,"id":"ETH-USD","channel":"v3_orderbook","contents":{"offset":"2693994577","bids":[],"asks":[["4217.6","0"]]}}
1635444244.5113869: {"type":"channel_data","connection_id":"60a4fc71-1312-4830-86f4-9eb98be106ac","message_id":1997,"id":"ETH-USD","channel":"v3_orderbook","contents":{"offset":"2693994579","bids":[["4214","992.139"]],"asks":[]}}
1635444244.551664: {"type":"channel_data","connection_id":"60a4fc71-1312-4830-86f4-9eb98be106ac","message_id":1998,"id":"UMA-USD","channel":"v3_orderbook","contents":{"offset":"2693994591","bids":[["11.27","29527"]],"asks":[]}}
1635444244.551726: {"type":"channel_data","connection_id":"60a4fc71-1312-4830-86f4-9eb98be106ac","message_id":1999,"id":"MKR-USD","channel":"v3_orderbook","contents":{"offset":"2693994594","bids":[],"asks":[["2384","48.598"]]}}
1635444244.565527: {"type":"channel_data","connection_id":"60a4fc71-1312-4830-86f4-9eb98be106ac","message_id":2000,"id":"MKR-USD","channel":"v3_orderbook","contents":{"offset":"2693994596","bids":[["2379","36.767"]],"asks":[]}}
1635444244.5655942: {"type":"channel_data","connection_id":"60a4fc71-1312-4830-86f4-9eb98be106ac","message_id":2001,"id":"ETH-USD","channel":"v3_orderbook","contents":{"offset":"2693994597","bids":[],"asks":[["4217.5","10.659"]]}}
1635444244.575569: {"type":"channel_data","connection_id":"60a4fc71-1312-4830-86f4-9eb98be106ac","message_id":2002,"id":"UMA-USD","channel":"v3_orderbook","contents":{"offset":"2693994601","bids":[["11.27","29261.6"]],"asks":[]}}
1635444244.575638: {"type":"channel_data","connection_id":"60a4fc71-1312-4830-86f4-9eb98be106ac","message_id":2003,"id":"ETH-USD","channel":"v3_orderbook","contents":{"offset":"2693994598","bids":[],"asks":[["4222.2","0.2"]]}}
1635444244.586132: {"type":"channel_data","connection_id":"60a4fc71-1312-4830-86f4-9eb98be106ac","message_id":2004,"id":"XMR-USD","channel":"v3_orderbook","contents":{"offset":"2693994606","bids":[["263.9","89.15"]],"asks":[]}}
1635444244.594469: {"type":"channel_data","connection_id":"60a4fc71-1312-4830-86f4-9eb98be106ac","message_id":2005,"id":"UNI-USD","channel":"v3_orderbook","contents":{"offset":"2693994612","bids":[["24.989","1814.1"]],"asks":[]}}
1635444244.595784: {"type":"channel_data","connection_id":"60a4fc71-1312-4830-86f4-9eb98be106ac","message_id":2006,"id":"LTC-USD","channel":"v3_orderbook","contents":{"offset":"2693994610","bids":[["187.4","423.83"]],"asks":[]}}
1635444244.59585: {"type":"channel_data","connection_id":"60a4fc71-1312-4830-86f4-9eb98be106ac","message_id":2007,"id":"XMR-USD","channel":"v3_orderbook","contents":{"offset":"2693994614","bids":[],"asks":[["266","70"]]}}
1635444244.595886: {"type":"channel_data","connection_id":"60a4fc71-1312-4830-86f4-9eb98be106ac","message_id":2008,"id":"UMA-USD","channel":"v3_orderbook","contents":{"offset":"2693994611","bids":[],"asks":[["11.35","2605.2"]]}}
1635444244.612651: {"type":"channel_data","connection_id":"60a4fc71-1312-4830-86f4-9eb98be106ac","message_id":2009,"id":"ETH-USD","channel":"v3_orderbook","contents":{"offset":"2693994615","bids":[],"asks":[["4217.5","0.875"]]}}
1635444244.612714: {"type":"channel_data","connection_id":"60a4fc71-1312-4830-86f4-9eb98be106ac","message_id":2010,"id":"ETH-USD","channel":"v3_orderbook","contents":{"offset":"2693994617","bids":[["4213.9","57.11"]],"asks":[]}}
1635444244.6364958: {"type":"channel_data","connection_id":"60a4fc71-1312-4830-86f4-9eb98be106ac","message_id":2011,"id":"ETH-USD","channel":"v3_orderbook","contents":{"offset":"2693994628","bids":[],"asks":[["4217.6","9.784"]]}}
1635444244.639334: {"type":"channel_data","connection_id":"60a4fc71-1312-4830-86f4-9eb98be106ac","message_id":2012,"id":"SUSHI-USD","channel":"v3_orderbook","contents":{"offset":"2693994626","bids":[["10.792","1534.9"]],"asks":[]}}
1635444244.653244: {"type":"channel_data","connection_id":"60a4fc71-1312-4830-86f4-9eb98be106ac","message_id":2013,"id":"SUSHI-USD","channel":"v3_trades","contents":{"trades":[{"size":"9","side":"SELL","price":"10.792","createdAt":"2021-10-28T18:04:04.678Z"}]}}
1635444244.6566558: {"type":"channel_data","connection_id":"60a4fc71-1312-4830-86f4-9eb98be106ac","message_id":2014,"id":"ETH-USD","channel":"v3_orderbook","contents":{"offset":"2693994631","bids":[["4210","0.21"]],"asks":[]}}
1635444244.6567109: {"type":"channel_data","connection_id":"60a4fc71-1312-4830-86f4-9eb98be106ac","message_id":2015,"id":"ETH-USD","channel":"v3_orderbook","contents":{"offset":"2693994632","bids":[["4214","999.354"]],"asks":[]}}
1635444244.679747: {"type":"channel_data","connection_id":"60a4fc71-1312-4830-86f4-9eb98be106ac","message_id":2016,"id":"UNI-USD","channel":"v3_orderbook","contents":{"offset":"2693994640","bids":[],"asks":[["25.125","501"]]}}
1635444244.716613: {"type":"channel_data","connection_id":"60a4fc71-1312-4830-86f4-9eb98be106ac","message_id":2017,"id":"UMA-USD","channel":"v3_orderbook","contents":{"offset":"2693994647","bids":[["11.25","4092"]],"asks":[]}}
1635444244.716683: {"type":"channel_data","connection_id":"60a4fc71-1312-4830-86f4-9eb98be106ac","message_id":2018,"id":"XMR-USD","channel":"v3_orderbook","contents":{"offset":"2693994648","bids":[["264.1","88.86"]],"asks":[]}}
1635444244.7267892: {"type":"channel_data","connection_id":"60a4fc71-1312-4830-86f4-9eb98be106ac","message_id":2019,"id":"MKR-USD","channel":"v3_orderbook","contents":{"offset":"2693994652","bids":[["2377","52.709"]],"asks":[]}}
1635444244.787383: {"type":"channel_data","connection_id":"60a4fc71-1312-4830-86f4-9eb98be106ac","message_id":2020,"id":"ETH-USD","channel":"v3_orderbook","contents":{"offset":"2693994668","bids":[["4205.4","0.196"]],"asks":[]}}
1635444244.803485: {"type":"channel_data","connection_id":"60a4fc71-1312-4830-86f4-9eb98be106ac","message_id":2021,"id":"LTC-USD","channel":"v3_orderbook","contents":{"offset":"2693994669","bids":[["187.2","83.71"]],"asks":[]}}
1635444244.814663: {"type":"channel_data","connection_id":"60a4fc71-1312-4830-86f4-9eb98be106ac","message_id":2022,"id":"BCH-USD","channel":"v3_orderbook","contents":{"offset":"2693994678","bids":[["572.6","1.91"]],"asks":[]}}
1635444244.814788: {"type":"channel_data","connection_id":"60a4fc71-1312-4830-86f4-9eb98be106ac","message_id":2023,"id":"BCH-USD","channel":"v3_orderbook","contents":{"offset":"2693994675","bids":[],"asks":[["576.9","1.91"]]}}
1635444244.822817: {"type":"channel_data","connection_id":"60a4fc71-1312-4830-86f4-9eb98be106ac","message_id":2024,"id":"LTC-USD","channel":"v3_orderbook","contents":{"offset":"2693994681","bids":[],"asks":[["188.6","66.85"]]}}
1635444244.959609: {"type":"channel_data","connection_id":"60a4fc71-1312-4830-86f4-9eb98be106ac","message_id":2025,"id":"LTC-USD","channel":"v3_orderbook","contents":{"offset":"2693994715","bids":[],"asks":[["189.2","1188.96"]]}}
1635444244.9645271: {"type":"channel_data","connection_id":"60a4fc71-1312-4830-86f4-9eb98be106ac","message_id":2026,"id":"UMA-USD","channel":"v3_orderbook","contents":{"offset":"2693994719","bids":[["11.27","29527"]],"asks":[]}}
1635444245.007995: {"type":"channel_data","connection_id":"60a4fc71-1312-4830-86f4-9eb98be106ac","message_id":2027,"id":"UMA-USD","channel":"v3_orderbook","contents":{"offset":"2693994729","bids":[["11.27","29261.6"]],"asks":[]}}
1635444245.008075: {"type":"channel_data","connection_id":"60a4fc71-1312-4830-86f4-9eb98be106ac","message_id":2028,"id":"UNI-USD","channel":"v3_orderbook","contents":{"offset":"2693994733","bids":[["24.866","998.8"],["24.865","0"]],"asks":[]}}
1635444245.027669: {"type":"channel_data","connection_id":"60a4fc71-1312-4830-86f4-9eb98be106ac","message_id":2029,"id":"ETH-USD","channel":"v3_orderbook","contents":{"offset":"2693994734","bids":[],"asks":[["4219.8","2.026"]]}}
1635444245.037525: {"type":"channel_data","connection_id":"60a4fc71-1312-4830-86f4-9eb98be106ac","message_id":2030,"id":"ETH-USD","channel":"v3_orderbook","contents":{"offset":"2693994738","bids":[],"asks":[["4219.7","0"]]}}
1635444245.037647: {"type":"channel_data","connection_id":"60a4fc71-1312-4830-86f4-9eb98be106ac","message_id":2031,"id":"SUSHI-USD","channel":"v3_orderbook","contents":{"offset":"2693994742","bids":[],"asks":[["10.805","372.6"]]}}
1635444245.068317: {"type":"channel_data","connection_id":"60a4fc71-1312-4830-86f4-9eb98be106ac","message_id":2032,"id":"ETH-USD","channel":"v3_orderbook","contents":{"offset":"2693994755","bids":[["4215.9","553.966"]],"asks":[]}}
1635444245.082967: {"type":"channel_data","connection_id":"60a4fc71-1312-4830-86f4-9eb98be106ac","message_id":2033,"id":"LTC-USD","channel":"v3_orderbook","contents":{"offset":"2693994758","bids":[["187.8","2894.08"]],"asks":[]}}
1635444245.094045: {"type":"channel_data","connection_id":"60a4fc71-1312-4830-86f4-9eb98be106ac","message_id":2034,"id":"LTC-USD","channel":"v3_trades","contents":{"trades":[{"size":"15","side":"SELL","price":"187.8","createdAt":"2021-10-28T18:04:05.123Z"}]}}
1635444245.102866: {"type":"channel_data","connection_id":"60a4fc71-1312-4830-86f4-9eb98be106ac","message_id":2035,"id":"ETH-USD","channel":"v3_orderbook","contents":{"offset":"2693994762","bids":[],"asks":[["4219.6","89.921"]]}}
1635444245.14306: {"type":"channel_data","connection_id":"60a4fc71-1312-4830-86f4-9eb98be106ac","message_id":2036,"id":"ETH-USD","channel":"v3_orderbook","contents":{"offset":"2693994765","bids":[],"asks":[["4216.7","9.4"]]}}
1635444245.1431282: {"type":"channel_data","connection_id":"60a4fc71-1312-4830-86f4-9eb98be106ac","message_id":2037,"id":"ETH-USD","channel":"v3_orderbook","contents":{"offset":"2693994768","bids":[["4214","992.139"]],"asks":[]}}
1635444245.143751: {"type":"channel_data","connection_id":"60a4fc71-1312-4830-86f4-9eb98be106ac","message_id":2038,"id":"ETH-USD","channel":"v3_orderbook","contents":{"offset":"2693994766","bids":[],"asks":[["4217.6","0"]]}}
1635444245.192103: {"type":"channel_data","connection_id":"60a4fc71-1312-4830-86f4-9eb98be106ac","message_id":2039,"id":"ETH-USD","channel":"v3_orderbook","contents":{"offset":"2693994777","bids":[["4213.9","64.325"]],"asks":[]}}
1635444245.2015512: {"type":"channel_data","connection_id":"60a4fc71-1312-4830-86f4-9eb98be106ac","message_id":2040,"id":"SUSHI-USD","channel":"v3_orderbook","contents":{"offset":"2693994779","bids":[["10.726","3247.6"],["10.725","0"]],"asks":[]}}
1635444245.317803: {"type":"channel_data","connection_id":"60a4fc71-1312-4830-86f4-9eb98be106ac","message_id":2041,"id":"UNI-USD","channel":"v3_orderbook","contents":{"offset":"2693994800","bids":[],"asks":[["25.053","16064.3"]]}}
1635444245.327318: {"type":"channel_data","connection_id":"60a4fc71-1312-4830-86f4-9eb98be106ac","message_id":2042,"id":"EOS-USD","channel":"v3_orderbook","contents":{"offset":"2693994804","bids":[],"asks":[["4.403","22393"]]}}
1635444245.32739: {"type":"channel_data","connection_id":"60a4fc71-1312-4830-86f4-9eb98be106ac","message_id":2043,"id":"UNI-USD","channel":"v3_orderbook","contents":{"offset":"2693994805","bids":[],"asks":[["25.081","0"]]}}
1635444245.3274229: {"type":"channel_data","connection_id":"60a4fc71-1312-4830-86f4-9eb98be106ac","message_id":2044,"id":"ETH-USD","channel":"v3_orderbook","contents":{"offset":"2693994806","bids":[],"asks":[["4226.6","1.971"]]}}
1635444245.3519092: {"type":"channel_data","connection_id":"60a4fc71-1312-4830-86f4-9eb98be106ac","message_id":2045,"id":"UNI-USD","channel":"v3_orderbook","contents":{"offset":"2693994816","bids":[],"asks":[["25.051","2836.2"]]}}
1635444245.351976: {"type":"channel_data","connection_id":"60a4fc71-1312-4830-86f4-9eb98be106ac","message_id":2046,"id":"SUSHI-USD","channel":"v3_orderbook","contents":{"offset":"2693994819","bids":[["10.779","8990.2"]],"asks":[]}}
1635444245.3971179: {"type":"channel_data","connection_id":"60a4fc71-1312-4830-86f4-9eb98be106ac","message_id":2047,"id":"UNI-USD","channel":"v3_orderbook","contents":{"offset":"2693994831","bids":[["25.03","399.5"]],"asks":[]}}
1635444245.397202: {"type":"channel_data","connection_id":"60a4fc71-1312-4830-86f4-9eb98be106ac","message_id":2048,"id":"LTC-USD","channel":"v3_orderbook","contents":{"offset":"2693994833","bids":[],"asks":[["188","2610.92"]]}}
1635444245.399178: {"type":"channel_data","connection_id":"60a4fc71-1312-4830-86f4-9eb98be106ac","message_id":2049,"id":"LTC-USD","channel":"v3_orderbook","contents":{"offset":"2693994832","bids":[],"asks":[["188","2992.81"]]}}
1635444245.399232: {"type":"channel_data","connection_id":"60a4fc71-1312-4830-86f4-9eb98be106ac","message_id":2050,"id":"UNI-USD","channel":"v3_orderbook","contents":{"offset":"2693994830","bids":[],"asks":[["25.053","109.1"]]}}
1635444245.4112709: {"type":"channel_data","connection_id":"60a4fc71-1312-4830-86f4-9eb98be106ac","message_id":2051,"id":"UNI-USD","channel":"v3_orderbook","contents":{"offset":"2693994841","bids":[],"asks":[["25.125","4088.9"]]}}
1635444245.411343: {"type":"channel_data","connection_id":"60a4fc71-1312-4830-86f4-9eb98be106ac","message_id":2052,"id":"LTC-USD","channel":"v3_orderbook","contents":{"offset":"2693994837","bids":[],"asks":[["188","523.26"]]}}
1635444245.413375: {"type":"channel_data","connection_id":"60a4fc71-1312-4830-86f4-9eb98be106ac","message_id":2053,"id":"ETH-USD","channel":"v3_orderbook","contents":{"offset":"2693994838","bids":[["4214.9","0"]],"asks":[]}}
1635444245.448491: {"type":"channel_data","connection_id":"60a4fc71-1312-4830-86f4-9eb98be106ac","message_id":2054,"id":"MKR-USD","channel":"v3_orderbook","contents":{"offset":"2693994851","bids":[],"asks":[["2383","15.282"]]}}
1635444245.45448: {"type":"channel_data","connection_id":"60a4fc71-1312-4830-86f4-9eb98be106ac","message_id":2055,"id":"UNI-USD","channel":"v3_orderbook","contents":{"offset":"2693994857","bids":[],"asks":[["25.09","389933.4"]]}}
1635444245.458121: {"type":"channel_data","connection_id":"60a4fc71-1312-4830-86f4-9eb98be106ac","message_id":2056,"id":"ETH-USD","channel":"v3_orderbook","contents":{"offset":"2693994854","bids":[["4213.9","57.11"]],"asks":[]}}
1635444245.4582038: {"type":"channel_data","connection_id":"60a4fc71-1312-4830-86f4-9eb98be106ac","message_id":2057,"id":"BCH-USD","channel":"v3_orderbook","contents":{"offset":"2693994858","bids":[["574.5","413.23"]],"asks":[]}}
1635444245.458241: {"type":"channel_data","connection_id":"60a4fc71-1312-4830-86f4-9eb98be106ac","message_id":2058,"id":"BCH-USD","channel":"v3_orderbook","contents":{"offset":"2693994856","bids":[],"asks":[["574.9","50.06"]]}}
1635444245.458278: {"type":"channel_data","connection_id":"60a4fc71-1312-4830-86f4-9eb98be106ac","message_id":2059,"id":"LTC-USD","channel":"v3_orderbook","contents":{"offset":"2693994859","bids":[],"asks":[["188.1","0"]]}}
1635444245.461704: {"type":"channel_data","connection_id":"60a4fc71-1312-4830-86f4-9eb98be106ac","message_id":2060,"id":"ETH-USD","channel":"v3_orderbook","contents":{"offset":"2693994865","bids":[["4215.2","0"]],"asks":[]}}
1635444245.461777: {"type":"channel_data","connection_id":"60a4fc71-1312-4830-86f4-9eb98be106ac","message_id":2061,"id":"LTC-USD","channel":"v3_orderbook","contents":{"offset":"2693994863","bids":[["187.6","42318.27"]],"asks":[]}}
1635444245.461807: {"type":"channel_data","connection_id":"60a4fc71-1312-4830-86f4-9eb98be106ac","message_id":2062,"id":"LTC-USD","channel":"v3_orderbook","contents":{"offset":"2693994860","bids":[],"asks":[["188","461.76"]]}}
1635444245.46183: {"type":"channel_data","connection_id":"60a4fc71-1312-4830-86f4-9eb98be106ac","message_id":2063,"id":"LTC-USD","channel":"v3_orderbook","contents":{"offset":"2693994861","bids":[],"asks":[["188.2","713.17"]]}}
1635444245.464153: {"type":"channel_data","connection_id":"60a4fc71-1312-4830-86f4-9eb98be106ac","message_id":2064,"id":"LTC-USD","channel":"v3_orderbook","contents":{"offset":"2693994866","bids":[["187.4","70.59"]],"asks":[]}}
1635444245.4642189: {"type":"channel_data","connection_id":"60a4fc71-1312-4830-86f4-9eb98be106ac","message_id":2065,"id":"LTC-USD","channel":"v3_orderbook","contents":{"offset":"2693994864","bids":[],"asks":[["188","403.19"]]}}
1635444245.4642482: {"type":"channel_data","connection_id":"60a4fc71-1312-4830-86f4-9eb98be106ac","message_id":2066,"id":"BCH-USD","channel":"v3_orderbook","contents":{"offset":"2693994862","bids":[],"asks":[["575.2","20.1"]]}}
1635444245.4681091: {"type":"channel_data","connection_id":"60a4fc71-1312-4830-86f4-9eb98be106ac","message_id":2067,"id":"LTC-USD","channel":"v3_orderbook","contents":{"offset":"2693994868","bids":[["187.6","394.34"]],"asks":[]}}
1635444245.4681711: {"type":"channel_data","connection_id":"60a4fc71-1312-4830-86f4-9eb98be106ac","message_id":2068,"id":"LTC-USD","channel":"v3_orderbook","contents":{"offset":"2693994871","bids":[["187.3","193.24"]],"asks":[]}}
1635444245.468195: {"type":"channel_data","connection_id":"60a4fc71-1312-4830-86f4-9eb98be106ac","message_id":2069,"id":"LTC-USD","channel":"v3_orderbook","contents":{"offset":"2693994869","bids":[["187.7","332.8"]],"asks":[]}}
1635444245.509449: {"type":"channel_data","connection_id":"60a4fc71-1312-4830-86f4-9eb98be106ac","message_id":2070,"id":"LTC-USD","channel":"v3_orderbook","contents":{"offset":"2693994872","bids":[["187.5","90.15"]],"asks":[]}}
1635444245.509566: {"type":"channel_data","connection_id":"60a4fc71-1312-4830-86f4-9eb98be106ac","message_id":2071,"id":"LTC-USD","channel":"v3_orderbook","contents":{"offset":"2693994867","bids":[],"asks":[["188","5.46"]]}}
1635444245.509619: {"type":"channel_data","connection_id":"60a4fc71-1312-4830-86f4-9eb98be106ac","message_id":2072,"id":"ETH-USD","channel":"v3_orderbook","contents":{"offset":"2693994870","bids":[["4214","999.354"]],"asks":[]}}
1635444245.5096881: {"type":"channel_data","connection_id":"60a4fc71-1312-4830-86f4-9eb98be106ac","message_id":2073,"id":"ETH-USD","channel":"v3_orderbook","contents":{"offset":"2693994876","bids":[],"asks":[["4217.6","9.784"]]}}
1635444245.509716: {"type":"channel_data","connection_id":"60a4fc71-1312-4830-86f4-9eb98be106ac","message_id":2074,"id":"LTC-USD","channel":"v3_orderbook","contents":{"offset":"2693994877","bids":[["187.7","274.23"]],"asks":[]}}
1635444245.509741: {"type":"channel_data","connection_id":"60a4fc71-1312-4830-86f4-9eb98be106ac","message_id":2075,"id":"CRV-USD","channel":"v3_orderbook","contents":{"offset":"2693994879","bids":[["4.849","1552"]],"asks":[]}}
1635444245.5097668: {"type":"channel_data","connection_id":"60a4fc71-1312-4830-86f4-9eb98be106ac","message_id":2076,"id":"LTC-USD","channel":"v3_orderbook","contents":{"offset":"2693994880","bids":[],"asks":[["188.4","111.09"]]}}
1635444245.509791: {"type":"channel_data","connection_id":"60a4fc71-1312-4830-86f4-9eb98be106ac","message_id":2077,"id":"EOS-USD","channel":"v3_orderbook","contents":{"offset":"2693994882","bids":[],"asks":[["4.406","1053"]]}}
1635444245.5098162: {"type":"channel_data","connection_id":"60a4fc71-1312-4830-86f4-9eb98be106ac","message_id":2078,"id":"UNI-USD","channel":"v3_orderbook","contents":{"offset":"2693994878","bids":[],"asks":[["25.058","2924.7"]]}}
1635444245.509841: {"type":"channel_data","connection_id":"60a4fc71-1312-4830-86f4-9eb98be106ac","message_id":2079,"id":"LTC-USD","channel":"v3_orderbook","contents":{"offset":"2693994885","bids":[["187.6","413.24"]],"asks":[]}}
1635444245.5098639: {"type":"channel_data","connection_id":"60a4fc71-1312-4830-86f4-9eb98be106ac","message_id":2080,"id":"BCH-USD","channel":"v3_orderbook","contents":{"offset":"2693994886","bids":[["574.5","418.84"]],"asks":[]}}
1635444245.509887: {"type":"channel_data","connection_id":"60a4fc71-1312-4830-86f4-9eb98be106ac","message_id":2081,"id":"ETH-USD","channel":"v3_orderbook","contents":{"offset":"2693994887","bids":[["4214.6","4.91"]],"asks":[]}}
1635444245.5156648: {"type":"channel_data","connection_id":"60a4fc71-1312-4830-86f4-9eb98be106ac","message_id":2082,"id":"ETH-USD","channel":"v3_orderbook","contents":{"offset":"2693994892","bids":[],"asks":[["4216","2.25"]]}}
1635444245.515726: {"type":"channel_data","connection_id":"60a4fc71-1312-4830-86f4-9eb98be106ac","message_id":2083,"id":"LTC-USD","channel":"v3_orderbook","contents":{"offset":"2693994894","bids":[],"asks":[["188.1","397.81"]]}}
1635444245.526966: {"type":"channel_data","connection_id":"60a4fc71-1312-4830-86f4-9eb98be106ac","message_id":2084,"id":"UNI-USD","channel":"v3_orderbook","contents":{"offset":"2693994897","bids":[["24.879","1997.7"],["24.878","0"]],"asks":[]}}
1635444245.540236: {"type":"channel_data","connection_id":"60a4fc71-1312-4830-86f4-9eb98be106ac","message_id":2085,"id":"LTC-USD","channel":"v3_orderbook","contents":{"offset":"2693994905","bids":[],"asks":[["188.1","2519.42"]]}}
1635444245.54032: {"type":"channel_data","connection_id":"60a4fc71-1312-4830-86f4-9eb98be106ac","message_id":2086,"id":"UNI-USD","channel":"v3_orderbook","contents":{"offset":"2693994901","bids":[],"asks":[["25.206","0"],["25.209","998.8"]]}}
1635444245.540365: {"type":"channel_data","connection_id":"60a4fc71-1312-4830-86f4-9eb98be106ac","message_id":2087,"id":"ETH-USD","channel":"v3_orderbook","contents":{"offset":"2693994904","bids":[["4214","992.139"]],"asks":[]}}
1635444245.542333: {"type":"channel_data","connection_id":"60a4fc71-1312-4830-86f4-9eb98be106ac","message_id":2088,"id":"LTC-USD","channel":"v3_orderbook","contents":{"offset":"2693994908","bids":[],"asks":[["188","0"]]}}
1635444245.5446389: {"type":"channel_data","connection_id":"60a4fc71-1312-4830-86f4-9eb98be106ac","message_id":2089,"id":"BCH-USD","channel":"v3_orderbook","contents":{"offset":"2693994906","bids":[],"asks":[["575","50.06"]]}}
1635444245.54924: {"type":"channel_data","connection_id":"60a4fc71-1312-4830-86f4-9eb98be106ac","message_id":2090,"id":"UNI-USD","channel":"v3_orderbook","contents":{"offset":"2693994911","bids":[],"asks":[["25.193","0"],["25.195","1997.7"]]}}
1635444245.552804: {"type":"channel_data","connection_id":"60a4fc71-1312-4830-86f4-9eb98be106ac","message_id":2091,"id":"UNI-USD","channel":"v3_orderbook","contents":{"offset":"2693994912","bids":[["24.904","1997.7"],["24.903","0"]],"asks":[]}}
1635444245.552869: {"type":"channel_data","connection_id":"60a4fc71-1312-4830-86f4-9eb98be106ac","message_id":2092,"id":"LTC-USD","channel":"v3_orderbook","contents":{"offset":"2693994917","bids":[],"asks":[["188.1","397.81"]]}}
1635444245.571174: {"type":"channel_data","connection_id":"60a4fc71-1312-4830-86f4-9eb98be106ac","message_id":2093,"id":"ETH-USD","channel":"v3_orderbook","contents":{"offset":"2693994920","bids":[],"asks":[["4217.6","0"]]}}
1635444245.5739882: {"type":"channel_data","connection_id":"60a4fc71-1312-4830-86f4-9eb98be106ac","message_id":2094,"id":"UNI-USD","channel":"v3_orderbook","contents":{"offset":"2693994927","bids":[],"asks":[["25.057","7798.6"]]}}
1635444245.574053: {"type":"channel_data","connection_id":"60a4fc71-1312-4830-86f4-9eb98be106ac","message_id":2095,"id":"BCH-USD","channel":"v3_orderbook","contents":{"offset":"2693994925","bids":[["574.6","201.89"]],"asks":[]}}
1635444245.574083: {"type":"channel_data","connection_id":"60a4fc71-1312-4830-86f4-9eb98be106ac","message_id":2096,"id":"ETH-USD","channel":"v3_orderbook","contents":{"offset":"2693994926","bids":[],"asks":[["4219.3","1.778"]]}}
1635444245.58873: {"type":"channel_data","connection_id":"60a4fc71-1312-4830-86f4-9eb98be106ac","message_id":2097,"id":"UNI-USD","channel":"v3_orderbook","contents":{"offset":"2693994935","bids":[],"asks":[["25.062","15655.3"]]}}
1635444245.588794: {"type":"channel_data","connection_id":"60a4fc71-1312-4830-86f4-9eb98be106ac","message_id":2098,"id":"LTC-USD","channel":"v3_orderbook","contents":{"offset":"2693994929","bids":[["187.8","2952.62"]],"asks":[]}}
1635444245.588819: {"type":"channel_data","connection_id":"60a4fc71-1312-4830-86f4-9eb98be106ac","message_id":2099,"id":"ETH-USD","channel":"v3_orderbook","contents":{"offset":"2693994933","bids":[["4213.9","64.325"]],"asks":[]}}
1635444245.5888388: {"type":"channel_data","connection_id":"60a4fc71-1312-4830-86f4-9eb98be106ac","message_id":2100,"id":"LTC-USD","channel":"v3_orderbook","contents":{"offset":"2693994928","bids":[],"asks":[["188.1","403.27"]]}}
1635444245.588856: {"type":"channel_data","connection_id":"60a4fc71-1312-4830-86f4-9eb98be106ac","message_id":2101,"id":"ETH-USD","channel":"v3_orderbook","contents":{"offset":"2693994934","bids":[["4215.5","186.501"]],"asks":[]}}
1635444245.588872: {"type":"channel_data","connection_id":"60a4fc71-1312-4830-86f4-9eb98be106ac","message_id":2102,"id":"SUSHI-USD","channel":"v3_orderbook","contents":{"offset":"2693994931","bids":[],"asks":[["10.866","0"],["10.867","1372.2"]]}}
1635444245.588896: {"type":"channel_data","connection_id":"60a4fc71-1312-4830-86f4-9eb98be106ac","message_id":2103,"id":"BCH-USD","channel":"v3_orderbook","contents":{"offset":"2693994937","bids":[["574.5","413.23"]],"asks":[]}}
1635444245.588912: {"type":"channel_data","connection_id":"60a4fc71-1312-4830-86f4-9eb98be106ac","message_id":2104,"id":"UNI-USD","channel":"v3_orderbook","contents":{"offset":"2693994936","bids":[],"asks":[["25.168","0"],["25.171","1214.8"]]}}
1635444245.5919218: {"type":"channel_data","connection_id":"60a4fc71-1312-4830-86f4-9eb98be106ac","message_id":2105,"id":"LTC-USD","channel":"v3_orderbook","contents":{"offset":"2693994939","bids":[],"asks":[["188.1","461.81"]]}}
1635444245.5951738: {"type":"channel_data","connection_id":"60a4fc71-1312-4830-86f4-9eb98be106ac","message_id":2106,"id":"UNI-USD","channel":"v3_orderbook","contents":{"offset":"2693994941","bids":[],"asks":[["25.057","0"]]}}
1635444245.595229: {"type":"channel_data","connection_id":"60a4fc71-1312-4830-86f4-9eb98be106ac","message_id":2107,"id":"UNI-USD","channel":"v3_orderbook","contents":{"offset":"2693994944","bids":[["25.034","2924.2"]],"asks":[]}}
1635444245.5952609: {"type":"channel_data","connection_id":"60a4fc71-1312-4830-86f4-9eb98be106ac","message_id":2108,"id":"LTC-USD","channel":"v3_orderbook","contents":{"offset":"2693994945","bids":[["187.6","394.34"]],"asks":[]}}
1635444245.596129: {"type":"channel_data","connection_id":"60a4fc71-1312-4830-86f4-9eb98be106ac","message_id":2109,"id":"LTC-USD","channel":"v3_orderbook","contents":{"offset":"2693994942","bids":[],"asks":[["188.1","1522.62"]]}}
1635444245.6064918: {"type":"channel_data","connection_id":"60a4fc71-1312-4830-86f4-9eb98be106ac","message_id":2110,"id":"LTC-USD","channel":"v3_orderbook","contents":{"offset":"2693994951","bids":[],"asks":[["188.2","705.19"]]}}
1635444245.6065521: {"type":"channel_data","connection_id":"60a4fc71-1312-4830-86f4-9eb98be106ac","message_id":2111,"id":"BCH-USD","channel":"v3_orderbook","contents":{"offset":"2693994948","bids":[],"asks":[["574.8","0"]]}}
1635444245.6065788: {"type":"channel_data","connection_id":"60a4fc71-1312-4830-86f4-9eb98be106ac","message_id":2112,"id":"MKR-USD","channel":"v3_orderbook","contents":{"offset":"2693994950","bids":[["2377","51.145"]],"asks":[]}}
1635444245.617507: {"type":"channel_data","connection_id":"60a4fc71-1312-4830-86f4-9eb98be106ac","message_id":2113,"id":"ETH-USD","channel":"v3_orderbook","contents":{"offset":"2693994953","bids":[["4215.9","548.033"]],"asks":[]}}
1635444245.617576: {"type":"channel_data","connection_id":"60a4fc71-1312-4830-86f4-9eb98be106ac","message_id":2114,"id":"LTC-USD","channel":"v3_orderbook","contents":{"offset":"2693994952","bids":[["187.5","74.81"]],"asks":[]}}
1635444245.629965: {"type":"channel_data","connection_id":"60a4fc71-1312-4830-86f4-9eb98be106ac","message_id":2115,"id":"LTC-USD","channel":"v3_orderbook","contents":{"offset":"2693994959","bids":[["187.7","286.21"]],"asks":[]}}
1635444245.6300302: {"type":"channel_data","connection_id":"60a4fc71-1312-4830-86f4-9eb98be106ac","message_id":2116,"id":"LTC-USD","channel":"v3_orderbook","contents":{"offset":"2693994960","bids":[["187.9","397.67"]],"asks":[]}}
1635444245.6443489: {"type":"channel_data","connection_id":"60a4fc71-1312-4830-86f4-9eb98be106ac","message_id":2117,"id":"LTC-USD","channel":"v3_orderbook","contents":{"offset":"2693994964","bids":[["187.8","2971.52"]],"asks":[]}}
1635444245.656977: {"type":"channel_data","connection_id":"60a4fc71-1312-4830-86f4-9eb98be106ac","message_id":2118,"id":"LTC-USD","channel":"v3_orderbook","contents":{"offset":"2693994968","bids":[["187.6","430.26"]],"asks":[]}}
1635444245.669487: {"type":"channel_data","connection_id":"60a4fc71-1312-4830-86f4-9eb98be106ac","message_id":2119,"id":"LTC-USD","channel":"v3_orderbook","contents":{"offset":"2693994972","bids":[],"asks":[["188.1","461.81"]]}}
1635444245.673072: {"type":"channel_data","connection_id":"60a4fc71-1312-4830-86f4-9eb98be106ac","message_id":2120,"id":"LTC-USD","channel":"v3_orderbook","contents":{"offset":"2693994980","bids":[["187.8","1953.31"]],"asks":[]}}
1635444245.673111: {"type":"channel_data","connection_id":"60a4fc71-1312-4830-86f4-9eb98be106ac","message_id":2121,"id":"BCH-USD","channel":"v3_orderbook","contents":{"offset":"2693994977","bids":[],"asks":[["575.3","368.51"]]}}
1635444245.677983: {"type":"channel_data","connection_id":"60a4fc71-1312-4830-86f4-9eb98be106ac","message_id":2122,"id":"LTC-USD","channel":"v3_orderbook","contents":{"offset":"2693994984","bids":[],"asks":[["188.1","531.92"]]}}
1635444245.6780329: {"type":"channel_data","connection_id":"60a4fc71-1312-4830-86f4-9eb98be106ac","message_id":2123,"id":"LTC-USD","channel":"v3_orderbook","contents":{"offset":"2693994981","bids":[["187.6","63"]],"asks":[]}}
1635444245.678062: {"type":"channel_data","connection_id":"60a4fc71-1312-4830-86f4-9eb98be106ac","message_id":2124,"id":"LTC-USD","channel":"v3_orderbook","contents":{"offset":"2693994982","bids":[["187.8","913.9"]],"asks":[]}}
1635444245.689234: {"type":"channel_data","connection_id":"60a4fc71-1312-4830-86f4-9eb98be106ac","message_id":2125,"id":"BCH-USD","channel":"v3_orderbook","contents":{"offset":"2693994988","bids":[],"asks":[["575.1","0"]]}}
1635444245.6892958: {"type":"channel_data","connection_id":"60a4fc71-1312-4830-86f4-9eb98be106ac","message_id":2126,"id":"BCH-USD","channel":"v3_orderbook","contents":{"offset":"2693994989","bids":[["574.4","123.37"]],"asks":[]}}
1635444245.7035599: {"type":"channel_data","connection_id":"60a4fc71-1312-4830-86f4-9eb98be106ac","message_id":2127,"id":"CRV-USD","channel":"v3_orderbook","contents":{"offset":"2693994991","bids":[],"asks":[["4.861","227"],["4.865","14787"]]}}
1635444245.71621: {"type":"channel_data","connection_id":"60a4fc71-1312-4830-86f4-9eb98be106ac","message_id":2128,"id":"LTC-USD","channel":"v3_orderbook","contents":{"offset":"2693994997","bids":[],"asks":[["188.1","2653.53"]]}}
1635444245.716274: {"type":"channel_data","connection_id":"60a4fc71-1312-4830-86f4-9eb98be106ac","message_id":2129,"id":"ETH-USD","channel":"v3_orderbook","contents":{"offset":"2693994998","bids":[],"asks":[["4216.7","126.87"]]}}
1635444245.716299: {"type":"channel_data","connection_id":"60a4fc71-1312-4830-86f4-9eb98be106ac","message_id":2130,"id":"UNI-USD","channel":"v3_orderbook","contents":{"offset":"2693994995","bids":[],"asks":[["25.062","31250.8"]]}}
1635444245.724271: {"type":"channel_data","connection_id":"60a4fc71-1312-4830-86f4-9eb98be106ac","message_id":2131,"id":"LTC-USD","channel":"v3_orderbook","contents":{"offset":"2693995001","bids":[],"asks":[["188.1","3051.2"]]}}
1635444245.724341: {"type":"channel_data","connection_id":"60a4fc71-1312-4830-86f4-9eb98be106ac","message_id":2132,"id":"LTC-USD","channel":"v3_orderbook","contents":{"offset":"2693995002","bids":[],"asks":[["188.1","929.59"]]}}
1635444245.7243671: {"type":"channel_data","connection_id":"60a4fc71-1312-4830-86f4-9eb98be106ac","message_id":2133,"id":"ETH-USD","channel":"v3_orderbook","contents":{"offset":"2693995000","bids":[["4199","0.202"]],"asks":[]}}
1635444245.724753: {"type":"channel_data","connection_id":"60a4fc71-1312-4830-86f4-9eb98be106ac","message_id":2134,"id":"LTC-USD","channel":"v3_orderbook","contents":{"offset":"2693995003","bids":[["187.8","895"]],"asks":[]}}
1635444245.737107: {"type":"channel_data","connection_id":"60a4fc71-1312-4830-86f4-9eb98be106ac","message_id":2135,"id":"BCH-USD","channel":"v3_orderbook","contents":{"offset":"2693995008","bids":[["573.4","10.38"]],"asks":[]}}
1635444245.737171: {"type":"channel_data","connection_id":"60a4fc71-1312-4830-86f4-9eb98be106ac","message_id":2136,"id":"LTC-USD","channel":"v3_orderbook","contents":{"offset":"2693995005","bids":[["187.7","42703.39"]],"asks":[]}}
1635444245.7371972: {"type":"channel_data","connection_id":"60a4fc71-1312-4830-86f4-9eb98be106ac","message_id":2137,"id":"LTC-USD","channel":"v3_orderbook","contents":{"offset":"2693995006","bids":[],"asks":[["188.1","531.92"]]}}
1635444245.7438421: {"type":"channel_data","connection_id":"60a4fc71-1312-4830-86f4-9eb98be106ac","message_id":2138,"id":"LTC-USD","channel":"v3_orderbook","contents":{"offset":"2693995009","bids":[["187.8","824.89"]],"asks":[]}}
1635444245.76494: {"type":"channel_data","connection_id":"60a4fc71-1312-4830-86f4-9eb98be106ac","message_id":2139,"id":"ETH-USD","channel":"v3_orderbook","contents":{"offset":"2693995015","bids":[],"asks":[["4217.6","9.784"]]}}
1635444245.765002: {"type":"channel_data","connection_id":"60a4fc71-1312-4830-86f4-9eb98be106ac","message_id":2140,"id":"ETH-USD","channel":"v3_orderbook","contents":{"offset":"2693995016","bids":[["4213.9","57.11"]],"asks":[]}}
1635444245.771441: {"type":"channel_data","connection_id":"60a4fc71-1312-4830-86f4-9eb98be106ac","message_id":2141,"id":"UNI-USD","channel":"v3_orderbook","contents":{"offset":"2693995022","bids":[["24.867","998.8"],["24.866","0"]],"asks":[]}}
1635444245.773779: {"type":"channel_data","connection_id":"60a4fc71-1312-4830-86f4-9eb98be106ac","message_id":2142,"id":"LTC-USD","channel":"v3_orderbook","contents":{"offset":"2693995019","bids":[["187.7","42722.29"]],"asks":[]}}
1635444245.782179: {"type":"channel_data","connection_id":"60a4fc71-1312-4830-86f4-9eb98be106ac","message_id":2143,"id":"ETH-USD","channel":"v3_orderbook","contents":{"offset":"2693995026","bids":[["4214","999.354"]],"asks":[]}}
1635444245.790194: {"type":"channel_data","connection_id":"60a4fc71-1312-4830-86f4-9eb98be106ac","message_id":2144,"id":"LTC-USD","channel":"v3_orderbook","contents":{"offset":"2693995032","bids":[["187.9","467.78"]],"asks":[]}}
1635444245.814123: {"type":"channel_data","connection_id":"60a4fc71-1312-4830-86f4-9eb98be106ac","message_id":2145,"id":"BCH-USD","channel":"v3_orderbook","contents":{"offset":"2693995039","bids":[],"asks":[["575.2","150.17"]]}}
1635444245.819777: {"type":"channel_data","connection_id":"60a4fc71-1312-4830-86f4-9eb98be106ac","message_id":2146,"id":"BCH-USD","channel":"v3_orderbook","contents":{"offset":"2693995050","bids":[["574.5","419.21"]],"asks":[]}}
1635444245.819843: {"type":"channel_data","connection_id":"60a4fc71-1312-4830-86f4-9eb98be106ac","message_id":2147,"id":"ETH-USD","channel":"v3_orderbook","contents":{"offset":"2693995046","bids":[["4213.7","1898.587"]],"asks":[]}}
1635444245.827352: {"type":"channel_data","connection_id":"60a4fc71-1312-4830-86f4-9eb98be106ac","message_id":2148,"id":"MKR-USD","channel":"v3_orderbook","contents":{"offset":"2693995055","bids":[["2379","21.755"]],"asks":[]}}
1635444245.82817: {"type":"channel_data","connection_id":"60a4fc71-1312-4830-86f4-9eb98be106ac","message_id":2149,"id":"MKR-USD","channel":"v3_orderbook","contents":{"offset":"2693995056","bids":[],"asks":[["2384","33.586"]]}}
1635444245.838237: {"type":"channel_data","connection_id":"60a4fc71-1312-4830-86f4-9eb98be106ac","message_id":2150,"id":"LTC-USD","channel":"v3_orderbook","contents":{"offset":"2693995063","bids":[["186.3","383.68"]],"asks":[]}}
1635444245.840001: {"type":"channel_data","connection_id":"60a4fc71-1312-4830-86f4-9eb98be106ac","message_id":2151,"id":"MKR-USD","channel":"v3_orderbook","contents":{"offset":"2693995065","bids":[["2380","28.716"]],"asks":[]}}
1635444245.8400462: {"type":"channel_data","connection_id":"60a4fc71-1312-4830-86f4-9eb98be106ac","message_id":2152,"id":"MKR-USD","channel":"v3_orderbook","contents":{"offset":"2693995062","bids":[],"asks":[["2385","63.7"]]}}
1635444245.840255: {"type":"channel_data","connection_id":"60a4fc71-1312-4830-86f4-9eb98be106ac","message_id":2153,"id":"MKR-USD","channel":"v3_orderbook","contents":{"offset":"2693995066","bids":[],"asks":[["2385","78.712"]]}}
1635444245.841432: {"type":"channel_data","connection_id":"60a4fc71-1312-4830-86f4-9eb98be106ac","message_id":2154,"id":"LTC-USD","channel":"v3_orderbook","contents":{"offset":"2693995067","bids":[["185.5","29.11"]],"asks":[]}}
1635444245.845475: {"type":"channel_data","connection_id":"60a4fc71-1312-4830-86f4-9eb98be106ac","message_id":2155,"id":"MKR-USD","channel":"v3_orderbook","contents":{"offset":"2693995068","bids":[],"asks":[["2385","93.724"]]}}
1635444245.8498461: {"type":"channel_data","connection_id":"60a4fc71-1312-4830-86f4-9eb98be106ac","message_id":2156,"id":"MKR-USD","channel":"v3_orderbook","contents":{"offset":"2693995073","bids":[],"asks":[["2384","18.574"]]}}
1635444245.8608341: {"type":"channel_data","connection_id":"60a4fc71-1312-4830-86f4-9eb98be106ac","message_id":2157,"id":"LTC-USD","channel":"v3_orderbook","contents":{"offset":"2693995081","bids":[["188","397.67"]],"asks":[]}}
1635444245.8609128: {"type":"channel_data","connection_id":"60a4fc71-1312-4830-86f4-9eb98be106ac","message_id":2158,"id":"LTC-USD","channel":"v3_orderbook","contents":{"offset":"2693995077","bids":[["187.9","1528.21"]],"asks":[]}}
1635444245.8636951: {"type":"channel_data","connection_id":"60a4fc71-1312-4830-86f4-9eb98be106ac","message_id":2159,"id":"LTC-USD","channel":"v3_orderbook","contents":{"offset":"2693995080","bids":[],"asks":[["188.1","2653.53"]]}}
1635444245.863752: {"type":"channel_data","connection_id":"60a4fc71-1312-4830-86f4-9eb98be106ac","message_id":2160,"id":"ETH-USD","channel":"v3_orderbook","contents":{"offset":"2693995078","bids":[["4214","992.139"]],"asks":[]}}
1635444245.881637: {"type":"channel_data","connection_id":"60a4fc71-1312-4830-86f4-9eb98be106ac","message_id":2161,"id":"ETH-USD","channel":"v3_orderbook","contents":{"offset":"2693995089","bids":[["4213.9","64.325"]],"asks":[]}}
1635444245.8817222: {"type":"channel_data","connection_id":"60a4fc71-1312-4830-86f4-9eb98be106ac","message_id":2162,"id":"LTC-USD","channel":"v3_orderbook","contents":{"offset":"2693995088","bids":[],"asks":[["188.1","531.92"]]}}
1635444245.88176: {"type":"channel_data","connection_id":"60a4fc71-1312-4830-86f4-9eb98be106ac","message_id":2163,"id":"MKR-USD","channel":"v3_orderbook","contents":{"offset":"2693995086","bids":[["2379","36.767"]],"asks":[]}}
1635444245.881789: {"type":"channel_data","connection_id":"60a4fc71-1312-4830-86f4-9eb98be106ac","message_id":2164,"id":"ETH-USD","channel":"v3_orderbook","contents":{"offset":"2693995082","bids":[],"asks":[["4217.6","0"]]}}
1635444245.881817: {"type":"channel_data","connection_id":"60a4fc71-1312-4830-86f4-9eb98be106ac","message_id":2165,"id":"LTC-USD","channel":"v3_orderbook","contents":{"offset":"2693995092","bids":[],"asks":[["188.1","1990.31"]]}}
1635444245.8851562: {"type":"channel_data","connection_id":"60a4fc71-1312-4830-86f4-9eb98be106ac","message_id":2166,"id":"EOS-USD","channel":"v3_orderbook","contents":{"offset":"2693995095","bids":[],"asks":[["4.405","43163"]]}}
1635444245.885202: {"type":"channel_data","connection_id":"60a4fc71-1312-4830-86f4-9eb98be106ac","message_id":2167,"id":"CRV-USD","channel":"v3_orderbook","contents":{"offset":"2693995096","bids":[["4.837","9651"]],"asks":[]}}
1635444245.8861032: {"type":"channel_data","connection_id":"60a4fc71-1312-4830-86f4-9eb98be106ac","message_id":2168,"id":"LTC-USD","channel":"v3_orderbook","contents":{"offset":"2693995090","bids":[],"asks":[["188.1","929.59"]]}}
1635444245.8903658: {"type":"channel_data","connection_id":"60a4fc71-1312-4830-86f4-9eb98be106ac","message_id":2169,"id":"EOS-USD","channel":"v3_orderbook","contents":{"offset":"2693995101","bids":[],"asks":[["4.404","3685"]]}}
1635444245.890412: {"type":"channel_data","connection_id":"60a4fc71-1312-4830-86f4-9eb98be106ac","message_id":2170,"id":"EOS-USD","channel":"v3_orderbook","contents":{"offset":"2693995105","bids":[["4.399","11336"]],"asks":[]}}
1635444245.89044: {"type":"channel_data","connection_id":"60a4fc71-1312-4830-86f4-9eb98be106ac","message_id":2171,"id":"ETH-USD","channel":"v3_orderbook","contents":{"offset":"2693995103","bids":[],"asks":[["4219.6","91.343"]]}}
1635444245.890464: {"type":"channel_data","connection_id":"60a4fc71-1312-4830-86f4-9eb98be106ac","message_id":2172,"id":"LTC-USD","channel":"v3_orderbook","contents":{"offset":"2693995098","bids":[["187.9","3649.07"]],"asks":[]}}
1635444245.900047: {"type":"channel_data","connection_id":"60a4fc71-1312-4830-86f4-9eb98be106ac","message_id":2173,"id":"LTC-USD","channel":"v3_orderbook","contents":{"offset":"2693995110","bids":[["187.9","1528.21"]],"asks":[]}}
1635444245.900682: {"type":"channel_data","connection_id":"60a4fc71-1312-4830-86f4-9eb98be106ac","message_id":2174,"id":"LTC-USD","channel":"v3_orderbook","contents":{"offset":"2693995108","bids":[],"asks":[["188.2","699.33"]]}}
1635444245.912501: {"type":"channel_data","connection_id":"60a4fc71-1312-4830-86f4-9eb98be106ac","message_id":2175,"id":"LTC-USD","channel":"v3_orderbook","contents":{"offset":"2693995113","bids":[],"asks":[["188.2","693.47"]]}}
1635444245.9130938: {"type":"channel_data","connection_id":"60a4fc71-1312-4830-86f4-9eb98be106ac","message_id":2176,"id":"UNI-USD","channel":"v3_orderbook","contents":{"offset":"2693995115","bids":[],"asks":[["25.062","15655.3"]]}}
1635444245.923316: {"type":"channel_data","connection_id":"60a4fc71-1312-4830-86f4-9eb98be106ac","message_id":2177,"id":"ETH-USD","channel":"v3_orderbook","contents":{"offset":"2693995119","bids":[["4213.3","21.973"]],"asks":[]}}
1635444245.9234: {"type":"channel_data","connection_id":"60a4fc71-1312-4830-86f4-9eb98be106ac","message_id":2178,"id":"LTC-USD","channel":"v3_orderbook","contents":{"offset":"2693995123","bids":[["187.7","42703.39"]],"asks":[]}}
1635444245.933595: {"type":"channel_data","connection_id":"60a4fc71-1312-4830-86f4-9eb98be106ac","message_id":2179,"id":"EOS-USD","channel":"v3_orderbook","contents":{"offset":"2693995128","bids":[["4.401","1136"]],"asks":[]}}
1635444245.9467258: {"type":"channel_data","connection_id":"60a4fc71-1312-4830-86f4-9eb98be106ac","message_id":2180,"id":"EOS-USD","channel":"v3_orderbook","contents":{"offset":"2693995133","bids":[],"asks":[["4.405","44299"]]}}
1635444245.9468002: {"type":"channel_data","connection_id":"60a4fc71-1312-4830-86f4-9eb98be106ac","message_id":2181,"id":"LTC-USD","channel":"v3_orderbook","contents":{"offset":"2693995136","bids":[],"asks":[["189.2","390.86"],["189.3","1581.12"]]}}
1635444245.946832: {"type":"channel_data","connection_id":"60a4fc71-1312-4830-86f4-9eb98be106ac","message_id":2182,"id":"LTC-USD","channel":"v3_orderbook","contents":{"offset":"2693995129","bids":[["187.5","68.95"]],"asks":[]}}
1635444245.946851: {"type":"channel_data","connection_id":"60a4fc71-1312-4830-86f4-9eb98be106ac","message_id":2183,"id":"LTC-USD","channel":"v3_orderbook","contents":{"offset":"2693995131","bids":[["187.3","187.38"]],"asks":[]}}
1635444245.951988: {"type":"channel_data","connection_id":"60a4fc71-1312-4830-86f4-9eb98be106ac","message_id":2184,"id":"LTC-USD","channel":"v3_orderbook","contents":{"offset":"2693995137","bids":[],"asks":[["188.1","1920.2"]]}}
1635444245.969325: {"type":"channel_data","connection_id":"60a4fc71-1312-4830-86f4-9eb98be106ac","message_id":2185,"id":"EOS-USD","channel":"v3_orderbook","contents":{"offset":"2693995141","bids":[],"asks":[["4.403","11196"]]}}
1635444245.969388: {"type":"channel_data","connection_id":"60a4fc71-1312-4830-86f4-9eb98be106ac","message_id":2186,"id":"EOS-USD","channel":"v3_orderbook","contents":{"offset":"2693995144","bids":[],"asks":[["4.405","10214"]]}}
1635444245.969412: {"type":"channel_data","connection_id":"60a4fc71-1312-4830-86f4-9eb98be106ac","message_id":2187,"id":"EOS-USD","channel":"v3_orderbook","contents":{"offset":"2693995138","bids":[["4.4","1476"]],"asks":[]}}
1635444245.96943: {"type":"channel_data","connection_id":"60a4fc71-1312-4830-86f4-9eb98be106ac","message_id":2188,"id":"EOS-USD","channel":"v3_orderbook","contents":{"offset":"2693995142","bids":[["4.39","1553"]],"asks":[]}}
1635444245.9694479: {"type":"channel_data","connection_id":"60a4fc71-1312-4830-86f4-9eb98be106ac","message_id":2189,"id":"ETH-USD","channel":"v3_orderbook","contents":{"offset":"2693995145","bids":[["4213.9","57.11"]],"asks":[]}}
1635444245.969465: {"type":"channel_data","connection_id":"60a4fc71-1312-4830-86f4-9eb98be106ac","message_id":2190,"id":"LTC-USD","channel":"v3_orderbook","contents":{"offset":"2693995143","bids":[],"asks":[["189","116.49"],["189.1","1165.14"]]}}
1635444245.970203: {"type":"channel_data","connection_id":"60a4fc71-1312-4830-86f4-9eb98be106ac","message_id":2191,"id":"ETH-USD","channel":"v3_orderbook","contents":{"offset":"2693995139","bids":[["4213.3","0"]],"asks":[]}}
1635444245.97884: {"type":"channel_data","connection_id":"60a4fc71-1312-4830-86f4-9eb98be106ac","message_id":2192,"id":"EOS-USD","channel":"v3_orderbook","contents":{"offset":"2693995149","bids":[],"asks":[["4.406","2189"]]}}
1635444245.978938: {"type":"channel_data","connection_id":"60a4fc71-1312-4830-86f4-9eb98be106ac","message_id":2193,"id":"ETH-USD","channel":"v3_orderbook","contents":{"offset":"2693995147","bids":[],"asks":[["4219.7","1.422"]]}}
1635444246.003458: {"type":"channel_data","connection_id":"60a4fc71-1312-4830-86f4-9eb98be106ac","message_id":2194,"id":"EOS-USD","channel":"v3_orderbook","contents":{"offset":"2693995157","bids":[["4.386","249"],["4.385","16117"]],"asks":[]}}
1635444246.019881: {"type":"channel_data","connection_id":"60a4fc71-1312-4830-86f4-9eb98be106ac","message_id":2195,"id":"UNI-USD","channel":"v3_orderbook","contents":{"offset":"2693995160","bids":[["24.882","1997.7"],["24.879","0"]],"asks":[]}}
1635444246.0216992: {"type":"channel_data","connection_id":"60a4fc71-1312-4830-86f4-9eb98be106ac","message_id":2196,"id":"LTC-USD","channel":"v3_orderbook","contents":{"offset":"2693995161","bids":[],"asks":[["188.4","116.94"]]}}
1635444246.021744: {"type":"channel_data","connection_id":"60a4fc71-1312-4830-86f4-9eb98be106ac","message_id":2197,"id":"LTC-USD","channel":"v3_orderbook","contents":{"offset":"2693995162","bids":[],"asks":[["188.5","21.11"]]}}
1635444246.02177: {"type":"channel_data","connection_id":"60a4fc71-1312-4830-86f4-9eb98be106ac","message_id":2198,"id":"LTC-USD","channel":"v3_orderbook","contents":{"offset":"2693995158","bids":[["187.7","42709.24"]],"asks":[]}}
1635444246.0222359: {"type":"channel_data","connection_id":"60a4fc71-1312-4830-86f4-9eb98be106ac","message_id":2199,"id":"ETH-USD","channel":"v3_orderbook","contents":{"offset":"2693995159","bids":[["4213.8","7.215"]],"asks":[]}}
1635444246.0363011: {"type":"channel_data","connection_id":"60a4fc71-1312-4830-86f4-9eb98be106ac","message_id":2200,"id":"UNI-USD","channel":"v3_orderbook","contents":{"offset":"2693995166","bids":[],"asks":[["25.195","0"],["25.197","1997.7"]]}}
1635444246.0363672: {"type":"channel_data","connection_id":"60a4fc71-1312-4830-86f4-9eb98be106ac","message_id":2201,"id":"LTC-USD","channel":"v3_orderbook","contents":{"offset":"2693995165","bids":[],"asks":[["188.1","4041.81"]]}}
1635444246.037261: {"type":"channel_data","connection_id":"60a4fc71-1312-4830-86f4-9eb98be106ac","message_id":2202,"id":"BCH-USD","channel":"v3_orderbook","contents":{"offset":"2693995167","bids":[["574.6","71.81"]],"asks":[]}}
1635444246.038153: {"type":"channel_data","connection_id":"60a4fc71-1312-4830-86f4-9eb98be106ac","message_id":2203,"id":"LTC-USD","channel":"v3_orderbook","contents":{"offset":"2693995163","bids":[["187.6","68.85"]],"asks":[]}}
1635444246.049697: {"type":"channel_data","connection_id":"60a4fc71-1312-4830-86f4-9eb98be106ac","message_id":2204,"id":"BCH-USD","channel":"v3_orderbook","contents":{"offset":"2693995170","bids":[["573.1","6.49"]],"asks":[]}}
1635444246.049812: {"type":"channel_data","connection_id":"60a4fc71-1312-4830-86f4-9eb98be106ac","message_id":2205,"id":"ETH-USD","channel":"v3_orderbook","contents":{"offset":"2693995168","bids":[],"asks":[["4217.4","57.806"]]}}
1635444246.049876: {"type":"channel_data","connection_id":"60a4fc71-1312-4830-86f4-9eb98be106ac","message_id":2206,"id":"BCH-USD","channel":"v3_orderbook","contents":{"offset":"2693995169","bids":[["573.8","5.5"]],"asks":[]}}
1635444246.04991: {"type":"channel_data","connection_id":"60a4fc71-1312-4830-86f4-9eb98be106ac","message_id":2207,"id":"UNI-USD","channel":"v3_orderbook","contents":{"offset":"2693995171","bids":[],"asks":[["25.171","147.7"],["25.172","1067.1"]]}}
1635444246.059036: {"type":"channel_data","connection_id":"60a4fc71-1312-4830-86f4-9eb98be106ac","message_id":2208,"id":"UNI-USD","channel":"v3_orderbook","contents":{"offset":"2693995176","bids":[["25.029","0"]],"asks":[]}}
1635444246.063172: {"type":"channel_data","connection_id":"60a4fc71-1312-4830-86f4-9eb98be106ac","message_id":2209,"id":"UNI-USD","channel":"v3_orderbook","contents":{"offset":"2693995175","bids":[],"asks":[["25.058","0"]]}}
1635444246.063221: {"type":"channel_data","connection_id":"60a4fc71-1312-4830-86f4-9eb98be106ac","message_id":2210,"id":"EOS-USD","channel":"v3_orderbook","contents":{"offset":"2693995179","bids":[],"asks":[["4.426","0"],["4.427","45215"]]}}
1635444246.0632498: {"type":"channel_data","connection_id":"60a4fc71-1312-4830-86f4-9eb98be106ac","message_id":2211,"id":"UNI-USD","channel":"v3_orderbook","contents":{"offset":"2693995180","bids":[["25.032","59.9"]],"asks":[]}}
1635444246.0661051: {"type":"channel_data","connection_id":"60a4fc71-1312-4830-86f4-9eb98be106ac","message_id":2212,"id":"ETH-USD","channel":"v3_orderbook","contents":{"offset":"2693995181","bids":[["4213.7","1917.775"]],"asks":[]}}
1635444246.070884: {"type":"channel_data","connection_id":"60a4fc71-1312-4830-86f4-9eb98be106ac","message_id":2213,"id":"UNI-USD","channel":"v3_orderbook","contents":{"offset":"2693995186","bids":[],"asks":[["25.209","0"],["25.21","998.8"]]}}
1635444246.070946: {"type":"channel_data","connection_id":"60a4fc71-1312-4830-86f4-9eb98be106ac","message_id":2214,"id":"LTC-USD","channel":"v3_orderbook","contents":{"offset":"2693995183","bids":[["187.9","2588.34"]],"asks":[]}}
1635444246.072715: {"type":"channel_data","connection_id":"60a4fc71-1312-4830-86f4-9eb98be106ac","message_id":2215,"id":"UMA-USD","channel":"v3_orderbook","contents":{"offset":"2693995188","bids":[["11.28","8905.7"]],"asks":[]}}
1635444246.083484: {"type":"channel_data","connection_id":"60a4fc71-1312-4830-86f4-9eb98be106ac","message_id":2216,"id":"UMA-USD","channel":"v3_orderbook","contents":{"offset":"2693995197","bids":[],"asks":[["11.33","25060.2"]]}}
1635444246.084387: {"type":"channel_data","connection_id":"60a4fc71-1312-4830-86f4-9eb98be106ac","message_id":2217,"id":"UNI-USD","channel":"v3_orderbook","contents":{"offset":"2693995195","bids":[["24.907","9499.7"],["24.904","0"]],"asks":[]}}
1635444246.0944278: {"type":"channel_data","connection_id":"60a4fc71-1312-4830-86f4-9eb98be106ac","message_id":2218,"id":"EOS-USD","channel":"v3_orderbook","contents":{"offset":"2693995202","bids":[],"asks":[["4.404","15004"]]}}
1635444246.095382: {"type":"channel_data","connection_id":"60a4fc71-1312-4830-86f4-9eb98be106ac","message_id":2219,"id":"EOS-USD","channel":"v3_orderbook","contents":{"offset":"2693995199","bids":[["4.392","1132552"]],"asks":[]}}
1635444246.1174579: {"type":"channel_data","connection_id":"60a4fc71-1312-4830-86f4-9eb98be106ac","message_id":2220,"id":"EOS-USD","channel":"v3_orderbook","contents":{"offset":"2693995206","bids":[["4.401","12456"]],"asks":[]}}
1635444246.117515: {"type":"channel_data","connection_id":"60a4fc71-1312-4830-86f4-9eb98be106ac","message_id":2221,"id":"UMA-USD","channel":"v3_orderbook","contents":{"offset":"2693995203","bids":[["11.28","8640.3"]],"asks":[]}}
1635444246.117536: {"type":"channel_data","connection_id":"60a4fc71-1312-4830-86f4-9eb98be106ac","message_id":2222,"id":"UMA-USD","channel":"v3_orderbook","contents":{"offset":"2693995207","bids":[["11.29","3336.6"]],"asks":[]}}
1635444246.1205409: {"type":"channel_data","connection_id":"60a4fc71-1312-4830-86f4-9eb98be106ac","message_id":2223,"id":"ETH-USD","channel":"v3_orderbook","contents":{"offset":"2693995204","bids":[],"asks":[["4219.4","0.02"]]}}
1635444246.1238909: {"type":"channel_data","connection_id":"60a4fc71-1312-4830-86f4-9eb98be106ac","message_id":2224,"id":"UMA-USD","channel":"v3_orderbook","contents":{"offset":"2693995208","bids":[],"asks":[["11.32","10825.2"]]}}
1635444246.12599: {"type":"channel_data","connection_id":"60a4fc71-1312-4830-86f4-9eb98be106ac","message_id":2225,"id":"EOS-USD","channel":"v3_orderbook","contents":{"offset":"2693995212","bids":[["4.395","0"]],"asks":[]}}
1635444246.134567: {"type":"channel_data","connection_id":"60a4fc71-1312-4830-86f4-9eb98be106ac","message_id":2226,"id":"UMA-USD","channel":"v3_orderbook","contents":{"offset":"2693995221","bids":[["11.28","11976.9"]],"asks":[]}}
1635444246.136632: {"type":"channel_data","connection_id":"60a4fc71-1312-4830-86f4-9eb98be106ac","message_id":2227,"id":"ETH-USD","channel":"v3_orderbook","contents":{"offset":"2693995215","bids":[],"asks":[["4232.9","0.315"]]}}
1635444246.1403542: {"type":"channel_data","connection_id":"60a4fc71-1312-4830-86f4-9eb98be106ac","message_id":2228,"id":"EOS-USD","channel":"v3_orderbook","contents":{"offset":"2693995220","bids":[],"asks":[["4.407","35510"]]}}
1635444246.143632: {"type":"channel_data","connection_id":"60a4fc71-1312-4830-86f4-9eb98be106ac","message_id":2229,"id":"UMA-USD","channel":"v3_orderbook","contents":{"offset":"2693995229","bids":[["11.28","11834.1"]],"asks":[]}}
1635444246.143682: {"type":"channel_data","connection_id":"60a4fc71-1312-4830-86f4-9eb98be106ac","message_id":2230,"id":"UMA-USD","channel":"v3_orderbook","contents":{"offset":"2693995225","bids":[],"asks":[["11.31","13443.8"]]}}
1635444246.147846: {"type":"channel_data","connection_id":"60a4fc71-1312-4830-86f4-9eb98be106ac","message_id":2231,"id":"ETH-USD","channel":"v3_orderbook","contents":{"offset":"2693995237","bids":[["4213.8","0"]],"asks":[]}}
1635444246.1497128: {"type":"channel_data","connection_id":"60a4fc71-1312-4830-86f4-9eb98be106ac","message_id":2232,"id":"UMA-USD","channel":"v3_orderbook","contents":{"offset":"2693995233","bids":[],"asks":[["11.34","389"]]}}
1635444246.1542778: {"type":"channel_data","connection_id":"60a4fc71-1312-4830-86f4-9eb98be106ac","message_id":2233,"id":"EOS-USD","channel":"v3_orderbook","contents":{"offset":"2693995240","bids":[["4.397","46319"]],"asks":[]}}
1635444246.154319: {"type":"channel_data","connection_id":"60a4fc71-1312-4830-86f4-9eb98be106ac","message_id":2234,"id":"ETH-USD","channel":"v3_orderbook","contents":{"offset":"2693995241","bids":[],"asks":[["4217.4","48.022"]]}}
1635444246.16624: {"type":"channel_data","connection_id":"60a4fc71-1312-4830-86f4-9eb98be106ac","message_id":2235,"id":"UMA-USD","channel":"v3_orderbook","contents":{"offset":"2693995248","bids":[["11.27","29404.4"]],"asks":[]}}
1635444246.1662982: {"type":"channel_data","connection_id":"60a4fc71-1312-4830-86f4-9eb98be106ac","message_id":2236,"id":"SUSHI-USD","channel":"v3_orderbook","contents":{"offset":"2693995246","bids":[["10.792","1801.3"]],"asks":[]}}
1635444246.170636: {"type":"channel_data","connection_id":"60a4fc71-1312-4830-86f4-9eb98be106ac","message_id":2237,"id":"BCH-USD","channel":"v3_orderbook","contents":{"offset":"2693995249","bids":[["574.7","291.93"]],"asks":[]}}
1635444246.170691: {"type":"channel_data","connection_id":"60a4fc71-1312-4830-86f4-9eb98be106ac","message_id":2238,"id":"ETH-USD","channel":"v3_orderbook","contents":{"offset":"2693995243","bids":[["4152.3","0"]],"asks":[]}}
1635444246.1707141: {"type":"channel_data","connection_id":"60a4fc71-1312-4830-86f4-9eb98be106ac","message_id":2239,"id":"ETH-USD","channel":"v3_orderbook","contents":{"offset":"2693995244","bids":[],"asks":[["4278.8","0"]]}}
1635444246.178557: {"type":"channel_data","connection_id":"60a4fc71-1312-4830-86f4-9eb98be106ac","message_id":2240,"id":"ETH-USD","channel":"v3_orderbook","contents":{"offset":"2693995250","bids":[["4213.9","64.325"]],"asks":[]}}
1635444246.190263: {"type":"channel_data","connection_id":"60a4fc71-1312-4830-86f4-9eb98be106ac","message_id":2241,"id":"UNI-USD","channel":"v3_orderbook","contents":{"offset":"2693995257","bids":[],"asks":[["25.065","3363.5"]]}}
1635444246.230685: {"type":"channel_data","connection_id":"60a4fc71-1312-4830-86f4-9eb98be106ac","message_id":2242,"id":"SUSHI-USD","channel":"v3_orderbook","contents":{"offset":"2693995266","bids":[["10.788","185.4"]],"asks":[]}}
1635444246.2307498: {"type":"channel_data","connection_id":"60a4fc71-1312-4830-86f4-9eb98be106ac","message_id":2243,"id":"SUSHI-USD","channel":"v3_orderbook","contents":{"offset":"2693995267","bids":[["10.78","1071.2"]],"asks":[]}}
1635444246.24139: {"type":"channel_data","connection_id":"60a4fc71-1312-4830-86f4-9eb98be106ac","message_id":2244,"id":"UNI-USD","channel":"v3_orderbook","contents":{"offset":"2693995270","bids":[["24.869","998.8"],["24.867","0"]],"asks":[]}}
1635444246.2542999: {"type":"channel_data","connection_id":"60a4fc71-1312-4830-86f4-9eb98be106ac","message_id":2245,"id":"UMA-USD","channel":"v3_orderbook","contents":{"offset":"2693995273","bids":[["11.27","29261.6"]],"asks":[]}}
1635444246.269088: {"type":"channel_data","connection_id":"60a4fc71-1312-4830-86f4-9eb98be106ac","message_id":2246,"id":"UMA-USD","channel":"v3_orderbook","contents":{"offset":"2693995280","bids":[["11.28","11976.9"]],"asks":[]}}
1635444246.321239: {"type":"channel_data","connection_id":"60a4fc71-1312-4830-86f4-9eb98be106ac","message_id":2247,"id":"UMA-USD","channel":"v3_orderbook","contents":{"offset":"2693995286","bids":[["11.27","29527.1"]],"asks":[]}}
1635444246.335317: {"type":"channel_data","connection_id":"60a4fc71-1312-4830-86f4-9eb98be106ac","message_id":2248,"id":"ETH-USD","channel":"v3_orderbook","contents":{"offset":"2693995290","bids":[["4213.7","1898.587"]],"asks":[]}}
1635444246.346426: {"type":"channel_data","connection_id":"60a4fc71-1312-4830-86f4-9eb98be106ac","message_id":2249,"id":"LTC-USD","channel":"v3_orderbook","contents":{"offset":"2693995291","bids":[["187","15.08"],["186.9","24.39"]],"asks":[]}}
1635444246.3465521: {"type":"channel_data","connection_id":"60a4fc71-1312-4830-86f4-9eb98be106ac","message_id":2250,"id":"SUSHI-USD","channel":"v3_orderbook","contents":{"offset":"2693995292","bids":[["10.79","8187.9"]],"asks":[]}}
1635444246.3591502: {"type":"channel_data","connection_id":"60a4fc71-1312-4830-86f4-9eb98be106ac","message_id":2251,"id":"LTC-USD","channel":"v3_orderbook","contents":{"offset":"2693995295","bids":[["187.6","84.18"]],"asks":[]}}
1635444246.370903: {"type":"channel_data","connection_id":"60a4fc71-1312-4830-86f4-9eb98be106ac","message_id":2252,"id":"UMA-USD","channel":"v3_orderbook","contents":{"offset":"2693995297","bids":[["11.27","29261.6"]],"asks":[]}}
1635444246.387436: {"type":"channel_data","connection_id":"60a4fc71-1312-4830-86f4-9eb98be106ac","message_id":2253,"id":"BCH-USD","channel":"v3_orderbook","contents":{"offset":"2693995302","bids":[["574.4","73.31"]],"asks":[]}}
1635444246.394014: {"type":"channel_data","connection_id":"60a4fc71-1312-4830-86f4-9eb98be106ac","message_id":2254,"id":"BCH-USD","channel":"v3_orderbook","contents":{"offset":"2693995304","bids":[],"asks":[["575.2","200.23"]]}}
1635444246.394073: {"type":"channel_data","connection_id":"60a4fc71-1312-4830-86f4-9eb98be106ac","message_id":2255,"id":"BCH-USD","channel":"v3_orderbook","contents":{"offset":"2693995303","bids":[["574.8","50.06"]],"asks":[]}}
1635444246.411919: {"type":"channel_data","connection_id":"60a4fc71-1312-4830-86f4-9eb98be106ac","message_id":2256,"id":"MKR-USD","channel":"v3_orderbook","contents":{"offset":"2693995310","bids":[],"asks":[["2385","91.727"]]}}
1635444246.411978: {"type":"channel_data","connection_id":"60a4fc71-1312-4830-86f4-9eb98be106ac","message_id":2257,"id":"CRV-USD","channel":"v3_orderbook","contents":{"offset":"2693995307","bids":[["4.821","96939"],["4.82","0"]],"asks":[]}}
1635444246.421074: {"type":"channel_data","connection_id":"60a4fc71-1312-4830-86f4-9eb98be106ac","message_id":2258,"id":"SUSHI-USD","channel":"v3_orderbook","contents":{"offset":"2693995312","bids":[["10.767","0"]],"asks":[]}}
1635444246.4211369: {"type":"channel_data","connection_id":"60a4fc71-1312-4830-86f4-9eb98be106ac","message_id":2259,"id":"BCH-USD","channel":"v3_orderbook","contents":{"offset":"2693995314","bids":[["574.7","166.87"]],"asks":[]}}
1635444246.421163: {"type":"channel_data","connection_id":"60a4fc71-1312-4830-86f4-9eb98be106ac","message_id":2260,"id":"CRV-USD","channel":"v3_orderbook","contents":{"offset":"2693995313","bids":[["4.852","10684"]],"asks":[]}}
1635444246.421184: {"type":"channel_data","connection_id":"60a4fc71-1312-4830-86f4-9eb98be106ac","message_id":2261,"id":"SUSHI-USD","channel":"v3_orderbook","contents":{"offset":"2693995311","bids":[["10.783","0"]],"asks":[]}}
1635444246.432645: {"type":"channel_data","connection_id":"60a4fc71-1312-4830-86f4-9eb98be106ac","message_id":2262,"id":"BCH-USD","channel":"v3_orderbook","contents":{"offset":"2693995317","bids":[["574.5","76.14"]],"asks":[]}}
1635444246.432708: {"type":"channel_data","connection_id":"60a4fc71-1312-4830-86f4-9eb98be106ac","message_id":2263,"id":"BCH-USD","channel":"v3_orderbook","contents":{"offset":"2693995322","bids":[["572.8","6"]],"asks":[]}}
1635444246.435861: {"type":"channel_data","connection_id":"60a4fc71-1312-4830-86f4-9eb98be106ac","message_id":2264,"id":"LTC-USD","channel":"v3_orderbook","contents":{"offset":"2693995319","bids":[["187.7","42647.74"]],"asks":[]}}
1635444246.435905: {"type":"channel_data","connection_id":"60a4fc71-1312-4830-86f4-9eb98be106ac","message_id":2265,"id":"ETH-USD","channel":"v3_orderbook","contents":{"offset":"2693995316","bids":[["4213.3","21.722"]],"asks":[]}}
1635444246.439204: {"type":"channel_data","connection_id":"60a4fc71-1312-4830-86f4-9eb98be106ac","message_id":2266,"id":"BCH-USD","channel":"v3_orderbook","contents":{"offset":"2693995323","bids":[],"asks":[["575.6","1.91"]]}}
1635444246.444421: {"type":"channel_data","connection_id":"60a4fc71-1312-4830-86f4-9eb98be106ac","message_id":2267,"id":"ETH-USD","channel":"v3_orderbook","contents":{"offset":"2693995328","bids":[["4215.9","547.333"]],"asks":[]}}
1635444246.444496: {"type":"channel_data","connection_id":"60a4fc71-1312-4830-86f4-9eb98be106ac","message_id":2268,"id":"ETH-USD","channel":"v3_orderbook","contents":{"offset":"2693995326","bids":[],"asks":[["4217.8","17.791"]]}}
1635444246.444524: {"type":"channel_data","connection_id":"60a4fc71-1312-4830-86f4-9eb98be106ac","message_id":2269,"id":"ETH-USD","channel":"v3_orderbook","contents":{"offset":"2693995327","bids":[],"asks":[["4219.1","0"]]}}
1635444246.4577248: {"type":"channel_data","connection_id":"60a4fc71-1312-4830-86f4-9eb98be106ac","message_id":2270,"id":"ETH-USD","channel":"v3_orderbook","contents":{"offset":"2693995336","bids":[],"asks":[["4217","0"]]}}
1635444246.457841: {"type":"channel_data","connection_id":"60a4fc71-1312-4830-86f4-9eb98be106ac","message_id":2271,"id":"ETH-USD","channel":"v3_orderbook","contents":{"offset":"2693995330","bids":[["4213.7","0"]],"asks":[]}}
1635444246.4579: {"type":"channel_data","connection_id":"60a4fc71-1312-4830-86f4-9eb98be106ac","message_id":2272,"id":"ETH-USD","channel":"v3_orderbook","contents":{"offset":"2693995337","bids":[],"asks":[["4216.7","9.4"]]}}
1635444246.457945: {"type":"channel_data","connection_id":"60a4fc71-1312-4830-86f4-9eb98be106ac","message_id":2273,"id":"ETH-USD","channel":"v3_orderbook","contents":{"offset":"2693995335","bids":[],"asks":[["4217","47.465"]]}}
1635444246.45798: {"type":"channel_data","connection_id":"60a4fc71-1312-4830-86f4-9eb98be106ac","message_id":2274,"id":"ETH-USD","channel":"v3_orderbook","contents":{"offset":"2693995331","bids":[["4152.7","1.4"]],"asks":[]}}
1635444246.460583: {"type":"channel_data","connection_id":"60a4fc71-1312-4830-86f4-9eb98be106ac","message_id":2275,"id":"ETH-USD","channel":"v3_orderbook","contents":{"offset":"2693995332","bids":[["4212.4","2.029"]],"asks":[]}}
1635444246.465006: {"type":"channel_data","connection_id":"60a4fc71-1312-4830-86f4-9eb98be106ac","message_id":2276,"id":"ETH-USD","channel":"v3_orderbook","contents":{"offset":"2693995341","bids":[],"asks":[["4219.6","89.921"]]}}
1635444246.465097: {"type":"channel_data","connection_id":"60a4fc71-1312-4830-86f4-9eb98be106ac","message_id":2277,"id":"MKR-USD","channel":"v3_orderbook","contents":{"offset":"2693995344","bids":[["2380","29.924"]],"asks":[]}}
1635444246.465475: {"type":"channel_data","connection_id":"60a4fc71-1312-4830-86f4-9eb98be106ac","message_id":2278,"id":"ETH-USD","channel":"v3_orderbook","contents":{"offset":"2693995338","bids":[["4215.9","523.601"]],"asks":[]}}
1635444246.469347: {"type":"channel_data","connection_id":"60a4fc71-1312-4830-86f4-9eb98be106ac","message_id":2279,"id":"ETH-USD","channel":"v3_orderbook","contents":{"offset":"2693995342","bids":[],"asks":[["4219.7","0"]]}}
1635444246.4694662: {"type":"channel_data","connection_id":"60a4fc71-1312-4830-86f4-9eb98be106ac","message_id":2280,"id":"LTC-USD","channel":"v3_orderbook","contents":{"offset":"2693995345","bids":[],"asks":[["188.2","678.3"]]}}
1635444246.469523: {"type":"channel_data","connection_id":"60a4fc71-1312-4830-86f4-9eb98be106ac","message_id":2281,"id":"ETH-USD","channel":"v3_orderbook","contents":{"offset":"2693995339","bids":[["4215.9","464.951"]],"asks":[]}}
1635444246.469567: {"type":"channel_data","connection_id":"60a4fc71-1312-4830-86f4-9eb98be106ac","message_id":2282,"id":"ETH-USD","channel":"v3_orderbook","contents":{"offset":"2693995343","bids":[],"asks":[["4220","730.526"]]}}
1635444246.469619: {"type":"channel_data","connection_id":"60a4fc71-1312-4830-86f4-9eb98be106ac","message_id":2283,"id":"EOS-USD","channel":"v3_orderbook","contents":{"offset":"2693995340","bids":[["4.398","5222"]],"asks":[]}}
1635444246.472235: {"type":"channel_data","connection_id":"60a4fc71-1312-4830-86f4-9eb98be106ac","message_id":2284,"id":"ETH-USD","channel":"v3_orderbook","contents":{"offset":"2693995346","bids":[["4214.6","2.071"]],"asks":[]}}
1635444246.4776928: {"type":"channel_data","connection_id":"60a4fc71-1312-4830-86f4-9eb98be106ac","message_id":2285,"id":"ETH-USD","channel":"v3_orderbook","contents":{"offset":"2693995357","bids":[["4215.5","69.031"]],"asks":[]}}
1635444246.477777: {"type":"channel_data","connection_id":"60a4fc71-1312-4830-86f4-9eb98be106ac","message_id":2286,"id":"ETH-USD","channel":"v3_orderbook","contents":{"offset":"2693995353","bids":[["4212.6","0"]],"asks":[]}}
1635444246.477814: {"type":"channel_data","connection_id":"60a4fc71-1312-4830-86f4-9eb98be106ac","message_id":2287,"id":"ETH-USD","channel":"v3_orderbook","contents":{"offset":"2693995351","bids":[],"asks":[["4218","5.065"]]}}
1635444246.477856: {"type":"channel_data","connection_id":"60a4fc71-1312-4830-86f4-9eb98be106ac","message_id":2288,"id":"ETH-USD","channel":"v3_orderbook","contents":{"offset":"2693995355","bids":[],"asks":[["4218.4","40"]]}}
1635444246.477885: {"type":"channel_data","connection_id":"60a4fc71-1312-4830-86f4-9eb98be106ac","message_id":2289,"id":"ETH-USD","channel":"v3_orderbook","contents":{"offset":"2693995354","bids":[],"asks":[["4220.1","92.9"]]}}
1635444246.4808729: {"type":"channel_data","connection_id":"60a4fc71-1312-4830-86f4-9eb98be106ac","message_id":2290,"id":"ETH-USD","channel":"v3_orderbook","contents":{"offset":"2693995358","bids":[["4213.3","0"]],"asks":[]}}
1635444246.480957: {"type":"channel_data","connection_id":"60a4fc71-1312-4830-86f4-9eb98be106ac","message_id":2291,"id":"MKR-USD","channel":"v3_orderbook","contents":{"offset":"2693995363","bids":[["2379","36.205"]],"asks":[]}}
1635444246.4809952: {"type":"channel_data","connection_id":"60a4fc71-1312-4830-86f4-9eb98be106ac","message_id":2292,"id":"ETH-USD","channel":"v3_orderbook","contents":{"offset":"2693995360","bids":[],"asks":[["4216.9","58.431"]]}}
1635444246.4814389: {"type":"channel_data","connection_id":"60a4fc71-1312-4830-86f4-9eb98be106ac","message_id":2293,"id":"ETH-USD","channel":"v3_orderbook","contents":{"offset":"2693995356","bids":[["4215.7","0"]],"asks":[]}}
1635444246.4854772: {"type":"channel_data","connection_id":"60a4fc71-1312-4830-86f4-9eb98be106ac","message_id":2294,"id":"LTC-USD","channel":"v3_orderbook","contents":{"offset":"2693995367","bids":[["187.8","886.36"]],"asks":[]}}
1635444246.485547: {"type":"channel_data","connection_id":"60a4fc71-1312-4830-86f4-9eb98be106ac","message_id":2295,"id":"ETH-USD","channel":"v3_orderbook","contents":{"offset":"2693995364","bids":[["4213.9","7.215"]],"asks":[]}}
1635444246.487239: {"type":"channel_data","connection_id":"60a4fc71-1312-4830-86f4-9eb98be106ac","message_id":2296,"id":"ETH-USD","channel":"v3_orderbook","contents":{"offset":"2693995368","bids":[],"asks":[["4218.8","0"]]}}
1635444246.4873018: {"type":"channel_data","connection_id":"60a4fc71-1312-4830-86f4-9eb98be106ac","message_id":2297,"id":"MKR-USD","channel":"v3_orderbook","contents":{"offset":"2693995365","bids":[],"asks":[["2385","90.956"]]}}
1635444246.488331: {"type":"channel_data","connection_id":"60a4fc71-1312-4830-86f4-9eb98be106ac","message_id":2298,"id":"ETH-USD","channel":"v3_orderbook","contents":{"offset":"2693995366","bids":[],"asks":[["4219.3","0.355"]]}}
1635444246.500149: {"type":"channel_data","connection_id":"60a4fc71-1312-4830-86f4-9eb98be106ac","message_id":2299,"id":"ETH-USD","channel":"v3_orderbook","contents":{"offset":"2693995376","bids":[],"asks":[["4217.8","4.3"]]}}
1635444246.5002282: {"type":"channel_data","connection_id":"60a4fc71-1312-4830-86f4-9eb98be106ac","message_id":2300,"id":"SUSHI-USD","channel":"v3_orderbook","contents":{"offset":"2693995373","bids":[["10.789","8452"]],"asks":[]}}
1635444246.500268: {"type":"channel_data","connection_id":"60a4fc71-1312-4830-86f4-9eb98be106ac","message_id":2301,"id":"UMA-USD","channel":"v3_orderbook","contents":{"offset":"2693995374","bids":[],"asks":[["11.33","2957.1"]]}}
1635444246.509192: {"type":"channel_data","connection_id":"60a4fc71-1312-4830-86f4-9eb98be106ac","message_id":2302,"id":"LTC-USD","channel":"v3_orderbook","contents":{"offset":"2693995383","bids":[],"asks":[["188.1","4056.98"]]}}
1635444246.509272: {"type":"channel_data","connection_id":"60a4fc71-1312-4830-86f4-9eb98be106ac","message_id":2303,"id":"SUSHI-USD","channel":"v3_orderbook","contents":{"offset":"2693995386","bids":[["10.792","1475.6"]],"asks":[]}}
1635444246.50931: {"type":"channel_data","connection_id":"60a4fc71-1312-4830-86f4-9eb98be106ac","message_id":2304,"id":"ETH-USD","channel":"v3_orderbook","contents":{"offset":"2693995380","bids":[],"asks":[["4216.6","25.418"]]}}
1635444246.514055: {"type":"channel_data","connection_id":"60a4fc71-1312-4830-86f4-9eb98be106ac","message_id":2305,"id":"LTC-USD","channel":"v3_orderbook","contents":{"offset":"2693995384","bids":[],"asks":[["188.1","4118.45"]]}}
1635444246.514155: {"type":"channel_data","connection_id":"60a4fc71-1312-4830-86f4-9eb98be106ac","message_id":2306,"id":"ETH-USD","channel":"v3_orderbook","contents":{"offset":"2693995381","bids":[["4215","22.496"]],"asks":[]}}
1635444246.514208: {"type":"channel_data","connection_id":"60a4fc71-1312-4830-86f4-9eb98be106ac","message_id":2307,"id":"ETH-USD","channel":"v3_orderbook","contents":{"offset":"2693995382","bids":[],"asks":[["4217.4","48.212"]]}}
1635444246.523778: {"type":"channel_data","connection_id":"60a4fc71-1312-4830-86f4-9eb98be106ac","message_id":2308,"id":"LTC-USD","channel":"v3_orderbook","contents":{"offset":"2693995394","bids":[["187.8","905.47"]],"asks":[]}}
1635444246.5238621: {"type":"channel_data","connection_id":"60a4fc71-1312-4830-86f4-9eb98be106ac","message_id":2309,"id":"LTC-USD","channel":"v3_orderbook","contents":{"offset":"2693995388","bids":[],"asks":[["188.8","935.48"]]}}
1635444246.5238972: {"type":"channel_data","connection_id":"60a4fc71-1312-4830-86f4-9eb98be106ac","message_id":2310,"id":"ETH-USD","channel":"v3_orderbook","contents":{"offset":"2693995392","bids":[],"asks":[["4279.2","1.4"]]}}
1635444246.5242682: {"type":"channel_data","connection_id":"60a4fc71-1312-4830-86f4-9eb98be106ac","message_id":2311,"id":"MKR-USD","channel":"v3_orderbook","contents":{"offset":"2693995393","bids":[],"asks":[["2384","19.362"]]}}
1635444246.5243452: {"type":"channel_data","connection_id":"60a4fc71-1312-4830-86f4-9eb98be106ac","message_id":2312,"id":"ETH-USD","channel":"v3_orderbook","contents":{"offset":"2693995390","bids":[],"asks":[["4219.6","88.38"]]}}
1635444246.524377: {"type":"channel_data","connection_id":"60a4fc71-1312-4830-86f4-9eb98be106ac","message_id":2313,"id":"CRV-USD","channel":"v3_orderbook","contents":{"offset":"2693995396","bids":[["4.848","1737"]],"asks":[]}}
1635444246.5279732: {"type":"channel_data","connection_id":"60a4fc71-1312-4830-86f4-9eb98be106ac","message_id":2314,"id":"ETH-USD","channel":"v3_orderbook","contents":{"offset":"2693995395","bids":[["4213.6","4.3"]],"asks":[]}}
1635444246.528057: {"type":"channel_data","connection_id":"60a4fc71-1312-4830-86f4-9eb98be106ac","message_id":2315,"id":"ETH-USD","channel":"v3_orderbook","contents":{"offset":"2693995398","bids":[["4215.9","464.921"]],"asks":[]}}
1635444246.532035: {"type":"channel_data","connection_id":"60a4fc71-1312-4830-86f4-9eb98be106ac","message_id":2316,"id":"ETH-USD","channel":"v3_orderbook","contents":{"offset":"2693995400","bids":[],"asks":[["4220.5","5622.17"]]}}
1635444246.5326452: {"type":"channel_data","connection_id":"60a4fc71-1312-4830-86f4-9eb98be106ac","message_id":2317,"id":"ETH-USD","channel":"v3_orderbook","contents":{"offset":"2693995401","bids":[["4213.7","7.215"]],"asks":[]}}
1635444246.542637: {"type":"channel_data","connection_id":"60a4fc71-1312-4830-86f4-9eb98be106ac","message_id":2318,"id":"ETH-USD","channel":"v3_orderbook","contents":{"offset":"2693995413","bids":[],"asks":[["4216.7","41.48"]]}}
1635444246.542718: {"type":"channel_data","connection_id":"60a4fc71-1312-4830-86f4-9eb98be106ac","message_id":2319,"id":"ETH-USD","channel":"v3_trades","contents":{"trades":[{"size":"0.03","side":"SELL","price":"4215.9","createdAt":"2021-10-28T18:04:06.569Z"}]}}
1635444246.5457659: {"type":"channel_data","connection_id":"60a4fc71-1312-4830-86f4-9eb98be106ac","message_id":2320,"id":"ETH-USD","channel":"v3_orderbook","contents":{"offset":"2693995417","bids":[["4215.9","449.964"]],"asks":[]}}
1635444246.547928: {"type":"channel_data","connection_id":"60a4fc71-1312-4830-86f4-9eb98be106ac","message_id":2321,"id":"UMA-USD","channel":"v3_orderbook","contents":{"offset":"2693995423","bids":[["11.27","29527.1"]],"asks":[]}}
1635444246.55416: {"type":"channel_data","connection_id":"60a4fc71-1312-4830-86f4-9eb98be106ac","message_id":2322,"id":"ETH-USD","channel":"v3_orderbook","contents":{"offset":"2693995419","bids":[],"asks":[["4217.5","10.659"]]}}
1635444246.554278: {"type":"channel_data","connection_id":"60a4fc71-1312-4830-86f4-9eb98be106ac","message_id":2323,"id":"LTC-USD","channel":"v3_orderbook","contents":{"offset":"2693995431","bids":[["187.4","53228.92"]],"asks":[]}}
1635444246.5543349: {"type":"channel_data","connection_id":"60a4fc71-1312-4830-86f4-9eb98be106ac","message_id":2324,"id":"ETH-USD","channel":"v3_orderbook","contents":{"offset":"2693995414","bids":[],"asks":[["4217.1","0.776"]]}}
1635444246.55438: {"type":"channel_data","connection_id":"60a4fc71-1312-4830-86f4-9eb98be106ac","message_id":2325,"id":"ETH-USD","channel":"v3_orderbook","contents":{"offset":"2693995427","bids":[],"asks":[["4216","3.15"]]}}
1635444246.557106: {"type":"channel_data","connection_id":"60a4fc71-1312-4830-86f4-9eb98be106ac","message_id":2326,"id":"EOS-USD","channel":"v3_orderbook","contents":{"offset":"2693995434","bids":[["4.4","340"]],"asks":[]}}
1635444246.557188: {"type":"channel_data","connection_id":"60a4fc71-1312-4830-86f4-9eb98be106ac","message_id":2327,"id":"UMA-USD","channel":"v3_orderbook","contents":{"offset":"2693995433","bids":[["11.28","11834.1"]],"asks":[]}}
1635444246.566666: {"type":"channel_data","connection_id":"60a4fc71-1312-4830-86f4-9eb98be106ac","message_id":2328,"id":"ETH-USD","channel":"v3_orderbook","contents":{"offset":"2693995437","bids":[],"asks":[["4222.6","0"]]}}
1635444246.5667489: {"type":"channel_data","connection_id":"60a4fc71-1312-4830-86f4-9eb98be106ac","message_id":2329,"id":"ETH-USD","channel":"v3_orderbook","contents":{"offset":"2693995444","bids":[["4214.8","1.691"]],"asks":[]}}
1635444246.566785: {"type":"channel_data","connection_id":"60a4fc71-1312-4830-86f4-9eb98be106ac","message_id":2330,"id":"UNI-USD","channel":"v3_orderbook","contents":{"offset":"2693995442","bids":[],"asks":[["25.065","439.5"]]}}
1635444246.566816: {"type":"channel_data","connection_id":"60a4fc71-1312-4830-86f4-9eb98be106ac","message_id":2331,"id":"ETH-USD","channel":"v3_orderbook","contents":{"offset":"2693995440","bids":[],"asks":[["4217.3","9.784"]]}}
1635444246.566842: {"type":"channel_data","connection_id":"60a4fc71-1312-4830-86f4-9eb98be106ac","message_id":2332,"id":"ETH-USD","channel":"v3_orderbook","contents":{"offset":"2693995441","bids":[],"asks":[["4220.5","0"]]}}
1635444246.566868: {"type":"channel_data","connection_id":"60a4fc71-1312-4830-86f4-9eb98be106ac","message_id":2333,"id":"ETH-USD","channel":"v3_orderbook","contents":{"offset":"2693995450","bids":[],"asks":[["4221.4","0.011"]]}}
1635444246.568931: {"type":"channel_data","connection_id":"60a4fc71-1312-4830-86f4-9eb98be106ac","message_id":2334,"id":"ETH-USD","channel":"v3_orderbook","contents":{"offset":"2693995448","bids":[["4211.2","0"]],"asks":[]}}
1635444246.5690129: {"type":"channel_data","connection_id":"60a4fc71-1312-4830-86f4-9eb98be106ac","message_id":2335,"id":"CRV-USD","channel":"v3_orderbook","contents":{"offset":"2693995445","bids":[["4.85","154"]],"asks":[]}}
1635444246.570411: {"type":"channel_data","connection_id":"60a4fc71-1312-4830-86f4-9eb98be106ac","message_id":2336,"id":"LTC-USD","channel":"v3_orderbook","contents":{"offset":"2693995449","bids":[],"asks":[["188.2","690.28"]]}}
1635444246.570467: {"type":"channel_data","connection_id":"60a4fc71-1312-4830-86f4-9eb98be106ac","message_id":2337,"id":"SUSHI-USD","channel":"v3_orderbook","contents":{"offset":"2693995460","bids":[["10.789","8785.7"]],"asks":[]}}
1635444246.575607: {"type":"channel_data","connection_id":"60a4fc71-1312-4830-86f4-9eb98be106ac","message_id":2338,"id":"EOS-USD","channel":"v3_orderbook","contents":{"offset":"2693995453","bids":[],"asks":[["4.405","9078"]]}}
1635444246.579823: {"type":"channel_data","connection_id":"60a4fc71-1312-4830-86f4-9eb98be106ac","message_id":2339,"id":"BCH-USD","channel":"v3_orderbook","contents":{"offset":"2693995464","bids":[],"asks":[["576.2","1.91"]]}}
1635444246.582365: {"type":"channel_data","connection_id":"60a4fc71-1312-4830-86f4-9eb98be106ac","message_id":2340,"id":"SUSHI-USD","channel":"v3_orderbook","contents":{"offset":"2693995474","bids":[["10.789","8924.6"]],"asks":[]}}
1635444246.5843022: {"type":"channel_data","connection_id":"60a4fc71-1312-4830-86f4-9eb98be106ac","message_id":2341,"id":"EOS-USD","channel":"v3_orderbook","contents":{"offset":"2693995454","bids":[],"asks":[["4.406","1053"]]}}
1635444246.584352: {"type":"channel_data","connection_id":"60a4fc71-1312-4830-86f4-9eb98be106ac","message_id":2342,"id":"BCH-USD","channel":"v3_orderbook","contents":{"offset":"2693995469","bids":[["573.5","1.91"]],"asks":[]}}
1635444246.5865211: {"type":"channel_data","connection_id":"60a4fc71-1312-4830-86f4-9eb98be106ac","message_id":2343,"id":"EOS-USD","channel":"v3_orderbook","contents":{"offset":"2693995479","bids":[["4.401","11320"]],"asks":[]}}
1635444246.586572: {"type":"channel_data","connection_id":"60a4fc71-1312-4830-86f4-9eb98be106ac","message_id":2344,"id":"CRV-USD","channel":"v3_orderbook","contents":{"offset":"2693995475","bids":[],"asks":[["4.86","2302"]]}}
1635444246.59288: {"type":"channel_data","connection_id":"60a4fc71-1312-4830-86f4-9eb98be106ac","message_id":2345,"id":"ETH-USD","channel":"v3_orderbook","contents":{"offset":"2693995473","bids":[],"asks":[["4224.2","0"]]}}
1635444246.592949: {"type":"channel_data","connection_id":"60a4fc71-1312-4830-86f4-9eb98be106ac","message_id":2346,"id":"CRV-USD","channel":"v3_orderbook","contents":{"offset":"2693995483","bids":[["4.848","1118"]],"asks":[]}}
1635444246.592982: {"type":"channel_data","connection_id":"60a4fc71-1312-4830-86f4-9eb98be106ac","message_id":2347,"id":"ETH-USD","channel":"v3_orderbook","contents":{"offset":"2693995492","bids":[["4213.7","0"]],"asks":[]}}
1635444246.595587: {"type":"channel_data","connection_id":"60a4fc71-1312-4830-86f4-9eb98be106ac","message_id":2348,"id":"LTC-USD","channel":"v3_orderbook","contents":{"offset":"2693995487","bids":[["187.5","52.12"]],"asks":[]}}
1635444246.607154: {"type":"channel_data","connection_id":"60a4fc71-1312-4830-86f4-9eb98be106ac","message_id":2349,"id":"ETH-USD","channel":"v3_orderbook","contents":{"offset":"2693995500","bids":[],"asks":[["4216.6","22.496"]]}}
1635444246.607235: {"type":"channel_data","connection_id":"60a4fc71-1312-4830-86f4-9eb98be106ac","message_id":2350,"id":"ETH-USD","channel":"v3_orderbook","contents":{"offset":"2693995493","bids":[["4214","991.949"]],"asks":[]}}
1635444246.60727: {"type":"channel_data","connection_id":"60a4fc71-1312-4830-86f4-9eb98be106ac","message_id":2351,"id":"UNI-USD","channel":"v3_orderbook","contents":{"offset":"2693995489","bids":[],"asks":[["25.062","59.8"]]}}
1635444246.607302: {"type":"channel_data","connection_id":"60a4fc71-1312-4830-86f4-9eb98be106ac","message_id":2352,"id":"UMA-USD","channel":"v3_orderbook","contents":{"offset":"2693995496","bids":[["11.27","29669.9"]],"asks":[]}}
1635444246.60733: {"type":"channel_data","connection_id":"60a4fc71-1312-4830-86f4-9eb98be106ac","message_id":2353,"id":"SUSHI-USD","channel":"v3_orderbook","contents":{"offset":"2693995499","bids":[["10.789","4922.3"]],"asks":[]}}
1635444246.607357: {"type":"channel_data","connection_id":"60a4fc71-1312-4830-86f4-9eb98be106ac","message_id":2354,"id":"ETH-USD","channel":"v3_orderbook","contents":{"offset":"2693995501","bids":[],"asks":[["4216","6.072"]]}}
1635444246.607379: {"type":"channel_data","connection_id":"60a4fc71-1312-4830-86f4-9eb98be106ac","message_id":2355,"id":"ETH-USD","channel":"v3_orderbook","contents":{"offset":"2693995497","bids":[],"asks":[["4218.1","11.777"]]}}
1635444246.607402: {"type":"channel_data","connection_id":"60a4fc71-1312-4830-86f4-9eb98be106ac","message_id":2356,"id":"ETH-USD","channel":"v3_orderbook","contents":{"offset":"2693995504","bids":[["4212.9","7.216"]],"asks":[]}}
1635444246.607423: {"type":"channel_data","connection_id":"60a4fc71-1312-4830-86f4-9eb98be106ac","message_id":2357,"id":"SUSHI-USD","channel":"v3_orderbook","contents":{"offset":"2693995503","bids":[["10.762","262.8"]],"asks":[]}}
1635444246.607446: {"type":"channel_data","connection_id":"60a4fc71-1312-4830-86f4-9eb98be106ac","message_id":2358,"id":"LTC-USD","channel":"v3_orderbook","contents":{"offset":"2693995486","bids":[],"asks":[["188.5","53179.44"]]}}
1635444246.607469: {"type":"channel_data","connection_id":"60a4fc71-1312-4830-86f4-9eb98be106ac","message_id":2359,"id":"BCH-USD","channel":"v3_orderbook","contents":{"offset":"2693995507","bids":[],"asks":[["575.5","5.49"]]}}
1635444246.6074922: {"type":"channel_data","connection_id":"60a4fc71-1312-4830-86f4-9eb98be106ac","message_id":2360,"id":"UMA-USD","channel":"v3_orderbook","contents":{"offset":"2693995516","bids":[["11.27","29404.4"]],"asks":[]}}
1635444246.609374: {"type":"channel_data","connection_id":"60a4fc71-1312-4830-86f4-9eb98be106ac","message_id":2361,"id":"SUSHI-USD","channel":"v3_orderbook","contents":{"offset":"2693995505","bids":[["10.789","472.6"]],"asks":[]}}
1635444246.609417: {"type":"channel_data","connection_id":"60a4fc71-1312-4830-86f4-9eb98be106ac","message_id":2362,"id":"BCH-USD","channel":"v3_orderbook","contents":{"offset":"2693995512","bids":[["574.5","70.16"]],"asks":[]}}
1635444246.61141: {"type":"channel_data","connection_id":"60a4fc71-1312-4830-86f4-9eb98be106ac","message_id":2363,"id":"SUSHI-USD","channel":"v3_orderbook","contents":{"offset":"2693995515","bids":[],"asks":[["10.802","4282.7"]]}}
1635444246.611472: {"type":"channel_data","connection_id":"60a4fc71-1312-4830-86f4-9eb98be106ac","message_id":2364,"id":"ETH-USD","channel":"v3_orderbook","contents":{"offset":"2693995494","bids":[["4211","5625.943"]],"asks":[]}}
1635444246.611507: {"type":"channel_data","connection_id":"60a4fc71-1312-4830-86f4-9eb98be106ac","message_id":2365,"id":"EOS-USD","channel":"v3_orderbook","contents":{"offset":"2693995524","bids":[],"asks":[["4.404","14601"]]}}
1635444246.611914: {"type":"channel_data","connection_id":"60a4fc71-1312-4830-86f4-9eb98be106ac","message_id":2366,"id":"ETH-USD","channel":"v3_orderbook","contents":{"offset":"2693995522","bids":[],"asks":[["4217.5","0.875"]]}}
1635444246.616949: {"type":"channel_data","connection_id":"60a4fc71-1312-4830-86f4-9eb98be106ac","message_id":2367,"id":"ETH-USD","channel":"v3_orderbook","contents":{"offset":"2693995528","bids":[],"asks":[["4216.5","9.783"]]}}
1635444246.617002: {"type":"channel_data","connection_id":"60a4fc71-1312-4830-86f4-9eb98be106ac","message_id":2368,"id":"BCH-USD","channel":"v3_orderbook","contents":{"offset":"2693995527","bids":[["574.1","13871.93"]],"asks":[]}}
1635444246.617036: {"type":"channel_data","connection_id":"60a4fc71-1312-4830-86f4-9eb98be106ac","message_id":2369,"id":"UNI-USD","channel":"v3_orderbook","contents":{"offset":"2693995530","bids":[],"asks":[["25.06","7797.7"]]}}
1635444246.6200728: {"type":"channel_data","connection_id":"60a4fc71-1312-4830-86f4-9eb98be106ac","message_id":2370,"id":"BCH-USD","channel":"v3_orderbook","contents":{"offset":"2693995531","bids":[],"asks":[["575.4","708.46"]]}}
1635444246.6257: {"type":"channel_data","connection_id":"60a4fc71-1312-4830-86f4-9eb98be106ac","message_id":2371,"id":"ETH-USD","channel":"v3_orderbook","contents":{"offset":"2693995540","bids":[["4215.4","58.75"]],"asks":[]}}
1635444246.6257868: {"type":"channel_data","connection_id":"60a4fc71-1312-4830-86f4-9eb98be106ac","message_id":2372,"id":"ETH-USD","channel":"v3_orderbook","contents":{"offset":"2693995529","bids":[],"asks":[["4217.3","0"]]}}
1635444246.629056: {"type":"channel_data","connection_id":"60a4fc71-1312-4830-86f4-9eb98be106ac","message_id":2373,"id":"SUSHI-USD","channel":"v3_orderbook","contents":{"offset":"2693995544","bids":[],"asks":[["10.807","1666.5"]]}}
1635444246.629143: {"type":"channel_data","connection_id":"60a4fc71-1312-4830-86f4-9eb98be106ac","message_id":2374,"id":"ETH-USD","channel":"v3_orderbook","contents":{"offset":"2693995539","bids":[["4214.6","119.571"]],"asks":[]}}
1635444246.6291971: {"type":"channel_data","connection_id":"60a4fc71-1312-4830-86f4-9eb98be106ac","message_id":2375,"id":"SUSHI-USD","channel":"v3_orderbook","contents":{"offset":"2693995533","bids":[],"asks":[["10.807","1961.8"]]}}
1635444246.6292381: {"type":"channel_data","connection_id":"60a4fc71-1312-4830-86f4-9eb98be106ac","message_id":2376,"id":"SUSHI-USD","channel":"v3_orderbook","contents":{"offset":"2693995543","bids":[],"asks":[["10.801","0"]]}}
1635444246.6311722: {"type":"channel_data","connection_id":"60a4fc71-1312-4830-86f4-9eb98be106ac","message_id":2377,"id":"LTC-USD","channel":"v3_orderbook","contents":{"offset":"2693995552","bids":[["187.4","53247.26"]],"asks":[]}}
1635444246.635373: {"type":"channel_data","connection_id":"60a4fc71-1312-4830-86f4-9eb98be106ac","message_id":2378,"id":"SUSHI-USD","channel":"v3_orderbook","contents":{"offset":"2693995541","bids":[["10.79","3706.8"]],"asks":[]}}
1635444246.6383622: {"type":"channel_data","connection_id":"60a4fc71-1312-4830-86f4-9eb98be106ac","message_id":2379,"id":"ETH-USD","channel":"v3_orderbook","contents":{"offset":"2693995556","bids":[],"asks":[["4217.1","12.553"]]}}
1635444246.638459: {"type":"channel_data","connection_id":"60a4fc71-1312-4830-86f4-9eb98be106ac","message_id":2380,"id":"SUSHI-USD","channel":"v3_orderbook","contents":{"offset":"2693995555","bids":[["10.789","138.9"]],"asks":[]}}
1635444246.639034: {"type":"channel_data","connection_id":"60a4fc71-1312-4830-86f4-9eb98be106ac","message_id":2381,"id":"SUSHI-USD","channel":"v3_orderbook","contents":{"offset":"2693995526","bids":[["10.791","0"]],"asks":[]}}
