1635444246.643541: {"type":"channel_data","connection_id":"60a4fc71-1312-4830-86f4-9eb98be106ac","message_id":2382,"id":"SUSHI-USD","channel":"v3_orderbook","contents":{"offset":"2693995557","bids":[],"asks":[["10.81","305.3"]]}}
1635444246.6436281: {"type":"channel_data","connection_id":"60a4fc71-1312-4830-86f4-9eb98be106ac","message_id":2383,"id":"EOS-USD","channel":"v3_orderbook","contents":{"offset":"2693995553","bids":[],"asks":[["4.404","3282"]]}}
1635444246.645513: {"type":"channel_data","connection_id":"60a4fc71-1312-4830-86f4-9eb98be106ac","message_id":2384,"id":"ETH-USD","channel":"v3_orderbook","contents":{"offset":"2693995572","bids":[["4214.6","2.071"]],"asks":[]}}
1635444246.646271: {"type":"channel_data","connection_id":"60a4fc71-1312-4830-86f4-9eb98be106ac","message_id":2385,"id":"ETH-USD","channel":"v3_orderbook","contents":{"offset":"2693995570","bids":[],"asks":[["4223.5","1.304"]]}}
1635444246.651291: {"type":"channel_data","connection_id":"60a4fc71-1312-4830-86f4-9eb98be106ac","message_id":2386,"id":"ETH-USD","channel":"v3_orderbook","contents":{"offset":"2693995571","bids":[["4215.5","22.851"]],"asks":[]}}
1635444246.65136: {"type":"channel_data","connection_id":"60a4fc71-1312-4830-86f4-9eb98be106ac","message_id":2387,"id":"ETH-USD","channel":"v3_orderbook","contents":{"offset":"2693995575","bids":[["4215.4","0"]],"asks":[]}}
1635444246.651396: {"type":"channel_data","connection_id":"60a4fc71-1312-4830-86f4-9eb98be106ac","message_id":2388,"id":"ETH-USD","channel":"v3_orderbook","contents":{"offset":"2693995580","bids":[],"asks":[["4217.3","58.75"]]}}
1635444246.651426: {"type":"channel_data","connection_id":"60a4fc71-1312-4830-86f4-9eb98be106ac","message_id":2389,"id":"ETH-USD","channel":"v3_orderbook","contents":{"offset":"2693995584","bids":[["4213.2","1350.09"]],"asks":[]}}
1635444246.655006: {"type":"channel_data","connection_id":"60a4fc71-1312-4830-86f4-9eb98be106ac","message_id":2390,"id":"EOS-USD","channel":"v3_orderbook","contents":{"offset":"2693995588","bids":[],"asks":[["4.402","403"]]}}
1635444246.6550632: {"type":"channel_data","connection_id":"60a4fc71-1312-4830-86f4-9eb98be106ac","message_id":2391,"id":"BCH-USD","channel":"v3_orderbook","contents":{"offset":"2693995592","bids":[["573.8","92.19"]],"asks":[]}}
1635444246.656935: {"type":"channel_data","connection_id":"60a4fc71-1312-4830-86f4-9eb98be106ac","message_id":2392,"id":"CRV-USD","channel":"v3_orderbook","contents":{"offset":"2693995587","bids":[["4.847","14661"]],"asks":[]}}
1635444246.6593962: {"type":"channel_data","connection_id":"60a4fc71-1312-4830-86f4-9eb98be106ac","message_id":2393,"id":"SUSHI-USD","channel":"v3_orderbook","contents":{"offset":"2693995550","bids":[],"asks":[["10.826","3752.2"]]}}
1635444246.659459: {"type":"channel_data","connection_id":"60a4fc71-1312-4830-86f4-9eb98be106ac","message_id":2394,"id":"CRV-USD","channel":"v3_orderbook","contents":{"offset":"2693995581","bids":[],"asks":[["4.859","618"]]}}
1635444246.659494: {"type":"channel_data","connection_id":"60a4fc71-1312-4830-86f4-9eb98be106ac","message_id":2395,"id":"CRV-USD","channel":"v3_orderbook","contents":{"offset":"2693995591","bids":[["4.852","5820"]],"asks":[]}}
1635444246.663284: {"type":"channel_data","connection_id":"60a4fc71-1312-4830-86f4-9eb98be106ac","message_id":2396,"id":"ETH-USD","channel":"v3_orderbook","contents":{"offset":"2693995558","bids":[["4213.2","1408.84"]],"asks":[]}}
1635444246.663878: {"type":"channel_data","connection_id":"60a4fc71-1312-4830-86f4-9eb98be106ac","message_id":2397,"id":"ETH-USD","channel":"v3_orderbook","contents":{"offset":"2693995599","bids":[],"asks":[["4217.3","0"]]}}
1635444246.669751: {"type":"channel_data","connection_id":"60a4fc71-1312-4830-86f4-9eb98be106ac","message_id":2398,"id":"ETH-USD","channel":"v3_orderbook","contents":{"offset":"2693995593","bids":[],"asks":[["4220","3.372"]]}}
1635444246.669827: {"type":"channel_data","connection_id":"60a4fc71-1312-4830-86f4-9eb98be106ac","message_id":2399,"id":"SUSHI-USD","channel":"v3_orderbook","contents":{"offset":"2693995607","bids":[["10.784","17445.5"]],"asks":[]}}
1635444246.669866: {"type":"channel_data","connection_id":"60a4fc71-1312-4830-86f4-9eb98be106ac","message_id":2400,"id":"EOS-USD","channel":"v3_orderbook","contents":{"offset":"2693995616","bids":[],"asks":[["4.404","4418"]]}}
1635444246.67272: {"type":"channel_data","connection_id":"60a4fc71-1312-4830-86f4-9eb98be106ac","message_id":2401,"id":"LTC-USD","channel":"v3_orderbook","contents":{"offset":"2693995601","bids":[["187.3","207.22"]],"asks":[]}}
1635444246.6727731: {"type":"channel_data","connection_id":"60a4fc71-1312-4830-86f4-9eb98be106ac","message_id":2402,"id":"SUSHI-USD","channel":"v3_orderbook","contents":{"offset":"2693995574","bids":[],"asks":[["10.81","0"]]}}
1635444246.677483: {"type":"channel_data","connection_id":"60a4fc71-1312-4830-86f4-9eb98be106ac","message_id":2403,"id":"UMA-USD","channel":"v3_orderbook","contents":{"offset":"2693995609","bids":[],"asks":[["11.32","10966.1"]]}}
1635444246.681052: {"type":"channel_data","connection_id":"60a4fc71-1312-4830-86f4-9eb98be106ac","message_id":2404,"id":"EOS-USD","channel":"v3_orderbook","contents":{"offset":"2693995626","bids":[["4.4","1476"]],"asks":[]}}
1635444246.681113: {"type":"channel_data","connection_id":"60a4fc71-1312-4830-86f4-9eb98be106ac","message_id":2405,"id":"UMA-USD","channel":"v3_orderbook","contents":{"offset":"2693995623","bids":[],"asks":[["11.33","7363.2"]]}}
1635444246.689985: {"type":"channel_data","connection_id":"60a4fc71-1312-4830-86f4-9eb98be106ac","message_id":2406,"id":"SUSHI-USD","channel":"v3_orderbook","contents":{"offset":"2693995621","bids":[],"asks":[["10.802","579.6"]]}}
1635444246.690038: {"type":"channel_data","connection_id":"60a4fc71-1312-4830-86f4-9eb98be106ac","message_id":2407,"id":"BCH-USD","channel":"v3_orderbook","contents":{"offset":"2693995635","bids":[],"asks":[["575.1","130.04"]]}}
1635444246.690067: {"type":"channel_data","connection_id":"60a4fc71-1312-4830-86f4-9eb98be106ac","message_id":2408,"id":"ETH-USD","channel":"v3_orderbook","contents":{"offset":"2693995590","bids":[["4215.9","393.739"]],"asks":[]}}
1635444246.690091: {"type":"channel_data","connection_id":"60a4fc71-1312-4830-86f4-9eb98be106ac","message_id":2409,"id":"EOS-USD","channel":"v3_orderbook","contents":{"offset":"2693995640","bids":[["4.401","0"]],"asks":[]}}
1635444246.691067: {"type":"channel_data","connection_id":"60a4fc71-1312-4830-86f4-9eb98be106ac","message_id":2410,"id":"EOS-USD","channel":"v3_orderbook","contents":{"offset":"2693995643","bids":[],"asks":[["4.407","1553"]]}}
1635444246.691116: {"type":"channel_data","connection_id":"60a4fc71-1312-4830-86f4-9eb98be106ac","message_id":2411,"id":"BCH-USD","channel":"v3_orderbook","contents":{"offset":"2693995648","bids":[["574.8","180.09"]],"asks":[]}}
1635444246.695004: {"type":"channel_data","connection_id":"60a4fc71-1312-4830-86f4-9eb98be106ac","message_id":2412,"id":"ETH-USD","channel":"v3_orderbook","contents":{"offset":"2693995633","bids":[["4214.5","0"]],"asks":[]}}
1635444246.6950788: {"type":"channel_data","connection_id":"60a4fc71-1312-4830-86f4-9eb98be106ac","message_id":2413,"id":"ETH-USD","channel":"v3_orderbook","contents":{"offset":"2693995652","bids":[],"asks":[["4217.4","45.29"]]}}
1635444246.695127: {"type":"channel_data","connection_id":"60a4fc71-1312-4830-86f4-9eb98be106ac","message_id":2414,"id":"UMA-USD","channel":"v3_orderbook","contents":{"offset":"2693995651","bids":[],"asks":[["11.33","29466.3"]]}}
1635444246.697162: {"type":"channel_data","connection_id":"60a4fc71-1312-4830-86f4-9eb98be106ac","message_id":2415,"id":"ETH-USD","channel":"v3_orderbook","contents":{"offset":"2693995655","bids":[],"asks":[["4216","63.832"]]}}
1635444246.698598: {"type":"channel_data","connection_id":"60a4fc71-1312-4830-86f4-9eb98be106ac","message_id":2416,"id":"EOS-USD","channel":"v3_orderbook","contents":{"offset":"2693995641","bids":[["4.399","0"]],"asks":[]}}
1635444246.7016802: {"type":"channel_data","connection_id":"60a4fc71-1312-4830-86f4-9eb98be106ac","message_id":2417,"id":"UMA-USD","channel":"v3_orderbook","contents":{"offset":"2693995659","bids":[],"asks":[["11.33","25060.2"]]}}
1635444246.704499: {"type":"channel_data","connection_id":"60a4fc71-1312-4830-86f4-9eb98be106ac","message_id":2418,"id":"ETH-USD","channel":"v3_orderbook","contents":{"offset":"2693995663","bids":[],"asks":[["4216.9","0"]]}}
1635444246.704581: {"type":"channel_data","connection_id":"60a4fc71-1312-4830-86f4-9eb98be106ac","message_id":2419,"id":"SUSHI-USD","channel":"v3_orderbook","contents":{"offset":"2693995668","bids":[],"asks":[["10.804","153.9"]]}}
1635444246.7063758: {"type":"channel_data","connection_id":"60a4fc71-1312-4830-86f4-9eb98be106ac","message_id":2420,"id":"ETH-USD","channel":"v3_orderbook","contents":{"offset":"2693995666","bids":[],"asks":[["4217.1","1422.443"]]}}
1635444246.707553: {"type":"channel_data","connection_id":"60a4fc71-1312-4830-86f4-9eb98be106ac","message_id":2421,"id":"SUSHI-USD","channel":"v3_orderbook","contents":{"offset":"2693995671","bids":[["10.79","0"]],"asks":[]}}
1635444246.7094588: {"type":"channel_data","connection_id":"60a4fc71-1312-4830-86f4-9eb98be106ac","message_id":2422,"id":"CRV-USD","channel":"v3_orderbook","contents":{"offset":"2693995674","bids":[["4.846","551"]],"asks":[]}}
1635444246.7321332: {"type":"channel_data","connection_id":"60a4fc71-1312-4830-86f4-9eb98be106ac","message_id":2423,"id":"UNI-USD","channel":"v3_orderbook","contents":{"offset":"2693995665","bids":[],"asks":[["25.06","0"]]}}
1635444246.732212: {"type":"channel_data","connection_id":"60a4fc71-1312-4830-86f4-9eb98be106ac","message_id":2424,"id":"ETH-USD","channel":"v3_orderbook","contents":{"offset":"2693995675","bids":[],"asks":[["4216.9","0.355"]]}}
1635444246.7322502: {"type":"channel_data","connection_id":"60a4fc71-1312-4830-86f4-9eb98be106ac","message_id":2425,"id":"UNI-USD","channel":"v3_orderbook","contents":{"offset":"2693995682","bids":[["25.034","0"]],"asks":[]}}
1635444246.7322822: {"type":"channel_data","connection_id":"60a4fc71-1312-4830-86f4-9eb98be106ac","message_id":2426,"id":"SUSHI-USD","channel":"v3_orderbook","contents":{"offset":"2693995669","bids":[["10.784","4002.3"]],"asks":[]}}
1635444246.73231: {"type":"channel_data","connection_id":"60a4fc71-1312-4830-86f4-9eb98be106ac","message_id":2427,"id":"ETH-USD","channel":"v3_orderbook","contents":{"offset":"2693995690","bids":[["4215","46.237"]],"asks":[]}}
1635444246.7323341: {"type":"channel_data","connection_id":"60a4fc71-1312-4830-86f4-9eb98be106ac","message_id":2428,"id":"ETH-USD","channel":"v3_orderbook","contents":{"offset":"2693995677","bids":[["4213.9","0"]],"asks":[]}}
1635444246.732359: {"type":"channel_data","connection_id":"60a4fc71-1312-4830-86f4-9eb98be106ac","message_id":2429,"id":"ETH-USD","channel":"v3_orderbook","contents":{"offset":"2693995692","bids":[["4215.9","388.932"]],"asks":[]}}
1635444246.732382: {"type":"channel_data","connection_id":"60a4fc71-1312-4830-86f4-9eb98be106ac","message_id":2430,"id":"BCH-USD","channel":"v3_orderbook","contents":{"offset":"2693995696","bids":[["574.7","131.81"]],"asks":[]}}
1635444246.732405: {"type":"channel_data","connection_id":"60a4fc71-1312-4830-86f4-9eb98be106ac","message_id":2431,"id":"ETH-USD","channel":"v3_orderbook","contents":{"offset":"2693995695","bids":[],"asks":[["4216","81.492"]]}}
1635444246.732426: {"type":"channel_data","connection_id":"60a4fc71-1312-4830-86f4-9eb98be106ac","message_id":2432,"id":"BCH-USD","channel":"v3_orderbook","contents":{"offset":"2693995700","bids":[["574.5","763.86"]],"asks":[]}}
1635444246.732448: {"type":"channel_data","connection_id":"60a4fc71-1312-4830-86f4-9eb98be106ac","message_id":2433,"id":"LTC-USD","channel":"v3_orderbook","contents":{"offset":"2693995703","bids":[],"asks":[["188.3","42737.52"]]}}
1635444246.7324722: {"type":"channel_data","connection_id":"60a4fc71-1312-4830-86f4-9eb98be106ac","message_id":2434,"id":"ETH-USD","channel":"v3_orderbook","contents":{"offset":"2693995693","bids":[["4208.5","92.52"]],"asks":[]}}
1635444246.732494: {"type":"channel_data","connection_id":"60a4fc71-1312-4830-86f4-9eb98be106ac","message_id":2435,"id":"CRV-USD","channel":"v3_orderbook","contents":{"offset":"2693995704","bids":[],"asks":[["4.859","5561"]]}}
1635444246.732518: {"type":"channel_data","connection_id":"60a4fc71-1312-4830-86f4-9eb98be106ac","message_id":2436,"id":"LTC-USD","channel":"v3_orderbook","contents":{"offset":"2693995711","bids":[["187.7","42684.35"]],"asks":[]}}
1635444246.735734: {"type":"channel_data","connection_id":"60a4fc71-1312-4830-86f4-9eb98be106ac","message_id":2437,"id":"EOS-USD","channel":"v3_orderbook","contents":{"offset":"2693995707","bids":[],"asks":[["4.403","0"]]}}
1635444246.735797: {"type":"channel_data","connection_id":"60a4fc71-1312-4830-86f4-9eb98be106ac","message_id":2438,"id":"UMA-USD","channel":"v3_orderbook","contents":{"offset":"2693995712","bids":[],"asks":[["11.32","10825.2"]]}}
1635444246.738928: {"type":"channel_data","connection_id":"60a4fc71-1312-4830-86f4-9eb98be106ac","message_id":2439,"id":"BCH-USD","channel":"v3_orderbook","contents":{"offset":"2693995697","bids":[["574.8","215.15"]],"asks":[]}}
1635444246.73898: {"type":"channel_data","connection_id":"60a4fc71-1312-4830-86f4-9eb98be106ac","message_id":2440,"id":"ETH-USD","channel":"v3_orderbook","contents":{"offset":"2693995709","bids":[["4210.1","2.03"]],"asks":[]}}
1635444246.739007: {"type":"channel_data","connection_id":"60a4fc71-1312-4830-86f4-9eb98be106ac","message_id":2441,"id":"SUSHI-USD","channel":"v3_orderbook","contents":{"offset":"2693995706","bids":[["10.792","1209.2"]],"asks":[]}}
1635444246.744329: {"type":"channel_data","connection_id":"60a4fc71-1312-4830-86f4-9eb98be106ac","message_id":2442,"id":"BCH-USD","channel":"v3_orderbook","contents":{"offset":"2693995716","bids":[["574.6","418.69"]],"asks":[]}}
1635444246.7487712: {"type":"channel_data","connection_id":"60a4fc71-1312-4830-86f4-9eb98be106ac","message_id":2443,"id":"CRV-USD","channel":"v3_orderbook","contents":{"offset":"2693995678","bids":[["4.847","13980"]],"asks":[]}}
1635444246.7488341: {"type":"channel_data","connection_id":"60a4fc71-1312-4830-86f4-9eb98be106ac","message_id":2444,"id":"UMA-USD","channel":"v3_orderbook","contents":{"offset":"2693995743","bids":[],"asks":[["11.31","13584.7"]]}}
1635444246.7511392: {"type":"channel_data","connection_id":"60a4fc71-1312-4830-86f4-9eb98be106ac","message_id":2445,"id":"ETH-USD","channel":"v3_orderbook","contents":{"offset":"2693995744","bids":[],"asks":[["4220.9","0"]]}}
1635444246.7534301: {"type":"channel_data","connection_id":"60a4fc71-1312-4830-86f4-9eb98be106ac","message_id":2446,"id":"UNI-USD","channel":"v3_orderbook","contents":{"offset":"2693995730","bids":[["24.882","0"],["24.879","1997.7"]],"asks":[]}}
1635444246.75719: {"type":"channel_data","connection_id":"60a4fc71-1312-4830-86f4-9eb98be106ac","message_id":2447,"id":"SUSHI-USD","channel":"v3_orderbook","contents":{"offset":"2693995740","bids":[["10.789","0"]],"asks":[]}}
1635444246.757248: {"type":"channel_data","connection_id":"60a4fc71-1312-4830-86f4-9eb98be106ac","message_id":2448,"id":"CRV-USD","channel":"v3_orderbook","contents":{"offset":"2693995747","bids":[],"asks":[["4.86","1710"]]}}
1635444246.7572858: {"type":"channel_data","connection_id":"60a4fc71-1312-4830-86f4-9eb98be106ac","message_id":2449,"id":"CRV-USD","channel":"v3_orderbook","contents":{"offset":"2693995729","bids":[],"asks":[["4.856","171"]]}}
1635444246.757317: {"type":"channel_data","connection_id":"60a4fc71-1312-4830-86f4-9eb98be106ac","message_id":2450,"id":"EOS-USD","channel":"v3_orderbook","contents":{"offset":"2693995759","bids":[["4.397","37241"]],"asks":[]}}
1635444246.759181: {"type":"channel_data","connection_id":"60a4fc71-1312-4830-86f4-9eb98be106ac","message_id":2451,"id":"CRV-USD","channel":"v3_orderbook","contents":{"offset":"2693995752","bids":[],"asks":[["4.859","4943"]]}}
1635444246.762157: {"type":"channel_data","connection_id":"60a4fc71-1312-4830-86f4-9eb98be106ac","message_id":2452,"id":"LTC-USD","channel":"v3_orderbook","contents":{"offset":"2693995748","bids":[["185.5","0"]],"asks":[]}}
1635444246.764999: {"type":"channel_data","connection_id":"60a4fc71-1312-4830-86f4-9eb98be106ac","message_id":2453,"id":"CRV-USD","channel":"v3_orderbook","contents":{"offset":"2693995746","bids":[],"asks":[["4.862","0"]]}}
1635444246.765055: {"type":"channel_data","connection_id":"60a4fc71-1312-4830-86f4-9eb98be106ac","message_id":2454,"id":"ETH-USD","channel":"v3_orderbook","contents":{"offset":"2693995767","bids":[],"asks":[["4216.2","117.48"]]}}
1635444246.7650912: {"type":"channel_data","connection_id":"60a4fc71-1312-4830-86f4-9eb98be106ac","message_id":2455,"id":"EOS-USD","channel":"v3_orderbook","contents":{"offset":"2693995702","bids":[["4.399","1137"]],"asks":[]}}
1635444246.7651231: {"type":"channel_data","connection_id":"60a4fc71-1312-4830-86f4-9eb98be106ac","message_id":2456,"id":"ETH-USD","channel":"v3_orderbook","contents":{"offset":"2693995763","bids":[],"asks":[["4216","105.229"]]}}
1635444246.767018: {"type":"channel_data","connection_id":"60a4fc71-1312-4830-86f4-9eb98be106ac","message_id":2457,"id":"EOS-USD","channel":"v3_orderbook","contents":{"offset":"2693995757","bids":[],"asks":[["4.405","10215"]]}}
1635444246.7703512: {"type":"channel_data","connection_id":"60a4fc71-1312-4830-86f4-9eb98be106ac","message_id":2458,"id":"ETH-USD","channel":"v3_orderbook","contents":{"offset":"2693995768","bids":[],"asks":[["4218.9","87.56"]]}}
1635444246.770396: {"type":"channel_data","connection_id":"60a4fc71-1312-4830-86f4-9eb98be106ac","message_id":2459,"id":"UNI-USD","channel":"v3_orderbook","contents":{"offset":"2693995710","bids":[["24.869","0"],["24.866","998.8"]],"asks":[]}}
1635444246.770432: {"type":"channel_data","connection_id":"60a4fc71-1312-4830-86f4-9eb98be106ac","message_id":2460,"id":"ETH-USD","channel":"v3_orderbook","contents":{"offset":"2693995762","bids":[["4213.1","47.481"]],"asks":[]}}
1635444246.771424: {"type":"channel_data","connection_id":"60a4fc71-1312-4830-86f4-9eb98be106ac","message_id":2461,"id":"ETH-USD","channel":"v3_orderbook","contents":{"offset":"2693995765","bids":[],"asks":[["4216.5","0"]]}}
1635444246.77379: {"type":"channel_data","connection_id":"60a4fc71-1312-4830-86f4-9eb98be106ac","message_id":2462,"id":"ETH-USD","channel":"v3_orderbook","contents":{"offset":"2693995776","bids":[],"asks":[["4222.1","4.696"]]}}
1635444246.779405: {"type":"channel_data","connection_id":"60a4fc71-1312-4830-86f4-9eb98be106ac","message_id":2463,"id":"BCH-USD","channel":"v3_orderbook","contents":{"offset":"2693995778","bids":[],"asks":[["575.1","135.27"]]}}
1635444246.779488: {"type":"channel_data","connection_id":"60a4fc71-1312-4830-86f4-9eb98be106ac","message_id":2464,"id":"ETH-USD","channel":"v3_orderbook","contents":{"offset":"2693995726","bids":[["4213.6","0"]],"asks":[]}}
1635444246.7847612: {"type":"channel_data","connection_id":"60a4fc71-1312-4830-86f4-9eb98be106ac","message_id":2465,"id":"EOS-USD","channel":"v3_orderbook","contents":{"offset":"2693995791","bids":[["4.395","9078"]],"asks":[]}}
1635444246.7848132: {"type":"channel_data","connection_id":"60a4fc71-1312-4830-86f4-9eb98be106ac","message_id":2466,"id":"ETH-USD","channel":"v3_orderbook","contents":{"offset":"2693995780","bids":[],"asks":[["4216","117.006"]]}}
1635444246.784841: {"type":"channel_data","connection_id":"60a4fc71-1312-4830-86f4-9eb98be106ac","message_id":2467,"id":"ETH-USD","channel":"v3_orderbook","contents":{"offset":"2693995769","bids":[["4212.9","0"]],"asks":[]}}
1635444246.784866: {"type":"channel_data","connection_id":"60a4fc71-1312-4830-86f4-9eb98be106ac","message_id":2468,"id":"UMA-USD","channel":"v3_orderbook","contents":{"offset":"2693995792","bids":[["11.27","29669.9"]],"asks":[]}}
1635444246.784888: {"type":"channel_data","connection_id":"60a4fc71-1312-4830-86f4-9eb98be106ac","message_id":2469,"id":"UNI-USD","channel":"v3_orderbook","contents":{"offset":"2693995799","bids":[["24.907","7502"],["24.904","1997.7"]],"asks":[]}}
1635444246.788498: {"type":"channel_data","connection_id":"60a4fc71-1312-4830-86f4-9eb98be106ac","message_id":2470,"id":"ETH-USD","channel":"v3_orderbook","contents":{"offset":"2693995742","bids":[],"asks":[["4218","3.168"]]}}
1635444246.791554: {"type":"channel_data","connection_id":"60a4fc71-1312-4830-86f4-9eb98be106ac","message_id":2471,"id":"EOS-USD","channel":"v3_orderbook","contents":{"offset":"2693995809","bids":[],"asks":[["4.417","249"],["4.418","842"]]}}
1635444246.795809: {"type":"channel_data","connection_id":"60a4fc71-1312-4830-86f4-9eb98be106ac","message_id":2472,"id":"ETH-USD","channel":"v3_orderbook","contents":{"offset":"2693995806","bids":[["4212.5","63.52"]],"asks":[]}}
1635444246.804053: {"type":"channel_data","connection_id":"60a4fc71-1312-4830-86f4-9eb98be106ac","message_id":2473,"id":"CRV-USD","channel":"v3_orderbook","contents":{"offset":"2693995817","bids":[],"asks":[["4.858","4943"]]}}
1635444246.804149: {"type":"channel_data","connection_id":"60a4fc71-1312-4830-86f4-9eb98be106ac","message_id":2474,"id":"SUSHI-USD","channel":"v3_orderbook","contents":{"offset":"2693995811","bids":[["10.787","0"]],"asks":[]}}
1635444246.804205: {"type":"channel_data","connection_id":"60a4fc71-1312-4830-86f4-9eb98be106ac","message_id":2475,"id":"SUSHI-USD","channel":"v3_orderbook","contents":{"offset":"2693995819","bids":[],"asks":[["10.805","0"]]}}
1635444246.8092842: {"type":"channel_data","connection_id":"60a4fc71-1312-4830-86f4-9eb98be106ac","message_id":2476,"id":"SUSHI-USD","channel":"v3_orderbook","contents":{"offset":"2693995818","bids":[],"asks":[["10.888","0"]]}}
1635444246.81514: {"type":"channel_data","connection_id":"60a4fc71-1312-4830-86f4-9eb98be106ac","message_id":2477,"id":"SUSHI-USD","channel":"v3_orderbook","contents":{"offset":"2693995782","bids":[["10.787","4581.1"]],"asks":[]}}
1635444246.820375: {"type":"channel_data","connection_id":"60a4fc71-1312-4830-86f4-9eb98be106ac","message_id":2478,"id":"SUSHI-USD","channel":"v3_orderbook","contents":{"offset":"2693995822","bids":[],"asks":[["10.808","0"]]}}
1635444246.820458: {"type":"channel_data","connection_id":"60a4fc71-1312-4830-86f4-9eb98be106ac","message_id":2479,"id":"ETH-USD","channel":"v3_orderbook","contents":{"offset":"2693995828","bids":[],"asks":[["4216.6","81.256"]]}}
1635444246.828832: {"type":"channel_data","connection_id":"60a4fc71-1312-4830-86f4-9eb98be106ac","message_id":2480,"id":"EOS-USD","channel":"v3_orderbook","contents":{"offset":"2693995836","bids":[],"asks":[["4.403","11322"]]}}
1635444246.8289149: {"type":"channel_data","connection_id":"60a4fc71-1312-4830-86f4-9eb98be106ac","message_id":2481,"id":"UMA-USD","channel":"v3_orderbook","contents":{"offset":"2693995834","bids":[["11.27","29404.4"]],"asks":[]}}
1635444246.830883: {"type":"channel_data","connection_id":"60a4fc71-1312-4830-86f4-9eb98be106ac","message_id":2482,"id":"MKR-USD","channel":"v3_orderbook","contents":{"offset":"2693995843","bids":[["2380","28.716"]],"asks":[]}}
1635444246.830951: {"type":"channel_data","connection_id":"60a4fc71-1312-4830-86f4-9eb98be106ac","message_id":2483,"id":"UNI-USD","channel":"v3_orderbook","contents":{"offset":"2693995838","bids":[["25.027","0"]],"asks":[]}}
1635444246.8388638: {"type":"channel_data","connection_id":"60a4fc71-1312-4830-86f4-9eb98be106ac","message_id":2484,"id":"ETH-USD","channel":"v3_orderbook","contents":{"offset":"2693995848","bids":[["4212.4","60.789"]],"asks":[]}}
1635444246.838927: {"type":"channel_data","connection_id":"60a4fc71-1312-4830-86f4-9eb98be106ac","message_id":2485,"id":"ETH-USD","channel":"v3_orderbook","contents":{"offset":"2693995845","bids":[],"asks":[["4216.1","135.353"]]}}
1635444246.84115: {"type":"channel_data","connection_id":"60a4fc71-1312-4830-86f4-9eb98be106ac","message_id":2486,"id":"SUSHI-USD","channel":"v3_orderbook","contents":{"offset":"2693995852","bids":[],"asks":[["10.799","4581.1"]]}}
1635444246.841205: {"type":"channel_data","connection_id":"60a4fc71-1312-4830-86f4-9eb98be106ac","message_id":2487,"id":"UNI-USD","channel":"v3_orderbook","contents":{"offset":"2693995856","bids":[],"asks":[["25.057","2924.9"]]}}
1635444246.841234: {"type":"channel_data","connection_id":"60a4fc71-1312-4830-86f4-9eb98be106ac","message_id":2488,"id":"UNI-USD","channel":"v3_orderbook","contents":{"offset":"2693995850","bids":[],"asks":[["25.054","7799.6"]]}}
1635444246.844725: {"type":"channel_data","connection_id":"60a4fc71-1312-4830-86f4-9eb98be106ac","message_id":2489,"id":"ETH-USD","channel":"v3_orderbook","contents":{"offset":"2693995854","bids":[],"asks":[["4220.9","11.76"]]}}
1635444246.864149: {"type":"channel_data","connection_id":"60a4fc71-1312-4830-86f4-9eb98be106ac","message_id":2490,"id":"SUSHI-USD","channel":"v3_orderbook","contents":{"offset":"2693995867","bids":[["10.788","4766.5"]],"asks":[]}}
1635444246.864264: {"type":"channel_data","connection_id":"60a4fc71-1312-4830-86f4-9eb98be106ac","message_id":2491,"id":"UNI-USD","channel":"v3_orderbook","contents":{"offset":"2693995857","bids":[["25.028","2924.9"]],"asks":[]}}
1635444246.86432: {"type":"channel_data","connection_id":"60a4fc71-1312-4830-86f4-9eb98be106ac","message_id":2492,"id":"ETH-USD","channel":"v3_orderbook","contents":{"offset":"2693995862","bids":[["4212.2","1917.105"]],"asks":[]}}
1635444246.866786: {"type":"channel_data","connection_id":"60a4fc71-1312-4830-86f4-9eb98be106ac","message_id":2493,"id":"SUSHI-USD","channel":"v3_orderbook","contents":{"offset":"2693995865","bids":[],"asks":[["10.799","0"]]}}
1635444246.8684878: {"type":"channel_data","connection_id":"60a4fc71-1312-4830-86f4-9eb98be106ac","message_id":2494,"id":"ETH-USD","channel":"v3_orderbook","contents":{"offset":"2693995873","bids":[],"asks":[["4216","127.717"]]}}
1635444246.868547: {"type":"channel_data","connection_id":"60a4fc71-1312-4830-86f4-9eb98be106ac","message_id":2495,"id":"ETH-USD","channel":"v3_orderbook","contents":{"offset":"2693995876","bids":[["4214.7","0"]],"asks":[]}}
1635444246.868583: {"type":"channel_data","connection_id":"60a4fc71-1312-4830-86f4-9eb98be106ac","message_id":2496,"id":"SUSHI-USD","channel":"v3_orderbook","contents":{"offset":"2693995868","bids":[["10.769","458084.2"]],"asks":[]}}
1635444246.8711941: {"type":"channel_data","connection_id":"60a4fc71-1312-4830-86f4-9eb98be106ac","message_id":2497,"id":"SUSHI-USD","channel":"v3_orderbook","contents":{"offset":"2693995870","bids":[],"asks":[["10.819","458222"]]}}
1635444246.871239: {"type":"channel_data","connection_id":"60a4fc71-1312-4830-86f4-9eb98be106ac","message_id":2498,"id":"UMA-USD","channel":"v3_orderbook","contents":{"offset":"2693995875","bids":[["11.27","29261.6"]],"asks":[]}}
1635444246.871268: {"type":"channel_data","connection_id":"60a4fc71-1312-4830-86f4-9eb98be106ac","message_id":2499,"id":"EOS-USD","channel":"v3_orderbook","contents":{"offset":"2693995847","bids":[["4.4","12799"]],"asks":[]}}
1635444246.87938: {"type":"channel_data","connection_id":"60a4fc71-1312-4830-86f4-9eb98be106ac","message_id":2500,"id":"ETH-USD","channel":"v3_orderbook","contents":{"offset":"2693995878","bids":[["4214.8","0"]],"asks":[]}}
1635444246.8794398: {"type":"channel_data","connection_id":"60a4fc71-1312-4830-86f4-9eb98be106ac","message_id":2501,"id":"UNI-USD","channel":"v3_orderbook","contents":{"offset":"2693995886","bids":[["25.033","15596.2"]],"asks":[]}}
1635444246.879478: {"type":"channel_data","connection_id":"60a4fc71-1312-4830-86f4-9eb98be106ac","message_id":2502,"id":"ETH-USD","channel":"v3_orderbook","contents":{"offset":"2693995888","bids":[["4196","0"],["4194.5","11.852"]],"asks":[]}}
1635444246.885005: {"type":"channel_data","connection_id":"60a4fc71-1312-4830-86f4-9eb98be106ac","message_id":2503,"id":"SUSHI-USD","channel":"v3_orderbook","contents":{"offset":"2693995887","bids":[],"asks":[["10.795","4581.6"]]}}
1635444246.885122: {"type":"channel_data","connection_id":"60a4fc71-1312-4830-86f4-9eb98be106ac","message_id":2504,"id":"LTC-USD","channel":"v3_orderbook","contents":{"offset":"2693995891","bids":[["187.9","2518.23"]],"asks":[]}}
1635444246.88518: {"type":"channel_data","connection_id":"60a4fc71-1312-4830-86f4-9eb98be106ac","message_id":2505,"id":"ETH-USD","channel":"v3_orderbook","contents":{"offset":"2693995863","bids":[],"asks":[["4223.7","0"]]}}
1635444246.88523: {"type":"channel_data","connection_id":"60a4fc71-1312-4830-86f4-9eb98be106ac","message_id":2506,"id":"SUSHI-USD","channel":"v3_orderbook","contents":{"offset":"2693995894","bids":[["10.736","0"],["10.734","3247.6"]],"asks":[]}}
1635444246.8856478: {"type":"channel_data","connection_id":"60a4fc71-1312-4830-86f4-9eb98be106ac","message_id":2507,"id":"SUSHI-USD","channel":"v3_orderbook","contents":{"offset":"2693995901","bids":[["10.769","110.8"]],"asks":[]}}
1635444246.885695: {"type":"channel_data","connection_id":"60a4fc71-1312-4830-86f4-9eb98be106ac","message_id":2508,"id":"EOS-USD","channel":"v3_orderbook","contents":{"offset":"2693995898","bids":[],"asks":[["4.406","35022"]]}}
1635444246.885726: {"type":"channel_data","connection_id":"60a4fc71-1312-4830-86f4-9eb98be106ac","message_id":2509,"id":"ETH-USD","channel":"v3_orderbook","contents":{"offset":"2693995900","bids":[["4212.5","56.304"]],"asks":[]}}
1635444246.902694: {"type":"channel_data","connection_id":"60a4fc71-1312-4830-86f4-9eb98be106ac","message_id":2510,"id":"CRV-USD","channel":"v3_orderbook","contents":{"offset":"2693995899","bids":[["4.818","947"],["4.817","16713"]],"asks":[]}}
1635444246.902784: {"type":"channel_data","connection_id":"60a4fc71-1312-4830-86f4-9eb98be106ac","message_id":2511,"id":"UMA-USD","channel":"v3_orderbook","contents":{"offset":"2693995895","bids":[],"asks":[["11.33","29466.7"]]}}
1635444246.902826: {"type":"channel_data","connection_id":"60a4fc71-1312-4830-86f4-9eb98be106ac","message_id":2512,"id":"ETH-USD","channel":"v3_orderbook","contents":{"offset":"2693995872","bids":[],"asks":[["4216","122.942"]]}}
1635444246.902855: {"type":"channel_data","connection_id":"60a4fc71-1312-4830-86f4-9eb98be106ac","message_id":2513,"id":"ETH-USD","channel":"v3_orderbook","contents":{"offset":"2693995902","bids":[],"asks":[["4216","132.524"]]}}
1635444246.902881: {"type":"channel_data","connection_id":"60a4fc71-1312-4830-86f4-9eb98be106ac","message_id":2514,"id":"SUSHI-USD","channel":"v3_orderbook","contents":{"offset":"2693995906","bids":[["10.72","0"],["10.718","5123"]],"asks":[]}}
1635444246.9029171: {"type":"channel_data","connection_id":"60a4fc71-1312-4830-86f4-9eb98be106ac","message_id":2515,"id":"ETH-USD","channel":"v3_orderbook","contents":{"offset":"2693995909","bids":[["4212.4","68.005"]],"asks":[]}}
1635444246.9029498: {"type":"channel_data","connection_id":"60a4fc71-1312-4830-86f4-9eb98be106ac","message_id":2516,"id":"SUSHI-USD","channel":"v3_orderbook","contents":{"offset":"2693995880","bids":[["10.788","185.4"]],"asks":[]}}
1635444246.902976: {"type":"channel_data","connection_id":"60a4fc71-1312-4830-86f4-9eb98be106ac","message_id":2517,"id":"CRV-USD","channel":"v3_orderbook","contents":{"offset":"2693995916","bids":[["4.85","0"]],"asks":[]}}
1635444246.903008: {"type":"channel_data","connection_id":"60a4fc71-1312-4830-86f4-9eb98be106ac","message_id":2518,"id":"BCH-USD","channel":"v3_orderbook","contents":{"offset":"2693995917","bids":[["573.9","49.7"]],"asks":[]}}
1635444246.9092119: {"type":"channel_data","connection_id":"60a4fc71-1312-4830-86f4-9eb98be106ac","message_id":2519,"id":"LTC-USD","channel":"v3_orderbook","contents":{"offset":"2693995919","bids":[],"asks":[["188.1","4188.56"]]}}
1635444246.9115222: {"type":"channel_data","connection_id":"60a4fc71-1312-4830-86f4-9eb98be106ac","message_id":2520,"id":"CRV-USD","channel":"v3_orderbook","contents":{"offset":"2693995925","bids":[["4.821","89712"],["4.82","7227"]],"asks":[]}}
1635444246.913704: {"type":"channel_data","connection_id":"60a4fc71-1312-4830-86f4-9eb98be106ac","message_id":2521,"id":"ETH-USD","channel":"v3_orderbook","contents":{"offset":"2693995931","bids":[],"asks":[["4218.3","55.112"]]}}
1635444246.913772: {"type":"channel_data","connection_id":"60a4fc71-1312-4830-86f4-9eb98be106ac","message_id":2522,"id":"SUSHI-USD","channel":"v3_orderbook","contents":{"offset":"2693995924","bids":[["10.726","0"],["10.723","3247.6"]],"asks":[]}}
1635444246.920331: {"type":"channel_data","connection_id":"60a4fc71-1312-4830-86f4-9eb98be106ac","message_id":2523,"id":"SUSHI-USD","channel":"v3_orderbook","contents":{"offset":"2693995934","bids":[],"asks":[["10.8","0"]]}}
1635444246.920419: {"type":"channel_data","connection_id":"60a4fc71-1312-4830-86f4-9eb98be106ac","message_id":2524,"id":"LTC-USD","channel":"v3_orderbook","contents":{"offset":"2693995928","bids":[["187.6","137.41"]],"asks":[]}}
1635444246.920457: {"type":"channel_data","connection_id":"60a4fc71-1312-4830-86f4-9eb98be106ac","message_id":2525,"id":"ETH-USD","channel":"v3_orderbook","contents":{"offset":"2693995937","bids":[],"asks":[["4216","127.749"]]}}
1635444246.925341: {"type":"channel_data","connection_id":"60a4fc71-1312-4830-86f4-9eb98be106ac","message_id":2526,"id":"ETH-USD","channel":"v3_orderbook","contents":{"offset":"2693995941","bids":[],"asks":[["4216.1","125.57"]]}}
1635444246.92539: {"type":"channel_data","connection_id":"60a4fc71-1312-4830-86f4-9eb98be106ac","message_id":2527,"id":"ETH-USD","channel":"v3_orderbook","contents":{"offset":"2693995947","bids":[],"asks":[["4216.9","0"]]}}
1635444246.927857: {"type":"channel_data","connection_id":"60a4fc71-1312-4830-86f4-9eb98be106ac","message_id":2528,"id":"EOS-USD","channel":"v3_orderbook","contents":{"offset":"2693995914","bids":[],"asks":[["4.402","0"]]}}
1635444246.9279091: {"type":"channel_data","connection_id":"60a4fc71-1312-4830-86f4-9eb98be106ac","message_id":2529,"id":"MKR-USD","channel":"v3_orderbook","contents":{"offset":"2693995936","bids":[["2381","18.6"]],"asks":[]}}
1635444246.9279392: {"type":"channel_data","connection_id":"60a4fc71-1312-4830-86f4-9eb98be106ac","message_id":2530,"id":"CRV-USD","channel":"v3_orderbook","contents":{"offset":"2693995942","bids":[["4.85","4943"]],"asks":[]}}
1635444246.9299011: {"type":"channel_data","connection_id":"60a4fc71-1312-4830-86f4-9eb98be106ac","message_id":2531,"id":"ETH-USD","channel":"v3_orderbook","contents":{"offset":"2693995945","bids":[["4215.3","22.496"]],"asks":[]}}
1635444246.936239: {"type":"channel_data","connection_id":"60a4fc71-1312-4830-86f4-9eb98be106ac","message_id":2532,"id":"ETH-USD","channel":"v3_orderbook","contents":{"offset":"2693995953","bids":[["4209.1","11.76"]],"asks":[]}}
1635444246.936872: {"type":"channel_data","connection_id":"60a4fc71-1312-4830-86f4-9eb98be106ac","message_id":2533,"id":"LTC-USD","channel":"v3_orderbook","contents":{"offset":"2693995922","bids":[["187.3","134.02"]],"asks":[]}}
1635444246.9378932: {"type":"channel_data","connection_id":"60a4fc71-1312-4830-86f4-9eb98be106ac","message_id":2534,"id":"UNI-USD","channel":"v3_orderbook","contents":{"offset":"2693995944","bids":[],"asks":[["25.055","15599.9"]]}}
1635444246.9379368: {"type":"channel_data","connection_id":"60a4fc71-1312-4830-86f4-9eb98be106ac","message_id":2535,"id":"EOS-USD","channel":"v3_orderbook","contents":{"offset":"2693995950","bids":[],"asks":[["4.403","11725"]]}}
1635444246.941534: {"type":"channel_data","connection_id":"60a4fc71-1312-4830-86f4-9eb98be106ac","message_id":2536,"id":"ETH-USD","channel":"v3_orderbook","contents":{"offset":"2693995951","bids":[["4212.6","4.3"]],"asks":[]}}
1635444246.94158: {"type":"channel_data","connection_id":"60a4fc71-1312-4830-86f4-9eb98be106ac","message_id":2537,"id":"SUSHI-USD","channel":"v3_orderbook","contents":{"offset":"2693995948","bids":[["10.78","0"]],"asks":[]}}
1635444246.950711: {"type":"channel_data","connection_id":"60a4fc71-1312-4830-86f4-9eb98be106ac","message_id":2538,"id":"SUSHI-USD","channel":"v3_orderbook","contents":{"offset":"2693995961","bids":[["10.786","373.2"]],"asks":[]}}
1635444246.950778: {"type":"channel_data","connection_id":"60a4fc71-1312-4830-86f4-9eb98be106ac","message_id":2539,"id":"SUSHI-USD","channel":"v3_orderbook","contents":{"offset":"2693995965","bids":[],"asks":[["10.822","0"]]}}
1635444246.9581509: {"type":"channel_data","connection_id":"60a4fc71-1312-4830-86f4-9eb98be106ac","message_id":2540,"id":"ETH-USD","channel":"v3_orderbook","contents":{"offset":"2693995938","bids":[],"asks":[["4216","137.532"]]}}
1635444246.962272: {"type":"channel_data","connection_id":"60a4fc71-1312-4830-86f4-9eb98be106ac","message_id":2541,"id":"SUSHI-USD","channel":"v3_orderbook","contents":{"offset":"2693995969","bids":[["10.785","0"]],"asks":[]}}
1635444246.971319: {"type":"channel_data","connection_id":"60a4fc71-1312-4830-86f4-9eb98be106ac","message_id":2542,"id":"EOS-USD","channel":"v3_orderbook","contents":{"offset":"2693995982","bids":[["4.398","16545"]],"asks":[]}}
1635444246.974868: {"type":"channel_data","connection_id":"60a4fc71-1312-4830-86f4-9eb98be106ac","message_id":2543,"id":"SUSHI-USD","channel":"v3_orderbook","contents":{"offset":"2693995984","bids":[["10.758","1095"]],"asks":[]}}
1635444246.9779332: {"type":"channel_data","connection_id":"60a4fc71-1312-4830-86f4-9eb98be106ac","message_id":2544,"id":"EOS-USD","channel":"v3_orderbook","contents":{"offset":"2693995989","bids":[],"asks":[["4.403","16267"]]}}
1635444246.977982: {"type":"channel_data","connection_id":"60a4fc71-1312-4830-86f4-9eb98be106ac","message_id":2545,"id":"ETH-USD","channel":"v3_orderbook","contents":{"offset":"2693995997","bids":[["4213.5","117.52"]],"asks":[]}}
1635444246.9786382: {"type":"channel_data","connection_id":"60a4fc71-1312-4830-86f4-9eb98be106ac","message_id":2546,"id":"CRV-USD","channel":"v3_orderbook","contents":{"offset":"2693995991","bids":[["4.825","0"],["4.824","7227"]],"asks":[]}}
1635444246.9814389: {"type":"channel_data","connection_id":"60a4fc71-1312-4830-86f4-9eb98be106ac","message_id":2547,"id":"ETH-USD","channel":"v3_orderbook","contents":{"offset":"2693995993","bids":[],"asks":[["4219.8","13.786"]]}}
1635444246.981494: {"type":"channel_data","connection_id":"60a4fc71-1312-4830-86f4-9eb98be106ac","message_id":2548,"id":"ETH-USD","channel":"v3_orderbook","contents":{"offset":"2693995998","bids":[["4215.9","332.329"]],"asks":[]}}
1635444246.984579: {"type":"channel_data","connection_id":"60a4fc71-1312-4830-86f4-9eb98be106ac","message_id":2549,"id":"ETH-USD","channel":"v3_orderbook","contents":{"offset":"2693995999","bids":[["4211","10089.169"]],"asks":[]}}
1635444246.9846232: {"type":"channel_data","connection_id":"60a4fc71-1312-4830-86f4-9eb98be106ac","message_id":2550,"id":"ETH-USD","channel":"v3_orderbook","contents":{"offset":"2693996005","bids":[["4215","23.741"]],"asks":[]}}
1635444246.985989: {"type":"channel_data","connection_id":"60a4fc71-1312-4830-86f4-9eb98be106ac","message_id":2551,"id":"SUSHI-USD","channel":"v3_orderbook","contents":{"offset":"2693996001","bids":[],"asks":[["10.813","333"]]}}
1635444246.99926: {"type":"channel_data","connection_id":"60a4fc71-1312-4830-86f4-9eb98be106ac","message_id":2552,"id":"SUSHI-USD","channel":"v3_orderbook","contents":{"offset":"2693996010","bids":[["10.792","0"]],"asks":[]}}
1635444246.99933: {"type":"channel_data","connection_id":"60a4fc71-1312-4830-86f4-9eb98be106ac","message_id":2553,"id":"SUSHI-USD","channel":"v3_orderbook","contents":{"offset":"2693996013","bids":[["10.786","0"]],"asks":[]}}
1635444246.999365: {"type":"channel_data","connection_id":"60a4fc71-1312-4830-86f4-9eb98be106ac","message_id":2554,"id":"ETH-USD","channel":"v3_orderbook","contents":{"offset":"2693996009","bids":[["4214","32.39"]],"asks":[]}}
1635444246.9993951: {"type":"channel_data","connection_id":"60a4fc71-1312-4830-86f4-9eb98be106ac","message_id":2555,"id":"ETH-USD","channel":"v3_orderbook","contents":{"offset":"2693996011","bids":[["4214.3","58.76"]],"asks":[]}}
1635444246.999421: {"type":"channel_data","connection_id":"60a4fc71-1312-4830-86f4-9eb98be106ac","message_id":2556,"id":"ETH-USD","channel":"v3_orderbook","contents":{"offset":"2693995987","bids":[],"asks":[["4216","125.755"]]}}
1635444246.999445: {"type":"channel_data","connection_id":"60a4fc71-1312-4830-86f4-9eb98be106ac","message_id":2557,"id":"CRV-USD","channel":"v3_orderbook","contents":{"offset":"2693996020","bids":[["4.852","1030"]],"asks":[]}}
1635444246.9994712: {"type":"channel_data","connection_id":"60a4fc71-1312-4830-86f4-9eb98be106ac","message_id":2558,"id":"ETH-USD","channel":"v3_orderbook","contents":{"offset":"2693996027","bids":[["4215.4","58.216"]],"asks":[]}}
1635444247.0024672: {"type":"channel_data","connection_id":"60a4fc71-1312-4830-86f4-9eb98be106ac","message_id":2559,"id":"SUSHI-USD","channel":"v3_orderbook","contents":{"offset":"2693996026","bids":[["10.784","8584.6"]],"asks":[]}}
1635444247.006349: {"type":"channel_data","connection_id":"60a4fc71-1312-4830-86f4-9eb98be106ac","message_id":2560,"id":"SUSHI-USD","channel":"v3_orderbook","contents":{"offset":"2693996032","bids":[],"asks":[["10.794","4583.1"]]}}
1635444247.0064042: {"type":"channel_data","connection_id":"60a4fc71-1312-4830-86f4-9eb98be106ac","message_id":2561,"id":"ETH-USD","channel":"v3_orderbook","contents":{"offset":"2693996035","bids":[["4215.9","309.833"]],"asks":[]}}
1635444247.006439: {"type":"channel_data","connection_id":"60a4fc71-1312-4830-86f4-9eb98be106ac","message_id":2562,"id":"SUSHI-USD","channel":"v3_orderbook","contents":{"offset":"2693996039","bids":[["10.786","3708.3"]],"asks":[]}}
1635444247.0070348: {"type":"channel_data","connection_id":"60a4fc71-1312-4830-86f4-9eb98be106ac","message_id":2563,"id":"ETH-USD","channel":"v3_orderbook","contents":{"offset":"2693996004","bids":[],"asks":[["4216","184.132"]]}}
1635444247.010554: {"type":"channel_data","connection_id":"60a4fc71-1312-4830-86f4-9eb98be106ac","message_id":2564,"id":"ETH-USD","channel":"v3_orderbook","contents":{"offset":"2693996046","bids":[],"asks":[["4217.8","735.031"]]}}
1635444247.0144541: {"type":"channel_data","connection_id":"60a4fc71-1312-4830-86f4-9eb98be106ac","message_id":2565,"id":"CRV-USD","channel":"v3_orderbook","contents":{"offset":"2693996047","bids":[],"asks":[["4.863","15500"]]}}
1635444247.014514: {"type":"channel_data","connection_id":"60a4fc71-1312-4830-86f4-9eb98be106ac","message_id":2566,"id":"SUSHI-USD","channel":"v3_orderbook","contents":{"offset":"2693996044","bids":[["10.779","401.8"]],"asks":[]}}
1635444247.023839: {"type":"channel_data","connection_id":"60a4fc71-1312-4830-86f4-9eb98be106ac","message_id":2567,"id":"ETH-USD","channel":"v3_orderbook","contents":{"offset":"2693996021","bids":[],"asks":[["4218.2","5876.785"]]}}
1635444247.024587: {"type":"channel_data","connection_id":"60a4fc71-1312-4830-86f4-9eb98be106ac","message_id":2568,"id":"MKR-USD","channel":"v3_orderbook","contents":{"offset":"2693996052","bids":[["2380","26.51"]],"asks":[]}}
1635444247.025228: {"type":"channel_data","connection_id":"60a4fc71-1312-4830-86f4-9eb98be106ac","message_id":2569,"id":"CRV-USD","channel":"v3_orderbook","contents":{"offset":"2693996041","bids":[],"asks":[["4.86","1030"]]}}
1635444247.027134: {"type":"channel_data","connection_id":"60a4fc71-1312-4830-86f4-9eb98be106ac","message_id":2570,"id":"ETH-USD","channel":"v3_orderbook","contents":{"offset":"2693996059","bids":[],"asks":[["4219","0.2"]]}}
1635444247.0282052: {"type":"channel_data","connection_id":"60a4fc71-1312-4830-86f4-9eb98be106ac","message_id":2571,"id":"SUSHI-USD","channel":"v3_orderbook","contents":{"offset":"2693996062","bids":[],"asks":[["10.8","13746.8"]]}}
1635444247.043921: {"type":"channel_data","connection_id":"60a4fc71-1312-4830-86f4-9eb98be106ac","message_id":2572,"id":"SUSHI-USD","channel":"v3_orderbook","contents":{"offset":"2693996037","bids":[],"asks":[["10.798","7706.9"]]}}
1635444247.0440152: {"type":"channel_data","connection_id":"60a4fc71-1312-4830-86f4-9eb98be106ac","message_id":2573,"id":"MKR-USD","channel":"v3_orderbook","contents":{"offset":"2693996071","bids":[["2378","70.429"]],"asks":[]}}
1635444247.046527: {"type":"channel_data","connection_id":"60a4fc71-1312-4830-86f4-9eb98be106ac","message_id":2574,"id":"SUSHI-USD","channel":"v3_orderbook","contents":{"offset":"2693996074","bids":[["10.762","458519.6"]],"asks":[]}}
1635444247.0540931: {"type":"channel_data","connection_id":"60a4fc71-1312-4830-86f4-9eb98be106ac","message_id":2575,"id":"SUSHI-USD","channel":"v3_orderbook","contents":{"offset":"2693996076","bids":[],"asks":[["10.909","942.1"],["10.921","0"]]}}
1635444247.054168: {"type":"channel_data","connection_id":"60a4fc71-1312-4830-86f4-9eb98be106ac","message_id":2576,"id":"CRV-USD","channel":"v3_orderbook","contents":{"offset":"2693996053","bids":[],"asks":[["4.865","14066"]]}}
1635444247.0542898: {"type":"channel_data","connection_id":"60a4fc71-1312-4830-86f4-9eb98be106ac","message_id":2577,"id":"SUSHI-USD","channel":"v3_orderbook","contents":{"offset":"2693996087","bids":[],"asks":[["10.804","15"]]}}
1635444247.057584: {"type":"channel_data","connection_id":"60a4fc71-1312-4830-86f4-9eb98be106ac","message_id":2578,"id":"SUSHI-USD","channel":"v3_orderbook","contents":{"offset":"2693996084","bids":[["10.785","4582.3"]],"asks":[]}}
1635444247.063804: {"type":"channel_data","connection_id":"60a4fc71-1312-4830-86f4-9eb98be106ac","message_id":2579,"id":"SUSHI-USD","channel":"v3_orderbook","contents":{"offset":"2693996100","bids":[["10.776","1558.6"]],"asks":[]}}
1635444247.077121: {"type":"channel_data","connection_id":"60a4fc71-1312-4830-86f4-9eb98be106ac","message_id":2580,"id":"SUSHI-USD","channel":"v3_orderbook","contents":{"offset":"2693996101","bids":[],"asks":[["10.797","681.4"]]}}
1635444247.077182: {"type":"channel_data","connection_id":"60a4fc71-1312-4830-86f4-9eb98be106ac","message_id":2581,"id":"ETH-USD","channel":"v3_orderbook","contents":{"offset":"2693996110","bids":[["4209.6","4.04"]],"asks":[]}}
1635444247.0772061: {"type":"channel_data","connection_id":"60a4fc71-1312-4830-86f4-9eb98be106ac","message_id":2582,"id":"ETH-USD","channel":"v3_orderbook","contents":{"offset":"2693996114","bids":[],"asks":[["4218","0.555"]]}}
1635444247.08212: {"type":"channel_data","connection_id":"60a4fc71-1312-4830-86f4-9eb98be106ac","message_id":2583,"id":"EOS-USD","channel":"v3_orderbook","contents":{"offset":"2693996112","bids":[],"asks":[["4.402","11323"]]}}
1635444247.0821812: {"type":"channel_data","connection_id":"60a4fc71-1312-4830-86f4-9eb98be106ac","message_id":2584,"id":"ETH-USD","channel":"v3_orderbook","contents":{"offset":"2693996118","bids":[],"asks":[["4216","231.613"]]}}
1635444247.087774: {"type":"channel_data","connection_id":"60a4fc71-1312-4830-86f4-9eb98be106ac","message_id":2585,"id":"UNI-USD","channel":"v3_orderbook","contents":{"offset":"2693996120","bids":[["25.028","18524.6"]],"asks":[]}}
1635444247.0887291: {"type":"channel_data","connection_id":"60a4fc71-1312-4830-86f4-9eb98be106ac","message_id":2586,"id":"SUSHI-USD","channel":"v3_orderbook","contents":{"offset":"2693996126","bids":[["10.779","14148.6"]],"asks":[]}}
1635444247.088768: {"type":"channel_data","connection_id":"60a4fc71-1312-4830-86f4-9eb98be106ac","message_id":2587,"id":"SUSHI-USD","channel":"v3_orderbook","contents":{"offset":"2693996129","bids":[["10.784","8908.5"]],"asks":[]}}
1635444247.0979588: {"type":"channel_data","connection_id":"60a4fc71-1312-4830-86f4-9eb98be106ac","message_id":2588,"id":"SUSHI-USD","channel":"v3_orderbook","contents":{"offset":"2693996136","bids":[["10.685","0"],["10.669","925.9"]],"asks":[]}}
1635444247.107025: {"type":"channel_data","connection_id":"60a4fc71-1312-4830-86f4-9eb98be106ac","message_id":2589,"id":"ETH-USD","channel":"v3_orderbook","contents":{"offset":"2693996139","bids":[],"asks":[["4239","33.366"],["4239.8","0"]]}}
1635444247.107094: {"type":"channel_data","connection_id":"60a4fc71-1312-4830-86f4-9eb98be106ac","message_id":2590,"id":"CRV-USD","channel":"v3_orderbook","contents":{"offset":"2693996137","bids":[["4.85","9887"]],"asks":[]}}
1635444247.107873: {"type":"channel_data","connection_id":"60a4fc71-1312-4830-86f4-9eb98be106ac","message_id":2591,"id":"ETH-USD","channel":"v3_orderbook","contents":{"offset":"2693996141","bids":[],"asks":[["4217","2.613"]]}}
1635444247.1164649: {"type":"channel_data","connection_id":"60a4fc71-1312-4830-86f4-9eb98be106ac","message_id":2592,"id":"CRV-USD","channel":"v3_orderbook","contents":{"offset":"2693996142","bids":[],"asks":[["4.862","4557"],["4.865","9509"]]}}
1635444247.1165261: {"type":"channel_data","connection_id":"60a4fc71-1312-4830-86f4-9eb98be106ac","message_id":2593,"id":"LTC-USD","channel":"v3_orderbook","contents":{"offset":"2693996147","bids":[],"asks":[["189.1","981.64"],["190.4","183.5"]]}}
1635444247.12682: {"type":"channel_data","connection_id":"60a4fc71-1312-4830-86f4-9eb98be106ac","message_id":2594,"id":"MKR-USD","channel":"v3_orderbook","contents":{"offset":"2693996158","bids":[],"asks":[["2397","58.47"],["2402","0"]]}}
1635444247.134798: {"type":"channel_data","connection_id":"60a4fc71-1312-4830-86f4-9eb98be106ac","message_id":2595,"id":"LTC-USD","channel":"v3_orderbook","contents":{"offset":"2693996157","bids":[["187.4","53229.89"]],"asks":[]}}
1635444247.139143: {"type":"channel_data","connection_id":"60a4fc71-1312-4830-86f4-9eb98be106ac","message_id":2596,"id":"SUSHI-USD","channel":"v3_orderbook","contents":{"offset":"2693996161","bids":[],"asks":[["10.806","30"]]}}
1635444247.141729: {"type":"channel_data","connection_id":"60a4fc71-1312-4830-86f4-9eb98be106ac","message_id":2597,"id":"SUSHI-USD","channel":"v3_orderbook","contents":{"offset":"2693996160","bids":[],"asks":[["10.795","0"]]}}
1635444247.1514611: {"type":"channel_data","connection_id":"60a4fc71-1312-4830-86f4-9eb98be106ac","message_id":2598,"id":"SUSHI-USD","channel":"v3_orderbook","contents":{"offset":"2693996169","bids":[],"asks":[["10.801","3713.9"]]}}
1635444247.1548748: {"type":"channel_data","connection_id":"60a4fc71-1312-4830-86f4-9eb98be106ac","message_id":2599,"id":"SUSHI-USD","channel":"v3_orderbook","contents":{"offset":"2693996170","bids":[["10.755","91705.7"]],"asks":[]}}
1635444247.154932: {"type":"channel_data","connection_id":"60a4fc71-1312-4830-86f4-9eb98be106ac","message_id":2600,"id":"ETH-USD","channel":"v3_orderbook","contents":{"offset":"2693996165","bids":[],"asks":[["4216","236.388"]]}}
1635444247.159898: {"type":"channel_data","connection_id":"60a4fc71-1312-4830-86f4-9eb98be106ac","message_id":2601,"id":"CRV-USD","channel":"v3_orderbook","contents":{"offset":"2693996177","bids":[],"asks":[["4.86","0"]]}}
1635444247.1630871: {"type":"channel_data","connection_id":"60a4fc71-1312-4830-86f4-9eb98be106ac","message_id":2602,"id":"ETH-USD","channel":"v3_orderbook","contents":{"offset":"2693996176","bids":[],"asks":[["4216.9","1899.245"]]}}
1635444247.163177: {"type":"channel_data","connection_id":"60a4fc71-1312-4830-86f4-9eb98be106ac","message_id":2603,"id":"SUSHI-USD","channel":"v3_orderbook","contents":{"offset":"2693996173","bids":[["10.772","0"]],"asks":[]}}
1635444247.17111: {"type":"channel_data","connection_id":"60a4fc71-1312-4830-86f4-9eb98be106ac","message_id":2604,"id":"ETH-USD","channel":"v3_orderbook","contents":{"offset":"2693996185","bids":[],"asks":[["4223.6","0"]]}}
1635444247.1711922: {"type":"channel_data","connection_id":"60a4fc71-1312-4830-86f4-9eb98be106ac","message_id":2605,"id":"CRV-USD","channel":"v3_orderbook","contents":{"offset":"2693996180","bids":[["4.852","0"]],"asks":[]}}
1635444247.1745129: {"type":"channel_data","connection_id":"60a4fc71-1312-4830-86f4-9eb98be106ac","message_id":2606,"id":"CRV-USD","channel":"v3_orderbook","contents":{"offset":"2693996186","bids":[],"asks":[["4.863","14469"]]}}
1635444247.174572: {"type":"channel_data","connection_id":"60a4fc71-1312-4830-86f4-9eb98be106ac","message_id":2607,"id":"MKR-USD","channel":"v3_orderbook","contents":{"offset":"2693996181","bids":[["2380","28.716"]],"asks":[]}}
1635444247.1809459: {"type":"channel_data","connection_id":"60a4fc71-1312-4830-86f4-9eb98be106ac","message_id":2608,"id":"CRV-USD","channel":"v3_orderbook","contents":{"offset":"2693996198","bids":[],"asks":[["5.022","0"]]}}
1635444247.182014: {"type":"channel_data","connection_id":"60a4fc71-1312-4830-86f4-9eb98be106ac","message_id":2609,"id":"CRV-USD","channel":"v3_orderbook","contents":{"offset":"2693996194","bids":[["4.682","0"]],"asks":[]}}
1635444247.189127: {"type":"channel_data","connection_id":"60a4fc71-1312-4830-86f4-9eb98be106ac","message_id":2610,"id":"SUSHI-USD","channel":"v3_orderbook","contents":{"offset":"2693996201","bids":[["10.767","3713.9"]],"asks":[]}}
1635444247.189169: {"type":"channel_data","connection_id":"60a4fc71-1312-4830-86f4-9eb98be106ac","message_id":2611,"id":"ETH-USD","channel":"v3_orderbook","contents":{"offset":"2693996199","bids":[],"asks":[["4217.8","730.731"]]}}
1635444247.189194: {"type":"channel_data","connection_id":"60a4fc71-1312-4830-86f4-9eb98be106ac","message_id":2612,"id":"CRV-USD","channel":"v3_orderbook","contents":{"offset":"2693996200","bids":[],"asks":[["4.859","0"]]}}
1635444247.1926441: {"type":"channel_data","connection_id":"60a4fc71-1312-4830-86f4-9eb98be106ac","message_id":2613,"id":"CRV-USD","channel":"v3_orderbook","contents":{"offset":"2693996206","bids":[["4.849","521"]],"asks":[]}}
1635444247.200175: {"type":"channel_data","connection_id":"60a4fc71-1312-4830-86f4-9eb98be106ac","message_id":2614,"id":"CRV-USD","channel":"v3_orderbook","contents":{"offset":"2693996213","bids":[],"asks":[["4.858","0"]]}}
1635444247.203628: {"type":"channel_data","connection_id":"60a4fc71-1312-4830-86f4-9eb98be106ac","message_id":2615,"id":"ETH-USD","channel":"v3_orderbook","contents":{"offset":"2693996223","bids":[["4212.4","60.789"]],"asks":[]}}
1635444247.203676: {"type":"channel_data","connection_id":"60a4fc71-1312-4830-86f4-9eb98be106ac","message_id":2616,"id":"EOS-USD","channel":"v3_orderbook","contents":{"offset":"2693996224","bids":[],"asks":[["4.404","3282"]]}}
1635444247.214802: {"type":"channel_data","connection_id":"60a4fc71-1312-4830-86f4-9eb98be106ac","message_id":2617,"id":"EOS-USD","channel":"v3_orderbook","contents":{"offset":"2693996230","bids":[],"asks":[["4.405","9078"]]}}
1635444247.214863: {"type":"channel_data","connection_id":"60a4fc71-1312-4830-86f4-9eb98be106ac","message_id":2618,"id":"SUSHI-USD","channel":"v3_orderbook","contents":{"offset":"2693996231","bids":[["10.788","1394.6"]],"asks":[]}}
1635444247.2148879: {"type":"channel_data","connection_id":"60a4fc71-1312-4830-86f4-9eb98be106ac","message_id":2619,"id":"CRV-USD","channel":"v3_orderbook","contents":{"offset":"2693996232","bids":[],"asks":[["4.854","3341"]]}}
1635444247.214916: {"type":"channel_data","connection_id":"60a4fc71-1312-4830-86f4-9eb98be106ac","message_id":2620,"id":"ETH-USD","channel":"v3_orderbook","contents":{"offset":"2693996234","bids":[["4212.6","11.516"]],"asks":[]}}
1635444247.2213829: {"type":"channel_data","connection_id":"60a4fc71-1312-4830-86f4-9eb98be106ac","message_id":2621,"id":"LTC-USD","channel":"v3_orderbook","contents":{"offset":"2693996237","bids":[["187.2","66.85"]],"asks":[]}}
1635444247.2214441: {"type":"channel_data","connection_id":"60a4fc71-1312-4830-86f4-9eb98be106ac","message_id":2622,"id":"ETH-USD","channel":"v3_orderbook","contents":{"offset":"2693996239","bids":[["4215.3","79.956"]],"asks":[]}}
1635444247.2214699: {"type":"channel_data","connection_id":"60a4fc71-1312-4830-86f4-9eb98be106ac","message_id":2623,"id":"ETH-USD","channel":"v3_orderbook","contents":{"offset":"2693996242","bids":[],"asks":[["4216.2","127.263"]]}}
1635444247.22149: {"type":"channel_data","connection_id":"60a4fc71-1312-4830-86f4-9eb98be106ac","message_id":2624,"id":"ETH-USD","channel":"v3_orderbook","contents":{"offset":"2693996240","bids":[],"asks":[["4218.2","5878.208"]]}}
1635444247.22251: {"type":"channel_data","connection_id":"60a4fc71-1312-4830-86f4-9eb98be106ac","message_id":2625,"id":"EOS-USD","channel":"v3_orderbook","contents":{"offset":"2693996243","bids":[["4.399","0"]],"asks":[]}}
1635444247.226021: {"type":"channel_data","connection_id":"60a4fc71-1312-4830-86f4-9eb98be106ac","message_id":2626,"id":"ETH-USD","channel":"v3_orderbook","contents":{"offset":"2693996248","bids":[],"asks":[["4216","226.605"]]}}
1635444247.2325602: {"type":"channel_data","connection_id":"60a4fc71-1312-4830-86f4-9eb98be106ac","message_id":2627,"id":"CRV-USD","channel":"v3_orderbook","contents":{"offset":"2693996259","bids":[],"asks":[["4.863","845"]]}}
1635444247.235498: {"type":"channel_data","connection_id":"60a4fc71-1312-4830-86f4-9eb98be106ac","message_id":2628,"id":"EOS-USD","channel":"v3_orderbook","contents":{"offset":"2693996255","bids":[["4.4","11663"]],"asks":[]}}
1635444247.2355452: {"type":"channel_data","connection_id":"60a4fc71-1312-4830-86f4-9eb98be106ac","message_id":2629,"id":"SUSHI-USD","channel":"v3_orderbook","contents":{"offset":"2693996258","bids":[["10.775","402"]],"asks":[]}}
1635444247.23557: {"type":"channel_data","connection_id":"60a4fc71-1312-4830-86f4-9eb98be106ac","message_id":2630,"id":"SUSHI-USD","channel":"v3_orderbook","contents":{"offset":"2693996252","bids":[["10.782","373.3"]],"asks":[]}}
1635444247.235589: {"type":"channel_data","connection_id":"60a4fc71-1312-4830-86f4-9eb98be106ac","message_id":2631,"id":"UNI-USD","channel":"v3_orderbook","contents":{"offset":"2693996256","bids":[["24.904","0"],["24.903","1997.7"]],"asks":[]}}
1635444247.236576: {"type":"channel_data","connection_id":"60a4fc71-1312-4830-86f4-9eb98be106ac","message_id":2632,"id":"XMR-USD","channel":"v3_orderbook","contents":{"offset":"2693996263","bids":[],"asks":[["265.5","104.14"]]}}
1635444247.239448: {"type":"channel_data","connection_id":"60a4fc71-1312-4830-86f4-9eb98be106ac","message_id":2633,"id":"UNI-USD","channel":"v3_orderbook","contents":{"offset":"2693996261","bids":[["24.879","0"],["24.878","1997.7"]],"asks":[]}}
1635444247.243247: {"type":"channel_data","connection_id":"60a4fc71-1312-4830-86f4-9eb98be106ac","message_id":2634,"id":"ETH-USD","channel":"v3_orderbook","contents":{"offset":"2693996265","bids":[],"asks":[["4217.8","732.154"]]}}
1635444247.255569: {"type":"channel_data","connection_id":"60a4fc71-1312-4830-86f4-9eb98be106ac","message_id":2635,"id":"ETH-USD","channel":"v3_orderbook","contents":{"offset":"2693996275","bids":[],"asks":[["4218.2","5879.72"]]}}
1635444247.255629: {"type":"channel_data","connection_id":"60a4fc71-1312-4830-86f4-9eb98be106ac","message_id":2636,"id":"SUSHI-USD","channel":"v3_orderbook","contents":{"offset":"2693996278","bids":[],"asks":[["10.798","3704.6"]]}}
1635444247.2556539: {"type":"channel_data","connection_id":"60a4fc71-1312-4830-86f4-9eb98be106ac","message_id":2637,"id":"ETH-USD","channel":"v3_orderbook","contents":{"offset":"2693996279","bids":[],"asks":[["4218.3","56.624"]]}}
1635444247.2556732: {"type":"channel_data","connection_id":"60a4fc71-1312-4830-86f4-9eb98be106ac","message_id":2638,"id":"ETH-USD","channel":"v3_orderbook","contents":{"offset":"2693996274","bids":[],"asks":[["4217.9","23.919"]]}}
1635444247.257942: {"type":"channel_data","connection_id":"60a4fc71-1312-4830-86f4-9eb98be106ac","message_id":2639,"id":"CRV-USD","channel":"v3_orderbook","contents":{"offset":"2693996276","bids":[["4.835","2501"],["4.834","1281"]],"asks":[]}}
1635444247.2579892: {"type":"channel_data","connection_id":"60a4fc71-1312-4830-86f4-9eb98be106ac","message_id":2640,"id":"SUSHI-USD","channel":"v3_orderbook","contents":{"offset":"2693996280","bids":[],"asks":[["10.793","8584.9"]]}}
1635444247.262553: {"type":"channel_data","connection_id":"60a4fc71-1312-4830-86f4-9eb98be106ac","message_id":2641,"id":"ETH-USD","channel":"v3_orderbook","contents":{"offset":"2693996286","bids":[["4215.4","0"]],"asks":[]}}
1635444247.262594: {"type":"channel_data","connection_id":"60a4fc71-1312-4830-86f4-9eb98be106ac","message_id":2642,"id":"SUSHI-USD","channel":"v3_orderbook","contents":{"offset":"2693996287","bids":[["10.779","14474"]],"asks":[]}}
1635444247.264767: {"type":"channel_data","connection_id":"60a4fc71-1312-4830-86f4-9eb98be106ac","message_id":2643,"id":"CRV-USD","channel":"v3_orderbook","contents":{"offset":"2693996290","bids":[["4.849","1552"]],"asks":[]}}
1635444247.264817: {"type":"channel_data","connection_id":"60a4fc71-1312-4830-86f4-9eb98be106ac","message_id":2644,"id":"SUSHI-USD","channel":"v3_orderbook","contents":{"offset":"2693996285","bids":[],"asks":[["10.797","1753"]]}}
1635444247.265333: {"type":"channel_data","connection_id":"60a4fc71-1312-4830-86f4-9eb98be106ac","message_id":2645,"id":"SUSHI-USD","channel":"v3_orderbook","contents":{"offset":"2693996288","bids":[["10.782","4375.6"]],"asks":[]}}
1635444247.273835: {"type":"channel_data","connection_id":"60a4fc71-1312-4830-86f4-9eb98be106ac","message_id":2646,"id":"SUSHI-USD","channel":"v3_orderbook","contents":{"offset":"2693996292","bids":[["10.784","12910.8"]],"asks":[]}}
1635444247.279158: {"type":"channel_data","connection_id":"60a4fc71-1312-4830-86f4-9eb98be106ac","message_id":2647,"id":"MKR-USD","channel":"v3_orderbook","contents":{"offset":"2693996296","bids":[["2378","72.426"]],"asks":[]}}
1635444247.279209: {"type":"channel_data","connection_id":"60a4fc71-1312-4830-86f4-9eb98be106ac","message_id":2648,"id":"SUSHI-USD","channel":"v3_orderbook","contents":{"offset":"2693996299","bids":[],"asks":[["10.793","12587.2"]]}}
1635444247.2792408: {"type":"channel_data","connection_id":"60a4fc71-1312-4830-86f4-9eb98be106ac","message_id":2649,"id":"ETH-USD","channel":"v3_orderbook","contents":{"offset":"2693996302","bids":[["4213","1015.76"]],"asks":[]}}
1635444247.279267: {"type":"channel_data","connection_id":"60a4fc71-1312-4830-86f4-9eb98be106ac","message_id":2650,"id":"ETH-USD","channel":"v3_orderbook","contents":{"offset":"2693996305","bids":[["4212.1","7.216"]],"asks":[]}}
1635444247.279289: {"type":"channel_data","connection_id":"60a4fc71-1312-4830-86f4-9eb98be106ac","message_id":2651,"id":"ETH-USD","channel":"v3_orderbook","contents":{"offset":"2693996300","bids":[],"asks":[["4218.1","4475.003"]]}}
1635444247.283457: {"type":"channel_data","connection_id":"60a4fc71-1312-4830-86f4-9eb98be106ac","message_id":2652,"id":"ETH-USD","channel":"v3_orderbook","contents":{"offset":"2693996301","bids":[],"asks":[["4216.2","117.48"]]}}
1635444247.283517: {"type":"channel_data","connection_id":"60a4fc71-1312-4830-86f4-9eb98be106ac","message_id":2653,"id":"ETH-USD","channel":"v3_orderbook","contents":{"offset":"2693996304","bids":[["4212.6","4.3"]],"asks":[]}}
1635444247.2882419: {"type":"channel_data","connection_id":"60a4fc71-1312-4830-86f4-9eb98be106ac","message_id":2654,"id":"CRV-USD","channel":"v3_orderbook","contents":{"offset":"2693996312","bids":[],"asks":[["4.866","13681"]]}}
1635444247.288301: {"type":"channel_data","connection_id":"60a4fc71-1312-4830-86f4-9eb98be106ac","message_id":2655,"id":"SUSHI-USD","channel":"v3_orderbook","contents":{"offset":"2693996311","bids":[],"asks":[["10.806","10030"]]}}
1635444247.288325: {"type":"channel_data","connection_id":"60a4fc71-1312-4830-86f4-9eb98be106ac","message_id":2656,"id":"ETH-USD","channel":"v3_orderbook","contents":{"offset":"2693996309","bids":[],"asks":[["4218.4","41.541"]]}}
1635444247.3098261: {"type":"channel_data","connection_id":"60a4fc71-1312-4830-86f4-9eb98be106ac","message_id":2657,"id":"CRV-USD","channel":"v3_orderbook","contents":{"offset":"2693996318","bids":[],"asks":[["4.87","1939"],["4.871","2778"]]}}
1635444247.3098948: {"type":"channel_data","connection_id":"60a4fc71-1312-4830-86f4-9eb98be106ac","message_id":2658,"id":"EOS-USD","channel":"v3_orderbook","contents":{"offset":"2693996319","bids":[],"asks":[["4.403","4945"]]}}
1635444247.309921: {"type":"channel_data","connection_id":"60a4fc71-1312-4830-86f4-9eb98be106ac","message_id":2659,"id":"SUSHI-USD","channel":"v3_orderbook","contents":{"offset":"2693996322","bids":[["10.788","185.4"]],"asks":[]}}
1635444247.311507: {"type":"channel_data","connection_id":"60a4fc71-1312-4830-86f4-9eb98be106ac","message_id":2660,"id":"SUSHI-USD","channel":"v3_orderbook","contents":{"offset":"2693996329","bids":[["10.772","8588.4"]],"asks":[]}}
1635444247.311548: {"type":"channel_data","connection_id":"60a4fc71-1312-4830-86f4-9eb98be106ac","message_id":2661,"id":"ETH-USD","channel":"v3_orderbook","contents":{"offset":"2693996328","bids":[],"asks":[["4216","236.388"]]}}
1635444247.311572: {"type":"channel_data","connection_id":"60a4fc71-1312-4830-86f4-9eb98be106ac","message_id":2662,"id":"EOS-USD","channel":"v3_orderbook","contents":{"offset":"2693996337","bids":[],"asks":[["4.403","6082"]]}}
1635444247.3115919: {"type":"channel_data","connection_id":"60a4fc71-1312-4830-86f4-9eb98be106ac","message_id":2663,"id":"CRV-USD","channel":"v3_orderbook","contents":{"offset":"2693996334","bids":[],"asks":[["4.856","325"]]}}
1635444247.316422: {"type":"channel_data","connection_id":"60a4fc71-1312-4830-86f4-9eb98be106ac","message_id":2664,"id":"CRV-USD","channel":"v3_orderbook","contents":{"offset":"2693996338","bids":[["4.814","1060"]],"asks":[]}}
1635444247.316478: {"type":"channel_data","connection_id":"60a4fc71-1312-4830-86f4-9eb98be106ac","message_id":2665,"id":"CRV-USD","channel":"v3_orderbook","contents":{"offset":"2693996332","bids":[],"asks":[["4.858","4944"]]}}
1635444247.31774: {"type":"channel_data","connection_id":"60a4fc71-1312-4830-86f4-9eb98be106ac","message_id":2666,"id":"EOS-USD","channel":"v3_orderbook","contents":{"offset":"2693996339","bids":[["4.399","1137"]],"asks":[]}}
1635444247.317782: {"type":"channel_data","connection_id":"60a4fc71-1312-4830-86f4-9eb98be106ac","message_id":2667,"id":"ETH-USD","channel":"v3_orderbook","contents":{"offset":"2693996342","bids":[["4209.7","1.782"]],"asks":[]}}
1635444247.327117: {"type":"channel_data","connection_id":"60a4fc71-1312-4830-86f4-9eb98be106ac","message_id":2668,"id":"LTC-USD","channel":"v3_orderbook","contents":{"offset":"2693996346","bids":[["187.5","33.58"]],"asks":[]}}
1635444247.332993: {"type":"channel_data","connection_id":"60a4fc71-1312-4830-86f4-9eb98be106ac","message_id":2669,"id":"CRV-USD","channel":"v3_orderbook","contents":{"offset":"2693996347","bids":[],"asks":[["4.858","0"]]}}
1635444247.333055: {"type":"channel_data","connection_id":"60a4fc71-1312-4830-86f4-9eb98be106ac","message_id":2670,"id":"LTC-USD","channel":"v3_orderbook","contents":{"offset":"2693996354","bids":[],"asks":[["188.8","940.03"]]}}
1635444247.333081: {"type":"channel_data","connection_id":"60a4fc71-1312-4830-86f4-9eb98be106ac","message_id":2671,"id":"BCH-USD","channel":"v3_orderbook","contents":{"offset":"2693996352","bids":[],"asks":[["576.5","19.14"]]}}
1635444247.333102: {"type":"channel_data","connection_id":"60a4fc71-1312-4830-86f4-9eb98be106ac","message_id":2672,"id":"CRV-USD","channel":"v3_orderbook","contents":{"offset":"2693996349","bids":[["4.841","6779"]],"asks":[]}}
1635444247.345998: {"type":"channel_data","connection_id":"60a4fc71-1312-4830-86f4-9eb98be106ac","message_id":2673,"id":"ETH-USD","channel":"v3_orderbook","contents":{"offset":"2693996355","bids":[],"asks":[["4216.4","4.3"]]}}
1635444247.3460622: {"type":"channel_data","connection_id":"60a4fc71-1312-4830-86f4-9eb98be106ac","message_id":2674,"id":"CRV-USD","channel":"v3_orderbook","contents":{"offset":"2693996359","bids":[],"asks":[["4.857","5171"]]}}
1635444247.348514: {"type":"channel_data","connection_id":"60a4fc71-1312-4830-86f4-9eb98be106ac","message_id":2675,"id":"ETH-USD","channel":"v3_orderbook","contents":{"offset":"2693996360","bids":[],"asks":[["4219.6","89.98"]]}}
1635444247.354559: {"type":"channel_data","connection_id":"60a4fc71-1312-4830-86f4-9eb98be106ac","message_id":2676,"id":"CRV-USD","channel":"v3_orderbook","contents":{"offset":"2693996374","bids":[["4.82","0"],["4.819","8152"]],"asks":[]}}
1635444247.3551319: {"type":"channel_data","connection_id":"60a4fc71-1312-4830-86f4-9eb98be106ac","message_id":2677,"id":"CRV-USD","channel":"v3_orderbook","contents":{"offset":"2693996375","bids":[],"asks":[["4.856","154"]]}}
1635444247.3588328: {"type":"channel_data","connection_id":"60a4fc71-1312-4830-86f4-9eb98be106ac","message_id":2678,"id":"CRV-USD","channel":"v3_orderbook","contents":{"offset":"2693996372","bids":[],"asks":[["4.87","1089"]]}}
1635444247.36599: {"type":"channel_data","connection_id":"60a4fc71-1312-4830-86f4-9eb98be106ac","message_id":2679,"id":"SUSHI-USD","channel":"v3_orderbook","contents":{"offset":"2693996382","bids":[["10.734","0"],["10.732","3247.6"]],"asks":[]}}
1635444247.366059: {"type":"channel_data","connection_id":"60a4fc71-1312-4830-86f4-9eb98be106ac","message_id":2680,"id":"SUSHI-USD","channel":"v3_orderbook","contents":{"offset":"2693996377","bids":[["10.784","13206.7"]],"asks":[]}}
1635444247.369472: {"type":"channel_data","connection_id":"60a4fc71-1312-4830-86f4-9eb98be106ac","message_id":2681,"id":"SUSHI-USD","channel":"v3_orderbook","contents":{"offset":"2693996378","bids":[["10.718","0"],["10.716","5123"]],"asks":[]}}
1635444247.369534: {"type":"channel_data","connection_id":"60a4fc71-1312-4830-86f4-9eb98be106ac","message_id":2682,"id":"SUSHI-USD","channel":"v3_orderbook","contents":{"offset":"2693996384","bids":[],"asks":[["10.804","281.2"]]}}
1635444247.369557: {"type":"channel_data","connection_id":"60a4fc71-1312-4830-86f4-9eb98be106ac","message_id":2683,"id":"CRV-USD","channel":"v3_orderbook","contents":{"offset":"2693996381","bids":[],"asks":[["4.854","3512"]]}}
1635444247.3792908: {"type":"channel_data","connection_id":"60a4fc71-1312-4830-86f4-9eb98be106ac","message_id":2684,"id":"EOS-USD","channel":"v3_orderbook","contents":{"offset":"2693996388","bids":[["4.398","17682"]],"asks":[]}}
1635444247.37935: {"type":"channel_data","connection_id":"60a4fc71-1312-4830-86f4-9eb98be106ac","message_id":2685,"id":"SUSHI-USD","channel":"v3_orderbook","contents":{"offset":"2693996391","bids":[],"asks":[["10.818","94830"]]}}
1635444247.3793762: {"type":"channel_data","connection_id":"60a4fc71-1312-4830-86f4-9eb98be106ac","message_id":2686,"id":"ETH-USD","channel":"v3_orderbook","contents":{"offset":"2693996389","bids":[],"asks":[["4217.5","0"]]}}
1635444247.384976: {"type":"channel_data","connection_id":"60a4fc71-1312-4830-86f4-9eb98be106ac","message_id":2687,"id":"EOS-USD","channel":"v3_orderbook","contents":{"offset":"2693996395","bids":[],"asks":[["4.404","4419"]]}}
1635444247.385035: {"type":"channel_data","connection_id":"60a4fc71-1312-4830-86f4-9eb98be106ac","message_id":2688,"id":"ETH-USD","channel":"v3_orderbook","contents":{"offset":"2693996393","bids":[["4213.2","0"]],"asks":[]}}
1635444247.389581: {"type":"channel_data","connection_id":"60a4fc71-1312-4830-86f4-9eb98be106ac","message_id":2689,"id":"ETH-USD","channel":"v3_orderbook","contents":{"offset":"2693996399","bids":[["4214.3","0"]],"asks":[]}}
1635444247.3896399: {"type":"channel_data","connection_id":"60a4fc71-1312-4830-86f4-9eb98be106ac","message_id":2690,"id":"LTC-USD","channel":"v3_orderbook","contents":{"offset":"2693996396","bids":[["185.8","29.07"]],"asks":[]}}
1635444247.389666: {"type":"channel_data","connection_id":"60a4fc71-1312-4830-86f4-9eb98be106ac","message_id":2691,"id":"CRV-USD","channel":"v3_orderbook","contents":{"offset":"2693996397","bids":[["4.817","0"],["4.816","17772"]],"asks":[]}}
1635444247.3963578: {"type":"channel_data","connection_id":"60a4fc71-1312-4830-86f4-9eb98be106ac","message_id":2692,"id":"SUSHI-USD","channel":"v3_orderbook","contents":{"offset":"2693996406","bids":[],"asks":[["10.805","295.4"]]}}
1635444247.39643: {"type":"channel_data","connection_id":"60a4fc71-1312-4830-86f4-9eb98be106ac","message_id":2693,"id":"MKR-USD","channel":"v3_orderbook","contents":{"offset":"2693996403","bids":[],"asks":[["2383","17.488"]]}}
1635444247.397328: {"type":"channel_data","connection_id":"60a4fc71-1312-4830-86f4-9eb98be106ac","message_id":2694,"id":"SUSHI-USD","channel":"v3_orderbook","contents":{"offset":"2693996402","bids":[["10.723","0"],["10.721","3692.5"]],"asks":[]}}
1635444247.3983428: {"type":"channel_data","connection_id":"60a4fc71-1312-4830-86f4-9eb98be106ac","message_id":2695,"id":"ETH-USD","channel":"v3_orderbook","contents":{"offset":"2693996407","bids":[["4215","0"]],"asks":[]}}
1635444247.404554: {"type":"channel_data","connection_id":"60a4fc71-1312-4830-86f4-9eb98be106ac","message_id":2696,"id":"CRV-USD","channel":"v3_orderbook","contents":{"offset":"2693996409","bids":[["4.849","1031"]],"asks":[]}}
1635444247.404617: {"type":"channel_data","connection_id":"60a4fc71-1312-4830-86f4-9eb98be106ac","message_id":2697,"id":"ETH-USD","channel":"v3_orderbook","contents":{"offset":"2693996408","bids":[],"asks":[["4217.2","26.053"]]}}
1635444247.405032: {"type":"channel_data","connection_id":"60a4fc71-1312-4830-86f4-9eb98be106ac","message_id":2698,"id":"SUSHI-USD","channel":"v3_orderbook","contents":{"offset":"2693996414","bids":[],"asks":[["10.803","556.3"]]}}
1635444247.405675: {"type":"channel_data","connection_id":"60a4fc71-1312-4830-86f4-9eb98be106ac","message_id":2699,"id":"ETH-USD","channel":"v3_orderbook","contents":{"offset":"2693996411","bids":[],"asks":[["4216.4","5.238"]]}}
1635444247.408012: {"type":"channel_data","connection_id":"60a4fc71-1312-4830-86f4-9eb98be106ac","message_id":2700,"id":"ETH-USD","channel":"v3_orderbook","contents":{"offset":"2693996417","bids":[],"asks":[["4218.2","5878.297"]]}}
1635444247.408064: {"type":"channel_data","connection_id":"60a4fc71-1312-4830-86f4-9eb98be106ac","message_id":2701,"id":"SUSHI-USD","channel":"v3_orderbook","contents":{"offset":"2693996416","bids":[],"asks":[["10.805","600.9"]]}}
1635444247.421112: {"type":"channel_data","connection_id":"60a4fc71-1312-4830-86f4-9eb98be106ac","message_id":2702,"id":"EOS-USD","channel":"v3_orderbook","contents":{"offset":"2693996418","bids":[],"asks":[["4.402","22648"]]}}
1635444247.421178: {"type":"channel_data","connection_id":"60a4fc71-1312-4830-86f4-9eb98be106ac","message_id":2703,"id":"ETH-USD","channel":"v3_orderbook","contents":{"offset":"2693996424","bids":[],"asks":[["4221.8","1.777"]]}}
1635444247.43233: {"type":"channel_data","connection_id":"60a4fc71-1312-4830-86f4-9eb98be106ac","message_id":2704,"id":"CRV-USD","channel":"v3_orderbook","contents":{"offset":"2693996425","bids":[],"asks":[["4.857","227"]]}}
1635444247.4334888: {"type":"channel_data","connection_id":"60a4fc71-1312-4830-86f4-9eb98be106ac","message_id":2705,"id":"CRV-USD","channel":"v3_orderbook","contents":{"offset":"2693996431","bids":[["4.848","525"]],"asks":[]}}
1635444247.4335308: {"type":"channel_data","connection_id":"60a4fc71-1312-4830-86f4-9eb98be106ac","message_id":2706,"id":"CRV-USD","channel":"v3_orderbook","contents":{"offset":"2693996429","bids":[],"asks":[["4.865","8860"]]}}
1635444247.437173: {"type":"channel_data","connection_id":"60a4fc71-1312-4830-86f4-9eb98be106ac","message_id":2707,"id":"SUSHI-USD","channel":"v3_orderbook","contents":{"offset":"2693996434","bids":[["10.784","12882.8"]],"asks":[]}}
1635444247.4469178: {"type":"channel_data","connection_id":"60a4fc71-1312-4830-86f4-9eb98be106ac","message_id":2708,"id":"CRV-USD","channel":"v3_orderbook","contents":{"offset":"2693996444","bids":[["4.846","1582"]],"asks":[]}}
1635444247.446982: {"type":"channel_data","connection_id":"60a4fc71-1312-4830-86f4-9eb98be106ac","message_id":2709,"id":"ETH-USD","channel":"v3_orderbook","contents":{"offset":"2693996445","bids":[["4214.9","57.533"]],"asks":[]}}
1635444247.447857: {"type":"channel_data","connection_id":"60a4fc71-1312-4830-86f4-9eb98be106ac","message_id":2710,"id":"XMR-USD","channel":"v3_orderbook","contents":{"offset":"2693996439","bids":[],"asks":[["274.3","0"]]}}
1635444247.450349: {"type":"channel_data","connection_id":"60a4fc71-1312-4830-86f4-9eb98be106ac","message_id":2711,"id":"CRV-USD","channel":"v3_orderbook","contents":{"offset":"2693996454","bids":[["4.824","0"],["4.823","7227"]],"asks":[]}}
1635444247.453675: {"type":"channel_data","connection_id":"60a4fc71-1312-4830-86f4-9eb98be106ac","message_id":2712,"id":"ETH-USD","channel":"v3_orderbook","contents":{"offset":"2693996450","bids":[["4214.6","25.815"]],"asks":[]}}
1635444247.4537349: {"type":"channel_data","connection_id":"60a4fc71-1312-4830-86f4-9eb98be106ac","message_id":2713,"id":"CRV-USD","channel":"v3_orderbook","contents":{"offset":"2693996447","bids":[],"asks":[["4.857","5172"]]}}
1635444247.458019: {"type":"channel_data","connection_id":"60a4fc71-1312-4830-86f4-9eb98be106ac","message_id":2714,"id":"CRV-USD","channel":"v3_orderbook","contents":{"offset":"2693996462","bids":[["4.834","2072"]],"asks":[]}}
1635444247.4580789: {"type":"channel_data","connection_id":"60a4fc71-1312-4830-86f4-9eb98be106ac","message_id":2715,"id":"XMR-USD","channel":"v3_orderbook","contents":{"offset":"2693996459","bids":[["255.7","0"]],"asks":[]}}
1635444247.463316: {"type":"channel_data","connection_id":"60a4fc71-1312-4830-86f4-9eb98be106ac","message_id":2716,"id":"CRV-USD","channel":"v3_orderbook","contents":{"offset":"2693996468","bids":[["4.681","2500"]],"asks":[]}}
1635444247.4759538: {"type":"channel_data","connection_id":"60a4fc71-1312-4830-86f4-9eb98be106ac","message_id":2717,"id":"CRV-USD","channel":"v3_orderbook","contents":{"offset":"2693996475","bids":[["4.843","1503"]],"asks":[]}}
1635444247.476021: {"type":"channel_data","connection_id":"60a4fc71-1312-4830-86f4-9eb98be106ac","message_id":2718,"id":"CRV-USD","channel":"v3_orderbook","contents":{"offset":"2693996472","bids":[["4.85","4944"]],"asks":[]}}
1635444247.476044: {"type":"channel_data","connection_id":"60a4fc71-1312-4830-86f4-9eb98be106ac","message_id":2719,"id":"CRV-USD","channel":"v3_orderbook","contents":{"offset":"2693996478","bids":[],"asks":[["4.861","14069"]]}}
1635444247.489887: {"type":"channel_data","connection_id":"60a4fc71-1312-4830-86f4-9eb98be106ac","message_id":2720,"id":"ETH-USD","channel":"v3_orderbook","contents":{"offset":"2693996494","bids":[["4215.9","191.389"]],"asks":[]}}
1635444247.489949: {"type":"channel_data","connection_id":"60a4fc71-1312-4830-86f4-9eb98be106ac","message_id":2721,"id":"SUSHI-USD","channel":"v3_orderbook","contents":{"offset":"2693996490","bids":[],"asks":[["10.909","942.5"]]}}
1635444247.499879: {"type":"channel_data","connection_id":"60a4fc71-1312-4830-86f4-9eb98be106ac","message_id":2722,"id":"SUSHI-USD","channel":"v3_orderbook","contents":{"offset":"2693996498","bids":[["10.786","3974.9"]],"asks":[]}}
1635444247.5051289: {"type":"channel_data","connection_id":"60a4fc71-1312-4830-86f4-9eb98be106ac","message_id":2723,"id":"SUSHI-USD","channel":"v3_orderbook","contents":{"offset":"2693996504","bids":[["10.786","266.6"]],"asks":[]}}
1635444247.507811: {"type":"channel_data","connection_id":"60a4fc71-1312-4830-86f4-9eb98be106ac","message_id":2724,"id":"ETH-USD","channel":"v3_trades","contents":{"trades":[{"size":"9.833","side":"SELL","price":"4215.9","createdAt":"2021-10-28T18:04:07.526Z"},{"size":"108.611","side":"SELL","price":"4215.9","createdAt":"2021-10-28T18:04:07.526Z"}]}}
1635444247.5078568: {"type":"channel_data","connection_id":"60a4fc71-1312-4830-86f4-9eb98be106ac","message_id":2725,"id":"SUSHI-USD","channel":"v3_orderbook","contents":{"offset":"2693996508","bids":[],"asks":[["10.798","0"]]}}
1635444247.509699: {"type":"channel_data","connection_id":"60a4fc71-1312-4830-86f4-9eb98be106ac","message_id":2726,"id":"ETH-USD","channel":"v3_orderbook","contents":{"offset":"2693996511","bids":[],"asks":[["4219.7","1.659"]]}}
1635444247.512108: {"type":"channel_data","connection_id":"60a4fc71-1312-4830-86f4-9eb98be106ac","message_id":2727,"id":"CRV-USD","channel":"v3_orderbook","contents":{"offset":"2693996513","bids":[["4.814","2066"]],"asks":[]}}
1635444247.519976: {"type":"channel_data","connection_id":"60a4fc71-1312-4830-86f4-9eb98be106ac","message_id":2728,"id":"ETH-USD","channel":"v3_orderbook","contents":{"offset":"2693996516","bids":[["4211.8","1410.27"]],"asks":[]}}
1635444247.520035: {"type":"channel_data","connection_id":"60a4fc71-1312-4830-86f4-9eb98be106ac","message_id":2729,"id":"CRV-USD","channel":"v3_orderbook","contents":{"offset":"2693996520","bids":[],"asks":[["5.021","2500"]]}}
1635444247.5200598: {"type":"channel_data","connection_id":"60a4fc71-1312-4830-86f4-9eb98be106ac","message_id":2730,"id":"ETH-USD","channel":"v3_orderbook","contents":{"offset":"2693996514","bids":[["4213.8","58.77"]],"asks":[]}}
1635444247.5200782: {"type":"channel_data","connection_id":"60a4fc71-1312-4830-86f4-9eb98be106ac","message_id":2731,"id":"SUSHI-USD","channel":"v3_orderbook","contents":{"offset":"2693996517","bids":[],"asks":[["10.815","775.4"]]}}
1635444247.52751: {"type":"channel_data","connection_id":"60a4fc71-1312-4830-86f4-9eb98be106ac","message_id":2732,"id":"SUSHI-USD","channel":"v3_orderbook","contents":{"offset":"2693996523","bids":[],"asks":[["10.813","0"]]}}
1635444247.529682: {"type":"channel_data","connection_id":"60a4fc71-1312-4830-86f4-9eb98be106ac","message_id":2733,"id":"UMA-USD","channel":"v3_orderbook","contents":{"offset":"2693996528","bids":[["11.27","29527.1"]],"asks":[]}}
1635444247.5391119: {"type":"channel_data","connection_id":"60a4fc71-1312-4830-86f4-9eb98be106ac","message_id":2734,"id":"EOS-USD","channel":"v3_orderbook","contents":{"offset":"2693996529","bids":[],"asks":[["4.404","3282"]]}}
1635444247.53919: {"type":"channel_data","connection_id":"60a4fc71-1312-4830-86f4-9eb98be106ac","message_id":2735,"id":"CRV-USD","channel":"v3_orderbook","contents":{"offset":"2693996534","bids":[],"asks":[["4.857","5830"]]}}
1635444247.543709: {"type":"channel_data","connection_id":"60a4fc71-1312-4830-86f4-9eb98be106ac","message_id":2736,"id":"EOS-USD","channel":"v3_orderbook","contents":{"offset":"2693996533","bids":[["4.399","0"]],"asks":[]}}
1635444247.54828: {"type":"channel_data","connection_id":"60a4fc71-1312-4830-86f4-9eb98be106ac","message_id":2737,"id":"CRV-USD","channel":"v3_orderbook","contents":{"offset":"2693996540","bids":[],"asks":[["4.856","747"]]}}
1635444247.548365: {"type":"channel_data","connection_id":"60a4fc71-1312-4830-86f4-9eb98be106ac","message_id":2738,"id":"EOS-USD","channel":"v3_orderbook","contents":{"offset":"2693996538","bids":[["4.398","16545"]],"asks":[]}}
1635444247.556274: {"type":"channel_data","connection_id":"60a4fc71-1312-4830-86f4-9eb98be106ac","message_id":2739,"id":"EOS-USD","channel":"v3_orderbook","contents":{"offset":"2693996545","bids":[],"asks":[["4.403","4945"]]}}
1635444247.5564: {"type":"channel_data","connection_id":"60a4fc71-1312-4830-86f4-9eb98be106ac","message_id":2740,"id":"UMA-USD","channel":"v3_orderbook","contents":{"offset":"2693996551","bids":[["11.27","29261.6"]],"asks":[]}}
1635444247.561553: {"type":"channel_data","connection_id":"60a4fc71-1312-4830-86f4-9eb98be106ac","message_id":2741,"id":"SUSHI-USD","channel":"v3_orderbook","contents":{"offset":"2693996553","bids":[],"asks":[["10.802","966.4"]]}}
1635444247.5658: {"type":"channel_data","connection_id":"60a4fc71-1312-4830-86f4-9eb98be106ac","message_id":2742,"id":"LTC-USD","channel":"v3_orderbook","contents":{"offset":"2693996556","bids":[["187.6","152.74"]],"asks":[]}}
1635444247.5690749: {"type":"channel_data","connection_id":"60a4fc71-1312-4830-86f4-9eb98be106ac","message_id":2743,"id":"ETH-USD","channel":"v3_orderbook","contents":{"offset":"2693996562","bids":[],"asks":[["4216.4","23.046"]]}}
1635444247.571174: {"type":"channel_data","connection_id":"60a4fc71-1312-4830-86f4-9eb98be106ac","message_id":2744,"id":"ETH-USD","channel":"v3_orderbook","contents":{"offset":"2693996566","bids":[],"asks":[["4238","14.866"],["4239","21.5"]]}}
1635444247.574753: {"type":"channel_data","connection_id":"60a4fc71-1312-4830-86f4-9eb98be106ac","message_id":2745,"id":"ETH-USD","channel":"v3_orderbook","contents":{"offset":"2693996564","bids":[],"asks":[["4222.4","19.874"]]}}
1635444247.583752: {"type":"channel_data","connection_id":"60a4fc71-1312-4830-86f4-9eb98be106ac","message_id":2746,"id":"SUSHI-USD","channel":"v3_orderbook","contents":{"offset":"2693996583","bids":[],"asks":[["10.8","14119.6"]]}}
1635444247.5897322: {"type":"channel_data","connection_id":"60a4fc71-1312-4830-86f4-9eb98be106ac","message_id":2747,"id":"CRV-USD","channel":"v3_orderbook","contents":{"offset":"2693996581","bids":[["4.848","5393"]],"asks":[]}}
1635444247.5932941: {"type":"channel_data","connection_id":"60a4fc71-1312-4830-86f4-9eb98be106ac","message_id":2748,"id":"SUSHI-USD","channel":"v3_orderbook","contents":{"offset":"2693996590","bids":[],"asks":[["10.804","15"]]}}
1635444247.597404: {"type":"channel_data","connection_id":"60a4fc71-1312-4830-86f4-9eb98be106ac","message_id":2749,"id":"SUSHI-USD","channel":"v3_orderbook","contents":{"offset":"2693996589","bids":[],"asks":[["10.807","2067.3"]]}}
1635444247.597526: {"type":"channel_data","connection_id":"60a4fc71-1312-4830-86f4-9eb98be106ac","message_id":2750,"id":"ETH-USD","channel":"v3_orderbook","contents":{"offset":"2693996596","bids":[],"asks":[["4216","230.452"]]}}
1635444247.6000068: {"type":"channel_data","connection_id":"60a4fc71-1312-4830-86f4-9eb98be106ac","message_id":2751,"id":"CRV-USD","channel":"v3_orderbook","contents":{"offset":"2693996601","bids":[],"asks":[["4.906","0"]]}}
1635444247.6000829: {"type":"channel_data","connection_id":"60a4fc71-1312-4830-86f4-9eb98be106ac","message_id":2752,"id":"ETH-USD","channel":"v3_orderbook","contents":{"offset":"2693996600","bids":[["4213.8","0"]],"asks":[]}}
1635444247.609765: {"type":"channel_data","connection_id":"60a4fc71-1312-4830-86f4-9eb98be106ac","message_id":2753,"id":"MKR-USD","channel":"v3_orderbook","contents":{"offset":"2693996606","bids":[],"asks":[["2385","92.953"]]}}
1635444247.609843: {"type":"channel_data","connection_id":"60a4fc71-1312-4830-86f4-9eb98be106ac","message_id":2754,"id":"CRV-USD","channel":"v3_orderbook","contents":{"offset":"2693996603","bids":[],"asks":[["4.856","5692"]]}}
1635444247.626417: {"type":"channel_data","connection_id":"60a4fc71-1312-4830-86f4-9eb98be106ac","message_id":2755,"id":"EOS-USD","channel":"v3_orderbook","contents":{"offset":"2693996611","bids":[],"asks":[["4.403","6082"]]}}
1635444247.626533: {"type":"channel_data","connection_id":"60a4fc71-1312-4830-86f4-9eb98be106ac","message_id":2756,"id":"SUSHI-USD","channel":"v3_orderbook","contents":{"offset":"2693996616","bids":[],"asks":[["10.792","1209.2"]]}}
1635444247.626592: {"type":"channel_data","connection_id":"60a4fc71-1312-4830-86f4-9eb98be106ac","message_id":2757,"id":"CRV-USD","channel":"v3_orderbook","contents":{"offset":"2693996622","bids":[["4.848","5770"]],"asks":[]}}
1635444247.632511: {"type":"channel_data","connection_id":"60a4fc71-1312-4830-86f4-9eb98be106ac","message_id":2758,"id":"CRV-USD","channel":"v3_orderbook","contents":{"offset":"2693996620","bids":[["4.847","13328"]],"asks":[]}}
1635444247.637918: {"type":"channel_data","connection_id":"60a4fc71-1312-4830-86f4-9eb98be106ac","message_id":2759,"id":"CRV-USD","channel":"v3_orderbook","contents":{"offset":"2693996632","bids":[],"asks":[["4.854","2512"]]}}
1635444247.6387: {"type":"channel_data","connection_id":"60a4fc71-1312-4830-86f4-9eb98be106ac","message_id":2760,"id":"SUSHI-USD","channel":"v3_orderbook","contents":{"offset":"2693996633","bids":[["10.785","0"]],"asks":[]}}
1635444247.65225: {"type":"channel_data","connection_id":"60a4fc71-1312-4830-86f4-9eb98be106ac","message_id":2761,"id":"MKR-USD","channel":"v3_orderbook","contents":{"offset":"2693996639","bids":[["2375","76.546"]],"asks":[]}}
1635444247.6523578: {"type":"channel_data","connection_id":"60a4fc71-1312-4830-86f4-9eb98be106ac","message_id":2762,"id":"SUSHI-USD","channel":"v3_orderbook","contents":{"offset":"2693996641","bids":[["10.752","0"],["10.75","101.9"]],"asks":[]}}
1635444247.659658: {"type":"channel_data","connection_id":"60a4fc71-1312-4830-86f4-9eb98be106ac","message_id":2763,"id":"ETH-USD","channel":"v3_orderbook","contents":{"offset":"2693996646","bids":[["4212.4","62.481"]],"asks":[]}}
1635444247.6597388: {"type":"channel_data","connection_id":"60a4fc71-1312-4830-86f4-9eb98be106ac","message_id":2764,"id":"ETH-USD","channel":"v3_orderbook","contents":{"offset":"2693996643","bids":[["4212.3","1.692"]],"asks":[]}}
1635444247.663056: {"type":"channel_data","connection_id":"60a4fc71-1312-4830-86f4-9eb98be106ac","message_id":2765,"id":"EOS-USD","channel":"v3_orderbook","contents":{"offset":"2693996642","bids":[],"asks":[["4.403","4945"]]}}
1635444247.674324: {"type":"channel_data","connection_id":"60a4fc71-1312-4830-86f4-9eb98be106ac","message_id":2766,"id":"CRV-USD","channel":"v3_orderbook","contents":{"offset":"2693996654","bids":[],"asks":[["4.857","6861"]]}}
1635444247.684582: {"type":"channel_data","connection_id":"60a4fc71-1312-4830-86f4-9eb98be106ac","message_id":2767,"id":"SUSHI-USD","channel":"v3_orderbook","contents":{"offset":"2693996657","bids":[],"asks":[["10.831","101.9"],["10.833","0"]]}}
1635444247.684714: {"type":"channel_data","connection_id":"60a4fc71-1312-4830-86f4-9eb98be106ac","message_id":2768,"id":"CRV-USD","channel":"v3_orderbook","contents":{"offset":"2693996663","bids":[],"asks":[["4.856","6310"]]}}
1635444247.684771: {"type":"channel_data","connection_id":"60a4fc71-1312-4830-86f4-9eb98be106ac","message_id":2769,"id":"ETH-USD","channel":"v3_orderbook","contents":{"offset":"2693996658","bids":[],"asks":[["4219.5","1.6"]]}}
1635444247.687636: {"type":"channel_data","connection_id":"60a4fc71-1312-4830-86f4-9eb98be106ac","message_id":2770,"id":"CRV-USD","channel":"v3_orderbook","contents":{"offset":"2693996661","bids":[],"asks":[["4.854","3512"]]}}
1635444247.711659: {"type":"channel_data","connection_id":"60a4fc71-1312-4830-86f4-9eb98be106ac","message_id":2771,"id":"CRV-USD","channel":"v3_orderbook","contents":{"offset":"2693996681","bids":[],"asks":[["4.856","6156"]]}}
1635444247.723135: {"type":"channel_data","connection_id":"60a4fc71-1312-4830-86f4-9eb98be106ac","message_id":2772,"id":"ETH-USD","channel":"v3_orderbook","contents":{"offset":"2693996689","bids":[],"asks":[["4217.7","20.604"]]}}
1635444247.72721: {"type":"channel_data","connection_id":"60a4fc71-1312-4830-86f4-9eb98be106ac","message_id":2773,"id":"ETH-USD","channel":"v3_orderbook","contents":{"offset":"2693996688","bids":[["4195.2","2.384"]],"asks":[]}}
1635444247.7273312: {"type":"channel_data","connection_id":"60a4fc71-1312-4830-86f4-9eb98be106ac","message_id":2774,"id":"SUSHI-USD","channel":"v3_orderbook","contents":{"offset":"2693996685","bids":[["10.783","3709.5"]],"asks":[]}}
1635444247.7273889: {"type":"channel_data","connection_id":"60a4fc71-1312-4830-86f4-9eb98be106ac","message_id":2775,"id":"ETH-USD","channel":"v3_orderbook","contents":{"offset":"2693996691","bids":[],"asks":[["4217.1","1424.384"]]}}
1635444247.7277482: {"type":"channel_data","connection_id":"60a4fc71-1312-4830-86f4-9eb98be106ac","message_id":2776,"id":"ETH-USD","channel":"v3_orderbook","contents":{"offset":"2693996690","bids":[],"asks":[["4218.6","2.026"]]}}
1635444247.73152: {"type":"channel_data","connection_id":"60a4fc71-1312-4830-86f4-9eb98be106ac","message_id":2777,"id":"ETH-USD","channel":"v3_orderbook","contents":{"offset":"2693996694","bids":[],"asks":[["4216.8","26.394"]]}}
1635444247.735053: {"type":"channel_data","connection_id":"60a4fc71-1312-4830-86f4-9eb98be106ac","message_id":2778,"id":"SUSHI-USD","channel":"v3_orderbook","contents":{"offset":"2693996700","bids":[["10.767","4130.4"]],"asks":[]}}
1635444247.735132: {"type":"channel_data","connection_id":"60a4fc71-1312-4830-86f4-9eb98be106ac","message_id":2779,"id":"CRV-USD","channel":"v3_orderbook","contents":{"offset":"2693996702","bids":[],"asks":[["4.86","741"]]}}
1635444247.7395341: {"type":"channel_data","connection_id":"60a4fc71-1312-4830-86f4-9eb98be106ac","message_id":2780,"id":"EOS-USD","channel":"v3_orderbook","contents":{"offset":"2693996701","bids":[],"asks":[["4.403","6082"]]}}
1635444247.743399: {"type":"channel_data","connection_id":"60a4fc71-1312-4830-86f4-9eb98be106ac","message_id":2781,"id":"CRV-USD","channel":"v3_orderbook","contents":{"offset":"2693996707","bids":[],"asks":[["4.858","680"]]}}
1635444247.755562: {"type":"channel_data","connection_id":"60a4fc71-1312-4830-86f4-9eb98be106ac","message_id":2782,"id":"SUSHI-USD","channel":"v3_orderbook","contents":{"offset":"2693996715","bids":[["10.767","416.5"]],"asks":[]}}
1635444247.7575629: {"type":"channel_data","connection_id":"60a4fc71-1312-4830-86f4-9eb98be106ac","message_id":2783,"id":"CRV-USD","channel":"v3_orderbook","contents":{"offset":"2693996711","bids":[],"asks":[["4.854","2512"]]}}
1635444247.7576241: {"type":"channel_data","connection_id":"60a4fc71-1312-4830-86f4-9eb98be106ac","message_id":2784,"id":"ETH-USD","channel":"v3_orderbook","contents":{"offset":"2693996714","bids":[["4215.5","22.496"]],"asks":[]}}
1635444247.760857: {"type":"channel_data","connection_id":"60a4fc71-1312-4830-86f4-9eb98be106ac","message_id":2785,"id":"ETH-USD","channel":"v3_orderbook","contents":{"offset":"2693996719","bids":[["4214.4","0"]],"asks":[]}}
1635444247.7614179: {"type":"channel_data","connection_id":"60a4fc71-1312-4830-86f4-9eb98be106ac","message_id":2786,"id":"EOS-USD","channel":"v3_orderbook","contents":{"offset":"2693996720","bids":[["4.4","12800"]],"asks":[]}}
1635444247.766913: {"type":"channel_data","connection_id":"60a4fc71-1312-4830-86f4-9eb98be106ac","message_id":2787,"id":"SUSHI-USD","channel":"v3_orderbook","contents":{"offset":"2693996723","bids":[["10.782","8828.2"]],"asks":[]}}
1635444247.7669609: {"type":"channel_data","connection_id":"60a4fc71-1312-4830-86f4-9eb98be106ac","message_id":2788,"id":"EOS-USD","channel":"v3_orderbook","contents":{"offset":"2693996725","bids":[],"asks":[["4.403","4945"]]}}
1635444247.770808: {"type":"channel_data","connection_id":"60a4fc71-1312-4830-86f4-9eb98be106ac","message_id":2789,"id":"XMR-USD","channel":"v3_orderbook","contents":{"offset":"2693996731","bids":[["264.7","434.34"]],"asks":[]}}
1635444247.776833: {"type":"channel_data","connection_id":"60a4fc71-1312-4830-86f4-9eb98be106ac","message_id":2790,"id":"SUSHI-USD","channel":"v3_orderbook","contents":{"offset":"2693996730","bids":[["10.761","3713.9"]],"asks":[]}}
1635444247.780022: {"type":"channel_data","connection_id":"60a4fc71-1312-4830-86f4-9eb98be106ac","message_id":2791,"id":"EOS-USD","channel":"v3_orderbook","contents":{"offset":"2693996736","bids":[["4.4","11663"]],"asks":[]}}
1635444247.780107: {"type":"channel_data","connection_id":"60a4fc71-1312-4830-86f4-9eb98be106ac","message_id":2792,"id":"XMR-USD","channel":"v3_orderbook","contents":{"offset":"2693996733","bids":[["265","75.75"]],"asks":[]}}
1635444247.790077: {"type":"channel_data","connection_id":"60a4fc71-1312-4830-86f4-9eb98be106ac","message_id":2793,"id":"ETH-USD","channel":"v3_orderbook","contents":{"offset":"2693996745","bids":[["4213.9","58.77"]],"asks":[]}}
1635444247.790158: {"type":"channel_data","connection_id":"60a4fc71-1312-4830-86f4-9eb98be106ac","message_id":2794,"id":"XMR-USD","channel":"v3_orderbook","contents":{"offset":"2693996739","bids":[],"asks":[["265.6","38"]]}}
1635444247.790194: {"type":"channel_data","connection_id":"60a4fc71-1312-4830-86f4-9eb98be106ac","message_id":2795,"id":"XMR-USD","channel":"v3_orderbook","contents":{"offset":"2693996744","bids":[],"asks":[["265.4","286.73"]]}}
1635444247.7902222: {"type":"channel_data","connection_id":"60a4fc71-1312-4830-86f4-9eb98be106ac","message_id":2796,"id":"CRV-USD","channel":"v3_orderbook","contents":{"offset":"2693996740","bids":[],"asks":[["4.862","5279"]]}}
1635444247.792227: {"type":"channel_data","connection_id":"60a4fc71-1312-4830-86f4-9eb98be106ac","message_id":2797,"id":"ETH-USD","channel":"v3_orderbook","contents":{"offset":"2693996746","bids":[],"asks":[["4217.4","45.1"]]}}
1635444247.801541: {"type":"channel_data","connection_id":"60a4fc71-1312-4830-86f4-9eb98be106ac","message_id":2798,"id":"ETH-USD","channel":"v3_orderbook","contents":{"offset":"2693996753","bids":[],"asks":[["4216","230.642"]]}}
1635444247.801621: {"type":"channel_data","connection_id":"60a4fc71-1312-4830-86f4-9eb98be106ac","message_id":2799,"id":"EOS-USD","channel":"v3_orderbook","contents":{"offset":"2693996751","bids":[],"asks":[["4.402","11323"]]}}
1635444247.8016598: {"type":"channel_data","connection_id":"60a4fc71-1312-4830-86f4-9eb98be106ac","message_id":2800,"id":"ETH-USD","channel":"v3_orderbook","contents":{"offset":"2693996749","bids":[["4215.9","201.009"]],"asks":[]}}
1635444247.8016891: {"type":"channel_data","connection_id":"60a4fc71-1312-4830-86f4-9eb98be106ac","message_id":2801,"id":"CRV-USD","channel":"v3_orderbook","contents":{"offset":"2693996752","bids":[],"asks":[["4.854","3512"]]}}
1635444247.810034: {"type":"channel_data","connection_id":"60a4fc71-1312-4830-86f4-9eb98be106ac","message_id":2802,"id":"SUSHI-USD","channel":"v3_orderbook","contents":{"offset":"2693996758","bids":[],"asks":[["10.794","8288.9"]]}}
1635444247.8414772: {"type":"channel_data","connection_id":"60a4fc71-1312-4830-86f4-9eb98be106ac","message_id":2803,"id":"CRV-USD","channel":"v3_orderbook","contents":{"offset":"2693996761","bids":[["4.819","925"],["4.818","8174"]],"asks":[]}}
1635444247.8415518: {"type":"channel_data","connection_id":"60a4fc71-1312-4830-86f4-9eb98be106ac","message_id":2804,"id":"ETH-USD","channel":"v3_orderbook","contents":{"offset":"2693996760","bids":[["4211","10089.179"]],"asks":[]}}
1635444247.847101: {"type":"channel_data","connection_id":"60a4fc71-1312-4830-86f4-9eb98be106ac","message_id":2805,"id":"ETH-USD","channel":"v3_orderbook","contents":{"offset":"2693996762","bids":[],"asks":[["4218.2","5878.307"]]}}
1635444247.856556: {"type":"channel_data","connection_id":"60a4fc71-1312-4830-86f4-9eb98be106ac","message_id":2806,"id":"SUSHI-USD","channel":"v3_orderbook","contents":{"offset":"2693996766","bids":[],"asks":[["10.8","13746.8"]]}}
1635444247.856673: {"type":"channel_data","connection_id":"60a4fc71-1312-4830-86f4-9eb98be106ac","message_id":2807,"id":"SUSHI-USD","channel":"v3_orderbook","contents":{"offset":"2693996771","bids":[["10.669","926"]],"asks":[]}}
1635444247.8583958: {"type":"channel_data","connection_id":"60a4fc71-1312-4830-86f4-9eb98be106ac","message_id":2808,"id":"SUSHI-USD","channel":"v3_orderbook","contents":{"offset":"2693996765","bids":[["10.761","0"]],"asks":[]}}
1635444247.861086: {"type":"channel_data","connection_id":"60a4fc71-1312-4830-86f4-9eb98be106ac","message_id":2809,"id":"SUSHI-USD","channel":"v3_orderbook","contents":{"offset":"2693996777","bids":[["10.732","0"],["10.729","4095.7"]],"asks":[]}}
1635444247.8611772: {"type":"channel_data","connection_id":"60a4fc71-1312-4830-86f4-9eb98be106ac","message_id":2810,"id":"EOS-USD","channel":"v3_orderbook","contents":{"offset":"2693996779","bids":[],"asks":[["4.404","4418"]]}}
1635444247.866289: {"type":"channel_data","connection_id":"60a4fc71-1312-4830-86f4-9eb98be106ac","message_id":2811,"id":"LTC-USD","channel":"v3_orderbook","contents":{"offset":"2693996783","bids":[],"asks":[["189.2","574.36"],["190.4","0"]]}}
1635444247.870902: {"type":"channel_data","connection_id":"60a4fc71-1312-4830-86f4-9eb98be106ac","message_id":2812,"id":"EOS-USD","channel":"v3_orderbook","contents":{"offset":"2693996780","bids":[["4.4","12800"]],"asks":[]}}
1635444247.870972: {"type":"channel_data","connection_id":"60a4fc71-1312-4830-86f4-9eb98be106ac","message_id":2813,"id":"XMR-USD","channel":"v3_orderbook","contents":{"offset":"2693996790","bids":[],"asks":[["265.5","97.84"]]}}
1635444247.87316: {"type":"channel_data","connection_id":"60a4fc71-1312-4830-86f4-9eb98be106ac","message_id":2814,"id":"SUSHI-USD","channel":"v3_orderbook","contents":{"offset":"2693996792","bids":[["10.721","444.9"],["10.718","3247.6"]],"asks":[]}}
1635444247.881742: {"type":"channel_data","connection_id":"60a4fc71-1312-4830-86f4-9eb98be106ac","message_id":2815,"id":"CRV-USD","channel":"v3_orderbook","contents":{"offset":"2693996802","bids":[],"asks":[["4.86","1772"]]}}
1635444247.897689: {"type":"channel_data","connection_id":"60a4fc71-1312-4830-86f4-9eb98be106ac","message_id":2816,"id":"SUSHI-USD","channel":"v3_orderbook","contents":{"offset":"2693996803","bids":[["10.716","0"],["10.713","5123"]],"asks":[]}}
1635444247.901736: {"type":"channel_data","connection_id":"60a4fc71-1312-4830-86f4-9eb98be106ac","message_id":2817,"id":"ETH-USD","channel":"v3_orderbook","contents":{"offset":"2693996804","bids":[],"asks":[["4216","227.72"]]}}
1635444247.9157279: {"type":"channel_data","connection_id":"60a4fc71-1312-4830-86f4-9eb98be106ac","message_id":2818,"id":"ETH-USD","channel":"v3_orderbook","contents":{"offset":"2693996815","bids":[],"asks":[["4216","227.62"]]}}
1635444247.91581: {"type":"channel_data","connection_id":"60a4fc71-1312-4830-86f4-9eb98be106ac","message_id":2819,"id":"SUSHI-USD","channel":"v3_orderbook","contents":{"offset":"2693996814","bids":[],"asks":[["10.803","278.5"]]}}
1635444247.915849: {"type":"channel_data","connection_id":"60a4fc71-1312-4830-86f4-9eb98be106ac","message_id":2820,"id":"EOS-USD","channel":"v3_orderbook","contents":{"offset":"2693996810","bids":[["4.399","1136"]],"asks":[]}}
1635444247.9175549: {"type":"channel_data","connection_id":"60a4fc71-1312-4830-86f4-9eb98be106ac","message_id":2821,"id":"ETH-USD","channel":"v3_orderbook","contents":{"offset":"2693996824","bids":[],"asks":[["4216.6","84.178"]]}}
1635444247.9176111: {"type":"channel_data","connection_id":"60a4fc71-1312-4830-86f4-9eb98be106ac","message_id":2822,"id":"EOS-USD","channel":"v3_orderbook","contents":{"offset":"2693996820","bids":[],"asks":[["4.405","10215"]]}}
1635444247.9205592: {"type":"channel_data","connection_id":"60a4fc71-1312-4830-86f4-9eb98be106ac","message_id":2823,"id":"EOS-USD","channel":"v3_orderbook","contents":{"offset":"2693996827","bids":[],"asks":[["4.403","16267"]]}}
1635444247.929473: {"type":"channel_data","connection_id":"60a4fc71-1312-4830-86f4-9eb98be106ac","message_id":2824,"id":"ETH-USD","channel":"v3_trades","contents":{"trades":[{"size":"0.1","side":"BUY","price":"4216","createdAt":"2021-10-28T18:04:07.950Z"}]}}
1635444247.940077: {"type":"channel_data","connection_id":"60a4fc71-1312-4830-86f4-9eb98be106ac","message_id":2825,"id":"CRV-USD","channel":"v3_orderbook","contents":{"offset":"2693996842","bids":[],"asks":[["4.861","14558"]]}}
1635444247.9583611: {"type":"channel_data","connection_id":"60a4fc71-1312-4830-86f4-9eb98be106ac","message_id":2826,"id":"SUSHI-USD","channel":"v3_orderbook","contents":{"offset":"2693996847","bids":[],"asks":[["10.792","0"]]}}
1635444247.986162: {"type":"channel_data","connection_id":"60a4fc71-1312-4830-86f4-9eb98be106ac","message_id":2827,"id":"LTC-USD","channel":"v3_orderbook","contents":{"offset":"2693996863","bids":[["186.1","56.53"]],"asks":[]}}
1635444247.9862459: {"type":"channel_data","connection_id":"60a4fc71-1312-4830-86f4-9eb98be106ac","message_id":2828,"id":"MKR-USD","channel":"v3_orderbook","contents":{"offset":"2693996867","bids":[],"asks":[["2383","25.942"]]}}
1635444247.986281: {"type":"channel_data","connection_id":"60a4fc71-1312-4830-86f4-9eb98be106ac","message_id":2829,"id":"ETH-USD","channel":"v3_orderbook","contents":{"offset":"2693996872","bids":[["4215.9","9.62"]],"asks":[]}}
1635444248.010457: {"type":"channel_data","connection_id":"60a4fc71-1312-4830-86f4-9eb98be106ac","message_id":2830,"id":"XMR-USD","channel":"v3_orderbook","contents":{"offset":"2693996884","bids":[["264.7","736.17"]],"asks":[]}}
1635444248.018922: {"type":"channel_data","connection_id":"60a4fc71-1312-4830-86f4-9eb98be106ac","message_id":2831,"id":"XMR-USD","channel":"v3_orderbook","contents":{"offset":"2693996886","bids":[],"asks":[["265.7","3134.94"]]}}
1635444248.022431: {"type":"channel_data","connection_id":"60a4fc71-1312-4830-86f4-9eb98be106ac","message_id":2832,"id":"ETH-USD","channel":"v3_orderbook","contents":{"offset":"2693996890","bids":[["4213.2","47.72"]],"asks":[]}}
1635444248.022487: {"type":"channel_data","connection_id":"60a4fc71-1312-4830-86f4-9eb98be106ac","message_id":2833,"id":"SUSHI-USD","channel":"v3_orderbook","contents":{"offset":"2693996892","bids":[],"asks":[["10.802","579.6"]]}}
1635444248.030213: {"type":"channel_data","connection_id":"60a4fc71-1312-4830-86f4-9eb98be106ac","message_id":2834,"id":"ETH-USD","channel":"v3_orderbook","contents":{"offset":"2693996894","bids":[["4212.5","38.5"]],"asks":[]}}
1635444248.030275: {"type":"channel_data","connection_id":"60a4fc71-1312-4830-86f4-9eb98be106ac","message_id":2835,"id":"ETH-USD","channel":"v3_orderbook","contents":{"offset":"2693996895","bids":[["4213.9","0"]],"asks":[]}}
1635444248.045428: {"type":"channel_data","connection_id":"60a4fc71-1312-4830-86f4-9eb98be106ac","message_id":2836,"id":"ETH-USD","channel":"v3_orderbook","contents":{"offset":"2693996899","bids":[],"asks":[["4237.8","11.866"],["4238","3"]]}}
1635444248.045494: {"type":"channel_data","connection_id":"60a4fc71-1312-4830-86f4-9eb98be106ac","message_id":2837,"id":"UMA-USD","channel":"v3_orderbook","contents":{"offset":"2693996900","bids":[["11.27","29527.1"]],"asks":[]}}
1635444248.052959: {"type":"channel_data","connection_id":"60a4fc71-1312-4830-86f4-9eb98be106ac","message_id":2838,"id":"ETH-USD","channel":"v3_orderbook","contents":{"offset":"2693996907","bids":[["4215.9","0"]],"asks":[]}}
1635444248.056175: {"type":"channel_data","connection_id":"60a4fc71-1312-4830-86f4-9eb98be106ac","message_id":2839,"id":"ETH-USD","channel":"v3_orderbook","contents":{"offset":"2693996908","bids":[],"asks":[["4215.7","23.744"]]}}
1635444248.056212: {"type":"channel_data","connection_id":"60a4fc71-1312-4830-86f4-9eb98be106ac","message_id":2840,"id":"CRV-USD","channel":"v3_orderbook","contents":{"offset":"2693996904","bids":[],"asks":[["4.864","802"]]}}
1635444248.056236: {"type":"channel_data","connection_id":"60a4fc71-1312-4830-86f4-9eb98be106ac","message_id":2841,"id":"XMR-USD","channel":"v3_orderbook","contents":{"offset":"2693996903","bids":[["255.7","40"]],"asks":[]}}
1635444248.0637481: {"type":"channel_data","connection_id":"60a4fc71-1312-4830-86f4-9eb98be106ac","message_id":2842,"id":"UMA-USD","channel":"v3_orderbook","contents":{"offset":"2693996915","bids":[["11.27","29261.6"]],"asks":[]}}
1635444248.06381: {"type":"channel_data","connection_id":"60a4fc71-1312-4830-86f4-9eb98be106ac","message_id":2843,"id":"ETH-USD","channel":"v3_orderbook","contents":{"offset":"2693996912","bids":[["4212.1","0"]],"asks":[]}}
1635444248.101485: {"type":"channel_data","connection_id":"60a4fc71-1312-4830-86f4-9eb98be106ac","message_id":2844,"id":"ETH-USD","channel":"v3_orderbook","contents":{"offset":"2693996923","bids":[],"asks":[["4216.4","5.238"]]}}
1635444248.101548: {"type":"channel_data","connection_id":"60a4fc71-1312-4830-86f4-9eb98be106ac","message_id":2845,"id":"ETH-USD","channel":"v3_orderbook","contents":{"offset":"2693996925","bids":[],"asks":[["4215.7","0"]]}}
1635444248.101572: {"type":"channel_data","connection_id":"60a4fc71-1312-4830-86f4-9eb98be106ac","message_id":2846,"id":"LTC-USD","channel":"v3_orderbook","contents":{"offset":"2693996929","bids":[["187.4","53235.73"],["187.2","61"]],"asks":[]}}
1635444248.1015959: {"type":"channel_data","connection_id":"60a4fc71-1312-4830-86f4-9eb98be106ac","message_id":2847,"id":"ETH-USD","channel":"v3_orderbook","contents":{"offset":"2693996928","bids":[],"asks":[["4216","217.837"]]}}
1635444248.1088781: {"type":"channel_data","connection_id":"60a4fc71-1312-4830-86f4-9eb98be106ac","message_id":2848,"id":"ETH-USD","channel":"v3_orderbook","contents":{"offset":"2693996934","bids":[],"asks":[["4215.8","9.783"]]}}
1635444248.114045: {"type":"channel_data","connection_id":"60a4fc71-1312-4830-86f4-9eb98be106ac","message_id":2849,"id":"MKR-USD","channel":"v3_orderbook","contents":{"offset":"2693996935","bids":[],"asks":[["2385","77.941"]]}}
1635444248.114109: {"type":"channel_data","connection_id":"60a4fc71-1312-4830-86f4-9eb98be106ac","message_id":2850,"id":"BCH-USD","channel":"v3_orderbook","contents":{"offset":"2693996938","bids":[["572.7","22.91"],["572.6","0"]],"asks":[]}}
1635444248.114153: {"type":"channel_data","connection_id":"60a4fc71-1312-4830-86f4-9eb98be106ac","message_id":2851,"id":"XMR-USD","channel":"v3_orderbook","contents":{"offset":"2693996936","bids":[],"asks":[["274.3","40"]]}}
1635444248.114182: {"type":"channel_data","connection_id":"60a4fc71-1312-4830-86f4-9eb98be106ac","message_id":2852,"id":"BCH-USD","channel":"v3_orderbook","contents":{"offset":"2693996932","bids":[],"asks":[["576.9","0"],["577","1.91"]]}}
1635444248.116891: {"type":"channel_data","connection_id":"60a4fc71-1312-4830-86f4-9eb98be106ac","message_id":2853,"id":"LTC-USD","channel":"v3_orderbook","contents":{"offset":"2693996939","bids":[],"asks":[["188.6","61"],["188.7","27.04"]]}}
1635444248.1169448: {"type":"channel_data","connection_id":"60a4fc71-1312-4830-86f4-9eb98be106ac","message_id":2854,"id":"MKR-USD","channel":"v3_orderbook","contents":{"offset":"2693996940","bids":[],"asks":[["2385","62.929"]]}}
1635444248.1281128: {"type":"channel_data","connection_id":"60a4fc71-1312-4830-86f4-9eb98be106ac","message_id":2855,"id":"XMR-USD","channel":"v3_orderbook","contents":{"offset":"2693996945","bids":[["265","151.21"]],"asks":[]}}
1635444248.128178: {"type":"channel_data","connection_id":"60a4fc71-1312-4830-86f4-9eb98be106ac","message_id":2856,"id":"ETH-USD","channel":"v3_orderbook","contents":{"offset":"2693996942","bids":[],"asks":[["4215.6","0.9"]]}}
1635444248.1282098: {"type":"channel_data","connection_id":"60a4fc71-1312-4830-86f4-9eb98be106ac","message_id":2857,"id":"ETH-USD","channel":"v3_orderbook","contents":{"offset":"2693996943","bids":[],"asks":[["4216","241.449"]]}}
1635444248.128232: {"type":"channel_data","connection_id":"60a4fc71-1312-4830-86f4-9eb98be106ac","message_id":2858,"id":"MKR-USD","channel":"v3_orderbook","contents":{"offset":"2693996946","bids":[],"asks":[["2384","34.374"]]}}
1635444248.128253: {"type":"channel_data","connection_id":"60a4fc71-1312-4830-86f4-9eb98be106ac","message_id":2859,"id":"MKR-USD","channel":"v3_orderbook","contents":{"offset":"2693996944","bids":[],"asks":[["2385","47.917"]]}}
1635444248.128271: {"type":"channel_data","connection_id":"60a4fc71-1312-4830-86f4-9eb98be106ac","message_id":2860,"id":"UMA-USD","channel":"v3_orderbook","contents":{"offset":"2693996947","bids":[["11.29","0"]],"asks":[]}}
1635444248.128295: {"type":"channel_data","connection_id":"60a4fc71-1312-4830-86f4-9eb98be106ac","message_id":2861,"id":"MKR-USD","channel":"v3_orderbook","contents":{"offset":"2693996948","bids":[["2379","51.217"]],"asks":[]}}
1635444248.128313: {"type":"channel_data","connection_id":"60a4fc71-1312-4830-86f4-9eb98be106ac","message_id":2862,"id":"UMA-USD","channel":"v3_orderbook","contents":{"offset":"2693996949","bids":[],"asks":[["11.31","10248.1"]]}}
1635444248.131762: {"type":"channel_data","connection_id":"60a4fc71-1312-4830-86f4-9eb98be106ac","message_id":2863,"id":"XMR-USD","channel":"v3_orderbook","contents":{"offset":"2693996953","bids":[],"asks":[["265.4","362.11"]]}}
1635444248.1318212: {"type":"channel_data","connection_id":"60a4fc71-1312-4830-86f4-9eb98be106ac","message_id":2864,"id":"ETH-USD","channel":"v3_orderbook","contents":{"offset":"2693996952","bids":[["4212.2","1924.321"]],"asks":[]}}
1635444248.1417642: {"type":"channel_data","connection_id":"60a4fc71-1312-4830-86f4-9eb98be106ac","message_id":2865,"id":"MKR-USD","channel":"v3_orderbook","contents":{"offset":"2693996963","bids":[],"asks":[["2384","49.386"]]}}
1635444248.143271: {"type":"channel_data","connection_id":"60a4fc71-1312-4830-86f4-9eb98be106ac","message_id":2866,"id":"MKR-USD","channel":"v3_orderbook","contents":{"offset":"2693996964","bids":[],"asks":[["2384","64.398"]]}}
1635444248.1504178: {"type":"channel_data","connection_id":"60a4fc71-1312-4830-86f4-9eb98be106ac","message_id":2867,"id":"ETH-USD","channel":"v3_orderbook","contents":{"offset":"2693996961","bids":[["4214","35.229"]],"asks":[]}}
1635444248.150474: {"type":"channel_data","connection_id":"60a4fc71-1312-4830-86f4-9eb98be106ac","message_id":2868,"id":"ETH-USD","channel":"v3_orderbook","contents":{"offset":"2693996966","bids":[["4208.4","0"],["4208.1","1.304"]],"asks":[]}}
1635444248.150511: {"type":"channel_data","connection_id":"60a4fc71-1312-4830-86f4-9eb98be106ac","message_id":2869,"id":"ETH-USD","channel":"v3_orderbook","contents":{"offset":"2693996968","bids":[],"asks":[["4223.1","1.304"],["4223.5","0"]]}}
1635444248.1505358: {"type":"channel_data","connection_id":"60a4fc71-1312-4830-86f4-9eb98be106ac","message_id":2870,"id":"ETH-USD","channel":"v3_orderbook","contents":{"offset":"2693996969","bids":[],"asks":[["4217.2","27.527"]]}}
1635444248.152481: {"type":"channel_data","connection_id":"60a4fc71-1312-4830-86f4-9eb98be106ac","message_id":2871,"id":"ETH-USD","channel":"v3_orderbook","contents":{"offset":"2693996971","bids":[],"asks":[["4216","236.642"]]}}
1635444248.1525261: {"type":"channel_data","connection_id":"60a4fc71-1312-4830-86f4-9eb98be106ac","message_id":2872,"id":"UMA-USD","channel":"v3_orderbook","contents":{"offset":"2693996975","bids":[["11.28","15170.7"]],"asks":[]}}
1635444248.153431: {"type":"channel_data","connection_id":"60a4fc71-1312-4830-86f4-9eb98be106ac","message_id":2873,"id":"ETH-USD","channel":"v3_orderbook","contents":{"offset":"2693996974","bids":[],"asks":[["4216","213.03"]]}}
1635444248.155313: {"type":"channel_data","connection_id":"60a4fc71-1312-4830-86f4-9eb98be106ac","message_id":2874,"id":"ETH-USD","channel":"v3_orderbook","contents":{"offset":"2693996970","bids":[["4214.1","58.76"]],"asks":[]}}
1635444248.155356: {"type":"channel_data","connection_id":"60a4fc71-1312-4830-86f4-9eb98be106ac","message_id":2875,"id":"SUSHI-USD","channel":"v3_orderbook","contents":{"offset":"2693996976","bids":[["10.765","4005.5"]],"asks":[]}}
1635444248.156194: {"type":"channel_data","connection_id":"60a4fc71-1312-4830-86f4-9eb98be106ac","message_id":2876,"id":"MKR-USD","channel":"v3_orderbook","contents":{"offset":"2693996973","bids":[],"asks":[["2383","40.954"]]}}
1635444248.165549: {"type":"channel_data","connection_id":"60a4fc71-1312-4830-86f4-9eb98be106ac","message_id":2877,"id":"ETH-USD","channel":"v3_orderbook","contents":{"offset":"2693996982","bids":[["4214.9","0"]],"asks":[]}}
1635444248.1656141: {"type":"channel_data","connection_id":"60a4fc71-1312-4830-86f4-9eb98be106ac","message_id":2878,"id":"ETH-USD","channel":"v3_orderbook","contents":{"offset":"2693996979","bids":[],"asks":[["4216","154.653"]]}}
1635444248.165649: {"type":"channel_data","connection_id":"60a4fc71-1312-4830-86f4-9eb98be106ac","message_id":2879,"id":"ETH-USD","channel":"v3_orderbook","contents":{"offset":"2693996980","bids":[],"asks":[["4215.6","5.707"]]}}
1635444248.166799: {"type":"channel_data","connection_id":"60a4fc71-1312-4830-86f4-9eb98be106ac","message_id":2880,"id":"ETH-USD","channel":"v3_orderbook","contents":{"offset":"2693996984","bids":[],"asks":[["4216","96.893"]]}}
1635444248.1668422: {"type":"channel_data","connection_id":"60a4fc71-1312-4830-86f4-9eb98be106ac","message_id":2881,"id":"CRV-USD","channel":"v3_orderbook","contents":{"offset":"2693996981","bids":[],"asks":[["4.867","9345"]]}}
1635444248.1668742: {"type":"channel_data","connection_id":"60a4fc71-1312-4830-86f4-9eb98be106ac","message_id":2882,"id":"UMA-USD","channel":"v3_orderbook","contents":{"offset":"2693996990","bids":[],"asks":[["11.3","3336.6"]]}}
1635444248.17405: {"type":"channel_data","connection_id":"60a4fc71-1312-4830-86f4-9eb98be106ac","message_id":2883,"id":"UMA-USD","channel":"v3_orderbook","contents":{"offset":"2693996992","bids":[],"asks":[["11.31","10107.2"]]}}
1635444248.201312: {"type":"channel_data","connection_id":"60a4fc71-1312-4830-86f4-9eb98be106ac","message_id":2884,"id":"ETH-USD","channel":"v3_orderbook","contents":{"offset":"2693996998","bids":[],"asks":[["4216","92.118"]]}}
1635444248.201371: {"type":"channel_data","connection_id":"60a4fc71-1312-4830-86f4-9eb98be106ac","message_id":2885,"id":"UMA-USD","channel":"v3_orderbook","contents":{"offset":"2693997001","bids":[["11.28","15313.5"]],"asks":[]}}
1635444248.2013981: {"type":"channel_data","connection_id":"60a4fc71-1312-4830-86f4-9eb98be106ac","message_id":2886,"id":"CRV-USD","channel":"v3_orderbook","contents":{"offset":"2693996999","bids":[],"asks":[["4.86","2364"]]}}
1635444248.203527: {"type":"channel_data","connection_id":"60a4fc71-1312-4830-86f4-9eb98be106ac","message_id":2887,"id":"CRV-USD","channel":"v3_orderbook","contents":{"offset":"2693997004","bids":[["4.845","1246"]],"asks":[]}}
1635444248.2068841: {"type":"channel_data","connection_id":"60a4fc71-1312-4830-86f4-9eb98be106ac","message_id":2888,"id":"UMA-USD","channel":"v3_orderbook","contents":{"offset":"2693997006","bids":[],"asks":[["11.33","29607.6"]]}}
1635444248.210363: {"type":"channel_data","connection_id":"60a4fc71-1312-4830-86f4-9eb98be106ac","message_id":2889,"id":"MKR-USD","channel":"v3_orderbook","contents":{"offset":"2693997009","bids":[["2376","2094.467"]],"asks":[]}}
1635444248.21136: {"type":"channel_data","connection_id":"60a4fc71-1312-4830-86f4-9eb98be106ac","message_id":2890,"id":"ETH-USD","channel":"v3_orderbook","contents":{"offset":"2693997008","bids":[],"asks":[["4215.6","10.482"]]}}
1635444248.211403: {"type":"channel_data","connection_id":"60a4fc71-1312-4830-86f4-9eb98be106ac","message_id":2891,"id":"ETH-USD","channel":"v3_orderbook","contents":{"offset":"2693997007","bids":[],"asks":[["4216","74.458"]]}}
1635444248.224517: {"type":"channel_data","connection_id":"60a4fc71-1312-4830-86f4-9eb98be106ac","message_id":2892,"id":"ETH-USD","channel":"v3_orderbook","contents":{"offset":"2693997016","bids":[],"asks":[["4215.9","2.289"]]}}
1635444248.2467709: {"type":"channel_data","connection_id":"60a4fc71-1312-4830-86f4-9eb98be106ac","message_id":2893,"id":"UMA-USD","channel":"v3_orderbook","contents":{"offset":"2693997022","bids":[["11.27","29527"]],"asks":[]}}
1635444248.2617369: {"type":"channel_data","connection_id":"60a4fc71-1312-4830-86f4-9eb98be106ac","message_id":2894,"id":"UMA-USD","channel":"v3_orderbook","contents":{"offset":"2693997032","bids":[["11.27","29261.6"]],"asks":[]}}
1635444248.266787: {"type":"channel_data","connection_id":"60a4fc71-1312-4830-86f4-9eb98be106ac","message_id":2895,"id":"ETH-USD","channel":"v3_orderbook","contents":{"offset":"2693997029","bids":[],"asks":[["4215.6","5.707"]]}}
1635444248.276185: {"type":"channel_data","connection_id":"60a4fc71-1312-4830-86f4-9eb98be106ac","message_id":2896,"id":"CRV-USD","channel":"v3_orderbook","contents":{"offset":"2693997034","bids":[],"asks":[["4.873","0"]]}}
1635444248.2762518: {"type":"channel_data","connection_id":"60a4fc71-1312-4830-86f4-9eb98be106ac","message_id":2897,"id":"ETH-USD","channel":"v3_orderbook","contents":{"offset":"2693997041","bids":[],"asks":[["4217.9","25.342"]]}}
1635444248.28246: {"type":"channel_data","connection_id":"60a4fc71-1312-4830-86f4-9eb98be106ac","message_id":2898,"id":"SUSHI-USD","channel":"v3_orderbook","contents":{"offset":"2693997047","bids":[],"asks":[["10.81","324.5"]]}}
1635444248.28481: {"type":"channel_data","connection_id":"60a4fc71-1312-4830-86f4-9eb98be106ac","message_id":2899,"id":"ETH-USD","channel":"v3_orderbook","contents":{"offset":"2693997045","bids":[["4194.5","11.853"]],"asks":[]}}
1635444248.297246: {"type":"channel_data","connection_id":"60a4fc71-1312-4830-86f4-9eb98be106ac","message_id":2900,"id":"ETH-USD","channel":"v3_orderbook","contents":{"offset":"2693997052","bids":[["4215.5","32.116"]],"asks":[]}}
1635444248.297305: {"type":"channel_data","connection_id":"60a4fc71-1312-4830-86f4-9eb98be106ac","message_id":2901,"id":"ETH-USD","channel":"v3_orderbook","contents":{"offset":"2693997048","bids":[],"asks":[["4216","72.308"]]}}
1635444248.309047: {"type":"channel_data","connection_id":"60a4fc71-1312-4830-86f4-9eb98be106ac","message_id":2902,"id":"SUSHI-USD","channel":"v3_orderbook","contents":{"offset":"2693997055","bids":[["10.669","925.9"]],"asks":[]}}
1635444248.3504279: {"type":"channel_data","connection_id":"60a4fc71-1312-4830-86f4-9eb98be106ac","message_id":2903,"id":"SUSHI-USD","channel":"v3_orderbook","contents":{"offset":"2693997072","bids":[],"asks":[["11.167","0"]]}}
1635444248.3504992: {"type":"channel_data","connection_id":"60a4fc71-1312-4830-86f4-9eb98be106ac","message_id":2904,"id":"SUSHI-USD","channel":"v3_orderbook","contents":{"offset":"2693997069","bids":[],"asks":[["10.793","13796.4"]]}}
1635444248.35279: {"type":"channel_data","connection_id":"60a4fc71-1312-4830-86f4-9eb98be106ac","message_id":2905,"id":"CRV-USD","channel":"v3_orderbook","contents":{"offset":"2693997073","bids":[["4.837","12435"]],"asks":[]}}
1635444248.3599732: {"type":"channel_data","connection_id":"60a4fc71-1312-4830-86f4-9eb98be106ac","message_id":2906,"id":"ETH-USD","channel":"v3_orderbook","contents":{"offset":"2693997078","bids":[],"asks":[["4215.9","0"]]}}
1635444248.360057: {"type":"channel_data","connection_id":"60a4fc71-1312-4830-86f4-9eb98be106ac","message_id":2907,"id":"SUSHI-USD","channel":"v3_orderbook","contents":{"offset":"2693997079","bids":[["10.411","0"]],"asks":[]}}
1635444248.389184: {"type":"channel_data","connection_id":"60a4fc71-1312-4830-86f4-9eb98be106ac","message_id":2908,"id":"ETH-USD","channel":"v3_orderbook","contents":{"offset":"2693997083","bids":[],"asks":[["4215.6","64.419"]]}}
1635444248.3892531: {"type":"channel_data","connection_id":"60a4fc71-1312-4830-86f4-9eb98be106ac","message_id":2909,"id":"ETH-USD","channel":"v3_orderbook","contents":{"offset":"2693997086","bids":[["4214.2","22.496"]],"asks":[]}}
1635444248.389759: {"type":"channel_data","connection_id":"60a4fc71-1312-4830-86f4-9eb98be106ac","message_id":2910,"id":"ETH-USD","channel":"v3_orderbook","contents":{"offset":"2693997087","bids":[],"asks":[["4217.9","2.846"]]}}
1635444248.391434: {"type":"channel_data","connection_id":"60a4fc71-1312-4830-86f4-9eb98be106ac","message_id":2911,"id":"SUSHI-USD","channel":"v3_orderbook","contents":{"offset":"2693997084","bids":[],"asks":[["10.808","333.1"]]}}
1635444248.391485: {"type":"channel_data","connection_id":"60a4fc71-1312-4830-86f4-9eb98be106ac","message_id":2912,"id":"ETH-USD","channel":"v3_orderbook","contents":{"offset":"2693997088","bids":[["4214.6","48.311"]],"asks":[]}}
1635444248.391513: {"type":"channel_data","connection_id":"60a4fc71-1312-4830-86f4-9eb98be106ac","message_id":2913,"id":"ETH-USD","channel":"v3_orderbook","contents":{"offset":"2693997085","bids":[],"asks":[["4215.6","86.915"]]}}
1635444248.40489: {"type":"channel_data","connection_id":"60a4fc71-1312-4830-86f4-9eb98be106ac","message_id":2914,"id":"ETH-USD","channel":"v3_orderbook","contents":{"offset":"2693997094","bids":[["4210.4","20.493"]],"asks":[]}}
1635444248.404961: {"type":"channel_data","connection_id":"60a4fc71-1312-4830-86f4-9eb98be106ac","message_id":2915,"id":"SUSHI-USD","channel":"v3_orderbook","contents":{"offset":"2693997089","bids":[],"asks":[["10.801","3980.1"]]}}
1635444248.404997: {"type":"channel_data","connection_id":"60a4fc71-1312-4830-86f4-9eb98be106ac","message_id":2916,"id":"ETH-USD","channel":"v3_orderbook","contents":{"offset":"2693997091","bids":[],"asks":[["4215.8","0"]]}}
1635444248.405028: {"type":"channel_data","connection_id":"60a4fc71-1312-4830-86f4-9eb98be106ac","message_id":2917,"id":"ETH-USD","channel":"v3_orderbook","contents":{"offset":"2693997095","bids":[],"asks":[["4217.8","730.731"]]}}
1635444248.405055: {"type":"channel_data","connection_id":"60a4fc71-1312-4830-86f4-9eb98be106ac","message_id":2918,"id":"ETH-USD","channel":"v3_orderbook","contents":{"offset":"2693997092","bids":[["4212.2","1917.105"]],"asks":[]}}
1635444248.4050791: {"type":"channel_data","connection_id":"60a4fc71-1312-4830-86f4-9eb98be106ac","message_id":2919,"id":"SUSHI-USD","channel":"v3_orderbook","contents":{"offset":"2693997090","bids":[],"asks":[["10.805","305.5"]]}}
1635444248.412607: {"type":"channel_data","connection_id":"60a4fc71-1312-4830-86f4-9eb98be106ac","message_id":2920,"id":"ETH-USD","channel":"v3_orderbook","contents":{"offset":"2693997097","bids":[],"asks":[["4216.6","81.256"]]}}
1635444248.412687: {"type":"channel_data","connection_id":"60a4fc71-1312-4830-86f4-9eb98be106ac","message_id":2921,"id":"SUSHI-USD","channel":"v3_orderbook","contents":{"offset":"2693997098","bids":[],"asks":[["10.805","0"]]}}
1635444248.412728: {"type":"channel_data","connection_id":"60a4fc71-1312-4830-86f4-9eb98be106ac","message_id":2922,"id":"LTC-USD","channel":"v3_orderbook","contents":{"offset":"2693997096","bids":[],"asks":[["188.1","4173.39"]]}}
1635444248.4351811: {"type":"channel_data","connection_id":"60a4fc71-1312-4830-86f4-9eb98be106ac","message_id":2923,"id":"ETH-USD","channel":"v3_orderbook","contents":{"offset":"2693997107","bids":[],"asks":[["4219.6","11.6"]]}}
1635444248.43524: {"type":"channel_data","connection_id":"60a4fc71-1312-4830-86f4-9eb98be106ac","message_id":2924,"id":"ETH-USD","channel":"v3_orderbook","contents":{"offset":"2693997106","bids":[],"asks":[["4216.2","0"]]}}
1635444248.435668: {"type":"channel_data","connection_id":"60a4fc71-1312-4830-86f4-9eb98be106ac","message_id":2925,"id":"CRV-USD","channel":"v3_orderbook","contents":{"offset":"2693997104","bids":[],"asks":[["4.861","15208"]]}}
1635444248.4362: {"type":"channel_data","connection_id":"60a4fc71-1312-4830-86f4-9eb98be106ac","message_id":2926,"id":"CRV-USD","channel":"v3_orderbook","contents":{"offset":"2693997109","bids":[["4.845","1840"]],"asks":[]}}
1635444248.444142: {"type":"channel_data","connection_id":"60a4fc71-1312-4830-86f4-9eb98be106ac","message_id":2927,"id":"ETH-USD","channel":"v3_orderbook","contents":{"offset":"2693997113","bids":[["4212.3","8.908"]],"asks":[]}}
1635444248.444757: {"type":"channel_data","connection_id":"60a4fc71-1312-4830-86f4-9eb98be106ac","message_id":2928,"id":"LTC-USD","channel":"v3_orderbook","contents":{"offset":"2693997112","bids":[],"asks":[["188.2","705.45"]]}}
1635444248.479441: {"type":"channel_data","connection_id":"60a4fc71-1312-4830-86f4-9eb98be106ac","message_id":2929,"id":"ETH-USD","channel":"v3_orderbook","contents":{"offset":"2693997126","bids":[],"asks":[["4215.6","143.925"]]}}
1635444248.483265: {"type":"channel_data","connection_id":"60a4fc71-1312-4830-86f4-9eb98be106ac","message_id":2930,"id":"ETH-USD","channel":"v3_orderbook","contents":{"offset":"2693997125","bids":[["4215.1","56.884"]],"asks":[]}}
1635444248.492206: {"type":"channel_data","connection_id":"60a4fc71-1312-4830-86f4-9eb98be106ac","message_id":2931,"id":"MKR-USD","channel":"v3_orderbook","contents":{"offset":"2693997128","bids":[["2377","9.068"]],"asks":[]}}
1635444248.506433: {"type":"channel_data","connection_id":"60a4fc71-1312-4830-86f4-9eb98be106ac","message_id":2932,"id":"ETH-USD","channel":"v3_orderbook","contents":{"offset":"2693997135","bids":[],"asks":[["4216.9","1902.167"]]}}
1635444248.519524: {"type":"channel_data","connection_id":"60a4fc71-1312-4830-86f4-9eb98be106ac","message_id":2933,"id":"ETH-USD","channel":"v3_orderbook","contents":{"offset":"2693997138","bids":[],"asks":[["4217.9","1.423"]]}}
1635444248.520399: {"type":"channel_data","connection_id":"60a4fc71-1312-4830-86f4-9eb98be106ac","message_id":2934,"id":"ETH-USD","channel":"v3_orderbook","contents":{"offset":"2693997141","bids":[],"asks":[["4237.8","11.868"]]}}
1635444248.530659: {"type":"channel_data","connection_id":"60a4fc71-1312-4830-86f4-9eb98be106ac","message_id":2935,"id":"ETH-USD","channel":"v3_orderbook","contents":{"offset":"2693997146","bids":[],"asks":[["4218.3","55.112"]]}}
1635444248.5307488: {"type":"channel_data","connection_id":"60a4fc71-1312-4830-86f4-9eb98be106ac","message_id":2936,"id":"ETH-USD","channel":"v3_orderbook","contents":{"offset":"2693997144","bids":[["4215.1","0"]],"asks":[]}}
1635444248.530805: {"type":"channel_data","connection_id":"60a4fc71-1312-4830-86f4-9eb98be106ac","message_id":2937,"id":"ETH-USD","channel":"v3_orderbook","contents":{"offset":"2693997143","bids":[],"asks":[["4215.6","151.857"]]}}
1635444248.53905: {"type":"channel_data","connection_id":"60a4fc71-1312-4830-86f4-9eb98be106ac","message_id":2938,"id":"UMA-USD","channel":"v3_orderbook","contents":{"offset":"2693997147","bids":[["11.27","29527.1"]],"asks":[]}}
1635444248.541343: {"type":"channel_data","connection_id":"60a4fc71-1312-4830-86f4-9eb98be106ac","message_id":2939,"id":"ETH-USD","channel":"v3_orderbook","contents":{"offset":"2693997152","bids":[],"asks":[["4218.2","5876.795"]]}}
1635444248.549918: {"type":"channel_data","connection_id":"60a4fc71-1312-4830-86f4-9eb98be106ac","message_id":2940,"id":"UMA-USD","channel":"v3_orderbook","contents":{"offset":"2693997155","bids":[],"asks":[["11.33","3098"]]}}
1635444248.549987: {"type":"channel_data","connection_id":"60a4fc71-1312-4830-86f4-9eb98be106ac","message_id":2941,"id":"UMA-USD","channel":"v3_orderbook","contents":{"offset":"2693997154","bids":[],"asks":[["11.33","25201.1"]]}}
1635444248.550019: {"type":"channel_data","connection_id":"60a4fc71-1312-4830-86f4-9eb98be106ac","message_id":2942,"id":"UMA-USD","channel":"v3_orderbook","contents":{"offset":"2693997157","bids":[["11.27","29261.6"]],"asks":[]}}
1635444248.566436: {"type":"channel_data","connection_id":"60a4fc71-1312-4830-86f4-9eb98be106ac","message_id":2943,"id":"ETH-USD","channel":"v3_orderbook","contents":{"offset":"2693997158","bids":[],"asks":[["4215.6","210.617"]]}}
1635444248.5781078: {"type":"channel_data","connection_id":"60a4fc71-1312-4830-86f4-9eb98be106ac","message_id":2944,"id":"SUSHI-USD","channel":"v3_orderbook","contents":{"offset":"2693997163","bids":[],"asks":[["10.797","2125.9"]]}}
1635444248.589864: {"type":"channel_data","connection_id":"60a4fc71-1312-4830-86f4-9eb98be106ac","message_id":2945,"id":"ETH-USD","channel":"v3_orderbook","contents":{"offset":"2693997171","bids":[],"asks":[["4216.1","142.25"]]}}
1635444248.5920682: {"type":"channel_data","connection_id":"60a4fc71-1312-4830-86f4-9eb98be106ac","message_id":2946,"id":"ETH-USD","channel":"v3_orderbook","contents":{"offset":"2693997165","bids":[],"asks":[["4215.6","212.906"]]}}
1635444248.600389: {"type":"channel_data","connection_id":"60a4fc71-1312-4830-86f4-9eb98be106ac","message_id":2947,"id":"UMA-USD","channel":"v3_orderbook","contents":{"offset":"2693997174","bids":[["11.28","14881.5"]],"asks":[]}}
1635444248.623049: {"type":"channel_data","connection_id":"60a4fc71-1312-4830-86f4-9eb98be106ac","message_id":2948,"id":"ETH-USD","channel":"v3_orderbook","contents":{"offset":"2693997187","bids":[["4211","10086.566"]],"asks":[]}}
1635444248.631679: {"type":"channel_data","connection_id":"60a4fc71-1312-4830-86f4-9eb98be106ac","message_id":2949,"id":"UMA-USD","channel":"v3_orderbook","contents":{"offset":"2693997191","bids":[["11.27","28898.1"]],"asks":[]}}
1635444248.6471791: {"type":"channel_data","connection_id":"60a4fc71-1312-4830-86f4-9eb98be106ac","message_id":2950,"id":"UMA-USD","channel":"v3_orderbook","contents":{"offset":"2693997193","bids":[["11.28","14470.6"]],"asks":[]}}
1635444248.647295: {"type":"channel_data","connection_id":"60a4fc71-1312-4830-86f4-9eb98be106ac","message_id":2951,"id":"SUSHI-USD","channel":"v3_orderbook","contents":{"offset":"2693997195","bids":[["10.771","2062.5"]],"asks":[]}}
1635444248.660141: {"type":"channel_data","connection_id":"60a4fc71-1312-4830-86f4-9eb98be106ac","message_id":2952,"id":"SUSHI-USD","channel":"v3_orderbook","contents":{"offset":"2693997202","bids":[],"asks":[["10.8","14024.6"]]}}
1635444248.660223: {"type":"channel_data","connection_id":"60a4fc71-1312-4830-86f4-9eb98be106ac","message_id":2953,"id":"SUSHI-USD","channel":"v3_orderbook","contents":{"offset":"2693997204","bids":[["10.412","1000"]],"asks":[]}}
1635444248.6698: {"type":"channel_data","connection_id":"60a4fc71-1312-4830-86f4-9eb98be106ac","message_id":2954,"id":"UMA-USD","channel":"v3_orderbook","contents":{"offset":"2693997209","bids":[],"asks":[["11.33","7504.4"]]}}
1635444248.67079: {"type":"channel_data","connection_id":"60a4fc71-1312-4830-86f4-9eb98be106ac","message_id":2955,"id":"ETH-USD","channel":"v3_orderbook","contents":{"offset":"2693997212","bids":[],"asks":[["4215.6","484.838"]]}}
1635444248.670835: {"type":"channel_data","connection_id":"60a4fc71-1312-4830-86f4-9eb98be106ac","message_id":2956,"id":"UMA-USD","channel":"v3_orderbook","contents":{"offset":"2693997213","bids":[],"asks":[["11.33","29607.5"]]}}
1635444248.679188: {"type":"channel_data","connection_id":"60a4fc71-1312-4830-86f4-9eb98be106ac","message_id":2957,"id":"ETH-USD","channel":"v3_orderbook","contents":{"offset":"2693997217","bids":[["4215.5","82.548"]],"asks":[]}}
1635444248.6919281: {"type":"channel_data","connection_id":"60a4fc71-1312-4830-86f4-9eb98be106ac","message_id":2958,"id":"CRV-USD","channel":"v3_orderbook","contents":{"offset":"2693997219","bids":[["4.848","5245"]],"asks":[]}}
1635444248.7042072: {"type":"channel_data","connection_id":"60a4fc71-1312-4830-86f4-9eb98be106ac","message_id":2959,"id":"ETH-USD","channel":"v3_orderbook","contents":{"offset":"2693997222","bids":[["4210","2.823"]],"asks":[]}}
1635444248.706028: {"type":"channel_data","connection_id":"60a4fc71-1312-4830-86f4-9eb98be106ac","message_id":2960,"id":"ETH-USD","channel":"v3_orderbook","contents":{"offset":"2693997224","bids":[],"asks":[["4218.1","4463.226"]]}}
1635444248.716297: {"type":"channel_data","connection_id":"60a4fc71-1312-4830-86f4-9eb98be106ac","message_id":2961,"id":"ETH-USD","channel":"v3_orderbook","contents":{"offset":"2693997228","bids":[],"asks":[["4217.1","1412.607"]]}}
1635444248.716368: {"type":"channel_data","connection_id":"60a4fc71-1312-4830-86f4-9eb98be106ac","message_id":2962,"id":"ETH-USD","channel":"v3_orderbook","contents":{"offset":"2693997229","bids":[["4215.2","56.835"]],"asks":[]}}
1635444248.7252429: {"type":"channel_data","connection_id":"60a4fc71-1312-4830-86f4-9eb98be106ac","message_id":2963,"id":"UMA-USD","channel":"v3_orderbook","contents":{"offset":"2693997235","bids":[],"asks":[["11.33","7504.4"]]}}
1635444248.725327: {"type":"channel_data","connection_id":"60a4fc71-1312-4830-86f4-9eb98be106ac","message_id":2964,"id":"UMA-USD","channel":"v3_orderbook","contents":{"offset":"2693997236","bids":[],"asks":[["11.33","3098"]]}}
1635444248.728284: {"type":"channel_data","connection_id":"60a4fc71-1312-4830-86f4-9eb98be106ac","message_id":2965,"id":"SUSHI-USD","channel":"v3_orderbook","contents":{"offset":"2693997237","bids":[],"asks":[["11.168","1000"]]}}
1635444248.75029: {"type":"channel_data","connection_id":"60a4fc71-1312-4830-86f4-9eb98be106ac","message_id":2966,"id":"UNI-USD","channel":"v3_orderbook","contents":{"offset":"2693997246","bids":[],"asks":[["25.079","0"]]}}
1635444248.793945: {"type":"channel_data","connection_id":"60a4fc71-1312-4830-86f4-9eb98be106ac","message_id":2967,"id":"UNI-USD","channel":"v3_orderbook","contents":{"offset":"2693997247","bids":[["25.03","0"]],"asks":[]}}
1635444248.7980878: {"type":"channel_data","connection_id":"60a4fc71-1312-4830-86f4-9eb98be106ac","message_id":2968,"id":"SUSHI-USD","channel":"v3_orderbook","contents":{"offset":"2693997242","bids":[],"asks":[["10.794","3705.8"]]}}
1635444248.7981398: {"type":"channel_data","connection_id":"60a4fc71-1312-4830-86f4-9eb98be106ac","message_id":2969,"id":"UNI-USD","channel":"v3_orderbook","contents":{"offset":"2693997248","bids":[],"asks":[["25.073","0"]]}}
1635444248.798166: {"type":"channel_data","connection_id":"60a4fc71-1312-4830-86f4-9eb98be106ac","message_id":2970,"id":"UNI-USD","channel":"v3_orderbook","contents":{"offset":"2693997249","bids":[["25.036","0"]],"asks":[]}}
1635444248.798186: {"type":"channel_data","connection_id":"60a4fc71-1312-4830-86f4-9eb98be106ac","message_id":2971,"id":"SUSHI-USD","channel":"v3_orderbook","contents":{"offset":"2693997250","bids":[],"asks":[["10.802","440.6"]]}}
1635444248.808179: {"type":"channel_data","connection_id":"60a4fc71-1312-4830-86f4-9eb98be106ac","message_id":2972,"id":"SUSHI-USD","channel":"v3_orderbook","contents":{"offset":"2693997259","bids":[],"asks":[["10.799","387"]]}}
1635444248.808275: {"type":"channel_data","connection_id":"60a4fc71-1312-4830-86f4-9eb98be106ac","message_id":2973,"id":"SUSHI-USD","channel":"v3_orderbook","contents":{"offset":"2693997255","bids":[["10.78","139"]],"asks":[]}}
1635444248.808301: {"type":"channel_data","connection_id":"60a4fc71-1312-4830-86f4-9eb98be106ac","message_id":2974,"id":"BCH-USD","channel":"v3_orderbook","contents":{"offset":"2693997258","bids":[["571.9","60.93"],["571.8","0"]],"asks":[]}}
1635444248.808328: {"type":"channel_data","connection_id":"60a4fc71-1312-4830-86f4-9eb98be106ac","message_id":2975,"id":"ETH-USD","channel":"v3_orderbook","contents":{"offset":"2693997253","bids":[["4195.3","11.853"],["4194.5","0"]],"asks":[]}}
1635444248.808353: {"type":"channel_data","connection_id":"60a4fc71-1312-4830-86f4-9eb98be106ac","message_id":2976,"id":"SUSHI-USD","channel":"v3_orderbook","contents":{"offset":"2693997262","bids":[["10.776","1697.6"]],"asks":[]}}
1635444248.809851: {"type":"channel_data","connection_id":"60a4fc71-1312-4830-86f4-9eb98be106ac","message_id":2977,"id":"BCH-USD","channel":"v3_orderbook","contents":{"offset":"2693997267","bids":[["571.6","262.47"],["571.5","0"]],"asks":[]}}
1635444248.812513: {"type":"channel_data","connection_id":"60a4fc71-1312-4830-86f4-9eb98be106ac","message_id":2978,"id":"ETH-USD","channel":"v3_orderbook","contents":{"offset":"2693997263","bids":[["4208.5","102.52"]],"asks":[]}}
1635444248.812568: {"type":"channel_data","connection_id":"60a4fc71-1312-4830-86f4-9eb98be106ac","message_id":2979,"id":"ETH-USD","channel":"v3_orderbook","contents":{"offset":"2693997264","bids":[],"asks":[["4217.6","20.653"]]}}
1635444248.818083: {"type":"channel_data","connection_id":"60a4fc71-1312-4830-86f4-9eb98be106ac","message_id":2980,"id":"UMA-USD","channel":"v3_orderbook","contents":{"offset":"2693997273","bids":[["11.27","28640.8"]],"asks":[]}}
1635444248.818146: {"type":"channel_data","connection_id":"60a4fc71-1312-4830-86f4-9eb98be106ac","message_id":2981,"id":"ETH-USD","channel":"v3_orderbook","contents":{"offset":"2693997270","bids":[],"asks":[["4215.6","490.774"]]}}
1635444248.820235: {"type":"channel_data","connection_id":"60a4fc71-1312-4830-86f4-9eb98be106ac","message_id":2982,"id":"ETH-USD","channel":"v3_orderbook","contents":{"offset":"2693997269","bids":[],"asks":[["4216.6","95.338"]]}}
1635444248.839981: {"type":"channel_data","connection_id":"60a4fc71-1312-4830-86f4-9eb98be106ac","message_id":2983,"id":"UNI-USD","channel":"v3_orderbook","contents":{"offset":"2693997283","bids":[],"asks":[["25.068","399.5"]]}}
1635444248.843424: {"type":"channel_data","connection_id":"60a4fc71-1312-4830-86f4-9eb98be106ac","message_id":2984,"id":"UMA-USD","channel":"v3_orderbook","contents":{"offset":"2693997284","bids":[["11.27","28906.2"]],"asks":[]}}
1635444248.850084: {"type":"channel_data","connection_id":"60a4fc71-1312-4830-86f4-9eb98be106ac","message_id":2985,"id":"UMA-USD","channel":"v3_orderbook","contents":{"offset":"2693997286","bids":[],"asks":[["11.33","25201.1"]]}}
1635444248.864244: {"type":"channel_data","connection_id":"60a4fc71-1312-4830-86f4-9eb98be106ac","message_id":2986,"id":"MKR-USD","channel":"v3_orderbook","contents":{"offset":"2693997295","bids":[["2381","8.312"]],"asks":[]}}
1635444248.8642828: {"type":"channel_data","connection_id":"60a4fc71-1312-4830-86f4-9eb98be106ac","message_id":2987,"id":"UMA-USD","channel":"v3_orderbook","contents":{"offset":"2693997290","bids":[],"asks":[["11.33","29607.3"]]}}
1635444248.864304: {"type":"channel_data","connection_id":"60a4fc71-1312-4830-86f4-9eb98be106ac","message_id":2988,"id":"UNI-USD","channel":"v3_orderbook","contents":{"offset":"2693997288","bids":[["25.019","0"]],"asks":[]}}
1635444248.872586: {"type":"channel_data","connection_id":"60a4fc71-1312-4830-86f4-9eb98be106ac","message_id":2989,"id":"UNI-USD","channel":"v3_orderbook","contents":{"offset":"2693997298","bids":[],"asks":[["25.068","0"]]}}
1635444248.8758981: {"type":"channel_data","connection_id":"60a4fc71-1312-4830-86f4-9eb98be106ac","message_id":2990,"id":"SUSHI-USD","channel":"v3_orderbook","contents":{"offset":"2693997300","bids":[],"asks":[["10.797","6546"]]}}
1635444248.8759522: {"type":"channel_data","connection_id":"60a4fc71-1312-4830-86f4-9eb98be106ac","message_id":2991,"id":"UMA-USD","channel":"v3_orderbook","contents":{"offset":"2693997303","bids":[["11.27","28640.8"]],"asks":[]}}
1635444248.884108: {"type":"channel_data","connection_id":"60a4fc71-1312-4830-86f4-9eb98be106ac","message_id":2992,"id":"UNI-USD","channel":"v3_orderbook","contents":{"offset":"2693997304","bids":[["25","1585.8"]],"asks":[]}}
1635444248.923133: {"type":"channel_data","connection_id":"60a4fc71-1312-4830-86f4-9eb98be106ac","message_id":2993,"id":"MKR-USD","channel":"v3_orderbook","contents":{"offset":"2693997315","bids":[["2376","2136.554"]],"asks":[]}}
1635444248.9231842: {"type":"channel_data","connection_id":"60a4fc71-1312-4830-86f4-9eb98be106ac","message_id":2994,"id":"UNI-USD","channel":"v3_orderbook","contents":{"offset":"2693997317","bids":[],"asks":[["25.068","399.5"]]}}
1635444248.944305: {"type":"channel_data","connection_id":"60a4fc71-1312-4830-86f4-9eb98be106ac","message_id":2995,"id":"UMA-USD","channel":"v3_orderbook","contents":{"offset":"2693997322","bids":[],"asks":[["11.33","29686.1"]]}}
1635444248.96904: {"type":"channel_data","connection_id":"60a4fc71-1312-4830-86f4-9eb98be106ac","message_id":2996,"id":"UNI-USD","channel":"v3_orderbook","contents":{"offset":"2693997331","bids":[],"asks":[["25.068","0"]]}}
1635444248.972343: {"type":"channel_data","connection_id":"60a4fc71-1312-4830-86f4-9eb98be106ac","message_id":2997,"id":"MKR-USD","channel":"v3_orderbook","contents":{"offset":"2693997334","bids":[["2380","27.508"]],"asks":[]}}
1635444248.985507: {"type":"channel_data","connection_id":"60a4fc71-1312-4830-86f4-9eb98be106ac","message_id":2998,"id":"MKR-USD","channel":"v3_orderbook","contents":{"offset":"2693997337","bids":[["2380","37.977"]],"asks":[]}}
1635444248.999315: {"type":"channel_data","connection_id":"60a4fc71-1312-4830-86f4-9eb98be106ac","message_id":2999,"id":"UNI-USD","channel":"v3_orderbook","contents":{"offset":"2693997340","bids":[["25.03","113.6"]],"asks":[]}}
1635444249.00176: {"type":"channel_data","connection_id":"60a4fc71-1312-4830-86f4-9eb98be106ac","message_id":3000,"id":"MKR-USD","channel":"v3_orderbook","contents":{"offset":"2693997342","bids":[["2380","39.185"]],"asks":[]}}
1635444249.014007: {"type":"channel_data","connection_id":"60a4fc71-1312-4830-86f4-9eb98be106ac","message_id":3001,"id":"ETH-USD","channel":"v3_orderbook","contents":{"offset":"2693997349","bids":[],"asks":[["4237.8","0"],["4237.9","105.172"]]}}
1635444249.03143: {"type":"channel_data","connection_id":"60a4fc71-1312-4830-86f4-9eb98be106ac","message_id":3002,"id":"ETH-USD","channel":"v3_orderbook","contents":{"offset":"2693997354","bids":[],"asks":[["4221.3","0"]]}}
1635444249.0315251: {"type":"channel_data","connection_id":"60a4fc71-1312-4830-86f4-9eb98be106ac","message_id":3003,"id":"UNI-USD","channel":"v3_orderbook","contents":{"offset":"2693997350","bids":[],"asks":[["25.068","399.5"]]}}
1635444249.03666: {"type":"channel_data","connection_id":"60a4fc71-1312-4830-86f4-9eb98be106ac","message_id":3004,"id":"SUSHI-USD","channel":"v3_orderbook","contents":{"offset":"2693997356","bids":[["10.782","4375.6"]],"asks":[]}}
1635444249.059249: {"type":"channel_data","connection_id":"60a4fc71-1312-4830-86f4-9eb98be106ac","message_id":3005,"id":"UNI-USD","channel":"v3_orderbook","contents":{"offset":"2693997363","bids":[],"asks":[["25.068","0"]]}}
1635444249.059308: {"type":"channel_data","connection_id":"60a4fc71-1312-4830-86f4-9eb98be106ac","message_id":3006,"id":"UNI-USD","channel":"v3_orderbook","contents":{"offset":"2693997364","bids":[["25.01","1585.8"]],"asks":[]}}
1635444249.059327: {"type":"channel_data","connection_id":"60a4fc71-1312-4830-86f4-9eb98be106ac","message_id":3007,"id":"UNI-USD","channel":"v3_orderbook","contents":{"offset":"2693997361","bids":[["25","0"]],"asks":[]}}
1635444249.084116: {"type":"channel_data","connection_id":"60a4fc71-1312-4830-86f4-9eb98be106ac","message_id":3008,"id":"ETH-USD","channel":"v3_orderbook","contents":{"offset":"2693997370","bids":[["4215.5","130.358"]],"asks":[]}}
1635444249.08417: {"type":"channel_data","connection_id":"60a4fc71-1312-4830-86f4-9eb98be106ac","message_id":3009,"id":"UNI-USD","channel":"v3_orderbook","contents":{"offset":"2693997367","bids":[],"asks":[["25.209","998.8"],["25.21","0"]]}}
1635444249.084842: {"type":"channel_data","connection_id":"60a4fc71-1312-4830-86f4-9eb98be106ac","message_id":3010,"id":"BCH-USD","channel":"v3_orderbook","contents":{"offset":"2693997365","bids":[["572.5","61.03"],["572.4","6.99"]],"asks":[]}}
1635444249.096043: {"type":"channel_data","connection_id":"60a4fc71-1312-4830-86f4-9eb98be106ac","message_id":3011,"id":"SUSHI-USD","channel":"v3_orderbook","contents":{"offset":"2693997373","bids":[],"asks":[["10.796","0"]]}}
1635444249.110785: {"type":"channel_data","connection_id":"60a4fc71-1312-4830-86f4-9eb98be106ac","message_id":3012,"id":"SUSHI-USD","channel":"v3_orderbook","contents":{"offset":"2693997374","bids":[["10.788","0"]],"asks":[]}}
1635444249.121546: {"type":"channel_data","connection_id":"60a4fc71-1312-4830-86f4-9eb98be106ac","message_id":3013,"id":"SUSHI-USD","channel":"v3_orderbook","contents":{"offset":"2693997377","bids":[],"asks":[["10.789","4002.3"]]}}
1635444249.131992: {"type":"channel_data","connection_id":"60a4fc71-1312-4830-86f4-9eb98be106ac","message_id":3014,"id":"ETH-USD","channel":"v3_orderbook","contents":{"offset":"2693997386","bids":[],"asks":[["4215.7","9.783"]]}}
1635444249.133474: {"type":"channel_data","connection_id":"60a4fc71-1312-4830-86f4-9eb98be106ac","message_id":3015,"id":"ETH-USD","channel":"v3_orderbook","contents":{"offset":"2693997384","bids":[["4212.3","1.692"]],"asks":[]}}
1635444249.1362062: {"type":"channel_data","connection_id":"60a4fc71-1312-4830-86f4-9eb98be106ac","message_id":3016,"id":"UNI-USD","channel":"v3_orderbook","contents":{"offset":"2693997382","bids":[],"asks":[["25.068","399.5"]]}}
1635444249.1466691: {"type":"channel_data","connection_id":"60a4fc71-1312-4830-86f4-9eb98be106ac","message_id":3017,"id":"SUSHI-USD","channel":"v3_orderbook","contents":{"offset":"2693997391","bids":[["10.784","12720.5"]],"asks":[]}}
1635444249.146729: {"type":"channel_data","connection_id":"60a4fc71-1312-4830-86f4-9eb98be106ac","message_id":3018,"id":"SUSHI-USD","channel":"v3_orderbook","contents":{"offset":"2693997390","bids":[["10.784","8300.5"]],"asks":[]}}
1635444249.1599512: {"type":"channel_data","connection_id":"60a4fc71-1312-4830-86f4-9eb98be106ac","message_id":3019,"id":"UNI-USD","channel":"v3_orderbook","contents":{"offset":"2693997395","bids":[],"asks":[["25.068","0"]]}}
1635444249.160011: {"type":"channel_data","connection_id":"60a4fc71-1312-4830-86f4-9eb98be106ac","message_id":3020,"id":"SUSHI-USD","channel":"v3_orderbook","contents":{"offset":"2693997392","bids":[],"asks":[["10.803","573.9"]]}}
1635444249.160032: {"type":"channel_data","connection_id":"60a4fc71-1312-4830-86f4-9eb98be106ac","message_id":3021,"id":"ETH-USD","channel":"v3_orderbook","contents":{"offset":"2693997397","bids":[],"asks":[["4218.4","43.053"]]}}
1635444249.1694348: {"type":"channel_data","connection_id":"60a4fc71-1312-4830-86f4-9eb98be106ac","message_id":3022,"id":"ETH-USD","channel":"v3_orderbook","contents":{"offset":"2693997400","bids":[["4212.1","7.216"]],"asks":[]}}
1635444249.18544: {"type":"channel_data","connection_id":"60a4fc71-1312-4830-86f4-9eb98be106ac","message_id":3023,"id":"ETH-USD","channel":"v3_orderbook","contents":{"offset":"2693997402","bids":[],"asks":[["4217.1","2.717"]]}}
1635444249.1855428: {"type":"channel_data","connection_id":"60a4fc71-1312-4830-86f4-9eb98be106ac","message_id":3024,"id":"ETH-USD","channel":"v3_orderbook","contents":{"offset":"2693997404","bids":[],"asks":[["4216.6","36.578"]]}}
1635444249.1855779: {"type":"channel_data","connection_id":"60a4fc71-1312-4830-86f4-9eb98be106ac","message_id":3025,"id":"SUSHI-USD","channel":"v3_orderbook","contents":{"offset":"2693997408","bids":[["10.786","0"]],"asks":[]}}
1635444249.188501: {"type":"channel_data","connection_id":"60a4fc71-1312-4830-86f4-9eb98be106ac","message_id":3026,"id":"SUSHI-USD","channel":"v3_orderbook","contents":{"offset":"2693997405","bids":[],"asks":[["10.803","879.4"]]}}
1635444249.188564: {"type":"channel_data","connection_id":"60a4fc71-1312-4830-86f4-9eb98be106ac","message_id":3027,"id":"ETH-USD","channel":"v3_orderbook","contents":{"offset":"2693997406","bids":[],"asks":[["4227.3","0"]]}}
1635444249.206601: {"type":"channel_data","connection_id":"60a4fc71-1312-4830-86f4-9eb98be106ac","message_id":3028,"id":"SUSHI-USD","channel":"v3_orderbook","contents":{"offset":"2693997412","bids":[],"asks":[["10.797","6351.6"]]}}
1635444249.210428: {"type":"channel_data","connection_id":"60a4fc71-1312-4830-86f4-9eb98be106ac","message_id":3029,"id":"UNI-USD","channel":"v3_orderbook","contents":{"offset":"2693997416","bids":[],"asks":[["25.196","2178.7"],["25.197","0"]]}}
1635444249.210491: {"type":"channel_data","connection_id":"60a4fc71-1312-4830-86f4-9eb98be106ac","message_id":3030,"id":"UNI-USD","channel":"v3_orderbook","contents":{"offset":"2693997414","bids":[],"asks":[["25.171","1214.8"],["25.172","0"]]}}
1635444249.2211359: {"type":"channel_data","connection_id":"60a4fc71-1312-4830-86f4-9eb98be106ac","message_id":3031,"id":"SUSHI-USD","channel":"v3_orderbook","contents":{"offset":"2693997417","bids":[["10.785","323.9"]],"asks":[]}}
1635444249.229812: {"type":"channel_data","connection_id":"60a4fc71-1312-4830-86f4-9eb98be106ac","message_id":3032,"id":"UNI-USD","channel":"v3_orderbook","contents":{"offset":"2693997423","bids":[["25.026","459.5"]],"asks":[]}}
1635444249.2333739: {"type":"channel_data","connection_id":"60a4fc71-1312-4830-86f4-9eb98be106ac","message_id":3033,"id":"UNI-USD","channel":"v3_orderbook","contents":{"offset":"2693997421","bids":[],"asks":[["25.068","399.5"]]}}
1635444249.233432: {"type":"channel_data","connection_id":"60a4fc71-1312-4830-86f4-9eb98be106ac","message_id":3034,"id":"CRV-USD","channel":"v3_orderbook","contents":{"offset":"2693997422","bids":[],"asks":[["4.858","0"]]}}
1635444249.255158: {"type":"channel_data","connection_id":"60a4fc71-1312-4830-86f4-9eb98be106ac","message_id":3035,"id":"ETH-USD","channel":"v3_orderbook","contents":{"offset":"2693997429","bids":[["4215.2","0"]],"asks":[]}}
1635444249.266358: {"type":"channel_data","connection_id":"60a4fc71-1312-4830-86f4-9eb98be106ac","message_id":3036,"id":"UNI-USD","channel":"v3_orderbook","contents":{"offset":"2693997434","bids":[["25.033","0"]],"asks":[]}}
1635444249.266453: {"type":"channel_data","connection_id":"60a4fc71-1312-4830-86f4-9eb98be106ac","message_id":3037,"id":"SUSHI-USD","channel":"v3_orderbook","contents":{"offset":"2693997436","bids":[["10.781","4421.1"]],"asks":[]}}
1635444249.2672262: {"type":"channel_data","connection_id":"60a4fc71-1312-4830-86f4-9eb98be106ac","message_id":3038,"id":"CRV-USD","channel":"v3_orderbook","contents":{"offset":"2693997435","bids":[],"asks":[["4.856","6310"]]}}
1635444249.267276: {"type":"channel_data","connection_id":"60a4fc71-1312-4830-86f4-9eb98be106ac","message_id":3039,"id":"UNI-USD","channel":"v3_orderbook","contents":{"offset":"2693997437","bids":[],"asks":[["25.063","399.6"]]}}
1635444249.2676601: {"type":"channel_data","connection_id":"60a4fc71-1312-4830-86f4-9eb98be106ac","message_id":3040,"id":"ETH-USD","channel":"v3_orderbook","contents":{"offset":"2693997438","bids":[],"asks":[["4218.1","4464.738"]]}}
1635444249.275819: {"type":"channel_data","connection_id":"60a4fc71-1312-4830-86f4-9eb98be106ac","message_id":3041,"id":"UNI-USD","channel":"v3_orderbook","contents":{"offset":"2693997447","bids":[["25.02","514.6"]],"asks":[]}}
1635444249.2779331: {"type":"channel_data","connection_id":"60a4fc71-1312-4830-86f4-9eb98be106ac","message_id":3042,"id":"SUSHI-USD","channel":"v3_orderbook","contents":{"offset":"2693997448","bids":[["10.753","2299"]],"asks":[]}}
1635444249.2794418: {"type":"channel_data","connection_id":"60a4fc71-1312-4830-86f4-9eb98be106ac","message_id":3043,"id":"EOS-USD","channel":"v3_orderbook","contents":{"offset":"2693997445","bids":[["4.386","0"],["4.385","16366"]],"asks":[]}}
1635444249.279501: {"type":"channel_data","connection_id":"60a4fc71-1312-4830-86f4-9eb98be106ac","message_id":3044,"id":"ETH-USD","channel":"v3_orderbook","contents":{"offset":"2693997446","bids":[],"asks":[["4225","1"]]}}
1635444249.300596: {"type":"channel_data","connection_id":"60a4fc71-1312-4830-86f4-9eb98be106ac","message_id":3045,"id":"ETH-USD","channel":"v3_orderbook","contents":{"offset":"2693997458","bids":[["4212.1","0"]],"asks":[]}}
1635444249.300666: {"type":"channel_data","connection_id":"60a4fc71-1312-4830-86f4-9eb98be106ac","message_id":3046,"id":"ETH-USD","channel":"v3_orderbook","contents":{"offset":"2693997452","bids":[["4211.9","7.216"]],"asks":[]}}
1635444249.300691: {"type":"channel_data","connection_id":"60a4fc71-1312-4830-86f4-9eb98be106ac","message_id":3047,"id":"UNI-USD","channel":"v3_orderbook","contents":{"offset":"2693997457","bids":[],"asks":[["25.069","399.6"]]}}
1635444249.301041: {"type":"channel_data","connection_id":"60a4fc71-1312-4830-86f4-9eb98be106ac","message_id":3048,"id":"ETH-USD","channel":"v3_orderbook","contents":{"offset":"2693997453","bids":[],"asks":[["4217.6","22.076"]]}}
1635444249.3097339: {"type":"channel_data","connection_id":"60a4fc71-1312-4830-86f4-9eb98be106ac","message_id":3049,"id":"ETH-USD","channel":"v3_orderbook","contents":{"offset":"2693997463","bids":[],"asks":[["4217.5","1.423"]]}}
1635444249.311947: {"type":"channel_data","connection_id":"60a4fc71-1312-4830-86f4-9eb98be106ac","message_id":3050,"id":"ETH-USD","channel":"v3_orderbook","contents":{"offset":"2693997464","bids":[["4195.3","0"],["4194.5","11.853"]],"asks":[]}}
1635444249.323383: {"type":"channel_data","connection_id":"60a4fc71-1312-4830-86f4-9eb98be106ac","message_id":3051,"id":"UNI-USD","channel":"v3_orderbook","contents":{"offset":"2693997465","bids":[["25.01","0"]],"asks":[]}}
1635444249.323444: {"type":"channel_data","connection_id":"60a4fc71-1312-4830-86f4-9eb98be106ac","message_id":3052,"id":"CRV-USD","channel":"v3_orderbook","contents":{"offset":"2693997470","bids":[["4.847","0"]],"asks":[]}}
1635444249.3345: {"type":"channel_data","connection_id":"60a4fc71-1312-4830-86f4-9eb98be106ac","message_id":3053,"id":"SUSHI-USD","channel":"v3_orderbook","contents":{"offset":"2693997474","bids":[["10.785","1533.1"]],"asks":[]}}
1635444249.3345642: {"type":"channel_data","connection_id":"60a4fc71-1312-4830-86f4-9eb98be106ac","message_id":3054,"id":"ETH-USD","channel":"v3_orderbook","contents":{"offset":"2693997476","bids":[],"asks":[["4215.7","0"]]}}
1635444249.337214: {"type":"channel_data","connection_id":"60a4fc71-1312-4830-86f4-9eb98be106ac","message_id":3055,"id":"ETH-USD","channel":"v3_orderbook","contents":{"offset":"2693997472","bids":[],"asks":[["4216","131.068"]]}}
1635444249.337333: {"type":"channel_data","connection_id":"60a4fc71-1312-4830-86f4-9eb98be106ac","message_id":3056,"id":"UMA-USD","channel":"v3_orderbook","contents":{"offset":"2693997475","bids":[["11.27","28906.2"]],"asks":[]}}
1635444249.344579: {"type":"channel_data","connection_id":"60a4fc71-1312-4830-86f4-9eb98be106ac","message_id":3057,"id":"ETH-USD","channel":"v3_orderbook","contents":{"offset":"2693997482","bids":[],"asks":[["4215.9","1410.08"]]}}
1635444249.3469498: {"type":"channel_data","connection_id":"60a4fc71-1312-4830-86f4-9eb98be106ac","message_id":3058,"id":"ETH-USD","channel":"v3_orderbook","contents":{"offset":"2693997477","bids":[],"asks":[["4215.6","484.838"]]}}
1635444249.347033: {"type":"channel_data","connection_id":"60a4fc71-1312-4830-86f4-9eb98be106ac","message_id":3059,"id":"SUSHI-USD","channel":"v3_orderbook","contents":{"offset":"2693997481","bids":[],"asks":[["10.909","942.6"]]}}
1635444249.3635159: {"type":"channel_data","connection_id":"60a4fc71-1312-4830-86f4-9eb98be106ac","message_id":3060,"id":"UMA-USD","channel":"v3_orderbook","contents":{"offset":"2693997487","bids":[["11.27","28640.8"]],"asks":[]}}
1635444249.363637: {"type":"channel_data","connection_id":"60a4fc71-1312-4830-86f4-9eb98be106ac","message_id":3061,"id":"UNI-USD","channel":"v3_orderbook","contents":{"offset":"2693997485","bids":[["25.02","2100.4"]],"asks":[]}}
1635444249.3684008: {"type":"channel_data","connection_id":"60a4fc71-1312-4830-86f4-9eb98be106ac","message_id":3062,"id":"SUSHI-USD","channel":"v3_orderbook","contents":{"offset":"2693997490","bids":[["10.669","926.3"]],"asks":[]}}
1635444249.3702452: {"type":"channel_data","connection_id":"60a4fc71-1312-4830-86f4-9eb98be106ac","message_id":3063,"id":"ETH-USD","channel":"v3_orderbook","contents":{"offset":"2693997495","bids":[["4214.1","0"]],"asks":[]}}
1635444249.371469: {"type":"channel_data","connection_id":"60a4fc71-1312-4830-86f4-9eb98be106ac","message_id":3064,"id":"ETH-USD","channel":"v3_orderbook","contents":{"offset":"2693997491","bids":[["4211","5623.34"]],"asks":[]}}
1635444249.3747132: {"type":"channel_data","connection_id":"60a4fc71-1312-4830-86f4-9eb98be106ac","message_id":3065,"id":"ETH-USD","channel":"v3_orderbook","contents":{"offset":"2693997489","bids":[["4214.6","24.567"]],"asks":[]}}
1635444249.37478: {"type":"channel_data","connection_id":"60a4fc71-1312-4830-86f4-9eb98be106ac","message_id":3066,"id":"ETH-USD","channel":"v3_orderbook","contents":{"offset":"2693997493","bids":[["4215.3","22.496"]],"asks":[]}}
1635444249.374805: {"type":"channel_data","connection_id":"60a4fc71-1312-4830-86f4-9eb98be106ac","message_id":3067,"id":"ETH-USD","channel":"v3_orderbook","contents":{"offset":"2693997497","bids":[["4212.2","17.86"]],"asks":[]}}
1635444249.383601: {"type":"channel_data","connection_id":"60a4fc71-1312-4830-86f4-9eb98be106ac","message_id":3068,"id":"ETH-USD","channel":"v3_orderbook","contents":{"offset":"2693997503","bids":[["4213.1","0"]],"asks":[]}}
1635444249.383668: {"type":"channel_data","connection_id":"60a4fc71-1312-4830-86f4-9eb98be106ac","message_id":3069,"id":"ETH-USD","channel":"v3_orderbook","contents":{"offset":"2693997501","bids":[],"asks":[["4216","107.331"]]}}
1635444249.389744: {"type":"channel_data","connection_id":"60a4fc71-1312-4830-86f4-9eb98be106ac","message_id":3070,"id":"ETH-USD","channel":"v3_orderbook","contents":{"offset":"2693997506","bids":[],"asks":[["4216","59.85"]]}}
1635444249.3898728: {"type":"channel_data","connection_id":"60a4fc71-1312-4830-86f4-9eb98be106ac","message_id":3071,"id":"ETH-USD","channel":"v3_orderbook","contents":{"offset":"2693997508","bids":[["4205.7","1.784"]],"asks":[]}}
1635444249.389903: {"type":"channel_data","connection_id":"60a4fc71-1312-4830-86f4-9eb98be106ac","message_id":3072,"id":"ETH-USD","channel":"v3_orderbook","contents":{"offset":"2693997507","bids":[["4212.4","3.721"]],"asks":[]}}
1635444249.389927: {"type":"channel_data","connection_id":"60a4fc71-1312-4830-86f4-9eb98be106ac","message_id":3073,"id":"ETH-USD","channel":"v3_orderbook","contents":{"offset":"2693997510","bids":[],"asks":[["4218.1","1.512"]]}}
1635444249.389947: {"type":"channel_data","connection_id":"60a4fc71-1312-4830-86f4-9eb98be106ac","message_id":3074,"id":"UNI-USD","channel":"v3_orderbook","contents":{"offset":"2693997509","bids":[["25.025","15601.2"]],"asks":[]}}
1635444249.396588: {"type":"channel_data","connection_id":"60a4fc71-1312-4830-86f4-9eb98be106ac","message_id":3075,"id":"ETH-USD","channel":"v3_orderbook","contents":{"offset":"2693997512","bids":[],"asks":[["4216.9","2.922"]]}}
1635444249.4201431: {"type":"channel_data","connection_id":"60a4fc71-1312-4830-86f4-9eb98be106ac","message_id":3076,"id":"UNI-USD","channel":"v3_orderbook","contents":{"offset":"2693997522","bids":[],"asks":[["25.077","1585.8"]]}}
1635444249.4202518: {"type":"channel_data","connection_id":"60a4fc71-1312-4830-86f4-9eb98be106ac","message_id":3077,"id":"ETH-USD","channel":"v3_orderbook","contents":{"offset":"2693997521","bids":[["4211.9","0"]],"asks":[]}}
1635444249.4202828: {"type":"channel_data","connection_id":"60a4fc71-1312-4830-86f4-9eb98be106ac","message_id":3078,"id":"UNI-USD","channel":"v3_orderbook","contents":{"offset":"2693997520","bids":[],"asks":[["25.087","0"]]}}
1635444249.4295812: {"type":"channel_data","connection_id":"60a4fc71-1312-4830-86f4-9eb98be106ac","message_id":3079,"id":"ETH-USD","channel":"v3_orderbook","contents":{"offset":"2693997524","bids":[["4212","7.216"]],"asks":[]}}
1635444249.429643: {"type":"channel_data","connection_id":"60a4fc71-1312-4830-86f4-9eb98be106ac","message_id":3080,"id":"SUSHI-USD","channel":"v3_orderbook","contents":{"offset":"2693997525","bids":[],"asks":[["10.797","1931.5"]]}}
1635444249.438667: {"type":"channel_data","connection_id":"60a4fc71-1312-4830-86f4-9eb98be106ac","message_id":3081,"id":"ETH-USD","channel":"v3_orderbook","contents":{"offset":"2693997528","bids":[["4214.7","56.473"]],"asks":[]}}
1635444249.438925: {"type":"channel_data","connection_id":"60a4fc71-1312-4830-86f4-9eb98be106ac","message_id":3082,"id":"ETH-USD","channel":"v3_orderbook","contents":{"offset":"2693997531","bids":[["4212.2","65.35"]],"asks":[]}}
1635444249.4389892: {"type":"channel_data","connection_id":"60a4fc71-1312-4830-86f4-9eb98be106ac","message_id":3083,"id":"ETH-USD","channel":"v3_orderbook","contents":{"offset":"2693997529","bids":[],"asks":[["4215.6","494.621"]]}}
1635444249.4469278: {"type":"channel_data","connection_id":"60a4fc71-1312-4830-86f4-9eb98be106ac","message_id":3084,"id":"CRV-USD","channel":"v3_orderbook","contents":{"offset":"2693997532","bids":[["4.844","22387"]],"asks":[]}}
1635444249.448839: {"type":"channel_data","connection_id":"60a4fc71-1312-4830-86f4-9eb98be106ac","message_id":3085,"id":"ETH-USD","channel":"v3_orderbook","contents":{"offset":"2693997534","bids":[["4212.2","47.49"]],"asks":[]}}
1635444249.458978: {"type":"channel_data","connection_id":"60a4fc71-1312-4830-86f4-9eb98be106ac","message_id":3086,"id":"UMA-USD","channel":"v3_orderbook","contents":{"offset":"2693997535","bids":[],"asks":[["11.34","295.6"]]}}
1635444249.459042: {"type":"channel_data","connection_id":"60a4fc71-1312-4830-86f4-9eb98be106ac","message_id":3087,"id":"SUSHI-USD","channel":"v3_orderbook","contents":{"offset":"2693997536","bids":[["10.785","1718.5"]],"asks":[]}}
1635444249.4600792: {"type":"channel_data","connection_id":"60a4fc71-1312-4830-86f4-9eb98be106ac","message_id":3088,"id":"ETH-USD","channel":"v3_orderbook","contents":{"offset":"2693997537","bids":[["4213","996.35"]],"asks":[]}}
1635444249.488863: {"type":"channel_data","connection_id":"60a4fc71-1312-4830-86f4-9eb98be106ac","message_id":3089,"id":"ETH-USD","channel":"v3_orderbook","contents":{"offset":"2693997551","bids":[["4213.6","58.53"]],"asks":[]}}
1635444249.491746: {"type":"channel_data","connection_id":"60a4fc71-1312-4830-86f4-9eb98be106ac","message_id":3090,"id":"ETH-USD","channel":"v3_orderbook","contents":{"offset":"2693997550","bids":[["4203.9","0.7"]],"asks":[]}}
1635444249.5047529: {"type":"channel_data","connection_id":"60a4fc71-1312-4830-86f4-9eb98be106ac","message_id":3091,"id":"ETH-USD","channel":"v3_orderbook","contents":{"offset":"2693997556","bids":[["4213.6","0"]],"asks":[]}}
1635444249.504816: {"type":"channel_data","connection_id":"60a4fc71-1312-4830-86f4-9eb98be106ac","message_id":3092,"id":"ETH-USD","channel":"v3_orderbook","contents":{"offset":"2693997555","bids":[["4211.6","59.835"]],"asks":[]}}
1635444249.50484: {"type":"channel_data","connection_id":"60a4fc71-1312-4830-86f4-9eb98be106ac","message_id":3093,"id":"ETH-USD","channel":"v3_orderbook","contents":{"offset":"2693997557","bids":[["4214.7","0"]],"asks":[]}}
1635444249.5231318: {"type":"channel_data","connection_id":"60a4fc71-1312-4830-86f4-9eb98be106ac","message_id":3094,"id":"UNI-USD","channel":"v3_orderbook","contents":{"offset":"2693997559","bids":[["25.039","0"]],"asks":[]}}
1635444249.5232: {"type":"channel_data","connection_id":"60a4fc71-1312-4830-86f4-9eb98be106ac","message_id":3095,"id":"UNI-USD","channel":"v3_orderbook","contents":{"offset":"2693997560","bids":[],"asks":[["25.208","998.8"],["25.209","0"]]}}
1635444249.523914: {"type":"channel_data","connection_id":"60a4fc71-1312-4830-86f4-9eb98be106ac","message_id":3096,"id":"UNI-USD","channel":"v3_orderbook","contents":{"offset":"2693997563","bids":[["25.01","1585.8"]],"asks":[]}}
1635444249.5239522: {"type":"channel_data","connection_id":"60a4fc71-1312-4830-86f4-9eb98be106ac","message_id":3097,"id":"UNI-USD","channel":"v3_orderbook","contents":{"offset":"2693997561","bids":[["25.02","514.6"]],"asks":[]}}
1635444249.5358: {"type":"channel_data","connection_id":"60a4fc71-1312-4830-86f4-9eb98be106ac","message_id":3098,"id":"ETH-USD","channel":"v3_orderbook","contents":{"offset":"2693997564","bids":[["4214.8","57.986"]],"asks":[]}}
1635444249.547482: {"type":"channel_data","connection_id":"60a4fc71-1312-4830-86f4-9eb98be106ac","message_id":3099,"id":"ETH-USD","channel":"v3_orderbook","contents":{"offset":"2693997567","bids":[["4211.4","1941.171"]],"asks":[]}}
1635444249.5475452: {"type":"channel_data","connection_id":"60a4fc71-1312-4830-86f4-9eb98be106ac","message_id":3100,"id":"ETH-USD","channel":"v3_orderbook","contents":{"offset":"2693997568","bids":[],"asks":[["4215.6","499.396"]]}}
1635444249.5475688: {"type":"channel_data","connection_id":"60a4fc71-1312-4830-86f4-9eb98be106ac","message_id":3101,"id":"UMA-USD","channel":"v3_orderbook","contents":{"offset":"2693997571","bids":[["11.28","14736"]],"asks":[]}}
1635444249.560224: {"type":"channel_data","connection_id":"60a4fc71-1312-4830-86f4-9eb98be106ac","message_id":3102,"id":"SUSHI-USD","channel":"v3_orderbook","contents":{"offset":"2693997575","bids":[],"asks":[["10.795","4421.2"]]}}
1635444249.5603461: {"type":"channel_data","connection_id":"60a4fc71-1312-4830-86f4-9eb98be106ac","message_id":3103,"id":"UNI-USD","channel":"v3_orderbook","contents":{"offset":"2693997574","bids":[["24.866","0"],["24.864","998.8"]],"asks":[]}}
1635444249.570078: {"type":"channel_data","connection_id":"60a4fc71-1312-4830-86f4-9eb98be106ac","message_id":3104,"id":"UMA-USD","channel":"v3_orderbook","contents":{"offset":"2693997580","bids":[["11.28","14470.6"]],"asks":[]}}
1635444249.5710459: {"type":"channel_data","connection_id":"60a4fc71-1312-4830-86f4-9eb98be106ac","message_id":3105,"id":"UNI-USD","channel":"v3_orderbook","contents":{"offset":"2693997577","bids":[["25.038","59.8"]],"asks":[]}}
1635444249.571192: {"type":"channel_data","connection_id":"60a4fc71-1312-4830-86f4-9eb98be106ac","message_id":3106,"id":"ETH-USD","channel":"v3_orderbook","contents":{"offset":"2693997579","bids":[],"asks":[["4216.9","0"]]}}
1635444249.579318: {"type":"channel_data","connection_id":"60a4fc71-1312-4830-86f4-9eb98be106ac","message_id":3107,"id":"ETH-USD","channel":"v3_orderbook","contents":{"offset":"2693997587","bids":[],"asks":[["4215.6","494.621"]]}}
1635444249.5902379: {"type":"channel_data","connection_id":"60a4fc71-1312-4830-86f4-9eb98be106ac","message_id":3108,"id":"UNI-USD","channel":"v3_orderbook","contents":{"offset":"2693997591","bids":[["24.95","0"],["24.947","43.9"]],"asks":[]}}
1635444249.605291: {"type":"channel_data","connection_id":"60a4fc71-1312-4830-86f4-9eb98be106ac","message_id":3109,"id":"ETH-USD","channel":"v3_orderbook","contents":{"offset":"2693997592","bids":[],"asks":[["4216.1","145.172"]]}}
1635444249.605391: {"type":"channel_data","connection_id":"60a4fc71-1312-4830-86f4-9eb98be106ac","message_id":3110,"id":"CRV-USD","channel":"v3_orderbook","contents":{"offset":"2693997593","bids":[["4.835","5090"]],"asks":[]}}
1635444249.60933: {"type":"channel_data","connection_id":"60a4fc71-1312-4830-86f4-9eb98be106ac","message_id":3111,"id":"ETH-USD","channel":"v3_orderbook","contents":{"offset":"2693997599","bids":[],"asks":[["4216","58.95"]]}}
1635444249.610898: {"type":"channel_data","connection_id":"60a4fc71-1312-4830-86f4-9eb98be106ac","message_id":3112,"id":"UNI-USD","channel":"v3_orderbook","contents":{"offset":"2693997597","bids":[["25.038","0"]],"asks":[]}}
1635444249.613328: {"type":"channel_data","connection_id":"60a4fc71-1312-4830-86f4-9eb98be106ac","message_id":3113,"id":"UNI-USD","channel":"v3_orderbook","contents":{"offset":"2693997601","bids":[],"asks":[["25.136","43.9"],["25.14","0"]]}}
1635444249.616448: {"type":"channel_data","connection_id":"60a4fc71-1312-4830-86f4-9eb98be106ac","message_id":3114,"id":"SUSHI-USD","channel":"v3_orderbook","contents":{"offset":"2693997605","bids":[],"asks":[["10.807","1666.5"]]}}
1635444249.6533399: {"type":"channel_data","connection_id":"60a4fc71-1312-4830-86f4-9eb98be106ac","message_id":3115,"id":"UNI-USD","channel":"v3_orderbook","contents":{"offset":"2693997613","bids":[["24.878","0"],["24.877","1997.7"]],"asks":[]}}
1635444249.653406: {"type":"channel_data","connection_id":"60a4fc71-1312-4830-86f4-9eb98be106ac","message_id":3116,"id":"ETH-USD","channel":"v3_orderbook","contents":{"offset":"2693997612","bids":[["4213.9","58.52"]],"asks":[]}}
1635444249.667317: {"type":"channel_data","connection_id":"60a4fc71-1312-4830-86f4-9eb98be106ac","message_id":3117,"id":"ETH-USD","channel":"v3_orderbook","contents":{"offset":"2693997615","bids":[],"asks":[["4216.8","24.496"]]}}
1635444249.677736: {"type":"channel_data","connection_id":"60a4fc71-1312-4830-86f4-9eb98be106ac","message_id":3118,"id":"ETH-USD","channel":"v3_orderbook","contents":{"offset":"2693997618","bids":[["4214.9","58.446"]],"asks":[]}}
1635444249.6777909: {"type":"channel_data","connection_id":"60a4fc71-1312-4830-86f4-9eb98be106ac","message_id":3119,"id":"ETH-USD","channel":"v3_orderbook","contents":{"offset":"2693997620","bids":[["4214.6","22.496"]],"asks":[]}}
1635444249.6778119: {"type":"channel_data","connection_id":"60a4fc71-1312-4830-86f4-9eb98be106ac","message_id":3120,"id":"UNI-USD","channel":"v3_orderbook","contents":{"offset":"2693997619","bids":[["24.903","0"],["24.902","1997.7"]],"asks":[]}}
1635444249.677834: {"type":"channel_data","connection_id":"60a4fc71-1312-4830-86f4-9eb98be106ac","message_id":3121,"id":"ETH-USD","channel":"v3_orderbook","contents":{"offset":"2693997621","bids":[],"asks":[["4217.1","0.776"]]}}
1635444249.6791732: {"type":"channel_data","connection_id":"60a4fc71-1312-4830-86f4-9eb98be106ac","message_id":3122,"id":"SUSHI-USD","channel":"v3_orderbook","contents":{"offset":"2693997617","bids":[["10.784","8300.5"]],"asks":[]}}
1635444249.67921: {"type":"channel_data","connection_id":"60a4fc71-1312-4830-86f4-9eb98be106ac","message_id":3123,"id":"UNI-USD","channel":"v3_orderbook","contents":{"offset":"2693997622","bids":[["25.034","2925.4"]],"asks":[]}}
1635444249.703985: {"type":"channel_data","connection_id":"60a4fc71-1312-4830-86f4-9eb98be106ac","message_id":3124,"id":"SUSHI-USD","channel":"v3_orderbook","contents":{"offset":"2693997624","bids":[["10.784","4298.2"]],"asks":[]}}
1635444249.704063: {"type":"channel_data","connection_id":"60a4fc71-1312-4830-86f4-9eb98be106ac","message_id":3125,"id":"ETH-USD","channel":"v3_orderbook","contents":{"offset":"2693997625","bids":[["4212.1","7.216"]],"asks":[]}}
1635444249.7095199: {"type":"channel_data","connection_id":"60a4fc71-1312-4830-86f4-9eb98be106ac","message_id":3126,"id":"ETH-USD","channel":"v3_orderbook","contents":{"offset":"2693997628","bids":[["4210.1","4466.131"]],"asks":[]}}
1635444249.7095811: {"type":"channel_data","connection_id":"60a4fc71-1312-4830-86f4-9eb98be106ac","message_id":3127,"id":"MKR-USD","channel":"v3_orderbook","contents":{"offset":"2693997629","bids":[["2379","49.89"]],"asks":[]}}
1635444249.717675: {"type":"channel_data","connection_id":"60a4fc71-1312-4830-86f4-9eb98be106ac","message_id":3128,"id":"ETH-USD","channel":"v3_orderbook","contents":{"offset":"2693997631","bids":[],"asks":[["4215.6","494.521"]]}}
1635444249.7177339: {"type":"channel_data","connection_id":"60a4fc71-1312-4830-86f4-9eb98be106ac","message_id":3129,"id":"UNI-USD","channel":"v3_orderbook","contents":{"offset":"2693997634","bids":[],"asks":[["25.17","1067.1"],["25.171","147.7"]]}}
1635444249.720831: {"type":"channel_data","connection_id":"60a4fc71-1312-4830-86f4-9eb98be106ac","message_id":3130,"id":"ETH-USD","channel":"v3_orderbook","contents":{"offset":"2693997633","bids":[["4214.8","0"]],"asks":[]}}
1635444249.720893: {"type":"channel_data","connection_id":"60a4fc71-1312-4830-86f4-9eb98be106ac","message_id":3131,"id":"ETH-USD","channel":"v3_orderbook","contents":{"offset":"2693997635","bids":[],"asks":[["4215.6","484.738"]]}}
1635444249.7335732: {"type":"channel_data","connection_id":"60a4fc71-1312-4830-86f4-9eb98be106ac","message_id":3132,"id":"ETH-USD","channel":"v3_orderbook","contents":{"offset":"2693997644","bids":[],"asks":[["4215.7","9.783"]]}}
1635444249.733631: {"type":"channel_data","connection_id":"60a4fc71-1312-4830-86f4-9eb98be106ac","message_id":3133,"id":"UNI-USD","channel":"v3_orderbook","contents":{"offset":"2693997643","bids":[],"asks":[["25.195","1997.7"],["25.196","181"]]}}
1635444249.7368052: {"type":"channel_data","connection_id":"60a4fc71-1312-4830-86f4-9eb98be106ac","message_id":3134,"id":"ETH-USD","channel":"v3_trades","contents":{"trades":[{"size":"0.1","side":"BUY","price":"4215.6","createdAt":"2021-10-28T18:04:09.758Z"}]}}
1635444249.737144: {"type":"channel_data","connection_id":"60a4fc71-1312-4830-86f4-9eb98be106ac","message_id":3135,"id":"ETH-USD","channel":"v3_orderbook","contents":{"offset":"2693997639","bids":[["4212","0"]],"asks":[]}}
1635444249.749855: {"type":"channel_data","connection_id":"60a4fc71-1312-4830-86f4-9eb98be106ac","message_id":3136,"id":"ETH-USD","channel":"v3_orderbook","contents":{"offset":"2693997645","bids":[],"asks":[["4215.7","46.613"]]}}
1635444249.765697: {"type":"channel_data","connection_id":"60a4fc71-1312-4830-86f4-9eb98be106ac","message_id":3137,"id":"ETH-USD","channel":"v3_orderbook","contents":{"offset":"2693997648","bids":[],"asks":[["4215.6","532.228"]]}}
1635444249.7657542: {"type":"channel_data","connection_id":"60a4fc71-1312-4830-86f4-9eb98be106ac","message_id":3138,"id":"MKR-USD","channel":"v3_orderbook","contents":{"offset":"2693997651","bids":[["2378","73.753"]],"asks":[]}}
1635444249.799216: {"type":"channel_data","connection_id":"60a4fc71-1312-4830-86f4-9eb98be106ac","message_id":3139,"id":"SUSHI-USD","channel":"v3_orderbook","contents":{"offset":"2693997655","bids":[["10.781","8842.4"]],"asks":[]}}
1635444249.7992709: {"type":"channel_data","connection_id":"60a4fc71-1312-4830-86f4-9eb98be106ac","message_id":3140,"id":"ETH-USD","channel":"v3_orderbook","contents":{"offset":"2693997659","bids":[["4213.9","0"]],"asks":[]}}
1635444249.799293: {"type":"channel_data","connection_id":"60a4fc71-1312-4830-86f4-9eb98be106ac","message_id":3141,"id":"SUSHI-USD","channel":"v3_orderbook","contents":{"offset":"2693997657","bids":[],"asks":[["10.909","942.7"]]}}
1635444249.808201: {"type":"channel_data","connection_id":"60a4fc71-1312-4830-86f4-9eb98be106ac","message_id":3142,"id":"ETH-USD","channel":"v3_orderbook","contents":{"offset":"2693997661","bids":[],"asks":[["4215.6","531.428"]]}}
1635444249.828338: {"type":"channel_data","connection_id":"60a4fc71-1312-4830-86f4-9eb98be106ac","message_id":3143,"id":"ETH-USD","channel":"v3_orderbook","contents":{"offset":"2693997674","bids":[["4214.3","23.745"]],"asks":[]}}
1635444249.828395: {"type":"channel_data","connection_id":"60a4fc71-1312-4830-86f4-9eb98be106ac","message_id":3144,"id":"SUSHI-USD","channel":"v3_orderbook","contents":{"offset":"2693997672","bids":[],"asks":[["10.799","0"]]}}
1635444249.8529642: {"type":"channel_data","connection_id":"60a4fc71-1312-4830-86f4-9eb98be106ac","message_id":3145,"id":"ETH-USD","channel":"v3_orderbook","contents":{"offset":"2693997680","bids":[],"asks":[["4216.4","1904.855"]]}}
1635444249.855346: {"type":"channel_data","connection_id":"60a4fc71-1312-4830-86f4-9eb98be106ac","message_id":3146,"id":"SUSHI-USD","channel":"v3_orderbook","contents":{"offset":"2693997678","bids":[],"asks":[["10.797","1558.6"]]}}
1635444249.8729348: {"type":"channel_data","connection_id":"60a4fc71-1312-4830-86f4-9eb98be106ac","message_id":3147,"id":"XMR-USD","channel":"v3_orderbook","contents":{"offset":"2693997682","bids":[["264.7","434.34"]],"asks":[]}}
1635444249.872989: {"type":"channel_data","connection_id":"60a4fc71-1312-4830-86f4-9eb98be106ac","message_id":3148,"id":"XMR-USD","channel":"v3_orderbook","contents":{"offset":"2693997684","bids":[],"asks":[["265.7","2833.41"]]}}
1635444249.884541: {"type":"channel_data","connection_id":"60a4fc71-1312-4830-86f4-9eb98be106ac","message_id":3149,"id":"XMR-USD","channel":"v3_orderbook","contents":{"offset":"2693997689","bids":[],"asks":[["265.4","286.73"]]}}
1635444249.8846269: {"type":"channel_data","connection_id":"60a4fc71-1312-4830-86f4-9eb98be106ac","message_id":3150,"id":"XMR-USD","channel":"v3_orderbook","contents":{"offset":"2693997685","bids":[["265","75.75"]],"asks":[]}}
1635444249.8947022: {"type":"channel_data","connection_id":"60a4fc71-1312-4830-86f4-9eb98be106ac","message_id":3151,"id":"ETH-USD","channel":"v3_orderbook","contents":{"offset":"2693997692","bids":[],"asks":[["4215.6","555.173"]]}}
1635444249.894762: {"type":"channel_data","connection_id":"60a4fc71-1312-4830-86f4-9eb98be106ac","message_id":3152,"id":"ETH-USD","channel":"v3_orderbook","contents":{"offset":"2693997696","bids":[],"asks":[["4215.6","555.973"]]}}
1635444249.8947809: {"type":"channel_data","connection_id":"60a4fc71-1312-4830-86f4-9eb98be106ac","message_id":3153,"id":"EOS-USD","channel":"v3_orderbook","contents":{"offset":"2693997693","bids":[],"asks":[["4.403","15864"]]}}
1635444249.89573: {"type":"channel_data","connection_id":"60a4fc71-1312-4830-86f4-9eb98be106ac","message_id":3154,"id":"SUSHI-USD","channel":"v3_orderbook","contents":{"offset":"2693997697","bids":[],"asks":[["10.798","269.7"]]}}
1635444249.899734: {"type":"channel_data","connection_id":"60a4fc71-1312-4830-86f4-9eb98be106ac","message_id":3155,"id":"ETH-USD","channel":"v3_orderbook","contents":{"offset":"2693997694","bids":[["4215","57.443"]],"asks":[]}}
1635444249.9115589: {"type":"channel_data","connection_id":"60a4fc71-1312-4830-86f4-9eb98be106ac","message_id":3156,"id":"EOS-USD","channel":"v3_orderbook","contents":{"offset":"2693997700","bids":[],"asks":[["4.404","4821"]]}}
1635444249.911689: {"type":"channel_data","connection_id":"60a4fc71-1312-4830-86f4-9eb98be106ac","message_id":3157,"id":"ETH-USD","channel":"v3_orderbook","contents":{"offset":"2693997701","bids":[["4214","93.749"]],"asks":[]}}
1635444249.911725: {"type":"channel_data","connection_id":"60a4fc71-1312-4830-86f4-9eb98be106ac","message_id":3158,"id":"UMA-USD","channel":"v3_orderbook","contents":{"offset":"2693997702","bids":[["11.27","28817.3"]],"asks":[]}}
1635444249.922526: {"type":"channel_data","connection_id":"60a4fc71-1312-4830-86f4-9eb98be106ac","message_id":3159,"id":"EOS-USD","channel":"v3_orderbook","contents":{"offset":"2693997705","bids":[["4.398","17051"]],"asks":[]}}
1635444249.940243: {"type":"channel_data","connection_id":"60a4fc71-1312-4830-86f4-9eb98be106ac","message_id":3160,"id":"UMA-USD","channel":"v3_orderbook","contents":{"offset":"2693997710","bids":[["11.27","29082.7"]],"asks":[]}}
1635444249.965389: {"type":"channel_data","connection_id":"60a4fc71-1312-4830-86f4-9eb98be106ac","message_id":3161,"id":"SUSHI-USD","channel":"v3_orderbook","contents":{"offset":"2693997719","bids":[["10.767","771.5"]],"asks":[]}}
1635444249.977291: {"type":"channel_data","connection_id":"60a4fc71-1312-4830-86f4-9eb98be106ac","message_id":3162,"id":"UMA-USD","channel":"v3_orderbook","contents":{"offset":"2693997725","bids":[["11.27","28817.3"]],"asks":[]}}
1635444249.996007: {"type":"channel_data","connection_id":"60a4fc71-1312-4830-86f4-9eb98be106ac","message_id":3163,"id":"ETH-USD","channel":"v3_orderbook","contents":{"offset":"2693997735","bids":[["4213","996.55"]],"asks":[]}}
1635444249.996062: {"type":"channel_data","connection_id":"60a4fc71-1312-4830-86f4-9eb98be106ac","message_id":3164,"id":"ETH-USD","channel":"v3_orderbook","contents":{"offset":"2693997736","bids":[],"asks":[["4217.7","4484.705"]]}}
1635444250.02823: {"type":"channel_data","connection_id":"60a4fc71-1312-4830-86f4-9eb98be106ac","message_id":3165,"id":"ETH-USD","channel":"v3_orderbook","contents":{"offset":"2693997745","bids":[["4214","35.229"]],"asks":[]}}
1635444250.057527: {"type":"channel_data","connection_id":"60a4fc71-1312-4830-86f4-9eb98be106ac","message_id":3166,"id":"ETH-USD","channel":"v3_orderbook","contents":{"offset":"2693997759","bids":[],"asks":[["4222.2","0"]]}}
1635444250.057579: {"type":"channel_data","connection_id":"60a4fc71-1312-4830-86f4-9eb98be106ac","message_id":3167,"id":"CRV-USD","channel":"v3_orderbook","contents":{"offset":"2693997757","bids":[],"asks":[["4.855","618"]]}}
1635444250.057599: {"type":"channel_data","connection_id":"60a4fc71-1312-4830-86f4-9eb98be106ac","message_id":3168,"id":"ETH-USD","channel":"v3_orderbook","contents":{"offset":"2693997758","bids":[["4210","2.623"]],"asks":[]}}
1635444250.075983: {"type":"channel_data","connection_id":"60a4fc71-1312-4830-86f4-9eb98be106ac","message_id":3169,"id":"UNI-USD","channel":"v3_orderbook","contents":{"offset":"2693997772","bids":[["25.01","0"]],"asks":[]}}
1635444250.1032808: {"type":"channel_data","connection_id":"60a4fc71-1312-4830-86f4-9eb98be106ac","message_id":3170,"id":"UNI-USD","channel":"v3_orderbook","contents":{"offset":"2693997780","bids":[["25.02","2100.4"]],"asks":[]}}
1635444250.1129029: {"type":"channel_data","connection_id":"60a4fc71-1312-4830-86f4-9eb98be106ac","message_id":3171,"id":"UMA-USD","channel":"v3_orderbook","contents":{"offset":"2693997786","bids":[["11.26","10296.6"]],"asks":[]}}
1635444250.192845: {"type":"channel_data","connection_id":"60a4fc71-1312-4830-86f4-9eb98be106ac","message_id":3172,"id":"ETH-USD","channel":"v3_orderbook","contents":{"offset":"2693997801","bids":[["4214.2","81.016"]],"asks":[]}}
1635444250.192941: {"type":"channel_data","connection_id":"60a4fc71-1312-4830-86f4-9eb98be106ac","message_id":3173,"id":"ETH-USD","channel":"v3_orderbook","contents":{"offset":"2693997812","bids":[["4211.8","1410.88"]],"asks":[]}}
1635444250.2010539: {"type":"channel_data","connection_id":"60a4fc71-1312-4830-86f4-9eb98be106ac","message_id":3174,"id":"SUSHI-USD","channel":"v3_orderbook","contents":{"offset":"2693997817","bids":[],"asks":[["10.824","388.1"]]}}
1635444250.211818: {"type":"channel_data","connection_id":"60a4fc71-1312-4830-86f4-9eb98be106ac","message_id":3175,"id":"UMA-USD","channel":"v3_orderbook","contents":{"offset":"2693997820","bids":[["11.26","10632.4"]],"asks":[]}}
1635444250.2225978: {"type":"channel_data","connection_id":"60a4fc71-1312-4830-86f4-9eb98be106ac","message_id":3176,"id":"MKR-USD","channel":"v3_orderbook","contents":{"offset":"2693997823","bids":[],"asks":[["2402","14.676"],["2403","1.781"]]}}
1635444250.222656: {"type":"channel_data","connection_id":"60a4fc71-1312-4830-86f4-9eb98be106ac","message_id":3177,"id":"ETH-USD","channel":"v3_orderbook","contents":{"offset":"2693997824","bids":[["4215.5","132.299"]],"asks":[]}}
1635444250.2510662: {"type":"channel_data","connection_id":"60a4fc71-1312-4830-86f4-9eb98be106ac","message_id":3178,"id":"XMR-USD","channel":"v3_orderbook","contents":{"offset":"2693997830","bids":[["265","151.21"]],"asks":[]}}
1635444250.251164: {"type":"channel_data","connection_id":"60a4fc71-1312-4830-86f4-9eb98be106ac","message_id":3179,"id":"XMR-USD","channel":"v3_orderbook","contents":{"offset":"2693997829","bids":[["264.7","736.16"]],"asks":[]}}
1635444250.251185: {"type":"channel_data","connection_id":"60a4fc71-1312-4830-86f4-9eb98be106ac","message_id":3180,"id":"CRV-USD","channel":"v3_orderbook","contents":{"offset":"2693997836","bids":[["4.835","2589"]],"asks":[]}}
1635444250.251203: {"type":"channel_data","connection_id":"60a4fc71-1312-4830-86f4-9eb98be106ac","message_id":3181,"id":"UMA-USD","channel":"v3_orderbook","contents":{"offset":"2693997835","bids":[["11.27","29082.7"]],"asks":[]}}
1635444250.25709: {"type":"channel_data","connection_id":"60a4fc71-1312-4830-86f4-9eb98be106ac","message_id":3182,"id":"CRV-USD","channel":"v3_orderbook","contents":{"offset":"2693997839","bids":[],"asks":[["4.869","2591"]]}}
1635444250.301455: {"type":"channel_data","connection_id":"60a4fc71-1312-4830-86f4-9eb98be106ac","message_id":3183,"id":"UMA-USD","channel":"v3_orderbook","contents":{"offset":"2693997847","bids":[["11.27","28817.3"]],"asks":[]}}
1635444250.332132: {"type":"channel_data","connection_id":"60a4fc71-1312-4830-86f4-9eb98be106ac","message_id":3184,"id":"CRV-USD","channel":"v3_orderbook","contents":{"offset":"2693997855","bids":[],"asks":[["4.854","2512"]]}}
1635444250.3321862: {"type":"channel_data","connection_id":"60a4fc71-1312-4830-86f4-9eb98be106ac","message_id":3185,"id":"CRV-USD","channel":"v3_orderbook","contents":{"offset":"2693997857","bids":[],"asks":[["4.866","5668"]]}}
1635444250.3398888: {"type":"channel_data","connection_id":"60a4fc71-1312-4830-86f4-9eb98be106ac","message_id":3186,"id":"CRV-USD","channel":"v3_orderbook","contents":{"offset":"2693997859","bids":[],"asks":[["4.863","8858"]]}}
1635444250.3497112: {"type":"channel_data","connection_id":"60a4fc71-1312-4830-86f4-9eb98be106ac","message_id":3187,"id":"XMR-USD","channel":"v3_orderbook","contents":{"offset":"2693997866","bids":[],"asks":[["265.7","3134.93"]]}}
1635444250.351596: {"type":"channel_data","connection_id":"60a4fc71-1312-4830-86f4-9eb98be106ac","message_id":3188,"id":"CRV-USD","channel":"v3_orderbook","contents":{"offset":"2693997868","bids":[],"asks":[["4.854","3512"]]}}
1635444250.351635: {"type":"channel_data","connection_id":"60a4fc71-1312-4830-86f4-9eb98be106ac","message_id":3189,"id":"XMR-USD","channel":"v3_orderbook","contents":{"offset":"2693997869","bids":[],"asks":[["265.4","362.11"]]}}
1635444250.391781: {"type":"channel_data","connection_id":"60a4fc71-1312-4830-86f4-9eb98be106ac","message_id":3190,"id":"UMA-USD","channel":"v3_orderbook","contents":{"offset":"2693997878","bids":[["11.26","11090.4"]],"asks":[]}}
1635444250.4053419: {"type":"channel_data","connection_id":"60a4fc71-1312-4830-86f4-9eb98be106ac","message_id":3191,"id":"UNI-USD","channel":"v3_orderbook","contents":{"offset":"2693997882","bids":[],"asks":[["25.207","998.8"],["25.208","0"]]}}
1635444250.405401: {"type":"channel_data","connection_id":"60a4fc71-1312-4830-86f4-9eb98be106ac","message_id":3192,"id":"CRV-USD","channel":"v3_orderbook","contents":{"offset":"2693997883","bids":[],"asks":[["4.854","2512"]]}}
1635444250.4054232: {"type":"channel_data","connection_id":"60a4fc71-1312-4830-86f4-9eb98be106ac","message_id":3193,"id":"ETH-USD","channel":"v3_orderbook","contents":{"offset":"2693997881","bids":[["4207.4","94.13"]],"asks":[]}}
1635444250.429303: {"type":"channel_data","connection_id":"60a4fc71-1312-4830-86f4-9eb98be106ac","message_id":3194,"id":"ETH-USD","channel":"v3_orderbook","contents":{"offset":"2693997888","bids":[["4213.9","2.029"]],"asks":[]}}
1635444250.429374: {"type":"channel_data","connection_id":"60a4fc71-1312-4830-86f4-9eb98be106ac","message_id":3195,"id":"ETH-USD","channel":"v3_orderbook","contents":{"offset":"2693997891","bids":[],"asks":[["4216.9","1.941"]]}}
1635444250.429397: {"type":"channel_data","connection_id":"60a4fc71-1312-4830-86f4-9eb98be106ac","message_id":3196,"id":"ETH-USD","channel":"v3_orderbook","contents":{"offset":"2693997889","bids":[],"asks":[["4216.6","38.476"]]}}
1635444250.496459: {"type":"channel_data","connection_id":"60a4fc71-1312-4830-86f4-9eb98be106ac","message_id":3197,"id":"MKR-USD","channel":"v3_orderbook","contents":{"offset":"2693997894","bids":[],"asks":[["2383","32.5"]]}}
1635444250.5462248: {"type":"channel_data","connection_id":"60a4fc71-1312-4830-86f4-9eb98be106ac","message_id":3198,"id":"BCH-USD","channel":"v3_orderbook","contents":{"offset":"2693997906","bids":[["571.7","262.47"],["571.6","0"]],"asks":[]}}
1635444250.5463161: {"type":"channel_data","connection_id":"60a4fc71-1312-4830-86f4-9eb98be106ac","message_id":3199,"id":"SUSHI-USD","channel":"v3_orderbook","contents":{"offset":"2693997900","bids":[],"asks":[["10.797","1931.5"]]}}
1635444250.5463529: {"type":"channel_data","connection_id":"60a4fc71-1312-4830-86f4-9eb98be106ac","message_id":3200,"id":"ETH-USD","channel":"v3_orderbook","contents":{"offset":"2693997902","bids":[["4214.6","24.098"]],"asks":[]}}
1635444250.548356: {"type":"channel_data","connection_id":"60a4fc71-1312-4830-86f4-9eb98be106ac","message_id":3201,"id":"CRV-USD","channel":"v3_orderbook","contents":{"offset":"2693997910","bids":[["4.848","5399"]],"asks":[]}}
1635444250.579254: {"type":"channel_data","connection_id":"60a4fc71-1312-4830-86f4-9eb98be106ac","message_id":3202,"id":"ETH-USD","channel":"v3_orderbook","contents":{"offset":"2693997913","bids":[],"asks":[["4215.6","561.909"]]}}
1635444250.6105878: {"type":"channel_data","connection_id":"60a4fc71-1312-4830-86f4-9eb98be106ac","message_id":3203,"id":"SUSHI-USD","channel":"v3_orderbook","contents":{"offset":"2693997922","bids":[],"asks":[["10.798","656.7"]]}}
1635444250.610713: {"type":"channel_data","connection_id":"60a4fc71-1312-4830-86f4-9eb98be106ac","message_id":3204,"id":"CRV-USD","channel":"v3_orderbook","contents":{"offset":"2693997920","bids":[["4.834","4573"]],"asks":[]}}
1635444250.620049: {"type":"channel_data","connection_id":"60a4fc71-1312-4830-86f4-9eb98be106ac","message_id":3205,"id":"ETH-USD","channel":"v3_orderbook","contents":{"offset":"2693997927","bids":[["4214.9","60.431"]],"asks":[]}}
1635444250.62533: {"type":"channel_data","connection_id":"60a4fc71-1312-4830-86f4-9eb98be106ac","message_id":3206,"id":"SUSHI-USD","channel":"v3_orderbook","contents":{"offset":"2693997926","bids":[],"asks":[["10.803","1280.4"]]}}
1635444250.634429: {"type":"channel_data","connection_id":"60a4fc71-1312-4830-86f4-9eb98be106ac","message_id":3207,"id":"UMA-USD","channel":"v3_orderbook","contents":{"offset":"2693997937","bids":[["11.28","11134"]],"asks":[]}}
1635444250.644012: {"type":"channel_data","connection_id":"60a4fc71-1312-4830-86f4-9eb98be106ac","message_id":3208,"id":"UMA-USD","channel":"v3_orderbook","contents":{"offset":"2693997939","bids":[],"asks":[["11.3","0"]]}}
1635444250.654285: {"type":"channel_data","connection_id":"60a4fc71-1312-4830-86f4-9eb98be106ac","message_id":3209,"id":"CRV-USD","channel":"v3_orderbook","contents":{"offset":"2693997941","bids":[],"asks":[["4.868","3208"]]}}
1635444250.667209: {"type":"channel_data","connection_id":"60a4fc71-1312-4830-86f4-9eb98be106ac","message_id":3210,"id":"UMA-USD","channel":"v3_orderbook","contents":{"offset":"2693997944","bids":[["11.29","3336.6"]],"asks":[]}}
1635444250.66728: {"type":"channel_data","connection_id":"60a4fc71-1312-4830-86f4-9eb98be106ac","message_id":3211,"id":"UMA-USD","channel":"v3_orderbook","contents":{"offset":"2693997942","bids":[],"asks":[["11.31","13443.8"]]}}
1635444250.6810591: {"type":"channel_data","connection_id":"60a4fc71-1312-4830-86f4-9eb98be106ac","message_id":3212,"id":"UMA-USD","channel":"v3_orderbook","contents":{"offset":"2693997946","bids":[["11.27","29082.7"]],"asks":[]}}
1635444250.709271: {"type":"channel_data","connection_id":"60a4fc71-1312-4830-86f4-9eb98be106ac","message_id":3213,"id":"ETH-USD","channel":"v3_orderbook","contents":{"offset":"2693997954","bids":[],"asks":[["4221","2.01"]]}}
1635444250.7093298: {"type":"channel_data","connection_id":"60a4fc71-1312-4830-86f4-9eb98be106ac","message_id":3214,"id":"CRV-USD","channel":"v3_orderbook","contents":{"offset":"2693997953","bids":[],"asks":[["4.854","3512"]]}}
1635444250.709357: {"type":"channel_data","connection_id":"60a4fc71-1312-4830-86f4-9eb98be106ac","message_id":3215,"id":"UMA-USD","channel":"v3_orderbook","contents":{"offset":"2693997955","bids":[["11.27","28817.3"]],"asks":[]}}
1635444250.721292: {"type":"channel_data","connection_id":"60a4fc71-1312-4830-86f4-9eb98be106ac","message_id":3216,"id":"UMA-USD","channel":"v3_orderbook","contents":{"offset":"2693997962","bids":[["11.28","10991.2"]],"asks":[]}}
1635444250.721354: {"type":"channel_data","connection_id":"60a4fc71-1312-4830-86f4-9eb98be106ac","message_id":3217,"id":"UMA-USD","channel":"v3_orderbook","contents":{"offset":"2693997958","bids":[],"asks":[["11.33","29545.2"]]}}
1635444250.7602508: {"type":"channel_data","connection_id":"60a4fc71-1312-4830-86f4-9eb98be106ac","message_id":3218,"id":"UMA-USD","channel":"v3_orderbook","contents":{"offset":"2693997973","bids":[],"asks":[["11.31","13584.7"]]}}
1635444250.769973: {"type":"channel_data","connection_id":"60a4fc71-1312-4830-86f4-9eb98be106ac","message_id":3219,"id":"XMR-USD","channel":"v3_orderbook","contents":{"offset":"2693997975","bids":[],"asks":[["265.4","286.73"]]}}
1635444250.770041: {"type":"channel_data","connection_id":"60a4fc71-1312-4830-86f4-9eb98be106ac","message_id":3220,"id":"XMR-USD","channel":"v3_orderbook","contents":{"offset":"2693997977","bids":[["264.7","434.34"]],"asks":[]}}
1635444250.777927: {"type":"channel_data","connection_id":"60a4fc71-1312-4830-86f4-9eb98be106ac","message_id":3221,"id":"CRV-USD","channel":"v3_orderbook","contents":{"offset":"2693997983","bids":[],"asks":[["4.854","2512"]]}}
1635444250.778921: {"type":"channel_data","connection_id":"60a4fc71-1312-4830-86f4-9eb98be106ac","message_id":3222,"id":"XMR-USD","channel":"v3_orderbook","contents":{"offset":"2693997980","bids":[],"asks":[["265.7","2833.41"]]}}
1635444250.803839: {"type":"channel_data","connection_id":"60a4fc71-1312-4830-86f4-9eb98be106ac","message_id":3223,"id":"ETH-USD","channel":"v3_orderbook","contents":{"offset":"2693997986","bids":[["4208.8","0.2"]],"asks":[]}}
1635444250.803901: {"type":"channel_data","connection_id":"60a4fc71-1312-4830-86f4-9eb98be106ac","message_id":3224,"id":"XMR-USD","channel":"v3_orderbook","contents":{"offset":"2693997987","bids":[["265","75.75"]],"asks":[]}}
1635444250.8463922: {"type":"channel_data","connection_id":"60a4fc71-1312-4830-86f4-9eb98be106ac","message_id":3225,"id":"ETH-USD","channel":"v3_orderbook","contents":{"offset":"2693997997","bids":[["4214.5","1.602"]],"asks":[]}}
1635444250.846462: {"type":"channel_data","connection_id":"60a4fc71-1312-4830-86f4-9eb98be106ac","message_id":3226,"id":"CRV-USD","channel":"v3_orderbook","contents":{"offset":"2693997993","bids":[],"asks":[["4.854","3512"]]}}
1635444250.880179: {"type":"channel_data","connection_id":"60a4fc71-1312-4830-86f4-9eb98be106ac","message_id":3227,"id":"ETH-USD","channel":"v3_orderbook","contents":{"offset":"2693998001","bids":[["4215.5","132.199"]],"asks":[]}}
1635444250.90241: {"type":"channel_data","connection_id":"60a4fc71-1312-4830-86f4-9eb98be106ac","message_id":3228,"id":"ETH-USD","channel":"v3_trades","contents":{"trades":[{"size":"0.1","side":"SELL","price":"4215.5","createdAt":"2021-10-28T18:04:10.920Z"}]}}
1635444250.950668: {"type":"channel_data","connection_id":"60a4fc71-1312-4830-86f4-9eb98be106ac","message_id":3229,"id":"UNI-USD","channel":"v3_orderbook","contents":{"offset":"2693998018","bids":[["25.02","514.6"]],"asks":[]}}
1635444250.963913: {"type":"channel_data","connection_id":"60a4fc71-1312-4830-86f4-9eb98be106ac","message_id":3230,"id":"SUSHI-USD","channel":"v3_orderbook","contents":{"offset":"2693998026","bids":[["10.75","0"],["10.747","547.6"]],"asks":[]}}
1635444250.9662411: {"type":"channel_data","connection_id":"60a4fc71-1312-4830-86f4-9eb98be106ac","message_id":3231,"id":"LTC-USD","channel":"v3_orderbook","contents":{"offset":"2693998024","bids":[],"asks":[["189.2","1372.46"],["189.3","783.02"]]}}
1635444250.9663: {"type":"channel_data","connection_id":"60a4fc71-1312-4830-86f4-9eb98be106ac","message_id":3232,"id":"MKR-USD","channel":"v3_orderbook","contents":{"offset":"2693998022","bids":[],"asks":[["2389","46.011"]]}}
1635444250.974848: {"type":"channel_data","connection_id":"60a4fc71-1312-4830-86f4-9eb98be106ac","message_id":3233,"id":"LTC-USD","channel":"v3_orderbook","contents":{"offset":"2693998032","bids":[],"asks":[["189","914.59"],["189.1","183.54"]]}}
1635444250.976963: {"type":"channel_data","connection_id":"60a4fc71-1312-4830-86f4-9eb98be106ac","message_id":3234,"id":"SUSHI-USD","channel":"v3_orderbook","contents":{"offset":"2693998029","bids":[],"asks":[["10.827","101.9"],["10.831","0"]]}}
1635444250.995121: {"type":"channel_data","connection_id":"60a4fc71-1312-4830-86f4-9eb98be106ac","message_id":3235,"id":"UNI-USD","channel":"v3_orderbook","contents":{"offset":"2693998034","bids":[["25.01","1585.8"]],"asks":[]}}
1635444251.012479: {"type":"channel_data","connection_id":"60a4fc71-1312-4830-86f4-9eb98be106ac","message_id":3236,"id":"CRV-USD","channel":"v3_orderbook","contents":{"offset":"2693998037","bids":[],"asks":[["4.863","845"]]}}
1635444251.012542: {"type":"channel_data","connection_id":"60a4fc71-1312-4830-86f4-9eb98be106ac","message_id":3237,"id":"CRV-USD","channel":"v3_orderbook","contents":{"offset":"2693998038","bids":[],"asks":[["4.866","13681"]]}}
1635444251.030595: {"type":"channel_data","connection_id":"60a4fc71-1312-4830-86f4-9eb98be106ac","message_id":3238,"id":"ETH-USD","channel":"v3_orderbook","contents":{"offset":"2693998044","bids":[],"asks":[["4217.9","0"]]}}
1635444251.030668: {"type":"channel_data","connection_id":"60a4fc71-1312-4830-86f4-9eb98be106ac","message_id":3239,"id":"MKR-USD","channel":"v3_orderbook","contents":{"offset":"2693998043","bids":[["2377","10.514"]],"asks":[]}}
1635444251.0306938: {"type":"channel_data","connection_id":"60a4fc71-1312-4830-86f4-9eb98be106ac","message_id":3240,"id":"ETH-USD","channel":"v3_orderbook","contents":{"offset":"2693998041","bids":[],"asks":[["4218.4","41.512"]]}}
1635444251.062958: {"type":"channel_data","connection_id":"60a4fc71-1312-4830-86f4-9eb98be106ac","message_id":3241,"id":"UMA-USD","channel":"v3_orderbook","contents":{"offset":"2693998050","bids":[],"asks":[["11.33","7442.1"]]}}
1635444251.065364: {"type":"channel_data","connection_id":"60a4fc71-1312-4830-86f4-9eb98be106ac","message_id":3242,"id":"UMA-USD","channel":"v3_orderbook","contents":{"offset":"2693998051","bids":[],"asks":[["11.33","3035.9"]]}}
1635444251.11056: {"type":"channel_data","connection_id":"60a4fc71-1312-4830-86f4-9eb98be106ac","message_id":3243,"id":"XMR-USD","channel":"v3_orderbook","contents":{"offset":"2693998068","bids":[],"asks":[["265.4","362.11"]]}}
1635444251.110621: {"type":"channel_data","connection_id":"60a4fc71-1312-4830-86f4-9eb98be106ac","message_id":3244,"id":"XMR-USD","channel":"v3_orderbook","contents":{"offset":"2693998065","bids":[["264.7","736.16"]],"asks":[]}}
1635444251.1353102: {"type":"channel_data","connection_id":"60a4fc71-1312-4830-86f4-9eb98be106ac","message_id":3245,"id":"SUSHI-USD","channel":"v3_orderbook","contents":{"offset":"2693998073","bids":[["10.779","18476.3"]],"asks":[]}}
1635444251.166584: {"type":"channel_data","connection_id":"60a4fc71-1312-4830-86f4-9eb98be106ac","message_id":3246,"id":"UMA-USD","channel":"v3_orderbook","contents":{"offset":"2693998080","bids":[["11.28","10107.2"]],"asks":[]}}
1635444251.17115: {"type":"channel_data","connection_id":"60a4fc71-1312-4830-86f4-9eb98be106ac","message_id":3247,"id":"ETH-USD","channel":"v3_orderbook","contents":{"offset":"2693998078","bids":[],"asks":[["4215.6","555.973"]]}}
1635444251.1755269: {"type":"channel_data","connection_id":"60a4fc71-1312-4830-86f4-9eb98be106ac","message_id":3248,"id":"UNI-USD","channel":"v3_orderbook","contents":{"offset":"2693998082","bids":[],"asks":[["25.194","1997.7"],["25.195","0"]]}}
1635444251.184889: {"type":"channel_data","connection_id":"60a4fc71-1312-4830-86f4-9eb98be106ac","message_id":3249,"id":"UNI-USD","channel":"v3_orderbook","contents":{"offset":"2693998084","bids":[],"asks":[["25.169","1067.1"],["25.17","0"]]}}
