1635444234.1525419: {"type":"channel_data","connection_id":"60a4fc71-1312-4830-86f4-9eb98be106ac","message_id":642,"id":"ETH-USD","channel":"v3_orderbook","contents":{"offset":"2693989974","bids":[["4214.4","3.194"]],"asks":[]}}
1635444234.1606069: {"type":"channel_data","connection_id":"60a4fc71-1312-4830-86f4-9eb98be106ac","message_id":643,"id":"UNI-USD","channel":"v3_orderbook","contents":{"offset":"2693989983","bids":[],"asks":[["25.207","998.8"],["25.208","0"]]}}
1635444234.1607099: {"type":"channel_data","connection_id":"60a4fc71-1312-4830-86f4-9eb98be106ac","message_id":644,"id":"ETH-USD","channel":"v3_orderbook","contents":{"offset":"2693989988","bids":[["4213.3","0"]],"asks":[]}}
1635444234.163903: {"type":"channel_data","connection_id":"60a4fc71-1312-4830-86f4-9eb98be106ac","message_id":645,"id":"ETH-USD","channel":"v3_orderbook","contents":{"offset":"2693989989","bids":[["4215.9","468.609"]],"asks":[]}}
1635444234.1639528: {"type":"channel_data","connection_id":"60a4fc71-1312-4830-86f4-9eb98be106ac","message_id":646,"id":"UMA-USD","channel":"v3_orderbook","contents":{"offset":"2693989984","bids":[["11.27","29150.7"]],"asks":[]}}
1635444234.1639879: {"type":"channel_data","connection_id":"60a4fc71-1312-4830-86f4-9eb98be106ac","message_id":647,"id":"ETH-USD","channel":"v3_orderbook","contents":{"offset":"2693989986","bids":[["4214.8","41.521"]],"asks":[]}}
1635444234.164017: {"type":"channel_data","connection_id":"60a4fc71-1312-4830-86f4-9eb98be106ac","message_id":648,"id":"EOS-USD","channel":"v3_orderbook","contents":{"offset":"2693989982","bids":[],"asks":[["4.404","14965"]]}}
1635444234.1708941: {"type":"channel_data","connection_id":"60a4fc71-1312-4830-86f4-9eb98be106ac","message_id":649,"id":"ETH-USD","channel":"v3_orderbook","contents":{"offset":"2693989991","bids":[],"asks":[["4216.5","0"]]}}
1635444234.170977: {"type":"channel_data","connection_id":"60a4fc71-1312-4830-86f4-9eb98be106ac","message_id":650,"id":"ETH-USD","channel":"v3_orderbook","contents":{"offset":"2693989993","bids":[],"asks":[["4216.8","162.537"]]}}
1635444234.1710122: {"type":"channel_data","connection_id":"60a4fc71-1312-4830-86f4-9eb98be106ac","message_id":651,"id":"ETH-USD","channel":"v3_orderbook","contents":{"offset":"2693989994","bids":[["4212.6","0"]],"asks":[]}}
1635444234.172735: {"type":"channel_data","connection_id":"60a4fc71-1312-4830-86f4-9eb98be106ac","message_id":652,"id":"BCH-USD","channel":"v3_orderbook","contents":{"offset":"2693989992","bids":[["574.4","123.37"]],"asks":[]}}
1635444234.172792: {"type":"channel_data","connection_id":"60a4fc71-1312-4830-86f4-9eb98be106ac","message_id":653,"id":"ETH-USD","channel":"v3_orderbook","contents":{"offset":"2693989990","bids":[["4215.6","57.45"]],"asks":[]}}
1635444234.180545: {"type":"channel_data","connection_id":"60a4fc71-1312-4830-86f4-9eb98be106ac","message_id":654,"id":"ETH-USD","channel":"v3_orderbook","contents":{"offset":"2693989997","bids":[],"asks":[["4217.5","0"]]}}
1635444234.205023: {"type":"channel_data","connection_id":"60a4fc71-1312-4830-86f4-9eb98be106ac","message_id":655,"id":"ETH-USD","channel":"v3_orderbook","contents":{"offset":"2693990001","bids":[["4215","1007.429"]],"asks":[]}}
1635444234.225236: {"type":"channel_data","connection_id":"60a4fc71-1312-4830-86f4-9eb98be106ac","message_id":656,"id":"SUSHI-USD","channel":"v3_orderbook","contents":{"offset":"2693990006","bids":[["10.785","4590"]],"asks":[]}}
1635444234.237678: {"type":"channel_data","connection_id":"60a4fc71-1312-4830-86f4-9eb98be106ac","message_id":657,"id":"ETH-USD","channel":"v3_orderbook","contents":{"offset":"2693990007","bids":[],"asks":[["4239.8","11.866"]]}}
1635444234.237762: {"type":"channel_data","connection_id":"60a4fc71-1312-4830-86f4-9eb98be106ac","message_id":658,"id":"ETH-USD","channel":"v3_orderbook","contents":{"offset":"2693990010","bids":[],"asks":[["4216.5","23.734"]]}}
1635444234.237797: {"type":"channel_data","connection_id":"60a4fc71-1312-4830-86f4-9eb98be106ac","message_id":659,"id":"SUSHI-USD","channel":"v3_orderbook","contents":{"offset":"2693990011","bids":[],"asks":[["10.809","295.3"]]}}
1635444234.249563: {"type":"channel_data","connection_id":"60a4fc71-1312-4830-86f4-9eb98be106ac","message_id":660,"id":"EOS-USD","channel":"v3_orderbook","contents":{"offset":"2693990020","bids":[],"asks":[["4.404","16101"]]}}
1635444234.2496908: {"type":"channel_data","connection_id":"60a4fc71-1312-4830-86f4-9eb98be106ac","message_id":661,"id":"EOS-USD","channel":"v3_orderbook","contents":{"offset":"2693990024","bids":[["4.401","1136"]],"asks":[]}}
1635444234.249726: {"type":"channel_data","connection_id":"60a4fc71-1312-4830-86f4-9eb98be106ac","message_id":662,"id":"BCH-USD","channel":"v3_orderbook","contents":{"offset":"2693990018","bids":[["574.4","816.16"]],"asks":[]}}
1635444234.253723: {"type":"channel_data","connection_id":"60a4fc71-1312-4830-86f4-9eb98be106ac","message_id":663,"id":"ETH-USD","channel":"v3_orderbook","contents":{"offset":"2693990022","bids":[],"asks":[["4216.5","0"]]}}
1635444234.259495: {"type":"channel_data","connection_id":"60a4fc71-1312-4830-86f4-9eb98be106ac","message_id":664,"id":"XMR-USD","channel":"v3_orderbook","contents":{"offset":"2693990025","bids":[["265","75.46"]],"asks":[]}}
1635444234.259573: {"type":"channel_data","connection_id":"60a4fc71-1312-4830-86f4-9eb98be106ac","message_id":665,"id":"ETH-USD","channel":"v3_orderbook","contents":{"offset":"2693990026","bids":[["4213.2","1380.711"]],"asks":[]}}
1635444234.263874: {"type":"channel_data","connection_id":"60a4fc71-1312-4830-86f4-9eb98be106ac","message_id":666,"id":"SUSHI-USD","channel":"v3_orderbook","contents":{"offset":"2693990028","bids":[["10.79","1475.7"]],"asks":[]}}
1635444234.2756999: {"type":"channel_data","connection_id":"60a4fc71-1312-4830-86f4-9eb98be106ac","message_id":667,"id":"SUSHI-USD","channel":"v3_orderbook","contents":{"offset":"2693990034","bids":[],"asks":[["10.921","927.3"]]}}
1635444234.284045: {"type":"channel_data","connection_id":"60a4fc71-1312-4830-86f4-9eb98be106ac","message_id":668,"id":"MKR-USD","channel":"v3_orderbook","contents":{"offset":"2693990041","bids":[],"asks":[["2383","15.282"]]}}
1635444234.28468: {"type":"channel_data","connection_id":"60a4fc71-1312-4830-86f4-9eb98be106ac","message_id":669,"id":"ETH-USD","channel":"v3_orderbook","contents":{"offset":"2693990043","bids":[],"asks":[["4218.8","1.94"]]}}
1635444234.295795: {"type":"channel_data","connection_id":"60a4fc71-1312-4830-86f4-9eb98be106ac","message_id":670,"id":"ETH-USD","channel":"v3_orderbook","contents":{"offset":"2693990049","bids":[["4214.1","18.485"]],"asks":[]}}
1635444234.29898: {"type":"channel_data","connection_id":"60a4fc71-1312-4830-86f4-9eb98be106ac","message_id":671,"id":"EOS-USD","channel":"v3_orderbook","contents":{"offset":"2693990046","bids":[["4.401","0"]],"asks":[]}}
1635444234.299065: {"type":"channel_data","connection_id":"60a4fc71-1312-4830-86f4-9eb98be106ac","message_id":672,"id":"MKR-USD","channel":"v3_orderbook","contents":{"offset":"2693990045","bids":[],"asks":[["2385","83.228"]]}}
1635444234.3046222: {"type":"channel_data","connection_id":"60a4fc71-1312-4830-86f4-9eb98be106ac","message_id":673,"id":"EOS-USD","channel":"v3_orderbook","contents":{"offset":"2693990053","bids":[],"asks":[["4.405","44299"]]}}
1635444234.304765: {"type":"channel_data","connection_id":"60a4fc71-1312-4830-86f4-9eb98be106ac","message_id":674,"id":"EOS-USD","channel":"v3_orderbook","contents":{"offset":"2693990052","bids":[],"asks":[["4.404","14965"]]}}
1635444234.305231: {"type":"channel_data","connection_id":"60a4fc71-1312-4830-86f4-9eb98be106ac","message_id":675,"id":"EOS-USD","channel":"v3_orderbook","contents":{"offset":"2693990054","bids":[["4.4","12333"]],"asks":[]}}
1635444234.30821: {"type":"channel_data","connection_id":"60a4fc71-1312-4830-86f4-9eb98be106ac","message_id":676,"id":"ETH-USD","channel":"v3_orderbook","contents":{"offset":"2693990050","bids":[],"asks":[["4216.5","23.734"]]}}
1635444234.315584: {"type":"channel_data","connection_id":"60a4fc71-1312-4830-86f4-9eb98be106ac","message_id":677,"id":"ETH-USD","channel":"v3_orderbook","contents":{"offset":"2693990055","bids":[],"asks":[["4216.8","105.05"]]}}
1635444234.327018: {"type":"channel_data","connection_id":"60a4fc71-1312-4830-86f4-9eb98be106ac","message_id":678,"id":"ETH-USD","channel":"v3_orderbook","contents":{"offset":"2693990060","bids":[],"asks":[["4216.8","48.228"]]}}
1635444234.328074: {"type":"channel_data","connection_id":"60a4fc71-1312-4830-86f4-9eb98be106ac","message_id":679,"id":"ETH-USD","channel":"v3_orderbook","contents":{"offset":"2693990061","bids":[],"asks":[["4216.5","0"]]}}
1635444234.328133: {"type":"channel_data","connection_id":"60a4fc71-1312-4830-86f4-9eb98be106ac","message_id":680,"id":"XMR-USD","channel":"v3_orderbook","contents":{"offset":"2693990058","bids":[],"asks":[["265.4","286.73"]]}}
1635444234.330186: {"type":"channel_data","connection_id":"60a4fc71-1312-4830-86f4-9eb98be106ac","message_id":681,"id":"SUSHI-USD","channel":"v3_orderbook","contents":{"offset":"2693990062","bids":[["10.79","266.5"]],"asks":[]}}
1635444234.337976: {"type":"channel_data","connection_id":"60a4fc71-1312-4830-86f4-9eb98be106ac","message_id":682,"id":"UNI-USD","channel":"v3_orderbook","contents":{"offset":"2693990070","bids":[["24.876","0"],["24.875","1997.7"]],"asks":[]}}
1635444234.338069: {"type":"channel_data","connection_id":"60a4fc71-1312-4830-86f4-9eb98be106ac","message_id":683,"id":"EOS-USD","channel":"v3_orderbook","contents":{"offset":"2693990066","bids":[],"asks":[["4.405","43163"]]}}
1635444234.343314: {"type":"channel_data","connection_id":"60a4fc71-1312-4830-86f4-9eb98be106ac","message_id":684,"id":"EOS-USD","channel":"v3_orderbook","contents":{"offset":"2693990067","bids":[["4.4","11196"]],"asks":[]}}
1635444234.350719: {"type":"channel_data","connection_id":"60a4fc71-1312-4830-86f4-9eb98be106ac","message_id":685,"id":"SUSHI-USD","channel":"v3_orderbook","contents":{"offset":"2693990073","bids":[],"asks":[["10.807","11666.5"]]}}
1635444234.350802: {"type":"channel_data","connection_id":"60a4fc71-1312-4830-86f4-9eb98be106ac","message_id":686,"id":"ETH-USD","channel":"v3_orderbook","contents":{"offset":"2693990074","bids":[],"asks":[["4218.1","0"]]}}
1635444234.385928: {"type":"channel_data","connection_id":"60a4fc71-1312-4830-86f4-9eb98be106ac","message_id":687,"id":"ETH-USD","channel":"v3_orderbook","contents":{"offset":"2693990086","bids":[],"asks":[["4216.5","23.734"]]}}
1635444234.406372: {"type":"channel_data","connection_id":"60a4fc71-1312-4830-86f4-9eb98be106ac","message_id":688,"id":"ETH-USD","channel":"v3_orderbook","contents":{"offset":"2693990092","bids":[],"asks":[["4219.2","11.304"]]}}
1635444234.406972: {"type":"channel_data","connection_id":"60a4fc71-1312-4830-86f4-9eb98be106ac","message_id":689,"id":"ETH-USD","channel":"v3_orderbook","contents":{"offset":"2693990091","bids":[],"asks":[["4216.5","0"]]}}
1635444234.4194481: {"type":"channel_data","connection_id":"60a4fc71-1312-4830-86f4-9eb98be106ac","message_id":690,"id":"ETH-USD","channel":"v3_orderbook","contents":{"offset":"2693990095","bids":[["4213.8","0"]],"asks":[]}}
1635444234.4361768: {"type":"channel_data","connection_id":"60a4fc71-1312-4830-86f4-9eb98be106ac","message_id":691,"id":"UNI-USD","channel":"v3_orderbook","contents":{"offset":"2693990097","bids":[["24.901","0"],["24.9","1997.7"]],"asks":[]}}
1635444234.4363148: {"type":"channel_data","connection_id":"60a4fc71-1312-4830-86f4-9eb98be106ac","message_id":692,"id":"EOS-USD","channel":"v3_orderbook","contents":{"offset":"2693990098","bids":[],"asks":[["4.404","16101"]]}}
1635444234.436374: {"type":"channel_data","connection_id":"60a4fc71-1312-4830-86f4-9eb98be106ac","message_id":693,"id":"ETH-USD","channel":"v3_orderbook","contents":{"offset":"2693990099","bids":[],"asks":[["4217.6","0"]]}}
1635444234.4417028: {"type":"channel_data","connection_id":"60a4fc71-1312-4830-86f4-9eb98be106ac","message_id":694,"id":"ETH-USD","channel":"v3_orderbook","contents":{"offset":"2693990100","bids":[],"asks":[["4219.3","1.778"]]}}
1635444234.453538: {"type":"channel_data","connection_id":"60a4fc71-1312-4830-86f4-9eb98be106ac","message_id":695,"id":"ETH-USD","channel":"v3_orderbook","contents":{"offset":"2693990104","bids":[["4213.7","7.215"]],"asks":[]}}
1635444234.453623: {"type":"channel_data","connection_id":"60a4fc71-1312-4830-86f4-9eb98be106ac","message_id":696,"id":"EOS-USD","channel":"v3_orderbook","contents":{"offset":"2693990105","bids":[],"asks":[["4.404","14965"]]}}
1635444234.45366: {"type":"channel_data","connection_id":"60a4fc71-1312-4830-86f4-9eb98be106ac","message_id":697,"id":"ETH-USD","channel":"v3_orderbook","contents":{"offset":"2693990101","bids":[],"asks":[["4216.5","23.734"]]}}
1635444234.4536881: {"type":"channel_data","connection_id":"60a4fc71-1312-4830-86f4-9eb98be106ac","message_id":698,"id":"ETH-USD","channel":"v3_orderbook","contents":{"offset":"2693990102","bids":[],"asks":[["4219.2","12.727"]]}}
1635444234.463905: {"type":"channel_data","connection_id":"60a4fc71-1312-4830-86f4-9eb98be106ac","message_id":699,"id":"SUSHI-USD","channel":"v3_orderbook","contents":{"offset":"2693990109","bids":[["10.751","1102.9"],["10.749","3124.3"]],"asks":[]}}
1635444234.463996: {"type":"channel_data","connection_id":"60a4fc71-1312-4830-86f4-9eb98be106ac","message_id":700,"id":"ETH-USD","channel":"v3_orderbook","contents":{"offset":"2693990110","bids":[],"asks":[["4219.6","79.941"]]}}
1635444234.476972: {"type":"channel_data","connection_id":"60a4fc71-1312-4830-86f4-9eb98be106ac","message_id":701,"id":"ETH-USD","channel":"v3_orderbook","contents":{"offset":"2693990112","bids":[],"asks":[["4220.9","1.659"]]}}
1635444234.485025: {"type":"channel_data","connection_id":"60a4fc71-1312-4830-86f4-9eb98be106ac","message_id":702,"id":"ETH-USD","channel":"v3_orderbook","contents":{"offset":"2693990119","bids":[],"asks":[["4219.7","1.511"]]}}
1635444234.485108: {"type":"channel_data","connection_id":"60a4fc71-1312-4830-86f4-9eb98be106ac","message_id":703,"id":"ETH-USD","channel":"v3_orderbook","contents":{"offset":"2693990121","bids":[],"asks":[["4219.8","1.511"]]}}
1635444234.485142: {"type":"channel_data","connection_id":"60a4fc71-1312-4830-86f4-9eb98be106ac","message_id":704,"id":"ETH-USD","channel":"v3_orderbook","contents":{"offset":"2693990117","bids":[],"asks":[["4217.8","13.629"]]}}
1635444234.486597: {"type":"channel_data","connection_id":"60a4fc71-1312-4830-86f4-9eb98be106ac","message_id":705,"id":"ETH-USD","channel":"v3_orderbook","contents":{"offset":"2693990115","bids":[],"asks":[["4217.5","9.784"]]}}
1635444234.495717: {"type":"channel_data","connection_id":"60a4fc71-1312-4830-86f4-9eb98be106ac","message_id":706,"id":"XMR-USD","channel":"v3_orderbook","contents":{"offset":"2693990127","bids":[],"asks":[["265.3","75.39"]]}}
1635444234.495796: {"type":"channel_data","connection_id":"60a4fc71-1312-4830-86f4-9eb98be106ac","message_id":707,"id":"ETH-USD","channel":"v3_orderbook","contents":{"offset":"2693990129","bids":[["4215","22.855"]],"asks":[]}}
1635444234.4960861: {"type":"channel_data","connection_id":"60a4fc71-1312-4830-86f4-9eb98be106ac","message_id":708,"id":"ETH-USD","channel":"v3_orderbook","contents":{"offset":"2693990128","bids":[],"asks":[["4219.1","1.423"]]}}
1635444234.500298: {"type":"channel_data","connection_id":"60a4fc71-1312-4830-86f4-9eb98be106ac","message_id":709,"id":"ETH-USD","channel":"v3_orderbook","contents":{"offset":"2693990126","bids":[["4213.7","0"]],"asks":[]}}
1635444234.500353: {"type":"channel_data","connection_id":"60a4fc71-1312-4830-86f4-9eb98be106ac","message_id":710,"id":"ETH-USD","channel":"v3_orderbook","contents":{"offset":"2693990130","bids":[],"asks":[["4216.5","0"]]}}
1635444234.5003881: {"type":"channel_data","connection_id":"60a4fc71-1312-4830-86f4-9eb98be106ac","message_id":711,"id":"ETH-USD","channel":"v3_orderbook","contents":{"offset":"2693990123","bids":[],"asks":[["4216.7","207.201"]]}}
1635444234.503128: {"type":"channel_data","connection_id":"60a4fc71-1312-4830-86f4-9eb98be106ac","message_id":712,"id":"ETH-USD","channel":"v3_orderbook","contents":{"offset":"2693990131","bids":[],"asks":[["4216.7","263.899"]]}}
1635444234.5127401: {"type":"channel_data","connection_id":"60a4fc71-1312-4830-86f4-9eb98be106ac","message_id":713,"id":"SUSHI-USD","channel":"v3_orderbook","contents":{"offset":"2693990138","bids":[],"asks":[["10.83","0"],["10.832","101.9"]]}}
1635444234.5208058: {"type":"channel_data","connection_id":"60a4fc71-1312-4830-86f4-9eb98be106ac","message_id":714,"id":"ETH-USD","channel":"v3_orderbook","contents":{"offset":"2693990143","bids":[],"asks":[["4216.7","228.199"]]}}
1635444234.522277: {"type":"channel_data","connection_id":"60a4fc71-1312-4830-86f4-9eb98be106ac","message_id":715,"id":"ETH-USD","channel":"v3_orderbook","contents":{"offset":"2693990144","bids":[["4214.1","0"]],"asks":[]}}
1635444234.536012: {"type":"channel_data","connection_id":"60a4fc71-1312-4830-86f4-9eb98be106ac","message_id":716,"id":"ETH-USD","channel":"v3_orderbook","contents":{"offset":"2693990151","bids":[],"asks":[["4221.7","0"]]}}
1635444234.536094: {"type":"channel_data","connection_id":"60a4fc71-1312-4830-86f4-9eb98be106ac","message_id":717,"id":"UNI-USD","channel":"v3_orderbook","contents":{"offset":"2693990152","bids":[["24.949","43.9"]],"asks":[]}}
1635444234.536133: {"type":"channel_data","connection_id":"60a4fc71-1312-4830-86f4-9eb98be106ac","message_id":718,"id":"ETH-USD","channel":"v3_orderbook","contents":{"offset":"2693990150","bids":[],"asks":[["4217.5","0"]]}}
1635444234.536163: {"type":"channel_data","connection_id":"60a4fc71-1312-4830-86f4-9eb98be106ac","message_id":719,"id":"EOS-USD","channel":"v3_orderbook","contents":{"offset":"2693990149","bids":[],"asks":[["4.404","16101"]]}}
1635444234.5380569: {"type":"channel_data","connection_id":"60a4fc71-1312-4830-86f4-9eb98be106ac","message_id":720,"id":"ETH-USD","channel":"v3_orderbook","contents":{"offset":"2693990146","bids":[["4213.2","1350.09"]],"asks":[]}}
1635444234.538673: {"type":"channel_data","connection_id":"60a4fc71-1312-4830-86f4-9eb98be106ac","message_id":721,"id":"LTC-USD","channel":"v3_orderbook","contents":{"offset":"2693990156","bids":[],"asks":[["189","116.49"]]}}
1635444234.5404742: {"type":"channel_data","connection_id":"60a4fc71-1312-4830-86f4-9eb98be106ac","message_id":722,"id":"UNI-USD","channel":"v3_orderbook","contents":{"offset":"2693990156","bids":[["24.984","0"]],"asks":[["25.078","0"]]}}
1635444234.5441952: {"type":"channel_data","connection_id":"60a4fc71-1312-4830-86f4-9eb98be106ac","message_id":723,"id":"EOS-USD","channel":"v3_orderbook","contents":{"offset":"2693990156","bids":[["4.383","3010"]],"asks":[["4.413","229125"]]}}
1635444234.5442948: {"type":"channel_data","connection_id":"60a4fc71-1312-4830-86f4-9eb98be106ac","message_id":724,"id":"UNI-USD","channel":"v3_orderbook","contents":{"offset":"2693990153","bids":[],"asks":[["25.125","3673.8"]]}}
1635444234.547963: {"type":"channel_data","connection_id":"60a4fc71-1312-4830-86f4-9eb98be106ac","message_id":725,"id":"ETH-USD","channel":"v3_orderbook","contents":{"offset":"2693990159","bids":[],"asks":[["4217.3","1908.604"]]}}
1635444234.5480452: {"type":"channel_data","connection_id":"60a4fc71-1312-4830-86f4-9eb98be106ac","message_id":726,"id":"ETH-USD","channel":"v3_orderbook","contents":{"offset":"2693990161","bids":[],"asks":[["4216.7","114.21"]]}}
1635444234.5480819: {"type":"channel_data","connection_id":"60a4fc71-1312-4830-86f4-9eb98be106ac","message_id":727,"id":"ETH-USD","channel":"v3_orderbook","contents":{"offset":"2693990157","bids":[["4213.5","7.216"]],"asks":[]}}
1635444234.548112: {"type":"channel_data","connection_id":"60a4fc71-1312-4830-86f4-9eb98be106ac","message_id":728,"id":"ETH-USD","channel":"v3_orderbook","contents":{"offset":"2693990158","bids":[],"asks":[["4216.7","170.908"]]}}
1635444234.5603998: {"type":"channel_data","connection_id":"60a4fc71-1312-4830-86f4-9eb98be106ac","message_id":729,"id":"ETH-USD","channel":"v3_orderbook","contents":{"offset":"2693990165","bids":[],"asks":[["4216.5","23.734"]]}}
1635444234.560481: {"type":"channel_data","connection_id":"60a4fc71-1312-4830-86f4-9eb98be106ac","message_id":730,"id":"EOS-USD","channel":"v3_orderbook","contents":{"offset":"2693990166","bids":[],"asks":[["4.404","14965"]]}}
1635444234.581003: {"type":"channel_data","connection_id":"60a4fc71-1312-4830-86f4-9eb98be106ac","message_id":731,"id":"CRV-USD","channel":"v3_orderbook","contents":{"offset":"2693990167","bids":[["4.852","9565"]],"asks":[]}}
1635444234.5851898: {"type":"channel_data","connection_id":"60a4fc71-1312-4830-86f4-9eb98be106ac","message_id":732,"id":"CRV-USD","channel":"v3_orderbook","contents":{"offset":"2693990173","bids":[["4.837","8860"],["4.832","745"]],"asks":[]}}
1635444234.585282: {"type":"channel_data","connection_id":"60a4fc71-1312-4830-86f4-9eb98be106ac","message_id":733,"id":"CRV-USD","channel":"v3_orderbook","contents":{"offset":"2693990170","bids":[["4.85","747"]],"asks":[]}}
1635444234.593577: {"type":"channel_data","connection_id":"60a4fc71-1312-4830-86f4-9eb98be106ac","message_id":734,"id":"ETH-USD","channel":"v3_orderbook","contents":{"offset":"2693990176","bids":[],"asks":[["4217.3","1898.821"]]}}
1635444234.6028428: {"type":"channel_data","connection_id":"60a4fc71-1312-4830-86f4-9eb98be106ac","message_id":735,"id":"ETH-USD","channel":"v3_orderbook","contents":{"offset":"2693990180","bids":[],"asks":[["4216.5","0"]]}}
1635444234.6029172: {"type":"channel_data","connection_id":"60a4fc71-1312-4830-86f4-9eb98be106ac","message_id":736,"id":"ETH-USD","channel":"v3_orderbook","contents":{"offset":"2693990181","bids":[["4213.5","0"]],"asks":[]}}
1635444234.606347: {"type":"channel_data","connection_id":"60a4fc71-1312-4830-86f4-9eb98be106ac","message_id":737,"id":"ETH-USD","channel":"v3_orderbook","contents":{"offset":"2693990184","bids":[],"asks":[["4217.2","32.279"]]}}
1635444234.606427: {"type":"channel_data","connection_id":"60a4fc71-1312-4830-86f4-9eb98be106ac","message_id":738,"id":"ETH-USD","channel":"v3_orderbook","contents":{"offset":"2693990179","bids":[["4213.4","7.216"]],"asks":[]}}
1635444234.619083: {"type":"channel_data","connection_id":"60a4fc71-1312-4830-86f4-9eb98be106ac","message_id":739,"id":"ETH-USD","channel":"v3_orderbook","contents":{"offset":"2693990188","bids":[["4215","22.496"]],"asks":[]}}
1635444234.619165: {"type":"channel_data","connection_id":"60a4fc71-1312-4830-86f4-9eb98be106ac","message_id":740,"id":"ETH-USD","channel":"v3_orderbook","contents":{"offset":"2693990186","bids":[["4212.6","32.186"]],"asks":[]}}
1635444234.619201: {"type":"channel_data","connection_id":"60a4fc71-1312-4830-86f4-9eb98be106ac","message_id":741,"id":"EOS-USD","channel":"v3_orderbook","contents":{"offset":"2693990185","bids":[],"asks":[["4.404","16101"]]}}
1635444234.619242: {"type":"channel_data","connection_id":"60a4fc71-1312-4830-86f4-9eb98be106ac","message_id":742,"id":"ETH-USD","channel":"v3_orderbook","contents":{"offset":"2693990190","bids":[],"asks":[["4217.5","0.875"]]}}
1635444234.6195588: {"type":"channel_data","connection_id":"60a4fc71-1312-4830-86f4-9eb98be106ac","message_id":743,"id":"CRV-USD","channel":"v3_orderbook","contents":{"offset":"2693990189","bids":[["4.848","2219"]],"asks":[]}}
1635444234.626623: {"type":"channel_data","connection_id":"60a4fc71-1312-4830-86f4-9eb98be106ac","message_id":744,"id":"LTC-USD","channel":"v3_orderbook","contents":{"offset":"2693990193","bids":[["187.8","2909.08"]],"asks":[]}}
1635444234.6289659: {"type":"channel_data","connection_id":"60a4fc71-1312-4830-86f4-9eb98be106ac","message_id":745,"id":"ETH-USD","channel":"v3_orderbook","contents":{"offset":"2693990194","bids":[["4213.8","18.69"]],"asks":[]}}
1635444234.6290119: {"type":"channel_data","connection_id":"60a4fc71-1312-4830-86f4-9eb98be106ac","message_id":746,"id":"CRV-USD","channel":"v3_orderbook","contents":{"offset":"2693990195","bids":[["4.847","14498"]],"asks":[]}}
1635444234.642155: {"type":"channel_data","connection_id":"60a4fc71-1312-4830-86f4-9eb98be106ac","message_id":747,"id":"LTC-USD","channel":"v3_orderbook","contents":{"offset":"2693990196","bids":[["187.6","42349.15"]],"asks":[]}}
1635444234.648936: {"type":"channel_data","connection_id":"60a4fc71-1312-4830-86f4-9eb98be106ac","message_id":748,"id":"CRV-USD","channel":"v3_orderbook","contents":{"offset":"2693990199","bids":[["4.846","10189"]],"asks":[]}}
1635444234.64902: {"type":"channel_data","connection_id":"60a4fc71-1312-4830-86f4-9eb98be106ac","message_id":749,"id":"EOS-USD","channel":"v3_orderbook","contents":{"offset":"2693990200","bids":[],"asks":[["4.404","14965"]]}}
1635444234.664968: {"type":"channel_data","connection_id":"60a4fc71-1312-4830-86f4-9eb98be106ac","message_id":750,"id":"ETH-USD","channel":"v3_orderbook","contents":{"offset":"2693990207","bids":[],"asks":[["4216.5","23.734"]]}}
1635444234.665086: {"type":"channel_data","connection_id":"60a4fc71-1312-4830-86f4-9eb98be106ac","message_id":751,"id":"CRV-USD","channel":"v3_orderbook","contents":{"offset":"2693990205","bids":[["4.849","0"]],"asks":[]}}
1635444234.676252: {"type":"channel_data","connection_id":"60a4fc71-1312-4830-86f4-9eb98be106ac","message_id":752,"id":"UNI-USD","channel":"v3_orderbook","contents":{"offset":"2693990215","bids":[],"asks":[["25.078","2904.4"]]}}
1635444234.704127: {"type":"channel_data","connection_id":"60a4fc71-1312-4830-86f4-9eb98be106ac","message_id":753,"id":"CRV-USD","channel":"v3_orderbook","contents":{"offset":"2693990210","bids":[],"asks":[["4.86","4761"]]}}
1635444234.704212: {"type":"channel_data","connection_id":"60a4fc71-1312-4830-86f4-9eb98be106ac","message_id":754,"id":"CRV-USD","channel":"v3_orderbook","contents":{"offset":"2693990217","bids":[["4.847","13817"]],"asks":[]}}
1635444234.70424: {"type":"channel_data","connection_id":"60a4fc71-1312-4830-86f4-9eb98be106ac","message_id":755,"id":"CRV-USD","channel":"v3_orderbook","contents":{"offset":"2693990219","bids":[["4.846","9595"]],"asks":[]}}
1635444234.704261: {"type":"channel_data","connection_id":"60a4fc71-1312-4830-86f4-9eb98be106ac","message_id":756,"id":"EOS-USD","channel":"v3_orderbook","contents":{"offset":"2693990223","bids":[],"asks":[["4.413","237930"]]}}
1635444234.704282: {"type":"channel_data","connection_id":"60a4fc71-1312-4830-86f4-9eb98be106ac","message_id":757,"id":"LTC-USD","channel":"v3_orderbook","contents":{"offset":"2693990225","bids":[["187.6","42330.25"]],"asks":[]}}
1635444234.711859: {"type":"channel_data","connection_id":"60a4fc71-1312-4830-86f4-9eb98be106ac","message_id":758,"id":"CRV-USD","channel":"v3_orderbook","contents":{"offset":"2693990236","bids":[],"asks":[["4.859","1649"]]}}
1635444234.7171211: {"type":"channel_data","connection_id":"60a4fc71-1312-4830-86f4-9eb98be106ac","message_id":759,"id":"CRV-USD","channel":"v3_orderbook","contents":{"offset":"2693990237","bids":[],"asks":[["4.862","0"]]}}
1635444234.717181: {"type":"channel_data","connection_id":"60a4fc71-1312-4830-86f4-9eb98be106ac","message_id":760,"id":"CRV-USD","channel":"v3_orderbook","contents":{"offset":"2693990232","bids":[],"asks":[["4.865","30243"]]}}
1635444234.717216: {"type":"channel_data","connection_id":"60a4fc71-1312-4830-86f4-9eb98be106ac","message_id":761,"id":"EOS-USD","channel":"v3_orderbook","contents":{"offset":"2693990230","bids":[["4.383","11814"]],"asks":[]}}
1635444234.719223: {"type":"channel_data","connection_id":"60a4fc71-1312-4830-86f4-9eb98be106ac","message_id":762,"id":"ETH-USD","channel":"v3_orderbook","contents":{"offset":"2693990238","bids":[],"asks":[["4216.5","0"]]}}
1635444234.7257988: {"type":"channel_data","connection_id":"60a4fc71-1312-4830-86f4-9eb98be106ac","message_id":763,"id":"CRV-USD","channel":"v3_orderbook","contents":{"offset":"2693990239","bids":[],"asks":[["4.865","16873"]]}}
1635444234.725921: {"type":"channel_data","connection_id":"60a4fc71-1312-4830-86f4-9eb98be106ac","message_id":764,"id":"CRV-USD","channel":"v3_orderbook","contents":{"offset":"2693990241","bids":[],"asks":[["4.863","253"]]}}
1635444234.725991: {"type":"channel_data","connection_id":"60a4fc71-1312-4830-86f4-9eb98be106ac","message_id":765,"id":"CRV-USD","channel":"v3_orderbook","contents":{"offset":"2693990240","bids":[["4.852","4790"]],"asks":[]}}
1635444234.7354612: {"type":"channel_data","connection_id":"60a4fc71-1312-4830-86f4-9eb98be106ac","message_id":766,"id":"ETH-USD","channel":"v3_orderbook","contents":{"offset":"2693990252","bids":[],"asks":[["4218.5","4462.23"]]}}
1635444234.7355819: {"type":"channel_data","connection_id":"60a4fc71-1312-4830-86f4-9eb98be106ac","message_id":767,"id":"ETH-USD","channel":"v3_orderbook","contents":{"offset":"2693990247","bids":[],"asks":[["4218.8","0"]]}}
1635444234.735635: {"type":"channel_data","connection_id":"60a4fc71-1312-4830-86f4-9eb98be106ac","message_id":768,"id":"ETH-USD","channel":"v3_orderbook","contents":{"offset":"2693990249","bids":[],"asks":[["4219.4","0"]]}}
1635444234.735678: {"type":"channel_data","connection_id":"60a4fc71-1312-4830-86f4-9eb98be106ac","message_id":769,"id":"UMA-USD","channel":"v3_orderbook","contents":{"offset":"2693990248","bids":[["11.27","29416.1"]],"asks":[]}}
1635444234.737464: {"type":"channel_data","connection_id":"60a4fc71-1312-4830-86f4-9eb98be106ac","message_id":770,"id":"ETH-USD","channel":"v3_orderbook","contents":{"offset":"2693990251","bids":[],"asks":[["4220.8","0"]]}}
1635444234.7498171: {"type":"channel_data","connection_id":"60a4fc71-1312-4830-86f4-9eb98be106ac","message_id":771,"id":"CRV-USD","channel":"v3_orderbook","contents":{"offset":"2693990255","bids":[],"asks":[["4.865","8860"]]}}
1635444234.749901: {"type":"channel_data","connection_id":"60a4fc71-1312-4830-86f4-9eb98be106ac","message_id":772,"id":"CRV-USD","channel":"v3_orderbook","contents":{"offset":"2693990260","bids":[["4.827","0"],["4.826","7227"]],"asks":[]}}
1635444234.749944: {"type":"channel_data","connection_id":"60a4fc71-1312-4830-86f4-9eb98be106ac","message_id":773,"id":"CRV-USD","channel":"v3_orderbook","contents":{"offset":"2693990257","bids":[["4.85","593"]],"asks":[]}}
1635444234.749973: {"type":"channel_data","connection_id":"60a4fc71-1312-4830-86f4-9eb98be106ac","message_id":774,"id":"CRV-USD","channel":"v3_orderbook","contents":{"offset":"2693990256","bids":[["4.822","0"],["4.821","97885"]],"asks":[]}}
1635444234.750005: {"type":"channel_data","connection_id":"60a4fc71-1312-4830-86f4-9eb98be106ac","message_id":775,"id":"CRV-USD","channel":"v3_orderbook","contents":{"offset":"2693990258","bids":[],"asks":[["4.863","8266"]]}}
1635444234.77415: {"type":"channel_data","connection_id":"60a4fc71-1312-4830-86f4-9eb98be106ac","message_id":776,"id":"UMA-USD","channel":"v3_orderbook","contents":{"offset":"2693990268","bids":[["11.27","29150.7"]],"asks":[]}}
1635444234.774265: {"type":"channel_data","connection_id":"60a4fc71-1312-4830-86f4-9eb98be106ac","message_id":777,"id":"ETH-USD","channel":"v3_orderbook","contents":{"offset":"2693990263","bids":[["4214","1039.61"]],"asks":[]}}
1635444234.774322: {"type":"channel_data","connection_id":"60a4fc71-1312-4830-86f4-9eb98be106ac","message_id":778,"id":"CRV-USD","channel":"v3_orderbook","contents":{"offset":"2693990265","bids":[],"asks":[["4.856","172"]]}}
1635444234.7743769: {"type":"channel_data","connection_id":"60a4fc71-1312-4830-86f4-9eb98be106ac","message_id":779,"id":"UMA-USD","channel":"v3_orderbook","contents":{"offset":"2693990266","bids":[["11.26","10175"]],"asks":[]}}
1635444234.77442: {"type":"channel_data","connection_id":"60a4fc71-1312-4830-86f4-9eb98be106ac","message_id":780,"id":"LTC-USD","channel":"v3_orderbook","contents":{"offset":"2693990270","bids":[["187.7","351.7"]],"asks":[]}}
1635444234.7798688: {"type":"channel_data","connection_id":"60a4fc71-1312-4830-86f4-9eb98be106ac","message_id":781,"id":"ETH-USD","channel":"v3_orderbook","contents":{"offset":"2693990273","bids":[],"asks":[["4216.5","23.734"]]}}
1635444234.782181: {"type":"channel_data","connection_id":"60a4fc71-1312-4830-86f4-9eb98be106ac","message_id":782,"id":"CRV-USD","channel":"v3_orderbook","contents":{"offset":"2693990274","bids":[],"asks":[["4.854","3341"]]}}
1635444234.793544: {"type":"channel_data","connection_id":"60a4fc71-1312-4830-86f4-9eb98be106ac","message_id":783,"id":"CRV-USD","channel":"v3_orderbook","contents":{"offset":"2693990279","bids":[],"asks":[["4.873","2732"]]}}
1635444234.794104: {"type":"channel_data","connection_id":"60a4fc71-1312-4830-86f4-9eb98be106ac","message_id":784,"id":"CRV-USD","channel":"v3_orderbook","contents":{"offset":"2693990280","bids":[],"asks":[["4.859","6515"]]}}
1635444234.805275: {"type":"channel_data","connection_id":"60a4fc71-1312-4830-86f4-9eb98be106ac","message_id":785,"id":"ETH-USD","channel":"v3_orderbook","contents":{"offset":"2693990284","bids":[],"asks":[["4216.5","0"]]}}
1635444234.805357: {"type":"channel_data","connection_id":"60a4fc71-1312-4830-86f4-9eb98be106ac","message_id":786,"id":"ETH-USD","channel":"v3_orderbook","contents":{"offset":"2693990289","bids":[],"asks":[["4216.5","116.683"]]}}
1635444234.805393: {"type":"channel_data","connection_id":"60a4fc71-1312-4830-86f4-9eb98be106ac","message_id":787,"id":"ETH-USD","channel":"v3_orderbook","contents":{"offset":"2693990286","bids":[],"asks":[["4216.5","58.695"]]}}
1635444234.814621: {"type":"channel_data","connection_id":"60a4fc71-1312-4830-86f4-9eb98be106ac","message_id":788,"id":"EOS-USD","channel":"v3_orderbook","contents":{"offset":"2693990292","bids":[],"asks":[["4.403","11196"]]}}
1635444234.814682: {"type":"channel_data","connection_id":"60a4fc71-1312-4830-86f4-9eb98be106ac","message_id":789,"id":"CRV-USD","channel":"v3_orderbook","contents":{"offset":"2693990293","bids":[],"asks":[["4.86","0"]]}}
1635444234.819036: {"type":"channel_data","connection_id":"60a4fc71-1312-4830-86f4-9eb98be106ac","message_id":790,"id":"UNI-USD","channel":"v3_orderbook","contents":{"offset":"2693990290","bids":[["24.984","1814"]],"asks":[]}}
1635444234.819105: {"type":"channel_data","connection_id":"60a4fc71-1312-4830-86f4-9eb98be106ac","message_id":791,"id":"EOS-USD","channel":"v3_orderbook","contents":{"offset":"2693990291","bids":[],"asks":[["4.404","16101"]]}}
1635444234.824706: {"type":"channel_data","connection_id":"60a4fc71-1312-4830-86f4-9eb98be106ac","message_id":792,"id":"EOS-USD","channel":"v3_orderbook","contents":{"offset":"2693990295","bids":[["4.401","1136"]],"asks":[]}}
1635444234.825692: {"type":"channel_data","connection_id":"60a4fc71-1312-4830-86f4-9eb98be106ac","message_id":793,"id":"ETH-USD","channel":"v3_orderbook","contents":{"offset":"2693990296","bids":[],"asks":[["4221.9","0"]]}}
1635444234.826766: {"type":"channel_data","connection_id":"60a4fc71-1312-4830-86f4-9eb98be106ac","message_id":794,"id":"ETH-USD","channel":"v3_orderbook","contents":{"offset":"2693990294","bids":[["4209.2","0"]],"asks":[]}}
1635444234.8368142: {"type":"channel_data","connection_id":"60a4fc71-1312-4830-86f4-9eb98be106ac","message_id":795,"id":"CRV-USD","channel":"v3_orderbook","contents":{"offset":"2693990304","bids":[["4.85","5459"]],"asks":[]}}
1635444234.83887: {"type":"channel_data","connection_id":"60a4fc71-1312-4830-86f4-9eb98be106ac","message_id":796,"id":"CRV-USD","channel":"v3_orderbook","contents":{"offset":"2693990302","bids":[["4.819","925"],["4.817","16713"]],"asks":[]}}
1635444234.848228: {"type":"channel_data","connection_id":"60a4fc71-1312-4830-86f4-9eb98be106ac","message_id":797,"id":"EOS-USD","channel":"v3_orderbook","contents":{"offset":"2693990309","bids":[],"asks":[["4.405","44299"]]}}
1635444234.848353: {"type":"channel_data","connection_id":"60a4fc71-1312-4830-86f4-9eb98be106ac","message_id":798,"id":"ETH-USD","channel":"v3_orderbook","contents":{"offset":"2693990306","bids":[["4215","22.743"]],"asks":[]}}
1635444234.848415: {"type":"channel_data","connection_id":"60a4fc71-1312-4830-86f4-9eb98be106ac","message_id":799,"id":"SUSHI-USD","channel":"v3_orderbook","contents":{"offset":"2693990307","bids":[],"asks":[["10.799","4621.2"]]}}
1635444234.8639019: {"type":"channel_data","connection_id":"60a4fc71-1312-4830-86f4-9eb98be106ac","message_id":800,"id":"EOS-USD","channel":"v3_orderbook","contents":{"offset":"2693990317","bids":[],"asks":[["4.405","43163"]]}}
1635444234.8640199: {"type":"channel_data","connection_id":"60a4fc71-1312-4830-86f4-9eb98be106ac","message_id":801,"id":"EOS-USD","channel":"v3_orderbook","contents":{"offset":"2693990312","bids":[["4.401","0"]],"asks":[]}}
1635444234.868437: {"type":"channel_data","connection_id":"60a4fc71-1312-4830-86f4-9eb98be106ac","message_id":802,"id":"CRV-USD","channel":"v3_orderbook","contents":{"offset":"2693990321","bids":[],"asks":[["4.854","1246"]]}}
1635444234.868567: {"type":"channel_data","connection_id":"60a4fc71-1312-4830-86f4-9eb98be106ac","message_id":803,"id":"EOS-USD","channel":"v3_orderbook","contents":{"offset":"2693990319","bids":[["4.4","12333"]],"asks":[]}}
1635444234.871644: {"type":"channel_data","connection_id":"60a4fc71-1312-4830-86f4-9eb98be106ac","message_id":804,"id":"ETH-USD","channel":"v3_orderbook","contents":{"offset":"2693990320","bids":[],"asks":[["4216.5","140.417"]]}}
1635444234.871727: {"type":"channel_data","connection_id":"60a4fc71-1312-4830-86f4-9eb98be106ac","message_id":805,"id":"SUSHI-USD","channel":"v3_orderbook","contents":{"offset":"2693990322","bids":[],"asks":[["10.804","13980.5"]]}}
1635444234.871765: {"type":"channel_data","connection_id":"60a4fc71-1312-4830-86f4-9eb98be106ac","message_id":806,"id":"EOS-USD","channel":"v3_orderbook","contents":{"offset":"2693990318","bids":[],"asks":[["4.404","14965"]]}}
1635444234.886017: {"type":"channel_data","connection_id":"60a4fc71-1312-4830-86f4-9eb98be106ac","message_id":807,"id":"EOS-USD","channel":"v3_orderbook","contents":{"offset":"2693990328","bids":[["4.4","11196"]],"asks":[]}}
1635444234.892886: {"type":"channel_data","connection_id":"60a4fc71-1312-4830-86f4-9eb98be106ac","message_id":808,"id":"CRV-USD","channel":"v3_orderbook","contents":{"offset":"2693990329","bids":[],"asks":[["4.859","5897"]]}}
1635444234.892967: {"type":"channel_data","connection_id":"60a4fc71-1312-4830-86f4-9eb98be106ac","message_id":809,"id":"UMA-USD","channel":"v3_orderbook","contents":{"offset":"2693990334","bids":[],"asks":[["11.33","23786.7"]]}}
1635444234.903012: {"type":"channel_data","connection_id":"60a4fc71-1312-4830-86f4-9eb98be106ac","message_id":810,"id":"UMA-USD","channel":"v3_orderbook","contents":{"offset":"2693990340","bids":[],"asks":[["11.33","1683.6"]]}}
1635444234.90309: {"type":"channel_data","connection_id":"60a4fc71-1312-4830-86f4-9eb98be106ac","message_id":811,"id":"ETH-USD","channel":"v3_orderbook","contents":{"offset":"2693990336","bids":[],"asks":[["4216.5","116.683"]]}}
1635444234.915885: {"type":"channel_data","connection_id":"60a4fc71-1312-4830-86f4-9eb98be106ac","message_id":812,"id":"CRV-USD","channel":"v3_orderbook","contents":{"offset":"2693990346","bids":[],"asks":[["4.863","21890"]]}}
1635444234.9159539: {"type":"channel_data","connection_id":"60a4fc71-1312-4830-86f4-9eb98be106ac","message_id":813,"id":"ETH-USD","channel":"v3_orderbook","contents":{"offset":"2693990347","bids":[],"asks":[["4239","33.366"],["4239.8","0"]]}}
1635444234.928419: {"type":"channel_data","connection_id":"60a4fc71-1312-4830-86f4-9eb98be106ac","message_id":814,"id":"BCH-USD","channel":"v3_orderbook","contents":{"offset":"2693990358","bids":[["572.3","60.93"],["572.2","0"]],"asks":[]}}
1635444234.930638: {"type":"channel_data","connection_id":"60a4fc71-1312-4830-86f4-9eb98be106ac","message_id":815,"id":"ETH-USD","channel":"v3_orderbook","contents":{"offset":"2693990350","bids":[["4215","22.496"]],"asks":[]}}
1635444234.930697: {"type":"channel_data","connection_id":"60a4fc71-1312-4830-86f4-9eb98be106ac","message_id":816,"id":"BCH-USD","channel":"v3_orderbook","contents":{"offset":"2693990355","bids":[["571.7","60.93"],["571.6","0"]],"asks":[]}}
1635444234.9307399: {"type":"channel_data","connection_id":"60a4fc71-1312-4830-86f4-9eb98be106ac","message_id":817,"id":"EOS-USD","channel":"v3_orderbook","contents":{"offset":"2693990356","bids":[],"asks":[["4.404","16101"]]}}
1635444234.9484842: {"type":"channel_data","connection_id":"60a4fc71-1312-4830-86f4-9eb98be106ac","message_id":818,"id":"UMA-USD","channel":"v3_orderbook","contents":{"offset":"2693990365","bids":[["11.27","29416.2"]],"asks":[]}}
1635444234.948571: {"type":"channel_data","connection_id":"60a4fc71-1312-4830-86f4-9eb98be106ac","message_id":819,"id":"CRV-USD","channel":"v3_orderbook","contents":{"offset":"2693990368","bids":[["4.846","1582"]],"asks":[]}}
1635444234.948607: {"type":"channel_data","connection_id":"60a4fc71-1312-4830-86f4-9eb98be106ac","message_id":820,"id":"ETH-USD","channel":"v3_orderbook","contents":{"offset":"2693990366","bids":[],"asks":[["4216.5","140.417"]]}}
1635444234.948638: {"type":"channel_data","connection_id":"60a4fc71-1312-4830-86f4-9eb98be106ac","message_id":821,"id":"EOS-USD","channel":"v3_orderbook","contents":{"offset":"2693990369","bids":[],"asks":[["4.404","14965"]]}}
1635444234.9521742: {"type":"channel_data","connection_id":"60a4fc71-1312-4830-86f4-9eb98be106ac","message_id":822,"id":"UMA-USD","channel":"v3_orderbook","contents":{"offset":"2693990367","bids":[],"asks":[["11.33","682.6"]]}}
1635444234.960871: {"type":"channel_data","connection_id":"60a4fc71-1312-4830-86f4-9eb98be106ac","message_id":823,"id":"CRV-USD","channel":"v3_orderbook","contents":{"offset":"2693990377","bids":[],"asks":[["4.859","10763"]]}}
1635444234.9720829: {"type":"channel_data","connection_id":"60a4fc71-1312-4830-86f4-9eb98be106ac","message_id":824,"id":"ETH-USD","channel":"v3_orderbook","contents":{"offset":"2693990382","bids":[],"asks":[["4216.5","116.683"]]}}
1635444234.972172: {"type":"channel_data","connection_id":"60a4fc71-1312-4830-86f4-9eb98be106ac","message_id":825,"id":"UMA-USD","channel":"v3_orderbook","contents":{"offset":"2693990384","bids":[["11.27","29150.7"]],"asks":[]}}
1635444234.97634: {"type":"channel_data","connection_id":"60a4fc71-1312-4830-86f4-9eb98be106ac","message_id":826,"id":"CRV-USD","channel":"v3_orderbook","contents":{"offset":"2693990383","bids":[],"asks":[["4.866","6470"]]}}
1635444234.9764018: {"type":"channel_data","connection_id":"60a4fc71-1312-4830-86f4-9eb98be106ac","message_id":827,"id":"UMA-USD","channel":"v3_orderbook","contents":{"offset":"2693990380","bids":[],"asks":[["11.69","0"]]}}
1635444234.982975: {"type":"channel_data","connection_id":"60a4fc71-1312-4830-86f4-9eb98be106ac","message_id":828,"id":"SUSHI-USD","channel":"v3_orderbook","contents":{"offset":"2693990389","bids":[["10.784","4002.3"]],"asks":[]}}
1635444234.989525: {"type":"channel_data","connection_id":"60a4fc71-1312-4830-86f4-9eb98be106ac","message_id":829,"id":"CRV-USD","channel":"v3_orderbook","contents":{"offset":"2693990394","bids":[["4.842","10010"]],"asks":[]}}
1635444234.989595: {"type":"channel_data","connection_id":"60a4fc71-1312-4830-86f4-9eb98be106ac","message_id":830,"id":"UMA-USD","channel":"v3_orderbook","contents":{"offset":"2693990395","bids":[["10.89","0"]],"asks":[]}}
1635444234.996854: {"type":"channel_data","connection_id":"60a4fc71-1312-4830-86f4-9eb98be106ac","message_id":831,"id":"ETH-USD","channel":"v3_orderbook","contents":{"offset":"2693990398","bids":[],"asks":[["4224.3","0"]]}}
1635444234.996929: {"type":"channel_data","connection_id":"60a4fc71-1312-4830-86f4-9eb98be106ac","message_id":832,"id":"CRV-USD","channel":"v3_orderbook","contents":{"offset":"2693990399","bids":[],"asks":[["4.854","246"]]}}
1635444235.0023181: {"type":"channel_data","connection_id":"60a4fc71-1312-4830-86f4-9eb98be106ac","message_id":833,"id":"SUSHI-USD","channel":"v3_orderbook","contents":{"offset":"2693990405","bids":[["10.786","11712.9"]],"asks":[]}}
1635444235.006331: {"type":"channel_data","connection_id":"60a4fc71-1312-4830-86f4-9eb98be106ac","message_id":834,"id":"SUSHI-USD","channel":"v3_orderbook","contents":{"offset":"2693990404","bids":[],"asks":[["10.808","407.4"]]}}
1635444235.018713: {"type":"channel_data","connection_id":"60a4fc71-1312-4830-86f4-9eb98be106ac","message_id":835,"id":"LTC-USD","channel":"v3_orderbook","contents":{"offset":"2693990417","bids":[],"asks":[["189","914.59"]]}}
1635444235.018796: {"type":"channel_data","connection_id":"60a4fc71-1312-4830-86f4-9eb98be106ac","message_id":836,"id":"EOS-USD","channel":"v3_orderbook","contents":{"offset":"2693990415","bids":[],"asks":[["4.404","16101"]]}}
1635444235.021823: {"type":"channel_data","connection_id":"60a4fc71-1312-4830-86f4-9eb98be106ac","message_id":837,"id":"ETH-USD","channel":"v3_orderbook","contents":{"offset":"2693990418","bids":[],"asks":[["4216.5","140.417"]]}}
1635444235.028235: {"type":"channel_data","connection_id":"60a4fc71-1312-4830-86f4-9eb98be106ac","message_id":838,"id":"UMA-USD","channel":"v3_orderbook","contents":{"offset":"2693990424","bids":[],"asks":[["11.33","27201.8"]]}}
1635444235.028308: {"type":"channel_data","connection_id":"60a4fc71-1312-4830-86f4-9eb98be106ac","message_id":839,"id":"CRV-USD","channel":"v3_orderbook","contents":{"offset":"2693990421","bids":[],"asks":[["4.867","7852"]]}}
1635444235.028866: {"type":"channel_data","connection_id":"60a4fc71-1312-4830-86f4-9eb98be106ac","message_id":840,"id":"SUSHI-USD","channel":"v3_orderbook","contents":{"offset":"2693990422","bids":[["10.79","1475.7"]],"asks":[]}}
1635444235.029757: {"type":"channel_data","connection_id":"60a4fc71-1312-4830-86f4-9eb98be106ac","message_id":841,"id":"UMA-USD","channel":"v3_orderbook","contents":{"offset":"2693990423","bids":[],"asks":[["11.33","5098.7"]]}}
1635444235.038176: {"type":"channel_data","connection_id":"60a4fc71-1312-4830-86f4-9eb98be106ac","message_id":842,"id":"CRV-USD","channel":"v3_orderbook","contents":{"offset":"2693990429","bids":[],"asks":[["4.881","0"]]}}
1635444235.038372: {"type":"channel_data","connection_id":"60a4fc71-1312-4830-86f4-9eb98be106ac","message_id":843,"id":"SUSHI-USD","channel":"v3_orderbook","contents":{"offset":"2693990432","bids":[["10.684","15"],["10.682","13393.3"]],"asks":[]}}
1635444235.038901: {"type":"channel_data","connection_id":"60a4fc71-1312-4830-86f4-9eb98be106ac","message_id":844,"id":"UMA-USD","channel":"v3_orderbook","contents":{"offset":"2693990433","bids":[["11.25","3091"]],"asks":[]}}
1635444235.049974: {"type":"channel_data","connection_id":"60a4fc71-1312-4830-86f4-9eb98be106ac","message_id":845,"id":"EOS-USD","channel":"v3_orderbook","contents":{"offset":"2693990437","bids":[["4.401","1136"]],"asks":[]}}
1635444235.050055: {"type":"channel_data","connection_id":"60a4fc71-1312-4830-86f4-9eb98be106ac","message_id":846,"id":"UMA-USD","channel":"v3_orderbook","contents":{"offset":"2693990440","bids":[],"asks":[["11.33","5098.7"]]}}
1635444235.05092: {"type":"channel_data","connection_id":"60a4fc71-1312-4830-86f4-9eb98be106ac","message_id":847,"id":"CRV-USD","channel":"v3_orderbook","contents":{"offset":"2693990439","bids":[["4.85","4866"]],"asks":[]}}
1635444235.058609: {"type":"channel_data","connection_id":"60a4fc71-1312-4830-86f4-9eb98be106ac","message_id":848,"id":"UNI-USD","channel":"v3_orderbook","contents":{"offset":"2693990448","bids":[["24.949","544.9"]],"asks":[]}}
1635444235.0593438: {"type":"channel_data","connection_id":"60a4fc71-1312-4830-86f4-9eb98be106ac","message_id":849,"id":"EOS-USD","channel":"v3_orderbook","contents":{"offset":"2693990446","bids":[],"asks":[["4.405","44299"]]}}
1635444235.0646589: {"type":"channel_data","connection_id":"60a4fc71-1312-4830-86f4-9eb98be106ac","message_id":850,"id":"UMA-USD","channel":"v3_orderbook","contents":{"offset":"2693990443","bids":[],"asks":[["11.33","682.6"]]}}
1635444235.069314: {"type":"channel_data","connection_id":"60a4fc71-1312-4830-86f4-9eb98be106ac","message_id":851,"id":"EOS-USD","channel":"v3_orderbook","contents":{"offset":"2693990456","bids":[["4.401","0"]],"asks":[]}}
1635444235.0693572: {"type":"channel_data","connection_id":"60a4fc71-1312-4830-86f4-9eb98be106ac","message_id":852,"id":"EOS-USD","channel":"v3_orderbook","contents":{"offset":"2693990454","bids":[],"asks":[["4.404","14965"]]}}
1635444235.071715: {"type":"channel_data","connection_id":"60a4fc71-1312-4830-86f4-9eb98be106ac","message_id":853,"id":"CRV-USD","channel":"v3_orderbook","contents":{"offset":"2693990458","bids":[],"asks":[["4.854","1246"]]}}
1635444235.072227: {"type":"channel_data","connection_id":"60a4fc71-1312-4830-86f4-9eb98be106ac","message_id":854,"id":"MKR-USD","channel":"v3_orderbook","contents":{"offset":"2693990452","bids":[["2376","0.462"]],"asks":[]}}
1635444235.0722618: {"type":"channel_data","connection_id":"60a4fc71-1312-4830-86f4-9eb98be106ac","message_id":855,"id":"ETH-USD","channel":"v3_orderbook","contents":{"offset":"2693990457","bids":[],"asks":[["4216.5","116.683"]]}}
1635444235.084106: {"type":"channel_data","connection_id":"60a4fc71-1312-4830-86f4-9eb98be106ac","message_id":856,"id":"EOS-USD","channel":"v3_orderbook","contents":{"offset":"2693990464","bids":[],"asks":[["4.405","43163"]]}}
1635444235.0841868: {"type":"channel_data","connection_id":"60a4fc71-1312-4830-86f4-9eb98be106ac","message_id":857,"id":"BCH-USD","channel":"v3_orderbook","contents":{"offset":"2693990462","bids":[["571.5","262.47"],["571.4","0"]],"asks":[]}}
1635444235.116259: {"type":"channel_data","connection_id":"60a4fc71-1312-4830-86f4-9eb98be106ac","message_id":858,"id":"EOS-USD","channel":"v3_orderbook","contents":{"offset":"2693990480","bids":[["4.4","11536"]],"asks":[]}}
1635444235.116382: {"type":"channel_data","connection_id":"60a4fc71-1312-4830-86f4-9eb98be106ac","message_id":859,"id":"EOS-USD","channel":"v3_orderbook","contents":{"offset":"2693990479","bids":[["4.398","16504"]],"asks":[]}}
1635444235.123713: {"type":"channel_data","connection_id":"60a4fc71-1312-4830-86f4-9eb98be106ac","message_id":860,"id":"SUSHI-USD","channel":"v3_orderbook","contents":{"offset":"2693990486","bids":[],"asks":[["10.804","14367.3"]]}}
1635444235.1237729: {"type":"channel_data","connection_id":"60a4fc71-1312-4830-86f4-9eb98be106ac","message_id":861,"id":"CRV-USD","channel":"v3_orderbook","contents":{"offset":"2693990490","bids":[],"asks":[["4.854","246"]]}}
1635444235.126037: {"type":"channel_data","connection_id":"60a4fc71-1312-4830-86f4-9eb98be106ac","message_id":862,"id":"UNI-USD","channel":"v3_orderbook","contents":{"offset":"2693990489","bids":[],"asks":[["25.125","4174.8"]]}}
1635444235.1283998: {"type":"channel_data","connection_id":"60a4fc71-1312-4830-86f4-9eb98be106ac","message_id":863,"id":"EOS-USD","channel":"v3_orderbook","contents":{"offset":"2693990487","bids":[],"asks":[["4.404","16101"]]}}
1635444235.1284878: {"type":"channel_data","connection_id":"60a4fc71-1312-4830-86f4-9eb98be106ac","message_id":864,"id":"ETH-USD","channel":"v3_orderbook","contents":{"offset":"2693990491","bids":[],"asks":[["4216.5","140.417"]]}}
1635444235.141902: {"type":"channel_data","connection_id":"60a4fc71-1312-4830-86f4-9eb98be106ac","message_id":865,"id":"EOS-USD","channel":"v3_orderbook","contents":{"offset":"2693990495","bids":[["4.4","12672"]],"asks":[]}}
1635444235.1528761: {"type":"channel_data","connection_id":"60a4fc71-1312-4830-86f4-9eb98be106ac","message_id":866,"id":"ETH-USD","channel":"v3_orderbook","contents":{"offset":"2693990500","bids":[],"asks":[["4216.5","116.683"]]}}
1635444235.1730292: {"type":"channel_data","connection_id":"60a4fc71-1312-4830-86f4-9eb98be106ac","message_id":867,"id":"EOS-USD","channel":"v3_orderbook","contents":{"offset":"2693990501","bids":[],"asks":[["4.405","44300"]]}}
1635444235.176904: {"type":"channel_data","connection_id":"60a4fc71-1312-4830-86f4-9eb98be106ac","message_id":868,"id":"ETH-USD","channel":"v3_orderbook","contents":{"offset":"2693990504","bids":[["4209.6","4.02"]],"asks":[]}}
1635444235.1769888: {"type":"channel_data","connection_id":"60a4fc71-1312-4830-86f4-9eb98be106ac","message_id":869,"id":"EOS-USD","channel":"v3_orderbook","contents":{"offset":"2693990505","bids":[["4.399","1137"]],"asks":[]}}
1635444235.191444: {"type":"channel_data","connection_id":"60a4fc71-1312-4830-86f4-9eb98be106ac","message_id":870,"id":"CRV-USD","channel":"v3_orderbook","contents":{"offset":"2693990512","bids":[],"asks":[["4.854","1246"]]}}
1635444235.191535: {"type":"channel_data","connection_id":"60a4fc71-1312-4830-86f4-9eb98be106ac","message_id":871,"id":"MKR-USD","channel":"v3_orderbook","contents":{"offset":"2693990510","bids":[],"asks":[["2385","99.949"]]}}
1635444235.191573: {"type":"channel_data","connection_id":"60a4fc71-1312-4830-86f4-9eb98be106ac","message_id":872,"id":"UNI-USD","channel":"v3_orderbook","contents":{"offset":"2693990513","bids":[],"asks":[["25.206","998.8"],["25.207","0"]]}}
1635444235.191614: {"type":"channel_data","connection_id":"60a4fc71-1312-4830-86f4-9eb98be106ac","message_id":873,"id":"MKR-USD","channel":"v3_orderbook","contents":{"offset":"2693990511","bids":[],"asks":[["2387","0.462"]]}}
1635444235.191957: {"type":"channel_data","connection_id":"60a4fc71-1312-4830-86f4-9eb98be106ac","message_id":874,"id":"UMA-USD","channel":"v3_orderbook","contents":{"offset":"2693990507","bids":[],"asks":[["11.33","22785.7"]]}}
1635444235.2050529: {"type":"channel_data","connection_id":"60a4fc71-1312-4830-86f4-9eb98be106ac","message_id":875,"id":"CRV-USD","channel":"v3_orderbook","contents":{"offset":"2693990515","bids":[["4.826","0"],["4.824","8160"]],"asks":[]}}
1635444235.213123: {"type":"channel_data","connection_id":"60a4fc71-1312-4830-86f4-9eb98be106ac","message_id":876,"id":"CRV-USD","channel":"v3_orderbook","contents":{"offset":"2693990522","bids":[["4.821","90658"],["4.819","8152"]],"asks":[]}}
1635444235.213212: {"type":"channel_data","connection_id":"60a4fc71-1312-4830-86f4-9eb98be106ac","message_id":877,"id":"MKR-USD","channel":"v3_orderbook","contents":{"offset":"2693990523","bids":[["2376","2094.467"]],"asks":[]}}
1635444235.222941: {"type":"channel_data","connection_id":"60a4fc71-1312-4830-86f4-9eb98be106ac","message_id":878,"id":"ETH-USD","channel":"v3_orderbook","contents":{"offset":"2693990524","bids":[],"asks":[["4216.5","140.417"]]}}
1635444235.234724: {"type":"channel_data","connection_id":"60a4fc71-1312-4830-86f4-9eb98be106ac","message_id":879,"id":"UMA-USD","channel":"v3_orderbook","contents":{"offset":"2693990526","bids":[["11.27","29416.2"]],"asks":[]}}
1635444235.255438: {"type":"channel_data","connection_id":"60a4fc71-1312-4830-86f4-9eb98be106ac","message_id":880,"id":"ETH-USD","channel":"v3_orderbook","contents":{"offset":"2693990533","bids":[],"asks":[["4222.3","1.41"]]}}
1635444235.255543: {"type":"channel_data","connection_id":"60a4fc71-1312-4830-86f4-9eb98be106ac","message_id":881,"id":"ETH-USD","channel":"v3_orderbook","contents":{"offset":"2693990534","bids":[],"asks":[["4216.5","116.683"]]}}
1635444235.261029: {"type":"channel_data","connection_id":"60a4fc71-1312-4830-86f4-9eb98be106ac","message_id":882,"id":"UMA-USD","channel":"v3_orderbook","contents":{"offset":"2693990538","bids":[],"asks":[["11.33","27201.6"]]}}
1635444235.262162: {"type":"channel_data","connection_id":"60a4fc71-1312-4830-86f4-9eb98be106ac","message_id":883,"id":"CRV-USD","channel":"v3_orderbook","contents":{"offset":"2693990539","bids":[],"asks":[["4.854","246"]]}}
1635444235.276479: {"type":"channel_data","connection_id":"60a4fc71-1312-4830-86f4-9eb98be106ac","message_id":884,"id":"UMA-USD","channel":"v3_orderbook","contents":{"offset":"2693990544","bids":[["11.27","29150.7"]],"asks":[]}}
1635444235.2875168: {"type":"channel_data","connection_id":"60a4fc71-1312-4830-86f4-9eb98be106ac","message_id":885,"id":"ETH-USD","channel":"v3_orderbook","contents":{"offset":"2693990552","bids":[],"asks":[["4216.5","140.417"]]}}
1635444235.287605: {"type":"channel_data","connection_id":"60a4fc71-1312-4830-86f4-9eb98be106ac","message_id":886,"id":"CRV-USD","channel":"v3_orderbook","contents":{"offset":"2693990551","bids":[],"asks":[["4.858","0"]]}}
1635444235.3100102: {"type":"channel_data","connection_id":"60a4fc71-1312-4830-86f4-9eb98be106ac","message_id":887,"id":"ETH-USD","channel":"v3_orderbook","contents":{"offset":"2693990557","bids":[],"asks":[["4216.5","116.683"]]}}
1635444235.3106: {"type":"channel_data","connection_id":"60a4fc71-1312-4830-86f4-9eb98be106ac","message_id":888,"id":"CRV-USD","channel":"v3_orderbook","contents":{"offset":"2693990560","bids":[["4.85","0"]],"asks":[]}}
1635444235.310656: {"type":"channel_data","connection_id":"60a4fc71-1312-4830-86f4-9eb98be106ac","message_id":889,"id":"UMA-USD","channel":"v3_orderbook","contents":{"offset":"2693990558","bids":[["10.89","1000"]],"asks":[]}}
1635444235.311148: {"type":"channel_data","connection_id":"60a4fc71-1312-4830-86f4-9eb98be106ac","message_id":890,"id":"CRV-USD","channel":"v3_orderbook","contents":{"offset":"2693990559","bids":[["4.817","0"],["4.816","16713"]],"asks":[]}}
1635444235.331059: {"type":"channel_data","connection_id":"60a4fc71-1312-4830-86f4-9eb98be106ac","message_id":891,"id":"CRV-USD","channel":"v3_orderbook","contents":{"offset":"2693990564","bids":[],"asks":[["4.854","1246"]]}}
1635444235.351177: {"type":"channel_data","connection_id":"60a4fc71-1312-4830-86f4-9eb98be106ac","message_id":892,"id":"ETH-USD","channel":"v3_orderbook","contents":{"offset":"2693990574","bids":[],"asks":[["4223.6","17.758"]]}}
1635444235.361335: {"type":"channel_data","connection_id":"60a4fc71-1312-4830-86f4-9eb98be106ac","message_id":893,"id":"ETH-USD","channel":"v3_orderbook","contents":{"offset":"2693990576","bids":[],"asks":[["4221.8","0"]]}}
1635444235.363965: {"type":"channel_data","connection_id":"60a4fc71-1312-4830-86f4-9eb98be106ac","message_id":894,"id":"ETH-USD","channel":"v3_orderbook","contents":{"offset":"2693990579","bids":[],"asks":[["4216.5","140.417"]]}}
1635444235.364036: {"type":"channel_data","connection_id":"60a4fc71-1312-4830-86f4-9eb98be106ac","message_id":895,"id":"CRV-USD","channel":"v3_orderbook","contents":{"offset":"2693990575","bids":[["4.845","1337"]],"asks":[]}}
1635444235.390319: {"type":"channel_data","connection_id":"60a4fc71-1312-4830-86f4-9eb98be106ac","message_id":896,"id":"CRV-USD","channel":"v3_orderbook","contents":{"offset":"2693990584","bids":[["4.816","17772"]],"asks":[]}}
1635444235.390404: {"type":"channel_data","connection_id":"60a4fc71-1312-4830-86f4-9eb98be106ac","message_id":897,"id":"ETH-USD","channel":"v3_orderbook","contents":{"offset":"2693990583","bids":[],"asks":[["4216.5","116.683"]]}}
1635444235.403358: {"type":"channel_data","connection_id":"60a4fc71-1312-4830-86f4-9eb98be106ac","message_id":898,"id":"ETH-USD","channel":"v3_orderbook","contents":{"offset":"2693990588","bids":[["4215","22.756"]],"asks":[]}}
1635444235.4034839: {"type":"channel_data","connection_id":"60a4fc71-1312-4830-86f4-9eb98be106ac","message_id":899,"id":"ETH-USD","channel":"v3_orderbook","contents":{"offset":"2693990592","bids":[["4208.5","92.52"]],"asks":[]}}
1635444235.419254: {"type":"channel_data","connection_id":"60a4fc71-1312-4830-86f4-9eb98be106ac","message_id":900,"id":"CRV-USD","channel":"v3_orderbook","contents":{"offset":"2693990598","bids":[["4.85","377"]],"asks":[]}}
1635444235.419383: {"type":"channel_data","connection_id":"60a4fc71-1312-4830-86f4-9eb98be106ac","message_id":901,"id":"UMA-USD","channel":"v3_orderbook","contents":{"offset":"2693990601","bids":[],"asks":[["11.69","1000"]]}}
1635444235.421398: {"type":"channel_data","connection_id":"60a4fc71-1312-4830-86f4-9eb98be106ac","message_id":902,"id":"CRV-USD","channel":"v3_orderbook","contents":{"offset":"2693990599","bids":[["4.838","6393"]],"asks":[]}}
1635444235.421479: {"type":"channel_data","connection_id":"60a4fc71-1312-4830-86f4-9eb98be106ac","message_id":903,"id":"CRV-USD","channel":"v3_orderbook","contents":{"offset":"2693990602","bids":[],"asks":[["4.854","246"]]}}
1635444235.421516: {"type":"channel_data","connection_id":"60a4fc71-1312-4830-86f4-9eb98be106ac","message_id":904,"id":"UNI-USD","channel":"v3_orderbook","contents":{"offset":"2693990600","bids":[],"asks":[["25.168","1067.1"],["25.169","0"]]}}
1635444235.4241269: {"type":"channel_data","connection_id":"60a4fc71-1312-4830-86f4-9eb98be106ac","message_id":905,"id":"BCH-USD","channel":"v3_orderbook","contents":{"offset":"2693990597","bids":[["571.8","60.93"],["571.7","0"]],"asks":[]}}
1635444235.431805: {"type":"channel_data","connection_id":"60a4fc71-1312-4830-86f4-9eb98be106ac","message_id":906,"id":"CRV-USD","channel":"v3_orderbook","contents":{"offset":"2693990603","bids":[["4.851","4865"]],"asks":[]}}
1635444235.434956: {"type":"channel_data","connection_id":"60a4fc71-1312-4830-86f4-9eb98be106ac","message_id":907,"id":"ETH-USD","channel":"v3_orderbook","contents":{"offset":"2693990604","bids":[],"asks":[["4220.8","1.6"]]}}
1635444235.4445848: {"type":"channel_data","connection_id":"60a4fc71-1312-4830-86f4-9eb98be106ac","message_id":908,"id":"ETH-USD","channel":"v3_orderbook","contents":{"offset":"2693990611","bids":[],"asks":[["4216.5","140.417"]]}}
1635444235.4540858: {"type":"channel_data","connection_id":"60a4fc71-1312-4830-86f4-9eb98be106ac","message_id":909,"id":"CRV-USD","channel":"v3_orderbook","contents":{"offset":"2693990617","bids":[["4.85","531"]],"asks":[]}}
1635444235.458854: {"type":"channel_data","connection_id":"60a4fc71-1312-4830-86f4-9eb98be106ac","message_id":910,"id":"CRV-USD","channel":"v3_orderbook","contents":{"offset":"2693990619","bids":[["4.837","9651"]],"asks":[]}}
1635444235.458975: {"type":"channel_data","connection_id":"60a4fc71-1312-4830-86f4-9eb98be106ac","message_id":911,"id":"CRV-USD","channel":"v3_orderbook","contents":{"offset":"2693990621","bids":[["4.844","2493"]],"asks":[]}}
1635444235.4662242: {"type":"channel_data","connection_id":"60a4fc71-1312-4830-86f4-9eb98be106ac","message_id":912,"id":"CRV-USD","channel":"v3_orderbook","contents":{"offset":"2693990627","bids":[],"asks":[["4.854","1246"]]}}
1635444235.4729211: {"type":"channel_data","connection_id":"60a4fc71-1312-4830-86f4-9eb98be106ac","message_id":913,"id":"ETH-USD","channel":"v3_orderbook","contents":{"offset":"2693990631","bids":[],"asks":[["4216.5","116.683"]]}}
1635444235.4775329: {"type":"channel_data","connection_id":"60a4fc71-1312-4830-86f4-9eb98be106ac","message_id":914,"id":"CRV-USD","channel":"v3_orderbook","contents":{"offset":"2693990638","bids":[],"asks":[["4.866","14483"]]}}
1635444235.480705: {"type":"channel_data","connection_id":"60a4fc71-1312-4830-86f4-9eb98be106ac","message_id":915,"id":"CRV-USD","channel":"v3_orderbook","contents":{"offset":"2693990641","bids":[],"asks":[["4.863","13877"]]}}
1635444235.487128: {"type":"channel_data","connection_id":"60a4fc71-1312-4830-86f4-9eb98be106ac","message_id":916,"id":"CRV-USD","channel":"v3_orderbook","contents":{"offset":"2693990644","bids":[],"asks":[["4.86","592"]]}}
1635444235.5006871: {"type":"channel_data","connection_id":"60a4fc71-1312-4830-86f4-9eb98be106ac","message_id":917,"id":"CRV-USD","channel":"v3_orderbook","contents":{"offset":"2693990649","bids":[],"asks":[["4.862","657"]]}}
1635444235.5007648: {"type":"channel_data","connection_id":"60a4fc71-1312-4830-86f4-9eb98be106ac","message_id":918,"id":"CRV-USD","channel":"v3_orderbook","contents":{"offset":"2693990651","bids":[],"asks":[["4.865","9581"]]}}
1635444235.500801: {"type":"channel_data","connection_id":"60a4fc71-1312-4830-86f4-9eb98be106ac","message_id":919,"id":"CRV-USD","channel":"v3_orderbook","contents":{"offset":"2693990655","bids":[],"asks":[["4.854","246"]]}}
1635444235.500829: {"type":"channel_data","connection_id":"60a4fc71-1312-4830-86f4-9eb98be106ac","message_id":920,"id":"CRV-USD","channel":"v3_orderbook","contents":{"offset":"2693990648","bids":[],"asks":[["4.86","1210"]]}}
1635444235.502634: {"type":"channel_data","connection_id":"60a4fc71-1312-4830-86f4-9eb98be106ac","message_id":921,"id":"ETH-USD","channel":"v3_orderbook","contents":{"offset":"2693990652","bids":[],"asks":[["4218.9","89.543"]]}}
1635444235.509734: {"type":"channel_data","connection_id":"60a4fc71-1312-4830-86f4-9eb98be106ac","message_id":922,"id":"ETH-USD","channel":"v3_orderbook","contents":{"offset":"2693990658","bids":[],"asks":[["4219.8","3.537"]]}}
1635444235.509805: {"type":"channel_data","connection_id":"60a4fc71-1312-4830-86f4-9eb98be106ac","message_id":923,"id":"ETH-USD","channel":"v3_orderbook","contents":{"offset":"2693990659","bids":[],"asks":[["4218","59.562"]]}}
1635444235.512838: {"type":"channel_data","connection_id":"60a4fc71-1312-4830-86f4-9eb98be106ac","message_id":924,"id":"ETH-USD","channel":"v3_orderbook","contents":{"offset":"2693990660","bids":[],"asks":[["4216.5","140.417"]]}}
1635444235.5128949: {"type":"channel_data","connection_id":"60a4fc71-1312-4830-86f4-9eb98be106ac","message_id":925,"id":"ETH-USD","channel":"v3_orderbook","contents":{"offset":"2693990661","bids":[],"asks":[["4218.3","57.052"]]}}
1635444235.5177758: {"type":"channel_data","connection_id":"60a4fc71-1312-4830-86f4-9eb98be106ac","message_id":926,"id":"UMA-USD","channel":"v3_orderbook","contents":{"offset":"2693990662","bids":[["11.25","4092"]],"asks":[]}}
1635444235.517905: {"type":"channel_data","connection_id":"60a4fc71-1312-4830-86f4-9eb98be106ac","message_id":927,"id":"CRV-USD","channel":"v3_orderbook","contents":{"offset":"2693990665","bids":[],"asks":[["4.859","5897"]]}}
1635444235.533078: {"type":"channel_data","connection_id":"60a4fc71-1312-4830-86f4-9eb98be106ac","message_id":928,"id":"EOS-USD","channel":"v3_orderbook","contents":{"offset":"2693990667","bids":[["4.397","37747"]],"asks":[]}}
1635444235.5331461: {"type":"channel_data","connection_id":"60a4fc71-1312-4830-86f4-9eb98be106ac","message_id":929,"id":"UMA-USD","channel":"v3_orderbook","contents":{"offset":"2693990670","bids":[["11.27","29416.2"]],"asks":[]}}
1635444235.5468001: {"type":"channel_data","connection_id":"60a4fc71-1312-4830-86f4-9eb98be106ac","message_id":930,"id":"CRV-USD","channel":"v3_orderbook","contents":{"offset":"2693990678","bids":[],"asks":[["4.863","14618"]]}}
1635444235.546889: {"type":"channel_data","connection_id":"60a4fc71-1312-4830-86f4-9eb98be106ac","message_id":931,"id":"ETH-USD","channel":"v3_orderbook","contents":{"offset":"2693990674","bids":[],"asks":[["4216.5","116.683"]]}}
1635444235.5579531: {"type":"channel_data","connection_id":"60a4fc71-1312-4830-86f4-9eb98be106ac","message_id":932,"id":"UMA-USD","channel":"v3_orderbook","contents":{"offset":"2693990682","bids":[["11.27","29150.7"]],"asks":[]}}
1635444235.558039: {"type":"channel_data","connection_id":"60a4fc71-1312-4830-86f4-9eb98be106ac","message_id":933,"id":"CRV-USD","channel":"v3_orderbook","contents":{"offset":"2693990680","bids":[],"asks":[["4.854","1246"]]}}
1635444235.566478: {"type":"channel_data","connection_id":"60a4fc71-1312-4830-86f4-9eb98be106ac","message_id":934,"id":"CRV-USD","channel":"v3_orderbook","contents":{"offset":"2693990689","bids":[["4.847","13328"]],"asks":[]}}
1635444235.649895: {"type":"channel_data","connection_id":"60a4fc71-1312-4830-86f4-9eb98be106ac","message_id":935,"id":"CRV-USD","channel":"v3_orderbook","contents":{"offset":"2693990692","bids":[["4.844","1396"]],"asks":[]}}
1635444235.650354: {"type":"channel_data","connection_id":"60a4fc71-1312-4830-86f4-9eb98be106ac","message_id":936,"id":"CRV-USD","channel":"v3_orderbook","contents":{"offset":"2693990693","bids":[["4.842","8013"]],"asks":[]}}
1635444235.655728: {"type":"channel_data","connection_id":"60a4fc71-1312-4830-86f4-9eb98be106ac","message_id":937,"id":"ETH-USD","channel":"v3_orderbook","contents":{"offset":"2693990702","bids":[["4212.6","0"]],"asks":[]}}
1635444235.6557949: {"type":"channel_data","connection_id":"60a4fc71-1312-4830-86f4-9eb98be106ac","message_id":938,"id":"ETH-USD","channel":"v3_orderbook","contents":{"offset":"2693990699","bids":[],"asks":[["4216.5","140.417"]]}}
1635444235.655821: {"type":"channel_data","connection_id":"60a4fc71-1312-4830-86f4-9eb98be106ac","message_id":939,"id":"CRV-USD","channel":"v3_orderbook","contents":{"offset":"2693990698","bids":[["4.844","744"]],"asks":[]}}
1635444235.6583521: {"type":"channel_data","connection_id":"60a4fc71-1312-4830-86f4-9eb98be106ac","message_id":940,"id":"CRV-USD","channel":"v3_orderbook","contents":{"offset":"2693990710","bids":[],"asks":[["4.861","9648"]]}}
1635444235.662712: {"type":"channel_data","connection_id":"60a4fc71-1312-4830-86f4-9eb98be106ac","message_id":941,"id":"UMA-USD","channel":"v3_orderbook","contents":{"offset":"2693990703","bids":[],"asks":[["11.33","28202.6"]]}}
1635444235.664452: {"type":"channel_data","connection_id":"60a4fc71-1312-4830-86f4-9eb98be106ac","message_id":942,"id":"CRV-USD","channel":"v3_orderbook","contents":{"offset":"2693990711","bids":[],"asks":[["4.87","1713"]]}}
1635444235.68468: {"type":"channel_data","connection_id":"60a4fc71-1312-4830-86f4-9eb98be106ac","message_id":943,"id":"ETH-USD","channel":"v3_orderbook","contents":{"offset":"2693990722","bids":[],"asks":[["4216.5","116.683"]]}}
1635444235.697773: {"type":"channel_data","connection_id":"60a4fc71-1312-4830-86f4-9eb98be106ac","message_id":944,"id":"XMR-USD","channel":"v3_orderbook","contents":{"offset":"2693990726","bids":[],"asks":[["265.3","0"]]}}
1635444235.6978471: {"type":"channel_data","connection_id":"60a4fc71-1312-4830-86f4-9eb98be106ac","message_id":945,"id":"CRV-USD","channel":"v3_orderbook","contents":{"offset":"2693990727","bids":[],"asks":[["4.863","15210"]]}}
1635444235.714737: {"type":"channel_data","connection_id":"60a4fc71-1312-4830-86f4-9eb98be106ac","message_id":946,"id":"ETH-USD","channel":"v3_orderbook","contents":{"offset":"2693990729","bids":[],"asks":[["4216.5","126.083"]]}}
1635444235.714837: {"type":"channel_data","connection_id":"60a4fc71-1312-4830-86f4-9eb98be106ac","message_id":947,"id":"CRV-USD","channel":"v3_orderbook","contents":{"offset":"2693990731","bids":[["4.851","0"]],"asks":[]}}
1635444235.731534: {"type":"channel_data","connection_id":"60a4fc71-1312-4830-86f4-9eb98be106ac","message_id":948,"id":"ETH-USD","channel":"v3_orderbook","contents":{"offset":"2693990732","bids":[],"asks":[["4216.5","149.817"]]}}
1635444235.7440221: {"type":"channel_data","connection_id":"60a4fc71-1312-4830-86f4-9eb98be106ac","message_id":949,"id":"CRV-USD","channel":"v3_orderbook","contents":{"offset":"2693990739","bids":[["4.836","0"]],"asks":[]}}
1635444235.744094: {"type":"channel_data","connection_id":"60a4fc71-1312-4830-86f4-9eb98be106ac","message_id":950,"id":"ETH-USD","channel":"v3_orderbook","contents":{"offset":"2693990735","bids":[["4213.1","1928.933"]],"asks":[]}}
1635444235.755091: {"type":"channel_data","connection_id":"60a4fc71-1312-4830-86f4-9eb98be106ac","message_id":951,"id":"ETH-USD","channel":"v3_orderbook","contents":{"offset":"2693990742","bids":[],"asks":[["4216.5","126.083"]]}}
1635444235.766965: {"type":"channel_data","connection_id":"60a4fc71-1312-4830-86f4-9eb98be106ac","message_id":952,"id":"ETH-USD","channel":"v3_orderbook","contents":{"offset":"2693990748","bids":[],"asks":[["4217","0"]]}}
1635444235.781975: {"type":"channel_data","connection_id":"60a4fc71-1312-4830-86f4-9eb98be106ac","message_id":953,"id":"MKR-USD","channel":"v3_orderbook","contents":{"offset":"2693990750","bids":[["2381","11.496"]],"asks":[]}}
1635444235.782052: {"type":"channel_data","connection_id":"60a4fc71-1312-4830-86f4-9eb98be106ac","message_id":954,"id":"ETH-USD","channel":"v3_orderbook","contents":{"offset":"2693990754","bids":[["4213.1","1898.821"]],"asks":[]}}
1635444235.791583: {"type":"channel_data","connection_id":"60a4fc71-1312-4830-86f4-9eb98be106ac","message_id":955,"id":"CRV-USD","channel":"v3_orderbook","contents":{"offset":"2693990757","bids":[],"asks":[["4.865","10230"]]}}
1635444235.803822: {"type":"channel_data","connection_id":"60a4fc71-1312-4830-86f4-9eb98be106ac","message_id":956,"id":"CRV-USD","channel":"v3_orderbook","contents":{"offset":"2693990761","bids":[],"asks":[["4.867","8559"]]}}
1635444235.806015: {"type":"channel_data","connection_id":"60a4fc71-1312-4830-86f4-9eb98be106ac","message_id":957,"id":"ETH-USD","channel":"v3_orderbook","contents":{"offset":"2693990759","bids":[],"asks":[["4216.5","149.817"]]}}
1635444235.8060732: {"type":"channel_data","connection_id":"60a4fc71-1312-4830-86f4-9eb98be106ac","message_id":958,"id":"MKR-USD","channel":"v3_orderbook","contents":{"offset":"2693990762","bids":[],"asks":[["2389","5.355"]]}}
1635444235.813484: {"type":"channel_data","connection_id":"60a4fc71-1312-4830-86f4-9eb98be106ac","message_id":959,"id":"ETH-USD","channel":"v3_orderbook","contents":{"offset":"2693990767","bids":[],"asks":[["4216.5","126.083"]]}}
1635444235.8481019: {"type":"channel_data","connection_id":"60a4fc71-1312-4830-86f4-9eb98be106ac","message_id":960,"id":"CRV-USD","channel":"v3_orderbook","contents":{"offset":"2693990774","bids":[["4.836","827"]],"asks":[]}}
1635444235.848228: {"type":"channel_data","connection_id":"60a4fc71-1312-4830-86f4-9eb98be106ac","message_id":961,"id":"CRV-USD","channel":"v3_orderbook","contents":{"offset":"2693990775","bids":[["4.852","9654"]],"asks":[]}}
1635444235.853041: {"type":"channel_data","connection_id":"60a4fc71-1312-4830-86f4-9eb98be106ac","message_id":962,"id":"SUSHI-USD","channel":"v3_orderbook","contents":{"offset":"2693990777","bids":[["10.722","3247.6"],["10.721","444.9"]],"asks":[]}}
1635444235.864347: {"type":"channel_data","connection_id":"60a4fc71-1312-4830-86f4-9eb98be106ac","message_id":963,"id":"XMR-USD","channel":"v3_orderbook","contents":{"offset":"2693990787","bids":[],"asks":[["265.4","362.1"]]}}
1635444235.864463: {"type":"channel_data","connection_id":"60a4fc71-1312-4830-86f4-9eb98be106ac","message_id":964,"id":"SUSHI-USD","channel":"v3_orderbook","contents":{"offset":"2693990786","bids":[["10.79","266.5"]],"asks":[]}}
1635444235.8786712: {"type":"channel_data","connection_id":"60a4fc71-1312-4830-86f4-9eb98be106ac","message_id":965,"id":"CRV-USD","channel":"v3_orderbook","contents":{"offset":"2693990790","bids":[],"asks":[["4.856","0"]]}}
1635444235.8787892: {"type":"channel_data","connection_id":"60a4fc71-1312-4830-86f4-9eb98be106ac","message_id":966,"id":"ETH-USD","channel":"v3_orderbook","contents":{"offset":"2693990793","bids":[["4212.6","32.191"]],"asks":[]}}
1635444235.879286: {"type":"channel_data","connection_id":"60a4fc71-1312-4830-86f4-9eb98be106ac","message_id":967,"id":"XMR-USD","channel":"v3_orderbook","contents":{"offset":"2693990791","bids":[["265","151.21"]],"asks":[]}}
1635444235.880063: {"type":"channel_data","connection_id":"60a4fc71-1312-4830-86f4-9eb98be106ac","message_id":968,"id":"ETH-USD","channel":"v3_orderbook","contents":{"offset":"2693990788","bids":[],"asks":[["4216","57.21"]]}}
1635444235.881579: {"type":"channel_data","connection_id":"60a4fc71-1312-4830-86f4-9eb98be106ac","message_id":969,"id":"CRV-USD","channel":"v3_orderbook","contents":{"offset":"2693990794","bids":[["4.845","594"]],"asks":[]}}
1635444235.8816588: {"type":"channel_data","connection_id":"60a4fc71-1312-4830-86f4-9eb98be106ac","message_id":970,"id":"CRV-USD","channel":"v3_orderbook","contents":{"offset":"2693990792","bids":[["4.824","7227"]],"asks":[]}}
1635444235.881695: {"type":"channel_data","connection_id":"60a4fc71-1312-4830-86f4-9eb98be106ac","message_id":971,"id":"ETH-USD","channel":"v3_orderbook","contents":{"offset":"2693990789","bids":[],"asks":[["4216.5","149.817"]]}}
1635444235.9011111: {"type":"channel_data","connection_id":"60a4fc71-1312-4830-86f4-9eb98be106ac","message_id":972,"id":"ETH-USD","channel":"v3_trades","contents":{"trades":[{"size":"0.1","side":"BUY","price":"4216","createdAt":"2021-10-28T18:03:55.921Z"}]}}
1635444235.901174: {"type":"channel_data","connection_id":"60a4fc71-1312-4830-86f4-9eb98be106ac","message_id":973,"id":"ETH-USD","channel":"v3_orderbook","contents":{"offset":"2693990796","bids":[],"asks":[["4216.5","126.083"]]}}
1635444235.919094: {"type":"channel_data","connection_id":"60a4fc71-1312-4830-86f4-9eb98be106ac","message_id":974,"id":"MKR-USD","channel":"v3_orderbook","contents":{"offset":"2693990798","bids":[],"asks":[["2384","10.29"]]}}
1635444235.921386: {"type":"channel_data","connection_id":"60a4fc71-1312-4830-86f4-9eb98be106ac","message_id":975,"id":"CRV-USD","channel":"v3_orderbook","contents":{"offset":"2693990797","bids":[["4.85","673"]],"asks":[]}}
1635444235.93694: {"type":"channel_data","connection_id":"60a4fc71-1312-4830-86f4-9eb98be106ac","message_id":976,"id":"MKR-USD","channel":"v3_orderbook","contents":{"offset":"2693990803","bids":[["2380","13.822"]],"asks":[]}}
1635444235.937021: {"type":"channel_data","connection_id":"60a4fc71-1312-4830-86f4-9eb98be106ac","message_id":977,"id":"ETH-USD","channel":"v3_orderbook","contents":{"offset":"2693990802","bids":[["4212.6","0"]],"asks":[]}}
1635444235.937061: {"type":"channel_data","connection_id":"60a4fc71-1312-4830-86f4-9eb98be106ac","message_id":978,"id":"EOS-USD","channel":"v3_orderbook","contents":{"offset":"2693990804","bids":[["4.39","1137828"]],"asks":[]}}
1635444235.9510489: {"type":"channel_data","connection_id":"60a4fc71-1312-4830-86f4-9eb98be106ac","message_id":979,"id":"SUSHI-USD","channel":"v3_orderbook","contents":{"offset":"2693990807","bids":[["10.733","3247.6"],["10.732","0"]],"asks":[]}}
1635444235.974804: {"type":"channel_data","connection_id":"60a4fc71-1312-4830-86f4-9eb98be106ac","message_id":980,"id":"MKR-USD","channel":"v3_orderbook","contents":{"offset":"2693990811","bids":[],"asks":[["2467","0"]]}}
1635444235.975389: {"type":"channel_data","connection_id":"60a4fc71-1312-4830-86f4-9eb98be106ac","message_id":981,"id":"ETH-USD","channel":"v3_orderbook","contents":{"offset":"2693990810","bids":[],"asks":[["4216.5","149.817"]]}}
1635444235.97596: {"type":"channel_data","connection_id":"60a4fc71-1312-4830-86f4-9eb98be106ac","message_id":982,"id":"MKR-USD","channel":"v3_orderbook","contents":{"offset":"2693990812","bids":[["2300","0"]],"asks":[]}}
1635444235.991929: {"type":"channel_data","connection_id":"60a4fc71-1312-4830-86f4-9eb98be106ac","message_id":983,"id":"UNI-USD","channel":"v3_orderbook","contents":{"offset":"2693990813","bids":[],"asks":[["25.167","1067.1"],["25.168","0"]]}}
1635444236.005601: {"type":"channel_data","connection_id":"60a4fc71-1312-4830-86f4-9eb98be106ac","message_id":984,"id":"UNI-USD","channel":"v3_orderbook","contents":{"offset":"2693990817","bids":[],"asks":[["25.205","998.8"],["25.206","0"]]}}
1635444236.0056808: {"type":"channel_data","connection_id":"60a4fc71-1312-4830-86f4-9eb98be106ac","message_id":985,"id":"ETH-USD","channel":"v3_orderbook","contents":{"offset":"2693990818","bids":[],"asks":[["4216.5","126.083"]]}}
1635444236.006542: {"type":"channel_data","connection_id":"60a4fc71-1312-4830-86f4-9eb98be106ac","message_id":986,"id":"UNI-USD","channel":"v3_orderbook","contents":{"offset":"2693990820","bids":[],"asks":[["25.193","1997.7"],["25.194","0"]]}}
1635444236.0088708: {"type":"channel_data","connection_id":"60a4fc71-1312-4830-86f4-9eb98be106ac","message_id":987,"id":"ETH-USD","channel":"v3_orderbook","contents":{"offset":"2693990821","bids":[["4212","0"]],"asks":[]}}
1635444236.02088: {"type":"channel_data","connection_id":"60a4fc71-1312-4830-86f4-9eb98be106ac","message_id":988,"id":"ETH-USD","channel":"v3_orderbook","contents":{"offset":"2693990827","bids":[["4213.1","1928.933"]],"asks":[]}}
1635444236.04333: {"type":"channel_data","connection_id":"60a4fc71-1312-4830-86f4-9eb98be106ac","message_id":989,"id":"UNI-USD","channel":"v3_orderbook","contents":{"offset":"2693990833","bids":[],"asks":[["25.079","0"]]}}
1635444236.0456629: {"type":"channel_data","connection_id":"60a4fc71-1312-4830-86f4-9eb98be106ac","message_id":990,"id":"UNI-USD","channel":"v3_orderbook","contents":{"offset":"2693990834","bids":[["25.036","0"]],"asks":[]}}
1635444236.048374: {"type":"channel_data","connection_id":"60a4fc71-1312-4830-86f4-9eb98be106ac","message_id":991,"id":"UNI-USD","channel":"v3_orderbook","contents":{"offset":"2693990838","bids":[["25.03","0"]],"asks":[]}}
1635444236.049939: {"type":"channel_data","connection_id":"60a4fc71-1312-4830-86f4-9eb98be106ac","message_id":992,"id":"ETH-USD","channel":"v3_orderbook","contents":{"offset":"2693990836","bids":[],"asks":[["4217.2","22.496"]]}}
1635444236.0499892: {"type":"channel_data","connection_id":"60a4fc71-1312-4830-86f4-9eb98be106ac","message_id":993,"id":"ETH-USD","channel":"v3_orderbook","contents":{"offset":"2693990837","bids":[["4213.4","0"]],"asks":[]}}
1635444236.057916: {"type":"channel_data","connection_id":"60a4fc71-1312-4830-86f4-9eb98be106ac","message_id":994,"id":"UNI-USD","channel":"v3_orderbook","contents":{"offset":"2693990841","bids":[],"asks":[["25.073","0"]]}}
1635444236.0579898: {"type":"channel_data","connection_id":"60a4fc71-1312-4830-86f4-9eb98be106ac","message_id":995,"id":"UNI-USD","channel":"v3_orderbook","contents":{"offset":"2693990840","bids":[],"asks":[["25.068","0"]]}}
1635444236.059705: {"type":"channel_data","connection_id":"60a4fc71-1312-4830-86f4-9eb98be106ac","message_id":996,"id":"ETH-USD","channel":"v3_orderbook","contents":{"offset":"2693990847","bids":[],"asks":[["4216.5","149.817"]]}}
1635444236.061918: {"type":"channel_data","connection_id":"60a4fc71-1312-4830-86f4-9eb98be106ac","message_id":997,"id":"SUSHI-USD","channel":"v3_orderbook","contents":{"offset":"2693990848","bids":[["10.717","5123"],["10.716","0"]],"asks":[]}}
1635444236.0683079: {"type":"channel_data","connection_id":"60a4fc71-1312-4830-86f4-9eb98be106ac","message_id":998,"id":"ETH-USD","channel":"v3_orderbook","contents":{"offset":"2693990854","bids":[["4211","5625.953"]],"asks":[]}}
1635444236.071564: {"type":"channel_data","connection_id":"60a4fc71-1312-4830-86f4-9eb98be106ac","message_id":999,"id":"ETH-USD","channel":"v3_orderbook","contents":{"offset":"2693990856","bids":[],"asks":[["4217.3","1901.743"]]}}
1635444236.0716212: {"type":"channel_data","connection_id":"60a4fc71-1312-4830-86f4-9eb98be106ac","message_id":1000,"id":"ETH-USD","channel":"v3_orderbook","contents":{"offset":"2693990853","bids":[["4213.5","7.216"]],"asks":[]}}
1635444236.0803368: {"type":"channel_data","connection_id":"60a4fc71-1312-4830-86f4-9eb98be106ac","message_id":1001,"id":"CRV-USD","channel":"v3_orderbook","contents":{"offset":"2693990862","bids":[],"asks":[["4.861","10327"]]}}
1635444236.080398: {"type":"channel_data","connection_id":"60a4fc71-1312-4830-86f4-9eb98be106ac","message_id":1002,"id":"ETH-USD","channel":"v3_orderbook","contents":{"offset":"2693990857","bids":[],"asks":[["4217.3","1911.526"]]}}
1635444236.082269: {"type":"channel_data","connection_id":"60a4fc71-1312-4830-86f4-9eb98be106ac","message_id":1003,"id":"ETH-USD","channel":"v3_orderbook","contents":{"offset":"2693990863","bids":[],"asks":[["4216.6","58.746"]]}}
1635444236.084456: {"type":"channel_data","connection_id":"60a4fc71-1312-4830-86f4-9eb98be106ac","message_id":1004,"id":"ETH-USD","channel":"v3_orderbook","contents":{"offset":"2693990865","bids":[["4213.1","1898.821"]],"asks":[]}}
1635444236.084515: {"type":"channel_data","connection_id":"60a4fc71-1312-4830-86f4-9eb98be106ac","message_id":1005,"id":"UNI-USD","channel":"v3_orderbook","contents":{"offset":"2693990866","bids":[["25.032","2896.4"]],"asks":[]}}
1635444236.186501: {"type":"channel_data","connection_id":"60a4fc71-1312-4830-86f4-9eb98be106ac","message_id":1006,"id":"ETH-USD","channel":"v3_orderbook","contents":{"offset":"2693990869","bids":[],"asks":[["4216.5","126.083"]]}}
1635444236.195773: {"type":"channel_data","connection_id":"60a4fc71-1312-4830-86f4-9eb98be106ac","message_id":1007,"id":"CRV-USD","channel":"v3_orderbook","contents":{"offset":"2693990877","bids":[["4.848","2838"]],"asks":[]}}
1635444236.195841: {"type":"channel_data","connection_id":"60a4fc71-1312-4830-86f4-9eb98be106ac","message_id":1008,"id":"UNI-USD","channel":"v3_orderbook","contents":{"offset":"2693990878","bids":[],"asks":[["25.068","399.5"]]}}
1635444236.1974049: {"type":"channel_data","connection_id":"60a4fc71-1312-4830-86f4-9eb98be106ac","message_id":1009,"id":"SUSHI-USD","channel":"v3_orderbook","contents":{"offset":"2693990881","bids":[["10.776","0"]],"asks":[]}}
1635444236.1992269: {"type":"channel_data","connection_id":"60a4fc71-1312-4830-86f4-9eb98be106ac","message_id":1010,"id":"SUSHI-USD","channel":"v3_orderbook","contents":{"offset":"2693990879","bids":[["10.771","0"]],"asks":[]}}
1635444236.199286: {"type":"channel_data","connection_id":"60a4fc71-1312-4830-86f4-9eb98be106ac","message_id":1011,"id":"SUSHI-USD","channel":"v3_orderbook","contents":{"offset":"2693990884","bids":[],"asks":[["10.793","0"]]}}
1635444236.1993222: {"type":"channel_data","connection_id":"60a4fc71-1312-4830-86f4-9eb98be106ac","message_id":1012,"id":"SUSHI-USD","channel":"v3_orderbook","contents":{"offset":"2693990882","bids":[],"asks":[["10.802","0"]]}}
1635444236.200587: {"type":"channel_data","connection_id":"60a4fc71-1312-4830-86f4-9eb98be106ac","message_id":1013,"id":"SUSHI-USD","channel":"v3_orderbook","contents":{"offset":"2693990880","bids":[],"asks":[["10.797","4482.3"]]}}
1635444236.2025821: {"type":"channel_data","connection_id":"60a4fc71-1312-4830-86f4-9eb98be106ac","message_id":1014,"id":"ETH-USD","channel":"v3_orderbook","contents":{"offset":"2693990885","bids":[],"asks":[["4221","1.81"]]}}
1635444236.202639: {"type":"channel_data","connection_id":"60a4fc71-1312-4830-86f4-9eb98be106ac","message_id":1015,"id":"EOS-USD","channel":"v3_orderbook","contents":{"offset":"2693990889","bids":[],"asks":[["4.417","0"],["4.418","1091"]]}}
1635444236.2026749: {"type":"channel_data","connection_id":"60a4fc71-1312-4830-86f4-9eb98be106ac","message_id":1016,"id":"UNI-USD","channel":"v3_orderbook","contents":{"offset":"2693990887","bids":[],"asks":[["25.068","0"]]}}
1635444236.210598: {"type":"channel_data","connection_id":"60a4fc71-1312-4830-86f4-9eb98be106ac","message_id":1017,"id":"XMR-USD","channel":"v3_orderbook","contents":{"offset":"2693990892","bids":[],"asks":[["265.4","286.73"]]}}
1635444236.210686: {"type":"channel_data","connection_id":"60a4fc71-1312-4830-86f4-9eb98be106ac","message_id":1018,"id":"EOS-USD","channel":"v3_orderbook","contents":{"offset":"2693990898","bids":[],"asks":[["4.405","35222"]]}}
1635444236.210727: {"type":"channel_data","connection_id":"60a4fc71-1312-4830-86f4-9eb98be106ac","message_id":1019,"id":"SUSHI-USD","channel":"v3_orderbook","contents":{"offset":"2693990893","bids":[],"asks":[["10.809","0"]]}}
1635444236.2107599: {"type":"channel_data","connection_id":"60a4fc71-1312-4830-86f4-9eb98be106ac","message_id":1020,"id":"ETH-USD","channel":"v3_orderbook","contents":{"offset":"2693990895","bids":[["4212.6","32.191"]],"asks":[]}}
1635444236.211396: {"type":"channel_data","connection_id":"60a4fc71-1312-4830-86f4-9eb98be106ac","message_id":1021,"id":"XMR-USD","channel":"v3_orderbook","contents":{"offset":"2693990899","bids":[["265","75.46"]],"asks":[]}}
1635444236.211458: {"type":"channel_data","connection_id":"60a4fc71-1312-4830-86f4-9eb98be106ac","message_id":1022,"id":"MKR-USD","channel":"v3_orderbook","contents":{"offset":"2693990896","bids":[],"asks":[["2389","47.215"]]}}
1635444236.211493: {"type":"channel_data","connection_id":"60a4fc71-1312-4830-86f4-9eb98be106ac","message_id":1023,"id":"CRV-USD","channel":"v3_orderbook","contents":{"offset":"2693990903","bids":[["4.846","2176"]],"asks":[]}}
1635444236.212265: {"type":"channel_data","connection_id":"60a4fc71-1312-4830-86f4-9eb98be106ac","message_id":1024,"id":"EOS-USD","channel":"v3_orderbook","contents":{"offset":"2693990901","bids":[["4.385","13356"],["4.384","0"]],"asks":[]}}
1635444236.227691: {"type":"channel_data","connection_id":"60a4fc71-1312-4830-86f4-9eb98be106ac","message_id":1025,"id":"ETH-USD","channel":"v3_orderbook","contents":{"offset":"2693990907","bids":[["4212.6","0"]],"asks":[]}}
1635444236.2367392: {"type":"channel_data","connection_id":"60a4fc71-1312-4830-86f4-9eb98be106ac","message_id":1026,"id":"EOS-USD","channel":"v3_orderbook","contents":{"offset":"2693990908","bids":[],"asks":[["4.407","11557"]]}}
1635444236.24825: {"type":"channel_data","connection_id":"60a4fc71-1312-4830-86f4-9eb98be106ac","message_id":1027,"id":"ETH-USD","channel":"v3_orderbook","contents":{"offset":"2693990913","bids":[],"asks":[["4217.3","1901.743"]]}}
1635444236.2483342: {"type":"channel_data","connection_id":"60a4fc71-1312-4830-86f4-9eb98be106ac","message_id":1028,"id":"ETH-USD","channel":"v3_orderbook","contents":{"offset":"2693990915","bids":[],"asks":[["4216.5","149.817"]]}}
1635444236.248835: {"type":"channel_data","connection_id":"60a4fc71-1312-4830-86f4-9eb98be106ac","message_id":1029,"id":"UNI-USD","channel":"v3_orderbook","contents":{"offset":"2693990912","bids":[],"asks":[["25.068","399.5"]]}}
1635444236.258791: {"type":"channel_data","connection_id":"60a4fc71-1312-4830-86f4-9eb98be106ac","message_id":1030,"id":"MKR-USD","channel":"v3_orderbook","contents":{"offset":"2693990918","bids":[["2374","434.211"]],"asks":[]}}
1635444236.2589068: {"type":"channel_data","connection_id":"60a4fc71-1312-4830-86f4-9eb98be106ac","message_id":1031,"id":"SUSHI-USD","channel":"v3_orderbook","contents":{"offset":"2693990921","bids":[["10.78","15004.9"]],"asks":[]}}
1635444236.258971: {"type":"channel_data","connection_id":"60a4fc71-1312-4830-86f4-9eb98be106ac","message_id":1032,"id":"MKR-USD","channel":"v3_orderbook","contents":{"offset":"2693990919","bids":[],"asks":[["2402","73.146"],["2403","1.781"]]}}
1635444236.2590358: {"type":"channel_data","connection_id":"60a4fc71-1312-4830-86f4-9eb98be106ac","message_id":1033,"id":"ETH-USD","channel":"v3_orderbook","contents":{"offset":"2693990922","bids":[["4213.5","0"]],"asks":[]}}
1635444236.260633: {"type":"channel_data","connection_id":"60a4fc71-1312-4830-86f4-9eb98be106ac","message_id":1034,"id":"CRV-USD","channel":"v3_orderbook","contents":{"offset":"2693990920","bids":[["4.842","9295"]],"asks":[]}}
1635444236.274434: {"type":"channel_data","connection_id":"60a4fc71-1312-4830-86f4-9eb98be106ac","message_id":1035,"id":"UNI-USD","channel":"v3_orderbook","contents":{"offset":"2693990927","bids":[],"asks":[["25.068","0"]]}}
1635444236.2874691: {"type":"channel_data","connection_id":"60a4fc71-1312-4830-86f4-9eb98be106ac","message_id":1036,"id":"ETH-USD","channel":"v3_orderbook","contents":{"offset":"2693990929","bids":[],"asks":[["4216.5","126.083"]]}}
1635444236.299006: {"type":"channel_data","connection_id":"60a4fc71-1312-4830-86f4-9eb98be106ac","message_id":1037,"id":"ETH-USD","channel":"v3_orderbook","contents":{"offset":"2693990931","bids":[["4213.4","7.216"]],"asks":[]}}
1635444236.3016121: {"type":"channel_data","connection_id":"60a4fc71-1312-4830-86f4-9eb98be106ac","message_id":1038,"id":"ETH-USD","channel":"v3_orderbook","contents":{"offset":"2693990932","bids":[],"asks":[["4217.2","32.279"]]}}
1635444236.314027: {"type":"channel_data","connection_id":"60a4fc71-1312-4830-86f4-9eb98be106ac","message_id":1039,"id":"SUSHI-USD","channel":"v3_orderbook","contents":{"offset":"2693990938","bids":[],"asks":[["10.795","1209.2"]]}}
1635444236.3300831: {"type":"channel_data","connection_id":"60a4fc71-1312-4830-86f4-9eb98be106ac","message_id":1040,"id":"ETH-USD","channel":"v3_orderbook","contents":{"offset":"2693990940","bids":[["4213.1","1927.278"]],"asks":[]}}
1635444236.330165: {"type":"channel_data","connection_id":"60a4fc71-1312-4830-86f4-9eb98be106ac","message_id":1041,"id":"SUSHI-USD","channel":"v3_orderbook","contents":{"offset":"2693990944","bids":[["10.724","3247.6"],["10.722","0"]],"asks":[]}}
1635444236.3378508: {"type":"channel_data","connection_id":"60a4fc71-1312-4830-86f4-9eb98be106ac","message_id":1042,"id":"ETH-USD","channel":"v3_orderbook","contents":{"offset":"2693990951","bids":[],"asks":[["4216.5","149.817"]]}}
1635444236.352776: {"type":"channel_data","connection_id":"60a4fc71-1312-4830-86f4-9eb98be106ac","message_id":1043,"id":"ETH-USD","channel":"v3_orderbook","contents":{"offset":"2693990953","bids":[["4215.9","467.909"]],"asks":[]}}
1635444236.3528588: {"type":"channel_data","connection_id":"60a4fc71-1312-4830-86f4-9eb98be106ac","message_id":1044,"id":"ETH-USD","channel":"v3_orderbook","contents":{"offset":"2693990954","bids":[],"asks":[["4216.7","0"]]}}
1635444236.352896: {"type":"channel_data","connection_id":"60a4fc71-1312-4830-86f4-9eb98be106ac","message_id":1045,"id":"SUSHI-USD","channel":"v3_orderbook","contents":{"offset":"2693990955","bids":[["10.775","440.5"]],"asks":[]}}
1635444236.352929: {"type":"channel_data","connection_id":"60a4fc71-1312-4830-86f4-9eb98be106ac","message_id":1046,"id":"UNI-USD","channel":"v3_orderbook","contents":{"offset":"2693990952","bids":[],"asks":[["25.068","399.5"]]}}
1635444236.368725: {"type":"channel_data","connection_id":"60a4fc71-1312-4830-86f4-9eb98be106ac","message_id":1047,"id":"XMR-USD","channel":"v3_orderbook","contents":{"offset":"2693990962","bids":[],"asks":[["265.4","362.11"]]}}
1635444236.381495: {"type":"channel_data","connection_id":"60a4fc71-1312-4830-86f4-9eb98be106ac","message_id":1048,"id":"ETH-USD","channel":"v3_orderbook","contents":{"offset":"2693990966","bids":[],"asks":[["4216.5","126.083"]]}}
1635444236.387163: {"type":"channel_data","connection_id":"60a4fc71-1312-4830-86f4-9eb98be106ac","message_id":1049,"id":"UNI-USD","channel":"v3_orderbook","contents":{"offset":"2693990969","bids":[],"asks":[["25.068","0"]]}}
1635444236.3921301: {"type":"channel_data","connection_id":"60a4fc71-1312-4830-86f4-9eb98be106ac","message_id":1050,"id":"SUSHI-USD","channel":"v3_orderbook","contents":{"offset":"2693990971","bids":[["10.682","13393.1"]],"asks":[]}}
1635444236.392189: {"type":"channel_data","connection_id":"60a4fc71-1312-4830-86f4-9eb98be106ac","message_id":1051,"id":"SUSHI-USD","channel":"v3_orderbook","contents":{"offset":"2693990972","bids":[["10.735","3247.6"],["10.733","0"]],"asks":[]}}
1635444236.402795: {"type":"channel_data","connection_id":"60a4fc71-1312-4830-86f4-9eb98be106ac","message_id":1052,"id":"ETH-USD","channel":"v3_orderbook","contents":{"offset":"2693990975","bids":[["4215","22.496"]],"asks":[]}}
1635444236.426095: {"type":"channel_data","connection_id":"60a4fc71-1312-4830-86f4-9eb98be106ac","message_id":1053,"id":"SUSHI-USD","channel":"v3_orderbook","contents":{"offset":"2693990979","bids":[["10.788","0"]],"asks":[]}}
1635444236.4261692: {"type":"channel_data","connection_id":"60a4fc71-1312-4830-86f4-9eb98be106ac","message_id":1054,"id":"CRV-USD","channel":"v3_orderbook","contents":{"offset":"2693990982","bids":[["4.848","3431"]],"asks":[]}}
1635444236.430464: {"type":"channel_data","connection_id":"60a4fc71-1312-4830-86f4-9eb98be106ac","message_id":1055,"id":"ETH-USD","channel":"v3_orderbook","contents":{"offset":"2693990978","bids":[["4213.1","1898.821"]],"asks":[]}}
1635444236.430511: {"type":"channel_data","connection_id":"60a4fc71-1312-4830-86f4-9eb98be106ac","message_id":1056,"id":"UNI-USD","channel":"v3_orderbook","contents":{"offset":"2693990980","bids":[],"asks":[["25.068","399.5"]]}}
1635444236.430541: {"type":"channel_data","connection_id":"60a4fc71-1312-4830-86f4-9eb98be106ac","message_id":1057,"id":"ETH-USD","channel":"v3_orderbook","contents":{"offset":"2693990981","bids":[],"asks":[["4216.1","33.736"]]}}
1635444236.4545548: {"type":"channel_data","connection_id":"60a4fc71-1312-4830-86f4-9eb98be106ac","message_id":1058,"id":"UNI-USD","channel":"v3_orderbook","contents":{"offset":"2693990993","bids":[],"asks":[["25.068","0"]]}}
1635444236.4568598: {"type":"channel_data","connection_id":"60a4fc71-1312-4830-86f4-9eb98be106ac","message_id":1059,"id":"SUSHI-USD","channel":"v3_orderbook","contents":{"offset":"2693990994","bids":[],"asks":[["10.801","486.8"]]}}
1635444236.456907: {"type":"channel_data","connection_id":"60a4fc71-1312-4830-86f4-9eb98be106ac","message_id":1060,"id":"ETH-USD","channel":"v3_orderbook","contents":{"offset":"2693990989","bids":[],"asks":[["4216.1","10"]]}}
1635444236.458786: {"type":"channel_data","connection_id":"60a4fc71-1312-4830-86f4-9eb98be106ac","message_id":1061,"id":"ETH-USD","channel":"v3_orderbook","contents":{"offset":"2693990991","bids":[["4215.9","467.889"]],"asks":[]}}
1635444236.467593: {"type":"channel_data","connection_id":"60a4fc71-1312-4830-86f4-9eb98be106ac","message_id":1062,"id":"ETH-USD","channel":"v3_orderbook","contents":{"offset":"2693990998","bids":[],"asks":[["4216.1","125.57"]]}}
1635444236.477365: {"type":"channel_data","connection_id":"60a4fc71-1312-4830-86f4-9eb98be106ac","message_id":1063,"id":"ETH-USD","channel":"v3_trades","contents":{"trades":[{"size":"0.02","side":"SELL","price":"4215.9","createdAt":"2021-10-28T18:03:56.498Z"}]}}
1635444236.482734: {"type":"channel_data","connection_id":"60a4fc71-1312-4830-86f4-9eb98be106ac","message_id":1064,"id":"UNI-USD","channel":"v3_orderbook","contents":{"offset":"2693991000","bids":[],"asks":[["25.192","1997.7"],["25.193","0"]]}}
1635444236.5034702: {"type":"channel_data","connection_id":"60a4fc71-1312-4830-86f4-9eb98be106ac","message_id":1065,"id":"MKR-USD","channel":"v3_orderbook","contents":{"offset":"2693991017","bids":[["2299","5"]],"asks":[]}}
1635444236.5035598: {"type":"channel_data","connection_id":"60a4fc71-1312-4830-86f4-9eb98be106ac","message_id":1066,"id":"SUSHI-USD","channel":"v3_orderbook","contents":{"offset":"2693991015","bids":[["10.719","5123"],["10.717","0"]],"asks":[]}}
1635444236.5165539: {"type":"channel_data","connection_id":"60a4fc71-1312-4830-86f4-9eb98be106ac","message_id":1067,"id":"SUSHI-USD","channel":"v3_orderbook","contents":{"offset":"2693991025","bids":[["10.787","295.8"]],"asks":[]}}
1635444236.516635: {"type":"channel_data","connection_id":"60a4fc71-1312-4830-86f4-9eb98be106ac","message_id":1068,"id":"UNI-USD","channel":"v3_orderbook","contents":{"offset":"2693991023","bids":[],"asks":[["25.068","399.5"]]}}
1635444236.516673: {"type":"channel_data","connection_id":"60a4fc71-1312-4830-86f4-9eb98be106ac","message_id":1069,"id":"SUSHI-USD","channel":"v3_orderbook","contents":{"offset":"2693991024","bids":[],"asks":[["10.797","0"]]}}
1635444236.5261598: {"type":"channel_data","connection_id":"60a4fc71-1312-4830-86f4-9eb98be106ac","message_id":1070,"id":"ETH-USD","channel":"v3_orderbook","contents":{"offset":"2693991030","bids":[],"asks":[["4216.1","149.306"]]}}
1635444236.530699: {"type":"channel_data","connection_id":"60a4fc71-1312-4830-86f4-9eb98be106ac","message_id":1071,"id":"ETH-USD","channel":"v3_orderbook","contents":{"offset":"2693991029","bids":[["4212.6","32.201"]],"asks":[]}}
1635444236.541827: {"type":"channel_data","connection_id":"60a4fc71-1312-4830-86f4-9eb98be106ac","message_id":1072,"id":"UNI-USD","channel":"v3_orderbook","contents":{"offset":"2693991039","bids":[],"asks":[["25.068","0"]]}}
1635444236.549964: {"type":"channel_data","connection_id":"60a4fc71-1312-4830-86f4-9eb98be106ac","message_id":1073,"id":"MKR-USD","channel":"v3_orderbook","contents":{"offset":"2693991042","bids":[],"asks":[["2466","5"]]}}
1635444236.550029: {"type":"channel_data","connection_id":"60a4fc71-1312-4830-86f4-9eb98be106ac","message_id":1074,"id":"ETH-USD","channel":"v3_orderbook","contents":{"offset":"2693991048","bids":[],"asks":[["4216.1","125.57"]]}}
1635444236.563284: {"type":"channel_data","connection_id":"60a4fc71-1312-4830-86f4-9eb98be106ac","message_id":1075,"id":"SUSHI-USD","channel":"v3_orderbook","contents":{"offset":"2693991050","bids":[],"asks":[["10.806","4184.4"]]}}
1635444236.574813: {"type":"channel_data","connection_id":"60a4fc71-1312-4830-86f4-9eb98be106ac","message_id":1076,"id":"UMA-USD","channel":"v3_orderbook","contents":{"offset":"2693991054","bids":[["11.27","29416.2"]],"asks":[]}}
1635444236.577934: {"type":"channel_data","connection_id":"60a4fc71-1312-4830-86f4-9eb98be106ac","message_id":1077,"id":"ETH-USD","channel":"v3_orderbook","contents":{"offset":"2693991053","bids":[["4212.6","0"]],"asks":[]}}
1635444236.5930712: {"type":"channel_data","connection_id":"60a4fc71-1312-4830-86f4-9eb98be106ac","message_id":1078,"id":"ETH-USD","channel":"v3_orderbook","contents":{"offset":"2693991062","bids":[],"asks":[["4216.1","149.306"]]}}
1635444236.593154: {"type":"channel_data","connection_id":"60a4fc71-1312-4830-86f4-9eb98be106ac","message_id":1079,"id":"SUSHI-USD","channel":"v3_orderbook","contents":{"offset":"2693991060","bids":[["10.79","0"]],"asks":[]}}
1635444236.601125: {"type":"channel_data","connection_id":"60a4fc71-1312-4830-86f4-9eb98be106ac","message_id":1080,"id":"UMA-USD","channel":"v3_orderbook","contents":{"offset":"2693991068","bids":[["11.27","29150.7"]],"asks":[]}}
1635444236.608765: {"type":"channel_data","connection_id":"60a4fc71-1312-4830-86f4-9eb98be106ac","message_id":1081,"id":"CRV-USD","channel":"v3_orderbook","contents":{"offset":"2693991073","bids":[["4.847","13980"]],"asks":[]}}
1635444236.608834: {"type":"channel_data","connection_id":"60a4fc71-1312-4830-86f4-9eb98be106ac","message_id":1082,"id":"UNI-USD","channel":"v3_orderbook","contents":{"offset":"2693991075","bids":[],"asks":[["25.068","399.5"]]}}
1635444236.619592: {"type":"channel_data","connection_id":"60a4fc71-1312-4830-86f4-9eb98be106ac","message_id":1083,"id":"ETH-USD","channel":"v3_orderbook","contents":{"offset":"2693991081","bids":[],"asks":[["4217.5","1.258"]]}}
1635444236.622717: {"type":"channel_data","connection_id":"60a4fc71-1312-4830-86f4-9eb98be106ac","message_id":1084,"id":"SUSHI-USD","channel":"v3_orderbook","contents":{"offset":"2693991082","bids":[],"asks":[["10.808","102"]]}}
1635444236.623462: {"type":"channel_data","connection_id":"60a4fc71-1312-4830-86f4-9eb98be106ac","message_id":1085,"id":"SUSHI-USD","channel":"v3_orderbook","contents":{"offset":"2693991086","bids":[["10.779","401.8"]],"asks":[]}}
1635444236.632639: {"type":"channel_data","connection_id":"60a4fc71-1312-4830-86f4-9eb98be106ac","message_id":1086,"id":"ETH-USD","channel":"v3_orderbook","contents":{"offset":"2693991093","bids":[],"asks":[["4216.1","125.57"]]}}
1635444236.64254: {"type":"channel_data","connection_id":"60a4fc71-1312-4830-86f4-9eb98be106ac","message_id":1087,"id":"SUSHI-USD","channel":"v3_orderbook","contents":{"offset":"2693991102","bids":[],"asks":[["10.795","5660.9"]]}}
1635444236.642625: {"type":"channel_data","connection_id":"60a4fc71-1312-4830-86f4-9eb98be106ac","message_id":1088,"id":"UNI-USD","channel":"v3_orderbook","contents":{"offset":"2693991097","bids":[],"asks":[["25.068","0"]]}}
1635444236.651765: {"type":"channel_data","connection_id":"60a4fc71-1312-4830-86f4-9eb98be106ac","message_id":1089,"id":"SUSHI-USD","channel":"v3_orderbook","contents":{"offset":"2693991105","bids":[["10.784","8454"]],"asks":[]}}
1635444236.652591: {"type":"channel_data","connection_id":"60a4fc71-1312-4830-86f4-9eb98be106ac","message_id":1090,"id":"EOS-USD","channel":"v3_orderbook","contents":{"offset":"2693991107","bids":[],"asks":[["4.407","2479"]]}}
1635444236.6526551: {"type":"channel_data","connection_id":"60a4fc71-1312-4830-86f4-9eb98be106ac","message_id":1091,"id":"UNI-USD","channel":"v3_orderbook","contents":{"offset":"2693991103","bids":[["24.949","501"],["24.947","43.9"]],"asks":[]}}
1635444236.673633: {"type":"channel_data","connection_id":"60a4fc71-1312-4830-86f4-9eb98be106ac","message_id":1092,"id":"EOS-USD","channel":"v3_orderbook","contents":{"offset":"2693991111","bids":[],"asks":[["4.405","44300"]]}}
1635444236.673704: {"type":"channel_data","connection_id":"60a4fc71-1312-4830-86f4-9eb98be106ac","message_id":1093,"id":"CRV-USD","channel":"v3_orderbook","contents":{"offset":"2693991112","bids":[["4.847","14661"]],"asks":[]}}
1635444236.685601: {"type":"channel_data","connection_id":"60a4fc71-1312-4830-86f4-9eb98be106ac","message_id":1094,"id":"MKR-USD","channel":"v3_orderbook","contents":{"offset":"2693991116","bids":[["2380","28.834"]],"asks":[]}}
1635444236.686093: {"type":"channel_data","connection_id":"60a4fc71-1312-4830-86f4-9eb98be106ac","message_id":1095,"id":"CRV-USD","channel":"v3_orderbook","contents":{"offset":"2693991114","bids":[["4.837","12268"]],"asks":[]}}
1635444236.686578: {"type":"channel_data","connection_id":"60a4fc71-1312-4830-86f4-9eb98be106ac","message_id":1096,"id":"CRV-USD","channel":"v3_orderbook","contents":{"offset":"2693991117","bids":[["4.845","1337"]],"asks":[]}}
1635444236.699018: {"type":"channel_data","connection_id":"60a4fc71-1312-4830-86f4-9eb98be106ac","message_id":1097,"id":"ETH-USD","channel":"v3_orderbook","contents":{"offset":"2693991121","bids":[["4213.1","1926.609"]],"asks":[]}}
1635444236.6991491: {"type":"channel_data","connection_id":"60a4fc71-1312-4830-86f4-9eb98be106ac","message_id":1098,"id":"UNI-USD","channel":"v3_orderbook","contents":{"offset":"2693991123","bids":[],"asks":[["25.136","43.9"],["25.138","0"]]}}
1635444236.709743: {"type":"channel_data","connection_id":"60a4fc71-1312-4830-86f4-9eb98be106ac","message_id":1099,"id":"MKR-USD","channel":"v3_orderbook","contents":{"offset":"2693991129","bids":[],"asks":[["2384","25.302"]]}}
1635444236.709823: {"type":"channel_data","connection_id":"60a4fc71-1312-4830-86f4-9eb98be106ac","message_id":1100,"id":"UNI-USD","channel":"v3_orderbook","contents":{"offset":"2693991130","bids":[],"asks":[["25.068","399.5"]]}}
1635444236.722809: {"type":"channel_data","connection_id":"60a4fc71-1312-4830-86f4-9eb98be106ac","message_id":1101,"id":"UMA-USD","channel":"v3_orderbook","contents":{"offset":"2693991134","bids":[],"asks":[["11.33","6099.5"]]}}
1635444236.722893: {"type":"channel_data","connection_id":"60a4fc71-1312-4830-86f4-9eb98be106ac","message_id":1102,"id":"UMA-USD","channel":"v3_orderbook","contents":{"offset":"2693991135","bids":[],"asks":[["11.33","1683.6"]]}}
1635444236.7366881: {"type":"channel_data","connection_id":"60a4fc71-1312-4830-86f4-9eb98be106ac","message_id":1103,"id":"ETH-USD","channel":"v3_orderbook","contents":{"offset":"2693991142","bids":[["4215.7","0"]],"asks":[]}}
1635444236.736817: {"type":"channel_data","connection_id":"60a4fc71-1312-4830-86f4-9eb98be106ac","message_id":1104,"id":"UNI-USD","channel":"v3_orderbook","contents":{"offset":"2693991140","bids":[],"asks":[["25.068","0"]]}}
1635444236.736882: {"type":"channel_data","connection_id":"60a4fc71-1312-4830-86f4-9eb98be106ac","message_id":1105,"id":"ETH-USD","channel":"v3_orderbook","contents":{"offset":"2693991141","bids":[],"asks":[["4216.1","149.306"]]}}
1635444236.7468228: {"type":"channel_data","connection_id":"60a4fc71-1312-4830-86f4-9eb98be106ac","message_id":1106,"id":"SUSHI-USD","channel":"v3_orderbook","contents":{"offset":"2693991145","bids":[["10.789","1543.9"]],"asks":[]}}
1635444236.74694: {"type":"channel_data","connection_id":"60a4fc71-1312-4830-86f4-9eb98be106ac","message_id":1107,"id":"ETH-USD","channel":"v3_orderbook","contents":{"offset":"2693991146","bids":[["4213.1","1898.821"]],"asks":[]}}
1635444236.7469969: {"type":"channel_data","connection_id":"60a4fc71-1312-4830-86f4-9eb98be106ac","message_id":1108,"id":"UNI-USD","channel":"v3_orderbook","contents":{"offset":"2693991147","bids":[],"asks":[["25.059","0"]]}}
1635444236.759277: {"type":"channel_data","connection_id":"60a4fc71-1312-4830-86f4-9eb98be106ac","message_id":1109,"id":"ETH-USD","channel":"v3_orderbook","contents":{"offset":"2693991150","bids":[],"asks":[["4223.3","0"],["4223.5","3.08"]]}}
1635444236.7593532: {"type":"channel_data","connection_id":"60a4fc71-1312-4830-86f4-9eb98be106ac","message_id":1110,"id":"UNI-USD","channel":"v3_orderbook","contents":{"offset":"2693991155","bids":[],"asks":[["25.056","0"]]}}
1635444236.7593842: {"type":"channel_data","connection_id":"60a4fc71-1312-4830-86f4-9eb98be106ac","message_id":1111,"id":"UNI-USD","channel":"v3_orderbook","contents":{"offset":"2693991151","bids":[],"asks":[["25.095","0"]]}}
1635444236.7598898: {"type":"channel_data","connection_id":"60a4fc71-1312-4830-86f4-9eb98be106ac","message_id":1112,"id":"UNI-USD","channel":"v3_orderbook","contents":{"offset":"2693991154","bids":[["25.025","0"]],"asks":[]}}
1635444236.759935: {"type":"channel_data","connection_id":"60a4fc71-1312-4830-86f4-9eb98be106ac","message_id":1113,"id":"UNI-USD","channel":"v3_orderbook","contents":{"offset":"2693991152","bids":[],"asks":[["25.06","0"]]}}
1635444236.759964: {"type":"channel_data","connection_id":"60a4fc71-1312-4830-86f4-9eb98be106ac","message_id":1114,"id":"UNI-USD","channel":"v3_orderbook","contents":{"offset":"2693991149","bids":[["25.019","0"]],"asks":[]}}
1635444236.765026: {"type":"channel_data","connection_id":"60a4fc71-1312-4830-86f4-9eb98be106ac","message_id":1115,"id":"UNI-USD","channel":"v3_orderbook","contents":{"offset":"2693991157","bids":[["25.022","0"]],"asks":[]}}
1635444236.768599: {"type":"channel_data","connection_id":"60a4fc71-1312-4830-86f4-9eb98be106ac","message_id":1116,"id":"ETH-USD","channel":"v3_orderbook","contents":{"offset":"2693991163","bids":[],"asks":[["4216.1","125.57"]]}}
1635444236.768663: {"type":"channel_data","connection_id":"60a4fc71-1312-4830-86f4-9eb98be106ac","message_id":1117,"id":"UNI-USD","channel":"v3_orderbook","contents":{"offset":"2693991158","bids":[["24.98","0"]],"asks":[]}}
1635444236.7687008: {"type":"channel_data","connection_id":"60a4fc71-1312-4830-86f4-9eb98be106ac","message_id":1118,"id":"ETH-USD","channel":"v3_orderbook","contents":{"offset":"2693991159","bids":[["4208.4","1.304"],["4208.2","0"]],"asks":[]}}
1635444236.769595: {"type":"channel_data","connection_id":"60a4fc71-1312-4830-86f4-9eb98be106ac","message_id":1119,"id":"CRV-USD","channel":"v3_orderbook","contents":{"offset":"2693991160","bids":[["4.839","102257"]],"asks":[]}}
1635444236.7721128: {"type":"channel_data","connection_id":"60a4fc71-1312-4830-86f4-9eb98be106ac","message_id":1120,"id":"BCH-USD","channel":"v3_orderbook","contents":{"offset":"2693991165","bids":[["572.4","67.92"],["572.3","0"]],"asks":[]}}
1635444236.792581: {"type":"channel_data","connection_id":"60a4fc71-1312-4830-86f4-9eb98be106ac","message_id":1121,"id":"SUSHI-USD","channel":"v3_orderbook","contents":{"offset":"2693991170","bids":[],"asks":[["10.921","927.4"]]}}
1635444236.805143: {"type":"channel_data","connection_id":"60a4fc71-1312-4830-86f4-9eb98be106ac","message_id":1122,"id":"UNI-USD","channel":"v3_orderbook","contents":{"offset":"2693991179","bids":[],"asks":[["25.068","399.5"]]}}
1635444236.822241: {"type":"channel_data","connection_id":"60a4fc71-1312-4830-86f4-9eb98be106ac","message_id":1123,"id":"UNI-USD","channel":"v3_orderbook","contents":{"offset":"2693991184","bids":[],"asks":[["25.068","0"]]}}
1635444236.833899: {"type":"channel_data","connection_id":"60a4fc71-1312-4830-86f4-9eb98be106ac","message_id":1124,"id":"ETH-USD","channel":"v3_orderbook","contents":{"offset":"2693991188","bids":[],"asks":[["4216.1","149.306"]]}}
1635444236.8488162: {"type":"channel_data","connection_id":"60a4fc71-1312-4830-86f4-9eb98be106ac","message_id":1125,"id":"ETH-USD","channel":"v3_orderbook","contents":{"offset":"2693991191","bids":[["4212.6","32.199"]],"asks":[]}}
1635444236.849491: {"type":"channel_data","connection_id":"60a4fc71-1312-4830-86f4-9eb98be106ac","message_id":1126,"id":"UMA-USD","channel":"v3_orderbook","contents":{"offset":"2693991192","bids":[],"asks":[["11.33","23786.7"]]}}
1635444236.849577: {"type":"channel_data","connection_id":"60a4fc71-1312-4830-86f4-9eb98be106ac","message_id":1127,"id":"UMA-USD","channel":"v3_orderbook","contents":{"offset":"2693991193","bids":[],"asks":[["11.33","28202.6"]]}}
1635444236.858204: {"type":"channel_data","connection_id":"60a4fc71-1312-4830-86f4-9eb98be106ac","message_id":1128,"id":"UNI-USD","channel":"v3_orderbook","contents":{"offset":"2693991202","bids":[],"asks":[["25.068","399.5"]]}}
1635444236.85917: {"type":"channel_data","connection_id":"60a4fc71-1312-4830-86f4-9eb98be106ac","message_id":1129,"id":"UMA-USD","channel":"v3_orderbook","contents":{"offset":"2693991200","bids":[],"asks":[["11.33","6099.5"]]}}
1635444236.859235: {"type":"channel_data","connection_id":"60a4fc71-1312-4830-86f4-9eb98be106ac","message_id":1130,"id":"UMA-USD","channel":"v3_orderbook","contents":{"offset":"2693991203","bids":[],"asks":[["11.33","1683.6"]]}}
1635444236.8732522: {"type":"channel_data","connection_id":"60a4fc71-1312-4830-86f4-9eb98be106ac","message_id":1131,"id":"ETH-USD","channel":"v3_orderbook","contents":{"offset":"2693991206","bids":[],"asks":[["4216.1","125.57"]]}}
1635444236.882339: {"type":"channel_data","connection_id":"60a4fc71-1312-4830-86f4-9eb98be106ac","message_id":1132,"id":"SUSHI-USD","channel":"v3_orderbook","contents":{"offset":"2693991213","bids":[["10.725","3247.6"],["10.724","0"]],"asks":[]}}
1635444236.888053: {"type":"channel_data","connection_id":"60a4fc71-1312-4830-86f4-9eb98be106ac","message_id":1133,"id":"UNI-USD","channel":"v3_orderbook","contents":{"offset":"2693991223","bids":[["25.032","10874"]],"asks":[]}}
1635444236.888721: {"type":"channel_data","connection_id":"60a4fc71-1312-4830-86f4-9eb98be106ac","message_id":1134,"id":"UMA-USD","channel":"v3_orderbook","contents":{"offset":"2693991218","bids":[["11.27","29416.2"]],"asks":[]}}
1635444236.888778: {"type":"channel_data","connection_id":"60a4fc71-1312-4830-86f4-9eb98be106ac","message_id":1135,"id":"UNI-USD","channel":"v3_orderbook","contents":{"offset":"2693991220","bids":[["25.002","400105.3"]],"asks":[]}}
1635444236.890341: {"type":"channel_data","connection_id":"60a4fc71-1312-4830-86f4-9eb98be106ac","message_id":1136,"id":"UNI-USD","channel":"v3_orderbook","contents":{"offset":"2693991219","bids":[["25.03","2991.6"]],"asks":[]}}
1635444236.890389: {"type":"channel_data","connection_id":"60a4fc71-1312-4830-86f4-9eb98be106ac","message_id":1137,"id":"UNI-USD","channel":"v3_orderbook","contents":{"offset":"2693991221","bids":[],"asks":[["25.068","0"]]}}
1635444236.8976572: {"type":"channel_data","connection_id":"60a4fc71-1312-4830-86f4-9eb98be106ac","message_id":1138,"id":"UNI-USD","channel":"v3_orderbook","contents":{"offset":"2693991226","bids":[],"asks":[["25.081","398879.4"]]}}
1635444236.897739: {"type":"channel_data","connection_id":"60a4fc71-1312-4830-86f4-9eb98be106ac","message_id":1139,"id":"UNI-USD","channel":"v3_orderbook","contents":{"offset":"2693991227","bids":[],"asks":[["25.053","16064.3"]]}}
1635444236.8995352: {"type":"channel_data","connection_id":"60a4fc71-1312-4830-86f4-9eb98be106ac","message_id":1140,"id":"UNI-USD","channel":"v3_orderbook","contents":{"offset":"2693991229","bids":[],"asks":[["25.053","19055.9"]]}}
1635444236.9041998: {"type":"channel_data","connection_id":"60a4fc71-1312-4830-86f4-9eb98be106ac","message_id":1141,"id":"SUSHI-USD","channel":"v3_orderbook","contents":{"offset":"2693991233","bids":[["10.736","3247.6"],["10.735","0"]],"asks":[]}}
1635444236.9145138: {"type":"channel_data","connection_id":"60a4fc71-1312-4830-86f4-9eb98be106ac","message_id":1142,"id":"UMA-USD","channel":"v3_orderbook","contents":{"offset":"2693991245","bids":[["11.27","29150.7"]],"asks":[]}}
1635444236.934804: {"type":"channel_data","connection_id":"60a4fc71-1312-4830-86f4-9eb98be106ac","message_id":1143,"id":"UNI-USD","channel":"v3_orderbook","contents":{"offset":"2693991261","bids":[["25.029","15955.2"]],"asks":[]}}
1635444236.942661: {"type":"channel_data","connection_id":"60a4fc71-1312-4830-86f4-9eb98be106ac","message_id":1144,"id":"ETH-USD","channel":"v3_orderbook","contents":{"offset":"2693991263","bids":[],"asks":[["4216.1","149.306"]]}}
1635444236.945867: {"type":"channel_data","connection_id":"60a4fc71-1312-4830-86f4-9eb98be106ac","message_id":1145,"id":"UNI-USD","channel":"v3_orderbook","contents":{"offset":"2693991267","bids":[["25.027","0"]],"asks":[]}}
1635444236.94633: {"type":"channel_data","connection_id":"60a4fc71-1312-4830-86f4-9eb98be106ac","message_id":1146,"id":"UNI-USD","channel":"v3_orderbook","contents":{"offset":"2693991264","bids":[],"asks":[["25.068","399.5"]]}}
1635444236.9541938: {"type":"channel_data","connection_id":"60a4fc71-1312-4830-86f4-9eb98be106ac","message_id":1147,"id":"SUSHI-USD","channel":"v3_orderbook","contents":{"offset":"2693991271","bids":[],"asks":[["10.803","544.7"]]}}
1635444236.968621: {"type":"channel_data","connection_id":"60a4fc71-1312-4830-86f4-9eb98be106ac","message_id":1148,"id":"UNI-USD","channel":"v3_orderbook","contents":{"offset":"2693991279","bids":[],"asks":[["25.068","0"]]}}
1635444236.968986: {"type":"channel_data","connection_id":"60a4fc71-1312-4830-86f4-9eb98be106ac","message_id":1149,"id":"ETH-USD","channel":"v3_orderbook","contents":{"offset":"2693991275","bids":[],"asks":[["4216.1","125.57"]]}}
1635444236.991609: {"type":"channel_data","connection_id":"60a4fc71-1312-4830-86f4-9eb98be106ac","message_id":1150,"id":"UNI-USD","channel":"v3_orderbook","contents":{"offset":"2693991284","bids":[["25.027","113.6"]],"asks":[]}}
1635444236.9916742: {"type":"channel_data","connection_id":"60a4fc71-1312-4830-86f4-9eb98be106ac","message_id":1151,"id":"XMR-USD","channel":"v3_orderbook","contents":{"offset":"2693991281","bids":[],"asks":[["265.4","286.73"]]}}
1635444236.9917: {"type":"channel_data","connection_id":"60a4fc71-1312-4830-86f4-9eb98be106ac","message_id":1152,"id":"UMA-USD","channel":"v3_orderbook","contents":{"offset":"2693991283","bids":[],"asks":[["11.33","6099.5"]]}}
1635444236.999735: {"type":"channel_data","connection_id":"60a4fc71-1312-4830-86f4-9eb98be106ac","message_id":1153,"id":"UMA-USD","channel":"v3_orderbook","contents":{"offset":"2693991288","bids":[],"asks":[["11.33","28202.6"]]}}
1635444237.010587: {"type":"channel_data","connection_id":"60a4fc71-1312-4830-86f4-9eb98be106ac","message_id":1154,"id":"SUSHI-USD","channel":"v3_orderbook","contents":{"offset":"2693991295","bids":[["10.77","0"]],"asks":[]}}
1635444237.0162282: {"type":"channel_data","connection_id":"60a4fc71-1312-4830-86f4-9eb98be106ac","message_id":1155,"id":"SUSHI-USD","channel":"v3_orderbook","contents":{"offset":"2693991296","bids":[["10.79","185.4"]],"asks":[]}}
1635444237.016299: {"type":"channel_data","connection_id":"60a4fc71-1312-4830-86f4-9eb98be106ac","message_id":1156,"id":"UNI-USD","channel":"v3_orderbook","contents":{"offset":"2693991297","bids":[],"asks":[["25.068","399.5"]]}}
1635444237.025619: {"type":"channel_data","connection_id":"60a4fc71-1312-4830-86f4-9eb98be106ac","message_id":1157,"id":"SUSHI-USD","channel":"v3_orderbook","contents":{"offset":"2693991302","bids":[["10.767","4130.4"]],"asks":[]}}
1635444237.038669: {"type":"channel_data","connection_id":"60a4fc71-1312-4830-86f4-9eb98be106ac","message_id":1158,"id":"SUSHI-USD","channel":"v3_orderbook","contents":{"offset":"2693991308","bids":[],"asks":[["10.798","11709.2"]]}}
1635444237.0493839: {"type":"channel_data","connection_id":"60a4fc71-1312-4830-86f4-9eb98be106ac","message_id":1159,"id":"UNI-USD","channel":"v3_orderbook","contents":{"offset":"2693991315","bids":[],"asks":[["25.068","0"]]}}
1635444237.078779: {"type":"channel_data","connection_id":"60a4fc71-1312-4830-86f4-9eb98be106ac","message_id":1160,"id":"ETH-USD","channel":"v3_orderbook","contents":{"offset":"2693991320","bids":[],"asks":[["4216.1","149.306"]]}}
1635444237.083553: {"type":"channel_data","connection_id":"60a4fc71-1312-4830-86f4-9eb98be106ac","message_id":1161,"id":"ETH-USD","channel":"v3_orderbook","contents":{"offset":"2693991329","bids":[],"asks":[["4216.1","125.57"]]}}
1635444237.113098: {"type":"channel_data","connection_id":"60a4fc71-1312-4830-86f4-9eb98be106ac","message_id":1162,"id":"UNI-USD","channel":"v3_orderbook","contents":{"offset":"2693991346","bids":[],"asks":[["25.053","35011.3"]]}}
1635444237.132787: {"type":"channel_data","connection_id":"60a4fc71-1312-4830-86f4-9eb98be106ac","message_id":1163,"id":"SUSHI-USD","channel":"v3_orderbook","contents":{"offset":"2693991348","bids":[],"asks":[["10.799","138.9"]]}}
1635444237.145677: {"type":"channel_data","connection_id":"60a4fc71-1312-4830-86f4-9eb98be106ac","message_id":1164,"id":"ETH-USD","channel":"v3_orderbook","contents":{"offset":"2693991351","bids":[],"asks":[["4216.1","149.306"]]}}
1635444237.155179: {"type":"channel_data","connection_id":"60a4fc71-1312-4830-86f4-9eb98be106ac","message_id":1165,"id":"XMR-USD","channel":"v3_orderbook","contents":{"offset":"2693991357","bids":[],"asks":[["265.3","75.39"]]}}
1635444237.165849: {"type":"channel_data","connection_id":"60a4fc71-1312-4830-86f4-9eb98be106ac","message_id":1166,"id":"UNI-USD","channel":"v3_orderbook","contents":{"offset":"2693991358","bids":[],"asks":[["25.068","399.5"]]}}
1635444237.1789691: {"type":"channel_data","connection_id":"60a4fc71-1312-4830-86f4-9eb98be106ac","message_id":1167,"id":"ETH-USD","channel":"v3_orderbook","contents":{"offset":"2693991364","bids":[],"asks":[["4216.1","125.57"]]}}
1635444237.189457: {"type":"channel_data","connection_id":"60a4fc71-1312-4830-86f4-9eb98be106ac","message_id":1168,"id":"UNI-USD","channel":"v3_orderbook","contents":{"offset":"2693991372","bids":[],"asks":[["25.068","0"]]}}
1635444237.21489: {"type":"channel_data","connection_id":"60a4fc71-1312-4830-86f4-9eb98be106ac","message_id":1169,"id":"UMA-USD","channel":"v3_orderbook","contents":{"offset":"2693991379","bids":[],"asks":[["11.33","23786.7"]]}}
1635444237.228075: {"type":"channel_data","connection_id":"60a4fc71-1312-4830-86f4-9eb98be106ac","message_id":1170,"id":"UMA-USD","channel":"v3_orderbook","contents":{"offset":"2693991385","bids":[],"asks":[["11.33","1683.6"]]}}
1635444237.228192: {"type":"channel_data","connection_id":"60a4fc71-1312-4830-86f4-9eb98be106ac","message_id":1171,"id":"ETH-USD","channel":"v3_orderbook","contents":{"offset":"2693991391","bids":[],"asks":[["4216.1","149.306"]]}}
1635444237.231061: {"type":"channel_data","connection_id":"60a4fc71-1312-4830-86f4-9eb98be106ac","message_id":1172,"id":"UNI-USD","channel":"v3_orderbook","contents":{"offset":"2693991390","bids":[],"asks":[["25.068","399.5"]]}}
1635444237.2391481: {"type":"channel_data","connection_id":"60a4fc71-1312-4830-86f4-9eb98be106ac","message_id":1173,"id":"SUSHI-USD","channel":"v3_orderbook","contents":{"offset":"2693991394","bids":[["10.789","1209.2"]],"asks":[]}}
1635444237.23923: {"type":"channel_data","connection_id":"60a4fc71-1312-4830-86f4-9eb98be106ac","message_id":1174,"id":"UMA-USD","channel":"v3_orderbook","contents":{"offset":"2693991392","bids":[["11.27","29416.2"]],"asks":[]}}
1635444237.250706: {"type":"channel_data","connection_id":"60a4fc71-1312-4830-86f4-9eb98be106ac","message_id":1175,"id":"SUSHI-USD","channel":"v3_orderbook","contents":{"offset":"2693991400","bids":[],"asks":[["10.797","4451.7"]]}}
1635444237.250786: {"type":"channel_data","connection_id":"60a4fc71-1312-4830-86f4-9eb98be106ac","message_id":1176,"id":"UNI-USD","channel":"v3_orderbook","contents":{"offset":"2693991401","bids":[],"asks":[["25.068","0"]]}}
1635444237.2655702: {"type":"channel_data","connection_id":"60a4fc71-1312-4830-86f4-9eb98be106ac","message_id":1177,"id":"UMA-USD","channel":"v3_orderbook","contents":{"offset":"2693991403","bids":[["11.27","29150.7"]],"asks":[]}}
1635444237.26565: {"type":"channel_data","connection_id":"60a4fc71-1312-4830-86f4-9eb98be106ac","message_id":1178,"id":"SUSHI-USD","channel":"v3_orderbook","contents":{"offset":"2693991405","bids":[["10.786","12047.6"]],"asks":[]}}
1635444237.273216: {"type":"channel_data","connection_id":"60a4fc71-1312-4830-86f4-9eb98be106ac","message_id":1179,"id":"SUSHI-USD","channel":"v3_orderbook","contents":{"offset":"2693991406","bids":[],"asks":[["10.921","927.3"]]}}
1635444237.291256: {"type":"channel_data","connection_id":"60a4fc71-1312-4830-86f4-9eb98be106ac","message_id":1180,"id":"ETH-USD","channel":"v3_orderbook","contents":{"offset":"2693991409","bids":[],"asks":[["4216.1","125.57"]]}}
1635444237.316046: {"type":"channel_data","connection_id":"60a4fc71-1312-4830-86f4-9eb98be106ac","message_id":1181,"id":"UNI-USD","channel":"v3_orderbook","contents":{"offset":"2693991419","bids":[],"asks":[["25.068","399.5"]]}}
1635444237.347646: {"type":"channel_data","connection_id":"60a4fc71-1312-4830-86f4-9eb98be106ac","message_id":1182,"id":"SUSHI-USD","channel":"v3_orderbook","contents":{"offset":"2693991431","bids":[["10.736","0"],["10.735","3247.6"]],"asks":[]}}
1635444237.347735: {"type":"channel_data","connection_id":"60a4fc71-1312-4830-86f4-9eb98be106ac","message_id":1183,"id":"SUSHI-USD","channel":"v3_orderbook","contents":{"offset":"2693991434","bids":[["10.779","727.2"]],"asks":[]}}
1635444237.351818: {"type":"channel_data","connection_id":"60a4fc71-1312-4830-86f4-9eb98be106ac","message_id":1184,"id":"UMA-USD","channel":"v3_orderbook","contents":{"offset":"2693991428","bids":[],"asks":[["11.33","23786.7"]]}}
1635444237.3541691: {"type":"channel_data","connection_id":"60a4fc71-1312-4830-86f4-9eb98be106ac","message_id":1185,"id":"UNI-USD","channel":"v3_orderbook","contents":{"offset":"2693991430","bids":[],"asks":[["25.068","0"]]}}
1635444237.3542242: {"type":"channel_data","connection_id":"60a4fc71-1312-4830-86f4-9eb98be106ac","message_id":1186,"id":"XMR-USD","channel":"v3_orderbook","contents":{"offset":"2693991436","bids":[["264","0"]],"asks":[]}}
1635444237.354254: {"type":"channel_data","connection_id":"60a4fc71-1312-4830-86f4-9eb98be106ac","message_id":1187,"id":"SUSHI-USD","channel":"v3_orderbook","contents":{"offset":"2693991437","bids":[["10.725","0"],["10.724","3247.6"]],"asks":[]}}
1635444237.3542862: {"type":"channel_data","connection_id":"60a4fc71-1312-4830-86f4-9eb98be106ac","message_id":1188,"id":"ETH-USD","channel":"v3_orderbook","contents":{"offset":"2693991438","bids":[],"asks":[["4216.2","23.735"]]}}
1635444237.359902: {"type":"channel_data","connection_id":"60a4fc71-1312-4830-86f4-9eb98be106ac","message_id":1189,"id":"XMR-USD","channel":"v3_orderbook","contents":{"offset":"2693991442","bids":[],"asks":[["265.9","1057.15"]]}}
1635444237.359963: {"type":"channel_data","connection_id":"60a4fc71-1312-4830-86f4-9eb98be106ac","message_id":1190,"id":"ETH-USD","channel":"v3_orderbook","contents":{"offset":"2693991444","bids":[["4212.6","0"]],"asks":[]}}
1635444237.364392: {"type":"channel_data","connection_id":"60a4fc71-1312-4830-86f4-9eb98be106ac","message_id":1191,"id":"MKR-USD","channel":"v3_orderbook","contents":{"offset":"2693991441","bids":[["2380","27.508"]],"asks":[]}}
1635444237.364477: {"type":"channel_data","connection_id":"60a4fc71-1312-4830-86f4-9eb98be106ac","message_id":1192,"id":"UMA-USD","channel":"v3_orderbook","contents":{"offset":"2693991446","bids":[],"asks":[["11.33","1683.6"]]}}
1635444237.3753998: {"type":"channel_data","connection_id":"60a4fc71-1312-4830-86f4-9eb98be106ac","message_id":1193,"id":"MKR-USD","channel":"v3_orderbook","contents":{"offset":"2693991448","bids":[["2381","10.288"]],"asks":[]}}
1635444237.389508: {"type":"channel_data","connection_id":"60a4fc71-1312-4830-86f4-9eb98be106ac","message_id":1194,"id":"ETH-USD","channel":"v3_orderbook","contents":{"offset":"2693991452","bids":[],"asks":[["4216.2","0"]]}}
1635444237.38958: {"type":"channel_data","connection_id":"60a4fc71-1312-4830-86f4-9eb98be106ac","message_id":1195,"id":"SUSHI-USD","channel":"v3_orderbook","contents":{"offset":"2693991456","bids":[],"asks":[["10.803","822.5"]]}}
1635444237.408169: {"type":"channel_data","connection_id":"60a4fc71-1312-4830-86f4-9eb98be106ac","message_id":1196,"id":"ETH-USD","channel":"v3_orderbook","contents":{"offset":"2693991458","bids":[],"asks":[["4217.2","22.496"]]}}
1635444237.40824: {"type":"channel_data","connection_id":"60a4fc71-1312-4830-86f4-9eb98be106ac","message_id":1197,"id":"ETH-USD","channel":"v3_orderbook","contents":{"offset":"2693991460","bids":[],"asks":[["4217.4","50.564"]]}}
1635444237.408268: {"type":"channel_data","connection_id":"60a4fc71-1312-4830-86f4-9eb98be106ac","message_id":1198,"id":"UMA-USD","channel":"v3_orderbook","contents":{"offset":"2693991459","bids":[],"asks":[["11.33","6099.4"]]}}
1635444237.408292: {"type":"channel_data","connection_id":"60a4fc71-1312-4830-86f4-9eb98be106ac","message_id":1199,"id":"XMR-USD","channel":"v3_orderbook","contents":{"offset":"2693991457","bids":[["265","0"]],"asks":[]}}
1635444237.412538: {"type":"channel_data","connection_id":"60a4fc71-1312-4830-86f4-9eb98be106ac","message_id":1200,"id":"SUSHI-USD","channel":"v3_orderbook","contents":{"offset":"2693991463","bids":[["10.767","416.5"]],"asks":[]}}
1635444237.4125938: {"type":"channel_data","connection_id":"60a4fc71-1312-4830-86f4-9eb98be106ac","message_id":1201,"id":"ETH-USD","channel":"v3_orderbook","contents":{"offset":"2693991462","bids":[["4213.4","0"]],"asks":[]}}
1635444237.429417: {"type":"channel_data","connection_id":"60a4fc71-1312-4830-86f4-9eb98be106ac","message_id":1202,"id":"UNI-USD","channel":"v3_orderbook","contents":{"offset":"2693991464","bids":[],"asks":[["25.068","399.5"]]}}
1635444237.4328551: {"type":"channel_data","connection_id":"60a4fc71-1312-4830-86f4-9eb98be106ac","message_id":1203,"id":"ETH-USD","channel":"v3_orderbook","contents":{"offset":"2693991467","bids":[["4213.6","13.206"]],"asks":[]}}
1635444237.435891: {"type":"channel_data","connection_id":"60a4fc71-1312-4830-86f4-9eb98be106ac","message_id":1204,"id":"MKR-USD","channel":"v3_orderbook","contents":{"offset":"2693991472","bids":[["2379","109.889"]],"asks":[]}}
1635444237.439965: {"type":"channel_data","connection_id":"60a4fc71-1312-4830-86f4-9eb98be106ac","message_id":1205,"id":"UNI-USD","channel":"v3_orderbook","contents":{"offset":"2693991479","bids":[],"asks":[["25.068","0"]]}}
1635444237.44002: {"type":"channel_data","connection_id":"60a4fc71-1312-4830-86f4-9eb98be106ac","message_id":1206,"id":"ETH-USD","channel":"v3_orderbook","contents":{"offset":"2693991474","bids":[],"asks":[["4216.2","23.735"]]}}
1635444237.441334: {"type":"channel_data","connection_id":"60a4fc71-1312-4830-86f4-9eb98be106ac","message_id":1207,"id":"UNI-USD","channel":"v3_orderbook","contents":{"offset":"2693991476","bids":[["24.876","1997.7"],["24.875","0"]],"asks":[]}}
1635444237.4415748: {"type":"channel_data","connection_id":"60a4fc71-1312-4830-86f4-9eb98be106ac","message_id":1208,"id":"SUSHI-USD","channel":"v3_orderbook","contents":{"offset":"2693991481","bids":[["10.772","12302.3"]],"asks":[]}}
1635444237.444267: {"type":"channel_data","connection_id":"60a4fc71-1312-4830-86f4-9eb98be106ac","message_id":1209,"id":"UNI-USD","channel":"v3_orderbook","contents":{"offset":"2693991478","bids":[["24.901","1997.7"],["24.9","0"]],"asks":[]}}
1635444237.446582: {"type":"channel_data","connection_id":"60a4fc71-1312-4830-86f4-9eb98be106ac","message_id":1210,"id":"SUSHI-USD","channel":"v3_orderbook","contents":{"offset":"2693991482","bids":[],"asks":[["10.806","3743.9"]]}}
1635444237.450058: {"type":"channel_data","connection_id":"60a4fc71-1312-4830-86f4-9eb98be106ac","message_id":1211,"id":"SUSHI-USD","channel":"v3_orderbook","contents":{"offset":"2693991487","bids":[["10.78","14518.1"]],"asks":[]}}
1635444237.450119: {"type":"channel_data","connection_id":"60a4fc71-1312-4830-86f4-9eb98be106ac","message_id":1212,"id":"SUSHI-USD","channel":"v3_orderbook","contents":{"offset":"2693991484","bids":[["10.775","0"]],"asks":[]}}
1635444237.45364: {"type":"channel_data","connection_id":"60a4fc71-1312-4830-86f4-9eb98be106ac","message_id":1213,"id":"MKR-USD","channel":"v3_orderbook","contents":{"offset":"2693991485","bids":[["2373","1.685"]],"asks":[]}}
1635444237.4601018: {"type":"channel_data","connection_id":"60a4fc71-1312-4830-86f4-9eb98be106ac","message_id":1214,"id":"ETH-USD","channel":"v3_orderbook","contents":{"offset":"2693991490","bids":[],"asks":[["4216.2","0"]]}}
1635444237.460803: {"type":"channel_data","connection_id":"60a4fc71-1312-4830-86f4-9eb98be106ac","message_id":1215,"id":"SUSHI-USD","channel":"v3_orderbook","contents":{"offset":"2693991489","bids":[["10.786","8045.3"]],"asks":[]}}
1635444237.46086: {"type":"channel_data","connection_id":"60a4fc71-1312-4830-86f4-9eb98be106ac","message_id":1216,"id":"ETH-USD","channel":"v3_orderbook","contents":{"offset":"2693991488","bids":[["4213.1","1925.19"]],"asks":[]}}
1635444237.478314: {"type":"channel_data","connection_id":"60a4fc71-1312-4830-86f4-9eb98be106ac","message_id":1217,"id":"XMR-USD","channel":"v3_orderbook","contents":{"offset":"2693991492","bids":[],"asks":[["266","88.86"],["266.1","4.53"]]}}
1635444237.487753: {"type":"channel_data","connection_id":"60a4fc71-1312-4830-86f4-9eb98be106ac","message_id":1218,"id":"SUSHI-USD","channel":"v3_orderbook","contents":{"offset":"2693991498","bids":[],"asks":[["10.801","0"]]}}
1635444237.487824: {"type":"channel_data","connection_id":"60a4fc71-1312-4830-86f4-9eb98be106ac","message_id":1219,"id":"UMA-USD","channel":"v3_orderbook","contents":{"offset":"2693991495","bids":[["11.27","29416.2"]],"asks":[]}}
1635444237.4892612: {"type":"channel_data","connection_id":"60a4fc71-1312-4830-86f4-9eb98be106ac","message_id":1220,"id":"XMR-USD","channel":"v3_orderbook","contents":{"offset":"2693991494","bids":[["264.1","70"],["264","18.86"]],"asks":[]}}
1635444237.4981241: {"type":"channel_data","connection_id":"60a4fc71-1312-4830-86f4-9eb98be106ac","message_id":1221,"id":"CRV-USD","channel":"v3_orderbook","contents":{"offset":"2693991500","bids":[],"asks":[["4.862","1209"]]}}
1635444237.4982011: {"type":"channel_data","connection_id":"60a4fc71-1312-4830-86f4-9eb98be106ac","message_id":1222,"id":"ETH-USD","channel":"v3_orderbook","contents":{"offset":"2693991501","bids":[],"asks":[["4216.2","23.735"]]}}
1635444237.4982378: {"type":"channel_data","connection_id":"60a4fc71-1312-4830-86f4-9eb98be106ac","message_id":1223,"id":"ETH-USD","channel":"v3_orderbook","contents":{"offset":"2693991502","bids":[["4213.1","1898.821"]],"asks":[]}}
1635444237.518107: {"type":"channel_data","connection_id":"60a4fc71-1312-4830-86f4-9eb98be106ac","message_id":1224,"id":"XMR-USD","channel":"v3_orderbook","contents":{"offset":"2693991506","bids":[["264.9","75.75"]],"asks":[]}}
1635444237.518189: {"type":"channel_data","connection_id":"60a4fc71-1312-4830-86f4-9eb98be106ac","message_id":1225,"id":"UMA-USD","channel":"v3_orderbook","contents":{"offset":"2693991504","bids":[["11.27","29150.7"]],"asks":[]}}
1635444237.518225: {"type":"channel_data","connection_id":"60a4fc71-1312-4830-86f4-9eb98be106ac","message_id":1226,"id":"ETH-USD","channel":"v3_orderbook","contents":{"offset":"2693991505","bids":[],"asks":[["4216.2","0"]]}}
1635444237.52923: {"type":"channel_data","connection_id":"60a4fc71-1312-4830-86f4-9eb98be106ac","message_id":1227,"id":"UMA-USD","channel":"v3_orderbook","contents":{"offset":"2693991508","bids":[],"asks":[["11.33","28202.5"]]}}
1635444237.5400581: {"type":"channel_data","connection_id":"60a4fc71-1312-4830-86f4-9eb98be106ac","message_id":1228,"id":"SUSHI-USD","channel":"v3_orderbook","contents":{"offset":"2693991511","bids":[["10.776","487"]],"asks":[]}}
1635444237.555549: {"type":"channel_data","connection_id":"60a4fc71-1312-4830-86f4-9eb98be106ac","message_id":1229,"id":"ETH-USD","channel":"v3_orderbook","contents":{"offset":"2693991513","bids":[],"asks":[["4216","57.11"]]}}
1635444237.56452: {"type":"channel_data","connection_id":"60a4fc71-1312-4830-86f4-9eb98be106ac","message_id":1230,"id":"ETH-USD","channel":"v3_trades","contents":{"trades":[{"size":"0.1","side":"BUY","price":"4216","createdAt":"2021-10-28T18:03:57.593Z"}]}}
1635444237.565102: {"type":"channel_data","connection_id":"60a4fc71-1312-4830-86f4-9eb98be106ac","message_id":1231,"id":"XMR-USD","channel":"v3_orderbook","contents":{"offset":"2693991515","bids":[["265","75.47"]],"asks":[]}}
1635444237.5756009: {"type":"channel_data","connection_id":"60a4fc71-1312-4830-86f4-9eb98be106ac","message_id":1232,"id":"UNI-USD","channel":"v3_orderbook","contents":{"offset":"2693991519","bids":[],"asks":[["25.068","399.5"]]}}
1635444237.575684: {"type":"channel_data","connection_id":"60a4fc71-1312-4830-86f4-9eb98be106ac","message_id":1233,"id":"ETH-USD","channel":"v3_orderbook","contents":{"offset":"2693991522","bids":[],"asks":[["4216.2","23.735"]]}}
1635444237.579453: {"type":"channel_data","connection_id":"60a4fc71-1312-4830-86f4-9eb98be106ac","message_id":1234,"id":"UNI-USD","channel":"v3_orderbook","contents":{"offset":"2693991518","bids":[],"asks":[["25.077","0"]]}}
1635444237.6016052: {"type":"channel_data","connection_id":"60a4fc71-1312-4830-86f4-9eb98be106ac","message_id":1235,"id":"UNI-USD","channel":"v3_orderbook","contents":{"offset":"2693991523","bids":[],"asks":[["25.087","1585.8"]]}}
1635444237.601686: {"type":"channel_data","connection_id":"60a4fc71-1312-4830-86f4-9eb98be106ac","message_id":1236,"id":"ETH-USD","channel":"v3_orderbook","contents":{"offset":"2693991526","bids":[],"asks":[["4217.4","40.78"]]}}
1635444237.601744: {"type":"channel_data","connection_id":"60a4fc71-1312-4830-86f4-9eb98be106ac","message_id":1237,"id":"MKR-USD","channel":"v3_orderbook","contents":{"offset":"2693991530","bids":[],"asks":[["2402","58.47"],["2403","16.457"]]}}
1635444237.601772: {"type":"channel_data","connection_id":"60a4fc71-1312-4830-86f4-9eb98be106ac","message_id":1238,"id":"UNI-USD","channel":"v3_orderbook","contents":{"offset":"2693991532","bids":[],"asks":[["25.068","0"]]}}
1635444237.601795: {"type":"channel_data","connection_id":"60a4fc71-1312-4830-86f4-9eb98be106ac","message_id":1239,"id":"ETH-USD","channel":"v3_orderbook","contents":{"offset":"2693991531","bids":[["4212.6","32.201"]],"asks":[]}}
1635444237.606796: {"type":"channel_data","connection_id":"60a4fc71-1312-4830-86f4-9eb98be106ac","message_id":1240,"id":"ETH-USD","channel":"v3_orderbook","contents":{"offset":"2693991533","bids":[],"asks":[["4216.2","0"]]}}
1635444237.6068869: {"type":"channel_data","connection_id":"60a4fc71-1312-4830-86f4-9eb98be106ac","message_id":1241,"id":"ETH-USD","channel":"v3_orderbook","contents":{"offset":"2693991534","bids":[["4213.6","5.991"]],"asks":[]}}
1635444237.628532: {"type":"channel_data","connection_id":"60a4fc71-1312-4830-86f4-9eb98be106ac","message_id":1242,"id":"ETH-USD","channel":"v3_orderbook","contents":{"offset":"2693991543","bids":[["4210","0.01"]],"asks":[]}}
1635444237.628646: {"type":"channel_data","connection_id":"60a4fc71-1312-4830-86f4-9eb98be106ac","message_id":1243,"id":"ETH-USD","channel":"v3_orderbook","contents":{"offset":"2693991541","bids":[],"asks":[["4222.2","0"]]}}
1635444237.631458: {"type":"channel_data","connection_id":"60a4fc71-1312-4830-86f4-9eb98be106ac","message_id":1244,"id":"SUSHI-USD","channel":"v3_orderbook","contents":{"offset":"2693991542","bids":[["10.772","8588.4"]],"asks":[]}}
1635444237.639864: {"type":"channel_data","connection_id":"60a4fc71-1312-4830-86f4-9eb98be106ac","message_id":1245,"id":"SUSHI-USD","channel":"v3_orderbook","contents":{"offset":"2693991546","bids":[["10.771","440.6"]],"asks":[]}}
1635444237.639925: {"type":"channel_data","connection_id":"60a4fc71-1312-4830-86f4-9eb98be106ac","message_id":1246,"id":"SUSHI-USD","channel":"v3_orderbook","contents":{"offset":"2693991545","bids":[["10.768","3967.1"]],"asks":[]}}
1635444237.6407979: {"type":"channel_data","connection_id":"60a4fc71-1312-4830-86f4-9eb98be106ac","message_id":1247,"id":"ETH-USD","channel":"v3_orderbook","contents":{"offset":"2693991544","bids":[["4213.7","7.215"]],"asks":[]}}
1635444237.652734: {"type":"channel_data","connection_id":"60a4fc71-1312-4830-86f4-9eb98be106ac","message_id":1248,"id":"XMR-USD","channel":"v3_orderbook","contents":{"offset":"2693991547","bids":[["265","0"]],"asks":[]}}
1635444237.6527948: {"type":"channel_data","connection_id":"60a4fc71-1312-4830-86f4-9eb98be106ac","message_id":1249,"id":"ETH-USD","channel":"v3_orderbook","contents":{"offset":"2693991549","bids":[],"asks":[["4217.5","11.042"]]}}
1635444237.652832: {"type":"channel_data","connection_id":"60a4fc71-1312-4830-86f4-9eb98be106ac","message_id":1250,"id":"ETH-USD","channel":"v3_orderbook","contents":{"offset":"2693991550","bids":[],"asks":[["4216.2","23.735"]]}}
1635444237.66453: {"type":"channel_data","connection_id":"60a4fc71-1312-4830-86f4-9eb98be106ac","message_id":1251,"id":"UNI-USD","channel":"v3_orderbook","contents":{"offset":"2693991554","bids":[["25.009","0"]],"asks":[]}}
1635444237.6650538: {"type":"channel_data","connection_id":"60a4fc71-1312-4830-86f4-9eb98be106ac","message_id":1252,"id":"MKR-USD","channel":"v3_orderbook","contents":{"offset":"2693991555","bids":[["2379","108.68"]],"asks":[]}}
1635444237.666712: {"type":"channel_data","connection_id":"60a4fc71-1312-4830-86f4-9eb98be106ac","message_id":1253,"id":"XMR-USD","channel":"v3_orderbook","contents":{"offset":"2693991553","bids":[["264","63.86"]],"asks":[]}}
1635444237.666794: {"type":"channel_data","connection_id":"60a4fc71-1312-4830-86f4-9eb98be106ac","message_id":1254,"id":"UNI-USD","channel":"v3_orderbook","contents":{"offset":"2693991552","bids":[],"asks":[["25.068","399.5"]]}}
1635444237.675232: {"type":"channel_data","connection_id":"60a4fc71-1312-4830-86f4-9eb98be106ac","message_id":1255,"id":"ETH-USD","channel":"v3_orderbook","contents":{"offset":"2693991559","bids":[],"asks":[["4216.2","0"]]}}
1635444237.6919382: {"type":"channel_data","connection_id":"60a4fc71-1312-4830-86f4-9eb98be106ac","message_id":1256,"id":"UNI-USD","channel":"v3_orderbook","contents":{"offset":"2693991562","bids":[["25.019","1585.8"]],"asks":[]}}
1635444237.6920478: {"type":"channel_data","connection_id":"60a4fc71-1312-4830-86f4-9eb98be106ac","message_id":1257,"id":"ETH-USD","channel":"v3_orderbook","contents":{"offset":"2693991561","bids":[],"asks":[["4219","25.662"]]}}
1635444237.6982741: {"type":"channel_data","connection_id":"60a4fc71-1312-4830-86f4-9eb98be106ac","message_id":1258,"id":"UNI-USD","channel":"v3_orderbook","contents":{"offset":"2693991565","bids":[],"asks":[["25.068","0"]]}}
1635444237.7106152: {"type":"channel_data","connection_id":"60a4fc71-1312-4830-86f4-9eb98be106ac","message_id":1259,"id":"ETH-USD","channel":"v3_orderbook","contents":{"offset":"2693991567","bids":[["4213.4","7.216"]],"asks":[]}}
1635444237.710701: {"type":"channel_data","connection_id":"60a4fc71-1312-4830-86f4-9eb98be106ac","message_id":1260,"id":"ETH-USD","channel":"v3_orderbook","contents":{"offset":"2693991569","bids":[["4213.7","0"]],"asks":[]}}
1635444237.724728: {"type":"channel_data","connection_id":"60a4fc71-1312-4830-86f4-9eb98be106ac","message_id":1261,"id":"ETH-USD","channel":"v3_orderbook","contents":{"offset":"2693991574","bids":[],"asks":[["4216.2","23.735"]]}}
1635444237.733313: {"type":"channel_data","connection_id":"60a4fc71-1312-4830-86f4-9eb98be106ac","message_id":1262,"id":"XMR-USD","channel":"v3_orderbook","contents":{"offset":"2693991578","bids":[],"asks":[["265.9","1102.15"]]}}
1635444237.7413068: {"type":"channel_data","connection_id":"60a4fc71-1312-4830-86f4-9eb98be106ac","message_id":1263,"id":"ETH-USD","channel":"v3_orderbook","contents":{"offset":"2693991579","bids":[],"asks":[["4217.2","32.279"]]}}
1635444237.74139: {"type":"channel_data","connection_id":"60a4fc71-1312-4830-86f4-9eb98be106ac","message_id":1264,"id":"ETH-USD","channel":"v3_orderbook","contents":{"offset":"2693991577","bids":[],"asks":[["4217.5","1.258"]]}}
1635444237.7472901: {"type":"channel_data","connection_id":"60a4fc71-1312-4830-86f4-9eb98be106ac","message_id":1265,"id":"ETH-USD","channel":"v3_orderbook","contents":{"offset":"2693991583","bids":[],"asks":[["4216.2","0"]]}}
1635444237.7473722: {"type":"channel_data","connection_id":"60a4fc71-1312-4830-86f4-9eb98be106ac","message_id":1266,"id":"UNI-USD","channel":"v3_orderbook","contents":{"offset":"2693991582","bids":[],"asks":[["25.068","399.5"]]}}
1635444237.759404: {"type":"channel_data","connection_id":"60a4fc71-1312-4830-86f4-9eb98be106ac","message_id":1267,"id":"SUSHI-USD","channel":"v3_orderbook","contents":{"offset":"2693991586","bids":[["10.752","383"],["10.751","1001"]],"asks":[]}}
1635444237.7594922: {"type":"channel_data","connection_id":"60a4fc71-1312-4830-86f4-9eb98be106ac","message_id":1268,"id":"ETH-USD","channel":"v3_orderbook","contents":{"offset":"2693991588","bids":[],"asks":[["4218","62.175"]]}}
1635444237.768233: {"type":"channel_data","connection_id":"60a4fc71-1312-4830-86f4-9eb98be106ac","message_id":1269,"id":"UNI-USD","channel":"v3_orderbook","contents":{"offset":"2693991591","bids":[],"asks":[["25.068","0"]]}}
1635444237.77246: {"type":"channel_data","connection_id":"60a4fc71-1312-4830-86f4-9eb98be106ac","message_id":1270,"id":"UNI-USD","channel":"v3_orderbook","contents":{"offset":"2693991589","bids":[],"asks":[["25.087","0"]]}}
1635444237.772545: {"type":"channel_data","connection_id":"60a4fc71-1312-4830-86f4-9eb98be106ac","message_id":1271,"id":"SUSHI-USD","channel":"v3_orderbook","contents":{"offset":"2693991590","bids":[],"asks":[["10.797","4938.7"]]}}
1635444237.790167: {"type":"channel_data","connection_id":"60a4fc71-1312-4830-86f4-9eb98be106ac","message_id":1272,"id":"UNI-USD","channel":"v3_orderbook","contents":{"offset":"2693991593","bids":[],"asks":[["25.077","1585.8"]]}}
1635444237.7963588: {"type":"channel_data","connection_id":"60a4fc71-1312-4830-86f4-9eb98be106ac","message_id":1273,"id":"SUSHI-USD","channel":"v3_orderbook","contents":{"offset":"2693991599","bids":[],"asks":[["10.832","0"],["10.833","101.9"]]}}
1635444237.7964869: {"type":"channel_data","connection_id":"60a4fc71-1312-4830-86f4-9eb98be106ac","message_id":1274,"id":"ETH-USD","channel":"v3_orderbook","contents":{"offset":"2693991596","bids":[],"asks":[["4216.2","23.735"]]}}
1635444237.796542: {"type":"channel_data","connection_id":"60a4fc71-1312-4830-86f4-9eb98be106ac","message_id":1275,"id":"ETH-USD","channel":"v3_orderbook","contents":{"offset":"2693991600","bids":[],"asks":[["4217.4","50.564"]]}}
1635444237.798502: {"type":"channel_data","connection_id":"60a4fc71-1312-4830-86f4-9eb98be106ac","message_id":1276,"id":"ETH-USD","channel":"v3_orderbook","contents":{"offset":"2693991597","bids":[],"asks":[["4217.2","22.496"]]}}
1635444237.811624: {"type":"channel_data","connection_id":"60a4fc71-1312-4830-86f4-9eb98be106ac","message_id":1277,"id":"ETH-USD","channel":"v3_orderbook","contents":{"offset":"2693991603","bids":[["4213.4","0"]],"asks":[]}}
1635444237.811711: {"type":"channel_data","connection_id":"60a4fc71-1312-4830-86f4-9eb98be106ac","message_id":1278,"id":"ETH-USD","channel":"v3_orderbook","contents":{"offset":"2693991604","bids":[],"asks":[["4216.2","0"]]}}
1635444237.823543: {"type":"channel_data","connection_id":"60a4fc71-1312-4830-86f4-9eb98be106ac","message_id":1279,"id":"XMR-USD","channel":"v3_orderbook","contents":{"offset":"2693991605","bids":[["264.9","151.23"]],"asks":[]}}
1635444237.832053: {"type":"channel_data","connection_id":"60a4fc71-1312-4830-86f4-9eb98be106ac","message_id":1280,"id":"UNI-USD","channel":"v3_orderbook","contents":{"offset":"2693991610","bids":[],"asks":[["25.068","399.5"]]}}
1635444237.832715: {"type":"channel_data","connection_id":"60a4fc71-1312-4830-86f4-9eb98be106ac","message_id":1281,"id":"CRV-USD","channel":"v3_orderbook","contents":{"offset":"2693991608","bids":[["4.841","5267"],["4.839","97700"]],"asks":[]}}
1635444237.8530612: {"type":"channel_data","connection_id":"60a4fc71-1312-4830-86f4-9eb98be106ac","message_id":1282,"id":"ETH-USD","channel":"v3_orderbook","contents":{"offset":"2693991616","bids":[["4213.6","13.206"]],"asks":[]}}
1635444237.854014: {"type":"channel_data","connection_id":"60a4fc71-1312-4830-86f4-9eb98be106ac","message_id":1283,"id":"ETH-USD","channel":"v3_orderbook","contents":{"offset":"2693991613","bids":[["4208.5","102.52"]],"asks":[]}}
1635444237.86358: {"type":"channel_data","connection_id":"60a4fc71-1312-4830-86f4-9eb98be106ac","message_id":1284,"id":"UNI-USD","channel":"v3_orderbook","contents":{"offset":"2693991617","bids":[],"asks":[["25.068","0"]]}}
1635444237.8781052: {"type":"channel_data","connection_id":"60a4fc71-1312-4830-86f4-9eb98be106ac","message_id":1285,"id":"SUSHI-USD","channel":"v3_orderbook","contents":{"offset":"2693991620","bids":[],"asks":[["10.87","2319.7"],["10.871","0"]]}}
1635444237.8781729: {"type":"channel_data","connection_id":"60a4fc71-1312-4830-86f4-9eb98be106ac","message_id":1286,"id":"ETH-USD","channel":"v3_orderbook","contents":{"offset":"2693991619","bids":[],"asks":[["4216.2","23.735"]]}}
1635444237.91201: {"type":"channel_data","connection_id":"60a4fc71-1312-4830-86f4-9eb98be106ac","message_id":1287,"id":"UMA-USD","channel":"v3_orderbook","contents":{"offset":"2693991626","bids":[],"asks":[["11.33","23786.7"]]}}
1635444237.912958: {"type":"channel_data","connection_id":"60a4fc71-1312-4830-86f4-9eb98be106ac","message_id":1288,"id":"UMA-USD","channel":"v3_orderbook","contents":{"offset":"2693991628","bids":[],"asks":[["11.33","1683.6"]]}}
1635444237.924242: {"type":"channel_data","connection_id":"60a4fc71-1312-4830-86f4-9eb98be106ac","message_id":1289,"id":"UMA-USD","channel":"v3_orderbook","contents":{"offset":"2693991631","bids":[],"asks":[["11.32","10825.2"]]}}
1635444237.9251032: {"type":"channel_data","connection_id":"60a4fc71-1312-4830-86f4-9eb98be106ac","message_id":1290,"id":"ETH-USD","channel":"v3_orderbook","contents":{"offset":"2693991629","bids":[],"asks":[["4216.2","0"]]}}
1635444237.925143: {"type":"channel_data","connection_id":"60a4fc71-1312-4830-86f4-9eb98be106ac","message_id":1291,"id":"SUSHI-USD","channel":"v3_orderbook","contents":{"offset":"2693991630","bids":[],"asks":[["10.802","440.6"]]}}
1635444237.936148: {"type":"channel_data","connection_id":"60a4fc71-1312-4830-86f4-9eb98be106ac","message_id":1292,"id":"CRV-USD","channel":"v3_orderbook","contents":{"offset":"2693991639","bids":[],"asks":[["4.873","0"]]}}
1635444237.936204: {"type":"channel_data","connection_id":"60a4fc71-1312-4830-86f4-9eb98be106ac","message_id":1293,"id":"UMA-USD","channel":"v3_orderbook","contents":{"offset":"2693991636","bids":[],"asks":[["11.31","13584.7"]]}}
1635444237.9547782: {"type":"channel_data","connection_id":"60a4fc71-1312-4830-86f4-9eb98be106ac","message_id":1294,"id":"UMA-USD","channel":"v3_orderbook","contents":{"offset":"2693991645","bids":[["11.27","29416.2"]],"asks":[]}}
1635444237.979733: {"type":"channel_data","connection_id":"60a4fc71-1312-4830-86f4-9eb98be106ac","message_id":1295,"id":"ETH-USD","channel":"v3_orderbook","contents":{"offset":"2693991650","bids":[],"asks":[["4216.2","23.735"]]}}
1635444237.9901922: {"type":"channel_data","connection_id":"60a4fc71-1312-4830-86f4-9eb98be106ac","message_id":1296,"id":"UMA-USD","channel":"v3_orderbook","contents":{"offset":"2693991655","bids":[["11.27","29150.7"]],"asks":[]}}
1635444238.0045671: {"type":"channel_data","connection_id":"60a4fc71-1312-4830-86f4-9eb98be106ac","message_id":1297,"id":"ETH-USD","channel":"v3_orderbook","contents":{"offset":"2693991659","bids":[],"asks":[["4216.2","0"]]}}
1635444238.029721: {"type":"channel_data","connection_id":"60a4fc71-1312-4830-86f4-9eb98be106ac","message_id":1298,"id":"UMA-USD","channel":"v3_orderbook","contents":{"offset":"2693991666","bids":[],"asks":[["11.33","23786.7"]]}}
1635444238.034496: {"type":"channel_data","connection_id":"60a4fc71-1312-4830-86f4-9eb98be106ac","message_id":1299,"id":"UNI-USD","channel":"v3_orderbook","contents":{"offset":"2693991664","bids":[],"asks":[["25.068","399.5"]]}}
1635444238.040732: {"type":"channel_data","connection_id":"60a4fc71-1312-4830-86f4-9eb98be106ac","message_id":1300,"id":"UMA-USD","channel":"v3_orderbook","contents":{"offset":"2693991668","bids":[],"asks":[["11.33","28207.3"]]}}
1635444238.043586: {"type":"channel_data","connection_id":"60a4fc71-1312-4830-86f4-9eb98be106ac","message_id":1301,"id":"SUSHI-USD","channel":"v3_orderbook","contents":{"offset":"2693991669","bids":[["10.768","253.2"]],"asks":[]}}
1635444238.0565948: {"type":"channel_data","connection_id":"60a4fc71-1312-4830-86f4-9eb98be106ac","message_id":1302,"id":"UNI-USD","channel":"v3_orderbook","contents":{"offset":"2693991671","bids":[],"asks":[["25.068","0"]]}}
1635444238.059648: {"type":"channel_data","connection_id":"60a4fc71-1312-4830-86f4-9eb98be106ac","message_id":1303,"id":"SUSHI-USD","channel":"v3_orderbook","contents":{"offset":"2693991673","bids":[["10.772","12302.3"]],"asks":[]}}
1635444238.098582: {"type":"channel_data","connection_id":"60a4fc71-1312-4830-86f4-9eb98be106ac","message_id":1304,"id":"ETH-USD","channel":"v3_orderbook","contents":{"offset":"2693991677","bids":[],"asks":[["4216.2","23.735"]]}}
1635444238.107271: {"type":"channel_data","connection_id":"60a4fc71-1312-4830-86f4-9eb98be106ac","message_id":1305,"id":"UNI-USD","channel":"v3_orderbook","contents":{"offset":"2693991680","bids":[],"asks":[["25.068","399.5"]]}}
1635444238.117235: {"type":"channel_data","connection_id":"60a4fc71-1312-4830-86f4-9eb98be106ac","message_id":1306,"id":"ETH-USD","channel":"v3_orderbook","contents":{"offset":"2693991682","bids":[],"asks":[["4216.2","0"]]}}
1635444238.1316102: {"type":"channel_data","connection_id":"60a4fc71-1312-4830-86f4-9eb98be106ac","message_id":1307,"id":"UNI-USD","channel":"v3_orderbook","contents":{"offset":"2693991687","bids":[],"asks":[["25.068","0"]]}}
1635444238.132056: {"type":"channel_data","connection_id":"60a4fc71-1312-4830-86f4-9eb98be106ac","message_id":1308,"id":"CRV-USD","channel":"v3_orderbook","contents":{"offset":"2693991689","bids":[],"asks":[["4.862","657"]]}}
1635444238.141618: {"type":"channel_data","connection_id":"60a4fc71-1312-4830-86f4-9eb98be106ac","message_id":1309,"id":"UNI-USD","channel":"v3_orderbook","contents":{"offset":"2693991692","bids":[["24.864","998.8"],["24.863","0"]],"asks":[]}}
1635444238.1533911: {"type":"channel_data","connection_id":"60a4fc71-1312-4830-86f4-9eb98be106ac","message_id":1310,"id":"SUSHI-USD","channel":"v3_orderbook","contents":{"offset":"2693991697","bids":[],"asks":[["10.802","813.3"]]}}
1635444238.168836: {"type":"channel_data","connection_id":"60a4fc71-1312-4830-86f4-9eb98be106ac","message_id":1311,"id":"SUSHI-USD","channel":"v3_orderbook","contents":{"offset":"2693991700","bids":[["10.784","8827.3"]],"asks":[]}}
1635444238.1758258: {"type":"channel_data","connection_id":"60a4fc71-1312-4830-86f4-9eb98be106ac","message_id":1312,"id":"UNI-USD","channel":"v3_orderbook","contents":{"offset":"2693991706","bids":[],"asks":[["25.068","399.5"]]}}
1635444238.178647: {"type":"channel_data","connection_id":"60a4fc71-1312-4830-86f4-9eb98be106ac","message_id":1313,"id":"MKR-USD","channel":"v3_orderbook","contents":{"offset":"2693991704","bids":[["2376","2096.031"]],"asks":[]}}
1635444238.178726: {"type":"channel_data","connection_id":"60a4fc71-1312-4830-86f4-9eb98be106ac","message_id":1314,"id":"MKR-USD","channel":"v3_orderbook","contents":{"offset":"2693991705","bids":[["2379","110.007"]],"asks":[]}}
1635444238.186332: {"type":"channel_data","connection_id":"60a4fc71-1312-4830-86f4-9eb98be106ac","message_id":1315,"id":"ETH-USD","channel":"v3_orderbook","contents":{"offset":"2693991712","bids":[],"asks":[["4216.5","67.388"]]}}
1635444238.199808: {"type":"channel_data","connection_id":"60a4fc71-1312-4830-86f4-9eb98be106ac","message_id":1316,"id":"UNI-USD","channel":"v3_orderbook","contents":{"offset":"2693991715","bids":[],"asks":[["25.068","0"]]}}
1635444238.199893: {"type":"channel_data","connection_id":"60a4fc71-1312-4830-86f4-9eb98be106ac","message_id":1317,"id":"ETH-USD","channel":"v3_orderbook","contents":{"offset":"2693991717","bids":[],"asks":[["4216.2","23.735"]]}}
1635444238.228433: {"type":"channel_data","connection_id":"60a4fc71-1312-4830-86f4-9eb98be106ac","message_id":1318,"id":"ETH-USD","channel":"v3_orderbook","contents":{"offset":"2693991727","bids":[["4213.6","5.991"]],"asks":[]}}
1635444238.230106: {"type":"channel_data","connection_id":"60a4fc71-1312-4830-86f4-9eb98be106ac","message_id":1319,"id":"ETH-USD","channel":"v3_orderbook","contents":{"offset":"2693991728","bids":[],"asks":[["4217.4","40.78"]]}}
1635444238.241073: {"type":"channel_data","connection_id":"60a4fc71-1312-4830-86f4-9eb98be106ac","message_id":1320,"id":"ETH-USD","channel":"v3_orderbook","contents":{"offset":"2693991730","bids":[["4213.7","7.215"]],"asks":[]}}
1635444238.241138: {"type":"channel_data","connection_id":"60a4fc71-1312-4830-86f4-9eb98be106ac","message_id":1321,"id":"ETH-USD","channel":"v3_orderbook","contents":{"offset":"2693991731","bids":[],"asks":[["4217.5","11.042"]]}}
1635444238.241715: {"type":"channel_data","connection_id":"60a4fc71-1312-4830-86f4-9eb98be106ac","message_id":1322,"id":"SUSHI-USD","channel":"v3_orderbook","contents":{"offset":"2693991736","bids":[["10.786","7710.6"]],"asks":[]}}
1635444238.242746: {"type":"channel_data","connection_id":"60a4fc71-1312-4830-86f4-9eb98be106ac","message_id":1323,"id":"ETH-USD","channel":"v3_orderbook","contents":{"offset":"2693991729","bids":[],"asks":[["4216.2","0"]]}}
1635444238.251858: {"type":"channel_data","connection_id":"60a4fc71-1312-4830-86f4-9eb98be106ac","message_id":1324,"id":"SUSHI-USD","channel":"v3_orderbook","contents":{"offset":"2693991737","bids":[],"asks":[["10.795","4451.7"]]}}
1635444238.271725: {"type":"channel_data","connection_id":"60a4fc71-1312-4830-86f4-9eb98be106ac","message_id":1325,"id":"UNI-USD","channel":"v3_orderbook","contents":{"offset":"2693991740","bids":[],"asks":[["25.068","399.5"]]}}
1635444238.271807: {"type":"channel_data","connection_id":"60a4fc71-1312-4830-86f4-9eb98be106ac","message_id":1326,"id":"ETH-USD","channel":"v3_orderbook","contents":{"offset":"2693991741","bids":[["4212.6","0"]],"asks":[]}}
1635444238.2834072: {"type":"channel_data","connection_id":"60a4fc71-1312-4830-86f4-9eb98be106ac","message_id":1327,"id":"SUSHI-USD","channel":"v3_orderbook","contents":{"offset":"2693991748","bids":[["10.789","1543.9"]],"asks":[]}}
1635444238.283526: {"type":"channel_data","connection_id":"60a4fc71-1312-4830-86f4-9eb98be106ac","message_id":1328,"id":"UNI-USD","channel":"v3_orderbook","contents":{"offset":"2693991749","bids":[],"asks":[["25.068","0"]]}}
1635444238.2928529: {"type":"channel_data","connection_id":"60a4fc71-1312-4830-86f4-9eb98be106ac","message_id":1329,"id":"ETH-USD","channel":"v3_orderbook","contents":{"offset":"2693991754","bids":[],"asks":[["4222.1","6.964"]]}}
1635444238.2929358: {"type":"channel_data","connection_id":"60a4fc71-1312-4830-86f4-9eb98be106ac","message_id":1330,"id":"UMA-USD","channel":"v3_orderbook","contents":{"offset":"2693991755","bids":[],"asks":[["11.33","23786.7"]]}}
1635444238.292974: {"type":"channel_data","connection_id":"60a4fc71-1312-4830-86f4-9eb98be106ac","message_id":1331,"id":"UMA-USD","channel":"v3_orderbook","contents":{"offset":"2693991756","bids":[],"asks":[["11.33","1683.6"]]}}
1635444238.293002: {"type":"channel_data","connection_id":"60a4fc71-1312-4830-86f4-9eb98be106ac","message_id":1332,"id":"ETH-USD","channel":"v3_orderbook","contents":{"offset":"2693991753","bids":[["4209.9","0.2"]],"asks":[]}}
1635444238.3038568: {"type":"channel_data","connection_id":"60a4fc71-1312-4830-86f4-9eb98be106ac","message_id":1333,"id":"ETH-USD","channel":"v3_orderbook","contents":{"offset":"2693991762","bids":[],"asks":[["4216.2","23.735"]]}}
1635444238.303939: {"type":"channel_data","connection_id":"60a4fc71-1312-4830-86f4-9eb98be106ac","message_id":1334,"id":"ETH-USD","channel":"v3_orderbook","contents":{"offset":"2693991760","bids":[],"asks":[["4217.5","1.258"]]}}
1635444238.30691: {"type":"channel_data","connection_id":"60a4fc71-1312-4830-86f4-9eb98be106ac","message_id":1335,"id":"UMA-USD","channel":"v3_orderbook","contents":{"offset":"2693991758","bids":[["11.27","29416.1"]],"asks":[]}}
1635444238.313938: {"type":"channel_data","connection_id":"60a4fc71-1312-4830-86f4-9eb98be106ac","message_id":1336,"id":"UMA-USD","channel":"v3_orderbook","contents":{"offset":"2693991764","bids":[["11.27","29150.7"]],"asks":[]}}
1635444238.3260632: {"type":"channel_data","connection_id":"60a4fc71-1312-4830-86f4-9eb98be106ac","message_id":1337,"id":"ETH-USD","channel":"v3_orderbook","contents":{"offset":"2693991770","bids":[["4213.7","0"]],"asks":[]}}
1635444238.328151: {"type":"channel_data","connection_id":"60a4fc71-1312-4830-86f4-9eb98be106ac","message_id":1338,"id":"UNI-USD","channel":"v3_orderbook","contents":{"offset":"2693991772","bids":[["25.036","399.4"]],"asks":[]}}
1635444238.328235: {"type":"channel_data","connection_id":"60a4fc71-1312-4830-86f4-9eb98be106ac","message_id":1339,"id":"ETH-USD","channel":"v3_orderbook","contents":{"offset":"2693991771","bids":[["4213.8","25.905"]],"asks":[]}}
1635444238.3398552: {"type":"channel_data","connection_id":"60a4fc71-1312-4830-86f4-9eb98be106ac","message_id":1340,"id":"ETH-USD","channel":"v3_orderbook","contents":{"offset":"2693991773","bids":[],"asks":[["4217.6","9.784"]]}}
1635444238.3399308: {"type":"channel_data","connection_id":"60a4fc71-1312-4830-86f4-9eb98be106ac","message_id":1341,"id":"UNI-USD","channel":"v3_orderbook","contents":{"offset":"2693991774","bids":[],"asks":[["25.073","399.4"]]}}
1635444238.345762: {"type":"channel_data","connection_id":"60a4fc71-1312-4830-86f4-9eb98be106ac","message_id":1342,"id":"ETH-USD","channel":"v3_orderbook","contents":{"offset":"2693991778","bids":[],"asks":[["4216.2","0"]]}}
1635444238.34588: {"type":"channel_data","connection_id":"60a4fc71-1312-4830-86f4-9eb98be106ac","message_id":1343,"id":"ETH-USD","channel":"v3_orderbook","contents":{"offset":"2693991777","bids":[["4213.1","1925.59"]],"asks":[]}}
1635444238.360476: {"type":"channel_data","connection_id":"60a4fc71-1312-4830-86f4-9eb98be106ac","message_id":1344,"id":"ETH-USD","channel":"v3_orderbook","contents":{"offset":"2693991780","bids":[],"asks":[["4216.8","105.927"]]}}
1635444238.3735712: {"type":"channel_data","connection_id":"60a4fc71-1312-4830-86f4-9eb98be106ac","message_id":1345,"id":"UNI-USD","channel":"v3_orderbook","contents":{"offset":"2693991781","bids":[["25.03","3391.1"]],"asks":[]}}
1635444238.381839: {"type":"channel_data","connection_id":"60a4fc71-1312-4830-86f4-9eb98be106ac","message_id":1346,"id":"UNI-USD","channel":"v3_orderbook","contents":{"offset":"2693991788","bids":[],"asks":[["25.079","399.5"]]}}
1635444238.384026: {"type":"channel_data","connection_id":"60a4fc71-1312-4830-86f4-9eb98be106ac","message_id":1347,"id":"ETH-USD","channel":"v3_orderbook","contents":{"offset":"2693991790","bids":[],"asks":[["4216.2","23.735"]]}}
1635444238.393462: {"type":"channel_data","connection_id":"60a4fc71-1312-4830-86f4-9eb98be106ac","message_id":1348,"id":"ETH-USD","channel":"v3_orderbook","contents":{"offset":"2693991793","bids":[],"asks":[["4217.8","0"]]}}
1635444238.431901: {"type":"channel_data","connection_id":"60a4fc71-1312-4830-86f4-9eb98be106ac","message_id":1349,"id":"UNI-USD","channel":"v3_orderbook","contents":{"offset":"2693991799","bids":[["25.032","59.9"]],"asks":[]}}
1635444238.4362419: {"type":"channel_data","connection_id":"60a4fc71-1312-4830-86f4-9eb98be106ac","message_id":1350,"id":"ETH-USD","channel":"v3_orderbook","contents":{"offset":"2693991797","bids":[],"asks":[["4216.2","0"]]}}
1635444238.43633: {"type":"channel_data","connection_id":"60a4fc71-1312-4830-86f4-9eb98be106ac","message_id":1351,"id":"UNI-USD","channel":"v3_orderbook","contents":{"offset":"2693991798","bids":[["25.032","2896.4"]],"asks":[]}}
1635444238.445343: {"type":"channel_data","connection_id":"60a4fc71-1312-4830-86f4-9eb98be106ac","message_id":1352,"id":"UMA-USD","channel":"v3_orderbook","contents":{"offset":"2693991801","bids":[],"asks":[["11.33","6104.5"]]}}
1635444238.463959: {"type":"channel_data","connection_id":"60a4fc71-1312-4830-86f4-9eb98be106ac","message_id":1353,"id":"UNI-USD","channel":"v3_orderbook","contents":{"offset":"2693991804","bids":[],"asks":[["25.914","0"]]}}
1635444238.464826: {"type":"channel_data","connection_id":"60a4fc71-1312-4830-86f4-9eb98be106ac","message_id":1354,"id":"UNI-USD","channel":"v3_orderbook","contents":{"offset":"2693991803","bids":[["24.161","0"]],"asks":[]}}
1635444238.464876: {"type":"channel_data","connection_id":"60a4fc71-1312-4830-86f4-9eb98be106ac","message_id":1355,"id":"UMA-USD","channel":"v3_orderbook","contents":{"offset":"2693991806","bids":[],"asks":[["11.33","28207.6"]]}}
1635444238.47438: {"type":"channel_data","connection_id":"60a4fc71-1312-4830-86f4-9eb98be106ac","message_id":1356,"id":"MKR-USD","channel":"v3_orderbook","contents":{"offset":"2693991811","bids":[["2380","28.716"]],"asks":[]}}
1635444238.4884422: {"type":"channel_data","connection_id":"60a4fc71-1312-4830-86f4-9eb98be106ac","message_id":1357,"id":"ETH-USD","channel":"v3_orderbook","contents":{"offset":"2693991816","bids":[],"asks":[["4218.1","14.442"]]}}
1635444238.498474: {"type":"channel_data","connection_id":"60a4fc71-1312-4830-86f4-9eb98be106ac","message_id":1358,"id":"ETH-USD","channel":"v3_orderbook","contents":{"offset":"2693991817","bids":[],"asks":[["4216.2","23.735"]]}}
1635444238.529834: {"type":"channel_data","connection_id":"60a4fc71-1312-4830-86f4-9eb98be106ac","message_id":1359,"id":"ETH-USD","channel":"v3_orderbook","contents":{"offset":"2693991822","bids":[],"asks":[["4216.2","0"]]}}
1635444238.538075: {"type":"channel_data","connection_id":"60a4fc71-1312-4830-86f4-9eb98be106ac","message_id":1360,"id":"UNI-USD","channel":"v3_orderbook","contents":{"offset":"2693991826","bids":[["25.032","8037.5"]],"asks":[]}}
1635444238.538135: {"type":"channel_data","connection_id":"60a4fc71-1312-4830-86f4-9eb98be106ac","message_id":1361,"id":"UNI-USD","channel":"v3_orderbook","contents":{"offset":"2693991824","bids":[["25.039","2994.8"]],"asks":[]}}
1635444238.5389628: {"type":"channel_data","connection_id":"60a4fc71-1312-4830-86f4-9eb98be106ac","message_id":1362,"id":"SUSHI-USD","channel":"v3_orderbook","contents":{"offset":"2693991825","bids":[["10.784","4375.6"]],"asks":[]}}
1635444238.580874: {"type":"channel_data","connection_id":"60a4fc71-1312-4830-86f4-9eb98be106ac","message_id":1363,"id":"ETH-USD","channel":"v3_orderbook","contents":{"offset":"2693991831","bids":[],"asks":[["4216.2","23.735"]]}}
1635444238.618146: {"type":"channel_data","connection_id":"60a4fc71-1312-4830-86f4-9eb98be106ac","message_id":1364,"id":"UNI-USD","channel":"v3_orderbook","contents":{"offset":"2693991840","bids":[],"asks":[["25.167","0"],["25.168","1067.1"]]}}
1635444238.618274: {"type":"channel_data","connection_id":"60a4fc71-1312-4830-86f4-9eb98be106ac","message_id":1365,"id":"ETH-USD","channel":"v3_orderbook","contents":{"offset":"2693991837","bids":[],"asks":[["4216.2","0"]]}}
1635444238.618331: {"type":"channel_data","connection_id":"60a4fc71-1312-4830-86f4-9eb98be106ac","message_id":1366,"id":"UNI-USD","channel":"v3_orderbook","contents":{"offset":"2693991838","bids":[],"asks":[["25.192","0"],["25.193","1997.7"]]}}
1635444238.6271071: {"type":"channel_data","connection_id":"60a4fc71-1312-4830-86f4-9eb98be106ac","message_id":1367,"id":"SUSHI-USD","channel":"v3_orderbook","contents":{"offset":"2693991842","bids":[],"asks":[["10.797","487"]]}}
1635444238.652946: {"type":"channel_data","connection_id":"60a4fc71-1312-4830-86f4-9eb98be106ac","message_id":1368,"id":"SUSHI-USD","channel":"v3_orderbook","contents":{"offset":"2693991850","bids":[],"asks":[["10.799","0"]]}}
1635444238.653026: {"type":"channel_data","connection_id":"60a4fc71-1312-4830-86f4-9eb98be106ac","message_id":1369,"id":"SUSHI-USD","channel":"v3_orderbook","contents":{"offset":"2693991848","bids":[["10.783","387.5"]],"asks":[]}}
1635444238.6530628: {"type":"channel_data","connection_id":"60a4fc71-1312-4830-86f4-9eb98be106ac","message_id":1370,"id":"SUSHI-USD","channel":"v3_orderbook","contents":{"offset":"2693991849","bids":[["10.787","0"]],"asks":[]}}
1635444238.659934: {"type":"channel_data","connection_id":"60a4fc71-1312-4830-86f4-9eb98be106ac","message_id":1371,"id":"SUSHI-USD","channel":"v3_orderbook","contents":{"offset":"2693991855","bids":[["10.789","334.7"]],"asks":[]}}
1635444238.662257: {"type":"channel_data","connection_id":"60a4fc71-1312-4830-86f4-9eb98be106ac","message_id":1372,"id":"SUSHI-USD","channel":"v3_orderbook","contents":{"offset":"2693991853","bids":[["10.786","12161.2"]],"asks":[]}}
1635444238.673314: {"type":"channel_data","connection_id":"60a4fc71-1312-4830-86f4-9eb98be106ac","message_id":1373,"id":"ETH-USD","channel":"v3_orderbook","contents":{"offset":"2693991859","bids":[],"asks":[["4216.2","23.735"]]}}
1635444238.674113: {"type":"channel_data","connection_id":"60a4fc71-1312-4830-86f4-9eb98be106ac","message_id":1374,"id":"SUSHI-USD","channel":"v3_orderbook","contents":{"offset":"2693991857","bids":[["10.79","1394.6"]],"asks":[]}}
1635444238.7122319: {"type":"channel_data","connection_id":"60a4fc71-1312-4830-86f4-9eb98be106ac","message_id":1375,"id":"ETH-USD","channel":"v3_orderbook","contents":{"offset":"2693991862","bids":[],"asks":[["4216.2","0"]]}}
1635444238.737872: {"type":"channel_data","connection_id":"60a4fc71-1312-4830-86f4-9eb98be106ac","message_id":1376,"id":"UNI-USD","channel":"v3_orderbook","contents":{"offset":"2693991874","bids":[["24.902","1997.7"],["24.901","0"]],"asks":[]}}
1635444238.743667: {"type":"channel_data","connection_id":"60a4fc71-1312-4830-86f4-9eb98be106ac","message_id":1377,"id":"CRV-USD","channel":"v3_orderbook","contents":{"offset":"2693991873","bids":[],"asks":[["4.873","2585"]]}}
1635444238.7437482: {"type":"channel_data","connection_id":"60a4fc71-1312-4830-86f4-9eb98be106ac","message_id":1378,"id":"UNI-USD","channel":"v3_orderbook","contents":{"offset":"2693991872","bids":[["24.966","764"],["24.941","0"]],"asks":[]}}
1635444238.754011: {"type":"channel_data","connection_id":"60a4fc71-1312-4830-86f4-9eb98be106ac","message_id":1379,"id":"UNI-USD","channel":"v3_orderbook","contents":{"offset":"2693991883","bids":[["24.877","1997.7"],["24.876","0"]],"asks":[]}}
1635444238.754085: {"type":"channel_data","connection_id":"60a4fc71-1312-4830-86f4-9eb98be106ac","message_id":1380,"id":"SUSHI-USD","channel":"v3_orderbook","contents":{"offset":"2693991881","bids":[],"asks":[["10.8","5521.6"]]}}
1635444238.770679: {"type":"channel_data","connection_id":"60a4fc71-1312-4830-86f4-9eb98be106ac","message_id":1381,"id":"ETH-USD","channel":"v3_orderbook","contents":{"offset":"2693991885","bids":[],"asks":[["4216.2","23.735"]]}}
1635444238.7942111: {"type":"channel_data","connection_id":"60a4fc71-1312-4830-86f4-9eb98be106ac","message_id":1382,"id":"ETH-USD","channel":"v3_orderbook","contents":{"offset":"2693991889","bids":[],"asks":[["4216.2","0"]]}}
1635444238.81334: {"type":"channel_data","connection_id":"60a4fc71-1312-4830-86f4-9eb98be106ac","message_id":1383,"id":"UNI-USD","channel":"v3_orderbook","contents":{"offset":"2693991895","bids":[["24.161","500"]],"asks":[]}}
1635444238.860221: {"type":"channel_data","connection_id":"60a4fc71-1312-4830-86f4-9eb98be106ac","message_id":1384,"id":"ETH-USD","channel":"v3_orderbook","contents":{"offset":"2693991904","bids":[["4215.3","24.524"]],"asks":[]}}
1635444238.872525: {"type":"channel_data","connection_id":"60a4fc71-1312-4830-86f4-9eb98be106ac","message_id":1385,"id":"UNI-USD","channel":"v3_orderbook","contents":{"offset":"2693991909","bids":[],"asks":[["25.914","500"]]}}
1635444238.8822458: {"type":"channel_data","connection_id":"60a4fc71-1312-4830-86f4-9eb98be106ac","message_id":1386,"id":"ETH-USD","channel":"v3_orderbook","contents":{"offset":"2693991914","bids":[],"asks":[["4216.2","23.735"]]}}
1635444238.88231: {"type":"channel_data","connection_id":"60a4fc71-1312-4830-86f4-9eb98be106ac","message_id":1387,"id":"ETH-USD","channel":"v3_orderbook","contents":{"offset":"2693991916","bids":[["4215.9","467.789"]],"asks":[]}}
1635444238.89638: {"type":"channel_data","connection_id":"60a4fc71-1312-4830-86f4-9eb98be106ac","message_id":1388,"id":"ETH-USD","channel":"v3_orderbook","contents":{"offset":"2693991918","bids":[],"asks":[["4216.2","0"]]}}
1635444238.8969622: {"type":"channel_data","connection_id":"60a4fc71-1312-4830-86f4-9eb98be106ac","message_id":1389,"id":"ETH-USD","channel":"v3_trades","contents":{"trades":[{"size":"0.1","side":"SELL","price":"4215.9","createdAt":"2021-10-28T18:03:58.920Z"}]}}
1635444238.9179258: {"type":"channel_data","connection_id":"60a4fc71-1312-4830-86f4-9eb98be106ac","message_id":1390,"id":"UMA-USD","channel":"v3_orderbook","contents":{"offset":"2693991922","bids":[],"asks":[["11.33","1683.6"]]}}
1635444238.9192991: {"type":"channel_data","connection_id":"60a4fc71-1312-4830-86f4-9eb98be106ac","message_id":1391,"id":"UMA-USD","channel":"v3_orderbook","contents":{"offset":"2693991921","bids":[],"asks":[["11.33","23786.7"]]}}
1635444238.9309618: {"type":"channel_data","connection_id":"60a4fc71-1312-4830-86f4-9eb98be106ac","message_id":1392,"id":"UMA-USD","channel":"v3_orderbook","contents":{"offset":"2693991926","bids":[["11.27","29416.1"]],"asks":[]}}
1635444238.943661: {"type":"channel_data","connection_id":"60a4fc71-1312-4830-86f4-9eb98be106ac","message_id":1393,"id":"ETH-USD","channel":"v3_orderbook","contents":{"offset":"2693991930","bids":[["4215.6","0"]],"asks":[]}}
1635444238.956168: {"type":"channel_data","connection_id":"60a4fc71-1312-4830-86f4-9eb98be106ac","message_id":1394,"id":"ETH-USD","channel":"v3_orderbook","contents":{"offset":"2693991935","bids":[],"asks":[["4216.2","23.735"]]}}
1635444238.956249: {"type":"channel_data","connection_id":"60a4fc71-1312-4830-86f4-9eb98be106ac","message_id":1395,"id":"UMA-USD","channel":"v3_orderbook","contents":{"offset":"2693991936","bids":[["11.27","29150.7"]],"asks":[]}}
1635444238.9789171: {"type":"channel_data","connection_id":"60a4fc71-1312-4830-86f4-9eb98be106ac","message_id":1396,"id":"ETH-USD","channel":"v3_orderbook","contents":{"offset":"2693991944","bids":[],"asks":[["4216.2","0"]]}}
1635444238.994349: {"type":"channel_data","connection_id":"60a4fc71-1312-4830-86f4-9eb98be106ac","message_id":1397,"id":"ETH-USD","channel":"v3_orderbook","contents":{"offset":"2693991949","bids":[],"asks":[["4217.6","0"]]}}
1635444238.994467: {"type":"channel_data","connection_id":"60a4fc71-1312-4830-86f4-9eb98be106ac","message_id":1398,"id":"ETH-USD","channel":"v3_orderbook","contents":{"offset":"2693991950","bids":[["4213.9","64.325"]],"asks":[]}}
1635444239.0040572: {"type":"channel_data","connection_id":"60a4fc71-1312-4830-86f4-9eb98be106ac","message_id":1399,"id":"ETH-USD","channel":"v3_orderbook","contents":{"offset":"2693991956","bids":[],"asks":[["4217.5","11.042"]]}}
1635444239.007169: {"type":"channel_data","connection_id":"60a4fc71-1312-4830-86f4-9eb98be106ac","message_id":1400,"id":"ETH-USD","channel":"v3_orderbook","contents":{"offset":"2693991953","bids":[["4213.8","18.69"]],"asks":[]}}
1635444239.0170891: {"type":"channel_data","connection_id":"60a4fc71-1312-4830-86f4-9eb98be106ac","message_id":1401,"id":"ETH-USD","channel":"v3_orderbook","contents":{"offset":"2693991959","bids":[],"asks":[["4218.1","0"]]}}
1635444239.029082: {"type":"channel_data","connection_id":"60a4fc71-1312-4830-86f4-9eb98be106ac","message_id":1402,"id":"ETH-USD","channel":"v3_orderbook","contents":{"offset":"2693991963","bids":[],"asks":[["4216.2","23.735"]]}}
1635444239.0453608: {"type":"channel_data","connection_id":"60a4fc71-1312-4830-86f4-9eb98be106ac","message_id":1403,"id":"UMA-USD","channel":"v3_orderbook","contents":{"offset":"2693991969","bids":[],"asks":[["11.33","28207.6"]]}}
1635444239.0454788: {"type":"channel_data","connection_id":"60a4fc71-1312-4830-86f4-9eb98be106ac","message_id":1404,"id":"UMA-USD","channel":"v3_orderbook","contents":{"offset":"2693991966","bids":[],"asks":[["11.33","23786.7"]]}}
1635444239.070671: {"type":"channel_data","connection_id":"60a4fc71-1312-4830-86f4-9eb98be106ac","message_id":1405,"id":"ETH-USD","channel":"v3_orderbook","contents":{"offset":"2693991974","bids":[["4215.8","58.18"]],"asks":[]}}
1635444239.079086: {"type":"channel_data","connection_id":"60a4fc71-1312-4830-86f4-9eb98be106ac","message_id":1406,"id":"SUSHI-USD","channel":"v3_orderbook","contents":{"offset":"2693991976","bids":[],"asks":[["10.798","7706.9"]]}}
1635444239.079136: {"type":"channel_data","connection_id":"60a4fc71-1312-4830-86f4-9eb98be106ac","message_id":1407,"id":"SUSHI-USD","channel":"v3_orderbook","contents":{"offset":"2693991979","bids":[["10.784","8377.9"]],"asks":[]}}
1635444239.09555: {"type":"channel_data","connection_id":"60a4fc71-1312-4830-86f4-9eb98be106ac","message_id":1408,"id":"SUSHI-USD","channel":"v3_orderbook","contents":{"offset":"2693991980","bids":[],"asks":[["10.793","4002.3"]]}}
1635444239.105512: {"type":"channel_data","connection_id":"60a4fc71-1312-4830-86f4-9eb98be106ac","message_id":1409,"id":"ETH-USD","channel":"v3_orderbook","contents":{"offset":"2693991989","bids":[],"asks":[["4216.2","0"]]}}
1635444239.1683671: {"type":"channel_data","connection_id":"60a4fc71-1312-4830-86f4-9eb98be106ac","message_id":1410,"id":"ETH-USD","channel":"v3_orderbook","contents":{"offset":"2693992004","bids":[],"asks":[["4217.8","13.491"]]}}
1635444239.1995578: {"type":"channel_data","connection_id":"60a4fc71-1312-4830-86f4-9eb98be106ac","message_id":1411,"id":"ETH-USD","channel":"v3_orderbook","contents":{"offset":"2693992018","bids":[],"asks":[["4216.2","23.735"]]}}
1635444239.223781: {"type":"channel_data","connection_id":"60a4fc71-1312-4830-86f4-9eb98be106ac","message_id":1412,"id":"ETH-USD","channel":"v3_orderbook","contents":{"offset":"2693992024","bids":[],"asks":[["4216.2","0"]]}}
1635444239.268418: {"type":"channel_data","connection_id":"60a4fc71-1312-4830-86f4-9eb98be106ac","message_id":1413,"id":"ETH-USD","channel":"v3_orderbook","contents":{"offset":"2693992038","bids":[],"asks":[["4216.2","23.735"]]}}
1635444239.28243: {"type":"channel_data","connection_id":"60a4fc71-1312-4830-86f4-9eb98be106ac","message_id":1414,"id":"SUSHI-USD","channel":"v3_orderbook","contents":{"offset":"2693992043","bids":[],"asks":[["10.827","0"]]}}
1635444239.295139: {"type":"channel_data","connection_id":"60a4fc71-1312-4830-86f4-9eb98be106ac","message_id":1415,"id":"SUSHI-USD","channel":"v3_orderbook","contents":{"offset":"2693992045","bids":[["10.751","0"]],"asks":[]}}
1635444239.3031948: {"type":"channel_data","connection_id":"60a4fc71-1312-4830-86f4-9eb98be106ac","message_id":1416,"id":"SUSHI-USD","channel":"v3_orderbook","contents":{"offset":"2693992048","bids":[["10.682","13393.3"]],"asks":[]}}
1635444239.303308: {"type":"channel_data","connection_id":"60a4fc71-1312-4830-86f4-9eb98be106ac","message_id":1417,"id":"ETH-USD","channel":"v3_orderbook","contents":{"offset":"2693992049","bids":[],"asks":[["4216.2","0"]]}}
1635444239.348774: {"type":"channel_data","connection_id":"60a4fc71-1312-4830-86f4-9eb98be106ac","message_id":1418,"id":"ETH-USD","channel":"v3_orderbook","contents":{"offset":"2693992059","bids":[],"asks":[["4216.2","23.735"]]}}
1635444239.357527: {"type":"channel_data","connection_id":"60a4fc71-1312-4830-86f4-9eb98be106ac","message_id":1419,"id":"ETH-USD","channel":"v3_orderbook","contents":{"offset":"2693992062","bids":[],"asks":[["4216.2","0"]]}}
1635444239.3719769: {"type":"channel_data","connection_id":"60a4fc71-1312-4830-86f4-9eb98be106ac","message_id":1420,"id":"SUSHI-USD","channel":"v3_orderbook","contents":{"offset":"2693992067","bids":[["10.79","1209.2"]],"asks":[]}}
1635444239.4053361: {"type":"channel_data","connection_id":"60a4fc71-1312-4830-86f4-9eb98be106ac","message_id":1421,"id":"SUSHI-USD","channel":"v3_orderbook","contents":{"offset":"2693992076","bids":[["10.786","12457.1"]],"asks":[]}}
1635444239.405417: {"type":"channel_data","connection_id":"60a4fc71-1312-4830-86f4-9eb98be106ac","message_id":1422,"id":"ETH-USD","channel":"v3_orderbook","contents":{"offset":"2693992077","bids":[],"asks":[["4216.2","23.735"]]}}
1635444239.405453: {"type":"channel_data","connection_id":"60a4fc71-1312-4830-86f4-9eb98be106ac","message_id":1423,"id":"SUSHI-USD","channel":"v3_orderbook","contents":{"offset":"2693992073","bids":[["10.789","601.2"]],"asks":[]}}
1635444239.417598: {"type":"channel_data","connection_id":"60a4fc71-1312-4830-86f4-9eb98be106ac","message_id":1424,"id":"ETH-USD","channel":"v3_orderbook","contents":{"offset":"2693992084","bids":[["4210.4","2.68"]],"asks":[]}}
1635444239.417681: {"type":"channel_data","connection_id":"60a4fc71-1312-4830-86f4-9eb98be106ac","message_id":1425,"id":"ETH-USD","channel":"v3_orderbook","contents":{"offset":"2693992085","bids":[],"asks":[["4216.2","0"]]}}
1635444239.465235: {"type":"channel_data","connection_id":"60a4fc71-1312-4830-86f4-9eb98be106ac","message_id":1426,"id":"ETH-USD","channel":"v3_orderbook","contents":{"offset":"2693992096","bids":[],"asks":[["4216.2","23.735"]]}}
1635444239.4962618: {"type":"channel_data","connection_id":"60a4fc71-1312-4830-86f4-9eb98be106ac","message_id":1427,"id":"ETH-USD","channel":"v3_orderbook","contents":{"offset":"2693992101","bids":[],"asks":[["4216.2","0"]]}}
1635444239.518868: {"type":"channel_data","connection_id":"60a4fc71-1312-4830-86f4-9eb98be106ac","message_id":1428,"id":"ETH-USD","channel":"v3_orderbook","contents":{"offset":"2693992104","bids":[],"asks":[["4219.6","79.921"]]}}
1635444239.535106: {"type":"channel_data","connection_id":"60a4fc71-1312-4830-86f4-9eb98be106ac","message_id":1429,"id":"SUSHI-USD","channel":"v3_orderbook","contents":{"offset":"2693992106","bids":[],"asks":[["10.8","1071.2"]]}}
1635444239.546069: {"type":"channel_data","connection_id":"60a4fc71-1312-4830-86f4-9eb98be106ac","message_id":1430,"id":"ETH-USD","channel":"v3_orderbook","contents":{"offset":"2693992109","bids":[],"asks":[["4216.2","23.735"]]}}
1635444239.560452: {"type":"channel_data","connection_id":"60a4fc71-1312-4830-86f4-9eb98be106ac","message_id":1431,"id":"LTC-USD","channel":"v3_orderbook","contents":{"offset":"2693992111","bids":[],"asks":[["189.2","1971.98"],["189.3","0"]]}}
1635444239.56224: {"type":"channel_data","connection_id":"60a4fc71-1312-4830-86f4-9eb98be106ac","message_id":1432,"id":"SUSHI-USD","channel":"v3_orderbook","contents":{"offset":"2693992113","bids":[],"asks":[["10.802","440.6"]]}}
1635444239.572368: {"type":"channel_data","connection_id":"60a4fc71-1312-4830-86f4-9eb98be106ac","message_id":1433,"id":"CRV-USD","channel":"v3_orderbook","contents":{"offset":"2693992115","bids":[["4.85","531"]],"asks":[]}}
1635444239.572434: {"type":"channel_data","connection_id":"60a4fc71-1312-4830-86f4-9eb98be106ac","message_id":1434,"id":"ETH-USD","channel":"v3_orderbook","contents":{"offset":"2693992116","bids":[],"asks":[["4216.2","0"]]}}
1635444239.58262: {"type":"channel_data","connection_id":"60a4fc71-1312-4830-86f4-9eb98be106ac","message_id":1435,"id":"SUSHI-USD","channel":"v3_orderbook","contents":{"offset":"2693992119","bids":[["10.753","1001"]],"asks":[]}}
1635444239.641057: {"type":"channel_data","connection_id":"60a4fc71-1312-4830-86f4-9eb98be106ac","message_id":1436,"id":"ETH-USD","channel":"v3_orderbook","contents":{"offset":"2693992136","bids":[],"asks":[["4216.8","48.228"]]}}
1635444239.6411169: {"type":"channel_data","connection_id":"60a4fc71-1312-4830-86f4-9eb98be106ac","message_id":1437,"id":"ETH-USD","channel":"v3_orderbook","contents":{"offset":"2693992134","bids":[],"asks":[["4216.2","23.735"]]}}
1635444239.64114: {"type":"channel_data","connection_id":"60a4fc71-1312-4830-86f4-9eb98be106ac","message_id":1438,"id":"ETH-USD","channel":"v3_orderbook","contents":{"offset":"2693992143","bids":[["4213.1","1898.821"]],"asks":[]}}
1635444239.64116: {"type":"channel_data","connection_id":"60a4fc71-1312-4830-86f4-9eb98be106ac","message_id":1439,"id":"SUSHI-USD","channel":"v3_orderbook","contents":{"offset":"2693992142","bids":[],"asks":[["10.829","1031"]]}}
1635444239.648181: {"type":"channel_data","connection_id":"60a4fc71-1312-4830-86f4-9eb98be106ac","message_id":1440,"id":"ETH-USD","channel":"v3_orderbook","contents":{"offset":"2693992148","bids":[],"asks":[["4216.2","0"]]}}
1635444239.651933: {"type":"channel_data","connection_id":"60a4fc71-1312-4830-86f4-9eb98be106ac","message_id":1441,"id":"SUSHI-USD","channel":"v3_orderbook","contents":{"offset":"2693992149","bids":[],"asks":[["10.798","12158.3"]]}}
1635444239.651989: {"type":"channel_data","connection_id":"60a4fc71-1312-4830-86f4-9eb98be106ac","message_id":1442,"id":"SUSHI-USD","channel":"v3_orderbook","contents":{"offset":"2693992147","bids":[],"asks":[["10.909","942.3"],["10.921","0"]]}}
1635444239.652756: {"type":"channel_data","connection_id":"60a4fc71-1312-4830-86f4-9eb98be106ac","message_id":1443,"id":"SUSHI-USD","channel":"v3_orderbook","contents":{"offset":"2693992156","bids":[["10.788","185.4"]],"asks":[]}}
1635444239.661546: {"type":"channel_data","connection_id":"60a4fc71-1312-4830-86f4-9eb98be106ac","message_id":1444,"id":"ETH-USD","channel":"v3_orderbook","contents":{"offset":"2693992160","bids":[],"asks":[["4219","21.362"]]}}
1635444239.661626: {"type":"channel_data","connection_id":"60a4fc71-1312-4830-86f4-9eb98be106ac","message_id":1445,"id":"ETH-USD","channel":"v3_orderbook","contents":{"offset":"2693992161","bids":[],"asks":[["4219.1","0"]]}}
1635444239.672592: {"type":"channel_data","connection_id":"60a4fc71-1312-4830-86f4-9eb98be106ac","message_id":1446,"id":"ETH-USD","channel":"v3_orderbook","contents":{"offset":"2693992167","bids":[["4213.6","13.207"]],"asks":[]}}
1635444239.675945: {"type":"channel_data","connection_id":"60a4fc71-1312-4830-86f4-9eb98be106ac","message_id":1447,"id":"ETH-USD","channel":"v3_orderbook","contents":{"offset":"2693992165","bids":[["4213.9","57.11"]],"asks":[]}}
1635444239.6846552: {"type":"channel_data","connection_id":"60a4fc71-1312-4830-86f4-9eb98be106ac","message_id":1448,"id":"SUSHI-USD","channel":"v3_orderbook","contents":{"offset":"2693992172","bids":[["10.79","0"]],"asks":[]}}
1635444239.684706: {"type":"channel_data","connection_id":"60a4fc71-1312-4830-86f4-9eb98be106ac","message_id":1449,"id":"ETH-USD","channel":"v3_orderbook","contents":{"offset":"2693992171","bids":[],"asks":[["4217.5","1.258"]]}}
1635444239.6957152: {"type":"channel_data","connection_id":"60a4fc71-1312-4830-86f4-9eb98be106ac","message_id":1450,"id":"ETH-USD","channel":"v3_orderbook","contents":{"offset":"2693992177","bids":[],"asks":[["4216.2","23.735"]]}}
1635444239.7066932: {"type":"channel_data","connection_id":"60a4fc71-1312-4830-86f4-9eb98be106ac","message_id":1451,"id":"ETH-USD","channel":"v3_orderbook","contents":{"offset":"2693992180","bids":[],"asks":[["4217.2","32.279"]]}}
1635444239.708801: {"type":"channel_data","connection_id":"60a4fc71-1312-4830-86f4-9eb98be106ac","message_id":1452,"id":"ETH-USD","channel":"v3_orderbook","contents":{"offset":"2693992184","bids":[],"asks":[["4216","58.01"]]}}
1635444239.708916: {"type":"channel_data","connection_id":"60a4fc71-1312-4830-86f4-9eb98be106ac","message_id":1453,"id":"ETH-USD","channel":"v3_orderbook","contents":{"offset":"2693992182","bids":[],"asks":[["4219.3","0.355"]]}}
1635444239.718519: {"type":"channel_data","connection_id":"60a4fc71-1312-4830-86f4-9eb98be106ac","message_id":1454,"id":"ETH-USD","channel":"v3_orderbook","contents":{"offset":"2693992186","bids":[],"asks":[["4219.2","11.304"]]}}
1635444239.718606: {"type":"channel_data","connection_id":"60a4fc71-1312-4830-86f4-9eb98be106ac","message_id":1455,"id":"ETH-USD","channel":"v3_orderbook","contents":{"offset":"2693992188","bids":[],"asks":[["4216.5","9.4"]]}}
1635444239.718643: {"type":"channel_data","connection_id":"60a4fc71-1312-4830-86f4-9eb98be106ac","message_id":1456,"id":"ETH-USD","channel":"v3_orderbook","contents":{"offset":"2693992187","bids":[],"asks":[["4216.2","0"]]}}
1635444239.724734: {"type":"channel_data","connection_id":"60a4fc71-1312-4830-86f4-9eb98be106ac","message_id":1457,"id":"ETH-USD","channel":"v3_orderbook","contents":{"offset":"2693992193","bids":[["4212.6","32.222"]],"asks":[]}}
1635444239.733906: {"type":"channel_data","connection_id":"60a4fc71-1312-4830-86f4-9eb98be106ac","message_id":1458,"id":"SUSHI-USD","channel":"v3_orderbook","contents":{"offset":"2693992194","bids":[],"asks":[["10.798","12297.3"]]}}
1635444239.744412: {"type":"channel_data","connection_id":"60a4fc71-1312-4830-86f4-9eb98be106ac","message_id":1459,"id":"SUSHI-USD","channel":"v3_orderbook","contents":{"offset":"2693992199","bids":[],"asks":[["10.802","579.6"]]}}
1635444239.744494: {"type":"channel_data","connection_id":"60a4fc71-1312-4830-86f4-9eb98be106ac","message_id":1460,"id":"ETH-USD","channel":"v3_orderbook","contents":{"offset":"2693992201","bids":[["4213.6","5.991"]],"asks":[]}}
1635444239.764822: {"type":"channel_data","connection_id":"60a4fc71-1312-4830-86f4-9eb98be106ac","message_id":1461,"id":"ETH-USD","channel":"v3_orderbook","contents":{"offset":"2693992207","bids":[],"asks":[["4217.1","9.813"]]}}
1635444239.764897: {"type":"channel_data","connection_id":"60a4fc71-1312-4830-86f4-9eb98be106ac","message_id":1462,"id":"LTC-USD","channel":"v3_orderbook","contents":{"offset":"2693992210","bids":[],"asks":[["194.5","0"]]}}
1635444239.764929: {"type":"channel_data","connection_id":"60a4fc71-1312-4830-86f4-9eb98be106ac","message_id":1463,"id":"ETH-USD","channel":"v3_orderbook","contents":{"offset":"2693992208","bids":[],"asks":[["4217.2","22.496"]]}}
1635444239.7665532: {"type":"channel_data","connection_id":"60a4fc71-1312-4830-86f4-9eb98be106ac","message_id":1464,"id":"SUSHI-USD","channel":"v3_orderbook","contents":{"offset":"2693992206","bids":[["10.685","925.9"],["10.682","12467.4"]],"asks":[]}}
1635444239.7711182: {"type":"channel_data","connection_id":"60a4fc71-1312-4830-86f4-9eb98be106ac","message_id":1465,"id":"UNI-USD","channel":"v3_orderbook","contents":{"offset":"2693992211","bids":[],"asks":[["25.053","19055.9"]]}}
1635444239.7746172: {"type":"channel_data","connection_id":"60a4fc71-1312-4830-86f4-9eb98be106ac","message_id":1466,"id":"LTC-USD","channel":"v3_orderbook","contents":{"offset":"2693992215","bids":[["181.3","0"]],"asks":[]}}
1635444239.774679: {"type":"channel_data","connection_id":"60a4fc71-1312-4830-86f4-9eb98be106ac","message_id":1467,"id":"ETH-USD","channel":"v3_orderbook","contents":{"offset":"2693992216","bids":[],"asks":[["4219","3.755"]]}}
1635444239.779863: {"type":"channel_data","connection_id":"60a4fc71-1312-4830-86f4-9eb98be106ac","message_id":1468,"id":"ETH-USD","channel":"v3_orderbook","contents":{"offset":"2693992212","bids":[["4213.8","0"]],"asks":[]}}
1635444239.7799401: {"type":"channel_data","connection_id":"60a4fc71-1312-4830-86f4-9eb98be106ac","message_id":1469,"id":"LTC-USD","channel":"v3_orderbook","contents":{"offset":"2693992219","bids":[["187.2","22.71"]],"asks":[]}}
1635444239.779976: {"type":"channel_data","connection_id":"60a4fc71-1312-4830-86f4-9eb98be106ac","message_id":1470,"id":"LTC-USD","channel":"v3_orderbook","contents":{"offset":"2693992213","bids":[],"asks":[["188.6","5.85"]]}}
1635444239.780004: {"type":"channel_data","connection_id":"60a4fc71-1312-4830-86f4-9eb98be106ac","message_id":1471,"id":"ETH-USD","channel":"v3_orderbook","contents":{"offset":"2693992214","bids":[],"asks":[["4216.2","23.735"]]}}
1635444239.798401: {"type":"channel_data","connection_id":"60a4fc71-1312-4830-86f4-9eb98be106ac","message_id":1472,"id":"ETH-USD","channel":"v3_orderbook","contents":{"offset":"2693992224","bids":[],"asks":[["4216.4","104.455"]]}}
1635444239.801481: {"type":"channel_data","connection_id":"60a4fc71-1312-4830-86f4-9eb98be106ac","message_id":1473,"id":"ETH-USD","channel":"v3_orderbook","contents":{"offset":"2693992221","bids":[],"asks":[["4217.8","17.791"]]}}
1635444239.814507: {"type":"channel_data","connection_id":"60a4fc71-1312-4830-86f4-9eb98be106ac","message_id":1474,"id":"ETH-USD","channel":"v3_orderbook","contents":{"offset":"2693992233","bids":[],"asks":[["4216.2","0"]]}}
1635444239.814593: {"type":"channel_data","connection_id":"60a4fc71-1312-4830-86f4-9eb98be106ac","message_id":1475,"id":"ETH-USD","channel":"v3_orderbook","contents":{"offset":"2693992229","bids":[["4213.5","7.216"]],"asks":[]}}
1635444239.846833: {"type":"channel_data","connection_id":"60a4fc71-1312-4830-86f4-9eb98be106ac","message_id":1476,"id":"ETH-USD","channel":"v3_orderbook","contents":{"offset":"2693992245","bids":[],"asks":[["4216.5","11.65"]]}}
1635444239.854806: {"type":"channel_data","connection_id":"60a4fc71-1312-4830-86f4-9eb98be106ac","message_id":1477,"id":"ETH-USD","channel":"v3_orderbook","contents":{"offset":"2693992255","bids":[],"asks":[["4217.2","32.279"]]}}
1635444239.862845: {"type":"channel_data","connection_id":"60a4fc71-1312-4830-86f4-9eb98be106ac","message_id":1478,"id":"ETH-USD","channel":"v3_orderbook","contents":{"offset":"2693992256","bids":[],"asks":[["4217.1","0.03"]]}}
1635444239.8668008: {"type":"channel_data","connection_id":"60a4fc71-1312-4830-86f4-9eb98be106ac","message_id":1479,"id":"ETH-USD","channel":"v3_orderbook","contents":{"offset":"2693992264","bids":[["4213.6","13.207"]],"asks":[]}}
1635444239.871238: {"type":"channel_data","connection_id":"60a4fc71-1312-4830-86f4-9eb98be106ac","message_id":1480,"id":"SUSHI-USD","channel":"v3_orderbook","contents":{"offset":"2693992259","bids":[["10.789","1810.4"]],"asks":[]}}
1635444239.871298: {"type":"channel_data","connection_id":"60a4fc71-1312-4830-86f4-9eb98be106ac","message_id":1481,"id":"ETH-USD","channel":"v3_orderbook","contents":{"offset":"2693992261","bids":[],"asks":[["4216.2","23.735"]]}}
1635444239.876509: {"type":"channel_data","connection_id":"60a4fc71-1312-4830-86f4-9eb98be106ac","message_id":1482,"id":"ETH-USD","channel":"v3_orderbook","contents":{"offset":"2693992268","bids":[["4210.1","2.05"]],"asks":[]}}
1635444239.8869739: {"type":"channel_data","connection_id":"60a4fc71-1312-4830-86f4-9eb98be106ac","message_id":1483,"id":"ETH-USD","channel":"v3_orderbook","contents":{"offset":"2693992274","bids":[],"asks":[["4216.5","68.886"]]}}
1635444239.887042: {"type":"channel_data","connection_id":"60a4fc71-1312-4830-86f4-9eb98be106ac","message_id":1484,"id":"ETH-USD","channel":"v3_orderbook","contents":{"offset":"2693992272","bids":[],"asks":[["4216.2","0"]]}}
1635444239.88707: {"type":"channel_data","connection_id":"60a4fc71-1312-4830-86f4-9eb98be106ac","message_id":1485,"id":"UNI-USD","channel":"v3_orderbook","contents":{"offset":"2693992273","bids":[],"asks":[["25.051","10785.4"]]}}
1635444239.888896: {"type":"channel_data","connection_id":"60a4fc71-1312-4830-86f4-9eb98be106ac","message_id":1486,"id":"SUSHI-USD","channel":"v3_orderbook","contents":{"offset":"2693992270","bids":[["10.771","692.2"]],"asks":[]}}
1635444239.8972192: {"type":"channel_data","connection_id":"60a4fc71-1312-4830-86f4-9eb98be106ac","message_id":1487,"id":"ETH-USD","channel":"v3_orderbook","contents":{"offset":"2693992276","bids":[],"asks":[["4218.3","74.688"]]}}
1635444239.897275: {"type":"channel_data","connection_id":"60a4fc71-1312-4830-86f4-9eb98be106ac","message_id":1488,"id":"ETH-USD","channel":"v3_orderbook","contents":{"offset":"2693992275","bids":[["4213.3","20.688"]],"asks":[]}}
1635444239.89918: {"type":"channel_data","connection_id":"60a4fc71-1312-4830-86f4-9eb98be106ac","message_id":1489,"id":"ETH-USD","channel":"v3_orderbook","contents":{"offset":"2693992278","bids":[["4213.5","0"]],"asks":[]}}
1635444239.932766: {"type":"channel_data","connection_id":"60a4fc71-1312-4830-86f4-9eb98be106ac","message_id":1490,"id":"ETH-USD","channel":"v3_orderbook","contents":{"offset":"2693992281","bids":[],"asks":[["4216.2","23.735"]]}}
1635444239.944265: {"type":"channel_data","connection_id":"60a4fc71-1312-4830-86f4-9eb98be106ac","message_id":1491,"id":"ETH-USD","channel":"v3_orderbook","contents":{"offset":"2693992285","bids":[],"asks":[["4216.5","11.65"]]}}
1635444239.967097: {"type":"channel_data","connection_id":"60a4fc71-1312-4830-86f4-9eb98be106ac","message_id":1492,"id":"UNI-USD","channel":"v3_orderbook","contents":{"offset":"2693992292","bids":[["24.95","43.9"],["24.947","0"]],"asks":[]}}
1635444239.9671779: {"type":"channel_data","connection_id":"60a4fc71-1312-4830-86f4-9eb98be106ac","message_id":1493,"id":"ETH-USD","channel":"v3_orderbook","contents":{"offset":"2693992291","bids":[["4213.3","0"]],"asks":[]}}
1635444239.9672089: {"type":"channel_data","connection_id":"60a4fc71-1312-4830-86f4-9eb98be106ac","message_id":1494,"id":"ETH-USD","channel":"v3_orderbook","contents":{"offset":"2693992293","bids":[],"asks":[["4216.2","0"]]}}
1635444239.967231: {"type":"channel_data","connection_id":"60a4fc71-1312-4830-86f4-9eb98be106ac","message_id":1495,"id":"SUSHI-USD","channel":"v3_orderbook","contents":{"offset":"2693992294","bids":[],"asks":[["10.804","14089.6"]]}}
1635444240.00595: {"type":"channel_data","connection_id":"60a4fc71-1312-4830-86f4-9eb98be106ac","message_id":1496,"id":"ETH-USD","channel":"v3_orderbook","contents":{"offset":"2693992300","bids":[],"asks":[["4217.2","22.496"]]}}
1635444240.01607: {"type":"channel_data","connection_id":"60a4fc71-1312-4830-86f4-9eb98be106ac","message_id":1497,"id":"UNI-USD","channel":"v3_orderbook","contents":{"offset":"2693992307","bids":[],"asks":[["25.136","0"],["25.14","43.9"]]}}
1635444240.0178938: {"type":"channel_data","connection_id":"60a4fc71-1312-4830-86f4-9eb98be106ac","message_id":1498,"id":"ETH-USD","channel":"v3_orderbook","contents":{"offset":"2693992308","bids":[["4213.6","5.991"]],"asks":[]}}
1635444240.021128: {"type":"channel_data","connection_id":"60a4fc71-1312-4830-86f4-9eb98be106ac","message_id":1499,"id":"ETH-USD","channel":"v3_orderbook","contents":{"offset":"2693992310","bids":[],"asks":[["4217","9.783"]]}}
1635444240.0418859: {"type":"channel_data","connection_id":"60a4fc71-1312-4830-86f4-9eb98be106ac","message_id":1500,"id":"LTC-USD","channel":"v3_orderbook","contents":{"offset":"2693992323","bids":[],"asks":[["189.2","1188.96"],["189.3","783.02"]]}}
1635444240.04196: {"type":"channel_data","connection_id":"60a4fc71-1312-4830-86f4-9eb98be106ac","message_id":1501,"id":"ETH-USD","channel":"v3_orderbook","contents":{"offset":"2693992320","bids":[["4213.4","7.216"]],"asks":[]}}
1635444240.046387: {"type":"channel_data","connection_id":"60a4fc71-1312-4830-86f4-9eb98be106ac","message_id":1502,"id":"CRV-USD","channel":"v3_orderbook","contents":{"offset":"2693992324","bids":[["4.817","16713"],["4.816","1059"]],"asks":[]}}
1635444240.046467: {"type":"channel_data","connection_id":"60a4fc71-1312-4830-86f4-9eb98be106ac","message_id":1503,"id":"ETH-USD","channel":"v3_orderbook","contents":{"offset":"2693992325","bids":[["4213.6","24.441"]],"asks":[]}}
1635444240.046498: {"type":"channel_data","connection_id":"60a4fc71-1312-4830-86f4-9eb98be106ac","message_id":1504,"id":"ETH-USD","channel":"v3_orderbook","contents":{"offset":"2693992321","bids":[],"asks":[["4216.2","23.735"]]}}
1635444240.053012: {"type":"channel_data","connection_id":"60a4fc71-1312-4830-86f4-9eb98be106ac","message_id":1505,"id":"ETH-USD","channel":"v3_orderbook","contents":{"offset":"2693992332","bids":[],"asks":[["4216.2","0"]]}}
1635444240.053107: {"type":"channel_data","connection_id":"60a4fc71-1312-4830-86f4-9eb98be106ac","message_id":1506,"id":"ETH-USD","channel":"v3_orderbook","contents":{"offset":"2693992328","bids":[],"asks":[["4219.3","0.375"]]}}
1635444240.078759: {"type":"channel_data","connection_id":"60a4fc71-1312-4830-86f4-9eb98be106ac","message_id":1507,"id":"CRV-USD","channel":"v3_orderbook","contents":{"offset":"2693992335","bids":[["4.82","7227"],["4.819","925"]],"asks":[]}}
1635444240.078866: {"type":"channel_data","connection_id":"60a4fc71-1312-4830-86f4-9eb98be106ac","message_id":1508,"id":"EOS-USD","channel":"v3_orderbook","contents":{"offset":"2693992336","bids":[],"asks":[["4.419","7957"],["4.42","0"]]}}
1635444240.095534: {"type":"channel_data","connection_id":"60a4fc71-1312-4830-86f4-9eb98be106ac","message_id":1509,"id":"ETH-USD","channel":"v3_orderbook","contents":{"offset":"2693992341","bids":[],"asks":[["4218.3","57.052"]]}}
1635444240.1050081: {"type":"channel_data","connection_id":"60a4fc71-1312-4830-86f4-9eb98be106ac","message_id":1510,"id":"SUSHI-USD","channel":"v3_orderbook","contents":{"offset":"2693992343","bids":[],"asks":[["10.803","278.5"]]}}
1635444240.1093209: {"type":"channel_data","connection_id":"60a4fc71-1312-4830-86f4-9eb98be106ac","message_id":1511,"id":"SUSHI-USD","channel":"v3_orderbook","contents":{"offset":"2693992342","bids":[],"asks":[["10.803","556.3"]]}}
1635444240.118371: {"type":"channel_data","connection_id":"60a4fc71-1312-4830-86f4-9eb98be106ac","message_id":1512,"id":"ETH-USD","channel":"v3_orderbook","contents":{"offset":"2693992344","bids":[],"asks":[["4216.4","160.851"]]}}
